{
  "version": 8,
  "blockIdVersion": 8,
  "anchorX": 0,
  "anchorY": 18,
  "anchorZ": 10,
  "blocks": [
    {
      "x": -4,
      "y": 2,
      "z": -9,
      "name": "Rock_Quartzite"
    },
    {
      "x": -4,
      "y": 3,
      "z": -9,
      "name": "Rock_Quartzite"
    },
    {
      "x": -4,
      "y": 4,
      "z": -9,
      "name": "Rock_Quartzite_Brick"
    },
    {
      "x": -4,
      "y": 5,
      "z": -9,
      "name": "Rock_Quartzite_Brick"
    },
    {
      "x": -4,
      "y": 2,
      "z": -8,
      "name": "Rock_Quartzite"
    },
    {
      "x": -4,
      "y": 3,
      "z": -8,
      "name": "Rock_Quartzite"
    },
    {
      "x": -4,
      "y": 4,
      "z": -8,
      "name": "Rock_Quartzite_Brick"
    },
    {
      "x": -4,
      "y": 5,
      "z": -8,
      "name": "Rock_Quartzite_Brick"
    },
    {
      "x": -4,
      "y": 6,
      "z": -8,
      "name": "Rock_Quartzite_Brick"
    },
    {
      "x": -4,
      "y": 2,
      "z": -7,
      "name": "Rock_Quartzite"
    },
    {
      "x": -4,
      "y": 3,
      "z": -7,
      "name": "Rock_Quartzite"
    },
    {
      "x": -4,
      "y": 4,
      "z": -7,
      "name": "Rock_Quartzite"
    },
    {
      "x": -4,
      "y": 5,
      "z": -7,
      "name": "Rock_Quartzite_Brick"
    },
    {
      "x": -4,
      "y": 6,
      "z": -7,
      "name": "Rock_Quartzite_Brick"
    },
    {
      "x": -4,
      "y": 7,
      "z": -7,
      "name": "Rock_Quartzite_Brick"
    },
    {
      "x": -4,
      "y": 3,
      "z": -6,
      "name": "Rock_Quartzite"
    },
    {
      "x": -4,
      "y": 4,
      "z": -6,
      "name": "Rock_Quartzite"
    },
    {
      "x": -4,
      "y": 5,
      "z": -6,
      "name": "Rock_Quartzite"
    },
    {
      "x": -4,
      "y": 6,
      "z": -6,
      "name": "Rock_Quartzite_Brick"
    },
    {
      "x": -4,
      "y": 7,
      "z": -6,
      "name": "Rock_Quartzite"
    },
    {
      "x": -4,
      "y": 8,
      "z": -6,
      "name": "Rock_Quartzite"
    },
    {
      "x": -4,
      "y": 4,
      "z": -5,
      "name": "Rock_Quartzite"
    },
    {
      "x": -4,
      "y": 5,
      "z": -5,
      "name": "Rock_Quartzite"
    },
    {
      "x": -4,
      "y": 6,
      "z": -5,
      "name": "Rock_Quartzite"
    },
    {
      "x": -4,
      "y": 7,
      "z": -5,
      "name": "Rock_Quartzite"
    },
    {
      "x": -4,
      "y": 8,
      "z": -5,
      "name": "Rock_Quartzite"
    },
    {
      "x": -4,
      "y": 9,
      "z": -5,
      "name": "Rock_Quartzite"
    },
    {
      "x": -4,
      "y": 5,
      "z": -4,
      "name": "Rock_Quartzite"
    },
    {
      "x": -4,
      "y": 6,
      "z": -4,
      "name": "Rock_Quartzite"
    },
    {
      "x": -4,
      "y": 7,
      "z": -4,
      "name": "Rock_Quartzite"
    },
    {
      "x": -4,
      "y": 10,
      "z": -4,
      "name": "Rock_Stone"
    },
    {
      "x": -4,
      "y": 6,
      "z": -3,
      "name": "Rock_Stone"
    },
    {
      "x": -4,
      "y": 10,
      "z": -3,
      "name": "Rock_Stone"
    },
    {
      "x": -4,
      "y": 11,
      "z": -3,
      "name": "Rock_Quartzite_Brick"
    },
    {
      "x": -4,
      "y": 6,
      "z": -2,
      "name": "Rock_Stone"
    },
    {
      "x": -4,
      "y": 7,
      "z": -2,
      "name": "Rock_Quartzite"
    },
    {
      "x": -4,
      "y": 9,
      "z": -2,
      "name": "Rock_Stone"
    },
    {
      "x": -4,
      "y": 10,
      "z": -2,
      "name": "Rock_Stone"
    },
    {
      "x": -4,
      "y": 11,
      "z": -2,
      "name": "Rock_Quartzite"
    },
    {
      "x": -4,
      "y": 12,
      "z": -2,
      "name": "Rock_Quartzite"
    },
    {
      "x": -4,
      "y": 7,
      "z": -1,
      "name": "Rock_Stone"
    },
    {
      "x": -4,
      "y": 8,
      "z": -1,
      "name": "Rock_Stone"
    },
    {
      "x": -4,
      "y": 9,
      "z": -1,
      "name": "Rock_Quartzite"
    },
    {
      "x": -4,
      "y": 10,
      "z": -1,
      "name": "Rock_Quartzite"
    },
    {
      "x": -4,
      "y": 11,
      "z": -1,
      "name": "Rock_Quartzite"
    },
    {
      "x": -4,
      "y": 12,
      "z": -1,
      "name": "Rock_Quartzite"
    },
    {
      "x": -4,
      "y": 9,
      "z": 0,
      "name": "Rock_Quartzite"
    },
    {
      "x": -4,
      "y": 10,
      "z": 0,
      "name": "Rock_Quartzite"
    },
    {
      "x": -4,
      "y": 11,
      "z": 0,
      "name": "Rock_Quartzite"
    },
    {
      "x": -4,
      "y": 12,
      "z": 0,
      "name": "Rock_Quartzite"
    },
    {
      "x": -4,
      "y": 10,
      "z": 1,
      "name": "Rock_Quartzite"
    },
    {
      "x": -4,
      "y": 11,
      "z": 1,
      "name": "Rock_Quartzite"
    },
    {
      "x": -4,
      "y": 12,
      "z": 1,
      "name": "Rock_Quartzite"
    },
    {
      "x": -4,
      "y": 11,
      "z": 2,
      "name": "Rock_Quartzite"
    },
    {
      "x": -3,
      "y": 0,
      "z": -10,
      "name": "Rock_Quartzite"
    },
    {
      "x": -3,
      "y": 1,
      "z": -10,
      "name": "Rock_Quartzite"
    },
    {
      "x": -3,
      "y": 2,
      "z": -10,
      "name": "Rock_Quartzite"
    },
    {
      "x": -3,
      "y": 3,
      "z": -10,
      "name": "Rock_Quartzite_Brick"
    },
    {
      "x": -3,
      "y": 4,
      "z": -10,
      "name": "Rock_Quartzite_Brick"
    },
    {
      "x": -3,
      "y": 5,
      "z": -10,
      "name": "Rock_Quartzite_Brick"
    },
    {
      "x": -3,
      "y": 0,
      "z": -9,
      "name": "Rock_Quartzite"
    },
    {
      "x": -3,
      "y": 1,
      "z": -9,
      "name": "Rock_Quartzite"
    },
    {
      "x": -3,
      "y": 2,
      "z": -9,
      "name": "Rock_Quartzite"
    },
    {
      "x": -3,
      "y": 3,
      "z": -9,
      "name": "Rock_Quartzite"
    },
    {
      "x": -3,
      "y": 4,
      "z": -9,
      "name": "Empty"
    },
    {
      "x": -3,
      "y": 5,
      "z": -9,
      "name": "Rock_Quartzite_Brick"
    },
    {
      "x": -3,
      "y": 6,
      "z": -9,
      "name": "Rock_Quartzite_Brick"
    },
    {
      "x": -3,
      "y": 1,
      "z": -8,
      "name": "Rock_Quartzite"
    },
    {
      "x": -3,
      "y": 2,
      "z": -8,
      "name": "Rock_Quartzite"
    },
    {
      "x": -3,
      "y": 3,
      "z": -8,
      "name": "Empty"
    },
    {
      "x": -3,
      "y": 4,
      "z": -8,
      "name": "Empty"
    },
    {
      "x": -3,
      "y": 5,
      "z": -8,
      "name": "Empty"
    },
    {
      "x": -3,
      "y": 6,
      "z": -8,
      "name": "Rock_Quartzite_Brick"
    },
    {
      "x": -3,
      "y": 7,
      "z": -8,
      "name": "Rock_Quartzite_Brick"
    },
    {
      "x": -3,
      "y": 1,
      "z": -7,
      "name": "Rock_Quartzite"
    },
    {
      "x": -3,
      "y": 2,
      "z": -7,
      "name": "Empty"
    },
    {
      "x": -3,
      "y": 3,
      "z": -7,
      "name": "Empty"
    },
    {
      "x": -3,
      "y": 4,
      "z": -7,
      "name": "Empty"
    },
    {
      "x": -3,
      "y": 5,
      "z": -7,
      "name": "Rock_Quartzite_Brick"
    },
    {
      "x": -3,
      "y": 6,
      "z": -7,
      "name": "Rock_Quartzite_Brick"
    },
    {
      "x": -3,
      "y": 7,
      "z": -7,
      "name": "Rock_Quartzite_Brick"
    },
    {
      "x": -3,
      "y": 8,
      "z": -7,
      "name": "Rock_Quartzite"
    },
    {
      "x": -3,
      "y": 2,
      "z": -6,
      "name": "Rock_Quartzite"
    },
    {
      "x": -3,
      "y": 3,
      "z": -6,
      "name": "Empty"
    },
    {
      "x": -3,
      "y": 4,
      "z": -6,
      "name": "Empty"
    },
    {
      "x": -3,
      "y": 5,
      "z": -6,
      "name": "Rock_Quartzite"
    },
    {
      "x": -3,
      "y": 6,
      "z": -6,
      "name": "Rock_Quartzite"
    },
    {
      "x": -3,
      "y": 7,
      "z": -6,
      "name": "Rock_Quartzite"
    },
    {
      "x": -3,
      "y": 8,
      "z": -6,
      "name": "Rock_Quartzite"
    },
    {
      "x": -3,
      "y": 9,
      "z": -6,
      "name": "Rock_Quartzite"
    },
    {
      "x": -3,
      "y": 3,
      "z": -5,
      "name": "Rock_Quartzite"
    },
    {
      "x": -3,
      "y": 4,
      "z": -5,
      "name": "Rock_Quartzite"
    },
    {
      "x": -3,
      "y": 5,
      "z": -5,
      "name": "Rock_Quartzite"
    },
    {
      "x": -3,
      "y": 6,
      "z": -5,
      "name": "Empty"
    },
    {
      "x": -3,
      "y": 7,
      "z": -5,
      "name": "Rock_Quartzite"
    },
    {
      "x": -3,
      "y": 8,
      "z": -5,
      "name": "Rock_Quartzite"
    },
    {
      "x": -3,
      "y": 9,
      "z": -5,
      "name": "Rock_Quartzite"
    },
    {
      "x": -3,
      "y": 10,
      "z": -5,
      "name": "Rock_Quartzite_Brick"
    },
    {
      "x": -3,
      "y": 4,
      "z": -4,
      "name": "Rock_Quartzite"
    },
    {
      "x": -3,
      "y": 5,
      "z": -4,
      "name": "Rock_Quartzite"
    },
    {
      "x": -3,
      "y": 6,
      "z": -4,
      "name": "Rock_Quartzite"
    },
    {
      "x": -3,
      "y": 7,
      "z": -4,
      "name": "Empty"
    },
    {
      "x": -3,
      "y": 8,
      "z": -4,
      "name": "Empty"
    },
    {
      "x": -3,
      "y": 9,
      "z": -4,
      "name": "Rock_Quartzite_Brick"
    },
    {
      "x": -3,
      "y": 10,
      "z": -4,
      "name": "Rock_Quartzite_Brick"
    },
    {
      "x": -3,
      "y": 11,
      "z": -4,
      "name": "Rock_Quartzite_Brick"
    },
    {
      "x": -3,
      "y": 6,
      "z": -3,
      "name": "Rock_Quartzite"
    },
    {
      "x": -3,
      "y": 7,
      "z": -3,
      "name": "Rubble_Stone"
    },
    {
      "x": -3,
      "y": 8,
      "z": -3,
      "name": "Empty"
    },
    {
      "x": -3,
      "y": 9,
      "z": -3,
      "name": "Empty"
    },
    {
      "x": -3,
      "y": 10,
      "z": -3,
      "name": "Rock_Quartzite_Brick"
    },
    {
      "x": -3,
      "y": 11,
      "z": -3,
      "name": "Rock_Quartzite_Brick"
    },
    {
      "x": -3,
      "y": 12,
      "z": -3,
      "name": "Rock_Quartzite_Brick"
    },
    {
      "x": -3,
      "y": 6,
      "z": -2,
      "name": "Rock_Quartzite"
    },
    {
      "x": -3,
      "y": 7,
      "z": -2,
      "name": "Empty"
    },
    {
      "x": -3,
      "y": 8,
      "z": -2,
      "name": "Empty"
    },
    {
      "x": -3,
      "y": 9,
      "z": -2,
      "name": "Empty"
    },
    {
      "x": -3,
      "y": 10,
      "z": -2,
      "name": "Empty"
    },
    {
      "x": -3,
      "y": 11,
      "z": -2,
      "name": "Rock_Quartzite_Brick"
    },
    {
      "x": -3,
      "y": 12,
      "z": -2,
      "name": "Rock_Quartzite"
    },
    {
      "x": -3,
      "y": 13,
      "z": -2,
      "name": "Rock_Quartzite"
    },
    {
      "x": -3,
      "y": 7,
      "z": -1,
      "name": "Rock_Quartzite"
    },
    {
      "x": -3,
      "y": 8,
      "z": -1,
      "name": "Rock_Quartzite"
    },
    {
      "x": -3,
      "y": 9,
      "z": -1,
      "name": "Rock_Quartzite"
    },
    {
      "x": -3,
      "y": 10,
      "z": -1,
      "name": "Empty"
    },
    {
      "x": -3,
      "y": 11,
      "z": -1,
      "name": "Rock_Quartzite"
    },
    {
      "x": -3,
      "y": 12,
      "z": -1,
      "name": "Rock_Quartzite"
    },
    {
      "x": -3,
      "y": 13,
      "z": -1,
      "name": "Rock_Quartzite"
    },
    {
      "x": -3,
      "y": 7,
      "z": 0,
      "name": "Rock_Quartzite"
    },
    {
      "x": -3,
      "y": 8,
      "z": 0,
      "name": "Rock_Quartzite"
    },
    {
      "x": -3,
      "y": 9,
      "z": 0,
      "name": "Rock_Stone_Cobble"
    },
    {
      "x": -3,
      "y": 10,
      "z": 0,
      "name": "Rock_Quartzite"
    },
    {
      "x": -3,
      "y": 11,
      "z": 0,
      "name": "Rock_Quartzite"
    },
    {
      "x": -3,
      "y": 12,
      "z": 0,
      "name": "Rock_Quartzite"
    },
    {
      "x": -3,
      "y": 13,
      "z": 0,
      "name": "Rock_Quartzite"
    },
    {
      "x": -3,
      "y": 9,
      "z": 1,
      "name": "Rock_Quartzite"
    },
    {
      "x": -3,
      "y": 10,
      "z": 1,
      "name": "Rock_Stone_Cobble"
    },
    {
      "x": -3,
      "y": 11,
      "z": 1,
      "name": "Rock_Stone_Cobble"
    },
    {
      "x": -3,
      "y": 12,
      "z": 1,
      "name": "Rock_Quartzite"
    },
    {
      "x": -3,
      "y": 13,
      "z": 1,
      "name": "Empty"
    },
    {
      "x": -3,
      "y": 10,
      "z": 2,
      "name": "Rock_Quartzite"
    },
    {
      "x": -3,
      "y": 11,
      "z": 2,
      "name": "Rock_Stone_Cobble"
    },
    {
      "x": -3,
      "y": 12,
      "z": 2,
      "name": "Rock_Stone_Cobble"
    },
    {
      "x": -3,
      "y": 13,
      "z": 2,
      "name": "Empty"
    },
    {
      "x": -3,
      "y": 11,
      "z": 3,
      "name": "Rock_Quartzite"
    },
    {
      "x": -3,
      "y": 12,
      "z": 3,
      "name": "Rock_Stone_Cobble"
    },
    {
      "x": -3,
      "y": 13,
      "z": 3,
      "name": "Rock_Quartzite"
    },
    {
      "x": -3,
      "y": 13,
      "z": 4,
      "name": "Rock_Quartzite"
    },
    {
      "x": -3,
      "y": 13,
      "z": 5,
      "name": "Rock_Stone_Cobble"
    },
    {
      "x": -2,
      "y": 0,
      "z": -10,
      "name": "Rock_Stone_Cobble"
    },
    {
      "x": -2,
      "y": 1,
      "z": -10,
      "name": "Empty"
    },
    {
      "x": -2,
      "y": 2,
      "z": -10,
      "name": "Empty"
    },
    {
      "x": -2,
      "y": 3,
      "z": -10,
      "name": "Empty"
    },
    {
      "x": -2,
      "y": 4,
      "z": -10,
      "name": "Empty"
    },
    {
      "x": -2,
      "y": 5,
      "z": -10,
      "name": "Rock_Quartzite_Brick"
    },
    {
      "x": -2,
      "y": 0,
      "z": -9,
      "name": "Rock_Stone_Cobble"
    },
    {
      "x": -2,
      "y": 1,
      "z": -9,
      "name": "Rock_Stone_Cobble_Half"
    },
    {
      "x": -2,
      "y": 2,
      "z": -9,
      "name": "Empty"
    },
    {
      "x": -2,
      "y": 3,
      "z": -9,
      "name": "Empty"
    },
    {
      "x": -2,
      "y": 4,
      "z": -9,
      "name": "Empty"
    },
    {
      "x": -2,
      "y": 5,
      "z": -9,
      "name": "Empty"
    },
    {
      "x": -2,
      "y": 6,
      "z": -9,
      "name": "Rock_Quartzite_Brick"
    },
    {
      "x": -2,
      "y": 7,
      "z": -9,
      "name": "Rock_Quartzite"
    },
    {
      "x": -2,
      "y": 0,
      "z": -8,
      "name": "Rock_Stone_Cobble"
    },
    {
      "x": -2,
      "y": 1,
      "z": -8,
      "name": "Rock_Stone_Cobble"
    },
    {
      "x": -2,
      "y": 2,
      "z": -8,
      "name": "Rock_Stone_Cobble_Stairs",
      "rotation": 2
    },
    {
      "x": -2,
      "y": 3,
      "z": -8,
      "name": "Empty"
    },
    {
      "x": -2,
      "y": 4,
      "z": -8,
      "name": "Empty"
    },
    {
      "x": -2,
      "y": 5,
      "z": -8,
      "name": "Empty"
    },
    {
      "x": -2,
      "y": 6,
      "z": -8,
      "name": "Empty"
    },
    {
      "x": -2,
      "y": 7,
      "z": -8,
      "name": "Rock_Quartzite"
    },
    {
      "x": -2,
      "y": 8,
      "z": -8,
      "name": "Rock_Quartzite"
    },
    {
      "x": -2,
      "y": 1,
      "z": -7,
      "name": "Rock_Stone_Cobble"
    },
    {
      "x": -2,
      "y": 2,
      "z": -7,
      "name": "Rock_Stone_Cobble"
    },
    {
      "x": -2,
      "y": 3,
      "z": -7,
      "name": "Rock_Stone_Cobble_Stairs",
      "rotation": 2
    },
    {
      "x": -2,
      "y": 4,
      "z": -7,
      "name": "Empty"
    },
    {
      "x": -2,
      "y": 5,
      "z": -7,
      "name": "Empty"
    },
    {
      "x": -2,
      "y": 6,
      "z": -7,
      "name": "Empty"
    },
    {
      "x": -2,
      "y": 7,
      "z": -7,
      "name": "Empty"
    },
    {
      "x": -2,
      "y": 8,
      "z": -7,
      "name": "Rock_Quartzite"
    },
    {
      "x": -2,
      "y": 2,
      "z": -6,
      "name": "Rock_Stone_Cobble"
    },
    {
      "x": -2,
      "y": 3,
      "z": -6,
      "name": "Rock_Stone_Cobble"
    },
    {
      "x": -2,
      "y": 4,
      "z": -6,
      "name": "Rock_Stone_Cobble_Stairs",
      "rotation": 2
    },
    {
      "x": -2,
      "y": 5,
      "z": -6,
      "name": "Empty"
    },
    {
      "x": -2,
      "y": 6,
      "z": -6,
      "name": "Wood_Torch_Wall",
      "rotation": 1
    },
    {
      "x": -2,
      "y": 7,
      "z": -6,
      "name": "Empty"
    },
    {
      "x": -2,
      "y": 8,
      "z": -6,
      "name": "Empty"
    },
    {
      "x": -2,
      "y": 9,
      "z": -6,
      "name": "Rock_Quartzite"
    },
    {
      "x": -2,
      "y": 10,
      "z": -6,
      "name": "Rock_Quartzite"
    },
    {
      "x": -2,
      "y": 3,
      "z": -5,
      "name": "Rock_Stone_Cobble"
    },
    {
      "x": -2,
      "y": 4,
      "z": -5,
      "name": "Rock_Stone_Cobble"
    },
    {
      "x": -2,
      "y": 5,
      "z": -5,
      "name": "Empty"
    },
    {
      "x": -2,
      "y": 6,
      "z": -5,
      "name": "Empty"
    },
    {
      "x": -2,
      "y": 7,
      "z": -5,
      "name": "Empty"
    },
    {
      "x": -2,
      "y": 8,
      "z": -5,
      "name": "Empty"
    },
    {
      "x": -2,
      "y": 9,
      "z": -5,
      "name": "Wood_Beech_Trunk_Full"
    },
    {
      "x": -2,
      "y": 10,
      "z": -5,
      "name": "Wood_Beech_Trunk_Full"
    },
    {
      "x": -2,
      "y": 11,
      "z": -5,
      "name": "Wood_Beech_Trunk_Full"
    },
    {
      "x": -2,
      "y": 4,
      "z": -4,
      "name": "Rock_Stone_Cobble"
    },
    {
      "x": -2,
      "y": 5,
      "z": -4,
      "name": "Rock_Stone_Cobble_Stairs",
      "rotation": 2
    },
    {
      "x": -2,
      "y": 6,
      "z": -4,
      "name": "Empty"
    },
    {
      "x": -2,
      "y": 7,
      "z": -4,
      "name": "Empty"
    },
    {
      "x": -2,
      "y": 8,
      "z": -4,
      "name": "Empty"
    },
    {
      "x": -2,
      "y": 9,
      "z": -4,
      "name": "Empty"
    },
    {
      "x": -2,
      "y": 10,
      "z": -4,
      "name": "Rock_Quartzite_Brick"
    },
    {
      "x": -2,
      "y": 11,
      "z": -4,
      "name": "Rock_Quartzite_Brick"
    },
    {
      "x": -2,
      "y": 12,
      "z": -4,
      "name": "Rock_Quartzite_Brick"
    },
    {
      "x": -2,
      "y": 5,
      "z": -3,
      "name": "Rock_Stone_Cobble"
    },
    {
      "x": -2,
      "y": 6,
      "z": -3,
      "name": "Rock_Stone_Cobble_Stairs",
      "rotation": 2
    },
    {
      "x": -2,
      "y": 7,
      "z": -3,
      "name": "Empty"
    },
    {
      "x": -2,
      "y": 8,
      "z": -3,
      "name": "Empty"
    },
    {
      "x": -2,
      "y": 9,
      "z": -3,
      "name": "Empty"
    },
    {
      "x": -2,
      "y": 10,
      "z": -3,
      "name": "Empty"
    },
    {
      "x": -2,
      "y": 11,
      "z": -3,
      "name": "Rock_Quartzite_Brick"
    },
    {
      "x": -2,
      "y": 12,
      "z": -3,
      "name": "Rock_Quartzite_Brick"
    },
    {
      "x": -2,
      "y": 6,
      "z": -2,
      "name": "Rock_Quartzite"
    },
    {
      "x": -2,
      "y": 7,
      "z": -2,
      "name": "Rubble_Stone_Medium"
    },
    {
      "x": -2,
      "y": 8,
      "z": -2,
      "name": "Empty"
    },
    {
      "x": -2,
      "y": 9,
      "z": -2,
      "name": "Empty"
    },
    {
      "x": -2,
      "y": 10,
      "z": -2,
      "name": "Empty"
    },
    {
      "x": -2,
      "y": 11,
      "z": -2,
      "name": "Empty"
    },
    {
      "x": -2,
      "y": 12,
      "z": -2,
      "name": "Rock_Quartzite"
    },
    {
      "x": -2,
      "y": 13,
      "z": -2,
      "name": "Rock_Quartzite"
    },
    {
      "x": -2,
      "y": 7,
      "z": -1,
      "name": "Rock_Quartzite"
    },
    {
      "x": -2,
      "y": 8,
      "z": -1,
      "name": "Rubble_Stone"
    },
    {
      "x": -2,
      "y": 9,
      "z": -1,
      "name": "Empty"
    },
    {
      "x": -2,
      "y": 10,
      "z": -1,
      "name": "Empty"
    },
    {
      "x": -2,
      "y": 11,
      "z": -1,
      "name": "Empty"
    },
    {
      "x": -2,
      "y": 12,
      "z": -1,
      "name": "Empty"
    },
    {
      "x": -2,
      "y": 13,
      "z": -1,
      "name": "Empty"
    },
    {
      "x": -2,
      "y": 8,
      "z": 0,
      "name": "Rock_Quartzite"
    },
    {
      "x": -2,
      "y": 9,
      "z": 0,
      "name": "Empty"
    },
    {
      "x": -2,
      "y": 10,
      "z": 0,
      "name": "Empty"
    },
    {
      "x": -2,
      "y": 11,
      "z": 0,
      "name": "Empty"
    },
    {
      "x": -2,
      "y": 12,
      "z": 0,
      "name": "Empty"
    },
    {
      "x": -2,
      "y": 13,
      "z": 0,
      "name": "Empty"
    },
    {
      "x": -2,
      "y": 14,
      "z": 0,
      "name": "Empty"
    },
    {
      "x": -2,
      "y": 9,
      "z": 1,
      "name": "Rock_Stone_Cobble"
    },
    {
      "x": -2,
      "y": 10,
      "z": 1,
      "name": "Rock_Stone_Cobble_Half"
    },
    {
      "x": -2,
      "y": 11,
      "z": 1,
      "name": "Empty"
    },
    {
      "x": -2,
      "y": 12,
      "z": 1,
      "name": "Empty"
    },
    {
      "x": -2,
      "y": 13,
      "z": 1,
      "name": "Empty"
    },
    {
      "x": -2,
      "y": 14,
      "z": 1,
      "name": "Empty"
    },
    {
      "x": -2,
      "y": 15,
      "z": 1,
      "name": "Empty"
    },
    {
      "x": -2,
      "y": 10,
      "z": 2,
      "name": "Rock_Stone_Cobble"
    },
    {
      "x": -2,
      "y": 11,
      "z": 2,
      "name": "Empty"
    },
    {
      "x": -2,
      "y": 12,
      "z": 2,
      "name": "Empty"
    },
    {
      "x": -2,
      "y": 13,
      "z": 2,
      "name": "Empty"
    },
    {
      "x": -2,
      "y": 14,
      "z": 2,
      "name": "Empty"
    },
    {
      "x": -2,
      "y": 15,
      "z": 2,
      "name": "Empty"
    },
    {
      "x": -2,
      "y": 16,
      "z": 2,
      "name": "Empty"
    },
    {
      "x": -2,
      "y": 11,
      "z": 3,
      "name": "Rock_Stone_Cobble"
    },
    {
      "x": -2,
      "y": 12,
      "z": 3,
      "name": "Rock_Stone_Cobble_Half"
    },
    {
      "x": -2,
      "y": 13,
      "z": 3,
      "name": "Empty"
    },
    {
      "x": -2,
      "y": 14,
      "z": 3,
      "name": "Empty"
    },
    {
      "x": -2,
      "y": 15,
      "z": 3,
      "name": "Empty"
    },
    {
      "x": -2,
      "y": 16,
      "z": 3,
      "name": "Empty"
    },
    {
      "x": -2,
      "y": 17,
      "z": 3,
      "name": "Empty"
    },
    {
      "x": -2,
      "y": 12,
      "z": 4,
      "name": "Rock_Stone_Cobble"
    },
    {
      "x": -2,
      "y": 13,
      "z": 4,
      "name": "Rock_Stone_Cobble_Stairs",
      "rotation": 2
    },
    {
      "x": -2,
      "y": 14,
      "z": 4,
      "name": "Empty"
    },
    {
      "x": -2,
      "y": 15,
      "z": 4,
      "name": "Empty"
    },
    {
      "x": -2,
      "y": 16,
      "z": 4,
      "name": "Empty"
    },
    {
      "x": -2,
      "y": 17,
      "z": 4,
      "name": "Empty"
    },
    {
      "x": -2,
      "y": 18,
      "z": 4,
      "name": "Empty"
    },
    {
      "x": -2,
      "y": 13,
      "z": 5,
      "name": "Rock_Stone_Cobble"
    },
    {
      "x": -2,
      "y": 14,
      "z": 5,
      "name": "Rock_Stone_Cobble_Stairs",
      "rotation": 2
    },
    {
      "x": -2,
      "y": 15,
      "z": 5,
      "name": "Empty"
    },
    {
      "x": -2,
      "y": 16,
      "z": 5,
      "name": "Empty"
    },
    {
      "x": -2,
      "y": 17,
      "z": 5,
      "name": "Empty"
    },
    {
      "x": -2,
      "y": 18,
      "z": 5,
      "name": "Empty"
    },
    {
      "x": -2,
      "y": 13,
      "z": 6,
      "name": "Rock_Stone_Cobble"
    },
    {
      "x": -2,
      "y": 14,
      "z": 6,
      "name": "Rock_Stone_Cobble"
    },
    {
      "x": -2,
      "y": 15,
      "z": 6,
      "name": "Rock_Stone_Cobble_Stairs",
      "rotation": 2
    },
    {
      "x": -2,
      "y": 16,
      "z": 6,
      "name": "Empty"
    },
    {
      "x": -2,
      "y": 17,
      "z": 6,
      "name": "Empty"
    },
    {
      "x": -2,
      "y": 18,
      "z": 6,
      "name": "Empty"
    },
    {
      "x": -2,
      "y": 13,
      "z": 7,
      "name": "Rock_Quartzite_Brick"
    },
    {
      "x": -2,
      "y": 14,
      "z": 7,
      "name": "Rock_Quartzite_Brick"
    },
    {
      "x": -2,
      "y": 15,
      "z": 7,
      "name": "Rock_Stone_Cobble"
    },
    {
      "x": -2,
      "y": 16,
      "z": 7,
      "name": "Rock_Stone_Cobble_Half",
      "rotation": 6
    },
    {
      "x": -2,
      "y": 17,
      "z": 7,
      "name": "Empty"
    },
    {
      "x": -2,
      "y": 18,
      "z": 7,
      "name": "Empty"
    },
    {
      "x": -2,
      "y": 13,
      "z": 8,
      "name": "Rock_Quartzite_Brick"
    },
    {
      "x": -2,
      "y": 14,
      "z": 8,
      "name": "Rock_Quartzite_Brick"
    },
    {
      "x": -2,
      "y": 15,
      "z": 8,
      "name": "Rock_Quartzite_Brick"
    },
    {
      "x": -2,
      "y": 16,
      "z": 8,
      "name": "Rock_Stone_Cobble"
    },
    {
      "x": -2,
      "y": 17,
      "z": 8,
      "name": "Rock_Stone_Cobble_Stairs",
      "rotation": 2
    },
    {
      "x": -2,
      "y": 18,
      "z": 8,
      "name": "Empty"
    },
    {
      "x": -2,
      "y": 13,
      "z": 9,
      "name": "Rock_Quartzite_Brick"
    },
    {
      "x": -2,
      "y": 14,
      "z": 9,
      "name": "Rock_Quartzite_Brick"
    },
    {
      "x": -2,
      "y": 15,
      "z": 9,
      "name": "Rock_Quartzite_Brick"
    },
    {
      "x": -2,
      "y": 16,
      "z": 9,
      "name": "Rock_Quartzite_Brick"
    },
    {
      "x": -2,
      "y": 17,
      "z": 9,
      "name": "Rock_Stone_Cobble"
    },
    {
      "x": -2,
      "y": 18,
      "z": 9,
      "name": "Rock_Stone_Cobble_Stairs",
      "rotation": 2
    },
    {
      "x": -2,
      "y": 14,
      "z": 10,
      "name": "Rock_Quartzite_Brick"
    },
    {
      "x": -2,
      "y": 15,
      "z": 10,
      "name": "Rock_Quartzite_Brick"
    },
    {
      "x": -2,
      "y": 16,
      "z": 10,
      "name": "Rock_Quartzite_Brick"
    },
    {
      "x": -2,
      "y": 17,
      "z": 10,
      "name": "Rock_Quartzite_Brick"
    },
    {
      "x": -2,
      "y": 18,
      "z": 10,
      "name": "Rock_Stone_Cobble"
    },
    {
      "x": -1,
      "y": 0,
      "z": -10,
      "name": "Rock_Stone_Cobble"
    },
    {
      "x": -1,
      "y": 1,
      "z": -10,
      "name": "Empty"
    },
    {
      "x": -1,
      "y": 2,
      "z": -10,
      "name": "Empty"
    },
    {
      "x": -1,
      "y": 3,
      "z": -10,
      "name": "Empty"
    },
    {
      "x": -1,
      "y": 4,
      "z": -10,
      "name": "Empty"
    },
    {
      "x": -1,
      "y": 5,
      "z": -10,
      "name": "Empty"
    },
    {
      "x": -1,
      "y": 0,
      "z": -9,
      "name": "Rock_Stone_Cobble"
    },
    {
      "x": -1,
      "y": 1,
      "z": -9,
      "name": "Rock_Stone_Cobble_Stairs",
      "rotation": 2
    },
    {
      "x": -1,
      "y": 2,
      "z": -9,
      "name": "Empty"
    },
    {
      "x": -1,
      "y": 3,
      "z": -9,
      "name": "Empty"
    },
    {
      "x": -1,
      "y": 4,
      "z": -9,
      "name": "Empty"
    },
    {
      "x": -1,
      "y": 5,
      "z": -9,
      "name": "Empty"
    },
    {
      "x": -1,
      "y": 6,
      "z": -9,
      "name": "Empty"
    },
    {
      "x": -1,
      "y": 0,
      "z": -8,
      "name": "Rock_Stone_Cobble"
    },
    {
      "x": -1,
      "y": 1,
      "z": -8,
      "name": "Rock_Stone_Cobble"
    },
    {
      "x": -1,
      "y": 2,
      "z": -8,
      "name": "Rock_Stone_Cobble_Stairs",
      "rotation": 2
    },
    {
      "x": -1,
      "y": 3,
      "z": -8,
      "name": "Empty"
    },
    {
      "x": -1,
      "y": 4,
      "z": -8,
      "name": "Empty"
    },
    {
      "x": -1,
      "y": 5,
      "z": -8,
      "name": "Empty"
    },
    {
      "x": -1,
      "y": 6,
      "z": -8,
      "name": "Empty"
    },
    {
      "x": -1,
      "y": 7,
      "z": -8,
      "name": "Empty"
    },
    {
      "x": -1,
      "y": 0,
      "z": -7,
      "name": "Rock_Stone_Cobble"
    },
    {
      "x": -1,
      "y": 1,
      "z": -7,
      "name": "Rock_Stone_Cobble"
    },
    {
      "x": -1,
      "y": 2,
      "z": -7,
      "name": "Rock_Stone_Cobble"
    },
    {
      "x": -1,
      "y": 3,
      "z": -7,
      "name": "Rock_Stone_Cobble_Stairs",
      "rotation": 2
    },
    {
      "x": -1,
      "y": 4,
      "z": -7,
      "name": "Empty"
    },
    {
      "x": -1,
      "y": 5,
      "z": -7,
      "name": "Empty"
    },
    {
      "x": -1,
      "y": 6,
      "z": -7,
      "name": "Empty"
    },
    {
      "x": -1,
      "y": 7,
      "z": -7,
      "name": "Empty"
    },
    {
      "x": -1,
      "y": 8,
      "z": -7,
      "name": "Wood_Beech_Trunk_Full"
    },
    {
      "x": -1,
      "y": 9,
      "z": -7,
      "name": "Wood_Beech_Trunk_Full"
    },
    {
      "x": -1,
      "y": 1,
      "z": -6,
      "name": "Rock_Stone_Cobble"
    },
    {
      "x": -1,
      "y": 2,
      "z": -6,
      "name": "Rock_Stone_Cobble"
    },
    {
      "x": -1,
      "y": 3,
      "z": -6,
      "name": "Rock_Stone_Cobble"
    },
    {
      "x": -1,
      "y": 4,
      "z": -6,
      "name": "Rock_Stone_Cobble_Stairs",
      "rotation": 2
    },
    {
      "x": -1,
      "y": 5,
      "z": -6,
      "name": "Empty"
    },
    {
      "x": -1,
      "y": 6,
      "z": -6,
      "name": "Empty"
    },
    {
      "x": -1,
      "y": 7,
      "z": -6,
      "name": "Empty"
    },
    {
      "x": -1,
      "y": 8,
      "z": -6,
      "name": "Empty"
    },
    {
      "x": -1,
      "y": 9,
      "z": -6,
      "name": "Empty"
    },
    {
      "x": -1,
      "y": 3,
      "z": -5,
      "name": "Rock_Stone_Cobble"
    },
    {
      "x": -1,
      "y": 4,
      "z": -5,
      "name": "Rock_Stone_Cobble"
    },
    {
      "x": -1,
      "y": 5,
      "z": -5,
      "name": "Empty"
    },
    {
      "x": -1,
      "y": 6,
      "z": -5,
      "name": "Empty"
    },
    {
      "x": -1,
      "y": 7,
      "z": -5,
      "name": "Empty"
    },
    {
      "x": -1,
      "y": 8,
      "z": -5,
      "name": "Empty"
    },
    {
      "x": -1,
      "y": 9,
      "z": -5,
      "name": "Empty"
    },
    {
      "x": -1,
      "y": 10,
      "z": -5,
      "name": "Rock_Quartzite"
    },
    {
      "x": -1,
      "y": 11,
      "z": -5,
      "name": "Wood_Beech_Trunk_Full"
    },
    {
      "x": -1,
      "y": 4,
      "z": -4,
      "name": "Rock_Stone_Cobble"
    },
    {
      "x": -1,
      "y": 5,
      "z": -4,
      "name": "Rock_Stone_Cobble_Stairs",
      "rotation": 2
    },
    {
      "x": -1,
      "y": 6,
      "z": -4,
      "name": "Empty"
    },
    {
      "x": -1,
      "y": 7,
      "z": -4,
      "name": "Empty"
    },
    {
      "x": -1,
      "y": 8,
      "z": -4,
      "name": "Empty"
    },
    {
      "x": -1,
      "y": 9,
      "z": -4,
      "name": "Empty"
    },
    {
      "x": -1,
      "y": 10,
      "z": -4,
      "name": "Empty"
    },
    {
      "x": -1,
      "y": 11,
      "z": -4,
      "name": "Rock_Quartzite_Brick"
    },
    {
      "x": -1,
      "y": 12,
      "z": -4,
      "name": "Rock_Quartzite_Brick"
    },
    {
      "x": -1,
      "y": 4,
      "z": -3,
      "name": "Rock_Stone_Cobble"
    },
    {
      "x": -1,
      "y": 5,
      "z": -3,
      "name": "Rock_Stone_Cobble"
    },
    {
      "x": -1,
      "y": 6,
      "z": -3,
      "name": "Empty"
    },
    {
      "x": -1,
      "y": 7,
      "z": -3,
      "name": "Empty"
    },
    {
      "x": -1,
      "y": 8,
      "z": -3,
      "name": "Empty"
    },
    {
      "x": -1,
      "y": 9,
      "z": -3,
      "name": "Empty"
    },
    {
      "x": -1,
      "y": 10,
      "z": -3,
      "name": "Empty"
    },
    {
      "x": -1,
      "y": 11,
      "z": -3,
      "name": "Rock_Quartzite_Brick"
    },
    {
      "x": -1,
      "y": 12,
      "z": -3,
      "name": "Rock_Quartzite_Brick"
    },
    {
      "x": -1,
      "y": 13,
      "z": -3,
      "name": "Rock_Quartzite_Brick"
    },
    {
      "x": -1,
      "y": 5,
      "z": -2,
      "name": "Rock_Stone_Cobble"
    },
    {
      "x": -1,
      "y": 6,
      "z": -2,
      "name": "Empty"
    },
    {
      "x": -1,
      "y": 7,
      "z": -2,
      "name": "Empty"
    },
    {
      "x": -1,
      "y": 8,
      "z": -2,
      "name": "Empty"
    },
    {
      "x": -1,
      "y": 9,
      "z": -2,
      "name": "Empty"
    },
    {
      "x": -1,
      "y": 10,
      "z": -2,
      "name": "Empty"
    },
    {
      "x": -1,
      "y": 11,
      "z": -2,
      "name": "Empty"
    },
    {
      "x": -1,
      "y": 12,
      "z": -2,
      "name": "Rock_Quartzite_Brick"
    },
    {
      "x": -1,
      "y": 13,
      "z": -2,
      "name": "Rock_Quartzite"
    },
    {
      "x": -1,
      "y": 5,
      "z": -1,
      "name": "Rock_Stone"
    },
    {
      "x": -1,
      "y": 6,
      "z": -1,
      "name": "Rock_Stone"
    },
    {
      "x": -1,
      "y": 7,
      "z": -1,
      "name": "Empty"
    },
    {
      "x": -1,
      "y": 8,
      "z": -1,
      "name": "Empty"
    },
    {
      "x": -1,
      "y": 9,
      "z": -1,
      "name": "Empty"
    },
    {
      "x": -1,
      "y": 10,
      "z": -1,
      "name": "Empty"
    },
    {
      "x": -1,
      "y": 11,
      "z": -1,
      "name": "Empty"
    },
    {
      "x": -1,
      "y": 12,
      "z": -1,
      "name": "Empty"
    },
    {
      "x": -1,
      "y": 13,
      "z": -1,
      "name": "Empty"
    },
    {
      "x": -1,
      "y": 6,
      "z": 0,
      "name": "Rock_Stone"
    },
    {
      "x": -1,
      "y": 7,
      "z": 0,
      "name": "Rock_Stone"
    },
    {
      "x": -1,
      "y": 8,
      "z": 0,
      "name": "Rock_Stone_Cobble"
    },
    {
      "x": -1,
      "y": 9,
      "z": 0,
      "name": "Empty"
    },
    {
      "x": -1,
      "y": 10,
      "z": 0,
      "name": "Empty"
    },
    {
      "x": -1,
      "y": 11,
      "z": 0,
      "name": "Empty"
    },
    {
      "x": -1,
      "y": 12,
      "z": 0,
      "name": "Empty"
    },
    {
      "x": -1,
      "y": 13,
      "z": 0,
      "name": "Empty"
    },
    {
      "x": -1,
      "y": 14,
      "z": 0,
      "name": "Empty"
    },
    {
      "x": -1,
      "y": 8,
      "z": 1,
      "name": "Rock_Stone"
    },
    {
      "x": -1,
      "y": 9,
      "z": 1,
      "name": "Rock_Stone_Cobble"
    },
    {
      "x": -1,
      "y": 10,
      "z": 1,
      "name": "Empty"
    },
    {
      "x": -1,
      "y": 11,
      "z": 1,
      "name": "Empty"
    },
    {
      "x": -1,
      "y": 12,
      "z": 1,
      "name": "Empty"
    },
    {
      "x": -1,
      "y": 13,
      "z": 1,
      "name": "Empty"
    },
    {
      "x": -1,
      "y": 14,
      "z": 1,
      "name": "Empty"
    },
    {
      "x": -1,
      "y": 15,
      "z": 1,
      "name": "Empty"
    },
    {
      "x": -1,
      "y": 9,
      "z": 2,
      "name": "Rock_Stone_Cobble"
    },
    {
      "x": -1,
      "y": 10,
      "z": 2,
      "name": "Rock_Stone_Cobble"
    },
    {
      "x": -1,
      "y": 11,
      "z": 2,
      "name": "Empty"
    },
    {
      "x": -1,
      "y": 12,
      "z": 2,
      "name": "Empty"
    },
    {
      "x": -1,
      "y": 13,
      "z": 2,
      "name": "Empty"
    },
    {
      "x": -1,
      "y": 14,
      "z": 2,
      "name": "Empty"
    },
    {
      "x": -1,
      "y": 15,
      "z": 2,
      "name": "Empty"
    },
    {
      "x": -1,
      "y": 16,
      "z": 2,
      "name": "Empty"
    },
    {
      "x": -1,
      "y": 10,
      "z": 3,
      "name": "Rock_Stone_Cobble"
    },
    {
      "x": -1,
      "y": 11,
      "z": 3,
      "name": "Rock_Stone_Cobble"
    },
    {
      "x": -1,
      "y": 12,
      "z": 3,
      "name": "Rock_Stone_Cobble_Half"
    },
    {
      "x": -1,
      "y": 13,
      "z": 3,
      "name": "Empty"
    },
    {
      "x": -1,
      "y": 14,
      "z": 3,
      "name": "Empty"
    },
    {
      "x": -1,
      "y": 15,
      "z": 3,
      "name": "Empty"
    },
    {
      "x": -1,
      "y": 16,
      "z": 3,
      "name": "Empty"
    },
    {
      "x": -1,
      "y": 17,
      "z": 3,
      "name": "Empty"
    },
    {
      "x": -1,
      "y": 11,
      "z": 4,
      "name": "Rock_Stone_Cobble"
    },
    {
      "x": -1,
      "y": 12,
      "z": 4,
      "name": "Rock_Stone_Cobble"
    },
    {
      "x": -1,
      "y": 13,
      "z": 4,
      "name": "Rock_Stone_Cobble_Stairs",
      "rotation": 2
    },
    {
      "x": -1,
      "y": 14,
      "z": 4,
      "name": "Empty"
    },
    {
      "x": -1,
      "y": 15,
      "z": 4,
      "name": "Empty"
    },
    {
      "x": -1,
      "y": 16,
      "z": 4,
      "name": "Empty"
    },
    {
      "x": -1,
      "y": 17,
      "z": 4,
      "name": "Empty"
    },
    {
      "x": -1,
      "y": 18,
      "z": 4,
      "name": "Empty"
    },
    {
      "x": -1,
      "y": 12,
      "z": 5,
      "name": "Rock_Stone_Cobble"
    },
    {
      "x": -1,
      "y": 13,
      "z": 5,
      "name": "Rock_Stone_Cobble"
    },
    {
      "x": -1,
      "y": 14,
      "z": 5,
      "name": "Rock_Stone_Cobble_Stairs",
      "rotation": 2
    },
    {
      "x": -1,
      "y": 15,
      "z": 5,
      "name": "Empty"
    },
    {
      "x": -1,
      "y": 16,
      "z": 5,
      "name": "Empty"
    },
    {
      "x": -1,
      "y": 17,
      "z": 5,
      "name": "Empty"
    },
    {
      "x": -1,
      "y": 18,
      "z": 5,
      "name": "Empty"
    },
    {
      "x": -1,
      "y": 13,
      "z": 6,
      "name": "Rock_Stone_Cobble"
    },
    {
      "x": -1,
      "y": 14,
      "z": 6,
      "name": "Rock_Stone_Cobble"
    },
    {
      "x": -1,
      "y": 15,
      "z": 6,
      "name": "Rock_Stone_Cobble_Stairs",
      "rotation": 2
    },
    {
      "x": -1,
      "y": 16,
      "z": 6,
      "name": "Empty"
    },
    {
      "x": -1,
      "y": 17,
      "z": 6,
      "name": "Empty"
    },
    {
      "x": -1,
      "y": 18,
      "z": 6,
      "name": "Empty"
    },
    {
      "x": -1,
      "y": 13,
      "z": 7,
      "name": "Rock_Quartzite_Brick"
    },
    {
      "x": -1,
      "y": 14,
      "z": 7,
      "name": "Rock_Quartzite_Brick"
    },
    {
      "x": -1,
      "y": 15,
      "z": 7,
      "name": "Rock_Stone_Cobble"
    },
    {
      "x": -1,
      "y": 16,
      "z": 7,
      "name": "Rock_Stone_Cobble_Stairs",
      "rotation": 2
    },
    {
      "x": -1,
      "y": 17,
      "z": 7,
      "name": "Empty"
    },
    {
      "x": -1,
      "y": 18,
      "z": 7,
      "name": "Empty"
    },
    {
      "x": -1,
      "y": 13,
      "z": 8,
      "name": "Rock_Quartzite_Brick"
    },
    {
      "x": -1,
      "y": 14,
      "z": 8,
      "name": "Rock_Quartzite_Brick"
    },
    {
      "x": -1,
      "y": 15,
      "z": 8,
      "name": "Rock_Quartzite_Brick"
    },
    {
      "x": -1,
      "y": 16,
      "z": 8,
      "name": "Rock_Stone_Cobble"
    },
    {
      "x": -1,
      "y": 17,
      "z": 8,
      "name": "Rock_Stone_Cobble_Stairs",
      "rotation": 2
    },
    {
      "x": -1,
      "y": 18,
      "z": 8,
      "name": "Empty"
    },
    {
      "x": -1,
      "y": 13,
      "z": 9,
      "name": "Rock_Quartzite_Brick"
    },
    {
      "x": -1,
      "y": 14,
      "z": 9,
      "name": "Rock_Quartzite_Brick"
    },
    {
      "x": -1,
      "y": 15,
      "z": 9,
      "name": "Rock_Quartzite_Brick"
    },
    {
      "x": -1,
      "y": 16,
      "z": 9,
      "name": "Rock_Quartzite_Brick"
    },
    {
      "x": -1,
      "y": 17,
      "z": 9,
      "name": "Rock_Stone_Cobble"
    },
    {
      "x": -1,
      "y": 18,
      "z": 9,
      "name": "Rock_Stone_Cobble_Stairs",
      "rotation": 2
    },
    {
      "x": -1,
      "y": 15,
      "z": 10,
      "name": "Rock_Quartzite_Brick"
    },
    {
      "x": -1,
      "y": 16,
      "z": 10,
      "name": "Rock_Quartzite_Brick"
    },
    {
      "x": -1,
      "y": 17,
      "z": 10,
      "name": "Rock_Quartzite_Brick"
    },
    {
      "x": -1,
      "y": 18,
      "z": 10,
      "name": "Rock_Stone_Cobble"
    },
    {
      "x": 0,
      "y": 0,
      "z": -10,
      "name": "Rock_Stone_Cobble"
    },
    {
      "x": 0,
      "y": 1,
      "z": -10,
      "name": "Empty"
    },
    {
      "x": 0,
      "y": 2,
      "z": -10,
      "name": "Empty"
    },
    {
      "x": 0,
      "y": 3,
      "z": -10,
      "name": "Empty"
    },
    {
      "x": 0,
      "y": 4,
      "z": -10,
      "name": "Empty"
    },
    {
      "x": 0,
      "y": 5,
      "z": -10,
      "name": "Rock_Quartzite"
    },
    {
      "x": 0,
      "y": 0,
      "z": -9,
      "name": "Rock_Stone_Cobble"
    },
    {
      "x": 0,
      "y": 1,
      "z": -9,
      "name": "Rock_Stone_Cobble_Stairs",
      "rotation": 2
    },
    {
      "x": 0,
      "y": 2,
      "z": -9,
      "name": "Empty"
    },
    {
      "x": 0,
      "y": 3,
      "z": -9,
      "name": "Empty"
    },
    {
      "x": 0,
      "y": 4,
      "z": -9,
      "name": "Empty"
    },
    {
      "x": 0,
      "y": 5,
      "z": -9,
      "name": "Empty"
    },
    {
      "x": 0,
      "y": 6,
      "z": -9,
      "name": "Rock_Quartzite"
    },
    {
      "x": 0,
      "y": 0,
      "z": -8,
      "name": "Rock_Stone_Cobble"
    },
    {
      "x": 0,
      "y": 1,
      "z": -8,
      "name": "Rock_Stone_Cobble"
    },
    {
      "x": 0,
      "y": 2,
      "z": -8,
      "name": "Rock_Stone_Cobble_Stairs",
      "rotation": 2
    },
    {
      "x": 0,
      "y": 3,
      "z": -8,
      "name": "Empty"
    },
    {
      "x": 0,
      "y": 4,
      "z": -8,
      "name": "Empty"
    },
    {
      "x": 0,
      "y": 5,
      "z": -8,
      "name": "Empty"
    },
    {
      "x": 0,
      "y": 6,
      "z": -8,
      "name": "Empty"
    },
    {
      "x": 0,
      "y": 7,
      "z": -8,
      "name": "Empty"
    },
    {
      "x": 0,
      "y": 0,
      "z": -7,
      "name": "Rock_Stone_Cobble"
    },
    {
      "x": 0,
      "y": 1,
      "z": -7,
      "name": "Rock_Stone_Cobble"
    },
    {
      "x": 0,
      "y": 2,
      "z": -7,
      "name": "Rock_Stone_Cobble"
    },
    {
      "x": 0,
      "y": 3,
      "z": -7,
      "name": "Rock_Stone_Cobble_Half"
    },
    {
      "x": 0,
      "y": 4,
      "z": -7,
      "name": "Empty"
    },
    {
      "x": 0,
      "y": 5,
      "z": -7,
      "name": "Empty"
    },
    {
      "x": 0,
      "y": 6,
      "z": -7,
      "name": "Empty"
    },
    {
      "x": 0,
      "y": 7,
      "z": -7,
      "name": "Empty"
    },
    {
      "x": 0,
      "y": 8,
      "z": -7,
      "name": "Empty"
    },
    {
      "x": 0,
      "y": 9,
      "z": -7,
      "name": "Wood_Beech_Trunk_Full"
    },
    {
      "x": 0,
      "y": 1,
      "z": -6,
      "name": "Rock_Stone_Cobble"
    },
    {
      "x": 0,
      "y": 2,
      "z": -6,
      "name": "Rock_Stone_Cobble"
    },
    {
      "x": 0,
      "y": 3,
      "z": -6,
      "name": "Rock_Stone_Cobble_Half"
    },
    {
      "x": 0,
      "y": 4,
      "z": -6,
      "name": "Empty"
    },
    {
      "x": 0,
      "y": 5,
      "z": -6,
      "name": "Empty"
    },
    {
      "x": 0,
      "y": 6,
      "z": -6,
      "name": "Empty"
    },
    {
      "x": 0,
      "y": 7,
      "z": -6,
      "name": "Empty"
    },
    {
      "x": 0,
      "y": 8,
      "z": -6,
      "name": "Empty"
    },
    {
      "x": 0,
      "y": 9,
      "z": -6,
      "name": "Empty"
    },
    {
      "x": 0,
      "y": 2,
      "z": -5,
      "name": "Rock_Stone_Cobble"
    },
    {
      "x": 0,
      "y": 3,
      "z": -5,
      "name": "Rock_Stone_Cobble"
    },
    {
      "x": 0,
      "y": 4,
      "z": -5,
      "name": "Rock_Stone_Cobble_Stairs",
      "rotation": 2
    },
    {
      "x": 0,
      "y": 5,
      "z": -5,
      "name": "Empty"
    },
    {
      "x": 0,
      "y": 6,
      "z": -5,
      "name": "Empty"
    },
    {
      "x": 0,
      "y": 7,
      "z": -5,
      "name": "Empty"
    },
    {
      "x": 0,
      "y": 8,
      "z": -5,
      "name": "Empty"
    },
    {
      "x": 0,
      "y": 9,
      "z": -5,
      "name": "Empty"
    },
    {
      "x": 0,
      "y": 10,
      "z": -5,
      "name": "Empty"
    },
    {
      "x": 0,
      "y": 11,
      "z": -5,
      "name": "Wood_Beech_Trunk_Full"
    },
    {
      "x": 0,
      "y": 4,
      "z": -4,
      "name": "Rock_Stone_Cobble"
    },
    {
      "x": 0,
      "y": 5,
      "z": -4,
      "name": "Rock_Stone_Cobble_Stairs",
      "rotation": 2
    },
    {
      "x": 0,
      "y": 6,
      "z": -4,
      "name": "Empty"
    },
    {
      "x": 0,
      "y": 7,
      "z": -4,
      "name": "Empty"
    },
    {
      "x": 0,
      "y": 8,
      "z": -4,
      "name": "Empty"
    },
    {
      "x": 0,
      "y": 9,
      "z": -4,
      "name": "Empty"
    },
    {
      "x": 0,
      "y": 10,
      "z": -4,
      "name": "Empty"
    },
    {
      "x": 0,
      "y": 11,
      "z": -4,
      "name": "Empty"
    },
    {
      "x": 0,
      "y": 4,
      "z": -3,
      "name": "Rock_Stone_Cobble"
    },
    {
      "x": 0,
      "y": 5,
      "z": -3,
      "name": "Rock_Stone_Cobble"
    },
    {
      "x": 0,
      "y": 6,
      "z": -3,
      "name": "Empty"
    },
    {
      "x": 0,
      "y": 7,
      "z": -3,
      "name": "Empty"
    },
    {
      "x": 0,
      "y": 8,
      "z": -3,
      "name": "Empty"
    },
    {
      "x": 0,
      "y": 9,
      "z": -3,
      "name": "Empty"
    },
    {
      "x": 0,
      "y": 10,
      "z": -3,
      "name": "Empty"
    },
    {
      "x": 0,
      "y": 11,
      "z": -3,
      "name": "Rock_Quartzite_Brick"
    },
    {
      "x": 0,
      "y": 12,
      "z": -3,
      "name": "Rock_Quartzite_Brick"
    },
    {
      "x": 0,
      "y": 13,
      "z": -3,
      "name": "Rock_Quartzite_Brick"
    },
    {
      "x": 0,
      "y": 5,
      "z": -2,
      "name": "Rock_Stone_Cobble"
    },
    {
      "x": 0,
      "y": 6,
      "z": -2,
      "name": "Empty"
    },
    {
      "x": 0,
      "y": 7,
      "z": -2,
      "name": "Empty"
    },
    {
      "x": 0,
      "y": 8,
      "z": -2,
      "name": "Empty"
    },
    {
      "x": 0,
      "y": 9,
      "z": -2,
      "name": "Empty"
    },
    {
      "x": 0,
      "y": 10,
      "z": -2,
      "name": "Empty"
    },
    {
      "x": 0,
      "y": 11,
      "z": -2,
      "name": "Empty"
    },
    {
      "x": 0,
      "y": 12,
      "z": -2,
      "name": "Empty"
    },
    {
      "x": 0,
      "y": 13,
      "z": -2,
      "name": "Rock_Quartzite"
    },
    {
      "x": 0,
      "y": 5,
      "z": -1,
      "name": "Rock_Stone"
    },
    {
      "x": 0,
      "y": 6,
      "z": -1,
      "name": "Rock_Stone_Cobble"
    },
    {
      "x": 0,
      "y": 7,
      "z": -1,
      "name": "Empty"
    },
    {
      "x": 0,
      "y": 8,
      "z": -1,
      "name": "Empty"
    },
    {
      "x": 0,
      "y": 9,
      "z": -1,
      "name": "Empty"
    },
    {
      "x": 0,
      "y": 10,
      "z": -1,
      "name": "Empty"
    },
    {
      "x": 0,
      "y": 11,
      "z": -1,
      "name": "Empty"
    },
    {
      "x": 0,
      "y": 12,
      "z": -1,
      "name": "Empty"
    },
    {
      "x": 0,
      "y": 13,
      "z": -1,
      "name": "Empty"
    },
    {
      "x": 0,
      "y": 5,
      "z": 0,
      "name": "Rock_Stone"
    },
    {
      "x": 0,
      "y": 6,
      "z": 0,
      "name": "Rock_Stone"
    },
    {
      "x": 0,
      "y": 7,
      "z": 0,
      "name": "Rock_Stone"
    },
    {
      "x": 0,
      "y": 8,
      "z": 0,
      "name": "Empty"
    },
    {
      "x": 0,
      "y": 9,
      "z": 0,
      "name": "Empty"
    },
    {
      "x": 0,
      "y": 10,
      "z": 0,
      "name": "Empty"
    },
    {
      "x": 0,
      "y": 11,
      "z": 0,
      "name": "Empty"
    },
    {
      "x": 0,
      "y": 12,
      "z": 0,
      "name": "Empty"
    },
    {
      "x": 0,
      "y": 13,
      "z": 0,
      "name": "Empty"
    },
    {
      "x": 0,
      "y": 14,
      "z": 0,
      "name": "Empty"
    },
    {
      "x": 0,
      "y": 7,
      "z": 1,
      "name": "Rock_Stone"
    },
    {
      "x": 0,
      "y": 8,
      "z": 1,
      "name": "Rock_Stone"
    },
    {
      "x": 0,
      "y": 9,
      "z": 1,
      "name": "Empty"
    },
    {
      "x": 0,
      "y": 10,
      "z": 1,
      "name": "Empty"
    },
    {
      "x": 0,
      "y": 11,
      "z": 1,
      "name": "Empty"
    },
    {
      "x": 0,
      "y": 12,
      "z": 1,
      "name": "Empty"
    },
    {
      "x": 0,
      "y": 13,
      "z": 1,
      "name": "Empty"
    },
    {
      "x": 0,
      "y": 14,
      "z": 1,
      "name": "Empty"
    },
    {
      "x": 0,
      "y": 15,
      "z": 1,
      "name": "Empty"
    },
    {
      "x": 0,
      "y": 9,
      "z": 2,
      "name": "Rock_Stone_Cobble"
    },
    {
      "x": 0,
      "y": 10,
      "z": 2,
      "name": "Rock_Stone_Cobble"
    },
    {
      "x": 0,
      "y": 11,
      "z": 2,
      "name": "Rock_Stone_Cobble_Stairs",
      "rotation": 2
    },
    {
      "x": 0,
      "y": 12,
      "z": 2,
      "name": "Empty"
    },
    {
      "x": 0,
      "y": 13,
      "z": 2,
      "name": "Empty"
    },
    {
      "x": 0,
      "y": 14,
      "z": 2,
      "name": "Empty"
    },
    {
      "x": 0,
      "y": 15,
      "z": 2,
      "name": "Empty"
    },
    {
      "x": 0,
      "y": 16,
      "z": 2,
      "name": "Empty"
    },
    {
      "x": 0,
      "y": 10,
      "z": 3,
      "name": "Rock_Stone_Cobble"
    },
    {
      "x": 0,
      "y": 11,
      "z": 3,
      "name": "Rock_Stone_Cobble"
    },
    {
      "x": 0,
      "y": 12,
      "z": 3,
      "name": "Rock_Stone_Cobble_Stairs",
      "rotation": 2
    },
    {
      "x": 0,
      "y": 13,
      "z": 3,
      "name": "Empty"
    },
    {
      "x": 0,
      "y": 14,
      "z": 3,
      "name": "Empty"
    },
    {
      "x": 0,
      "y": 15,
      "z": 3,
      "name": "Empty"
    },
    {
      "x": 0,
      "y": 16,
      "z": 3,
      "name": "Empty"
    },
    {
      "x": 0,
      "y": 17,
      "z": 3,
      "name": "Empty"
    },
    {
      "x": 0,
      "y": 10,
      "z": 4,
      "name": "Rock_Stone_Cobble"
    },
    {
      "x": 0,
      "y": 11,
      "z": 4,
      "name": "Rock_Stone_Cobble"
    },
    {
      "x": 0,
      "y": 12,
      "z": 4,
      "name": "Rock_Stone_Cobble"
    },
    {
      "x": 0,
      "y": 13,
      "z": 4,
      "name": "Rock_Stone_Cobble_Stairs",
      "rotation": 2
    },
    {
      "x": 0,
      "y": 14,
      "z": 4,
      "name": "Empty"
    },
    {
      "x": 0,
      "y": 15,
      "z": 4,
      "name": "Empty"
    },
    {
      "x": 0,
      "y": 16,
      "z": 4,
      "name": "Empty"
    },
    {
      "x": 0,
      "y": 17,
      "z": 4,
      "name": "Empty"
    },
    {
      "x": 0,
      "y": 18,
      "z": 4,
      "name": "Empty"
    },
    {
      "x": 0,
      "y": 11,
      "z": 5,
      "name": "Rock_Stone_Cobble"
    },
    {
      "x": 0,
      "y": 12,
      "z": 5,
      "name": "Rock_Stone_Cobble"
    },
    {
      "x": 0,
      "y": 13,
      "z": 5,
      "name": "Rock_Stone_Cobble"
    },
    {
      "x": 0,
      "y": 14,
      "z": 5,
      "name": "Rock_Stone_Cobble_Stairs",
      "rotation": 2
    },
    {
      "x": 0,
      "y": 15,
      "z": 5,
      "name": "Empty"
    },
    {
      "x": 0,
      "y": 16,
      "z": 5,
      "name": "Empty"
    },
    {
      "x": 0,
      "y": 17,
      "z": 5,
      "name": "Empty"
    },
    {
      "x": 0,
      "y": 18,
      "z": 5,
      "name": "Empty"
    },
    {
      "x": 0,
      "y": 12,
      "z": 6,
      "name": "Rock_Stone_Cobble"
    },
    {
      "x": 0,
      "y": 13,
      "z": 6,
      "name": "Rock_Stone_Cobble"
    },
    {
      "x": 0,
      "y": 14,
      "z": 6,
      "name": "Rock_Stone_Cobble"
    },
    {
      "x": 0,
      "y": 15,
      "z": 6,
      "name": "Rock_Stone_Cobble_Stairs",
      "rotation": 2
    },
    {
      "x": 0,
      "y": 16,
      "z": 6,
      "name": "Empty"
    },
    {
      "x": 0,
      "y": 17,
      "z": 6,
      "name": "Empty"
    },
    {
      "x": 0,
      "y": 18,
      "z": 6,
      "name": "Empty"
    },
    {
      "x": 0,
      "y": 13,
      "z": 7,
      "name": "Rock_Quartzite_Brick"
    },
    {
      "x": 0,
      "y": 14,
      "z": 7,
      "name": "Rock_Quartzite_Brick"
    },
    {
      "x": 0,
      "y": 15,
      "z": 7,
      "name": "Rock_Stone_Cobble"
    },
    {
      "x": 0,
      "y": 16,
      "z": 7,
      "name": "Rock_Stone_Cobble_Stairs",
      "rotation": 2
    },
    {
      "x": 0,
      "y": 17,
      "z": 7,
      "name": "Empty"
    },
    {
      "x": 0,
      "y": 18,
      "z": 7,
      "name": "Empty"
    },
    {
      "x": 0,
      "y": 13,
      "z": 8,
      "name": "Rock_Quartzite_Brick"
    },
    {
      "x": 0,
      "y": 14,
      "z": 8,
      "name": "Rock_Quartzite_Brick"
    },
    {
      "x": 0,
      "y": 15,
      "z": 8,
      "name": "Rock_Quartzite_Brick"
    },
    {
      "x": 0,
      "y": 16,
      "z": 8,
      "name": "Rock_Stone_Cobble"
    },
    {
      "x": 0,
      "y": 17,
      "z": 8,
      "name": "Rock_Stone_Cobble_Stairs",
      "rotation": 2
    },
    {
      "x": 0,
      "y": 18,
      "z": 8,
      "name": "Empty"
    },
    {
      "x": 0,
      "y": 13,
      "z": 9,
      "name": "Rock_Quartzite_Brick"
    },
    {
      "x": 0,
      "y": 14,
      "z": 9,
      "name": "Rock_Quartzite_Brick"
    },
    {
      "x": 0,
      "y": 15,
      "z": 9,
      "name": "Rock_Quartzite_Brick"
    },
    {
      "x": 0,
      "y": 16,
      "z": 9,
      "name": "Rock_Quartzite_Brick"
    },
    {
      "x": 0,
      "y": 17,
      "z": 9,
      "name": "Rock_Stone_Cobble"
    },
    {
      "x": 0,
      "y": 18,
      "z": 9,
      "name": "Rock_Stone_Cobble_Stairs",
      "rotation": 2
    },
    {
      "x": 0,
      "y": 15,
      "z": 10,
      "name": "Rock_Quartzite_Brick"
    },
    {
      "x": 0,
      "y": 16,
      "z": 10,
      "name": "Rock_Quartzite_Brick"
    },
    {
      "x": 0,
      "y": 17,
      "z": 10,
      "name": "Rock_Quartzite_Brick"
    },
    {
      "x": 0,
      "y": 18,
      "z": 10,
      "name": "Rock_Stone_Cobble"
    },
    {
      "x": 1,
      "y": 0,
      "z": -10,
      "name": "Rock_Stone_Cobble"
    },
    {
      "x": 1,
      "y": 1,
      "z": -10,
      "name": "Empty"
    },
    {
      "x": 1,
      "y": 2,
      "z": -10,
      "name": "Empty"
    },
    {
      "x": 1,
      "y": 3,
      "z": -10,
      "name": "Empty"
    },
    {
      "x": 1,
      "y": 4,
      "z": -10,
      "name": "Empty"
    },
    {
      "x": 1,
      "y": 5,
      "z": -10,
      "name": "Rock_Quartzite_Brick"
    },
    {
      "x": 1,
      "y": 0,
      "z": -9,
      "name": "Rock_Stone_Cobble"
    },
    {
      "x": 1,
      "y": 1,
      "z": -9,
      "name": "Rock_Stone_Cobble_Half"
    },
    {
      "x": 1,
      "y": 2,
      "z": -9,
      "name": "Empty"
    },
    {
      "x": 1,
      "y": 3,
      "z": -9,
      "name": "Empty"
    },
    {
      "x": 1,
      "y": 4,
      "z": -9,
      "name": "Empty"
    },
    {
      "x": 1,
      "y": 5,
      "z": -9,
      "name": "Empty"
    },
    {
      "x": 1,
      "y": 6,
      "z": -9,
      "name": "Rock_Quartzite"
    },
    {
      "x": 1,
      "y": 7,
      "z": -9,
      "name": "Rock_Quartzite"
    },
    {
      "x": 1,
      "y": 0,
      "z": -8,
      "name": "Rock_Stone_Cobble"
    },
    {
      "x": 1,
      "y": 1,
      "z": -8,
      "name": "Rock_Stone_Cobble"
    },
    {
      "x": 1,
      "y": 2,
      "z": -8,
      "name": "Rock_Stone_Cobble_Half"
    },
    {
      "x": 1,
      "y": 3,
      "z": -8,
      "name": "Empty"
    },
    {
      "x": 1,
      "y": 4,
      "z": -8,
      "name": "Empty"
    },
    {
      "x": 1,
      "y": 5,
      "z": -8,
      "name": "Empty"
    },
    {
      "x": 1,
      "y": 6,
      "z": -8,
      "name": "Empty"
    },
    {
      "x": 1,
      "y": 7,
      "z": -8,
      "name": "Rock_Quartzite"
    },
    {
      "x": 1,
      "y": 0,
      "z": -7,
      "name": "Rock_Stone_Cobble"
    },
    {
      "x": 1,
      "y": 1,
      "z": -7,
      "name": "Rock_Stone_Cobble"
    },
    {
      "x": 1,
      "y": 2,
      "z": -7,
      "name": "Rock_Quartzite"
    },
    {
      "x": 1,
      "y": 3,
      "z": -7,
      "name": "Empty"
    },
    {
      "x": 1,
      "y": 4,
      "z": -7,
      "name": "Empty"
    },
    {
      "x": 1,
      "y": 5,
      "z": -7,
      "name": "Empty"
    },
    {
      "x": 1,
      "y": 6,
      "z": -7,
      "name": "Empty"
    },
    {
      "x": 1,
      "y": 7,
      "z": -7,
      "name": "Wood_Beech_Trunk_Full"
    },
    {
      "x": 1,
      "y": 8,
      "z": -7,
      "name": "Wood_Beech_Trunk_Full"
    },
    {
      "x": 1,
      "y": 9,
      "z": -7,
      "name": "Wood_Beech_Trunk_Full"
    },
    {
      "x": 1,
      "y": 1,
      "z": -6,
      "name": "Rock_Stone_Cobble"
    },
    {
      "x": 1,
      "y": 2,
      "z": -6,
      "name": "Rock_Stone_Cobble"
    },
    {
      "x": 1,
      "y": 3,
      "z": -6,
      "name": "Rock_Stone_Cobble_Half"
    },
    {
      "x": 1,
      "y": 4,
      "z": -6,
      "name": "Empty"
    },
    {
      "x": 1,
      "y": 5,
      "z": -6,
      "name": "Empty"
    },
    {
      "x": 1,
      "y": 6,
      "z": -6,
      "name": "Empty"
    },
    {
      "x": 1,
      "y": 7,
      "z": -6,
      "name": "Empty"
    },
    {
      "x": 1,
      "y": 8,
      "z": -6,
      "name": "Empty"
    },
    {
      "x": 1,
      "y": 9,
      "z": -6,
      "name": "Wood_Beech_Trunk_Full"
    },
    {
      "x": 1,
      "y": 2,
      "z": -5,
      "name": "Rock_Stone_Cobble"
    },
    {
      "x": 1,
      "y": 3,
      "z": -5,
      "name": "Rock_Stone_Cobble"
    },
    {
      "x": 1,
      "y": 4,
      "z": -5,
      "name": "Rock_Stone_Cobble"
    },
    {
      "x": 1,
      "y": 5,
      "z": -5,
      "name": "Empty"
    },
    {
      "x": 1,
      "y": 6,
      "z": -5,
      "name": "Empty"
    },
    {
      "x": 1,
      "y": 7,
      "z": -5,
      "name": "Empty"
    },
    {
      "x": 1,
      "y": 8,
      "z": -5,
      "name": "Empty"
    },
    {
      "x": 1,
      "y": 9,
      "z": -5,
      "name": "Wood_Beech_Trunk_Full"
    },
    {
      "x": 1,
      "y": 10,
      "z": -5,
      "name": "Wood_Beech_Trunk_Full"
    },
    {
      "x": 1,
      "y": 11,
      "z": -5,
      "name": "Wood_Beech_Trunk_Full"
    },
    {
      "x": 1,
      "y": 4,
      "z": -4,
      "name": "Rock_Stone_Cobble"
    },
    {
      "x": 1,
      "y": 5,
      "z": -4,
      "name": "Rock_Stone_Cobble_Stairs",
      "rotation": 2
    },
    {
      "x": 1,
      "y": 6,
      "z": -4,
      "name": "Empty"
    },
    {
      "x": 1,
      "y": 7,
      "z": -4,
      "name": "Empty"
    },
    {
      "x": 1,
      "y": 8,
      "z": -4,
      "name": "Empty"
    },
    {
      "x": 1,
      "y": 9,
      "z": -4,
      "name": "Empty"
    },
    {
      "x": 1,
      "y": 10,
      "z": -4,
      "name": "Empty"
    },
    {
      "x": 1,
      "y": 11,
      "z": -4,
      "name": "Wood_Beech_Trunk_Full"
    },
    {
      "x": 1,
      "y": 4,
      "z": -3,
      "name": "Rock_Stone_Cobble"
    },
    {
      "x": 1,
      "y": 5,
      "z": -3,
      "name": "Rock_Stone_Cobble"
    },
    {
      "x": 1,
      "y": 6,
      "z": -3,
      "name": "Empty"
    },
    {
      "x": 1,
      "y": 7,
      "z": -3,
      "name": "Empty"
    },
    {
      "x": 1,
      "y": 8,
      "z": -3,
      "name": "Empty"
    },
    {
      "x": 1,
      "y": 9,
      "z": -3,
      "name": "Empty"
    },
    {
      "x": 1,
      "y": 10,
      "z": -3,
      "name": "Empty"
    },
    {
      "x": 1,
      "y": 11,
      "z": -3,
      "name": "Empty"
    },
    {
      "x": 1,
      "y": 12,
      "z": -3,
      "name": "Wood_Beech_Trunk_Full"
    },
    {
      "x": 1,
      "y": 5,
      "z": -2,
      "name": "Rock_Stone"
    },
    {
      "x": 1,
      "y": 6,
      "z": -2,
      "name": "Empty"
    },
    {
      "x": 1,
      "y": 7,
      "z": -2,
      "name": "Empty"
    },
    {
      "x": 1,
      "y": 8,
      "z": -2,
      "name": "Empty"
    },
    {
      "x": 1,
      "y": 9,
      "z": -2,
      "name": "Empty"
    },
    {
      "x": 1,
      "y": 10,
      "z": -2,
      "name": "Empty"
    },
    {
      "x": 1,
      "y": 11,
      "z": -2,
      "name": "Empty"
    },
    {
      "x": 1,
      "y": 12,
      "z": -2,
      "name": "Empty"
    },
    {
      "x": 1,
      "y": 13,
      "z": -2,
      "name": "Rock_Quartzite"
    },
    {
      "x": 1,
      "y": 5,
      "z": -1,
      "name": "Rock_Stone"
    },
    {
      "x": 1,
      "y": 6,
      "z": -1,
      "name": "Rock_Stone"
    },
    {
      "x": 1,
      "y": 7,
      "z": -1,
      "name": "Empty"
    },
    {
      "x": 1,
      "y": 8,
      "z": -1,
      "name": "Empty"
    },
    {
      "x": 1,
      "y": 9,
      "z": -1,
      "name": "Empty"
    },
    {
      "x": 1,
      "y": 10,
      "z": -1,
      "name": "Empty"
    },
    {
      "x": 1,
      "y": 11,
      "z": -1,
      "name": "Empty"
    },
    {
      "x": 1,
      "y": 12,
      "z": -1,
      "name": "Empty"
    },
    {
      "x": 1,
      "y": 13,
      "z": -1,
      "name": "Empty"
    },
    {
      "x": 1,
      "y": 6,
      "z": 0,
      "name": "Rock_Stone"
    },
    {
      "x": 1,
      "y": 7,
      "z": 0,
      "name": "Rock_Stone"
    },
    {
      "x": 1,
      "y": 8,
      "z": 0,
      "name": "Rock_Stone_Cobble"
    },
    {
      "x": 1,
      "y": 9,
      "z": 0,
      "name": "Rock_Stone_Cobble_Stairs",
      "rotation": 2
    },
    {
      "x": 1,
      "y": 10,
      "z": 0,
      "name": "Empty"
    },
    {
      "x": 1,
      "y": 11,
      "z": 0,
      "name": "Empty"
    },
    {
      "x": 1,
      "y": 12,
      "z": 0,
      "name": "Empty"
    },
    {
      "x": 1,
      "y": 13,
      "z": 0,
      "name": "Empty"
    },
    {
      "x": 1,
      "y": 14,
      "z": 0,
      "name": "Empty"
    },
    {
      "x": 1,
      "y": 7,
      "z": 1,
      "name": "Rock_Stone"
    },
    {
      "x": 1,
      "y": 8,
      "z": 1,
      "name": "Rock_Stone"
    },
    {
      "x": 1,
      "y": 9,
      "z": 1,
      "name": "Rock_Stone_Cobble"
    },
    {
      "x": 1,
      "y": 10,
      "z": 1,
      "name": "Empty"
    },
    {
      "x": 1,
      "y": 11,
      "z": 1,
      "name": "Empty"
    },
    {
      "x": 1,
      "y": 12,
      "z": 1,
      "name": "Empty"
    },
    {
      "x": 1,
      "y": 13,
      "z": 1,
      "name": "Empty"
    },
    {
      "x": 1,
      "y": 14,
      "z": 1,
      "name": "Empty"
    },
    {
      "x": 1,
      "y": 15,
      "z": 1,
      "name": "Empty"
    },
    {
      "x": 1,
      "y": 9,
      "z": 2,
      "name": "Rock_Stone_Cobble"
    },
    {
      "x": 1,
      "y": 10,
      "z": 2,
      "name": "Rock_Stone_Cobble"
    },
    {
      "x": 1,
      "y": 11,
      "z": 2,
      "name": "Rock_Stone_Cobble_Stairs",
      "rotation": 2
    },
    {
      "x": 1,
      "y": 12,
      "z": 2,
      "name": "Empty"
    },
    {
      "x": 1,
      "y": 13,
      "z": 2,
      "name": "Empty"
    },
    {
      "x": 1,
      "y": 14,
      "z": 2,
      "name": "Empty"
    },
    {
      "x": 1,
      "y": 15,
      "z": 2,
      "name": "Empty"
    },
    {
      "x": 1,
      "y": 16,
      "z": 2,
      "name": "Empty"
    },
    {
      "x": 1,
      "y": 10,
      "z": 3,
      "name": "Rock_Stone_Cobble"
    },
    {
      "x": 1,
      "y": 11,
      "z": 3,
      "name": "Rock_Stone_Cobble"
    },
    {
      "x": 1,
      "y": 12,
      "z": 3,
      "name": "Rock_Stone_Cobble_Stairs",
      "rotation": 2
    },
    {
      "x": 1,
      "y": 13,
      "z": 3,
      "name": "Empty"
    },
    {
      "x": 1,
      "y": 14,
      "z": 3,
      "name": "Empty"
    },
    {
      "x": 1,
      "y": 15,
      "z": 3,
      "name": "Empty"
    },
    {
      "x": 1,
      "y": 16,
      "z": 3,
      "name": "Empty"
    },
    {
      "x": 1,
      "y": 17,
      "z": 3,
      "name": "Empty"
    },
    {
      "x": 1,
      "y": 10,
      "z": 4,
      "name": "Rock_Stone_Cobble"
    },
    {
      "x": 1,
      "y": 11,
      "z": 4,
      "name": "Rock_Stone_Cobble"
    },
    {
      "x": 1,
      "y": 12,
      "z": 4,
      "name": "Rock_Stone_Cobble"
    },
    {
      "x": 1,
      "y": 13,
      "z": 4,
      "name": "Rock_Stone_Cobble_Stairs",
      "rotation": 2
    },
    {
      "x": 1,
      "y": 14,
      "z": 4,
      "name": "Empty"
    },
    {
      "x": 1,
      "y": 15,
      "z": 4,
      "name": "Empty"
    },
    {
      "x": 1,
      "y": 16,
      "z": 4,
      "name": "Empty"
    },
    {
      "x": 1,
      "y": 17,
      "z": 4,
      "name": "Empty"
    },
    {
      "x": 1,
      "y": 18,
      "z": 4,
      "name": "Empty"
    },
    {
      "x": 1,
      "y": 11,
      "z": 5,
      "name": "Rock_Stone_Cobble"
    },
    {
      "x": 1,
      "y": 12,
      "z": 5,
      "name": "Rock_Stone_Cobble"
    },
    {
      "x": 1,
      "y": 13,
      "z": 5,
      "name": "Rock_Stone_Cobble"
    },
    {
      "x": 1,
      "y": 14,
      "z": 5,
      "name": "Rock_Stone_Cobble_Stairs",
      "rotation": 2
    },
    {
      "x": 1,
      "y": 15,
      "z": 5,
      "name": "Empty"
    },
    {
      "x": 1,
      "y": 16,
      "z": 5,
      "name": "Empty"
    },
    {
      "x": 1,
      "y": 17,
      "z": 5,
      "name": "Empty"
    },
    {
      "x": 1,
      "y": 18,
      "z": 5,
      "name": "Empty"
    },
    {
      "x": 1,
      "y": 12,
      "z": 6,
      "name": "Rock_Stone_Cobble"
    },
    {
      "x": 1,
      "y": 13,
      "z": 6,
      "name": "Rock_Stone_Cobble"
    },
    {
      "x": 1,
      "y": 14,
      "z": 6,
      "name": "Rock_Stone_Cobble"
    },
    {
      "x": 1,
      "y": 15,
      "z": 6,
      "name": "Rock_Stone_Cobble_Half"
    },
    {
      "x": 1,
      "y": 16,
      "z": 6,
      "name": "Empty"
    },
    {
      "x": 1,
      "y": 17,
      "z": 6,
      "name": "Empty"
    },
    {
      "x": 1,
      "y": 18,
      "z": 6,
      "name": "Empty"
    },
    {
      "x": 1,
      "y": 13,
      "z": 7,
      "name": "Rock_Quartzite_Brick"
    },
    {
      "x": 1,
      "y": 14,
      "z": 7,
      "name": "Rock_Quartzite_Brick"
    },
    {
      "x": 1,
      "y": 15,
      "z": 7,
      "name": "Rock_Stone_Cobble"
    },
    {
      "x": 1,
      "y": 16,
      "z": 7,
      "name": "Rock_Stone_Cobble_Stairs",
      "rotation": 2
    },
    {
      "x": 1,
      "y": 17,
      "z": 7,
      "name": "Empty"
    },
    {
      "x": 1,
      "y": 18,
      "z": 7,
      "name": "Empty"
    },
    {
      "x": 1,
      "y": 13,
      "z": 8,
      "name": "Rock_Quartzite_Brick"
    },
    {
      "x": 1,
      "y": 14,
      "z": 8,
      "name": "Rock_Quartzite_Brick"
    },
    {
      "x": 1,
      "y": 15,
      "z": 8,
      "name": "Rock_Quartzite_Brick"
    },
    {
      "x": 1,
      "y": 16,
      "z": 8,
      "name": "Rock_Stone_Cobble"
    },
    {
      "x": 1,
      "y": 17,
      "z": 8,
      "name": "Rock_Stone_Cobble_Stairs",
      "rotation": 2
    },
    {
      "x": 1,
      "y": 18,
      "z": 8,
      "name": "Empty"
    },
    {
      "x": 1,
      "y": 13,
      "z": 9,
      "name": "Rock_Quartzite_Brick"
    },
    {
      "x": 1,
      "y": 14,
      "z": 9,
      "name": "Rock_Quartzite_Brick"
    },
    {
      "x": 1,
      "y": 15,
      "z": 9,
      "name": "Rock_Quartzite_Brick"
    },
    {
      "x": 1,
      "y": 16,
      "z": 9,
      "name": "Rock_Quartzite_Brick"
    },
    {
      "x": 1,
      "y": 17,
      "z": 9,
      "name": "Rock_Stone_Cobble"
    },
    {
      "x": 1,
      "y": 18,
      "z": 9,
      "name": "Rock_Stone_Cobble_Half"
    },
    {
      "x": 1,
      "y": 14,
      "z": 10,
      "name": "Rock_Quartzite_Brick"
    },
    {
      "x": 1,
      "y": 15,
      "z": 10,
      "name": "Rock_Quartzite_Brick"
    },
    {
      "x": 1,
      "y": 16,
      "z": 10,
      "name": "Rock_Quartzite_Brick"
    },
    {
      "x": 1,
      "y": 17,
      "z": 10,
      "name": "Rock_Quartzite_Brick"
    },
    {
      "x": 1,
      "y": 18,
      "z": 10,
      "name": "Rock_Stone_Cobble_Half"
    },
    {
      "x": 2,
      "y": 0,
      "z": -10,
      "name": "Rock_Stone_Cobble"
    },
    {
      "x": 2,
      "y": 1,
      "z": -10,
      "name": "Empty"
    },
    {
      "x": 2,
      "y": 2,
      "z": -10,
      "name": "Empty"
    },
    {
      "x": 2,
      "y": 3,
      "z": -10,
      "name": "Empty"
    },
    {
      "x": 2,
      "y": 4,
      "z": -10,
      "name": "Empty"
    },
    {
      "x": 2,
      "y": 5,
      "z": -10,
      "name": "Rock_Quartzite_Brick"
    },
    {
      "x": 2,
      "y": 0,
      "z": -9,
      "name": "Rock_Stone_Cobble"
    },
    {
      "x": 2,
      "y": 1,
      "z": -9,
      "name": "Rock_Quartzite"
    },
    {
      "x": 2,
      "y": 2,
      "z": -9,
      "name": "Empty"
    },
    {
      "x": 2,
      "y": 3,
      "z": -9,
      "name": "Empty"
    },
    {
      "x": 2,
      "y": 4,
      "z": -9,
      "name": "Empty"
    },
    {
      "x": 2,
      "y": 5,
      "z": -9,
      "name": "Empty"
    },
    {
      "x": 2,
      "y": 6,
      "z": -9,
      "name": "Rock_Quartzite_Brick"
    },
    {
      "x": 2,
      "y": 0,
      "z": -8,
      "name": "Rock_Stone_Cobble"
    },
    {
      "x": 2,
      "y": 1,
      "z": -8,
      "name": "Rock_Quartzite"
    },
    {
      "x": 2,
      "y": 2,
      "z": -8,
      "name": "Rock_Quartzite"
    },
    {
      "x": 2,
      "y": 3,
      "z": -8,
      "name": "Empty"
    },
    {
      "x": 2,
      "y": 4,
      "z": -8,
      "name": "Empty"
    },
    {
      "x": 2,
      "y": 5,
      "z": -8,
      "name": "Empty"
    },
    {
      "x": 2,
      "y": 6,
      "z": -8,
      "name": "Empty"
    },
    {
      "x": 2,
      "y": 7,
      "z": -8,
      "name": "Rock_Quartzite"
    },
    {
      "x": 2,
      "y": 8,
      "z": -8,
      "name": "Rock_Quartzite"
    },
    {
      "x": 2,
      "y": 1,
      "z": -7,
      "name": "Rock_Stone_Cobble"
    },
    {
      "x": 2,
      "y": 2,
      "z": -7,
      "name": "Rock_Quartzite"
    },
    {
      "x": 2,
      "y": 3,
      "z": -7,
      "name": "Empty"
    },
    {
      "x": 2,
      "y": 4,
      "z": -7,
      "name": "Empty"
    },
    {
      "x": 2,
      "y": 5,
      "z": -7,
      "name": "Empty"
    },
    {
      "x": 2,
      "y": 6,
      "z": -7,
      "name": "Empty"
    },
    {
      "x": 2,
      "y": 7,
      "z": -7,
      "name": "Empty"
    },
    {
      "x": 2,
      "y": 8,
      "z": -7,
      "name": "Rock_Quartzite"
    },
    {
      "x": 2,
      "y": 9,
      "z": -7,
      "name": "Rock_Quartzite"
    },
    {
      "x": 2,
      "y": 2,
      "z": -6,
      "name": "Rock_Stone_Cobble"
    },
    {
      "x": 2,
      "y": 3,
      "z": -6,
      "name": "Empty"
    },
    {
      "x": 2,
      "y": 4,
      "z": -6,
      "name": "Empty"
    },
    {
      "x": 2,
      "y": 5,
      "z": -6,
      "name": "Empty"
    },
    {
      "x": 2,
      "y": 6,
      "z": -6,
      "name": "Empty"
    },
    {
      "x": 2,
      "y": 7,
      "z": -6,
      "name": "Empty"
    },
    {
      "x": 2,
      "y": 8,
      "z": -6,
      "name": "Empty"
    },
    {
      "x": 2,
      "y": 9,
      "z": -6,
      "name": "Rock_Quartzite"
    },
    {
      "x": 2,
      "y": 3,
      "z": -5,
      "name": "Rock_Stone_Cobble"
    },
    {
      "x": 2,
      "y": 4,
      "z": -5,
      "name": "Rock_Stone_Cobble_Stairs",
      "rotation": 2
    },
    {
      "x": 2,
      "y": 5,
      "z": -5,
      "name": "Empty"
    },
    {
      "x": 2,
      "y": 6,
      "z": -5,
      "name": "Empty"
    },
    {
      "x": 2,
      "y": 7,
      "z": -5,
      "name": "Empty"
    },
    {
      "x": 2,
      "y": 8,
      "z": -5,
      "name": "Empty"
    },
    {
      "x": 2,
      "y": 9,
      "z": -5,
      "name": "Empty"
    },
    {
      "x": 2,
      "y": 10,
      "z": -5,
      "name": "Rock_Quartzite"
    },
    {
      "x": 2,
      "y": 11,
      "z": -5,
      "name": "Rock_Quartzite"
    },
    {
      "x": 2,
      "y": 4,
      "z": -4,
      "name": "Rock_Stone_Cobble"
    },
    {
      "x": 2,
      "y": 5,
      "z": -4,
      "name": "Rock_Stone_Cobble_Half"
    },
    {
      "x": 2,
      "y": 6,
      "z": -4,
      "name": "Empty"
    },
    {
      "x": 2,
      "y": 7,
      "z": -4,
      "name": "Empty"
    },
    {
      "x": 2,
      "y": 8,
      "z": -4,
      "name": "Empty"
    },
    {
      "x": 2,
      "y": 9,
      "z": -4,
      "name": "Empty"
    },
    {
      "x": 2,
      "y": 10,
      "z": -4,
      "name": "Empty"
    },
    {
      "x": 2,
      "y": 11,
      "z": -4,
      "name": "Rock_Quartzite"
    },
    {
      "x": 2,
      "y": 5,
      "z": -3,
      "name": "Rock_Stone_Cobble"
    },
    {
      "x": 2,
      "y": 6,
      "z": -3,
      "name": "Rock_Stone_Cobble_Half"
    },
    {
      "x": 2,
      "y": 7,
      "z": -3,
      "name": "Empty"
    },
    {
      "x": 2,
      "y": 8,
      "z": -3,
      "name": "Empty"
    },
    {
      "x": 2,
      "y": 9,
      "z": -3,
      "name": "Empty"
    },
    {
      "x": 2,
      "y": 10,
      "z": -3,
      "name": "Empty"
    },
    {
      "x": 2,
      "y": 11,
      "z": -3,
      "name": "Empty"
    },
    {
      "x": 2,
      "y": 12,
      "z": -3,
      "name": "Rock_Quartzite"
    },
    {
      "x": 2,
      "y": 6,
      "z": -2,
      "name": "Rock_Stone_Cobble"
    },
    {
      "x": 2,
      "y": 7,
      "z": -2,
      "name": "Empty"
    },
    {
      "x": 2,
      "y": 8,
      "z": -2,
      "name": "Empty"
    },
    {
      "x": 2,
      "y": 9,
      "z": -2,
      "name": "Wood_Torch_Wall",
      "rotation": 3
    },
    {
      "x": 2,
      "y": 10,
      "z": -2,
      "name": "Empty"
    },
    {
      "x": 2,
      "y": 11,
      "z": -2,
      "name": "Empty"
    },
    {
      "x": 2,
      "y": 12,
      "z": -2,
      "name": "Empty"
    },
    {
      "x": 2,
      "y": 13,
      "z": -2,
      "name": "Rock_Quartzite"
    },
    {
      "x": 2,
      "y": 6,
      "z": -1,
      "name": "Rock_Stone"
    },
    {
      "x": 2,
      "y": 7,
      "z": -1,
      "name": "Rock_Stone_Cobble"
    },
    {
      "x": 2,
      "y": 8,
      "z": -1,
      "name": "Rock_Stone_Cobble_Stairs",
      "rotation": 2
    },
    {
      "x": 2,
      "y": 9,
      "z": -1,
      "name": "Empty"
    },
    {
      "x": 2,
      "y": 10,
      "z": -1,
      "name": "Empty"
    },
    {
      "x": 2,
      "y": 11,
      "z": -1,
      "name": "Empty"
    },
    {
      "x": 2,
      "y": 12,
      "z": -1,
      "name": "Empty"
    },
    {
      "x": 2,
      "y": 13,
      "z": -1,
      "name": "Empty"
    },
    {
      "x": 2,
      "y": 7,
      "z": 0,
      "name": "Rock_Stone"
    },
    {
      "x": 2,
      "y": 8,
      "z": 0,
      "name": "Rock_Stone_Cobble"
    },
    {
      "x": 2,
      "y": 9,
      "z": 0,
      "name": "Rock_Stone_Cobble_Stairs",
      "rotation": 2
    },
    {
      "x": 2,
      "y": 10,
      "z": 0,
      "name": "Empty"
    },
    {
      "x": 2,
      "y": 11,
      "z": 0,
      "name": "Empty"
    },
    {
      "x": 2,
      "y": 12,
      "z": 0,
      "name": "Empty"
    },
    {
      "x": 2,
      "y": 13,
      "z": 0,
      "name": "Empty"
    },
    {
      "x": 2,
      "y": 14,
      "z": 0,
      "name": "Empty"
    },
    {
      "x": 2,
      "y": 9,
      "z": 1,
      "name": "Rock_Stone_Cobble"
    },
    {
      "x": 2,
      "y": 10,
      "z": 1,
      "name": "Rock_Stone_Cobble_Stairs",
      "rotation": 2
    },
    {
      "x": 2,
      "y": 11,
      "z": 1,
      "name": "Empty"
    },
    {
      "x": 2,
      "y": 12,
      "z": 1,
      "name": "Empty"
    },
    {
      "x": 2,
      "y": 13,
      "z": 1,
      "name": "Empty"
    },
    {
      "x": 2,
      "y": 14,
      "z": 1,
      "name": "Empty"
    },
    {
      "x": 2,
      "y": 15,
      "z": 1,
      "name": "Empty"
    },
    {
      "x": 2,
      "y": 10,
      "z": 2,
      "name": "Rock_Stone_Cobble"
    },
    {
      "x": 2,
      "y": 11,
      "z": 2,
      "name": "Rock_Stone_Cobble_Stairs",
      "rotation": 2
    },
    {
      "x": 2,
      "y": 12,
      "z": 2,
      "name": "Empty"
    },
    {
      "x": 2,
      "y": 13,
      "z": 2,
      "name": "Empty"
    },
    {
      "x": 2,
      "y": 14,
      "z": 2,
      "name": "Empty"
    },
    {
      "x": 2,
      "y": 15,
      "z": 2,
      "name": "Empty"
    },
    {
      "x": 2,
      "y": 16,
      "z": 2,
      "name": "Empty"
    },
    {
      "x": 2,
      "y": 10,
      "z": 3,
      "name": "Rock_Stone_Cobble"
    },
    {
      "x": 2,
      "y": 11,
      "z": 3,
      "name": "Rock_Stone_Cobble"
    },
    {
      "x": 2,
      "y": 12,
      "z": 3,
      "name": "Rock_Stone_Cobble_Stairs",
      "rotation": 2
    },
    {
      "x": 2,
      "y": 13,
      "z": 3,
      "name": "Empty"
    },
    {
      "x": 2,
      "y": 14,
      "z": 3,
      "name": "Empty"
    },
    {
      "x": 2,
      "y": 15,
      "z": 3,
      "name": "Empty"
    },
    {
      "x": 2,
      "y": 16,
      "z": 3,
      "name": "Empty"
    },
    {
      "x": 2,
      "y": 17,
      "z": 3,
      "name": "Empty"
    },
    {
      "x": 2,
      "y": 11,
      "z": 4,
      "name": "Rock_Stone_Cobble"
    },
    {
      "x": 2,
      "y": 12,
      "z": 4,
      "name": "Rock_Stone_Cobble"
    },
    {
      "x": 2,
      "y": 13,
      "z": 4,
      "name": "Rock_Stone_Cobble_Stairs",
      "rotation": 2
    },
    {
      "x": 2,
      "y": 14,
      "z": 4,
      "name": "Empty"
    },
    {
      "x": 2,
      "y": 15,
      "z": 4,
      "name": "Empty"
    },
    {
      "x": 2,
      "y": 16,
      "z": 4,
      "name": "Empty"
    },
    {
      "x": 2,
      "y": 17,
      "z": 4,
      "name": "Empty"
    },
    {
      "x": 2,
      "y": 18,
      "z": 4,
      "name": "Empty"
    },
    {
      "x": 2,
      "y": 13,
      "z": 5,
      "name": "Rock_Stone_Cobble"
    },
    {
      "x": 2,
      "y": 14,
      "z": 5,
      "name": "Rock_Stone_Cobble_Stairs",
      "rotation": 2
    },
    {
      "x": 2,
      "y": 15,
      "z": 5,
      "name": "Empty"
    },
    {
      "x": 2,
      "y": 16,
      "z": 5,
      "name": "Empty"
    },
    {
      "x": 2,
      "y": 17,
      "z": 5,
      "name": "Empty"
    },
    {
      "x": 2,
      "y": 18,
      "z": 5,
      "name": "Empty"
    },
    {
      "x": 2,
      "y": 13,
      "z": 6,
      "name": "Rock_Stone_Cobble"
    },
    {
      "x": 2,
      "y": 14,
      "z": 6,
      "name": "Rock_Stone_Cobble"
    },
    {
      "x": 2,
      "y": 15,
      "z": 6,
      "name": "Rock_Stone_Cobble_Stairs",
      "rotation": 2
    },
    {
      "x": 2,
      "y": 16,
      "z": 6,
      "name": "Empty"
    },
    {
      "x": 2,
      "y": 17,
      "z": 6,
      "name": "Empty"
    },
    {
      "x": 2,
      "y": 18,
      "z": 6,
      "name": "Empty"
    },
    {
      "x": 2,
      "y": 13,
      "z": 7,
      "name": "Rock_Quartzite_Brick"
    },
    {
      "x": 2,
      "y": 14,
      "z": 7,
      "name": "Rock_Quartzite_Brick"
    },
    {
      "x": 2,
      "y": 15,
      "z": 7,
      "name": "Rock_Stone_Cobble"
    },
    {
      "x": 2,
      "y": 16,
      "z": 7,
      "name": "Rock_Stone_Cobble_Stairs",
      "rotation": 2
    },
    {
      "x": 2,
      "y": 17,
      "z": 7,
      "name": "Empty"
    },
    {
      "x": 2,
      "y": 18,
      "z": 7,
      "name": "Empty"
    },
    {
      "x": 2,
      "y": 13,
      "z": 8,
      "name": "Rock_Quartzite_Brick"
    },
    {
      "x": 2,
      "y": 14,
      "z": 8,
      "name": "Rock_Quartzite_Brick"
    },
    {
      "x": 2,
      "y": 15,
      "z": 8,
      "name": "Rock_Quartzite_Brick"
    },
    {
      "x": 2,
      "y": 16,
      "z": 8,
      "name": "Rock_Stone_Cobble"
    },
    {
      "x": 2,
      "y": 17,
      "z": 8,
      "name": "Rock_Stone_Cobble_Stairs",
      "rotation": 2
    },
    {
      "x": 2,
      "y": 18,
      "z": 8,
      "name": "Empty"
    },
    {
      "x": 2,
      "y": 13,
      "z": 9,
      "name": "Rock_Quartzite_Brick"
    },
    {
      "x": 2,
      "y": 14,
      "z": 9,
      "name": "Rock_Quartzite_Brick"
    },
    {
      "x": 2,
      "y": 15,
      "z": 9,
      "name": "Rock_Quartzite_Brick"
    },
    {
      "x": 2,
      "y": 16,
      "z": 9,
      "name": "Rock_Quartzite_Brick"
    },
    {
      "x": 2,
      "y": 17,
      "z": 9,
      "name": "Rock_Stone_Cobble"
    },
    {
      "x": 2,
      "y": 18,
      "z": 9,
      "name": "Rock_Stone_Cobble_Half"
    },
    {
      "x": 2,
      "y": 13,
      "z": 10,
      "name": "Rock_Quartzite_Brick"
    },
    {
      "x": 2,
      "y": 14,
      "z": 10,
      "name": "Rock_Quartzite_Brick"
    },
    {
      "x": 2,
      "y": 15,
      "z": 10,
      "name": "Rock_Quartzite_Brick"
    },
    {
      "x": 2,
      "y": 16,
      "z": 10,
      "name": "Rock_Quartzite_Brick"
    },
    {
      "x": 2,
      "y": 17,
      "z": 10,
      "name": "Rock_Quartzite_Brick"
    },
    {
      "x": 2,
      "y": 18,
      "z": 10,
      "name": "Soil_Gravel"
    },
    {
      "x": 3,
      "y": 0,
      "z": -10,
      "name": "Rock_Quartzite"
    },
    {
      "x": 3,
      "y": 1,
      "z": -10,
      "name": "Rock_Quartzite"
    },
    {
      "x": 3,
      "y": 2,
      "z": -10,
      "name": "Rock_Quartzite"
    },
    {
      "x": 3,
      "y": 3,
      "z": -10,
      "name": "Rock_Quartzite_Brick"
    },
    {
      "x": 3,
      "y": 4,
      "z": -10,
      "name": "Rock_Quartzite_Brick"
    },
    {
      "x": 3,
      "y": 5,
      "z": -10,
      "name": "Rock_Quartzite_Brick"
    },
    {
      "x": 3,
      "y": 0,
      "z": -9,
      "name": "Rock_Quartzite"
    },
    {
      "x": 3,
      "y": 1,
      "z": -9,
      "name": "Rock_Quartzite"
    },
    {
      "x": 3,
      "y": 2,
      "z": -9,
      "name": "Rock_Quartzite"
    },
    {
      "x": 3,
      "y": 3,
      "z": -9,
      "name": "Rock_Quartzite"
    },
    {
      "x": 3,
      "y": 4,
      "z": -9,
      "name": "Rock_Quartzite_Brick"
    },
    {
      "x": 3,
      "y": 5,
      "z": -9,
      "name": "Rock_Quartzite_Brick"
    },
    {
      "x": 3,
      "y": 6,
      "z": -9,
      "name": "Rock_Quartzite_Brick"
    },
    {
      "x": 3,
      "y": 1,
      "z": -8,
      "name": "Rock_Quartzite"
    },
    {
      "x": 3,
      "y": 2,
      "z": -8,
      "name": "Rock_Quartzite"
    },
    {
      "x": 3,
      "y": 3,
      "z": -8,
      "name": "Empty"
    },
    {
      "x": 3,
      "y": 4,
      "z": -8,
      "name": "Empty"
    },
    {
      "x": 3,
      "y": 5,
      "z": -8,
      "name": "Rock_Quartzite_Brick"
    },
    {
      "x": 3,
      "y": 6,
      "z": -8,
      "name": "Rock_Quartzite"
    },
    {
      "x": 3,
      "y": 7,
      "z": -8,
      "name": "Rock_Quartzite"
    },
    {
      "x": 3,
      "y": 1,
      "z": -7,
      "name": "Rock_Quartzite"
    },
    {
      "x": 3,
      "y": 2,
      "z": -7,
      "name": "Rock_Quartzite"
    },
    {
      "x": 3,
      "y": 3,
      "z": -7,
      "name": "Empty"
    },
    {
      "x": 3,
      "y": 4,
      "z": -7,
      "name": "Empty"
    },
    {
      "x": 3,
      "y": 5,
      "z": -7,
      "name": "Empty"
    },
    {
      "x": 3,
      "y": 6,
      "z": -7,
      "name": "Empty"
    },
    {
      "x": 3,
      "y": 7,
      "z": -7,
      "name": "Rock_Quartzite_Brick"
    },
    {
      "x": 3,
      "y": 8,
      "z": -7,
      "name": "Rock_Quartzite_Brick"
    },
    {
      "x": 3,
      "y": 2,
      "z": -6,
      "name": "Rock_Quartzite"
    },
    {
      "x": 3,
      "y": 3,
      "z": -6,
      "name": "Empty"
    },
    {
      "x": 3,
      "y": 4,
      "z": -6,
      "name": "Empty"
    },
    {
      "x": 3,
      "y": 5,
      "z": -6,
      "name": "Empty"
    },
    {
      "x": 3,
      "y": 6,
      "z": -6,
      "name": "Empty"
    },
    {
      "x": 3,
      "y": 7,
      "z": -6,
      "name": "Empty"
    },
    {
      "x": 3,
      "y": 8,
      "z": -6,
      "name": "Rock_Quartzite_Brick"
    },
    {
      "x": 3,
      "y": 9,
      "z": -6,
      "name": "Rock_Quartzite_Brick"
    },
    {
      "x": 3,
      "y": 2,
      "z": -5,
      "name": "Rock_Stone"
    },
    {
      "x": 3,
      "y": 3,
      "z": -5,
      "name": "Rock_Stone"
    },
    {
      "x": 3,
      "y": 4,
      "z": -5,
      "name": "Rock_Stone"
    },
    {
      "x": 3,
      "y": 5,
      "z": -5,
      "name": "Empty"
    },
    {
      "x": 3,
      "y": 6,
      "z": -5,
      "name": "Empty"
    },
    {
      "x": 3,
      "y": 7,
      "z": -5,
      "name": "Empty"
    },
    {
      "x": 3,
      "y": 8,
      "z": -5,
      "name": "Empty"
    },
    {
      "x": 3,
      "y": 9,
      "z": -5,
      "name": "Rock_Quartzite_Brick"
    },
    {
      "x": 3,
      "y": 10,
      "z": -5,
      "name": "Rock_Quartzite"
    },
    {
      "x": 3,
      "y": 4,
      "z": -4,
      "name": "Rock_Stone"
    },
    {
      "x": 3,
      "y": 5,
      "z": -4,
      "name": "Rock_Stone_Cobble"
    },
    {
      "x": 3,
      "y": 6,
      "z": -4,
      "name": "Rock_Stone_Cobble"
    },
    {
      "x": 3,
      "y": 7,
      "z": -4,
      "name": "Rock_Quartzite_Brick"
    },
    {
      "x": 3,
      "y": 8,
      "z": -4,
      "name": "Rock_Quartzite_Brick"
    },
    {
      "x": 3,
      "y": 9,
      "z": -4,
      "name": "Rock_Quartzite_Brick"
    },
    {
      "x": 3,
      "y": 10,
      "z": -4,
      "name": "Rock_Quartzite"
    },
    {
      "x": 3,
      "y": 11,
      "z": -4,
      "name": "Rock_Quartzite"
    },
    {
      "x": 3,
      "y": 6,
      "z": -3,
      "name": "Rock_Stone_Cobble"
    },
    {
      "x": 3,
      "y": 7,
      "z": -3,
      "name": "Rock_Stone_Cobble"
    },
    {
      "x": 3,
      "y": 8,
      "z": -3,
      "name": "Rock_Quartzite_Brick"
    },
    {
      "x": 3,
      "y": 9,
      "z": -3,
      "name": "Rock_Quartzite_Brick"
    },
    {
      "x": 3,
      "y": 10,
      "z": -3,
      "name": "Rock_Quartzite"
    },
    {
      "x": 3,
      "y": 11,
      "z": -3,
      "name": "Rock_Quartzite"
    },
    {
      "x": 3,
      "y": 12,
      "z": -3,
      "name": "Rock_Quartzite"
    },
    {
      "x": 3,
      "y": 7,
      "z": -2,
      "name": "Rock_Stone_Cobble"
    },
    {
      "x": 3,
      "y": 8,
      "z": -2,
      "name": "Rock_Quartzite_Brick"
    },
    {
      "x": 3,
      "y": 9,
      "z": -2,
      "name": "Rock_Quartzite_Brick"
    },
    {
      "x": 3,
      "y": 10,
      "z": -2,
      "name": "Rock_Quartzite"
    },
    {
      "x": 3,
      "y": 11,
      "z": -2,
      "name": "Rock_Quartzite"
    },
    {
      "x": 3,
      "y": 12,
      "z": -2,
      "name": "Rock_Quartzite"
    },
    {
      "x": 3,
      "y": 13,
      "z": -2,
      "name": "Rock_Quartzite"
    },
    {
      "x": 3,
      "y": 7,
      "z": -1,
      "name": "Rock_Quartzite"
    },
    {
      "x": 3,
      "y": 8,
      "z": -1,
      "name": "Rock_Quartzite_Brick"
    },
    {
      "x": 3,
      "y": 9,
      "z": -1,
      "name": "Rock_Quartzite_Brick"
    },
    {
      "x": 3,
      "y": 10,
      "z": -1,
      "name": "Rock_Quartzite_Brick"
    },
    {
      "x": 3,
      "y": 11,
      "z": -1,
      "name": "Rock_Quartzite"
    },
    {
      "x": 3,
      "y": 12,
      "z": -1,
      "name": "Rock_Quartzite"
    },
    {
      "x": 3,
      "y": 13,
      "z": -1,
      "name": "Rock_Quartzite"
    },
    {
      "x": 3,
      "y": 8,
      "z": 0,
      "name": "Rock_Quartzite_Brick"
    },
    {
      "x": 3,
      "y": 9,
      "z": 0,
      "name": "Rock_Quartzite_Brick"
    },
    {
      "x": 3,
      "y": 10,
      "z": 0,
      "name": "Rock_Quartzite_Brick"
    },
    {
      "x": 3,
      "y": 11,
      "z": 0,
      "name": "Empty"
    },
    {
      "x": 3,
      "y": 12,
      "z": 0,
      "name": "Empty"
    },
    {
      "x": 3,
      "y": 13,
      "z": 0,
      "name": "Empty"
    },
    {
      "x": 3,
      "y": 9,
      "z": 1,
      "name": "Rock_Quartzite_Brick"
    },
    {
      "x": 3,
      "y": 10,
      "z": 1,
      "name": "Rock_Quartzite_Brick"
    },
    {
      "x": 3,
      "y": 11,
      "z": 1,
      "name": "Rock_Quartzite"
    },
    {
      "x": 3,
      "y": 12,
      "z": 1,
      "name": "Empty"
    },
    {
      "x": 3,
      "y": 13,
      "z": 1,
      "name": "Empty"
    },
    {
      "x": 3,
      "y": 10,
      "z": 2,
      "name": "Rock_Quartzite"
    },
    {
      "x": 3,
      "y": 11,
      "z": 2,
      "name": "Rock_Quartzite"
    },
    {
      "x": 3,
      "y": 12,
      "z": 2,
      "name": "Rock_Quartzite"
    },
    {
      "x": 3,
      "y": 13,
      "z": 2,
      "name": "Empty"
    },
    {
      "x": 3,
      "y": 11,
      "z": 3,
      "name": "Rock_Quartzite"
    },
    {
      "x": 3,
      "y": 12,
      "z": 3,
      "name": "Rock_Quartzite"
    },
    {
      "x": 3,
      "y": 13,
      "z": 3,
      "name": "Rock_Quartzite"
    },
    {
      "x": 3,
      "y": 13,
      "z": 4,
      "name": "Rock_Quartzite"
    },
    {
      "x": 3,
      "y": 13,
      "z": 5,
      "name": "Rock_Stone_Cobble"
    },
    {
      "x": 4,
      "y": 1,
      "z": -10,
      "name": "Rock_Quartzite"
    },
    {
      "x": 4,
      "y": 2,
      "z": -10,
      "name": "Rock_Quartzite"
    },
    {
      "x": 4,
      "y": 3,
      "z": -10,
      "name": "Rock_Quartzite"
    },
    {
      "x": 4,
      "y": 1,
      "z": -9,
      "name": "Rock_Quartzite"
    },
    {
      "x": 4,
      "y": 2,
      "z": -9,
      "name": "Rock_Quartzite"
    },
    {
      "x": 4,
      "y": 3,
      "z": -9,
      "name": "Rock_Quartzite"
    },
    {
      "x": 4,
      "y": 4,
      "z": -9,
      "name": "Rock_Quartzite_Brick"
    },
    {
      "x": 4,
      "y": 5,
      "z": -9,
      "name": "Rock_Quartzite_Brick"
    },
    {
      "x": 4,
      "y": 1,
      "z": -8,
      "name": "Rock_Stone"
    },
    {
      "x": 4,
      "y": 2,
      "z": -8,
      "name": "Rock_Quartzite"
    },
    {
      "x": 4,
      "y": 3,
      "z": -8,
      "name": "Rock_Quartzite"
    },
    {
      "x": 4,
      "y": 4,
      "z": -8,
      "name": "Rock_Stone"
    },
    {
      "x": 4,
      "y": 5,
      "z": -8,
      "name": "Rock_Stone"
    },
    {
      "x": 4,
      "y": 6,
      "z": -8,
      "name": "Rock_Stone"
    },
    {
      "x": 4,
      "y": 1,
      "z": -7,
      "name": "Rock_Stone"
    },
    {
      "x": 4,
      "y": 2,
      "z": -7,
      "name": "Rock_Stone"
    },
    {
      "x": 4,
      "y": 3,
      "z": -7,
      "name": "Rock_Stone"
    },
    {
      "x": 4,
      "y": 6,
      "z": -7,
      "name": "Rock_Quartzite"
    },
    {
      "x": 4,
      "y": 7,
      "z": -7,
      "name": "Rock_Quartzite_Brick"
    },
    {
      "x": 4,
      "y": 8,
      "z": -7,
      "name": "Rock_Quartzite_Brick"
    },
    {
      "x": 4,
      "y": 1,
      "z": -6,
      "name": "Rock_Stone"
    },
    {
      "x": 4,
      "y": 2,
      "z": -6,
      "name": "Rock_Stone"
    },
    {
      "x": 4,
      "y": 3,
      "z": -6,
      "name": "Rock_Stone"
    },
    {
      "x": 4,
      "y": 4,
      "z": -6,
      "name": "Rock_Stone"
    },
    {
      "x": 4,
      "y": 7,
      "z": -6,
      "name": "Rock_Quartzite_Brick"
    },
    {
      "x": 4,
      "y": 8,
      "z": -6,
      "name": "Rock_Quartzite_Brick"
    },
    {
      "x": 4,
      "y": 2,
      "z": -5,
      "name": "Rock_Stone"
    },
    {
      "x": 4,
      "y": 3,
      "z": -5,
      "name": "Rock_Stone"
    },
    {
      "x": 4,
      "y": 4,
      "z": -5,
      "name": "Rock_Stone"
    },
    {
      "x": 4,
      "y": 5,
      "z": -5,
      "name": "Rock_Stone"
    },
    {
      "x": 4,
      "y": 6,
      "z": -5,
      "name": "Rock_Stone"
    },
    {
      "x": 4,
      "y": 7,
      "z": -5,
      "name": "Rock_Quartzite_Brick"
    },
    {
      "x": 4,
      "y": 8,
      "z": -5,
      "name": "Rock_Quartzite_Brick"
    },
    {
      "x": 4,
      "y": 9,
      "z": -5,
      "name": "Rock_Quartzite_Brick"
    },
    {
      "x": 4,
      "y": 7,
      "z": -4,
      "name": "Rock_Quartzite_Brick"
    },
    {
      "x": 4,
      "y": 8,
      "z": -4,
      "name": "Rock_Quartzite_Brick"
    },
    {
      "x": 4,
      "y": 9,
      "z": -4,
      "name": "Rock_Quartzite_Brick"
    },
    {
      "x": 4,
      "y": 10,
      "z": -4,
      "name": "Rock_Quartzite"
    },
    {
      "x": 4,
      "y": 11,
      "z": -4,
      "name": "Rock_Quartzite"
    },
    {
      "x": 4,
      "y": 8,
      "z": -3,
      "name": "Rock_Quartzite_Brick"
    },
    {
      "x": 4,
      "y": 9,
      "z": -3,
      "name": "Rock_Quartzite_Brick"
    },
    {
      "x": 4,
      "y": 10,
      "z": -3,
      "name": "Rock_Quartzite_Brick"
    },
    {
      "x": 4,
      "y": 11,
      "z": -3,
      "name": "Rock_Quartzite"
    },
    {
      "x": 4,
      "y": 12,
      "z": -3,
      "name": "Rock_Quartzite"
    },
    {
      "x": 4,
      "y": 8,
      "z": -2,
      "name": "Rock_Quartzite_Brick"
    },
    {
      "x": 4,
      "y": 9,
      "z": -2,
      "name": "Rock_Quartzite_Brick"
    },
    {
      "x": 4,
      "y": 10,
      "z": -2,
      "name": "Rock_Quartzite"
    },
    {
      "x": 4,
      "y": 11,
      "z": -2,
      "name": "Rock_Quartzite"
    },
    {
      "x": 4,
      "y": 12,
      "z": -2,
      "name": "Rock_Quartzite"
    },
    {
      "x": 4,
      "y": 9,
      "z": -1,
      "name": "Rock_Quartzite_Brick"
    },
    {
      "x": 4,
      "y": 10,
      "z": -1,
      "name": "Rock_Quartzite_Brick"
    },
    {
      "x": 4,
      "y": 11,
      "z": -1,
      "name": "Rock_Quartzite"
    },
    {
      "x": 4,
      "y": 12,
      "z": -1,
      "name": "Rock_Quartzite"
    },
    {
      "x": 4,
      "y": 13,
      "z": -1,
      "name": "Rock_Quartzite"
    },
    {
      "x": 4,
      "y": 9,
      "z": 0,
      "name": "Rock_Quartzite_Brick"
    },
    {
      "x": 4,
      "y": 10,
      "z": 0,
      "name": "Rock_Quartzite_Brick"
    },
    {
      "x": 4,
      "y": 11,
      "z": 0,
      "name": "Rock_Quartzite_Brick"
    },
    {
      "x": 4,
      "y": 10,
      "z": 1,
      "name": "Rock_Quartzite_Brick"
    },
    {
      "x": 4,
      "y": 11,
      "z": 1,
      "name": "Rock_Quartzite"
    },
    {
      "x": 4,
      "y": 12,
      "z": 1,
      "name": "Rock_Quartzite"
    },
    {
      "x": 4,
      "y": 11,
      "z": 2,
      "name": "Rock_Quartzite"
    },
    {
      "x": 4,
      "y": 12,
      "z": 2,
      "name": "Rock_Quartzite"
    },
    {
      "x": 4,
      "y": 12,
      "z": 3,
      "name": "Rock_Quartzite"
    },
    {
      "x": 4,
      "y": 13,
      "z": 3,
      "name": "Rock_Quartzite"
    },
    {
      "x": 5,
      "y": 2,
      "z": -8,
      "name": "Rock_Stone"
    },
    {
      "x": 5,
      "y": 3,
      "z": -8,
      "name": "Rock_Stone"
    },
    {
      "x": 5,
      "y": 2,
      "z": -7,
      "name": "Rock_Stone"
    },
    {
      "x": 5,
      "y": 3,
      "z": -7,
      "name": "Rock_Stone"
    },
    {
      "x": 5,
      "y": 4,
      "z": -7,
      "name": "Rock_Stone"
    },
    {
      "x": 5,
      "y": 5,
      "z": -7,
      "name": "Rock_Stone"
    },
    {
      "x": 5,
      "y": 6,
      "z": -7,
      "name": "Rock_Stone"
    },
    {
      "x": 5,
      "y": 2,
      "z": -6,
      "name": "Rock_Stone"
    },
    {
      "x": 5,
      "y": 3,
      "z": -6,
      "name": "Rock_Stone"
    },
    {
      "x": 5,
      "y": 4,
      "z": -6,
      "name": "Rock_Stone"
    },
    {
      "x": 5,
      "y": 5,
      "z": -6,
      "name": "Rock_Stone"
    },
    {
      "x": 5,
      "y": 6,
      "z": -6,
      "name": "Rock_Stone"
    },
    {
      "x": 5,
      "y": 3,
      "z": -5,
      "name": "Rock_Stone"
    },
    {
      "x": 5,
      "y": 4,
      "z": -5,
      "name": "Rock_Stone"
    },
    {
      "x": 5,
      "y": 5,
      "z": -5,
      "name": "Rock_Stone"
    }
  ]
}