{
  "version": 8,
  "blockIdVersion": 8,
  "anchorX": 6,
  "anchorY": 38,
  "anchorZ": 10,
  "blocks": [
    {
      "x": -15,
      "y": 68,
      "z": -6,
      "name": "Rock_Volcanic"
    },
    {
      "x": -15,
      "y": 69,
      "z": -6,
      "name": "Rock_Volcanic"
    },
    {
      "x": -15,
      "y": 65,
      "z": -5,
      "name": "Rock_Volcanic"
    },
    {
      "x": -15,
      "y": 66,
      "z": -5,
      "name": "Rock_Volcanic"
    },
    {
      "x": -15,
      "y": 67,
      "z": -5,
      "name": "Rock_Volcanic"
    },
    {
      "x": -14,
      "y": 66,
      "z": -6,
      "name": "Rock_Volcanic"
    },
    {
      "x": -14,
      "y": 67,
      "z": -6,
      "name": "Rock_Volcanic"
    },
    {
      "x": -14,
      "y": 64,
      "z": -5,
      "name": "Rock_Volcanic"
    },
    {
      "x": -14,
      "y": 65,
      "z": -5,
      "name": "Rock_Volcanic"
    },
    {
      "x": -14,
      "y": 66,
      "z": -5,
      "name": "Rock_Volcanic"
    },
    {
      "x": -14,
      "y": 67,
      "z": -5,
      "name": "Rock_Volcanic"
    },
    {
      "x": -14,
      "y": 68,
      "z": -5,
      "name": "Rock_Volcanic"
    },
    {
      "x": -14,
      "y": 63,
      "z": -4,
      "name": "Rock_Volcanic"
    },
    {
      "x": -14,
      "y": 64,
      "z": -4,
      "name": "Rock_Volcanic"
    },
    {
      "x": -14,
      "y": 65,
      "z": -4,
      "name": "Rock_Volcanic"
    },
    {
      "x": -14,
      "y": 66,
      "z": -4,
      "name": "Rock_Volcanic"
    },
    {
      "x": -13,
      "y": 63,
      "z": -5,
      "name": "Rock_Volcanic"
    },
    {
      "x": -13,
      "y": 64,
      "z": -5,
      "name": "Rock_Volcanic"
    },
    {
      "x": -13,
      "y": 65,
      "z": -5,
      "name": "Rock_Volcanic"
    },
    {
      "x": -13,
      "y": 66,
      "z": -5,
      "name": "Rock_Volcanic"
    },
    {
      "x": -13,
      "y": 62,
      "z": -4,
      "name": "Rock_Volcanic"
    },
    {
      "x": -13,
      "y": 63,
      "z": -4,
      "name": "Rock_Volcanic"
    },
    {
      "x": -13,
      "y": 64,
      "z": -4,
      "name": "Rock_Volcanic"
    },
    {
      "x": -13,
      "y": 65,
      "z": -4,
      "name": "Rock_Volcanic"
    },
    {
      "x": -13,
      "y": 63,
      "z": -3,
      "name": "Rock_Volcanic"
    },
    {
      "x": -13,
      "y": 64,
      "z": -3,
      "name": "Rock_Volcanic"
    },
    {
      "x": -12,
      "y": 62,
      "z": -5,
      "name": "Rock_Volcanic"
    },
    {
      "x": -12,
      "y": 63,
      "z": -5,
      "name": "Rock_Volcanic"
    },
    {
      "x": -12,
      "y": 64,
      "z": -5,
      "name": "Rock_Volcanic"
    },
    {
      "x": -12,
      "y": 59,
      "z": -4,
      "name": "Rock_Volcanic"
    },
    {
      "x": -12,
      "y": 60,
      "z": -4,
      "name": "Rock_Volcanic"
    },
    {
      "x": -12,
      "y": 61,
      "z": -4,
      "name": "Rock_Volcanic"
    },
    {
      "x": -12,
      "y": 62,
      "z": -4,
      "name": "Rock_Volcanic_Cracked_Lava"
    },
    {
      "x": -12,
      "y": 63,
      "z": -4,
      "name": "Rock_Volcanic"
    },
    {
      "x": -12,
      "y": 64,
      "z": -4,
      "name": "Rock_Volcanic"
    },
    {
      "x": -12,
      "y": 59,
      "z": -3,
      "name": "Rock_Volcanic"
    },
    {
      "x": -12,
      "y": 60,
      "z": -3,
      "name": "Rock_Volcanic_Cracked_Lava"
    },
    {
      "x": -12,
      "y": 61,
      "z": -3,
      "name": "Rock_Volcanic_Cracked_Lava"
    },
    {
      "x": -12,
      "y": 62,
      "z": -3,
      "name": "Rock_Volcanic_Cracked_Lava"
    },
    {
      "x": -12,
      "y": 63,
      "z": -3,
      "name": "Rock_Volcanic_Cracked_Lava"
    },
    {
      "x": -12,
      "y": 64,
      "z": -3,
      "name": "Rock_Volcanic"
    },
    {
      "x": -12,
      "y": 60,
      "z": -2,
      "name": "Rock_Volcanic_Cracked_Lava"
    },
    {
      "x": -12,
      "y": 61,
      "z": -2,
      "name": "Rock_Volcanic_Cracked_Lava"
    },
    {
      "x": -12,
      "y": 62,
      "z": -2,
      "name": "Rock_Volcanic_Cracked_Lava"
    },
    {
      "x": -11,
      "y": 59,
      "z": -4,
      "name": "Rock_Volcanic"
    },
    {
      "x": -11,
      "y": 60,
      "z": -4,
      "name": "Rock_Volcanic"
    },
    {
      "x": -11,
      "y": 61,
      "z": -4,
      "name": "Rock_Volcanic"
    },
    {
      "x": -11,
      "y": 62,
      "z": -4,
      "name": "Rock_Volcanic_Cracked_Lava"
    },
    {
      "x": -11,
      "y": 63,
      "z": -4,
      "name": "Rock_Volcanic"
    },
    {
      "x": -11,
      "y": 57,
      "z": -3,
      "name": "Rock_Volcanic"
    },
    {
      "x": -11,
      "y": 58,
      "z": -3,
      "name": "Rock_Volcanic"
    },
    {
      "x": -11,
      "y": 59,
      "z": -3,
      "name": "Rock_Volcanic"
    },
    {
      "x": -11,
      "y": 60,
      "z": -3,
      "name": "Rock_Volcanic_Cracked_Lava"
    },
    {
      "x": -11,
      "y": 61,
      "z": -3,
      "name": "Rock_Volcanic_Cracked_Lava"
    },
    {
      "x": -11,
      "y": 62,
      "z": -3,
      "name": "Rock_Volcanic_Cracked_Lava"
    },
    {
      "x": -11,
      "y": 63,
      "z": -3,
      "name": "Rock_Volcanic_Cracked_Lava"
    },
    {
      "x": -11,
      "y": 57,
      "z": -2,
      "name": "Rock_Volcanic"
    },
    {
      "x": -11,
      "y": 58,
      "z": -2,
      "name": "Rock_Volcanic"
    },
    {
      "x": -11,
      "y": 59,
      "z": -2,
      "name": "Rock_Volcanic_Cracked_Lava"
    },
    {
      "x": -11,
      "y": 60,
      "z": -2,
      "name": "Rock_Volcanic_Cracked_Lava"
    },
    {
      "x": -11,
      "y": 61,
      "z": -2,
      "name": "Rock_Volcanic_Cracked_Lava"
    },
    {
      "x": -11,
      "y": 62,
      "z": -2,
      "name": "Rock_Volcanic_Cracked_Lava"
    },
    {
      "x": -11,
      "y": 57,
      "z": -1,
      "name": "Rock_Volcanic"
    },
    {
      "x": -11,
      "y": 58,
      "z": -1,
      "name": "Rock_Volcanic"
    },
    {
      "x": -11,
      "y": 59,
      "z": -1,
      "name": "Rock_Volcanic_Cracked_Lava"
    },
    {
      "x": -11,
      "y": 60,
      "z": -1,
      "name": "Rock_Volcanic_Cracked_Lava"
    },
    {
      "x": -10,
      "y": 60,
      "z": -4,
      "name": "Rock_Volcanic"
    },
    {
      "x": -10,
      "y": 61,
      "z": -4,
      "name": "Rock_Volcanic"
    },
    {
      "x": -10,
      "y": 62,
      "z": -4,
      "name": "Rock_Volcanic_Cracked_Lava"
    },
    {
      "x": -10,
      "y": 58,
      "z": -3,
      "name": "Rock_Volcanic"
    },
    {
      "x": -10,
      "y": 59,
      "z": -3,
      "name": "Rock_Volcanic"
    },
    {
      "x": -10,
      "y": 60,
      "z": -3,
      "name": "Rock_Volcanic_Cracked_Lava"
    },
    {
      "x": -10,
      "y": 61,
      "z": -3,
      "name": "Rock_Volcanic_Cracked_Lava"
    },
    {
      "x": -10,
      "y": 56,
      "z": -2,
      "name": "Rock_Volcanic"
    },
    {
      "x": -10,
      "y": 57,
      "z": -2,
      "name": "Rock_Volcanic"
    },
    {
      "x": -10,
      "y": 58,
      "z": -2,
      "name": "Rock_Volcanic"
    },
    {
      "x": -10,
      "y": 59,
      "z": -2,
      "name": "Rock_Volcanic_Cracked_Lava"
    },
    {
      "x": -10,
      "y": 60,
      "z": -2,
      "name": "Rock_Volcanic_Cracked_Lava"
    },
    {
      "x": -10,
      "y": 61,
      "z": -2,
      "name": "Rock_Volcanic_Cracked_Lava"
    },
    {
      "x": -10,
      "y": 55,
      "z": -1,
      "name": "Rock_Volcanic"
    },
    {
      "x": -10,
      "y": 56,
      "z": -1,
      "name": "Rock_Volcanic"
    },
    {
      "x": -10,
      "y": 57,
      "z": -1,
      "name": "Rock_Volcanic"
    },
    {
      "x": -10,
      "y": 58,
      "z": -1,
      "name": "Rock_Volcanic_Cracked_Lava"
    },
    {
      "x": -10,
      "y": 59,
      "z": -1,
      "name": "Rock_Volcanic_Cracked_Lava"
    },
    {
      "x": -10,
      "y": 55,
      "z": 0,
      "name": "Rock_Volcanic"
    },
    {
      "x": -10,
      "y": 56,
      "z": 0,
      "name": "Rock_Volcanic"
    },
    {
      "x": -10,
      "y": 57,
      "z": 0,
      "name": "Rock_Volcanic"
    },
    {
      "x": -10,
      "y": 58,
      "z": 0,
      "name": "Rock_Volcanic_Cracked_Lava"
    },
    {
      "x": -9,
      "y": 58,
      "z": -3,
      "name": "Rock_Volcanic"
    },
    {
      "x": -9,
      "y": 59,
      "z": -3,
      "name": "Rock_Volcanic"
    },
    {
      "x": -9,
      "y": 60,
      "z": -3,
      "name": "Rock_Volcanic"
    },
    {
      "x": -9,
      "y": 55,
      "z": -2,
      "name": "Rock_Volcanic"
    },
    {
      "x": -9,
      "y": 56,
      "z": -2,
      "name": "Rock_Volcanic"
    },
    {
      "x": -9,
      "y": 57,
      "z": -2,
      "name": "Rock_Volcanic_Cracked_Lava"
    },
    {
      "x": -9,
      "y": 58,
      "z": -2,
      "name": "Rock_Volcanic_Cracked_Lava"
    },
    {
      "x": -9,
      "y": 59,
      "z": -2,
      "name": "Rock_Volcanic"
    },
    {
      "x": -9,
      "y": 60,
      "z": -2,
      "name": "Rock_Volcanic_Cracked_Lava"
    },
    {
      "x": -9,
      "y": 55,
      "z": -1,
      "name": "Rock_Volcanic"
    },
    {
      "x": -9,
      "y": 56,
      "z": -1,
      "name": "Rock_Volcanic"
    },
    {
      "x": -9,
      "y": 57,
      "z": -1,
      "name": "Rock_Volcanic_Cracked_Lava"
    },
    {
      "x": -9,
      "y": 58,
      "z": -1,
      "name": "Rock_Volcanic_Cracked_Lava"
    },
    {
      "x": -9,
      "y": 53,
      "z": 0,
      "name": "Rock_Volcanic"
    },
    {
      "x": -9,
      "y": 54,
      "z": 0,
      "name": "Rock_Volcanic"
    },
    {
      "x": -9,
      "y": 55,
      "z": 0,
      "name": "Rock_Volcanic"
    },
    {
      "x": -9,
      "y": 56,
      "z": 0,
      "name": "Rock_Volcanic"
    },
    {
      "x": -9,
      "y": 57,
      "z": 0,
      "name": "Rock_Volcanic_Cracked_Lava"
    },
    {
      "x": -9,
      "y": 58,
      "z": 0,
      "name": "Rock_Volcanic_Cracked_Lava"
    },
    {
      "x": -9,
      "y": 53,
      "z": 1,
      "name": "Rock_Volcanic"
    },
    {
      "x": -9,
      "y": 54,
      "z": 1,
      "name": "Rock_Volcanic"
    },
    {
      "x": -9,
      "y": 55,
      "z": 1,
      "name": "Rock_Volcanic"
    },
    {
      "x": -9,
      "y": 56,
      "z": 1,
      "name": "Rock_Volcanic"
    },
    {
      "x": -8,
      "y": 55,
      "z": -2,
      "name": "Rock_Volcanic"
    },
    {
      "x": -8,
      "y": 56,
      "z": -2,
      "name": "Rock_Volcanic_Cracked_Lava"
    },
    {
      "x": -8,
      "y": 57,
      "z": -2,
      "name": "Rock_Volcanic_Cracked_Lava"
    },
    {
      "x": -8,
      "y": 58,
      "z": -2,
      "name": "Rock_Volcanic_Cracked_Lava"
    },
    {
      "x": -8,
      "y": 59,
      "z": -2,
      "name": "Rock_Volcanic"
    },
    {
      "x": -8,
      "y": 53,
      "z": -1,
      "name": "Rock_Volcanic"
    },
    {
      "x": -8,
      "y": 54,
      "z": -1,
      "name": "Rock_Volcanic_Cracked_Lava"
    },
    {
      "x": -8,
      "y": 55,
      "z": -1,
      "name": "Rock_Volcanic"
    },
    {
      "x": -8,
      "y": 56,
      "z": -1,
      "name": "Rock_Volcanic_Cracked_Lava"
    },
    {
      "x": -8,
      "y": 57,
      "z": -1,
      "name": "Rock_Volcanic_Cracked_Lava"
    },
    {
      "x": -8,
      "y": 58,
      "z": -1,
      "name": "Rock_Volcanic_Cracked_Lava"
    },
    {
      "x": -8,
      "y": 52,
      "z": 0,
      "name": "Rock_Volcanic"
    },
    {
      "x": -8,
      "y": 53,
      "z": 0,
      "name": "Rock_Volcanic"
    },
    {
      "x": -8,
      "y": 54,
      "z": 0,
      "name": "Rock_Volcanic_Cracked_Lava"
    },
    {
      "x": -8,
      "y": 55,
      "z": 0,
      "name": "Rock_Volcanic"
    },
    {
      "x": -8,
      "y": 56,
      "z": 0,
      "name": "Rock_Volcanic_Cracked_Lava"
    },
    {
      "x": -8,
      "y": 57,
      "z": 0,
      "name": "Rock_Volcanic_Cracked_Lava"
    },
    {
      "x": -8,
      "y": 58,
      "z": 0,
      "name": "Rock_Volcanic_Cracked_Lava"
    },
    {
      "x": -8,
      "y": 51,
      "z": 1,
      "name": "Rock_Volcanic"
    },
    {
      "x": -8,
      "y": 52,
      "z": 1,
      "name": "Rock_Volcanic"
    },
    {
      "x": -8,
      "y": 53,
      "z": 1,
      "name": "Rock_Volcanic"
    },
    {
      "x": -8,
      "y": 54,
      "z": 1,
      "name": "Rock_Volcanic_Cracked_Lava"
    },
    {
      "x": -8,
      "y": 55,
      "z": 1,
      "name": "Rock_Volcanic"
    },
    {
      "x": -8,
      "y": 56,
      "z": 1,
      "name": "Rock_Volcanic"
    },
    {
      "x": -8,
      "y": 51,
      "z": 2,
      "name": "Rock_Volcanic"
    },
    {
      "x": -8,
      "y": 52,
      "z": 2,
      "name": "Rock_Volcanic"
    },
    {
      "x": -8,
      "y": 53,
      "z": 2,
      "name": "Rock_Volcanic"
    },
    {
      "x": -8,
      "y": 54,
      "z": 2,
      "name": "Rock_Volcanic"
    },
    {
      "x": -8,
      "y": 50,
      "z": 3,
      "name": "Rock_Volcanic"
    },
    {
      "x": -8,
      "y": 51,
      "z": 3,
      "name": "Rock_Volcanic"
    },
    {
      "x": -7,
      "y": 53,
      "z": -1,
      "name": "Rock_Volcanic_Cracked_Lava"
    },
    {
      "x": -7,
      "y": 54,
      "z": -1,
      "name": "Rock_Volcanic_Cracked_Lava"
    },
    {
      "x": -7,
      "y": 55,
      "z": -1,
      "name": "Rock_Volcanic_Cracked_Lava"
    },
    {
      "x": -7,
      "y": 56,
      "z": -1,
      "name": "Rock_Volcanic_Cracked_Lava"
    },
    {
      "x": -7,
      "y": 57,
      "z": -1,
      "name": "Rock_Volcanic_Cracked_Lava"
    },
    {
      "x": -7,
      "y": 51,
      "z": 0,
      "name": "Rock_Volcanic"
    },
    {
      "x": -7,
      "y": 52,
      "z": 0,
      "name": "Rock_Volcanic"
    },
    {
      "x": -7,
      "y": 53,
      "z": 0,
      "name": "Rock_Volcanic_Cracked_Lava"
    },
    {
      "x": -7,
      "y": 54,
      "z": 0,
      "name": "Rock_Volcanic_Cracked_Lava"
    },
    {
      "x": -7,
      "y": 55,
      "z": 0,
      "name": "Rock_Volcanic_Cracked_Lava"
    },
    {
      "x": -7,
      "y": 56,
      "z": 0,
      "name": "Rock_Volcanic_Cracked_Lava"
    },
    {
      "x": -7,
      "y": 57,
      "z": 0,
      "name": "Rock_Volcanic_Cracked_Lava"
    },
    {
      "x": -7,
      "y": 48,
      "z": 1,
      "name": "Rock_Volcanic"
    },
    {
      "x": -7,
      "y": 49,
      "z": 1,
      "name": "Rock_Volcanic"
    },
    {
      "x": -7,
      "y": 50,
      "z": 1,
      "name": "Rock_Volcanic"
    },
    {
      "x": -7,
      "y": 51,
      "z": 1,
      "name": "Rock_Volcanic"
    },
    {
      "x": -7,
      "y": 52,
      "z": 1,
      "name": "Rock_Volcanic"
    },
    {
      "x": -7,
      "y": 53,
      "z": 1,
      "name": "Rock_Volcanic_Cracked_Lava"
    },
    {
      "x": -7,
      "y": 54,
      "z": 1,
      "name": "Rock_Volcanic_Cracked_Lava"
    },
    {
      "x": -7,
      "y": 55,
      "z": 1,
      "name": "Rock_Volcanic_Cracked_Lava"
    },
    {
      "x": -7,
      "y": 47,
      "z": 2,
      "name": "Rock_Volcanic"
    },
    {
      "x": -7,
      "y": 48,
      "z": 2,
      "name": "Rock_Volcanic"
    },
    {
      "x": -7,
      "y": 49,
      "z": 2,
      "name": "Rock_Volcanic"
    },
    {
      "x": -7,
      "y": 50,
      "z": 2,
      "name": "Rock_Volcanic"
    },
    {
      "x": -7,
      "y": 51,
      "z": 2,
      "name": "Rock_Volcanic"
    },
    {
      "x": -7,
      "y": 52,
      "z": 2,
      "name": "Rock_Volcanic"
    },
    {
      "x": -7,
      "y": 53,
      "z": 2,
      "name": "Rock_Volcanic"
    },
    {
      "x": -7,
      "y": 54,
      "z": 2,
      "name": "Rock_Volcanic_Cracked_Lava"
    },
    {
      "x": -7,
      "y": 55,
      "z": 2,
      "name": "Rock_Volcanic"
    },
    {
      "x": -7,
      "y": 46,
      "z": 3,
      "name": "Rock_Volcanic"
    },
    {
      "x": -7,
      "y": 47,
      "z": 3,
      "name": "Rock_Volcanic"
    },
    {
      "x": -7,
      "y": 48,
      "z": 3,
      "name": "Rock_Volcanic"
    },
    {
      "x": -7,
      "y": 49,
      "z": 3,
      "name": "Rock_Volcanic"
    },
    {
      "x": -7,
      "y": 50,
      "z": 3,
      "name": "Rock_Volcanic"
    },
    {
      "x": -7,
      "y": 51,
      "z": 3,
      "name": "Rock_Volcanic"
    },
    {
      "x": -7,
      "y": 52,
      "z": 3,
      "name": "Rock_Volcanic"
    },
    {
      "x": -7,
      "y": 53,
      "z": 3,
      "name": "Rock_Volcanic"
    },
    {
      "x": -7,
      "y": 46,
      "z": 4,
      "name": "Rock_Volcanic"
    },
    {
      "x": -7,
      "y": 47,
      "z": 4,
      "name": "Rock_Volcanic"
    },
    {
      "x": -7,
      "y": 48,
      "z": 4,
      "name": "Rock_Volcanic"
    },
    {
      "x": -7,
      "y": 49,
      "z": 4,
      "name": "Rock_Volcanic"
    },
    {
      "x": -6,
      "y": 53,
      "z": -1,
      "name": "Rock_Volcanic_Cracked_Lava"
    },
    {
      "x": -6,
      "y": 54,
      "z": -1,
      "name": "Rock_Volcanic_Cracked_Lava"
    },
    {
      "x": -6,
      "y": 50,
      "z": 0,
      "name": "Rock_Volcanic"
    },
    {
      "x": -6,
      "y": 51,
      "z": 0,
      "name": "Rock_Volcanic"
    },
    {
      "x": -6,
      "y": 52,
      "z": 0,
      "name": "Rock_Volcanic"
    },
    {
      "x": -6,
      "y": 53,
      "z": 0,
      "name": "Rock_Volcanic_Cracked_Lava"
    },
    {
      "x": -6,
      "y": 54,
      "z": 0,
      "name": "Rock_Volcanic_Cracked_Lava"
    },
    {
      "x": -6,
      "y": 55,
      "z": 0,
      "name": "Rock_Volcanic_Cracked_Lava"
    },
    {
      "x": -6,
      "y": 46,
      "z": 1,
      "name": "Rock_Volcanic"
    },
    {
      "x": -6,
      "y": 47,
      "z": 1,
      "name": "Rock_Volcanic"
    },
    {
      "x": -6,
      "y": 48,
      "z": 1,
      "name": "Rock_Volcanic"
    },
    {
      "x": -6,
      "y": 49,
      "z": 1,
      "name": "Rock_Volcanic"
    },
    {
      "x": -6,
      "y": 50,
      "z": 1,
      "name": "Rock_Volcanic"
    },
    {
      "x": -6,
      "y": 51,
      "z": 1,
      "name": "Rock_Volcanic"
    },
    {
      "x": -6,
      "y": 52,
      "z": 1,
      "name": "Rock_Volcanic"
    },
    {
      "x": -6,
      "y": 53,
      "z": 1,
      "name": "Rock_Volcanic_Cracked_Lava"
    },
    {
      "x": -6,
      "y": 54,
      "z": 1,
      "name": "Rock_Volcanic_Cracked_Lava"
    },
    {
      "x": -6,
      "y": 55,
      "z": 1,
      "name": "Rock_Volcanic_Cracked_Lava"
    },
    {
      "x": -6,
      "y": 45,
      "z": 2,
      "name": "Rock_Volcanic"
    },
    {
      "x": -6,
      "y": 46,
      "z": 2,
      "name": "Rock_Volcanic"
    },
    {
      "x": -6,
      "y": 47,
      "z": 2,
      "name": "Rock_Volcanic"
    },
    {
      "x": -6,
      "y": 48,
      "z": 2,
      "name": "Rock_Volcanic"
    },
    {
      "x": -6,
      "y": 49,
      "z": 2,
      "name": "Rock_Volcanic"
    },
    {
      "x": -6,
      "y": 50,
      "z": 2,
      "name": "Rock_Volcanic"
    },
    {
      "x": -6,
      "y": 51,
      "z": 2,
      "name": "Rock_Volcanic"
    },
    {
      "x": -6,
      "y": 52,
      "z": 2,
      "name": "Rock_Volcanic"
    },
    {
      "x": -6,
      "y": 53,
      "z": 2,
      "name": "Rock_Volcanic"
    },
    {
      "x": -6,
      "y": 54,
      "z": 2,
      "name": "Rock_Volcanic_Cracked_Lava"
    },
    {
      "x": -6,
      "y": 55,
      "z": 2,
      "name": "Rock_Volcanic"
    },
    {
      "x": -6,
      "y": 45,
      "z": 3,
      "name": "Rock_Volcanic"
    },
    {
      "x": -6,
      "y": 46,
      "z": 3,
      "name": "Rock_Volcanic"
    },
    {
      "x": -6,
      "y": 47,
      "z": 3,
      "name": "Rock_Volcanic"
    },
    {
      "x": -6,
      "y": 48,
      "z": 3,
      "name": "Rock_Volcanic"
    },
    {
      "x": -6,
      "y": 49,
      "z": 3,
      "name": "Rock_Volcanic"
    },
    {
      "x": -6,
      "y": 50,
      "z": 3,
      "name": "Rock_Volcanic"
    },
    {
      "x": -6,
      "y": 51,
      "z": 3,
      "name": "Rock_Volcanic"
    },
    {
      "x": -6,
      "y": 52,
      "z": 3,
      "name": "Rock_Volcanic"
    },
    {
      "x": -6,
      "y": 53,
      "z": 3,
      "name": "Rock_Volcanic"
    },
    {
      "x": -6,
      "y": 44,
      "z": 4,
      "name": "Rock_Volcanic"
    },
    {
      "x": -6,
      "y": 45,
      "z": 4,
      "name": "Rock_Volcanic"
    },
    {
      "x": -6,
      "y": 46,
      "z": 4,
      "name": "Rock_Volcanic"
    },
    {
      "x": -6,
      "y": 47,
      "z": 4,
      "name": "Rock_Volcanic"
    },
    {
      "x": -6,
      "y": 48,
      "z": 4,
      "name": "Rock_Volcanic"
    },
    {
      "x": -6,
      "y": 49,
      "z": 4,
      "name": "Rock_Volcanic"
    },
    {
      "x": -6,
      "y": 50,
      "z": 4,
      "name": "Rock_Volcanic"
    },
    {
      "x": -6,
      "y": 44,
      "z": 5,
      "name": "Rock_Volcanic"
    },
    {
      "x": -6,
      "y": 45,
      "z": 5,
      "name": "Rock_Volcanic"
    },
    {
      "x": -6,
      "y": 46,
      "z": 5,
      "name": "Rock_Volcanic"
    },
    {
      "x": -6,
      "y": 47,
      "z": 5,
      "name": "Rock_Volcanic"
    },
    {
      "x": -6,
      "y": 48,
      "z": 5,
      "name": "Rock_Volcanic"
    },
    {
      "x": -6,
      "y": 49,
      "z": 5,
      "name": "Rock_Volcanic"
    },
    {
      "x": -5,
      "y": 51,
      "z": 0,
      "name": "Rock_Volcanic"
    },
    {
      "x": -5,
      "y": 52,
      "z": 0,
      "name": "Rock_Volcanic"
    },
    {
      "x": -5,
      "y": 53,
      "z": 0,
      "name": "Rock_Volcanic_Cracked_Lava"
    },
    {
      "x": -5,
      "y": 46,
      "z": 1,
      "name": "Rock_Volcanic"
    },
    {
      "x": -5,
      "y": 47,
      "z": 1,
      "name": "Rock_Volcanic"
    },
    {
      "x": -5,
      "y": 48,
      "z": 1,
      "name": "Rock_Volcanic"
    },
    {
      "x": -5,
      "y": 49,
      "z": 1,
      "name": "Rock_Volcanic"
    },
    {
      "x": -5,
      "y": 50,
      "z": 1,
      "name": "Rock_Volcanic"
    },
    {
      "x": -5,
      "y": 51,
      "z": 1,
      "name": "Rock_Volcanic"
    },
    {
      "x": -5,
      "y": 52,
      "z": 1,
      "name": "Rock_Volcanic"
    },
    {
      "x": -5,
      "y": 53,
      "z": 1,
      "name": "Rock_Volcanic_Cracked_Lava"
    },
    {
      "x": -5,
      "y": 54,
      "z": 1,
      "name": "Rock_Volcanic_Cracked_Lava"
    },
    {
      "x": -5,
      "y": 43,
      "z": 2,
      "name": "Rock_Volcanic"
    },
    {
      "x": -5,
      "y": 44,
      "z": 2,
      "name": "Rock_Volcanic"
    },
    {
      "x": -5,
      "y": 45,
      "z": 2,
      "name": "Rock_Volcanic"
    },
    {
      "x": -5,
      "y": 46,
      "z": 2,
      "name": "Rock_Volcanic"
    },
    {
      "x": -5,
      "y": 47,
      "z": 2,
      "name": "Rock_Volcanic"
    },
    {
      "x": -5,
      "y": 48,
      "z": 2,
      "name": "Rock_Volcanic"
    },
    {
      "x": -5,
      "y": 49,
      "z": 2,
      "name": "Rock_Volcanic"
    },
    {
      "x": -5,
      "y": 50,
      "z": 2,
      "name": "Rock_Volcanic"
    },
    {
      "x": -5,
      "y": 51,
      "z": 2,
      "name": "Rock_Volcanic"
    },
    {
      "x": -5,
      "y": 52,
      "z": 2,
      "name": "Rock_Volcanic"
    },
    {
      "x": -5,
      "y": 53,
      "z": 2,
      "name": "Rock_Volcanic"
    },
    {
      "x": -5,
      "y": 54,
      "z": 2,
      "name": "Rock_Volcanic_Cracked_Lava"
    },
    {
      "x": -5,
      "y": 43,
      "z": 3,
      "name": "Rock_Volcanic"
    },
    {
      "x": -5,
      "y": 44,
      "z": 3,
      "name": "Rock_Volcanic"
    },
    {
      "x": -5,
      "y": 45,
      "z": 3,
      "name": "Rock_Volcanic"
    },
    {
      "x": -5,
      "y": 46,
      "z": 3,
      "name": "Rock_Volcanic"
    },
    {
      "x": -5,
      "y": 47,
      "z": 3,
      "name": "Rock_Volcanic"
    },
    {
      "x": -5,
      "y": 48,
      "z": 3,
      "name": "Rock_Volcanic"
    },
    {
      "x": -5,
      "y": 49,
      "z": 3,
      "name": "Rock_Volcanic"
    },
    {
      "x": -5,
      "y": 50,
      "z": 3,
      "name": "Rock_Volcanic"
    },
    {
      "x": -5,
      "y": 51,
      "z": 3,
      "name": "Rock_Volcanic"
    },
    {
      "x": -5,
      "y": 52,
      "z": 3,
      "name": "Rock_Volcanic"
    },
    {
      "x": -5,
      "y": 43,
      "z": 4,
      "name": "Rock_Volcanic"
    },
    {
      "x": -5,
      "y": 44,
      "z": 4,
      "name": "Rock_Volcanic"
    },
    {
      "x": -5,
      "y": 45,
      "z": 4,
      "name": "Rock_Volcanic"
    },
    {
      "x": -5,
      "y": 46,
      "z": 4,
      "name": "Rock_Volcanic"
    },
    {
      "x": -5,
      "y": 47,
      "z": 4,
      "name": "Rock_Volcanic"
    },
    {
      "x": -5,
      "y": 48,
      "z": 4,
      "name": "Rock_Volcanic"
    },
    {
      "x": -5,
      "y": 49,
      "z": 4,
      "name": "Rock_Volcanic"
    },
    {
      "x": -5,
      "y": 50,
      "z": 4,
      "name": "Rock_Volcanic"
    },
    {
      "x": -5,
      "y": 51,
      "z": 4,
      "name": "Rock_Volcanic"
    },
    {
      "x": -5,
      "y": 44,
      "z": 5,
      "name": "Rock_Volcanic"
    },
    {
      "x": -5,
      "y": 45,
      "z": 5,
      "name": "Rock_Volcanic"
    },
    {
      "x": -5,
      "y": 46,
      "z": 5,
      "name": "Rock_Volcanic"
    },
    {
      "x": -5,
      "y": 47,
      "z": 5,
      "name": "Rock_Volcanic"
    },
    {
      "x": -5,
      "y": 48,
      "z": 5,
      "name": "Rock_Volcanic"
    },
    {
      "x": -5,
      "y": 49,
      "z": 5,
      "name": "Rock_Volcanic"
    },
    {
      "x": -5,
      "y": 45,
      "z": 6,
      "name": "Rock_Volcanic"
    },
    {
      "x": -5,
      "y": 46,
      "z": 6,
      "name": "Rock_Volcanic"
    },
    {
      "x": -5,
      "y": 47,
      "z": 6,
      "name": "Rock_Volcanic"
    },
    {
      "x": -4,
      "y": 45,
      "z": 1,
      "name": "Rock_Volcanic"
    },
    {
      "x": -4,
      "y": 46,
      "z": 1,
      "name": "Rock_Volcanic"
    },
    {
      "x": -4,
      "y": 47,
      "z": 1,
      "name": "Rock_Volcanic"
    },
    {
      "x": -4,
      "y": 48,
      "z": 1,
      "name": "Rock_Volcanic"
    },
    {
      "x": -4,
      "y": 49,
      "z": 1,
      "name": "Rock_Volcanic"
    },
    {
      "x": -4,
      "y": 50,
      "z": 1,
      "name": "Rock_Volcanic"
    },
    {
      "x": -4,
      "y": 51,
      "z": 1,
      "name": "Rock_Volcanic"
    },
    {
      "x": -4,
      "y": 52,
      "z": 1,
      "name": "Rock_Volcanic"
    },
    {
      "x": -4,
      "y": 43,
      "z": 2,
      "name": "Rock_Volcanic"
    },
    {
      "x": -4,
      "y": 44,
      "z": 2,
      "name": "Rock_Volcanic"
    },
    {
      "x": -4,
      "y": 45,
      "z": 2,
      "name": "Rock_Volcanic"
    },
    {
      "x": -4,
      "y": 46,
      "z": 2,
      "name": "Rock_Volcanic"
    },
    {
      "x": -4,
      "y": 47,
      "z": 2,
      "name": "Rock_Volcanic"
    },
    {
      "x": -4,
      "y": 48,
      "z": 2,
      "name": "Rock_Volcanic"
    },
    {
      "x": -4,
      "y": 49,
      "z": 2,
      "name": "Rock_Volcanic"
    },
    {
      "x": -4,
      "y": 50,
      "z": 2,
      "name": "Rock_Volcanic"
    },
    {
      "x": -4,
      "y": 51,
      "z": 2,
      "name": "Rock_Volcanic"
    },
    {
      "x": -4,
      "y": 52,
      "z": 2,
      "name": "Rock_Volcanic"
    },
    {
      "x": -4,
      "y": 42,
      "z": 3,
      "name": "Rock_Volcanic"
    },
    {
      "x": -4,
      "y": 43,
      "z": 3,
      "name": "Rock_Volcanic"
    },
    {
      "x": -4,
      "y": 44,
      "z": 3,
      "name": "Rock_Volcanic"
    },
    {
      "x": -4,
      "y": 45,
      "z": 3,
      "name": "Rock_Volcanic"
    },
    {
      "x": -4,
      "y": 46,
      "z": 3,
      "name": "Rock_Volcanic"
    },
    {
      "x": -4,
      "y": 47,
      "z": 3,
      "name": "Rock_Volcanic"
    },
    {
      "x": -4,
      "y": 48,
      "z": 3,
      "name": "Rock_Volcanic"
    },
    {
      "x": -4,
      "y": 49,
      "z": 3,
      "name": "Rock_Volcanic"
    },
    {
      "x": -4,
      "y": 50,
      "z": 3,
      "name": "Rock_Volcanic"
    },
    {
      "x": -4,
      "y": 51,
      "z": 3,
      "name": "Rock_Volcanic"
    },
    {
      "x": -4,
      "y": 41,
      "z": 4,
      "name": "Rock_Volcanic"
    },
    {
      "x": -4,
      "y": 42,
      "z": 4,
      "name": "Rock_Volcanic"
    },
    {
      "x": -4,
      "y": 43,
      "z": 4,
      "name": "Rock_Volcanic"
    },
    {
      "x": -4,
      "y": 44,
      "z": 4,
      "name": "Rock_Volcanic"
    },
    {
      "x": -4,
      "y": 45,
      "z": 4,
      "name": "Rock_Volcanic"
    },
    {
      "x": -4,
      "y": 46,
      "z": 4,
      "name": "Rock_Volcanic"
    },
    {
      "x": -4,
      "y": 47,
      "z": 4,
      "name": "Rock_Volcanic"
    },
    {
      "x": -4,
      "y": 48,
      "z": 4,
      "name": "Rock_Volcanic"
    },
    {
      "x": -4,
      "y": 49,
      "z": 4,
      "name": "Rock_Volcanic"
    },
    {
      "x": -4,
      "y": 50,
      "z": 4,
      "name": "Rock_Volcanic"
    },
    {
      "x": -4,
      "y": 51,
      "z": 4,
      "name": "Rock_Volcanic"
    },
    {
      "x": -4,
      "y": 41,
      "z": 5,
      "name": "Rock_Volcanic"
    },
    {
      "x": -4,
      "y": 42,
      "z": 5,
      "name": "Rock_Volcanic"
    },
    {
      "x": -4,
      "y": 43,
      "z": 5,
      "name": "Rock_Volcanic"
    },
    {
      "x": -4,
      "y": 44,
      "z": 5,
      "name": "Rock_Volcanic"
    },
    {
      "x": -4,
      "y": 45,
      "z": 5,
      "name": "Rock_Volcanic"
    },
    {
      "x": -4,
      "y": 46,
      "z": 5,
      "name": "Rock_Volcanic_Cracked_Lava"
    },
    {
      "x": -4,
      "y": 47,
      "z": 5,
      "name": "Rock_Volcanic"
    },
    {
      "x": -4,
      "y": 48,
      "z": 5,
      "name": "Rock_Volcanic"
    },
    {
      "x": -4,
      "y": 49,
      "z": 5,
      "name": "Rock_Volcanic"
    },
    {
      "x": -4,
      "y": 42,
      "z": 6,
      "name": "Rock_Volcanic"
    },
    {
      "x": -4,
      "y": 43,
      "z": 6,
      "name": "Rock_Volcanic"
    },
    {
      "x": -4,
      "y": 44,
      "z": 6,
      "name": "Rock_Volcanic"
    },
    {
      "x": -4,
      "y": 45,
      "z": 6,
      "name": "Rock_Volcanic"
    },
    {
      "x": -4,
      "y": 46,
      "z": 6,
      "name": "Rock_Volcanic_Cracked_Lava"
    },
    {
      "x": -4,
      "y": 47,
      "z": 6,
      "name": "Rock_Volcanic"
    },
    {
      "x": -4,
      "y": 44,
      "z": 7,
      "name": "Rock_Volcanic"
    },
    {
      "x": -4,
      "y": 45,
      "z": 7,
      "name": "Rock_Volcanic"
    },
    {
      "x": -4,
      "y": 46,
      "z": 7,
      "name": "Rock_Volcanic_Cracked_Lava"
    },
    {
      "x": -3,
      "y": 44,
      "z": 1,
      "name": "Rock_Volcanic"
    },
    {
      "x": -3,
      "y": 45,
      "z": 1,
      "name": "Rock_Volcanic"
    },
    {
      "x": -3,
      "y": 46,
      "z": 1,
      "name": "Rock_Volcanic"
    },
    {
      "x": -3,
      "y": 47,
      "z": 1,
      "name": "Rock_Volcanic"
    },
    {
      "x": -3,
      "y": 48,
      "z": 1,
      "name": "Rock_Volcanic"
    },
    {
      "x": -3,
      "y": 49,
      "z": 1,
      "name": "Rock_Volcanic"
    },
    {
      "x": -3,
      "y": 50,
      "z": 1,
      "name": "Rock_Volcanic"
    },
    {
      "x": -3,
      "y": 42,
      "z": 2,
      "name": "Rock_Volcanic"
    },
    {
      "x": -3,
      "y": 43,
      "z": 2,
      "name": "Rock_Volcanic"
    },
    {
      "x": -3,
      "y": 44,
      "z": 2,
      "name": "Rock_Volcanic"
    },
    {
      "x": -3,
      "y": 45,
      "z": 2,
      "name": "Rock_Volcanic"
    },
    {
      "x": -3,
      "y": 46,
      "z": 2,
      "name": "Rock_Volcanic"
    },
    {
      "x": -3,
      "y": 47,
      "z": 2,
      "name": "Rock_Volcanic"
    },
    {
      "x": -3,
      "y": 48,
      "z": 2,
      "name": "Rock_Volcanic_Cracked_Lava"
    },
    {
      "x": -3,
      "y": 49,
      "z": 2,
      "name": "Rock_Volcanic"
    },
    {
      "x": -3,
      "y": 50,
      "z": 2,
      "name": "Rock_Volcanic"
    },
    {
      "x": -3,
      "y": 40,
      "z": 3,
      "name": "Rock_Volcanic"
    },
    {
      "x": -3,
      "y": 41,
      "z": 3,
      "name": "Rock_Volcanic"
    },
    {
      "x": -3,
      "y": 42,
      "z": 3,
      "name": "Rock_Volcanic"
    },
    {
      "x": -3,
      "y": 43,
      "z": 3,
      "name": "Rock_Volcanic"
    },
    {
      "x": -3,
      "y": 44,
      "z": 3,
      "name": "Rock_Volcanic"
    },
    {
      "x": -3,
      "y": 45,
      "z": 3,
      "name": "Rock_Volcanic"
    },
    {
      "x": -3,
      "y": 46,
      "z": 3,
      "name": "Rock_Volcanic"
    },
    {
      "x": -3,
      "y": 47,
      "z": 3,
      "name": "Rock_Volcanic"
    },
    {
      "x": -3,
      "y": 48,
      "z": 3,
      "name": "Rock_Volcanic_Cracked_Lava"
    },
    {
      "x": -3,
      "y": 49,
      "z": 3,
      "name": "Rock_Volcanic"
    },
    {
      "x": -3,
      "y": 50,
      "z": 3,
      "name": "Rock_Volcanic"
    },
    {
      "x": -3,
      "y": 40,
      "z": 4,
      "name": "Rock_Volcanic"
    },
    {
      "x": -3,
      "y": 41,
      "z": 4,
      "name": "Rock_Volcanic"
    },
    {
      "x": -3,
      "y": 42,
      "z": 4,
      "name": "Rock_Volcanic"
    },
    {
      "x": -3,
      "y": 43,
      "z": 4,
      "name": "Rock_Volcanic"
    },
    {
      "x": -3,
      "y": 44,
      "z": 4,
      "name": "Rock_Volcanic"
    },
    {
      "x": -3,
      "y": 45,
      "z": 4,
      "name": "Rock_Volcanic"
    },
    {
      "x": -3,
      "y": 46,
      "z": 4,
      "name": "Rock_Volcanic_Cracked_Lava"
    },
    {
      "x": -3,
      "y": 47,
      "z": 4,
      "name": "Rock_Volcanic_Cracked_Lava"
    },
    {
      "x": -3,
      "y": 48,
      "z": 4,
      "name": "Rock_Volcanic_Cracked_Lava"
    },
    {
      "x": -3,
      "y": 49,
      "z": 4,
      "name": "Rock_Volcanic"
    },
    {
      "x": -3,
      "y": 50,
      "z": 4,
      "name": "Rock_Volcanic"
    },
    {
      "x": -3,
      "y": 40,
      "z": 5,
      "name": "Rock_Volcanic"
    },
    {
      "x": -3,
      "y": 41,
      "z": 5,
      "name": "Rock_Volcanic"
    },
    {
      "x": -3,
      "y": 42,
      "z": 5,
      "name": "Rock_Volcanic"
    },
    {
      "x": -3,
      "y": 43,
      "z": 5,
      "name": "Rock_Volcanic"
    },
    {
      "x": -3,
      "y": 44,
      "z": 5,
      "name": "Rock_Volcanic"
    },
    {
      "x": -3,
      "y": 45,
      "z": 5,
      "name": "Rock_Volcanic_Cracked_Lava"
    },
    {
      "x": -3,
      "y": 46,
      "z": 5,
      "name": "Rock_Volcanic_Cracked_Lava"
    },
    {
      "x": -3,
      "y": 47,
      "z": 5,
      "name": "Rock_Volcanic_Cracked_Lava"
    },
    {
      "x": -3,
      "y": 48,
      "z": 5,
      "name": "Rock_Volcanic"
    },
    {
      "x": -3,
      "y": 49,
      "z": 5,
      "name": "Rock_Volcanic"
    },
    {
      "x": -3,
      "y": 41,
      "z": 6,
      "name": "Rock_Volcanic"
    },
    {
      "x": -3,
      "y": 42,
      "z": 6,
      "name": "Rock_Volcanic"
    },
    {
      "x": -3,
      "y": 43,
      "z": 6,
      "name": "Rock_Volcanic"
    },
    {
      "x": -3,
      "y": 44,
      "z": 6,
      "name": "Rock_Volcanic"
    },
    {
      "x": -3,
      "y": 45,
      "z": 6,
      "name": "Rock_Volcanic_Cracked_Lava"
    },
    {
      "x": -3,
      "y": 46,
      "z": 6,
      "name": "Rock_Volcanic_Cracked_Lava"
    },
    {
      "x": -3,
      "y": 41,
      "z": 7,
      "name": "Rock_Volcanic"
    },
    {
      "x": -3,
      "y": 42,
      "z": 7,
      "name": "Rock_Volcanic"
    },
    {
      "x": -3,
      "y": 43,
      "z": 7,
      "name": "Rock_Volcanic_Cracked_Lava"
    },
    {
      "x": -3,
      "y": 44,
      "z": 7,
      "name": "Rock_Volcanic"
    },
    {
      "x": -3,
      "y": 45,
      "z": 7,
      "name": "Rock_Volcanic_Cracked_Lava"
    },
    {
      "x": -3,
      "y": 46,
      "z": 7,
      "name": "Rock_Volcanic_Cracked_Lava"
    },
    {
      "x": -2,
      "y": 44,
      "z": 1,
      "name": "Rock_Volcanic"
    },
    {
      "x": -2,
      "y": 45,
      "z": 1,
      "name": "Rock_Volcanic"
    },
    {
      "x": -2,
      "y": 46,
      "z": 1,
      "name": "Rock_Volcanic"
    },
    {
      "x": -2,
      "y": 47,
      "z": 1,
      "name": "Rock_Volcanic"
    },
    {
      "x": -2,
      "y": 48,
      "z": 1,
      "name": "Rock_Volcanic_Cracked_Lava"
    },
    {
      "x": -2,
      "y": 41,
      "z": 2,
      "name": "Rock_Volcanic"
    },
    {
      "x": -2,
      "y": 42,
      "z": 2,
      "name": "Rock_Volcanic"
    },
    {
      "x": -2,
      "y": 43,
      "z": 2,
      "name": "Rock_Volcanic"
    },
    {
      "x": -2,
      "y": 44,
      "z": 2,
      "name": "Rock_Volcanic"
    },
    {
      "x": -2,
      "y": 45,
      "z": 2,
      "name": "Rock_Volcanic"
    },
    {
      "x": -2,
      "y": 46,
      "z": 2,
      "name": "Rock_Volcanic"
    },
    {
      "x": -2,
      "y": 47,
      "z": 2,
      "name": "Rock_Volcanic_Cracked_Lava"
    },
    {
      "x": -2,
      "y": 48,
      "z": 2,
      "name": "Rock_Volcanic_Cracked_Lava"
    },
    {
      "x": -2,
      "y": 49,
      "z": 2,
      "name": "Rock_Volcanic_Cracked_Lava"
    },
    {
      "x": -2,
      "y": 50,
      "z": 2,
      "name": "Rock_Volcanic"
    },
    {
      "x": -2,
      "y": 40,
      "z": 3,
      "name": "Rock_Volcanic"
    },
    {
      "x": -2,
      "y": 41,
      "z": 3,
      "name": "Rock_Volcanic"
    },
    {
      "x": -2,
      "y": 42,
      "z": 3,
      "name": "Rock_Volcanic"
    },
    {
      "x": -2,
      "y": 43,
      "z": 3,
      "name": "Rock_Volcanic"
    },
    {
      "x": -2,
      "y": 44,
      "z": 3,
      "name": "Rock_Volcanic"
    },
    {
      "x": -2,
      "y": 45,
      "z": 3,
      "name": "Rock_Volcanic"
    },
    {
      "x": -2,
      "y": 46,
      "z": 3,
      "name": "Rock_Volcanic"
    },
    {
      "x": -2,
      "y": 47,
      "z": 3,
      "name": "Rock_Volcanic_Cracked_Lava"
    },
    {
      "x": -2,
      "y": 48,
      "z": 3,
      "name": "Rock_Volcanic_Cracked_Lava"
    },
    {
      "x": -2,
      "y": 49,
      "z": 3,
      "name": "Rock_Volcanic_Cracked_Lava"
    },
    {
      "x": -2,
      "y": 50,
      "z": 3,
      "name": "Rock_Volcanic"
    },
    {
      "x": -2,
      "y": 38,
      "z": 4,
      "name": "Rock_Volcanic"
    },
    {
      "x": -2,
      "y": 39,
      "z": 4,
      "name": "Rock_Volcanic"
    },
    {
      "x": -2,
      "y": 40,
      "z": 4,
      "name": "Rock_Volcanic"
    },
    {
      "x": -2,
      "y": 41,
      "z": 4,
      "name": "Rock_Volcanic"
    },
    {
      "x": -2,
      "y": 42,
      "z": 4,
      "name": "Rock_Volcanic"
    },
    {
      "x": -2,
      "y": 43,
      "z": 4,
      "name": "Rock_Volcanic"
    },
    {
      "x": -2,
      "y": 44,
      "z": 4,
      "name": "Rock_Volcanic"
    },
    {
      "x": -2,
      "y": 45,
      "z": 4,
      "name": "Rock_Volcanic"
    },
    {
      "x": -2,
      "y": 46,
      "z": 4,
      "name": "Rock_Volcanic_Cracked_Lava"
    },
    {
      "x": -2,
      "y": 47,
      "z": 4,
      "name": "Rock_Volcanic_Cracked_Lava"
    },
    {
      "x": -2,
      "y": 48,
      "z": 4,
      "name": "Rock_Volcanic_Cracked_Lava"
    },
    {
      "x": -2,
      "y": 49,
      "z": 4,
      "name": "Rock_Volcanic_Cracked_Lava"
    },
    {
      "x": -2,
      "y": 38,
      "z": 5,
      "name": "Rock_Volcanic"
    },
    {
      "x": -2,
      "y": 39,
      "z": 5,
      "name": "Rock_Volcanic"
    },
    {
      "x": -2,
      "y": 40,
      "z": 5,
      "name": "Rock_Volcanic"
    },
    {
      "x": -2,
      "y": 41,
      "z": 5,
      "name": "Rock_Volcanic"
    },
    {
      "x": -2,
      "y": 42,
      "z": 5,
      "name": "Rock_Volcanic"
    },
    {
      "x": -2,
      "y": 43,
      "z": 5,
      "name": "Rock_Volcanic"
    },
    {
      "x": -2,
      "y": 44,
      "z": 5,
      "name": "Rock_Volcanic"
    },
    {
      "x": -2,
      "y": 45,
      "z": 5,
      "name": "Rock_Volcanic_Cracked_Lava"
    },
    {
      "x": -2,
      "y": 46,
      "z": 5,
      "name": "Rock_Volcanic_Cracked_Lava"
    },
    {
      "x": -2,
      "y": 47,
      "z": 5,
      "name": "Rock_Volcanic_Cracked_Lava"
    },
    {
      "x": -2,
      "y": 48,
      "z": 5,
      "name": "Rock_Volcanic_Cracked_Lava"
    },
    {
      "x": -2,
      "y": 39,
      "z": 6,
      "name": "Rock_Volcanic"
    },
    {
      "x": -2,
      "y": 40,
      "z": 6,
      "name": "Rock_Volcanic"
    },
    {
      "x": -2,
      "y": 41,
      "z": 6,
      "name": "Rock_Volcanic"
    },
    {
      "x": -2,
      "y": 42,
      "z": 6,
      "name": "Rock_Volcanic"
    },
    {
      "x": -2,
      "y": 43,
      "z": 6,
      "name": "Rock_Volcanic_Cracked_Lava"
    },
    {
      "x": -2,
      "y": 44,
      "z": 6,
      "name": "Rock_Volcanic"
    },
    {
      "x": -2,
      "y": 45,
      "z": 6,
      "name": "Rock_Volcanic_Cracked_Lava"
    },
    {
      "x": -2,
      "y": 46,
      "z": 6,
      "name": "Rock_Volcanic_Cracked_Lava"
    },
    {
      "x": -2,
      "y": 39,
      "z": 7,
      "name": "Rock_Volcanic"
    },
    {
      "x": -2,
      "y": 40,
      "z": 7,
      "name": "Rock_Volcanic"
    },
    {
      "x": -2,
      "y": 41,
      "z": 7,
      "name": "Rock_Volcanic"
    },
    {
      "x": -2,
      "y": 42,
      "z": 7,
      "name": "Rock_Volcanic_Cracked_Lava"
    },
    {
      "x": -2,
      "y": 43,
      "z": 7,
      "name": "Rock_Volcanic_Cracked_Lava"
    },
    {
      "x": -2,
      "y": 44,
      "z": 7,
      "name": "Rock_Volcanic_Cracked_Lava"
    },
    {
      "x": -2,
      "y": 45,
      "z": 7,
      "name": "Rock_Volcanic_Cracked_Lava"
    },
    {
      "x": -2,
      "y": 40,
      "z": 8,
      "name": "Rock_Volcanic"
    },
    {
      "x": -2,
      "y": 41,
      "z": 8,
      "name": "Rock_Volcanic"
    },
    {
      "x": -2,
      "y": 42,
      "z": 8,
      "name": "Rock_Volcanic_Cracked_Lava"
    },
    {
      "x": -1,
      "y": 46,
      "z": 1,
      "name": "Rock_Volcanic"
    },
    {
      "x": -1,
      "y": 47,
      "z": 1,
      "name": "Rock_Volcanic"
    },
    {
      "x": -1,
      "y": 40,
      "z": 2,
      "name": "Rock_Volcanic"
    },
    {
      "x": -1,
      "y": 41,
      "z": 2,
      "name": "Rock_Volcanic"
    },
    {
      "x": -1,
      "y": 42,
      "z": 2,
      "name": "Rock_Volcanic"
    },
    {
      "x": -1,
      "y": 43,
      "z": 2,
      "name": "Rock_Volcanic"
    },
    {
      "x": -1,
      "y": 44,
      "z": 2,
      "name": "Rock_Volcanic"
    },
    {
      "x": -1,
      "y": 45,
      "z": 2,
      "name": "Rock_Volcanic"
    },
    {
      "x": -1,
      "y": 46,
      "z": 2,
      "name": "Rock_Volcanic"
    },
    {
      "x": -1,
      "y": 47,
      "z": 2,
      "name": "Rock_Volcanic_Cracked_Lava"
    },
    {
      "x": -1,
      "y": 48,
      "z": 2,
      "name": "Rock_Volcanic_Cracked_Lava"
    },
    {
      "x": -1,
      "y": 39,
      "z": 3,
      "name": "Rock_Volcanic"
    },
    {
      "x": -1,
      "y": 40,
      "z": 3,
      "name": "Rock_Volcanic"
    },
    {
      "x": -1,
      "y": 41,
      "z": 3,
      "name": "Rock_Volcanic"
    },
    {
      "x": -1,
      "y": 42,
      "z": 3,
      "name": "Rock_Volcanic"
    },
    {
      "x": -1,
      "y": 43,
      "z": 3,
      "name": "Rock_Volcanic"
    },
    {
      "x": -1,
      "y": 44,
      "z": 3,
      "name": "Rock_Volcanic"
    },
    {
      "x": -1,
      "y": 45,
      "z": 3,
      "name": "Rock_Volcanic"
    },
    {
      "x": -1,
      "y": 46,
      "z": 3,
      "name": "Rock_Volcanic"
    },
    {
      "x": -1,
      "y": 47,
      "z": 3,
      "name": "Rock_Volcanic_Cracked_Lava"
    },
    {
      "x": -1,
      "y": 48,
      "z": 3,
      "name": "Rock_Volcanic_Cracked_Lava"
    },
    {
      "x": -1,
      "y": 38,
      "z": 4,
      "name": "Rock_Volcanic"
    },
    {
      "x": -1,
      "y": 39,
      "z": 4,
      "name": "Rock_Volcanic"
    },
    {
      "x": -1,
      "y": 40,
      "z": 4,
      "name": "Rock_Volcanic"
    },
    {
      "x": -1,
      "y": 41,
      "z": 4,
      "name": "Rock_Volcanic"
    },
    {
      "x": -1,
      "y": 42,
      "z": 4,
      "name": "Rock_Volcanic"
    },
    {
      "x": -1,
      "y": 43,
      "z": 4,
      "name": "Rock_Volcanic"
    },
    {
      "x": -1,
      "y": 44,
      "z": 4,
      "name": "Rock_Volcanic"
    },
    {
      "x": -1,
      "y": 45,
      "z": 4,
      "name": "Rock_Volcanic"
    },
    {
      "x": -1,
      "y": 46,
      "z": 4,
      "name": "Rock_Volcanic_Cracked_Lava"
    },
    {
      "x": -1,
      "y": 47,
      "z": 4,
      "name": "Rock_Volcanic_Cracked_Lava"
    },
    {
      "x": -1,
      "y": 36,
      "z": 5,
      "name": "Rock_Volcanic"
    },
    {
      "x": -1,
      "y": 37,
      "z": 5,
      "name": "Rock_Volcanic"
    },
    {
      "x": -1,
      "y": 38,
      "z": 5,
      "name": "Rock_Volcanic"
    },
    {
      "x": -1,
      "y": 39,
      "z": 5,
      "name": "Rock_Volcanic"
    },
    {
      "x": -1,
      "y": 40,
      "z": 5,
      "name": "Rock_Volcanic"
    },
    {
      "x": -1,
      "y": 41,
      "z": 5,
      "name": "Rock_Volcanic"
    },
    {
      "x": -1,
      "y": 42,
      "z": 5,
      "name": "Rock_Volcanic"
    },
    {
      "x": -1,
      "y": 43,
      "z": 5,
      "name": "Rock_Volcanic"
    },
    {
      "x": -1,
      "y": 44,
      "z": 5,
      "name": "Rock_Volcanic"
    },
    {
      "x": -1,
      "y": 45,
      "z": 5,
      "name": "Rock_Volcanic_Cracked_Lava"
    },
    {
      "x": -1,
      "y": 46,
      "z": 5,
      "name": "Rock_Volcanic_Cracked_Lava"
    },
    {
      "x": -1,
      "y": 47,
      "z": 5,
      "name": "Rock_Volcanic_Cracked_Lava"
    },
    {
      "x": -1,
      "y": 35,
      "z": 6,
      "name": "Rock_Volcanic"
    },
    {
      "x": -1,
      "y": 36,
      "z": 6,
      "name": "Rock_Volcanic"
    },
    {
      "x": -1,
      "y": 37,
      "z": 6,
      "name": "Rock_Volcanic"
    },
    {
      "x": -1,
      "y": 38,
      "z": 6,
      "name": "Rock_Volcanic"
    },
    {
      "x": -1,
      "y": 39,
      "z": 6,
      "name": "Rock_Volcanic"
    },
    {
      "x": -1,
      "y": 40,
      "z": 6,
      "name": "Rock_Volcanic"
    },
    {
      "x": -1,
      "y": 41,
      "z": 6,
      "name": "Rock_Volcanic"
    },
    {
      "x": -1,
      "y": 42,
      "z": 6,
      "name": "Rock_Volcanic"
    },
    {
      "x": -1,
      "y": 43,
      "z": 6,
      "name": "Rock_Volcanic_Cracked_Lava"
    },
    {
      "x": -1,
      "y": 44,
      "z": 6,
      "name": "Rock_Volcanic"
    },
    {
      "x": -1,
      "y": 45,
      "z": 6,
      "name": "Rock_Volcanic_Cracked_Lava"
    },
    {
      "x": -1,
      "y": 35,
      "z": 7,
      "name": "Rock_Volcanic"
    },
    {
      "x": -1,
      "y": 36,
      "z": 7,
      "name": "Rock_Volcanic"
    },
    {
      "x": -1,
      "y": 37,
      "z": 7,
      "name": "Rock_Volcanic"
    },
    {
      "x": -1,
      "y": 38,
      "z": 7,
      "name": "Rock_Volcanic"
    },
    {
      "x": -1,
      "y": 39,
      "z": 7,
      "name": "Rock_Volcanic"
    },
    {
      "x": -1,
      "y": 40,
      "z": 7,
      "name": "Rock_Volcanic"
    },
    {
      "x": -1,
      "y": 41,
      "z": 7,
      "name": "Rock_Volcanic"
    },
    {
      "x": -1,
      "y": 42,
      "z": 7,
      "name": "Rock_Volcanic_Cracked_Lava"
    },
    {
      "x": -1,
      "y": 43,
      "z": 7,
      "name": "Rock_Volcanic_Cracked_Lava"
    },
    {
      "x": -1,
      "y": 44,
      "z": 7,
      "name": "Rock_Volcanic_Cracked_Lava"
    },
    {
      "x": -1,
      "y": 45,
      "z": 7,
      "name": "Rock_Volcanic_Cracked_Lava"
    },
    {
      "x": -1,
      "y": 36,
      "z": 8,
      "name": "Rock_Volcanic"
    },
    {
      "x": -1,
      "y": 37,
      "z": 8,
      "name": "Rock_Volcanic"
    },
    {
      "x": -1,
      "y": 38,
      "z": 8,
      "name": "Rock_Volcanic"
    },
    {
      "x": -1,
      "y": 39,
      "z": 8,
      "name": "Rock_Volcanic"
    },
    {
      "x": -1,
      "y": 40,
      "z": 8,
      "name": "Rock_Volcanic"
    },
    {
      "x": -1,
      "y": 41,
      "z": 8,
      "name": "Rock_Volcanic"
    },
    {
      "x": -1,
      "y": 42,
      "z": 8,
      "name": "Rock_Volcanic_Cracked_Lava"
    },
    {
      "x": -1,
      "y": 43,
      "z": 8,
      "name": "Rock_Volcanic_Cracked_Lava"
    },
    {
      "x": -1,
      "y": 41,
      "z": 9,
      "name": "Rock_Volcanic"
    },
    {
      "x": 0,
      "y": 39,
      "z": 2,
      "name": "Rock_Volcanic"
    },
    {
      "x": 0,
      "y": 40,
      "z": 2,
      "name": "Rock_Volcanic"
    },
    {
      "x": 0,
      "y": 41,
      "z": 2,
      "name": "Rock_Volcanic"
    },
    {
      "x": 0,
      "y": 42,
      "z": 2,
      "name": "Rock_Volcanic"
    },
    {
      "x": 0,
      "y": 43,
      "z": 2,
      "name": "Rock_Volcanic"
    },
    {
      "x": 0,
      "y": 44,
      "z": 2,
      "name": "Rock_Volcanic"
    },
    {
      "x": 0,
      "y": 45,
      "z": 2,
      "name": "Rock_Volcanic"
    },
    {
      "x": 0,
      "y": 46,
      "z": 2,
      "name": "Rock_Volcanic"
    },
    {
      "x": 0,
      "y": 38,
      "z": 3,
      "name": "Rock_Volcanic"
    },
    {
      "x": 0,
      "y": 39,
      "z": 3,
      "name": "Rock_Volcanic"
    },
    {
      "x": 0,
      "y": 40,
      "z": 3,
      "name": "Rock_Volcanic"
    },
    {
      "x": 0,
      "y": 41,
      "z": 3,
      "name": "Rock_Volcanic"
    },
    {
      "x": 0,
      "y": 42,
      "z": 3,
      "name": "Rock_Volcanic"
    },
    {
      "x": 0,
      "y": 43,
      "z": 3,
      "name": "Rock_Volcanic"
    },
    {
      "x": 0,
      "y": 44,
      "z": 3,
      "name": "Rock_Volcanic"
    },
    {
      "x": 0,
      "y": 45,
      "z": 3,
      "name": "Rock_Volcanic"
    },
    {
      "x": 0,
      "y": 46,
      "z": 3,
      "name": "Rock_Volcanic"
    },
    {
      "x": 0,
      "y": 47,
      "z": 3,
      "name": "Rock_Volcanic_Cracked_Lava"
    },
    {
      "x": 0,
      "y": 35,
      "z": 4,
      "name": "Rock_Volcanic"
    },
    {
      "x": 0,
      "y": 36,
      "z": 4,
      "name": "Rock_Volcanic"
    },
    {
      "x": 0,
      "y": 37,
      "z": 4,
      "name": "Rock_Volcanic"
    },
    {
      "x": 0,
      "y": 38,
      "z": 4,
      "name": "Rock_Volcanic"
    },
    {
      "x": 0,
      "y": 39,
      "z": 4,
      "name": "Rock_Volcanic"
    },
    {
      "x": 0,
      "y": 40,
      "z": 4,
      "name": "Rock_Volcanic"
    },
    {
      "x": 0,
      "y": 41,
      "z": 4,
      "name": "Rock_Volcanic"
    },
    {
      "x": 0,
      "y": 42,
      "z": 4,
      "name": "Rock_Volcanic"
    },
    {
      "x": 0,
      "y": 43,
      "z": 4,
      "name": "Rock_Volcanic"
    },
    {
      "x": 0,
      "y": 44,
      "z": 4,
      "name": "Rock_Volcanic"
    },
    {
      "x": 0,
      "y": 45,
      "z": 4,
      "name": "Rock_Volcanic"
    },
    {
      "x": 0,
      "y": 46,
      "z": 4,
      "name": "Rock_Volcanic_Cracked_Lava"
    },
    {
      "x": 0,
      "y": 47,
      "z": 4,
      "name": "Rock_Volcanic_Cracked_Lava"
    },
    {
      "x": 0,
      "y": 35,
      "z": 5,
      "name": "Rock_Volcanic"
    },
    {
      "x": 0,
      "y": 36,
      "z": 5,
      "name": "Rock_Volcanic"
    },
    {
      "x": 0,
      "y": 37,
      "z": 5,
      "name": "Rock_Volcanic"
    },
    {
      "x": 0,
      "y": 38,
      "z": 5,
      "name": "Rock_Volcanic"
    },
    {
      "x": 0,
      "y": 39,
      "z": 5,
      "name": "Rock_Volcanic"
    },
    {
      "x": 0,
      "y": 40,
      "z": 5,
      "name": "Rock_Volcanic"
    },
    {
      "x": 0,
      "y": 41,
      "z": 5,
      "name": "Rock_Volcanic"
    },
    {
      "x": 0,
      "y": 42,
      "z": 5,
      "name": "Rock_Volcanic"
    },
    {
      "x": 0,
      "y": 43,
      "z": 5,
      "name": "Rock_Volcanic"
    },
    {
      "x": 0,
      "y": 44,
      "z": 5,
      "name": "Rock_Volcanic"
    },
    {
      "x": 0,
      "y": 45,
      "z": 5,
      "name": "Rock_Volcanic"
    },
    {
      "x": 0,
      "y": 46,
      "z": 5,
      "name": "Rock_Volcanic_Cracked_Lava"
    },
    {
      "x": 0,
      "y": 33,
      "z": 6,
      "name": "Rock_Volcanic"
    },
    {
      "x": 0,
      "y": 34,
      "z": 6,
      "name": "Rock_Volcanic"
    },
    {
      "x": 0,
      "y": 35,
      "z": 6,
      "name": "Rock_Volcanic"
    },
    {
      "x": 0,
      "y": 36,
      "z": 6,
      "name": "Rock_Volcanic"
    },
    {
      "x": 0,
      "y": 37,
      "z": 6,
      "name": "Rock_Volcanic"
    },
    {
      "x": 0,
      "y": 38,
      "z": 6,
      "name": "Rock_Volcanic"
    },
    {
      "x": 0,
      "y": 39,
      "z": 6,
      "name": "Rock_Volcanic"
    },
    {
      "x": 0,
      "y": 40,
      "z": 6,
      "name": "Rock_Volcanic"
    },
    {
      "x": 0,
      "y": 41,
      "z": 6,
      "name": "Rock_Volcanic"
    },
    {
      "x": 0,
      "y": 42,
      "z": 6,
      "name": "Rock_Volcanic"
    },
    {
      "x": 0,
      "y": 43,
      "z": 6,
      "name": "Rock_Volcanic_Cracked_Lava"
    },
    {
      "x": 0,
      "y": 44,
      "z": 6,
      "name": "Rock_Volcanic"
    },
    {
      "x": 0,
      "y": 45,
      "z": 6,
      "name": "Rock_Volcanic"
    },
    {
      "x": 0,
      "y": 33,
      "z": 7,
      "name": "Rock_Volcanic"
    },
    {
      "x": 0,
      "y": 34,
      "z": 7,
      "name": "Rock_Volcanic"
    },
    {
      "x": 0,
      "y": 35,
      "z": 7,
      "name": "Rock_Volcanic"
    },
    {
      "x": 0,
      "y": 36,
      "z": 7,
      "name": "Rock_Volcanic"
    },
    {
      "x": 0,
      "y": 37,
      "z": 7,
      "name": "Rock_Volcanic"
    },
    {
      "x": 0,
      "y": 38,
      "z": 7,
      "name": "Rock_Volcanic"
    },
    {
      "x": 0,
      "y": 39,
      "z": 7,
      "name": "Rock_Volcanic"
    },
    {
      "x": 0,
      "y": 40,
      "z": 7,
      "name": "Rock_Volcanic"
    },
    {
      "x": 0,
      "y": 41,
      "z": 7,
      "name": "Rock_Volcanic_Cracked_Lava"
    },
    {
      "x": 0,
      "y": 42,
      "z": 7,
      "name": "Rock_Volcanic_Cracked_Lava"
    },
    {
      "x": 0,
      "y": 43,
      "z": 7,
      "name": "Rock_Volcanic_Cracked_Lava"
    },
    {
      "x": 0,
      "y": 44,
      "z": 7,
      "name": "Rock_Volcanic_Cracked_Lava"
    },
    {
      "x": 0,
      "y": 33,
      "z": 8,
      "name": "Rock_Volcanic"
    },
    {
      "x": 0,
      "y": 34,
      "z": 8,
      "name": "Rock_Volcanic"
    },
    {
      "x": 0,
      "y": 35,
      "z": 8,
      "name": "Rock_Volcanic"
    },
    {
      "x": 0,
      "y": 36,
      "z": 8,
      "name": "Rock_Volcanic"
    },
    {
      "x": 0,
      "y": 37,
      "z": 8,
      "name": "Rock_Volcanic"
    },
    {
      "x": 0,
      "y": 38,
      "z": 8,
      "name": "Rock_Volcanic"
    },
    {
      "x": 0,
      "y": 39,
      "z": 8,
      "name": "Rock_Volcanic"
    },
    {
      "x": 0,
      "y": 40,
      "z": 8,
      "name": "Rock_Volcanic"
    },
    {
      "x": 0,
      "y": 41,
      "z": 8,
      "name": "Rock_Volcanic_Cracked_Lava"
    },
    {
      "x": 0,
      "y": 42,
      "z": 8,
      "name": "Rock_Volcanic_Cracked_Lava"
    },
    {
      "x": 0,
      "y": 43,
      "z": 8,
      "name": "Rock_Volcanic_Cracked_Lava"
    },
    {
      "x": 0,
      "y": 39,
      "z": 9,
      "name": "Rock_Volcanic"
    },
    {
      "x": 0,
      "y": 40,
      "z": 9,
      "name": "Rock_Volcanic"
    },
    {
      "x": 0,
      "y": 41,
      "z": 9,
      "name": "Rock_Volcanic_Cracked_Lava"
    },
    {
      "x": 0,
      "y": 42,
      "z": 9,
      "name": "Rock_Volcanic_Cracked_Lava"
    },
    {
      "x": 1,
      "y": 39,
      "z": 2,
      "name": "Rock_Volcanic"
    },
    {
      "x": 1,
      "y": 40,
      "z": 2,
      "name": "Rock_Volcanic"
    },
    {
      "x": 1,
      "y": 41,
      "z": 2,
      "name": "Rock_Volcanic"
    },
    {
      "x": 1,
      "y": 42,
      "z": 2,
      "name": "Rock_Volcanic"
    },
    {
      "x": 1,
      "y": 43,
      "z": 2,
      "name": "Rock_Volcanic"
    },
    {
      "x": 1,
      "y": 37,
      "z": 3,
      "name": "Rock_Volcanic"
    },
    {
      "x": 1,
      "y": 38,
      "z": 3,
      "name": "Rock_Volcanic"
    },
    {
      "x": 1,
      "y": 39,
      "z": 3,
      "name": "Rock_Volcanic"
    },
    {
      "x": 1,
      "y": 40,
      "z": 3,
      "name": "Rock_Volcanic"
    },
    {
      "x": 1,
      "y": 41,
      "z": 3,
      "name": "Rock_Volcanic"
    },
    {
      "x": 1,
      "y": 42,
      "z": 3,
      "name": "Rock_Volcanic"
    },
    {
      "x": 1,
      "y": 43,
      "z": 3,
      "name": "Rock_Volcanic"
    },
    {
      "x": 1,
      "y": 44,
      "z": 3,
      "name": "Rock_Volcanic"
    },
    {
      "x": 1,
      "y": 45,
      "z": 3,
      "name": "Rock_Volcanic"
    },
    {
      "x": 1,
      "y": 35,
      "z": 4,
      "name": "Rock_Volcanic"
    },
    {
      "x": 1,
      "y": 36,
      "z": 4,
      "name": "Rock_Volcanic"
    },
    {
      "x": 1,
      "y": 37,
      "z": 4,
      "name": "Rock_Volcanic"
    },
    {
      "x": 1,
      "y": 38,
      "z": 4,
      "name": "Rock_Volcanic"
    },
    {
      "x": 1,
      "y": 39,
      "z": 4,
      "name": "Rock_Volcanic"
    },
    {
      "x": 1,
      "y": 40,
      "z": 4,
      "name": "Rock_Volcanic"
    },
    {
      "x": 1,
      "y": 41,
      "z": 4,
      "name": "Rock_Volcanic"
    },
    {
      "x": 1,
      "y": 42,
      "z": 4,
      "name": "Rock_Volcanic"
    },
    {
      "x": 1,
      "y": 43,
      "z": 4,
      "name": "Rock_Volcanic"
    },
    {
      "x": 1,
      "y": 44,
      "z": 4,
      "name": "Rock_Volcanic"
    },
    {
      "x": 1,
      "y": 45,
      "z": 4,
      "name": "Rock_Volcanic"
    },
    {
      "x": 1,
      "y": 33,
      "z": 5,
      "name": "Rock_Volcanic"
    },
    {
      "x": 1,
      "y": 34,
      "z": 5,
      "name": "Rock_Volcanic"
    },
    {
      "x": 1,
      "y": 35,
      "z": 5,
      "name": "Rock_Volcanic"
    },
    {
      "x": 1,
      "y": 36,
      "z": 5,
      "name": "Rock_Volcanic"
    },
    {
      "x": 1,
      "y": 37,
      "z": 5,
      "name": "Rock_Volcanic"
    },
    {
      "x": 1,
      "y": 38,
      "z": 5,
      "name": "Rock_Volcanic"
    },
    {
      "x": 1,
      "y": 39,
      "z": 5,
      "name": "Rock_Volcanic"
    },
    {
      "x": 1,
      "y": 40,
      "z": 5,
      "name": "Rock_Volcanic"
    },
    {
      "x": 1,
      "y": 41,
      "z": 5,
      "name": "Rock_Volcanic"
    },
    {
      "x": 1,
      "y": 42,
      "z": 5,
      "name": "Rock_Volcanic"
    },
    {
      "x": 1,
      "y": 43,
      "z": 5,
      "name": "Rock_Volcanic"
    },
    {
      "x": 1,
      "y": 44,
      "z": 5,
      "name": "Rock_Volcanic"
    },
    {
      "x": 1,
      "y": 32,
      "z": 6,
      "name": "Rock_Volcanic"
    },
    {
      "x": 1,
      "y": 33,
      "z": 6,
      "name": "Rock_Volcanic"
    },
    {
      "x": 1,
      "y": 34,
      "z": 6,
      "name": "Rock_Volcanic"
    },
    {
      "x": 1,
      "y": 35,
      "z": 6,
      "name": "Rock_Volcanic"
    },
    {
      "x": 1,
      "y": 36,
      "z": 6,
      "name": "Rock_Volcanic"
    },
    {
      "x": 1,
      "y": 37,
      "z": 6,
      "name": "Rock_Volcanic"
    },
    {
      "x": 1,
      "y": 38,
      "z": 6,
      "name": "Rock_Volcanic"
    },
    {
      "x": 1,
      "y": 39,
      "z": 6,
      "name": "Rock_Volcanic"
    },
    {
      "x": 1,
      "y": 40,
      "z": 6,
      "name": "Rock_Volcanic"
    },
    {
      "x": 1,
      "y": 41,
      "z": 6,
      "name": "Rock_Volcanic_Cracked_Lava"
    },
    {
      "x": 1,
      "y": 42,
      "z": 6,
      "name": "Rock_Volcanic"
    },
    {
      "x": 1,
      "y": 43,
      "z": 6,
      "name": "Rock_Volcanic"
    },
    {
      "x": 1,
      "y": 31,
      "z": 7,
      "name": "Rock_Volcanic"
    },
    {
      "x": 1,
      "y": 32,
      "z": 7,
      "name": "Rock_Volcanic"
    },
    {
      "x": 1,
      "y": 33,
      "z": 7,
      "name": "Rock_Volcanic"
    },
    {
      "x": 1,
      "y": 34,
      "z": 7,
      "name": "Rock_Volcanic"
    },
    {
      "x": 1,
      "y": 35,
      "z": 7,
      "name": "Rock_Volcanic"
    },
    {
      "x": 1,
      "y": 36,
      "z": 7,
      "name": "Rock_Volcanic"
    },
    {
      "x": 1,
      "y": 37,
      "z": 7,
      "name": "Rock_Volcanic"
    },
    {
      "x": 1,
      "y": 38,
      "z": 7,
      "name": "Rock_Volcanic"
    },
    {
      "x": 1,
      "y": 39,
      "z": 7,
      "name": "Rock_Volcanic"
    },
    {
      "x": 1,
      "y": 40,
      "z": 7,
      "name": "Rock_Volcanic_Cracked_Lava"
    },
    {
      "x": 1,
      "y": 41,
      "z": 7,
      "name": "Rock_Volcanic_Cracked_Lava"
    },
    {
      "x": 1,
      "y": 42,
      "z": 7,
      "name": "Rock_Volcanic_Cracked_Lava"
    },
    {
      "x": 1,
      "y": 43,
      "z": 7,
      "name": "Rock_Volcanic_Cracked_Lava"
    },
    {
      "x": 1,
      "y": 31,
      "z": 8,
      "name": "Rock_Volcanic"
    },
    {
      "x": 1,
      "y": 32,
      "z": 8,
      "name": "Rock_Volcanic"
    },
    {
      "x": 1,
      "y": 33,
      "z": 8,
      "name": "Rock_Volcanic"
    },
    {
      "x": 1,
      "y": 34,
      "z": 8,
      "name": "Rock_Volcanic"
    },
    {
      "x": 1,
      "y": 35,
      "z": 8,
      "name": "Rock_Volcanic"
    },
    {
      "x": 1,
      "y": 36,
      "z": 8,
      "name": "Rock_Volcanic"
    },
    {
      "x": 1,
      "y": 37,
      "z": 8,
      "name": "Rock_Volcanic"
    },
    {
      "x": 1,
      "y": 38,
      "z": 8,
      "name": "Rock_Volcanic"
    },
    {
      "x": 1,
      "y": 39,
      "z": 8,
      "name": "Rock_Volcanic"
    },
    {
      "x": 1,
      "y": 40,
      "z": 8,
      "name": "Rock_Volcanic_Cracked_Lava"
    },
    {
      "x": 1,
      "y": 41,
      "z": 8,
      "name": "Rock_Volcanic_Cracked_Lava"
    },
    {
      "x": 1,
      "y": 42,
      "z": 8,
      "name": "Rock_Volcanic_Cracked_Lava"
    },
    {
      "x": 1,
      "y": 31,
      "z": 9,
      "name": "Rock_Volcanic"
    },
    {
      "x": 1,
      "y": 32,
      "z": 9,
      "name": "Rock_Volcanic"
    },
    {
      "x": 1,
      "y": 33,
      "z": 9,
      "name": "Rock_Volcanic"
    },
    {
      "x": 1,
      "y": 34,
      "z": 9,
      "name": "Rock_Volcanic"
    },
    {
      "x": 1,
      "y": 35,
      "z": 9,
      "name": "Rock_Volcanic"
    },
    {
      "x": 1,
      "y": 36,
      "z": 9,
      "name": "Rock_Volcanic"
    },
    {
      "x": 1,
      "y": 37,
      "z": 9,
      "name": "Rock_Volcanic"
    },
    {
      "x": 1,
      "y": 38,
      "z": 9,
      "name": "Rock_Volcanic"
    },
    {
      "x": 1,
      "y": 39,
      "z": 9,
      "name": "Rock_Volcanic"
    },
    {
      "x": 1,
      "y": 40,
      "z": 9,
      "name": "Rock_Volcanic_Cracked_Lava"
    },
    {
      "x": 1,
      "y": 41,
      "z": 9,
      "name": "Rock_Volcanic_Cracked_Lava"
    },
    {
      "x": 1,
      "y": 42,
      "z": 9,
      "name": "Rock_Volcanic_Cracked_Lava"
    },
    {
      "x": 1,
      "y": 30,
      "z": 10,
      "name": "Rock_Volcanic"
    },
    {
      "x": 1,
      "y": 31,
      "z": 10,
      "name": "Rock_Volcanic"
    },
    {
      "x": 1,
      "y": 32,
      "z": 10,
      "name": "Rock_Volcanic"
    },
    {
      "x": 1,
      "y": 33,
      "z": 10,
      "name": "Rock_Volcanic"
    },
    {
      "x": 1,
      "y": 34,
      "z": 10,
      "name": "Rock_Volcanic"
    },
    {
      "x": 1,
      "y": 35,
      "z": 10,
      "name": "Rock_Volcanic"
    },
    {
      "x": 1,
      "y": 36,
      "z": 10,
      "name": "Rock_Volcanic"
    },
    {
      "x": 1,
      "y": 37,
      "z": 10,
      "name": "Rock_Volcanic"
    },
    {
      "x": 1,
      "y": 38,
      "z": 10,
      "name": "Rock_Volcanic"
    },
    {
      "x": 1,
      "y": 39,
      "z": 10,
      "name": "Rock_Volcanic"
    },
    {
      "x": 1,
      "y": 31,
      "z": 11,
      "name": "Rock_Volcanic"
    },
    {
      "x": 2,
      "y": 39,
      "z": 2,
      "name": "Rock_Volcanic"
    },
    {
      "x": 2,
      "y": 40,
      "z": 2,
      "name": "Rock_Volcanic"
    },
    {
      "x": 2,
      "y": 41,
      "z": 2,
      "name": "Rock_Volcanic"
    },
    {
      "x": 2,
      "y": 36,
      "z": 3,
      "name": "Rock_Volcanic"
    },
    {
      "x": 2,
      "y": 37,
      "z": 3,
      "name": "Rock_Volcanic"
    },
    {
      "x": 2,
      "y": 38,
      "z": 3,
      "name": "Rock_Volcanic"
    },
    {
      "x": 2,
      "y": 39,
      "z": 3,
      "name": "Rock_Volcanic"
    },
    {
      "x": 2,
      "y": 40,
      "z": 3,
      "name": "Rock_Volcanic"
    },
    {
      "x": 2,
      "y": 41,
      "z": 3,
      "name": "Rock_Volcanic"
    },
    {
      "x": 2,
      "y": 42,
      "z": 3,
      "name": "Rock_Volcanic"
    },
    {
      "x": 2,
      "y": 43,
      "z": 3,
      "name": "Rock_Volcanic"
    },
    {
      "x": 2,
      "y": 33,
      "z": 4,
      "name": "Rock_Volcanic"
    },
    {
      "x": 2,
      "y": 34,
      "z": 4,
      "name": "Rock_Volcanic"
    },
    {
      "x": 2,
      "y": 35,
      "z": 4,
      "name": "Rock_Volcanic"
    },
    {
      "x": 2,
      "y": 36,
      "z": 4,
      "name": "Rock_Volcanic"
    },
    {
      "x": 2,
      "y": 37,
      "z": 4,
      "name": "Rock_Volcanic"
    },
    {
      "x": 2,
      "y": 38,
      "z": 4,
      "name": "Rock_Volcanic"
    },
    {
      "x": 2,
      "y": 39,
      "z": 4,
      "name": "Rock_Volcanic"
    },
    {
      "x": 2,
      "y": 40,
      "z": 4,
      "name": "Rock_Volcanic"
    },
    {
      "x": 2,
      "y": 41,
      "z": 4,
      "name": "Rock_Volcanic"
    },
    {
      "x": 2,
      "y": 42,
      "z": 4,
      "name": "Rock_Volcanic"
    },
    {
      "x": 2,
      "y": 43,
      "z": 4,
      "name": "Rock_Volcanic"
    },
    {
      "x": 2,
      "y": 44,
      "z": 4,
      "name": "Rock_Volcanic"
    },
    {
      "x": 2,
      "y": 32,
      "z": 5,
      "name": "Rock_Volcanic"
    },
    {
      "x": 2,
      "y": 33,
      "z": 5,
      "name": "Rock_Volcanic"
    },
    {
      "x": 2,
      "y": 34,
      "z": 5,
      "name": "Rock_Volcanic"
    },
    {
      "x": 2,
      "y": 35,
      "z": 5,
      "name": "Rock_Volcanic"
    },
    {
      "x": 2,
      "y": 36,
      "z": 5,
      "name": "Rock_Volcanic"
    },
    {
      "x": 2,
      "y": 37,
      "z": 5,
      "name": "Rock_Volcanic"
    },
    {
      "x": 2,
      "y": 38,
      "z": 5,
      "name": "Rock_Volcanic"
    },
    {
      "x": 2,
      "y": 39,
      "z": 5,
      "name": "Rock_Volcanic"
    },
    {
      "x": 2,
      "y": 40,
      "z": 5,
      "name": "Rock_Volcanic"
    },
    {
      "x": 2,
      "y": 41,
      "z": 5,
      "name": "Rock_Volcanic"
    },
    {
      "x": 2,
      "y": 42,
      "z": 5,
      "name": "Rock_Volcanic"
    },
    {
      "x": 2,
      "y": 43,
      "z": 5,
      "name": "Rock_Volcanic"
    },
    {
      "x": 2,
      "y": 44,
      "z": 5,
      "name": "Rock_Volcanic"
    },
    {
      "x": 2,
      "y": 31,
      "z": 6,
      "name": "Rock_Volcanic"
    },
    {
      "x": 2,
      "y": 32,
      "z": 6,
      "name": "Rock_Volcanic"
    },
    {
      "x": 2,
      "y": 33,
      "z": 6,
      "name": "Rock_Volcanic"
    },
    {
      "x": 2,
      "y": 34,
      "z": 6,
      "name": "Rock_Volcanic"
    },
    {
      "x": 2,
      "y": 35,
      "z": 6,
      "name": "Rock_Volcanic"
    },
    {
      "x": 2,
      "y": 36,
      "z": 6,
      "name": "Rock_Volcanic"
    },
    {
      "x": 2,
      "y": 37,
      "z": 6,
      "name": "Rock_Volcanic"
    },
    {
      "x": 2,
      "y": 38,
      "z": 6,
      "name": "Rock_Volcanic"
    },
    {
      "x": 2,
      "y": 39,
      "z": 6,
      "name": "Rock_Volcanic"
    },
    {
      "x": 2,
      "y": 40,
      "z": 6,
      "name": "Rock_Volcanic"
    },
    {
      "x": 2,
      "y": 41,
      "z": 6,
      "name": "Rock_Volcanic_Cracked_Lava"
    },
    {
      "x": 2,
      "y": 42,
      "z": 6,
      "name": "Rock_Volcanic"
    },
    {
      "x": 2,
      "y": 43,
      "z": 6,
      "name": "Rock_Volcanic"
    },
    {
      "x": 2,
      "y": 30,
      "z": 7,
      "name": "Rock_Volcanic"
    },
    {
      "x": 2,
      "y": 31,
      "z": 7,
      "name": "Rock_Volcanic"
    },
    {
      "x": 2,
      "y": 32,
      "z": 7,
      "name": "Rock_Volcanic"
    },
    {
      "x": 2,
      "y": 33,
      "z": 7,
      "name": "Rock_Volcanic"
    },
    {
      "x": 2,
      "y": 34,
      "z": 7,
      "name": "Rock_Volcanic"
    },
    {
      "x": 2,
      "y": 35,
      "z": 7,
      "name": "Rock_Volcanic"
    },
    {
      "x": 2,
      "y": 36,
      "z": 7,
      "name": "Rock_Volcanic"
    },
    {
      "x": 2,
      "y": 37,
      "z": 7,
      "name": "Rock_Volcanic"
    },
    {
      "x": 2,
      "y": 38,
      "z": 7,
      "name": "Rock_Volcanic"
    },
    {
      "x": 2,
      "y": 39,
      "z": 7,
      "name": "Rock_Volcanic"
    },
    {
      "x": 2,
      "y": 40,
      "z": 7,
      "name": "Rock_Volcanic_Cracked_Lava"
    },
    {
      "x": 2,
      "y": 41,
      "z": 7,
      "name": "Rock_Volcanic_Cracked_Lava"
    },
    {
      "x": 2,
      "y": 42,
      "z": 7,
      "name": "Rock_Volcanic_Cracked_Lava"
    },
    {
      "x": 2,
      "y": 29,
      "z": 8,
      "name": "Rock_Volcanic"
    },
    {
      "x": 2,
      "y": 30,
      "z": 8,
      "name": "Rock_Volcanic"
    },
    {
      "x": 2,
      "y": 31,
      "z": 8,
      "name": "Rock_Volcanic"
    },
    {
      "x": 2,
      "y": 32,
      "z": 8,
      "name": "Rock_Volcanic"
    },
    {
      "x": 2,
      "y": 33,
      "z": 8,
      "name": "Rock_Volcanic"
    },
    {
      "x": 2,
      "y": 34,
      "z": 8,
      "name": "Rock_Volcanic"
    },
    {
      "x": 2,
      "y": 35,
      "z": 8,
      "name": "Rock_Volcanic"
    },
    {
      "x": 2,
      "y": 36,
      "z": 8,
      "name": "Rock_Volcanic"
    },
    {
      "x": 2,
      "y": 37,
      "z": 8,
      "name": "Rock_Volcanic"
    },
    {
      "x": 2,
      "y": 38,
      "z": 8,
      "name": "Rock_Volcanic"
    },
    {
      "x": 2,
      "y": 39,
      "z": 8,
      "name": "Rock_Volcanic"
    },
    {
      "x": 2,
      "y": 40,
      "z": 8,
      "name": "Rock_Volcanic_Cracked_Lava"
    },
    {
      "x": 2,
      "y": 41,
      "z": 8,
      "name": "Rock_Volcanic_Cracked_Lava"
    },
    {
      "x": 2,
      "y": 29,
      "z": 9,
      "name": "Rock_Volcanic"
    },
    {
      "x": 2,
      "y": 30,
      "z": 9,
      "name": "Rock_Volcanic"
    },
    {
      "x": 2,
      "y": 31,
      "z": 9,
      "name": "Rock_Volcanic"
    },
    {
      "x": 2,
      "y": 32,
      "z": 9,
      "name": "Rock_Volcanic"
    },
    {
      "x": 2,
      "y": 33,
      "z": 9,
      "name": "Rock_Volcanic"
    },
    {
      "x": 2,
      "y": 34,
      "z": 9,
      "name": "Rock_Volcanic"
    },
    {
      "x": 2,
      "y": 35,
      "z": 9,
      "name": "Rock_Volcanic"
    },
    {
      "x": 2,
      "y": 36,
      "z": 9,
      "name": "Rock_Volcanic"
    },
    {
      "x": 2,
      "y": 37,
      "z": 9,
      "name": "Rock_Volcanic"
    },
    {
      "x": 2,
      "y": 38,
      "z": 9,
      "name": "Rock_Volcanic"
    },
    {
      "x": 2,
      "y": 39,
      "z": 9,
      "name": "Rock_Volcanic"
    },
    {
      "x": 2,
      "y": 40,
      "z": 9,
      "name": "Rock_Volcanic_Cracked_Lava"
    },
    {
      "x": 2,
      "y": 29,
      "z": 10,
      "name": "Rock_Volcanic"
    },
    {
      "x": 2,
      "y": 30,
      "z": 10,
      "name": "Rock_Volcanic"
    },
    {
      "x": 2,
      "y": 31,
      "z": 10,
      "name": "Rock_Volcanic"
    },
    {
      "x": 2,
      "y": 32,
      "z": 10,
      "name": "Rock_Volcanic"
    },
    {
      "x": 2,
      "y": 33,
      "z": 10,
      "name": "Rock_Volcanic"
    },
    {
      "x": 2,
      "y": 34,
      "z": 10,
      "name": "Rock_Volcanic"
    },
    {
      "x": 2,
      "y": 35,
      "z": 10,
      "name": "Rock_Volcanic"
    },
    {
      "x": 2,
      "y": 36,
      "z": 10,
      "name": "Rock_Volcanic"
    },
    {
      "x": 2,
      "y": 37,
      "z": 10,
      "name": "Rock_Volcanic"
    },
    {
      "x": 2,
      "y": 38,
      "z": 10,
      "name": "Rock_Volcanic"
    },
    {
      "x": 2,
      "y": 28,
      "z": 11,
      "name": "Rock_Volcanic"
    },
    {
      "x": 2,
      "y": 29,
      "z": 11,
      "name": "Rock_Volcanic"
    },
    {
      "x": 2,
      "y": 30,
      "z": 11,
      "name": "Rock_Volcanic"
    },
    {
      "x": 2,
      "y": 31,
      "z": 11,
      "name": "Rock_Volcanic"
    },
    {
      "x": 2,
      "y": 32,
      "z": 11,
      "name": "Rock_Volcanic"
    },
    {
      "x": 2,
      "y": 33,
      "z": 11,
      "name": "Rock_Volcanic"
    },
    {
      "x": 2,
      "y": 34,
      "z": 11,
      "name": "Rock_Volcanic"
    },
    {
      "x": 2,
      "y": 35,
      "z": 11,
      "name": "Rock_Volcanic"
    },
    {
      "x": 2,
      "y": 29,
      "z": 12,
      "name": "Rock_Volcanic"
    },
    {
      "x": 2,
      "y": 30,
      "z": 12,
      "name": "Rock_Volcanic"
    },
    {
      "x": 2,
      "y": 31,
      "z": 12,
      "name": "Rock_Volcanic"
    },
    {
      "x": 2,
      "y": 32,
      "z": 12,
      "name": "Rock_Volcanic"
    },
    {
      "x": 3,
      "y": 37,
      "z": 3,
      "name": "Rock_Volcanic"
    },
    {
      "x": 3,
      "y": 38,
      "z": 3,
      "name": "Rock_Volcanic"
    },
    {
      "x": 3,
      "y": 39,
      "z": 3,
      "name": "Rock_Volcanic"
    },
    {
      "x": 3,
      "y": 33,
      "z": 4,
      "name": "Rock_Volcanic"
    },
    {
      "x": 3,
      "y": 34,
      "z": 4,
      "name": "Rock_Volcanic"
    },
    {
      "x": 3,
      "y": 35,
      "z": 4,
      "name": "Rock_Volcanic"
    },
    {
      "x": 3,
      "y": 36,
      "z": 4,
      "name": "Rock_Volcanic"
    },
    {
      "x": 3,
      "y": 37,
      "z": 4,
      "name": "Rock_Volcanic"
    },
    {
      "x": 3,
      "y": 38,
      "z": 4,
      "name": "Rock_Volcanic"
    },
    {
      "x": 3,
      "y": 39,
      "z": 4,
      "name": "Rock_Volcanic"
    },
    {
      "x": 3,
      "y": 40,
      "z": 4,
      "name": "Rock_Volcanic"
    },
    {
      "x": 3,
      "y": 41,
      "z": 4,
      "name": "Rock_Volcanic"
    },
    {
      "x": 3,
      "y": 31,
      "z": 5,
      "name": "Rock_Volcanic"
    },
    {
      "x": 3,
      "y": 32,
      "z": 5,
      "name": "Rock_Volcanic"
    },
    {
      "x": 3,
      "y": 33,
      "z": 5,
      "name": "Rock_Volcanic"
    },
    {
      "x": 3,
      "y": 34,
      "z": 5,
      "name": "Rock_Volcanic"
    },
    {
      "x": 3,
      "y": 35,
      "z": 5,
      "name": "Rock_Volcanic"
    },
    {
      "x": 3,
      "y": 36,
      "z": 5,
      "name": "Rock_Volcanic"
    },
    {
      "x": 3,
      "y": 37,
      "z": 5,
      "name": "Rock_Volcanic"
    },
    {
      "x": 3,
      "y": 38,
      "z": 5,
      "name": "Rock_Volcanic"
    },
    {
      "x": 3,
      "y": 39,
      "z": 5,
      "name": "Rock_Volcanic"
    },
    {
      "x": 3,
      "y": 40,
      "z": 5,
      "name": "Rock_Volcanic"
    },
    {
      "x": 3,
      "y": 41,
      "z": 5,
      "name": "Rock_Volcanic"
    },
    {
      "x": 3,
      "y": 42,
      "z": 5,
      "name": "Rock_Volcanic"
    },
    {
      "x": 3,
      "y": 30,
      "z": 6,
      "name": "Rock_Volcanic"
    },
    {
      "x": 3,
      "y": 31,
      "z": 6,
      "name": "Rock_Volcanic"
    },
    {
      "x": 3,
      "y": 32,
      "z": 6,
      "name": "Rock_Volcanic"
    },
    {
      "x": 3,
      "y": 33,
      "z": 6,
      "name": "Rock_Volcanic"
    },
    {
      "x": 3,
      "y": 34,
      "z": 6,
      "name": "Rock_Volcanic"
    },
    {
      "x": 3,
      "y": 35,
      "z": 6,
      "name": "Rock_Volcanic"
    },
    {
      "x": 3,
      "y": 36,
      "z": 6,
      "name": "Rock_Volcanic"
    },
    {
      "x": 3,
      "y": 37,
      "z": 6,
      "name": "Rock_Volcanic"
    },
    {
      "x": 3,
      "y": 38,
      "z": 6,
      "name": "Rock_Volcanic"
    },
    {
      "x": 3,
      "y": 39,
      "z": 6,
      "name": "Rock_Volcanic"
    },
    {
      "x": 3,
      "y": 40,
      "z": 6,
      "name": "Rock_Volcanic"
    },
    {
      "x": 3,
      "y": 41,
      "z": 6,
      "name": "Rock_Volcanic_Cracked_Lava"
    },
    {
      "x": 3,
      "y": 42,
      "z": 6,
      "name": "Rock_Volcanic"
    },
    {
      "x": 3,
      "y": 29,
      "z": 7,
      "name": "Rock_Volcanic"
    },
    {
      "x": 3,
      "y": 30,
      "z": 7,
      "name": "Rock_Volcanic"
    },
    {
      "x": 3,
      "y": 31,
      "z": 7,
      "name": "Rock_Volcanic"
    },
    {
      "x": 3,
      "y": 32,
      "z": 7,
      "name": "Rock_Volcanic"
    },
    {
      "x": 3,
      "y": 33,
      "z": 7,
      "name": "Rock_Volcanic"
    },
    {
      "x": 3,
      "y": 34,
      "z": 7,
      "name": "Rock_Volcanic"
    },
    {
      "x": 3,
      "y": 35,
      "z": 7,
      "name": "Rock_Volcanic"
    },
    {
      "x": 3,
      "y": 36,
      "z": 7,
      "name": "Rock_Volcanic"
    },
    {
      "x": 3,
      "y": 37,
      "z": 7,
      "name": "Rock_Volcanic"
    },
    {
      "x": 3,
      "y": 38,
      "z": 7,
      "name": "Rock_Volcanic"
    },
    {
      "x": 3,
      "y": 39,
      "z": 7,
      "name": "Rock_Volcanic"
    },
    {
      "x": 3,
      "y": 40,
      "z": 7,
      "name": "Rock_Volcanic"
    },
    {
      "x": 3,
      "y": 41,
      "z": 7,
      "name": "Rock_Volcanic_Cracked_Lava"
    },
    {
      "x": 3,
      "y": 28,
      "z": 8,
      "name": "Rock_Volcanic"
    },
    {
      "x": 3,
      "y": 29,
      "z": 8,
      "name": "Rock_Volcanic"
    },
    {
      "x": 3,
      "y": 30,
      "z": 8,
      "name": "Rock_Volcanic"
    },
    {
      "x": 3,
      "y": 31,
      "z": 8,
      "name": "Rock_Volcanic"
    },
    {
      "x": 3,
      "y": 32,
      "z": 8,
      "name": "Rock_Volcanic"
    },
    {
      "x": 3,
      "y": 33,
      "z": 8,
      "name": "Rock_Volcanic"
    },
    {
      "x": 3,
      "y": 34,
      "z": 8,
      "name": "Rock_Volcanic"
    },
    {
      "x": 3,
      "y": 35,
      "z": 8,
      "name": "Rock_Volcanic"
    },
    {
      "x": 3,
      "y": 36,
      "z": 8,
      "name": "Rock_Volcanic"
    },
    {
      "x": 3,
      "y": 37,
      "z": 8,
      "name": "Rock_Volcanic"
    },
    {
      "x": 3,
      "y": 38,
      "z": 8,
      "name": "Rock_Volcanic"
    },
    {
      "x": 3,
      "y": 39,
      "z": 8,
      "name": "Rock_Volcanic"
    },
    {
      "x": 3,
      "y": 40,
      "z": 8,
      "name": "Rock_Volcanic_Cracked_Lava"
    },
    {
      "x": 3,
      "y": 41,
      "z": 8,
      "name": "Rock_Volcanic_Cracked_Lava"
    },
    {
      "x": 3,
      "y": 28,
      "z": 9,
      "name": "Rock_Volcanic"
    },
    {
      "x": 3,
      "y": 29,
      "z": 9,
      "name": "Rock_Volcanic"
    },
    {
      "x": 3,
      "y": 30,
      "z": 9,
      "name": "Rock_Volcanic"
    },
    {
      "x": 3,
      "y": 31,
      "z": 9,
      "name": "Rock_Volcanic"
    },
    {
      "x": 3,
      "y": 32,
      "z": 9,
      "name": "Rock_Volcanic"
    },
    {
      "x": 3,
      "y": 33,
      "z": 9,
      "name": "Rock_Volcanic"
    },
    {
      "x": 3,
      "y": 34,
      "z": 9,
      "name": "Rock_Volcanic"
    },
    {
      "x": 3,
      "y": 35,
      "z": 9,
      "name": "Rock_Volcanic"
    },
    {
      "x": 3,
      "y": 36,
      "z": 9,
      "name": "Rock_Volcanic"
    },
    {
      "x": 3,
      "y": 37,
      "z": 9,
      "name": "Rock_Volcanic"
    },
    {
      "x": 3,
      "y": 38,
      "z": 9,
      "name": "Rock_Volcanic"
    },
    {
      "x": 3,
      "y": 39,
      "z": 9,
      "name": "Rock_Volcanic"
    },
    {
      "x": 3,
      "y": 40,
      "z": 9,
      "name": "Rock_Volcanic_Cracked_Lava"
    },
    {
      "x": 3,
      "y": 28,
      "z": 10,
      "name": "Rock_Volcanic"
    },
    {
      "x": 3,
      "y": 29,
      "z": 10,
      "name": "Rock_Volcanic"
    },
    {
      "x": 3,
      "y": 30,
      "z": 10,
      "name": "Rock_Volcanic"
    },
    {
      "x": 3,
      "y": 31,
      "z": 10,
      "name": "Rock_Volcanic"
    },
    {
      "x": 3,
      "y": 32,
      "z": 10,
      "name": "Rock_Volcanic"
    },
    {
      "x": 3,
      "y": 33,
      "z": 10,
      "name": "Rock_Volcanic"
    },
    {
      "x": 3,
      "y": 34,
      "z": 10,
      "name": "Rock_Volcanic"
    },
    {
      "x": 3,
      "y": 35,
      "z": 10,
      "name": "Rock_Volcanic"
    },
    {
      "x": 3,
      "y": 36,
      "z": 10,
      "name": "Rock_Volcanic"
    },
    {
      "x": 3,
      "y": 37,
      "z": 10,
      "name": "Rock_Volcanic"
    },
    {
      "x": 3,
      "y": 38,
      "z": 10,
      "name": "Rock_Volcanic"
    },
    {
      "x": 3,
      "y": 28,
      "z": 11,
      "name": "Rock_Volcanic"
    },
    {
      "x": 3,
      "y": 29,
      "z": 11,
      "name": "Rock_Volcanic"
    },
    {
      "x": 3,
      "y": 30,
      "z": 11,
      "name": "Rock_Volcanic"
    },
    {
      "x": 3,
      "y": 31,
      "z": 11,
      "name": "Rock_Volcanic"
    },
    {
      "x": 3,
      "y": 32,
      "z": 11,
      "name": "Rock_Volcanic"
    },
    {
      "x": 3,
      "y": 33,
      "z": 11,
      "name": "Rock_Volcanic"
    },
    {
      "x": 3,
      "y": 34,
      "z": 11,
      "name": "Rock_Volcanic"
    },
    {
      "x": 3,
      "y": 35,
      "z": 11,
      "name": "Rock_Volcanic"
    },
    {
      "x": 3,
      "y": 36,
      "z": 11,
      "name": "Rock_Volcanic"
    },
    {
      "x": 3,
      "y": 37,
      "z": 11,
      "name": "Rock_Volcanic"
    },
    {
      "x": 3,
      "y": 28,
      "z": 12,
      "name": "Rock_Volcanic"
    },
    {
      "x": 3,
      "y": 29,
      "z": 12,
      "name": "Rock_Volcanic"
    },
    {
      "x": 3,
      "y": 30,
      "z": 12,
      "name": "Rock_Volcanic"
    },
    {
      "x": 3,
      "y": 31,
      "z": 12,
      "name": "Rock_Volcanic"
    },
    {
      "x": 3,
      "y": 32,
      "z": 12,
      "name": "Rock_Volcanic"
    },
    {
      "x": 3,
      "y": 33,
      "z": 12,
      "name": "Rock_Volcanic"
    },
    {
      "x": 3,
      "y": 29,
      "z": 13,
      "name": "Rock_Volcanic"
    },
    {
      "x": 3,
      "y": 30,
      "z": 13,
      "name": "Rock_Volcanic"
    },
    {
      "x": 3,
      "y": 31,
      "z": 13,
      "name": "Rock_Volcanic"
    },
    {
      "x": 3,
      "y": 32,
      "z": 13,
      "name": "Rock_Volcanic"
    },
    {
      "x": 4,
      "y": 36,
      "z": 3,
      "name": "Rock_Volcanic"
    },
    {
      "x": 4,
      "y": 37,
      "z": 3,
      "name": "Rock_Volcanic"
    },
    {
      "x": 4,
      "y": 33,
      "z": 4,
      "name": "Rock_Volcanic"
    },
    {
      "x": 4,
      "y": 34,
      "z": 4,
      "name": "Rock_Volcanic"
    },
    {
      "x": 4,
      "y": 35,
      "z": 4,
      "name": "Rock_Volcanic"
    },
    {
      "x": 4,
      "y": 36,
      "z": 4,
      "name": "Rock_Volcanic"
    },
    {
      "x": 4,
      "y": 37,
      "z": 4,
      "name": "Rock_Volcanic"
    },
    {
      "x": 4,
      "y": 38,
      "z": 4,
      "name": "Rock_Volcanic"
    },
    {
      "x": 4,
      "y": 39,
      "z": 4,
      "name": "Rock_Volcanic"
    },
    {
      "x": 4,
      "y": 30,
      "z": 5,
      "name": "Rock_Volcanic"
    },
    {
      "x": 4,
      "y": 31,
      "z": 5,
      "name": "Rock_Volcanic"
    },
    {
      "x": 4,
      "y": 32,
      "z": 5,
      "name": "Rock_Volcanic"
    },
    {
      "x": 4,
      "y": 33,
      "z": 5,
      "name": "Rock_Volcanic"
    },
    {
      "x": 4,
      "y": 34,
      "z": 5,
      "name": "Rock_Volcanic"
    },
    {
      "x": 4,
      "y": 35,
      "z": 5,
      "name": "Rock_Volcanic"
    },
    {
      "x": 4,
      "y": 36,
      "z": 5,
      "name": "Rock_Volcanic"
    },
    {
      "x": 4,
      "y": 37,
      "z": 5,
      "name": "Rock_Volcanic"
    },
    {
      "x": 4,
      "y": 38,
      "z": 5,
      "name": "Rock_Volcanic"
    },
    {
      "x": 4,
      "y": 39,
      "z": 5,
      "name": "Rock_Volcanic"
    },
    {
      "x": 4,
      "y": 40,
      "z": 5,
      "name": "Rock_Volcanic"
    },
    {
      "x": 4,
      "y": 29,
      "z": 6,
      "name": "Rock_Volcanic"
    },
    {
      "x": 4,
      "y": 30,
      "z": 6,
      "name": "Rock_Volcanic"
    },
    {
      "x": 4,
      "y": 31,
      "z": 6,
      "name": "Rock_Volcanic"
    },
    {
      "x": 4,
      "y": 32,
      "z": 6,
      "name": "Rock_Volcanic"
    },
    {
      "x": 4,
      "y": 33,
      "z": 6,
      "name": "Rock_Volcanic"
    },
    {
      "x": 4,
      "y": 34,
      "z": 6,
      "name": "Rock_Volcanic"
    },
    {
      "x": 4,
      "y": 35,
      "z": 6,
      "name": "Rock_Volcanic"
    },
    {
      "x": 4,
      "y": 36,
      "z": 6,
      "name": "Rock_Volcanic"
    },
    {
      "x": 4,
      "y": 37,
      "z": 6,
      "name": "Rock_Volcanic"
    },
    {
      "x": 4,
      "y": 38,
      "z": 6,
      "name": "Rock_Volcanic"
    },
    {
      "x": 4,
      "y": 39,
      "z": 6,
      "name": "Rock_Volcanic"
    },
    {
      "x": 4,
      "y": 40,
      "z": 6,
      "name": "Rock_Volcanic"
    },
    {
      "x": 4,
      "y": 41,
      "z": 6,
      "name": "Rock_Volcanic"
    },
    {
      "x": 4,
      "y": 28,
      "z": 7,
      "name": "Rock_Volcanic"
    },
    {
      "x": 4,
      "y": 29,
      "z": 7,
      "name": "Rock_Volcanic"
    },
    {
      "x": 4,
      "y": 30,
      "z": 7,
      "name": "Rock_Volcanic"
    },
    {
      "x": 4,
      "y": 31,
      "z": 7,
      "name": "Rock_Volcanic"
    },
    {
      "x": 4,
      "y": 32,
      "z": 7,
      "name": "Rock_Volcanic"
    },
    {
      "x": 4,
      "y": 33,
      "z": 7,
      "name": "Rock_Volcanic"
    },
    {
      "x": 4,
      "y": 34,
      "z": 7,
      "name": "Rock_Volcanic"
    },
    {
      "x": 4,
      "y": 35,
      "z": 7,
      "name": "Rock_Volcanic"
    },
    {
      "x": 4,
      "y": 36,
      "z": 7,
      "name": "Rock_Volcanic"
    },
    {
      "x": 4,
      "y": 37,
      "z": 7,
      "name": "Rock_Volcanic"
    },
    {
      "x": 4,
      "y": 38,
      "z": 7,
      "name": "Rock_Volcanic"
    },
    {
      "x": 4,
      "y": 39,
      "z": 7,
      "name": "Rock_Volcanic"
    },
    {
      "x": 4,
      "y": 40,
      "z": 7,
      "name": "Rock_Volcanic"
    },
    {
      "x": 4,
      "y": 41,
      "z": 7,
      "name": "Rock_Volcanic_Cracked_Lava"
    },
    {
      "x": 4,
      "y": 27,
      "z": 8,
      "name": "Rock_Volcanic"
    },
    {
      "x": 4,
      "y": 28,
      "z": 8,
      "name": "Rock_Volcanic"
    },
    {
      "x": 4,
      "y": 29,
      "z": 8,
      "name": "Rock_Volcanic"
    },
    {
      "x": 4,
      "y": 30,
      "z": 8,
      "name": "Rock_Volcanic"
    },
    {
      "x": 4,
      "y": 31,
      "z": 8,
      "name": "Rock_Volcanic"
    },
    {
      "x": 4,
      "y": 32,
      "z": 8,
      "name": "Rock_Volcanic"
    },
    {
      "x": 4,
      "y": 33,
      "z": 8,
      "name": "Rock_Volcanic"
    },
    {
      "x": 4,
      "y": 34,
      "z": 8,
      "name": "Rock_Volcanic"
    },
    {
      "x": 4,
      "y": 35,
      "z": 8,
      "name": "Rock_Volcanic"
    },
    {
      "x": 4,
      "y": 36,
      "z": 8,
      "name": "Rock_Volcanic"
    },
    {
      "x": 4,
      "y": 37,
      "z": 8,
      "name": "Rock_Volcanic"
    },
    {
      "x": 4,
      "y": 38,
      "z": 8,
      "name": "Rock_Volcanic"
    },
    {
      "x": 4,
      "y": 39,
      "z": 8,
      "name": "Rock_Volcanic"
    },
    {
      "x": 4,
      "y": 40,
      "z": 8,
      "name": "Rock_Volcanic"
    },
    {
      "x": 4,
      "y": 27,
      "z": 9,
      "name": "Rock_Volcanic"
    },
    {
      "x": 4,
      "y": 28,
      "z": 9,
      "name": "Rock_Volcanic"
    },
    {
      "x": 4,
      "y": 29,
      "z": 9,
      "name": "Rock_Volcanic"
    },
    {
      "x": 4,
      "y": 30,
      "z": 9,
      "name": "Rock_Volcanic"
    },
    {
      "x": 4,
      "y": 31,
      "z": 9,
      "name": "Rock_Volcanic"
    },
    {
      "x": 4,
      "y": 32,
      "z": 9,
      "name": "Rock_Volcanic"
    },
    {
      "x": 4,
      "y": 33,
      "z": 9,
      "name": "Rock_Volcanic"
    },
    {
      "x": 4,
      "y": 34,
      "z": 9,
      "name": "Rock_Volcanic"
    },
    {
      "x": 4,
      "y": 35,
      "z": 9,
      "name": "Rock_Volcanic"
    },
    {
      "x": 4,
      "y": 36,
      "z": 9,
      "name": "Rock_Volcanic"
    },
    {
      "x": 4,
      "y": 37,
      "z": 9,
      "name": "Rock_Volcanic"
    },
    {
      "x": 4,
      "y": 38,
      "z": 9,
      "name": "Rock_Volcanic"
    },
    {
      "x": 4,
      "y": 39,
      "z": 9,
      "name": "Rock_Volcanic"
    },
    {
      "x": 4,
      "y": 40,
      "z": 9,
      "name": "Rock_Volcanic"
    },
    {
      "x": 4,
      "y": 26,
      "z": 10,
      "name": "Rock_Volcanic"
    },
    {
      "x": 4,
      "y": 27,
      "z": 10,
      "name": "Rock_Volcanic"
    },
    {
      "x": 4,
      "y": 28,
      "z": 10,
      "name": "Rock_Volcanic"
    },
    {
      "x": 4,
      "y": 29,
      "z": 10,
      "name": "Rock_Volcanic"
    },
    {
      "x": 4,
      "y": 30,
      "z": 10,
      "name": "Rock_Volcanic"
    },
    {
      "x": 4,
      "y": 31,
      "z": 10,
      "name": "Rock_Volcanic"
    },
    {
      "x": 4,
      "y": 32,
      "z": 10,
      "name": "Rock_Volcanic"
    },
    {
      "x": 4,
      "y": 33,
      "z": 10,
      "name": "Rock_Volcanic"
    },
    {
      "x": 4,
      "y": 34,
      "z": 10,
      "name": "Rock_Volcanic"
    },
    {
      "x": 4,
      "y": 35,
      "z": 10,
      "name": "Rock_Volcanic"
    },
    {
      "x": 4,
      "y": 36,
      "z": 10,
      "name": "Rock_Volcanic"
    },
    {
      "x": 4,
      "y": 37,
      "z": 10,
      "name": "Rock_Volcanic"
    },
    {
      "x": 4,
      "y": 38,
      "z": 10,
      "name": "Rock_Volcanic"
    },
    {
      "x": 4,
      "y": 26,
      "z": 11,
      "name": "Rock_Volcanic"
    },
    {
      "x": 4,
      "y": 27,
      "z": 11,
      "name": "Rock_Volcanic"
    },
    {
      "x": 4,
      "y": 28,
      "z": 11,
      "name": "Rock_Volcanic"
    },
    {
      "x": 4,
      "y": 29,
      "z": 11,
      "name": "Rock_Volcanic"
    },
    {
      "x": 4,
      "y": 30,
      "z": 11,
      "name": "Rock_Volcanic"
    },
    {
      "x": 4,
      "y": 31,
      "z": 11,
      "name": "Rock_Volcanic"
    },
    {
      "x": 4,
      "y": 32,
      "z": 11,
      "name": "Rock_Volcanic"
    },
    {
      "x": 4,
      "y": 33,
      "z": 11,
      "name": "Rock_Volcanic"
    },
    {
      "x": 4,
      "y": 34,
      "z": 11,
      "name": "Rock_Volcanic"
    },
    {
      "x": 4,
      "y": 35,
      "z": 11,
      "name": "Rock_Volcanic"
    },
    {
      "x": 4,
      "y": 36,
      "z": 11,
      "name": "Rock_Volcanic"
    },
    {
      "x": 4,
      "y": 26,
      "z": 12,
      "name": "Rock_Volcanic"
    },
    {
      "x": 4,
      "y": 27,
      "z": 12,
      "name": "Rock_Volcanic"
    },
    {
      "x": 4,
      "y": 28,
      "z": 12,
      "name": "Rock_Volcanic"
    },
    {
      "x": 4,
      "y": 29,
      "z": 12,
      "name": "Rock_Volcanic"
    },
    {
      "x": 4,
      "y": 30,
      "z": 12,
      "name": "Rock_Volcanic"
    },
    {
      "x": 4,
      "y": 31,
      "z": 12,
      "name": "Rock_Volcanic"
    },
    {
      "x": 4,
      "y": 32,
      "z": 12,
      "name": "Rock_Volcanic"
    },
    {
      "x": 4,
      "y": 33,
      "z": 12,
      "name": "Rock_Volcanic"
    },
    {
      "x": 4,
      "y": 34,
      "z": 12,
      "name": "Rock_Volcanic"
    },
    {
      "x": 4,
      "y": 27,
      "z": 13,
      "name": "Rock_Volcanic"
    },
    {
      "x": 4,
      "y": 28,
      "z": 13,
      "name": "Rock_Volcanic"
    },
    {
      "x": 4,
      "y": 29,
      "z": 13,
      "name": "Rock_Volcanic"
    },
    {
      "x": 4,
      "y": 30,
      "z": 13,
      "name": "Rock_Volcanic"
    },
    {
      "x": 4,
      "y": 31,
      "z": 13,
      "name": "Rock_Volcanic"
    },
    {
      "x": 4,
      "y": 32,
      "z": 13,
      "name": "Rock_Volcanic"
    },
    {
      "x": 5,
      "y": 33,
      "z": 4,
      "name": "Rock_Volcanic"
    },
    {
      "x": 5,
      "y": 34,
      "z": 4,
      "name": "Rock_Volcanic"
    },
    {
      "x": 5,
      "y": 36,
      "z": 4,
      "name": "Rock_Volcanic"
    },
    {
      "x": 5,
      "y": 37,
      "z": 4,
      "name": "Rock_Volcanic"
    },
    {
      "x": 5,
      "y": 30,
      "z": 5,
      "name": "Rock_Volcanic"
    },
    {
      "x": 5,
      "y": 31,
      "z": 5,
      "name": "Rock_Volcanic"
    },
    {
      "x": 5,
      "y": 32,
      "z": 5,
      "name": "Rock_Volcanic"
    },
    {
      "x": 5,
      "y": 33,
      "z": 5,
      "name": "Rock_Volcanic"
    },
    {
      "x": 5,
      "y": 34,
      "z": 5,
      "name": "Rock_Volcanic"
    },
    {
      "x": 5,
      "y": 35,
      "z": 5,
      "name": "Rock_Volcanic"
    },
    {
      "x": 5,
      "y": 36,
      "z": 5,
      "name": "Rock_Volcanic"
    },
    {
      "x": 5,
      "y": 37,
      "z": 5,
      "name": "Rock_Volcanic"
    },
    {
      "x": 5,
      "y": 38,
      "z": 5,
      "name": "Rock_Volcanic"
    },
    {
      "x": 5,
      "y": 39,
      "z": 5,
      "name": "Rock_Volcanic"
    },
    {
      "x": 5,
      "y": 28,
      "z": 6,
      "name": "Rock_Volcanic"
    },
    {
      "x": 5,
      "y": 29,
      "z": 6,
      "name": "Rock_Volcanic"
    },
    {
      "x": 5,
      "y": 30,
      "z": 6,
      "name": "Rock_Volcanic"
    },
    {
      "x": 5,
      "y": 31,
      "z": 6,
      "name": "Rock_Volcanic"
    },
    {
      "x": 5,
      "y": 32,
      "z": 6,
      "name": "Rock_Volcanic"
    },
    {
      "x": 5,
      "y": 33,
      "z": 6,
      "name": "Rock_Volcanic"
    },
    {
      "x": 5,
      "y": 34,
      "z": 6,
      "name": "Rock_Volcanic"
    },
    {
      "x": 5,
      "y": 35,
      "z": 6,
      "name": "Rock_Volcanic"
    },
    {
      "x": 5,
      "y": 36,
      "z": 6,
      "name": "Rock_Volcanic"
    },
    {
      "x": 5,
      "y": 37,
      "z": 6,
      "name": "Rock_Volcanic"
    },
    {
      "x": 5,
      "y": 38,
      "z": 6,
      "name": "Rock_Volcanic"
    },
    {
      "x": 5,
      "y": 39,
      "z": 6,
      "name": "Rock_Volcanic"
    },
    {
      "x": 5,
      "y": 27,
      "z": 7,
      "name": "Rock_Volcanic"
    },
    {
      "x": 5,
      "y": 28,
      "z": 7,
      "name": "Rock_Volcanic"
    },
    {
      "x": 5,
      "y": 29,
      "z": 7,
      "name": "Rock_Volcanic"
    },
    {
      "x": 5,
      "y": 30,
      "z": 7,
      "name": "Rock_Volcanic"
    },
    {
      "x": 5,
      "y": 31,
      "z": 7,
      "name": "Rock_Volcanic"
    },
    {
      "x": 5,
      "y": 32,
      "z": 7,
      "name": "Rock_Volcanic"
    },
    {
      "x": 5,
      "y": 33,
      "z": 7,
      "name": "Rock_Volcanic"
    },
    {
      "x": 5,
      "y": 34,
      "z": 7,
      "name": "Rock_Volcanic"
    },
    {
      "x": 5,
      "y": 35,
      "z": 7,
      "name": "Rock_Volcanic"
    },
    {
      "x": 5,
      "y": 36,
      "z": 7,
      "name": "Rock_Volcanic"
    },
    {
      "x": 5,
      "y": 37,
      "z": 7,
      "name": "Rock_Volcanic"
    },
    {
      "x": 5,
      "y": 38,
      "z": 7,
      "name": "Rock_Volcanic"
    },
    {
      "x": 5,
      "y": 39,
      "z": 7,
      "name": "Rock_Volcanic"
    },
    {
      "x": 5,
      "y": 26,
      "z": 8,
      "name": "Rock_Volcanic"
    },
    {
      "x": 5,
      "y": 27,
      "z": 8,
      "name": "Rock_Volcanic"
    },
    {
      "x": 5,
      "y": 28,
      "z": 8,
      "name": "Rock_Volcanic"
    },
    {
      "x": 5,
      "y": 29,
      "z": 8,
      "name": "Rock_Volcanic"
    },
    {
      "x": 5,
      "y": 30,
      "z": 8,
      "name": "Rock_Volcanic"
    },
    {
      "x": 5,
      "y": 31,
      "z": 8,
      "name": "Rock_Volcanic"
    },
    {
      "x": 5,
      "y": 32,
      "z": 8,
      "name": "Rock_Volcanic"
    },
    {
      "x": 5,
      "y": 33,
      "z": 8,
      "name": "Rock_Volcanic"
    },
    {
      "x": 5,
      "y": 34,
      "z": 8,
      "name": "Rock_Volcanic"
    },
    {
      "x": 5,
      "y": 35,
      "z": 8,
      "name": "Rock_Volcanic"
    },
    {
      "x": 5,
      "y": 36,
      "z": 8,
      "name": "Rock_Volcanic"
    },
    {
      "x": 5,
      "y": 37,
      "z": 8,
      "name": "Rock_Volcanic"
    },
    {
      "x": 5,
      "y": 38,
      "z": 8,
      "name": "Rock_Volcanic"
    },
    {
      "x": 5,
      "y": 39,
      "z": 8,
      "name": "Rock_Volcanic"
    },
    {
      "x": 5,
      "y": 25,
      "z": 9,
      "name": "Rock_Volcanic"
    },
    {
      "x": 5,
      "y": 26,
      "z": 9,
      "name": "Rock_Volcanic"
    },
    {
      "x": 5,
      "y": 27,
      "z": 9,
      "name": "Rock_Volcanic"
    },
    {
      "x": 5,
      "y": 28,
      "z": 9,
      "name": "Rock_Volcanic"
    },
    {
      "x": 5,
      "y": 29,
      "z": 9,
      "name": "Rock_Volcanic"
    },
    {
      "x": 5,
      "y": 30,
      "z": 9,
      "name": "Rock_Volcanic"
    },
    {
      "x": 5,
      "y": 31,
      "z": 9,
      "name": "Rock_Volcanic"
    },
    {
      "x": 5,
      "y": 32,
      "z": 9,
      "name": "Rock_Volcanic"
    },
    {
      "x": 5,
      "y": 33,
      "z": 9,
      "name": "Rock_Volcanic"
    },
    {
      "x": 5,
      "y": 34,
      "z": 9,
      "name": "Rock_Volcanic"
    },
    {
      "x": 5,
      "y": 35,
      "z": 9,
      "name": "Rock_Volcanic"
    },
    {
      "x": 5,
      "y": 36,
      "z": 9,
      "name": "Rock_Volcanic"
    },
    {
      "x": 5,
      "y": 37,
      "z": 9,
      "name": "Rock_Volcanic"
    },
    {
      "x": 5,
      "y": 38,
      "z": 9,
      "name": "Rock_Volcanic"
    },
    {
      "x": 5,
      "y": 25,
      "z": 10,
      "name": "Rock_Volcanic"
    },
    {
      "x": 5,
      "y": 26,
      "z": 10,
      "name": "Rock_Volcanic"
    },
    {
      "x": 5,
      "y": 27,
      "z": 10,
      "name": "Rock_Volcanic"
    },
    {
      "x": 5,
      "y": 28,
      "z": 10,
      "name": "Rock_Volcanic"
    },
    {
      "x": 5,
      "y": 29,
      "z": 10,
      "name": "Rock_Volcanic"
    },
    {
      "x": 5,
