{
  "version": 8,
  "blockIdVersion": 8,
  "anchorX": 6,
  "anchorY": 12,
  "anchorZ": 9,
  "blocks": [
    {
      "x": -12,
      "y": 26,
      "z": -11,
      "name": "Rock_Volcanic"
    },
    {
      "x": -12,
      "y": 27,
      "z": -11,
      "name": "Rock_Volcanic"
    },
    {
      "x": -12,
      "y": 28,
      "z": -11,
      "name": "Rock_Volcanic"
    },
    {
      "x": -11,
      "y": 26,
      "z": -11,
      "name": "Rock_Volcanic"
    },
    {
      "x": -11,
      "y": 27,
      "z": -11,
      "name": "Rock_Volcanic"
    },
    {
      "x": -11,
      "y": 25,
      "z": -10,
      "name": "Rock_Volcanic"
    },
    {
      "x": -11,
      "y": 26,
      "z": -10,
      "name": "Rock_Volcanic"
    },
    {
      "x": -11,
      "y": 27,
      "z": -10,
      "name": "Rock_Volcanic"
    },
    {
      "x": -11,
      "y": 24,
      "z": -9,
      "name": "Rock_Volcanic"
    },
    {
      "x": -11,
      "y": 25,
      "z": -9,
      "name": "Rock_Volcanic"
    },
    {
      "x": -11,
      "y": 26,
      "z": -9,
      "name": "Rock_Volcanic"
    },
    {
      "x": -10,
      "y": 24,
      "z": -10,
      "name": "Rock_Volcanic"
    },
    {
      "x": -10,
      "y": 25,
      "z": -10,
      "name": "Rock_Volcanic"
    },
    {
      "x": -10,
      "y": 26,
      "z": -10,
      "name": "Rock_Volcanic"
    },
    {
      "x": -10,
      "y": 23,
      "z": -9,
      "name": "Rock_Volcanic"
    },
    {
      "x": -10,
      "y": 24,
      "z": -9,
      "name": "Rock_Volcanic"
    },
    {
      "x": -10,
      "y": 25,
      "z": -9,
      "name": "Rock_Volcanic"
    },
    {
      "x": -10,
      "y": 26,
      "z": -9,
      "name": "Rock_Volcanic"
    },
    {
      "x": -10,
      "y": 23,
      "z": -8,
      "name": "Rock_Volcanic"
    },
    {
      "x": -10,
      "y": 24,
      "z": -8,
      "name": "Rock_Volcanic"
    },
    {
      "x": -10,
      "y": 25,
      "z": -8,
      "name": "Rock_Volcanic"
    },
    {
      "x": -10,
      "y": 23,
      "z": -7,
      "name": "Rock_Volcanic"
    },
    {
      "x": -10,
      "y": 24,
      "z": -7,
      "name": "Rock_Volcanic"
    },
    {
      "x": -9,
      "y": 23,
      "z": -9,
      "name": "Rock_Volcanic"
    },
    {
      "x": -9,
      "y": 24,
      "z": -9,
      "name": "Rock_Volcanic"
    },
    {
      "x": -9,
      "y": 25,
      "z": -9,
      "name": "Rock_Volcanic"
    },
    {
      "x": -9,
      "y": 22,
      "z": -8,
      "name": "Rock_Volcanic"
    },
    {
      "x": -9,
      "y": 23,
      "z": -8,
      "name": "Rock_Volcanic"
    },
    {
      "x": -9,
      "y": 24,
      "z": -8,
      "name": "Rock_Volcanic"
    },
    {
      "x": -9,
      "y": 25,
      "z": -8,
      "name": "Rock_Volcanic"
    },
    {
      "x": -9,
      "y": 22,
      "z": -7,
      "name": "Rock_Volcanic"
    },
    {
      "x": -9,
      "y": 23,
      "z": -7,
      "name": "Rock_Volcanic"
    },
    {
      "x": -9,
      "y": 24,
      "z": -7,
      "name": "Rock_Volcanic"
    },
    {
      "x": -9,
      "y": 22,
      "z": -6,
      "name": "Rock_Volcanic"
    },
    {
      "x": -9,
      "y": 23,
      "z": -6,
      "name": "Rock_Volcanic"
    },
    {
      "x": -9,
      "y": 24,
      "z": -6,
      "name": "Rock_Volcanic"
    },
    {
      "x": -8,
      "y": 23,
      "z": -9,
      "name": "Rock_Volcanic"
    },
    {
      "x": -8,
      "y": 24,
      "z": -9,
      "name": "Rock_Volcanic"
    },
    {
      "x": -8,
      "y": 22,
      "z": -8,
      "name": "Rock_Volcanic"
    },
    {
      "x": -8,
      "y": 23,
      "z": -8,
      "name": "Rock_Volcanic"
    },
    {
      "x": -8,
      "y": 24,
      "z": -8,
      "name": "Rock_Volcanic"
    },
    {
      "x": -8,
      "y": 21,
      "z": -7,
      "name": "Rock_Volcanic"
    },
    {
      "x": -8,
      "y": 22,
      "z": -7,
      "name": "Rock_Volcanic"
    },
    {
      "x": -8,
      "y": 23,
      "z": -7,
      "name": "Rock_Volcanic"
    },
    {
      "x": -8,
      "y": 24,
      "z": -7,
      "name": "Rock_Volcanic"
    },
    {
      "x": -8,
      "y": 21,
      "z": -6,
      "name": "Rock_Volcanic"
    },
    {
      "x": -8,
      "y": 22,
      "z": -6,
      "name": "Rock_Volcanic"
    },
    {
      "x": -8,
      "y": 23,
      "z": -6,
      "name": "Rock_Volcanic"
    },
    {
      "x": -8,
      "y": 24,
      "z": -6,
      "name": "Rock_Volcanic"
    },
    {
      "x": -8,
      "y": 21,
      "z": -5,
      "name": "Rock_Volcanic"
    },
    {
      "x": -8,
      "y": 22,
      "z": -5,
      "name": "Rock_Volcanic"
    },
    {
      "x": -8,
      "y": 23,
      "z": -5,
      "name": "Rock_Volcanic"
    },
    {
      "x": -7,
      "y": 22,
      "z": -8,
      "name": "Rock_Volcanic"
    },
    {
      "x": -7,
      "y": 23,
      "z": -8,
      "name": "Rock_Volcanic"
    },
    {
      "x": -7,
      "y": 24,
      "z": -8,
      "name": "Rock_Volcanic"
    },
    {
      "x": -7,
      "y": 21,
      "z": -7,
      "name": "Rock_Volcanic"
    },
    {
      "x": -7,
      "y": 22,
      "z": -7,
      "name": "Rock_Volcanic"
    },
    {
      "x": -7,
      "y": 23,
      "z": -7,
      "name": "Rock_Volcanic"
    },
    {
      "x": -7,
      "y": 24,
      "z": -7,
      "name": "Rock_Volcanic"
    },
    {
      "x": -7,
      "y": 20,
      "z": -6,
      "name": "Rock_Volcanic"
    },
    {
      "x": -7,
      "y": 21,
      "z": -6,
      "name": "Rock_Volcanic"
    },
    {
      "x": -7,
      "y": 22,
      "z": -6,
      "name": "Rock_Volcanic"
    },
    {
      "x": -7,
      "y": 23,
      "z": -6,
      "name": "Rock_Volcanic"
    },
    {
      "x": -7,
      "y": 20,
      "z": -5,
      "name": "Rock_Volcanic"
    },
    {
      "x": -7,
      "y": 21,
      "z": -5,
      "name": "Rock_Volcanic"
    },
    {
      "x": -7,
      "y": 22,
      "z": -5,
      "name": "Rock_Volcanic"
    },
    {
      "x": -7,
      "y": 20,
      "z": -4,
      "name": "Rock_Volcanic"
    },
    {
      "x": -7,
      "y": 21,
      "z": -4,
      "name": "Rock_Volcanic"
    },
    {
      "x": -7,
      "y": 22,
      "z": -4,
      "name": "Rock_Volcanic"
    },
    {
      "x": -6,
      "y": 21,
      "z": -7,
      "name": "Rock_Volcanic"
    },
    {
      "x": -6,
      "y": 22,
      "z": -7,
      "name": "Rock_Volcanic"
    },
    {
      "x": -6,
      "y": 20,
      "z": -6,
      "name": "Rock_Volcanic"
    },
    {
      "x": -6,
      "y": 21,
      "z": -6,
      "name": "Rock_Volcanic"
    },
    {
      "x": -6,
      "y": 22,
      "z": -6,
      "name": "Rock_Volcanic"
    },
    {
      "x": -6,
      "y": 19,
      "z": -5,
      "name": "Rock_Volcanic"
    },
    {
      "x": -6,
      "y": 20,
      "z": -5,
      "name": "Rock_Volcanic"
    },
    {
      "x": -6,
      "y": 21,
      "z": -5,
      "name": "Rock_Volcanic"
    },
    {
      "x": -6,
      "y": 22,
      "z": -5,
      "name": "Rock_Volcanic"
    },
    {
      "x": -6,
      "y": 19,
      "z": -4,
      "name": "Rock_Volcanic"
    },
    {
      "x": -6,
      "y": 20,
      "z": -4,
      "name": "Rock_Volcanic"
    },
    {
      "x": -6,
      "y": 21,
      "z": -4,
      "name": "Rock_Volcanic"
    },
    {
      "x": -6,
      "y": 22,
      "z": -4,
      "name": "Rock_Volcanic"
    },
    {
      "x": -6,
      "y": 19,
      "z": -3,
      "name": "Rock_Volcanic"
    },
    {
      "x": -6,
      "y": 20,
      "z": -3,
      "name": "Rock_Volcanic"
    },
    {
      "x": -5,
      "y": 20,
      "z": -6,
      "name": "Rock_Volcanic"
    },
    {
      "x": -5,
      "y": 21,
      "z": -6,
      "name": "Rock_Volcanic"
    },
    {
      "x": -5,
      "y": 22,
      "z": -6,
      "name": "Rock_Volcanic"
    },
    {
      "x": -5,
      "y": 18,
      "z": -5,
      "name": "Rock_Volcanic"
    },
    {
      "x": -5,
      "y": 19,
      "z": -5,
      "name": "Rock_Volcanic"
    },
    {
      "x": -5,
      "y": 20,
      "z": -5,
      "name": "Rock_Volcanic"
    },
    {
      "x": -5,
      "y": 21,
      "z": -5,
      "name": "Rock_Volcanic"
    },
    {
      "x": -5,
      "y": 18,
      "z": -4,
      "name": "Rock_Volcanic"
    },
    {
      "x": -5,
      "y": 19,
      "z": -4,
      "name": "Rock_Volcanic"
    },
    {
      "x": -5,
      "y": 20,
      "z": -4,
      "name": "Rock_Volcanic"
    },
    {
      "x": -5,
      "y": 21,
      "z": -4,
      "name": "Rock_Volcanic"
    },
    {
      "x": -5,
      "y": 18,
      "z": -3,
      "name": "Rock_Volcanic"
    },
    {
      "x": -5,
      "y": 19,
      "z": -3,
      "name": "Rock_Volcanic"
    },
    {
      "x": -5,
      "y": 20,
      "z": -3,
      "name": "Rock_Volcanic"
    },
    {
      "x": -4,
      "y": 18,
      "z": -5,
      "name": "Rock_Volcanic"
    },
    {
      "x": -4,
      "y": 19,
      "z": -5,
      "name": "Rock_Volcanic"
    },
    {
      "x": -4,
      "y": 20,
      "z": -5,
      "name": "Rock_Volcanic_Cracked_Lava"
    },
    {
      "x": -4,
      "y": 21,
      "z": -5,
      "name": "Rock_Volcanic"
    },
    {
      "x": -4,
      "y": 17,
      "z": -4,
      "name": "Rock_Volcanic"
    },
    {
      "x": -4,
      "y": 18,
      "z": -4,
      "name": "Rock_Volcanic"
    },
    {
      "x": -4,
      "y": 19,
      "z": -4,
      "name": "Rock_Volcanic"
    },
    {
      "x": -4,
      "y": 20,
      "z": -4,
      "name": "Rock_Volcanic_Cracked_Lava"
    },
    {
      "x": -4,
      "y": 17,
      "z": -3,
      "name": "Rock_Volcanic"
    },
    {
      "x": -4,
      "y": 18,
      "z": -3,
      "name": "Rock_Volcanic"
    },
    {
      "x": -4,
      "y": 19,
      "z": -3,
      "name": "Rock_Volcanic"
    },
    {
      "x": -4,
      "y": 20,
      "z": -3,
      "name": "Rock_Volcanic_Cracked_Lava"
    },
    {
      "x": -4,
      "y": 17,
      "z": -2,
      "name": "Rock_Volcanic"
    },
    {
      "x": -4,
      "y": 18,
      "z": -2,
      "name": "Rock_Volcanic"
    },
    {
      "x": -4,
      "y": 19,
      "z": -2,
      "name": "Rock_Volcanic"
    },
    {
      "x": -3,
      "y": 18,
      "z": -5,
      "name": "Rock_Volcanic"
    },
    {
      "x": -3,
      "y": 19,
      "z": -5,
      "name": "Rock_Volcanic_Cracked_Lava"
    },
    {
      "x": -3,
      "y": 20,
      "z": -5,
      "name": "Rock_Volcanic_Cracked_Lava"
    },
    {
      "x": -3,
      "y": 16,
      "z": -4,
      "name": "Rock_Volcanic"
    },
    {
      "x": -3,
      "y": 17,
      "z": -4,
      "name": "Rock_Volcanic"
    },
    {
      "x": -3,
      "y": 18,
      "z": -4,
      "name": "Rock_Volcanic"
    },
    {
      "x": -3,
      "y": 19,
      "z": -4,
      "name": "Rock_Volcanic_Cracked_Lava"
    },
    {
      "x": -3,
      "y": 20,
      "z": -4,
      "name": "Rock_Volcanic_Cracked_Lava"
    },
    {
      "x": -3,
      "y": 16,
      "z": -3,
      "name": "Rock_Volcanic"
    },
    {
      "x": -3,
      "y": 17,
      "z": -3,
      "name": "Rock_Volcanic"
    },
    {
      "x": -3,
      "y": 18,
      "z": -3,
      "name": "Rock_Volcanic"
    },
    {
      "x": -3,
      "y": 19,
      "z": -3,
      "name": "Rock_Volcanic_Cracked_Lava"
    },
    {
      "x": -3,
      "y": 20,
      "z": -3,
      "name": "Rock_Volcanic_Cracked_Lava"
    },
    {
      "x": -3,
      "y": 16,
      "z": -2,
      "name": "Rock_Volcanic"
    },
    {
      "x": -3,
      "y": 17,
      "z": -2,
      "name": "Rock_Volcanic"
    },
    {
      "x": -3,
      "y": 18,
      "z": -2,
      "name": "Rock_Volcanic"
    },
    {
      "x": -3,
      "y": 19,
      "z": -2,
      "name": "Rock_Volcanic"
    },
    {
      "x": -3,
      "y": 16,
      "z": -1,
      "name": "Rock_Volcanic"
    },
    {
      "x": -3,
      "y": 17,
      "z": -1,
      "name": "Rock_Volcanic"
    },
    {
      "x": -3,
      "y": 18,
      "z": -1,
      "name": "Rock_Volcanic"
    },
    {
      "x": -3,
      "y": 16,
      "z": 0,
      "name": "Rock_Volcanic"
    },
    {
      "x": -3,
      "y": 17,
      "z": 0,
      "name": "Rock_Volcanic"
    },
    {
      "x": -2,
      "y": 16,
      "z": -4,
      "name": "Rock_Volcanic"
    },
    {
      "x": -2,
      "y": 17,
      "z": -4,
      "name": "Rock_Volcanic"
    },
    {
      "x": -2,
      "y": 18,
      "z": -4,
      "name": "Rock_Volcanic"
    },
    {
      "x": -2,
      "y": 19,
      "z": -4,
      "name": "Rock_Volcanic_Cracked_Lava"
    },
    {
      "x": -2,
      "y": 20,
      "z": -4,
      "name": "Rock_Volcanic_Cracked_Lava"
    },
    {
      "x": -2,
      "y": 15,
      "z": -3,
      "name": "Rock_Volcanic"
    },
    {
      "x": -2,
      "y": 16,
      "z": -3,
      "name": "Rock_Volcanic"
    },
    {
      "x": -2,
      "y": 17,
      "z": -3,
      "name": "Rock_Volcanic"
    },
    {
      "x": -2,
      "y": 18,
      "z": -3,
      "name": "Rock_Volcanic"
    },
    {
      "x": -2,
      "y": 19,
      "z": -3,
      "name": "Rock_Volcanic_Cracked_Lava"
    },
    {
      "x": -2,
      "y": 15,
      "z": -2,
      "name": "Rock_Volcanic"
    },
    {
      "x": -2,
      "y": 16,
      "z": -2,
      "name": "Rock_Volcanic"
    },
    {
      "x": -2,
      "y": 17,
      "z": -2,
      "name": "Rock_Volcanic"
    },
    {
      "x": -2,
      "y": 18,
      "z": -2,
      "name": "Rock_Volcanic"
    },
    {
      "x": -2,
      "y": 19,
      "z": -2,
      "name": "Rock_Volcanic"
    },
    {
      "x": -2,
      "y": 14,
      "z": -1,
      "name": "Rock_Volcanic"
    },
    {
      "x": -2,
      "y": 15,
      "z": -1,
      "name": "Rock_Volcanic"
    },
    {
      "x": -2,
      "y": 16,
      "z": -1,
      "name": "Rock_Volcanic"
    },
    {
      "x": -2,
      "y": 17,
      "z": -1,
      "name": "Rock_Volcanic"
    },
    {
      "x": -2,
      "y": 18,
      "z": -1,
      "name": "Rock_Volcanic"
    },
    {
      "x": -2,
      "y": 14,
      "z": 0,
      "name": "Rock_Volcanic"
    },
    {
      "x": -2,
      "y": 15,
      "z": 0,
      "name": "Rock_Volcanic"
    },
    {
      "x": -2,
      "y": 16,
      "z": 0,
      "name": "Rock_Volcanic"
    },
    {
      "x": -2,
      "y": 17,
      "z": 0,
      "name": "Rock_Volcanic_Cracked_Lava"
    },
    {
      "x": -2,
      "y": 14,
      "z": 1,
      "name": "Rock_Volcanic"
    },
    {
      "x": -2,
      "y": 15,
      "z": 1,
      "name": "Rock_Volcanic"
    },
    {
      "x": -2,
      "y": 16,
      "z": 1,
      "name": "Rock_Volcanic"
    },
    {
      "x": -1,
      "y": 16,
      "z": -4,
      "name": "Rock_Volcanic"
    },
    {
      "x": -1,
      "y": 17,
      "z": -4,
      "name": "Rock_Volcanic"
    },
    {
      "x": -1,
      "y": 18,
      "z": -4,
      "name": "Rock_Volcanic"
    },
    {
      "x": -1,
      "y": 19,
      "z": -4,
      "name": "Rock_Volcanic_Cracked_Lava"
    },
    {
      "x": -1,
      "y": 15,
      "z": -3,
      "name": "Rock_Volcanic"
    },
    {
      "x": -1,
      "y": 16,
      "z": -3,
      "name": "Rock_Volcanic"
    },
    {
      "x": -1,
      "y": 17,
      "z": -3,
      "name": "Rock_Volcanic_Cracked_Lava"
    },
    {
      "x": -1,
      "y": 18,
      "z": -3,
      "name": "Rock_Volcanic"
    },
    {
      "x": -1,
      "y": 19,
      "z": -3,
      "name": "Rock_Volcanic_Cracked_Lava"
    },
    {
      "x": -1,
      "y": 14,
      "z": -2,
      "name": "Rock_Volcanic"
    },
    {
      "x": -1,
      "y": 15,
      "z": -2,
      "name": "Rock_Volcanic"
    },
    {
      "x": -1,
      "y": 16,
      "z": -2,
      "name": "Rock_Volcanic"
    },
    {
      "x": -1,
      "y": 17,
      "z": -2,
      "name": "Rock_Volcanic_Cracked_Lava"
    },
    {
      "x": -1,
      "y": 18,
      "z": -2,
      "name": "Rock_Volcanic"
    },
    {
      "x": -1,
      "y": 13,
      "z": -1,
      "name": "Rock_Volcanic"
    },
    {
      "x": -1,
      "y": 14,
      "z": -1,
      "name": "Rock_Volcanic"
    },
    {
      "x": -1,
      "y": 15,
      "z": -1,
      "name": "Rock_Volcanic"
    },
    {
      "x": -1,
      "y": 16,
      "z": -1,
      "name": "Rock_Volcanic"
    },
    {
      "x": -1,
      "y": 17,
      "z": -1,
      "name": "Rock_Volcanic_Cracked_Lava"
    },
    {
      "x": -1,
      "y": 18,
      "z": -1,
      "name": "Rock_Volcanic"
    },
    {
      "x": -1,
      "y": 13,
      "z": 0,
      "name": "Rock_Volcanic"
    },
    {
      "x": -1,
      "y": 14,
      "z": 0,
      "name": "Rock_Volcanic"
    },
    {
      "x": -1,
      "y": 15,
      "z": 0,
      "name": "Rock_Volcanic"
    },
    {
      "x": -1,
      "y": 16,
      "z": 0,
      "name": "Rock_Volcanic_Cracked_Lava"
    },
    {
      "x": -1,
      "y": 17,
      "z": 0,
      "name": "Rock_Volcanic_Cracked_Lava"
    },
    {
      "x": -1,
      "y": 13,
      "z": 1,
      "name": "Rock_Volcanic"
    },
    {
      "x": -1,
      "y": 14,
      "z": 1,
      "name": "Rock_Volcanic"
    },
    {
      "x": -1,
      "y": 15,
      "z": 1,
      "name": "Rock_Volcanic"
    },
    {
      "x": -1,
      "y": 16,
      "z": 1,
      "name": "Rock_Volcanic_Cracked_Lava"
    },
    {
      "x": 0,
      "y": 16,
      "z": -4,
      "name": "Rock_Volcanic"
    },
    {
      "x": 0,
      "y": 17,
      "z": -4,
      "name": "Rock_Volcanic_Cracked_Lava"
    },
    {
      "x": 0,
      "y": 18,
      "z": -4,
      "name": "Rock_Volcanic"
    },
    {
      "x": 0,
      "y": 14,
      "z": -3,
      "name": "Rock_Volcanic"
    },
    {
      "x": 0,
      "y": 15,
      "z": -3,
      "name": "Rock_Volcanic"
    },
    {
      "x": 0,
      "y": 16,
      "z": -3,
      "name": "Rock_Volcanic_Cracked_Lava"
    },
    {
      "x": 0,
      "y": 17,
      "z": -3,
      "name": "Rock_Volcanic_Cracked_Lava"
    },
    {
      "x": 0,
      "y": 18,
      "z": -3,
      "name": "Rock_Volcanic_Cracked_Lava"
    },
    {
      "x": 0,
      "y": 13,
      "z": -2,
      "name": "Rock_Volcanic"
    },
    {
      "x": 0,
      "y": 14,
      "z": -2,
      "name": "Rock_Volcanic"
    },
    {
      "x": 0,
      "y": 15,
      "z": -2,
      "name": "Rock_Volcanic"
    },
    {
      "x": 0,
      "y": 16,
      "z": -2,
      "name": "Rock_Volcanic_Cracked_Lava"
    },
    {
      "x": 0,
      "y": 17,
      "z": -2,
      "name": "Rock_Volcanic_Cracked_Lava"
    },
    {
      "x": 0,
      "y": 18,
      "z": -2,
      "name": "Rock_Volcanic_Cracked_Lava"
    },
    {
      "x": 0,
      "y": 12,
      "z": -1,
      "name": "Rock_Volcanic"
    },
    {
      "x": 0,
      "y": 13,
      "z": -1,
      "name": "Rock_Volcanic"
    },
    {
      "x": 0,
      "y": 14,
      "z": -1,
      "name": "Rock_Volcanic"
    },
    {
      "x": 0,
      "y": 15,
      "z": -1,
      "name": "Rock_Volcanic"
    },
    {
      "x": 0,
      "y": 16,
      "z": -1,
      "name": "Rock_Volcanic_Cracked_Lava"
    },
    {
      "x": 0,
      "y": 17,
      "z": -1,
      "name": "Rock_Volcanic_Cracked_Lava"
    },
    {
      "x": 0,
      "y": 18,
      "z": -1,
      "name": "Rock_Volcanic_Cracked_Lava"
    },
    {
      "x": 0,
      "y": 11,
      "z": 0,
      "name": "Rock_Volcanic"
    },
    {
      "x": 0,
      "y": 12,
      "z": 0,
      "name": "Rock_Volcanic"
    },
    {
      "x": 0,
      "y": 13,
      "z": 0,
      "name": "Rock_Volcanic"
    },
    {
      "x": 0,
      "y": 14,
      "z": 0,
      "name": "Rock_Volcanic"
    },
    {
      "x": 0,
      "y": 15,
      "z": 0,
      "name": "Rock_Volcanic"
    },
    {
      "x": 0,
      "y": 16,
      "z": 0,
      "name": "Rock_Volcanic_Cracked_Lava"
    },
    {
      "x": 0,
      "y": 17,
      "z": 0,
      "name": "Rock_Volcanic_Cracked_Lava"
    },
    {
      "x": 0,
      "y": 10,
      "z": 1,
      "name": "Rock_Volcanic"
    },
    {
      "x": 0,
      "y": 11,
      "z": 1,
      "name": "Rock_Volcanic"
    },
    {
      "x": 0,
      "y": 12,
      "z": 1,
      "name": "Rock_Volcanic"
    },
    {
      "x": 0,
      "y": 13,
      "z": 1,
      "name": "Rock_Volcanic"
    },
    {
      "x": 0,
      "y": 14,
      "z": 1,
      "name": "Rock_Volcanic"
    },
    {
      "x": 0,
      "y": 15,
      "z": 1,
      "name": "Rock_Volcanic"
    },
    {
      "x": 0,
      "y": 16,
      "z": 1,
      "name": "Rock_Volcanic_Cracked_Lava"
    },
    {
      "x": 0,
      "y": 17,
      "z": 1,
      "name": "Rock_Volcanic_Cracked_Lava"
    },
    {
      "x": 0,
      "y": 11,
      "z": 2,
      "name": "Rock_Volcanic"
    },
    {
      "x": 0,
      "y": 12,
      "z": 2,
      "name": "Rock_Volcanic"
    },
    {
      "x": 0,
      "y": 13,
      "z": 2,
      "name": "Rock_Volcanic"
    },
    {
      "x": 0,
      "y": 14,
      "z": 2,
      "name": "Rock_Volcanic"
    },
    {
      "x": 0,
      "y": 15,
      "z": 2,
      "name": "Rock_Volcanic"
    },
    {
      "x": 1,
      "y": 16,
      "z": -4,
      "name": "Rock_Volcanic"
    },
    {
      "x": 1,
      "y": 17,
      "z": -4,
      "name": "Rock_Volcanic_Cracked_Lava"
    },
    {
      "x": 1,
      "y": 18,
      "z": -4,
      "name": "Rock_Volcanic"
    },
    {
      "x": 1,
      "y": 13,
      "z": -3,
      "name": "Rock_Volcanic"
    },
    {
      "x": 1,
      "y": 14,
      "z": -3,
      "name": "Rock_Volcanic"
    },
    {
      "x": 1,
      "y": 15,
      "z": -3,
      "name": "Rock_Volcanic"
    },
    {
      "x": 1,
      "y": 16,
      "z": -3,
      "name": "Rock_Volcanic_Cracked_Lava"
    },
    {
      "x": 1,
      "y": 17,
      "z": -3,
      "name": "Rock_Volcanic_Cracked_Lava"
    },
    {
      "x": 1,
      "y": 18,
      "z": -3,
      "name": "Rock_Volcanic_Cracked_Lava"
    },
    {
      "x": 1,
      "y": 12,
      "z": -2,
      "name": "Rock_Volcanic"
    },
    {
      "x": 1,
      "y": 13,
      "z": -2,
      "name": "Rock_Volcanic"
    },
    {
      "x": 1,
      "y": 14,
      "z": -2,
      "name": "Rock_Volcanic"
    },
    {
      "x": 1,
      "y": 15,
      "z": -2,
      "name": "Rock_Volcanic"
    },
    {
      "x": 1,
      "y": 16,
      "z": -2,
      "name": "Rock_Volcanic_Cracked_Lava"
    },
    {
      "x": 1,
      "y": 17,
      "z": -2,
      "name": "Rock_Volcanic_Cracked_Lava"
    },
    {
      "x": 1,
      "y": 10,
      "z": -1,
      "name": "Rock_Volcanic"
    },
    {
      "x": 1,
      "y": 11,
      "z": -1,
      "name": "Rock_Volcanic"
    },
    {
      "x": 1,
      "y": 12,
      "z": -1,
      "name": "Rock_Volcanic"
    },
    {
      "x": 1,
      "y": 13,
      "z": -1,
      "name": "Rock_Volcanic"
    },
    {
      "x": 1,
      "y": 14,
      "z": -1,
      "name": "Rock_Volcanic"
    },
    {
      "x": 1,
      "y": 15,
      "z": -1,
      "name": "Rock_Volcanic"
    },
    {
      "x": 1,
      "y": 16,
      "z": -1,
      "name": "Rock_Volcanic_Cracked_Lava"
    },
    {
      "x": 1,
      "y": 17,
      "z": -1,
      "name": "Rock_Volcanic_Cracked_Lava"
    },
    {
      "x": 1,
      "y": 9,
      "z": 0,
      "name": "Rock_Volcanic"
    },
    {
      "x": 1,
      "y": 10,
      "z": 0,
      "name": "Rock_Volcanic"
    },
    {
      "x": 1,
      "y": 11,
      "z": 0,
      "name": "Rock_Volcanic"
    },
    {
      "x": 1,
      "y": 12,
      "z": 0,
      "name": "Rock_Volcanic"
    },
    {
      "x": 1,
      "y": 13,
      "z": 0,
      "name": "Rock_Volcanic"
    },
    {
      "x": 1,
      "y": 14,
      "z": 0,
      "name": "Rock_Volcanic"
    },
    {
      "x": 1,
      "y": 15,
      "z": 0,
      "name": "Rock_Volcanic"
    },
    {
      "x": 1,
      "y": 16,
      "z": 0,
      "name": "Rock_Volcanic_Cracked_Lava"
    },
    {
      "x": 1,
      "y": 17,
      "z": 0,
      "name": "Rock_Volcanic_Cracked_Lava"
    },
    {
      "x": 1,
      "y": 9,
      "z": 1,
      "name": "Rock_Volcanic"
    },
    {
      "x": 1,
      "y": 10,
      "z": 1,
      "name": "Rock_Volcanic"
    },
    {
      "x": 1,
      "y": 11,
      "z": 1,
      "name": "Rock_Volcanic"
    },
    {
      "x": 1,
      "y": 12,
      "z": 1,
      "name": "Rock_Volcanic"
    },
    {
      "x": 1,
      "y": 13,
      "z": 1,
      "name": "Rock_Volcanic"
    },
    {
      "x": 1,
      "y": 14,
      "z": 1,
      "name": "Rock_Volcanic"
    },
    {
      "x": 1,
      "y": 15,
      "z": 1,
      "name": "Rock_Volcanic"
    },
    {
      "x": 1,
      "y": 16,
      "z": 1,
      "name": "Rock_Volcanic_Cracked_Lava"
    },
    {
      "x": 1,
      "y": 17,
      "z": 1,
      "name": "Rock_Volcanic_Cracked_Lava"
    },
    {
      "x": 1,
      "y": 9,
      "z": 2,
      "name": "Rock_Volcanic"
    },
    {
      "x": 1,
      "y": 10,
      "z": 2,
      "name": "Rock_Volcanic"
    },
    {
      "x": 1,
      "y": 11,
      "z": 2,
      "name": "Rock_Volcanic"
    },
    {
      "x": 1,
      "y": 12,
      "z": 2,
      "name": "Rock_Volcanic"
    },
    {
      "x": 1,
      "y": 13,
      "z": 2,
      "name": "Rock_Volcanic"
    },
    {
      "x": 1,
      "y": 14,
      "z": 2,
      "name": "Rock_Volcanic"
    },
    {
      "x": 1,
      "y": 15,
      "z": 2,
      "name": "Rock_Volcanic"
    },
    {
      "x": 1,
      "y": 9,
      "z": 3,
      "name": "Rock_Volcanic"
    },
    {
      "x": 1,
      "y": 10,
      "z": 3,
      "name": "Rock_Volcanic"
    },
    {
      "x": 1,
      "y": 11,
      "z": 3,
      "name": "Rock_Volcanic"
    },
    {
      "x": 1,
      "y": 13,
      "z": 3,
      "name": "Rock_Volcanic"
    },
    {
      "x": 2,
      "y": 14,
      "z": -3,
      "name": "Rock_Volcanic"
    },
    {
      "x": 2,
      "y": 15,
      "z": -3,
      "name": "Rock_Volcanic"
    },
    {
      "x": 2,
      "y": 16,
      "z": -3,
      "name": "Rock_Volcanic_Cracked_Lava"
    },
    {
      "x": 2,
      "y": 17,
      "z": -3,
      "name": "Rock_Volcanic_Cracked_Lava"
    },
    {
      "x": 2,
      "y": 11,
      "z": -2,
      "name": "Rock_Volcanic"
    },
    {
      "x": 2,
      "y": 12,
      "z": -2,
      "name": "Rock_Volcanic"
    },
    {
      "x": 2,
      "y": 13,
      "z": -2,
      "name": "Rock_Volcanic"
    },
    {
      "x": 2,
      "y": 14,
      "z": -2,
      "name": "Rock_Volcanic"
    },
    {
      "x": 2,
      "y": 15,
      "z": -2,
      "name": "Rock_Volcanic"
    },
    {
      "x": 2,
      "y": 16,
      "z": -2,
      "name": "Rock_Volcanic_Cracked_Lava"
    },
    {
      "x": 2,
      "y": 17,
      "z": -2,
      "name": "Rock_Volcanic_Cracked_Lava"
    },
    {
      "x": 2,
      "y": 9,
      "z": -1,
      "name": "Rock_Volcanic"
    },
    {
      "x": 2,
      "y": 10,
      "z": -1,
      "name": "Rock_Volcanic"
    },
    {
      "x": 2,
      "y": 11,
      "z": -1,
      "name": "Rock_Volcanic"
    },
    {
      "x": 2,
      "y": 12,
      "z": -1,
      "name": "Rock_Volcanic"
    },
    {
      "x": 2,
      "y": 13,
      "z": -1,
      "name": "Rock_Volcanic"
    },
    {
      "x": 2,
      "y": 14,
      "z": -1,
      "name": "Rock_Volcanic"
    },
    {
      "x": 2,
      "y": 15,
      "z": -1,
      "name": "Rock_Volcanic"
    },
    {
      "x": 2,
      "y": 16,
      "z": -1,
      "name": "Rock_Volcanic_Cracked_Lava"
    },
    {
      "x": 2,
      "y": 17,
      "z": -1,
      "name": "Rock_Volcanic_Cracked_Lava"
    },
    {
      "x": 2,
      "y": 8,
      "z": 0,
      "name": "Rock_Volcanic"
    },
    {
      "x": 2,
      "y": 9,
      "z": 0,
      "name": "Rock_Volcanic"
    },
    {
      "x": 2,
      "y": 10,
      "z": 0,
      "name": "Rock_Volcanic"
    },
    {
      "x": 2,
      "y": 11,
      "z": 0,
      "name": "Rock_Volcanic"
    },
    {
      "x": 2,
      "y": 12,
      "z": 0,
      "name": "Rock_Volcanic"
    },
    {
      "x": 2,
      "y": 13,
      "z": 0,
      "name": "Rock_Volcanic"
    },
    {
      "x": 2,
      "y": 14,
      "z": 0,
      "name": "Rock_Volcanic"
    },
    {
      "x": 2,
      "y": 15,
      "z": 0,
      "name": "Rock_Volcanic"
    },
    {
      "x": 2,
      "y": 16,
      "z": 0,
      "name": "Rock_Volcanic"
    },
    {
      "x": 2,
      "y": 7,
      "z": 1,
      "name": "Rock_Volcanic"
    },
    {
      "x": 2,
      "y": 8,
      "z": 1,
      "name": "Rock_Volcanic"
    },
    {
      "x": 2,
      "y": 9,
      "z": 1,
      "name": "Rock_Volcanic"
    },
    {
      "x": 2,
      "y": 10,
      "z": 1,
      "name": "Rock_Volcanic"
    },
    {
      "x": 2,
      "y": 11,
      "z": 1,
      "name": "Rock_Volcanic"
    },
    {
      "x": 2,
      "y": 12,
      "z": 1,
      "name": "Rock_Volcanic"
    },
    {
      "x": 2,
      "y": 13,
      "z": 1,
      "name": "Rock_Volcanic"
    },
    {
      "x": 2,
      "y": 14,
      "z": 1,
      "name": "Rock_Volcanic"
    },
    {
      "x": 2,
      "y": 15,
      "z": 1,
      "name": "Rock_Volcanic"
    },
    {
      "x": 2,
      "y": 16,
      "z": 1,
      "name": "Rock_Volcanic"
    },
    {
      "x": 2,
      "y": 7,
      "z": 2,
      "name": "Rock_Volcanic"
    },
    {
      "x": 2,
      "y": 8,
      "z": 2,
      "name": "Rock_Volcanic"
    },
    {
      "x": 2,
      "y": 9,
      "z": 2,
      "name": "Rock_Volcanic"
    },
    {
      "x": 2,
      "y": 10,
      "z": 2,
      "name": "Rock_Volcanic"
    },
    {
      "x": 2,
      "y": 11,
      "z": 2,
      "name": "Rock_Volcanic"
    },
    {
      "x": 2,
      "y": 12,
      "z": 2,
      "name": "Rock_Volcanic"
    },
    {
      "x": 2,
      "y": 13,
      "z": 2,
      "name": "Rock_Volcanic"
    },
    {
      "x": 2,
      "y": 14,
      "z": 2,
      "name": "Rock_Volcanic"
    },
    {
      "x": 2,
      "y": 15,
      "z": 2,
      "name": "Rock_Volcanic"
    },
    {
      "x": 2,
      "y": 7,
      "z": 3,
      "name": "Rock_Volcanic"
    },
    {
      "x": 2,
      "y": 8,
      "z": 3,
      "name": "Rock_Volcanic"
    },
    {
      "x": 2,
      "y": 9,
      "z": 3,
      "name": "Rock_Volcanic"
    },
    {
      "x": 2,
      "y": 10,
      "z": 3,
      "name": "Rock_Volcanic"
    },
    {
      "x": 2,
      "y": 11,
      "z": 3,
      "name": "Rock_Volcanic"
    },
    {
      "x": 2,
      "y": 12,
      "z": 3,
      "name": "Rock_Volcanic"
    },
    {
      "x": 2,
      "y": 13,
      "z": 3,
      "name": "Rock_Volcanic"
    },
    {
      "x": 2,
      "y": 9,
      "z": 4,
      "name": "Rock_Volcanic"
    },
    {
      "x": 2,
      "y": 10,
      "z": 4,
      "name": "Rock_Volcanic"
    },
    {
      "x": 2,
      "y": 12,
      "z": 4,
      "name": "Rock_Volcanic"
    },
    {
      "x": 3,
      "y": 13,
      "z": -3,
      "name": "Rock_Volcanic"
    },
    {
      "x": 3,
      "y": 14,
      "z": -3,
      "name": "Rock_Volcanic"
    },
    {
      "x": 3,
      "y": 11,
      "z": -2,
      "name": "Rock_Volcanic"
    },
    {
      "x": 3,
      "y": 12,
      "z": -2,
      "name": "Rock_Volcanic"
    },
    {
      "x": 3,
      "y": 13,
      "z": -2,
      "name": "Rock_Volcanic"
    },
    {
      "x": 3,
      "y": 14,
      "z": -2,
      "name": "Rock_Volcanic"
    },
    {
      "x": 3,
      "y": 15,
      "z": -2,
      "name": "Rock_Volcanic"
    },
    {
      "x": 3,
      "y": 9,
      "z": -1,
      "name": "Rock_Volcanic"
    },
    {
      "x": 3,
      "y": 10,
      "z": -1,
      "name": "Rock_Volcanic"
    },
    {
      "x": 3,
      "y": 11,
      "z": -1,
      "name": "Rock_Volcanic"
    },
    {
      "x": 3,
      "y": 12,
      "z": -1,
      "name": "Rock_Volcanic"
    },
    {
      "x": 3,
      "y": 13,
      "z": -1,
      "name": "Rock_Volcanic"
    },
    {
      "x": 3,
      "y": 14,
      "z": -1,
      "name": "Rock_Volcanic"
    },
    {
      "x": 3,
      "y": 15,
      "z": -1,
      "name": "Rock_Volcanic"
    },
    {
      "x": 3,
      "y": 16,
      "z": -1,
      "name": "Rock_Volcanic"
    },
    {
      "x": 3,
      "y": 7,
      "z": 0,
      "name": "Rock_Volcanic"
    },
    {
      "x": 3,
      "y": 8,
      "z": 0,
      "name": "Rock_Volcanic"
    },
    {
      "x": 3,
      "y": 9,
      "z": 0,
      "name": "Rock_Volcanic"
    },
    {
      "x": 3,
      "y": 10,
      "z": 0,
      "name": "Rock_Volcanic"
    },
    {
      "x": 3,
      "y": 11,
      "z": 0,
      "name": "Rock_Volcanic"
    },
    {
      "x": 3,
      "y": 12,
      "z": 0,
      "name": "Rock_Volcanic"
    },
    {
      "x": 3,
      "y": 13,
      "z": 0,
      "name": "Rock_Volcanic"
    },
    {
      "x": 3,
      "y": 14,
      "z": 0,
      "name": "Rock_Volcanic"
    },
    {
      "x": 3,
      "y": 15,
      "z": 0,
      "name": "Rock_Volcanic"
    },
    {
      "x": 3,
      "y": 16,
      "z": 0,
      "name": "Rock_Volcanic"
    },
    {
      "x": 3,
      "y": 6,
      "z": 1,
      "name": "Rock_Volcanic"
    },
    {
      "x": 3,
      "y": 7,
      "z": 1,
      "name": "Rock_Volcanic"
    },
    {
      "x": 3,
      "y": 8,
      "z": 1,
      "name": "Rock_Volcanic"
    },
    {
      "x": 3,
      "y": 9,
      "z": 1,
      "name": "Rock_Volcanic"
    },
    {
      "x": 3,
      "y": 10,
      "z": 1,
      "name": "Rock_Volcanic"
    },
    {
      "x": 3,
      "y": 11,
      "z": 1,
      "name": "Rock_Volcanic"
    },
    {
      "x": 3,
      "y": 12,
      "z": 1,
      "name": "Rock_Volcanic"
    },
    {
      "x": 3,
      "y": 13,
      "z": 1,
      "name": "Rock_Volcanic"
    },
    {
      "x": 3,
      "y": 14,
      "z": 1,
      "name": "Rock_Volcanic"
    },
    {
      "x": 3,
      "y": 15,
      "z": 1,
      "name": "Rock_Volcanic"
    },
    {
      "x": 3,
      "y": 6,
      "z": 2,
      "name": "Rock_Volcanic"
    },
    {
      "x": 3,
      "y": 7,
      "z": 2,
      "name": "Rock_Volcanic"
    },
    {
      "x": 3,
      "y": 8,
      "z": 2,
      "name": "Rock_Volcanic"
    },
    {
      "x": 3,
      "y": 9,
      "z": 2,
      "name": "Rock_Volcanic"
    },
    {
      "x": 3,
      "y": 10,
      "z": 2,
      "name": "Rock_Volcanic"
    },
    {
      "x": 3,
      "y": 11,
      "z": 2,
      "name": "Rock_Volcanic"
    },
    {
      "x": 3,
      "y": 12,
      "z": 2,
      "name": "Rock_Volcanic"
    },
    {
      "x": 3,
      "y": 13,
      "z": 2,
      "name": "Rock_Volcanic"
    },
    {
      "x": 3,
      "y": 6,
      "z": 3,
      "name": "Rock_Volcanic"
    },
    {
      "x": 3,
      "y": 7,
      "z": 3,
      "name": "Rock_Volcanic"
    },
    {
      "x": 3,
      "y": 8,
      "z": 3,
      "name": "Rock_Volcanic"
    },
    {
      "x": 3,
      "y": 9,
      "z": 3,
      "name": "Rock_Volcanic"
    },
    {
      "x": 3,
      "y": 10,
      "z": 3,
      "name": "Rock_Volcanic"
    },
    {
      "x": 3,
      "y": 11,
      "z": 3,
      "name": "Rock_Volcanic"
    },
    {
      "x": 3,
      "y": 12,
      "z": 3,
      "name": "Rock_Volcanic"
    },
    {
      "x": 3,
      "y": 13,
      "z": 3,
      "name": "Rock_Volcanic"
    },
    {
      "x": 3,
      "y": 6,
      "z": 4,
      "name": "Rock_Volcanic"
    },
    {
      "x": 3,
      "y": 7,
      "z": 4,
      "name": "Rock_Volcanic"
    },
    {
      "x": 3,
      "y": 8,
      "z": 4,
      "name": "Rock_Volcanic"
    },
    {
      "x": 3,
      "y": 9,
      "z": 4,
      "name": "Rock_Volcanic"
    },
    {
      "x": 3,
      "y": 10,
      "z": 4,
      "name": "Rock_Volcanic"
    },
    {
      "x": 3,
      "y": 11,
      "z": 4,
      "name": "Rock_Volcanic"
    },
    {
      "x": 3,
      "y": 12,
      "z": 4,
      "name": "Rock_Volcanic"
    },
    {
      "x": 3,
      "y": 7,
      "z": 5,
      "name": "Rock_Volcanic"
    },
    {
      "x": 3,
      "y": 9,
      "z": 5,
      "name": "Rock_Volcanic"
    },
    {
      "x": 4,
      "y": 8,
      "z": -1,
      "name": "Rock_Volcanic"
    },
    {
      "x": 4,
      "y": 9,
      "z": -1,
      "name": "Rock_Volcanic"
    },
    {
      "x": 4,
      "y": 10,
      "z": -1,
      "name": "Rock_Volcanic"
    },
    {
      "x": 4,
      "y": 11,
      "z": -1,
      "name": "Rock_Volcanic"
    },
    {
      "x": 4,
      "y": 12,
      "z": -1,
      "name": "Rock_Volcanic"
    },
    {
      "x": 4,
      "y": 13,
      "z": -1,
      "name": "Rock_Volcanic"
    },
    {
      "x": 4,
      "y": 7,
      "z": 0,
      "name": "Rock_Volcanic"
    },
    {
      "x": 4,
      "y": 8,
      "z": 0,
      "name": "Rock_Volcanic"
    },
    {
      "x": 4,
      "y": 9,
      "z": 0,
      "name": "Rock_Volcanic"
    },
    {
      "x": 4,
      "y": 10,
      "z": 0,
      "name": "Rock_Volcanic"
    },
    {
      "x": 4,
      "y": 11,
      "z": 0,
      "name": "Rock_Volcanic"
    },
    {
      "x": 4,
      "y": 12,
      "z": 0,
      "name": "Rock_Volcanic"
    },
    {
      "x": 4,
      "y": 13,
      "z": 0,
      "name": "Rock_Volcanic"
    },
    {
      "x": 4,
      "y": 5,
      "z": 1,
      "name": "Rock_Volcanic"
    },
    {
      "x": 4,
      "y": 6,
      "z": 1,
      "name": "Rock_Volcanic"
    },
    {
      "x": 4,
      "y": 7,
      "z": 1,
      "name": "Rock_Volcanic"
    },
    {
      "x": 4,
      "y": 8,
      "z": 1,
      "name": "Rock_Volcanic"
    },
    {
      "x": 4,
      "y": 9,
      "z": 1,
      "name": "Rock_Volcanic"
    },
    {
      "x": 4,
      "y": 10,
      "z": 1,
      "name": "Rock_Volcanic"
    },
    {
      "x": 4,
      "y": 11,
      "z": 1,
      "name": "Rock_Volcanic"
    },
    {
      "x": 4,
      "y": 12,
      "z": 1,
      "name": "Rock_Volcanic"
    },
    {
      "x": 4,
      "y": 13,
      "z": 1,
      "name": "Rock_Volcanic"
    },
    {
      "x": 4,
      "y": 5,
      "z": 2,
      "name": "Rock_Volcanic"
    },
    {
      "x": 4,
      "y": 6,
      "z": 2,
      "name": "Rock_Volcanic"
    },
    {
      "x": 4,
      "y": 7,
      "z": 2,
      "name": "Rock_Volcanic"
    },
    {
      "x": 4,
      "y": 8,
      "z": 2,
      "name": "Rock_Volcanic"
    },
    {
      "x": 4,
      "y": 9,
      "z": 2,
      "name": "Rock_Volcanic"
    },
    {
      "x": 4,
      "y": 10,
      "z": 2,
      "name": "Rock_Volcanic"
    },
    {
      "x": 4,
      "y": 11,
      "z": 2,
      "name": "Rock_Volcanic"
    },
    {
      "x": 4,
      "y": 12,
      "z": 2,
      "name": "Rock_Volcanic"
    },
    {
      "x": 4,
      "y": 13,
      "z": 2,
      "name": "Rock_Volcanic"
    },
    {
      "x": 4,
      "y": 4,
      "z": 3,
      "name": "Rock_Volcanic"
    },
    {
      "x": 4,
      "y": 5,
      "z": 3,
      "name": "Rock_Volcanic"
    },
    {
      "x": 4,
      "y": 6,
      "z": 3,
      "name": "Rock_Volcanic"
    },
    {
      "x": 4,
      "y": 7,
      "z": 3,
      "name": "Rock_Volcanic"
    },
    {
      "x": 4,
      "y": 8,
      "z": 3,
      "name": "Rock_Volcanic"
    },
    {
      "x": 4,
      "y": 9,
      "z": 3,
      "name": "Rock_Volcanic"
    },
    {
      "x": 4,
      "y": 10,
      "z": 3,
      "name": "Rock_Volcanic"
    },
    {
      "x": 4,
      "y": 11,
      "z": 3,
      "name": "Rock_Volcanic"
    },
    {
      "x": 4,
      "y": 12,
      "z": 3,
      "name": "Rock_Volcanic"
    },
    {
      "x": 4,
      "y": 4,
      "z": 4,
      "name": "Rock_Volcanic"
    },
    {
      "x": 4,
      "y": 5,
      "z": 4,
      "name": "Rock_Volcanic"
    },
    {
      "x": 4,
      "y": 6,
      "z": 4,
      "name": "Rock_Volcanic"
    },
    {
      "x": 4,
      "y": 7,
      "z": 4,
      "name": "Rock_Volcanic"
    },
    {
      "x": 4,
      "y": 8,
      "z": 4,
      "name": "Rock_Volcanic"
    },
    {
      "x": 4,
      "y": 9,
      "z": 4,
      "name": "Rock_Volcanic"
    },
    {
      "x": 4,
      "y": 10,
      "z": 4,
      "name": "Rock_Volcanic"
    },
    {
      "x": 4,
      "y": 11,
      "z": 4,
      "name": "Rock_Volcanic"
    },
    {
      "x": 4,
      "y": 5,
      "z": 5,
      "name": "Rock_Volcanic"
    },
    {
      "x": 4,
      "y": 6,
      "z": 5,
      "name": "Rock_Volcanic"
    },
    {
      "x": 4,
      "y": 7,
      "z": 5,
      "name": "Rock_Volcanic"
    },
    {
      "x": 4,
      "y": 8,
      "z": 5,
      "name": "Rock_Volcanic"
    },
    {
      "x": 4,
      "y": 9,
      "z": 5,
      "name": "Rock_Volcanic"
    },
    {
      "x": 4,
      "y": 4,
      "z": 6,
      "name": "Rock_Volcanic"
    },
    {
      "x": 4,
      "y": 6,
      "z": 6,
      "name": "Rock_Volcanic"
    },
    {
      "x": 4,
      "y": 7,
      "z": 6,
      "name": "Rock_Volcanic"
    },
    {
      "x": 5,
      "y": 8,
      "z": -1,
      "name": "Rock_Volcanic"
    },
    {
      "x": 5,
      "y": 9,
      "z": -1,
      "name": "Rock_Volcanic"
    },
    {
      "x": 5,
      "y": 10,
      "z": -1,
      "name": "Rock_Volcanic"
    },
    {
      "x": 5,
      "y": 11,
      "z": -1,
      "name": "Rock_Volcanic"
    },
    {
      "x": 5,
      "y": 12,
      "z": -1,
      "name": "Rock_Volcanic"
    },
    {
      "x": 5,
      "y": 5,
      "z": 0,
      "name": "Rock_Volcanic"
    },
    {
      "x": 5,
      "y": 6,
      "z": 0,
      "name": "Rock_Volcanic"
    },
    {
      "x": 5,
      "y": 7,
      "z": 0,
      "name": "Rock_Volcanic"
    },
    {
      "x": 5,
      "y": 8,
      "z": 0,
      "name": "Rock_Volcanic"
    },
    {
      "x": 5,
      "y": 9,
      "z": 0,
      "name": "Rock_Volcanic"
    },
    {
      "x": 5,
      "y": 10,
      "z": 0,
      "name": "Rock_Volcanic"
    },
    {
      "x": 5,
      "y": 11,
      "z": 0,
      "name": "Rock_Volcanic"
    },
    {
      "x": 5,
      "y": 12,
      "z": 0,
      "name": "Rock_Volcanic"
    },
    {
      "x": 5,
      "y": 13,
      "z": 0,
      "name": "Rock_Volcanic"
    },
    {
      "x": 5,
      "y": 4,
      "z": 1,
      "name": "Rock_Volcanic"
    },
    {
      "x": 5,
      "y": 5,
      "z": 1,
      "name": "Rock_Volcanic"
    },
    {
      "x": 5,
      "y": 6,
      "z": 1,
      "name": "Rock_Volcanic"
    },
    {
      "x": 5,
      "y": 7,
      "z": 1,
      "name": "Rock_Volcanic"
    },
    {
      "x": 5,
      "y": 8,
      "z": 1,
      "name": "Rock_Volcanic"
    },
    {
      "x": 5,
      "y": 9,
      "z": 1,
      "name": "Rock_Volcanic"
    },
    {
      "x": 5,
      "y": 10,
      "z": 1,
      "name": "Rock_Volcanic"
    },
    {
      "x": 5,
      "y": 11,
      "z": 1,
      "name": "Rock_Volcanic"
    },
    {
      "x": 5,
      "y": 12,
      "z": 1,
      "name": "Rock_Volcanic"
    },
    {
      "x": 5,
      "y": 13,
      "z": 1,
      "name": "Rock_Volcanic"
    },
    {
      "x": 5,
      "y": 4,
      "z": 2,
      "name": "Rock_Volcanic"
    },
    {
      "x": 5,
      "y": 5,
      "z": 2,
      "name": "Rock_Volcanic"
    },
    {
      "x": 5,
      "y": 6,
      "z": 2,
      "name": "Rock_Volcanic"
    },
    {
      "x": 5,
      "y": 7,
      "z": 2,
      "name": "Rock_Volcanic"
    },
    {
      "x": 5,
      "y": 8,
      "z": 2,
      "name": "Rock_Volcanic"
    },
    {
      "x": 5,
      "y": 9,
      "z": 2,
      "name": "Rock_Volcanic"
    },
    {
      "x": 5,
      "y": 10,
      "z": 2,
      "name": "Rock_Volcanic"
    },
    {
      "x": 5,
      "y": 11,
      "z": 2,
      "name": "Rock_Volcanic"
    },
    {
      "x": 5,
      "y": 12,
      "z": 2,
      "name": "Rock_Volcanic"
    },
    {
      "x": 5,
      "y": 3,
      "z": 3,
      "name": "Rock_Volcanic"
    },
    {
      "x": 5,
      "y": 4,
      "z": 3,
      "name": "Rock_Volcanic"
    },
    {
      "x": 5,
      "y": 5,
      "z": 3,
      "name": "Rock_Volcanic"
    },
    {
      "x": 5,
      "y": 6,
      "z": 3,
      "name": "Rock_Volcanic"
    },
    {
      "x": 5,
      "y": 7,
      "z": 3,
      "name": "Rock_Volcanic"
    },
    {
      "x": 5,
      "y": 8,
      "z": 3,
      "name": "Rock_Volcanic"
    },
    {
      "x": 5,
      "y": 9,
      "z": 3,
      "name": "Rock_Volcanic"
    },
    {
      "x": 5,
      "y": 10,
      "z": 3,
      "name": "Rock_Volcanic"
    },
    {
      "x": 5,
      "y": 11,
      "z": 3,
      "name": "Rock_Volcanic"
    },
    {
      "x": 5,
      "y": 3,
      "z": 4,
      "name": "Rock_Volcanic"
    },
    {
      "x": 5,
      "y": 4,
      "z": 4,
      "name": "Rock_Volcanic"
    },
    {
      "x": 5,
      "y": 5,
      "z": 4,
      "name": "Rock_Volcanic"
    },
    {
      "x": 5,
      "y": 6,
      "z": 4,
      "name": "Rock_Volcanic"
    },
    {
      "x": 5,
      "y": 7,
      "z": 4,
      "name": "Rock_Volcanic"
    },
    {
      "x": 5,
      "y": 8,
      "z": 4,
      "name": "Rock_Volcanic"
    },
    {
      "x": 5,
      "y": 9,
      "z": 4,
      "name": "Rock_Volcanic"
    },
    {
      "x": 5,
      "y": 10,
      "z": 4,
      "name": "Rock_Volcanic"
    },
    {
      "x": 5,
      "y": 3,
      "z": 5,
      "name": "Rock_Volcanic"
    },
    {
      "x": 5,
      "y": 4,
      "z": 5,
      "name": "Rock_Volcanic"
    },
    {
      "x": 5,
      "y": 5,
      "z": 5,
      "name": "Rock_Volcanic"
    },
    {
      "x": 5,
      "y": 6,
      "z": 5,
      "name": "Rock_Volcanic"
    },
    {
      "x": 5,
      "y": 7,
      "z": 5,
      "name": "Rock_Volcanic"
    },
    {
      "x": 5,
      "y": 8,
      "z": 5,
      "name": "Rock_Volcanic"
    },
    {
      "x": 5,
      "y": 9,
      "z": 5,
      "name": "Rock_Volcanic"
    },
    {
      "x": 5,
      "y": 3,
      "z": 6,
      "name": "Rock_Volcanic"
    },
    {
      "x": 5,
      "y": 4,
      "z": 6,
      "name": "Rock_Volcanic"
    },
    {
      "x": 5,
      "y": 5,
      "z": 6,
      "name": "Rock_Volcanic"
    },
    {
      "x": 5,
      "y": 6,
      "z": 6,
      "name": "Rock_Volcanic"
    },
    {
      "x": 5,
      "y": 7,
      "z": 6,
      "name": "Rock_Volcanic"
    },
    {
      "x": 5,
      "y": 8,
      "z": 6,
      "name": "Rock_Volcanic"
    },
    {
      "x": 5,
      "y": 4,
      "z": 7,
      "name": "Rock_Volcanic"
    },
    {
      "x": 5,
      "y": 5,
      "z": 7,
      "name": "Rock_Volcanic"
    },
    {
      "x": 5,
      "y": 6,
      "z": 7,
      "name": "Rock_Volcanic"
    },
    {
      "x": 6,
      "y": 7,
      "z": -1,
      "name": "Rock_Volcanic"
    },
    {
      "x": 6,
      "y": 8,
      "z": -1,
      "name": "Rock_Volcanic"
    },
    {
      "x": 6,
      "y": 9,
      "z": -1,
      "name": "Rock_Volcanic"
    },
    {
      "x": 6,
      "y": 10,
      "z": -1,
      "name": "Rock_Volcanic"
    },
    {
      "x": 6,
      "y": 11,
      "z": -1,
      "name": "Rock_Volcanic"
    },
    {
      "x": 6,
      "y": 4,
      "z": 0,
      "name": "Rock_Volcanic"
    },
    {
      "x": 6,
      "y": 5,
      "z": 0,
      "name": "Rock_Volcanic"
    },
    {
      "x": 6,
      "y": 6,
      "z": 0,
      "name": "Rock_Volcanic"
    },
    {
      "x": 6,
      "y": 7,
      "z": 0,
      "name": "Rock_Volcanic"
    },
    {
      "x": 6,
      "y": 8,
      "z": 0,
      "name": "Rock_Volcanic"
    },
    {
      "x": 6,
      "y": 9,
      "z": 0,
      "name": "Rock_Volcanic"
    },
    {
      "x": 6,
      "y": 10,
      "z": 0,
      "name": "Rock_Volcanic"
    },
    {
      "x": 6,
      "y": 11,
      "z": 0,
      "name": "Rock_Volcanic"
    },
    {
      "x": 6,
      "y": 12,
      "z": 0,
      "name": "Rock_Volcanic"
    },
    {
      "x": 6,
      "y": 3,
      "z": 1,
      "name": "Rock_Volcanic"
    },
    {
      "x": 6,
      "y": 4,
      "z": 1,
      "name": "Rock_Volcanic"
    },
    {
      "x": 6,
      "y": 5,
      "z": 1,
      "name": "Rock_Volcanic"
    },
    {
      "x": 6,
      "y": 6,
      "z": 1,
      "name": "Rock_Volcanic"
    },
    {
      "x": 6,
      "y": 7,
      "z": 1,
      "name": "Rock_Volcanic"
    },
    {
      "x": 6,
      "y": 8,
      "z": 1,
      "name": "Rock_Volcanic"
    },
    {
      "x": 6,
      "y": 9,
      "z": 1,
      "name": "Rock_Volcanic"
    },
    {
      "x": 6,
      "y": 10,
      "z": 1,
      "name": "Rock_Volcanic"
    },
    {
      "x": 6,
      "y": 11,
      "z": 1,
      "name": "Rock_Volcanic"
    },
    {
      "x": 6,
      "y": 12,
      "z": 1,
      "name": "Rock_Volcanic"
    },
    {
      "x": 6,
      "y": 3,
      "z": 2,
      "name": "Rock_Volcanic"
    },
    {
      "x": 6,
      "y": 4,
      "z": 2,
      "name": "Rock_Volcanic"
    },
    {
      "x": 6,
      "y": 5,
      "z": 2,
      "name": "Rock_Volcanic"
    },
    {
      "x": 6,
      "y": 6,
      "z": 2,
      "name": "Rock_Volcanic"
    },
    {
      "x": 6,
      "y": 7,
      "z": 2,
      "name": "Rock_Volcanic"
    },
    {
      "x": 6,
      "y": 8,
      "z": 2,
      "name": "Rock_Volcanic"
    },
    {
      "x": 6,
      "y": 9,
      "z": 2,
      "name": "Rock_Volcanic"
    },
    {
      "x": 6,
      "y": 10,
      "z": 2,
      "name": "Rock_Volcanic"
    },
    {
      "x": 6,
      "y": 11,
      "z": 2,
      "name": "Rock_Volcanic"
    },
    {
      "x": 6,
      "y": 12,
      "z": 2,
      "name": "Rock_Volcanic"
    },
    {
      "x": 6,
      "y": 2,
      "z": 3,
      "name": "Rock_Volcanic"
    },
    {
      "x": 6,
      "y": 3,
      "z": 3,
      "name": "Rock_Volcanic"
    },
    {
      "x": 6,
      "y": 4,
      "z": 3,
      "name": "Rock_Volcanic"
    },
    {
      "x": 6,
      "y": 5,
      "z": 3,
      "name": "Rock_Volcanic"
    },
    {
      "x": 6,
      "y": 6,
      "z": 3,
      "name": "Rock_Volcanic"
    },
    {
      "x": 6,
      "y": 7,
      "z": 3,
      "name": "Rock_Volcanic"
    },
    {
      "x": 6,
      "y": 8,
      "z": 3,
      "name": "Rock_Volcanic"
    },
    {
      "x": 6,
      "y": 9,
      "z": 3,
      "name": "Rock_Volcanic"
    },
    {
      "x": 6,
      "y": 10,
      "z": 3,
      "name": "Rock_Volcanic"
    },
    {
      "x": 6,
      "y": 11,
      "z": 3,
      "name": "Rock_Volcanic"
    },
    {
      "x": 6,
      "y": 2,
      "z": 4,
      "name": "Rock_Volcanic"
    },
    {
      "x": 6,
      "y": 3,
      "z": 4,
      "name": "Rock_Volcanic"
    },
    {
      "x": 6,
      "y": 4,
      "z": 4,
      "name": "Rock_Volcanic"
    },
    {
      "x": 6,
      "y": 5,
      "z": 4,
      "name": "Rock_Volcanic"
    },
    {
      "x": 6,
      "y": 6,
      "z": 4,
      "name": "Rock_Volcanic"
    },
    {
      "x": 6,
      "y": 7,
      "z": 4,
      "name": "Rock_Volcanic"
    },
    {
      "x": 6,
      "y": 8,
      "z": 4,
      "name": "Rock_Volcanic"
    },
    {
      "x": 6,
      "y": 9,
      "z": 4,
      "name": "Rock_Volcanic"
    },
    {
      "x": 6,
      "y": 10,
      "z": 4,
      "name": "Rock_Volcanic"
    },
    {
      "x": 6,
      "y": 2,
      "z": 5,
      "name": "Rock_Volcanic"
    },
    {
      "x": 6,
      "y": 3,
      "z": 5,
      "name": "Rock_Volcanic"
    },
    {
      "x": 6,
      "y": 4,
      "z": 5,
      "name": "Rock_Volcanic"
    },
    {
      "x": 6,
      "y": 5,
      "z": 5,
      "name": "Rock_Volcanic"
    },
    {
      "x": 6,
      "y": 6,
      "z": 5,
      "name": "Rock_Volcanic"
    },
    {
      "x": 6,
      "y": 7,
      "z": 5,
      "name": "Rock_Volcanic"
    },
    {
      "x": 6,
      "y": 8,
      "z": 5,
      "name": "Rock_Volcanic"
    },
    {
      "x": 6,
      "y": 9,
      "z": 5,
      "name": "Rock_Volcanic"
    },
    {
      "x": 6,
      "y": 2,
      "z": 6,
      "name": "Rock_Volcanic"
    },
    {
      "x": 6,
      "y": 3,
      "z": 6,
      "name": "Rock_Volcanic"
    },
    {
      "x": 6,
      "y": 4,
      "z": 6,
      "name": "Rock_Volcanic"
    },
    {
      "x": 6,
      "y": 5,
      "z": 6,
      "name": "Rock_Volcanic"
    },
    {
      "x": 6,
      "y": 6,
      "z": 6,
      "name": "Rock_Volcanic"
    },
    {
      "x": 6,
      "y": 7,
      "z": 6,
      "name": "Rock_Volcanic"
    },
    {
      "x": 6,
      "y": 8,
      "z": 6,
      "name": "Rock_Volcanic"
    },
    {
      "x": 6,
      "y": 3,
      "z": 7,
      "name": "Rock_Volcanic"
    },
    {
      "x": 6,
      "y": 4,
      "z": 7,
      "name": "Rock_Volcanic"
    },
    {
      "x": 6,
      "y": 5,
      "z": 7,
      "name": "Rock_Volcanic"
    },
    {
      "x": 6,
      "y": 6,
      "z": 7,
      "name": "Rock_Volcanic"
    },
    {
      "x": 6,
      "y": 7,
      "z": 7,
      "name": "Rock_Volcanic"
    },
    {
      "x": 6,
      "y": 4,
      "z": 8,
      "name": "Rock_Volcanic"
    },
    {
      "x": 6,
      "y": 5,
      "z": 8,
      "name": "Rock_Volcanic"
    },
    {
      "x": 6,
      "y": 6,
      "z": 8,
      "name": "Rock_Volcanic"
    },
    {
      "x": 7,
      "y": 4,
      "z": 0,
      "name": "Rock_Volcanic"
    },
    {
      "x": 7,
      "y": 5,
      "z": 0,
      "name": "Rock_Volcanic"
    },
    {
      "x": 7,
      "y": 6,
      "z": 0,
      "name": "Rock_Volcanic"
    },
    {
      "x": 7,
      "y": 7,
      "z": 0,
      "name": "Rock_Volcanic"
    },
    {
      "x": 7,
      "y": 8,
      "z": 0,
      "name": "Rock_Volcanic"
    },
    {
      "x": 7,
      "y": 9,
      "z": 0,
      "name": "Rock_Volcanic"
    },
    {
      "x": 7,
      "y": 10,
      "z": 0,
      "name": "Rock_Volcanic"
    },
    {
      "x": 7,
      "y": 3,
      "z": 1,
      "name": "Rock_Volcanic"
    },
    {
      "x": 7,
      "y": 4,
      "z": 1,
      "name": "Rock_Volcanic"
    },
    {
      "x": 7,
      "y": 5,
      "z": 1,
      "name": "Rock_Volcanic"
    },
    {
      "x": 7,
      "y": 6,
      "z": 1,
      "name": "Rock_Volcanic"
    },
    {
      "x": 7,
      "y": 7,
      "z": 1,
      "name": "Rock_Volcanic"
    },
    {
      "x": 7,
      "y": 8,
      "z": 1,
      "name": "Rock_Volcanic"
    },
    {
      "x": 7,
      "y": 9,
      "z": 1,
      "name": "Rock_Volcanic"
    },
    {
      "x": 7,
      "y": 10,
      "z": 1,
      "name": "Rock_Volcanic"
    },
    {
      "x": 7,
      "y": 11,
      "z": 1,
      "name": "Rock_Volcanic"
    },
    {
      "x": 7,
      "y": 3,
      "z": 2,
      "name": "Rock_Volcanic"
    },
    {
      "x": 7,
      "y": 4,
      "z": 2,
      "name": "Rock_Volcanic"
    },
    {
      "x": 7,
      "y": 5,
      "z": 2,
      "name": "Rock_Volcanic"
    },
    {
      "x": 7,
      "y": 6,
      "z": 2,
      "name": "Rock_Volcanic"
    },
    {
      "x": 7,
      "y": 7,
      "z": 2,
      "name": "Rock_Volcanic"
    },
    {
      "x": 7,
      "y": 8,
      "z": 2,
      "name": "Rock_Volcanic"
    },
    {
      "x": 7,
      "y": 9,
      "z": 2,
      "name": "Rock_Volcanic"
    },
    {
      "x": 7,
      "y": 10,
      "z": 2,
      "name": "Rock_Volcanic"
    },
    {
      "x": 7,
      "y": 11,
      "z": 2,
      "name": "Rock_Volcanic"
    },
    {
      "x": 7,
      "y": 2,
      "z": 3,
      "name": "Rock_Volcanic"
    },
    {
      "x": 7,
      "y": 3,
      "z": 3,
      "name": "Rock_Volcanic"
    },
    {
      "x": 7,
      "y": 4,
      "z": 3,
      "name": "Rock_Volcanic"
    },
    {
      "x": 7,
      "y": 5,
      "z": 3,
      "name": "Rock_Volcanic"
    },
    {
      "x": 7,
      "y": 6,
      "z": 3,
      "name": "Rock_Volcanic"
    },
    {
      "x": 7,
      "y": 7,
      "z": 3,
      "name": "Rock_Volcanic"
    },
    {
      "x": 7,
      "y": 8,
      "z": 3,
      "name": "Rock_Volcanic"
    },
    {
      "x": 7,
      "y": 9,
      "z": 3,
      "name": "Rock_Volcanic"
    },
    {
      "x": 7,
      "y": 2,
      "z": 4,
      "name": "Rock_Volcanic"
    },
    {
      "x": 7,
      "y": 3,
      "z": 4,
      "name": "Rock_Volcanic"
    },
    {
      "x": 7,
      "y": 4,
      "z": 4,
      "name": "Rock_Volcanic"
    },
    {
      "x": 7,
      "y": 5,
      "z": 4,
      "name": "Rock_Volcanic"
    },
    {
      "x": 7,
      "y": 6,
      "z": 4,
      "name": "Rock_Volcanic"
    },
    {
      "x": 7,
      "y": 7,
      "z": 4,
      "name": "Rock_Volcanic"
    },
    {
      "x": 7,
      "y": 8,
      "z": 4,
      "name": "Rock_Volcanic"
    },
    {
      "x": 7,
      "y": 9,
      "z": 4,
      "name": "Rock_Volcanic"
    },
    {
      "x": 7,
      "y": 2,
      "z": 5,
      "name": "Rock_Volcanic"
    },
    {
      "x": 7,
      "y": 3,
      "z": 5,
      "name": "Rock_Volcanic"
    },
    {
      "x": 7,
      "y": 4,
      "z": 5,
      "name": "Rock_Volcanic"
    },
    {
      "x": 7,
      "y": 5,
      "z": 5,
      "name": "Rock_Volcanic"
    },
    {
      "x": 7,
      "y": 6,
      "z": 5,
      "name": "Rock_Volcanic"
    },
    {
      "x": 7,
      "y": 7,
      "z": 5,
      "name": "Rock_Volcanic"
    },
    {
      "x": 7,
      "y": 8,
      "z": 5,
      "name": "Rock_Volcanic"
    },
    {
      "x": 7,
      "y": 2,
      "z": 6,
      "name": "Rock_Volcanic"
    },
    {
      "x": 7,
      "y": 3,
      "z": 6,
      "name": "Rock_Volcanic"
    },
    {
      "x": 7,
      "y": 4,
      "z": 6,
      "name": "Rock_Volcanic"
    },
    {
      "x": 7,
      "y": 5,
      "z": 6,
      "name": "Rock_Volcanic"
    },
    {
      "x": 7,
      "y": 6,
      "z": 6,
      "name": "Rock_Volcanic"
    },
    {
      "x": 7,
      "y": 7,
      "z": 6,
      "name": "Rock_Volcanic"
    },
    {
      "x": 7,
      "y": 8,
      "z": 6,
      "name": "Rock_Volcanic"
    },
    {
      "x": 7,
      "y": 3,
      "z": 7,
      "name": "Rock_Volcanic"
    },
    {
      "x": 7,
      "y": 4,
      "z": 7,
      "name": "Rock_Volcanic"
    },
    {
      "x": 7,
      "y": 5,
      "z": 7,
      "name": "Rock_Volcanic"
    },
    {
      "x": 7,
      "y": 6,
      "z": 7,
      "name": "Rock_Volcanic"
    },
    {
      "x": 7,
      "y": 7,
      "z": 7,
      "name": "Rock_Volcanic"
    },
    {
      "x": 7,
      "y": 4,
      "z": 8,
      "name": "Rock_Volcanic"
    },
    {
      "x": 7,
      "y": 5,
      "z": 8,
      "name": "Rock_Volcanic"
    },
    {
      "x": 7,
      "y": 6,
      "z": 8,
      "name": "Rock_Volcanic"
    },
    {
      "x": 8,
      "y": 4,
      "z": 0,
      "name": "Rock_Volcanic"
    },
    {
      "x": 8,
      "y": 5,
      "z": 0,
      "name": "Rock_Volcanic"
    },
    {
      "x": 8,
      "y": 6,
      "z": 0,
      "name": "Rock_Volcanic"
    },
    {
      "x": 8,
      "y": 7,
      "z": 0,
      "name": "Rock_Volcanic"
    },
    {
      "x": 8,
      "y": 8,
      "z": 0,
      "name": "Rock_Volcanic"
    },
    {
      "x": 8,
      "y": 3,
      "z": 1,
      "name": "Rock_Volcanic"
    },
    {
      "x": 8,
      "y": 4,
      "z": 1,
      "name": "Rock_Volcanic"
    },
    {
      "x": 8,
      "y": 5,
      "z": 1,
      "name": "Rock_Volcanic"
    },
    {
      "x": 8,
      "y": 6,
      "z": 1,
      "name": "Rock_Volcanic"
    },
    {
      "x": 8,
      "y": 7,
      "z": 1,
      "name": "Rock_Volcanic"
    },
    {
      "x": 8,
      "y": 8,
      "z": 1,
      "name": "Rock_Volcanic"
    },
    {
      "x": 8,
      "y": 9,
      "z": 1,
      "name": "Rock_Volcanic"
    },
    {
      "x": 8,
      "y": 3,
      "z": 2,
      "name": "Rock_Volcanic"
    },
    {
      "x": 8,
      "y": 4,
      "z": 2,
      "name": "Rock_Volcanic"
    },
    {
      "x": 8,
      "y": 5,
      "z": 2,
      "name": "Rock_Volcanic"
    },
    {
      "x": 8,
      "y": 6,
      "z": 2,
      "name": "Rock_Volcanic"
    },
    {
      "x": 8,
      "y": 7,
      "z": 2,
      "name": "Rock_Volcanic"
    },
    {
      "x": 8,
      "y": 8,
      "z": 2,
      "name": "Rock_Volcanic"
    },
    {
      "x": 8,
      "y": 9,
      "z": 2,
      "name": "Rock_Volcanic"
    },
    {
      "x": 8,
      "y": 3,
      "z": 3,
      "name": "Rock_Volcanic"
    },
    {
      "x": 8,
      "y": 4,
      "z": 3,
      "name": "Rock_Volcanic"
    },
    {
      "x": 8,
      "y": 5,
      "z": 3,
      "name": "Rock_Volcanic"
    },
    {
      "x": 8,
      "y": 6,
      "z": 3,
      "name": "Rock_Volcanic"
    },
    {
      "x": 8,
      "y": 7,
      "z": 3,
      "name": "Rock_Volcanic"
    },
    {
      "x": 8,
      "y": 8,
      "z": 3,
      "name": "Rock_Volcanic"
    },
    {
      "x": 8,
      "y": 2,
      "z": 4,
      "name": "Rock_Volcanic"
    },
    {
      "x": 8,
      "y": 3,
      "z": 4,
      "name": "Rock_Volcanic"
    },
    {
      "x": 8,
      "y": 4,
      "z": 4,
      "name": "Rock_Volcanic"
    },
    {
      "x": 8,
      "y": 5,
      "z": 4,
      "name": "Rock_Volcanic"
    },
    {
      "x": 8,
      "y": 6,
      "z": 4,
      "name": "Rock_Volcanic"
    },
    {
      "x": 8,
      "y": 7,
      "z": 4,
      "name": "Rock_Volcanic"
    },
    {
      "x": 8,
      "y": 8,
      "z": 4,
      "name": "Rock_Volcanic"
    },
    {
      "x": 8,
      "y": 2,
      "z": 5,
      "name": "Rock_Volcanic"
    },
    {
      "x": 8,
      "y": 3,
      "z": 5,
      "name": "Rock_Volcanic"
    },
    {
      "x": 8,
      "y": 4,
      "z": 5,
      "name": "Rock_Volcanic"
    },
    {
      "x": 8,
      "y": 5,
      "z": 5,
      "name": "Rock_Volcanic"
    },
    {
      "x": 8,
      "y": 6,
      "z": 5,
      "name": "Rock_Volcanic"
    },
    {
      "x": 8,
      "y": 7,
      "z": 5,
      "name": "Rock_Volcanic"
    },
    {
      "x": 8,
      "y": 8,
      "z": 5,
      "name": "Rock_Volcanic"
    },
    {
      "x": 8,
      "y": 2,
      "z": 6,
      "name": "Rock_Volcanic"
    },
    {
      "x": 8,
      "y": 3,
      "z": 6,
      "name": "Rock_Volcanic"
    },
    {
      "x": 8,
      "y": 4,
      "z": 6,
      "name": "Rock_Volcanic"
    },
    {
      "x": 8,
      "y": 5,
      "z": 6,
      "name": "Rock_Volcanic"
    },
    {
      "x": 8,
      "y": 6,
      "z": 6,
      "name": "Rock_Volcanic"
    },
    {
      "x": 8,
      "y": 7,
      "z": 6,
      "name": "Rock_Volcanic"
    },
    {
      "x": 8,
      "y": 8,
      "z": 6,
      "name": "Rock_Volcanic"
    },
    {
      "x": 8,
      "y": 3,
      "z": 7,
      "name": "Rock_Volcanic"
    },
    {
      "x": 8,
      "y": 4,
      "z": 7,
      "name": "Rock_Volcanic"
    },
    {
      "x": 8,
      "y": 5,
      "z": 7,
      "name": "Rock_Volcanic"
    },
    {
      "x": 8,
      "y": 6,
      "z": 7,
      "name": "Rock_Volcanic"
    },
    {
      "x": 8,
      "y": 7,
      "z": 7,
      "name": "Rock_Volcanic"
    },
    {
      "x": 8,
      "y": 4,
      "z": 8,
      "name": "Rock_Volcanic"
    },
    {
      "x": 8,
      "y": 5,
      "z": 8,
      "name": "Rock_Volcanic"
    },
    {
      "x": 8,
      "y": 6,
      "z": 8,
      "name": "Rock_Volcanic"
    },
    {
      "x": 9,
      "y": 4,
      "z": 1,
      "name": "Rock_Volcanic"
    },
    {
      "x": 9,
      "y": 5,
      "z": 1,
      "name": "Rock_Volcanic"
    },
    {
      "x": 9,
      "y": 6,
      "z": 1,
      "name": "Rock_Volcanic"
    },
    {
      "x": 9,
      "y": 4,
      "z": 2,
      "name": "Rock_Volcanic"
    },
    {
      "x": 9,
      "y": 5,
      "z": 2,
      "name": "Rock_Volcanic"
    },
    {
      "x": 9,
      "y": 6,
      "z": 2,
      "name": "Rock_Volcanic"
    },
    {
      "x": 9,
      "y": 7,
      "z": 2,
      "name": "Rock_Volcanic"
    },
    {
      "x": 9,
      "y": 3,
      "z": 3,
      "name": "Rock_Volcanic"
    },
    {
      "x": 9,
      "y": 4,
      "z": 3,
      "name": "Rock_Volcanic"
    },
    {
      "x": 9,
      "y": 5,
      "z": 3,
      "name": "Rock_Volcanic"
    },
    {
      "x": 9,
      "y": 6,
      "z": 3,
      "name": "Rock_Volcanic"
    },
    {
      "x": 9,
      "y": 7,
      "z": 3,
      "name": "Rock_Volcanic"
    },
    {
      "x": 9,
      "y": 3,
      "z": 4,
      "name": "Rock_Volcanic"
    },
    {
      "x": 9,
      "y": 4,
      "z": 4,
      "name": "Rock_Volcanic"
    },
    {
      "x": 9,
      "y": 5,
      "z": 4,
      "name": "Rock_Volcanic"
    },
    {
      "x": 9,
      "y": 6,
      "z": 4,
      "name": "Rock_Volcanic"
    },
    {
      "x": 9,
      "y": 7,
      "z": 4,
      "name": "Rock_Volcanic"
    },
    {
      "x": 9,
      "y": 3,
      "z": 5,
      "name": "Rock_Volcanic"
    },
    {
      "x": 9,
      "y": 4,
      "z": 5,
      "name": "Rock_Volcanic"
    },
    {
      "x": 9,
      "y": 5,
      "z": 5,
      "name": "Rock_Volcanic"
    },
    {
      "x": 9,
      "y": 6,
      "z": 5,
      "name": "Rock_Volcanic"
    },
    {
      "x": 9,
      "y": 3,
      "z": 6,
      "name": "Rock_Volcanic"
    },
    {
      "x": 9,
      "y": 4,
      "z": 6,
      "name": "Rock_Volcanic"
    },
    {
      "x": 9,
      "y": 5,
      "z": 6,
      "name": "Rock_Volcanic"
    },
    {
      "x": 9,
      "y": 6,
      "z": 6,
      "name": "Rock_Volcanic"
    },
    {
      "x": 9,
      "y": 7,
      "z": 6,
      "name": "Rock_Volcanic"
    },
    {
      "x": 9,
      "y": 4,
      "z": 7,
      "name": "Rock_Volcanic"
    },
    {
      "x": 9,
      "y": 5,
      "z": 7,
      "name": "Rock_Volcanic"
    },
    {
      "x": 9,
      "y": 6,
      "z": 7,
      "name": "Rock_Volcanic"
    },
    {
      "x": 10,
      "y": 5,
      "z": 3,
      "name": "Rock_Volcanic"
    },
    {
      "x": 10,
      "y": 5,
      "z": 4,
      "name": "Rock_Volcanic"
    },
    {
      "x": 10,
      "y": 4,
      "z": 5,
      "name": "Rock_Volcanic"
    },
    {
      "x": 10,
      "y": 4,
      "z": 6,
      "name": "Rock_Volcanic"
    },
    {
      "x": 10,
      "y": 5,
      "z": 6,
      "name": "Rock_Volcanic"
    },
    {
      "x": 10,
      "y": 6,
      "z": 6,
      "name": "Rock_Volcanic"
    }
  ]
}