{
  "version": 8,
  "blockIdVersion": 8,
  "anchorX": -1,
  "anchorY": 27,
  "anchorZ": 1,
  "blocks": [
    {
      "x": -10,
      "y": 47,
      "z": 1,
      "name": "Plant_Leaves_Birch"
    },
    {
      "x": -10,
      "y": 50,
      "z": 2,
      "name": "Plant_Leaves_Birch"
    },
    {
      "x": -10,
      "y": 46,
      "z": 3,
      "name": "Plant_Leaves_Birch"
    },
    {
      "x": -10,
      "y": 52,
      "z": 4,
      "name": "Plant_Leaves_Birch"
    },
    {
      "x": -9,
      "y": 46,
      "z": 0,
      "name": "Plant_Leaves_Birch"
    },
    {
      "x": -9,
      "y": 47,
      "z": 0,
      "name": "Plant_Leaves_Birch"
    },
    {
      "x": -9,
      "y": 51,
      "z": 0,
      "name": "Plant_Leaves_Birch"
    },
    {
      "x": -9,
      "y": 52,
      "z": 0,
      "name": "Plant_Leaves_Birch"
    },
    {
      "x": -9,
      "y": 44,
      "z": 1,
      "name": "Plant_Leaves_Birch"
    },
    {
      "x": -9,
      "y": 45,
      "z": 1,
      "name": "Plant_Leaves_Birch"
    },
    {
      "x": -9,
      "y": 46,
      "z": 1,
      "name": "Plant_Leaves_Birch"
    },
    {
      "x": -9,
      "y": 47,
      "z": 1,
      "name": "Plant_Leaves_Birch"
    },
    {
      "x": -9,
      "y": 48,
      "z": 1,
      "name": "Plant_Leaves_Birch"
    },
    {
      "x": -9,
      "y": 50,
      "z": 1,
      "name": "Plant_Leaves_Birch"
    },
    {
      "x": -9,
      "y": 51,
      "z": 1,
      "name": "Plant_Leaves_Birch"
    },
    {
      "x": -9,
      "y": 52,
      "z": 1,
      "name": "Plant_Leaves_Birch"
    },
    {
      "x": -9,
      "y": 53,
      "z": 1,
      "name": "Plant_Leaves_Birch"
    },
    {
      "x": -9,
      "y": 30,
      "z": 2,
      "name": "Soil_Dirt"
    },
    {
      "x": -9,
      "y": 31,
      "z": 2,
      "name": "Soil_Grass"
    },
    {
      "x": -9,
      "y": 44,
      "z": 2,
      "name": "Plant_Leaves_Birch"
    },
    {
      "x": -9,
      "y": 45,
      "z": 2,
      "name": "Plant_Leaves_Birch"
    },
    {
      "x": -9,
      "y": 46,
      "z": 2,
      "name": "Plant_Leaves_Birch"
    },
    {
      "x": -9,
      "y": 47,
      "z": 2,
      "name": "Plant_Leaves_Birch"
    },
    {
      "x": -9,
      "y": 48,
      "z": 2,
      "name": "Plant_Leaves_Birch"
    },
    {
      "x": -9,
      "y": 49,
      "z": 2,
      "name": "Plant_Leaves_Birch"
    },
    {
      "x": -9,
      "y": 50,
      "z": 2,
      "name": "Plant_Leaves_Birch"
    },
    {
      "x": -9,
      "y": 51,
      "z": 2,
      "name": "Plant_Leaves_Birch"
    },
    {
      "x": -9,
      "y": 52,
      "z": 2,
      "name": "Plant_Leaves_Birch"
    },
    {
      "x": -9,
      "y": 53,
      "z": 2,
      "name": "Plant_Leaves_Birch"
    },
    {
      "x": -9,
      "y": 54,
      "z": 2,
      "name": "Plant_Leaves_Birch"
    },
    {
      "x": -9,
      "y": 26,
      "z": 3,
      "name": "Rock_Stone"
    },
    {
      "x": -9,
      "y": 27,
      "z": 3,
      "name": "Rock_Stone"
    },
    {
      "x": -9,
      "y": 28,
      "z": 3,
      "name": "Rock_Stone"
    },
    {
      "x": -9,
      "y": 29,
      "z": 3,
      "name": "Soil_Dirt"
    },
    {
      "x": -9,
      "y": 30,
      "z": 3,
      "name": "Soil_Dirt"
    },
    {
      "x": -9,
      "y": 31,
      "z": 3,
      "name": "Soil_Grass"
    },
    {
      "x": -9,
      "y": 43,
      "z": 3,
      "name": "Plant_Leaves_Birch"
    },
    {
      "x": -9,
      "y": 44,
      "z": 3,
      "name": "Plant_Leaves_Birch"
    },
    {
      "x": -9,
      "y": 45,
      "z": 3,
      "name": "Plant_Leaves_Birch"
    },
    {
      "x": -9,
      "y": 46,
      "z": 3,
      "name": "Plant_Leaves_Birch"
    },
    {
      "x": -9,
      "y": 47,
      "z": 3,
      "name": "Plant_Leaves_Birch"
    },
    {
      "x": -9,
      "y": 48,
      "z": 3,
      "name": "Plant_Leaves_Birch"
    },
    {
      "x": -9,
      "y": 49,
      "z": 3,
      "name": "Plant_Leaves_Birch"
    },
    {
      "x": -9,
      "y": 50,
      "z": 3,
      "name": "Plant_Leaves_Birch"
    },
    {
      "x": -9,
      "y": 51,
      "z": 3,
      "name": "Plant_Leaves_Birch"
    },
    {
      "x": -9,
      "y": 52,
      "z": 3,
      "name": "Plant_Leaves_Birch"
    },
    {
      "x": -9,
      "y": 27,
      "z": 4,
      "name": "Rock_Stone"
    },
    {
      "x": -9,
      "y": 28,
      "z": 4,
      "name": "Rock_Stone"
    },
    {
      "x": -9,
      "y": 29,
      "z": 4,
      "name": "Soil_Dirt"
    },
    {
      "x": -9,
      "y": 30,
      "z": 4,
      "name": "Soil_Dirt"
    },
    {
      "x": -9,
      "y": 31,
      "z": 4,
      "name": "Soil_Grass"
    },
    {
      "x": -9,
      "y": 32,
      "z": 4,
      "name": "Plant_Grass_Sharp"
    },
    {
      "x": -9,
      "y": 43,
      "z": 4,
      "name": "Plant_Leaves_Birch"
    },
    {
      "x": -9,
      "y": 44,
      "z": 4,
      "name": "Plant_Leaves_Birch"
    },
    {
      "x": -9,
      "y": 47,
      "z": 4,
      "name": "Plant_Leaves_Birch"
    },
    {
      "x": -9,
      "y": 48,
      "z": 4,
      "name": "Plant_Leaves_Birch"
    },
    {
      "x": -9,
      "y": 49,
      "z": 4,
      "name": "Plant_Leaves_Birch"
    },
    {
      "x": -9,
      "y": 51,
      "z": 4,
      "name": "Plant_Leaves_Birch"
    },
    {
      "x": -9,
      "y": 52,
      "z": 4,
      "name": "Plant_Leaves_Birch"
    },
    {
      "x": -9,
      "y": 53,
      "z": 4,
      "name": "Plant_Leaves_Birch"
    },
    {
      "x": -9,
      "y": 44,
      "z": 5,
      "name": "Plant_Leaves_Birch"
    },
    {
      "x": -9,
      "y": 45,
      "z": 5,
      "name": "Plant_Leaves_Birch"
    },
    {
      "x": -9,
      "y": 46,
      "z": 5,
      "name": "Plant_Leaves_Birch"
    },
    {
      "x": -8,
      "y": 45,
      "z": -2,
      "name": "Plant_Leaves_Birch"
    },
    {
      "x": -8,
      "y": 23,
      "z": -1,
      "name": "Soil_Dirt"
    },
    {
      "x": -8,
      "y": 24,
      "z": -1,
      "name": "Soil_Dirt"
    },
    {
      "x": -8,
      "y": 25,
      "z": -1,
      "name": "Soil_Grass"
    },
    {
      "x": -8,
      "y": 45,
      "z": -1,
      "name": "Plant_Leaves_Birch"
    },
    {
      "x": -8,
      "y": 50,
      "z": -1,
      "name": "Plant_Leaves_Birch"
    },
    {
      "x": -8,
      "y": 20,
      "z": 0,
      "name": "Rock_Stone_Mossy"
    },
    {
      "x": -8,
      "y": 21,
      "z": 0,
      "name": "Rock_Stone_Mossy"
    },
    {
      "x": -8,
      "y": 22,
      "z": 0,
      "name": "Rock_Stone_Mossy"
    },
    {
      "x": -8,
      "y": 23,
      "z": 0,
      "name": "Soil_Dirt"
    },
    {
      "x": -8,
      "y": 24,
      "z": 0,
      "name": "Soil_Dirt"
    },
    {
      "x": -8,
      "y": 25,
      "z": 0,
      "name": "Soil_Grass"
    },
    {
      "x": -8,
      "y": 26,
      "z": 0,
      "name": "Plant_Grass_Sharp"
    },
    {
      "x": -8,
      "y": 43,
      "z": 0,
      "name": "Plant_Leaves_Birch"
    },
    {
      "x": -8,
      "y": 44,
      "z": 0,
      "name": "Plant_Leaves_Birch"
    },
    {
      "x": -8,
      "y": 45,
      "z": 0,
      "name": "Plant_Leaves_Birch"
    },
    {
      "x": -8,
      "y": 46,
      "z": 0,
      "name": "Plant_Leaves_Birch"
    },
    {
      "x": -8,
      "y": 47,
      "z": 0,
      "name": "Plant_Leaves_Birch"
    },
    {
      "x": -8,
      "y": 48,
      "z": 0,
      "name": "Plant_Leaves_Birch"
    },
    {
      "x": -8,
      "y": 50,
      "z": 0,
      "name": "Plant_Leaves_Birch"
    },
    {
      "x": -8,
      "y": 51,
      "z": 0,
      "name": "Plant_Leaves_Birch"
    },
    {
      "x": -8,
      "y": 52,
      "z": 0,
      "name": "Plant_Leaves_Birch"
    },
    {
      "x": -8,
      "y": 53,
      "z": 0,
      "name": "Plant_Leaves_Birch"
    },
    {
      "x": -8,
      "y": 20,
      "z": 1,
      "name": "Rock_Stone_Mossy"
    },
    {
      "x": -8,
      "y": 21,
      "z": 1,
      "name": "Rock_Stone_Mossy"
    },
    {
      "x": -8,
      "y": 22,
      "z": 1,
      "name": "Rock_Stone"
    },
    {
      "x": -8,
      "y": 23,
      "z": 1,
      "name": "Rock_Stone"
    },
    {
      "x": -8,
      "y": 24,
      "z": 1,
      "name": "Soil_Dirt"
    },
    {
      "x": -8,
      "y": 25,
      "z": 1,
      "name": "Soil_Grass"
    },
    {
      "x": -8,
      "y": 26,
      "z": 1,
      "name": "Plant_Grass_Sharp"
    },
    {
      "x": -8,
      "y": 28,
      "z": 1,
      "name": "Soil_Dirt"
    },
    {
      "x": -8,
      "y": 29,
      "z": 1,
      "name": "Soil_Dirt"
    },
    {
      "x": -8,
      "y": 30,
      "z": 1,
      "name": "Soil_Dirt"
    },
    {
      "x": -8,
      "y": 31,
      "z": 1,
      "name": "Soil_Grass"
    },
    {
      "x": -8,
      "y": 50,
      "z": 1,
      "name": "Plant_Leaves_Birch"
    },
    {
      "x": -8,
      "y": 55,
      "z": 1,
      "name": "Plant_Leaves_Birch"
    },
    {
      "x": -8,
      "y": 56,
      "z": 1,
      "name": "Plant_Leaves_Birch"
    },
    {
      "x": -8,
      "y": 57,
      "z": 1,
      "name": "Plant_Leaves_Birch"
    },
    {
      "x": -8,
      "y": 20,
      "z": 2,
      "name": "Rock_Stone"
    },
    {
      "x": -8,
      "y": 21,
      "z": 2,
      "name": "Rock_Stone"
    },
    {
      "x": -8,
      "y": 22,
      "z": 2,
      "name": "Rock_Stone"
    },
    {
      "x": -8,
      "y": 23,
      "z": 2,
      "name": "Rock_Stone"
    },
    {
      "x": -8,
      "y": 24,
      "z": 2,
      "name": "Rock_Stone"
    },
    {
      "x": -8,
      "y": 25,
      "z": 2,
      "name": "Rock_Stone_Mossy"
    },
    {
      "x": -8,
      "y": 26,
      "z": 2,
      "name": "Rock_Stone_Mossy"
    },
    {
      "x": -8,
      "y": 27,
      "z": 2,
      "name": "Rock_Stone_Mossy"
    },
    {
      "x": -8,
      "y": 28,
      "z": 2,
      "name": "Soil_Dirt"
    },
    {
      "x": -8,
      "y": 29,
      "z": 2,
      "name": "Soil_Dirt"
    },
    {
      "x": -8,
      "y": 30,
      "z": 2,
      "name": "Soil_Dirt"
    },
    {
      "x": -8,
      "y": 31,
      "z": 2,
      "name": "Soil_Grass"
    },
    {
      "x": -8,
      "y": 42,
      "z": 2,
      "name": "Plant_Leaves_Birch"
    },
    {
      "x": -8,
      "y": 43,
      "z": 2,
      "name": "Plant_Leaves_Birch"
    },
    {
      "x": -8,
      "y": 44,
      "z": 2,
      "name": "Plant_Leaves_Birch"
    },
    {
      "x": -8,
      "y": 45,
      "z": 2,
      "name": "Plant_Leaves_Birch"
    },
    {
      "x": -8,
      "y": 53,
      "z": 2,
      "name": "Plant_Leaves_Birch"
    },
    {
      "x": -8,
      "y": 54,
      "z": 2,
      "name": "Plant_Leaves_Birch"
    },
    {
      "x": -8,
      "y": 55,
      "z": 2,
      "name": "Plant_Leaves_Birch"
    },
    {
      "x": -8,
      "y": 56,
      "z": 2,
      "name": "Plant_Leaves_Birch"
    },
    {
      "x": -8,
      "y": 57,
      "z": 2,
      "name": "Plant_Leaves_Birch"
    },
    {
      "x": -8,
      "y": 22,
      "z": 3,
      "name": "Rock_Stone"
    },
    {
      "x": -8,
      "y": 23,
      "z": 3,
      "name": "Rock_Stone"
    },
    {
      "x": -8,
      "y": 24,
      "z": 3,
      "name": "Rock_Stone"
    },
    {
      "x": -8,
      "y": 25,
      "z": 3,
      "name": "Rock_Stone"
    },
    {
      "x": -8,
      "y": 26,
      "z": 3,
      "name": "Rock_Stone_Mossy"
    },
    {
      "x": -8,
      "y": 27,
      "z": 3,
      "name": "Rock_Stone"
    },
    {
      "x": -8,
      "y": 28,
      "z": 3,
      "name": "Rock_Stone_Mossy"
    },
    {
      "x": -8,
      "y": 29,
      "z": 3,
      "name": "Soil_Dirt"
    },
    {
      "x": -8,
      "y": 30,
      "z": 3,
      "name": "Soil_Dirt"
    },
    {
      "x": -8,
      "y": 31,
      "z": 3,
      "name": "Soil_Grass"
    },
    {
      "x": -8,
      "y": 43,
      "z": 3,
      "name": "Wood_Birch_Branch_Long",
      "rotation": 5
    },
    {
      "x": -8,
      "y": 44,
      "z": 3,
      "name": "Plant_Leaves_Birch"
    },
    {
      "x": -8,
      "y": 47,
      "z": 3,
      "name": "Wood_Birch_Branch_Long",
      "rotation": 5
    },
    {
      "x": -8,
      "y": 51,
      "z": 3,
      "name": "Plant_Leaves_Birch"
    },
    {
      "x": -8,
      "y": 54,
      "z": 3,
      "name": "Plant_Leaves_Birch"
    },
    {
      "x": -8,
      "y": 55,
      "z": 3,
      "name": "Plant_Leaves_Birch"
    },
    {
      "x": -8,
      "y": 56,
      "z": 3,
      "name": "Plant_Leaves_Birch"
    },
    {
      "x": -8,
      "y": 22,
      "z": 4,
      "name": "Rock_Stone"
    },
    {
      "x": -8,
      "y": 23,
      "z": 4,
      "name": "Rock_Stone"
    },
    {
      "x": -8,
      "y": 24,
      "z": 4,
      "name": "Rock_Stone"
    },
    {
      "x": -8,
      "y": 25,
      "z": 4,
      "name": "Rock_Stone"
    },
    {
      "x": -8,
      "y": 26,
      "z": 4,
      "name": "Rock_Stone"
    },
    {
      "x": -8,
      "y": 27,
      "z": 4,
      "name": "Rock_Stone"
    },
    {
      "x": -8,
      "y": 28,
      "z": 4,
      "name": "Soil_Dirt"
    },
    {
      "x": -8,
      "y": 29,
      "z": 4,
      "name": "Soil_Dirt"
    },
    {
      "x": -8,
      "y": 30,
      "z": 4,
      "name": "Soil_Dirt"
    },
    {
      "x": -8,
      "y": 31,
      "z": 4,
      "name": "Soil_Grass"
    },
    {
      "x": -8,
      "y": 32,
      "z": 4,
      "name": "Plant_Grass_Sharp"
    },
    {
      "x": -8,
      "y": 43,
      "z": 4,
      "name": "Plant_Leaves_Birch"
    },
    {
      "x": -8,
      "y": 49,
      "z": 4,
      "name": "Plant_Leaves_Birch"
    },
    {
      "x": -8,
      "y": 51,
      "z": 4,
      "name": "Plant_Leaves_Birch"
    },
    {
      "x": -8,
      "y": 52,
      "z": 4,
      "name": "Plant_Leaves_Birch"
    },
    {
      "x": -8,
      "y": 53,
      "z": 4,
      "name": "Plant_Leaves_Birch"
    },
    {
      "x": -8,
      "y": 55,
      "z": 4,
      "name": "Plant_Leaves_Birch"
    },
    {
      "x": -8,
      "y": 31,
      "z": 5,
      "name": "Soil_Grass"
    },
    {
      "x": -8,
      "y": 42,
      "z": 5,
      "name": "Plant_Leaves_Birch"
    },
    {
      "x": -8,
      "y": 43,
      "z": 5,
      "name": "Plant_Leaves_Birch"
    },
    {
      "x": -8,
      "y": 44,
      "z": 5,
      "name": "Plant_Leaves_Birch"
    },
    {
      "x": -8,
      "y": 45,
      "z": 5,
      "name": "Plant_Leaves_Birch"
    },
    {
      "x": -8,
      "y": 49,
      "z": 5,
      "name": "Plant_Leaves_Birch"
    },
    {
      "x": -8,
      "y": 50,
      "z": 5,
      "name": "Plant_Leaves_Birch"
    },
    {
      "x": -8,
      "y": 52,
      "z": 5,
      "name": "Plant_Leaves_Birch"
    },
    {
      "x": -8,
      "y": 45,
      "z": 6,
      "name": "Plant_Leaves_Birch"
    },
    {
      "x": -8,
      "y": 46,
      "z": 6,
      "name": "Plant_Leaves_Birch"
    },
    {
      "x": -8,
      "y": 47,
      "z": 6,
      "name": "Plant_Leaves_Birch"
    },
    {
      "x": -7,
      "y": 22,
      "z": -3,
      "name": "Rock_Stone_Mossy"
    },
    {
      "x": -7,
      "y": 23,
      "z": -3,
      "name": "Rock_Stone_Mossy"
    },
    {
      "x": -7,
      "y": 24,
      "z": -3,
      "name": "Soil_Dirt"
    },
    {
      "x": -7,
      "y": 25,
      "z": -3,
      "name": "Soil_Dirt"
    },
    {
      "x": -7,
      "y": 26,
      "z": -3,
      "name": "Soil_Grass"
    },
    {
      "x": -7,
      "y": 21,
      "z": -2,
      "name": "Rock_Stone"
    },
    {
      "x": -7,
      "y": 22,
      "z": -2,
      "name": "Rock_Stone_Mossy"
    },
    {
      "x": -7,
      "y": 23,
      "z": -2,
      "name": "Soil_Dirt"
    },
    {
      "x": -7,
      "y": 24,
      "z": -2,
      "name": "Soil_Dirt"
    },
    {
      "x": -7,
      "y": 25,
      "z": -2,
      "name": "Soil_Dirt"
    },
    {
      "x": -7,
      "y": 26,
      "z": -2,
      "name": "Soil_Grass"
    },
    {
      "x": -7,
      "y": 20,
      "z": -1,
      "name": "Rock_Stone"
    },
    {
      "x": -7,
      "y": 21,
      "z": -1,
      "name": "Rock_Stone"
    },
    {
      "x": -7,
      "y": 22,
      "z": -1,
      "name": "Rock_Stone"
    },
    {
      "x": -7,
      "y": 23,
      "z": -1,
      "name": "Soil_Dirt"
    },
    {
      "x": -7,
      "y": 24,
      "z": -1,
      "name": "Soil_Dirt"
    },
    {
      "x": -7,
      "y": 25,
      "z": -1,
      "name": "Soil_Grass"
    },
    {
      "x": -7,
      "y": 26,
      "z": -1,
      "name": "Plant_Grass_Sharp_Tall"
    },
    {
      "x": -7,
      "y": 27,
      "z": -1,
      "name": "Plant_Grass_Sharp_Tall",
      "filler": 1024
    },
    {
      "x": -7,
      "y": 44,
      "z": -1,
      "name": "Plant_Leaves_Birch"
    },
    {
      "x": -7,
      "y": 45,
      "z": -1,
      "name": "Plant_Leaves_Birch"
    },
    {
      "x": -7,
      "y": 46,
      "z": -1,
      "name": "Plant_Leaves_Birch"
    },
    {
      "x": -7,
      "y": 47,
      "z": -1,
      "name": "Plant_Leaves_Birch"
    },
    {
      "x": -7,
      "y": 49,
      "z": -1,
      "name": "Plant_Leaves_Birch"
    },
    {
      "x": -7,
      "y": 50,
      "z": -1,
      "name": "Plant_Leaves_Birch"
    },
    {
      "x": -7,
      "y": 51,
      "z": -1,
      "name": "Plant_Leaves_Birch"
    },
    {
      "x": -7,
      "y": 20,
      "z": 0,
      "name": "Rock_Stone_Mossy"
    },
    {
      "x": -7,
      "y": 21,
      "z": 0,
      "name": "Rock_Stone_Mossy"
    },
    {
      "x": -7,
      "y": 22,
      "z": 0,
      "name": "Rock_Stone"
    },
    {
      "x": -7,
      "y": 23,
      "z": 0,
      "name": "Soil_Dirt"
    },
    {
      "x": -7,
      "y": 24,
      "z": 0,
      "name": "Soil_Dirt"
    },
    {
      "x": -7,
      "y": 25,
      "z": 0,
      "name": "Soil_Dirt"
    },
    {
      "x": -7,
      "y": 26,
      "z": 0,
      "name": "Rock_Stone"
    },
    {
      "x": -7,
      "y": 27,
      "z": 0,
      "name": "Rock_Stone"
    },
    {
      "x": -7,
      "y": 28,
      "z": 0,
      "name": "Soil_Dirt"
    },
    {
      "x": -7,
      "y": 29,
      "z": 0,
      "name": "Soil_Grass"
    },
    {
      "x": -7,
      "y": 55,
      "z": 0,
      "name": "Plant_Leaves_Birch"
    },
    {
      "x": -7,
      "y": 56,
      "z": 0,
      "name": "Plant_Leaves_Birch"
    },
    {
      "x": -7,
      "y": 20,
      "z": 1,
      "name": "Rock_Stone"
    },
    {
      "x": -7,
      "y": 21,
      "z": 1,
      "name": "Rock_Stone"
    },
    {
      "x": -7,
      "y": 22,
      "z": 1,
      "name": "Rock_Stone"
    },
    {
      "x": -7,
      "y": 23,
      "z": 1,
      "name": "Rock_Stone"
    },
    {
      "x": -7,
      "y": 24,
      "z": 1,
      "name": "Soil_Dirt"
    },
    {
      "x": -7,
      "y": 25,
      "z": 1,
      "name": "Rock_Stone"
    },
    {
      "x": -7,
      "y": 26,
      "z": 1,
      "name": "Rock_Stone"
    },
    {
      "x": -7,
      "y": 27,
      "z": 1,
      "name": "Rock_Stone"
    },
    {
      "x": -7,
      "y": 28,
      "z": 1,
      "name": "Soil_Dirt"
    },
    {
      "x": -7,
      "y": 29,
      "z": 1,
      "name": "Soil_Dirt"
    },
    {
      "x": -7,
      "y": 30,
      "z": 1,
      "name": "Soil_Dirt"
    },
    {
      "x": -7,
      "y": 31,
      "z": 1,
      "name": "Soil_Grass"
    },
    {
      "x": -7,
      "y": 57,
      "z": 1,
      "name": "Plant_Leaves_Birch"
    },
    {
      "x": -7,
      "y": 58,
      "z": 1,
      "name": "Plant_Leaves_Birch"
    },
    {
      "x": -7,
      "y": 20,
      "z": 2,
      "name": "Rock_Stone"
    },
    {
      "x": -7,
      "y": 21,
      "z": 2,
      "name": "Rock_Stone"
    },
    {
      "x": -7,
      "y": 22,
      "z": 2,
      "name": "Rock_Stone"
    },
    {
      "x": -7,
      "y": 23,
      "z": 2,
      "name": "Rock_Stone"
    },
    {
      "x": -7,
      "y": 24,
      "z": 2,
      "name": "Rock_Stone"
    },
    {
      "x": -7,
      "y": 25,
      "z": 2,
      "name": "Rock_Stone"
    },
    {
      "x": -7,
      "y": 26,
      "z": 2,
      "name": "Rock_Stone_Mossy"
    },
    {
      "x": -7,
      "y": 27,
      "z": 2,
      "name": "Rock_Stone"
    },
    {
      "x": -7,
      "y": 28,
      "z": 2,
      "name": "Soil_Dirt"
    },
    {
      "x": -7,
      "y": 29,
      "z": 2,
      "name": "Soil_Dirt"
    },
    {
      "x": -7,
      "y": 30,
      "z": 2,
      "name": "Soil_Dirt"
    },
    {
      "x": -7,
      "y": 31,
      "z": 2,
      "name": "Soil_Grass"
    },
    {
      "x": -7,
      "y": 51,
      "z": 2,
      "name": "Wood_Birch_Branch_Corner",
      "rotation": 3
    },
    {
      "x": -7,
      "y": 52,
      "z": 2,
      "name": "Wood_Birch_Branch_Long"
    },
    {
      "x": -7,
      "y": 53,
      "z": 2,
      "name": "Wood_Birch_Branch_Long"
    },
    {
      "x": -7,
      "y": 54,
      "z": 2,
      "name": "Wood_Birch_Branch_Long"
    },
    {
      "x": -7,
      "y": 57,
      "z": 2,
      "name": "Plant_Leaves_Birch"
    },
    {
      "x": -7,
      "y": 58,
      "z": 2,
      "name": "Plant_Leaves_Birch"
    },
    {
      "x": -7,
      "y": 59,
      "z": 2,
      "name": "Plant_Leaves_Birch"
    },
    {
      "x": -7,
      "y": 20,
      "z": 3,
      "name": "Rock_Stone"
    },
    {
      "x": -7,
      "y": 21,
      "z": 3,
      "name": "Rock_Stone"
    },
    {
      "x": -7,
      "y": 22,
      "z": 3,
      "name": "Rock_Stone"
    },
    {
      "x": -7,
      "y": 23,
      "z": 3,
      "name": "Rock_Stone"
    },
    {
      "x": -7,
      "y": 24,
      "z": 3,
      "name": "Rock_Stone"
    },
    {
      "x": -7,
      "y": 25,
      "z": 3,
      "name": "Rock_Stone"
    },
    {
      "x": -7,
      "y": 26,
      "z": 3,
      "name": "Rock_Stone"
    },
    {
      "x": -7,
      "y": 27,
      "z": 3,
      "name": "Rock_Stone"
    },
    {
      "x": -7,
      "y": 28,
      "z": 3,
      "name": "Rock_Stone"
    },
    {
      "x": -7,
      "y": 29,
      "z": 3,
      "name": "Soil_Dirt"
    },
    {
      "x": -7,
      "y": 30,
      "z": 3,
      "name": "Soil_Dirt"
    },
    {
      "x": -7,
      "y": 31,
      "z": 3,
      "name": "Soil_Grass"
    },
    {
      "x": -7,
      "y": 32,
      "z": 3,
      "name": "Plant_Grass_Sharp_Tall"
    },
    {
      "x": -7,
      "y": 33,
      "z": 3,
      "name": "Plant_Grass_Sharp_Tall",
      "filler": 1024
    },
    {
      "x": -7,
      "y": 43,
      "z": 3,
      "name": "Wood_Birch_Branch_Long",
      "rotation": 5
    },
    {
      "x": -7,
      "y": 47,
      "z": 3,
      "name": "Wood_Birch_Branch_Long",
      "rotation": 5
    },
    {
      "x": -7,
      "y": 57,
      "z": 3,
      "name": "Plant_Leaves_Birch"
    },
    {
      "x": -7,
      "y": 58,
      "z": 3,
      "name": "Plant_Leaves_Birch"
    },
    {
      "x": -7,
      "y": 21,
      "z": 4,
      "name": "Rock_Stone"
    },
    {
      "x": -7,
      "y": 22,
      "z": 4,
      "name": "Rock_Stone"
    },
    {
      "x": -7,
      "y": 23,
      "z": 4,
      "name": "Rock_Stone"
    },
    {
      "x": -7,
      "y": 24,
      "z": 4,
      "name": "Rock_Stone"
    },
    {
      "x": -7,
      "y": 25,
      "z": 4,
      "name": "Rock_Stone"
    },
    {
      "x": -7,
      "y": 26,
      "z": 4,
      "name": "Rock_Stone"
    },
    {
      "x": -7,
      "y": 27,
      "z": 4,
      "name": "Rock_Stone"
    },
    {
      "x": -7,
      "y": 28,
      "z": 4,
      "name": "Soil_Dirt"
    },
    {
      "x": -7,
      "y": 29,
      "z": 4,
      "name": "Soil_Dirt"
    },
    {
      "x": -7,
      "y": 30,
      "z": 4,
      "name": "Soil_Dirt"
    },
    {
      "x": -7,
      "y": 31,
      "z": 4,
      "name": "Soil_Grass"
    },
    {
      "x": -7,
      "y": 32,
      "z": 4,
      "name": "Plant_Grass_Sharp_Tall"
    },
    {
      "x": -7,
      "y": 33,
      "z": 4,
      "name": "Plant_Grass_Sharp_Tall",
      "filler": 1024
    },
    {
      "x": -7,
      "y": 54,
      "z": 4,
      "name": "Plant_Leaves_Birch"
    },
    {
      "x": -7,
      "y": 55,
      "z": 4,
      "name": "Plant_Leaves_Birch"
    },
    {
      "x": -7,
      "y": 56,
      "z": 4,
      "name": "Plant_Leaves_Birch"
    },
    {
      "x": -7,
      "y": 57,
      "z": 4,
      "name": "Plant_Leaves_Birch"
    },
    {
      "x": -7,
      "y": 24,
      "z": 5,
      "name": "Rock_Stone"
    },
    {
      "x": -7,
      "y": 25,
      "z": 5,
      "name": "Rock_Stone"
    },
    {
      "x": -7,
      "y": 26,
      "z": 5,
      "name": "Rock_Stone"
    },
    {
      "x": -7,
      "y": 27,
      "z": 5,
      "name": "Rock_Stone"
    },
    {
      "x": -7,
      "y": 28,
      "z": 5,
      "name": "Soil_Dirt"
    },
    {
      "x": -7,
      "y": 29,
      "z": 5,
      "name": "Soil_Dirt"
    },
    {
      "x": -7,
      "y": 30,
      "z": 5,
      "name": "Soil_Dirt"
    },
    {
      "x": -7,
      "y": 31,
      "z": 5,
      "name": "Soil_Grass"
    },
    {
      "x": -7,
      "y": 42,
      "z": 5,
      "name": "Plant_Leaves_Birch"
    },
    {
      "x": -7,
      "y": 50,
      "z": 5,
      "name": "Plant_Leaves_Birch"
    },
    {
      "x": -7,
      "y": 51,
      "z": 5,
      "name": "Plant_Leaves_Birch"
    },
    {
      "x": -7,
      "y": 52,
      "z": 5,
      "name": "Plant_Leaves_Birch"
    },
    {
      "x": -7,
      "y": 55,
      "z": 5,
      "name": "Plant_Leaves_Birch"
    },
    {
      "x": -7,
      "y": 42,
      "z": 6,
      "name": "Plant_Leaves_Birch"
    },
    {
      "x": -7,
      "y": 43,
      "z": 6,
      "name": "Plant_Leaves_Birch"
    },
    {
      "x": -7,
      "y": 45,
      "z": 6,
      "name": "Plant_Leaves_Birch"
    },
    {
      "x": -7,
      "y": 46,
      "z": 6,
      "name": "Plant_Leaves_Birch"
    },
    {
      "x": -7,
      "y": 47,
      "z": 6,
      "name": "Plant_Leaves_Birch"
    },
    {
      "x": -7,
      "y": 48,
      "z": 6,
      "name": "Plant_Leaves_Birch"
    },
    {
      "x": -6,
      "y": 20,
      "z": -3,
      "name": "Rock_Stone"
    },
    {
      "x": -6,
      "y": 21,
      "z": -3,
      "name": "Rock_Stone"
    },
    {
      "x": -6,
      "y": 22,
      "z": -3,
      "name": "Rock_Stone_Mossy"
    },
    {
      "x": -6,
      "y": 23,
      "z": -3,
      "name": "Rock_Stone"
    },
    {
      "x": -6,
      "y": 24,
      "z": -3,
      "name": "Soil_Dirt"
    },
    {
      "x": -6,
      "y": 25,
      "z": -3,
      "name": "Soil_Dirt"
    },
    {
      "x": -6,
      "y": 26,
      "z": -3,
      "name": "Soil_Grass"
    },
    {
      "x": -6,
      "y": 27,
      "z": -3,
      "name": "Plant_Grass_Sharp"
    },
    {
      "x": -6,
      "y": 20,
      "z": -2,
      "name": "Rock_Stone"
    },
    {
      "x": -6,
      "y": 21,
      "z": -2,
      "name": "Rock_Stone"
    },
    {
      "x": -6,
      "y": 22,
      "z": -2,
      "name": "Rock_Stone"
    },
    {
      "x": -6,
      "y": 23,
      "z": -2,
      "name": "Rock_Stone"
    },
    {
      "x": -6,
      "y": 24,
      "z": -2,
      "name": "Soil_Dirt"
    },
    {
      "x": -6,
      "y": 25,
      "z": -2,
      "name": "Soil_Dirt"
    },
    {
      "x": -6,
      "y": 26,
      "z": -2,
      "name": "Soil_Grass"
    },
    {
      "x": -6,
      "y": 27,
      "z": -2,
      "name": "Plant_Grass_Sharp"
    },
    {
      "x": -6,
      "y": 47,
      "z": -2,
      "name": "Plant_Leaves_Birch"
    },
    {
      "x": -6,
      "y": 49,
      "z": -2,
      "name": "Plant_Leaves_Birch"
    },
    {
      "x": -6,
      "y": 50,
      "z": -2,
      "name": "Plant_Leaves_Birch"
    },
    {
      "x": -6,
      "y": 52,
      "z": -2,
      "name": "Plant_Leaves_Birch"
    },
    {
      "x": -6,
      "y": 18,
      "z": -1,
      "name": "Rock_Stone_Mossy"
    },
    {
      "x": -6,
      "y": 19,
      "z": -1,
      "name": "Rock_Stone_Mossy"
    },
    {
      "x": -6,
      "y": 20,
      "z": -1,
      "name": "Rock_Stone_Mossy"
    },
    {
      "x": -6,
      "y": 21,
      "z": -1,
      "name": "Rock_Stone"
    },
    {
      "x": -6,
      "y": 22,
      "z": -1,
      "name": "Rock_Stone"
    },
    {
      "x": -6,
      "y": 23,
      "z": -1,
      "name": "Rock_Stone"
    },
    {
      "x": -6,
      "y": 24,
      "z": -1,
      "name": "Soil_Dirt"
    },
    {
      "x": -6,
      "y": 25,
      "z": -1,
      "name": "Soil_Dirt"
    },
    {
      "x": -6,
      "y": 26,
      "z": -1,
      "name": "Rock_Stone"
    },
    {
      "x": -6,
      "y": 27,
      "z": -1,
      "name": "Rock_Stone"
    },
    {
      "x": -6,
      "y": 28,
      "z": -1,
      "name": "Rock_Stone"
    },
    {
      "x": -6,
      "y": 29,
      "z": -1,
      "name": "Rock_Stone"
    },
    {
      "x": -6,
      "y": 30,
      "z": -1,
      "name": "Rock_Stone"
    },
    {
      "x": -6,
      "y": 31,
      "z": -1,
      "name": "Rock_Stone"
    },
    {
      "x": -6,
      "y": 32,
      "z": -1,
      "name": "Rock_Stone"
    },
    {
      "x": -6,
      "y": 43,
      "z": -1,
      "name": "Plant_Leaves_Birch"
    },
    {
      "x": -6,
      "y": 44,
      "z": -1,
      "name": "Plant_Leaves_Birch"
    },
    {
      "x": -6,
      "y": 45,
      "z": -1,
      "name": "Plant_Leaves_Birch"
    },
    {
      "x": -6,
      "y": 46,
      "z": -1,
      "name": "Plant_Leaves_Birch"
    },
    {
      "x": -6,
      "y": 47,
      "z": -1,
      "name": "Plant_Leaves_Birch"
    },
    {
      "x": -6,
      "y": 48,
      "z": -1,
      "name": "Plant_Leaves_Birch"
    },
    {
      "x": -6,
      "y": 49,
      "z": -1,
      "name": "Plant_Leaves_Birch"
    },
    {
      "x": -6,
      "y": 50,
      "z": -1,
      "name": "Plant_Leaves_Birch"
    },
    {
      "x": -6,
      "y": 51,
      "z": -1,
      "name": "Plant_Leaves_Birch"
    },
    {
      "x": -6,
      "y": 52,
      "z": -1,
      "name": "Plant_Leaves_Birch"
    },
    {
      "x": -6,
      "y": 53,
      "z": -1,
      "name": "Plant_Leaves_Birch"
    },
    {
      "x": -6,
      "y": 54,
      "z": -1,
      "name": "Plant_Leaves_Birch"
    },
    {
      "x": -6,
      "y": 56,
      "z": -1,
      "name": "Plant_Leaves_Birch"
    },
    {
      "x": -6,
      "y": 18,
      "z": 0,
      "name": "Rock_Stone"
    },
    {
      "x": -6,
      "y": 19,
      "z": 0,
      "name": "Rock_Stone_Mossy"
    },
    {
      "x": -6,
      "y": 20,
      "z": 0,
      "name": "Rock_Stone"
    },
    {
      "x": -6,
      "y": 21,
      "z": 0,
      "name": "Rock_Stone"
    },
    {
      "x": -6,
      "y": 22,
      "z": 0,
      "name": "Rock_Stone"
    },
    {
      "x": -6,
      "y": 23,
      "z": 0,
      "name": "Rock_Stone"
    },
    {
      "x": -6,
      "y": 24,
      "z": 0,
      "name": "Soil_Dirt"
    },
    {
      "x": -6,
      "y": 25,
      "z": 0,
      "name": "Rock_Stone"
    },
    {
      "x": -6,
      "y": 26,
      "z": 0,
      "name": "Rock_Stone"
    },
    {
      "x": -6,
      "y": 27,
      "z": 0,
      "name": "Rock_Stone"
    },
    {
      "x": -6,
      "y": 28,
      "z": 0,
      "name": "Rock_Stone"
    },
    {
      "x": -6,
      "y": 29,
      "z": 0,
      "name": "Soil_Dirt"
    },
    {
      "x": -6,
      "y": 30,
      "z": 0,
      "name": "Rock_Stone"
    },
    {
      "x": -6,
      "y": 31,
      "z": 0,
      "name": "Rock_Stone"
    },
    {
      "x": -6,
      "y": 32,
      "z": 0,
      "name": "Rock_Stone_Mossy"
    },
    {
      "x": -6,
      "y": 33,
      "z": 0,
      "name": "Rock_Stone_Mossy"
    },
    {
      "x": -6,
      "y": 34,
      "z": 0,
      "name": "Rock_Stone_Mossy"
    },
    {
      "x": -6,
      "y": 35,
      "z": 0,
      "name": "Soil_Dirt"
    },
    {
      "x": -6,
      "y": 41,
      "z": 0,
      "name": "Plant_Leaves_Birch"
    },
    {
      "x": -6,
      "y": 42,
      "z": 0,
      "name": "Plant_Leaves_Birch"
    },
    {
      "x": -6,
      "y": 43,
      "z": 0,
      "name": "Plant_Leaves_Birch"
    },
    {
      "x": -6,
      "y": 44,
      "z": 0,
      "name": "Plant_Leaves_Birch"
    },
    {
      "x": -6,
      "y": 45,
      "z": 0,
      "name": "Plant_Leaves_Birch"
    },
    {
      "x": -6,
      "y": 52,
      "z": 0,
      "name": "Plant_Leaves_Birch"
    },
    {
      "x": -6,
      "y": 55,
      "z": 0,
      "name": "Plant_Leaves_Birch"
    },
    {
      "x": -6,
      "y": 56,
      "z": 0,
      "name": "Plant_Leaves_Birch"
    },
    {
      "x": -6,
      "y": 57,
      "z": 0,
      "name": "Plant_Leaves_Birch"
    },
    {
      "x": -6,
      "y": 18,
      "z": 1,
      "name": "Rock_Stone"
    },
    {
      "x": -6,
      "y": 19,
      "z": 1,
      "name": "Rock_Stone"
    },
    {
      "x": -6,
      "y": 20,
      "z": 1,
      "name": "Rock_Stone"
    },
    {
      "x": -6,
      "y": 21,
      "z": 1,
      "name": "Rock_Stone"
    },
    {
      "x": -6,
      "y": 22,
      "z": 1,
      "name": "Rock_Stone"
    },
    {
      "x": -6,
      "y": 23,
      "z": 1,
      "name": "Rock_Stone"
    },
    {
      "x": -6,
      "y": 24,
      "z": 1,
      "name": "Rock_Stone"
    },
    {
      "x": -6,
      "y": 25,
      "z": 1,
      "name": "Rock_Stone"
    },
    {
      "x": -6,
      "y": 26,
      "z": 1,
      "name": "Rock_Stone"
    },
    {
      "x": -6,
      "y": 27,
      "z": 1,
      "name": "Rock_Stone"
    },
    {
      "x": -6,
      "y": 28,
      "z": 1,
      "name": "Rock_Stone"
    },
    {
      "x": -6,
      "y": 29,
      "z": 1,
      "name": "Soil_Dirt"
    },
    {
      "x": -6,
      "y": 30,
      "z": 1,
      "name": "Rock_Stone"
    },
    {
      "x": -6,
      "y": 31,
      "z": 1,
      "name": "Soil_Dirt"
    },
    {
      "x": -6,
      "y": 32,
      "z": 1,
      "name": "Rock_Stone"
    },
    {
      "x": -6,
      "y": 33,
      "z": 1,
      "name": "Rock_Stone_Mossy"
    },
    {
      "x": -6,
      "y": 34,
      "z": 1,
      "name": "Rock_Stone_Mossy"
    },
    {
      "x": -6,
      "y": 35,
      "z": 1,
      "name": "Rock_Stone_Mossy"
    },
    {
      "x": -6,
      "y": 36,
      "z": 1,
      "name": "Soil_Dirt"
    },
    {
      "x": -6,
      "y": 37,
      "z": 1,
      "name": "Soil_Grass"
    },
    {
      "x": -6,
      "y": 45,
      "z": 1,
      "name": "Wood_Birch_Branch_Long",
      "rotation": 4
    },
    {
      "x": -6,
      "y": 50,
      "z": 1,
      "name": "Wood_Birch_Branch_Corner",
      "rotation": 2
    },
    {
      "x": -6,
      "y": 51,
      "z": 1,
      "name": "Wood_Birch_Branch_Long"
    },
    {
      "x": -6,
      "y": 52,
      "z": 1,
      "name": "Wood_Birch_Branch_Long"
    },
    {
      "x": -6,
      "y": 53,
      "z": 1,
      "name": "Wood_Birch_Branch_Long"
    },
    {
      "x": -6,
      "y": 54,
      "z": 1,
      "name": "Wood_Birch_Branch_Long"
    },
    {
      "x": -6,
      "y": 55,
      "z": 1,
      "name": "Wood_Birch_Branch_Long"
    },
    {
      "x": -6,
      "y": 56,
      "z": 1,
      "name": "Wood_Birch_Branch_Long"
    },
    {
      "x": -6,
      "y": 57,
      "z": 1,
      "name": "Plant_Leaves_Birch"
    },
    {
      "x": -6,
      "y": 58,
      "z": 1,
      "name": "Plant_Leaves_Birch"
    },
    {
      "x": -6,
      "y": 59,
      "z": 1,
      "name": "Plant_Leaves_Birch"
    },
    {
      "x": -6,
      "y": 19,
      "z": 2,
      "name": "Rock_Stone"
    },
    {
      "x": -6,
      "y": 20,
      "z": 2,
      "name": "Rock_Stone"
    },
    {
      "x": -6,
      "y": 21,
      "z": 2,
      "name": "Rock_Stone"
    },
    {
      "x": -6,
      "y": 22,
      "z": 2,
      "name": "Rock_Stone"
    },
    {
      "x": -6,
      "y": 23,
      "z": 2,
      "name": "Rock_Stone"
    },
    {
      "x": -6,
      "y": 24,
      "z": 2,
      "name": "Rock_Stone"
    },
    {
      "x": -6,
      "y": 25,
      "z": 2,
      "name": "Rock_Stone"
    },
    {
      "x": -6,
      "y": 26,
      "z": 2,
      "name": "Rock_Stone"
    },
    {
      "x": -6,
      "y": 27,
      "z": 2,
      "name": "Rock_Stone"
    },
    {
      "x": -6,
      "y": 28,
      "z": 2,
      "name": "Rock_Stone"
    },
    {
      "x": -6,
      "y": 29,
      "z": 2,
      "name": "Soil_Dirt"
    },
    {
      "x": -6,
      "y": 30,
      "z": 2,
      "name": "Rock_Stone"
    },
    {
      "x": -6,
      "y": 31,
      "z": 2,
      "name": "Soil_Dirt"
    },
    {
      "x": -6,
      "y": 32,
      "z": 2,
      "name": "Wood_Birch_Trunk"
    },
    {
      "x": -6,
      "y": 33,
      "z": 2,
      "name": "Wood_Birch_Trunk"
    },
    {
      "x": -6,
      "y": 34,
      "z": 2,
      "name": "Wood_Birch_Trunk"
    },
    {
      "x": -6,
      "y": 35,
      "z": 2,
      "name": "Wood_Birch_Trunk"
    },
    {
      "x": -6,
      "y": 36,
      "z": 2,
      "name": "Wood_Birch_Trunk"
    },
    {
      "x": -6,
      "y": 37,
      "z": 2,
      "name": "Wood_Birch_Trunk"
    },
    {
      "x": -6,
      "y": 38,
      "z": 2,
      "name": "Wood_Birch_Trunk"
    },
    {
      "x": -6,
      "y": 39,
      "z": 2,
      "name": "Wood_Birch_Trunk_Full"
    },
    {
      "x": -6,
      "y": 45,
      "z": 2,
      "name": "Wood_Birch_Branch_Long",
      "rotation": 4
    },
    {
      "x": -6,
      "y": 48,
      "z": 2,
      "name": "Wood_Birch_Trunk_Full"
    },
    {
      "x": -6,
      "y": 49,
      "z": 2,
      "name": "Wood_Birch_Trunk"
    },
    {
      "x": -6,
      "y": 50,
      "z": 2,
      "name": "Wood_Birch_Trunk"
    },
    {
      "x": -6,
      "y": 51,
      "z": 2,
      "name": "Wood_Birch_Trunk"
    },
    {
      "x": -6,
      "y": 52,
      "z": 2,
      "name": "Wood_Birch_Trunk"
    },
    {
      "x": -6,
      "y": 53,
      "z": 2,
      "name": "Wood_Birch_Trunk_Full"
    },
    {
      "x": -6,
      "y": 54,
      "z": 2,
      "name": "Wood_Birch_Branch_Long"
    },
    {
      "x": -6,
      "y": 55,
      "z": 2,
      "name": "Wood_Birch_Branch_Long"
    },
    {
      "x": -6,
      "y": 56,
      "z": 2,
      "name": "Wood_Birch_Branch_Long"
    },
    {
      "x": -6,
      "y": 57,
      "z": 2,
      "name": "Wood_Birch_Branch_Long"
    },
    {
      "x": -6,
      "y": 58,
      "z": 2,
      "name": "Wood_Birch_Branch_Long"
    },
    {
      "x": -6,
      "y": 59,
      "z": 2,
      "name": "Plant_Leaves_Birch"
    },
    {
      "x": -6,
      "y": 19,
      "z": 3,
      "name": "Rock_Stone"
    },
    {
      "x": -6,
      "y": 20,
      "z": 3,
      "name": "Rock_Stone"
    },
    {
      "x": -6,
      "y": 21,
      "z": 3,
      "name": "Rock_Stone"
    },
    {
      "x": -6,
      "y": 22,
      "z": 3,
      "name": "Rock_Stone"
    },
    {
      "x": -6,
      "y": 23,
      "z": 3,
      "name": "Rock_Stone"
    },
    {
      "x": -6,
      "y": 24,
      "z": 3,
      "name": "Rock_Stone"
    },
    {
      "x": -6,
      "y": 25,
      "z": 3,
      "name": "Rock_Stone"
    },
    {
      "x": -6,
      "y": 26,
      "z": 3,
      "name": "Rock_Stone"
    },
    {
      "x": -6,
      "y": 27,
      "z": 3,
      "name": "Rock_Stone"
    },
    {
      "x": -6,
      "y": 28,
      "z": 3,
      "name": "Rock_Stone"
    },
    {
      "x": -6,
      "y": 29,
      "z": 3,
      "name": "Soil_Dirt"
    },
    {
      "x": -6,
      "y": 30,
      "z": 3,
      "name": "Rock_Stone"
    },
    {
      "x": -6,
      "y": 31,
      "z": 3,
      "name": "Wood_Birch_Trunk"
    },
    {
      "x": -6,
      "y": 32,
      "z": 3,
      "name": "Wood_Birch_Trunk"
    },
    {
      "x": -6,
      "y": 33,
      "z": 3,
      "name": "Wood_Birch_Trunk"
    },
    {
      "x": -6,
      "y": 34,
      "z": 3,
      "name": "Wood_Birch_Trunk"
    },
    {
      "x": -6,
      "y": 35,
      "z": 3,
      "name": "Wood_Birch_Trunk"
    },
    {
      "x": -6,
      "y": 36,
      "z": 3,
      "name": "Wood_Birch_Trunk"
    },
    {
      "x": -6,
      "y": 37,
      "z": 3,
      "name": "Wood_Birch_Trunk"
    },
    {
      "x": -6,
      "y": 38,
      "z": 3,
      "name": "Wood_Birch_Trunk"
    },
    {
      "x": -6,
      "y": 39,
      "z": 3,
      "name": "Wood_Birch_Trunk"
    },
    {
      "x": -6,
      "y": 40,
      "z": 3,
      "name": "Wood_Birch_Trunk"
    },
    {
      "x": -6,
      "y": 41,
      "z": 3,
      "name": "Wood_Birch_Trunk"
    },
    {
      "x": -6,
      "y": 42,
      "z": 3,
      "name": "Wood_Birch_Trunk"
    },
    {
      "x": -6,
      "y": 43,
      "z": 3,
      "name": "Wood_Birch_Trunk"
    },
    {
      "x": -6,
      "y": 44,
      "z": 3,
      "name": "Wood_Birch_Trunk"
    },
    {
      "x": -6,
      "y": 45,
      "z": 3,
      "name": "Wood_Birch_Trunk"
    },
    {
      "x": -6,
      "y": 46,
      "z": 3,
      "name": "Wood_Birch_Trunk"
    },
    {
      "x": -6,
      "y": 47,
      "z": 3,
      "name": "Wood_Birch_Trunk"
    },
    {
      "x": -6,
      "y": 48,
      "z": 3,
      "name": "Wood_Birch_Trunk_Full"
    },
    {
      "x": -6,
      "y": 49,
      "z": 3,
      "name": "Wood_Birch_Branch_Long"
    },
    {
      "x": -6,
      "y": 50,
      "z": 3,
      "name": "Wood_Birch_Branch_Long"
    },
    {
      "x": -6,
      "y": 51,
      "z": 3,
      "name": "Wood_Birch_Branch_Long"
    },
    {
      "x": -6,
      "y": 52,
      "z": 3,
      "name": "Wood_Birch_Branch_Long"
    },
    {
      "x": -6,
      "y": 53,
      "z": 3,
      "name": "Wood_Birch_Branch_Long"
    },
    {
      "x": -6,
      "y": 54,
      "z": 3,
      "name": "Wood_Birch_Branch_Long"
    },
    {
      "x": -6,
      "y": 57,
      "z": 3,
      "name": "Plant_Leaves_Birch"
    },
    {
      "x": -6,
      "y": 59,
      "z": 3,
      "name": "Plant_Leaves_Birch"
    },
    {
      "x": -6,
      "y": 20,
      "z": 4,
      "name": "Rock_Stone"
    },
    {
      "x": -6,
      "y": 21,
      "z": 4,
      "name": "Rock_Stone"
    },
    {
      "x": -6,
      "y": 22,
      "z": 4,
      "name": "Rock_Stone"
    },
    {
      "x": -6,
      "y": 23,
      "z": 4,
      "name": "Rock_Stone"
    },
    {
      "x": -6,
      "y": 24,
      "z": 4,
      "name": "Rock_Stone"
    },
    {
      "x": -6,
      "y": 25,
      "z": 4,
      "name": "Rock_Stone"
    },
    {
      "x": -6,
      "y": 26,
      "z": 4,
      "name": "Rock_Stone"
    },
    {
      "x": -6,
      "y": 27,
      "z": 4,
      "name": "Rock_Stone"
    },
    {
      "x": -6,
      "y": 28,
      "z": 4,
      "name": "Soil_Dirt"
    },
    {
      "x": -6,
      "y": 29,
      "z": 4,
      "name": "Soil_Dirt"
    },
    {
      "x": -6,
      "y": 30,
      "z": 4,
      "name": "Soil_Dirt"
    },
    {
      "x": -6,
      "y": 31,
      "z": 4,
      "name": "Rock_Stone"
    },
    {
      "x": -6,
      "y": 32,
      "z": 4,
      "name": "Rock_Stone_Mossy"
    },
    {
      "x": -6,
      "y": 33,
      "z": 4,
      "name": "Rock_Stone_Mossy"
    },
    {
      "x": -6,
      "y": 34,
      "z": 4,
      "name": "Rock_Stone_Mossy"
    },
    {
      "x": -6,
      "y": 43,
      "z": 4,
      "name": "Wood_Birch_Branch_Long",
      "rotation": 4
    },
    {
      "x": -6,
      "y": 50,
      "z": 4,
      "name": "Plant_Leaves_Birch"
    },
    {
      "x": -6,
      "y": 51,
      "z": 4,
      "name": "Plant_Leaves_Birch"
    },
    {
      "x": -6,
      "y": 54,
      "z": 4,
      "name": "Plant_Leaves_Birch"
    },
    {
      "x": -6,
      "y": 55,
      "z": 4,
      "name": "Plant_Leaves_Birch"
    },
    {
      "x": -6,
      "y": 56,
      "z": 4,
      "name": "Plant_Leaves_Birch"
    },
    {
      "x": -6,
      "y": 57,
      "z": 4,
      "name": "Plant_Leaves_Birch"
    },
    {
      "x": -6,
      "y": 20,
      "z": 5,
      "name": "Rock_Stone"
    },
    {
      "x": -6,
      "y": 21,
      "z": 5,
      "name": "Rock_Stone"
    },
    {
      "x": -6,
      "y": 22,
      "z": 5,
      "name": "Rock_Stone"
    },
    {
      "x": -6,
      "y": 23,
      "z": 5,
      "name": "Rock_Stone"
    },
    {
      "x": -6,
      "y": 24,
      "z": 5,
      "name": "Rock_Stone"
    },
    {
      "x": -6,
      "y": 25,
      "z": 5,
      "name": "Rock_Stone"
    },
    {
      "x": -6,
      "y": 26,
      "z": 5,
      "name": "Rock_Stone"
    },
    {
      "x": -6,
      "y": 27,
      "z": 5,
      "name": "Rock_Stone"
    },
    {
      "x": -6,
      "y": 28,
      "z": 5,
      "name": "Soil_Dirt"
    },
    {
      "x": -6,
      "y": 29,
      "z": 5,
      "name": "Soil_Dirt"
    },
    {
      "x": -6,
      "y": 30,
      "z": 5,
      "name": "Soil_Dirt"
    },
    {
      "x": -6,
      "y": 31,
      "z": 5,
      "name": "Soil_Grass"
    },
    {
      "x": -6,
      "y": 32,
      "z": 5,
      "name": "Plant_Grass_Sharp"
    },
    {
      "x": -6,
      "y": 40,
      "z": 5,
      "name": "Plant_Leaves_Birch"
    },
    {
      "x": -6,
      "y": 41,
      "z": 5,
      "name": "Plant_Leaves_Birch"
    },
    {
      "x": -6,
      "y": 43,
      "z": 5,
      "name": "Wood_Birch_Branch_Long",
      "rotation": 4
    },
    {
      "x": -6,
      "y": 44,
      "z": 5,
      "name": "Plant_Leaves_Birch"
    },
    {
      "x": -6,
      "y": 45,
      "z": 5,
      "name": "Plant_Leaves_Birch"
    },
    {
      "x": -6,
      "y": 46,
      "z": 5,
      "name": "Plant_Leaves_Birch"
    },
    {
      "x": -6,
      "y": 47,
      "z": 5,
      "name": "Plant_Leaves_Birch"
    },
    {
      "x": -6,
      "y": 48,
      "z": 5,
      "name": "Plant_Leaves_Birch"
    },
    {
      "x": -6,
      "y": 49,
      "z": 5,
      "name": "Plant_Leaves_Birch"
    },
    {
      "x": -6,
      "y": 50,
      "z": 5,
      "name": "Plant_Leaves_Birch"
    },
    {
      "x": -6,
      "y": 51,
      "z": 5,
      "name": "Plant_Leaves_Birch"
    },
    {
      "x": -6,
      "y": 52,
      "z": 5,
      "name": "Plant_Leaves_Birch"
    },
    {
      "x": -6,
      "y": 53,
      "z": 5,
      "name": "Plant_Leaves_Birch"
    },
    {
      "x": -6,
      "y": 55,
      "z": 5,
      "name": "Plant_Leaves_Birch"
    },
    {
      "x": -6,
      "y": 21,
      "z": 6,
      "name": "Rock_Stone"
    },
    {
      "x": -6,
      "y": 22,
      "z": 6,
      "name": "Rock_Stone"
    },
    {
      "x": -6,
      "y": 23,
      "z": 6,
      "name": "Rock_Stone"
    },
    {
      "x": -6,
      "y": 24,
      "z": 6,
      "name": "Rock_Stone"
    },
    {
      "x": -6,
      "y": 25,
      "z": 6,
      "name": "Rock_Stone"
    },
    {
      "x": -6,
      "y": 26,
      "z": 6,
      "name": "Rock_Stone"
    },
    {
      "x": -6,
      "y": 41,
      "z": 6,
      "name": "Plant_Leaves_Birch"
    },
    {
      "x": -6,
      "y": 42,
      "z": 6,
      "name": "Plant_Leaves_Birch"
    },
    {
      "x": -6,
      "y": 43,
      "z": 6,
      "name": "Plant_Leaves_Birch"
    },
    {
      "x": -6,
      "y": 44,
      "z": 6,
      "name": "Plant_Leaves_Birch"
    },
    {
      "x": -6,
      "y": 45,
      "z": 6,
      "name": "Plant_Leaves_Birch"
    },
    {
      "x": -6,
      "y": 46,
      "z": 6,
      "name": "Plant_Leaves_Birch"
    },
    {
      "x": -6,
      "y": 50,
      "z": 6,
      "name": "Plant_Leaves_Birch"
    },
    {
      "x": -6,
      "y": 44,
      "z": 7,
      "name": "Plant_Leaves_Birch"
    },
    {
      "x": -5,
      "y": 21,
      "z": -4,
      "name": "Rock_Stone"
    },
    {
      "x": -5,
      "y": 22,
      "z": -4,
      "name": "Rock_Stone"
    },
    {
      "x": -5,
      "y": 23,
      "z": -4,
      "name": "Rock_Stone"
    },
    {
      "x": -5,
      "y": 24,
      "z": -4,
      "name": "Soil_Dirt"
    },
    {
      "x": -5,
      "y": 25,
      "z": -4,
      "name": "Soil_Dirt"
    },
    {
      "x": -5,
      "y": 26,
      "z": -4,
      "name": "Soil_Grass"
    },
    {
      "x": -5,
      "y": 20,
      "z": -3,
      "name": "Rock_Stone"
    },
    {
      "x": -5,
      "y": 21,
      "z": -3,
      "name": "Rock_Stone"
    },
    {
      "x": -5,
      "y": 22,
      "z": -3,
      "name": "Rock_Stone"
    },
    {
      "x": -5,
      "y": 23,
      "z": -3,
      "name": "Rock_Stone"
    },
    {
      "x": -5,
      "y": 24,
      "z": -3,
      "name": "Soil_Dirt"
    },
    {
      "x": -5,
      "y": 25,
      "z": -3,
      "name": "Soil_Dirt"
    },
    {
      "x": -5,
      "y": 26,
      "z": -3,
      "name": "Soil_Grass"
    },
    {
      "x": -5,
      "y": 27,
      "z": -3,
      "name": "Plant_Grass_Sharp"
    },
    {
      "x": -5,
      "y": 18,
      "z": -2,
      "name": "Rock_Stone_Mossy"
    },
    {
      "x": -5,
      "y": 19,
      "z": -2,
      "name": "Rock_Stone_Mossy"
    },
    {
      "x": -5,
      "y": 20,
      "z": -2,
      "name": "Rock_Stone"
    },
    {
      "x": -5,
      "y": 21,
      "z": -2,
      "name": "Rock_Stone"
    },
    {
      "x": -5,
      "y": 22,
      "z": -2,
      "name": "Rock_Stone"
    },
    {
      "x": -5,
      "y": 23,
      "z": -2,
      "name": "Rock_Stone"
    },
    {
      "x": -5,
      "y": 24,
      "z": -2,
      "name": "Rock_Stone"
    },
    {
      "x": -5,
      "y": 25,
      "z": -2,
      "name": "Soil_Dirt"
    },
    {
      "x": -5,
      "y": 26,
      "z": -2,
      "name": "Rock_Stone"
    },
    {
      "x": -5,
      "y": 27,
      "z": -2,
      "name": "Rock_Stone"
    },
    {
      "x": -5,
      "y": 28,
      "z": -2,
      "name": "Rock_Stone"
    },
    {
      "x": -5,
      "y": 29,
      "z": -2,
      "name": "Rock_Stone"
    },
    {
      "x": -5,
      "y": 30,
      "z": -2,
      "name": "Rock_Stone"
    },
    {
      "x": -5,
      "y": 31,
      "z": -2,
      "name": "Rock_Stone"
    },
    {
      "x": -5,
      "y": 32,
      "z": -2,
      "name": "Rock_Stone"
    },
    {
      "x": -5,
      "y": 33,
      "z": -2,
      "name": "Rock_Stone_Mossy"
    },
    {
      "x": -5,
      "y": 34,
      "z": -2,
      "name": "Rock_Stone_Mossy"
    },
    {
      "x": -5,
      "y": 35,
      "z": -2,
      "name": "Soil_Dirt"
    },
    {
      "x": -5,
      "y": 36,
      "z": -2,
      "name": "Soil_Dirt"
    },
    {
      "x": -5,
      "y": 44,
      "z": -2,
      "name": "Plant_Leaves_Birch"
    },
    {
      "x": -5,
      "y": 50,
      "z": -2,
      "name": "Plant_Leaves_Birch"
    },
    {
      "x": -5,
      "y": 18,
      "z": -1,
      "name": "Rock_Stone_Mossy"
    },
    {
      "x": -5,
      "y": 19,
      "z": -1,
      "name": "Rock_Stone_Mossy"
    },
    {
      "x": -5,
      "y": 20,
      "z": -1,
      "name": "Rock_Stone"
    },
    {
      "x": -5,
      "y": 21,
      "z": -1,
      "name": "Rock_Stone"
    },
    {
      "x": -5,
      "y": 22,
      "z": -1,
      "name": "Rock_Stone"
    },
    {
      "x": -5,
      "y": 23,
      "z": -1,
      "name": "Rock_Stone"
    },
    {
      "x": -5,
      "y": 24,
      "z": -1,
      "name": "Rock_Stone"
    },
    {
      "x": -5,
      "y": 25,
      "z": -1,
      "name": "Rock_Stone"
    },
    {
      "x": -5,
      "y": 26,
      "z": -1,
      "name": "Rock_Stone"
    },
    {
      "x": -5,
      "y": 27,
      "z": -1,
      "name": "Rock_Stone"
    },
    {
      "x": -5,
      "y": 28,
      "z": -1,
      "name": "Rock_Stone"
    },
    {
      "x": -5,
      "y": 29,
      "z": -1,
      "name": "Rock_Stone"
    },
    {
      "x": -5,
      "y": 30,
      "z": -1,
      "name": "Rock_Stone"
    },
    {
      "x": -5,
      "y": 31,
      "z": -1,
      "name": "Rock_Stone"
    },
    {
      "x": -5,
      "y": 32,
      "z": -1,
      "name": "Rock_Stone"
    },
    {
      "x": -5,
      "y": 33,
      "z": -1,
      "name": "Rock_Stone"
    },
    {
      "x": -5,
      "y": 34,
      "z": -1,
      "name": "Rock_Stone_Mossy"
    },
    {
      "x": -5,
      "y": 35,
      "z": -1,
      "name": "Soil_Dirt"
    },
    {
      "x": -5,
      "y": 36,
      "z": -1,
      "name": "Soil_Dirt"
    },
    {
      "x": -5,
      "y": 37,
      "z": -1,
      "name": "Soil_Dirt"
    },
    {
      "x": -5,
      "y": 38,
      "z": -1,
      "name": "Soil_Dirt"
    },
    {
      "x": -5,
      "y": 39,
      "z": -1,
      "name": "Soil_Grass"
    },
    {
      "x": -5,
      "y": 43,
      "z": -1,
      "name": "Plant_Leaves_Birch"
    },
    {
      "x": -5,
      "y": 44,
      "z": -1,
      "name": "Plant_Leaves_Birch"
    },
    {
      "x": -5,
      "y": 45,
      "z": -1,
      "name": "Plant_Leaves_Birch"
    },
    {
      "x": -5,
      "y": 48,
      "z": -1,
      "name": "Plant_Leaves_Birch"
    },
    {
      "x": -5,
      "y": 49,
      "z": -1,
      "name": "Plant_Leaves_Birch"
    },
    {
      "x": -5,
      "y": 50,
      "z": -1,
      "name": "Plant_Leaves_Birch"
    },
    {
      "x": -5,
      "y": 51,
      "z": -1,
      "name": "Plant_Leaves_Birch"
    },
    {
      "x": -5,
      "y": 52,
      "z": -1,
      "name": "Plant_Leaves_Birch"
    },
    {
      "x": -5,
      "y": 18,
      "z": 0,
      "name": "Rock_Stone"
    },
    {
      "x": -5,
      "y": 19,
      "z": 0,
      "name": "Rock_Stone"
    },
    {
      "x": -5,
      "y": 20,
      "z": 0,
      "name": "Rock_Stone"
    },
    {
      "x": -5,
      "y": 21,
      "z": 0,
      "name": "Rock_Stone"
    },
    {
      "x": -5,
      "y": 22,
      "z": 0,
      "name": "Rock_Stone"
    },
    {
      "x": -5,
      "y": 23,
      "z": 0,
      "name": "Rock_Stone"
    },
    {
      "x": -5,
      "y": 24,
      "z": 0,
      "name": "Rock_Stone"
    },
    {
      "x": -5,
      "y": 25,
      "z": 0,
      "name": "Rock_Stone"
    },
    {
      "x": -5,
      "y": 26,
      "z": 0,
      "name": "Rock_Stone"
    },
    {
      "x": -5,
      "y": 27,
      "z": 0,
      "name": "Rock_Stone"
    },
    {
      "x": -5,
      "y": 28,
      "z": 0,
      "name": "Rock_Stone"
    },
    {
      "x": -5,
      "y": 29,
      "z": 0,
      "name": "Rock_Stone"
    },
    {
      "x": -5,
      "y": 30,
      "z": 0,
      "name": "Rock_Stone"
    },
    {
      "x": -5,
      "y": 31,
      "z": 0,
      "name": "Rock_Stone"
    },
    {
      "x": -5,
      "y": 32,
      "z": 0,
      "name": "Rock_Stone"
    },
    {
      "x": -5,
      "y": 33,
      "z": 0,
      "name": "Rock_Stone_Mossy"
    },
    {
      "x": -5,
      "y": 34,
      "z": 0,
      "name": "Rock_Stone_Mossy"
    },
    {
      "x": -5,
      "y": 35,
      "z": 0,
      "name": "Soil_Dirt"
    },
    {
      "x": -5,
      "y": 36,
      "z": 0,
      "name": "Soil_Dirt"
    },
    {
      "x": -5,
      "y": 37,
      "z": 0,
      "name": "Soil_Dirt"
    },
    {
      "x": -5,
      "y": 38,
      "z": 0,
      "name": "Soil_Dirt"
    },
    {
      "x": -5,
      "y": 39,
      "z": 0,
      "name": "Soil_Grass"
    },
    {
      "x": -5,
      "y": 43,
      "z": 0,
      "name": "Plant_Leaves_Birch"
    },
    {
      "x": -5,
      "y": 53,
      "z": 0,
      "name": "Plant_Leaves_Birch"
    },
    {
      "x": -5,
      "y": 56,
      "z": 0,
      "name": "Plant_Leaves_Birch"
    },
    {
      "x": -5,
      "y": 18,
      "z": 1,
      "name": "Rock_Stone"
    },
    {
      "x": -5,
      "y": 19,
      "z": 1,
      "name": "Rock_Stone"
    },
    {
      "x": -5,
      "y": 20,
      "z": 1,
      "name": "Rock_Stone"
    },
    {
      "x": -5,
      "y": 21,
      "z": 1,
      "name": "Rock_Stone"
    },
    {
      "x": -5,
      "y": 22,
      "z": 1,
      "name": "Rock_Stone"
    },
    {
      "x": -5,
      "y": 23,
      "z": 1,
      "name": "Rock_Stone"
    },
    {
      "x": -5,
      "y": 24,
      "z": 1,
      "name": "Rock_Stone"
    },
    {
      "x": -5,
      "y": 25,
      "z": 1,
      "name": "Rock_Stone"
    },
    {
      "x": -5,
      "y": 26,
      "z": 1,
      "name": "Rock_Stone"
    },
    {
      "x": -5,
      "y": 27,
      "z": 1,
      "name": "Rock_Stone"
    },
    {
      "x": -5,
      "y": 28,
      "z": 1,
      "name": "Rock_Stone"
    },
    {
      "x": -5,
      "y": 29,
      "z": 1,
      "name": "Rock_Stone"
    },
    {
      "x": -5,
      "y": 30,
      "z": 1,
      "name": "Rock_Stone"
    },
    {
      "x": -5,
      "y": 31,
      "z": 1,
      "name": "Rock_Stone"
    },
    {
      "x": -5,
      "y": 32,
      "z": 1,
      "name": "Rock_Stone"
    },
    {
      "x": -5,
      "y": 33,
      "z": 1,
      "name": "Rock_Stone"
    },
    {
      "x": -5,
      "y": 34,
      "z": 1,
      "name": "Rock_Stone"
    },
    {
      "x": -5,
      "y": 35,
      "z": 1,
      "name": "Rock_Stone"
    },
    {
      "x": -5,
      "y": 36,
      "z": 1,
      "name": "Soil_Dirt"
    },
    {
      "x": -5,
      "y": 37,
      "z": 1,
      "name": "Soil_Grass"
    },
    {
      "x": -5,
      "y": 58,
      "z": 1,
      "name": "Plant_Leaves_Birch"
    },
    {
      "x": -5,
      "y": 18,
      "z": 2,
      "name": "Rock_Stone"
    },
    {
      "x": -5,
      "y": 19,
      "z": 2,
      "name": "Rock_Stone"
    },
    {
      "x": -5,
      "y": 20,
      "z": 2,
      "name": "Rock_Stone"
    },
    {
      "x": -5,
      "y": 21,
      "z": 2,
      "name": "Rock_Stone"
    },
    {
      "x": -5,
      "y": 22,
      "z": 2,
      "name": "Rock_Stone"
    },
    {
      "x": -5,
      "y": 23,
      "z": 2,
      "name": "Rock_Stone"
    },
    {
      "x": -5,
      "y": 24,
      "z": 2,
      "name": "Rock_Stone"
    },
    {
      "x": -5,
      "y": 25,
      "z": 2,
      "name": "Rock_Stone"
    },
    {
      "x": -5,
      "y": 26,
      "z": 2,
      "name": "Rock_Stone"
    },
    {
      "x": -5,
      "y": 27,
      "z": 2,
      "name": "Rock_Stone"
    },
    {
      "x": -5,
      "y": 28,
      "z": 2,
      "name": "Rock_Stone"
    },
    {
      "x": -5,
      "y": 29,
      "z": 2,
      "name": "Rock_Stone"
    },
    {
      "x": -5,
      "y": 30,
      "z": 2,
      "name": "Rock_Stone"
    },
    {
      "x": -5,
      "y": 31,
      "z": 2,
      "name": "Rock_Stone"
    },
    {
      "x": -5,
      "y": 32,
      "z": 2,
      "name": "Rock_Stone"
    },
    {
      "x": -5,
      "y": 33,
      "z": 2,
      "name": "Rock_Stone"
    },
    {
      "x": -5,
      "y": 34,
      "z": 2,
      "name": "Rock_Stone"
    },
    {
      "x": -5,
      "y": 35,
      "z": 2,
      "name": "Soil_Dirt"
    },
    {
      "x": -5,
      "y": 36,
      "z": 2,
      "name": "Soil_Dirt"
    },
    {
      "x": -5,
      "y": 37,
      "z": 2,
      "name": "Soil_Grass"
    },
    {
      "x": -5,
      "y": 50,
      "z": 2,
      "name": "Wood_Birch_Branch_Long",
      "rotation": 5
    },
    {
      "x": -5,
      "y": 58,
      "z": 2,
      "name": "Plant_Leaves_Birch"
    },
    {
      "x": -5,
      "y": 59,
      "z": 2,
      "name": "Plant_Leaves_Birch"
    },
    {
      "x": -5,
      "y": 18,
      "z": 3,
      "name": "Rock_Stone"
    },
    {
      "x": -5,
      "y": 19,
      "z": 3,
      "name": "Rock_Stone"
    },
    {
      "x": -5,
      "y": 20,
      "z": 3,
      "name": "Rock_Stone"
    },
    {
      "x": -5,
      "y": 21,
      "z": 3,
      "name": "Rock_Stone"
    },
    {
      "x": -5,
      "y": 22,
      "z": 3,
      "name": "Rock_Stone"
    },
    {
      "x": -5,
      "y": 23,
      "z": 3,
      "name": "Rock_Stone"
    },
    {
      "x": -5,
      "y": 24,
      "z": 3,
      "name": "Rock_Stone"
    },
    {
      "x": -5,
      "y": 25,
      "z": 3,
      "name": "Rock_Stone"
    },
    {
      "x": -5,
      "y": 26,
      "z": 3,
      "name": "Rock_Stone"
    },
    {
      "x": -5,
      "y": 27,
      "z": 3,
      "name": "Rock_Stone"
    },
    {
      "x": -5,
      "y": 28,
      "z": 3,
      "name": "Rock_Stone"
    },
    {
      "x": -5,
      "y": 29,
      "z": 3,
      "name": "Rock_Stone"
    },
    {
      "x": -5,
      "y": 30,
      "z": 3,
      "name": "Rock_Stone"
    },
    {
      "x": -5,
      "y": 31,
      "z": 3,
      "name": "Rock_Stone"
    },
    {
      "x": -5,
      "y": 32,
      "z": 3,
      "name": "Wood_Birch_Trunk"
    },
    {
      "x": -5,
      "y": 33,
      "z": 3,
      "name": "Wood_Birch_Trunk"
    },
    {
      "x": -5,
      "y": 34,
      "z": 3,
      "name": "Wood_Birch_Trunk"
    },
    {
      "x": -5,
      "y": 35,
      "z": 3,
      "name": "Wood_Birch_Trunk"
    },
    {
      "x": -5,
      "y": 36,
      "z": 3,
      "name": "Wood_Birch_Trunk"
    },
    {
      "x": -5,
      "y": 37,
      "z": 3,
      "name": "Wood_Birch_Trunk_Full"
    },
    {
      "x": -5,
      "y": 42,
      "z": 3,
      "name": "Wood_Birch_Branch_Long",
      "rotation": 5
    },
    {
      "x": -5,
      "y": 45,
      "z": 3,
      "name": "Wood_Birch_Branch_Corner",
      "rotation": 1
    },
    {
      "x": -5,
      "y": 46,
      "z": 3,
      "name": "Wood_Birch_Branch_Long"
    },
    {
      "x": -5,
      "y": 47,
      "z": 3,
      "name": "Wood_Birch_Branch_Long"
    },
    {
      "x": -5,
      "y": 48,
      "z": 3,
      "name": "Wood_Birch_Branch_Long"
    },
    {
      "x": -5,
      "y": 49,
      "z": 3,
      "name": "Wood_Birch_Branch_Long"
    },
    {
      "x": -5,
      "y": 50,
      "z": 3,
      "name": "Wood_Birch_Branch_Long"
    },
    {
      "x": -5,
      "y": 51,
      "z": 3,
      "name": "Wood_Birch_Branch_Long"
    },
    {
      "x": -5,
      "y": 57,
      "z": 3,
      "name": "Plant_Leaves_Birch"
    },
    {
      "x": -5,
      "y": 58,
      "z": 3,
      "name": "Plant_Leaves_Birch"
    },
    {
      "x": -5,
      "y": 18,
      "z": 4,
      "name": "Rock_Stone"
    },
    {
      "x": -5,
      "y": 19,
      "z": 4,
      "name": "Rock_Stone"
    },
    {
      "x": -5,
      "y": 20,
      "z": 4,
      "name": "Rock_Stone"
    },
    {
      "x": -5,
      "y": 21,
      "z": 4,
      "name": "Rock_Stone"
    },
    {
      "x": -5,
      "y": 22,
      "z": 4,
      "name": "Rock_Stone"
    },
    {
      "x": -5,
      "y": 23,
      "z": 4,
      "name": "Rock_Stone"
    },
    {
      "x": -5,
      "y": 24,
      "z": 4,
      "name": "Rock_Stone"
    },
    {
      "x": -5,
      "y": 25,
      "z": 4,
      "name": "Rock_Stone"
    },
    {
      "x": -5,
      "y": 26,
      "z": 4,
      "name": "Rock_Stone"
    },
    {
      "x": -5,
      "y": 27,
      "z": 4,
      "name": "Rock_Stone"
    },
    {
      "x": -5,
      "y": 28,
      "z": 4,
      "name": "Rock_Stone"
    },
    {
      "x": -5,
      "y": 29,
      "z": 4,
      "name": "Soil_Dirt"
    },
    {
      "x": -5,
      "y": 30,
      "z": 4,
      "name": "Rock_Stone"
    },
    {
      "x": -5,
      "y": 31,
      "z": 4,
      "name": "Soil_Dirt"
    },
    {
      "x": -5,
      "y": 32,
      "z": 4,
      "name": "Rock_Stone"
    },
    {
      "x": -5,
      "y": 33,
      "z": 4,
      "name": "Rock_Stone_Mossy"
    },
    {
      "x": -5,
      "y": 34,
      "z": 4,
      "name": "Soil_Dirt"
    },
    {
      "x": -5,
      "y": 35,
      "z": 4,
      "name": "Soil_Dirt"
    },
    {
      "x": -5,
      "y": 36,
      "z": 4,
      "name": "Soil_Dirt"
    },
    {
      "x": -5,
      "y": 37,
      "z": 4,
      "name": "Soil_Grass"
    },
    {
      "x": -5,
      "y": 54,
      "z": 4,
      "name": "Plant_Leaves_Birch"
    },
    {
      "x": -5,
      "y": 56,
      "z": 4,
      "name": "Plant_Leaves_Birch"
    },
    {
      "x": -5,
      "y": 20,
      "z": 5,
      "name": "Rock_Stone"
    },
    {
      "x": -5,
      "y": 21,
      "z": 5,
      "name": "Rock_Stone"
    },
    {
      "x": -5,
      "y": 22,
      "z": 5,
      "name": "Rock_Stone"
    },
    {
      "x": -5,
      "y": 23,
      "z": 5,
      "name": "Rock_Stone"
    },
    {
      "x": -5,
      "y": 24,
      "z": 5,
      "name": "Rock_Stone"
    },
    {
      "x": -5,
      "y": 25,
      "z": 5,
      "name": "Rock_Stone"
    },
    {
      "x": -5,
      "y": 26,
      "z": 5,
      "name": "Rock_Stone"
    },
    {
      "x": -5,
      "y": 27,
      "z": 5,
      "name": "Rock_Stone_Mossy"
    },
    {
      "x": -5,
      "y": 28,
      "z": 5,
      "name": "Rock_Stone"
    },
    {
      "x": -5,
      "y": 29,
      "z": 5,
      "name": "Soil_Dirt"
    },
    {
      "x": -5,
      "y": 30,
      "z": 5,
      "name": "Soil_Dirt"
    },
    {
      "x": -5,
      "y": 31,
      "z": 5,
      "name": "Soil_Dirt"
    },
    {
      "x": -5,
      "y": 32,
      "z": 5,
      "name": "Soil_Grass"
    },
    {
      "x": -5,
      "y": 46,
      "z": 5,
      "name": "Plant_Leaves_Birch"
    },
    {
      "x": -5,
      "y": 47,
      "z": 5,
      "name": "Plant_Leaves_Birch"
    },
    {
      "x": -5,
      "y": 48,
      "z": 5,
      "name": "Plant_Leaves_Birch"
    },
    {
      "x": -5,
      "y": 49,
      "z": 5,
      "name": "Plant_Leaves_Birch"
    },
    {
      "x": -5,
      "y": 50,
      "z": 5,
      "name": "Plant_Leaves_Birch"
    },
    {
      "x": -5,
      "y": 51,
      "z": 5,
      "name": "Plant_Leaves_Birch"
    },
    {
      "x": -5,
      "y": 52,
      "z": 5,
      "name": "Plant_Leaves_Birch"
    },
    {
      "x": -5,
      "y": 20,
      "z": 6,
      "name": "Rock_Stone"
    },
    {
      "x": -5,
      "y": 21,
      "z": 6,
      "name": "Rock_Stone"
    },
    {
      "x": -5,
      "y": 22,
      "z": 6,
      "name": "Rock_Stone"
    },
    {
      "x": -5,
      "y": 23,
      "z": 6,
      "name": "Rock_Stone"
    },
    {
      "x": -5,
      "y": 24,
      "z": 6,
      "name": "Rock_Stone"
    },
    {
      "x": -5,
      "y": 25,
      "z": 6,
      "name": "Rock_Stone"
    },
    {
      "x": -5,
      "y": 26,
      "z": 6,
      "name": "Rock_Stone_Mossy"
    },
    {
      "x": -5,
      "y": 27,
      "z": 6,
      "name": "Rock_Stone_Mossy"
    },
    {
      "x": -5,
      "y": 28,
      "z": 6,
      "name": "Rock_Stone_Mossy"
    },
    {
      "x": -5,
      "y": 29,
      "z": 6,
      "name": "Soil_Dirt"
    },
    {
      "x": -5,
      "y": 30,
      "z": 6,
      "name": "Soil_Grass"
    },
    {
      "x": -5,
      "y": 42,
      "z": 6,
      "name": "Plant_Leaves_Birch"
    },
    {
      "x": -5,
      "y": 43,
      "z": 6,
      "name": "Plant_Leaves_Birch"
    },
    {
      "x": -5,
      "y": 44,
      "z": 6,
      "name": "Plant_Leaves_Birch"
    },
    {
      "x": -5,
      "y": 48,
      "z": 6,
      "name": "Plant_Leaves_Birch"
    },
    {
      "x": -5,
      "y": 42,
      "z": 7,
      "name": "Plant_Leaves_Birch"
    },
    {
      "x": -4,
      "y": 20,
      "z": -4,
      "name": "Rock_Stone"
    },
    {
      "x": -4,
      "y": 21,
      "z": -4,
      "name": "Rock_Stone"
    },
    {
      "x": -4,
      "y": 22,
      "z": -4,
      "name": "Rock_Stone"
    },
    {
      "x": -4,
      "y": 23,
      "z": -4,
      "name": "Rock_Stone"
    },
    {
      "x": -4,
      "y": 24,
      "z": -4,
      "name": "Soil_Dirt"
    },
    {
      "x": -4,
      "y": 25,
      "z": -4,
      "name": "Soil_Dirt"
    },
    {
      "x": -4,
      "y": 26,
      "z": -4,
      "name": "Soil_Grass"
    },
    {
      "x": -4,
      "y": 20,
      "z": -3,
      "name": "Rock_Stone"
    },
    {
      "x": -4,
      "y": 21,
      "z": -3,
      "name": "Rock_Stone"
    },
    {
      "x": -4,
      "y": 22,
      "z": -3,
      "name": "Rock_Stone"
    },
    {
      "x": -4,
      "y": 23,
      "z": -3,
      "name": "Rock_Stone"
    },
    {
      "x": -4,
      "y": 24,
      "z": -3,
      "name": "Soil_Dirt"
    },
    {
      "x": -4,
      "y": 25,
      "z": -3,
      "name": "Soil_Dirt"
    },
    {
      "x": -4,
      "y": 26,
      "z": -3,
      "name": "Soil_Grass"
    },
    {
      "x": -4,
      "y": 27,
      "z": -3,
      "name": "Plant_Grass_Sharp"
    },
    {
      "x": -4,
      "y": 31,
      "z": -3,
      "name": "Rock_Stone"
    },
    {
      "x": -4,
      "y": 32,
      "z": -3,
      "name": "Rock_Stone"
    },
    {
      "x": -4,
      "y": 33,
      "z": -3,
      "name": "Rock_Stone"
    },
    {
      "x": -4,
      "y": 18,
      "z": -2,
      "name": "Rock_Stone_Mossy"
    },
    {
      "x": -4,
      "y": 19,
      "z": -2,
      "name": "Rock_Stone"
    },
    {
      "x": -4,
      "y": 20,
      "z": -2,
      "name": "Rock_Stone"
    },
    {
      "x": -4,
      "y": 21,
      "z": -2,
      "name": "Rock_Stone"
    },
    {
      "x": -4,
      "y": 22,
      "z": -2,
      "name": "Rock_Stone"
    },
    {
      "x": -4,
      "y": 23,
      "z": -2,
      "name": "Rock_Stone"
    },
    {
      "x": -4,
      "y": 24,
      "z": -2,
      "name": "Rock_Stone"
    },
    {
      "x": -4,
      "y": 25,
      "z": -2,
      "name": "Soil_Dirt"
    },
    {
      "x": -4,
      "y": 26,
      "z": -2,
      "name": "Soil_Dirt"
    },
    {
      "x": -4,
      "y": 27,
      "z": -2,
      "name": "Rock_Stone"
    },
    {
      "x": -4,
      "y": 28,
      "z": -2,
      "name": "Rock_Stone"
    },
    {
      "x": -4,
      "y": 29,
      "z": -2,
      "name": "Rock_Stone"
    },
    {
      "x": -4,
      "y": 30,
      "z": -2,
      "name": "Rock_Stone"
    },
    {
      "x": -4,
      "y": 31,
      "z": -2,
      "name": "Rock_Stone"
    },
    {
      "x": -4,
      "y": 32,
      "z": -2,
      "name": "Rock_Stone"
    },
    {
      "x": -4,
      "y": 33,
      "z": -2,
      "name": "Rock_Stone"
    },
    {
      "x": -4,
      "y": 34,
      "z": -2,
      "name": "Soil_Dirt"
    },
    {
      "x": -4,
      "y": 35,
      "z": -2,
      "name": "Soil_Dirt"
    },
    {
      "x": -4,
      "y": 36,
      "z": -2,
      "name": "Soil_Dirt"
    },
    {
      "x": -4,
      "y": 37,
      "z": -2,
      "name": "Soil_Dirt"
    },
    {
      "x": -4,
      "y": 38,
      "z": -2,
      "name": "Soil_Dirt"
    },
    {
      "x": -4,
      "y": 39,
      "z": -2,
      "name": "Soil_Grass"
    },
    {
      "x": -4,
      "y": 48,
      "z": -2,
      "name": "Plant_Leaves_Birch"
    },
    {
      "x": -4,
      "y": 18,
      "z": -1,
      "name": "Rock_Stone"
    },
    {
      "x": -4,
      "y": 19,
      "z": -1,
      "name": "Rock_Stone"
    },
    {
      "x": -4,
      "y": 20,
      "z": -1,
      "name": "Rock_Stone"
    },
    {
      "x": -4,
      "y": 21,
      "z": -1,
      "name": "Rock_Stone"
    },
    {
      "x": -4,
      "y": 22,
      "z": -1,
      "name": "Rock_Stone"
    },
    {
      "x": -4,
      "y": 23,
      "z": -1,
      "name": "Rock_Stone"
    },
    {
      "x": -4,
      "y": 24,
      "z": -1,
      "name": "Rock_Stone"
    },
    {
      "x": -4,
      "y": 25,
      "z": -1,
      "name": "Rock_Stone"
    },
    {
      "x": -4,
      "y": 26,
      "z": -1,
      "name": "Rock_Stone"
    },
    {
      "x": -4,
      "y": 27,
      "z": -1,
      "name": "Rock_Stone"
    },
    {
      "x": -4,
      "y": 28,
      "z": -1,
      "name": "Rock_Stone"
    },
    {
      "x": -4,
      "y": 29,
      "z": -1,
      "name": "Rock_Stone"
    },
    {
      "x": -4,
      "y": 30,
      "z": -1,
      "name": "Rock_Stone"
    },
    {
      "x": -4,
      "y": 31,
      "z": -1,
      "name": "Rock_Stone"
    },
    {
      "x": -4,
      "y": 32,
      "z": -1,
      "name": "Rock_Stone"
    },
    {
      "x": -4,
      "y": 33,
      "z": -1,
      "name": "Rock_Stone"
    },
    {
      "x": -4,
      "y": 34,
      "z": -1,
      "name": "Rock_Stone"
    },
    {
      "x": -4,
      "y": 35,
      "z": -1,
      "name": "Soil_Dirt"
    },
    {
      "x": -4,
      "y": 36,
      "z": -1,
      "name": "Soil_Dirt"
    },
    {
      "x": -4,
      "y": 37,
      "z": -1,
      "name": "Soil_Dirt"
    },
    {
      "x": -4,
      "y": 38,
      "z": -1,
      "name": "Soil_Dirt"
    },
    {
      "x": -4,
      "y": 39,
      "z": -1,
      "name": "Soil_Grass"
    },
    {
      "x": -4,
      "y": 48,
      "z": -1,
      "name": "Plant_Leaves_Birch"
    },
    {
      "x": -4,
      "y": 50,
      "z": -1,
      "name": "Plant_Leaves_Birch"
    },
    {
      "x": -4,
      "y": 51,
      "z": -1,
      "name": "Plant_Leaves_Birch"
    },
    {
      "x": -4,
      "y": 52,
      "z": -1,
      "name": "Plant_Leaves_Birch"
    },
    {
      "x": -4,
      "y": 18,
      "z": 0,
      "name": "Rock_Stone"
    },
    {
      "x": -4,
      "y": 19,
      "z": 0,
      "name": "Rock_Stone"
    },
    {
      "x": -4,
      "y": 20,
      "z": 0,
      "name": "Rock_Stone"
    },
    {
      "x": -4,
      "y": 21,
      "z": 0,
      "name": "Rock_Stone"
    },
    {
      "x": -4,
      "y": 22,
      "z": 0,
      "name": "Rock_Stone"
    },
    {
      "x": -4,
      "y": 23,
      "z": 0,
      "name": "Rock_Stone"
    },
    {
      "x": -4,
      "y": 24,
      "z": 0,
      "name": "Rock_Stone"
    },
    {
      "x": -4,
      "y": 25,
      "z": 0,
      "name": "Rock_Stone"
    },
    {
      "x": -4,
      "y": 26,
      "z": 0,
      "name": "Rock_Stone"
    },
    {
      "x": -4,
      "y": 27,
      "z": 0,
      "name": "Rock_Stone"
    },
    {
      "x": -4,
      "y": 28,
      "z": 0,
      "name": "Rock_Stone"
    },
    {
      "x": -4,
      "y": 29,
      "z": 0,
      "name": "Rock_Stone"
    },
    {
      "x": -4,
      "y": 30,
      "z": 0,
      "name": "Rock_Stone"
    },
    {
      "x": -4,
      "y": 31,
      "z": 0,
      "name": "Rock_Stone"
    },
    {
      "x": -4,
      "y": 32,
      "z": 0,
      "name": "Rock_Stone"
    },
    {
      "x": -4,
      "y": 33,
      "z": 0,
      "name": "Rock_Stone"
    },
    {
      "x": -4,
      "y": 34,
      "z": 0,
      "name": "Rock_Stone"
    },
    {
      "x": -4,
      "y": 35,
      "z": 0,
      "name": "Soil_Dirt"
    },
    {
      "x": -4,
      "y": 36,
      "z": 0,
      "name": "Soil_Dirt"
    },
    {
      "x": -4,
      "y": 37,
      "z": 0,
      "name": "Soil_Dirt"
    },
    {
      "x": -4,
      "y": 38,
      "z": 0,
      "name": "Soil_Dirt"
    },
    {
      "x": -4,
      "y": 39,
      "z": 0,
      "name": "Soil_Grass"
    },
    {
      "x": -4,
      "y": 43,
      "z": 0,
      "name": "Plant_Leaves_Birch"
    },
    {
      "x": -4,
      "y": 44,
      "z": 0,
      "name": "Plant_Leaves_Birch"
    },
    {
      "x": -4,
      "y": 45,
      "z": 0,
      "name": "Plant_Leaves_Birch"
    },
    {
      "x": -4,
      "y": 46,
      "z": 0,
      "name": "Plant_Leaves_Birch"
    },
    {
      "x": -4,
      "y": 47,
      "z": 0,
      "name": "Plant_Leaves_Birch"
    },
    {
      "x": -4,
      "y": 48,
      "z": 0,
      "name": "Plant_Leaves_Birch"
    },
    {
      "x": -4,
      "y": 49,
      "z": 0,
      "name": "Plant_Leaves_Birch"
    },
    {
      "x": -4,
      "y": 50,
      "z": 0,
      "name": "Plant_Leaves_Birch"
    },
    {
      "x": -4,
      "y": 51,
      "z": 0,
      "name": "Plant_Leaves_Birch"
    },
    {
      "x": -4,
      "y": 53,
      "z": 0,
      "name": "Plant_Leaves_Birch"
    },
    {
      "x": -4,
      "y": 54,
      "z": 0,
      "name": "Plant_Leaves_Birch"
    },
    {
      "x": -4,
      "y": 55,
      "z": 0,
      "name": "Plant_Leaves_Birch"
    },
    {
      "x": -4,
      "y": 56,
      "z": 0,
      "name": "Plant_Leaves_Birch"
    },
    {
      "x": -4,
      "y": 18,
      "z": 1,
      "name": "Rock_Stone"
    },
    {
      "x": -4,
      "y": 19,
      "z": 1,
      "name": "Rock_Stone"
    },
    {
      "x": -4,
      "y": 20,
      "z": 1,
      "name": "Rock_Stone"
    },
    {
      "x": -4,
      "y": 21,
      "z": 1,
      "name": "Rock_Stone"
    },
    {
      "x": -4,
      "y": 22,
      "z": 1,
      "name": "Rock_Stone"
    },
    {
      "x": -4,
      "y": 23,
      "z": 1,
      "name": "Rock_Stone"
    },
    {
      "x": -4,
      "y": 24,
      "z": 1,
      "name": "Rock_Stone"
    },
    {
      "x": -4,
      "y": 25,
      "z": 1,
      "name": "Rock_Stone"
    },
    {
      "x": -4,
      "y": 26,
      "z": 1,
      "name": "Rock_Stone"
    },
    {
      "x": -4,
      "y": 27,
      "z": 1,
      "name": "Rock_Stone"
    },
    {
      "x": -4,
      "y": 28,
      "z": 1,
      "name": "Rock_Stone"
    },
    {
      "x": -4,
      "y": 29,
      "z": 1,
      "name": "Rock_Stone"
    },
    {
      "x": -4,
      "y": 30,
      "z": 1,
      "name": "Rock_Stone"
    },
    {
      "x": -4,
      "y": 31,
      "z": 1,
      "name": "Rock_Stone"
    },
    {
      "x": -4,
      "y": 32,
      "z": 1,
      "name": "Rock_Stone"
    },
    {
      "x": -4,
      "y": 33,
      "z": 1,
      "name": "Rock_Stone"
    },
    {
      "x": -4,
      "y": 34,
      "z": 1,
      "name": "Rock_Stone"
    },
    {
      "x": -4,
      "y": 35,
      "z": 1,
      "name": "Rock_Stone"
    },
    {
      "x": -4,
      "y": 36,
      "z": 1,
      "name": "Soil_Dirt"
    },
    {
      "x": -4,
      "y": 37,
      "z": 1,
      "name": "Soil_Dirt"
    },
    {
      "x": -4,
      "y": 38,
      "z": 1,
      "name": "Soil_Dirt"
    },
    {
      "x": -4,
      "y": 39,
      "z": 1,
      "name": "Soil_Grass"
    },
    {
      "x": -4,
      "y": 53,
      "z": 1,
      "name": "Plant_Leaves_Birch"
    },
    {
      "x": -4,
      "y": 55,
      "z": 1,
      "name": "Plant_Leaves_Birch"
    },
    {
      "x": -4,
      "y": 56,
      "z": 1,
      "name": "Plant_Leaves_Birch"
    },
    {
      "x": -4,
      "y": 57,
      "z": 1,
      "name": "Plant_Leaves_Birch"
    },
    {
      "x": -4,
      "y": 18,
      "z": 2,
      "name": "Rock_Stone"
    },
    {
      "x": -4,
      "y": 19,
      "z": 2,
      "name": "Rock_Stone"
    },
    {
      "x": -4,
      "y": 20,
      "z": 2,
      "name": "Rock_Stone"
    },
    {
      "x": -4,
      "y": 21,
      "z": 2,
      "name": "Rock_Stone"
    },
    {
      "x": -4,
      "y": 22,
      "z": 2,
      "name": "Rock_Stone"
    },
    {
      "x": -4,
      "y": 23,
      "z": 2,
      "name": "Rock_Stone"
    },
    {
      "x": -4,
      "y": 24,
      "z": 2,
      "name": "Rock_Stone"
    },
    {
      "x": -4,
      "y": 25,
      "z": 2,
      "name": "Rock_Stone"
    },
    {
      "x": -4,
      "y": 26,
      "z": 2,
      "name": "Rock_Stone"
    },
    {
      "x": -4,
      "y": 27,
      "z": 2,
      "name": "Rock_Stone"
    },
    {
      "x": -4,
      "y": 28,
      "z": 2,
      "name": "Rock_Stone"
    },
    {
      "x": -4,
      "y": 29,
      "z": 2,
      "name": "Rock_Stone"
    },
    {
      "x": -4,
      "y": 30,
      "z": 2,
      "name": "Rock_Stone"
    },
    {
      "x": -4,
      "y": 31,
      "z": 2,
      "name": "Rock_Stone"
    },
    {
      "x": -4,
      "y": 32,
      "z": 2,
      "name": "Rock_Stone"
    },
    {
      "x": -4,
      "y": 33,
      "z": 2,
      "name": "Rock_Stone"
    },
    {
      "x": -4,
      "y": 34,
      "z": 2,
      "name": "Rock_Stone"
    },
    {
      "x": -4,
      "y": 35,
      "z": 2,
      "name": "Rock_Stone"
    },
    {
      "x": -4,
      "y": 36,
      "z": 2,
      "name": "Soil_Dirt"
    },
    {
      "x": -4,
      "y": 37,
      "z": 2,
      "name": "Soil_Grass"
    },
    {
      "x": -4,
      "y": 38,
      "z": 2,
      "name": "Plant_Grass_Sharp"
    },
    {
      "x": -4,
      "y": 50,
      "z": 2,
      "name": "Wood_Birch_Branch_Long",
      "rotation": 5
    },
    {
      "x": -4,
      "y": 54,
      "z": 2,
      "name": "Plant_Leaves_Birch"
    },
    {
      "x": -4,
      "y": 55,
      "z": 2,
      "name": "Plant_Leaves_Birch"
    },
    {
      "x": -4,
      "y": 56,
      "z": 2,
      "name": "Plant_Leaves_Birch"
    },
    {
      "x": -4,
      "y": 57,
      "z": 2,
      "name": "Plant_Leaves_Birch"
    },
    {
      "x": -4,
      "y": 58,
      "z": 2,
      "name": "Plant_Leaves_Birch"
    },
    {
      "x": -4,
      "y": 18,
      "z": 3,
      "name": "Rock_Stone"
    },
    {
      "x": -4,
      "y": 19,
      "z": 3,
      "name": "Rock_Stone"
    },
    {
      "x": -4,
      "y": 20,
      "z": 3,
      "name": "Rock_Stone"
    },
    {
      "x": -4,
      "y": 21,
      "z": 3,
      "name": "Rock_Stone"
    },
    {
      "x": -4,
      "y": 22,
      "z": 3,
      "name": "Rock_Stone"
    },
    {
      "x": -4,
      "y": 23,
      "z": 3,
      "name": "Rock_Stone"
    },
    {
      "x": -4,
      "y": 24,
      "z": 3,
      "name": "Rock_Stone"
    },
    {
      "x": -4,
      "y": 25,
      "z": 3,
      "name": "Rock_Stone"
    },
    {
      "x": -4,
      "y": 26,
      "z": 3,
      "name": "Rock_Stone"
    },
    {
      "x": -4,
      "y": 27,
      "z": 3,
      "name": "Rock_Stone"
    },
    {
      "x": -4,
      "y": 28,
      "z": 3,
      "name": "Rock_Stone"
    },
    {
      "x": -4,
      "y": 29,
      "z": 3,
      "name": "Rock_Stone"
    },
    {
      "x": -4,
      "y": 30,
      "z": 3,
      "name": "Rock_Stone"
    },
    {
      "x": -4,
      "y": 31,
      "z": 3,
      "name": "Rock_Stone"
    },
    {
      "x": -4,
      "y": 32,
      "z": 3,
      "name": "Rock_Stone"
    },
    {
      "x": -4,
      "y": 33,
      "z": 3,
      "name": "Rock_Stone"
    },
    {
      "x": -4,
      "y": 34,
      "z": 3,
      "name": "Soil_Dirt"
    },
    {
      "x": -4,
      "y": 35,
      "z": 3,
      "name": "Rock_Stone"
    },
    {
      "x": -4,
      "y": 36,
      "z": 3,
      "name": "Soil_Dirt"
    },
    {
      "x": -4,
      "y": 37,
      "z": 3,
      "name": "Soil_Grass"
    },
    {
      "x": -4,
      "y": 38,
      "z": 3,
      "name": "Plant_Grass_Sharp_Tall"
    },
    {
      "x": -4,
      "y": 39,
      "z": 3,
      "name": "Plant_Grass_Sharp_Tall",
      "filler": 1024
    },
    {
      "x": -4,
      "y": 42,
      "z": 3,
      "name": "Wood_Birch_Branch_Long",
      "rotation": 5
    },
    {
      "x": -4,
      "y": 46,
      "z": 3,
      "name": "Plant_Leaves_Birch"
    },
    {
      "x": -4,
      "y": 47,
      "z": 3,
      "name": "Plant_Leaves_Birch"
    },
    {
      "x": -4,
      "y": 48,
      "z": 3,
      "name": "Plant_Leaves_Birch"
    },
    {
      "x": -4,
      "y": 49,
      "z": 3,
      "name": "Plant_Leaves_Birch"
    },
    {
      "x": -4,
      "y": 50,
      "z": 3,
      "name": "Plant_Leaves_Birch"
    },
    {
      "x": -4,
      "y": 51,
      "z": 3,
      "name": "Plant_Leaves_Birch"
    },
    {
      "x": -4,
      "y": 52,
      "z": 3,
      "name": "Plant_Leaves_Birch"
    },
    {
      "x": -4,
      "y": 53,
      "z": 3,
      "name": "Plant_Leaves_Birch"
    },
    {
      "x": -4,
      "y": 54,
      "z": 3,
      "name": "Plant_Leaves_Birch"
    },
    {
      "x": -4,
      "y": 56,
      "z": 3,
      "name": "Plant_Leaves_Birch"
    },
    {
      "x": -4,
      "y": 18,
      "z": 4,
      "name": "Rock_Stone"
    },
    {
      "x": -4,
      "y": 19,
      "z": 4,
      "name": "Rock_Stone"
    },
    {
      "x": -4,
      "y": 20,
      "z": 4,
      "name": "Rock_Stone"
    },
    {
      "x": -4,
      "y": 21,
      "z": 4,
      "name": "Rock_Stone"
    },
    {
      "x": -4,
      "y": 22,
      "z": 4,
      "name": "Rock_Stone"
    },
    {
      "x": -4,
      "y": 23,
      "z": 4,
      "name": "Rock_Stone"
    },
    {
      "x": -4,
      "y": 24,
      "z": 4,
      "name": "Rock_Stone"
    },
    {
      "x": -4,
      "y": 25,
      "z": 4,
      "name": "Rock_Stone"
    },
    {
      "x": -4,
      "y": 26,
      "z": 4,
      "name": "Rock_Stone"
    },
    {
      "x": -4,
      "y": 27,
      "z": 4,
      "name": "Rock_Stone"
    },
    {
      "x": -4,
      "y": 28,
      "z": 4,
      "name": "Rock_Stone"
    },
    {
      "x": -4,
      "y": 29,
      "z": 4,
      "name": "Rock_Stone"
    },
    {
      "x": -4,
      "y": 30,
      "z": 4,
      "name": "Rock_Stone"
    },
    {
      "x": -4,
      "y": 31,
      "z": 4,
      "name": "Soil_Dirt"
    },
    {
      "x": -4,
      "y": 32,
      "z": 4,
      "name": "Rock_Stone"
    },
    {
      "x": -4,
      "y": 33,
      "z": 4,
      "name": "Soil_Dirt"
    },
    {
      "x": -4,
      "y": 34,
      "z": 4,
      "name": "Soil_Dirt"
    },
    {
      "x": -4,
      "y": 35,
      "z": 4,
      "name": "Soil_Dirt"
    },
    {
      "x": -4,
      "y": 36,
      "z": 4,
      "name": "Soil_Dirt"
    },
    {
      "x": -4,
      "y": 37,
      "z": 4,
      "name": "Soil_Grass"
    },
    {
      "x": -4,
      "y": 38,
      "z": 4,
      "name": "Plant_Grass_Sharp_Tall"
    },
    {
      "x": -4,
      "y": 39,
      "z": 4,
      "name": "Plant_Grass_Sharp_Tall",
      "filler": 1024
    },
    {
      "x": -4,
      "y": 47,
      "z": 4,
      "name": "Plant_Leaves_Birch"
    },
    {
      "x": -4,
      "y": 48,
      "z": 4,
      "name": "Plant_Leaves_Birch"
    },
    {
      "x": -4,
      "y": 49,
      "z": 4,
      "name": "Plant_Leaves_Birch"
    },
    {
      "x": -4,
      "y": 50,
      "z": 4,
      "name": "Plant_Leaves_Birch"
    },
    {
      "x": -4,
      "y": 51,
      "z": 4,
      "name": "Plant_Leaves_Birch"
    },
    {
      "x": -4,
      "y": 52,
      "z": 4,
      "name": "Plant_Leaves_Birch"
    },
    {
      "x": -4,
      "y": 20,
      "z": 5,
      "name": "Rock_Stone"
    },
    {
      "x": -4,
      "y": 21,
      "z": 5,
      "name": "Rock_Stone"
    },
    {
      "x": -4,
      "y": 22,
      "z": 5,
      "name": "Rock_Stone"
    },
    {
      "x": -4,
      "y": 23,
      "z": 5,
      "name": "Rock_Stone"
    },
    {
      "x": -4,
      "y": 24,
      "z": 5,
      "name": "Rock_Stone"
    },
    {
      "x": -4,
      "y": 25,
      "z": 5,
      "name": "Rock_Stone"
    },
    {
      "x": -4,
      "y": 26,
      "z": 5,
      "name": "Rock_Stone"
    },
    {
      "x": -4,
      "y": 27,
      "z": 5,
      "name": "Rock_Stone"
    },
    {
      "x": -4,
      "y": 28,
      "z": 5,
      "name": "Rock_Stone_Mossy"
    },
    {
      "x": -4,
      "y": 29,
      "z": 5,
      "name": "Rock_Stone"
    },
    {
      "x": -4,
      "y": 30,
      "z": 5,
      "name": "Soil_Dirt"
    },
    {
      "x": -4,
      "y": 31,
      "z": 5,
      "name": "Soil_Dirt"
    },
    {
      "x": -4,
      "y": 32,
      "z": 5,
      "name": "Soil_Dirt"
    },
    {
      "x": -4,
      "y": 33,
      "z": 5,
      "name": "Soil_Dirt"
    },
    {
      "x": -4,
      "y": 34,
      "z": 5,
      "name": "Soil_Dirt"
    },
    {
      "x": -4,
      "y": 35,
      "z": 5,
      "name": "Soil_Dirt"
    },
    {
      "x": -4,
      "y": 36,
      "z": 5,
      "name": "Soil_Grass"
    },
    {
      "x": -4,
      "y": 43,
      "z": 5,
      "name": "Plant_Leaves_Birch"
    },
    {
      "x": -4,
      "y": 46,
      "z": 5,
      "name": "Plant_Leaves_Birch"
    },
    {
      "x": -4,
      "y": 48,
      "z": 5,
      "name": "Plant_Leaves_Birch"
    },
    {
      "x": -4,
      "y": 49,
      "z": 5,
      "name": "Plant_Leaves_Birch"
    },
    {
      "x": -4,
      "y": 50,
      "z": 5,
      "name": "Plant_Leaves_Birch"
    },
    {
      "x": -4,
      "y": 20,
      "z": 6,
      "name": "Rock_Stone"
    },
    {
      "x": -4,
      "y": 21,
      "z": 6,
      "name": "Rock_Stone"
    },
    {
      "x": -4,
      "y": 22,
      "z": 6,
      "name": "Rock_Stone"
    },
    {
      "x": -4,
      "y": 23,
      "z": 6,
      "name": "Rock_Stone"
    },
    {
      "x": -4,
      "y": 24,
      "z": 6,
      "name": "Rock_Stone"
    },
    {
      "x": -4,
      "y": 25,
      "z": 6,
      "name": "Rock_Stone"
    },
    {
      "x": -4,
      "y": 26,
      "z": 6,
      "name": "Rock_Stone"
    },
    {
      "x": -4,
      "y": 27,
      "z": 6,
      "name": "Rock_Stone_Mossy"
    },
    {
      "x": -4,
      "y": 28,
      "z": 6,
      "name": "Rock_Stone_Mossy"
    },
    {
      "x": -4,
      "y": 29,
      "z": 6,
      "name": "Rock_Stone_Mossy"
    },
    {
      "x": -4,
      "y": 30,
      "z": 6,
      "name": "Soil_Dirt"
    },
    {
      "x": -4,
      "y": 31,
      "z": 6,
      "name": "Soil_Dirt"
    },
    {
      "x": -4,
      "y": 32,
      "z": 6,
      "name": "Soil_Grass"
    },
    {
      "x": -4,
      "y": 43,
      "z": 6,
      "name": "Plant_Leaves_Birch"
    },
    {
      "x": -3,
      "y": 20,
      "z": -4,
      "name": "Rock_Stone"
    },
    {
      "x": -3,
      "y": 21,
      "z": -4,
      "name": "Rock_Stone"
    },
    {
      "x": -3,
      "y": 22,
      "z": -4,
      "name": "Rock_Stone"
    },
    {
      "x": -3,
      "y": 23,
      "z": -4,
      "name": "Rock_Stone"
    },
    {
      "x": -3,
      "y": 24,
      "z": -4,
      "name": "Soil_Dirt"
    },
    {
      "x": -3,
      "y": 25,
      "z": -4,
      "name": "Soil_Dirt"
    },
    {
      "x": -3,
      "y": 26,
      "z": -4,
      "name": "Soil_Dirt"
    },
    {
      "x": -3,
      "y": 27,
      "z": -4,
      "name": "Soil_Grass"
    },
    {
      "x": -3,
      "y": 19,
      "z": -3,
      "name": "Rock_Stone"
    },
    {
      "x": -3,
      "y": 20,
      "z": -3,
      "name": "Rock_Stone"
    },
    {
      "x": -3,
      "y": 21,
      "z": -3,
      "name": "Rock_Stone"
    },
    {
      "x": -3,
      "y": 22,
      "z": -3,
      "name": "Rock_Stone"
    },
    {
      "x": -3,
      "y": 23,
      "z": -3,
      "name": "Rock_Stone"
    },
    {
      "x": -3,
      "y": 24,
      "z": -3,
      "name": "Soil_Dirt"
    },
    {
      "x": -3,
      "y": 25,
      "z": -3,
      "name": "Soil_Dirt"
    },
    {
      "x": -3,
      "y": 26,
      "z": -3,
      "name": "Soil_Dirt"
    },
    {
      "x": -3,
      "y": 27,
      "z": -3,
      "name": "Rock_Stone"
    },
    {
      "x": -3,
      "y": 28,
      "z": -3,
      "name": "Rock_Stone"
    },
    {
      "x": -3,
      "y": 29,
      "z": -3,
      "name": "Rock_Stone"
    },
    {
      "x": -3,
      "y": 30,
      "z": -3,
      "name": "Rock_Stone"
    },
    {
      "x": -3,
      "y": 31,
      "z": -3,
      "name": "Rock_Stone"
    },
    {
      "x": -3,
      "y": 32,
      "z": -3,
      "name": "Rock_Stone"
    },
    {
      "x": -3,
      "y": 33,
      "z": -3,
      "name": "Rock_Stone"
    },
    {
      "x": -3,
      "y": 34,
      "z": -3,
      "name": "Soil_Dirt"
    },
    {
      "x": -3,
      "y": 35,
      "z": -3,
      "name": "Soil_Grass"
    },
    {
      "x": -3,
      "y": 18,
      "z": -2,
      "name": "Rock_Stone"
    },
    {
      "x": -3,
      "y": 19,
      "z": -2,
      "name": "Rock_Stone"
    },
    {
      "x": -3,
      "y": 20,
      "z": -2,
      "name": "Rock_Stone"
    },
    {
      "x": -3,
      "y": 21,
      "z": -2,
      "name": "Rock_Stone"
    },
    {
      "x": -3,
      "y": 22,
      "z": -2,
      "name": "Rock_Stone"
    },
    {
      "x": -3,
      "y": 23,
      "z": -2,
      "name": "Rock_Stone"
    },
    {
      "x": -3,
      "y": 24,
      "z": -2,
      "name": "Rock_Stone"
    },
    {
      "x": -3,
      "y": 25,
      "z": -2,
      "name": "Soil_Dirt"
    },
    {
      "x": -3,
      "y": 26,
      "z": -2,
      "name": "Soil_Dirt"
    },
    {
      "x": -3,
      "y": 27,
      "z": -2,
      "name": "Rock_Stone"
    },
    {
      "x": -3,
      "y": 28,
      "z": -2,
      "name": "Rock_Stone"
    },
    {
      "x": -3,
      "y": 29,
      "z": -2,
      "name": "Rock_Stone"
    },
    {
      "x": -3,
      "y": 30,
      "z": -2,
      "name": "Rock_Stone"
    },
    {
      "x": -3,
      "y": 31,
      "z": -2,
      "name": "Rock_Stone"
    },
    {
      "x": -3,
      "y": 32,
      "z": -2,
      "name": "Rock_Stone"
    },
    {
      "x": -3,
      "y": 33,
      "z": -2,
      "name": "Rock_Stone"
    },
    {
      "x": -3,
      "y": 34,
      "z": -2,
      "name": "Soil_Dirt"
    },
    {
      "x": -3,
      "y": 35,
      "z": -2,
      "name": "Soil_Dirt"
    },
    {
      "x": -3,
      "y": 36,
      "z": -2,
      "name": "Soil_Dirt"
    },
    {
      "x": -3,
      "y": 37,
      "z": -2,
      "name": "Soil_Dirt"
    },
    {
      "x": -3,
      "y": 38,
      "z": -2,
      "name": "Soil_Dirt"
    },
    {
      "x": -3,
      "y": 39,
      "z": -2,
      "name": "Soil_Grass"
    },
    {
      "x": -3,
      "y": 40,
      "z": -2,
      "name": "Plant_Grass_Sharp_Tall"
    },
    {
      "x": -3,
      "y": 41,
      "z": -2,
      "name": "Plant_Grass_Sharp_Tall",
      "filler": 1024
    },
    {
      "x": -3,
      "y": 18,
      "z": -1,
      "name": "Rock_Stone"
    },
    {
      "x": -3,
      "y": 19,
      "z": -1,
      "name": "Rock_Stone"
    },
    {
      "x": -3,
      "y": 20,
      "z": -1,
      "name": "Rock_Stone"
    },
    {
      "x": -3,
      "y": 21,
      "z": -1,
      "name": "Rock_Stone"
    },
    {
      "x": -3,
      "y": 22,
      "z": -1,
      "name": "Rock_Stone"
    },
    {
      "x": -3,
      "y": 23,
      "z": -1,
      "name": "Rock_Stone"
    },
    {
      "x": -3,
      "y": 24,
      "z": -1,
      "name": "Rock_Stone"
    },
    {
      "x": -3,
      "y": 25,
      "z": -1,
      "name": "Rock_Stone"
    },
    {
      "x": -3,
      "y": 26,
      "z": -1,
      "name": "Rock_Stone"
    },
    {
      "x": -3,
      "y": 27,
      "z": -1,
      "name": "Rock_Stone"
    },
    {
      "x": -3,
      "y": 28,
      "z": -1,
      "name": "Rock_Stone"
    },
    {
      "x": -3,
      "y": 29,
      "z": -1,
      "name": "Rock_Stone"
    },
    {
      "x": -3,
      "y": 30,
      "z": -1,
      "name": "Rock_Stone"
    },
    {
      "x": -3,
      "y": 31,
      "z": -1,
      "name": "Rock_Stone"
    },
    {
      "x": -3,
      "y": 32,
      "z": -1,
      "name": "Rock_Stone"
    },
    {
      "x": -3,
      "y": 33,
      "z": -1,
      "name": "Rock_Stone"
    },
    {
      "x": -3,
      "y": 34,
      "z": -1,
      "name": "Rock_Stone"
    },
    {
      "x": -3,
      "y": 35,
      "z": -1,
      "name": "Soil_Dirt"
    },
    {
      "x": -3,
      "y": 36,
      "z": -1,
      "name": "Soil_Dirt"
    },
    {
      "x": -3,
      "y": 37,
      "z": -1,
      "name": "Soil_Dirt"
    },
    {
      "x": -3,
      "y": 38,
      "z": -1,
      "name": "Soil_Dirt"
    },
    {
      "x": -3,
      "y": 39,
      "z": -1,
      "name": "Soil_Grass"
    },
    {
      "x": -3,
      "y": 18,
      "z": 0,
      "name": "Rock_Stone"
    },
    {
      "x": -3,
      "y": 19,
      "z": 0,
      "name": "Rock_Stone"
    },
    {
      "x": -3,
      "y": 20,
      "z": 0,
      "name": "Rock_Stone"
    },
    {
      "x": -3,
      "y": 21,
      "z": 0,
      "name": "Rock_Stone"
    },
    {
      "x": -3,
      "y": 22,
      "z": 0,
      "name": "Rock_Stone"
    },
    {
      "x": -3,
      "y": 23,
      "z": 0,
      "name": "Rock_Stone"
    },
    {
      "x": -3,
      "y": 24,
      "z": 0,
      "name": "Rock_Stone"
    },
    {
      "x": -3,
      "y": 25,
      "z": 0,
      "name": "Rock_Stone"
    },
    {
      "x": -3,
      "y": 26,
      "z": 0,
      "name": "Rock_Stone"
    },
    {
      "x": -3,
      "y": 27,
      "z": 0,
      "name": "Rock_Stone"
    },
    {
      "x": -3,
      "y": 28,
      "z": 0,
      "name": "Rock_Stone"
    },
    {
      "x": -3,
      "y": 29,
      "z": 0,
      "name": "Rock_Stone"
    },
    {
      "x": -3,
      "y": 30,
      "z": 0,
      "name": "Rock_Stone"
    },
    {
      "x": -3,
      "y": 31,
      "z": 0,
      "name": "Rock_Stone"
    },
    {
      "x": -3,
      "y": 32,
      "z": 0,
      "name": "Rock_Stone"
    },
    {
      "x": -3,
      "y": 33,
      "z": 0,
      "name": "Rock_Stone"
    },
    {
      "x": -3,
      "y": 34,
      "z": 0,
      "name": "Rock_Stone"
    },
    {
      "x": -3,
      "y": 35,
      "z": 0,
      "name": "Rock_Stone"
    },
    {
      "x": -3,
      "y": 36,
      "z": 0,
      "name": "Soil_Dirt"
    },
    {
      "x": -3,
      "y": 37,
      "z": 0,
      "name": "Soil_Dirt"
    },
    {
      "x": -3,
      "y": 38,
      "z": 0,
      "name": "Soil_Dirt"
    },
    {
      "x": -3,
      "y": 39,
      "z": 0,
      "name": "Soil_Grass"
    },
    {
      "x": -3,
      "y": 45,
      "z": 0,
      "name": "Plant_Leaves_Birch"
    },
    {
      "x": -3,
      "y": 46,
      "z": 0,
      "name": "Plant_Leaves_Birch"
    },
    {
      "x": -3,
      "y": 49,
      "z": 0,
      "name": "Plant_Leaves_Birch"
    },
    {
      "x": -3,
      "y": 50,
      "z": 0,
      "name": "Plant_Leaves_Birch"
    },
    {
      "x": -3,
      "y": 18,
      "z": 1,
      "name": "Rock_Stone"
    },
    {
      "x": -3,
      "y": 19,
      "z": 1,
      "name": "Rock_Stone"
    },
    {
      "x": -3,
      "y": 20,
      "z": 1,
      "name": "Rock_Stone"
    },
    {
      "x": -3,
      "y": 21,
      "z": 1,
      "name": "Rock_Stone"
    },
    {
      "x": -3,
      "y": 22,
      "z": 1,
      "name": "Rock_Stone"
    },
    {
      "x": -3,
      "y": 23,
      "z": 1,
      "name": "Rock_Stone"
    },
    {
      "x": -3,
      "y": 24,
      "z": 1,
      "name": "Rock_Stone"
    },
    {
      "x": -3,
      "y": 25,
      "z": 1,
      "name": "Rock_Stone"
    },
    {
      "x": -3,
      "y": 26,
      "z": 1,
      "name": "Rock_Stone"
    },
    {
      "x": -3,
      "y": 27,
      "z": 1,
      "name": "Rock_Stone"
    },
    {
      "x": -3,
      "y": 28,
      "z": 1,
      "name": "Rock_Stone"
    },
    {
      "x": -3,
      "y": 29,
      "z": 1,
      "name": "Rock_Stone"
    },
    {
      "x": -3,
      "y": 30,
      "z": 1,
      "name": "Rock_Stone"
    },
    {
      "x": -3,
      "y": 31,
      "z": 1,
      "name": "Rock_Stone"
    },
    {
      "x": -3,
      "y": 32,
      "z": 1,
      "name": "Rock_Stone"
    },
    {
      "x": -3,
      "y": 33,
      "z": 1,
      "name": "Rock_Stone"
    },
    {
      "x": -3,
      "y": 34,
      "z": 1,
      "name": "Rock_Stone"
    },
    {
      "x": -3,
      "y": 35,
      "z": 1,
      "name": "Rock_Stone"
    },
    {
      "x": -3,
      "y": 36,
      "z": 1,
      "name": "Rock_Stone"
    },
    {
      "x": -3,
      "y": 37,
      "z": 1,
      "name": "Rock_Stone"
    },
    {
      "x": -3,
      "y": 38,
      "z": 1,
      "name": "Soil_Dirt"
    },
    {
      "x": -3,
      "y": 39,
      "z": 1,
      "name": "Soil_Grass"
    },
    {
      "x": -3,
      "y": 43,
      "z": 1,
      "name": "Plant_Leaves_Birch"
    },
    {
      "x": -3,
      "y": 44,
      "z": 1,
      "name": "Plant_Leaves_Birch"
    },
    {
      "x": -3,
      "y": 46,
      "z": 1,
      "name": "Plant_Leaves_Birch"
    },
    {
      "x": -3,
      "y": 47,
      "z": 1,
      "name": "Plant_Leaves_Birch"
    },
    {
      "x": -3,
      "y": 48,
      "z": 1,
      "name": "Plant_Leaves_Birch"
    },
    {
      "x": -3,
      "y": 49,
      "z": 1,
      "name": "Plant_Leaves_Birch"
    },
    {
      "x": -3,
      "y": 50,
      "z": 1,
      "name": "Plant_Leaves_Birch"
    },
    {
      "x": -3,
      "y": 52,
      "z": 1,
      "name": "Plant_Leaves_Birch"
    },
    {
      "x": -3,
      "y": 53,
      "z": 1,
      "name": "Plant_Leaves_Birch"
    },
    {
      "x": -3,
      "y": 18,
      "z": 2,
      "name": "Rock_Stone"
    },
    {
      "x": -3,
      "y": 19,
      "z": 2,
      "name": "Rock_Stone"
    },
    {
      "x": -3,
      "y": 20,
      "z": 2,
      "name": "Rock_Stone"
    },
    {
      "x": -3,
      "y": 21,
      "z": 2,
      "name": "Rock_Stone"
    },
    {
      "x": -3,
      "y": 22,
      "z": 2,
      "name": "Rock_Stone"
    },
    {
      "x": -3,
      "y": 23,
      "z": 2,
