{
  "version": 8,
  "blockIdVersion": 8,
  "anchorX": -3,
  "anchorY": 19,
  "anchorZ": 0,
  "blocks": [
    {
      "x": -9,
      "y": 26,
      "z": -4,
      "name": "Soil_Grass"
    },
    {
      "x": -9,
      "y": 24,
      "z": -3,
      "name": "Rock_Stone_Mossy"
    },
    {
      "x": -9,
      "y": 25,
      "z": -3,
      "name": "Soil_Dirt"
    },
    {
      "x": -9,
      "y": 26,
      "z": -3,
      "name": "Soil_Grass"
    },
    {
      "x": -9,
      "y": 24,
      "z": -2,
      "name": "Rock_Stone"
    },
    {
      "x": -9,
      "y": 25,
      "z": -2,
      "name": "Soil_Dirt"
    },
    {
      "x": -9,
      "y": 26,
      "z": -2,
      "name": "Soil_Grass"
    },
    {
      "x": -9,
      "y": 22,
      "z": -1,
      "name": "Rock_Stone"
    },
    {
      "x": -9,
      "y": 23,
      "z": -1,
      "name": "Rock_Stone"
    },
    {
      "x": -9,
      "y": 24,
      "z": -1,
      "name": "Soil_Dirt"
    },
    {
      "x": -9,
      "y": 25,
      "z": -1,
      "name": "Soil_Dirt"
    },
    {
      "x": -9,
      "y": 26,
      "z": -1,
      "name": "Soil_Grass"
    },
    {
      "x": -9,
      "y": 22,
      "z": 0,
      "name": "Rock_Stone"
    },
    {
      "x": -9,
      "y": 23,
      "z": 0,
      "name": "Rock_Stone"
    },
    {
      "x": -9,
      "y": 24,
      "z": 0,
      "name": "Soil_Dirt"
    },
    {
      "x": -9,
      "y": 25,
      "z": 0,
      "name": "Soil_Grass"
    },
    {
      "x": -9,
      "y": 22,
      "z": 1,
      "name": "Rock_Stone"
    },
    {
      "x": -9,
      "y": 23,
      "z": 1,
      "name": "Rock_Stone"
    },
    {
      "x": -9,
      "y": 24,
      "z": 1,
      "name": "Soil_Dirt"
    },
    {
      "x": -9,
      "y": 25,
      "z": 1,
      "name": "Soil_Grass"
    },
    {
      "x": -9,
      "y": 23,
      "z": 2,
      "name": "Rock_Stone"
    },
    {
      "x": -9,
      "y": 24,
      "z": 2,
      "name": "Soil_Dirt"
    },
    {
      "x": -9,
      "y": 25,
      "z": 2,
      "name": "Soil_Grass"
    },
    {
      "x": -8,
      "y": 23,
      "z": -5,
      "name": "Rock_Stone_Mossy"
    },
    {
      "x": -8,
      "y": 24,
      "z": -5,
      "name": "Rock_Stone_Mossy"
    },
    {
      "x": -8,
      "y": 25,
      "z": -5,
      "name": "Soil_Grass"
    },
    {
      "x": -8,
      "y": 20,
      "z": -4,
      "name": "Rock_Stone"
    },
    {
      "x": -8,
      "y": 21,
      "z": -4,
      "name": "Rock_Stone"
    },
    {
      "x": -8,
      "y": 22,
      "z": -4,
      "name": "Rock_Stone"
    },
    {
      "x": -8,
      "y": 23,
      "z": -4,
      "name": "Rock_Stone_Mossy"
    },
    {
      "x": -8,
      "y": 24,
      "z": -4,
      "name": "Rock_Stone_Mossy"
    },
    {
      "x": -8,
      "y": 25,
      "z": -4,
      "name": "Soil_Dirt"
    },
    {
      "x": -8,
      "y": 26,
      "z": -4,
      "name": "Soil_Grass"
    },
    {
      "x": -8,
      "y": 19,
      "z": -3,
      "name": "Rock_Stone"
    },
    {
      "x": -8,
      "y": 20,
      "z": -3,
      "name": "Rock_Stone"
    },
    {
      "x": -8,
      "y": 21,
      "z": -3,
      "name": "Rock_Stone"
    },
    {
      "x": -8,
      "y": 22,
      "z": -3,
      "name": "Rock_Stone"
    },
    {
      "x": -8,
      "y": 23,
      "z": -3,
      "name": "Rock_Stone"
    },
    {
      "x": -8,
      "y": 24,
      "z": -3,
      "name": "Rock_Stone_Mossy"
    },
    {
      "x": -8,
      "y": 25,
      "z": -3,
      "name": "Soil_Dirt"
    },
    {
      "x": -8,
      "y": 26,
      "z": -3,
      "name": "Soil_Grass"
    },
    {
      "x": -8,
      "y": 19,
      "z": -2,
      "name": "Rock_Stone"
    },
    {
      "x": -8,
      "y": 20,
      "z": -2,
      "name": "Rock_Stone"
    },
    {
      "x": -8,
      "y": 21,
      "z": -2,
      "name": "Rock_Stone"
    },
    {
      "x": -8,
      "y": 22,
      "z": -2,
      "name": "Rock_Stone"
    },
    {
      "x": -8,
      "y": 23,
      "z": -2,
      "name": "Rock_Stone"
    },
    {
      "x": -8,
      "y": 24,
      "z": -2,
      "name": "Rock_Stone"
    },
    {
      "x": -8,
      "y": 25,
      "z": -2,
      "name": "Soil_Dirt"
    },
    {
      "x": -8,
      "y": 26,
      "z": -2,
      "name": "Soil_Grass"
    },
    {
      "x": -8,
      "y": 27,
      "z": -2,
      "name": "Plant_Grass_Sharp_Tall"
    },
    {
      "x": -8,
      "y": 28,
      "z": -2,
      "name": "Plant_Grass_Sharp_Tall",
      "filler": 1024
    },
    {
      "x": -8,
      "y": 19,
      "z": -1,
      "name": "Rock_Stone"
    },
    {
      "x": -8,
      "y": 20,
      "z": -1,
      "name": "Rock_Stone"
    },
    {
      "x": -8,
      "y": 21,
      "z": -1,
      "name": "Rock_Stone"
    },
    {
      "x": -8,
      "y": 22,
      "z": -1,
      "name": "Rock_Stone"
    },
    {
      "x": -8,
      "y": 23,
      "z": -1,
      "name": "Rock_Stone"
    },
    {
      "x": -8,
      "y": 24,
      "z": -1,
      "name": "Soil_Dirt"
    },
    {
      "x": -8,
      "y": 25,
      "z": -1,
      "name": "Soil_Dirt"
    },
    {
      "x": -8,
      "y": 26,
      "z": -1,
      "name": "Soil_Grass"
    },
    {
      "x": -8,
      "y": 27,
      "z": -1,
      "name": "Plant_Grass_Sharp"
    },
    {
      "x": -8,
      "y": 33,
      "z": -1,
      "name": "Rock_Stone"
    },
    {
      "x": -8,
      "y": 34,
      "z": -1,
      "name": "Soil_Dirt"
    },
    {
      "x": -8,
      "y": 35,
      "z": -1,
      "name": "Soil_Grass"
    },
    {
      "x": -8,
      "y": 20,
      "z": 0,
      "name": "Rock_Stone"
    },
    {
      "x": -8,
      "y": 21,
      "z": 0,
      "name": "Rock_Stone"
    },
    {
      "x": -8,
      "y": 22,
      "z": 0,
      "name": "Rock_Stone"
    },
    {
      "x": -8,
      "y": 23,
      "z": 0,
      "name": "Rock_Stone"
    },
    {
      "x": -8,
      "y": 24,
      "z": 0,
      "name": "Soil_Dirt"
    },
    {
      "x": -8,
      "y": 25,
      "z": 0,
      "name": "Soil_Dirt"
    },
    {
      "x": -8,
      "y": 26,
      "z": 0,
      "name": "Soil_Grass"
    },
    {
      "x": -8,
      "y": 27,
      "z": 0,
      "name": "Plant_Grass_Sharp"
    },
    {
      "x": -8,
      "y": 33,
      "z": 0,
      "name": "Rock_Stone"
    },
    {
      "x": -8,
      "y": 34,
      "z": 0,
      "name": "Soil_Dirt"
    },
    {
      "x": -8,
      "y": 35,
      "z": 0,
      "name": "Soil_Grass"
    },
    {
      "x": -8,
      "y": 20,
      "z": 1,
      "name": "Rock_Stone"
    },
    {
      "x": -8,
      "y": 21,
      "z": 1,
      "name": "Rock_Stone"
    },
    {
      "x": -8,
      "y": 22,
      "z": 1,
      "name": "Rock_Stone"
    },
    {
      "x": -8,
      "y": 23,
      "z": 1,
      "name": "Rock_Stone"
    },
    {
      "x": -8,
      "y": 24,
      "z": 1,
      "name": "Soil_Dirt"
    },
    {
      "x": -8,
      "y": 25,
      "z": 1,
      "name": "Soil_Dirt"
    },
    {
      "x": -8,
      "y": 26,
      "z": 1,
      "name": "Soil_Grass"
    },
    {
      "x": -8,
      "y": 34,
      "z": 1,
      "name": "Soil_Dirt"
    },
    {
      "x": -8,
      "y": 35,
      "z": 1,
      "name": "Soil_Grass"
    },
    {
      "x": -8,
      "y": 36,
      "z": 1,
      "name": "Plant_Bush"
    },
    {
      "x": -8,
      "y": 20,
      "z": 2,
      "name": "Rock_Stone"
    },
    {
      "x": -8,
      "y": 21,
      "z": 2,
      "name": "Rock_Stone"
    },
    {
      "x": -8,
      "y": 22,
      "z": 2,
      "name": "Rock_Stone"
    },
    {
      "x": -8,
      "y": 23,
      "z": 2,
      "name": "Rock_Stone"
    },
    {
      "x": -8,
      "y": 24,
      "z": 2,
      "name": "Soil_Dirt"
    },
    {
      "x": -8,
      "y": 25,
      "z": 2,
      "name": "Soil_Dirt"
    },
    {
      "x": -8,
      "y": 26,
      "z": 2,
      "name": "Soil_Grass"
    },
    {
      "x": -8,
      "y": 22,
      "z": 3,
      "name": "Rock_Stone"
    },
    {
      "x": -8,
      "y": 23,
      "z": 3,
      "name": "Rock_Stone_Mossy"
    },
    {
      "x": -8,
      "y": 24,
      "z": 3,
      "name": "Soil_Dirt"
    },
    {
      "x": -8,
      "y": 25,
      "z": 3,
      "name": "Soil_Dirt"
    },
    {
      "x": -8,
      "y": 26,
      "z": 3,
      "name": "Soil_Grass"
    },
    {
      "x": -8,
      "y": 24,
      "z": 4,
      "name": "Soil_Dirt"
    },
    {
      "x": -8,
      "y": 25,
      "z": 4,
      "name": "Soil_Grass"
    },
    {
      "x": -7,
      "y": 22,
      "z": -5,
      "name": "Rock_Stone"
    },
    {
      "x": -7,
      "y": 23,
      "z": -5,
      "name": "Rock_Stone_Mossy"
    },
    {
      "x": -7,
      "y": 24,
      "z": -5,
      "name": "Rock_Stone_Mossy"
    },
    {
      "x": -7,
      "y": 25,
      "z": -5,
      "name": "Soil_Dirt"
    },
    {
      "x": -7,
      "y": 26,
      "z": -5,
      "name": "Soil_Grass"
    },
    {
      "x": -7,
      "y": 27,
      "z": -5,
      "name": "Plant_Grass_Sharp"
    },
    {
      "x": -7,
      "y": 17,
      "z": -4,
      "name": "Rock_Stone"
    },
    {
      "x": -7,
      "y": 18,
      "z": -4,
      "name": "Rock_Stone"
    },
    {
      "x": -7,
      "y": 19,
      "z": -4,
      "name": "Rock_Stone"
    },
    {
      "x": -7,
      "y": 20,
      "z": -4,
      "name": "Rock_Stone"
    },
    {
      "x": -7,
      "y": 21,
      "z": -4,
      "name": "Rock_Stone"
    },
    {
      "x": -7,
      "y": 22,
      "z": -4,
      "name": "Rock_Stone"
    },
    {
      "x": -7,
      "y": 23,
      "z": -4,
      "name": "Rock_Stone"
    },
    {
      "x": -7,
      "y": 24,
      "z": -4,
      "name": "Rock_Stone_Mossy"
    },
    {
      "x": -7,
      "y": 25,
      "z": -4,
      "name": "Soil_Dirt"
    },
    {
      "x": -7,
      "y": 26,
      "z": -4,
      "name": "Soil_Grass"
    },
    {
      "x": -7,
      "y": 27,
      "z": -4,
      "name": "Plant_Grass_Sharp"
    },
    {
      "x": -7,
      "y": 15,
      "z": -3,
      "name": "Rock_Stone"
    },
    {
      "x": -7,
      "y": 16,
      "z": -3,
      "name": "Rock_Stone"
    },
    {
      "x": -7,
      "y": 17,
      "z": -3,
      "name": "Rock_Stone"
    },
    {
      "x": -7,
      "y": 18,
      "z": -3,
      "name": "Rock_Stone"
    },
    {
      "x": -7,
      "y": 19,
      "z": -3,
      "name": "Rock_Stone"
    },
    {
      "x": -7,
      "y": 20,
      "z": -3,
      "name": "Rock_Stone"
    },
    {
      "x": -7,
      "y": 21,
      "z": -3,
      "name": "Rock_Stone"
    },
    {
      "x": -7,
      "y": 22,
      "z": -3,
      "name": "Rock_Stone"
    },
    {
      "x": -7,
      "y": 23,
      "z": -3,
      "name": "Rock_Stone"
    },
    {
      "x": -7,
      "y": 24,
      "z": -3,
      "name": "Rock_Stone"
    },
    {
      "x": -7,
      "y": 25,
      "z": -3,
      "name": "Rock_Stone"
    },
    {
      "x": -7,
      "y": 26,
      "z": -3,
      "name": "Soil_Grass"
    },
    {
      "x": -7,
      "y": 13,
      "z": -2,
      "name": "Rock_Stone"
    },
    {
      "x": -7,
      "y": 14,
      "z": -2,
      "name": "Rock_Stone"
    },
    {
      "x": -7,
      "y": 15,
      "z": -2,
      "name": "Rock_Stone"
    },
    {
      "x": -7,
      "y": 16,
      "z": -2,
      "name": "Rock_Stone"
    },
    {
      "x": -7,
      "y": 17,
      "z": -2,
      "name": "Rock_Stone"
    },
    {
      "x": -7,
      "y": 18,
      "z": -2,
      "name": "Rock_Stone"
    },
    {
      "x": -7,
      "y": 19,
      "z": -2,
      "name": "Rock_Stone"
    },
    {
      "x": -7,
      "y": 20,
      "z": -2,
      "name": "Rock_Stone"
    },
    {
      "x": -7,
      "y": 21,
      "z": -2,
      "name": "Rock_Stone"
    },
    {
      "x": -7,
      "y": 22,
      "z": -2,
      "name": "Rock_Stone"
    },
    {
      "x": -7,
      "y": 23,
      "z": -2,
      "name": "Rock_Stone"
    },
    {
      "x": -7,
      "y": 24,
      "z": -2,
      "name": "Rock_Stone"
    },
    {
      "x": -7,
      "y": 25,
      "z": -2,
      "name": "Rock_Stone"
    },
    {
      "x": -7,
      "y": 26,
      "z": -2,
      "name": "Soil_Grass"
    },
    {
      "x": -7,
      "y": 27,
      "z": -2,
      "name": "Plant_Grass_Sharp_Tall"
    },
    {
      "x": -7,
      "y": 28,
      "z": -2,
      "name": "Plant_Grass_Sharp_Tall",
      "filler": 1024
    },
    {
      "x": -7,
      "y": 30,
      "z": -2,
      "name": "Rock_Stone"
    },
    {
      "x": -7,
      "y": 31,
      "z": -2,
      "name": "Rock_Stone"
    },
    {
      "x": -7,
      "y": 32,
      "z": -2,
      "name": "Rock_Stone"
    },
    {
      "x": -7,
      "y": 33,
      "z": -2,
      "name": "Rock_Stone"
    },
    {
      "x": -7,
      "y": 34,
      "z": -2,
      "name": "Soil_Dirt"
    },
    {
      "x": -7,
      "y": 13,
      "z": -1,
      "name": "Rock_Stone"
    },
    {
      "x": -7,
      "y": 14,
      "z": -1,
      "name": "Rock_Stone"
    },
    {
      "x": -7,
      "y": 15,
      "z": -1,
      "name": "Rock_Stone"
    },
    {
      "x": -7,
      "y": 16,
      "z": -1,
      "name": "Rock_Stone"
    },
    {
      "x": -7,
      "y": 17,
      "z": -1,
      "name": "Rock_Stone"
    },
    {
      "x": -7,
      "y": 18,
      "z": -1,
      "name": "Rock_Stone"
    },
    {
      "x": -7,
      "y": 19,
      "z": -1,
      "name": "Rock_Stone"
    },
    {
      "x": -7,
      "y": 20,
      "z": -1,
      "name": "Rock_Stone"
    },
    {
      "x": -7,
      "y": 21,
      "z": -1,
      "name": "Rock_Stone"
    },
    {
      "x": -7,
      "y": 22,
      "z": -1,
      "name": "Rock_Stone"
    },
    {
      "x": -7,
      "y": 23,
      "z": -1,
      "name": "Rock_Stone"
    },
    {
      "x": -7,
      "y": 24,
      "z": -1,
      "name": "Rock_Stone"
    },
    {
      "x": -7,
      "y": 25,
      "z": -1,
      "name": "Soil_Dirt"
    },
    {
      "x": -7,
      "y": 26,
      "z": -1,
      "name": "Soil_Grass"
    },
    {
      "x": -7,
      "y": 27,
      "z": -1,
      "name": "Empty"
    },
    {
      "x": -7,
      "y": 28,
      "z": -1,
      "name": "Rock_Stone_Mossy"
    },
    {
      "x": -7,
      "y": 29,
      "z": -1,
      "name": "Rock_Stone_Mossy"
    },
    {
      "x": -7,
      "y": 30,
      "z": -1,
      "name": "Rock_Stone"
    },
    {
      "x": -7,
      "y": 31,
      "z": -1,
      "name": "Rock_Stone"
    },
    {
      "x": -7,
      "y": 32,
      "z": -1,
      "name": "Rock_Stone"
    },
    {
      "x": -7,
      "y": 33,
      "z": -1,
      "name": "Rock_Stone"
    },
    {
      "x": -7,
      "y": 34,
      "z": -1,
      "name": "Soil_Dirt"
    },
    {
      "x": -7,
      "y": 35,
      "z": -1,
      "name": "Soil_Grass"
    },
    {
      "x": -7,
      "y": 14,
      "z": 0,
      "name": "Rock_Stone"
    },
    {
      "x": -7,
      "y": 15,
      "z": 0,
      "name": "Rock_Stone"
    },
    {
      "x": -7,
      "y": 16,
      "z": 0,
      "name": "Rock_Stone"
    },
    {
      "x": -7,
      "y": 17,
      "z": 0,
      "name": "Rock_Stone"
    },
    {
      "x": -7,
      "y": 18,
      "z": 0,
      "name": "Rock_Stone"
    },
    {
      "x": -7,
      "y": 19,
      "z": 0,
      "name": "Rock_Stone"
    },
    {
      "x": -7,
      "y": 20,
      "z": 0,
      "name": "Rock_Stone"
    },
    {
      "x": -7,
      "y": 21,
      "z": 0,
      "name": "Rock_Stone"
    },
    {
      "x": -7,
      "y": 22,
      "z": 0,
      "name": "Rock_Stone"
    },
    {
      "x": -7,
      "y": 23,
      "z": 0,
      "name": "Rock_Stone"
    },
    {
      "x": -7,
      "y": 24,
      "z": 0,
      "name": "Rock_Stone"
    },
    {
      "x": -7,
      "y": 25,
      "z": 0,
      "name": "Soil_Dirt"
    },
    {
      "x": -7,
      "y": 26,
      "z": 0,
      "name": "Soil_Grass"
    },
    {
      "x": -7,
      "y": 27,
      "z": 0,
      "name": "Plant_Grass_Sharp"
    },
    {
      "x": -7,
      "y": 28,
      "z": 0,
      "name": "Rock_Stone_Mossy"
    },
    {
      "x": -7,
      "y": 29,
      "z": 0,
      "name": "Rock_Stone"
    },
    {
      "x": -7,
      "y": 30,
      "z": 0,
      "name": "Rock_Stone"
    },
    {
      "x": -7,
      "y": 31,
      "z": 0,
      "name": "Rock_Stone"
    },
    {
      "x": -7,
      "y": 32,
      "z": 0,
      "name": "Rock_Stone"
    },
    {
      "x": -7,
      "y": 33,
      "z": 0,
      "name": "Rock_Stone"
    },
    {
      "x": -7,
      "y": 34,
      "z": 0,
      "name": "Soil_Dirt"
    },
    {
      "x": -7,
      "y": 35,
      "z": 0,
      "name": "Soil_Dirt"
    },
    {
      "x": -7,
      "y": 36,
      "z": 0,
      "name": "Soil_Grass"
    },
    {
      "x": -7,
      "y": 37,
      "z": 0,
      "name": "*Plant_Crop_Berry_Block_State_Definitions_StageFinal",
      "components": {
        "Components": {
          "FarmingBlock": {}
        }
      }
    },
    {
      "x": -7,
      "y": 14,
      "z": 1,
      "name": "Rock_Stone"
    },
    {
      "x": -7,
      "y": 15,
      "z": 1,
      "name": "Rock_Stone"
    },
    {
      "x": -7,
      "y": 16,
      "z": 1,
      "name": "Rock_Stone"
    },
    {
      "x": -7,
      "y": 17,
      "z": 1,
      "name": "Rock_Stone"
    },
    {
      "x": -7,
      "y": 18,
      "z": 1,
      "name": "Rock_Stone"
    },
    {
      "x": -7,
      "y": 19,
      "z": 1,
      "name": "Rock_Stone"
    },
    {
      "x": -7,
      "y": 20,
      "z": 1,
      "name": "Rock_Stone"
    },
    {
      "x": -7,
      "y": 21,
      "z": 1,
      "name": "Rock_Stone"
    },
    {
      "x": -7,
      "y": 22,
      "z": 1,
      "name": "Rock_Stone"
    },
    {
      "x": -7,
      "y": 23,
      "z": 1,
      "name": "Rock_Stone"
    },
    {
      "x": -7,
      "y": 24,
      "z": 1,
      "name": "Rock_Stone"
    },
    {
      "x": -7,
      "y": 25,
      "z": 1,
      "name": "Soil_Dirt"
    },
    {
      "x": -7,
      "y": 26,
      "z": 1,
      "name": "Soil_Grass"
    },
    {
      "x": -7,
      "y": 29,
      "z": 1,
      "name": "Rock_Stone"
    },
    {
      "x": -7,
      "y": 30,
      "z": 1,
      "name": "Rock_Stone"
    },
    {
      "x": -7,
      "y": 31,
      "z": 1,
      "name": "Rock_Stone"
    },
    {
      "x": -7,
      "y": 32,
      "z": 1,
      "name": "Rock_Stone"
    },
    {
      "x": -7,
      "y": 33,
      "z": 1,
      "name": "Rock_Stone"
    },
    {
      "x": -7,
      "y": 34,
      "z": 1,
      "name": "Soil_Dirt"
    },
    {
      "x": -7,
      "y": 35,
      "z": 1,
      "name": "Soil_Dirt"
    },
    {
      "x": -7,
      "y": 36,
      "z": 1,
      "name": "Soil_Grass"
    },
    {
      "x": -7,
      "y": 37,
      "z": 1,
      "name": "*Plant_Crop_Berry_Block_State_Definitions_StageFinal",
      "components": {
        "Components": {
          "FarmingBlock": {}
        }
      }
    },
    {
      "x": -7,
      "y": 14,
      "z": 2,
      "name": "Rock_Stone"
    },
    {
      "x": -7,
      "y": 15,
      "z": 2,
      "name": "Rock_Stone"
    },
    {
      "x": -7,
      "y": 16,
      "z": 2,
      "name": "Rock_Stone"
    },
    {
      "x": -7,
      "y": 17,
      "z": 2,
      "name": "Rock_Stone"
    },
    {
      "x": -7,
      "y": 18,
      "z": 2,
      "name": "Rock_Stone"
    },
    {
      "x": -7,
      "y": 19,
      "z": 2,
      "name": "Rock_Stone"
    },
    {
      "x": -7,
      "y": 20,
      "z": 2,
      "name": "Rock_Stone"
    },
    {
      "x": -7,
      "y": 21,
      "z": 2,
      "name": "Rock_Stone"
    },
    {
      "x": -7,
      "y": 22,
      "z": 2,
      "name": "Rock_Stone"
    },
    {
      "x": -7,
      "y": 23,
      "z": 2,
      "name": "Rock_Stone"
    },
    {
      "x": -7,
      "y": 24,
      "z": 2,
      "name": "Soil_Dirt"
    },
    {
      "x": -7,
      "y": 25,
      "z": 2,
      "name": "Soil_Dirt"
    },
    {
      "x": -7,
      "y": 26,
      "z": 2,
      "name": "Soil_Grass"
    },
    {
      "x": -7,
      "y": 31,
      "z": 2,
      "name": "Rock_Stone"
    },
    {
      "x": -7,
      "y": 32,
      "z": 2,
      "name": "Rock_Stone"
    },
    {
      "x": -7,
      "y": 33,
      "z": 2,
      "name": "Rock_Stone"
    },
    {
      "x": -7,
      "y": 34,
      "z": 2,
      "name": "Soil_Dirt"
    },
    {
      "x": -7,
      "y": 35,
      "z": 2,
      "name": "Soil_Dirt"
    },
    {
      "x": -7,
      "y": 36,
      "z": 2,
      "name": "Soil_Grass"
    },
    {
      "x": -7,
      "y": 15,
      "z": 3,
      "name": "Rock_Stone"
    },
    {
      "x": -7,
      "y": 16,
      "z": 3,
      "name": "Rock_Stone"
    },
    {
      "x": -7,
      "y": 17,
      "z": 3,
      "name": "Rock_Stone"
    },
    {
      "x": -7,
      "y": 18,
      "z": 3,
      "name": "Rock_Stone"
    },
    {
      "x": -7,
      "y": 19,
      "z": 3,
      "name": "Rock_Stone"
    },
    {
      "x": -7,
      "y": 20,
      "z": 3,
      "name": "Rock_Stone"
    },
    {
      "x": -7,
      "y": 21,
      "z": 3,
      "name": "Rock_Stone"
    },
    {
      "x": -7,
      "y": 22,
      "z": 3,
      "name": "Rock_Stone"
    },
    {
      "x": -7,
      "y": 23,
      "z": 3,
      "name": "Rock_Stone"
    },
    {
      "x": -7,
      "y": 24,
      "z": 3,
      "name": "Soil_Dirt"
    },
    {
      "x": -7,
      "y": 25,
      "z": 3,
      "name": "Soil_Dirt"
    },
    {
      "x": -7,
      "y": 26,
      "z": 3,
      "name": "Soil_Grass"
    },
    {
      "x": -7,
      "y": 27,
      "z": 3,
      "name": "Plant_Grass_Sharp"
    },
    {
      "x": -7,
      "y": 18,
      "z": 4,
      "name": "Rock_Stone"
    },
    {
      "x": -7,
      "y": 19,
      "z": 4,
      "name": "Rock_Stone"
    },
    {
      "x": -7,
      "y": 20,
      "z": 4,
      "name": "Rock_Stone"
    },
    {
      "x": -7,
      "y": 21,
      "z": 4,
      "name": "Rock_Stone"
    },
    {
      "x": -7,
      "y": 22,
      "z": 4,
      "name": "Rock_Stone"
    },
    {
      "x": -7,
      "y": 23,
      "z": 4,
      "name": "Rock_Stone_Mossy"
    },
    {
      "x": -7,
      "y": 24,
      "z": 4,
      "name": "Soil_Dirt"
    },
    {
      "x": -7,
      "y": 25,
      "z": 4,
      "name": "Soil_Grass"
    },
    {
      "x": -6,
      "y": 13,
      "z": -5,
      "name": "Rock_Stone"
    },
    {
      "x": -6,
      "y": 14,
      "z": -5,
      "name": "Rock_Stone"
    },
    {
      "x": -6,
      "y": 15,
      "z": -5,
      "name": "Rock_Stone"
    },
    {
      "x": -6,
      "y": 16,
      "z": -5,
      "name": "Rock_Stone"
    },
    {
      "x": -6,
      "y": 17,
      "z": -5,
      "name": "Rock_Stone"
    },
    {
      "x": -6,
      "y": 18,
      "z": -5,
      "name": "Rock_Stone"
    },
    {
      "x": -6,
      "y": 19,
      "z": -5,
      "name": "Rock_Stone"
    },
    {
      "x": -6,
      "y": 20,
      "z": -5,
      "name": "Rock_Stone"
    },
    {
      "x": -6,
      "y": 22,
      "z": -5,
      "name": "Rock_Stone"
    },
    {
      "x": -6,
      "y": 23,
      "z": -5,
      "name": "Rock_Stone"
    },
    {
      "x": -6,
      "y": 24,
      "z": -5,
      "name": "Rock_Stone"
    },
    {
      "x": -6,
      "y": 25,
      "z": -5,
      "name": "Soil_Dirt"
    },
    {
      "x": -6,
      "y": 26,
      "z": -5,
      "name": "Soil_Grass"
    },
    {
      "x": -6,
      "y": 27,
      "z": -5,
      "name": "Plant_Grass_Sharp"
    },
    {
      "x": -6,
      "y": 13,
      "z": -4,
      "name": "Rock_Stone"
    },
    {
      "x": -6,
      "y": 14,
      "z": -4,
      "name": "Rock_Stone"
    },
    {
      "x": -6,
      "y": 15,
      "z": -4,
      "name": "Rock_Stone"
    },
    {
      "x": -6,
      "y": 16,
      "z": -4,
      "name": "Rock_Stone"
    },
    {
      "x": -6,
      "y": 17,
      "z": -4,
      "name": "Rock_Stone"
    },
    {
      "x": -6,
      "y": 18,
      "z": -4,
      "name": "Rock_Stone"
    },
    {
      "x": -6,
      "y": 19,
      "z": -4,
      "name": "Rock_Stone"
    },
    {
      "x": -6,
      "y": 20,
      "z": -4,
      "name": "Rock_Stone"
    },
    {
      "x": -6,
      "y": 21,
      "z": -4,
      "name": "Rock_Stone"
    },
    {
      "x": -6,
      "y": 22,
      "z": -4,
      "name": "Rock_Stone"
    },
    {
      "x": -6,
      "y": 23,
      "z": -4,
      "name": "Rock_Stone"
    },
    {
      "x": -6,
      "y": 24,
      "z": -4,
      "name": "Rock_Stone"
    },
    {
      "x": -6,
      "y": 25,
      "z": -4,
      "name": "Soil_Dirt"
    },
    {
      "x": -6,
      "y": 26,
      "z": -4,
      "name": "Soil_Dirt"
    },
    {
      "x": -6,
      "y": 27,
      "z": -4,
      "name": "Soil_Dirt"
    },
    {
      "x": -6,
      "y": 28,
      "z": -4,
      "name": "Soil_Grass"
    },
    {
      "x": -6,
      "y": 12,
      "z": -3,
      "name": "Rock_Stone"
    },
    {
      "x": -6,
      "y": 13,
      "z": -3,
      "name": "Rock_Stone"
    },
    {
      "x": -6,
      "y": 14,
      "z": -3,
      "name": "Rock_Stone"
    },
    {
      "x": -6,
      "y": 15,
      "z": -3,
      "name": "Rock_Stone"
    },
    {
      "x": -6,
      "y": 16,
      "z": -3,
      "name": "Rock_Stone"
    },
    {
      "x": -6,
      "y": 17,
      "z": -3,
      "name": "Rock_Stone"
    },
    {
      "x": -6,
      "y": 18,
      "z": -3,
      "name": "Rock_Stone"
    },
    {
      "x": -6,
      "y": 19,
      "z": -3,
      "name": "Rock_Stone"
    },
    {
      "x": -6,
      "y": 20,
      "z": -3,
      "name": "Rock_Stone"
    },
    {
      "x": -6,
      "y": 21,
      "z": -3,
      "name": "Rock_Stone"
    },
    {
      "x": -6,
      "y": 22,
      "z": -3,
      "name": "Rock_Stone"
    },
    {
      "x": -6,
      "y": 23,
      "z": -3,
      "name": "Rock_Stone"
    },
    {
      "x": -6,
      "y": 24,
      "z": -3,
      "name": "Rock_Stone"
    },
    {
      "x": -6,
      "y": 25,
      "z": -3,
      "name": "Rock_Stone"
    },
    {
      "x": -6,
      "y": 26,
      "z": -3,
      "name": "Soil_Dirt"
    },
    {
      "x": -6,
      "y": 27,
      "z": -3,
      "name": "Soil_Dirt"
    },
    {
      "x": -6,
      "y": 28,
      "z": -3,
      "name": "Soil_Dirt"
    },
    {
      "x": -6,
      "y": 29,
      "z": -3,
      "name": "Soil_Grass"
    },
    {
      "x": -6,
      "y": 30,
      "z": -3,
      "name": "Plant_Grass_Sharp"
    },
    {
      "x": -6,
      "y": 12,
      "z": -2,
      "name": "Rock_Stone"
    },
    {
      "x": -6,
      "y": 13,
      "z": -2,
      "name": "Rock_Stone"
    },
    {
      "x": -6,
      "y": 14,
      "z": -2,
      "name": "Rock_Stone"
    },
    {
      "x": -6,
      "y": 15,
      "z": -2,
      "name": "Rock_Stone"
    },
    {
      "x": -6,
      "y": 16,
      "z": -2,
      "name": "Rock_Stone"
    },
    {
      "x": -6,
      "y": 17,
      "z": -2,
      "name": "Rock_Stone"
    },
    {
      "x": -6,
      "y": 18,
      "z": -2,
      "name": "Rock_Stone"
    },
    {
      "x": -6,
      "y": 19,
      "z": -2,
      "name": "Rock_Stone"
    },
    {
      "x": -6,
      "y": 20,
      "z": -2,
      "name": "Rock_Stone"
    },
    {
      "x": -6,
      "y": 21,
      "z": -2,
      "name": "Rock_Stone"
    },
    {
      "x": -6,
      "y": 22,
      "z": -2,
      "name": "Rock_Stone"
    },
    {
      "x": -6,
      "y": 23,
      "z": -2,
      "name": "Rock_Stone"
    },
    {
      "x": -6,
      "y": 24,
      "z": -2,
      "name": "Rock_Stone"
    },
    {
      "x": -6,
      "y": 25,
      "z": -2,
      "name": "Rock_Stone"
    },
    {
      "x": -6,
      "y": 26,
      "z": -2,
      "name": "Rock_Stone"
    },
    {
      "x": -6,
      "y": 27,
      "z": -2,
      "name": "Rock_Stone_Mossy"
    },
    {
      "x": -6,
      "y": 28,
      "z": -2,
      "name": "Soil_Dirt"
    },
    {
      "x": -6,
      "y": 29,
      "z": -2,
      "name": "Soil_Dirt"
    },
    {
      "x": -6,
      "y": 30,
      "z": -2,
      "name": "Rock_Stone_Mossy"
    },
    {
      "x": -6,
      "y": 31,
      "z": -2,
      "name": "Rock_Stone"
    },
    {
      "x": -6,
      "y": 32,
      "z": -2,
      "name": "Rock_Stone"
    },
    {
      "x": -6,
      "y": 33,
      "z": -2,
      "name": "Soil_Dirt"
    },
    {
      "x": -6,
      "y": 34,
      "z": -2,
      "name": "Soil_Dirt"
    },
    {
      "x": -6,
      "y": 35,
      "z": -2,
      "name": "Soil_Grass"
    },
    {
      "x": -6,
      "y": 11,
      "z": -1,
      "name": "Rock_Stone"
    },
    {
      "x": -6,
      "y": 12,
      "z": -1,
      "name": "Rock_Stone"
    },
    {
      "x": -6,
      "y": 13,
      "z": -1,
      "name": "Rock_Stone"
    },
    {
      "x": -6,
      "y": 14,
      "z": -1,
      "name": "Rock_Stone"
    },
    {
      "x": -6,
      "y": 15,
      "z": -1,
      "name": "Rock_Stone"
    },
    {
      "x": -6,
      "y": 16,
      "z": -1,
      "name": "Rock_Stone"
    },
    {
      "x": -6,
      "y": 17,
      "z": -1,
      "name": "Rock_Stone"
    },
    {
      "x": -6,
      "y": 18,
      "z": -1,
      "name": "Rock_Stone"
    },
    {
      "x": -6,
      "y": 19,
      "z": -1,
      "name": "Rock_Stone"
    },
    {
      "x": -6,
      "y": 20,
      "z": -1,
      "name": "Rock_Stone"
    },
    {
      "x": -6,
      "y": 21,
      "z": -1,
      "name": "Rock_Stone"
    },
    {
      "x": -6,
      "y": 22,
      "z": -1,
      "name": "Rock_Stone"
    },
    {
      "x": -6,
      "y": 23,
      "z": -1,
      "name": "Rock_Stone"
    },
    {
      "x": -6,
      "y": 24,
      "z": -1,
      "name": "Rock_Stone"
    },
    {
      "x": -6,
      "y": 25,
      "z": -1,
      "name": "Rock_Stone"
    },
    {
      "x": -6,
      "y": 26,
      "z": -1,
      "name": "Soil_Dirt"
    },
    {
      "x": -6,
      "y": 27,
      "z": -1,
      "name": "Rock_Stone_Mossy"
    },
    {
      "x": -6,
      "y": 28,
      "z": -1,
      "name": "Rock_Stone_Mossy"
    },
    {
      "x": -6,
      "y": 29,
      "z": -1,
      "name": "Rock_Stone_Mossy"
    },
    {
      "x": -6,
      "y": 30,
      "z": -1,
      "name": "Rock_Stone"
    },
    {
      "x": -6,
      "y": 31,
      "z": -1,
      "name": "Rock_Stone"
    },
    {
      "x": -6,
      "y": 32,
      "z": -1,
      "name": "Rock_Stone"
    },
    {
      "x": -6,
      "y": 33,
      "z": -1,
      "name": "Soil_Dirt"
    },
    {
      "x": -6,
      "y": 34,
      "z": -1,
      "name": "Soil_Dirt"
    },
    {
      "x": -6,
      "y": 35,
      "z": -1,
      "name": "Soil_Dirt"
    },
    {
      "x": -6,
      "y": 36,
      "z": -1,
      "name": "Soil_Grass"
    },
    {
      "x": -6,
      "y": 11,
      "z": 0,
      "name": "Rock_Stone"
    },
    {
      "x": -6,
      "y": 12,
      "z": 0,
      "name": "Rock_Stone"
    },
    {
      "x": -6,
      "y": 13,
      "z": 0,
      "name": "Rock_Stone"
    },
    {
      "x": -6,
      "y": 14,
      "z": 0,
      "name": "Rock_Stone"
    },
    {
      "x": -6,
      "y": 15,
      "z": 0,
      "name": "Rock_Stone"
    },
    {
      "x": -6,
      "y": 16,
      "z": 0,
      "name": "Rock_Stone"
    },
    {
      "x": -6,
      "y": 17,
      "z": 0,
      "name": "Rock_Stone"
    },
    {
      "x": -6,
      "y": 18,
      "z": 0,
      "name": "Rock_Stone"
    },
    {
      "x": -6,
      "y": 19,
      "z": 0,
      "name": "Rock_Stone"
    },
    {
      "x": -6,
      "y": 20,
      "z": 0,
      "name": "Rock_Stone"
    },
    {
      "x": -6,
      "y": 21,
      "z": 0,
      "name": "Rock_Stone"
    },
    {
      "x": -6,
      "y": 22,
      "z": 0,
      "name": "Rock_Stone"
    },
    {
      "x": -6,
      "y": 23,
      "z": 0,
      "name": "Rock_Stone"
    },
    {
      "x": -6,
      "y": 24,
      "z": 0,
      "name": "Rock_Stone"
    },
    {
      "x": -6,
      "y": 25,
      "z": 0,
      "name": "Rock_Stone"
    },
    {
      "x": -6,
      "y": 26,
      "z": 0,
      "name": "Soil_Dirt"
    },
    {
      "x": -6,
      "y": 27,
      "z": 0,
      "name": "Rock_Stone_Mossy"
    },
    {
      "x": -6,
      "y": 28,
      "z": 0,
      "name": "Rock_Stone"
    },
    {
      "x": -6,
      "y": 29,
      "z": 0,
      "name": "Rock_Stone"
    },
    {
      "x": -6,
      "y": 30,
      "z": 0,
      "name": "Rock_Stone"
    },
    {
      "x": -6,
      "y": 31,
      "z": 0,
      "name": "Rock_Stone"
    },
    {
      "x": -6,
      "y": 32,
      "z": 0,
      "name": "Rock_Stone"
    },
    {
      "x": -6,
      "y": 33,
      "z": 0,
      "name": "Rock_Stone"
    },
    {
      "x": -6,
      "y": 34,
      "z": 0,
      "name": "Rock_Stone"
    },
    {
      "x": -6,
      "y": 35,
      "z": 0,
      "name": "Soil_Dirt"
    },
    {
      "x": -6,
      "y": 36,
      "z": 0,
      "name": "Soil_Grass"
    },
    {
      "x": -6,
      "y": 37,
      "z": 0,
      "name": "Plant_Grass_Sharp"
    },
    {
      "x": -6,
      "y": 11,
      "z": 1,
      "name": "Rock_Stone"
    },
    {
      "x": -6,
      "y": 12,
      "z": 1,
      "name": "Rock_Stone"
    },
    {
      "x": -6,
      "y": 13,
      "z": 1,
      "name": "Rock_Stone"
    },
    {
      "x": -6,
      "y": 14,
      "z": 1,
      "name": "Rock_Stone"
    },
    {
      "x": -6,
      "y": 15,
      "z": 1,
      "name": "Rock_Stone"
    },
    {
      "x": -6,
      "y": 16,
      "z": 1,
      "name": "Rock_Stone"
    },
    {
      "x": -6,
      "y": 17,
      "z": 1,
      "name": "Rock_Stone"
    },
    {
      "x": -6,
      "y": 18,
      "z": 1,
      "name": "Rock_Stone"
    },
    {
      "x": -6,
      "y": 19,
      "z": 1,
      "name": "Rock_Stone"
    },
    {
      "x": -6,
      "y": 20,
      "z": 1,
      "name": "Rock_Stone"
    },
    {
      "x": -6,
      "y": 21,
      "z": 1,
      "name": "Rock_Stone"
    },
    {
      "x": -6,
      "y": 22,
      "z": 1,
      "name": "Rock_Stone"
    },
    {
      "x": -6,
      "y": 23,
      "z": 1,
      "name": "Rock_Stone"
    },
    {
      "x": -6,
      "y": 24,
      "z": 1,
      "name": "Rock_Stone"
    },
    {
      "x": -6,
      "y": 25,
      "z": 1,
      "name": "Rock_Stone"
    },
    {
      "x": -6,
      "y": 26,
      "z": 1,
      "name": "Soil_Dirt"
    },
    {
      "x": -6,
      "y": 27,
      "z": 1,
      "name": "Rock_Stone"
    },
    {
      "x": -6,
      "y": 28,
      "z": 1,
      "name": "Rock_Stone"
    },
    {
      "x": -6,
      "y": 29,
      "z": 1,
      "name": "Rock_Stone"
    },
    {
      "x": -6,
      "y": 30,
      "z": 1,
      "name": "Rock_Stone"
    },
    {
      "x": -6,
      "y": 31,
      "z": 1,
      "name": "Rock_Stone"
    },
    {
      "x": -6,
      "y": 32,
      "z": 1,
      "name": "Rock_Stone"
    },
    {
      "x": -6,
      "y": 33,
      "z": 1,
      "name": "Rock_Stone"
    },
    {
      "x": -6,
      "y": 34,
      "z": 1,
      "name": "Soil_Dirt"
    },
    {
      "x": -6,
      "y": 35,
      "z": 1,
      "name": "Soil_Dirt"
    },
    {
      "x": -6,
      "y": 36,
      "z": 1,
      "name": "Soil_Grass"
    },
    {
      "x": -6,
      "y": 37,
      "z": 1,
      "name": "*Plant_Crop_Berry_Block_State_Definitions_StageFinal",
      "components": {
        "Components": {
          "FarmingBlock": {}
        }
      }
    },
    {
      "x": -6,
      "y": 13,
      "z": 2,
      "name": "Rock_Stone"
    },
    {
      "x": -6,
      "y": 14,
      "z": 2,
      "name": "Rock_Stone"
    },
    {
      "x": -6,
      "y": 15,
      "z": 2,
      "name": "Rock_Stone"
    },
    {
      "x": -6,
      "y": 16,
      "z": 2,
      "name": "Rock_Stone"
    },
    {
      "x": -6,
      "y": 17,
      "z": 2,
      "name": "Rock_Stone"
    },
    {
      "x": -6,
      "y": 18,
      "z": 2,
      "name": "Rock_Stone"
    },
    {
      "x": -6,
      "y": 19,
      "z": 2,
      "name": "Rock_Stone"
    },
    {
      "x": -6,
      "y": 20,
      "z": 2,
      "name": "Rock_Stone"
    },
    {
      "x": -6,
      "y": 21,
      "z": 2,
      "name": "Rock_Stone"
    },
    {
      "x": -6,
      "y": 22,
      "z": 2,
      "name": "Rock_Stone"
    },
    {
      "x": -6,
      "y": 23,
      "z": 2,
      "name": "Rock_Stone"
    },
    {
      "x": -6,
      "y": 24,
      "z": 2,
      "name": "Rock_Stone"
    },
    {
      "x": -6,
      "y": 25,
      "z": 2,
      "name": "Soil_Dirt"
    },
    {
      "x": -6,
      "y": 26,
      "z": 2,
      "name": "Soil_Grass"
    },
    {
      "x": -6,
      "y": 28,
      "z": 2,
      "name": "Rock_Stone"
    },
    {
      "x": -6,
      "y": 29,
      "z": 2,
      "name": "Rock_Stone"
    },
    {
      "x": -6,
      "y": 30,
      "z": 2,
      "name": "Rock_Stone"
    },
    {
      "x": -6,
      "y": 31,
      "z": 2,
      "name": "Rock_Stone"
    },
    {
      "x": -6,
      "y": 32,
      "z": 2,
      "name": "Rock_Stone"
    },
    {
      "x": -6,
      "y": 33,
      "z": 2,
      "name": "Rock_Stone"
    },
    {
      "x": -6,
      "y": 34,
      "z": 2,
      "name": "Soil_Dirt"
    },
    {
      "x": -6,
      "y": 35,
      "z": 2,
      "name": "Soil_Dirt"
    },
    {
      "x": -6,
      "y": 36,
      "z": 2,
      "name": "Soil_Grass"
    },
    {
      "x": -6,
      "y": 13,
      "z": 3,
      "name": "Rock_Stone"
    },
    {
      "x": -6,
      "y": 14,
      "z": 3,
      "name": "Rock_Stone"
    },
    {
      "x": -6,
      "y": 15,
      "z": 3,
      "name": "Rock_Stone"
    },
    {
      "x": -6,
      "y": 16,
      "z": 3,
      "name": "Rock_Stone"
    },
    {
      "x": -6,
      "y": 17,
      "z": 3,
      "name": "Rock_Stone"
    },
    {
      "x": -6,
      "y": 18,
      "z": 3,
      "name": "Rock_Stone"
    },
    {
      "x": -6,
      "y": 19,
      "z": 3,
      "name": "Rock_Stone_Mossy"
    },
    {
      "x": -6,
      "y": 20,
      "z": 3,
      "name": "Rock_Stone"
    },
    {
      "x": -6,
      "y": 21,
      "z": 3,
      "name": "Rock_Stone_Mossy"
    },
    {
      "x": -6,
      "y": 22,
      "z": 3,
      "name": "Rock_Stone"
    },
    {
      "x": -6,
      "y": 23,
      "z": 3,
      "name": "Rock_Stone_Mossy"
    },
    {
      "x": -6,
      "y": 24,
      "z": 3,
      "name": "Soil_Dirt"
    },
    {
      "x": -6,
      "y": 25,
      "z": 3,
      "name": "Soil_Dirt"
    },
    {
      "x": -6,
      "y": 26,
      "z": 3,
      "name": "Soil_Grass"
    },
    {
      "x": -6,
      "y": 13,
      "z": 4,
      "name": "Rock_Stone"
    },
    {
      "x": -6,
      "y": 14,
      "z": 4,
      "name": "Rock_Stone"
    },
    {
      "x": -6,
      "y": 15,
      "z": 4,
      "name": "Rock_Stone"
    },
    {
      "x": -6,
      "y": 16,
      "z": 4,
      "name": "Rock_Stone"
    },
    {
      "x": -6,
      "y": 17,
      "z": 4,
      "name": "Rock_Stone"
    },
    {
      "x": -6,
      "y": 18,
      "z": 4,
      "name": "Rock_Stone_Mossy"
    },
    {
      "x": -6,
      "y": 19,
      "z": 4,
      "name": "Rock_Stone_Mossy"
    },
    {
      "x": -6,
      "y": 20,
      "z": 4,
      "name": "Rock_Stone"
    },
    {
      "x": -6,
      "y": 21,
      "z": 4,
      "name": "Rock_Stone"
    },
    {
      "x": -6,
      "y": 22,
      "z": 4,
      "name": "Rock_Stone_Mossy"
    },
    {
      "x": -6,
      "y": 23,
      "z": 4,
      "name": "Rock_Stone_Mossy"
    },
    {
      "x": -6,
      "y": 24,
      "z": 4,
      "name": "Soil_Dirt"
    },
    {
      "x": -6,
      "y": 25,
      "z": 4,
      "name": "Soil_Dirt"
    },
    {
      "x": -6,
      "y": 26,
      "z": 4,
      "name": "Soil_Grass"
    },
    {
      "x": -6,
      "y": 32,
      "z": 6,
      "name": "Plant_Leaves_Birch"
    },
    {
      "x": -6,
      "y": 35,
      "z": 6,
      "name": "Plant_Leaves_Birch"
    },
    {
      "x": -6,
      "y": 30,
      "z": 8,
      "name": "Plant_Leaves_Birch"
    },
    {
      "x": -5,
      "y": 19,
      "z": -6,
      "name": "Rock_Stone_Mossy"
    },
    {
      "x": -5,
      "y": 20,
      "z": -6,
      "name": "Soil_Dirt"
    },
    {
      "x": -5,
      "y": 21,
      "z": -6,
      "name": "Soil_Dirt"
    },
    {
      "x": -5,
      "y": 22,
      "z": -6,
      "name": "Soil_Grass"
    },
    {
      "x": -5,
      "y": 13,
      "z": -5,
      "name": "Rock_Stone"
    },
    {
      "x": -5,
      "y": 14,
      "z": -5,
      "name": "Rock_Stone"
    },
    {
      "x": -5,
      "y": 15,
      "z": -5,
      "name": "Rock_Stone"
    },
    {
      "x": -5,
      "y": 16,
      "z": -5,
      "name": "Rock_Stone"
    },
    {
      "x": -5,
      "y": 17,
      "z": -5,
      "name": "Rock_Stone"
    },
    {
      "x": -5,
      "y": 18,
      "z": -5,
      "name": "Rock_Stone"
    },
    {
      "x": -5,
      "y": 19,
      "z": -5,
      "name": "Rock_Stone"
    },
    {
      "x": -5,
      "y": 20,
      "z": -5,
      "name": "Soil_Dirt"
    },
    {
      "x": -5,
      "y": 21,
      "z": -5,
      "name": "Soil_Dirt"
    },
    {
      "x": -5,
      "y": 22,
      "z": -5,
      "name": "Soil_Grass"
    },
    {
      "x": -5,
      "y": 25,
      "z": -5,
      "name": "Rock_Stone"
    },
    {
      "x": -5,
      "y": 26,
      "z": -5,
      "name": "Soil_Grass"
    },
    {
      "x": -5,
      "y": 12,
      "z": -4,
      "name": "Rock_Stone"
    },
    {
      "x": -5,
      "y": 13,
      "z": -4,
      "name": "Rock_Stone"
    },
    {
      "x": -5,
      "y": 14,
      "z": -4,
      "name": "Rock_Stone"
    },
    {
      "x": -5,
      "y": 15,
      "z": -4,
      "name": "Rock_Stone"
    },
    {
      "x": -5,
      "y": 16,
      "z": -4,
      "name": "Rock_Stone"
    },
    {
      "x": -5,
      "y": 17,
      "z": -4,
      "name": "Rock_Stone"
    },
    {
      "x": -5,
      "y": 18,
      "z": -4,
      "name": "Rock_Stone"
    },
    {
      "x": -5,
      "y": 19,
      "z": -4,
      "name": "Rock_Stone"
    },
    {
      "x": -5,
      "y": 20,
      "z": -4,
      "name": "Rock_Stone"
    },
    {
      "x": -5,
      "y": 21,
      "z": -4,
      "name": "Soil_Dirt"
    },
    {
      "x": -5,
      "y": 22,
      "z": -4,
      "name": "Rock_Stone"
    },
    {
      "x": -5,
      "y": 23,
      "z": -4,
      "name": "Rock_Stone"
    },
    {
      "x": -5,
      "y": 24,
      "z": -4,
      "name": "Rock_Stone"
    },
    {
      "x": -5,
      "y": 25,
      "z": -4,
      "name": "Rock_Stone"
    },
    {
      "x": -5,
      "y": 26,
      "z": -4,
      "name": "Soil_Dirt"
    },
    {
      "x": -5,
      "y": 27,
      "z": -4,
      "name": "Soil_Dirt"
    },
    {
      "x": -5,
      "y": 28,
      "z": -4,
      "name": "Soil_Dirt"
    },
    {
      "x": -5,
      "y": 29,
      "z": -4,
      "name": "Soil_Grass"
    },
    {
      "x": -5,
      "y": 30,
      "z": -4,
      "name": "Plant_Grass_Sharp_Tall"
    },
    {
      "x": -5,
      "y": 31,
      "z": -4,
      "name": "Plant_Grass_Sharp_Tall",
      "filler": 1024
    },
    {
      "x": -5,
      "y": 11,
      "z": -3,
      "name": "Rock_Stone"
    },
    {
      "x": -5,
      "y": 12,
      "z": -3,
      "name": "Rock_Stone"
    },
    {
      "x": -5,
      "y": 13,
      "z": -3,
      "name": "Rock_Stone"
    },
    {
      "x": -5,
      "y": 14,
      "z": -3,
      "name": "Rock_Stone"
    },
    {
      "x": -5,
      "y": 15,
      "z": -3,
      "name": "Rock_Stone"
    },
    {
      "x": -5,
      "y": 16,
      "z": -3,
      "name": "Rock_Stone"
    },
    {
      "x": -5,
      "y": 17,
      "z": -3,
      "name": "Rock_Stone"
    },
    {
      "x": -5,
      "y": 18,
      "z": -3,
      "name": "Rock_Stone"
    },
    {
      "x": -5,
      "y": 19,
      "z": -3,
      "name": "Rock_Stone"
    },
    {
      "x": -5,
      "y": 20,
      "z": -3,
      "name": "Rock_Stone"
    },
    {
      "x": -5,
      "y": 21,
      "z": -3,
      "name": "Rock_Stone"
    },
    {
      "x": -5,
      "y": 22,
      "z": -3,
      "name": "Rock_Stone"
    },
    {
      "x": -5,
      "y": 23,
      "z": -3,
      "name": "Rock_Stone"
    },
    {
      "x": -5,
      "y": 24,
      "z": -3,
      "name": "Rock_Stone"
    },
    {
      "x": -5,
      "y": 25,
      "z": -3,
      "name": "Rock_Stone"
    },
    {
      "x": -5,
      "y": 26,
      "z": -3,
      "name": "Rock_Stone"
    },
    {
      "x": -5,
      "y": 27,
      "z": -3,
      "name": "Soil_Dirt"
    },
    {
      "x": -5,
      "y": 28,
      "z": -3,
      "name": "Soil_Dirt"
    },
    {
      "x": -5,
      "y": 29,
      "z": -3,
      "name": "Soil_Grass"
    },
    {
      "x": -5,
      "y": 30,
      "z": -3,
      "name": "Plant_Grass_Sharp_Tall"
    },
    {
      "x": -5,
      "y": 31,
      "z": -3,
      "name": "Plant_Grass_Sharp_Tall",
      "filler": 1024
    },
    {
      "x": -5,
      "y": 10,
      "z": -2,
      "name": "Rock_Stone"
    },
    {
      "x": -5,
      "y": 11,
      "z": -2,
      "name": "Rock_Stone"
    },
    {
      "x": -5,
      "y": 12,
      "z": -2,
      "name": "Rock_Stone"
    },
    {
      "x": -5,
      "y": 13,
      "z": -2,
      "name": "Rock_Stone"
    },
    {
      "x": -5,
      "y": 14,
      "z": -2,
      "name": "Rock_Stone"
    },
    {
      "x": -5,
      "y": 15,
      "z": -2,
      "name": "Rock_Stone"
    },
    {
      "x": -5,
      "y": 16,
      "z": -2,
      "name": "Rock_Stone"
    },
    {
      "x": -5,
      "y": 17,
      "z": -2,
      "name": "Rock_Stone"
    },
    {
      "x": -5,
      "y": 18,
      "z": -2,
      "name": "Rock_Stone"
    },
    {
      "x": -5,
      "y": 19,
      "z": -2,
      "name": "Rock_Stone"
    },
    {
      "x": -5,
      "y": 20,
      "z": -2,
      "name": "Rock_Stone"
    },
    {
      "x": -5,
      "y": 21,
      "z": -2,
      "name": "Rock_Stone"
    },
    {
      "x": -5,
      "y": 22,
      "z": -2,
      "name": "Rock_Stone"
    },
    {
      "x": -5,
      "y": 23,
      "z": -2,
      "name": "Rock_Stone"
    },
    {
      "x": -5,
      "y": 24,
      "z": -2,
      "name": "Rock_Stone"
    },
    {
      "x": -5,
      "y": 25,
      "z": -2,
      "name": "Rock_Stone"
    },
    {
      "x": -5,
      "y": 26,
      "z": -2,
      "name": "Rock_Stone"
    },
    {
      "x": -5,
      "y": 27,
      "z": -2,
      "name": "Rock_Stone"
    },
    {
      "x": -5,
      "y": 28,
      "z": -2,
      "name": "Soil_Dirt"
    },
    {
      "x": -5,
      "y": 29,
      "z": -2,
      "name": "Soil_Dirt"
    },
    {
      "x": -5,
      "y": 30,
      "z": -2,
      "name": "Rock_Stone"
    },
    {
      "x": -5,
      "y": 31,
      "z": -2,
      "name": "Rock_Stone"
    },
    {
      "x": -5,
      "y": 32,
      "z": -2,
      "name": "Soil_Dirt"
    },
    {
      "x": -5,
      "y": 33,
      "z": -2,
      "name": "Soil_Dirt"
    },
    {
      "x": -5,
      "y": 34,
      "z": -2,
      "name": "Soil_Dirt"
    },
    {
      "x": -5,
      "y": 35,
      "z": -2,
      "name": "Soil_Grass"
    },
    {
      "x": -5,
      "y": 10,
      "z": -1,
      "name": "Rock_Stone"
    },
    {
      "x": -5,
      "y": 11,
      "z": -1,
      "name": "Rock_Stone"
    },
    {
      "x": -5,
      "y": 12,
      "z": -1,
      "name": "Rock_Stone"
    },
    {
      "x": -5,
      "y": 13,
      "z": -1,
      "name": "Rock_Stone"
    },
    {
      "x": -5,
      "y": 14,
      "z": -1,
      "name": "Rock_Stone"
    },
    {
      "x": -5,
      "y": 15,
      "z": -1,
      "name": "Rock_Stone"
    },
    {
      "x": -5,
      "y": 16,
      "z": -1,
      "name": "Rock_Stone"
    },
    {
      "x": -5,
      "y": 17,
      "z": -1,
      "name": "Rock_Stone"
    },
    {
      "x": -5,
      "y": 18,
      "z": -1,
      "name": "Rock_Stone"
    },
    {
      "x": -5,
      "y": 19,
      "z": -1,
      "name": "Rock_Stone"
    },
    {
      "x": -5,
      "y": 20,
      "z": -1,
      "name": "Rock_Stone"
    },
    {
      "x": -5,
      "y": 21,
      "z": -1,
      "name": "Rock_Stone"
    },
    {
      "x": -5,
      "y": 22,
      "z": -1,
      "name": "Rock_Stone"
    },
    {
      "x": -5,
      "y": 23,
      "z": -1,
      "name": "Rock_Stone"
    },
    {
      "x": -5,
      "y": 24,
      "z": -1,
      "name": "Rock_Stone"
    },
    {
      "x": -5,
      "y": 25,
      "z": -1,
      "name": "Rock_Stone"
    },
    {
      "x": -5,
      "y": 26,
      "z": -1,
      "name": "Rock_Stone"
    },
    {
      "x": -5,
      "y": 27,
      "z": -1,
      "name": "Rock_Stone_Mossy"
    },
    {
      "x": -5,
      "y": 28,
      "z": -1,
      "name": "Rock_Stone"
    },
    {
      "x": -5,
      "y": 29,
      "z": -1,
      "name": "Rock_Stone"
    },
    {
      "x": -5,
      "y": 30,
      "z": -1,
      "name": "Rock_Stone"
    },
    {
      "x": -5,
      "y": 31,
      "z": -1,
      "name": "Rock_Stone"
    },
    {
      "x": -5,
      "y": 32,
      "z": -1,
      "name": "Soil_Dirt"
    },
    {
      "x": -5,
      "y": 33,
      "z": -1,
      "name": "Soil_Dirt"
    },
    {
      "x": -5,
      "y": 34,
      "z": -1,
      "name": "Soil_Dirt"
    },
    {
      "x": -5,
      "y": 35,
      "z": -1,
      "name": "Soil_Dirt"
    },
    {
      "x": -5,
      "y": 36,
      "z": -1,
      "name": "Soil_Grass"
    },
    {
      "x": -5,
      "y": 37,
      "z": -1,
      "name": "Plant_Grass_Sharp"
    },
    {
      "x": -5,
      "y": 10,
      "z": 0,
      "name": "Rock_Stone"
    },
    {
      "x": -5,
      "y": 11,
      "z": 0,
      "name": "Rock_Stone"
    },
    {
      "x": -5,
      "y": 12,
      "z": 0,
      "name": "Rock_Stone"
    },
    {
      "x": -5,
      "y": 13,
      "z": 0,
      "name": "Rock_Stone"
    },
    {
      "x": -5,
      "y": 14,
      "z": 0,
      "name": "Rock_Stone"
    },
    {
      "x": -5,
      "y": 15,
      "z": 0,
      "name": "Rock_Stone"
    },
    {
      "x": -5,
      "y": 16,
      "z": 0,
      "name": "Rock_Stone"
    },
    {
      "x": -5,
      "y": 17,
      "z": 0,
      "name": "Rock_Stone"
    },
    {
      "x": -5,
      "y": 18,
      "z": 0,
      "name": "Rock_Stone"
    },
    {
      "x": -5,
      "y": 19,
      "z": 0,
      "name": "Rock_Stone"
    },
    {
      "x": -5,
      "y": 20,
      "z": 0,
      "name": "Rock_Stone"
    },
    {
      "x": -5,
      "y": 21,
      "z": 0,
      "name": "Rock_Stone"
    },
    {
      "x": -5,
      "y": 22,
      "z": 0,
      "name": "Rock_Stone"
    },
    {
      "x": -5,
      "y": 23,
      "z": 0,
      "name": "Rock_Stone"
    },
    {
      "x": -5,
      "y": 24,
      "z": 0,
      "name": "Rock_Stone"
    },
    {
      "x": -5,
      "y": 25,
      "z": 0,
      "name": "Rock_Stone"
    },
    {
      "x": -5,
      "y": 26,
      "z": 0,
      "name": "Rock_Stone"
    },
    {
      "x": -5,
      "y": 27,
      "z": 0,
      "name": "Rock_Stone"
    },
    {
      "x": -5,
      "y": 28,
      "z": 0,
      "name": "Rock_Stone"
    },
    {
      "x": -5,
      "y": 29,
      "z": 0,
      "name": "Rock_Stone"
    },
    {
      "x": -5,
      "y": 30,
      "z": 0,
      "name": "Rock_Stone"
    },
    {
      "x": -5,
      "y": 31,
      "z": 0,
      "name": "Rock_Stone"
    },
    {
      "x": -5,
      "y": 32,
      "z": 0,
      "name": "Rock_Stone"
    },
    {
      "x": -5,
      "y": 33,
      "z": 0,
      "name": "Soil_Dirt"
    },
    {
      "x": -5,
      "y": 34,
      "z": 0,
      "name": "Soil_Dirt"
    },
    {
      "x": -5,
      "y": 35,
      "z": 0,
      "name": "Soil_Dirt"
    },
    {
      "x": -5,
      "y": 36,
      "z": 0,
      "name": "Soil_Grass"
    },
    {
      "x": -5,
      "y": 37,
      "z": 0,
      "name": "Plant_Grass_Sharp"
    },
    {
      "x": -5,
      "y": 10,
      "z": 1,
      "name": "Rock_Stone"
    },
    {
      "x": -5,
      "y": 11,
      "z": 1,
      "name": "Rock_Stone"
    },
    {
      "x": -5,
      "y": 12,
      "z": 1,
      "name": "Rock_Stone"
    },
    {
      "x": -5,
      "y": 13,
      "z": 1,
      "name": "Rock_Stone"
    },
    {
      "x": -5,
      "y": 14,
      "z": 1,
      "name": "Rock_Stone"
    },
    {
      "x": -5,
      "y": 15,
      "z": 1,
      "name": "Rock_Stone"
    },
    {
      "x": -5,
      "y": 16,
      "z": 1,
      "name": "Rock_Stone"
    },
    {
      "x": -5,
      "y": 17,
      "z": 1,
      "name": "Rock_Stone"
    },
    {
      "x": -5,
      "y": 18,
      "z": 1,
      "name": "Rock_Stone"
    },
    {
      "x": -5,
      "y": 19,
      "z": 1,
      "name": "Rock_Stone"
    },
    {
      "x": -5,
      "y": 20,
      "z": 1,
      "name": "Rock_Stone"
    },
    {
      "x": -5,
      "y": 21,
      "z": 1,
      "name": "Rock_Stone"
    },
    {
      "x": -5,
      "y": 22,
      "z": 1,
      "name": "Rock_Stone"
    },
    {
      "x": -5,
      "y": 23,
      "z": 1,
      "name": "Rock_Stone"
    },
    {
      "x": -5,
      "y": 24,
      "z": 1,
      "name": "Rock_Stone"
    },
    {
      "x": -5,
      "y": 25,
      "z": 1,
      "name": "Rock_Stone"
    },
    {
      "x": -5,
      "y": 26,
      "z": 1,
      "name": "Rock_Stone"
    },
    {
      "x": -5,
      "y": 27,
      "z": 1,
      "name": "Rock_Stone"
    },
    {
      "x": -5,
      "y": 28,
      "z": 1,
      "name": "Rock_Stone"
    },
    {
      "x": -5,
      "y": 29,
      "z": 1,
      "name": "Rock_Stone"
    },
    {
      "x": -5,
      "y": 30,
      "z": 1,
      "name": "Rock_Stone"
    },
    {
      "x": -5,
      "y": 31,
      "z": 1,
      "name": "Rock_Stone"
    },
    {
      "x": -5,
      "y": 32,
      "z": 1,
      "name": "Rock_Stone"
    },
    {
      "x": -5,
      "y": 33,
      "z": 1,
      "name": "Rock_Stone"
    },
    {
      "x": -5,
      "y": 34,
      "z": 1,
      "name": "Soil_Dirt"
    },
    {
      "x": -5,
      "y": 35,
      "z": 1,
      "name": "Soil_Dirt"
    },
    {
      "x": -5,
      "y": 36,
      "z": 1,
      "name": "Soil_Grass"
    },
    {
      "x": -5,
      "y": 37,
      "z": 1,
      "name": "Plant_Bush"
    },
    {
      "x": -5,
      "y": 10,
      "z": 2,
      "name": "Rock_Stone"
    },
    {
      "x": -5,
      "y": 11,
      "z": 2,
      "name": "Rock_Stone"
    },
    {
      "x": -5,
      "y": 12,
      "z": 2,
      "name": "Rock_Stone"
    },
    {
      "x": -5,
      "y": 13,
      "z": 2,
      "name": "Rock_Stone"
    },
    {
      "x": -5,
      "y": 14,
      "z": 2,
      "name": "Rock_Stone"
    },
    {
      "x": -5,
      "y": 15,
      "z": 2,
      "name": "Rock_Stone"
    },
    {
      "x": -5,
      "y": 16,
      "z": 2,
      "name": "Rock_Stone"
    },
    {
      "x": -5,
      "y": 17,
      "z": 2,
      "name": "Rock_Stone"
    },
    {
      "x": -5,
      "y": 18,
      "z": 2,
      "name": "Rock_Stone"
    },
    {
      "x": -5,
      "y": 19,
      "z": 2,
      "name": "Rock_Stone"
    },
    {
      "x": -5,
      "y": 20,
      "z": 2,
      "name": "Rock_Stone"
    },
    {
      "x": -5,
      "y": 21,
      "z": 2,
      "name": "Rock_Stone"
    },
    {
      "x": -5,
      "y": 22,
      "z": 2,
      "name": "Rock_Stone"
    },
    {
      "x": -5,
      "y": 23,
      "z": 2,
      "name": "Rock_Stone"
    },
    {
      "x": -5,
      "y": 24,
      "z": 2,
      "name": "Rock_Stone"
    },
    {
      "x": -5,
      "y": 25,
      "z": 2,
      "name": "Rock_Stone"
    },
    {
      "x": -5,
      "y": 26,
      "z": 2,
      "name": "Soil_Grass"
    },
    {
      "x": -5,
      "y": 28,
      "z": 2,
      "name": "Rock_Stone"
    },
    {
      "x": -5,
      "y": 29,
      "z": 2,
      "name": "Rock_Stone"
    },
    {
      "x": -5,
      "y": 30,
      "z": 2,
      "name": "Rock_Stone"
    },
    {
      "x": -5,
      "y": 31,
      "z": 2,
      "name": "Rock_Stone"
    },
    {
      "x": -5,
      "y": 32,
      "z": 2,
      "name": "Rock_Stone"
    },
    {
      "x": -5,
      "y": 33,
      "z": 2,
      "name": "Rock_Stone"
    },
    {
      "x": -5,
      "y": 34,
      "z": 2,
      "name": "Soil_Dirt"
    },
    {
      "x": -5,
      "y": 35,
      "z": 2,
      "name": "Soil_Grass"
    },
    {
      "x": -5,
      "y": 11,
      "z": 3,
      "name": "Rock_Stone"
    },
    {
      "x": -5,
      "y": 12,
      "z": 3,
      "name": "Rock_Stone"
    },
    {
      "x": -5,
      "y": 13,
      "z": 3,
      "name": "Rock_Stone"
    },
    {
      "x": -5,
      "y": 14,
      "z": 3,
      "name": "Rock_Stone"
    },
    {
      "x": -5,
      "y": 15,
      "z": 3,
      "name": "Rock_Stone"
    },
    {
      "x": -5,
      "y": 16,
      "z": 3,
      "name": "Rock_Stone"
    },
    {
      "x": -5,
      "y": 17,
      "z": 3,
      "name": "Rock_Stone"
    },
    {
      "x": -5,
      "y": 18,
      "z": 3,
      "name": "Rock_Stone"
    },
    {
      "x": -5,
      "y": 19,
      "z": 3,
      "name": "Rock_Stone"
    },
    {
      "x": -5,
      "y": 20,
      "z": 3,
      "name": "Rock_Stone"
    },
    {
      "x": -5,
      "y": 21,
      "z": 3,
      "name": "Rock_Stone"
    },
    {
      "x": -5,
      "y": 22,
      "z": 3,
      "name": "Rock_Stone"
    },
    {
      "x": -5,
      "y": 23,
      "z": 3,
      "name": "Rock_Stone"
    },
    {
      "x": -5,
      "y": 24,
      "z": 3,
      "name": "Rock_Stone"
    },
    {
      "x": -5,
      "y": 25,
      "z": 3,
      "name": "Soil_Dirt"
    },
    {
      "x": -5,
      "y": 26,
      "z": 3,
      "name": "Soil_Grass"
    },
    {
      "x": -5,
      "y": 13,
      "z": 4,
      "name": "Rock_Stone"
    },
    {
      "x": -5,
      "y": 14,
      "z": 4,
      "name": "Rock_Stone"
    },
    {
      "x": -5,
      "y": 15,
      "z": 4,
      "name": "Rock_Stone"
    },
    {
      "x": -5,
      "y": 16,
      "z": 4,
      "name": "Rock_Stone"
    },
    {
      "x": -5,
      "y": 17,
      "z": 4,
      "name": "Rock_Stone"
    },
    {
      "x": -5,
      "y": 18,
      "z": 4,
      "name": "Rock_Stone"
    },
    {
      "x": -5,
      "y": 19,
      "z": 4,
      "name": "Rock_Stone_Mossy"
    },
    {
      "x": -5,
      "y": 20,
      "z": 4,
      "name": "Rock_Stone_Mossy"
    },
    {
      "x": -5,
      "y": 21,
      "z": 4,
      "name": "Rock_Stone_Mossy"
    },
    {
      "x": -5,
      "y": 22,
      "z": 4,
      "name": "Rock_Stone"
    },
    {
      "x": -5,
      "y": 23,
      "z": 4,
      "name": "Rock_Stone_Mossy"
    },
    {
      "x": -5,
      "y": 24,
      "z": 4,
      "name": "Rock_Stone_Mossy"
    },
    {
      "x": -5,
      "y": 25,
      "z": 4,
      "name": "Soil_Dirt"
    },
    {
      "x": -5,
      "y": 26,
      "z": 4,
      "name": "Soil_Grass"
    },
    {
      "x": -5,
      "y": 29,
      "z": 4,
      "name": "Plant_Leaves_Birch"
    },
    {
      "x": -5,
      "y": 30,
      "z": 4,
      "name": "Plant_Leaves_Birch"
    },
    {
      "x": -5,
      "y": 31,
      "z": 4,
      "name": "Plant_Leaves_Birch"
    },
    {
      "x": -5,
      "y": 33,
      "z": 4,
      "name": "Plant_Leaves_Birch"
    },
    {
      "x": -5,
      "y": 34,
      "z": 4,
      "name": "Plant_Leaves_Birch"
    },
    {
      "x": -5,
      "y": 15,
      "z": 5,
      "name": "Rock_Stone"
    },
    {
      "x": -5,
      "y": 16,
      "z": 5,
      "name": "Rock_Stone"
    },
    {
      "x": -5,
      "y": 17,
      "z": 5,
      "name": "Rock_Stone"
    },
    {
      "x": -5,
      "y": 18,
      "z": 5,
      "name": "Soil_Dirt"
    },
    {
      "x": -5,
      "y": 19,
      "z": 5,
      "name": "Soil_Dirt"
    },
    {
      "x": -5,
      "y": 20,
      "z": 5,
      "name": "Soil_Grass"
    },
    {
      "x": -5,
      "y": 29,
      "z": 5,
      "name": "Plant_Leaves_Birch"
    },
    {
      "x": -5,
      "y": 30,
      "z": 5,
      "name": "Plant_Leaves_Birch"
    },
    {
      "x": -5,
      "y": 31,
      "z": 5,
      "name": "Plant_Leaves_Birch"
    },
    {
      "x": -5,
      "y": 32,
      "z": 5,
      "name": "Plant_Leaves_Birch"
    },
    {
      "x": -5,
      "y": 33,
      "z": 5,
      "name": "Plant_Leaves_Birch"
    },
    {
      "x": -5,
      "y": 34,
      "z": 5,
      "name": "Plant_Leaves_Birch"
    },
    {
      "x": -5,
      "y": 36,
      "z": 5,
      "name": "Plant_Leaves_Birch"
    },
    {
      "x": -5,
      "y": 28,
      "z": 6,
      "name": "Plant_Leaves_Birch"
    },
    {
      "x": -5,
      "y": 29,
      "z": 6,
      "name": "Plant_Leaves_Birch"
    },
    {
      "x": -5,
      "y": 30,
      "z": 6,
      "name": "Plant_Leaves_Birch"
    },
    {
      "x": -5,
      "y": 31,
      "z": 6,
      "name": "Plant_Leaves_Birch"
    },
    {
      "x": -5,
      "y": 32,
      "z": 6,
      "name": "Plant_Leaves_Birch"
    },
    {
      "x": -5,
      "y": 33,
      "z": 6,
      "name": "Plant_Leaves_Birch"
    },
    {
      "x": -5,
      "y": 34,
      "z": 6,
      "name": "Plant_Leaves_Birch"
    },
    {
      "x": -5,
      "y": 35,
      "z": 6,
      "name": "Plant_Leaves_Birch"
    },
    {
      "x": -5,
      "y": 36,
      "z": 6,
      "name": "Plant_Leaves_Birch"
    },
    {
      "x": -5,
      "y": 37,
      "z": 6,
      "name": "Plant_Leaves_Birch"
    },
    {
      "x": -5,
      "y": 38,
      "z": 6,
      "name": "Plant_Leaves_Birch"
    },
    {
      "x": -5,
      "y": 30,
      "z": 7,
      "name": "Plant_Leaves_Birch"
    },
    {
      "x": -5,
      "y": 31,
      "z": 7,
      "name": "Plant_Leaves_Birch"
    },
    {
      "x": -5,
      "y": 32,
      "z": 7,
      "name": "Plant_Leaves_Birch"
    },
    {
      "x": -5,
      "y": 33,
      "z": 7,
      "name": "Plant_Leaves_Birch"
    },
    {
      "x": -5,
      "y": 34,
      "z": 7,
      "name": "Plant_Leaves_Birch"
    },
    {
      "x": -5,
      "y": 35,
      "z": 7,
      "name": "Plant_Leaves_Birch"
    },
    {
      "x": -5,
      "y": 36,
      "z": 7,
      "name": "Plant_Leaves_Birch"
    },
    {
      "x": -5,
      "y": 30,
      "z": 8,
      "name": "Plant_Leaves_Birch"
    },
    {
      "x": -5,
      "y": 31,
      "z": 8,
      "name": "Plant_Leaves_Birch"
    },
    {
      "x": -5,
      "y": 32,
      "z": 8,
      "name": "Plant_Leaves_Birch"
    },
    {
      "x": -5,
      "y": 33,
      "z": 8,
      "name": "Plant_Leaves_Birch"
    },
    {
      "x": -4,
      "y": 15,
      "z": -6,
      "name": "Rock_Stone"
    },
    {
      "x": -4,
      "y": 16,
      "z": -6,
      "name": "Rock_Stone"
    },
    {
      "x": -4,
      "y": 17,
      "z": -6,
      "name": "Rock_Stone"
    },
    {
      "x": -4,
      "y": 18,
      "z": -6,
      "name": "Rock_Stone_Mossy"
    },
    {
      "x": -4,
      "y": 19,
      "z": -6,
      "name": "Rock_Stone"
    },
    {
      "x": -4,
      "y": 20,
      "z": -6,
      "name": "Soil_Dirt"
    },
    {
      "x": -4,
      "y": 21,
      "z": -6,
      "name": "Soil_Dirt"
    },
    {
      "x": -4,
      "y": 22,
      "z": -6,
      "name": "Soil_Grass"
    },
    {
      "x": -4,
      "y": 12,
      "z": -5,
      "name": "Rock_Stone"
    },
    {
      "x": -4,
      "y": 13,
      "z": -5,
      "name": "Rock_Stone"
    },
    {
      "x": -4,
      "y": 14,
      "z": -5,
      "name": "Rock_Stone"
    },
    {
      "x": -4,
      "y": 15,
      "z": -5,
      "name": "Rock_Stone"
    },
    {
      "x": -4,
      "y": 16,
      "z": -5,
      "name": "Rock_Stone"
    },
    {
      "x": -4,
      "y": 17,
      "z": -5,
      "name": "Rock_Stone"
    },
    {
      "x": -4,
      "y": 18,
      "z": -5,
      "name": "Rock_Stone"
    },
    {
      "x": -4,
      "y": 19,
      "z": -5,
      "name": "Rock_Stone"
    },
    {
      "x": -4,
      "y": 20,
      "z": -5,
      "name": "Soil_Dirt"
    },
    {
      "x": -4,
      "y": 21,
      "z": -5,
      "name": "Soil_Dirt"
    },
    {
      "x": -4,
      "y": 22,
      "z": -5,
      "name": "Soil_Grass"
    },
    {
      "x": -4,
      "y": 12,
      "z": -4,
      "name": "Rock_Stone"
    },
    {
      "x": -4,
      "y": 13,
      "z": -4,
      "name": "Rock_Stone"
    },
    {
      "x": -4,
      "y": 14,
      "z": -4,
      "name": "Rock_Stone"
    },
    {
      "x": -4,
      "y": 15,
      "z": -4,
      "name": "Rock_Stone"
    },
    {
      "x": -4,
      "y": 16,
      "z": -4,
      "name": "Rock_Stone"
    },
    {
      "x": -4,
      "y": 17,
      "z": -4,
      "name": "Rock_Stone"
    },
    {
      "x": -4,
      "y": 18,
      "z": -4,
      "name": "Rock_Stone"
    },
    {
      "x": -4,
      "y": 19,
      "z": -4,
      "name": "Rock_Stone"
    },
    {
      "x": -4,
      "y": 20,
      "z": -4,
      "name": "Rock_Stone"
    },
    {
      "x": -4,
      "y": 21,
      "z": -4,
      "name": "Soil_Dirt"
    },
    {
      "x": -4,
      "y": 22,
      "z": -4,
      "name": "Rock_Stone"
    },
    {
      "x": -4,
      "y": 23,
      "z": -4,
      "name": "Rock_Stone"
    },
    {
      "x": -4,
      "y": 24,
      "z": -4,
      "name": "Rock_Stone"
    },
    {
      "x": -4,
      "y": 25,
      "z": -4,
      "name": "Rock_Stone"
    },
    {
      "x": -4,
      "y": 26,
      "z": -4,
      "name": "Rock_Stone"
    },
    {
      "x": -4,
      "y": 27,
      "z": -4,
      "name": "Rock_Stone"
    },
    {
      "x": -4,
      "y": 28,
      "z": -4,
      "name": "Soil_Dirt"
    },
    {
      "x": -4,
      "y": 29,
      "z": -4,
      "name": "Soil_Grass"
    },
    {
      "x": -4,
      "y": 30,
      "z": -4,
      "name": "Plant_Grass_Sharp"
    },
    {
      "x": -4,
      "y": 10,
      "z": -3,
      "name": "Rock_Stone"
    },
    {
      "x": -4,
      "y": 11,
      "z": -3,
      "name": "Rock_Stone"
    },
    {
      "x": -4,
      "y": 12,
      "z": -3,
      "name": "Rock_Stone"
    },
    {
      "x": -4,
      "y": 13,
      "z": -3,
      "name": "Rock_Stone"
    },
    {
      "x": -4,
      "y": 14,
      "z": -3,
      "name": "Rock_Stone"
    },
    {
      "x": -4,
      "y": 15,
      "z": -3,
      "name": "Rock_Stone"
    },
    {
      "x": -4,
      "y": 16,
      "z": -3,
      "name": "Rock_Stone"
    },
    {
      "x": -4,
      "y": 17,
      "z": -3,
      "name": "Rock_Stone"
    },
    {
      "x": -4,
      "y": 18,
      "z": -3,
      "name": "Rock_Stone"
    },
    {
      "x": -4,
      "y": 19,
      "z": -3,
      "name": "Rock_Stone"
    },
    {
      "x": -4,
      "y": 20,
      "z": -3,
      "name": "Rock_Stone"
    },
    {
      "x": -4,
      "y": 21,
      "z": -3,
      "name": "Rock_Stone"
    },
    {
      "x": -4,
      "y": 22,
      "z": -3,
      "name": "Rock_Stone"
    },
    {
      "x": -4,
      "y": 23,
      "z": -3,
      "name": "Rock_Stone"
    },
    {
      "x": -4,
      "y": 24,
      "z": -3,
      "name": "Rock_Stone"
    },
    {
      "x": -4,
      "y": 25,
      "z": -3,
      "name": "Rock_Stone"
    },
    {
      "x": -4,
      "y": 26,
      "z": -3,
      "name": "Rock_Stone"
    },
    {
      "x": -4,
      "y": 27,
      "z": -3,
      "name": "Rock_Stone"
    },
    {
      "x": -4,
      "y": 28,
      "z": -3,
      "name": "Soil_Dirt"
    },
    {
      "x": -4,
      "y": 29,
      "z": -3,
      "name": "Soil_Dirt"
    },
    {
      "x": -4,
      "y": 30,
      "z": -3,
      "name": "Soil_Grass"
    },
    {
      "x": -4,
      "y": 31,
      "z": -3,
      "name": "Plant_Grass_Sharp"
    },
    {
      "x": -4,
      "y": 10,
      "z": -2,
      "name": "Rock_Stone"
    },
    {
      "x": -4,
      "y": 11,
      "z": -2,
      "name": "Rock_Stone"
    },
    {
      "x": -4,
      "y": 12,
      "z": -2,
      "name": "Rock_Stone"
    },
    {
      "x": -4,
      "y": 13,
      "z": -2,
      "name": "Rock_Stone"
    },
    {
      "x": -4,
      "y": 14,
      "z": -2,
      "name": "Rock_Stone"
    },
    {
      "x": -4,
      "y": 15,
      "z": -2,
      "name": "Rock_Stone"
    },
    {
      "x": -4,
      "y": 16,
      "z": -2,
      "name": "Rock_Stone"
    },
    {
      "x": -4,
      "y": 17,
      "z": -2,
      "name": "Rock_Stone"
    },
    {
      "x": -4,
      "y": 18,
      "z": -2,
      "name": "Rock_Stone"
    },
    {
      "x": -4,
      "y": 19,
      "z": -2,
      "name": "Rock_Stone"
    },
    {
      "x": -4,
      "y": 20,
      "z": -2,
      "name": "Rock_Stone"
    },
    {
      "x": -4,
      "y": 21,
      "z": -2,
      "name": "Rock_Stone"
    },
    {
      "x": -4,
      "y": 22,
      "z": -2,
      "name": "Rock_Stone"
    },
    {
      "x": -4,
      "y": 23,
      "z": -2,
      "name": "Rock_Stone"
    },
    {
      "x": -4,
      "y": 24,
      "z": -2,
      "name": "Rock_Stone"
    },
    {
      "x": -4,
      "y": 25,
      "z": -2,
      "name": "Rock_Stone"
    },
    {
      "x": -4,
      "y": 26,
      "z": -2,
      "name": "Rock_Stone"
    },
    {
      "x": -4,
      "y": 27,
      "z": -2,
      "name": "Rock_Stone"
    },
    {
      "x": -4,
      "y": 28,
      "z": -2,
      "name": "Rock_Stone"
    },
    {
      "x": -4,
      "y": 29,
      "z": -2,
      "name": "Soil_Dirt"
    },
    {
      "x": -4,
      "y": 30,
      "z": -2,
      "name": "Rock_Stone"
    },
    {
      "x": -4,
      "y": 31,
      "z": -2,
      "name": "Rock_Stone"
    },
    {
      "x": -4,
      "y": 32,
      "z": -2,
      "name": "Soil_Dirt"
    },
    {
      "x": -4,
      "y": 33,
      "z": -2,
      "name": "Soil_Dirt"
    },
    {
      "x": -4,
      "y": 34,
      "z": -2,
      "name": "Soil_Dirt"
    },
    {
      "x": -4,
      "y": 35,
      "z": -2,
      "name": "Soil_Grass"
    },
    {
      "x": -4,
      "y": 9,
      "z": -1,
      "name": "Rock_Stone"
    },
    {
      "x": -4,
      "y": 10,
      "z": -1,
      "name": "Rock_Stone"
    },
    {
      "x": -4,
      "y": 11,
      "z": -1,
      "name": "Rock_Stone"
    },
    {
      "x": -4,
      "y": 12,
      "z": -1,
      "name": "Rock_Stone"
    },
    {
      "x": -4,
      "y": 13,
      "z": -1,
      "name": "Rock_Stone"
    },
    {
      "x": -4,
      "y": 14,
      "z": -1,
      "name": "Rock_Stone"
    },
    {
      "x": -4,
      "y": 15,
      "z": -1,
      "name": "Rock_Stone"
    },
    {
      "x": -4,
      "y": 16,
      "z": -1,
      "name": "Rock_Stone"
    },
    {
      "x": -4,
      "y": 17,
      "z": -1,
      "name": "Rock_Stone"
    },
    {
      "x": -4,
      "y": 18,
      "z": -1,
      "name": "Rock_Stone"
    },
    {
      "x": -4,
      "y": 19,
      "z": -1,
      "name": "Rock_Stone"
    },
    {
      "x": -4,
      "y": 20,
      "z": -1,
      "name": "Rock_Stone"
    },
    {
      "x": -4,
      "y": 21,
      "z": -1,
      "name": "Rock_Stone"
    },
    {
      "x": -4,
      "y": 22,
      "z": -1,
      "name": "Rock_Stone"
    },
    {
      "x": -4,
      "y": 23,
      "z": -1,
      "name": "Rock_Stone"
    },
    {
      "x": -4,
      "y": 24,
      "z": -1,
      "name": "Rock_Stone"
    },
    {
      "x": -4,
      "y": 25,
      "z": -1,
      "name": "Rock_Stone"
    },
    {
      "x": -4,
      "y": 26,
      "z": -1,
      "name": "Rock_Stone"
    },
    {
      "x": -4,
      "y": 27,
      "z": -1,
      "name": "Rock_Stone"
    },
    {
      "x": -4,
      "y": 28,
      "z": -1,
      "name": "Rock_Stone"
    },
    {
      "x": -4,
      "y": 29,
      "z": -1,
      "name": "Rock_Stone"
    },
    {
      "x": -4,
      "y": 30,
      "z": -1,
      "name": "Rock_Stone"
    },
    {
      "x": -4,
      "y": 31,
      "z": -1,
      "name": "Soil_Dirt"
    },
    {
      "x": -4,
      "y": 32,
      "z": -1,
      "name": "Soil_Dirt"
    },
    {
      "x": -4,
      "y": 33,
      "z": -1,
      "name": "Soil_Dirt"
    },
    {
      "x": -4,
      "y": 34,
      "z": -1,
      "name": "Soil_Dirt"
    },
    {
      "x": -4,
      "y": 35,
      "z": -1,
      "name": "Soil_Grass"
    },
    {
      "x": -4,
      "y": 36,
      "z": -1,
      "name": "Plant_Grass_Sharp"
    },
    {
      "x": -4,
      "y": 9,
      "z": 0,
      "name": "Rock_Stone"
    },
    {
      "x": -4,
      "y": 10,
      "z": 0,
      "name": "Rock_Stone"
    },
    {
      "x": -4,
      "y": 11,
      "z": 0,
      "name": "Rock_Stone"
    },
    {
      "x": -4,
      "y": 12,
      "z": 0,
      "name": "Rock_Stone"
    },
    {
      "x": -4,
      "y": 13,
      "z": 0,
      "name": "Rock_Stone"
    },
    {
      "x": -4,
      "y": 14,
      "z": 0,
      "name": "Rock_Stone"
    },
    {
      "x": -4,
      "y": 15,
      "z": 0,
      "name": "Rock_Stone"
    },
    {
      "x": -4,
      "y": 16,
      "z": 0,
      "name": "Rock_Stone"
    },
    {
      "x": -4,
      "y": 17,
      "z": 0,
      "name": "Rock_Stone"
    },
    {
      "x": -4,
      "y": 18,
      "z": 0,
      "name": "Rock_Stone"
    },
    {
      "x": -4,
      "y": 19,
      "z": 0,
      "name": "Rock_Stone"
    },
    {
      "x": -4,
      "y": 20,
      "z": 0,
      "name": "Rock_Stone"
    },
    {
      "x": -4,
      "y": 21,
      "z": 0,
      "name": "Rock_Stone"
    },
    {
      "x": -4,
      "y": 22,
      "z": 0,
      "name": "Rock_Stone"
    },
    {
      "x": -4,
      "y": 23,
      "z": 0,
      "name": "Rock_Stone"
    },
    {
      "x": -4,
      "y": 24,
      "z": 0,
      "name": "Rock_Stone"
    },
    {
      "x": -4,
      "y": 25,
      "z": 0,
      "name": "Rock_Stone"
    },
    {
      "x": -4,
      "y": 26,
      "z": 0,
      "name": "Rock_Stone"
    },
    {
      "x": -4,
      "y": 27,
      "z": 0,
      "name": "Rock_Stone"
    },
    {
      "x": -4,
      "y": 28,
      "z": 0,
      "name": "Rock_Stone"
    },
    {
      "x": -4,
      "y": 29,
      "z": 0,
      "name": "Rock_Stone"
    },
    {
      "x": -4,
      "y": 30,
      "z": 0,
      "name": "Rock_Stone"
    },
    {
      "x": -4,
      "y": 31,
      "z": 0,
      "name": "Soil_Dirt"
    },
    {
      "x": -4,
      "y": 32,
      "z": 0,
      "name": "Soil_Dirt"
    },
    {
      "x": -4,
      "y": 33,
      "z": 0,
      "name": "Soil_Dirt"
    },
    {
      "x": -4,
      "y": 34,
      "z": 0,
      "name": "Soil_Dirt"
    },
    {
      "x": -4,
      "y": 35,
      "z": 0,
      "name": "Soil_Grass"
    },
    {
      "x": -4,
      "y": 36,
      "z": 0,
      "name": "Plant_Grass_Sharp"
    },
    {
      "x": -4,
      "y": 9,
      "z": 1,
      "name": "Rock_Stone"
    },
    {
      "x": -4,
      "y": 10,
      "z": 1,
      "name": "Rock_Stone"
    },
    {
      "x": -4,
      "y": 11,
      "z": 1,
      "name": "Rock_Stone"
    },
    {
      "x": -4,
      "y": 12,
      "z": 1,
      "name": "Rock_Stone"
    },
    {
      "x": -4,
      "y": 13,
      "z": 1,
      "name": "Rock_Stone"
    },
    {
      "x": -4,
      "y": 14,
      "z": 1,
      "name": "Rock_Stone"
    },
    {
      "x": -4,
      "y": 15,
      "z": 1,
      "name": "Rock_Stone"
    },
    {
      "x": -4,
      "y": 16,
      "z": 1,
      "name": "Rock_Stone"
    },
    {
      "x": -4,
      "y": 17,
      "z": 1,
      "name": "Rock_Stone"
    },
    {
      "x": -4,
      "y": 18,
      "z": 1,
      "name": "Rock_Stone"
    },
    {
      "x": -4,
      "y": 19,
      "z": 1,
      "name": "Rock_Stone"
    },
    {
      "x": -4,
      "y": 20,
      "z": 1,
      "name": "Rock_Stone"
    },
    {
      "x": -4,
      "y": 21,
      "z": 1,
      "name": "Rock_Stone"
    },
    {
      "x": -4,
      "y": 22,
      "z": 1,
      "name": "Rock_Stone"
    },
    {
      "x": -4,
      "y": 23,
      "z": 1,
      "name": "Rock_Stone"
    },
    {
      "x": -4,
      "y": 24,
      "z": 1,
      "name": "Rock_Stone"
    },
    {
      "x": -4,
      "y": 25,
      "z": 1,
      "name": "Rock_Stone"
    },
    {
      "x": -4,
      "y": 26,
      "z": 1,
      "name": "Rock_Stone"
    },
    {
      "x": -4,
      "y": 27,
      "z": 1,
      "name": "Rock_Stone"
    },
    {
      "x": -4,
      "y": 28,
      "z": 1,
      "name": "Rock_Stone"
    },
    {
      "x": -4,
      "y": 29,
      "z": 1,
      "name": "Rock_Stone"
    },
    {
      "x": -4,
      "y": 30,
      "z": 1,
      "name": "Rock_Stone"
    },
    {
      "x": -4,
      "y": 31,
      "z": 1,
      "name": "Soil_Dirt"
    },
    {
      "x": -4,
      "y": 32,
      "z": 1,
      "name": "Soil_Dirt"
    },
    {
      "x": -4,
      "y": 33,
      "z": 1,
      "name": "Soil_Dirt"
    },
    {
      "x": -4,
      "y": 34,
      "z": 1,
      "name": "Soil_Dirt"
    },
    {
      "x": -4,
      "y": 35,
      "z": 1,
      "name": "Soil_Grass"
    },
    {
      "x": -4,
      "y": 10,
      "z": 2,
      "name": "Rock_Stone"
    },
    {
      "x": -4,
      "y": 11,
      "z": 2,
      "name": "Rock_Stone"
    },
    {
      "x": -4,
      "y": 12,
      "z": 2,
      "name": "Rock_Stone"
    },
    {
      "x": -4,
      "y": 13,
      "z": 2,
      "name": "Rock_Stone"
    },
    {
      "x": -4,
      "y": 14,
      "z": 2,
      "name": "Rock_Stone"
    },
    {
      "x": -4,
      "y": 15,
      "z": 2,
      "name": "Rock_Stone"
    },
    {
      "x": -4,
      "y": 16,
      "z": 2,
      "name": "Rock_Stone"
    },
    {
      "x": -4,
      "y": 17,
      "z": 2,
      "name": "Rock_Stone"
    },
    {
      "x": -4,
      "y": 18,
      "z": 2,
      "name": "Rock_Stone"
    },
    {
      "x": -4,
      "y": 19,
      "z": 2,
      "name": "Rock_Stone"
    },
    {
      "x": -4,
      "y": 20,
      "z": 2,
      "name": "Rock_Stone"
    },
    {
      "x": -4,
      "y": 21,
      "z": 2,
      "name": "Rock_Stone"
    },
    {
      "x": -4,
      "y": 22,
      "z": 2,
      "name": "Rock_Stone"
    },
    {
      "x": -4,
      "y": 23,
      "z": 2,
      "name": "Rock_Stone"
    },
    {
      "x": -4,
      "y": 24,
      "z": 2,
      "name": "Rock_Stone"
    },
    {
      "x": -4,
      "y": 25,
      "z": 2,
      "name": "Rock_Stone"
    },
    {
      "x": -4,
      "y": 26,
      "z": 2,
      "name": "Soil_Dirt"
    },
    {
      "x": -4,
      "y": 27,
      "z": 2,
      "name": "Rock_Stone_Mossy"
    },
    {
      "x": -4,
      "y": 28,
      "z": 2,
      "name": "Rock_Stone"
    },
    {
      "x": -4,
      "y": 29,
      "z": 2,
      "name": "Rock_Stone_Mossy"
    },
    {
      "x": -4,
      "y": 30,
      "z": 2,
      "name": "Rock_Stone"
    },
    {
      "x": -4,
      "y": 31,
      "z": 2,
      "name": "Rock_Stone"
    },
    {
      "x": -4,
      "y": 32,
      "z": 2,
      "name": "Soil_Dirt"
    },
    {
      "x": -4,
      "y": 33,
      "z": 2,
      "name": "Soil_Dirt"
    },
    {
      "x": -4,
      "y": 34,
      "z": 2,
      "name": "Soil_Dirt"
    },
    {
      "x": -4,
      "y": 35,
      "z": 2,
      "name": "Soil_Grass"
    },
    {
      "x": -4,
      "y": 10,
      "z": 3,
      "name": "Rock_Stone"
    },
    {
      "x": -4,
      "y": 11,
      "z": 3,
      "name": "Rock_Stone"
    },
    {
      "x": -4,
      "y": 12,
      "z": 3,
      "name": "Rock_Stone"
    },
    {
      "x": -4,
      "y": 13,
      "z": 3,
      "name": "Rock_Stone"
    },
    {
      "x": -4,
      "y": 14,
      "z": 3,
      "name": "Rock_Stone"
    },
    {
      "x": -4,
      "y": 15,
      "z": 3,
      "name": "Rock_Stone"
    },
    {
      "x": -4,
      "y": 16,
      "z": 3,
      "name": "Rock_Stone"
    },
    {
      "x": -4,
      "y": 17,
      "z": 3,
      "name": "Rock_Stone"
    },
    {
      "x": -4,
      "y": 18,
      "z": 3,
      "name": "Rock_Stone"
    },
    {
      "x": -4,
      "y": 19,
      "z": 3,
      "name": "Rock_Stone"
    },
    {
      "x": -4,
      "y": 20,
      "z": 3,
      "name": "Rock_Stone"
    },
    {
      "x": -4,
      "y": 21,
      "z": 3,
      "name": "Soil_Dirt"
    },
    {
      "x": -4,
      "y": 22,
      "z": 3,
      "name": "Rock_Stone"
    },
    {
      "x": -4,
      "y": 23,
      "z": 3,
      "name": "Rock_Stone"
    },
    {
      "x": -4,
      "y": 24,
      "z": 3,
      "name": "Rock_Stone"
    },
    {
      "x": -4,
      "y": 25,
      "z": 3,
      "name": "Soil_Dirt"
    },
    {
      "x": -4,
      "y": 26,
      "z": 3,
      "name": "Soil_Grass"
    },
    {
      "x": -4,
      "y": 29,
      "z": 3,
      "name": "Plant_Leaves_Birch"
    },
    {
      "x": -4,
      "y": 30,
      "z": 3,
      "name": "Plant_Leaves_Birch"
    },
    {
      "x": -4,
      "y": 31,
      "z": 3,
      "name": "Plant_Leaves_Birch"
    },
    {
      "x": -4,
      "y": 32,
      "z": 3,
      "name": "Plant_Leaves_Birch"
    },
    {
      "x": -4,
      "y": 12,
      "z": 4,
      "name": "Rock_Stone"
    },
    {
      "x": -4,
      "y": 13,
      "z": 4,
      "name": "Rock_Stone"
    },
    {
      "x": -4,
      "y": 14,
      "z": 4,
      "name": "Rock_Stone"
    },
    {
      "x": -4,
      "y": 15,
      "z": 4,
      "name": "Rock_Stone"
    },
    {
      "x": -4,
      "y": 16,
      "z": 4,
      "name": "Rock_Stone"
    },
    {
      "x": -4,
      "y": 17,
      "z": 4,
      "name": "Rock_Stone"
    },
    {
      "x": -4,
      "y": 18,
      "z": 4,
      "name": "Rock_Stone"
    },
    {
      "x": -4,
      "y": 19,
      "z": 4,
      "name": "Rock_Stone"
    },
    {
      "x": -4,
      "y": 20,
      "z": 4,
      "name": "Soil_Dirt"
    },
    {
      "x": -4,
      "y": 21,
      "z": 4,
      "name": "Soil_Dirt"
    },
    {
      "x": -4,
      "y": 22,
      "z": 4,
      "name": "Soil_Dirt"
    },
    {
      "x": -4,
      "y": 23,
      "z": 4,
      "name": "Rock_Stone"
    },
    {
      "x": -4,
      "y": 24,
      "z": 4,
      "name": "Rock_Stone"
    },
    {
      "x": -4,
      "y": 25,
      "z": 4,
      "name": "Soil_Dirt"
    },
    {
      "x": -4,
      "y": 26,
      "z": 4,
      "name": "Soil_Grass"
    },
    {
      "x": -4,
      "y": 34,
      "z": 4,
      "name": "Plant_Leaves_Birch"
    },
    {
      "x": -4,
      "y": 35,
      "z": 4,
      "name": "Plant_Leaves_Birch"
    },
    {
      "x": -4,
      "y": 36,
      "z": 4,
      "name": "Plant_Leaves_Birch"
    },
    {
      "x": -4,
      "y": 13,
      "z": 5,
      "name": "Rock_Stone"
    },
    {
      "x": -4,
      "y": 14,
      "z": 5,
      "name": "Rock_Stone"
    },
    {
      "x": -4,
      "y": 15,
      "z": 5,
      "name": "Rock_Stone"
    },
    {
      "x": -4,
      "y": 16,
      "z": 5,
      "name": "Rock_Stone"
    },
    {
      "x": -4,
      "y": 17,
      "z": 5,
      "name": "Rock_Stone"
    },
    {
      "x": -4,
      "y": 18,
      "z": 5,
      "name": "Rock_Stone"
    },
    {
      "x": -4,
      "y": 19,
      "z": 5,
      "name": "Soil_Dirt"
    },
    {
      "x": -4,
      "y": 20,
      "z": 5,
      "name": "Soil_Dirt"
    },
    {
      "x": -4,
      "y": 21,
      "z": 5,
      "name": "Soil_Dirt"
    },
    {
      "x": -4,
      "y": 22,
      "z": 5,
      "name": "Soil_Grass"
    },
    {
      "x": -4,
      "y": 34,
      "z": 5,
      "name": "Plant_Leaves_Birch"
    },
    {
      "x": -4,
      "y": 35,
      "z": 5,
      "name": "Plant_Leaves_Birch"
    },
    {
      "x": -4,
      "y": 37,
      "z": 5,
      "name": "Plant_Leaves_Birch"
    },
    {
      "x": -4,
      "y": 38,
      "z": 5,
      "name": "Plant_Leaves_Birch"
    },
    {
      "x": -4,
      "y": 39,
      "z": 5,
      "name": "Plant_Leaves_Birch"
    },
    {
      "x": -4,
      "y": 27,
      "z": 6,
      "name": "Plant_Leaves_Birch"
    },
    {
      "x": -4,
      "y": 28,
      "z": 6,
      "name": "Plant_Leaves_Birch"
    },
    {
      "x": -4,
      "y": 29,
      "z": 6,
      "name": "Wood_Birch_Branch_Long",
      "rotation": 5
    },
    {
      "x": -4,
      "y": 33,
      "z": 6,
      "name": "Wood_Birch_Branch_Corner",
      "rotation": 3
    },
    {
      "x": -4,
      "y": 34,
      "z": 6,
      "name": "Wood_Birch_Branch_Long"
    },
    {
      "x": -4,
      "y": 35,
      "z": 6,
      "name": "Wood_Birch_Branch_Long"
    },
    {
      "x": -4,
      "y": 36,
      "z": 6,
      "name": "Wood_Birch_Branch_Long"
    },
    {
      "x": -4,
      "y": 37,
      "z": 6,
      "name": "Plant_Leaves_Birch"
    },
    {
      "x": -4,
      "y": 38,
      "z": 6,
      "name": "Plant_Leaves_Birch"
    },
    {
      "x": -4,
      "y": 39,
      "z": 6,
      "name": "Plant_Leaves_Birch"
    },
    {
      "x": -4,
      "y": 40,
      "z": 6,
      "name": "Plant_Leaves_Birch"
    },
    {
      "x": -4,
      "y": 29,
      "z": 7,
      "name": "Plant_Leaves_Birch"
    },
    {
      "x": -4,
      "y": 38,
      "z": 7,
      "name": "Plant_Leaves_Birch"
    },
    {
      "x": -4,
      "y": 39,
      "z": 7,
      "name": "Plant_Leaves_Birch"
    },
    {
      "x": -4,
      "y": 34,
      "z": 8,
      "name": "Plant_Leaves_Birch"
    },
    {
      "x": -4,
      "y": 35,
      "z": 8,
      "name": "Plant_Leaves_Birch"
    },
    {
      "x": -4,
      "y": 36,
      "z": 8,
      "name": "Plant_Leaves_Birch"
    },
    {
      "x": -4,
      "y": 29,
      "z": 9,
      "name": "Plant_Leaves_Birch"
    },
    {
      "x": -4,
      "y": 30,
      "z": 9,
      "name": "Plant_Leaves_Birch"
    },
    {
      "x": -4,
      "y": 31,
      "z": 9,
      "name": "Plant_Leaves_Birch"
    },
    {
      "x": -4,
      "y": 32,
      "z": 9,
      "name": "Plant_Leaves_Birch"
    },
    {
      "x": -4,
      "y": 33,
      "z": 9,
      "name": "Plant_Leaves_Birch"
    },
    {
      "x": -3,
      "y": 15,
      "z": -6,
      "name": "Rock_Stone"
    },
    {
      "x": -3,
      "y": 16,
      "z": -6,
      "name": "Rock_Stone"
    },
    {
      "x": -3,
      "y": 17,
      "z": -6,
      "name": "Rock_Stone_Mossy"
    },
    {
      "x": -3,
      "y": 18,
      "z": -6,
      "name": "Rock_Stone_Mossy"
    },
    {
      "x": -3,
      "y": 19,
      "z": -6,
      "name": "Rock_Stone_Mossy"
    },
    {
      "x": -3,
      "y": 20,
      "z": -6,
      "name": "Soil_Dirt"
    },
    {
      "x": -3,
      "y": 21,
      "z": -6,
      "name": "Soil_Dirt"
    },
    {
      "x": -3,
      "y": 22,
      "z": -6,
      "name": "Soil_Grass"
    },
    {
      "x": -3,
      "y": 23,
      "z": -6,
      "name": "Plant_Grass_Sharp"
    },
    {
      "x": -3,
      "y": 12,
      "z": -5,
      "name": "Rock_Stone"
    },
    {
      "x": -3,
      "y": 13,
      "z": -5,
      "name": "Rock_Stone"
    },
    {
      "x": -3,
      "y": 14,
      "z": -5,
      "name": "Rock_Stone"
    },
    {
      "x": -3,
      "y": 15,
      "z": -5,
      "name": "Rock_Stone"
    },
    {
      "x": -3,
      "y": 16,
      "z": -5,
      "name": "Rock_Stone"
    },
    {
      "x": -3,
      "y": 17,
      "z": -5,
      "name": "Rock_Stone"
    },
    {
      "x": -3,
      "y": 18,
      "z": -5,
      "name": "Rock_Stone_Mossy"
    },
    {
      "x": -3,
      "y": 19,
      "z": -5,
      "name": "Rock_Stone"
    },
    {
      "x": -3,
      "y": 20,
      "z": -5,
      "name": "Soil_Dirt"
    },
    {
      "x": -3,
      "y": 21,
      "z": -5,
      "name": "Soil_Dirt"
    },
    {
      "x": -3,
      "y": 22,
      "z": -5,
      "name": "Soil_Grass"
    },
    {
      "x": -3,
      "y": 23,
      "z": -5,
      "name": "Plant_Grass_Sharp"
    },
    {
      "x": -3,
      "y": 11,
      "z": -4,
      "name": "Rock_Stone"
    },
    {
      "x": -3,
      "y": 12,
      "z": -4,
      "name": "Rock_Stone"
    },
    {
      "x": -3,
      "y": 13,
      "z": -4,
      "name": "Rock_Stone"
    },
    {
      "x": -3,
      "y": 14,
      "z": -4,
      "name": "Rock_Stone"
    },
    {
      "x": -3,
      "y": 15,
      "z": -4,
      "name": "Rock_Stone"
    },
    {
      "x": -3,
      "y": 16,
      "z": -4,
      "name": "Rock_Stone"
    },
    {
      "x": -3,
      "y": 17,
      "z": -4,
      "name": "Rock_Stone"
    },
    {
      "x": -3,
      "y": 18,
      "z": -4,
      "name": "Rock_Stone"
    },
    {
      "x": -3,
      "y": 19,
      "z": -4,
      "name": "Rock_Stone"
    },
    {
      "x": -3,
      "y": 20,
      "z": -4,
      "name": "Rock_Stone"
    },
    {
      "x": -3,
      "y": 21,
      "z": -4,
      "name": "Soil_Dirt"
    },
    {
      "x": -3,
      "y": 22,
      "z": -4,
      "name": "Soil_Dirt"
    },
    {
      "x": -3,
      "y": 23,
      "z": -4,
      "name": "Rock_Stone"
    },
    {
      "x": -3,
      "y": 24,
      "z": -4,
      "name": "Rock_Stone"
    },
    {
      "x": -3,
      "y": 25,
      "z": -4,
      "name": "Rock_Stone"
    },
    {
      "x": -3,
      "y": 26,
      "z": -4,
      "name": "Rock_Stone"
    },
    {
      "x": -3,
      "y": 27,
      "z": -4,
      "name": "Rock_Stone"
    },
    {
      "x": -3,
      "y": 28,
      "z": -4,
      "name": "Soil_Dirt"
    },
    {
      "x": -3,
      "y": 29,
      "z": -4,
      "name": "Soil_Grass"
    },
    {
      "x": -3,
      "y": 10,
      "z": -3,
      "name": "Rock_Stone"
    },
    {
      "x": -3,
      "y": 11,
      "z": -3,
      "name": "Rock_Stone"
    },
    {
      "x": -3,
      "y": 12,
      "z": -3,
      "name": "Rock_Stone"
    },
    {
      "x": -3,
      "y": 13,
      "z": -3,
      "name": "Rock_Stone"
    },
    {
      "x": -3,
      "y": 14,
      "z": -3,
      "name": "Rock_Stone"
    },
    {
      "x": -3,
      "y": 15,
      "z": -3,
      "name": "Rock_Stone"
    },
    {
      "x": -3,
      "y": 16,
      "z": -3,
      "name": "Rock_Stone"
    },
    {
      "x": -3,
      "y": 17,
      "z": -3,
      "name": "Rock_Stone"
    },
    {
      "x": -3,
      "y": 18,
      "z": -3,
      "name": "Rock_Stone"
    },
    {
      "x": -3,
      "y": 19,
      "z": -3,
      "name": "Rock_Stone"
    },
    {
      "x": -3,
      "y": 20,
      "z": -3,
      "name": "Rock_Stone"
    },
    {
      "x": -3,
      "y": 21,
      "z": -3,
      "name": "Rock_Stone"
    },
    {
      "x": -3,
      "y": 22,
      "z": -3,
      "name": "Rock_Stone"
    },
    {
      "x": -3,
      "y": 23,
      "z": -3,
      "name": "Rock_Stone"
    },
    {
      "x": -3,
      "y": 24,
      "z": -3,
      "name": "Rock_Stone"
    },
    {
      "x": -3,
      "y": 25,
      "z": -3,
      "name": "Rock_Stone"
    },
    {
      "x": -3,
      "y": 26,
      "z": -3,
      "name": "Rock_Stone"
    },
    {
      "x": -3,
      "y": 27,
      "z": -3,
      "name": "Rock_Stone"
    },
    {
      "x": -3,
      "y": 28,
      "z": -3,
      "name": "Soil_Dirt"
    },
    {
      "x": -3,
      "y": 29,
      "z": -3,
      "name": "Soil_Dirt"
    },
    {
      "x": -3,
      "y": 30,
      "z": -3,
      "name": "Soil_Grass"
    },
    {
      "x": -3,
      "y": 9,
      "z": -2,
      "name": "Rock_Stone"
    },
    {
      "x": -3,
      "y": 10,
      "z": -2,
      "name": "Rock_Stone"
    },
    {
      "x": -3,
      "y": 11,
      "z": -2,
      "name": "Rock_Stone"
    },
    {
      "x": -3,
      "y": 12,
      "z": -2,
      "name": "Rock_Stone"
    },
    {
      "x": -3,
      "y": 13,
      "z": -2,
      "name": "Rock_Stone"
    },
    {
      "x": -3,
      "y": 14,
      "z": -2,
      "name": "Rock_Stone"
    },
    {
      "x": -3,
      "y": 15,
      "z": -2,
      "name": "Rock_Stone"
    },
    {
      "x": -3,
      "y": 16,
      "z": -2,
      "name": "Rock_Stone"
    },
    {
      "x": -3,
      "y": 17,
      "z": -2,
      "name": "Rock_Stone"
    },
    {
      "x": -3,
      "y": 18,
      "z": -2,
      "name": "Rock_Stone"
    },
    {
      "x": -3,
      "y": 19,
      "z": -2,
      "name": "Rock_Stone"
    },
    {
      "x": -3,
      "y": 20,
      "z": -2,
      "name": "Rock_Stone"
    },
    {
      "x": -3,
      "y": 21,
      "z": -2,
      "name": "Rock_Stone"
    },
    {
      "x": -3,
      "y": 22,
      "z": -2,
      "name": "Rock_Stone"
    },
    {
      "x": -3,
      "y": 23,
      "z": -2,
      "name": "Rock_Stone"
    },
    {
      "x": -3,
      "y": 24,
      "z": -2,
      "name": "Rock_Stone"
    },
    {
      "x": -3,
      "y": 25,
      "z": -2,
      "name": "Rock_Stone"
    },
    {
      "x": -3,
      "y": 26,
      "z": -2,
      "name": "Rock_Stone"
    },
    {
      "x": -3,
      "y": 27,
      "z": -2,
      "name": "Rock_Stone"
    },
    {
      "x": -3,
      "y": 28,
      "z": -2,
      "name": "Rock_Stone"
    },
    {
      "x": -3,
      "y": 29,
      "z": -2,
      "name": "Soil_Dirt"
    },
    {
      "x": -3,
      "y": 30,
      "z": -2,
      "name": "Soil_Dirt"
    },
    {
      "x": -3,
      "y": 31,
      "z": -2,
      "name": "Soil_Dirt"
    },
    {
      "x": -3,
      "y": 32,
      "z": -2,
      "name": "Soil_Dirt"
    },
    {
      "x": -3,
      "y": 33,
      "z": -2,
      "name": "Soil_Grass"
    },
    {
      "x": -3,
      "y": 9,
      "z": -1,
      "name": "Rock_Stone"
    },
    {
      "x": -3,
      "y": 10,
      "z": -1,
      "name": "Rock_Stone"
    },
    {
      "x": -3,
      "y": 11,
      "z": -1,
      "name": "Rock_Stone"
    },
    {
      "x": -3,
      "y": 12,
      "z": -1,
      "name": "Rock_Stone"
    },
    {
      "x": -3,
      "y": 13,
      "z": -1,
      "name": "Rock_Stone"
    },
    {
      "x": -3,
      "y": 14,
      "z": -1,
      "name": "Rock_Stone"
    },
    {
      "x": -3,
      "y": 15,
      "z": -1,
      "name": "Rock_Stone"
    },
    {
      "x": -3,
      "y": 16,
      "z": -1,
      "name": "Rock_Stone"
    },
    {
      "x": -3,
      "y": 17,
      "z": -1,
      "name": "Rock_Stone"
    },
    {
      "x": -3,
      "y": 18,
      "z": -1,
      "name": "Rock_Stone"
    },
    {
      "x": -3,
      "y": 19,
      "z": -1,
      "name": "Rock_Stone"
    },
    {
      "x": -3,
      "y": 20,
      "z": -1,
      "name": "Rock_Stone"
    },
    {
      "x": -3,
      "y": 21,
      "z": -1,
      "name": "Rock_Stone"
    },
    {
      "x": -3,
      "y": 22,
      "z": -1,
      "name": "Rock_Stone"
    },
    {
      "x": -3,
      "y": 23,
      "z": -1,
      "name": "Rock_Stone"
    },
    {
      "x": -3,
      "y": 24,
      "z": -1,
      "name": "Rock_Stone"
    },
    {
      "x": -3,
      "y": 25,
      "z": -1,
      "name": "Rock_Stone"
    },
    {
      "x": -3,
      "y": 26,
      "z": -1,
      "name": "Rock_Stone"
    },
    {
      "x": -3,
      "y": 27,
      "z": -1,
      "name": "Rock_Stone"
    },
    {
      "x": -3,
      "y": 28,
      "z": -1,
      "name": "Rock_Stone"
    },
    {
      "x": -3,
      "y": 29,
      "z": -1,
      "name": "Rock_Stone"
    },
    {
      "x": -3,
      "y": 30,
      "z": -1,
      "name": "Soil_Dirt"
    },
    {
      "x": -3,
      "y": 31,
      "z": -1,
      "name": "Soil_Dirt"
    },
    {
      "x": -3,
      "y": 32,
      "z": -1,
      "name": "Soil_Dirt"
    },
    {
      "x": -3,
      "y": 33,
      "z": -1,
      "name": "Soil_Grass"
    },
    {
      "x": -3,
      "y": 9,
      "z": 0,
      "name": "Rock_Stone"
    },
    {
      "x": -3,
      "y": 10,
      "z": 0,
      "name": "Rock_Stone"
    },
    {
      "x": -3,
      "y": 11,
      "z": 0,
      "name": "Rock_Stone"
    },
    {
      "x": -3,
      "y": 12,
      "z": 0,
      "name": "Rock_Stone"
    },
    {
      "x": -3,
      "y": 13,
      "z": 0,
      "name": "Rock_Stone"
    },
    {
      "x": -3,
      "y": 14,
      "z": 0,
      "name": "Rock_Stone"
    },
    {
      "x": -3,
      "y": 15,
      "z": 0,
      "name": "Rock_Stone"
    },
    {
      "x": -3,
      "y": 16,
      "z": 0,
      "name": "Rock_Stone"
    },
    {
      "x": -3,
      "y": 17,
      "z": 0,
      "name": "Rock_Stone"
    },
    {
      "x": -3,
      "y": 18,
      "z": 0,
      "name": "Rock_Stone"
    },
    {
      "x": -3,
      "y": 19,
      "z": 0,
      "name": "Rock_Stone"
    },
    {
      "x": -3,
      "y": 20,
      "z": 0,
      "name": "Rock_Stone"
    },
    {
      "x": -3,
      "y": 21,
      "z": 0,
      "name": "Rock_Stone"
    },
    {
      "x": -3,
      "y": 22,
      "z": 0,
      "name": "Rock_Stone"
    },
    {
      "x": -3,
      "y": 23,
      "z": 0,
      "name": "Rock_Stone"
    },
    {
      "x": -3,
      "y": 24,
      "z": 0,
      "name": "Rock_Stone"
    },
    {
      "x": -3,
      "y": 25,
      "z": 0,
      "name": "Rock_Stone"
    },
    {
      "x": -3,
      "y": 26,
      "z": 0,
      "name": "Rock_Stone"
    },
    {
      "x": -3,
      "y": 27,
      "z": 0,
      "name": "Rock_Stone"
    },
    {
      "x": -3,
      "y": 28,
      "z": 0,
      "name": "Rock_Stone"
    },
    {
      "x": -3,
      "y": 29,
      "z": 0,
      "name": "Rock_Stone"
    },
    {
      "x": -3,
      "y": 30,
      "z": 0,
      "name": "Soil_Dirt"
    },
    {
      "x": -3,
      "y": 31,
      "z": 0,
      "name": "Soil_Dirt"
    },
    {
      "x": -3,
      "y": 32,
      "z": 0,
      "name": "Soil_Dirt"
    },
    {
      "x": -3,
      "y": 33,
      "z": 0,
      "name": "Soil_Dirt"
    },
    {
      "x": -3,
      "y": 34,
      "z": 0,
      "name": "Soil_Dirt"
    },
    {
      "x": -3,
      "y": 35,
      "z": 0,
      "name": "Soil_Grass"
    },
    {
      "x": -3,
      "y": 9,
      "z": 1,
      "name": "Rock_Stone"
    },
    {
      "x": -3,
      "y": 10,
      "z": 1,
      "name": "Rock_Stone"
    },
    {
      "x": -3,
      "y": 11,
      "z": 1,
      "name": "Rock_Stone"
    },
    {
      "x": -3,
      "y": 12,
      "z": 1,
      "name": "Rock_Stone"
    },
    {
      "x": -3,
      "y": 13,
      "z": 1,
      "name": "Rock_Stone"
    },
    {
      "x": -3,
      "y": 14,
      "z": 1,
      "name": "Rock_Stone"
    },
    {
      "x": -3,
      "y": 15,
      "z": 1,
      "name": "Rock_Stone"
    },
    {
      "x": -3,
      "y": 16,
      "z": 1,
      "name": "Rock_Stone"
    },
    {
      "x": -3,
      "y": 17,
      "z": 1,
      "name": "Rock_Stone"
    },
    {
      "x": -3,
      "y": 18,
      "z": 1,
      "name": "Rock_Stone"
    },
    {
      "x": -3,
      "y": 19,
      "z": 1,
      "name": "Rock_Stone"
    },
    {
      "x": -3,
      "y": 20,
      "z": 1,
      "name": "Rock_Stone"
    },
    {
      "x": -3,
      "y": 21,
      "z": 1,
      "name": "Rock_Stone"
    },
    {
      "x": -3,
      "y": 22,
      "z": 1,
      "name": "Rock_Stone"
    },
    {
      "x": -3,
      "y": 23,
      "z": 1,
      "name": "Rock_Stone"
    },
    {
      "x": -3,
      "y": 24,
      "z": 1,
      "name": "Rock_Stone"
    },
    {
      "x": -3,
      "y": 25,
      "z": 1,
      "name": "Rock_Stone"
    },
    {
      "x": -3,
      "y": 26,
      "z": 1,
      "name": "Rock_Stone"
    },
    {
      "x": -3,
      "y": 27,
      "z": 1,
      "name": "Rock_Stone_Mossy"
    },
    {
      "x": -3,
      "y": 28,
      "z": 1,
      "name": "Rock_Stone"
    },
    {
      "x": -3,
      "y": 29,
      "z": 1,
      "name": "Soil_Dirt"
    },
    {
      "x": -3,
      "y": 30,
      "z": 1,
      "name": "Soil_Dirt"
    },
    {
      "x": -3,
      "y": 31,
      "z": 1,
      "name": "Soil_Dirt"
    },
    {
      "x": -3,
      "y": 32,
      "z": 1,
      "name": "Soil_Dirt"
    },
    {
      "x": -3,
      "y": 33,
      "z": 1,
      "name": "Soil_Dirt"
    },
    {
      "x": -3,
      "y": 34,
      "z": 1,
      "name": "Soil_Dirt"
    },
    {
      "x": -3,
      "y": 35,
      "z": 1,
      "name": "Soil_Grass"
    },
    {
      "x": -3,
      "y": 9,
      "z": 2,
      "name": "Rock_Stone"
    },
    {
      "x": -3,
      "y": 10,
      "z": 2,
      "name": "Rock_Stone"
    },
    {
      "x": -3,
      "y": 11,
      "z": 2,
      "name": "Rock_Stone"
    },
    {
      "x": -3,
      "y": 12,
      "z": 2,
