{
  "version": 8,
  "blockIdVersion": 8,
  "anchorX": 2,
  "anchorY": 1,
  "anchorZ": 7,
  "blocks": [
    {
      "x": -4,
      "y": 0,
      "z": -6,
      "name": "Rock_Basalt_Cobble"
    },
    {
      "x": -4,
      "y": 1,
      "z": -6,
      "name": "Rock_Basalt_Cobble"
    },
    {
      "x": -4,
      "y": 2,
      "z": -6,
      "name": "Rock_Basalt_Brick_Smooth"
    },
    {
      "x": -4,
      "y": 3,
      "z": -6,
      "name": "Rock_Basalt_Cobble"
    },
    {
      "x": -4,
      "y": 4,
      "z": -6,
      "name": "Rock_Basalt_Cobble"
    },
    {
      "x": -4,
      "y": 5,
      "z": -6,
      "name": "Rock_Basalt_Cobble"
    },
    {
      "x": -4,
      "y": 6,
      "z": -6,
      "name": "Rock_Basalt_Cobble"
    },
    {
      "x": -4,
      "y": 0,
      "z": -5,
      "name": "Rock_Basalt_Cobble"
    },
    {
      "x": -4,
      "y": 1,
      "z": -5,
      "name": "Rock_Basalt_Cobble"
    },
    {
      "x": -4,
      "y": 2,
      "z": -5,
      "name": "Rock_Basalt_Brick_Smooth"
    },
    {
      "x": -4,
      "y": 3,
      "z": -5,
      "name": "Rock_Basalt_Cobble"
    },
    {
      "x": -4,
      "y": 4,
      "z": -5,
      "name": "Rock_Basalt_Cobble"
    },
    {
      "x": -4,
      "y": 5,
      "z": -5,
      "name": "Rock_Basalt_Cobble"
    },
    {
      "x": -4,
      "y": 6,
      "z": -5,
      "name": "Rock_Basalt_Cobble"
    },
    {
      "x": -4,
      "y": 0,
      "z": -4,
      "name": "Rock_Basalt_Cobble"
    },
    {
      "x": -4,
      "y": 1,
      "z": -4,
      "name": "Rock_Basalt_Cobble"
    },
    {
      "x": -4,
      "y": 2,
      "z": -4,
      "name": "Rock_Basalt_Brick_Smooth"
    },
    {
      "x": -4,
      "y": 3,
      "z": -4,
      "name": "Rock_Basalt_Cobble"
    },
    {
      "x": -4,
      "y": 4,
      "z": -4,
      "name": "Rock_Basalt_Cobble"
    },
    {
      "x": -4,
      "y": 5,
      "z": -4,
      "name": "Rock_Basalt_Cobble"
    },
    {
      "x": -4,
      "y": 6,
      "z": -4,
      "name": "Rock_Basalt_Cobble"
    },
    {
      "x": -4,
      "y": 0,
      "z": -3,
      "name": "Rock_Basalt_Cobble"
    },
    {
      "x": -4,
      "y": 1,
      "z": -3,
      "name": "Rock_Basalt_Cobble"
    },
    {
      "x": -4,
      "y": 2,
      "z": -3,
      "name": "Rock_Basalt_Brick_Smooth"
    },
    {
      "x": -4,
      "y": 3,
      "z": -3,
      "name": "Rock_Basalt_Cobble"
    },
    {
      "x": -4,
      "y": 4,
      "z": -3,
      "name": "Rock_Basalt_Cobble"
    },
    {
      "x": -4,
      "y": 5,
      "z": -3,
      "name": "Rock_Basalt_Cobble"
    },
    {
      "x": -4,
      "y": 6,
      "z": -3,
      "name": "Rock_Basalt_Cobble"
    },
    {
      "x": -4,
      "y": 0,
      "z": -2,
      "name": "Rock_Basalt_Cobble"
    },
    {
      "x": -4,
      "y": 1,
      "z": -2,
      "name": "Rock_Basalt_Cobble"
    },
    {
      "x": -4,
      "y": 2,
      "z": -2,
      "name": "Rock_Basalt_Brick_Smooth"
    },
    {
      "x": -4,
      "y": 3,
      "z": -2,
      "name": "Rock_Basalt_Cobble"
    },
    {
      "x": -4,
      "y": 4,
      "z": -2,
      "name": "Rock_Basalt_Cobble"
    },
    {
      "x": -4,
      "y": 5,
      "z": -2,
      "name": "Rock_Basalt_Cobble"
    },
    {
      "x": -4,
      "y": 6,
      "z": -2,
      "name": "Rock_Basalt_Cobble"
    },
    {
      "x": -4,
      "y": 0,
      "z": -1,
      "name": "Rock_Basalt_Cobble"
    },
    {
      "x": -4,
      "y": 1,
      "z": -1,
      "name": "Rock_Basalt_Cobble"
    },
    {
      "x": -4,
      "y": 2,
      "z": -1,
      "name": "Rock_Basalt_Brick_Smooth"
    },
    {
      "x": -4,
      "y": 3,
      "z": -1,
      "name": "Rock_Basalt_Cobble"
    },
    {
      "x": -4,
      "y": 4,
      "z": -1,
      "name": "Rock_Basalt_Cobble"
    },
    {
      "x": -4,
      "y": 5,
      "z": -1,
      "name": "Rock_Basalt_Cobble"
    },
    {
      "x": -4,
      "y": 6,
      "z": -1,
      "name": "Rock_Basalt_Cobble"
    },
    {
      "x": -4,
      "y": 0,
      "z": 0,
      "name": "Rock_Basalt_Cobble"
    },
    {
      "x": -4,
      "y": 1,
      "z": 0,
      "name": "Rock_Basalt_Cobble"
    },
    {
      "x": -4,
      "y": 2,
      "z": 0,
      "name": "Rock_Basalt_Brick_Smooth"
    },
    {
      "x": -4,
      "y": 3,
      "z": 0,
      "name": "Rock_Basalt_Cobble"
    },
    {
      "x": -4,
      "y": 4,
      "z": 0,
      "name": "Rock_Basalt_Cobble"
    },
    {
      "x": -4,
      "y": 5,
      "z": 0,
      "name": "Rock_Basalt_Cobble"
    },
    {
      "x": -4,
      "y": 6,
      "z": 0,
      "name": "Rock_Basalt_Cobble"
    },
    {
      "x": -4,
      "y": 0,
      "z": 1,
      "name": "Rock_Basalt_Cobble"
    },
    {
      "x": -4,
      "y": 1,
      "z": 1,
      "name": "Rock_Basalt_Cobble"
    },
    {
      "x": -4,
      "y": 2,
      "z": 1,
      "name": "Rock_Basalt_Brick_Smooth"
    },
    {
      "x": -4,
      "y": 3,
      "z": 1,
      "name": "Rock_Basalt_Cobble"
    },
    {
      "x": -4,
      "y": 4,
      "z": 1,
      "name": "Rock_Basalt_Cobble"
    },
    {
      "x": -4,
      "y": 5,
      "z": 1,
      "name": "Rock_Basalt_Cobble"
    },
    {
      "x": -4,
      "y": 6,
      "z": 1,
      "name": "Rock_Basalt_Cobble"
    },
    {
      "x": -4,
      "y": 0,
      "z": 2,
      "name": "Rock_Basalt_Cobble"
    },
    {
      "x": -4,
      "y": 1,
      "z": 2,
      "name": "Rock_Basalt_Cobble"
    },
    {
      "x": -4,
      "y": 2,
      "z": 2,
      "name": "Rock_Basalt_Brick_Smooth"
    },
    {
      "x": -4,
      "y": 3,
      "z": 2,
      "name": "Rock_Basalt_Cobble"
    },
    {
      "x": -4,
      "y": 4,
      "z": 2,
      "name": "Rock_Basalt_Cobble"
    },
    {
      "x": -4,
      "y": 5,
      "z": 2,
      "name": "Rock_Basalt_Cobble"
    },
    {
      "x": -4,
      "y": 6,
      "z": 2,
      "name": "Rock_Basalt_Cobble"
    },
    {
      "x": -4,
      "y": 0,
      "z": 3,
      "name": "Rock_Basalt_Cobble"
    },
    {
      "x": -4,
      "y": 1,
      "z": 3,
      "name": "Rock_Basalt_Cobble"
    },
    {
      "x": -4,
      "y": 2,
      "z": 3,
      "name": "Rock_Basalt_Brick_Smooth"
    },
    {
      "x": -4,
      "y": 3,
      "z": 3,
      "name": "Rock_Basalt_Cobble"
    },
    {
      "x": -4,
      "y": 4,
      "z": 3,
      "name": "Rock_Basalt_Cobble"
    },
    {
      "x": -4,
      "y": 5,
      "z": 3,
      "name": "Rock_Basalt_Cobble"
    },
    {
      "x": -4,
      "y": 6,
      "z": 3,
      "name": "Rock_Basalt_Cobble"
    },
    {
      "x": -4,
      "y": 0,
      "z": 4,
      "name": "Rock_Basalt_Cobble"
    },
    {
      "x": -4,
      "y": 1,
      "z": 4,
      "name": "Rock_Basalt_Cobble"
    },
    {
      "x": -4,
      "y": 2,
      "z": 4,
      "name": "Rock_Basalt_Brick_Smooth"
    },
    {
      "x": -4,
      "y": 3,
      "z": 4,
      "name": "Rock_Basalt_Cobble"
    },
    {
      "x": -4,
      "y": 4,
      "z": 4,
      "name": "Rock_Basalt_Cobble"
    },
    {
      "x": -4,
      "y": 5,
      "z": 4,
      "name": "Rock_Basalt_Cobble"
    },
    {
      "x": -4,
      "y": 6,
      "z": 4,
      "name": "Rock_Basalt_Cobble"
    },
    {
      "x": -4,
      "y": 0,
      "z": 5,
      "name": "Rock_Basalt_Cobble"
    },
    {
      "x": -4,
      "y": 1,
      "z": 5,
      "name": "Rock_Basalt_Cobble"
    },
    {
      "x": -4,
      "y": 2,
      "z": 5,
      "name": "Rock_Basalt_Brick_Smooth"
    },
    {
      "x": -4,
      "y": 3,
      "z": 5,
      "name": "Rock_Basalt_Cobble"
    },
    {
      "x": -4,
      "y": 4,
      "z": 5,
      "name": "Rock_Basalt_Cobble"
    },
    {
      "x": -4,
      "y": 5,
      "z": 5,
      "name": "Rock_Basalt_Cobble"
    },
    {
      "x": -4,
      "y": 6,
      "z": 5,
      "name": "Rock_Basalt_Cobble"
    },
    {
      "x": -4,
      "y": 0,
      "z": 6,
      "name": "Rock_Basalt_Cobble"
    },
    {
      "x": -4,
      "y": 1,
      "z": 6,
      "name": "Rock_Basalt_Cobble"
    },
    {
      "x": -4,
      "y": 2,
      "z": 6,
      "name": "Rock_Basalt_Brick_Smooth"
    },
    {
      "x": -4,
      "y": 3,
      "z": 6,
      "name": "Rock_Basalt_Cobble"
    },
    {
      "x": -4,
      "y": 4,
      "z": 6,
      "name": "Rock_Basalt_Cobble"
    },
    {
      "x": -4,
      "y": 5,
      "z": 6,
      "name": "Rock_Basalt_Cobble"
    },
    {
      "x": -4,
      "y": 6,
      "z": 6,
      "name": "Rock_Basalt_Cobble"
    },
    {
      "x": -4,
      "y": 0,
      "z": 7,
      "name": "Rock_Basalt_Cobble"
    },
    {
      "x": -4,
      "y": 1,
      "z": 7,
      "name": "Rock_Basalt_Cobble"
    },
    {
      "x": -4,
      "y": 2,
      "z": 7,
      "name": "Rock_Basalt_Brick_Smooth"
    },
    {
      "x": -4,
      "y": 3,
      "z": 7,
      "name": "Rock_Basalt_Cobble"
    },
    {
      "x": -4,
      "y": 4,
      "z": 7,
      "name": "Rock_Basalt_Cobble"
    },
    {
      "x": -4,
      "y": 5,
      "z": 7,
      "name": "Rock_Basalt_Cobble"
    },
    {
      "x": -4,
      "y": 6,
      "z": 7,
      "name": "Rock_Basalt_Cobble"
    },
    {
      "x": -3,
      "y": 0,
      "z": -6,
      "name": "Rock_Basalt_Cobble"
    },
    {
      "x": -3,
      "y": 1,
      "z": -6,
      "name": "Rock_Basalt_Cobble"
    },
    {
      "x": -3,
      "y": 2,
      "z": -6,
      "name": "Rock_Basalt_Brick_Smooth"
    },
    {
      "x": -3,
      "y": 3,
      "z": -6,
      "name": "Rock_Basalt_Cobble"
    },
    {
      "x": -3,
      "y": 4,
      "z": -6,
      "name": "Rock_Basalt_Cobble"
    },
    {
      "x": -3,
      "y": 5,
      "z": -6,
      "name": "Rock_Basalt_Cobble"
    },
    {
      "x": -3,
      "y": 6,
      "z": -6,
      "name": "Rock_Basalt_Cobble"
    },
    {
      "x": -3,
      "y": 0,
      "z": -5,
      "name": "Rock_Basalt_Cobble"
    },
    {
      "x": -3,
      "y": 1,
      "z": -5,
      "name": "Wood_Darkwood_Planks"
    },
    {
      "x": -3,
      "y": 2,
      "z": -5,
      "name": "Furniture_Tavern_Wardrobe",
      "filler": 31
    },
    {
      "x": -3,
      "y": 3,
      "z": -5,
      "name": "Furniture_Tavern_Wardrobe",
      "filler": 1055
    },
    {
      "x": -3,
      "y": 4,
      "z": -5,
      "name": "Empty"
    },
    {
      "x": -3,
      "y": 5,
      "z": -5,
      "name": "Wood_Darkwood_Planks"
    },
    {
      "x": -3,
      "y": 6,
      "z": -5,
      "name": "Wood_Darkwood_Planks"
    },
    {
      "x": -3,
      "y": 0,
      "z": -4,
      "name": "Rock_Basalt_Cobble"
    },
    {
      "x": -3,
      "y": 1,
      "z": -4,
      "name": "Wood_Darkwood_Planks"
    },
    {
      "x": -3,
      "y": 2,
      "z": -4,
      "name": "Empty"
    },
    {
      "x": -3,
      "y": 3,
      "z": -4,
      "name": "Empty"
    },
    {
      "x": -3,
      "y": 4,
      "z": -4,
      "name": "Empty"
    },
    {
      "x": -3,
      "y": 5,
      "z": -4,
      "name": "Wood_Darkwood_Planks_Half",
      "rotation": 5
    },
    {
      "x": -3,
      "y": 6,
      "z": -4,
      "name": "Wood_Darkwood_Planks"
    },
    {
      "x": -3,
      "y": 0,
      "z": -3,
      "name": "Rock_Basalt_Cobble"
    },
    {
      "x": -3,
      "y": 1,
      "z": -3,
      "name": "Wood_Darkwood_Planks"
    },
    {
      "x": -3,
      "y": 2,
      "z": -3,
      "name": "Furniture_Tavern_Wardrobe",
      "rotation": 1
    },
    {
      "x": -3,
      "y": 3,
      "z": -3,
      "name": "Furniture_Tavern_Wardrobe",
      "filler": 1024,
      "rotation": 1
    },
    {
      "x": -3,
      "y": 4,
      "z": -3,
      "name": "Furniture_Village_Shelf_Full",
      "rotation": 1
    },
    {
      "x": -3,
      "y": 5,
      "z": -3,
      "name": "Wood_Darkwood_Planks_Half",
      "rotation": 5
    },
    {
      "x": -3,
      "y": 6,
      "z": -3,
      "name": "Wood_Darkwood_Planks"
    },
    {
      "x": -3,
      "y": 0,
      "z": -2,
      "name": "Rock_Basalt_Cobble"
    },
    {
      "x": -3,
      "y": 1,
      "z": -2,
      "name": "Wood_Darkwood_Planks"
    },
    {
      "x": -3,
      "y": 2,
      "z": -2,
      "name": "Furniture_Tavern_Wardrobe",
      "filler": 32,
      "rotation": 1
    },
    {
      "x": -3,
      "y": 3,
      "z": -2,
      "name": "Furniture_Tavern_Wardrobe",
      "filler": 1056,
      "rotation": 1
    },
    {
      "x": -3,
      "y": 4,
      "z": -2,
      "name": "Empty"
    },
    {
      "x": -3,
      "y": 5,
      "z": -2,
      "name": "Wood_Darkwood_Planks_Half",
      "rotation": 5
    },
    {
      "x": -3,
      "y": 6,
      "z": -2,
      "name": "Wood_Darkwood_Planks"
    },
    {
      "x": -3,
      "y": 0,
      "z": -1,
      "name": "Rock_Basalt_Cobble"
    },
    {
      "x": -3,
      "y": 1,
      "z": -1,
      "name": "Wood_Darkwood_Planks"
    },
    {
      "x": -3,
      "y": 2,
      "z": -1,
      "name": "Furniture_Tavern_Planter"
    },
    {
      "x": -3,
      "y": 3,
      "z": -1,
      "name": "Plant_Flower_Tall_Yellow"
    },
    {
      "x": -3,
      "y": 4,
      "z": -1,
      "name": "Empty"
    },
    {
      "x": -3,
      "y": 5,
      "z": -1,
      "name": "Wood_Darkwood_Planks_Half",
      "rotation": 5
    },
    {
      "x": -3,
      "y": 6,
      "z": -1,
      "name": "Wood_Darkwood_Planks"
    },
    {
      "x": -3,
      "y": 0,
      "z": 0,
      "name": "Rock_Basalt_Cobble"
    },
    {
      "x": -3,
      "y": 1,
      "z": 0,
      "name": "Wood_Darkwood_Planks"
    },
    {
      "x": -3,
      "y": 2,
      "z": 0,
      "name": "Furniture_Village_Shelf_Full",
      "rotation": 1
    },
    {
      "x": -3,
      "y": 3,
      "z": 0,
      "name": "Furniture_Village_Shelf_Full",
      "rotation": 1
    },
    {
      "x": -3,
      "y": 4,
      "z": 0,
      "name": "Furniture_Village_Shelf_Full",
      "rotation": 1
    },
    {
      "x": -3,
      "y": 5,
      "z": 0,
      "name": "Wood_Darkwood_Planks_Half",
      "rotation": 5
    },
    {
      "x": -3,
      "y": 6,
      "z": 0,
      "name": "Wood_Darkwood_Planks"
    },
    {
      "x": -3,
      "y": 0,
      "z": 1,
      "name": "Rock_Basalt_Cobble"
    },
    {
      "x": -3,
      "y": 1,
      "z": 1,
      "name": "Wood_Darkwood_Planks"
    },
    {
      "x": -3,
      "y": 2,
      "z": 1,
      "name": "Furniture_Village_Shelf_Full",
      "rotation": 1
    },
    {
      "x": -3,
      "y": 3,
      "z": 1,
      "name": "Furniture_Village_Shelf_Full",
      "rotation": 1
    },
    {
      "x": -3,
      "y": 4,
      "z": 1,
      "name": "Furniture_Village_Shelf_Full",
      "rotation": 1
    },
    {
      "x": -3,
      "y": 5,
      "z": 1,
      "name": "Wood_Darkwood_Planks_Half",
      "rotation": 5
    },
    {
      "x": -3,
      "y": 6,
      "z": 1,
      "name": "Wood_Darkwood_Planks"
    },
    {
      "x": -3,
      "y": 0,
      "z": 2,
      "name": "Rock_Basalt_Cobble"
    },
    {
      "x": -3,
      "y": 1,
      "z": 2,
      "name": "Wood_Darkwood_Planks"
    },
    {
      "x": -3,
      "y": 2,
      "z": 2,
      "name": "Empty"
    },
    {
      "x": -3,
      "y": 3,
      "z": 2,
      "name": "Empty"
    },
    {
      "x": -3,
      "y": 4,
      "z": 2,
      "name": "Empty"
    },
    {
      "x": -3,
      "y": 5,
      "z": 2,
      "name": "Wood_Darkwood_Planks_Half",
      "rotation": 5
    },
    {
      "x": -3,
      "y": 6,
      "z": 2,
      "name": "Wood_Darkwood_Planks"
    },
    {
      "x": -3,
      "y": 0,
      "z": 3,
      "name": "Rock_Basalt_Cobble"
    },
    {
      "x": -3,
      "y": 1,
      "z": 3,
      "name": "Wood_Darkwood_Planks"
    },
    {
      "x": -3,
      "y": 2,
      "z": 3,
      "name": "Furniture_Village_Bookcase",
      "rotation": 1
    },
    {
      "x": -3,
      "y": 3,
      "z": 3,
      "name": "Furniture_Village_Bookcase",
      "rotation": 1
    },
    {
      "x": -3,
      "y": 4,
      "z": 3,
      "name": "Furniture_Village_Bookcase",
      "rotation": 1
    },
    {
      "x": -3,
      "y": 5,
      "z": 3,
      "name": "Wood_Darkwood_Planks_Half",
      "rotation": 5
    },
    {
      "x": -3,
      "y": 6,
      "z": 3,
      "name": "Wood_Darkwood_Planks"
    },
    {
      "x": -3,
      "y": 0,
      "z": 4,
      "name": "Rock_Basalt_Cobble"
    },
    {
      "x": -3,
      "y": 1,
      "z": 4,
      "name": "Wood_Darkwood_Planks"
    },
    {
      "x": -3,
      "y": 2,
      "z": 4,
      "name": "Furniture_Village_Bookcase",
      "rotation": 1
    },
    {
      "x": -3,
      "y": 3,
      "z": 4,
      "name": "Furniture_Village_Shelf_Full",
      "rotation": 1
    },
    {
      "x": -3,
      "y": 4,
      "z": 4,
      "name": "Furniture_Village_Shelf_Full",
      "rotation": 1
    },
    {
      "x": -3,
      "y": 5,
      "z": 4,
      "name": "Wood_Darkwood_Planks_Half",
      "rotation": 5
    },
    {
      "x": -3,
      "y": 6,
      "z": 4,
      "name": "Wood_Darkwood_Planks"
    },
    {
      "x": -3,
      "y": 0,
      "z": 5,
      "name": "Rock_Basalt_Cobble"
    },
    {
      "x": -3,
      "y": 1,
      "z": 5,
      "name": "Wood_Darkwood_Planks"
    },
    {
      "x": -3,
      "y": 2,
      "z": 5,
      "name": "Furniture_Village_Bookcase",
      "rotation": 1
    },
    {
      "x": -3,
      "y": 3,
      "z": 5,
      "name": "Furniture_Village_Shelf_Full",
      "rotation": 1
    },
    {
      "x": -3,
      "y": 4,
      "z": 5,
      "name": "Furniture_Village_Shelf_Full",
      "rotation": 1
    },
    {
      "x": -3,
      "y": 5,
      "z": 5,
      "name": "Wood_Darkwood_Planks_Half",
      "rotation": 5
    },
    {
      "x": -3,
      "y": 6,
      "z": 5,
      "name": "Wood_Darkwood_Planks"
    },
    {
      "x": -3,
      "y": 0,
      "z": 6,
      "name": "Rock_Basalt_Cobble"
    },
    {
      "x": -3,
      "y": 1,
      "z": 6,
      "name": "Wood_Darkwood_Planks"
    },
    {
      "x": -3,
      "y": 2,
      "z": 6,
      "name": "Empty"
    },
    {
      "x": -3,
      "y": 3,
      "z": 6,
      "name": "Empty"
    },
    {
      "x": -3,
      "y": 4,
      "z": 6,
      "name": "Empty"
    },
    {
      "x": -3,
      "y": 5,
      "z": 6,
      "name": "Wood_Darkwood_Planks"
    },
    {
      "x": -3,
      "y": 6,
      "z": 6,
      "name": "Wood_Darkwood_Planks"
    },
    {
      "x": -3,
      "y": 0,
      "z": 7,
      "name": "Rock_Basalt_Cobble"
    },
    {
      "x": -3,
      "y": 1,
      "z": 7,
      "name": "Rock_Basalt_Cobble"
    },
    {
      "x": -3,
      "y": 2,
      "z": 7,
      "name": "Rock_Basalt_Brick_Smooth"
    },
    {
      "x": -3,
      "y": 3,
      "z": 7,
      "name": "Rock_Basalt_Cobble"
    },
    {
      "x": -3,
      "y": 4,
      "z": 7,
      "name": "Rock_Basalt_Cobble"
    },
    {
      "x": -3,
      "y": 5,
      "z": 7,
      "name": "Rock_Basalt_Cobble"
    },
    {
      "x": -3,
      "y": 6,
      "z": 7,
      "name": "Rock_Basalt_Cobble"
    },
    {
      "x": -2,
      "y": 0,
      "z": -6,
      "name": "Rock_Basalt_Cobble"
    },
    {
      "x": -2,
      "y": 1,
      "z": -6,
      "name": "Rock_Basalt_Cobble"
    },
    {
      "x": -2,
      "y": 2,
      "z": -6,
      "name": "Rock_Basalt_Brick_Smooth"
    },
    {
      "x": -2,
      "y": 3,
      "z": -6,
      "name": "Rock_Basalt_Cobble"
    },
    {
      "x": -2,
      "y": 4,
      "z": -6,
      "name": "Rock_Basalt_Cobble"
    },
    {
      "x": -2,
      "y": 5,
      "z": -6,
      "name": "Rock_Basalt_Cobble"
    },
    {
      "x": -2,
      "y": 6,
      "z": -6,
      "name": "Rock_Basalt_Cobble"
    },
    {
      "x": -2,
      "y": 0,
      "z": -5,
      "name": "Rock_Basalt_Cobble"
    },
    {
      "x": -2,
      "y": 1,
      "z": -5,
      "name": "Wood_Darkwood_Planks"
    },
    {
      "x": -2,
      "y": 2,
      "z": -5,
      "name": "Furniture_Tavern_Wardrobe"
    },
    {
      "x": -2,
      "y": 3,
      "z": -5,
      "name": "Furniture_Tavern_Wardrobe",
      "filler": 1024
    },
    {
      "x": -2,
      "y": 4,
      "z": -5,
      "name": "Deco_Lantern"
    },
    {
      "x": -2,
      "y": 5,
      "z": -5,
      "name": "Wood_Darkwood_Planks_Half",
      "rotation": 4
    },
    {
      "x": -2,
      "y": 6,
      "z": -5,
      "name": "Wood_Darkwood_Planks"
    },
    {
      "x": -2,
      "y": 0,
      "z": -4,
      "name": "Rock_Basalt_Cobble"
    },
    {
      "x": -2,
      "y": 1,
      "z": -4,
      "name": "Wood_Darkwood_Planks"
    },
    {
      "x": -2,
      "y": 2,
      "z": -4,
      "name": "Empty"
    },
    {
      "x": -2,
      "y": 3,
      "z": -4,
      "name": "Empty"
    },
    {
      "x": -2,
      "y": 4,
      "z": -4,
      "name": "Empty"
    },
    {
      "x": -2,
      "y": 5,
      "z": -4,
      "name": "Empty"
    },
    {
      "x": -2,
      "y": 6,
      "z": -4,
      "name": "Wood_Darkwood_Planks"
    },
    {
      "x": -2,
      "y": 0,
      "z": -3,
      "name": "Rock_Basalt_Cobble"
    },
    {
      "x": -2,
      "y": 1,
      "z": -3,
      "name": "Wood_Darkwood_Planks"
    },
    {
      "x": -2,
      "y": 2,
      "z": -3,
      "name": "Empty"
    },
    {
      "x": -2,
      "y": 3,
      "z": -3,
      "name": "Empty"
    },
    {
      "x": -2,
      "y": 4,
      "z": -3,
      "name": "Empty"
    },
    {
      "x": -2,
      "y": 5,
      "z": -3,
      "name": "Empty"
    },
    {
      "x": -2,
      "y": 6,
      "z": -3,
      "name": "Wood_Darkwood_Planks"
    },
    {
      "x": -2,
      "y": 0,
      "z": -2,
      "name": "Rock_Basalt_Cobble"
    },
    {
      "x": -2,
      "y": 1,
      "z": -2,
      "name": "Wood_Darkwood_Planks"
    },
    {
      "x": -2,
      "y": 2,
      "z": -2,
      "name": "Empty"
    },
    {
      "x": -2,
      "y": 3,
      "z": -2,
      "name": "Empty"
    },
    {
      "x": -2,
      "y": 4,
      "z": -2,
      "name": "Empty"
    },
    {
      "x": -2,
      "y": 5,
      "z": -2,
      "name": "Empty"
    },
    {
      "x": -2,
      "y": 6,
      "z": -2,
      "name": "Wood_Darkwood_Planks"
    },
    {
      "x": -2,
      "y": 0,
      "z": -1,
      "name": "Rock_Basalt_Cobble"
    },
    {
      "x": -2,
      "y": 1,
      "z": -1,
      "name": "Wood_Darkwood_Planks"
    },
    {
      "x": -2,
      "y": 2,
      "z": -1,
      "name": "Empty"
    },
    {
      "x": -2,
      "y": 3,
      "z": -1,
      "name": "Empty"
    },
    {
      "x": -2,
      "y": 4,
      "z": -1,
      "name": "Empty"
    },
    {
      "x": -2,
      "y": 5,
      "z": -1,
      "name": "Empty"
    },
    {
      "x": -2,
      "y": 6,
      "z": -1,
      "name": "Wood_Darkwood_Planks"
    },
    {
      "x": -2,
      "y": 0,
      "z": 0,
      "name": "Rock_Basalt_Cobble"
    },
    {
      "x": -2,
      "y": 1,
      "z": 0,
      "name": "Wood_Darkwood_Planks"
    },
    {
      "x": -2,
      "y": 2,
      "z": 0,
      "name": "Empty"
    },
    {
      "x": -2,
      "y": 3,
      "z": 0,
      "name": "Empty"
    },
    {
      "x": -2,
      "y": 4,
      "z": 0,
      "name": "Empty"
    },
    {
      "x": -2,
      "y": 5,
      "z": 0,
      "name": "Empty"
    },
    {
      "x": -2,
      "y": 6,
      "z": 0,
      "name": "Wood_Darkwood_Planks"
    },
    {
      "x": -2,
      "y": 0,
      "z": 1,
      "name": "Rock_Basalt_Cobble"
    },
    {
      "x": -2,
      "y": 1,
      "z": 1,
      "name": "Wood_Darkwood_Planks"
    },
    {
      "x": -2,
      "y": 2,
      "z": 1,
      "name": "Empty"
    },
    {
      "x": -2,
      "y": 3,
      "z": 1,
      "name": "Empty"
    },
    {
      "x": -2,
      "y": 4,
      "z": 1,
      "name": "Empty"
    },
    {
      "x": -2,
      "y": 5,
      "z": 1,
      "name": "Wood_Darkwood_Planks_Half",
      "rotation": 7
    },
    {
      "x": -2,
      "y": 6,
      "z": 1,
      "name": "Wood_Darkwood_Planks"
    },
    {
      "x": -2,
      "y": 0,
      "z": 2,
      "name": "Rock_Basalt_Cobble"
    },
    {
      "x": -2,
      "y": 1,
      "z": 2,
      "name": "Wood_Darkwood_Planks"
    },
    {
      "x": -2,
      "y": 2,
      "z": 2,
      "name": "Empty"
    },
    {
      "x": -2,
      "y": 3,
      "z": 2,
      "name": "Empty"
    },
    {
      "x": -2,
      "y": 4,
      "z": 2,
      "name": "Empty"
    },
    {
      "x": -2,
      "y": 5,
      "z": 2,
      "name": "Wood_Darkwood_Planks_Half",
      "rotation": 7
    },
    {
      "x": -2,
      "y": 6,
      "z": 2,
      "name": "Wood_Darkwood_Planks"
    },
    {
      "x": -2,
      "y": 0,
      "z": 3,
      "name": "Rock_Basalt_Cobble"
    },
    {
      "x": -2,
      "y": 1,
      "z": 3,
      "name": "Wood_Darkwood_Planks"
    },
    {
      "x": -2,
      "y": 2,
      "z": 3,
      "name": "Empty"
    },
    {
      "x": -2,
      "y": 3,
      "z": 3,
      "name": "Empty"
    },
    {
      "x": -2,
      "y": 4,
      "z": 3,
      "name": "Empty"
    },
    {
      "x": -2,
      "y": 5,
      "z": 3,
      "name": "Wood_Darkwood_Planks_Half",
      "rotation": 7
    },
    {
      "x": -2,
      "y": 6,
      "z": 3,
      "name": "Wood_Darkwood_Planks"
    },
    {
      "x": -2,
      "y": 0,
      "z": 4,
      "name": "Rock_Basalt_Cobble"
    },
    {
      "x": -2,
      "y": 1,
      "z": 4,
      "name": "Wood_Darkwood_Planks"
    },
    {
      "x": -2,
      "y": 2,
      "z": 4,
      "name": "Empty"
    },
    {
      "x": -2,
      "y": 3,
      "z": 4,
      "name": "Empty"
    },
    {
      "x": -2,
      "y": 4,
      "z": 4,
      "name": "Empty"
    },
    {
      "x": -2,
      "y": 5,
      "z": 4,
      "name": "Empty"
    },
    {
      "x": -2,
      "y": 6,
      "z": 4,
      "name": "Wood_Darkwood_Planks"
    },
    {
      "x": -2,
      "y": 0,
      "z": 5,
      "name": "Rock_Basalt_Cobble"
    },
    {
      "x": -2,
      "y": 1,
      "z": 5,
      "name": "Wood_Darkwood_Planks"
    },
    {
      "x": -2,
      "y": 2,
      "z": 5,
      "name": "Empty"
    },
    {
      "x": -2,
      "y": 3,
      "z": 5,
      "name": "Empty"
    },
    {
      "x": -2,
      "y": 4,
      "z": 5,
      "name": "Empty"
    },
    {
      "x": -2,
      "y": 5,
      "z": 5,
      "name": "Empty"
    },
    {
      "x": -2,
      "y": 6,
      "z": 5,
      "name": "Wood_Darkwood_Planks"
    },
    {
      "x": -2,
      "y": 0,
      "z": 6,
      "name": "Rock_Basalt_Cobble"
    },
    {
      "x": -2,
      "y": 1,
      "z": 6,
      "name": "Wood_Darkwood_Planks"
    },
    {
      "x": -2,
      "y": 2,
      "z": 6,
      "name": "Empty"
    },
    {
      "x": -2,
      "y": 3,
      "z": 6,
      "name": "Empty"
    },
    {
      "x": -2,
      "y": 4,
      "z": 6,
      "name": "Empty"
    },
    {
      "x": -2,
      "y": 5,
      "z": 6,
      "name": "Wood_Darkwood_Planks_Half",
      "rotation": 6
    },
    {
      "x": -2,
      "y": 6,
      "z": 6,
      "name": "Wood_Darkwood_Planks"
    },
    {
      "x": -2,
      "y": 0,
      "z": 7,
      "name": "Rock_Basalt_Cobble"
    },
    {
      "x": -2,
      "y": 1,
      "z": 7,
      "name": "Rock_Basalt_Cobble"
    },
    {
      "x": -2,
      "y": 2,
      "z": 7,
      "name": "Rock_Basalt_Brick_Smooth"
    },
    {
      "x": -2,
      "y": 3,
      "z": 7,
      "name": "Rock_Basalt_Cobble"
    },
    {
      "x": -2,
      "y": 4,
      "z": 7,
      "name": "Rock_Basalt_Cobble"
    },
    {
      "x": -2,
      "y": 5,
      "z": 7,
      "name": "Rock_Basalt_Cobble"
    },
    {
      "x": -2,
      "y": 6,
      "z": 7,
      "name": "Rock_Basalt_Cobble"
    },
    {
      "x": -1,
      "y": 0,
      "z": -6,
      "name": "Rock_Basalt_Cobble"
    },
    {
      "x": -1,
      "y": 1,
      "z": -6,
      "name": "Rock_Basalt_Cobble"
    },
    {
      "x": -1,
      "y": 2,
      "z": -6,
      "name": "Rock_Basalt_Brick_Smooth"
    },
    {
      "x": -1,
      "y": 3,
      "z": -6,
      "name": "Rock_Basalt_Cobble"
    },
    {
      "x": -1,
      "y": 4,
      "z": -6,
      "name": "Rock_Basalt_Cobble"
    },
    {
      "x": -1,
      "y": 5,
      "z": -6,
      "name": "Rock_Basalt_Cobble"
    },
    {
      "x": -1,
      "y": 6,
      "z": -6,
      "name": "Rock_Basalt_Cobble"
    },
    {
      "x": -1,
      "y": 0,
      "z": -5,
      "name": "Rock_Basalt_Cobble"
    },
    {
      "x": -1,
      "y": 1,
      "z": -5,
      "name": "Wood_Darkwood_Planks"
    },
    {
      "x": -1,
      "y": 2,
      "z": -5,
      "name": "Empty"
    },
    {
      "x": -1,
      "y": 3,
      "z": -5,
      "name": "Empty"
    },
    {
      "x": -1,
      "y": 4,
      "z": -5,
      "name": "Empty"
    },
    {
      "x": -1,
      "y": 5,
      "z": -5,
      "name": "Wood_Darkwood_Planks"
    },
    {
      "x": -1,
      "y": 6,
      "z": -5,
      "name": "Wood_Darkwood_Planks"
    },
    {
      "x": -1,
      "y": 0,
      "z": -4,
      "name": "Rock_Basalt_Cobble"
    },
    {
      "x": -1,
      "y": 1,
      "z": -4,
      "name": "Wood_Darkwood_Planks"
    },
    {
      "x": -1,
      "y": 2,
      "z": -4,
      "name": "Empty"
    },
    {
      "x": -1,
      "y": 3,
      "z": -4,
      "name": "Empty"
    },
    {
      "x": -1,
      "y": 4,
      "z": -4,
      "name": "Empty"
    },
    {
      "x": -1,
      "y": 5,
      "z": -4,
      "name": "Wood_Darkwood_Planks_Half",
      "rotation": 7
    },
    {
      "x": -1,
      "y": 6,
      "z": -4,
      "name": "Wood_Darkwood_Planks"
    },
    {
      "x": -1,
      "y": 0,
      "z": -3,
      "name": "Rock_Basalt_Cobble"
    },
    {
      "x": -1,
      "y": 1,
      "z": -3,
      "name": "Wood_Darkwood_Planks"
    },
    {
      "x": -1,
      "y": 2,
      "z": -3,
      "name": "Empty"
    },
    {
      "x": -1,
      "y": 3,
      "z": -3,
      "name": "Empty"
    },
    {
      "x": -1,
      "y": 4,
      "z": -3,
      "name": "Empty"
    },
    {
      "x": -1,
      "y": 5,
      "z": -3,
      "name": "Empty"
    },
    {
      "x": -1,
      "y": 6,
      "z": -3,
      "name": "Wood_Darkwood_Planks"
    },
    {
      "x": -1,
      "y": 0,
      "z": -2,
      "name": "Rock_Basalt_Cobble"
    },
    {
      "x": -1,
      "y": 1,
      "z": -2,
      "name": "Wood_Darkwood_Planks"
    },
    {
      "x": -1,
      "y": 2,
      "z": -2,
      "name": "Empty"
    },
    {
      "x": -1,
      "y": 3,
      "z": -2,
      "name": "Empty"
    },
    {
      "x": -1,
      "y": 4,
      "z": -2,
      "name": "Empty"
    },
    {
      "x": -1,
      "y": 5,
      "z": -2,
      "name": "Empty"
    },
    {
      "x": -1,
      "y": 6,
      "z": -2,
      "name": "Wood_Darkwood_Planks"
    },
    {
      "x": -1,
      "y": 0,
      "z": -1,
      "name": "Rock_Basalt_Cobble"
    },
    {
      "x": -1,
      "y": 1,
      "z": -1,
      "name": "Wood_Darkwood_Planks"
    },
    {
      "x": -1,
      "y": 2,
      "z": -1,
      "name": "Empty"
    },
    {
      "x": -1,
      "y": 3,
      "z": -1,
      "name": "Empty"
    },
    {
      "x": -1,
      "y": 4,
      "z": -1,
      "name": "Empty"
    },
    {
      "x": -1,
      "y": 5,
      "z": -1,
      "name": "Empty"
    },
    {
      "x": -1,
      "y": 6,
      "z": -1,
      "name": "Wood_Darkwood_Planks"
    },
    {
      "x": -1,
      "y": 0,
      "z": 0,
      "name": "Rock_Basalt_Cobble"
    },
    {
      "x": -1,
      "y": 1,
      "z": 0,
      "name": "Wood_Darkwood_Planks"
    },
    {
      "x": -1,
      "y": 2,
      "z": 0,
      "name": "Empty"
    },
    {
      "x": -1,
      "y": 3,
      "z": 0,
      "name": "Empty"
    },
    {
      "x": -1,
      "y": 4,
      "z": 0,
      "name": "Empty"
    },
    {
      "x": -1,
      "y": 5,
      "z": 0,
      "name": "Wood_Darkwood_Planks_Half",
      "rotation": 6
    },
    {
      "x": -1,
      "y": 6,
      "z": 0,
      "name": "Wood_Darkwood_Planks"
    },
    {
      "x": -1,
      "y": 0,
      "z": 1,
      "name": "Rock_Basalt_Cobble"
    },
    {
      "x": -1,
      "y": 1,
      "z": 1,
      "name": "Wood_Darkwood_Planks"
    },
    {
      "x": -1,
      "y": 2,
      "z": 1,
      "name": "Rock_Basalt_Brick_Smooth"
    },
    {
      "x": -1,
      "y": 3,
      "z": 1,
      "name": "Rock_Basalt_Cobble"
    },
    {
      "x": -1,
      "y": 4,
      "z": 1,
      "name": "Rock_Basalt_Cobble"
    },
    {
      "x": -1,
      "y": 5,
      "z": 1,
      "name": "Rock_Basalt_Cobble"
    },
    {
      "x": -1,
      "y": 6,
      "z": 1,
      "name": "Wood_Darkwood_Planks"
    },
    {
      "x": -1,
      "y": 0,
      "z": 2,
      "name": "Rock_Basalt_Cobble"
    },
    {
      "x": -1,
      "y": 1,
      "z": 2,
      "name": "Wood_Darkwood_Planks"
    },
    {
      "x": -1,
      "y": 2,
      "z": 2,
      "name": "Rock_Basalt_Brick_Smooth"
    },
    {
      "x": -1,
      "y": 3,
      "z": 2,
      "name": "Rock_Basalt_Cobble"
    },
    {
      "x": -1,
      "y": 4,
      "z": 2,
      "name": "Rock_Basalt_Cobble"
    },
    {
      "x": -1,
      "y": 5,
      "z": 2,
      "name": "Rock_Basalt_Cobble"
    },
    {
      "x": -1,
      "y": 6,
      "z": 2,
      "name": "Wood_Darkwood_Planks"
    },
    {
      "x": -1,
      "y": 0,
      "z": 3,
      "name": "Rock_Basalt_Cobble"
    },
    {
      "x": -1,
      "y": 1,
      "z": 3,
      "name": "Wood_Darkwood_Planks"
    },
    {
      "x": -1,
      "y": 2,
      "z": 3,
      "name": "Rock_Basalt_Brick_Smooth"
    },
    {
      "x": -1,
      "y": 3,
      "z": 3,
      "name": "Rock_Basalt_Cobble"
    },
    {
      "x": -1,
      "y": 4,
      "z": 3,
      "name": "Rock_Basalt_Cobble"
    },
    {
      "x": -1,
      "y": 5,
      "z": 3,
      "name": "Rock_Basalt_Cobble"
    },
    {
      "x": -1,
      "y": 6,
      "z": 3,
      "name": "Wood_Darkwood_Planks"
    },
    {
      "x": -1,
      "y": 0,
      "z": 4,
      "name": "Rock_Basalt_Cobble"
    },
    {
      "x": -1,
      "y": 1,
      "z": 4,
      "name": "Wood_Darkwood_Planks"
    },
    {
      "x": -1,
      "y": 2,
      "z": 4,
      "name": "Empty"
    },
    {
      "x": -1,
      "y": 3,
      "z": 4,
      "name": "Empty"
    },
    {
      "x": -1,
      "y": 4,
      "z": 4,
      "name": "Empty"
    },
    {
      "x": -1,
      "y": 5,
      "z": 4,
      "name": "Wood_Darkwood_Planks_Half",
      "rotation": 4
    },
    {
      "x": -1,
      "y": 6,
      "z": 4,
      "name": "Wood_Darkwood_Planks"
    },
    {
      "x": -1,
      "y": 0,
      "z": 5,
      "name": "Rock_Basalt_Cobble"
    },
    {
      "x": -1,
      "y": 1,
      "z": 5,
      "name": "Wood_Darkwood_Planks"
    },
    {
      "x": -1,
      "y": 2,
      "z": 5,
      "name": "Empty"
    },
    {
      "x": -1,
      "y": 3,
      "z": 5,
      "name": "Empty"
    },
    {
      "x": -1,
      "y": 4,
      "z": 5,
      "name": "Empty"
    },
    {
      "x": -1,
      "y": 5,
      "z": 5,
      "name": "Empty"
    },
    {
      "x": -1,
      "y": 6,
      "z": 5,
      "name": "Wood_Darkwood_Planks"
    },
    {
      "x": -1,
      "y": 0,
      "z": 6,
      "name": "Rock_Basalt_Cobble"
    },
    {
      "x": -1,
      "y": 1,
      "z": 6,
      "name": "Wood_Darkwood_Planks"
    },
    {
      "x": -1,
      "y": 2,
      "z": 6,
      "name": "Empty"
    },
    {
      "x": -1,
      "y": 3,
      "z": 6,
      "name": "Empty"
    },
    {
      "x": -1,
      "y": 4,
      "z": 6,
      "name": "Empty"
    },
    {
      "x": -1,
      "y": 5,
      "z": 6,
      "name": "Wood_Darkwood_Planks_Half",
      "rotation": 6
    },
    {
      "x": -1,
      "y": 6,
      "z": 6,
      "name": "Wood_Darkwood_Planks"
    },
    {
      "x": -1,
      "y": 0,
      "z": 7,
      "name": "Rock_Basalt_Cobble"
    },
    {
      "x": -1,
      "y": 1,
      "z": 7,
      "name": "Wood_Darkwood_Planks"
    },
    {
      "x": -1,
      "y": 2,
      "z": 7,
      "name": "Empty"
    },
    {
      "x": -1,
      "y": 3,
      "z": 7,
      "name": "Empty"
    },
    {
      "x": -1,
      "y": 4,
      "z": 7,
      "name": "Empty"
    },
    {
      "x": -1,
      "y": 5,
      "z": 7,
      "name": "Rock_Basalt_Cobble"
    },
    {
      "x": -1,
      "y": 6,
      "z": 7,
      "name": "Rock_Basalt_Cobble"
    },
    {
      "x": 0,
      "y": 0,
      "z": -6,
      "name": "Rock_Basalt_Cobble"
    },
    {
      "x": 0,
      "y": 1,
      "z": -6,
      "name": "Rock_Basalt_Cobble"
    },
    {
      "x": 0,
      "y": 2,
      "z": -6,
      "name": "Rock_Basalt_Brick_Smooth"
    },
    {
      "x": 0,
      "y": 3,
      "z": -6,
      "name": "Rock_Basalt_Cobble"
    },
    {
      "x": 0,
      "y": 4,
      "z": -6,
      "name": "Rock_Basalt_Cobble"
    },
    {
      "x": 0,
      "y": 5,
      "z": -6,
      "name": "Rock_Basalt_Cobble"
    },
    {
      "x": 0,
      "y": 6,
      "z": -6,
      "name": "Rock_Basalt_Cobble"
    },
    {
      "x": 0,
      "y": 0,
      "z": -5,
      "name": "Rock_Basalt_Cobble"
    },
    {
      "x": 0,
      "y": 1,
      "z": -5,
      "name": "Wood_Darkwood_Planks"
    },
    {
      "x": 0,
      "y": 2,
      "z": -5,
      "name": "Rock_Basalt_Brick_Smooth"
    },
    {
      "x": 0,
      "y": 3,
      "z": -5,
      "name": "Rock_Basalt_Cobble"
    },
    {
      "x": 0,
      "y": 4,
      "z": -5,
      "name": "Rock_Basalt_Cobble"
    },
    {
      "x": 0,
      "y": 5,
      "z": -5,
      "name": "Rock_Basalt_Cobble"
    },
    {
      "x": 0,
      "y": 6,
      "z": -5,
      "name": "Wood_Darkwood_Planks"
    },
    {
      "x": 0,
      "y": 0,
      "z": -4,
      "name": "Rock_Basalt_Cobble"
    },
    {
      "x": 0,
      "y": 1,
      "z": -4,
      "name": "Wood_Darkwood_Planks"
    },
    {
      "x": 0,
      "y": 2,
      "z": -4,
      "name": "Rock_Basalt_Brick_Smooth"
    },
    {
      "x": 0,
      "y": 3,
      "z": -4,
      "name": "Rock_Basalt_Cobble"
    },
    {
      "x": 0,
      "y": 4,
      "z": -4,
      "name": "Rock_Basalt_Cobble"
    },
    {
      "x": 0,
      "y": 5,
      "z": -4,
      "name": "Rock_Basalt_Cobble"
    },
    {
      "x": 0,
      "y": 6,
      "z": -4,
      "name": "Wood_Darkwood_Planks"
    },
    {
      "x": 0,
      "y": 0,
      "z": -3,
      "name": "Rock_Basalt_Cobble"
    },
    {
      "x": 0,
      "y": 1,
      "z": -3,
      "name": "Wood_Darkwood_Planks"
    },
    {
      "x": 0,
      "y": 2,
      "z": -3,
      "name": "Empty"
    },
    {
      "x": 0,
      "y": 3,
      "z": -3,
      "name": "Empty"
    },
    {
      "x": 0,
      "y": 4,
      "z": -3,
      "name": "Empty"
    },
    {
      "x": 0,
      "y": 5,
      "z": -3,
      "name": "Wood_Darkwood_Planks_Half",
      "rotation": 4
    },
    {
      "x": 0,
      "y": 6,
      "z": -3,
      "name": "Wood_Darkwood_Planks"
    },
    {
      "x": 0,
      "y": 0,
      "z": -2,
      "name": "Rock_Basalt_Cobble"
    },
    {
      "x": 0,
      "y": 1,
      "z": -2,
      "name": "Wood_Darkwood_Planks"
    },
    {
      "x": 0,
      "y": 2,
      "z": -2,
      "name": "Empty"
    },
    {
      "x": 0,
      "y": 3,
      "z": -2,
      "name": "Empty"
    },
    {
      "x": 0,
      "y": 4,
      "z": -2,
      "name": "Empty"
    },
    {
      "x": 0,
      "y": 5,
      "z": -2,
      "name": "Empty"
    },
    {
      "x": 0,
      "y": 6,
      "z": -2,
      "name": "Wood_Darkwood_Planks"
    },
    {
      "x": 0,
      "y": 0,
      "z": -1,
      "name": "Rock_Basalt_Cobble"
    },
    {
      "x": 0,
      "y": 1,
      "z": -1,
      "name": "Wood_Darkwood_Planks"
    },
    {
      "x": 0,
      "y": 2,
      "z": -1,
      "name": "Empty"
    },
    {
      "x": 0,
      "y": 3,
      "z": -1,
      "name": "Empty"
    },
    {
      "x": 0,
      "y": 4,
      "z": -1,
      "name": "Empty"
    },
    {
      "x": 0,
      "y": 5,
      "z": -1,
      "name": "Empty"
    },
    {
      "x": 0,
      "y": 6,
      "z": -1,
      "name": "Wood_Darkwood_Planks"
    },
    {
      "x": 0,
      "y": 0,
      "z": 0,
      "name": "Rock_Basalt_Cobble"
    },
    {
      "x": 0,
      "y": 1,
      "z": 0,
      "name": "Wood_Darkwood_Planks"
    },
    {
      "x": 0,
      "y": 2,
      "z": 0,
      "name": "Empty"
    },
    {
      "x": 0,
      "y": 3,
      "z": 0,
      "name": "Empty"
    },
    {
      "x": 0,
      "y": 4,
      "z": 0,
      "name": "Empty"
    },
    {
      "x": 0,
      "y": 5,
      "z": 0,
      "name": "Empty"
    },
    {
      "x": 0,
      "y": 6,
      "z": 0,
      "name": "Wood_Darkwood_Planks"
    },
    {
      "x": 0,
      "y": 0,
      "z": 1,
      "name": "Rock_Basalt_Cobble"
    },
    {
      "x": 0,
      "y": 1,
      "z": 1,
      "name": "Wood_Darkwood_Planks"
    },
    {
      "x": 0,
      "y": 2,
      "z": 1,
      "name": "Block_Spawner_Block",
      "components": {
        "Components": {
          "BlockSpawner": {
            "BlockSpawnerId": "Zone3_Encounters_Tier3"
          }
        }
      },
      "rotation": 1
    },
    {
      "x": 0,
      "y": 3,
      "z": 1,
      "name": "Empty"
    },
    {
      "x": 0,
      "y": 4,
      "z": 1,
      "name": "Empty"
    },
    {
      "x": 0,
      "y": 5,
      "z": 1,
      "name": "Wood_Darkwood_Planks_Half",
      "rotation": 5
    },
    {
      "x": 0,
      "y": 6,
      "z": 1,
      "name": "Wood_Darkwood_Planks"
    },
    {
      "x": 0,
      "y": 0,
      "z": 2,
      "name": "Rock_Basalt_Cobble"
    },
    {
      "x": 0,
      "y": 1,
      "z": 2,
      "name": "Wood_Darkwood_Planks"
    },
    {
      "x": 0,
      "y": 2,
      "z": 2,
      "name": "Furniture_Tavern_Planter"
    },
    {
      "x": 0,
      "y": 3,
      "z": 2,
      "name": "Plant_Bush_Winter_Red"
    },
    {
      "x": 0,
      "y": 4,
      "z": 2,
      "name": "Plant_Bush_Winter_Red"
    },
    {
      "x": 0,
      "y": 5,
      "z": 2,
      "name": "Wood_Darkwood_Planks"
    },
    {
      "x": 0,
      "y": 6,
      "z": 2,
      "name": "Wood_Darkwood_Planks"
    },
    {
      "x": 0,
      "y": 0,
      "z": 3,
      "name": "Rock_Basalt_Cobble"
    },
    {
      "x": 0,
      "y": 1,
      "z": 3,
      "name": "Wood_Darkwood_Planks"
    },
    {
      "x": 0,
      "y": 2,
      "z": 3,
      "name": "Rock_Basalt_Brick_Smooth"
    },
    {
      "x": 0,
      "y": 3,
      "z": 3,
      "name": "Rock_Basalt_Cobble"
    },
    {
      "x": 0,
      "y": 4,
      "z": 3,
      "name": "Rock_Basalt_Cobble"
    },
    {
      "x": 0,
      "y": 5,
      "z": 3,
      "name": "Rock_Basalt_Cobble"
    },
    {
      "x": 0,
      "y": 6,
      "z": 3,
      "name": "Wood_Darkwood_Planks"
    },
    {
      "x": 0,
      "y": 0,
      "z": 4,
      "name": "Rock_Basalt_Cobble"
    },
    {
      "x": 0,
      "y": 1,
      "z": 4,
      "name": "Wood_Darkwood_Planks"
    },
    {
      "x": 0,
      "y": 2,
      "z": 4,
      "name": "Empty"
    },
    {
      "x": 0,
      "y": 3,
      "z": 4,
      "name": "Furniture_Lumberjack_Shelf"
    },
    {
      "x": 0,
      "y": 4,
      "z": 4,
      "name": "Deco_Mug"
    },
    {
      "x": 0,
      "y": 5,
      "z": 4,
      "name": "Wood_Darkwood_Planks_Half",
      "rotation": 4
    },
    {
      "x": 0,
      "y": 6,
      "z": 4,
      "name": "Wood_Darkwood_Planks"
    },
    {
      "x": 0,
      "y": 0,
      "z": 5,
      "name": "Rock_Basalt_Cobble"
    },
    {
      "x": 0,
      "y": 1,
      "z": 5,
      "name": "Wood_Darkwood_Planks"
    },
    {
      "x": 0,
      "y": 2,
      "z": 5,
      "name": "Empty"
    },
    {
      "x": 0,
      "y": 3,
      "z": 5,
      "name": "Empty"
    },
    {
      "x": 0,
      "y": 4,
      "z": 5,
      "name": "Empty"
    },
    {
      "x": 0,
      "y": 5,
      "z": 5,
      "name": "Empty"
    },
    {
      "x": 0,
      "y": 6,
      "z": 5,
      "name": "Wood_Darkwood_Planks"
    },
    {
      "x": 0,
      "y": 0,
      "z": 6,
      "name": "Rock_Basalt_Cobble"
    },
    {
      "x": 0,
      "y": 1,
      "z": 6,
      "name": "Wood_Darkwood_Planks"
    },
    {
      "x": 0,
      "y": 2,
      "z": 6,
      "name": "Empty"
    },
    {
      "x": 0,
      "y": 3,
      "z": 6,
      "name": "Empty"
    },
    {
      "x": 0,
      "y": 4,
      "z": 6,
      "name": "Empty"
    },
    {
      "x": 0,
      "y": 5,
      "z": 6,
      "name": "Wood_Darkwood_Planks_Half",
      "rotation": 6
    },
    {
      "x": 0,
      "y": 6,
      "z": 6,
      "name": "Wood_Darkwood_Planks"
    },
    {
      "x": 0,
      "y": 0,
      "z": 7,
      "name": "Rock_Basalt_Cobble"
    },
    {
      "x": 0,
      "y": 1,
      "z": 7,
      "name": "Wood_Darkwood_Planks"
    },
    {
      "x": 0,
      "y": 2,
      "z": 7,
      "name": "Empty"
    },
    {
      "x": 0,
      "y": 3,
      "z": 7,
      "name": "Empty"
    },
    {
      "x": 0,
      "y": 4,
      "z": 7,
      "name": "Empty"
    },
    {
      "x": 0,
      "y": 5,
      "z": 7,
      "name": "Rock_Basalt_Cobble"
    },
    {
      "x": 0,
      "y": 6,
      "z": 7,
      "name": "Rock_Basalt_Cobble"
    },
    {
      "x": 1,
      "y": 0,
      "z": -6,
      "name": "Rock_Basalt_Cobble"
    },
    {
      "x": 1,
      "y": 1,
      "z": -6,
      "name": "Rock_Basalt_Cobble"
    },
    {
      "x": 1,
      "y": 2,
      "z": -6,
      "name": "Rock_Basalt_Brick_Smooth"
    },
    {
      "x": 1,
      "y": 3,
      "z": -6,
      "name": "Rock_Basalt_Cobble"
    },
    {
      "x": 1,
      "y": 4,
      "z": -6,
      "name": "Rock_Basalt_Cobble"
    },
    {
      "x": 1,
      "y": 5,
      "z": -6,
      "name": "Rock_Basalt_Cobble"
    },
    {
      "x": 1,
      "y": 6,
      "z": -6,
      "name": "Rock_Basalt_Cobble"
    },
    {
      "x": 1,
      "y": 0,
      "z": -5,
      "name": "Rock_Basalt_Cobble"
    },
    {
      "x": 1,
      "y": 1,
      "z": -5,
      "name": "Wood_Darkwood_Planks"
    },
    {
      "x": 1,
      "y": 2,
      "z": -5,
      "name": "Furniture_Ancient_Barrel"
    },
    {
      "x": 1,
      "y": 3,
      "z": -5,
      "name": "Furniture_Ancient_Barrel"
    },
    {
      "x": 1,
      "y": 4,
      "z": -5,
      "name": "Empty"
    },
    {
      "x": 1,
      "y": 5,
      "z": -5,
      "name": "Wood_Darkwood_Planks"
    },
    {
      "x": 1,
      "y": 6,
      "z": -5,
      "name": "Wood_Darkwood_Planks"
    },
    {
      "x": 1,
      "y": 0,
      "z": -4,
      "name": "Rock_Basalt_Cobble"
    },
    {
      "x": 1,
      "y": 1,
      "z": -4,
      "name": "Wood_Darkwood_Planks"
    },
    {
      "x": 1,
      "y": 2,
      "z": -4,
      "name": "Furniture_Ancient_Barrel"
    },
    {
      "x": 1,
      "y": 3,
      "z": -4,
      "name": "Empty"
    },
    {
      "x": 1,
      "y": 4,
      "z": -4,
      "name": "Empty"
    },
    {
      "x": 1,
      "y": 5,
      "z": -4,
      "name": "Wood_Darkwood_Planks_Half",
      "rotation": 5
    },
    {
      "x": 1,
      "y": 6,
      "z": -4,
      "name": "Wood_Darkwood_Planks"
    },
    {
      "x": 1,
      "y": 0,
      "z": -3,
      "name": "Rock_Basalt_Cobble"
    },
    {
      "x": 1,
      "y": 1,
      "z": -3,
      "name": "Wood_Darkwood_Planks"
    },
    {
      "x": 1,
      "y": 2,
      "z": -3,
      "name": "Empty"
    },
    {
      "x": 1,
      "y": 3,
      "z": -3,
      "name": "Empty"
    },
    {
      "x": 1,
      "y": 4,
      "z": -3,
      "name": "Empty"
    },
    {
      "x": 1,
      "y": 5,
      "z": -3,
      "name": "Empty"
    },
    {
      "x": 1,
      "y": 6,
      "z": -3,
      "name": "Wood_Darkwood_Planks"
    },
    {
      "x": 1,
      "y": 0,
      "z": -2,
      "name": "Rock_Basalt_Cobble"
    },
    {
      "x": 1,
      "y": 1,
      "z": -2,
      "name": "Wood_Darkwood_Planks"
    },
    {
      "x": 1,
      "y": 2,
      "z": -2,
      "name": "Empty"
    },
    {
      "x": 1,
      "y": 3,
      "z": -2,
      "name": "Empty"
    },
    {
      "x": 1,
      "y": 4,
      "z": -2,
      "name": "Empty"
    },
    {
      "x": 1,
      "y": 5,
      "z": -2,
      "name": "Empty"
    },
    {
      "x": 1,
      "y": 6,
      "z": -2,
      "name": "Wood_Darkwood_Planks"
    },
    {
      "x": 1,
      "y": 0,
      "z": -1,
      "name": "Rock_Basalt_Cobble"
    },
    {
      "x": 1,
      "y": 1,
      "z": -1,
      "name": "Wood_Darkwood_Planks"
    },
    {
      "x": 1,
      "y": 2,
      "z": -1,
      "name": "Empty"
    },
    {
      "x": 1,
      "y": 3,
      "z": -1,
      "name": "Empty"
    },
    {
      "x": 1,
      "y": 4,
      "z": -1,
      "name": "Empty"
    },
    {
      "x": 1,
      "y": 5,
      "z": -1,
      "name": "Empty"
    },
    {
      "x": 1,
      "y": 6,
      "z": -1,
      "name": "Wood_Darkwood_Planks"
    },
    {
      "x": 1,
      "y": 0,
      "z": 0,
      "name": "Rock_Basalt_Cobble"
    },
    {
      "x": 1,
      "y": 1,
      "z": 0,
      "name": "Wood_Darkwood_Planks"
    },
    {
      "x": 1,
      "y": 2,
      "z": 0,
      "name": "Empty"
    },
    {
      "x": 1,
      "y": 3,
      "z": 0,
      "name": "Empty"
    },
    {
      "x": 1,
      "y": 4,
      "z": 0,
      "name": "Empty"
    },
    {
      "x": 1,
      "y": 5,
      "z": 0,
      "name": "Empty"
    },
    {
      "x": 1,
      "y": 6,
      "z": 0,
      "name": "Wood_Darkwood_Planks"
    },
    {
      "x": 1,
      "y": 0,
      "z": 1,
      "name": "Rock_Basalt_Cobble"
    },
    {
      "x": 1,
      "y": 1,
      "z": 1,
      "name": "Wood_Darkwood_Planks"
    },
    {
      "x": 1,
      "y": 2,
      "z": 1,
      "name": "Empty"
    },
    {
      "x": 1,
      "y": 3,
      "z": 1,
      "name": "Empty"
    },
    {
      "x": 1,
      "y": 4,
      "z": 1,
      "name": "Empty"
    },
    {
      "x": 1,
      "y": 5,
      "z": 1,
      "name": "Empty"
    },
    {
      "x": 1,
      "y": 6,
      "z": 1,
      "name": "Wood_Darkwood_Planks"
    },
    {
      "x": 1,
      "y": 0,
      "z": 2,
      "name": "Rock_Basalt_Cobble"
    },
    {
      "x": 1,
      "y": 1,
      "z": 2,
      "name": "Wood_Darkwood_Planks"
    },
    {
      "x": 1,
      "y": 2,
      "z": 2,
      "name": "Furniture_Village_Bookcase",
      "rotation": 2
    },
    {
      "x": 1,
      "y": 3,
      "z": 2,
      "name": "Furniture_Village_Bookcase",
      "rotation": 2
    },
    {
      "x": 1,
      "y": 4,
      "z": 2,
      "name": "Furniture_Village_Bookcase",
      "rotation": 2
    },
    {
      "x": 1,
      "y": 5,
      "z": 2,
      "name": "Wood_Darkwood_Planks_Half",
      "rotation": 6
    },
    {
      "x": 1,
      "y": 6,
      "z": 2,
      "name": "Wood_Darkwood_Planks"
    },
    {
      "x": 1,
      "y": 0,
      "z": 3,
      "name": "Rock_Basalt_Cobble"
    },
    {
      "x": 1,
      "y": 1,
      "z": 3,
      "name": "Wood_Darkwood_Planks"
    },
    {
      "x": 1,
      "y": 2,
      "z": 3,
      "name": "Rock_Basalt_Brick_Smooth"
    },
    {
      "x": 1,
      "y": 3,
      "z": 3,
      "name": "Rock_Basalt_Cobble"
    },
    {
      "x": 1,
      "y": 4,
      "z": 3,
      "name": "Rock_Basalt_Cobble"
    },
    {
      "x": 1,
      "y": 5,
      "z": 3,
      "name": "Rock_Basalt_Cobble"
    },
    {
      "x": 1,
      "y": 6,
      "z": 3,
      "name": "Wood_Darkwood_Planks"
    },
    {
      "x": 1,
      "y": 0,
      "z": 4,
      "name": "Rock_Basalt_Cobble"
    },
    {
      "x": 1,
      "y": 1,
      "z": 4,
      "name": "Wood_Darkwood_Planks"
    },
    {
      "x": 1,
      "y": 2,
      "z": 4,
      "name": "Furniture_Village_Counter",
      "filler": 31
    },
    {
      "x": 1,
      "y": 3,
      "z": 4,
      "name": "Furniture_Lumberjack_Shelf"
    },
    {
      "x": 1,
      "y": 4,
      "z": 4,
      "name": "Rock_Crystal_Pink_Small"
    },
    {
      "x": 1,
      "y": 5,
      "z": 4,
      "name": "Wood_Darkwood_Planks_Half",
      "rotation": 4
    },
    {
      "x": 1,
      "y": 6,
      "z": 4,
      "name": "Wood_Darkwood_Planks"
    },
    {
      "x": 1,
      "y": 0,
      "z": 5,
      "name": "Rock_Basalt_Cobble"
    },
    {
      "x": 1,
      "y": 1,
      "z": 5,
      "name": "Wood_Darkwood_Planks"
    },
    {
      "x": 1,
      "y": 2,
      "z": 5,
      "name": "Empty"
    },
    {
      "x": 1,
      "y": 3,
      "z": 5,
      "name": "Empty"
    },
    {
      "x": 1,
      "y": 4,
      "z": 5,
      "name": "Empty"
    },
    {
      "x": 1,
      "y": 5,
      "z": 5,
      "name": "Empty"
    },
    {
      "x": 1,
      "y": 6,
      "z": 5,
      "name": "Wood_Darkwood_Planks"
    },
    {
      "x": 1,
      "y": 0,
      "z": 6,
      "name": "Rock_Basalt_Cobble"
    },
    {
      "x": 1,
      "y": 1,
      "z": 6,
      "name": "Wood_Darkwood_Planks"
    },
    {
      "x": 1,
      "y": 2,
      "z": 6,
      "name": "Empty"
    },
    {
      "x": 1,
      "y": 3,
      "z": 6,
      "name": "Empty"
    },
    {
      "x": 1,
      "y": 4,
      "z": 6,
      "name": "Empty"
    },
    {
      "x": 1,
      "y": 5,
      "z": 6,
      "name": "Wood_Darkwood_Planks_Half",
      "rotation": 6
    },
    {
      "x": 1,
      "y": 6,
      "z": 6,
      "name": "Wood_Darkwood_Planks"
    },
    {
      "x": 1,
      "y": 0,
      "z": 7,
      "name": "Rock_Basalt_Cobble"
    },
    {
      "x": 1,
      "y": 1,
      "z": 7,
      "name": "Wood_Darkwood_Planks"
    },
    {
      "x": 1,
      "y": 2,
      "z": 7,
      "name": "Empty"
    },
    {
      "x": 1,
      "y": 3,
      "z": 7,
      "name": "Empty"
    },
    {
      "x": 1,
      "y": 4,
      "z": 7,
      "name": "Empty"
    },
    {
      "x": 1,
      "y": 5,
      "z": 7,
      "name": "Rock_Basalt_Cobble"
    },
    {
      "x": 1,
      "y": 6,
      "z": 7,
      "name": "Rock_Basalt_Cobble"
    },
    {
      "x": 2,
      "y": 0,
      "z": -6,
      "name": "Rock_Basalt_Cobble"
    },
    {
      "x": 2,
      "y": 1,
      "z": -6,
      "name": "Rock_Basalt_Cobble"
    },
    {
      "x": 2,
      "y": 2,
      "z": -6,
      "name": "Rock_Basalt_Brick_Smooth"
    },
    {
      "x": 2,
      "y": 3,
      "z": -6,
      "name": "Rock_Basalt_Cobble"
    },
    {
      "x": 2,
      "y": 4,
      "z": -6,
      "name": "Rock_Basalt_Cobble"
    },
    {
      "x": 2,
      "y": 5,
      "z": -6,
      "name": "Rock_Basalt_Cobble"
    },
    {
      "x": 2,
      "y": 6,
      "z": -6,
      "name": "Rock_Basalt_Cobble"
    },
    {
      "x": 2,
      "y": 0,
      "z": -5,
      "name": "Rock_Basalt_Cobble"
    },
    {
      "x": 2,
      "y": 1,
      "z": -5,
      "name": "Wood_Darkwood_Planks"
    },
    {
      "x": 2,
      "y": 2,
      "z": -5,
      "name": "Furniture_Village_Bookcase"
    },
    {
      "x": 2,
      "y": 3,
      "z": -5,
      "name": "Furniture_Village_Bookcase"
    },
    {
      "x": 2,
      "y": 4,
      "z": -5,
      "name": "Furniture_Village_Bookcase"
    },
    {
      "x": 2,
      "y": 5,
      "z": -5,
      "name": "Wood_Darkwood_Planks_Half",
      "rotation": 4
    },
    {
      "x": 2,
      "y": 6,
      "z": -5,
      "name": "Wood_Darkwood_Planks"
    },
    {
      "x": 2,
      "y": 0,
      "z": -4,
      "name": "Rock_Basalt_Cobble"
    },
    {
      "x": 2,
      "y": 1,
      "z": -4,
      "name": "Wood_Darkwood_Planks"
    },
    {
      "x": 2,
      "y": 2,
      "z": -4,
      "name": "Furniture_Village_Bed",
      "components": {
        "Components": {
          "RespawnBlock": {}
        }
      },
      "filler": 30,
      "rotation": 3
    },
    {
      "x": 2,
      "y": 3,
      "z": -4,
      "name": "Furniture_Village_Bed",
      "components": {
        "Components": {
          "RespawnBlock": {}
        }
      },
      "filler": 1054,
      "rotation": 3
    },
    {
      "x": 2,
      "y": 4,
      "z": -4,
      "name": "Empty"
    },
    {
      "x": 2,
      "y": 5,
      "z": -4,
      "name": "Empty"
    },
    {
      "x": 2,
      "y": 6,
      "z": -4,
      "name": "Wood_Darkwood_Planks"
    },
    {
      "x": 2,
      "y": 0,
      "z": -3,
      "name": "Rock_Basalt_Cobble"
    },
    {
      "x": 2,
      "y": 1,
      "z": -3,
      "name": "Wood_Darkwood_Planks"
    },
    {
      "x": 2,
      "y": 2,
      "z": -3,
      "name": "Furniture_Village_Bed",
      "components": {
        "Components": {
          "RespawnBlock": {}
        }
      },
      "filler": 62,
      "rotation": 3
    },
    {
      "x": 2,
      "y": 3,
      "z": -3,
      "name": "Furniture_Village_Bed",
      "components": {
        "Components": {
          "RespawnBlock": {}
        }
      },
      "filler": 1086,
      "rotation": 3
    },
    {
      "x": 2,
      "y": 4,
      "z": -3,
      "name": "Empty"
    },
    {
      "x": 2,
      "y": 5,
      "z": -3,
      "name": "Empty"
    },
    {
      "x": 2,
      "y": 6,
      "z": -3,
      "name": "Wood_Darkwood_Planks"
    },
    {
      "x": 2,
      "y": 0,
      "z": -2,
      "name": "Rock_Basalt_Cobble"
    },
    {
      "x": 2,
      "y": 1,
      "z": -2,
      "name": "Wood_Darkwood_Planks"
    },
    {
      "x": 2,
      "y": 2,
      "z": -2,
      "name": "Empty"
    },
    {
      "x": 2,
      "y": 3,
      "z": -2,
      "name": "Empty"
    },
    {
      "x": 2,
      "y": 4,
      "z": -2,
      "name": "Empty"
    },
    {
      "x": 2,
      "y": 5,
      "z": -2,
      "name": "Empty"
    },
    {
      "x": 2,
      "y": 6,
      "z": -2,
      "name": "Wood_Darkwood_Planks"
    },
    {
      "x": 2,
      "y": 0,
      "z": -1,
      "name": "Rock_Basalt_Cobble"
    },
    {
      "x": 2,
      "y": 1,
      "z": -1,
      "name": "Wood_Darkwood_Planks"
    },
    {
      "x": 2,
      "y": 2,
      "z": -1,
      "name": "Empty"
    },
    {
      "x": 2,
      "y": 3,
      "z": -1,
      "name": "Empty"
    },
    {
      "x": 2,
      "y": 4,
      "z": -1,
      "name": "Empty"
    },
    {
      "x": 2,
      "y": 5,
      "z": -1,
      "name": "Empty"
    },
    {
      "x": 2,
      "y": 6,
      "z": -1,
      "name": "Wood_Darkwood_Planks"
    },
    {
      "x": 2,
      "y": 0,
      "z": 0,
      "name": "Rock_Basalt_Cobble"
    },
    {
      "x": 2,
      "y": 1,
      "z": 0,
      "name": "Wood_Darkwood_Planks"
    },
    {
      "x": 2,
      "y": 2,
      "z": 0,
      "name": "Furniture_Village_Bed",
      "components": {
        "Components": {
          "RespawnBlock": {}
        }
      },
      "filler": 30,
      "rotation": 3
    },
    {
      "x": 2,
      "y": 3,
      "z": 0,
      "name": "Furniture_Village_Bed",
      "components": {
        "Components": {
          "RespawnBlock": {}
        }
      },
      "filler": 1054,
      "rotation": 3
    },
    {
      "x": 2,
      "y": 4,
      "z": 0,
      "name": "Empty"
    },
    {
      "x": 2,
      "y": 5,
      "z": 0,
      "name": "Empty"
    },
    {
      "x": 2,
      "y": 6,
      "z": 0,
      "name": "Wood_Darkwood_Planks"
    },
    {
      "x": 2,
      "y": 0,
      "z": 1,
      "name": "Rock_Basalt_Cobble"
    },
    {
      "x": 2,
      "y": 1,
      "z": 1,
      "name": "Wood_Darkwood_Planks"
    },
    {
      "x": 2,
      "y": 2,
      "z": 1,
      "name": "Furniture_Village_Bed",
      "components": {
        "Components": {
          "RespawnBlock": {}
        }
      },
      "filler": 62,
      "rotation": 3
    },
    {
      "x": 2,
      "y": 3,
      "z": 1,
      "name": "Furniture_Village_Bed",
      "components": {
        "Components": {
          "RespawnBlock": {}
        }
      },
      "filler": 1086,
      "rotation": 3
    },
    {
      "x": 2,
      "y": 4,
      "z": 1,
      "name": "Empty"
    },
    {
      "x": 2,
      "y": 5,
      "z": 1,
      "name": "Empty"
    },
    {
      "x": 2,
      "y": 6,
      "z": 1,
      "name": "Wood_Darkwood_Planks"
    },
    {
      "x": 2,
      "y": 0,
      "z": 2,
      "name": "Rock_Basalt_Cobble"
    },
    {
      "x": 2,
      "y": 1,
      "z": 2,
      "name": "Wood_Darkwood_Planks"
    },
    {
      "x": 2,
      "y": 2,
      "z": 2,
      "name": "Furniture_Village_Bookcase",
      "rotation": 2
    },
    {
      "x": 2,
      "y": 3,
      "z": 2,
      "name": "Furniture_Village_Bookcase",
      "rotation": 2
    },
    {
      "x": 2,
      "y": 4,
      "z": 2,
      "name": "Furniture_Village_Bookcase",
      "rotation": 2
    },
    {
      "x": 2,
      "y": 5,
      "z": 2,
      "name": "Wood_Darkwood_Planks_Half",
      "rotation": 6
    },
    {
      "x": 2,
      "y": 6,
      "z": 2,
      "name": "Wood_Darkwood_Planks"
    },
    {
      "x": 2,
      "y": 0,
      "z": 3,
      "name": "Rock_Basalt_Cobble"
    },
    {
      "x": 2,
      "y": 1,
      "z": 3,
      "name": "Wood_Darkwood_Planks"
    },
    {
      "x": 2,
      "y": 2,
      "z": 3,
      "name": "Rock_Basalt_Brick_Smooth"
    },
    {
      "x": 2,
      "y": 3,
      "z": 3,
      "name": "Rock_Basalt_Cobble"
    },
    {
      "x": 2,
      "y": 4,
      "z": 3,
      "name": "Rock_Basalt_Cobble"
    },
    {
      "x": 2,
      "y": 5,
      "z": 3,
      "name": "Rock_Basalt_Cobble"
    },
    {
      "x": 2,
      "y": 6,
      "z": 3,
      "name": "Wood_Darkwood_Planks"
    },
    {
      "x": 2,
      "y": 0,
      "z": 4,
      "name": "Rock_Basalt_Cobble"
    },
    {
      "x": 2,
      "y": 1,
      "z": 4,
      "name": "Wood_Darkwood_Planks"
    },
    {
      "x": 2,
      "y": 2,
      "z": 4,
      "name": "Furniture_Village_Counter"
    },
    {
      "x": 2,
      "y": 3,
      "z": 4,
      "name": "Deco_Iron_Stack"
    },
    {
      "x": 2,
      "y": 4,
      "z": 4,
      "name": "Deco_Iron_Stack"
    },
    {
      "x": 2,
      "y": 5,
      "z": 4,
      "name": "Wood_Darkwood_Planks_Half",
      "rotation": 4
    },
    {
      "x": 2,
      "y": 6,
      "z": 4,
      "name": "Wood_Darkwood_Planks"
    },
    {
      "x": 2,
      "y": 0,
      "z": 5,
      "name": "Rock_Basalt_Cobble"
    },
    {
      "x": 2,
      "y": 1,
      "z": 5,
      "name": "Wood_Darkwood_Planks"
    },
    {
      "x": 2,
      "y": 2,
      "z": 5,
      "name": "Empty"
    },
    {
      "x": 2,
      "y": 3,
      "z": 5,
      "name": "Empty"
    },
    {
      "x": 2,
      "y": 4,
      "z": 5,
      "name": "Empty"
    },
    {
      "x": 2,
      "y": 5,
      "z": 5,
      "name": "Empty"
    },
    {
      "x": 2,
      "y": 6,
      "z": 5,
      "name": "Wood_Darkwood_Planks"
    },
    {
      "x": 2,
      "y": 0,
      "z": 6,
      "name": "Rock_Basalt_Cobble"
    },
    {
      "x": 2,
      "y": 1,
      "z": 6,
      "name": "Wood_Darkwood_Planks"
    },
    {
      "x": 2,
      "y": 2,
      "z": 6,
      "name": "Empty"
    },
    {
      "x": 2,
      "y": 3,
      "z": 6,
      "name": "Empty"
    },
    {
      "x": 2,
      "y": 4,
      "z": 6,
      "name": "Empty"
    },
    {
      "x": 2,
      "y": 5,
      "z": 6,
      "name": "Wood_Darkwood_Planks_Half",
      "rotation": 6
    },
    {
      "x": 2,
      "y": 6,
      "z": 6,
      "name": "Wood_Darkwood_Planks"
    },
    {
      "x": 2,
      "y": 0,
      "z": 7,
      "name": "Rock_Basalt_Cobble"
    },
    {
      "x": 2,
      "y": 1,
      "z": 7,
      "name": "Wood_Darkwood_Planks"
    },
    {
      "x": 2,
      "y": 2,
      "z": 7,
      "name": "Rock_Basalt_Brick_Smooth"
    },
    {
      "x": 2,
      "y": 3,
      "z": 7,
      "name": "Rock_Basalt_Cobble"
    },
    {
      "x": 2,
      "y": 4,
      "z": 7,
      "name": "Rock_Basalt_Cobble"
    },
    {
      "x": 2,
      "y": 5,
      "z": 7,
      "name": "Rock_Basalt_Cobble"
    },
    {
      "x": 2,
      "y": 6,
      "z": 7,
      "name": "Rock_Basalt_Cobble"
    },
    {
      "x": 3,
      "y": 0,
      "z": -6,
      "name": "Rock_Basalt_Cobble"
    },
    {
      "x": 3,
      "y": 1,
      "z": -6,
      "name": "Rock_Basalt_Cobble"
    },
    {
      "x": 3,
      "y": 2,
      "z": -6,
      "name": "Rock_Basalt_Brick_Smooth"
    },
    {
      "x": 3,
      "y": 3,
      "z": -6,
      "name": "Rock_Basalt_Cobble"
    },
    {
      "x": 3,
      "y": 4,
      "z": -6,
      "name": "Rock_Basalt_Cobble"
    },
    {
      "x": 3,
      "y": 5,
      "z": -6,
      "name": "Rock_Basalt_Cobble"
    },
    {
      "x": 3,
      "y": 6,
      "z": -6,
      "name": "Rock_Basalt_Cobble"
    },
    {
      "x": 3,
      "y": 0,
      "z": -5,
      "name": "Rock_Basalt_Cobble"
    },
    {
      "x": 3,
      "y": 1,
      "z": -5,
      "name": "Wood_Darkwood_Planks"
    },
    {
      "x": 3,
      "y": 2,
      "z": -5,
      "name": "Furniture_Village_Bookcase"
    },
    {
      "x": 3,
      "y": 3,
      "z": -5,
      "name": "Furniture_Village_Bookcase"
    },
    {
      "x": 3,
      "y": 4,
      "z": -5,
      "name": "Furniture_Village_Bookcase"
    },
    {
      "x": 3,
      "y": 5,
      "z": -5,
      "name": "Wood_Darkwood_Planks_Half",
      "rotation": 4
    },
    {
      "x": 3,
      "y": 6,
      "z": -5,
      "name": "Wood_Darkwood_Planks"
    },
    {
      "x": 3,
      "y": 0,
      "z": -4,
      "name": "Rock_Basalt_Cobble"
    },
    {
      "x": 3,
      "y": 1,
      "z": -4,
      "name": "Wood_Darkwood_Planks"
    },
    {
      "x": 3,
      "y": 2,
      "z": -4,
      "name": "Furniture_Village_Bed",
      "components": {
        "Components": {
          "RespawnBlock": {}
        }
      },
      "filler": 31,
      "rotation": 3
    },
    {
      "x": 3,
      "y": 3,
      "z": -4,
      "name": "Furniture_Village_Bed",
      "components": {
        "Components": {
          "RespawnBlock": {}
        }
      },
      "filler": 1055,
      "rotation": 3
    },
    {
      "x": 3,
      "y": 4,
      "z": -4,
      "name": "Empty"
    },
    {
      "x": 3,
      "y": 5,
      "z": -4,
      "name": "Empty"
    },
    {
      "x": 3,
      "y": 6,
      "z": -4,
      "name": "Wood_Darkwood_Planks"
    },
    {
      "x": 3,
      "y": 0,
      "z": -3,
      "name": "Rock_Basalt_Cobble"
    },
    {
      "x": 3,
      "y": 1,
      "z": -3,
      "name": "Wood_Darkwood_Planks"
    },
    {
      "x": 3,
      "y": 2,
      "z": -3,
      "name": "Furniture_Village_Bed",
      "components": {
        "Components": {
          "RespawnBlock": {}
        }
      },
      "filler": 63,
      "rotation": 3
    },
    {
      "x": 3,
      "y": 3,
      "z": -3,
      "name": "Furniture_Village_Bed",
      "components": {
        "Components": {
          "RespawnBlock": {}
        }
      },
      "filler": 1087,
      "rotation": 3
    },
    {
      "x": 3,
      "y": 4,
      "z": -3,
      "name": "Empty"
    },
    {
      "x": 3,
      "y": 5,
      "z": -3,
      "name": "Empty"
    },
    {
      "x": 3,
      "y": 6,
      "z": -3,
      "name": "Wood_Darkwood_Planks"
    },
    {
      "x": 3,
      "y": 0,
      "z": -2,
      "name": "Rock_Basalt_Cobble"
    },
    {
      "x": 3,
      "y": 1,
      "z": -2,
      "name": "Wood_Darkwood_Planks"
    },
    {
      "x": 3,
      "y": 2,
      "z": -2,
      "name": "Empty"
    },
    {
      "x": 3,
      "y": 3,
      "z": -2,
      "name": "Empty"
    },
    {
      "x": 3,
      "y": 4,
      "z": -2,
      "name": "Empty"
    },
    {
      "x": 3,
      "y": 5,
      "z": -2,
      "name": "Empty"
    },
    {
      "x": 3,
      "y": 6,
      "z": -2,
      "name": "Wood_Darkwood_Planks"
    },
    {
      "x": 3,
      "y": 0,
      "z": -1,
      "name": "Rock_Basalt_Cobble"
    },
    {
      "x": 3,
      "y": 1,
      "z": -1,
      "name": "Wood_Darkwood_Planks"
    },
    {
      "x": 3,
      "y": 2,
      "z": -1,
      "name": "Empty"
    },
    {
      "x": 3,
      "y": 3,
      "z": -1,
      "name": "Empty"
    },
    {
      "x": 3,
      "y": 4,
      "z": -1,
      "name": "Empty"
    },
    {
      "x": 3,
      "y": 5,
      "z": -1,
      "name": "Empty"
    },
    {
      "x": 3,
      "y": 6,
      "z": -1,
      "name": "Wood_Darkwood_Planks"
    },
    {
      "x": 3,
      "y": 0,
      "z": 0,
      "name": "Rock_Basalt_Cobble"
    },
    {
      "x": 3,
      "y": 1,
      "z": 0,
      "name": "Wood_Darkwood_Planks"
    },
    {
      "x": 3,
      "y": 2,
      "z": 0,
      "name": "Furniture_Village_Bed",
      "components": {
        "Components": {
          "RespawnBlock": {}
        }
      },
      "filler": 31,
      "rotation": 3
    },
    {
      "x": 3,
      "y": 3,
      "z": 0,
      "name": "Furniture_Village_Bed",
      "components": {
        "Components": {
          "RespawnBlock": {}
        }
      },
      "filler": 1055,
      "rotation": 3
    },
    {
      "x": 3,
      "y": 4,
      "z": 0,
      "name": "Empty"
    },
    {
      "x": 3,
      "y": 5,
      "z": 0,
      "name": "Empty"
    },
    {
      "x": 3,
      "y": 6,
      "z": 0,
      "name": "Wood_Darkwood_Planks"
    },
    {
      "x": 3,
      "y": 0,
      "z": 1,
      "name": "Rock_Basalt_Cobble"
    },
    {
      "x": 3,
      "y": 1,
      "z": 1,
      "name": "Wood_Darkwood_Planks"
    },
    {
      "x": 3,
      "y": 2,
      "z": 1,
      "name": "Furniture_Village_Bed",
      "components": {
        "Components": {
          "RespawnBlock": {}
        }
      },
      "filler": 63,
      "rotation": 3
    },
    {
      "x": 3,
      "y": 3,
      "z": 1,
      "name": "Furniture_Village_Bed",
      "components": {
        "Components": {
          "RespawnBlock": {}
        }
      },
      "filler": 1087,
      "rotation": 3
    },
    {
      "x": 3,
      "y": 4,
      "z": 1,
      "name": "Empty"
    },
    {
      "x": 3,
      "y": 5,
      "z": 1,
      "name": "Empty"
    },
    {
      "x": 3,
      "y": 6,
      "z": 1,
      "name": "Wood_Darkwood_Planks"
    },
    {
      "x": 3,
      "y": 0,
      "z": 2,
      "name": "Rock_Basalt_Cobble"
    },
    {
      "x": 3,
      "y": 1,
      "z": 2,
      "name": "Wood_Darkwood_Planks"
    },
    {
      "x": 3,
      "y": 2,
      "z": 2,
      "name": "Furniture_Village_Bookcase",
      "rotation": 2
    },
    {
      "x": 3,
      "y": 3,
      "z": 2,
      "name": "Furniture_Village_Bookcase",
      "rotation": 2
    },
    {
      "x": 3,
      "y": 4,
      "z": 2,
      "name": "Furniture_Village_Bookcase",
      "rotation": 2
    },
    {
      "x": 3,
      "y": 5,
      "z": 2,
      "name": "Wood_Darkwood_Planks_Half",
      "rotation": 6
    },
    {
      "x": 3,
      "y": 6,
      "z": 2,
      "name": "Wood_Darkwood_Planks"
    },
    {
      "x": 3,
      "y": 0,
      "z": 3,
      "name": "Rock_Basalt_Cobble"
    },
    {
      "x": 3,
      "y": 1,
      "z": 3,
      "name": "Wood_Darkwood_Planks"
    },
    {
      "x": 3,
      "y": 2,
      "z": 3,
      "name": "Rock_Basalt_Brick_Smooth"
    },
    {
      "x": 3,
      "y": 3,
      "z": 3,
      "name": "Rock_Basalt_Cobble"
    },
    {
      "x": 3,
      "y": 4,
      "z": 3,
      "name": "Rock_Basalt_Cobble"
    },
    {
      "x": 3,
      "y": 5,
      "z": 3,
      "name": "Rock_Basalt_Cobble"
    },
    {
      "x": 3,
      "y": 6,
      "z": 3,
      "name": "Wood_Darkwood_Planks"
    },
    {
      "x": 3,
      "y": 0,
      "z": 4,
      "name": "Rock_Basalt_Cobble"
    },
    {
      "x": 3,
      "y": 1,
      "z": 4,
      "name": "Wood_Darkwood_Planks"
    },
    {
      "x": 3,
      "y": 2,
      "z": 4,
      "name": "Empty"
    },
    {
      "x": 3,
      "y": 3,
      "z": 4,
      "name": "Empty"
    },
    {
      "x": 3,
      "y": 4,
      "z": 4,
      "name": "Empty"
    },
    {
      "x": 3,
      "y": 5,
      "z": 4,
      "name": "Wood_Darkwood_Planks_Half",
      "rotation": 4
    },
    {
      "x": 3,
      "y": 6,
      "z": 4,
      "name": "Wood_Darkwood_Planks"
    },
    {
      "x": 3,
      "y": 0,
      "z": 5,
      "name": "Rock_Basalt_Cobble"
    },
    {
      "x": 3,
      "y": 1,
      "z": 5,
      "name": "Wood_Darkwood_Planks"
    },
    {
      "x": 3,
      "y": 2,
      "z": 5,
      "name": "Empty"
    },
    {
      "x": 3,
      "y": 3,
      "z": 5,
      "name": "Empty"
    },
    {
      "x": 3,
      "y": 4,
      "z": 5,
      "name": "Empty"
    },
    {
      "x": 3,
      "y": 5,
      "z": 5,
      "name": "Empty"
    },
    {
      "x": 3,
      "y": 6,
      "z": 5,
      "name": "Wood_Darkwood_Planks"
    },
    {
      "x": 3,
      "y": 0,
      "z": 6,
      "name": "Rock_Basalt_Cobble"
    },
    {
      "x": 3,
      "y": 1,
      "z": 6,
      "name": "Wood_Darkwood_Planks"
    },
    {
      "x": 3,
      "y": 2,
      "z": 6,
      "name": "Empty"
    },
    {
      "x": 3,
      "y": 3,
      "z": 6,
      "name": "Empty"
    },
    {
      "x": 3,
      "y": 4,
      "z": 6,
      "name": "Empty"
    },
    {
      "x": 3,
      "y": 5,
      "z": 6,
      "name": "Wood_Darkwood_Planks_Half",
      "rotation": 6
    },
    {
      "x": 3,
      "y": 6,
      "z": 6,
      "name": "Wood_Darkwood_Planks"
    },
    {
      "x": 3,
      "y": 0,
      "z": 7,
      "name": "Rock_Basalt_Cobble"
    },
    {
      "x": 3,
      "y": 1,
      "z": 7,
      "name": "Rock_Basalt_Cobble"
    },
    {
      "x": 3,
      "y": 2,
      "z": 7,
      "name": "Rock_Basalt_Brick_Smooth"
    },
    {
      "x": 3,
      "y": 3,
      "z": 7,
      "name": "Rock_Basalt_Cobble"
    },
    {
      "x": 3,
      "y": 4,
      "z": 7,
      "name": "Rock_Basalt_Cobble"
    },
    {
      "x": 3,
      "y": 5,
      "z": 7,
      "name": "Rock_Basalt_Cobble"
    },
    {
      "x": 3,
      "y": 6,
      "z": 7,
      "name": "Rock_Basalt_Cobble"
    },
    {
      "x": 4,
      "y": 0,
      "z": -6,
      "name": "Rock_Basalt_Cobble"
    },
    {
      "x": 4,
      "y": 1,
      "z": -6,
      "name": "Rock_Basalt_Cobble"
    },
    {
      "x": 4,
      "y": 2,
      "z": -6,
      "name": "Rock_Basalt_Brick_Smooth"
    },
    {
      "x": 4,
      "y": 3,
      "z": -6,
      "name": "Rock_Basalt_Cobble"
    },
    {
      "x": 4,
      "y": 4,
      "z": -6,
      "name": "Rock_Basalt_Cobble"
    },
    {
      "x": 4,
      "y": 5,
      "z": -6,
      "name": "Rock_Basalt_Cobble"
    },
    {
      "x": 4,
      "y": 6,
      "z": -6,
      "name": "Rock_Basalt_Cobble"
    },
    {
      "x": 4,
      "y": 0,
      "z": -5,
      "name": "Rock_Basalt_Cobble"
    },
    {
      "x": 4,
      "y": 1,
      "z": -5,
      "name": "Wood_Darkwood_Planks"
    },
    {
      "x": 4,
      "y": 2,
      "z": -5,
      "name": "Furniture_Ancient_Barrel"
    },
    {
      "x": 4,
      "y": 3,
      "z": -5,
      "name": "Empty"
    },
    {
      "x": 4,
      "y": 4,
      "z": -5,
      "name": "Empty"
    },
    {
      "x": 4,
      "y": 5,
      "z": -5,
      "name": "Wood_Darkwood_Planks"
    },
    {
      "x": 4,
      "y": 6,
      "z": -5,
      "name": "Wood_Darkwood_Planks"
    },
    {
      "x": 4,
      "y": 0,
      "z": -4,
      "name": "Rock_Basalt_Cobble"
    },
    {
      "x": 4,
      "y": 1,
      "z": -4,
      "name": "Wood_Darkwood_Planks"
    },
    {
      "x": 4,
      "y": 2,
      "z": -4,
      "name": "Furniture_Village_Bed",
      "components": {
        "Components": {
          "RespawnBlock": {}
        }
      },
      "rotation": 3
    },
    {
      "x": 4,
      "y": 3,
      "z": -4,
      "name": "Furniture_Village_Bed",
      "components": {
        "Components": {
          "RespawnBlock": {}
        }
      },
      "filler": 1024,
      "rotation": 3
    },
    {
      "x": 4,
      "y": 4,
      "z": -4,
      "name": "Empty"
    },
    {
      "x": 4,
      "y": 5,
      "z": -4,
      "name": "Wood_Darkwood_Planks_Half",
      "rotation": 7
    },
    {
      "x": 4,
      "y": 6,
      "z": -4,
      "name": "Wood_Darkwood_Planks"
    },
    {
      "x": 4,
      "y": 0,
      "z": -3,
      "name": "Rock_Basalt_Cobble"
    },
    {
      "x": 4,
      "y": 1,
      "z": -3,
      "name": "Wood_Darkwood_Planks"
    },
    {
      "x": 4,
      "y": 2,
      "z": -3,
      "name": "Furniture_Village_Bed",
      "components": {
        "Components": {
          "RespawnBlock": {}
        }
      },
      "filler": 32,
      "rotation": 3
    },
    {
      "x": 4,
      "y": 3,
      "z": -3,
      "name": "Furniture_Village_Bed",
      "components": {
        "Components": {
          "RespawnBlock": {}
        }
      },
      "filler": 1056,
      "rotation": 3
    },
    {
      "x": 4,
      "y": 4,
      "z": -3,
      "name": "Empty"
    },
    {
      "x": 4,
      "y": 5,
      "z": -3,
      "name": "Wood_Darkwood_Planks_Half",
      "rotation": 7
    },
    {
      "x": 4,
      "y": 6,
      "z": -3,
      "name": "Wood_Darkwood_Planks"
    },
    {
      "x": 4,
      "y": 0,
      "z": -2,
      "name": "Rock_Basalt_Cobble"
    },
    {
      "x": 4,
      "y": 1,
      "z": -2,
      "name": "Wood_Darkwood_Planks"
    },
    {
      "x": 4,
      "y": 2,
      "z": -2,
      "name": "Furniture_Village_Counter",
      "filler": 992,
      "rotation": 3
    },
    {
      "x": 4,
      "y": 3,
      "z": -2,
      "name": "Furniture_Lumberjack_Shelf",
      "rotation": 3
    },
    {
      "x": 4,
      "y": 4,
      "z": -2,
      "name": "Deco_Lantern"
    },
    {
      "x": 4,
      "y": 5,
      "z": -2,
      "name": "Wood_Darkwood_Planks_Half",
      "rotation": 7
    },
    {
      "x": 4,
      "y": 6,
      "z": -2,
      "name": "Wood_Darkwood_Planks"
    },
    {
      "x": 4,
      "y": 0,
      "z": -1,
      "name": "Rock_Basalt_Cobble"
    },
    {
      "x": 4,
      "y": 1,
      "z": -1,
      "name": "Wood_Darkwood_Planks"
    },
    {
      "x": 4,
      "y": 2,
      "z": -1,
      "name": "Furniture_Village_Counter",
      "rotation": 3
    },
    {
      "x": 4,
      "y": 3,
      "z": -1,
      "name": "Container_Bucket"
    },
    {
      "x": 4,
      "y": 4,
      "z": -1,
      "name": "Empty"
    },
    {
      "x": 4,
      "y": 5,
      "z": -1,
      "name": "Wood_Darkwood_Planks_Half",
      "rotation": 7
    },
    {
      "x": 4,
      "y": 6,
      "z": -1,
      "name": "Wood_Darkwood_Planks"
    },
    {
      "x": 4,
      "y": 0,
      "z": 0,
      "name": "Rock_Basalt_Cobble"
    },
    {
      "x": 4,
      "y": 1,
      "z": 0,
      "name": "Wood_Darkwood_Planks"
    },
    {
      "x": 4,
      "y": 2,
      "z": 0,
      "name": "Furniture_Village_Bed",
      "components": {
        "Components": {
          "RespawnBlock": {}
        }
      },
      "rotation": 3
    },
    {
      "x": 4,
      "y": 3,
      "z": 0,
      "name": "Furniture_Village_Bed",
      "components": {
        "Components": {
          "RespawnBlock": {}
        }
      },
      "filler": 1024,
      "rotation": 3
    },
    {
      "x": 4,
      "y": 4,
      "z": 0,
      "name": "Empty"
    },
    {
      "x": 4,
      "y": 5,
      "z": 0,
      "name": "Wood_Darkwood_Planks_Half",
      "rotation": 7
    },
    {
      "x": 4,
      "y": 6,
      "z": 0,
      "name": "Wood_Darkwood_Planks"
    },
    {
      "x": 4,
      "y": 0,
      "z": 1,
      "name": "Rock_Basalt_Cobble"
    },
    {
      "x": 4,
      "y": 1,
      "z": 1,
      "name": "Wood_Darkwood_Planks"
    },
    {
      "x": 4,
      "y": 2,
      "z": 1,
      "name": "Furniture_Village_Bed",
      "components": {
        "Components": {
          "RespawnBlock": {}
        }
      },
      "filler": 32,
      "rotation": 3
    },
    {
      "x": 4,
      "y": 3,
      "z": 1,
      "name": "Furniture_Village_Bed",
      "components": {
        "Components": {
          "RespawnBlock": {}
        }
      },
      "filler": 1056,
      "rotation": 3
    },
    {
      "x": 4,
      "y": 4,
      "z": 1,
      "name": "Empty"
    },
    {
      "x": 4,
      "y": 5,
      "z": 1,
      "name": "Wood_Darkwood_Planks_Half",
      "rotation": 7
    },
    {
      "x": 4,
      "y": 6,
      "z": 1,
      "name": "Wood_Darkwood_Planks"
    },
    {
      "x": 4,
      "y": 0,
      "z": 2,
      "name": "Rock_Basalt_Cobble"
    },
    {
      "x": 4,
      "y": 1,
      "z": 2,
      "name": "Wood_Darkwood_Planks"
    },
    {
      "x": 4,
      "y": 2,
      "z": 2,
      "name": "Empty"
    },
    {
      "x": 4,
      "y": 3,
      "z": 2,
      "name": "Furniture_Lumberjack_Shelf",
      "rotation": 3
    },
    {
      "x": 4,
      "y": 4,
      "z": 2,
      "name": "Deco_Coral_Shell_Swirly"
    },
    {
      "x": 4,
      "y": 5,
      "z": 2,
      "name": "Wood_Darkwood_Planks"
    },
    {
      "x": 4,
      "y": 6,
      "z": 2,
      "name": "Wood_Darkwood_Planks"
    },
    {
      "x": 4,
      "y": 0,
      "z": 3,
      "name": "Rock_Basalt_Cobble"
    },
    {
      "x": 4,
      "y": 1,
      "z": 3,
      "name": "Wood_Darkwood_Planks"
    },
    {
      "x": 4,
      "y": 2,
      "z": 3,
      "name": "Rock_Basalt_Brick_Smooth"
    },
    {
      "x": 4,
      "y": 3,
      "z": 3,
      "name": "Rock_Basalt_Cobble"
    },
    {
      "x": 4,
      "y": 4,
      "z": 3,
      "name": "Rock_Basalt_Cobble"
    },
    {
      "x": 4,
      "y": 5,
      "z": 3,
      "name": "Rock_Basalt_Cobble"
    },
    {
      "x": 4,
      "y": 6,
      "z": 3,
      "name": "Wood_Darkwood_Planks"
    },
    {
      "x": 4,
      "y": 0,
      "z": 4,
      "name": "Rock_Basalt_Cobble"
    },
    {
      "x": 4,
      "y": 1,
      "z": 4,
      "name": "Wood_Darkwood_Planks"
    },
    {
      "x": 4,
      "y": 2,
      "z": 4,
      "name": "Furniture_Village_Bookcase",
      "rotation": 3
    },
    {
      "x": 4,
      "y": 3,
      "z": 4,
      "name": "Furniture_Village_Bookcase",
      "rotation": 3
    },
    {
      "x": 4,
      "y": 4,
      "z": 4,
      "name": "Furniture_Village_Bookcase",
      "rotation": 3
    },
    {
      "x": 4,
      "y": 5,
      "z": 4,
      "name": "Wood_Darkwood_Planks"
    },
    {
      "x": 4,
      "y": 6,
      "z": 4,
      "name": "Wood_Darkwood_Planks"
    },
    {
      "x": 4,
      "y": 0,
      "z": 5,
      "name": "Rock_Basalt_Cobble"
    },
    {
      "x": 4,
      "y": 1,
      "z": 5,
      "name": "Wood_Darkwood_Planks"
    },
    {
      "x": 4,
      "y": 2,
      "z": 5,
      "name": "Furniture_Village_Bookcase",
      "rotation": 3
    },
    {
      "x": 4,
      "y": 3,
      "z": 5,
      "name": "Furniture_Village_Bookcase",
      "rotation": 3
    },
    {
      "x": 4,
      "y": 4,
      "z": 5,
      "name": "Furniture_Village_Bookcase",
      "rotation": 3
    },
    {
      "x": 4,
      "y": 5,
      "z": 5,
      "name": "Wood_Darkwood_Planks_Half",
      "rotation": 7
    },
    {
      "x": 4,
      "y": 6,
      "z": 5,
      "name": "Wood_Darkwood_Planks"
    },
    {
      "x": 4,
      "y": 0,
      "z": 6,
      "name": "Rock_Basalt_Cobble"
    },
    {
      "x": 4,
      "y": 1,
      "z": 6,
      "name": "Wood_Darkwood_Planks"
    },
    {
      "x": 4,
      "y": 2,
      "z": 6,
      "name": "Furniture_Village_Bookcase",
      "rotation": 3
    },
    {
      "x": 4,
      "y": 3,
      "z": 6,
      "name": "Furniture_Village_Bookcase",
      "rotation": 3
    },
    {
      "x": 4,
      "y": 4,
      "z": 6,
      "name": "Furniture_Village_Bookcase",
      "rotation": 3
    },
    {
      "x": 4,
      "y": 5,
      "z": 6,
      "name": "Wood_Darkwood_Planks"
    },
    {
      "x": 4,
      "y": 6,
      "z": 6,
      "name": "Wood_Darkwood_Planks"
    },
    {
      "x": 4,
      "y": 0,
      "z": 7,
      "name": "Rock_Basalt_Cobble"
    },
    {
      "x": 4,
      "y": 1,
      "z": 7,
      "name": "Rock_Basalt_Cobble"
    },
    {
      "x": 4,
      "y": 2,
      "z": 7,
      "name": "Rock_Basalt_Brick_Smooth"
    },
    {
      "x": 4,
      "y": 3,
      "z": 7,
      "name": "Rock_Basalt_Cobble"
    },
    {
      "x": 4,
      "y": 4,
      "z": 7,
      "name": "Rock_Basalt_Cobble"
    },
    {
      "x": 4,
      "y": 5,
      "z": 7,
      "name": "Rock_Basalt_Cobble"
    },
    {
      "x": 4,
      "y": 6,
      "z": 7,
      "name": "Rock_Basalt_Cobble"
    },
    {
      "x": 5,
      "y": 0,
      "z": -6,
      "name": "Rock_Basalt_Cobble"
    },
    {
      "x": 5,
      "y": 1,
      "z": -6,
      "name": "Rock_Basalt_Cobble"
    },
    {
      "x": 5,
      "y": 2,
      "z": -6,
      "name": "Rock_Basalt_Brick_Smooth"
    },
    {
      "x": 5,
      "y": 3,
      "z": -6,
      "name": "Rock_Basalt_Cobble"
    },
    {
      "x": 5,
      "y": 4,
      "z": -6,
      "name": "Rock_Basalt_Cobble"
    },
    {
      "x": 5,
      "y": 5,
      "z": -6,
      "name": "Rock_Basalt_Cobble"
    },
    {
      "x": 5,
      "y": 6,
      "z": -6,
      "name": "Rock_Basalt_Cobble"
    },
    {
      "x": 5,
      "y": 0,
      "z": -5,
      "name": "Rock_Basalt_Cobble"
    },
    {
      "x": 5,
      "y": 1,
      "z": -5,
      "name": "Rock_Basalt_Cobble"
    },
    {
      "x": 5,
      "y": 2,
      "z": -5,
      "name": "Rock_Basalt_Brick_Smooth"
    },
    {
      "x": 5,
      "y": 3,
      "z": -5,
      "name": "Rock_Basalt_Cobble"
    },
    {
      "x": 5,
      "y": 4,
      "z": -5,
      "name": "Rock_Basalt_Cobble"
    },
    {
      "x": 5,
      "y": 5,
      "z": -5,
      "name": "Rock_Basalt_Cobble"
    },
    {
      "x": 5,
      "y": 6,
      "z": -5,
      "name": "Rock_Basalt_Cobble"
    },
    {
      "x": 5,
      "y": 0,
      "z": -4,
      "name": "Rock_Basalt_Cobble"
    },
    {
      "x": 5,
      "y": 1,
      "z": -4,
      "name": "Rock_Basalt_Cobble"
    },
    {
      "x": 5,
      "y": 2,
      "z": -4,
      "name": "Rock_Basalt_Brick_Smooth"
    },
    {
      "x": 5,
      "y": 3,
      "z": -4,
      "name": "Rock_Basalt_Cobble"
    },
    {
      "x": 5,
      "y": 4,
      "z": -4,
      "name": "Rock_Basalt_Cobble"
    },
    {
      "x": 5,
      "y": 5,
      "z": -4,
      "name": "Rock_Basalt_Cobble"
    },
    {
      "x": 5,
      "y": 6,
      "z": -4,
      "name": "Rock_Basalt_Cobble"
    },
    {
      "x": 5,
      "y": 0,
      "z": -3,
      "name": "Rock_Basalt_Cobble"
    },
    {
      "x": 5,
      "y": 1,
      "z": -3,
      "name": "Rock_Basalt_Cobble"
    },
    {
      "x": 5,
      "y": 2,
      "z": -3,
      "name": "Rock_Basalt_Brick_Smooth"
    },
    {
      "x": 5,
      "y": 3,
      "z": -3,
      "name": "Rock_Basalt_Cobble"
    },
    {
      "x": 5,
      "y": 4,
      "z": -3,
      "name": "Rock_Basalt_Cobble"
    },
    {
      "x": 5,
      "y": 5,
      "z": -3,
      "name": "Rock_Basalt_Cobble"
    },
    {
      "x": 5,
      "y": 6,
      "z": -3,
      "name": "Rock_Basalt_Cobble"
    },
    {
      "x": 5,
      "y": 0,
      "z": -2,
      "name": "Rock_Basalt_Cobble"
    },
    {
      "x": 5,
      "y": 1,
      "z": -2,
      "name": "Rock_Basalt_Cobble"
    },
    {
      "x": 5,
      "y": 2,
      "z": -2,
      "name": "Rock_Basalt_Brick_Smooth"
    },
    {
      "x": 5,
      "y": 3,
      "z": -2,
      "name": "Rock_Basalt_Cobble"
    },
    {
      "x": 5,
      "y": 4,
      "z": -2,
      "name": "Rock_Basalt_Cobble"
    },
    {
      "x": 5,
      "y": 5,
      "z": -2,
      "name": "Rock_Basalt_Cobble"
    },
    {
      "x": 5,
      "y": 6,
      "z": -2,
      "name": "Rock_Basalt_Cobble"
    },
    {
      "x": 5,
      "y": 0,
      "z": -1,
      "name": "Rock_Basalt_Cobble"
    },
    {
      "x": 5,
      "y": 1,
      "z": -1,
      "name": "Rock_Basalt_Cobble"
    },
    {
      "x": 5,
      "y": 2,
      "z": -1,
      "name": "Rock_Basalt_Brick_Smooth"
    },
    {
      "x": 5,
      "y": 3,
      "z": -1,
      "name": "Rock_Basalt_Cobble"
    },
    {
      "x": 5,
      "y": 4,
      "z": -1,
      "name": "Rock_Basalt_Cobble"
    },
    {
      "x": 5,
      "y": 5,
      "z": -1,
      "name": "Rock_Basalt_Cobble"
    },
    {
      "x": 5,
      "y": 6,
      "z": -1,
      "name": "Rock_Basalt_Cobble"
    },
    {
      "x": 5,
      "y": 0,
      "z": 0,
      "name": "Rock_Basalt_Cobble"
    },
    {
      "x": 5,
      "y": 1,
      "z": 0,
      "name": "Rock_Basalt_Cobble"
    },
    {
      "x": 5,
      "y": 2,
      "z": 0,
      "name": "Rock_Basalt_Brick_Smooth"
    },
    {
      "x": 5,
      "y": 3,
      "z": 0,
      "name": "Rock_Basalt_Cobble"
    },
    {
      "x": 5,
      "y": 4,
      "z": 0,
      "name": "Rock_Basalt_Cobble"
    },
    {
      "x": 5,
      "y": 5,
      "z": 0,
      "name": "Rock_Basalt_Cobble"
    },
    {
      "x": 5,
      "y": 6,
      "z": 0,
      "name": "Rock_Basalt_Cobble"
    },
    {
      "x": 5,
      "y": 0,
      "z": 1,
      "name": "Rock_Basalt_Cobble"
    },
    {
      "x": 5,
      "y": 1,
      "z": 1,
      "name": "Rock_Basalt_Cobble"
    },
    {
      "x": 5,
      "y": 2,
      "z": 1,
      "name": "Rock_Basalt_Brick_Smooth"
    },
    {
      "x": 5,
      "y": 3,
      "z": 1,
      "name": "Rock_Basalt_Cobble"
    },
    {
      "x": 5,
      "y": 4,
      "z": 1,
      "name": "Rock_Basalt_Cobble"
    },
    {
      "x": 5,
      "y": 5,
      "z": 1,
      "name": "Rock_Basalt_Cobble"
    },
    {
      "x": 5,
      "y": 6,
      "z": 1,
      "name": "Rock_Basalt_Cobble"
    },
    {
      "x": 5,
      "y": 0,
      "z": 2,
      "name": "Rock_Basalt_Cobble"
    },
    {
      "x": 5,
      "y": 1,
      "z": 2,
      "name": "Rock_Basalt_Cobble"
    },
    {
      "x": 5,
      "y": 2,
      "z": 2,
      "name": "Rock_Basalt_Brick_Smooth"
    },
    {
      "x": 5,
      "y": 3,
      "z": 2,
      "name": "Rock_Basalt_Cobble"
    },
    {
      "x": 5,
      "y": 4,
      "z": 2,
      "name": "Rock_Basalt_Cobble"
    },
    {
      "x": 5,
      "y": 5,
      "z": 2,
      "name": "Rock_Basalt_Cobble"
    },
    {
      "x": 5,
      "y": 6,
      "z": 2,
      "name": "Rock_Basalt_Cobble"
    },
    {
      "x": 5,
      "y": 0,
      "z": 3,
      "name": "Rock_Basalt_Cobble"
    },
    {
      "x": 5,
      "y": 1,
      "z": 3,
      "name": "Rock_Basalt_Cobble"
    },
    {
      "x": 5,
      "y": 2,
      "z": 3,
      "name": "Rock_Basalt_Brick_Smooth"
    },
    {
      "x": 5,
      "y": 3,
      "z": 3,
      "name": "Rock_Basalt_Cobble"
    },
    {
      "x": 5,
      "y": 4,
      "z": 3,
      "name": "Rock_Basalt_Cobble"
    },
    {
      "x": 5,
      "y": 5,
      "z": 3,
      "name": "Rock_Basalt_Cobble"
    },
    {
      "x": 5,
      "y": 6,
      "z": 3,
      "name": "Rock_Basalt_Cobble"
    },
    {
      "x": 5,
      "y": 0,
      "z": 4,
      "name": "Rock_Basalt_Cobble"
    },
    {
      "x": 5,
      "y": 1,
      "z": 4,
      "name": "Rock_Basalt_Cobble"
    },
    {
      "x": 5,
      "y": 2,
      "z": 4,
      "name": "Rock_Basalt_Brick_Smooth"
    },
    {
      "x": 5,
      "y": 3,
      "z": 4,
      "name": "Rock_Basalt_Cobble"
    },
    {
      "x": 5,
      "y": 4,
      "z": 4,
      "name": "Rock_Basalt_Cobble"
    },
    {
      "x": 5,
      "y": 5,
      "z": 4,
      "name": "Rock_Basalt_Cobble"
    },
    {
      "x": 5,
      "y": 6,
      "z": 4,
      "name": "Rock_Basalt_Cobble"
    },
    {
      "x": 5,
      "y": 0,
      "z": 5,
      "name": "Rock_Basalt_Cobble"
    },
    {
      "x": 5,
      "y": 1,
      "z": 5,
      "name": "Rock_Basalt_Cobble"
    },
    {
      "x": 5,
      "y": 2,
      "z": 5,
      "name": "Rock_Basalt_Brick_Smooth"
    },
    {
      "x": 5,
      "y": 3,
      "z": 5,
      "name": "Rock_Basalt_Cobble"
    },
    {
      "x": 5,
      "y": 4,
      "z": 5,
      "name": "Rock_Basalt_Cobble"
    },
    {
      "x": 5,
      "y": 5,
      "z": 5,
      "name": "Rock_Basalt_Cobble"
    },
    {
      "x": 5,
      "y": 6,
      "z": 5,
      "name": "Rock_Basalt_Cobble"
    },
    {
      "x": 5,
      "y": 0,
      "z": 6,
      "name": "Rock_Basalt_Cobble"
    },
    {
      "x": 5,
      "y": 1,
      "z": 6,
      "name": "Rock_Basalt_Cobble"
    },
    {
      "x": 5,
      "y": 2,
      "z": 6,
      "name": "Rock_Basalt_Brick_Smooth"
    },
    {
      "x": 5,
      "y": 3,
      "z": 6,
      "name": "Rock_Basalt_Cobble"
    },
    {
      "x": 5,
      "y": 4,
      "z": 6,
      "name": "Rock_Basalt_Cobble"
    },
    {
      "x": 5,
      "y": 5,
      "z": 6,
      "name": "Rock_Basalt_Cobble"
    },
    {
      "x": 5,
      "y": 6,
      "z": 6,
      "name": "Rock_Basalt_Cobble"
    },
    {
      "x": 5,
      "y": 0,
      "z": 7,
      "name": "Rock_Basalt_Cobble"
    },
    {
      "x": 5,
      "y": 1,
      "z": 7,
      "name": "Rock_Basalt_Cobble"
    },
    {
      "x": 5,
      "y": 2,
      "z": 7,
      "name": "Rock_Basalt_Brick_Smooth"
    },
    {
      "x": 5,
      "y": 3,
      "z": 7,
      "name": "Rock_Basalt_Cobble"
    },
    {
      "x": 5,
      "y": 4,
      "z": 7,
      "name": "Rock_Basalt_Cobble"
    },
    {
      "x": 5,
      "y": 5,
      "z": 7,
      "name": "Rock_Basalt_Cobble"
    },
    {
      "x": 5,
      "y": 6,
      "z": 7,
      "name": "Rock_Basalt_Cobble"
    }
  ]
}