{
  "version": 8,
  "blockIdVersion": 8,
  "anchorX": -1,
  "anchorY": 15,
  "anchorZ": -8,
  "blocks": [
    {
      "x": -5,
      "y": 3,
      "z": -6,
      "name": "Rock_Slate"
    },
    {
      "x": -5,
      "y": 4,
      "z": -6,
      "name": "Rock_Slate"
    },
    {
      "x": -5,
      "y": 5,
      "z": -6,
      "name": "Rock_Slate"
    },
    {
      "x": -5,
      "y": 17,
      "z": -6,
      "name": "Rock_Slate"
    },
    {
      "x": -5,
      "y": 18,
      "z": -6,
      "name": "Rock_Slate"
    },
    {
      "x": -5,
      "y": 19,
      "z": -6,
      "name": "Rock_Slate"
    },
    {
      "x": -5,
      "y": 3,
      "z": -5,
      "name": "Rock_Slate"
    },
    {
      "x": -5,
      "y": 4,
      "z": -5,
      "name": "Rock_Slate"
    },
    {
      "x": -5,
      "y": 5,
      "z": -5,
      "name": "Rock_Slate"
    },
    {
      "x": -5,
      "y": 17,
      "z": -5,
      "name": "Rock_Slate"
    },
    {
      "x": -5,
      "y": 18,
      "z": -5,
      "name": "Rock_Slate"
    },
    {
      "x": -5,
      "y": 19,
      "z": -5,
      "name": "Rock_Slate"
    },
    {
      "x": -5,
      "y": 3,
      "z": -4,
      "name": "Rock_Slate"
    },
    {
      "x": -5,
      "y": 4,
      "z": -4,
      "name": "Rock_Slate"
    },
    {
      "x": -5,
      "y": 5,
      "z": -4,
      "name": "Rock_Slate"
    },
    {
      "x": -5,
      "y": 17,
      "z": -4,
      "name": "Rock_Slate"
    },
    {
      "x": -5,
      "y": 18,
      "z": -4,
      "name": "Rock_Slate"
    },
    {
      "x": -5,
      "y": 19,
      "z": -4,
      "name": "Rock_Slate"
    },
    {
      "x": -5,
      "y": 3,
      "z": -3,
      "name": "Rock_Slate"
    },
    {
      "x": -5,
      "y": 4,
      "z": -3,
      "name": "Rock_Slate"
    },
    {
      "x": -5,
      "y": 5,
      "z": -3,
      "name": "Rock_Slate"
    },
    {
      "x": -5,
      "y": 4,
      "z": -2,
      "name": "Rock_Slate"
    },
    {
      "x": -5,
      "y": 5,
      "z": -2,
      "name": "Rock_Slate"
    },
    {
      "x": -5,
      "y": 18,
      "z": -1,
      "name": "Plant_Leaves_Burnt"
    },
    {
      "x": -5,
      "y": 18,
      "z": 0,
      "name": "Plant_Leaves_Burnt"
    },
    {
      "x": -4,
      "y": 5,
      "z": -8,
      "name": "Rock_Slate"
    },
    {
      "x": -4,
      "y": 3,
      "z": -7,
      "name": "Rock_Slate"
    },
    {
      "x": -4,
      "y": 4,
      "z": -7,
      "name": "Rock_Slate"
    },
    {
      "x": -4,
      "y": 5,
      "z": -7,
      "name": "Rock_Slate"
    },
    {
      "x": -4,
      "y": 17,
      "z": -7,
      "name": "Rock_Slate"
    },
    {
      "x": -4,
      "y": 18,
      "z": -7,
      "name": "Rock_Slate"
    },
    {
      "x": -4,
      "y": 19,
      "z": -7,
      "name": "Rock_Slate"
    },
    {
      "x": -4,
      "y": 2,
      "z": -6,
      "name": "Rock_Slate"
    },
    {
      "x": -4,
      "y": 3,
      "z": -6,
      "name": "Rock_Slate"
    },
    {
      "x": -4,
      "y": 4,
      "z": -6,
      "name": "Rock_Slate"
    },
    {
      "x": -4,
      "y": 5,
      "z": -6,
      "name": "Rock_Slate"
    },
    {
      "x": -4,
      "y": 9,
      "z": -6,
      "name": "Rock_Slate"
    },
    {
      "x": -4,
      "y": 10,
      "z": -6,
      "name": "Rock_Slate"
    },
    {
      "x": -4,
      "y": 11,
      "z": -6,
      "name": "Rock_Slate"
    },
    {
      "x": -4,
      "y": 14,
      "z": -6,
      "name": "Rock_Slate"
    },
    {
      "x": -4,
      "y": 15,
      "z": -6,
      "name": "Rock_Slate"
    },
    {
      "x": -4,
      "y": 16,
      "z": -6,
      "name": "Rock_Slate"
    },
    {
      "x": -4,
      "y": 17,
      "z": -6,
      "name": "Rock_Slate"
    },
    {
      "x": -4,
      "y": 18,
      "z": -6,
      "name": "Rock_Slate"
    },
    {
      "x": -4,
      "y": 19,
      "z": -6,
      "name": "Rock_Slate"
    },
    {
      "x": -4,
      "y": 20,
      "z": -6,
      "name": "Rock_Slate"
    },
    {
      "x": -4,
      "y": 2,
      "z": -5,
      "name": "Rock_Slate"
    },
    {
      "x": -4,
      "y": 3,
      "z": -5,
      "name": "Rock_Slate"
    },
    {
      "x": -4,
      "y": 4,
      "z": -5,
      "name": "Rock_Slate"
    },
    {
      "x": -4,
      "y": 5,
      "z": -5,
      "name": "Rock_Slate"
    },
    {
      "x": -4,
      "y": 8,
      "z": -5,
      "name": "Rock_Slate"
    },
    {
      "x": -4,
      "y": 9,
      "z": -5,
      "name": "Rock_Slate"
    },
    {
      "x": -4,
      "y": 10,
      "z": -5,
      "name": "Rock_Slate"
    },
    {
      "x": -4,
      "y": 11,
      "z": -5,
      "name": "Rock_Slate"
    },
    {
      "x": -4,
      "y": 12,
      "z": -5,
      "name": "Rubble_Slate"
    },
    {
      "x": -4,
      "y": 14,
      "z": -5,
      "name": "Rock_Slate"
    },
    {
      "x": -4,
      "y": 15,
      "z": -5,
      "name": "Rock_Slate"
    },
    {
      "x": -4,
      "y": 16,
      "z": -5,
      "name": "Rock_Slate"
    },
    {
      "x": -4,
      "y": 17,
      "z": -5,
      "name": "Rock_Slate"
    },
    {
      "x": -4,
      "y": 18,
      "z": -5,
      "name": "Rock_Slate"
    },
    {
      "x": -4,
      "y": 19,
      "z": -5,
      "name": "Rock_Slate"
    },
    {
      "x": -4,
      "y": 20,
      "z": -5,
      "name": "Rock_Slate"
    },
    {
      "x": -4,
      "y": 2,
      "z": -4,
      "name": "Rock_Slate"
    },
    {
      "x": -4,
      "y": 3,
      "z": -4,
      "name": "Rock_Slate"
    },
    {
      "x": -4,
      "y": 4,
      "z": -4,
      "name": "Rock_Slate"
    },
    {
      "x": -4,
      "y": 5,
      "z": -4,
      "name": "Rock_Slate"
    },
    {
      "x": -4,
      "y": 6,
      "z": -4,
      "name": "Rock_Slate"
    },
    {
      "x": -4,
      "y": 7,
      "z": -4,
      "name": "Rock_Slate"
    },
    {
      "x": -4,
      "y": 8,
      "z": -4,
      "name": "Rock_Slate"
    },
    {
      "x": -4,
      "y": 9,
      "z": -4,
      "name": "Rock_Slate"
    },
    {
      "x": -4,
      "y": 10,
      "z": -4,
      "name": "Rock_Slate"
    },
    {
      "x": -4,
      "y": 11,
      "z": -4,
      "name": "Rock_Slate"
    },
    {
      "x": -4,
      "y": 15,
      "z": -4,
      "name": "Rock_Slate"
    },
    {
      "x": -4,
      "y": 16,
      "z": -4,
      "name": "Rock_Slate"
    },
    {
      "x": -4,
      "y": 17,
      "z": -4,
      "name": "Rock_Slate"
    },
    {
      "x": -4,
      "y": 18,
      "z": -4,
      "name": "Rock_Slate"
    },
    {
      "x": -4,
      "y": 19,
      "z": -4,
      "name": "Rock_Slate"
    },
    {
      "x": -4,
      "y": 3,
      "z": -3,
      "name": "Rock_Slate"
    },
    {
      "x": -4,
      "y": 4,
      "z": -3,
      "name": "Rock_Slate"
    },
    {
      "x": -4,
      "y": 5,
      "z": -3,
      "name": "Rock_Slate"
    },
    {
      "x": -4,
      "y": 6,
      "z": -3,
      "name": "Rock_Slate"
    },
    {
      "x": -4,
      "y": 7,
      "z": -3,
      "name": "Rock_Slate"
    },
    {
      "x": -4,
      "y": 8,
      "z": -3,
      "name": "Rock_Slate"
    },
    {
      "x": -4,
      "y": 9,
      "z": -3,
      "name": "Rock_Slate"
    },
    {
      "x": -4,
      "y": 10,
      "z": -3,
      "name": "Rock_Slate"
    },
    {
      "x": -4,
      "y": 17,
      "z": -3,
      "name": "Rock_Slate"
    },
    {
      "x": -4,
      "y": 18,
      "z": -3,
      "name": "Rock_Slate"
    },
    {
      "x": -4,
      "y": 19,
      "z": -3,
      "name": "Rock_Slate"
    },
    {
      "x": -4,
      "y": 3,
      "z": -2,
      "name": "Rock_Slate"
    },
    {
      "x": -4,
      "y": 4,
      "z": -2,
      "name": "Rock_Slate"
    },
    {
      "x": -4,
      "y": 5,
      "z": -2,
      "name": "Rock_Slate"
    },
    {
      "x": -4,
      "y": 18,
      "z": -1,
      "name": "Plant_Leaves_Burnt"
    },
    {
      "x": -4,
      "y": 19,
      "z": -1,
      "name": "Plant_Leaves_Burnt"
    },
    {
      "x": -4,
      "y": 17,
      "z": 0,
      "name": "Plant_Leaves_Burnt"
    },
    {
      "x": -4,
      "y": 18,
      "z": 0,
      "name": "Wood_Burnt_Trunk_Full",
      "rotation": 5
    },
    {
      "x": -4,
      "y": 19,
      "z": 0,
      "name": "Plant_Leaves_Burnt"
    },
    {
      "x": -3,
      "y": 17,
      "z": -9,
      "name": "Rock_Slate"
    },
    {
      "x": -3,
      "y": 18,
      "z": -9,
      "name": "Rock_Slate"
    },
    {
      "x": -3,
      "y": 19,
      "z": -9,
      "name": "Rock_Slate"
    },
    {
      "x": -3,
      "y": 3,
      "z": -8,
      "name": "Rock_Slate"
    },
    {
      "x": -3,
      "y": 4,
      "z": -8,
      "name": "Rock_Slate"
    },
    {
      "x": -3,
      "y": 5,
      "z": -8,
      "name": "Rock_Slate"
    },
    {
      "x": -3,
      "y": 14,
      "z": -8,
      "name": "Rock_Slate"
    },
    {
      "x": -3,
      "y": 15,
      "z": -8,
      "name": "Rock_Slate"
    },
    {
      "x": -3,
      "y": 16,
      "z": -8,
      "name": "Rock_Slate"
    },
    {
      "x": -3,
      "y": 17,
      "z": -8,
      "name": "Rock_Slate"
    },
    {
      "x": -3,
      "y": 18,
      "z": -8,
      "name": "Rock_Slate"
    },
    {
      "x": -3,
      "y": 19,
      "z": -8,
      "name": "Rock_Slate"
    },
    {
      "x": -3,
      "y": 2,
      "z": -7,
      "name": "Rock_Slate"
    },
    {
      "x": -3,
      "y": 3,
      "z": -7,
      "name": "Rock_Slate"
    },
    {
      "x": -3,
      "y": 4,
      "z": -7,
      "name": "Rock_Slate"
    },
    {
      "x": -3,
      "y": 5,
      "z": -7,
      "name": "Rock_Slate"
    },
    {
      "x": -3,
      "y": 6,
      "z": -7,
      "name": "Rock_Slate"
    },
    {
      "x": -3,
      "y": 7,
      "z": -7,
      "name": "Rock_Slate"
    },
    {
      "x": -3,
      "y": 8,
      "z": -7,
      "name": "Rock_Slate"
    },
    {
      "x": -3,
      "y": 9,
      "z": -7,
      "name": "Rock_Slate"
    },
    {
      "x": -3,
      "y": 10,
      "z": -7,
      "name": "Rock_Slate"
    },
    {
      "x": -3,
      "y": 11,
      "z": -7,
      "name": "Rock_Slate"
    },
    {
      "x": -3,
      "y": 12,
      "z": -7,
      "name": "Rock_Slate"
    },
    {
      "x": -3,
      "y": 13,
      "z": -7,
      "name": "Rock_Slate"
    },
    {
      "x": -3,
      "y": 14,
      "z": -7,
      "name": "Rock_Slate"
    },
    {
      "x": -3,
      "y": 15,
      "z": -7,
      "name": "Rock_Slate"
    },
    {
      "x": -3,
      "y": 16,
      "z": -7,
      "name": "Rock_Slate"
    },
    {
      "x": -3,
      "y": 17,
      "z": -7,
      "name": "Rock_Slate"
    },
    {
      "x": -3,
      "y": 18,
      "z": -7,
      "name": "Rock_Slate"
    },
    {
      "x": -3,
      "y": 19,
      "z": -7,
      "name": "Rock_Slate"
    },
    {
      "x": -3,
      "y": 20,
      "z": -7,
      "name": "Rock_Slate"
    },
    {
      "x": -3,
      "y": 2,
      "z": -6,
      "name": "Rock_Slate"
    },
    {
      "x": -3,
      "y": 3,
      "z": -6,
      "name": "Rock_Slate"
    },
    {
      "x": -3,
      "y": 4,
      "z": -6,
      "name": "Rock_Slate"
    },
    {
      "x": -3,
      "y": 5,
      "z": -6,
      "name": "Rock_Slate"
    },
    {
      "x": -3,
      "y": 6,
      "z": -6,
      "name": "Rock_Slate"
    },
    {
      "x": -3,
      "y": 7,
      "z": -6,
      "name": "Rock_Slate"
    },
    {
      "x": -3,
      "y": 8,
      "z": -6,
      "name": "Rock_Slate"
    },
    {
      "x": -3,
      "y": 9,
      "z": -6,
      "name": "Rock_Slate"
    },
    {
      "x": -3,
      "y": 10,
      "z": -6,
      "name": "Rock_Slate"
    },
    {
      "x": -3,
      "y": 11,
      "z": -6,
      "name": "Rock_Slate"
    },
    {
      "x": -3,
      "y": 12,
      "z": -6,
      "name": "Rock_Slate"
    },
    {
      "x": -3,
      "y": 13,
      "z": -6,
      "name": "Rock_Slate"
    },
    {
      "x": -3,
      "y": 14,
      "z": -6,
      "name": "Rock_Slate"
    },
    {
      "x": -3,
      "y": 15,
      "z": -6,
      "name": "Rock_Slate"
    },
    {
      "x": -3,
      "y": 16,
      "z": -6,
      "name": "Rock_Slate"
    },
    {
      "x": -3,
      "y": 17,
      "z": -6,
      "name": "Rock_Slate"
    },
    {
      "x": -3,
      "y": 18,
      "z": -6,
      "name": "Rock_Slate"
    },
    {
      "x": -3,
      "y": 19,
      "z": -6,
      "name": "Rock_Slate"
    },
    {
      "x": -3,
      "y": 20,
      "z": -6,
      "name": "Rock_Slate"
    },
    {
      "x": -3,
      "y": 21,
      "z": -6,
      "name": "Rubble_Slate"
    },
    {
      "x": -3,
      "y": 2,
      "z": -5,
      "name": "Rock_Slate"
    },
    {
      "x": -3,
      "y": 3,
      "z": -5,
      "name": "Rock_Slate"
    },
    {
      "x": -3,
      "y": 4,
      "z": -5,
      "name": "Rock_Slate"
    },
    {
      "x": -3,
      "y": 5,
      "z": -5,
      "name": "Rock_Slate"
    },
    {
      "x": -3,
      "y": 6,
      "z": -5,
      "name": "Rock_Slate"
    },
    {
      "x": -3,
      "y": 7,
      "z": -5,
      "name": "Rock_Slate"
    },
    {
      "x": -3,
      "y": 8,
      "z": -5,
      "name": "Rock_Slate"
    },
    {
      "x": -3,
      "y": 9,
      "z": -5,
      "name": "Rock_Slate"
    },
    {
      "x": -3,
      "y": 10,
      "z": -5,
      "name": "Rock_Slate"
    },
    {
      "x": -3,
      "y": 11,
      "z": -5,
      "name": "Rock_Slate"
    },
    {
      "x": -3,
      "y": 12,
      "z": -5,
      "name": "Rock_Slate"
    },
    {
      "x": -3,
      "y": 13,
      "z": -5,
      "name": "Rock_Slate"
    },
    {
      "x": -3,
      "y": 14,
      "z": -5,
      "name": "Rock_Slate"
    },
    {
      "x": -3,
      "y": 15,
      "z": -5,
      "name": "Rock_Slate"
    },
    {
      "x": -3,
      "y": 16,
      "z": -5,
      "name": "Rock_Slate"
    },
    {
      "x": -3,
      "y": 17,
      "z": -5,
      "name": "Rock_Slate"
    },
    {
      "x": -3,
      "y": 18,
      "z": -5,
      "name": "Rock_Slate"
    },
    {
      "x": -3,
      "y": 19,
      "z": -5,
      "name": "Rock_Slate"
    },
    {
      "x": -3,
      "y": 20,
      "z": -5,
      "name": "Rock_Slate"
    },
    {
      "x": -3,
      "y": 2,
      "z": -4,
      "name": "Rock_Slate"
    },
    {
      "x": -3,
      "y": 3,
      "z": -4,
      "name": "Rock_Slate"
    },
    {
      "x": -3,
      "y": 4,
      "z": -4,
      "name": "Rock_Slate"
    },
    {
      "x": -3,
      "y": 5,
      "z": -4,
      "name": "Rock_Slate"
    },
    {
      "x": -3,
      "y": 6,
      "z": -4,
      "name": "Rock_Slate"
    },
    {
      "x": -3,
      "y": 7,
      "z": -4,
      "name": "Rock_Slate"
    },
    {
      "x": -3,
      "y": 8,
      "z": -4,
      "name": "Rock_Slate"
    },
    {
      "x": -3,
      "y": 9,
      "z": -4,
      "name": "Rock_Slate"
    },
    {
      "x": -3,
      "y": 10,
      "z": -4,
      "name": "Rock_Slate"
    },
    {
      "x": -3,
      "y": 11,
      "z": -4,
      "name": "Rock_Slate"
    },
    {
      "x": -3,
      "y": 12,
      "z": -4,
      "name": "Rock_Slate"
    },
    {
      "x": -3,
      "y": 13,
      "z": -4,
      "name": "Rock_Slate"
    },
    {
      "x": -3,
      "y": 14,
      "z": -4,
      "name": "Rock_Slate"
    },
    {
      "x": -3,
      "y": 15,
      "z": -4,
      "name": "Rock_Slate"
    },
    {
      "x": -3,
      "y": 16,
      "z": -4,
      "name": "Rock_Slate"
    },
    {
      "x": -3,
      "y": 17,
      "z": -4,
      "name": "Rock_Slate"
    },
    {
      "x": -3,
      "y": 18,
      "z": -4,
      "name": "Rock_Slate"
    },
    {
      "x": -3,
      "y": 19,
      "z": -4,
      "name": "Rock_Slate"
    },
    {
      "x": -3,
      "y": 2,
      "z": -3,
      "name": "Rock_Slate"
    },
    {
      "x": -3,
      "y": 3,
      "z": -3,
      "name": "Rock_Slate"
    },
    {
      "x": -3,
      "y": 4,
      "z": -3,
      "name": "Rock_Slate"
    },
    {
      "x": -3,
      "y": 5,
      "z": -3,
      "name": "Rock_Slate"
    },
    {
      "x": -3,
      "y": 6,
      "z": -3,
      "name": "Rock_Slate"
    },
    {
      "x": -3,
      "y": 7,
      "z": -3,
      "name": "Rock_Slate"
    },
    {
      "x": -3,
      "y": 8,
      "z": -3,
      "name": "Rock_Slate"
    },
    {
      "x": -3,
      "y": 9,
      "z": -3,
      "name": "Rock_Slate"
    },
    {
      "x": -3,
      "y": 10,
      "z": -3,
      "name": "Rock_Slate"
    },
    {
      "x": -3,
      "y": 11,
      "z": -3,
      "name": "Rock_Slate"
    },
    {
      "x": -3,
      "y": 17,
      "z": -3,
      "name": "Rock_Slate"
    },
    {
      "x": -3,
      "y": 18,
      "z": -3,
      "name": "Rock_Slate"
    },
    {
      "x": -3,
      "y": 19,
      "z": -3,
      "name": "Rock_Slate"
    },
    {
      "x": -3,
      "y": 20,
      "z": -3,
      "name": "Rubble_Slate"
    },
    {
      "x": -3,
      "y": 4,
      "z": -2,
      "name": "Rock_Slate"
    },
    {
      "x": -3,
      "y": 5,
      "z": -2,
      "name": "Rock_Slate"
    },
    {
      "x": -3,
      "y": 18,
      "z": -1,
      "name": "Plant_Leaves_Burnt"
    },
    {
      "x": -3,
      "y": 17,
      "z": 0,
      "name": "Plant_Leaves_Burnt"
    },
    {
      "x": -3,
      "y": 18,
      "z": 0,
      "name": "Wood_Burnt_Trunk",
      "rotation": 5
    },
    {
      "x": -3,
      "y": 19,
      "z": 0,
      "name": "Plant_Leaves_Burnt"
    },
    {
      "x": -3,
      "y": 17,
      "z": 7,
      "name": "Wood_Burnt_Trunk_Full",
      "rotation": 5
    },
    {
      "x": -3,
      "y": 17,
      "z": 8,
      "name": "Wood_Burnt_Trunk_Full",
      "rotation": 4
    },
    {
      "x": -3,
      "y": 3,
      "z": 9,
      "name": "Rock_Slate"
    },
    {
      "x": -3,
      "y": 4,
      "z": 9,
      "name": "Rock_Slate"
    },
    {
      "x": -3,
      "y": 17,
      "z": 9,
      "name": "Wood_Burnt_Trunk_Full",
      "rotation": 4
    },
    {
      "x": -3,
      "y": 3,
      "z": 10,
      "name": "Rock_Slate"
    },
    {
      "x": -3,
      "y": 4,
      "z": 10,
      "name": "Rock_Slate"
    },
    {
      "x": -3,
      "y": 8,
      "z": 10,
      "name": "Rock_Slate"
    },
    {
      "x": -3,
      "y": 9,
      "z": 10,
      "name": "Rock_Slate"
    },
    {
      "x": -3,
      "y": 10,
      "z": 10,
      "name": "Plant_Crop_Mushroom_Glowing_Violet"
    },
    {
      "x": -3,
      "y": 7,
      "z": 11,
      "name": "Rock_Slate"
    },
    {
      "x": -3,
      "y": 8,
      "z": 11,
      "name": "Rock_Slate"
    },
    {
      "x": -3,
      "y": 9,
      "z": 11,
      "name": "Rock_Slate"
    },
    {
      "x": -3,
      "y": 10,
      "z": 11,
      "name": "Rock_Slate"
    },
    {
      "x": -3,
      "y": 11,
      "z": 11,
      "name": "Rubble_Slate"
    },
    {
      "x": -3,
      "y": 8,
      "z": 12,
      "name": "Rock_Slate"
    },
    {
      "x": -3,
      "y": 9,
      "z": 12,
      "name": "Rock_Slate"
    },
    {
      "x": -3,
      "y": 10,
      "z": 12,
      "name": "Rock_Slate"
    },
    {
      "x": -2,
      "y": 22,
      "z": -12,
      "name": "Plant_Leaves_Burnt"
    },
    {
      "x": -2,
      "y": 17,
      "z": -11,
      "name": "Rock_Slate"
    },
    {
      "x": -2,
      "y": 18,
      "z": -11,
      "name": "Rock_Slate"
    },
    {
      "x": -2,
      "y": 19,
      "z": -11,
      "name": "Rock_Slate"
    },
    {
      "x": -2,
      "y": 21,
      "z": -11,
      "name": "Plant_Leaves_Burnt"
    },
    {
      "x": -2,
      "y": 22,
      "z": -11,
      "name": "Plant_Leaves_Burnt"
    },
    {
      "x": -2,
      "y": 14,
      "z": -10,
      "name": "Rock_Slate"
    },
    {
      "x": -2,
      "y": 15,
      "z": -10,
      "name": "Rock_Slate"
    },
    {
      "x": -2,
      "y": 16,
      "z": -10,
      "name": "Rock_Slate"
    },
    {
      "x": -2,
      "y": 17,
      "z": -10,
      "name": "Rock_Slate"
    },
    {
      "x": -2,
      "y": 18,
      "z": -10,
      "name": "Rock_Slate"
    },
    {
      "x": -2,
      "y": 19,
      "z": -10,
      "name": "Rock_Slate"
    },
    {
      "x": -2,
      "y": 3,
      "z": -9,
      "name": "Rock_Slate"
    },
    {
      "x": -2,
      "y": 4,
      "z": -9,
      "name": "Rock_Slate"
    },
    {
      "x": -2,
      "y": 5,
      "z": -9,
      "name": "Rock_Slate"
    },
    {
      "x": -2,
      "y": 6,
      "z": -9,
      "name": "Rock_Slate"
    },
    {
      "x": -2,
      "y": 7,
      "z": -9,
      "name": "Rock_Slate"
    },
    {
      "x": -2,
      "y": 8,
      "z": -9,
      "name": "Rock_Slate"
    },
    {
      "x": -2,
      "y": 9,
      "z": -9,
      "name": "Rock_Slate"
    },
    {
      "x": -2,
      "y": 10,
      "z": -9,
      "name": "Rock_Slate"
    },
    {
      "x": -2,
      "y": 11,
      "z": -9,
      "name": "Rock_Slate"
    },
    {
      "x": -2,
      "y": 12,
      "z": -9,
      "name": "Rock_Slate"
    },
    {
      "x": -2,
      "y": 13,
      "z": -9,
      "name": "Rock_Slate"
    },
    {
      "x": -2,
      "y": 14,
      "z": -9,
      "name": "Rock_Slate"
    },
    {
      "x": -2,
      "y": 15,
      "z": -9,
      "name": "Rock_Slate"
    },
    {
      "x": -2,
      "y": 16,
      "z": -9,
      "name": "Rock_Slate"
    },
    {
      "x": -2,
      "y": 17,
      "z": -9,
      "name": "Rock_Slate"
    },
    {
      "x": -2,
      "y": 18,
      "z": -9,
      "name": "Rock_Slate"
    },
    {
      "x": -2,
      "y": 19,
      "z": -9,
      "name": "Rock_Slate"
    },
    {
      "x": -2,
      "y": 21,
      "z": -9,
      "name": "Plant_Leaves_Burnt"
    },
    {
      "x": -2,
      "y": 3,
      "z": -8,
      "name": "Rock_Slate"
    },
    {
      "x": -2,
      "y": 4,
      "z": -8,
      "name": "Rock_Slate"
    },
    {
      "x": -2,
      "y": 5,
      "z": -8,
      "name": "Rock_Slate"
    },
    {
      "x": -2,
      "y": 6,
      "z": -8,
      "name": "Rock_Slate"
    },
    {
      "x": -2,
      "y": 7,
      "z": -8,
      "name": "Rock_Slate"
    },
    {
      "x": -2,
      "y": 8,
      "z": -8,
      "name": "Rock_Slate"
    },
    {
      "x": -2,
      "y": 9,
      "z": -8,
      "name": "Rock_Slate"
    },
    {
      "x": -2,
      "y": 10,
      "z": -8,
      "name": "Rock_Slate"
    },
    {
      "x": -2,
      "y": 11,
      "z": -8,
      "name": "Rock_Slate"
    },
    {
      "x": -2,
      "y": 12,
      "z": -8,
      "name": "Rock_Slate"
    },
    {
      "x": -2,
      "y": 13,
      "z": -8,
      "name": "Rock_Slate"
    },
    {
      "x": -2,
      "y": 14,
      "z": -8,
      "name": "Rock_Slate"
    },
    {
      "x": -2,
      "y": 15,
      "z": -8,
      "name": "Rock_Slate"
    },
    {
      "x": -2,
      "y": 16,
      "z": -8,
      "name": "Rock_Slate"
    },
    {
      "x": -2,
      "y": 17,
      "z": -8,
      "name": "Rock_Slate"
    },
    {
      "x": -2,
      "y": 18,
      "z": -8,
      "name": "Rock_Slate"
    },
    {
      "x": -2,
      "y": 19,
      "z": -8,
      "name": "Rock_Slate"
    },
    {
      "x": -2,
      "y": 2,
      "z": -7,
      "name": "Rock_Slate"
    },
    {
      "x": -2,
      "y": 3,
      "z": -7,
      "name": "Rock_Slate"
    },
    {
      "x": -2,
      "y": 4,
      "z": -7,
      "name": "Rock_Slate"
    },
    {
      "x": -2,
      "y": 5,
      "z": -7,
      "name": "Rock_Slate"
    },
    {
      "x": -2,
      "y": 6,
      "z": -7,
      "name": "Rock_Slate"
    },
    {
      "x": -2,
      "y": 7,
      "z": -7,
      "name": "Rock_Slate"
    },
    {
      "x": -2,
      "y": 8,
      "z": -7,
      "name": "Rock_Slate"
    },
    {
      "x": -2,
      "y": 9,
      "z": -7,
      "name": "Rock_Slate"
    },
    {
      "x": -2,
      "y": 10,
      "z": -7,
      "name": "Rock_Slate"
    },
    {
      "x": -2,
      "y": 11,
      "z": -7,
      "name": "Rock_Slate"
    },
    {
      "x": -2,
      "y": 12,
      "z": -7,
      "name": "Rock_Slate"
    },
    {
      "x": -2,
      "y": 13,
      "z": -7,
      "name": "Rock_Slate"
    },
    {
      "x": -2,
      "y": 14,
      "z": -7,
      "name": "Rock_Slate"
    },
    {
      "x": -2,
      "y": 15,
      "z": -7,
      "name": "Rock_Slate"
    },
    {
      "x": -2,
      "y": 16,
      "z": -7,
      "name": "Rock_Slate"
    },
    {
      "x": -2,
      "y": 17,
      "z": -7,
      "name": "Rock_Slate"
    },
    {
      "x": -2,
      "y": 18,
      "z": -7,
      "name": "Rock_Slate"
    },
    {
      "x": -2,
      "y": 19,
      "z": -7,
      "name": "Rock_Slate"
    },
    {
      "x": -2,
      "y": 20,
      "z": -7,
      "name": "Rock_Slate"
    },
    {
      "x": -2,
      "y": 2,
      "z": -6,
      "name": "Rock_Slate"
    },
    {
      "x": -2,
      "y": 3,
      "z": -6,
      "name": "Rock_Slate"
    },
    {
      "x": -2,
      "y": 4,
      "z": -6,
      "name": "Rock_Slate"
    },
    {
      "x": -2,
      "y": 5,
      "z": -6,
      "name": "Rock_Slate"
    },
    {
      "x": -2,
      "y": 6,
      "z": -6,
      "name": "Rock_Slate"
    },
    {
      "x": -2,
      "y": 7,
      "z": -6,
      "name": "Rock_Slate"
    },
    {
      "x": -2,
      "y": 8,
      "z": -6,
      "name": "Rock_Slate"
    },
    {
      "x": -2,
      "y": 9,
      "z": -6,
      "name": "Rock_Slate"
    },
    {
      "x": -2,
      "y": 10,
      "z": -6,
      "name": "Rock_Slate"
    },
    {
      "x": -2,
      "y": 11,
      "z": -6,
      "name": "Rock_Slate"
    },
    {
      "x": -2,
      "y": 12,
      "z": -6,
      "name": "Rock_Slate"
    },
    {
      "x": -2,
      "y": 13,
      "z": -6,
      "name": "Rock_Slate"
    },
    {
      "x": -2,
      "y": 14,
      "z": -6,
      "name": "Rock_Slate"
    },
    {
      "x": -2,
      "y": 15,
      "z": -6,
      "name": "Rock_Slate"
    },
    {
      "x": -2,
      "y": 16,
      "z": -6,
      "name": "Rock_Slate"
    },
    {
      "x": -2,
      "y": 17,
      "z": -6,
      "name": "Rock_Slate"
    },
    {
      "x": -2,
      "y": 18,
      "z": -6,
      "name": "Rock_Slate"
    },
    {
      "x": -2,
      "y": 19,
      "z": -6,
      "name": "Rock_Slate"
    },
    {
      "x": -2,
      "y": 20,
      "z": -6,
      "name": "Rock_Slate"
    },
    {
      "x": -2,
      "y": 2,
      "z": -5,
      "name": "Rock_Slate"
    },
    {
      "x": -2,
      "y": 3,
      "z": -5,
      "name": "Rock_Slate"
    },
    {
      "x": -2,
      "y": 4,
      "z": -5,
      "name": "Rock_Slate"
    },
    {
      "x": -2,
      "y": 5,
      "z": -5,
      "name": "Rock_Slate"
    },
    {
      "x": -2,
      "y": 6,
      "z": -5,
      "name": "Rock_Slate"
    },
    {
      "x": -2,
      "y": 7,
      "z": -5,
      "name": "Rock_Slate"
    },
    {
      "x": -2,
      "y": 8,
      "z": -5,
      "name": "Rock_Slate"
    },
    {
      "x": -2,
      "y": 9,
      "z": -5,
      "name": "Rock_Slate"
    },
    {
      "x": -2,
      "y": 10,
      "z": -5,
      "name": "Rock_Slate"
    },
    {
      "x": -2,
      "y": 11,
      "z": -5,
      "name": "Rock_Slate"
    },
    {
      "x": -2,
      "y": 12,
      "z": -5,
      "name": "Rock_Slate"
    },
    {
      "x": -2,
      "y": 13,
      "z": -5,
      "name": "Rock_Slate"
    },
    {
      "x": -2,
      "y": 14,
      "z": -5,
      "name": "Rock_Slate"
    },
    {
      "x": -2,
      "y": 15,
      "z": -5,
      "name": "Rock_Slate"
    },
    {
      "x": -2,
      "y": 16,
      "z": -5,
      "name": "Rock_Slate"
    },
    {
      "x": -2,
      "y": 17,
      "z": -5,
      "name": "Rock_Slate"
    },
    {
      "x": -2,
      "y": 18,
      "z": -5,
      "name": "Rock_Slate"
    },
    {
      "x": -2,
      "y": 19,
      "z": -5,
      "name": "Rock_Slate"
    },
    {
      "x": -2,
      "y": 20,
      "z": -5,
      "name": "Rock_Slate"
    },
    {
      "x": -2,
      "y": 2,
      "z": -4,
      "name": "Rock_Slate"
    },
    {
      "x": -2,
      "y": 3,
      "z": -4,
      "name": "Rock_Slate"
    },
    {
      "x": -2,
      "y": 4,
      "z": -4,
      "name": "Rock_Slate"
    },
    {
      "x": -2,
      "y": 5,
      "z": -4,
      "name": "Rock_Slate"
    },
    {
      "x": -2,
      "y": 6,
      "z": -4,
      "name": "Rock_Slate"
    },
    {
      "x": -2,
      "y": 7,
      "z": -4,
      "name": "Rock_Slate"
    },
    {
      "x": -2,
      "y": 8,
      "z": -4,
      "name": "Rock_Slate"
    },
    {
      "x": -2,
      "y": 9,
      "z": -4,
      "name": "Rock_Slate"
    },
    {
      "x": -2,
      "y": 10,
      "z": -4,
      "name": "Rock_Slate"
    },
    {
      "x": -2,
      "y": 11,
      "z": -4,
      "name": "Rock_Slate"
    },
    {
      "x": -2,
      "y": 12,
      "z": -4,
      "name": "Rock_Slate"
    },
    {
      "x": -2,
      "y": 13,
      "z": -4,
      "name": "Rock_Slate"
    },
    {
      "x": -2,
      "y": 14,
      "z": -4,
      "name": "Rock_Slate"
    },
    {
      "x": -2,
      "y": 15,
      "z": -4,
      "name": "Rock_Slate"
    },
    {
      "x": -2,
      "y": 16,
      "z": -4,
      "name": "Rock_Slate"
    },
    {
      "x": -2,
      "y": 17,
      "z": -4,
      "name": "Rock_Slate"
    },
    {
      "x": -2,
      "y": 18,
      "z": -4,
      "name": "Rock_Slate"
    },
    {
      "x": -2,
      "y": 19,
      "z": -4,
      "name": "Rock_Slate"
    },
    {
      "x": -2,
      "y": 20,
      "z": -4,
      "name": "Wood_Burnt_Trunk_Full",
      "rotation": 5
    },
    {
      "x": -2,
      "y": 3,
      "z": -3,
      "name": "Rock_Slate"
    },
    {
      "x": -2,
      "y": 4,
      "z": -3,
      "name": "Rock_Slate"
    },
    {
      "x": -2,
      "y": 5,
      "z": -3,
      "name": "Rock_Slate"
    },
    {
      "x": -2,
      "y": 7,
      "z": -3,
      "name": "Rock_Slate"
    },
    {
      "x": -2,
      "y": 8,
      "z": -3,
      "name": "Rock_Slate"
    },
    {
      "x": -2,
      "y": 9,
      "z": -3,
      "name": "Rock_Slate"
    },
    {
      "x": -2,
      "y": 10,
      "z": -3,
      "name": "Rock_Slate"
    },
    {
      "x": -2,
      "y": 11,
      "z": -3,
      "name": "Rock_Slate"
    },
    {
      "x": -2,
      "y": 17,
      "z": -3,
      "name": "Rock_Slate"
    },
    {
      "x": -2,
      "y": 18,
      "z": -3,
      "name": "Rock_Slate"
    },
    {
      "x": -2,
      "y": 19,
      "z": -3,
      "name": "Rock_Slate"
    },
    {
      "x": -2,
      "y": 18,
      "z": 0,
      "name": "Wood_Burnt_Trunk",
      "rotation": 5
    },
    {
      "x": -2,
      "y": 19,
      "z": 0,
      "name": "Wood_Burnt_Trunk_Full",
      "rotation": 5
    },
    {
      "x": -2,
      "y": 12,
      "z": 5,
      "name": "Wood_Burnt_Roots"
    },
    {
      "x": -2,
      "y": 13,
      "z": 5,
      "name": "Wood_Burnt_Trunk_Full"
    },
    {
      "x": -2,
      "y": 14,
      "z": 5,
      "name": "Wood_Burnt_Trunk_Full"
    },
    {
      "x": -2,
      "y": 15,
      "z": 5,
      "name": "Wood_Burnt_Trunk_Full",
      "rotation": 4
    },
    {
      "x": -2,
      "y": 15,
      "z": 6,
      "name": "Wood_Burnt_Trunk_Full"
    },
    {
      "x": -2,
      "y": 16,
      "z": 6,
      "name": "Wood_Burnt_Trunk_Full",
      "rotation": 5
    },
    {
      "x": -2,
      "y": 17,
      "z": 7,
      "name": "Wood_Burnt_Trunk_Full",
      "rotation": 5
    },
    {
      "x": -2,
      "y": 3,
      "z": 8,
      "name": "Rock_Slate"
    },
    {
      "x": -2,
      "y": 4,
      "z": 8,
      "name": "Rock_Slate"
    },
    {
      "x": -2,
      "y": 3,
      "z": 9,
      "name": "Rock_Slate"
    },
    {
      "x": -2,
      "y": 4,
      "z": 9,
      "name": "Rock_Slate"
    },
    {
      "x": -2,
      "y": 6,
      "z": 9,
      "name": "Rock_Slate"
    },
    {
      "x": -2,
      "y": 7,
      "z": 9,
      "name": "Rock_Slate"
    },
    {
      "x": -2,
      "y": 8,
      "z": 9,
      "name": "Rock_Slate"
    },
    {
      "x": -2,
      "y": 9,
      "z": 9,
      "name": "Rock_Slate"
    },
    {
      "x": -2,
      "y": 12,
      "z": 9,
      "name": "Wood_Burnt_Roots"
    },
    {
      "x": -2,
      "y": 13,
      "z": 9,
      "name": "Wood_Burnt_Trunk_Full"
    },
    {
      "x": -2,
      "y": 14,
      "z": 9,
      "name": "Wood_Burnt_Trunk_Full"
    },
    {
      "x": -2,
      "y": 15,
      "z": 9,
      "name": "Wood_Burnt_Trunk_Full",
      "rotation": 5
    },
    {
      "x": -2,
      "y": 3,
      "z": 10,
      "name": "Rock_Slate"
    },
    {
      "x": -2,
      "y": 4,
      "z": 10,
      "name": "Rock_Slate"
    },
    {
      "x": -2,
      "y": 5,
      "z": 10,
      "name": "Rock_Slate"
    },
    {
      "x": -2,
      "y": 6,
      "z": 10,
      "name": "Rock_Slate"
    },
    {
      "x": -2,
      "y": 7,
      "z": 10,
      "name": "Rock_Slate"
    },
    {
      "x": -2,
      "y": 8,
      "z": 10,
      "name": "Rock_Slate"
    },
    {
      "x": -2,
      "y": 9,
      "z": 10,
      "name": "Rock_Slate"
    },
    {
      "x": -2,
      "y": 10,
      "z": 10,
      "name": "Rock_Slate"
    },
    {
      "x": -2,
      "y": 11,
      "z": 10,
      "name": "Rock_Slate"
    },
    {
      "x": -2,
      "y": 12,
      "z": 10,
      "name": "Rock_Slate"
    },
    {
      "x": -2,
      "y": 13,
      "z": 10,
      "name": "Rock_Slate"
    },
    {
      "x": -2,
      "y": 14,
      "z": 10,
      "name": "Wood_Burnt_Trunk_Full",
      "rotation": 4
    },
    {
      "x": -2,
      "y": 3,
      "z": 11,
      "name": "Rock_Slate"
    },
    {
      "x": -2,
      "y": 4,
      "z": 11,
      "name": "Rock_Slate"
    },
    {
      "x": -2,
      "y": 5,
      "z": 11,
      "name": "Rock_Slate"
    },
    {
      "x": -2,
      "y": 6,
      "z": 11,
      "name": "Rock_Slate"
    },
    {
      "x": -2,
      "y": 7,
      "z": 11,
      "name": "Rock_Slate"
    },
    {
      "x": -2,
      "y": 8,
      "z": 11,
      "name": "Rock_Slate"
    },
    {
      "x": -2,
      "y": 9,
      "z": 11,
      "name": "Rock_Slate"
    },
    {
      "x": -2,
      "y": 10,
      "z": 11,
      "name": "Rock_Slate"
    },
    {
      "x": -2,
      "y": 11,
      "z": 11,
      "name": "Rock_Slate"
    },
    {
      "x": -2,
      "y": 12,
      "z": 11,
      "name": "Rock_Slate"
    },
    {
      "x": -2,
      "y": 13,
      "z": 11,
      "name": "Rock_Slate"
    },
    {
      "x": -2,
      "y": 3,
      "z": 12,
      "name": "Rock_Slate"
    },
    {
      "x": -2,
      "y": 4,
      "z": 12,
      "name": "Rock_Slate"
    },
    {
      "x": -2,
      "y": 5,
      "z": 12,
      "name": "Rock_Slate"
    },
    {
      "x": -2,
      "y": 6,
      "z": 12,
      "name": "Rock_Slate"
    },
    {
      "x": -2,
      "y": 7,
      "z": 12,
      "name": "Rock_Slate"
    },
    {
      "x": -2,
      "y": 8,
      "z": 12,
      "name": "Rock_Slate"
    },
    {
      "x": -2,
      "y": 9,
      "z": 12,
      "name": "Rock_Slate"
    },
    {
      "x": -2,
      "y": 10,
      "z": 12,
      "name": "Rock_Slate"
    },
    {
      "x": -2,
      "y": 12,
      "z": 12,
      "name": "Rock_Slate"
    },
    {
      "x": -2,
      "y": 13,
      "z": 12,
      "name": "Rock_Slate"
    },
    {
      "x": -2,
      "y": 14,
      "z": 12,
      "name": "Rock_Slate"
    },
    {
      "x": -2,
      "y": 9,
      "z": 13,
      "name": "Rock_Slate"
    },
    {
      "x": -2,
      "y": 10,
      "z": 13,
      "name": "Rock_Slate"
    },
    {
      "x": -1,
      "y": 22,
      "z": -14,
      "name": "Plant_Leaves_Burnt"
    },
    {
      "x": -1,
      "y": 21,
      "z": -13,
      "name": "Plant_Leaves_Burnt"
    },
    {
      "x": -1,
      "y": 22,
      "z": -13,
      "name": "Wood_Burnt_Trunk",
      "rotation": 4
    },
    {
      "x": -1,
      "y": 23,
      "z": -13,
      "name": "Plant_Leaves_Burnt"
    },
    {
      "x": -1,
      "y": 21,
      "z": -12,
      "name": "Plant_Leaves_Burnt"
    },
    {
      "x": -1,
      "y": 22,
      "z": -12,
      "name": "Wood_Burnt_Trunk",
      "rotation": 4
    },
    {
      "x": -1,
      "y": 23,
      "z": -12,
      "name": "Plant_Leaves_Burnt"
    },
    {
      "x": -1,
      "y": 15,
      "z": -11,
      "name": "Rock_Slate"
    },
    {
      "x": -1,
      "y": 16,
      "z": -11,
      "name": "Rock_Slate"
    },
    {
      "x": -1,
      "y": 17,
      "z": -11,
      "name": "Rock_Slate"
    },
    {
      "x": -1,
      "y": 18,
      "z": -11,
      "name": "Rock_Slate"
    },
    {
      "x": -1,
      "y": 19,
      "z": -11,
      "name": "Rock_Slate"
    },
    {
      "x": -1,
      "y": 21,
      "z": -11,
      "name": "Wood_Burnt_Trunk",
      "rotation": 4
    },
    {
      "x": -1,
      "y": 22,
      "z": -11,
      "name": "Wood_Burnt_Trunk_Full",
      "rotation": 4
    },
    {
      "x": -1,
      "y": 3,
      "z": -10,
      "name": "Rock_Slate"
    },
    {
      "x": -1,
      "y": 4,
      "z": -10,
      "name": "Rock_Slate"
    },
    {
      "x": -1,
      "y": 5,
      "z": -10,
      "name": "Rock_Slate"
    },
    {
      "x": -1,
      "y": 6,
      "z": -10,
      "name": "Rock_Slate"
    },
    {
      "x": -1,
      "y": 7,
      "z": -10,
      "name": "Rock_Slate"
    },
    {
      "x": -1,
      "y": 8,
      "z": -10,
      "name": "Rock_Slate"
    },
    {
      "x": -1,
      "y": 9,
      "z": -10,
      "name": "Rock_Slate"
    },
    {
      "x": -1,
      "y": 10,
      "z": -10,
      "name": "Rock_Slate"
    },
    {
      "x": -1,
      "y": 11,
      "z": -10,
      "name": "Rock_Slate"
    },
    {
      "x": -1,
      "y": 12,
      "z": -10,
      "name": "Rock_Slate"
    },
    {
      "x": -1,
      "y": 13,
      "z": -10,
      "name": "Rock_Slate"
    },
    {
      "x": -1,
      "y": 14,
      "z": -10,
      "name": "Rock_Slate"
    },
    {
      "x": -1,
      "y": 15,
      "z": -10,
      "name": "Rock_Slate"
    },
    {
      "x": -1,
      "y": 16,
      "z": -10,
      "name": "Rock_Slate"
    },
    {
      "x": -1,
      "y": 17,
      "z": -10,
      "name": "Rock_Slate"
    },
    {
      "x": -1,
      "y": 18,
      "z": -10,
      "name": "Rock_Slate"
    },
    {
      "x": -1,
      "y": 19,
      "z": -10,
      "name": "Rock_Slate"
    },
    {
      "x": -1,
      "y": 20,
      "z": -10,
      "name": "Plant_Leaves_Burnt"
    },
    {
      "x": -1,
      "y": 21,
      "z": -10,
      "name": "Wood_Burnt_Trunk",
      "rotation": 4
    },
    {
      "x": -1,
      "y": 22,
      "z": -10,
      "name": "Plant_Leaves_Burnt"
    },
    {
      "x": -1,
      "y": 2,
      "z": -9,
      "name": "Rock_Slate"
    },
    {
      "x": -1,
      "y": 3,
      "z": -9,
      "name": "Rock_Slate"
    },
    {
      "x": -1,
      "y": 4,
      "z": -9,
      "name": "Rock_Slate"
    },
    {
      "x": -1,
      "y": 5,
      "z": -9,
      "name": "Rock_Slate"
    },
    {
      "x": -1,
      "y": 6,
      "z": -9,
      "name": "Rock_Slate"
    },
    {
      "x": -1,
      "y": 7,
      "z": -9,
      "name": "Rock_Slate"
    },
    {
      "x": -1,
      "y": 8,
      "z": -9,
      "name": "Rock_Slate"
    },
    {
      "x": -1,
      "y": 9,
      "z": -9,
      "name": "Rock_Slate"
    },
    {
      "x": -1,
      "y": 10,
      "z": -9,
      "name": "Rock_Slate"
    },
    {
      "x": -1,
      "y": 11,
      "z": -9,
      "name": "Rock_Slate"
    },
    {
      "x": -1,
      "y": 12,
      "z": -9,
      "name": "Rock_Slate"
    },
    {
      "x": -1,
      "y": 13,
      "z": -9,
      "name": "Rock_Slate"
    },
    {
      "x": -1,
      "y": 14,
      "z": -9,
      "name": "Rock_Slate"
    },
    {
      "x": -1,
      "y": 15,
      "z": -9,
      "name": "Rock_Slate"
    },
    {
      "x": -1,
      "y": 16,
      "z": -9,
      "name": "Rock_Slate"
    },
    {
      "x": -1,
      "y": 17,
      "z": -9,
      "name": "Rock_Slate"
    },
    {
      "x": -1,
      "y": 18,
      "z": -9,
      "name": "Rock_Slate"
    },
    {
      "x": -1,
      "y": 19,
      "z": -9,
      "name": "Rock_Slate"
    },
    {
      "x": -1,
      "y": 20,
      "z": -9,
      "name": "Wood_Burnt_Trunk",
      "rotation": 4
    },
    {
      "x": -1,
      "y": 21,
      "z": -9,
      "name": "Wood_Burnt_Trunk",
      "rotation": 4
    },
    {
      "x": -1,
      "y": 2,
      "z": -8,
      "name": "Rock_Slate"
    },
    {
      "x": -1,
      "y": 3,
      "z": -8,
      "name": "Rock_Slate"
    },
    {
      "x": -1,
      "y": 4,
      "z": -8,
      "name": "Rock_Slate"
    },
    {
      "x": -1,
      "y": 5,
      "z": -8,
      "name": "Rock_Slate"
    },
    {
      "x": -1,
      "y": 6,
      "z": -8,
      "name": "Rock_Slate"
    },
    {
      "x": -1,
      "y": 7,
      "z": -8,
      "name": "Rock_Slate"
    },
    {
      "x": -1,
      "y": 8,
      "z": -8,
      "name": "Rock_Slate"
    },
    {
      "x": -1,
      "y": 9,
      "z": -8,
      "name": "Rock_Slate"
    },
    {
      "x": -1,
      "y": 10,
      "z": -8,
      "name": "Rock_Slate"
    },
    {
      "x": -1,
      "y": 11,
      "z": -8,
      "name": "Rock_Slate"
    },
    {
      "x": -1,
      "y": 12,
      "z": -8,
      "name": "Rock_Slate"
    },
    {
      "x": -1,
      "y": 13,
      "z": -8,
      "name": "Rock_Slate"
    },
    {
      "x": -1,
      "y": 14,
      "z": -8,
      "name": "Rock_Slate"
    },
    {
      "x": -1,
      "y": 15,
      "z": -8,
      "name": "Rock_Slate"
    },
    {
      "x": -1,
      "y": 16,
      "z": -8,
      "name": "Rock_Slate"
    },
    {
      "x": -1,
      "y": 17,
      "z": -8,
      "name": "Rock_Slate"
    },
    {
      "x": -1,
      "y": 18,
      "z": -8,
      "name": "Rock_Slate"
    },
    {
      "x": -1,
      "y": 19,
      "z": -8,
      "name": "Rock_Slate"
    },
    {
      "x": -1,
      "y": 20,
      "z": -8,
      "name": "Wood_Burnt_Trunk",
      "rotation": 4
    },
    {
      "x": -1,
      "y": 21,
      "z": -8,
      "name": "Wood_Burnt_Trunk",
      "rotation": 4
    },
    {
      "x": -1,
      "y": 2,
      "z": -7,
      "name": "Rock_Slate"
    },
    {
      "x": -1,
      "y": 3,
      "z": -7,
      "name": "Rock_Slate"
    },
    {
      "x": -1,
      "y": 4,
      "z": -7,
      "name": "Rock_Slate"
    },
    {
      "x": -1,
      "y": 5,
      "z": -7,
      "name": "Rock_Slate"
    },
    {
      "x": -1,
      "y": 6,
      "z": -7,
      "name": "Rock_Slate"
    },
    {
      "x": -1,
      "y": 7,
      "z": -7,
      "name": "Rock_Slate"
    },
    {
      "x": -1,
      "y": 8,
      "z": -7,
      "name": "Rock_Slate"
    },
    {
      "x": -1,
      "y": 9,
      "z": -7,
      "name": "Rock_Slate"
    },
    {
      "x": -1,
      "y": 10,
      "z": -7,
      "name": "Rock_Slate"
    },
    {
      "x": -1,
      "y": 11,
      "z": -7,
      "name": "Rock_Slate"
    },
    {
      "x": -1,
      "y": 12,
      "z": -7,
      "name": "Rock_Slate"
    },
    {
      "x": -1,
      "y": 13,
      "z": -7,
      "name": "Rock_Slate"
    },
    {
      "x": -1,
      "y": 14,
      "z": -7,
      "name": "Rock_Slate"
    },
    {
      "x": -1,
      "y": 15,
      "z": -7,
      "name": "Rock_Slate"
    },
    {
      "x": -1,
      "y": 16,
      "z": -7,
      "name": "Rock_Slate"
    },
    {
      "x": -1,
      "y": 17,
      "z": -7,
      "name": "Rock_Slate"
    },
    {
      "x": -1,
      "y": 18,
      "z": -7,
      "name": "Rock_Slate"
    },
    {
      "x": -1,
      "y": 19,
      "z": -7,
      "name": "Rock_Slate"
    },
    {
      "x": -1,
      "y": 20,
      "z": -7,
      "name": "Wood_Burnt_Trunk",
      "rotation": 4
    },
    {
      "x": -1,
      "y": 21,
      "z": -7,
      "name": "Wood_Burnt_Trunk_Full",
      "rotation": 4
    },
    {
      "x": -1,
      "y": 2,
      "z": -6,
      "name": "Rock_Slate"
    },
    {
      "x": -1,
      "y": 3,
      "z": -6,
      "name": "Rock_Slate"
    },
    {
      "x": -1,
      "y": 4,
      "z": -6,
      "name": "Rock_Slate"
    },
    {
      "x": -1,
      "y": 5,
      "z": -6,
      "name": "Rock_Slate"
    },
    {
      "x": -1,
      "y": 6,
      "z": -6,
      "name": "Rock_Slate"
    },
    {
      "x": -1,
      "y": 7,
      "z": -6,
      "name": "Rock_Slate"
    },
    {
      "x": -1,
      "y": 8,
      "z": -6,
      "name": "Rock_Slate"
    },
    {
      "x": -1,
      "y": 9,
      "z": -6,
      "name": "Rock_Slate"
    },
    {
      "x": -1,
      "y": 10,
      "z": -6,
      "name": "Rock_Slate"
    },
    {
      "x": -1,
      "y": 11,
      "z": -6,
      "name": "Rock_Slate"
    },
    {
      "x": -1,
      "y": 12,
      "z": -6,
      "name": "Rock_Slate"
    },
    {
      "x": -1,
      "y": 13,
      "z": -6,
      "name": "Rock_Slate"
    },
    {
      "x": -1,
      "y": 14,
      "z": -6,
      "name": "Rock_Slate"
    },
    {
      "x": -1,
      "y": 15,
      "z": -6,
      "name": "Rock_Slate"
    },
    {
      "x": -1,
      "y": 16,
      "z": -6,
      "name": "Rock_Slate"
    },
    {
      "x": -1,
      "y": 17,
      "z": -6,
      "name": "Rock_Slate"
    },
    {
      "x": -1,
      "y": 18,
      "z": -6,
      "name": "Rock_Slate"
    },
    {
      "x": -1,
      "y": 19,
      "z": -6,
      "name": "Rock_Slate"
    },
    {
      "x": -1,
      "y": 20,
      "z": -6,
      "name": "Wood_Burnt_Trunk",
      "rotation": 4
    },
    {
      "x": -1,
      "y": 2,
      "z": -5,
      "name": "Rock_Slate"
    },
    {
      "x": -1,
      "y": 3,
      "z": -5,
      "name": "Rock_Slate"
    },
    {
      "x": -1,
      "y": 4,
      "z": -5,
      "name": "Rock_Slate"
    },
    {
      "x": -1,
      "y": 5,
      "z": -5,
      "name": "Rock_Slate"
    },
    {
      "x": -1,
      "y": 6,
      "z": -5,
      "name": "Rock_Slate"
    },
    {
      "x": -1,
      "y": 7,
      "z": -5,
      "name": "Rock_Slate"
    },
    {
      "x": -1,
      "y": 8,
      "z": -5,
      "name": "Rock_Slate"
    },
    {
      "x": -1,
      "y": 9,
      "z": -5,
      "name": "Rock_Slate"
    },
    {
      "x": -1,
      "y": 10,
      "z": -5,
      "name": "Rock_Slate"
    },
    {
      "x": -1,
      "y": 11,
      "z": -5,
      "name": "Rock_Slate"
    },
    {
      "x": -1,
      "y": 12,
      "z": -5,
      "name": "Rock_Slate"
    },
    {
      "x": -1,
      "y": 13,
      "z": -5,
      "name": "Rock_Slate"
    },
    {
      "x": -1,
      "y": 14,
      "z": -5,
      "name": "Rock_Slate"
    },
    {
      "x": -1,
      "y": 15,
      "z": -5,
      "name": "Rock_Slate"
    },
    {
      "x": -1,
      "y": 16,
      "z": -5,
      "name": "Rock_Slate"
    },
    {
      "x": -1,
      "y": 17,
      "z": -5,
      "name": "Rock_Slate"
    },
    {
      "x": -1,
      "y": 18,
      "z": -5,
      "name": "Rock_Slate"
    },
    {
      "x": -1,
      "y": 19,
      "z": -5,
      "name": "Rock_Slate"
    },
    {
      "x": -1,
      "y": 20,
      "z": -5,
      "name": "Wood_Burnt_Trunk",
      "rotation": 4
    },
    {
      "x": -1,
      "y": 3,
      "z": -4,
      "name": "Rock_Slate"
    },
    {
      "x": -1,
      "y": 4,
      "z": -4,
      "name": "Rock_Slate"
    },
    {
      "x": -1,
      "y": 5,
      "z": -4,
      "name": "Rock_Slate"
    },
    {
      "x": -1,
      "y": 6,
      "z": -4,
      "name": "Rock_Slate"
    },
    {
      "x": -1,
      "y": 7,
      "z": -4,
      "name": "Rock_Slate"
    },
    {
      "x": -1,
      "y": 8,
      "z": -4,
      "name": "Rock_Slate"
    },
    {
      "x": -1,
      "y": 9,
      "z": -4,
      "name": "Rock_Slate"
    },
    {
      "x": -1,
      "y": 10,
      "z": -4,
      "name": "Rock_Slate"
    },
    {
      "x": -1,
      "y": 11,
      "z": -4,
      "name": "Rock_Slate"
    },
    {
      "x": -1,
      "y": 12,
      "z": -4,
      "name": "Rock_Slate"
    },
    {
      "x": -1,
      "y": 13,
      "z": -4,
      "name": "Rock_Slate"
    },
    {
      "x": -1,
      "y": 14,
      "z": -4,
      "name": "Rock_Slate"
    },
    {
      "x": -1,
      "y": 15,
      "z": -4,
      "name": "Rock_Slate"
    },
    {
      "x": -1,
      "y": 16,
      "z": -4,
      "name": "Rock_Slate"
    },
    {
      "x": -1,
      "y": 17,
      "z": -4,
      "name": "Rock_Slate"
    },
    {
      "x": -1,
      "y": 18,
      "z": -4,
      "name": "Rock_Slate"
    },
    {
      "x": -1,
      "y": 19,
      "z": -4,
      "name": "Rock_Slate"
    },
    {
      "x": -1,
      "y": 20,
      "z": -4,
      "name": "Wood_Burnt_Trunk",
      "rotation": 4
    },
    {
      "x": -1,
      "y": 19,
      "z": -3,
      "name": "Wood_Burnt_Trunk",
      "rotation": 4
    },
    {
      "x": -1,
      "y": 20,
      "z": -3,
      "name": "Wood_Burnt_Trunk_Full",
      "rotation": 4
    },
    {
      "x": -1,
      "y": 18,
      "z": -2,
      "name": "Wood_Burnt_Trunk",
      "rotation": 4
    },
    {
      "x": -1,
      "y": 19,
      "z": -2,
      "name": "Wood_Burnt_Trunk",
      "rotation": 4
    },
    {
      "x": -1,
      "y": 18,
      "z": -1,
      "name": "Wood_Burnt_Trunk",
      "rotation": 4
    },
    {
      "x": -1,
      "y": 19,
      "z": -1,
      "name": "Wood_Burnt_Trunk",
      "rotation": 4
    },
    {
      "x": -1,
      "y": 18,
      "z": 0,
      "name": "Wood_Burnt_Trunk",
      "rotation": 4
    },
    {
      "x": -1,
      "y": 19,
      "z": 0,
      "name": "Wood_Burnt_Trunk_Full",
      "rotation": 4
    },
    {
      "x": -1,
      "y": 20,
      "z": 0,
      "name": "Wood_Burnt_Branch_Long"
    },
    {
      "x": -1,
      "y": 17,
      "z": 1,
      "name": "Wood_Burnt_Trunk",
      "rotation": 4
    },
    {
      "x": -1,
      "y": 18,
      "z": 1,
      "name": "Wood_Burnt_Trunk",
      "rotation": 4
    },
    {
      "x": -1,
      "y": 17,
      "z": 2,
      "name": "Wood_Burnt_Trunk",
      "rotation": 4
    },
    {
      "x": -1,
      "y": 18,
      "z": 2,
      "name": "Wood_Burnt_Trunk",
      "rotation": 4
    },
    {
      "x": -1,
      "y": 17,
      "z": 3,
      "name": "Wood_Burnt_Trunk",
      "rotation": 4
    },
    {
      "x": -1,
      "y": 18,
      "z": 3,
      "name": "Wood_Burnt_Trunk_Full",
      "rotation": 4
    },
    {
      "x": -1,
      "y": 16,
      "z": 4,
      "name": "Wood_Burnt_Trunk",
      "rotation": 4
    },
    {
      "x": -1,
      "y": 17,
      "z": 4,
      "name": "Wood_Burnt_Trunk",
      "rotation": 4
    },
    {
      "x": -1,
      "y": 16,
      "z": 5,
      "name": "Wood_Burnt_Trunk",
      "rotation": 4
    },
    {
      "x": -1,
      "y": 17,
      "z": 5,
      "name": "Wood_Burnt_Trunk",
      "rotation": 4
    },
    {
      "x": -1,
      "y": 16,
      "z": 6,
      "name": "Wood_Burnt_Trunk",
      "rotation": 4
    },
    {
      "x": -1,
      "y": 17,
      "z": 6,
      "name": "Wood_Burnt_Trunk_Full",
      "rotation": 4
    },
    {
      "x": -1,
      "y": 16,
      "z": 7,
      "name": "Wood_Burnt_Trunk",
      "rotation": 4
    },
    {
      "x": -1,
      "y": 17,
      "z": 7,
      "name": "Wood_Burnt_Trunk_Full"
    },
    {
      "x": -1,
      "y": 18,
      "z": 7,
      "name": "Wood_Burnt_Trunk_Full"
    },
    {
      "x": -1,
      "y": 3,
      "z": 8,
      "name": "Rock_Slate"
    },
    {
      "x": -1,
      "y": 4,
      "z": 8,
      "name": "Rock_Slate"
    },
    {
      "x": -1,
      "y": 11,
      "z": 8,
      "name": "Rock_Slate"
    },
    {
      "x": -1,
      "y": 12,
      "z": 8,
      "name": "Rock_Slate"
    },
    {
      "x": -1,
      "y": 13,
      "z": 8,
      "name": "Rock_Slate"
    },
    {
      "x": -1,
      "y": 15,
      "z": 8,
      "name": "Wood_Burnt_Trunk",
      "rotation": 4
    },
    {
      "x": -1,
      "y": 16,
      "z": 8,
      "name": "Wood_Burnt_Trunk_Full",
      "rotation": 4
    },
    {
      "x": -1,
      "y": 3,
      "z": 9,
      "name": "Rock_Slate"
    },
    {
      "x": -1,
      "y": 4,
      "z": 9,
      "name": "Rock_Slate"
    },
    {
      "x": -1,
      "y": 5,
      "z": 9,
      "name": "Rock_Slate"
    },
    {
      "x": -1,
      "y": 6,
      "z": 9,
      "name": "Rock_Slate"
    },
    {
      "x": -1,
      "y": 7,
      "z": 9,
      "name": "Rock_Slate"
    },
    {
      "x": -1,
      "y": 8,
      "z": 9,
      "name": "Rock_Slate"
    },
    {
      "x": -1,
      "y": 9,
      "z": 9,
      "name": "Rock_Slate"
    },
    {
      "x": -1,
      "y": 10,
      "z": 9,
      "name": "Rock_Slate"
    },
    {
      "x": -1,
      "y": 11,
      "z": 9,
      "name": "Rock_Slate"
    },
    {
      "x": -1,
      "y": 12,
      "z": 9,
      "name": "Rock_Slate"
    },
    {
      "x": -1,
      "y": 13,
      "z": 9,
      "name": "Rock_Slate"
    },
    {
      "x": -1,
      "y": 15,
      "z": 9,
      "name": "Wood_Burnt_Trunk",
      "rotation": 4
    },
    {
      "x": -1,
      "y": 16,
      "z": 9,
      "name": "Wood_Burnt_Trunk_Full",
      "rotation": 4
    },
    {
      "x": -1,
      "y": 3,
      "z": 10,
      "name": "Rock_Slate"
    },
    {
      "x": -1,
      "y": 4,
      "z": 10,
      "name": "Rock_Slate"
    },
    {
      "x": -1,
      "y": 5,
      "z": 10,
      "name": "Rock_Slate"
    },
    {
      "x": -1,
      "y": 6,
      "z": 10,
      "name": "Rock_Slate"
    },
    {
      "x": -1,
      "y": 7,
      "z": 10,
      "name": "Rock_Slate"
    },
    {
      "x": -1,
      "y": 8,
      "z": 10,
      "name": "Rock_Slate"
    },
    {
      "x": -1,
      "y": 9,
      "z": 10,
      "name": "Rock_Slate"
    },
    {
      "x": -1,
      "y": 10,
      "z": 10,
      "name": "Rock_Slate"
    },
    {
      "x": -1,
      "y": 11,
      "z": 10,
      "name": "Rock_Slate"
    },
    {
      "x": -1,
      "y": 12,
      "z": 10,
      "name": "Rock_Slate"
    },
    {
      "x": -1,
      "y": 13,
      "z": 10,
      "name": "Rock_Slate"
    },
    {
      "x": -1,
      "y": 15,
      "z": 10,
      "name": "Wood_Burnt_Trunk_Full",
      "rotation": 4
    },
    {
      "x": -1,
      "y": 16,
      "z": 10,
      "name": "Wood_Burnt_Trunk_Full",
      "rotation": 4
    },
    {
      "x": -1,
      "y": 3,
      "z": 11,
      "name": "Rock_Slate"
    },
    {
      "x": -1,
      "y": 4,
      "z": 11,
      "name": "Rock_Slate"
    },
    {
      "x": -1,
      "y": 5,
      "z": 11,
      "name": "Rock_Slate"
    },
    {
      "x": -1,
      "y": 6,
      "z": 11,
      "name": "Rock_Slate"
    },
    {
      "x": -1,
      "y": 7,
      "z": 11,
      "name": "Rock_Slate"
    },
    {
      "x": -1,
      "y": 8,
      "z": 11,
      "name": "Rock_Slate"
    },
    {
      "x": -1,
      "y": 9,
      "z": 11,
      "name": "Rock_Slate"
    },
    {
      "x": -1,
      "y": 10,
      "z": 11,
      "name": "Rock_Slate"
    },
    {
      "x": -1,
      "y": 11,
      "z": 11,
      "name": "Rock_Slate"
    },
    {
      "x": -1,
      "y": 12,
      "z": 11,
      "name": "Rock_Slate"
    },
    {
      "x": -1,
      "y": 13,
      "z": 11,
      "name": "Rock_Slate"
    },
    {
      "x": -1,
      "y": 14,
      "z": 11,
      "name": "Wood_Burnt_Trunk_Full",
      "rotation": 4
    },
    {
      "x": -1,
      "y": 15,
      "z": 11,
      "name": "Wood_Burnt_Trunk_Full",
      "rotation": 4
    },
    {
      "x": -1,
      "y": 3,
      "z": 12,
      "name": "Rock_Slate"
    },
    {
      "x": -1,
      "y": 4,
      "z": 12,
      "name": "Rock_Slate"
    },
    {
      "x": -1,
      "y": 5,
      "z": 12,
      "name": "Rock_Slate"
    },
    {
      "x": -1,
      "y": 6,
      "z": 12,
      "name": "Rock_Slate"
    },
    {
      "x": -1,
      "y": 7,
      "z": 12,
      "name": "Rock_Slate"
    },
    {
      "x": -1,
      "y": 8,
      "z": 12,
      "name": "Rock_Slate"
    },
    {
      "x": -1,
      "y": 9,
      "z": 12,
      "name": "Rock_Slate"
    },
    {
      "x": -1,
      "y": 10,
      "z": 12,
      "name": "Rock_Slate"
    },
    {
      "x": -1,
      "y": 11,
      "z": 12,
      "name": "Rock_Slate"
    },
    {
      "x": -1,
      "y": 12,
      "z": 12,
      "name": "Rock_Slate"
    },
    {
      "x": -1,
      "y": 13,
      "z": 12,
      "name": "Rock_Slate"
    },
    {
      "x": -1,
      "y": 14,
      "z": 12,
      "name": "Wood_Burnt_Trunk_Full",
      "rotation": 4
    },
    {
      "x": -1,
      "y": 15,
      "z": 12,
      "name": "Wood_Burnt_Trunk_Full",
      "rotation": 4
    },
    {
      "x": -1,
      "y": 7,
      "z": 13,
      "name": "Rock_Slate"
    },
    {
      "x": -1,
      "y": 8,
      "z": 13,
      "name": "Rock_Slate"
    },
    {
      "x": -1,
      "y": 9,
      "z": 13,
      "name": "Rock_Slate"
    },
    {
      "x": -1,
      "y": 10,
      "z": 13,
      "name": "Rock_Slate"
    },
    {
      "x": -1,
      "y": 14,
      "z": 13,
      "name": "Wood_Burnt_Trunk_Full",
      "rotation": 4
    },
    {
      "x": 0,
      "y": 22,
      "z": -13,
      "name": "Plant_Leaves_Burnt"
    },
    {
      "x": 0,
      "y": 22,
      "z": -12,
      "name": "Plant_Leaves_Burnt"
    },
    {
      "x": 0,
      "y": 15,
      "z": -11,
      "name": "Rock_Slate"
    },
    {
      "x": 0,
      "y": 16,
      "z": -11,
      "name": "Rock_Slate"
    },
    {
      "x": 0,
      "y": 17,
      "z": -11,
      "name": "Rock_Slate"
    },
    {
      "x": 0,
      "y": 18,
      "z": -11,
      "name": "Rock_Slate"
    },
    {
      "x": 0,
      "y": 19,
      "z": -11,
      "name": "Rock_Slate"
    },
    {
      "x": 0,
      "y": 21,
      "z": -11,
      "name": "Plant_Leaves_Burnt"
    },
    {
      "x": 0,
      "y": 22,
      "z": -11,
      "name": "Plant_Leaves_Burnt"
    },
    {
      "x": 0,
      "y": 2,
      "z": -10,
      "name": "Rock_Slate"
    },
    {
      "x": 0,
      "y": 3,
      "z": -10,
      "name": "Rock_Slate"
    },
    {
      "x": 0,
      "y": 4,
      "z": -10,
      "name": "Rock_Slate"
    },
    {
      "x": 0,
      "y": 5,
      "z": -10,
      "name": "Rock_Slate"
    },
    {
      "x": 0,
      "y": 6,
      "z": -10,
      "name": "Rock_Slate"
    },
    {
      "x": 0,
      "y": 7,
      "z": -10,
      "name": "Rock_Slate"
    },
    {
      "x": 0,
      "y": 8,
      "z": -10,
      "name": "Rock_Slate"
    },
    {
      "x": 0,
      "y": 9,
      "z": -10,
      "name": "Rock_Slate"
    },
    {
      "x": 0,
      "y": 10,
      "z": -10,
      "name": "Rock_Slate"
    },
    {
      "x": 0,
      "y": 11,
      "z": -10,
      "name": "Rock_Slate"
    },
    {
      "x": 0,
      "y": 12,
      "z": -10,
      "name": "Rock_Slate"
    },
    {
      "x": 0,
      "y": 13,
      "z": -10,
      "name": "Rock_Slate"
    },
    {
      "x": 0,
      "y": 14,
      "z": -10,
      "name": "Rock_Slate"
    },
    {
      "x": 0,
      "y": 15,
      "z": -10,
      "name": "Rock_Slate"
    },
    {
      "x": 0,
      "y": 16,
      "z": -10,
      "name": "Rock_Slate"
    },
    {
      "x": 0,
      "y": 17,
      "z": -10,
      "name": "Rock_Slate"
    },
    {
      "x": 0,
      "y": 18,
      "z": -10,
      "name": "Rock_Slate"
    },
    {
      "x": 0,
      "y": 19,
      "z": -10,
      "name": "Rock_Slate"
    },
    {
      "x": 0,
      "y": 21,
      "z": -10,
      "name": "Plant_Leaves_Burnt"
    },
    {
      "x": 0,
      "y": 2,
      "z": -9,
      "name": "Rock_Slate"
    },
    {
      "x": 0,
      "y": 3,
      "z": -9,
      "name": "Rock_Slate"
    },
    {
      "x": 0,
      "y": 4,
      "z": -9,
      "name": "Rock_Slate"
    },
    {
      "x": 0,
      "y": 5,
      "z": -9,
      "name": "Rock_Slate"
    },
    {
      "x": 0,
      "y": 6,
      "z": -9,
      "name": "Rock_Slate"
    },
    {
      "x": 0,
      "y": 7,
      "z": -9,
      "name": "Rock_Slate"
    },
    {
      "x": 0,
      "y": 8,
      "z": -9,
      "name": "Rock_Slate"
    },
    {
      "x": 0,
      "y": 9,
      "z": -9,
      "name": "Rock_Slate"
    },
    {
      "x": 0,
      "y": 10,
      "z": -9,
      "name": "Rock_Slate"
    },
    {
      "x": 0,
      "y": 11,
      "z": -9,
      "name": "Rock_Slate"
    },
    {
      "x": 0,
      "y": 12,
      "z": -9,
      "name": "Rock_Slate"
    },
    {
      "x": 0,
      "y": 13,
      "z": -9,
      "name": "Rock_Slate"
    },
    {
      "x": 0,
      "y": 14,
      "z": -9,
      "name": "Rock_Slate"
    },
    {
      "x": 0,
      "y": 15,
      "z": -9,
      "name": "Rock_Slate"
    },
    {
      "x": 0,
      "y": 16,
      "z": -9,
      "name": "Rock_Slate"
    },
    {
      "x": 0,
      "y": 17,
      "z": -9,
      "name": "Rock_Slate"
    },
    {
      "x": 0,
      "y": 18,
      "z": -9,
      "name": "Rock_Slate"
    },
    {
      "x": 0,
      "y": 19,
      "z": -9,
      "name": "Rock_Slate"
    },
    {
      "x": 0,
      "y": 21,
      "z": -9,
      "name": "Plant_Leaves_Burnt"
    },
    {
      "x": 0,
      "y": 2,
      "z": -8,
      "name": "Rock_Slate"
    },
    {
      "x": 0,
      "y": 3,
      "z": -8,
      "name": "Rock_Slate"
    },
    {
      "x": 0,
      "y": 4,
      "z": -8,
      "name": "Rock_Slate"
    },
    {
      "x": 0,
      "y": 5,
      "z": -8,
      "name": "Rock_Slate"
    },
    {
      "x": 0,
      "y": 6,
      "z": -8,
      "name": "Rock_Slate"
    },
    {
      "x": 0,
      "y": 7,
      "z": -8,
      "name": "Rock_Slate"
    },
    {
      "x": 0,
      "y": 8,
      "z": -8,
      "name": "Rock_Slate"
    },
    {
      "x": 0,
      "y": 9,
      "z": -8,
      "name": "Rock_Slate"
    },
    {
      "x": 0,
      "y": 10,
      "z": -8,
      "name": "Rock_Slate"
    },
    {
      "x": 0,
      "y": 11,
      "z": -8,
      "name": "Rock_Slate"
    },
    {
      "x": 0,
      "y": 12,
      "z": -8,
      "name": "Rock_Slate"
    },
    {
      "x": 0,
      "y": 13,
      "z": -8,
      "name": "Rock_Slate"
    },
    {
      "x": 0,
      "y": 14,
      "z": -8,
      "name": "Rock_Slate"
    },
    {
      "x": 0,
      "y": 15,
      "z": -8,
      "name": "Rock_Slate"
    },
    {
      "x": 0,
      "y": 16,
      "z": -8,
      "name": "Rock_Slate"
    },
    {
      "x": 0,
      "y": 17,
      "z": -8,
      "name": "Rock_Slate"
    },
    {
      "x": 0,
      "y": 18,
      "z": -8,
      "name": "Rock_Slate"
    },
    {
      "x": 0,
      "y": 19,
      "z": -8,
      "name": "Rock_Slate"
    },
    {
      "x": 0,
      "y": 21,
      "z": -8,
      "name": "Wood_Burnt_Trunk",
      "rotation": 5
    },
    {
      "x": 0,
      "y": 2,
      "z": -7,
      "name": "Rock_Slate"
    },
    {
      "x": 0,
      "y": 3,
      "z": -7,
      "name": "Rock_Slate"
    },
    {
      "x": 0,
      "y": 4,
      "z": -7,
      "name": "Rock_Slate"
    },
    {
      "x": 0,
      "y": 5,
      "z": -7,
      "name": "Rock_Slate"
    },
    {
      "x": 0,
      "y": 6,
      "z": -7,
      "name": "Rock_Slate"
    },
    {
      "x": 0,
      "y": 7,
      "z": -7,
      "name": "Rock_Slate"
    },
    {
      "x": 0,
      "y": 8,
      "z": -7,
      "name": "Rock_Slate"
    },
    {
      "x": 0,
      "y": 9,
      "z": -7,
      "name": "Rock_Slate"
    },
    {
      "x": 0,
      "y": 10,
      "z": -7,
      "name": "Rock_Slate"
    },
    {
      "x": 0,
      "y": 11,
      "z": -7,
      "name": "Rock_Slate"
    },
    {
      "x": 0,
      "y": 12,
      "z": -7,
      "name": "Rock_Slate"
    },
    {
      "x": 0,
      "y": 13,
      "z": -7,
      "name": "Rock_Slate"
    },
    {
      "x": 0,
      "y": 14,
      "z": -7,
      "name": "Rock_Slate"
    },
    {
      "x": 0,
      "y": 15,
      "z": -7,
      "name": "Rock_Slate"
    },
    {
      "x": 0,
      "y": 16,
      "z": -7,
      "name": "Rock_Slate"
    },
    {
      "x": 0,
      "y": 17,
      "z": -7,
      "name": "Rock_Slate"
    },
    {
      "x": 0,
      "y": 18,
      "z": -7,
      "name": "Rock_Slate"
    },
    {
      "x": 0,
      "y": 19,
      "z": -7,
      "name": "Rock_Slate"
    },
    {
      "x": 0,
      "y": 2,
      "z": -6,
      "name": "Rock_Slate"
    },
    {
      "x": 0,
      "y": 3,
      "z": -6,
      "name": "Rock_Slate"
    },
    {
      "x": 0,
      "y": 4,
      "z": -6,
      "name": "Rock_Slate"
    },
    {
      "x": 0,
      "y": 5,
      "z": -6,
      "name": "Rock_Slate"
    },
    {
      "x": 0,
      "y": 6,
      "z": -6,
      "name": "Rock_Slate"
    },
    {
      "x": 0,
      "y": 7,
      "z": -6,
      "name": "Rock_Slate"
    },
    {
      "x": 0,
      "y": 8,
      "z": -6,
      "name": "Rock_Slate"
    },
    {
      "x": 0,
      "y": 9,
      "z": -6,
      "name": "Rock_Slate"
    },
    {
      "x": 0,
      "y": 10,
      "z": -6,
      "name": "Rock_Slate"
    },
    {
      "x": 0,
      "y": 11,
      "z": -6,
      "name": "Rock_Slate"
    },
    {
      "x": 0,
      "y": 12,
      "z": -6,
      "name": "Rock_Slate"
    },
    {
      "x": 0,
      "y": 13,
      "z": -6,
      "name": "Rock_Slate"
    },
    {
      "x": 0,
      "y": 14,
      "z": -6,
      "name": "Rock_Slate"
    },
    {
      "x": 0,
      "y": 15,
      "z": -6,
      "name": "Rock_Slate"
    },
    {
      "x": 0,
      "y": 16,
      "z": -6,
      "name": "Rock_Slate"
    },
    {
      "x": 0,
      "y": 17,
      "z": -6,
      "name": "Rock_Slate"
    },
    {
      "x": 0,
      "y": 18,
      "z": -6,
      "name": "Rock_Slate"
    },
    {
      "x": 0,
      "y": 19,
      "z": -6,
      "name": "Rock_Slate"
    },
    {
      "x": 0,
      "y": 20,
      "z": -6,
      "name": "Wood_Burnt_Trunk_Full",
      "rotation": 5
    },
    {
      "x": 0,
      "y": 21,
      "z": -6,
      "name": "Plant_Leaves_Burnt"
    },
    {
      "x": 0,
      "y": 3,
      "z": -5,
      "name": "Rock_Slate"
    },
    {
      "x": 0,
      "y": 4,
      "z": -5,
      "name": "Rock_Slate"
    },
    {
      "x": 0,
      "y": 5,
      "z": -5,
      "name": "Rock_Slate"
    },
    {
      "x": 0,
      "y": 6,
      "z": -5,
      "name": "Rock_Slate"
    },
    {
      "x": 0,
      "y": 7,
      "z": -5,
      "name": "Rock_Slate"
    },
    {
      "x": 0,
      "y": 8,
      "z": -5,
      "name": "Rock_Slate"
    },
    {
      "x": 0,
      "y": 9,
      "z": -5,
      "name": "Rock_Slate"
    },
    {
      "x": 0,
      "y": 10,
      "z": -5,
      "name": "Rock_Slate"
    },
    {
      "x": 0,
      "y": 11,
      "z": -5,
      "name": "Rock_Slate"
    },
    {
      "x": 0,
      "y": 12,
      "z": -5,
      "name": "Rock_Slate"
    },
    {
      "x": 0,
      "y": 13,
      "z": -5,
      "name": "Rock_Slate"
    },
    {
      "x": 0,
      "y": 14,
      "z": -5,
      "name": "Rock_Slate"
    },
    {
      "x": 0,
      "y": 15,
      "z": -5,
      "name": "Rock_Slate"
    },
    {
      "x": 0,
      "y": 16,
      "z": -5,
      "name": "Rock_Slate"
    },
    {
      "x": 0,
      "y": 17,
      "z": -5,
      "name": "Rock_Slate"
    },
    {
      "x": 0,
      "y": 18,
      "z": -5,
      "name": "Rock_Slate"
    },
    {
      "x": 0,
      "y": 19,
      "z": -5,
      "name": "Rock_Slate"
    },
    {
      "x": 0,
      "y": 20,
      "z": -5,
      "name": "Plant_Leaves_Burnt"
    },
    {
      "x": 0,
      "y": 15,
      "z": -4,
      "name": "Rock_Slate"
    },
    {
      "x": 0,
      "y": 16,
      "z": -4,
      "name": "Rock_Slate"
    },
    {
      "x": 0,
      "y": 17,
      "z": -4,
      "name": "Rock_Slate"
    },
    {
      "x": 0,
      "y": 18,
      "z": -4,
      "name": "Rock_Slate"
    },
    {
      "x": 0,
      "y": 19,
      "z": -4,
      "name": "Rock_Slate"
    },
    {
      "x": 0,
      "y": 19,
      "z": -3,
      "name": "Wood_Burnt_Trunk",
      "rotation": 5
    },
    {
      "x": 0,
      "y": 18,
      "z": 1,
      "name": "Wood_Burnt_Trunk",
      "rotation": 5
    },
    {
      "x": 0,
      "y": 14,
      "z": 4,
      "name": "Wood_Burnt_Trunk_Full"
    },
    {
      "x": 0,
      "y": 15,
      "z": 4,
      "name": "Wood_Burnt_Trunk_Full"
    },
    {
      "x": 0,
      "y": 16,
      "z": 4,
      "name": "Wood_Burnt_Trunk_Full",
      "rotation": 4
    },
    {
      "x": 0,
      "y": 16,
      "z": 5,
      "name": "Wood_Burnt_Trunk_Full",
      "rotation": 5
    },
    {
      "x": 0,
      "y": 3,
      "z": 8,
      "name": "Rock_Slate"
    },
    {
      "x": 0,
      "y": 4,
      "z": 8,
      "name": "Rock_Slate"
    },
    {
      "x": 0,
      "y": 11,
      "z": 8,
      "name": "Rock_Slate"
    },
    {
      "x": 0,
      "y": 12,
      "z": 8,
      "name": "Rock_Slate"
    },
    {
      "x": 0,
      "y": 13,
      "z": 8,
      "name": "Rock_Slate"
    },
    {
      "x": 0,
      "y": 3,
      "z": 9,
      "name": "Rock_Slate"
    },
    {
      "x": 0,
      "y": 4,
      "z": 9,
      "name": "Rock_Slate"
    },
    {
      "x": 0,
      "y": 5,
      "z": 9,
      "name": "Rock_Slate"
    },
    {
      "x": 0,
      "y": 6,
      "z": 9,
      "name": "Rock_Slate"
    },
    {
      "x": 0,
      "y": 7,
      "z": 9,
      "name": "Rock_Slate"
    },
    {
      "x": 0,
      "y": 8,
      "z": 9,
      "name": "Rock_Slate"
    },
    {
      "x": 0,
      "y": 9,
      "z": 9,
      "name": "Rock_Slate"
    },
    {
      "x": 0,
      "y": 10,
      "z": 9,
      "name": "Rock_Slate"
    },
    {
      "x": 0,
      "y": 11,
      "z": 9,
      "name": "Rock_Slate"
    },
    {
      "x": 0,
      "y": 12,
      "z": 9,
      "name": "Rock_Slate"
    },
    {
      "x": 0,
      "y": 13,
      "z": 9,
      "name": "Rock_Slate"
    },
    {
      "x": 0,
      "y": 14,
      "z": 9,
      "name": "Rubble_Slate"
    },
    {
      "x": 0,
      "y": 3,
      "z": 10,
      "name": "Rock_Slate"
    },
    {
      "x": 0,
      "y": 4,
      "z": 10,
      "name": "Rock_Slate"
    },
    {
      "x": 0,
      "y": 5,
      "z": 10,
      "name": "Rock_Slate"
    },
    {
      "x": 0,
      "y": 6,
      "z": 10,
      "name": "Rock_Slate"
    },
    {
      "x": 0,
      "y": 7,
      "z": 10,
      "name": "Rock_Slate"
    },
    {
      "x": 0,
      "y": 8,
      "z": 10,
      "name": "Rock_Slate"
    },
    {
      "x": 0,
      "y": 9,
      "z": 10,
      "name": "Rock_Slate"
    },
    {
      "x": 0,
      "y": 10,
      "z": 10,
      "name": "Rock_Slate"
    },
    {
      "x": 0,
      "y": 11,
      "z": 10,
      "name": "Rock_Slate"
    },
    {
      "x": 0,
      "y": 12,
      "z": 10,
      "name": "Rock_Slate"
    },
    {
      "x": 0,
      "y": 13,
      "z": 10,
      "name": "Rock_Slate"
    },
    {
      "x": 0,
      "y": 3,
      "z": 11,
      "name": "Rock_Slate"
    },
    {
      "x": 0,
      "y": 4,
      "z": 11,
      "name": "Rock_Slate"
    },
    {
      "x": 0,
      "y": 5,
      "z": 11,
      "name": "Rock_Slate"
    },
    {
      "x": 0,
      "y": 6,
      "z": 11,
      "name": "Rock_Slate"
    },
    {
      "x": 0,
      "y": 7,
      "z": 11,
      "name": "Rock_Slate"
    },
    {
      "x": 0,
      "y": 8,
      "z": 11,
      "name": "Rock_Slate"
    },
    {
      "x": 0,
      "y": 9,
      "z": 11,
      "name": "Rock_Slate"
    },
    {
      "x": 0,
      "y": 10,
      "z": 11,
      "name": "Rock_Slate"
    },
    {
      "x": 0,
      "y": 11,
      "z": 11,
      "name": "Rock_Slate"
    },
    {
      "x": 0,
      "y": 12,
      "z": 11,
      "name": "Rock_Slate"
    },
    {
      "x": 0,
      "y": 13,
      "z": 11,
      "name": "Rock_Slate"
    },
    {
      "x": 0,
      "y": 14,
      "z": 11,
      "name": "Rock_Slate"
    },
    {
      "x": 0,
      "y": 3,
      "z": 12,
      "name": "Rock_Slate"
    },
    {
      "x": 0,
      "y": 4,
      "z": 12,
      "name": "Rock_Slate"
    },
    {
      "x": 0,
      "y": 5,
      "z": 12,
      "name": "Rock_Slate"
    },
    {
      "x": 0,
      "y": 6,
      "z": 12,
      "name": "Rock_Slate"
    },
    {
      "x": 0,
      "y": 7,
      "z": 12,
      "name": "Rock_Slate"
    },
    {
      "x": 0,
      "y": 8,
      "z": 12,
      "name": "Rock_Slate"
    },
    {
      "x": 0,
      "y": 9,
      "z": 12,
      "name": "Rock_Slate"
    },
    {
      "x": 0,
      "y": 10,
      "z": 12,
      "name": "Rock_Slate"
    },
    {
      "x": 0,
      "y": 11,
      "z": 12,
      "name": "Rock_Slate"
    },
    {
      "x": 0,
      "y": 12,
      "z": 12,
      "name": "Rock_Slate"
    },
    {
      "x": 0,
      "y": 13,
      "z": 12,
      "name": "Rock_Slate"
    },
    {
      "x": 0,
      "y": 14,
      "z": 12,
      "name": "Rock_Slate"
    },
    {
      "x": 0,
      "y": 3,
      "z": 13,
      "name": "Rock_Slate"
    },
    {
      "x": 0,
      "y": 4,
      "z": 13,
      "name": "Rock_Slate"
    },
    {
      "x": 0,
      "y": 7,
      "z": 13,
      "name": "Rock_Slate"
    },
    {
      "x": 0,
      "y": 8,
      "z": 13,
      "name": "Rock_Slate"
    },
    {
      "x": 0,
      "y": 9,
      "z": 13,
      "name": "Rock_Slate"
    },
    {
      "x": 0,
      "y": 10,
      "z": 13,
      "name": "Rock_Slate"
    },
    {
      "x": 0,
      "y": 11,
      "z": 13,
      "name": "Rubble_Slate"
    },
    {
      "x": 1,
      "y": 17,
      "z": -11,
      "name": "Rock_Slate"
    },
    {
      "x": 1,
      "y": 18,
      "z": -11,
      "name": "Rock_Slate"
    },
    {
      "x": 1,
      "y": 19,
      "z": -11,
      "name": "Rock_Slate"
    },
    {
      "x": 1,
      "y": 3,
      "z": -10,
      "name": "Rock_Slate"
    },
    {
      "x": 1,
      "y": 4,
      "z": -10,
      "name": "Rock_Slate"
    },
    {
      "x": 1,
      "y": 5,
      "z": -10,
      "name": "Rock_Slate"
    },
    {
      "x": 1,
      "y": 6,
      "z": -10,
      "name": "Rock_Slate"
    },
    {
      "x": 1,
      "y": 7,
      "z": -10,
      "name": "Rock_Slate"
    },
    {
      "x": 1,
      "y": 8,
      "z": -10,
      "name": "Rock_Slate"
    },
    {
      "x": 1,
      "y": 9,
      "z": -10,
      "name": "Rock_Slate"
    },
    {
      "x": 1,
      "y": 10,
      "z": -10,
      "name": "Rock_Slate"
    },
    {
      "x": 1,
      "y": 11,
      "z": -10,
      "name": "Rock_Slate"
    },
    {
      "x": 1,
      "y": 12,
      "z": -10,
      "name": "Rock_Slate"
    },
    {
      "x": 1,
      "y": 13,
      "z": -10,
      "name": "Rock_Slate"
    },
    {
      "x": 1,
      "y": 14,
      "z": -10,
      "name": "Rock_Slate"
    },
    {
      "x": 1,
      "y": 15,
      "z": -10,
      "name": "Rock_Slate"
    },
    {
      "x": 1,
      "y": 16,
      "z": -10,
      "name": "Rock_Slate"
    },
    {
      "x": 1,
      "y": 17,
      "z": -10,
      "name": "Rock_Slate"
    },
    {
      "x": 1,
      "y": 18,
      "z": -10,
      "name": "Rock_Slate"
    },
    {
      "x": 1,
      "y": 19,
      "z": -10,
      "name": "Rock_Slate"
    },
    {
      "x": 1,
      "y": 20,
      "z": -10,
      "name": "Rock_Slate"
    },
    {
      "x": 1,
      "y": 3,
      "z": -9,
      "name": "Rock_Slate"
    },
    {
      "x": 1,
      "y": 4,
      "z": -9,
      "name": "Rock_Slate"
    },
    {
      "x": 1,
      "y": 5,
      "z": -9,
      "name": "Rock_Slate"
    },
    {
      "x": 1,
      "y": 6,
      "z": -9,
      "name": "Rock_Slate"
    },
    {
      "x": 1,
      "y": 7,
      "z": -9,
      "name": "Rock_Slate"
    },
    {
      "x": 1,
      "y": 8,
      "z": -9,
      "name": "Rock_Slate"
    },
    {
      "x": 1,
      "y": 9,
      "z": -9,
      "name": "Rock_Slate"
    },
    {
      "x": 1,
      "y": 10,
      "z": -9,
      "name": "Rock_Slate"
    },
    {
      "x": 1,
      "y": 11,
      "z": -9,
      "name": "Rock_Slate"
    },
    {
      "x": 1,
      "y": 12,
      "z": -9,
      "name": "Rock_Slate"
    },
    {
      "x": 1,
      "y": 13,
      "z": -9,
      "name": "Rock_Slate"
    },
    {
      "x": 1,
      "y": 14,
      "z": -9,
      "name": "Rock_Slate"
    },
    {
      "x": 1,
      "y": 15,
      "z": -9,
      "name": "Rock_Slate"
    },
    {
      "x": 1,
      "y": 16,
      "z": -9,
      "name": "Rock_Slate"
    },
    {
      "x": 1,
      "y": 17,
      "z": -9,
      "name": "Rock_Slate"
    },
    {
      "x": 1,
      "y": 18,
      "z": -9,
      "name": "Rock_Slate"
    },
    {
      "x": 1,
      "y": 19,
      "z": -9,
      "name": "Rock_Slate"
    },
    {
      "x": 1,
      "y": 20,
      "z": -9,
      "name": "Rock_Slate"
    },
    {
      "x": 1,
      "y": 3,
      "z": -8,
      "name": "Rock_Slate"
    },
    {
      "x": 1,
      "y": 4,
      "z": -8,
      "name": "Rock_Slate"
    },
    {
      "x": 1,
      "y": 5,
      "z": -8,
      "name": "Rock_Slate"
    },
    {
      "x": 1,
      "y": 6,
      "z": -8,
      "name": "Rock_Slate"
    },
    {
      "x": 1,
      "y": 7,
      "z": -8,
      "name": "Rock_Slate"
    },
    {
      "x": 1,
      "y": 8,
      "z": -8,
      "name": "Rock_Slate"
    },
    {
      "x": 1,
      "y": 9,
      "z": -8,
      "name": "Rock_Slate"
    },
    {
      "x": 1,
      "y": 10,
      "z": -8,
      "name": "Rock_Slate"
    },
    {
      "x": 1,
      "y": 11,
      "z": -8,
      "name": "Rock_Slate"
    },
    {
      "x": 1,
      "y": 12,
      "z": -8,
      "name": "Rock_Slate"
    },
    {
      "x": 1,
      "y": 13,
      "z": -8,
      "name": "Rock_Slate"
    },
    {
      "x": 1,
      "y": 14,
      "z": -8,
      "name": "Rock_Slate"
    },
    {
      "x": 1,
      "y": 15,
      "z": -8,
      "name": "Rock_Slate"
    },
    {
      "x": 1,
      "y": 16,
      "z": -8,
      "name": "Rock_Slate"
    },
    {
      "x": 1,
      "y": 17,
      "z": -8,
      "name": "Rock_Slate"
    },
    {
      "x": 1,
      "y": 18,
      "z": -8,
      "name": "Rock_Slate"
    },
    {
      "x": 1,
      "y": 19,
      "z": -8,
      "name": "Rock_Slate"
    },
    {
      "x": 1,
      "y": 20,
      "z": -8,
      "name": "Rock_Slate"
    },
    {
      "x": 1,
      "y": 3,
      "z": -7,
      "name": "Rock_Slate"
    },
    {
      "x": 1,
      "y": 4,
      "z": -7,
      "name": "Rock_Slate"
    },
    {
      "x": 1,
      "y": 5,
      "z": -7,
      "name": "Rock_Slate"
    },
    {
      "x": 1,
      "y": 6,
      "z": -7,
      "name": "Rock_Slate"
    },
    {
      "x": 1,
      "y": 7,
      "z": -7,
      "name": "Rock_Slate"
    },
    {
      "x": 1,
      "y": 8,
      "z": -7,
      "name": "Rock_Slate"
    },
    {
      "x": 1,
      "y": 9,
      "z": -7,
      "name": "Rock_Slate"
    },
    {
      "x": 1,
      "y": 10,
      "z": -7,
      "name": "Rock_Slate"
    },
    {
      "x": 1,
      "y": 11,
      "z": -7,
      "name": "Rock_Slate"
    },
    {
      "x": 1,
      "y": 12,
      "z": -7,
      "name": "Rock_Slate"
    },
    {
      "x": 1,
      "y": 13,
      "z": -7,
      "name": "Rock_Slate"
    },
    {
      "x": 1,
      "y": 14,
      "z": -7,
      "name": "Rock_Slate"
    },
    {
      "x": 1,
      "y": 15,
      "z": -7,
      "name": "Rock_Slate"
    },
    {
      "x": 1,
      "y": 16,
      "z": -7,
      "name": "Rock_Slate"
    },
    {
      "x": 1,
      "y": 17,
      "z": -7,
      "name": "Rock_Slate"
    },
    {
      "x": 1,
      "y": 18,
      "z": -7,
      "name": "Rock_Slate"
    },
    {
      "x": 1,
      "y": 19,
      "z": -7,
      "name": "Rock_Slate"
    },
    {
      "x": 1,
      "y": 20,
      "z": -7,
      "name": "Plant_Leaves_Burnt"
    },
    {
      "x": 1,
      "y": 3,
      "z": -6,
      "name": "Rock_Slate"
    },
    {
      "x": 1,
      "y": 4,
      "z": -6,
      "name": "Rock_Slate"
    },
    {
      "x": 1,
      "y": 5,
      "z": -6,
      "name": "Rock_Slate"
    },
    {
      "x": 1,
      "y": 6,
      "z": -6,
      "name": "Rock_Slate"
    },
    {
      "x": 1,
      "y": 7,
      "z": -6,
      "name": "Rock_Slate"
    },
    {
      "x": 1,
      "y": 8,
      "z": -6,
      "name": "Rock_Slate"
    },
    {
      "x": 1,
      "y": 9,
      "z": -6,
      "name": "Rock_Slate"
    },
    {
      "x": 1,
      "y": 10,
      "z": -6,
      "name": "Rock_Slate"
    },
    {
      "x": 1,
      "y": 11,
      "z": -6,
      "name": "Rock_Slate"
    },
    {
      "x": 1,
      "y": 12,
      "z": -6,
      "name": "Rock_Slate"
    },
    {
      "x": 1,
      "y": 13,
      "z": -6,
      "name": "Rock_Slate"
    },
    {
      "x": 1,
      "y": 14,
      "z": -6,
      "name": "Rock_Slate"
    },
    {
      "x": 1,
      "y": 15,
      "z": -6,
      "name": "Rock_Slate"
    },
    {
      "x": 1,
      "y": 16,
      "z": -6,
      "name": "Rock_Slate"
    },
    {
      "x": 1,
      "y": 17,
      "z": -6,
      "name": "Rock_Slate"
    },
    {
      "x": 1,
      "y": 18,
      "z": -6,
      "name": "Rock_Slate"
    },
    {
      "x": 1,
      "y": 19,
      "z": -6,
      "name": "Rock_Slate"
    },
    {
      "x": 1,
      "y": 20,
      "z": -6,
      "name": "Wood_Burnt_Branch_Long",
      "rotation": 5
    },
    {
      "x": 1,
      "y": 21,
      "z": -6,
      "name": "Plant_Leaves_Burnt"
    },
    {
      "x": 1,
      "y": 14,
      "z": -5,
      "name": "Rock_Slate"
    },
    {
      "x": 1,
      "y": 15,
      "z": -5,
      "name": "Rock_Slate"
    },
    {
      "x": 1,
      "y": 16,
      "z": -5,
      "name": "Rock_Slate"
    },
    {
      "x": 1,
      "y": 17,
      "z": -5,
      "name": "Rock_Slate"
    },
    {
      "x": 1,
      "y": 18,
      "z": -5,
      "name": "Rock_Slate"
    },
    {
      "x": 1,
      "y": 19,
      "z": -5,
      "name": "Rock_Slate"
    },
    {
      "x": 1,
      "y": 20,
      "z": -5,
      "name": "Plant_Leaves_Burnt"
    },
    {
      "x": 1,
      "y": 18,
      "z": -3,
      "name": "Wood_Burnt_Branch_Long"
    },
    {
      "x": 1,
      "y": 19,
      "z": -3,
      "name": "Wood_Burnt_Trunk",
      "rotation": 5
    },
    {
      "x": 1,
      "y": 18,
      "z": 1,
      "name": "Wood_Burnt_Trunk_Full",
      "rotation": 5
    },
    {
      "x": 1,
      "y": 18,
      "z": 2,
      "name": "Wood_Burnt_Trunk_Full"
    },
    {
      "x": 1,
      "y": 12,
      "z": 4,
      "name": "Wood_Burnt_Roots"
    },
    {
      "x": 1,
      "y": 13,
      "z": 4,
      "name": "Wood_Burnt_Trunk_Full"
    },
    {
      "x": 1,
      "y": 14,
      "z": 4,
      "name": "Wood_Burnt_Trunk_Full",
      "rotation": 5
    },
    {
      "x": 1,
      "y": 16,
      "z": 5,
      "name": "Wood_Burnt_Trunk_Full",
      "rotation": 5
    },
    {
      "x": 1,
      "y": 14,
      "z": 6,
      "name": "Wood_Burnt_Trunk_Full"
    },
    {
      "x": 1,
      "y": 15,
      "z": 6,
      "name": "Wood_Burnt_Trunk_Full"
    },
    {
      "x": 1,
      "y": 16,
      "z": 6,
      "name": "Wood_Burnt_Trunk_Full",
      "rotation": 4
    },
    {
      "x": 1,
      "y": 11,
      "z": 7,
      "name": "Wood_Burnt_Roots"
    },
    {
      "x": 1,
      "y": 12,
      "z": 7,
      "name": "Wood_Burnt_Trunk_Full"
    },
    {
      "x": 1,
      "y": 13,
      "z": 7,
      "name": "Wood_Burnt_Trunk_Full"
    },
    {
      "x": 1,
      "y": 14,
      "z": 7,
      "name": "Wood_Burnt_Trunk_Full",
      "rotation": 4
    },
    {
      "x": 1,
      "y": 3,
      "z": 9,
      "name": "Rock_Slate"
    },
    {
      "x": 1,
      "y": 4,
      "z": 9,
      "name": "Rock_Slate"
    },
    {
      "x": 1,
      "y": 7,
      "z": 9,
      "name": "Rock_Slate"
    },
    {
      "x": 1,
      "y": 8,
      "z": 9,
      "name": "Rock_Slate"
    },
    {
      "x": 1,
      "y": 9,
      "z": 9,
      "name": "Rock_Slate"
    },
    {
      "x": 1,
      "y": 10,
      "z": 9,
      "name": "Rock_Slate"
    },
    {
      "x": 1,
      "y": 11,
      "z": 9,
      "name": "Rock_Slate"
    },
    {
      "x": 1,
      "y": 12,
      "z": 9,
      "name": "Rock_Slate"
    },
    {
      "x": 1,
      "y": 13,
      "z": 9,
      "name": "Rock_Slate"
    },
    {
      "x": 1,
      "y": 3,
      "z": 10,
      "name": "Rock_Slate"
    },
    {
      "x": 1,
      "y": 4,
      "z": 10,
      "name": "Rock_Slate"
    },
    {
      "x": 1,
      "y": 5,
      "z": 10,
      "name": "Rock_Slate"
    },
    {
      "x": 1,
      "y": 7,
      "z": 10,
      "name": "Rock_Slate"
    },
    {
      "x": 1,
      "y": 8,
      "z": 10,
      "name": "Rock_Slate"
    },
    {
      "x": 1,
      "y": 9,
      "z": 10,
      "name": "Rock_Slate"
    },
    {
      "x": 1,
      "y": 10,
      "z": 10,
      "name": "Rock_Slate"
    },
    {
      "x": 1,
      "y": 11,
      "z": 10,
      "name": "Rock_Slate"
    },
    {
      "x": 1,
      "y": 12,
      "z": 10,
      "name": "Rock_Slate"
    },
    {
      "x": 1,
      "y": 13,
      "z": 10,
      "name": "Rock_Slate"
    },
    {
      "x": 1,
      "y": 3,
      "z": 11,
      "name": "Rock_Slate"
    },
    {
      "x": 1,
      "y": 4,
      "z": 11,
      "name": "Rock_Slate"
    },
    {
      "x": 1,
      "y": 5,
      "z": 11,
      "name": "Rock_Slate"
    },
    {
      "x": 1,
      "y": 7,
      "z": 11,
      "name": "Rock_Slate"
    },
    {
      "x": 1,
      "y": 8,
      "z": 11,
      "name": "Rock_Slate"
    },
    {
      "x": 1,
      "y": 9,
      "z": 11,
      "name": "Rock_Slate"
    },
    {
      "x": 1,
      "y": 10,
      "z": 11,
      "name": "Rock_Slate"
    },
    {
      "x": 1,
      "y": 11,
      "z": 11,
      "name": "Rock_Slate"
    },
    {
      "x": 1,
      "y": 12,
      "z": 11,
      "name": "Rock_Slate"
    },
    {
      "x": 1,
      "y": 13,
      "z": 11,
      "name": "Rock_Slate"
    },
    {
      "x": 1,
      "y": 14,
      "z": 11,
      "name": "Rock_Slate"
    },
    {
      "x": 1,
      "y": 15,
      "z": 11,
      "name": "Rubble_Slate"
    },
    {
      "x": 1,
      "y": 3,
      "z": 12,
      "name": "Rock_Slate"
    },
    {
      "x": 1,
      "y": 4,
      "z": 12,
      "name": "Rock_Slate"
    },
    {
      "x": 1,
      "y": 5,
      "z": 12,
      "name": "Rock_Slate"
    },
    {
      "x": 1,
      "y": 8,
      "z": 12,
      "name": "Rock_Slate"
    },
    {
      "x": 1,
      "y": 9,
      "z": 12,
      "name": "Rock_Slate"
    },
    {
      "x": 1,
      "y": 10,
      "z": 12,
      "name": "Rock_Slate"
    },
    {
      "x": 1,
      "y": 11,
      "z": 12,
      "name": "Rock_Slate"
    },
    {
      "x": 1,
      "y": 12,
      "z": 12,
      "name": "Rock_Slate"
    },
    {
      "x": 1,
      "y": 13,
      "z": 12,
      "name": "Rock_Slate"
    },
    {
      "x": 1,
      "y": 14,
      "z": 12,
      "name": "Rock_Slate"
    },
    {
      "x": 2,
      "y": 15,
      "z": -10,
      "name": "Rock_Slate"
    },
    {
      "x": 2,
      "y": 16,
      "z": -10,
      "name": "Rock_Slate"
    },
    {
      "x": 2,
      "y": 17,
      "z": -10,
      "name": "Rock_Slate"
    },
    {
      "x": 2,
      "y": 18,
      "z": -10,
      "name": "Rock_Slate"
    },
    {
      "x": 2,
      "y": 19,
      "z": -10,
      "name": "Rock_Slate"
    },
    {
      "x": 2,
      "y": 20,
      "z": -10,
      "name": "Rock_Slate"
    },
    {
      "x": 2,
      "y": 21,
      "z": -10,
      "name": "Rubble_Slate"
    },
    {
      "x": 2,
      "y": 14,
      "z": -9,
      "name": "Rock_Slate"
    },
    {
      "x": 2,
      "y": 15,
      "z": -9,
      "name": "Rock_Slate"
    },
    {
      "x": 2,
      "y": 16,
      "z": -9,
      "name": "Rock_Slate"
    },
    {
      "x": 2,
      "y": 17,
      "z": -9,
      "name": "Rock_Slate"
    },
    {
      "x": 2,
      "y": 18,
      "z": -9,
      "name": "Rock_Slate"
    },
    {
      "x": 2,
      "y": 19,
      "z": -9,
      "name": "Rock_Slate"
    },
    {
      "x": 2,
      "y": 20,
      "z": -9,
      "name": "Rock_Slate"
    },
    {
      "x": 2,
      "y": 17,
      "z": -8,
      "name": "Rock_Slate"
    },
    {
      "x": 2,
      "y": 18,
      "z": -8,
      "name": "Rock_Slate"
    },
    {
      "x": 2,
      "y": 19,
      "z": -8,
      "name": "Rock_Slate"
    },
    {
      "x": 2,
      "y": 20,
      "z": -8,
      "name": "Rock_Slate"
    },
    {
      "x": 2,
      "y": 20,
      "z": -6,
      "name": "Plant_Leaves_Burnt"
    },
    {
      "x": 2,
      "y": 19,
      "z": -3,
      "name": "Wood_Burnt_Branch_Long",
      "rotation": 5
    },
    {
      "x": 2,
      "y": 18,
      "z": 1,
      "name": "Wood_Burnt_Branch_Short",
      "rotation": 1
    }
  ]
}