{
  "version": 8,
  "blockIdVersion": 8,
  "anchorX": 0,
  "anchorY": 8,
  "anchorZ": 0,
  "blocks": [
    {
      "x": -17,
      "y": 35,
      "z": -7,
      "name": "Rock_Chalk"
    },
    {
      "x": -17,
      "y": 36,
      "z": -7,
      "name": "Rock_Chalk"
    },
    {
      "x": -17,
      "y": 37,
      "z": -7,
      "name": "Rock_Chalk"
    },
    {
      "x": -16,
      "y": 34,
      "z": -8,
      "name": "Rock_Chalk"
    },
    {
      "x": -16,
      "y": 35,
      "z": -8,
      "name": "Rock_Chalk"
    },
    {
      "x": -16,
      "y": 36,
      "z": -8,
      "name": "Rock_Chalk"
    },
    {
      "x": -16,
      "y": 37,
      "z": -8,
      "name": "Rock_Chalk"
    },
    {
      "x": -16,
      "y": 38,
      "z": -8,
      "name": "Rock_Chalk"
    },
    {
      "x": -16,
      "y": 39,
      "z": -8,
      "name": "Rock_Chalk"
    },
    {
      "x": -16,
      "y": 32,
      "z": -7,
      "name": "Rock_Chalk"
    },
    {
      "x": -16,
      "y": 33,
      "z": -7,
      "name": "Rock_Chalk"
    },
    {
      "x": -16,
      "y": 34,
      "z": -7,
      "name": "Rock_Chalk"
    },
    {
      "x": -16,
      "y": 35,
      "z": -7,
      "name": "Rock_Chalk"
    },
    {
      "x": -16,
      "y": 36,
      "z": -7,
      "name": "Rock_Chalk"
    },
    {
      "x": -16,
      "y": 37,
      "z": -7,
      "name": "Rock_Chalk"
    },
    {
      "x": -16,
      "y": 38,
      "z": -7,
      "name": "Rock_Chalk"
    },
    {
      "x": -16,
      "y": 39,
      "z": -7,
      "name": "Rock_Chalk"
    },
    {
      "x": -16,
      "y": 40,
      "z": -7,
      "name": "Rock_Chalk"
    },
    {
      "x": -16,
      "y": 32,
      "z": -6,
      "name": "Rock_Chalk"
    },
    {
      "x": -16,
      "y": 33,
      "z": -6,
      "name": "Rock_Chalk"
    },
    {
      "x": -16,
      "y": 34,
      "z": -6,
      "name": "Rock_Chalk"
    },
    {
      "x": -16,
      "y": 35,
      "z": -6,
      "name": "Rock_Chalk"
    },
    {
      "x": -16,
      "y": 36,
      "z": -6,
      "name": "Rock_Chalk"
    },
    {
      "x": -16,
      "y": 37,
      "z": -6,
      "name": "Rock_Chalk"
    },
    {
      "x": -16,
      "y": 38,
      "z": -6,
      "name": "Rock_Chalk"
    },
    {
      "x": -15,
      "y": 34,
      "z": -10,
      "name": "Rock_Chalk"
    },
    {
      "x": -15,
      "y": 35,
      "z": -10,
      "name": "Rock_Chalk"
    },
    {
      "x": -15,
      "y": 36,
      "z": -10,
      "name": "Rock_Chalk"
    },
    {
      "x": -15,
      "y": 37,
      "z": -10,
      "name": "Rock_Chalk"
    },
    {
      "x": -15,
      "y": 38,
      "z": -10,
      "name": "Rock_Chalk"
    },
    {
      "x": -15,
      "y": 39,
      "z": -10,
      "name": "Rock_Chalk"
    },
    {
      "x": -15,
      "y": 14,
      "z": -9,
      "name": "Rock_Marble"
    },
    {
      "x": -15,
      "y": 15,
      "z": -9,
      "name": "Rock_Marble"
    },
    {
      "x": -15,
      "y": 16,
      "z": -9,
      "name": "Rock_Marble"
    },
    {
      "x": -15,
      "y": 17,
      "z": -9,
      "name": "Rock_Marble"
    },
    {
      "x": -15,
      "y": 18,
      "z": -9,
      "name": "Rock_Chalk"
    },
    {
      "x": -15,
      "y": 19,
      "z": -9,
      "name": "Rock_Chalk"
    },
    {
      "x": -15,
      "y": 20,
      "z": -9,
      "name": "Rock_Chalk"
    },
    {
      "x": -15,
      "y": 21,
      "z": -9,
      "name": "Rock_Chalk"
    },
    {
      "x": -15,
      "y": 22,
      "z": -9,
      "name": "Rock_Chalk"
    },
    {
      "x": -15,
      "y": 23,
      "z": -9,
      "name": "Rock_Chalk"
    },
    {
      "x": -15,
      "y": 24,
      "z": -9,
      "name": "Rock_Chalk"
    },
    {
      "x": -15,
      "y": 25,
      "z": -9,
      "name": "Rock_Chalk"
    },
    {
      "x": -15,
      "y": 26,
      "z": -9,
      "name": "Rock_Chalk"
    },
    {
      "x": -15,
      "y": 27,
      "z": -9,
      "name": "Rock_Chalk"
    },
    {
      "x": -15,
      "y": 28,
      "z": -9,
      "name": "Rock_Chalk"
    },
    {
      "x": -15,
      "y": 29,
      "z": -9,
      "name": "Rock_Chalk"
    },
    {
      "x": -15,
      "y": 30,
      "z": -9,
      "name": "Rock_Chalk"
    },
    {
      "x": -15,
      "y": 31,
      "z": -9,
      "name": "Rock_Chalk"
    },
    {
      "x": -15,
      "y": 32,
      "z": -9,
      "name": "Rock_Chalk"
    },
    {
      "x": -15,
      "y": 33,
      "z": -9,
      "name": "Rock_Chalk"
    },
    {
      "x": -15,
      "y": 34,
      "z": -9,
      "name": "Rock_Chalk"
    },
    {
      "x": -15,
      "y": 35,
      "z": -9,
      "name": "Rock_Chalk"
    },
    {
      "x": -15,
      "y": 36,
      "z": -9,
      "name": "Rock_Chalk"
    },
    {
      "x": -15,
      "y": 37,
      "z": -9,
      "name": "Rock_Chalk"
    },
    {
      "x": -15,
      "y": 38,
      "z": -9,
      "name": "Rock_Chalk"
    },
    {
      "x": -15,
      "y": 39,
      "z": -9,
      "name": "Rock_Chalk"
    },
    {
      "x": -15,
      "y": 40,
      "z": -9,
      "name": "Rock_Chalk"
    },
    {
      "x": -15,
      "y": 41,
      "z": -9,
      "name": "Rock_Chalk"
    },
    {
      "x": -15,
      "y": 42,
      "z": -9,
      "name": "Rock_Chalk"
    },
    {
      "x": -15,
      "y": 43,
      "z": -9,
      "name": "Rock_Chalk"
    },
    {
      "x": -15,
      "y": 44,
      "z": -9,
      "name": "Rock_Marble"
    },
    {
      "x": -15,
      "y": 13,
      "z": -8,
      "name": "Rock_Marble"
    },
    {
      "x": -15,
      "y": 14,
      "z": -8,
      "name": "Rock_Marble"
    },
    {
      "x": -15,
      "y": 15,
      "z": -8,
      "name": "Rock_Marble"
    },
    {
      "x": -15,
      "y": 16,
      "z": -8,
      "name": "Rock_Marble"
    },
    {
      "x": -15,
      "y": 17,
      "z": -8,
      "name": "Rock_Chalk"
    },
    {
      "x": -15,
      "y": 18,
      "z": -8,
      "name": "Rock_Chalk"
    },
    {
      "x": -15,
      "y": 19,
      "z": -8,
      "name": "Rock_Chalk"
    },
    {
      "x": -15,
      "y": 20,
      "z": -8,
      "name": "Rock_Chalk"
    },
    {
      "x": -15,
      "y": 21,
      "z": -8,
      "name": "Rock_Chalk"
    },
    {
      "x": -15,
      "y": 22,
      "z": -8,
      "name": "Rock_Chalk"
    },
    {
      "x": -15,
      "y": 23,
      "z": -8,
      "name": "Rock_Chalk"
    },
    {
      "x": -15,
      "y": 24,
      "z": -8,
      "name": "Rock_Chalk"
    },
    {
      "x": -15,
      "y": 25,
      "z": -8,
      "name": "Rock_Chalk"
    },
    {
      "x": -15,
      "y": 26,
      "z": -8,
      "name": "Rock_Chalk"
    },
    {
      "x": -15,
      "y": 27,
      "z": -8,
      "name": "Rock_Chalk"
    },
    {
      "x": -15,
      "y": 28,
      "z": -8,
      "name": "Rock_Chalk"
    },
    {
      "x": -15,
      "y": 29,
      "z": -8,
      "name": "Rock_Chalk"
    },
    {
      "x": -15,
      "y": 30,
      "z": -8,
      "name": "Rock_Chalk"
    },
    {
      "x": -15,
      "y": 31,
      "z": -8,
      "name": "Rock_Chalk"
    },
    {
      "x": -15,
      "y": 32,
      "z": -8,
      "name": "Rock_Chalk"
    },
    {
      "x": -15,
      "y": 33,
      "z": -8,
      "name": "Rock_Chalk"
    },
    {
      "x": -15,
      "y": 34,
      "z": -8,
      "name": "Rock_Chalk"
    },
    {
      "x": -15,
      "y": 35,
      "z": -8,
      "name": "Rock_Chalk"
    },
    {
      "x": -15,
      "y": 36,
      "z": -8,
      "name": "Rock_Chalk"
    },
    {
      "x": -15,
      "y": 37,
      "z": -8,
      "name": "Rock_Chalk"
    },
    {
      "x": -15,
      "y": 38,
      "z": -8,
      "name": "Rock_Chalk"
    },
    {
      "x": -15,
      "y": 39,
      "z": -8,
      "name": "Rock_Chalk"
    },
    {
      "x": -15,
      "y": 40,
      "z": -8,
      "name": "Rock_Chalk"
    },
    {
      "x": -15,
      "y": 41,
      "z": -8,
      "name": "Rock_Chalk"
    },
    {
      "x": -15,
      "y": 42,
      "z": -8,
      "name": "Rock_Chalk"
    },
    {
      "x": -15,
      "y": 43,
      "z": -8,
      "name": "Rock_Marble"
    },
    {
      "x": -15,
      "y": 44,
      "z": -8,
      "name": "Rock_Marble"
    },
    {
      "x": -15,
      "y": 45,
      "z": -8,
      "name": "Rock_Marble"
    },
    {
      "x": -15,
      "y": 46,
      "z": -8,
      "name": "Rock_Marble"
    },
    {
      "x": -15,
      "y": 47,
      "z": -8,
      "name": "Rock_Marble"
    },
    {
      "x": -15,
      "y": 48,
      "z": -8,
      "name": "Rock_Marble"
    },
    {
      "x": -15,
      "y": 12,
      "z": -7,
      "name": "Rock_Marble"
    },
    {
      "x": -15,
      "y": 13,
      "z": -7,
      "name": "Rock_Marble"
    },
    {
      "x": -15,
      "y": 14,
      "z": -7,
      "name": "Rock_Marble"
    },
    {
      "x": -15,
      "y": 15,
      "z": -7,
      "name": "Rock_Marble"
    },
    {
      "x": -15,
      "y": 16,
      "z": -7,
      "name": "Rock_Marble"
    },
    {
      "x": -15,
      "y": 17,
      "z": -7,
      "name": "Rock_Chalk"
    },
    {
      "x": -15,
      "y": 18,
      "z": -7,
      "name": "Rock_Chalk"
    },
    {
      "x": -15,
      "y": 19,
      "z": -7,
      "name": "Rock_Chalk"
    },
    {
      "x": -15,
      "y": 20,
      "z": -7,
      "name": "Rock_Chalk"
    },
    {
      "x": -15,
      "y": 21,
      "z": -7,
      "name": "Rock_Chalk"
    },
    {
      "x": -15,
      "y": 22,
      "z": -7,
      "name": "Rock_Chalk"
    },
    {
      "x": -15,
      "y": 23,
      "z": -7,
      "name": "Rock_Chalk"
    },
    {
      "x": -15,
      "y": 24,
      "z": -7,
      "name": "Rock_Chalk"
    },
    {
      "x": -15,
      "y": 25,
      "z": -7,
      "name": "Rock_Chalk"
    },
    {
      "x": -15,
      "y": 26,
      "z": -7,
      "name": "Rock_Chalk"
    },
    {
      "x": -15,
      "y": 27,
      "z": -7,
      "name": "Rock_Chalk"
    },
    {
      "x": -15,
      "y": 28,
      "z": -7,
      "name": "Rock_Chalk"
    },
    {
      "x": -15,
      "y": 29,
      "z": -7,
      "name": "Rock_Chalk"
    },
    {
      "x": -15,
      "y": 30,
      "z": -7,
      "name": "Rock_Chalk"
    },
    {
      "x": -15,
      "y": 31,
      "z": -7,
      "name": "Rock_Chalk"
    },
    {
      "x": -15,
      "y": 32,
      "z": -7,
      "name": "Rock_Chalk"
    },
    {
      "x": -15,
      "y": 33,
      "z": -7,
      "name": "Rock_Chalk"
    },
    {
      "x": -15,
      "y": 34,
      "z": -7,
      "name": "Rock_Chalk"
    },
    {
      "x": -15,
      "y": 35,
      "z": -7,
      "name": "Rock_Chalk"
    },
    {
      "x": -15,
      "y": 36,
      "z": -7,
      "name": "Rock_Chalk"
    },
    {
      "x": -15,
      "y": 37,
      "z": -7,
      "name": "Rock_Chalk"
    },
    {
      "x": -15,
      "y": 38,
      "z": -7,
      "name": "Rock_Chalk"
    },
    {
      "x": -15,
      "y": 39,
      "z": -7,
      "name": "Rock_Chalk"
    },
    {
      "x": -15,
      "y": 40,
      "z": -7,
      "name": "Rock_Chalk"
    },
    {
      "x": -15,
      "y": 41,
      "z": -7,
      "name": "Rock_Chalk"
    },
    {
      "x": -15,
      "y": 42,
      "z": -7,
      "name": "Rock_Chalk"
    },
    {
      "x": -15,
      "y": 43,
      "z": -7,
      "name": "Rock_Marble"
    },
    {
      "x": -15,
      "y": 44,
      "z": -7,
      "name": "Rock_Marble"
    },
    {
      "x": -15,
      "y": 45,
      "z": -7,
      "name": "Rock_Marble"
    },
    {
      "x": -15,
      "y": 46,
      "z": -7,
      "name": "Rock_Marble"
    },
    {
      "x": -15,
      "y": 47,
      "z": -7,
      "name": "Rock_Marble"
    },
    {
      "x": -15,
      "y": 12,
      "z": -6,
      "name": "Rock_Marble"
    },
    {
      "x": -15,
      "y": 13,
      "z": -6,
      "name": "Rock_Marble"
    },
    {
      "x": -15,
      "y": 14,
      "z": -6,
      "name": "Rock_Marble"
    },
    {
      "x": -15,
      "y": 15,
      "z": -6,
      "name": "Rock_Marble"
    },
    {
      "x": -15,
      "y": 16,
      "z": -6,
      "name": "Rock_Chalk"
    },
    {
      "x": -15,
      "y": 17,
      "z": -6,
      "name": "Rock_Chalk"
    },
    {
      "x": -15,
      "y": 18,
      "z": -6,
      "name": "Rock_Chalk"
    },
    {
      "x": -15,
      "y": 19,
      "z": -6,
      "name": "Rock_Chalk"
    },
    {
      "x": -15,
      "y": 20,
      "z": -6,
      "name": "Rock_Chalk"
    },
    {
      "x": -15,
      "y": 21,
      "z": -6,
      "name": "Rock_Chalk"
    },
    {
      "x": -15,
      "y": 22,
      "z": -6,
      "name": "Rock_Chalk"
    },
    {
      "x": -15,
      "y": 23,
      "z": -6,
      "name": "Rock_Chalk"
    },
    {
      "x": -15,
      "y": 24,
      "z": -6,
      "name": "Rock_Chalk"
    },
    {
      "x": -15,
      "y": 25,
      "z": -6,
      "name": "Rock_Chalk"
    },
    {
      "x": -15,
      "y": 26,
      "z": -6,
      "name": "Rock_Chalk"
    },
    {
      "x": -15,
      "y": 27,
      "z": -6,
      "name": "Rock_Chalk"
    },
    {
      "x": -15,
      "y": 28,
      "z": -6,
      "name": "Rock_Chalk"
    },
    {
      "x": -15,
      "y": 29,
      "z": -6,
      "name": "Rock_Chalk"
    },
    {
      "x": -15,
      "y": 30,
      "z": -6,
      "name": "Rock_Chalk"
    },
    {
      "x": -15,
      "y": 31,
      "z": -6,
      "name": "Rock_Chalk"
    },
    {
      "x": -15,
      "y": 32,
      "z": -6,
      "name": "Rock_Chalk"
    },
    {
      "x": -15,
      "y": 33,
      "z": -6,
      "name": "Rock_Chalk"
    },
    {
      "x": -15,
      "y": 34,
      "z": -6,
      "name": "Rock_Chalk"
    },
    {
      "x": -15,
      "y": 35,
      "z": -6,
      "name": "Rock_Chalk"
    },
    {
      "x": -15,
      "y": 36,
      "z": -6,
      "name": "Rock_Chalk"
    },
    {
      "x": -15,
      "y": 37,
      "z": -6,
      "name": "Rock_Chalk"
    },
    {
      "x": -15,
      "y": 38,
      "z": -6,
      "name": "Rock_Chalk"
    },
    {
      "x": -15,
      "y": 39,
      "z": -6,
      "name": "Rock_Chalk"
    },
    {
      "x": -15,
      "y": 40,
      "z": -6,
      "name": "Rock_Chalk"
    },
    {
      "x": -15,
      "y": 41,
      "z": -6,
      "name": "Rock_Chalk"
    },
    {
      "x": -15,
      "y": 42,
      "z": -6,
      "name": "Rock_Chalk"
    },
    {
      "x": -15,
      "y": 43,
      "z": -6,
      "name": "Rock_Marble"
    },
    {
      "x": -15,
      "y": 44,
      "z": -6,
      "name": "Rock_Marble"
    },
    {
      "x": -15,
      "y": 45,
      "z": -6,
      "name": "Rock_Marble"
    },
    {
      "x": -15,
      "y": 12,
      "z": -5,
      "name": "Rock_Marble"
    },
    {
      "x": -15,
      "y": 13,
      "z": -5,
      "name": "Rock_Marble"
    },
    {
      "x": -15,
      "y": 14,
      "z": -5,
      "name": "Rock_Marble"
    },
    {
      "x": -15,
      "y": 15,
      "z": -5,
      "name": "Rock_Marble"
    },
    {
      "x": -15,
      "y": 16,
      "z": -5,
      "name": "Rock_Chalk"
    },
    {
      "x": -15,
      "y": 17,
      "z": -5,
      "name": "Rock_Chalk"
    },
    {
      "x": -15,
      "y": 18,
      "z": -5,
      "name": "Rock_Chalk"
    },
    {
      "x": -15,
      "y": 19,
      "z": -5,
      "name": "Rock_Chalk"
    },
    {
      "x": -15,
      "y": 20,
      "z": -5,
      "name": "Rock_Chalk"
    },
    {
      "x": -15,
      "y": 21,
      "z": -5,
      "name": "Rock_Chalk"
    },
    {
      "x": -15,
      "y": 22,
      "z": -5,
      "name": "Rock_Chalk"
    },
    {
      "x": -15,
      "y": 23,
      "z": -5,
      "name": "Rock_Chalk"
    },
    {
      "x": -15,
      "y": 24,
      "z": -5,
      "name": "Rock_Chalk"
    },
    {
      "x": -15,
      "y": 25,
      "z": -5,
      "name": "Rock_Chalk"
    },
    {
      "x": -15,
      "y": 26,
      "z": -5,
      "name": "Rock_Chalk"
    },
    {
      "x": -15,
      "y": 27,
      "z": -5,
      "name": "Rock_Chalk"
    },
    {
      "x": -15,
      "y": 28,
      "z": -5,
      "name": "Rock_Chalk"
    },
    {
      "x": -15,
      "y": 29,
      "z": -5,
      "name": "Rock_Chalk"
    },
    {
      "x": -15,
      "y": 30,
      "z": -5,
      "name": "Rock_Chalk"
    },
    {
      "x": -15,
      "y": 31,
      "z": -5,
      "name": "Rock_Chalk"
    },
    {
      "x": -15,
      "y": 32,
      "z": -5,
      "name": "Rock_Chalk"
    },
    {
      "x": -15,
      "y": 33,
      "z": -5,
      "name": "Rock_Chalk"
    },
    {
      "x": -15,
      "y": 34,
      "z": -5,
      "name": "Rock_Chalk"
    },
    {
      "x": -15,
      "y": 35,
      "z": -5,
      "name": "Rock_Chalk"
    },
    {
      "x": -15,
      "y": 36,
      "z": -5,
      "name": "Rock_Chalk"
    },
    {
      "x": -15,
      "y": 37,
      "z": -5,
      "name": "Rock_Chalk"
    },
    {
      "x": -15,
      "y": 38,
      "z": -5,
      "name": "Rock_Chalk"
    },
    {
      "x": -15,
      "y": 39,
      "z": -5,
      "name": "Rock_Chalk"
    },
    {
      "x": -15,
      "y": 40,
      "z": -5,
      "name": "Rock_Chalk"
    },
    {
      "x": -15,
      "y": 41,
      "z": -5,
      "name": "Rock_Chalk"
    },
    {
      "x": -15,
      "y": 42,
      "z": -5,
      "name": "Rock_Chalk"
    },
    {
      "x": -15,
      "y": 14,
      "z": -4,
      "name": "Rock_Marble"
    },
    {
      "x": -15,
      "y": 15,
      "z": -4,
      "name": "Rock_Marble"
    },
    {
      "x": -15,
      "y": 16,
      "z": -4,
      "name": "Rock_Chalk"
    },
    {
      "x": -15,
      "y": 17,
      "z": -4,
      "name": "Rock_Chalk"
    },
    {
      "x": -15,
      "y": 18,
      "z": -4,
      "name": "Rock_Chalk"
    },
    {
      "x": -15,
      "y": 19,
      "z": -4,
      "name": "Rock_Chalk"
    },
    {
      "x": -15,
      "y": 20,
      "z": -4,
      "name": "Rock_Chalk"
    },
    {
      "x": -15,
      "y": 21,
      "z": -4,
      "name": "Rock_Chalk"
    },
    {
      "x": -15,
      "y": 22,
      "z": -4,
      "name": "Rock_Chalk"
    },
    {
      "x": -15,
      "y": 23,
      "z": -4,
      "name": "Rock_Chalk"
    },
    {
      "x": -15,
      "y": 24,
      "z": -4,
      "name": "Rock_Chalk"
    },
    {
      "x": -15,
      "y": 25,
      "z": -4,
      "name": "Rock_Chalk"
    },
    {
      "x": -15,
      "y": 26,
      "z": -4,
      "name": "Rock_Chalk"
    },
    {
      "x": -15,
      "y": 27,
      "z": -4,
      "name": "Rock_Chalk"
    },
    {
      "x": -15,
      "y": 28,
      "z": -4,
      "name": "Rock_Chalk"
    },
    {
      "x": -15,
      "y": 29,
      "z": -4,
      "name": "Rock_Chalk"
    },
    {
      "x": -15,
      "y": 32,
      "z": -4,
      "name": "Rock_Chalk"
    },
    {
      "x": -15,
      "y": 33,
      "z": -4,
      "name": "Rock_Chalk"
    },
    {
      "x": -15,
      "y": 34,
      "z": -4,
      "name": "Rock_Chalk"
    },
    {
      "x": -15,
      "y": 35,
      "z": -4,
      "name": "Rock_Chalk"
    },
    {
      "x": -15,
      "y": 36,
      "z": -4,
      "name": "Rock_Chalk"
    },
    {
      "x": -15,
      "y": 37,
      "z": -4,
      "name": "Rock_Chalk"
    },
    {
      "x": -15,
      "y": 38,
      "z": -4,
      "name": "Rock_Chalk"
    },
    {
      "x": -14,
      "y": 14,
      "z": -11,
      "name": "Rock_Marble"
    },
    {
      "x": -14,
      "y": 15,
      "z": -11,
      "name": "Rock_Marble"
    },
    {
      "x": -14,
      "y": 16,
      "z": -11,
      "name": "Rock_Marble"
    },
    {
      "x": -14,
      "y": 17,
      "z": -11,
      "name": "Rock_Marble"
    },
    {
      "x": -14,
      "y": 18,
      "z": -11,
      "name": "Rock_Marble"
    },
    {
      "x": -14,
      "y": 19,
      "z": -11,
      "name": "Rock_Marble"
    },
    {
      "x": -14,
      "y": 20,
      "z": -11,
      "name": "Rock_Marble"
    },
    {
      "x": -14,
      "y": 21,
      "z": -11,
      "name": "Rock_Marble"
    },
    {
      "x": -14,
      "y": 22,
      "z": -11,
      "name": "Rock_Marble"
    },
    {
      "x": -14,
      "y": 23,
      "z": -11,
      "name": "Rock_Chalk"
    },
    {
      "x": -14,
      "y": 24,
      "z": -11,
      "name": "Rock_Chalk"
    },
    {
      "x": -14,
      "y": 25,
      "z": -11,
      "name": "Rock_Chalk"
    },
    {
      "x": -14,
      "y": 26,
      "z": -11,
      "name": "Rock_Chalk"
    },
    {
      "x": -14,
      "y": 27,
      "z": -11,
      "name": "Rock_Chalk"
    },
    {
      "x": -14,
      "y": 28,
      "z": -11,
      "name": "Rock_Chalk"
    },
    {
      "x": -14,
      "y": 29,
      "z": -11,
      "name": "Rock_Chalk"
    },
    {
      "x": -14,
      "y": 30,
      "z": -11,
      "name": "Rock_Chalk"
    },
    {
      "x": -14,
      "y": 31,
      "z": -11,
      "name": "Rock_Chalk"
    },
    {
      "x": -14,
      "y": 32,
      "z": -11,
      "name": "Rock_Chalk"
    },
    {
      "x": -14,
      "y": 33,
      "z": -11,
      "name": "Rock_Chalk"
    },
    {
      "x": -14,
      "y": 34,
      "z": -11,
      "name": "Rock_Chalk"
    },
    {
      "x": -14,
      "y": 35,
      "z": -11,
      "name": "Rock_Chalk"
    },
    {
      "x": -14,
      "y": 36,
      "z": -11,
      "name": "Rock_Chalk"
    },
    {
      "x": -14,
      "y": 37,
      "z": -11,
      "name": "Rock_Chalk"
    },
    {
      "x": -14,
      "y": 38,
      "z": -11,
      "name": "Rock_Chalk"
    },
    {
      "x": -14,
      "y": 39,
      "z": -11,
      "name": "Rock_Chalk"
    },
    {
      "x": -14,
      "y": 40,
      "z": -11,
      "name": "Rock_Chalk"
    },
    {
      "x": -14,
      "y": 41,
      "z": -11,
      "name": "Rock_Chalk"
    },
    {
      "x": -14,
      "y": 42,
      "z": -11,
      "name": "Rock_Chalk"
    },
    {
      "x": -14,
      "y": 4,
      "z": -10,
      "name": "Rock_Marble"
    },
    {
      "x": -14,
      "y": 5,
      "z": -10,
      "name": "Rock_Marble"
    },
    {
      "x": -14,
      "y": 9,
      "z": -10,
      "name": "Rock_Marble"
    },
    {
      "x": -14,
      "y": 10,
      "z": -10,
      "name": "Rock_Marble"
    },
    {
      "x": -14,
      "y": 11,
      "z": -10,
      "name": "Rock_Marble"
    },
    {
      "x": -14,
      "y": 12,
      "z": -10,
      "name": "Rock_Marble"
    },
    {
      "x": -14,
      "y": 13,
      "z": -10,
      "name": "Rock_Marble"
    },
    {
      "x": -14,
      "y": 14,
      "z": -10,
      "name": "Rock_Marble"
    },
    {
      "x": -14,
      "y": 15,
      "z": -10,
      "name": "Rock_Marble"
    },
    {
      "x": -14,
      "y": 16,
      "z": -10,
      "name": "Rock_Marble"
    },
    {
      "x": -14,
      "y": 17,
      "z": -10,
      "name": "Rock_Marble"
    },
    {
      "x": -14,
      "y": 18,
      "z": -10,
      "name": "Rock_Chalk"
    },
    {
      "x": -14,
      "y": 19,
      "z": -10,
      "name": "Rock_Chalk"
    },
    {
      "x": -14,
      "y": 20,
      "z": -10,
      "name": "Rock_Chalk"
    },
    {
      "x": -14,
      "y": 21,
      "z": -10,
      "name": "Rock_Chalk"
    },
    {
      "x": -14,
      "y": 22,
      "z": -10,
      "name": "Rock_Chalk"
    },
    {
      "x": -14,
      "y": 23,
      "z": -10,
      "name": "Rock_Chalk"
    },
    {
      "x": -14,
      "y": 24,
      "z": -10,
      "name": "Rock_Chalk"
    },
    {
      "x": -14,
      "y": 25,
      "z": -10,
      "name": "Rock_Chalk"
    },
    {
      "x": -14,
      "y": 26,
      "z": -10,
      "name": "Rock_Chalk"
    },
    {
      "x": -14,
      "y": 27,
      "z": -10,
      "name": "Rock_Chalk"
    },
    {
      "x": -14,
      "y": 28,
      "z": -10,
      "name": "Rock_Chalk"
    },
    {
      "x": -14,
      "y": 29,
      "z": -10,
      "name": "Rock_Chalk"
    },
    {
      "x": -14,
      "y": 30,
      "z": -10,
      "name": "Rock_Chalk"
    },
    {
      "x": -14,
      "y": 31,
      "z": -10,
      "name": "Rock_Chalk"
    },
    {
      "x": -14,
      "y": 32,
      "z": -10,
      "name": "Rock_Chalk"
    },
    {
      "x": -14,
      "y": 33,
      "z": -10,
      "name": "Rock_Chalk"
    },
    {
      "x": -14,
      "y": 34,
      "z": -10,
      "name": "Rock_Chalk"
    },
    {
      "x": -14,
      "y": 35,
      "z": -10,
      "name": "Rock_Chalk"
    },
    {
      "x": -14,
      "y": 36,
      "z": -10,
      "name": "Rock_Chalk"
    },
    {
      "x": -14,
      "y": 37,
      "z": -10,
      "name": "Rock_Chalk"
    },
    {
      "x": -14,
      "y": 38,
      "z": -10,
      "name": "Rock_Chalk"
    },
    {
      "x": -14,
      "y": 39,
      "z": -10,
      "name": "Rock_Chalk"
    },
    {
      "x": -14,
      "y": 40,
      "z": -10,
      "name": "Rock_Chalk"
    },
    {
      "x": -14,
      "y": 41,
      "z": -10,
      "name": "Rock_Chalk"
    },
    {
      "x": -14,
      "y": 42,
      "z": -10,
      "name": "Rock_Chalk"
    },
    {
      "x": -14,
      "y": 43,
      "z": -10,
      "name": "Rock_Chalk"
    },
    {
      "x": -14,
      "y": 44,
      "z": -10,
      "name": "Rock_Chalk"
    },
    {
      "x": -14,
      "y": 45,
      "z": -10,
      "name": "Rock_Chalk"
    },
    {
      "x": -14,
      "y": 46,
      "z": -10,
      "name": "Rock_Chalk"
    },
    {
      "x": -14,
      "y": 47,
      "z": -10,
      "name": "Rock_Chalk"
    },
    {
      "x": -14,
      "y": 48,
      "z": -10,
      "name": "Rock_Chalk"
    },
    {
      "x": -14,
      "y": 49,
      "z": -10,
      "name": "Rock_Chalk"
    },
    {
      "x": -14,
      "y": 50,
      "z": -10,
      "name": "Rock_Marble"
    },
    {
      "x": -14,
      "y": 51,
      "z": -10,
      "name": "Rock_Marble"
    },
    {
      "x": -14,
      "y": 52,
      "z": -10,
      "name": "Rock_Marble"
    },
    {
      "x": -14,
      "y": 4,
      "z": -9,
      "name": "Rock_Marble"
    },
    {
      "x": -14,
      "y": 5,
      "z": -9,
      "name": "Rock_Marble"
    },
    {
      "x": -14,
      "y": 6,
      "z": -9,
      "name": "Rock_Marble"
    },
    {
      "x": -14,
      "y": 7,
      "z": -9,
      "name": "Rock_Marble"
    },
    {
      "x": -14,
      "y": 8,
      "z": -9,
      "name": "Rock_Marble"
    },
    {
      "x": -14,
      "y": 9,
      "z": -9,
      "name": "Rock_Marble"
    },
    {
      "x": -14,
      "y": 10,
      "z": -9,
      "name": "Rock_Marble"
    },
    {
      "x": -14,
      "y": 11,
      "z": -9,
      "name": "Rock_Marble"
    },
    {
      "x": -14,
      "y": 12,
      "z": -9,
      "name": "Rock_Marble"
    },
    {
      "x": -14,
      "y": 13,
      "z": -9,
      "name": "Rock_Marble"
    },
    {
      "x": -14,
      "y": 14,
      "z": -9,
      "name": "Rock_Marble"
    },
    {
      "x": -14,
      "y": 15,
      "z": -9,
      "name": "Rock_Marble"
    },
    {
      "x": -14,
      "y": 16,
      "z": -9,
      "name": "Rock_Chalk"
    },
    {
      "x": -14,
      "y": 17,
      "z": -9,
      "name": "Rock_Chalk"
    },
    {
      "x": -14,
      "y": 18,
      "z": -9,
      "name": "Rock_Chalk"
    },
    {
      "x": -14,
      "y": 19,
      "z": -9,
      "name": "Rock_Chalk"
    },
    {
      "x": -14,
      "y": 20,
      "z": -9,
      "name": "Rock_Chalk"
    },
    {
      "x": -14,
      "y": 21,
      "z": -9,
      "name": "Rock_Chalk"
    },
    {
      "x": -14,
      "y": 22,
      "z": -9,
      "name": "Rock_Chalk"
    },
    {
      "x": -14,
      "y": 23,
      "z": -9,
      "name": "Rock_Chalk"
    },
    {
      "x": -14,
      "y": 24,
      "z": -9,
      "name": "Rock_Chalk"
    },
    {
      "x": -14,
      "y": 25,
      "z": -9,
      "name": "Rock_Chalk"
    },
    {
      "x": -14,
      "y": 26,
      "z": -9,
      "name": "Rock_Chalk"
    },
    {
      "x": -14,
      "y": 27,
      "z": -9,
      "name": "Rock_Chalk"
    },
    {
      "x": -14,
      "y": 28,
      "z": -9,
      "name": "Rock_Chalk"
    },
    {
      "x": -14,
      "y": 29,
      "z": -9,
      "name": "Rock_Chalk"
    },
    {
      "x": -14,
      "y": 30,
      "z": -9,
      "name": "Rock_Chalk"
    },
    {
      "x": -14,
      "y": 31,
      "z": -9,
      "name": "Rock_Chalk"
    },
    {
      "x": -14,
      "y": 32,
      "z": -9,
      "name": "Rock_Chalk"
    },
    {
      "x": -14,
      "y": 33,
      "z": -9,
      "name": "Rock_Chalk"
    },
    {
      "x": -14,
      "y": 34,
      "z": -9,
      "name": "Rock_Chalk"
    },
    {
      "x": -14,
      "y": 35,
      "z": -9,
      "name": "Rock_Chalk"
    },
    {
      "x": -14,
      "y": 36,
      "z": -9,
      "name": "Rock_Chalk"
    },
    {
      "x": -14,
      "y": 37,
      "z": -9,
      "name": "Rock_Chalk"
    },
    {
      "x": -14,
      "y": 38,
      "z": -9,
      "name": "Rock_Chalk"
    },
    {
      "x": -14,
      "y": 39,
      "z": -9,
      "name": "Rock_Chalk"
    },
    {
      "x": -14,
      "y": 40,
      "z": -9,
      "name": "Rock_Chalk"
    },
    {
      "x": -14,
      "y": 41,
      "z": -9,
      "name": "Rock_Chalk"
    },
    {
      "x": -14,
      "y": 42,
      "z": -9,
      "name": "Rock_Chalk"
    },
    {
      "x": -14,
      "y": 43,
      "z": -9,
      "name": "Rock_Chalk"
    },
    {
      "x": -14,
      "y": 44,
      "z": -9,
      "name": "Rock_Chalk"
    },
    {
      "x": -14,
      "y": 45,
      "z": -9,
      "name": "Rock_Chalk"
    },
    {
      "x": -14,
      "y": 46,
      "z": -9,
      "name": "Rock_Chalk"
    },
    {
      "x": -14,
      "y": 47,
      "z": -9,
      "name": "Rock_Chalk"
    },
    {
      "x": -14,
      "y": 48,
      "z": -9,
      "name": "Rock_Marble"
    },
    {
      "x": -14,
      "y": 49,
      "z": -9,
      "name": "Rock_Marble"
    },
    {
      "x": -14,
      "y": 50,
      "z": -9,
      "name": "Rock_Marble"
    },
    {
      "x": -14,
      "y": 51,
      "z": -9,
      "name": "Rock_Marble"
    },
    {
      "x": -14,
      "y": 52,
      "z": -9,
      "name": "Rock_Marble"
    },
    {
      "x": -14,
      "y": 53,
      "z": -9,
      "name": "Rock_Marble"
    },
    {
      "x": -14,
      "y": 54,
      "z": -9,
      "name": "Rock_Marble"
    },
    {
      "x": -14,
      "y": 3,
      "z": -8,
      "name": "Rock_Marble"
    },
    {
      "x": -14,
      "y": 4,
      "z": -8,
      "name": "Rock_Marble"
    },
    {
      "x": -14,
      "y": 5,
      "z": -8,
      "name": "Rock_Marble"
    },
    {
      "x": -14,
      "y": 6,
      "z": -8,
      "name": "Rock_Marble"
    },
    {
      "x": -14,
      "y": 7,
      "z": -8,
      "name": "Rock_Marble"
    },
    {
      "x": -14,
      "y": 8,
      "z": -8,
      "name": "Rock_Marble"
    },
    {
      "x": -14,
      "y": 9,
      "z": -8,
      "name": "Rock_Marble"
    },
    {
      "x": -14,
      "y": 10,
      "z": -8,
      "name": "Rock_Marble"
    },
    {
      "x": -14,
      "y": 11,
      "z": -8,
      "name": "Rock_Marble"
    },
    {
      "x": -14,
      "y": 12,
      "z": -8,
      "name": "Rock_Marble"
    },
    {
      "x": -14,
      "y": 13,
      "z": -8,
      "name": "Rock_Marble"
    },
    {
      "x": -14,
      "y": 14,
      "z": -8,
      "name": "Rock_Marble"
    },
    {
      "x": -14,
      "y": 15,
      "z": -8,
      "name": "Rock_Chalk"
    },
    {
      "x": -14,
      "y": 16,
      "z": -8,
      "name": "Rock_Chalk"
    },
    {
      "x": -14,
      "y": 17,
      "z": -8,
      "name": "Rock_Chalk"
    },
    {
      "x": -14,
      "y": 18,
      "z": -8,
      "name": "Rock_Chalk"
    },
    {
      "x": -14,
      "y": 19,
      "z": -8,
      "name": "Rock_Chalk"
    },
    {
      "x": -14,
      "y": 20,
      "z": -8,
      "name": "Rock_Chalk"
    },
    {
      "x": -14,
      "y": 21,
      "z": -8,
      "name": "Rock_Chalk"
    },
    {
      "x": -14,
      "y": 22,
      "z": -8,
      "name": "Rock_Chalk"
    },
    {
      "x": -14,
      "y": 23,
      "z": -8,
      "name": "Rock_Chalk"
    },
    {
      "x": -14,
      "y": 24,
      "z": -8,
      "name": "Rock_Chalk"
    },
    {
      "x": -14,
      "y": 25,
      "z": -8,
      "name": "Rock_Chalk"
    },
    {
      "x": -14,
      "y": 26,
      "z": -8,
      "name": "Rock_Chalk"
    },
    {
      "x": -14,
      "y": 27,
      "z": -8,
      "name": "Rock_Chalk"
    },
    {
      "x": -14,
      "y": 28,
      "z": -8,
      "name": "Rock_Chalk"
    },
    {
      "x": -14,
      "y": 29,
      "z": -8,
      "name": "Rock_Chalk"
    },
    {
      "x": -14,
      "y": 30,
      "z": -8,
      "name": "Rock_Chalk"
    },
    {
      "x": -14,
      "y": 31,
      "z": -8,
      "name": "Rock_Chalk"
    },
    {
      "x": -14,
      "y": 32,
      "z": -8,
      "name": "Rock_Chalk"
    },
    {
      "x": -14,
      "y": 33,
      "z": -8,
      "name": "Rock_Chalk"
    },
    {
      "x": -14,
      "y": 34,
      "z": -8,
      "name": "Rock_Chalk"
    },
    {
      "x": -14,
      "y": 35,
      "z": -8,
      "name": "Rock_Chalk"
    },
    {
      "x": -14,
      "y": 36,
      "z": -8,
      "name": "Rock_Chalk"
    },
    {
      "x": -14,
      "y": 37,
      "z": -8,
      "name": "Rock_Chalk"
    },
    {
      "x": -14,
      "y": 38,
      "z": -8,
      "name": "Rock_Chalk"
    },
    {
      "x": -14,
      "y": 39,
      "z": -8,
      "name": "Rock_Chalk"
    },
    {
      "x": -14,
      "y": 40,
      "z": -8,
      "name": "Rock_Chalk"
    },
    {
      "x": -14,
      "y": 41,
      "z": -8,
      "name": "Rock_Chalk"
    },
    {
      "x": -14,
      "y": 42,
      "z": -8,
      "name": "Rock_Chalk"
    },
    {
      "x": -14,
      "y": 43,
      "z": -8,
      "name": "Rock_Chalk"
    },
    {
      "x": -14,
      "y": 44,
      "z": -8,
      "name": "Rock_Chalk"
    },
    {
      "x": -14,
      "y": 45,
      "z": -8,
      "name": "Rock_Chalk"
    },
    {
      "x": -14,
      "y": 46,
      "z": -8,
      "name": "Rock_Marble"
    },
    {
      "x": -14,
      "y": 47,
      "z": -8,
      "name": "Rock_Marble"
    },
    {
      "x": -14,
      "y": 48,
      "z": -8,
      "name": "Rock_Marble"
    },
    {
      "x": -14,
      "y": 49,
      "z": -8,
      "name": "Rock_Marble"
    },
    {
      "x": -14,
      "y": 50,
      "z": -8,
      "name": "Rock_Marble"
    },
    {
      "x": -14,
      "y": 51,
      "z": -8,
      "name": "Rock_Marble"
    },
    {
      "x": -14,
      "y": 52,
      "z": -8,
      "name": "Rock_Marble"
    },
    {
      "x": -14,
      "y": 53,
      "z": -8,
      "name": "Rock_Marble"
    },
    {
      "x": -14,
      "y": 54,
      "z": -8,
      "name": "Rock_Marble"
    },
    {
      "x": -14,
      "y": 55,
      "z": -8,
      "name": "Rock_Marble"
    },
    {
      "x": -14,
      "y": 3,
      "z": -7,
      "name": "Rock_Marble"
    },
    {
      "x": -14,
      "y": 4,
      "z": -7,
      "name": "Rock_Marble"
    },
    {
      "x": -14,
      "y": 5,
      "z": -7,
      "name": "Rock_Marble"
    },
    {
      "x": -14,
      "y": 6,
      "z": -7,
      "name": "Rock_Marble"
    },
    {
      "x": -14,
      "y": 7,
      "z": -7,
      "name": "Rock_Marble"
    },
    {
      "x": -14,
      "y": 8,
      "z": -7,
      "name": "Rock_Marble"
    },
    {
      "x": -14,
      "y": 9,
      "z": -7,
      "name": "Rock_Marble"
    },
    {
      "x": -14,
      "y": 10,
      "z": -7,
      "name": "Rock_Marble"
    },
    {
      "x": -14,
      "y": 11,
      "z": -7,
      "name": "Rock_Marble"
    },
    {
      "x": -14,
      "y": 12,
      "z": -7,
      "name": "Rock_Marble"
    },
    {
      "x": -14,
      "y": 13,
      "z": -7,
      "name": "Rock_Marble"
    },
    {
      "x": -14,
      "y": 14,
      "z": -7,
      "name": "Rock_Chalk"
    },
    {
      "x": -14,
      "y": 15,
      "z": -7,
      "name": "Rock_Chalk"
    },
    {
      "x": -14,
      "y": 16,
      "z": -7,
      "name": "Rock_Chalk"
    },
    {
      "x": -14,
      "y": 17,
      "z": -7,
      "name": "Rock_Chalk"
    },
    {
      "x": -14,
      "y": 18,
      "z": -7,
      "name": "Rock_Chalk"
    },
    {
      "x": -14,
      "y": 19,
      "z": -7,
      "name": "Rock_Chalk"
    },
    {
      "x": -14,
      "y": 20,
      "z": -7,
      "name": "Rock_Chalk"
    },
    {
      "x": -14,
      "y": 21,
      "z": -7,
      "name": "Rock_Chalk"
    },
    {
      "x": -14,
      "y": 22,
      "z": -7,
      "name": "Rock_Chalk"
    },
    {
      "x": -14,
      "y": 23,
      "z": -7,
      "name": "Rock_Chalk"
    },
    {
      "x": -14,
      "y": 24,
      "z": -7,
      "name": "Rock_Chalk"
    },
    {
      "x": -14,
      "y": 25,
      "z": -7,
      "name": "Rock_Chalk"
    },
    {
      "x": -14,
      "y": 26,
      "z": -7,
      "name": "Rock_Chalk"
    },
    {
      "x": -14,
      "y": 27,
      "z": -7,
      "name": "Rock_Chalk"
    },
    {
      "x": -14,
      "y": 28,
      "z": -7,
      "name": "Rock_Chalk"
    },
    {
      "x": -14,
      "y": 29,
      "z": -7,
      "name": "Rock_Chalk"
    },
    {
      "x": -14,
      "y": 30,
      "z": -7,
      "name": "Rock_Chalk"
    },
    {
      "x": -14,
      "y": 31,
      "z": -7,
      "name": "Rock_Chalk"
    },
    {
      "x": -14,
      "y": 32,
      "z": -7,
      "name": "Rock_Chalk"
    },
    {
      "x": -14,
      "y": 33,
      "z": -7,
      "name": "Rock_Chalk"
    },
    {
      "x": -14,
      "y": 34,
      "z": -7,
      "name": "Rock_Chalk"
    },
    {
      "x": -14,
      "y": 35,
      "z": -7,
      "name": "Rock_Chalk"
    },
    {
      "x": -14,
      "y": 36,
      "z": -7,
      "name": "Rock_Chalk"
    },
    {
      "x": -14,
      "y": 37,
      "z": -7,
      "name": "Rock_Chalk"
    },
    {
      "x": -14,
      "y": 38,
      "z": -7,
      "name": "Rock_Chalk"
    },
    {
      "x": -14,
      "y": 39,
      "z": -7,
      "name": "Rock_Chalk"
    },
    {
      "x": -14,
      "y": 40,
      "z": -7,
      "name": "Rock_Chalk"
    },
    {
      "x": -14,
      "y": 41,
      "z": -7,
      "name": "Rock_Chalk"
    },
    {
      "x": -14,
      "y": 42,
      "z": -7,
      "name": "Rock_Chalk"
    },
    {
      "x": -14,
      "y": 43,
      "z": -7,
      "name": "Rock_Chalk"
    },
    {
      "x": -14,
      "y": 44,
      "z": -7,
      "name": "Rock_Chalk"
    },
    {
      "x": -14,
      "y": 45,
      "z": -7,
      "name": "Rock_Marble"
    },
    {
      "x": -14,
      "y": 46,
      "z": -7,
      "name": "Rock_Marble"
    },
    {
      "x": -14,
      "y": 47,
      "z": -7,
      "name": "Rock_Marble"
    },
    {
      "x": -14,
      "y": 48,
      "z": -7,
      "name": "Rock_Marble"
    },
    {
      "x": -14,
      "y": 49,
      "z": -7,
      "name": "Rock_Marble"
    },
    {
      "x": -14,
      "y": 50,
      "z": -7,
      "name": "Rock_Marble"
    },
    {
      "x": -14,
      "y": 51,
      "z": -7,
      "name": "Rock_Marble"
    },
    {
      "x": -14,
      "y": 52,
      "z": -7,
      "name": "Rock_Marble"
    },
    {
      "x": -14,
      "y": 53,
      "z": -7,
      "name": "Rock_Marble"
    },
    {
      "x": -14,
      "y": 54,
      "z": -7,
      "name": "Rock_Marble"
    },
    {
      "x": -14,
      "y": 55,
      "z": -7,
      "name": "Rock_Marble"
    },
    {
      "x": -14,
      "y": 3,
      "z": -6,
      "name": "Rock_Marble"
    },
    {
      "x": -14,
      "y": 4,
      "z": -6,
      "name": "Rock_Marble"
    },
    {
      "x": -14,
      "y": 5,
      "z": -6,
      "name": "Rock_Marble"
    },
    {
      "x": -14,
      "y": 6,
      "z": -6,
      "name": "Rock_Marble"
    },
    {
      "x": -14,
      "y": 7,
      "z": -6,
      "name": "Rock_Marble"
    },
    {
      "x": -14,
      "y": 8,
      "z": -6,
      "name": "Rock_Marble"
    },
    {
      "x": -14,
      "y": 9,
      "z": -6,
      "name": "Rock_Marble"
    },
    {
      "x": -14,
      "y": 10,
      "z": -6,
      "name": "Rock_Marble"
    },
    {
      "x": -14,
      "y": 11,
      "z": -6,
      "name": "Rock_Marble"
    },
    {
      "x": -14,
      "y": 12,
      "z": -6,
      "name": "Rock_Marble"
    },
    {
      "x": -14,
      "y": 13,
      "z": -6,
      "name": "Rock_Marble"
    },
    {
      "x": -14,
      "y": 14,
      "z": -6,
      "name": "Rock_Chalk"
    },
    {
      "x": -14,
      "y": 15,
      "z": -6,
      "name": "Rock_Chalk"
    },
    {
      "x": -14,
      "y": 16,
      "z": -6,
      "name": "Rock_Chalk"
    },
    {
      "x": -14,
      "y": 17,
      "z": -6,
      "name": "Rock_Chalk"
    },
    {
      "x": -14,
      "y": 18,
      "z": -6,
      "name": "Rock_Chalk"
    },
    {
      "x": -14,
      "y": 19,
      "z": -6,
      "name": "Rock_Chalk"
    },
    {
      "x": -14,
      "y": 20,
      "z": -6,
      "name": "Rock_Chalk"
    },
    {
      "x": -14,
      "y": 21,
      "z": -6,
      "name": "Rock_Chalk"
    },
    {
      "x": -14,
      "y": 22,
      "z": -6,
      "name": "Rock_Chalk"
    },
    {
      "x": -14,
      "y": 23,
      "z": -6,
      "name": "Rock_Chalk"
    },
    {
      "x": -14,
      "y": 24,
      "z": -6,
      "name": "Rock_Chalk"
    },
    {
      "x": -14,
      "y": 25,
      "z": -6,
      "name": "Rock_Chalk"
    },
    {
      "x": -14,
      "y": 26,
      "z": -6,
      "name": "Rock_Chalk"
    },
    {
      "x": -14,
      "y": 27,
      "z": -6,
      "name": "Rock_Chalk"
    },
    {
      "x": -14,
      "y": 28,
      "z": -6,
      "name": "Rock_Chalk"
    },
    {
      "x": -14,
      "y": 29,
      "z": -6,
      "name": "Rock_Chalk"
    },
    {
      "x": -14,
      "y": 30,
      "z": -6,
      "name": "Rock_Chalk"
    },
    {
      "x": -14,
      "y": 31,
      "z": -6,
      "name": "Rock_Chalk"
    },
    {
      "x": -14,
      "y": 32,
      "z": -6,
      "name": "Rock_Chalk"
    },
    {
      "x": -14,
      "y": 33,
      "z": -6,
      "name": "Rock_Chalk"
    },
    {
      "x": -14,
      "y": 34,
      "z": -6,
      "name": "Rock_Chalk"
    },
    {
      "x": -14,
      "y": 35,
      "z": -6,
      "name": "Rock_Chalk"
    },
    {
      "x": -14,
      "y": 36,
      "z": -6,
      "name": "Rock_Chalk"
    },
    {
      "x": -14,
      "y": 37,
      "z": -6,
      "name": "Rock_Chalk"
    },
    {
      "x": -14,
      "y": 38,
      "z": -6,
      "name": "Rock_Chalk"
    },
    {
      "x": -14,
      "y": 39,
      "z": -6,
      "name": "Rock_Chalk"
    },
    {
      "x": -14,
      "y": 40,
      "z": -6,
      "name": "Rock_Chalk"
    },
    {
      "x": -14,
      "y": 41,
      "z": -6,
      "name": "Rock_Chalk"
    },
    {
      "x": -14,
      "y": 42,
      "z": -6,
      "name": "Rock_Chalk"
    },
    {
      "x": -14,
      "y": 43,
      "z": -6,
      "name": "Rock_Chalk"
    },
    {
      "x": -14,
      "y": 44,
      "z": -6,
      "name": "Rock_Chalk"
    },
    {
      "x": -14,
      "y": 45,
      "z": -6,
      "name": "Rock_Marble"
    },
    {
      "x": -14,
      "y": 46,
      "z": -6,
      "name": "Rock_Marble"
    },
    {
      "x": -14,
      "y": 47,
      "z": -6,
      "name": "Rock_Marble"
    },
    {
      "x": -14,
      "y": 48,
      "z": -6,
      "name": "Rock_Marble"
    },
    {
      "x": -14,
      "y": 49,
      "z": -6,
      "name": "Rock_Marble"
    },
    {
      "x": -14,
      "y": 50,
      "z": -6,
      "name": "Rock_Marble"
    },
    {
      "x": -14,
      "y": 51,
      "z": -6,
      "name": "Rock_Marble"
    },
    {
      "x": -14,
      "y": 52,
      "z": -6,
      "name": "Rock_Marble"
    },
    {
      "x": -14,
      "y": 53,
      "z": -6,
      "name": "Rock_Marble"
    },
    {
      "x": -14,
      "y": 4,
      "z": -5,
      "name": "Rock_Marble"
    },
    {
      "x": -14,
      "y": 5,
      "z": -5,
      "name": "Rock_Marble"
    },
    {
      "x": -14,
      "y": 6,
      "z": -5,
      "name": "Rock_Marble"
    },
    {
      "x": -14,
      "y": 7,
      "z": -5,
      "name": "Rock_Marble"
    },
    {
      "x": -14,
      "y": 8,
      "z": -5,
      "name": "Rock_Marble"
    },
    {
      "x": -14,
      "y": 9,
      "z": -5,
      "name": "Rock_Marble"
    },
    {
      "x": -14,
      "y": 10,
      "z": -5,
      "name": "Rock_Marble"
    },
    {
      "x": -14,
      "y": 11,
      "z": -5,
      "name": "Rock_Marble"
    },
    {
      "x": -14,
      "y": 12,
      "z": -5,
      "name": "Rock_Marble"
    },
    {
      "x": -14,
      "y": 13,
      "z": -5,
      "name": "Rock_Marble"
    },
    {
      "x": -14,
      "y": 14,
      "z": -5,
      "name": "Rock_Chalk"
    },
    {
      "x": -14,
      "y": 15,
      "z": -5,
      "name": "Rock_Chalk"
    },
    {
      "x": -14,
      "y": 16,
      "z": -5,
      "name": "Rock_Chalk"
    },
    {
      "x": -14,
      "y": 17,
      "z": -5,
      "name": "Rock_Chalk"
    },
    {
      "x": -14,
      "y": 18,
      "z": -5,
      "name": "Rock_Chalk"
    },
    {
      "x": -14,
      "y": 19,
      "z": -5,
      "name": "Rock_Chalk"
    },
    {
      "x": -14,
      "y": 20,
      "z": -5,
      "name": "Rock_Chalk"
    },
    {
      "x": -14,
      "y": 21,
      "z": -5,
      "name": "Rock_Chalk"
    },
    {
      "x": -14,
      "y": 22,
      "z": -5,
      "name": "Rock_Chalk"
    },
    {
      "x": -14,
      "y": 23,
      "z": -5,
      "name": "Rock_Chalk"
    },
    {
      "x": -14,
      "y": 24,
      "z": -5,
      "name": "Rock_Chalk"
    },
    {
      "x": -14,
      "y": 25,
      "z": -5,
      "name": "Rock_Chalk"
    },
    {
      "x": -14,
      "y": 26,
      "z": -5,
      "name": "Rock_Chalk"
    },
    {
      "x": -14,
      "y": 27,
      "z": -5,
      "name": "Rock_Chalk"
    },
    {
      "x": -14,
      "y": 28,
      "z": -5,
      "name": "Rock_Chalk"
    },
    {
      "x": -14,
      "y": 29,
      "z": -5,
      "name": "Rock_Chalk"
    },
    {
      "x": -14,
      "y": 30,
      "z": -5,
      "name": "Rock_Chalk"
    },
    {
      "x": -14,
      "y": 31,
      "z": -5,
      "name": "Rock_Chalk"
    },
    {
      "x": -14,
      "y": 32,
      "z": -5,
      "name": "Rock_Chalk"
    },
    {
      "x": -14,
      "y": 33,
      "z": -5,
      "name": "Rock_Chalk"
    },
    {
      "x": -14,
      "y": 34,
      "z": -5,
      "name": "Rock_Chalk"
    },
    {
      "x": -14,
      "y": 35,
      "z": -5,
      "name": "Rock_Chalk"
    },
    {
      "x": -14,
      "y": 36,
      "z": -5,
      "name": "Rock_Chalk"
    },
    {
      "x": -14,
      "y": 37,
      "z": -5,
      "name": "Rock_Chalk"
    },
    {
      "x": -14,
      "y": 38,
      "z": -5,
      "name": "Rock_Chalk"
    },
    {
      "x": -14,
      "y": 39,
      "z": -5,
      "name": "Rock_Chalk"
    },
    {
      "x": -14,
      "y": 40,
      "z": -5,
      "name": "Rock_Chalk"
    },
    {
      "x": -14,
      "y": 41,
      "z": -5,
      "name": "Rock_Chalk"
    },
    {
      "x": -14,
      "y": 42,
      "z": -5,
      "name": "Rock_Chalk"
    },
    {
      "x": -14,
      "y": 43,
      "z": -5,
      "name": "Rock_Chalk"
    },
    {
      "x": -14,
      "y": 44,
      "z": -5,
      "name": "Rock_Marble"
    },
    {
      "x": -14,
      "y": 45,
      "z": -5,
      "name": "Rock_Marble"
    },
    {
      "x": -14,
      "y": 46,
      "z": -5,
      "name": "Rock_Marble"
    },
    {
      "x": -14,
      "y": 47,
      "z": -5,
      "name": "Rock_Marble"
    },
    {
      "x": -14,
      "y": 48,
      "z": -5,
      "name": "Rock_Marble"
    },
    {
      "x": -14,
      "y": 5,
      "z": -4,
      "name": "Rock_Marble"
    },
    {
      "x": -14,
      "y": 6,
      "z": -4,
      "name": "Rock_Marble"
    },
    {
      "x": -14,
      "y": 7,
      "z": -4,
      "name": "Rock_Marble"
    },
    {
      "x": -14,
      "y": 8,
      "z": -4,
      "name": "Rock_Marble"
    },
    {
      "x": -14,
      "y": 9,
      "z": -4,
      "name": "Rock_Marble"
    },
    {
      "x": -14,
      "y": 10,
      "z": -4,
      "name": "Rock_Marble"
    },
    {
      "x": -14,
      "y": 11,
      "z": -4,
      "name": "Rock_Marble"
    },
    {
      "x": -14,
      "y": 12,
      "z": -4,
      "name": "Rock_Marble"
    },
    {
      "x": -14,
      "y": 13,
      "z": -4,
      "name": "Rock_Marble"
    },
    {
      "x": -14,
      "y": 14,
      "z": -4,
      "name": "Rock_Chalk"
    },
    {
      "x": -14,
      "y": 15,
      "z": -4,
      "name": "Rock_Chalk"
    },
    {
      "x": -14,
      "y": 16,
      "z": -4,
      "name": "Rock_Chalk"
    },
    {
      "x": -14,
      "y": 17,
      "z": -4,
      "name": "Rock_Chalk"
    },
    {
      "x": -14,
      "y": 18,
      "z": -4,
      "name": "Rock_Chalk"
    },
    {
      "x": -14,
      "y": 19,
      "z": -4,
      "name": "Rock_Chalk"
    },
    {
      "x": -14,
      "y": 20,
      "z": -4,
      "name": "Rock_Chalk"
    },
    {
      "x": -14,
      "y": 21,
      "z": -4,
      "name": "Rock_Chalk"
    },
    {
      "x": -14,
      "y": 22,
      "z": -4,
      "name": "Rock_Chalk"
    },
    {
      "x": -14,
      "y": 23,
      "z": -4,
      "name": "Rock_Chalk"
    },
    {
      "x": -14,
      "y": 24,
      "z": -4,
      "name": "Rock_Chalk"
    },
    {
      "x": -14,
      "y": 25,
      "z": -4,
      "name": "Rock_Chalk"
    },
    {
      "x": -14,
      "y": 26,
      "z": -4,
      "name": "Rock_Chalk"
    },
    {
      "x": -14,
      "y": 27,
      "z": -4,
      "name": "Rock_Chalk"
    },
    {
      "x": -14,
      "y": 28,
      "z": -4,
      "name": "Rock_Chalk"
    },
    {
      "x": -14,
      "y": 29,
      "z": -4,
      "name": "Rock_Chalk"
    },
    {
      "x": -14,
      "y": 30,
      "z": -4,
      "name": "Rock_Chalk"
    },
    {
      "x": -14,
      "y": 31,
      "z": -4,
      "name": "Rock_Chalk"
    },
    {
      "x": -14,
      "y": 32,
      "z": -4,
      "name": "Rock_Chalk"
    },
    {
      "x": -14,
      "y": 33,
      "z": -4,
      "name": "Rock_Chalk"
    },
    {
      "x": -14,
      "y": 34,
      "z": -4,
      "name": "Rock_Chalk"
    },
    {
      "x": -14,
      "y": 35,
      "z": -4,
      "name": "Rock_Chalk"
    },
    {
      "x": -14,
      "y": 36,
      "z": -4,
      "name": "Rock_Chalk"
    },
    {
      "x": -14,
      "y": 37,
      "z": -4,
      "name": "Rock_Chalk"
    },
    {
      "x": -14,
      "y": 38,
      "z": -4,
      "name": "Rock_Chalk"
    },
    {
      "x": -14,
      "y": 39,
      "z": -4,
      "name": "Rock_Chalk"
    },
    {
      "x": -14,
      "y": 40,
      "z": -4,
      "name": "Rock_Chalk"
    },
    {
      "x": -14,
      "y": 41,
      "z": -4,
      "name": "Rock_Chalk"
    },
    {
      "x": -14,
      "y": 42,
      "z": -4,
      "name": "Rock_Chalk"
    },
    {
      "x": -14,
      "y": 43,
      "z": -4,
      "name": "Rock_Chalk"
    },
    {
      "x": -14,
      "y": 44,
      "z": -4,
      "name": "Rock_Marble"
    },
    {
      "x": -14,
      "y": 9,
      "z": -3,
      "name": "Rock_Marble"
    },
    {
      "x": -14,
      "y": 10,
      "z": -3,
      "name": "Rock_Marble"
    },
    {
      "x": -14,
      "y": 11,
      "z": -3,
      "name": "Rock_Marble"
    },
    {
      "x": -14,
      "y": 12,
      "z": -3,
      "name": "Rock_Marble"
    },
    {
      "x": -14,
      "y": 13,
      "z": -3,
      "name": "Rock_Marble"
    },
    {
      "x": -14,
      "y": 14,
      "z": -3,
      "name": "Rock_Marble"
    },
    {
      "x": -14,
      "y": 15,
      "z": -3,
      "name": "Rock_Chalk"
    },
    {
      "x": -14,
      "y": 16,
      "z": -3,
      "name": "Rock_Chalk"
    },
    {
      "x": -14,
      "y": 17,
      "z": -3,
      "name": "Rock_Chalk"
    },
    {
      "x": -14,
      "y": 18,
      "z": -3,
      "name": "Rock_Chalk"
    },
    {
      "x": -14,
      "y": 19,
      "z": -3,
      "name": "Rock_Chalk"
    },
    {
      "x": -14,
      "y": 20,
      "z": -3,
      "name": "Rock_Chalk"
    },
    {
      "x": -14,
      "y": 21,
      "z": -3,
      "name": "Rock_Chalk"
    },
    {
      "x": -14,
      "y": 22,
      "z": -3,
      "name": "Rock_Chalk"
    },
    {
      "x": -14,
      "y": 23,
      "z": -3,
      "name": "Rock_Chalk"
    },
    {
      "x": -14,
      "y": 24,
      "z": -3,
      "name": "Rock_Chalk"
    },
    {
      "x": -14,
      "y": 25,
      "z": -3,
      "name": "Rock_Chalk"
    },
    {
      "x": -14,
      "y": 26,
      "z": -3,
      "name": "Rock_Chalk"
    },
    {
      "x": -14,
      "y": 27,
      "z": -3,
      "name": "Rock_Chalk"
    },
    {
      "x": -14,
      "y": 28,
      "z": -3,
      "name": "Rock_Chalk"
    },
    {
      "x": -14,
      "y": 29,
      "z": -3,
      "name": "Rock_Chalk"
    },
    {
      "x": -14,
      "y": 30,
      "z": -3,
      "name": "Rock_Chalk"
    },
    {
      "x": -14,
      "y": 31,
      "z": -3,
      "name": "Rock_Chalk"
    },
    {
      "x": -14,
      "y": 32,
      "z": -3,
      "name": "Rock_Chalk"
    },
    {
      "x": -14,
      "y": 33,
      "z": -3,
      "name": "Rock_Chalk"
    },
    {
      "x": -14,
      "y": 34,
      "z": -3,
      "name": "Rock_Chalk"
    },
    {
      "x": -14,
      "y": 35,
      "z": -3,
      "name": "Rock_Chalk"
    },
    {
      "x": -14,
      "y": 36,
      "z": -3,
      "name": "Rock_Chalk"
    },
    {
      "x": -14,
      "y": 37,
      "z": -3,
      "name": "Rock_Chalk"
    },
    {
      "x": -14,
      "y": 38,
      "z": -3,
      "name": "Rock_Chalk"
    },
    {
      "x": -14,
      "y": 17,
      "z": -2,
      "name": "Rock_Chalk"
    },
    {
      "x": -14,
      "y": 18,
      "z": -2,
      "name": "Rock_Chalk"
    },
    {
      "x": -14,
      "y": 19,
      "z": -2,
      "name": "Rock_Chalk"
    },
    {
      "x": -14,
      "y": 20,
      "z": -2,
      "name": "Rock_Chalk"
    },
    {
      "x": -14,
      "y": 21,
      "z": -2,
      "name": "Rock_Chalk"
    },
    {
      "x": -13,
      "y": 4,
      "z": -12,
      "name": "Rock_Marble"
    },
    {
      "x": -13,
      "y": 5,
      "z": -12,
      "name": "Rock_Marble"
    },
    {
      "x": -13,
      "y": 6,
      "z": -12,
      "name": "Rock_Marble"
    },
    {
      "x": -13,
      "y": 7,
      "z": -12,
      "name": "Rock_Marble"
    },
    {
      "x": -13,
      "y": 8,
      "z": -12,
      "name": "Rock_Marble"
    },
    {
      "x": -13,
      "y": 9,
      "z": -12,
      "name": "Rock_Marble"
    },
    {
      "x": -13,
      "y": 10,
      "z": -12,
      "name": "Rock_Marble"
    },
    {
      "x": -13,
      "y": 11,
      "z": -12,
      "name": "Rock_Marble"
    },
    {
      "x": -13,
      "y": 12,
      "z": -12,
      "name": "Rock_Marble"
    },
    {
      "x": -13,
      "y": 13,
      "z": -12,
      "name": "Rock_Marble"
    },
    {
      "x": -13,
      "y": 14,
      "z": -12,
      "name": "Rock_Marble"
    },
    {
      "x": -13,
      "y": 15,
      "z": -12,
      "name": "Rock_Marble"
    },
    {
      "x": -13,
      "y": 16,
      "z": -12,
      "name": "Rock_Marble"
    },
    {
      "x": -13,
      "y": 17,
      "z": -12,
      "name": "Rock_Marble"
    },
    {
      "x": -13,
      "y": 18,
      "z": -12,
      "name": "Rock_Marble"
    },
    {
      "x": -13,
      "y": 19,
      "z": -12,
      "name": "Rock_Marble"
    },
    {
      "x": -13,
      "y": 20,
      "z": -12,
      "name": "Rock_Marble"
    },
    {
      "x": -13,
      "y": 21,
      "z": -12,
      "name": "Rock_Marble"
    },
    {
      "x": -13,
      "y": 22,
      "z": -12,
      "name": "Rock_Marble"
    },
    {
      "x": -13,
      "y": 23,
      "z": -12,
      "name": "Rock_Marble"
    },
    {
      "x": -13,
      "y": 24,
      "z": -12,
      "name": "Rock_Marble"
    },
    {
      "x": -13,
      "y": 25,
      "z": -12,
      "name": "Rock_Marble"
    },
    {
      "x": -13,
      "y": 26,
      "z": -12,
      "name": "Rock_Marble"
    },
    {
      "x": -13,
      "y": 27,
      "z": -12,
      "name": "Rock_Chalk"
    },
    {
      "x": -13,
      "y": 28,
      "z": -12,
      "name": "Rock_Chalk"
    },
    {
      "x": -13,
      "y": 29,
      "z": -12,
      "name": "Rock_Chalk"
    },
    {
      "x": -13,
      "y": 30,
      "z": -12,
      "name": "Rock_Chalk"
    },
    {
      "x": -13,
      "y": 31,
      "z": -12,
      "name": "Rock_Chalk"
    },
    {
      "x": -13,
      "y": 32,
      "z": -12,
      "name": "Rock_Chalk"
    },
    {
      "x": -13,
      "y": 33,
      "z": -12,
      "name": "Rock_Chalk"
    },
    {
      "x": -13,
      "y": 34,
      "z": -12,
      "name": "Rock_Chalk"
    },
    {
      "x": -13,
      "y": 35,
      "z": -12,
      "name": "Rock_Chalk"
    },
    {
      "x": -13,
      "y": 36,
      "z": -12,
      "name": "Rock_Chalk"
    },
    {
      "x": -13,
      "y": 37,
      "z": -12,
      "name": "Rock_Chalk"
    },
    {
      "x": -13,
      "y": 38,
      "z": -12,
      "name": "Rock_Chalk"
    },
    {
      "x": -13,
      "y": 39,
      "z": -12,
      "name": "Rock_Chalk"
    },
    {
      "x": -13,
      "y": 40,
      "z": -12,
      "name": "Rock_Chalk"
    },
    {
      "x": -13,
      "y": 41,
      "z": -12,
      "name": "Rock_Chalk"
    },
    {
      "x": -13,
      "y": 3,
      "z": -11,
      "name": "Rock_Marble"
    },
    {
      "x": -13,
      "y": 4,
      "z": -11,
      "name": "Rock_Marble"
    },
    {
      "x": -13,
      "y": 5,
      "z": -11,
      "name": "Rock_Marble"
    },
    {
      "x": -13,
      "y": 6,
      "z": -11,
      "name": "Rock_Marble"
    },
    {
      "x": -13,
      "y": 7,
      "z": -11,
      "name": "Rock_Marble"
    },
    {
      "x": -13,
      "y": 8,
      "z": -11,
      "name": "Rock_Marble"
    },
    {
      "x": -13,
      "y": 9,
      "z": -11,
      "name": "Rock_Marble"
    },
    {
      "x": -13,
      "y": 10,
      "z": -11,
      "name": "Rock_Marble"
    },
    {
      "x": -13,
      "y": 11,
      "z": -11,
      "name": "Rock_Marble"
    },
    {
      "x": -13,
      "y": 12,
      "z": -11,
      "name": "Rock_Marble"
    },
    {
      "x": -13,
      "y": 13,
      "z": -11,
      "name": "Rock_Marble"
    },
    {
      "x": -13,
      "y": 14,
      "z": -11,
      "name": "Rock_Marble"
    },
    {
      "x": -13,
      "y": 15,
      "z": -11,
      "name": "Rock_Marble"
    },
    {
      "x": -13,
      "y": 16,
      "z": -11,
      "name": "Rock_Marble"
    },
    {
      "x": -13,
      "y": 17,
      "z": -11,
      "name": "Rock_Marble"
    },
    {
      "x": -13,
      "y": 18,
      "z": -11,
      "name": "Rock_Marble"
    },
    {
      "x": -13,
      "y": 19,
      "z": -11,
      "name": "Rock_Marble"
    },
    {
      "x": -13,
      "y": 20,
      "z": -11,
      "name": "Rock_Marble"
    },
    {
      "x": -13,
      "y": 21,
      "z": -11,
      "name": "Rock_Chalk"
    },
    {
      "x": -13,
      "y": 22,
      "z": -11,
      "name": "Rock_Chalk"
    },
    {
      "x": -13,
      "y": 23,
      "z": -11,
      "name": "Rock_Chalk"
    },
    {
      "x": -13,
      "y": 24,
      "z": -11,
      "name": "Rock_Chalk"
    },
    {
      "x": -13,
      "y": 25,
      "z": -11,
      "name": "Rock_Chalk"
    },
    {
      "x": -13,
      "y": 26,
      "z": -11,
      "name": "Rock_Chalk"
    },
    {
      "x": -13,
      "y": 27,
      "z": -11,
      "name": "Rock_Chalk"
    },
    {
      "x": -13,
      "y": 28,
      "z": -11,
      "name": "Rock_Chalk"
    },
    {
      "x": -13,
      "y": 29,
      "z": -11,
      "name": "Rock_Chalk"
    },
    {
      "x": -13,
      "y": 30,
      "z": -11,
      "name": "Rock_Chalk"
    },
    {
      "x": -13,
      "y": 31,
      "z": -11,
      "name": "Rock_Chalk"
    },
    {
      "x": -13,
      "y": 32,
      "z": -11,
      "name": "Rock_Chalk"
    },
    {
      "x": -13,
      "y": 33,
      "z": -11,
      "name": "Rock_Chalk"
    },
    {
      "x": -13,
      "y": 34,
      "z": -11,
      "name": "Rock_Chalk"
    },
    {
      "x": -13,
      "y": 35,
      "z": -11,
      "name": "Rock_Chalk"
    },
    {
      "x": -13,
      "y": 36,
      "z": -11,
      "name": "Rock_Chalk"
    },
    {
      "x": -13,
      "y": 37,
      "z": -11,
      "name": "Rock_Chalk"
    },
    {
      "x": -13,
      "y": 38,
      "z": -11,
      "name": "Rock_Chalk"
    },
    {
      "x": -13,
      "y": 39,
      "z": -11,
      "name": "Rock_Chalk"
    },
    {
      "x": -13,
      "y": 40,
      "z": -11,
      "name": "Rock_Chalk"
    },
    {
      "x": -13,
      "y": 41,
      "z": -11,
      "name": "Rock_Chalk"
    },
    {
      "x": -13,
      "y": 42,
      "z": -11,
      "name": "Rock_Chalk"
    },
    {
      "x": -13,
      "y": 43,
      "z": -11,
      "name": "Rock_Chalk"
    },
    {
      "x": -13,
      "y": 44,
      "z": -11,
      "name": "Rock_Chalk"
    },
    {
      "x": -13,
      "y": 45,
      "z": -11,
      "name": "Rock_Chalk"
    },
    {
      "x": -13,
      "y": 46,
      "z": -11,
      "name": "Rock_Chalk"
    },
    {
      "x": -13,
      "y": 47,
      "z": -11,
      "name": "Rock_Chalk"
    },
    {
      "x": -13,
      "y": 48,
      "z": -11,
      "name": "Rock_Chalk"
    },
    {
      "x": -13,
      "y": 49,
      "z": -11,
      "name": "Rock_Chalk"
    },
    {
      "x": -13,
      "y": 50,
      "z": -11,
      "name": "Rock_Chalk"
    },
    {
      "x": -13,
      "y": 51,
      "z": -11,
      "name": "Rock_Chalk"
    },
    {
      "x": -13,
      "y": 52,
      "z": -11,
      "name": "Rock_Chalk"
    },
    {
      "x": -13,
      "y": 53,
      "z": -11,
      "name": "Rock_Chalk"
    },
    {
      "x": -13,
      "y": 54,
      "z": -11,
      "name": "Rock_Chalk"
    },
    {
      "x": -13,
      "y": 3,
      "z": -10,
      "name": "Rock_Marble"
    },
    {
      "x": -13,
      "y": 4,
      "z": -10,
      "name": "Rock_Marble"
    },
    {
      "x": -13,
      "y": 5,
      "z": -10,
      "name": "Rock_Marble"
    },
    {
      "x": -13,
      "y": 6,
      "z": -10,
      "name": "Rock_Marble"
    },
    {
      "x": -13,
      "y": 7,
      "z": -10,
      "name": "Rock_Marble"
    },
    {
      "x": -13,
      "y": 8,
      "z": -10,
      "name": "Rock_Marble"
    },
    {
      "x": -13,
      "y": 9,
      "z": -10,
      "name": "Rock_Marble"
    },
    {
      "x": -13,
      "y": 10,
      "z": -10,
      "name": "Rock_Marble"
    },
    {
      "x": -13,
      "y": 11,
      "z": -10,
      "name": "Rock_Marble"
    },
    {
      "x": -13,
      "y": 12,
      "z": -10,
      "name": "Rock_Marble"
    },
    {
      "x": -13,
      "y": 13,
      "z": -10,
      "name": "Rock_Marble"
    },
    {
      "x": -13,
      "y": 14,
      "z": -10,
      "name": "Rock_Marble"
    },
    {
      "x": -13,
      "y": 15,
      "z": -10,
      "name": "Rock_Marble"
    },
    {
      "x": -13,
      "y": 16,
      "z": -10,
      "name": "Rock_Chalk"
    },
    {
      "x": -13,
      "y": 17,
      "z": -10,
      "name": "Rock_Chalk"
    },
    {
      "x": -13,
      "y": 18,
      "z": -10,
      "name": "Rock_Chalk"
    },
    {
      "x": -13,
      "y": 19,
      "z": -10,
      "name": "Rock_Chalk"
    },
    {
      "x": -13,
      "y": 20,
      "z": -10,
      "name": "Rock_Chalk"
    },
    {
      "x": -13,
      "y": 21,
      "z": -10,
      "name": "Rock_Chalk"
    },
    {
      "x": -13,
      "y": 22,
      "z": -10,
      "name": "Rock_Chalk"
    },
    {
      "x": -13,
      "y": 23,
      "z": -10,
      "name": "Rock_Chalk"
    },
    {
      "x": -13,
      "y": 24,
      "z": -10,
      "name": "Rock_Chalk"
    },
    {
      "x": -13,
      "y": 25,
      "z": -10,
      "name": "Rock_Chalk"
    },
    {
      "x": -13,
      "y": 26,
      "z": -10,
      "name": "Rock_Chalk"
    },
    {
      "x": -13,
      "y": 27,
      "z": -10,
      "name": "Rock_Chalk"
    },
    {
      "x": -13,
      "y": 28,
      "z": -10,
      "name": "Rock_Chalk"
    },
    {
      "x": -13,
      "y": 29,
      "z": -10,
      "name": "Rock_Chalk"
    },
    {
      "x": -13,
      "y": 30,
      "z": -10,
      "name": "Rock_Chalk"
    },
    {
      "x": -13,
      "y": 31,
      "z": -10,
      "name": "Rock_Chalk"
    },
    {
      "x": -13,
      "y": 32,
      "z": -10,
      "name": "Rock_Chalk"
    },
    {
      "x": -13,
      "y": 33,
      "z": -10,
      "name": "Rock_Chalk"
    },
    {
      "x": -13,
      "y": 34,
      "z": -10,
      "name": "Rock_Chalk"
    },
    {
      "x": -13,
      "y": 35,
      "z": -10,
      "name": "Rock_Chalk"
    },
    {
      "x": -13,
      "y": 36,
      "z": -10,
      "name": "Rock_Chalk"
    },
    {
      "x": -13,
      "y": 37,
      "z": -10,
      "name": "Rock_Chalk"
    },
    {
      "x": -13,
      "y": 38,
      "z": -10,
      "name": "Rock_Chalk"
    },
    {
      "x": -13,
      "y": 39,
      "z": -10,
      "name": "Rock_Chalk"
    },
    {
      "x": -13,
      "y": 40,
      "z": -10,
      "name": "Rock_Chalk"
    },
    {
      "x": -13,
      "y": 41,
      "z": -10,
      "name": "Rock_Chalk"
    },
    {
      "x": -13,
      "y": 42,
      "z": -10,
      "name": "Rock_Chalk"
    },
    {
      "x": -13,
      "y": 43,
      "z": -10,
      "name": "Rock_Chalk"
    },
    {
      "x": -13,
      "y": 44,
      "z": -10,
      "name": "Rock_Chalk"
    },
    {
      "x": -13,
      "y": 45,
      "z": -10,
      "name": "Rock_Chalk"
    },
    {
      "x": -13,
      "y": 46,
      "z": -10,
      "name": "Rock_Chalk"
    },
    {
      "x": -13,
      "y": 47,
      "z": -10,
      "name": "Rock_Chalk"
    },
    {
      "x": -13,
      "y": 48,
      "z": -10,
      "name": "Rock_Chalk"
    },
    {
      "x": -13,
      "y": 49,
      "z": -10,
      "name": "Rock_Chalk"
    },
    {
      "x": -13,
      "y": 50,
      "z": -10,
      "name": "Rock_Chalk"
    },
    {
      "x": -13,
      "y": 51,
      "z": -10,
      "name": "Rock_Chalk"
    },
    {
      "x": -13,
      "y": 52,
      "z": -10,
      "name": "Rock_Chalk"
    },
    {
      "x": -13,
      "y": 53,
      "z": -10,
      "name": "Rock_Chalk"
    },
    {
      "x": -13,
      "y": 54,
      "z": -10,
      "name": "Rock_Chalk"
    },
    {
      "x": -13,
      "y": 55,
      "z": -10,
      "name": "Rock_Marble"
    },
    {
      "x": -13,
      "y": 56,
      "z": -10,
      "name": "Rock_Marble"
    },
    {
      "x": -13,
      "y": 57,
      "z": -10,
      "name": "Rock_Marble"
    },
    {
      "x": -13,
      "y": 58,
      "z": -10,
      "name": "Rock_Marble"
    },
    {
      "x": -13,
      "y": 2,
      "z": -9,
      "name": "Rock_Marble"
    },
    {
      "x": -13,
      "y": 3,
      "z": -9,
      "name": "Rock_Marble"
    },
    {
      "x": -13,
      "y": 4,
      "z": -9,
      "name": "Rock_Marble"
    },
    {
      "x": -13,
      "y": 5,
      "z": -9,
      "name": "Rock_Marble"
    },
    {
      "x": -13,
      "y": 6,
      "z": -9,
      "name": "Rock_Marble"
    },
    {
      "x": -13,
      "y": 7,
      "z": -9,
      "name": "Rock_Marble"
    },
    {
      "x": -13,
      "y": 8,
      "z": -9,
      "name": "Rock_Marble"
    },
    {
      "x": -13,
      "y": 9,
      "z": -9,
      "name": "Rock_Marble"
    },
    {
      "x": -13,
      "y": 10,
      "z": -9,
      "name": "Rock_Marble"
    },
    {
      "x": -13,
      "y": 11,
      "z": -9,
      "name": "Rock_Marble"
    },
    {
      "x": -13,
      "y": 12,
      "z": -9,
      "name": "Rock_Marble"
    },
    {
      "x": -13,
      "y": 13,
      "z": -9,
      "name": "Rock_Marble"
    },
    {
      "x": -13,
      "y": 14,
      "z": -9,
      "name": "Rock_Chalk"
    },
    {
      "x": -13,
      "y": 15,
      "z": -9,
      "name": "Rock_Chalk"
    },
    {
      "x": -13,
      "y": 16,
      "z": -9,
      "name": "Rock_Chalk"
    },
    {
      "x": -13,
      "y": 17,
      "z": -9,
      "name": "Rock_Chalk"
    },
    {
      "x": -13,
      "y": 18,
      "z": -9,
      "name": "Rock_Chalk"
    },
    {
      "x": -13,
      "y": 19,
      "z": -9,
      "name": "Rock_Chalk"
    },
    {
      "x": -13,
      "y": 20,
      "z": -9,
      "name": "Rock_Chalk"
    },
    {
      "x": -13,
      "y": 21,
      "z": -9,
      "name": "Rock_Chalk"
    },
    {
      "x": -13,
      "y": 22,
      "z": -9,
      "name": "Rock_Chalk"
    },
    {
      "x": -13,
      "y": 23,
      "z": -9,
      "name": "Rock_Chalk"
    },
    {
      "x": -13,
      "y": 24,
      "z": -9,
      "name": "Rock_Chalk"
    },
    {
      "x": -13,
      "y": 25,
      "z": -9,
      "name": "Rock_Chalk"
    },
    {
      "x": -13,
      "y": 26,
      "z": -9,
      "name": "Rock_Chalk"
    },
    {
      "x": -13,
      "y": 27,
      "z": -9,
      "name": "Rock_Chalk"
    },
    {
      "x": -13,
      "y": 28,
      "z": -9,
      "name": "Rock_Chalk"
    },
    {
      "x": -13,
      "y": 29,
      "z": -9,
      "name": "Rock_Chalk"
    },
    {
      "x": -13,
      "y": 30,
      "z": -9,
      "name": "Rock_Chalk"
    },
    {
      "x": -13,
      "y": 31,
      "z": -9,
      "name": "Rock_Chalk"
    },
    {
      "x": -13,
      "y": 32,
      "z": -9,
      "name": "Rock_Chalk"
    },
    {
      "x": -13,
      "y": 33,
      "z": -9,
      "name": "Rock_Chalk"
    },
    {
      "x": -13,
      "y": 34,
      "z": -9,
      "name": "Rock_Chalk"
    },
    {
      "x": -13,
      "y": 35,
      "z": -9,
      "name": "Rock_Chalk"
    },
    {
      "x": -13,
      "y": 36,
      "z": -9,
      "name": "Rock_Chalk"
    },
    {
      "x": -13,
      "y": 37,
      "z": -9,
      "name": "Rock_Chalk"
    },
    {
      "x": -13,
      "y": 38,
      "z": -9,
      "name": "Rock_Chalk"
    },
    {
      "x": -13,
      "y": 39,
      "z": -9,
      "name": "Rock_Chalk"
    },
    {
      "x": -13,
      "y": 40,
      "z": -9,
      "name": "Rock_Chalk"
    },
    {
      "x": -13,
      "y": 41,
      "z": -9,
      "name": "Rock_Chalk"
    },
    {
      "x": -13,
      "y": 42,
      "z": -9,
      "name": "Rock_Chalk"
    },
    {
      "x": -13,
      "y": 43,
      "z": -9,
      "name": "Rock_Chalk"
    },
    {
      "x": -13,
      "y": 44,
      "z": -9,
      "name": "Rock_Chalk"
    },
    {
      "x": -13,
      "y": 45,
      "z": -9,
      "name": "Rock_Chalk"
    },
    {
      "x": -13,
      "y": 46,
      "z": -9,
      "name": "Rock_Chalk"
    },
    {
      "x": -13,
      "y": 47,
      "z": -9,
      "name": "Rock_Chalk"
    },
    {
      "x": -13,
      "y": 48,
      "z": -9,
      "name": "Rock_Chalk"
    },
    {
      "x": -13,
      "y": 49,
      "z": -9,
      "name": "Rock_Chalk"
    },
    {
      "x": -13,
      "y": 50,
      "z": -9,
      "name": "Rock_Chalk"
    },
    {
      "x": -13,
      "y": 51,
      "z": -9,
      "name": "Rock_Chalk"
    },
    {
      "x": -13,
      "y": 52,
      "z": -9,
      "name": "Rock_Chalk"
    },
    {
      "x": -13,
      "y": 53,
      "z": -9,
      "name": "Rock_Marble"
    },
    {
      "x": -13,
      "y": 54,
      "z": -9,
      "name": "Rock_Marble"
    },
    {
      "x": -13,
      "y": 55,
      "z": -9,
      "name": "Rock_Marble"
    },
    {
      "x": -13,
      "y": 56,
      "z": -9,
      "name": "Rock_Marble"
    },
    {
      "x": -13,
      "y": 57,
      "z": -9,
      "name": "Rock_Marble"
    },
    {
      "x": -13,
      "y": 58,
      "z": -9,
      "name": "Rock_Marble"
    },
    {
      "x": -13,
      "y": 59,
      "z": -9,
      "name": "Rock_Marble"
    },
    {
      "x": -13,
      "y": 60,
      "z": -9,
      "name": "Rock_Marble"
    },
    {
      "x": -13,
      "y": 2,
      "z": -8,
      "name": "Rock_Marble"
    },
    {
      "x": -13,
      "y": 3,
      "z": -8,
      "name": "Rock_Marble"
    },
    {
      "x": -13,
      "y": 4,
      "z": -8,
      "name": "Rock_Marble"
    },
    {
      "x": -13,
      "y": 5,
      "z": -8,
      "name": "Rock_Marble"
    },
    {
      "x": -13,
      "y": 6,
      "z": -8,
      "name": "Rock_Marble"
    },
    {
      "x": -13,
      "y": 7,
      "z": -8,
      "name": "Rock_Marble"
    },
    {
      "x": -13,
      "y": 8,
      "z": -8,
      "name": "Rock_Marble"
    },
    {
      "x": -13,
      "y": 9,
      "z": -8,
      "name": "Rock_Marble"
    },
    {
      "x": -13,
      "y": 10,
      "z": -8,
      "name": "Rock_Marble"
    },
    {
      "x": -13,
      "y": 11,
      "z": -8,
      "name": "Rock_Marble"
    },
    {
      "x": -13,
      "y": 12,
      "z": -8,
      "name": "Rock_Chalk"
    },
    {
      "x": -13,
      "y": 13,
      "z": -8,
      "name": "Rock_Chalk"
    },
    {
      "x": -13,
      "y": 14,
      "z": -8,
      "name": "Rock_Chalk"
    },
    {
      "x": -13,
      "y": 15,
      "z": -8,
      "name": "Rock_Chalk"
    },
    {
      "x": -13,
      "y": 16,
      "z": -8,
      "name": "Rock_Chalk"
    },
    {
      "x": -13,
      "y": 17,
      "z": -8,
      "name": "Rock_Chalk"
    },
    {
      "x": -13,
      "y": 18,
      "z": -8,
      "name": "Rock_Chalk"
    },
    {
      "x": -13,
      "y": 19,
      "z": -8,
      "name": "Rock_Chalk"
    },
    {
      "x": -13,
      "y": 20,
      "z": -8,
      "name": "Rock_Chalk"
    },
    {
      "x": -13,
      "y": 21,
      "z": -8,
      "name": "Rock_Chalk"
    },
    {
      "x": -13,
      "y": 22,
      "z": -8,
      "name": "Rock_Chalk"
    },
    {
      "x": -13,
      "y": 23,
      "z": -8,
      "name": "Rock_Chalk"
    },
    {
      "x": -13,
      "y": 24,
      "z": -8,
      "name": "Rock_Chalk"
    },
    {
      "x": -13,
      "y": 25,
      "z": -8,
      "name": "Rock_Chalk"
    },
    {
      "x": -13,
      "y": 26,
      "z": -8,
      "name": "Rock_Chalk"
    },
    {
      "x": -13,
      "y": 27,
      "z": -8,
      "name": "Rock_Chalk"
    },
    {
      "x": -13,
      "y": 28,
      "z": -8,
      "name": "Rock_Chalk"
    },
    {
      "x": -13,
      "y": 29,
      "z": -8,
      "name": "Rock_Chalk"
    },
    {
      "x": -13,
      "y": 30,
      "z": -8,
      "name": "Rock_Chalk"
    },
    {
      "x": -13,
      "y": 31,
      "z": -8,
      "name": "Rock_Chalk"
    },
    {
      "x": -13,
      "y": 32,
      "z": -8,
      "name": "Rock_Chalk"
    },
    {
      "x": -13,
      "y": 33,
      "z": -8,
      "name": "Rock_Chalk"
    },
    {
      "x": -13,
      "y": 34,
      "z": -8,
      "name": "Rock_Chalk"
    },
    {
      "x": -13,
      "y": 35,
      "z": -8,
      "name": "Rock_Chalk"
    },
    {
      "x": -13,
      "y": 36,
      "z": -8,
      "name": "Rock_Chalk"
    },
    {
      "x": -13,
      "y": 37,
      "z": -8,
      "name": "Rock_Chalk"
    },
    {
      "x": -13,
      "y": 38,
      "z": -8,
      "name": "Rock_Chalk"
    },
    {
      "x": -13,
      "y": 39,
      "z": -8,
      "name": "Rock_Chalk"
    },
    {
      "x": -13,
      "y": 40,
      "z": -8,
      "name": "Rock_Chalk"
    },
    {
      "x": -13,
      "y": 41,
      "z": -8,
      "name": "Rock_Chalk"
    },
    {
      "x": -13,
      "y": 42,
      "z": -8,
      "name": "Rock_Chalk"
    },
    {
      "x": -13,
      "y": 43,
      "z": -8,
      "name": "Rock_Chalk"
    },
    {
      "x": -13,
      "y": 44,
      "z": -8,
      "name": "Rock_Chalk"
    },
    {
      "x": -13,
      "y": 45,
      "z": -8,
      "name": "Rock_Chalk"
    },
    {
      "x": -13,
      "y": 46,
      "z": -8,
      "name": "Rock_Chalk"
    },
    {
      "x": -13,
      "y": 47,
      "z": -8,
      "name": "Rock_Chalk"
    },
    {
      "x": -13,
      "y": 48,
      "z": -8,
      "name": "Rock_Chalk"
    },
    {
      "x": -13,
      "y": 49,
      "z": -8,
      "name": "Rock_Chalk"
    },
    {
      "x": -13,
      "y": 50,
      "z": -8,
      "name": "Rock_Chalk"
    },
    {
      "x": -13,
      "y": 51,
      "z": -8,
      "name": "Rock_Marble"
    },
    {
      "x": -13,
      "y": 52,
      "z": -8,
      "name": "Rock_Marble"
    },
    {
      "x": -13,
      "y": 53,
      "z": -8,
      "name": "Rock_Marble"
    },
    {
      "x": -13,
      "y": 54,
      "z": -8,
      "name": "Rock_Marble"
    },
    {
      "x": -13,
      "y": 55,
      "z": -8,
      "name": "Rock_Marble"
    },
    {
      "x": -13,
      "y": 56,
      "z": -8,
      "name": "Rock_Marble"
    },
    {
      "x": -13,
      "y": 57,
      "z": -8,
      "name": "Rock_Marble"
    },
    {
      "x": -13,
      "y": 58,
      "z": -8,
      "name": "Rock_Marble"
    },
    {
      "x": -13,
      "y": 59,
      "z": -8,
      "name": "Rock_Marble"
    },
    {
      "x": -13,
      "y": 60,
      "z": -8,
      "name": "Rock_Marble"
    },
    {
      "x": -13,
      "y": 61,
      "z": -8,
      "name": "Rock_Marble"
    },
    {
      "x": -13,
      "y": 2,
      "z": -7,
      "name": "Rock_Marble"
    },
    {
      "x": -13,
      "y": 3,
      "z": -7,
      "name": "Rock_Marble"
    },
    {
      "x": -13,
      "y": 4,
      "z": -7,
      "name": "Rock_Marble"
    },
    {
      "x": -13,
      "y": 5,
      "z": -7,
      "name": "Rock_Marble"
    },
    {
      "x": -13,
      "y": 6,
      "z": -7,
      "name": "Rock_Marble"
    },
    {
      "x": -13,
      "y": 7,
      "z": -7,
      "name": "Rock_Marble"
    },
    {
      "x": -13,
      "y": 8,
      "z": -7,
      "name": "Rock_Marble"
    },
    {
      "x": -13,
      "y": 9,
      "z": -7,
      "name": "Rock_Marble"
    },
    {
      "x": -13,
      "y": 10,
      "z": -7,
      "name": "Rock_Marble"
    },
    {
      "x": -13,
      "y": 11,
      "z": -7,
      "name": "Rock_Marble"
    },
    {
      "x": -13,
      "y": 12,
      "z": -7,
      "name": "Rock_Chalk"
    },
    {
      "x": -13,
      "y": 13,
      "z": -7,
      "name": "Rock_Chalk"
    },
    {
      "x": -13,
      "y": 14,
      "z": -7,
      "name": "Rock_Chalk"
    },
    {
      "x": -13,
      "y": 15,
      "z": -7,
      "name": "Rock_Chalk"
    },
    {
      "x": -13,
      "y": 16,
      "z": -7,
      "name": "Rock_Chalk"
    },
    {
      "x": -13,
      "y": 17,
      "z": -7,
      "name": "Rock_Chalk"
    },
    {
      "x": -13,
      "y": 18,
      "z": -7,
      "name": "Rock_Chalk"
    },
    {
      "x": -13,
      "y": 19,
      "z": -7,
      "name": "Rock_Chalk"
    },
    {
      "x": -13,
      "y": 20,
      "z": -7,
      "name": "Rock_Chalk"
    },
    {
      "x": -13,
      "y": 21,
      "z": -7,
      "name": "Rock_Chalk"
    },
    {
      "x": -13,
      "y": 22,
      "z": -7,
      "name": "Rock_Chalk"
    },
    {
      "x": -13,
      "y": 23,
      "z": -7,
      "name": "Rock_Chalk"
    },
    {
      "x": -13,
      "y": 24,
      "z": -7,
      "name": "Rock_Chalk"
    },
    {
      "x": -13,
      "y": 25,
      "z": -7,
      "name": "Rock_Chalk"
    },
    {
      "x": -13,
      "y": 26,
      "z": -7,
      "name": "Rock_Chalk"
    },
    {
      "x": -13,
      "y": 27,
      "z": -7,
      "name": "Rock_Chalk"
    },
    {
      "x": -13,
      "y": 28,
      "z": -7,
      "name": "Rock_Chalk"
    },
    {
      "x": -13,
      "y": 29,
      "z": -7,
      "name": "Rock_Chalk"
    },
    {
      "x": -13,
      "y": 30,
      "z": -7,
      "name": "Rock_Chalk"
    },
    {
      "x": -13,
      "y": 31,
      "z": -7,
      "name": "Rock_Chalk"
    },
    {
      "x": -13,
      "y": 32,
      "z": -7,
      "name": "Rock_Chalk"
    },
    {
      "x": -13,
      "y": 33,
      "z": -7,
      "name": "Rock_Chalk"
    },
    {
      "x": -13,
      "y": 34,
      "z": -7,
      "name": "Rock_Chalk"
    },
    {
      "x": -13,
      "y": 35,
      "z": -7,
      "name": "Rock_Chalk"
    },
    {
      "x": -13,
      "y": 36,
      "z": -7,
      "name": "Rock_Chalk"
    },
    {
      "x": -13,
      "y": 37,
      "z": -7,
      "name": "Rock_Chalk"
    },
    {
      "x": -13,
      "y": 38,
      "z": -7,
      "name": "Rock_Chalk"
    },
    {
      "x": -13,
      "y": 39,
      "z": -7,
      "name": "Rock_Chalk"
    },
    {
      "x": -13,
      "y": 40,
      "z": -7,
      "name": "Rock_Chalk"
    },
    {
      "x": -13,
      "y": 41,
      "z": -7,
      "name": "Rock_Chalk"
    },
    {
      "x": -13,
      "y": 42,
      "z": -7,
      "name": "Rock_Chalk"
    },
    {
      "x": -13,
      "y": 43,
      "z": -7,
      "name": "Rock_Chalk"
    },
    {
      "x": -13,
      "y": 44,
      "z": -7,
      "name": "Rock_Chalk"
    },
    {
      "x": -13,
      "y": 45,
      "z": -7,
      "name": "Rock_Chalk"
    },
    {
      "x": -13,
      "y": 46,
      "z": -7,
      "name": "Rock_Chalk"
    },
    {
      "x": -13,
      "y": 47,
      "z": -7,
      "name": "Rock_Chalk"
    },
    {
      "x": -13,
      "y": 48,
      "z": -7,
      "name": "Rock_Chalk"
    },
    {
      "x": -13,
      "y": 49,
      "z": -7,
      "name": "Rock_Marble"
    },
    {
      "x": -13,
      "y": 50,
      "z": -7,
      "name": "Rock_Marble"
    },
    {
      "x": -13,
      "y": 51,
      "z": -7,
      "name": "Rock_Marble"
    },
    {
      "x": -13,
      "y": 52,
      "z": -7,
      "name": "Rock_Marble"
    },
    {
      "x": -13,
      "y": 53,
      "z": -7,
      "name": "Rock_Marble"
    },
    {
      "x": -13,
      "y": 54,
      "z": -7,
      "name": "Rock_Marble"
    },
    {
      "x": -13,
      "y": 55,
      "z": -7,
      "name": "Rock_Marble"
    },
    {
      "x": -13,
      "y": 56,
      "z": -7,
      "name": "Rock_Marble"
    },
    {
      "x": -13,
      "y": 57,
      "z": -7,
      "name": "Rock_Marble"
    },
    {
      "x": -13,
      "y": 58,
      "z": -7,
      "name": "Rock_Marble"
    },
    {
      "x": -13,
      "y": 59,
      "z": -7,
      "name": "Rock_Marble"
    },
    {
      "x": -13,
      "y": 60,
      "z": -7,
      "name": "Rock_Marble"
    },
    {
      "x": -13,
      "y": 61,
      "z": -7,
      "name": "Rock_Marble"
    },
    {
      "x": -13,
      "y": 2,
      "z": -6,
      "name": "Rock_Marble"
    },
    {
      "x": -13,
      "y": 3,
      "z": -6,
      "name": "Rock_Marble"
    },
    {
      "x": -13,
      "y": 4,
      "z": -6,
      "name": "Rock_Marble"
    },
    {
      "x": -13,
      "y": 5,
      "z": -6,
      "name": "Rock_Marble"
    },
    {
      "x": -13,
      "y": 6,
      "z": -6,
      "name": "Rock_Marble"
    },
    {
      "x": -13,
      "y": 7,
      "z": -6,
      "name": "Rock_Marble"
    },
    {
      "x": -13,
      "y": 8,
      "z": -6,
      "name": "Rock_Marble"
    },
    {
      "x": -13,
      "y": 9,
      "z": -6,
      "name": "Rock_Marble"
    },
    {
      "x": -13,
      "y": 10,
      "z": -6,
      "name": "Rock_Marble"
    },
    {
      "x": -13,
      "y": 11,
      "z": -6,
      "name": "Rock_Marble"
    },
    {
      "x": -13,
      "y": 12,
      "z": -6,
      "name": "Rock_Chalk"
    },
    {
      "x": -13,
      "y": 13,
      "z": -6,
      "name": "Rock_Chalk"
    },
    {
      "x": -13,
      "y": 14,
      "z": -6,
      "name": "Rock_Chalk"
    },
    {
      "x": -13,
      "y": 15,
      "z": -6,
      "name": "Rock_Chalk"
    },
    {
      "x": -13,
      "y": 16,
      "z": -6,
      "name": "Rock_Chalk"
    },
    {
      "x": -13,
      "y": 17,
      "z": -6,
      "name": "Rock_Chalk"
    },
    {
      "x": -13,
      "y": 18,
      "z": -6,
      "name": "Rock_Chalk"
    },
    {
      "x": -13,
      "y": 19,
      "z": -6,
      "name": "Rock_Chalk"
    },
    {
      "x": -13,
      "y": 20,
      "z": -6,
      "name": "Rock_Chalk"
    },
    {
      "x": -13,
      "y": 21,
      "z": -6,
      "name": "Rock_Chalk"
    },
    {
      "x": -13,
      "y": 22,
      "z": -6,
      "name": "Rock_Chalk"
    },
    {
      "x": -13,
      "y": 23,
      "z": -6,
      "name": "Rock_Chalk"
    },
    {
      "x": -13,
      "y": 24,
      "z": -6,
      "name": "Rock_Chalk"
    },
    {
      "x": -13,
      "y": 25,
      "z": -6,
      "name": "Rock_Chalk"
    },
    {
      "x": -13,
      "y": 26,
      "z": -6,
      "name": "Rock_Chalk"
    },
    {
      "x": -13,
      "y": 27,
      "z": -6,
      "name": "Rock_Chalk"
    },
    {
      "x": -13,
      "y": 28,
      "z": -6,
      "name": "Rock_Chalk"
    },
    {
      "x": -13,
      "y": 29,
      "z": -6,
      "name": "Rock_Chalk"
    },
    {
      "x": -13,
      "y": 30,
      "z": -6,
      "name": "Rock_Chalk"
    },
    {
      "x": -13,
      "y": 31,
      "z": -6,
      "name": "Rock_Chalk"
    },
    {
      "x": -13,
      "y": 32,
      "z": -6,
      "name": "Rock_Chalk"
    },
    {
      "x": -13,
      "y": 33,
      "z": -6,
      "name": "Rock_Chalk"
    },
    {
      "x": -13,
      "y": 34,
      "z": -6,
      "name": "Rock_Chalk"
    },
    {
      "x": -13,
      "y": 35,
      "z": -6,
      "name": "Rock_Chalk"
    },
    {
      "x": -13,
      "y": 36,
      "z": -6,
      "name": "Rock_Chalk"
    },
    {
      "x": -13,
      "y": 37,
      "z": -6,
      "name": "Rock_Chalk"
    },
    {
      "x": -13,
      "y": 38,
      "z": -6,
      "name": "Rock_Chalk"
    },
    {
      "x": -13,
      "y": 39,
      "z": -6,
      "name": "Rock_Chalk"
    },
    {
      "x": -13,
      "y": 40,
      "z": -6,
      "name": "Rock_Chalk"
    },
    {
      "x": -13,
      "y": 41,
      "z": -6,
      "name": "Rock_Chalk"
    },
    {
      "x": -13,
      "y": 42,
      "z": -6,
      "name": "Rock_Chalk"
    },
    {
      "x": -13,
      "y": 43,
      "z": -6,
      "name": "Rock_Chalk"
    },
    {
      "x": -13,
      "y": 44,
      "z": -6,
      "name": "Rock_Chalk"
    },
    {
      "x": -13,
      "y": 45,
      "z": -6,
      "name": "Rock_Chalk"
    },
    {
      "x": -13,
      "y": 46,
      "z": -6,
      "name": "Rock_Chalk"
    },
    {
      "x": -13,
      "y": 47,
      "z": -6,
      "name": "Rock_Marble"
    },
    {
      "x": -13,
      "y": 48,
      "z": -6,
      "name": "Rock_Marble"
    },
    {
      "x": -13,
      "y": 49,
      "z": -6,
      "name": "Rock_Marble"
    },
    {
      "x": -13,
      "y": 50,
      "z": -6,
      "name": "Rock_Marble"
    },
    {
      "x": -13,
      "y": 51,
      "z": -6,
      "name": "Rock_Marble"
    },
    {
      "x": -13,
      "y": 52,
      "z": -6,
      "name": "Rock_Marble"
    },
    {
      "x": -13,
      "y": 53,
      "z": -6,
      "name": "Rock_Marble"
    },
    {
      "x": -13,
      "y": 54,
      "z": -6,
      "name": "Rock_Marble"
    },
    {
      "x": -13,
      "y": 55,
      "z": -6,
      "name": "Rock_Marble"
    },
    {
      "x": -13,
      "y": 56,
      "z": -6,
      "name": "Rock_Marble"
    },
    {
      "x": -13,
      "y": 57,
      "z": -6,
      "name": "Rock_Marble"
    },
    {
      "x": -13,
      "y": 58,
      "z": -6,
      "name": "Rock_Marble"
    },
    {
      "x": -13,
      "y": 59,
      "z": -6,
      "name": "Rock_Marble"
    },
    {
      "x": -13,
      "y": 60,
      "z": -6,
      "name": "Rock_Marble"
    },
    {
      "x": -13,
      "y": 2,
      "z": -5,
      "name": "Rock_Marble"
    },
    {
      "x": -13,
      "y": 3,
      "z": -5,
      "name": "Rock_Marble"
    },
    {
      "x": -13,
      "y": 4,
      "z": -5,
      "name": "Rock_Marble"
    },
    {
      "x": -13,
      "y": 5,
      "z": -5,
      "name": "Rock_Marble"
    },
    {
      "x": -13,
      "y": 6,
      "z": -5,
      "name": "Rock_Marble"
    },
    {
      "x": -13,
      "y": 7,
      "z": -5,
      "name": "Rock_Marble"
    },
    {
      "x": -13,
      "y": 8,
      "z": -5,
      "name": "Rock_Marble"
    },
    {
      "x": -13,
      "y": 9,
      "z": -5,
      "name": "Rock_Marble"
    },
    {
      "x": -13,
      "y": 10,
      "z": -5,
      "name": "Rock_Marble"
    },
    {
      "x": -13,
      "y": 11,
      "z": -5,
      "name": "Rock_Marble"
    },
    {
      "x": -13,
      "y": 12,
      "z": -5,
      "name": "Rock_Chalk"
    },
    {
      "x": -13,
      "y": 13,
      "z": -5,
      "name": "Rock_Chalk"
    },
    {
      "x": -13,
      "y": 14,
      "z": -5,
      "name": "Rock_Chalk"
    },
    {
      "x": -13,
      "y": 15,
      "z": -5,
      "name": "Rock_Chalk"
    },
    {
      "x": -13,
      "y": 16,
      "z": -5,
      "name": "Rock_Chalk"
    },
    {
      "x": -13,
      "y": 17,
      "z": -5,
      "name": "Rock_Chalk"
    },
    {
      "x": -13,
      "y": 18,
      "z": -5,
      "name": "Rock_Chalk"
    },
    {
      "x": -13,
      "y": 19,
      "z": -5,
      "name": "Rock_Chalk"
    },
    {
      "x": -13,
      "y": 20,
      "z": -5,
      "name": "Rock_Chalk"
    },
    {
      "x": -13,
      "y": 21,
      "z": -5,
      "name": "Rock_Chalk"
    },
    {
      "x": -13,
      "y": 22,
      "z": -5,
      "name": "Rock_Chalk"
    },
    {
      "x": -13,
      "y": 23,
      "z": -5,
      "name": "Rock_Chalk"
    },
    {
      "x": -13,
      "y": 24,
      "z": -5,
      "name": "Rock_Chalk"
    },
    {
      "x": -13,
      "y": 25,
      "z": -5,
      "name": "Rock_Chalk"
    },
    {
      "x": -13,
      "y": 26,
      "z": -5,
      "name": "Rock_Chalk"
    },
    {
      "x": -13,
      "y": 27,
      "z": -5,
      "name": "Rock_Chalk"
    },
    {
      "x": -13,
      "y": 28,
      "z": -5,
      "name": "Rock_Chalk"
    },
    {
      "x": -13,
      "y": 29,
      "z": -5,
      "name": "Rock_Chalk"
    },
    {
      "x": -13,
      "y": 30,
      "z": -5,
      "name": "Rock_Chalk"
    },
    {
      "x": -13,
      "y": 31,
      "z": -5,
      "name": "Rock_Chalk"
    },
    {
      "x": -13,
      "y": 32,
      "z": -5,
      "name": "Rock_Chalk"
    },
    {
      "x": -13,
      "y": 33,
      "z": -5,
      "name": "Rock_Chalk"
    },
    {
      "x": -13,
      "y": 34,
      "z": -5,
      "name": "Rock_Chalk"
    },
    {
      "x": -13,
      "y": 35,
      "z": -5,
      "name": "Rock_Chalk"
    },
    {
      "x": -13,
      "y": 36,
      "z": -5,
      "name": "Rock_Chalk"
    },
    {
      "x": -13,
      "y": 37,
      "z": -5,
      "name": "Rock_Chalk"
    },
    {
      "x": -13,
      "y": 38,
      "z": -5,
      "name": "Rock_Chalk"
    },
    {
      "x": -13,
      "y": 39,
      "z": -5,
      "name": "Rock_Chalk"
    },
    {
      "x": -13,
      "y": 40,
      "z": -5,
      "name": "Rock_Chalk"
    },
    {
      "x": -13,
      "y": 41,
      "z": -5,
      "name": "Rock_Chalk"
    },
    {
      "x": -13,
      "y": 42,
      "z": -5,
      "name": "Rock_Chalk"
    },
    {
      "x": -13,
      "y": 43,
      "z": -5,
      "name": "Rock_Chalk"
    },
    {
      "x": -13,
      "y": 44,
      "z": -5,
      "name": "Rock_Chalk"
    },
    {
      "x": -13,
      "y": 45,
      "z": -5,
      "name": "Rock_Chalk"
    },
    {
      "x": -13,
      "y": 46,
      "z": -5,
      "name": "Rock_Marble"
    },
    {
      "x": -13,
      "y": 47,
      "z": -5,
      "name": "Rock_Marble"
    },
    {
      "x": -13,
      "y": 48,
      "z": -5,
      "name": "Rock_Marble"
    },
    {
      "x": -13,
      "y": 49,
      "z": -5,
      "name": "Rock_Marble"
    },
    {
      "x": -13,
      "y": 50,
      "z": -5,
      "name": "Rock_Marble"
    },
    {
      "x": -13,
      "y": 51,
      "z": -5,
      "name": "Rock_Marble"
    },
    {
      "x": -13,
      "y": 52,
      "z": -5,
      "name": "Rock_Marble"
    },
    {
      "x": -13,
      "y": 53,
      "z": -5,
      "name": "Rock_Marble"
    },
    {
      "x": -13,
      "y": 54,
      "z": -5,
      "name": "Rock_Marble"
    },
    {
      "x": -13,
      "y": 55,
      "z": -5,
      "name": "Rock_Marble"
    },
    {
      "x": -13,
      "y": 56,
      "z": -5,
      "name": "Rock_Marble"
    },
    {
      "x": -13,
      "y": 57,
      "z": -5,
      "name": "Rock_Marble"
    },
    {
      "x": -13,
      "y": 2,
      "z": -4,
      "name": "Rock_Marble"
    },
    {
      "x": -13,
      "y": 3,
      "z": -4,
      "name": "Rock_Marble"
    },
    {
      "x": -13,
      "y": 4,
      "z": -4,
      "name": "Rock_Marble"
    },
    {
      "x": -13,
      "y": 5,
      "z": -4,
      "name": "Rock_Marble"
    },
    {
      "x": -13,
      "y": 6,
      "z": -4,
      "name": "Rock_Marble"
    },
    {
      "x": -13,
      "y": 7,
      "z": -4,
      "name": "Rock_Marble"
    },
    {
      "x": -13,
      "y": 8,
      "z": -4,
      "name": "Rock_Marble"
    },
    {
      "x": -13,
      "y": 9,
      "z": -4,
      "name": "Rock_Marble"
    },
    {
      "x": -13,
      "y": 10,
      "z": -4,
      "name": "Rock_Marble"
    },
    {
      "x": -13,
      "y": 11,
      "z": -4,
      "name": "Rock_Marble"
    },
    {
      "x": -13,
      "y": 12,
      "z": -4,
      "name": "Rock_Chalk"
    },
    {
      "x": -13,
      "y": 13,
      "z": -4,
      "name": "Rock_Chalk"
    },
    {
      "x": -13,
      "y": 14,
      "z": -4,
      "name": "Rock_Chalk"
    },
    {
      "x": -13,
      "y": 15,
      "z": -4,
      "name": "Rock_Chalk"
    },
    {
      "x": -13,
      "y": 16,
      "z": -4,
      "name": "Rock_Chalk"
    },
    {
      "x": -13,
      "y": 17,
      "z": -4,
      "name": "Rock_Chalk"
    },
    {
      "x": -13,
      "y": 18,
      "z": -4,
      "name": "Rock_Chalk"
    },
    {
      "x": -13,
      "y": 19,
      "z": -4,
      "name": "Rock_Chalk"
    },
    {
      "x": -13,
      "y": 20,
      "z": -4,
      "name": "Rock_Chalk"
    },
    {
      "x": -13,
      "y": 21,
      "z": -4,
      "name": "Rock_Chalk"
    },
    {
      "x": -13,
      "y": 22,
      "z": -4,
      "name": "Rock_Chalk"
    },
    {
      "x": -13,
      "y": 23,
      "z": -4,
      "name": "Rock_Chalk"
    },
    {
      "x": -13,
      "y": 24,
      "z": -4,
      "name": "Rock_Chalk"
    },
    {
      "x": -13,
      "y": 25,
      "z": -4,
      "name": "Rock_Chalk"
    },
    {
      "x": -13,
      "y": 26,
      "z": -4,
      "name": "Rock_Chalk"
    },
    {
      "x": -13,
      "y": 27,
      "z": -4,
      "name": "Rock_Chalk"
    },
    {
      "x": -13,
      "y": 28,
      "z": -4,
      "name": "Rock_Chalk"
    },
    {
      "x": -13,
      "y": 29,
      "z": -4,
      "name": "Rock_Chalk"
    },
    {
      "x": -13,
      "y": 30,
      "z": -4,
      "name": "Rock_Chalk"
    },
    {
      "x": -13,
      "y": 31,
      "z": -4,
      "name": "Rock_Chalk"
    },
    {
      "x": -13,
      "y": 32,
      "z": -4,
      "name": "Rock_Chalk"
    },
    {
      "x": -13,
      "y": 33,
      "z": -4,
      "name": "Rock_Chalk"
    },
    {
      "x": -13,
      "y": 34,
      "z": -4,
      "name": "Rock_Chalk"
    },
    {
      "x": -13,
      "y": 35,
      "z": -4,
      "name": "Rock_Chalk"
    },
    {
      "x": -13,
      "y": 36,
      "z": -4,
      "name": "Rock_Chalk"
    },
    {
      "x": -13,
      "y": 37,
      "z": -4,
      "name": "Rock_Chalk"
    },
    {
      "x": -13,
      "y": 38,
      "z": -4,
      "name": "Rock_Chalk"
    },
    {
      "x": -13,
      "y": 39,
      "z": -4,
      "name": "Rock_Chalk"
    },
    {
      "x": -13,
      "y": 40,
      "z": -4,
      "name": "Rock_Chalk"
    },
    {
      "x": -13,
      "y": 41,
      "z": -4,
      "name": "Rock_Chalk"
    },
    {
      "x": -13,
      "y": 42,
      "z": -4,
      "name": "Rock_Chalk"
    },
    {
      "x": -13,
      "y": 43,
      "z": -4,
      "name": "Rock_Chalk"
    },
    {
      "x": -13,
      "y": 44,
      "z": -4,
      "name": "Rock_Chalk"
    },
    {
      "x": -13,
      "y": 45,
      "z": -4,
      "name": "Rock_Marble"
    },
    {
      "x": -13,
      "y": 46,
      "z": -4,
      "name": "Rock_Marble"
    },
    {
      "x": -13,
      "y": 47,
      "z": -4,
      "name": "Rock_Marble"
    },
    {
      "x": -13,
      "y": 48,
      "z": -4,
      "name": "Rock_Marble"
    },
    {
      "x": -13,
      "y": 49,
      "z": -4,
      "name": "Rock_Marble"
    },
    {
      "x": -13,
      "y": 50,
      "z": -4,
      "name": "Rock_Marble"
    },
    {
      "x": -13,
      "y": 51,
      "z": -4,
      "name": "Rock_Marble"
    },
    {
      "x": -13,
      "y": 52,
      "z": -4,
      "name": "Rock_Marble"
    },
    {
      "x": -13,
      "y": 2,
      "z": -3,
      "name": "Rock_Marble"
    },
    {
      "x": -13,
      "y": 3,
      "z": -3,
      "name": "Rock_Marble"
    },
    {
      "x": -13,
      "y": 4,
      "z": -3,
      "name": "Rock_Marble"
    },
    {
      "x": -13,
      "y": 5,
      "z": -3,
      "name": "Rock_Marble"
    },
    {
      "x": -13,
      "y": 6,
      "z": -3,
      "name": "Rock_Marble"
    },
    {
      "x": -13,
      "y": 7,
      "z": -3,
      "name": "Rock_Marble"
    },
    {
      "x": -13,
      "y": 8,
      "z": -3,
      "name": "Rock_Marble"
    },
    {
      "x": -13,
      "y": 9,
      "z": -3,
      "name": "Rock_Marble"
    },
    {
      "x": -13,
      "y": 10,
      "z": -3,
      "name": "Rock_Marble"
    },
    {
      "x": -13,
      "y": 11,
      "z": -3,
      "name": "Rock_Marble"
    },
    {
      "x": -13,
      "y": 12,
      "z": -3,
      "name": "Rock_Marble"
    },
    {
      "x": -13,
      "y": 13,
      "z": -3,
      "name": "Rock_Chalk"
    },
    {
      "x": -13,
      "y": 14,
      "z": -3,
      "name": "Rock_Chalk"
    },
    {
      "x": -13,
      "y": 15,
      "z": -3,
      "name": "Rock_Chalk"
    },
    {
      "x": -13,
      "y": 16,
      "z": -3,
      "name": "Rock_Chalk"
    },
    {
      "x": -13,
      "y": 17,
      "z": -3,
      "name": "Rock_Chalk"
    },
    {
      "x": -13,
      "y": 18,
      "z": -3,
      "name": "Rock_Chalk"
    },
    {
      "x": -13,
      "y": 19,
      "z": -3,
      "name": "Rock_Chalk"
    },
    {
      "x": -13,
      "y": 20,
      "z": -3,
      "name": "Rock_Chalk"
    },
    {
      "x": -13,
      "y": 21,
      "z": -3,
      "name": "Rock_Chalk"
    },
    {
      "x": -13,
      "y": 22,
      "z": -3,
      "name": "Rock_Chalk"
    },
    {
      "x": -13,
      "y": 23,
      "z": -3,
      "name": "Rock_Chalk"
    },
    {
      "x": -13,
      "y": 24,
      "z": -3,
      "name": "Rock_Chalk"
    },
    {
      "x": -13,
      "y": 25,
      "z": -3,
      "name": "Rock_Chalk"
    },
    {
      "x": -13,
      "y": 26,
      "z": -3,
      "name": "Rock_Chalk"
    },
    {
      "x": -13,
      "y": 27,
      "z": -3,
      "name": "Rock_Chalk"
    },
    {
      "x": -13,
      "y": 28,
      "z": -3,
      "name": "Rock_Chalk"
    },
    {
      "x": -13,
      "y": 29,
      "z": -3,
      "name": "Rock_Chalk"
    },
    {
      "x": -13,
      "y": 30,
      "z": -3,
      "name": "Rock_Chalk"
    },
    {
      "x": -13,
      "y": 31,
      "z": -3,
      "name": "Rock_Chalk"
    },
    {
      "x": -13,
      "y": 32,
      "z": -3,
      "name": "Rock_Chalk"
    },
    {
      "x": -13,
      "y": 33,
      "z": -3,
      "name": "Rock_Chalk"
    },
    {
      "x": -13,
      "y": 34,
      "z": -3,
      "name": "Rock_Chalk"
    },
    {
      "x": -13,
      "y": 35,
      "z": -3,
      "name": "Rock_Chalk"
    },
    {
      "x": -13,
      "y": 36,
      "z": -3,
      "name": "Rock_Chalk"
    },
    {
      "x": -13,
      "y": 37,
      "z": -3,
      "name": "Rock_Chalk"
    },
    {
      "x": -13,
      "y": 38,
      "z": -3,
      "name": "Rock_Chalk"
    },
    {
      "x": -13,
      "y": 39,
      "z": -3,
      "name": "Rock_Chalk"
    },
    {
      "x": -13,
      "y": 40,
      "z": -3,
      "name": "Rock_Chalk"
    },
    {
      "x": -13,
      "y": 41,
      "z": -3,
      "name": "Rock_Chalk"
    },
