{
  "version": 8,
  "blockIdVersion": 8,
  "anchorX": 0,
  "anchorY": 8,
  "anchorZ": 0,
  "blocks": [
    {
      "x": -24,
      "y": 39,
      "z": -4,
      "name": "Rock_Marble"
    },
    {
      "x": -24,
      "y": 40,
      "z": -4,
      "name": "Rock_Marble"
    },
    {
      "x": -24,
      "y": 41,
      "z": -4,
      "name": "Rock_Marble"
    },
    {
      "x": -24,
      "y": 42,
      "z": -4,
      "name": "Soil_Grass"
    },
    {
      "x": -24,
      "y": 35,
      "z": -3,
      "name": "Rock_Marble"
    },
    {
      "x": -24,
      "y": 36,
      "z": -3,
      "name": "Rock_Marble"
    },
    {
      "x": -24,
      "y": 37,
      "z": -3,
      "name": "Rock_Marble"
    },
    {
      "x": -24,
      "y": 38,
      "z": -3,
      "name": "Rock_Marble"
    },
    {
      "x": -24,
      "y": 39,
      "z": -3,
      "name": "Rock_Marble"
    },
    {
      "x": -24,
      "y": 40,
      "z": -3,
      "name": "Rock_Marble"
    },
    {
      "x": -24,
      "y": 41,
      "z": -3,
      "name": "Rock_Marble"
    },
    {
      "x": -24,
      "y": 42,
      "z": -3,
      "name": "Rock_Marble"
    },
    {
      "x": -23,
      "y": 40,
      "z": -6,
      "name": "Rock_Chalk"
    },
    {
      "x": -23,
      "y": 36,
      "z": -5,
      "name": "Rock_Chalk"
    },
    {
      "x": -23,
      "y": 37,
      "z": -5,
      "name": "Rock_Chalk"
    },
    {
      "x": -23,
      "y": 38,
      "z": -5,
      "name": "Rock_Chalk"
    },
    {
      "x": -23,
      "y": 39,
      "z": -5,
      "name": "Rock_Chalk"
    },
    {
      "x": -23,
      "y": 40,
      "z": -5,
      "name": "Rock_Chalk"
    },
    {
      "x": -23,
      "y": 41,
      "z": -5,
      "name": "Rock_Chalk"
    },
    {
      "x": -23,
      "y": 33,
      "z": -4,
      "name": "Rock_Marble"
    },
    {
      "x": -23,
      "y": 34,
      "z": -4,
      "name": "Rock_Marble"
    },
    {
      "x": -23,
      "y": 35,
      "z": -4,
      "name": "Rock_Marble"
    },
    {
      "x": -23,
      "y": 36,
      "z": -4,
      "name": "Rock_Marble"
    },
    {
      "x": -23,
      "y": 37,
      "z": -4,
      "name": "Rock_Marble"
    },
    {
      "x": -23,
      "y": 38,
      "z": -4,
      "name": "Rock_Marble"
    },
    {
      "x": -23,
      "y": 39,
      "z": -4,
      "name": "Rock_Marble"
    },
    {
      "x": -23,
      "y": 40,
      "z": -4,
      "name": "Rock_Marble"
    },
    {
      "x": -23,
      "y": 41,
      "z": -4,
      "name": "Soil_Dirt"
    },
    {
      "x": -23,
      "y": 42,
      "z": -4,
      "name": "Soil_Grass"
    },
    {
      "x": -23,
      "y": 30,
      "z": -3,
      "name": "Rock_Marble"
    },
    {
      "x": -23,
      "y": 31,
      "z": -3,
      "name": "Rock_Marble"
    },
    {
      "x": -23,
      "y": 32,
      "z": -3,
      "name": "Rock_Marble"
    },
    {
      "x": -23,
      "y": 33,
      "z": -3,
      "name": "Rock_Marble"
    },
    {
      "x": -23,
      "y": 34,
      "z": -3,
      "name": "Rock_Marble"
    },
    {
      "x": -23,
      "y": 35,
      "z": -3,
      "name": "Rock_Marble"
    },
    {
      "x": -23,
      "y": 36,
      "z": -3,
      "name": "Rock_Marble"
    },
    {
      "x": -23,
      "y": 37,
      "z": -3,
      "name": "Rock_Marble"
    },
    {
      "x": -23,
      "y": 38,
      "z": -3,
      "name": "Rock_Marble"
    },
    {
      "x": -23,
      "y": 39,
      "z": -3,
      "name": "Rock_Marble"
    },
    {
      "x": -23,
      "y": 40,
      "z": -3,
      "name": "Rock_Marble"
    },
    {
      "x": -23,
      "y": 41,
      "z": -3,
      "name": "Rock_Marble"
    },
    {
      "x": -23,
      "y": 42,
      "z": -3,
      "name": "Soil_Grass"
    },
    {
      "x": -23,
      "y": 28,
      "z": -2,
      "name": "Rock_Marble"
    },
    {
      "x": -23,
      "y": 29,
      "z": -2,
      "name": "Rock_Marble"
    },
    {
      "x": -23,
      "y": 30,
      "z": -2,
      "name": "Rock_Marble"
    },
    {
      "x": -23,
      "y": 31,
      "z": -2,
      "name": "Rock_Marble"
    },
    {
      "x": -23,
      "y": 32,
      "z": -2,
      "name": "Rock_Marble"
    },
    {
      "x": -23,
      "y": 33,
      "z": -2,
      "name": "Rock_Marble"
    },
    {
      "x": -23,
      "y": 34,
      "z": -2,
      "name": "Rock_Marble"
    },
    {
      "x": -23,
      "y": 35,
      "z": -2,
      "name": "Rock_Marble"
    },
    {
      "x": -23,
      "y": 36,
      "z": -2,
      "name": "Rock_Marble"
    },
    {
      "x": -23,
      "y": 37,
      "z": -2,
      "name": "Rock_Marble"
    },
    {
      "x": -23,
      "y": 38,
      "z": -2,
      "name": "Rock_Marble"
    },
    {
      "x": -23,
      "y": 39,
      "z": -2,
      "name": "Rock_Marble"
    },
    {
      "x": -23,
      "y": 40,
      "z": -2,
      "name": "Rock_Marble"
    },
    {
      "x": -23,
      "y": 41,
      "z": -2,
      "name": "Rock_Marble"
    },
    {
      "x": -23,
      "y": 42,
      "z": -2,
      "name": "Rock_Marble"
    },
    {
      "x": -22,
      "y": 36,
      "z": -7,
      "name": "Rock_Chalk"
    },
    {
      "x": -22,
      "y": 37,
      "z": -7,
      "name": "Rock_Chalk"
    },
    {
      "x": -22,
      "y": 38,
      "z": -7,
      "name": "Rock_Chalk"
    },
    {
      "x": -22,
      "y": 39,
      "z": -7,
      "name": "Rock_Chalk"
    },
    {
      "x": -22,
      "y": 40,
      "z": -7,
      "name": "Rock_Chalk"
    },
    {
      "x": -22,
      "y": 10,
      "z": -6,
      "name": "Rock_Chalk"
    },
    {
      "x": -22,
      "y": 11,
      "z": -6,
      "name": "Rock_Chalk"
    },
    {
      "x": -22,
      "y": 12,
      "z": -6,
      "name": "Rock_Chalk"
    },
    {
      "x": -22,
      "y": 13,
      "z": -6,
      "name": "Rock_Chalk"
    },
    {
      "x": -22,
      "y": 14,
      "z": -6,
      "name": "Rock_Chalk"
    },
    {
      "x": -22,
      "y": 30,
      "z": -6,
      "name": "Rock_Chalk"
    },
    {
      "x": -22,
      "y": 31,
      "z": -6,
      "name": "Rock_Chalk"
    },
    {
      "x": -22,
      "y": 32,
      "z": -6,
      "name": "Rock_Chalk"
    },
    {
      "x": -22,
      "y": 33,
      "z": -6,
      "name": "Rock_Chalk"
    },
    {
      "x": -22,
      "y": 34,
      "z": -6,
      "name": "Rock_Chalk"
    },
    {
      "x": -22,
      "y": 35,
      "z": -6,
      "name": "Rock_Chalk"
    },
    {
      "x": -22,
      "y": 36,
      "z": -6,
      "name": "Rock_Chalk"
    },
    {
      "x": -22,
      "y": 37,
      "z": -6,
      "name": "Rock_Chalk"
    },
    {
      "x": -22,
      "y": 38,
      "z": -6,
      "name": "Rock_Chalk"
    },
    {
      "x": -22,
      "y": 39,
      "z": -6,
      "name": "Rock_Chalk"
    },
    {
      "x": -22,
      "y": 40,
      "z": -6,
      "name": "Rock_Chalk"
    },
    {
      "x": -22,
      "y": 41,
      "z": -6,
      "name": "Soil_Grass"
    },
    {
      "x": -22,
      "y": 5,
      "z": -5,
      "name": "Rock_Marble"
    },
    {
      "x": -22,
      "y": 6,
      "z": -5,
      "name": "Rock_Marble"
    },
    {
      "x": -22,
      "y": 7,
      "z": -5,
      "name": "Rock_Marble"
    },
    {
      "x": -22,
      "y": 8,
      "z": -5,
      "name": "Rock_Marble"
    },
    {
      "x": -22,
      "y": 9,
      "z": -5,
      "name": "Rock_Marble"
    },
    {
      "x": -22,
      "y": 10,
      "z": -5,
      "name": "Rock_Marble"
    },
    {
      "x": -22,
      "y": 11,
      "z": -5,
      "name": "Rock_Marble"
    },
    {
      "x": -22,
      "y": 12,
      "z": -5,
      "name": "Rock_Marble"
    },
    {
      "x": -22,
      "y": 13,
      "z": -5,
      "name": "Rock_Marble"
    },
    {
      "x": -22,
      "y": 14,
      "z": -5,
      "name": "Rock_Marble"
    },
    {
      "x": -22,
      "y": 15,
      "z": -5,
      "name": "Rock_Marble"
    },
    {
      "x": -22,
      "y": 16,
      "z": -5,
      "name": "Rock_Marble"
    },
    {
      "x": -22,
      "y": 27,
      "z": -5,
      "name": "Rock_Marble"
    },
    {
      "x": -22,
      "y": 28,
      "z": -5,
      "name": "Rock_Marble"
    },
    {
      "x": -22,
      "y": 29,
      "z": -5,
      "name": "Rock_Marble"
    },
    {
      "x": -22,
      "y": 30,
      "z": -5,
      "name": "Rock_Marble"
    },
    {
      "x": -22,
      "y": 31,
      "z": -5,
      "name": "Rock_Marble"
    },
    {
      "x": -22,
      "y": 32,
      "z": -5,
      "name": "Rock_Marble"
    },
    {
      "x": -22,
      "y": 33,
      "z": -5,
      "name": "Rock_Marble"
    },
    {
      "x": -22,
      "y": 34,
      "z": -5,
      "name": "Rock_Chalk"
    },
    {
      "x": -22,
      "y": 35,
      "z": -5,
      "name": "Rock_Chalk"
    },
    {
      "x": -22,
      "y": 36,
      "z": -5,
      "name": "Rock_Chalk"
    },
    {
      "x": -22,
      "y": 37,
      "z": -5,
      "name": "Rock_Chalk"
    },
    {
      "x": -22,
      "y": 38,
      "z": -5,
      "name": "Rock_Chalk"
    },
    {
      "x": -22,
      "y": 39,
      "z": -5,
      "name": "Rock_Chalk"
    },
    {
      "x": -22,
      "y": 40,
      "z": -5,
      "name": "Rock_Chalk"
    },
    {
      "x": -22,
      "y": 41,
      "z": -5,
      "name": "Soil_Grass"
    },
    {
      "x": -22,
      "y": 4,
      "z": -4,
      "name": "Rock_Marble"
    },
    {
      "x": -22,
      "y": 5,
      "z": -4,
      "name": "Rock_Marble"
    },
    {
      "x": -22,
      "y": 6,
      "z": -4,
      "name": "Rock_Marble"
    },
    {
      "x": -22,
      "y": 7,
      "z": -4,
      "name": "Rock_Marble"
    },
    {
      "x": -22,
      "y": 8,
      "z": -4,
      "name": "Rock_Marble"
    },
    {
      "x": -22,
      "y": 9,
      "z": -4,
      "name": "Rock_Marble"
    },
    {
      "x": -22,
      "y": 10,
      "z": -4,
      "name": "Rock_Marble"
    },
    {
      "x": -22,
      "y": 11,
      "z": -4,
      "name": "Rock_Marble"
    },
    {
      "x": -22,
      "y": 12,
      "z": -4,
      "name": "Rock_Marble"
    },
    {
      "x": -22,
      "y": 13,
      "z": -4,
      "name": "Rock_Marble"
    },
    {
      "x": -22,
      "y": 14,
      "z": -4,
      "name": "Rock_Marble"
    },
    {
      "x": -22,
      "y": 15,
      "z": -4,
      "name": "Rock_Marble"
    },
    {
      "x": -22,
      "y": 16,
      "z": -4,
      "name": "Rock_Marble"
    },
    {
      "x": -22,
      "y": 17,
      "z": -4,
      "name": "Rock_Marble"
    },
    {
      "x": -22,
      "y": 26,
      "z": -4,
      "name": "Rock_Marble"
    },
    {
      "x": -22,
      "y": 27,
      "z": -4,
      "name": "Rock_Marble"
    },
    {
      "x": -22,
      "y": 28,
      "z": -4,
      "name": "Rock_Marble"
    },
    {
      "x": -22,
      "y": 29,
      "z": -4,
      "name": "Rock_Marble"
    },
    {
      "x": -22,
      "y": 30,
      "z": -4,
      "name": "Rock_Marble"
    },
    {
      "x": -22,
      "y": 31,
      "z": -4,
      "name": "Rock_Marble"
    },
    {
      "x": -22,
      "y": 32,
      "z": -4,
      "name": "Rock_Marble"
    },
    {
      "x": -22,
      "y": 33,
      "z": -4,
      "name": "Rock_Marble"
    },
    {
      "x": -22,
      "y": 34,
      "z": -4,
      "name": "Rock_Marble"
    },
    {
      "x": -22,
      "y": 35,
      "z": -4,
      "name": "Rock_Marble"
    },
    {
      "x": -22,
      "y": 36,
      "z": -4,
      "name": "Rock_Marble"
    },
    {
      "x": -22,
      "y": 37,
      "z": -4,
      "name": "Rock_Marble"
    },
    {
      "x": -22,
      "y": 38,
      "z": -4,
      "name": "Rock_Marble"
    },
    {
      "x": -22,
      "y": 39,
      "z": -4,
      "name": "Rock_Marble"
    },
    {
      "x": -22,
      "y": 40,
      "z": -4,
      "name": "Rock_Marble"
    },
    {
      "x": -22,
      "y": 41,
      "z": -4,
      "name": "Soil_Grass"
    },
    {
      "x": -22,
      "y": 3,
      "z": -3,
      "name": "Rock_Marble"
    },
    {
      "x": -22,
      "y": 4,
      "z": -3,
      "name": "Rock_Marble"
    },
    {
      "x": -22,
      "y": 5,
      "z": -3,
      "name": "Rock_Marble"
    },
    {
      "x": -22,
      "y": 6,
      "z": -3,
      "name": "Rock_Marble"
    },
    {
      "x": -22,
      "y": 7,
      "z": -3,
      "name": "Rock_Marble"
    },
    {
      "x": -22,
      "y": 8,
      "z": -3,
      "name": "Rock_Marble"
    },
    {
      "x": -22,
      "y": 9,
      "z": -3,
      "name": "Rock_Marble"
    },
    {
      "x": -22,
      "y": 10,
      "z": -3,
      "name": "Rock_Marble"
    },
    {
      "x": -22,
      "y": 11,
      "z": -3,
      "name": "Rock_Marble"
    },
    {
      "x": -22,
      "y": 12,
      "z": -3,
      "name": "Rock_Marble"
    },
    {
      "x": -22,
      "y": 13,
      "z": -3,
      "name": "Rock_Marble"
    },
    {
      "x": -22,
      "y": 14,
      "z": -3,
      "name": "Rock_Marble"
    },
    {
      "x": -22,
      "y": 15,
      "z": -3,
      "name": "Rock_Marble"
    },
    {
      "x": -22,
      "y": 16,
      "z": -3,
      "name": "Rock_Marble"
    },
    {
      "x": -22,
      "y": 17,
      "z": -3,
      "name": "Rock_Marble"
    },
    {
      "x": -22,
      "y": 26,
      "z": -3,
      "name": "Rock_Marble"
    },
    {
      "x": -22,
      "y": 27,
      "z": -3,
      "name": "Rock_Marble"
    },
    {
      "x": -22,
      "y": 28,
      "z": -3,
      "name": "Rock_Marble"
    },
    {
      "x": -22,
      "y": 29,
      "z": -3,
      "name": "Rock_Marble"
    },
    {
      "x": -22,
      "y": 30,
      "z": -3,
      "name": "Rock_Marble"
    },
    {
      "x": -22,
      "y": 31,
      "z": -3,
      "name": "Rock_Marble"
    },
    {
      "x": -22,
      "y": 32,
      "z": -3,
      "name": "Rock_Marble"
    },
    {
      "x": -22,
      "y": 33,
      "z": -3,
      "name": "Rock_Marble"
    },
    {
      "x": -22,
      "y": 34,
      "z": -3,
      "name": "Rock_Marble"
    },
    {
      "x": -22,
      "y": 35,
      "z": -3,
      "name": "Rock_Marble"
    },
    {
      "x": -22,
      "y": 36,
      "z": -3,
      "name": "Rock_Marble"
    },
    {
      "x": -22,
      "y": 37,
      "z": -3,
      "name": "Rock_Marble"
    },
    {
      "x": -22,
      "y": 38,
      "z": -3,
      "name": "Rock_Marble"
    },
    {
      "x": -22,
      "y": 39,
      "z": -3,
      "name": "Rock_Marble"
    },
    {
      "x": -22,
      "y": 40,
      "z": -3,
      "name": "Rock_Marble"
    },
    {
      "x": -22,
      "y": 41,
      "z": -3,
      "name": "Soil_Dirt"
    },
    {
      "x": -22,
      "y": 42,
      "z": -3,
      "name": "Soil_Grass"
    },
    {
      "x": -22,
      "y": 3,
      "z": -2,
      "name": "Rock_Marble"
    },
    {
      "x": -22,
      "y": 4,
      "z": -2,
      "name": "Rock_Marble"
    },
    {
      "x": -22,
      "y": 5,
      "z": -2,
      "name": "Rock_Marble"
    },
    {
      "x": -22,
      "y": 6,
      "z": -2,
      "name": "Rock_Marble"
    },
    {
      "x": -22,
      "y": 7,
      "z": -2,
      "name": "Rock_Marble"
    },
    {
      "x": -22,
      "y": 8,
      "z": -2,
      "name": "Rock_Marble"
    },
    {
      "x": -22,
      "y": 9,
      "z": -2,
      "name": "Rock_Marble"
    },
    {
      "x": -22,
      "y": 10,
      "z": -2,
      "name": "Rock_Marble"
    },
    {
      "x": -22,
      "y": 11,
      "z": -2,
      "name": "Rock_Marble"
    },
    {
      "x": -22,
      "y": 12,
      "z": -2,
      "name": "Rock_Marble"
    },
    {
      "x": -22,
      "y": 13,
      "z": -2,
      "name": "Rock_Marble"
    },
    {
      "x": -22,
      "y": 14,
      "z": -2,
      "name": "Rock_Marble"
    },
    {
      "x": -22,
      "y": 15,
      "z": -2,
      "name": "Rock_Marble"
    },
    {
      "x": -22,
      "y": 16,
      "z": -2,
      "name": "Rock_Marble"
    },
    {
      "x": -22,
      "y": 17,
      "z": -2,
      "name": "Rock_Marble"
    },
    {
      "x": -22,
      "y": 23,
      "z": -2,
      "name": "Rock_Marble"
    },
    {
      "x": -22,
      "y": 24,
      "z": -2,
      "name": "Rock_Marble"
    },
    {
      "x": -22,
      "y": 25,
      "z": -2,
      "name": "Rock_Marble"
    },
    {
      "x": -22,
      "y": 26,
      "z": -2,
      "name": "Rock_Marble"
    },
    {
      "x": -22,
      "y": 27,
      "z": -2,
      "name": "Rock_Marble"
    },
    {
      "x": -22,
      "y": 28,
      "z": -2,
      "name": "Rock_Marble"
    },
    {
      "x": -22,
      "y": 29,
      "z": -2,
      "name": "Rock_Marble"
    },
    {
      "x": -22,
      "y": 30,
      "z": -2,
      "name": "Rock_Marble"
    },
    {
      "x": -22,
      "y": 31,
      "z": -2,
      "name": "Rock_Marble"
    },
    {
      "x": -22,
      "y": 32,
      "z": -2,
      "name": "Rock_Marble"
    },
    {
      "x": -22,
      "y": 33,
      "z": -2,
      "name": "Rock_Marble"
    },
    {
      "x": -22,
      "y": 34,
      "z": -2,
      "name": "Rock_Marble"
    },
    {
      "x": -22,
      "y": 35,
      "z": -2,
      "name": "Rock_Marble"
    },
    {
      "x": -22,
      "y": 36,
      "z": -2,
      "name": "Rock_Marble"
    },
    {
      "x": -22,
      "y": 37,
      "z": -2,
      "name": "Rock_Marble"
    },
    {
      "x": -22,
      "y": 38,
      "z": -2,
      "name": "Rock_Marble"
    },
    {
      "x": -22,
      "y": 39,
      "z": -2,
      "name": "Rock_Marble"
    },
    {
      "x": -22,
      "y": 40,
      "z": -2,
      "name": "Rock_Marble"
    },
    {
      "x": -22,
      "y": 41,
      "z": -2,
      "name": "Rock_Marble"
    },
    {
      "x": -22,
      "y": 42,
      "z": -2,
      "name": "Soil_Grass"
    },
    {
      "x": -22,
      "y": 3,
      "z": -1,
      "name": "Rock_Marble"
    },
    {
      "x": -22,
      "y": 4,
      "z": -1,
      "name": "Rock_Marble"
    },
    {
      "x": -22,
      "y": 5,
      "z": -1,
      "name": "Rock_Marble"
    },
    {
      "x": -22,
      "y": 6,
      "z": -1,
      "name": "Rock_Marble"
    },
    {
      "x": -22,
      "y": 7,
      "z": -1,
      "name": "Rock_Marble"
    },
    {
      "x": -22,
      "y": 8,
      "z": -1,
      "name": "Rock_Marble"
    },
    {
      "x": -22,
      "y": 9,
      "z": -1,
      "name": "Rock_Marble"
    },
    {
      "x": -22,
      "y": 10,
      "z": -1,
      "name": "Rock_Marble"
    },
    {
      "x": -22,
      "y": 11,
      "z": -1,
      "name": "Rock_Marble"
    },
    {
      "x": -22,
      "y": 12,
      "z": -1,
      "name": "Rock_Marble"
    },
    {
      "x": -22,
      "y": 13,
      "z": -1,
      "name": "Rock_Marble"
    },
    {
      "x": -22,
      "y": 23,
      "z": -1,
      "name": "Rock_Marble"
    },
    {
      "x": -22,
      "y": 24,
      "z": -1,
      "name": "Rock_Marble"
    },
    {
      "x": -22,
      "y": 25,
      "z": -1,
      "name": "Rock_Marble"
    },
    {
      "x": -22,
      "y": 26,
      "z": -1,
      "name": "Rock_Marble"
    },
    {
      "x": -22,
      "y": 27,
      "z": -1,
      "name": "Rock_Marble"
    },
    {
      "x": -22,
      "y": 28,
      "z": -1,
      "name": "Rock_Marble"
    },
    {
      "x": -22,
      "y": 29,
      "z": -1,
      "name": "Rock_Marble"
    },
    {
      "x": -22,
      "y": 30,
      "z": -1,
      "name": "Rock_Marble"
    },
    {
      "x": -22,
      "y": 31,
      "z": -1,
      "name": "Rock_Marble"
    },
    {
      "x": -22,
      "y": 32,
      "z": -1,
      "name": "Rock_Marble"
    },
    {
      "x": -22,
      "y": 33,
      "z": -1,
      "name": "Rock_Marble"
    },
    {
      "x": -22,
      "y": 34,
      "z": -1,
      "name": "Rock_Marble"
    },
    {
      "x": -22,
      "y": 35,
      "z": -1,
      "name": "Rock_Marble"
    },
    {
      "x": -22,
      "y": 36,
      "z": -1,
      "name": "Rock_Marble"
    },
    {
      "x": -22,
      "y": 37,
      "z": -1,
      "name": "Rock_Marble"
    },
    {
      "x": -22,
      "y": 38,
      "z": -1,
      "name": "Rock_Marble"
    },
    {
      "x": -22,
      "y": 39,
      "z": -1,
      "name": "Rock_Marble"
    },
    {
      "x": -22,
      "y": 40,
      "z": -1,
      "name": "Rock_Marble"
    },
    {
      "x": -22,
      "y": 41,
      "z": -1,
      "name": "Rock_Marble"
    },
    {
      "x": -22,
      "y": 42,
      "z": -1,
      "name": "Rock_Marble"
    },
    {
      "x": -22,
      "y": 3,
      "z": 0,
      "name": "Rock_Marble"
    },
    {
      "x": -22,
      "y": 4,
      "z": 0,
      "name": "Rock_Marble"
    },
    {
      "x": -22,
      "y": 5,
      "z": 0,
      "name": "Rock_Marble"
    },
    {
      "x": -22,
      "y": 6,
      "z": 0,
      "name": "Rock_Marble"
    },
    {
      "x": -22,
      "y": 7,
      "z": 0,
      "name": "Rock_Marble"
    },
    {
      "x": -22,
      "y": 8,
      "z": 0,
      "name": "Rock_Marble"
    },
    {
      "x": -22,
      "y": 9,
      "z": 0,
      "name": "Rock_Marble"
    },
    {
      "x": -22,
      "y": 38,
      "z": 0,
      "name": "Rock_Marble"
    },
    {
      "x": -22,
      "y": 4,
      "z": 1,
      "name": "Rock_Marble"
    },
    {
      "x": -22,
      "y": 5,
      "z": 1,
      "name": "Rock_Marble"
    },
    {
      "x": -22,
      "y": 6,
      "z": 1,
      "name": "Rock_Marble"
    },
    {
      "x": -21,
      "y": 4,
      "z": -12,
      "name": "Rock_Chalk"
    },
    {
      "x": -21,
      "y": 5,
      "z": -12,
      "name": "Rock_Chalk"
    },
    {
      "x": -21,
      "y": 3,
      "z": -11,
      "name": "Rock_Chalk"
    },
    {
      "x": -21,
      "y": 4,
      "z": -11,
      "name": "Rock_Chalk"
    },
    {
      "x": -21,
      "y": 5,
      "z": -11,
      "name": "Rock_Chalk"
    },
    {
      "x": -21,
      "y": 6,
      "z": -11,
      "name": "Rock_Chalk"
    },
    {
      "x": -21,
      "y": 7,
      "z": -11,
      "name": "Rock_Chalk"
    },
    {
      "x": -21,
      "y": 3,
      "z": -10,
      "name": "Rock_Chalk"
    },
    {
      "x": -21,
      "y": 4,
      "z": -10,
      "name": "Rock_Chalk"
    },
    {
      "x": -21,
      "y": 5,
      "z": -10,
      "name": "Rock_Chalk"
    },
    {
      "x": -21,
      "y": 6,
      "z": -10,
      "name": "Rock_Chalk"
    },
    {
      "x": -21,
      "y": 7,
      "z": -10,
      "name": "Rock_Chalk"
    },
    {
      "x": -21,
      "y": 8,
      "z": -10,
      "name": "Rock_Chalk"
    },
    {
      "x": -21,
      "y": 9,
      "z": -10,
      "name": "Rock_Chalk"
    },
    {
      "x": -21,
      "y": 3,
      "z": -9,
      "name": "Rock_Chalk"
    },
    {
      "x": -21,
      "y": 4,
      "z": -9,
      "name": "Rock_Chalk"
    },
    {
      "x": -21,
      "y": 5,
      "z": -9,
      "name": "Rock_Chalk"
    },
    {
      "x": -21,
      "y": 6,
      "z": -9,
      "name": "Rock_Chalk"
    },
    {
      "x": -21,
      "y": 7,
      "z": -9,
      "name": "Rock_Chalk"
    },
    {
      "x": -21,
      "y": 8,
      "z": -9,
      "name": "Rock_Chalk"
    },
    {
      "x": -21,
      "y": 9,
      "z": -9,
      "name": "Rock_Chalk"
    },
    {
      "x": -21,
      "y": 3,
      "z": -8,
      "name": "Rock_Chalk"
    },
    {
      "x": -21,
      "y": 4,
      "z": -8,
      "name": "Rock_Chalk"
    },
    {
      "x": -21,
      "y": 5,
      "z": -8,
      "name": "Rock_Chalk"
    },
    {
      "x": -21,
      "y": 6,
      "z": -8,
      "name": "Rock_Chalk"
    },
    {
      "x": -21,
      "y": 7,
      "z": -8,
      "name": "Rock_Chalk"
    },
    {
      "x": -21,
      "y": 8,
      "z": -8,
      "name": "Rock_Chalk"
    },
    {
      "x": -21,
      "y": 9,
      "z": -8,
      "name": "Rock_Chalk"
    },
    {
      "x": -21,
      "y": 10,
      "z": -8,
      "name": "Rock_Chalk"
    },
    {
      "x": -21,
      "y": 11,
      "z": -8,
      "name": "Rock_Chalk"
    },
    {
      "x": -21,
      "y": 12,
      "z": -8,
      "name": "Rock_Chalk"
    },
    {
      "x": -21,
      "y": 13,
      "z": -8,
      "name": "Rock_Chalk"
    },
    {
      "x": -21,
      "y": 14,
      "z": -8,
      "name": "Rock_Chalk"
    },
    {
      "x": -21,
      "y": 15,
      "z": -8,
      "name": "Rock_Chalk"
    },
    {
      "x": -21,
      "y": 16,
      "z": -8,
      "name": "Rock_Chalk"
    },
    {
      "x": -21,
      "y": 17,
      "z": -8,
      "name": "Rock_Chalk"
    },
    {
      "x": -21,
      "y": 18,
      "z": -8,
      "name": "Rock_Chalk"
    },
    {
      "x": -21,
      "y": 19,
      "z": -8,
      "name": "Rock_Chalk"
    },
    {
      "x": -21,
      "y": 20,
      "z": -8,
      "name": "Rock_Chalk"
    },
    {
      "x": -21,
      "y": 21,
      "z": -8,
      "name": "Rock_Chalk"
    },
    {
      "x": -21,
      "y": 31,
      "z": -8,
      "name": "Rock_Chalk"
    },
    {
      "x": -21,
      "y": 32,
      "z": -8,
      "name": "Rock_Chalk"
    },
    {
      "x": -21,
      "y": 33,
      "z": -8,
      "name": "Rock_Chalk"
    },
    {
      "x": -21,
      "y": 34,
      "z": -8,
      "name": "Rock_Chalk"
    },
    {
      "x": -21,
      "y": 35,
      "z": -8,
      "name": "Rock_Chalk"
    },
    {
      "x": -21,
      "y": 36,
      "z": -8,
      "name": "Rock_Chalk"
    },
    {
      "x": -21,
      "y": 37,
      "z": -8,
      "name": "Rock_Chalk"
    },
    {
      "x": -21,
      "y": 38,
      "z": -8,
      "name": "Rock_Chalk"
    },
    {
      "x": -21,
      "y": 39,
      "z": -8,
      "name": "Rock_Chalk"
    },
    {
      "x": -21,
      "y": 40,
      "z": -8,
      "name": "Rock_Chalk"
    },
    {
      "x": -21,
      "y": 4,
      "z": -7,
      "name": "Rock_Chalk"
    },
    {
      "x": -21,
      "y": 5,
      "z": -7,
      "name": "Rock_Chalk"
    },
    {
      "x": -21,
      "y": 6,
      "z": -7,
      "name": "Rock_Chalk"
    },
    {
      "x": -21,
      "y": 7,
      "z": -7,
      "name": "Rock_Chalk"
    },
    {
      "x": -21,
      "y": 8,
      "z": -7,
      "name": "Rock_Chalk"
    },
    {
      "x": -21,
      "y": 9,
      "z": -7,
      "name": "Rock_Chalk"
    },
    {
      "x": -21,
      "y": 10,
      "z": -7,
      "name": "Rock_Chalk"
    },
    {
      "x": -21,
      "y": 11,
      "z": -7,
      "name": "Rock_Chalk"
    },
    {
      "x": -21,
      "y": 12,
      "z": -7,
      "name": "Rock_Chalk"
    },
    {
      "x": -21,
      "y": 13,
      "z": -7,
      "name": "Rock_Chalk"
    },
    {
      "x": -21,
      "y": 14,
      "z": -7,
      "name": "Rock_Chalk"
    },
    {
      "x": -21,
      "y": 15,
      "z": -7,
      "name": "Rock_Chalk"
    },
    {
      "x": -21,
      "y": 16,
      "z": -7,
      "name": "Rock_Chalk"
    },
    {
      "x": -21,
      "y": 17,
      "z": -7,
      "name": "Rock_Chalk"
    },
    {
      "x": -21,
      "y": 18,
      "z": -7,
      "name": "Rock_Chalk"
    },
    {
      "x": -21,
      "y": 19,
      "z": -7,
      "name": "Rock_Chalk"
    },
    {
      "x": -21,
      "y": 20,
      "z": -7,
      "name": "Rock_Chalk"
    },
    {
      "x": -21,
      "y": 21,
      "z": -7,
      "name": "Rock_Chalk"
    },
    {
      "x": -21,
      "y": 22,
      "z": -7,
      "name": "Rock_Chalk"
    },
    {
      "x": -21,
      "y": 23,
      "z": -7,
      "name": "Rock_Chalk"
    },
    {
      "x": -21,
      "y": 25,
      "z": -7,
      "name": "Rock_Chalk"
    },
    {
      "x": -21,
      "y": 26,
      "z": -7,
      "name": "Rock_Chalk"
    },
    {
      "x": -21,
      "y": 27,
      "z": -7,
      "name": "Rock_Chalk"
    },
    {
      "x": -21,
      "y": 28,
      "z": -7,
      "name": "Rock_Chalk"
    },
    {
      "x": -21,
      "y": 29,
      "z": -7,
      "name": "Rock_Chalk"
    },
    {
      "x": -21,
      "y": 30,
      "z": -7,
      "name": "Rock_Chalk"
    },
    {
      "x": -21,
      "y": 31,
      "z": -7,
      "name": "Rock_Chalk"
    },
    {
      "x": -21,
      "y": 32,
      "z": -7,
      "name": "Rock_Chalk"
    },
    {
      "x": -21,
      "y": 33,
      "z": -7,
      "name": "Rock_Chalk"
    },
    {
      "x": -21,
      "y": 34,
      "z": -7,
      "name": "Rock_Chalk"
    },
    {
      "x": -21,
      "y": 35,
      "z": -7,
      "name": "Rock_Chalk"
    },
    {
      "x": -21,
      "y": 36,
      "z": -7,
      "name": "Rock_Chalk"
    },
    {
      "x": -21,
      "y": 37,
      "z": -7,
      "name": "Rock_Chalk"
    },
    {
      "x": -21,
      "y": 38,
      "z": -7,
      "name": "Rock_Chalk"
    },
    {
      "x": -21,
      "y": 39,
      "z": -7,
      "name": "Rock_Chalk"
    },
    {
      "x": -21,
      "y": 40,
      "z": -7,
      "name": "Soil_Grass"
    },
    {
      "x": -21,
      "y": 3,
      "z": -6,
      "name": "Rock_Chalk"
    },
    {
      "x": -21,
      "y": 4,
      "z": -6,
      "name": "Rock_Chalk"
    },
    {
      "x": -21,
      "y": 5,
      "z": -6,
      "name": "Rock_Chalk"
    },
    {
      "x": -21,
      "y": 6,
      "z": -6,
      "name": "Rock_Chalk"
    },
    {
      "x": -21,
      "y": 7,
      "z": -6,
      "name": "Rock_Chalk"
    },
    {
      "x": -21,
      "y": 8,
      "z": -6,
      "name": "Rock_Chalk"
    },
    {
      "x": -21,
      "y": 9,
      "z": -6,
      "name": "Rock_Chalk"
    },
    {
      "x": -21,
      "y": 10,
      "z": -6,
      "name": "Rock_Chalk"
    },
    {
      "x": -21,
      "y": 11,
      "z": -6,
      "name": "Rock_Chalk"
    },
    {
      "x": -21,
      "y": 12,
      "z": -6,
      "name": "Rock_Chalk"
    },
    {
      "x": -21,
      "y": 13,
      "z": -6,
      "name": "Rock_Chalk"
    },
    {
      "x": -21,
      "y": 14,
      "z": -6,
      "name": "Rock_Chalk"
    },
    {
      "x": -21,
      "y": 15,
      "z": -6,
      "name": "Rock_Chalk"
    },
    {
      "x": -21,
      "y": 16,
      "z": -6,
      "name": "Rock_Chalk"
    },
    {
      "x": -21,
      "y": 17,
      "z": -6,
      "name": "Rock_Chalk"
    },
    {
      "x": -21,
      "y": 18,
      "z": -6,
      "name": "Rock_Chalk"
    },
    {
      "x": -21,
      "y": 19,
      "z": -6,
      "name": "Rock_Chalk"
    },
    {
      "x": -21,
      "y": 20,
      "z": -6,
      "name": "Rock_Chalk"
    },
    {
      "x": -21,
      "y": 21,
      "z": -6,
      "name": "Rock_Chalk"
    },
    {
      "x": -21,
      "y": 22,
      "z": -6,
      "name": "Rock_Chalk"
    },
    {
      "x": -21,
      "y": 23,
      "z": -6,
      "name": "Rock_Chalk"
    },
    {
      "x": -21,
      "y": 24,
      "z": -6,
      "name": "Rock_Chalk"
    },
    {
      "x": -21,
      "y": 25,
      "z": -6,
      "name": "Rock_Chalk"
    },
    {
      "x": -21,
      "y": 26,
      "z": -6,
      "name": "Rock_Chalk"
    },
    {
      "x": -21,
      "y": 27,
      "z": -6,
      "name": "Rock_Chalk"
    },
    {
      "x": -21,
      "y": 28,
      "z": -6,
      "name": "Rock_Chalk"
    },
    {
      "x": -21,
      "y": 29,
      "z": -6,
      "name": "Rock_Chalk"
    },
    {
      "x": -21,
      "y": 30,
      "z": -6,
      "name": "Rock_Chalk"
    },
    {
      "x": -21,
      "y": 31,
      "z": -6,
      "name": "Rock_Chalk"
    },
    {
      "x": -21,
      "y": 32,
      "z": -6,
      "name": "Rock_Chalk"
    },
    {
      "x": -21,
      "y": 33,
      "z": -6,
      "name": "Rock_Chalk"
    },
    {
      "x": -21,
      "y": 34,
      "z": -6,
      "name": "Rock_Chalk"
    },
    {
      "x": -21,
      "y": 35,
      "z": -6,
      "name": "Rock_Chalk"
    },
    {
      "x": -21,
      "y": 36,
      "z": -6,
      "name": "Rock_Chalk"
    },
    {
      "x": -21,
      "y": 37,
      "z": -6,
      "name": "Rock_Chalk"
    },
    {
      "x": -21,
      "y": 38,
      "z": -6,
      "name": "Rock_Chalk"
    },
    {
      "x": -21,
      "y": 39,
      "z": -6,
      "name": "Rock_Chalk"
    },
    {
      "x": -21,
      "y": 40,
      "z": -6,
      "name": "Soil_Dirt"
    },
    {
      "x": -21,
      "y": 41,
      "z": -6,
      "name": "Soil_Grass"
    },
    {
      "x": -21,
      "y": 3,
      "z": -5,
      "name": "Rock_Chalk"
    },
    {
      "x": -21,
      "y": 4,
      "z": -5,
      "name": "Rock_Chalk"
    },
    {
      "x": -21,
      "y": 5,
      "z": -5,
      "name": "Rock_Chalk"
    },
    {
      "x": -21,
      "y": 6,
      "z": -5,
      "name": "Rock_Chalk"
    },
    {
      "x": -21,
      "y": 7,
      "z": -5,
      "name": "Rock_Chalk"
    },
    {
      "x": -21,
      "y": 8,
      "z": -5,
      "name": "Rock_Chalk"
    },
    {
      "x": -21,
      "y": 9,
      "z": -5,
      "name": "Rock_Chalk"
    },
    {
      "x": -21,
      "y": 10,
      "z": -5,
      "name": "Rock_Chalk"
    },
    {
      "x": -21,
      "y": 11,
      "z": -5,
      "name": "Rock_Chalk"
    },
    {
      "x": -21,
      "y": 12,
      "z": -5,
      "name": "Rock_Chalk"
    },
    {
      "x": -21,
      "y": 13,
      "z": -5,
      "name": "Rock_Chalk"
    },
    {
      "x": -21,
      "y": 14,
      "z": -5,
      "name": "Rock_Chalk"
    },
    {
      "x": -21,
      "y": 15,
      "z": -5,
      "name": "Rock_Chalk"
    },
    {
      "x": -21,
      "y": 16,
      "z": -5,
      "name": "Rock_Chalk"
    },
    {
      "x": -21,
      "y": 17,
      "z": -5,
      "name": "Rock_Chalk"
    },
    {
      "x": -21,
      "y": 18,
      "z": -5,
      "name": "Rock_Chalk"
    },
    {
      "x": -21,
      "y": 19,
      "z": -5,
      "name": "Rock_Chalk"
    },
    {
      "x": -21,
      "y": 20,
      "z": -5,
      "name": "Rock_Chalk"
    },
    {
      "x": -21,
      "y": 21,
      "z": -5,
      "name": "Rock_Chalk"
    },
    {
      "x": -21,
      "y": 22,
      "z": -5,
      "name": "Rock_Chalk"
    },
    {
      "x": -21,
      "y": 23,
      "z": -5,
      "name": "Rock_Chalk"
    },
    {
      "x": -21,
      "y": 24,
      "z": -5,
      "name": "Rock_Chalk"
    },
    {
      "x": -21,
      "y": 25,
      "z": -5,
      "name": "Rock_Chalk"
    },
    {
      "x": -21,
      "y": 26,
      "z": -5,
      "name": "Rock_Chalk"
    },
    {
      "x": -21,
      "y": 27,
      "z": -5,
      "name": "Rock_Marble"
    },
    {
      "x": -21,
      "y": 28,
      "z": -5,
      "name": "Rock_Marble"
    },
    {
      "x": -21,
      "y": 29,
      "z": -5,
      "name": "Rock_Marble"
    },
    {
      "x": -21,
      "y": 30,
      "z": -5,
      "name": "Rock_Marble"
    },
    {
      "x": -21,
      "y": 31,
      "z": -5,
      "name": "Rock_Marble"
    },
    {
      "x": -21,
      "y": 32,
      "z": -5,
      "name": "Rock_Marble"
    },
    {
      "x": -21,
      "y": 33,
      "z": -5,
      "name": "Rock_Marble"
    },
    {
      "x": -21,
      "y": 34,
      "z": -5,
      "name": "Rock_Chalk"
    },
    {
      "x": -21,
      "y": 35,
      "z": -5,
      "name": "Rock_Chalk"
    },
    {
      "x": -21,
      "y": 36,
      "z": -5,
      "name": "Rock_Chalk"
    },
    {
      "x": -21,
      "y": 37,
      "z": -5,
      "name": "Rock_Chalk"
    },
    {
      "x": -21,
      "y": 38,
      "z": -5,
      "name": "Rock_Marble"
    },
    {
      "x": -21,
      "y": 39,
      "z": -5,
      "name": "Rock_Marble"
    },
    {
      "x": -21,
      "y": 40,
      "z": -5,
      "name": "Soil_Dirt"
    },
    {
      "x": -21,
      "y": 41,
      "z": -5,
      "name": "Soil_Grass"
    },
    {
      "x": -21,
      "y": 3,
      "z": -4,
      "name": "Rock_Marble"
    },
    {
      "x": -21,
      "y": 4,
      "z": -4,
      "name": "Rock_Marble"
    },
    {
      "x": -21,
      "y": 5,
      "z": -4,
      "name": "Rock_Marble"
    },
    {
      "x": -21,
      "y": 6,
      "z": -4,
      "name": "Rock_Marble"
    },
    {
      "x": -21,
      "y": 7,
      "z": -4,
      "name": "Rock_Marble"
    },
    {
      "x": -21,
      "y": 8,
      "z": -4,
      "name": "Rock_Marble"
    },
    {
      "x": -21,
      "y": 9,
      "z": -4,
      "name": "Rock_Marble"
    },
    {
      "x": -21,
      "y": 10,
      "z": -4,
      "name": "Rock_Marble"
    },
    {
      "x": -21,
      "y": 11,
      "z": -4,
      "name": "Rock_Marble"
    },
    {
      "x": -21,
      "y": 12,
      "z": -4,
      "name": "Rock_Marble"
    },
    {
      "x": -21,
      "y": 13,
      "z": -4,
      "name": "Rock_Marble"
    },
    {
      "x": -21,
      "y": 14,
      "z": -4,
      "name": "Rock_Marble"
    },
    {
      "x": -21,
      "y": 15,
      "z": -4,
      "name": "Rock_Marble"
    },
    {
      "x": -21,
      "y": 16,
      "z": -4,
      "name": "Rock_Marble"
    },
    {
      "x": -21,
      "y": 17,
      "z": -4,
      "name": "Rock_Marble"
    },
    {
      "x": -21,
      "y": 18,
      "z": -4,
      "name": "Rock_Marble"
    },
    {
      "x": -21,
      "y": 19,
      "z": -4,
      "name": "Rock_Marble"
    },
    {
      "x": -21,
      "y": 20,
      "z": -4,
      "name": "Rock_Marble"
    },
    {
      "x": -21,
      "y": 21,
      "z": -4,
      "name": "Rock_Marble"
    },
    {
      "x": -21,
      "y": 22,
      "z": -4,
      "name": "Rock_Marble"
    },
    {
      "x": -21,
      "y": 23,
      "z": -4,
      "name": "Rock_Marble"
    },
    {
      "x": -21,
      "y": 24,
      "z": -4,
      "name": "Rock_Marble"
    },
    {
      "x": -21,
      "y": 25,
      "z": -4,
      "name": "Rock_Marble"
    },
    {
      "x": -21,
      "y": 26,
      "z": -4,
      "name": "Rock_Marble"
    },
    {
      "x": -21,
      "y": 27,
      "z": -4,
      "name": "Rock_Marble"
    },
    {
      "x": -21,
      "y": 28,
      "z": -4,
      "name": "Rock_Marble"
    },
    {
      "x": -21,
      "y": 29,
      "z": -4,
      "name": "Rock_Marble"
    },
    {
      "x": -21,
      "y": 30,
      "z": -4,
      "name": "Rock_Marble"
    },
    {
      "x": -21,
      "y": 31,
      "z": -4,
      "name": "Rock_Marble"
    },
    {
      "x": -21,
      "y": 32,
      "z": -4,
      "name": "Rock_Marble"
    },
    {
      "x": -21,
      "y": 33,
      "z": -4,
      "name": "Rock_Marble"
    },
    {
      "x": -21,
      "y": 34,
      "z": -4,
      "name": "Rock_Marble"
    },
    {
      "x": -21,
      "y": 35,
      "z": -4,
      "name": "Rock_Marble"
    },
    {
      "x": -21,
      "y": 36,
      "z": -4,
      "name": "Rock_Marble"
    },
    {
      "x": -21,
      "y": 37,
      "z": -4,
      "name": "Rock_Marble"
    },
    {
      "x": -21,
      "y": 38,
      "z": -4,
      "name": "Rock_Marble"
    },
    {
      "x": -21,
      "y": 39,
      "z": -4,
      "name": "Rock_Marble"
    },
    {
      "x": -21,
      "y": 40,
      "z": -4,
      "name": "Soil_Dirt"
    },
    {
      "x": -21,
      "y": 41,
      "z": -4,
      "name": "Soil_Grass"
    },
    {
      "x": -21,
      "y": 3,
      "z": -3,
      "name": "Rock_Marble"
    },
    {
      "x": -21,
      "y": 4,
      "z": -3,
      "name": "Rock_Marble"
    },
    {
      "x": -21,
      "y": 5,
      "z": -3,
      "name": "Rock_Marble"
    },
    {
      "x": -21,
      "y": 6,
      "z": -3,
      "name": "Rock_Marble"
    },
    {
      "x": -21,
      "y": 7,
      "z": -3,
      "name": "Rock_Marble"
    },
    {
      "x": -21,
      "y": 8,
      "z": -3,
      "name": "Rock_Marble"
    },
    {
      "x": -21,
      "y": 9,
      "z": -3,
      "name": "Rock_Marble"
    },
    {
      "x": -21,
      "y": 10,
      "z": -3,
      "name": "Rock_Marble"
    },
    {
      "x": -21,
      "y": 11,
      "z": -3,
      "name": "Rock_Marble"
    },
    {
      "x": -21,
      "y": 12,
      "z": -3,
      "name": "Rock_Marble"
    },
    {
      "x": -21,
      "y": 13,
      "z": -3,
      "name": "Rock_Marble"
    },
    {
      "x": -21,
      "y": 14,
      "z": -3,
      "name": "Rock_Marble"
    },
    {
      "x": -21,
      "y": 15,
      "z": -3,
      "name": "Rock_Marble"
    },
    {
      "x": -21,
      "y": 16,
      "z": -3,
      "name": "Rock_Marble"
    },
    {
      "x": -21,
      "y": 17,
      "z": -3,
      "name": "Rock_Marble"
    },
    {
      "x": -21,
      "y": 18,
      "z": -3,
      "name": "Rock_Marble"
    },
    {
      "x": -21,
      "y": 19,
      "z": -3,
      "name": "Rock_Marble"
    },
    {
      "x": -21,
      "y": 20,
      "z": -3,
      "name": "Rock_Marble"
    },
    {
      "x": -21,
      "y": 21,
      "z": -3,
      "name": "Rock_Marble"
    },
    {
      "x": -21,
      "y": 22,
      "z": -3,
      "name": "Rock_Marble"
    },
    {
      "x": -21,
      "y": 23,
      "z": -3,
      "name": "Rock_Marble"
    },
    {
      "x": -21,
      "y": 24,
      "z": -3,
      "name": "Rock_Marble"
    },
    {
      "x": -21,
      "y": 25,
      "z": -3,
      "name": "Rock_Marble"
    },
    {
      "x": -21,
      "y": 26,
      "z": -3,
      "name": "Rock_Marble"
    },
    {
      "x": -21,
      "y": 27,
      "z": -3,
      "name": "Rock_Marble"
    },
    {
      "x": -21,
      "y": 28,
      "z": -3,
      "name": "Rock_Marble"
    },
    {
      "x": -21,
      "y": 29,
      "z": -3,
      "name": "Rock_Marble"
    },
    {
      "x": -21,
      "y": 30,
      "z": -3,
      "name": "Rock_Marble"
    },
    {
      "x": -21,
      "y": 31,
      "z": -3,
      "name": "Rock_Marble"
    },
    {
      "x": -21,
      "y": 32,
      "z": -3,
      "name": "Rock_Marble"
    },
    {
      "x": -21,
      "y": 33,
      "z": -3,
      "name": "Rock_Marble"
    },
    {
      "x": -21,
      "y": 34,
      "z": -3,
      "name": "Rock_Marble"
    },
    {
      "x": -21,
      "y": 35,
      "z": -3,
      "name": "Rock_Marble"
    },
    {
      "x": -21,
      "y": 36,
      "z": -3,
      "name": "Rock_Marble"
    },
    {
      "x": -21,
      "y": 37,
      "z": -3,
      "name": "Rock_Marble"
    },
    {
      "x": -21,
      "y": 38,
      "z": -3,
      "name": "Rock_Marble"
    },
    {
      "x": -21,
      "y": 39,
      "z": -3,
      "name": "Rock_Marble"
    },
    {
      "x": -21,
      "y": 40,
      "z": -3,
      "name": "Rock_Marble"
    },
    {
      "x": -21,
      "y": 41,
      "z": -3,
      "name": "Soil_Dirt"
    },
    {
      "x": -21,
      "y": 42,
      "z": -3,
      "name": "Soil_Grass"
    },
    {
      "x": -21,
      "y": 2,
      "z": -2,
      "name": "Rock_Marble"
    },
    {
      "x": -21,
      "y": 3,
      "z": -2,
      "name": "Rock_Marble"
    },
    {
      "x": -21,
      "y": 4,
      "z": -2,
      "name": "Rock_Marble"
    },
    {
      "x": -21,
      "y": 5,
      "z": -2,
      "name": "Rock_Marble"
    },
    {
      "x": -21,
      "y": 6,
      "z": -2,
      "name": "Rock_Marble"
    },
    {
      "x": -21,
      "y": 7,
      "z": -2,
      "name": "Rock_Marble"
    },
    {
      "x": -21,
      "y": 8,
      "z": -2,
      "name": "Rock_Marble"
    },
    {
      "x": -21,
      "y": 9,
      "z": -2,
      "name": "Rock_Marble"
    },
    {
      "x": -21,
      "y": 10,
      "z": -2,
      "name": "Rock_Marble"
    },
    {
      "x": -21,
      "y": 11,
      "z": -2,
      "name": "Rock_Marble"
    },
    {
      "x": -21,
      "y": 12,
      "z": -2,
      "name": "Rock_Marble"
    },
    {
      "x": -21,
      "y": 13,
      "z": -2,
      "name": "Rock_Marble"
    },
    {
      "x": -21,
      "y": 14,
      "z": -2,
      "name": "Rock_Marble"
    },
    {
      "x": -21,
      "y": 15,
      "z": -2,
      "name": "Rock_Marble"
    },
    {
      "x": -21,
      "y": 16,
      "z": -2,
      "name": "Rock_Marble"
    },
    {
      "x": -21,
      "y": 17,
      "z": -2,
      "name": "Rock_Marble"
    },
    {
      "x": -21,
      "y": 18,
      "z": -2,
      "name": "Rock_Marble"
    },
    {
      "x": -21,
      "y": 19,
      "z": -2,
      "name": "Rock_Marble"
    },
    {
      "x": -21,
      "y": 20,
      "z": -2,
      "name": "Rock_Marble"
    },
    {
      "x": -21,
      "y": 21,
      "z": -2,
      "name": "Rock_Marble"
    },
    {
      "x": -21,
      "y": 22,
      "z": -2,
      "name": "Rock_Marble"
    },
    {
      "x": -21,
      "y": 23,
      "z": -2,
      "name": "Rock_Marble"
    },
    {
      "x": -21,
      "y": 24,
      "z": -2,
      "name": "Rock_Marble"
    },
    {
      "x": -21,
      "y": 25,
      "z": -2,
      "name": "Rock_Marble"
    },
    {
      "x": -21,
      "y": 26,
      "z": -2,
      "name": "Rock_Marble"
    },
    {
      "x": -21,
      "y": 27,
      "z": -2,
      "name": "Rock_Marble"
    },
    {
      "x": -21,
      "y": 28,
      "z": -2,
      "name": "Rock_Marble"
    },
    {
      "x": -21,
      "y": 29,
      "z": -2,
      "name": "Rock_Marble"
    },
    {
      "x": -21,
      "y": 30,
      "z": -2,
      "name": "Rock_Marble"
    },
    {
      "x": -21,
      "y": 31,
      "z": -2,
      "name": "Rock_Marble"
    },
    {
      "x": -21,
      "y": 32,
      "z": -2,
      "name": "Rock_Marble"
    },
    {
      "x": -21,
      "y": 33,
      "z": -2,
      "name": "Rock_Marble"
    },
    {
      "x": -21,
      "y": 34,
      "z": -2,
      "name": "Rock_Marble"
    },
    {
      "x": -21,
      "y": 35,
      "z": -2,
      "name": "Rock_Marble"
    },
    {
      "x": -21,
      "y": 36,
      "z": -2,
      "name": "Rock_Marble"
    },
    {
      "x": -21,
      "y": 37,
      "z": -2,
      "name": "Rock_Marble"
    },
    {
      "x": -21,
      "y": 38,
      "z": -2,
      "name": "Rock_Marble"
    },
    {
      "x": -21,
      "y": 39,
      "z": -2,
      "name": "Rock_Marble"
    },
    {
      "x": -21,
      "y": 40,
      "z": -2,
      "name": "Rock_Marble"
    },
    {
      "x": -21,
      "y": 41,
      "z": -2,
      "name": "Soil_Dirt"
    },
    {
      "x": -21,
      "y": 42,
      "z": -2,
      "name": "Soil_Grass"
    },
    {
      "x": -21,
      "y": 2,
      "z": -1,
      "name": "Rock_Marble"
    },
    {
      "x": -21,
      "y": 3,
      "z": -1,
      "name": "Rock_Marble"
    },
    {
      "x": -21,
      "y": 4,
      "z": -1,
      "name": "Rock_Marble"
    },
    {
      "x": -21,
      "y": 5,
      "z": -1,
      "name": "Rock_Marble"
    },
    {
      "x": -21,
      "y": 6,
      "z": -1,
      "name": "Rock_Marble"
    },
    {
      "x": -21,
      "y": 7,
      "z": -1,
      "name": "Rock_Marble"
    },
    {
      "x": -21,
      "y": 8,
      "z": -1,
      "name": "Rock_Marble"
    },
    {
      "x": -21,
      "y": 9,
      "z": -1,
      "name": "Rock_Marble"
    },
    {
      "x": -21,
      "y": 10,
      "z": -1,
      "name": "Rock_Marble"
    },
    {
      "x": -21,
      "y": 11,
      "z": -1,
      "name": "Rock_Marble"
    },
    {
      "x": -21,
      "y": 12,
      "z": -1,
      "name": "Rock_Marble"
    },
    {
      "x": -21,
      "y": 13,
      "z": -1,
      "name": "Rock_Marble"
    },
    {
      "x": -21,
      "y": 14,
      "z": -1,
      "name": "Rock_Marble"
    },
    {
      "x": -21,
      "y": 15,
      "z": -1,
      "name": "Rock_Marble"
    },
    {
      "x": -21,
      "y": 16,
      "z": -1,
      "name": "Rock_Marble"
    },
    {
      "x": -21,
      "y": 17,
      "z": -1,
      "name": "Rock_Marble"
    },
    {
      "x": -21,
      "y": 18,
      "z": -1,
      "name": "Rock_Marble"
    },
    {
      "x": -21,
      "y": 19,
      "z": -1,
      "name": "Rock_Marble"
    },
    {
      "x": -21,
      "y": 20,
      "z": -1,
      "name": "Rock_Marble"
    },
    {
      "x": -21,
      "y": 21,
      "z": -1,
      "name": "Rock_Marble"
    },
    {
      "x": -21,
      "y": 22,
      "z": -1,
      "name": "Rock_Marble"
    },
    {
      "x": -21,
      "y": 23,
      "z": -1,
      "name": "Rock_Marble"
    },
    {
      "x": -21,
      "y": 24,
      "z": -1,
      "name": "Rock_Marble"
    },
    {
      "x": -21,
      "y": 25,
      "z": -1,
      "name": "Rock_Marble"
    },
    {
      "x": -21,
      "y": 26,
      "z": -1,
      "name": "Rock_Marble"
    },
    {
      "x": -21,
      "y": 27,
      "z": -1,
      "name": "Rock_Marble"
    },
    {
      "x": -21,
      "y": 28,
      "z": -1,
      "name": "Rock_Marble"
    },
    {
      "x": -21,
      "y": 29,
      "z": -1,
      "name": "Rock_Marble"
    },
    {
      "x": -21,
      "y": 30,
      "z": -1,
      "name": "Rock_Marble"
    },
    {
      "x": -21,
      "y": 31,
      "z": -1,
      "name": "Rock_Marble"
    },
    {
      "x": -21,
      "y": 32,
      "z": -1,
      "name": "Rock_Marble"
    },
    {
      "x": -21,
      "y": 33,
      "z": -1,
      "name": "Rock_Marble"
    },
    {
      "x": -21,
      "y": 34,
      "z": -1,
      "name": "Rock_Marble"
    },
    {
      "x": -21,
      "y": 35,
      "z": -1,
      "name": "Rock_Marble"
    },
    {
      "x": -21,
      "y": 36,
      "z": -1,
      "name": "Rock_Marble"
    },
    {
      "x": -21,
      "y": 37,
      "z": -1,
      "name": "Rock_Marble"
    },
    {
      "x": -21,
      "y": 38,
      "z": -1,
      "name": "Rock_Marble"
    },
    {
      "x": -21,
      "y": 39,
      "z": -1,
      "name": "Rock_Marble"
    },
    {
      "x": -21,
      "y": 40,
      "z": -1,
      "name": "Rock_Marble"
    },
    {
      "x": -21,
      "y": 41,
      "z": -1,
      "name": "Rock_Marble"
    },
    {
      "x": -21,
      "y": 42,
      "z": -1,
      "name": "Soil_Grass"
    },
    {
      "x": -21,
      "y": 2,
      "z": 0,
      "name": "Rock_Marble"
    },
    {
      "x": -21,
      "y": 3,
      "z": 0,
      "name": "Rock_Marble"
    },
    {
      "x": -21,
      "y": 4,
      "z": 0,
      "name": "Rock_Marble"
    },
    {
      "x": -21,
      "y": 5,
      "z": 0,
      "name": "Rock_Marble"
    },
    {
      "x": -21,
      "y": 6,
      "z": 0,
      "name": "Rock_Marble"
    },
    {
      "x": -21,
      "y": 7,
      "z": 0,
      "name": "Rock_Marble"
    },
    {
      "x": -21,
      "y": 8,
      "z": 0,
      "name": "Rock_Marble"
    },
    {
      "x": -21,
      "y": 9,
      "z": 0,
      "name": "Rock_Marble"
    },
    {
      "x": -21,
      "y": 10,
      "z": 0,
      "name": "Rock_Marble"
    },
    {
      "x": -21,
      "y": 11,
      "z": 0,
      "name": "Rock_Marble"
    },
    {
      "x": -21,
      "y": 12,
      "z": 0,
      "name": "Rock_Marble"
    },
    {
      "x": -21,
      "y": 13,
      "z": 0,
      "name": "Rock_Marble"
    },
    {
      "x": -21,
      "y": 14,
      "z": 0,
      "name": "Rock_Marble"
    },
    {
      "x": -21,
      "y": 15,
      "z": 0,
      "name": "Rock_Marble"
    },
    {
      "x": -21,
      "y": 16,
      "z": 0,
      "name": "Rock_Marble"
    },
    {
      "x": -21,
      "y": 17,
      "z": 0,
      "name": "Rock_Marble"
    },
    {
      "x": -21,
      "y": 18,
      "z": 0,
      "name": "Rock_Marble"
    },
    {
      "x": -21,
      "y": 19,
      "z": 0,
      "name": "Rock_Marble"
    },
    {
      "x": -21,
      "y": 20,
      "z": 0,
      "name": "Rock_Marble"
    },
    {
      "x": -21,
      "y": 21,
      "z": 0,
      "name": "Rock_Marble"
    },
    {
      "x": -21,
      "y": 22,
      "z": 0,
      "name": "Rock_Marble"
    },
    {
      "x": -21,
      "y": 23,
      "z": 0,
      "name": "Rock_Marble"
    },
    {
      "x": -21,
      "y": 24,
      "z": 0,
      "name": "Rock_Marble"
    },
    {
      "x": -21,
      "y": 25,
      "z": 0,
      "name": "Rock_Marble"
    },
    {
      "x": -21,
      "y": 26,
      "z": 0,
      "name": "Rock_Marble"
    },
    {
      "x": -21,
      "y": 27,
      "z": 0,
      "name": "Rock_Marble"
    },
    {
      "x": -21,
      "y": 28,
      "z": 0,
      "name": "Rock_Marble"
    },
    {
      "x": -21,
      "y": 29,
      "z": 0,
      "name": "Rock_Marble"
    },
    {
      "x": -21,
      "y": 30,
      "z": 0,
      "name": "Rock_Marble"
    },
    {
      "x": -21,
      "y": 31,
      "z": 0,
      "name": "Rock_Marble"
    },
    {
      "x": -21,
      "y": 32,
      "z": 0,
      "name": "Rock_Marble"
    },
    {
      "x": -21,
      "y": 33,
      "z": 0,
      "name": "Rock_Marble"
    },
    {
      "x": -21,
      "y": 34,
      "z": 0,
      "name": "Rock_Marble"
    },
    {
      "x": -21,
      "y": 35,
      "z": 0,
      "name": "Rock_Marble"
    },
    {
      "x": -21,
      "y": 36,
      "z": 0,
      "name": "Rock_Marble"
    },
    {
      "x": -21,
      "y": 37,
      "z": 0,
      "name": "Rock_Marble"
    },
    {
      "x": -21,
      "y": 38,
      "z": 0,
      "name": "Rock_Marble"
    },
    {
      "x": -21,
      "y": 39,
      "z": 0,
      "name": "Rock_Marble"
    },
    {
      "x": -21,
      "y": 40,
      "z": 0,
      "name": "Rock_Marble"
    },
    {
      "x": -21,
      "y": 41,
      "z": 0,
      "name": "Rock_Marble"
    },
    {
      "x": -21,
      "y": 42,
      "z": 0,
      "name": "Rock_Marble"
    },
    {
      "x": -21,
      "y": 3,
      "z": 1,
      "name": "Rock_Marble"
    },
    {
      "x": -21,
      "y": 4,
      "z": 1,
      "name": "Rock_Marble"
    },
    {
      "x": -21,
      "y": 5,
      "z": 1,
      "name": "Rock_Marble"
    },
    {
      "x": -21,
      "y": 6,
      "z": 1,
      "name": "Rock_Marble"
    },
    {
      "x": -21,
      "y": 7,
      "z": 1,
      "name": "Rock_Marble"
    },
    {
      "x": -21,
      "y": 8,
      "z": 1,
      "name": "Rock_Marble"
    },
    {
      "x": -21,
      "y": 9,
      "z": 1,
      "name": "Rock_Marble"
    },
    {
      "x": -21,
      "y": 10,
      "z": 1,
      "name": "Rock_Marble"
    },
    {
      "x": -21,
      "y": 11,
      "z": 1,
      "name": "Rock_Marble"
    },
    {
      "x": -21,
      "y": 12,
      "z": 1,
      "name": "Rock_Marble"
    },
    {
      "x": -21,
      "y": 13,
      "z": 1,
      "name": "Rock_Marble"
    },
    {
      "x": -21,
      "y": 14,
      "z": 1,
      "name": "Rock_Marble"
    },
    {
      "x": -21,
      "y": 15,
      "z": 1,
      "name": "Rock_Marble"
    },
    {
      "x": -21,
      "y": 16,
      "z": 1,
      "name": "Rock_Marble"
    },
    {
      "x": -21,
      "y": 17,
      "z": 1,
      "name": "Rock_Marble"
    },
    {
      "x": -21,
      "y": 18,
      "z": 1,
      "name": "Rock_Marble"
    },
    {
      "x": -21,
      "y": 33,
      "z": 1,
      "name": "Rock_Marble"
    },
    {
      "x": -21,
      "y": 34,
      "z": 1,
      "name": "Rock_Marble"
    },
    {
      "x": -21,
      "y": 35,
      "z": 1,
      "name": "Rock_Marble"
    },
    {
      "x": -21,
      "y": 36,
      "z": 1,
      "name": "Rock_Marble"
    },
    {
      "x": -21,
      "y": 37,
      "z": 1,
      "name": "Rock_Marble"
    },
    {
      "x": -21,
      "y": 38,
      "z": 1,
      "name": "Rock_Marble"
    },
    {
      "x": -21,
      "y": 39,
      "z": 1,
      "name": "Rock_Marble"
    },
    {
      "x": -21,
      "y": 40,
      "z": 1,
      "name": "Rock_Marble"
    },
    {
      "x": -21,
      "y": 4,
      "z": 2,
      "name": "Rock_Marble"
    },
    {
      "x": -21,
      "y": 5,
      "z": 2,
      "name": "Rock_Marble"
    },
    {
      "x": -21,
      "y": 6,
      "z": 2,
      "name": "Rock_Marble"
    },
    {
      "x": -21,
      "y": 7,
      "z": 2,
      "name": "Rock_Marble"
    },
    {
      "x": -21,
      "y": 8,
      "z": 2,
      "name": "Rock_Marble"
    },
    {
      "x": -21,
      "y": 9,
      "z": 2,
      "name": "Rock_Marble"
    },
    {
      "x": -21,
      "y": 10,
      "z": 2,
      "name": "Rock_Marble"
    },
    {
      "x": -21,
      "y": 11,
      "z": 2,
      "name": "Rock_Marble"
    },
    {
      "x": -21,
      "y": 12,
      "z": 2,
      "name": "Rock_Marble"
    },
    {
      "x": -21,
      "y": 13,
      "z": 2,
      "name": "Rock_Marble"
    },
    {
      "x": -21,
      "y": 14,
      "z": 2,
      "name": "Rock_Marble"
    },
    {
      "x": -20,
      "y": 3,
      "z": -13,
      "name": "Rock_Chalk"
    },
    {
      "x": -20,
      "y": 4,
      "z": -13,
      "name": "Rock_Chalk"
    },
    {
      "x": -20,
      "y": 5,
      "z": -13,
      "name": "Rock_Chalk"
    },
    {
      "x": -20,
      "y": 6,
      "z": -13,
      "name": "Rock_Chalk"
    },
    {
      "x": -20,
      "y": 7,
      "z": -13,
      "name": "Rock_Chalk"
    },
    {
      "x": -20,
      "y": 3,
      "z": -12,
      "name": "Rock_Chalk"
    },
    {
      "x": -20,
      "y": 4,
      "z": -12,
      "name": "Rock_Chalk"
    },
    {
      "x": -20,
      "y": 5,
      "z": -12,
      "name": "Rock_Chalk"
    },
    {
      "x": -20,
      "y": 6,
      "z": -12,
      "name": "Rock_Chalk"
    },
    {
      "x": -20,
      "y": 7,
      "z": -12,
      "name": "Rock_Chalk"
    },
    {
      "x": -20,
      "y": 8,
      "z": -12,
      "name": "Rock_Chalk"
    },
    {
      "x": -20,
      "y": 9,
      "z": -12,
      "name": "Rock_Chalk"
    },
    {
      "x": -20,
      "y": 3,
      "z": -11,
      "name": "Rock_Chalk"
    },
    {
      "x": -20,
      "y": 4,
      "z": -11,
      "name": "Rock_Chalk"
    },
    {
      "x": -20,
      "y": 5,
      "z": -11,
      "name": "Rock_Chalk"
    },
    {
      "x": -20,
      "y": 6,
      "z": -11,
      "name": "Rock_Chalk"
    },
    {
      "x": -20,
      "y": 7,
      "z": -11,
      "name": "Rock_Chalk"
    },
    {
      "x": -20,
      "y": 8,
      "z": -11,
      "name": "Rock_Chalk"
    },
    {
      "x": -20,
      "y": 9,
      "z": -11,
      "name": "Rock_Chalk"
    },
    {
      "x": -20,
      "y": 10,
      "z": -11,
      "name": "Rock_Chalk"
    },
    {
      "x": -20,
      "y": 11,
      "z": -11,
      "name": "Rock_Chalk"
    },
    {
      "x": -20,
      "y": 12,
      "z": -11,
      "name": "Rock_Chalk"
    },
    {
      "x": -20,
      "y": 2,
      "z": -10,
      "name": "Rock_Chalk"
    },
    {
      "x": -20,
      "y": 3,
      "z": -10,
      "name": "Rock_Chalk"
    },
    {
      "x": -20,
      "y": 4,
      "z": -10,
      "name": "Rock_Chalk"
    },
    {
      "x": -20,
      "y": 5,
      "z": -10,
      "name": "Rock_Chalk"
    },
    {
      "x": -20,
      "y": 6,
      "z": -10,
      "name": "Rock_Chalk"
    },
    {
      "x": -20,
      "y": 7,
      "z": -10,
      "name": "Rock_Chalk"
    },
    {
      "x": -20,
      "y": 8,
      "z": -10,
      "name": "Rock_Chalk"
    },
    {
      "x": -20,
      "y": 9,
      "z": -10,
      "name": "Rock_Chalk"
    },
    {
      "x": -20,
      "y": 10,
      "z": -10,
      "name": "Rock_Chalk"
    },
    {
      "x": -20,
      "y": 11,
      "z": -10,
      "name": "Rock_Chalk"
    },
    {
      "x": -20,
      "y": 12,
      "z": -10,
      "name": "Rock_Chalk"
    },
    {
      "x": -20,
      "y": 13,
      "z": -10,
      "name": "Rock_Chalk"
    },
    {
      "x": -20,
      "y": 14,
      "z": -10,
      "name": "Rock_Chalk"
    },
    {
      "x": -20,
      "y": 15,
      "z": -10,
      "name": "Rock_Chalk"
    },
    {
      "x": -20,
      "y": 16,
      "z": -10,
      "name": "Rock_Chalk"
    },
    {
      "x": -20,
      "y": 17,
      "z": -10,
      "name": "Rock_Chalk"
    },
    {
      "x": -20,
      "y": 18,
      "z": -10,
      "name": "Rock_Chalk"
    },
    {
      "x": -20,
      "y": 19,
      "z": -10,
      "name": "Rock_Chalk"
    },
    {
      "x": -20,
      "y": 20,
      "z": -10,
      "name": "Rock_Chalk"
    },
    {
      "x": -20,
      "y": 21,
      "z": -10,
      "name": "Rock_Chalk"
    },
    {
      "x": -20,
      "y": 22,
      "z": -10,
      "name": "Rock_Chalk"
    },
    {
      "x": -20,
      "y": 23,
      "z": -10,
      "name": "Rock_Chalk"
    },
    {
      "x": -20,
      "y": 3,
      "z": -9,
      "name": "Rock_Chalk"
    },
    {
      "x": -20,
      "y": 4,
      "z": -9,
      "name": "Rock_Chalk"
    },
    {
      "x": -20,
      "y": 5,
      "z": -9,
      "name": "Rock_Chalk"
    },
    {
      "x": -20,
      "y": 6,
      "z": -9,
      "name": "Rock_Chalk"
    },
    {
      "x": -20,
      "y": 7,
      "z": -9,
      "name": "Rock_Chalk"
    },
    {
      "x": -20,
      "y": 8,
      "z": -9,
      "name": "Rock_Chalk"
    },
    {
      "x": -20,
      "y": 9,
      "z": -9,
      "name": "Rock_Chalk"
    },
    {
      "x": -20,
      "y": 10,
      "z": -9,
      "name": "Rock_Chalk"
    },
    {
      "x": -20,
      "y": 11,
      "z": -9,
      "name": "Rock_Chalk"
    },
    {
      "x": -20,
      "y": 12,
      "z": -9,
      "name": "Rock_Chalk"
    },
    {
      "x": -20,
      "y": 13,
      "z": -9,
      "name": "Rock_Chalk"
    },
    {
      "x": -20,
      "y": 14,
      "z": -9,
      "name": "Rock_Chalk"
    },
    {
      "x": -20,
      "y": 15,
      "z": -9,
      "name": "Rock_Chalk"
    },
    {
      "x": -20,
      "y": 16,
      "z": -9,
      "name": "Rock_Chalk"
    },
    {
      "x": -20,
      "y": 17,
      "z": -9,
      "name": "Rock_Chalk"
    },
    {
      "x": -20,
      "y": 18,
      "z": -9,
      "name": "Rock_Chalk"
    },
    {
      "x": -20,
      "y": 19,
      "z": -9,
      "name": "Rock_Chalk"
    },
    {
      "x": -20,
      "y": 20,
      "z": -9,
      "name": "Rock_Chalk"
    },
    {
      "x": -20,
      "y": 21,
      "z": -9,
      "name": "Rock_Chalk"
    },
    {
      "x": -20,
      "y": 22,
      "z": -9,
      "name": "Rock_Chalk"
    },
    {
      "x": -20,
      "y": 23,
      "z": -9,
      "name": "Rock_Chalk"
    },
    {
      "x": -20,
      "y": 24,
      "z": -9,
      "name": "Rock_Chalk"
    },
    {
      "x": -20,
      "y": 25,
      "z": -9,
      "name": "Rock_Chalk"
    },
    {
      "x": -20,
      "y": 26,
      "z": -9,
      "name": "Rock_Chalk"
    },
    {
      "x": -20,
      "y": 27,
      "z": -9,
      "name": "Rock_Chalk"
    },
    {
      "x": -20,
      "y": 28,
      "z": -9,
      "name": "Rock_Chalk"
    },
    {
      "x": -20,
      "y": 29,
      "z": -9,
      "name": "Rock_Chalk"
    },
    {
      "x": -20,
      "y": 30,
      "z": -9,
      "name": "Rock_Chalk"
    },
    {
      "x": -20,
      "y": 31,
      "z": -9,
      "name": "Rock_Chalk"
    },
    {
      "x": -20,
      "y": 32,
      "z": -9,
      "name": "Rock_Chalk"
    },
    {
      "x": -20,
      "y": 33,
      "z": -9,
      "name": "Rock_Chalk"
    },
    {
      "x": -20,
      "y": 34,
      "z": -9,
      "name": "Rock_Chalk"
    },
    {
      "x": -20,
      "y": 35,
      "z": -9,
      "name": "Rock_Chalk"
    },
    {
      "x": -20,
      "y": 3,
      "z": -8,
      "name": "Rock_Chalk"
    },
    {
      "x": -20,
      "y": 4,
      "z": -8,
      "name": "Rock_Chalk"
    },
    {
      "x": -20,
      "y": 5,
      "z": -8,
      "name": "Rock_Chalk"
    },
    {
      "x": -20,
      "y": 6,
      "z": -8,
      "name": "Rock_Chalk"
    },
    {
      "x": -20,
      "y": 7,
      "z": -8,
      "name": "Rock_Chalk"
    },
    {
      "x": -20,
      "y": 8,
      "z": -8,
      "name": "Rock_Chalk"
    },
    {
      "x": -20,
      "y": 9,
      "z": -8,
      "name": "Rock_Chalk"
    },
    {
      "x": -20,
      "y": 10,
      "z": -8,
      "name": "Rock_Chalk"
    },
    {
      "x": -20,
      "y": 11,
      "z": -8,
      "name": "Rock_Chalk"
    },
    {
      "x": -20,
      "y": 12,
      "z": -8,
      "name": "Rock_Chalk"
    },
    {
      "x": -20,
      "y": 13,
      "z": -8,
      "name": "Rock_Chalk"
    },
    {
      "x": -20,
      "y": 14,
      "z": -8,
      "name": "Rock_Chalk"
    },
    {
      "x": -20,
      "y": 15,
      "z": -8,
      "name": "Rock_Chalk"
    },
    {
      "x": -20,
      "y": 16,
      "z": -8,
      "name": "Rock_Chalk"
    },
    {
      "x": -20,
      "y": 17,
      "z": -8,
      "name": "Rock_Chalk"
    },
    {
      "x": -20,
      "y": 18,
      "z": -8,
      "name": "Rock_Chalk"
    },
    {
      "x": -20,
      "y": 19,
      "z": -8,
      "name": "Rock_Chalk"
    },
    {
      "x": -20,
      "y": 20,
      "z": -8,
      "name": "Rock_Chalk"
    },
    {
      "x": -20,
      "y": 21,
      "z": -8,
      "name": "Rock_Chalk"
    },
    {
      "x": -20,
      "y": 22,
      "z": -8,
      "name": "Rock_Chalk"
    },
    {
      "x": -20,
      "y": 23,
      "z": -8,
      "name": "Rock_Chalk"
    },
    {
      "x": -20,
      "y": 24,
      "z": -8,
      "name": "Rock_Chalk"
    },
    {
      "x": -20,
      "y": 25,
      "z": -8,
      "name": "Rock_Chalk"
    },
    {
      "x": -20,
      "y": 26,
      "z": -8,
      "name": "Rock_Chalk"
    },
    {
      "x": -20,
      "y": 27,
      "z": -8,
      "name": "Rock_Chalk"
    },
    {
      "x": -20,
      "y": 28,
      "z": -8,
      "name": "Rock_Chalk"
    },
    {
      "x": -20,
      "y": 29,
      "z": -8,
      "name": "Rock_Chalk"
    },
    {
      "x": -20,
      "y": 30,
      "z": -8,
      "name": "Rock_Chalk"
    },
    {
      "x": -20,
      "y": 31,
      "z": -8,
      "name": "Rock_Chalk"
    },
    {
      "x": -20,
      "y": 32,
      "z": -8,
      "name": "Rock_Chalk"
    },
    {
      "x": -20,
      "y": 33,
      "z": -8,
      "name": "Rock_Chalk"
    },
    {
      "x": -20,
      "y": 34,
      "z": -8,
      "name": "Rock_Chalk"
    },
    {
      "x": -20,
      "y": 35,
      "z": -8,
      "name": "Rock_Chalk"
    },
    {
      "x": -20,
      "y": 36,
      "z": -8,
      "name": "Rock_Chalk"
    },
    {
      "x": -20,
      "y": 37,
      "z": -8,
      "name": "Rock_Chalk"
    },
    {
      "x": -20,
      "y": 38,
      "z": -8,
      "name": "Rock_Chalk"
    },
    {
      "x": -20,
      "y": 39,
      "z": -8,
      "name": "Rock_Chalk"
    },
    {
      "x": -20,
      "y": 40,
      "z": -8,
      "name": "Soil_Grass"
    },
    {
      "x": -20,
      "y": 3,
      "z": -7,
      "name": "Rock_Chalk"
    },
    {
      "x": -20,
      "y": 4,
      "z": -7,
      "name": "Rock_Chalk"
    },
    {
      "x": -20,
      "y": 5,
      "z": -7,
      "name": "Rock_Chalk"
    },
    {
      "x": -20,
      "y": 6,
      "z": -7,
      "name": "Rock_Chalk"
    },
    {
      "x": -20,
      "y": 7,
      "z": -7,
      "name": "Rock_Chalk"
    },
    {
      "x": -20,
      "y": 8,
      "z": -7,
      "name": "Rock_Chalk"
    },
    {
      "x": -20,
      "y": 9,
      "z": -7,
      "name": "Rock_Chalk"
    },
    {
      "x": -20,
      "y": 10,
      "z": -7,
      "name": "Rock_Chalk"
    },
    {
      "x": -20,
      "y": 11,
      "z": -7,
      "name": "Rock_Chalk"
    },
    {
      "x": -20,
      "y": 12,
      "z": -7,
      "name": "Rock_Chalk"
    },
    {
      "x": -20,
      "y": 13,
      "z": -7,
      "name": "Rock_Chalk"
    },
    {
      "x": -20,
      "y": 14,
      "z": -7,
      "name": "Rock_Chalk"
    },
    {
      "x": -20,
      "y": 15,
      "z": -7,
      "name": "Rock_Chalk"
    },
    {
      "x": -20,
      "y": 16,
      "z": -7,
      "name": "Rock_Chalk"
    },
    {
      "x": -20,
      "y": 17,
      "z": -7,
      "name": "Rock_Chalk"
    },
    {
      "x": -20,
      "y": 18,
      "z": -7,
      "name": "Rock_Chalk"
    },
    {
      "x": -20,
      "y": 19,
      "z": -7,
      "name": "Rock_Chalk"
    },
    {
      "x": -20,
      "y": 20,
      "z": -7,
      "name": "Rock_Chalk"
    },
    {
      "x": -20,
      "y": 21,
      "z": -7,
      "name": "Rock_Chalk"
    },
    {
      "x": -20,
      "y": 22,
      "z": -7,
      "name": "Rock_Chalk"
    },
    {
      "x": -20,
      "y": 23,
      "z": -7,
      "name": "Rock_Chalk"
    },
    {
      "x": -20,
      "y": 24,
      "z": -7,
      "name": "Rock_Chalk"
    },
    {
      "x": -20,
      "y": 25,
      "z": -7,
      "name": "Rock_Chalk"
    },
    {
      "x": -20,
      "y": 26,
      "z": -7,
      "name": "Rock_Chalk"
    },
    {
      "x": -20,
      "y": 27,
      "z": -7,
      "name": "Rock_Chalk"
    },
    {
      "x": -20,
      "y": 28,
      "z": -7,
      "name": "Rock_Chalk"
    },
    {
      "x": -20,
      "y": 29,
      "z": -7,
      "name": "Rock_Chalk"
    },
    {
      "x": -20,
      "y": 30,
      "z": -7,
      "name": "Rock_Chalk"
    },
    {
      "x": -20,
      "y": 31,
      "z": -7,
      "name": "Rock_Chalk"
    },
    {
      "x": -20,
      "y": 32,
      "z": -7,
      "name": "Rock_Chalk"
    },
    {
      "x": -20,
      "y": 33,
      "z": -7,
      "name": "Rock_Chalk"
    },
    {
      "x": -20,
      "y": 34,
      "z": -7,
      "name": "Rock_Chalk"
    },
    {
      "x": -20,
      "y": 35,
      "z": -7,
      "name": "Rock_Chalk"
    },
    {
      "x": -20,
      "y": 36,
      "z": -7,
      "name": "Rock_Chalk"
    },
    {
      "x": -20,
      "y": 37,
      "z": -7,
      "name": "Rock_Chalk"
    },
    {
      "x": -20,
      "y": 38,
      "z": -7,
      "name": "Rock_Chalk"
    },
    {
      "x": -20,
      "y": 39,
      "z": -7,
      "name": "Rock_Chalk"
    },
    {
      "x": -20,
      "y": 40,
      "z": -7,
      "name": "Soil_Grass"
    },
    {
      "x": -20,
      "y": 3,
      "z": -6,
      "name": "Rock_Chalk"
    },
    {
      "x": -20,
      "y": 4,
      "z": -6,
      "name": "Rock_Chalk"
    },
    {
      "x": -20,
      "y": 5,
      "z": -6,
      "name": "Rock_Chalk"
    },
    {
      "x": -20,
      "y": 6,
      "z": -6,
      "name": "Rock_Chalk"
    },
    {
      "x": -20,
      "y": 7,
      "z": -6,
      "name": "Rock_Chalk"
    },
    {
      "x": -20,
      "y": 8,
      "z": -6,
      "name": "Rock_Chalk"
    },
    {
      "x": -20,
      "y": 9,
      "z": -6,
      "name": "Rock_Chalk"
    },
    {
      "x": -20,
      "y": 10,
      "z": -6,
      "name": "Rock_Chalk"
    },
    {
      "x": -20,
      "y": 11,
      "z": -6,
      "name": "Rock_Chalk"
    },
    {
      "x": -20,
      "y": 12,
      "z": -6,
      "name": "Rock_Chalk"
    },
    {
      "x": -20,
      "y": 13,
      "z": -6,
      "name": "Rock_Chalk"
    },
    {
      "x": -20,
      "y": 14,
      "z": -6,
      "name": "Rock_Chalk"
    },
    {
      "x": -20,
      "y": 15,
      "z": -6,
      "name": "Rock_Chalk"
    },
    {
      "x": -20,
      "y": 16,
      "z": -6,
      "name": "Rock_Chalk"
    },
    {
      "x": -20,
      "y": 17,
      "z": -6,
      "name": "Rock_Chalk"
    },
    {
      "x": -20,
      "y": 18,
      "z": -6,
      "name": "Rock_Chalk"
    },
    {
      "x": -20,
      "y": 19,
      "z": -6,
      "name": "Rock_Chalk"
    },
    {
      "x": -20,
      "y": 20,
      "z": -6,
      "name": "Rock_Chalk"
    },
    {
      "x": -20,
      "y": 21,
      "z": -6,
      "name": "Rock_Chalk"
    },
    {
      "x": -20,
      "y": 22,
      "z": -6,
      "name": "Rock_Chalk"
    },
    {
      "x": -20,
      "y": 23,
      "z": -6,
      "name": "Rock_Chalk"
    },
    {
      "x": -20,
      "y": 24,
      "z": -6,
      "name": "Rock_Chalk"
    },
    {
      "x": -20,
      "y": 25,
      "z": -6,
      "name": "Rock_Chalk"
    },
    {
      "x": -20,
      "y": 26,
      "z": -6,
      "name": "Rock_Chalk"
    },
    {
      "x": -20,
      "y": 27,
      "z": -6,
      "name": "Rock_Chalk"
    },
    {
      "x": -20,
      "y": 28,
      "z": -6,
      "name": "Rock_Chalk"
    },
    {
      "x": -20,
      "y": 29,
      "z": -6,
      "name": "Rock_Chalk"
    },
    {
      "x": -20,
      "y": 30,
      "z": -6,
      "name": "Rock_Chalk"
    },
    {
      "x": -20,
      "y": 31,
      "z": -6,
      "name": "Rock_Chalk"
    },
    {
      "x": -20,
      "y": 32,
      "z": -6,
      "name": "Rock_Chalk"
    },
    {
      "x": -20,
      "y": 33,
      "z": -6,
      "name": "Rock_Chalk"
    },
    {
      "x": -20,
      "y": 34,
      "z": -6,
      "name": "Rock_Chalk"
    },
    {
      "x": -20,
      "y": 35,
      "z": -6,
      "name": "Rock_Chalk"
    },
    {
      "x": -20,
      "y": 36,
      "z": -6,
      "name": "Rock_Chalk"
    },
    {
      "x": -20,
      "y": 37,
      "z": -6,
      "name": "Rock_Chalk"
    },
    {
      "x": -20,
      "y": 38,
      "z": -6,
      "name": "Rock_Chalk"
    },
    {
      "x": -20,
      "y": 39,
      "z": -6,
      "name": "Soil_Dirt"
    },
    {
      "x": -20,
      "y": 40,
      "z": -6,
      "name": "Soil_Grass"
    },
    {
      "x": -20,
      "y": 2,
      "z": -5,
      "name": "Rock_Chalk"
    },
    {
      "x": -20,
      "y": 3,
      "z": -5,
      "name": "Rock_Chalk"
    },
    {
      "x": -20,
      "y": 4,
      "z": -5,
      "name": "Rock_Chalk"
    },
    {
      "x": -20,
      "y": 5,
      "z": -5,
      "name": "Rock_Chalk"
    },
    {
      "x": -20,
      "y": 6,
      "z": -5,
      "name": "Rock_Chalk"
    },
    {
      "x": -20,
      "y": 7,
      "z": -5,
      "name": "Rock_Chalk"
    },
    {
      "x": -20,
      "y": 8,
      "z": -5,
      "name": "Rock_Chalk"
    },
    {
      "x": -20,
      "y": 9,
      "z": -5,
      "name": "Rock_Chalk"
    },
    {
      "x": -20,
      "y": 10,
      "z": -5,
      "name": "Rock_Chalk"
    },
    {
      "x": -20,
      "y": 11,
      "z": -5,
      "name": "Rock_Chalk"
    },
    {
      "x": -20,
      "y": 12,
      "z": -5,
      "name": "Rock_Chalk"
    },
    {
      "x": -20,
      "y": 13,
      "z": -5,
      "name": "Rock_Chalk"
    },
    {
      "x": -20,
      "y": 14,
      "z": -5,
      "name": "Rock_Chalk"
    },
    {
      "x": -20,
      "y": 15,
      "z": -5,
      "name": "Rock_Chalk"
    },
    {
      "x": -20,
      "y": 16,
      "z": -5,
      "name": "Rock_Chalk"
    },
    {
      "x": -20,
      "y": 17,
      "z": -5,
      "name": "Rock_Chalk"
    },
    {
      "x": -20,
      "y": 18,
      "z": -5,
      "name": "Rock_Chalk"
    },
    {
      "x": -20,
      "y": 19,
      "z": -5,
      "name": "Rock_Chalk"
    },
    {
      "x": -20,
      "y": 20,
      "z": -5,
      "name": "Rock_Chalk"
    },
    {
      "x": -20,
      "y": 21,
      "z": -5,
      "name": "Rock_Chalk"
    },
    {
      "x": -20,
      "y": 22,
      "z": -5,
      "name": "Rock_Chalk"
    },
    {
      "x": -20,
      "y": 23,
      "z": -5,
      "name": "Rock_Chalk"
    },
    {
      "x": -20,
      "y": 24,
      "z": -5,
      "name": "Rock_Chalk"
    },
    {
      "x": -20,
      "y": 25,
      "z": -5,
      "name": "Rock_Chalk"
    },
    {
      "x": -20,
      "y": 26,
      "z": -5,
      "name": "Rock_Chalk"
    },
    {
      "x": -20,
      "y": 27,
      "z": -5,
      "name": "Rock_Chalk"
    },
    {
      "x": -20,
      "y": 28,
      "z": -5,
      "name": "Rock_Chalk"
    },
    {
      "x": -20,
      "y": 29,
      "z": -5,
      "name": "Rock_Chalk"
    },
    {
      "x": -20,
      "y": 30,
      "z": -5,
      "name": "Rock_Chalk"
    },
    {
      "x": -20,
      "y": 31,
      "z": -5,
      "name": "Rock_Chalk"
    },
    {
      "x": -20,
      "y": 32,
      "z": -5,
      "name": "Rock_Chalk"
    },
    {
      "x": -20,
      "y": 33,
      "z": -5,
      "name": "Rock_Marble"
    },
    {
      "x": -20,
      "y": 34,
      "z": -5,
      "name": "Rock_Marble"
    },
    {
      "x": -20,
      "y": 35,
      "z": -5,
      "name": "Rock_Marble"
    },
    {
      "x": -20,
      "y": 36,
      "z": -5,
      "name": "Rock_Marble"
    },
    {
      "x": -20,
      "y": 37,
      "z": -5,
      "name": "Rock_Marble"
    },
    {
      "x": -20,
      "y": 38,
      "z": -5,
      "name": "Rock_Marble"
    },
    {
      "x": -20,
      "y": 39,
      "z": -5,
      "name": "Soil_Dirt"
    },
    {
      "x": -20,
      "y": 40,
      "z": -5,
      "name": "Soil_Dirt"
    },
    {
      "x": -20,
      "y": 41,
      "z": -5,
      "name": "Soil_Grass"
    },
    {
      "x": -20,
      "y": 2,
      "z": -4,
      "name": "Rock_Chalk"
    },
    {
      "x": -20,
      "y": 3,
      "z": -4,
      "name": "Rock_Chalk"
    },
    {
      "x": -20,
      "y": 4,
      "z": -4,
      "name": "Rock_Chalk"
    },
    {
      "x": -20,
      "y": 5,
      "z": -4,
      "name": "Rock_Chalk"
    },
    {
      "x": -20,
      "y": 6,
      "z": -4,
      "name": "Rock_Chalk"
    },
    {
      "x": -20,
      "y": 7,
      "z": -4,
      "name": "Rock_Chalk"
    },
    {
      "x": -20,
      "y": 8,
      "z": -4,
      "name": "Rock_Chalk"
    },
    {
      "x": -20,
      "y": 9,
      "z": -4,
      "name": "Rock_Chalk"
    },
    {
      "x": -20,
      "y": 10,
      "z": -4,
      "name": "Rock_Chalk"
    },
    {
      "x": -20,
      "y": 11,
      "z": -4,
      "name": "Rock_Chalk"
    },
    {
      "x": -20,
      "y": 12,
      "z": -4,
      "name": "Rock_Chalk"
    },
    {
      "x": -20,
      "y": 13,
      "z": -4,
      "name": "Rock_Chalk"
    },
    {
      "x": -20,
      "y": 14,
      "z": -4,
      "name": "Rock_Chalk"
    },
    {
      "x": -20,
      "y": 15,
      "z": -4,
      "name": "Rock_Chalk"
    },
    {
      "x": -20,
      "y": 16,
      "z": -4,
      "name": "Rock_Chalk"
    },
    {
      "x": -20,
      "y": 17,
      "z": -4,
      "name": "Rock_Chalk"
    },
    {
      "x": -20,
      "y": 18,
      "z": -4,
      "name": "Rock_Chalk"
    },
    {
      "x": -20,
      "y": 19,
      "z": -4,
      "name": "Rock_Chalk"
    },
    {
      "x": -20,
      "y": 20,
      "z": -4,
      "name": "Rock_Chalk"
    },
    {
      "x": -20,
      "y": 21,
      "z": -4,
      "name": "Rock_Chalk"
    },
    {
      "x": -20,
      "y": 22,
      "z": -4,
      "name": "Rock_Chalk"
    },
    {
      "x": -20,
      "y": 23,
      "z": -4,
      "name": "Rock_Chalk"
    },
    {
      "x": -20,
      "y": 24,
      "z": -4,
      "name": "Rock_Chalk"
    },
    {
      "x": -20,
      "y": 25,
      "z": -4,
      "name": "Rock_Marble"
    },
    {
      "x": -20,
      "y": 26,
      "z": -4,
      "name": "Rock_Marble"
    },
    {
      "x": -20,
      "y": 27,
      "z": -4,
      "name": "Rock_Marble"
    },
    {
      "x": -20,
      "y": 28,
      "z": -4,
      "name": "Rock_Marble"
    },
    {
      "x": -20,
      "y": 29,
      "z": -4,
      "name": "Rock_Marble"
    },
    {
      "x": -20,
      "y": 30,
      "z": -4,
      "name": "Rock_Marble"
    },
    {
      "x": -20,
      "y": 31,
      "z": -4,
      "name": "Rock_Marble"
    },
    {
      "x": -20,
      "y": 32,
      "z": -4,
      "name": "Rock_Marble"
    },
    {
      "x": -20,
      "y": 33,
      "z": -4,
      "name": "Rock_Marble"
    },
    {
      "x": -20,
      "y": 34,
      "z": -4,
      "name": "Rock_Marble"
    },
    {
      "x": -20,
      "y": 35,
      "z": -4,
      "name": "Rock_Marble"
    },
    {
      "x": -20,
      "y": 36,
      "z": -4,
      "name": "Rock_Marble"
    },
    {
      "x": -20,
      "y": 37,
      "z": -4,
      "name": "Rock_Marble"
    },
    {
      "x": -20,
      "y": 38,
      "z": -4,
      "name": "Rock_Marble"
    },
    {
      "x": -20,
      "y": 39,
      "z": -4,
      "name": "Soil_Dirt"
    },
    {
      "x": -20,
      "y": 40,
      "z": -4,
      "name": "Soil_Dirt"
    },
    {
      "x": -20,
      "y": 41,
      "z": -4,
      "name": "Soil_Grass"
    },
    {
      "x": -20,
      "y": 2,
      "z": -3,
      "name": "Rock_Marble"
    },
    {
      "x": -20,
      "y": 3,
      "z": -3,
      "name": "Rock_Marble"
    },
    {
      "x": -20,
      "y": 4,
      "z": -3,
      "name": "Rock_Marble"
    },
    {
      "x": -20,
      "y": 5,
      "z": -3,
      "name": "Rock_Marble"
    },
    {
      "x": -20,
      "y": 6,
      "z": -3,
      "name": "Rock_Marble"
    },
    {
      "x": -20,
      "y": 7,
      "z": -3,
      "name": "Rock_Marble"
    },
    {
      "x": -20,
      "y": 8,
      "z": -3,
      "name": "Rock_Marble"
    },
    {
      "x": -20,
      "y": 9,
      "z": -3,
      "name": "Rock_Marble"
    },
    {
      "x": -20,
      "y": 10,
      "z": -3,
      "name": "Rock_Marble"
    },
    {
      "x": -20,
      "y": 11,
      "z": -3,
      "name": "Rock_Marble"
    },
    {
      "x": -20,
      "y": 12,
      "z": -3,
      "name": "Rock_Marble"
    },
    {
      "x": -20,
      "y": 13,
      "z": -3,
      "name": "Rock_Marble"
    },
    {
      "x": -20,
      "y": 14,
      "z": -3,
      "name": "Rock_Marble"
    },
    {
      "x": -20,
      "y": 15,
      "z": -3,
      "name": "Rock_Marble"
    },
    {
      "x": -20,
      "y": 16,
      "z": -3,
      "name": "Rock_Marble"
    },
    {
      "x": -20,
      "y": 17,
      "z": -3,
      "name": "Rock_Marble"
    },
    {
      "x": -20,
      "y": 18,
      "z": -3,
      "name": "Rock_Marble"
    },
    {
      "x": -20,
      "y": 19,
      "z": -3,
      "name": "Rock_Marble"
    },
    {
      "x": -20,
      "y": 20,
      "z": -3,
      "name": "Rock_Marble"
    },
    {
      "x": -20,
      "y": 21,
      "z": -3,
      "name": "Rock_Marble"
    },
    {
      "x": -20,
      "y": 22,
      "z": -3,
      "name": "Rock_Marble"
    },
    {
      "x": -20,
      "y": 23,
      "z": -3,
      "name": "Rock_Marble"
    },
    {
      "x": -20,
      "y": 24,
      "z": -3,
      "name": "Rock_Marble"
    },
    {
      "x": -20,
      "y": 25,
      "z": -3,
      "name": "Rock_Marble"
    },
    {
      "x": -20,
      "y": 26,
      "z": -3,
      "name": "Rock_Marble"
    },
    {
      "x": -20,
      "y": 27,
      "z": -3,
      "name": "Rock_Marble"
    },
    {
      "x": -20,
      "y": 28,
      "z": -3,
      "name": "Rock_Marble"
    },
    {
      "x": -20,
      "y": 29,
      "z": -3,
      "name": "Rock_Marble"
    },
    {
      "x": -20,
      "y": 30,
      "z": -3,
      "name": "Rock_Marble"
    },
    {
      "x": -20,
      "y": 31,
      "z": -3,
      "name": "Rock_Marble"
    },
    {
      "x": -20,
      "y": 32,
      "z": -3,
      "name": "Rock_Marble"
    },
    {
      "x": -20,
      "y": 33,
      "z": -3,
      "name": "Rock_Marble"
    },
    {
      "x": -20,
      "y": 34,
      "z": -3,
      "name": "Rock_Marble"
    },
    {
      "x": -20,
      "y": 35,
      "z": -3,
      "name": "Rock_Marble"
    },
    {
      "x": -20,
      "y": 36,
      "z": -3,
      "name": "Rock_Marble"
    },
    {
      "x": -20,
      "y": 37,
      "z": -3,
      "name": "Rock_Marble"
    },
    {
      "x": -20,
      "y": 38,
      "z": -3,
      "name": "Rock_Marble"
    },
    {
      "x": -20,
      "y": 39,
      "z": -3,
      "name": "Rock_Marble"
    },
    {
      "x": -20,
      "y": 40,
      "z": -3,
      "name": "Soil_Dirt"
    },
    {
      "x": -20,
      "y": 41,
      "z": -3,
      "name": "Soil_Grass"
    },
    {
      "x": -20,
      "y": 2,
      "z": -2,
      "name": "Rock_Marble"
    },
    {
      "x": -20,
      "y": 3,
      "z": -2,
      "name": "Rock_Marble"
    },
    {
      "x": -20,
      "y": 4,
      "z": -2,
      "name": "Rock_Marble"
    },
    {
      "x": -20,
      "y": 5,
      "z": -2,
      "name": "Rock_Marble"
    },
    {
      "x": -20,
      "y": 6,
      "z": -2,
      "name": "Rock_Marble"
    },
    {
      "x": -20,
      "y": 7,
      "z": -2,
      "name": "Rock_Marble"
    },
    {
      "x": -20,
      "y": 8,
      "z": -2,
      "name": "Rock_Marble"
    },
    {
      "x": -20,
      "y": 9,
      "z": -2,
      "name": "Rock_Marble"
    },
    {
      "x": -20,
      "y": 10,
      "z": -2,
      "name": "Rock_Marble"
    },
    {
      "x": -20,
      "y": 11,
      "z": -2,
      "name": "Rock_Marble"
    },
    {
      "x": -20,
      "y": 12,
      "z": -2,
      "name": "Rock_Marble"
    },
    {
      "x": -20,
      "y": 13,
      "z": -2,
      "name": "Rock_Marble"
    },
    {
      "x": -20,
      "y": 14,
      "z": -2,
      "name": "Rock_Marble"
    },
    {
      "x": -20,
      "y": 15,
      "z": -2,
      "name": "Rock_Marble"
    },
    {
      "x": -20,
      "y": 16,
      "z": -2,
      "name": "Rock_Marble"
    },
    {
      "x": -20,
      "y": 17,
      "z": -2,
      "name": "Rock_Marble"
    },
    {
      "x": -20,
      "y": 18,
      "z": -2,
      "name": "Rock_Marble"
    },
    {
      "x": -20,
      "y": 19,
      "z": -2,
      "name": "Rock_Marble"
    },
    {
      "x": -20,
      "y": 20,
      "z": -2,
      "name": "Rock_Marble"
    },
    {
      "x": -20,
      "y": 21,
      "z": -2,
      "name": "Rock_Marble"
    },
    {
      "x": -20,
      "y": 22,
      "z": -2,
      "name": "Rock_Marble"
    },
    {
      "x": -20,
      "y": 23,
      "z": -2,
      "name": "Rock_Marble"
    },
    {
      "x": -20,
      "y": 24,
      "z": -2,
      "name": "Rock_Marble"
    },
    {
      "x": -20,
      "y": 25,
      "z": -2,
      "name": "Rock_Marble"
    },
    {
      "x": -20,
      "y": 26,
      "z": -2,
      "name": "Rock_Marble"
    },
    {
      "x": -20,
      "y": 27,
      "z": -2,
      "name": "Rock_Marble"
    },
    {
      "x": -20,
      "y": 28,
      "z": -2,
      "name": "Rock_Marble"
    },
    {
      "x": -20,
      "y": 29,
      "z": -2,
      "name": "Rock_Marble"
    },
    {
      "x": -20,
      "y": 30,
      "z": -2,
      "name": "Rock_Marble"
    },
    {
      "x": -20,
      "y": 31,
      "z": -2,
      "name": "Rock_Marble"
    },
    {
      "x": -20,
      "y": 32,
      "z": -2,
      "name": "Rock_Marble"
    },
    {
      "x": -20,
      "y": 33,
      "z": -2,
      "name": "Rock_Marble"
    },
    {
      "x": -20,
      "y": 34,
      "z": -2,
      "name": "Rock_Marble"
    },
    {
      "x": -20,
      "y": 35,
      "z": -2,
      "name": "Rock_Marble"
    },
    {
      "x": -20,
      "y": 36,
      "z": -2,
      "name": "Rock_Marble"
    },
    {
      "x": -20,
      "y": 37,
      "z": -2,
      "name": "Rock_Marble"
    },
    {
      "x": -20,
      "y": 38,
      "z": -2,
      "name": "Rock_Marble"
    },
    {
      "x": -20,
      "y": 39,
      "z": -2,
      "name": "Rock_Marble"
    },
    {
      "x": -20,
      "y": 40,
      "z": -2,
      "name": "Soil_Dirt"
    },
    {
      "x": -20,
      "y": 41,
      "z": -2,
      "name": "Soil_Dirt"
    },
    {
      "x": -20,
      "y": 42,
      "z": -2,
      "name": "Soil_Grass"
    },
    {
      "x": -20,
      "y": 2,
      "z": -1,
      "name": "Rock_Marble"
    },
    {
      "x": -20,
      "y": 3,
      "z": -1,
      "name": "Rock_Marble"
    },
    {
      "x": -20,
      "y": 4,
      "z": -1,
      "name": "Rock_Marble"
    },
    {
      "x": -20,
      "y": 5,
      "z": -1,
      "name": "Rock_Marble"
    },
    {
      "x": -20,
      "y": 6,
      "z": -1,
      "name": "Rock_Marble"
    },
    {
      "x": -20,
      "y": 7,
      "z": -1,
      "name": "Rock_Marble"
    },
    {
      "x": -20,
      "y": 8,
      "z": -1,
      "name": "Rock_Marble"
    },
    {
      "x": -20,
      "y": 9,
      "z": -1,
      "name": "Rock_Marble"
    },
    {
      "x": -20,
      "y": 10,
      "z": -1,
      "name": "Rock_Marble"
    },
    {
      "x": -20,
      "y": 11,
      "z": -1,
      "name": "Rock_Marble"
    },
    {
      "x": -20,
      "y": 12,
      "z": -1,
      "name": "Rock_Marble"
    },
    {
      "x": -20,
      "y": 13,
      "z": -1,
      "name": "Rock_Marble"
    },
    {
      "x": -20,
      "y": 14,
      "z": -1,
      "name": "Rock_Marble"
    },
    {
      "x": -20,
      "y": 15,
      "z": -1,
      "name": "Rock_Marble"
    },
    {
      "x": -20,
      "y": 16,
      "z": -1,
      "name": "Rock_Marble"
    },
    {
      "x": -20,
      "y": 17,
      "z": -1,
      "name": "Rock_Marble"
    },
    {
      "x": -20,
      "y": 18,
      "z": -1,
      "name": "Rock_Marble"
    },
    {
      "x": -20,
      "y": 19,
      "z": -1,
      "name": "Rock_Marble"
    },
    {
      "x": -20,
      "y": 20,
      "z": -1,
      "name": "Rock_Marble"
    },
    {
      "x": -20,
      "y": 21,
      "z": -1,
      "name": "Rock_Marble"
    },
    {
      "x": -20,
      "y": 22,
      "z": -1,
      "name": "Rock_Marble"
    },
    {
      "x": -20,
      "y": 23,
      "z": -1,
      "name": "Rock_Marble"
    },
    {
      "x": -20,
      "y": 24,
      "z": -1,
      "name": "Rock_Marble"
    },
    {
      "x": -20,
      "y": 25,
      "z": -1,
      "name": "Rock_Marble"
    },
    {
      "x": -20,
      "y": 26,
      "z": -1,
      "name": "Rock_Marble"
    },
    {
      "x": -20,
      "y": 27,
      "z": -1,
      "name": "Rock_Marble"
    },
    {
      "x": -20,
      "y": 28,
      "z": -1,
      "name": "Rock_Marble"
    },
    {
      "x": -20,
      "y": 29,
      "z": -1,
      "name": "Rock_Marble"
    },
    {
      "x": -20,
      "y": 30,
      "z": -1,
      "name": "Rock_Marble"
    },
    {
      "x": -20,
      "y": 31,
      "z": -1,
      "name": "Rock_Marble"
    },
    {
      "x": -20,
      "y": 32,
      "z": -1,
      "name": "Rock_Marble"
    },
    {
      "x": -20,
      "y": 33,
      "z": -1,
      "name": "Rock_Marble"
    },
    {
      "x": -20,
      "y": 34,
      "z": -1,
      "name": "Rock_Marble"
    },
    {
      "x": -20,
      "y": 35,
      "z": -1,
      "name": "Rock_Marble"
    },
    {
      "x": -20,
      "y": 36,
      "z": -1,
      "name": "Rock_Marble"
    },
    {
      "x": -20,
      "y": 37,
      "z": -1,
      "name": "Rock_Marble"
    },
    {
      "x": -20,
      "y": 38,
      "z": -1,
      "name": "Rock_Marble"
    },
    {
      "x": -20,
      "y": 39,
      "z": -1,
      "name": "Rock_Marble"
    },
    {
      "x": -20,
      "y": 40,
      "z": -1,
      "name": "Rock_Marble"
    },
    {
      "x": -20,
      "y": 41,
      "z": -1,
      "name": "Soil_Dirt"
    },
    {
      "x": -20,
      "y": 42,
      "z": -1,
      "name": "Soil_Grass"
    },
    {
      "x": -20,
      "y": 2,
      "z": 0,
      "name": "Rock_Marble"
    },
    {
      "x": -20,
      "y": 3,
      "z": 0,
      "name": "Rock_Marble"
    },
    {
      "x": -20,
      "y": 4,
      "z": 0,
      "name": "Rock_Marble"
    },
    {
      "x": -20,
      "y": 5,
      "z": 0,
      "name": "Rock_Marble"
    },
    {
      "x": -20,
      "y": 6,
      "z": 0,
      "name": "Rock_Marble"
    },
    {
      "x": -20,
      "y": 7,
      "z": 0,
      "name": "Rock_Marble"
    },
    {
      "x": -20,
      "y": 8,
      "z": 0,
      "name": "Rock_Marble"
    },
    {
      "x": -20,
      "y": 9,
      "z": 0,
      "name": "Rock_Marble"
    },
    {
      "x": -20,
      "y": 10,
      "z": 0,
      "name": "Rock_Marble"
    },
    {
      "x": -20,
      "y": 11,
      "z": 0,
      "name": "Rock_Marble"
    },
    {
      "x": -20,
      "y": 12,
      "z": 0,
      "name": "Rock_Marble"
    },
    {
      "x": -20,
      "y": 13,
      "z": 0,
      "name": "Rock_Marble"
    },
    {
      "x": -20,
      "y": 14,
      "z": 0,
      "name": "Rock_Marble"
    },
    {
      "x": -20,
      "y": 15,
      "z": 0,
      "name": "Rock_Marble"
    },
    {
      "x": -20,
      "y": 16,
      "z": 0,
      "name": "Rock_Marble"
    },
    {
      "x": -20,
      "y": 17,
      "z": 0,
      "name": "Rock_Marble"
    },
    {
      "x": -20,
      "y": 18,
      "z": 0,
      "name": "Rock_Marble"
    },
    {
      "x": -20,
      "y": 19,
      "z": 0,
      "name": "Rock_Marble"
    },
    {
      "x": -20,
      "y": 20,
      "z": 0,
      "name": "Rock_Marble"
    },
    {
      "x": -20,
      "y": 21,
      "z": 0,
      "name": "Rock_Marble"
    },
    {
      "x": -20,
      "y": 22,
      "z": 0,
      "name": "Rock_Marble"
    },
    {
      "x": -20,
      "y": 23,
      "z": 0,
      "name": "Rock_Marble"
    },
    {
      "x": -20,
      "y": 24,
      "z": 0,
      "name": "Rock_Marble"
    },
    {
      "x": -20,
      "y": 25,
      "z": 0,
      "name": "Rock_Marble"
    },
    {
      "x": -20,
      "y": 26,
      "z": 0,
      "name": "Rock_Marble"
    },
    {
      "x": -20,
      "y": 27,
      "z": 0,
      "name": "Rock_Marble"
    },
    {
      "x": -20,
      "y": 28,
      "z": 0,
      "name": "Rock_Marble"
    },
    {
      "x": -20,
      "y": 29,
      "z": 0,
      "name": "Rock_Marble"
    },
    {
      "x": -20,
      "y": 30,
      "z": 0,
      "name": "Rock_Marble"
    },
    {
      "x": -20,
      "y": 31,
      "z": 0,
      "name": "Rock_Marble"
    },
    {
      "x": -20,
      "y": 32,
      "z": 0,
      "name": "Rock_Marble"
    },
    {
      "x": -20,
      "y": 33,
      "z": 0,
      "name": "Rock_Marble"
    },
    {
      "x": -20,
      "y": 34,
      "z": 0,
      "name": "Rock_Marble"
    },
    {
      "x": -20,
      "y": 35,
      "z": 0,
      "name": "Rock_Marble"
    },
    {
      "x": -20,
      "y": 36,
      "z": 0,
      "name": "Rock_Marble"
    },
    {
      "x": -20,
      "y": 37,
      "z": 0,
      "name": "Rock_Marble"
    },
    {
      "x": -20,
      "y": 38,
      "z": 0,
      "name": "Rock_Marble"
    },
    {
      "x": -20,
      "y": 39,
      "z": 0,
      "name": "Rock_Marble"
    },
    {
      "x": -20,
      "y": 40,
      "z": 0,
      "name": "Rock_Marble"
    },
    {
      "x": -20,
      "y": 41,
      "z": 0,
      "name": "Rock_Marble"
    },
    {
      "x": -20,
      "y": 42,
      "z": 0,
      "name": "Soil_Grass"
    },
    {
      "x": -20,
      "y": 2,
      "z": 1,
      "name": "Rock_Marble"
    },
    {
      "x": -20,
      "y": 3,
      "z": 1,
      "name": "Rock_Marble"
    },
    {
      "x": -20,
      "y": 4,
      "z": 1,
      "name": "Rock_Marble"
    },
    {
      "x": -20,
      "y": 5,
      "z": 1,
      "name": "Rock_Marble"
    },
    {
      "x": -20,
      "y": 6,
      "z": 1,
      "name": "Rock_Marble"
    },
    {
      "x": -20,
      "y": 7,
      "z": 1,
      "name": "Rock_Marble"
    },
    {
      "x": -20,
      "y": 8,
      "z": 1,
      "name": "Rock_Marble"
    },
    {
      "x": -20,
      "y": 9,
      "z": 1,
      "name": "Rock_Marble"
    },
    {
      "x": -20,
      "y": 10,
      "z": 1,
      "name": "Rock_Marble"
    },
    {
      "x": -20,
      "y": 11,
      "z": 1,
      "name": "Rock_Marble"
    },
    {
      "x": -20,
      "y": 12,
      "z": 1,
      "name": "Rock_Marble"
    },
    {
      "x": -20,
      "y": 13,
      "z": 1,
      "name": "Rock_Marble"
    },
    {
      "x": -20,
      "y": 14,
      "z": 1,
      "name": "Rock_Marble"
    },
    {
      "x": -20,
      "y": 15,
      "z": 1,
      "name": "Rock_Marble"
    },
    {
      "x": -20,
      "y": 16,
      "z": 1,
      "name": "Rock_Marble"
    },
    {
      "x": -20,
      "y": 17,
      "z": 1,
      "name": "Rock_Marble"
    },
    {
      "x": -20,
      "y": 18,
      "z": 1,
      "name": "Rock_Marble"
    },
    {
      "x": -20,
      "y": 19,
      "z": 1,
      "name": "Rock_Marble"
    },
    {
      "x": -20,
      "y": 20,
      "z": 1,
      "name": "Rock_Marble"
    },
    {
      "x": -20,
      "y": 21,
      "z": 1,
      "name": "Rock_Marble"
    },
    {
      "x": -20,
      "y": 22,
      "z": 1,
      "name": "Rock_Marble"
    },
    {
      "x": -20,
      "y": 23,
      "z": 1,
      "name": "Rock_Marble"
    },
    {
      "x": -20,
      "y": 24,
      "z": 1,
      "name": "Rock_Marble"
    },
    {
      "x": -20,
      "y": 25,
      "z": 1,
      "name": "Rock_Marble"
    },
    {
      "x": -20,
      "y": 26,
      "z": 1,
      "name": "Rock_Marble"
    },
    {
      "x": -20,
      "y": 27,
      "z": 1,
      "name": "Rock_Marble"
    },
    {
      "x": -20,
      "y": 28,
      "z": 1,
      "name": "Rock_Marble"
    },
    {
      "x": -20,
      "y": 29,
      "z": 1,
      "name": "Rock_Marble"
    },
    {
      "x": -20,
      "y": 30,
      "z": 1,
      "name": "Rock_Marble"
    },
    {
      "x": -20,
      "y": 31,
      "z": 1,
      "name": "Rock_Marble"
    },
    {
      "x": -20,
      "y": 32,
      "z": 1,
      "name": "Rock_Marble"
    },
    {
      "x": -20,
      "y": 33,
      "z": 1,
      "name": "Rock_Marble"
    },
    {
      "x": -20,
      "y": 34,
      "z": 1,
      "name": "Rock_Marble"
    },
    {
      "x": -20,
      "y": 35,
      "z": 1,
      "name": "Rock_Marble"
    },
    {
      "x": -20,
      "y": 36,
      "z": 1,
      "name": "Rock_Marble"
    },
    {
      "x": -20,
      "y": 37,
      "z": 1,
      "name": "Rock_Marble"
    },
    {
      "x": -20,
      "y": 38,
      "z": 1,
      "name": "Rock_Marble"
    },
    {
      "x": -20,
      "y": 39,
      "z": 1,
      "name": "Rock_Marble"
    },
    {
      "x": -20,
      "y": 40,
      "z": 1,
      "name": "Rock_Marble"
    },
    {
      "x": -20,
      "y": 41,
      "z": 1,
      "name": "Rock_Marble"
    },
    {
      "x": -20,
      "y": 42,
      "z": 1,
      "name": "Rock_Marble"
    },
    {
      "x": -20,
      "y": 3,
      "z": 2,
      "name": "Rock_Marble"
    },
    {
      "x": -20,
      "y": 4,
      "z": 2,
      "name": "Rock_Marble"
    },
    {
      "x": -20,
      "y": 5,
      "z": 2,
      "name": "Rock_Marble"
    },
    {
      "x": -20,
      "y": 6,
      "z": 2,
      "name": "Rock_Marble"
    },
    {
      "x": -20,
      "y": 7,
      "z": 2,
      "name": "Rock_Marble"
    },
    {
      "x": -20,
      "y": 8,
      "z": 2,
      "name": "Rock_Marble"
    },
    {
      "x": -20,
      "y": 9,
      "z": 2,
      "name": "Rock_Marble"
    },
    {
      "x": -20,
      "y": 10,
      "z": 2,
      "name": "Rock_Marble"
    },
    {
      "x": -20,
      "y": 11,
      "z": 2,
      "name": "Rock_Marble"
    },
    {
      "x": -20,
      "y": 12,
      "z": 2,
      "name": "Rock_Marble"
    },
    {
      "x": -20,
      "y": 13,
      "z": 2,
      "name": "Rock_Marble"
    },
    {
      "x": -20,
      "y": 14,
      "z": 2,
      "name": "Rock_Marble"
    },
    {
      "x": -20,
      "y": 15,
      "z": 2,
      "name": "Rock_Marble"
    },
    {
      "x": -20,
      "y": 16,
      "z": 2,
      "name": "Rock_Marble"
    },
    {
      "x": -20,
      "y": 17,
      "z": 2,
      "name": "Rock_Marble"
    },
    {
      "x": -20,
      "y": 18,
      "z": 2,
      "name": "Rock_Marble"
    },
    {
      "x": -20,
      "y": 19,
      "z": 2,
      "name": "Rock_Marble"
    },
    {
      "x": -20,
      "y": 20,
      "z": 2,
      "name": "Rock_Marble"
    },
    {
      "x": -20,
      "y": 21,
      "z": 2,
      "name": "Rock_Marble"
    },
    {
      "x": -20,
      "y": 22,
      "z": 2,
      "name": "Rock_Marble"
    },
    {
      "x": -20,
      "y": 23,
      "z": 2,
      "name": "Rock_Marble"
    },
    {
      "x": -20,
      "y": 24,
      "z": 2,
      "name": "Rock_Marble"
    },
    {
      "x": -20,
      "y": 29,
      "z": 2,
      "name": "Rock_Marble"
    },
    {
      "x": -20,
      "y": 30,
      "z": 2,
      "name": "Rock_Marble"
    },
    {
      "x": -20,
      "y": 31,
      "z": 2,
      "name": "Rock_Marble"
    },
    {
      "x": -20,
      "y": 32,
      "z": 2,
      "name": "Rock_Marble"
    },
    {
      "x": -20,
      "y": 33,
      "z": 2,
      "name": "Rock_Marble"
    },
    {
      "x": -20,
      "y": 34,
      "z": 2,
      "name": "Rock_Marble"
    },
    {
      "x": -20,
      "y": 35,
      "z": 2,
      "name": "Rock_Marble"
    },
    {
      "x": -20,
      "y": 36,
      "z": 2,
      "name": "Rock_Marble"
    },
    {
      "x": -20,
      "y": 37,
      "z": 2,
      "name": "Rock_Marble"
    },
    {
      "x": -20,
      "y": 38,
      "z": 2,
      "name": "Rock_Marble"
    },
    {
      "x": -20,
      "y": 39,
      "z": 2,
      "name": "Rock_Marble"
    },
    {
      "x": -20,
      "y": 40,
      "z": 2,
      "name": "Rock_Marble"
    },
    {
      "x": -20,
      "y": 4,
      "z": 3,
      "name": "Rock_Marble"
    },
    {
      "x": -20,
      "y": 5,
      "z": 3,
      "name": "Rock_Marble"
    },
    {
      "x": -20,
      "y": 6,
      "z": 3,
      "name": "Rock_Marble"
    },
    {
      "x": -20,
      "y": 7,
