{
  "version": 8,
  "blockIdVersion": 8,
  "anchorX": -4,
  "anchorY": 6,
  "anchorZ": 1,
  "blocks": [
    {
      "x": -35,
      "y": 2,
      "z": 5,
      "name": "Plant_Coral_Block_Purple"
    },
    {
      "x": -35,
      "y": 3,
      "z": 5,
      "name": "Plant_Coral_Block_Purple"
    },
    {
      "x": -35,
      "y": 4,
      "z": 5,
      "name": "Plant_Coral_Block_Purple"
    },
    {
      "x": -35,
      "y": 3,
      "z": 6,
      "name": "Plant_Coral_Block_Purple"
    },
    {
      "x": -35,
      "y": 4,
      "z": 6,
      "name": "Plant_Coral_Block_Purple"
    },
    {
      "x": -34,
      "y": 3,
      "z": 4,
      "name": "Plant_Coral_Block_Purple"
    },
    {
      "x": -34,
      "y": 4,
      "z": 4,
      "name": "Plant_Coral_Block_Purple"
    },
    {
      "x": -34,
      "y": 1,
      "z": 5,
      "name": "Plant_Coral_Block_Purple"
    },
    {
      "x": -34,
      "y": 2,
      "z": 5,
      "name": "Plant_Coral_Block_Purple"
    },
    {
      "x": -34,
      "y": 3,
      "z": 5,
      "name": "Plant_Coral_Block_Purple"
    },
    {
      "x": -34,
      "y": 4,
      "z": 5,
      "name": "Plant_Coral_Block_Purple"
    },
    {
      "x": -34,
      "y": 5,
      "z": 5,
      "name": "Plant_Coral_Block_Purple"
    },
    {
      "x": -34,
      "y": 6,
      "z": 5,
      "name": "Plant_Coral_Model_Violet"
    },
    {
      "x": -34,
      "y": 2,
      "z": 6,
      "name": "Plant_Coral_Block_Purple"
    },
    {
      "x": -34,
      "y": 3,
      "z": 6,
      "name": "Plant_Coral_Block_Purple"
    },
    {
      "x": -34,
      "y": 4,
      "z": 6,
      "name": "Plant_Coral_Block_Purple"
    },
    {
      "x": -34,
      "y": 5,
      "z": 6,
      "name": "Plant_Coral_Block_Purple"
    },
    {
      "x": -33,
      "y": 2,
      "z": -6,
      "name": "Soil_Gravel_Sand_White"
    },
    {
      "x": -33,
      "y": 2,
      "z": -5,
      "name": "Soil_Gravel_Sand_White"
    },
    {
      "x": -33,
      "y": 2,
      "z": -4,
      "name": "Soil_Gravel_Sand_White"
    },
    {
      "x": -33,
      "y": 2,
      "z": -3,
      "name": "Rock_Sandstone_Brick"
    },
    {
      "x": -33,
      "y": 3,
      "z": -3,
      "name": "Soil_Gravel_Sand_White"
    },
    {
      "x": -33,
      "y": 2,
      "z": -2,
      "name": "Rock_Sandstone_Brick"
    },
    {
      "x": -33,
      "y": 3,
      "z": -2,
      "name": "Soil_Gravel_Sand_White"
    },
    {
      "x": -33,
      "y": 2,
      "z": -1,
      "name": "Rock_Sandstone_Brick"
    },
    {
      "x": -33,
      "y": 3,
      "z": -1,
      "name": "Soil_Gravel_Sand_White"
    },
    {
      "x": -33,
      "y": 2,
      "z": 0,
      "name": "Rock_Sandstone_Brick"
    },
    {
      "x": -33,
      "y": 3,
      "z": 0,
      "name": "Rock_Sandstone_Brick"
    },
    {
      "x": -33,
      "y": 4,
      "z": 0,
      "name": "Rock_Sandstone_Red_Cobble"
    },
    {
      "x": -33,
      "y": 2,
      "z": 1,
      "name": "Rock_Sandstone_Brick"
    },
    {
      "x": -33,
      "y": 3,
      "z": 1,
      "name": "Rock_Sandstone_Brick"
    },
    {
      "x": -33,
      "y": 4,
      "z": 1,
      "name": "Rock_Sandstone_Red_Cobble"
    },
    {
      "x": -33,
      "y": 2,
      "z": 2,
      "name": "Rock_Sandstone_Brick"
    },
    {
      "x": -33,
      "y": 3,
      "z": 2,
      "name": "Rock_Sandstone_Brick"
    },
    {
      "x": -33,
      "y": 4,
      "z": 2,
      "name": "Rock_Sandstone_Red_Cobble"
    },
    {
      "x": -33,
      "y": 2,
      "z": 3,
      "name": "Rock_Sandstone_Brick"
    },
    {
      "x": -33,
      "y": 3,
      "z": 3,
      "name": "Rock_Sandstone_Brick"
    },
    {
      "x": -33,
      "y": 4,
      "z": 3,
      "name": "Rock_Sandstone_Red_Cobble"
    },
    {
      "x": -33,
      "y": 2,
      "z": 4,
      "name": "Rock_Sandstone_Brick"
    },
    {
      "x": -33,
      "y": 3,
      "z": 4,
      "name": "Rock_Sandstone_Brick"
    },
    {
      "x": -33,
      "y": 4,
      "z": 4,
      "name": "Rock_Sandstone_Red_Cobble"
    },
    {
      "x": -33,
      "y": 5,
      "z": 4,
      "name": "Plant_Coral_Block_Purple"
    },
    {
      "x": -33,
      "y": 2,
      "z": 5,
      "name": "Rock_Sandstone_Brick"
    },
    {
      "x": -33,
      "y": 3,
      "z": 5,
      "name": "Rock_Sandstone_Brick"
    },
    {
      "x": -33,
      "y": 4,
      "z": 5,
      "name": "Rock_Sandstone_Red_Cobble"
    },
    {
      "x": -33,
      "y": 5,
      "z": 5,
      "name": "Plant_Coral_Block_Purple"
    },
    {
      "x": -33,
      "y": 6,
      "z": 5,
      "name": "Plant_Coral_Block_Purple"
    },
    {
      "x": -33,
      "y": 7,
      "z": 5,
      "name": "Plant_Coral_Model_Violet"
    },
    {
      "x": -33,
      "y": 2,
      "z": 6,
      "name": "Rock_Sandstone_Brick"
    },
    {
      "x": -33,
      "y": 3,
      "z": 6,
      "name": "Rock_Sandstone_Brick"
    },
    {
      "x": -33,
      "y": 4,
      "z": 6,
      "name": "Rock_Sandstone_Red_Cobble"
    },
    {
      "x": -33,
      "y": 5,
      "z": 6,
      "name": "Plant_Coral_Block_Purple"
    },
    {
      "x": -33,
      "y": 6,
      "z": 6,
      "name": "Plant_Coral_Model_Violet"
    },
    {
      "x": -33,
      "y": 2,
      "z": 7,
      "name": "Rock_Sandstone_Brick"
    },
    {
      "x": -33,
      "y": 3,
      "z": 7,
      "name": "Rock_Sandstone_Brick"
    },
    {
      "x": -33,
      "y": 4,
      "z": 7,
      "name": "Rock_Sandstone_Red_Cobble"
    },
    {
      "x": -32,
      "y": 2,
      "z": -8,
      "name": "Rock_Sandstone_Brick"
    },
    {
      "x": -32,
      "y": 3,
      "z": -8,
      "name": "Soil_Gravel_Sand_White"
    },
    {
      "x": -32,
      "y": 2,
      "z": -7,
      "name": "Rock_Sandstone_Brick"
    },
    {
      "x": -32,
      "y": 3,
      "z": -7,
      "name": "Soil_Gravel_Sand_White"
    },
    {
      "x": -32,
      "y": 2,
      "z": -6,
      "name": "Rock_Sandstone_Brick"
    },
    {
      "x": -32,
      "y": 3,
      "z": -6,
      "name": "Soil_Gravel_Sand_White"
    },
    {
      "x": -32,
      "y": 2,
      "z": -5,
      "name": "Rock_Stone"
    },
    {
      "x": -32,
      "y": 3,
      "z": -5,
      "name": "Soil_Gravel_Sand_White"
    },
    {
      "x": -32,
      "y": 2,
      "z": -4,
      "name": "Rock_Stone"
    },
    {
      "x": -32,
      "y": 3,
      "z": -4,
      "name": "Soil_Gravel_Sand_White"
    },
    {
      "x": -32,
      "y": 2,
      "z": -3,
      "name": "Rock_Stone"
    },
    {
      "x": -32,
      "y": 3,
      "z": -3,
      "name": "Rock_Stone"
    },
    {
      "x": -32,
      "y": 4,
      "z": -3,
      "name": "Soil_Gravel_Sand_White"
    },
    {
      "x": -32,
      "y": 2,
      "z": -2,
      "name": "Rock_Stone"
    },
    {
      "x": -32,
      "y": 3,
      "z": -2,
      "name": "Rock_Stone"
    },
    {
      "x": -32,
      "y": 4,
      "z": -2,
      "name": "Soil_Gravel_Sand_White"
    },
    {
      "x": -32,
      "y": 2,
      "z": -1,
      "name": "Rock_Stone"
    },
    {
      "x": -32,
      "y": 3,
      "z": -1,
      "name": "Rock_Stone"
    },
    {
      "x": -32,
      "y": 4,
      "z": -1,
      "name": "Soil_Gravel_Sand_White"
    },
    {
      "x": -32,
      "y": 2,
      "z": 0,
      "name": "Rock_Stone"
    },
    {
      "x": -32,
      "y": 3,
      "z": 0,
      "name": "Rock_Stone"
    },
    {
      "x": -32,
      "y": 4,
      "z": 0,
      "name": "Soil_Gravel_Sand_White"
    },
    {
      "x": -32,
      "y": 2,
      "z": 1,
      "name": "Rock_Stone"
    },
    {
      "x": -32,
      "y": 3,
      "z": 1,
      "name": "Rock_Stone"
    },
    {
      "x": -32,
      "y": 4,
      "z": 1,
      "name": "Soil_Gravel_Sand_White"
    },
    {
      "x": -32,
      "y": 2,
      "z": 2,
      "name": "Rock_Stone"
    },
    {
      "x": -32,
      "y": 3,
      "z": 2,
      "name": "Rock_Stone"
    },
    {
      "x": -32,
      "y": 4,
      "z": 2,
      "name": "Soil_Gravel_Sand_White"
    },
    {
      "x": -32,
      "y": 11,
      "z": 2,
      "name": "Plant_Coral_Bush_Blue"
    },
    {
      "x": -32,
      "y": 2,
      "z": 3,
      "name": "Rock_Stone"
    },
    {
      "x": -32,
      "y": 3,
      "z": 3,
      "name": "Rock_Stone"
    },
    {
      "x": -32,
      "y": 4,
      "z": 3,
      "name": "Soil_Gravel_Sand_White"
    },
    {
      "x": -32,
      "y": 10,
      "z": 3,
      "name": "Plant_Coral_Bush_Blue"
    },
    {
      "x": -32,
      "y": 11,
      "z": 3,
      "name": "Plant_Coral_Bush_Blue"
    },
    {
      "x": -32,
      "y": 12,
      "z": 3,
      "name": "Plant_Coral_Bush_Blue"
    },
    {
      "x": -32,
      "y": 13,
      "z": 3,
      "name": "Plant_Coral_Bush_Blue"
    },
    {
      "x": -32,
      "y": 14,
      "z": 3,
      "name": "Plant_Coral_Bush_Blue"
    },
    {
      "x": -32,
      "y": 2,
      "z": 4,
      "name": "Rock_Stone"
    },
    {
      "x": -32,
      "y": 3,
      "z": 4,
      "name": "Rock_Stone"
    },
    {
      "x": -32,
      "y": 4,
      "z": 4,
      "name": "Rock_Stone"
    },
    {
      "x": -32,
      "y": 5,
      "z": 4,
      "name": "Plant_Coral_Block_Purple"
    },
    {
      "x": -32,
      "y": 6,
      "z": 4,
      "name": "Plant_Coral_Block_Purple"
    },
    {
      "x": -32,
      "y": 2,
      "z": 5,
      "name": "Rock_Stone"
    },
    {
      "x": -32,
      "y": 3,
      "z": 5,
      "name": "Rock_Stone"
    },
    {
      "x": -32,
      "y": 4,
      "z": 5,
      "name": "Rock_Stone"
    },
    {
      "x": -32,
      "y": 5,
      "z": 5,
      "name": "Plant_Coral_Block_Purple"
    },
    {
      "x": -32,
      "y": 6,
      "z": 5,
      "name": "Plant_Coral_Block_Purple"
    },
    {
      "x": -32,
      "y": 7,
      "z": 5,
      "name": "Plant_Coral_Model_Violet"
    },
    {
      "x": -32,
      "y": 2,
      "z": 6,
      "name": "Rock_Stone"
    },
    {
      "x": -32,
      "y": 3,
      "z": 6,
      "name": "Rock_Stone"
    },
    {
      "x": -32,
      "y": 4,
      "z": 6,
      "name": "Rock_Stone"
    },
    {
      "x": -32,
      "y": 5,
      "z": 6,
      "name": "Plant_Coral_Block_Purple"
    },
    {
      "x": -32,
      "y": 6,
      "z": 6,
      "name": "Plant_Coral_Block_Purple"
    },
    {
      "x": -32,
      "y": 7,
      "z": 6,
      "name": "Plant_Coral_Model_Violet"
    },
    {
      "x": -32,
      "y": 2,
      "z": 7,
      "name": "Rock_Stone"
    },
    {
      "x": -32,
      "y": 3,
      "z": 7,
      "name": "Rock_Stone"
    },
    {
      "x": -32,
      "y": 4,
      "z": 7,
      "name": "Soil_Gravel_Sand_White"
    },
    {
      "x": -32,
      "y": 2,
      "z": 8,
      "name": "Rock_Sandstone_Brick"
    },
    {
      "x": -32,
      "y": 3,
      "z": 8,
      "name": "Soil_Gravel_Sand_White"
    },
    {
      "x": -32,
      "y": 2,
      "z": 9,
      "name": "Rock_Sandstone_Brick"
    },
    {
      "x": -32,
      "y": 3,
      "z": 9,
      "name": "Soil_Gravel_Sand_White"
    },
    {
      "x": -32,
      "y": 2,
      "z": 10,
      "name": "Rock_Sandstone_Brick"
    },
    {
      "x": -32,
      "y": 3,
      "z": 10,
      "name": "Soil_Gravel_Sand_White"
    },
    {
      "x": -31,
      "y": 2,
      "z": -11,
      "name": "Rock_Sandstone_Brick"
    },
    {
      "x": -31,
      "y": 3,
      "z": -11,
      "name": "Rock_Sandstone_Brick"
    },
    {
      "x": -31,
      "y": 4,
      "z": -11,
      "name": "Rock_Sandstone_Red_Cobble"
    },
    {
      "x": -31,
      "y": 2,
      "z": -10,
      "name": "Rock_Sandstone_Brick"
    },
    {
      "x": -31,
      "y": 3,
      "z": -10,
      "name": "Rock_Sandstone_Brick"
    },
    {
      "x": -31,
      "y": 4,
      "z": -10,
      "name": "Rock_Sandstone_Red_Cobble"
    },
    {
      "x": -31,
      "y": 2,
      "z": -9,
      "name": "Rock_Sandstone_Brick"
    },
    {
      "x": -31,
      "y": 3,
      "z": -9,
      "name": "Soil_Gravel_Sand_White"
    },
    {
      "x": -31,
      "y": 2,
      "z": -8,
      "name": "Rock_Stone"
    },
    {
      "x": -31,
      "y": 3,
      "z": -8,
      "name": "Soil_Gravel_Sand_White"
    },
    {
      "x": -31,
      "y": 2,
      "z": -7,
      "name": "Rock_Stone"
    },
    {
      "x": -31,
      "y": 3,
      "z": -7,
      "name": "Soil_Gravel_Sand_White"
    },
    {
      "x": -31,
      "y": 2,
      "z": -6,
      "name": "Rock_Stone"
    },
    {
      "x": -31,
      "y": 3,
      "z": -6,
      "name": "Rock_Stone"
    },
    {
      "x": -31,
      "y": 4,
      "z": -6,
      "name": "Soil_Gravel_Sand_White"
    },
    {
      "x": -31,
      "y": 2,
      "z": -5,
      "name": "Rock_Stone"
    },
    {
      "x": -31,
      "y": 3,
      "z": -5,
      "name": "Rock_Stone"
    },
    {
      "x": -31,
      "y": 4,
      "z": -5,
      "name": "Soil_Gravel_Sand_White"
    },
    {
      "x": -31,
      "y": 2,
      "z": -4,
      "name": "Rock_Stone"
    },
    {
      "x": -31,
      "y": 3,
      "z": -4,
      "name": "Rock_Stone"
    },
    {
      "x": -31,
      "y": 4,
      "z": -4,
      "name": "Soil_Gravel_Sand_White"
    },
    {
      "x": -31,
      "y": 2,
      "z": -3,
      "name": "Rock_Stone"
    },
    {
      "x": -31,
      "y": 3,
      "z": -3,
      "name": "Rock_Stone"
    },
    {
      "x": -31,
      "y": 4,
      "z": -3,
      "name": "Soil_Gravel_Sand_White"
    },
    {
      "x": -31,
      "y": 2,
      "z": -2,
      "name": "Rock_Stone"
    },
    {
      "x": -31,
      "y": 3,
      "z": -2,
      "name": "Rock_Stone"
    },
    {
      "x": -31,
      "y": 4,
      "z": -2,
      "name": "Soil_Gravel_Sand_White"
    },
    {
      "x": -31,
      "y": 2,
      "z": -1,
      "name": "Rock_Stone"
    },
    {
      "x": -31,
      "y": 3,
      "z": -1,
      "name": "Rock_Stone"
    },
    {
      "x": -31,
      "y": 4,
      "z": -1,
      "name": "Soil_Gravel_Sand_White"
    },
    {
      "x": -31,
      "y": 2,
      "z": 0,
      "name": "Rock_Stone"
    },
    {
      "x": -31,
      "y": 3,
      "z": 0,
      "name": "Rock_Stone"
    },
    {
      "x": -31,
      "y": 4,
      "z": 0,
      "name": "Soil_Gravel_Sand_White"
    },
    {
      "x": -31,
      "y": 2,
      "z": 1,
      "name": "Rock_Stone"
    },
    {
      "x": -31,
      "y": 3,
      "z": 1,
      "name": "Rock_Stone"
    },
    {
      "x": -31,
      "y": 4,
      "z": 1,
      "name": "Soil_Gravel_Sand_White"
    },
    {
      "x": -31,
      "y": 2,
      "z": 2,
      "name": "Rock_Stone"
    },
    {
      "x": -31,
      "y": 3,
      "z": 2,
      "name": "Rock_Stone"
    },
    {
      "x": -31,
      "y": 4,
      "z": 2,
      "name": "Soil_Gravel_Sand_White"
    },
    {
      "x": -31,
      "y": 10,
      "z": 2,
      "name": "Plant_Coral_Bush_Blue"
    },
    {
      "x": -31,
      "y": 2,
      "z": 3,
      "name": "Rock_Stone"
    },
    {
      "x": -31,
      "y": 3,
      "z": 3,
      "name": "Rock_Stone"
    },
    {
      "x": -31,
      "y": 4,
      "z": 3,
      "name": "Soil_Gravel_Sand_White"
    },
    {
      "x": -31,
      "y": 9,
      "z": 3,
      "name": "Plant_Coral_Bush_Blue"
    },
    {
      "x": -31,
      "y": 10,
      "z": 3,
      "name": "Plant_Coral_Block_Purple"
    },
    {
      "x": -31,
      "y": 11,
      "z": 3,
      "name": "Plant_Coral_Block_Purple"
    },
    {
      "x": -31,
      "y": 12,
      "z": 3,
      "name": "Plant_Coral_Bush_Blue"
    },
    {
      "x": -31,
      "y": 2,
      "z": 4,
      "name": "Rock_Stone"
    },
    {
      "x": -31,
      "y": 3,
      "z": 4,
      "name": "Rock_Stone"
    },
    {
      "x": -31,
      "y": 4,
      "z": 4,
      "name": "Rock_Stone"
    },
    {
      "x": -31,
      "y": 5,
      "z": 4,
      "name": "Plant_Coral_Block_Purple"
    },
    {
      "x": -31,
      "y": 6,
      "z": 4,
      "name": "Plant_Coral_Block_Purple"
    },
    {
      "x": -31,
      "y": 9,
      "z": 4,
      "name": "Plant_Coral_Bush_Blue"
    },
    {
      "x": -31,
      "y": 10,
      "z": 4,
      "name": "Plant_Coral_Bush_Blue"
    },
    {
      "x": -31,
      "y": 11,
      "z": 4,
      "name": "Plant_Coral_Bush_Blue"
    },
    {
      "x": -31,
      "y": 2,
      "z": 5,
      "name": "Rock_Stone"
    },
    {
      "x": -31,
      "y": 3,
      "z": 5,
      "name": "Rock_Stone"
    },
    {
      "x": -31,
      "y": 4,
      "z": 5,
      "name": "Rock_Stone"
    },
    {
      "x": -31,
      "y": 5,
      "z": 5,
      "name": "Plant_Coral_Block_Purple"
    },
    {
      "x": -31,
      "y": 6,
      "z": 5,
      "name": "Plant_Coral_Block_Purple"
    },
    {
      "x": -31,
      "y": 7,
      "z": 5,
      "name": "Plant_Coral_Block_Purple"
    },
    {
      "x": -31,
      "y": 2,
      "z": 6,
      "name": "Rock_Stone"
    },
    {
      "x": -31,
      "y": 3,
      "z": 6,
      "name": "Rock_Stone"
    },
    {
      "x": -31,
      "y": 4,
      "z": 6,
      "name": "Rock_Stone"
    },
    {
      "x": -31,
      "y": 5,
      "z": 6,
      "name": "Plant_Coral_Block_Purple"
    },
    {
      "x": -31,
      "y": 6,
      "z": 6,
      "name": "Plant_Coral_Block_Purple"
    },
    {
      "x": -31,
      "y": 7,
      "z": 6,
      "name": "Plant_Coral_Block_Purple"
    },
    {
      "x": -31,
      "y": 2,
      "z": 7,
      "name": "Rock_Stone"
    },
    {
      "x": -31,
      "y": 3,
      "z": 7,
      "name": "Rock_Stone"
    },
    {
      "x": -31,
      "y": 4,
      "z": 7,
      "name": "Soil_Gravel_Sand_White"
    },
    {
      "x": -31,
      "y": 2,
      "z": 8,
      "name": "Rock_Stone"
    },
    {
      "x": -31,
      "y": 3,
      "z": 8,
      "name": "Rock_Stone"
    },
    {
      "x": -31,
      "y": 4,
      "z": 8,
      "name": "Soil_Gravel_Sand_White"
    },
    {
      "x": -31,
      "y": 2,
      "z": 9,
      "name": "Rock_Stone"
    },
    {
      "x": -31,
      "y": 3,
      "z": 9,
      "name": "Rock_Stone"
    },
    {
      "x": -31,
      "y": 4,
      "z": 9,
      "name": "Soil_Gravel_Sand_White"
    },
    {
      "x": -31,
      "y": 2,
      "z": 10,
      "name": "Rock_Stone"
    },
    {
      "x": -31,
      "y": 3,
      "z": 10,
      "name": "Soil_Gravel_Sand_White"
    },
    {
      "x": -31,
      "y": 2,
      "z": 11,
      "name": "Rock_Sandstone_Brick"
    },
    {
      "x": -31,
      "y": 3,
      "z": 11,
      "name": "Soil_Gravel_Sand_White"
    },
    {
      "x": -31,
      "y": 2,
      "z": 12,
      "name": "Rock_Sandstone_Brick"
    },
    {
      "x": -31,
      "y": 3,
      "z": 12,
      "name": "Rock_Sandstone_Brick"
    },
    {
      "x": -31,
      "y": 4,
      "z": 12,
      "name": "Rock_Sandstone_Red_Cobble"
    },
    {
      "x": -31,
      "y": 2,
      "z": 13,
      "name": "Rock_Sandstone_Brick"
    },
    {
      "x": -31,
      "y": 3,
      "z": 13,
      "name": "Rock_Sandstone_Brick"
    },
    {
      "x": -31,
      "y": 4,
      "z": 13,
      "name": "Rock_Sandstone_Red_Cobble"
    },
    {
      "x": -30,
      "y": 2,
      "z": -13,
      "name": "Rock_Sandstone_Brick"
    },
    {
      "x": -30,
      "y": 3,
      "z": -13,
      "name": "Rock_Sandstone_Brick"
    },
    {
      "x": -30,
      "y": 4,
      "z": -13,
      "name": "Rock_Sandstone_Red_Cobble"
    },
    {
      "x": -30,
      "y": 2,
      "z": -12,
      "name": "Rock_Sandstone_Brick"
    },
    {
      "x": -30,
      "y": 3,
      "z": -12,
      "name": "Rock_Sandstone_Brick"
    },
    {
      "x": -30,
      "y": 4,
      "z": -12,
      "name": "Rock_Sandstone_Red_Cobble"
    },
    {
      "x": -30,
      "y": 2,
      "z": -11,
      "name": "Rock_Stone"
    },
    {
      "x": -30,
      "y": 3,
      "z": -11,
      "name": "Rock_Stone"
    },
    {
      "x": -30,
      "y": 4,
      "z": -11,
      "name": "Soil_Gravel_Sand_White"
    },
    {
      "x": -30,
      "y": 2,
      "z": -10,
      "name": "Rock_Stone"
    },
    {
      "x": -30,
      "y": 3,
      "z": -10,
      "name": "Rock_Stone"
    },
    {
      "x": -30,
      "y": 4,
      "z": -10,
      "name": "Soil_Gravel_Sand_White"
    },
    {
      "x": -30,
      "y": 2,
      "z": -9,
      "name": "Rock_Stone"
    },
    {
      "x": -30,
      "y": 3,
      "z": -9,
      "name": "Rock_Stone"
    },
    {
      "x": -30,
      "y": 4,
      "z": -9,
      "name": "Soil_Gravel_Sand_White"
    },
    {
      "x": -30,
      "y": 2,
      "z": -8,
      "name": "Rock_Stone"
    },
    {
      "x": -30,
      "y": 3,
      "z": -8,
      "name": "Rock_Stone"
    },
    {
      "x": -30,
      "y": 4,
      "z": -8,
      "name": "Soil_Gravel_Sand_White"
    },
    {
      "x": -30,
      "y": 2,
      "z": -7,
      "name": "Rock_Stone"
    },
    {
      "x": -30,
      "y": 3,
      "z": -7,
      "name": "Rock_Stone"
    },
    {
      "x": -30,
      "y": 4,
      "z": -7,
      "name": "Soil_Gravel_Sand_White"
    },
    {
      "x": -30,
      "y": 2,
      "z": -6,
      "name": "Rock_Stone"
    },
    {
      "x": -30,
      "y": 3,
      "z": -6,
      "name": "Rock_Stone"
    },
    {
      "x": -30,
      "y": 4,
      "z": -6,
      "name": "Soil_Gravel_Sand_White"
    },
    {
      "x": -30,
      "y": 2,
      "z": -5,
      "name": "Rock_Stone"
    },
    {
      "x": -30,
      "y": 3,
      "z": -5,
      "name": "Rock_Stone"
    },
    {
      "x": -30,
      "y": 4,
      "z": -5,
      "name": "Soil_Gravel_Sand_White"
    },
    {
      "x": -30,
      "y": 2,
      "z": -4,
      "name": "Rock_Stone"
    },
    {
      "x": -30,
      "y": 3,
      "z": -4,
      "name": "Rock_Stone"
    },
    {
      "x": -30,
      "y": 4,
      "z": -4,
      "name": "Soil_Gravel_Sand_White"
    },
    {
      "x": -30,
      "y": 5,
      "z": -4,
      "name": "Soil_Gravel_Sand_White"
    },
    {
      "x": -30,
      "y": 2,
      "z": -3,
      "name": "Rock_Stone"
    },
    {
      "x": -30,
      "y": 3,
      "z": -3,
      "name": "Rock_Stone"
    },
    {
      "x": -30,
      "y": 4,
      "z": -3,
      "name": "Soil_Gravel_Sand_White"
    },
    {
      "x": -30,
      "y": 5,
      "z": -3,
      "name": "Soil_Gravel_Sand_White"
    },
    {
      "x": -30,
      "y": 2,
      "z": -2,
      "name": "Rock_Stone"
    },
    {
      "x": -30,
      "y": 3,
      "z": -2,
      "name": "Rock_Stone"
    },
    {
      "x": -30,
      "y": 4,
      "z": -2,
      "name": "Soil_Gravel_Sand_White"
    },
    {
      "x": -30,
      "y": 5,
      "z": -2,
      "name": "Soil_Gravel_Sand_White"
    },
    {
      "x": -30,
      "y": 2,
      "z": -1,
      "name": "Rock_Stone"
    },
    {
      "x": -30,
      "y": 3,
      "z": -1,
      "name": "Rock_Stone"
    },
    {
      "x": -30,
      "y": 4,
      "z": -1,
      "name": "Soil_Gravel_Sand_White"
    },
    {
      "x": -30,
      "y": 5,
      "z": -1,
      "name": "Soil_Gravel_Sand_White"
    },
    {
      "x": -30,
      "y": 2,
      "z": 0,
      "name": "Rock_Stone"
    },
    {
      "x": -30,
      "y": 3,
      "z": 0,
      "name": "Rock_Stone"
    },
    {
      "x": -30,
      "y": 4,
      "z": 0,
      "name": "Soil_Gravel_Sand_White"
    },
    {
      "x": -30,
      "y": 5,
      "z": 0,
      "name": "Soil_Gravel_Sand_White"
    },
    {
      "x": -30,
      "y": 2,
      "z": 1,
      "name": "Rock_Stone"
    },
    {
      "x": -30,
      "y": 3,
      "z": 1,
      "name": "Rock_Stone"
    },
    {
      "x": -30,
      "y": 4,
      "z": 1,
      "name": "Soil_Gravel_Sand_White"
    },
    {
      "x": -30,
      "y": 2,
      "z": 2,
      "name": "Rock_Stone"
    },
    {
      "x": -30,
      "y": 3,
      "z": 2,
      "name": "Rock_Stone"
    },
    {
      "x": -30,
      "y": 4,
      "z": 2,
      "name": "Rock_Stone"
    },
    {
      "x": -30,
      "y": 5,
      "z": 2,
      "name": "Plant_Coral_Block_Purple"
    },
    {
      "x": -30,
      "y": 6,
      "z": 2,
      "name": "Plant_Coral_Block_Purple"
    },
    {
      "x": -30,
      "y": 8,
      "z": 2,
      "name": "Plant_Coral_Bush_Blue"
    },
    {
      "x": -30,
      "y": 9,
      "z": 2,
      "name": "Plant_Coral_Bush_Blue"
    },
    {
      "x": -30,
      "y": 2,
      "z": 3,
      "name": "Rock_Stone"
    },
    {
      "x": -30,
      "y": 3,
      "z": 3,
      "name": "Rock_Stone"
    },
    {
      "x": -30,
      "y": 4,
      "z": 3,
      "name": "Rock_Stone"
    },
    {
      "x": -30,
      "y": 5,
      "z": 3,
      "name": "Plant_Coral_Block_Purple"
    },
    {
      "x": -30,
      "y": 6,
      "z": 3,
      "name": "Plant_Coral_Block_Purple"
    },
    {
      "x": -30,
      "y": 7,
      "z": 3,
      "name": "Plant_Coral_Block_Purple"
    },
    {
      "x": -30,
      "y": 8,
      "z": 3,
      "name": "Plant_Coral_Bush_Blue"
    },
    {
      "x": -30,
      "y": 9,
      "z": 3,
      "name": "Plant_Coral_Block_Purple"
    },
    {
      "x": -30,
      "y": 10,
      "z": 3,
      "name": "Plant_Coral_Block_Purple"
    },
    {
      "x": -30,
      "y": 2,
      "z": 4,
      "name": "Rock_Stone"
    },
    {
      "x": -30,
      "y": 3,
      "z": 4,
      "name": "Rock_Stone"
    },
    {
      "x": -30,
      "y": 4,
      "z": 4,
      "name": "Rock_Stone"
    },
    {
      "x": -30,
      "y": 5,
      "z": 4,
      "name": "Plant_Coral_Block_Purple"
    },
    {
      "x": -30,
      "y": 6,
      "z": 4,
      "name": "Plant_Coral_Block_Purple"
    },
    {
      "x": -30,
      "y": 7,
      "z": 4,
      "name": "Plant_Coral_Block_Purple"
    },
    {
      "x": -30,
      "y": 9,
      "z": 4,
      "name": "Plant_Coral_Bush_Blue"
    },
    {
      "x": -30,
      "y": 2,
      "z": 5,
      "name": "Rock_Stone"
    },
    {
      "x": -30,
      "y": 3,
      "z": 5,
      "name": "Rock_Stone"
    },
    {
      "x": -30,
      "y": 4,
      "z": 5,
      "name": "Rock_Stone"
    },
    {
      "x": -30,
      "y": 5,
      "z": 5,
      "name": "Plant_Coral_Block_Purple"
    },
    {
      "x": -30,
      "y": 6,
      "z": 5,
      "name": "Plant_Coral_Block_Purple"
    },
    {
      "x": -30,
      "y": 7,
      "z": 5,
      "name": "Plant_Coral_Block_Purple"
    },
    {
      "x": -30,
      "y": 2,
      "z": 6,
      "name": "Rock_Stone"
    },
    {
      "x": -30,
      "y": 3,
      "z": 6,
      "name": "Rock_Stone"
    },
    {
      "x": -30,
      "y": 4,
      "z": 6,
      "name": "Rock_Stone"
    },
    {
      "x": -30,
      "y": 5,
      "z": 6,
      "name": "Plant_Coral_Block_Purple"
    },
    {
      "x": -30,
      "y": 6,
      "z": 6,
      "name": "Plant_Coral_Block_Purple"
    },
    {
      "x": -30,
      "y": 7,
      "z": 6,
      "name": "Plant_Coral_Block_Purple"
    },
    {
      "x": -30,
      "y": 2,
      "z": 7,
      "name": "Rock_Stone"
    },
    {
      "x": -30,
      "y": 3,
      "z": 7,
      "name": "Rock_Stone"
    },
    {
      "x": -30,
      "y": 4,
      "z": 7,
      "name": "Soil_Gravel_Sand_White"
    },
    {
      "x": -30,
      "y": 2,
      "z": 8,
      "name": "Rock_Stone"
    },
    {
      "x": -30,
      "y": 3,
      "z": 8,
      "name": "Rock_Stone"
    },
    {
      "x": -30,
      "y": 4,
      "z": 8,
      "name": "Soil_Gravel_Sand_White"
    },
    {
      "x": -30,
      "y": 2,
      "z": 9,
      "name": "Rock_Stone"
    },
    {
      "x": -30,
      "y": 3,
      "z": 9,
      "name": "Rock_Stone"
    },
    {
      "x": -30,
      "y": 4,
      "z": 9,
      "name": "Soil_Gravel_Sand_White"
    },
    {
      "x": -30,
      "y": 2,
      "z": 10,
      "name": "Rock_Stone"
    },
    {
      "x": -30,
      "y": 3,
      "z": 10,
      "name": "Rock_Stone"
    },
    {
      "x": -30,
      "y": 4,
      "z": 10,
      "name": "Soil_Gravel_Sand_White"
    },
    {
      "x": -30,
      "y": 2,
      "z": 11,
      "name": "Rock_Stone"
    },
    {
      "x": -30,
      "y": 3,
      "z": 11,
      "name": "Rock_Stone"
    },
    {
      "x": -30,
      "y": 4,
      "z": 11,
      "name": "Soil_Gravel_Sand_White"
    },
    {
      "x": -30,
      "y": 2,
      "z": 12,
      "name": "Rock_Stone"
    },
    {
      "x": -30,
      "y": 3,
      "z": 12,
      "name": "Rock_Stone"
    },
    {
      "x": -30,
      "y": 4,
      "z": 12,
      "name": "Soil_Gravel_Sand_White"
    },
    {
      "x": -30,
      "y": 2,
      "z": 13,
      "name": "Rock_Stone"
    },
    {
      "x": -30,
      "y": 3,
      "z": 13,
      "name": "Rock_Stone"
    },
    {
      "x": -30,
      "y": 4,
      "z": 13,
      "name": "Soil_Gravel_Sand_White"
    },
    {
      "x": -30,
      "y": 2,
      "z": 14,
      "name": "Rock_Sandstone_Brick"
    },
    {
      "x": -30,
      "y": 3,
      "z": 14,
      "name": "Rock_Sandstone_Brick"
    },
    {
      "x": -30,
      "y": 4,
      "z": 14,
      "name": "Rock_Sandstone_Red_Cobble"
    },
    {
      "x": -30,
      "y": 2,
      "z": 15,
      "name": "Rock_Sandstone_Brick"
    },
    {
      "x": -30,
      "y": 3,
      "z": 15,
      "name": "Rock_Sandstone_Brick"
    },
    {
      "x": -30,
      "y": 4,
      "z": 15,
      "name": "Rock_Sandstone_Red_Cobble"
    },
    {
      "x": -29,
      "y": 0,
      "z": -20,
      "name": "Plant_Coral_Block_Purple"
    },
    {
      "x": -29,
      "y": 1,
      "z": -20,
      "name": "Plant_Coral_Block_Purple"
    },
    {
      "x": -29,
      "y": 1,
      "z": -19,
      "name": "Plant_Coral_Block_Purple"
    },
    {
      "x": -29,
      "y": 2,
      "z": -19,
      "name": "Plant_Coral_Block_Purple"
    },
    {
      "x": -29,
      "y": 2,
      "z": -15,
      "name": "Rock_Sandstone_Brick"
    },
    {
      "x": -29,
      "y": 3,
      "z": -15,
      "name": "Rock_Sandstone_Brick"
    },
    {
      "x": -29,
      "y": 4,
      "z": -15,
      "name": "Rock_Sandstone_Red_Cobble"
    },
    {
      "x": -29,
      "y": 2,
      "z": -14,
      "name": "Rock_Sandstone_Brick"
    },
    {
      "x": -29,
      "y": 3,
      "z": -14,
      "name": "Rock_Sandstone_Brick"
    },
    {
      "x": -29,
      "y": 4,
      "z": -14,
      "name": "Rock_Sandstone_Red_Cobble"
    },
    {
      "x": -29,
      "y": 2,
      "z": -13,
      "name": "Rock_Stone"
    },
    {
      "x": -29,
      "y": 3,
      "z": -13,
      "name": "Rock_Stone"
    },
    {
      "x": -29,
      "y": 4,
      "z": -13,
      "name": "Soil_Gravel_Sand_White"
    },
    {
      "x": -29,
      "y": 2,
      "z": -12,
      "name": "Rock_Stone"
    },
    {
      "x": -29,
      "y": 3,
      "z": -12,
      "name": "Rock_Stone"
    },
    {
      "x": -29,
      "y": 4,
      "z": -12,
      "name": "Soil_Gravel_Sand_White"
    },
    {
      "x": -29,
      "y": 2,
      "z": -11,
      "name": "Rock_Stone"
    },
    {
      "x": -29,
      "y": 3,
      "z": -11,
      "name": "Rock_Stone"
    },
    {
      "x": -29,
      "y": 4,
      "z": -11,
      "name": "Soil_Gravel_Sand_White"
    },
    {
      "x": -29,
      "y": 2,
      "z": -10,
      "name": "Rock_Stone"
    },
    {
      "x": -29,
      "y": 3,
      "z": -10,
      "name": "Rock_Stone"
    },
    {
      "x": -29,
      "y": 4,
      "z": -10,
      "name": "Soil_Gravel_Sand_White"
    },
    {
      "x": -29,
      "y": 2,
      "z": -9,
      "name": "Rock_Stone"
    },
    {
      "x": -29,
      "y": 3,
      "z": -9,
      "name": "Rock_Stone"
    },
    {
      "x": -29,
      "y": 4,
      "z": -9,
      "name": "Soil_Gravel_Sand_White"
    },
    {
      "x": -29,
      "y": 2,
      "z": -8,
      "name": "Rock_Stone"
    },
    {
      "x": -29,
      "y": 3,
      "z": -8,
      "name": "Rock_Stone"
    },
    {
      "x": -29,
      "y": 4,
      "z": -8,
      "name": "Soil_Gravel_Sand_White"
    },
    {
      "x": -29,
      "y": 5,
      "z": -8,
      "name": "Soil_Gravel_Sand_White"
    },
    {
      "x": -29,
      "y": 2,
      "z": -7,
      "name": "Rock_Stone"
    },
    {
      "x": -29,
      "y": 3,
      "z": -7,
      "name": "Rock_Stone"
    },
    {
      "x": -29,
      "y": 4,
      "z": -7,
      "name": "Soil_Gravel_Sand_White"
    },
    {
      "x": -29,
      "y": 5,
      "z": -7,
      "name": "Soil_Gravel_Sand_White"
    },
    {
      "x": -29,
      "y": 2,
      "z": -6,
      "name": "Rock_Stone"
    },
    {
      "x": -29,
      "y": 3,
      "z": -6,
      "name": "Rock_Stone"
    },
    {
      "x": -29,
      "y": 4,
      "z": -6,
      "name": "Soil_Gravel_Sand_White"
    },
    {
      "x": -29,
      "y": 5,
      "z": -6,
      "name": "Soil_Gravel_Sand_White"
    },
    {
      "x": -29,
      "y": 2,
      "z": -5,
      "name": "Rock_Stone"
    },
    {
      "x": -29,
      "y": 3,
      "z": -5,
      "name": "Rock_Stone"
    },
    {
      "x": -29,
      "y": 4,
      "z": -5,
      "name": "Soil_Gravel_Sand_White"
    },
    {
      "x": -29,
      "y": 5,
      "z": -5,
      "name": "Soil_Gravel_Sand_White"
    },
    {
      "x": -29,
      "y": 2,
      "z": -4,
      "name": "Rock_Sandstone_Brick"
    },
    {
      "x": -29,
      "y": 3,
      "z": -4,
      "name": "Rock_Sandstone_Brick"
    },
    {
      "x": -29,
      "y": 4,
      "z": -4,
      "name": "Rock_Sandstone_Red_Cobble"
    },
    {
      "x": -29,
      "y": 5,
      "z": -4,
      "name": "Soil_Gravel_Sand_White"
    },
    {
      "x": -29,
      "y": 2,
      "z": -3,
      "name": "Rock_Sandstone_Brick"
    },
    {
      "x": -29,
      "y": 3,
      "z": -3,
      "name": "Rock_Sandstone_Brick"
    },
    {
      "x": -29,
      "y": 4,
      "z": -3,
      "name": "Rock_Sandstone_Red_Cobble"
    },
    {
      "x": -29,
      "y": 5,
      "z": -3,
      "name": "Soil_Gravel_Sand_White"
    },
    {
      "x": -29,
      "y": 2,
      "z": -2,
      "name": "Rock_Sandstone_Brick"
    },
    {
      "x": -29,
      "y": 3,
      "z": -2,
      "name": "Rock_Sandstone_Brick"
    },
    {
      "x": -29,
      "y": 4,
      "z": -2,
      "name": "Rock_Sandstone_Red_Cobble"
    },
    {
      "x": -29,
      "y": 5,
      "z": -2,
      "name": "Rock_Sandstone_Brick"
    },
    {
      "x": -29,
      "y": 6,
      "z": -2,
      "name": "Rock_Sandstone_Red_Cobble"
    },
    {
      "x": -29,
      "y": 2,
      "z": -1,
      "name": "Rock_Sandstone_Brick"
    },
    {
      "x": -29,
      "y": 3,
      "z": -1,
      "name": "Rock_Sandstone_Brick"
    },
    {
      "x": -29,
      "y": 4,
      "z": -1,
      "name": "Rock_Sandstone_Red_Cobble"
    },
    {
      "x": -29,
      "y": 5,
      "z": -1,
      "name": "Rock_Sandstone_Brick"
    },
    {
      "x": -29,
      "y": 6,
      "z": -1,
      "name": "Rock_Sandstone_Red_Cobble"
    },
    {
      "x": -29,
      "y": 7,
      "z": -1,
      "name": "Plant_Coral_Block_Purple"
    },
    {
      "x": -29,
      "y": 2,
      "z": 0,
      "name": "Rock_Sandstone_Brick"
    },
    {
      "x": -29,
      "y": 3,
      "z": 0,
      "name": "Rock_Sandstone_Brick"
    },
    {
      "x": -29,
      "y": 4,
      "z": 0,
      "name": "Rock_Sandstone_Red_Cobble"
    },
    {
      "x": -29,
      "y": 5,
      "z": 0,
      "name": "Rock_Sandstone_Brick"
    },
    {
      "x": -29,
      "y": 6,
      "z": 0,
      "name": "Rock_Sandstone_Red_Cobble"
    },
    {
      "x": -29,
      "y": 7,
      "z": 0,
      "name": "Plant_Coral_Block_Purple"
    },
    {
      "x": -29,
      "y": 8,
      "z": 0,
      "name": "Plant_Coral_Block_Purple"
    },
    {
      "x": -29,
      "y": 2,
      "z": 1,
      "name": "Rock_Sandstone_Brick"
    },
    {
      "x": -29,
      "y": 3,
      "z": 1,
      "name": "Rock_Sandstone_Brick"
    },
    {
      "x": -29,
      "y": 4,
      "z": 1,
      "name": "Rock_Sandstone_Red_Cobble"
    },
    {
      "x": -29,
      "y": 5,
      "z": 1,
      "name": "Rock_Sandstone_Brick"
    },
    {
      "x": -29,
      "y": 6,
      "z": 1,
      "name": "Rock_Sandstone_Red_Cobble"
    },
    {
      "x": -29,
      "y": 7,
      "z": 1,
      "name": "Plant_Coral_Block_Purple"
    },
    {
      "x": -29,
      "y": 8,
      "z": 1,
      "name": "Plant_Coral_Block_Purple"
    },
    {
      "x": -29,
      "y": 2,
      "z": 2,
      "name": "Rock_Sandstone_Brick"
    },
    {
      "x": -29,
      "y": 3,
      "z": 2,
      "name": "Rock_Sandstone_Brick"
    },
    {
      "x": -29,
      "y": 4,
      "z": 2,
      "name": "Rock_Sandstone_Red_Cobble"
    },
    {
      "x": -29,
      "y": 5,
      "z": 2,
      "name": "Rock_Sandstone_Brick"
    },
    {
      "x": -29,
      "y": 6,
      "z": 2,
      "name": "Rock_Sandstone_Red_Cobble"
    },
    {
      "x": -29,
      "y": 7,
      "z": 2,
      "name": "Plant_Coral_Block_Purple"
    },
    {
      "x": -29,
      "y": 8,
      "z": 2,
      "name": "Plant_Coral_Block_Purple"
    },
    {
      "x": -29,
      "y": 2,
      "z": 3,
      "name": "Rock_Sandstone_Brick"
    },
    {
      "x": -29,
      "y": 3,
      "z": 3,
      "name": "Rock_Sandstone_Brick"
    },
    {
      "x": -29,
      "y": 4,
      "z": 3,
      "name": "Rock_Sandstone_Red_Cobble"
    },
    {
      "x": -29,
      "y": 5,
      "z": 3,
      "name": "Rock_Sandstone_Brick"
    },
    {
      "x": -29,
      "y": 6,
      "z": 3,
      "name": "Rock_Sandstone_Red_Cobble"
    },
    {
      "x": -29,
      "y": 7,
      "z": 3,
      "name": "Plant_Coral_Block_Purple"
    },
    {
      "x": -29,
      "y": 8,
      "z": 3,
      "name": "Plant_Coral_Block_Purple"
    },
    {
      "x": -29,
      "y": 9,
      "z": 3,
      "name": "Plant_Coral_Block_Purple"
    },
    {
      "x": -29,
      "y": 2,
      "z": 4,
      "name": "Rock_Sandstone_Brick"
    },
    {
      "x": -29,
      "y": 3,
      "z": 4,
      "name": "Rock_Sandstone_Brick"
    },
    {
      "x": -29,
      "y": 4,
      "z": 4,
      "name": "Rock_Sandstone_Red_Cobble"
    },
    {
      "x": -29,
      "y": 5,
      "z": 4,
      "name": "Rock_Sandstone_Brick"
    },
    {
      "x": -29,
      "y": 6,
      "z": 4,
      "name": "Rock_Sandstone_Red_Cobble"
    },
    {
      "x": -29,
      "y": 7,
      "z": 4,
      "name": "Plant_Coral_Block_Purple"
    },
    {
      "x": -29,
      "y": 8,
      "z": 4,
      "name": "Plant_Coral_Bush_Blue"
    },
    {
      "x": -29,
      "y": 2,
      "z": 5,
      "name": "Rock_Sandstone_Brick"
    },
    {
      "x": -29,
      "y": 3,
      "z": 5,
      "name": "Rock_Sandstone_Brick"
    },
    {
      "x": -29,
      "y": 4,
      "z": 5,
      "name": "Rock_Sandstone_Red_Cobble"
    },
    {
      "x": -29,
      "y": 5,
      "z": 5,
      "name": "Rock_Sandstone_Brick"
    },
    {
      "x": -29,
      "y": 6,
      "z": 5,
      "name": "Rock_Sandstone_Red_Cobble"
    },
    {
      "x": -29,
      "y": 7,
      "z": 5,
      "name": "Plant_Coral_Block_Purple"
    },
    {
      "x": -29,
      "y": 2,
      "z": 6,
      "name": "Rock_Sandstone_Brick"
    },
    {
      "x": -29,
      "y": 3,
      "z": 6,
      "name": "Rock_Sandstone_Brick"
    },
    {
      "x": -29,
      "y": 4,
      "z": 6,
      "name": "Rock_Sandstone_Red_Cobble"
    },
    {
      "x": -29,
      "y": 5,
      "z": 6,
      "name": "Rock_Sandstone_Brick"
    },
    {
      "x": -29,
      "y": 6,
      "z": 6,
      "name": "Rock_Sandstone_Red_Cobble"
    },
    {
      "x": -29,
      "y": 7,
      "z": 6,
      "name": "Plant_Coral_Block_Purple"
    },
    {
      "x": -29,
      "y": 2,
      "z": 7,
      "name": "Rock_Stone"
    },
    {
      "x": -29,
      "y": 3,
      "z": 7,
      "name": "Rock_Stone"
    },
    {
      "x": -29,
      "y": 4,
      "z": 7,
      "name": "Soil_Gravel_Sand_White"
    },
    {
      "x": -29,
      "y": 2,
      "z": 8,
      "name": "Rock_Stone"
    },
    {
      "x": -29,
      "y": 3,
      "z": 8,
      "name": "Rock_Stone"
    },
    {
      "x": -29,
      "y": 4,
      "z": 8,
      "name": "Soil_Gravel_Sand_White"
    },
    {
      "x": -29,
      "y": 2,
      "z": 9,
      "name": "Rock_Stone"
    },
    {
      "x": -29,
      "y": 3,
      "z": 9,
      "name": "Rock_Stone"
    },
    {
      "x": -29,
      "y": 4,
      "z": 9,
      "name": "Soil_Gravel_Sand_White"
    },
    {
      "x": -29,
      "y": 2,
      "z": 10,
      "name": "Rock_Stone"
    },
    {
      "x": -29,
      "y": 3,
      "z": 10,
      "name": "Rock_Stone"
    },
    {
      "x": -29,
      "y": 4,
      "z": 10,
      "name": "Soil_Gravel_Sand_White"
    },
    {
      "x": -29,
      "y": 2,
      "z": 11,
      "name": "Rock_Stone"
    },
    {
      "x": -29,
      "y": 3,
      "z": 11,
      "name": "Rock_Stone"
    },
    {
      "x": -29,
      "y": 4,
      "z": 11,
      "name": "Soil_Gravel_Sand_White"
    },
    {
      "x": -29,
      "y": 2,
      "z": 12,
      "name": "Rock_Stone"
    },
    {
      "x": -29,
      "y": 3,
      "z": 12,
      "name": "Rock_Stone"
    },
    {
      "x": -29,
      "y": 4,
      "z": 12,
      "name": "Soil_Gravel_Sand_White"
    },
    {
      "x": -29,
      "y": 2,
      "z": 13,
      "name": "Rock_Stone"
    },
    {
      "x": -29,
      "y": 3,
      "z": 13,
      "name": "Rock_Stone"
    },
    {
      "x": -29,
      "y": 4,
      "z": 13,
      "name": "Soil_Gravel_Sand_White"
    },
    {
      "x": -29,
      "y": 2,
      "z": 14,
      "name": "Rock_Stone"
    },
    {
      "x": -29,
      "y": 3,
      "z": 14,
      "name": "Rock_Stone"
    },
    {
      "x": -29,
      "y": 4,
      "z": 14,
      "name": "Soil_Gravel_Sand_White"
    },
    {
      "x": -29,
      "y": 2,
      "z": 15,
      "name": "Rock_Stone"
    },
    {
      "x": -29,
      "y": 3,
      "z": 15,
      "name": "Rock_Stone"
    },
    {
      "x": -29,
      "y": 4,
      "z": 15,
      "name": "Soil_Gravel_Sand_White"
    },
    {
      "x": -29,
      "y": 2,
      "z": 16,
      "name": "Rock_Sandstone_Brick"
    },
    {
      "x": -29,
      "y": 3,
      "z": 16,
      "name": "Rock_Sandstone_Brick"
    },
    {
      "x": -29,
      "y": 4,
      "z": 16,
      "name": "Rock_Sandstone_Red_Cobble"
    },
    {
      "x": -29,
      "y": 2,
      "z": 17,
      "name": "Rock_Sandstone_Brick"
    },
    {
      "x": -29,
      "y": 3,
      "z": 17,
      "name": "Rock_Sandstone_Brick"
    },
    {
      "x": -29,
      "y": 4,
      "z": 17,
      "name": "Rock_Sandstone_Red_Cobble"
    },
    {
      "x": -28,
      "y": 1,
      "z": -20,
      "name": "Plant_Coral_Block_Purple"
    },
    {
      "x": -28,
      "y": 2,
      "z": -20,
      "name": "Plant_Coral_Block_Purple"
    },
    {
      "x": -28,
      "y": 3,
      "z": -20,
      "name": "Plant_Coral_Block_Purple"
    },
    {
      "x": -28,
      "y": 2,
      "z": -19,
      "name": "Plant_Coral_Block_Purple"
    },
    {
      "x": -28,
      "y": 3,
      "z": -19,
      "name": "Plant_Coral_Block_Purple"
    },
    {
      "x": -28,
      "y": 4,
      "z": -19,
      "name": "Plant_Coral_Block_Purple"
    },
    {
      "x": -28,
      "y": 2,
      "z": -18,
      "name": "Plant_Coral_Block_Purple"
    },
    {
      "x": -28,
      "y": 3,
      "z": -18,
      "name": "Plant_Coral_Block_Purple"
    },
    {
      "x": -28,
      "y": 4,
      "z": -18,
      "name": "Plant_Coral_Block_Purple"
    },
    {
      "x": -28,
      "y": 5,
      "z": -18,
      "name": "Plant_Coral_Block_Purple"
    },
    {
      "x": -28,
      "y": 2,
      "z": -17,
      "name": "Rock_Sandstone_Brick"
    },
    {
      "x": -28,
      "y": 3,
      "z": -17,
      "name": "Rock_Sandstone_Brick"
    },
    {
      "x": -28,
      "y": 4,
      "z": -17,
      "name": "Rock_Sandstone_Red_Cobble"
    },
    {
      "x": -28,
      "y": 2,
      "z": -16,
      "name": "Rock_Sandstone_Brick"
    },
    {
      "x": -28,
      "y": 3,
      "z": -16,
      "name": "Rock_Sandstone_Brick"
    },
    {
      "x": -28,
      "y": 4,
      "z": -16,
      "name": "Rock_Sandstone_Red_Cobble"
    },
    {
      "x": -28,
      "y": 2,
      "z": -15,
      "name": "Rock_Stone"
    },
    {
      "x": -28,
      "y": 3,
      "z": -15,
      "name": "Rock_Stone"
    },
    {
      "x": -28,
      "y": 4,
      "z": -15,
      "name": "Soil_Gravel_Sand_White"
    },
    {
      "x": -28,
      "y": 2,
      "z": -14,
      "name": "Rock_Stone"
    },
    {
      "x": -28,
      "y": 3,
      "z": -14,
      "name": "Rock_Stone"
    },
    {
      "x": -28,
      "y": 4,
      "z": -14,
      "name": "Soil_Gravel_Sand_White"
    },
    {
      "x": -28,
      "y": 2,
      "z": -13,
      "name": "Rock_Stone"
    },
    {
      "x": -28,
      "y": 3,
      "z": -13,
      "name": "Rock_Stone"
    },
    {
      "x": -28,
      "y": 4,
      "z": -13,
      "name": "Soil_Gravel_Sand_White"
    },
    {
      "x": -28,
      "y": 2,
      "z": -12,
      "name": "Rock_Stone"
    },
    {
      "x": -28,
      "y": 3,
      "z": -12,
      "name": "Rock_Stone"
    },
    {
      "x": -28,
      "y": 4,
      "z": -12,
      "name": "Soil_Gravel_Sand_White"
    },
    {
      "x": -28,
      "y": 2,
      "z": -11,
      "name": "Rock_Stone"
    },
    {
      "x": -28,
      "y": 3,
      "z": -11,
      "name": "Rock_Stone"
    },
    {
      "x": -28,
      "y": 4,
      "z": -11,
      "name": "Soil_Gravel_Sand_White"
    },
    {
      "x": -28,
      "y": 2,
      "z": -10,
      "name": "Rock_Stone"
    },
    {
      "x": -28,
      "y": 3,
      "z": -10,
      "name": "Rock_Stone"
    },
    {
      "x": -28,
      "y": 4,
      "z": -10,
      "name": "Soil_Gravel_Sand_White"
    },
    {
      "x": -28,
      "y": 2,
      "z": -9,
      "name": "Rock_Stone"
    },
    {
      "x": -28,
      "y": 3,
      "z": -9,
      "name": "Rock_Stone"
    },
    {
      "x": -28,
      "y": 4,
      "z": -9,
      "name": "Soil_Gravel_Sand_White"
    },
    {
      "x": -28,
      "y": 5,
      "z": -9,
      "name": "Soil_Gravel_Sand_White"
    },
    {
      "x": -28,
      "y": 2,
      "z": -8,
      "name": "Rock_Stone"
    },
    {
      "x": -28,
      "y": 3,
      "z": -8,
      "name": "Rock_Stone"
    },
    {
      "x": -28,
      "y": 4,
      "z": -8,
      "name": "Soil_Gravel_Sand_White"
    },
    {
      "x": -28,
      "y": 5,
      "z": -8,
      "name": "Soil_Gravel_Sand_White"
    },
    {
      "x": -28,
      "y": 2,
      "z": -7,
      "name": "Rock_Sandstone_Brick"
    },
    {
      "x": -28,
      "y": 3,
      "z": -7,
      "name": "Rock_Sandstone_Brick"
    },
    {
      "x": -28,
      "y": 4,
      "z": -7,
      "name": "Rock_Sandstone_Red_Cobble"
    },
    {
      "x": -28,
      "y": 5,
      "z": -7,
      "name": "Soil_Gravel_Sand_White"
    },
    {
      "x": -28,
      "y": 2,
      "z": -6,
      "name": "Rock_Sandstone_Brick"
    },
    {
      "x": -28,
      "y": 3,
      "z": -6,
      "name": "Rock_Sandstone_Brick"
    },
    {
      "x": -28,
      "y": 4,
      "z": -6,
      "name": "Rock_Sandstone_Red_Cobble"
    },
    {
      "x": -28,
      "y": 5,
      "z": -6,
      "name": "Soil_Gravel_Sand_White"
    },
    {
      "x": -28,
      "y": 2,
      "z": -5,
      "name": "Rock_Sandstone_Brick"
    },
    {
      "x": -28,
      "y": 3,
      "z": -5,
      "name": "Rock_Sandstone_Brick"
    },
    {
      "x": -28,
      "y": 4,
      "z": -5,
      "name": "Rock_Sandstone_Red_Cobble"
    },
    {
      "x": -28,
      "y": 5,
      "z": -5,
      "name": "Soil_Gravel_Sand_White"
    },
    {
      "x": -28,
      "y": 2,
      "z": -4,
      "name": "Rock_Stone"
    },
    {
      "x": -28,
      "y": 3,
      "z": -4,
      "name": "Rock_Stone"
    },
    {
      "x": -28,
      "y": 4,
      "z": -4,
      "name": "Rock_Stone"
    },
    {
      "x": -28,
      "y": 5,
      "z": -4,
      "name": "Rock_Stone"
    },
    {
      "x": -28,
      "y": 6,
      "z": -4,
      "name": "Soil_Gravel_Sand_White"
    },
    {
      "x": -28,
      "y": 2,
      "z": -3,
      "name": "Rock_Stone"
    },
    {
      "x": -28,
      "y": 3,
      "z": -3,
      "name": "Rock_Stone"
    },
    {
      "x": -28,
      "y": 4,
      "z": -3,
      "name": "Rock_Stone"
    },
    {
      "x": -28,
      "y": 5,
      "z": -3,
      "name": "Rock_Stone"
    },
    {
      "x": -28,
      "y": 6,
      "z": -3,
      "name": "Soil_Gravel_Sand_White"
    },
    {
      "x": -28,
      "y": 2,
      "z": -2,
      "name": "Rock_Stone"
    },
    {
      "x": -28,
      "y": 3,
      "z": -2,
      "name": "Rock_Stone"
    },
    {
      "x": -28,
      "y": 4,
      "z": -2,
      "name": "Rock_Stone"
    },
    {
      "x": -28,
      "y": 5,
      "z": -2,
      "name": "Rock_Stone"
    },
    {
      "x": -28,
      "y": 6,
      "z": -2,
      "name": "Rock_Stone"
    },
    {
      "x": -28,
      "y": 7,
      "z": -2,
      "name": "Plant_Coral_Block_Purple"
    },
    {
      "x": -28,
      "y": 8,
      "z": -2,
      "name": "Plant_Coral_Block_Purple"
    },
    {
      "x": -28,
      "y": 2,
      "z": -1,
      "name": "Rock_Stone"
    },
    {
      "x": -28,
      "y": 3,
      "z": -1,
      "name": "Rock_Stone"
    },
    {
      "x": -28,
      "y": 4,
      "z": -1,
      "name": "Rock_Stone"
    },
    {
      "x": -28,
      "y": 5,
      "z": -1,
      "name": "Rock_Stone"
    },
    {
      "x": -28,
      "y": 6,
      "z": -1,
      "name": "Rock_Stone"
    },
    {
      "x": -28,
      "y": 7,
      "z": -1,
      "name": "Plant_Coral_Block_Purple"
    },
    {
      "x": -28,
      "y": 8,
      "z": -1,
      "name": "Plant_Coral_Block_Purple"
    },
    {
      "x": -28,
      "y": 2,
      "z": 0,
      "name": "Rock_Stone"
    },
    {
      "x": -28,
      "y": 3,
      "z": 0,
      "name": "Rock_Stone"
    },
    {
      "x": -28,
      "y": 4,
      "z": 0,
      "name": "Rock_Stone"
    },
    {
      "x": -28,
      "y": 5,
      "z": 0,
      "name": "Rock_Stone"
    },
    {
      "x": -28,
      "y": 6,
      "z": 0,
      "name": "Rock_Stone"
    },
    {
      "x": -28,
      "y": 7,
      "z": 0,
      "name": "Plant_Coral_Block_Purple"
    },
    {
      "x": -28,
      "y": 8,
      "z": 0,
      "name": "Plant_Coral_Block_Purple"
    },
    {
      "x": -28,
      "y": 2,
      "z": 1,
      "name": "Rock_Stone"
    },
    {
      "x": -28,
      "y": 3,
      "z": 1,
      "name": "Rock_Stone"
    },
    {
      "x": -28,
      "y": 4,
      "z": 1,
      "name": "Rock_Stone"
    },
    {
      "x": -28,
      "y": 5,
      "z": 1,
      "name": "Rock_Stone"
    },
    {
      "x": -28,
      "y": 6,
      "z": 1,
      "name": "Rock_Stone"
    },
    {
      "x": -28,
      "y": 7,
      "z": 1,
      "name": "Plant_Coral_Block_Purple"
    },
    {
      "x": -28,
      "y": 8,
      "z": 1,
      "name": "Plant_Coral_Block_Purple"
    },
    {
      "x": -28,
      "y": 2,
      "z": 2,
      "name": "Rock_Stone"
    },
    {
      "x": -28,
      "y": 3,
      "z": 2,
      "name": "Rock_Stone"
    },
    {
      "x": -28,
      "y": 4,
      "z": 2,
      "name": "Rock_Stone"
    },
    {
      "x": -28,
      "y": 5,
      "z": 2,
      "name": "Rock_Stone"
    },
    {
      "x": -28,
      "y": 6,
      "z": 2,
      "name": "Rock_Stone"
    },
    {
      "x": -28,
      "y": 7,
      "z": 2,
      "name": "Plant_Coral_Block_Purple"
    },
    {
      "x": -28,
      "y": 8,
      "z": 2,
      "name": "Plant_Coral_Block_Purple"
    },
    {
      "x": -28,
      "y": 2,
      "z": 3,
      "name": "Rock_Stone"
    },
    {
      "x": -28,
      "y": 3,
      "z": 3,
      "name": "Rock_Stone"
    },
    {
      "x": -28,
      "y": 4,
      "z": 3,
      "name": "Rock_Stone"
    },
    {
      "x": -28,
      "y": 5,
      "z": 3,
      "name": "Rock_Stone"
    },
    {
      "x": -28,
      "y": 6,
      "z": 3,
      "name": "Rock_Stone"
    },
    {
      "x": -28,
      "y": 7,
      "z": 3,
      "name": "Plant_Coral_Block_Purple"
    },
    {
      "x": -28,
      "y": 8,
      "z": 3,
      "name": "Plant_Coral_Block_Purple"
    },
    {
      "x": -28,
      "y": 2,
      "z": 4,
      "name": "Rock_Stone"
    },
    {
      "x": -28,
      "y": 3,
      "z": 4,
      "name": "Rock_Stone"
    },
    {
      "x": -28,
      "y": 4,
      "z": 4,
      "name": "Rock_Stone"
    },
    {
      "x": -28,
      "y": 5,
      "z": 4,
      "name": "Rock_Stone"
    },
    {
      "x": -28,
      "y": 6,
      "z": 4,
      "name": "Rock_Stone"
    },
    {
      "x": -28,
      "y": 7,
      "z": 4,
      "name": "Plant_Coral_Block_Purple"
    },
    {
      "x": -28,
      "y": 2,
      "z": 5,
      "name": "Rock_Stone"
    },
    {
      "x": -28,
      "y": 3,
      "z": 5,
      "name": "Rock_Stone"
    },
    {
      "x": -28,
      "y": 4,
      "z": 5,
      "name": "Rock_Stone"
    },
    {
      "x": -28,
      "y": 5,
      "z": 5,
      "name": "Rock_Stone"
    },
    {
      "x": -28,
      "y": 6,
      "z": 5,
      "name": "Rock_Stone"
    },
    {
      "x": -28,
      "y": 7,
      "z": 5,
      "name": "Plant_Coral_Block_Purple"
    },
    {
      "x": -28,
      "y": 2,
      "z": 6,
      "name": "Rock_Stone"
    },
    {
      "x": -28,
      "y": 3,
      "z": 6,
      "name": "Rock_Stone"
    },
    {
      "x": -28,
      "y": 4,
      "z": 6,
      "name": "Rock_Stone"
    },
    {
      "x": -28,
      "y": 5,
      "z": 6,
      "name": "Rock_Stone"
    },
    {
      "x": -28,
      "y": 6,
      "z": 6,
      "name": "Soil_Gravel_Sand_White"
    },
    {
      "x": -28,
      "y": 2,
      "z": 7,
      "name": "Rock_Sandstone_Brick"
    },
    {
      "x": -28,
      "y": 3,
      "z": 7,
      "name": "Rock_Sandstone_Brick"
    },
    {
      "x": -28,
      "y": 4,
      "z": 7,
      "name": "Rock_Sandstone_Red_Cobble"
    },
    {
      "x": -28,
      "y": 5,
      "z": 7,
      "name": "Rock_Sandstone_Brick"
    },
    {
      "x": -28,
      "y": 6,
      "z": 7,
      "name": "Rock_Sandstone_Red_Cobble"
    },
    {
      "x": -28,
      "y": 2,
      "z": 8,
      "name": "Rock_Sandstone_Brick"
    },
    {
      "x": -28,
      "y": 3,
      "z": 8,
      "name": "Rock_Sandstone_Brick"
    },
    {
      "x": -28,
      "y": 4,
      "z": 8,
      "name": "Rock_Sandstone_Red_Cobble"
    },
    {
      "x": -28,
      "y": 5,
      "z": 8,
      "name": "Rock_Sandstone_Brick"
    },
    {
      "x": -28,
      "y": 6,
      "z": 8,
      "name": "Rock_Sandstone_Red_Cobble"
    },
    {
      "x": -28,
      "y": 2,
      "z": 9,
      "name": "Rock_Sandstone_Brick"
    },
    {
      "x": -28,
      "y": 3,
      "z": 9,
      "name": "Rock_Sandstone_Brick"
    },
    {
      "x": -28,
      "y": 4,
      "z": 9,
      "name": "Rock_Sandstone_Red_Cobble"
    },
    {
      "x": -28,
      "y": 5,
      "z": 9,
      "name": "Rock_Sandstone_Brick"
    },
    {
      "x": -28,
      "y": 6,
      "z": 9,
      "name": "Rock_Sandstone_Red_Cobble"
    },
    {
      "x": -28,
      "y": 2,
      "z": 10,
      "name": "Rock_Stone"
    },
    {
      "x": -28,
      "y": 3,
      "z": 10,
      "name": "Rock_Stone"
    },
    {
      "x": -28,
      "y": 4,
      "z": 10,
      "name": "Soil_Gravel_Sand_White"
    },
    {
      "x": -28,
      "y": 2,
      "z": 11,
      "name": "Rock_Stone"
    },
    {
      "x": -28,
      "y": 3,
      "z": 11,
      "name": "Rock_Stone"
    },
    {
      "x": -28,
      "y": 4,
      "z": 11,
      "name": "Soil_Gravel_Sand_White"
    },
    {
      "x": -28,
      "y": 2,
      "z": 12,
      "name": "Rock_Stone"
    },
    {
      "x": -28,
      "y": 3,
      "z": 12,
      "name": "Rock_Stone"
    },
    {
      "x": -28,
      "y": 4,
      "z": 12,
      "name": "Soil_Gravel_Sand_White"
    },
    {
      "x": -28,
      "y": 2,
      "z": 13,
      "name": "Rock_Stone"
    },
    {
      "x": -28,
      "y": 3,
      "z": 13,
      "name": "Rock_Stone"
    },
    {
      "x": -28,
      "y": 4,
      "z": 13,
      "name": "Soil_Gravel_Sand_White"
    },
    {
      "x": -28,
      "y": 2,
      "z": 14,
      "name": "Rock_Stone"
    },
    {
      "x": -28,
      "y": 3,
      "z": 14,
      "name": "Rock_Stone"
    },
    {
      "x": -28,
      "y": 4,
      "z": 14,
      "name": "Soil_Gravel_Sand_White"
    },
    {
      "x": -28,
      "y": 2,
      "z": 15,
      "name": "Rock_Stone"
    },
    {
      "x": -28,
      "y": 3,
      "z": 15,
      "name": "Rock_Stone"
    },
    {
      "x": -28,
      "y": 4,
      "z": 15,
      "name": "Soil_Gravel_Sand_White"
    },
    {
      "x": -28,
      "y": 2,
      "z": 16,
      "name": "Rock_Stone"
    },
    {
      "x": -28,
      "y": 3,
      "z": 16,
      "name": "Rock_Stone"
    },
    {
      "x": -28,
      "y": 4,
      "z": 16,
      "name": "Soil_Gravel_Sand_White"
    },
    {
      "x": -28,
      "y": 2,
      "z": 17,
      "name": "Rock_Stone"
    },
    {
      "x": -28,
      "y": 3,
      "z": 17,
      "name": "Rock_Stone"
    },
    {
      "x": -28,
      "y": 4,
      "z": 17,
      "name": "Soil_Gravel_Sand_White"
    },
    {
      "x": -28,
      "y": 2,
      "z": 18,
      "name": "Rock_Sandstone_Brick"
    },
    {
      "x": -28,
      "y": 3,
      "z": 18,
      "name": "Rock_Sandstone_Brick"
    },
    {
      "x": -28,
      "y": 4,
      "z": 18,
      "name": "Rock_Sandstone_Red_Cobble"
    },
    {
      "x": -28,
      "y": 2,
      "z": 19,
      "name": "Rock_Sandstone_Brick"
    },
    {
      "x": -28,
      "y": 3,
      "z": 19,
      "name": "Rock_Sandstone_Brick"
    },
    {
      "x": -28,
      "y": 4,
      "z": 19,
      "name": "Rock_Sandstone_Red_Cobble"
    },
    {
      "x": -27,
      "y": 2,
      "z": -19,
      "name": "Plant_Coral_Block_Purple"
    },
    {
      "x": -27,
      "y": 3,
      "z": -19,
      "name": "Plant_Coral_Block_Purple"
    },
    {
      "x": -27,
      "y": 4,
      "z": -19,
      "name": "Plant_Coral_Block_Purple"
    },
    {
      "x": -27,
      "y": 5,
      "z": -19,
      "name": "Plant_Coral_Block_Purple"
    },
    {
      "x": -27,
      "y": 2,
      "z": -18,
      "name": "Rock_Sandstone_Brick"
    },
    {
      "x": -27,
      "y": 3,
      "z": -18,
      "name": "Rock_Sandstone_Brick"
    },
    {
      "x": -27,
      "y": 4,
      "z": -18,
      "name": "Rock_Sandstone_Red_Cobble"
    },
    {
      "x": -27,
      "y": 5,
      "z": -18,
      "name": "Plant_Coral_Block_Purple"
    },
    {
      "x": -27,
      "y": 6,
      "z": -18,
      "name": "Plant_Coral_Block_Purple"
    },
    {
      "x": -27,
      "y": 7,
      "z": -18,
      "name": "Plant_Coral_Model_Violet"
    },
    {
      "x": -27,
      "y": 2,
      "z": -17,
      "name": "Rock_Stone"
    },
    {
      "x": -27,
      "y": 3,
      "z": -17,
      "name": "Rock_Stone"
    },
    {
      "x": -27,
      "y": 4,
      "z": -17,
      "name": "Rock_Stone"
    },
    {
      "x": -27,
      "y": 5,
      "z": -17,
      "name": "Plant_Coral_Block_Purple"
    },
    {
      "x": -27,
      "y": 6,
      "z": -17,
      "name": "Plant_Coral_Block_Purple"
    },
    {
      "x": -27,
      "y": 2,
      "z": -16,
      "name": "Rock_Stone"
    },
    {
      "x": -27,
      "y": 3,
      "z": -16,
      "name": "Rock_Stone"
    },
    {
      "x": -27,
      "y": 4,
      "z": -16,
      "name": "Soil_Gravel_Sand_White"
    },
    {
      "x": -27,
      "y": 2,
      "z": -15,
      "name": "Rock_Stone"
    },
    {
      "x": -27,
      "y": 3,
      "z": -15,
      "name": "Rock_Stone"
    },
    {
      "x": -27,
      "y": 4,
      "z": -15,
      "name": "Soil_Gravel_Sand_White"
    },
    {
      "x": -27,
      "y": 2,
      "z": -14,
      "name": "Rock_Stone"
    },
    {
      "x": -27,
      "y": 3,
      "z": -14,
      "name": "Rock_Stone"
    },
    {
      "x": -27,
      "y": 4,
      "z": -14,
      "name": "Soil_Gravel_Sand_White"
    },
    {
      "x": -27,
      "y": 2,
      "z": -13,
      "name": "Rock_Stone"
    },
    {
      "x": -27,
      "y": 3,
      "z": -13,
      "name": "Rock_Stone"
    },
    {
      "x": -27,
      "y": 4,
      "z": -13,
      "name": "Soil_Gravel_Sand_White"
    },
    {
      "x": -27,
      "y": 2,
      "z": -12,
      "name": "Rock_Stone"
    },
    {
      "x": -27,
      "y": 3,
      "z": -12,
      "name": "Rock_Stone"
    },
    {
      "x": -27,
      "y": 4,
      "z": -12,
      "name": "Soil_Gravel_Sand_White"
    },
    {
      "x": -27,
      "y": 2,
      "z": -11,
      "name": "Rock_Stone"
    },
    {
      "x": -27,
      "y": 3,
      "z": -11,
      "name": "Rock_Stone"
    },
    {
      "x": -27,
      "y": 4,
      "z": -11,
      "name": "Soil_Gravel_Sand_White"
    },
    {
      "x": -27,
      "y": 2,
      "z": -10,
      "name": "Rock_Sandstone_Brick"
    },
    {
      "x": -27,
      "y": 3,
      "z": -10,
      "name": "Rock_Sandstone_Brick"
    },
    {
      "x": -27,
      "y": 4,
      "z": -10,
      "name": "Rock_Sandstone_Red_Cobble"
    },
    {
      "x": -27,
      "y": 5,
      "z": -10,
      "name": "Rock_Sandstone_Brick"
    },
    {
      "x": -27,
      "y": 6,
      "z": -10,
      "name": "Rock_Sandstone_Red_Cobble"
    },
    {
      "x": -27,
      "y": 2,
      "z": -9,
      "name": "Rock_Sandstone_Brick"
    },
    {
      "x": -27,
      "y": 3,
      "z": -9,
      "name": "Rock_Sandstone_Brick"
    },
    {
      "x": -27,
      "y": 4,
      "z": -9,
      "name": "Rock_Sandstone_Red_Cobble"
    },
    {
      "x": -27,
      "y": 5,
      "z": -9,
      "name": "Rock_Sandstone_Brick"
    },
    {
      "x": -27,
      "y": 6,
      "z": -9,
      "name": "Rock_Sandstone_Red_Cobble"
    },
    {
      "x": -27,
      "y": 2,
      "z": -8,
      "name": "Rock_Sandstone_Brick"
    },
    {
      "x": -27,
      "y": 3,
      "z": -8,
      "name": "Rock_Sandstone_Brick"
    },
    {
      "x": -27,
      "y": 4,
      "z": -8,
      "name": "Rock_Sandstone_Red_Cobble"
    },
    {
      "x": -27,
      "y": 5,
      "z": -8,
      "name": "Rock_Sandstone_Brick"
    },
    {
      "x": -27,
      "y": 6,
      "z": -8,
      "name": "Rock_Sandstone_Red_Cobble"
    },
    {
      "x": -27,
      "y": 2,
      "z": -7,
      "name": "Rock_Stone"
    },
    {
      "x": -27,
      "y": 3,
      "z": -7,
      "name": "Rock_Stone"
    },
    {
      "x": -27,
      "y": 4,
      "z": -7,
      "name": "Rock_Stone"
    },
    {
      "x": -27,
      "y": 5,
      "z": -7,
      "name": "Rock_Stone"
    },
    {
      "x": -27,
      "y": 6,
      "z": -7,
      "name": "Soil_Gravel_Sand_White"
    },
    {
      "x": -27,
      "y": 2,
      "z": -6,
      "name": "Rock_Stone"
    },
    {
      "x": -27,
      "y": 3,
      "z": -6,
      "name": "Rock_Stone"
    },
    {
      "x": -27,
      "y": 4,
      "z": -6,
      "name": "Rock_Stone"
    },
    {
      "x": -27,
      "y": 5,
      "z": -6,
      "name": "Rock_Stone"
    },
    {
      "x": -27,
      "y": 6,
      "z": -6,
      "name": "Soil_Gravel_Sand_White"
    },
    {
      "x": -27,
      "y": 2,
      "z": -5,
      "name": "Rock_Stone"
    },
    {
      "x": -27,
      "y": 3,
      "z": -5,
      "name": "Rock_Stone"
    },
    {
      "x": -27,
      "y": 4,
      "z": -5,
      "name": "Rock_Stone"
    },
    {
      "x": -27,
      "y": 5,
      "z": -5,
      "name": "Rock_Stone"
    },
    {
      "x": -27,
      "y": 6,
      "z": -5,
      "name": "Soil_Gravel_Sand_White"
    },
    {
      "x": -27,
      "y": 2,
      "z": -4,
      "name": "Rock_Stone"
    },
    {
      "x": -27,
      "y": 3,
      "z": -4,
      "name": "Rock_Stone"
    },
    {
      "x": -27,
      "y": 4,
      "z": -4,
      "name": "Rock_Stone"
    },
    {
      "x": -27,
      "y": 5,
      "z": -4,
      "name": "Rock_Stone"
    },
    {
      "x": -27,
      "y": 6,
      "z": -4,
      "name": "Soil_Gravel_Sand_White"
    },
    {
      "x": -27,
      "y": 2,
      "z": -3,
      "name": "Rock_Stone"
    },
    {
      "x": -27,
      "y": 3,
      "z": -3,
      "name": "Rock_Stone"
    },
    {
      "x": -27,
      "y": 4,
      "z": -3,
      "name": "Rock_Stone"
    },
    {
      "x": -27,
      "y": 5,
      "z": -3,
      "name": "Rock_Stone"
    },
    {
      "x": -27,
      "y": 6,
      "z": -3,
      "name": "Rock_Stone"
    },
    {
      "x": -27,
      "y": 7,
      "z": -3,
      "name": "Plant_Coral_Block_Purple"
    },
    {
      "x": -27,
      "y": 2,
      "z": -2,
      "name": "Rock_Stone"
    },
    {
      "x": -27,
      "y": 3,
      "z": -2,
      "name": "Rock_Stone"
    },
    {
      "x": -27,
      "y": 4,
      "z": -2,
      "name": "Rock_Stone"
    },
    {
      "x": -27,
      "y": 5,
      "z": -2,
      "name": "Rock_Stone"
    },
    {
      "x": -27,
      "y": 6,
      "z": -2,
      "name": "Rock_Stone"
    },
    {
      "x": -27,
      "y": 7,
      "z": -2,
      "name": "Plant_Coral_Block_Purple"
    },
    {
      "x": -27,
      "y": 8,
      "z": -2,
      "name": "Plant_Coral_Block_Purple"
    },
    {
      "x": -27,
      "y": 2,
      "z": -1,
      "name": "Rock_Stone"
    },
    {
      "x": -27,
      "y": 3,
      "z": -1,
      "name": "Rock_Stone"
    },
    {
      "x": -27,
      "y": 4,
      "z": -1,
      "name": "Rock_Stone"
    },
    {
      "x": -27,
      "y": 5,
      "z": -1,
      "name": "Rock_Stone"
    },
    {
      "x": -27,
      "y": 6,
      "z": -1,
      "name": "Rock_Stone"
    },
    {
      "x": -27,
      "y": 7,
      "z": -1,
      "name": "Plant_Coral_Block_Purple"
    },
    {
      "x": -27,
      "y": 8,
      "z": -1,
      "name": "Plant_Coral_Block_Purple"
    },
    {
      "x": -27,
      "y": 2,
      "z": 0,
      "name": "Rock_Stone"
    },
    {
      "x": -27,
      "y": 3,
      "z": 0,
      "name": "Rock_Stone"
    },
    {
      "x": -27,
      "y": 4,
      "z": 0,
      "name": "Rock_Stone"
    },
    {
      "x": -27,
      "y": 5,
      "z": 0,
      "name": "Rock_Stone"
    },
    {
      "x": -27,
      "y": 6,
      "z": 0,
      "name": "Rock_Stone"
    },
    {
      "x": -27,
      "y": 7,
      "z": 0,
      "name": "Plant_Coral_Block_Purple"
    },
    {
      "x": -27,
      "y": 8,
      "z": 0,
      "name": "Plant_Coral_Block_Purple"
    },
    {
      "x": -27,
      "y": 2,
      "z": 1,
      "name": "Rock_Stone"
    },
    {
      "x": -27,
      "y": 3,
      "z": 1,
      "name": "Rock_Stone"
    },
    {
      "x": -27,
      "y": 4,
      "z": 1,
      "name": "Rock_Stone"
    },
    {
      "x": -27,
      "y": 5,
      "z": 1,
      "name": "Rock_Stone"
    },
    {
      "x": -27,
      "y": 6,
      "z": 1,
      "name": "Rock_Stone"
    },
    {
      "x": -27,
      "y": 7,
      "z": 1,
      "name": "Plant_Coral_Block_Purple"
    },
    {
      "x": -27,
      "y": 8,
      "z": 1,
      "name": "Plant_Coral_Block_Purple"
    },
    {
      "x": -27,
      "y": 2,
      "z": 2,
      "name": "Rock_Stone"
    },
    {
      "x": -27,
      "y": 3,
      "z": 2,
      "name": "Rock_Stone"
    },
    {
      "x": -27,
      "y": 4,
      "z": 2,
      "name": "Rock_Stone"
    },
    {
      "x": -27,
      "y": 5,
      "z": 2,
      "name": "Rock_Stone"
    },
    {
      "x": -27,
      "y": 6,
      "z": 2,
      "name": "Rock_Stone"
    },
    {
      "x": -27,
      "y": 7,
      "z": 2,
      "name": "Plant_Coral_Block_Purple"
    },
    {
      "x": -27,
      "y": 2,
      "z": 3,
      "name": "Rock_Stone"
    },
    {
      "x": -27,
      "y": 3,
      "z": 3,
      "name": "Rock_Stone"
    },
    {
      "x": -27,
      "y": 4,
      "z": 3,
      "name": "Rock_Stone"
    },
    {
      "x": -27,
      "y": 5,
      "z": 3,
      "name": "Rock_Stone"
    },
    {
      "x": -27,
      "y": 6,
      "z": 3,
      "name": "Rock_Stone"
    },
    {
      "x": -27,
      "y": 7,
      "z": 3,
      "name": "Plant_Coral_Block_Purple"
    },
    {
      "x": -27,
      "y": 2,
      "z": 4,
      "name": "Rock_Stone"
    },
    {
      "x": -27,
      "y": 3,
      "z": 4,
      "name": "Rock_Stone"
    },
    {
      "x": -27,
      "y": 4,
      "z": 4,
      "name": "Rock_Stone"
    },
    {
      "x": -27,
      "y": 5,
      "z": 4,
      "name": "Rock_Stone"
    },
    {
      "x": -27,
      "y": 6,
      "z": 4,
      "name": "Soil_Gravel_Sand_White"
    },
    {
      "x": -27,
      "y": 2,
      "z": 5,
      "name": "Rock_Stone"
    },
    {
      "x": -27,
      "y": 3,
      "z": 5,
      "name": "Rock_Stone"
    },
    {
      "x": -27,
      "y": 4,
      "z": 5,
      "name": "Rock_Stone"
    },
    {
      "x": -27,
      "y": 5,
      "z": 5,
      "name": "Rock_Stone"
    },
    {
      "x": -27,
      "y": 6,
      "z": 5,
      "name": "Soil_Gravel_Sand_White"
    },
    {
      "x": -27,
      "y": 2,
      "z": 6,
      "name": "Rock_Stone"
    },
    {
      "x": -27,
      "y": 3,
      "z": 6,
      "name": "Rock_Stone"
    },
    {
      "x": -27,
      "y": 4,
      "z": 6,
      "name": "Rock_Stone"
    },
    {
      "x": -27,
      "y": 5,
      "z": 6,
      "name": "Rock_Stone"
    },
    {
      "x": -27,
      "y": 6,
      "z": 6,
      "name": "Soil_Gravel_Sand_White"
    },
    {
      "x": -27,
      "y": 2,
      "z": 7,
      "name": "Rock_Stone"
    },
    {
      "x": -27,
      "y": 3,
      "z": 7,
      "name": "Rock_Stone"
    },
    {
      "x": -27,
      "y": 4,
      "z": 7,
      "name": "Rock_Stone"
    },
    {
      "x": -27,
      "y": 5,
      "z": 7,
      "name": "Rock_Stone"
    },
    {
      "x": -27,
      "y": 6,
      "z": 7,
      "name": "Soil_Gravel_Sand_White"
    },
    {
      "x": -27,
      "y": 2,
      "z": 8,
      "name": "Rock_Stone"
    },
    {
      "x": -27,
      "y": 3,
      "z": 8,
      "name": "Rock_Stone"
    },
    {
      "x": -27,
      "y": 4,
      "z": 8,
      "name": "Rock_Stone"
    },
    {
      "x": -27,
      "y": 5,
      "z": 8,
      "name": "Rock_Stone"
    },
    {
      "x": -27,
      "y": 6,
      "z": 8,
      "name": "Soil_Gravel_Sand_White"
    },
    {
      "x": -27,
      "y": 2,
      "z": 9,
      "name": "Rock_Stone"
    },
    {
      "x": -27,
      "y": 3,
      "z": 9,
      "name": "Rock_Stone"
    },
    {
      "x": -27,
      "y": 4,
      "z": 9,
      "name": "Rock_Stone"
    },
    {
      "x": -27,
      "y": 5,
      "z": 9,
      "name": "Rock_Stone"
    },
    {
      "x": -27,
      "y": 6,
      "z": 9,
      "name": "Soil_Gravel_Sand_White"
    },
    {
      "x": -27,
      "y": 2,
      "z": 10,
      "name": "Rock_Sandstone_Brick"
    },
    {
      "x": -27,
      "y": 3,
      "z": 10,
      "name": "Rock_Sandstone_Brick"
    },
    {
      "x": -27,
      "y": 4,
      "z": 10,
      "name": "Rock_Sandstone_Red_Cobble"
    },
    {
      "x": -27,
      "y": 5,
      "z": 10,
      "name": "Rock_Sandstone_Brick"
    },
    {
      "x": -27,
      "y": 6,
      "z": 10,
      "name": "Rock_Sandstone_Red_Cobble"
    },
    {
      "x": -27,
      "y": 2,
      "z": 11,
      "name": "Rock_Sandstone_Brick"
    },
    {
      "x": -27,
      "y": 3,
      "z": 11,
      "name": "Rock_Sandstone_Brick"
    },
    {
      "x": -27,
      "y": 4,
      "z": 11,
      "name": "Rock_Sandstone_Red_Cobble"
    },
    {
      "x": -27,
      "y": 5,
      "z": 11,
      "name": "Rock_Sandstone_Brick"
    },
    {
      "x": -27,
      "y": 6,
      "z": 11,
      "name": "Rock_Sandstone_Red_Cobble"
    },
    {
      "x": -27,
      "y": 2,
      "z": 12,
      "name": "Rock_Sandstone_Brick"
    },
    {
      "x": -27,
      "y": 3,
      "z": 12,
      "name": "Rock_Sandstone_Brick"
    },
    {
      "x": -27,
      "y": 4,
      "z": 12,
      "name": "Rock_Sandstone_Red_Cobble"
    },
    {
      "x": -27,
      "y": 5,
      "z": 12,
      "name": "Rock_Sandstone_Brick"
    },
    {
      "x": -27,
      "y": 6,
      "z": 12,
      "name": "Rock_Sandstone_Red_Cobble"
    },
    {
      "x": -27,
      "y": 2,
      "z": 13,
      "name": "Rock_Stone"
    },
    {
      "x": -27,
      "y": 3,
      "z": 13,
      "name": "Rock_Stone"
    },
    {
      "x": -27,
      "y": 4,
      "z": 13,
      "name": "Soil_Gravel_Sand_White"
    },
    {
      "x": -27,
      "y": 2,
      "z": 14,
      "name": "Rock_Stone"
    },
    {
      "x": -27,
      "y": 3,
      "z": 14,
      "name": "Rock_Stone"
    },
    {
      "x": -27,
      "y": 4,
      "z": 14,
      "name": "Soil_Gravel_Sand_White"
    },
    {
      "x": -27,
      "y": 2,
      "z": 15,
      "name": "Rock_Stone"
    },
    {
      "x": -27,
      "y": 3,
      "z": 15,
      "name": "Rock_Stone"
    },
    {
      "x": -27,
      "y": 4,
      "z": 15,
      "name": "Soil_Gravel_Sand_White"
    },
    {
      "x": -27,
      "y": 2,
      "z": 16,
      "name": "Rock_Stone"
    },
    {
      "x": -27,
      "y": 3,
      "z": 16,
      "name": "Rock_Stone"
    },
    {
      "x": -27,
      "y": 4,
      "z": 16,
      "name": "Soil_Gravel_Sand_White"
    },
    {
      "x": -27,
      "y": 2,
      "z": 17,
      "name": "Rock_Stone"
    },
    {
      "x": -27,
      "y": 3,
      "z": 17,
      "name": "Rock_Stone"
    },
    {
      "x": -27,
      "y": 4,
      "z": 17,
      "name": "Soil_Gravel_Sand_White"
    },
    {
      "x": -27,
      "y": 2,
      "z": 18,
      "name": "Rock_Stone"
    },
    {
      "x": -27,
      "y": 3,
      "z": 18,
      "name": "Rock_Stone"
    },
    {
      "x": -27,
      "y": 4,
      "z": 18,
      "name": "Soil_Gravel_Sand_White"
    },
    {
      "x": -27,
      "y": 2,
      "z": 19,
      "name": "Rock_Stone"
    },
    {
      "x": -27,
      "y": 3,
      "z": 19,
      "name": "Rock_Stone"
    },
    {
      "x": -27,
      "y": 4,
      "z": 19,
      "name": "Soil_Gravel_Sand_White"
    },
    {
      "x": -27,
      "y": 2,
      "z": 20,
      "name": "Rock_Sandstone_Brick"
    },
    {
      "x": -27,
      "y": 3,
      "z": 20,
      "name": "Rock_Sandstone_Brick"
    },
    {
      "x": -27,
      "y": 4,
      "z": 20,
      "name": "Rock_Sandstone_Red_Cobble"
    },
    {
      "x": -26,
      "y": 2,
      "z": -19,
      "name": "Rock_Sandstone_Brick"
    },
    {
      "x": -26,
      "y": 3,
      "z": -19,
      "name": "Rock_Sandstone_Brick"
    },
    {
      "x": -26,
      "y": 4,
      "z": -19,
      "name": "Rock_Sandstone_Red_Cobble"
    },
    {
      "x": -26,
      "y": 5,
      "z": -19,
      "name": "Plant_Coral_Block_Purple"
    },
    {
      "x": -26,
      "y": 2,
      "z": -18,
      "name": "Rock_Stone"
    },
    {
      "x": -26,
      "y": 3,
      "z": -18,
      "name": "Rock_Stone"
    },
    {
      "x": -26,
      "y": 4,
      "z": -18,
      "name": "Rock_Stone"
    },
    {
      "x": -26,
      "y": 5,
      "z": -18,
      "name": "Plant_Coral_Block_Purple"
    },
    {
      "x": -26,
      "y": 6,
      "z": -18,
      "name": "Plant_Coral_Block_Purple"
    },
    {
      "x": -26,
      "y": 2,
      "z": -17,
      "name": "Rock_Stone"
    },
    {
      "x": -26,
      "y": 3,
      "z": -17,
      "name": "Rock_Stone"
    },
    {
      "x": -26,
      "y": 4,
      "z": -17,
      "name": "Rock_Stone"
    },
    {
      "x": -26,
      "y": 5,
      "z": -17,
      "name": "Plant_Coral_Block_Purple"
    },
    {
      "x": -26,
      "y": 6,
      "z": -17,
      "name": "Plant_Coral_Block_Purple"
    },
    {
      "x": -26,
      "y": 2,
      "z": -16,
      "name": "Rock_Stone"
    },
    {
      "x": -26,
      "y": 3,
      "z": -16,
      "name": "Rock_Stone"
    },
    {
      "x": -26,
      "y": 4,
      "z": -16,
      "name": "Rock_Stone"
    },
    {
      "x": -26,
      "y": 5,
      "z": -16,
      "name": "Plant_Coral_Block_Purple"
    },
    {
      "x": -26,
      "y": 6,
      "z": -16,
      "name": "Plant_Coral_Block_Purple"
    },
    {
      "x": -26,
      "y": 7,
      "z": -16,
      "name": "Plant_Coral_Model_Violet"
    },
    {
      "x": -26,
      "y": 2,
      "z": -15,
      "name": "Rock_Stone"
    },
    {
      "x": -26,
      "y": 3,
      "z": -15,
      "name": "Rock_Stone"
    },
    {
      "x": -26,
      "y": 4,
      "z": -15,
      "name": "Soil_Gravel_Sand_White"
    },
    {
      "x": -26,
      "y": 2,
      "z": -14,
      "name": "Rock_Stone"
    },
    {
      "x": -26,
      "y": 3,
      "z": -14,
      "name": "Rock_Stone"
    },
    {
      "x": -26,
      "y": 4,
      "z": -14,
      "name": "Soil_Gravel_Sand_White"
    },
    {
      "x": -26,
      "y": 2,
      "z": -13,
      "name": "Rock_Stone"
    },
    {
      "x": -26,
      "y": 3,
      "z": -13,
      "name": "Rock_Stone"
    },
    {
      "x": -26,
      "y": 4,
      "z": -13,
      "name": "Soil_Gravel_Sand_White"
    },
    {
      "x": -26,
      "y": 2,
      "z": -12,
      "name": "Rock_Sandstone_Brick"
    },
    {
      "x": -26,
      "y": 3,
      "z": -12,
      "name": "Rock_Sandstone_Brick"
    },
    {
      "x": -26,
      "y": 4,
      "z": -12,
      "name": "Rock_Sandstone_Red_Cobble"
    },
    {
      "x": -26,
      "y": 5,
      "z": -12,
      "name": "Rock_Sandstone_Brick"
    },
    {
      "x": -26,
      "y": 6,
      "z": -12,
      "name": "Rock_Sandstone_Red_Cobble"
    },
    {
      "x": -26,
      "y": 2,
      "z": -11,
      "name": "Rock_Sandstone_Brick"
    },
    {
      "x": -26,
      "y": 3,
      "z": -11,
      "name": "Rock_Sandstone_Brick"
    },
    {
      "x": -26,
      "y": 4,
      "z": -11,
      "name": "Rock_Sandstone_Red_Cobble"
    },
    {
      "x": -26,
      "y": 5,
      "z": -11,
      "name": "Rock_Sandstone_Brick"
    },
    {
      "x": -26,
      "y": 6,
      "z": -11,
      "name": "Rock_Sandstone_Red_Cobble"
    },
    {
      "x": -26,
      "y": 2,
      "z": -10,
      "name": "Rock_Stone"
    },
    {
      "x": -26,
      "y": 3,
      "z": -10,
      "name": "Rock_Stone"
    },
    {
      "x": -26,
      "y": 4,
      "z": -10,
      "name": "Rock_Stone"
    },
    {
      "x": -26,
      "y": 5,
      "z": -10,
      "name": "Rock_Stone"
    },
    {
      "x": -26,
      "y": 6,
      "z": -10,
      "name": "Soil_Gravel_Sand_White"
    },
    {
      "x": -26,
      "y": 2,
      "z": -9,
      "name": "Rock_Stone"
    },
    {
      "x": -26,
      "y": 3,
      "z": -9,
      "name": "Rock_Stone"
    },
    {
      "x": -26,
      "y": 4,
      "z": -9,
      "name": "Rock_Stone"
    },
    {
      "x": -26,
      "y": 5,
      "z": -9,
      "name": "Rock_Stone"
    },
    {
      "x": -26,
      "y": 6,
      "z": -9,
      "name": "Soil_Gravel_Sand_White"
    },
    {
      "x": -26,
      "y": 2,
      "z": -8,
      "name": "Rock_Stone"
    },
    {
      "x": -26,
      "y": 3,
      "z": -8,
      "name": "Rock_Stone"
    },
    {
      "x": -26,
      "y": 4,
      "z": -8,
      "name": "Rock_Stone"
    },
    {
      "x": -26,
      "y": 5,
      "z": -8,
      "name": "Rock_Stone"
    },
    {
      "x": -26,
      "y": 6,
      "z": -8,
      "name": "Soil_Gravel_Sand_White"
    },
    {
      "x": -26,
      "y": 2,
      "z": -7,
      "name": "Rock_Stone"
    },
    {
      "x": -26,
      "y": 3,
      "z": -7,
      "name": "Rock_Stone"
    },
    {
      "x": -26,
      "y": 4,
      "z": -7,
      "name": "Rock_Stone"
    },
    {
      "x": -26,
      "y": 5,
      "z": -7,
      "name": "Rock_Stone"
    },
    {
      "x": -26,
      "y": 6,
      "z": -7,
      "name": "Soil_Gravel_Sand_White"
    },
    {
      "x": -26,
      "y": 2,
      "z": -6,
      "name": "Rock_Stone"
    },
    {
      "x": -26,
      "y": 3,
      "z": -6,
      "name": "Rock_Stone"
    },
    {
      "x": -26,
      "y": 4,
      "z": -6,
      "name": "Rock_Stone"
    },
    {
      "x": -26,
      "y": 5,
      "z": -6,
      "name": "Rock_Stone"
    },
    {
      "x": -26,
      "y": 6,
      "z": -6,
      "name": "Soil_Gravel_Sand_White"
    },
    {
      "x": -26,
      "y": 2,
      "z": -5,
      "name": "Rock_Stone"
    },
    {
      "x": -26,
      "y": 3,
      "z": -5,
      "name": "Rock_Stone"
    },
    {
      "x": -26,
      "y": 4,
      "z": -5,
      "name": "Rock_Stone"
    },
    {
      "x": -26,
      "y": 5,
      "z": -5,
      "name": "Rock_Stone"
    },
    {
      "x": -26,
      "y": 6,
      "z": -5,
      "name": "Soil_Gravel_Sand_White"
    },
    {
      "x": -26,
      "y": 2,
      "z": -4,
      "name": "Rock_Stone"
    },
    {
      "x": -26,
      "y": 3,
      "z": -4,
      "name": "Rock_Stone"
    },
    {
      "x": -26,
      "y": 4,
      "z": -4,
      "name": "Rock_Stone"
    },
    {
      "x": -26,
      "y": 5,
      "z": -4,
      "name": "Rock_Stone"
    },
    {
      "x": -26,
      "y": 6,
      "z": -4,
      "name": "Soil_Gravel_Sand_White"
    },
    {
      "x": -26,
      "y": 2,
      "z": -3,
      "name": "Rock_Stone"
    },
    {
      "x": -26,
      "y": 3,
      "z": -3,
      "name": "Rock_Stone"
    },
    {
      "x": -26,
      "y": 4,
      "z": -3,
      "name": "Rock_Stone"
    },
    {
      "x": -26,
      "y": 5,
      "z": -3,
      "name": "Rock_Stone"
    },
    {
      "x": -26,
      "y": 6,
      "z": -3,
      "name": "Rock_Stone"
    },
    {
      "x": -26,
      "y": 7,
      "z": -3,
      "name": "Plant_Coral_Block_Purple"
    },
    {
      "x": -26,
      "y": 8,
      "z": -3,
      "name": "Plant_Coral_Block_Purple"
    },
    {
      "x": -26,
      "y": 2,
      "z": -2,
      "name": "Rock_Stone"
    },
    {
      "x": -26,
      "y": 3,
      "z": -2,
      "name": "Rock_Stone"
    },
    {
      "x": -26,
      "y": 4,
      "z": -2,
      "name": "Rock_Stone"
    },
    {
      "x": -26,
      "y": 5,
      "z": -2,
      "name": "Rock_Stone"
    },
    {
      "x": -26,
      "y": 6,
      "z": -2,
      "name": "Rock_Stone"
    },
    {
      "x": -26,
      "y": 7,
      "z": -2,
      "name": "Plant_Coral_Block_Purple"
    },
    {
      "x": -26,
      "y": 8,
      "z": -2,
      "name": "Plant_Coral_Block_Purple"
    },
    {
      "x": -26,
      "y": 9,
      "z": -2,
      "name": "Plant_Coral_Block_Purple"
    },
    {
      "x": -26,
      "y": 2,
      "z": -1,
      "name": "Rock_Stone"
    },
    {
      "x": -26,
      "y": 3,
      "z": -1,
      "name": "Rock_Stone"
    },
    {
      "x": -26,
      "y": 4,
      "z": -1,
      "name": "Rock_Stone"
    },
    {
      "x": -26,
      "y": 5,
      "z": -1,
      "name": "Rock_Stone"
    },
    {
      "x": -26,
      "y": 6,
      "z": -1,
      "name": "Rock_Stone"
    },
    {
      "x": -26,
      "y": 7,
      "z": -1,
      "name": "Plant_Coral_Block_Purple"
    },
    {
      "x": -26,
      "y": 8,
      "z": -1,
      "name": "Plant_Coral_Block_Purple"
    },
    {
      "x": -26,
      "y": 9,
      "z": -1,
      "name": "Plant_Coral_Block_Purple"
    },
    {
      "x": -26,
      "y": 2,
      "z": 0,
      "name": "Rock_Stone"
    },
    {
      "x": -26,
      "y": 3,
      "z": 0,
      "name": "Rock_Stone"
    },
    {
      "x": -26,
      "y": 4,
      "z": 0,
      "name": "Rock_Stone"
    },
    {
      "x": -26,
      "y": 5,
      "z": 0,
      "name": "Rock_Stone"
    },
    {
      "x": -26,
      "y": 6,
      "z": 0,
      "name": "Soil_Gravel_Sand_White"
    },
    {
      "x": -26,
      "y": 2,
      "z": 1,
      "name": "Rock_Stone"
    },
    {
      "x": -26,
      "y": 3,
      "z": 1,
      "name": "Rock_Stone"
    },
    {
      "x": -26,
      "y": 4,
      "z": 1,
      "name": "Rock_Stone"
    },
    {
      "x": -26,
      "y": 5,
      "z": 1,
      "name": "Rock_Stone"
    },
    {
      "x": -26,
      "y": 6,
      "z": 1,
      "name": "Soil_Gravel_Sand_White"
    },
    {
      "x": -26,
      "y": 2,
      "z": 2,
      "name": "Rock_Stone"
    },
    {
      "x": -26,
      "y": 3,
      "z": 2,
      "name": "Rock_Stone"
    },
    {
      "x": -26,
      "y": 4,
      "z": 2,
      "name": "Rock_Stone"
    },
    {
      "x": -26,
      "y": 5,
      "z": 2,
      "name": "Rock_Stone"
    },
    {
      "x": -26,
      "y": 6,
      "z": 2,
      "name": "Soil_Gravel_Sand_White"
    },
    {
      "x": -26,
      "y": 2,
      "z": 3,
      "name": "Rock_Stone"
    },
    {
      "x": -26,
      "y": 3,
      "z": 3,
      "name": "Rock_Stone"
    },
    {
      "x": -26,
      "y": 4,
      "z": 3,
      "name": "Rock_Stone"
    },
    {
      "x": -26,
      "y": 5,
      "z": 3,
      "name": "Rock_Stone"
    },
    {
      "x": -26,
      "y": 6,
      "z": 3,
      "name": "Soil_Gravel_Sand_White"
    },
    {
      "x": -26,
      "y": 2,
      "z": 4,
      "name": "Rock_Stone"
    },
    {
      "x": -26,
      "y": 3,
      "z": 4,
      "name": "Rock_Stone"
    },
    {
      "x": -26,
      "y": 4,
      "z": 4,
      "name": "Rock_Stone"
    },
    {
      "x": -26,
      "y": 5,
      "z": 4,
      "name": "Rock_Stone"
    },
    {
      "x": -26,
      "y": 6,
      "z": 4,
      "name": "Soil_Gravel_Sand_White"
    },
    {
      "x": -26,
      "y": 2,
      "z": 5,
      "name": "Rock_Stone"
    },
    {
      "x": -26,
      "y": 3,
      "z": 5,
      "name": "Rock_Stone"
    },
    {
      "x": -26,
      "y": 4,
      "z": 5,
      "name": "Rock_Stone"
    },
    {
      "x": -26,
      "y": 5,
      "z": 5,
      "name": "Rock_Stone"
    },
    {
      "x": -26,
      "y": 6,
      "z": 5,
      "name": "Soil_Gravel_Sand_White"
    },
    {
      "x": -26,
      "y": 2,
      "z": 6,
      "name": "Rock_Stone"
    },
    {
      "x": -26,
      "y": 3,
      "z": 6,
      "name": "Rock_Stone"
    },
    {
      "x": -26,
      "y": 4,
      "z": 6,
      "name": "Rock_Stone"
    },
    {
      "x": -26,
      "y": 5,
      "z": 6,
      "name": "Rock_Stone"
    },
    {
      "x": -26,
      "y": 6,
      "z": 6,
      "name": "Soil_Gravel_Sand_White"
    },
    {
      "x": -26,
      "y": 2,
      "z": 7,
      "name": "Rock_Stone"
    },
    {
      "x": -26,
      "y": 3,
      "z": 7,
      "name": "Rock_Stone"
    },
    {
      "x": -26,
      "y": 4,
      "z": 7,
      "name": "Rock_Stone"
    },
    {
      "x": -26,
      "y": 5,
      "z": 7,
      "name": "Rock_Stone"
    },
    {
      "x": -26,
      "y": 6,
      "z": 7,
      "name": "Soil_Gravel_Sand_White"
    },
    {
      "x": -26,
      "y": 2,
      "z": 8,
      "name": "Rock_Stone"
    },
    {
      "x": -26,
      "y": 3,
      "z": 8,
      "name": "Rock_Stone"
    },
    {
      "x": -26,
      "y": 4,
      "z": 8,
      "name": "Rock_Stone"
    },
    {
      "x": -26,
      "y": 5,
      "z": 8,
      "name": "Rock_Stone"
    },
    {
      "x": -26,
      "y": 6,
      "z": 8,
      "name": "Soil_Gravel_Sand_White"
    },
    {
      "x": -26,
      "y": 2,
      "z": 9,
      "name": "Rock_Stone"
    },
    {
      "x": -26,
      "y": 3,
      "z": 9,
      "name": "Rock_Stone"
    },
    {
      "x": -26,
      "y": 4,
      "z": 9,
      "name": "Rock_Stone"
    },
    {
      "x": -26,
      "y": 5,
      "z": 9,
      "name": "Rock_Stone"
    },
    {
      "x": -26,
      "y": 6,
      "z": 9,
      "name": "Soil_Gravel_Sand_White"
    },
    {
      "x": -26,
      "y": 2,
      "z": 10,
      "name": "Rock_Stone"
    },
    {
      "x": -26,
      "y": 3,
      "z": 10,
      "name": "Rock_Stone"
    },
    {
      "x": -26,
      "y": 4,
      "z": 10,
      "name": "Rock_Stone"
    },
    {
      "x": -26,
      "y": 5,
      "z": 10,
      "name": "Rock_Stone"
    },
    {
      "x": -26,
      "y": 6,
      "z": 10,
      "name": "Soil_Gravel_Sand_White"
    },
    {
      "x": -26,
      "y": 2,
      "z": 11,
      "name": "Rock_Stone"
    },
    {
      "x": -26,
      "y": 3,
      "z": 11,
      "name": "Rock_Stone"
    },
    {
      "x": -26,
      "y": 4,
      "z": 11,
      "name": "Rock_Stone"
    },
    {
      "x": -26,
      "y": 5,
      "z": 11,
      "name": "Rock_Stone"
    },
    {
      "x": -26,
      "y": 6,
      "z": 11,
      "name": "Soil_Gravel_Sand_White"
    },
    {
      "x": -26,
      "y": 2,
      "z": 12,
      "name": "Rock_Stone"
    },
    {
      "x": -26,
      "y": 3,
      "z": 12,
      "name": "Rock_Stone"
    },
    {
      "x": -26,
      "y": 4,
      "z": 12,
      "name": "Rock_Stone"
    },
    {
      "x": -26,
      "y": 5,
      "z": 12,
      "name": "Rock_Stone"
    },
    {
      "x": -26,
      "y": 6,
      "z": 12,
      "name": "Soil_Gravel_Sand_White"
    },
    {
      "x": -26,
      "y": 2,
      "z": 13,
      "name": "Rock_Sandstone_Brick"
    },
    {
      "x": -26,
      "y": 3,
      "z": 13,
      "name": "Rock_Sandstone_Brick"
    },
    {
      "x": -26,
      "y": 4,
      "z": 13,
      "name": "Rock_Sandstone_Red_Cobble"
    },
    {
      "x": -26,
      "y": 5,
      "z": 13,
      "name": "Rock_Sandstone_Brick"
    },
    {
      "x": -26,
      "y": 6,
      "z": 13,
      "name": "Rock_Sandstone_Red_Cobble"
    },
    {
      "x": -26,
      "y": 2,
      "z": 14,
      "name": "Rock_Sandstone_Brick"
    },
    {
      "x": -26,
      "y": 3,
      "z": 14,
      "name": "Rock_Sandstone_Brick"
    },
    {
      "x": -26,
      "y": 4,
      "z": 14,
      "name": "Rock_Sandstone_Red_Cobble"
    },
    {
      "x": -26,
      "y": 5,
      "z": 14,
      "name": "Rock_Sandstone_Brick"
    },
    {
      "x": -26,
      "y": 6,
      "z": 14,
      "name": "Rock_Sandstone_Red_Cobble"
    },
    {
      "x": -26,
      "y": 2,
      "z": 15,
      "name": "Rock_Stone"
    },
    {
      "x": -26,
      "y": 3,
      "z": 15,
      "name": "Rock_Stone"
    },
    {
      "x": -26,
      "y": 4,
      "z": 15,
      "name": "Soil_Gravel_Sand_White"
    },
    {
      "x": -26,
      "y": 5,
      "z": 15,
      "name": "Soil_Gravel_Sand_White"
    },
    {
      "x": -26,
      "y": 2,
      "z": 16,
      "name": "Rock_Stone"
    },
    {
      "x": -26,
      "y": 3,
      "z": 16,
      "name": "Rock_Stone"
    },
    {
      "x": -26,
      "y": 4,
      "z": 16,
      "name": "Soil_Gravel_Sand_White"
    },
    {
      "x": -26,
      "y": 5,
      "z": 16,
      "name": "Soil_Gravel_Sand_White"
    },
    {
      "x": -26,
      "y": 2,
      "z": 17,
      "name": "Rock_Stone"
    },
    {
      "x": -26,
      "y": 3,
      "z": 17,
      "name": "Rock_Stone"
    },
    {
      "x": -26,
      "y": 4,
      "z": 17,
      "name": "Soil_Gravel_Sand_White"
    },
    {
      "x": -26,
      "y": 2,
      "z": 18,
      "name": "Rock_Stone"
    },
    {
      "x": -26,
      "y": 3,
      "z": 18,
      "name": "Rock_Stone"
    },
    {
      "x": -26,
      "y": 4,
      "z": 18,
      "name": "Soil_Gravel_Sand_White"
    },
    {
      "x": -26,
      "y": 2,
      "z": 19,
      "name": "Rock_Stone"
    },
    {
      "x": -26,
      "y": 3,
      "z": 19,
      "name": "Rock_Stone"
    },
    {
      "x": -26,
      "y": 4,
      "z": 19,
      "name": "Soil_Gravel_Sand_White"
    },
    {
      "x": -26,
      "y": 2,
      "z": 20,
      "name": "Rock_Stone"
    },
    {
      "x": -26,
      "y": 3,
      "z": 20,
      "name": "Rock_Stone"
    },
    {
      "x": -26,
      "y": 4,
      "z": 20,
      "name": "Soil_Gravel_Sand_White"
    },
    {
      "x": -26,
      "y": 2,
      "z": 21,
      "name": "Rock_Sandstone_Brick"
    },
    {
      "x": -26,
      "y": 3,
      "z": 21,
      "name": "Rock_Sandstone_Brick"
    },
    {
      "x": -26,
      "y": 4,
      "z": 21,
      "name": "Rock_Sandstone_Red_Cobble"
    },
    {
      "x": -25,
      "y": 2,
      "z": -20,
      "name": "Rock_Sandstone_Brick"
    },
    {
      "x": -25,
      "y": 3,
      "z": -20,
      "name": "Rock_Sandstone_Brick"
    },
    {
      "x": -25,
      "y": 4,
      "z": -20,
      "name": "Rock_Sandstone_Red_Cobble"
    },
    {
      "x": -25,
      "y": 2,
      "z": -19,
      "name": "Rock_Stone"
    },
    {
      "x": -25,
      "y": 3,
      "z": -19,
      "name": "Rock_Stone"
    },
    {
      "x": -25,
      "y": 4,
      "z": -19,
      "name": "Soil_Gravel_Sand_White"
    },
    {
      "x": -25,
      "y": 2,
      "z": -18,
      "name": "Rock_Stone"
    },
    {
      "x": -25,
      "y": 3,
      "z": -18,
      "name": "Rock_Stone"
    },
    {
      "x": -25,
      "y": 4,
      "z": -18,
      "name": "Rock_Stone"
    },
    {
      "x": -25,
      "y": 5,
      "z": -18,
      "name": "Plant_Coral_Block_Purple"
    },
    {
      "x": -25,
      "y": 2,
      "z": -17,
      "name": "Rock_Stone"
    },
    {
      "x": -25,
      "y": 3,
      "z": -17,
      "name": "Rock_Stone"
    },
    {
      "x": -25,
      "y": 4,
      "z": -17,
      "name": "Rock_Stone"
    },
    {
      "x": -25,
      "y": 5,
      "z": -17,
      "name": "Plant_Coral_Block_Purple"
    },
    {
      "x": -25,
      "y": 6,
      "z": -17,
      "name": "Plant_Coral_Block_Purple"
    },
    {
      "x": -25,
      "y": 2,
      "z": -16,
      "name": "Rock_Stone"
    },
    {
      "x": -25,
      "y": 3,
      "z": -16,
      "name": "Rock_Stone"
    },
    {
      "x": -25,
      "y": 4,
      "z": -16,
      "name": "Rock_Stone"
    },
    {
      "x": -25,
      "y": 5,
      "z": -16,
      "name": "Plant_Coral_Block_Purple"
    },
    {
      "x": -25,
      "y": 6,
      "z": -16,
      "name": "Plant_Coral_Block_Purple"
    },
    {
      "x": -25,
      "y": 7,
      "z": -16,
      "name": "Plant_Coral_Block_Purple"
    },
    {
      "x": -25,
      "y": 8,
      "z": -16,
      "name": "Plant_Coral_Model_Violet"
    },
    {
      "x": -25,
      "y": 2,
      "z": -15,
      "name": "Rock_Stone"
    },
    {
      "x": -25,
      "y": 3,
      "z": -15,
      "name": "Rock_Stone"
    },
    {
      "x": -25,
      "y": 4,
      "z": -15,
      "name": "Rock_Stone"
    },
    {
      "x": -25,
      "y": 5,
      "z": -15,
      "name": "Plant_Coral_Block_Purple"
    },
    {
      "x": -25,
      "y": 6,
      "z": -15,
      "name": "Plant_Coral_Block_Purple"
    },
    {
      "x": -25,
      "y": 7,
      "z": -15,
      "name": "Plant_Coral_Block_Purple"
    },
    {
      "x": -25,
      "y": 8,
      "z": -15,
      "name": "Plant_Coral_Model_Violet"
    },
    {
      "x": -25,
      "y": 2,
      "z": -14,
      "name": "Rock_Sandstone_Brick"
    },
    {
      "x": -25,
      "y": 3,
      "z": -14,
      "name": "Rock_Sandstone_Brick"
    },
    {
      "x": -25,
      "y": 4,
      "z": -14,
      "name": "Rock_Sandstone_Red_Cobble"
    },
    {
      "x": -25,
      "y": 5,
      "z": -14,
      "name": "Rock_Sandstone_Brick"
    },
    {
      "x": -25,
      "y": 6,
      "z": -14,
      "name": "Rock_Sandstone_Red_Cobble"
    },
    {
      "x": -25,
      "y": 7,
      "z": -14,
      "name": "Plant_Coral_Block_Purple"
    },
    {
      "x": -25,
      "y": 2,
      "z": -13,
      "name": "Rock_Sandstone_Brick"
    },
    {
      "x": -25,
      "y": 3,
      "z": -13,
      "name": "Rock_Sandstone_Brick"
    },
    {
      "x": -25,
      "y": 4,
      "z": -13,
      "name": "Rock_Sandstone_Red_Cobble"
    },
    {
      "x": -25,
      "y": 5,
      "z": -13,
      "name": "Rock_Sandstone_Brick"
    },
    {
      "x": -25,
      "y": 6,
      "z": -13,
      "name": "Rock_Sandstone_Red_Cobble"
    },
    {
      "x": -25,
      "y": 2,
      "z": -12,
      "name": "Rock_Stone"
    },
    {
      "x": -25,
      "y": 3,
      "z": -12,
      "name": "Rock_Stone"
    },
    {
      "x": -25,
      "y": 4,
      "z": -12,
      "name": "Rock_Stone"
    },
    {
      "x": -25,
      "y": 5,
      "z": -12,
      "name": "Rock_Stone"
    },
    {
      "x": -25,
      "y": 6,
      "z": -12,
      "name": "Soil_Gravel_Sand_White"
    },
    {
      "x": -25,
      "y": 2,
      "z": -11,
      "name": "Rock_Stone"
    },
    {
      "x": -25,
      "y": 3,
      "z": -11,
      "name": "Rock_Stone"
    },
    {
      "x": -25,
      "y": 4,
      "z": -11,
      "name": "Rock_Stone"
    },
    {
      "x": -25,
      "y": 5,
      "z": -11,
      "name": "Rock_Stone"
    },
    {
      "x": -25,
      "y": 6,
      "z": -11,
      "name": "Soil_Gravel_Sand_White"
    },
    {
      "x": -25,
      "y": 2,
      "z": -10,
      "name": "Rock_Stone"
    },
    {
      "x": -25,
      "y": 3,
      "z": -10,
      "name": "Rock_Stone"
    },
    {
      "x": -25,
      "y": 4,
      "z": -10,
      "name": "Rock_Stone"
    },
    {
      "x": -25,
      "y": 5,
      "z": -10,
      "name": "Rock_Stone"
    },
    {
      "x": -25,
      "y": 6,
      "z": -10,
      "name": "Soil_Gravel_Sand_White"
    },
    {
      "x": -25,
      "y": 2,
      "z": -9,
      "name": "Rock_Stone"
    },
    {
      "x": -25,
      "y": 3,
      "z": -9,
      "name": "Rock_Stone"
    },
    {
      "x": -25,
      "y": 4,
      "z": -9,
      "name": "Rock_Stone"
    },
    {
      "x": -25,
      "y": 5,
      "z": -9,
      "name": "Rock_Stone"
    },
    {
      "x": -25,
      "y": 6,
      "z": -9,
      "name": "Soil_Gravel_Sand_White"
    },
    {
      "x": -25,
      "y": 2,
      "z": -8,
      "name": "Rock_Stone"
    },
    {
      "x": -25,
      "y": 3,
      "z": -8,
      "name": "Rock_Stone"
    },
    {
      "x": -25,
      "y": 4,
      "z": -8,
      "name": "Rock_Stone"
    },
    {
      "x": -25,
      "y": 5,
      "z": -8,
      "name": "Rock_Stone"
    },
    {
      "x": -25,
      "y": 6,
      "z": -8,
      "name": "Soil_Gravel_Sand_White"
    },
    {
      "x": -25,
      "y": 2,
      "z": -7,
      "name": "Rock_Stone"
    },
    {
      "x": -25,
      "y": 3,
      "z": -7,
      "name": "Rock_Stone"
    },
    {
      "x": -25,
      "y": 4,
      "z": -7,
      "name": "Rock_Stone"
    },
    {
      "x": -25,
      "y": 5,
      "z": -7,
      "name": "Rock_Stone"
    },
    {
      "x": -25,
      "y": 6,
      "z": -7,
      "name": "Soil_Gravel_Sand_White"
    },
    {
      "x": -25,
      "y": 2,
      "z": -6,
      "name": "Rock_Stone"
    },
    {
      "x": -25,
      "y": 3,
      "z": -6,
      "name": "Rock_Stone"
    },
    {
      "x": -25,
      "y": 4,
      "z": -6,
      "name": "Rock_Stone"
    },
    {
      "x": -25,
      "y": 5,
      "z": -6,
      "name": "Rock_Stone"
    },
    {
      "x": -25,
      "y": 6,
      "z": -6,
      "name": "Soil_Gravel_Sand_White"
    },
    {
      "x": -25,
      "y": 2,
      "z": -5,
      "name": "Rock_Stone"
    },
    {
      "x": -25,
      "y": 3,
      "z": -5,
      "name": "Rock_Stone"
    },
    {
      "x": -25,
      "y": 4,
      "z": -5,
      "name": "Rock_Stone"
    },
    {
      "x": -25,
      "y": 5,
      "z": -5,
      "name": "Rock_Stone"
    },
    {
      "x": -25,
      "y": 6,
      "z": -5,
      "name": "Soil_Gravel_Sand_White"
    },
    {
      "x": -25,
      "y": 2,
      "z": -4,
      "name": "Rock_Stone"
    },
    {
      "x": -25,
      "y": 3,
      "z": -4,
      "name": "Rock_Stone"
    },
    {
      "x": -25,
      "y": 4,
      "z": -4,
      "name": "Rock_Stone"
    },
    {
      "x": -25,
      "y": 5,
      "z": -4,
      "name": "Rock_Stone"
    },
    {
      "x": -25,
      "y": 6,
      "z": -4,
      "name": "Soil_Gravel_Sand_White"
    },
    {
      "x": -25,
      "y": 2,
      "z": -3,
      "name": "Rock_Sandstone_Brick"
    },
    {
      "x": -25,
      "y": 3,
      "z": -3,
      "name": "Rock_Sandstone_Brick"
    },
    {
      "x": -25,
      "y": 4,
      "z": -3,
      "name": "Rock_Sandstone_Red_Cobble"
    },
    {
      "x": -25,
      "y": 5,
      "z": -3,
      "name": "Rock_Sandstone_Brick"
    },
    {
      "x": -25,
      "y": 6,
