{
  "version": 8,
  "blockIdVersion": 8,
  "anchorX": 5,
  "anchorY": 8,
  "anchorZ": -1,
  "blocks": [
    {
      "x": 1,
      "y": 8,
      "z": -2,
      "name": "Rock_Slate"
    },
    {
      "x": 1,
      "y": 7,
      "z": -1,
      "name": "Rock_Slate"
    },
    {
      "x": 1,
      "y": 8,
      "z": -1,
      "name": "Rock_Slate"
    },
    {
      "x": 1,
      "y": 7,
      "z": 0,
      "name": "Rock_Slate"
    },
    {
      "x": 1,
      "y": 8,
      "z": 0,
      "name": "Rock_Slate"
    },
    {
      "x": 1,
      "y": 7,
      "z": 1,
      "name": "Rock_Slate"
    },
    {
      "x": 2,
      "y": 8,
      "z": -3,
      "name": "Rock_Slate"
    },
    {
      "x": 2,
      "y": 7,
      "z": -2,
      "name": "Rock_Slate"
    },
    {
      "x": 2,
      "y": 8,
      "z": -2,
      "name": "Rock_Slate"
    },
    {
      "x": 2,
      "y": 9,
      "z": -2,
      "name": "Rock_Slate"
    },
    {
      "x": 2,
      "y": 6,
      "z": -1,
      "name": "Rock_Slate"
    },
    {
      "x": 2,
      "y": 7,
      "z": -1,
      "name": "Rock_Slate"
    },
    {
      "x": 2,
      "y": 8,
      "z": -1,
      "name": "Rock_Slate"
    },
    {
      "x": 2,
      "y": 9,
      "z": -1,
      "name": "Rock_Slate"
    },
    {
      "x": 2,
      "y": 10,
      "z": -1,
      "name": "Rock_Slate"
    },
    {
      "x": 2,
      "y": 6,
      "z": 0,
      "name": "Rock_Slate"
    },
    {
      "x": 2,
      "y": 7,
      "z": 0,
      "name": "Rock_Slate"
    },
    {
      "x": 2,
      "y": 8,
      "z": 0,
      "name": "Rock_Slate"
    },
    {
      "x": 2,
      "y": 9,
      "z": 0,
      "name": "Rock_Slate"
    },
    {
      "x": 2,
      "y": 10,
      "z": 0,
      "name": "Rock_Slate"
    },
    {
      "x": 2,
      "y": 7,
      "z": 1,
      "name": "Rock_Slate"
    },
    {
      "x": 2,
      "y": 8,
      "z": 1,
      "name": "Rock_Slate"
    },
    {
      "x": 2,
      "y": 9,
      "z": 1,
      "name": "Rock_Slate"
    },
    {
      "x": 2,
      "y": 10,
      "z": 1,
      "name": "Rock_Slate"
    },
    {
      "x": 2,
      "y": 11,
      "z": 1,
      "name": "Rock_Stone_Cobble"
    },
    {
      "x": 2,
      "y": 7,
      "z": 2,
      "name": "Rock_Slate"
    },
    {
      "x": 2,
      "y": 8,
      "z": 2,
      "name": "Rock_Slate"
    },
    {
      "x": 2,
      "y": 9,
      "z": 2,
      "name": "Rock_Slate"
    },
    {
      "x": 2,
      "y": 10,
      "z": 2,
      "name": "Rock_Stone_Cobble"
    },
    {
      "x": 2,
      "y": 11,
      "z": 2,
      "name": "Rock_Stone_Cobble"
    },
    {
      "x": 2,
      "y": 10,
      "z": 3,
      "name": "Rock_Stone_Cobble_Half",
      "rotation": 7
    },
    {
      "x": 2,
      "y": 11,
      "z": 3,
      "name": "Rock_Stone_Cobble_Half",
      "rotation": 7
    },
    {
      "x": 3,
      "y": 7,
      "z": -3,
      "name": "Rock_Slate"
    },
    {
      "x": 3,
      "y": 8,
      "z": -3,
      "name": "Rock_Slate"
    },
    {
      "x": 3,
      "y": 9,
      "z": -3,
      "name": "Rock_Slate"
    },
    {
      "x": 3,
      "y": 6,
      "z": -2,
      "name": "Rock_Slate"
    },
    {
      "x": 3,
      "y": 7,
      "z": -2,
      "name": "Rock_Slate"
    },
    {
      "x": 3,
      "y": 8,
      "z": -2,
      "name": "Rock_Slate"
    },
    {
      "x": 3,
      "y": 9,
      "z": -2,
      "name": "Rock_Slate"
    },
    {
      "x": 3,
      "y": 10,
      "z": -2,
      "name": "Rock_Slate"
    },
    {
      "x": 3,
      "y": 6,
      "z": -1,
      "name": "Rock_Slate"
    },
    {
      "x": 3,
      "y": 7,
      "z": -1,
      "name": "Rock_Slate"
    },
    {
      "x": 3,
      "y": 8,
      "z": -1,
      "name": "Rock_Slate"
    },
    {
      "x": 3,
      "y": 9,
      "z": -1,
      "name": "Rock_Slate"
    },
    {
      "x": 3,
      "y": 10,
      "z": -1,
      "name": "Rock_Slate"
    },
    {
      "x": 3,
      "y": 6,
      "z": 0,
      "name": "Rock_Slate"
    },
    {
      "x": 3,
      "y": 7,
      "z": 0,
      "name": "Rock_Slate"
    },
    {
      "x": 3,
      "y": 8,
      "z": 0,
      "name": "Rock_Slate"
    },
    {
      "x": 3,
      "y": 9,
      "z": 0,
      "name": "Rock_Slate"
    },
    {
      "x": 3,
      "y": 10,
      "z": 0,
      "name": "Rock_Slate"
    },
    {
      "x": 3,
      "y": 6,
      "z": 1,
      "name": "Rock_Slate"
    },
    {
      "x": 3,
      "y": 7,
      "z": 1,
      "name": "Rock_Slate"
    },
    {
      "x": 3,
      "y": 8,
      "z": 1,
      "name": "Rock_Slate"
    },
    {
      "x": 3,
      "y": 9,
      "z": 1,
      "name": "Rock_Slate"
    },
    {
      "x": 3,
      "y": 10,
      "z": 1,
      "name": "Rock_Slate"
    },
    {
      "x": 3,
      "y": 6,
      "z": 2,
      "name": "Rock_Slate"
    },
    {
      "x": 3,
      "y": 7,
      "z": 2,
      "name": "Rock_Slate"
    },
    {
      "x": 3,
      "y": 8,
      "z": 2,
      "name": "Rock_Slate"
    },
    {
      "x": 3,
      "y": 9,
      "z": 2,
      "name": "Rock_Slate"
    },
    {
      "x": 3,
      "y": 10,
      "z": 2,
      "name": "Rock_Slate"
    },
    {
      "x": 3,
      "y": 11,
      "z": 2,
      "name": "Furniture_Ancient_Barrel"
    },
    {
      "x": 3,
      "y": 7,
      "z": 3,
      "name": "Rock_Slate"
    },
    {
      "x": 3,
      "y": 8,
      "z": 3,
      "name": "Rock_Slate"
    },
    {
      "x": 3,
      "y": 9,
      "z": 3,
      "name": "Rock_Stone_Cobble"
    },
    {
      "x": 3,
      "y": 10,
      "z": 3,
      "name": "Rock_Stone_Cobble"
    },
    {
      "x": 3,
      "y": 11,
      "z": 3,
      "name": "Rock_Stone_Cobble"
    },
    {
      "x": 3,
      "y": 12,
      "z": 3,
      "name": "Rubble_Stone"
    },
    {
      "x": 4,
      "y": 7,
      "z": -4,
      "name": "Rock_Slate"
    },
    {
      "x": 4,
      "y": 8,
      "z": -4,
      "name": "Rock_Slate"
    },
    {
      "x": 4,
      "y": 9,
      "z": -4,
      "name": "Rock_Slate"
    },
    {
      "x": 4,
      "y": 10,
      "z": -4,
      "name": "Rock_Stone_Cobble"
    },
    {
      "x": 4,
      "y": 7,
      "z": -3,
      "name": "Rock_Slate"
    },
    {
      "x": 4,
      "y": 8,
      "z": -3,
      "name": "Rock_Slate"
    },
    {
      "x": 4,
      "y": 9,
      "z": -3,
      "name": "Rock_Slate"
    },
    {
      "x": 4,
      "y": 10,
      "z": -3,
      "name": "Rock_Slate"
    },
    {
      "x": 4,
      "y": 11,
      "z": -3,
      "name": "Furniture_Ancient_Barrel"
    },
    {
      "x": 4,
      "y": 6,
      "z": -2,
      "name": "Rock_Slate"
    },
    {
      "x": 4,
      "y": 7,
      "z": -2,
      "name": "Rock_Slate"
    },
    {
      "x": 4,
      "y": 8,
      "z": -2,
      "name": "Rock_Slate"
    },
    {
      "x": 4,
      "y": 9,
      "z": -2,
      "name": "Rock_Slate"
    },
    {
      "x": 4,
      "y": 10,
      "z": -2,
      "name": "Rock_Slate"
    },
    {
      "x": 4,
      "y": 6,
      "z": -1,
      "name": "Rock_Slate"
    },
    {
      "x": 4,
      "y": 7,
      "z": -1,
      "name": "Rock_Slate"
    },
    {
      "x": 4,
      "y": 8,
      "z": -1,
      "name": "Rock_Slate"
    },
    {
      "x": 4,
      "y": 9,
      "z": -1,
      "name": "Rock_Slate"
    },
    {
      "x": 4,
      "y": 10,
      "z": -1,
      "name": "Rock_Slate"
    },
    {
      "x": 4,
      "y": 11,
      "z": -1,
      "name": "Rock_Slate"
    },
    {
      "x": 4,
      "y": 6,
      "z": 0,
      "name": "Rock_Slate"
    },
    {
      "x": 4,
      "y": 7,
      "z": 0,
      "name": "Rock_Slate"
    },
    {
      "x": 4,
      "y": 8,
      "z": 0,
      "name": "Rock_Slate"
    },
    {
      "x": 4,
      "y": 9,
      "z": 0,
      "name": "Rock_Slate"
    },
    {
      "x": 4,
      "y": 10,
      "z": 0,
      "name": "Rock_Slate"
    },
    {
      "x": 4,
      "y": 11,
      "z": 0,
      "name": "Rock_Slate"
    },
    {
      "x": 4,
      "y": 6,
      "z": 1,
      "name": "Rock_Slate"
    },
    {
      "x": 4,
      "y": 7,
      "z": 1,
      "name": "Rock_Slate"
    },
    {
      "x": 4,
      "y": 8,
      "z": 1,
      "name": "Rock_Slate"
    },
    {
      "x": 4,
      "y": 9,
      "z": 1,
      "name": "Rock_Slate"
    },
    {
      "x": 4,
      "y": 10,
      "z": 1,
      "name": "Rock_Slate"
    },
    {
      "x": 4,
      "y": 11,
      "z": 1,
      "name": "Rock_Slate"
    },
    {
      "x": 4,
      "y": 6,
      "z": 2,
      "name": "Rock_Slate"
    },
    {
      "x": 4,
      "y": 7,
      "z": 2,
      "name": "Rock_Slate"
    },
    {
      "x": 4,
      "y": 8,
      "z": 2,
      "name": "Rock_Slate"
    },
    {
      "x": 4,
      "y": 9,
      "z": 2,
      "name": "Rock_Slate"
    },
    {
      "x": 4,
      "y": 10,
      "z": 2,
      "name": "Rock_Slate"
    },
    {
      "x": 4,
      "y": 7,
      "z": 3,
      "name": "Rock_Slate"
    },
    {
      "x": 4,
      "y": 8,
      "z": 3,
      "name": "Rock_Slate"
    },
    {
      "x": 4,
      "y": 9,
      "z": 3,
      "name": "Rock_Slate"
    },
    {
      "x": 4,
      "y": 10,
      "z": 3,
      "name": "Rock_Stone_Cobble"
    },
    {
      "x": 4,
      "y": 11,
      "z": 3,
      "name": "Rock_Stone_Cobble"
    },
    {
      "x": 4,
      "y": 12,
      "z": 3,
      "name": "Rock_Stone_Cobble"
    },
    {
      "x": 5,
      "y": 7,
      "z": -4,
      "name": "Rock_Slate"
    },
    {
      "x": 5,
      "y": 8,
      "z": -4,
      "name": "Rock_Slate"
    },
    {
      "x": 5,
      "y": 9,
      "z": -4,
      "name": "Rock_Slate"
    },
    {
      "x": 5,
      "y": 10,
      "z": -4,
      "name": "Rock_Stone_Cobble"
    },
    {
      "x": 5,
      "y": 11,
      "z": -4,
      "name": "Rock_Stone_Cobble_Half",
      "rotation": 7
    },
    {
      "x": 5,
      "y": 6,
      "z": -3,
      "name": "Rock_Slate"
    },
    {
      "x": 5,
      "y": 7,
      "z": -3,
      "name": "Rock_Slate"
    },
    {
      "x": 5,
      "y": 8,
      "z": -3,
      "name": "Rock_Slate"
    },
    {
      "x": 5,
      "y": 9,
      "z": -3,
      "name": "Rock_Slate"
    },
    {
      "x": 5,
      "y": 10,
      "z": -3,
      "name": "Rock_Slate"
    },
    {
      "x": 5,
      "y": 11,
      "z": -3,
      "name": "Furniture_Ancient_Crate",
      "rotation": 3
    },
    {
      "x": 5,
      "y": 6,
      "z": -2,
      "name": "Rock_Slate"
    },
    {
      "x": 5,
      "y": 7,
      "z": -2,
      "name": "Rock_Slate"
    },
    {
      "x": 5,
      "y": 8,
      "z": -2,
      "name": "Rock_Slate"
    },
    {
      "x": 5,
      "y": 9,
      "z": -2,
      "name": "Rock_Slate"
    },
    {
      "x": 5,
      "y": 10,
      "z": -2,
      "name": "Rock_Slate"
    },
    {
      "x": 5,
      "y": 11,
      "z": -2,
      "name": "Rock_Slate"
    },
    {
      "x": 5,
      "y": 6,
      "z": -1,
      "name": "Rock_Slate"
    },
    {
      "x": 5,
      "y": 7,
      "z": -1,
      "name": "Rock_Slate"
    },
    {
      "x": 5,
      "y": 8,
      "z": -1,
      "name": "Rock_Slate"
    },
    {
      "x": 5,
      "y": 9,
      "z": -1,
      "name": "Rock_Slate"
    },
    {
      "x": 5,
      "y": 10,
      "z": -1,
      "name": "Rock_Slate"
    },
    {
      "x": 5,
      "y": 11,
      "z": -1,
      "name": "Rock_Slate"
    },
    {
      "x": 5,
      "y": 6,
      "z": 0,
      "name": "Rock_Slate"
    },
    {
      "x": 5,
      "y": 7,
      "z": 0,
      "name": "Rock_Slate"
    },
    {
      "x": 5,
      "y": 8,
      "z": 0,
      "name": "Rock_Slate"
    },
    {
      "x": 5,
      "y": 9,
      "z": 0,
      "name": "Rock_Slate"
    },
    {
      "x": 5,
      "y": 10,
      "z": 0,
      "name": "Rock_Slate"
    },
    {
      "x": 5,
      "y": 11,
      "z": 0,
      "name": "Rock_Slate"
    },
    {
      "x": 5,
      "y": 6,
      "z": 1,
      "name": "Rock_Slate"
    },
    {
      "x": 5,
      "y": 7,
      "z": 1,
      "name": "Rock_Slate"
    },
    {
      "x": 5,
      "y": 8,
      "z": 1,
      "name": "Rock_Slate"
    },
    {
      "x": 5,
      "y": 9,
      "z": 1,
      "name": "Rock_Slate"
    },
    {
      "x": 5,
      "y": 10,
      "z": 1,
      "name": "Rock_Slate"
    },
    {
      "x": 5,
      "y": 11,
      "z": 1,
      "name": "Rock_Slate"
    },
    {
      "x": 5,
      "y": 6,
      "z": 2,
      "name": "Rock_Slate"
    },
    {
      "x": 5,
      "y": 7,
      "z": 2,
      "name": "Rock_Slate"
    },
    {
      "x": 5,
      "y": 8,
      "z": 2,
      "name": "Rock_Slate"
    },
    {
      "x": 5,
      "y": 9,
      "z": 2,
      "name": "Rock_Slate"
    },
    {
      "x": 5,
      "y": 10,
      "z": 2,
      "name": "Rock_Slate"
    },
    {
      "x": 5,
      "y": 7,
      "z": 3,
      "name": "Rock_Slate"
    },
    {
      "x": 5,
      "y": 8,
      "z": 3,
      "name": "Rock_Slate"
    },
    {
      "x": 5,
      "y": 9,
      "z": 3,
      "name": "Rock_Slate"
    },
    {
      "x": 5,
      "y": 10,
      "z": 3,
      "name": "Rock_Stone_Cobble"
    },
    {
      "x": 5,
      "y": 11,
      "z": 3,
      "name": "Rock_Stone_Cobble_Half",
      "rotation": 5
    },
    {
      "x": 5,
      "y": 12,
      "z": 3,
      "name": "Rock_Stone_Cobble_Half",
      "rotation": 5
    },
    {
      "x": 6,
      "y": 7,
      "z": -4,
      "name": "Rock_Slate"
    },
    {
      "x": 6,
      "y": 8,
      "z": -4,
      "name": "Rock_Slate"
    },
    {
      "x": 6,
      "y": 9,
      "z": -4,
      "name": "Rock_Stone_Cobble"
    },
    {
      "x": 6,
      "y": 10,
      "z": -4,
      "name": "Rock_Stone_Cobble"
    },
    {
      "x": 6,
      "y": 11,
      "z": -4,
      "name": "Rock_Stone_Cobble"
    },
    {
      "x": 6,
      "y": 6,
      "z": -3,
      "name": "Rock_Slate"
    },
    {
      "x": 6,
      "y": 7,
      "z": -3,
      "name": "Rock_Slate"
    },
    {
      "x": 6,
      "y": 8,
      "z": -3,
      "name": "Rock_Slate"
    },
    {
      "x": 6,
      "y": 9,
      "z": -3,
      "name": "Rock_Slate"
    },
    {
      "x": 6,
      "y": 10,
      "z": -3,
      "name": "Rock_Stone_Cobble"
    },
    {
      "x": 6,
      "y": 11,
      "z": -3,
      "name": "Rock_Stone_Cobble"
    },
    {
      "x": 6,
      "y": 12,
      "z": -3,
      "name": "Rubble_Stone"
    },
    {
      "x": 6,
      "y": 6,
      "z": -2,
      "name": "Rock_Slate"
    },
    {
      "x": 6,
      "y": 7,
      "z": -2,
      "name": "Rock_Slate"
    },
    {
      "x": 6,
      "y": 8,
      "z": -2,
      "name": "Rock_Slate"
    },
    {
      "x": 6,
      "y": 9,
      "z": -2,
      "name": "Rock_Slate"
    },
    {
      "x": 6,
      "y": 10,
      "z": -2,
      "name": "Rock_Slate"
    },
    {
      "x": 6,
      "y": 11,
      "z": -2,
      "name": "Rock_Slate"
    },
    {
      "x": 6,
      "y": 6,
      "z": -1,
      "name": "Rock_Slate"
    },
    {
      "x": 6,
      "y": 7,
      "z": -1,
      "name": "Rock_Slate"
    },
    {
      "x": 6,
      "y": 8,
      "z": -1,
      "name": "Rock_Slate"
    },
    {
      "x": 6,
      "y": 9,
      "z": -1,
      "name": "Rock_Slate"
    },
    {
      "x": 6,
      "y": 10,
      "z": -1,
      "name": "Rock_Slate"
    },
    {
      "x": 6,
      "y": 11,
      "z": -1,
      "name": "Rock_Slate"
    },
    {
      "x": 6,
      "y": 6,
      "z": 0,
      "name": "Rock_Slate"
    },
    {
      "x": 6,
      "y": 7,
      "z": 0,
      "name": "Rock_Slate"
    },
    {
      "x": 6,
      "y": 8,
      "z": 0,
      "name": "Rock_Slate"
    },
    {
      "x": 6,
      "y": 9,
      "z": 0,
      "name": "Rock_Slate"
    },
    {
      "x": 6,
      "y": 10,
      "z": 0,
      "name": "Rock_Slate"
    },
    {
      "x": 6,
      "y": 11,
      "z": 0,
      "name": "Rock_Slate"
    },
    {
      "x": 6,
      "y": 6,
      "z": 1,
      "name": "Rock_Slate"
    },
    {
      "x": 6,
      "y": 7,
      "z": 1,
      "name": "Rock_Slate"
    },
    {
      "x": 6,
      "y": 8,
      "z": 1,
      "name": "Rock_Slate"
    },
    {
      "x": 6,
      "y": 9,
      "z": 1,
      "name": "Rock_Slate"
    },
    {
      "x": 6,
      "y": 10,
      "z": 1,
      "name": "Rock_Slate"
    },
    {
      "x": 6,
      "y": 7,
      "z": 2,
      "name": "Rock_Slate"
    },
    {
      "x": 6,
      "y": 8,
      "z": 2,
      "name": "Rock_Slate"
    },
    {
      "x": 6,
      "y": 9,
      "z": 2,
      "name": "Rock_Slate"
    },
    {
      "x": 6,
      "y": 10,
      "z": 2,
      "name": "Rock_Slate"
    },
    {
      "x": 6,
      "y": 11,
      "z": 2,
      "name": "Rubble_Stone"
    },
    {
      "x": 6,
      "y": 7,
      "z": 3,
      "name": "Rock_Slate"
    },
    {
      "x": 6,
      "y": 8,
      "z": 3,
      "name": "Rock_Slate"
    },
    {
      "x": 6,
      "y": 9,
      "z": 3,
      "name": "Rock_Slate"
    },
    {
      "x": 6,
      "y": 10,
      "z": 3,
      "name": "Rock_Stone_Cobble"
    },
    {
      "x": 6,
      "y": 11,
      "z": 3,
      "name": "Rubble_Stone_Medium"
    },
    {
      "x": 7,
      "y": 7,
      "z": -3,
      "name": "Rock_Slate"
    },
    {
      "x": 7,
      "y": 8,
      "z": -3,
      "name": "Rock_Slate"
    },
    {
      "x": 7,
      "y": 7,
      "z": -2,
      "name": "Rock_Slate"
    },
    {
      "x": 7,
      "y": 8,
      "z": -2,
      "name": "Rock_Slate"
    },
    {
      "x": 7,
      "y": 9,
      "z": -2,
      "name": "Rock_Slate"
    },
    {
      "x": 7,
      "y": 6,
      "z": -1,
      "name": "Rock_Slate"
    },
    {
      "x": 7,
      "y": 7,
      "z": -1,
      "name": "Rock_Slate"
    },
    {
      "x": 7,
      "y": 8,
      "z": -1,
      "name": "Rock_Slate"
    },
    {
      "x": 7,
      "y": 9,
      "z": -1,
      "name": "Rock_Slate"
    },
    {
      "x": 7,
      "y": 10,
      "z": -1,
      "name": "Rock_Slate"
    },
    {
      "x": 7,
      "y": 6,
      "z": 0,
      "name": "Rock_Slate"
    },
    {
      "x": 7,
      "y": 7,
      "z": 0,
      "name": "Rock_Slate"
    },
    {
      "x": 7,
      "y": 8,
      "z": 0,
      "name": "Rock_Slate"
    },
    {
      "x": 7,
      "y": 9,
      "z": 0,
      "name": "Rock_Slate"
    },
    {
      "x": 7,
      "y": 10,
      "z": 0,
      "name": "Rock_Slate"
    },
    {
      "x": 7,
      "y": 6,
      "z": 1,
      "name": "Rock_Slate"
    },
    {
      "x": 7,
      "y": 7,
      "z": 1,
      "name": "Rock_Slate"
    },
    {
      "x": 7,
      "y": 8,
      "z": 1,
      "name": "Rock_Slate"
    },
    {
      "x": 7,
      "y": 9,
      "z": 1,
      "name": "Rock_Slate"
    },
    {
      "x": 7,
      "y": 10,
      "z": 1,
      "name": "Rock_Slate"
    },
    {
      "x": 7,
      "y": 7,
      "z": 2,
      "name": "Rock_Slate"
    },
    {
      "x": 7,
      "y": 8,
      "z": 2,
      "name": "Rock_Slate"
    },
    {
      "x": 7,
      "y": 9,
      "z": 2,
      "name": "Rock_Slate"
    },
    {
      "x": 7,
      "y": 8,
      "z": 3,
      "name": "Rock_Slate"
    },
    {
      "x": 7,
      "y": 9,
      "z": 3,
      "name": "Rock_Slate"
    },
    {
      "x": 8,
      "y": 7,
      "z": -2,
      "name": "Rock_Slate"
    },
    {
      "x": 8,
      "y": 8,
      "z": -2,
      "name": "Rock_Slate"
    },
    {
      "x": 8,
      "y": 7,
      "z": -1,
      "name": "Rock_Slate"
    },
    {
      "x": 8,
      "y": 8,
      "z": -1,
      "name": "Rock_Slate"
    },
    {
      "x": 8,
      "y": 9,
      "z": -1,
      "name": "Rock_Slate"
    },
    {
      "x": 8,
      "y": 7,
      "z": 0,
      "name": "Rock_Slate"
    },
    {
      "x": 8,
      "y": 8,
      "z": 0,
      "name": "Rock_Slate"
    },
    {
      "x": 8,
      "y": 9,
      "z": 0,
      "name": "Rock_Slate"
    },
    {
      "x": 8,
      "y": 7,
      "z": 1,
      "name": "Rock_Slate"
    },
    {
      "x": 8,
      "y": 8,
      "z": 1,
      "name": "Rock_Slate"
    },
    {
      "x": 8,
      "y": 9,
      "z": 1,
      "name": "Rock_Slate"
    },
    {
      "x": 8,
      "y": 8,
      "z": 2,
      "name": "Rock_Slate"
    },
    {
      "x": 8,
      "y": 9,
      "z": 2,
      "name": "Rock_Slate"
    }
  ]
}