{
  "version": 8,
  "blockIdVersion": 8,
  "anchorX": 5,
  "anchorY": 13,
  "anchorZ": 0,
  "blocks": [
    {
      "x": -4,
      "y": 18,
      "z": 1,
      "name": "Deco_Bone_Full"
    },
    {
      "x": -4,
      "y": 19,
      "z": 1,
      "name": "Deco_Bone_Full"
    },
    {
      "x": -4,
      "y": 20,
      "z": 1,
      "name": "Deco_Bone_Full"
    },
    {
      "x": -4,
      "y": 21,
      "z": 1,
      "name": "Deco_Bone_Full"
    },
    {
      "x": -4,
      "y": 22,
      "z": 1,
      "name": "Deco_Bone_Full"
    },
    {
      "x": -4,
      "y": 23,
      "z": 1,
      "name": "Deco_Bone_Full"
    },
    {
      "x": -4,
      "y": 24,
      "z": 1,
      "name": "Deco_Bone_Full"
    },
    {
      "x": -4,
      "y": 18,
      "z": 2,
      "name": "Deco_Bone_Full"
    },
    {
      "x": -3,
      "y": 18,
      "z": 1,
      "name": "Deco_Bone_Full"
    },
    {
      "x": -3,
      "y": 16,
      "z": 2,
      "name": "Deco_Bone_Full"
    },
    {
      "x": -3,
      "y": 17,
      "z": 2,
      "name": "Deco_Bone_Full"
    },
    {
      "x": -3,
      "y": 18,
      "z": 2,
      "name": "Deco_Bone_Full"
    },
    {
      "x": -3,
      "y": 17,
      "z": 3,
      "name": "Deco_Bone_Full"
    },
    {
      "x": -2,
      "y": 17,
      "z": 2,
      "name": "Deco_Bone_Full"
    },
    {
      "x": -2,
      "y": 15,
      "z": 3,
      "name": "Deco_Bone_Full"
    },
    {
      "x": -2,
      "y": 16,
      "z": 3,
      "name": "Deco_Bone_Full"
    },
    {
      "x": -2,
      "y": 17,
      "z": 3,
      "name": "Deco_Bone_Full"
    },
    {
      "x": -2,
      "y": 16,
      "z": 4,
      "name": "Deco_Bone_Full"
    },
    {
      "x": -2,
      "y": 16,
      "z": 5,
      "name": "Deco_Bone_Full"
    },
    {
      "x": -2,
      "y": 16,
      "z": 6,
      "name": "Deco_Bone_Full"
    },
    {
      "x": -1,
      "y": 16,
      "z": 3,
      "name": "Deco_Bone_Full"
    },
    {
      "x": -1,
      "y": 15,
      "z": 4,
      "name": "Deco_Bone_Full"
    },
    {
      "x": -1,
      "y": 16,
      "z": 4,
      "name": "Deco_Bone_Full"
    },
    {
      "x": -1,
      "y": 14,
      "z": 5,
      "name": "Deco_Bone_Full"
    },
    {
      "x": -1,
      "y": 15,
      "z": 5,
      "name": "Deco_Bone_Full"
    },
    {
      "x": -1,
      "y": 16,
      "z": 5,
      "name": "Deco_Bone_Full"
    },
    {
      "x": -1,
      "y": 17,
      "z": 5,
      "name": "Deco_Bone_Full"
    },
    {
      "x": -1,
      "y": 15,
      "z": 6,
      "name": "Deco_Bone_Full"
    },
    {
      "x": -1,
      "y": 16,
      "z": 6,
      "name": "Deco_Bone_Full"
    },
    {
      "x": 0,
      "y": 14,
      "z": 3,
      "name": "Deco_Bone_Full"
    },
    {
      "x": 0,
      "y": 15,
      "z": 3,
      "name": "Deco_Bone_Full"
    },
    {
      "x": 0,
      "y": 16,
      "z": 3,
      "name": "Deco_Bone_Full"
    },
    {
      "x": 0,
      "y": 11,
      "z": 4,
      "name": "Deco_Bone_Full"
    },
    {
      "x": 0,
      "y": 12,
      "z": 4,
      "name": "Deco_Bone_Full"
    },
    {
      "x": 0,
      "y": 13,
      "z": 4,
      "name": "Deco_Bone_Full"
    },
    {
      "x": 0,
      "y": 14,
      "z": 4,
      "name": "Deco_Bone_Full"
    },
    {
      "x": 0,
      "y": 15,
      "z": 4,
      "name": "Deco_Bone_Full"
    },
    {
      "x": 0,
      "y": 16,
      "z": 4,
      "name": "Deco_Bone_Full"
    },
    {
      "x": 0,
      "y": 17,
      "z": 4,
      "name": "Deco_Bone_Full"
    },
    {
      "x": 0,
      "y": 8,
      "z": 5,
      "name": "Deco_Bone_Full"
    },
    {
      "x": 0,
      "y": 9,
      "z": 5,
      "name": "Deco_Bone_Full"
    },
    {
      "x": 0,
      "y": 10,
      "z": 5,
      "name": "Deco_Bone_Full"
    },
    {
      "x": 0,
      "y": 11,
      "z": 5,
      "name": "Deco_Bone_Full"
    },
    {
      "x": 0,
      "y": 12,
      "z": 5,
      "name": "Deco_Bone_Full"
    },
    {
      "x": 0,
      "y": 13,
      "z": 5,
      "name": "Deco_Bone_Full"
    },
    {
      "x": 0,
      "y": 14,
      "z": 5,
      "name": "Deco_Bone_Full"
    },
    {
      "x": 0,
      "y": 15,
      "z": 5,
      "name": "Deco_Bone_Full"
    },
    {
      "x": 0,
      "y": 16,
      "z": 5,
      "name": "Deco_Bone_Full"
    },
    {
      "x": 0,
      "y": 17,
      "z": 5,
      "name": "Deco_Bone_Full"
    },
    {
      "x": 0,
      "y": 14,
      "z": 6,
      "name": "Deco_Bone_Full"
    },
    {
      "x": 0,
      "y": 15,
      "z": 6,
      "name": "Deco_Bone_Full"
    },
    {
      "x": 0,
      "y": 16,
      "z": 6,
      "name": "Deco_Bone_Full"
    },
    {
      "x": 0,
      "y": 17,
      "z": 6,
      "name": "Deco_Bone_Full"
    },
    {
      "x": 1,
      "y": 12,
      "z": 3,
      "name": "Deco_Bone_Full"
    },
    {
      "x": 1,
      "y": 13,
      "z": 3,
      "name": "Deco_Bone_Full"
    },
    {
      "x": 1,
      "y": 14,
      "z": 3,
      "name": "Deco_Bone_Full"
    },
    {
      "x": 1,
      "y": 15,
      "z": 3,
      "name": "Deco_Bone_Full"
    },
    {
      "x": 1,
      "y": 16,
      "z": 3,
      "name": "Deco_Bone_Full"
    },
    {
      "x": 1,
      "y": 7,
      "z": 4,
      "name": "Deco_Bone_Full"
    },
    {
      "x": 1,
      "y": 8,
      "z": 4,
      "name": "Deco_Bone_Full"
    },
    {
      "x": 1,
      "y": 9,
      "z": 4,
      "name": "Deco_Bone_Full"
    },
    {
      "x": 1,
      "y": 10,
      "z": 4,
      "name": "Deco_Bone_Full"
    },
    {
      "x": 1,
      "y": 11,
      "z": 4,
      "name": "Deco_Bone_Full"
    },
    {
      "x": 1,
      "y": 12,
      "z": 4,
      "name": "Deco_Bone_Full"
    },
    {
      "x": 1,
      "y": 13,
      "z": 4,
      "name": "Deco_Bone_Full"
    },
    {
      "x": 1,
      "y": 14,
      "z": 4,
      "name": "Deco_Bone_Full"
    },
    {
      "x": 1,
      "y": 15,
      "z": 4,
      "name": "Deco_Bone_Full"
    },
    {
      "x": 1,
      "y": 16,
      "z": 4,
      "name": "Deco_Bone_Full"
    },
    {
      "x": 1,
      "y": 17,
      "z": 4,
      "name": "Deco_Bone_Full"
    },
    {
      "x": 1,
      "y": 11,
      "z": 5,
      "name": "Deco_Bone_Full"
    },
    {
      "x": 1,
      "y": 12,
      "z": 5,
      "name": "Deco_Bone_Full"
    },
    {
      "x": 1,
      "y": 13,
      "z": 5,
      "name": "Deco_Bone_Full"
    },
    {
      "x": 1,
      "y": 14,
      "z": 5,
      "name": "Deco_Bone_Full"
    },
    {
      "x": 1,
      "y": 15,
      "z": 5,
      "name": "Deco_Bone_Full"
    },
    {
      "x": 1,
      "y": 16,
      "z": 5,
      "name": "Deco_Bone_Full"
    },
    {
      "x": 1,
      "y": 17,
      "z": 5,
      "name": "Deco_Bone_Full"
    },
    {
      "x": 1,
      "y": 15,
      "z": 6,
      "name": "Deco_Bone_Full"
    },
    {
      "x": 1,
      "y": 16,
      "z": 6,
      "name": "Deco_Bone_Full"
    },
    {
      "x": 1,
      "y": 16,
      "z": 7,
      "name": "Deco_Bone_Full"
    },
    {
      "x": 2,
      "y": 18,
      "z": -6,
      "name": "Deco_Bone_Full"
    },
    {
      "x": 2,
      "y": 19,
      "z": -6,
      "name": "Deco_Bone_Full"
    },
    {
      "x": 2,
      "y": 20,
      "z": -6,
      "name": "Deco_Bone_Full"
    },
    {
      "x": 2,
      "y": 21,
      "z": -6,
      "name": "Deco_Bone_Full"
    },
    {
      "x": 2,
      "y": 22,
      "z": -6,
      "name": "Deco_Bone_Full"
    },
    {
      "x": 2,
      "y": 23,
      "z": -6,
      "name": "Deco_Bone_Full"
    },
    {
      "x": 2,
      "y": 24,
      "z": -6,
      "name": "Deco_Bone_Full"
    },
    {
      "x": 2,
      "y": 25,
      "z": -6,
      "name": "Deco_Bone_Full"
    },
    {
      "x": 2,
      "y": 18,
      "z": -5,
      "name": "Deco_Bone_Full"
    },
    {
      "x": 2,
      "y": 23,
      "z": -5,
      "name": "Plant_Crop_Health3"
    },
    {
      "x": 2,
      "y": 24,
      "z": -5,
      "name": "Plant_Crop_Health3",
      "filler": 1024
    },
    {
      "x": 2,
      "y": 23,
      "z": -4,
      "name": "Empty"
    },
    {
      "x": 2,
      "y": 24,
      "z": -4,
      "name": "Empty"
    },
    {
      "x": 2,
      "y": 15,
      "z": 2,
      "name": "Deco_Bone_Full"
    },
    {
      "x": 2,
      "y": 14,
      "z": 3,
      "name": "Deco_Bone_Full"
    },
    {
      "x": 2,
      "y": 15,
      "z": 3,
      "name": "Deco_Bone_Full"
    },
    {
      "x": 2,
      "y": 12,
      "z": 4,
      "name": "Deco_Bone_Full"
    },
    {
      "x": 2,
      "y": 13,
      "z": 4,
      "name": "Deco_Bone_Full"
    },
    {
      "x": 2,
      "y": 14,
      "z": 4,
      "name": "Deco_Bone_Full"
    },
    {
      "x": 2,
      "y": 15,
      "z": 4,
      "name": "Deco_Bone_Full"
    },
    {
      "x": 2,
      "y": 16,
      "z": 4,
      "name": "Deco_Bone_Full"
    },
    {
      "x": 2,
      "y": 14,
      "z": 5,
      "name": "Deco_Bone_Full"
    },
    {
      "x": 2,
      "y": 15,
      "z": 5,
      "name": "Deco_Bone_Full"
    },
    {
      "x": 2,
      "y": 16,
      "z": 5,
      "name": "Deco_Bone_Full"
    },
    {
      "x": 2,
      "y": 16,
      "z": 6,
      "name": "Deco_Bone_Full"
    },
    {
      "x": 2,
      "y": 15,
      "z": 7,
      "name": "Deco_Bone_Full"
    },
    {
      "x": 2,
      "y": 16,
      "z": 7,
      "name": "Deco_Bone_Full"
    },
    {
      "x": 2,
      "y": 17,
      "z": 7,
      "name": "Deco_Bone_Full"
    },
    {
      "x": 2,
      "y": 17,
      "z": 8,
      "name": "Deco_Bone_Full"
    },
    {
      "x": 3,
      "y": 18,
      "z": -6,
      "name": "Deco_Bone_Full"
    },
    {
      "x": 3,
      "y": 16,
      "z": -5,
      "name": "Deco_Bone_Full"
    },
    {
      "x": 3,
      "y": 17,
      "z": -5,
      "name": "Deco_Bone_Full"
    },
    {
      "x": 3,
      "y": 18,
      "z": -5,
      "name": "Deco_Bone_Full"
    },
    {
      "x": 3,
      "y": 25,
      "z": -5,
      "name": "Deco_Bone_Full"
    },
    {
      "x": 3,
      "y": 26,
      "z": -5,
      "name": "Deco_Bone_Full"
    },
    {
      "x": 3,
      "y": 27,
      "z": -5,
      "name": "Deco_Bone_Full"
    },
    {
      "x": 3,
      "y": 17,
      "z": -4,
      "name": "Deco_Bone_Full"
    },
    {
      "x": 3,
      "y": 15,
      "z": 1,
      "name": "Deco_Bone_Full"
    },
    {
      "x": 3,
      "y": 14,
      "z": 2,
      "name": "Deco_Bone_Full"
    },
    {
      "x": 3,
      "y": 15,
      "z": 2,
      "name": "Deco_Bone_Full"
    },
    {
      "x": 3,
      "y": 15,
      "z": 3,
      "name": "Deco_Bone_Full"
    },
    {
      "x": 3,
      "y": 17,
      "z": 7,
      "name": "Deco_Bone_Full"
    },
    {
      "x": 3,
      "y": 16,
      "z": 8,
      "name": "Deco_Bone_Full"
    },
    {
      "x": 3,
      "y": 17,
      "z": 8,
      "name": "Deco_Bone_Full"
    },
    {
      "x": 3,
      "y": 18,
      "z": 8,
      "name": "Deco_Bone_Full"
    },
    {
      "x": 3,
      "y": 18,
      "z": 9,
      "name": "Deco_Bone_Full"
    },
    {
      "x": 4,
      "y": 17,
      "z": -5,
      "name": "Deco_Bone_Full"
    },
    {
      "x": 4,
      "y": 15,
      "z": -4,
      "name": "Deco_Bone_Full"
    },
    {
      "x": 4,
      "y": 16,
      "z": -4,
      "name": "Deco_Bone_Full"
    },
    {
      "x": 4,
      "y": 17,
      "z": -4,
      "name": "Deco_Bone_Full"
    },
    {
      "x": 4,
      "y": 27,
      "z": -4,
      "name": "Deco_Bone_Full"
    },
    {
      "x": 4,
      "y": 28,
      "z": -4,
      "name": "Deco_Bone_Full"
    },
    {
      "x": 4,
      "y": 16,
      "z": -3,
      "name": "Deco_Bone_Full"
    },
    {
      "x": 4,
      "y": 15,
      "z": 0,
      "name": "Deco_Bone_Full"
    },
    {
      "x": 4,
      "y": 14,
      "z": 1,
      "name": "Deco_Bone_Full"
    },
    {
      "x": 4,
      "y": 15,
      "z": 1,
      "name": "Deco_Bone_Full"
    },
    {
      "x": 4,
      "y": 15,
      "z": 2,
      "name": "Deco_Bone_Full"
    },
    {
      "x": 4,
      "y": 18,
      "z": 8,
      "name": "Deco_Bone_Full"
    },
    {
      "x": 4,
      "y": 18,
      "z": 9,
      "name": "Deco_Bone_Full"
    },
    {
      "x": 4,
      "y": 19,
      "z": 9,
      "name": "Deco_Bone_Full"
    },
    {
      "x": 4,
      "y": 20,
      "z": 9,
      "name": "Deco_Bone_Full"
    },
    {
      "x": 4,
      "y": 21,
      "z": 9,
      "name": "Deco_Bone_Full"
    },
    {
      "x": 5,
      "y": 16,
      "z": -4,
      "name": "Deco_Bone_Full"
    },
    {
      "x": 5,
      "y": 15,
      "z": -3,
      "name": "Deco_Bone_Full"
    },
    {
      "x": 5,
      "y": 16,
      "z": -3,
      "name": "Deco_Bone_Full"
    },
    {
      "x": 5,
      "y": 15,
      "z": -2,
      "name": "Deco_Bone_Full"
    },
    {
      "x": 5,
      "y": 16,
      "z": -2,
      "name": "Deco_Bone_Full"
    },
    {
      "x": 5,
      "y": 13,
      "z": -1,
      "name": "Deco_Bone_Full"
    },
    {
      "x": 5,
      "y": 14,
      "z": -1,
      "name": "Deco_Bone_Full"
    },
    {
      "x": 5,
      "y": 15,
      "z": -1,
      "name": "Deco_Bone_Full"
    },
    {
      "x": 5,
      "y": 16,
      "z": -1,
      "name": "Deco_Bone_Full"
    },
    {
      "x": 5,
      "y": 13,
      "z": 0,
      "name": "Deco_Bone_Full"
    },
    {
      "x": 5,
      "y": 14,
      "z": 0,
      "name": "Deco_Bone_Full"
    },
    {
      "x": 5,
      "y": 15,
      "z": 0,
      "name": "Deco_Bone_Full"
    },
    {
      "x": 5,
      "y": 15,
      "z": 1,
      "name": "Deco_Bone_Full"
    },
    {
      "x": 6,
      "y": 16,
      "z": -3,
      "name": "Deco_Bone_Full"
    },
    {
      "x": 6,
      "y": 11,
      "z": -2,
      "name": "Deco_Bone_Full"
    },
    {
      "x": 6,
      "y": 12,
      "z": -2,
      "name": "Deco_Bone_Full"
    },
    {
      "x": 6,
      "y": 13,
      "z": -2,
      "name": "Deco_Bone_Full"
    },
    {
      "x": 6,
      "y": 14,
      "z": -2,
      "name": "Deco_Bone_Full"
    },
    {
      "x": 6,
      "y": 15,
      "z": -2,
      "name": "Deco_Bone_Full"
    },
    {
      "x": 6,
      "y": 16,
      "z": -2,
      "name": "Deco_Bone_Full"
    },
    {
      "x": 6,
      "y": 17,
      "z": -2,
      "name": "Deco_Bone_Full"
    },
    {
      "x": 6,
      "y": 7,
      "z": -1,
      "name": "Deco_Bone_Full"
    },
    {
      "x": 6,
      "y": 8,
      "z": -1,
      "name": "Deco_Bone_Full"
    },
    {
      "x": 6,
      "y": 9,
      "z": -1,
      "name": "Deco_Bone_Full"
    },
    {
      "x": 6,
      "y": 10,
      "z": -1,
      "name": "Deco_Bone_Full"
    },
    {
      "x": 6,
      "y": 11,
      "z": -1,
      "name": "Deco_Bone_Full"
    },
    {
      "x": 6,
      "y": 12,
      "z": -1,
      "name": "Deco_Bone_Full"
    },
    {
      "x": 6,
      "y": 13,
      "z": -1,
      "name": "Deco_Bone_Full"
    },
    {
      "x": 6,
      "y": 14,
      "z": -1,
      "name": "Deco_Bone_Full"
    },
    {
      "x": 6,
      "y": 15,
      "z": -1,
      "name": "Deco_Bone_Full"
    },
    {
      "x": 6,
      "y": 16,
      "z": -1,
      "name": "Deco_Bone_Full"
    },
    {
      "x": 6,
      "y": 17,
      "z": -1,
      "name": "Deco_Bone_Full"
    },
    {
      "x": 6,
      "y": 13,
      "z": 0,
      "name": "Deco_Bone_Full"
    },
    {
      "x": 6,
      "y": 14,
      "z": 0,
      "name": "Deco_Bone_Full"
    },
    {
      "x": 6,
      "y": 15,
      "z": 0,
      "name": "Deco_Bone_Full"
    },
    {
      "x": 6,
      "y": 16,
      "z": 0,
      "name": "Deco_Bone_Full"
    },
    {
      "x": 7,
      "y": 21,
      "z": -11,
      "name": "Deco_Bone_Full"
    },
    {
      "x": 7,
      "y": 22,
      "z": -11,
      "name": "Deco_Bone_Full"
    },
    {
      "x": 7,
      "y": 15,
      "z": -3,
      "name": "Deco_Bone_Full"
    },
    {
      "x": 7,
      "y": 16,
      "z": -3,
      "name": "Deco_Bone_Full"
    },
    {
      "x": 7,
      "y": 8,
      "z": -2,
      "name": "Deco_Bone_Full"
    },
    {
      "x": 7,
      "y": 9,
      "z": -2,
      "name": "Deco_Bone_Full"
    },
    {
      "x": 7,
      "y": 10,
      "z": -2,
      "name": "Deco_Bone_Full"
    },
    {
      "x": 7,
      "y": 11,
      "z": -2,
      "name": "Deco_Bone_Full"
    },
    {
      "x": 7,
      "y": 12,
      "z": -2,
      "name": "Deco_Bone_Full"
    },
    {
      "x": 7,
      "y": 13,
      "z": -2,
      "name": "Deco_Bone_Full"
    },
    {
      "x": 7,
      "y": 14,
      "z": -2,
      "name": "Deco_Bone_Full"
    },
    {
      "x": 7,
      "y": 15,
      "z": -2,
      "name": "Deco_Bone_Full"
    },
    {
      "x": 7,
      "y": 16,
      "z": -2,
      "name": "Deco_Bone_Full"
    },
    {
      "x": 7,
      "y": 17,
      "z": -2,
      "name": "Deco_Bone_Full"
    },
    {
      "x": 7,
      "y": 11,
      "z": -1,
      "name": "Deco_Bone_Full"
    },
    {
      "x": 7,
      "y": 12,
      "z": -1,
      "name": "Deco_Bone_Full"
    },
    {
      "x": 7,
      "y": 13,
      "z": -1,
      "name": "Deco_Bone_Full"
    },
    {
      "x": 7,
      "y": 14,
      "z": -1,
      "name": "Deco_Bone_Full"
    },
    {
      "x": 7,
      "y": 15,
      "z": -1,
      "name": "Deco_Bone_Full"
    },
    {
      "x": 7,
      "y": 16,
      "z": -1,
      "name": "Deco_Bone_Full"
    },
    {
      "x": 7,
      "y": 17,
      "z": -1,
      "name": "Deco_Bone_Full"
    },
    {
      "x": 7,
      "y": 15,
      "z": 0,
      "name": "Deco_Bone_Full"
    },
    {
      "x": 7,
      "y": 16,
      "z": 0,
      "name": "Deco_Bone_Full"
    },
    {
      "x": 8,
      "y": 19,
      "z": -11,
      "name": "Deco_Bone_Full"
    },
    {
      "x": 8,
      "y": 20,
      "z": -11,
      "name": "Deco_Bone_Full"
    },
    {
      "x": 8,
      "y": 21,
      "z": -11,
      "name": "Deco_Bone_Full"
    },
    {
      "x": 8,
      "y": 16,
      "z": -4,
      "name": "Deco_Bone_Full"
    },
    {
      "x": 8,
      "y": 15,
      "z": -3,
      "name": "Deco_Bone_Full"
    },
    {
      "x": 8,
      "y": 16,
      "z": -3,
      "name": "Deco_Bone_Full"
    },
    {
      "x": 8,
      "y": 15,
      "z": -2,
      "name": "Deco_Bone_Full"
    },
    {
      "x": 8,
      "y": 16,
      "z": -2,
      "name": "Deco_Bone_Full"
    },
    {
      "x": 8,
      "y": 16,
      "z": -1,
      "name": "Deco_Bone_Full"
    },
    {
      "x": 8,
      "y": 15,
      "z": 0,
      "name": "Deco_Bone_Full"
    },
    {
      "x": 8,
      "y": 16,
      "z": 0,
      "name": "Deco_Bone_Full"
    },
    {
      "x": 8,
      "y": 16,
      "z": 1,
      "name": "Deco_Bone_Full"
    },
    {
      "x": 9,
      "y": 18,
      "z": -11,
      "name": "Deco_Bone_Full"
    },
    {
      "x": 9,
      "y": 19,
      "z": -11,
      "name": "Deco_Bone_Full"
    },
    {
      "x": 9,
      "y": 19,
      "z": -10,
      "name": "Deco_Bone_Full"
    },
    {
      "x": 9,
      "y": 16,
      "z": -5,
      "name": "Deco_Bone_Full"
    },
    {
      "x": 9,
      "y": 15,
      "z": -4,
      "name": "Deco_Bone_Full"
    },
    {
      "x": 9,
      "y": 16,
      "z": -4,
      "name": "Deco_Bone_Full"
    },
    {
      "x": 9,
      "y": 16,
      "z": -3,
      "name": "Deco_Bone_Full"
    },
    {
      "x": 9,
      "y": 16,
      "z": 0,
      "name": "Deco_Bone_Full"
    },
    {
      "x": 9,
      "y": 15,
      "z": 1,
      "name": "Deco_Bone_Full"
    },
    {
      "x": 9,
      "y": 16,
      "z": 1,
      "name": "Deco_Bone_Full"
    },
    {
      "x": 9,
      "y": 17,
      "z": 1,
      "name": "Deco_Bone_Full"
    },
    {
      "x": 9,
      "y": 17,
      "z": 2,
      "name": "Deco_Bone_Full"
    },
    {
      "x": 10,
      "y": 19,
      "z": -11,
      "name": "Deco_Bone_Full"
    },
    {
      "x": 10,
      "y": 17,
      "z": -10,
      "name": "Deco_Bone_Full"
    },
    {
      "x": 10,
      "y": 18,
      "z": -10,
      "name": "Deco_Bone_Full"
    },
    {
      "x": 10,
      "y": 18,
      "z": -9,
      "name": "Deco_Bone_Full"
    },
    {
      "x": 10,
      "y": 16,
      "z": -6,
      "name": "Deco_Bone_Full"
    },
    {
      "x": 10,
      "y": 15,
      "z": -5,
      "name": "Deco_Bone_Full"
    },
    {
      "x": 10,
      "y": 16,
      "z": -5,
      "name": "Deco_Bone_Full"
    },
    {
      "x": 10,
      "y": 16,
      "z": -4,
      "name": "Deco_Bone_Full"
    },
    {
      "x": 10,
      "y": 17,
      "z": 1,
      "name": "Deco_Bone_Full"
    },
    {
      "x": 10,
      "y": 16,
      "z": 2,
      "name": "Deco_Bone_Full"
    },
    {
      "x": 10,
      "y": 17,
      "z": 2,
      "name": "Deco_Bone_Full"
    },
    {
      "x": 10,
      "y": 18,
      "z": 2,
      "name": "Deco_Bone_Full"
    },
    {
      "x": 10,
      "y": 25,
      "z": 2,
      "name": "Deco_Bone_Full"
    },
    {
      "x": 10,
      "y": 26,
      "z": 2,
      "name": "Deco_Bone_Full"
    },
    {
      "x": 10,
      "y": 18,
      "z": 3,
      "name": "Deco_Bone_Full"
    },
    {
      "x": 11,
      "y": 18,
      "z": -10,
      "name": "Deco_Bone_Full"
    },
    {
      "x": 11,
      "y": 17,
      "z": -9,
      "name": "Deco_Bone_Full"
    },
    {
      "x": 11,
      "y": 18,
      "z": -9,
      "name": "Deco_Bone_Full"
    },
    {
      "x": 11,
      "y": 15,
      "z": -8,
      "name": "Deco_Bone_Full"
    },
    {
      "x": 11,
      "y": 16,
      "z": -8,
      "name": "Deco_Bone_Full"
    },
    {
      "x": 11,
      "y": 17,
      "z": -8,
      "name": "Deco_Bone_Full"
    },
    {
      "x": 11,
      "y": 18,
      "z": -8,
      "name": "Deco_Bone_Full"
    },
    {
      "x": 11,
      "y": 13,
      "z": -7,
      "name": "Deco_Bone_Full"
    },
    {
      "x": 11,
      "y": 14,
      "z": -7,
      "name": "Deco_Bone_Full"
    },
    {
      "x": 11,
      "y": 15,
      "z": -7,
      "name": "Deco_Bone_Full"
    },
    {
      "x": 11,
      "y": 16,
      "z": -7,
      "name": "Deco_Bone_Full"
    },
    {
      "x": 11,
      "y": 17,
      "z": -7,
      "name": "Deco_Bone_Full"
    },
    {
      "x": 11,
      "y": 18,
      "z": -7,
      "name": "Deco_Bone_Full"
    },
    {
      "x": 11,
      "y": 15,
      "z": -6,
      "name": "Deco_Bone_Full"
    },
    {
      "x": 11,
      "y": 16,
      "z": -6,
      "name": "Deco_Bone_Full"
    },
    {
      "x": 11,
      "y": 17,
      "z": -6,
      "name": "Deco_Bone_Full"
    },
    {
      "x": 11,
      "y": 16,
      "z": -5,
      "name": "Deco_Bone_Full"
    },
    {
      "x": 11,
      "y": 18,
      "z": 2,
      "name": "Deco_Bone_Full"
    },
    {
      "x": 11,
      "y": 18,
      "z": 3,
      "name": "Deco_Bone_Full"
    },
    {
      "x": 11,
      "y": 19,
      "z": 3,
      "name": "Deco_Bone_Full"
    },
    {
      "x": 11,
      "y": 20,
      "z": 3,
      "name": "Deco_Bone_Full"
    },
    {
      "x": 11,
      "y": 21,
      "z": 3,
      "name": "Deco_Bone_Full"
    },
    {
      "x": 11,
      "y": 22,
      "z": 3,
      "name": "Deco_Bone_Full"
    },
    {
      "x": 11,
      "y": 23,
      "z": 3,
      "name": "Deco_Bone_Full"
    },
    {
      "x": 11,
      "y": 24,
      "z": 3,
      "name": "Deco_Bone_Full"
    },
    {
      "x": 11,
      "y": 25,
      "z": 3,
      "name": "Deco_Bone_Full"
    },
    {
      "x": 12,
      "y": 16,
      "z": -9,
      "name": "Deco_Bone_Full"
    },
    {
      "x": 12,
      "y": 17,
      "z": -9,
      "name": "Deco_Bone_Full"
    },
    {
      "x": 12,
      "y": 18,
      "z": -9,
      "name": "Deco_Bone_Full"
    },
    {
      "x": 12,
      "y": 11,
      "z": -8,
      "name": "Deco_Bone_Full"
    },
    {
      "x": 12,
      "y": 12,
      "z": -8,
      "name": "Deco_Bone_Full"
    },
    {
      "x": 12,
      "y": 13,
      "z": -8,
      "name": "Deco_Bone_Full"
    },
    {
      "x": 12,
      "y": 14,
      "z": -8,
      "name": "Deco_Bone_Full"
    },
    {
      "x": 12,
      "y": 15,
      "z": -8,
      "name": "Deco_Bone_Full"
    },
    {
      "x": 12,
      "y": 16,
      "z": -8,
      "name": "Deco_Bone_Full"
    },
    {
      "x": 12,
      "y": 17,
      "z": -8,
      "name": "Deco_Bone_Full"
    },
    {
      "x": 12,
      "y": 18,
      "z": -8,
      "name": "Deco_Bone_Full"
    },
    {
      "x": 12,
      "y": 19,
      "z": -8,
      "name": "Deco_Bone_Full"
    },
    {
      "x": 12,
      "y": 8,
      "z": -7,
      "name": "Deco_Bone_Full"
    },
    {
      "x": 12,
      "y": 9,
      "z": -7,
      "name": "Deco_Bone_Full"
    },
    {
      "x": 12,
      "y": 10,
      "z": -7,
      "name": "Deco_Bone_Full"
    },
    {
      "x": 12,
      "y": 11,
      "z": -7,
      "name": "Deco_Bone_Full"
    },
    {
      "x": 12,
      "y": 12,
      "z": -7,
      "name": "Deco_Bone_Full"
    },
    {
      "x": 12,
      "y": 13,
      "z": -7,
      "name": "Deco_Bone_Full"
    },
    {
      "x": 12,
      "y": 14,
      "z": -7,
      "name": "Deco_Bone_Full"
    },
    {
      "x": 12,
      "y": 15,
      "z": -7,
      "name": "Deco_Bone_Full"
    },
    {
      "x": 12,
      "y": 16,
      "z": -7,
      "name": "Deco_Bone_Full"
    },
    {
      "x": 12,
      "y": 17,
      "z": -7,
      "name": "Deco_Bone_Full"
    },
    {
      "x": 12,
      "y": 18,
      "z": -7,
      "name": "Deco_Bone_Full"
    },
    {
      "x": 12,
      "y": 19,
      "z": -7,
      "name": "Deco_Bone_Full"
    },
    {
      "x": 12,
      "y": 13,
      "z": -6,
      "name": "Deco_Bone_Full"
    },
    {
      "x": 12,
      "y": 14,
      "z": -6,
      "name": "Deco_Bone_Full"
    },
    {
      "x": 12,
      "y": 15,
      "z": -6,
      "name": "Deco_Bone_Full"
    },
    {
      "x": 12,
      "y": 16,
      "z": -6,
      "name": "Deco_Bone_Full"
    },
    {
      "x": 12,
      "y": 17,
      "z": -6,
      "name": "Deco_Bone_Full"
    },
    {
      "x": 12,
      "y": 18,
      "z": -6,
      "name": "Deco_Bone_Full"
    },
    {
      "x": 13,
      "y": 17,
      "z": -9,
      "name": "Deco_Bone_Full"
    },
    {
      "x": 13,
      "y": 18,
      "z": -9,
      "name": "Deco_Bone_Full"
    },
    {
      "x": 13,
      "y": 9,
      "z": -8,
      "name": "Deco_Bone_Full"
    },
    {
      "x": 13,
      "y": 10,
      "z": -8,
      "name": "Deco_Bone_Full"
    },
    {
      "x": 13,
      "y": 11,
      "z": -8,
      "name": "Deco_Bone_Full"
    },
    {
      "x": 13,
      "y": 12,
      "z": -8,
      "name": "Deco_Bone_Full"
    },
    {
      "x": 13,
      "y": 13,
      "z": -8,
      "name": "Deco_Bone_Full"
    },
    {
      "x": 13,
      "y": 14,
      "z": -8,
      "name": "Deco_Bone_Full"
    },
    {
      "x": 13,
      "y": 15,
      "z": -8,
      "name": "Deco_Bone_Full"
    },
    {
      "x": 13,
      "y": 16,
      "z": -8,
      "name": "Deco_Bone_Full"
    },
    {
      "x": 13,
      "y": 17,
      "z": -8,
      "name": "Deco_Bone_Full"
    },
    {
      "x": 13,
      "y": 18,
      "z": -8,
      "name": "Deco_Bone_Full"
    },
    {
      "x": 13,
      "y": 19,
      "z": -8,
      "name": "Deco_Bone_Full"
    },
    {
      "x": 13,
      "y": 11,
      "z": -7,
      "name": "Deco_Bone_Full"
    },
    {
      "x": 13,
      "y": 12,
      "z": -7,
      "name": "Deco_Bone_Full"
    },
    {
      "x": 13,
      "y": 13,
      "z": -7,
      "name": "Deco_Bone_Full"
    },
    {
      "x": 13,
      "y": 14,
      "z": -7,
      "name": "Deco_Bone_Full"
    },
    {
      "x": 13,
      "y": 15,
      "z": -7,
      "name": "Deco_Bone_Full"
    },
    {
      "x": 13,
      "y": 16,
      "z": -7,
      "name": "Deco_Bone_Full"
    },
    {
      "x": 13,
      "y": 17,
      "z": -7,
      "name": "Deco_Bone_Full"
    },
    {
      "x": 13,
      "y": 18,
      "z": -7,
      "name": "Deco_Bone_Full"
    },
    {
      "x": 13,
      "y": 19,
      "z": -7,
      "name": "Deco_Bone_Full"
    },
    {
      "x": 13,
      "y": 15,
      "z": -6,
      "name": "Deco_Bone_Full"
    },
    {
      "x": 13,
      "y": 16,
      "z": -6,
      "name": "Deco_Bone_Full"
    },
    {
      "x": 13,
      "y": 17,
      "z": -6,
      "name": "Deco_Bone_Full"
    },
    {
      "x": 13,
      "y": 18,
      "z": -6,
      "name": "Deco_Bone_Full"
    },
    {
      "x": 14,
      "y": 17,
      "z": -10,
      "name": "Deco_Bone_Full"
    },
    {
      "x": 14,
      "y": 16,
      "z": -9,
      "name": "Deco_Bone_Full"
    },
    {
      "x": 14,
      "y": 17,
      "z": -9,
      "name": "Deco_Bone_Full"
    },
    {
      "x": 14,
      "y": 18,
      "z": -9,
      "name": "Deco_Bone_Full"
    },
    {
      "x": 14,
      "y": 17,
      "z": -8,
      "name": "Deco_Bone_Full"
    },
    {
      "x": 14,
      "y": 18,
      "z": -8,
      "name": "Deco_Bone_Full"
    },
    {
      "x": 14,
      "y": 16,
      "z": -7,
      "name": "Deco_Bone_Full"
    },
    {
      "x": 14,
      "y": 17,
      "z": -7,
      "name": "Deco_Bone_Full"
    },
    {
      "x": 14,
      "y": 18,
      "z": -7,
      "name": "Deco_Bone_Full"
    },
    {
      "x": 14,
      "y": 17,
      "z": -6,
      "name": "Deco_Bone_Full"
    },
    {
      "x": 14,
      "y": 18,
      "z": -6,
      "name": "Deco_Bone_Full"
    },
    {
      "x": 14,
      "y": 18,
      "z": -5,
      "name": "Deco_Bone_Full"
    },
    {
      "x": 15,
      "y": 18,
      "z": -6,
      "name": "Deco_Bone_Full"
    },
    {
      "x": 15,
      "y": 17,
      "z": -5,
      "name": "Deco_Bone_Full"
    },
    {
      "x": 15,
      "y": 18,
      "z": -5,
      "name": "Deco_Bone_Full"
    },
    {
      "x": 15,
      "y": 19,
      "z": -4,
      "name": "Deco_Bone_Full"
    },
    {
      "x": 16,
      "y": 19,
      "z": -5,
      "name": "Deco_Bone_Full"
    },
    {
      "x": 16,
      "y": 18,
      "z": -4,
      "name": "Deco_Bone_Full"
    },
    {
      "x": 16,
      "y": 19,
      "z": -4,
      "name": "Deco_Bone_Full"
    },
    {
      "x": 16,
      "y": 23,
      "z": -4,
      "name": "Empty"
    },
    {
      "x": 16,
      "y": 24,
      "z": -4,
      "name": "Empty"
    },
    {
      "x": 16,
      "y": 19,
      "z": -3,
      "name": "Deco_Bone_Full"
    },
    {
      "x": 16,
      "y": 20,
      "z": -3,
      "name": "Deco_Bone_Full"
    },
    {
      "x": 16,
      "y": 21,
      "z": -3,
      "name": "Deco_Bone_Full"
    },
    {
      "x": 16,
      "y": 23,
      "z": -3,
      "name": "Plant_Crop_Health3",
      "rotation": 2
    },
    {
      "x": 16,
      "y": 24,
      "z": -3,
      "name": "Plant_Crop_Health3",
      "filler": 1024,
      "rotation": 2
    },
    {
      "x": 16,
      "y": 21,
      "z": -2,
      "name": "Deco_Bone_Full"
    },
    {
      "x": 16,
      "y": 22,
      "z": -2,
      "name": "Deco_Bone_Full"
    },
    {
      "x": 16,
      "y": 23,
      "z": -2,
      "name": "Deco_Bone_Full"
    },
    {
      "x": 16,
      "y": 24,
      "z": -2,
      "name": "Deco_Bone_Full"
    },
    {
      "x": 16,
      "y": 25,
      "z": -2,
      "name": "Deco_Bone_Full"
    },
    {
      "x": 16,
      "y": 26,
      "z": -2,
      "name": "Deco_Bone_Full"
    }
  ]
}