{
  "version": 8,
  "blockIdVersion": 8,
  "anchorX": 6,
  "anchorY": 6,
  "anchorZ": 5,
  "blocks": [
    {
      "x": 1,
      "y": 20,
      "z": 5,
      "name": "Plant_Leaves_Aspen"
    },
    {
      "x": 2,
      "y": 19,
      "z": 3,
      "name": "Plant_Leaves_Aspen"
    },
    {
      "x": 2,
      "y": 19,
      "z": 4,
      "name": "Plant_Leaves_Aspen"
    },
    {
      "x": 2,
      "y": 20,
      "z": 4,
      "name": "Plant_Leaves_Aspen"
    },
    {
      "x": 2,
      "y": 21,
      "z": 4,
      "name": "Plant_Leaves_Aspen"
    },
    {
      "x": 2,
      "y": 22,
      "z": 4,
      "name": "Plant_Leaves_Aspen"
    },
    {
      "x": 2,
      "y": 18,
      "z": 5,
      "name": "Plant_Leaves_Aspen"
    },
    {
      "x": 2,
      "y": 19,
      "z": 5,
      "name": "Plant_Leaves_Aspen"
    },
    {
      "x": 2,
      "y": 20,
      "z": 5,
      "name": "Plant_Leaves_Aspen"
    },
    {
      "x": 2,
      "y": 21,
      "z": 5,
      "name": "Plant_Leaves_Aspen"
    },
    {
      "x": 2,
      "y": 22,
      "z": 5,
      "name": "Plant_Leaves_Aspen"
    },
    {
      "x": 2,
      "y": 23,
      "z": 5,
      "name": "Plant_Leaves_Aspen"
    },
    {
      "x": 2,
      "y": 18,
      "z": 6,
      "name": "Plant_Leaves_Aspen"
    },
    {
      "x": 2,
      "y": 19,
      "z": 6,
      "name": "Plant_Leaves_Aspen"
    },
    {
      "x": 3,
      "y": 22,
      "z": 3,
      "name": "Plant_Leaves_Aspen"
    },
    {
      "x": 3,
      "y": 22,
      "z": 4,
      "name": "Plant_Leaves_Aspen"
    },
    {
      "x": 3,
      "y": 23,
      "z": 4,
      "name": "Plant_Leaves_Aspen"
    },
    {
      "x": 3,
      "y": 24,
      "z": 4,
      "name": "Plant_Leaves_Aspen"
    },
    {
      "x": 3,
      "y": 25,
      "z": 4,
      "name": "Plant_Leaves_Aspen"
    },
    {
      "x": 3,
      "y": 17,
      "z": 5,
      "name": "Plant_Leaves_Aspen"
    },
    {
      "x": 3,
      "y": 18,
      "z": 5,
      "name": "Plant_Leaves_Aspen"
    },
    {
      "x": 3,
      "y": 19,
      "z": 5,
      "name": "Wood_Aspen_Branch_Corner",
      "rotation": 3
    },
    {
      "x": 3,
      "y": 20,
      "z": 5,
      "name": "Wood_Aspen_Branch_Long"
    },
    {
      "x": 3,
      "y": 21,
      "z": 5,
      "name": "Wood_Aspen_Branch_Long"
    },
    {
      "x": 3,
      "y": 23,
      "z": 5,
      "name": "Plant_Leaves_Aspen"
    },
    {
      "x": 3,
      "y": 24,
      "z": 5,
      "name": "Plant_Leaves_Aspen"
    },
    {
      "x": 3,
      "y": 25,
      "z": 5,
      "name": "Plant_Leaves_Aspen"
    },
    {
      "x": 3,
      "y": 21,
      "z": 6,
      "name": "Plant_Leaves_Aspen"
    },
    {
      "x": 3,
      "y": 22,
      "z": 6,
      "name": "Plant_Leaves_Aspen"
    },
    {
      "x": 3,
      "y": 23,
      "z": 6,
      "name": "Plant_Leaves_Aspen"
    },
    {
      "x": 3,
      "y": 20,
      "z": 7,
      "name": "Plant_Leaves_Aspen"
    },
    {
      "x": 3,
      "y": 21,
      "z": 7,
      "name": "Plant_Leaves_Aspen"
    },
    {
      "x": 4,
      "y": 20,
      "z": 2,
      "name": "Plant_Leaves_Aspen"
    },
    {
      "x": 4,
      "y": 20,
      "z": 3,
      "name": "Plant_Leaves_Aspen"
    },
    {
      "x": 4,
      "y": 23,
      "z": 3,
      "name": "Plant_Leaves_Aspen"
    },
    {
      "x": 4,
      "y": 19,
      "z": 4,
      "name": "Wood_Aspen_Branch_Corner",
      "rotation": 2
    },
    {
      "x": 4,
      "y": 20,
      "z": 4,
      "name": "Wood_Aspen_Branch_Long"
    },
    {
      "x": 4,
      "y": 21,
      "z": 4,
      "name": "Wood_Aspen_Branch_Long"
    },
    {
      "x": 4,
      "y": 22,
      "z": 4,
      "name": "Plant_Leaves_Aspen"
    },
    {
      "x": 4,
      "y": 23,
      "z": 4,
      "name": "Plant_Leaves_Aspen"
    },
    {
      "x": 4,
      "y": 24,
      "z": 4,
      "name": "Plant_Leaves_Aspen"
    },
    {
      "x": 4,
      "y": 25,
      "z": 4,
      "name": "Plant_Leaves_Aspen"
    },
    {
      "x": 4,
      "y": 19,
      "z": 5,
      "name": "Wood_Aspen_Trunk_Full"
    },
    {
      "x": 4,
      "y": 20,
      "z": 5,
      "name": "Wood_Aspen_Branch_Long"
    },
    {
      "x": 4,
      "y": 21,
      "z": 5,
      "name": "Wood_Aspen_Branch_Long"
    },
    {
      "x": 4,
      "y": 22,
      "z": 5,
      "name": "Wood_Aspen_Branch_Long"
    },
    {
      "x": 4,
      "y": 23,
      "z": 5,
      "name": "Wood_Aspen_Branch_Long"
    },
    {
      "x": 4,
      "y": 24,
      "z": 5,
      "name": "Plant_Leaves_Aspen"
    },
    {
      "x": 4,
      "y": 25,
      "z": 5,
      "name": "Plant_Leaves_Aspen"
    },
    {
      "x": 4,
      "y": 26,
      "z": 5,
      "name": "Plant_Leaves_Aspen"
    },
    {
      "x": 4,
      "y": 24,
      "z": 6,
      "name": "Plant_Leaves_Aspen"
    },
    {
      "x": 4,
      "y": 25,
      "z": 6,
      "name": "Plant_Leaves_Aspen"
    },
    {
      "x": 4,
      "y": 26,
      "z": 6,
      "name": "Plant_Leaves_Aspen"
    },
    {
      "x": 4,
      "y": 22,
      "z": 7,
      "name": "Plant_Leaves_Aspen"
    },
    {
      "x": 4,
      "y": 21,
      "z": 8,
      "name": "Plant_Leaves_Aspen"
    },
    {
      "x": 4,
      "y": 18,
      "z": 9,
      "name": "Plant_Leaves_Aspen"
    },
    {
      "x": 5,
      "y": 20,
      "z": 1,
      "name": "Plant_Leaves_Aspen"
    },
    {
      "x": 5,
      "y": 18,
      "z": 2,
      "name": "Plant_Leaves_Aspen"
    },
    {
      "x": 5,
      "y": 19,
      "z": 2,
      "name": "Plant_Leaves_Aspen"
    },
    {
      "x": 5,
      "y": 20,
      "z": 2,
      "name": "Plant_Leaves_Aspen"
    },
    {
      "x": 5,
      "y": 22,
      "z": 2,
      "name": "Plant_Leaves_Aspen"
    },
    {
      "x": 5,
      "y": 17,
      "z": 3,
      "name": "Plant_Leaves_Aspen"
    },
    {
      "x": 5,
      "y": 19,
      "z": 3,
      "name": "Plant_Leaves_Aspen"
    },
    {
      "x": 5,
      "y": 24,
      "z": 3,
      "name": "Plant_Leaves_Aspen"
    },
    {
      "x": 5,
      "y": 25,
      "z": 3,
      "name": "Plant_Leaves_Aspen"
    },
    {
      "x": 5,
      "y": 26,
      "z": 3,
      "name": "Plant_Leaves_Aspen"
    },
    {
      "x": 5,
      "y": 27,
      "z": 4,
      "name": "Plant_Leaves_Aspen"
    },
    {
      "x": 5,
      "y": 19,
      "z": 5,
      "name": "Wood_Aspen_Trunk_Full"
    },
    {
      "x": 5,
      "y": 26,
      "z": 5,
      "name": "Plant_Leaves_Aspen"
    },
    {
      "x": 5,
      "y": 27,
      "z": 5,
      "name": "Plant_Leaves_Aspen"
    },
    {
      "x": 5,
      "y": 28,
      "z": 5,
      "name": "Plant_Leaves_Aspen"
    },
    {
      "x": 5,
      "y": 27,
      "z": 6,
      "name": "Plant_Leaves_Aspen"
    },
    {
      "x": 5,
      "y": 18,
      "z": 7,
      "name": "Wood_Aspen_Branch_Corner",
      "rotation": 3
    },
    {
      "x": 5,
      "y": 19,
      "z": 7,
      "name": "Wood_Aspen_Branch_Long"
    },
    {
      "x": 5,
      "y": 20,
      "z": 7,
      "name": "Wood_Aspen_Branch_Long"
    },
    {
      "x": 5,
      "y": 21,
      "z": 7,
      "name": "Plant_Leaves_Aspen"
    },
    {
      "x": 5,
      "y": 22,
      "z": 7,
      "name": "Plant_Leaves_Aspen"
    },
    {
      "x": 5,
      "y": 23,
      "z": 7,
      "name": "Plant_Leaves_Aspen"
    },
    {
      "x": 5,
      "y": 24,
      "z": 7,
      "name": "Plant_Leaves_Aspen"
    },
    {
      "x": 5,
      "y": 21,
      "z": 8,
      "name": "Plant_Leaves_Aspen"
    },
    {
      "x": 5,
      "y": 22,
      "z": 8,
      "name": "Plant_Leaves_Aspen"
    },
    {
      "x": 5,
      "y": 23,
      "z": 8,
      "name": "Plant_Leaves_Aspen"
    },
    {
      "x": 5,
      "y": 24,
      "z": 8,
      "name": "Plant_Leaves_Aspen"
    },
    {
      "x": 5,
      "y": 18,
      "z": 9,
      "name": "Plant_Leaves_Aspen"
    },
    {
      "x": 5,
      "y": 19,
      "z": 9,
      "name": "Plant_Leaves_Aspen"
    },
    {
      "x": 5,
      "y": 20,
      "z": 9,
      "name": "Plant_Leaves_Aspen"
    },
    {
      "x": 5,
      "y": 21,
      "z": 9,
      "name": "Plant_Leaves_Aspen"
    },
    {
      "x": 6,
      "y": 17,
      "z": 2,
      "name": "Plant_Leaves_Aspen"
    },
    {
      "x": 6,
      "y": 18,
      "z": 2,
      "name": "Plant_Leaves_Aspen"
    },
    {
      "x": 6,
      "y": 19,
      "z": 2,
      "name": "Plant_Leaves_Aspen"
    },
    {
      "x": 6,
      "y": 20,
      "z": 2,
      "name": "Plant_Leaves_Aspen"
    },
    {
      "x": 6,
      "y": 21,
      "z": 2,
      "name": "Plant_Leaves_Aspen"
    },
    {
      "x": 6,
      "y": 22,
      "z": 2,
      "name": "Plant_Leaves_Aspen"
    },
    {
      "x": 6,
      "y": 23,
      "z": 2,
      "name": "Plant_Leaves_Aspen"
    },
    {
      "x": 6,
      "y": 24,
      "z": 2,
      "name": "Plant_Leaves_Aspen"
    },
    {
      "x": 6,
      "y": 17,
      "z": 3,
      "name": "Plant_Leaves_Aspen"
    },
    {
      "x": 6,
      "y": 20,
      "z": 3,
      "name": "Plant_Leaves_Aspen"
    },
    {
      "x": 6,
      "y": 21,
      "z": 3,
      "name": "Plant_Leaves_Aspen"
    },
    {
      "x": 6,
      "y": 22,
      "z": 3,
      "name": "Plant_Leaves_Aspen"
    },
    {
      "x": 6,
      "y": 23,
      "z": 3,
      "name": "Plant_Leaves_Aspen"
    },
    {
      "x": 6,
      "y": 24,
      "z": 3,
      "name": "Plant_Leaves_Aspen"
    },
    {
      "x": 6,
      "y": 25,
      "z": 3,
      "name": "Plant_Leaves_Aspen"
    },
    {
      "x": 6,
      "y": 26,
      "z": 3,
      "name": "Plant_Leaves_Aspen"
    },
    {
      "x": 6,
      "y": 27,
      "z": 3,
      "name": "Plant_Leaves_Aspen"
    },
    {
      "x": 6,
      "y": 13,
      "z": 4,
      "name": "Wood_Aspen_Branch_Short",
      "rotation": 2
    },
    {
      "x": 6,
      "y": 17,
      "z": 4,
      "name": "Wood_Aspen_Trunk_Full"
    },
    {
      "x": 6,
      "y": 18,
      "z": 4,
      "name": "Wood_Aspen_Branch_Long"
    },
    {
      "x": 6,
      "y": 19,
      "z": 4,
      "name": "Wood_Aspen_Branch_Long"
    },
    {
      "x": 6,
      "y": 20,
      "z": 4,
      "name": "Wood_Aspen_Branch_Long"
    },
    {
      "x": 6,
      "y": 21,
      "z": 4,
      "name": "Wood_Aspen_Branch_Long"
    },
    {
      "x": 6,
      "y": 23,
      "z": 4,
      "name": "Wood_Aspen_Branch_Corner",
      "rotation": 2
    },
    {
      "x": 6,
      "y": 24,
      "z": 4,
      "name": "Wood_Aspen_Branch_Long"
    },
    {
      "x": 6,
      "y": 25,
      "z": 4,
      "name": "Wood_Aspen_Branch_Long"
    },
    {
      "x": 6,
      "y": 26,
      "z": 4,
      "name": "Wood_Aspen_Branch_Long"
    },
    {
      "x": 6,
      "y": 27,
      "z": 4,
      "name": "Plant_Leaves_Aspen"
    },
    {
      "x": 6,
      "y": 28,
      "z": 4,
      "name": "Plant_Leaves_Aspen"
    },
    {
      "x": 6,
      "y": 29,
      "z": 4,
      "name": "Plant_Leaves_Aspen"
    },
    {
      "x": 6,
      "y": 4,
      "z": 5,
      "name": "Wood_Aspen_Trunk"
    },
    {
      "x": 6,
      "y": 5,
      "z": 5,
      "name": "Wood_Aspen_Trunk"
    },
    {
      "x": 6,
      "y": 6,
      "z": 5,
      "name": "Wood_Aspen_Trunk"
    },
    {
      "x": 6,
      "y": 7,
      "z": 5,
      "name": "Wood_Aspen_Trunk"
    },
    {
      "x": 6,
      "y": 8,
      "z": 5,
      "name": "Wood_Aspen_Trunk"
    },
    {
      "x": 6,
      "y": 9,
      "z": 5,
      "name": "Wood_Aspen_Trunk"
    },
    {
      "x": 6,
      "y": 10,
      "z": 5,
      "name": "Wood_Aspen_Trunk"
    },
    {
      "x": 6,
      "y": 11,
      "z": 5,
      "name": "Wood_Aspen_Trunk"
    },
    {
      "x": 6,
      "y": 12,
      "z": 5,
      "name": "Wood_Aspen_Trunk"
    },
    {
      "x": 6,
      "y": 13,
      "z": 5,
      "name": "Wood_Aspen_Trunk"
    },
    {
      "x": 6,
      "y": 14,
      "z": 5,
      "name": "Wood_Aspen_Trunk"
    },
    {
      "x": 6,
      "y": 15,
      "z": 5,
      "name": "Wood_Aspen_Trunk"
    },
    {
      "x": 6,
      "y": 16,
      "z": 5,
      "name": "Wood_Aspen_Trunk"
    },
    {
      "x": 6,
      "y": 17,
      "z": 5,
      "name": "Wood_Aspen_Trunk"
    },
    {
      "x": 6,
      "y": 18,
      "z": 5,
      "name": "Wood_Aspen_Trunk"
    },
    {
      "x": 6,
      "y": 19,
      "z": 5,
      "name": "Wood_Aspen_Trunk"
    },
    {
      "x": 6,
      "y": 20,
      "z": 5,
      "name": "Wood_Aspen_Trunk"
    },
    {
      "x": 6,
      "y": 21,
      "z": 5,
      "name": "Wood_Aspen_Trunk"
    },
    {
      "x": 6,
      "y": 22,
      "z": 5,
      "name": "Wood_Aspen_Trunk_Full"
    },
    {
      "x": 6,
      "y": 23,
      "z": 5,
      "name": "Wood_Aspen_Trunk_Full"
    },
    {
      "x": 6,
      "y": 24,
      "z": 5,
      "name": "Wood_Aspen_Branch_Long"
    },
    {
      "x": 6,
      "y": 25,
      "z": 5,
      "name": "Wood_Aspen_Branch_Long"
    },
    {
      "x": 6,
      "y": 26,
      "z": 5,
      "name": "Wood_Aspen_Branch_Long"
    },
    {
      "x": 6,
      "y": 27,
      "z": 5,
      "name": "Wood_Aspen_Branch_Long"
    },
    {
      "x": 6,
      "y": 28,
      "z": 5,
      "name": "Wood_Aspen_Branch_Long"
    },
    {
      "x": 6,
      "y": 29,
      "z": 5,
      "name": "Plant_Leaves_Aspen"
    },
    {
      "x": 6,
      "y": 16,
      "z": 6,
      "name": "Wood_Aspen_Branch_Short"
    },
    {
      "x": 6,
      "y": 18,
      "z": 6,
      "name": "Wood_Aspen_Trunk_Full"
    },
    {
      "x": 6,
      "y": 27,
      "z": 6,
      "name": "Plant_Leaves_Aspen"
    },
    {
      "x": 6,
      "y": 28,
      "z": 6,
      "name": "Plant_Leaves_Aspen"
    },
    {
      "x": 6,
      "y": 18,
      "z": 7,
      "name": "Wood_Aspen_Trunk_Full"
    },
    {
      "x": 6,
      "y": 19,
      "z": 7,
      "name": "Wood_Aspen_Branch_Long"
    },
    {
      "x": 6,
      "y": 20,
      "z": 7,
      "name": "Wood_Aspen_Branch_Long"
    },
    {
      "x": 6,
      "y": 21,
      "z": 7,
      "name": "Wood_Aspen_Branch_Long"
    },
    {
      "x": 6,
      "y": 22,
      "z": 7,
      "name": "Wood_Aspen_Branch_Long"
    },
    {
      "x": 6,
      "y": 23,
      "z": 7,
      "name": "Plant_Leaves_Aspen"
    },
    {
      "x": 6,
      "y": 24,
      "z": 7,
      "name": "Plant_Leaves_Aspen"
    },
    {
      "x": 6,
      "y": 25,
      "z": 7,
      "name": "Plant_Leaves_Aspen"
    },
    {
      "x": 6,
      "y": 16,
      "z": 8,
      "name": "Plant_Leaves_Aspen"
    },
    {
      "x": 6,
      "y": 17,
      "z": 8,
      "name": "Plant_Leaves_Aspen"
    },
    {
      "x": 6,
      "y": 18,
      "z": 8,
      "name": "Wood_Aspen_Branch_Corner"
    },
    {
      "x": 6,
      "y": 19,
      "z": 8,
      "name": "Wood_Aspen_Branch_Long"
    },
    {
      "x": 6,
      "y": 20,
      "z": 8,
      "name": "Wood_Aspen_Branch_Long"
    },
    {
      "x": 6,
      "y": 22,
      "z": 8,
      "name": "Plant_Leaves_Aspen"
    },
    {
      "x": 6,
      "y": 23,
      "z": 8,
      "name": "Plant_Leaves_Aspen"
    },
    {
      "x": 6,
      "y": 24,
      "z": 8,
      "name": "Plant_Leaves_Aspen"
    },
    {
      "x": 6,
      "y": 17,
      "z": 9,
      "name": "Plant_Leaves_Aspen"
    },
    {
      "x": 6,
      "y": 18,
      "z": 9,
      "name": "Plant_Leaves_Aspen"
    },
    {
      "x": 6,
      "y": 19,
      "z": 9,
      "name": "Plant_Leaves_Aspen"
    },
    {
      "x": 6,
      "y": 20,
      "z": 9,
      "name": "Plant_Leaves_Aspen"
    },
    {
      "x": 6,
      "y": 21,
      "z": 9,
      "name": "Plant_Leaves_Aspen"
    },
    {
      "x": 6,
      "y": 22,
      "z": 9,
      "name": "Plant_Leaves_Aspen"
    },
    {
      "x": 6,
      "y": 19,
      "z": 10,
      "name": "Plant_Leaves_Aspen"
    },
    {
      "x": 7,
      "y": 19,
      "z": 2,
      "name": "Plant_Leaves_Aspen"
    },
    {
      "x": 7,
      "y": 20,
      "z": 2,
      "name": "Plant_Leaves_Aspen"
    },
    {
      "x": 7,
      "y": 22,
      "z": 2,
      "name": "Plant_Leaves_Aspen"
    },
    {
      "x": 7,
      "y": 17,
      "z": 3,
      "name": "Plant_Leaves_Aspen"
    },
    {
      "x": 7,
      "y": 18,
      "z": 3,
      "name": "Plant_Leaves_Aspen"
    },
    {
      "x": 7,
      "y": 19,
      "z": 3,
      "name": "Plant_Leaves_Aspen"
    },
    {
      "x": 7,
      "y": 20,
      "z": 3,
      "name": "Plant_Leaves_Aspen"
    },
    {
      "x": 7,
      "y": 22,
      "z": 3,
      "name": "Plant_Leaves_Aspen"
    },
    {
      "x": 7,
      "y": 23,
      "z": 3,
      "name": "Plant_Leaves_Aspen"
    },
    {
      "x": 7,
      "y": 25,
      "z": 3,
      "name": "Plant_Leaves_Aspen"
    },
    {
      "x": 7,
      "y": 26,
      "z": 3,
      "name": "Plant_Leaves_Aspen"
    },
    {
      "x": 7,
      "y": 27,
      "z": 4,
      "name": "Plant_Leaves_Aspen"
    },
    {
      "x": 7,
      "y": 28,
      "z": 4,
      "name": "Plant_Leaves_Aspen"
    },
    {
      "x": 7,
      "y": 10,
      "z": 5,
      "name": "Wood_Aspen_Branch_Short",
      "rotation": 1
    },
    {
      "x": 7,
      "y": 17,
      "z": 5,
      "name": "Wood_Aspen_Trunk_Full"
    },
    {
      "x": 7,
      "y": 26,
      "z": 5,
      "name": "Plant_Leaves_Aspen"
    },
    {
      "x": 7,
      "y": 27,
      "z": 5,
      "name": "Plant_Leaves_Aspen"
    },
    {
      "x": 7,
      "y": 28,
      "z": 5,
      "name": "Plant_Leaves_Aspen"
    },
    {
      "x": 7,
      "y": 29,
      "z": 5,
      "name": "Plant_Leaves_Aspen"
    },
    {
      "x": 7,
      "y": 17,
      "z": 6,
      "name": "Wood_Aspen_Branch_Corner"
    },
    {
      "x": 7,
      "y": 18,
      "z": 6,
      "name": "Wood_Aspen_Branch_Long"
    },
    {
      "x": 7,
      "y": 19,
      "z": 6,
      "name": "Wood_Aspen_Branch_Long"
    },
    {
      "x": 7,
      "y": 20,
      "z": 6,
      "name": "Wood_Aspen_Branch_Long"
    },
    {
      "x": 7,
      "y": 21,
      "z": 6,
      "name": "Plant_Leaves_Aspen"
    },
    {
      "x": 7,
      "y": 22,
      "z": 6,
      "name": "Plant_Leaves_Aspen"
    },
    {
      "x": 7,
      "y": 26,
      "z": 6,
      "name": "Plant_Leaves_Aspen"
    },
    {
      "x": 7,
      "y": 27,
      "z": 6,
      "name": "Plant_Leaves_Aspen"
    },
    {
      "x": 7,
      "y": 17,
      "z": 7,
      "name": "Plant_Leaves_Aspen"
    },
    {
      "x": 7,
      "y": 18,
      "z": 7,
      "name": "Plant_Leaves_Aspen"
    },
    {
      "x": 7,
      "y": 19,
      "z": 7,
      "name": "Plant_Leaves_Aspen"
    },
    {
      "x": 7,
      "y": 20,
      "z": 7,
      "name": "Plant_Leaves_Aspen"
    },
    {
      "x": 7,
      "y": 21,
      "z": 7,
      "name": "Plant_Leaves_Aspen"
    },
    {
      "x": 7,
      "y": 23,
      "z": 7,
      "name": "Plant_Leaves_Aspen"
    },
    {
      "x": 7,
      "y": 24,
      "z": 7,
      "name": "Plant_Leaves_Aspen"
    },
    {
      "x": 7,
      "y": 20,
      "z": 8,
      "name": "Plant_Leaves_Aspen"
    },
    {
      "x": 7,
      "y": 21,
      "z": 8,
      "name": "Plant_Leaves_Aspen"
    },
    {
      "x": 7,
      "y": 22,
      "z": 8,
      "name": "Plant_Leaves_Aspen"
    },
    {
      "x": 7,
      "y": 17,
      "z": 9,
      "name": "Plant_Leaves_Aspen"
    },
    {
      "x": 7,
      "y": 18,
      "z": 9,
      "name": "Plant_Leaves_Aspen"
    },
    {
      "x": 8,
      "y": 17,
      "z": 3,
      "name": "Plant_Leaves_Aspen"
    },
    {
      "x": 8,
      "y": 19,
      "z": 3,
      "name": "Plant_Leaves_Aspen"
    },
    {
      "x": 8,
      "y": 20,
      "z": 3,
      "name": "Plant_Leaves_Aspen"
    },
    {
      "x": 8,
      "y": 21,
      "z": 3,
      "name": "Plant_Leaves_Aspen"
    },
    {
      "x": 8,
      "y": 22,
      "z": 3,
      "name": "Plant_Leaves_Aspen"
    },
    {
      "x": 8,
      "y": 17,
      "z": 4,
      "name": "Plant_Leaves_Aspen"
    },
    {
      "x": 8,
      "y": 18,
      "z": 4,
      "name": "Wood_Aspen_Branch_Corner",
      "rotation": 2
    },
    {
      "x": 8,
      "y": 19,
      "z": 4,
      "name": "Wood_Aspen_Branch_Long"
    },
    {
      "x": 8,
      "y": 20,
      "z": 4,
      "name": "Wood_Aspen_Branch_Long"
    },
    {
      "x": 8,
      "y": 21,
      "z": 4,
      "name": "Plant_Leaves_Aspen"
    },
    {
      "x": 8,
      "y": 22,
      "z": 4,
      "name": "Plant_Leaves_Aspen"
    },
    {
      "x": 8,
      "y": 23,
      "z": 4,
      "name": "Plant_Leaves_Aspen"
    },
    {
      "x": 8,
      "y": 15,
      "z": 5,
      "name": "Plant_Leaves_Aspen"
    },
    {
      "x": 8,
      "y": 16,
      "z": 5,
      "name": "Plant_Leaves_Aspen"
    },
    {
      "x": 8,
      "y": 17,
      "z": 5,
      "name": "Wood_Aspen_Trunk_Full"
    },
    {
      "x": 8,
      "y": 18,
      "z": 5,
      "name": "Wood_Aspen_Trunk_Full"
    },
    {
      "x": 8,
      "y": 19,
      "z": 5,
      "name": "Wood_Aspen_Branch_Long"
    },
    {
      "x": 8,
      "y": 20,
      "z": 5,
      "name": "Wood_Aspen_Branch_Long"
    },
    {
      "x": 8,
      "y": 21,
      "z": 5,
      "name": "Wood_Aspen_Branch_Long"
    },
    {
      "x": 8,
      "y": 22,
      "z": 5,
      "name": "Plant_Leaves_Aspen"
    },
    {
      "x": 8,
      "y": 23,
      "z": 5,
      "name": "Plant_Leaves_Aspen"
    },
    {
      "x": 8,
      "y": 24,
      "z": 5,
      "name": "Plant_Leaves_Aspen"
    },
    {
      "x": 8,
      "y": 27,
      "z": 5,
      "name": "Plant_Leaves_Aspen"
    },
    {
      "x": 8,
      "y": 17,
      "z": 6,
      "name": "Plant_Leaves_Aspen"
    },
    {
      "x": 8,
      "y": 18,
      "z": 6,
      "name": "Plant_Leaves_Aspen"
    },
    {
      "x": 8,
      "y": 19,
      "z": 6,
      "name": "Plant_Leaves_Aspen"
    },
    {
      "x": 8,
      "y": 26,
      "z": 6,
      "name": "Plant_Leaves_Aspen"
    },
    {
      "x": 8,
      "y": 17,
      "z": 7,
      "name": "Plant_Leaves_Aspen"
    },
    {
      "x": 8,
      "y": 19,
      "z": 8,
      "name": "Plant_Leaves_Aspen"
    },
    {
      "x": 8,
      "y": 20,
      "z": 8,
      "name": "Plant_Leaves_Aspen"
    },
    {
      "x": 9,
      "y": 18,
      "z": 3,
      "name": "Plant_Leaves_Aspen"
    },
    {
      "x": 9,
      "y": 19,
      "z": 3,
      "name": "Plant_Leaves_Aspen"
    },
    {
      "x": 9,
      "y": 20,
      "z": 3,
      "name": "Plant_Leaves_Aspen"
    },
    {
      "x": 9,
      "y": 16,
      "z": 4,
      "name": "Plant_Leaves_Aspen"
    },
    {
      "x": 9,
      "y": 17,
      "z": 4,
      "name": "Plant_Leaves_Aspen"
    },
    {
      "x": 9,
      "y": 18,
      "z": 4,
      "name": "Plant_Leaves_Aspen"
    },
    {
      "x": 9,
      "y": 19,
      "z": 4,
      "name": "Plant_Leaves_Aspen"
    },
    {
      "x": 9,
      "y": 20,
      "z": 4,
      "name": "Plant_Leaves_Aspen"
    },
    {
      "x": 9,
      "y": 21,
      "z": 4,
      "name": "Plant_Leaves_Aspen"
    },
    {
      "x": 9,
      "y": 22,
      "z": 4,
      "name": "Plant_Leaves_Aspen"
    },
    {
      "x": 9,
      "y": 16,
      "z": 5,
      "name": "Plant_Leaves_Aspen"
    },
    {
      "x": 9,
      "y": 17,
      "z": 5,
      "name": "Plant_Leaves_Aspen"
    },
    {
      "x": 9,
      "y": 18,
      "z": 5,
      "name": "Plant_Leaves_Aspen"
    },
    {
      "x": 9,
      "y": 19,
      "z": 5,
      "name": "Plant_Leaves_Aspen"
    },
    {
      "x": 9,
      "y": 20,
      "z": 5,
      "name": "Plant_Leaves_Aspen"
    },
    {
      "x": 9,
      "y": 21,
      "z": 5,
      "name": "Plant_Leaves_Aspen"
    },
    {
      "x": 9,
      "y": 22,
      "z": 5,
      "name": "Plant_Leaves_Aspen"
    },
    {
      "x": 9,
      "y": 15,
      "z": 6,
      "name": "Plant_Leaves_Aspen"
    },
    {
      "x": 9,
      "y": 16,
      "z": 6,
      "name": "Plant_Leaves_Aspen"
    },
    {
      "x": 9,
      "y": 17,
      "z": 6,
      "name": "Plant_Leaves_Aspen"
    },
    {
      "x": 9,
      "y": 19,
      "z": 6,
      "name": "Plant_Leaves_Aspen"
    },
    {
      "x": 10,
      "y": 20,
      "z": 5,
      "name": "Plant_Leaves_Aspen"
    },
    {
      "x": 10,
      "y": 17,
      "z": 6,
      "name": "Plant_Leaves_Aspen"
    }
  ]
}