{
  "version": 8,
  "blockIdVersion": 10,
  "anchorX": -1,
  "anchorY": 10,
  "anchorZ": 4,
  "blocks": [
    {
      "x": -15,
      "y": 33,
      "z": 0,
      "name": "Plant_Leaves_Crystal"
    },
    {
      "x": -15,
      "y": 33,
      "z": 1,
      "name": "Plant_Leaves_Crystal"
    },
    {
      "x": -15,
      "y": 36,
      "z": 1,
      "name": "Plant_Leaves_Crystal"
    },
    {
      "x": -15,
      "y": 33,
      "z": 2,
      "name": "Plant_Leaves_Crystal"
    },
    {
      "x": -15,
      "y": 36,
      "z": 2,
      "name": "Plant_Leaves_Crystal"
    },
    {
      "x": -15,
      "y": 33,
      "z": 3,
      "name": "Plant_Leaves_Crystal"
    },
    {
      "x": -15,
      "y": 34,
      "z": 3,
      "name": "Plant_Leaves_Crystal"
    },
    {
      "x": -15,
      "y": 36,
      "z": 3,
      "name": "Plant_Leaves_Crystal"
    },
    {
      "x": -14,
      "y": 32,
      "z": -1,
      "name": "Plant_Leaves_Crystal"
    },
    {
      "x": -14,
      "y": 33,
      "z": -1,
      "name": "Plant_Leaves_Crystal"
    },
    {
      "x": -14,
      "y": 33,
      "z": 0,
      "name": "Plant_Leaves_Crystal"
    },
    {
      "x": -14,
      "y": 36,
      "z": 0,
      "name": "Plant_Leaves_Crystal"
    },
    {
      "x": -14,
      "y": 32,
      "z": 1,
      "name": "Plant_Leaves_Crystal"
    },
    {
      "x": -14,
      "y": 33,
      "z": 1,
      "name": "Plant_Leaves_Crystal"
    },
    {
      "x": -14,
      "y": 34,
      "z": 1,
      "name": "Plant_Leaves_Crystal"
    },
    {
      "x": -14,
      "y": 36,
      "z": 1,
      "name": "Plant_Leaves_Crystal"
    },
    {
      "x": -14,
      "y": 33,
      "z": 2,
      "name": "Plant_Leaves_Crystal"
    },
    {
      "x": -14,
      "y": 36,
      "z": 2,
      "name": "Plant_Leaves_Crystal"
    },
    {
      "x": -14,
      "y": 32,
      "z": 3,
      "name": "Plant_Leaves_Crystal"
    },
    {
      "x": -14,
      "y": 33,
      "z": 3,
      "name": "Plant_Leaves_Crystal"
    },
    {
      "x": -14,
      "y": 34,
      "z": 3,
      "name": "Plant_Leaves_Crystal"
    },
    {
      "x": -14,
      "y": 36,
      "z": 3,
      "name": "Plant_Leaves_Crystal"
    },
    {
      "x": -14,
      "y": 37,
      "z": 3,
      "name": "Plant_Leaves_Crystal"
    },
    {
      "x": -14,
      "y": 32,
      "z": 4,
      "name": "Plant_Leaves_Crystal"
    },
    {
      "x": -14,
      "y": 33,
      "z": 4,
      "name": "Plant_Leaves_Crystal"
    },
    {
      "x": -14,
      "y": 36,
      "z": 4,
      "name": "Plant_Leaves_Crystal"
    },
    {
      "x": -13,
      "y": 32,
      "z": -1,
      "name": "Plant_Leaves_Crystal"
    },
    {
      "x": -13,
      "y": 33,
      "z": -1,
      "name": "Plant_Leaves_Crystal"
    },
    {
      "x": -13,
      "y": 34,
      "z": -1,
      "name": "Plant_Leaves_Crystal"
    },
    {
      "x": -13,
      "y": 35,
      "z": -1,
      "name": "Plant_Leaves_Crystal"
    },
    {
      "x": -13,
      "y": 36,
      "z": -1,
      "name": "Plant_Leaves_Crystal"
    },
    {
      "x": -13,
      "y": 32,
      "z": 0,
      "name": "Plant_Leaves_Crystal"
    },
    {
      "x": -13,
      "y": 33,
      "z": 0,
      "name": "Plant_Leaves_Crystal"
    },
    {
      "x": -13,
      "y": 36,
      "z": 0,
      "name": "Plant_Leaves_Crystal"
    },
    {
      "x": -13,
      "y": 33,
      "z": 1,
      "name": "Plant_Leaves_Crystal"
    },
    {
      "x": -13,
      "y": 34,
      "z": 1,
      "name": "Plant_Leaves_Crystal"
    },
    {
      "x": -13,
      "y": 35,
      "z": 1,
      "name": "Plant_Leaves_Crystal"
    },
    {
      "x": -13,
      "y": 36,
      "z": 1,
      "name": "Plant_Leaves_Crystal"
    },
    {
      "x": -13,
      "y": 37,
      "z": 1,
      "name": "Plant_Leaves_Crystal"
    },
    {
      "x": -13,
      "y": 33,
      "z": 2,
      "name": "Plant_Leaves_Crystal"
    },
    {
      "x": -13,
      "y": 34,
      "z": 2,
      "name": "Plant_Leaves_Crystal"
    },
    {
      "x": -13,
      "y": 35,
      "z": 2,
      "name": "Plant_Leaves_Crystal"
    },
    {
      "x": -13,
      "y": 36,
      "z": 2,
      "name": "Plant_Leaves_Crystal"
    },
    {
      "x": -13,
      "y": 32,
      "z": 3,
      "name": "Plant_Leaves_Crystal"
    },
    {
      "x": -13,
      "y": 33,
      "z": 3,
      "name": "Plant_Leaves_Crystal"
    },
    {
      "x": -13,
      "y": 34,
      "z": 3,
      "name": "Plant_Leaves_Crystal"
    },
    {
      "x": -13,
      "y": 35,
      "z": 3,
      "name": "Plant_Leaves_Crystal"
    },
    {
      "x": -13,
      "y": 36,
      "z": 3,
      "name": "Plant_Leaves_Crystal"
    },
    {
      "x": -13,
      "y": 37,
      "z": 3,
      "name": "Plant_Leaves_Crystal"
    },
    {
      "x": -13,
      "y": 32,
      "z": 4,
      "name": "Plant_Leaves_Crystal"
    },
    {
      "x": -13,
      "y": 33,
      "z": 4,
      "name": "Plant_Leaves_Crystal"
    },
    {
      "x": -13,
      "y": 34,
      "z": 4,
      "name": "Plant_Leaves_Crystal"
    },
    {
      "x": -13,
      "y": 35,
      "z": 4,
      "name": "Plant_Leaves_Crystal"
    },
    {
      "x": -13,
      "y": 36,
      "z": 4,
      "name": "Plant_Leaves_Crystal"
    },
    {
      "x": -13,
      "y": 33,
      "z": 5,
      "name": "Plant_Leaves_Crystal"
    },
    {
      "x": -13,
      "y": 34,
      "z": 5,
      "name": "Plant_Leaves_Crystal"
    },
    {
      "x": -13,
      "y": 36,
      "z": 5,
      "name": "Plant_Leaves_Crystal"
    },
    {
      "x": -13,
      "y": 34,
      "z": 10,
      "name": "Plant_Leaves_Crystal"
    },
    {
      "x": -13,
      "y": 34,
      "z": 11,
      "name": "Plant_Leaves_Crystal"
    },
    {
      "x": -13,
      "y": 34,
      "z": 12,
      "name": "Plant_Leaves_Crystal"
    },
    {
      "x": -12,
      "y": 33,
      "z": -2,
      "name": "Plant_Leaves_Crystal"
    },
    {
      "x": -12,
      "y": 33,
      "z": -1,
      "name": "Plant_Leaves_Crystal"
    },
    {
      "x": -12,
      "y": 35,
      "z": -1,
      "name": "Plant_Leaves_Crystal"
    },
    {
      "x": -12,
      "y": 36,
      "z": -1,
      "name": "Plant_Leaves_Crystal"
    },
    {
      "x": -12,
      "y": 32,
      "z": 0,
      "name": "Plant_Leaves_Crystal"
    },
    {
      "x": -12,
      "y": 33,
      "z": 0,
      "name": "Plant_Leaves_Crystal"
    },
    {
      "x": -12,
      "y": 34,
      "z": 0,
      "name": "Plant_Leaves_Crystal"
    },
    {
      "x": -12,
      "y": 35,
      "z": 0,
      "name": "Plant_Leaves_Crystal"
    },
    {
      "x": -12,
      "y": 36,
      "z": 0,
      "name": "Plant_Leaves_Crystal"
    },
    {
      "x": -12,
      "y": 32,
      "z": 1,
      "name": "Plant_Leaves_Crystal"
    },
    {
      "x": -12,
      "y": 33,
      "z": 1,
      "name": "Plant_Leaves_Crystal"
    },
    {
      "x": -12,
      "y": 34,
      "z": 1,
      "name": "Plant_Leaves_Crystal"
    },
    {
      "x": -12,
      "y": 35,
      "z": 1,
      "name": "Plant_Leaves_Crystal"
    },
    {
      "x": -12,
      "y": 36,
      "z": 1,
      "name": "Plant_Leaves_Crystal"
    },
    {
      "x": -12,
      "y": 37,
      "z": 1,
      "name": "Plant_Leaves_Crystal"
    },
    {
      "x": -12,
      "y": 33,
      "z": 2,
      "name": "Plant_Leaves_Crystal"
    },
    {
      "x": -12,
      "y": 34,
      "z": 2,
      "name": "Plant_Leaves_Crystal"
    },
    {
      "x": -12,
      "y": 35,
      "z": 2,
      "name": "Plant_Leaves_Crystal"
    },
    {
      "x": -12,
      "y": 36,
      "z": 2,
      "name": "Plant_Leaves_Crystal"
    },
    {
      "x": -12,
      "y": 37,
      "z": 2,
      "name": "Plant_Leaves_Crystal"
    },
    {
      "x": -12,
      "y": 38,
      "z": 2,
      "name": "Plant_Leaves_Crystal"
    },
    {
      "x": -12,
      "y": 32,
      "z": 3,
      "name": "Plant_Leaves_Crystal"
    },
    {
      "x": -12,
      "y": 33,
      "z": 3,
      "name": "Plant_Leaves_Crystal"
    },
    {
      "x": -12,
      "y": 34,
      "z": 3,
      "name": "Plant_Leaves_Crystal"
    },
    {
      "x": -12,
      "y": 35,
      "z": 3,
      "name": "Plant_Leaves_Crystal"
    },
    {
      "x": -12,
      "y": 36,
      "z": 3,
      "name": "Plant_Leaves_Crystal"
    },
    {
      "x": -12,
      "y": 37,
      "z": 3,
      "name": "Plant_Leaves_Crystal"
    },
    {
      "x": -12,
      "y": 38,
      "z": 3,
      "name": "Plant_Leaves_Crystal"
    },
    {
      "x": -12,
      "y": 33,
      "z": 4,
      "name": "Plant_Leaves_Crystal"
    },
    {
      "x": -12,
      "y": 34,
      "z": 4,
      "name": "Plant_Leaves_Crystal"
    },
    {
      "x": -12,
      "y": 35,
      "z": 4,
      "name": "Plant_Leaves_Crystal"
    },
    {
      "x": -12,
      "y": 36,
      "z": 4,
      "name": "Plant_Leaves_Crystal"
    },
    {
      "x": -12,
      "y": 37,
      "z": 4,
      "name": "Plant_Leaves_Crystal"
    },
    {
      "x": -12,
      "y": 33,
      "z": 5,
      "name": "Plant_Leaves_Crystal"
    },
    {
      "x": -12,
      "y": 34,
      "z": 5,
      "name": "Plant_Leaves_Crystal"
    },
    {
      "x": -12,
      "y": 36,
      "z": 5,
      "name": "Plant_Leaves_Crystal"
    },
    {
      "x": -12,
      "y": 37,
      "z": 5,
      "name": "Plant_Leaves_Crystal"
    },
    {
      "x": -12,
      "y": 33,
      "z": 6,
      "name": "Plant_Leaves_Crystal"
    },
    {
      "x": -12,
      "y": 34,
      "z": 6,
      "name": "Plant_Leaves_Crystal"
    },
    {
      "x": -12,
      "y": 36,
      "z": 6,
      "name": "Plant_Leaves_Crystal"
    },
    {
      "x": -12,
      "y": 33,
      "z": 8,
      "name": "Plant_Leaves_Crystal"
    },
    {
      "x": -12,
      "y": 34,
      "z": 8,
      "name": "Plant_Leaves_Crystal"
    },
    {
      "x": -12,
      "y": 34,
      "z": 9,
      "name": "Plant_Leaves_Crystal"
    },
    {
      "x": -12,
      "y": 34,
      "z": 10,
      "name": "Plant_Leaves_Crystal"
    },
    {
      "x": -12,
      "y": 33,
      "z": 11,
      "name": "Plant_Leaves_Crystal"
    },
    {
      "x": -12,
      "y": 34,
      "z": 11,
      "name": "Plant_Leaves_Crystal"
    },
    {
      "x": -12,
      "y": 35,
      "z": 11,
      "name": "Plant_Leaves_Crystal"
    },
    {
      "x": -12,
      "y": 34,
      "z": 12,
      "name": "Plant_Leaves_Crystal"
    },
    {
      "x": -12,
      "y": 33,
      "z": 13,
      "name": "Plant_Leaves_Crystal"
    },
    {
      "x": -11,
      "y": 33,
      "z": -4,
      "name": "Plant_Leaves_Crystal"
    },
    {
      "x": -11,
      "y": 33,
      "z": -3,
      "name": "Plant_Leaves_Crystal"
    },
    {
      "x": -11,
      "y": 33,
      "z": -2,
      "name": "Plant_Leaves_Crystal"
    },
    {
      "x": -11,
      "y": 34,
      "z": -2,
      "name": "Plant_Leaves_Crystal"
    },
    {
      "x": -11,
      "y": 36,
      "z": -2,
      "name": "Plant_Leaves_Crystal"
    },
    {
      "x": -11,
      "y": 32,
      "z": -1,
      "name": "Wood_Crystal_Branch_Corner",
      "rotation": 2
    },
    {
      "x": -11,
      "y": 33,
      "z": -1,
      "name": "Plant_Leaves_Crystal"
    },
    {
      "x": -11,
      "y": 34,
      "z": -1,
      "name": "Plant_Leaves_Crystal"
    },
    {
      "x": -11,
      "y": 36,
      "z": -1,
      "name": "Plant_Leaves_Crystal"
    },
    {
      "x": -11,
      "y": 32,
      "z": 0,
      "name": "Wood_Crystal_Branch_Long",
      "rotation": 4
    },
    {
      "x": -11,
      "y": 34,
      "z": 0,
      "name": "Plant_Leaves_Crystal"
    },
    {
      "x": -11,
      "y": 35,
      "z": 0,
      "name": "Plant_Leaves_Crystal"
    },
    {
      "x": -11,
      "y": 36,
      "z": 0,
      "name": "Plant_Leaves_Crystal"
    },
    {
      "x": -11,
      "y": 37,
      "z": 0,
      "name": "Plant_Leaves_Crystal"
    },
    {
      "x": -11,
      "y": 32,
      "z": 1,
      "name": "Wood_Crystal_Branch_Long",
      "rotation": 4
    },
    {
      "x": -11,
      "y": 33,
      "z": 1,
      "name": "Plant_Leaves_Crystal"
    },
    {
      "x": -11,
      "y": 34,
      "z": 1,
      "name": "Plant_Leaves_Crystal"
    },
    {
      "x": -11,
      "y": 35,
      "z": 1,
      "name": "Plant_Leaves_Crystal"
    },
    {
      "x": -11,
      "y": 36,
      "z": 1,
      "name": "Plant_Leaves_Crystal"
    },
    {
      "x": -11,
      "y": 37,
      "z": 1,
      "name": "Plant_Leaves_Crystal"
    },
    {
      "x": -11,
      "y": 38,
      "z": 1,
      "name": "Plant_Leaves_Crystal"
    },
    {
      "x": -11,
      "y": 31,
      "z": 2,
      "name": "Wood_Crystal_Roots"
    },
    {
      "x": -11,
      "y": 32,
      "z": 2,
      "name": "Wood_Crystal_Trunk_Full"
    },
    {
      "x": -11,
      "y": 33,
      "z": 2,
      "name": "Plant_Leaves_Crystal"
    },
    {
      "x": -11,
      "y": 34,
      "z": 2,
      "name": "Plant_Leaves_Crystal"
    },
    {
      "x": -11,
      "y": 35,
      "z": 2,
      "name": "Wood_Crystal_Trunk_Full"
    },
    {
      "x": -11,
      "y": 36,
      "z": 2,
      "name": "Plant_Leaves_Crystal"
    },
    {
      "x": -11,
      "y": 37,
      "z": 2,
      "name": "Plant_Leaves_Crystal"
    },
    {
      "x": -11,
      "y": 38,
      "z": 2,
      "name": "Plant_Leaves_Crystal"
    },
    {
      "x": -11,
      "y": 31,
      "z": 3,
      "name": "Plant_Fruit_Pinkberry",
      "rotation": 8
    },
    {
      "x": -11,
      "y": 32,
      "z": 3,
      "name": "Plant_Leaves_Crystal"
    },
    {
      "x": -11,
      "y": 33,
      "z": 3,
      "name": "Plant_Leaves_Crystal"
    },
    {
      "x": -11,
      "y": 35,
      "z": 3,
      "name": "Plant_Leaves_Crystal"
    },
    {
      "x": -11,
      "y": 36,
      "z": 3,
      "name": "Plant_Leaves_Crystal"
    },
    {
      "x": -11,
      "y": 37,
      "z": 3,
      "name": "Plant_Leaves_Crystal"
    },
    {
      "x": -11,
      "y": 38,
      "z": 3,
      "name": "Plant_Leaves_Crystal"
    },
    {
      "x": -11,
      "y": 33,
      "z": 4,
      "name": "Plant_Leaves_Crystal"
    },
    {
      "x": -11,
      "y": 34,
      "z": 4,
      "name": "Plant_Leaves_Crystal"
    },
    {
      "x": -11,
      "y": 35,
      "z": 4,
      "name": "Plant_Leaves_Crystal"
    },
    {
      "x": -11,
      "y": 36,
      "z": 4,
      "name": "Plant_Leaves_Crystal"
    },
    {
      "x": -11,
      "y": 37,
      "z": 4,
      "name": "Plant_Leaves_Crystal"
    },
    {
      "x": -11,
      "y": 32,
      "z": 5,
      "name": "Plant_Leaves_Crystal"
    },
    {
      "x": -11,
      "y": 33,
      "z": 5,
      "name": "Plant_Leaves_Crystal"
    },
    {
      "x": -11,
      "y": 36,
      "z": 5,
      "name": "Plant_Leaves_Crystal"
    },
    {
      "x": -11,
      "y": 37,
      "z": 5,
      "name": "Plant_Leaves_Crystal"
    },
    {
      "x": -11,
      "y": 32,
      "z": 6,
      "name": "Plant_Leaves_Crystal"
    },
    {
      "x": -11,
      "y": 33,
      "z": 6,
      "name": "Plant_Leaves_Crystal"
    },
    {
      "x": -11,
      "y": 36,
      "z": 6,
      "name": "Plant_Leaves_Crystal"
    },
    {
      "x": -11,
      "y": 33,
      "z": 7,
      "name": "Plant_Leaves_Crystal"
    },
    {
      "x": -11,
      "y": 34,
      "z": 7,
      "name": "Plant_Leaves_Crystal"
    },
    {
      "x": -11,
      "y": 32,
      "z": 8,
      "name": "Plant_Leaves_Crystal"
    },
    {
      "x": -11,
      "y": 33,
      "z": 8,
      "name": "Plant_Leaves_Crystal"
    },
    {
      "x": -11,
      "y": 34,
      "z": 8,
      "name": "Plant_Leaves_Crystal"
    },
    {
      "x": -11,
      "y": 32,
      "z": 9,
      "name": "Plant_Leaves_Crystal"
    },
    {
      "x": -11,
      "y": 33,
      "z": 9,
      "name": "Plant_Leaves_Crystal"
    },
    {
      "x": -11,
      "y": 34,
      "z": 9,
      "name": "Plant_Leaves_Crystal"
    },
    {
      "x": -11,
      "y": 35,
      "z": 9,
      "name": "Plant_Leaves_Crystal"
    },
    {
      "x": -11,
      "y": 34,
      "z": 10,
      "name": "Plant_Leaves_Crystal"
    },
    {
      "x": -11,
      "y": 35,
      "z": 10,
      "name": "Plant_Leaves_Crystal"
    },
    {
      "x": -11,
      "y": 34,
      "z": 11,
      "name": "Plant_Leaves_Crystal"
    },
    {
      "x": -11,
      "y": 35,
      "z": 11,
      "name": "Plant_Leaves_Crystal"
    },
    {
      "x": -11,
      "y": 33,
      "z": 12,
      "name": "Plant_Leaves_Crystal"
    },
    {
      "x": -11,
      "y": 34,
      "z": 12,
      "name": "Plant_Leaves_Crystal"
    },
    {
      "x": -11,
      "y": 33,
      "z": 13,
      "name": "Plant_Leaves_Crystal"
    },
    {
      "x": -11,
      "y": 34,
      "z": 13,
      "name": "Plant_Leaves_Crystal"
    },
    {
      "x": -11,
      "y": 34,
      "z": 14,
      "name": "Plant_Leaves_Crystal"
    },
    {
      "x": -10,
      "y": 32,
      "z": -5,
      "name": "Plant_Leaves_Crystal"
    },
    {
      "x": -10,
      "y": 33,
      "z": -5,
      "name": "Plant_Leaves_Crystal"
    },
    {
      "x": -10,
      "y": 33,
      "z": -4,
      "name": "Plant_Leaves_Crystal"
    },
    {
      "x": -10,
      "y": 36,
      "z": -4,
      "name": "Plant_Leaves_Crystal"
    },
    {
      "x": -10,
      "y": 32,
      "z": -3,
      "name": "Plant_Leaves_Crystal"
    },
    {
      "x": -10,
      "y": 33,
      "z": -3,
      "name": "Plant_Leaves_Crystal"
    },
    {
      "x": -10,
      "y": 34,
      "z": -3,
      "name": "Plant_Leaves_Crystal"
    },
    {
      "x": -10,
      "y": 36,
      "z": -3,
      "name": "Plant_Leaves_Crystal"
    },
    {
      "x": -10,
      "y": 32,
      "z": -2,
      "name": "Wood_Crystal_Branch_Corner",
      "rotation": 3
    },
    {
      "x": -10,
      "y": 33,
      "z": -2,
      "name": "Plant_Leaves_Crystal"
    },
    {
      "x": -10,
      "y": 34,
      "z": -2,
      "name": "Plant_Leaves_Crystal"
    },
    {
      "x": -10,
      "y": 35,
      "z": -2,
      "name": "Plant_Leaves_Crystal"
    },
    {
      "x": -10,
      "y": 36,
      "z": -2,
      "name": "Plant_Leaves_Crystal"
    },
    {
      "x": -10,
      "y": 37,
      "z": -2,
      "name": "Plant_Leaves_Crystal"
    },
    {
      "x": -10,
      "y": 38,
      "z": -2,
      "name": "Plant_Leaves_Crystal"
    },
    {
      "x": -10,
      "y": 33,
      "z": -1,
      "name": "Plant_Leaves_Crystal"
    },
    {
      "x": -10,
      "y": 34,
      "z": -1,
      "name": "Plant_Leaves_Crystal"
    },
    {
      "x": -10,
      "y": 36,
      "z": -1,
      "name": "Plant_Leaves_Crystal"
    },
    {
      "x": -10,
      "y": 37,
      "z": -1,
      "name": "Plant_Leaves_Crystal"
    },
    {
      "x": -10,
      "y": 38,
      "z": -1,
      "name": "Plant_Leaves_Crystal"
    },
    {
      "x": -10,
      "y": 32,
      "z": 0,
      "name": "Plant_Fruit_Pinkberry",
      "rotation": 8
    },
    {
      "x": -10,
      "y": 33,
      "z": 0,
      "name": "Plant_Leaves_Crystal"
    },
    {
      "x": -10,
      "y": 35,
      "z": 0,
      "name": "Plant_Leaves_Crystal"
    },
    {
      "x": -10,
      "y": 37,
      "z": 0,
      "name": "Plant_Leaves_Crystal"
    },
    {
      "x": -10,
      "y": 38,
      "z": 0,
      "name": "Plant_Leaves_Crystal"
    },
    {
      "x": -10,
      "y": 33,
      "z": 1,
      "name": "Plant_Leaves_Crystal"
    },
    {
      "x": -10,
      "y": 35,
      "z": 1,
      "name": "Plant_Leaves_Crystal"
    },
    {
      "x": -10,
      "y": 36,
      "z": 1,
      "name": "Plant_Leaves_Crystal"
    },
    {
      "x": -10,
      "y": 37,
      "z": 1,
      "name": "Plant_Leaves_Crystal"
    },
    {
      "x": -10,
      "y": 38,
      "z": 1,
      "name": "Plant_Leaves_Crystal"
    },
    {
      "x": -10,
      "y": 32,
      "z": 2,
      "name": "Wood_Crystal_Trunk_Full"
    },
    {
      "x": -10,
      "y": 33,
      "z": 2,
      "name": "Plant_Leaves_Crystal"
    },
    {
      "x": -10,
      "y": 34,
      "z": 2,
      "name": "Plant_Leaves_Crystal"
    },
    {
      "x": -10,
      "y": 35,
      "z": 2,
      "name": "Wood_Crystal_Trunk_Full"
    },
    {
      "x": -10,
      "y": 36,
      "z": 2,
      "name": "Plant_Leaves_Crystal"
    },
    {
      "x": -10,
      "y": 37,
      "z": 2,
      "name": "Plant_Leaves_Crystal"
    },
    {
      "x": -10,
      "y": 38,
      "z": 2,
      "name": "Plant_Leaves_Crystal"
    },
    {
      "x": -10,
      "y": 32,
      "z": 3,
      "name": "Wood_Crystal_Trunk_Full"
    },
    {
      "x": -10,
      "y": 33,
      "z": 3,
      "name": "Plant_Leaves_Crystal"
    },
    {
      "x": -10,
      "y": 34,
      "z": 3,
      "name": "Plant_Leaves_Crystal"
    },
    {
      "x": -10,
      "y": 35,
      "z": 3,
      "name": "Plant_Leaves_Crystal"
    },
    {
      "x": -10,
      "y": 36,
      "z": 3,
      "name": "Plant_Leaves_Crystal"
    },
    {
      "x": -10,
      "y": 38,
      "z": 3,
      "name": "Plant_Leaves_Crystal"
    },
    {
      "x": -10,
      "y": 28,
      "z": 4,
      "name": "Plant_Leaves_Crystal"
    },
    {
      "x": -10,
      "y": 32,
      "z": 4,
      "name": "Plant_Leaves_Crystal"
    },
    {
      "x": -10,
      "y": 33,
      "z": 4,
      "name": "Plant_Leaves_Crystal"
    },
    {
      "x": -10,
      "y": 34,
      "z": 4,
      "name": "Plant_Leaves_Crystal"
    },
    {
      "x": -10,
      "y": 35,
      "z": 4,
      "name": "Plant_Leaves_Crystal"
    },
    {
      "x": -10,
      "y": 36,
      "z": 4,
      "name": "Plant_Leaves_Crystal"
    },
    {
      "x": -10,
      "y": 37,
      "z": 4,
      "name": "Plant_Leaves_Crystal"
    },
    {
      "x": -10,
      "y": 38,
      "z": 4,
      "name": "Plant_Leaves_Crystal"
    },
    {
      "x": -10,
      "y": 28,
      "z": 5,
      "name": "Plant_Leaves_Crystal"
    },
    {
      "x": -10,
      "y": 33,
      "z": 5,
      "name": "Plant_Leaves_Crystal"
    },
    {
      "x": -10,
      "y": 34,
      "z": 5,
      "name": "Plant_Leaves_Crystal"
    },
    {
      "x": -10,
      "y": 35,
      "z": 5,
      "name": "Plant_Leaves_Crystal"
    },
    {
      "x": -10,
      "y": 36,
      "z": 5,
      "name": "Plant_Leaves_Crystal"
    },
    {
      "x": -10,
      "y": 28,
      "z": 6,
      "name": "Plant_Leaves_Crystal"
    },
    {
      "x": -10,
      "y": 33,
      "z": 6,
      "name": "Plant_Leaves_Crystal"
    },
    {
      "x": -10,
      "y": 35,
      "z": 6,
      "name": "Plant_Leaves_Crystal"
    },
    {
      "x": -10,
      "y": 36,
      "z": 6,
      "name": "Plant_Leaves_Crystal"
    },
    {
      "x": -10,
      "y": 24,
      "z": 7,
      "name": "Plant_Leaves_Crystal"
    },
    {
      "x": -10,
      "y": 25,
      "z": 7,
      "name": "Plant_Leaves_Crystal"
    },
    {
      "x": -10,
      "y": 26,
      "z": 7,
      "name": "Plant_Leaves_Crystal"
    },
    {
      "x": -10,
      "y": 27,
      "z": 7,
      "name": "Plant_Leaves_Crystal"
    },
    {
      "x": -10,
      "y": 28,
      "z": 7,
      "name": "Plant_Leaves_Crystal"
    },
    {
      "x": -10,
      "y": 33,
      "z": 7,
      "name": "Plant_Leaves_Crystal"
    },
    {
      "x": -10,
      "y": 34,
      "z": 7,
      "name": "Plant_Leaves_Crystal"
    },
    {
      "x": -10,
      "y": 36,
      "z": 7,
      "name": "Plant_Leaves_Crystal"
    },
    {
      "x": -10,
      "y": 32,
      "z": 8,
      "name": "Plant_Leaves_Crystal"
    },
    {
      "x": -10,
      "y": 33,
      "z": 8,
      "name": "Plant_Leaves_Crystal"
    },
    {
      "x": -10,
      "y": 34,
      "z": 8,
      "name": "Plant_Leaves_Crystal"
    },
    {
      "x": -10,
      "y": 34,
      "z": 9,
      "name": "Plant_Leaves_Crystal"
    },
    {
      "x": -10,
      "y": 35,
      "z": 9,
      "name": "Plant_Leaves_Crystal"
    },
    {
      "x": -10,
      "y": 36,
      "z": 9,
      "name": "Plant_Leaves_Crystal"
    },
    {
      "x": -10,
      "y": 34,
      "z": 10,
      "name": "Plant_Leaves_Crystal"
    },
    {
      "x": -10,
      "y": 35,
      "z": 10,
      "name": "Plant_Leaves_Crystal"
    },
    {
      "x": -10,
      "y": 34,
      "z": 11,
      "name": "Plant_Leaves_Crystal"
    },
    {
      "x": -10,
      "y": 35,
      "z": 11,
      "name": "Plant_Leaves_Crystal"
    },
    {
      "x": -10,
      "y": 33,
      "z": 12,
      "name": "Plant_Leaves_Crystal"
    },
    {
      "x": -10,
      "y": 34,
      "z": 12,
      "name": "Plant_Leaves_Crystal"
    },
    {
      "x": -10,
      "y": 35,
      "z": 12,
      "name": "Plant_Leaves_Crystal"
    },
    {
      "x": -10,
      "y": 30,
      "z": 13,
      "name": "Plant_Leaves_Crystal"
    },
    {
      "x": -10,
      "y": 31,
      "z": 13,
      "name": "Plant_Leaves_Crystal"
    },
    {
      "x": -10,
      "y": 32,
      "z": 13,
      "name": "Plant_Leaves_Crystal"
    },
    {
      "x": -10,
      "y": 33,
      "z": 13,
      "name": "Plant_Leaves_Crystal"
    },
    {
      "x": -10,
      "y": 34,
      "z": 13,
      "name": "Plant_Leaves_Crystal"
    },
    {
      "x": -10,
      "y": 35,
      "z": 13,
      "name": "Plant_Leaves_Crystal"
    },
    {
      "x": -10,
      "y": 34,
      "z": 14,
      "name": "Plant_Leaves_Crystal"
    },
    {
      "x": -10,
      "y": 34,
      "z": 15,
      "name": "Plant_Leaves_Crystal"
    },
    {
      "x": -10,
      "y": 34,
      "z": 16,
      "name": "Plant_Leaves_Crystal"
    },
    {
      "x": -9,
      "y": 32,
      "z": -5,
      "name": "Plant_Leaves_Crystal"
    },
    {
      "x": -9,
      "y": 33,
      "z": -5,
      "name": "Plant_Leaves_Crystal"
    },
    {
      "x": -9,
      "y": 34,
      "z": -5,
      "name": "Plant_Leaves_Crystal"
    },
    {
      "x": -9,
      "y": 35,
      "z": -5,
      "name": "Plant_Leaves_Crystal"
    },
    {
      "x": -9,
      "y": 36,
      "z": -5,
      "name": "Plant_Leaves_Crystal"
    },
    {
      "x": -9,
      "y": 33,
      "z": -4,
      "name": "Plant_Leaves_Crystal"
    },
    {
      "x": -9,
      "y": 34,
      "z": -4,
      "name": "Plant_Leaves_Crystal"
    },
    {
      "x": -9,
      "y": 36,
      "z": -4,
      "name": "Plant_Leaves_Crystal"
    },
    {
      "x": -9,
      "y": 31,
      "z": -3,
      "name": "Plant_Fruit_Pinkberry",
      "rotation": 8
    },
    {
      "x": -9,
      "y": 32,
      "z": -3,
      "name": "Plant_Leaves_Crystal"
    },
    {
      "x": -9,
      "y": 33,
      "z": -3,
      "name": "Plant_Leaves_Crystal"
    },
    {
      "x": -9,
      "y": 34,
      "z": -3,
      "name": "Plant_Leaves_Crystal"
    },
    {
      "x": -9,
      "y": 35,
      "z": -3,
      "name": "Plant_Leaves_Crystal"
    },
    {
      "x": -9,
      "y": 36,
      "z": -3,
      "name": "Plant_Leaves_Crystal"
    },
    {
      "x": -9,
      "y": 37,
      "z": -3,
      "name": "Plant_Leaves_Crystal"
    },
    {
      "x": -9,
      "y": 38,
      "z": -3,
      "name": "Plant_Leaves_Crystal"
    },
    {
      "x": -9,
      "y": 31,
      "z": -2,
      "name": "Wood_Crystal_Roots"
    },
    {
      "x": -9,
      "y": 32,
      "z": -2,
      "name": "Wood_Crystal_Trunk_Full"
    },
    {
      "x": -9,
      "y": 33,
      "z": -2,
      "name": "Plant_Leaves_Crystal"
    },
    {
      "x": -9,
      "y": 34,
      "z": -2,
      "name": "Plant_Leaves_Crystal"
    },
    {
      "x": -9,
      "y": 35,
      "z": -2,
      "name": "Plant_Leaves_Crystal"
    },
    {
      "x": -9,
      "y": 36,
      "z": -2,
      "name": "Plant_Leaves_Crystal"
    },
    {
      "x": -9,
      "y": 37,
      "z": -2,
      "name": "Plant_Leaves_Crystal"
    },
    {
      "x": -9,
      "y": 38,
      "z": -2,
      "name": "Plant_Leaves_Crystal"
    },
    {
      "x": -9,
      "y": 32,
      "z": -1,
      "name": "Plant_Leaves_Crystal"
    },
    {
      "x": -9,
      "y": 33,
      "z": -1,
      "name": "Plant_Leaves_Crystal"
    },
    {
      "x": -9,
      "y": 34,
      "z": -1,
      "name": "Plant_Leaves_Crystal"
    },
    {
      "x": -9,
      "y": 36,
      "z": -1,
      "name": "Plant_Leaves_Crystal"
    },
    {
      "x": -9,
      "y": 37,
      "z": -1,
      "name": "Plant_Leaves_Crystal"
    },
    {
      "x": -9,
      "y": 38,
      "z": -1,
      "name": "Plant_Leaves_Crystal"
    },
    {
      "x": -9,
      "y": 35,
      "z": 0,
      "name": "Plant_Leaves_Crystal"
    },
    {
      "x": -9,
      "y": 36,
      "z": 0,
      "name": "Plant_Leaves_Crystal"
    },
    {
      "x": -9,
      "y": 38,
      "z": 0,
      "name": "Plant_Leaves_Crystal"
    },
    {
      "x": -9,
      "y": 33,
      "z": 1,
      "name": "Plant_Leaves_Crystal"
    },
    {
      "x": -9,
      "y": 35,
      "z": 1,
      "name": "Plant_Leaves_Crystal"
    },
    {
      "x": -9,
      "y": 36,
      "z": 1,
      "name": "Plant_Leaves_Crystal"
    },
    {
      "x": -9,
      "y": 38,
      "z": 1,
      "name": "Plant_Leaves_Crystal"
    },
    {
      "x": -9,
      "y": 32,
      "z": 2,
      "name": "Wood_Crystal_Trunk_Full"
    },
    {
      "x": -9,
      "y": 35,
      "z": 2,
      "name": "Wood_Crystal_Trunk_Full"
    },
    {
      "x": -9,
      "y": 36,
      "z": 2,
      "name": "Plant_Leaves_Crystal"
    },
    {
      "x": -9,
      "y": 37,
      "z": 2,
      "name": "Plant_Leaves_Crystal"
    },
    {
      "x": -9,
      "y": 38,
      "z": 2,
      "name": "Plant_Leaves_Crystal"
    },
    {
      "x": -9,
      "y": 26,
      "z": 3,
      "name": "Plant_Leaves_Crystal"
    },
    {
      "x": -9,
      "y": 27,
      "z": 3,
      "name": "Plant_Leaves_Crystal"
    },
    {
      "x": -9,
      "y": 28,
      "z": 3,
      "name": "Plant_Leaves_Crystal"
    },
    {
      "x": -9,
      "y": 33,
      "z": 3,
      "name": "Plant_Leaves_Crystal"
    },
    {
      "x": -9,
      "y": 35,
      "z": 3,
      "name": "Wood_Crystal_Trunk_Full"
    },
    {
      "x": -9,
      "y": 36,
      "z": 3,
      "name": "Plant_Leaves_Crystal"
    },
    {
      "x": -9,
      "y": 37,
      "z": 3,
      "name": "Plant_Leaves_Crystal"
    },
    {
      "x": -9,
      "y": 38,
      "z": 3,
      "name": "Plant_Leaves_Crystal"
    },
    {
      "x": -9,
      "y": 28,
      "z": 4,
      "name": "Plant_Leaves_Crystal"
    },
    {
      "x": -9,
      "y": 33,
      "z": 4,
      "name": "Plant_Leaves_Crystal"
    },
    {
      "x": -9,
      "y": 35,
      "z": 4,
      "name": "Plant_Leaves_Crystal"
    },
    {
      "x": -9,
      "y": 36,
      "z": 4,
      "name": "Plant_Leaves_Crystal"
    },
    {
      "x": -9,
      "y": 37,
      "z": 4,
      "name": "Plant_Leaves_Crystal"
    },
    {
      "x": -9,
      "y": 38,
      "z": 4,
      "name": "Plant_Leaves_Crystal"
    },
    {
      "x": -9,
      "y": 27,
      "z": 5,
      "name": "Plant_Leaves_Crystal"
    },
    {
      "x": -9,
      "y": 28,
      "z": 5,
      "name": "Plant_Leaves_Crystal"
    },
    {
      "x": -9,
      "y": 33,
      "z": 5,
      "name": "Plant_Leaves_Crystal"
    },
    {
      "x": -9,
      "y": 35,
      "z": 5,
      "name": "Plant_Leaves_Crystal"
    },
    {
      "x": -9,
      "y": 36,
      "z": 5,
      "name": "Plant_Leaves_Crystal"
    },
    {
      "x": -9,
      "y": 37,
      "z": 5,
      "name": "Plant_Leaves_Crystal"
    },
    {
      "x": -9,
      "y": 38,
      "z": 5,
      "name": "Plant_Leaves_Crystal"
    },
    {
      "x": -9,
      "y": 27,
      "z": 6,
      "name": "Wood_Crystal_Branch_Corner",
      "rotation": 3
    },
    {
      "x": -9,
      "y": 28,
      "z": 6,
      "name": "Plant_Leaves_Crystal"
    },
    {
      "x": -9,
      "y": 28,
      "z": 7,
      "name": "Plant_Leaves_Crystal"
    },
    {
      "x": -9,
      "y": 33,
      "z": 7,
      "name": "Plant_Leaves_Crystal"
    },
    {
      "x": -9,
      "y": 34,
      "z": 7,
      "name": "Plant_Leaves_Crystal"
    },
    {
      "x": -9,
      "y": 36,
      "z": 7,
      "name": "Plant_Leaves_Crystal"
    },
    {
      "x": -9,
      "y": 33,
      "z": 8,
      "name": "Plant_Leaves_Crystal"
    },
    {
      "x": -9,
      "y": 34,
      "z": 8,
      "name": "Plant_Leaves_Crystal"
    },
    {
      "x": -9,
      "y": 35,
      "z": 8,
      "name": "Plant_Leaves_Crystal"
    },
    {
      "x": -9,
      "y": 36,
      "z": 8,
      "name": "Plant_Leaves_Crystal"
    },
    {
      "x": -9,
      "y": 33,
      "z": 9,
      "name": "Plant_Leaves_Crystal"
    },
    {
      "x": -9,
      "y": 34,
      "z": 9,
      "name": "Plant_Leaves_Crystal"
    },
    {
      "x": -9,
      "y": 35,
      "z": 9,
      "name": "Plant_Leaves_Crystal"
    },
    {
      "x": -9,
      "y": 36,
      "z": 9,
      "name": "Plant_Leaves_Crystal"
    },
    {
      "x": -9,
      "y": 32,
      "z": 10,
      "name": "Wood_Crystal_Roots"
    },
    {
      "x": -9,
      "y": 33,
      "z": 10,
      "name": "Wood_Crystal_Trunk_Full"
    },
    {
      "x": -9,
      "y": 34,
      "z": 10,
      "name": "Plant_Leaves_Crystal"
    },
    {
      "x": -9,
      "y": 35,
      "z": 10,
      "name": "Plant_Leaves_Crystal"
    },
    {
      "x": -9,
      "y": 36,
      "z": 10,
      "name": "Plant_Leaves_Crystal"
    },
    {
      "x": -9,
      "y": 37,
      "z": 10,
      "name": "Plant_Leaves_Crystal"
    },
    {
      "x": -9,
      "y": 33,
      "z": 11,
      "name": "Wood_Crystal_Branch_Corner"
    },
    {
      "x": -9,
      "y": 34,
      "z": 11,
      "name": "Plant_Leaves_Crystal"
    },
    {
      "x": -9,
      "y": 36,
      "z": 11,
      "name": "Plant_Leaves_Crystal"
    },
    {
      "x": -9,
      "y": 33,
      "z": 12,
      "name": "Plant_Leaves_Crystal"
    },
    {
      "x": -9,
      "y": 34,
      "z": 12,
      "name": "Plant_Leaves_Crystal"
    },
    {
      "x": -9,
      "y": 35,
      "z": 12,
      "name": "Plant_Leaves_Crystal"
    },
    {
      "x": -9,
      "y": 36,
      "z": 12,
      "name": "Plant_Leaves_Crystal"
    },
    {
      "x": -9,
      "y": 32,
      "z": 13,
      "name": "Plant_Leaves_Crystal"
    },
    {
      "x": -9,
      "y": 33,
      "z": 13,
      "name": "Plant_Leaves_Crystal"
    },
    {
      "x": -9,
      "y": 34,
      "z": 13,
      "name": "Plant_Leaves_Crystal"
    },
    {
      "x": -9,
      "y": 35,
      "z": 13,
      "name": "Plant_Leaves_Crystal"
    },
    {
      "x": -9,
      "y": 36,
      "z": 13,
      "name": "Plant_Leaves_Crystal"
    },
    {
      "x": -9,
      "y": 34,
      "z": 14,
      "name": "Plant_Leaves_Crystal"
    },
    {
      "x": -9,
      "y": 35,
      "z": 14,
      "name": "Plant_Leaves_Crystal"
    },
    {
      "x": -9,
      "y": 34,
      "z": 15,
      "name": "Plant_Leaves_Crystal"
    },
    {
      "x": -9,
      "y": 35,
      "z": 15,
      "name": "Plant_Leaves_Crystal"
    },
    {
      "x": -9,
      "y": 34,
      "z": 16,
      "name": "Plant_Leaves_Crystal"
    },
    {
      "x": -9,
      "y": 35,
      "z": 16,
      "name": "Plant_Leaves_Crystal"
    },
    {
      "x": -8,
      "y": 33,
      "z": -6,
      "name": "Plant_Leaves_Crystal"
    },
    {
      "x": -8,
      "y": 33,
      "z": -5,
      "name": "Plant_Leaves_Crystal"
    },
    {
      "x": -8,
      "y": 36,
      "z": -5,
      "name": "Plant_Leaves_Crystal"
    },
    {
      "x": -8,
      "y": 32,
      "z": -4,
      "name": "Plant_Leaves_Crystal"
    },
    {
      "x": -8,
      "y": 33,
      "z": -4,
      "name": "Plant_Leaves_Crystal"
    },
    {
      "x": -8,
      "y": 34,
      "z": -4,
      "name": "Plant_Leaves_Crystal"
    },
    {
      "x": -8,
      "y": 36,
      "z": -4,
      "name": "Plant_Leaves_Crystal"
    },
    {
      "x": -8,
      "y": 37,
      "z": -4,
      "name": "Plant_Leaves_Crystal"
    },
    {
      "x": -8,
      "y": 38,
      "z": -4,
      "name": "Plant_Leaves_Crystal"
    },
    {
      "x": -8,
      "y": 32,
      "z": -3,
      "name": "Wood_Crystal_Branch_Corner",
      "rotation": 2
    },
    {
      "x": -8,
      "y": 33,
      "z": -3,
      "name": "Plant_Leaves_Crystal"
    },
    {
      "x": -8,
      "y": 34,
      "z": -3,
      "name": "Plant_Leaves_Crystal"
    },
    {
      "x": -8,
      "y": 35,
      "z": -3,
      "name": "Plant_Leaves_Crystal"
    },
    {
      "x": -8,
      "y": 36,
      "z": -3,
      "name": "Plant_Leaves_Crystal"
    },
    {
      "x": -8,
      "y": 37,
      "z": -3,
      "name": "Plant_Leaves_Crystal"
    },
    {
      "x": -8,
      "y": 38,
      "z": -3,
      "name": "Plant_Leaves_Crystal"
    },
    {
      "x": -8,
      "y": 31,
      "z": -2,
      "name": "Wood_Crystal_Roots"
    },
    {
      "x": -8,
      "y": 32,
      "z": -2,
      "name": "Wood_Crystal_Trunk_Full"
    },
    {
      "x": -8,
      "y": 33,
      "z": -2,
      "name": "Plant_Leaves_Crystal"
    },
    {
      "x": -8,
      "y": 35,
      "z": -2,
      "name": "Wood_Crystal_Trunk_Full"
    },
    {
      "x": -8,
      "y": 36,
      "z": -2,
      "name": "Plant_Leaves_Crystal"
    },
    {
      "x": -8,
      "y": 37,
      "z": -2,
      "name": "Plant_Leaves_Crystal"
    },
    {
      "x": -8,
      "y": 38,
      "z": -2,
      "name": "Plant_Leaves_Crystal"
    },
    {
      "x": -8,
      "y": 32,
      "z": -1,
      "name": "Wood_Crystal_Trunk_Full"
    },
    {
      "x": -8,
      "y": 33,
      "z": -1,
      "name": "Plant_Leaves_Crystal"
    },
    {
      "x": -8,
      "y": 35,
      "z": -1,
      "name": "Plant_Leaves_Crystal"
    },
    {
      "x": -8,
      "y": 36,
      "z": -1,
      "name": "Plant_Leaves_Crystal"
    },
    {
      "x": -8,
      "y": 37,
      "z": -1,
      "name": "Plant_Leaves_Crystal"
    },
    {
      "x": -8,
      "y": 38,
      "z": -1,
      "name": "Plant_Leaves_Crystal"
    },
    {
      "x": -8,
      "y": 32,
      "z": 0,
      "name": "Wood_Crystal_Trunk_Full"
    },
    {
      "x": -8,
      "y": 35,
      "z": 0,
      "name": "Plant_Leaves_Crystal"
    },
    {
      "x": -8,
      "y": 38,
      "z": 0,
      "name": "Plant_Leaves_Crystal"
    },
    {
      "x": -8,
      "y": 35,
      "z": 1,
      "name": "Plant_Leaves_Crystal"
    },
    {
      "x": -8,
      "y": 36,
      "z": 1,
      "name": "Plant_Leaves_Crystal"
    },
    {
      "x": -8,
      "y": 38,
      "z": 1,
      "name": "Plant_Leaves_Crystal"
    },
    {
      "x": -8,
      "y": 28,
      "z": 2,
      "name": "Plant_Leaves_Crystal"
    },
    {
      "x": -8,
      "y": 31,
      "z": 2,
      "name": "Wood_Crystal_Trunk_Full"
    },
    {
      "x": -8,
      "y": 32,
      "z": 2,
      "name": "Wood_Crystal_Trunk_Full"
    },
    {
      "x": -8,
      "y": 35,
      "z": 2,
      "name": "Wood_Crystal_Trunk_Full"
    },
    {
      "x": -8,
      "y": 38,
      "z": 2,
      "name": "Plant_Leaves_Crystal"
    },
    {
      "x": -8,
      "y": 28,
      "z": 3,
      "name": "Plant_Leaves_Crystal"
    },
    {
      "x": -8,
      "y": 36,
      "z": 3,
      "name": "Plant_Leaves_Crystal"
    },
    {
      "x": -8,
      "y": 38,
      "z": 3,
      "name": "Plant_Leaves_Crystal"
    },
    {
      "x": -8,
      "y": 27,
      "z": 4,
      "name": "Plant_Leaves_Crystal"
    },
    {
      "x": -8,
      "y": 28,
      "z": 4,
      "name": "Plant_Leaves_Crystal"
    },
    {
      "x": -8,
      "y": 36,
      "z": 4,
      "name": "Plant_Leaves_Crystal"
    },
    {
      "x": -8,
      "y": 38,
      "z": 4,
      "name": "Plant_Leaves_Crystal"
    },
    {
      "x": -8,
      "y": 27,
      "z": 5,
      "name": "Plant_Leaves_Crystal"
    },
    {
      "x": -8,
      "y": 28,
      "z": 5,
      "name": "Plant_Leaves_Crystal"
    },
    {
      "x": -8,
      "y": 29,
      "z": 5,
      "name": "Plant_Leaves_Crystal"
    },
    {
      "x": -8,
      "y": 36,
      "z": 5,
      "name": "Plant_Leaves_Crystal"
    },
    {
      "x": -8,
      "y": 27,
      "z": 6,
      "name": "Wood_Crystal_Trunk_Full"
    },
    {
      "x": -8,
      "y": 28,
      "z": 6,
      "name": "Plant_Leaves_Crystal"
    },
    {
      "x": -8,
      "y": 29,
      "z": 6,
      "name": "Plant_Leaves_Crystal"
    },
    {
      "x": -8,
      "y": 33,
      "z": 6,
      "name": "Plant_Leaves_Crystal"
    },
    {
      "x": -8,
      "y": 28,
      "z": 7,
      "name": "Plant_Leaves_Crystal"
    },
    {
      "x": -8,
      "y": 33,
      "z": 7,
      "name": "Plant_Leaves_Crystal"
    },
    {
      "x": -8,
      "y": 34,
      "z": 7,
      "name": "Plant_Leaves_Crystal"
    },
    {
      "x": -8,
      "y": 35,
      "z": 7,
      "name": "Plant_Leaves_Crystal"
    },
    {
      "x": -8,
      "y": 36,
      "z": 7,
      "name": "Plant_Leaves_Crystal"
    },
    {
      "x": -8,
      "y": 27,
      "z": 8,
      "name": "Plant_Leaves_Crystal"
    },
    {
      "x": -8,
      "y": 28,
      "z": 8,
      "name": "Plant_Leaves_Crystal"
    },
    {
      "x": -8,
      "y": 33,
      "z": 8,
      "name": "Plant_Leaves_Crystal"
    },
    {
      "x": -8,
      "y": 34,
      "z": 8,
      "name": "Plant_Leaves_Crystal"
    },
    {
      "x": -8,
      "y": 35,
      "z": 8,
      "name": "Plant_Leaves_Crystal"
    },
    {
      "x": -8,
      "y": 36,
      "z": 8,
      "name": "Plant_Leaves_Crystal"
    },
    {
      "x": -8,
      "y": 33,
      "z": 9,
      "name": "Wood_Crystal_Trunk_Full"
    },
    {
      "x": -8,
      "y": 34,
      "z": 9,
      "name": "Plant_Leaves_Crystal"
    },
    {
      "x": -8,
      "y": 35,
      "z": 9,
      "name": "Plant_Leaves_Crystal"
    },
    {
      "x": -8,
      "y": 36,
      "z": 9,
      "name": "Plant_Leaves_Crystal"
    },
    {
      "x": -8,
      "y": 32,
      "z": 10,
      "name": "Wood_Crystal_Roots"
    },
    {
      "x": -8,
      "y": 33,
      "z": 10,
      "name": "Wood_Crystal_Trunk_Full"
    },
    {
      "x": -8,
      "y": 34,
      "z": 10,
      "name": "Plant_Leaves_Crystal"
    },
    {
      "x": -8,
      "y": 35,
      "z": 10,
      "name": "Plant_Leaves_Crystal"
    },
    {
      "x": -8,
      "y": 36,
      "z": 10,
      "name": "Plant_Leaves_Crystal"
    },
    {
      "x": -8,
      "y": 37,
      "z": 10,
      "name": "Plant_Leaves_Crystal"
    },
    {
      "x": -8,
      "y": 33,
      "z": 11,
      "name": "Wood_Crystal_Branch_Long",
      "rotation": 4
    },
    {
      "x": -8,
      "y": 35,
      "z": 11,
      "name": "Plant_Leaves_Crystal"
    },
    {
      "x": -8,
      "y": 36,
      "z": 11,
      "name": "Plant_Leaves_Crystal"
    },
    {
      "x": -8,
      "y": 33,
      "z": 12,
      "name": "Wood_Crystal_Branch_Long",
      "rotation": 4
    },
    {
      "x": -8,
      "y": 34,
      "z": 12,
      "name": "Plant_Leaves_Crystal"
    },
    {
      "x": -8,
      "y": 35,
      "z": 12,
      "name": "Plant_Leaves_Crystal"
    },
    {
      "x": -8,
      "y": 36,
      "z": 12,
      "name": "Plant_Leaves_Crystal"
    },
    {
      "x": -8,
      "y": 34,
      "z": 13,
      "name": "Plant_Leaves_Crystal"
    },
    {
      "x": -8,
      "y": 35,
      "z": 13,
      "name": "Plant_Leaves_Crystal"
    },
    {
      "x": -8,
      "y": 33,
      "z": 14,
      "name": "Plant_Leaves_Crystal"
    },
    {
      "x": -8,
      "y": 34,
      "z": 14,
      "name": "Plant_Leaves_Crystal"
    },
    {
      "x": -8,
      "y": 32,
      "z": 15,
      "name": "Plant_Leaves_Crystal"
    },
    {
      "x": -8,
      "y": 33,
      "z": 15,
      "name": "Plant_Leaves_Crystal"
    },
    {
      "x": -8,
      "y": 34,
      "z": 15,
      "name": "Plant_Leaves_Crystal"
    },
    {
      "x": -8,
      "y": 35,
      "z": 15,
      "name": "Plant_Leaves_Crystal"
    },
    {
      "x": -8,
      "y": 32,
      "z": 16,
      "name": "Plant_Leaves_Crystal"
    },
    {
      "x": -8,
      "y": 33,
      "z": 16,
      "name": "Plant_Leaves_Crystal"
    },
    {
      "x": -8,
      "y": 34,
      "z": 16,
      "name": "Plant_Leaves_Crystal"
    },
    {
      "x": -8,
      "y": 35,
      "z": 16,
      "name": "Plant_Leaves_Crystal"
    },
    {
      "x": -8,
      "y": 34,
      "z": 17,
      "name": "Plant_Leaves_Crystal"
    },
    {
      "x": -7,
      "y": 33,
      "z": -6,
      "name": "Plant_Leaves_Crystal"
    },
    {
      "x": -7,
      "y": 36,
      "z": -6,
      "name": "Plant_Leaves_Crystal"
    },
    {
      "x": -7,
      "y": 33,
      "z": -5,
      "name": "Plant_Leaves_Crystal"
    },
    {
      "x": -7,
      "y": 36,
      "z": -5,
      "name": "Plant_Leaves_Crystal"
    },
    {
      "x": -7,
      "y": 38,
      "z": -5,
      "name": "Plant_Leaves_Crystal"
    },
    {
      "x": -7,
      "y": 32,
      "z": -4,
      "name": "Plant_Leaves_Crystal"
    },
    {
      "x": -7,
      "y": 33,
      "z": -4,
      "name": "Plant_Leaves_Crystal"
    },
    {
      "x": -7,
      "y": 35,
      "z": -4,
      "name": "Plant_Leaves_Crystal"
    },
    {
      "x": -7,
      "y": 36,
      "z": -4,
      "name": "Plant_Leaves_Crystal"
    },
    {
      "x": -7,
      "y": 37,
      "z": -4,
      "name": "Plant_Leaves_Crystal"
    },
    {
      "x": -7,
      "y": 38,
      "z": -4,
      "name": "Plant_Leaves_Crystal"
    },
    {
      "x": -7,
      "y": 32,
      "z": -3,
      "name": "Plant_Leaves_Crystal"
    },
    {
      "x": -7,
      "y": 33,
      "z": -3,
      "name": "Plant_Leaves_Crystal"
    },
    {
      "x": -7,
      "y": 34,
      "z": -3,
      "name": "Plant_Leaves_Crystal"
    },
    {
      "x": -7,
      "y": 35,
      "z": -3,
      "name": "Plant_Leaves_Crystal"
    },
    {
      "x": -7,
      "y": 36,
      "z": -3,
      "name": "Plant_Leaves_Crystal"
    },
    {
      "x": -7,
      "y": 37,
      "z": -3,
      "name": "Plant_Leaves_Crystal"
    },
    {
      "x": -7,
      "y": 38,
      "z": -3,
      "name": "Plant_Leaves_Crystal"
    },
    {
      "x": -7,
      "y": 32,
      "z": -2,
      "name": "Plant_Leaves_Crystal"
    },
    {
      "x": -7,
      "y": 33,
      "z": -2,
      "name": "Plant_Leaves_Crystal"
    },
    {
      "x": -7,
      "y": 34,
      "z": -2,
      "name": "Plant_Leaves_Crystal"
    },
    {
      "x": -7,
      "y": 35,
      "z": -2,
      "name": "Wood_Crystal_Trunk_Full"
    },
    {
      "x": -7,
      "y": 36,
      "z": -2,
      "name": "Plant_Leaves_Crystal"
    },
    {
      "x": -7,
      "y": 37,
      "z": -2,
      "name": "Plant_Leaves_Crystal"
    },
    {
      "x": -7,
      "y": 38,
      "z": -2,
      "name": "Plant_Leaves_Crystal"
    },
    {
      "x": -7,
      "y": 33,
      "z": -1,
      "name": "Plant_Leaves_Crystal"
    },
    {
      "x": -7,
      "y": 34,
      "z": -1,
      "name": "Plant_Leaves_Crystal"
    },
    {
      "x": -7,
      "y": 35,
      "z": -1,
      "name": "Wood_Crystal_Trunk_Full"
    },
    {
      "x": -7,
      "y": 36,
      "z": -1,
      "name": "Plant_Leaves_Crystal"
    },
    {
      "x": -7,
      "y": 37,
      "z": -1,
      "name": "Plant_Leaves_Crystal"
    },
    {
      "x": -7,
      "y": 38,
      "z": -1,
      "name": "Plant_Leaves_Crystal"
    },
    {
      "x": -7,
      "y": 32,
      "z": 0,
      "name": "Wood_Crystal_Trunk_Full"
    },
    {
      "x": -7,
      "y": 33,
      "z": 0,
      "name": "Plant_Leaves_Crystal"
    },
    {
      "x": -7,
      "y": 35,
      "z": 0,
      "name": "Wood_Crystal_Trunk_Full"
    },
    {
      "x": -7,
      "y": 37,
      "z": 0,
      "name": "Plant_Leaves_Crystal"
    },
    {
      "x": -7,
      "y": 38,
      "z": 0,
      "name": "Plant_Leaves_Crystal"
    },
    {
      "x": -7,
      "y": 31,
      "z": 1,
      "name": "Wood_Crystal_Trunk_Full"
    },
    {
      "x": -7,
      "y": 32,
      "z": 1,
      "name": "Wood_Crystal_Trunk_Full"
    },
    {
      "x": -7,
      "y": 33,
      "z": 1,
      "name": "Plant_Leaves_Crystal"
    },
    {
      "x": -7,
      "y": 35,
      "z": 1,
      "name": "Plant_Leaves_Crystal"
    },
    {
      "x": -7,
      "y": 37,
      "z": 1,
      "name": "Plant_Leaves_Crystal"
    },
    {
      "x": -7,
      "y": 38,
      "z": 1,
      "name": "Plant_Leaves_Crystal"
    },
    {
      "x": -7,
      "y": 27,
      "z": 2,
      "name": "Wood_Crystal_Branch_Corner",
      "rotation": 2
    },
    {
      "x": -7,
      "y": 31,
      "z": 2,
      "name": "Wood_Crystal_Trunk_Full"
    },
    {
      "x": -7,
      "y": 32,
      "z": 2,
      "name": "Wood_Crystal_Trunk_Full"
    },
    {
      "x": -7,
      "y": 35,
      "z": 2,
      "name": "Wood_Crystal_Trunk_Full"
    },
    {
      "x": -7,
      "y": 38,
      "z": 2,
      "name": "Plant_Leaves_Crystal"
    },
    {
      "x": -7,
      "y": 27,
      "z": 3,
      "name": "Wood_Crystal_Branch_Long",
      "rotation": 4
    },
    {
      "x": -7,
      "y": 28,
      "z": 3,
      "name": "Plant_Leaves_Crystal"
    },
    {
      "x": -7,
      "y": 29,
      "z": 3,
      "name": "Plant_Leaves_Crystal"
    },
    {
      "x": -7,
      "y": 27,
      "z": 4,
      "name": "Wood_Crystal_Branch_Long",
      "rotation": 4
    },
    {
      "x": -7,
      "y": 28,
      "z": 4,
      "name": "Plant_Leaves_Crystal"
    },
    {
      "x": -7,
      "y": 27,
      "z": 5,
      "name": "Wood_Crystal_Branch_Long",
      "rotation": 4
    },
    {
      "x": -7,
      "y": 28,
      "z": 5,
      "name": "Plant_Leaves_Crystal"
    },
    {
      "x": -7,
      "y": 29,
      "z": 5,
      "name": "Plant_Leaves_Crystal"
    },
    {
      "x": -7,
      "y": 38,
      "z": 5,
      "name": "Plant_Leaves_Crystal"
    },
    {
      "x": -7,
      "y": 27,
      "z": 6,
      "name": "Wood_Crystal_Trunk_Full"
    },
    {
      "x": -7,
      "y": 28,
      "z": 6,
      "name": "Plant_Leaves_Crystal"
    },
    {
      "x": -7,
      "y": 29,
      "z": 6,
      "name": "Plant_Leaves_Crystal"
    },
    {
      "x": -7,
      "y": 33,
      "z": 6,
      "name": "Plant_Leaves_Crystal"
    },
    {
      "x": -7,
      "y": 34,
      "z": 6,
      "name": "Plant_Leaves_Crystal"
    },
    {
      "x": -7,
      "y": 27,
      "z": 7,
      "name": "Plant_Leaves_Crystal"
    },
    {
      "x": -7,
      "y": 28,
      "z": 7,
      "name": "Plant_Leaves_Crystal"
    },
    {
      "x": -7,
      "y": 33,
      "z": 7,
      "name": "Plant_Leaves_Crystal"
    },
    {
      "x": -7,
      "y": 34,
      "z": 7,
      "name": "Plant_Leaves_Crystal"
    },
    {
      "x": -7,
      "y": 36,
      "z": 7,
      "name": "Plant_Leaves_Crystal"
    },
    {
      "x": -7,
      "y": 38,
      "z": 7,
      "name": "Plant_Leaves_Crystal"
    },
    {
      "x": -7,
      "y": 28,
      "z": 8,
      "name": "Plant_Leaves_Crystal"
    },
    {
      "x": -7,
      "y": 34,
      "z": 8,
      "name": "Plant_Leaves_Crystal"
    },
    {
      "x": -7,
      "y": 36,
      "z": 8,
      "name": "Plant_Leaves_Crystal"
    },
    {
      "x": -7,
      "y": 28,
      "z": 9,
      "name": "Plant_Leaves_Crystal"
    },
    {
      "x": -7,
      "y": 35,
      "z": 9,
      "name": "Plant_Leaves_Crystal"
    },
    {
      "x": -7,
      "y": 36,
      "z": 9,
      "name": "Plant_Leaves_Crystal"
    },
    {
      "x": -7,
      "y": 38,
      "z": 9,
      "name": "Plant_Leaves_Crystal"
    },
    {
      "x": -7,
      "y": 33,
      "z": 10,
      "name": "Wood_Crystal_Trunk_Full"
    },
    {
      "x": -7,
      "y": 36,
      "z": 10,
      "name": "Plant_Leaves_Crystal"
    },
    {
      "x": -7,
      "y": 37,
      "z": 10,
      "name": "Plant_Leaves_Crystal"
    },
    {
      "x": -7,
      "y": 34,
      "z": 11,
      "name": "Plant_Leaves_Crystal"
    },
    {
      "x": -7,
      "y": 35,
      "z": 11,
      "name": "Plant_Leaves_Crystal"
    },
    {
      "x": -7,
      "y": 36,
      "z": 11,
      "name": "Plant_Leaves_Crystal"
    },
    {
      "x": -7,
      "y": 37,
      "z": 11,
      "name": "Plant_Leaves_Crystal"
    },
    {
      "x": -7,
      "y": 33,
      "z": 12,
      "name": "Plant_Leaves_Crystal"
    },
    {
      "x": -7,
      "y": 34,
      "z": 12,
      "name": "Plant_Leaves_Crystal"
    },
    {
      "x": -7,
      "y": 35,
      "z": 12,
      "name": "Plant_Leaves_Crystal"
    },
    {
      "x": -7,
      "y": 36,
      "z": 12,
      "name": "Plant_Leaves_Crystal"
    },
    {
      "x": -7,
      "y": 33,
      "z": 13,
      "name": "Plant_Leaves_Crystal"
    },
    {
      "x": -7,
      "y": 34,
      "z": 13,
      "name": "Plant_Leaves_Crystal"
    },
    {
      "x": -7,
      "y": 35,
      "z": 13,
      "name": "Plant_Leaves_Crystal"
    },
    {
      "x": -7,
      "y": 36,
      "z": 13,
      "name": "Plant_Leaves_Crystal"
    },
    {
      "x": -7,
      "y": 37,
      "z": 13,
      "name": "Plant_Leaves_Crystal"
    },
    {
      "x": -7,
      "y": 32,
      "z": 14,
      "name": "Plant_Leaves_Crystal"
    },
    {
      "x": -7,
      "y": 33,
      "z": 14,
      "name": "Plant_Leaves_Crystal"
    },
    {
      "x": -7,
      "y": 34,
      "z": 14,
      "name": "Plant_Leaves_Crystal"
    },
    {
      "x": -7,
      "y": 35,
      "z": 14,
      "name": "Plant_Leaves_Crystal"
    },
    {
      "x": -7,
      "y": 36,
      "z": 14,
      "name": "Plant_Leaves_Crystal"
    },
    {
      "x": -7,
      "y": 34,
      "z": 15,
      "name": "Plant_Leaves_Crystal"
    },
    {
      "x": -7,
      "y": 34,
      "z": 16,
      "name": "Plant_Leaves_Crystal"
    },
    {
      "x": -7,
      "y": 35,
      "z": 16,
      "name": "Plant_Leaves_Crystal"
    },
    {
      "x": -7,
      "y": 34,
      "z": 17,
      "name": "Plant_Leaves_Crystal"
    },
    {
      "x": -6,
      "y": 34,
      "z": -7,
      "name": "Plant_Leaves_Crystal"
    },
    {
      "x": -6,
      "y": 34,
      "z": -6,
      "name": "Plant_Leaves_Crystal"
    },
    {
      "x": -6,
      "y": 36,
      "z": -6,
      "name": "Plant_Leaves_Crystal"
    },
    {
      "x": -6,
      "y": 37,
      "z": -6,
      "name": "Plant_Leaves_Crystal"
    },
    {
      "x": -6,
      "y": 31,
      "z": -5,
      "name": "Plant_Leaves_Crystal"
    },
    {
      "x": -6,
      "y": 32,
      "z": -5,
      "name": "Plant_Leaves_Crystal"
    },
    {
      "x": -6,
      "y": 33,
      "z": -5,
      "name": "Plant_Leaves_Crystal"
    },
    {
      "x": -6,
      "y": 34,
      "z": -5,
      "name": "Plant_Leaves_Crystal"
    },
    {
      "x": -6,
      "y": 36,
      "z": -5,
      "name": "Plant_Leaves_Crystal"
    },
    {
      "x": -6,
      "y": 38,
      "z": -5,
      "name": "Plant_Leaves_Crystal"
    },
    {
      "x": -6,
      "y": 33,
      "z": -4,
      "name": "Plant_Leaves_Crystal"
    },
    {
      "x": -6,
      "y": 34,
      "z": -4,
      "name": "Plant_Leaves_Crystal"
    },
    {
      "x": -6,
      "y": 35,
      "z": -4,
      "name": "Plant_Leaves_Crystal"
    },
    {
      "x": -6,
      "y": 36,
      "z": -4,
      "name": "Plant_Leaves_Crystal"
    },
    {
      "x": -6,
      "y": 3,
      "z": -3,
      "name": "Wood_Crystal_Roots"
    },
    {
      "x": -6,
      "y": 4,
      "z": -3,
      "name": "Wood_Crystal_Trunk"
    },
    {
      "x": -6,
      "y": 5,
      "z": -3,
      "name": "Wood_Crystal_Trunk"
    },
    {
      "x": -6,
      "y": 6,
      "z": -3,
      "name": "Wood_Crystal_Trunk"
    },
    {
      "x": -6,
      "y": 7,
      "z": -3,
      "name": "Wood_Crystal_Trunk"
    },
    {
      "x": -6,
      "y": 8,
      "z": -3,
      "name": "Wood_Crystal_Trunk_Full"
    },
    {
      "x": -6,
      "y": 33,
      "z": -3,
      "name": "Plant_Leaves_Crystal"
    },
    {
      "x": -6,
      "y": 34,
      "z": -3,
      "name": "Plant_Leaves_Crystal"
    },
    {
      "x": -6,
      "y": 35,
      "z": -3,
      "name": "Plant_Leaves_Crystal"
    },
    {
      "x": -6,
      "y": 36,
      "z": -3,
      "name": "Plant_Leaves_Crystal"
    },
    {
      "x": -6,
      "y": 37,
      "z": -3,
      "name": "Plant_Leaves_Crystal"
    },
    {
      "x": -6,
      "y": 38,
      "z": -3,
      "name": "Plant_Leaves_Crystal"
    },
    {
      "x": -6,
      "y": 5,
      "z": -2,
      "name": "Wood_Crystal_Trunk"
    },
    {
      "x": -6,
      "y": 6,
      "z": -2,
      "name": "Wood_Crystal_Trunk"
    },
    {
      "x": -6,
      "y": 7,
      "z": -2,
      "name": "Wood_Crystal_Trunk_Full"
    },
    {
      "x": -6,
      "y": 33,
      "z": -2,
      "name": "Plant_Leaves_Crystal"
    },
    {
      "x": -6,
      "y": 35,
      "z": -2,
      "name": "Plant_Leaves_Crystal"
    },
    {
      "x": -6,
      "y": 36,
      "z": -2,
      "name": "Plant_Leaves_Crystal"
    },
    {
      "x": -6,
      "y": 37,
      "z": -2,
      "name": "Plant_Leaves_Crystal"
    },
    {
      "x": -6,
      "y": 38,
      "z": -2,
      "name": "Plant_Leaves_Crystal"
    },
    {
      "x": -6,
      "y": 26,
      "z": -1,
      "name": "Plant_Leaves_Crystal"
    },
    {
      "x": -6,
      "y": 27,
      "z": -1,
      "name": "Plant_Leaves_Crystal"
    },
    {
      "x": -6,
      "y": 33,
      "z": -1,
      "name": "Plant_Leaves_Crystal"
    },
    {
      "x": -6,
      "y": 34,
      "z": -1,
      "name": "Plant_Leaves_Crystal"
    },
    {
      "x": -6,
      "y": 36,
      "z": -1,
      "name": "Plant_Leaves_Crystal"
    },
    {
      "x": -6,
      "y": 37,
      "z": -1,
      "name": "Wood_Crystal_Trunk_Full"
    },
    {
      "x": -6,
      "y": 38,
      "z": -1,
      "name": "Plant_Leaves_Crystal"
    },
    {
      "x": -6,
      "y": 27,
      "z": 0,
      "name": "Plant_Leaves_Crystal"
    },
    {
      "x": -6,
      "y": 33,
      "z": 0,
      "name": "Plant_Leaves_Crystal"
    },
    {
      "x": -6,
      "y": 35,
      "z": 0,
      "name": "Wood_Crystal_Trunk_Full"
    },
    {
      "x": -6,
      "y": 36,
      "z": 0,
      "name": "Plant_Leaves_Crystal"
    },
    {
      "x": -6,
      "y": 37,
      "z": 0,
      "name": "Plant_Leaves_Crystal"
    },
    {
      "x": -6,
      "y": 38,
      "z": 0,
      "name": "Plant_Leaves_Crystal"
    },
    {
      "x": -6,
      "y": 35,
      "z": 1,
      "name": "Wood_Crystal_Trunk_Full"
    },
    {
      "x": -6,
      "y": 36,
      "z": 1,
      "name": "Plant_Leaves_Crystal"
    },
    {
      "x": -6,
      "y": 37,
      "z": 1,
      "name": "Plant_Leaves_Crystal"
    },
    {
      "x": -6,
      "y": 38,
      "z": 1,
      "name": "Plant_Leaves_Crystal"
    },
    {
      "x": -6,
      "y": 31,
      "z": 2,
      "name": "Wood_Crystal_Trunk_Full"
    },
    {
      "x": -6,
      "y": 32,
      "z": 2,
      "name": "Wood_Crystal_Trunk_Full"
    },
    {
      "x": -6,
      "y": 35,
      "z": 2,
      "name": "Wood_Crystal_Trunk_Full"
    },
    {
      "x": -6,
      "y": 37,
      "z": 2,
      "name": "Plant_Leaves_Crystal"
    },
    {
      "x": -6,
      "y": 38,
      "z": 2,
      "name": "Plant_Leaves_Crystal"
    },
    {
      "x": -6,
      "y": 28,
      "z": 3,
      "name": "Plant_Leaves_Crystal"
    },
    {
      "x": -6,
      "y": 31,
      "z": 3,
      "name": "Wood_Crystal_Trunk_Full"
    },
    {
      "x": -6,
      "y": 28,
      "z": 4,
      "name": "Plant_Leaves_Crystal"
    },
    {
      "x": -6,
      "y": 38,
      "z": 4,
      "name": "Plant_Leaves_Crystal"
    },
    {
      "x": -6,
      "y": 27,
      "z": 5,
      "name": "Wood_Crystal_Branch_Corner",
      "rotation": 2
    },
    {
      "x": -6,
      "y": 28,
      "z": 5,
      "name": "Plant_Leaves_Crystal"
    },
    {
      "x": -6,
      "y": 29,
      "z": 5,
      "name": "Plant_Leaves_Crystal"
    },
    {
      "x": -6,
      "y": 38,
      "z": 5,
      "name": "Plant_Leaves_Crystal"
    },
    {
      "x": -6,
      "y": 27,
      "z": 6,
      "name": "Wood_Crystal_Trunk_Full"
    },
    {
      "x": -6,
      "y": 28,
      "z": 6,
      "name": "Plant_Leaves_Crystal"
    },
    {
      "x": -6,
      "y": 29,
      "z": 6,
      "name": "Plant_Leaves_Crystal"
    },
    {
      "x": -6,
      "y": 38,
      "z": 6,
      "name": "Plant_Leaves_Crystal"
    },
    {
      "x": -6,
      "y": 26,
      "z": 7,
      "name": "Wood_Crystal_Roots"
    },
    {
      "x": -6,
      "y": 27,
      "z": 7,
      "name": "Wood_Crystal_Trunk_Full"
    },
    {
      "x": -6,
      "y": 28,
      "z": 7,
      "name": "Plant_Leaves_Crystal"
    },
    {
      "x": -6,
      "y": 29,
      "z": 7,
      "name": "Plant_Leaves_Crystal"
    },
    {
      "x": -6,
      "y": 33,
      "z": 7,
      "name": "Plant_Leaves_Crystal"
    },
    {
      "x": -6,
      "y": 34,
      "z": 7,
      "name": "Plant_Leaves_Crystal"
    },
    {
      "x": -6,
      "y": 38,
      "z": 7,
      "name": "Plant_Leaves_Crystal"
    },
    {
      "x": -6,
      "y": 27,
      "z": 8,
      "name": "Wood_Crystal_Branch_Corner"
    },
    {
      "x": -6,
      "y": 28,
      "z": 8,
      "name": "Plant_Leaves_Crystal"
    },
    {
      "x": -6,
      "y": 29,
      "z": 8,
      "name": "Plant_Leaves_Crystal"
    },
    {
      "x": -6,
      "y": 34,
      "z": 8,
      "name": "Plant_Leaves_Crystal"
    },
    {
      "x": -6,
      "y": 35,
      "z": 8,
      "name": "Plant_Leaves_Crystal"
    },
    {
      "x": -6,
      "y": 37,
      "z": 8,
      "name": "Wood_Crystal_Branch_Corner",
      "rotation": 3
    },
    {
      "x": -6,
      "y": 38,
      "z": 8,
      "name": "Plant_Leaves_Crystal"
    },
    {
      "x": -6,
      "y": 28,
      "z": 9,
      "name": "Plant_Leaves_Crystal"
    },
    {
      "x": -6,
      "y": 36,
      "z": 9,
      "name": "Plant_Leaves_Crystal"
    },
    {
      "x": -6,
      "y": 37,
      "z": 9,
      "name": "Plant_Leaves_Crystal"
    },
    {
      "x": -6,
      "y": 38,
      "z": 9,
      "name": "Plant_Leaves_Crystal"
    },
    {
      "x": -6,
      "y": 32,
      "z": 10,
      "name": "Wood_Crystal_Trunk_Full"
    },
    {
      "x": -6,
      "y": 33,
      "z": 10,
      "name": "Wood_Crystal_Trunk_Full"
    },
    {
      "x": -6,
      "y": 36,
      "z": 10,
      "name": "Plant_Leaves_Crystal"
    },
    {
      "x": -6,
      "y": 34,
      "z": 11,
      "name": "Plant_Leaves_Crystal"
    },
    {
      "x": -6,
      "y": 36,
      "z": 11,
      "name": "Plant_Leaves_Crystal"
    },
    {
      "x": -6,
      "y": 37,
      "z": 11,
      "name": "Plant_Leaves_Crystal"
    },
    {
      "x": -6,
      "y": 32,
      "z": 12,
      "name": "Wood_Crystal_Roots"
    },
    {
      "x": -6,
      "y": 33,
      "z": 12,
      "name": "Wood_Crystal_Trunk_Full"
    },
    {
      "x": -6,
      "y": 34,
      "z": 12,
      "name": "Plant_Leaves_Crystal"
    },
    {
      "x": -6,
      "y": 36,
      "z": 12,
      "name": "Plant_Leaves_Crystal"
    },
    {
      "x": -6,
      "y": 32,
      "z": 13,
      "name": "Wood_Crystal_Roots"
    },
    {
      "x": -6,
      "y": 33,
      "z": 13,
      "name": "Wood_Crystal_Trunk_Full"
    },
    {
      "x": -6,
      "y": 34,
      "z": 13,
      "name": "Plant_Leaves_Crystal"
    },
    {
      "x": -6,
      "y": 35,
      "z": 13,
      "name": "Plant_Leaves_Crystal"
    },
    {
      "x": -6,
      "y": 36,
      "z": 13,
      "name": "Plant_Leaves_Crystal"
    },
    {
      "x": -6,
      "y": 37,
      "z": 13,
      "name": "Plant_Leaves_Crystal"
    },
    {
      "x": -6,
      "y": 33,
      "z": 14,
      "name": "Wood_Crystal_Trunk_Full"
    },
    {
      "x": -6,
      "y": 34,
      "z": 14,
      "name": "Plant_Leaves_Crystal"
    },
    {
      "x": -6,
      "y": 35,
      "z": 14,
      "name": "Plant_Leaves_Crystal"
    },
    {
      "x": -6,
      "y": 36,
      "z": 14,
      "name": "Plant_Leaves_Crystal"
    },
    {
      "x": -6,
      "y": 33,
      "z": 15,
      "name": "Wood_Crystal_Branch_Corner"
    },
    {
      "x": -6,
      "y": 34,
      "z": 15,
      "name": "Plant_Leaves_Crystal"
    },
    {
      "x": -6,
      "y": 35,
      "z": 15,
      "name": "Plant_Leaves_Crystal"
    },
    {
      "x": -6,
      "y": 36,
      "z": 15,
      "name": "Plant_Leaves_Crystal"
    },
    {
      "x": -6,
      "y": 34,
      "z": 16,
      "name": "Plant_Leaves_Crystal"
    },
    {
      "x": -6,
      "y": 35,
      "z": 16,
      "name": "Plant_Leaves_Crystal"
    },
    {
      "x": -6,
      "y": 34,
      "z": 17,
      "name": "Plant_Leaves_Crystal"
    },
    {
      "x": -6,
      "y": 35,
      "z": 17,
      "name": "Plant_Leaves_Crystal"
    },
    {
      "x": -6,
      "y": 34,
      "z": 18,
      "name": "Plant_Leaves_Crystal"
    },
    {
      "x": -5,
      "y": 34,
      "z": -7,
      "name": "Plant_Leaves_Crystal"
    },
    {
      "x": -5,
      "y": 37,
      "z": -7,
      "name": "Plant_Leaves_Crystal"
    },
    {
      "x": -5,
      "y": 38,
      "z": -7,
      "name": "Plant_Leaves_Crystal"
    },
    {
      "x": -5,
      "y": 34,
      "z": -6,
      "name": "Plant_Leaves_Crystal"
    },
    {
      "x": -5,
      "y": 37,
      "z": -6,
      "name": "Plant_Leaves_Crystal"
    },
    {
      "x": -5,
      "y": 38,
      "z": -6,
      "name": "Plant_Leaves_Crystal"
    },
    {
      "x": -5,
      "y": 33,
      "z": -5,
      "name": "Plant_Leaves_Crystal"
    },
    {
      "x": -5,
      "y": 34,
      "z": -5,
      "name": "Plant_Leaves_Crystal"
    },
    {
      "x": -5,
      "y": 35,
      "z": -5,
      "name": "Plant_Leaves_Crystal"
    },
    {
      "x": -5,
      "y": 36,
      "z": -5,
      "name": "Plant_Leaves_Crystal"
    },
    {
      "x": -5,
      "y": 37,
      "z": -5,
      "name": "Plant_Leaves_Crystal"
    },
    {
      "x": -5,
      "y": 38,
      "z": -5,
      "name": "Plant_Leaves_Crystal"
    },
    {
      "x": -5,
      "y": 33,
      "z": -4,
      "name": "Plant_Leaves_Crystal"
    },
    {
      "x": -5,
      "y": 34,
      "z": -4,
      "name": "Plant_Leaves_Crystal"
    },
    {
      "x": -5,
      "y": 36,
      "z": -4,
      "name": "Plant_Leaves_Crystal"
    },
    {
      "x": -5,
      "y": 37,
      "z": -4,
      "name": "Plant_Leaves_Crystal"
    },
    {
      "x": -5,
      "y": 38,
      "z": -4,
      "name": "Plant_Leaves_Crystal"
    },
    {
      "x": -5,
      "y": 4,
      "z": -3,
      "name": "Wood_Crystal_Roots"
    },
    {
      "x": -5,
      "y": 5,
      "z": -3,
      "name": "Wood_Crystal_Trunk"
    },
    {
      "x": -5,
      "y": 6,
      "z": -3,
      "name": "Wood_Crystal_Trunk"
    },
    {
      "x": -5,
      "y": 7,
      "z": -3,
      "name": "Wood_Crystal_Trunk"
    },
    {
      "x": -5,
      "y": 8,
      "z": -3,
      "name": "Wood_Crystal_Trunk"
    },
    {
      "x": -5,
      "y": 9,
      "z": -3,
      "name": "Wood_Crystal_Trunk_Full"
    },
    {
      "x": -5,
      "y": 27,
      "z": -3,
      "name": "Plant_Leaves_Crystal"
    },
    {
      "x": -5,
      "y": 33,
      "z": -3,
      "name": "Wood_Crystal_Branch_Corner",
      "rotation": 3
    },
    {
      "x": -5,
      "y": 36,
      "z": -3,
      "name": "Plant_Leaves_Crystal"
    },
    {
      "x": -5,
      "y": 37,
      "z": -3,
      "name": "Wood_Crystal_Trunk_Full"
    },
    {
      "x": -5,
      "y": 38,
      "z": -3,
      "name": "Plant_Leaves_Crystal"
    },
    {
      "x": -5,
      "y": 5,
      "z": -2,
      "name": "Wood_Crystal_Roots"
    },
    {
      "x": -5,
      "y": 6,
      "z": -2,
      "name": "Wood_Crystal_Trunk"
    },
    {
      "x": -5,
      "y": 7,
      "z": -2,
      "name": "Wood_Crystal_Trunk"
    },
    {
      "x": -5,
      "y": 8,
      "z": -2,
      "name": "Wood_Crystal_Trunk"
    },
    {
      "x": -5,
      "y": 9,
      "z": -2,
      "name": "Wood_Crystal_Trunk"
    },
    {
      "x": -5,
      "y": 10,
      "z": -2,
      "name": "Wood_Crystal_Trunk_Full"
    },
    {
      "x": -5,
      "y": 26,
      "z": -2,
      "name": "Plant_Leaves_Crystal"
    },
    {
      "x": -5,
      "y": 27,
      "z": -2,
      "name": "Plant_Leaves_Crystal"
    },
    {
      "x": -5,
      "y": 36,
      "z": -2,
      "name": "Plant_Leaves_Crystal"
    },
    {
      "x": -5,
      "y": 37,
      "z": -2,
      "name": "Wood_Crystal_Trunk_Full"
    },
    {
      "x": -5,
      "y": 38,
      "z": -2,
      "name": "Plant_Leaves_Crystal"
    },
    {
      "x": -5,
      "y": 7,
      "z": -1,
      "name": "Wood_Crystal_Trunk"
    },
    {
      "x": -5,
      "y": 8,
      "z": -1,
      "name": "Wood_Crystal_Trunk"
    },
    {
      "x": -5,
      "y": 9,
      "z": -1,
      "name": "Wood_Crystal_Trunk"
    },
    {
      "x": -5,
      "y": 10,
      "z": -1,
      "name": "Wood_Crystal_Trunk"
    },
    {
      "x": -5,
      "y": 11,
      "z": -1,
      "name": "Wood_Crystal_Trunk_Full"
    },
    {
      "x": -5,
      "y": 26,
      "z": -1,
      "name": "Plant_Leaves_Crystal"
    },
    {
      "x": -5,
      "y": 27,
      "z": -1,
      "name": "Plant_Leaves_Crystal"
    },
    {
      "x": -5,
      "y": 28,
      "z": -1,
      "name": "Plant_Leaves_Crystal"
    },
    {
      "x": -5,
      "y": 36,
      "z": -1,
      "name": "Plant_Leaves_Crystal"
    },
    {
      "x": -5,
      "y": 37,
      "z": -1,
      "name": "Wood_Crystal_Trunk_Full"
    },
    {
      "x": -5,
      "y": 7,
      "z": 0,
      "name": "Wood_Crystal_Roots"
    },
    {
      "x": -5,
      "y": 8,
      "z": 0,
      "name": "Wood_Crystal_Trunk"
    },
    {
      "x": -5,
      "y": 9,
      "z": 0,
      "name": "Wood_Crystal_Trunk"
    },
    {
      "x": -5,
      "y": 10,
      "z": 0,
      "name": "Wood_Crystal_Trunk"
    },
    {
      "x": -5,
      "y": 11,
      "z": 0,
      "name": "Wood_Crystal_Trunk"
    },
    {
      "x": -5,
      "y": 12,
      "z": 0,
      "name": "Wood_Crystal_Trunk_Full"
    },
    {
      "x": -5,
      "y": 26,
      "z": 0,
      "name": "Plant_Leaves_Crystal"
    },
    {
      "x": -5,
      "y": 27,
      "z": 0,
      "name": "Plant_Leaves_Crystal"
    },
    {
      "x": -5,
      "y": 36,
      "z": 0,
      "name": "Wood_Crystal_Trunk_Full"
    },
    {
      "x": -5,
      "y": 37,
      "z": 0,
      "name": "Wood_Crystal_Trunk"
    },
    {
      "x": -5,
      "y": 38,
      "z": 0,
      "name": "Wood_Crystal_Trunk_Full"
    },
    {
      "x": -5,
      "y": 9,
      "z": 1,
      "name": "Wood_Crystal_Trunk"
    },
    {
      "x": -5,
      "y": 10,
      "z": 1,
      "name": "Wood_Crystal_Trunk"
    },
    {
      "x": -5,
      "y": 11,
      "z": 1,
      "name": "Wood_Crystal_Trunk"
    },
    {
      "x": -5,
      "y": 12,
      "z": 1,
      "name": "Wood_Crystal_Trunk"
    },
    {
      "x": -5,
      "y": 13,
      "z": 1,
      "name": "Wood_Crystal_Trunk_Full"
    },
    {
      "x": -5,
      "y": 26,
      "z": 1,
      "name": "Plant_Fruit_Pinkberry",
      "rotation": 8
    },
    {
      "x": -5,
      "y": 27,
      "z": 1,
      "name": "Plant_Leaves_Crystal"
    },
    {
      "x": -5,
      "y": 37,
      "z": 1,
      "name": "Plant_Leaves_Crystal"
    },
    {
      "x": -5,
      "y": 10,
      "z": 2,
      "name": "Wood_Crystal_Trunk"
    },
    {
      "x": -5,
      "y": 11,
      "z": 2,
      "name": "Wood_Crystal_Trunk"
    },
    {
      "x": -5,
      "y": 12,
      "z": 2,
      "name": "Wood_Crystal_Trunk_Full"
    },
    {
      "x": -5,
      "y": 34,
      "z": 2,
      "name": "Wood_Crystal_Trunk_Full"
    },
    {
      "x": -5,
      "y": 35,
      "z": 2,
      "name": "Wood_Crystal_Trunk_Full"
    },
    {
      "x": -5,
      "y": 38,
      "z": 2,
      "name": "Plant_Leaves_Crystal"
    },
    {
      "x": -5,
      "y": 28,
      "z": 3,
      "name": "Plant_Leaves_Crystal"
    },
    {
      "x": -5,
      "y": 30,
      "z": 3,
      "name": "Wood_Crystal_Trunk_Full"
    },
    {
      "x": -5,
      "y": 31,
      "z": 3,
      "name": "Wood_Crystal_Trunk_Full"
    },
    {
      "x": -5,
      "y": 34,
      "z": 3,
      "name": "Wood_Crystal_Trunk_Full"
    },
    {
      "x": -5,
      "y": 28,
      "z": 4,
      "name": "Plant_Leaves_Crystal"
    },
    {
      "x": -5,
      "y": 29,
      "z": 4,
      "name": "Wood_Crystal_Trunk_Full"
    },
    {
      "x": -5,
      "y": 30,
      "z": 4,
      "name": "Wood_Crystal_Trunk"
    },
    {
      "x": -5,
      "y": 31,
      "z": 4,
      "name": "Wood_Crystal_Trunk_Full"
    },
    {
      "x": -5,
      "y": 37,
      "z": 4,
      "name": "Wood_Crystal_Trunk_Full"
    },
    {
      "x": -5,
      "y": 38,
      "z": 4,
      "name": "Plant_Leaves_Crystal"
    },
    {
      "x": -5,
      "y": 26,
      "z": 5,
      "name": "Wood_Crystal_Trunk_Full"
    },
    {
      "x": -5,
      "y": 27,
      "z": 5,
      "name": "Wood_Crystal_Trunk"
    },
    {
      "x": -5,
      "y": 28,
      "z": 5,
      "name": "Wood_Crystal_Trunk_Full"
    },
    {
      "x": -5,
      "y": 37,
      "z": 5,
      "name": "Plant_Leaves_Crystal"
    },
    {
      "x": -5,
      "y": 38,
      "z": 5,
      "name": "Plant_Leaves_Crystal"
    },
    {
      "x": -5,
      "y": 27,
      "z": 6,
      "name": "Wood_Crystal_Trunk_Full"
    },
    {
      "x": -5,
      "y": 37,
      "z": 6,
      "name": "Plant_Leaves_Crystal"
    },
    {
      "x": -5,
      "y": 38,
      "z": 6,
      "name": "Plant_Leaves_Crystal"
    },
    {
      "x": -5,
      "y": 28,
      "z": 7,
      "name": "Plant_Leaves_Crystal"
    },
    {
      "x": -5,
      "y": 38,
      "z": 7,
      "name": "Plant_Leaves_Crystal"
    },
    {
      "x": -5,
      "y": 9,
      "z": 8,
      "name": "Wood_Crystal_Trunk"
    },
    {
      "x": -5,
      "y": 10,
      "z": 8,
      "name": "Wood_Crystal_Trunk_Full"
    },
    {
      "x": -5,
      "y": 28,
      "z": 8,
      "name": "Plant_Leaves_Crystal"
    },
    {
      "x": -5,
      "y": 34,
      "z": 8,
      "name": "Plant_Leaves_Crystal"
    },
    {
      "x": -5,
      "y": 35,
      "z": 8,
      "name": "Plant_Leaves_Crystal"
    },
    {
      "x": -5,
      "y": 37,
      "z": 8,
      "name": "Wood_Crystal_Branch_Long",
      "rotation": 5
    },
    {
      "x": -5,
      "y": 7,
      "z": 9,
      "name": "Wood_Crystal_Trunk"
    },
    {
      "x": -5,
      "y": 8,
      "z": 9,
      "name": "Wood_Crystal_Trunk"
    },
    {
      "x": -5,
      "y": 9,
      "z": 9,
      "name": "Wood_Crystal_Trunk"
    },
    {
      "x": -5,
      "y": 10,
      "z": 9,
      "name": "Wood_Crystal_Trunk"
    },
    {
      "x": -5,
      "y": 11,
      "z": 9,
      "name": "Wood_Crystal_Trunk_Full"
    },
    {
      "x": -5,
      "y": 35,
      "z": 9,
      "name": "Plant_Leaves_Crystal"
    },
    {
      "x": -5,
      "y": 36,
      "z": 9,
      "name": "Plant_Leaves_Crystal"
    },
    {
      "x": -5,
      "y": 5,
      "z": 10,
      "name": "Wood_Crystal_Roots"
    },
    {
      "x": -5,
      "y": 6,
      "z": 10,
      "name": "Wood_Crystal_Trunk"
    },
    {
      "x": -5,
      "y": 7,
      "z": 10,
      "name": "Wood_Crystal_Trunk"
    },
    {
      "x": -5,
      "y": 8,
      "z": 10,
      "name": "Wood_Crystal_Trunk"
    },
    {
      "x": -5,
      "y": 9,
      "z": 10,
      "name": "Wood_Crystal_Trunk"
    },
    {
      "x": -5,
      "y": 10,
      "z": 10,
      "name": "Wood_Crystal_Trunk_Full"
    },
    {
      "x": -5,
      "y": 32,
      "z": 10,
      "name": "Wood_Crystal_Trunk_Full"
    },
    {
      "x": -5,
      "y": 33,
      "z": 10,
      "name": "Wood_Crystal_Trunk_Full"
    },
    {
      "x": -5,
      "y": 35,
      "z": 10,
      "name": "Plant_Leaves_Crystal"
    },
    {
      "x": -5,
      "y": 36,
      "z": 10,
      "name": "Plant_Leaves_Crystal"
    },
    {
      "x": -5,
      "y": 37,
      "z": 10,
      "name": "Plant_Leaves_Crystal"
    },
    {
      "x": -5,
      "y": 38,
      "z": 10,
      "name": "Plant_Leaves_Crystal"
    },
    {
      "x": -5,
      "y": 6,
      "z": 11,
      "name": "Wood_Crystal_Trunk"
    },
    {
      "x": -5,
      "y": 7,
      "z": 11,
      "name": "Wood_Crystal_Trunk"
    },
    {
      "x": -5,
      "y": 8,
      "z": 11,
      "name": "Wood_Crystal_Trunk_Full"
    },
    {
      "x": -5,
      "y": 26,
      "z": 11,
      "name": "Plant_Leaves_Crystal"
    },
    {
      "x": -5,
      "y": 33,
      "z": 11,
      "name": "Wood_Crystal_Trunk_Full"
    },
    {
      "x": -5,
      "y": 35,
      "z": 11,
      "name": "Plant_Leaves_Crystal"
    },
    {
      "x": -5,
      "y": 36,
      "z": 11,
      "name": "Plant_Leaves_Crystal"
    },
    {
      "x": -5,
      "y": 37,
      "z": 11,
      "name": "Plant_Leaves_Crystal"
    },
    {
      "x": -5,
      "y": 38,
      "z": 11,
      "name": "Plant_Leaves_Crystal"
    },
    {
      "x": -5,
      "y": 33,
      "z": 12,
      "name": "Wood_Crystal_Trunk_Full"
    },
    {
      "x": -5,
      "y": 34,
      "z": 12,
      "name": "Plant_Leaves_Crystal"
    },
    {
      "x": -5,
      "y": 35,
      "z": 12,
      "name": "Plant_Leaves_Crystal"
    },
    {
      "x": -5,
      "y": 36,
      "z": 12,
      "name": "Plant_Leaves_Crystal"
    },
    {
      "x": -5,
      "y": 37,
      "z": 12,
      "name": "Plant_Leaves_Crystal"
    },
    {
      "x": -5,
      "y": 35,
      "z": 13,
      "name": "Plant_Leaves_Crystal"
    },
    {
      "x": -5,
      "y": 36,
      "z": 13,
      "name": "Plant_Leaves_Crystal"
    },
    {
      "x": -5,
      "y": 36,
      "z": 14,
      "name": "Plant_Leaves_Crystal"
    },
    {
      "x": -5,
      "y": 34,
      "z": 15,
      "name": "Plant_Leaves_Crystal"
    },
    {
      "x": -5,
      "y": 35,
      "z": 15,
      "name": "Plant_Leaves_Crystal"
    },
    {
      "x": -5,
      "y": 34,
      "z": 16,
      "name": "Plant_Leaves_Crystal"
    },
    {
      "x": -5,
      "y": 34,
      "z": 17,
      "name": "Plant_Leaves_Crystal"
    },
    {
      "x": -5,
      "y": 34,
      "z": 18,
      "name": "Plant_Leaves_Crystal"
    },
    {
      "x": -4,
      "y": 34,
      "z": -7,
      "name": "Plant_Leaves_Crystal"
    },
    {
      "x": -4,
      "y": 38,
      "z": -7,
      "name": "Plant_Leaves_Crystal"
    },
    {
      "x": -4,
      "y": 34,
      "z": -6,
      "name": "Plant_Leaves_Crystal"
    },
    {
      "x": -4,
      "y": 35,
      "z": -6,
      "name": "Plant_Leaves_Crystal"
    },
    {
      "x": -4,
      "y": 38,
      "z": -6,
      "name": "Plant_Leaves_Crystal"
    },
    {
      "x": -4,
      "y": 34,
      "z": -5,
      "name": "Plant_Leaves_Crystal"
    },
    {
      "x": -4,
      "y": 35,
      "z": -5,
      "name": "Plant_Leaves_Crystal"
    },
    {
      "x": -4,
      "y": 36,
      "z": -5,
      "name": "Plant_Leaves_Crystal"
    },
    {
      "x": -4,
      "y": 38,
      "z": -5,
      "name": "Plant_Leaves_Crystal"
    },
    {
      "x": -4,
      "y": 27,
      "z": -4,
      "name": "Plant_Leaves_Crystal"
    },
    {
      "x": -4,
      "y": 33,
      "z": -4,
      "name": "Plant_Leaves_Crystal"
    },
    {
      "x": -4,
      "y": 34,
      "z": -4,
      "name": "Plant_Leaves_Crystal"
    },
    {
      "x": -4,
      "y": 36,
      "z": -4,
      "name": "Plant_Leaves_Crystal"
    },
    {
      "x": -4,
      "y": 38,
      "z": -4,
      "name": "Plant_Leaves_Crystal"
    },
    {
      "x": -4,
      "y": 6,
      "z": -3,
      "name": "Wood_Crystal_Trunk"
    },
    {
      "x": -4,
      "y": 7,
      "z": -3,
      "name": "Wood_Crystal_Trunk"
    },
    {
      "x": -4,
      "y": 8,
      "z": -3,
      "name": "Wood_Crystal_Trunk"
    },
    {
      "x": -4,
      "y": 9,
      "z": -3,
      "name": "Wood_Crystal_Trunk_Full"
    },
    {
      "x": -4,
      "y": 27,
      "z": -3,
      "name": "Plant_Leaves_Crystal"
    },
    {
      "x": -4,
      "y": 33,
      "z": -3,
      "name": "Wood_Crystal_Branch_Long",
      "rotation": 5
    },
    {
      "x": -4,
      "y": 34,
      "z": -3,
      "name": "Plant_Leaves_Crystal"
    },
    {
      "x": -4,
      "y": 35,
      "z": -3,
      "name": "Plant_Leaves_Crystal"
    },
    {
      "x": -4,
      "y": 36,
      "z": -3,
      "name": "Plant_Leaves_Crystal"
    },
    {
      "x": -4,
      "y": 38,
      "z": -3,
      "name": "Plant_Leaves_Crystal"
    },
    {
      "x": -4,
      "y": 6,
      "z": -2,
      "name": "Wood_Crystal_Trunk"
    },
    {
      "x": -4,
      "y": 7,
      "z": -2,
      "name": "Wood_Crystal_Trunk"
    },
    {
      "x": -4,
      "y": 8,
      "z": -2,
      "name": "Wood_Crystal_Trunk"
    },
    {
      "x": -4,
      "y": 9,
      "z": -2,
      "name": "Wood_Crystal_Trunk"
    },
    {
      "x": -4,
      "y": 10,
      "z": -2,
      "name": "Wood_Crystal_Trunk"
    },
    {
      "x": -4,
      "y": 11,
      "z": -2,
      "name": "Wood_Crystal_Trunk_Full"
    },
    {
      "x": -4,
      "y": 23,
      "z": -2,
      "name": "Plant_Leaves_Crystal"
    },
    {
      "x": -4,
      "y": 24,
      "z": -2,
      "name": "Plant_Leaves_Crystal"
    },
    {
      "x": -4,
      "y": 25,
      "z": -2,
      "name": "Plant_Leaves_Crystal"
    },
    {
      "x": -4,
      "y": 26,
      "z": -2,
      "name": "Plant_Leaves_Crystal"
    },
    {
      "x": -4,
      "y": 27,
      "z": -2,
      "name": "Plant_Leaves_Crystal"
    },
    {
      "x": -4,
      "y": 34,
      "z": -2,
      "name": "Plant_Leaves_Crystal"
    },
    {
      "x": -4,
      "y": 38,
      "z": -2,
      "name": "Plant_Leaves_Crystal"
    },
    {
      "x": -4,
      "y": 6,
      "z": -1,
      "name": "Wood_Crystal_Roots"
    },
    {
      "x": -4,
      "y": 7,
      "z": -1,
      "name": "Wood_Crystal_Trunk"
    },
    {
      "x": -4,
      "y": 8,
      "z": -1,
      "name": "Wood_Crystal_Trunk"
    },
    {
      "x": -4,
      "y": 9,
      "z": -1,
      "name": "Wood_Crystal_Trunk"
    },
    {
      "x": -4,
      "y": 10,
      "z": -1,
      "name": "Wood_Crystal_Trunk"
    },
    {
      "x": -4,
      "y": 11,
      "z": -1,
      "name": "Wood_Crystal_Trunk"
    },
    {
      "x": -4,
      "y": 12,
      "z": -1,
      "name": "Wood_Crystal_Trunk_Full"
    },
    {
      "x": -4,
      "y": 26,
      "z": -1,
      "name": "Wood_Crystal_Branch_Long",
      "rotation": 5
    },
    {
      "x": -4,
      "y": 27,
      "z": -1,
      "name": "Plant_Leaves_Crystal"
    },
    {
      "x": -4,
      "y": 28,
      "z": -1,
      "name": "Plant_Leaves_Crystal"
    },
    {
      "x": -4,
      "y": 38,
      "z": -1,
      "name": "Plant_Leaves_Crystal"
    },
    {
      "x": -4,
      "y": 7,
      "z": 0,
      "name": "Wood_Crystal_Trunk"
    },
    {
      "x": -4,
      "y": 8,
      "z": 0,
      "name": "Wood_Crystal_Trunk"
    },
    {
      "x": -4,
      "y": 9,
      "z": 0,
      "name": "Wood_Crystal_Trunk"
    },
    {
      "x": -4,
      "y": 10,
      "z": 0,
      "name": "Wood_Crystal_Trunk"
    },
    {
      "x": -4,
      "y": 11,
      "z": 0,
      "name": "Wood_Crystal_Trunk"
    },
    {
      "x": -4,
      "y": 12,
      "z": 0,
      "name": "Wood_Crystal_Trunk_Full"
    },
    {
      "x": -4,
      "y": 13,
      "z": 0,
      "name": "Plant_Crop_Mushroom_Glowing_Red"
    },
    {
      "x": -4,
      "y": 26,
      "z": 0,
      "name": "Plant_Leaves_Crystal"
    },
    {
      "x": -4,
      "y": 27,
      "z": 0,
      "name": "Plant_Leaves_Crystal"
    },
    {
      "x": -4,
      "y": 28,
      "z": 0,
      "name": "Plant_Leaves_Crystal"
    },
    {
      "x": -4,
      "y": 35,
      "z": 0,
      "name": "Wood_Crystal_Trunk_Full"
    },
    {
      "x": -4,
      "y": 36,
      "z": 0,
      "name": "Wood_Crystal_Trunk_Full"
    },
    {
      "x": -4,
      "y": 8,
      "z": 1,
      "name": "Wood_Crystal_Roots"
    },
    {
      "x": -4,
      "y": 9,
      "z": 1,
      "name": "Wood_Crystal_Trunk"
    },
    {
      "x": -4,
      "y": 10,
      "z": 1,
      "name": "Wood_Crystal_Trunk"
    },
    {
      "x": -4,
      "y": 11,
      "z": 1,
      "name": "Wood_Crystal_Trunk"
    },
    {
      "x": -4,
      "y": 12,
      "z": 1,
      "name": "Wood_Crystal_Trunk"
    },
    {
      "x": -4,
      "y": 13,
      "z": 1,
      "name": "Wood_Crystal_Trunk"
    },
    {
      "x": -4,
      "y": 14,
      "z": 1,
      "name": "Wood_Crystal_Trunk_Full"
    },
    {
      "x": -4,
      "y": 27,
      "z": 1,
      "name": "Plant_Leaves_Crystal"
    },
    {
      "x": -4,
      "y": 35,
      "z": 1,
      "name": "Wood_Crystal_Trunk_Full"
    },
    {
      "x": -4,
      "y": 38,
      "z": 1,
      "name": "Plant_Leaves_Crystal"
    },
    {
      "x": -4,
      "y": 9,
      "z": 2,
      "name": "Wood_Crystal_Trunk"
    },
    {
      "x": -4,
      "y": 10,
      "z": 2,
      "name": "Wood_Crystal_Trunk"
    },
    {
      "x": -4,
      "y": 11,
      "z": 2,
      "name": "Wood_Crystal_Trunk"
    },
    {
      "x": -4,
      "y": 12,
      "z": 2,
      "name": "Wood_Crystal_Trunk"
    },
    {
      "x": -4,
      "y": 13,
      "z": 2,
      "name": "Wood_Crystal_Trunk"
    },
    {
      "x": -4,
      "y": 14,
      "z": 2,
      "name": "Wood_Crystal_Trunk"
    },
    {
      "x": -4,
      "y": 15,
      "z": 2,
      "name": "Wood_Crystal_Trunk_Full"
    },
    {
      "x": -4,
      "y": 27,
      "z": 2,
      "name": "Plant_Leaves_Crystal"
    },
    {
      "x": -4,
      "y": 38,
      "z": 2,
      "name": "Plant_Leaves_Crystal"
    },
    {
      "x": -4,
      "y": 10,
      "z": 3,
      "name": "Wood_Crystal_Trunk"
    },
    {
      "x": -4,
      "y": 11,
      "z": 3,
      "name": "Wood_Crystal_Trunk"
    },
    {
      "x": -4,
      "y": 12,
      "z": 3,
      "name": "Wood_Crystal_Trunk"
    },
    {
      "x": -4,
      "y": 13,
      "z": 3,
      "name": "Wood_Crystal_Trunk"
    },
    {
      "x": -4,
      "y": 14,
      "z": 3,
      "name": "Wood_Crystal_Trunk"
    },
    {
      "x": -4,
      "y": 15,
      "z": 3,
      "name": "Wood_Crystal_Trunk_Full"
    },
    {
      "x": -4,
      "y": 29,
      "z": 3,
      "name": "Wood_Crystal_Trunk_Full"
    },
    {
      "x": -4,
      "y": 30,
      "z": 3,
      "name": "Wood_Crystal_Trunk"
    },
    {
      "x": -4,
      "y": 31,
      "z": 3,
      "name": "Wood_Crystal_Trunk_Full"
    },
    {
      "x": -4,
      "y": 33,
      "z": 3,
      "name": "Wood_Crystal_Trunk_Full"
    },
    {
      "x": -4,
      "y": 34,
      "z": 3,
      "name": "Wood_Crystal_Trunk_Full"
    },
    {
      "x": -4,
      "y": 11,
      "z": 4,
      "name": "Wood_Crystal_Trunk"
    },
    {
      "x": -4,
      "y": 12,
      "z": 4,
      "name": "Wood_Crystal_Trunk"
    },
    {
      "x": -4,
      "y": 13,
      "z": 4,
      "name": "Wood_Crystal_Trunk"
    },
    {
      "x": -4,
      "y": 24,
      "z": 4,
      "name": "Wood_Crystal_Trunk_Full"
    },
    {
      "x": -4,
      "y": 25,
      "z": 4,
      "name": "Wood_Crystal_Trunk"
    },
    {
      "x": -4,
      "y": 26,
      "z": 4,
      "name": "Wood_Crystal_Trunk"
    },
    {
      "x": -4,
      "y": 27,
      "z": 4,
      "name": "Wood_Crystal_Trunk"
    },
    {
      "x": -4,
      "y": 28,
      "z": 4,
      "name": "Wood_Crystal_Trunk"
    },
    {
      "x": -4,
      "y": 29,
      "z": 4,
      "name": "Wood_Crystal_Trunk"
    },
    {
      "x": -4,
      "y": 30,
      "z": 4,
      "name": "Wood_Crystal_Trunk"
    },
    {
      "x": -4,
      "y": 31,
      "z": 4,
      "name": "Wood_Crystal_Trunk"
    },
    {
      "x": -4,
      "y": 32,
      "z": 4,
      "name": "Wood_Crystal_Trunk"
    },
    {
      "x": -4,
      "y": 33,
      "z": 4,
      "name": "Wood_Crystal_Trunk"
    },
    {
      "x": -4,
      "y": 34,
      "z": 4,
      "name": "Wood_Crystal_Trunk_Full"
    },
    {
      "x": -4,
      "y": 37,
      "z": 4,
      "name": "Wood_Crystal_Trunk_Full"
    },
    {
      "x": -4,
      "y": 38,
      "z": 4,
      "name": "Plant_Leaves_Crystal"
    },
    {
      "x": -4,
      "y": 10,
      "z": 5,
      "name": "Wood_Crystal_Trunk"
    },
    {
      "x": -4,
      "y": 11,
      "z": 5,
      "name": "Wood_Crystal_Trunk"
    },
    {
      "x": -4,
      "y": 12,
      "z": 5,
      "name": "Wood_Crystal_Trunk"
    },
    {
      "x": -4,
      "y": 13,
      "z": 5,
      "name": "Rock_Crystal_Pink_Medium"
    },
    {
      "x": -4,
      "y": 18,
      "z": 5,
      "name": "Plant_Flower_Common_Poisoned2",
      "rotation": 7
    },
    {
      "x": -4,
      "y": 26,
      "z": 5,
      "name": "Wood_Crystal_Trunk_Full"
    },
    {
      "x": -4,
      "y": 27,
      "z": 5,
      "name": "Wood_Crystal_Trunk"
    },
    {
      "x": -4,
      "y": 28,
      "z": 5,
      "name": "Wood_Crystal_Trunk"
    },
    {
      "x": -4,
      "y": 29,
      "z": 5,
      "name": "Wood_Crystal_Trunk"
    },
    {
      "x": -4,
      "y": 30,
      "z": 5,
      "name": "Wood_Crystal_Trunk_Full"
    },
    {
      "x": -4,
      "y": 37,
      "z": 5,
      "name": "Plant_Leaves_Crystal"
    },
    {
      "x": -4,
      "y": 38,
      "z": 5,
      "name": "Plant_Leaves_Crystal"
    },
    {
      "x": -4,
      "y": 10,
      "z": 6,
      "name": "Wood_Crystal_Trunk"
    },
    {
      "x": -4,
      "y": 11,
      "z": 6,
      "name": "Wood_Crystal_Trunk"
    },
    {
      "x": -4,
      "y": 12,
      "z": 6,
      "name": "Wood_Crystal_Trunk"
    },
    {
      "x": -4,
      "y": 13,
      "z": 6,
      "name": "Wood_Crystal_Trunk"
    },
    {
      "x": -4,
      "y": 14,
      "z": 6,
      "name": "Wood_Crystal_Trunk"
    },
    {
      "x": -4,
      "y": 16,
      "z": 6,
      "name": "Plant_Flower_Common_Poisoned2",
      "rotation": 6
    },
    {
      "x": -4,
      "y": 17,
      "z": 6,
      "name": "Plant_Flower_Common_Poisoned2",
      "rotation": 7
    },
    {
      "x": -4,
      "y": 18,
      "z": 6,
      "name": "Plant_Flower_Common_Poisoned2",
      "rotation": 7
    },
    {
      "x": -4,
      "y": 37,
      "z": 6,
      "name": "Plant_Leaves_Crystal"
    },
    {
      "x": -4,
      "y": 38,
      "z": 6,
      "name": "Plant_Leaves_Crystal"
    },
    {
      "x": -4,
      "y": 11,
      "z": 7,
      "name": "Wood_Crystal_Trunk"
    },
    {
      "x": -4,
      "y": 12,
      "z": 7,
      "name": "Wood_Crystal_Trunk"
    },
    {
      "x": -4,
      "y": 13,
      "z": 7,
      "name": "Wood_Crystal_Trunk"
    },
    {
      "x": -4,
      "y": 14,
      "z": 7,
      "name": "Wood_Crystal_Trunk"
    },
    {
      "x": -4,
      "y": 15,
      "z": 7,
      "name": "Wood_Crystal_Trunk"
    },
    {
      "x": -4,
      "y": 16,
      "z": 7,
      "name": "Wood_Crystal_Trunk_Full"
    },
    {
      "x": -4,
      "y": 38,
      "z": 7,
      "name": "Plant_Leaves_Crystal"
    },
    {
      "x": -4,
      "y": 8,
      "z": 8,
      "name": "Wood_Crystal_Trunk"
    },
    {
      "x": -4,
      "y": 9,
      "z": 8,
      "name": "Wood_Crystal_Trunk"
    },
    {
      "x": -4,
      "y": 10,
      "z": 8,
      "name": "Wood_Crystal_Trunk"
    },
    {
      "x": -4,
      "y": 11,
      "z": 8,
      "name": "Wood_Crystal_Trunk"
    },
    {
      "x": -4,
      "y": 12,
      "z": 8,
      "name": "Wood_Crystal_Trunk"
    },
    {
      "x": -4,
      "y": 13,
      "z": 8,
      "name": "Wood_Crystal_Trunk"
    },
    {
      "x": -4,
      "y": 14,
      "z": 8,
      "name": "Wood_Crystal_Trunk"
    },
    {
      "x": -4,
      "y": 15,
      "z": 8,
      "name": "Wood_Crystal_Trunk"
    },
    {
      "x": -4,
      "y": 16,
      "z": 8,
      "name": "Wood_Crystal_Trunk"
    },
    {
      "x": -4,
      "y": 17,
      "z": 8,
      "name": "Wood_Crystal_Trunk"
    },
    {
      "x": -4,
      "y": 18,
      "z": 8,
      "name": "Wood_Crystal_Trunk_Full"
    },
    {
      "x": -4,
      "y": 26,
      "z": 8,
      "name": "Plant_Leaves_Crystal"
    },
    {
      "x": -4,
      "y": 31,
      "z": 8,
      "name": "Wood_Crystal_Trunk_Full"
    },
    {
      "x": -4,
      "y": 32,
      "z": 8,
      "name": "Wood_Crystal_Trunk_Full"
    },
    {
      "x": -4,
      "y": 37,
      "z": 8,
      "name": "Wood_Crystal_Branch_Long",
      "rotation": 5
    },
    {
      "x": -4,
      "y": 38,
      "z": 8,
      "name": "Plant_Leaves_Crystal"
    },
    {
      "x": -4,
      "y": 6,
      "z": 9,
      "name": "Wood_Crystal_Roots"
    },
    {
      "x": -4,
      "y": 7,
      "z": 9,
      "name": "Wood_Crystal_Trunk"
    },
    {
      "x": -4,
      "y": 8,
      "z": 9,
      "name": "Wood_Crystal_Trunk"
    },
    {
      "x": -4,
      "y": 9,
      "z": 9,
      "name": "Wood_Crystal_Trunk"
    },
    {
      "x": -4,
      "y": 10,
      "z": 9,
      "name": "Wood_Crystal_Trunk"
    },
    {
      "x": -4,
      "y": 11,
      "z": 9,
      "name": "Wood_Crystal_Trunk"
    },
    {
      "x": -4,
      "y": 12,
      "z": 9,
      "name": "Wood_Crystal_Trunk"
    },
    {
      "x": -4,
      "y": 13,
      "z": 9,
      "name": "Wood_Crystal_Trunk"
    },
    {
      "x": -4,
      "y": 14,
      "z": 9,
      "name": "Wood_Crystal_Trunk_Full"
    },
    {
      "x": -4,
      "y": 26,
      "z": 9,
      "name": "Plant_Leaves_Crystal"
    },
    {
      "x": -4,
      "y": 32,
      "z": 9,
      "name": "Wood_Crystal_Trunk_Full"
    },
    {
      "x": -4,
      "y": 33,
      "z": 9,
      "name": "Wood_Crystal_Trunk_Full"
    },
    {
      "x": -4,
      "y": 35,
      "z": 9,
      "name": "Plant_Leaves_Crystal"
    },
    {
      "x": -4,
      "y": 36,
      "z": 9,
      "name": "Plant_Leaves_Crystal"
    },
    {
      "x": -4,
      "y": 38,
      "z": 9,
      "name": "Plant_Leaves_Crystal"
    },
    {
      "x": -4,
      "y": 6,
      "z": 10,
      "name": "Wood_Crystal_Roots"
    },
    {
      "x": -4,
      "y": 7,
      "z": 10,
      "name": "Wood_Crystal_Trunk"
    },
    {
      "x": -4,
      "y": 8,
      "z": 10,
      "name": "Wood_Crystal_Trunk"
    },
    {
      "x": -4,
      "y": 9,
      "z": 10,
      "name": "Wood_Crystal_Trunk"
    },
    {
      "x": -4,
      "y": 10,
      "z": 10,
      "name": "Wood_Crystal_Trunk"
    },
    {
      "x": -4,
      "y": 11,
      "z": 10,
      "name": "Wood_Crystal_Trunk"
    },
    {
      "x": -4,
      "y": 12,
      "z": 10,
      "name": "Wood_Crystal_Trunk"
    },
    {
      "x": -4,
      "y": 13,
      "z": 10,
      "name": "Wood_Crystal_Trunk_Full"
    },
    {
      "x": -4,
      "y": 26,
      "z": 10,
      "name": "Plant_Leaves_Crystal"
    },
    {
      "x": -4,
      "y": 27,
      "z": 10,
      "name": "Plant_Leaves_Crystal"
    },
    {
      "x": -4,
      "y": 32,
      "z": 10,
      "name": "Wood_Crystal_Trunk_Full"
    },
    {
      "x": -4,
      "y": 33,
      "z": 10,
      "name": "Wood_Crystal_Trunk_Full"
    },
    {
      "x": -4,
      "y": 35,
      "z": 10,
      "name": "Plant_Leaves_Crystal"
    },
    {
      "x": -4,
      "y": 36,
      "z": 10,
      "name": "Plant_Leaves_Crystal"
    },
    {
      "x": -4,
      "y": 37,
      "z": 10,
      "name": "Plant_Leaves_Crystal"
    },
    {
      "x": -4,
      "y": 38,
      "z": 10,
      "name": "Plant_Leaves_Crystal"
    },
    {
      "x": -4,
      "y": 6,
      "z": 11,
      "name": "Wood_Crystal_Trunk"
    },
    {
      "x": -4,
      "y": 7,
      "z": 11,
      "name": "Wood_Crystal_Trunk"
    },
    {
      "x": -4,
      "y": 8,
      "z": 11,
      "name": "Wood_Crystal_Trunk"
    },
    {
      "x": -4,
      "y": 9,
      "z": 11,
      "name": "Wood_Crystal_Trunk_Full"
    },
    {
      "x": -4,
      "y": 26,
      "z": 11,
      "name": "Plant_Leaves_Crystal"
    },
    {
      "x": -4,
      "y": 35,
      "z": 11,
      "name": "Plant_Leaves_Crystal"
    },
    {
      "x": -4,
      "y": 36,
      "z": 11,
      "name": "Plant_Leaves_Crystal"
    },
    {
      "x": -4,
      "y": 37,
      "z": 11,
      "name": "Plant_Leaves_Crystal"
    },
    {
      "x": -4,
      "y": 38,
      "z": 11,
      "name": "Plant_Leaves_Crystal"
    },
    {
      "x": -4,
      "y": 25,
      "z": 12,
      "name": "Plant_Leaves_Crystal"
    },
    {
      "x": -4,
      "y": 26,
      "z": 12,
      "name": "Plant_Leaves_Crystal"
    },
    {
      "x": -4,
      "y": 34,
      "z": 12,
      "name": "Plant_Leaves_Crystal"
    },
    {
      "x": -4,
      "y": 35,
      "z": 12,
      "name": "Plant_Leaves_Crystal"
    },
    {
      "x": -4,
      "y": 36,
      "z": 12,
      "name": "Plant_Leaves_Crystal"
    },
    {
      "x": -4,
      "y": 38,
      "z": 12,
      "name": "Plant_Leaves_Crystal"
    },
    {
      "x": -4,
      "y": 34,
      "z": 13,
      "name": "Plant_Leaves_Crystal"
    },
    {
      "x": -4,
      "y": 35,
      "z": 13,
      "name": "Plant_Leaves_Crystal"
    },
    {
      "x": -4,
      "y": 34,
      "z": 14,
      "name": "Plant_Leaves_Crystal"
    },
    {
      "x": -4,
      "y": 35,
      "z": 14,
      "name": "Plant_Leaves_Crystal"
    },
    {
      "x": -4,
      "y": 34,
      "z": 15,
      "name": "Plant_Leaves_Crystal"
    },
    {
      "x": -4,
      "y": 35,
      "z": 15,
      "name": "Plant_Leaves_Crystal"
    },
    {
      "x": -4,
      "y": 36,
      "z": 15,
      "name": "Plant_Leaves_Crystal"
    },
    {
      "x": -4,
      "y": 34,
      "z": 16,
      "name": "Plant_Leaves_Crystal"
    },
    {
      "x": -4,
      "y": 34,
      "z": 17,
      "name": "Plant_Leaves_Crystal"
    },
    {
      "x": -3,
      "y": 33,
      "z": -7,
      "name": "Plant_Leaves_Crystal"
    },
    {
      "x": -3,
      "y": 34,
      "z": -7,
      "name": "Plant_Leaves_Crystal"
    },
    {
      "x": -3,
      "y": 33,
      "z": -6,
      "name": "Plant_Leaves_Crystal"
    },
    {
      "x": -3,
      "y": 34,
      "z": -6,
      "name": "Plant_Leaves_Crystal"
    },
    {
      "x": -3,
      "y": 35,
      "z": -6,
      "name": "Plant_Leaves_Crystal"
    },
    {
      "x": -3,
      "y": 38,
      "z": -6,
      "name": "Plant_Leaves_Crystal"
    },
    {
      "x": -3,
      "y": 34,
      "z": -5,
      "name": "Plant_Leaves_Crystal"
    },
    {
      "x": -3,
      "y": 35,
      "z": -5,
      "name": "Plant_Leaves_Crystal"
    },
    {
      "x": -3,
      "y": 38,
      "z": -5,
      "name": "Plant_Leaves_Crystal"
    },
    {
      "x": -3,
      "y": 27,
      "z": -4,
      "name": "Plant_Leaves_Crystal"
    },
    {
      "x": -3,
      "y": 34,
      "z": -4,
      "name": "Plant_Leaves_Crystal"
    },
    {
      "x": -3,
      "y": 35,
      "z": -4,
      "name": "Plant_Leaves_Crystal"
    },
    {
      "x": -3,
      "y": 36,
      "z": -4,
      "name": "Plant_Leaves_Crystal"
    },
    {
      "x": -3,
      "y": 38,
      "z": -4,
      "name": "Plant_Leaves_Crystal"
    },
    {
      "x": -3,
      "y": 25,
      "z": -3,
      "name": "Plant_Leaves_Crystal"
    },
    {
      "x": -3,
      "y": 26,
      "z": -3,
      "name": "Plant_Leaves_Crystal"
    },
    {
      "x": -3,
      "y": 27,
      "z": -3,
      "name": "Plant_Leaves_Crystal"
    },
    {
      "x": -3,
      "y": 28,
      "z": -3,
      "name": "Plant_Leaves_Crystal"
    },
    {
      "x": -3,
      "y": 33,
      "z": -3,
      "name": "Wood_Crystal_Branch_Long",
      "rotation": 5
    },
    {
      "x": -3,
      "y": 34,
      "z": -3,
      "name": "Plant_Leaves_Crystal"
    },
    {
      "x": -3,
      "y": 35,
      "z": -3,
      "name": "Plant_Leaves_Crystal"
    },
    {
      "x": -3,
      "y": 36,
      "z": -3,
      "name": "Plant_Leaves_Crystal"
    },
    {
      "x": -3,
      "y": 38,
      "z": -3,
      "name": "Plant_Leaves_Crystal"
    },
    {
      "x": -3,
      "y": 7,
      "z": -2,
      "name": "Wood_Crystal_Trunk"
