{
  "version": 8,
  "blockIdVersion": 8,
  "anchorX": 15,
  "anchorY": 12,
  "anchorZ": 14,
  "blocks": [
    {
      "x": 5,
      "y": 14,
      "z": 11,
      "name": "Rock_Shale"
    },
    {
      "x": 5,
      "y": 15,
      "z": 11,
      "name": "Rock_Shale"
    },
    {
      "x": 5,
      "y": 16,
      "z": 11,
      "name": "Rock_Shale"
    },
    {
      "x": 5,
      "y": 17,
      "z": 11,
      "name": "Rock_Shale"
    },
    {
      "x": 5,
      "y": 18,
      "z": 11,
      "name": "Rock_Shale"
    },
    {
      "x": 5,
      "y": 19,
      "z": 11,
      "name": "Rock_Shale"
    },
    {
      "x": 5,
      "y": 20,
      "z": 11,
      "name": "Soil_Snow"
    },
    {
      "x": 5,
      "y": 13,
      "z": 12,
      "name": "Rock_Shale"
    },
    {
      "x": 5,
      "y": 14,
      "z": 12,
      "name": "Rock_Shale"
    },
    {
      "x": 5,
      "y": 15,
      "z": 12,
      "name": "Rock_Shale"
    },
    {
      "x": 5,
      "y": 16,
      "z": 12,
      "name": "Rock_Shale"
    },
    {
      "x": 5,
      "y": 17,
      "z": 12,
      "name": "Rock_Shale"
    },
    {
      "x": 5,
      "y": 18,
      "z": 12,
      "name": "Rock_Shale"
    },
    {
      "x": 5,
      "y": 21,
      "z": 12,
      "name": "Soil_Snow"
    },
    {
      "x": 5,
      "y": 15,
      "z": 13,
      "name": "Rock_Shale"
    },
    {
      "x": 5,
      "y": 16,
      "z": 13,
      "name": "Rock_Shale"
    },
    {
      "x": 5,
      "y": 20,
      "z": 13,
      "name": "Soil_Snow"
    },
    {
      "x": 5,
      "y": 21,
      "z": 13,
      "name": "Soil_Snow"
    },
    {
      "x": 6,
      "y": 15,
      "z": 10,
      "name": "Rock_Shale"
    },
    {
      "x": 6,
      "y": 16,
      "z": 10,
      "name": "Rock_Shale"
    },
    {
      "x": 6,
      "y": 17,
      "z": 10,
      "name": "Rock_Shale"
    },
    {
      "x": 6,
      "y": 18,
      "z": 10,
      "name": "Rock_Shale"
    },
    {
      "x": 6,
      "y": 21,
      "z": 10,
      "name": "Soil_Snow"
    },
    {
      "x": 6,
      "y": 12,
      "z": 11,
      "name": "Rock_Shale"
    },
    {
      "x": 6,
      "y": 13,
      "z": 11,
      "name": "Rock_Shale"
    },
    {
      "x": 6,
      "y": 14,
      "z": 11,
      "name": "Rock_Shale"
    },
    {
      "x": 6,
      "y": 15,
      "z": 11,
      "name": "Rock_Shale"
    },
    {
      "x": 6,
      "y": 16,
      "z": 11,
      "name": "Rock_Shale"
    },
    {
      "x": 6,
      "y": 17,
      "z": 11,
      "name": "Rock_Shale"
    },
    {
      "x": 6,
      "y": 18,
      "z": 11,
      "name": "Rock_Shale"
    },
    {
      "x": 6,
      "y": 19,
      "z": 11,
      "name": "Soil_Dirt_Cold"
    },
    {
      "x": 6,
      "y": 20,
      "z": 11,
      "name": "Soil_Dirt_Cold"
    },
    {
      "x": 6,
      "y": 21,
      "z": 11,
      "name": "Soil_Snow"
    },
    {
      "x": 6,
      "y": 22,
      "z": 11,
      "name": "Plant_Bush_Winter_Snow"
    },
    {
      "x": 6,
      "y": 11,
      "z": 12,
      "name": "Rock_Shale"
    },
    {
      "x": 6,
      "y": 12,
      "z": 12,
      "name": "Rock_Shale"
    },
    {
      "x": 6,
      "y": 13,
      "z": 12,
      "name": "Rock_Shale"
    },
    {
      "x": 6,
      "y": 14,
      "z": 12,
      "name": "Rock_Shale"
    },
    {
      "x": 6,
      "y": 15,
      "z": 12,
      "name": "Rock_Shale"
    },
    {
      "x": 6,
      "y": 16,
      "z": 12,
      "name": "Rock_Shale"
    },
    {
      "x": 6,
      "y": 17,
      "z": 12,
      "name": "Rock_Shale"
    },
    {
      "x": 6,
      "y": 18,
      "z": 12,
      "name": "Rock_Shale"
    },
    {
      "x": 6,
      "y": 19,
      "z": 12,
      "name": "Soil_Dirt_Cold"
    },
    {
      "x": 6,
      "y": 20,
      "z": 12,
      "name": "Soil_Dirt_Cold"
    },
    {
      "x": 6,
      "y": 21,
      "z": 12,
      "name": "Soil_Dirt_Cold"
    },
    {
      "x": 6,
      "y": 22,
      "z": 12,
      "name": "Soil_Snow"
    },
    {
      "x": 6,
      "y": 11,
      "z": 13,
      "name": "Rock_Shale"
    },
    {
      "x": 6,
      "y": 12,
      "z": 13,
      "name": "Rock_Shale"
    },
    {
      "x": 6,
      "y": 13,
      "z": 13,
      "name": "Rock_Shale"
    },
    {
      "x": 6,
      "y": 14,
      "z": 13,
      "name": "Rock_Shale"
    },
    {
      "x": 6,
      "y": 15,
      "z": 13,
      "name": "Rock_Shale"
    },
    {
      "x": 6,
      "y": 16,
      "z": 13,
      "name": "Rock_Shale"
    },
    {
      "x": 6,
      "y": 17,
      "z": 13,
      "name": "Rock_Shale"
    },
    {
      "x": 6,
      "y": 18,
      "z": 13,
      "name": "Rock_Shale"
    },
    {
      "x": 6,
      "y": 20,
      "z": 13,
      "name": "Soil_Dirt_Cold"
    },
    {
      "x": 6,
      "y": 21,
      "z": 13,
      "name": "Soil_Dirt_Cold"
    },
    {
      "x": 6,
      "y": 22,
      "z": 13,
      "name": "Soil_Snow"
    },
    {
      "x": 6,
      "y": 11,
      "z": 14,
      "name": "Rock_Shale"
    },
    {
      "x": 6,
      "y": 21,
      "z": 14,
      "name": "Soil_Snow"
    },
    {
      "x": 7,
      "y": 16,
      "z": 10,
      "name": "Rock_Shale"
    },
    {
      "x": 7,
      "y": 17,
      "z": 10,
      "name": "Rock_Shale"
    },
    {
      "x": 7,
      "y": 18,
      "z": 10,
      "name": "Rock_Shale"
    },
    {
      "x": 7,
      "y": 19,
      "z": 10,
      "name": "Soil_Dirt_Cold"
    },
    {
      "x": 7,
      "y": 20,
      "z": 10,
      "name": "Soil_Snow"
    },
    {
      "x": 7,
      "y": 21,
      "z": 10,
      "name": "Soil_Snow"
    },
    {
      "x": 7,
      "y": 13,
      "z": 11,
      "name": "Rock_Shale"
    },
    {
      "x": 7,
      "y": 14,
      "z": 11,
      "name": "Rock_Shale"
    },
    {
      "x": 7,
      "y": 15,
      "z": 11,
      "name": "Rock_Shale"
    },
    {
      "x": 7,
      "y": 16,
      "z": 11,
      "name": "Rock_Shale"
    },
    {
      "x": 7,
      "y": 17,
      "z": 11,
      "name": "Rock_Shale"
    },
    {
      "x": 7,
      "y": 18,
      "z": 11,
      "name": "Soil_Dirt_Cold"
    },
    {
      "x": 7,
      "y": 19,
      "z": 11,
      "name": "Soil_Dirt_Cold"
    },
    {
      "x": 7,
      "y": 20,
      "z": 11,
      "name": "Soil_Dirt_Cold"
    },
    {
      "x": 7,
      "y": 21,
      "z": 11,
      "name": "Soil_Snow"
    },
    {
      "x": 7,
      "y": 22,
      "z": 11,
      "name": "Soil_Snow"
    },
    {
      "x": 7,
      "y": 10,
      "z": 12,
      "name": "Rock_Shale"
    },
    {
      "x": 7,
      "y": 11,
      "z": 12,
      "name": "Rock_Shale"
    },
    {
      "x": 7,
      "y": 12,
      "z": 12,
      "name": "Rock_Shale"
    },
    {
      "x": 7,
      "y": 13,
      "z": 12,
      "name": "Rock_Shale"
    },
    {
      "x": 7,
      "y": 14,
      "z": 12,
      "name": "Rock_Shale"
    },
    {
      "x": 7,
      "y": 15,
      "z": 12,
      "name": "Rock_Shale"
    },
    {
      "x": 7,
      "y": 16,
      "z": 12,
      "name": "Rock_Shale"
    },
    {
      "x": 7,
      "y": 17,
      "z": 12,
      "name": "Rock_Shale"
    },
    {
      "x": 7,
      "y": 18,
      "z": 12,
      "name": "Rock_Shale"
    },
    {
      "x": 7,
      "y": 19,
      "z": 12,
      "name": "Soil_Dirt_Cold"
    },
    {
      "x": 7,
      "y": 20,
      "z": 12,
      "name": "Soil_Dirt_Cold"
    },
    {
      "x": 7,
      "y": 21,
      "z": 12,
      "name": "Soil_Dirt_Cold"
    },
    {
      "x": 7,
      "y": 22,
      "z": 12,
      "name": "Soil_Snow"
    },
    {
      "x": 7,
      "y": 10,
      "z": 13,
      "name": "Rock_Shale"
    },
    {
      "x": 7,
      "y": 11,
      "z": 13,
      "name": "Rock_Shale"
    },
    {
      "x": 7,
      "y": 12,
      "z": 13,
      "name": "Rock_Shale"
    },
    {
      "x": 7,
      "y": 13,
      "z": 13,
      "name": "Rock_Shale"
    },
    {
      "x": 7,
      "y": 14,
      "z": 13,
      "name": "Rock_Shale"
    },
    {
      "x": 7,
      "y": 15,
      "z": 13,
      "name": "Rock_Shale"
    },
    {
      "x": 7,
      "y": 16,
      "z": 13,
      "name": "Rock_Shale"
    },
    {
      "x": 7,
      "y": 17,
      "z": 13,
      "name": "Rock_Shale"
    },
    {
      "x": 7,
      "y": 18,
      "z": 13,
      "name": "Rock_Shale"
    },
    {
      "x": 7,
      "y": 19,
      "z": 13,
      "name": "Soil_Dirt_Cold"
    },
    {
      "x": 7,
      "y": 20,
      "z": 13,
      "name": "Soil_Dirt_Cold"
    },
    {
      "x": 7,
      "y": 21,
      "z": 13,
      "name": "Soil_Dirt_Cold"
    },
    {
      "x": 7,
      "y": 22,
      "z": 13,
      "name": "Soil_Snow"
    },
    {
      "x": 7,
      "y": 10,
      "z": 14,
      "name": "Rock_Shale"
    },
    {
      "x": 7,
      "y": 11,
      "z": 14,
      "name": "Rock_Shale"
    },
    {
      "x": 7,
      "y": 12,
      "z": 14,
      "name": "Rock_Shale"
    },
    {
      "x": 7,
      "y": 13,
      "z": 14,
      "name": "Rock_Shale"
    },
    {
      "x": 7,
      "y": 21,
      "z": 14,
      "name": "Soil_Dirt_Cold"
    },
    {
      "x": 7,
      "y": 22,
      "z": 14,
      "name": "Soil_Dirt_Cold"
    },
    {
      "x": 7,
      "y": 23,
      "z": 14,
      "name": "Soil_Snow"
    },
    {
      "x": 7,
      "y": 20,
      "z": 15,
      "name": "Soil_Snow"
    },
    {
      "x": 7,
      "y": 21,
      "z": 15,
      "name": "Soil_Snow"
    },
    {
      "x": 7,
      "y": 22,
      "z": 15,
      "name": "Soil_Snow"
    },
    {
      "x": 8,
      "y": 21,
      "z": 10,
      "name": "Soil_Snow"
    },
    {
      "x": 8,
      "y": 18,
      "z": 11,
      "name": "Rock_Shale"
    },
    {
      "x": 8,
      "y": 19,
      "z": 11,
      "name": "Soil_Dirt_Cold"
    },
    {
      "x": 8,
      "y": 20,
      "z": 11,
      "name": "Soil_Dirt_Cold"
    },
    {
      "x": 8,
      "y": 21,
      "z": 11,
      "name": "Soil_Dirt_Cold"
    },
    {
      "x": 8,
      "y": 22,
      "z": 11,
      "name": "Soil_Snow"
    },
    {
      "x": 8,
      "y": 12,
      "z": 12,
      "name": "Rock_Shale"
    },
    {
      "x": 8,
      "y": 13,
      "z": 12,
      "name": "Rock_Shale"
    },
    {
      "x": 8,
      "y": 14,
      "z": 12,
      "name": "Rock_Shale"
    },
    {
      "x": 8,
      "y": 15,
      "z": 12,
      "name": "Rock_Shale"
    },
    {
      "x": 8,
      "y": 17,
      "z": 12,
      "name": "Rock_Shale"
    },
    {
      "x": 8,
      "y": 18,
      "z": 12,
      "name": "Rock_Shale"
    },
    {
      "x": 8,
      "y": 19,
      "z": 12,
      "name": "Soil_Dirt_Cold"
    },
    {
      "x": 8,
      "y": 20,
      "z": 12,
      "name": "Soil_Dirt_Cold"
    },
    {
      "x": 8,
      "y": 21,
      "z": 12,
      "name": "Soil_Dirt_Cold"
    },
    {
      "x": 8,
      "y": 22,
      "z": 12,
      "name": "Soil_Dirt_Cold"
    },
    {
      "x": 8,
      "y": 23,
      "z": 12,
      "name": "Soil_Snow"
    },
    {
      "x": 8,
      "y": 24,
      "z": 12,
      "name": "Plant_Bush_Winter_Snow"
    },
    {
      "x": 8,
      "y": 9,
      "z": 13,
      "name": "Rock_Shale"
    },
    {
      "x": 8,
      "y": 10,
      "z": 13,
      "name": "Rock_Shale"
    },
    {
      "x": 8,
      "y": 11,
      "z": 13,
      "name": "Rock_Shale"
    },
    {
      "x": 8,
      "y": 12,
      "z": 13,
      "name": "Rock_Shale"
    },
    {
      "x": 8,
      "y": 13,
      "z": 13,
      "name": "Rock_Shale"
    },
    {
      "x": 8,
      "y": 14,
      "z": 13,
      "name": "Rock_Shale"
    },
    {
      "x": 8,
      "y": 19,
      "z": 13,
      "name": "Rock_Shale"
    },
    {
      "x": 8,
      "y": 20,
      "z": 13,
      "name": "Soil_Dirt_Cold"
    },
    {
      "x": 8,
      "y": 21,
      "z": 13,
      "name": "Soil_Dirt_Cold"
    },
    {
      "x": 8,
      "y": 22,
      "z": 13,
      "name": "Soil_Dirt_Cold"
    },
    {
      "x": 8,
      "y": 23,
      "z": 13,
      "name": "Soil_Snow"
    },
    {
      "x": 8,
      "y": 9,
      "z": 14,
      "name": "Rock_Shale"
    },
    {
      "x": 8,
      "y": 10,
      "z": 14,
      "name": "Rock_Shale"
    },
    {
      "x": 8,
      "y": 11,
      "z": 14,
      "name": "Rock_Shale"
    },
    {
      "x": 8,
      "y": 12,
      "z": 14,
      "name": "Rock_Shale"
    },
    {
      "x": 8,
      "y": 20,
      "z": 14,
      "name": "Rock_Ice"
    },
    {
      "x": 8,
      "y": 21,
      "z": 14,
      "name": "Soil_Dirt_Cold"
    },
    {
      "x": 8,
      "y": 22,
      "z": 14,
      "name": "Soil_Dirt_Cold"
    },
    {
      "x": 8,
      "y": 23,
      "z": 14,
      "name": "Soil_Snow"
    },
    {
      "x": 8,
      "y": 10,
      "z": 15,
      "name": "Rock_Shale"
    },
    {
      "x": 8,
      "y": 11,
      "z": 15,
      "name": "Rock_Shale"
    },
    {
      "x": 8,
      "y": 22,
      "z": 15,
      "name": "Soil_Snow"
    },
    {
      "x": 8,
      "y": 23,
      "z": 15,
      "name": "Soil_Snow"
    },
    {
      "x": 9,
      "y": 21,
      "z": 11,
      "name": "Soil_Snow"
    },
    {
      "x": 9,
      "y": 22,
      "z": 11,
      "name": "Soil_Snow"
    },
    {
      "x": 9,
      "y": 23,
      "z": 11,
      "name": "Soil_Snow"
    },
    {
      "x": 9,
      "y": 20,
      "z": 12,
      "name": "Rock_Shale"
    },
    {
      "x": 9,
      "y": 21,
      "z": 12,
      "name": "Soil_Dirt_Cold"
    },
    {
      "x": 9,
      "y": 22,
      "z": 12,
      "name": "Soil_Dirt_Cold"
    },
    {
      "x": 9,
      "y": 23,
      "z": 12,
      "name": "Soil_Snow"
    },
    {
      "x": 9,
      "y": 9,
      "z": 13,
      "name": "Rock_Shale"
    },
    {
      "x": 9,
      "y": 10,
      "z": 13,
      "name": "Rock_Shale"
    },
    {
      "x": 9,
      "y": 19,
      "z": 13,
      "name": "Rock_Ice"
    },
    {
      "x": 9,
      "y": 20,
      "z": 13,
      "name": "Rock_Ice"
    },
    {
      "x": 9,
      "y": 21,
      "z": 13,
      "name": "Rock_Ice"
    },
    {
      "x": 9,
      "y": 22,
      "z": 13,
      "name": "Soil_Dirt_Cold"
    },
    {
      "x": 9,
      "y": 23,
      "z": 13,
      "name": "Soil_Snow"
    },
    {
      "x": 9,
      "y": 9,
      "z": 14,
      "name": "Rock_Shale"
    },
    {
      "x": 9,
      "y": 10,
      "z": 14,
      "name": "Rock_Shale"
    },
    {
      "x": 9,
      "y": 11,
      "z": 14,
      "name": "Rock_Shale"
    },
    {
      "x": 9,
      "y": 20,
      "z": 14,
      "name": "Rock_Ice_Icicles",
      "rotation": 8
    },
    {
      "x": 9,
      "y": 21,
      "z": 14,
      "name": "Rock_Ice"
    },
    {
      "x": 9,
      "y": 22,
      "z": 14,
      "name": "Soil_Dirt_Cold"
    },
    {
      "x": 9,
      "y": 23,
      "z": 14,
      "name": "Soil_Dirt_Cold"
    },
    {
      "x": 9,
      "y": 24,
      "z": 14,
      "name": "Soil_Snow"
    },
    {
      "x": 9,
      "y": 9,
      "z": 15,
      "name": "Rock_Shale"
    },
    {
      "x": 9,
      "y": 10,
      "z": 15,
      "name": "Rock_Shale"
    },
    {
      "x": 9,
      "y": 21,
      "z": 15,
      "name": "Soil_Snow"
    },
    {
      "x": 9,
      "y": 22,
      "z": 15,
      "name": "Soil_Snow"
    },
    {
      "x": 9,
      "y": 23,
      "z": 15,
      "name": "Soil_Snow"
    },
    {
      "x": 10,
      "y": 22,
      "z": 11,
      "name": "Soil_Snow"
    },
    {
      "x": 10,
      "y": 23,
      "z": 11,
      "name": "Soil_Snow"
    },
    {
      "x": 10,
      "y": 21,
      "z": 12,
      "name": "Soil_Dirt_Cold"
    },
    {
      "x": 10,
      "y": 22,
      "z": 12,
      "name": "Soil_Dirt_Cold"
    },
    {
      "x": 10,
      "y": 23,
      "z": 12,
      "name": "Soil_Dirt_Cold"
    },
    {
      "x": 10,
      "y": 24,
      "z": 12,
      "name": "Soil_Snow"
    },
    {
      "x": 10,
      "y": 20,
      "z": 13,
      "name": "Rock_Shale"
    },
    {
      "x": 10,
      "y": 21,
      "z": 13,
      "name": "Soil_Dirt_Cold"
    },
    {
      "x": 10,
      "y": 22,
      "z": 13,
      "name": "Soil_Dirt_Cold"
    },
    {
      "x": 10,
      "y": 23,
      "z": 13,
      "name": "Soil_Dirt_Cold"
    },
    {
      "x": 10,
      "y": 24,
      "z": 13,
      "name": "Soil_Snow"
    },
    {
      "x": 10,
      "y": 8,
      "z": 14,
      "name": "Rock_Shale"
    },
    {
      "x": 10,
      "y": 9,
      "z": 14,
      "name": "Rock_Shale"
    },
    {
      "x": 10,
      "y": 10,
      "z": 14,
      "name": "Rock_Shale"
    },
    {
      "x": 10,
      "y": 21,
      "z": 14,
      "name": "Rock_Ice"
    },
    {
      "x": 10,
      "y": 22,
      "z": 14,
      "name": "Soil_Dirt_Cold"
    },
    {
      "x": 10,
      "y": 23,
      "z": 14,
      "name": "Soil_Dirt_Cold"
    },
    {
      "x": 10,
      "y": 24,
      "z": 14,
      "name": "Soil_Snow"
    },
    {
      "x": 10,
      "y": 9,
      "z": 15,
      "name": "Rock_Shale"
    },
    {
      "x": 10,
      "y": 23,
      "z": 15,
      "name": "Soil_Snow"
    },
    {
      "x": 10,
      "y": 24,
      "z": 15,
      "name": "Soil_Snow"
    },
    {
      "x": 10,
      "y": 9,
      "z": 16,
      "name": "Rock_Shale"
    },
    {
      "x": 11,
      "y": 20,
      "z": 11,
      "name": "Soil_Snow"
    },
    {
      "x": 11,
      "y": 21,
      "z": 11,
      "name": "Soil_Snow"
    },
    {
      "x": 11,
      "y": 22,
      "z": 11,
      "name": "Soil_Snow"
    },
    {
      "x": 11,
      "y": 23,
      "z": 11,
      "name": "Soil_Snow"
    },
    {
      "x": 11,
      "y": 21,
      "z": 12,
      "name": "Rock_Shale"
    },
    {
      "x": 11,
      "y": 22,
      "z": 12,
      "name": "Soil_Dirt_Cold"
    },
    {
      "x": 11,
      "y": 23,
      "z": 12,
      "name": "Soil_Dirt_Cold"
    },
    {
      "x": 11,
      "y": 24,
      "z": 12,
      "name": "Soil_Snow"
    },
    {
      "x": 11,
      "y": 21,
      "z": 13,
      "name": "Soil_Dirt_Cold"
    },
    {
      "x": 11,
      "y": 22,
      "z": 13,
      "name": "Soil_Dirt_Cold"
    },
    {
      "x": 11,
      "y": 23,
      "z": 13,
      "name": "Soil_Dirt_Cold"
    },
    {
      "x": 11,
      "y": 24,
      "z": 13,
      "name": "Soil_Snow"
    },
    {
      "x": 11,
      "y": 25,
      "z": 13,
      "name": "Soil_Snow"
    },
    {
      "x": 11,
      "y": 9,
      "z": 14,
      "name": "Rock_Shale"
    },
    {
      "x": 11,
      "y": 19,
      "z": 14,
      "name": "Rock_Ice_Icicles",
      "rotation": 8
    },
    {
      "x": 11,
      "y": 20,
      "z": 14,
      "name": "Rock_Ice"
    },
    {
      "x": 11,
      "y": 21,
      "z": 14,
      "name": "Rock_Ice"
    },
    {
      "x": 11,
      "y": 22,
      "z": 14,
      "name": "Soil_Dirt_Cold"
    },
    {
      "x": 11,
      "y": 23,
      "z": 14,
      "name": "Soil_Dirt_Cold"
    },
    {
      "x": 11,
      "y": 24,
      "z": 14,
      "name": "Soil_Snow"
    },
    {
      "x": 11,
      "y": 25,
      "z": 14,
      "name": "Soil_Snow"
    },
    {
      "x": 11,
      "y": 8,
      "z": 15,
      "name": "Rock_Shale"
    },
    {
      "x": 11,
      "y": 9,
      "z": 15,
      "name": "Rock_Shale"
    },
    {
      "x": 11,
      "y": 22,
      "z": 15,
      "name": "Rock_Ice"
    },
    {
      "x": 11,
      "y": 23,
      "z": 15,
      "name": "Soil_Dirt_Cold"
    },
    {
      "x": 11,
      "y": 24,
      "z": 15,
      "name": "Soil_Dirt_Cold"
    },
    {
      "x": 11,
      "y": 25,
      "z": 15,
      "name": "Soil_Snow"
    },
    {
      "x": 11,
      "y": 9,
      "z": 16,
      "name": "Rock_Shale"
    },
    {
      "x": 11,
      "y": 10,
      "z": 16,
      "name": "Rock_Shale"
    },
    {
      "x": 11,
      "y": 22,
      "z": 16,
      "name": "Soil_Snow"
    },
    {
      "x": 11,
      "y": 23,
      "z": 16,
      "name": "Soil_Snow"
    },
    {
      "x": 11,
      "y": 24,
      "z": 16,
      "name": "Soil_Snow"
    },
    {
      "x": 11,
      "y": 11,
      "z": 17,
      "name": "Rock_Shale"
    },
    {
      "x": 12,
      "y": 24,
      "z": 12,
      "name": "Soil_Snow"
    },
    {
      "x": 12,
      "y": 25,
      "z": 12,
      "name": "Soil_Snow"
    },
    {
      "x": 12,
      "y": 22,
      "z": 13,
      "name": "Soil_Dirt_Cold"
    },
    {
      "x": 12,
      "y": 23,
      "z": 13,
      "name": "Soil_Dirt_Cold"
    },
    {
      "x": 12,
      "y": 24,
      "z": 13,
      "name": "Soil_Snow"
    },
    {
      "x": 12,
      "y": 25,
      "z": 13,
      "name": "Soil_Snow"
    },
    {
      "x": 12,
      "y": 22,
      "z": 14,
      "name": "Rock_Ice"
    },
    {
      "x": 12,
      "y": 23,
      "z": 14,
      "name": "Soil_Dirt_Cold"
    },
    {
      "x": 12,
      "y": 24,
      "z": 14,
      "name": "Soil_Dirt_Cold"
    },
    {
      "x": 12,
      "y": 25,
      "z": 14,
      "name": "Soil_Snow"
    },
    {
      "x": 12,
      "y": 9,
      "z": 15,
      "name": "Rock_Shale"
    },
    {
      "x": 12,
      "y": 10,
      "z": 15,
      "name": "Rock_Shale"
    },
    {
      "x": 12,
      "y": 21,
      "z": 15,
      "name": "Rock_Ice_Icicles",
      "rotation": 8
    },
    {
      "x": 12,
      "y": 22,
      "z": 15,
      "name": "Rock_Shale"
    },
    {
      "x": 12,
      "y": 23,
      "z": 15,
      "name": "Soil_Dirt_Cold"
    },
    {
      "x": 12,
      "y": 24,
      "z": 15,
      "name": "Soil_Dirt_Cold"
    },
    {
      "x": 12,
      "y": 25,
      "z": 15,
      "name": "Soil_Snow"
    },
    {
      "x": 12,
      "y": 9,
      "z": 16,
      "name": "Rock_Shale"
    },
    {
      "x": 12,
      "y": 10,
      "z": 16,
      "name": "Rock_Shale"
    },
    {
      "x": 12,
      "y": 11,
      "z": 16,
      "name": "Rock_Shale"
    },
    {
      "x": 12,
      "y": 24,
      "z": 16,
      "name": "Soil_Snow"
    },
    {
      "x": 12,
      "y": 25,
      "z": 16,
      "name": "Soil_Snow"
    },
    {
      "x": 12,
      "y": 10,
      "z": 17,
      "name": "Rock_Shale"
    },
    {
      "x": 12,
      "y": 11,
      "z": 17,
      "name": "Rock_Shale"
    },
    {
      "x": 12,
      "y": 12,
      "z": 17,
      "name": "Rock_Shale"
    },
    {
      "x": 13,
      "y": 22,
      "z": 12,
      "name": "Soil_Snow"
    },
    {
      "x": 13,
      "y": 23,
      "z": 12,
      "name": "Soil_Snow"
    },
    {
      "x": 13,
      "y": 24,
      "z": 12,
      "name": "Soil_Snow"
    },
    {
      "x": 13,
      "y": 25,
      "z": 12,
      "name": "Soil_Snow"
    },
    {
      "x": 13,
      "y": 23,
      "z": 13,
      "name": "Soil_Dirt_Cold"
    },
    {
      "x": 13,
      "y": 24,
      "z": 13,
      "name": "Soil_Snow"
    },
    {
      "x": 13,
      "y": 25,
      "z": 13,
      "name": "Soil_Snow"
    },
    {
      "x": 13,
      "y": 22,
      "z": 14,
      "name": "Rock_Shale"
    },
    {
      "x": 13,
      "y": 23,
      "z": 14,
      "name": "Soil_Dirt_Cold"
    },
    {
      "x": 13,
      "y": 24,
      "z": 14,
      "name": "Soil_Dirt_Cold"
    },
    {
      "x": 13,
      "y": 25,
      "z": 14,
      "name": "Soil_Snow"
    },
    {
      "x": 13,
      "y": 9,
      "z": 15,
      "name": "Rock_Shale"
    },
    {
      "x": 13,
      "y": 10,
      "z": 15,
      "name": "Rock_Shale"
    },
    {
      "x": 13,
      "y": 11,
      "z": 15,
      "name": "Rock_Shale"
    },
    {
      "x": 13,
      "y": 22,
      "z": 15,
      "name": "Rock_Shale"
    },
    {
      "x": 13,
      "y": 23,
      "z": 15,
      "name": "Soil_Dirt_Cold"
    },
    {
      "x": 13,
      "y": 24,
      "z": 15,
      "name": "Soil_Dirt_Cold"
    },
    {
      "x": 13,
      "y": 25,
      "z": 15,
      "name": "Soil_Snow"
    },
    {
      "x": 13,
      "y": 9,
      "z": 16,
      "name": "Rock_Shale"
    },
    {
      "x": 13,
      "y": 10,
      "z": 16,
      "name": "Rock_Shale"
    },
    {
      "x": 13,
      "y": 11,
      "z": 16,
      "name": "Rock_Shale"
    },
    {
      "x": 13,
      "y": 12,
      "z": 16,
      "name": "Rock_Shale"
    },
    {
      "x": 13,
      "y": 13,
      "z": 16,
      "name": "Rock_Shale"
    },
    {
      "x": 13,
      "y": 22,
      "z": 16,
      "name": "Rock_Shale"
    },
    {
      "x": 13,
      "y": 23,
      "z": 16,
      "name": "Soil_Dirt_Cold"
    },
    {
      "x": 13,
      "y": 24,
      "z": 16,
      "name": "Soil_Dirt_Cold"
    },
    {
      "x": 13,
      "y": 25,
      "z": 16,
      "name": "Soil_Snow"
    },
    {
      "x": 13,
      "y": 10,
      "z": 17,
      "name": "Rock_Shale"
    },
    {
      "x": 13,
      "y": 11,
      "z": 17,
      "name": "Rock_Shale"
    },
    {
      "x": 13,
      "y": 12,
      "z": 17,
      "name": "Rock_Shale"
    },
    {
      "x": 13,
      "y": 13,
      "z": 17,
      "name": "Rock_Shale"
    },
    {
      "x": 13,
      "y": 23,
      "z": 17,
      "name": "Soil_Snow"
    },
    {
      "x": 13,
      "y": 24,
      "z": 17,
      "name": "Soil_Snow"
    },
    {
      "x": 13,
      "y": 11,
      "z": 18,
      "name": "Rock_Shale"
    },
    {
      "x": 13,
      "y": 12,
      "z": 18,
      "name": "Rock_Shale"
    },
    {
      "x": 13,
      "y": 13,
      "z": 18,
      "name": "Rock_Shale"
    },
    {
      "x": 14,
      "y": 24,
      "z": 12,
      "name": "Soil_Snow"
    },
    {
      "x": 14,
      "y": 23,
      "z": 13,
      "name": "Soil_Dirt_Cold"
    },
    {
      "x": 14,
      "y": 24,
      "z": 13,
      "name": "Soil_Dirt_Cold"
    },
    {
      "x": 14,
      "y": 25,
      "z": 13,
      "name": "Soil_Snow"
    },
    {
      "x": 14,
      "y": 21,
      "z": 14,
      "name": "Rock_Shale"
    },
    {
      "x": 14,
      "y": 22,
      "z": 14,
      "name": "Soil_Dirt_Cold"
    },
    {
      "x": 14,
      "y": 23,
      "z": 14,
      "name": "Soil_Dirt_Cold"
    },
    {
      "x": 14,
      "y": 24,
      "z": 14,
      "name": "Soil_Dirt_Cold"
    },
    {
      "x": 14,
      "y": 25,
      "z": 14,
      "name": "Soil_Snow"
    },
    {
      "x": 14,
      "y": 10,
      "z": 15,
      "name": "Rock_Shale"
    },
    {
      "x": 14,
      "y": 11,
      "z": 15,
      "name": "Rock_Shale"
    },
    {
      "x": 14,
      "y": 12,
      "z": 15,
      "name": "Rock_Shale"
    },
    {
      "x": 14,
      "y": 13,
      "z": 15,
      "name": "Rock_Shale"
    },
    {
      "x": 14,
      "y": 14,
      "z": 15,
      "name": "Rock_Shale"
    },
    {
      "x": 14,
      "y": 18,
      "z": 15,
      "name": "Rock_Shale"
    },
    {
      "x": 14,
      "y": 19,
      "z": 15,
      "name": "Rock_Shale"
    },
    {
      "x": 14,
      "y": 20,
      "z": 15,
      "name": "Rock_Shale"
    },
    {
      "x": 14,
      "y": 21,
      "z": 15,
      "name": "Rock_Shale"
    },
    {
      "x": 14,
      "y": 22,
      "z": 15,
      "name": "Soil_Dirt_Cold"
    },
    {
      "x": 14,
      "y": 23,
      "z": 15,
      "name": "Soil_Dirt_Cold"
    },
    {
      "x": 14,
      "y": 24,
      "z": 15,
      "name": "Soil_Dirt_Cold"
    },
    {
      "x": 14,
      "y": 25,
      "z": 15,
      "name": "Soil_Snow"
    },
    {
      "x": 14,
      "y": 10,
      "z": 16,
      "name": "Rock_Shale"
    },
    {
      "x": 14,
      "y": 11,
      "z": 16,
      "name": "Rock_Shale"
    },
    {
      "x": 14,
      "y": 12,
      "z": 16,
      "name": "Rock_Shale"
    },
    {
      "x": 14,
      "y": 13,
      "z": 16,
      "name": "Rock_Shale"
    },
    {
      "x": 14,
      "y": 14,
      "z": 16,
      "name": "Rock_Shale"
    },
    {
      "x": 14,
      "y": 15,
      "z": 16,
      "name": "Rock_Shale"
    },
    {
      "x": 14,
      "y": 20,
      "z": 16,
      "name": "Rock_Shale"
    },
    {
      "x": 14,
      "y": 21,
      "z": 16,
      "name": "Rock_Shale"
    },
    {
      "x": 14,
      "y": 22,
      "z": 16,
      "name": "Soil_Dirt_Cold"
    },
    {
      "x": 14,
      "y": 23,
      "z": 16,
      "name": "Soil_Dirt_Cold"
    },
    {
      "x": 14,
      "y": 24,
      "z": 16,
      "name": "Soil_Dirt_Cold"
    },
    {
      "x": 14,
      "y": 25,
      "z": 16,
      "name": "Soil_Snow"
    },
    {
      "x": 14,
      "y": 9,
      "z": 17,
      "name": "Rock_Shale"
    },
    {
      "x": 14,
      "y": 10,
      "z": 17,
      "name": "Rock_Shale"
    },
    {
      "x": 14,
      "y": 11,
      "z": 17,
      "name": "Rock_Shale"
    },
    {
      "x": 14,
      "y": 12,
      "z": 17,
      "name": "Rock_Shale"
    },
    {
      "x": 14,
      "y": 13,
      "z": 17,
      "name": "Rock_Shale"
    },
    {
      "x": 14,
      "y": 14,
      "z": 17,
      "name": "Rock_Shale"
    },
    {
      "x": 14,
      "y": 23,
      "z": 17,
      "name": "Soil_Dirt_Cold"
    },
    {
      "x": 14,
      "y": 24,
      "z": 17,
      "name": "Soil_Snow"
    },
    {
      "x": 14,
      "y": 10,
      "z": 18,
      "name": "Rock_Shale"
    },
    {
      "x": 14,
      "y": 11,
      "z": 18,
      "name": "Rock_Shale"
    },
    {
      "x": 14,
      "y": 12,
      "z": 18,
      "name": "Rock_Shale"
    },
    {
      "x": 14,
      "y": 13,
      "z": 18,
      "name": "Rock_Shale"
    },
    {
      "x": 14,
      "y": 12,
      "z": 19,
      "name": "Rock_Shale"
    },
    {
      "x": 15,
      "y": 23,
      "z": 12,
      "name": "Soil_Snow"
    },
    {
      "x": 15,
      "y": 24,
      "z": 12,
      "name": "Soil_Snow"
    },
    {
      "x": 15,
      "y": 22,
      "z": 13,
      "name": "Rock_Shale"
    },
    {
      "x": 15,
      "y": 23,
      "z": 13,
      "name": "Soil_Dirt_Cold"
    },
    {
      "x": 15,
      "y": 24,
      "z": 13,
      "name": "Soil_Snow"
    },
    {
      "x": 15,
      "y": 12,
      "z": 14,
      "name": "Rock_Shale"
    },
    {
      "x": 15,
      "y": 20,
      "z": 14,
      "name": "Rock_Shale"
    },
    {
      "x": 15,
      "y": 21,
      "z": 14,
      "name": "Rock_Shale"
    },
    {
      "x": 15,
      "y": 22,
      "z": 14,
      "name": "Soil_Dirt_Cold"
    },
    {
      "x": 15,
      "y": 23,
      "z": 14,
      "name": "Soil_Dirt_Cold"
    },
    {
      "x": 15,
      "y": 24,
      "z": 14,
      "name": "Soil_Dirt_Cold"
    },
    {
      "x": 15,
      "y": 25,
      "z": 14,
      "name": "Soil_Snow"
    },
    {
      "x": 15,
      "y": 12,
      "z": 15,
      "name": "Rock_Shale"
    },
    {
      "x": 15,
      "y": 13,
      "z": 15,
      "name": "Rock_Shale"
    },
    {
      "x": 15,
      "y": 14,
      "z": 15,
      "name": "Rock_Shale"
    },
    {
      "x": 15,
      "y": 15,
      "z": 15,
      "name": "Rock_Shale"
    },
    {
      "x": 15,
      "y": 16,
      "z": 15,
      "name": "Rock_Shale"
    },
    {
      "x": 15,
      "y": 17,
      "z": 15,
      "name": "Rock_Shale"
    },
    {
      "x": 15,
      "y": 18,
      "z": 15,
      "name": "Rock_Shale"
    },
    {
      "x": 15,
      "y": 19,
      "z": 15,
      "name": "Rock_Shale"
    },
    {
      "x": 15,
      "y": 20,
      "z": 15,
      "name": "Rock_Shale"
    },
    {
      "x": 15,
      "y": 21,
      "z": 15,
      "name": "Rock_Shale"
    },
    {
      "x": 15,
      "y": 22,
      "z": 15,
      "name": "Soil_Dirt_Cold"
    },
    {
      "x": 15,
      "y": 23,
      "z": 15,
      "name": "Soil_Dirt_Cold"
    },
    {
      "x": 15,
      "y": 24,
      "z": 15,
      "name": "Soil_Snow"
    },
    {
      "x": 15,
      "y": 25,
      "z": 15,
      "name": "Soil_Snow"
    },
    {
      "x": 15,
      "y": 10,
      "z": 16,
      "name": "Rock_Shale"
    },
    {
      "x": 15,
      "y": 11,
      "z": 16,
      "name": "Rock_Shale"
    },
    {
      "x": 15,
      "y": 12,
      "z": 16,
      "name": "Rock_Shale"
    },
    {
      "x": 15,
      "y": 13,
      "z": 16,
      "name": "Rock_Shale"
    },
    {
      "x": 15,
      "y": 14,
      "z": 16,
      "name": "Rock_Shale"
    },
    {
      "x": 15,
      "y": 15,
      "z": 16,
      "name": "Rock_Shale"
    },
    {
      "x": 15,
      "y": 16,
      "z": 16,
      "name": "Rock_Shale"
    },
    {
      "x": 15,
      "y": 17,
      "z": 16,
      "name": "Rock_Shale"
    },
    {
      "x": 15,
      "y": 18,
      "z": 16,
      "name": "Rock_Shale"
    },
    {
      "x": 15,
      "y": 19,
      "z": 16,
      "name": "Rock_Shale"
    },
    {
      "x": 15,
      "y": 20,
      "z": 16,
      "name": "Rock_Shale"
    },
    {
      "x": 15,
      "y": 21,
      "z": 16,
      "name": "Soil_Dirt_Cold"
    },
    {
      "x": 15,
      "y": 22,
      "z": 16,
      "name": "Soil_Dirt_Cold"
    },
    {
      "x": 15,
      "y": 23,
      "z": 16,
      "name": "Soil_Dirt_Cold"
    },
    {
      "x": 15,
      "y": 24,
      "z": 16,
      "name": "Soil_Snow"
    },
    {
      "x": 15,
      "y": 10,
      "z": 17,
      "name": "Rock_Shale"
    },
    {
      "x": 15,
      "y": 11,
      "z": 17,
      "name": "Rock_Shale"
    },
    {
      "x": 15,
      "y": 12,
      "z": 17,
      "name": "Rock_Shale"
    },
    {
      "x": 15,
      "y": 13,
      "z": 17,
      "name": "Rock_Shale"
    },
    {
      "x": 15,
      "y": 14,
      "z": 17,
      "name": "Rock_Shale"
    },
    {
      "x": 15,
      "y": 15,
      "z": 17,
      "name": "Rock_Shale"
    },
    {
      "x": 15,
      "y": 21,
      "z": 17,
      "name": "Rock_Shale"
    },
    {
      "x": 15,
      "y": 22,
      "z": 17,
      "name": "Soil_Dirt_Cold"
    },
    {
      "x": 15,
      "y": 23,
      "z": 17,
      "name": "Soil_Dirt_Cold"
    },
    {
      "x": 15,
      "y": 24,
      "z": 17,
      "name": "Soil_Snow"
    },
    {
      "x": 15,
      "y": 10,
      "z": 18,
      "name": "Rock_Shale"
    },
    {
      "x": 15,
      "y": 11,
      "z": 18,
      "name": "Rock_Shale"
    },
    {
      "x": 15,
      "y": 12,
      "z": 18,
      "name": "Rock_Shale"
    },
    {
      "x": 15,
      "y": 13,
      "z": 18,
      "name": "Rock_Shale"
    },
    {
      "x": 15,
      "y": 14,
      "z": 18,
      "name": "Rock_Shale"
    },
    {
      "x": 15,
      "y": 15,
      "z": 18,
      "name": "Rock_Shale"
    },
    {
      "x": 15,
      "y": 22,
      "z": 18,
      "name": "Soil_Snow"
    },
    {
      "x": 15,
      "y": 23,
      "z": 18,
      "name": "Soil_Snow"
    },
    {
      "x": 15,
      "y": 11,
      "z": 19,
      "name": "Rock_Shale"
    },
    {
      "x": 15,
      "y": 12,
      "z": 19,
      "name": "Rock_Shale"
    },
    {
      "x": 15,
      "y": 13,
      "z": 19,
      "name": "Rock_Shale"
    },
    {
      "x": 16,
      "y": 21,
      "z": 12,
      "name": "Soil_Snow"
    },
    {
      "x": 16,
      "y": 22,
      "z": 12,
      "name": "Soil_Snow"
    },
    {
      "x": 16,
      "y": 23,
      "z": 12,
      "name": "Soil_Snow"
    },
    {
      "x": 16,
      "y": 21,
      "z": 13,
      "name": "Rock_Shale"
    },
    {
      "x": 16,
      "y": 22,
      "z": 13,
      "name": "Rock_Shale"
    },
    {
      "x": 16,
      "y": 23,
      "z": 13,
      "name": "Soil_Dirt_Cold"
    },
    {
      "x": 16,
      "y": 24,
      "z": 13,
      "name": "Soil_Snow"
    },
    {
      "x": 16,
      "y": 20,
      "z": 14,
      "name": "Rock_Shale"
    },
    {
      "x": 16,
      "y": 21,
      "z": 14,
      "name": "Rock_Shale"
    },
    {
      "x": 16,
      "y": 22,
      "z": 14,
      "name": "Soil_Dirt_Cold"
    },
    {
      "x": 16,
      "y": 23,
      "z": 14,
      "name": "Soil_Dirt_Cold"
    },
    {
      "x": 16,
      "y": 24,
      "z": 14,
      "name": "Soil_Snow"
    },
    {
      "x": 16,
      "y": 18,
      "z": 15,
      "name": "Rock_Shale"
    },
    {
      "x": 16,
      "y": 19,
      "z": 15,
      "name": "Rock_Shale"
    },
    {
      "x": 16,
      "y": 20,
      "z": 15,
      "name": "Rock_Shale"
    },
    {
      "x": 16,
      "y": 21,
      "z": 15,
      "name": "Soil_Dirt_Cold"
    },
    {
      "x": 16,
      "y": 22,
      "z": 15,
      "name": "Soil_Dirt_Cold"
    },
    {
      "x": 16,
      "y": 23,
      "z": 15,
      "name": "Soil_Dirt_Cold"
    },
    {
      "x": 16,
      "y": 24,
      "z": 15,
      "name": "Soil_Snow"
    },
    {
      "x": 16,
      "y": 10,
      "z": 16,
      "name": "Rock_Shale"
    },
    {
      "x": 16,
      "y": 11,
      "z": 16,
      "name": "Rock_Shale"
    },
    {
      "x": 16,
      "y": 12,
      "z": 16,
      "name": "Rock_Shale"
    },
    {
      "x": 16,
      "y": 19,
      "z": 16,
      "name": "Rock_Shale"
    },
    {
      "x": 16,
      "y": 20,
      "z": 16,
      "name": "Rock_Shale"
    },
    {
      "x": 16,
      "y": 21,
      "z": 16,
      "name": "Soil_Dirt_Cold"
    },
    {
      "x": 16,
      "y": 22,
      "z": 16,
      "name": "Soil_Dirt_Cold"
    },
    {
      "x": 16,
      "y": 23,
      "z": 16,
      "name": "Soil_Dirt_Cold"
    },
    {
      "x": 16,
      "y": 24,
      "z": 16,
      "name": "Soil_Snow"
    },
    {
      "x": 16,
      "y": 10,
      "z": 17,
      "name": "Rock_Shale"
    },
    {
      "x": 16,
      "y": 11,
      "z": 17,
      "name": "Rock_Shale"
    },
    {
      "x": 16,
      "y": 12,
      "z": 17,
      "name": "Rock_Shale"
    },
    {
      "x": 16,
      "y": 13,
      "z": 17,
      "name": "Rock_Shale"
    },
    {
      "x": 16,
      "y": 22,
      "z": 17,
      "name": "Soil_Dirt_Cold"
    },
    {
      "x": 16,
      "y": 23,
      "z": 17,
      "name": "Soil_Dirt_Cold"
    },
    {
      "x": 16,
      "y": 24,
      "z": 17,
      "name": "Soil_Snow"
    },
    {
      "x": 16,
      "y": 10,
      "z": 18,
      "name": "Rock_Shale"
    },
    {
      "x": 16,
      "y": 11,
      "z": 18,
      "name": "Rock_Shale"
    },
    {
      "x": 16,
      "y": 12,
      "z": 18,
      "name": "Rock_Shale"
    },
    {
      "x": 16,
      "y": 23,
      "z": 18,
      "name": "Soil_Snow"
    },
    {
      "x": 16,
      "y": 24,
      "z": 18,
      "name": "Soil_Snow"
    },
    {
      "x": 17,
      "y": 20,
      "z": 13,
      "name": "Rock_Shale"
    },
    {
      "x": 17,
      "y": 21,
      "z": 13,
      "name": "Rock_Shale"
    },
    {
      "x": 17,
      "y": 22,
      "z": 13,
      "name": "Rock_Shale"
    },
    {
      "x": 17,
      "y": 23,
      "z": 13,
      "name": "Soil_Snow"
    },
    {
      "x": 17,
      "y": 20,
      "z": 14,
      "name": "Rock_Shale"
    },
    {
      "x": 17,
      "y": 21,
      "z": 14,
      "name": "Rock_Shale"
    },
    {
      "x": 17,
      "y": 22,
      "z": 14,
      "name": "Soil_Dirt_Cold"
    },
    {
      "x": 17,
      "y": 23,
      "z": 14,
      "name": "Soil_Snow"
    },
    {
      "x": 17,
      "y": 24,
      "z": 14,
      "name": "Soil_Snow"
    },
    {
      "x": 17,
      "y": 25,
      "z": 14,
      "name": "Plant_Bush_Winter_Snow"
    },
    {
      "x": 17,
      "y": 19,
      "z": 15,
      "name": "Rock_Shale"
    },
    {
      "x": 17,
      "y": 20,
      "z": 15,
      "name": "Rock_Shale"
    },
    {
      "x": 17,
      "y": 21,
      "z": 15,
      "name": "Soil_Dirt_Cold"
    },
    {
      "x": 17,
      "y": 22,
      "z": 15,
      "name": "Soil_Dirt_Cold"
    },
    {
      "x": 17,
      "y": 23,
      "z": 15,
      "name": "Soil_Dirt_Cold"
    },
    {
      "x": 17,
      "y": 24,
      "z": 15,
      "name": "Soil_Snow"
    },
    {
      "x": 17,
      "y": 10,
      "z": 16,
      "name": "Rock_Shale"
    },
    {
      "x": 17,
      "y": 20,
      "z": 16,
      "name": "Rock_Ice"
    },
    {
      "x": 17,
      "y": 21,
      "z": 16,
      "name": "Rock_Shale"
    },
    {
      "x": 17,
      "y": 22,
      "z": 16,
      "name": "Soil_Dirt_Cold"
    },
    {
      "x": 17,
      "y": 23,
      "z": 16,
      "name": "Soil_Dirt_Cold"
    },
    {
      "x": 17,
      "y": 24,
      "z": 16,
      "name": "Soil_Snow"
    },
    {
      "x": 17,
      "y": 10,
      "z": 17,
      "name": "Rock_Shale"
    },
    {
      "x": 17,
      "y": 11,
      "z": 17,
      "name": "Rock_Shale"
    },
    {
      "x": 17,
      "y": 22,
      "z": 17,
      "name": "Soil_Dirt_Cold"
    },
    {
      "x": 17,
      "y": 23,
      "z": 17,
      "name": "Soil_Dirt_Cold"
    },
    {
      "x": 17,
      "y": 24,
      "z": 17,
      "name": "Soil_Snow"
    },
    {
      "x": 17,
      "y": 11,
      "z": 18,
      "name": "Rock_Shale"
    },
    {
      "x": 17,
      "y": 21,
      "z": 18,
      "name": "Soil_Snow"
    },
    {
      "x": 17,
      "y": 22,
      "z": 18,
      "name": "Soil_Snow"
    },
    {
      "x": 17,
      "y": 23,
      "z": 18,
      "name": "Soil_Snow"
    },
    {
      "x": 18,
      "y": 20,
      "z": 13,
      "name": "Rock_Shale"
    },
    {
      "x": 18,
      "y": 21,
      "z": 13,
      "name": "Rock_Shale"
    },
    {
      "x": 18,
      "y": 22,
      "z": 13,
      "name": "Soil_Snow"
    },
    {
      "x": 18,
      "y": 23,
      "z": 13,
      "name": "Soil_Snow"
    },
    {
      "x": 18,
      "y": 19,
      "z": 14,
      "name": "Rock_Shale"
    },
    {
      "x": 18,
      "y": 20,
      "z": 14,
      "name": "Rock_Shale"
    },
    {
      "x": 18,
      "y": 21,
      "z": 14,
      "name": "Rock_Shale"
    },
    {
      "x": 18,
      "y": 22,
      "z": 14,
      "name": "Soil_Dirt_Cold"
    },
    {
      "x": 18,
      "y": 23,
      "z": 14,
      "name": "Soil_Snow"
    },
    {
      "x": 18,
      "y": 19,
      "z": 15,
      "name": "Rock_Shale"
    },
    {
      "x": 18,
      "y": 20,
      "z": 15,
      "name": "Rock_Shale"
    },
    {
      "x": 18,
      "y": 21,
      "z": 15,
      "name": "Soil_Dirt_Cold"
    },
    {
      "x": 18,
      "y": 22,
      "z": 15,
      "name": "Soil_Dirt_Cold"
    },
    {
      "x": 18,
      "y": 23,
      "z": 15,
      "name": "Soil_Dirt_Cold"
    },
    {
      "x": 18,
      "y": 24,
      "z": 15,
      "name": "Soil_Snow"
    },
    {
      "x": 18,
      "y": 17,
      "z": 16,
      "name": "Rock_Ice_Icicles",
      "rotation": 8
    },
    {
      "x": 18,
      "y": 18,
      "z": 16,
      "name": "Rock_Ice"
    },
    {
      "x": 18,
      "y": 19,
      "z": 16,
      "name": "Rock_Ice"
    },
    {
      "x": 18,
      "y": 20,
      "z": 16,
      "name": "Rock_Ice"
    },
    {
      "x": 18,
      "y": 21,
      "z": 16,
      "name": "Rock_Ice"
    },
    {
      "x": 18,
      "y": 22,
      "z": 16,
      "name": "Rock_Ice"
    },
    {
      "x": 18,
      "y": 23,
      "z": 16,
      "name": "Soil_Dirt_Cold"
    },
    {
      "x": 18,
      "y": 24,
      "z": 16,
      "name": "Soil_Snow"
    },
    {
      "x": 18,
      "y": 10,
      "z": 17,
      "name": "Rock_Shale"
    },
    {
      "x": 18,
      "y": 11,
      "z": 17,
      "name": "Rock_Shale"
    },
    {
      "x": 18,
      "y": 20,
      "z": 17,
      "name": "Rock_Ice_Icicles",
      "rotation": 8
    },
    {
      "x": 18,
      "y": 21,
      "z": 17,
      "name": "Rock_Ice"
    },
    {
      "x": 18,
      "y": 22,
      "z": 17,
      "name": "Rock_Ice"
    },
    {
      "x": 18,
      "y": 23,
      "z": 17,
      "name": "Soil_Snow"
    },
    {
      "x": 18,
      "y": 24,
      "z": 17,
      "name": "Soil_Snow"
    },
    {
      "x": 18,
      "y": 11,
      "z": 18,
      "name": "Rock_Shale"
    },
    {
      "x": 18,
      "y": 11,
      "z": 19,
      "name": "Rock_Shale"
    },
    {
      "x": 19,
      "y": 21,
      "z": 13,
      "name": "Rock_Shale"
    },
    {
      "x": 19,
      "y": 22,
      "z": 13,
      "name": "Soil_Snow"
    },
    {
      "x": 19,
      "y": 19,
      "z": 14,
      "name": "Rock_Shale"
    },
    {
      "x": 19,
      "y": 20,
      "z": 14,
      "name": "Rock_Shale"
    },
    {
      "x": 19,
      "y": 21,
      "z": 14,
      "name": "Soil_Dirt_Cold"
    },
    {
      "x": 19,
      "y": 22,
      "z": 14,
      "name": "Soil_Dirt_Cold"
    },
    {
      "x": 19,
      "y": 23,
      "z": 14,
      "name": "Soil_Snow"
    },
    {
      "x": 19,
      "y": 18,
      "z": 15,
      "name": "Rock_Shale"
    },
    {
      "x": 19,
      "y": 19,
      "z": 15,
      "name": "Rock_Shale"
    },
    {
      "x": 19,
      "y": 20,
      "z": 15,
      "name": "Rock_Shale"
    },
    {
      "x": 19,
      "y": 21,
      "z": 15,
      "name": "Soil_Dirt_Cold"
    },
    {
      "x": 19,
      "y": 22,
      "z": 15,
      "name": "Soil_Dirt_Cold"
    },
    {
      "x": 19,
      "y": 23,
      "z": 15,
      "name": "Soil_Snow"
    },
    {
      "x": 19,
      "y": 18,
      "z": 16,
      "name": "Rock_Shale"
    },
    {
      "x": 19,
      "y": 19,
      "z": 16,
      "name": "Rock_Shale"
    },
    {
      "x": 19,
      "y": 20,
      "z": 16,
      "name": "Rock_Shale"
    },
    {
      "x": 19,
      "y": 21,
      "z": 16,
      "name": "Soil_Dirt_Cold"
    },
    {
      "x": 19,
      "y": 22,
      "z": 16,
      "name": "Soil_Dirt_Cold"
    },
    {
      "x": 19,
      "y": 23,
      "z": 16,
      "name": "Soil_Dirt_Cold"
    },
    {
      "x": 19,
      "y": 24,
      "z": 16,
      "name": "Soil_Snow"
    },
    {
      "x": 19,
      "y": 11,
      "z": 17,
      "name": "Rock_Shale"
    },
    {
      "x": 19,
      "y": 12,
      "z": 17,
      "name": "Rock_Shale"
    },
    {
      "x": 19,
      "y": 18,
      "z": 17,
      "name": "Rock_Shale"
    },
    {
      "x": 19,
      "y": 19,
      "z": 17,
      "name": "Rock_Shale"
    },
    {
      "x": 19,
      "y": 20,
      "z": 17,
      "name": "Rock_Shale"
    },
    {
      "x": 19,
      "y": 21,
      "z": 17,
      "name": "Rock_Shale"
    },
    {
      "x": 19,
      "y": 22,
      "z": 17,
      "name": "Soil_Snow"
    },
    {
      "x": 19,
      "y": 23,
      "z": 17,
      "name": "Soil_Snow"
    },
    {
      "x": 19,
      "y": 24,
      "z": 17,
      "name": "Soil_Snow"
    },
    {
      "x": 19,
      "y": 11,
      "z": 18,
      "name": "Rock_Shale"
    },
    {
      "x": 19,
      "y": 12,
      "z": 18,
      "name": "Rock_Shale"
    },
    {
      "x": 19,
      "y": 13,
      "z": 18,
      "name": "Rock_Shale"
    },
    {
      "x": 19,
      "y": 14,
      "z": 18,
      "name": "Rock_Shale"
    },
    {
      "x": 19,
      "y": 15,
      "z": 18,
      "name": "Rock_Shale"
    },
    {
      "x": 19,
      "y": 23,
      "z": 18,
      "name": "Soil_Snow"
    },
    {
      "x": 19,
      "y": 12,
      "z": 19,
      "name": "Rock_Shale"
    },
    {
      "x": 19,
      "y": 13,
      "z": 19,
      "name": "Rock_Shale"
    },
    {
      "x": 20,
      "y": 21,
      "z": 13,
      "name": "Soil_Snow"
    },
    {
      "x": 20,
      "y": 19,
      "z": 14,
      "name": "Rock_Shale"
    },
    {
      "x": 20,
      "y": 20,
      "z": 14,
      "name": "Rock_Shale"
    },
    {
      "x": 20,
      "y": 21,
      "z": 14,
      "name": "Soil_Dirt_Cold"
    },
    {
      "x": 20,
      "y": 22,
      "z": 14,
      "name": "Soil_Snow"
    },
    {
      "x": 20,
      "y": 18,
      "z": 15,
      "name": "Rock_Shale"
    },
    {
      "x": 20,
      "y": 19,
      "z": 15,
      "name": "Rock_Shale"
    },
    {
      "x": 20,
      "y": 20,
      "z": 15,
      "name": "Soil_Dirt_Cold"
    },
    {
      "x": 20,
      "y": 21,
      "z": 15,
      "name": "Soil_Dirt_Cold"
    },
    {
      "x": 20,
      "y": 22,
      "z": 15,
      "name": "Soil_Dirt_Cold"
    },
    {
      "x": 20,
      "y": 23,
      "z": 15,
      "name": "Soil_Snow"
    },
    {
      "x": 20,
      "y": 17,
      "z": 16,
      "name": "Rock_Shale"
    },
    {
      "x": 20,
      "y": 18,
      "z": 16,
      "name": "Rock_Shale"
    },
    {
      "x": 20,
      "y": 19,
      "z": 16,
      "name": "Rock_Shale"
    },
    {
      "x": 20,
      "y": 20,
      "z": 16,
      "name": "Rock_Shale"
    },
    {
      "x": 20,
      "y": 21,
      "z": 16,
      "name": "Soil_Dirt_Cold"
    },
    {
      "x": 20,
      "y": 22,
      "z": 16,
      "name": "Soil_Dirt_Cold"
    },
    {
      "x": 20,
      "y": 23,
      "z": 16,
      "name": "Soil_Snow"
    },
    {
      "x": 20,
      "y": 11,
      "z": 17,
      "name": "Rock_Shale"
    },
    {
      "x": 20,
      "y": 12,
      "z": 17,
      "name": "Rock_Shale"
    },
    {
      "x": 20,
      "y": 13,
      "z": 17,
      "name": "Rock_Shale"
    },
    {
      "x": 20,
      "y": 14,
      "z": 17,
      "name": "Rock_Shale"
    },
    {
      "x": 20,
      "y": 15,
      "z": 17,
      "name": "Rock_Shale"
    },
    {
      "x": 20,
      "y": 17,
      "z": 17,
      "name": "Rock_Shale"
    },
    {
      "x": 20,
      "y": 18,
      "z": 17,
      "name": "Rock_Shale"
    },
    {
      "x": 20,
      "y": 19,
      "z": 17,
      "name": "Rock_Shale"
    },
    {
      "x": 20,
      "y": 20,
      "z": 17,
      "name": "Rock_Shale"
    },
    {
      "x": 20,
      "y": 21,
      "z": 17,
      "name": "Rock_Shale"
    },
    {
      "x": 20,
      "y": 22,
      "z": 17,
      "name": "Soil_Dirt_Cold"
    },
    {
      "x": 20,
      "y": 23,
      "z": 17,
      "name": "Soil_Snow"
    },
    {
      "x": 20,
      "y": 12,
      "z": 18,
      "name": "Rock_Shale"
    },
    {
      "x": 20,
      "y": 13,
      "z": 18,
      "name": "Rock_Shale"
    },
    {
      "x": 20,
      "y": 14,
      "z": 18,
      "name": "Rock_Shale"
    },
    {
      "x": 20,
      "y": 15,
      "z": 18,
      "name": "Rock_Shale"
    },
    {
      "x": 20,
      "y": 16,
      "z": 18,
      "name": "Rock_Shale"
    },
    {
      "x": 20,
      "y": 17,
      "z": 18,
      "name": "Rock_Shale"
    },
    {
      "x": 20,
      "y": 18,
      "z": 18,
      "name": "Rock_Shale"
    },
    {
      "x": 20,
      "y": 19,
      "z": 18,
      "name": "Rock_Shale"
    },
    {
      "x": 20,
      "y": 20,
      "z": 18,
      "name": "Rock_Shale"
    },
    {
      "x": 20,
      "y": 21,
      "z": 18,
      "name": "Soil_Snow"
    },
    {
      "x": 20,
      "y": 22,
      "z": 18,
      "name": "Soil_Snow"
    },
    {
      "x": 20,
      "y": 23,
      "z": 18,
      "name": "Soil_Snow"
    },
    {
      "x": 20,
      "y": 12,
      "z": 19,
      "name": "Rock_Shale"
    },
    {
      "x": 20,
      "y": 13,
      "z": 19,
      "name": "Rock_Shale"
    },
    {
      "x": 20,
      "y": 14,
      "z": 19,
      "name": "Rock_Shale"
    },
    {
      "x": 20,
      "y": 15,
      "z": 19,
      "name": "Rock_Shale"
    },
    {
      "x": 20,
      "y": 16,
      "z": 19,
      "name": "Rock_Shale"
    },
    {
      "x": 20,
      "y": 17,
      "z": 19,
      "name": "Rock_Shale"
    },
    {
      "x": 21,
      "y": 20,
      "z": 14,
      "name": "Soil_Snow"
    },
    {
      "x": 21,
      "y": 21,
      "z": 14,
      "name": "Soil_Snow"
    },
    {
      "x": 21,
      "y": 22,
      "z": 14,
      "name": "Soil_Snow"
    },
    {
      "x": 21,
      "y": 18,
      "z": 15,
      "name": "Rock_Shale"
    },
    {
      "x": 21,
      "y": 19,
      "z": 15,
      "name": "Rock_Shale"
    },
    {
      "x": 21,
      "y": 20,
      "z": 15,
      "name": "Rock_Shale"
    },
    {
      "x": 21,
      "y": 21,
      "z": 15,
      "name": "Soil_Dirt_Cold"
    },
    {
      "x": 21,
      "y": 22,
      "z": 15,
      "name": "Soil_Dirt_Cold"
    },
    {
      "x": 21,
      "y": 23,
      "z": 15,
      "name": "Soil_Snow"
    },
    {
      "x": 21,
      "y": 14,
      "z": 16,
      "name": "Rock_Shale"
    },
    {
      "x": 21,
      "y": 15,
      "z": 16,
      "name": "Rock_Shale"
    },
    {
      "x": 21,
      "y": 16,
      "z": 16,
      "name": "Rock_Shale"
    },
    {
      "x": 21,
      "y": 17,
      "z": 16,
      "name": "Rock_Shale"
    },
    {
      "x": 21,
      "y": 18,
      "z": 16,
      "name": "Rock_Shale"
    },
    {
      "x": 21,
      "y": 19,
      "z": 16,
      "name": "Rock_Shale"
    },
    {
      "x": 21,
      "y": 20,
      "z": 16,
      "name": "Rock_Shale"
    },
    {
      "x": 21,
      "y": 21,
      "z": 16,
      "name": "Soil_Dirt_Cold"
    },
    {
      "x": 21,
      "y": 22,
      "z": 16,
      "name": "Soil_Dirt_Cold"
    },
    {
      "x": 21,
      "y": 23,
      "z": 16,
      "name": "Soil_Snow"
    },
    {
      "x": 21,
      "y": 13,
      "z": 17,
      "name": "Rock_Shale"
    },
    {
      "x": 21,
      "y": 14,
      "z": 17,
      "name": "Rock_Shale"
    },
    {
      "x": 21,
      "y": 15,
      "z": 17,
      "name": "Rock_Shale"
    },
    {
      "x": 21,
      "y": 16,
      "z": 17,
      "name": "Rock_Shale"
    },
    {
      "x": 21,
      "y": 17,
      "z": 17,
      "name": "Rock_Shale"
    },
    {
      "x": 21,
      "y": 18,
      "z": 17,
      "name": "Rock_Shale"
    },
    {
      "x": 21,
      "y": 19,
      "z": 17,
      "name": "Rock_Shale"
    },
    {
      "x": 21,
      "y": 20,
      "z": 17,
      "name": "Rock_Shale"
    },
    {
      "x": 21,
      "y": 21,
      "z": 17,
      "name": "Soil_Dirt_Cold"
    },
    {
      "x": 21,
      "y": 22,
      "z": 17,
      "name": "Soil_Dirt_Cold"
    },
    {
      "x": 21,
      "y": 23,
      "z": 17,
      "name": "Soil_Snow"
    },
    {
      "x": 21,
      "y": 12,
      "z": 18,
      "name": "Rock_Shale"
    },
    {
      "x": 21,
      "y": 13,
      "z": 18,
      "name": "Rock_Shale"
    },
    {
      "x": 21,
      "y": 14,
      "z": 18,
      "name": "Rock_Shale"
    },
    {
      "x": 21,
      "y": 15,
      "z": 18,
      "name": "Rock_Shale"
    },
    {
      "x": 21,
      "y": 16,
      "z": 18,
      "name": "Rock_Shale"
    },
    {
      "x": 21,
      "y": 17,
      "z": 18,
      "name": "Rock_Shale"
    },
    {
      "x": 21,
      "y": 18,
      "z": 18,
      "name": "Rock_Shale"
    },
    {
      "x": 21,
      "y": 19,
      "z": 18,
      "name": "Rock_Shale"
    },
    {
      "x": 21,
      "y": 20,
      "z": 18,
      "name": "Rock_Shale"
    },
    {
      "x": 21,
      "y": 21,
      "z": 18,
      "name": "Soil_Dirt_Cold"
    },
    {
      "x": 21,
      "y": 22,
      "z": 18,
      "name": "Soil_Snow"
    },
    {
      "x": 21,
      "y": 13,
      "z": 19,
      "name": "Rock_Shale"
    },
    {
      "x": 21,
      "y": 14,
      "z": 19,
      "name": "Rock_Shale"
    },
    {
      "x": 21,
      "y": 15,
      "z": 19,
      "name": "Rock_Shale"
    },
    {
      "x": 21,
      "y": 16,
      "z": 19,
      "name": "Rock_Shale"
    },
    {
      "x": 21,
      "y": 17,
      "z": 19,
      "name": "Rock_Shale"
    },
    {
      "x": 21,
      "y": 18,
      "z": 19,
      "name": "Rock_Shale"
    },
    {
      "x": 21,
      "y": 20,
      "z": 19,
      "name": "Soil_Snow"
    },
    {
      "x": 21,
      "y": 21,
      "z": 19,
      "name": "Soil_Snow"
    },
    {
      "x": 22,
      "y": 19,
      "z": 15,
      "name": "Rock_Shale"
    },
    {
      "x": 22,
      "y": 20,
      "z": 15,
      "name": "Rock_Shale"
    },
    {
      "x": 22,
      "y": 21,
      "z": 15,
      "name": "Soil_Snow"
    },
    {
      "x": 22,
      "y": 22,
      "z": 15,
      "name": "Soil_Snow"
    },
    {
      "x": 22,
      "y": 16,
      "z": 16,
      "name": "Rock_Shale"
    },
    {
      "x": 22,
      "y": 17,
      "z": 16,
      "name": "Rock_Shale"
    },
    {
      "x": 22,
      "y": 18,
      "z": 16,
      "name": "Rock_Shale"
    },
    {
      "x": 22,
      "y": 19,
      "z": 16,
      "name": "Rock_Shale"
    },
    {
      "x": 22,
      "y": 20,
      "z": 16,
      "name": "Rock_Shale"
    },
    {
      "x": 22,
      "y": 21,
      "z": 16,
      "name": "Soil_Dirt_Cold"
    },
    {
      "x": 22,
      "y": 22,
      "z": 16,
      "name": "Soil_Snow"
    },
    {
      "x": 22,
      "y": 23,
      "z": 16,
      "name": "Soil_Snow"
    },
    {
      "x": 22,
      "y": 14,
      "z": 17,
      "name": "Rock_Shale"
    },
    {
      "x": 22,
      "y": 15,
      "z": 17,
      "name": "Rock_Shale"
    },
    {
      "x": 22,
      "y": 16,
      "z": 17,
      "name": "Rock_Shale"
    },
    {
      "x": 22,
      "y": 17,
      "z": 17,
      "name": "Rock_Shale"
    },
    {
      "x": 22,
      "y": 18,
      "z": 17,
      "name": "Rock_Shale"
    },
    {
      "x": 22,
      "y": 19,
      "z": 17,
      "name": "Rock_Shale"
    },
    {
      "x": 22,
      "y": 20,
      "z": 17,
      "name": "Soil_Dirt_Cold"
    },
    {
      "x": 22,
      "y": 21,
      "z": 17,
      "name": "Soil_Dirt_Cold"
    },
    {
      "x": 22,
      "y": 22,
      "z": 17,
      "name": "Soil_Dirt_Cold"
    },
    {
      "x": 22,
      "y": 23,
      "z": 17,
      "name": "Soil_Snow"
    },
    {
      "x": 22,
      "y": 14,
      "z": 18,
      "name": "Rock_Shale"
    },
    {
      "x": 22,
      "y": 15,
      "z": 18,
      "name": "Rock_Shale"
    },
    {
      "x": 22,
      "y": 16,
      "z": 18,
      "name": "Rock_Shale"
    },
    {
      "x": 22,
      "y": 17,
      "z": 18,
      "name": "Rock_Shale"
    },
    {
      "x": 22,
      "y": 18,
      "z": 18,
      "name": "Rock_Shale"
    },
    {
      "x": 22,
      "y": 19,
      "z": 18,
      "name": "Rock_Shale"
    },
    {
      "x": 22,
      "y": 20,
      "z": 18,
      "name": "Soil_Snow"
    },
    {
      "x": 22,
      "y": 21,
      "z": 18,
      "name": "Soil_Snow"
    },
    {
      "x": 22,
      "y": 22,
      "z": 18,
      "name": "Soil_Snow"
    },
    {
      "x": 22,
      "y": 14,
      "z": 19,
      "name": "Rock_Shale"
    },
    {
      "x": 22,
      "y": 15,
      "z": 19,
      "name": "Rock_Shale"
    },
    {
      "x": 23,
      "y": 22,
      "z": 16,
      "name": "Soil_Snow"
    },
    {
      "x": 23,
      "y": 16,
      "z": 17,
      "name": "Rock_Shale"
    },
    {
      "x": 23,
      "y": 17,
      "z": 17,
      "name": "Rock_Shale"
    },
    {
      "x": 23,
      "y": 18,
      "z": 17,
      "name": "Rock_Shale"
    },
    {
      "x": 23,
      "y": 21,
      "z": 17,
      "name": "Soil_Snow"
    },
    {
      "x": 23,
      "y": 22,
      "z": 17,
      "name": "Soil_Snow"
    },
    {
      "x": 23,
      "y": 17,
      "z": 18,
      "name": "Rock_Shale"
    },
    {
      "x": 23,
      "y": 18,
      "z": 18,
      "name": "Rock_Shale"
    }
  ]
}