{
  "version": 8,
  "blockIdVersion": 8,
  "anchorX": 0,
  "anchorY": 8,
  "anchorZ": 0,
  "blocks": [
    {
      "x": -14,
      "y": 8,
      "z": 1,
      "name": "Rock_Basalt"
    },
    {
      "x": -14,
      "y": 9,
      "z": 1,
      "name": "Rock_Basalt"
    },
    {
      "x": -14,
      "y": 10,
      "z": 1,
      "name": "Rock_Basalt"
    },
    {
      "x": -14,
      "y": 6,
      "z": 2,
      "name": "Rock_Basalt"
    },
    {
      "x": -14,
      "y": 7,
      "z": 2,
      "name": "Rock_Basalt"
    },
    {
      "x": -14,
      "y": 8,
      "z": 2,
      "name": "Rock_Basalt"
    },
    {
      "x": -14,
      "y": 9,
      "z": 2,
      "name": "Rock_Basalt"
    },
    {
      "x": -14,
      "y": 10,
      "z": 2,
      "name": "Rock_Basalt"
    },
    {
      "x": -14,
      "y": 6,
      "z": 3,
      "name": "Rock_Basalt"
    },
    {
      "x": -14,
      "y": 7,
      "z": 3,
      "name": "Rock_Basalt"
    },
    {
      "x": -14,
      "y": 8,
      "z": 3,
      "name": "Rock_Basalt"
    },
    {
      "x": -14,
      "y": 9,
      "z": 3,
      "name": "Rock_Basalt"
    },
    {
      "x": -14,
      "y": 10,
      "z": 3,
      "name": "Rock_Basalt"
    },
    {
      "x": -14,
      "y": 7,
      "z": 4,
      "name": "Rock_Basalt"
    },
    {
      "x": -14,
      "y": 8,
      "z": 4,
      "name": "Rock_Basalt"
    },
    {
      "x": -14,
      "y": 9,
      "z": 4,
      "name": "Rock_Basalt"
    },
    {
      "x": -14,
      "y": 10,
      "z": 4,
      "name": "Rock_Basalt"
    },
    {
      "x": -13,
      "y": 8,
      "z": -1,
      "name": "Rock_Basalt"
    },
    {
      "x": -13,
      "y": 9,
      "z": -1,
      "name": "Rock_Basalt"
    },
    {
      "x": -13,
      "y": 10,
      "z": -1,
      "name": "Rock_Basalt"
    },
    {
      "x": -13,
      "y": 7,
      "z": 0,
      "name": "Rock_Basalt"
    },
    {
      "x": -13,
      "y": 8,
      "z": 0,
      "name": "Rock_Basalt"
    },
    {
      "x": -13,
      "y": 9,
      "z": 0,
      "name": "Rock_Basalt"
    },
    {
      "x": -13,
      "y": 10,
      "z": 0,
      "name": "Rock_Basalt"
    },
    {
      "x": -13,
      "y": 11,
      "z": 0,
      "name": "Plant_Moss_Block_Green_Dark"
    },
    {
      "x": -13,
      "y": 12,
      "z": 0,
      "name": "Plant_Moss_Block_Green_Dark"
    },
    {
      "x": -13,
      "y": 4,
      "z": 1,
      "name": "Rock_Basalt"
    },
    {
      "x": -13,
      "y": 5,
      "z": 1,
      "name": "Rock_Basalt"
    },
    {
      "x": -13,
      "y": 6,
      "z": 1,
      "name": "Rock_Basalt"
    },
    {
      "x": -13,
      "y": 7,
      "z": 1,
      "name": "Rock_Basalt"
    },
    {
      "x": -13,
      "y": 8,
      "z": 1,
      "name": "Rock_Basalt"
    },
    {
      "x": -13,
      "y": 9,
      "z": 1,
      "name": "Rock_Basalt"
    },
    {
      "x": -13,
      "y": 10,
      "z": 1,
      "name": "Rock_Basalt"
    },
    {
      "x": -13,
      "y": 11,
      "z": 1,
      "name": "Rock_Basalt"
    },
    {
      "x": -13,
      "y": 12,
      "z": 1,
      "name": "Plant_Moss_Block_Green_Dark"
    },
    {
      "x": -13,
      "y": 13,
      "z": 1,
      "name": "Plant_Moss_Block_Green_Dark"
    },
    {
      "x": -13,
      "y": 3,
      "z": 2,
      "name": "Rock_Basalt"
    },
    {
      "x": -13,
      "y": 4,
      "z": 2,
      "name": "Rock_Basalt"
    },
    {
      "x": -13,
      "y": 5,
      "z": 2,
      "name": "Rock_Basalt"
    },
    {
      "x": -13,
      "y": 6,
      "z": 2,
      "name": "Rock_Basalt"
    },
    {
      "x": -13,
      "y": 7,
      "z": 2,
      "name": "Rock_Basalt"
    },
    {
      "x": -13,
      "y": 8,
      "z": 2,
      "name": "Rock_Basalt"
    },
    {
      "x": -13,
      "y": 9,
      "z": 2,
      "name": "Rock_Basalt"
    },
    {
      "x": -13,
      "y": 10,
      "z": 2,
      "name": "Rock_Basalt"
    },
    {
      "x": -13,
      "y": 11,
      "z": 2,
      "name": "Rock_Basalt"
    },
    {
      "x": -13,
      "y": 12,
      "z": 2,
      "name": "Plant_Moss_Block_Green_Dark"
    },
    {
      "x": -13,
      "y": 13,
      "z": 2,
      "name": "Plant_Moss_Block_Green_Dark"
    },
    {
      "x": -13,
      "y": 3,
      "z": 3,
      "name": "Rock_Basalt"
    },
    {
      "x": -13,
      "y": 4,
      "z": 3,
      "name": "Rock_Basalt"
    },
    {
      "x": -13,
      "y": 5,
      "z": 3,
      "name": "Rock_Basalt"
    },
    {
      "x": -13,
      "y": 6,
      "z": 3,
      "name": "Rock_Basalt"
    },
    {
      "x": -13,
      "y": 7,
      "z": 3,
      "name": "Rock_Basalt"
    },
    {
      "x": -13,
      "y": 8,
      "z": 3,
      "name": "Rock_Basalt"
    },
    {
      "x": -13,
      "y": 9,
      "z": 3,
      "name": "Rock_Basalt"
    },
    {
      "x": -13,
      "y": 10,
      "z": 3,
      "name": "Rock_Basalt"
    },
    {
      "x": -13,
      "y": 11,
      "z": 3,
      "name": "Rock_Basalt"
    },
    {
      "x": -13,
      "y": 12,
      "z": 3,
      "name": "Plant_Moss_Block_Green_Dark"
    },
    {
      "x": -13,
      "y": 13,
      "z": 3,
      "name": "Plant_Moss_Block_Green_Dark"
    },
    {
      "x": -13,
      "y": 4,
      "z": 4,
      "name": "Rock_Basalt"
    },
    {
      "x": -13,
      "y": 5,
      "z": 4,
      "name": "Rock_Basalt"
    },
    {
      "x": -13,
      "y": 6,
      "z": 4,
      "name": "Rock_Basalt"
    },
    {
      "x": -13,
      "y": 7,
      "z": 4,
      "name": "Rock_Basalt"
    },
    {
      "x": -13,
      "y": 8,
      "z": 4,
      "name": "Rock_Basalt"
    },
    {
      "x": -13,
      "y": 9,
      "z": 4,
      "name": "Rock_Basalt"
    },
    {
      "x": -13,
      "y": 10,
      "z": 4,
      "name": "Rock_Basalt"
    },
    {
      "x": -13,
      "y": 11,
      "z": 4,
      "name": "Rock_Basalt"
    },
    {
      "x": -13,
      "y": 12,
      "z": 4,
      "name": "Plant_Moss_Block_Green_Dark"
    },
    {
      "x": -13,
      "y": 13,
      "z": 4,
      "name": "Plant_Moss_Block_Green_Dark"
    },
    {
      "x": -13,
      "y": 6,
      "z": 5,
      "name": "Rock_Basalt"
    },
    {
      "x": -13,
      "y": 7,
      "z": 5,
      "name": "Rock_Basalt"
    },
    {
      "x": -13,
      "y": 8,
      "z": 5,
      "name": "Rock_Basalt"
    },
    {
      "x": -13,
      "y": 9,
      "z": 5,
      "name": "Rock_Basalt"
    },
    {
      "x": -13,
      "y": 10,
      "z": 5,
      "name": "Rock_Basalt"
    },
    {
      "x": -13,
      "y": 11,
      "z": 5,
      "name": "Plant_Moss_Block_Green_Dark"
    },
    {
      "x": -13,
      "y": 12,
      "z": 5,
      "name": "Plant_Moss_Block_Green_Dark"
    },
    {
      "x": -13,
      "y": 7,
      "z": 6,
      "name": "Rock_Basalt"
    },
    {
      "x": -13,
      "y": 8,
      "z": 6,
      "name": "Rock_Basalt"
    },
    {
      "x": -13,
      "y": 9,
      "z": 6,
      "name": "Rock_Basalt"
    },
    {
      "x": -13,
      "y": 10,
      "z": 6,
      "name": "Rock_Basalt"
    },
    {
      "x": -12,
      "y": 8,
      "z": -1,
      "name": "Rock_Basalt"
    },
    {
      "x": -12,
      "y": 9,
      "z": -1,
      "name": "Rock_Basalt"
    },
    {
      "x": -12,
      "y": 10,
      "z": -1,
      "name": "Rock_Basalt"
    },
    {
      "x": -12,
      "y": 11,
      "z": -1,
      "name": "Plant_Moss_Block_Green_Dark"
    },
    {
      "x": -12,
      "y": 12,
      "z": -1,
      "name": "Plant_Moss_Block_Green_Dark"
    },
    {
      "x": -12,
      "y": 4,
      "z": 0,
      "name": "Rock_Basalt"
    },
    {
      "x": -12,
      "y": 5,
      "z": 0,
      "name": "Rock_Basalt"
    },
    {
      "x": -12,
      "y": 6,
      "z": 0,
      "name": "Rock_Basalt"
    },
    {
      "x": -12,
      "y": 7,
      "z": 0,
      "name": "Rock_Basalt"
    },
    {
      "x": -12,
      "y": 8,
      "z": 0,
      "name": "Rock_Basalt"
    },
    {
      "x": -12,
      "y": 9,
      "z": 0,
      "name": "Rock_Basalt"
    },
    {
      "x": -12,
      "y": 10,
      "z": 0,
      "name": "Rock_Basalt"
    },
    {
      "x": -12,
      "y": 11,
      "z": 0,
      "name": "Rock_Basalt"
    },
    {
      "x": -12,
      "y": 12,
      "z": 0,
      "name": "Plant_Moss_Block_Green_Dark"
    },
    {
      "x": -12,
      "y": 13,
      "z": 0,
      "name": "Plant_Moss_Block_Green_Dark"
    },
    {
      "x": -12,
      "y": 3,
      "z": 1,
      "name": "Rock_Basalt"
    },
    {
      "x": -12,
      "y": 4,
      "z": 1,
      "name": "Rock_Basalt"
    },
    {
      "x": -12,
      "y": 5,
      "z": 1,
      "name": "Rock_Basalt"
    },
    {
      "x": -12,
      "y": 6,
      "z": 1,
      "name": "Rock_Basalt"
    },
    {
      "x": -12,
      "y": 7,
      "z": 1,
      "name": "Rock_Basalt"
    },
    {
      "x": -12,
      "y": 8,
      "z": 1,
      "name": "Rock_Basalt"
    },
    {
      "x": -12,
      "y": 9,
      "z": 1,
      "name": "Rock_Basalt"
    },
    {
      "x": -12,
      "y": 10,
      "z": 1,
      "name": "Rock_Basalt"
    },
    {
      "x": -12,
      "y": 11,
      "z": 1,
      "name": "Rock_Basalt"
    },
    {
      "x": -12,
      "y": 12,
      "z": 1,
      "name": "Plant_Moss_Block_Green_Dark"
    },
    {
      "x": -12,
      "y": 13,
      "z": 1,
      "name": "Plant_Moss_Block_Green_Dark"
    },
    {
      "x": -12,
      "y": 2,
      "z": 2,
      "name": "Rock_Basalt"
    },
    {
      "x": -12,
      "y": 3,
      "z": 2,
      "name": "Rock_Basalt"
    },
    {
      "x": -12,
      "y": 4,
      "z": 2,
      "name": "Rock_Basalt"
    },
    {
      "x": -12,
      "y": 5,
      "z": 2,
      "name": "Rock_Basalt"
    },
    {
      "x": -12,
      "y": 6,
      "z": 2,
      "name": "Rock_Basalt"
    },
    {
      "x": -12,
      "y": 7,
      "z": 2,
      "name": "Rock_Basalt"
    },
    {
      "x": -12,
      "y": 8,
      "z": 2,
      "name": "Rock_Basalt"
    },
    {
      "x": -12,
      "y": 9,
      "z": 2,
      "name": "Rock_Basalt"
    },
    {
      "x": -12,
      "y": 10,
      "z": 2,
      "name": "Rock_Basalt"
    },
    {
      "x": -12,
      "y": 11,
      "z": 2,
      "name": "Rock_Basalt"
    },
    {
      "x": -12,
      "y": 12,
      "z": 2,
      "name": "Plant_Moss_Block_Green_Dark"
    },
    {
      "x": -12,
      "y": 13,
      "z": 2,
      "name": "Plant_Moss_Block_Green_Dark"
    },
    {
      "x": -12,
      "y": 2,
      "z": 3,
      "name": "Rock_Basalt"
    },
    {
      "x": -12,
      "y": 3,
      "z": 3,
      "name": "Rock_Basalt"
    },
    {
      "x": -12,
      "y": 4,
      "z": 3,
      "name": "Rock_Basalt"
    },
    {
      "x": -12,
      "y": 5,
      "z": 3,
      "name": "Rock_Basalt"
    },
    {
      "x": -12,
      "y": 6,
      "z": 3,
      "name": "Rock_Basalt"
    },
    {
      "x": -12,
      "y": 7,
      "z": 3,
      "name": "Rock_Basalt"
    },
    {
      "x": -12,
      "y": 8,
      "z": 3,
      "name": "Rock_Basalt"
    },
    {
      "x": -12,
      "y": 9,
      "z": 3,
      "name": "Rock_Basalt"
    },
    {
      "x": -12,
      "y": 10,
      "z": 3,
      "name": "Rock_Basalt"
    },
    {
      "x": -12,
      "y": 11,
      "z": 3,
      "name": "Rock_Basalt"
    },
    {
      "x": -12,
      "y": 12,
      "z": 3,
      "name": "Plant_Moss_Block_Green_Dark"
    },
    {
      "x": -12,
      "y": 13,
      "z": 3,
      "name": "Plant_Moss_Block_Green_Dark"
    },
    {
      "x": -12,
      "y": 2,
      "z": 4,
      "name": "Rock_Basalt"
    },
    {
      "x": -12,
      "y": 3,
      "z": 4,
      "name": "Rock_Basalt"
    },
    {
      "x": -12,
      "y": 4,
      "z": 4,
      "name": "Rock_Basalt"
    },
    {
      "x": -12,
      "y": 5,
      "z": 4,
      "name": "Rock_Basalt"
    },
    {
      "x": -12,
      "y": 6,
      "z": 4,
      "name": "Rock_Basalt"
    },
    {
      "x": -12,
      "y": 7,
      "z": 4,
      "name": "Rock_Basalt"
    },
    {
      "x": -12,
      "y": 8,
      "z": 4,
      "name": "Rock_Basalt"
    },
    {
      "x": -12,
      "y": 9,
      "z": 4,
      "name": "Rock_Basalt"
    },
    {
      "x": -12,
      "y": 10,
      "z": 4,
      "name": "Rock_Basalt"
    },
    {
      "x": -12,
      "y": 11,
      "z": 4,
      "name": "Rock_Basalt"
    },
    {
      "x": -12,
      "y": 12,
      "z": 4,
      "name": "Plant_Moss_Block_Green_Dark"
    },
    {
      "x": -12,
      "y": 13,
      "z": 4,
      "name": "Plant_Moss_Block_Green_Dark"
    },
    {
      "x": -12,
      "y": 3,
      "z": 5,
      "name": "Rock_Basalt"
    },
    {
      "x": -12,
      "y": 4,
      "z": 5,
      "name": "Rock_Basalt"
    },
    {
      "x": -12,
      "y": 5,
      "z": 5,
      "name": "Rock_Basalt"
    },
    {
      "x": -12,
      "y": 6,
      "z": 5,
      "name": "Rock_Basalt"
    },
    {
      "x": -12,
      "y": 7,
      "z": 5,
      "name": "Rock_Basalt"
    },
    {
      "x": -12,
      "y": 8,
      "z": 5,
      "name": "Rock_Basalt"
    },
    {
      "x": -12,
      "y": 9,
      "z": 5,
      "name": "Rock_Basalt"
    },
    {
      "x": -12,
      "y": 10,
      "z": 5,
      "name": "Rock_Basalt"
    },
    {
      "x": -12,
      "y": 11,
      "z": 5,
      "name": "Rock_Basalt"
    },
    {
      "x": -12,
      "y": 12,
      "z": 5,
      "name": "Plant_Moss_Block_Green_Dark"
    },
    {
      "x": -12,
      "y": 13,
      "z": 5,
      "name": "Plant_Moss_Block_Green_Dark"
    },
    {
      "x": -12,
      "y": 5,
      "z": 6,
      "name": "Rock_Basalt"
    },
    {
      "x": -12,
      "y": 6,
      "z": 6,
      "name": "Rock_Basalt"
    },
    {
      "x": -12,
      "y": 7,
      "z": 6,
      "name": "Rock_Basalt"
    },
    {
      "x": -12,
      "y": 8,
      "z": 6,
      "name": "Rock_Basalt"
    },
    {
      "x": -12,
      "y": 9,
      "z": 6,
      "name": "Rock_Basalt"
    },
    {
      "x": -12,
      "y": 10,
      "z": 6,
      "name": "Rock_Basalt"
    },
    {
      "x": -12,
      "y": 11,
      "z": 6,
      "name": "Plant_Moss_Block_Green_Dark"
    },
    {
      "x": -12,
      "y": 12,
      "z": 6,
      "name": "Plant_Moss_Block_Green_Dark"
    },
    {
      "x": -12,
      "y": 8,
      "z": 7,
      "name": "Rock_Basalt"
    },
    {
      "x": -12,
      "y": 9,
      "z": 7,
      "name": "Rock_Basalt"
    },
    {
      "x": -12,
      "y": 10,
      "z": 7,
      "name": "Rock_Basalt"
    },
    {
      "x": -12,
      "y": 11,
      "z": 7,
      "name": "Rock_Basalt"
    },
    {
      "x": -11,
      "y": 4,
      "z": -1,
      "name": "Rock_Basalt"
    },
    {
      "x": -11,
      "y": 5,
      "z": -1,
      "name": "Rock_Basalt"
    },
    {
      "x": -11,
      "y": 6,
      "z": -1,
      "name": "Rock_Basalt"
    },
    {
      "x": -11,
      "y": 7,
      "z": -1,
      "name": "Rock_Basalt"
    },
    {
      "x": -11,
      "y": 8,
      "z": -1,
      "name": "Rock_Basalt"
    },
    {
      "x": -11,
      "y": 9,
      "z": -1,
      "name": "Rock_Basalt"
    },
    {
      "x": -11,
      "y": 10,
      "z": -1,
      "name": "Rock_Basalt"
    },
    {
      "x": -11,
      "y": 11,
      "z": -1,
      "name": "Rock_Basalt"
    },
    {
      "x": -11,
      "y": 12,
      "z": -1,
      "name": "Plant_Moss_Block_Green_Dark"
    },
    {
      "x": -11,
      "y": 13,
      "z": -1,
      "name": "Plant_Moss_Block_Green_Dark"
    },
    {
      "x": -11,
      "y": 3,
      "z": 0,
      "name": "Rock_Basalt"
    },
    {
      "x": -11,
      "y": 4,
      "z": 0,
      "name": "Rock_Basalt"
    },
    {
      "x": -11,
      "y": 5,
      "z": 0,
      "name": "Rock_Basalt"
    },
    {
      "x": -11,
      "y": 6,
      "z": 0,
      "name": "Rock_Basalt"
    },
    {
      "x": -11,
      "y": 7,
      "z": 0,
      "name": "Rock_Basalt"
    },
    {
      "x": -11,
      "y": 8,
      "z": 0,
      "name": "Rock_Basalt"
    },
    {
      "x": -11,
      "y": 9,
      "z": 0,
      "name": "Rock_Basalt"
    },
    {
      "x": -11,
      "y": 10,
      "z": 0,
      "name": "Rock_Basalt"
    },
    {
      "x": -11,
      "y": 11,
      "z": 0,
      "name": "Rock_Basalt"
    },
    {
      "x": -11,
      "y": 12,
      "z": 0,
      "name": "Plant_Moss_Block_Green_Dark"
    },
    {
      "x": -11,
      "y": 13,
      "z": 0,
      "name": "Plant_Moss_Block_Green_Dark"
    },
    {
      "x": -11,
      "y": 2,
      "z": 1,
      "name": "Rock_Basalt"
    },
    {
      "x": -11,
      "y": 3,
      "z": 1,
      "name": "Rock_Basalt"
    },
    {
      "x": -11,
      "y": 4,
      "z": 1,
      "name": "Rock_Basalt"
    },
    {
      "x": -11,
      "y": 5,
      "z": 1,
      "name": "Rock_Basalt"
    },
    {
      "x": -11,
      "y": 6,
      "z": 1,
      "name": "Rock_Basalt"
    },
    {
      "x": -11,
      "y": 7,
      "z": 1,
      "name": "Rock_Basalt"
    },
    {
      "x": -11,
      "y": 8,
      "z": 1,
      "name": "Rock_Basalt"
    },
    {
      "x": -11,
      "y": 9,
      "z": 1,
      "name": "Rock_Basalt"
    },
    {
      "x": -11,
      "y": 10,
      "z": 1,
      "name": "Rock_Basalt"
    },
    {
      "x": -11,
      "y": 11,
      "z": 1,
      "name": "Rock_Basalt"
    },
    {
      "x": -11,
      "y": 12,
      "z": 1,
      "name": "Plant_Moss_Block_Green_Dark"
    },
    {
      "x": -11,
      "y": 13,
      "z": 1,
      "name": "Plant_Moss_Block_Green_Dark"
    },
    {
      "x": -11,
      "y": 1,
      "z": 2,
      "name": "Rock_Basalt"
    },
    {
      "x": -11,
      "y": 2,
      "z": 2,
      "name": "Rock_Basalt"
    },
    {
      "x": -11,
      "y": 3,
      "z": 2,
      "name": "Rock_Basalt"
    },
    {
      "x": -11,
      "y": 4,
      "z": 2,
      "name": "Rock_Basalt"
    },
    {
      "x": -11,
      "y": 5,
      "z": 2,
      "name": "Rock_Basalt"
    },
    {
      "x": -11,
      "y": 6,
      "z": 2,
      "name": "Rock_Basalt"
    },
    {
      "x": -11,
      "y": 7,
      "z": 2,
      "name": "Rock_Basalt"
    },
    {
      "x": -11,
      "y": 8,
      "z": 2,
      "name": "Rock_Basalt"
    },
    {
      "x": -11,
      "y": 9,
      "z": 2,
      "name": "Rock_Basalt"
    },
    {
      "x": -11,
      "y": 10,
      "z": 2,
      "name": "Rock_Basalt"
    },
    {
      "x": -11,
      "y": 11,
      "z": 2,
      "name": "Rock_Basalt"
    },
    {
      "x": -11,
      "y": 12,
      "z": 2,
      "name": "Plant_Moss_Block_Green_Dark"
    },
    {
      "x": -11,
      "y": 13,
      "z": 2,
      "name": "Plant_Moss_Block_Green_Dark"
    },
    {
      "x": -11,
      "y": 1,
      "z": 3,
      "name": "Rock_Basalt"
    },
    {
      "x": -11,
      "y": 2,
      "z": 3,
      "name": "Rock_Basalt"
    },
    {
      "x": -11,
      "y": 3,
      "z": 3,
      "name": "Rock_Basalt"
    },
    {
      "x": -11,
      "y": 4,
      "z": 3,
      "name": "Rock_Basalt"
    },
    {
      "x": -11,
      "y": 5,
      "z": 3,
      "name": "Rock_Basalt"
    },
    {
      "x": -11,
      "y": 6,
      "z": 3,
      "name": "Rock_Basalt"
    },
    {
      "x": -11,
      "y": 7,
      "z": 3,
      "name": "Rock_Basalt"
    },
    {
      "x": -11,
      "y": 8,
      "z": 3,
      "name": "Rock_Basalt"
    },
    {
      "x": -11,
      "y": 9,
      "z": 3,
      "name": "Rock_Basalt"
    },
    {
      "x": -11,
      "y": 10,
      "z": 3,
      "name": "Rock_Basalt"
    },
    {
      "x": -11,
      "y": 11,
      "z": 3,
      "name": "Rock_Basalt"
    },
    {
      "x": -11,
      "y": 12,
      "z": 3,
      "name": "Plant_Moss_Block_Green_Dark"
    },
    {
      "x": -11,
      "y": 13,
      "z": 3,
      "name": "Plant_Moss_Block_Green_Dark"
    },
    {
      "x": -11,
      "y": 1,
      "z": 4,
      "name": "Rock_Basalt"
    },
    {
      "x": -11,
      "y": 2,
      "z": 4,
      "name": "Rock_Basalt"
    },
    {
      "x": -11,
      "y": 3,
      "z": 4,
      "name": "Rock_Basalt"
    },
    {
      "x": -11,
      "y": 4,
      "z": 4,
      "name": "Rock_Basalt"
    },
    {
      "x": -11,
      "y": 5,
      "z": 4,
      "name": "Rock_Basalt"
    },
    {
      "x": -11,
      "y": 6,
      "z": 4,
      "name": "Rock_Basalt"
    },
    {
      "x": -11,
      "y": 7,
      "z": 4,
      "name": "Rock_Basalt"
    },
    {
      "x": -11,
      "y": 8,
      "z": 4,
      "name": "Rock_Basalt"
    },
    {
      "x": -11,
      "y": 9,
      "z": 4,
      "name": "Rock_Basalt"
    },
    {
      "x": -11,
      "y": 10,
      "z": 4,
      "name": "Rock_Basalt"
    },
    {
      "x": -11,
      "y": 11,
      "z": 4,
      "name": "Rock_Basalt"
    },
    {
      "x": -11,
      "y": 12,
      "z": 4,
      "name": "Plant_Moss_Block_Green_Dark"
    },
    {
      "x": -11,
      "y": 13,
      "z": 4,
      "name": "Plant_Moss_Block_Green_Dark"
    },
    {
      "x": -11,
      "y": 2,
      "z": 5,
      "name": "Rock_Basalt"
    },
    {
      "x": -11,
      "y": 3,
      "z": 5,
      "name": "Rock_Basalt"
    },
    {
      "x": -11,
      "y": 4,
      "z": 5,
      "name": "Rock_Basalt"
    },
    {
      "x": -11,
      "y": 5,
      "z": 5,
      "name": "Rock_Basalt"
    },
    {
      "x": -11,
      "y": 6,
      "z": 5,
      "name": "Rock_Basalt"
    },
    {
      "x": -11,
      "y": 7,
      "z": 5,
      "name": "Rock_Basalt"
    },
    {
      "x": -11,
      "y": 8,
      "z": 5,
      "name": "Rock_Basalt"
    },
    {
      "x": -11,
      "y": 9,
      "z": 5,
      "name": "Rock_Basalt"
    },
    {
      "x": -11,
      "y": 10,
      "z": 5,
      "name": "Rock_Basalt"
    },
    {
      "x": -11,
      "y": 11,
      "z": 5,
      "name": "Rock_Basalt"
    },
    {
      "x": -11,
      "y": 12,
      "z": 5,
      "name": "Plant_Moss_Block_Green_Dark"
    },
    {
      "x": -11,
      "y": 13,
      "z": 5,
      "name": "Plant_Moss_Block_Green_Dark"
    },
    {
      "x": -11,
      "y": 3,
      "z": 6,
      "name": "Rock_Basalt"
    },
    {
      "x": -11,
      "y": 4,
      "z": 6,
      "name": "Rock_Basalt"
    },
    {
      "x": -11,
      "y": 5,
      "z": 6,
      "name": "Rock_Basalt"
    },
    {
      "x": -11,
      "y": 6,
      "z": 6,
      "name": "Rock_Basalt"
    },
    {
      "x": -11,
      "y": 7,
      "z": 6,
      "name": "Rock_Basalt"
    },
    {
      "x": -11,
      "y": 8,
      "z": 6,
      "name": "Rock_Basalt"
    },
    {
      "x": -11,
      "y": 9,
      "z": 6,
      "name": "Rock_Basalt"
    },
    {
      "x": -11,
      "y": 10,
      "z": 6,
      "name": "Rock_Basalt"
    },
    {
      "x": -11,
      "y": 11,
      "z": 6,
      "name": "Rock_Basalt"
    },
    {
      "x": -11,
      "y": 12,
      "z": 6,
      "name": "Plant_Moss_Block_Green_Dark"
    },
    {
      "x": -11,
      "y": 13,
      "z": 6,
      "name": "Plant_Moss_Block_Green_Dark"
    },
    {
      "x": -11,
      "y": 6,
      "z": 7,
      "name": "Rock_Basalt"
    },
    {
      "x": -11,
      "y": 7,
      "z": 7,
      "name": "Rock_Basalt"
    },
    {
      "x": -11,
      "y": 8,
      "z": 7,
      "name": "Rock_Basalt"
    },
    {
      "x": -11,
      "y": 9,
      "z": 7,
      "name": "Rock_Basalt"
    },
    {
      "x": -11,
      "y": 10,
      "z": 7,
      "name": "Rock_Basalt"
    },
    {
      "x": -11,
      "y": 11,
      "z": 7,
      "name": "Plant_Moss_Block_Green_Dark"
    },
    {
      "x": -11,
      "y": 12,
      "z": 7,
      "name": "Plant_Moss_Block_Green_Dark"
    },
    {
      "x": -10,
      "y": 6,
      "z": -2,
      "name": "Rock_Basalt"
    },
    {
      "x": -10,
      "y": 8,
      "z": -2,
      "name": "Rock_Basalt"
    },
    {
      "x": -10,
      "y": 9,
      "z": -2,
      "name": "Rock_Basalt"
    },
    {
      "x": -10,
      "y": 10,
      "z": -2,
      "name": "Rock_Basalt"
    },
    {
      "x": -10,
      "y": 3,
      "z": -1,
      "name": "Rock_Basalt"
    },
    {
      "x": -10,
      "y": 4,
      "z": -1,
      "name": "Rock_Basalt"
    },
    {
      "x": -10,
      "y": 5,
      "z": -1,
      "name": "Rock_Basalt"
    },
    {
      "x": -10,
      "y": 6,
      "z": -1,
      "name": "Rock_Basalt"
    },
    {
      "x": -10,
      "y": 7,
      "z": -1,
      "name": "Rock_Basalt"
    },
    {
      "x": -10,
      "y": 8,
      "z": -1,
      "name": "Rock_Basalt"
    },
    {
      "x": -10,
      "y": 9,
      "z": -1,
      "name": "Rock_Basalt"
    },
    {
      "x": -10,
      "y": 10,
      "z": -1,
      "name": "Rock_Basalt"
    },
    {
      "x": -10,
      "y": 11,
      "z": -1,
      "name": "Rock_Basalt"
    },
    {
      "x": -10,
      "y": 12,
      "z": -1,
      "name": "Plant_Moss_Block_Green_Dark"
    },
    {
      "x": -10,
      "y": 13,
      "z": -1,
      "name": "Plant_Moss_Block_Green_Dark"
    },
    {
      "x": -10,
      "y": 2,
      "z": 0,
      "name": "Rock_Basalt"
    },
    {
      "x": -10,
      "y": 3,
      "z": 0,
      "name": "Rock_Basalt"
    },
    {
      "x": -10,
      "y": 4,
      "z": 0,
      "name": "Rock_Basalt"
    },
    {
      "x": -10,
      "y": 5,
      "z": 0,
      "name": "Rock_Basalt"
    },
    {
      "x": -10,
      "y": 6,
      "z": 0,
      "name": "Rock_Basalt"
    },
    {
      "x": -10,
      "y": 7,
      "z": 0,
      "name": "Rock_Basalt"
    },
    {
      "x": -10,
      "y": 8,
      "z": 0,
      "name": "Rock_Basalt"
    },
    {
      "x": -10,
      "y": 9,
      "z": 0,
      "name": "Rock_Basalt"
    },
    {
      "x": -10,
      "y": 10,
      "z": 0,
      "name": "Rock_Basalt"
    },
    {
      "x": -10,
      "y": 11,
      "z": 0,
      "name": "Rock_Basalt"
    },
    {
      "x": -10,
      "y": 12,
      "z": 0,
      "name": "Plant_Moss_Block_Green_Dark"
    },
    {
      "x": -10,
      "y": 13,
      "z": 0,
      "name": "Plant_Moss_Block_Green_Dark"
    },
    {
      "x": -10,
      "y": 1,
      "z": 1,
      "name": "Rock_Basalt"
    },
    {
      "x": -10,
      "y": 2,
      "z": 1,
      "name": "Rock_Basalt"
    },
    {
      "x": -10,
      "y": 3,
      "z": 1,
      "name": "Rock_Basalt"
    },
    {
      "x": -10,
      "y": 4,
      "z": 1,
      "name": "Rock_Basalt"
    },
    {
      "x": -10,
      "y": 5,
      "z": 1,
      "name": "Rock_Basalt"
    },
    {
      "x": -10,
      "y": 6,
      "z": 1,
      "name": "Rock_Basalt"
    },
    {
      "x": -10,
      "y": 7,
      "z": 1,
      "name": "Rock_Basalt"
    },
    {
      "x": -10,
      "y": 8,
      "z": 1,
      "name": "Rock_Basalt"
    },
    {
      "x": -10,
      "y": 9,
      "z": 1,
      "name": "Rock_Basalt"
    },
    {
      "x": -10,
      "y": 10,
      "z": 1,
      "name": "Rock_Basalt"
    },
    {
      "x": -10,
      "y": 11,
      "z": 1,
      "name": "Rock_Basalt"
    },
    {
      "x": -10,
      "y": 12,
      "z": 1,
      "name": "Plant_Moss_Block_Green_Dark"
    },
    {
      "x": -10,
      "y": 13,
      "z": 1,
      "name": "Plant_Moss_Block_Green_Dark"
    },
    {
      "x": -10,
      "y": 1,
      "z": 2,
      "name": "Rock_Basalt"
    },
    {
      "x": -10,
      "y": 2,
      "z": 2,
      "name": "Rock_Basalt"
    },
    {
      "x": -10,
      "y": 3,
      "z": 2,
      "name": "Rock_Basalt"
    },
    {
      "x": -10,
      "y": 4,
      "z": 2,
      "name": "Rock_Basalt"
    },
    {
      "x": -10,
      "y": 5,
      "z": 2,
      "name": "Rock_Basalt"
    },
    {
      "x": -10,
      "y": 6,
      "z": 2,
      "name": "Rock_Basalt"
    },
    {
      "x": -10,
      "y": 7,
      "z": 2,
      "name": "Rock_Basalt"
    },
    {
      "x": -10,
      "y": 8,
      "z": 2,
      "name": "Rock_Basalt"
    },
    {
      "x": -10,
      "y": 9,
      "z": 2,
      "name": "Rock_Basalt"
    },
    {
      "x": -10,
      "y": 10,
      "z": 2,
      "name": "Rock_Basalt"
    },
    {
      "x": -10,
      "y": 11,
      "z": 2,
      "name": "Rock_Basalt"
    },
    {
      "x": -10,
      "y": 12,
      "z": 2,
      "name": "Plant_Moss_Block_Green_Dark"
    },
    {
      "x": -10,
      "y": 13,
      "z": 2,
      "name": "Plant_Moss_Block_Green_Dark"
    },
    {
      "x": -10,
      "y": 1,
      "z": 3,
      "name": "Rock_Basalt"
    },
    {
      "x": -10,
      "y": 2,
      "z": 3,
      "name": "Rock_Basalt"
    },
    {
      "x": -10,
      "y": 3,
      "z": 3,
      "name": "Rock_Basalt"
    },
    {
      "x": -10,
      "y": 4,
      "z": 3,
      "name": "Rock_Basalt"
    },
    {
      "x": -10,
      "y": 5,
      "z": 3,
      "name": "Rock_Basalt"
    },
    {
      "x": -10,
      "y": 6,
      "z": 3,
      "name": "Rock_Basalt"
    },
    {
      "x": -10,
      "y": 7,
      "z": 3,
      "name": "Rock_Basalt"
    },
    {
      "x": -10,
      "y": 8,
      "z": 3,
      "name": "Rock_Basalt"
    },
    {
      "x": -10,
      "y": 9,
      "z": 3,
      "name": "Rock_Basalt"
    },
    {
      "x": -10,
      "y": 10,
      "z": 3,
      "name": "Rock_Basalt"
    },
    {
      "x": -10,
      "y": 11,
      "z": 3,
      "name": "Rock_Basalt"
    },
    {
      "x": -10,
      "y": 12,
      "z": 3,
      "name": "Plant_Moss_Block_Green_Dark"
    },
    {
      "x": -10,
      "y": 13,
      "z": 3,
      "name": "Plant_Moss_Block_Green_Dark"
    },
    {
      "x": -10,
      "y": 1,
      "z": 4,
      "name": "Rock_Basalt"
    },
    {
      "x": -10,
      "y": 2,
      "z": 4,
      "name": "Rock_Basalt"
    },
    {
      "x": -10,
      "y": 3,
      "z": 4,
      "name": "Rock_Basalt"
    },
    {
      "x": -10,
      "y": 4,
      "z": 4,
      "name": "Rock_Basalt"
    },
    {
      "x": -10,
      "y": 5,
      "z": 4,
      "name": "Rock_Basalt"
    },
    {
      "x": -10,
      "y": 6,
      "z": 4,
      "name": "Rock_Basalt"
    },
    {
      "x": -10,
      "y": 7,
      "z": 4,
      "name": "Rock_Basalt"
    },
    {
      "x": -10,
      "y": 8,
      "z": 4,
      "name": "Rock_Basalt"
    },
    {
      "x": -10,
      "y": 9,
      "z": 4,
      "name": "Rock_Basalt"
    },
    {
      "x": -10,
      "y": 10,
      "z": 4,
      "name": "Rock_Basalt"
    },
    {
      "x": -10,
      "y": 11,
      "z": 4,
      "name": "Rock_Basalt"
    },
    {
      "x": -10,
      "y": 12,
      "z": 4,
      "name": "Plant_Moss_Block_Green_Dark"
    },
    {
      "x": -10,
      "y": 13,
      "z": 4,
      "name": "Plant_Moss_Block_Green_Dark"
    },
    {
      "x": -10,
      "y": 1,
      "z": 5,
      "name": "Rock_Basalt"
    },
    {
      "x": -10,
      "y": 2,
      "z": 5,
      "name": "Rock_Basalt"
    },
    {
      "x": -10,
      "y": 3,
      "z": 5,
      "name": "Rock_Basalt"
    },
    {
      "x": -10,
      "y": 4,
      "z": 5,
      "name": "Rock_Basalt"
    },
    {
      "x": -10,
      "y": 5,
      "z": 5,
      "name": "Rock_Basalt"
    },
    {
      "x": -10,
      "y": 6,
      "z": 5,
      "name": "Rock_Basalt"
    },
    {
      "x": -10,
      "y": 7,
      "z": 5,
      "name": "Rock_Basalt"
    },
    {
      "x": -10,
      "y": 8,
      "z": 5,
      "name": "Rock_Basalt"
    },
    {
      "x": -10,
      "y": 9,
      "z": 5,
      "name": "Rock_Basalt"
    },
    {
      "x": -10,
      "y": 10,
      "z": 5,
      "name": "Rock_Basalt"
    },
    {
      "x": -10,
      "y": 11,
      "z": 5,
      "name": "Rock_Basalt"
    },
    {
      "x": -10,
      "y": 12,
      "z": 5,
      "name": "Plant_Moss_Block_Green_Dark"
    },
    {
      "x": -10,
      "y": 13,
      "z": 5,
      "name": "Plant_Moss_Block_Green_Dark"
    },
    {
      "x": -10,
      "y": 2,
      "z": 6,
      "name": "Rock_Basalt"
    },
    {
      "x": -10,
      "y": 3,
      "z": 6,
      "name": "Rock_Basalt"
    },
    {
      "x": -10,
      "y": 4,
      "z": 6,
      "name": "Rock_Basalt"
    },
    {
      "x": -10,
      "y": 5,
      "z": 6,
      "name": "Rock_Basalt"
    },
    {
      "x": -10,
      "y": 6,
      "z": 6,
      "name": "Rock_Basalt"
    },
    {
      "x": -10,
      "y": 7,
      "z": 6,
      "name": "Rock_Basalt"
    },
    {
      "x": -10,
      "y": 8,
      "z": 6,
      "name": "Rock_Basalt"
    },
    {
      "x": -10,
      "y": 9,
      "z": 6,
      "name": "Rock_Basalt"
    },
    {
      "x": -10,
      "y": 10,
      "z": 6,
      "name": "Rock_Basalt"
    },
    {
      "x": -10,
      "y": 11,
      "z": 6,
      "name": "Plant_Moss_Block_Green_Dark"
    },
    {
      "x": -10,
      "y": 12,
      "z": 6,
      "name": "Plant_Moss_Block_Green_Dark"
    },
    {
      "x": -10,
      "y": 5,
      "z": 7,
      "name": "Rock_Basalt"
    },
    {
      "x": -10,
      "y": 6,
      "z": 7,
      "name": "Rock_Basalt"
    },
    {
      "x": -10,
      "y": 7,
      "z": 7,
      "name": "Rock_Basalt"
    },
    {
      "x": -10,
      "y": 8,
      "z": 7,
      "name": "Rock_Basalt"
    },
    {
      "x": -10,
      "y": 9,
      "z": 7,
      "name": "Rock_Basalt"
    },
    {
      "x": -10,
      "y": 10,
      "z": 7,
      "name": "Rock_Basalt"
    },
    {
      "x": -10,
      "y": 11,
      "z": 7,
      "name": "Plant_Moss_Block_Green_Dark"
    },
    {
      "x": -10,
      "y": 12,
      "z": 7,
      "name": "Plant_Moss_Block_Green_Dark"
    },
    {
      "x": -9,
      "y": 3,
      "z": -2,
      "name": "Rock_Basalt"
    },
    {
      "x": -9,
      "y": 4,
      "z": -2,
      "name": "Rock_Basalt"
    },
    {
      "x": -9,
      "y": 5,
      "z": -2,
      "name": "Rock_Basalt"
    },
    {
      "x": -9,
      "y": 6,
      "z": -2,
      "name": "Rock_Basalt"
    },
    {
      "x": -9,
      "y": 7,
      "z": -2,
      "name": "Rock_Basalt"
    },
    {
      "x": -9,
      "y": 8,
      "z": -2,
      "name": "Rock_Basalt"
    },
    {
      "x": -9,
      "y": 9,
      "z": -2,
      "name": "Rock_Basalt"
    },
    {
      "x": -9,
      "y": 10,
      "z": -2,
      "name": "Rock_Basalt"
    },
    {
      "x": -9,
      "y": 2,
      "z": -1,
      "name": "Rock_Basalt"
    },
    {
      "x": -9,
      "y": 3,
      "z": -1,
      "name": "Rock_Basalt"
    },
    {
      "x": -9,
      "y": 4,
      "z": -1,
      "name": "Rock_Basalt"
    },
    {
      "x": -9,
      "y": 5,
      "z": -1,
      "name": "Rock_Basalt"
    },
    {
      "x": -9,
      "y": 6,
      "z": -1,
      "name": "Rock_Basalt"
    },
    {
      "x": -9,
      "y": 7,
      "z": -1,
      "name": "Rock_Basalt"
    },
    {
      "x": -9,
      "y": 8,
      "z": -1,
      "name": "Rock_Basalt"
    },
    {
      "x": -9,
      "y": 9,
      "z": -1,
      "name": "Rock_Basalt"
    },
    {
      "x": -9,
      "y": 10,
      "z": -1,
      "name": "Rock_Basalt"
    },
    {
      "x": -9,
      "y": 11,
      "z": -1,
      "name": "Rock_Basalt"
    },
    {
      "x": -9,
      "y": 12,
      "z": -1,
      "name": "Plant_Moss_Block_Green_Dark"
    },
    {
      "x": -9,
      "y": 13,
      "z": -1,
      "name": "Plant_Moss_Block_Green_Dark"
    },
    {
      "x": -9,
      "y": 1,
      "z": 0,
      "name": "Rock_Basalt"
    },
    {
      "x": -9,
      "y": 2,
      "z": 0,
      "name": "Rock_Basalt"
    },
    {
      "x": -9,
      "y": 3,
      "z": 0,
      "name": "Rock_Basalt"
    },
    {
      "x": -9,
      "y": 4,
      "z": 0,
      "name": "Rock_Basalt"
    },
    {
      "x": -9,
      "y": 5,
      "z": 0,
      "name": "Rock_Basalt"
    },
    {
      "x": -9,
      "y": 6,
      "z": 0,
      "name": "Rock_Basalt"
    },
    {
      "x": -9,
      "y": 7,
      "z": 0,
      "name": "Rock_Basalt"
    },
    {
      "x": -9,
      "y": 8,
      "z": 0,
      "name": "Rock_Basalt"
    },
    {
      "x": -9,
      "y": 9,
      "z": 0,
      "name": "Rock_Basalt"
    },
    {
      "x": -9,
      "y": 10,
      "z": 0,
      "name": "Rock_Basalt"
    },
    {
      "x": -9,
      "y": 11,
      "z": 0,
      "name": "Rock_Basalt"
    },
    {
      "x": -9,
      "y": 12,
      "z": 0,
      "name": "Plant_Moss_Block_Green_Dark"
    },
    {
      "x": -9,
      "y": 13,
      "z": 0,
      "name": "Plant_Moss_Block_Green_Dark"
    },
    {
      "x": -9,
      "y": 1,
      "z": 1,
      "name": "Rock_Basalt"
    },
    {
      "x": -9,
      "y": 2,
      "z": 1,
      "name": "Rock_Basalt"
    },
    {
      "x": -9,
      "y": 3,
      "z": 1,
      "name": "Rock_Basalt"
    },
    {
      "x": -9,
      "y": 4,
      "z": 1,
      "name": "Rock_Basalt"
    },
    {
      "x": -9,
      "y": 5,
      "z": 1,
      "name": "Rock_Basalt"
    },
    {
      "x": -9,
      "y": 6,
      "z": 1,
      "name": "Rock_Basalt"
    },
    {
      "x": -9,
      "y": 7,
      "z": 1,
      "name": "Rock_Basalt"
    },
    {
      "x": -9,
      "y": 8,
      "z": 1,
      "name": "Rock_Basalt"
    },
    {
      "x": -9,
      "y": 9,
      "z": 1,
      "name": "Rock_Basalt"
    },
    {
      "x": -9,
      "y": 10,
      "z": 1,
      "name": "Rock_Basalt"
    },
    {
      "x": -9,
      "y": 11,
      "z": 1,
      "name": "Rock_Basalt"
    },
    {
      "x": -9,
      "y": 12,
      "z": 1,
      "name": "Plant_Moss_Block_Green_Dark"
    },
    {
      "x": -9,
      "y": 13,
      "z": 1,
      "name": "Plant_Moss_Block_Green_Dark"
    },
    {
      "x": -9,
      "y": 0,
      "z": 2,
      "name": "Rock_Basalt"
    },
    {
      "x": -9,
      "y": 1,
      "z": 2,
      "name": "Rock_Basalt"
    },
    {
      "x": -9,
      "y": 2,
      "z": 2,
      "name": "Rock_Basalt"
    },
    {
      "x": -9,
      "y": 3,
      "z": 2,
      "name": "Rock_Basalt"
    },
    {
      "x": -9,
      "y": 4,
      "z": 2,
      "name": "Rock_Basalt"
    },
    {
      "x": -9,
      "y": 5,
      "z": 2,
      "name": "Rock_Basalt"
    },
    {
      "x": -9,
      "y": 6,
      "z": 2,
      "name": "Rock_Basalt"
    },
    {
      "x": -9,
      "y": 7,
      "z": 2,
      "name": "Rock_Basalt"
    },
    {
      "x": -9,
      "y": 8,
      "z": 2,
      "name": "Rock_Basalt"
    },
    {
      "x": -9,
      "y": 9,
      "z": 2,
      "name": "Rock_Basalt"
    },
    {
      "x": -9,
      "y": 10,
      "z": 2,
      "name": "Rock_Basalt"
    },
    {
      "x": -9,
      "y": 11,
      "z": 2,
      "name": "Rock_Basalt"
    },
    {
      "x": -9,
      "y": 12,
      "z": 2,
      "name": "Plant_Moss_Block_Green_Dark"
    },
    {
      "x": -9,
      "y": 13,
      "z": 2,
      "name": "Plant_Moss_Block_Green_Dark"
    },
    {
      "x": -9,
      "y": 0,
      "z": 3,
      "name": "Rock_Basalt"
    },
    {
      "x": -9,
      "y": 1,
      "z": 3,
      "name": "Rock_Basalt"
    },
    {
      "x": -9,
      "y": 2,
      "z": 3,
      "name": "Rock_Basalt"
    },
    {
      "x": -9,
      "y": 3,
      "z": 3,
      "name": "Rock_Basalt"
    },
    {
      "x": -9,
      "y": 4,
      "z": 3,
      "name": "Rock_Basalt"
    },
    {
      "x": -9,
      "y": 5,
      "z": 3,
      "name": "Rock_Basalt"
    },
    {
      "x": -9,
      "y": 6,
      "z": 3,
      "name": "Rock_Basalt"
    },
    {
      "x": -9,
      "y": 7,
      "z": 3,
      "name": "Rock_Basalt"
    },
    {
      "x": -9,
      "y": 8,
      "z": 3,
      "name": "Rock_Basalt"
    },
    {
      "x": -9,
      "y": 9,
      "z": 3,
      "name": "Rock_Basalt"
    },
    {
      "x": -9,
      "y": 10,
      "z": 3,
      "name": "Rock_Basalt"
    },
    {
      "x": -9,
      "y": 11,
      "z": 3,
      "name": "Rock_Basalt"
    },
    {
      "x": -9,
      "y": 12,
      "z": 3,
      "name": "Plant_Moss_Block_Green_Dark"
    },
    {
      "x": -9,
      "y": 13,
      "z": 3,
      "name": "Plant_Moss_Block_Green_Dark"
    },
    {
      "x": -9,
      "y": 1,
      "z": 4,
      "name": "Rock_Basalt"
    },
    {
      "x": -9,
      "y": 2,
      "z": 4,
      "name": "Rock_Basalt"
    },
    {
      "x": -9,
      "y": 3,
      "z": 4,
      "name": "Rock_Basalt"
    },
    {
      "x": -9,
      "y": 4,
      "z": 4,
      "name": "Rock_Basalt"
    },
    {
      "x": -9,
      "y": 5,
      "z": 4,
      "name": "Rock_Basalt"
    },
    {
      "x": -9,
      "y": 6,
      "z": 4,
      "name": "Rock_Basalt"
    },
    {
      "x": -9,
      "y": 7,
      "z": 4,
      "name": "Rock_Basalt"
    },
    {
      "x": -9,
      "y": 8,
      "z": 4,
      "name": "Rock_Basalt"
    },
    {
      "x": -9,
      "y": 9,
      "z": 4,
      "name": "Rock_Basalt"
    },
    {
      "x": -9,
      "y": 10,
      "z": 4,
      "name": "Rock_Basalt"
    },
    {
      "x": -9,
      "y": 11,
      "z": 4,
      "name": "Rock_Basalt"
    },
    {
      "x": -9,
      "y": 12,
      "z": 4,
      "name": "Plant_Moss_Block_Green_Dark"
    },
    {
      "x": -9,
      "y": 13,
      "z": 4,
      "name": "Plant_Moss_Block_Green_Dark"
    },
    {
      "x": -9,
      "y": 1,
      "z": 5,
      "name": "Rock_Basalt"
    },
    {
      "x": -9,
      "y": 2,
      "z": 5,
      "name": "Rock_Basalt"
    },
    {
      "x": -9,
      "y": 3,
      "z": 5,
      "name": "Rock_Basalt"
    },
    {
      "x": -9,
      "y": 4,
      "z": 5,
      "name": "Rock_Basalt"
    },
    {
      "x": -9,
      "y": 5,
      "z": 5,
      "name": "Rock_Basalt"
    },
    {
      "x": -9,
      "y": 6,
      "z": 5,
      "name": "Rock_Basalt"
    },
    {
      "x": -9,
      "y": 7,
      "z": 5,
      "name": "Rock_Basalt"
    },
    {
      "x": -9,
      "y": 8,
      "z": 5,
      "name": "Rock_Basalt"
    },
    {
      "x": -9,
      "y": 9,
      "z": 5,
      "name": "Rock_Basalt"
    },
    {
      "x": -9,
      "y": 10,
      "z": 5,
      "name": "Rock_Basalt"
    },
    {
      "x": -9,
      "y": 11,
      "z": 5,
      "name": "Rock_Basalt"
    },
    {
      "x": -9,
      "y": 12,
      "z": 5,
      "name": "Plant_Moss_Block_Green_Dark"
    },
    {
      "x": -9,
      "y": 13,
      "z": 5,
      "name": "Plant_Moss_Block_Green_Dark"
    },
    {
      "x": -9,
      "y": 2,
      "z": 6,
      "name": "Rock_Basalt"
    },
    {
      "x": -9,
      "y": 3,
      "z": 6,
      "name": "Rock_Basalt"
    },
    {
      "x": -9,
      "y": 4,
      "z": 6,
      "name": "Rock_Basalt"
    },
    {
      "x": -9,
      "y": 5,
      "z": 6,
      "name": "Rock_Basalt"
    },
    {
      "x": -9,
      "y": 6,
      "z": 6,
      "name": "Rock_Basalt"
    },
    {
      "x": -9,
      "y": 7,
      "z": 6,
      "name": "Rock_Basalt"
    },
    {
      "x": -9,
      "y": 8,
      "z": 6,
      "name": "Rock_Basalt"
    },
    {
      "x": -9,
      "y": 9,
      "z": 6,
      "name": "Rock_Basalt"
    },
    {
      "x": -9,
      "y": 10,
      "z": 6,
      "name": "Rock_Basalt"
    },
    {
      "x": -9,
      "y": 11,
      "z": 6,
      "name": "Plant_Moss_Block_Green_Dark"
    },
    {
      "x": -9,
      "y": 12,
      "z": 6,
      "name": "Plant_Moss_Block_Green_Dark"
    },
    {
      "x": -9,
      "y": 4,
      "z": 7,
      "name": "Rock_Basalt"
    },
    {
      "x": -9,
      "y": 5,
      "z": 7,
      "name": "Rock_Basalt"
    },
    {
      "x": -9,
      "y": 6,
      "z": 7,
      "name": "Rock_Basalt"
    },
    {
      "x": -9,
      "y": 7,
      "z": 7,
      "name": "Rock_Basalt"
    },
    {
      "x": -9,
      "y": 8,
      "z": 7,
      "name": "Rock_Basalt"
    },
    {
      "x": -9,
      "y": 9,
      "z": 7,
      "name": "Rock_Basalt"
    },
    {
      "x": -9,
      "y": 10,
      "z": 7,
      "name": "Rock_Basalt"
    },
    {
      "x": -9,
      "y": 11,
      "z": 7,
      "name": "Rock_Basalt"
    },
    {
      "x": -8,
      "y": 4,
      "z": -3,
      "name": "Rock_Basalt"
    },
    {
      "x": -8,
      "y": 5,
      "z": -3,
      "name": "Rock_Basalt"
    },
    {
      "x": -8,
      "y": 6,
      "z": -3,
      "name": "Rock_Basalt"
    },
    {
      "x": -8,
      "y": 7,
      "z": -3,
      "name": "Rock_Basalt"
    },
    {
      "x": -8,
      "y": 8,
      "z": -3,
      "name": "Rock_Basalt"
    },
    {
      "x": -8,
      "y": 2,
      "z": -2,
      "name": "Rock_Basalt"
    },
    {
      "x": -8,
      "y": 3,
      "z": -2,
      "name": "Rock_Basalt"
    },
    {
      "x": -8,
      "y": 4,
      "z": -2,
      "name": "Rock_Basalt"
    },
    {
      "x": -8,
      "y": 5,
      "z": -2,
      "name": "Rock_Basalt"
    },
    {
      "x": -8,
      "y": 6,
      "z": -2,
      "name": "Rock_Basalt"
    },
    {
      "x": -8,
      "y": 7,
      "z": -2,
      "name": "Rock_Basalt"
    },
    {
      "x": -8,
      "y": 8,
      "z": -2,
      "name": "Rock_Basalt"
    },
    {
      "x": -8,
      "y": 2,
      "z": -1,
      "name": "Rock_Basalt"
    },
    {
      "x": -8,
      "y": 3,
      "z": -1,
      "name": "Rock_Basalt"
    },
    {
      "x": -8,
      "y": 4,
      "z": -1,
      "name": "Rock_Basalt"
    },
    {
      "x": -8,
      "y": 5,
      "z": -1,
      "name": "Rock_Basalt"
    },
    {
      "x": -8,
      "y": 6,
      "z": -1,
      "name": "Rock_Basalt"
    },
    {
      "x": -8,
      "y": 7,
      "z": -1,
      "name": "Rock_Basalt"
    },
    {
      "x": -8,
      "y": 8,
      "z": -1,
      "name": "Rock_Basalt"
    },
    {
      "x": -8,
      "y": 9,
      "z": -1,
      "name": "Rock_Basalt"
    },
    {
      "x": -8,
      "y": 10,
      "z": -1,
      "name": "Rock_Basalt"
    },
    {
      "x": -8,
      "y": 11,
      "z": -1,
      "name": "Rock_Basalt"
    },
    {
      "x": -8,
      "y": 12,
      "z": -1,
      "name": "Rock_Basalt"
    },
    {
      "x": -8,
      "y": 1,
      "z": 0,
      "name": "Rock_Basalt"
    },
    {
      "x": -8,
      "y": 2,
      "z": 0,
      "name": "Rock_Basalt"
    },
    {
      "x": -8,
      "y": 3,
      "z": 0,
      "name": "Rock_Basalt"
    },
    {
      "x": -8,
      "y": 4,
      "z": 0,
      "name": "Rock_Basalt"
    },
    {
      "x": -8,
      "y": 5,
      "z": 0,
      "name": "Rock_Basalt"
    },
    {
      "x": -8,
      "y": 6,
      "z": 0,
      "name": "Rock_Basalt"
    },
    {
      "x": -8,
      "y": 7,
      "z": 0,
      "name": "Rock_Basalt"
    },
    {
      "x": -8,
      "y": 8,
      "z": 0,
      "name": "Rock_Basalt"
    },
    {
      "x": -8,
      "y": 9,
      "z": 0,
      "name": "Rock_Basalt"
    },
    {
      "x": -8,
      "y": 10,
      "z": 0,
      "name": "Rock_Basalt"
    },
    {
      "x": -8,
      "y": 11,
      "z": 0,
      "name": "Rock_Basalt"
    },
    {
      "x": -8,
      "y": 12,
      "z": 0,
      "name": "Plant_Moss_Block_Green_Dark"
    },
    {
      "x": -8,
      "y": 13,
      "z": 0,
      "name": "Plant_Moss_Block_Green_Dark"
    },
    {
      "x": -8,
      "y": 14,
      "z": 0,
      "name": "Plant_Bramble_Moss_Twisted"
    },
    {
      "x": -8,
      "y": 1,
      "z": 1,
      "name": "Rock_Basalt"
    },
    {
      "x": -8,
      "y": 2,
      "z": 1,
      "name": "Rock_Basalt"
    },
    {
      "x": -8,
      "y": 3,
      "z": 1,
      "name": "Rock_Basalt"
    },
    {
      "x": -8,
      "y": 4,
      "z": 1,
      "name": "Rock_Basalt"
    },
    {
      "x": -8,
      "y": 5,
      "z": 1,
      "name": "Rock_Basalt"
    },
    {
      "x": -8,
      "y": 6,
      "z": 1,
      "name": "Rock_Basalt"
    },
    {
      "x": -8,
      "y": 7,
      "z": 1,
      "name": "Rock_Basalt"
    },
    {
      "x": -8,
      "y": 8,
      "z": 1,
      "name": "Rock_Basalt"
    },
    {
      "x": -8,
      "y": 9,
      "z": 1,
      "name": "Rock_Basalt"
    },
    {
      "x": -8,
      "y": 10,
      "z": 1,
      "name": "Rock_Basalt"
    },
    {
      "x": -8,
      "y": 11,
      "z": 1,
      "name": "Rock_Basalt"
    },
    {
      "x": -8,
      "y": 12,
      "z": 1,
      "name": "Rock_Basalt"
    },
    {
      "x": -8,
      "y": 13,
      "z": 1,
      "name": "Plant_Moss_Block_Green_Dark"
    },
    {
      "x": -8,
      "y": 14,
      "z": 1,
      "name": "Plant_Moss_Block_Green_Dark"
    },
    {
      "x": -8,
      "y": 0,
      "z": 2,
      "name": "Rock_Basalt"
    },
    {
      "x": -8,
      "y": 1,
      "z": 2,
      "name": "Rock_Basalt"
    },
    {
      "x": -8,
      "y": 2,
      "z": 2,
      "name": "Rock_Basalt"
    },
    {
      "x": -8,
      "y": 3,
      "z": 2,
      "name": "Rock_Basalt"
    },
    {
      "x": -8,
      "y": 4,
      "z": 2,
      "name": "Rock_Basalt"
    },
    {
      "x": -8,
      "y": 5,
      "z": 2,
      "name": "Rock_Basalt"
    },
    {
      "x": -8,
      "y": 6,
      "z": 2,
      "name": "Rock_Basalt"
    },
    {
      "x": -8,
      "y": 7,
      "z": 2,
      "name": "Rock_Basalt"
    },
    {
      "x": -8,
      "y": 8,
      "z": 2,
      "name": "Rock_Basalt"
    },
    {
      "x": -8,
      "y": 9,
      "z": 2,
      "name": "Rock_Basalt"
    },
    {
      "x": -8,
      "y": 10,
      "z": 2,
      "name": "Rock_Basalt"
    },
    {
      "x": -8,
      "y": 11,
      "z": 2,
      "name": "Rock_Basalt"
    },
    {
      "x": -8,
      "y": 12,
      "z": 2,
      "name": "Rock_Basalt"
    },
    {
      "x": -8,
      "y": 13,
      "z": 2,
      "name": "Rock_Basalt"
    },
    {
      "x": -8,
      "y": 14,
      "z": 2,
      "name": "Plant_Moss_Block_Green_Dark"
    },
    {
      "x": -8,
      "y": 15,
      "z": 2,
      "name": "Plant_Moss_Block_Green_Dark"
    },
    {
      "x": -8,
      "y": 0,
      "z": 3,
      "name": "Rock_Basalt"
    },
    {
      "x": -8,
      "y": 1,
      "z": 3,
      "name": "Rock_Basalt"
    },
    {
      "x": -8,
      "y": 2,
      "z": 3,
      "name": "Rock_Basalt"
    },
    {
      "x": -8,
      "y": 3,
      "z": 3,
      "name": "Rock_Basalt"
    },
    {
      "x": -8,
      "y": 4,
      "z": 3,
      "name": "Rock_Basalt"
    },
    {
      "x": -8,
      "y": 5,
      "z": 3,
      "name": "Rock_Basalt"
    },
    {
      "x": -8,
      "y": 6,
      "z": 3,
      "name": "Rock_Basalt"
    },
    {
      "x": -8,
      "y": 7,
      "z": 3,
      "name": "Rock_Basalt"
    },
    {
      "x": -8,
      "y": 8,
      "z": 3,
      "name": "Rock_Basalt"
    },
    {
      "x": -8,
      "y": 9,
      "z": 3,
      "name": "Rock_Basalt"
    },
    {
      "x": -8,
      "y": 10,
      "z": 3,
      "name": "Rock_Basalt"
    },
    {
      "x": -8,
      "y": 11,
      "z": 3,
      "name": "Rock_Basalt"
    },
    {
      "x": -8,
      "y": 12,
      "z": 3,
      "name": "Rock_Basalt"
    },
    {
      "x": -8,
      "y": 13,
      "z": 3,
      "name": "Plant_Moss_Block_Green_Dark"
    },
    {
      "x": -8,
      "y": 14,
      "z": 3,
      "name": "Plant_Moss_Block_Green_Dark"
    },
    {
      "x": -8,
      "y": 0,
      "z": 4,
      "name": "Rock_Basalt"
    },
    {
      "x": -8,
      "y": 1,
      "z": 4,
      "name": "Rock_Basalt"
    },
    {
      "x": -8,
      "y": 2,
      "z": 4,
      "name": "Rock_Basalt"
    },
    {
      "x": -8,
      "y": 3,
      "z": 4,
      "name": "Rock_Basalt"
    },
    {
      "x": -8,
      "y": 4,
      "z": 4,
      "name": "Rock_Basalt"
    },
    {
      "x": -8,
      "y": 5,
      "z": 4,
      "name": "Rock_Basalt"
    },
    {
      "x": -8,
      "y": 6,
      "z": 4,
      "name": "Rock_Basalt"
    },
    {
      "x": -8,
      "y": 7,
      "z": 4,
      "name": "Rock_Basalt"
    },
    {
      "x": -8,
      "y": 8,
      "z": 4,
      "name": "Rock_Basalt"
    },
    {
      "x": -8,
      "y": 9,
      "z": 4,
      "name": "Rock_Basalt"
    },
    {
      "x": -8,
      "y": 10,
      "z": 4,
      "name": "Rock_Basalt"
    },
    {
      "x": -8,
      "y": 11,
      "z": 4,
      "name": "Rock_Basalt"
    },
    {
      "x": -8,
      "y": 12,
      "z": 4,
      "name": "Plant_Moss_Block_Green_Dark"
    },
    {
      "x": -8,
      "y": 13,
      "z": 4,
      "name": "Plant_Moss_Block_Green_Dark"
    },
    {
      "x": -8,
      "y": 1,
      "z": 5,
      "name": "Rock_Basalt"
    },
    {
      "x": -8,
      "y": 2,
      "z": 5,
      "name": "Rock_Basalt"
    },
    {
      "x": -8,
      "y": 3,
      "z": 5,
      "name": "Rock_Basalt"
    },
    {
      "x": -8,
      "y": 4,
      "z": 5,
      "name": "Rock_Basalt"
    },
    {
      "x": -8,
      "y": 5,
      "z": 5,
      "name": "Rock_Basalt"
    },
    {
      "x": -8,
      "y": 6,
      "z": 5,
      "name": "Rock_Basalt"
    },
    {
      "x": -8,
      "y": 7,
      "z": 5,
      "name": "Rock_Basalt"
    },
    {
      "x": -8,
      "y": 8,
      "z": 5,
      "name": "Rock_Basalt"
    },
    {
      "x": -8,
      "y": 9,
      "z": 5,
      "name": "Rock_Basalt"
    },
    {
      "x": -8,
      "y": 10,
      "z": 5,
      "name": "Rock_Basalt"
    },
    {
      "x": -8,
      "y": 11,
      "z": 5,
      "name": "Plant_Moss_Block_Green_Dark"
    },
    {
      "x": -8,
      "y": 12,
      "z": 5,
      "name": "Plant_Moss_Block_Green_Dark"
    },
    {
      "x": -8,
      "y": 1,
      "z": 6,
      "name": "Rock_Basalt"
    },
    {
      "x": -8,
      "y": 2,
      "z": 6,
      "name": "Rock_Basalt"
    },
    {
      "x": -8,
      "y": 3,
      "z": 6,
      "name": "Rock_Basalt"
    },
    {
      "x": -8,
      "y": 4,
      "z": 6,
      "name": "Rock_Basalt"
    },
    {
      "x": -8,
      "y": 5,
      "z": 6,
      "name": "Rock_Basalt"
    },
    {
      "x": -8,
      "y": 6,
      "z": 6,
      "name": "Rock_Basalt"
    },
    {
      "x": -8,
      "y": 7,
      "z": 6,
      "name": "Rock_Basalt"
    },
    {
      "x": -8,
      "y": 8,
      "z": 6,
      "name": "Rock_Basalt"
    },
    {
      "x": -8,
      "y": 9,
      "z": 6,
      "name": "Rock_Basalt"
    },
    {
      "x": -8,
      "y": 10,
      "z": 6,
      "name": "Rock_Basalt"
    },
    {
      "x": -8,
      "y": 11,
      "z": 6,
      "name": "Rock_Basalt"
    },
    {
      "x": -8,
      "y": 2,
      "z": 7,
      "name": "Rock_Basalt"
    },
    {
      "x": -8,
      "y": 3,
      "z": 7,
      "name": "Rock_Basalt"
    },
    {
      "x": -8,
      "y": 4,
      "z": 7,
      "name": "Rock_Basalt"
    },
    {
      "x": -8,
      "y": 5,
      "z": 7,
      "name": "Rock_Basalt"
    },
    {
      "x": -8,
      "y": 6,
      "z": 7,
      "name": "Rock_Basalt"
    },
    {
      "x": -8,
      "y": 7,
      "z": 7,
      "name": "Rock_Basalt"
    },
    {
      "x": -8,
      "y": 5,
      "z": 8,
      "name": "Rock_Basalt"
    },
    {
      "x": -7,
      "y": 11,
      "z": -10,
      "name": "Rock_Basalt"
    },
    {
      "x": -7,
      "y": 12,
      "z": -10,
      "name": "Rock_Basalt"
    },
    {
      "x": -7,
      "y": 13,
      "z": -10,
      "name": "Rock_Basalt"
    },
    {
      "x": -7,
      "y": 8,
      "z": -9,
      "name": "Rock_Basalt"
    },
    {
      "x": -7,
      "y": 9,
      "z": -9,
      "name": "Rock_Basalt"
    },
    {
      "x": -7,
      "y": 10,
      "z": -9,
      "name": "Rock_Basalt"
    },
    {
      "x": -7,
      "y": 11,
      "z": -9,
      "name": "Rock_Basalt"
    },
    {
      "x": -7,
      "y": 12,
      "z": -9,
      "name": "Rock_Basalt"
    },
    {
      "x": -7,
      "y": 13,
      "z": -9,
      "name": "Rock_Basalt"
    },
    {
      "x": -7,
      "y": 14,
      "z": -9,
      "name": "Rock_Basalt"
    },
    {
      "x": -7,
      "y": 15,
      "z": -9,
      "name": "Rock_Basalt"
    },
    {
      "x": -7,
      "y": 16,
      "z": -9,
      "name": "Soil_Dirt_Burnt"
    },
    {
      "x": -7,
      "y": 17,
      "z": -9,
      "name": "Soil_Dirt_Burnt"
    },
    {
      "x": -7,
      "y": 6,
      "z": -8,
      "name": "Rock_Basalt"
    },
    {
      "x": -7,
      "y": 7,
      "z": -8,
      "name": "Rock_Basalt"
    },
    {
      "x": -7,
      "y": 8,
      "z": -8,
      "name": "Rock_Basalt"
    },
    {
      "x": -7,
      "y": 9,
      "z": -8,
      "name": "Rock_Basalt"
    },
    {
      "x": -7,
      "y": 10,
      "z": -8,
      "name": "Rock_Basalt"
    },
    {
      "x": -7,
      "y": 11,
      "z": -8,
      "name": "Rock_Basalt"
    },
    {
      "x": -7,
      "y": 12,
      "z": -8,
      "name": "Rock_Basalt"
    },
    {
      "x": -7,
      "y": 13,
      "z": -8,
      "name": "Rock_Basalt"
    },
    {
      "x": -7,
      "y": 14,
      "z": -8,
      "name": "Rock_Basalt"
    },
    {
      "x": -7,
      "y": 15,
      "z": -8,
      "name": "Rock_Basalt"
    },
    {
      "x": -7,
      "y": 16,
      "z": -8,
      "name": "Rock_Basalt"
    },
    {
      "x": -7,
      "y": 17,
      "z": -8,
      "name": "Rock_Basalt"
    },
    {
      "x": -7,
      "y": 18,
      "z": -8,
      "name": "Soil_Dirt_Burnt"
    },
    {
      "x": -7,
      "y": 19,
      "z": -8,
      "name": "Soil_Dirt_Burnt"
    },
    {
      "x": -7,
      "y": 5,
      "z": -7,
      "name": "Rock_Basalt"
    },
    {
      "x": -7,
      "y": 6,
      "z": -7,
      "name": "Rock_Basalt"
    },
    {
      "x": -7,
      "y": 7,
      "z": -7,
      "name": "Rock_Basalt"
    },
    {
      "x": -7,
      "y": 8,
      "z": -7,
      "name": "Rock_Basalt"
    },
    {
      "x": -7,
      "y": 9,
      "z": -7,
      "name": "Rock_Basalt"
    },
    {
      "x": -7,
      "y": 10,
      "z": -7,
      "name": "Rock_Basalt"
    },
    {
      "x": -7,
      "y": 11,
      "z": -7,
      "name": "Rock_Basalt"
    },
    {
      "x": -7,
      "y": 12,
      "z": -7,
      "name": "Rock_Basalt"
    },
    {
      "x": -7,
      "y": 13,
      "z": -7,
      "name": "Rock_Basalt"
    },
    {
      "x": -7,
      "y": 14,
      "z": -7,
      "name": "Rock_Basalt"
    },
    {
      "x": -7,
      "y": 15,
      "z": -7,
      "name": "Rock_Basalt"
    },
    {
      "x": -7,
      "y": 16,
      "z": -7,
      "name": "Rock_Basalt"
    },
    {
      "x": -7,
      "y": 17,
      "z": -7,
      "name": "Rock_Basalt"
    },
    {
      "x": -7,
      "y": 18,
      "z": -7,
      "name": "Rock_Basalt"
    },
    {
      "x": -7,
      "y": 19,
      "z": -7,
      "name": "Soil_Dirt_Burnt"
    },
    {
      "x": -7,
      "y": 20,
      "z": -7,
      "name": "Soil_Grass_Burnt"
    },
    {
      "x": -7,
      "y": 6,
      "z": -6,
      "name": "Rock_Basalt"
    },
    {
      "x": -7,
      "y": 7,
      "z": -6,
      "name": "Rock_Basalt"
    },
    {
      "x": -7,
      "y": 8,
      "z": -6,
      "name": "Rock_Basalt"
    },
    {
      "x": -7,
      "y": 9,
      "z": -6,
      "name": "Rock_Basalt"
    },
    {
      "x": -7,
      "y": 10,
      "z": -6,
      "name": "Rock_Basalt"
    },
    {
      "x": -7,
      "y": 11,
      "z": -6,
      "name": "Rock_Basalt"
    },
    {
      "x": -7,
      "y": 12,
      "z": -6,
      "name": "Rock_Basalt"
    },
    {
      "x": -7,
      "y": 13,
      "z": -6,
      "name": "Rock_Basalt"
    },
    {
      "x": -7,
      "y": 14,
      "z": -6,
      "name": "Rock_Basalt"
    },
    {
      "x": -7,
      "y": 15,
      "z": -6,
      "name": "Rock_Basalt"
    },
    {
      "x": -7,
      "y": 16,
      "z": -6,
      "name": "Rock_Basalt"
    },
    {
      "x": -7,
      "y": 17,
      "z": -6,
      "name": "Rock_Basalt"
    },
    {
      "x": -7,
      "y": 18,
      "z": -6,
      "name": "Rock_Basalt"
    },
    {
      "x": -7,
      "y": 19,
      "z": -6,
      "name": "Soil_Dirt_Burnt"
    },
    {
      "x": -7,
      "y": 20,
      "z": -6,
      "name": "Soil_Grass_Burnt"
    },
    {
      "x": -7,
      "y": 6,
      "z": -5,
      "name": "Rock_Basalt"
    },
    {
      "x": -7,
      "y": 7,
      "z": -5,
      "name": "Rock_Basalt"
    },
    {
      "x": -7,
      "y": 8,
      "z": -5,
      "name": "Rock_Basalt"
    },
    {
      "x": -7,
      "y": 9,
      "z": -5,
      "name": "Rock_Basalt"
    },
    {
      "x": -7,
      "y": 10,
      "z": -5,
      "name": "Rock_Basalt"
    },
    {
      "x": -7,
      "y": 11,
      "z": -5,
      "name": "Rock_Basalt"
    },
    {
      "x": -7,
      "y": 12,
      "z": -5,
      "name": "Rock_Basalt"
    },
    {
      "x": -7,
      "y": 13,
      "z": -5,
      "name": "Rock_Basalt"
    },
    {
      "x": -7,
      "y": 14,
      "z": -5,
      "name": "Rock_Basalt"
    },
    {
      "x": -7,
      "y": 15,
      "z": -5,
      "name": "Rock_Basalt"
    },
    {
      "x": -7,
      "y": 16,
      "z": -5,
      "name": "Rock_Basalt"
    },
    {
      "x": -7,
      "y": 17,
      "z": -5,
      "name": "Rock_Basalt"
    },
    {
      "x": -7,
      "y": 18,
      "z": -5,
      "name": "Rock_Basalt"
    },
    {
      "x": -7,
      "y": 19,
      "z": -5,
      "name": "Soil_Dirt_Burnt"
    },
    {
      "x": -7,
      "y": 20,
      "z": -5,
      "name": "Soil_Grass_Burnt"
    },
    {
      "x": -7,
      "y": 4,
      "z": -4,
      "name": "Rock_Basalt"
    },
    {
      "x": -7,
      "y": 5,
      "z": -4,
      "name": "Rock_Basalt"
    },
    {
      "x": -7,
      "y": 6,
      "z": -4,
      "name": "Rock_Basalt"
    },
    {
      "x": -7,
      "y": 7,
      "z": -4,
      "name": "Rock_Basalt"
    },
    {
      "x": -7,
      "y": 8,
      "z": -4,
      "name": "Rock_Basalt"
    },
    {
      "x": -7,
      "y": 9,
      "z": -4,
      "name": "Rubble_Basalt"
    },
    {
      "x": -7,
      "y": 11,
      "z": -4,
      "name": "Rock_Basalt"
    },
    {
      "x": -7,
      "y": 12,
      "z": -4,
      "name": "Rock_Basalt"
    },
    {
      "x": -7,
      "y": 13,
      "z": -4,
      "name": "Rock_Basalt"
    },
    {
      "x": -7,
      "y": 14,
      "z": -4,
      "name": "Rock_Basalt"
    },
    {
      "x": -7,
      "y": 15,
      "z": -4,
      "name": "Rock_Basalt"
    },
    {
      "x": -7,
      "y": 16,
      "z": -4,
      "name": "Rock_Basalt"
    },
    {
      "x": -7,
      "y": 17,
      "z": -4,
      "name": "Rock_Basalt"
    },
    {
      "x": -7,
      "y": 18,
      "z": -4,
      "name": "Rock_Basalt"
    },
    {
      "x": -7,
      "y": 19,
      "z": -4,
      "name": "Soil_Dirt_Burnt"
    },
    {
      "x": -7,
      "y": 20,
      "z": -4,
      "name": "Soil_Grass_Burnt"
    },
    {
      "x": -7,
      "y": 2,
      "z": -3,
      "name": "Rock_Basalt"
    },
    {
      "x": -7,
      "y": 3,
      "z": -3,
      "name": "Rock_Basalt"
    },
    {
      "x": -7,
      "y": 4,
      "z": -3,
      "name": "Rock_Basalt"
    },
    {
      "x": -7,
      "y": 5,
      "z": -3,
      "name": "Rock_Basalt"
    },
    {
      "x": -7,
      "y": 6,
      "z": -3,
      "name": "Rock_Basalt"
    },
    {
      "x": -7,
      "y": 7,
      "z": -3,
      "name": "Rock_Basalt"
    },
    {
      "x": -7,
      "y": 8,
      "z": -3,
      "name": "Rock_Basalt"
    },
    {
      "x": -7,
      "y": 13,
      "z": -3,
      "name": "Rock_Basalt"
    },
    {
      "x": -7,
      "y": 14,
      "z": -3,
      "name": "Rock_Basalt"
    },
    {
      "x": -7,
      "y": 15,
      "z": -3,
      "name": "Rock_Basalt"
    },
    {
      "x": -7,
      "y": 16,
      "z": -3,
      "name": "Rock_Basalt"
    },
    {
      "x": -7,
      "y": 17,
      "z": -3,
      "name": "Rock_Basalt"
    },
    {
      "x": -7,
      "y": 18,
      "z": -3,
      "name": "Rock_Basalt"
    },
    {
      "x": -7,
      "y": 19,
      "z": -3,
      "name": "Soil_Dirt_Burnt"
    },
    {
      "x": -7,
      "y": 20,
      "z": -3,
      "name": "Soil_Grass_Burnt"
    },
    {
      "x": -7,
      "y": 2,
      "z": -2,
      "name": "Rock_Basalt"
    },
    {
      "x": -7,
      "y": 3,
      "z": -2,
      "name": "Rock_Basalt"
    },
    {
      "x": -7,
      "y": 4,
      "z": -2,
      "name": "Rock_Basalt"
    },
    {
      "x": -7,
      "y": 5,
      "z": -2,
      "name": "Rock_Basalt"
    },
    {
      "x": -7,
      "y": 6,
      "z": -2,
      "name": "Rock_Basalt"
    },
    {
      "x": -7,
      "y": 7,
      "z": -2,
      "name": "Rock_Basalt"
    },
    {
      "x": -7,
      "y": 8,
      "z": -2,
      "name": "Rock_Basalt"
    },
    {
      "x": -7,
      "y": 15,
      "z": -2,
      "name": "Rock_Basalt"
    },
    {
      "x": -7,
      "y": 16,
      "z": -2,
      "name": "Rock_Basalt"
    },
    {
      "x": -7,
      "y": 17,
      "z": -2,
      "name": "Rock_Basalt"
    },
    {
      "x": -7,
      "y": 18,
      "z": -2,
      "name": "Soil_Dirt_Burnt"
    },
    {
      "x": -7,
      "y": 19,
      "z": -2,
      "name": "Soil_Grass_Burnt"
    },
    {
      "x": -7,
      "y": 1,
      "z": -1,
      "name": "Rock_Basalt"
    },
    {
      "x": -7,
      "y": 2,
      "z": -1,
      "name": "Rock_Basalt"
    },
    {
      "x": -7,
      "y": 3,
      "z": -1,
      "name": "Rock_Basalt"
    },
    {
      "x": -7,
      "y": 4,
      "z": -1,
      "name": "Rock_Basalt"
    },
    {
      "x": -7,
      "y": 5,
      "z": -1,
      "name": "Rock_Basalt"
    },
    {
      "x": -7,
      "y": 6,
      "z": -1,
      "name": "Rock_Basalt"
    },
    {
      "x": -7,
      "y": 7,
      "z": -1,
      "name": "Rock_Basalt"
    },
    {
      "x": -7,
      "y": 8,
      "z": -1,
      "name": "Rock_Basalt"
    },
    {
      "x": -7,
      "y": 9,
      "z": -1,
      "name": "Rock_Basalt"
    },
    {
      "x": -7,
      "y": 10,
      "z": -1,
      "name": "Rock_Basalt"
    },
    {
      "x": -7,
      "y": 11,
      "z": -1,
      "name": "Rock_Basalt"
    },
    {
      "x": -7,
      "y": 17,
      "z": -1,
      "name": "Rock_Basalt"
    },
    {
      "x": -7,
      "y": 18,
      "z": -1,
      "name": "Rock_Basalt"
    },
    {
      "x": -7,
      "y": 19,
      "z": -1,
      "name": "Rock_Basalt"
    },
    {
      "x": -7,
      "y": 0,
      "z": 0,
      "name": "Rock_Basalt"
    },
    {
      "x": -7,
      "y": 1,
      "z": 0,
      "name": "Rock_Basalt"
    },
    {
      "x": -7,
      "y": 2,
      "z": 0,
      "name": "Rock_Basalt"
    },
    {
      "x": -7,
      "y": 3,
      "z": 0,
      "name": "Rock_Basalt"
    },
    {
      "x": -7,
      "y": 4,
      "z": 0,
      "name": "Rock_Basalt"
    },
    {
      "x": -7,
      "y": 5,
      "z": 0,
      "name": "Rock_Basalt"
    },
    {
      "x": -7,
      "y": 6,
      "z": 0,
      "name": "Rock_Basalt"
    },
    {
      "x": -7,
      "y": 7,
      "z": 0,
      "name": "Rock_Basalt"
    },
    {
      "x": -7,
      "y": 8,
      "z": 0,
      "name": "Rock_Basalt"
    },
    {
      "x": -7,
      "y": 9,
      "z": 0,
      "name": "Rock_Basalt"
    },
    {
      "x": -7,
      "y": 10,
      "z": 0,
      "name": "Rock_Basalt"
    },
    {
      "x": -7,
      "y": 11,
      "z": 0,
      "name": "Rock_Basalt"
    },
    {
      "x": -7,
      "y": 12,
      "z": 0,
      "name": "Rock_Basalt"
    },
    {
      "x": -7,
      "y": 13,
      "z": 0,
      "name": "Rock_Basalt"
    },
    {
      "x": -7,
      "y": 14,
      "z": 0,
      "name": "Plant_Bramble_Moss_Twisted"
    },
    {
      "x": -7,
      "y": 0,
      "z": 1,
      "name": "Rock_Basalt"
    },
    {
      "x": -7,
      "y": 1,
      "z": 1,
      "name": "Rock_Basalt"
    },
    {
      "x": -7,
      "y": 2,
      "z": 1,
      "name": "Rock_Basalt"
    },
    {
      "x": -7,
      "y": 3,
      "z": 1,
      "name": "Rock_Basalt"
    },
    {
      "x": -7,
      "y": 4,
      "z": 1,
      "name": "Rock_Basalt"
    },
    {
      "x": -7,
      "y": 5,
      "z": 1,
      "name": "Rock_Basalt"
    },
    {
      "x": -7,
      "y": 6,
      "z": 1,
      "name": "Rock_Basalt"
    },
    {
      "x": -7,
      "y": 7,
      "z": 1,
      "name": "Rock_Basalt"
    },
    {
      "x": -7,
      "y": 8,
      "z": 1,
      "name": "Rock_Basalt"
    },
    {
      "x": -7,
      "y": 9,
      "z": 1,
      "name": "Rock_Basalt"
    },
    {
      "x": -7,
      "y": 10,
      "z": 1,
      "name": "Rock_Basalt"
    },
    {
      "x": -7,
      "y": 11,
      "z": 1,
      "name": "Rock_Basalt"
    },
    {
      "x": -7,
      "y": 12,
      "z": 1,
      "name": "Rock_Basalt"
    },
    {
      "x": -7,
      "y": 13,
      "z": 1,
      "name": "Plant_Moss_Block_Green_Dark"
    },
    {
      "x": -7,
      "y": 14,
      "z": 1,
      "name": "Plant_Moss_Block_Green_Dark"
    },
    {
      "x": -7,
      "y": 15,
      "z": 1,
      "name": "Plant_Bramble_Moss_Twisted"
    },
    {
      "x": -7,
      "y": 0,
      "z": 2,
      "name": "Rock_Basalt"
    },
    {
      "x": -7,
      "y": 1,
      "z": 2,
      "name": "Rock_Basalt"
    },
    {
      "x": -7,
      "y": 2,
      "z": 2,
      "name": "Rock_Basalt"
    },
    {
      "x": -7,
      "y": 3,
      "z": 2,
      "name": "Rock_Basalt"
    },
    {
      "x": -7,
      "y": 4,
      "z": 2,
      "name": "Rock_Basalt"
    },
    {
      "x": -7,
      "y": 5,
      "z": 2,
      "name": "Rock_Basalt"
    },
    {
      "x": -7,
      "y": 6,
      "z": 2,
      "name": "Rock_Basalt"
    },
    {
      "x": -7,
      "y": 7,
      "z": 2,
      "name": "Rock_Basalt"
    },
    {
      "x": -7,
      "y": 8,
      "z": 2,
      "name": "Rock_Basalt"
    },
    {
      "x": -7,
      "y": 9,
      "z": 2,
      "name": "Rock_Basalt"
    },
    {
      "x": -7,
      "y": 10,
      "z": 2,
      "name": "Rock_Basalt"
    },
    {
      "x": -7,
      "y": 11,
      "z": 2,
      "name": "Rock_Basalt"
    },
    {
      "x": -7,
      "y": 12,
      "z": 2,
      "name": "Rock_Basalt"
    },
    {
      "x": -7,
      "y": 13,
      "z": 2,
      "name": "Rock_Basalt"
    },
    {
      "x": -7,
      "y": 14,
      "z": 2,
      "name": "Rock_Basalt"
    },
    {
      "x": -7,
      "y": 15,
      "z": 2,
      "name": "Rock_Basalt"
    },
    {
      "x": -7,
      "y": 16,
      "z": 2,
      "name": "Rock_Basalt"
    },
    {
      "x": -7,
      "y": 17,
      "z": 2,
      "name": "Rock_Basalt"
    },
    {
      "x": -7,
      "y": 18,
      "z": 2,
      "name": "Rock_Basalt"
    },
    {
      "x": -7,
      "y": 19,
      "z": 2,
      "name": "Rock_Basalt"
    },
    {
      "x": -7,
      "y": 20,
      "z": 2,
      "name": "Rock_Basalt"
    },
    {
      "x": -7,
      "y": 21,
      "z": 2,
      "name": "Rock_Basalt"
    },
    {
      "x": -7,
      "y": 22,
      "z": 2,
      "name": "Rubble_Basalt"
    },
    {
      "x": -7,
      "y": 0,
      "z": 3,
      "name": "Rock_Basalt"
    },
    {
      "x": -7,
      "y": 1,
      "z": 3,
      "name": "Rock_Basalt"
    },
    {
      "x": -7,
      "y": 2,
      "z": 3,
      "name": "Rock_Basalt"
    },
    {
      "x": -7,
      "y": 3,
      "z": 3,
      "name": "Rock_Basalt"
    },
    {
      "x": -7,
      "y": 4,
      "z": 3,
      "name": "Rock_Basalt"
    },
    {
      "x": -7,
      "y": 5,
      "z": 3,
      "name": "Rock_Basalt"
    },
    {
      "x": -7,
      "y": 6,
      "z": 3,
      "name": "Rock_Basalt"
    },
    {
      "x": -7,
      "y": 7,
      "z": 3,
      "name": "Rock_Basalt"
    },
    {
      "x": -7,
      "y": 8,
      "z": 3,
      "name": "Rock_Basalt"
    },
    {
      "x": -7,
      "y": 9,
      "z": 3,
      "name": "Rock_Basalt"
    },
    {
      "x": -7,
      "y": 10,
      "z": 3,
      "name": "Rock_Basalt"
    },
    {
      "x": -7,
      "y": 11,
      "z": 3,
      "name": "Rock_Basalt"
    },
    {
      "x": -7,
      "y": 12,
      "z": 3,
      "name": "Rock_Basalt"
    },
    {
      "x": -7,
      "y": 13,
      "z": 3,
      "name": "Rock_Basalt"
    },
    {
      "x": -7,
      "y": 14,
      "z": 3,
      "name": "Rock_Basalt"
    },
    {
      "x": -7,
      "y": 15,
      "z": 3,
      "name": "Rock_Basalt"
    },
    {
      "x": -7,
      "y": 16,
      "z": 3,
      "name": "Rock_Basalt"
    },
    {
      "x": -7,
      "y": 17,
      "z": 3,
      "name": "Rock_Basalt"
    },
    {
      "x": -7,
      "y": 18,
      "z": 3,
      "name": "Rock_Basalt"
    },
    {
      "x": -7,
      "y": 19,
      "z": 3,
      "name": "Rock_Basalt"
    },
    {
      "x": -7,
      "y": 20,
      "z": 3,
      "name": "Rock_Basalt"
    },
    {
      "x": -7,
      "y": 21,
      "z": 3,
      "name": "Rock_Basalt"
    },
    {
      "x": -7,
      "y": 22,
      "z": 3,
      "name": "Rock_Basalt"
    },
    {
      "x": -7,
      "y": 0,
      "z": 4,
      "name": "Rock_Basalt"
    },
    {
      "x": -7,
      "y": 1,
      "z": 4,
      "name": "Rock_Basalt"
    },
    {
      "x": -7,
      "y": 2,
      "z": 4,
      "name": "Rock_Basalt"
    },
    {
      "x": -7,
      "y": 3,
      "z": 4,
      "name": "Rock_Basalt"
    },
    {
      "x": -7,
      "y": 4,
      "z": 4,
      "name": "Rock_Basalt"
    },
    {
      "x": -7,
      "y": 5,
      "z": 4,
      "name": "Rock_Basalt"
    },
    {
      "x": -7,
      "y": 6,
      "z": 4,
      "name": "Rock_Basalt"
    },
    {
      "x": -7,
      "y": 7,
      "z": 4,
      "name": "Rock_Basalt"
    },
    {
      "x": -7,
      "y": 8,
      "z": 4,
      "name": "Rock_Basalt"
    },
    {
      "x": -7,
      "y": 9,
      "z": 4,
      "name": "Rock_Basalt"
    },
    {
      "x": -7,
      "y": 10,
      "z": 4,
      "name": "Rock_Basalt"
    },
    {
      "x": -7,
      "y": 11,
      "z": 4,
      "name": "Rock_Basalt"
    },
    {
      "x": -7,
      "y": 12,
      "z": 4,
      "name": "Rock_Basalt"
    },
    {
      "x": -7,
      "y": 13,
      "z": 4,
      "name": "Rock_Basalt"
    },
    {
      "x": -7,
      "y": 14,
      "z": 4,
      "name": "Rock_Basalt_Stalactite_Small"
    },
    {
      "x": -7,
      "y": 18,
      "z": 4,
      "name": "Rock_Basalt"
    },
    {
      "x": -7,
      "y": 19,
      "z": 4,
      "name": "Rock_Basalt"
    },
    {
      "x": -7,
      "y": 20,
      "z": 4,
      "name": "Rock_Basalt"
    },
    {
      "x": -7,
      "y": 21,
      "z": 4,
      "name": "Rock_Basalt"
    },
    {
      "x": -7,
      "y": 22,
      "z": 4,
      "name": "Rock_Basalt"
    },
    {
      "x": -7,
      "y": 1,
      "z": 5,
      "name": "Rock_Basalt"
    },
    {
      "x": -7,
      "y": 2,
      "z": 5,
      "name": "Rock_Basalt"
    },
    {
      "x": -7,
      "y": 3,
      "z": 5,
      "name": "Rock_Basalt"
    },
    {
      "x": -7,
      "y": 4,
      "z": 5,
      "name": "Rock_Basalt"
    },
    {
      "x": -7,
      "y": 5,
      "z": 5,
      "name": "Rock_Basalt"
    },
    {
      "x": -7,
      "y": 6,
      "z": 5,
      "name": "Rock_Basalt"
    },
    {
      "x": -7,
      "y": 7,
      "z": 5,
      "name": "Rock_Basalt"
    },
    {
      "x": -7,
      "y": 8,
      "z": 5,
      "name": "Rock_Basalt"
    },
    {
      "x": -7,
      "y": 9,
      "z": 5,
      "name": "Rock_Basalt"
    },
    {
      "x": -7,
      "y": 10,
      "z": 5,
      "name": "Rock_Basalt"
    },
    {
      "x": -7,
      "y": 11,
      "z": 5,
      "name": "Rock_Basalt"
    },
    {
      "x": -7,
      "y": 12,
      "z": 5,
      "name": "Rock_Basalt"
    },
    {
      "x": -7,
      "y": 13,
      "z": 5,
      "name": "Rock_Basalt"
    },
    {
      "x": -7,
      "y": 14,
      "z": 5,
      "name": "Rock_Basalt"
    },
    {
      "x": -7,
      "y": 1,
      "z": 6,
      "name": "Rock_Basalt"
    },
    {
      "x": -7,
      "y": 2,
      "z": 6,
      "name": "Rock_Basalt"
    },
    {
      "x": -7,
      "y": 3,
      "z": 6,
      "name": "Rock_Basalt"
    },
    {
      "x": -7,
      "y": 4,
      "z": 6,
      "name": "Rock_Basalt"
    },
    {
      "x": -7,
      "y": 5,
      "z": 6,
      "name": "Rock_Basalt"
    },
    {
      "x": -7,
      "y": 6,
      "z": 6,
      "name": "Rock_Basalt"
    },
    {
      "x": -7,
      "y": 7,
      "z": 6,
      "name": "Rock_Basalt"
    },
    {
      "x": -7,
      "y": 8,
      "z": 6,
      "name": "Rock_Basalt"
    },
    {
      "x": -7,
      "y": 9,
      "z": 6,
      "name": "Rock_Basalt"
    },
    {
      "x": -7,
      "y": 10,
      "z": 6,
      "name": "Rock_Basalt"
    },
    {
      "x": -7,
      "y": 11,
      "z": 6,
      "name": "Rock_Basalt"
    },
    {
      "x": -7,
      "y": 12,
      "z": 6,
      "name": "Rock_Basalt"
    },
    {
      "x": -7,
      "y": 13,
      "z": 6,
      "name": "Rock_Basalt"
    },
    {
      "x": -7,
      "y": 14,
      "z": 6,
      "name": "Rock_Basalt"
    },
    {
      "x": -7,
      "y": 15,
      "z": 6,
      "name": "Rock_Basalt"
    },
    {
      "x": -7,
      "y": 16,
      "z": 6,
      "name": "Rock_Basalt"
    },
    {
      "x": -7,
      "y": 17,
      "z": 6,
      "name": "Rock_Basalt"
    },
    {
      "x": -7,
      "y": 2,
      "z": 7,
      "name": "Rock_Basalt"
    },
    {
      "x": -7,
      "y": 3,
      "z": 7,
      "name": "Rock_Basalt"
    },
    {
      "x": -7,
      "y": 4,
      "z": 7,
      "name": "Rock_Basalt"
    },
    {
      "x": -7,
      "y": 5,
      "z": 7,
      "name": "Rock_Basalt"
    },
    {
      "x": -7,
      "y": 6,
      "z": 7,
      "name": "Rock_Basalt"
    },
    {
      "x": -7,
      "y": 7,
      "z": 7,
      "name": "Rock_Basalt"
    },
    {
      "x": -7,
      "y": 11,
      "z": 7,
      "name": "Rock_Basalt"
    },
    {
      "x": -7,
      "y": 12,
      "z": 7,
      "name": "Rock_Basalt"
    },
    {
      "x": -7,
      "y": 13,
      "z": 7,
      "name": "Rock_Basalt"
    },
    {
      "x": -7,
      "y": 14,
      "z": 7,
      "name": "Rock_Basalt"
    },
    {
      "x": -7,
      "y": 15,
      "z": 7,
      "name": "Rock_Basalt"
    },
    {
      "x": -7,
      "y": 16,
      "z": 7,
      "name": "Rock_Basalt"
    },
    {
      "x": -7,
      "y": 17,
      "z": 7,
      "name": "Rock_Basalt"
    },
    {
      "x": -7,
      "y": 18,
      "z": 7,
      "name": "Rock_Basalt"
    },
    {
      "x": -7,
      "y": 19,
      "z": 7,
      "name": "Rock_Basalt"
    },
    {
      "x": -7,
      "y": 3,
      "z": 8,
      "name": "Rock_Basalt"
    },
    {
      "x": -7,
      "y": 4,
      "z": 8,
      "name": "Rock_Basalt"
    },
    {
      "x": -7,
      "y": 5,
      "z": 8,
      "name": "Rock_Basalt"
    },
    {
      "x": -7,
      "y": 6,
      "z": 8,
      "name": "Rock_Basalt"
    },
    {
      "x": -7,
      "y": 7,
      "z": 8,
      "name": "Rock_Basalt"
    },
    {
      "x": -7,
      "y": 8,
      "z": 8,
      "name": "Rock_Basalt"
    },
    {
      "x": -7,
      "y": 13,
      "z": 8,
      "name": "Rock_Basalt"
    },
    {
      "x": -7,
      "y": 14,
      "z": 8,
      "name": "Rock_Basalt"
    },
    {
      "x": -7,
      "y": 15,
      "z": 8,
      "name": "Rock_Basalt"
    },
    {
      "x": -7,
      "y": 16,
      "z": 8,
      "name": "Rock_Basalt"
    },
    {
      "x": -7,
      "y": 17,
      "z": 8,
      "name": "Rock_Basalt"
    },
    {
      "x": -7,
      "y": 18,
      "z": 8,
      "name": "Rock_Basalt"
    },
    {
      "x": -7,
      "y": 19,
      "z": 8,
      "name": "Rock_Basalt"
    },
    {
      "x": -7,
      "y": 20,
      "z": 8,
      "name": "Rock_Basalt"
    },
    {
      "x": -7,
      "y": 16,
      "z": 9,
      "name": "Rock_Basalt"
    },
    {
      "x": -7,
      "y": 17,
      "z": 9,
      "name": "Rock_Basalt"
    },
    {
      "x": -7,
      "y": 18,
      "z": 9,
      "name": "Rock_Basalt"
    },
    {
      "x": -7,
      "y": 19,
      "z": 9,
      "name": "Rock_Basalt"
    },
    {
      "x": -7,
      "y": 20,
      "z": 9,
      "name": "Rubble_Basalt_Medium"
    },
    {
      "x": -6,
      "y": 7,
      "z": -11,
      "name": "Rock_Basalt"
    },
    {
      "x": -6,
      "y": 8,
      "z": -11,
      "name": "Rock_Basalt"
    },
    {
      "x": -6,
      "y": 9,
      "z": -11,
      "name": "Rock_Basalt"
    },
    {
      "x": -6,
      "y": 10,
      "z": -11,
      "name": "Rock_Basalt"
    },
    {
      "x": -6,
      "y": 11,
      "z": -11,
      "name": "Rock_Basalt"
    },
    {
      "x": -6,
      "y": 12,
      "z": -11,
      "name": "Rock_Basalt"
    },
    {
      "x": -6,
      "y": 13,
      "z": -11,
      "name": "Rock_Basalt"
    },
    {
      "x": -6,
      "y": 14,
      "z": -11,
      "name": "Rock_Basalt"
    },
    {
      "x": -6,
      "y": 15,
      "z": -11,
      "name": "Rock_Basalt"
    },
    {
      "x": -6,
      "y": 16,
      "z": -11,
      "name": "Rock_Basalt"
    },
    {
      "x": -6,
      "y": 7,
      "z": -10,
      "name": "Rock_Basalt"
    },
    {
      "x": -6,
      "y": 8,
      "z": -10,
      "name": "Rock_Basalt"
    },
    {
      "x": -6,
      "y": 9,
      "z": -10,
      "name": "Rock_Basalt"
    },
    {
      "x": -6,
      "y": 10,
      "z": -10,
      "name": "Rock_Basalt"
    },
    {
      "x": -6,
      "y": 11,
      "z": -10,
      "name": "Rock_Basalt"
    },
    {
      "x": -6,
      "y": 12,
      "z": -10,
      "name": "Rock_Basalt"
    },
    {
      "x": -6,
      "y": 13,
      "z": -10,
      "name": "Rock_Basalt"
    },
    {
      "x": -6,
      "y": 14,
      "z": -10,
      "name": "Rock_Basalt"
    },
    {
      "x": -6,
      "y": 15,
      "z": -10,
      "name": "Rock_Basalt"
    },
    {
      "x": -6,
      "y": 16,
      "z": -10,
      "name": "Rock_Basalt"
    },
    {
      "x": -6,
      "y": 17,
      "z": -10,
      "name": "Rock_Basalt"
    },
    {
      "x": -6,
      "y": 18,
      "z": -10,
      "name": "Rock_Basalt"
    },
    {
      "x": -6,
      "y": 19,
      "z": -10,
      "name": "Rock_Basalt"
    },
    {
      "x": -6,
      "y": 5,
      "z": -9,
      "name": "Rock_Basalt"
    },
    {
      "x": -6,
      "y": 6,
      "z": -9,
      "name": "Rock_Basalt"
    },
    {
      "x": -6,
      "y": 7,
      "z": -9,
      "name": "Rock_Basalt"
    },
    {
      "x": -6,
      "y": 8,
      "z": -9,
      "name": "Rock_Basalt"
    },
    {
      "x": -6,
      "y": 9,
      "z": -9,
      "name": "Rock_Basalt"
    },
    {
      "x": -6,
      "y": 10,
      "z": -9,
      "name": "Rock_Basalt"
    },
    {
      "x": -6,
      "y": 11,
      "z": -9,
      "name": "Rock_Basalt"
    },
    {
      "x": -6,
      "y": 12,
      "z": -9,
      "name": "Rock_Basalt"
    },
    {
      "x": -6,
      "y": 13,
      "z": -9,
      "name": "Rock_Basalt"
    },
    {
      "x": -6,
      "y": 14,
      "z": -9,
      "name": "Rock_Basalt"
    },
    {
      "x": -6,
      "y": 15,
      "z": -9,
      "name": "Rock_Basalt"
    },
    {
      "x": -6,
      "y": 16,
      "z": -9,
      "name": "Rock_Basalt"
    },
    {
      "x": -6,
      "y": 17,
      "z": -9,
      "name": "Rock_Basalt"
    },
    {
      "x": -6,
      "y": 18,
      "z": -9,
      "name": "Rock_Basalt"
    },
    {
      "x": -6,
      "y": 19,
      "z": -9,
      "name": "Soil_Dirt_Burnt"
    },
    {
      "x": -6,
      "y": 20,
      "z": -9,
      "name": "Soil_Dirt_Burnt"
    },
    {
      "x": -6,
      "y": 4,
      "z": -8,
      "name": "Rock_Basalt"
    },
    {
      "x": -6,
      "y": 5,
      "z": -8,
      "name": "Rock_Basalt"
    },
    {
      "x": -6,
      "y": 6,
      "z": -8,
      "name": "Rock_Basalt"
    },
    {
      "x": -6,
      "y": 7,
      "z": -8,
      "name": "Rock_Basalt"
    },
    {
      "x": -6,
      "y": 8,
      "z": -8,
      "name": "Rock_Basalt"
    },
    {
      "x": -6,
      "y": 9,
      "z": -8,
      "name": "Rock_Basalt"
    },
    {
      "x": -6,
      "y": 10,
      "z": -8,
      "name": "Rock_Basalt"
    },
    {
      "x": -6,
      "y": 11,
      "z": -8,
      "name": "Rock_Basalt"
    },
    {
      "x": -6,
      "y": 12,
      "z": -8,
      "name": "Rock_Basalt"
    },
    {
      "x": -6,
      "y": 13,
      "z": -8,
      "name": "Rock_Basalt"
    },
    {
      "x": -6,
      "y": 14,
      "z": -8,
      "name": "Rock_Basalt"
    },
    {
      "x": -6,
      "y": 15,
      "z": -8,
      "name": "Rock_Basalt"
    },
    {
      "x": -6,
      "y": 16,
      "z": -8,
      "name": "Rock_Basalt"
    },
    {
      "x": -6,
      "y": 17,
      "z": -8,
      "name": "Rock_Basalt"
    },
    {
      "x": -6,
      "y": 18,
      "z": -8,
      "name": "Rock_Basalt"
    },
    {
      "x": -6,
      "y": 19,
      "z": -8,
      "name": "Soil_Dirt_Burnt"
    },
    {
      "x": -6,
      "y": 20,
      "z": -8,
      "name": "Soil_Grass_Burnt"
    },
    {
      "x": -6,
      "y": 4,
      "z": -7,
      "name": "Rock_Basalt"
    },
    {
      "x": -6,
      "y": 5,
      "z": -7,
      "name": "Rock_Basalt"
    },
    {
      "x": -6,
      "y": 6,
      "z": -7,
      "name": "Rock_Basalt"
    },
    {
      "x": -6,
      "y": 7,
      "z": -7,
      "name": "Rock_Basalt"
    },
    {
      "x": -6,
      "y": 8,
      "z": -7,
      "name": "Rock_Basalt"
    },
    {
      "x": -6,
      "y": 9,
      "z": -7,
      "name": "Rock_Basalt"
    },
    {
      "x": -6,
      "y": 10,
      "z": -7,
      "name": "Rock_Basalt"
    },
    {
      "x": -6,
      "y": 11,
      "z": -7,
      "name": "Rock_Basalt"
    },
    {
      "x": -6,
      "y": 12,
      "z": -7,
      "name": "Rock_Basalt"
    },
    {
      "x": -6,
      "y": 13,
      "z": -7,
      "name": "Rock_Basalt"
    },
    {
      "x": -6,
      "y": 14,
      "z": -7,
      "name": "Rock_Basalt"
    },
    {
      "x": -6,
      "y": 15,
      "z": -7,
      "name": "Rock_Basalt"
    },
    {
      "x": -6,
      "y": 16,
      "z": -7,
      "name": "Rock_Basalt"
    },
    {
      "x": -6,
      "y": 17,
      "z": -7,
      "name": "Rock_Basalt"
    },
    {
      "x": -6,
      "y": 18,
      "z": -7,
      "name": "Rock_Basalt"
    },
    {
      "x": -6,
      "y": 19,
      "z": -7,
      "name": "Soil_Dirt_Burnt"
    },
    {
      "x": -6,
      "y": 20,
      "z": -7,
      "name": "Soil_Grass_Burnt"
    },
    {
      "x": -6,
      "y": 4,
      "z": -6,
      "name": "Rock_Basalt"
    },
    {
      "x": -6,
      "y": 5,
      "z": -6,
      "name": "Rock_Basalt"
    },
    {
      "x": -6,
      "y": 6,
      "z": -6,
      "name": "Rock_Basalt"
    },
    {
      "x": -6,
      "y": 7,
      "z": -6,
      "name": "Rock_Basalt"
    },
    {
      "x": -6,
      "y": 8,
      "z": -6,
      "name": "Rock_Basalt"
    },
    {
      "x": -6,
      "y": 9,
      "z": -6,
      "name": "Rock_Basalt"
    },
    {
      "x": -6,
      "y": 10,
      "z": -6,
      "name": "Rock_Basalt"
    },
    {
      "x": -6,
      "y": 11,
      "z": -6,
      "name": "Rock_Basalt"
    },
    {
      "x": -6,
      "y": 12,
      "z": -6,
      "name": "Rock_Basalt"
    },
    {
      "x": -6,
      "y": 13,
      "z": -6,
      "name": "Rock_Basalt"
    },
    {
      "x": -6,
      "y": 14,
      "z": -6,
      "name": "Rock_Basalt"
    },
    {
      "x": -6,
      "y": 15,
      "z": -6,
      "name": "Rock_Basalt"
    },
    {
      "x": -6,
      "y": 16,
      "z": -6,
      "name": "Rock_Basalt"
    },
    {
      "x": -6,
      "y": 17,
      "z": -6,
      "name": "Rock_Basalt"
    },
    {
      "x": -6,
      "y": 18,
      "z": -6,
      "name": "Rock_Basalt"
    },
    {
      "x": -6,
      "y": 19,
      "z": -6,
      "name": "Soil_Dirt_Burnt"
    },
    {
      "x": -6,
      "y": 20,
      "z": -6,
      "name": "Soil_Grass_Burnt"
    },
    {
      "x": -6,
      "y": 3,
      "z": -5,
      "name": "Rock_Basalt"
    },
    {
      "x": -6,
      "y": 4,
      "z": -5,
      "name": "Rock_Basalt"
    },
    {
      "x": -6,
      "y": 5,
      "z": -5,
      "name": "Rock_Basalt"
    },
    {
      "x": -6,
      "y": 6,
      "z": -5,
      "name": "Rock_Basalt"
    },
    {
      "x": -6,
      "y": 7,
      "z": -5,
      "name": "Rock_Basalt"
    },
    {
      "x": -6,
      "y": 8,
      "z": -5,
      "name": "Rock_Basalt"
    },
    {
      "x": -6,
      "y": 9,
      "z": -5,
      "name": "Rock_Basalt"
    },
    {
      "x": -6,
      "y": 10,
      "z": -5,
      "name": "Rock_Basalt"
    },
    {
      "x": -6,
      "y": 11,
      "z": -5,
      "name": "Rock_Basalt"
    },
    {
      "x": -6,
      "y": 12,
      "z": -5,
      "name": "Rock_Basalt"
    },
    {
      "x": -6,
      "y": 13,
      "z": -5,
      "name": "Rock_Basalt"
    },
    {
      "x": -6,
      "y": 14,
      "z": -5,
      "name": "Rock_Basalt"
    },
    {
      "x": -6,
      "y": 15,
      "z": -5,
      "name": "Rock_Basalt"
    },
    {
      "x": -6,
      "y": 16,
      "z": -5,
      "name": "Rock_Basalt"
    },
    {
      "x": -6,
      "y": 17,
      "z": -5,
      "name": "Rock_Basalt"
    },
    {
      "x": -6,
      "y": 18,
      "z": -5,
      "name": "Rock_Basalt"
    },
    {
      "x": -6,
      "y": 19,
      "z": -5,
      "name": "Soil_Dirt_Burnt"
    },
    {
      "x": -6,
      "y": 20,
      "z": -5,
      "name": "Soil_Grass_Burnt"
    },
    {
      "x": -6,
      "y": 2,
      "z": -4,
      "name": "Rock_Basalt"
    },
    {
      "x": -6,
      "y": 3,
      "z": -4,
      "name": "Rock_Basalt"
    },
    {
      "x": -6,
      "y": 4,
      "z": -4,
      "name": "Rock_Basalt"
    },
    {
      "x": -6,
      "y": 5,
      "z": -4,
      "name": "Rock_Basalt"
    },
    {
      "x": -6,
      "y": 6,
      "z": -4,
      "name": "Rock_Basalt"
    },
    {
      "x": -6,
      "y": 7,
      "z": -4,
      "name": "Rock_Basalt"
    },
    {
      "x": -6,
      "y": 8,
      "z": -4,
      "name": "Rock_Basalt"
    },
    {
      "x": -6,
      "y": 9,
      "z": -4,
      "name": "Rock_Basalt"
    },
    {
      "x": -6,
      "y": 10,
      "z": -4,
      "name": "Rock_Basalt"
    },
    {
      "x": -6,
      "y": 11,
      "z": -4,
      "name": "Rock_Basalt"
    },
    {
      "x": -6,
      "y": 12,
      "z": -4,
      "name": "Rock_Basalt"
    },
    {
      "x": -6,
      "y": 13,
      "z": -4,
      "name": "Rock_Basalt"
    },
    {
      "x": -6,
      "y": 14,
      "z": -4,
      "name": "Rock_Basalt"
    },
    {
      "x": -6,
      "y": 15,
      "z": -4,
      "name": "Rock_Basalt"
    },
    {
      "x": -6,
      "y": 16,
      "z": -4,
      "name": "Rock_Basalt"
    },
    {
      "x": -6,
      "y": 17,
      "z": -4,
      "name": "Rock_Basalt"
    },
    {
      "x": -6,
      "y": 18,
      "z": -4,
      "name": "Rock_Basalt"
    },
    {
      "x": -6,
      "y": 19,
      "z": -4,
      "name": "Soil_Dirt_Burnt"
    },
    {
      "x": -6,
      "y": 20,
      "z": -4,
      "name": "Soil_Grass_Burnt"
    },
    {
      "x": -6,
      "y": 2,
      "z": -3,
      "name": "Rock_Basalt"
    },
    {
      "x": -6,
      "y": 3,
      "z": -3,
      "name": "Rock_Basalt"
    },
    {
      "x": -6,
      "y": 4,
      "z": -3,
      "name": "Rock_Basalt"
    },
    {
      "x": -6,
      "y": 5,
      "z": -3,
      "name": "Rock_Basalt"
    },
    {
      "x": -6,
      "y": 6,
      "z": -3,
      "name": "Rock_Basalt"
    },
    {
      "x": -6,
      "y": 7,
      "z": -3,
      "name": "Rock_Basalt"
    },
    {
      "x": -6,
      "y": 8,
      "z": -3,
      "name": "Rock_Basalt"
    },
    {
      "x": -6,
      "y": 11,
      "z": -3,
      "name": "Rock_Basalt"
    },
    {
      "x": -6,
      "y": 12,
      "z": -3,
      "name": "Rock_Basalt"
    },
    {
      "x": -6,
      "y": 13,
      "z": -3,
      "name": "Rock_Basalt"
    },
    {
      "x": -6,
      "y": 14,
      "z": -3,
      "name": "Rock_Basalt"
    },
    {
      "x": -6,
      "y": 15,
      "z": -3,
      "name": "Rock_Basalt"
    },
    {
      "x": -6,
      "y": 16,
      "z": -3,
      "name": "Rock_Basalt"
    },
    {
      "x": -6,
      "y": 17,
      "z": -3,
      "name": "Rock_Basalt"
    },
    {
      "x": -6,
      "y": 18,
      "z": -3,
      "name": "Rock_Basalt"
    },
    {
      "x": -6,
      "y": 19,
      "z": -3,
      "name": "Soil_Dirt_Burnt"
    },
    {
      "x": -6,
      "y": 20,
      "z": -3,
      "name": "Soil_Grass_Burnt"
    },
    {
      "x": -6,
      "y": 1,
      "z": -2,
      "name": "Rock_Basalt"
    },
    {
      "x": -6,
      "y": 2,
      "z": -2,
      "name": "Rock_Basalt"
    },
    {
      "x": -6,
      "y": 3,
      "z": -2,
      "name": "Rock_Basalt"
    },
    {
      "x": -6,
      "y": 4,
      "z": -2,
      "name": "Rock_Basalt"
    },
    {
      "x": -6,
      "y": 5,
      "z": -2,
      "name": "Rock_Basalt"
    },
    {
      "x": -6,
      "y": 6,
      "z": -2,
      "name": "Rock_Basalt"
    },
    {
      "x": -6,
      "y": 7,
      "z": -2,
      "name": "Rock_Basalt"
    },
    {
      "x": -6,
      "y": 8,
      "z": -2,
      "name": "Rock_Basalt"
    },
    {
      "x": -6,
      "y": 9,
      "z": -2,
      "name": "Rock_Basalt"
    },
    {
      "x": -6,
      "y": 10,
      "z": -2,
      "name": "Rock_Basalt"
    },
    {
      "x": -6,
      "y": 11,
      "z": -2,
      "name": "Rock_Basalt"
    },
    {
      "x": -6,
      "y": 12,
      "z": -2,
      "name": "Rock_Basalt"
    },
    {
      "x": -6,
      "y": 13,
      "z": -2,
      "name": "Rock_Basalt"
    },
    {
      "x": -6,
      "y": 14,
      "z": -2,
      "name": "Rock_Basalt"
    },
    {
      "x": -6,
      "y": 15,
      "z": -2,
      "name": "Rock_Basalt"
    },
    {
      "x": -6,
      "y": 16,
      "z": -2,
      "name": "Rock_Basalt"
    },
    {
      "x": -6,
      "y": 17,
      "z": -2,
      "name": "Rock_Basalt"
    },
    {
      "x": -6,
      "y": 18,
      "z": -2,
      "name": "Rock_Basalt"
    },
    {
      "x": -6,
      "y": 19,
      "z": -2,
      "name": "Soil_Dirt_Burnt"
    },
    {
      "x": -6,
      "y": 20,
      "z": -2,
      "name": "Soil_Grass_Burnt"
    },
    {
      "x": -6,
      "y": 21,
      "z": -2,
      "name": "Plant_Grass_Gnarled"
    },
    {
      "x": -6,
      "y": 1,
      "z": -1,
      "name": "Rock_Basalt"
    },
    {
      "x": -6,
      "y": 2,
      "z": -1,
      "name": "Rock_Basalt"
    },
    {
      "x": -6,
      "y": 3,
      "z": -1,
      "name": "Rock_Basalt"
    },
    {
      "x": -6,
      "y": 4,
      "z": -1,
      "name": "Rock_Basalt"
    },
    {
      "x": -6,
      "y": 5,
      "z": -1,
      "name": "Rock_Basalt"
    },
    {
      "x": -6,
      "y": 6,
      "z": -1,
      "name": "Rock_Basalt"
    },
    {
      "x": -6,
      "y": 7,
      "z": -1,
      "name": "Rock_Basalt"
    },
    {
      "x": -6,
      "y": 8,
      "z": -1,
      "name": "Rock_Basalt"
    },
    {
      "x": -6,
      "y": 9,
      "z": -1,
      "name": "Rock_Basalt"
    },
    {
      "x": -6,
      "y": 10,
      "z": -1,
      "name": "Rock_Basalt"
    },
    {
      "x": -6,
      "y": 11,
      "z": -1,
      "name": "Rock_Basalt"
    },
    {
      "x": -6,
      "y": 12,
      "z": -1,
      "name": "Rock_Basalt"
    },
    {
      "x": -6,
      "y": 13,
      "z": -1,
      "name": "Rock_Basalt"
    },
    {
      "x": -6,
      "y": 14,
      "z": -1,
      "name": "Rock_Basalt"
    },
    {
      "x": -6,
      "y": 15,
      "z": -1,
      "name": "Rock_Basalt"
    },
    {
      "x": -6,
      "y": 16,
      "z": -1,
      "name": "Rock_Basalt"
    },
    {
      "x": -6,
      "y": 17,
      "z": -1,
      "name": "Rock_Basalt"
    },
    {
      "x": -6,
      "y": 18,
      "z": -1,
      "name": "Rock_Basalt"
    },
    {
      "x": -6,
      "y": 19,
      "z": -1,
      "name": "Rock_Basalt"
    },
    {
      "x": -6,
      "y": 20,
      "z": -1,
      "name": "Soil_Grass_Burnt"
    },
    {
      "x": -6,
      "y": 0,
      "z": 0,
      "name": "Rock_Basalt"
    },
    {
      "x": -6,
      "y": 1,
      "z": 0,
      "name": "Rock_Basalt"
    },
    {
      "x": -6,
      "y": 2,
      "z": 0,
      "name": "Rock_Basalt"
    },
    {
      "x": -6,
      "y": 3,
      "z": 0,
      "name": "Rock_Basalt"
    },
    {
      "x": -6,
      "y": 4,
      "z": 0,
      "name": "Rock_Basalt"
    },
    {
      "x": -6,
      "y": 5,
      "z": 0,
      "name": "Rock_Basalt"
    },
    {
      "x": -6,
      "y": 6,
      "z": 0,
      "name": "Rock_Basalt"
    },
    {
      "x": -6,
      "y": 7,
      "z": 0,
      "name": "Rock_Basalt"
    },
    {
      "x": -6,
      "y": 8,
      "z": 0,
      "name": "Rock_Basalt"
    },
    {
      "x": -6,
      "y": 9,
      "z": 0,
      "name": "Rock_Basalt"
    },
    {
      "x": -6,
      "y": 10,
      "z": 0,
      "name": "Rock_Basalt"
    },
    {
      "x": -6,
      "y": 11,
      "z": 0,
      "name": "Rock_Basalt"
    },
    {
      "x": -6,
      "y": 12,
      "z": 0,
      "name": "Rock_Basalt"
    },
    {
      "x": -6,
      "y": 13,
      "z": 0,
      "name": "Rock_Basalt"
    },
    {
      "x": -6,
      "y": 14,
      "z": 0,
      "name": "Rock_Basalt"
    },
    {
      "x": -6,
      "y": 15,
      "z": 0,
      "name": "Rock_Basalt"
    },
    {
      "x": -6,
      "y": 0,
      "z": 1,
      "name": "Rock_Basalt"
    },
    {
      "x": -6,
      "y": 1,
      "z": 1,
      "name": "Rock_Basalt"
    },
    {
      "x": -6,
      "y": 2,
      "z": 1,
      "name": "Rock_Basalt"
    },
    {
      "x": -6,
      "y": 3,
      "z": 1,
      "name": "Rock_Basalt"
    },
    {
      "x": -6,
      "y": 4,
      "z": 1,
      "name": "Rock_Basalt"
    },
    {
      "x": -6,
      "y": 5,
      "z": 1,
      "name": "Rock_Basalt"
    },
    {
      "x": -6,
      "y": 6,
      "z": 1,
      "name": "Rock_Basalt"
    },
    {
      "x": -6,
      "y": 7,
      "z": 1,
      "name": "Rock_Basalt"
    },
    {
      "x": -6,
      "y": 8,
      "z": 1,
      "name": "Rock_Basalt"
    },
    {
      "x": -6,
      "y": 9,
      "z": 1,
      "name": "Rock_Basalt"
    },
    {
      "x": -6,
      "y": 10,
      "z": 1,
      "name": "Rock_Basalt"
    },
    {
      "x": -6,
      "y": 11,
      "z": 1,
      "name": "Rock_Basalt"
    },
    {
      "x": -6,
      "y": 12,
      "z": 1,
      "name": "Rock_Basalt"
    },
    {
      "x": -6,
      "y": 13,
      "z": 1,
      "name": "Rock_Basalt"
    },
    {
      "x": -6,
      "y": 14,
      "z": 1,
      "name": "Rock_Basalt"
    },
    {
      "x": -6,
      "y": 15,
      "z": 1,
      "name": "Rock_Basalt"
    },
    {
      "x": -6,
      "y": 16,
      "z": 1,
      "name": "Rock_Basalt"
    },
    {
      "x": -6,
      "y": 0,
      "z": 2,
      "name": "Rock_Basalt"
    },
    {
      "x": -6,
      "y": 1,
      "z": 2,
      "name": "Rock_Basalt"
    },
    {
      "x": -6,
      "y": 2,
      "z": 2,
      "name": "Rock_Basalt"
    },
    {
      "x": -6,
      "y": 3,
      "z": 2,
      "name": "Rock_Basalt"
    },
    {
      "x": -6,
      "y": 4,
      "z": 2,
      "name": "Rock_Basalt"
    },
    {
      "x": -6,
      "y": 5,
      "z": 2,
      "name": "Rock_Basalt"
    },
    {
      "x": -6,
      "y": 6,
      "z": 2,
      "name": "Rock_Basalt"
    },
    {
      "x": -6,
      "y": 7,
      "z": 2,
      "name": "Rock_Basalt"
    },
    {
      "x": -6,
      "y": 8,
      "z": 2,
      "name": "Rock_Basalt"
    },
    {
      "x": -6,
      "y": 9,
      "z": 2,
      "name": "Rock_Basalt"
    },
    {
      "x": -6,
      "y": 10,
      "z": 2,
      "name": "Rock_Basalt"
    },
    {
      "x": -6,
      "y": 11,
      "z": 2,
      "name": "Rock_Basalt"
    },
    {
      "x": -6,
      "y": 12,
      "z": 2,
      "name": "Rock_Basalt"
    },
    {
      "x": -6,
      "y": 13,
      "z": 2,
      "name": "Rock_Basalt"
    },
    {
      "x": -6,
      "y": 14,
      "z": 2,
      "name": "Rock_Basalt"
    },
    {
      "x": -6,
      "y": 15,
      "z": 2,
      "name": "Rock_Basalt"
    },
    {
      "x": -6,
      "y": 16,
      "z": 2,
      "name": "Rock_Basalt"
    },
    {
      "x": -6,
      "y": 17,
      "z": 2,
      "name": "Rock_Basalt"
    },
    {
      "x": -6,
      "y": 18,
      "z": 2,
      "name": "Rock_Basalt"
    },
    {
      "x": -6,
      "y": 19,
      "z": 2,
      "name": "Rock_Basalt"
    },
    {
      "x": -6,
      "y": 20,
      "z": 2,
      "name": "Rock_Basalt"
    },
    {
