{
  "version": 8,
  "blockIdVersion": 10,
  "anchorX": 9,
  "anchorY": 10,
  "anchorZ": 5,
  "blocks": [
    {
      "x": 9,
      "y": 16,
      "z": 4,
      "name": "Plant_Leaves_Bottle"
    },
    {
      "x": 9,
      "y": 8,
      "z": 5,
      "name": "Wood_Bottletree_Trunk"
    },
    {
      "x": 9,
      "y": 9,
      "z": 5,
      "name": "Wood_Bottletree_Trunk"
    },
    {
      "x": 9,
      "y": 10,
      "z": 5,
      "name": "Wood_Bottletree_Trunk"
    },
    {
      "x": 9,
      "y": 11,
      "z": 5,
      "name": "Wood_Bottletree_Trunk"
    },
    {
      "x": 9,
      "y": 12,
      "z": 5,
      "name": "Wood_Bottletree_Trunk"
    },
    {
      "x": 9,
      "y": 13,
      "z": 5,
      "name": "Wood_Bottletree_Trunk_Full"
    },
    {
      "x": 9,
      "y": 17,
      "z": 5,
      "name": "Plant_Leaves_Bottle"
    },
    {
      "x": 9,
      "y": 17,
      "z": 6,
      "name": "Plant_Leaves_Bottle"
    },
    {
      "x": 9,
      "y": 18,
      "z": 6,
      "name": "Plant_Leaves_Bottle"
    },
    {
      "x": 10,
      "y": 16,
      "z": 4,
      "name": "Plant_Leaves_Bottle"
    },
    {
      "x": 10,
      "y": 17,
      "z": 4,
      "name": "Plant_Leaves_Bottle"
    },
    {
      "x": 10,
      "y": 18,
      "z": 4,
      "name": "Plant_Leaves_Bottle"
    },
    {
      "x": 10,
      "y": 13,
      "z": 5,
      "name": "Wood_Bottletree_Trunk_Full"
    },
    {
      "x": 10,
      "y": 18,
      "z": 5,
      "name": "Plant_Leaves_Bottle"
    },
    {
      "x": 10,
      "y": 19,
      "z": 5,
      "name": "Plant_Leaves_Bottle"
    },
    {
      "x": 10,
      "y": 13,
      "z": 6,
      "name": "Wood_Bottletree_Trunk_Full"
    },
    {
      "x": 10,
      "y": 14,
      "z": 6,
      "name": "Wood_Bottletree_Trunk"
    },
    {
      "x": 10,
      "y": 15,
      "z": 6,
      "name": "Wood_Bottletree_Trunk_Full"
    },
    {
      "x": 10,
      "y": 16,
      "z": 6,
      "name": "Wood_Bottletree_Branch_Long"
    },
    {
      "x": 10,
      "y": 17,
      "z": 6,
      "name": "Wood_Bottletree_Branch_Long"
    },
    {
      "x": 10,
      "y": 18,
      "z": 6,
      "name": "Wood_Bottletree_Branch_Long"
    },
    {
      "x": 10,
      "y": 19,
      "z": 6,
      "name": "Plant_Leaves_Bottle"
    },
    {
      "x": 10,
      "y": 17,
      "z": 7,
      "name": "Plant_Leaves_Bottle"
    },
    {
      "x": 10,
      "y": 18,
      "z": 7,
      "name": "Plant_Leaves_Bottle"
    },
    {
      "x": 10,
      "y": 19,
      "z": 7,
      "name": "Plant_Leaves_Bottle"
    },
    {
      "x": 10,
      "y": 16,
      "z": 8,
      "name": "Plant_Leaves_Bottle"
    },
    {
      "x": 10,
      "y": 17,
      "z": 8,
      "name": "Plant_Leaves_Bottle"
    },
    {
      "x": 11,
      "y": 18,
      "z": 3,
      "name": "Plant_Leaves_Bottle"
    },
    {
      "x": 11,
      "y": 17,
      "z": 4,
      "name": "Plant_Leaves_Bottle"
    },
    {
      "x": 11,
      "y": 18,
      "z": 4,
      "name": "Plant_Leaves_Bottle"
    },
    {
      "x": 11,
      "y": 19,
      "z": 4,
      "name": "Plant_Leaves_Bottle"
    },
    {
      "x": 11,
      "y": 19,
      "z": 5,
      "name": "Plant_Leaves_Bottle"
    },
    {
      "x": 11,
      "y": 20,
      "z": 5,
      "name": "Plant_Leaves_Bottle"
    },
    {
      "x": 11,
      "y": 15,
      "z": 6,
      "name": "Wood_Bottletree_Trunk_Full"
    },
    {
      "x": 11,
      "y": 16,
      "z": 6,
      "name": "Wood_Bottletree_Trunk_Full"
    },
    {
      "x": 11,
      "y": 19,
      "z": 6,
      "name": "Plant_Leaves_Bottle"
    },
    {
      "x": 11,
      "y": 20,
      "z": 6,
      "name": "Plant_Leaves_Bottle"
    },
    {
      "x": 11,
      "y": 17,
      "z": 7,
      "name": "Plant_Leaves_Bottle"
    },
    {
      "x": 11,
      "y": 19,
      "z": 7,
      "name": "Plant_Leaves_Bottle"
    },
    {
      "x": 11,
      "y": 17,
      "z": 8,
      "name": "Plant_Leaves_Bottle"
    },
    {
      "x": 11,
      "y": 18,
      "z": 8,
      "name": "Plant_Leaves_Bottle"
    },
    {
      "x": 11,
      "y": 17,
      "z": 9,
      "name": "Plant_Leaves_Bottle"
    },
    {
      "x": 12,
      "y": 18,
      "z": 3,
      "name": "Plant_Leaves_Bottle"
    },
    {
      "x": 12,
      "y": 17,
      "z": 4,
      "name": "Plant_Leaves_Bottle"
    },
    {
      "x": 12,
      "y": 18,
      "z": 4,
      "name": "Plant_Leaves_Bottle"
    },
    {
      "x": 12,
      "y": 19,
      "z": 4,
      "name": "Plant_Leaves_Bottle"
    },
    {
      "x": 12,
      "y": 20,
      "z": 5,
      "name": "Plant_Leaves_Bottle"
    },
    {
      "x": 12,
      "y": 16,
      "z": 6,
      "name": "Wood_Bottletree_Trunk_Full"
    },
    {
      "x": 12,
      "y": 20,
      "z": 6,
      "name": "Plant_Leaves_Bottle"
    },
    {
      "x": 12,
      "y": 16,
      "z": 7,
      "name": "Wood_Bottletree_Branch_Corner"
    },
    {
      "x": 12,
      "y": 17,
      "z": 7,
      "name": "Wood_Bottletree_Branch_Long"
    },
    {
      "x": 12,
      "y": 18,
      "z": 7,
      "name": "Wood_Bottletree_Branch_Long"
    },
    {
      "x": 12,
      "y": 19,
      "z": 7,
      "name": "Wood_Bottletree_Branch_Long"
    },
    {
      "x": 12,
      "y": 20,
      "z": 7,
      "name": "Plant_Leaves_Bottle"
    },
    {
      "x": 12,
      "y": 17,
      "z": 8,
      "name": "Plant_Leaves_Bottle"
    },
    {
      "x": 12,
      "y": 18,
      "z": 8,
      "name": "Plant_Leaves_Bottle"
    },
    {
      "x": 12,
      "y": 19,
      "z": 8,
      "name": "Plant_Leaves_Bottle"
    },
    {
      "x": 12,
      "y": 17,
      "z": 9,
      "name": "Plant_Leaves_Bottle"
    },
    {
      "x": 13,
      "y": 18,
      "z": 3,
      "name": "Plant_Leaves_Bottle"
    },
    {
      "x": 13,
      "y": 19,
      "z": 3,
      "name": "Plant_Leaves_Bottle"
    },
    {
      "x": 13,
      "y": 18,
      "z": 4,
      "name": "Plant_Leaves_Bottle"
    },
    {
      "x": 13,
      "y": 19,
      "z": 4,
      "name": "Plant_Leaves_Bottle"
    },
    {
      "x": 13,
      "y": 20,
      "z": 4,
      "name": "Plant_Leaves_Bottle"
    },
    {
      "x": 13,
      "y": 16,
      "z": 6,
      "name": "Wood_Bottletree_Trunk_Full"
    },
    {
      "x": 13,
      "y": 17,
      "z": 6,
      "name": "Wood_Bottletree_Trunk_Full"
    },
    {
      "x": 13,
      "y": 21,
      "z": 6,
      "name": "Plant_Leaves_Bottle"
    },
    {
      "x": 13,
      "y": 20,
      "z": 7,
      "name": "Plant_Leaves_Bottle"
    },
    {
      "x": 13,
      "y": 17,
      "z": 8,
      "name": "Plant_Leaves_Bottle"
    },
    {
      "x": 13,
      "y": 18,
      "z": 8,
      "name": "Plant_Leaves_Bottle"
    },
    {
      "x": 13,
      "y": 19,
      "z": 8,
      "name": "Plant_Leaves_Bottle"
    },
    {
      "x": 13,
      "y": 20,
      "z": 8,
      "name": "Plant_Leaves_Bottle"
    },
    {
      "x": 13,
      "y": 17,
      "z": 9,
      "name": "Plant_Leaves_Bottle"
    },
    {
      "x": 14,
      "y": 18,
      "z": 3,
      "name": "Plant_Leaves_Bottle"
    },
    {
      "x": 14,
      "y": 19,
      "z": 3,
      "name": "Plant_Leaves_Bottle"
    },
    {
      "x": 14,
      "y": 19,
      "z": 4,
      "name": "Plant_Leaves_Bottle"
    },
    {
      "x": 14,
      "y": 20,
      "z": 4,
      "name": "Plant_Leaves_Bottle"
    },
    {
      "x": 14,
      "y": 19,
      "z": 5,
      "name": "Wood_Bottletree_Branch_Corner",
      "rotation": 2
    },
    {
      "x": 14,
      "y": 20,
      "z": 5,
      "name": "Wood_Bottletree_Branch_Long"
    },
    {
      "x": 14,
      "y": 21,
      "z": 5,
      "name": "Plant_Leaves_Bottle"
    },
    {
      "x": 14,
      "y": 17,
      "z": 6,
      "name": "Wood_Bottletree_Trunk_Full"
    },
    {
      "x": 14,
      "y": 18,
      "z": 6,
      "name": "Wood_Bottletree_Trunk"
    },
    {
      "x": 14,
      "y": 19,
      "z": 6,
      "name": "Wood_Bottletree_Trunk_Full"
    },
    {
      "x": 14,
      "y": 20,
      "z": 6,
      "name": "Wood_Bottletree_Branch_Long"
    },
    {
      "x": 14,
      "y": 21,
      "z": 6,
      "name": "Plant_Leaves_Bottle"
    },
    {
      "x": 14,
      "y": 21,
      "z": 7,
      "name": "Plant_Leaves_Bottle"
    },
    {
      "x": 14,
      "y": 18,
      "z": 8,
      "name": "Plant_Leaves_Bottle"
    },
    {
      "x": 14,
      "y": 19,
      "z": 8,
      "name": "Plant_Leaves_Bottle"
    },
    {
      "x": 14,
      "y": 20,
      "z": 8,
      "name": "Plant_Leaves_Bottle"
    },
    {
      "x": 14,
      "y": 18,
      "z": 9,
      "name": "Plant_Leaves_Bottle"
    },
    {
      "x": 15,
      "y": 19,
      "z": 3,
      "name": "Plant_Leaves_Bottle"
    },
    {
      "x": 15,
      "y": 18,
      "z": 4,
      "name": "Plant_Leaves_Bottle"
    },
    {
      "x": 15,
      "y": 19,
      "z": 4,
      "name": "Plant_Leaves_Bottle"
    },
    {
      "x": 15,
      "y": 20,
      "z": 4,
      "name": "Plant_Leaves_Bottle"
    },
    {
      "x": 15,
      "y": 20,
      "z": 5,
      "name": "Plant_Leaves_Bottle"
    },
    {
      "x": 15,
      "y": 21,
      "z": 5,
      "name": "Plant_Leaves_Bottle"
    },
    {
      "x": 15,
      "y": 18,
      "z": 6,
      "name": "Wood_Bottletree_Branch_Long",
      "rotation": 5
    },
    {
      "x": 15,
      "y": 20,
      "z": 6,
      "name": "Plant_Leaves_Bottle"
    },
    {
      "x": 15,
      "y": 21,
      "z": 6,
      "name": "Plant_Leaves_Bottle"
    },
    {
      "x": 15,
      "y": 20,
      "z": 7,
      "name": "Plant_Leaves_Bottle"
    },
    {
      "x": 15,
      "y": 19,
      "z": 8,
      "name": "Plant_Leaves_Bottle"
    },
    {
      "x": 15,
      "y": 20,
      "z": 8,
      "name": "Plant_Leaves_Bottle"
    },
    {
      "x": 15,
      "y": 19,
      "z": 9,
      "name": "Plant_Leaves_Bottle"
    },
    {
      "x": 16,
      "y": 18,
      "z": 4,
      "name": "Plant_Leaves_Bottle"
    },
    {
      "x": 16,
      "y": 19,
      "z": 4,
      "name": "Plant_Leaves_Bottle"
    },
    {
      "x": 16,
      "y": 18,
      "z": 5,
      "name": "Plant_Leaves_Bottle"
    },
    {
      "x": 16,
      "y": 20,
      "z": 5,
      "name": "Plant_Leaves_Bottle"
    },
    {
      "x": 16,
      "y": 18,
      "z": 6,
      "name": "Plant_Leaves_Bottle"
    },
    {
      "x": 16,
      "y": 19,
      "z": 6,
      "name": "Plant_Leaves_Bottle"
    },
    {
      "x": 16,
      "y": 20,
      "z": 6,
      "name": "Plant_Leaves_Bottle"
    },
    {
      "x": 16,
      "y": 19,
      "z": 7,
      "name": "Plant_Leaves_Bottle"
    },
    {
      "x": 16,
      "y": 19,
      "z": 8,
      "name": "Plant_Leaves_Bottle"
    }
  ]
}