{
  "version": 8,
  "blockIdVersion": 8,
  "anchorX": 0,
  "anchorY": 0,
  "anchorZ": 0,
  "blocks": [
    {
      "x": -2,
      "y": 0,
      "z": -4,
      "name": "Rock_Stone"
    },
    {
      "x": -2,
      "y": 1,
      "z": -4,
      "name": "Rock_Stone"
    },
    {
      "x": -2,
      "y": 2,
      "z": -4,
      "name": "Empty"
    },
    {
      "x": -2,
      "y": 3,
      "z": -4,
      "name": "Empty"
    },
    {
      "x": -2,
      "y": 4,
      "z": -4,
      "name": "Empty"
    },
    {
      "x": -2,
      "y": 0,
      "z": -3,
      "name": "Rock_Stone"
    },
    {
      "x": -2,
      "y": 1,
      "z": -3,
      "name": "Rock_Stone"
    },
    {
      "x": -2,
      "y": 2,
      "z": -3,
      "name": "Plant_Moss_Rug_Blue"
    },
    {
      "x": -2,
      "y": 3,
      "z": -3,
      "name": "Empty"
    },
    {
      "x": -2,
      "y": 4,
      "z": -3,
      "name": "Empty"
    },
    {
      "x": -2,
      "y": 5,
      "z": -3,
      "name": "Empty"
    },
    {
      "x": -2,
      "y": 0,
      "z": -2,
      "name": "Rock_Stone"
    },
    {
      "x": -2,
      "y": 1,
      "z": -2,
      "name": "Rock_Quartzite_Brick_Pillar_Base"
    },
    {
      "x": -2,
      "y": 2,
      "z": -2,
      "name": "Rock_Quartzite_Brick_Pillar_Middle"
    },
    {
      "x": -2,
      "y": 3,
      "z": -2,
      "name": "Rock_Quartzite_Brick_Pillar_Middle"
    },
    {
      "x": -2,
      "y": 4,
      "z": -2,
      "name": "Rock_Quartzite_Brick_Pillar_Base",
      "rotation": 8
    },
    {
      "x": -2,
      "y": 0,
      "z": -1,
      "name": "Rock_Stone"
    },
    {
      "x": -2,
      "y": 1,
      "z": -1,
      "name": "Rock_Quartzite_Brick"
    },
    {
      "x": -2,
      "y": 2,
      "z": -1,
      "name": "Rock_Quartzite_Brick_Wall",
      "rotation": 1
    },
    {
      "x": -2,
      "y": 3,
      "z": -1,
      "name": "Empty"
    },
    {
      "x": -2,
      "y": 4,
      "z": -1,
      "name": "Empty"
    },
    {
      "x": -2,
      "y": 5,
      "z": -1,
      "name": "Empty"
    },
    {
      "x": -2,
      "y": 0,
      "z": 0,
      "name": "Rock_Stone"
    },
    {
      "x": -2,
      "y": 1,
      "z": 0,
      "name": "Rock_Quartzite_Brick_Smooth"
    },
    {
      "x": -2,
      "y": 2,
      "z": 0,
      "name": "Rock_Quartzite_Brick_Wall",
      "rotation": 1
    },
    {
      "x": -2,
      "y": 3,
      "z": 0,
      "name": "Empty"
    },
    {
      "x": -2,
      "y": 4,
      "z": 0,
      "name": "Empty"
    },
    {
      "x": -2,
      "y": 5,
      "z": 0,
      "name": "Empty"
    },
    {
      "x": -1,
      "y": 2,
      "z": -7,
      "name": "Rock_Stone"
    },
    {
      "x": -1,
      "y": 3,
      "z": -7,
      "name": "Rock_Quartzite_Brick"
    },
    {
      "x": -1,
      "y": 4,
      "z": -7,
      "name": "Rock_Quartzite_Brick"
    },
    {
      "x": -1,
      "y": 0,
      "z": -6,
      "name": "Rock_Stone"
    },
    {
      "x": -1,
      "y": 1,
      "z": -6,
      "name": "Rock_Stone"
    },
    {
      "x": -1,
      "y": 2,
      "z": -6,
      "name": "Rock_Stone"
    },
    {
      "x": -1,
      "y": 3,
      "z": -6,
      "name": "Empty"
    },
    {
      "x": -1,
      "y": 4,
      "z": -6,
      "name": "Rock_Quartzite_Brick_Half",
      "rotation": 5
    },
    {
      "x": -1,
      "y": 5,
      "z": -6,
      "name": "Rock_Quartzite_Brick"
    },
    {
      "x": -1,
      "y": -1,
      "z": -5,
      "name": "Rock_Stone"
    },
    {
      "x": -1,
      "y": 0,
      "z": -5,
      "name": "Rock_Stone"
    },
    {
      "x": -1,
      "y": 1,
      "z": -5,
      "name": "Rock_Stone_Cobble"
    },
    {
      "x": -1,
      "y": 2,
      "z": -5,
      "name": "Empty"
    },
    {
      "x": -1,
      "y": 3,
      "z": -5,
      "name": "Empty"
    },
    {
      "x": -1,
      "y": 4,
      "z": -5,
      "name": "Empty"
    },
    {
      "x": -1,
      "y": 5,
      "z": -5,
      "name": "Plant_Moss_Wall_Blue"
    },
    {
      "x": -1,
      "y": -1,
      "z": -4,
      "name": "Rock_Stone"
    },
    {
      "x": -1,
      "y": 0,
      "z": -4,
      "name": "Rock_Stone"
    },
    {
      "x": -1,
      "y": 1,
      "z": -4,
      "name": "Rock_Stone_Cobble"
    },
    {
      "x": -1,
      "y": 2,
      "z": -4,
      "name": "Empty"
    },
    {
      "x": -1,
      "y": 3,
      "z": -4,
      "name": "Empty"
    },
    {
      "x": -1,
      "y": 4,
      "z": -4,
      "name": "Empty"
    },
    {
      "x": -1,
      "y": 5,
      "z": -4,
      "name": "Empty"
    },
    {
      "x": -1,
      "y": -1,
      "z": -3,
      "name": "Rock_Stone"
    },
    {
      "x": -1,
      "y": 0,
      "z": -3,
      "name": "Rock_Stone_Cobble"
    },
    {
      "x": -1,
      "y": 1,
      "z": -3,
      "name": "Rock_Stone"
    },
    {
      "x": -1,
      "y": 2,
      "z": -3,
      "name": "Empty"
    },
    {
      "x": -1,
      "y": 3,
      "z": -3,
      "name": "Empty"
    },
    {
      "x": -1,
      "y": 4,
      "z": -3,
      "name": "Empty"
    },
    {
      "x": -1,
      "y": 5,
      "z": -3,
      "name": "Empty"
    },
    {
      "x": -1,
      "y": 6,
      "z": -3,
      "name": "Empty"
    },
    {
      "x": -1,
      "y": -1,
      "z": -2,
      "name": "Rock_Stone"
    },
    {
      "x": -1,
      "y": 0,
      "z": -2,
      "name": "Rock_Stone_Cobble"
    },
    {
      "x": -1,
      "y": 1,
      "z": -2,
      "name": "Rock_Stone_Cobble_Half"
    },
    {
      "x": -1,
      "y": 2,
      "z": -2,
      "name": "Empty"
    },
    {
      "x": -1,
      "y": 3,
      "z": -2,
      "name": "Empty"
    },
    {
      "x": -1,
      "y": 4,
      "z": -2,
      "name": "Empty"
    },
    {
      "x": -1,
      "y": 5,
      "z": -2,
      "name": "Empty"
    },
    {
      "x": -1,
      "y": 6,
      "z": -2,
      "name": "Empty"
    },
    {
      "x": -1,
      "y": -1,
      "z": -1,
      "name": "Rock_Stone"
    },
    {
      "x": -1,
      "y": 0,
      "z": -1,
      "name": "Rock_Stone"
    },
    {
      "x": -1,
      "y": 1,
      "z": -1,
      "name": "Plant_Moss_Rug_Blue"
    },
    {
      "x": -1,
      "y": 2,
      "z": -1,
      "name": "Empty"
    },
    {
      "x": -1,
      "y": 3,
      "z": -1,
      "name": "Empty"
    },
    {
      "x": -1,
      "y": 4,
      "z": -1,
      "name": "Empty"
    },
    {
      "x": -1,
      "y": 5,
      "z": -1,
      "name": "Empty"
    },
    {
      "x": -1,
      "y": 6,
      "z": -1,
      "name": "Empty"
    },
    {
      "x": -1,
      "y": 0,
      "z": 0,
      "name": "Rock_Stone_Cobble"
    },
    {
      "x": -1,
      "y": 1,
      "z": 0,
      "name": "Empty"
    },
    {
      "x": -1,
      "y": 2,
      "z": 0,
      "name": "Empty"
    },
    {
      "x": -1,
      "y": 3,
      "z": 0,
      "name": "Empty"
    },
    {
      "x": -1,
      "y": 4,
      "z": 0,
      "name": "Empty"
    },
    {
      "x": -1,
      "y": 5,
      "z": 0,
      "name": "Empty"
    },
    {
      "x": -1,
      "y": 6,
      "z": 0,
      "name": "Empty"
    },
    {
      "x": -1,
      "y": 7,
      "z": 0,
      "name": "Empty"
    },
    {
      "x": 0,
      "y": 1,
      "z": -7,
      "name": "Rock_Stone"
    },
    {
      "x": 0,
      "y": 2,
      "z": -7,
      "name": "Rock_Quartzite_Brick"
    },
    {
      "x": 0,
      "y": 3,
      "z": -7,
      "name": "Rock_Quartzite_Brick"
    },
    {
      "x": 0,
      "y": 4,
      "z": -7,
      "name": "Rock_Quartzite_Brick"
    },
    {
      "x": 0,
      "y": -1,
      "z": -6,
      "name": "Rock_Stone"
    },
    {
      "x": 0,
      "y": 0,
      "z": -6,
      "name": "Rock_Stone"
    },
    {
      "x": 0,
      "y": 1,
      "z": -6,
      "name": "Rock_Stone_Cobble"
    },
    {
      "x": 0,
      "y": 2,
      "z": -6,
      "name": "Rock_Quartzite_Brick_Pillar_Base"
    },
    {
      "x": 0,
      "y": 3,
      "z": -6,
      "name": "Rock_Crystal_Green_Medium"
    },
    {
      "x": 0,
      "y": 4,
      "z": -6,
      "name": "Empty"
    },
    {
      "x": 0,
      "y": 5,
      "z": -6,
      "name": "Rock_Quartzite_Brick_Half",
      "rotation": 8
    },
    {
      "x": 0,
      "y": -1,
      "z": -5,
      "name": "Rock_Stone"
    },
    {
      "x": 0,
      "y": 0,
      "z": -5,
      "name": "Rock_Stone"
    },
    {
      "x": 0,
      "y": 1,
      "z": -5,
      "name": "Rock_Stone_Cobble"
    },
    {
      "x": 0,
      "y": 2,
      "z": -5,
      "name": "Empty"
    },
    {
      "x": 0,
      "y": 3,
      "z": -5,
      "name": "Empty"
    },
    {
      "x": 0,
      "y": 4,
      "z": -5,
      "name": "Empty"
    },
    {
      "x": 0,
      "y": 5,
      "z": -5,
      "name": "Empty"
    },
    {
      "x": 0,
      "y": -1,
      "z": -4,
      "name": "Rock_Stone"
    },
    {
      "x": 0,
      "y": 0,
      "z": -4,
      "name": "Rock_Stone_Cobble"
    },
    {
      "x": 0,
      "y": 1,
      "z": -4,
      "name": "Rock_Stone_Cobble"
    },
    {
      "x": 0,
      "y": 2,
      "z": -4,
      "name": "Empty"
    },
    {
      "x": 0,
      "y": 3,
      "z": -4,
      "name": "Empty"
    },
    {
      "x": 0,
      "y": 4,
      "z": -4,
      "name": "Empty"
    },
    {
      "x": 0,
      "y": 5,
      "z": -4,
      "name": "Empty"
    },
    {
      "x": 0,
      "y": 6,
      "z": -4,
      "name": "Empty"
    },
    {
      "x": 0,
      "y": -1,
      "z": -3,
      "name": "Rock_Stone"
    },
    {
      "x": 0,
      "y": 0,
      "z": -3,
      "name": "Rock_Stone_Cobble"
    },
    {
      "x": 0,
      "y": 1,
      "z": -3,
      "name": "Rock_Stone_Cobble"
    },
    {
      "x": 0,
      "y": 2,
      "z": -3,
      "name": "Empty"
    },
    {
      "x": 0,
      "y": 3,
      "z": -3,
      "name": "Empty"
    },
    {
      "x": 0,
      "y": 4,
      "z": -3,
      "name": "Empty"
    },
    {
      "x": 0,
      "y": 5,
      "z": -3,
      "name": "Empty"
    },
    {
      "x": 0,
      "y": 6,
      "z": -3,
      "name": "Empty"
    },
    {
      "x": 0,
      "y": 7,
      "z": -3,
      "name": "Empty"
    },
    {
      "x": 0,
      "y": -1,
      "z": -2,
      "name": "Rock_Stone"
    },
    {
      "x": 0,
      "y": 0,
      "z": -2,
      "name": "Rock_Stone_Cobble"
    },
    {
      "x": 0,
      "y": 1,
      "z": -2,
      "name": "Rock_Stone_Cobble_Half"
    },
    {
      "x": 0,
      "y": 2,
      "z": -2,
      "name": "Empty"
    },
    {
      "x": 0,
      "y": 3,
      "z": -2,
      "name": "Empty"
    },
    {
      "x": 0,
      "y": 4,
      "z": -2,
      "name": "Empty"
    },
    {
      "x": 0,
      "y": 5,
      "z": -2,
      "name": "Empty"
    },
    {
      "x": 0,
      "y": 6,
      "z": -2,
      "name": "Empty"
    },
    {
      "x": 0,
      "y": -1,
      "z": -1,
      "name": "Rock_Stone"
    },
    {
      "x": 0,
      "y": 0,
      "z": -1,
      "name": "Rock_Stone_Cobble"
    },
    {
      "x": 0,
      "y": 1,
      "z": -1,
      "name": "Rock_Stone_Cobble_Half"
    },
    {
      "x": 0,
      "y": 2,
      "z": -1,
      "name": "Empty"
    },
    {
      "x": 0,
      "y": 3,
      "z": -1,
      "name": "Empty"
    },
    {
      "x": 0,
      "y": 4,
      "z": -1,
      "name": "Empty"
    },
    {
      "x": 0,
      "y": 5,
      "z": -1,
      "name": "Empty"
    },
    {
      "x": 0,
      "y": 6,
      "z": -1,
      "name": "Empty"
    },
    {
      "x": 0,
      "y": 7,
      "z": -1,
      "name": "Empty"
    },
    {
      "x": 0,
      "y": -1,
      "z": 0,
      "name": "Rock_Stone"
    },
    {
      "x": 0,
      "y": 0,
      "z": 0,
      "name": "Rock_Stone_Cobble"
    },
    {
      "x": 0,
      "y": 1,
      "z": 0,
      "name": "Empty"
    },
    {
      "x": 0,
      "y": 2,
      "z": 0,
      "name": "Empty"
    },
    {
      "x": 0,
      "y": 3,
      "z": 0,
      "name": "Empty"
    },
    {
      "x": 0,
      "y": 4,
      "z": 0,
      "name": "Empty"
    },
    {
      "x": 0,
      "y": 5,
      "z": 0,
      "name": "Empty"
    },
    {
      "x": 0,
      "y": 6,
      "z": 0,
      "name": "Empty"
    },
    {
      "x": 0,
      "y": 7,
      "z": 0,
      "name": "Empty"
    },
    {
      "x": 1,
      "y": 0,
      "z": -7,
      "name": "Rock_Stone"
    },
    {
      "x": 1,
      "y": 1,
      "z": -7,
      "name": "Rock_Stone"
    },
    {
      "x": 1,
      "y": 2,
      "z": -7,
      "name": "Rock_Quartzite_Brick"
    },
    {
      "x": 1,
      "y": 3,
      "z": -7,
      "name": "Rock_Quartzite_Brick"
    },
    {
      "x": 1,
      "y": -1,
      "z": -6,
      "name": "Rock_Stone"
    },
    {
      "x": 1,
      "y": 0,
      "z": -6,
      "name": "Rock_Stone"
    },
    {
      "x": 1,
      "y": 1,
      "z": -6,
      "name": "Rock_Quartzite_Brick_Smooth"
    },
    {
      "x": 1,
      "y": 2,
      "z": -6,
      "name": "Plant_Moss_Rug_Blue"
    },
    {
      "x": 1,
      "y": 3,
      "z": -6,
      "name": "Empty"
    },
    {
      "x": 1,
      "y": 4,
      "z": -6,
      "name": "Rock_Quartzite_Brick_Half",
      "rotation": 7
    },
    {
      "x": 1,
      "y": 5,
      "z": -6,
      "name": "Rock_Quartzite_Brick"
    },
    {
      "x": 1,
      "y": -1,
      "z": -5,
      "name": "Rock_Stone"
    },
    {
      "x": 1,
      "y": 0,
      "z": -5,
      "name": "Rock_Stone"
    },
    {
      "x": 1,
      "y": 1,
      "z": -5,
      "name": "Rock_Stone_Cobble"
    },
    {
      "x": 1,
      "y": 2,
      "z": -5,
      "name": "Empty"
    },
    {
      "x": 1,
      "y": 3,
      "z": -5,
      "name": "Empty"
    },
    {
      "x": 1,
      "y": 4,
      "z": -5,
      "name": "Empty"
    },
    {
      "x": 1,
      "y": 5,
      "z": -5,
      "name": "Empty"
    },
    {
      "x": 1,
      "y": -2,
      "z": -4,
      "name": "Rock_Stone"
    },
    {
      "x": 1,
      "y": -1,
      "z": -4,
      "name": "Rock_Stone"
    },
    {
      "x": 1,
      "y": 0,
      "z": -4,
      "name": "Rock_Stone_Cobble"
    },
    {
      "x": 1,
      "y": 1,
      "z": -4,
      "name": "Rock_Stone_Cobble"
    },
    {
      "x": 1,
      "y": 2,
      "z": -4,
      "name": "Empty"
    },
    {
      "x": 1,
      "y": 3,
      "z": -4,
      "name": "Empty"
    },
    {
      "x": 1,
      "y": 4,
      "z": -4,
      "name": "Empty"
    },
    {
      "x": 1,
      "y": 5,
      "z": -4,
      "name": "Empty"
    },
    {
      "x": 1,
      "y": -2,
      "z": -3,
      "name": "Rock_Stone"
    },
    {
      "x": 1,
      "y": -1,
      "z": -3,
      "name": "Rock_Stone"
    },
    {
      "x": 1,
      "y": 0,
      "z": -3,
      "name": "Rock_Stone_Cobble"
    },
    {
      "x": 1,
      "y": 1,
      "z": -3,
      "name": "Rock_Stone_Cobble"
    },
    {
      "x": 1,
      "y": 2,
      "z": -3,
      "name": "Empty"
    },
    {
      "x": 1,
      "y": 3,
      "z": -3,
      "name": "Empty"
    },
    {
      "x": 1,
      "y": 4,
      "z": -3,
      "name": "Empty"
    },
    {
      "x": 1,
      "y": 5,
      "z": -3,
      "name": "Empty"
    },
    {
      "x": 1,
      "y": -1,
      "z": -2,
      "name": "Rock_Stone"
    },
    {
      "x": 1,
      "y": 0,
      "z": -2,
      "name": "Rock_Stone_Cobble"
    },
    {
      "x": 1,
      "y": 1,
      "z": -2,
      "name": "Rock_Stone_Cobble"
    },
    {
      "x": 1,
      "y": 2,
      "z": -2,
      "name": "Empty"
    },
    {
      "x": 1,
      "y": 3,
      "z": -2,
      "name": "Empty"
    },
    {
      "x": 1,
      "y": 4,
      "z": -2,
      "name": "Empty"
    },
    {
      "x": 1,
      "y": 5,
      "z": -2,
      "name": "Empty"
    },
    {
      "x": 1,
      "y": -1,
      "z": -1,
      "name": "Rock_Stone"
    },
    {
      "x": 1,
      "y": 0,
      "z": -1,
      "name": "Rock_Stone_Cobble"
    },
    {
      "x": 1,
      "y": 1,
      "z": -1,
      "name": "Rock_Stone_Cobble_Half"
    },
    {
      "x": 1,
      "y": 2,
      "z": -1,
      "name": "Empty"
    },
    {
      "x": 1,
      "y": 3,
      "z": -1,
      "name": "Plant_Moss_Wall_Blue",
      "rotation": 3
    },
    {
      "x": 1,
      "y": 4,
      "z": -1,
      "name": "Empty"
    },
    {
      "x": 1,
      "y": 5,
      "z": -1,
      "name": "Empty"
    },
    {
      "x": 1,
      "y": 6,
      "z": -1,
      "name": "Empty"
    },
    {
      "x": 1,
      "y": -1,
      "z": 0,
      "name": "Rock_Stone"
    },
    {
      "x": 1,
      "y": 0,
      "z": 0,
      "name": "Rock_Stone"
    },
    {
      "x": 1,
      "y": 1,
      "z": 0,
      "name": "Plant_Moss_Rug_Blue"
    },
    {
      "x": 1,
      "y": 2,
      "z": 0,
      "name": "Empty"
    },
    {
      "x": 1,
      "y": 3,
      "z": 0,
      "name": "Empty"
    },
    {
      "x": 1,
      "y": 4,
      "z": 0,
      "name": "Empty"
    },
    {
      "x": 1,
      "y": 5,
      "z": 0,
      "name": "Empty"
    },
    {
      "x": 1,
      "y": 6,
      "z": 0,
      "name": "Empty"
    },
    {
      "x": 2,
      "y": 0,
      "z": -7,
      "name": "Rock_Stone"
    },
    {
      "x": 2,
      "y": 1,
      "z": -7,
      "name": "Rock_Stone"
    },
    {
      "x": 2,
      "y": 2,
      "z": -7,
      "name": "Rock_Stone"
    },
    {
      "x": 2,
      "y": -1,
      "z": -6,
      "name": "Rock_Stone"
    },
    {
      "x": 2,
      "y": 0,
      "z": -6,
      "name": "Rock_Stone"
    },
    {
      "x": 2,
      "y": 1,
      "z": -6,
      "name": "Rock_Quartzite_Brick_Smooth"
    },
    {
      "x": 2,
      "y": 2,
      "z": -6,
      "name": "Rock_Quartzite_Brick"
    },
    {
      "x": 2,
      "y": 3,
      "z": -6,
      "name": "Rock_Quartzite_Brick"
    },
    {
      "x": 2,
      "y": 4,
      "z": -6,
      "name": "Rock_Quartzite_Brick"
    },
    {
      "x": 2,
      "y": -2,
      "z": -5,
      "name": "Rock_Stone"
    },
    {
      "x": 2,
      "y": -1,
      "z": -5,
      "name": "Rock_Stone"
    },
    {
      "x": 2,
      "y": 0,
      "z": -5,
      "name": "Rock_Stone_Cobble"
    },
    {
      "x": 2,
      "y": 1,
      "z": -5,
      "name": "Rock_Quartzite_Brick"
    },
    {
      "x": 2,
      "y": 2,
      "z": -5,
      "name": "Rock_Quartzite_Brick"
    },
    {
      "x": 2,
      "y": 3,
      "z": -5,
      "name": "Rock_Quartzite_Brick"
    },
    {
      "x": 2,
      "y": 4,
      "z": -5,
      "name": "Rock_Quartzite_Brick_Half",
      "rotation": 4
    },
    {
      "x": 2,
      "y": 5,
      "z": -5,
      "name": "Rock_Quartzite_Brick_Half",
      "rotation": 4
    },
    {
      "x": 2,
      "y": 6,
      "z": -5,
      "name": "Empty"
    },
    {
      "x": 2,
      "y": -2,
      "z": -4,
      "name": "Rock_Stone"
    },
    {
      "x": 2,
      "y": -1,
      "z": -4,
      "name": "Rock_Stone"
    },
    {
      "x": 2,
      "y": 0,
      "z": -4,
      "name": "Rock_Stone_Cobble"
    },
    {
      "x": 2,
      "y": 1,
      "z": -4,
      "name": "Rock_Quartzite_Brick"
    },
    {
      "x": 2,
      "y": 2,
      "z": -4,
      "name": "Empty"
    },
    {
      "x": 2,
      "y": 3,
      "z": -4,
      "name": "Empty"
    },
    {
      "x": 2,
      "y": 4,
      "z": -4,
      "name": "Empty"
    },
    {
      "x": 2,
      "y": 5,
      "z": -4,
      "name": "Plant_Moss_Cave_Blue",
      "rotation": 8
    },
    {
      "x": 2,
      "y": -2,
      "z": -3,
      "name": "Rock_Stone"
    },
    {
      "x": 2,
      "y": -1,
      "z": -3,
      "name": "Rock_Stone"
    },
    {
      "x": 2,
      "y": 0,
      "z": -3,
      "name": "Rock_Stone"
    },
    {
      "x": 2,
      "y": 1,
      "z": -3,
      "name": "Rock_Quartzite_Brick"
    },
    {
      "x": 2,
      "y": 2,
      "z": -3,
      "name": "Empty"
    },
    {
      "x": 2,
      "y": 3,
      "z": -3,
      "name": "Empty"
    },
    {
      "x": 2,
      "y": 4,
      "z": -3,
      "name": "Empty"
    },
    {
      "x": 2,
      "y": 5,
      "z": -3,
      "name": "Empty"
    },
    {
      "x": 2,
      "y": 6,
      "z": -3,
      "name": "Empty"
    },
    {
      "x": 2,
      "y": -1,
      "z": -2,
      "name": "Rock_Stone"
    },
    {
      "x": 2,
      "y": 0,
      "z": -2,
      "name": "Rock_Stone"
    },
    {
      "x": 2,
      "y": 1,
      "z": -2,
      "name": "Rock_Quartzite_Brick_Smooth"
    },
    {
      "x": 2,
      "y": 2,
      "z": -2,
      "name": "Rock_Quartzite_Brick_Pillar_Base"
    },
    {
      "x": 2,
      "y": 3,
      "z": -2,
      "name": "Rock_Quartzite_Brick_Pillar_Middle"
    },
    {
      "x": 2,
      "y": 4,
      "z": -2,
      "name": "Rock_Quartzite_Brick_Pillar_Middle"
    },
    {
      "x": 2,
      "y": 5,
      "z": -2,
      "name": "Rock_Quartzite_Brick_Pillar_Base",
      "rotation": 8
    },
    {
      "x": 2,
      "y": 6,
      "z": -2,
      "name": "Empty"
    },
    {
      "x": 2,
      "y": -1,
      "z": -1,
      "name": "Rock_Stone"
    },
    {
      "x": 2,
      "y": 0,
      "z": -1,
      "name": "Rock_Stone"
    },
    {
      "x": 2,
      "y": 1,
      "z": -1,
      "name": "Rock_Quartzite_Brick"
    },
    {
      "x": 2,
      "y": 2,
      "z": -1,
      "name": "Rock_Quartzite_Brick"
    },
    {
      "x": 2,
      "y": 3,
      "z": -1,
      "name": "Rock_Quartzite_Brick"
    },
    {
      "x": 2,
      "y": 4,
      "z": -1,
      "name": "Plant_Moss_Rug_Blue"
    },
    {
      "x": 2,
      "y": 5,
      "z": -1,
      "name": "Empty"
    },
    {
      "x": 2,
      "y": 0,
      "z": 0,
      "name": "Rock_Stone"
    },
    {
      "x": 2,
      "y": 1,
      "z": 0,
      "name": "Rock_Quartzite_Brick"
    },
    {
      "x": 2,
      "y": 2,
      "z": 0,
      "name": "Rock_Quartzite_Brick_Wall",
      "rotation": 3
    },
    {
      "x": 2,
      "y": 3,
      "z": 0,
      "name": "Empty"
    },
    {
      "x": 2,
      "y": 4,
      "z": 0,
      "name": "Empty"
    },
    {
      "x": 3,
      "y": 0,
      "z": -7,
      "name": "Rock_Stone"
    },
    {
      "x": 3,
      "y": 1,
      "z": -7,
      "name": "Rock_Stone"
    },
    {
      "x": 3,
      "y": -1,
      "z": -6,
      "name": "Rock_Stone"
    },
    {
      "x": 3,
      "y": 0,
      "z": -6,
      "name": "Rock_Stone"
    },
    {
      "x": 3,
      "y": 1,
      "z": -6,
      "name": "Rock_Quartzite_Brick_Wall"
    },
    {
      "x": 3,
      "y": 2,
      "z": -6,
      "name": "Empty"
    },
    {
      "x": 3,
      "y": 3,
      "z": -6,
      "name": "Empty"
    },
    {
      "x": 3,
      "y": 4,
      "z": -6,
      "name": "Empty"
    },
    {
      "x": 3,
      "y": -2,
      "z": -5,
      "name": "Rock_Stone"
    },
    {
      "x": 3,
      "y": -1,
      "z": -5,
      "name": "Rock_Stone"
    },
    {
      "x": 3,
      "y": 0,
      "z": -5,
      "name": "Rock_Stone_Cobble"
    },
    {
      "x": 3,
      "y": 1,
      "z": -5,
      "name": "Plant_Moss_Rug_Blue"
    },
    {
      "x": 3,
      "y": 2,
      "z": -5,
      "name": "Empty"
    },
    {
      "x": 3,
      "y": 3,
      "z": -5,
      "name": "Empty"
    },
    {
      "x": 3,
      "y": 4,
      "z": -5,
      "name": "Empty"
    },
    {
      "x": 3,
      "y": 5,
      "z": -5,
      "name": "Empty"
    },
    {
      "x": 3,
      "y": 6,
      "z": -5,
      "name": "Empty"
    },
    {
      "x": 3,
      "y": -2,
      "z": -4,
      "name": "Rock_Stone"
    },
    {
      "x": 3,
      "y": -1,
      "z": -4,
      "name": "Rock_Stone"
    },
    {
      "x": 3,
      "y": 0,
      "z": -4,
      "name": "Rock_Stone_Cobble"
    },
    {
      "x": 3,
      "y": 1,
      "z": -4,
      "name": "Plant_Moss_Rug_Blue"
    },
    {
      "x": 3,
      "y": 2,
      "z": -4,
      "name": "Empty"
    },
    {
      "x": 3,
      "y": 3,
      "z": -4,
      "name": "Empty"
    },
    {
      "x": 3,
      "y": 4,
      "z": -4,
      "name": "Empty"
    },
    {
      "x": 3,
      "y": 5,
      "z": -4,
      "name": "Empty"
    },
    {
      "x": 3,
      "y": -2,
      "z": -3,
      "name": "Rock_Stone"
    },
    {
      "x": 3,
      "y": -1,
      "z": -3,
      "name": "Rock_Stone"
    },
    {
      "x": 3,
      "y": 0,
      "z": -3,
      "name": "Rock_Stone_Cobble"
    },
    {
      "x": 3,
      "y": 1,
      "z": -3,
      "name": "Empty"
    },
    {
      "x": 3,
      "y": 2,
      "z": -3,
      "name": "Empty"
    },
    {
      "x": 3,
      "y": 3,
      "z": -3,
      "name": "Empty"
    },
    {
      "x": 3,
      "y": 4,
      "z": -3,
      "name": "Empty"
    },
    {
      "x": 3,
      "y": 5,
      "z": -3,
      "name": "Empty"
    },
    {
      "x": 3,
      "y": -1,
      "z": -2,
      "name": "Rock_Stone"
    },
    {
      "x": 3,
      "y": 0,
      "z": -2,
      "name": "Rock_Stone"
    },
    {
      "x": 3,
      "y": 1,
      "z": -2,
      "name": "Rock_Quartzite_Brick"
    },
    {
      "x": 3,
      "y": 2,
      "z": -2,
      "name": "Rock_Quartzite_Brick_Half",
      "rotation": 6
    },
    {
      "x": 3,
      "y": 3,
      "z": -2,
      "name": "Rock_Quartzite_Brick_Half",
      "rotation": 6
    },
    {
      "x": 4,
      "y": 0,
      "z": -6,
      "name": "Plant_Moss_Block_Blue"
    },
    {
      "x": 4,
      "y": 1,
      "z": -6,
      "name": "Rock_Quartzite_Brick_Wall"
    },
    {
      "x": 4,
      "y": 2,
      "z": -6,
      "name": "Empty"
    },
    {
      "x": 4,
      "y": 3,
      "z": -6,
      "name": "Empty"
    },
    {
      "x": 4,
      "y": 4,
      "z": -6,
      "name": "Empty"
    },
    {
      "x": 4,
      "y": 5,
      "z": -6,
      "name": "Empty"
    },
    {
      "x": 4,
      "y": -1,
      "z": -5,
      "name": "Rock_Stone"
    },
    {
      "x": 4,
      "y": 0,
      "z": -5,
      "name": "Plant_Moss_Block_Blue"
    },
    {
      "x": 4,
      "y": 1,
      "z": -5,
      "name": "Empty"
    },
    {
      "x": 4,
      "y": 2,
      "z": -5,
      "name": "Empty"
    },
    {
      "x": 4,
      "y": 3,
      "z": -5,
      "name": "Empty"
    },
    {
      "x": 4,
      "y": 4,
      "z": -5,
      "name": "Empty"
    },
    {
      "x": 4,
      "y": 5,
      "z": -5,
      "name": "Empty"
    },
    {
      "x": 4,
      "y": 6,
      "z": -5,
      "name": "Empty"
    },
    {
      "x": 4,
      "y": -1,
      "z": -4,
      "name": "Rock_Stone"
    },
    {
      "x": 4,
      "y": 0,
      "z": -4,
      "name": "Rock_Stone_Cobble"
    },
    {
      "x": 4,
      "y": 1,
      "z": -4,
      "name": "Empty"
    },
    {
      "x": 4,
      "y": 2,
      "z": -4,
      "name": "Empty"
    },
    {
      "x": 4,
      "y": 3,
      "z": -4,
      "name": "Empty"
    },
    {
      "x": 4,
      "y": 4,
      "z": -4,
      "name": "Empty"
    },
    {
      "x": 4,
      "y": 5,
      "z": -4,
      "name": "Empty"
    },
    {
      "x": 4,
      "y": -1,
      "z": -3,
      "name": "Rock_Stone"
    },
    {
      "x": 4,
      "y": 0,
      "z": -3,
      "name": "Rock_Stone_Cobble"
    },
    {
      "x": 4,
      "y": 1,
      "z": -3,
      "name": "Empty"
    },
    {
      "x": 4,
      "y": 2,
      "z": -3,
      "name": "Empty"
    },
    {
      "x": 4,
      "y": 3,
      "z": -3,
      "name": "Empty"
    },
    {
      "x": 4,
      "y": 4,
      "z": -3,
      "name": "Empty"
    },
    {
      "x": 4,
      "y": 0,
      "z": -2,
      "name": "Rock_Stone_Cobble"
    },
    {
      "x": 4,
      "y": 1,
      "z": -2,
      "name": "Rock_Quartzite_Brick_Half",
      "rotation": 6
    },
    {
      "x": 4,
      "y": 2,
      "z": -2,
      "name": "Rock_Quartzite_Brick_Half",
      "rotation": 6
    }
  ]
}