{
  "version": 8,
  "blockIdVersion": 8,
  "anchorX": 10,
  "anchorY": 46,
  "anchorZ": 11,
  "blocks": [
    {
      "x": 3,
      "y": 41,
      "z": 5,
      "name": "Rock_Sandstone"
    },
    {
      "x": 3,
      "y": 42,
      "z": 5,
      "name": "Rock_Sandstone"
    },
    {
      "x": 3,
      "y": 43,
      "z": 5,
      "name": "Rock_Sandstone"
    },
    {
      "x": 3,
      "y": 44,
      "z": 5,
      "name": "Rock_Sandstone"
    },
    {
      "x": 3,
      "y": 40,
      "z": 6,
      "name": "Rock_Sandstone"
    },
    {
      "x": 3,
      "y": 41,
      "z": 6,
      "name": "Rock_Sandstone"
    },
    {
      "x": 3,
      "y": 42,
      "z": 6,
      "name": "Rock_Sandstone"
    },
    {
      "x": 3,
      "y": 43,
      "z": 6,
      "name": "Rock_Sandstone"
    },
    {
      "x": 3,
      "y": 44,
      "z": 6,
      "name": "Rock_Sandstone"
    },
    {
      "x": 3,
      "y": 45,
      "z": 6,
      "name": "Rock_Sandstone"
    },
    {
      "x": 3,
      "y": 33,
      "z": 7,
      "name": "Rock_Sandstone_White"
    },
    {
      "x": 3,
      "y": 34,
      "z": 7,
      "name": "Rock_Sandstone_White"
    },
    {
      "x": 3,
      "y": 35,
      "z": 7,
      "name": "Rock_Sandstone"
    },
    {
      "x": 3,
      "y": 40,
      "z": 7,
      "name": "Rock_Sandstone"
    },
    {
      "x": 3,
      "y": 41,
      "z": 7,
      "name": "Rock_Sandstone"
    },
    {
      "x": 3,
      "y": 42,
      "z": 7,
      "name": "Rock_Sandstone"
    },
    {
      "x": 3,
      "y": 43,
      "z": 7,
      "name": "Rock_Sandstone"
    },
    {
      "x": 3,
      "y": 44,
      "z": 7,
      "name": "Rock_Sandstone"
    },
    {
      "x": 3,
      "y": 45,
      "z": 7,
      "name": "Rock_Sandstone"
    },
    {
      "x": 3,
      "y": 33,
      "z": 8,
      "name": "Rock_Sandstone_White"
    },
    {
      "x": 3,
      "y": 34,
      "z": 8,
      "name": "Rock_Sandstone_White"
    },
    {
      "x": 3,
      "y": 35,
      "z": 8,
      "name": "Rock_Sandstone"
    },
    {
      "x": 3,
      "y": 36,
      "z": 8,
      "name": "Rock_Sandstone"
    },
    {
      "x": 3,
      "y": 39,
      "z": 8,
      "name": "Rock_Sandstone"
    },
    {
      "x": 3,
      "y": 40,
      "z": 8,
      "name": "Rock_Sandstone"
    },
    {
      "x": 3,
      "y": 41,
      "z": 8,
      "name": "Rock_Sandstone"
    },
    {
      "x": 3,
      "y": 42,
      "z": 8,
      "name": "Rock_Sandstone"
    },
    {
      "x": 3,
      "y": 43,
      "z": 8,
      "name": "Rock_Sandstone"
    },
    {
      "x": 3,
      "y": 44,
      "z": 8,
      "name": "Rock_Sandstone"
    },
    {
      "x": 3,
      "y": 45,
      "z": 8,
      "name": "Rock_Sandstone"
    },
    {
      "x": 3,
      "y": 32,
      "z": 9,
      "name": "Rock_Sandstone_White"
    },
    {
      "x": 3,
      "y": 33,
      "z": 9,
      "name": "Rock_Sandstone_White"
    },
    {
      "x": 3,
      "y": 34,
      "z": 9,
      "name": "Rock_Sandstone_White"
    },
    {
      "x": 3,
      "y": 35,
      "z": 9,
      "name": "Rock_Sandstone"
    },
    {
      "x": 3,
      "y": 36,
      "z": 9,
      "name": "Rock_Sandstone"
    },
    {
      "x": 3,
      "y": 39,
      "z": 9,
      "name": "Rock_Sandstone"
    },
    {
      "x": 3,
      "y": 40,
      "z": 9,
      "name": "Rock_Sandstone"
    },
    {
      "x": 3,
      "y": 41,
      "z": 9,
      "name": "Rock_Sandstone"
    },
    {
      "x": 3,
      "y": 42,
      "z": 9,
      "name": "Rock_Sandstone"
    },
    {
      "x": 3,
      "y": 43,
      "z": 9,
      "name": "Rock_Sandstone"
    },
    {
      "x": 3,
      "y": 32,
      "z": 10,
      "name": "Rock_Sandstone_White"
    },
    {
      "x": 3,
      "y": 33,
      "z": 10,
      "name": "Rock_Sandstone_White"
    },
    {
      "x": 3,
      "y": 34,
      "z": 10,
      "name": "Rock_Sandstone_White"
    },
    {
      "x": 3,
      "y": 35,
      "z": 10,
      "name": "Rock_Sandstone"
    },
    {
      "x": 3,
      "y": 36,
      "z": 10,
      "name": "Rock_Sandstone"
    },
    {
      "x": 3,
      "y": 39,
      "z": 10,
      "name": "Rock_Sandstone"
    },
    {
      "x": 3,
      "y": 40,
      "z": 10,
      "name": "Rock_Sandstone"
    },
    {
      "x": 3,
      "y": 41,
      "z": 10,
      "name": "Rock_Sandstone"
    },
    {
      "x": 3,
      "y": 32,
      "z": 11,
      "name": "Rock_Sandstone_White"
    },
    {
      "x": 3,
      "y": 33,
      "z": 11,
      "name": "Rock_Sandstone_White"
    },
    {
      "x": 3,
      "y": 34,
      "z": 11,
      "name": "Rock_Sandstone_White"
    },
    {
      "x": 3,
      "y": 35,
      "z": 11,
      "name": "Rock_Sandstone"
    },
    {
      "x": 3,
      "y": 36,
      "z": 11,
      "name": "Rock_Sandstone"
    },
    {
      "x": 3,
      "y": 32,
      "z": 12,
      "name": "Rock_Sandstone_White"
    },
    {
      "x": 3,
      "y": 33,
      "z": 12,
      "name": "Rock_Sandstone_White"
    },
    {
      "x": 3,
      "y": 34,
      "z": 12,
      "name": "Rock_Sandstone_White"
    },
    {
      "x": 3,
      "y": 35,
      "z": 12,
      "name": "Rock_Sandstone"
    },
    {
      "x": 3,
      "y": 36,
      "z": 12,
      "name": "Rock_Sandstone"
    },
    {
      "x": 3,
      "y": 33,
      "z": 13,
      "name": "Rock_Sandstone_White"
    },
    {
      "x": 3,
      "y": 34,
      "z": 13,
      "name": "Rock_Sandstone_White"
    },
    {
      "x": 3,
      "y": 35,
      "z": 13,
      "name": "Rock_Sandstone"
    },
    {
      "x": 4,
      "y": 40,
      "z": 5,
      "name": "Rock_Sandstone"
    },
    {
      "x": 4,
      "y": 41,
      "z": 5,
      "name": "Rock_Sandstone"
    },
    {
      "x": 4,
      "y": 42,
      "z": 5,
      "name": "Rock_Sandstone"
    },
    {
      "x": 4,
      "y": 43,
      "z": 5,
      "name": "Rock_Sandstone"
    },
    {
      "x": 4,
      "y": 44,
      "z": 5,
      "name": "Rock_Sandstone"
    },
    {
      "x": 4,
      "y": 45,
      "z": 5,
      "name": "Rock_Sandstone"
    },
    {
      "x": 4,
      "y": 32,
      "z": 6,
      "name": "Rock_Sandstone_White"
    },
    {
      "x": 4,
      "y": 33,
      "z": 6,
      "name": "Rock_Sandstone_White"
    },
    {
      "x": 4,
      "y": 34,
      "z": 6,
      "name": "Rock_Sandstone_White"
    },
    {
      "x": 4,
      "y": 35,
      "z": 6,
      "name": "Rock_Sandstone"
    },
    {
      "x": 4,
      "y": 36,
      "z": 6,
      "name": "Rock_Sandstone"
    },
    {
      "x": 4,
      "y": 39,
      "z": 6,
      "name": "Rock_Sandstone"
    },
    {
      "x": 4,
      "y": 40,
      "z": 6,
      "name": "Rock_Sandstone"
    },
    {
      "x": 4,
      "y": 41,
      "z": 6,
      "name": "Rock_Sandstone"
    },
    {
      "x": 4,
      "y": 42,
      "z": 6,
      "name": "Rock_Sandstone"
    },
    {
      "x": 4,
      "y": 43,
      "z": 6,
      "name": "Rock_Sandstone"
    },
    {
      "x": 4,
      "y": 44,
      "z": 6,
      "name": "Rock_Sandstone"
    },
    {
      "x": 4,
      "y": 45,
      "z": 6,
      "name": "Rock_Sandstone"
    },
    {
      "x": 4,
      "y": 31,
      "z": 7,
      "name": "Rock_Sandstone"
    },
    {
      "x": 4,
      "y": 32,
      "z": 7,
      "name": "Rock_Sandstone_White"
    },
    {
      "x": 4,
      "y": 33,
      "z": 7,
      "name": "Rock_Sandstone_White"
    },
    {
      "x": 4,
      "y": 34,
      "z": 7,
      "name": "Rock_Sandstone_White"
    },
    {
      "x": 4,
      "y": 35,
      "z": 7,
      "name": "Rock_Sandstone"
    },
    {
      "x": 4,
      "y": 36,
      "z": 7,
      "name": "Rock_Sandstone"
    },
    {
      "x": 4,
      "y": 38,
      "z": 7,
      "name": "Rock_Sandstone"
    },
    {
      "x": 4,
      "y": 39,
      "z": 7,
      "name": "Rock_Sandstone"
    },
    {
      "x": 4,
      "y": 40,
      "z": 7,
      "name": "Rock_Sandstone"
    },
    {
      "x": 4,
      "y": 41,
      "z": 7,
      "name": "Rock_Sandstone"
    },
    {
      "x": 4,
      "y": 42,
      "z": 7,
      "name": "Rock_Sandstone"
    },
    {
      "x": 4,
      "y": 43,
      "z": 7,
      "name": "Rock_Sandstone"
    },
    {
      "x": 4,
      "y": 44,
      "z": 7,
      "name": "Rock_Sandstone"
    },
    {
      "x": 4,
      "y": 45,
      "z": 7,
      "name": "Rock_Sandstone"
    },
    {
      "x": 4,
      "y": 31,
      "z": 8,
      "name": "Rock_Sandstone"
    },
    {
      "x": 4,
      "y": 32,
      "z": 8,
      "name": "Rock_Sandstone_White"
    },
    {
      "x": 4,
      "y": 33,
      "z": 8,
      "name": "Rock_Sandstone_White"
    },
    {
      "x": 4,
      "y": 34,
      "z": 8,
      "name": "Rock_Sandstone_White"
    },
    {
      "x": 4,
      "y": 35,
      "z": 8,
      "name": "Rock_Sandstone"
    },
    {
      "x": 4,
      "y": 36,
      "z": 8,
      "name": "Rock_Sandstone"
    },
    {
      "x": 4,
      "y": 38,
      "z": 8,
      "name": "Rock_Sandstone"
    },
    {
      "x": 4,
      "y": 39,
      "z": 8,
      "name": "Rock_Sandstone"
    },
    {
      "x": 4,
      "y": 40,
      "z": 8,
      "name": "Rock_Sandstone"
    },
    {
      "x": 4,
      "y": 41,
      "z": 8,
      "name": "Rock_Sandstone"
    },
    {
      "x": 4,
      "y": 42,
      "z": 8,
      "name": "Rock_Sandstone"
    },
    {
      "x": 4,
      "y": 43,
      "z": 8,
      "name": "Rock_Sandstone"
    },
    {
      "x": 4,
      "y": 44,
      "z": 8,
      "name": "Rock_Sandstone"
    },
    {
      "x": 4,
      "y": 45,
      "z": 8,
      "name": "Rock_Sandstone"
    },
    {
      "x": 4,
      "y": 31,
      "z": 9,
      "name": "Rock_Sandstone"
    },
    {
      "x": 4,
      "y": 32,
      "z": 9,
      "name": "Rock_Sandstone_White"
    },
    {
      "x": 4,
      "y": 33,
      "z": 9,
      "name": "Rock_Sandstone_White"
    },
    {
      "x": 4,
      "y": 34,
      "z": 9,
      "name": "Rock_Sandstone_White"
    },
    {
      "x": 4,
      "y": 35,
      "z": 9,
      "name": "Rock_Sandstone"
    },
    {
      "x": 4,
      "y": 36,
      "z": 9,
      "name": "Rock_Sandstone"
    },
    {
      "x": 4,
      "y": 38,
      "z": 9,
      "name": "Rock_Sandstone"
    },
    {
      "x": 4,
      "y": 39,
      "z": 9,
      "name": "Rock_Sandstone"
    },
    {
      "x": 4,
      "y": 40,
      "z": 9,
      "name": "Rock_Sandstone"
    },
    {
      "x": 4,
      "y": 41,
      "z": 9,
      "name": "Rock_Sandstone"
    },
    {
      "x": 4,
      "y": 42,
      "z": 9,
      "name": "Rock_Sandstone"
    },
    {
      "x": 4,
      "y": 43,
      "z": 9,
      "name": "Rock_Sandstone"
    },
    {
      "x": 4,
      "y": 31,
      "z": 10,
      "name": "Rock_Sandstone"
    },
    {
      "x": 4,
      "y": 32,
      "z": 10,
      "name": "Rock_Sandstone_White"
    },
    {
      "x": 4,
      "y": 33,
      "z": 10,
      "name": "Rock_Sandstone_White"
    },
    {
      "x": 4,
      "y": 34,
      "z": 10,
      "name": "Rock_Sandstone_White"
    },
    {
      "x": 4,
      "y": 35,
      "z": 10,
      "name": "Rock_Sandstone"
    },
    {
      "x": 4,
      "y": 36,
      "z": 10,
      "name": "Rock_Sandstone"
    },
    {
      "x": 4,
      "y": 38,
      "z": 10,
      "name": "Rock_Sandstone"
    },
    {
      "x": 4,
      "y": 39,
      "z": 10,
      "name": "Rock_Sandstone"
    },
    {
      "x": 4,
      "y": 40,
      "z": 10,
      "name": "Rock_Sandstone"
    },
    {
      "x": 4,
      "y": 41,
      "z": 10,
      "name": "Rock_Sandstone"
    },
    {
      "x": 4,
      "y": 31,
      "z": 11,
      "name": "Rock_Sandstone"
    },
    {
      "x": 4,
      "y": 32,
      "z": 11,
      "name": "Rock_Sandstone_White"
    },
    {
      "x": 4,
      "y": 33,
      "z": 11,
      "name": "Rock_Sandstone_White"
    },
    {
      "x": 4,
      "y": 34,
      "z": 11,
      "name": "Rock_Sandstone_White"
    },
    {
      "x": 4,
      "y": 35,
      "z": 11,
      "name": "Rock_Sandstone"
    },
    {
      "x": 4,
      "y": 36,
      "z": 11,
      "name": "Rock_Sandstone"
    },
    {
      "x": 4,
      "y": 43,
      "z": 11,
      "name": "Rock_Sandstone"
    },
    {
      "x": 4,
      "y": 44,
      "z": 11,
      "name": "Rock_Sandstone"
    },
    {
      "x": 4,
      "y": 45,
      "z": 11,
      "name": "Rock_Sandstone"
    },
    {
      "x": 4,
      "y": 32,
      "z": 12,
      "name": "Rock_Sandstone_White"
    },
    {
      "x": 4,
      "y": 33,
      "z": 12,
      "name": "Rock_Sandstone_White"
    },
    {
      "x": 4,
      "y": 34,
      "z": 12,
      "name": "Rock_Sandstone_White"
    },
    {
      "x": 4,
      "y": 35,
      "z": 12,
      "name": "Rock_Sandstone"
    },
    {
      "x": 4,
      "y": 36,
      "z": 12,
      "name": "Rock_Sandstone"
    },
    {
      "x": 4,
      "y": 39,
      "z": 12,
      "name": "Rock_Sandstone"
    },
    {
      "x": 4,
      "y": 40,
      "z": 12,
      "name": "Rock_Sandstone"
    },
    {
      "x": 4,
      "y": 41,
      "z": 12,
      "name": "Rock_Sandstone"
    },
    {
      "x": 4,
      "y": 42,
      "z": 12,
      "name": "Rock_Sandstone"
    },
    {
      "x": 4,
      "y": 43,
      "z": 12,
      "name": "Rock_Sandstone"
    },
    {
      "x": 4,
      "y": 44,
      "z": 12,
      "name": "Rock_Sandstone"
    },
    {
      "x": 4,
      "y": 45,
      "z": 12,
      "name": "Rock_Sandstone"
    },
    {
      "x": 4,
      "y": 32,
      "z": 13,
      "name": "Rock_Sandstone_White"
    },
    {
      "x": 4,
      "y": 33,
      "z": 13,
      "name": "Rock_Sandstone_White"
    },
    {
      "x": 4,
      "y": 34,
      "z": 13,
      "name": "Rock_Sandstone_White"
    },
    {
      "x": 4,
      "y": 35,
      "z": 13,
      "name": "Rock_Sandstone"
    },
    {
      "x": 4,
      "y": 36,
      "z": 13,
      "name": "Rock_Sandstone"
    },
    {
      "x": 4,
      "y": 39,
      "z": 13,
      "name": "Rock_Sandstone"
    },
    {
      "x": 4,
      "y": 40,
      "z": 13,
      "name": "Rock_Sandstone"
    },
    {
      "x": 4,
      "y": 41,
      "z": 13,
      "name": "Rock_Sandstone"
    },
    {
      "x": 4,
      "y": 42,
      "z": 13,
      "name": "Rock_Sandstone"
    },
    {
      "x": 4,
      "y": 43,
      "z": 13,
      "name": "Rock_Sandstone"
    },
    {
      "x": 4,
      "y": 44,
      "z": 13,
      "name": "Rock_Sandstone"
    },
    {
      "x": 4,
      "y": 45,
      "z": 13,
      "name": "Rock_Sandstone"
    },
    {
      "x": 4,
      "y": 32,
      "z": 14,
      "name": "Rock_Sandstone_White"
    },
    {
      "x": 4,
      "y": 33,
      "z": 14,
      "name": "Rock_Sandstone_White"
    },
    {
      "x": 4,
      "y": 34,
      "z": 14,
      "name": "Rock_Sandstone_White"
    },
    {
      "x": 4,
      "y": 35,
      "z": 14,
      "name": "Rock_Sandstone"
    },
    {
      "x": 4,
      "y": 39,
      "z": 14,
      "name": "Rock_Sandstone"
    },
    {
      "x": 4,
      "y": 40,
      "z": 14,
      "name": "Rock_Sandstone"
    },
    {
      "x": 4,
      "y": 41,
      "z": 14,
      "name": "Rock_Sandstone"
    },
    {
      "x": 4,
      "y": 42,
      "z": 14,
      "name": "Rock_Sandstone"
    },
    {
      "x": 4,
      "y": 43,
      "z": 14,
      "name": "Rock_Sandstone"
    },
    {
      "x": 4,
      "y": 44,
      "z": 14,
      "name": "Rock_Sandstone"
    },
    {
      "x": 4,
      "y": 40,
      "z": 15,
      "name": "Rock_Sandstone"
    },
    {
      "x": 4,
      "y": 41,
      "z": 15,
      "name": "Rock_Sandstone"
    },
    {
      "x": 4,
      "y": 42,
      "z": 15,
      "name": "Rock_Sandstone"
    },
    {
      "x": 4,
      "y": 43,
      "z": 15,
      "name": "Rock_Sandstone"
    },
    {
      "x": 4,
      "y": 44,
      "z": 15,
      "name": "Rock_Sandstone"
    },
    {
      "x": 4,
      "y": 40,
      "z": 16,
      "name": "Rock_Sandstone"
    },
    {
      "x": 4,
      "y": 41,
      "z": 16,
      "name": "Rock_Sandstone"
    },
    {
      "x": 4,
      "y": 42,
      "z": 16,
      "name": "Rock_Sandstone"
    },
    {
      "x": 4,
      "y": 43,
      "z": 16,
      "name": "Rock_Sandstone"
    },
    {
      "x": 5,
      "y": 34,
      "z": 5,
      "name": "Rock_Sandstone_White"
    },
    {
      "x": 5,
      "y": 35,
      "z": 5,
      "name": "Rock_Sandstone"
    },
    {
      "x": 5,
      "y": 36,
      "z": 5,
      "name": "Rock_Sandstone"
    },
    {
      "x": 5,
      "y": 39,
      "z": 5,
      "name": "Rock_Sandstone"
    },
    {
      "x": 5,
      "y": 40,
      "z": 5,
      "name": "Rock_Sandstone"
    },
    {
      "x": 5,
      "y": 41,
      "z": 5,
      "name": "Rock_Sandstone"
    },
    {
      "x": 5,
      "y": 42,
      "z": 5,
      "name": "Rock_Sandstone"
    },
    {
      "x": 5,
      "y": 43,
      "z": 5,
      "name": "Rock_Sandstone"
    },
    {
      "x": 5,
      "y": 44,
      "z": 5,
      "name": "Rock_Sandstone"
    },
    {
      "x": 5,
      "y": 45,
      "z": 5,
      "name": "Rock_Sandstone"
    },
    {
      "x": 5,
      "y": 32,
      "z": 6,
      "name": "Rock_Sandstone_White"
    },
    {
      "x": 5,
      "y": 33,
      "z": 6,
      "name": "Rock_Sandstone_White"
    },
    {
      "x": 5,
      "y": 34,
      "z": 6,
      "name": "Rock_Sandstone_White"
    },
    {
      "x": 5,
      "y": 35,
      "z": 6,
      "name": "Rock_Sandstone"
    },
    {
      "x": 5,
      "y": 36,
      "z": 6,
      "name": "Rock_Sandstone"
    },
    {
      "x": 5,
      "y": 37,
      "z": 6,
      "name": "Rock_Sandstone"
    },
    {
      "x": 5,
      "y": 38,
      "z": 6,
      "name": "Rock_Sandstone"
    },
    {
      "x": 5,
      "y": 39,
      "z": 6,
      "name": "Rock_Sandstone"
    },
    {
      "x": 5,
      "y": 40,
      "z": 6,
      "name": "Rock_Sandstone"
    },
    {
      "x": 5,
      "y": 41,
      "z": 6,
      "name": "Rock_Sandstone"
    },
    {
      "x": 5,
      "y": 42,
      "z": 6,
      "name": "Rock_Sandstone"
    },
    {
      "x": 5,
      "y": 43,
      "z": 6,
      "name": "Rock_Sandstone"
    },
    {
      "x": 5,
      "y": 44,
      "z": 6,
      "name": "Rock_Sandstone"
    },
    {
      "x": 5,
      "y": 45,
      "z": 6,
      "name": "Rock_Sandstone"
    },
    {
      "x": 5,
      "y": 31,
      "z": 7,
      "name": "Rock_Sandstone"
    },
    {
      "x": 5,
      "y": 32,
      "z": 7,
      "name": "Rock_Sandstone_White"
    },
    {
      "x": 5,
      "y": 33,
      "z": 7,
      "name": "Rock_Sandstone_White"
    },
    {
      "x": 5,
      "y": 34,
      "z": 7,
      "name": "Rock_Sandstone_White"
    },
    {
      "x": 5,
      "y": 35,
      "z": 7,
      "name": "Rock_Sandstone"
    },
    {
      "x": 5,
      "y": 36,
      "z": 7,
      "name": "Rock_Sandstone"
    },
    {
      "x": 5,
      "y": 37,
      "z": 7,
      "name": "Rock_Sandstone"
    },
    {
      "x": 5,
      "y": 38,
      "z": 7,
      "name": "Rock_Sandstone"
    },
    {
      "x": 5,
      "y": 39,
      "z": 7,
      "name": "Rock_Sandstone"
    },
    {
      "x": 5,
      "y": 40,
      "z": 7,
      "name": "Rock_Sandstone"
    },
    {
      "x": 5,
      "y": 41,
      "z": 7,
      "name": "Rock_Sandstone"
    },
    {
      "x": 5,
      "y": 42,
      "z": 7,
      "name": "Rock_Sandstone"
    },
    {
      "x": 5,
      "y": 43,
      "z": 7,
      "name": "Rock_Sandstone"
    },
    {
      "x": 5,
      "y": 44,
      "z": 7,
      "name": "Rock_Sandstone"
    },
    {
      "x": 5,
      "y": 45,
      "z": 7,
      "name": "Rock_Sandstone"
    },
    {
      "x": 5,
      "y": 31,
      "z": 8,
      "name": "Rock_Sandstone"
    },
    {
      "x": 5,
      "y": 32,
      "z": 8,
      "name": "Rock_Sandstone_White"
    },
    {
      "x": 5,
      "y": 33,
      "z": 8,
      "name": "Rock_Sandstone_White"
    },
    {
      "x": 5,
      "y": 34,
      "z": 8,
      "name": "Rock_Sandstone_White"
    },
    {
      "x": 5,
      "y": 35,
      "z": 8,
      "name": "Rock_Sandstone"
    },
    {
      "x": 5,
      "y": 36,
      "z": 8,
      "name": "Rock_Sandstone"
    },
    {
      "x": 5,
      "y": 37,
      "z": 8,
      "name": "Rock_Sandstone"
    },
    {
      "x": 5,
      "y": 38,
      "z": 8,
      "name": "Rock_Sandstone"
    },
    {
      "x": 5,
      "y": 39,
      "z": 8,
      "name": "Rock_Sandstone"
    },
    {
      "x": 5,
      "y": 40,
      "z": 8,
      "name": "Rock_Sandstone"
    },
    {
      "x": 5,
      "y": 41,
      "z": 8,
      "name": "Rock_Sandstone"
    },
    {
      "x": 5,
      "y": 42,
      "z": 8,
      "name": "Rock_Sandstone"
    },
    {
      "x": 5,
      "y": 43,
      "z": 8,
      "name": "Rock_Sandstone"
    },
    {
      "x": 5,
      "y": 44,
      "z": 8,
      "name": "Rock_Sandstone"
    },
    {
      "x": 5,
      "y": 45,
      "z": 8,
      "name": "Rock_Sandstone"
    },
    {
      "x": 5,
      "y": 31,
      "z": 9,
      "name": "Rock_Sandstone"
    },
    {
      "x": 5,
      "y": 32,
      "z": 9,
      "name": "Rock_Sandstone_White"
    },
    {
      "x": 5,
      "y": 33,
      "z": 9,
      "name": "Rock_Sandstone_White"
    },
    {
      "x": 5,
      "y": 34,
      "z": 9,
      "name": "Rock_Sandstone_White"
    },
    {
      "x": 5,
      "y": 35,
      "z": 9,
      "name": "Rock_Sandstone"
    },
    {
      "x": 5,
      "y": 36,
      "z": 9,
      "name": "Rock_Sandstone"
    },
    {
      "x": 5,
      "y": 37,
      "z": 9,
      "name": "Rock_Sandstone"
    },
    {
      "x": 5,
      "y": 38,
      "z": 9,
      "name": "Rock_Sandstone"
    },
    {
      "x": 5,
      "y": 39,
      "z": 9,
      "name": "Rock_Sandstone"
    },
    {
      "x": 5,
      "y": 40,
      "z": 9,
      "name": "Rock_Sandstone"
    },
    {
      "x": 5,
      "y": 41,
      "z": 9,
      "name": "Rock_Sandstone"
    },
    {
      "x": 5,
      "y": 42,
      "z": 9,
      "name": "Rock_Sandstone"
    },
    {
      "x": 5,
      "y": 43,
      "z": 9,
      "name": "Rock_Sandstone"
    },
    {
      "x": 5,
      "y": 44,
      "z": 9,
      "name": "Rock_Sandstone"
    },
    {
      "x": 5,
      "y": 31,
      "z": 10,
      "name": "Rock_Sandstone"
    },
    {
      "x": 5,
      "y": 32,
      "z": 10,
      "name": "Rock_Sandstone_White"
    },
    {
      "x": 5,
      "y": 33,
      "z": 10,
      "name": "Rock_Sandstone_White"
    },
    {
      "x": 5,
      "y": 34,
      "z": 10,
      "name": "Rock_Sandstone_White"
    },
    {
      "x": 5,
      "y": 35,
      "z": 10,
      "name": "Rock_Sandstone"
    },
    {
      "x": 5,
      "y": 36,
      "z": 10,
      "name": "Rock_Sandstone"
    },
    {
      "x": 5,
      "y": 37,
      "z": 10,
      "name": "Rock_Sandstone"
    },
    {
      "x": 5,
      "y": 38,
      "z": 10,
      "name": "Rock_Sandstone"
    },
    {
      "x": 5,
      "y": 39,
      "z": 10,
      "name": "Rock_Sandstone"
    },
    {
      "x": 5,
      "y": 40,
      "z": 10,
      "name": "Rock_Sandstone"
    },
    {
      "x": 5,
      "y": 41,
      "z": 10,
      "name": "Rock_Sandstone"
    },
    {
      "x": 5,
      "y": 42,
      "z": 10,
      "name": "Rock_Sandstone"
    },
    {
      "x": 5,
      "y": 43,
      "z": 10,
      "name": "Rock_Sandstone"
    },
    {
      "x": 5,
      "y": 44,
      "z": 10,
      "name": "Rock_Sandstone"
    },
    {
      "x": 5,
      "y": 31,
      "z": 11,
      "name": "Rock_Sandstone"
    },
    {
      "x": 5,
      "y": 32,
      "z": 11,
      "name": "Rock_Sandstone_White"
    },
    {
      "x": 5,
      "y": 33,
      "z": 11,
      "name": "Rock_Sandstone_White"
    },
    {
      "x": 5,
      "y": 34,
      "z": 11,
      "name": "Rock_Sandstone_White"
    },
    {
      "x": 5,
      "y": 35,
      "z": 11,
      "name": "Rock_Sandstone"
    },
    {
      "x": 5,
      "y": 36,
      "z": 11,
      "name": "Rock_Sandstone"
    },
    {
      "x": 5,
      "y": 40,
      "z": 11,
      "name": "Rock_Sandstone"
    },
    {
      "x": 5,
      "y": 41,
      "z": 11,
      "name": "Rock_Sandstone"
    },
    {
      "x": 5,
      "y": 42,
      "z": 11,
      "name": "Rock_Sandstone"
    },
    {
      "x": 5,
      "y": 43,
      "z": 11,
      "name": "Rock_Sandstone"
    },
    {
      "x": 5,
      "y": 44,
      "z": 11,
      "name": "Rock_Sandstone"
    },
    {
      "x": 5,
      "y": 45,
      "z": 11,
      "name": "Rock_Sandstone"
    },
    {
      "x": 5,
      "y": 31,
      "z": 12,
      "name": "Rock_Sandstone"
    },
    {
      "x": 5,
      "y": 32,
      "z": 12,
      "name": "Rock_Sandstone_White"
    },
    {
      "x": 5,
      "y": 33,
      "z": 12,
      "name": "Rock_Sandstone_White"
    },
    {
      "x": 5,
      "y": 34,
      "z": 12,
      "name": "Rock_Sandstone_White"
    },
    {
      "x": 5,
      "y": 35,
      "z": 12,
      "name": "Rock_Sandstone"
    },
    {
      "x": 5,
      "y": 36,
      "z": 12,
      "name": "Rock_Sandstone"
    },
    {
      "x": 5,
      "y": 39,
      "z": 12,
      "name": "Rock_Sandstone"
    },
    {
      "x": 5,
      "y": 40,
      "z": 12,
      "name": "Rock_Sandstone"
    },
    {
      "x": 5,
      "y": 41,
      "z": 12,
      "name": "Rock_Sandstone"
    },
    {
      "x": 5,
      "y": 42,
      "z": 12,
      "name": "Rock_Sandstone"
    },
    {
      "x": 5,
      "y": 43,
      "z": 12,
      "name": "Rock_Sandstone"
    },
    {
      "x": 5,
      "y": 44,
      "z": 12,
      "name": "Rock_Sandstone"
    },
    {
      "x": 5,
      "y": 45,
      "z": 12,
      "name": "Rock_Sandstone"
    },
    {
      "x": 5,
      "y": 31,
      "z": 13,
      "name": "Rock_Sandstone"
    },
    {
      "x": 5,
      "y": 32,
      "z": 13,
      "name": "Rock_Sandstone_White"
    },
    {
      "x": 5,
      "y": 33,
      "z": 13,
      "name": "Rock_Sandstone_White"
    },
    {
      "x": 5,
      "y": 34,
      "z": 13,
      "name": "Rock_Sandstone_White"
    },
    {
      "x": 5,
      "y": 35,
      "z": 13,
      "name": "Rock_Sandstone"
    },
    {
      "x": 5,
      "y": 36,
      "z": 13,
      "name": "Rock_Sandstone"
    },
    {
      "x": 5,
      "y": 38,
      "z": 13,
      "name": "Rock_Sandstone"
    },
    {
      "x": 5,
      "y": 39,
      "z": 13,
      "name": "Rock_Sandstone"
    },
    {
      "x": 5,
      "y": 40,
      "z": 13,
      "name": "Rock_Sandstone"
    },
    {
      "x": 5,
      "y": 41,
      "z": 13,
      "name": "Rock_Sandstone"
    },
    {
      "x": 5,
      "y": 42,
      "z": 13,
      "name": "Rock_Sandstone"
    },
    {
      "x": 5,
      "y": 43,
      "z": 13,
      "name": "Rock_Sandstone"
    },
    {
      "x": 5,
      "y": 44,
      "z": 13,
      "name": "Rock_Sandstone"
    },
    {
      "x": 5,
      "y": 45,
      "z": 13,
      "name": "Rock_Sandstone"
    },
    {
      "x": 5,
      "y": 32,
      "z": 14,
      "name": "Rock_Sandstone_White"
    },
    {
      "x": 5,
      "y": 33,
      "z": 14,
      "name": "Rock_Sandstone_White"
    },
    {
      "x": 5,
      "y": 34,
      "z": 14,
      "name": "Rock_Sandstone_White"
    },
    {
      "x": 5,
      "y": 35,
      "z": 14,
      "name": "Rock_Sandstone"
    },
    {
      "x": 5,
      "y": 36,
      "z": 14,
      "name": "Rock_Sandstone"
    },
    {
      "x": 5,
      "y": 38,
      "z": 14,
      "name": "Rock_Sandstone"
    },
    {
      "x": 5,
      "y": 39,
      "z": 14,
      "name": "Rock_Sandstone"
    },
    {
      "x": 5,
      "y": 40,
      "z": 14,
      "name": "Rock_Sandstone"
    },
    {
      "x": 5,
      "y": 41,
      "z": 14,
      "name": "Rock_Sandstone"
    },
    {
      "x": 5,
      "y": 42,
      "z": 14,
      "name": "Rock_Sandstone"
    },
    {
      "x": 5,
      "y": 43,
      "z": 14,
      "name": "Rock_Sandstone"
    },
    {
      "x": 5,
      "y": 44,
      "z": 14,
      "name": "Rock_Sandstone"
    },
    {
      "x": 5,
      "y": 45,
      "z": 14,
      "name": "Rock_Sandstone"
    },
    {
      "x": 5,
      "y": 33,
      "z": 15,
      "name": "Rock_Sandstone_White"
    },
    {
      "x": 5,
      "y": 34,
      "z": 15,
      "name": "Rock_Sandstone_White"
    },
    {
      "x": 5,
      "y": 35,
      "z": 15,
      "name": "Rock_Sandstone"
    },
    {
      "x": 5,
      "y": 38,
      "z": 15,
      "name": "Rock_Sandstone"
    },
    {
      "x": 5,
      "y": 39,
      "z": 15,
      "name": "Rock_Sandstone"
    },
    {
      "x": 5,
      "y": 40,
      "z": 15,
      "name": "Rock_Sandstone"
    },
    {
      "x": 5,
      "y": 41,
      "z": 15,
      "name": "Rock_Sandstone"
    },
    {
      "x": 5,
      "y": 42,
      "z": 15,
      "name": "Rock_Sandstone"
    },
    {
      "x": 5,
      "y": 43,
      "z": 15,
      "name": "Rock_Sandstone"
    },
    {
      "x": 5,
      "y": 44,
      "z": 15,
      "name": "Rock_Sandstone"
    },
    {
      "x": 5,
      "y": 45,
      "z": 15,
      "name": "Rock_Sandstone"
    },
    {
      "x": 5,
      "y": 38,
      "z": 16,
      "name": "Rock_Sandstone"
    },
    {
      "x": 5,
      "y": 39,
      "z": 16,
      "name": "Rock_Sandstone"
    },
    {
      "x": 5,
      "y": 40,
      "z": 16,
      "name": "Rock_Sandstone"
    },
    {
      "x": 5,
      "y": 41,
      "z": 16,
      "name": "Rock_Sandstone"
    },
    {
      "x": 5,
      "y": 42,
      "z": 16,
      "name": "Rock_Sandstone"
    },
    {
      "x": 5,
      "y": 43,
      "z": 16,
      "name": "Rock_Sandstone"
    },
    {
      "x": 5,
      "y": 44,
      "z": 16,
      "name": "Rock_Sandstone"
    },
    {
      "x": 5,
      "y": 45,
      "z": 16,
      "name": "Rock_Sandstone"
    },
    {
      "x": 5,
      "y": 39,
      "z": 17,
      "name": "Rock_Sandstone"
    },
    {
      "x": 5,
      "y": 40,
      "z": 17,
      "name": "Rock_Sandstone"
    },
    {
      "x": 5,
      "y": 41,
      "z": 17,
      "name": "Rock_Sandstone"
    },
    {
      "x": 5,
      "y": 42,
      "z": 17,
      "name": "Rock_Sandstone"
    },
    {
      "x": 5,
      "y": 43,
      "z": 17,
      "name": "Rock_Sandstone"
    },
    {
      "x": 6,
      "y": 39,
      "z": 4,
      "name": "Rock_Sandstone"
    },
    {
      "x": 6,
      "y": 40,
      "z": 4,
      "name": "Rock_Sandstone"
    },
    {
      "x": 6,
      "y": 41,
      "z": 4,
      "name": "Rock_Sandstone"
    },
    {
      "x": 6,
      "y": 42,
      "z": 4,
      "name": "Rock_Sandstone"
    },
    {
      "x": 6,
      "y": 32,
      "z": 5,
      "name": "Rock_Sandstone_White"
    },
    {
      "x": 6,
      "y": 33,
      "z": 5,
      "name": "Rock_Sandstone_White"
    },
    {
      "x": 6,
      "y": 34,
      "z": 5,
      "name": "Rock_Sandstone_White"
    },
    {
      "x": 6,
      "y": 35,
      "z": 5,
      "name": "Rock_Sandstone"
    },
    {
      "x": 6,
      "y": 36,
      "z": 5,
      "name": "Rock_Sandstone"
    },
    {
      "x": 6,
      "y": 38,
      "z": 5,
      "name": "Rock_Sandstone"
    },
    {
      "x": 6,
      "y": 39,
      "z": 5,
      "name": "Rock_Sandstone"
    },
    {
      "x": 6,
      "y": 40,
      "z": 5,
      "name": "Rock_Sandstone"
    },
    {
      "x": 6,
      "y": 41,
      "z": 5,
      "name": "Rock_Sandstone"
    },
    {
      "x": 6,
      "y": 42,
      "z": 5,
      "name": "Rock_Sandstone"
    },
    {
      "x": 6,
      "y": 43,
      "z": 5,
      "name": "Rock_Sandstone"
    },
    {
      "x": 6,
      "y": 44,
      "z": 5,
      "name": "Rock_Sandstone"
    },
    {
      "x": 6,
      "y": 45,
      "z": 5,
      "name": "Rock_Sandstone"
    },
    {
      "x": 6,
      "y": 32,
      "z": 6,
      "name": "Rock_Sandstone_White"
    },
    {
      "x": 6,
      "y": 33,
      "z": 6,
      "name": "Rock_Sandstone_White"
    },
    {
      "x": 6,
      "y": 34,
      "z": 6,
      "name": "Rock_Sandstone_White"
    },
    {
      "x": 6,
      "y": 35,
      "z": 6,
      "name": "Rock_Sandstone"
    },
    {
      "x": 6,
      "y": 36,
      "z": 6,
      "name": "Rock_Sandstone"
    },
    {
      "x": 6,
      "y": 37,
      "z": 6,
      "name": "Rock_Sandstone"
    },
    {
      "x": 6,
      "y": 38,
      "z": 6,
      "name": "Rock_Sandstone"
    },
    {
      "x": 6,
      "y": 39,
      "z": 6,
      "name": "Rock_Sandstone"
    },
    {
      "x": 6,
      "y": 40,
      "z": 6,
      "name": "Rock_Sandstone"
    },
    {
      "x": 6,
      "y": 41,
      "z": 6,
      "name": "Rock_Sandstone"
    },
    {
      "x": 6,
      "y": 42,
      "z": 6,
      "name": "Rock_Sandstone"
    },
    {
      "x": 6,
      "y": 43,
      "z": 6,
      "name": "Rock_Sandstone"
    },
    {
      "x": 6,
      "y": 44,
      "z": 6,
      "name": "Rock_Sandstone"
    },
    {
      "x": 6,
      "y": 45,
      "z": 6,
      "name": "Rock_Sandstone"
    },
    {
      "x": 6,
      "y": 31,
      "z": 7,
      "name": "Rock_Sandstone"
    },
    {
      "x": 6,
      "y": 32,
      "z": 7,
      "name": "Rock_Sandstone_White"
    },
    {
      "x": 6,
      "y": 33,
      "z": 7,
      "name": "Rock_Sandstone_White"
    },
    {
      "x": 6,
      "y": 34,
      "z": 7,
      "name": "Rock_Sandstone_White"
    },
    {
      "x": 6,
      "y": 35,
      "z": 7,
      "name": "Rock_Sandstone"
    },
    {
      "x": 6,
      "y": 36,
      "z": 7,
      "name": "Rock_Sandstone"
    },
    {
      "x": 6,
      "y": 37,
      "z": 7,
      "name": "Rock_Sandstone"
    },
    {
      "x": 6,
      "y": 38,
      "z": 7,
      "name": "Rock_Sandstone"
    },
    {
      "x": 6,
      "y": 39,
      "z": 7,
      "name": "Rock_Sandstone"
    },
    {
      "x": 6,
      "y": 40,
      "z": 7,
      "name": "Rock_Sandstone"
    },
    {
      "x": 6,
      "y": 41,
      "z": 7,
      "name": "Rock_Sandstone"
    },
    {
      "x": 6,
      "y": 42,
      "z": 7,
      "name": "Rock_Sandstone"
    },
    {
      "x": 6,
      "y": 43,
      "z": 7,
      "name": "Rock_Sandstone"
    },
    {
      "x": 6,
      "y": 44,
      "z": 7,
      "name": "Rock_Sandstone"
    },
    {
      "x": 6,
      "y": 45,
      "z": 7,
      "name": "Rock_Sandstone"
    },
    {
      "x": 6,
      "y": 26,
      "z": 8,
      "name": "Soil_Clay"
    },
    {
      "x": 6,
      "y": 27,
      "z": 8,
      "name": "Soil_Clay"
    },
    {
      "x": 6,
      "y": 28,
      "z": 8,
      "name": "Rock_Sandstone_White"
    },
    {
      "x": 6,
      "y": 29,
      "z": 8,
      "name": "Rock_Sandstone"
    },
    {
      "x": 6,
      "y": 31,
      "z": 8,
      "name": "Rock_Sandstone"
    },
    {
      "x": 6,
      "y": 32,
      "z": 8,
      "name": "Rock_Sandstone_White"
    },
    {
      "x": 6,
      "y": 33,
      "z": 8,
      "name": "Rock_Sandstone_White"
    },
    {
      "x": 6,
      "y": 34,
      "z": 8,
      "name": "Rock_Sandstone_White"
    },
    {
      "x": 6,
      "y": 35,
      "z": 8,
      "name": "Rock_Sandstone"
    },
    {
      "x": 6,
      "y": 36,
      "z": 8,
      "name": "Rock_Sandstone"
    },
    {
      "x": 6,
      "y": 37,
      "z": 8,
      "name": "Rock_Sandstone"
    },
    {
      "x": 6,
      "y": 38,
      "z": 8,
      "name": "Rock_Sandstone"
    },
    {
      "x": 6,
      "y": 39,
      "z": 8,
      "name": "Rock_Sandstone"
    },
    {
      "x": 6,
      "y": 40,
      "z": 8,
      "name": "Rock_Sandstone"
    },
    {
      "x": 6,
      "y": 41,
      "z": 8,
      "name": "Rock_Sandstone"
    },
    {
      "x": 6,
      "y": 42,
      "z": 8,
      "name": "Rock_Sandstone"
    },
    {
      "x": 6,
      "y": 43,
      "z": 8,
      "name": "Rock_Sandstone"
    },
    {
      "x": 6,
      "y": 44,
      "z": 8,
      "name": "Rock_Sandstone"
    },
    {
      "x": 6,
      "y": 45,
      "z": 8,
      "name": "Rock_Sandstone"
    },
    {
      "x": 6,
      "y": 24,
      "z": 9,
      "name": "Rock_Sandstone"
    },
    {
      "x": 6,
      "y": 25,
      "z": 9,
      "name": "Rock_Sandstone"
    },
    {
      "x": 6,
      "y": 26,
      "z": 9,
      "name": "Soil_Clay"
    },
    {
      "x": 6,
      "y": 27,
      "z": 9,
      "name": "Soil_Clay"
    },
    {
      "x": 6,
      "y": 28,
      "z": 9,
      "name": "Rock_Sandstone_White"
    },
    {
      "x": 6,
      "y": 29,
      "z": 9,
      "name": "Rock_Sandstone"
    },
    {
      "x": 6,
      "y": 30,
      "z": 9,
      "name": "Rock_Sandstone"
    },
    {
      "x": 6,
      "y": 31,
      "z": 9,
      "name": "Rock_Sandstone"
    },
    {
      "x": 6,
      "y": 32,
      "z": 9,
      "name": "Rock_Sandstone_White"
    },
    {
      "x": 6,
      "y": 33,
      "z": 9,
      "name": "Rock_Sandstone_White"
    },
    {
      "x": 6,
      "y": 34,
      "z": 9,
      "name": "Rock_Sandstone_White"
    },
    {
      "x": 6,
      "y": 35,
      "z": 9,
      "name": "Rock_Sandstone"
    },
    {
      "x": 6,
      "y": 36,
      "z": 9,
      "name": "Rock_Sandstone"
    },
    {
      "x": 6,
      "y": 37,
      "z": 9,
      "name": "Rock_Sandstone"
    },
    {
      "x": 6,
      "y": 38,
      "z": 9,
      "name": "Rock_Sandstone"
    },
    {
      "x": 6,
      "y": 39,
      "z": 9,
      "name": "Rock_Sandstone"
    },
    {
      "x": 6,
      "y": 40,
      "z": 9,
      "name": "Rock_Sandstone"
    },
    {
      "x": 6,
      "y": 41,
      "z": 9,
      "name": "Rock_Sandstone"
    },
    {
      "x": 6,
      "y": 42,
      "z": 9,
      "name": "Rock_Sandstone"
    },
    {
      "x": 6,
      "y": 43,
      "z": 9,
      "name": "Rock_Sandstone"
    },
    {
      "x": 6,
      "y": 44,
      "z": 9,
      "name": "Rock_Sandstone"
    },
    {
      "x": 6,
      "y": 45,
      "z": 9,
      "name": "Rock_Sandstone"
    },
    {
      "x": 6,
      "y": 24,
      "z": 10,
      "name": "Rock_Sandstone"
    },
    {
      "x": 6,
      "y": 25,
      "z": 10,
      "name": "Rock_Sandstone"
    },
    {
      "x": 6,
      "y": 26,
      "z": 10,
      "name": "Soil_Clay"
    },
    {
      "x": 6,
      "y": 27,
      "z": 10,
      "name": "Soil_Clay"
    },
    {
      "x": 6,
      "y": 28,
      "z": 10,
      "name": "Rock_Sandstone_White"
    },
    {
      "x": 6,
      "y": 29,
      "z": 10,
      "name": "Rock_Sandstone"
    },
    {
      "x": 6,
      "y": 30,
      "z": 10,
      "name": "Rock_Sandstone"
    },
    {
      "x": 6,
      "y": 31,
      "z": 10,
      "name": "Rock_Sandstone"
    },
    {
      "x": 6,
      "y": 32,
      "z": 10,
      "name": "Rock_Sandstone_White"
    },
    {
      "x": 6,
      "y": 33,
      "z": 10,
      "name": "Rock_Sandstone_White"
    },
    {
      "x": 6,
      "y": 34,
      "z": 10,
      "name": "Rock_Sandstone_White"
    },
    {
      "x": 6,
      "y": 35,
      "z": 10,
      "name": "Rock_Sandstone"
    },
    {
      "x": 6,
      "y": 36,
      "z": 10,
      "name": "Rock_Sandstone"
    },
    {
      "x": 6,
      "y": 37,
      "z": 10,
      "name": "Rock_Sandstone"
    },
    {
      "x": 6,
      "y": 38,
      "z": 10,
      "name": "Rock_Sandstone"
    },
    {
      "x": 6,
      "y": 39,
      "z": 10,
      "name": "Rock_Sandstone"
    },
    {
      "x": 6,
      "y": 40,
      "z": 10,
      "name": "Rock_Sandstone"
    },
    {
      "x": 6,
      "y": 41,
      "z": 10,
      "name": "Rock_Sandstone"
    },
    {
      "x": 6,
      "y": 42,
      "z": 10,
      "name": "Rock_Sandstone"
    },
    {
      "x": 6,
      "y": 43,
      "z": 10,
      "name": "Rock_Sandstone"
    },
    {
      "x": 6,
      "y": 44,
      "z": 10,
      "name": "Rock_Sandstone"
    },
    {
      "x": 6,
      "y": 45,
      "z": 10,
      "name": "Rock_Sandstone"
    },
    {
      "x": 6,
      "y": 24,
      "z": 11,
      "name": "Rock_Sandstone"
    },
    {
      "x": 6,
      "y": 25,
      "z": 11,
      "name": "Rock_Sandstone"
    },
    {
      "x": 6,
      "y": 26,
      "z": 11,
      "name": "Soil_Clay"
    },
    {
      "x": 6,
      "y": 27,
      "z": 11,
      "name": "Soil_Clay"
    },
    {
      "x": 6,
      "y": 28,
      "z": 11,
      "name": "Rock_Sandstone_White"
    },
    {
      "x": 6,
      "y": 29,
      "z": 11,
      "name": "Rock_Sandstone"
    },
    {
      "x": 6,
      "y": 30,
      "z": 11,
      "name": "Rock_Sandstone"
    },
    {
      "x": 6,
      "y": 31,
      "z": 11,
      "name": "Rock_Sandstone"
    },
    {
      "x": 6,
      "y": 32,
      "z": 11,
      "name": "Rock_Sandstone_White"
    },
    {
      "x": 6,
      "y": 33,
      "z": 11,
      "name": "Rock_Sandstone_White"
    },
    {
      "x": 6,
      "y": 34,
      "z": 11,
      "name": "Rock_Sandstone_White"
    },
    {
      "x": 6,
      "y": 35,
      "z": 11,
      "name": "Rock_Sandstone"
    },
    {
      "x": 6,
      "y": 36,
      "z": 11,
      "name": "Rock_Sandstone"
    },
    {
      "x": 6,
      "y": 37,
      "z": 11,
      "name": "Rock_Sandstone"
    },
    {
      "x": 6,
      "y": 38,
      "z": 11,
      "name": "Rock_Sandstone"
    },
    {
      "x": 6,
      "y": 39,
      "z": 11,
      "name": "Rock_Sandstone"
    },
    {
      "x": 6,
      "y": 40,
      "z": 11,
      "name": "Rock_Sandstone"
    },
    {
      "x": 6,
      "y": 41,
      "z": 11,
      "name": "Rock_Sandstone"
    },
    {
      "x": 6,
      "y": 42,
      "z": 11,
      "name": "Rock_Sandstone"
    },
    {
      "x": 6,
      "y": 43,
      "z": 11,
      "name": "Rock_Sandstone"
    },
    {
      "x": 6,
      "y": 44,
      "z": 11,
      "name": "Rock_Sandstone"
    },
    {
      "x": 6,
      "y": 45,
      "z": 11,
      "name": "Rock_Sandstone"
    },
    {
      "x": 6,
      "y": 28,
      "z": 12,
      "name": "Rock_Sandstone_White"
    },
    {
      "x": 6,
      "y": 29,
      "z": 12,
      "name": "Rock_Sandstone"
    },
    {
      "x": 6,
      "y": 30,
      "z": 12,
      "name": "Rock_Sandstone"
    },
    {
      "x": 6,
      "y": 31,
      "z": 12,
      "name": "Rock_Sandstone"
    },
    {
      "x": 6,
      "y": 32,
      "z": 12,
      "name": "Rock_Sandstone_White"
    },
    {
      "x": 6,
      "y": 33,
      "z": 12,
      "name": "Rock_Sandstone_White"
    },
    {
      "x": 6,
      "y": 34,
      "z": 12,
      "name": "Rock_Sandstone_White"
    },
    {
      "x": 6,
      "y": 35,
      "z": 12,
      "name": "Rock_Sandstone"
    },
    {
      "x": 6,
      "y": 36,
      "z": 12,
      "name": "Rock_Sandstone"
    },
    {
      "x": 6,
      "y": 37,
      "z": 12,
      "name": "Rock_Sandstone"
    },
    {
      "x": 6,
      "y": 38,
      "z": 12,
      "name": "Rock_Sandstone"
    },
    {
      "x": 6,
      "y": 39,
      "z": 12,
      "name": "Rock_Sandstone"
    },
    {
      "x": 6,
      "y": 40,
      "z": 12,
      "name": "Rock_Sandstone"
    },
    {
      "x": 6,
      "y": 41,
      "z": 12,
      "name": "Rock_Sandstone"
    },
    {
      "x": 6,
      "y": 42,
      "z": 12,
      "name": "Rock_Sandstone"
    },
    {
      "x": 6,
      "y": 43,
      "z": 12,
      "name": "Rock_Sandstone"
    },
    {
      "x": 6,
      "y": 44,
      "z": 12,
      "name": "Rock_Sandstone"
    },
    {
      "x": 6,
      "y": 45,
      "z": 12,
      "name": "Rock_Sandstone"
    },
    {
      "x": 6,
      "y": 30,
      "z": 13,
      "name": "Rock_Sandstone"
    },
    {
      "x": 6,
      "y": 31,
      "z": 13,
      "name": "Rock_Sandstone"
    },
    {
      "x": 6,
      "y": 32,
      "z": 13,
      "name": "Rock_Sandstone_White"
    },
    {
      "x": 6,
      "y": 33,
      "z": 13,
      "name": "Rock_Sandstone_White"
    },
    {
      "x": 6,
      "y": 34,
      "z": 13,
      "name": "Rock_Sandstone_White"
    },
    {
      "x": 6,
      "y": 35,
      "z": 13,
      "name": "Rock_Sandstone"
    },
    {
      "x": 6,
      "y": 36,
      "z": 13,
      "name": "Rock_Sandstone"
    },
    {
      "x": 6,
      "y": 37,
      "z": 13,
      "name": "Rock_Sandstone"
    },
    {
      "x": 6,
      "y": 38,
      "z": 13,
      "name": "Rock_Sandstone"
    },
    {
      "x": 6,
      "y": 39,
      "z": 13,
      "name": "Rock_Sandstone"
    },
    {
      "x": 6,
      "y": 40,
      "z": 13,
      "name": "Rock_Sandstone"
    },
    {
      "x": 6,
      "y": 41,
      "z": 13,
      "name": "Rock_Sandstone"
    },
    {
      "x": 6,
      "y": 42,
      "z": 13,
      "name": "Rock_Sandstone"
    },
    {
      "x": 6,
      "y": 43,
      "z": 13,
      "name": "Rock_Sandstone"
    },
    {
      "x": 6,
      "y": 44,
      "z": 13,
      "name": "Rock_Sandstone"
    },
    {
      "x": 6,
      "y": 45,
      "z": 13,
      "name": "Rock_Sandstone"
    },
    {
      "x": 6,
      "y": 32,
      "z": 14,
      "name": "Rock_Sandstone_White"
    },
    {
      "x": 6,
      "y": 33,
      "z": 14,
      "name": "Rock_Sandstone_White"
    },
    {
      "x": 6,
      "y": 34,
      "z": 14,
      "name": "Rock_Sandstone_White"
    },
    {
      "x": 6,
      "y": 35,
      "z": 14,
      "name": "Rock_Sandstone"
    },
    {
      "x": 6,
      "y": 36,
      "z": 14,
      "name": "Rock_Sandstone"
    },
    {
      "x": 6,
      "y": 37,
      "z": 14,
      "name": "Rock_Sandstone"
    },
    {
      "x": 6,
      "y": 38,
      "z": 14,
      "name": "Rock_Sandstone"
    },
    {
      "x": 6,
      "y": 39,
      "z": 14,
      "name": "Rock_Sandstone"
    },
    {
      "x": 6,
      "y": 40,
      "z": 14,
      "name": "Rock_Sandstone"
    },
    {
      "x": 6,
      "y": 41,
      "z": 14,
      "name": "Rock_Sandstone"
    },
    {
      "x": 6,
      "y": 42,
      "z": 14,
      "name": "Rock_Sandstone"
    },
    {
      "x": 6,
      "y": 43,
      "z": 14,
      "name": "Rock_Sandstone"
    },
    {
      "x": 6,
      "y": 44,
      "z": 14,
      "name": "Rock_Sandstone"
    },
    {
      "x": 6,
      "y": 45,
      "z": 14,
      "name": "Rock_Sandstone"
    },
    {
      "x": 6,
      "y": 32,
      "z": 15,
      "name": "Rock_Sandstone_White"
    },
    {
      "x": 6,
      "y": 33,
      "z": 15,
      "name": "Rock_Sandstone_White"
    },
    {
      "x": 6,
      "y": 34,
      "z": 15,
      "name": "Rock_Sandstone_White"
    },
    {
      "x": 6,
      "y": 35,
      "z": 15,
      "name": "Rock_Sandstone"
    },
    {
      "x": 6,
      "y": 37,
      "z": 15,
      "name": "Rock_Sandstone"
    },
    {
      "x": 6,
      "y": 38,
      "z": 15,
      "name": "Rock_Sandstone"
    },
    {
      "x": 6,
      "y": 39,
      "z": 15,
      "name": "Rock_Sandstone"
    },
    {
      "x": 6,
      "y": 40,
      "z": 15,
      "name": "Rock_Sandstone"
    },
    {
      "x": 6,
      "y": 41,
      "z": 15,
      "name": "Rock_Sandstone"
    },
    {
      "x": 6,
      "y": 42,
      "z": 15,
      "name": "Rock_Sandstone"
    },
    {
      "x": 6,
      "y": 43,
      "z": 15,
      "name": "Rock_Sandstone"
    },
    {
      "x": 6,
      "y": 44,
      "z": 15,
      "name": "Rock_Sandstone"
    },
    {
      "x": 6,
      "y": 45,
      "z": 15,
      "name": "Rock_Sandstone"
    },
    {
      "x": 6,
      "y": 37,
      "z": 16,
      "name": "Rock_Sandstone"
    },
    {
      "x": 6,
      "y": 38,
      "z": 16,
      "name": "Rock_Sandstone"
    },
    {
      "x": 6,
      "y": 39,
      "z": 16,
      "name": "Rock_Sandstone"
    },
    {
      "x": 6,
      "y": 40,
      "z": 16,
      "name": "Rock_Sandstone"
    },
    {
      "x": 6,
      "y": 41,
      "z": 16,
      "name": "Rock_Sandstone"
    },
    {
      "x": 6,
      "y": 42,
      "z": 16,
      "name": "Rock_Sandstone"
    },
    {
      "x": 6,
      "y": 43,
      "z": 16,
      "name": "Rock_Sandstone"
    },
    {
      "x": 6,
      "y": 44,
      "z": 16,
      "name": "Rock_Sandstone"
    },
    {
      "x": 6,
      "y": 45,
      "z": 16,
      "name": "Rock_Sandstone"
    },
    {
      "x": 6,
      "y": 38,
      "z": 17,
      "name": "Rock_Sandstone"
    },
    {
      "x": 6,
      "y": 39,
      "z": 17,
      "name": "Rock_Sandstone"
    },
    {
      "x": 6,
      "y": 40,
      "z": 17,
      "name": "Rock_Sandstone"
    },
    {
      "x": 6,
      "y": 41,
      "z": 17,
      "name": "Rock_Sandstone"
    },
    {
      "x": 6,
      "y": 42,
      "z": 17,
      "name": "Rock_Sandstone"
    },
    {
      "x": 6,
      "y": 43,
      "z": 17,
      "name": "Rock_Sandstone"
    },
    {
      "x": 6,
      "y": 44,
      "z": 17,
      "name": "Rock_Sandstone"
    },
    {
      "x": 7,
      "y": 39,
      "z": 4,
      "name": "Rock_Sandstone"
    },
    {
      "x": 7,
      "y": 40,
      "z": 4,
      "name": "Rock_Sandstone"
    },
    {
      "x": 7,
      "y": 41,
      "z": 4,
      "name": "Rock_Sandstone"
    },
    {
      "x": 7,
      "y": 42,
      "z": 4,
      "name": "Rock_Sandstone"
    },
    {
      "x": 7,
      "y": 43,
      "z": 4,
      "name": "Rock_Sandstone"
    },
    {
      "x": 7,
      "y": 32,
      "z": 5,
      "name": "Rock_Sandstone_White"
    },
    {
      "x": 7,
      "y": 33,
      "z": 5,
      "name": "Rock_Sandstone_White"
    },
    {
      "x": 7,
      "y": 34,
      "z": 5,
      "name": "Rock_Sandstone_White"
    },
    {
      "x": 7,
      "y": 35,
      "z": 5,
      "name": "Rock_Sandstone"
    },
    {
      "x": 7,
      "y": 36,
      "z": 5,
      "name": "Rock_Sandstone"
    },
    {
      "x": 7,
      "y": 38,
      "z": 5,
      "name": "Rock_Sandstone"
    },
    {
      "x": 7,
      "y": 39,
      "z": 5,
      "name": "Rock_Sandstone"
    },
    {
      "x": 7,
      "y": 40,
      "z": 5,
      "name": "Rock_Sandstone"
    },
    {
      "x": 7,
      "y": 41,
      "z": 5,
      "name": "Rock_Sandstone"
    },
    {
      "x": 7,
      "y": 42,
      "z": 5,
      "name": "Rock_Sandstone"
    },
    {
      "x": 7,
      "y": 43,
      "z": 5,
      "name": "Rock_Sandstone"
    },
    {
      "x": 7,
      "y": 44,
      "z": 5,
      "name": "Rock_Sandstone"
    },
    {
      "x": 7,
      "y": 45,
      "z": 5,
      "name": "Rock_Sandstone"
    },
    {
      "x": 7,
      "y": 31,
      "z": 6,
      "name": "Rock_Sandstone"
    },
    {
      "x": 7,
      "y": 32,
      "z": 6,
      "name": "Rock_Sandstone_White"
    },
    {
      "x": 7,
      "y": 33,
      "z": 6,
      "name": "Rock_Sandstone_White"
    },
    {
      "x": 7,
      "y": 34,
      "z": 6,
      "name": "Rock_Sandstone_White"
    },
    {
      "x": 7,
      "y": 35,
      "z": 6,
      "name": "Rock_Sandstone"
    },
    {
      "x": 7,
      "y": 36,
      "z": 6,
      "name": "Rock_Sandstone"
    },
    {
      "x": 7,
      "y": 37,
      "z": 6,
      "name": "Rock_Sandstone"
    },
    {
      "x": 7,
      "y": 38,
      "z": 6,
      "name": "Rock_Sandstone"
    },
    {
      "x": 7,
      "y": 39,
      "z": 6,
      "name": "Rock_Sandstone"
    },
    {
      "x": 7,
      "y": 40,
      "z": 6,
      "name": "Rock_Sandstone"
    },
    {
      "x": 7,
      "y": 41,
      "z": 6,
      "name": "Rock_Sandstone"
    },
    {
      "x": 7,
      "y": 42,
      "z": 6,
      "name": "Rock_Sandstone"
    },
    {
      "x": 7,
      "y": 43,
      "z": 6,
      "name": "Rock_Sandstone"
    },
    {
      "x": 7,
      "y": 44,
      "z": 6,
      "name": "Rock_Sandstone"
    },
    {
      "x": 7,
      "y": 45,
      "z": 6,
      "name": "Rock_Sandstone"
    },
    {
      "x": 7,
      "y": 24,
      "z": 7,
      "name": "Rock_Sandstone"
    },
    {
      "x": 7,
      "y": 25,
      "z": 7,
      "name": "Rock_Sandstone"
    },
    {
      "x": 7,
      "y": 26,
      "z": 7,
      "name": "Soil_Clay"
    },
    {
      "x": 7,
      "y": 27,
      "z": 7,
      "name": "Soil_Clay"
    },
    {
      "x": 7,
      "y": 28,
      "z": 7,
      "name": "Rock_Sandstone_White"
    },
    {
      "x": 7,
      "y": 29,
      "z": 7,
      "name": "Rock_Sandstone"
    },
    {
      "x": 7,
      "y": 31,
      "z": 7,
      "name": "Rock_Sandstone"
    },
    {
      "x": 7,
      "y": 32,
      "z": 7,
      "name": "Rock_Sandstone_White"
    },
    {
      "x": 7,
      "y": 33,
      "z": 7,
      "name": "Rock_Sandstone_White"
    },
    {
      "x": 7,
      "y": 34,
      "z": 7,
      "name": "Rock_Sandstone_White"
    },
    {
      "x": 7,
      "y": 35,
      "z": 7,
      "name": "Rock_Sandstone"
    },
    {
      "x": 7,
      "y": 36,
      "z": 7,
      "name": "Rock_Sandstone"
    },
    {
      "x": 7,
      "y": 37,
      "z": 7,
      "name": "Rock_Sandstone"
    },
    {
      "x": 7,
      "y": 38,
      "z": 7,
      "name": "Rock_Sandstone"
    },
    {
      "x": 7,
      "y": 39,
      "z": 7,
      "name": "Rock_Sandstone"
    },
    {
      "x": 7,
      "y": 40,
      "z": 7,
      "name": "Rock_Sandstone"
    },
    {
      "x": 7,
      "y": 41,
      "z": 7,
      "name": "Rock_Sandstone"
    },
    {
      "x": 7,
      "y": 42,
      "z": 7,
      "name": "Rock_Sandstone"
    },
    {
      "x": 7,
      "y": 43,
      "z": 7,
      "name": "Rock_Sandstone"
    },
    {
      "x": 7,
      "y": 44,
      "z": 7,
      "name": "Rock_Sandstone"
    },
    {
      "x": 7,
      "y": 45,
      "z": 7,
      "name": "Rock_Sandstone"
    },
    {
      "x": 7,
      "y": 5,
      "z": 8,
      "name": "Rock_Sandstone"
    },
    {
      "x": 7,
      "y": 6,
      "z": 8,
      "name": "Rock_Sandstone"
    },
    {
      "x": 7,
      "y": 7,
      "z": 8,
      "name": "Rock_Sandstone"
    },
    {
      "x": 7,
      "y": 22,
      "z": 8,
      "name": "Rock_Sandstone_White"
    },
    {
      "x": 7,
      "y": 23,
      "z": 8,
      "name": "Rock_Sandstone"
    },
    {
      "x": 7,
      "y": 24,
      "z": 8,
      "name": "Rock_Sandstone"
    },
    {
      "x": 7,
      "y": 25,
      "z": 8,
      "name": "Rock_Sandstone"
    },
    {
      "x": 7,
      "y": 26,
      "z": 8,
      "name": "Soil_Clay"
    },
    {
      "x": 7,
      "y": 27,
      "z": 8,
      "name": "Soil_Clay"
    },
    {
      "x": 7,
      "y": 28,
      "z": 8,
      "name": "Rock_Sandstone_White"
    },
    {
      "x": 7,
      "y": 29,
      "z": 8,
      "name": "Rock_Sandstone"
    },
    {
      "x": 7,
      "y": 30,
      "z": 8,
      "name": "Rock_Sandstone"
    },
    {
      "x": 7,
      "y": 31,
      "z": 8,
      "name": "Rock_Sandstone"
    },
    {
      "x": 7,
      "y": 32,
      "z": 8,
      "name": "Rock_Sandstone_White"
    },
    {
      "x": 7,
      "y": 33,
      "z": 8,
      "name": "Rock_Sandstone_White"
    },
    {
      "x": 7,
      "y": 34,
      "z": 8,
      "name": "Rock_Sandstone_White"
    },
    {
      "x": 7,
      "y": 35,
      "z": 8,
      "name": "Rock_Sandstone"
    },
    {
      "x": 7,
      "y": 36,
      "z": 8,
      "name": "Rock_Sandstone"
    },
    {
      "x": 7,
      "y": 37,
      "z": 8,
      "name": "Rock_Sandstone"
    },
    {
      "x": 7,
      "y": 38,
      "z": 8,
      "name": "Rock_Sandstone"
    },
    {
      "x": 7,
      "y": 39,
      "z": 8,
      "name": "Rock_Sandstone"
    },
    {
      "x": 7,
      "y": 40,
      "z": 8,
      "name": "Rock_Sandstone"
    },
    {
      "x": 7,
      "y": 41,
      "z": 8,
      "name": "Rock_Sandstone"
    },
    {
      "x": 7,
      "y": 42,
      "z": 8,
      "name": "Rock_Sandstone"
    },
    {
      "x": 7,
      "y": 43,
      "z": 8,
      "name": "Rock_Sandstone"
    },
    {
      "x": 7,
      "y": 44,
      "z": 8,
      "name": "Rock_Sandstone"
    },
    {
      "x": 7,
      "y": 45,
      "z": 8,
      "name": "Rock_Sandstone"
    },
    {
      "x": 7,
      "y": 2,
      "z": 9,
      "name": "Rock_Sandstone"
    },
    {
      "x": 7,
      "y": 3,
      "z": 9,
      "name": "Rock_Sandstone"
    },
    {
      "x": 7,
      "y": 4,
      "z": 9,
      "name": "Rock_Sandstone"
    },
    {
      "x": 7,
      "y": 5,
      "z": 9,
      "name": "Rock_Sandstone"
    },
    {
      "x": 7,
      "y": 6,
      "z": 9,
      "name": "Rock_Sandstone"
    },
    {
      "x": 7,
      "y": 7,
      "z": 9,
      "name": "Rock_Sandstone"
    },
    {
      "x": 7,
      "y": 8,
      "z": 9,
      "name": "Rock_Sandstone"
    },
    {
      "x": 7,
      "y": 11,
      "z": 9,
      "name": "Rock_Sandstone_Red"
    },
    {
      "x": 7,
      "y": 12,
      "z": 9,
      "name": "Rock_Sandstone_Red"
    },
    {
      "x": 7,
      "y": 13,
      "z": 9,
      "name": "Soil_Clay"
    },
    {
      "x": 7,
      "y": 14,
      "z": 9,
      "name": "Soil_Clay"
    },
    {
      "x": 7,
      "y": 20,
      "z": 9,
      "name": "Rock_Sandstone"
    },
    {
      "x": 7,
      "y": 21,
      "z": 9,
      "name": "Rock_Sandstone_Red"
    },
    {
      "x": 7,
      "y": 22,
      "z": 9,
      "name": "Rock_Sandstone_White"
    },
    {
      "x": 7,
      "y": 23,
      "z": 9,
      "name": "Rock_Sandstone"
    },
    {
      "x": 7,
      "y": 24,
      "z": 9,
      "name": "Rock_Sandstone"
    },
    {
      "x": 7,
      "y": 25,
      "z": 9,
      "name": "Rock_Sandstone"
    },
    {
      "x": 7,
      "y": 26,
      "z": 9,
      "name": "Soil_Clay"
    },
    {
      "x": 7,
      "y": 27,
      "z": 9,
      "name": "Soil_Clay"
    },
    {
      "x": 7,
      "y": 28,
      "z": 9,
      "name": "Rock_Sandstone_White"
    },
    {
      "x": 7,
      "y": 29,
      "z": 9,
      "name": "Rock_Sandstone"
    },
    {
      "x": 7,
      "y": 30,
      "z": 9,
      "name": "Rock_Sandstone"
    },
    {
      "x": 7,
      "y": 31,
      "z": 9,
      "name": "Rock_Sandstone"
    },
    {
      "x": 7,
      "y": 32,
      "z": 9,
      "name": "Rock_Sandstone_White"
    },
    {
      "x": 7,
      "y": 33,
      "z": 9,
      "name": "Rock_Sandstone_White"
    },
    {
      "x": 7,
      "y": 34,
      "z": 9,
      "name": "Rock_Sandstone_White"
    },
    {
      "x": 7,
      "y": 35,
      "z": 9,
      "name": "Rock_Sandstone"
    },
    {
      "x": 7,
      "y": 36,
      "z": 9,
      "name": "Rock_Sandstone"
    },
    {
      "x": 7,
      "y": 37,
      "z": 9,
      "name": "Rock_Sandstone"
    },
    {
      "x": 7,
      "y": 38,
      "z": 9,
      "name": "Rock_Sandstone"
    },
    {
      "x": 7,
      "y": 39,
      "z": 9,
      "name": "Rock_Sandstone"
    },
    {
      "x": 7,
      "y": 40,
      "z": 9,
      "name": "Rock_Sandstone"
    },
    {
      "x": 7,
      "y": 41,
      "z": 9,
      "name": "Rock_Sandstone"
    },
    {
      "x": 7,
      "y": 42,
      "z": 9,
      "name": "Rock_Sandstone"
    },
    {
      "x": 7,
      "y": 43,
      "z": 9,
      "name": "Rock_Sandstone"
    },
    {
      "x": 7,
      "y": 44,
      "z": 9,
      "name": "Rock_Sandstone"
    },
    {
      "x": 7,
      "y": 45,
      "z": 9,
      "name": "Rock_Sandstone"
    },
    {
      "x": 7,
      "y": 1,
      "z": 10,
      "name": "Rock_Sandstone"
    },
    {
      "x": 7,
      "y": 2,
      "z": 10,
      "name": "Rock_Sandstone"
    },
    {
      "x": 7,
      "y": 3,
      "z": 10,
      "name": "Rock_Sandstone"
    },
    {
      "x": 7,
      "y": 4,
      "z": 10,
      "name": "Rock_Sandstone"
    },
    {
      "x": 7,
      "y": 5,
      "z": 10,
      "name": "Rock_Sandstone"
    },
    {
      "x": 7,
      "y": 6,
      "z": 10,
      "name": "Rock_Sandstone"
    },
    {
      "x": 7,
      "y": 7,
      "z": 10,
      "name": "Rock_Sandstone"
    },
    {
      "x": 7,
      "y": 8,
      "z": 10,
      "name": "Rock_Sandstone"
    },
    {
      "x": 7,
      "y": 9,
      "z": 10,
      "name": "Soil_Clay"
    },
    {
      "x": 7,
      "y": 10,
      "z": 10,
      "name": "Soil_Clay"
    },
    {
      "x": 7,
      "y": 11,
      "z": 10,
      "name": "Rock_Sandstone_Red"
    },
    {
      "x": 7,
      "y": 12,
      "z": 10,
      "name": "Rock_Sandstone_Red"
    },
    {
      "x": 7,
      "y": 13,
      "z": 10,
      "name": "Soil_Clay"
    },
    {
      "x": 7,
      "y": 14,
      "z": 10,
      "name": "Soil_Clay"
    },
    {
      "x": 7,
      "y": 15,
      "z": 10,
      "name": "Rock_Sandstone_Red"
    },
    {
      "x": 7,
      "y": 16,
      "z": 10,
      "name": "Soil_Dirt_Dry"
    },
    {
      "x": 7,
      "y": 17,
      "z": 10,
      "name": "Soil_Clay"
    },
    {
      "x": 7,
      "y": 20,
      "z": 10,
      "name": "Rock_Sandstone"
    },
    {
      "x": 7,
      "y": 21,
      "z": 10,
      "name": "Rock_Sandstone_Red"
    },
    {
      "x": 7,
      "y": 22,
      "z": 10,
      "name": "Rock_Sandstone_White"
    },
    {
      "x": 7,
      "y": 23,
      "z": 10,
      "name": "Rock_Sandstone"
    },
    {
      "x": 7,
      "y": 24,
      "z": 10,
      "name": "Rock_Sandstone"
    },
    {
      "x": 7,
      "y": 25,
      "z": 10,
      "name": "Rock_Sandstone"
    },
    {
      "x": 7,
      "y": 26,
      "z": 10,
      "name": "Soil_Clay"
    },
    {
      "x": 7,
      "y": 27,
      "z": 10,
      "name": "Soil_Clay"
    },
    {
      "x": 7,
      "y": 28,
      "z": 10,
      "name": "Rock_Sandstone_White"
    },
    {
      "x": 7,
      "y": 29,
      "z": 10,
      "name": "Rock_Sandstone"
    },
    {
      "x": 7,
      "y": 30,
      "z": 10,
      "name": "Rock_Sandstone"
    },
    {
      "x": 7,
      "y": 31,
      "z": 10,
      "name": "Rock_Sandstone"
    },
    {
      "x": 7,
      "y": 32,
      "z": 10,
      "name": "Rock_Sandstone_White"
    },
    {
      "x": 7,
      "y": 33,
      "z": 10,
      "name": "Rock_Sandstone_White"
    },
    {
      "x": 7,
      "y": 34,
      "z": 10,
      "name": "Rock_Sandstone_White"
    },
    {
      "x": 7,
      "y": 35,
      "z": 10,
      "name": "Rock_Sandstone"
    },
    {
      "x": 7,
      "y": 36,
      "z": 10,
      "name": "Rock_Sandstone"
    },
    {
      "x": 7,
      "y": 37,
      "z": 10,
      "name": "Rock_Sandstone"
    },
    {
      "x": 7,
      "y": 38,
      "z": 10,
      "name": "Rock_Sandstone"
    },
    {
      "x": 7,
      "y": 39,
      "z": 10,
      "name": "Rock_Sandstone"
    },
    {
      "x": 7,
      "y": 40,
      "z": 10,
      "name": "Rock_Sandstone"
    },
    {
      "x": 7,
      "y": 41,
      "z": 10,
      "name": "Rock_Sandstone"
    },
    {
      "x": 7,
      "y": 42,
      "z": 10,
      "name": "Rock_Sandstone"
    },
    {
      "x": 7,
      "y": 43,
      "z": 10,
      "name": "Rock_Sandstone"
    },
    {
      "x": 7,
      "y": 44,
      "z": 10,
      "name": "Rock_Sandstone"
    },
    {
      "x": 7,
      "y": 45,
      "z": 10,
      "name": "Rock_Sandstone"
    },
    {
      "x": 7,
      "y": 0,
      "z": 11,
      "name": "Rock_Sandstone"
    },
    {
      "x": 7,
      "y": 1,
      "z": 11,
      "name": "Rock_Sandstone"
    },
    {
      "x": 7,
      "y": 2,
      "z": 11,
      "name": "Rock_Sandstone"
    },
    {
      "x": 7,
      "y": 3,
      "z": 11,
      "name": "Rock_Sandstone"
    },
    {
      "x": 7,
      "y": 4,
      "z": 11,
      "name": "Rock_Sandstone"
    },
    {
      "x": 7,
      "y": 5,
      "z": 11,
      "name": "Rock_Sandstone"
    },
    {
      "x": 7,
      "y": 6,
      "z": 11,
      "name": "Rock_Sandstone"
    },
    {
      "x": 7,
      "y": 7,
      "z": 11,
      "name": "Rock_Sandstone"
    },
    {
      "x": 7,
      "y": 8,
      "z": 11,
      "name": "Rock_Sandstone"
    },
    {
      "x": 7,
      "y": 9,
      "z": 11,
      "name": "Soil_Clay"
    },
    {
      "x": 7,
      "y": 10,
      "z": 11,
      "name": "Soil_Clay"
    },
    {
      "x": 7,
      "y": 11,
      "z": 11,
      "name": "Rock_Sandstone_Red"
    },
    {
      "x": 7,
      "y": 12,
      "z": 11,
      "name": "Rock_Sandstone_Red"
    },
    {
      "x": 7,
      "y": 13,
      "z": 11,
      "name": "Soil_Clay"
    },
    {
      "x": 7,
      "y": 14,
      "z": 11,
      "name": "Soil_Clay"
    },
    {
      "x": 7,
      "y": 15,
      "z": 11,
      "name": "Rock_Sandstone_Red"
    },
    {
      "x": 7,
      "y": 16,
      "z": 11,
      "name": "Soil_Dirt_Dry"
    },
    {
      "x": 7,
      "y": 17,
      "z": 11,
      "name": "Soil_Clay"
    },
    {
      "x": 7,
      "y": 18,
      "z": 11,
      "name": "Soil_Clay"
    },
    {
      "x": 7,
      "y": 20,
      "z": 11,
      "name": "Rock_Sandstone"
    },
    {
      "x": 7,
      "y": 21,
      "z": 11,
      "name": "Rock_Sandstone_Red"
    },
    {
      "x": 7,
      "y": 22,
      "z": 11,
      "name": "Rock_Sandstone_White"
    },
    {
      "x": 7,
      "y": 23,
      "z": 11,
      "name": "Rock_Sandstone"
    },
    {
      "x": 7,
      "y": 24,
      "z": 11,
      "name": "Rock_Sandstone"
    },
    {
      "x": 7,
      "y": 25,
      "z": 11,
      "name": "Rock_Sandstone"
    },
    {
      "x": 7,
      "y": 26,
      "z": 11,
      "name": "Soil_Clay"
    },
    {
      "x": 7,
      "y": 27,
      "z": 11,
      "name": "Soil_Clay"
    },
    {
      "x": 7,
      "y": 28,
      "z": 11,
      "name": "Rock_Sandstone_White"
    },
    {
      "x": 7,
      "y": 29,
      "z": 11,
      "name": "Rock_Sandstone"
    },
    {
      "x": 7,
      "y": 30,
      "z": 11,
      "name": "Rock_Sandstone"
    },
    {
      "x": 7,
      "y": 31,
      "z": 11,
      "name": "Rock_Sandstone"
    },
    {
      "x": 7,
      "y": 32,
      "z": 11,
      "name": "Rock_Sandstone_White"
    },
    {
      "x": 7,
      "y": 33,
      "z": 11,
      "name": "Rock_Sandstone_White"
    },
    {
      "x": 7,
      "y": 34,
      "z": 11,
      "name": "Rock_Sandstone_White"
    },
    {
      "x": 7,
      "y": 35,
      "z": 11,
      "name": "Rock_Sandstone"
    },
    {
      "x": 7,
      "y": 36,
      "z": 11,
      "name": "Rock_Sandstone"
    },
    {
      "x": 7,
      "y": 37,
      "z": 11,
      "name": "Rock_Sandstone"
    },
    {
      "x": 7,
      "y": 38,
      "z": 11,
      "name": "Rock_Sandstone"
    },
    {
      "x": 7,
      "y": 39,
      "z": 11,
      "name": "Rock_Sandstone"
    },
    {
      "x": 7,
      "y": 40,
      "z": 11,
      "name": "Rock_Sandstone"
    },
    {
      "x": 7,
      "y": 41,
      "z": 11,
      "name": "Rock_Sandstone"
    },
    {
      "x": 7,
      "y": 42,
      "z": 11,
      "name": "Rock_Sandstone"
    },
    {
      "x": 7,
      "y": 43,
      "z": 11,
      "name": "Rock_Sandstone"
    },
    {
      "x": 7,
      "y": 44,
      "z": 11,
      "name": "Rock_Sandstone"
    },
    {
      "x": 7,
      "y": 45,
      "z": 11,
      "name": "Rock_Sandstone"
    },
    {
      "x": 7,
      "y": 0,
      "z": 12,
      "name": "Rock_Sandstone"
    },
    {
      "x": 7,
      "y": 1,
      "z": 12,
      "name": "Rock_Sandstone"
    },
    {
      "x": 7,
      "y": 2,
      "z": 12,
      "name": "Rock_Sandstone"
    },
    {
      "x": 7,
      "y": 3,
      "z": 12,
      "name": "Rock_Sandstone"
    },
    {
      "x": 7,
      "y": 4,
      "z": 12,
      "name": "Rock_Sandstone"
    },
    {
      "x": 7,
      "y": 5,
      "z": 12,
      "name": "Rock_Sandstone"
    },
    {
      "x": 7,
      "y": 6,
      "z": 12,
      "name": "Rock_Sandstone"
    },
    {
      "x": 7,
      "y": 7,
      "z": 12,
      "name": "Rock_Sandstone"
    },
    {
      "x": 7,
      "y": 8,
      "z": 12,
      "name": "Rock_Sandstone"
    },
    {
      "x": 7,
      "y": 9,
      "z": 12,
      "name": "Soil_Clay"
    },
    {
      "x": 7,
      "y": 10,
      "z": 12,
      "name": "Soil_Clay"
    },
    {
      "x": 7,
      "y": 11,
      "z": 12,
      "name": "Rock_Sandstone_Red"
    },
    {
      "x": 7,
      "y": 12,
      "z": 12,
      "name": "Rock_Sandstone_Red"
    },
    {
      "x": 7,
      "y": 13,
      "z": 12,
      "name": "Soil_Clay"
    },
    {
      "x": 7,
      "y": 14,
      "z": 12,
      "name": "Soil_Clay"
    },
    {
      "x": 7,
      "y": 15,
      "z": 12,
      "name": "Rock_Sandstone_Red"
    },
    {
      "x": 7,
      "y": 16,
      "z": 12,
      "name": "Soil_Dirt_Dry"
    },
    {
      "x": 7,
      "y": 17,
      "z": 12,
      "name": "Soil_Clay"
    },
    {
      "x": 7,
      "y": 18,
      "z": 12,
      "name": "Soil_Clay"
    },
    {
      "x": 7,
      "y": 20,
      "z": 12,
      "name": "Rock_Sandstone"
    },
    {
      "x": 7,
      "y": 21,
      "z": 12,
      "name": "Rock_Sandstone_Red"
    },
    {
      "x": 7,
      "y": 22,
      "z": 12,
      "name": "Rock_Sandstone_White"
    },
    {
      "x": 7,
      "y": 23,
      "z": 12,
      "name": "Rock_Sandstone"
    },
    {
      "x": 7,
      "y": 24,
      "z": 12,
      "name": "Rock_Sandstone"
    },
    {
      "x": 7,
      "y": 25,
      "z": 12,
      "name": "Rock_Sandstone"
    },
    {
      "x": 7,
      "y": 26,
      "z": 12,
      "name": "Soil_Clay"
    },
    {
      "x": 7,
      "y": 27,
      "z": 12,
      "name": "Soil_Clay"
    },
    {
      "x": 7,
      "y": 28,
      "z": 12,
      "name": "Rock_Sandstone_White"
    },
    {
      "x": 7,
      "y": 29,
      "z": 12,
      "name": "Rock_Sandstone"
    },
    {
      "x": 7,
      "y": 30,
      "z": 12,
      "name": "Rock_Sandstone"
    },
    {
      "x": 7,
      "y": 31,
      "z": 12,
      "name": "Rock_Sandstone"
    },
    {
      "x": 7,
      "y": 32,
      "z": 12,
      "name": "Rock_Sandstone_White"
    },
    {
      "x": 7,
      "y": 33,
      "z": 12,
      "name": "Rock_Sandstone_White"
    },
    {
      "x": 7,
      "y": 34,
      "z": 12,
      "name": "Rock_Sandstone_White"
    },
    {
      "x": 7,
      "y": 35,
      "z": 12,
      "name": "Rock_Sandstone"
    },
    {
      "x": 7,
      "y": 36,
      "z": 12,
      "name": "Rock_Sandstone"
    },
    {
      "x": 7,
      "y": 37,
      "z": 12,
      "name": "Rock_Sandstone"
    },
    {
      "x": 7,
      "y": 38,
      "z": 12,
      "name": "Rock_Sandstone"
    },
    {
      "x": 7,
      "y": 39,
      "z": 12,
      "name": "Rock_Sandstone"
    },
    {
      "x": 7,
      "y": 40,
      "z": 12,
      "name": "Rock_Sandstone"
    },
    {
      "x": 7,
      "y": 41,
      "z": 12,
      "name": "Rock_Sandstone"
    },
    {
      "x": 7,
      "y": 42,
      "z": 12,
      "name": "Rock_Sandstone"
    },
    {
      "x": 7,
      "y": 43,
      "z": 12,
      "name": "Rock_Sandstone"
    },
    {
      "x": 7,
      "y": 44,
      "z": 12,
      "name": "Rock_Sandstone"
    },
    {
      "x": 7,
      "y": 45,
      "z": 12,
      "name": "Rock_Sandstone"
    },
    {
      "x": 7,
      "y": 0,
      "z": 13,
      "name": "Rock_Sandstone"
    },
    {
      "x": 7,
      "y": 1,
      "z": 13,
      "name": "Rock_Sandstone"
    },
    {
      "x": 7,
      "y": 2,
      "z": 13,
      "name": "Rock_Sandstone"
    },
    {
      "x": 7,
      "y": 3,
      "z": 13,
      "name": "Rock_Sandstone"
    },
    {
      "x": 7,
      "y": 4,
      "z": 13,
      "name": "Rock_Sandstone"
    },
    {
      "x": 7,
      "y": 5,
      "z": 13,
      "name": "Rock_Sandstone"
    },
    {
      "x": 7,
      "y": 6,
      "z": 13,
      "name": "Rock_Sandstone"
    },
    {
      "x": 7,
      "y": 7,
      "z": 13,
      "name": "Rock_Sandstone"
    },
    {
      "x": 7,
      "y": 8,
      "z": 13,
      "name": "Rock_Sandstone"
    },
    {
      "x": 7,
      "y": 9,
      "z": 13,
      "name": "Soil_Clay"
    },
    {
      "x": 7,
      "y": 10,
      "z": 13,
      "name": "Soil_Clay"
    },
    {
      "x": 7,
      "y": 11,
      "z": 13,
      "name": "Rock_Sandstone_Red"
    },
    {
      "x": 7,
      "y": 12,
      "z": 13,
      "name": "Rock_Sandstone_Red"
    },
    {
      "x": 7,
      "y": 13,
      "z": 13,
      "name": "Soil_Clay"
    },
    {
      "x": 7,
      "y": 14,
      "z": 13,
      "name": "Soil_Clay"
    },
    {
      "x": 7,
      "y": 15,
      "z": 13,
      "name": "Rock_Sandstone_Red"
    },
    {
      "x": 7,
      "y": 16,
      "z": 13,
      "name": "Soil_Dirt_Dry"
    },
    {
      "x": 7,
      "y": 17,
      "z": 13,
      "name": "Soil_Clay"
    },
    {
      "x": 7,
      "y": 18,
      "z": 13,
      "name": "Soil_Clay"
    },
    {
      "x": 7,
      "y": 22,
      "z": 13,
      "name": "Rock_Sandstone_White"
    },
    {
      "x": 7,
      "y": 23,
      "z": 13,
      "name": "Rock_Sandstone"
    },
    {
      "x": 7,
      "y": 24,
      "z": 13,
      "name": "Rock_Sandstone"
    },
    {
      "x": 7,
      "y": 27,
      "z": 13,
      "name": "Soil_Clay"
    },
    {
      "x": 7,
      "y": 28,
      "z": 13,
      "name": "Rock_Sandstone_White"
    },
    {
      "x": 7,
      "y": 29,
      "z": 13,
      "name": "Rock_Sandstone"
    },
    {
      "x": 7,
      "y": 30,
      "z": 13,
      "name": "Rock_Sandstone"
    },
    {
      "x": 7,
      "y": 31,
      "z": 13,
      "name": "Rock_Sandstone"
    },
    {
      "x": 7,
      "y": 32,
      "z": 13,
      "name": "Rock_Sandstone_White"
    },
    {
      "x": 7,
      "y": 33,
      "z": 13,
      "name": "Rock_Sandstone_White"
    },
    {
      "x": 7,
      "y": 34,
      "z": 13,
      "name": "Rock_Sandstone_White"
    },
    {
      "x": 7,
      "y": 35,
      "z": 13,
      "name": "Rock_Sandstone"
    },
    {
      "x": 7,
      "y": 36,
      "z": 13,
      "name": "Rock_Sandstone"
    },
    {
      "x": 7,
      "y": 37,
      "z": 13,
      "name": "Rock_Sandstone"
    },
    {
      "x": 7,
      "y": 38,
      "z": 13,
      "name": "Rock_Sandstone"
    },
    {
      "x": 7,
      "y": 39,
      "z": 13,
      "name": "Rock_Sandstone"
    },
    {
      "x": 7,
      "y": 40,
      "z": 13,
      "name": "Rock_Sandstone"
    },
    {
      "x": 7,
      "y": 41,
      "z": 13,
      "name": "Rock_Sandstone"
    },
    {
      "x": 7,
      "y": 42,
      "z": 13,
      "name": "Rock_Sandstone"
    },
    {
      "x": 7,
      "y": 43,
      "z": 13,
      "name": "Rock_Sandstone"
    },
    {
      "x": 7,
      "y": 44,
      "z": 13,
      "name": "Rock_Sandstone"
    },
    {
      "x": 7,
      "y": 45,
      "z": 13,
      "name": "Rock_Sandstone"
    },
    {
      "x": 7,
      "y": 1,
      "z": 14,
      "name": "Rock_Sandstone"
    },
    {
      "x": 7,
      "y": 2,
      "z": 14,
      "name": "Rock_Sandstone"
    },
    {
      "x": 7,
      "y": 3,
      "z": 14,
      "name": "Rock_Sandstone"
    },
    {
      "x": 7,
      "y": 4,
      "z": 14,
      "name": "Rock_Sandstone"
    },
    {
      "x": 7,
      "y": 5,
      "z": 14,
      "name": "Rock_Sandstone"
    },
    {
      "x": 7,
      "y": 6,
      "z": 14,
      "name": "Rock_Sandstone"
    },
    {
      "x": 7,
      "y": 7,
      "z": 14,
      "name": "Rock_Sandstone"
    },
    {
      "x": 7,
      "y": 8,
      "z": 14,
      "name": "Rock_Sandstone"
    },
    {
      "x": 7,
      "y": 9,
      "z": 14,
      "name": "Soil_Clay"
    },
    {
      "x": 7,
      "y": 12,
      "z": 14,
      "name": "Rock_Sandstone_Red"
    },
    {
      "x": 7,
      "y": 13,
      "z": 14,
      "name": "Soil_Clay"
    },
    {
      "x": 7,
      "y": 14,
      "z": 14,
      "name": "Soil_Clay"
    },
    {
      "x": 7,
      "y": 30,
      "z": 14,
      "name": "Rock_Sandstone"
    },
    {
      "x": 7,
      "y": 31,
      "z": 14,
      "name": "Rock_Sandstone"
    },
    {
      "x": 7,
      "y": 32,
      "z": 14,
      "name": "Rock_Sandstone_White"
    },
    {
      "x": 7,
      "y": 33,
      "z": 14,
      "name": "Rock_Sandstone_White"
    },
    {
      "x": 7,
      "y": 34,
      "z": 14,
      "name": "Rock_Sandstone_White"
    },
    {
      "x": 7,
      "y": 35,
      "z": 14,
      "name": "Rock_Sandstone"
    },
    {
      "x": 7,
      "y": 36,
      "z": 14,
      "name": "Rock_Sandstone"
    },
    {
      "x": 7,
      "y": 37,
      "z": 14,
      "name": "Rock_Sandstone"
    },
    {
      "x": 7,
      "y": 38,
      "z": 14,
      "name": "Rock_Sandstone"
    },
    {
      "x": 7,
      "y": 39,
      "z": 14,
      "name": "Rock_Sandstone"
    },
    {
      "x": 7,
      "y": 40,
      "z": 14,
      "name": "Rock_Sandstone"
    },
    {
      "x": 7,
      "y": 41,
      "z": 14,
      "name": "Rock_Sandstone"
    },
    {
      "x": 7,
      "y": 42,
      "z": 14,
      "name": "Rock_Sandstone"
    },
    {
      "x": 7,
      "y": 43,
      "z": 14,
      "name": "Rock_Sandstone"
    },
    {
      "x": 7,
      "y": 44,
      "z": 14,
      "name": "Rock_Sandstone"
    },
    {
      "x": 7,
      "y": 45,
      "z": 14,
      "name": "Rock_Sandstone"
    },
    {
      "x": 7,
      "y": 2,
      "z": 15,
      "name": "Rock_Sandstone"
    },
    {
      "x": 7,
      "y": 3,
      "z": 15,
      "name": "Rock_Sandstone"
    },
    {
      "x": 7,
      "y": 4,
      "z": 15,
      "name": "Rock_Sandstone"
    },
    {
      "x": 7,
      "y": 5,
      "z": 15,
      "name": "Rock_Sandstone"
    },
    {
      "x": 7,
      "y": 31,
      "z": 15,
      "name": "Rock_Sandstone"
    },
    {
      "x": 7,
      "y": 32,
      "z": 15,
      "name": "Rock_Sandstone_White"
    },
    {
      "x": 7,
      "y": 33,
      "z": 15,
      "name": "Rock_Sandstone_White"
    },
    {
      "x": 7,
      "y": 34,
      "z": 15,
      "name": "Rock_Sandstone_White"
    },
    {
      "x": 7,
      "y": 35,
      "z": 15,
      "name": "Rock_Sandstone"
    },
    {
      "x": 7,
      "y": 36,
      "z": 15,
      "name": "Rock_Sandstone"
    },
    {
      "x": 7,
      "y": 37,
      "z": 15,
      "name": "Rock_Sandstone"
    },
    {
      "x": 7,
      "y": 38,
      "z": 15,
      "name": "Rock_Sandstone"
    },
    {
      "x": 7,
      "y": 39,
      "z": 15,
      "name": "Rock_Sandstone"
    },
    {
      "x": 7,
      "y": 40,
      "z": 15,
      "name": "Rock_Sandstone"
    },
    {
      "x": 7,
      "y": 41,
      "z": 15,
      "name": "Rock_Sandstone"
    },
    {
      "x": 7,
      "y": 42,
      "z": 15,
      "name": "Rock_Sandstone"
    },
    {
      "x": 7,
      "y": 43,
      "z": 15,
      "name": "Rock_Sandstone"
    },
    {
      "x": 7,
      "y": 44,
      "z": 15,
      "name": "Rock_Sandstone"
    },
    {
      "x": 7,
      "y": 45,
      "z": 15,
      "name": "Rock_Sandstone"
    },
    {
      "x": 7,
      "y": 37,
      "z": 16,
      "name": "Rock_Sandstone"
    },
    {
      "x": 7,
      "y": 38,
      "z": 16,
      "name": "Rock_Sandstone"
    },
    {
      "x": 7,
      "y": 39,
      "z": 16,
      "name": "Rock_Sandstone"
    },
    {
      "x": 7,
      "y": 40,
      "z": 16,
      "name": "Rock_Sandstone"
    },
    {
      "x": 7,
      "y": 41,
      "z": 16,
      "name": "Rock_Sandstone"
    },
    {
      "x": 7,
      "y": 42,
      "z": 16,
      "name": "Rock_Sandstone"
    },
    {
      "x": 7,
      "y": 43,
      "z": 16,
      "name": "Rock_Sandstone"
    },
    {
      "x": 7,
      "y": 44,
      "z": 16,
      "name": "Rock_Sandstone"
    },
    {
      "x": 7,
      "y": 45,
      "z": 16,
      "name": "Rock_Sandstone"
    },
    {
      "x": 7,
      "y": 38,
      "z": 17,
      "name": "Rock_Sandstone"
    },
    {
      "x": 7,
      "y": 39,
      "z": 17,
      "name": "Rock_Sandstone"
    },
    {
      "x": 7,
      "y": 40,
      "z": 17,
      "name": "Rock_Sandstone"
    },
    {
      "x": 7,
      "y": 41,
      "z": 17,
      "name": "Rock_Sandstone"
    },
    {
      "x": 7,
      "y": 42,
      "z": 17,
      "name": "Rock_Sandstone"
    },
    {
      "x": 7,
      "y": 43,
      "z": 17,
      "name": "Rock_Sandstone"
    },
    {
      "x": 7,
      "y": 44,
      "z": 17,
      "name": "Rock_Sandstone"
    },
    {
      "x": 8,
      "y": 39,
      "z": 4,
      "name": "Rock_Sandstone"
    },
    {
      "x": 8,
      "y": 40,
      "z": 4,
      "name": "Rock_Sandstone"
    },
    {
      "x": 8,
      "y": 41,
      "z": 4,
      "name": "Rock_Sandstone"
    },
    {
      "x": 8,
      "y": 42,
      "z": 4,
      "name": "Rock_Sandstone"
    },
    {
      "x": 8,
      "y": 43,
      "z": 4,
      "name": "Rock_Sandstone"
    },
    {
      "x": 8,
      "y": 35,
      "z": 5,
      "name": "Rock_Sandstone"
    },
    {
      "x": 8,
      "y": 36,
      "z": 5,
      "name": "Rock_Sandstone"
    },
    {
      "x": 8,
      "y": 38,
      "z": 5,
      "name": "Rock_Sandstone"
    },
    {
      "x": 8,
      "y": 39,
      "z": 5,
      "name": "Rock_Sandstone"
    },
    {
      "x": 8,
      "y": 40,
      "z": 5,
      "name": "Rock_Sandstone"
    },
    {
      "x": 8,
      "y": 41,
      "z": 5,
      "name": "Rock_Sandstone"
    },
    {
      "x": 8,
      "y": 42,
      "z": 5,
      "name": "Rock_Sandstone"
    },
    {
      "x": 8,
      "y": 43,
      "z": 5,
      "name": "Rock_Sandstone"
    },
    {
      "x": 8,
      "y": 44,
      "z": 5,
      "name": "Rock_Sandstone"
    },
    {
      "x": 8,
      "y": 45,
      "z": 5,
      "name": "Rock_Sandstone"
    },
    {
      "x": 8,
      "y": 26,
      "z": 6,
      "name": "Soil_Clay"
    },
    {
      "x": 8,
      "y": 27,
      "z": 6,
      "name": "Soil_Clay"
    },
    {
      "x": 8,
      "y": 28,
      "z": 6,
      "name": "Rock_Sandstone_White"
    },
    {
      "x": 8,
      "y": 31,
      "z": 6,
      "name": "Rock_Sandstone"
    },
    {
      "x": 8,
      "y": 32,
      "z": 6,
      "name": "Rock_Sandstone_White"
    },
    {
      "x": 8,
      "y": 33,
      "z": 6,
      "name": "Rock_Sandstone_White"
    },
    {
      "x": 8,
      "y": 34,
      "z": 6,
      "name": "Rock_Sandstone_White"
    },
    {
      "x": 8,
      "y": 35,
      "z": 6,
      "name": "Rock_Sandstone"
    },
    {
      "x": 8,
      "y": 36,
      "z": 6,
      "name": "Rock_Sandstone"
    },
    {
      "x": 8,
      "y": 37,
      "z": 6,
      "name": "Rock_Sandstone"
    },
    {
      "x": 8,
      "y": 38,
      "z": 6,
      "name": "Rock_Sandstone"
    },
    {
      "x": 8,
      "y": 39,
      "z": 6,
      "name": "Rock_Sandstone"
    },
    {
      "x": 8,
      "y": 40,
      "z": 6,
      "name": "Rock_Sandstone"
    },
    {
      "x": 8,
      "y": 41,
      "z": 6,
      "name": "Rock_Sandstone"
    },
    {
      "x": 8,
      "y": 42,
      "z": 6,
      "name": "Rock_Sandstone"
    },
    {
      "x": 8,
      "y": 43,
      "z": 6,
      "name": "Rock_Sandstone"
    },
    {
      "x": 8,
      "y": 44,
      "z": 6,
      "name": "Rock_Sandstone"
    },
    {
      "x": 8,
      "y": 45,
      "z": 6,
      "name": "Rock_Sandstone"
    },
    {
      "x": 8,
      "y": 5,
      "z": 7,
      "name": "Rock_Sandstone"
    },
    {
      "x": 8,
      "y": 6,
      "z": 7,
      "name": "Rock_Sandstone"
    },
    {
      "x": 8,
      "y": 7,
      "z": 7,
      "name": "Rock_Sandstone"
    },
    {
      "x": 8,
      "y": 8,
      "z": 7,
      "name": "Rock_Sandstone"
    },
    {
      "x": 8,
      "y": 23,
      "z": 7,
      "name": "Rock_Sandstone"
    },
    {
      "x": 8,
      "y": 24,
      "z": 7,
      "name": "Rock_Sandstone"
    },
    {
      "x": 8,
      "y": 25,
      "z": 7,
      "name": "Rock_Sandstone"
    },
    {
      "x": 8,
      "y": 26,
      "z": 7,
      "name": "Soil_Clay"
    },
    {
      "x": 8,
      "y": 27,
      "z": 7,
      "name": "Soil_Clay"
    },
    {
      "x": 8,
      "y": 28,
      "z": 7,
      "name": "Rock_Sandstone_White"
    },
    {
      "x": 8,
      "y": 29,
      "z": 7,
      "name": "Rock_Sandstone"
    },
    {
      "x": 8,
      "y": 31,
      "z": 7,
      "name": "Rock_Sandstone"
    },
    {
      "x": 8,
      "y": 32,
      "z": 7,
      "name": "Rock_Sandstone_White"
    },
    {
      "x": 8,
      "y": 33,
      "z": 7,
      "name": "Rock_Sandstone_White"
    },
    {
      "x": 8,
      "y": 34,
      "z": 7,
      "name": "Rock_Sandstone_White"
    },
    {
      "x": 8,
      "y": 35,
      "z": 7,
      "name": "Rock_Sandstone"
    },
    {
      "x": 8,
      "y": 36,
      "z": 7,
      "name": "Rock_Sandstone"
    },
    {
      "x": 8,
      "y": 37,
      "z": 7,
      "name": "Rock_Sandstone"
    },
    {
      "x": 8,
      "y": 38,
      "z": 7,
      "name": "Rock_Sandstone"
    },
    {
      "x": 8,
      "y": 39,
      "z": 7,
      "name": "Rock_Sandstone"
    },
    {
      "x": 8,
      "y": 40,
      "z": 7,
      "name": "Rock_Sandstone"
    },
    {
      "x": 8,
      "y": 41,
      "z": 7,
      "name": "Rock_Sandstone"
    },
    {
      "x": 8,
      "y": 42,
      "z": 7,
      "name": "Rock_Sandstone"
    },
    {
      "x": 8,
      "y": 43,
      "z": 7,
      "name": "Rock_Sandstone"
    },
    {
      "x": 8,
      "y": 44,
      "z": 7,
      "name": "Rock_Sandstone"
    },
    {
      "x": 8,
      "y": 45,
      "z": 7,
      "name": "Rock_Sandstone"
    },
    {
      "x": 8,
      "y": 4,
      "z": 8,
      "name": "Rock_Sandstone"
    },
    {
      "x": 8,
      "y": 5,
      "z": 8,
      "name": "Rock_Sandstone"
    },
    {
      "x": 8,
      "y": 6,
      "z": 8,
      "name": "Rock_Sandstone"
    },
    {
      "x": 8,
      "y": 7,
      "z": 8,
      "name": "Rock_Sandstone"
    },
    {
      "x": 8,
      "y": 8,
      "z": 8,
      "name": "Rock_Sandstone"
    },
    {
      "x": 8,
      "y": 9,
      "z": 8,
      "name": "Soil_Clay"
    },
    {
      "x": 8,
      "y": 12,
      "z": 8,
      "name": "Rock_Sandstone_Red"
    },
    {
      "x": 8,
      "y": 13,
      "z": 8,
      "name": "Soil_Clay"
    },
    {
      "x": 8,
      "y": 14,
      "z": 8,
      "name": "Soil_Clay"
    },
    {
      "x": 8,
      "y": 19,
      "z": 8,
      "name": "Rock_Sandstone"
    },
    {
      "x": 8,
      "y": 20,
      "z": 8,
      "name": "Rock_Sandstone"
    },
    {
      "x": 8,
      "y": 21,
      "z": 8,
      "name": "Rock_Sandstone_Red"
    },
    {
      "x": 8,
      "y": 22,
      "z": 8,
      "name": "Rock_Sandstone_White"
    },
    {
      "x": 8,
      "y": 23,
      "z": 8,
      "name": "Rock_Sandstone"
    },
    {
      "x": 8,
      "y": 24,
      "z": 8,
      "name": "Rock_Sandstone"
    },
    {
      "x": 8,
      "y": 25,
      "z": 8,
      "name": "Rock_Sandstone"
    },
    {
      "x": 8,
      "y": 26,
      "z": 8,
      "name": "Soil_Clay"
    },
    {
      "x": 8,
      "y": 27,
      "z": 8,
      "name": "Soil_Clay"
    },
    {
      "x": 8,
      "y": 28,
      "z": 8,
      "name": "Rock_Sandstone_White"
    },
    {
      "x": 8,
      "y": 29,
      "z": 8,
      "name": "Rock_Sandstone"
    },
    {
      "x": 8,
      "y": 30,
      "z": 8,
      "name": "Rock_Sandstone"
    },
    {
      "x": 8,
      "y": 31,
      "z": 8,
      "name": "Rock_Sandstone"
    },
    {
      "x": 8,
      "y": 32,
      "z": 8,
      "name": "Rock_Sandstone_White"
    },
    {
      "x": 8,
      "y": 33,
      "z": 8,
      "name": "Rock_Sandstone_White"
    },
    {
      "x": 8,
      "y": 34,
      "z": 8,
      "name": "Rock_Sandstone_White"
    },
    {
      "x": 8,
      "y": 35,
      "z": 8,
      "name": "Rock_Sandstone"
    },
    {
      "x": 8,
      "y": 36,
      "z": 8,
      "name": "Rock_Sandstone"
    },
    {
      "x": 8,
      "y": 37,
      "z": 8,
      "name": "Rock_Sandstone"
    },
    {
      "x": 8,
      "y": 38,
      "z": 8,
      "name": "Rock_Sandstone"
    },
    {
      "x": 8,
      "y": 39,
      "z": 8,
      "name": "Rock_Sandstone"
    },
    {
      "x": 8,
      "y": 40,
      "z": 8,
      "name": "Rock_Sandstone"
    },
    {
      "x": 8,
      "y": 41,
      "z": 8,
      "name": "Rock_Sandstone"
    },
    {
      "x": 8,
      "y": 42,
      "z": 8,
      "name": "Rock_Sandstone"
    },
    {
      "x": 8,
      "y": 43,
      "z": 8,
      "name": "Rock_Sandstone"
    },
    {
      "x": 8,
      "y": 44,
      "z": 8,
      "name": "Rock_Sandstone"
    },
    {
      "x": 8,
      "y": 45,
      "z": 8,
      "name": "Rock_Sandstone"
    },
    {
      "x": 8,
      "y": 1,
      "z": 9,
      "name": "Rock_Sandstone"
    },
    {
      "x": 8,
      "y": 2,
      "z": 9,
      "name": "Rock_Sandstone"
    },
    {
      "x": 8,
      "y": 3,
      "z": 9,
      "name": "Rock_Sandstone"
    },
    {
      "x": 8,
      "y": 4,
      "z": 9,
      "name": "Rock_Sandstone"
    },
    {
      "x": 8,
      "y": 5,
      "z": 9,
      "name": "Rock_Sandstone"
    },
    {
      "x": 8,
      "y": 6,
      "z": 9,
      "name": "Rock_Sandstone"
    },
    {
      "x": 8,
      "y": 7,
      "z": 9,
      "name": "Rock_Sandstone"
    },
    {
      "x": 8,
      "y": 8,
      "z": 9,
      "name": "Rock_Sandstone"
    },
    {
      "x": 8,
      "y": 9,
      "z": 9,
      "name": "Soil_Clay"
    },
    {
      "x": 8,
      "y": 10,
      "z": 9,
      "name": "Soil_Clay"
    },
    {
      "x": 8,
      "y": 11,
      "z": 9,
      "name": "Rock_Sandstone_Red"
    },
    {
      "x": 8,
      "y": 12,
      "z": 9,
      "name": "Rock_Sandstone_Red"
    },
    {
      "x": 8,
      "y": 13,
      "z": 9,
      "name": "Soil_Clay"
    },
    {
      "x": 8,
      "y": 14,
      "z": 9,
      "name": "Soil_Clay"
    },
    {
      "x": 8,
      "y": 15,
      "z": 9,
      "name": "Rock_Sandstone_Red"
    },
    {
      "x": 8,
      "y": 16,
      "z": 9,
      "name": "Soil_Dirt_Dry"
    },
    {
      "x": 8,
      "y": 18,
      "z": 9,
      "name": "Soil_Clay"
    },
    {
      "x": 8,
      "y": 19,
      "z": 9,
      "name": "Rock_Sandstone"
    },
    {
      "x": 8,
      "y": 20,
      "z": 9,
      "name": "Rock_Sandstone"
    },
    {
      "x": 8,
      "y": 21,
      "z": 9,
      "name": "Rock_Sandstone_Red"
    },
    {
      "x": 8,
      "y": 22,
      "z": 9,
      "name": "Rock_Sandstone_White"
    },
    {
      "x": 8,
      "y": 23,
      "z": 9,
      "name": "Rock_Sandstone"
    },
    {
      "x": 8,
      "y": 24,
      "z": 9,
      "name": "Rock_Sandstone"
    },
    {
      "x": 8,
      "y": 25,
      "z": 9,
      "name": "Rock_Sandstone"
    },
    {
      "x": 8,
      "y": 26,
      "z": 9,
      "name": "Soil_Clay"
    },
    {
      "x": 8,
      "y": 27,
      "z": 9,
      "name": "Soil_Clay"
    },
    {
      "x": 8,
      "y": 28,
      "z": 9,
      "name": "Rock_Sandstone_White"
    },
    {
      "x": 8,
      "y": 29,
      "z": 9,
      "name": "Rock_Sandstone"
    },
    {
      "x": 8,
      "y": 30,
      "z": 9,
      "name": "Rock_Sandstone"
    },
    {
      "x": 8,
      "y": 31,
      "z": 9,
      "name": "Rock_Sandstone"
    },
    {
      "x": 8,
      "y": 32,
      "z": 9,
      "name": "Rock_Sandstone_White"
    },
    {
      "x": 8,
      "y": 33,
      "z": 9,
      "name": "Rock_Sandstone_White"
    },
    {
      "x": 8,
      "y": 34,
      "z": 9,
      "name": "Rock_Sandstone_White"
    },
    {
      "x": 8,
      "y": 35,
      "z": 9,
      "name": "Rock_Sandstone"
    },
    {
      "x": 8,
      "y": 36,
      "z": 9,
      "name": "Rock_Sandstone"
    },
    {
      "x": 8,
      "y": 37,
      "z": 9,
      "name": "Rock_Sandstone"
    },
    {
      "x": 8,
      "y": 38,
      "z": 9,
      "name": "Rock_Sandstone"
    },
    {
      "x": 8,
      "y": 39,
      "z": 9,
      "name": "Rock_Sandstone"
    },
    {
      "x": 8,
      "y": 40,
      "z": 9,
      "name": "Rock_Sandstone"
    },
    {
      "x": 8,
      "y": 41,
      "z": 9,
      "name": "Rock_Sandstone"
    },
    {
      "x": 8,
      "y": 42,
      "z": 9,
      "name": "Rock_Sandstone"
    },
    {
      "x": 8,
      "y": 43,
      "z": 9,
      "name": "Rock_Sandstone"
    },
    {
      "x": 8,
      "y": 44,
      "z": 9,
      "name": "Rock_Sandstone"
    },
    {
      "x": 8,
      "y": 45,
      "z": 9,
      "name": "Rock_Sandstone"
    },
    {
      "x": 8,
      "y": 0,
      "z": 10,
      "name": "Rock_Sandstone"
    },
    {
      "x": 8,
      "y": 1,
      "z": 10,
      "name": "Rock_Sandstone"
    },
    {
      "x": 8,
      "y": 2,
      "z": 10,
      "name": "Rock_Sandstone"
    },
    {
      "x": 8,
      "y": 3,
      "z": 10,
      "name": "Rock_Sandstone"
    },
    {
      "x": 8,
      "y": 4,
      "z": 10,
      "name": "Rock_Sandstone"
    },
    {
      "x": 8,
      "y": 5,
      "z": 10,
      "name": "Rock_Sandstone"
    },
    {
      "x": 8,
      "y": 6,
      "z": 10,
      "name": "Rock_Sandstone"
    },
    {
      "x": 8,
      "y": 7,
      "z": 10,
      "name": "Rock_Sandstone"
    },
    {
      "x": 8,
      "y": 8,
      "z": 10,
      "name": "Rock_Sandstone"
    },
    {
      "x": 8,
      "y": 9,
      "z": 10,
      "name": "Soil_Clay"
    },
    {
      "x": 8,
      "y": 10,
      "z": 10,
      "name": "Soil_Clay"
    },
    {
      "x": 8,
      "y": 11,
      "z": 10,
      "name": "Rock_Sandstone_Red"
    },
    {
      "x": 8,
      "y": 12,
      "z": 10,
      "name": "Rock_Sandstone_Red"
    },
    {
      "x": 8,
      "y": 13,
      "z": 10,
      "name": "Soil_Clay"
    },
    {
      "x": 8,
      "y": 14,
      "z": 10,
      "name": "Soil_Clay"
    },
    {
      "x": 8,
      "y": 15,
      "z": 10,
      "name": "Rock_Sandstone_Red"
    },
    {
      "x": 8,
      "y": 16,
      "z": 10,
      "name": "Soil_Dirt_Dry"
    },
    {
      "x": 8,
      "y": 17,
      "z": 10,
      "name": "Soil_Clay"
    },
    {
      "x": 8,
      "y": 18,
      "z": 10,
      "name": "Soil_Clay"
    },
    {
      "x": 8,
      "y": 19,
      "z": 10,
      "name": "Rock_Sandstone"
    },
    {
      "x": 8,
      "y": 20,
      "z": 10,
      "name": "Rock_Sandstone"
    },
    {
      "x": 8,
      "y": 21,
      "z": 10,
      "name": "Rock_Sandstone_Red"
    },
    {
      "x": 8,
      "y": 22,
      "z": 10,
      "name": "Rock_Sandstone_White"
    },
    {
      "x": 8,
      "y": 23,
      "z": 10,
      "name": "Rock_Sandstone"
    },
    {
      "x": 8,
      "y": 24,
      "z": 10,
      "name": "Rock_Sandstone"
    },
    {
      "x": 8,
      "y": 25,
      "z": 10,
      "name": "Rock_Sandstone"
    },
    {
      "x": 8,
      "y": 26,
      "z": 10,
      "name": "Soil_Clay"
    },
    {
      "x": 8,
      "y": 27,
      "z": 10,
      "name": "Soil_Clay"
    },
    {
      "x": 8,
      "y": 28,
      "z": 10,
      "name": "Rock_Sandstone_White"
    },
    {
      "x": 8,
      "y": 29,
      "z": 10,
      "name": "Rock_Sandstone"
    },
    {
      "x": 8,
      "y": 30,
      "z": 10,
      "name": "Rock_Sandstone"
    },
    {
      "x": 8,
      "y": 31,
      "z": 10,
      "name": "Rock_Sandstone"
    },
    {
      "x": 8,
      "y": 32,
      "z": 10,
      "name": "Rock_Sandstone_White"
    },
    {
      "x": 8,
      "y": 33,
      "z": 10,
      "name": "Rock_Sandstone_White"
    },
    {
      "x": 8,
      "y": 34,
      "z": 10,
      "name": "Rock_Sandstone_White"
    },
    {
      "x": 8,
      "y": 35,
      "z": 10,
      "name": "Rock_Sandstone"
    },
    {
      "x": 8,
      "y": 36,
      "z": 10,
      "name": "Rock_Sandstone"
    },
    {
      "x": 8,
      "y": 37,
      "z": 10,
      "name": "Rock_Sandstone"
    },
    {
      "x": 8,
      "y": 38,
      "z": 10,
      "name": "Rock_Sandstone"
    },
    {
      "x": 8,
      "y": 39,
      "z": 10,
      "name": "Rock_Sandstone"
    },
    {
      "x": 8,
      "y": 40,
      "z": 10,
      "name": "Rock_Sandstone"
    },
    {
      "x": 8,
      "y": 41,
      "z": 10,
      "name": "Rock_Sandstone"
    },
    {
      "x": 8,
      "y": 42,
      "z": 10,
      "name": "Rock_Sandstone"
    },
    {
      "x": 8,
      "y": 43,
      "z": 10,
      "name": "Rock_Sandstone"
    },
    {
      "x": 8,
      "y": 44,
      "z": 10,
      "name": "Rock_Sandstone"
    },
    {
      "x": 8,
      "y": 45,
      "z": 10,
      "name": "Rock_Sandstone"
    },
    {
      "x": 8,
      "y": 0,
      "z": 11,
      "name": "Rock_Sandstone"
    },
    {
      "x": 8,
      "y": 1,
      "z": 11,
      "name": "Rock_Sandstone"
    },
    {
      "x": 8,
      "y": 2,
      "z": 11,
      "name": "Rock_Sandstone"
    },
    {
      "x": 8,
      "y": 3,
      "z": 11,
      "name": "Rock_Sandstone"
    },
    {
      "x": 8,
      "y": 4,
      "z": 11,
      "name": "Rock_Sandstone"
    },
    {
      "x": 8,
      "y": 5,
      "z": 11,
      "name": "Rock_Sandstone"
    },
    {
      "x": 8,
      "y": 6,
      "z": 11,
      "name": "Rock_Sandstone"
    },
    {
      "x": 8,
      "y": 7,
      "z": 11,
      "name": "Rock_Sandstone"
    },
    {
      "x": 8,
      "y": 8,
      "z": 11,
      "name": "Rock_Sandstone"
    },
    {
      "x": 8,
      "y": 9,
      "z": 11,
      "name": "Soil_Clay"
    },
    {
      "x": 8,
      "y": 10,
      "z": 11,
      "name": "Soil_Clay"
    },
    {
      "x": 8,
      "y": 11,
      "z": 11,
      "name": "Rock_Sandstone_Red"
    },
    {
      "x": 8,
      "y": 12,
      "z": 11,
      "name": "Rock_Sandstone_Red"
    },
    {
      "x": 8,
      "y": 13,
      "z": 11,
      "name": "Soil_Clay"
    },
    {
      "x": 8,
      "y": 14,
      "z": 11,
      "name": "Soil_Clay"
    },
    {
      "x": 8,
      "y": 15,
      "z": 11,
      "name": "Rock_Sandstone_Red"
    },
    {
      "x": 8,
      "y": 16,
      "z": 11,
      "name": "Soil_Dirt_Dry"
    },
    {
      "x": 8,
      "y": 17,
      "z": 11,
      "name": "Soil_Clay"
    },
    {
      "x": 8,
      "y": 18,
      "z": 11,
      "name": "Soil_Clay"
    },
    {
      "x": 8,
      "y": 19,
      "z": 11,
      "name": "Rock_Sandstone"
    },
    {
      "x": 8,
      "y": 20,
      "z": 11,
      "name": "Rock_Sandstone"
    },
    {
      "x": 8,
      "y": 21,
      "z": 11,
      "name": "Rock_Sandstone_Red"
    },
    {
      "x": 8,
      "y": 22,
      "z": 11,
      "name": "Rock_Sandstone_White"
    },
    {
      "x": 8,
      "y": 23,
      "z": 11,
      "name": "Rock_Sandstone"
    },
    {
      "x": 8,
      "y": 24,
      "z": 11,
      "name": "Rock_Sandstone"
    },
    {
      "x": 8,
      "y": 25,
      "z": 11,
      "name": "Rock_Sandstone"
    },
    {
      "x": 8,
      "y": 26,
      "z": 11,
      "name": "Soil_Clay"
    },
    {
      "x": 8,
      "y": 27,
      "z": 11,
      "name": "Soil_Clay"
    },
    {
      "x": 8,
      "y": 28,
      "z": 11,
      "name": "Rock_Sandstone_White"
    },
    {
      "x": 8,
      "y": 29,
      "z": 11,
      "name": "Rock_Sandstone"
    },
    {
      "x": 8,
      "y": 30,
      "z": 11,
      "name": "Rock_Sandstone"
    },
    {
      "x": 8,
      "y": 31,
      "z": 11,
      "name": "Rock_Sandstone"
    },
    {
      "x": 8,
      "y": 32,
      "z": 11,
      "name": "Rock_Sandstone_White"
    },
    {
      "x": 8,
      "y": 33,
      "z": 11,
      "name": "Rock_Sandstone_White"
    },
    {
      "x": 8,
      "y": 34,
      "z": 11,
      "name": "Rock_Sandstone_White"
    },
    {
      "x": 8,
      "y": 35,
      "z": 11,
      "name": "Rock_Sandstone"
    },
    {
      "x": 8,
      "y": 36,
      "z": 11,
      "name": "Rock_Sandstone"
    },
    {
      "x": 8,
      "y": 37,
      "z": 11,
      "name": "Rock_Sandstone"
    },
    {
      "x": 8,
      "y": 38,
      "z": 11,
      "name": "Rock_Sandstone"
    },
    {
      "x": 8,
      "y": 39,
      "z": 11,
      "name": "Rock_Sandstone"
    },
    {
      "x": 8,
      "y": 40,
      "z": 11,
      "name": "Rock_Sandstone"
    },
    {
      "x": 8,
      "y": 41,
      "z": 11,
      "name": "Rock_Sandstone"
    },
    {
      "x": 8,
      "y": 42,
      "z": 11,
      "name": "Rock_Sandstone"
    },
    {
      "x": 8,
      "y": 43,
      "z": 11,
      "name": "Rock_Sandstone"
    },
    {
      "x": 8,
      "y": 44,
      "z": 11,
      "name": "Rock_Sandstone"
    },
    {
      "x": 8,
      "y": 45,
