{
  "version": 8,
  "blockIdVersion": 8,
  "anchorX": -1,
  "anchorY": 3,
  "anchorZ": -7,
  "blocks": [
    {
      "x": -8,
      "y": 6,
      "z": -6,
      "name": "Soil_Mud_Dry"
    },
    {
      "x": -8,
      "y": 7,
      "z": -6,
      "name": "Soil_Mud_Dry"
    },
    {
      "x": -8,
      "y": 8,
      "z": -6,
      "name": "Soil_Mud_Dry"
    },
    {
      "x": -8,
      "y": 9,
      "z": -6,
      "name": "Soil_Mud_Dry"
    },
    {
      "x": -8,
      "y": 10,
      "z": -6,
      "name": "Soil_Mud_Dry"
    },
    {
      "x": -8,
      "y": 11,
      "z": -6,
      "name": "Soil_Mud_Dry"
    },
    {
      "x": -8,
      "y": 12,
      "z": -6,
      "name": "Soil_Mud_Dry"
    },
    {
      "x": -8,
      "y": 6,
      "z": -5,
      "name": "Soil_Mud_Dry"
    },
    {
      "x": -8,
      "y": 7,
      "z": -5,
      "name": "Soil_Mud_Dry"
    },
    {
      "x": -8,
      "y": 8,
      "z": -5,
      "name": "Soil_Mud_Dry"
    },
    {
      "x": -8,
      "y": 9,
      "z": -5,
      "name": "Soil_Mud_Dry"
    },
    {
      "x": -8,
      "y": 10,
      "z": -5,
      "name": "Soil_Mud_Dry"
    },
    {
      "x": -8,
      "y": 11,
      "z": -5,
      "name": "Soil_Mud_Dry"
    },
    {
      "x": -8,
      "y": 12,
      "z": -5,
      "name": "Soil_Mud_Dry"
    },
    {
      "x": -8,
      "y": 13,
      "z": -5,
      "name": "Soil_Mud_Dry"
    },
    {
      "x": -8,
      "y": 5,
      "z": -4,
      "name": "Soil_Dirt_Poisoned"
    },
    {
      "x": -8,
      "y": 6,
      "z": -4,
      "name": "Soil_Mud_Dry"
    },
    {
      "x": -8,
      "y": 7,
      "z": -4,
      "name": "Soil_Mud_Dry"
    },
    {
      "x": -8,
      "y": 8,
      "z": -4,
      "name": "Soil_Mud_Dry"
    },
    {
      "x": -8,
      "y": 9,
      "z": -4,
      "name": "Soil_Mud_Dry"
    },
    {
      "x": -8,
      "y": 10,
      "z": -4,
      "name": "Soil_Mud_Dry"
    },
    {
      "x": -8,
      "y": 11,
      "z": -4,
      "name": "Soil_Mud_Dry"
    },
    {
      "x": -8,
      "y": 12,
      "z": -4,
      "name": "Soil_Mud_Dry"
    },
    {
      "x": -8,
      "y": 13,
      "z": -4,
      "name": "Soil_Mud_Dry"
    },
    {
      "x": -8,
      "y": 14,
      "z": -4,
      "name": "Soil_Mud_Dry"
    },
    {
      "x": -8,
      "y": 3,
      "z": -3,
      "name": "Soil_Mud_Dry"
    },
    {
      "x": -8,
      "y": 4,
      "z": -3,
      "name": "Soil_Mud_Dry"
    },
    {
      "x": -8,
      "y": 5,
      "z": -3,
      "name": "Empty"
    },
    {
      "x": -8,
      "y": 6,
      "z": -3,
      "name": "Empty"
    },
    {
      "x": -8,
      "y": 7,
      "z": -3,
      "name": "Empty"
    },
    {
      "x": -8,
      "y": 8,
      "z": -3,
      "name": "Soil_Mud_Dry"
    },
    {
      "x": -8,
      "y": 9,
      "z": -3,
      "name": "Soil_Mud_Dry"
    },
    {
      "x": -8,
      "y": 10,
      "z": -3,
      "name": "Soil_Mud_Dry"
    },
    {
      "x": -8,
      "y": 11,
      "z": -3,
      "name": "Soil_Mud_Dry"
    },
    {
      "x": -8,
      "y": 12,
      "z": -3,
      "name": "Soil_Mud_Dry"
    },
    {
      "x": -8,
      "y": 13,
      "z": -3,
      "name": "Soil_Mud_Dry"
    },
    {
      "x": -8,
      "y": 14,
      "z": -3,
      "name": "Soil_Mud_Dry"
    },
    {
      "x": -8,
      "y": 3,
      "z": -2,
      "name": "Soil_Dirt_Poisoned"
    },
    {
      "x": -8,
      "y": 4,
      "z": -2,
      "name": "Empty"
    },
    {
      "x": -8,
      "y": 5,
      "z": -2,
      "name": "Empty"
    },
    {
      "x": -8,
      "y": 6,
      "z": -2,
      "name": "Empty"
    },
    {
      "x": -8,
      "y": 7,
      "z": -2,
      "name": "Empty"
    },
    {
      "x": -8,
      "y": 8,
      "z": -2,
      "name": "Empty"
    },
    {
      "x": -8,
      "y": 9,
      "z": -2,
      "name": "Empty"
    },
    {
      "x": -8,
      "y": 10,
      "z": -2,
      "name": "Soil_Mud_Dry"
    },
    {
      "x": -8,
      "y": 11,
      "z": -2,
      "name": "Soil_Mud_Dry"
    },
    {
      "x": -8,
      "y": 12,
      "z": -2,
      "name": "Soil_Mud_Dry"
    },
    {
      "x": -8,
      "y": 13,
      "z": -2,
      "name": "Soil_Mud_Dry"
    },
    {
      "x": -8,
      "y": 14,
      "z": -2,
      "name": "Soil_Mud_Dry"
    },
    {
      "x": -8,
      "y": 3,
      "z": -1,
      "name": "Soil_Mud_Dry"
    },
    {
      "x": -8,
      "y": 4,
      "z": -1,
      "name": "Empty"
    },
    {
      "x": -8,
      "y": 5,
      "z": -1,
      "name": "Empty"
    },
    {
      "x": -8,
      "y": 6,
      "z": -1,
      "name": "Empty"
    },
    {
      "x": -8,
      "y": 7,
      "z": -1,
      "name": "Empty"
    },
    {
      "x": -8,
      "y": 8,
      "z": -1,
      "name": "Empty"
    },
    {
      "x": -8,
      "y": 9,
      "z": -1,
      "name": "Empty"
    },
    {
      "x": -8,
      "y": 10,
      "z": -1,
      "name": "Soil_Mud_Dry"
    },
    {
      "x": -8,
      "y": 11,
      "z": -1,
      "name": "Soil_Mud_Dry"
    },
    {
      "x": -8,
      "y": 12,
      "z": -1,
      "name": "Soil_Mud_Dry"
    },
    {
      "x": -8,
      "y": 13,
      "z": -1,
      "name": "Soil_Mud_Dry"
    },
    {
      "x": -8,
      "y": 14,
      "z": -1,
      "name": "Soil_Mud_Dry"
    },
    {
      "x": -8,
      "y": 3,
      "z": 0,
      "name": "Soil_Mud_Dry"
    },
    {
      "x": -8,
      "y": 4,
      "z": 0,
      "name": "Empty"
    },
    {
      "x": -8,
      "y": 5,
      "z": 0,
      "name": "Empty"
    },
    {
      "x": -8,
      "y": 6,
      "z": 0,
      "name": "Empty"
    },
    {
      "x": -8,
      "y": 7,
      "z": 0,
      "name": "Empty"
    },
    {
      "x": -8,
      "y": 8,
      "z": 0,
      "name": "Empty"
    },
    {
      "x": -8,
      "y": 9,
      "z": 0,
      "name": "Empty"
    },
    {
      "x": -8,
      "y": 10,
      "z": 0,
      "name": "Soil_Mud_Dry"
    },
    {
      "x": -8,
      "y": 11,
      "z": 0,
      "name": "Soil_Mud_Dry"
    },
    {
      "x": -8,
      "y": 12,
      "z": 0,
      "name": "Soil_Mud_Dry"
    },
    {
      "x": -8,
      "y": 13,
      "z": 0,
      "name": "Soil_Mud_Dry"
    },
    {
      "x": -8,
      "y": 14,
      "z": 0,
      "name": "Soil_Mud_Dry"
    },
    {
      "x": -8,
      "y": 3,
      "z": 1,
      "name": "Soil_Mud_Dry"
    },
    {
      "x": -8,
      "y": 4,
      "z": 1,
      "name": "Empty"
    },
    {
      "x": -8,
      "y": 5,
      "z": 1,
      "name": "Empty"
    },
    {
      "x": -8,
      "y": 6,
      "z": 1,
      "name": "Empty"
    },
    {
      "x": -8,
      "y": 7,
      "z": 1,
      "name": "Empty"
    },
    {
      "x": -8,
      "y": 8,
      "z": 1,
      "name": "Empty"
    },
    {
      "x": -8,
      "y": 9,
      "z": 1,
      "name": "Soil_Mud_Dry"
    },
    {
      "x": -8,
      "y": 10,
      "z": 1,
      "name": "Soil_Mud_Dry"
    },
    {
      "x": -8,
      "y": 11,
      "z": 1,
      "name": "Soil_Mud_Dry"
    },
    {
      "x": -8,
      "y": 12,
      "z": 1,
      "name": "Soil_Mud_Dry"
    },
    {
      "x": -8,
      "y": 13,
      "z": 1,
      "name": "Soil_Mud_Dry"
    },
    {
      "x": -8,
      "y": 14,
      "z": 1,
      "name": "Soil_Mud_Dry"
    },
    {
      "x": -8,
      "y": 3,
      "z": 2,
      "name": "Soil_Mud_Dry"
    },
    {
      "x": -8,
      "y": 4,
      "z": 2,
      "name": "Empty"
    },
    {
      "x": -8,
      "y": 5,
      "z": 2,
      "name": "Empty"
    },
    {
      "x": -8,
      "y": 6,
      "z": 2,
      "name": "Empty"
    },
    {
      "x": -8,
      "y": 7,
      "z": 2,
      "name": "Empty"
    },
    {
      "x": -8,
      "y": 8,
      "z": 2,
      "name": "Empty"
    },
    {
      "x": -8,
      "y": 9,
      "z": 2,
      "name": "Soil_Mud_Dry"
    },
    {
      "x": -8,
      "y": 10,
      "z": 2,
      "name": "Soil_Mud_Dry"
    },
    {
      "x": -8,
      "y": 11,
      "z": 2,
      "name": "Soil_Mud_Dry"
    },
    {
      "x": -8,
      "y": 12,
      "z": 2,
      "name": "Soil_Mud_Dry"
    },
    {
      "x": -8,
      "y": 13,
      "z": 2,
      "name": "Soil_Mud_Dry"
    },
    {
      "x": -8,
      "y": 14,
      "z": 2,
      "name": "Soil_Mud_Dry"
    },
    {
      "x": -8,
      "y": 3,
      "z": 3,
      "name": "Soil_Mud_Dry"
    },
    {
      "x": -8,
      "y": 4,
      "z": 3,
      "name": "Empty"
    },
    {
      "x": -8,
      "y": 5,
      "z": 3,
      "name": "Empty"
    },
    {
      "x": -8,
      "y": 6,
      "z": 3,
      "name": "Empty"
    },
    {
      "x": -8,
      "y": 7,
      "z": 3,
      "name": "Empty"
    },
    {
      "x": -8,
      "y": 8,
      "z": 3,
      "name": "Soil_Mud_Dry"
    },
    {
      "x": -8,
      "y": 9,
      "z": 3,
      "name": "Soil_Mud_Dry"
    },
    {
      "x": -8,
      "y": 10,
      "z": 3,
      "name": "Soil_Mud_Dry"
    },
    {
      "x": -8,
      "y": 11,
      "z": 3,
      "name": "Soil_Mud_Dry"
    },
    {
      "x": -8,
      "y": 12,
      "z": 3,
      "name": "Soil_Mud_Dry"
    },
    {
      "x": -8,
      "y": 13,
      "z": 3,
      "name": "Soil_Mud_Dry"
    },
    {
      "x": -8,
      "y": 14,
      "z": 3,
      "name": "Soil_Mud_Dry"
    },
    {
      "x": -8,
      "y": 3,
      "z": 4,
      "name": "Soil_Mud_Dry"
    },
    {
      "x": -8,
      "y": 4,
      "z": 4,
      "name": "Soil_Mud_Dry"
    },
    {
      "x": -8,
      "y": 5,
      "z": 4,
      "name": "Soil_Mud_Dry"
    },
    {
      "x": -8,
      "y": 6,
      "z": 4,
      "name": "Soil_Mud_Dry"
    },
    {
      "x": -8,
      "y": 7,
      "z": 4,
      "name": "Soil_Mud_Dry"
    },
    {
      "x": -8,
      "y": 8,
      "z": 4,
      "name": "Soil_Mud_Dry"
    },
    {
      "x": -8,
      "y": 9,
      "z": 4,
      "name": "Soil_Mud_Dry"
    },
    {
      "x": -8,
      "y": 10,
      "z": 4,
      "name": "Soil_Mud_Dry"
    },
    {
      "x": -8,
      "y": 11,
      "z": 4,
      "name": "Soil_Mud_Dry"
    },
    {
      "x": -8,
      "y": 12,
      "z": 4,
      "name": "Soil_Mud_Dry"
    },
    {
      "x": -8,
      "y": 13,
      "z": 4,
      "name": "Soil_Mud_Dry"
    },
    {
      "x": -8,
      "y": 14,
      "z": 4,
      "name": "Soil_Mud_Dry"
    },
    {
      "x": -8,
      "y": 3,
      "z": 5,
      "name": "Soil_Mud_Dry"
    },
    {
      "x": -8,
      "y": 4,
      "z": 5,
      "name": "Soil_Mud_Dry"
    },
    {
      "x": -8,
      "y": 5,
      "z": 5,
      "name": "Soil_Mud_Dry"
    },
    {
      "x": -8,
      "y": 6,
      "z": 5,
      "name": "Soil_Mud_Dry"
    },
    {
      "x": -8,
      "y": 7,
      "z": 5,
      "name": "Soil_Mud_Dry"
    },
    {
      "x": -8,
      "y": 8,
      "z": 5,
      "name": "Soil_Mud_Dry"
    },
    {
      "x": -8,
      "y": 9,
      "z": 5,
      "name": "Soil_Mud_Dry"
    },
    {
      "x": -8,
      "y": 10,
      "z": 5,
      "name": "Soil_Mud_Dry"
    },
    {
      "x": -8,
      "y": 11,
      "z": 5,
      "name": "Soil_Mud_Dry"
    },
    {
      "x": -8,
      "y": 12,
      "z": 5,
      "name": "Soil_Mud_Dry"
    },
    {
      "x": -8,
      "y": 13,
      "z": 5,
      "name": "Soil_Mud_Dry"
    },
    {
      "x": -8,
      "y": 14,
      "z": 5,
      "name": "Soil_Mud_Dry"
    },
    {
      "x": -8,
      "y": 4,
      "z": 6,
      "name": "Soil_Mud_Dry"
    },
    {
      "x": -8,
      "y": 5,
      "z": 6,
      "name": "Soil_Mud_Dry"
    },
    {
      "x": -8,
      "y": 6,
      "z": 6,
      "name": "Soil_Mud_Dry"
    },
    {
      "x": -8,
      "y": 7,
      "z": 6,
      "name": "Soil_Mud_Dry"
    },
    {
      "x": -8,
      "y": 8,
      "z": 6,
      "name": "Soil_Mud_Dry"
    },
    {
      "x": -8,
      "y": 9,
      "z": 6,
      "name": "Soil_Mud_Dry"
    },
    {
      "x": -8,
      "y": 10,
      "z": 6,
      "name": "Soil_Mud_Dry"
    },
    {
      "x": -8,
      "y": 11,
      "z": 6,
      "name": "Soil_Mud_Dry"
    },
    {
      "x": -8,
      "y": 12,
      "z": 6,
      "name": "Soil_Mud_Dry"
    },
    {
      "x": -8,
      "y": 13,
      "z": 6,
      "name": "Soil_Mud_Dry"
    },
    {
      "x": -8,
      "y": 5,
      "z": 7,
      "name": "Soil_Mud_Dry"
    },
    {
      "x": -8,
      "y": 6,
      "z": 7,
      "name": "Soil_Mud_Dry"
    },
    {
      "x": -8,
      "y": 7,
      "z": 7,
      "name": "Soil_Mud_Dry"
    },
    {
      "x": -8,
      "y": 8,
      "z": 7,
      "name": "Soil_Mud_Dry"
    },
    {
      "x": -8,
      "y": 9,
      "z": 7,
      "name": "Soil_Mud_Dry"
    },
    {
      "x": -8,
      "y": 10,
      "z": 7,
      "name": "Soil_Mud_Dry"
    },
    {
      "x": -8,
      "y": 11,
      "z": 7,
      "name": "Soil_Mud_Dry"
    },
    {
      "x": -8,
      "y": 12,
      "z": 7,
      "name": "Soil_Mud_Dry"
    },
    {
      "x": -7,
      "y": 5,
      "z": -7,
      "name": "Soil_Mud_Dry"
    },
    {
      "x": -7,
      "y": 6,
      "z": -7,
      "name": "Soil_Mud_Dry"
    },
    {
      "x": -7,
      "y": 7,
      "z": -7,
      "name": "Soil_Mud_Dry"
    },
    {
      "x": -7,
      "y": 8,
      "z": -7,
      "name": "Soil_Mud_Dry"
    },
    {
      "x": -7,
      "y": 9,
      "z": -7,
      "name": "Soil_Mud_Dry"
    },
    {
      "x": -7,
      "y": 10,
      "z": -7,
      "name": "Soil_Mud_Dry"
    },
    {
      "x": -7,
      "y": 11,
      "z": -7,
      "name": "Soil_Mud_Dry"
    },
    {
      "x": -7,
      "y": 12,
      "z": -7,
      "name": "Soil_Mud_Dry"
    },
    {
      "x": -7,
      "y": 5,
      "z": -6,
      "name": "Soil_Mud_Dry"
    },
    {
      "x": -7,
      "y": 6,
      "z": -6,
      "name": "Soil_Mud_Dry"
    },
    {
      "x": -7,
      "y": 7,
      "z": -6,
      "name": "Soil_Mud_Dry"
    },
    {
      "x": -7,
      "y": 8,
      "z": -6,
      "name": "Soil_Mud_Dry"
    },
    {
      "x": -7,
      "y": 9,
      "z": -6,
      "name": "Soil_Mud_Dry"
    },
    {
      "x": -7,
      "y": 10,
      "z": -6,
      "name": "Soil_Mud_Dry"
    },
    {
      "x": -7,
      "y": 11,
      "z": -6,
      "name": "Soil_Mud_Dry"
    },
    {
      "x": -7,
      "y": 12,
      "z": -6,
      "name": "Soil_Mud_Dry"
    },
    {
      "x": -7,
      "y": 13,
      "z": -6,
      "name": "Soil_Mud_Dry"
    },
    {
      "x": -7,
      "y": 4,
      "z": -5,
      "name": "Soil_Dirt_Poisoned"
    },
    {
      "x": -7,
      "y": 5,
      "z": -5,
      "name": "Soil_Dirt_Poisoned"
    },
    {
      "x": -7,
      "y": 6,
      "z": -5,
      "name": "Soil_Mud_Dry"
    },
    {
      "x": -7,
      "y": 7,
      "z": -5,
      "name": "Soil_Mud_Dry"
    },
    {
      "x": -7,
      "y": 8,
      "z": -5,
      "name": "Soil_Mud_Dry"
    },
    {
      "x": -7,
      "y": 9,
      "z": -5,
      "name": "Soil_Mud_Dry"
    },
    {
      "x": -7,
      "y": 10,
      "z": -5,
      "name": "Soil_Mud_Dry"
    },
    {
      "x": -7,
      "y": 11,
      "z": -5,
      "name": "Soil_Mud_Dry"
    },
    {
      "x": -7,
      "y": 12,
      "z": -5,
      "name": "Soil_Mud_Dry"
    },
    {
      "x": -7,
      "y": 13,
      "z": -5,
      "name": "Soil_Mud_Dry"
    },
    {
      "x": -7,
      "y": 14,
      "z": -5,
      "name": "Soil_Mud_Dry"
    },
    {
      "x": -7,
      "y": 2,
      "z": -4,
      "name": "Soil_Mud_Dry"
    },
    {
      "x": -7,
      "y": 3,
      "z": -4,
      "name": "Soil_Dirt_Poisoned"
    },
    {
      "x": -7,
      "y": 4,
      "z": -4,
      "name": "Soil_Dirt_Poisoned"
    },
    {
      "x": -7,
      "y": 5,
      "z": -4,
      "name": "Soil_Dirt_Poisoned"
    },
    {
      "x": -7,
      "y": 6,
      "z": -4,
      "name": "Empty"
    },
    {
      "x": -7,
      "y": 7,
      "z": -4,
      "name": "Empty"
    },
    {
      "x": -7,
      "y": 8,
      "z": -4,
      "name": "Empty"
    },
    {
      "x": -7,
      "y": 9,
      "z": -4,
      "name": "Soil_Hive"
    },
    {
      "x": -7,
      "y": 10,
      "z": -4,
      "name": "Soil_Mud_Dry"
    },
    {
      "x": -7,
      "y": 11,
      "z": -4,
      "name": "Soil_Mud_Dry"
    },
    {
      "x": -7,
      "y": 12,
      "z": -4,
      "name": "Soil_Mud_Dry"
    },
    {
      "x": -7,
      "y": 13,
      "z": -4,
      "name": "Soil_Mud_Dry"
    },
    {
      "x": -7,
      "y": 14,
      "z": -4,
      "name": "Soil_Mud_Dry"
    },
    {
      "x": -7,
      "y": 2,
      "z": -3,
      "name": "Soil_Mud_Dry"
    },
    {
      "x": -7,
      "y": 3,
      "z": -3,
      "name": "Soil_Dirt_Poisoned"
    },
    {
      "x": -7,
      "y": 4,
      "z": -3,
      "name": "Soil_Dirt_Poisoned"
    },
    {
      "x": -7,
      "y": 5,
      "z": -3,
      "name": "Soil_Dirt_Poisoned"
    },
    {
      "x": -7,
      "y": 6,
      "z": -3,
      "name": "Empty"
    },
    {
      "x": -7,
      "y": 7,
      "z": -3,
      "name": "Empty"
    },
    {
      "x": -7,
      "y": 8,
      "z": -3,
      "name": "Empty"
    },
    {
      "x": -7,
      "y": 9,
      "z": -3,
      "name": "Soil_Hive"
    },
    {
      "x": -7,
      "y": 10,
      "z": -3,
      "name": "Empty"
    },
    {
      "x": -7,
      "y": 11,
      "z": -3,
      "name": "Soil_Mud_Dry"
    },
    {
      "x": -7,
      "y": 12,
      "z": -3,
      "name": "Soil_Mud_Dry"
    },
    {
      "x": -7,
      "y": 13,
      "z": -3,
      "name": "Soil_Mud_Dry"
    },
    {
      "x": -7,
      "y": 14,
      "z": -3,
      "name": "Soil_Mud_Dry"
    },
    {
      "x": -7,
      "y": 15,
      "z": -3,
      "name": "Soil_Mud_Dry"
    },
    {
      "x": -7,
      "y": 2,
      "z": -2,
      "name": "Soil_Dirt_Poisoned"
    },
    {
      "x": -7,
      "y": 3,
      "z": -2,
      "name": "Soil_Dirt_Poisoned"
    },
    {
      "x": -7,
      "y": 4,
      "z": -2,
      "name": "Empty"
    },
    {
      "x": -7,
      "y": 5,
      "z": -2,
      "name": "Empty"
    },
    {
      "x": -7,
      "y": 6,
      "z": -2,
      "name": "Empty"
    },
    {
      "x": -7,
      "y": 7,
      "z": -2,
      "name": "Empty"
    },
    {
      "x": -7,
      "y": 8,
      "z": -2,
      "name": "Empty"
    },
    {
      "x": -7,
      "y": 9,
      "z": -2,
      "name": "Soil_Hive"
    },
    {
      "x": -7,
      "y": 10,
      "z": -2,
      "name": "Empty"
    },
    {
      "x": -7,
      "y": 11,
      "z": -2,
      "name": "Soil_Mud_Dry"
    },
    {
      "x": -7,
      "y": 12,
      "z": -2,
      "name": "Soil_Mud_Dry"
    },
    {
      "x": -7,
      "y": 13,
      "z": -2,
      "name": "Soil_Mud_Dry"
    },
    {
      "x": -7,
      "y": 14,
      "z": -2,
      "name": "Soil_Mud_Dry"
    },
    {
      "x": -7,
      "y": 15,
      "z": -2,
      "name": "Soil_Mud_Dry"
    },
    {
      "x": -7,
      "y": 2,
      "z": -1,
      "name": "Soil_Mud_Dry"
    },
    {
      "x": -7,
      "y": 3,
      "z": -1,
      "name": "Soil_Dirt_Poisoned"
    },
    {
      "x": -7,
      "y": 4,
      "z": -1,
      "name": "Empty"
    },
    {
      "x": -7,
      "y": 5,
      "z": -1,
      "name": "Empty"
    },
    {
      "x": -7,
      "y": 6,
      "z": -1,
      "name": "Empty"
    },
    {
      "x": -7,
      "y": 7,
      "z": -1,
      "name": "Empty"
    },
    {
      "x": -7,
      "y": 8,
      "z": -1,
      "name": "Empty"
    },
    {
      "x": -7,
      "y": 9,
      "z": -1,
      "name": "Empty"
    },
    {
      "x": -7,
      "y": 10,
      "z": -1,
      "name": "Soil_Mud_Dry"
    },
    {
      "x": -7,
      "y": 11,
      "z": -1,
      "name": "Soil_Mud_Dry"
    },
    {
      "x": -7,
      "y": 12,
      "z": -1,
      "name": "Soil_Mud_Dry"
    },
    {
      "x": -7,
      "y": 13,
      "z": -1,
      "name": "Soil_Mud_Dry"
    },
    {
      "x": -7,
      "y": 14,
      "z": -1,
      "name": "Soil_Mud_Dry"
    },
    {
      "x": -7,
      "y": 15,
      "z": -1,
      "name": "Soil_Mud_Dry"
    },
    {
      "x": -7,
      "y": 2,
      "z": 0,
      "name": "Soil_Mud_Dry"
    },
    {
      "x": -7,
      "y": 3,
      "z": 0,
      "name": "Soil_Mud_Dry"
    },
    {
      "x": -7,
      "y": 4,
      "z": 0,
      "name": "Empty"
    },
    {
      "x": -7,
      "y": 5,
      "z": 0,
      "name": "Empty"
    },
    {
      "x": -7,
      "y": 6,
      "z": 0,
      "name": "Empty"
    },
    {
      "x": -7,
      "y": 7,
      "z": 0,
      "name": "Empty"
    },
    {
      "x": -7,
      "y": 8,
      "z": 0,
      "name": "Empty"
    },
    {
      "x": -7,
      "y": 9,
      "z": 0,
      "name": "Empty"
    },
    {
      "x": -7,
      "y": 10,
      "z": 0,
      "name": "Soil_Mud_Dry"
    },
    {
      "x": -7,
      "y": 11,
      "z": 0,
      "name": "Soil_Mud_Dry"
    },
    {
      "x": -7,
      "y": 12,
      "z": 0,
      "name": "Soil_Mud_Dry"
    },
    {
      "x": -7,
      "y": 13,
      "z": 0,
      "name": "Soil_Mud_Dry"
    },
    {
      "x": -7,
      "y": 14,
      "z": 0,
      "name": "Soil_Mud_Dry"
    },
    {
      "x": -7,
      "y": 15,
      "z": 0,
      "name": "Soil_Mud_Dry"
    },
    {
      "x": -7,
      "y": 2,
      "z": 1,
      "name": "Soil_Mud_Dry"
    },
    {
      "x": -7,
      "y": 3,
      "z": 1,
      "name": "Soil_Dirt_Poisoned"
    },
    {
      "x": -7,
      "y": 4,
      "z": 1,
      "name": "Empty"
    },
    {
      "x": -7,
      "y": 5,
      "z": 1,
      "name": "Empty"
    },
    {
      "x": -7,
      "y": 6,
      "z": 1,
      "name": "Empty"
    },
    {
      "x": -7,
      "y": 7,
      "z": 1,
      "name": "Empty"
    },
    {
      "x": -7,
      "y": 8,
      "z": 1,
      "name": "Empty"
    },
    {
      "x": -7,
      "y": 9,
      "z": 1,
      "name": "Empty"
    },
    {
      "x": -7,
      "y": 10,
      "z": 1,
      "name": "Empty"
    },
    {
      "x": -7,
      "y": 11,
      "z": 1,
      "name": "Soil_Mud_Dry"
    },
    {
      "x": -7,
      "y": 12,
      "z": 1,
      "name": "Soil_Mud_Dry"
    },
    {
      "x": -7,
      "y": 13,
      "z": 1,
      "name": "Soil_Mud_Dry"
    },
    {
      "x": -7,
      "y": 14,
      "z": 1,
      "name": "Soil_Mud_Dry"
    },
    {
      "x": -7,
      "y": 15,
      "z": 1,
      "name": "Soil_Mud_Dry"
    },
    {
      "x": -7,
      "y": 2,
      "z": 2,
      "name": "Soil_Mud_Dry"
    },
    {
      "x": -7,
      "y": 3,
      "z": 2,
      "name": "Soil_Mud_Dry"
    },
    {
      "x": -7,
      "y": 4,
      "z": 2,
      "name": "Empty"
    },
    {
      "x": -7,
      "y": 5,
      "z": 2,
      "name": "Empty"
    },
    {
      "x": -7,
      "y": 6,
      "z": 2,
      "name": "Empty"
    },
    {
      "x": -7,
      "y": 7,
      "z": 2,
      "name": "Empty"
    },
    {
      "x": -7,
      "y": 8,
      "z": 2,
      "name": "Empty"
    },
    {
      "x": -7,
      "y": 9,
      "z": 2,
      "name": "Soil_Hive"
    },
    {
      "x": -7,
      "y": 10,
      "z": 2,
      "name": "Empty"
    },
    {
      "x": -7,
      "y": 11,
      "z": 2,
      "name": "Soil_Mud_Dry"
    },
    {
      "x": -7,
      "y": 12,
      "z": 2,
      "name": "Soil_Mud_Dry"
    },
    {
      "x": -7,
      "y": 13,
      "z": 2,
      "name": "Soil_Mud_Dry"
    },
    {
      "x": -7,
      "y": 14,
      "z": 2,
      "name": "Soil_Mud_Dry"
    },
    {
      "x": -7,
      "y": 15,
      "z": 2,
      "name": "Soil_Mud_Dry"
    },
    {
      "x": -7,
      "y": 2,
      "z": 3,
      "name": "Soil_Mud_Dry"
    },
    {
      "x": -7,
      "y": 3,
      "z": 3,
      "name": "Soil_Dirt_Poisoned"
    },
    {
      "x": -7,
      "y": 4,
      "z": 3,
      "name": "Soil_Roots_Poisoned"
    },
    {
      "x": -7,
      "y": 5,
      "z": 3,
      "name": "Soil_Roots_Poisoned"
    },
    {
      "x": -7,
      "y": 6,
      "z": 3,
      "name": "Soil_Hive"
    },
    {
      "x": -7,
      "y": 7,
      "z": 3,
      "name": "Empty"
    },
    {
      "x": -7,
      "y": 8,
      "z": 3,
      "name": "Empty"
    },
    {
      "x": -7,
      "y": 9,
      "z": 3,
      "name": "Empty"
    },
    {
      "x": -7,
      "y": 10,
      "z": 3,
      "name": "Empty"
    },
    {
      "x": -7,
      "y": 11,
      "z": 3,
      "name": "Soil_Mud_Dry"
    },
    {
      "x": -7,
      "y": 12,
      "z": 3,
      "name": "Soil_Mud_Dry"
    },
    {
      "x": -7,
      "y": 13,
      "z": 3,
      "name": "Soil_Mud_Dry"
    },
    {
      "x": -7,
      "y": 14,
      "z": 3,
      "name": "Soil_Mud_Dry"
    },
    {
      "x": -7,
      "y": 15,
      "z": 3,
      "name": "Soil_Mud_Dry"
    },
    {
      "x": -7,
      "y": 2,
      "z": 4,
      "name": "Soil_Mud_Dry"
    },
    {
      "x": -7,
      "y": 3,
      "z": 4,
      "name": "Soil_Dirt_Poisoned"
    },
    {
      "x": -7,
      "y": 4,
      "z": 4,
      "name": "Soil_Dirt_Poisoned"
    },
    {
      "x": -7,
      "y": 5,
      "z": 4,
      "name": "Soil_Mud_Dry"
    },
    {
      "x": -7,
      "y": 6,
      "z": 4,
      "name": "Soil_Mud_Dry"
    },
    {
      "x": -7,
      "y": 7,
      "z": 4,
      "name": "Empty"
    },
    {
      "x": -7,
      "y": 8,
      "z": 4,
      "name": "Empty"
    },
    {
      "x": -7,
      "y": 9,
      "z": 4,
      "name": "Empty"
    },
    {
      "x": -7,
      "y": 10,
      "z": 4,
      "name": "Empty"
    },
    {
      "x": -7,
      "y": 11,
      "z": 4,
      "name": "Soil_Mud_Dry"
    },
    {
      "x": -7,
      "y": 12,
      "z": 4,
      "name": "Soil_Mud_Dry"
    },
    {
      "x": -7,
      "y": 13,
      "z": 4,
      "name": "Soil_Mud_Dry"
    },
    {
      "x": -7,
      "y": 14,
      "z": 4,
      "name": "Soil_Mud_Dry"
    },
    {
      "x": -7,
      "y": 15,
      "z": 4,
      "name": "Soil_Mud_Dry"
    },
    {
      "x": -7,
      "y": 3,
      "z": 5,
      "name": "Soil_Mud_Dry"
    },
    {
      "x": -7,
      "y": 4,
      "z": 5,
      "name": "Soil_Mud_Dry"
    },
    {
      "x": -7,
      "y": 5,
      "z": 5,
      "name": "Soil_Mud_Dry"
    },
    {
      "x": -7,
      "y": 6,
      "z": 5,
      "name": "Soil_Mud_Dry"
    },
    {
      "x": -7,
      "y": 7,
      "z": 5,
      "name": "Soil_Mud_Dry"
    },
    {
      "x": -7,
      "y": 8,
      "z": 5,
      "name": "Soil_Mud_Dry"
    },
    {
      "x": -7,
      "y": 9,
      "z": 5,
      "name": "Soil_Mud_Dry"
    },
    {
      "x": -7,
      "y": 10,
      "z": 5,
      "name": "Soil_Mud_Dry"
    },
    {
      "x": -7,
      "y": 11,
      "z": 5,
      "name": "Soil_Mud_Dry"
    },
    {
      "x": -7,
      "y": 12,
      "z": 5,
      "name": "Soil_Mud_Dry"
    },
    {
      "x": -7,
      "y": 13,
      "z": 5,
      "name": "Soil_Mud_Dry"
    },
    {
      "x": -7,
      "y": 14,
      "z": 5,
      "name": "Soil_Mud_Dry"
    },
    {
      "x": -7,
      "y": 4,
      "z": 6,
      "name": "Soil_Dirt_Poisoned"
    },
    {
      "x": -7,
      "y": 5,
      "z": 6,
      "name": "Soil_Mud_Dry"
    },
    {
      "x": -7,
      "y": 6,
      "z": 6,
      "name": "Soil_Mud_Dry"
    },
    {
      "x": -7,
      "y": 7,
      "z": 6,
      "name": "Soil_Mud_Dry"
    },
    {
      "x": -7,
      "y": 8,
      "z": 6,
      "name": "Soil_Mud_Dry"
    },
    {
      "x": -7,
      "y": 9,
      "z": 6,
      "name": "Soil_Mud_Dry"
    },
    {
      "x": -7,
      "y": 10,
      "z": 6,
      "name": "Soil_Mud_Dry"
    },
    {
      "x": -7,
      "y": 11,
      "z": 6,
      "name": "Soil_Mud_Dry"
    },
    {
      "x": -7,
      "y": 12,
      "z": 6,
      "name": "Soil_Mud_Dry"
    },
    {
      "x": -7,
      "y": 13,
      "z": 6,
      "name": "Soil_Mud_Dry"
    },
    {
      "x": -7,
      "y": 14,
      "z": 6,
      "name": "Soil_Mud_Dry"
    },
    {
      "x": -7,
      "y": 5,
      "z": 7,
      "name": "Soil_Mud_Dry"
    },
    {
      "x": -7,
      "y": 6,
      "z": 7,
      "name": "Soil_Mud_Dry"
    },
    {
      "x": -7,
      "y": 7,
      "z": 7,
      "name": "Soil_Mud_Dry"
    },
    {
      "x": -7,
      "y": 8,
      "z": 7,
      "name": "Soil_Mud_Dry"
    },
    {
      "x": -7,
      "y": 9,
      "z": 7,
      "name": "Soil_Mud_Dry"
    },
    {
      "x": -7,
      "y": 10,
      "z": 7,
      "name": "Soil_Mud_Dry"
    },
    {
      "x": -7,
      "y": 11,
      "z": 7,
      "name": "Soil_Mud_Dry"
    },
    {
      "x": -7,
      "y": 12,
      "z": 7,
      "name": "Soil_Mud_Dry"
    },
    {
      "x": -7,
      "y": 13,
      "z": 7,
      "name": "Soil_Mud_Dry"
    },
    {
      "x": -7,
      "y": 5,
      "z": 8,
      "name": "Soil_Mud_Dry"
    },
    {
      "x": -7,
      "y": 6,
      "z": 8,
      "name": "Soil_Mud_Dry"
    },
    {
      "x": -7,
      "y": 7,
      "z": 8,
      "name": "Soil_Mud_Dry"
    },
    {
      "x": -7,
      "y": 8,
      "z": 8,
      "name": "Soil_Mud_Dry"
    },
    {
      "x": -7,
      "y": 9,
      "z": 8,
      "name": "Soil_Mud_Dry"
    },
    {
      "x": -7,
      "y": 10,
      "z": 8,
      "name": "Soil_Mud_Dry"
    },
    {
      "x": -7,
      "y": 11,
      "z": 8,
      "name": "Soil_Mud_Dry"
    },
    {
      "x": -7,
      "y": 12,
      "z": 8,
      "name": "Soil_Mud_Dry"
    },
    {
      "x": -6,
      "y": 4,
      "z": -7,
      "name": "Soil_Dirt_Poisoned"
    },
    {
      "x": -6,
      "y": 5,
      "z": -7,
      "name": "Soil_Mud_Dry"
    },
    {
      "x": -6,
      "y": 6,
      "z": -7,
      "name": "Soil_Mud_Dry"
    },
    {
      "x": -6,
      "y": 7,
      "z": -7,
      "name": "Soil_Mud_Dry"
    },
    {
      "x": -6,
      "y": 8,
      "z": -7,
      "name": "Soil_Mud_Dry"
    },
    {
      "x": -6,
      "y": 9,
      "z": -7,
      "name": "Soil_Mud_Dry"
    },
    {
      "x": -6,
      "y": 10,
      "z": -7,
      "name": "Soil_Mud_Dry"
    },
    {
      "x": -6,
      "y": 11,
      "z": -7,
      "name": "Soil_Mud_Dry"
    },
    {
      "x": -6,
      "y": 12,
      "z": -7,
      "name": "Soil_Mud_Dry"
    },
    {
      "x": -6,
      "y": 13,
      "z": -7,
      "name": "Soil_Mud_Dry"
    },
    {
      "x": -6,
      "y": 4,
      "z": -6,
      "name": "Soil_Dirt_Poisoned"
    },
    {
      "x": -6,
      "y": 5,
      "z": -6,
      "name": "Soil_Dirt_Poisoned"
    },
    {
      "x": -6,
      "y": 6,
      "z": -6,
      "name": "Soil_Hive"
    },
    {
      "x": -6,
      "y": 7,
      "z": -6,
      "name": "Soil_Hive"
    },
    {
      "x": -6,
      "y": 8,
      "z": -6,
      "name": "Soil_Hive"
    },
    {
      "x": -6,
      "y": 9,
      "z": -6,
      "name": "Empty"
    },
    {
      "x": -6,
      "y": 10,
      "z": -6,
      "name": "Soil_Mud_Dry"
    },
    {
      "x": -6,
      "y": 11,
      "z": -6,
      "name": "Soil_Mud_Dry"
    },
    {
      "x": -6,
      "y": 12,
      "z": -6,
      "name": "Soil_Mud_Dry"
    },
    {
      "x": -6,
      "y": 13,
      "z": -6,
      "name": "Soil_Mud_Dry"
    },
    {
      "x": -6,
      "y": 14,
      "z": -6,
      "name": "Soil_Mud_Dry"
    },
    {
      "x": -6,
      "y": 2,
      "z": -5,
      "name": "Soil_Mud_Dry"
    },
    {
      "x": -6,
      "y": 3,
      "z": -5,
      "name": "Soil_Roots_Poisoned"
    },
    {
      "x": -6,
      "y": 4,
      "z": -5,
      "name": "Soil_Roots_Poisoned"
    },
    {
      "x": -6,
      "y": 5,
      "z": -5,
      "name": "Soil_Roots_Poisoned"
    },
    {
      "x": -6,
      "y": 6,
      "z": -5,
      "name": "Soil_Roots_Poisoned"
    },
    {
      "x": -6,
      "y": 7,
      "z": -5,
      "name": "Empty"
    },
    {
      "x": -6,
      "y": 8,
      "z": -5,
      "name": "Empty"
    },
    {
      "x": -6,
      "y": 9,
      "z": -5,
      "name": "Empty"
    },
    {
      "x": -6,
      "y": 10,
      "z": -5,
      "name": "Soil_Hive"
    },
    {
      "x": -6,
      "y": 11,
      "z": -5,
      "name": "Empty"
    },
    {
      "x": -6,
      "y": 12,
      "z": -5,
      "name": "Soil_Mud_Dry"
    },
    {
      "x": -6,
      "y": 13,
      "z": -5,
      "name": "Soil_Mud_Dry"
    },
    {
      "x": -6,
      "y": 14,
      "z": -5,
      "name": "Soil_Mud_Dry"
    },
    {
      "x": -6,
      "y": 15,
      "z": -5,
      "name": "Soil_Mud_Dry"
    },
    {
      "x": -6,
      "y": 2,
      "z": -4,
      "name": "Soil_Mud_Dry"
    },
    {
      "x": -6,
      "y": 3,
      "z": -4,
      "name": "Soil_Roots_Poisoned"
    },
    {
      "x": -6,
      "y": 4,
      "z": -4,
      "name": "Empty"
    },
    {
      "x": -6,
      "y": 5,
      "z": -4,
      "name": "Empty"
    },
    {
      "x": -6,
      "y": 6,
      "z": -4,
      "name": "Empty"
    },
    {
      "x": -6,
      "y": 7,
      "z": -4,
      "name": "Empty"
    },
    {
      "x": -6,
      "y": 8,
      "z": -4,
      "name": "Empty"
    },
    {
      "x": -6,
      "y": 9,
      "z": -4,
      "name": "Empty"
    },
    {
      "x": -6,
      "y": 10,
      "z": -4,
      "name": "Soil_Hive"
    },
    {
      "x": -6,
      "y": 11,
      "z": -4,
      "name": "Empty"
    },
    {
      "x": -6,
      "y": 12,
      "z": -4,
      "name": "Soil_Mud_Dry"
    },
    {
      "x": -6,
      "y": 13,
      "z": -4,
      "name": "Soil_Mud_Dry"
    },
    {
      "x": -6,
      "y": 14,
      "z": -4,
      "name": "Soil_Mud_Dry"
    },
    {
      "x": -6,
      "y": 15,
      "z": -4,
      "name": "Soil_Mud_Dry"
    },
    {
      "x": -6,
      "y": 2,
      "z": -3,
      "name": "Soil_Dirt_Poisoned"
    },
    {
      "x": -6,
      "y": 3,
      "z": -3,
      "name": "Soil_Dirt_Poisoned"
    },
    {
      "x": -6,
      "y": 4,
      "z": -3,
      "name": "Empty"
    },
    {
      "x": -6,
      "y": 5,
      "z": -3,
      "name": "Empty"
    },
    {
      "x": -6,
      "y": 6,
      "z": -3,
      "name": "Empty"
    },
    {
      "x": -6,
      "y": 7,
      "z": -3,
      "name": "Empty"
    },
    {
      "x": -6,
      "y": 8,
      "z": -3,
      "name": "Empty"
    },
    {
      "x": -6,
      "y": 9,
      "z": -3,
      "name": "Empty"
    },
    {
      "x": -6,
      "y": 10,
      "z": -3,
      "name": "Empty"
    },
    {
      "x": -6,
      "y": 11,
      "z": -3,
      "name": "Empty"
    },
    {
      "x": -6,
      "y": 12,
      "z": -3,
      "name": "Soil_Mud_Dry"
    },
    {
      "x": -6,
      "y": 13,
      "z": -3,
      "name": "Soil_Mud_Dry"
    },
    {
      "x": -6,
      "y": 14,
      "z": -3,
      "name": "Soil_Mud_Dry"
    },
    {
      "x": -6,
      "y": 15,
      "z": -3,
      "name": "Soil_Mud_Dry"
    },
    {
      "x": -6,
      "y": 2,
      "z": -2,
      "name": "Soil_Mud_Dry"
    },
    {
      "x": -6,
      "y": 3,
      "z": -2,
      "name": "Soil_Dirt_Poisoned"
    },
    {
      "x": -6,
      "y": 4,
      "z": -2,
      "name": "Empty"
    },
    {
      "x": -6,
      "y": 5,
      "z": -2,
      "name": "Empty"
    },
    {
      "x": -6,
      "y": 6,
      "z": -2,
      "name": "Empty"
    },
    {
      "x": -6,
      "y": 7,
      "z": -2,
      "name": "Empty"
    },
    {
      "x": -6,
      "y": 8,
      "z": -2,
      "name": "Empty"
    },
    {
      "x": -6,
      "y": 9,
      "z": -2,
      "name": "Empty"
    },
    {
      "x": -6,
      "y": 10,
      "z": -2,
      "name": "Soil_Hive"
    },
    {
      "x": -6,
      "y": 11,
      "z": -2,
      "name": "Empty"
    },
    {
      "x": -6,
      "y": 12,
      "z": -2,
      "name": "Empty"
    },
    {
      "x": -6,
      "y": 13,
      "z": -2,
      "name": "Soil_Mud_Dry"
    },
    {
      "x": -6,
      "y": 14,
      "z": -2,
      "name": "Soil_Mud_Dry"
    },
    {
      "x": -6,
      "y": 15,
      "z": -2,
      "name": "Soil_Mud_Dry"
    },
    {
      "x": -6,
      "y": 2,
      "z": -1,
      "name": "Soil_Mud_Dry"
    },
    {
      "x": -6,
      "y": 3,
      "z": -1,
      "name": "Soil_Mud_Dry"
    },
    {
      "x": -6,
      "y": 4,
      "z": -1,
      "name": "Empty"
    },
    {
      "x": -6,
      "y": 5,
      "z": -1,
      "name": "Empty"
    },
    {
      "x": -6,
      "y": 6,
      "z": -1,
      "name": "Empty"
    },
    {
      "x": -6,
      "y": 7,
      "z": -1,
      "name": "Empty"
    },
    {
      "x": -6,
      "y": 8,
      "z": -1,
      "name": "Empty"
    },
    {
      "x": -6,
      "y": 9,
      "z": -1,
      "name": "Empty"
    },
    {
      "x": -6,
      "y": 10,
      "z": -1,
      "name": "Soil_Hive"
    },
    {
      "x": -6,
      "y": 11,
      "z": -1,
      "name": "Empty"
    },
    {
      "x": -6,
      "y": 12,
      "z": -1,
      "name": "Empty"
    },
    {
      "x": -6,
      "y": 13,
      "z": -1,
      "name": "Soil_Mud_Dry"
    },
    {
      "x": -6,
      "y": 14,
      "z": -1,
      "name": "Soil_Mud_Dry"
    },
    {
      "x": -6,
      "y": 15,
      "z": -1,
      "name": "Soil_Mud_Dry"
    },
    {
      "x": -6,
      "y": 2,
      "z": 0,
      "name": "Soil_Mud_Dry"
    },
    {
      "x": -6,
      "y": 3,
      "z": 0,
      "name": "Soil_Roots_Poisoned"
    },
    {
      "x": -6,
      "y": 4,
      "z": 0,
      "name": "Empty"
    },
    {
      "x": -6,
      "y": 5,
      "z": 0,
      "name": "Empty"
    },
    {
      "x": -6,
      "y": 6,
      "z": 0,
      "name": "Empty"
    },
    {
      "x": -6,
      "y": 7,
      "z": 0,
      "name": "Empty"
    },
    {
      "x": -6,
      "y": 8,
      "z": 0,
      "name": "Empty"
    },
    {
      "x": -6,
      "y": 9,
      "z": 0,
      "name": "Empty"
    },
    {
      "x": -6,
      "y": 10,
      "z": 0,
      "name": "Soil_Hive"
    },
    {
      "x": -6,
      "y": 11,
      "z": 0,
      "name": "Empty"
    },
    {
      "x": -6,
      "y": 12,
      "z": 0,
      "name": "Soil_Mud_Dry"
    },
    {
      "x": -6,
      "y": 13,
      "z": 0,
      "name": "Soil_Mud_Dry"
    },
    {
      "x": -6,
      "y": 14,
      "z": 0,
      "name": "Soil_Mud_Dry"
    },
    {
      "x": -6,
      "y": 15,
      "z": 0,
      "name": "Soil_Mud_Dry"
    },
    {
      "x": -6,
      "y": 2,
      "z": 1,
      "name": "Soil_Dirt_Poisoned"
    },
    {
      "x": -6,
      "y": 3,
      "z": 1,
      "name": "Soil_Dirt_Poisoned"
    },
    {
      "x": -6,
      "y": 4,
      "z": 1,
      "name": "Empty"
    },
    {
      "x": -6,
      "y": 5,
      "z": 1,
      "name": "Empty"
    },
    {
      "x": -6,
      "y": 6,
      "z": 1,
      "name": "Empty"
    },
    {
      "x": -6,
      "y": 7,
      "z": 1,
      "name": "Empty"
    },
    {
      "x": -6,
      "y": 8,
      "z": 1,
      "name": "Empty"
    },
    {
      "x": -6,
      "y": 9,
      "z": 1,
      "name": "Soil_Hive"
    },
    {
      "x": -6,
      "y": 10,
      "z": 1,
      "name": "Soil_Hive"
    },
    {
      "x": -6,
      "y": 11,
      "z": 1,
      "name": "Soil_Hive"
    },
    {
      "x": -6,
      "y": 12,
      "z": 1,
      "name": "Soil_Mud_Dry"
    },
    {
      "x": -6,
      "y": 13,
      "z": 1,
      "name": "Soil_Mud_Dry"
    },
    {
      "x": -6,
      "y": 14,
      "z": 1,
      "name": "Soil_Mud_Dry"
    },
    {
      "x": -6,
      "y": 15,
      "z": 1,
      "name": "Soil_Mud_Dry"
    },
    {
      "x": -6,
      "y": 2,
      "z": 2,
      "name": "Soil_Mud_Dry"
    },
    {
      "x": -6,
      "y": 3,
      "z": 2,
      "name": "Soil_Roots_Poisoned"
    },
    {
      "x": -6,
      "y": 4,
      "z": 2,
      "name": "Empty"
    },
    {
      "x": -6,
      "y": 5,
      "z": 2,
      "name": "Empty"
    },
    {
      "x": -6,
      "y": 6,
      "z": 2,
      "name": "Empty"
    },
    {
      "x": -6,
      "y": 7,
      "z": 2,
      "name": "Empty"
    },
    {
      "x": -6,
      "y": 8,
      "z": 2,
      "name": "Empty"
    },
    {
      "x": -6,
      "y": 9,
      "z": 2,
      "name": "Empty"
    },
    {
      "x": -6,
      "y": 10,
      "z": 2,
      "name": "Empty"
    },
    {
      "x": -6,
      "y": 11,
      "z": 2,
      "name": "Soil_Mud_Dry"
    },
    {
      "x": -6,
      "y": 12,
      "z": 2,
      "name": "Soil_Mud_Dry"
    },
    {
      "x": -6,
      "y": 13,
      "z": 2,
      "name": "Soil_Mud_Dry"
    },
    {
      "x": -6,
      "y": 14,
      "z": 2,
      "name": "Soil_Mud_Dry"
    },
    {
      "x": -6,
      "y": 15,
      "z": 2,
      "name": "Soil_Mud_Dry"
    },
    {
      "x": -6,
      "y": 2,
      "z": 3,
      "name": "Soil_Mud_Dry"
    },
    {
      "x": -6,
      "y": 3,
      "z": 3,
      "name": "Soil_Roots_Poisoned"
    },
    {
      "x": -6,
      "y": 4,
      "z": 3,
      "name": "Soil_Roots_Poisoned"
    },
    {
      "x": -6,
      "y": 5,
      "z": 3,
      "name": "Empty"
    },
    {
      "x": -6,
      "y": 6,
      "z": 3,
      "name": "Empty"
    },
    {
      "x": -6,
      "y": 7,
      "z": 3,
      "name": "Empty"
    },
    {
      "x": -6,
      "y": 8,
      "z": 3,
      "name": "Empty"
    },
    {
      "x": -6,
      "y": 9,
      "z": 3,
      "name": "Empty"
    },
    {
      "x": -6,
      "y": 10,
      "z": 3,
      "name": "Empty"
    },
    {
      "x": -6,
      "y": 11,
      "z": 3,
      "name": "Soil_Mud_Dry"
    },
    {
      "x": -6,
      "y": 12,
      "z": 3,
      "name": "Soil_Mud_Dry"
    },
    {
      "x": -6,
      "y": 13,
      "z": 3,
      "name": "Soil_Mud_Dry"
    },
    {
      "x": -6,
      "y": 14,
      "z": 3,
      "name": "Soil_Mud_Dry"
    },
    {
      "x": -6,
      "y": 15,
      "z": 3,
      "name": "Soil_Mud_Dry"
    },
    {
      "x": -6,
      "y": 2,
      "z": 4,
      "name": "Soil_Dirt_Poisoned"
    },
    {
      "x": -6,
      "y": 3,
      "z": 4,
      "name": "Soil_Dirt_Poisoned"
    },
    {
      "x": -6,
      "y": 4,
      "z": 4,
      "name": "Empty"
    },
    {
      "x": -6,
      "y": 5,
      "z": 4,
      "name": "Empty"
    },
    {
      "x": -6,
      "y": 6,
      "z": 4,
      "name": "Empty"
    },
    {
      "x": -6,
      "y": 7,
      "z": 4,
      "name": "Empty"
    },
    {
      "x": -6,
      "y": 8,
      "z": 4,
      "name": "Empty"
    },
    {
      "x": -6,
      "y": 9,
      "z": 4,
      "name": "Deco_Scarak_Eggsacks",
      "rotation": 6
    },
    {
      "x": -6,
      "y": 10,
      "z": 4,
      "name": "Empty"
    },
    {
      "x": -6,
      "y": 11,
      "z": 4,
      "name": "Soil_Mud_Dry"
    },
    {
      "x": -6,
      "y": 12,
      "z": 4,
      "name": "Soil_Mud_Dry"
    },
    {
      "x": -6,
      "y": 13,
      "z": 4,
      "name": "Soil_Mud_Dry"
    },
    {
      "x": -6,
      "y": 14,
      "z": 4,
      "name": "Soil_Mud_Dry"
    },
    {
      "x": -6,
      "y": 15,
      "z": 4,
      "name": "Soil_Mud_Dry"
    },
    {
      "x": -6,
      "y": 3,
      "z": 5,
      "name": "Soil_Dirt_Poisoned"
    },
    {
      "x": -6,
      "y": 4,
      "z": 5,
      "name": "Plant_Bramble_Dead_Twisted"
    },
    {
      "x": -6,
      "y": 5,
      "z": 5,
      "name": "Empty"
    },
    {
      "x": -6,
      "y": 6,
      "z": 5,
      "name": "Empty"
    },
    {
      "x": -6,
      "y": 7,
      "z": 5,
      "name": "Empty"
    },
    {
      "x": -6,
      "y": 8,
      "z": 5,
      "name": "Empty"
    },
    {
      "x": -6,
      "y": 9,
      "z": 5,
      "name": "Soil_Hive"
    },
    {
      "x": -6,
      "y": 10,
      "z": 5,
      "name": "Soil_Hive"
    },
    {
      "x": -6,
      "y": 11,
      "z": 5,
      "name": "Soil_Mud_Dry"
    },
    {
      "x": -6,
      "y": 12,
      "z": 5,
      "name": "Soil_Mud_Dry"
    },
    {
      "x": -6,
      "y": 13,
      "z": 5,
      "name": "Soil_Mud_Dry"
    },
    {
      "x": -6,
      "y": 14,
      "z": 5,
      "name": "Soil_Mud_Dry"
    },
    {
      "x": -6,
      "y": 15,
      "z": 5,
      "name": "Soil_Mud_Dry"
    },
    {
      "x": -6,
      "y": 3,
      "z": 6,
      "name": "Soil_Dirt_Poisoned"
    },
    {
      "x": -6,
      "y": 4,
      "z": 6,
      "name": "Soil_Dirt_Poisoned"
    },
    {
      "x": -6,
      "y": 5,
      "z": 6,
      "name": "Soil_Dirt_Poisoned"
    },
    {
      "x": -6,
      "y": 6,
      "z": 6,
      "name": "Soil_Mud_Dry"
    },
    {
      "x": -6,
      "y": 7,
      "z": 6,
      "name": "Empty"
    },
    {
      "x": -6,
      "y": 8,
      "z": 6,
      "name": "Soil_Hive"
    },
    {
      "x": -6,
      "y": 9,
      "z": 6,
      "name": "Soil_Hive"
    },
    {
      "x": -6,
      "y": 10,
      "z": 6,
      "name": "Soil_Mud_Dry"
    },
    {
      "x": -6,
      "y": 11,
      "z": 6,
      "name": "Soil_Mud_Dry"
    },
    {
      "x": -6,
      "y": 12,
      "z": 6,
      "name": "Soil_Mud_Dry"
    },
    {
      "x": -6,
      "y": 13,
      "z": 6,
      "name": "Soil_Mud_Dry"
    },
    {
      "x": -6,
      "y": 14,
      "z": 6,
      "name": "Soil_Mud_Dry"
    },
    {
      "x": -6,
      "y": 15,
      "z": 6,
      "name": "Soil_Mud_Dry"
    },
    {
      "x": -6,
      "y": 4,
      "z": 7,
      "name": "Soil_Dirt_Poisoned"
    },
    {
      "x": -6,
      "y": 5,
      "z": 7,
      "name": "Soil_Mud_Dry"
    },
    {
      "x": -6,
      "y": 6,
      "z": 7,
      "name": "Soil_Mud_Dry"
    },
    {
      "x": -6,
      "y": 7,
      "z": 7,
      "name": "Soil_Mud_Dry"
    },
    {
      "x": -6,
      "y": 8,
      "z": 7,
      "name": "Soil_Mud_Dry"
    },
    {
      "x": -6,
      "y": 9,
      "z": 7,
      "name": "Soil_Mud_Dry"
    },
    {
      "x": -6,
      "y": 10,
      "z": 7,
      "name": "Soil_Mud_Dry"
    },
    {
      "x": -6,
      "y": 11,
      "z": 7,
      "name": "Soil_Mud_Dry"
    },
    {
      "x": -6,
      "y": 12,
      "z": 7,
      "name": "Soil_Mud_Dry"
    },
    {
      "x": -6,
      "y": 13,
      "z": 7,
      "name": "Soil_Mud_Dry"
    },
    {
      "x": -6,
      "y": 14,
      "z": 7,
      "name": "Soil_Mud_Dry"
    },
    {
      "x": -6,
      "y": 4,
      "z": 8,
      "name": "Soil_Mud_Dry"
    },
    {
      "x": -6,
      "y": 5,
      "z": 8,
      "name": "Soil_Mud_Dry"
    },
    {
      "x": -6,
      "y": 6,
      "z": 8,
      "name": "Soil_Mud_Dry"
    },
    {
      "x": -6,
      "y": 7,
      "z": 8,
      "name": "Soil_Mud_Dry"
    },
    {
      "x": -6,
      "y": 8,
      "z": 8,
      "name": "Soil_Mud_Dry"
    },
    {
      "x": -6,
      "y": 9,
      "z": 8,
      "name": "Soil_Mud_Dry"
    },
    {
      "x": -6,
      "y": 10,
      "z": 8,
      "name": "Soil_Mud_Dry"
    },
    {
      "x": -6,
      "y": 11,
      "z": 8,
      "name": "Soil_Mud_Dry"
    },
    {
      "x": -6,
      "y": 12,
      "z": 8,
      "name": "Soil_Mud_Dry"
    },
    {
      "x": -6,
      "y": 13,
      "z": 8,
      "name": "Soil_Mud_Dry"
    },
    {
      "x": -5,
      "y": 3,
      "z": -7,
      "name": "Soil_Mud_Dry"
    },
    {
      "x": -5,
      "y": 4,
      "z": -7,
      "name": "Soil_Mud_Dry"
    },
    {
      "x": -5,
      "y": 5,
      "z": -7,
      "name": "Soil_Mud_Dry"
    },
    {
      "x": -5,
      "y": 6,
      "z": -7,
      "name": "Soil_Mud_Dry"
    },
    {
      "x": -5,
      "y": 7,
      "z": -7,
      "name": "Soil_Mud_Dry"
    },
    {
      "x": -5,
      "y": 8,
      "z": -7,
      "name": "Soil_Mud_Dry"
    },
    {
      "x": -5,
      "y": 9,
      "z": -7,
      "name": "Soil_Mud_Dry"
    },
    {
      "x": -5,
      "y": 10,
      "z": -7,
      "name": "Soil_Mud_Dry"
    },
    {
      "x": -5,
      "y": 11,
      "z": -7,
      "name": "Soil_Mud_Dry"
    },
    {
      "x": -5,
      "y": 12,
      "z": -7,
      "name": "Soil_Mud_Dry"
    },
    {
      "x": -5,
      "y": 13,
      "z": -7,
      "name": "Soil_Mud_Dry"
    },
    {
      "x": -5,
      "y": 14,
      "z": -7,
      "name": "Soil_Mud_Dry"
    },
    {
      "x": -5,
      "y": 2,
      "z": -6,
      "name": "Soil_Mud_Dry"
    },
    {
      "x": -5,
      "y": 3,
      "z": -6,
      "name": "Soil_Dirt_Poisoned"
    },
    {
      "x": -5,
      "y": 4,
      "z": -6,
      "name": "Plant_Crop_Mushroom_Glowing_Orange"
    },
    {
      "x": -5,
      "y": 5,
      "z": -6,
      "name": "Empty"
    },
    {
      "x": -5,
      "y": 6,
      "z": -6,
      "name": "Empty"
    },
    {
      "x": -5,
      "y": 7,
      "z": -6,
      "name": "Empty"
    },
    {
      "x": -5,
      "y": 8,
      "z": -6,
      "name": "Empty"
    },
    {
      "x": -5,
      "y": 9,
      "z": -6,
      "name": "Empty"
    },
    {
      "x": -5,
      "y": 10,
      "z": -6,
      "name": "Soil_Mud_Dry"
    },
    {
      "x": -5,
      "y": 11,
      "z": -6,
      "name": "Soil_Mud_Dry"
    },
    {
      "x": -5,
      "y": 12,
      "z": -6,
      "name": "Soil_Mud_Dry"
    },
    {
      "x": -5,
      "y": 13,
      "z": -6,
      "name": "Soil_Mud_Dry"
    },
    {
      "x": -5,
      "y": 14,
      "z": -6,
      "name": "Soil_Mud_Dry"
    },
    {
      "x": -5,
      "y": 2,
      "z": -5,
      "name": "Soil_Dirt_Poisoned"
    },
    {
      "x": -5,
      "y": 3,
      "z": -5,
      "name": "Soil_Roots_Poisoned"
    },
    {
      "x": -5,
      "y": 4,
      "z": -5,
      "name": "Empty"
    },
    {
      "x": -5,
      "y": 5,
      "z": -5,
      "name": "Empty"
    },
    {
      "x": -5,
      "y": 6,
      "z": -5,
      "name": "Empty"
    },
    {
      "x": -5,
      "y": 7,
      "z": -5,
      "name": "Empty"
    },
    {
      "x": -5,
      "y": 8,
      "z": -5,
      "name": "Soil_Hive"
    },
    {
      "x": -5,
      "y": 9,
      "z": -5,
      "name": "Soil_Hive"
    },
    {
      "x": -5,
      "y": 10,
      "z": -5,
      "name": "Soil_Hive"
    },
    {
      "x": -5,
      "y": 11,
      "z": -5,
      "name": "Empty"
    },
    {
      "x": -5,
      "y": 12,
      "z": -5,
      "name": "Empty"
    },
    {
      "x": -5,
      "y": 13,
      "z": -5,
      "name": "Soil_Mud_Dry"
    },
    {
      "x": -5,
      "y": 14,
      "z": -5,
      "name": "Soil_Mud_Dry"
    },
    {
      "x": -5,
      "y": 15,
      "z": -5,
      "name": "Soil_Mud_Dry"
    },
    {
      "x": -5,
      "y": 2,
      "z": -4,
      "name": "Soil_Mud_Dry"
    },
    {
      "x": -5,
      "y": 3,
      "z": -4,
      "name": "Soil_Roots_Poisoned"
    },
    {
      "x": -5,
      "y": 4,
      "z": -4,
      "name": "Empty"
    },
    {
      "x": -5,
      "y": 5,
      "z": -4,
      "name": "Empty"
    },
    {
      "x": -5,
      "y": 6,
      "z": -4,
      "name": "Empty"
    },
    {
      "x": -5,
      "y": 7,
      "z": -4,
      "name": "Empty"
    },
    {
      "x": -5,
      "y": 8,
      "z": -4,
      "name": "Empty"
    },
    {
      "x": -5,
      "y": 9,
      "z": -4,
      "name": "Empty"
    },
    {
      "x": -5,
      "y": 10,
      "z": -4,
      "name": "Empty"
    },
    {
      "x": -5,
      "y": 11,
      "z": -4,
      "name": "Empty"
    },
    {
      "x": -5,
      "y": 12,
      "z": -4,
      "name": "Empty"
    },
    {
      "x": -5,
      "y": 13,
      "z": -4,
      "name": "Soil_Mud_Dry"
    },
    {
      "x": -5,
      "y": 14,
      "z": -4,
      "name": "Soil_Mud_Dry"
    },
    {
      "x": -5,
      "y": 15,
      "z": -4,
      "name": "Soil_Mud_Dry"
    },
    {
      "x": -5,
      "y": 2,
      "z": -3,
      "name": "Soil_Mud_Dry"
    },
    {
      "x": -5,
      "y": 3,
      "z": -3,
      "name": "Soil_Roots_Poisoned"
    },
    {
      "x": -5,
      "y": 4,
      "z": -3,
      "name": "Empty"
    },
    {
      "x": -5,
      "y": 5,
      "z": -3,
      "name": "Empty"
    },
    {
      "x": -5,
      "y": 6,
      "z": -3,
      "name": "Empty"
    },
    {
      "x": -5,
      "y": 7,
      "z": -3,
      "name": "Empty"
    },
    {
      "x": -5,
      "y": 8,
      "z": -3,
      "name": "Empty"
    },
    {
      "x": -5,
      "y": 9,
      "z": -3,
      "name": "Empty"
    },
    {
      "x": -5,
      "y": 10,
      "z": -3,
      "name": "Empty"
    },
    {
      "x": -5,
      "y": 11,
      "z": -3,
      "name": "Empty"
    },
    {
      "x": -5,
      "y": 12,
      "z": -3,
      "name": "Empty"
    },
    {
      "x": -5,
      "y": 13,
      "z": -3,
      "name": "Soil_Mud_Dry"
    },
    {
      "x": -5,
      "y": 14,
      "z": -3,
      "name": "Soil_Mud_Dry"
    },
    {
      "x": -5,
      "y": 15,
      "z": -3,
      "name": "Soil_Mud_Dry"
    },
    {
      "x": -5,
      "y": 2,
      "z": -2,
      "name": "Soil_Mud_Dry"
    },
    {
      "x": -5,
      "y": 3,
      "z": -2,
      "name": "Soil_Hive"
    },
    {
      "x": -5,
      "y": 4,
      "z": -2,
      "name": "Empty"
    },
    {
      "x": -5,
      "y": 5,
      "z": -2,
      "name": "Empty"
    },
    {
      "x": -5,
      "y": 6,
      "z": -2,
      "name": "Empty"
    },
    {
      "x": -5,
      "y": 7,
      "z": -2,
      "name": "Empty"
    },
    {
      "x": -5,
      "y": 8,
      "z": -2,
      "name": "Empty"
    },
    {
      "x": -5,
      "y": 9,
      "z": -2,
      "name": "Empty"
    },
    {
      "x": -5,
      "y": 10,
      "z": -2,
      "name": "Empty"
    },
    {
      "x": -5,
      "y": 11,
      "z": -2,
      "name": "Empty"
    },
    {
      "x": -5,
      "y": 12,
      "z": -2,
      "name": "Empty"
    },
    {
      "x": -5,
      "y": 13,
      "z": -2,
      "name": "Soil_Mud_Dry"
    },
    {
      "x": -5,
      "y": 14,
      "z": -2,
      "name": "Soil_Mud_Dry"
    },
    {
      "x": -5,
      "y": 15,
      "z": -2,
      "name": "Soil_Mud_Dry"
    },
    {
      "x": -5,
      "y": 2,
      "z": -1,
      "name": "Soil_Mud_Dry"
    },
    {
      "x": -5,
      "y": 3,
      "z": -1,
      "name": "Soil_Hive"
    },
    {
      "x": -5,
      "y": 4,
      "z": -1,
      "name": "Empty"
    },
    {
      "x": -5,
      "y": 5,
      "z": -1,
      "name": "Empty"
    },
    {
      "x": -5,
      "y": 6,
      "z": -1,
      "name": "Empty"
    },
    {
      "x": -5,
      "y": 7,
      "z": -1,
      "name": "Empty"
    },
    {
      "x": -5,
      "y": 8,
      "z": -1,
      "name": "Empty"
    },
    {
      "x": -5,
      "y": 9,
      "z": -1,
      "name": "Empty"
    },
    {
      "x": -5,
      "y": 10,
      "z": -1,
      "name": "Empty"
    },
    {
      "x": -5,
      "y": 11,
      "z": -1,
      "name": "Empty"
    },
    {
      "x": -5,
      "y": 12,
      "z": -1,
      "name": "Empty"
    },
    {
      "x": -5,
      "y": 13,
      "z": -1,
      "name": "Empty"
    },
    {
      "x": -5,
      "y": 14,
      "z": -1,
      "name": "Soil_Mud_Dry"
    },
    {
      "x": -5,
      "y": 15,
      "z": -1,
      "name": "Soil_Mud_Dry"
    },
    {
      "x": -5,
      "y": 2,
      "z": 0,
      "name": "Soil_Mud_Dry"
    },
    {
      "x": -5,
      "y": 3,
      "z": 0,
      "name": "Soil_Dirt_Poisoned"
    },
    {
      "x": -5,
      "y": 4,
      "z": 0,
      "name": "Empty"
    },
    {
      "x": -5,
      "y": 5,
      "z": 0,
      "name": "Empty"
    },
    {
      "x": -5,
      "y": 6,
      "z": 0,
      "name": "Empty"
    },
    {
      "x": -5,
      "y": 7,
      "z": 0,
      "name": "Empty"
    },
    {
      "x": -5,
      "y": 8,
      "z": 0,
      "name": "Empty"
    },
    {
      "x": -5,
      "y": 9,
      "z": 0,
      "name": "Empty"
    },
    {
      "x": -5,
      "y": 10,
      "z": 0,
      "name": "Empty"
    },
    {
      "x": -5,
      "y": 11,
      "z": 0,
      "name": "Empty"
    },
    {
      "x": -5,
      "y": 12,
      "z": 0,
      "name": "Empty"
    },
    {
      "x": -5,
      "y": 13,
      "z": 0,
      "name": "Empty"
    },
    {
      "x": -5,
      "y": 14,
      "z": 0,
      "name": "Soil_Mud_Dry"
    },
    {
      "x": -5,
      "y": 15,
      "z": 0,
      "name": "Soil_Mud_Dry"
    },
    {
      "x": -5,
      "y": 2,
      "z": 1,
      "name": "Soil_Mud_Dry"
    },
    {
      "x": -5,
      "y": 3,
      "z": 1,
      "name": "Soil_Dirt_Poisoned"
    },
    {
      "x": -5,
      "y": 4,
      "z": 1,
      "name": "Plant_Bramble_Dead_Lavathorn"
    },
    {
      "x": -5,
      "y": 5,
      "z": 1,
      "name": "Empty"
    },
    {
      "x": -5,
      "y": 6,
      "z": 1,
      "name": "Empty"
    },
    {
      "x": -5,
      "y": 7,
      "z": 1,
      "name": "Empty"
    },
    {
      "x": -5,
      "y": 8,
      "z": 1,
      "name": "Empty"
    },
    {
      "x": -5,
      "y": 9,
      "z": 1,
      "name": "Empty"
    },
    {
      "x": -5,
      "y": 10,
      "z": 1,
      "name": "Empty"
    },
    {
      "x": -5,
      "y": 11,
      "z": 1,
      "name": "Wood_Dry_Roots"
    },
    {
      "x": -5,
      "y": 12,
      "z": 1,
      "name": "Soil_Hive"
    },
    {
      "x": -5,
      "y": 13,
      "z": 1,
      "name": "Soil_Mud_Dry"
    },
    {
      "x": -5,
      "y": 14,
      "z": 1,
      "name": "Soil_Mud_Dry"
    },
    {
      "x": -5,
      "y": 15,
      "z": 1,
      "name": "Soil_Mud_Dry"
    },
    {
      "x": -5,
      "y": 2,
      "z": 2,
      "name": "Soil_Mud_Dry"
    },
    {
      "x": -5,
      "y": 3,
      "z": 2,
      "name": "Soil_Roots_Poisoned"
    },
    {
      "x": -5,
      "y": 4,
      "z": 2,
      "name": "Empty"
    },
    {
      "x": -5,
      "y": 5,
      "z": 2,
      "name": "Empty"
    },
    {
      "x": -5,
      "y": 6,
      "z": 2,
      "name": "Empty"
    },
    {
      "x": -5,
      "y": 7,
      "z": 2,
      "name": "Empty"
    },
    {
      "x": -5,
      "y": 8,
      "z": 2,
      "name": "Empty"
    },
    {
      "x": -5,
      "y": 9,
      "z": 2,
      "name": "Empty"
    },
    {
      "x": -5,
      "y": 10,
      "z": 2,
      "name": "Empty"
    },
    {
      "x": -5,
      "y": 11,
      "z": 2,
      "name": "Soil_Hive"
    },
    {
      "x": -5,
      "y": 13,
      "z": 2,
      "name": "Soil_Mud_Dry"
    },
    {
      "x": -5,
      "y": 14,
      "z": 2,
      "name": "Soil_Mud_Dry"
    },
    {
      "x": -5,
      "y": 15,
      "z": 2,
      "name": "Soil_Mud_Dry"
    },
    {
      "x": -5,
      "y": 2,
      "z": 3,
      "name": "Soil_Dirt_Poisoned"
    },
    {
      "x": -5,
      "y": 3,
      "z": 3,
      "name": "Soil_Dirt_Poisoned"
    },
    {
      "x": -5,
      "y": 4,
      "z": 3,
      "name": "Empty"
    },
    {
      "x": -5,
      "y": 5,
      "z": 3,
      "name": "Empty"
    },
    {
      "x": -5,
      "y": 6,
      "z": 3,
      "name": "Empty"
    },
    {
      "x": -5,
      "y": 7,
      "z": 3,
      "name": "Empty"
    },
    {
      "x": -5,
      "y": 8,
      "z": 3,
      "name": "Empty"
    },
    {
      "x": -5,
      "y": 9,
      "z": 3,
      "name": "Empty"
    },
    {
      "x": -5,
      "y": 10,
      "z": 3,
      "name": "Empty"
    },
    {
      "x": -5,
      "y": 11,
      "z": 3,
      "name": "Soil_Hive"
    },
    {
      "x": -5,
      "y": 12,
      "z": 3,
      "name": "Soil_Mud_Dry"
    },
    {
      "x": -5,
      "y": 13,
      "z": 3,
      "name": "Soil_Mud_Dry"
    },
    {
      "x": -5,
      "y": 14,
      "z": 3,
      "name": "Soil_Mud_Dry"
    },
    {
      "x": -5,
      "y": 15,
      "z": 3,
      "name": "Soil_Mud_Dry"
    },
    {
      "x": -5,
      "y": 2,
      "z": 4,
      "name": "Soil_Dirt_Poisoned"
    },
    {
      "x": -5,
      "y": 3,
      "z": 4,
      "name": "Soil_Dirt_Poisoned"
    },
    {
      "x": -5,
      "y": 4,
      "z": 4,
      "name": "Plant_Bramble_Dead_Twisted"
    },
    {
      "x": -5,
      "y": 5,
      "z": 4,
      "name": "Empty"
    },
    {
      "x": -5,
      "y": 6,
      "z": 4,
      "name": "Empty"
    },
    {
      "x": -5,
      "y": 7,
      "z": 4,
      "name": "Empty"
    },
    {
      "x": -5,
      "y": 8,
      "z": 4,
      "name": "Empty"
    },
    {
      "x": -5,
      "y": 9,
      "z": 4,
      "name": "Empty"
    },
    {
      "x": -5,
      "y": 10,
      "z": 4,
      "name": "*Deco_Scarak_Eggsacks_State_Definitions_Off",
      "rotation": 6
    },
    {
      "x": -5,
      "y": 12,
      "z": 4,
      "name": "Soil_Mud_Dry"
    },
    {
      "x": -5,
      "y": 13,
      "z": 4,
      "name": "Soil_Mud_Dry"
    },
    {
      "x": -5,
      "y": 14,
      "z": 4,
      "name": "Soil_Mud_Dry"
    },
    {
      "x": -5,
      "y": 15,
      "z": 4,
      "name": "Soil_Mud_Dry"
    },
    {
      "x": -5,
      "y": 2,
      "z": 5,
      "name": "Soil_Mud_Dry"
    },
    {
      "x": -5,
      "y": 3,
      "z": 5,
      "name": "Soil_Dirt_Poisoned"
    },
    {
      "x": -5,
      "y": 4,
      "z": 5,
      "name": "Empty"
    },
    {
      "x": -5,
      "y": 5,
      "z": 5,
      "name": "Empty"
    },
    {
      "x": -5,
      "y": 6,
      "z": 5,
      "name": "Empty"
    },
    {
      "x": -5,
      "y": 7,
      "z": 5,
      "name": "Empty"
    },
    {
      "x": -5,
      "y": 8,
      "z": 5,
      "name": "Empty"
    },
    {
      "x": -5,
      "y": 9,
      "z": 5,
      "name": "*Deco_Scarak_Eggsacks_State_Definitions_Off",
      "rotation": 8
    },
    {
      "x": -5,
      "y": 10,
      "z": 5,
      "name": "Soil_Hive"
    },
    {
      "x": -5,
      "y": 11,
      "z": 5,
      "name": "Soil_Hive"
    },
    {
      "x": -5,
      "y": 12,
      "z": 5,
      "name": "Soil_Mud_Dry"
    },
    {
      "x": -5,
      "y": 13,
      "z": 5,
      "name": "Soil_Mud_Dry"
    },
    {
      "x": -5,
      "y": 14,
      "z": 5,
      "name": "Soil_Mud_Dry"
    },
    {
      "x": -5,
      "y": 15,
      "z": 5,
      "name": "Soil_Mud_Dry"
    },
    {
      "x": -5,
      "y": 3,
      "z": 6,
      "name": "Soil_Mud_Dry"
    },
    {
      "x": -5,
      "y": 4,
      "z": 6,
      "name": "Soil_Dirt_Poisoned"
    },
    {
      "x": -5,
      "y": 5,
      "z": 6,
      "name": "Empty"
    },
    {
      "x": -5,
      "y": 6,
      "z": 6,
      "name": "Soil_Hive"
    },
    {
      "x": -5,
      "y": 7,
      "z": 6,
      "name": "Soil_Hive"
    },
    {
      "x": -5,
      "y": 8,
      "z": 6,
      "name": "Soil_Hive"
    },
    {
      "x": -5,
      "y": 9,
      "z": 6,
      "name": "Empty"
    },
    {
      "x": -5,
      "y": 10,
      "z": 6,
      "name": "Empty"
    },
    {
      "x": -5,
      "y": 11,
      "z": 6,
      "name": "Soil_Mud_Dry"
    },
    {
      "x": -5,
      "y": 12,
      "z": 6,
      "name": "Soil_Mud_Dry"
    },
    {
      "x": -5,
      "y": 13,
      "z": 6,
      "name": "Soil_Mud_Dry"
    },
    {
      "x": -5,
      "y": 14,
      "z": 6,
      "name": "Soil_Mud_Dry"
    },
    {
      "x": -5,
      "y": 15,
      "z": 6,
      "name": "Soil_Mud_Dry"
    },
    {
      "x": -5,
      "y": 4,
      "z": 7,
      "name": "Soil_Hive"
    },
    {
      "x": -5,
      "y": 5,
      "z": 7,
      "name": "Soil_Hive"
    },
    {
      "x": -5,
      "y": 6,
      "z": 7,
      "name": "Soil_Hive"
    },
    {
      "x": -5,
      "y": 7,
      "z": 7,
      "name": "Soil_Mud_Dry"
    },
    {
      "x": -5,
      "y": 8,
      "z": 7,
      "name": "Soil_Mud_Dry"
    },
    {
      "x": -5,
      "y": 9,
      "z": 7,
      "name": "Soil_Mud_Dry"
    },
    {
      "x": -5,
      "y": 10,
      "z": 7,
      "name": "Soil_Mud_Dry"
    },
    {
      "x": -5,
      "y": 11,
      "z": 7,
      "name": "Soil_Mud_Dry"
    },
    {
      "x": -5,
      "y": 12,
      "z": 7,
      "name": "Soil_Mud_Dry"
    },
    {
      "x": -5,
      "y": 13,
      "z": 7,
      "name": "Soil_Mud_Dry"
    },
    {
      "x": -5,
      "y": 14,
      "z": 7,
      "name": "Soil_Mud_Dry"
    },
    {
      "x": -5,
      "y": 3,
      "z": 8,
      "name": "Soil_Mud_Dry"
    },
    {
      "x": -5,
      "y": 4,
      "z": 8,
      "name": "Soil_Mud_Dry"
    },
    {
      "x": -5,
      "y": 5,
      "z": 8,
      "name": "Soil_Mud_Dry"
    },
    {
      "x": -5,
      "y": 6,
      "z": 8,
      "name": "Soil_Mud_Dry"
    },
    {
      "x": -5,
      "y": 7,
      "z": 8,
      "name": "Soil_Mud_Dry"
    },
    {
      "x": -5,
      "y": 8,
      "z": 8,
      "name": "Soil_Mud_Dry"
    },
    {
      "x": -5,
      "y": 9,
      "z": 8,
      "name": "Soil_Mud_Dry"
    },
    {
      "x": -5,
      "y": 10,
      "z": 8,
      "name": "Soil_Mud_Dry"
    },
    {
      "x": -5,
      "y": 11,
      "z": 8,
      "name": "Soil_Mud_Dry"
    },
    {
      "x": -5,
      "y": 12,
      "z": 8,
      "name": "Soil_Mud_Dry"
    },
    {
      "x": -5,
      "y": 13,
      "z": 8,
      "name": "Soil_Mud_Dry"
    },
    {
      "x": -5,
      "y": 14,
      "z": 8,
      "name": "Soil_Mud_Dry"
    },
    {
      "x": -4,
      "y": 3,
      "z": -7,
      "name": "Soil_Mud_Dry"
    },
    {
      "x": -4,
      "y": 4,
      "z": -7,
      "name": "Soil_Mud_Dry"
    },
    {
      "x": -4,
      "y": 5,
      "z": -7,
      "name": "Soil_Mud_Dry"
    },
    {
      "x": -4,
      "y": 6,
      "z": -7,
      "name": "Empty"
    },
    {
      "x": -4,
      "y": 7,
      "z": -7,
      "name": "Empty"
    },
    {
      "x": -4,
      "y": 8,
      "z": -7,
      "name": "Soil_Mud_Dry"
    },
    {
      "x": -4,
      "y": 9,
      "z": -7,
      "name": "Soil_Mud_Dry"
    },
    {
      "x": -4,
      "y": 10,
      "z": -7,
      "name": "Soil_Mud_Dry"
    },
    {
      "x": -4,
      "y": 11,
      "z": -7,
      "name": "Soil_Mud_Dry"
    },
    {
      "x": -4,
      "y": 12,
      "z": -7,
      "name": "Soil_Mud_Dry"
    },
    {
      "x": -4,
      "y": 13,
      "z": -7,
      "name": "Soil_Mud_Dry"
    },
    {
      "x": -4,
      "y": 14,
      "z": -7,
      "name": "Soil_Mud_Dry"
    },
    {
      "x": -4,
      "y": 2,
      "z": -6,
      "name": "Soil_Mud_Dry"
    },
    {
      "x": -4,
      "y": 3,
      "z": -6,
      "name": "Soil_Mud_Dry"
    },
    {
      "x": -4,
      "y": 4,
      "z": -6,
      "name": "Empty"
    },
    {
      "x": -4,
      "y": 5,
      "z": -6,
      "name": "Empty"
    },
    {
      "x": -4,
      "y": 6,
      "z": -6,
      "name": "Empty"
    },
    {
      "x": -4,
      "y": 7,
      "z": -6,
      "name": "Empty"
    },
    {
      "x": -4,
      "y": 8,
      "z": -6,
      "name": "Empty"
    },
    {
      "x": -4,
      "y": 9,
      "z": -6,
      "name": "Empty"
    },
    {
      "x": -4,
      "y": 10,
      "z": -6,
      "name": "Empty"
    },
    {
      "x": -4,
      "y": 11,
      "z": -6,
      "name": "Empty"
    },
    {
      "x": -4,
      "y": 12,
      "z": -6,
      "name": "Soil_Mud_Dry"
    },
    {
      "x": -4,
      "y": 13,
      "z": -6,
      "name": "Soil_Mud_Dry"
    },
    {
      "x": -4,
      "y": 14,
      "z": -6,
      "name": "Soil_Mud_Dry"
    },
    {
      "x": -4,
      "y": 15,
      "z": -6,
      "name": "Soil_Mud_Dry"
    },
    {
      "x": -4,
      "y": 2,
      "z": -5,
      "name": "Soil_Mud_Dry"
    },
    {
      "x": -4,
      "y": 3,
      "z": -5,
      "name": "Soil_Dirt_Poisoned"
    },
    {
      "x": -4,
      "y": 4,
      "z": -5,
      "name": "Empty"
    },
    {
      "x": -4,
      "y": 5,
      "z": -5,
      "name": "Empty"
    },
    {
      "x": -4,
      "y": 6,
      "z": -5,
      "name": "Empty"
    },
    {
      "x": -4,
      "y": 7,
      "z": -5,
      "name": "Empty"
    },
    {
      "x": -4,
      "y": 8,
      "z": -5,
      "name": "Empty"
    },
    {
      "x": -4,
      "y": 9,
      "z": -5,
      "name": "Soil_Hive"
    },
    {
      "x": -4,
      "y": 10,
      "z": -5,
      "name": "Empty"
    },
    {
      "x": -4,
      "y": 11,
      "z": -5,
      "name": "Empty"
    },
    {
      "x": -4,
      "y": 12,
      "z": -5,
      "name": "Empty"
    },
    {
      "x": -4,
      "y": 13,
      "z": -5,
      "name": "Soil_Mud_Dry"
    },
    {
      "x": -4,
      "y": 14,
      "z": -5,
      "name": "Soil_Mud_Dry"
    },
    {
      "x": -4,
      "y": 15,
      "z": -5,
      "name": "Soil_Mud_Dry"
    },
    {
      "x": -4,
      "y": 2,
      "z": -4,
      "name": "Soil_Mud_Dry"
    },
    {
      "x": -4,
      "y": 3,
      "z": -4,
      "name": "Soil_Mud_Dry"
    },
    {
      "x": -4,
      "y": 4,
      "z": -4,
      "name": "Empty"
    },
    {
      "x": -4,
      "y": 5,
      "z": -4,
      "name": "Empty"
    },
    {
      "x": -4,
      "y": 6,
      "z": -4,
      "name": "Empty"
    },
    {
      "x": -4,
      "y": 7,
      "z": -4,
      "name": "Empty"
    },
    {
      "x": -4,
      "y": 8,
      "z": -4,
      "name": "Empty"
    },
    {
      "x": -4,
      "y": 9,
      "z": -4,
      "name": "Empty"
    },
    {
      "x": -4,
      "y": 10,
      "z": -4,
      "name": "Empty"
    },
    {
      "x": -4,
      "y": 11,
      "z": -4,
      "name": "Empty"
    },
    {
      "x": -4,
      "y": 12,
      "z": -4,
      "name": "Empty"
    },
    {
      "x": -4,
      "y": 13,
      "z": -4,
      "name": "Soil_Mud_Dry"
    },
    {
      "x": -4,
      "y": 14,
      "z": -4,
      "name": "Soil_Mud_Dry"
    },
    {
      "x": -4,
      "y": 15,
      "z": -4,
      "name": "Soil_Mud_Dry"
    },
    {
      "x": -4,
      "y": 2,
      "z": -3,
      "name": "Soil_Mud_Dry"
    },
    {
      "x": -4,
      "y": 3,
      "z": -3,
      "name": "Soil_Hive"
    },
    {
      "x": -4,
      "y": 4,
      "z": -3,
      "name": "Empty"
    },
    {
      "x": -4,
      "y": 5,
      "z": -3,
      "name": "Empty"
    },
    {
      "x": -4,
      "y": 6,
      "z": -3,
      "name": "Empty"
    },
    {
      "x": -4,
      "y": 7,
      "z": -3,
      "name": "Empty"
    },
    {
      "x": -4,
      "y": 8,
      "z": -3,
      "name": "Empty"
    },
    {
      "x": -4,
      "y": 9,
      "z": -3,
      "name": "Empty"
    },
    {
      "x": -4,
      "y": 10,
      "z": -3,
      "name": "Empty"
    },
    {
      "x": -4,
      "y": 11,
      "z": -3,
      "name": "Empty"
    },
    {
      "x": -4,
      "y": 12,
      "z": -3,
      "name": "Empty"
    },
    {
      "x": -4,
      "y": 13,
      "z": -3,
      "name": "Empty"
    },
    {
      "x": -4,
      "y": 14,
      "z": -3,
      "name": "Soil_Mud_Dry"
    },
    {
      "x": -4,
      "y": 15,
      "z": -3,
      "name": "Soil_Mud_Dry"
    },
    {
      "x": -4,
      "y": 2,
      "z": -2,
      "name": "Soil_Mud_Dry"
    },
    {
      "x": -4,
      "y": 3,
      "z": -2,
      "name": "Soil_Hive"
    },
    {
      "x": -4,
      "y": 4,
      "z": -2,
      "name": "Empty"
    },
    {
      "x": -4,
      "y": 5,
      "z": -2,
      "name": "Empty"
    },
    {
      "x": -4,
      "y": 6,
      "z": -2,
      "name": "Empty"
    },
    {
      "x": -4,
      "y": 7,
      "z": -2,
      "name": "Empty"
    },
    {
      "x": -4,
      "y": 8,
      "z": -2,
      "name": "Empty"
    },
    {
      "x": -4,
      "y": 9,
      "z": -2,
      "name": "Empty"
    },
    {
      "x": -4,
      "y": 10,
      "z": -2,
      "name": "Empty"
    },
    {
      "x": -4,
      "y": 11,
      "z": -2,
      "name": "Empty"
    },
    {
      "x": -4,
      "y": 12,
      "z": -2,
      "name": "Empty"
    },
    {
      "x": -4,
      "y": 13,
      "z": -2,
      "name": "Empty"
    },
    {
      "x": -4,
      "y": 14,
      "z": -2,
      "name": "Soil_Mud_Dry"
    },
    {
      "x": -4,
      "y": 15,
      "z": -2,
      "name": "Soil_Mud_Dry"
    },
    {
      "x": -4,
      "y": 2,
      "z": -1,
      "name": "Soil_Mud_Dry"
    },
    {
      "x": -4,
      "y": 3,
      "z": -1,
      "name": "Soil_Dirt_Poisoned"
    },
    {
      "x": -4,
      "y": 4,
      "z": -1,
      "name": "Empty"
    },
    {
      "x": -4,
      "y": 5,
      "z": -1,
      "name": "Empty"
    },
    {
      "x": -4,
      "y": 6,
      "z": -1,
      "name": "Empty"
    },
    {
      "x": -4,
      "y": 7,
      "z": -1,
      "name": "Empty"
    },
    {
      "x": -4,
      "y": 8,
      "z": -1,
      "name": "Empty"
    },
    {
      "x": -4,
      "y": 9,
      "z": -1,
      "name": "Empty"
    },
    {
      "x": -4,
      "y": 10,
      "z": -1,
      "name": "Empty"
    },
    {
      "x": -4,
      "y": 11,
      "z": -1,
      "name": "Empty"
    },
    {
      "x": -4,
      "y": 12,
      "z": -1,
      "name": "Empty"
    },
    {
      "x": -4,
      "y": 13,
      "z": -1,
      "name": "Empty"
    },
    {
      "x": -4,
      "y": 14,
      "z": -1,
      "name": "Soil_Mud_Dry"
    },
    {
      "x": -4,
      "y": 15,
      "z": -1,
      "name": "Soil_Mud_Dry"
    },
    {
      "x": -4,
      "y": 2,
      "z": 0,
      "name": "Soil_Dirt_Poisoned"
    },
    {
      "x": -4,
      "y": 3,
      "z": 0,
      "name": "Soil_Dirt_Poisoned"
    },
    {
      "x": -4,
      "y": 4,
      "z": 0,
      "name": "Plant_Bramble_Dead_Twisted"
    },
    {
      "x": -4,
      "y": 5,
      "z": 0,
      "name": "Empty"
    },
    {
      "x": -4,
      "y": 6,
      "z": 0,
      "name": "Empty"
    },
    {
      "x": -4,
      "y": 7,
      "z": 0,
      "name": "Empty"
    },
    {
      "x": -4,
      "y": 8,
      "z": 0,
      "name": "Empty"
    },
    {
      "x": -4,
      "y": 9,
      "z": 0,
      "name": "Empty"
    },
    {
      "x": -4,
      "y": 10,
      "z": 0,
      "name": "Empty"
    },
    {
      "x": -4,
      "y": 11,
      "z": 0,
      "name": "Empty"
    },
    {
      "x": -4,
      "y": 12,
      "z": 0,
      "name": "Empty"
    },
    {
      "x": -4,
      "y": 13,
      "z": 0,
      "name": "Soil_Hive"
    },
    {
      "x": -4,
      "y": 14,
      "z": 0,
      "name": "Soil_Mud_Dry"
    },
    {
      "x": -4,
      "y": 15,
      "z": 0,
      "name": "Soil_Mud_Dry"
    },
    {
      "x": -4,
      "y": 2,
      "z": 1,
      "name": "Soil_Dirt_Poisoned"
    },
    {
      "x": -4,
      "y": 3,
      "z": 1,
      "name": "Soil_Roots_Poisoned"
    },
    {
      "x": -4,
      "y": 4,
      "z": 1,
      "name": "Empty"
    },
    {
      "x": -4,
      "y": 5,
      "z": 1,
      "name": "Empty"
    },
    {
      "x": -4,
      "y": 6,
      "z": 1,
      "name": "Empty"
    },
    {
      "x": -4,
      "y": 7,
      "z": 1,
      "name": "Empty"
    },
    {
      "x": -4,
      "y": 8,
      "z": 1,
      "name": "Empty"
    },
    {
      "x": -4,
      "y": 9,
      "z": 1,
      "name": "Empty"
    },
    {
      "x": -4,
      "y": 10,
      "z": 1,
      "name": "Empty"
    },
    {
      "x": -4,
      "y": 11,
      "z": 1,
      "name": "Deco_Scarak_Eggsacks",
      "rotation": 8
    },
    {
      "x": -4,
      "y": 12,
      "z": 1,
      "name": "Soil_Hive"
    },
    {
      "x": -4,
      "y": 13,
      "z": 1,
      "name": "Soil_Mud_Dry"
    },
    {
      "x": -4,
      "y": 14,
      "z": 1,
      "name": "Soil_Mud_Dry"
    },
    {
      "x": -4,
      "y": 15,
      "z": 1,
      "name": "Soil_Mud_Dry"
    },
    {
      "x": -4,
      "y": 2,
      "z": 2,
      "name": "Soil_Dirt_Poisoned"
    },
    {
      "x": -4,
      "y": 3,
      "z": 2,
      "name": "Soil_Roots_Poisoned"
    },
    {
      "x": -4,
      "y": 4,
      "z": 2,
      "name": "Empty"
    },
    {
      "x": -4,
      "y": 5,
      "z": 2,
      "name": "Empty"
    },
    {
      "x": -4,
      "y": 6,
      "z": 2,
      "name": "Empty"
    },
    {
      "x": -4,
      "y": 7,
      "z": 2,
      "name": "Empty"
    },
    {
      "x": -4,
      "y": 8,
      "z": 2,
      "name": "Empty"
    },
    {
      "x": -4,
      "y": 9,
      "z": 2,
      "name": "Empty"
    },
    {
      "x": -4,
      "y": 10,
      "z": 2,
      "name": "Empty"
    },
    {
      "x": -4,
      "y": 11,
      "z": 2,
      "name": "Empty"
    },
    {
      "x": -4,
      "y": 12,
      "z": 2,
      "name": "Soil_Hive"
    },
    {
      "x": -4,
      "y": 13,
      "z": 2,
      "name": "Soil_Mud_Dry"
    },
    {
      "x": -4,
      "y": 14,
      "z": 2,
      "name": "Soil_Mud_Dry"
    },
    {
      "x": -4,
      "y": 15,
      "z": 2,
      "name": "Soil_Mud_Dry"
    },
    {
      "x": -4,
      "y": 2,
      "z": 3,
      "name": "Soil_Dirt_Poisoned"
    },
    {
      "x": -4,
      "y": 3,
      "z": 3,
      "name": "Soil_Dirt_Poisoned"
    },
    {
      "x": -4,
      "y": 4,
      "z": 3,
      "name": "Empty"
    },
    {
      "x": -4,
      "y": 5,
      "z": 3,
      "name": "Empty"
    },
    {
      "x": -4,
      "y": 6,
      "z": 3,
      "name": "Empty"
    },
    {
      "x": -4,
      "y": 7,
      "z": 3,
      "name": "Empty"
    },
    {
      "x": -4,
      "y": 8,
      "z": 3,
      "name": "Empty"
    },
    {
      "x": -4,
      "y": 9,
      "z": 3,
      "name": "Empty"
    },
    {
      "x": -4,
      "y": 10,
      "z": 3,
      "name": "Empty"
    },
    {
      "x": -4,
      "y": 11,
      "z": 3,
      "name": "Empty"
    },
    {
      "x": -4,
      "y": 12,
      "z": 3,
      "name": "Empty"
    },
    {
      "x": -4,
      "y": 13,
      "z": 3,
      "name": "Soil_Mud_Dry"
    },
    {
      "x": -4,
      "y": 14,
      "z": 3,
      "name": "Soil_Mud_Dry"
    },
    {
      "x": -4,
      "y": 15,
      "z": 3,
      "name": "Soil_Mud_Dry"
    },
    {
      "x": -4,
      "y": 2,
      "z": 4,
      "name": "Soil_Mud_Dry"
    },
    {
      "x": -4,
      "y": 3,
      "z": 4,
      "name": "Soil_Roots_Poisoned"
    },
    {
      "x": -4,
      "y": 4,
      "z": 4,
      "name": "Empty"
    },
    {
      "x": -4,
      "y": 5,
      "z": 4,
      "name": "Empty"
    },
    {
      "x": -4,
      "y": 6,
      "z": 4,
      "name": "Empty"
    },
    {
      "x": -4,
      "y": 7,
      "z": 4,
      "name": "Empty"
    },
    {
      "x": -4,
      "y": 8,
      "z": 4,
      "name": "Empty"
    },
    {
      "x": -4,
      "y": 9,
      "z": 4,
      "name": "Empty"
    },
    {
      "x": -4,
      "y": 10,
      "z": 4,
      "name": "Empty"
    },
    {
      "x": -4,
      "y": 11,
      "z": 4,
      "name": "*Deco_Scarak_Eggsacks_State_Definitions_Off",
      "rotation": 6
    },
    {
      "x": -4,
      "y": 12,
      "z": 4,
      "name": "Empty"
    },
    {
      "x": -4,
      "y": 13,
      "z": 4,
      "name": "Soil_Mud_Dry"
    },
    {
      "x": -4,
      "y": 14,
      "z": 4,
      "name": "Soil_Mud_Dry"
    },
    {
      "x": -4,
      "y": 15,
      "z": 4,
      "name": "Soil_Mud_Dry"
    },
    {
      "x": -4,
      "y": 2,
      "z": 5,
      "name": "Soil_Mud_Dry"
    },
    {
      "x": -4,
      "y": 3,
      "z": 5,
      "name": "Soil_Mud_Dry"
    },
    {
      "x": -4,
      "y": 4,
      "z": 5,
      "name": "Empty"
    },
    {
      "x": -4,
      "y": 5,
      "z": 5,
      "name": "Empty"
    },
    {
      "x": -4,
      "y": 6,
      "z": 5,
      "name": "Empty"
    },
    {
      "x": -4,
      "y": 7,
      "z": 5,
      "name": "Empty"
    },
    {
      "x": -4,
      "y": 8,
      "z": 5,
      "name": "Empty"
    },
    {
      "x": -4,
      "y": 9,
      "z": 5,
      "name": "Empty"
    },
    {
      "x": -4,
      "y": 10,
      "z": 5,
      "name": "Empty"
    },
    {
      "x": -4,
      "y": 11,
      "z": 5,
      "name": "Soil_Hive"
    },
    {
      "x": -4,
      "y": 12,
      "z": 5,
      "name": "Soil_Mud_Dry"
    },
    {
      "x": -4,
      "y": 13,
      "z": 5,
      "name": "Soil_Mud_Dry"
    },
    {
      "x": -4,
      "y": 14,
      "z": 5,
      "name": "Soil_Mud_Dry"
    },
    {
      "x": -4,
      "y": 15,
      "z": 5,
      "name": "Soil_Mud_Dry"
    },
    {
      "x": -4,
      "y": 2,
      "z": 6,
      "name": "Soil_Mud_Dry"
    },
    {
      "x": -4,
      "y": 3,
      "z": 6,
      "name": "Soil_Roots_Poisoned"
    },
    {
      "x": -4,
      "y": 4,
      "z": 6,
      "name": "Empty"
    },
    {
      "x": -4,
      "y": 5,
      "z": 6,
      "name": "Empty"
    },
    {
      "x": -4,
      "y": 6,
      "z": 6,
      "name": "Empty"
    },
    {
      "x": -4,
      "y": 7,
      "z": 6,
      "name": "Empty"
    },
    {
      "x": -4,
      "y": 8,
      "z": 6,
      "name": "Empty"
    },
    {
      "x": -4,
      "y": 9,
      "z": 6,
      "name": "Empty"
    },
    {
      "x": -4,
      "y": 10,
      "z": 6,
      "name": "Empty"
    },
    {
      "x": -4,
      "y": 11,
      "z": 6,
      "name": "Empty"
    },
    {
      "x": -4,
      "y": 12,
      "z": 6,
      "name": "Soil_Mud_Dry"
    },
    {
      "x": -4,
      "y": 13,
      "z": 6,
      "name": "Soil_Mud_Dry"
    },
    {
      "x": -4,
      "y": 14,
      "z": 6,
      "name": "Soil_Mud_Dry"
    },
    {
      "x": -4,
      "y": 15,
      "z": 6,
      "name": "Soil_Mud_Dry"
    },
    {
      "x": -4,
      "y": 2,
      "z": 7,
      "name": "Soil_Mud_Dry"
    },
    {
      "x": -4,
      "y": 3,
      "z": 7,
      "name": "Soil_Mud_Dry"
    },
    {
      "x": -4,
      "y": 4,
      "z": 7,
      "name": "Empty"
    },
    {
      "x": -4,
      "y": 5,
      "z": 7,
      "name": "Empty"
    },
    {
      "x": -4,
      "y": 6,
      "z": 7,
      "name": "Empty"
    },
    {
      "x": -4,
      "y": 7,
      "z": 7,
      "name": "Empty"
    },
    {
      "x": -4,
      "y": 8,
      "z": 7,
      "name": "Empty"
    },
    {
      "x": -4,
      "y": 9,
      "z": 7,
      "name": "Empty"
    },
    {
      "x": -4,
      "y": 10,
      "z": 7,
      "name": "Soil_Mud_Dry"
    },
    {
      "x": -4,
      "y": 11,
      "z": 7,
      "name": "Soil_Mud_Dry"
    },
    {
      "x": -4,
      "y": 12,
      "z": 7,
      "name": "Soil_Mud_Dry"
    },
    {
      "x": -4,
      "y": 13,
      "z": 7,
      "name": "Soil_Mud_Dry"
    },
    {
      "x": -4,
      "y": 14,
      "z": 7,
      "name": "Soil_Mud_Dry"
    },
    {
      "x": -4,
      "y": 15,
      "z": 7,
      "name": "Soil_Mud_Dry"
    },
    {
      "x": -4,
      "y": 3,
      "z": 8,
      "name": "Soil_Mud_Dry"
    },
    {
      "x": -4,
      "y": 4,
      "z": 8,
      "name": "Soil_Mud_Dry"
    },
    {
      "x": -4,
      "y": 5,
      "z": 8,
      "name": "Empty"
    },
    {
      "x": -4,
      "y": 6,
      "z": 8,
      "name": "Empty"
    },
    {
      "x": -4,
      "y": 7,
      "z": 8,
      "name": "Empty"
    },
    {
      "x": -4,
      "y": 8,
      "z": 8,
      "name": "Soil_Mud_Dry"
    },
    {
      "x": -4,
      "y": 9,
      "z": 8,
      "name": "Soil_Mud_Dry"
    },
    {
      "x": -4,
      "y": 10,
      "z": 8,
      "name": "Soil_Mud_Dry"
    },
    {
      "x": -4,
      "y": 11,
      "z": 8,
      "name": "Soil_Mud_Dry"
    },
    {
      "x": -4,
      "y": 12,
      "z": 8,
      "name": "Soil_Mud_Dry"
    },
    {
      "x": -4,
      "y": 13,
      "z": 8,
      "name": "Soil_Mud_Dry"
    },
    {
      "x": -4,
      "y": 14,
      "z": 8,
      "name": "Soil_Mud_Dry"
    },
    {
      "x": -3,
      "y": 3,
      "z": -7,
      "name": "Soil_Mud_Dry"
    },
    {
      "x": -3,
      "y": 4,
      "z": -7,
      "name": "Empty"
    },
    {
      "x": -3,
      "y": 5,
      "z": -7,
      "name": "Empty"
    },
    {
      "x": -3,
      "y": 6,
      "z": -7,
      "name": "Empty"
    },
    {
      "x": -3,
      "y": 7,
      "z": -7,
      "name": "Empty"
    },
    {
      "x": -3,
      "y": 8,
      "z": -7,
      "name": "Empty"
    },
    {
      "x": -3,
      "y": 9,
      "z": -7,
      "name": "Soil_Mud_Dry"
    },
    {
      "x": -3,
      "y": 10,
      "z": -7,
      "name": "Soil_Mud_Dry"
    },
    {
      "x": -3,
      "y": 11,
      "z": -7,
      "name": "Soil_Mud_Dry"
    },
    {
      "x": -3,
      "y": 12,
      "z": -7,
      "name": "Soil_Mud_Dry"
    },
    {
      "x": -3,
      "y": 13,
      "z": -7,
      "name": "Soil_Mud_Dry"
    },
    {
      "x": -3,
      "y": 14,
      "z": -7,
      "name": "Soil_Mud_Dry"
    },
    {
      "x": -3,
      "y": 2,
      "z": -6,
      "name": "Soil_Mud_Dry"
    },
    {
      "x": -3,
      "y": 3,
      "z": -6,
      "name": "Soil_Mud_Dry"
    },
    {
      "x": -3,
      "y": 4,
      "z": -6,
      "name": "Empty"
    },
    {
      "x": -3,
      "y": 5,
      "z": -6,
      "name": "Empty"
    },
    {
      "x": -3,
      "y": 6,
      "z": -6,
      "name": "Empty"
    },
    {
      "x": -3,
      "y": 7,
      "z": -6,
      "name": "Empty"
    },
    {
      "x": -3,
      "y": 8,
      "z": -6,
      "name": "Empty"
    },
    {
      "x": -3,
      "y": 9,
      "z": -6,
      "name": "Empty"
    },
    {
      "x": -3,
      "y": 10,
      "z": -6,
      "name": "Empty"
    },
    {
      "x": -3,
      "y": 11,
      "z": -6,
      "name": "Empty"
    },
    {
      "x": -3,
      "y": 12,
      "z": -6,
      "name": "Soil_Mud_Dry"
    },
    {
      "x": -3,
      "y": 13,
      "z": -6,
      "name": "Soil_Mud_Dry"
    },
    {
      "x": -3,
      "y": 14,
      "z": -6,
      "name": "Soil_Mud_Dry"
    },
    {
      "x": -3,
      "y": 15,
      "z": -6,
      "name": "Soil_Mud_Dry"
    },
    {
      "x": -3,
      "y": 2,
      "z": -5,
      "name": "Soil_Mud_Dry"
    },
    {
      "x": -3,
      "y": 3,
      "z": -5,
      "name": "Soil_Mud_Dry"
    },
    {
      "x": -3,
      "y": 4,
      "z": -5,
      "name": "Empty"
    },
    {
      "x": -3,
      "y": 5,
      "z": -5,
      "name": "Empty"
    },
    {
      "x": -3,
      "y": 6,
      "z": -5,
      "name": "Empty"
    },
    {
      "x": -3,
      "y": 7,
      "z": -5,
      "name": "Empty"
    },
    {
      "x": -3,
      "y": 8,
      "z": -5,
      "name": "Empty"
    },
    {
      "x": -3,
      "y": 9,
      "z": -5,
      "name": "Soil_Hive"
    },
    {
      "x": -3,
      "y": 10,
      "z": -5,
      "name": "Empty"
    },
    {
      "x": -3,
      "y": 11,
      "z": -5,
      "name": "Empty"
    },
    {
      "x": -3,
      "y": 12,
      "z": -5,
      "name": "Empty"
    },
    {
      "x": -3,
      "y": 13,
      "z": -5,
      "name": "Soil_Mud_Dry"
    },
    {
      "x": -3,
      "y": 14,
      "z": -5,
      "name": "Soil_Mud_Dry"
    },
    {
      "x": -3,
      "y": 15,
      "z": -5,
      "name": "Soil_Mud_Dry"
    },
    {
      "x": -3,
      "y": 2,
      "z": -4,
      "name": "Soil_Mud_Dry"
    },
    {
      "x": -3,
      "y": 3,
      "z": -4,
      "name": "Soil_Mud_Dry"
    },
    {
      "x": -3,
      "y": 4,
      "z": -4,
      "name": "Empty"
    },
    {
      "x": -3,
      "y": 5,
      "z": -4,
      "name": "Empty"
    },
    {
      "x": -3,
      "y": 6,
      "z": -4,
      "name": "Empty"
    },
    {
      "x": -3,
      "y": 7,
      "z": -4,
      "name": "Empty"
    },
    {
      "x": -3,
      "y": 8,
      "z": -4,
      "name": "Empty"
    },
    {
      "x": -3,
      "y": 9,
      "z": -4,
      "name": "Empty"
    },
    {
      "x": -3,
      "y": 10,
      "z": -4,
      "name": "Empty"
    },
    {
      "x": -3,
      "y": 11,
      "z": -4,
      "name": "Empty"
    },
    {
      "x": -3,
      "y": 12,
      "z": -4,
      "name": "Empty"
    },
    {
      "x": -3,
      "y": 13,
      "z": -4,
      "name": "Soil_Mud_Dry"
    },
    {
      "x": -3,
      "y": 14,
      "z": -4,
      "name": "Soil_Mud_Dry"
    },
    {
      "x": -3,
      "y": 15,
      "z": -4,
      "name": "Soil_Mud_Dry"
    },
    {
      "x": -3,
      "y": 2,
      "z": -3,
      "name": "Soil_Mud_Dry"
    },
    {
      "x": -3,
      "y": 3,
      "z": -3,
      "name": "Soil_Hive"
    },
    {
      "x": -3,
      "y": 4,
      "z": -3,
      "name": "Empty"
    },
    {
      "x": -3,
      "y": 5,
      "z": -3,
      "name": "Empty"
    },
    {
      "x": -3,
      "y": 6,
      "z": -3,
      "name": "Empty"
    },
    {
      "x": -3,
      "y": 7,
      "z": -3,
      "name": "Empty"
    },
    {
      "x": -3,
      "y": 8,
      "z": -3,
      "name": "Empty"
    },
    {
      "x": -3,
      "y": 9,
      "z": -3,
      "name": "Empty"
    },
    {
      "x": -3,
      "y": 10,
      "z": -3,
      "name": "Empty"
    },
    {
      "x": -3,
      "y": 11,
      "z": -3,
      "name": "Empty"
    },
    {
      "x": -3,
      "y": 12,
      "z": -3,
      "name": "Empty"
    },
    {
      "x": -3,
      "y": 13,
      "z": -3,
      "name": "Empty"
    },
    {
      "x": -3,
      "y": 14,
      "z": -3,
      "name": "Soil_Mud_Dry"
    },
    {
      "x": -3,
      "y": 15,
      "z": -3,
      "name": "Soil_Mud_Dry"
    },
    {
      "x": -3,
      "y": 2,
      "z": -2,
      "name": "Soil_Mud_Dry"
    },
    {
      "x": -3,
      "y": 3,
      "z": -2,
      "name": "Soil_Hive"
    },
    {
      "x": -3,
      "y": 4,
      "z": -2,
      "name": "Empty"
    },
    {
      "x": -3,
      "y": 5,
      "z": -2,
      "name": "Empty"
    },
    {
      "x": -3,
      "y": 6,
      "z": -2,
      "name": "Empty"
    },
    {
      "x": -3,
      "y": 7,
      "z": -2,
      "name": "Empty"
    },
    {
      "x": -3,
      "y": 8,
      "z": -2,
      "name": "Empty"
    },
    {
      "x": -3,
      "y": 9,
      "z": -2,
      "name": "Empty"
    },
    {
      "x": -3,
      "y": 10,
      "z": -2,
      "name": "Empty"
    },
    {
      "x": -3,
      "y": 11,
      "z": -2,
      "name": "Empty"
    },
    {
      "x": -3,
      "y": 12,
      "z": -2,
      "name": "Empty"
    },
    {
      "x": -3,
      "y": 13,
      "z": -2,
      "name": "Empty"
    },
    {
      "x": -3,
      "y": 14,
      "z": -2,
      "name": "Soil_Mud_Dry"
    },
    {
      "x": -3,
      "y": 15,
      "z": -2,
      "name": "Soil_Mud_Dry"
    },
    {
      "x": -3,
      "y": 2,
      "z": -1,
      "name": "Soil_Mud_Dry"
    },
    {
      "x": -3,
      "y": 3,
      "z": -1,
      "name": "Soil_Mud_Dry"
    },
    {
      "x": -3,
      "y": 4,
      "z": -1,
      "name": "Empty"
    },
    {
      "x": -3,
      "y": 5,
      "z": -1,
      "name": "Empty"
    },
    {
      "x": -3,
      "y": 6,
      "z": -1,
      "name": "Empty"
    },
    {
      "x": -3,
      "y": 7,
      "z": -1,
      "name": "Empty"
    },
    {
      "x": -3,
      "y": 8,
      "z": -1,
      "name": "Empty"
    },
    {
      "x": -3,
      "y": 9,
      "z": -1,
      "name": "Empty"
    },
    {
      "x": -3,
      "y": 10,
      "z": -1,
      "name": "Empty"
    },
    {
      "x": -3,
      "y": 11,
      "z": -1,
      "name": "Empty"
    },
    {
      "x": -3,
      "y": 12,
      "z": -1,
      "name": "Empty"
    },
    {
      "x": -3,
      "y": 13,
      "z": -1,
      "name": "Empty"
    },
    {
      "x": -3,
      "y": 14,
      "z": -1,
      "name": "Soil_Mud_Dry"
    },
    {
      "x": -3,
      "y": 15,
      "z": -1,
      "name": "Soil_Mud_Dry"
    },
    {
      "x": -3,
      "y": 2,
      "z": 0,
      "name": "Soil_Mud_Dry"
    },
    {
      "x": -3,
      "y": 3,
      "z": 0,
      "name": "Soil_Dirt_Poisoned"
    },
    {
      "x": -3,
      "y": 4,
      "z": 0,
      "name": "Empty"
    },
    {
      "x": -3,
      "y": 5,
      "z": 0,
      "name": "Empty"
    },
    {
      "x": -3,
      "y": 6,
      "z": 0,
      "name": "Empty"
    },
    {
      "x": -3,
      "y": 7,
      "z": 0,
      "name": "Empty"
    },
    {
      "x": -3,
      "y": 8,
      "z": 0,
      "name": "Empty"
    },
    {
      "x": -3,
      "y": 9,
      "z": 0,
      "name": "Empty"
    },
    {
      "x": -3,
      "y": 10,
      "z": 0,
      "name": "Empty"
    },
    {
      "x": -3,
      "y": 11,
      "z": 0,
      "name": "Empty"
    },
    {
      "x": -3,
      "y": 12,
      "z": 0,
      "name": "Empty"
    },
    {
      "x": -3,
      "y": 13,
      "z": 0,
      "name": "Soil_Hive"
    },
    {
      "x": -3,
      "y": 14,
      "z": 0,
      "name": "Soil_Mud_Dry"
    },
    {
      "x": -3,
      "y": 15,
      "z": 0,
      "name": "Soil_Mud_Dry"
    },
    {
      "x": -3,
      "y": 2,
      "z": 1,
      "name": "Soil_Mud_Dry"
    },
    {
      "x": -3,
      "y": 3,
      "z": 1,
      "name": "Soil_Roots_Poisoned"
    },
    {
      "x": -3,
      "y": 4,
      "z": 1,
      "name": "Empty"
    },
    {
      "x": -3,
      "y": 5,
      "z": 1,
      "name": "Empty"
    },
    {
      "x": -3,
      "y": 6,
      "z": 1,
      "name": "Empty"
    },
    {
      "x": -3,
      "y": 7,
      "z": 1,
      "name": "Empty"
    },
    {
      "x": -3,
      "y": 8,
      "z": 1,
      "name": "Empty"
    },
    {
      "x": -3,
      "y": 9,
      "z": 1,
      "name": "Empty"
    },
    {
      "x": -3,
      "y": 10,
      "z": 1,
      "name": "Empty"
    },
    {
      "x": -3,
      "y": 11,
      "z": 1,
      "name": "*Deco_Scarak_Eggsacks_State_Definitions_Off",
      "rotation": 8
    },
    {
      "x": -3,
      "y": 12,
      "z": 1,
      "name": "Soil_Hive"
    },
    {
      "x": -3,
      "y": 13,
      "z": 1,
      "name": "Soil_Mud_Dry"
    },
    {
      "x": -3,
      "y": 14,
      "z": 1,
      "name": "Soil_Mud_Dry"
    },
    {
      "x": -3,
      "y": 15,
      "z": 1,
      "name": "Soil_Mud_Dry"
    },
    {
      "x": -3,
      "y": 2,
      "z": 2,
      "name": "Soil_Dirt_Poisoned"
    },
    {
      "x": -3,
      "y": 3,
      "z": 2,
      "name": "Soil_Dirt_Poisoned"
    },
    {
      "x": -3,
      "y": 4,
      "z": 2,
      "name": "Empty"
    },
    {
      "x": -3,
      "y": 5,
      "z": 2,
      "name": "Empty"
    },
    {
      "x": -3,
      "y": 6,
      "z": 2,
      "name": "Empty"
    },
    {
      "x": -3,
      "y": 7,
      "z": 2,
      "name": "Empty"
    },
    {
      "x": -3,
      "y": 8,
      "z": 2,
      "name": "Empty"
    },
    {
      "x": -3,
      "y": 9,
      "z": 2,
      "name": "Empty"
    },
    {
      "x": -3,
      "y": 10,
      "z": 2,
      "name": "Empty"
    },
    {
      "x": -3,
      "y": 11,
      "z": 2,
      "name": "Empty"
    },
    {
      "x": -3,
      "y": 12,
      "z": 2,
      "name": "Soil_Hive"
    },
    {
      "x": -3,
      "y": 13,
      "z": 2,
      "name": "Soil_Mud_Dry"
    },
    {
      "x": -3,
      "y": 14,
      "z": 2,
      "name": "Soil_Mud_Dry"
    },
    {
      "x": -3,
      "y": 15,
      "z": 2,
      "name": "Soil_Mud_Dry"
    },
    {
      "x": -3,
      "y": 2,
      "z": 3,
      "name": "Soil_Dirt_Poisoned"
    },
    {
      "x": -3,
      "y": 3,
      "z": 3,
      "name": "Soil_Dirt_Poisoned"
    },
    {
      "x": -3,
      "y": 4,
      "z": 3,
      "name": "Empty"
    },
    {
      "x": -3,
      "y": 5,
      "z": 3,
      "name": "Empty"
    },
    {
      "x": -3,
      "y": 6,
      "z": 3,
      "name": "Empty"
    },
    {
      "x": -3,
      "y": 7,
      "z": 3,
      "name": "Empty"
    },
    {
      "x": -3,
      "y": 8,
      "z": 3,
      "name": "Empty"
    },
    {
      "x": -3,
      "y": 9,
      "z": 3,
      "name": "Empty"
    },
    {
      "x": -3,
      "y": 10,
      "z": 3,
      "name": "Empty"
    },
    {
      "x": -3,
      "y": 11,
      "z": 3,
      "name": "Empty"
    },
    {
      "x": -3,
      "y": 12,
      "z": 3,
      "name": "Empty"
    },
    {
      "x": -3,
      "y": 13,
      "z": 3,
      "name": "Soil_Mud_Dry"
    },
    {
      "x": -3,
      "y": 14,
      "z": 3,
      "name": "Soil_Mud_Dry"
    },
    {
      "x": -3,
      "y": 15,
      "z": 3,
      "name": "Soil_Mud_Dry"
    },
    {
      "x": -3,
      "y": 2,
      "z": 4,
      "name": "Soil_Mud_Dry"
    },
    {
      "x": -3,
      "y": 3,
      "z": 4,
      "name": "Soil_Roots_Poisoned"
    },
    {
      "x": -3,
      "y": 4,
      "z": 4,
      "name": "Empty"
    },
    {
      "x": -3,
      "y": 5,
      "z": 4,
      "name": "Empty"
    },
    {
      "x": -3,
      "y": 6,
      "z": 4,
      "name": "Empty"
    },
    {
      "x": -3,
      "y": 7,
      "z": 4,
      "name": "Empty"
    },
    {
      "x": -3,
      "y": 8,
      "z": 4,
      "name": "Empty"
    },
    {
      "x": -3,
      "y": 9,
      "z": 4,
      "name": "Empty"
    },
    {
      "x": -3,
      "y": 10,
      "z": 4,
      "name": "Empty"
    },
    {
      "x": -3,
      "y": 11,
      "z": 4,
      "name": "Deco_Scarak_Eggsacks",
      "rotation": 6
    },
    {
      "x": -3,
      "y": 12,
      "z": 4,
      "name": "Empty"
    },
    {
      "x": -3,
      "y": 13,
      "z": 4,
      "name": "Soil_Mud_Dry"
    },
    {
      "x": -3,
      "y": 14,
      "z": 4,
      "name": "Soil_Mud_Dry"
    },
    {
      "x": -3,
      "y": 15,
      "z": 4,
      "name": "Soil_Mud_Dry"
    },
    {
      "x": -3,
      "y": 2,
      "z": 5,
      "name": "Soil_Mud_Dry"
    },
    {
      "x": -3,
      "y": 3,
      "z": 5,
      "name": "Soil_Roots_Poisoned"
    },
    {
      "x": -3,
      "y": 4,
      "z": 5,
      "name": "Empty"
    },
    {
      "x": -3,
      "y": 5,
      "z": 5,
      "name": "Empty"
    },
    {
      "x": -3,
      "y": 6,
      "z": 5,
      "name": "Empty"
    },
    {
      "x": -3,
      "y": 7,
      "z": 5,
      "name": "Empty"
    },
    {
      "x": -3,
      "y": 8,
      "z": 5,
      "name": "Empty"
    },
    {
      "x": -3,
      "y": 9,
      "z": 5,
      "name": "Empty"
    },
    {
      "x": -3,
      "y": 10,
      "z": 5,
      "name": "Empty"
    },
    {
      "x": -3,
      "y": 11,
      "z": 5,
      "name": "Soil_Hive"
    },
    {
      "x": -3,
      "y": 12,
      "z": 5,
      "name": "Soil_Mud_Dry"
    },
    {
      "x": -3,
      "y": 13,
      "z": 5,
      "name": "Soil_Mud_Dry"
    },
    {
      "x": -3,
      "y": 14,
      "z": 5,
      "name": "Soil_Mud_Dry"
    },
    {
      "x": -3,
      "y": 15,
      "z": 5,
      "name": "Soil_Mud_Dry"
    },
    {
      "x": -3,
      "y": 2,
      "z": 6,
      "name": "Soil_Mud_Dry"
    },
    {
      "x": -3,
      "y": 3,
      "z": 6,
      "name": "Soil_Roots_Poisoned"
    },
    {
      "x": -3,
      "y": 4,
      "z": 6,
      "name": "Empty"
    },
    {
      "x": -3,
      "y": 5,
      "z": 6,
      "name": "Empty"
    },
    {
      "x": -3,
      "y": 6,
      "z": 6,
      "name": "Empty"
    },
    {
      "x": -3,
      "y": 7,
      "z": 6,
      "name": "Empty"
    },
    {
      "x": -3,
      "y": 8,
      "z": 6,
      "name": "Empty"
    },
    {
      "x": -3,
      "y": 9,
      "z": 6,
      "name": "Empty"
    },
    {
      "x": -3,
      "y": 10,
      "z": 6,
      "name": "Empty"
    },
    {
      "x": -3,
      "y": 11,
      "z": 6,
      "name": "Empty"
    },
    {
      "x": -3,
      "y": 12,
      "z": 6,
      "name": "Soil_Mud_Dry"
    },
    {
      "x": -3,
      "y": 13,
      "z": 6,
      "name": "Soil_Mud_Dry"
    },
    {
      "x": -3,
      "y": 14,
      "z": 6,
      "name": "Soil_Mud_Dry"
    },
    {
      "x": -3,
      "y": 15,
      "z": 6,
      "name": "Soil_Mud_Dry"
    },
    {
      "x": -3,
      "y": 2,
      "z": 7,
      "name": "Soil_Mud_Dry"
    },
    {
      "x": -3,
      "y": 3,
      "z": 7,
      "name": "Soil_Mud_Dry"
    },
    {
      "x": -3,
      "y": 4,
      "z": 7,
      "name": "Empty"
    },
    {
      "x": -3,
      "y": 5,
      "z": 7,
      "name": "Empty"
    },
    {
      "x": -3,
      "y": 6,
      "z": 7,
      "name": "Empty"
    },
    {
      "x": -3,
      "y": 7,
      "z": 7,
      "name": "Empty"
    },
    {
      "x": -3,
      "y": 8,
      "z": 7,
      "name": "Empty"
    },
    {
      "x": -3,
      "y": 9,
      "z": 7,
      "name": "Empty"
    },
    {
      "x": -3,
      "y": 10,
      "z": 7,
      "name": "Soil_Mud_Dry"
    },
    {
      "x": -3,
      "y": 11,
      "z": 7,
      "name": "Soil_Mud_Dry"
    },
    {
      "x": -3,
      "y": 12,
      "z": 7,
      "name": "Soil_Mud_Dry"
    },
    {
      "x": -3,
      "y": 13,
      "z": 7,
      "name": "Soil_Mud_Dry"
    },
    {
      "x": -3,
      "y": 14,
      "z": 7,
      "name": "Soil_Mud_Dry"
    },
    {
      "x": -3,
      "y": 15,
      "z": 7,
      "name": "Soil_Mud_Dry"
    },
    {
      "x": -3,
      "y": 3,
      "z": 8,
      "name": "Soil_Mud_Dry"
    },
    {
      "x": -3,
      "y": 4,
      "z": 8,
