{
  "version": 8,
  "blockIdVersion": 8,
  "anchorX": 7,
  "anchorY": 7,
  "anchorZ": 7,
  "blocks": [
    {
      "x": 4,
      "y": 12,
      "z": 7,
      "name": "Plant_Leaves_Dead"
    },
    {
      "x": 4,
      "y": 14,
      "z": 7,
      "name": "Plant_Leaves_Dead"
    },
    {
      "x": 4,
      "y": 14,
      "z": 8,
      "name": "Plant_Leaves_Dead"
    },
    {
      "x": 5,
      "y": 12,
      "z": 6,
      "name": "Plant_Leaves_Dead"
    },
    {
      "x": 5,
      "y": 17,
      "z": 6,
      "name": "Plant_Leaves_Dead"
    },
    {
      "x": 5,
      "y": 12,
      "z": 7,
      "name": "Plant_Leaves_Dead"
    },
    {
      "x": 5,
      "y": 15,
      "z": 7,
      "name": "Plant_Leaves_Dead"
    },
    {
      "x": 5,
      "y": 17,
      "z": 7,
      "name": "Plant_Leaves_Dead"
    },
    {
      "x": 5,
      "y": 20,
      "z": 7,
      "name": "Plant_Leaves_Dead"
    },
    {
      "x": 5,
      "y": 12,
      "z": 8,
      "name": "Plant_Leaves_Dead"
    },
    {
      "x": 5,
      "y": 14,
      "z": 8,
      "name": "Plant_Leaves_Dead"
    },
    {
      "x": 6,
      "y": 12,
      "z": 6,
      "name": "Plant_Leaves_Dead"
    },
    {
      "x": 6,
      "y": 15,
      "z": 6,
      "name": "Plant_Leaves_Dead"
    },
    {
      "x": 6,
      "y": 18,
      "z": 6,
      "name": "Plant_Leaves_Dead"
    },
    {
      "x": 6,
      "y": 22,
      "z": 6,
      "name": "Plant_Leaves_Dead"
    },
    {
      "x": 6,
      "y": 9,
      "z": 7,
      "name": "Wood_Fir_Branch_Short",
      "rotation": 3
    },
    {
      "x": 6,
      "y": 12,
      "z": 7,
      "name": "Wood_Fir_Branch_Long",
      "rotation": 5
    },
    {
      "x": 6,
      "y": 13,
      "z": 7,
      "name": "Plant_Leaves_Dead"
    },
    {
      "x": 6,
      "y": 15,
      "z": 7,
      "name": "Wood_Fir_Branch_Long",
      "rotation": 5
    },
    {
      "x": 6,
      "y": 17,
      "z": 7,
      "name": "Plant_Leaves_Dead"
    },
    {
      "x": 6,
      "y": 18,
      "z": 7,
      "name": "Plant_Leaves_Dead"
    },
    {
      "x": 6,
      "y": 20,
      "z": 7,
      "name": "Wood_Fir_Branch_Long",
      "rotation": 5
    },
    {
      "x": 6,
      "y": 21,
      "z": 7,
      "name": "Plant_Leaves_Dead"
    },
    {
      "x": 6,
      "y": 22,
      "z": 7,
      "name": "Wood_Fir_Branch_Corner",
      "rotation": 3
    },
    {
      "x": 6,
      "y": 23,
      "z": 7,
      "name": "Plant_Leaves_Dead"
    },
    {
      "x": 6,
      "y": 25,
      "z": 7,
      "name": "Plant_Leaves_Dead"
    },
    {
      "x": 6,
      "y": 26,
      "z": 7,
      "name": "Plant_Leaves_Dead"
    },
    {
      "x": 6,
      "y": 28,
      "z": 7,
      "name": "Plant_Leaves_Dead"
    },
    {
      "x": 6,
      "y": 1,
      "z": 8,
      "name": "Wood_Fir_Roots"
    },
    {
      "x": 6,
      "y": 2,
      "z": 8,
      "name": "Wood_Fir_Trunk_Full"
    },
    {
      "x": 6,
      "y": 12,
      "z": 8,
      "name": "Plant_Leaves_Dead"
    },
    {
      "x": 6,
      "y": 15,
      "z": 8,
      "name": "Plant_Leaves_Dead"
    },
    {
      "x": 6,
      "y": 18,
      "z": 8,
      "name": "Plant_Leaves_Dead"
    },
    {
      "x": 6,
      "y": 12,
      "z": 9,
      "name": "Plant_Leaves_Dead"
    },
    {
      "x": 7,
      "y": 14,
      "z": 4,
      "name": "Plant_Leaves_Dead"
    },
    {
      "x": 7,
      "y": 14,
      "z": 5,
      "name": "Plant_Leaves_Dead"
    },
    {
      "x": 7,
      "y": 15,
      "z": 5,
      "name": "Plant_Leaves_Dead"
    },
    {
      "x": 7,
      "y": 19,
      "z": 5,
      "name": "Plant_Leaves_Dead"
    },
    {
      "x": 7,
      "y": 3,
      "z": 6,
      "name": "Wood_Fir_Roots"
    },
    {
      "x": 7,
      "y": 4,
      "z": 6,
      "name": "Wood_Fir_Trunk"
    },
    {
      "x": 7,
      "y": 5,
      "z": 6,
      "name": "Wood_Fir_Trunk"
    },
    {
      "x": 7,
      "y": 6,
      "z": 6,
      "name": "Wood_Fir_Trunk_Full"
    },
    {
      "x": 7,
      "y": 10,
      "z": 6,
      "name": "Wood_Fir_Branch_Long",
      "rotation": 4
    },
    {
      "x": 7,
      "y": 12,
      "z": 6,
      "name": "Plant_Leaves_Dead"
    },
    {
      "x": 7,
      "y": 15,
      "z": 6,
      "name": "Wood_Fir_Branch_Long",
      "rotation": 4
    },
    {
      "x": 7,
      "y": 16,
      "z": 6,
      "name": "Plant_Leaves_Dead"
    },
    {
      "x": 7,
      "y": 19,
      "z": 6,
      "name": "Wood_Fir_Branch_Long",
      "rotation": 4
    },
    {
      "x": 7,
      "y": 20,
      "z": 6,
      "name": "Plant_Leaves_Dead"
    },
    {
      "x": 7,
      "y": 22,
      "z": 6,
      "name": "Plant_Leaves_Dead"
    },
    {
      "x": 7,
      "y": 23,
      "z": 6,
      "name": "Plant_Leaves_Dead"
    },
    {
      "x": 7,
      "y": 25,
      "z": 6,
      "name": "Plant_Leaves_Dead"
    },
    {
      "x": 7,
      "y": 26,
      "z": 6,
      "name": "Plant_Leaves_Dead"
    },
    {
      "x": 7,
      "y": 28,
      "z": 6,
      "name": "Plant_Leaves_Dead"
    },
    {
      "x": 7,
      "y": 29,
      "z": 6,
      "name": "Plant_Leaves_Dead"
    },
    {
      "x": 7,
      "y": 5,
      "z": 7,
      "name": "Wood_Fir_Trunk"
    },
    {
      "x": 7,
      "y": 6,
      "z": 7,
      "name": "Wood_Fir_Trunk"
    },
    {
      "x": 7,
      "y": 7,
      "z": 7,
      "name": "Wood_Fir_Trunk"
    },
    {
      "x": 7,
      "y": 8,
      "z": 7,
      "name": "Wood_Fir_Trunk"
    },
    {
      "x": 7,
      "y": 9,
      "z": 7,
      "name": "Wood_Fir_Trunk"
    },
    {
      "x": 7,
      "y": 10,
      "z": 7,
      "name": "Wood_Fir_Trunk"
    },
    {
      "x": 7,
      "y": 11,
      "z": 7,
      "name": "Wood_Fir_Trunk"
    },
    {
      "x": 7,
      "y": 12,
      "z": 7,
      "name": "Wood_Fir_Trunk"
    },
    {
      "x": 7,
      "y": 13,
      "z": 7,
      "name": "Wood_Fir_Trunk"
    },
    {
      "x": 7,
      "y": 14,
      "z": 7,
      "name": "Wood_Fir_Trunk"
    },
    {
      "x": 7,
      "y": 15,
      "z": 7,
      "name": "Wood_Fir_Trunk"
    },
    {
      "x": 7,
      "y": 16,
      "z": 7,
      "name": "Wood_Fir_Trunk"
    },
    {
      "x": 7,
      "y": 17,
      "z": 7,
      "name": "Wood_Fir_Trunk"
    },
    {
      "x": 7,
      "y": 18,
      "z": 7,
      "name": "Wood_Fir_Trunk"
    },
    {
      "x": 7,
      "y": 19,
      "z": 7,
      "name": "Wood_Fir_Trunk"
    },
    {
      "x": 7,
      "y": 20,
      "z": 7,
      "name": "Wood_Fir_Trunk"
    },
    {
      "x": 7,
      "y": 21,
      "z": 7,
      "name": "Wood_Fir_Trunk"
    },
    {
      "x": 7,
      "y": 22,
      "z": 7,
      "name": "Wood_Fir_Trunk"
    },
    {
      "x": 7,
      "y": 23,
      "z": 7,
      "name": "Wood_Fir_Trunk"
    },
    {
      "x": 7,
      "y": 24,
      "z": 7,
      "name": "Wood_Fir_Trunk"
    },
    {
      "x": 7,
      "y": 25,
      "z": 7,
      "name": "Wood_Fir_Trunk_Full"
    },
    {
      "x": 7,
      "y": 26,
      "z": 7,
      "name": "Plant_Leaves_Dead"
    },
    {
      "x": 7,
      "y": 27,
      "z": 7,
      "name": "Plant_Leaves_Dead"
    },
    {
      "x": 7,
      "y": 28,
      "z": 7,
      "name": "Plant_Leaves_Dead"
    },
    {
      "x": 7,
      "y": 29,
      "z": 7,
      "name": "Plant_Leaves_Dead"
    },
    {
      "x": 7,
      "y": 30,
      "z": 7,
      "name": "Plant_Leaves_Dead"
    },
    {
      "x": 7,
      "y": 31,
      "z": 7,
      "name": "Plant_Leaves_Dead"
    },
    {
      "x": 7,
      "y": 32,
      "z": 7,
      "name": "Plant_Leaves_Dead"
    },
    {
      "x": 7,
      "y": 33,
      "z": 7,
      "name": "Plant_Leaves_Dead"
    },
    {
      "x": 7,
      "y": 34,
      "z": 7,
      "name": "Plant_Leaves_Dead"
    },
    {
      "x": 7,
      "y": 0,
      "z": 8,
      "name": "Wood_Fir_Roots"
    },
    {
      "x": 7,
      "y": 1,
      "z": 8,
      "name": "Wood_Fir_Trunk"
    },
    {
      "x": 7,
      "y": 2,
      "z": 8,
      "name": "Wood_Fir_Trunk"
    },
    {
      "x": 7,
      "y": 3,
      "z": 8,
      "name": "Wood_Fir_Trunk"
    },
    {
      "x": 7,
      "y": 4,
      "z": 8,
      "name": "Wood_Fir_Trunk"
    },
    {
      "x": 7,
      "y": 5,
      "z": 8,
      "name": "Wood_Fir_Trunk_Full"
    },
    {
      "x": 7,
      "y": 11,
      "z": 8,
      "name": "Wood_Fir_Branch_Short"
    },
    {
      "x": 7,
      "y": 14,
      "z": 8,
      "name": "Plant_Leaves_Dead"
    },
    {
      "x": 7,
      "y": 17,
      "z": 8,
      "name": "Plant_Leaves_Dead"
    },
    {
      "x": 7,
      "y": 20,
      "z": 8,
      "name": "Plant_Leaves_Dead"
    },
    {
      "x": 7,
      "y": 21,
      "z": 8,
      "name": "Plant_Leaves_Dead"
    },
    {
      "x": 7,
      "y": 22,
      "z": 8,
      "name": "Plant_Leaves_Dead"
    },
    {
      "x": 7,
      "y": 25,
      "z": 8,
      "name": "Plant_Leaves_Dead"
    },
    {
      "x": 7,
      "y": 26,
      "z": 8,
      "name": "Plant_Leaves_Dead"
    },
    {
      "x": 7,
      "y": 28,
      "z": 8,
      "name": "Plant_Leaves_Dead"
    },
    {
      "x": 7,
      "y": 20,
      "z": 9,
      "name": "Plant_Leaves_Dead"
    },
    {
      "x": 8,
      "y": 11,
      "z": 5,
      "name": "Plant_Leaves_Dead"
    },
    {
      "x": 8,
      "y": 11,
      "z": 6,
      "name": "Plant_Leaves_Dead"
    },
    {
      "x": 8,
      "y": 12,
      "z": 6,
      "name": "Plant_Leaves_Dead"
    },
    {
      "x": 8,
      "y": 19,
      "z": 6,
      "name": "Plant_Leaves_Dead"
    },
    {
      "x": 8,
      "y": 22,
      "z": 6,
      "name": "Plant_Leaves_Dead"
    },
    {
      "x": 8,
      "y": 25,
      "z": 6,
      "name": "Plant_Leaves_Dead"
    },
    {
      "x": 8,
      "y": 4,
      "z": 7,
      "name": "Wood_Fir_Roots"
    },
    {
      "x": 8,
      "y": 5,
      "z": 7,
      "name": "Wood_Fir_Trunk_Full"
    },
    {
      "x": 8,
      "y": 11,
      "z": 7,
      "name": "Plant_Leaves_Dead"
    },
    {
      "x": 8,
      "y": 12,
      "z": 7,
      "name": "Plant_Leaves_Dead"
    },
    {
      "x": 8,
      "y": 14,
      "z": 7,
      "name": "Plant_Leaves_Dead"
    },
    {
      "x": 8,
      "y": 16,
      "z": 7,
      "name": "Wood_Fir_Branch_Long",
      "rotation": 5
    },
    {
      "x": 8,
      "y": 17,
      "z": 7,
      "name": "Plant_Leaves_Dead"
    },
    {
      "x": 8,
      "y": 19,
      "z": 7,
      "name": "Plant_Leaves_Dead"
    },
    {
      "x": 8,
      "y": 20,
      "z": 7,
      "name": "Plant_Leaves_Dead"
    },
    {
      "x": 8,
      "y": 22,
      "z": 7,
      "name": "Plant_Leaves_Dead"
    },
    {
      "x": 8,
      "y": 24,
      "z": 7,
      "name": "Plant_Leaves_Dead"
    },
    {
      "x": 8,
      "y": 25,
      "z": 7,
      "name": "Plant_Leaves_Dead"
    },
    {
      "x": 8,
      "y": 26,
      "z": 7,
      "name": "Plant_Leaves_Dead"
    },
    {
      "x": 8,
      "y": 27,
      "z": 7,
      "name": "Plant_Leaves_Dead"
    },
    {
      "x": 8,
      "y": 29,
      "z": 7,
      "name": "Plant_Leaves_Dead"
    },
    {
      "x": 8,
      "y": 30,
      "z": 7,
      "name": "Plant_Leaves_Dead"
    },
    {
      "x": 8,
      "y": 14,
      "z": 8,
      "name": "Plant_Leaves_Dead"
    },
    {
      "x": 8,
      "y": 17,
      "z": 8,
      "name": "Plant_Leaves_Dead"
    },
    {
      "x": 8,
      "y": 21,
      "z": 8,
      "name": "Plant_Leaves_Dead"
    },
    {
      "x": 9,
      "y": 11,
      "z": 5,
      "name": "Plant_Leaves_Dead"
    },
    {
      "x": 9,
      "y": 11,
      "z": 6,
      "name": "Plant_Leaves_Dead"
    },
    {
      "x": 9,
      "y": 19,
      "z": 7,
      "name": "Plant_Leaves_Dead"
    },
    {
      "x": 9,
      "y": 22,
      "z": 7,
      "name": "Plant_Leaves_Dead"
    },
    {
      "x": 9,
      "y": 13,
      "z": 8,
      "name": "Plant_Leaves_Dead"
    },
    {
      "x": 9,
      "y": 14,
      "z": 8,
      "name": "Plant_Leaves_Dead"
    },
    {
      "x": 9,
      "y": 16,
      "z": 8,
      "name": "Plant_Leaves_Dead"
    },
    {
      "x": 9,
      "y": 17,
      "z": 8,
      "name": "Plant_Leaves_Dead"
    },
    {
      "x": 9,
      "y": 13,
      "z": 9,
      "name": "Plant_Leaves_Dead"
    },
    {
      "x": 9,
      "y": 16,
      "z": 9,
      "name": "Plant_Leaves_Dead"
    },
    {
      "x": 10,
      "y": 13,
      "z": 8,
      "name": "Plant_Leaves_Dead"
    },
    {
      "x": 10,
      "y": 16,
      "z": 8,
      "name": "Plant_Leaves_Dead"
    },
    {
      "x": 10,
      "y": 13,
      "z": 9,
      "name": "Plant_Leaves_Dead"
    }
  ]
}