{
  "version": 8,
  "blockIdVersion": 8,
  "anchorX": 4,
  "anchorY": 10,
  "anchorZ": 4,
  "blocks": [
    {
      "x": 1,
      "y": 16,
      "z": 2,
      "name": "Plant_Leaves_Dead"
    },
    {
      "x": 1,
      "y": 16,
      "z": 3,
      "name": "Plant_Leaves_Dead"
    },
    {
      "x": 2,
      "y": 16,
      "z": 2,
      "name": "Plant_Leaves_Dead"
    },
    {
      "x": 2,
      "y": 16,
      "z": 3,
      "name": "Plant_Leaves_Dead"
    },
    {
      "x": 2,
      "y": 17,
      "z": 3,
      "name": "Plant_Leaves_Dead"
    },
    {
      "x": 2,
      "y": 18,
      "z": 4,
      "name": "Plant_Leaves_Dead"
    },
    {
      "x": 2,
      "y": 21,
      "z": 4,
      "name": "Plant_Leaves_Dead"
    },
    {
      "x": 2,
      "y": 15,
      "z": 5,
      "name": "Plant_Leaves_Dead"
    },
    {
      "x": 2,
      "y": 15,
      "z": 6,
      "name": "Plant_Leaves_Dead"
    },
    {
      "x": 3,
      "y": 2,
      "z": 3,
      "name": "Wood_Fir_Roots"
    },
    {
      "x": 3,
      "y": 3,
      "z": 3,
      "name": "Wood_Fir_Trunk"
    },
    {
      "x": 3,
      "y": 4,
      "z": 3,
      "name": "Wood_Fir_Trunk"
    },
    {
      "x": 3,
      "y": 5,
      "z": 3,
      "name": "Wood_Fir_Trunk"
    },
    {
      "x": 3,
      "y": 6,
      "z": 3,
      "name": "Wood_Fir_Trunk"
    },
    {
      "x": 3,
      "y": 7,
      "z": 3,
      "name": "Wood_Fir_Trunk_Full"
    },
    {
      "x": 3,
      "y": 17,
      "z": 3,
      "name": "Plant_Leaves_Dead"
    },
    {
      "x": 3,
      "y": 21,
      "z": 3,
      "name": "Plant_Leaves_Dead"
    },
    {
      "x": 3,
      "y": 26,
      "z": 3,
      "name": "Plant_Leaves_Dead"
    },
    {
      "x": 3,
      "y": 6,
      "z": 4,
      "name": "Wood_Fir_Roots"
    },
    {
      "x": 3,
      "y": 7,
      "z": 4,
      "name": "Wood_Fir_Trunk"
    },
    {
      "x": 3,
      "y": 8,
      "z": 4,
      "name": "Wood_Fir_Trunk_Full"
    },
    {
      "x": 3,
      "y": 15,
      "z": 4,
      "name": "Plant_Leaves_Dead"
    },
    {
      "x": 3,
      "y": 16,
      "z": 4,
      "name": "Plant_Leaves_Dead"
    },
    {
      "x": 3,
      "y": 17,
      "z": 4,
      "name": "Plant_Leaves_Dead"
    },
    {
      "x": 3,
      "y": 18,
      "z": 4,
      "name": "Plant_Leaves_Dead"
    },
    {
      "x": 3,
      "y": 19,
      "z": 4,
      "name": "Plant_Leaves_Dead"
    },
    {
      "x": 3,
      "y": 21,
      "z": 4,
      "name": "Plant_Leaves_Dead"
    },
    {
      "x": 3,
      "y": 22,
      "z": 4,
      "name": "Plant_Leaves_Dead"
    },
    {
      "x": 3,
      "y": 23,
      "z": 4,
      "name": "Plant_Leaves_Dead"
    },
    {
      "x": 3,
      "y": 26,
      "z": 4,
      "name": "Plant_Leaves_Dead"
    },
    {
      "x": 3,
      "y": 27,
      "z": 4,
      "name": "Plant_Leaves_Dead"
    },
    {
      "x": 3,
      "y": 29,
      "z": 4,
      "name": "Plant_Leaves_Dead"
    },
    {
      "x": 3,
      "y": 30,
      "z": 4,
      "name": "Plant_Leaves_Dead"
    },
    {
      "x": 3,
      "y": 15,
      "z": 5,
      "name": "Plant_Leaves_Dead"
    },
    {
      "x": 3,
      "y": 16,
      "z": 5,
      "name": "Plant_Leaves_Dead"
    },
    {
      "x": 3,
      "y": 18,
      "z": 5,
      "name": "Plant_Leaves_Dead"
    },
    {
      "x": 3,
      "y": 21,
      "z": 5,
      "name": "Plant_Leaves_Dead"
    },
    {
      "x": 3,
      "y": 22,
      "z": 5,
      "name": "Plant_Leaves_Dead"
    },
    {
      "x": 3,
      "y": 23,
      "z": 5,
      "name": "Plant_Leaves_Dead"
    },
    {
      "x": 3,
      "y": 15,
      "z": 6,
      "name": "Plant_Leaves_Dead"
    },
    {
      "x": 4,
      "y": 19,
      "z": 2,
      "name": "Plant_Leaves_Dead"
    },
    {
      "x": 4,
      "y": 13,
      "z": 3,
      "name": "Wood_Fir_Branch_Short",
      "rotation": 2
    },
    {
      "x": 4,
      "y": 17,
      "z": 3,
      "name": "Plant_Leaves_Dead"
    },
    {
      "x": 4,
      "y": 19,
      "z": 3,
      "name": "Wood_Fir_Branch_Long",
      "rotation": 4
    },
    {
      "x": 4,
      "y": 20,
      "z": 3,
      "name": "Plant_Leaves_Dead"
    },
    {
      "x": 4,
      "y": 23,
      "z": 3,
      "name": "Plant_Leaves_Dead"
    },
    {
      "x": 4,
      "y": 24,
      "z": 3,
      "name": "Plant_Leaves_Dead"
    },
    {
      "x": 4,
      "y": 25,
      "z": 3,
      "name": "Plant_Leaves_Dead"
    },
    {
      "x": 4,
      "y": 26,
      "z": 3,
      "name": "Plant_Leaves_Dead"
    },
    {
      "x": 4,
      "y": 27,
      "z": 3,
      "name": "Plant_Leaves_Dead"
    },
    {
      "x": 4,
      "y": 28,
      "z": 3,
      "name": "Plant_Leaves_Dead"
    },
    {
      "x": 4,
      "y": 30,
      "z": 3,
      "name": "Plant_Leaves_Dead"
    },
    {
      "x": 4,
      "y": 31,
      "z": 3,
      "name": "Plant_Leaves_Dead"
    },
    {
      "x": 4,
      "y": 8,
      "z": 4,
      "name": "Wood_Fir_Trunk"
    },
    {
      "x": 4,
      "y": 9,
      "z": 4,
      "name": "Wood_Fir_Trunk"
    },
    {
      "x": 4,
      "y": 10,
      "z": 4,
      "name": "Wood_Fir_Trunk"
    },
    {
      "x": 4,
      "y": 11,
      "z": 4,
      "name": "Wood_Fir_Trunk"
    },
    {
      "x": 4,
      "y": 12,
      "z": 4,
      "name": "Wood_Fir_Trunk"
    },
    {
      "x": 4,
      "y": 13,
      "z": 4,
      "name": "Wood_Fir_Trunk"
    },
    {
      "x": 4,
      "y": 14,
      "z": 4,
      "name": "Wood_Fir_Trunk"
    },
    {
      "x": 4,
      "y": 15,
      "z": 4,
      "name": "Wood_Fir_Trunk"
    },
    {
      "x": 4,
      "y": 16,
      "z": 4,
      "name": "Wood_Fir_Trunk"
    },
    {
      "x": 4,
      "y": 17,
      "z": 4,
      "name": "Wood_Fir_Trunk"
    },
    {
      "x": 4,
      "y": 18,
      "z": 4,
      "name": "Wood_Fir_Trunk"
    },
    {
      "x": 4,
      "y": 19,
      "z": 4,
      "name": "Wood_Fir_Trunk"
    },
    {
      "x": 4,
      "y": 20,
      "z": 4,
      "name": "Wood_Fir_Trunk"
    },
    {
      "x": 4,
      "y": 21,
      "z": 4,
      "name": "Wood_Fir_Trunk"
    },
    {
      "x": 4,
      "y": 22,
      "z": 4,
      "name": "Wood_Fir_Trunk"
    },
    {
      "x": 4,
      "y": 23,
      "z": 4,
      "name": "Wood_Fir_Trunk"
    },
    {
      "x": 4,
      "y": 24,
      "z": 4,
      "name": "Wood_Fir_Trunk"
    },
    {
      "x": 4,
      "y": 25,
      "z": 4,
      "name": "Wood_Fir_Trunk_Full"
    },
    {
      "x": 4,
      "y": 26,
      "z": 4,
      "name": "Wood_Fir_Trunk_Full"
    },
    {
      "x": 4,
      "y": 27,
      "z": 4,
      "name": "Plant_Leaves_Dead"
    },
    {
      "x": 4,
      "y": 28,
      "z": 4,
      "name": "Plant_Leaves_Dead"
    },
    {
      "x": 4,
      "y": 29,
      "z": 4,
      "name": "Plant_Leaves_Dead"
    },
    {
      "x": 4,
      "y": 30,
      "z": 4,
      "name": "Plant_Leaves_Dead"
    },
    {
      "x": 4,
      "y": 31,
      "z": 4,
      "name": "Plant_Leaves_Dead"
    },
    {
      "x": 4,
      "y": 32,
      "z": 4,
      "name": "Plant_Leaves_Dead"
    },
    {
      "x": 4,
      "y": 33,
      "z": 4,
      "name": "Plant_Leaves_Dead"
    },
    {
      "x": 4,
      "y": 34,
      "z": 4,
      "name": "Plant_Leaves_Dead"
    },
    {
      "x": 4,
      "y": 35,
      "z": 4,
      "name": "Plant_Leaves_Dead"
    },
    {
      "x": 4,
      "y": 4,
      "z": 5,
      "name": "Wood_Fir_Roots"
    },
    {
      "x": 4,
      "y": 5,
      "z": 5,
      "name": "Wood_Fir_Trunk"
    },
    {
      "x": 4,
      "y": 6,
      "z": 5,
      "name": "Wood_Fir_Trunk"
    },
    {
      "x": 4,
      "y": 7,
      "z": 5,
      "name": "Wood_Fir_Trunk"
    },
    {
      "x": 4,
      "y": 8,
      "z": 5,
      "name": "Wood_Fir_Trunk_Full"
    },
    {
      "x": 4,
      "y": 15,
      "z": 5,
      "name": "Plant_Leaves_Dead"
    },
    {
      "x": 4,
      "y": 16,
      "z": 5,
      "name": "Plant_Leaves_Dead"
    },
    {
      "x": 4,
      "y": 18,
      "z": 5,
      "name": "Wood_Fir_Branch_Long",
      "rotation": 4
    },
    {
      "x": 4,
      "y": 19,
      "z": 5,
      "name": "Plant_Leaves_Dead"
    },
    {
      "x": 4,
      "y": 21,
      "z": 5,
      "name": "Plant_Leaves_Dead"
    },
    {
      "x": 4,
      "y": 24,
      "z": 5,
      "name": "Plant_Leaves_Dead"
    },
    {
      "x": 4,
      "y": 26,
      "z": 5,
      "name": "Plant_Leaves_Dead"
    },
    {
      "x": 4,
      "y": 27,
      "z": 5,
      "name": "Plant_Leaves_Dead"
    },
    {
      "x": 4,
      "y": 29,
      "z": 5,
      "name": "Plant_Leaves_Dead"
    },
    {
      "x": 4,
      "y": 18,
      "z": 6,
      "name": "Plant_Leaves_Dead"
    },
    {
      "x": 4,
      "y": 21,
      "z": 6,
      "name": "Plant_Leaves_Dead"
    },
    {
      "x": 5,
      "y": 16,
      "z": 2,
      "name": "Plant_Leaves_Dead"
    },
    {
      "x": 5,
      "y": 16,
      "z": 3,
      "name": "Plant_Leaves_Dead"
    },
    {
      "x": 5,
      "y": 17,
      "z": 3,
      "name": "Plant_Leaves_Dead"
    },
    {
      "x": 5,
      "y": 19,
      "z": 3,
      "name": "Plant_Leaves_Dead"
    },
    {
      "x": 5,
      "y": 14,
      "z": 4,
      "name": "Wood_Fir_Branch_Corner",
      "rotation": 1
    },
    {
      "x": 5,
      "y": 15,
      "z": 4,
      "name": "Plant_Leaves_Dead"
    },
    {
      "x": 5,
      "y": 16,
      "z": 4,
      "name": "Plant_Leaves_Dead"
    },
    {
      "x": 5,
      "y": 17,
      "z": 4,
      "name": "Plant_Leaves_Dead"
    },
    {
      "x": 5,
      "y": 19,
      "z": 4,
      "name": "Plant_Leaves_Dead"
    },
    {
      "x": 5,
      "y": 20,
      "z": 4,
      "name": "Plant_Leaves_Dead"
    },
    {
      "x": 5,
      "y": 21,
      "z": 4,
      "name": "Wood_Fir_Branch_Corner",
      "rotation": 1
    },
    {
      "x": 5,
      "y": 22,
      "z": 4,
      "name": "Plant_Leaves_Dead"
    },
    {
      "x": 5,
      "y": 24,
      "z": 4,
      "name": "Wood_Fir_Branch_Corner",
      "rotation": 1
    },
    {
      "x": 5,
      "y": 25,
      "z": 4,
      "name": "Plant_Leaves_Dead"
    },
    {
      "x": 5,
      "y": 26,
      "z": 4,
      "name": "Plant_Leaves_Dead"
    },
    {
      "x": 5,
      "y": 27,
      "z": 4,
      "name": "Plant_Leaves_Dead"
    },
    {
      "x": 5,
      "y": 29,
      "z": 4,
      "name": "Plant_Leaves_Dead"
    },
    {
      "x": 5,
      "y": 15,
      "z": 5,
      "name": "Plant_Leaves_Dead"
    },
    {
      "x": 6,
      "y": 16,
      "z": 2,
      "name": "Plant_Leaves_Dead"
    },
    {
      "x": 6,
      "y": 16,
      "z": 3,
      "name": "Plant_Leaves_Dead"
    },
    {
      "x": 6,
      "y": 19,
      "z": 4,
      "name": "Plant_Leaves_Dead"
    },
    {
      "x": 6,
      "y": 14,
      "z": 5,
      "name": "Plant_Leaves_Dead"
    },
    {
      "x": 6,
      "y": 15,
      "z": 5,
      "name": "Plant_Leaves_Dead"
    }
  ]
}