{
  "version": 8,
  "blockIdVersion": 8,
  "anchorX": 0,
  "anchorY": 0,
  "anchorZ": 0,
  "blocks": [
    {
      "x": -11,
      "y": 0,
      "z": -5,
      "name": "Rock_Stone"
    },
    {
      "x": -11,
      "y": 1,
      "z": -5,
      "name": "Rock_Stone"
    },
    {
      "x": -11,
      "y": 2,
      "z": -5,
      "name": "Rock_Stone"
    },
    {
      "x": -11,
      "y": 3,
      "z": -5,
      "name": "Rock_Stone"
    },
    {
      "x": -11,
      "y": 4,
      "z": -5,
      "name": "Rock_Stone"
    },
    {
      "x": -11,
      "y": 5,
      "z": -5,
      "name": "Rock_Stone"
    },
    {
      "x": -11,
      "y": 6,
      "z": -5,
      "name": "Rock_Stone"
    },
    {
      "x": -11,
      "y": 7,
      "z": -5,
      "name": "Rock_Stone"
    },
    {
      "x": -11,
      "y": 8,
      "z": -5,
      "name": "Rock_Stone"
    },
    {
      "x": -11,
      "y": 9,
      "z": -5,
      "name": "Rock_Stone"
    },
    {
      "x": -11,
      "y": 0,
      "z": -4,
      "name": "Rock_Stone"
    },
    {
      "x": -11,
      "y": 1,
      "z": -4,
      "name": "Rock_Stone"
    },
    {
      "x": -11,
      "y": 2,
      "z": -4,
      "name": "Rock_Stone"
    },
    {
      "x": -11,
      "y": 3,
      "z": -4,
      "name": "Rock_Stone"
    },
    {
      "x": -11,
      "y": 4,
      "z": -4,
      "name": "Rock_Stone"
    },
    {
      "x": -11,
      "y": 5,
      "z": -4,
      "name": "Rock_Stone"
    },
    {
      "x": -11,
      "y": 6,
      "z": -4,
      "name": "Rock_Stone"
    },
    {
      "x": -11,
      "y": 7,
      "z": -4,
      "name": "Rock_Stone"
    },
    {
      "x": -11,
      "y": 8,
      "z": -4,
      "name": "Rock_Stone"
    },
    {
      "x": -11,
      "y": 9,
      "z": -4,
      "name": "Rock_Stone"
    },
    {
      "x": -11,
      "y": 0,
      "z": -3,
      "name": "Rock_Stone"
    },
    {
      "x": -11,
      "y": 1,
      "z": -3,
      "name": "Rock_Stone"
    },
    {
      "x": -11,
      "y": 2,
      "z": -3,
      "name": "Rock_Stone"
    },
    {
      "x": -11,
      "y": 3,
      "z": -3,
      "name": "Rock_Stone"
    },
    {
      "x": -11,
      "y": 4,
      "z": -3,
      "name": "Rock_Stone"
    },
    {
      "x": -11,
      "y": 5,
      "z": -3,
      "name": "Rock_Stone"
    },
    {
      "x": -11,
      "y": 6,
      "z": -3,
      "name": "Rock_Stone"
    },
    {
      "x": -11,
      "y": 7,
      "z": -3,
      "name": "Rock_Stone"
    },
    {
      "x": -11,
      "y": 8,
      "z": -3,
      "name": "Rock_Stone"
    },
    {
      "x": -11,
      "y": 9,
      "z": -3,
      "name": "Rock_Stone"
    },
    {
      "x": -11,
      "y": 0,
      "z": -2,
      "name": "Rock_Stone"
    },
    {
      "x": -11,
      "y": 1,
      "z": -2,
      "name": "Rock_Stone"
    },
    {
      "x": -11,
      "y": 2,
      "z": -2,
      "name": "Rock_Stone"
    },
    {
      "x": -11,
      "y": 3,
      "z": -2,
      "name": "Rock_Stone"
    },
    {
      "x": -11,
      "y": 4,
      "z": -2,
      "name": "Rock_Stone"
    },
    {
      "x": -11,
      "y": 5,
      "z": -2,
      "name": "Rock_Stone"
    },
    {
      "x": -11,
      "y": 6,
      "z": -2,
      "name": "Rock_Stone"
    },
    {
      "x": -11,
      "y": 7,
      "z": -2,
      "name": "Rock_Stone"
    },
    {
      "x": -11,
      "y": 8,
      "z": -2,
      "name": "Rock_Stone"
    },
    {
      "x": -11,
      "y": 9,
      "z": -2,
      "name": "Rock_Stone"
    },
    {
      "x": -11,
      "y": 0,
      "z": -1,
      "name": "Rock_Stone"
    },
    {
      "x": -11,
      "y": 1,
      "z": -1,
      "name": "Rock_Stone"
    },
    {
      "x": -11,
      "y": 2,
      "z": -1,
      "name": "Rock_Stone"
    },
    {
      "x": -11,
      "y": 3,
      "z": -1,
      "name": "Rock_Stone"
    },
    {
      "x": -11,
      "y": 4,
      "z": -1,
      "name": "Rock_Stone"
    },
    {
      "x": -11,
      "y": 5,
      "z": -1,
      "name": "Rock_Stone"
    },
    {
      "x": -11,
      "y": 6,
      "z": -1,
      "name": "Rock_Stone"
    },
    {
      "x": -11,
      "y": 7,
      "z": -1,
      "name": "Rock_Stone"
    },
    {
      "x": -11,
      "y": 8,
      "z": -1,
      "name": "Rock_Stone"
    },
    {
      "x": -11,
      "y": 9,
      "z": -1,
      "name": "Rock_Stone"
    },
    {
      "x": -11,
      "y": 0,
      "z": 0,
      "name": "Rock_Stone"
    },
    {
      "x": -11,
      "y": 1,
      "z": 0,
      "name": "Rock_Stone"
    },
    {
      "x": -11,
      "y": 2,
      "z": 0,
      "name": "Rock_Stone"
    },
    {
      "x": -11,
      "y": 3,
      "z": 0,
      "name": "Rock_Stone"
    },
    {
      "x": -11,
      "y": 4,
      "z": 0,
      "name": "Rock_Stone"
    },
    {
      "x": -11,
      "y": 5,
      "z": 0,
      "name": "Rock_Stone"
    },
    {
      "x": -11,
      "y": 6,
      "z": 0,
      "name": "Rock_Stone"
    },
    {
      "x": -11,
      "y": 7,
      "z": 0,
      "name": "Rock_Stone"
    },
    {
      "x": -11,
      "y": 8,
      "z": 0,
      "name": "Rock_Stone"
    },
    {
      "x": -11,
      "y": 9,
      "z": 0,
      "name": "Rock_Stone"
    },
    {
      "x": -11,
      "y": 0,
      "z": 1,
      "name": "Rock_Stone"
    },
    {
      "x": -11,
      "y": 1,
      "z": 1,
      "name": "Rock_Stone"
    },
    {
      "x": -11,
      "y": 2,
      "z": 1,
      "name": "Rock_Stone"
    },
    {
      "x": -11,
      "y": 3,
      "z": 1,
      "name": "Rock_Stone"
    },
    {
      "x": -11,
      "y": 4,
      "z": 1,
      "name": "Rock_Stone"
    },
    {
      "x": -11,
      "y": 5,
      "z": 1,
      "name": "Rock_Stone"
    },
    {
      "x": -11,
      "y": 6,
      "z": 1,
      "name": "Rock_Stone"
    },
    {
      "x": -11,
      "y": 7,
      "z": 1,
      "name": "Rock_Stone"
    },
    {
      "x": -11,
      "y": 8,
      "z": 1,
      "name": "Rock_Stone"
    },
    {
      "x": -11,
      "y": 9,
      "z": 1,
      "name": "Rock_Stone"
    },
    {
      "x": -11,
      "y": 0,
      "z": 2,
      "name": "Rock_Stone"
    },
    {
      "x": -11,
      "y": 1,
      "z": 2,
      "name": "Rock_Stone"
    },
    {
      "x": -11,
      "y": 2,
      "z": 2,
      "name": "Rock_Stone"
    },
    {
      "x": -11,
      "y": 3,
      "z": 2,
      "name": "Rock_Stone"
    },
    {
      "x": -11,
      "y": 4,
      "z": 2,
      "name": "Rock_Stone"
    },
    {
      "x": -11,
      "y": 5,
      "z": 2,
      "name": "Rock_Stone"
    },
    {
      "x": -11,
      "y": 6,
      "z": 2,
      "name": "Rock_Stone"
    },
    {
      "x": -11,
      "y": 7,
      "z": 2,
      "name": "Rock_Stone"
    },
    {
      "x": -11,
      "y": 8,
      "z": 2,
      "name": "Rock_Stone"
    },
    {
      "x": -11,
      "y": 9,
      "z": 2,
      "name": "Rock_Stone"
    },
    {
      "x": -11,
      "y": 0,
      "z": 3,
      "name": "Rock_Stone"
    },
    {
      "x": -11,
      "y": 1,
      "z": 3,
      "name": "Rock_Stone"
    },
    {
      "x": -11,
      "y": 2,
      "z": 3,
      "name": "Rock_Stone"
    },
    {
      "x": -11,
      "y": 3,
      "z": 3,
      "name": "Rock_Stone"
    },
    {
      "x": -11,
      "y": 4,
      "z": 3,
      "name": "Rock_Stone"
    },
    {
      "x": -11,
      "y": 5,
      "z": 3,
      "name": "Rock_Stone"
    },
    {
      "x": -11,
      "y": 6,
      "z": 3,
      "name": "Rock_Stone"
    },
    {
      "x": -11,
      "y": 7,
      "z": 3,
      "name": "Rock_Stone"
    },
    {
      "x": -11,
      "y": 8,
      "z": 3,
      "name": "Rock_Stone"
    },
    {
      "x": -11,
      "y": 9,
      "z": 3,
      "name": "Rock_Stone"
    },
    {
      "x": -11,
      "y": 0,
      "z": 4,
      "name": "Rock_Stone"
    },
    {
      "x": -11,
      "y": 1,
      "z": 4,
      "name": "Rock_Stone"
    },
    {
      "x": -11,
      "y": 2,
      "z": 4,
      "name": "Rock_Stone"
    },
    {
      "x": -11,
      "y": 3,
      "z": 4,
      "name": "Rock_Stone"
    },
    {
      "x": -11,
      "y": 4,
      "z": 4,
      "name": "Rock_Stone"
    },
    {
      "x": -11,
      "y": 5,
      "z": 4,
      "name": "Rock_Stone"
    },
    {
      "x": -11,
      "y": 6,
      "z": 4,
      "name": "Rock_Stone"
    },
    {
      "x": -11,
      "y": 7,
      "z": 4,
      "name": "Rock_Stone"
    },
    {
      "x": -11,
      "y": 8,
      "z": 4,
      "name": "Rock_Stone"
    },
    {
      "x": -11,
      "y": 9,
      "z": 4,
      "name": "Rock_Stone"
    },
    {
      "x": -11,
      "y": 0,
      "z": 5,
      "name": "Rock_Stone"
    },
    {
      "x": -11,
      "y": 1,
      "z": 5,
      "name": "Rock_Stone"
    },
    {
      "x": -11,
      "y": 2,
      "z": 5,
      "name": "Rock_Stone"
    },
    {
      "x": -11,
      "y": 3,
      "z": 5,
      "name": "Rock_Stone"
    },
    {
      "x": -11,
      "y": 4,
      "z": 5,
      "name": "Rock_Stone"
    },
    {
      "x": -11,
      "y": 5,
      "z": 5,
      "name": "Rock_Stone"
    },
    {
      "x": -11,
      "y": 6,
      "z": 5,
      "name": "Rock_Stone"
    },
    {
      "x": -11,
      "y": 7,
      "z": 5,
      "name": "Rock_Stone"
    },
    {
      "x": -11,
      "y": 8,
      "z": 5,
      "name": "Rock_Stone"
    },
    {
      "x": -11,
      "y": 9,
      "z": 5,
      "name": "Rock_Stone"
    },
    {
      "x": -10,
      "y": 0,
      "z": -5,
      "name": "Rock_Stone"
    },
    {
      "x": -10,
      "y": 1,
      "z": -5,
      "name": "Rock_Stone"
    },
    {
      "x": -10,
      "y": 2,
      "z": -5,
      "name": "Rock_Stone"
    },
    {
      "x": -10,
      "y": 3,
      "z": -5,
      "name": "Rock_Stone"
    },
    {
      "x": -10,
      "y": 4,
      "z": -5,
      "name": "Rock_Stone"
    },
    {
      "x": -10,
      "y": 5,
      "z": -5,
      "name": "Rock_Stone"
    },
    {
      "x": -10,
      "y": 6,
      "z": -5,
      "name": "Rock_Stone"
    },
    {
      "x": -10,
      "y": 7,
      "z": -5,
      "name": "Rock_Stone"
    },
    {
      "x": -10,
      "y": 8,
      "z": -5,
      "name": "Rock_Stone"
    },
    {
      "x": -10,
      "y": 9,
      "z": -5,
      "name": "Rock_Stone"
    },
    {
      "x": -10,
      "y": 0,
      "z": -4,
      "name": "Rock_Stone"
    },
    {
      "x": -10,
      "y": 1,
      "z": -4,
      "name": "Rock_Stone"
    },
    {
      "x": -10,
      "y": 2,
      "z": -4,
      "name": "Rock_Stone"
    },
    {
      "x": -10,
      "y": 3,
      "z": -4,
      "name": "Rock_Stone"
    },
    {
      "x": -10,
      "y": 4,
      "z": -4,
      "name": "Rock_Stone"
    },
    {
      "x": -10,
      "y": 5,
      "z": -4,
      "name": "Rock_Stone"
    },
    {
      "x": -10,
      "y": 6,
      "z": -4,
      "name": "Rock_Stone"
    },
    {
      "x": -10,
      "y": 7,
      "z": -4,
      "name": "Rock_Stone"
    },
    {
      "x": -10,
      "y": 8,
      "z": -4,
      "name": "Rock_Stone"
    },
    {
      "x": -10,
      "y": 9,
      "z": -4,
      "name": "Rock_Stone"
    },
    {
      "x": -10,
      "y": 0,
      "z": -3,
      "name": "Rock_Stone"
    },
    {
      "x": -10,
      "y": 1,
      "z": -3,
      "name": "Rock_Stone"
    },
    {
      "x": -10,
      "y": 2,
      "z": -3,
      "name": "Rock_Stone"
    },
    {
      "x": -10,
      "y": 3,
      "z": -3,
      "name": "Rock_Stone"
    },
    {
      "x": -10,
      "y": 4,
      "z": -3,
      "name": "Rock_Stone"
    },
    {
      "x": -10,
      "y": 5,
      "z": -3,
      "name": "Rock_Stone"
    },
    {
      "x": -10,
      "y": 6,
      "z": -3,
      "name": "Rock_Stone"
    },
    {
      "x": -10,
      "y": 7,
      "z": -3,
      "name": "Rock_Stone"
    },
    {
      "x": -10,
      "y": 8,
      "z": -3,
      "name": "Rock_Stone"
    },
    {
      "x": -10,
      "y": 9,
      "z": -3,
      "name": "Rock_Stone"
    },
    {
      "x": -10,
      "y": 0,
      "z": -2,
      "name": "Rock_Stone"
    },
    {
      "x": -10,
      "y": 1,
      "z": -2,
      "name": "Rock_Stone"
    },
    {
      "x": -10,
      "y": 2,
      "z": -2,
      "name": "Rock_Stone"
    },
    {
      "x": -10,
      "y": 3,
      "z": -2,
      "name": "Rock_Stone"
    },
    {
      "x": -10,
      "y": 4,
      "z": -2,
      "name": "Rock_Stone"
    },
    {
      "x": -10,
      "y": 5,
      "z": -2,
      "name": "Rock_Stone"
    },
    {
      "x": -10,
      "y": 6,
      "z": -2,
      "name": "Rock_Stone"
    },
    {
      "x": -10,
      "y": 7,
      "z": -2,
      "name": "Rock_Stone"
    },
    {
      "x": -10,
      "y": 8,
      "z": -2,
      "name": "Rock_Stone"
    },
    {
      "x": -10,
      "y": 9,
      "z": -2,
      "name": "Rock_Stone"
    },
    {
      "x": -10,
      "y": 0,
      "z": -1,
      "name": "Rock_Stone"
    },
    {
      "x": -10,
      "y": 1,
      "z": -1,
      "name": "Rock_Stone"
    },
    {
      "x": -10,
      "y": 2,
      "z": -1,
      "name": "Rock_Stone"
    },
    {
      "x": -10,
      "y": 3,
      "z": -1,
      "name": "Rock_Stone"
    },
    {
      "x": -10,
      "y": 4,
      "z": -1,
      "name": "Rock_Stone"
    },
    {
      "x": -10,
      "y": 5,
      "z": -1,
      "name": "Rock_Stone"
    },
    {
      "x": -10,
      "y": 6,
      "z": -1,
      "name": "Rock_Stone"
    },
    {
      "x": -10,
      "y": 7,
      "z": -1,
      "name": "Rock_Stone"
    },
    {
      "x": -10,
      "y": 8,
      "z": -1,
      "name": "Rock_Stone"
    },
    {
      "x": -10,
      "y": 9,
      "z": -1,
      "name": "Rock_Stone"
    },
    {
      "x": -10,
      "y": 0,
      "z": 0,
      "name": "Rock_Stone"
    },
    {
      "x": -10,
      "y": 1,
      "z": 0,
      "name": "Rock_Stone"
    },
    {
      "x": -10,
      "y": 2,
      "z": 0,
      "name": "Rock_Stone"
    },
    {
      "x": -10,
      "y": 3,
      "z": 0,
      "name": "Plant_Crop_Mushroom_Flatcap_Green",
      "components": {
        "Components": {
          "FarmingBlock": {}
        }
      }
    },
    {
      "x": -10,
      "y": 4,
      "z": 0,
      "name": "Empty"
    },
    {
      "x": -10,
      "y": 5,
      "z": 0,
      "name": "Plant_Moss_Cave_Green_Dark",
      "rotation": 8
    },
    {
      "x": -10,
      "y": 6,
      "z": 0,
      "name": "Rock_Stone"
    },
    {
      "x": -10,
      "y": 7,
      "z": 0,
      "name": "Rock_Stone"
    },
    {
      "x": -10,
      "y": 8,
      "z": 0,
      "name": "Rock_Stone"
    },
    {
      "x": -10,
      "y": 9,
      "z": 0,
      "name": "Rock_Stone"
    },
    {
      "x": -10,
      "y": 0,
      "z": 1,
      "name": "Rock_Stone"
    },
    {
      "x": -10,
      "y": 1,
      "z": 1,
      "name": "Rock_Stone"
    },
    {
      "x": -10,
      "y": 2,
      "z": 1,
      "name": "Block_Spawner_Block",
      "components": {
        "Components": {
          "BlockSpawner": {
            "BlockSpawnerId": "Zone1_Goblin_Tier3"
          }
        }
      },
      "rotation": 1
    },
    {
      "x": -10,
      "y": 3,
      "z": 1,
      "name": "Empty"
    },
    {
      "x": -10,
      "y": 4,
      "z": 1,
      "name": "Empty"
    },
    {
      "x": -10,
      "y": 5,
      "z": 1,
      "name": "Empty"
    },
    {
      "x": -10,
      "y": 6,
      "z": 1,
      "name": "Empty"
    },
    {
      "x": -10,
      "y": 7,
      "z": 1,
      "name": "Empty"
    },
    {
      "x": -10,
      "y": 8,
      "z": 1,
      "name": "Rock_Stone"
    },
    {
      "x": -10,
      "y": 9,
      "z": 1,
      "name": "Rock_Stone"
    },
    {
      "x": -10,
      "y": 0,
      "z": 2,
      "name": "Rock_Stone"
    },
    {
      "x": -10,
      "y": 1,
      "z": 2,
      "name": "Rock_Stone"
    },
    {
      "x": -10,
      "y": 2,
      "z": 2,
      "name": "Rock_Stone"
    },
    {
      "x": -10,
      "y": 3,
      "z": 2,
      "name": "Plant_Moss_Rug_Green_Dark"
    },
    {
      "x": -10,
      "y": 4,
      "z": 2,
      "name": "Empty"
    },
    {
      "x": -10,
      "y": 5,
      "z": 2,
      "name": "Empty"
    },
    {
      "x": -10,
      "y": 6,
      "z": 2,
      "name": "Empty"
    },
    {
      "x": -10,
      "y": 7,
      "z": 2,
      "name": "Plant_Moss_Wall_Green_Dark",
      "rotation": 1
    },
    {
      "x": -10,
      "y": 8,
      "z": 2,
      "name": "Rock_Stone"
    },
    {
      "x": -10,
      "y": 9,
      "z": 2,
      "name": "Rock_Stone"
    },
    {
      "x": -10,
      "y": 0,
      "z": 3,
      "name": "Rock_Stone"
    },
    {
      "x": -10,
      "y": 1,
      "z": 3,
      "name": "Rock_Stone"
    },
    {
      "x": -10,
      "y": 2,
      "z": 3,
      "name": "Rock_Stone"
    },
    {
      "x": -10,
      "y": 3,
      "z": 3,
      "name": "Rock_Stone"
    },
    {
      "x": -10,
      "y": 4,
      "z": 3,
      "name": "Rock_Stone"
    },
    {
      "x": -10,
      "y": 5,
      "z": 3,
      "name": "Empty"
    },
    {
      "x": -10,
      "y": 6,
      "z": 3,
      "name": "Empty"
    },
    {
      "x": -10,
      "y": 7,
      "z": 3,
      "name": "Rock_Stone"
    },
    {
      "x": -10,
      "y": 8,
      "z": 3,
      "name": "Rock_Stone"
    },
    {
      "x": -10,
      "y": 9,
      "z": 3,
      "name": "Rock_Stone"
    },
    {
      "x": -10,
      "y": 0,
      "z": 4,
      "name": "Rock_Stone"
    },
    {
      "x": -10,
      "y": 1,
      "z": 4,
      "name": "Rock_Stone"
    },
    {
      "x": -10,
      "y": 2,
      "z": 4,
      "name": "Rock_Stone"
    },
    {
      "x": -10,
      "y": 3,
      "z": 4,
      "name": "Rock_Stone"
    },
    {
      "x": -10,
      "y": 4,
      "z": 4,
      "name": "Rock_Stone"
    },
    {
      "x": -10,
      "y": 5,
      "z": 4,
      "name": "Rock_Stone"
    },
    {
      "x": -10,
      "y": 6,
      "z": 4,
      "name": "Rock_Stone"
    },
    {
      "x": -10,
      "y": 7,
      "z": 4,
      "name": "Rock_Stone"
    },
    {
      "x": -10,
      "y": 8,
      "z": 4,
      "name": "Rock_Stone"
    },
    {
      "x": -10,
      "y": 9,
      "z": 4,
      "name": "Rock_Stone"
    },
    {
      "x": -10,
      "y": 0,
      "z": 5,
      "name": "Rock_Stone"
    },
    {
      "x": -10,
      "y": 1,
      "z": 5,
      "name": "Rock_Stone"
    },
    {
      "x": -10,
      "y": 2,
      "z": 5,
      "name": "Rock_Stone"
    },
    {
      "x": -10,
      "y": 3,
      "z": 5,
      "name": "Rock_Stone"
    },
    {
      "x": -10,
      "y": 4,
      "z": 5,
      "name": "Rock_Stone"
    },
    {
      "x": -10,
      "y": 5,
      "z": 5,
      "name": "Rock_Stone"
    },
    {
      "x": -10,
      "y": 6,
      "z": 5,
      "name": "Rock_Stone"
    },
    {
      "x": -10,
      "y": 7,
      "z": 5,
      "name": "Rock_Stone"
    },
    {
      "x": -10,
      "y": 8,
      "z": 5,
      "name": "Rock_Stone"
    },
    {
      "x": -10,
      "y": 9,
      "z": 5,
      "name": "Rock_Stone"
    },
    {
      "x": -9,
      "y": 0,
      "z": -5,
      "name": "Rock_Stone"
    },
    {
      "x": -9,
      "y": 1,
      "z": -5,
      "name": "Rock_Stone"
    },
    {
      "x": -9,
      "y": 2,
      "z": -5,
      "name": "Rock_Stone"
    },
    {
      "x": -9,
      "y": 3,
      "z": -5,
      "name": "Rock_Stone"
    },
    {
      "x": -9,
      "y": 4,
      "z": -5,
      "name": "Rock_Stone"
    },
    {
      "x": -9,
      "y": 5,
      "z": -5,
      "name": "Rock_Stone"
    },
    {
      "x": -9,
      "y": 6,
      "z": -5,
      "name": "Rock_Stone"
    },
    {
      "x": -9,
      "y": 7,
      "z": -5,
      "name": "Rock_Stone"
    },
    {
      "x": -9,
      "y": 8,
      "z": -5,
      "name": "Rock_Stone"
    },
    {
      "x": -9,
      "y": 9,
      "z": -5,
      "name": "Rock_Stone"
    },
    {
      "x": -9,
      "y": 0,
      "z": -4,
      "name": "Rock_Stone"
    },
    {
      "x": -9,
      "y": 1,
      "z": -4,
      "name": "Rock_Stone"
    },
    {
      "x": -9,
      "y": 2,
      "z": -4,
      "name": "Rock_Stone"
    },
    {
      "x": -9,
      "y": 3,
      "z": -4,
      "name": "Rock_Stone"
    },
    {
      "x": -9,
      "y": 4,
      "z": -4,
      "name": "Rock_Stone"
    },
    {
      "x": -9,
      "y": 5,
      "z": -4,
      "name": "Rock_Stone"
    },
    {
      "x": -9,
      "y": 6,
      "z": -4,
      "name": "Rock_Stone"
    },
    {
      "x": -9,
      "y": 7,
      "z": -4,
      "name": "Rock_Stone"
    },
    {
      "x": -9,
      "y": 8,
      "z": -4,
      "name": "Rock_Stone"
    },
    {
      "x": -9,
      "y": 9,
      "z": -4,
      "name": "Rock_Stone"
    },
    {
      "x": -9,
      "y": 0,
      "z": -3,
      "name": "Rock_Stone"
    },
    {
      "x": -9,
      "y": 1,
      "z": -3,
      "name": "Rock_Stone"
    },
    {
      "x": -9,
      "y": 2,
      "z": -3,
      "name": "Rock_Stone"
    },
    {
      "x": -9,
      "y": 3,
      "z": -3,
      "name": "Rock_Stone"
    },
    {
      "x": -9,
      "y": 4,
      "z": -3,
      "name": "Empty"
    },
    {
      "x": -9,
      "y": 5,
      "z": -3,
      "name": "Rock_Stone"
    },
    {
      "x": -9,
      "y": 6,
      "z": -3,
      "name": "Rock_Stone"
    },
    {
      "x": -9,
      "y": 7,
      "z": -3,
      "name": "Rock_Stone"
    },
    {
      "x": -9,
      "y": 8,
      "z": -3,
      "name": "Rock_Stone"
    },
    {
      "x": -9,
      "y": 9,
      "z": -3,
      "name": "Rock_Stone"
    },
    {
      "x": -9,
      "y": 0,
      "z": -2,
      "name": "Rock_Stone"
    },
    {
      "x": -9,
      "y": 1,
      "z": -2,
      "name": "Rock_Stone"
    },
    {
      "x": -9,
      "y": 2,
      "z": -2,
      "name": "Rubble_Stone_Medium"
    },
    {
      "x": -9,
      "y": 3,
      "z": -2,
      "name": "Empty"
    },
    {
      "x": -9,
      "y": 4,
      "z": -2,
      "name": "Empty"
    },
    {
      "x": -9,
      "y": 5,
      "z": -2,
      "name": "Plant_Moss_Wall_Green_Dark"
    },
    {
      "x": -9,
      "y": 6,
      "z": -2,
      "name": "Empty"
    },
    {
      "x": -9,
      "y": 7,
      "z": -2,
      "name": "Empty"
    },
    {
      "x": -9,
      "y": 8,
      "z": -2,
      "name": "Rock_Stone"
    },
    {
      "x": -9,
      "y": 9,
      "z": -2,
      "name": "Rock_Stone"
    },
    {
      "x": -9,
      "y": 0,
      "z": -1,
      "name": "Rock_Stone"
    },
    {
      "x": -9,
      "y": 1,
      "z": -1,
      "name": "Rock_Stone"
    },
    {
      "x": -9,
      "y": 2,
      "z": -1,
      "name": "Furniture_Tavern_Barrel"
    },
    {
      "x": -9,
      "y": 3,
      "z": -1,
      "name": "Empty"
    },
    {
      "x": -9,
      "y": 4,
      "z": -1,
      "name": "Empty"
    },
    {
      "x": -9,
      "y": 5,
      "z": -1,
      "name": "Empty"
    },
    {
      "x": -9,
      "y": 6,
      "z": -1,
      "name": "Rock_Stone_Stalactite_Large",
      "filler": 31744,
      "rotation": 8
    },
    {
      "x": -9,
      "y": 7,
      "z": -1,
      "name": "Rock_Stone_Stalactite_Large",
      "rotation": 8
    },
    {
      "x": -9,
      "y": 8,
      "z": -1,
      "name": "Rock_Stone"
    },
    {
      "x": -9,
      "y": 9,
      "z": -1,
      "name": "Rock_Stone"
    },
    {
      "x": -9,
      "y": 0,
      "z": 0,
      "name": "Rock_Stone"
    },
    {
      "x": -9,
      "y": 1,
      "z": 0,
      "name": "Rock_Stone"
    },
    {
      "x": -9,
      "y": 2,
      "z": 0,
      "name": "Empty"
    },
    {
      "x": -9,
      "y": 3,
      "z": 0,
      "name": "Empty"
    },
    {
      "x": -9,
      "y": 4,
      "z": 0,
      "name": "Empty"
    },
    {
      "x": -9,
      "y": 5,
      "z": 0,
      "name": "Empty"
    },
    {
      "x": -9,
      "y": 6,
      "z": 0,
      "name": "Empty"
    },
    {
      "x": -9,
      "y": 7,
      "z": 0,
      "name": "Empty"
    },
    {
      "x": -9,
      "y": 8,
      "z": 0,
      "name": "Empty"
    },
    {
      "x": -9,
      "y": 9,
      "z": 0,
      "name": "Rock_Stone"
    },
    {
      "x": -9,
      "y": 0,
      "z": 1,
      "name": "Rock_Stone"
    },
    {
      "x": -9,
      "y": 1,
      "z": 1,
      "name": "Rock_Stone"
    },
    {
      "x": -9,
      "y": 2,
      "z": 1,
      "name": "Empty"
    },
    {
      "x": -9,
      "y": 3,
      "z": 1,
      "name": "Empty"
    },
    {
      "x": -9,
      "y": 4,
      "z": 1,
      "name": "Empty"
    },
    {
      "x": -9,
      "y": 5,
      "z": 1,
      "name": "Empty"
    },
    {
      "x": -9,
      "y": 6,
      "z": 1,
      "name": "Empty"
    },
    {
      "x": -9,
      "y": 7,
      "z": 1,
      "name": "Rock_Stone_Stalactite_Small",
      "rotation": 8
    },
    {
      "x": -9,
      "y": 8,
      "z": 1,
      "name": "Rock_Stone"
    },
    {
      "x": -9,
      "y": 9,
      "z": 1,
      "name": "Rock_Stone"
    },
    {
      "x": -9,
      "y": 0,
      "z": 2,
      "name": "Rock_Stone"
    },
    {
      "x": -9,
      "y": 1,
      "z": 2,
      "name": "Rock_Stone"
    },
    {
      "x": -9,
      "y": 2,
      "z": 2,
      "name": "Plant_Moss_Rug_Green_Dark"
    },
    {
      "x": -9,
      "y": 3,
      "z": 2,
      "name": "Empty"
    },
    {
      "x": -9,
      "y": 4,
      "z": 2,
      "name": "Empty"
    },
    {
      "x": -9,
      "y": 5,
      "z": 2,
      "name": "Empty"
    },
    {
      "x": -9,
      "y": 6,
      "z": 2,
      "name": "Empty"
    },
    {
      "x": -9,
      "y": 7,
      "z": 2,
      "name": "Empty"
    },
    {
      "x": -9,
      "y": 8,
      "z": 2,
      "name": "Rock_Stone"
    },
    {
      "x": -9,
      "y": 9,
      "z": 2,
      "name": "Rock_Stone"
    },
    {
      "x": -9,
      "y": 0,
      "z": 3,
      "name": "Rock_Stone"
    },
    {
      "x": -9,
      "y": 1,
      "z": 3,
      "name": "Rock_Stone"
    },
    {
      "x": -9,
      "y": 2,
      "z": 3,
      "name": "Plant_Moss_Rug_Green_Dark"
    },
    {
      "x": -9,
      "y": 3,
      "z": 3,
      "name": "Empty"
    },
    {
      "x": -9,
      "y": 4,
      "z": 3,
      "name": "Empty"
    },
    {
      "x": -9,
      "y": 5,
      "z": 3,
      "name": "Empty"
    },
    {
      "x": -9,
      "y": 6,
      "z": 3,
      "name": "Empty"
    },
    {
      "x": -9,
      "y": 7,
      "z": 3,
      "name": "Rock_Stone"
    },
    {
      "x": -9,
      "y": 8,
      "z": 3,
      "name": "Rock_Stone"
    },
    {
      "x": -9,
      "y": 9,
      "z": 3,
      "name": "Rock_Stone"
    },
    {
      "x": -9,
      "y": 0,
      "z": 4,
      "name": "Rock_Stone"
    },
    {
      "x": -9,
      "y": 1,
      "z": 4,
      "name": "Rock_Stone"
    },
    {
      "x": -9,
      "y": 2,
      "z": 4,
      "name": "Rock_Stone"
    },
    {
      "x": -9,
      "y": 3,
      "z": 4,
      "name": "Rock_Stone_Stalactite_Small"
    },
    {
      "x": -9,
      "y": 4,
      "z": 4,
      "name": "Rock_Stone_Stalactite_Large",
      "filler": 31744,
      "rotation": 8
    },
    {
      "x": -9,
      "y": 5,
      "z": 4,
      "name": "Rock_Stone_Stalactite_Large",
      "rotation": 8
    },
    {
      "x": -9,
      "y": 6,
      "z": 4,
      "name": "Rock_Stone"
    },
    {
      "x": -9,
      "y": 7,
      "z": 4,
      "name": "Rock_Stone"
    },
    {
      "x": -9,
      "y": 8,
      "z": 4,
      "name": "Rock_Stone"
    },
    {
      "x": -9,
      "y": 9,
      "z": 4,
      "name": "Rock_Stone"
    },
    {
      "x": -9,
      "y": 0,
      "z": 5,
      "name": "Rock_Stone"
    },
    {
      "x": -9,
      "y": 1,
      "z": 5,
      "name": "Rock_Stone"
    },
    {
      "x": -9,
      "y": 2,
      "z": 5,
      "name": "Rock_Stone"
    },
    {
      "x": -9,
      "y": 3,
      "z": 5,
      "name": "Rock_Stone"
    },
    {
      "x": -9,
      "y": 4,
      "z": 5,
      "name": "Rock_Stone"
    },
    {
      "x": -9,
      "y": 5,
      "z": 5,
      "name": "Rock_Stone"
    },
    {
      "x": -9,
      "y": 6,
      "z": 5,
      "name": "Rock_Stone"
    },
    {
      "x": -9,
      "y": 7,
      "z": 5,
      "name": "Rock_Stone"
    },
    {
      "x": -9,
      "y": 8,
      "z": 5,
      "name": "Rock_Stone"
    },
    {
      "x": -9,
      "y": 9,
      "z": 5,
      "name": "Rock_Stone"
    },
    {
      "x": -8,
      "y": 0,
      "z": -5,
      "name": "Rock_Stone"
    },
    {
      "x": -8,
      "y": 1,
      "z": -5,
      "name": "Rock_Stone"
    },
    {
      "x": -8,
      "y": 2,
      "z": -5,
      "name": "Rock_Stone"
    },
    {
      "x": -8,
      "y": 3,
      "z": -5,
      "name": "Rock_Stone"
    },
    {
      "x": -8,
      "y": 4,
      "z": -5,
      "name": "Rock_Stone"
    },
    {
      "x": -8,
      "y": 5,
      "z": -5,
      "name": "Rock_Stone"
    },
    {
      "x": -8,
      "y": 6,
      "z": -5,
      "name": "Rock_Stone"
    },
    {
      "x": -8,
      "y": 7,
      "z": -5,
      "name": "Rock_Stone"
    },
    {
      "x": -8,
      "y": 8,
      "z": -5,
      "name": "Rock_Stone"
    },
    {
      "x": -8,
      "y": 9,
      "z": -5,
      "name": "Rock_Stone"
    },
    {
      "x": -8,
      "y": 0,
      "z": -4,
      "name": "Rock_Stone"
    },
    {
      "x": -8,
      "y": 1,
      "z": -4,
      "name": "Rock_Stone"
    },
    {
      "x": -8,
      "y": 2,
      "z": -4,
      "name": "Rock_Stone"
    },
    {
      "x": -8,
      "y": 3,
      "z": -4,
      "name": "Rock_Stone"
    },
    {
      "x": -8,
      "y": 4,
      "z": -4,
      "name": "Rock_Stone"
    },
    {
      "x": -8,
      "y": 5,
      "z": -4,
      "name": "Rock_Stone"
    },
    {
      "x": -8,
      "y": 6,
      "z": -4,
      "name": "Rock_Stone"
    },
    {
      "x": -8,
      "y": 7,
      "z": -4,
      "name": "Rock_Stone"
    },
    {
      "x": -8,
      "y": 8,
      "z": -4,
      "name": "Rock_Stone"
    },
    {
      "x": -8,
      "y": 9,
      "z": -4,
      "name": "Rock_Stone"
    },
    {
      "x": -8,
      "y": 0,
      "z": -3,
      "name": "Rock_Stone"
    },
    {
      "x": -8,
      "y": 1,
      "z": -3,
      "name": "Rock_Stone"
    },
    {
      "x": -8,
      "y": 2,
      "z": -3,
      "name": "Rubble_Stone"
    },
    {
      "x": -8,
      "y": 3,
      "z": -3,
      "name": "Empty"
    },
    {
      "x": -8,
      "y": 4,
      "z": -3,
      "name": "Empty"
    },
    {
      "x": -8,
      "y": 5,
      "z": -3,
      "name": "Empty"
    },
    {
      "x": -8,
      "y": 6,
      "z": -3,
      "name": "Empty"
    },
    {
      "x": -8,
      "y": 7,
      "z": -3,
      "name": "Rock_Stone"
    },
    {
      "x": -8,
      "y": 8,
      "z": -3,
      "name": "Rock_Stone"
    },
    {
      "x": -8,
      "y": 9,
      "z": -3,
      "name": "Rock_Stone"
    },
    {
      "x": -8,
      "y": 0,
      "z": -2,
      "name": "Rock_Stone"
    },
    {
      "x": -8,
      "y": 1,
      "z": -2,
      "name": "Rock_Stone"
    },
    {
      "x": -8,
      "y": 2,
      "z": -2,
      "name": "Empty"
    },
    {
      "x": -8,
      "y": 3,
      "z": -2,
      "name": "Empty"
    },
    {
      "x": -8,
      "y": 4,
      "z": -2,
      "name": "Empty"
    },
    {
      "x": -8,
      "y": 5,
      "z": -2,
      "name": "Empty"
    },
    {
      "x": -8,
      "y": 6,
      "z": -2,
      "name": "Empty"
    },
    {
      "x": -8,
      "y": 7,
      "z": -2,
      "name": "Empty"
    },
    {
      "x": -8,
      "y": 8,
      "z": -2,
      "name": "Rock_Stone"
    },
    {
      "x": -8,
      "y": 9,
      "z": -2,
      "name": "Rock_Stone"
    },
    {
      "x": -8,
      "y": 0,
      "z": -1,
      "name": "Rock_Stone"
    },
    {
      "x": -8,
      "y": 1,
      "z": -1,
      "name": "Rock_Stone"
    },
    {
      "x": -8,
      "y": 2,
      "z": -1,
      "name": "Empty"
    },
    {
      "x": -8,
      "y": 3,
      "z": -1,
      "name": "Empty"
    },
    {
      "x": -8,
      "y": 4,
      "z": -1,
      "name": "Empty"
    },
    {
      "x": -8,
      "y": 5,
      "z": -1,
      "name": "Empty"
    },
    {
      "x": -8,
      "y": 6,
      "z": -1,
      "name": "Empty"
    },
    {
      "x": -8,
      "y": 7,
      "z": -1,
      "name": "Empty"
    },
    {
      "x": -8,
      "y": 8,
      "z": -1,
      "name": "Empty"
    },
    {
      "x": -8,
      "y": 9,
      "z": -1,
      "name": "Rock_Stone"
    },
    {
      "x": -8,
      "y": 0,
      "z": 0,
      "name": "Rock_Stone"
    },
    {
      "x": -8,
      "y": 1,
      "z": 0,
      "name": "Deco_Bone_Skulls"
    },
    {
      "x": -8,
      "y": 2,
      "z": 0,
      "name": "Empty"
    },
    {
      "x": -8,
      "y": 3,
      "z": 0,
      "name": "Empty"
    },
    {
      "x": -8,
      "y": 4,
      "z": 0,
      "name": "Empty"
    },
    {
      "x": -8,
      "y": 5,
      "z": 0,
      "name": "Empty"
    },
    {
      "x": -8,
      "y": 6,
      "z": 0,
      "name": "Empty"
    },
    {
      "x": -8,
      "y": 7,
      "z": 0,
      "name": "Empty"
    },
    {
      "x": -8,
      "y": 8,
      "z": 0,
      "name": "Empty"
    },
    {
      "x": -8,
      "y": 9,
      "z": 0,
      "name": "Rock_Stone"
    },
    {
      "x": -8,
      "y": 0,
      "z": 1,
      "name": "Rock_Stone"
    },
    {
      "x": -8,
      "y": 1,
      "z": 1,
      "name": "Deco_Bone_Pile"
    },
    {
      "x": -8,
      "y": 2,
      "z": 1,
      "name": "Empty"
    },
    {
      "x": -8,
      "y": 3,
      "z": 1,
      "name": "Empty"
    },
    {
      "x": -8,
      "y": 4,
      "z": 1,
      "name": "Empty"
    },
    {
      "x": -8,
      "y": 5,
      "z": 1,
      "name": "Empty"
    },
    {
      "x": -8,
      "y": 6,
      "z": 1,
      "name": "Empty"
    },
    {
      "x": -8,
      "y": 7,
      "z": 1,
      "name": "Empty"
    },
    {
      "x": -8,
      "y": 8,
      "z": 1,
      "name": "Empty"
    },
    {
      "x": -8,
      "y": 9,
      "z": 1,
      "name": "Rock_Stone"
    },
    {
      "x": -8,
      "y": 0,
      "z": 2,
      "name": "Rock_Stone"
    },
    {
      "x": -8,
      "y": 1,
      "z": 2,
      "name": "Empty"
    },
    {
      "x": -8,
      "y": 2,
      "z": 2,
      "name": "Empty"
    },
    {
      "x": -8,
      "y": 3,
      "z": 2,
      "name": "Empty"
    },
    {
      "x": -8,
      "y": 4,
      "z": 2,
      "name": "Empty"
    },
    {
      "x": -8,
      "y": 5,
      "z": 2,
      "name": "Empty"
    },
    {
      "x": -8,
      "y": 6,
      "z": 2,
      "name": "Empty"
    },
    {
      "x": -8,
      "y": 7,
      "z": 2,
      "name": "Empty"
    },
    {
      "x": -8,
      "y": 8,
      "z": 2,
      "name": "Rock_Stone"
    },
    {
      "x": -8,
      "y": 9,
      "z": 2,
      "name": "Rock_Stone"
    },
    {
      "x": -8,
      "y": 0,
      "z": 3,
      "name": "Rock_Stone"
    },
    {
      "x": -8,
      "y": 1,
      "z": 3,
      "name": "Rock_Stone"
    },
    {
      "x": -8,
      "y": 2,
      "z": 3,
      "name": "Plant_Moss_Rug_Green_Dark"
    },
    {
      "x": -8,
      "y": 3,
      "z": 3,
      "name": "Empty"
    },
    {
      "x": -8,
      "y": 4,
      "z": 3,
      "name": "Empty"
    },
    {
      "x": -8,
      "y": 5,
      "z": 3,
      "name": "Empty"
    },
    {
      "x": -8,
      "y": 6,
      "z": 3,
      "name": "Empty"
    },
    {
      "x": -8,
      "y": 7,
      "z": 3,
      "name": "Empty"
    },
    {
      "x": -8,
      "y": 8,
      "z": 3,
      "name": "Rock_Stone"
    },
    {
      "x": -8,
      "y": 9,
      "z": 3,
      "name": "Rock_Stone"
    },
    {
      "x": -8,
      "y": 0,
      "z": 4,
      "name": "Rock_Stone"
    },
    {
      "x": -8,
      "y": 1,
      "z": 4,
      "name": "Rock_Stone"
    },
    {
      "x": -8,
      "y": 2,
      "z": 4,
      "name": "Rock_Stone"
    },
    {
      "x": -8,
      "y": 3,
      "z": 4,
      "name": "Plant_Moss_Green_Dark"
    },
    {
      "x": -8,
      "y": 4,
      "z": 4,
      "name": "Empty"
    },
    {
      "x": -8,
      "y": 5,
      "z": 4,
      "name": "Empty"
    },
    {
      "x": -8,
      "y": 6,
      "z": 4,
      "name": "Empty"
    },
    {
      "x": -8,
      "y": 7,
      "z": 4,
      "name": "Rock_Stone"
    },
    {
      "x": -8,
      "y": 8,
      "z": 4,
      "name": "Rock_Stone"
    },
    {
      "x": -8,
      "y": 9,
      "z": 4,
      "name": "Rock_Stone"
    },
    {
      "x": -8,
      "y": 0,
      "z": 5,
      "name": "Rock_Stone"
    },
    {
      "x": -8,
      "y": 1,
      "z": 5,
      "name": "Rock_Stone"
    },
    {
      "x": -8,
      "y": 2,
      "z": 5,
      "name": "Rock_Stone"
    },
    {
      "x": -8,
      "y": 3,
      "z": 5,
      "name": "Rock_Stone"
    },
    {
      "x": -8,
      "y": 4,
      "z": 5,
      "name": "Rock_Stone"
    },
    {
      "x": -8,
      "y": 5,
      "z": 5,
      "name": "Rock_Stone"
    },
    {
      "x": -8,
      "y": 6,
      "z": 5,
      "name": "Rock_Stone"
    },
    {
      "x": -8,
      "y": 7,
      "z": 5,
      "name": "Rock_Stone"
    },
    {
      "x": -8,
      "y": 8,
      "z": 5,
      "name": "Rock_Stone"
    },
    {
      "x": -8,
      "y": 9,
      "z": 5,
      "name": "Rock_Stone"
    },
    {
      "x": -7,
      "y": 0,
      "z": -5,
      "name": "Rock_Stone"
    },
    {
      "x": -7,
      "y": 1,
      "z": -5,
      "name": "Rock_Stone"
    },
    {
      "x": -7,
      "y": 2,
      "z": -5,
      "name": "Rock_Stone"
    },
    {
      "x": -7,
      "y": 3,
      "z": -5,
      "name": "Rock_Stone"
    },
    {
      "x": -7,
      "y": 4,
      "z": -5,
      "name": "Rock_Stone"
    },
    {
      "x": -7,
      "y": 5,
      "z": -5,
      "name": "Rock_Stone"
    },
    {
      "x": -7,
      "y": 6,
      "z": -5,
      "name": "Rock_Stone"
    },
    {
      "x": -7,
      "y": 7,
      "z": -5,
      "name": "Rock_Stone"
    },
    {
      "x": -7,
      "y": 8,
      "z": -5,
      "name": "Rock_Stone"
    },
    {
      "x": -7,
      "y": 9,
      "z": -5,
      "name": "Rock_Stone"
    },
    {
      "x": -7,
      "y": 0,
      "z": -4,
      "name": "Rock_Stone"
    },
    {
      "x": -7,
      "y": 1,
      "z": -4,
      "name": "Rock_Stone"
    },
    {
      "x": -7,
      "y": 2,
      "z": -4,
      "name": "Rock_Stone"
    },
    {
      "x": -7,
      "y": 3,
      "z": -4,
      "name": "Rock_Stone"
    },
    {
      "x": -7,
      "y": 4,
      "z": -4,
      "name": "Rock_Stone"
    },
    {
      "x": -7,
      "y": 5,
      "z": -4,
      "name": "Rock_Stone"
    },
    {
      "x": -7,
      "y": 6,
      "z": -4,
      "name": "Rock_Stone"
    },
    {
      "x": -7,
      "y": 7,
      "z": -4,
      "name": "Rock_Stone"
    },
    {
      "x": -7,
      "y": 8,
      "z": -4,
      "name": "Rock_Stone"
    },
    {
      "x": -7,
      "y": 9,
      "z": -4,
      "name": "Rock_Stone"
    },
    {
      "x": -7,
      "y": 0,
      "z": -3,
      "name": "Rock_Stone"
    },
    {
      "x": -7,
      "y": 1,
      "z": -3,
      "name": "Rock_Stone"
    },
    {
      "x": -7,
      "y": 2,
      "z": -3,
      "name": "Plant_Moss_Green_Dark"
    },
    {
      "x": -7,
      "y": 3,
      "z": -3,
      "name": "Empty"
    },
    {
      "x": -7,
      "y": 4,
      "z": -3,
      "name": "Empty"
    },
    {
      "x": -7,
      "y": 5,
      "z": -3,
      "name": "Empty"
    },
    {
      "x": -7,
      "y": 6,
      "z": -3,
      "name": "Rock_Stone"
    },
    {
      "x": -7,
      "y": 7,
      "z": -3,
      "name": "Rock_Stone"
    },
    {
      "x": -7,
      "y": 8,
      "z": -3,
      "name": "Rock_Stone"
    },
    {
      "x": -7,
      "y": 9,
      "z": -3,
      "name": "Rock_Stone"
    },
    {
      "x": -7,
      "y": 0,
      "z": -2,
      "name": "Rock_Stone"
    },
    {
      "x": -7,
      "y": 1,
      "z": -2,
      "name": "Rock_Stone"
    },
    {
      "x": -7,
      "y": 2,
      "z": -2,
      "name": "Empty"
    },
    {
      "x": -7,
      "y": 3,
      "z": -2,
      "name": "Empty"
    },
    {
      "x": -7,
      "y": 4,
      "z": -2,
      "name": "Empty"
    },
    {
      "x": -7,
      "y": 5,
      "z": -2,
      "name": "Empty"
    },
    {
      "x": -7,
      "y": 6,
      "z": -2,
      "name": "Empty"
    },
    {
      "x": -7,
      "y": 7,
      "z": -2,
      "name": "Rock_Stone"
    },
    {
      "x": -7,
      "y": 8,
      "z": -2,
      "name": "Rock_Stone"
    },
    {
      "x": -7,
      "y": 9,
      "z": -2,
      "name": "Rock_Stone"
    },
    {
      "x": -7,
      "y": 0,
      "z": -1,
      "name": "Rock_Stone"
    },
    {
      "x": -7,
      "y": 1,
      "z": -1,
      "name": "Empty"
    },
    {
      "x": -7,
      "y": 2,
      "z": -1,
      "name": "Empty"
    },
    {
      "x": -7,
      "y": 3,
      "z": -1,
      "name": "Empty"
    },
    {
      "x": -7,
      "y": 4,
      "z": -1,
      "name": "Empty"
    },
    {
      "x": -7,
      "y": 5,
      "z": -1,
      "name": "Empty"
    },
    {
      "x": -7,
      "y": 6,
      "z": -1,
      "name": "Empty"
    },
    {
      "x": -7,
      "y": 7,
      "z": -1,
      "name": "Empty"
    },
    {
      "x": -7,
      "y": 8,
      "z": -1,
      "name": "Empty"
    },
    {
      "x": -7,
      "y": 9,
      "z": -1,
      "name": "Rock_Stone"
    },
    {
      "x": -7,
      "y": 0,
      "z": 0,
      "name": "Rock_Stone"
    },
    {
      "x": -7,
      "y": 1,
      "z": 0,
      "name": "Empty"
    },
    {
      "x": -7,
      "y": 2,
      "z": 0,
      "name": "Empty"
    },
    {
      "x": -7,
      "y": 3,
      "z": 0,
      "name": "Empty"
    },
    {
      "x": -7,
      "y": 4,
      "z": 0,
      "name": "Empty"
    },
    {
      "x": -7,
      "y": 5,
      "z": 0,
      "name": "Empty"
    },
    {
      "x": -7,
      "y": 6,
      "z": 0,
      "name": "Empty"
    },
    {
      "x": -7,
      "y": 7,
      "z": 0,
      "name": "Empty"
    },
    {
      "x": -7,
      "y": 8,
      "z": 0,
      "name": "Empty"
    },
    {
      "x": -7,
      "y": 9,
      "z": 0,
      "name": "Rock_Stone"
    },
    {
      "x": -7,
      "y": 0,
      "z": 1,
      "name": "Rock_Stone"
    },
    {
      "x": -7,
      "y": 1,
      "z": 1,
      "name": "Empty"
    },
    {
      "x": -7,
      "y": 2,
      "z": 1,
      "name": "Empty"
    },
    {
      "x": -7,
      "y": 3,
      "z": 1,
      "name": "Empty"
    },
    {
      "x": -7,
      "y": 4,
      "z": 1,
      "name": "Empty"
    },
    {
      "x": -7,
      "y": 5,
      "z": 1,
      "name": "Empty"
    },
    {
      "x": -7,
      "y": 6,
      "z": 1,
      "name": "Empty"
    },
    {
      "x": -7,
      "y": 7,
      "z": 1,
      "name": "Empty"
    },
    {
      "x": -7,
      "y": 8,
      "z": 1,
      "name": "Empty"
    },
    {
      "x": -7,
      "y": 9,
      "z": 1,
      "name": "Rock_Stone"
    },
    {
      "x": -7,
      "y": 0,
      "z": 2,
      "name": "Rock_Stone"
    },
    {
      "x": -7,
      "y": 1,
      "z": 2,
      "name": "Deco_Pot_Clay_Broken"
    },
    {
      "x": -7,
      "y": 2,
      "z": 2,
      "name": "Empty"
    },
    {
      "x": -7,
      "y": 3,
      "z": 2,
      "name": "Empty"
    },
    {
      "x": -7,
      "y": 4,
      "z": 2,
      "name": "Empty"
    },
    {
      "x": -7,
      "y": 5,
      "z": 2,
      "name": "Empty"
    },
    {
      "x": -7,
      "y": 6,
      "z": 2,
      "name": "Empty"
    },
    {
      "x": -7,
      "y": 7,
      "z": 2,
      "name": "Empty"
    },
    {
      "x": -7,
      "y": 8,
      "z": 2,
      "name": "Empty"
    },
    {
      "x": -7,
      "y": 9,
      "z": 2,
      "name": "Rock_Stone"
    },
    {
      "x": -7,
      "y": 0,
      "z": 3,
      "name": "Rock_Stone"
    },
    {
      "x": -7,
      "y": 1,
      "z": 3,
      "name": "Empty"
    },
    {
      "x": -7,
      "y": 2,
      "z": 3,
      "name": "Empty"
    },
    {
      "x": -7,
      "y": 3,
      "z": 3,
      "name": "Empty"
    },
    {
      "x": -7,
      "y": 4,
      "z": 3,
      "name": "Empty"
    },
    {
      "x": -7,
      "y": 5,
      "z": 3,
      "name": "Empty"
    },
    {
      "x": -7,
      "y": 6,
      "z": 3,
      "name": "Empty"
    },
    {
      "x": -7,
      "y": 7,
      "z": 3,
      "name": "Plant_Moss_Cave_Green_Dark",
      "rotation": 8
    },
    {
      "x": -7,
      "y": 8,
      "z": 3,
      "name": "Rock_Stone"
    },
    {
      "x": -7,
      "y": 9,
      "z": 3,
      "name": "Rock_Stone"
    },
    {
      "x": -7,
      "y": 0,
      "z": 4,
      "name": "Rock_Stone"
    },
    {
      "x": -7,
      "y": 1,
      "z": 4,
      "name": "Rock_Stone"
    },
    {
      "x": -7,
      "y": 2,
      "z": 4,
      "name": "Furniture_Tavern_Barrel"
    },
    {
      "x": -7,
      "y": 3,
      "z": 4,
      "name": "Empty"
    },
    {
      "x": -7,
      "y": 4,
      "z": 4,
      "name": "Empty"
    },
    {
      "x": -7,
      "y": 5,
      "z": 4,
      "name": "Rock_Stone"
    },
    {
      "x": -7,
      "y": 6,
      "z": 4,
      "name": "Rock_Stone"
    },
    {
      "x": -7,
      "y": 7,
      "z": 4,
      "name": "Rock_Stone"
    },
    {
      "x": -7,
      "y": 8,
      "z": 4,
      "name": "Rock_Stone"
    },
    {
      "x": -7,
      "y": 9,
      "z": 4,
      "name": "Rock_Stone"
    },
    {
      "x": -7,
      "y": 0,
      "z": 5,
      "name": "Rock_Stone"
    },
    {
      "x": -7,
      "y": 1,
      "z": 5,
      "name": "Rock_Stone"
    },
    {
      "x": -7,
      "y": 2,
      "z": 5,
      "name": "Rock_Stone"
    },
    {
      "x": -7,
      "y": 3,
      "z": 5,
      "name": "Rock_Stone"
    },
    {
      "x": -7,
      "y": 4,
      "z": 5,
      "name": "Rock_Stone"
    },
    {
      "x": -7,
      "y": 5,
      "z": 5,
      "name": "Rock_Stone"
    },
    {
      "x": -7,
      "y": 6,
      "z": 5,
      "name": "Rock_Stone"
    },
    {
      "x": -7,
      "y": 7,
      "z": 5,
      "name": "Rock_Stone"
    },
    {
      "x": -7,
      "y": 8,
      "z": 5,
      "name": "Rock_Stone"
    },
    {
      "x": -7,
      "y": 9,
      "z": 5,
      "name": "Rock_Stone"
    },
    {
      "x": -6,
      "y": 0,
      "z": -5,
      "name": "Rock_Stone"
    },
    {
      "x": -6,
      "y": 1,
      "z": -5,
      "name": "Rock_Stone"
    },
    {
      "x": -6,
      "y": 2,
      "z": -5,
      "name": "Rock_Stone"
    },
    {
      "x": -6,
      "y": 3,
      "z": -5,
      "name": "Rock_Stone"
    },
    {
      "x": -6,
      "y": 4,
      "z": -5,
      "name": "Rock_Stone"
    },
    {
      "x": -6,
      "y": 5,
      "z": -5,
      "name": "Rock_Stone"
    },
    {
      "x": -6,
      "y": 6,
      "z": -5,
      "name": "Rock_Stone"
    },
    {
      "x": -6,
      "y": 7,
      "z": -5,
      "name": "Rock_Stone"
    },
    {
      "x": -6,
      "y": 8,
      "z": -5,
      "name": "Rock_Stone"
    },
    {
      "x": -6,
      "y": 9,
      "z": -5,
      "name": "Rock_Stone"
    },
    {
      "x": -6,
      "y": 0,
      "z": -4,
      "name": "Rock_Stone"
    },
    {
      "x": -6,
      "y": 1,
      "z": -4,
      "name": "Rock_Stone"
    },
    {
      "x": -6,
      "y": 2,
      "z": -4,
      "name": "Rock_Stone"
    },
    {
      "x": -6,
      "y": 3,
      "z": -4,
      "name": "Rock_Stone"
    },
    {
      "x": -6,
      "y": 4,
      "z": -4,
      "name": "Rock_Stone"
    },
    {
      "x": -6,
      "y": 5,
      "z": -4,
      "name": "Rock_Stone"
    },
    {
      "x": -6,
      "y": 6,
      "z": -4,
      "name": "Rock_Stone"
    },
    {
      "x": -6,
      "y": 7,
      "z": -4,
      "name": "Rock_Stone"
    },
    {
      "x": -6,
      "y": 8,
      "z": -4,
      "name": "Rock_Stone"
    },
    {
      "x": -6,
      "y": 9,
      "z": -4,
      "name": "Rock_Stone"
    },
    {
      "x": -6,
      "y": 0,
      "z": -3,
      "name": "Rock_Stone"
    },
    {
      "x": -6,
      "y": 1,
      "z": -3,
      "name": "Rock_Stone"
    },
    {
      "x": -6,
      "y": 2,
      "z": -3,
      "name": "Rock_Stone"
    },
    {
      "x": -6,
      "y": 3,
      "z": -3,
      "name": "Rock_Stone"
    },
    {
      "x": -6,
      "y": 4,
      "z": -3,
      "name": "Rock_Stone"
    },
    {
      "x": -6,
      "y": 5,
      "z": -3,
      "name": "Empty"
    },
    {
      "x": -6,
      "y": 6,
      "z": -3,
      "name": "Rock_Stone"
    },
    {
      "x": -6,
      "y": 7,
      "z": -3,
      "name": "Rock_Stone"
    },
    {
      "x": -6,
      "y": 8,
      "z": -3,
      "name": "Rock_Stone"
    },
    {
      "x": -6,
      "y": 9,
      "z": -3,
      "name": "Rock_Stone"
    },
    {
      "x": -6,
      "y": 0,
      "z": -2,
      "name": "Rock_Stone"
    },
    {
      "x": -6,
      "y": 1,
      "z": -2,
      "name": "Rock_Stone"
    },
    {
      "x": -6,
      "y": 2,
      "z": -2,
      "name": "Rock_Stone_Stalactite_Small"
    },
    {
      "x": -6,
      "y": 3,
      "z": -2,
      "name": "Empty"
    },
    {
      "x": -6,
      "y": 4,
      "z": -2,
      "name": "Empty"
    },
    {
      "x": -6,
      "y": 5,
      "z": -2,
      "name": "Empty"
    },
    {
      "x": -6,
      "y": 6,
      "z": -2,
      "name": "Empty"
    },
    {
      "x": -6,
      "y": 7,
      "z": -2,
      "name": "Rock_Stone"
    },
    {
      "x": -6,
      "y": 8,
      "z": -2,
      "name": "Rock_Stone"
    },
    {
      "x": -6,
      "y": 9,
      "z": -2,
      "name": "Rock_Stone"
    },
    {
      "x": -6,
      "y": 0,
      "z": -1,
      "name": "Rock_Stone"
    },
    {
      "x": -6,
      "y": 1,
      "z": -1,
      "name": "Empty"
    },
    {
      "x": -6,
      "y": 2,
      "z": -1,
      "name": "Empty"
    },
    {
      "x": -6,
      "y": 3,
      "z": -1,
      "name": "Empty"
    },
    {
      "x": -6,
      "y": 4,
      "z": -1,
      "name": "Empty"
    },
    {
      "x": -6,
      "y": 5,
      "z": -1,
      "name": "Empty"
    },
    {
      "x": -6,
      "y": 6,
      "z": -1,
      "name": "Empty"
    },
    {
      "x": -6,
      "y": 7,
      "z": -1,
      "name": "Rock_Stone"
    },
    {
      "x": -6,
      "y": 8,
      "z": -1,
      "name": "Rock_Stone"
    },
    {
      "x": -6,
      "y": 9,
      "z": -1,
      "name": "Rock_Stone"
    },
    {
      "x": -6,
      "y": 0,
      "z": 0,
      "name": "Rock_Stone"
    },
    {
      "x": -6,
      "y": 1,
      "z": 0,
      "name": "Empty"
    },
    {
      "x": -6,
      "y": 2,
      "z": 0,
      "name": "Empty"
    },
    {
      "x": -6,
      "y": 3,
      "z": 0,
      "name": "Empty"
    },
    {
      "x": -6,
      "y": 4,
      "z": 0,
      "name": "Empty"
    },
    {
      "x": -6,
      "y": 5,
      "z": 0,
      "name": "Empty"
    },
    {
      "x": -6,
      "y": 6,
      "z": 0,
      "name": "Empty"
    },
    {
      "x": -6,
      "y": 7,
      "z": 0,
      "name": "Empty"
    },
    {
      "x": -6,
      "y": 8,
      "z": 0,
      "name": "Rock_Stone"
    },
    {
      "x": -6,
      "y": 9,
      "z": 0,
      "name": "Rock_Stone"
    },
    {
      "x": -6,
      "y": 0,
      "z": 1,
      "name": "Rock_Stone"
    },
    {
      "x": -6,
      "y": 1,
      "z": 1,
      "name": "Empty"
    },
    {
      "x": -6,
      "y": 2,
      "z": 1,
      "name": "Empty"
    },
    {
      "x": -6,
      "y": 3,
      "z": 1,
      "name": "Empty"
    },
    {
      "x": -6,
      "y": 4,
      "z": 1,
      "name": "Empty"
    },
    {
      "x": -6,
      "y": 5,
      "z": 1,
      "name": "Empty"
    },
    {
      "x": -6,
      "y": 6,
      "z": 1,
      "name": "Empty"
    },
    {
      "x": -6,
      "y": 7,
      "z": 1,
      "name": "Empty"
    },
    {
      "x": -6,
      "y": 8,
      "z": 1,
      "name": "Empty"
    },
    {
      "x": -6,
      "y": 9,
      "z": 1,
      "name": "Rock_Stone"
    },
    {
      "x": -6,
      "y": 0,
      "z": 2,
      "name": "Rock_Stone"
    },
    {
      "x": -6,
      "y": 1,
      "z": 2,
      "name": "Empty"
    },
    {
      "x": -6,
      "y": 2,
      "z": 2,
      "name": "Empty"
    },
    {
      "x": -6,
      "y": 3,
      "z": 2,
      "name": "Empty"
    },
    {
      "x": -6,
      "y": 4,
      "z": 2,
      "name": "Empty"
    },
    {
      "x": -6,
      "y": 5,
      "z": 2,
      "name": "Empty"
    },
    {
      "x": -6,
      "y": 6,
      "z": 2,
      "name": "Empty"
    },
    {
      "x": -6,
      "y": 7,
      "z": 2,
      "name": "Empty"
    },
    {
      "x": -6,
      "y": 8,
      "z": 2,
      "name": "Empty"
    },
    {
      "x": -6,
      "y": 9,
      "z": 2,
      "name": "Rock_Stone"
    },
    {
      "x": -6,
      "y": 0,
      "z": 3,
      "name": "Rock_Stone"
    },
    {
      "x": -6,
      "y": 1,
      "z": 3,
      "name": "Rock_Stone"
    },
    {
      "x": -6,
      "y": 2,
      "z": 3,
      "name": "Empty"
    },
    {
      "x": -6,
      "y": 3,
      "z": 3,
      "name": "Empty"
    },
    {
      "x": -6,
      "y": 4,
      "z": 3,
      "name": "Empty"
    },
    {
      "x": -6,
      "y": 5,
      "z": 3,
      "name": "Empty"
    },
    {
      "x": -6,
      "y": 6,
      "z": 3,
      "name": "Empty"
    },
    {
      "x": -6,
      "y": 7,
      "z": 3,
      "name": "Empty"
    },
    {
      "x": -6,
      "y": 8,
      "z": 3,
      "name": "Empty"
    },
    {
      "x": -6,
      "y": 9,
      "z": 3,
      "name": "Rock_Stone"
    },
    {
      "x": -6,
      "y": 0,
      "z": 4,
      "name": "Rock_Stone"
    },
    {
      "x": -6,
      "y": 1,
      "z": 4,
      "name": "Rock_Stone"
    },
    {
      "x": -6,
      "y": 2,
      "z": 4,
      "name": "Rock_Stone"
    },
    {
      "x": -6,
      "y": 3,
      "z": 4,
      "name": "Rock_Stone"
    },
    {
      "x": -6,
      "y": 4,
      "z": 4,
      "name": "Rock_Stone"
    },
    {
      "x": -6,
      "y": 5,
      "z": 4,
      "name": "Rock_Stone"
    },
    {
      "x": -6,
      "y": 6,
      "z": 4,
      "name": "Rock_Stone"
    },
    {
      "x": -6,
      "y": 7,
      "z": 4,
      "name": "Rock_Stone"
    },
    {
      "x": -6,
      "y": 8,
      "z": 4,
      "name": "Rock_Stone"
    },
    {
      "x": -6,
      "y": 9,
      "z": 4,
      "name": "Rock_Stone"
    },
    {
      "x": -6,
      "y": 0,
      "z": 5,
      "name": "Rock_Stone"
    },
    {
      "x": -6,
      "y": 1,
      "z": 5,
      "name": "Rock_Stone"
    },
    {
      "x": -6,
      "y": 2,
      "z": 5,
      "name": "Rock_Stone"
    },
    {
      "x": -6,
      "y": 3,
      "z": 5,
      "name": "Rock_Stone"
    },
    {
      "x": -6,
      "y": 4,
      "z": 5,
      "name": "Rock_Stone"
    },
    {
      "x": -6,
      "y": 5,
      "z": 5,
      "name": "Rock_Stone"
    },
    {
      "x": -6,
      "y": 6,
      "z": 5,
      "name": "Rock_Stone"
    },
    {
      "x": -6,
      "y": 7,
      "z": 5,
      "name": "Rock_Stone"
    },
    {
      "x": -6,
      "y": 8,
      "z": 5,
      "name": "Rock_Stone"
    },
    {
      "x": -6,
      "y": 9,
      "z": 5,
      "name": "Rock_Stone"
    },
    {
      "x": -5,
      "y": 0,
      "z": -5,
      "name": "Rock_Stone"
    },
    {
      "x": -5,
      "y": 1,
      "z": -5,
      "name": "Rock_Stone"
    },
    {
      "x": -5,
      "y": 2,
      "z": -5,
      "name": "Rock_Stone"
    },
    {
      "x": -5,
      "y": 3,
      "z": -5,
      "name": "Rock_Stone"
    },
    {
      "x": -5,
      "y": 4,
      "z": -5,
      "name": "Rock_Stone"
    },
    {
      "x": -5,
      "y": 5,
      "z": -5,
      "name": "Rock_Stone"
    },
    {
      "x": -5,
      "y": 6,
      "z": -5,
      "name": "Rock_Stone"
    },
    {
      "x": -5,
      "y": 7,
      "z": -5,
      "name": "Rock_Stone"
    },
    {
      "x": -5,
      "y": 8,
      "z": -5,
      "name": "Rock_Stone"
    },
    {
      "x": -5,
      "y": 9,
      "z": -5,
      "name": "Rock_Stone"
    },
    {
      "x": -5,
      "y": 0,
      "z": -4,
      "name": "Rock_Stone"
    },
    {
      "x": -5,
      "y": 1,
      "z": -4,
      "name": "Rock_Stone"
    },
    {
      "x": -5,
      "y": 2,
      "z": -4,
      "name": "Rock_Stone"
    },
    {
      "x": -5,
      "y": 3,
      "z": -4,
      "name": "Rock_Stone"
    },
    {
      "x": -5,
      "y": 4,
      "z": -4,
      "name": "Rock_Stone"
    },
    {
      "x": -5,
      "y": 5,
      "z": -4,
      "name": "Rock_Stone"
    },
    {
      "x": -5,
      "y": 6,
      "z": -4,
      "name": "Rock_Stone"
    },
    {
      "x": -5,
      "y": 7,
      "z": -4,
      "name": "Rock_Stone"
    },
    {
      "x": -5,
      "y": 8,
      "z": -4,
      "name": "Rock_Stone"
    },
    {
      "x": -5,
      "y": 9,
      "z": -4,
      "name": "Rock_Stone"
    },
    {
      "x": -5,
      "y": 0,
      "z": -3,
      "name": "Rock_Stone"
    },
    {
      "x": -5,
      "y": 1,
      "z": -3,
      "name": "Rock_Stone"
    },
    {
      "x": -5,
      "y": 2,
      "z": -3,
      "name": "Rock_Stone"
    },
    {
      "x": -5,
      "y": 3,
      "z": -3,
      "name": "Rock_Stone"
    },
    {
      "x": -5,
      "y": 4,
      "z": -3,
      "name": "Rock_Stone"
    },
    {
      "x": -5,
      "y": 5,
      "z": -3,
      "name": "Rock_Stone"
    },
    {
      "x": -5,
      "y": 6,
      "z": -3,
      "name": "Rock_Stone"
    },
    {
      "x": -5,
      "y": 7,
      "z": -3,
      "name": "Rock_Stone"
    },
    {
      "x": -5,
      "y": 8,
      "z": -3,
      "name": "Rock_Stone"
    },
    {
      "x": -5,
      "y": 9,
      "z": -3,
      "name": "Rock_Stone"
    },
    {
      "x": -5,
      "y": 0,
      "z": -2,
      "name": "Rock_Stone"
    },
    {
      "x": -5,
      "y": 1,
      "z": -2,
      "name": "Rock_Stone"
    },
    {
      "x": -5,
      "y": 2,
      "z": -2,
      "name": "Rock_Stone"
    },
    {
      "x": -5,
      "y": 3,
      "z": -2,
      "name": "Rock_Stone"
    },
    {
      "x": -5,
      "y": 4,
      "z": -2,
      "name": "Plant_Moss_Rug_Green_Dark"
    },
    {
      "x": -5,
      "y": 5,
      "z": -2,
      "name": "Rock_Stone"
    },
    {
      "x": -5,
      "y": 6,
      "z": -2,
      "name": "Rock_Stone"
    },
    {
      "x": -5,
      "y": 7,
      "z": -2,
      "name": "Rock_Stone"
    },
    {
      "x": -5,
      "y": 8,
      "z": -2,
      "name": "Rock_Stone"
    },
    {
      "x": -5,
      "y": 9,
      "z": -2,
      "name": "Rock_Stone"
    },
    {
      "x": -5,
      "y": 0,
      "z": -1,
      "name": "Rock_Stone"
    },
    {
      "x": -5,
      "y": 1,
      "z": -1,
      "name": "Rock_Stone"
    },
    {
      "x": -5,
      "y": 2,
      "z": -1,
      "name": "Rock_Stone"
    },
    {
      "x": -5,
      "y": 3,
      "z": -1,
      "name": "Plant_Moss_Rug_Green_Dark"
    },
    {
      "x": -5,
      "y": 4,
      "z": -1,
      "name": "Empty"
    },
    {
      "x": -5,
      "y": 5,
      "z": -1,
      "name": "Empty"
    },
    {
      "x": -5,
      "y": 6,
      "z": -1,
      "name": "Rock_Stone"
    },
    {
      "x": -5,
      "y": 7,
      "z": -1,
      "name": "Rock_Stone"
    },
    {
      "x": -5,
      "y": 8,
      "z": -1,
      "name": "Rock_Stone"
    },
    {
      "x": -5,
      "y": 9,
      "z": -1,
      "name": "Rock_Stone"
    },
    {
      "x": -5,
      "y": 0,
      "z": 0,
      "name": "Rock_Stone"
    },
    {
      "x": -5,
      "y": 1,
      "z": 0,
      "name": "Rock_Stone"
    },
    {
      "x": -5,
      "y": 2,
      "z": 0,
      "name": "Rock_Stone"
    },
    {
      "x": -5,
      "y": 3,
      "z": 0,
      "name": "Empty"
    },
    {
      "x": -5,
      "y": 4,
      "z": 0,
      "name": "Rock_Stone_Stalactite_Large",
      "filler": 31744,
      "rotation": 8
    },
    {
      "x": -5,
      "y": 5,
      "z": 0,
      "name": "Rock_Stone_Stalactite_Large",
      "rotation": 8
    },
    {
      "x": -5,
      "y": 6,
      "z": 0,
      "name": "Rock_Stone"
    },
    {
      "x": -5,
      "y": 7,
      "z": 0,
      "name": "Rock_Stone"
    },
    {
      "x": -5,
      "y": 8,
      "z": 0,
      "name": "Rock_Stone"
    },
    {
      "x": -5,
      "y": 9,
      "z": 0,
      "name": "Rock_Stone"
    },
    {
      "x": -5,
      "y": 0,
      "z": 1,
      "name": "Rock_Stone"
    },
    {
      "x": -5,
      "y": 1,
      "z": 1,
      "name": "Empty"
    },
    {
      "x": -5,
      "y": 2,
      "z": 1,
      "name": "Empty"
    },
    {
      "x": -5,
      "y": 3,
      "z": 1,
      "name": "Empty"
    },
    {
      "x": -5,
      "y": 4,
      "z": 1,
      "name": "Empty"
    },
    {
      "x": -5,
      "y": 5,
      "z": 1,
      "name": "Empty"
    },
    {
      "x": -5,
      "y": 6,
      "z": 1,
      "name": "Empty"
    },
    {
      "x": -5,
      "y": 7,
      "z": 1,
      "name": "Rock_Stone"
    },
    {
      "x": -5,
      "y": 8,
      "z": 1,
      "name": "Rock_Stone"
    },
    {
      "x": -5,
      "y": 9,
      "z": 1,
      "name": "Rock_Stone"
    },
    {
      "x": -5,
      "y": 0,
      "z": 2,
      "name": "Rock_Stone"
    },
    {
      "x": -5,
      "y": 1,
      "z": 2,
      "name": "Rubble_Stone_Medium"
    },
    {
      "x": -5,
      "y": 2,
      "z": 2,
      "name": "Empty"
    },
    {
      "x": -5,
      "y": 3,
      "z": 2,
      "name": "Empty"
    },
    {
      "x": -5,
      "y": 4,
      "z": 2,
      "name": "Empty"
    },
    {
      "x": -5,
      "y": 5,
      "z": 2,
      "name": "Empty"
    },
    {
      "x": -5,
      "y": 6,
      "z": 2,
      "name": "Empty"
    },
    {
      "x": -5,
      "y": 7,
      "z": 2,
      "name": "Empty"
    },
    {
      "x": -5,
      "y": 8,
      "z": 2,
      "name": "Rock_Stone"
    },
    {
      "x": -5,
      "y": 9,
      "z": 2,
      "name": "Rock_Stone"
    },
    {
      "x": -5,
      "y": 0,
      "z": 3,
      "name": "Rock_Stone"
    },
    {
      "x": -5,
      "y": 1,
      "z": 3,
      "name": "Rock_Stone"
    },
    {
      "x": -5,
      "y": 2,
      "z": 3,
      "name": "Rock_Stone"
    },
    {
      "x": -5,
      "y": 3,
      "z": 3,
      "name": "Rock_Stone"
    },
    {
      "x": -5,
      "y": 4,
      "z": 3,
      "name": "Rock_Stone"
    },
    {
      "x": -5,
      "y": 5,
      "z": 3,
      "name": "Empty"
    },
    {
      "x": -5,
      "y": 6,
      "z": 3,
      "name": "Rock_Stone"
    },
    {
      "x": -5,
      "y": 7,
      "z": 3,
      "name": "Rock_Stone"
    },
    {
      "x": -5,
      "y": 8,
      "z": 3,
      "name": "Rock_Stone"
    },
    {
      "x": -5,
      "y": 9,
      "z": 3,
      "name": "Rock_Stone"
    },
    {
      "x": -5,
      "y": 0,
      "z": 4,
      "name": "Rock_Stone"
    },
    {
      "x": -5,
      "y": 1,
      "z": 4,
      "name": "Rock_Stone"
    },
    {
      "x": -5,
      "y": 2,
      "z": 4,
      "name": "Rock_Stone"
    },
    {
      "x": -5,
      "y": 3,
      "z": 4,
      "name": "Rock_Stone"
    },
    {
      "x": -5,
      "y": 4,
      "z": 4,
      "name": "Rock_Stone"
    },
    {
      "x": -5,
      "y": 5,
      "z": 4,
      "name": "Rock_Stone"
    },
    {
      "x": -5,
      "y": 6,
      "z": 4,
      "name": "Rock_Stone"
    },
    {
      "x": -5,
      "y": 7,
      "z": 4,
      "name": "Rock_Stone"
    },
    {
      "x": -5,
      "y": 8,
      "z": 4,
      "name": "Rock_Stone"
    },
    {
      "x": -5,
      "y": 9,
      "z": 4,
      "name": "Rock_Stone"
    },
    {
      "x": -5,
      "y": 0,
      "z": 5,
      "name": "Rock_Stone"
    },
    {
      "x": -5,
      "y": 1,
      "z": 5,
      "name": "Rock_Stone"
    },
    {
      "x": -5,
      "y": 2,
      "z": 5,
      "name": "Rock_Stone"
    },
    {
      "x": -5,
      "y": 3,
      "z": 5,
      "name": "Rock_Stone"
    },
    {
      "x": -5,
      "y": 4,
      "z": 5,
      "name": "Rock_Stone"
    },
    {
      "x": -5,
      "y": 5,
      "z": 5,
      "name": "Rock_Stone"
    },
    {
      "x": -5,
      "y": 6,
      "z": 5,
      "name": "Rock_Stone"
    },
    {
      "x": -5,
      "y": 7,
      "z": 5,
      "name": "Rock_Stone"
    },
    {
      "x": -5,
      "y": 8,
      "z": 5,
      "name": "Rock_Stone"
    },
    {
      "x": -5,
      "y": 9,
      "z": 5,
      "name": "Rock_Stone"
    },
    {
      "x": -4,
      "y": 0,
      "z": -5,
      "name": "Rock_Stone"
    },
    {
      "x": -4,
      "y": 1,
      "z": -5,
      "name": "Rock_Stone"
    },
    {
      "x": -4,
      "y": 2,
      "z": -5,
      "name": "Rock_Stone"
    },
    {
      "x": -4,
      "y": 3,
      "z": -5,
      "name": "Rock_Stone"
    },
    {
      "x": -4,
      "y": 4,
      "z": -5,
      "name": "Rock_Stone"
    },
    {
      "x": -4,
      "y": 5,
      "z": -5,
      "name": "Rock_Stone"
    },
    {
      "x": -4,
      "y": 6,
      "z": -5,
      "name": "Rock_Stone"
    },
    {
      "x": -4,
      "y": 7,
      "z": -5,
      "name": "Rock_Stone"
    },
    {
      "x": -4,
      "y": 8,
      "z": -5,
      "name": "Rock_Stone"
    },
    {
      "x": -4,
      "y": 9,
      "z": -5,
      "name": "Rock_Stone"
    },
    {
      "x": -4,
      "y": 0,
      "z": -4,
      "name": "Rock_Stone"
    },
    {
      "x": -4,
      "y": 1,
      "z": -4,
      "name": "Rock_Stone"
    },
    {
      "x": -4,
      "y": 2,
      "z": -4,
      "name": "Rock_Stone"
    },
    {
      "x": -4,
      "y": 3,
      "z": -4,
      "name": "Rock_Stone"
    },
    {
      "x": -4,
      "y": 4,
      "z": -4,
      "name": "Rock_Stone"
    },
    {
      "x": -4,
      "y": 5,
      "z": -4,
      "name": "Rock_Stone"
    },
    {
      "x": -4,
      "y": 6,
      "z": -4,
      "name": "Rock_Stone"
    },
    {
      "x": -4,
      "y": 7,
      "z": -4,
      "name": "Rock_Stone"
    },
    {
      "x": -4,
      "y": 8,
      "z": -4,
      "name": "Rock_Stone"
    },
    {
      "x": -4,
      "y": 9,
      "z": -4,
      "name": "Rock_Stone"
    },
    {
      "x": -4,
      "y": 0,
      "z": -3,
      "name": "Rock_Stone"
    },
    {
      "x": -4,
      "y": 1,
      "z": -3,
      "name": "Rock_Stone"
    },
    {
      "x": -4,
      "y": 2,
      "z": -3,
      "name": "Rock_Stone"
    },
    {
      "x": -4,
      "y": 3,
      "z": -3,
      "name": "Rock_Stone"
    },
    {
      "x": -4,
      "y": 4,
      "z": -3,
      "name": "Rock_Stone"
    },
    {
      "x": -4,
      "y": 5,
      "z": -3,
      "name": "Rock_Stone"
    },
    {
      "x": -4,
      "y": 6,
      "z": -3,
      "name": "Rock_Stone"
    },
    {
      "x": -4,
      "y": 7,
      "z": -3,
      "name": "Rock_Stone"
    },
    {
      "x": -4,
      "y": 8,
      "z": -3,
      "name": "Rock_Stone"
    },
    {
      "x": -4,
      "y": 9,
      "z": -3,
      "name": "Rock_Stone"
    },
    {
      "x": -4,
      "y": 0,
      "z": -2,
      "name": "Rock_Stone"
    },
    {
      "x": -4,
      "y": 1,
      "z": -2,
      "name": "Rock_Stone"
    },
    {
      "x": -4,
      "y": 2,
      "z": -2,
      "name": "Rock_Stone"
    },
    {
      "x": -4,
      "y": 3,
      "z": -2,
      "name": "Rock_Stone"
    },
    {
      "x": -4,
      "y": 4,
      "z": -2,
      "name": "Rock_Stone"
    },
    {
      "x": -4,
      "y": 5,
      "z": -2,
      "name": "Rock_Stone"
    },
    {
      "x": -4,
      "y": 6,
      "z": -2,
      "name": "Rock_Stone"
    },
    {
      "x": -4,
      "y": 7,
      "z": -2,
      "name": "Rock_Stone"
    },
    {
      "x": -4,
      "y": 8,
      "z": -2,
      "name": "Rock_Stone"
    },
    {
      "x": -4,
      "y": 9,
      "z": -2,
      "name": "Rock_Stone"
    },
    {
      "x": -4,
      "y": 0,
      "z": -1,
      "name": "Rock_Stone"
    },
    {
      "x": -4,
      "y": 1,
      "z": -1,
      "name": "Rock_Stone"
    },
    {
      "x": -4,
      "y": 2,
      "z": -1,
      "name": "Rock_Stone"
    },
    {
      "x": -4,
      "y": 3,
      "z": -1,
      "name": "Rock_Stone"
    },
    {
      "x": -4,
      "y": 4,
      "z": -1,
      "name": "Rock_Stone"
    },
    {
      "x": -4,
      "y": 5,
      "z": -1,
      "name": "Rock_Stone"
    },
    {
      "x": -4,
      "y": 6,
      "z": -1,
      "name": "Rock_Stone"
    },
    {
      "x": -4,
      "y": 7,
      "z": -1,
      "name": "Rock_Stone"
    },
    {
      "x": -4,
      "y": 8,
      "z": -1,
      "name": "Rock_Stone"
    },
    {
      "x": -4,
      "y": 9,
      "z": -1,
      "name": "Rock_Stone"
    },
    {
      "x": -4,
      "y": 0,
      "z": 0,
      "name": "Rock_Stone"
    },
    {
      "x": -4,
      "y": 1,
      "z": 0,
      "name": "Rock_Stone"
    },
    {
      "x": -4,
      "y": 2,
      "z": 0,
      "name": "Rock_Stone"
    },
    {
      "x": -4,
      "y": 3,
      "z": 0,
      "name": "Rock_Stone_Mossy"
    },
    {
      "x": -4,
      "y": 4,
      "z": 0,
      "name": "Rock_Stone_Mossy"
    },
    {
      "x": -4,
      "y": 5,
      "z": 0,
      "name": "Rock_Stone"
    },
    {
      "x": -4,
      "y": 6,
      "z": 0,
      "name": "Rock_Stone"
    },
    {
      "x": -4,
      "y": 7,
      "z": 0,
      "name": "Rock_Stone"
    },
    {
      "x": -4,
      "y": 8,
      "z": 0,
      "name": "Rock_Stone"
    },
    {
      "x": -4,
      "y": 9,
      "z": 0,
      "name": "Rock_Stone"
    },
    {
      "x": -4,
      "y": 0,
      "z": 1,
      "name": "Rock_Stone"
    },
    {
      "x": -4,
      "y": 1,
      "z": 1,
      "name": "Rock_Stone"
    },
    {
      "x": -4,
      "y": 2,
      "z": 1,
      "name": "Rock_Stone_Mossy"
    },
    {
      "x": -4,
      "y": 3,
      "z": 1,
      "name": "Rock_Stone_Mossy"
    },
    {
      "x": -4,
      "y": 4,
      "z": 1,
      "name": "Rock_Stone_Mossy"
    },
    {
      "x": -4,
      "y": 5,
      "z": 1,
      "name": "Rock_Stone_Mossy"
    },
    {
      "x": -4,
      "y": 6,
      "z": 1,
      "name": "Rock_Stone"
    },
    {
      "x": -4,
      "y": 7,
      "z": 1,
      "name": "Rock_Stone"
    },
    {
      "x": -4,
      "y": 8,
      "z": 1,
      "name": "Rock_Stone"
    },
    {
      "x": -4,
      "y": 9,
      "z": 1,
      "name": "Rock_Stone"
    },
    {
      "x": -4,
      "y": 0,
      "z": 2,
      "name": "Rock_Stone"
    },
    {
      "x": -4,
      "y": 1,
      "z": 2,
      "name": "Rock_Stone"
    },
    {
      "x": -4,
      "y": 2,
      "z": 2,
      "name": "Rock_Stone_Mossy"
    },
    {
      "x": -4,
      "y": 3,
      "z": 2,
      "name": "Rock_Stone_Mossy"
    },
    {
      "x": -4,
      "y": 4,
      "z": 2,
      "name": "Rock_Stone"
    },
    {
      "x": -4,
      "y": 5,
      "z": 2,
      "name": "Rock_Stone"
    },
    {
      "x": -4,
      "y": 6,
      "z": 2,
      "name": "Rock_Stone"
    },
    {
      "x": -4,
      "y": 7,
      "z": 2,
      "name": "Rock_Stone"
    },
    {
      "x": -4,
      "y": 8,
      "z": 2,
      "name": "Rock_Stone"
    },
    {
      "x": -4,
      "y": 9,
      "z": 2,
      "name": "Rock_Stone"
    },
    {
      "x": -4,
      "y": 0,
      "z": 3,
      "name": "Rock_Stone"
    },
    {
      "x": -4,
      "y": 1,
      "z": 3,
      "name": "Rock_Stone"
    },
    {
      "x": -4,
      "y": 2,
      "z": 3,
      "name": "Rock_Stone"
    },
    {
      "x": -4,
      "y": 3,
      "z": 3,
      "name": "Rock_Stone"
    },
    {
      "x": -4,
      "y": 4,
      "z": 3,
      "name": "Rock_Stone"
    },
    {
      "x": -4,
      "y": 5,
      "z": 3,
      "name": "Rock_Stone"
    },
    {
      "x": -4,
      "y": 6,
      "z": 3,
      "name": "Rock_Stone"
    },
    {
      "x": -4,
      "y": 7,
      "z": 3,
      "name": "Rock_Stone"
    },
    {
      "x": -4,
      "y": 8,
      "z": 3,
      "name": "Rock_Stone"
    },
    {
      "x": -4,
      "y": 9,
      "z": 3,
      "name": "Rock_Stone"
    },
    {
      "x": -4,
      "y": 0,
      "z": 4,
      "name": "Rock_Stone"
    },
    {
      "x": -4,
      "y": 1,
      "z": 4,
      "name": "Rock_Stone"
    },
    {
      "x": -4,
      "y": 2,
      "z": 4,
      "name": "Rock_Stone"
    },
    {
      "x": -4,
      "y": 3,
      "z": 4,
      "name": "Rock_Stone"
    },
    {
      "x": -4,
      "y": 4,
      "z": 4,
      "name": "Rock_Stone"
    },
    {
      "x": -4,
      "y": 5,
      "z": 4,
      "name": "Rock_Stone"
    },
    {
      "x": -4,
      "y": 6,
      "z": 4,
      "name": "Rock_Stone"
    },
    {
      "x": -4,
      "y": 7,
      "z": 4,
      "name": "Rock_Stone"
    },
    {
      "x": -4,
      "y": 8,
      "z": 4,
      "name": "Rock_Stone"
    },
    {
      "x": -4,
      "y": 9,
      "z": 4,
      "name": "Rock_Stone"
    },
    {
      "x": -4,
      "y": 0,
      "z": 5,
      "name": "Rock_Stone"
    },
    {
      "x": -4,
      "y": 1,
      "z": 5,
      "name": "Rock_Stone"
    },
    {
      "x": -4,
      "y": 2,
      "z": 5,
      "name": "Rock_Stone"
    },
    {
      "x": -4,
      "y": 3,
      "z": 5,
      "name": "Rock_Stone"
    },
    {
      "x": -4,
      "y": 4,
      "z": 5,
      "name": "Rock_Stone"
    },
    {
      "x": -4,
      "y": 5,
      "z": 5,
      "name": "Rock_Stone"
    },
    {
      "x": -4,
      "y": 6,
      "z": 5,
      "name": "Rock_Stone"
    },
    {
      "x": -4,
      "y": 7,
      "z": 5,
      "name": "Rock_Stone"
    },
    {
      "x": -4,
      "y": 8,
      "z": 5,
      "name": "Rock_Stone"
    },
    {
      "x": -4,
      "y": 9,
      "z": 5,
      "name": "Rock_Stone"
    },
    {
      "x": -3,
      "y": 0,
      "z": -5,
      "name": "Rock_Stone"
    },
    {
      "x": -3,
      "y": 1,
      "z": -5,
      "name": "Rock_Stone"
    },
    {
      "x": -3,
      "y": 2,
      "z": -5,
      "name": "Rock_Stone"
    },
    {
      "x": -3,
      "y": 3,
      "z": -5,
      "name": "Rock_Stone"
    },
    {
      "x": -3,
      "y": 4,
      "z": -5,
      "name": "Rock_Stone"
    },
    {
      "x": -3,
      "y": 5,
      "z": -5,
      "name": "Rock_Stone"
    },
    {
      "x": -3,
      "y": 6,
      "z": -5,
      "name": "Rock_Stone"
    },
    {
      "x": -3,
      "y": 7,
      "z": -5,
      "name": "Rock_Stone"
    },
    {
      "x": -3,
      "y": 8,
      "z": -5,
      "name": "Rock_Stone"
    },
    {
      "x": -3,
      "y": 9,
      "z": -5,
      "name": "Rock_Stone"
    },
    {
      "x": -3,
      "y": 0,
      "z": -4,
      "name": "Rock_Stone"
    },
    {
      "x": -3,
      "y": 1,
      "z": -4,
      "name": "Rock_Stone"
    },
    {
      "x": -3,
      "y": 2,
      "z": -4,
      "name": "Rock_Stone"
    },
    {
      "x": -3,
      "y": 3,
      "z": -4,
      "name": "Rock_Stone"
    },
    {
      "x": -3,
      "y": 4,
      "z": -4,
      "name": "Rock_Stone"
    },
    {
      "x": -3,
      "y": 5,
      "z": -4,
      "name": "Rock_Stone"
    },
    {
      "x": -3,
      "y": 6,
      "z": -4,
      "name": "Rock_Stone"
    },
    {
      "x": -3,
      "y": 7,
      "z": -4,
      "name": "Rock_Stone"
    },
    {
      "x": -3,
      "y": 8,
      "z": -4,
      "name": "Rock_Stone"
    },
    {
      "x": -3,
      "y": 9,
      "z": -4,
      "name": "Rock_Stone"
    },
    {
      "x": -3,
      "y": 0,
      "z": -3,
      "name": "Rock_Stone"
    },
    {
      "x": -3,
      "y": 1,
      "z": -3,
      "name": "Rock_Stone"
    },
    {
      "x": -3,
      "y": 2,
      "z": -3,
      "name": "Rock_Stone"
    },
    {
      "x": -3,
      "y": 3,
      "z": -3,
      "name": "Rock_Stone"
    },
    {
      "x": -3,
      "y": 4,
      "z": -3,
      "name": "Rock_Stone"
    },
    {
      "x": -3,
      "y": 5,
      "z": -3,
      "name": "Rock_Stone"
    },
    {
      "x": -3,
      "y": 6,
      "z": -3,
      "name": "Rock_Stone"
    },
    {
      "x": -3,
      "y": 7,
      "z": -3,
      "name": "Rock_Stone"
    },
    {
      "x": -3,
      "y": 8,
      "z": -3,
      "name": "Rock_Stone"
    },
    {
      "x": -3,
      "y": 9,
      "z": -3,
      "name": "Rock_Stone"
    },
    {
      "x": -3,
      "y": 0,
      "z": -2,
      "name": "Rock_Stone"
    },
    {
      "x": -3,
      "y": 1,
      "z": -2,
      "name": "Rock_Stone_Cobble"
    },
    {
      "x": -3,
      "y": 2,
      "z": -2,
      "name": "Rock_Stone_Cobble"
    },
    {
      "x": -3,
      "y": 3,
      "z": -2,
      "name": "Empty"
    },
    {
      "x": -3,
      "y": 4,
      "z": -2,
      "name": "Empty"
    },
    {
      "x": -3,
      "y": 5,
      "z": -2,
      "name": "Wood_Beech_Trunk",
      "support": 1,
      "rotation": 4
    },
    {
      "x": -3,
      "y": 6,
      "z": -2,
      "name": "Rock_Stone"
    },
    {
      "x": -3,
      "y": 7,
      "z": -2,
      "name": "Rock_Stone"
    },
    {
      "x": -3,
      "y": 8,
      "z": -2,
      "name": "Rock_Stone"
    },
    {
      "x": -3,
      "y": 9,
      "z": -2,
      "name": "Rock_Stone"
    },
    {
      "x": -3,
      "y": 0,
      "z": -1,
      "name": "Rock_Stone"
    },
    {
      "x": -3,
      "y": 1,
      "z": -1,
      "name": "Wood_Beech_Trunk"
    },
    {
      "x": -3,
      "y": 2,
      "z": -1,
      "name": "Wood_Beech_Trunk"
    },
    {
      "x": -3,
      "y": 3,
      "z": -1,
      "name": "Wood_Beech_Trunk"
    },
    {
      "x": -3,
      "y": 4,
      "z": -1,
      "name": "Wood_Beech_Trunk"
    },
    {
      "x": -3,
      "y": 5,
      "z": -1,
      "name": "Wood_Beech_Trunk"
    },
    {
      "x": -3,
      "y": 6,
      "z": -1,
      "name": "Wood_Beech_Trunk"
    },
    {
      "x": -3,
      "y": 7,
      "z": -1,
      "name": "Rock_Stone"
    },
    {
      "x": -3,
      "y": 8,
      "z": -1,
      "name": "Rock_Stone"
    },
    {
      "x": -3,
      "y": 9,
      "z": -1,
      "name": "Rock_Stone"
    },
    {
      "x": -3,
      "y": 0,
      "z": 0,
      "name": "Rock_Stone"
    },
    {
      "x": -3,
      "y": 1,
      "z": 0,
      "name": "Rock_Stone_Cobble"
    },
    {
      "x": -3,
      "y": 2,
      "z": 0,
      "name": "Rock_Stone_Cobble"
    },
    {
      "x": -3,
      "y": 3,
      "z": 0,
      "name": "Rock_Stone_Cobble"
    },
    {
      "x": -3,
      "y": 4,
      "z": 0,
      "name": "Empty"
    },
    {
      "x": -3,
      "y": 5,
      "z": 0,
      "name": "Empty"
    },
    {
      "x": -3,
      "y": 6,
      "z": 0,
      "name": "Wood_Beech_Trunk",
      "rotation": 4
    },
    {
      "x": -3,
      "y": 7,
      "z": 0,
      "name": "Rock_Stone"
    },
    {
      "x": -3,
      "y": 8,
      "z": 0,
      "name": "Rock_Stone"
    },
    {
      "x": -3,
      "y": 9,
      "z": 0,
      "name": "Rock_Stone"
    },
    {
      "x": -3,
      "y": 0,
      "z": 1,
      "name": "Rock_Stone"
    },
    {
      "x": -3,
      "y": 1,
      "z": 1,
      "name": "Rock_Stone_Cobble"
    },
    {
      "x": -3,
      "y": 2,
      "z": 1,
      "name": "Empty"
    },
    {
      "x": -3,
      "y": 3,
      "z": 1,
      "name": "Empty"
    },
    {
      "x": -3,
      "y": 4,
      "z": 1,
      "name": "Empty"
    },
    {
      "x": -3,
      "y": 5,
      "z": 1,
      "name": "Rock_Stone"
    },
    {
      "x": -3,
      "y": 6,
      "z": 1,
      "name": "Wood_Beech_Trunk",
      "rotation": 4
    },
    {
      "x": -3,
      "y": 7,
      "z": 1,
      "name": "Rock_Stone"
    },
    {
      "x": -3,
      "y": 8,
      "z": 1,
      "name": "Rock_Stone"
    },
    {
      "x": -3,
      "y": 9,
      "z": 1,
      "name": "Rock_Stone"
    },
    {
      "x": -3,
      "y": 0,
      "z": 2,
      "name": "Rock_Stone"
    },
    {
      "x": -3,
      "y": 1,
      "z": 2,
      "name": "Rock_Stone"
    },
    {
      "x": -3,
      "y": 2,
      "z": 2,
      "name": "Rock_Stone"
    },
    {
      "x": -3,
      "y": 3,
      "z": 2,
      "name": "Rock_Stone"
    },
    {
      "x": -3,
      "y": 4,
      "z": 2,
      "name": "Rock_Stone"
    },
    {
      "x": -3,
      "y": 5,
      "z": 2,
      "name": "Rock_Stone"
    },
    {
      "x": -3,
      "y": 6,
      "z": 2,
      "name": "Rock_Stone"
    },
    {
      "x": -3,
      "y": 7,
      "z": 2,
      "name": "Rock_Stone"
    },
    {
      "x": -3,
      "y": 8,
      "z": 2,
      "name": "Rock_Stone"
    },
    {
      "x": -3,
      "y": 9,
      "z": 2,
      "name": "Rock_Stone"
    },
    {
      "x": -3,
      "y": 0,
      "z": 3,
      "name": "Rock_Stone"
    },
    {
      "x": -3,
      "y": 1,
      "z": 3,
      "name": "Rock_Stone"
    },
    {
      "x": -3,
      "y": 2,
      "z": 3,
      "name": "Rock_Stone"
    },
    {
      "x": -3,
      "y": 3,
      "z": 3,
      "name": "Rock_Stone"
    },
    {
      "x": -3,
      "y": 4,
      "z": 3,
      "name": "Rock_Stone"
    },
    {
      "x": -3,
      "y": 5,
      "z": 3,
      "name": "Rock_Stone"
    },
    {
      "x": -3,
      "y": 6,
      "z": 3,
      "name": "Rock_Stone"
    },
    {
      "x": -3,
      "y": 7,
      "z": 3,
      "name": "Rock_Stone"
    },
    {
      "x": -3,
      "y": 8,
      "z": 3,
      "name": "Rock_Stone"
    },
    {
      "x": -3,
      "y": 9,
      "z": 3,
      "name": "Rock_Stone"
    },
    {
      "x": -3,
      "y": 0,
      "z": 4,
      "name": "Rock_Stone"
    },
    {
      "x": -3,
      "y": 1,
      "z": 4,
      "name": "Rock_Stone"
    },
    {
      "x": -3,
      "y": 2,
      "z": 4,
      "name": "Rock_Stone"
    },
    {
      "x": -3,
      "y": 3,
      "z": 4,
      "name": "Rock_Stone"
    },
    {
      "x": -3,
      "y": 4,
      "z": 4,
      "name": "Rock_Stone"
    },
    {
      "x": -3,
      "y": 5,
      "z": 4,
      "name": "Rock_Stone"
    },
    {
      "x": -3,
      "y": 6,
      "z": 4,
      "name": "Rock_Stone"
    },
    {
      "x": -3,
      "y": 7,
      "z": 4,
      "name": "Rock_Stone"
    },
    {
      "x": -3,
      "y": 8,
      "z": 4,
      "name": "Rock_Stone"
    },
    {
      "x": -3,
      "y": 9,
      "z": 4,
      "name": "Rock_Stone"
    },
    {
      "x": -3,
      "y": 0,
      "z": 5,
      "name": "Rock_Stone"
    },
    {
      "x": -3,
      "y": 1,
      "z": 5,
      "name": "Rock_Stone"
    },
    {
      "x": -3,
      "y": 2,
      "z": 5,
      "name": "Rock_Stone"
    },
    {
      "x": -3,
      "y": 3,
      "z": 5,
      "name": "Rock_Stone"
    },
    {
      "x": -3,
      "y": 4,
      "z": 5,
      "name": "Rock_Stone"
    },
    {
      "x": -3,
      "y": 5,
      "z": 5,
      "name": "Rock_Stone"
    },
    {
      "x": -3,
      "y": 6,
      "z": 5,
      "name": "Rock_Stone"
    },
    {
      "x": -3,
      "y": 7,
      "z": 5,
      "name": "Rock_Stone"
    },
    {
      "x": -3,
      "y": 8,
      "z": 5,
      "name": "Rock_Stone"
    },
    {
      "x": -3,
      "y": 9,
      "z": 5,
      "name": "Rock_Stone"
    },
    {
      "x": -2,
      "y": 0,
      "z": -5,
      "name": "Rock_Stone"
    },
    {
      "x": -2,
      "y": 1,
      "z": -5,
      "name": "Rock_Stone"
    },
    {
      "x": -2,
      "y": 2,
      "z": -5,
      "name": "Rock_Stone"
    },
    {
      "x": -2,
      "y": 3,
      "z": -5,
      "name": "Rock_Stone"
    },
    {
      "x": -2,
      "y": 4,
      "z": -5,
      "name": "Rock_Stone"
    },
    {
      "x": -2,
      "y": 5,
      "z": -5,
      "name": "Rock_Stone"
    },
    {
      "x": -2,
      "y": 6,
      "z": -5,
      "name": "Rock_Stone"
    },
    {
      "x": -2,
      "y": 7,
      "z": -5,
      "name": "Rock_Stone"
    },
    {
      "x": -2,
      "y": 8,
      "z": -5,
      "name": "Rock_Stone"
    },
    {
      "x": -2,
      "y": 9,
      "z": -5,
      "name": "Rock_Stone"
    },
    {
      "x": -2,
      "y": 0,
      "z": -4,
      "name": "Rock_Stone"
    },
    {
      "x": -2,
      "y": 1,
      "z": -4,
      "name": "Rock_Stone"
    },
    {
      "x": -2,
      "y": 2,
      "z": -4,
      "name": "Rock_Stone"
    },
    {
      "x": -2,
      "y": 3,
      "z": -4,
      "name": "Rock_Stone"
    },
    {
      "x": -2,
      "y": 4,
      "z": -4,
      "name": "Rock_Stone"
    },
    {
      "x": -2,
      "y": 5,
      "z": -4,
      "name": "Rock_Stone"
    },
    {
      "x": -2,
      "y": 6,
      "z": -4,
      "name": "Rock_Stone"
    },
    {
      "x": -2,
      "y": 7,
      "z": -4,
      "name": "Rock_Stone"
    },
    {
      "x": -2,
      "y": 8,
      "z": -4,
      "name": "Rock_Stone"
    },
    {
      "x": -2,
      "y": 9,
      "z": -4,
      "name": "Rock_Stone"
    },
    {
      "x": -2,
      "y": 0,
      "z": -3,
      "name": "Rock_Stone"
    },
    {
      "x": -2,
      "y": 1,
      "z": -3,
      "name": "Rock_Stone"
    },
    {
      "x": -2,
      "y": 2,
      "z": -3,
      "name": "Rock_Stone"
    },
    {
      "x": -2,
      "y": 3,
      "z": -3,
      "name": "Rock_Stone"
    },
    {
      "x": -2,
      "y": 4,
      "z": -3,
      "name": "Empty"
    },
    {
      "x": -2,
      "y": 5,
      "z": -3,
      "name": "Wood_Beech_Trunk",
      "support": 2,
      "rotation": 5
    },
    {
      "x": -2,
      "y": 6,
      "z": -3,
      "name": "Rock_Stone_Cobble"
    },
    {
      "x": -2,
      "y": 7,
      "z": -3,
      "name": "Rock_Stone_Cobble"
    },
    {
      "x": -2,
      "y": 8,
      "z": -3,
      "name": "Rock_Stone"
    },
    {
      "x": -2,
      "y": 9,
      "z": -3,
      "name": "Rock_Stone"
    },
    {
      "x": -2,
      "y": 0,
      "z": -2,
      "name": "Rock_Stone"
    },
    {
      "x": -2,
      "y": 1,
      "z": -2,
      "name": "Rock_Stone_Cobble"
    },
    {
      "x": -2,
      "y": 2,
      "z": -2,
      "name": "Rock_Stone_Cobble"
    },
    {
      "x": -2,
      "y": 3,
      "z": -2,
      "name": "Empty"
    },
    {
      "x": -2,
      "y": 4,
      "z": -2,
      "name": "Empty"
    },
    {
      "x": -2,
      "y": 5,
      "z": -2,
      "name": "Empty"
    },
    {
      "x": -2,
      "y": 6,
      "z": -2,
      "name": "Rock_Stone_Cobble"
    },
    {
      "x": -2,
      "y": 7,
      "z": -2,
      "name": "Rock_Stone_Cobble"
    },
    {
      "x": -2,
      "y": 8,
      "z": -2,
      "name": "Rock_Stone"
    },
    {
      "x": -2,
      "y": 9,
      "z": -2,
      "name": "Rock_Stone"
    },
    {
      "x": -2,
      "y": 0,
      "z": -1,
      "name": "Rock_Stone"
    },
    {
      "x": -2,
      "y": 1,
      "z": -1,
      "name": "Wood_Softwood_Planks_Half",
      "rotation": 5
    },
    {
      "x": -2,
      "y": 2,
      "z": -1,
      "name": "Empty"
    },
    {
      "x": -2,
      "y": 3,
      "z": -1,
      "name": "Empty"
    },
    {
      "x": -2,
      "y": 4,
      "z": -1,
      "name": "Empty"
    },
    {
      "x": -2,
      "y": 5,
      "z": -1,
      "name": "Empty"
    },
    {
      "x": -2,
      "y": 6,
      "z": -1,
      "name": "Wood_Softwood_Planks_Half",
      "rotation": 8
    },
    {
      "x": -2,
      "y": 7,
      "z": -1,
      "name": "Wood_Beech_Trunk",
      "rotation": 5
    },
    {
      "x": -2,
      "y": 8,
      "z": -1,
      "name": "Rock_Stone"
    },
    {
      "x": -2,
      "y": 9,
      "z": -1,
      "name": "Rock_Stone"
    },
    {
      "x": -2,
      "y": 0,
      "z": 0,
      "name": "Rock_Stone"
    },
    {
      "x": -2,
      "y": 1,
      "z": 0,
      "name": "Rock_Stone"
    },
    {
      "x": -2,
      "y": 2,
      "z": 0,
      "name": "Empty"
    },
    {
      "x": -2,
      "y": 3,
      "z": 0,
      "name": "Empty"
    },
    {
      "x": -2,
      "y": 4,
      "z": 0,
      "name": "Empty"
    },
    {
      "x": -2,
      "y": 5,
      "z": 0,
      "name": "Empty"
    },
    {
      "x": -2,
      "y": 6,
      "z": 0,
      "name": "Empty"
    },
    {
      "x": -2,
      "y": 7,
      "z": 0,
      "name": "Rock_Stone_Cobble"
    },
    {
      "x": -2,
      "y": 8,
      "z": 0,
      "name": "Rock_Stone_Cobble"
    },
    {
      "x": -2,
      "y": 9,
      "z": 0,
      "name": "Rock_Stone"
    },
    {
      "x": -2,
      "y": 0,
      "z": 1,
      "name": "Rock_Stone"
    },
    {
      "x": -2,
      "y": 1,
      "z": 1,
      "name": "Rock_Stone"
    },
    {
      "x": -2,
      "y": 2,
      "z": 1,
      "name": "Rubble_Stone"
    },
    {
      "x": -2,
      "y": 3,
      "z": 1,
      "name": "Empty"
    },
    {
      "x": -2,
      "y": 4,
      "z": 1,
      "name": "Empty"
    },
    {
      "x": -2,
      "y": 5,
      "z": 1,
      "name": "Empty"
    },
    {
      "x": -2,
      "y": 6,
      "z": 1,
      "name": "Wood_Softwood_Planks_Half",
      "rotation": 6
    },
    {
      "x": -2,
      "y": 7,
      "z": 1,
      "name": "Rock_Stone_Cobble"
    },
    {
      "x": -2,
      "y": 8,
      "z": 1,
      "name": "Rock_Stone_Cobble"
    },
    {
      "x": -2,
      "y": 9,
      "z": 1,
      "name": "Rock_Stone"
    },
    {
      "x": -2,
      "y": 0,
      "z": 2,
      "name": "Rock_Stone"
    },
    {
      "x": -2,
      "y": 1,
      "z": 2,
      "name": "Rock_Stone_Cobble"
    },
    {
      "x": -2,
      "y": 2,
      "z": 2,
      "name": "Rock_Stone_Cobble"
    },
    {
      "x": -2,
      "y": 3,
      "z": 2,
      "name": "Empty"
    },
    {
      "x": -2,
      "y": 4,
      "z": 2,
      "name": "Empty"
    },
    {
      "x": -2,
      "y": 5,
      "z": 2,
      "name": "Empty"
    },
    {
      "x": -2,
      "y": 6,
      "z": 2,
      "name": "Wood_Beech_Trunk",
      "rotation": 4
    },
    {
      "x": -2,
      "y": 7,
      "z": 2,
      "name": "Rock_Stone_Cobble"
    },
    {
      "x": -2,
      "y": 8,
      "z": 2,
      "name": "Rock_Stone"
    },
    {
      "x": -2,
      "y": 9,
      "z": 2,
      "name": "Rock_Stone"
    },
    {
      "x": -2,
      "y": 0,
      "z": 3,
      "name": "Rock_Stone"
    },
    {
      "x": -2,
      "y": 1,
      "z": 3,
      "name": "Rock_Stone_Cobble"
    },
    {
      "x": -2,
      "y": 2,
      "z": 3,
      "name": "Rock_Stone_Cobble"
    },
    {
      "x": -2,
      "y": 3,
      "z": 3,
      "name": "Empty"
    },
    {
      "x": -2,
      "y": 4,
      "z": 3,
      "name": "Rock_Stone"
    },
    {
      "x": -2,
      "y": 5,
      "z": 3,
      "name": "Rock_Stone"
    },
    {
      "x": -2,
      "y": 6,
      "z": 3,
      "name": "Wood_Beech_Trunk",
      "rotation": 4
    },
    {
      "x": -2,
      "y": 7,
      "z": 3,
      "name": "Rock_Stone"
    },
    {
      "x": -2,
      "y": 8,
      "z": 3,
      "name": "Rock_Stone"
    },
    {
      "x": -2,
      "y": 9,
      "z": 3,
      "name": "Rock_Stone"
    },
    {
      "x": -2,
      "y": 0,
      "z": 4,
      "name": "Rock_Stone"
    },
    {
      "x": -2,
      "y": 1,
      "z": 4,
      "name": "Rock_Stone"
    },
    {
      "x": -2,
      "y": 2,
      "z": 4,
      "name": "Rock_Stone"
    },
    {
      "x": -2,
      "y": 3,
      "z": 4,
      "name": "Rock_Stone"
    },
    {
      "x": -2,
      "y": 4,
      "z": 4,
      "name": "Rock_Stone"
    },
    {
      "x": -2,
      "y": 5,
      "z": 4,
      "name": "Rock_Stone"
    },
    {
      "x": -2,
      "y": 6,
      "z": 4,
      "name": "Rock_Stone"
    },
    {
      "x": -2,
      "y": 7,
      "z": 4,
      "name": "Rock_Stone"
    },
    {
      "x": -2,
      "y": 8,
      "z": 4,
      "name": "Rock_Stone"
    },
    {
      "x": -2,
      "y": 9,
      "z": 4,
      "name": "Rock_Stone"
    },
    {
      "x": -2,
      "y": 0,
      "z": 5,
      "name": "Rock_Stone"
    },
    {
      "x": -2,
      "y": 1,
      "z": 5,
      "name": "Rock_Stone"
    },
    {
      "x": -2,
      "y": 2,
      "z": 5,
      "name": "Rock_Stone"
    },
    {
      "x": -2,
      "y": 3,
      "z": 5,
      "name": "Rock_Stone"
    },
    {
      "x": -2,
      "y": 4,
      "z": 5,
      "name": "Rock_Stone"
    },
    {
      "x": -2,
      "y": 5,
      "z": 5,
      "name": "Rock_Stone"
    },
    {
      "x": -2,
      "y": 6,
      "z": 5,
      "name": "Rock_Stone"
    },
    {
      "x": -2,
      "y": 7,
      "z": 5,
      "name": "Rock_Stone"
    },
    {
      "x": -2,
      "y": 8,
      "z": 5,
      "name": "Rock_Stone"
    },
    {
      "x": -2,
      "y": 9,
      "z": 5,
      "name": "Rock_Stone"
    },
    {
      "x": -1,
      "y": 0,
      "z": -5,
      "name": "Rock_Stone"
    },
    {
      "x": -1,
      "y": 1,
      "z": -5,
      "name": "Rock_Stone"
    },
    {
      "x": -1,
      "y": 2,
      "z": -5,
      "name": "Rock_Stone"
    },
    {
      "x": -1,
      "y": 3,
      "z": -5,
      "name": "Rock_Stone"
    },
    {
      "x": -1,
      "y": 4,
      "z": -5,
      "name": "Rock_Stone"
    },
    {
      "x": -1,
      "y": 5,
      "z": -5,
      "name": "Rock_Stone"
    },
    {
      "x": -1,
      "y": 6,
      "z": -5,
      "name": "Rock_Stone"
    },
    {
      "x": -1,
      "y": 7,
      "z": -5,
      "name": "Rock_Stone"
    },
    {
      "x": -1,
      "y": 8,
      "z": -5,
      "name": "Rock_Stone"
    },
    {
      "x": -1,
      "y": 9,
      "z": -5,
      "name": "Rock_Stone"
    },
    {
      "x": -1,
      "y": 0,
      "z": -4,
      "name": "Rock_Stone"
    },
    {
      "x": -1,
      "y": 1,
      "z": -4,
      "name": "Rock_Stone"
    },
    {
      "x": -1,
      "y": 2,
      "z": -4,
      "name": "Rock_Stone"
    },
    {
      "x": -1,
      "y": 3,
      "z": -4,
      "name": "Rock_Stone"
    },
    {
      "x": -1,
      "y": 4,
      "z": -4,
      "name": "Rock_Stone"
    },
    {
      "x": -1,
      "y": 5,
      "z": -4,
      "name": "Rock_Stone"
    },
    {
      "x": -1,
      "y": 6,
      "z": -4,
      "name": "Rock_Stone"
    },
    {
      "x": -1,
      "y": 7,
      "z": -4,
      "name": "Rock_Stone"
    },
    {
      "x": -1,
      "y": 8,
      "z": -4,
      "name": "Rock_Stone"
    },
    {
      "x": -1,
      "y": 9,
      "z": -4,
      "name": "Rock_Stone"
    },
    {
      "x": -1,
      "y": 0,
      "z": -3,
      "name": "Rock_Stone"
    },
    {
      "x": -1,
      "y": 1,
      "z": -3,
      "name": "Rock_Stone_Cobble"
    },
    {
      "x": -1,
      "y": 2,
      "z": -3,
      "name": "Rock_Stone_Cobble"
    },
    {
      "x": -1,
      "y": 3,
      "z": -3,
      "name": "Empty"
    },
    {
      "x": -1,
      "y": 4,
      "z": -3,
      "name": "Empty"
    },
    {
      "x": -1,
      "y": 5,
      "z": -3,
      "name": "Wood_Beech_Trunk",
      "support": 1,
      "rotation": 5
    },
    {
      "x": -1,
      "y": 6,
      "z": -3,
      "name": "Rock_Stone_Cobble"
    },
    {
      "x": -1,
      "y": 7,
      "z": -3,
      "name": "Rock_Stone_Cobble"
    },
    {
      "x": -1,
      "y": 8,
      "z": -3,
      "name": "Rock_Stone_Cobble"
    },
    {
      "x": -1,
      "y": 9,
      "z": -3,
      "name": "Rock_Stone"
    },
    {
      "x": -1,
      "y": 0,
      "z": -2,
      "name": "Rock_Stone"
    },
    {
      "x": -1,
      "y": 1,
      "z": -2,
      "name": "Furniture_Tavern_Barrel"
    },
    {
      "x": -1,
      "y": 2,
      "z": -2,
      "name": "Empty"
    },
    {
      "x": -1,
      "y": 3,
      "z": -2,
      "name": "Empty"
    },
    {
      "x": -1,
      "y": 4,
      "z": -2,
      "name": "Empty"
    },
    {
      "x": -1,
      "y": 5,
      "z": -2,
      "name": "Empty"
    },
    {
      "x": -1,
      "y": 6,
      "z": -2,
      "name": "Rock_Stone_Cobble"
    },
    {
      "x": -1,
      "y": 7,
      "z": -2,
      "name": "Rock_Stone_Cobble"
    },
    {
      "x": -1,
      "y": 8,
      "z": -2,
      "name": "Rock_Stone_Cobble"
    },
    {
      "x": -1,
      "y": 9,
      "z": -2,
      "name": "Rock_Stone"
    },
    {
      "x": -1,
      "y": 0,
      "z": -1,
      "name": "Rock_Stone"
    },
    {
      "x": -1,
      "y": 1,
      "z": -1,
      "name": "Empty"
    },
    {
      "x": -1,
      "y": 2,
      "z": -1,
      "name": "Empty"
    },
    {
      "x": -1,
      "y": 3,
      "z": -1,
      "name": "Empty"
    },
    {
      "x": -1,
      "y": 4,
      "z": -1,
      "name": "Empty"
    },
    {
      "x": -1,
      "y": 5,
      "z": -1,
      "name": "Empty"
    },
    {
      "x": -1,
      "y": 6,
      "z": -1,
      "name": "Empty"
    },
    {
      "x": -1,
      "y": 7,
      "z": -1,
      "name": "Wood_Beech_Trunk",
      "support": 1,
      "rotation": 5
    },
    {
      "x": -1,
      "y": 8,
      "z": -1,
      "name": "Rock_Stone_Cobble"
    },
    {
      "x": -1,
      "y": 9,
      "z": -1,
      "name": "Rock_Stone"
    },
    {
      "x": -1,
      "y": 0,
      "z": 0,
      "name": "Rock_Stone"
    },
    {
      "x": -1,
      "y": 1,
      "z": 0,
      "name": "Rubble_Stone_Medium"
    },
    {
      "x": -1,
      "y": 2,
      "z": 0,
      "name": "Empty"
    },
    {
      "x": -1,
      "y": 3,
      "z": 0,
      "name": "Empty"
    },
    {
      "x": -1,
      "y": 4,
      "z": 0,
      "name": "Empty"
    },
    {
      "x": -1,
      "y": 5,
      "z": 0,
      "name": "Empty"
    },
    {
      "x": -1,
      "y": 6,
      "z": 0,
      "name": "Empty"
    },
    {
      "x": -1,
      "y": 7,
      "z": 0,
      "name": "Rock_Stone_Cobble"
    },
    {
      "x": -1,
      "y": 8,
      "z": 0,
      "name": "Rock_Stone_Cobble"
    },
    {
      "x": -1,
      "y": 9,
      "z": 0,
      "name": "Rock_Stone"
    },
    {
      "x": -1,
      "y": 0,
      "z": 1,
      "name": "Rock_Stone"
    },
    {
      "x": -1,
      "y": 1,
      "z": 1,
      "name": "Rock_Stone"
    },
    {
      "x": -1,
      "y": 2,
      "z": 1,
      "name": "Empty"
    },
    {
      "x": -1,
      "y": 3,
      "z": 1,
      "name": "Empty"
    },
    {
      "x": -1,
      "y": 4,
      "z": 1,
      "name": "Empty"
    },
    {
      "x": -1,
      "y": 5,
      "z": 1,
      "name": "Empty"
    },
    {
      "x": -1,
      "y": 6,
      "z": 1,
      "name": "Empty"
    },
    {
      "x": -1,
      "y": 7,
      "z": 1,
      "name": "Rock_Stone_Cobble"
    },
    {
      "x": -1,
      "y": 8,
      "z": 1,
      "name": "Rock_Stone_Cobble"
    },
    {
      "x": -1,
      "y": 9,
      "z": 1,
      "name": "Rock_Stone"
    },
    {
      "x": -1,
      "y": 0,
      "z": 2,
      "name": "Rock_Stone"
    },
    {
      "x": -1,
      "y": 1,
      "z": 2,
      "name": "Rock_Stone"
    },
    {
      "x": -1,
      "y": 2,
      "z": 2,
      "name": "Empty"
    },
    {
      "x": -1,
      "y": 3,
      "z": 2,
      "name": "Empty"
    },
    {
      "x": -1,
      "y": 4,
      "z": 2,
      "name": "Empty"
    },
    {
      "x": -1,
      "y": 5,
      "z": 2,
      "name": "Empty"
    },
    {
      "x": -1,
      "y": 6,
      "z": 2,
      "name": "Empty"
    },
    {
      "x": -1,
      "y": 7,
      "z": 2,
      "name": "Rock_Stone_Cobble"
    },
    {
      "x": -1,
      "y": 8,
      "z": 2,
      "name": "Rock_Stone_Cobble"
    },
    {
      "x": -1,
      "y": 9,
      "z": 2,
      "name": "Rock_Stone"
    },
    {
      "x": -1,
      "y": 0,
      "z": 3,
      "name": "Rock_Stone"
    },
    {
      "x": -1,
      "y": 1,
      "z": 3,
      "name": "Rock_Stone"
    },
    {
      "x": -1,
      "y": 2,
      "z": 3,
      "name": "Empty"
    },
    {
      "x": -1,
      "y": 3,
      "z": 3,
      "name": "Empty"
    },
    {
      "x": -1,
      "y": 4,
      "z": 3,
      "name": "Empty"
    },
    {
      "x": -1,
      "y": 5,
      "z": 3,
      "name": "Empty"
    },
    {
      "x": -1,
      "y": 6,
      "z": 3,
      "name": "Wood_Softwood_Planks_Half",
      "rotation": 7
    },
    {
      "x": -1,
      "y": 7,
