{
  "version": 8,
  "blockIdVersion": 8,
  "anchorX": 6,
  "anchorY": 13,
  "anchorZ": 6,
  "blocks": [
    {
      "x": -11,
      "y": 33,
      "z": -10,
      "name": "Rock_Volcanic"
    },
    {
      "x": -11,
      "y": 34,
      "z": -10,
      "name": "Rock_Volcanic"
    },
    {
      "x": -11,
      "y": 33,
      "z": -9,
      "name": "Rock_Volcanic"
    },
    {
      "x": -10,
      "y": 31,
      "z": -9,
      "name": "Rock_Volcanic"
    },
    {
      "x": -10,
      "y": 32,
      "z": -9,
      "name": "Rock_Volcanic"
    },
    {
      "x": -10,
      "y": 33,
      "z": -9,
      "name": "Rock_Volcanic"
    },
    {
      "x": -10,
      "y": 31,
      "z": -8,
      "name": "Rock_Volcanic"
    },
    {
      "x": -10,
      "y": 32,
      "z": -8,
      "name": "Rock_Volcanic"
    },
    {
      "x": -9,
      "y": 31,
      "z": -9,
      "name": "Rock_Volcanic"
    },
    {
      "x": -9,
      "y": 32,
      "z": -9,
      "name": "Rock_Volcanic"
    },
    {
      "x": -9,
      "y": 29,
      "z": -8,
      "name": "Rock_Volcanic"
    },
    {
      "x": -9,
      "y": 30,
      "z": -8,
      "name": "Rock_Volcanic"
    },
    {
      "x": -9,
      "y": 31,
      "z": -8,
      "name": "Rock_Volcanic"
    },
    {
      "x": -9,
      "y": 32,
      "z": -8,
      "name": "Rock_Volcanic"
    },
    {
      "x": -9,
      "y": 28,
      "z": -7,
      "name": "Rock_Volcanic"
    },
    {
      "x": -9,
      "y": 29,
      "z": -7,
      "name": "Rock_Volcanic"
    },
    {
      "x": -9,
      "y": 30,
      "z": -7,
      "name": "Rock_Volcanic"
    },
    {
      "x": -9,
      "y": 31,
      "z": -7,
      "name": "Rock_Volcanic"
    },
    {
      "x": -9,
      "y": 32,
      "z": -7,
      "name": "Rock_Volcanic"
    },
    {
      "x": -9,
      "y": 27,
      "z": -6,
      "name": "Rock_Volcanic"
    },
    {
      "x": -9,
      "y": 28,
      "z": -6,
      "name": "Rock_Volcanic"
    },
    {
      "x": -9,
      "y": 29,
      "z": -6,
      "name": "Rock_Volcanic"
    },
    {
      "x": -8,
      "y": 30,
      "z": -9,
      "name": "Rock_Volcanic"
    },
    {
      "x": -8,
      "y": 31,
      "z": -9,
      "name": "Rock_Volcanic"
    },
    {
      "x": -8,
      "y": 32,
      "z": -9,
      "name": "Rock_Volcanic"
    },
    {
      "x": -8,
      "y": 28,
      "z": -8,
      "name": "Rock_Volcanic"
    },
    {
      "x": -8,
      "y": 29,
      "z": -8,
      "name": "Rock_Volcanic"
    },
    {
      "x": -8,
      "y": 30,
      "z": -8,
      "name": "Rock_Volcanic"
    },
    {
      "x": -8,
      "y": 31,
      "z": -8,
      "name": "Rock_Volcanic"
    },
    {
      "x": -8,
      "y": 32,
      "z": -8,
      "name": "Rock_Volcanic"
    },
    {
      "x": -8,
      "y": 26,
      "z": -7,
      "name": "Rock_Volcanic"
    },
    {
      "x": -8,
      "y": 27,
      "z": -7,
      "name": "Rock_Volcanic"
    },
    {
      "x": -8,
      "y": 28,
      "z": -7,
      "name": "Rock_Volcanic"
    },
    {
      "x": -8,
      "y": 29,
      "z": -7,
      "name": "Rock_Volcanic"
    },
    {
      "x": -8,
      "y": 30,
      "z": -7,
      "name": "Rock_Volcanic"
    },
    {
      "x": -8,
      "y": 31,
      "z": -7,
      "name": "Rock_Volcanic"
    },
    {
      "x": -8,
      "y": 25,
      "z": -6,
      "name": "Rock_Volcanic"
    },
    {
      "x": -8,
      "y": 26,
      "z": -6,
      "name": "Rock_Volcanic"
    },
    {
      "x": -8,
      "y": 27,
      "z": -6,
      "name": "Rock_Volcanic"
    },
    {
      "x": -8,
      "y": 28,
      "z": -6,
      "name": "Rock_Volcanic"
    },
    {
      "x": -8,
      "y": 29,
      "z": -6,
      "name": "Rock_Volcanic"
    },
    {
      "x": -8,
      "y": 30,
      "z": -6,
      "name": "Rock_Volcanic"
    },
    {
      "x": -8,
      "y": 24,
      "z": -5,
      "name": "Rock_Volcanic"
    },
    {
      "x": -8,
      "y": 25,
      "z": -5,
      "name": "Rock_Volcanic"
    },
    {
      "x": -8,
      "y": 26,
      "z": -5,
      "name": "Rock_Volcanic"
    },
    {
      "x": -7,
      "y": 30,
      "z": -8,
      "name": "Rock_Volcanic"
    },
    {
      "x": -7,
      "y": 31,
      "z": -8,
      "name": "Rock_Volcanic"
    },
    {
      "x": -7,
      "y": 25,
      "z": -7,
      "name": "Rock_Volcanic"
    },
    {
      "x": -7,
      "y": 26,
      "z": -7,
      "name": "Rock_Volcanic"
    },
    {
      "x": -7,
      "y": 27,
      "z": -7,
      "name": "Rock_Volcanic"
    },
    {
      "x": -7,
      "y": 28,
      "z": -7,
      "name": "Rock_Volcanic"
    },
    {
      "x": -7,
      "y": 29,
      "z": -7,
      "name": "Rock_Volcanic"
    },
    {
      "x": -7,
      "y": 30,
      "z": -7,
      "name": "Rock_Volcanic"
    },
    {
      "x": -7,
      "y": 31,
      "z": -7,
      "name": "Rock_Volcanic"
    },
    {
      "x": -7,
      "y": 24,
      "z": -6,
      "name": "Rock_Volcanic"
    },
    {
      "x": -7,
      "y": 25,
      "z": -6,
      "name": "Rock_Volcanic"
    },
    {
      "x": -7,
      "y": 26,
      "z": -6,
      "name": "Rock_Volcanic"
    },
    {
      "x": -7,
      "y": 27,
      "z": -6,
      "name": "Rock_Volcanic"
    },
    {
      "x": -7,
      "y": 28,
      "z": -6,
      "name": "Rock_Volcanic"
    },
    {
      "x": -7,
      "y": 29,
      "z": -6,
      "name": "Rock_Volcanic"
    },
    {
      "x": -7,
      "y": 30,
      "z": -6,
      "name": "Rock_Volcanic"
    },
    {
      "x": -7,
      "y": 24,
      "z": -5,
      "name": "Rock_Volcanic"
    },
    {
      "x": -7,
      "y": 25,
      "z": -5,
      "name": "Rock_Volcanic"
    },
    {
      "x": -7,
      "y": 26,
      "z": -5,
      "name": "Rock_Volcanic_Cracked_Poisoned"
    },
    {
      "x": -7,
      "y": 27,
      "z": -5,
      "name": "Rock_Volcanic"
    },
    {
      "x": -7,
      "y": 28,
      "z": -5,
      "name": "Rock_Volcanic"
    },
    {
      "x": -7,
      "y": 29,
      "z": -5,
      "name": "Rock_Volcanic"
    },
    {
      "x": -7,
      "y": 23,
      "z": -4,
      "name": "Rock_Volcanic"
    },
    {
      "x": -7,
      "y": 24,
      "z": -4,
      "name": "Rock_Volcanic"
    },
    {
      "x": -7,
      "y": 25,
      "z": -4,
      "name": "Rock_Volcanic_Cracked_Poisoned"
    },
    {
      "x": -7,
      "y": 26,
      "z": -4,
      "name": "Rock_Volcanic_Cracked_Poisoned"
    },
    {
      "x": -7,
      "y": 27,
      "z": -4,
      "name": "Rock_Volcanic_Cracked_Poisoned"
    },
    {
      "x": -7,
      "y": 28,
      "z": -4,
      "name": "Rock_Volcanic"
    },
    {
      "x": -6,
      "y": 24,
      "z": -7,
      "name": "Rock_Volcanic"
    },
    {
      "x": -6,
      "y": 25,
      "z": -7,
      "name": "Rock_Volcanic"
    },
    {
      "x": -6,
      "y": 26,
      "z": -7,
      "name": "Rock_Volcanic"
    },
    {
      "x": -6,
      "y": 27,
      "z": -7,
      "name": "Rock_Volcanic"
    },
    {
      "x": -6,
      "y": 24,
      "z": -6,
      "name": "Rock_Volcanic"
    },
    {
      "x": -6,
      "y": 25,
      "z": -6,
      "name": "Rock_Volcanic"
    },
    {
      "x": -6,
      "y": 26,
      "z": -6,
      "name": "Rock_Volcanic"
    },
    {
      "x": -6,
      "y": 27,
      "z": -6,
      "name": "Rock_Volcanic"
    },
    {
      "x": -6,
      "y": 28,
      "z": -6,
      "name": "Rock_Volcanic"
    },
    {
      "x": -6,
      "y": 29,
      "z": -6,
      "name": "Rock_Volcanic"
    },
    {
      "x": -6,
      "y": 23,
      "z": -5,
      "name": "Rock_Volcanic"
    },
    {
      "x": -6,
      "y": 24,
      "z": -5,
      "name": "Rock_Volcanic"
    },
    {
      "x": -6,
      "y": 25,
      "z": -5,
      "name": "Rock_Volcanic"
    },
    {
      "x": -6,
      "y": 26,
      "z": -5,
      "name": "Rock_Volcanic_Cracked_Poisoned"
    },
    {
      "x": -6,
      "y": 27,
      "z": -5,
      "name": "Rock_Volcanic"
    },
    {
      "x": -6,
      "y": 28,
      "z": -5,
      "name": "Rock_Volcanic"
    },
    {
      "x": -6,
      "y": 29,
      "z": -5,
      "name": "Rock_Volcanic"
    },
    {
      "x": -6,
      "y": 22,
      "z": -4,
      "name": "Rock_Volcanic"
    },
    {
      "x": -6,
      "y": 23,
      "z": -4,
      "name": "Rock_Volcanic"
    },
    {
      "x": -6,
      "y": 24,
      "z": -4,
      "name": "Rock_Volcanic"
    },
    {
      "x": -6,
      "y": 25,
      "z": -4,
      "name": "Rock_Volcanic_Cracked_Poisoned"
    },
    {
      "x": -6,
      "y": 26,
      "z": -4,
      "name": "Rock_Volcanic_Cracked_Poisoned"
    },
    {
      "x": -6,
      "y": 27,
      "z": -4,
      "name": "Rock_Volcanic_Cracked_Poisoned"
    },
    {
      "x": -6,
      "y": 28,
      "z": -4,
      "name": "Rock_Volcanic"
    },
    {
      "x": -6,
      "y": 22,
      "z": -3,
      "name": "Rock_Volcanic"
    },
    {
      "x": -6,
      "y": 23,
      "z": -3,
      "name": "Rock_Volcanic"
    },
    {
      "x": -6,
      "y": 24,
      "z": -3,
      "name": "Rock_Volcanic"
    },
    {
      "x": -6,
      "y": 25,
      "z": -3,
      "name": "Rock_Volcanic_Cracked_Poisoned"
    },
    {
      "x": -6,
      "y": 26,
      "z": -3,
      "name": "Rock_Volcanic_Cracked_Poisoned"
    },
    {
      "x": -5,
      "y": 25,
      "z": -7,
      "name": "Rock_Volcanic"
    },
    {
      "x": -5,
      "y": 23,
      "z": -6,
      "name": "Rock_Volcanic"
    },
    {
      "x": -5,
      "y": 24,
      "z": -6,
      "name": "Rock_Volcanic"
    },
    {
      "x": -5,
      "y": 25,
      "z": -6,
      "name": "Rock_Volcanic"
    },
    {
      "x": -5,
      "y": 26,
      "z": -6,
      "name": "Rock_Volcanic"
    },
    {
      "x": -5,
      "y": 27,
      "z": -6,
      "name": "Rock_Volcanic"
    },
    {
      "x": -5,
      "y": 28,
      "z": -6,
      "name": "Rock_Volcanic"
    },
    {
      "x": -5,
      "y": 22,
      "z": -5,
      "name": "Rock_Volcanic"
    },
    {
      "x": -5,
      "y": 23,
      "z": -5,
      "name": "Rock_Volcanic"
    },
    {
      "x": -5,
      "y": 24,
      "z": -5,
      "name": "Rock_Volcanic"
    },
    {
      "x": -5,
      "y": 25,
      "z": -5,
      "name": "Rock_Volcanic"
    },
    {
      "x": -5,
      "y": 26,
      "z": -5,
      "name": "Rock_Volcanic_Cracked_Poisoned"
    },
    {
      "x": -5,
      "y": 27,
      "z": -5,
      "name": "Rock_Volcanic"
    },
    {
      "x": -5,
      "y": 28,
      "z": -5,
      "name": "Rock_Volcanic"
    },
    {
      "x": -5,
      "y": 21,
      "z": -4,
      "name": "Rock_Volcanic"
    },
    {
      "x": -5,
      "y": 22,
      "z": -4,
      "name": "Rock_Volcanic"
    },
    {
      "x": -5,
      "y": 23,
      "z": -4,
      "name": "Rock_Volcanic"
    },
    {
      "x": -5,
      "y": 24,
      "z": -4,
      "name": "Rock_Volcanic"
    },
    {
      "x": -5,
      "y": 25,
      "z": -4,
      "name": "Rock_Volcanic_Cracked_Poisoned"
    },
    {
      "x": -5,
      "y": 26,
      "z": -4,
      "name": "Rock_Volcanic_Cracked_Poisoned"
    },
    {
      "x": -5,
      "y": 27,
      "z": -4,
      "name": "Rock_Volcanic_Cracked_Poisoned"
    },
    {
      "x": -5,
      "y": 20,
      "z": -3,
      "name": "Rock_Volcanic"
    },
    {
      "x": -5,
      "y": 21,
      "z": -3,
      "name": "Rock_Volcanic"
    },
    {
      "x": -5,
      "y": 22,
      "z": -3,
      "name": "Rock_Volcanic"
    },
    {
      "x": -5,
      "y": 23,
      "z": -3,
      "name": "Rock_Volcanic"
    },
    {
      "x": -5,
      "y": 24,
      "z": -3,
      "name": "Rock_Volcanic_Cracked_Poisoned"
    },
    {
      "x": -5,
      "y": 25,
      "z": -3,
      "name": "Rock_Volcanic_Cracked_Poisoned"
    },
    {
      "x": -5,
      "y": 26,
      "z": -3,
      "name": "Rock_Volcanic_Cracked_Poisoned"
    },
    {
      "x": -5,
      "y": 20,
      "z": -2,
      "name": "Rock_Volcanic"
    },
    {
      "x": -5,
      "y": 21,
      "z": -2,
      "name": "Rock_Volcanic"
    },
    {
      "x": -5,
      "y": 22,
      "z": -2,
      "name": "Rock_Volcanic"
    },
    {
      "x": -5,
      "y": 23,
      "z": -2,
      "name": "Rock_Volcanic"
    },
    {
      "x": -5,
      "y": 24,
      "z": -2,
      "name": "Rock_Volcanic_Cracked_Poisoned"
    },
    {
      "x": -5,
      "y": 25,
      "z": -2,
      "name": "Rock_Volcanic_Cracked_Poisoned"
    },
    {
      "x": -5,
      "y": 19,
      "z": -1,
      "name": "Rock_Volcanic"
    },
    {
      "x": -5,
      "y": 20,
      "z": -1,
      "name": "Rock_Volcanic"
    },
    {
      "x": -5,
      "y": 21,
      "z": -1,
      "name": "Rock_Volcanic"
    },
    {
      "x": -5,
      "y": 22,
      "z": -1,
      "name": "Rock_Volcanic"
    },
    {
      "x": -4,
      "y": 24,
      "z": -6,
      "name": "Rock_Volcanic"
    },
    {
      "x": -4,
      "y": 25,
      "z": -6,
      "name": "Rock_Volcanic"
    },
    {
      "x": -4,
      "y": 22,
      "z": -5,
      "name": "Rock_Volcanic"
    },
    {
      "x": -4,
      "y": 23,
      "z": -5,
      "name": "Rock_Volcanic"
    },
    {
      "x": -4,
      "y": 24,
      "z": -5,
      "name": "Rock_Volcanic"
    },
    {
      "x": -4,
      "y": 25,
      "z": -5,
      "name": "Rock_Volcanic"
    },
    {
      "x": -4,
      "y": 26,
      "z": -5,
      "name": "Rock_Volcanic"
    },
    {
      "x": -4,
      "y": 27,
      "z": -5,
      "name": "Rock_Volcanic"
    },
    {
      "x": -4,
      "y": 20,
      "z": -4,
      "name": "Rock_Volcanic"
    },
    {
      "x": -4,
      "y": 21,
      "z": -4,
      "name": "Rock_Volcanic"
    },
    {
      "x": -4,
      "y": 22,
      "z": -4,
      "name": "Rock_Volcanic"
    },
    {
      "x": -4,
      "y": 23,
      "z": -4,
      "name": "Rock_Volcanic"
    },
    {
      "x": -4,
      "y": 24,
      "z": -4,
      "name": "Rock_Volcanic"
    },
    {
      "x": -4,
      "y": 25,
      "z": -4,
      "name": "Rock_Volcanic_Cracked_Poisoned"
    },
    {
      "x": -4,
      "y": 26,
      "z": -4,
      "name": "Rock_Volcanic_Cracked_Poisoned"
    },
    {
      "x": -4,
      "y": 27,
      "z": -4,
      "name": "Rock_Volcanic"
    },
    {
      "x": -4,
      "y": 18,
      "z": -3,
      "name": "Rock_Volcanic"
    },
    {
      "x": -4,
      "y": 19,
      "z": -3,
      "name": "Rock_Volcanic"
    },
    {
      "x": -4,
      "y": 20,
      "z": -3,
      "name": "Rock_Volcanic"
    },
    {
      "x": -4,
      "y": 21,
      "z": -3,
      "name": "Rock_Volcanic"
    },
    {
      "x": -4,
      "y": 22,
      "z": -3,
      "name": "Rock_Volcanic"
    },
    {
      "x": -4,
      "y": 23,
      "z": -3,
      "name": "Rock_Volcanic"
    },
    {
      "x": -4,
      "y": 24,
      "z": -3,
      "name": "Rock_Volcanic_Cracked_Poisoned"
    },
    {
      "x": -4,
      "y": 25,
      "z": -3,
      "name": "Rock_Volcanic_Cracked_Poisoned"
    },
    {
      "x": -4,
      "y": 18,
      "z": -2,
      "name": "Rock_Volcanic"
    },
    {
      "x": -4,
      "y": 19,
      "z": -2,
      "name": "Rock_Volcanic"
    },
    {
      "x": -4,
      "y": 20,
      "z": -2,
      "name": "Rock_Volcanic"
    },
    {
      "x": -4,
      "y": 21,
      "z": -2,
      "name": "Rock_Volcanic"
    },
    {
      "x": -4,
      "y": 22,
      "z": -2,
      "name": "Rock_Volcanic"
    },
    {
      "x": -4,
      "y": 23,
      "z": -2,
      "name": "Rock_Volcanic"
    },
    {
      "x": -4,
      "y": 24,
      "z": -2,
      "name": "Rock_Volcanic_Cracked_Poisoned"
    },
    {
      "x": -4,
      "y": 25,
      "z": -2,
      "name": "Rock_Volcanic_Cracked_Poisoned"
    },
    {
      "x": -4,
      "y": 17,
      "z": -1,
      "name": "Rock_Volcanic"
    },
    {
      "x": -4,
      "y": 18,
      "z": -1,
      "name": "Rock_Volcanic"
    },
    {
      "x": -4,
      "y": 19,
      "z": -1,
      "name": "Rock_Volcanic"
    },
    {
      "x": -4,
      "y": 20,
      "z": -1,
      "name": "Rock_Volcanic"
    },
    {
      "x": -4,
      "y": 21,
      "z": -1,
      "name": "Rock_Volcanic"
    },
    {
      "x": -4,
      "y": 22,
      "z": -1,
      "name": "Rock_Volcanic"
    },
    {
      "x": -4,
      "y": 23,
      "z": -1,
      "name": "Rock_Volcanic"
    },
    {
      "x": -4,
      "y": 17,
      "z": 0,
      "name": "Rock_Volcanic"
    },
    {
      "x": -4,
      "y": 18,
      "z": 0,
      "name": "Rock_Volcanic"
    },
    {
      "x": -4,
      "y": 19,
      "z": 0,
      "name": "Rock_Volcanic"
    },
    {
      "x": -4,
      "y": 20,
      "z": 0,
      "name": "Rock_Volcanic"
    },
    {
      "x": -3,
      "y": 19,
      "z": -4,
      "name": "Rock_Volcanic"
    },
    {
      "x": -3,
      "y": 20,
      "z": -4,
      "name": "Rock_Volcanic"
    },
    {
      "x": -3,
      "y": 21,
      "z": -4,
      "name": "Rock_Volcanic"
    },
    {
      "x": -3,
      "y": 22,
      "z": -4,
      "name": "Rock_Volcanic"
    },
    {
      "x": -3,
      "y": 23,
      "z": -4,
      "name": "Rock_Volcanic"
    },
    {
      "x": -3,
      "y": 24,
      "z": -4,
      "name": "Rock_Volcanic"
    },
    {
      "x": -3,
      "y": 25,
      "z": -4,
      "name": "Rock_Volcanic_Cracked_Poisoned"
    },
    {
      "x": -3,
      "y": 17,
      "z": -3,
      "name": "Rock_Volcanic"
    },
    {
      "x": -3,
      "y": 18,
      "z": -3,
      "name": "Rock_Volcanic"
    },
    {
      "x": -3,
      "y": 19,
      "z": -3,
      "name": "Rock_Volcanic"
    },
    {
      "x": -3,
      "y": 20,
      "z": -3,
      "name": "Rock_Volcanic"
    },
    {
      "x": -3,
      "y": 21,
      "z": -3,
      "name": "Rock_Volcanic"
    },
    {
      "x": -3,
      "y": 22,
      "z": -3,
      "name": "Rock_Volcanic"
    },
    {
      "x": -3,
      "y": 23,
      "z": -3,
      "name": "Rock_Volcanic"
    },
    {
      "x": -3,
      "y": 24,
      "z": -3,
      "name": "Rock_Volcanic_Cracked_Poisoned"
    },
    {
      "x": -3,
      "y": 25,
      "z": -3,
      "name": "Rock_Volcanic_Cracked_Poisoned"
    },
    {
      "x": -3,
      "y": 17,
      "z": -2,
      "name": "Rock_Volcanic"
    },
    {
      "x": -3,
      "y": 18,
      "z": -2,
      "name": "Rock_Volcanic"
    },
    {
      "x": -3,
      "y": 19,
      "z": -2,
      "name": "Rock_Volcanic"
    },
    {
      "x": -3,
      "y": 20,
      "z": -2,
      "name": "Rock_Volcanic"
    },
    {
      "x": -3,
      "y": 21,
      "z": -2,
      "name": "Rock_Volcanic"
    },
    {
      "x": -3,
      "y": 22,
      "z": -2,
      "name": "Rock_Volcanic_Cracked_Poisoned"
    },
    {
      "x": -3,
      "y": 23,
      "z": -2,
      "name": "Rock_Volcanic"
    },
    {
      "x": -3,
      "y": 24,
      "z": -2,
      "name": "Rock_Volcanic_Cracked_Poisoned"
    },
    {
      "x": -3,
      "y": 17,
      "z": -1,
      "name": "Rock_Volcanic"
    },
    {
      "x": -3,
      "y": 18,
      "z": -1,
      "name": "Rock_Volcanic"
    },
    {
      "x": -3,
      "y": 19,
      "z": -1,
      "name": "Rock_Volcanic"
    },
    {
      "x": -3,
      "y": 20,
      "z": -1,
      "name": "Rock_Volcanic"
    },
    {
      "x": -3,
      "y": 21,
      "z": -1,
      "name": "Rock_Volcanic"
    },
    {
      "x": -3,
      "y": 22,
      "z": -1,
      "name": "Rock_Volcanic_Cracked_Poisoned"
    },
    {
      "x": -3,
      "y": 23,
      "z": -1,
      "name": "Rock_Volcanic"
    },
    {
      "x": -3,
      "y": 24,
      "z": -1,
      "name": "Rock_Volcanic_Cracked_Poisoned"
    },
    {
      "x": -3,
      "y": 16,
      "z": 0,
      "name": "Rock_Volcanic"
    },
    {
      "x": -3,
      "y": 17,
      "z": 0,
      "name": "Rock_Volcanic"
    },
    {
      "x": -3,
      "y": 18,
      "z": 0,
      "name": "Rock_Volcanic"
    },
    {
      "x": -3,
      "y": 19,
      "z": 0,
      "name": "Rock_Volcanic"
    },
    {
      "x": -3,
      "y": 20,
      "z": 0,
      "name": "Rock_Volcanic"
    },
    {
      "x": -3,
      "y": 21,
      "z": 0,
      "name": "Rock_Volcanic"
    },
    {
      "x": -3,
      "y": 22,
      "z": 0,
      "name": "Rock_Volcanic_Cracked_Poisoned"
    },
    {
      "x": -3,
      "y": 16,
      "z": 1,
      "name": "Rock_Volcanic"
    },
    {
      "x": -3,
      "y": 17,
      "z": 1,
      "name": "Rock_Volcanic"
    },
    {
      "x": -3,
      "y": 18,
      "z": 1,
      "name": "Rock_Volcanic"
    },
    {
      "x": -3,
      "y": 19,
      "z": 1,
      "name": "Rock_Volcanic"
    },
    {
      "x": -3,
      "y": 20,
      "z": 1,
      "name": "Rock_Volcanic"
    },
    {
      "x": -3,
      "y": 17,
      "z": 2,
      "name": "Rock_Volcanic"
    },
    {
      "x": -3,
      "y": 18,
      "z": 2,
      "name": "Rock_Volcanic"
    },
    {
      "x": -3,
      "y": 19,
      "z": 2,
      "name": "Rock_Volcanic"
    },
    {
      "x": -2,
      "y": 19,
      "z": -4,
      "name": "Rock_Volcanic"
    },
    {
      "x": -2,
      "y": 20,
      "z": -4,
      "name": "Rock_Volcanic"
    },
    {
      "x": -2,
      "y": 21,
      "z": -4,
      "name": "Rock_Volcanic"
    },
    {
      "x": -2,
      "y": 22,
      "z": -4,
      "name": "Rock_Volcanic"
    },
    {
      "x": -2,
      "y": 17,
      "z": -3,
      "name": "Rock_Volcanic"
    },
    {
      "x": -2,
      "y": 18,
      "z": -3,
      "name": "Rock_Volcanic"
    },
    {
      "x": -2,
      "y": 19,
      "z": -3,
      "name": "Rock_Volcanic"
    },
    {
      "x": -2,
      "y": 20,
      "z": -3,
      "name": "Rock_Volcanic"
    },
    {
      "x": -2,
      "y": 21,
      "z": -3,
      "name": "Rock_Volcanic"
    },
    {
      "x": -2,
      "y": 22,
      "z": -3,
      "name": "Rock_Volcanic_Cracked_Poisoned"
    },
    {
      "x": -2,
      "y": 23,
      "z": -3,
      "name": "Rock_Volcanic"
    },
    {
      "x": -2,
      "y": 24,
      "z": -3,
      "name": "Rock_Volcanic"
    },
    {
      "x": -2,
      "y": 16,
      "z": -2,
      "name": "Rock_Volcanic"
    },
    {
      "x": -2,
      "y": 17,
      "z": -2,
      "name": "Rock_Volcanic"
    },
    {
      "x": -2,
      "y": 18,
      "z": -2,
      "name": "Rock_Volcanic"
    },
    {
      "x": -2,
      "y": 19,
      "z": -2,
      "name": "Rock_Volcanic"
    },
    {
      "x": -2,
      "y": 20,
      "z": -2,
      "name": "Rock_Volcanic"
    },
    {
      "x": -2,
      "y": 21,
      "z": -2,
      "name": "Rock_Volcanic_Cracked_Poisoned"
    },
    {
      "x": -2,
      "y": 22,
      "z": -2,
      "name": "Rock_Volcanic_Cracked_Poisoned"
    },
    {
      "x": -2,
      "y": 23,
      "z": -2,
      "name": "Rock_Volcanic_Cracked_Poisoned"
    },
    {
      "x": -2,
      "y": 24,
      "z": -2,
      "name": "Rock_Volcanic"
    },
    {
      "x": -2,
      "y": 15,
      "z": -1,
      "name": "Rock_Volcanic"
    },
    {
      "x": -2,
      "y": 16,
      "z": -1,
      "name": "Rock_Volcanic"
    },
    {
      "x": -2,
      "y": 17,
      "z": -1,
      "name": "Rock_Volcanic"
    },
    {
      "x": -2,
      "y": 18,
      "z": -1,
      "name": "Rock_Volcanic"
    },
    {
      "x": -2,
      "y": 19,
      "z": -1,
      "name": "Rock_Volcanic"
    },
    {
      "x": -2,
      "y": 20,
      "z": -1,
      "name": "Rock_Volcanic"
    },
    {
      "x": -2,
      "y": 21,
      "z": -1,
      "name": "Rock_Volcanic_Cracked_Poisoned"
    },
    {
      "x": -2,
      "y": 22,
      "z": -1,
      "name": "Rock_Volcanic_Cracked_Poisoned"
    },
    {
      "x": -2,
      "y": 23,
      "z": -1,
      "name": "Rock_Volcanic_Cracked_Poisoned"
    },
    {
      "x": -2,
      "y": 24,
      "z": -1,
      "name": "Rock_Volcanic"
    },
    {
      "x": -2,
      "y": 15,
      "z": 0,
      "name": "Rock_Volcanic"
    },
    {
      "x": -2,
      "y": 16,
      "z": 0,
      "name": "Rock_Volcanic"
    },
    {
      "x": -2,
      "y": 17,
      "z": 0,
      "name": "Rock_Volcanic"
    },
    {
      "x": -2,
      "y": 18,
      "z": 0,
      "name": "Rock_Volcanic"
    },
    {
      "x": -2,
      "y": 19,
      "z": 0,
      "name": "Rock_Volcanic"
    },
    {
      "x": -2,
      "y": 20,
      "z": 0,
      "name": "Rock_Volcanic"
    },
    {
      "x": -2,
      "y": 21,
      "z": 0,
      "name": "Rock_Volcanic_Cracked_Poisoned"
    },
    {
      "x": -2,
      "y": 22,
      "z": 0,
      "name": "Rock_Volcanic_Cracked_Poisoned"
    },
    {
      "x": -2,
      "y": 14,
      "z": 1,
      "name": "Rock_Volcanic"
    },
    {
      "x": -2,
      "y": 15,
      "z": 1,
      "name": "Rock_Volcanic"
    },
    {
      "x": -2,
      "y": 16,
      "z": 1,
      "name": "Rock_Volcanic"
    },
    {
      "x": -2,
      "y": 17,
      "z": 1,
      "name": "Rock_Volcanic"
    },
    {
      "x": -2,
      "y": 18,
      "z": 1,
      "name": "Rock_Volcanic"
    },
    {
      "x": -2,
      "y": 19,
      "z": 1,
      "name": "Rock_Volcanic"
    },
    {
      "x": -2,
      "y": 20,
      "z": 1,
      "name": "Rock_Volcanic"
    },
    {
      "x": -2,
      "y": 21,
      "z": 1,
      "name": "Rock_Volcanic"
    },
    {
      "x": -2,
      "y": 13,
      "z": 2,
      "name": "Rock_Volcanic"
    },
    {
      "x": -2,
      "y": 14,
      "z": 2,
      "name": "Rock_Volcanic"
    },
    {
      "x": -2,
      "y": 15,
      "z": 2,
      "name": "Rock_Volcanic"
    },
    {
      "x": -2,
      "y": 16,
      "z": 2,
      "name": "Rock_Volcanic"
    },
    {
      "x": -2,
      "y": 17,
      "z": 2,
      "name": "Rock_Volcanic"
    },
    {
      "x": -2,
      "y": 18,
      "z": 2,
      "name": "Rock_Volcanic"
    },
    {
      "x": -2,
      "y": 19,
      "z": 2,
      "name": "Rock_Volcanic"
    },
    {
      "x": -2,
      "y": 12,
      "z": 3,
      "name": "Rock_Volcanic"
    },
    {
      "x": -2,
      "y": 13,
      "z": 3,
      "name": "Rock_Volcanic"
    },
    {
      "x": -2,
      "y": 14,
      "z": 3,
      "name": "Rock_Volcanic"
    },
    {
      "x": -2,
      "y": 15,
      "z": 3,
      "name": "Rock_Volcanic"
    },
    {
      "x": -2,
      "y": 16,
      "z": 3,
      "name": "Rock_Volcanic"
    },
    {
      "x": -2,
      "y": 17,
      "z": 3,
      "name": "Rock_Volcanic"
    },
    {
      "x": -2,
      "y": 18,
      "z": 3,
      "name": "Rock_Volcanic"
    },
    {
      "x": -2,
      "y": 15,
      "z": 4,
      "name": "Rock_Volcanic"
    },
    {
      "x": -2,
      "y": 16,
      "z": 4,
      "name": "Rock_Volcanic"
    },
    {
      "x": -1,
      "y": 19,
      "z": -4,
      "name": "Rock_Volcanic"
    },
    {
      "x": -1,
      "y": 20,
      "z": -4,
      "name": "Rock_Volcanic"
    },
    {
      "x": -1,
      "y": 21,
      "z": -4,
      "name": "Rock_Volcanic"
    },
    {
      "x": -1,
      "y": 17,
      "z": -3,
      "name": "Rock_Volcanic"
    },
    {
      "x": -1,
      "y": 18,
      "z": -3,
      "name": "Rock_Volcanic"
    },
    {
      "x": -1,
      "y": 19,
      "z": -3,
      "name": "Rock_Volcanic"
    },
    {
      "x": -1,
      "y": 20,
      "z": -3,
      "name": "Rock_Volcanic"
    },
    {
      "x": -1,
      "y": 21,
      "z": -3,
      "name": "Rock_Volcanic"
    },
    {
      "x": -1,
      "y": 22,
      "z": -3,
      "name": "Rock_Volcanic_Cracked_Poisoned"
    },
    {
      "x": -1,
      "y": 23,
      "z": -3,
      "name": "Rock_Volcanic"
    },
    {
      "x": -1,
      "y": 15,
      "z": -2,
      "name": "Rock_Volcanic"
    },
    {
      "x": -1,
      "y": 16,
      "z": -2,
      "name": "Rock_Volcanic"
    },
    {
      "x": -1,
      "y": 17,
      "z": -2,
      "name": "Rock_Volcanic"
    },
    {
      "x": -1,
      "y": 18,
      "z": -2,
      "name": "Rock_Volcanic_Cracked_Poisoned"
    },
    {
      "x": -1,
      "y": 19,
      "z": -2,
      "name": "Rock_Volcanic"
    },
    {
      "x": -1,
      "y": 20,
      "z": -2,
      "name": "Rock_Volcanic"
    },
    {
      "x": -1,
      "y": 21,
      "z": -2,
      "name": "Rock_Volcanic_Cracked_Poisoned"
    },
    {
      "x": -1,
      "y": 22,
      "z": -2,
      "name": "Rock_Volcanic_Cracked_Poisoned"
    },
    {
      "x": -1,
      "y": 23,
      "z": -2,
      "name": "Rock_Volcanic_Cracked_Poisoned"
    },
    {
      "x": -1,
      "y": 14,
      "z": -1,
      "name": "Rock_Volcanic"
    },
    {
      "x": -1,
      "y": 15,
      "z": -1,
      "name": "Rock_Volcanic"
    },
    {
      "x": -1,
      "y": 16,
      "z": -1,
      "name": "Rock_Volcanic"
    },
    {
      "x": -1,
      "y": 17,
      "z": -1,
      "name": "Rock_Volcanic"
    },
    {
      "x": -1,
      "y": 18,
      "z": -1,
      "name": "Rock_Volcanic_Cracked_Poisoned"
    },
    {
      "x": -1,
      "y": 19,
      "z": -1,
      "name": "Rock_Volcanic"
    },
    {
      "x": -1,
      "y": 20,
      "z": -1,
      "name": "Rock_Volcanic"
    },
    {
      "x": -1,
      "y": 21,
      "z": -1,
      "name": "Rock_Volcanic_Cracked_Poisoned"
    },
    {
      "x": -1,
      "y": 22,
      "z": -1,
      "name": "Rock_Volcanic_Cracked_Poisoned"
    },
    {
      "x": -1,
      "y": 13,
      "z": 0,
      "name": "Rock_Volcanic"
    },
    {
      "x": -1,
      "y": 14,
      "z": 0,
      "name": "Rock_Volcanic"
    },
    {
      "x": -1,
      "y": 15,
      "z": 0,
      "name": "Rock_Volcanic"
    },
    {
      "x": -1,
      "y": 16,
      "z": 0,
      "name": "Rock_Volcanic"
    },
    {
      "x": -1,
      "y": 17,
      "z": 0,
      "name": "Rock_Volcanic"
    },
    {
      "x": -1,
      "y": 18,
      "z": 0,
      "name": "Rock_Volcanic_Cracked_Poisoned"
    },
    {
      "x": -1,
      "y": 19,
      "z": 0,
      "name": "Rock_Volcanic"
    },
    {
      "x": -1,
      "y": 20,
      "z": 0,
      "name": "Rock_Volcanic"
    },
    {
      "x": -1,
      "y": 21,
      "z": 0,
      "name": "Empty"
    },
    {
      "x": -1,
      "y": 11,
      "z": 1,
      "name": "Rock_Volcanic"
    },
    {
      "x": -1,
      "y": 12,
      "z": 1,
      "name": "Rock_Volcanic"
    },
    {
      "x": -1,
      "y": 13,
      "z": 1,
      "name": "Rock_Volcanic"
    },
    {
      "x": -1,
      "y": 14,
      "z": 1,
      "name": "Rock_Volcanic"
    },
    {
      "x": -1,
      "y": 15,
      "z": 1,
      "name": "Rock_Volcanic"
    },
    {
      "x": -1,
      "y": 16,
      "z": 1,
      "name": "Rock_Volcanic"
    },
    {
      "x": -1,
      "y": 17,
      "z": 1,
      "name": "Rock_Volcanic"
    },
    {
      "x": -1,
      "y": 18,
      "z": 1,
      "name": "Empty"
    },
    {
      "x": -1,
      "y": 19,
      "z": 1,
      "name": "Empty"
    },
    {
      "x": -1,
      "y": 20,
      "z": 1,
      "name": "Empty"
    },
    {
      "x": -1,
      "y": 21,
      "z": 1,
      "name": "Empty"
    },
    {
      "x": -1,
      "y": 10,
      "z": 2,
      "name": "Rock_Volcanic"
    },
    {
      "x": -1,
      "y": 11,
      "z": 2,
      "name": "Rock_Volcanic"
    },
    {
      "x": -1,
      "y": 12,
      "z": 2,
      "name": "Rock_Volcanic"
    },
    {
      "x": -1,
      "y": 13,
      "z": 2,
      "name": "Rock_Volcanic"
    },
    {
      "x": -1,
      "y": 14,
      "z": 2,
      "name": "Rock_Volcanic"
    },
    {
      "x": -1,
      "y": 15,
      "z": 2,
      "name": "Rock_Volcanic"
    },
    {
      "x": -1,
      "y": 16,
      "z": 2,
      "name": "Rock_Volcanic"
    },
    {
      "x": -1,
      "y": 17,
      "z": 2,
      "name": "Rock_Volcanic"
    },
    {
      "x": -1,
      "y": 18,
      "z": 2,
      "name": "Empty"
    },
    {
      "x": -1,
      "y": 9,
      "z": 3,
      "name": "Rock_Volcanic"
    },
    {
      "x": -1,
      "y": 10,
      "z": 3,
      "name": "Rock_Volcanic"
    },
    {
      "x": -1,
      "y": 11,
      "z": 3,
      "name": "Rock_Volcanic"
    },
    {
      "x": -1,
      "y": 12,
      "z": 3,
      "name": "Rock_Volcanic"
    },
    {
      "x": -1,
      "y": 13,
      "z": 3,
      "name": "Rock_Volcanic"
    },
    {
      "x": -1,
      "y": 14,
      "z": 3,
      "name": "Rock_Volcanic"
    },
    {
      "x": -1,
      "y": 15,
      "z": 3,
      "name": "Rock_Volcanic"
    },
    {
      "x": -1,
      "y": 16,
      "z": 3,
      "name": "Rock_Volcanic"
    },
    {
      "x": -1,
      "y": 17,
      "z": 3,
      "name": "Rock_Volcanic"
    },
    {
      "x": -1,
      "y": 18,
      "z": 3,
      "name": "Rock_Volcanic"
    },
    {
      "x": -1,
      "y": 9,
      "z": 4,
      "name": "Rock_Volcanic"
    },
    {
      "x": -1,
      "y": 10,
      "z": 4,
      "name": "Rock_Volcanic"
    },
    {
      "x": -1,
      "y": 11,
      "z": 4,
      "name": "Rock_Volcanic"
    },
    {
      "x": -1,
      "y": 12,
      "z": 4,
      "name": "Rock_Volcanic"
    },
    {
      "x": -1,
      "y": 13,
      "z": 4,
      "name": "Rock_Volcanic"
    },
    {
      "x": -1,
      "y": 14,
      "z": 4,
      "name": "Rock_Volcanic"
    },
    {
      "x": -1,
      "y": 15,
      "z": 4,
      "name": "Rock_Volcanic_Cracked_Poisoned"
    },
    {
      "x": -1,
      "y": 16,
      "z": 4,
      "name": "Rock_Volcanic"
    },
    {
      "x": -1,
      "y": 17,
      "z": 4,
      "name": "Rock_Volcanic"
    },
    {
      "x": -1,
      "y": 10,
      "z": 5,
      "name": "Rock_Volcanic"
    },
    {
      "x": -1,
      "y": 11,
      "z": 5,
      "name": "Rock_Volcanic"
    },
    {
      "x": -1,
      "y": 12,
      "z": 5,
      "name": "Rock_Volcanic"
    },
    {
      "x": -1,
      "y": 13,
      "z": 5,
      "name": "Rock_Volcanic"
    },
    {
      "x": 0,
      "y": 17,
      "z": -3,
      "name": "Rock_Volcanic"
    },
    {
      "x": 0,
      "y": 18,
      "z": -3,
      "name": "Rock_Volcanic_Cracked_Poisoned"
    },
    {
      "x": 0,
      "y": 19,
      "z": -3,
      "name": "Rock_Volcanic"
    },
    {
      "x": 0,
      "y": 20,
      "z": -3,
      "name": "Rock_Volcanic"
    },
    {
      "x": 0,
      "y": 15,
      "z": -2,
      "name": "Rock_Volcanic"
    },
    {
      "x": 0,
      "y": 16,
      "z": -2,
      "name": "Rock_Volcanic"
    },
    {
      "x": 0,
      "y": 17,
      "z": -2,
      "name": "Rock_Volcanic_Cracked_Poisoned"
    },
    {
      "x": 0,
      "y": 18,
      "z": -2,
      "name": "Rock_Volcanic_Cracked_Poisoned"
    },
    {
      "x": 0,
      "y": 19,
      "z": -2,
      "name": "Rock_Volcanic_Cracked_Poisoned"
    },
    {
      "x": 0,
      "y": 20,
      "z": -2,
      "name": "Rock_Volcanic"
    },
    {
      "x": 0,
      "y": 21,
      "z": -2,
      "name": "Rock_Volcanic_Cracked_Poisoned"
    },
    {
      "x": 0,
      "y": 13,
      "z": -1,
      "name": "Rock_Volcanic"
    },
    {
      "x": 0,
      "y": 14,
      "z": -1,
      "name": "Rock_Volcanic"
    },
    {
      "x": 0,
      "y": 15,
      "z": -1,
      "name": "Rock_Volcanic"
    },
    {
      "x": 0,
      "y": 16,
      "z": -1,
      "name": "Rock_Volcanic"
    },
    {
      "x": 0,
      "y": 17,
      "z": -1,
      "name": "Rock_Volcanic_Cracked_Poisoned"
    },
    {
      "x": 0,
      "y": 18,
      "z": -1,
      "name": "Rock_Volcanic_Cracked_Poisoned"
    },
    {
      "x": 0,
      "y": 19,
      "z": -1,
      "name": "Rock_Volcanic_Cracked_Poisoned"
    },
    {
      "x": 0,
      "y": 20,
      "z": -1,
      "name": "Rock_Volcanic"
    },
    {
      "x": 0,
      "y": 21,
      "z": -1,
      "name": "Rock_Volcanic_Cracked_Poisoned"
    },
    {
      "x": 0,
      "y": 12,
      "z": 0,
      "name": "Rock_Volcanic"
    },
    {
      "x": 0,
      "y": 13,
      "z": 0,
      "name": "Rock_Volcanic"
    },
    {
      "x": 0,
      "y": 14,
      "z": 0,
      "name": "Rock_Volcanic"
    },
    {
      "x": 0,
      "y": 15,
      "z": 0,
      "name": "Rock_Volcanic"
    },
    {
      "x": 0,
      "y": 16,
      "z": 0,
      "name": "Rock_Volcanic"
    },
    {
      "x": 0,
      "y": 17,
      "z": 0,
      "name": "Rock_Volcanic_Cracked_Poisoned"
    },
    {
      "x": 0,
      "y": 18,
      "z": 0,
      "name": "Rock_Volcanic_Cracked_Poisoned"
    },
    {
      "x": 0,
      "y": 19,
      "z": 0,
      "name": "Rock_Volcanic_Cracked_Poisoned"
    },
    {
      "x": 0,
      "y": 20,
      "z": 0,
      "name": "Rock_Volcanic"
    },
    {
      "x": 0,
      "y": 21,
      "z": 0,
      "name": "Rock_Volcanic_Cracked_Poisoned"
    },
    {
      "x": 0,
      "y": 10,
      "z": 1,
      "name": "Rock_Volcanic"
    },
    {
      "x": 0,
      "y": 11,
      "z": 1,
      "name": "Rock_Volcanic"
    },
    {
      "x": 0,
      "y": 12,
      "z": 1,
      "name": "Rock_Volcanic"
    },
    {
      "x": 0,
      "y": 13,
      "z": 1,
      "name": "Rock_Volcanic"
    },
    {
      "x": 0,
      "y": 14,
      "z": 1,
      "name": "Rock_Volcanic"
    },
    {
      "x": 0,
      "y": 15,
      "z": 1,
      "name": "Rock_Volcanic"
    },
    {
      "x": 0,
      "y": 16,
      "z": 1,
      "name": "Rock_Volcanic"
    },
    {
      "x": 0,
      "y": 17,
      "z": 1,
      "name": "Rock_Volcanic"
    },
    {
      "x": 0,
      "y": 18,
      "z": 1,
      "name": "Rock_Volcanic_Cracked_Poisoned"
    },
    {
      "x": 0,
      "y": 19,
      "z": 1,
      "name": "Rock_Volcanic"
    },
    {
      "x": 0,
      "y": 20,
      "z": 1,
      "name": "Rock_Volcanic"
    },
    {
      "x": 0,
      "y": 9,
      "z": 2,
      "name": "Rock_Volcanic"
    },
    {
      "x": 0,
      "y": 10,
      "z": 2,
      "name": "Rock_Volcanic"
    },
    {
      "x": 0,
      "y": 11,
      "z": 2,
      "name": "Rock_Volcanic"
    },
    {
      "x": 0,
      "y": 12,
      "z": 2,
      "name": "Rock_Volcanic"
    },
    {
      "x": 0,
      "y": 13,
      "z": 2,
      "name": "Rock_Volcanic"
    },
    {
      "x": 0,
      "y": 14,
      "z": 2,
      "name": "Rock_Volcanic"
    },
    {
      "x": 0,
      "y": 15,
      "z": 2,
      "name": "Rock_Volcanic"
    },
    {
      "x": 0,
      "y": 16,
      "z": 2,
      "name": "Rock_Volcanic"
    },
    {
      "x": 0,
      "y": 17,
      "z": 2,
      "name": "Rock_Volcanic"
    },
    {
      "x": 0,
      "y": 18,
      "z": 2,
      "name": "Empty"
    },
    {
      "x": 0,
      "y": 9,
      "z": 3,
      "name": "Rock_Volcanic"
    },
    {
      "x": 0,
      "y": 10,
      "z": 3,
      "name": "Rock_Volcanic"
    },
    {
      "x": 0,
      "y": 11,
      "z": 3,
      "name": "Rock_Volcanic"
    },
    {
      "x": 0,
      "y": 12,
      "z": 3,
      "name": "Rock_Volcanic"
    },
    {
      "x": 0,
      "y": 13,
      "z": 3,
      "name": "Rock_Volcanic"
    },
    {
      "x": 0,
      "y": 14,
      "z": 3,
      "name": "Rock_Volcanic"
    },
    {
      "x": 0,
      "y": 15,
      "z": 3,
      "name": "Rock_Volcanic_Cracked_Poisoned"
    },
    {
      "x": 0,
      "y": 16,
      "z": 3,
      "name": "Rock_Volcanic"
    },
    {
      "x": 0,
      "y": 17,
      "z": 3,
      "name": "Rock_Volcanic"
    },
    {
      "x": 0,
      "y": 18,
      "z": 3,
      "name": "Rock_Volcanic"
    },
    {
      "x": 0,
      "y": 8,
      "z": 4,
      "name": "Rock_Volcanic"
    },
    {
      "x": 0,
      "y": 9,
      "z": 4,
      "name": "Rock_Volcanic"
    },
    {
      "x": 0,
      "y": 10,
      "z": 4,
      "name": "Rock_Volcanic"
    },
    {
      "x": 0,
      "y": 11,
      "z": 4,
      "name": "Rock_Volcanic"
    },
    {
      "x": 0,
      "y": 12,
      "z": 4,
      "name": "Rock_Volcanic"
    },
    {
      "x": 0,
      "y": 13,
      "z": 4,
      "name": "Rock_Volcanic"
    },
    {
      "x": 0,
      "y": 14,
      "z": 4,
      "name": "Rock_Volcanic"
    },
    {
      "x": 0,
      "y": 15,
      "z": 4,
      "name": "Rock_Volcanic_Cracked_Poisoned"
    },
    {
      "x": 0,
      "y": 16,
      "z": 4,
      "name": "Rock_Volcanic_Cracked_Poisoned"
    },
    {
      "x": 0,
      "y": 17,
      "z": 4,
      "name": "Rock_Volcanic"
    },
    {
      "x": 0,
      "y": 8,
      "z": 5,
      "name": "Rock_Volcanic"
    },
    {
      "x": 0,
      "y": 9,
      "z": 5,
      "name": "Rock_Volcanic"
    },
    {
      "x": 0,
      "y": 10,
      "z": 5,
      "name": "Rock_Volcanic"
    },
    {
      "x": 0,
      "y": 11,
      "z": 5,
      "name": "Rock_Volcanic"
    },
    {
      "x": 0,
      "y": 12,
      "z": 5,
      "name": "Rock_Volcanic"
    },
    {
      "x": 0,
      "y": 13,
      "z": 5,
      "name": "Rock_Volcanic"
    },
    {
      "x": 0,
      "y": 14,
      "z": 5,
      "name": "Rock_Volcanic_Cracked_Poisoned"
    },
    {
      "x": 0,
      "y": 15,
      "z": 5,
      "name": "Rock_Volcanic_Cracked_Poisoned"
    },
    {
      "x": 0,
      "y": 9,
      "z": 6,
      "name": "Rock_Volcanic"
    },
    {
      "x": 0,
      "y": 10,
      "z": 6,
      "name": "Rock_Volcanic"
    },
    {
      "x": 0,
      "y": 11,
      "z": 6,
      "name": "Rock_Volcanic"
    },
    {
      "x": 0,
      "y": 12,
      "z": 6,
      "name": "Rock_Volcanic"
    },
    {
      "x": 0,
      "y": 13,
      "z": 6,
      "name": "Rock_Volcanic"
    },
    {
      "x": 0,
      "y": 14,
      "z": 6,
      "name": "Rock_Volcanic_Cracked_Poisoned"
    },
    {
      "x": 1,
      "y": 16,
      "z": -2,
      "name": "Rock_Volcanic"
    },
    {
      "x": 1,
      "y": 17,
      "z": -2,
      "name": "Rock_Volcanic_Cracked_Poisoned"
    },
    {
      "x": 1,
      "y": 18,
      "z": -2,
      "name": "Rock_Volcanic_Cracked_Poisoned"
    },
    {
      "x": 1,
      "y": 12,
      "z": -1,
      "name": "Rock_Volcanic"
    },
    {
      "x": 1,
      "y": 13,
      "z": -1,
      "name": "Rock_Volcanic"
    },
    {
      "x": 1,
      "y": 14,
      "z": -1,
      "name": "Rock_Volcanic"
    },
    {
      "x": 1,
      "y": 15,
      "z": -1,
      "name": "Rock_Volcanic"
    },
    {
      "x": 1,
      "y": 16,
      "z": -1,
      "name": "Rock_Volcanic"
    },
    {
      "x": 1,
      "y": 17,
      "z": -1,
      "name": "Rock_Volcanic_Cracked_Poisoned"
    },
    {
      "x": 1,
      "y": 18,
      "z": -1,
      "name": "Rock_Volcanic_Cracked_Poisoned"
    },
    {
      "x": 1,
      "y": 19,
      "z": -1,
      "name": "Rock_Volcanic_Cracked_Poisoned"
    },
    {
      "x": 1,
      "y": 11,
      "z": 0,
      "name": "Rock_Volcanic"
    },
    {
      "x": 1,
      "y": 12,
      "z": 0,
      "name": "Rock_Volcanic"
    },
    {
      "x": 1,
      "y": 13,
      "z": 0,
      "name": "Rock_Volcanic"
    },
    {
      "x": 1,
      "y": 14,
      "z": 0,
      "name": "Rock_Volcanic"
    },
    {
      "x": 1,
      "y": 15,
      "z": 0,
      "name": "Rock_Volcanic"
    },
    {
      "x": 1,
      "y": 16,
      "z": 0,
      "name": "Rock_Volcanic"
    },
    {
      "x": 1,
      "y": 17,
      "z": 0,
      "name": "Rock_Volcanic_Cracked_Poisoned"
    },
    {
      "x": 1,
      "y": 18,
      "z": 0,
      "name": "Rock_Volcanic_Cracked_Poisoned"
    },
    {
      "x": 1,
      "y": 19,
      "z": 0,
      "name": "Rock_Volcanic_Cracked_Poisoned"
    },
    {
      "x": 1,
      "y": 9,
      "z": 1,
      "name": "Rock_Volcanic"
    },
    {
      "x": 1,
      "y": 10,
      "z": 1,
      "name": "Rock_Volcanic"
    },
    {
      "x": 1,
      "y": 11,
      "z": 1,
      "name": "Rock_Volcanic"
    },
    {
      "x": 1,
      "y": 12,
      "z": 1,
      "name": "Rock_Volcanic"
    },
    {
      "x": 1,
      "y": 13,
      "z": 1,
      "name": "Rock_Volcanic"
    },
    {
      "x": 1,
      "y": 14,
      "z": 1,
      "name": "Rock_Volcanic"
    },
    {
      "x": 1,
      "y": 15,
      "z": 1,
      "name": "Rock_Volcanic"
    },
    {
      "x": 1,
      "y": 16,
      "z": 1,
      "name": "Rock_Volcanic"
    },
    {
      "x": 1,
      "y": 17,
      "z": 1,
      "name": "Rock_Volcanic"
    },
    {
      "x": 1,
      "y": 18,
      "z": 1,
      "name": "Rock_Volcanic_Cracked_Poisoned"
    },
    {
      "x": 1,
      "y": 8,
      "z": 2,
      "name": "Rock_Volcanic"
    },
    {
      "x": 1,
      "y": 9,
      "z": 2,
      "name": "Rock_Volcanic"
    },
    {
      "x": 1,
      "y": 10,
      "z": 2,
      "name": "Rock_Volcanic"
    },
    {
      "x": 1,
      "y": 11,
      "z": 2,
      "name": "Rock_Volcanic"
    },
    {
      "x": 1,
      "y": 12,
      "z": 2,
      "name": "Rock_Volcanic"
    },
    {
      "x": 1,
      "y": 13,
      "z": 2,
      "name": "Rock_Volcanic"
    },
    {
      "x": 1,
      "y": 14,
      "z": 2,
      "name": "Rock_Volcanic"
    },
    {
      "x": 1,
      "y": 15,
      "z": 2,
      "name": "Rock_Volcanic"
    },
    {
      "x": 1,
      "y": 16,
      "z": 2,
      "name": "Rock_Volcanic_Cracked_Poisoned"
    },
    {
      "x": 1,
      "y": 17,
      "z": 2,
      "name": "Rock_Volcanic"
    },
    {
      "x": 1,
      "y": 18,
      "z": 2,
      "name": "Rock_Volcanic"
    },
    {
      "x": 1,
      "y": 8,
      "z": 3,
      "name": "Rock_Volcanic"
    },
    {
      "x": 1,
      "y": 9,
      "z": 3,
      "name": "Rock_Volcanic"
    },
    {
      "x": 1,
      "y": 10,
      "z": 3,
      "name": "Rock_Volcanic"
    },
    {
      "x": 1,
      "y": 11,
      "z": 3,
      "name": "Rock_Volcanic"
    },
    {
      "x": 1,
      "y": 12,
      "z": 3,
      "name": "Rock_Volcanic"
    },
    {
      "x": 1,
      "y": 13,
      "z": 3,
      "name": "Rock_Volcanic"
    },
    {
      "x": 1,
      "y": 14,
      "z": 3,
      "name": "Rock_Volcanic"
    },
    {
      "x": 1,
      "y": 15,
      "z": 3,
      "name": "Rock_Volcanic_Cracked_Poisoned"
    },
    {
      "x": 1,
      "y": 16,
      "z": 3,
      "name": "Rock_Volcanic_Cracked_Poisoned"
    },
    {
      "x": 1,
      "y": 17,
      "z": 3,
      "name": "Rock_Volcanic"
    },
    {
      "x": 1,
      "y": 18,
      "z": 3,
      "name": "Rock_Volcanic"
    },
    {
      "x": 1,
      "y": 8,
      "z": 4,
      "name": "Rock_Volcanic"
    },
    {
      "x": 1,
      "y": 9,
      "z": 4,
      "name": "Rock_Volcanic"
    },
    {
      "x": 1,
      "y": 10,
      "z": 4,
      "name": "Rock_Volcanic"
    },
    {
      "x": 1,
      "y": 11,
      "z": 4,
      "name": "Rock_Volcanic"
    },
    {
      "x": 1,
      "y": 12,
      "z": 4,
      "name": "Rock_Volcanic"
    },
    {
      "x": 1,
      "y": 13,
      "z": 4,
      "name": "Rock_Volcanic"
    },
    {
      "x": 1,
      "y": 14,
      "z": 4,
      "name": "Rock_Volcanic"
    },
    {
      "x": 1,
      "y": 15,
      "z": 4,
      "name": "Rock_Volcanic_Cracked_Poisoned"
    },
    {
      "x": 1,
      "y": 16,
      "z": 4,
      "name": "Rock_Volcanic_Cracked_Poisoned"
    },
    {
      "x": 1,
      "y": 17,
      "z": 4,
      "name": "Rock_Volcanic"
    },
    {
      "x": 1,
      "y": 7,
      "z": 5,
      "name": "Rock_Volcanic"
    },
    {
      "x": 1,
      "y": 8,
      "z": 5,
      "name": "Rock_Volcanic"
    },
    {
      "x": 1,
      "y": 9,
      "z": 5,
      "name": "Rock_Volcanic"
    },
    {
      "x": 1,
      "y": 10,
      "z": 5,
      "name": "Rock_Volcanic"
    },
    {
      "x": 1,
      "y": 11,
      "z": 5,
      "name": "Rock_Volcanic"
    },
    {
      "x": 1,
      "y": 12,
      "z": 5,
      "name": "Rock_Volcanic"
    },
    {
      "x": 1,
      "y": 13,
      "z": 5,
      "name": "Rock_Volcanic"
    },
    {
      "x": 1,
      "y": 14,
      "z": 5,
      "name": "Rock_Volcanic_Cracked_Poisoned"
    },
    {
      "x": 1,
      "y": 15,
      "z": 5,
      "name": "Rock_Volcanic_Cracked_Poisoned"
    },
    {
      "x": 1,
      "y": 7,
      "z": 6,
      "name": "Rock_Volcanic"
    },
    {
      "x": 1,
      "y": 8,
      "z": 6,
      "name": "Rock_Volcanic"
    },
    {
      "x": 1,
      "y": 9,
      "z": 6,
      "name": "Rock_Volcanic"
    },
    {
      "x": 1,
      "y": 10,
      "z": 6,
      "name": "Rock_Volcanic"
    },
    {
      "x": 1,
      "y": 11,
      "z": 6,
      "name": "Rock_Volcanic"
    },
    {
      "x": 1,
      "y": 12,
      "z": 6,
      "name": "Rock_Volcanic"
    },
    {
      "x": 1,
      "y": 13,
      "z": 6,
      "name": "Rock_Volcanic"
    },
    {
      "x": 1,
      "y": 14,
      "z": 6,
      "name": "Rock_Volcanic_Cracked_Poisoned"
    },
    {
      "x": 1,
      "y": 8,
      "z": 7,
      "name": "Rock_Volcanic"
    },
    {
      "x": 1,
      "y": 9,
      "z": 7,
      "name": "Rock_Volcanic"
    },
    {
      "x": 1,
      "y": 10,
      "z": 7,
      "name": "Rock_Volcanic"
    },
    {
      "x": 1,
      "y": 11,
      "z": 7,
      "name": "Rock_Volcanic"
    },
    {
      "x": 2,
      "y": 12,
      "z": -1,
      "name": "Rock_Volcanic"
    },
    {
      "x": 2,
      "y": 13,
      "z": -1,
      "name": "Rock_Volcanic"
    },
    {
      "x": 2,
      "y": 14,
      "z": -1,
      "name": "Rock_Volcanic"
    },
    {
      "x": 2,
      "y": 15,
      "z": -1,
      "name": "Rock_Volcanic"
    },
    {
      "x": 2,
      "y": 16,
      "z": -1,
      "name": "Rock_Volcanic"
    },
    {
      "x": 2,
      "y": 17,
      "z": -1,
      "name": "Rock_Volcanic_Cracked_Poisoned"
    },
    {
      "x": 2,
      "y": 11,
      "z": 0,
      "name": "Rock_Volcanic"
    },
    {
      "x": 2,
      "y": 12,
      "z": 0,
      "name": "Rock_Volcanic"
    },
    {
      "x": 2,
      "y": 13,
      "z": 0,
      "name": "Rock_Volcanic"
    },
    {
      "x": 2,
      "y": 14,
      "z": 0,
      "name": "Rock_Volcanic"
    },
    {
      "x": 2,
      "y": 15,
      "z": 0,
      "name": "Rock_Volcanic"
    },
    {
      "x": 2,
      "y": 16,
      "z": 0,
      "name": "Rock_Volcanic"
    },
    {
      "x": 2,
      "y": 17,
      "z": 0,
      "name": "Rock_Volcanic_Cracked_Poisoned"
    },
    {
      "x": 2,
      "y": 18,
      "z": 0,
      "name": "Rock_Volcanic_Cracked_Poisoned"
    },
    {
      "x": 2,
      "y": 9,
      "z": 1,
      "name": "Rock_Volcanic"
    },
    {
      "x": 2,
      "y": 10,
      "z": 1,
      "name": "Rock_Volcanic"
    },
    {
      "x": 2,
      "y": 11,
      "z": 1,
      "name": "Rock_Volcanic"
    },
    {
      "x": 2,
      "y": 12,
      "z": 1,
      "name": "Rock_Volcanic"
    },
    {
      "x": 2,
      "y": 13,
      "z": 1,
      "name": "Rock_Volcanic"
    },
    {
      "x": 2,
      "y": 14,
      "z": 1,
      "name": "Rock_Volcanic"
    },
    {
      "x": 2,
      "y": 15,
      "z": 1,
      "name": "Rock_Volcanic"
    },
    {
      "x": 2,
      "y": 16,
      "z": 1,
      "name": "Rock_Volcanic_Cracked_Poisoned"
    },
    {
      "x": 2,
      "y": 17,
      "z": 1,
      "name": "Rock_Volcanic"
    },
    {
      "x": 2,
      "y": 18,
      "z": 1,
      "name": "Rock_Volcanic_Cracked_Poisoned"
    },
    {
      "x": 2,
      "y": 8,
      "z": 2,
      "name": "Rock_Volcanic"
    },
    {
      "x": 2,
      "y": 9,
      "z": 2,
      "name": "Rock_Volcanic"
    },
    {
      "x": 2,
      "y": 10,
      "z": 2,
      "name": "Rock_Volcanic"
    },
    {
      "x": 2,
      "y": 11,
      "z": 2,
      "name": "Rock_Volcanic"
    },
    {
      "x": 2,
      "y": 12,
      "z": 2,
      "name": "Rock_Volcanic"
    },
    {
      "x": 2,
      "y": 13,
      "z": 2,
      "name": "Rock_Volcanic"
    },
    {
      "x": 2,
      "y": 14,
      "z": 2,
      "name": "Rock_Volcanic"
    },
    {
      "x": 2,
      "y": 15,
      "z": 2,
      "name": "Rock_Volcanic_Cracked_Poisoned"
    },
    {
      "x": 2,
      "y": 16,
      "z": 2,
      "name": "Rock_Volcanic_Cracked_Poisoned"
    },
    {
      "x": 2,
      "y": 17,
      "z": 2,
      "name": "Rock_Volcanic_Cracked_Poisoned"
    },
    {
      "x": 2,
      "y": 7,
      "z": 3,
      "name": "Rock_Volcanic"
    },
    {
      "x": 2,
      "y": 8,
      "z": 3,
      "name": "Rock_Volcanic"
    },
    {
      "x": 2,
      "y": 9,
      "z": 3,
      "name": "Rock_Volcanic"
    },
    {
      "x": 2,
      "y": 10,
      "z": 3,
      "name": "Rock_Volcanic"
    },
    {
      "x": 2,
      "y": 11,
      "z": 3,
      "name": "Rock_Volcanic"
    },
    {
      "x": 2,
      "y": 12,
      "z": 3,
      "name": "Rock_Volcanic"
    },
    {
      "x": 2,
      "y": 13,
      "z": 3,
      "name": "Rock_Volcanic"
    },
    {
      "x": 2,
      "y": 14,
      "z": 3,
      "name": "Rock_Volcanic"
    },
    {
      "x": 2,
      "y": 15,
      "z": 3,
      "name": "Rock_Volcanic_Cracked_Poisoned"
    },
    {
      "x": 2,
      "y": 16,
      "z": 3,
      "name": "Rock_Volcanic_Cracked_Poisoned"
    },
    {
      "x": 2,
      "y": 7,
      "z": 4,
      "name": "Rock_Volcanic"
    },
    {
      "x": 2,
      "y": 8,
      "z": 4,
      "name": "Rock_Volcanic"
    },
    {
      "x": 2,
      "y": 9,
      "z": 4,
      "name": "Rock_Volcanic"
    },
    {
      "x": 2,
      "y": 10,
      "z": 4,
      "name": "Rock_Volcanic"
    },
    {
      "x": 2,
      "y": 11,
      "z": 4,
      "name": "Rock_Volcanic"
    },
    {
      "x": 2,
      "y": 12,
      "z": 4,
      "name": "Rock_Volcanic"
    },
    {
      "x": 2,
      "y": 13,
      "z": 4,
      "name": "Rock_Volcanic"
    },
    {
      "x": 2,
      "y": 14,
      "z": 4,
      "name": "Rock_Volcanic_Cracked_Poisoned"
    },
    {
      "x": 2,
      "y": 15,
      "z": 4,
      "name": "Rock_Volcanic_Cracked_Poisoned"
    },
    {
      "x": 2,
      "y": 16,
      "z": 4,
      "name": "Rock_Volcanic_Cracked_Poisoned"
    },
    {
      "x": 2,
      "y": 6,
      "z": 5,
      "name": "Rock_Volcanic"
    },
    {
      "x": 2,
      "y": 7,
      "z": 5,
      "name": "Rock_Volcanic"
    },
    {
      "x": 2,
      "y": 8,
      "z": 5,
      "name": "Rock_Volcanic"
    },
    {
      "x": 2,
      "y": 9,
      "z": 5,
      "name": "Rock_Volcanic"
    },
    {
      "x": 2,
      "y": 10,
      "z": 5,
      "name": "Rock_Volcanic"
    },
    {
      "x": 2,
      "y": 11,
      "z": 5,
      "name": "Rock_Volcanic"
    },
    {
      "x": 2,
      "y": 12,
      "z": 5,
      "name": "Rock_Volcanic"
    },
    {
      "x": 2,
      "y": 13,
      "z": 5,
      "name": "Rock_Volcanic"
    },
    {
      "x": 2,
      "y": 14,
      "z": 5,
      "name": "Rock_Volcanic_Cracked_Poisoned"
    },
    {
      "x": 2,
      "y": 15,
      "z": 5,
      "name": "Rock_Volcanic_Cracked_Poisoned"
    },
    {
      "x": 2,
      "y": 6,
      "z": 6,
      "name": "Rock_Volcanic"
    },
    {
      "x": 2,
      "y": 7,
      "z": 6,
      "name": "Rock_Volcanic"
    },
    {
      "x": 2,
      "y": 8,
      "z": 6,
      "name": "Rock_Volcanic"
    },
    {
      "x": 2,
      "y": 9,
      "z": 6,
      "name": "Rock_Volcanic"
    },
    {
      "x": 2,
      "y": 10,
      "z": 6,
      "name": "Rock_Volcanic"
    },
    {
      "x": 2,
      "y": 11,
      "z": 6,
      "name": "Rock_Volcanic"
    },
    {
      "x": 2,
      "y": 12,
      "z": 6,
      "name": "Rock_Volcanic"
    },
    {
      "x": 2,
      "y": 13,
      "z": 6,
      "name": "Rock_Volcanic"
    },
    {
      "x": 2,
      "y": 14,
      "z": 6,
      "name": "Rock_Volcanic_Cracked_Poisoned"
    },
    {
      "x": 2,
      "y": 6,
      "z": 7,
      "name": "Rock_Volcanic"
    },
    {
      "x": 2,
      "y": 7,
      "z": 7,
      "name": "Rock_Volcanic"
    },
    {
      "x": 2,
      "y": 8,
      "z": 7,
      "name": "Rock_Volcanic"
    },
    {
      "x": 2,
      "y": 9,
      "z": 7,
      "name": "Rock_Volcanic"
    },
    {
      "x": 2,
      "y": 10,
      "z": 7,
      "name": "Rock_Volcanic"
    },
    {
      "x": 2,
      "y": 11,
      "z": 7,
      "name": "Rock_Volcanic"
    },
    {
      "x": 2,
      "y": 12,
      "z": 7,
      "name": "Rock_Volcanic"
    },
    {
      "x": 2,
      "y": 13,
      "z": 7,
      "name": "Rock_Volcanic"
    },
    {
      "x": 2,
      "y": 14,
      "z": 7,
      "name": "Rock_Volcanic"
    },
    {
      "x": 2,
      "y": 7,
      "z": 8,
      "name": "Rock_Volcanic"
    },
    {
      "x": 2,
      "y": 8,
      "z": 8,
      "name": "Rock_Volcanic"
    },
    {
      "x": 2,
      "y": 9,
      "z": 8,
      "name": "Rock_Volcanic"
    },
    {
      "x": 2,
      "y": 10,
      "z": 8,
      "name": "Rock_Volcanic"
    },
    {
      "x": 3,
      "y": 11,
      "z": 0,
      "name": "Rock_Volcanic"
    },
    {
      "x": 3,
      "y": 12,
      "z": 0,
      "name": "Rock_Volcanic"
    },
    {
      "x": 3,
      "y": 13,
      "z": 0,
      "name": "Rock_Volcanic"
    },
    {
      "x": 3,
      "y": 14,
      "z": 0,
      "name": "Rock_Volcanic"
    },
    {
      "x": 3,
      "y": 15,
      "z": 0,
      "name": "Rock_Volcanic"
    },
    {
      "x": 3,
      "y": 16,
      "z": 0,
      "name": "Rock_Volcanic"
    },
    {
      "x": 3,
      "y": 9,
      "z": 1,
      "name": "Rock_Volcanic"
    },
    {
      "x": 3,
      "y": 10,
      "z": 1,
      "name": "Rock_Volcanic"
    },
    {
      "x": 3,
      "y": 11,
      "z": 1,
      "name": "Rock_Volcanic"
    },
    {
      "x": 3,
      "y": 12,
      "z": 1,
      "name": "Rock_Volcanic"
    },
    {
      "x": 3,
      "y": 13,
      "z": 1,
      "name": "Rock_Volcanic"
    },
    {
      "x": 3,
      "y": 14,
      "z": 1,
      "name": "Rock_Volcanic"
    },
    {
      "x": 3,
      "y": 15,
      "z": 1,
      "name": "Rock_Volcanic"
    },
    {
      "x": 3,
      "y": 16,
      "z": 1,
      "name": "Rock_Volcanic_Cracked_Poisoned"
    },
    {
      "x": 3,
      "y": 8,
      "z": 2,
      "name": "Rock_Volcanic"
    },
    {
      "x": 3,
      "y": 9,
      "z": 2,
      "name": "Rock_Volcanic"
    },
    {
      "x": 3,
      "y": 10,
      "z": 2,
      "name": "Rock_Volcanic"
    },
    {
      "x": 3,
      "y": 11,
      "z": 2,
      "name": "Rock_Volcanic"
    },
    {
      "x": 3,
      "y": 12,
      "z": 2,
      "name": "Rock_Volcanic"
    },
    {
      "x": 3,
      "y": 13,
      "z": 2,
      "name": "Rock_Volcanic"
    },
    {
      "x": 3,
      "y": 14,
      "z": 2,
      "name": "Rock_Volcanic"
    },
    {
      "x": 3,
      "y": 15,
      "z": 2,
      "name": "Rock_Volcanic_Cracked_Poisoned"
    },
    {
      "x": 3,
      "y": 16,
      "z": 2,
      "name": "Rock_Volcanic_Cracked_Poisoned"
    },
    {
      "x": 3,
      "y": 7,
      "z": 3,
      "name": "Rock_Volcanic"
    },
    {
      "x": 3,
      "y": 8,
      "z": 3,
      "name": "Rock_Volcanic"
    },
    {
      "x": 3,
      "y": 9,
      "z": 3,
      "name": "Rock_Volcanic"
    },
    {
      "x": 3,
      "y": 10,
      "z": 3,
      "name": "Rock_Volcanic"
    },
    {
      "x": 3,
      "y": 11,
      "z": 3,
      "name": "Rock_Volcanic"
    },
    {
      "x": 3,
      "y": 12,
      "z": 3,
      "name": "Rock_Volcanic"
    },
    {
      "x": 3,
      "y": 13,
      "z": 3,
      "name": "Rock_Volcanic"
    },
    {
      "x": 3,
      "y": 14,
      "z": 3,
      "name": "Rock_Volcanic"
    },
    {
      "x": 3,
      "y": 15,
      "z": 3,
      "name": "Rock_Volcanic_Cracked_Poisoned"
    },
    {
      "x": 3,
      "y": 16,
      "z": 3,
      "name": "Rock_Volcanic_Cracked_Poisoned"
    },
    {
      "x": 3,
      "y": 6,
      "z": 4,
      "name": "Rock_Volcanic"
    },
    {
      "x": 3,
      "y": 7,
      "z": 4,
      "name": "Rock_Volcanic"
    },
    {
      "x": 3,
      "y": 8,
      "z": 4,
      "name": "Rock_Volcanic"
    },
    {
      "x": 3,
      "y": 9,
      "z": 4,
      "name": "Rock_Volcanic"
    },
    {
      "x": 3,
      "y": 10,
      "z": 4,
      "name": "Rock_Volcanic"
    },
    {
      "x": 3,
      "y": 11,
      "z": 4,
      "name": "Rock_Volcanic"
    },
    {
      "x": 3,
      "y": 12,
      "z": 4,
      "name": "Rock_Volcanic"
    },
    {
      "x": 3,
      "y": 13,
      "z": 4,
      "name": "Rock_Volcanic"
    },
    {
      "x": 3,
      "y": 14,
      "z": 4,
      "name": "Rock_Volcanic"
    },
    {
      "x": 3,
      "y": 15,
      "z": 4,
      "name": "Rock_Volcanic_Cracked_Poisoned"
    },
    {
      "x": 3,
      "y": 16,
      "z": 4,
      "name": "Rock_Volcanic_Cracked_Poisoned"
    },
    {
      "x": 3,
      "y": 6,
      "z": 5,
      "name": "Rock_Volcanic"
    },
    {
      "x": 3,
      "y": 7,
      "z": 5,
      "name": "Rock_Volcanic"
    },
    {
      "x": 3,
      "y": 8,
      "z": 5,
      "name": "Rock_Volcanic"
    },
    {
      "x": 3,
      "y": 9,
      "z": 5,
      "name": "Rock_Volcanic"
    },
    {
      "x": 3,
      "y": 10,
      "z": 5,
      "name": "Rock_Volcanic"
    },
    {
      "x": 3,
      "y": 11,
      "z": 5,
      "name": "Rock_Volcanic"
    },
    {
      "x": 3,
      "y": 12,
      "z": 5,
      "name": "Rock_Volcanic"
    },
    {
      "x": 3,
      "y": 13,
      "z": 5,
      "name": "Rock_Volcanic"
    },
    {
      "x": 3,
      "y": 14,
      "z": 5,
      "name": "Rock_Volcanic"
    },
    {
      "x": 3,
      "y": 5,
      "z": 6,
      "name": "Rock_Volcanic"
    },
    {
      "x": 3,
      "y": 6,
      "z": 6,
      "name": "Rock_Volcanic"
    },
    {
      "x": 3,
      "y": 7,
      "z": 6,
      "name": "Rock_Volcanic"
    },
    {
      "x": 3,
      "y": 8,
      "z": 6,
      "name": "Rock_Volcanic"
    },
    {
      "x": 3,
      "y": 9,
      "z": 6,
      "name": "Rock_Volcanic"
    },
    {
      "x": 3,
      "y": 10,
      "z": 6,
      "name": "Rock_Volcanic"
    },
    {
      "x": 3,
      "y": 11,
      "z": 6,
      "name": "Rock_Volcanic"
    },
    {
      "x": 3,
      "y": 12,
      "z": 6,
      "name": "Rock_Volcanic"
    },
    {
      "x": 3,
      "y": 13,
      "z": 6,
      "name": "Rock_Volcanic"
    },
    {
      "x": 3,
      "y": 14,
      "z": 6,
      "name": "Rock_Volcanic"
    },
    {
      "x": 3,
      "y": 5,
      "z": 7,
      "name": "Rock_Volcanic"
    },
    {
      "x": 3,
      "y": 6,
      "z": 7,
      "name": "Rock_Volcanic"
    },
    {
      "x": 3,
      "y": 7,
      "z": 7,
      "name": "Rock_Volcanic"
    },
    {
      "x": 3,
      "y": 8,
      "z": 7,
      "name": "Rock_Volcanic"
    },
    {
      "x": 3,
      "y": 9,
      "z": 7,
      "name": "Rock_Volcanic"
    },
    {
      "x": 3,
      "y": 10,
      "z": 7,
      "name": "Rock_Volcanic"
    },
    {
      "x": 3,
      "y": 11,
      "z": 7,
      "name": "Rock_Volcanic"
    },
    {
      "x": 3,
      "y": 12,
      "z": 7,
      "name": "Rock_Volcanic"
    },
    {
      "x": 3,
      "y": 13,
      "z": 7,
      "name": "Rock_Volcanic"
    },
    {
      "x": 3,
      "y": 14,
      "z": 7,
      "name": "Rock_Volcanic"
    },
    {
      "x": 3,
      "y": 5,
      "z": 8,
      "name": "Rock_Volcanic"
    },
    {
      "x": 3,
      "y": 6,
      "z": 8,
      "name": "Rock_Volcanic"
    },
    {
      "x": 3,
      "y": 7,
      "z": 8,
      "name": "Rock_Volcanic"
    },
    {
      "x": 3,
      "y": 8,
      "z": 8,
      "name": "Rock_Volcanic"
    },
    {
      "x": 3,
      "y": 9,
      "z": 8,
      "name": "Rock_Volcanic"
    },
    {
      "x": 3,
      "y": 10,
      "z": 8,
      "name": "Rock_Volcanic"
    },
    {
      "x": 3,
      "y": 11,
      "z": 8,
      "name": "Rock_Volcanic"
    },
    {
      "x": 3,
      "y": 7,
      "z": 9,
      "name": "Rock_Volcanic"
    },
    {
      "x": 3,
      "y": 8,
      "z": 9,
      "name": "Rock_Volcanic"
    },
    {
      "x": 3,
      "y": 9,
      "z": 9,
      "name": "Rock_Volcanic"
    },
    {
      "x": 4,
      "y": 12,
      "z": 0,
      "name": "Rock_Volcanic"
    },
    {
      "x": 4,
      "y": 13,
      "z": 0,
      "name": "Rock_Volcanic"
    },
    {
      "x": 4,
      "y": 14,
      "z": 0,
      "name": "Rock_Volcanic"
    },
    {
      "x": 4,
      "y": 9,
      "z": 1,
      "name": "Rock_Volcanic"
    },
    {
      "x": 4,
      "y": 10,
      "z": 1,
      "name": "Rock_Volcanic"
    },
    {
      "x": 4,
      "y": 11,
      "z": 1,
      "name": "Rock_Volcanic"
    },
    {
      "x": 4,
      "y": 12,
      "z": 1,
      "name": "Rock_Volcanic"
    },
    {
      "x": 4,
      "y": 13,
      "z": 1,
      "name": "Rock_Volcanic"
    },
    {
      "x": 4,
      "y": 14,
      "z": 1,
      "name": "Rock_Volcanic"
    },
    {
      "x": 4,
      "y": 15,
      "z": 1,
      "name": "Rock_Volcanic"
    },
    {
      "x": 4,
      "y": 7,
      "z": 2,
      "name": "Rock_Volcanic"
    },
    {
      "x": 4,
      "y": 8,
      "z": 2,
      "name": "Rock_Volcanic"
    },
    {
      "x": 4,
      "y": 9,
      "z": 2,
      "name": "Rock_Volcanic"
    },
    {
      "x": 4,
      "y": 10,
      "z": 2,
      "name": "Rock_Volcanic"
    },
    {
      "x": 4,
      "y": 11,
      "z": 2,
      "name": "Rock_Volcanic"
    },
    {
      "x": 4,
      "y": 12,
      "z": 2,
      "name": "Rock_Volcanic"
    },
    {
      "x": 4,
      "y": 13,
      "z": 2,
      "name": "Rock_Volcanic"
    },
    {
      "x": 4,
      "y": 14,
      "z": 2,
      "name": "Rock_Volcanic"
    },
    {
      "x": 4,
      "y": 15,
      "z": 2,
      "name": "Rock_Volcanic_Cracked_Poisoned"
    },
    {
      "x": 4,
      "y": 6,
      "z": 3,
      "name": "Rock_Volcanic"
    },
    {
      "x": 4,
      "y": 7,
      "z": 3,
      "name": "Rock_Volcanic"
    },
    {
      "x": 4,
      "y": 8,
      "z": 3,
      "name": "Rock_Volcanic"
    },
    {
      "x": 4,
      "y": 9,
      "z": 3,
      "name": "Rock_Volcanic"
    },
    {
      "x": 4,
      "y": 10,
      "z": 3,
      "name": "Rock_Volcanic"
    },
    {
      "x": 4,
      "y": 11,
      "z": 3,
      "name": "Rock_Volcanic"
    },
    {
      "x": 4,
      "y": 12,
      "z": 3,
      "name": "Rock_Volcanic"
    },
    {
      "x": 4,
      "y": 13,
      "z": 3,
      "name": "Rock_Volcanic"
    },
    {
      "x": 4,
      "y": 14,
      "z": 3,
      "name": "Rock_Volcanic"
    },
    {
      "x": 4,
      "y": 6,
      "z": 4,
      "name": "Rock_Volcanic"
    },
    {
      "x": 4,
      "y": 7,
      "z": 4,
      "name": "Rock_Volcanic"
    },
    {
      "x": 4,
      "y": 8,
      "z": 4,
      "name": "Rock_Volcanic"
    },
    {
      "x": 4,
      "y": 9,
      "z": 4,
      "name": "Rock_Volcanic"
    },
    {
      "x": 4,
      "y": 10,
      "z": 4,
      "name": "Rock_Volcanic"
    },
    {
      "x": 4,
      "y": 11,
      "z": 4,
      "name": "Rock_Volcanic"
    },
    {
      "x": 4,
      "y": 12,
      "z": 4,
      "name": "Rock_Volcanic"
    },
    {
      "x": 4,
      "y": 13,
      "z": 4,
      "name": "Rock_Volcanic"
    },
    {
      "x": 4,
      "y": 14,
      "z": 4,
      "name": "Rock_Volcanic"
    },
    {
      "x": 4,
      "y": 5,
      "z": 5,
      "name": "Rock_Volcanic"
    },
    {
      "x": 4,
      "y": 6,
      "z": 5,
      "name": "Rock_Volcanic"
    },
    {
      "x": 4,
      "y": 7,
      "z": 5,
      "name": "Rock_Volcanic"
    },
    {
      "x": 4,
      "y": 8,
      "z": 5,
      "name": "Rock_Volcanic"
    },
    {
      "x": 4,
      "y": 9,
      "z": 5,
      "name": "Rock_Volcanic"
    },
    {
      "x": 4,
      "y": 10,
      "z": 5,
      "name": "Rock_Volcanic"
    },
    {
      "x": 4,
      "y": 11,
      "z": 5,
      "name": "Rock_Volcanic"
    },
    {
      "x": 4,
      "y": 12,
      "z": 5,
      "name": "Rock_Volcanic"
    },
    {
      "x": 4,
      "y": 13,
      "z": 5,
      "name": "Rock_Volcanic"
    },
    {
      "x": 4,
      "y": 14,
      "z": 5,
      "name": "Rock_Volcanic"
    },
    {
      "x": 4,
      "y": 5,
      "z": 6,
      "name": "Rock_Volcanic"
    },
    {
      "x": 4,
      "y": 6,
      "z": 6,
      "name": "Rock_Volcanic"
    },
    {
      "x": 4,
      "y": 7,
      "z": 6,
      "name": "Rock_Volcanic"
    },
    {
      "x": 4,
      "y": 8,
      "z": 6,
      "name": "Rock_Volcanic"
    },
    {
      "x": 4,
      "y": 9,
      "z": 6,
      "name": "Rock_Volcanic"
    },
    {
      "x": 4,
      "y": 10,
      "z": 6,
      "name": "Rock_Volcanic"
    },
    {
      "x": 4,
      "y": 11,
      "z": 6,
      "name": "Rock_Volcanic"
    },
    {
      "x": 4,
      "y": 12,
      "z": 6,
      "name": "Rock_Volcanic"
    },
    {
      "x": 4,
      "y": 13,
      "z": 6,
      "name": "Rock_Volcanic"
    },
    {
      "x": 4,
      "y": 14,
      "z": 6,
      "name": "Rock_Volcanic"
    },
    {
      "x": 4,
      "y": 4,
      "z": 7,
      "name": "Rock_Volcanic"
    },
    {
      "x": 4,
      "y": 5,
      "z": 7,
      "name": "Rock_Volcanic"
    },
    {
      "x": 4,
      "y": 6,
      "z": 7,
      "name": "Rock_Volcanic"
    },
    {
      "x": 4,
      "y": 7,
      "z": 7,
      "name": "Rock_Volcanic"
    },
    {
      "x": 4,
      "y": 8,
      "z": 7,
      "name": "Rock_Volcanic"
    },
    {
      "x": 4,
      "y": 9,
      "z": 7,
      "name": "Rock_Volcanic"
    },
    {
      "x": 4,
      "y": 10,
      "z": 7,
      "name": "Rock_Volcanic"
    },
    {
      "x": 4,
      "y": 11,
      "z": 7,
      "name": "Rock_Volcanic"
    },
    {
      "x": 4,
      "y": 12,
      "z": 7,
      "name": "Rock_Volcanic"
    },
    {
      "x": 4,
      "y": 13,
      "z": 7,
      "name": "Rock_Volcanic"
    },
    {
      "x": 4,
      "y": 3,
      "z": 8,
      "name": "Rock_Volcanic"
    },
    {
      "x": 4,
      "y": 4,
      "z": 8,
      "name": "Rock_Volcanic"
    },
    {
      "x": 4,
      "y": 5,
      "z": 8,
      "name": "Rock_Volcanic"
    },
    {
      "x": 4,
      "y": 6,
      "z": 8,
      "name": "Rock_Volcanic"
    },
    {
      "x": 4,
      "y": 7,
      "z": 8,
      "name": "Rock_Volcanic"
    },
    {
      "x": 4,
      "y": 8,
      "z": 8,
      "name": "Rock_Volcanic"
    },
    {
      "x": 4,
      "y": 9,
      "z": 8,
      "name": "Rock_Volcanic"
    },
    {
      "x": 4,
      "y": 10,
      "z": 8,
      "name": "Rock_Volcanic"
    },
    {
      "x": 4,
      "y": 11,
      "z": 8,
      "name": "Rock_Volcanic"
    },
    {
      "x": 4,
      "y": 3,
      "z": 9,
      "name": "Rock_Volcanic"
    },
    {
      "x": 4,
      "y": 4,
      "z": 9,
      "name": "Rock_Volcanic"
    },
    {
      "x": 4,
      "y": 5,
      "z": 9,
      "name": "Rock_Volcanic"
    },
    {
      "x": 4,
      "y": 6,
      "z": 9,
      "name": "Rock_Volcanic"
    },
    {
      "x": 4,
      "y": 7,
      "z": 9,
      "name": "Rock_Volcanic"
    },
    {
      "x": 4,
      "y": 8,
      "z": 9,
      "name": "Rock_Volcanic"
    },
    {
      "x": 4,
      "y": 9,
      "z": 9,
      "name": "Rock_Volcanic"
    },
    {
      "x": 4,
      "y": 10,
      "z": 9,
      "name": "Rock_Volcanic"
    },
    {
      "x": 4,
      "y": 6,
      "z": 10,
      "name": "Rock_Volcanic"
    },
    {
      "x": 4,
      "y": 7,
      "z": 10,
      "name": "Rock_Volcanic"
    },
    {
      "x": 4,
      "y": 8,
      "z": 10,
      "name": "Rock_Volcanic"
    },
    {
      "x": 5,
      "y": 11,
      "z": 1,
      "name": "Rock_Volcanic"
    },
    {
      "x": 5,
      "y": 13,
      "z": 1,
      "name": "Rock_Volcanic"
    },
    {
      "x": 5,
      "y": 8,
      "z": 2,
      "name": "Rock_Volcanic"
    },
    {
      "x": 5,
      "y": 9,
      "z": 2,
      "name": "Rock_Volcanic"
    },
    {
      "x": 5,
      "y": 10,
      "z": 2,
      "name": "Rock_Volcanic"
    },
    {
      "x": 5,
      "y": 11,
      "z": 2,
      "name": "Rock_Volcanic"
    },
    {
      "x": 5,
      "y": 12,
      "z": 2,
      "name": "Rock_Volcanic"
    },
    {
      "x": 5,
      "y": 13,
      "z": 2,
      "name": "Rock_Volcanic"
    },
    {
      "x": 5,
      "y": 14,
      "z": 2,
      "name": "Rock_Volcanic"
    },
    {
      "x": 5,
      "y": 6,
      "z": 3,
      "name": "Rock_Volcanic"
    },
    {
      "x": 5,
      "y": 7,
      "z": 3,
      "name": "Rock_Volcanic"
    },
    {
      "x": 5,
      "y": 8,
      "z": 3,
      "name": "Rock_Volcanic"
    },
    {
      "x": 5,
      "y": 9,
      "z": 3,
      "name": "Rock_Volcanic"
    },
    {
      "x": 5,
      "y": 10,
      "z": 3,
      "name": "Rock_Volcanic"
    },
    {
      "x": 5,
      "y": 11,
      "z": 3,
      "name": "Rock_Volcanic"
    },
    {
      "x": 5,
      "y": 12,
      "z": 3,
      "name": "Rock_Volcanic"
    },
    {
      "x": 5,
      "y": 13,
      "z": 3,
      "name": "Rock_Volcanic"
    },
    {
      "x": 5,
      "y": 14,
      "z": 3,
      "name": "Rock_Volcanic"
    },
    {
      "x": 5,
      "y": 5,
      "z": 4,
      "name": "Rock_Volcanic"
    },
    {
      "x": 5,
      "y": 6,
      "z": 4,
      "name": "Rock_Volcanic"
    },
    {
      "x": 5,
      "y": 7,
      "z": 4,
      "name": "Rock_Volcanic"
    },
    {
      "x": 5,
      "y": 8,
      "z": 4,
      "name": "Rock_Volcanic"
    },
    {
      "x": 5,
      "y": 9,
      "z": 4,
      "name": "Rock_Volcanic"
    },
    {
      "x": 5,
      "y": 10,
      "z": 4,
      "name": "Rock_Volcanic"
    },
    {
      "x": 5,
      "y": 11,
      "z": 4,
      "name": "Rock_Volcanic"
    },
    {
      "x": 5,
      "y": 12,
      "z": 4,
      "name": "Rock_Volcanic"
    },
    {
      "x": 5,
      "y": 13,
      "z": 4,
      "name": "Rock_Volcanic"
    },
    {
      "x": 5,
      "y": 14,
      "z": 4,
      "name": "Rock_Volcanic"
    },
    {
      "x": 5,
      "y": 5,
      "z": 5,
      "name": "Rock_Volcanic"
    },
    {
      "x": 5,
      "y": 6,
      "z": 5,
      "name": "Rock_Volcanic"
    },
    {
      "x": 5,
      "y": 7,
      "z": 5,
      "name": "Rock_Volcanic"
    },
    {
      "x": 5,
      "y": 8,
      "z": 5,
      "name": "Rock_Volcanic"
    },
    {
      "x": 5,
      "y": 9,
      "z": 5,
      "name": "Rock_Volcanic"
    },
    {
      "x": 5,
      "y": 10,
      "z": 5,
      "name": "Rock_Volcanic"
    },
    {
      "x": 5,
      "y": 11,
      "z": 5,
      "name": "Rock_Volcanic"
    },
    {
      "x": 5,
      "y": 12,
      "z": 5,
      "name": "Rock_Volcanic"
    },
    {
      "x": 5,
      "y": 13,
      "z": 5,
      "name": "Rock_Volcanic"
    },
    {
      "x": 5,
      "y": 4,
      "z": 6,
      "name": "Rock_Volcanic"
    },
    {
      "x": 5,
      "y": 5,
      "z": 6,
      "name": "Rock_Volcanic"
    },
    {
      "x": 5,
      "y": 6,
      "z": 6,
      "name": "Rock_Volcanic"
    },
    {
      "x": 5,
      "y": 7,
      "z": 6,
      "name": "Rock_Volcanic"
    },
    {
      "x": 5,
      "y": 8,
      "z": 6,
      "name": "Rock_Volcanic"
    },
    {
      "x": 5,
      "y": 9,
      "z": 6,
      "name": "Rock_Volcanic"
    },
    {
      "x": 5,
      "y": 10,
      "z": 6,
      "name": "Rock_Volcanic"
    },
    {
      "x": 5,
      "y": 11,
      "z": 6,
      "name": "Rock_Volcanic"
    },
    {
      "x": 5,
      "y": 12,
      "z": 6,
      "name": "Rock_Volcanic"
    },
    {
      "x": 5,
      "y": 13,
      "z": 6,
      "name": "Rock_Volcanic"
    },
    {
      "x": 5,
      "y": 3,
      "z": 7,
      "name": "Rock_Volcanic"
    },
    {
      "x": 5,
      "y": 4,
      "z": 7,
      "name": "Rock_Volcanic"
    },
    {
      "x": 5,
      "y": 5,
      "z": 7,
      "name": "Rock_Volcanic"
    },
    {
      "x": 5,
      "y": 6,
      "z": 7,
      "name": "Rock_Volcanic"
    },
    {
      "x": 5,
      "y": 7,
      "z": 7,
      "name": "Rock_Volcanic"
    },
    {
      "x": 5,
      "y": 8,
      "z": 7,
      "name": "Rock_Volcanic"
    },
    {
      "x": 5,
      "y": 9,
      "z": 7,
      "name": "Rock_Volcanic"
    },
    {
      "x": 5,
      "y": 10,
      "z": 7,
      "name": "Rock_Volcanic"
    },
    {
      "x": 5,
      "y": 11,
      "z": 7,
      "name": "Rock_Volcanic"
    },
    {
      "x": 5,
      "y": 12,
      "z": 7,
      "name": "Rock_Volcanic"
    },
    {
      "x": 5,
      "y": 13,
      "z": 7,
      "name": "Rock_Volcanic"
    },
    {
      "x": 5,
      "y": 2,
      "z": 8,
      "name": "Rock_Volcanic"
    },
    {
      "x": 5,
      "y": 3,
      "z": 8,
      "name": "Rock_Volcanic"
    },
    {
      "x": 5,
      "y": 4,
      "z": 8,
      "name": "Rock_Volcanic"
    },
    {
      "x": 5,
      "y": 5,
      "z": 8,
      "name": "Rock_Volcanic"
    },
    {
      "x": 5,
      "y": 6,
      "z": 8,
      "name": "Rock_Volcanic"
    },
    {
      "x": 5,
      "y": 7,
      "z": 8,
      "name": "Rock_Volcanic"
    },
    {
      "x": 5,
      "y": 8,
      "z": 8,
      "name": "Rock_Volcanic"
    },
    {
      "x": 5,
      "y": 9,
      "z": 8,
      "name": "Rock_Volcanic"
    },
    {
      "x": 5,
      "y": 10,
      "z": 8,
      "name": "Rock_Volcanic"
    },
    {
      "x": 5,
      "y": 11,
      "z": 8,
      "name": "Rock_Volcanic"
    },
    {
      "x": 5,
      "y": 2,
      "z": 9,
      "name": "Rock_Volcanic"
    },
    {
      "x": 5,
      "y": 3,
      "z": 9,
      "name": "Rock_Volcanic"
    },
    {
      "x": 5,
      "y": 4,
      "z": 9,
      "name": "Rock_Volcanic"
    },
    {
      "x": 5,
      "y": 5,
      "z": 9,
      "name": "Rock_Volcanic"
    },
    {
      "x": 5,
      "y": 6,
      "z": 9,
      "name": "Rock_Volcanic"
    },
    {
      "x": 5,
      "y": 7,
      "z": 9,
      "name": "Rock_Volcanic"
    },
    {
      "x": 5,
      "y": 8,
      "z": 9,
      "name": "Rock_Volcanic"
    },
    {
      "x": 5,
      "y": 9,
      "z": 9,
      "name": "Rock_Volcanic"
    },
    {
      "x": 5,
      "y": 10,
      "z": 9,
      "name": "Rock_Volcanic"
    },
    {
      "x": 5,
      "y": 4,
      "z": 10,
      "name": "Rock_Volcanic"
    },
    {
      "x": 5,
      "y": 5,
      "z": 10,
      "name": "Rock_Volcanic"
    },
    {
      "x": 5,
      "y": 6,
      "z": 10,
      "name": "Rock_Volcanic"
    },
    {
      "x": 5,
      "y": 7,
      "z": 10,
      "name": "Rock_Volcanic"
    },
    {
      "x": 5,
      "y": 8,
      "z": 10,
      "name": "Rock_Volcanic"
    },
    {
      "x": 5,
      "y": 9,
      "z": 10,
      "name": "Rock_Volcanic"
    },
    {
      "x": 6,
      "y": 7,
      "z": 3,
      "name": "Rock_Volcanic"
    },
    {
      "x": 6,
      "y": 8,
      "z": 3,
      "name": "Rock_Volcanic"
    },
    {
      "x": 6,
      "y": 9,
      "z": 3,
      "name": "Rock_Volcanic"
    },
    {
      "x": 6,
      "y": 10,
      "z": 3,
      "name": "Rock_Volcanic"
    },
    {
      "x": 6,
      "y": 11,
      "z": 3,
      "name": "Rock_Volcanic"
    },
    {
      "x": 6,
      "y": 5,
      "z": 4,
      "name": "Rock_Volcanic"
    },
    {
      "x": 6,
      "y": 6,
      "z": 4,
      "name": "Rock_Volcanic"
    },
    {
      "x": 6,
      "y": 7,
      "z": 4,
      "name": "Rock_Volcanic"
    },
    {
      "x": 6,
      "y": 8,
      "z": 4,
      "name": "Rock_Volcanic"
    },
    {
      "x": 6,
      "y": 9,
      "z": 4,
      "name": "Rock_Volcanic"
    },
    {
      "x": 6,
      "y": 10,
      "z": 4,
      "name": "Rock_Volcanic"
    },
    {
      "x": 6,
      "y": 11,
      "z": 4,
      "name": "Rock_Volcanic"
    },
    {
      "x": 6,
      "y": 12,
      "z": 4,
      "name": "Rock_Volcanic"
    },
    {
      "x": 6,
      "y": 4,
      "z": 5,
      "name": "Rock_Volcanic"
    },
    {
      "x": 6,
      "y": 5,
      "z": 5,
      "name": "Rock_Volcanic"
    },
    {
      "x": 6,
      "y": 6,
      "z": 5,
      "name": "Rock_Volcanic"
    },
    {
      "x": 6,
      "y": 7,
      "z": 5,
      "name": "Rock_Volcanic"
    },
    {
      "x": 6,
      "y": 8,
      "z": 5,
      "name": "Rock_Volcanic"
    },
    {
      "x": 6,
      "y": 9,
      "z": 5,
      "name": "Rock_Volcanic"
    },
    {
      "x": 6,
      "y": 10,
      "z": 5,
      "name": "Rock_Volcanic"
    },
    {
      "x": 6,
      "y": 11,
      "z": 5,
      "name": "Rock_Volcanic"
    },
    {
      "x": 6,
      "y": 12,
      "z": 5,
      "name": "Rock_Volcanic"
    },
    {
      "x": 6,
      "y": 3,
      "z": 6,
      "name": "Rock_Volcanic"
    },
    {
      "x": 6,
      "y": 4,
      "z": 6,
      "name": "Rock_Volcanic"
    },
    {
      "x": 6,
      "y": 5,
      "z": 6,
      "name": "Rock_Volcanic"
    },
    {
      "x": 6,
      "y": 6,
      "z": 6,
      "name": "Rock_Volcanic"
    },
    {
      "x": 6,
      "y": 7,
      "z": 6,
      "name": "Rock_Volcanic"
    },
    {
      "x": 6,
      "y": 8,
      "z": 6,
      "name": "Rock_Volcanic"
    },
    {
      "x": 6,
      "y": 9,
      "z": 6,
      "name": "Rock_Volcanic"
    },
    {
      "x": 6,
      "y": 10,
      "z": 6,
      "name": "Rock_Volcanic"
    },
    {
      "x": 6,
      "y": 11,
      "z": 6,
      "name": "Rock_Volcanic"
    },
    {
      "x": 6,
      "y": 2,
      "z": 7,
      "name": "Rock_Volcanic"
    },
    {
      "x": 6,
      "y": 3,
      "z": 7,
      "name": "Rock_Volcanic"
    },
    {
      "x": 6,
      "y": 4,
      "z": 7,
      "name": "Rock_Volcanic"
    },
    {
      "x": 6,
      "y": 5,
      "z": 7,
      "name": "Rock_Volcanic"
    },
    {
      "x": 6,
      "y": 6,
      "z": 7,
      "name": "Rock_Volcanic"
    },
    {
      "x": 6,
      "y": 7,
      "z": 7,
      "name": "Rock_Volcanic"
    },
    {
      "x": 6,
      "y": 8,
      "z": 7,
      "name": "Rock_Volcanic"
    },
    {
      "x": 6,
      "y": 9,
      "z": 7,
      "name": "Rock_Volcanic"
    },
    {
      "x": 6,
      "y": 10,
      "z": 7,
      "name": "Rock_Volcanic"
    },
    {
      "x": 6,
      "y": 11,
      "z": 7,
      "name": "Rock_Volcanic"
    },
    {
      "x": 6,
      "y": 2,
      "z": 8,
      "name": "Rock_Volcanic"
    },
    {
      "x": 6,
      "y": 3,
      "z": 8,
      "name": "Rock_Volcanic"
    },
    {
      "x": 6,
      "y": 4,
      "z": 8,
      "name": "Rock_Volcanic"
    },
    {
      "x": 6,
      "y": 5,
      "z": 8,
      "name": "Rock_Volcanic"
    },
    {
      "x": 6,
      "y": 6,
      "z": 8,
      "name": "Rock_Volcanic"
    },
    {
      "x": 6,
      "y": 7,
      "z": 8,
      "name": "Rock_Volcanic"
    },
    {
      "x": 6,
      "y": 8,
      "z": 8,
      "name": "Rock_Volcanic"
    },
    {
      "x": 6,
      "y": 9,
      "z": 8,
      "name": "Rock_Volcanic"
    },
    {
      "x": 6,
      "y": 10,
      "z": 8,
      "name": "Rock_Volcanic"
    },
    {
      "x": 6,
      "y": 11,
      "z": 8,
      "name": "Rock_Volcanic"
    },
    {
      "x": 6,
      "y": 1,
      "z": 9,
      "name": "Rock_Volcanic"
    },
    {
      "x": 6,
      "y": 2,
      "z": 9,
      "name": "Rock_Volcanic"
    },
    {
      "x": 6,
      "y": 3,
      "z": 9,
      "name": "Rock_Volcanic"
    },
    {
      "x": 6,
      "y": 4,
      "z": 9,
      "name": "Rock_Volcanic"
    },
    {
      "x": 6,
      "y": 5,
      "z": 9,
      "name": "Rock_Volcanic"
    },
    {
      "x": 6,
      "y": 6,
      "z": 9,
      "name": "Rock_Volcanic"
    },
    {
      "x": 6,
      "y": 7,
      "z": 9,
      "name": "Rock_Volcanic"
    },
    {
      "x": 6,
      "y": 8,
      "z": 9,
      "name": "Rock_Volcanic"
    },
    {
      "x": 6,
      "y": 9,
      "z": 9,
      "name": "Rock_Volcanic"
    },
    {
      "x": 6,
      "y": 10,
      "z": 9,
      "name": "Rock_Volcanic"
    },
    {
      "x": 6,
      "y": 2,
      "z": 10,
      "name": "Rock_Volcanic"
    },
    {
      "x": 6,
      "y": 3,
      "z": 10,
      "name": "Rock_Volcanic"
    },
    {
      "x": 6,
      "y": 4,
      "z": 10,
      "name": "Rock_Volcanic"
    },
    {
      "x": 6,
      "y": 5,
      "z": 10,
      "name": "Rock_Volcanic"
    },
    {
      "x": 6,
      "y": 6,
      "z": 10,
      "name": "Rock_Volcanic"
    },
    {
      "x": 6,
      "y": 7,
      "z": 10,
      "name": "Rock_Volcanic"
    },
    {
      "x": 6,
      "y": 8,
      "z": 10,
      "name": "Rock_Volcanic"
    },
    {
      "x": 6,
      "y": 4,
      "z": 11,
      "name": "Rock_Volcanic"
    },
    {
      "x": 6,
      "y": 5,
      "z": 11,
      "name": "Rock_Volcanic"
    },
    {
      "x": 7,
      "y": 8,
      "z": 3,
      "name": "Rock_Volcanic"
    },
    {
      "x": 7,
      "y": 6,
      "z": 4,
      "name": "Rock_Volcanic"
    },
    {
      "x": 7,
      "y": 7,
      "z": 4,
      "name": "Rock_Volcanic"
    },
    {
      "x": 7,
      "y": 8,
      "z": 4,
      "name": "Rock_Volcanic"
    },
    {
      "x": 7,
      "y": 9,
      "z": 4,
      "name": "Rock_Volcanic"
    },
    {
      "x": 7,
      "y": 10,
      "z": 4,
      "name": "Rock_Volcanic"
    },
    {
      "x": 7,
      "y": 4,
      "z": 5,
      "name": "Rock_Volcanic"
    },
    {
      "x": 7,
      "y": 5,
      "z": 5,
      "name": "Rock_Volcanic"
    },
    {
      "x": 7,
      "y": 6,
      "z": 5,
      "name": "Rock_Volcanic"
    },
    {
      "x": 7,
      "y": 7,
      "z": 5,
      "name": "Rock_Volcanic"
    },
    {
      "x": 7,
      "y": 8,
      "z": 5,
      "name": "Rock_Volcanic"
    },
    {
      "x": 7,
      "y": 9,
      "z": 5,
      "name": "Rock_Volcanic"
    },
    {
      "x": 7,
      "y": 10,
      "z": 5,
      "name": "Rock_Volcanic"
    },
    {
      "x": 7,
      "y": 11,
      "z": 5,
      "name": "Rock_Volcanic"
    },
    {
      "x": 7,
      "y": 2,
      "z": 6,
      "name": "Rock_Volcanic"
    },
    {
      "x": 7,
      "y": 3,
      "z": 6,
      "name": "Rock_Volcanic"
    },
    {
      "x": 7,
      "y": 4,
      "z": 6,
      "name": "Rock_Volcanic"
    },
    {
      "x": 7,
      "y": 5,
      "z": 6,
      "name": "Rock_Volcanic"
    },
    {
      "x": 7,
      "y": 6,
      "z": 6,
      "name": "Rock_Volcanic"
    },
    {
      "x": 7,
      "y": 7,
      "z": 6,
      "name": "Rock_Volcanic"
    },
    {
      "x": 7,
      "y": 8,
      "z": 6,
      "name": "Rock_Volcanic"
    },
    {
      "x": 7,
      "y": 9,
      "z": 6,
      "name": "Rock_Volcanic"
    },
    {
      "x": 7,
      "y": 10,
      "z": 6,
      "name": "Rock_Volcanic"
    },
    {
      "x": 7,
      "y": 2,
      "z": 7,
      "name": "Rock_Volcanic"
    },
    {
      "x": 7,
      "y": 3,
      "z": 7,
      "name": "Rock_Volcanic"
    },
    {
      "x": 7,
      "y": 4,
      "z": 7,
      "name": "Rock_Volcanic"
    },
    {
      "x": 7,
      "y": 5,
      "z": 7,
      "name": "Rock_Volcanic"
    },
    {
      "x": 7,
      "y": 6,
      "z": 7,
      "name": "Rock_Volcanic"
    },
    {
      "x": 7,
      "y": 7,
      "z": 7,
      "name": "Rock_Volcanic"
    },
    {
      "x": 7,
      "y": 8,
      "z": 7,
      "name": "Rock_Volcanic"
    },
    {
      "x": 7,
      "y": 9,
      "z": 7,
      "name": "Rock_Volcanic"
    },
    {
      "x": 7,
      "y": 10,
      "z": 7,
      "name": "Rock_Volcanic"
    },
    {
      "x": 7,
      "y": 1,
      "z": 8,
      "name": "Rock_Volcanic"
    },
    {
      "x": 7,
      "y": 2,
      "z": 8,
      "name": "Rock_Volcanic"
    },
    {
      "x": 7,
      "y": 3,
      "z": 8,
      "name": "Rock_Volcanic"
    },
    {
      "x": 7,
      "y": 4,
      "z": 8,
      "name": "Rock_Volcanic"
    },
    {
      "x": 7,
      "y": 5,
      "z": 8,
      "name": "Rock_Volcanic"
    },
    {
      "x": 7,
      "y": 6,
      "z": 8,
      "name": "Rock_Volcanic"
    },
    {
      "x": 7,
      "y": 7,
      "z": 8,
      "name": "Rock_Volcanic"
    },
    {
      "x": 7,
      "y": 8,
      "z": 8,
      "name": "Rock_Volcanic"
    },
    {
      "x": 7,
      "y": 9,
      "z": 8,
      "name": "Rock_Volcanic"
    },
    {
      "x": 7,
      "y": 10,
      "z": 8,
      "name": "Rock_Volcanic"
    },
    {
      "x": 7,
      "y": 1,
      "z": 9,
      "name": "Rock_Volcanic"
    },
    {
      "x": 7,
      "y": 2,
      "z": 9,
      "name": "Rock_Volcanic"
    },
    {
      "x": 7,
      "y": 3,
      "z": 9,
      "name": "Rock_Volcanic"
    },
    {
      "x": 7,
      "y": 4,
      "z": 9,
      "name": "Rock_Volcanic"
    },
    {
      "x": 7,
      "y": 5,
      "z": 9,
      "name": "Rock_Volcanic"
    },
    {
      "x": 7,
      "y": 6,
      "z": 9,
      "name": "Rock_Volcanic"
    },
    {
      "x": 7,
      "y": 7,
      "z": 9,
      "name": "Rock_Volcanic"
    },
    {
      "x": 7,
      "y": 8,
      "z": 9,
      "name": "Rock_Volcanic"
    },
    {
      "x": 7,
      "y": 9,
      "z": 9,
      "name": "Rock_Volcanic"
    },
    {
      "x": 7,
      "y": 2,
      "z": 10,
      "name": "Rock_Volcanic"
    },
    {
      "x": 7,
      "y": 3,
      "z": 10,
      "name": "Rock_Volcanic"
    },
    {
      "x": 7,
      "y": 4,
      "z": 10,
      "name": "Rock_Volcanic"
    },
    {
      "x": 7,
      "y": 5,
      "z": 10,
      "name": "Rock_Volcanic"
    },
    {
      "x": 7,
      "y": 6,
      "z": 10,
      "name": "Rock_Volcanic"
    },
    {
      "x": 7,
      "y": 7,
      "z": 10,
      "name": "Rock_Volcanic"
    },
    {
      "x": 7,
      "y": 8,
      "z": 10,
      "name": "Rock_Volcanic"
    },
    {
      "x": 7,
      "y": 3,
      "z": 11,
      "name": "Rock_Volcanic"
    },
    {
      "x": 7,
      "y": 4,
      "z": 11,
      "name": "Rock_Volcanic"
    },
    {
      "x": 7,
      "y": 5,
      "z": 11,
      "name": "Rock_Volcanic"
    },
    {
      "x": 8,
      "y": 7,
      "z": 4,
      "name": "Rock_Volcanic"
    },
    {
      "x": 8,
      "y": 3,
      "z": 5,
      "name": "Rock_Volcanic"
    },
    {
      "x": 8,
      "y": 4,
      "z": 5,
      "name": "Rock_Volcanic"
    },
    {
      "x": 8,
      "y": 5,
      "z": 5,
      "name": "Rock_Volcanic"
    },
    {
      "x": 8,
      "y": 6,
      "z": 5,
      "name": "Rock_Volcanic"
    },
    {
      "x": 8,
      "y": 7,
      "z": 5,
      "name": "Rock_Volcanic"
    },
    {
      "x": 8,
      "y": 8,
      "z": 5,
      "name": "Rock_Volcanic"
    },
    {
      "x": 8,
      "y": 2,
      "z": 6,
      "name": "Rock_Volcanic"
    },
    {
      "x": 8,
      "y": 3,
      "z": 6,
      "name": "Rock_Volcanic"
    },
    {
      "x": 8,
      "y": 4,
      "z": 6,
      "name": "Rock_Volcanic"
    },
    {
      "x": 8,
      "y": 5,
      "z": 6,
      "name": "Rock_Volcanic"
    },
    {
      "x": 8,
      "y": 6,
      "z": 6,
      "name": "Rock_Volcanic"
    },
    {
      "x": 8,
      "y": 7,
      "z": 6,
      "name": "Rock_Volcanic"
    },
    {
      "x": 8,
      "y": 8,
      "z": 6,
      "name": "Rock_Volcanic"
    },
    {
      "x": 8,
      "y": 9,
      "z": 6,
      "name": "Rock_Volcanic"
    },
    {
      "x": 8,
      "y": 0,
      "z": 7,
      "name": "Rock_Volcanic"
    },
    {
      "x": 8,
      "y": 1,
      "z": 7,
      "name": "Rock_Volcanic"
    },
    {
      "x": 8,
      "y": 2,
      "z": 7,
      "name": "Rock_Volcanic"
    },
    {
      "x": 8,
      "y": 3,
      "z": 7,
      "name": "Rock_Volcanic"
    },
    {
      "x": 8,
      "y": 4,
      "z": 7,
      "name": "Rock_Volcanic"
    },
    {
      "x": 8,
      "y": 5,
      "z": 7,
      "name": "Rock_Volcanic"
    },
    {
      "x": 8,
      "y": 6,
      "z": 7,
      "name": "Rock_Volcanic"
    },
    {
      "x": 8,
      "y": 7,
      "z": 7,
      "name": "Rock_Volcanic"
    },
    {
      "x": 8,
      "y": 8,
      "z": 7,
      "name": "Rock_Volcanic"
    },
    {
      "x": 8,
      "y": 9,
      "z": 7,
      "name": "Rock_Volcanic"
    },
    {
      "x": 8,
      "y": 0,
      "z": 8,
      "name": "Rock_Volcanic"
    },
    {
      "x": 8,
      "y": 1,
      "z": 8,
      "name": "Rock_Volcanic"
    },
    {
      "x": 8,
      "y": 2,
      "z": 8,
      "name": "Rock_Volcanic"
    },
    {
      "x": 8,
      "y": 3,
      "z": 8,
      "name": "Rock_Volcanic"
    },
    {
      "x": 8,
      "y": 4,
      "z": 8,
      "name": "Rock_Volcanic"
    },
    {
      "x": 8,
      "y": 5,
      "z": 8,
      "name": "Rock_Volcanic"
    },
    {
      "x": 8,
      "y": 6,
      "z": 8,
      "name": "Rock_Volcanic"
    },
    {
      "x": 8,
      "y": 7,
      "z": 8,
      "name": "Rock_Volcanic"
    },
    {
      "x": 8,
      "y": 8,
      "z": 8,
      "name": "Rock_Volcanic"
    },
    {
      "x": 8,
      "y": 9,
      "z": 8,
      "name": "Rock_Volcanic"
    },
    {
      "x": 8,
      "y": 0,
      "z": 9,
      "name": "Rock_Volcanic"
    },
    {
      "x": 8,
      "y": 1,
      "z": 9,
      "name": "Rock_Volcanic"
    },
    {
      "x": 8,
      "y": 2,
      "z": 9,
      "name": "Rock_Volcanic"
    },
    {
      "x": 8,
      "y": 3,
      "z": 9,
      "name": "Rock_Volcanic"
    },
    {
      "x": 8,
      "y": 4,
      "z": 9,
      "name": "Rock_Volcanic"
    },
    {
      "x": 8,
      "y": 5,
      "z": 9,
      "name": "Rock_Volcanic"
    },
    {
      "x": 8,
      "y": 6,
      "z": 9,
      "name": "Rock_Volcanic"
    },
    {
      "x": 8,
      "y": 7,
      "z": 9,
      "name": "Rock_Volcanic"
    },
    {
      "x": 8,
      "y": 8,
      "z": 9,
      "name": "Rock_Volcanic"
    },
    {
      "x": 8,
      "y": 1,
      "z": 10,
      "name": "Rock_Volcanic"
    },
    {
      "x": 8,
      "y": 2,
      "z": 10,
      "name": "Rock_Volcanic"
    },
    {
      "x": 8,
      "y": 3,
      "z": 10,
      "name": "Rock_Volcanic"
    },
    {
      "x": 8,
      "y": 4,
      "z": 10,
      "name": "Rock_Volcanic"
    },
    {
      "x": 8,
      "y": 5,
      "z": 10,
      "name": "Rock_Volcanic"
    },
    {
      "x": 8,
      "y": 6,
      "z": 10,
      "name": "Rock_Volcanic"
    },
    {
      "x": 8,
      "y": 2,
      "z": 11,
      "name": "Rock_Volcanic"
    },
    {
      "x": 8,
      "y": 3,
      "z": 11,
      "name": "Rock_Volcanic"
    },
    {
      "x": 8,
      "y": 4,
      "z": 11,
      "name": "Rock_Volcanic"
    },
    {
      "x": 9,
      "y": 4,
      "z": 5,
      "name": "Rock_Volcanic"
    },
    {
      "x": 9,
      "y": 2,
      "z": 6,
      "name": "Rock_Volcanic"
    },
    {
      "x": 9,
      "y": 3,
      "z": 6,
      "name": "Rock_Volcanic"
    },
    {
      "x": 9,
      "y": 4,
      "z": 6,
      "name": "Rock_Volcanic"
    },
    {
      "x": 9,
      "y": 5,
      "z": 6,
      "name": "Rock_Volcanic"
    },
    {
      "x": 9,
      "y": 6,
      "z": 6,
      "name": "Rock_Volcanic"
    },
    {
      "x": 9,
      "y": 7,
      "z": 6,
      "name": "Rock_Volcanic"
    },
    {
      "x": 9,
      "y": 0,
      "z": 7,
      "name": "Rock_Volcanic"
    },
    {
      "x": 9,
      "y": 1,
      "z": 7,
      "name": "Rock_Volcanic"
    },
    {
      "x": 9,
      "y": 2,
      "z": 7,
      "name": "Rock_Volcanic"
    },
    {
      "x": 9,
      "y": 3,
      "z": 7,
      "name": "Rock_Volcanic"
    },
    {
      "x": 9,
      "y": 4,
      "z": 7,
      "name": "Rock_Volcanic"
    },
    {
      "x": 9,
      "y": 5,
      "z": 7,
      "name": "Rock_Volcanic"
    },
    {
      "x": 9,
      "y": 6,
      "z": 7,
      "name": "Rock_Volcanic"
    },
    {
      "x": 9,
      "y": 7,
      "z": 7,
      "name": "Rock_Volcanic"
    },
    {
      "x": 9,
      "y": 0,
      "z": 8,
      "name": "Rock_Volcanic"
    },
    {
      "x": 9,
      "y": 1,
      "z": 8,
      "name": "Rock_Volcanic"
    },
    {
      "x": 9,
      "y": 2,
      "z": 8,
      "name": "Rock_Volcanic"
    },
    {
      "x": 9,
      "y": 3,
      "z": 8,
      "name": "Rock_Volcanic"
    },
    {
      "x": 9,
      "y": 4,
      "z": 8,
      "name": "Rock_Volcanic"
    },
    {
      "x": 9,
      "y": 5,
      "z": 8,
      "name": "Rock_Volcanic"
    },
    {
      "x": 9,
      "y": 6,
      "z": 8,
      "name": "Rock_Volcanic"
    },
    {
      "x": 9,
      "y": 7,
      "z": 8,
      "name": "Rock_Volcanic"
    },
    {
      "x": 9,
      "y": 0,
      "z": 9,
      "name": "Rock_Volcanic"
    },
    {
      "x": 9,
      "y": 1,
      "z": 9,
      "name": "Rock_Volcanic"
    },
    {
      "x": 9,
      "y": 2,
      "z": 9,
      "name": "Rock_Volcanic"
    },
    {
      "x": 9,
      "y": 3,
      "z": 9,
      "name": "Rock_Volcanic"
    },
    {
      "x": 9,
      "y": 4,
      "z": 9,
      "name": "Rock_Volcanic"
    },
    {
      "x": 9,
      "y": 5,
      "z": 9,
      "name": "Rock_Volcanic"
    },
    {
      "x": 9,
      "y": 6,
      "z": 9,
      "name": "Rock_Volcanic"
    },
    {
      "x": 9,
      "y": 1,
      "z": 10,
      "name": "Rock_Volcanic"
    },
    {
      "x": 9,
      "y": 2,
      "z": 10,
      "name": "Rock_Volcanic"
    },
    {
      "x": 9,
      "y": 3,
      "z": 10,
      "name": "Rock_Volcanic"
    },
    {
      "x": 9,
      "y": 4,
      "z": 10,
      "name": "Rock_Volcanic"
    },
    {
      "x": 9,
      "y": 5,
      "z": 10,
      "name": "Rock_Volcanic"
    },
    {
      "x": 9,
      "y": 2,
      "z": 11,
      "name": "Rock_Volcanic"
    },
    {
      "x": 9,
      "y": 3,
      "z": 11,
      "name": "Rock_Volcanic"
    },
    {
      "x": 9,
      "y": 4,
      "z": 11,
      "name": "Rock_Volcanic"
    },
    {
      "x": 10,
      "y": 2,
      "z": 6,
      "name": "Rock_Volcanic"
    },
    {
      "x": 10,
      "y": 3,
      "z": 6,
      "name": "Rock_Volcanic"
    },
    {
      "x": 10,
      "y": 4,
      "z": 6,
      "name": "Rock_Volcanic"
    },
    {
      "x": 10,
      "y": 5,
      "z": 6,
      "name": "Rock_Volcanic"
    },
    {
      "x": 10,
      "y": 0,
      "z": 7,
      "name": "Rock_Volcanic"
    },
    {
      "x": 10,
      "y": 1,
      "z": 7,
      "name": "Rock_Volcanic"
    },
    {
      "x": 10,
      "y": 2,
      "z": 7,
      "name": "Rock_Volcanic"
    },
    {
      "x": 10,
      "y": 3,
      "z": 7,
      "name": "Rock_Volcanic"
    },
    {
      "x": 10,
      "y": 4,
      "z": 7,
      "name": "Rock_Volcanic"
    },
    {
      "x": 10,
      "y": 5,
      "z": 7,
      "name": "Rock_Volcanic"
    },
    {
      "x": 10,
      "y": 6,
      "z": 7,
      "name": "Rock_Volcanic"
    },
    {
      "x": 10,
      "y": 0,
      "z": 8,
      "name": "Rock_Volcanic"
    },
    {
      "x": 10,
      "y": 1,
      "z": 8,
      "name": "Rock_Volcanic"
    },
    {
      "x": 10,
      "y": 2,
      "z": 8,
      "name": "Rock_Volcanic"
    },
    {
      "x": 10,
      "y": 3,
      "z": 8,
      "name": "Rock_Volcanic"
    },
    {
      "x": 10,
      "y": 4,
      "z": 8,
      "name": "Rock_Volcanic"
    },
    {
      "x": 10,
      "y": 5,
      "z": 8,
      "name": "Rock_Volcanic"
    },
    {
      "x": 10,
      "y": 6,
      "z": 8,
      "name": "Rock_Volcanic"
    },
    {
      "x": 10,
      "y": 0,
      "z": 9,
      "name": "Rock_Volcanic"
    },
    {
      "x": 10,
      "y": 1,
      "z": 9,
      "name": "Rock_Volcanic"
    },
    {
      "x": 10,
      "y": 2,
      "z": 9,
      "name": "Rock_Volcanic"
    },
    {
      "x": 10,
      "y": 3,
      "z": 9,
      "name": "Rock_Volcanic"
    },
    {
      "x": 10,
      "y": 4,
      "z": 9,
      "name": "Rock_Volcanic"
    },
    {
      "x": 10,
      "y": 5,
      "z": 9,
      "name": "Rock_Volcanic"
    },
    {
      "x": 10,
      "y": 1,
      "z": 10,
      "name": "Rock_Volcanic"
    },
    {
      "x": 10,
      "y": 2,
      "z": 10,
      "name": "Rock_Volcanic"
    },
    {
      "x": 10,
      "y": 3,
      "z": 10,
      "name": "Rock_Volcanic"
    },
    {
      "x": 10,
      "y": 4,
      "z": 10,
      "name": "Rock_Volcanic"
    },
    {
      "x": 10,
      "y": 2,
      "z": 11,
      "name": "Rock_Volcanic"
    },
    {
      "x": 10,
      "y": 3,
      "z": 11,
      "name": "Rock_Volcanic"
    },
    {
      "x": 11,
      "y": 1,
      "z": 7,
      "name": "Rock_Volcanic"
    },
    {
      "x": 11,
      "y": 2,
      "z": 7,
      "name": "Rock_Volcanic"
    },
    {
      "x": 11,
      "y": 3,
      "z": 7,
      "name": "Rock_Volcanic"
    },
    {
      "x": 11,
      "y": 4,
      "z": 7,
