{
  "version": 8,
  "blockIdVersion": 8,
  "anchorX": 0,
  "anchorY": 0,
  "anchorZ": 0,
  "blocks": [
    {
      "x": -22,
      "y": -3,
      "z": 5,
      "name": "Wood_Softwood_Planks"
    },
    {
      "x": -22,
      "y": -2,
      "z": 5,
      "name": "Wood_Softwood_Stairs",
      "rotation": 3
    },
    {
      "x": -21,
      "y": -3,
      "z": 4,
      "name": "Wood_Softwood_Planks"
    },
    {
      "x": -21,
      "y": -3,
      "z": 5,
      "name": "Wood_Softwood_Planks"
    },
    {
      "x": -21,
      "y": -2,
      "z": 5,
      "name": "Wood_Softwood_Planks"
    },
    {
      "x": -21,
      "y": -1,
      "z": 5,
      "name": "Wood_Softwood_Stairs",
      "rotation": 3
    },
    {
      "x": -21,
      "y": -3,
      "z": 6,
      "name": "Wood_Softwood_Planks"
    },
    {
      "x": -21,
      "y": -2,
      "z": 6,
      "name": "Wood_Softwood_Planks"
    },
    {
      "x": -21,
      "y": -1,
      "z": 6,
      "name": "Wood_Softwood_Stairs",
      "rotation": 3
    },
    {
      "x": -20,
      "y": 3,
      "z": -1,
      "name": "Wood_Deadwood_Roof_Hollow",
      "rotation": 3
    },
    {
      "x": -20,
      "y": 3,
      "z": 0,
      "name": "Wood_Deadwood_Roof_Hollow",
      "rotation": 3
    },
    {
      "x": -20,
      "y": -3,
      "z": 4,
      "name": "Wood_Softwood_Planks"
    },
    {
      "x": -20,
      "y": -2,
      "z": 4,
      "name": "Wood_Softwood_Planks"
    },
    {
      "x": -20,
      "y": -1,
      "z": 4,
      "name": "Wood_Softwood_Planks"
    },
    {
      "x": -20,
      "y": -3,
      "z": 5,
      "name": "Wood_Softwood_Planks"
    },
    {
      "x": -20,
      "y": -2,
      "z": 5,
      "name": "Wood_Softwood_Planks"
    },
    {
      "x": -20,
      "y": -1,
      "z": 5,
      "name": "Wood_Softwood_Planks"
    },
    {
      "x": -20,
      "y": -3,
      "z": 6,
      "name": "Wood_Softwood_Planks"
    },
    {
      "x": -20,
      "y": -2,
      "z": 6,
      "name": "Wood_Softwood_Planks"
    },
    {
      "x": -20,
      "y": -1,
      "z": 6,
      "name": "Wood_Softwood_Planks"
    },
    {
      "x": -20,
      "y": 3,
      "z": 7,
      "name": "Wood_Deadwood_Roof_Hollow",
      "rotation": 3
    },
    {
      "x": -20,
      "y": 3,
      "z": 8,
      "name": "Wood_Deadwood_Roof_Hollow",
      "rotation": 3
    },
    {
      "x": -19,
      "y": 0,
      "z": -3,
      "name": "Wood_Oak_Trunk"
    },
    {
      "x": -19,
      "y": 1,
      "z": -3,
      "name": "Wood_Oak_Trunk"
    },
    {
      "x": -19,
      "y": 2,
      "z": -3,
      "name": "Wood_Oak_Trunk"
    },
    {
      "x": -19,
      "y": -1,
      "z": -2,
      "name": "Wood_Softwood_Fence",
      "rotation": 1
    },
    {
      "x": -19,
      "y": 0,
      "z": -2,
      "name": "Wood_Oak_Trunk",
      "rotation": 4
    },
    {
      "x": -19,
      "y": 1,
      "z": -2,
      "name": "Wood_Softwood_Decorative"
    },
    {
      "x": -19,
      "y": 2,
      "z": -2,
      "name": "Wood_Softwood_Decorative"
    },
    {
      "x": -19,
      "y": 3,
      "z": -2,
      "name": "Wood_Softwood_Decorative"
    },
    {
      "x": -19,
      "y": -1,
      "z": -1,
      "name": "Wood_Softwood_Fence",
      "rotation": 1
    },
    {
      "x": -19,
      "y": 0,
      "z": -1,
      "name": "Wood_Oak_Trunk",
      "rotation": 4
    },
    {
      "x": -19,
      "y": 1,
      "z": -1,
      "name": "Wood_Softwood_Planks"
    },
    {
      "x": -19,
      "y": 2,
      "z": -1,
      "name": "Furniture_Crude_Window",
      "rotation": 1
    },
    {
      "x": -19,
      "y": 3,
      "z": -1,
      "name": "Wood_Softwood_Planks"
    },
    {
      "x": -19,
      "y": 4,
      "z": -1,
      "name": "Wood_Deadwood_Roof",
      "rotation": 3
    },
    {
      "x": -19,
      "y": 5,
      "z": -1,
      "name": "Empty"
    },
    {
      "x": -19,
      "y": -1,
      "z": 0,
      "name": "Wood_Softwood_Fence",
      "rotation": 1
    },
    {
      "x": -19,
      "y": 0,
      "z": 0,
      "name": "Wood_Oak_Trunk",
      "rotation": 4
    },
    {
      "x": -19,
      "y": 1,
      "z": 0,
      "name": "Wood_Softwood_Planks"
    },
    {
      "x": -19,
      "y": 2,
      "z": 0,
      "name": "Furniture_Crude_Window",
      "rotation": 1
    },
    {
      "x": -19,
      "y": 3,
      "z": 0,
      "name": "Wood_Softwood_Planks"
    },
    {
      "x": -19,
      "y": 4,
      "z": 0,
      "name": "Wood_Deadwood_Roof",
      "rotation": 3
    },
    {
      "x": -19,
      "y": 5,
      "z": 0,
      "name": "Empty"
    },
    {
      "x": -19,
      "y": -1,
      "z": 1,
      "name": "Wood_Softwood_Fence",
      "rotation": 1
    },
    {
      "x": -19,
      "y": 0,
      "z": 1,
      "name": "Wood_Oak_Trunk",
      "rotation": 4
    },
    {
      "x": -19,
      "y": 1,
      "z": 1,
      "name": "Wood_Softwood_Planks"
    },
    {
      "x": -19,
      "y": 2,
      "z": 1,
      "name": "Wood_Softwood_Planks"
    },
    {
      "x": -19,
      "y": 3,
      "z": 1,
      "name": "Wood_Softwood_Planks"
    },
    {
      "x": -19,
      "y": 4,
      "z": 1,
      "name": "Wood_Deadwood_Roof",
      "rotation": 3
    },
    {
      "x": -19,
      "y": 5,
      "z": 1,
      "name": "Empty"
    },
    {
      "x": -19,
      "y": 6,
      "z": 1,
      "name": "Empty"
    },
    {
      "x": -19,
      "y": 7,
      "z": 1,
      "name": "Empty"
    },
    {
      "x": -19,
      "y": -1,
      "z": 2,
      "name": "Wood_Softwood_Fence",
      "rotation": 1
    },
    {
      "x": -19,
      "y": 0,
      "z": 2,
      "name": "Wood_Oak_Trunk",
      "rotation": 4
    },
    {
      "x": -19,
      "y": 1,
      "z": 2,
      "name": "Wood_Softwood_Planks"
    },
    {
      "x": -19,
      "y": 2,
      "z": 2,
      "name": "Wood_Softwood_Planks"
    },
    {
      "x": -19,
      "y": 3,
      "z": 2,
      "name": "Empty"
    },
    {
      "x": -19,
      "y": 4,
      "z": 2,
      "name": "Empty"
    },
    {
      "x": -19,
      "y": 5,
      "z": 2,
      "name": "Empty"
    },
    {
      "x": -19,
      "y": 6,
      "z": 2,
      "name": "Empty"
    },
    {
      "x": -19,
      "y": 7,
      "z": 2,
      "name": "Empty"
    },
    {
      "x": -19,
      "y": -1,
      "z": 3,
      "name": "Wood_Softwood_Fence",
      "rotation": 1
    },
    {
      "x": -19,
      "y": 0,
      "z": 3,
      "name": "Wood_Oak_Trunk",
      "rotation": 4
    },
    {
      "x": -19,
      "y": 1,
      "z": 3,
      "name": "Empty"
    },
    {
      "x": -19,
      "y": 2,
      "z": 3,
      "name": "Empty"
    },
    {
      "x": -19,
      "y": 3,
      "z": 3,
      "name": "Empty"
    },
    {
      "x": -19,
      "y": 4,
      "z": 3,
      "name": "Empty"
    },
    {
      "x": -19,
      "y": 5,
      "z": 3,
      "name": "Empty"
    },
    {
      "x": -19,
      "y": 6,
      "z": 3,
      "name": "Empty"
    },
    {
      "x": -19,
      "y": 7,
      "z": 3,
      "name": "Empty"
    },
    {
      "x": -19,
      "y": -1,
      "z": 4,
      "name": "Wood_Softwood_Fence",
      "rotation": 1
    },
    {
      "x": -19,
      "y": 0,
      "z": 4,
      "name": "Wood_Oak_Trunk",
      "rotation": 4
    },
    {
      "x": -19,
      "y": 1,
      "z": 4,
      "name": "Empty"
    },
    {
      "x": -19,
      "y": 2,
      "z": 4,
      "name": "Empty"
    },
    {
      "x": -19,
      "y": 3,
      "z": 4,
      "name": "Empty"
    },
    {
      "x": -19,
      "y": 4,
      "z": 4,
      "name": "Empty"
    },
    {
      "x": -19,
      "y": 5,
      "z": 4,
      "name": "Empty"
    },
    {
      "x": -19,
      "y": 6,
      "z": 4,
      "name": "Empty"
    },
    {
      "x": -19,
      "y": 7,
      "z": 4,
      "name": "Empty"
    },
    {
      "x": -19,
      "y": -1,
      "z": 5,
      "name": "Wood_Softwood_Fence",
      "rotation": 1
    },
    {
      "x": -19,
      "y": 0,
      "z": 5,
      "name": "Wood_Oak_Trunk",
      "rotation": 4
    },
    {
      "x": -19,
      "y": 1,
      "z": 5,
      "name": "Empty"
    },
    {
      "x": -19,
      "y": 2,
      "z": 5,
      "name": "Empty"
    },
    {
      "x": -19,
      "y": 3,
      "z": 5,
      "name": "Empty"
    },
    {
      "x": -19,
      "y": 4,
      "z": 5,
      "name": "Empty"
    },
    {
      "x": -19,
      "y": 5,
      "z": 5,
      "name": "Empty"
    },
    {
      "x": -19,
      "y": 6,
      "z": 5,
      "name": "Empty"
    },
    {
      "x": -19,
      "y": 7,
      "z": 5,
      "name": "Empty"
    },
    {
      "x": -19,
      "y": -1,
      "z": 6,
      "name": "Wood_Softwood_Fence",
      "rotation": 1
    },
    {
      "x": -19,
      "y": 0,
      "z": 6,
      "name": "Wood_Oak_Trunk",
      "rotation": 4
    },
    {
      "x": -19,
      "y": 1,
      "z": 6,
      "name": "Wood_Softwood_Planks"
    },
    {
      "x": -19,
      "y": 2,
      "z": 6,
      "name": "Empty"
    },
    {
      "x": -19,
      "y": 3,
      "z": 6,
      "name": "Empty"
    },
    {
      "x": -19,
      "y": 4,
      "z": 6,
      "name": "Empty"
    },
    {
      "x": -19,
      "y": 5,
      "z": 6,
      "name": "Empty"
    },
    {
      "x": -19,
      "y": 6,
      "z": 6,
      "name": "Empty"
    },
    {
      "x": -19,
      "y": 7,
      "z": 6,
      "name": "Empty"
    },
    {
      "x": -19,
      "y": -1,
      "z": 7,
      "name": "Wood_Softwood_Fence",
      "rotation": 1
    },
    {
      "x": -19,
      "y": 0,
      "z": 7,
      "name": "Wood_Oak_Trunk",
      "rotation": 4
    },
    {
      "x": -19,
      "y": 1,
      "z": 7,
      "name": "Wood_Softwood_Decorative"
    },
    {
      "x": -19,
      "y": 2,
      "z": 7,
      "name": "Wood_Softwood_Decorative"
    },
    {
      "x": -19,
      "y": 3,
      "z": 7,
      "name": "Wood_Softwood_Decorative"
    },
    {
      "x": -19,
      "y": 4,
      "z": 7,
      "name": "Wood_Deadwood_Roof",
      "rotation": 3
    },
    {
      "x": -19,
      "y": 5,
      "z": 7,
      "name": "Empty"
    },
    {
      "x": -19,
      "y": 6,
      "z": 7,
      "name": "Empty"
    },
    {
      "x": -19,
      "y": 7,
      "z": 7,
      "name": "Empty"
    },
    {
      "x": -19,
      "y": -3,
      "z": 8,
      "name": "Wood_Oak_Trunk"
    },
    {
      "x": -19,
      "y": -2,
      "z": 8,
      "name": "Wood_Oak_Trunk"
    },
    {
      "x": -19,
      "y": -1,
      "z": 8,
      "name": "Wood_Oak_Trunk"
    },
    {
      "x": -19,
      "y": 0,
      "z": 8,
      "name": "Wood_Oak_Trunk"
    },
    {
      "x": -19,
      "y": 1,
      "z": 8,
      "name": "Wood_Oak_Trunk"
    },
    {
      "x": -19,
      "y": 2,
      "z": 8,
      "name": "Wood_Oak_Trunk"
    },
    {
      "x": -19,
      "y": 3,
      "z": 8,
      "name": "Wood_Oak_Trunk"
    },
    {
      "x": -19,
      "y": 4,
      "z": 8,
      "name": "Wood_Deadwood_Roof",
      "rotation": 3
    },
    {
      "x": -19,
      "y": 5,
      "z": 8,
      "name": "Empty"
    },
    {
      "x": -19,
      "y": 6,
      "z": 8,
      "name": "Empty"
    },
    {
      "x": -19,
      "y": 7,
      "z": 8,
      "name": "Empty"
    },
    {
      "x": -19,
      "y": 1,
      "z": 9,
      "name": "Empty"
    },
    {
      "x": -19,
      "y": 2,
      "z": 9,
      "name": "Empty"
    },
    {
      "x": -19,
      "y": 3,
      "z": 9,
      "name": "Empty"
    },
    {
      "x": -19,
      "y": 4,
      "z": 9,
      "name": "Empty"
    },
    {
      "x": -19,
      "y": 5,
      "z": 9,
      "name": "Empty"
    },
    {
      "x": -19,
      "y": 6,
      "z": 9,
      "name": "Empty"
    },
    {
      "x": -19,
      "y": 7,
      "z": 9,
      "name": "Empty"
    },
    {
      "x": -19,
      "y": 1,
      "z": 10,
      "name": "Empty"
    },
    {
      "x": -19,
      "y": 2,
      "z": 10,
      "name": "Empty"
    },
    {
      "x": -19,
      "y": 3,
      "z": 10,
      "name": "Empty"
    },
    {
      "x": -19,
      "y": 4,
      "z": 10,
      "name": "Empty"
    },
    {
      "x": -19,
      "y": 5,
      "z": 10,
      "name": "Empty"
    },
    {
      "x": -19,
      "y": 6,
      "z": 10,
      "name": "Empty"
    },
    {
      "x": -19,
      "y": 7,
      "z": 10,
      "name": "Empty"
    },
    {
      "x": -18,
      "y": 0,
      "z": -2,
      "name": "Wood_Beech_Trunk",
      "rotation": 5
    },
    {
      "x": -18,
      "y": 1,
      "z": -2,
      "name": "Wood_Softwood_Decorative"
    },
    {
      "x": -18,
      "y": 2,
      "z": -2,
      "name": "Wood_Softwood_Fence",
      "rotation": 2
    },
    {
      "x": -18,
      "y": 3,
      "z": -2,
      "name": "Wood_Softwood_Decorative"
    },
    {
      "x": -18,
      "y": 4,
      "z": -2,
      "name": "Wood_Softwood_Decorative"
    },
    {
      "x": -18,
      "y": 5,
      "z": -2,
      "name": "Wood_Deadwood_Roof_Flat"
    },
    {
      "x": -18,
      "y": 0,
      "z": -1,
      "name": "Wood_Deadwood_Planks"
    },
    {
      "x": -18,
      "y": 1,
      "z": -1,
      "name": "Empty"
    },
    {
      "x": -18,
      "y": 2,
      "z": -1,
      "name": "Empty"
    },
    {
      "x": -18,
      "y": 3,
      "z": -1,
      "name": "Empty"
    },
    {
      "x": -18,
      "y": 4,
      "z": -1,
      "name": "Wood_Softwood_Planks"
    },
    {
      "x": -18,
      "y": 5,
      "z": -1,
      "name": "Wood_Deadwood_Roof_Flat"
    },
    {
      "x": -18,
      "y": 0,
      "z": 0,
      "name": "Wood_Deadwood_Planks"
    },
    {
      "x": -18,
      "y": 1,
      "z": 0,
      "name": "Furniture_Village_Crate",
      "components": {
        "Components": {
          "container": {
            "Position": {
              "X": -18,
              "Y": 1,
              "Z": 0
            },
            "Custom": false,
            "AllowViewing": true,
            "ItemContainer": {
              "Capacity": 20,
              "Items": {}
            }
          }
        }
      }
    },
    {
      "x": -18,
      "y": 2,
      "z": 0,
      "name": "Empty"
    },
    {
      "x": -18,
      "y": 3,
      "z": 0,
      "name": "Empty"
    },
    {
      "x": -18,
      "y": 4,
      "z": 0,
      "name": "Wood_Softwood_Planks"
    },
    {
      "x": -18,
      "y": 5,
      "z": 0,
      "name": "Wood_Deadwood_Roof_Flat"
    },
    {
      "x": -18,
      "y": 0,
      "z": 1,
      "name": "Wood_Deadwood_Planks"
    },
    {
      "x": -18,
      "y": 1,
      "z": 1,
      "name": "Furniture_Village_Crate",
      "components": {
        "Components": {
          "container": {
            "Position": {
              "X": -18,
              "Y": 1,
              "Z": 1
            },
            "Custom": false,
            "AllowViewing": true,
            "ItemContainer": {
              "Capacity": 20,
              "Items": {}
            }
          }
        }
      }
    },
    {
      "x": -18,
      "y": 2,
      "z": 1,
      "name": "Furniture_Village_Crate",
      "components": {
        "Components": {
          "container": {
            "Position": {
              "X": -18,
              "Y": 2,
              "Z": 1
            },
            "Custom": false,
            "AllowViewing": true,
            "ItemContainer": {
              "Capacity": 20,
              "Items": {}
            }
          }
        }
      }
    },
    {
      "x": -18,
      "y": 3,
      "z": 1,
      "name": "Empty"
    },
    {
      "x": -18,
      "y": 4,
      "z": 1,
      "name": "Wood_Softwood_Planks"
    },
    {
      "x": -18,
      "y": 5,
      "z": 1,
      "name": "Wood_Deadwood_Roof_Flat"
    },
    {
      "x": -18,
      "y": 6,
      "z": 1,
      "name": "Empty"
    },
    {
      "x": -18,
      "y": 7,
      "z": 1,
      "name": "Empty"
    },
    {
      "x": -18,
      "y": 0,
      "z": 2,
      "name": "Wood_Deadwood_Decorative"
    },
    {
      "x": -18,
      "y": 1,
      "z": 2,
      "name": "Empty"
    },
    {
      "x": -18,
      "y": 2,
      "z": 2,
      "name": "Empty"
    },
    {
      "x": -18,
      "y": 3,
      "z": 2,
      "name": "Empty"
    },
    {
      "x": -18,
      "y": 4,
      "z": 2,
      "name": "Empty"
    },
    {
      "x": -18,
      "y": 5,
      "z": 2,
      "name": "Empty"
    },
    {
      "x": -18,
      "y": 6,
      "z": 2,
      "name": "Empty"
    },
    {
      "x": -18,
      "y": 7,
      "z": 2,
      "name": "Empty"
    },
    {
      "x": -18,
      "y": -1,
      "z": 3,
      "name": "Wood_Softwood_Planks_Half",
      "rotation": 8
    },
    {
      "x": -18,
      "y": 0,
      "z": 3,
      "name": "Wood_Softwood_Planks"
    },
    {
      "x": -18,
      "y": 1,
      "z": 3,
      "name": "Empty"
    },
    {
      "x": -18,
      "y": 2,
      "z": 3,
      "name": "Empty"
    },
    {
      "x": -18,
      "y": 3,
      "z": 3,
      "name": "Empty"
    },
    {
      "x": -18,
      "y": 4,
      "z": 3,
      "name": "Empty"
    },
    {
      "x": -18,
      "y": 5,
      "z": 3,
      "name": "Empty"
    },
    {
      "x": -18,
      "y": 6,
      "z": 3,
      "name": "Empty"
    },
    {
      "x": -18,
      "y": 7,
      "z": 3,
      "name": "Empty"
    },
    {
      "x": -18,
      "y": -3,
      "z": 4,
      "name": "Rock_Stone_Cobble"
    },
    {
      "x": -18,
      "y": -2,
      "z": 4,
      "name": "Rock_Stone_Cobble"
    },
    {
      "x": -18,
      "y": -1,
      "z": 4,
      "name": "Wood_Softwood_Planks_Half",
      "rotation": 8
    },
    {
      "x": -18,
      "y": 0,
      "z": 4,
      "name": "Wood_Softwood_Planks"
    },
    {
      "x": -18,
      "y": 1,
      "z": 4,
      "name": "Empty"
    },
    {
      "x": -18,
      "y": 2,
      "z": 4,
      "name": "Empty"
    },
    {
      "x": -18,
      "y": 3,
      "z": 4,
      "name": "Empty"
    },
    {
      "x": -18,
      "y": 4,
      "z": 4,
      "name": "Empty"
    },
    {
      "x": -18,
      "y": 5,
      "z": 4,
      "name": "Empty"
    },
    {
      "x": -18,
      "y": 6,
      "z": 4,
      "name": "Empty"
    },
    {
      "x": -18,
      "y": 7,
      "z": 4,
      "name": "Empty"
    },
    {
      "x": -18,
      "y": 0,
      "z": 5,
      "name": "Wood_Softwood_Planks"
    },
    {
      "x": -18,
      "y": 1,
      "z": 5,
      "name": "Empty"
    },
    {
      "x": -18,
      "y": 2,
      "z": 5,
      "name": "Empty"
    },
    {
      "x": -18,
      "y": 3,
      "z": 5,
      "name": "Empty"
    },
    {
      "x": -18,
      "y": 4,
      "z": 5,
      "name": "Empty"
    },
    {
      "x": -18,
      "y": 5,
      "z": 5,
      "name": "Empty"
    },
    {
      "x": -18,
      "y": 6,
      "z": 5,
      "name": "Empty"
    },
    {
      "x": -18,
      "y": 7,
      "z": 5,
      "name": "Empty"
    },
    {
      "x": -18,
      "y": 0,
      "z": 6,
      "name": "Wood_Softwood_Planks"
    },
    {
      "x": -18,
      "y": 1,
      "z": 6,
      "name": "Empty"
    },
    {
      "x": -18,
      "y": 2,
      "z": 6,
      "name": "Empty"
    },
    {
      "x": -18,
      "y": 3,
      "z": 6,
      "name": "Empty"
    },
    {
      "x": -18,
      "y": 4,
      "z": 6,
      "name": "Empty"
    },
    {
      "x": -18,
      "y": 5,
      "z": 6,
      "name": "Empty"
    },
    {
      "x": -18,
      "y": 6,
      "z": 6,
      "name": "Empty"
    },
    {
      "x": -18,
      "y": 7,
      "z": 6,
      "name": "Empty"
    },
    {
      "x": -18,
      "y": 0,
      "z": 7,
      "name": "Wood_Softwood_Planks"
    },
    {
      "x": -18,
      "y": 1,
      "z": 7,
      "name": "Wood_Softwood_Decorative"
    },
    {
      "x": -18,
      "y": 2,
      "z": 7,
      "name": "Wood_Softwood_Decorative"
    },
    {
      "x": -18,
      "y": 3,
      "z": 7,
      "name": "Wood_Softwood_Decorative"
    },
    {
      "x": -18,
      "y": 4,
      "z": 7,
      "name": "Wood_Softwood_Decorative"
    },
    {
      "x": -18,
      "y": 5,
      "z": 7,
      "name": "Wood_Deadwood_Roof_Flat"
    },
    {
      "x": -18,
      "y": 6,
      "z": 7,
      "name": "Empty"
    },
    {
      "x": -18,
      "y": 7,
      "z": 7,
      "name": "Empty"
    },
    {
      "x": -18,
      "y": -1,
      "z": 8,
      "name": "Wood_Softwood_Fence",
      "rotation": 2
    },
    {
      "x": -18,
      "y": 0,
      "z": 8,
      "name": "Wood_Oak_Trunk",
      "rotation": 5
    },
    {
      "x": -18,
      "y": 1,
      "z": 8,
      "name": "Empty"
    },
    {
      "x": -18,
      "y": 2,
      "z": 8,
      "name": "Empty"
    },
    {
      "x": -18,
      "y": 3,
      "z": 8,
      "name": "Empty"
    },
    {
      "x": -18,
      "y": 4,
      "z": 8,
      "name": "Empty"
    },
    {
      "x": -18,
      "y": 5,
      "z": 8,
      "name": "Wood_Deadwood_Roof_Flat"
    },
    {
      "x": -18,
      "y": 6,
      "z": 8,
      "name": "Empty"
    },
    {
      "x": -18,
      "y": 7,
      "z": 8,
      "name": "Empty"
    },
    {
      "x": -18,
      "y": 1,
      "z": 9,
      "name": "Empty"
    },
    {
      "x": -18,
      "y": 2,
      "z": 9,
      "name": "Empty"
    },
    {
      "x": -18,
      "y": 3,
      "z": 9,
      "name": "Empty"
    },
    {
      "x": -18,
      "y": 4,
      "z": 9,
      "name": "Empty"
    },
    {
      "x": -18,
      "y": 5,
      "z": 9,
      "name": "Empty"
    },
    {
      "x": -18,
      "y": 6,
      "z": 9,
      "name": "Empty"
    },
    {
      "x": -18,
      "y": 7,
      "z": 9,
      "name": "Empty"
    },
    {
      "x": -18,
      "y": 1,
      "z": 10,
      "name": "Empty"
    },
    {
      "x": -18,
      "y": 2,
      "z": 10,
      "name": "Empty"
    },
    {
      "x": -18,
      "y": 3,
      "z": 10,
      "name": "Empty"
    },
    {
      "x": -18,
      "y": 4,
      "z": 10,
      "name": "Empty"
    },
    {
      "x": -18,
      "y": 5,
      "z": 10,
      "name": "Empty"
    },
    {
      "x": -18,
      "y": 6,
      "z": 10,
      "name": "Empty"
    },
    {
      "x": -18,
      "y": 7,
      "z": 10,
      "name": "Empty"
    },
    {
      "x": -17,
      "y": -2,
      "z": -2,
      "name": "Rock_Stone_Cobble"
    },
    {
      "x": -17,
      "y": -1,
      "z": -2,
      "name": "Rock_Stone_Cobble"
    },
    {
      "x": -17,
      "y": 0,
      "z": -2,
      "name": "Wood_Beech_Trunk",
      "rotation": 5
    },
    {
      "x": -17,
      "y": 1,
      "z": -2,
      "name": "Wood_Softwood_Planks"
    },
    {
      "x": -17,
      "y": 2,
      "z": -2,
      "name": "Wood_Softwood_Planks"
    },
    {
      "x": -17,
      "y": 3,
      "z": -2,
      "name": "Wood_Softwood_Planks"
    },
    {
      "x": -17,
      "y": 4,
      "z": -2,
      "name": "Wood_Softwood_Planks"
    },
    {
      "x": -17,
      "y": 5,
      "z": -2,
      "name": "Wood_Deadwood_Roof",
      "rotation": 3
    },
    {
      "x": -17,
      "y": -2,
      "z": -1,
      "name": "Rock_Stone_Cobble"
    },
    {
      "x": -17,
      "y": -1,
      "z": -1,
      "name": "Rock_Stone_Cobble"
    },
    {
      "x": -17,
      "y": 0,
      "z": -1,
      "name": "Wood_Deadwood_Planks"
    },
    {
      "x": -17,
      "y": 1,
      "z": -1,
      "name": "Empty"
    },
    {
      "x": -17,
      "y": 2,
      "z": -1,
      "name": "Empty"
    },
    {
      "x": -17,
      "y": 3,
      "z": -1,
      "name": "Empty"
    },
    {
      "x": -17,
      "y": 4,
      "z": -1,
      "name": "Wood_Softwood_Planks_Half",
      "rotation": 8
    },
    {
      "x": -17,
      "y": 5,
      "z": -1,
      "name": "Wood_Deadwood_Roof",
      "rotation": 3
    },
    {
      "x": -17,
      "y": -1,
      "z": 0,
      "name": "Rock_Stone_Cobble"
    },
    {
      "x": -17,
      "y": 0,
      "z": 0,
      "name": "Wood_Deadwood_Decorative"
    },
    {
      "x": -17,
      "y": 1,
      "z": 0,
      "name": "Empty"
    },
    {
      "x": -17,
      "y": 2,
      "z": 0,
      "name": "Empty"
    },
    {
      "x": -17,
      "y": 3,
      "z": 0,
      "name": "Empty"
    },
    {
      "x": -17,
      "y": 4,
      "z": 0,
      "name": "Wood_Softwood_Planks_Half",
      "rotation": 8
    },
    {
      "x": -17,
      "y": 5,
      "z": 0,
      "name": "Empty"
    },
    {
      "x": -17,
      "y": -2,
      "z": 1,
      "name": "Rock_Stone_Cobble"
    },
    {
      "x": -17,
      "y": -1,
      "z": 1,
      "name": "Rock_Stone_Cobble"
    },
    {
      "x": -17,
      "y": 0,
      "z": 1,
      "name": "Wood_Deadwood_Decorative"
    },
    {
      "x": -17,
      "y": 1,
      "z": 1,
      "name": "Empty"
    },
    {
      "x": -17,
      "y": 2,
      "z": 1,
      "name": "Empty"
    },
    {
      "x": -17,
      "y": 3,
      "z": 1,
      "name": "Empty"
    },
    {
      "x": -17,
      "y": 4,
      "z": 1,
      "name": "Empty"
    },
    {
      "x": -17,
      "y": 5,
      "z": 1,
      "name": "Empty"
    },
    {
      "x": -17,
      "y": 6,
      "z": 1,
      "name": "Empty"
    },
    {
      "x": -17,
      "y": 7,
      "z": 1,
      "name": "Empty"
    },
    {
      "x": -17,
      "y": -2,
      "z": 2,
      "name": "Rock_Stone_Cobble"
    },
    {
      "x": -17,
      "y": -1,
      "z": 2,
      "name": "Rock_Stone_Cobble"
    },
    {
      "x": -17,
      "y": 0,
      "z": 2,
      "name": "Wood_Deadwood_Decorative"
    },
    {
      "x": -17,
      "y": 1,
      "z": 2,
      "name": "Empty"
    },
    {
      "x": -17,
      "y": 2,
      "z": 2,
      "name": "Empty"
    },
    {
      "x": -17,
      "y": 3,
      "z": 2,
      "name": "Empty"
    },
    {
      "x": -17,
      "y": 4,
      "z": 2,
      "name": "Empty"
    },
    {
      "x": -17,
      "y": 5,
      "z": 2,
      "name": "Empty"
    },
    {
      "x": -17,
      "y": 6,
      "z": 2,
      "name": "Empty"
    },
    {
      "x": -17,
      "y": 7,
      "z": 2,
      "name": "Empty"
    },
    {
      "x": -17,
      "y": -3,
      "z": 3,
      "name": "Rock_Stone_Cobble"
    },
    {
      "x": -17,
      "y": -2,
      "z": 3,
      "name": "Rock_Stone_Cobble"
    },
    {
      "x": -17,
      "y": -1,
      "z": 3,
      "name": "Wood_Softwood_Planks_Half",
      "rotation": 8
    },
    {
      "x": -17,
      "y": 0,
      "z": 3,
      "name": "Wood_Softwood_Planks"
    },
    {
      "x": -17,
      "y": 1,
      "z": 3,
      "name": "Empty"
    },
    {
      "x": -17,
      "y": 2,
      "z": 3,
      "name": "Empty"
    },
    {
      "x": -17,
      "y": 3,
      "z": 3,
      "name": "Empty"
    },
    {
      "x": -17,
      "y": 4,
      "z": 3,
      "name": "Empty"
    },
    {
      "x": -17,
      "y": 5,
      "z": 3,
      "name": "Empty"
    },
    {
      "x": -17,
      "y": 6,
      "z": 3,
      "name": "Empty"
    },
    {
      "x": -17,
      "y": 7,
      "z": 3,
      "name": "Empty"
    },
    {
      "x": -17,
      "y": -3,
      "z": 4,
      "name": "Rock_Stone_Cobble"
    },
    {
      "x": -17,
      "y": -2,
      "z": 4,
      "name": "Rock_Stone_Cobble"
    },
    {
      "x": -17,
      "y": -1,
      "z": 4,
      "name": "Wood_Softwood_Planks_Half",
      "rotation": 8
    },
    {
      "x": -17,
      "y": 0,
      "z": 4,
      "name": "Wood_Softwood_Planks"
    },
    {
      "x": -17,
      "y": 1,
      "z": 4,
      "name": "Empty"
    },
    {
      "x": -17,
      "y": 2,
      "z": 4,
      "name": "Empty"
    },
    {
      "x": -17,
      "y": 3,
      "z": 4,
      "name": "Empty"
    },
    {
      "x": -17,
      "y": 4,
      "z": 4,
      "name": "Empty"
    },
    {
      "x": -17,
      "y": 5,
      "z": 4,
      "name": "Empty"
    },
    {
      "x": -17,
      "y": 6,
      "z": 4,
      "name": "Empty"
    },
    {
      "x": -17,
      "y": 7,
      "z": 4,
      "name": "Empty"
    },
    {
      "x": -17,
      "y": -1,
      "z": 5,
      "name": "Wood_Softwood_Planks_Half",
      "rotation": 8
    },
    {
      "x": -17,
      "y": 0,
      "z": 5,
      "name": "Wood_Softwood_Planks"
    },
    {
      "x": -17,
      "y": 1,
      "z": 5,
      "name": "Empty"
    },
    {
      "x": -17,
      "y": 2,
      "z": 5,
      "name": "Empty"
    },
    {
      "x": -17,
      "y": 3,
      "z": 5,
      "name": "Empty"
    },
    {
      "x": -17,
      "y": 4,
      "z": 5,
      "name": "Empty"
    },
    {
      "x": -17,
      "y": 5,
      "z": 5,
      "name": "Empty"
    },
    {
      "x": -17,
      "y": 6,
      "z": 5,
      "name": "Empty"
    },
    {
      "x": -17,
      "y": 7,
      "z": 5,
      "name": "Empty"
    },
    {
      "x": -17,
      "y": 0,
      "z": 6,
      "name": "Wood_Softwood_Planks"
    },
    {
      "x": -17,
      "y": 1,
      "z": 6,
      "name": "Empty"
    },
    {
      "x": -17,
      "y": 2,
      "z": 6,
      "name": "Empty"
    },
    {
      "x": -17,
      "y": 3,
      "z": 6,
      "name": "Empty"
    },
    {
      "x": -17,
      "y": 4,
      "z": 6,
      "name": "Wood_Softwood_Planks_Half",
      "rotation": 8
    },
    {
      "x": -17,
      "y": 5,
      "z": 6,
      "name": "Empty"
    },
    {
      "x": -17,
      "y": 6,
      "z": 6,
      "name": "Empty"
    },
    {
      "x": -17,
      "y": 7,
      "z": 6,
      "name": "Empty"
    },
    {
      "x": -17,
      "y": 0,
      "z": 7,
      "name": "Wood_Softwood_Planks"
    },
    {
      "x": -17,
      "y": 1,
      "z": 7,
      "name": "Wood_Softwood_Planks"
    },
    {
      "x": -17,
      "y": 2,
      "z": 7,
      "name": "Wood_Softwood_Planks"
    },
    {
      "x": -17,
      "y": 3,
      "z": 7,
      "name": "Wood_Softwood_Planks"
    },
    {
      "x": -17,
      "y": 4,
      "z": 7,
      "name": "Wood_Softwood_Planks"
    },
    {
      "x": -17,
      "y": 5,
      "z": 7,
      "name": "Wood_Softwood_Planks_Half"
    },
    {
      "x": -17,
      "y": 6,
      "z": 7,
      "name": "Empty"
    },
    {
      "x": -17,
      "y": 7,
      "z": 7,
      "name": "Empty"
    },
    {
      "x": -17,
      "y": -1,
      "z": 8,
      "name": "Wood_Softwood_Fence",
      "rotation": 2
    },
    {
      "x": -17,
      "y": 0,
      "z": 8,
      "name": "Wood_Oak_Trunk",
      "rotation": 5
    },
    {
      "x": -17,
      "y": 1,
      "z": 8,
      "name": "Empty"
    },
    {
      "x": -17,
      "y": 2,
      "z": 8,
      "name": "Empty"
    },
    {
      "x": -17,
      "y": 3,
      "z": 8,
      "name": "Empty"
    },
    {
      "x": -17,
      "y": 4,
      "z": 8,
      "name": "Empty"
    },
    {
      "x": -17,
      "y": 5,
      "z": 8,
      "name": "Wood_Deadwood_Roof_Hollow",
      "rotation": 3
    },
    {
      "x": -17,
      "y": 6,
      "z": 8,
      "name": "Empty"
    },
    {
      "x": -17,
      "y": 7,
      "z": 8,
      "name": "Empty"
    },
    {
      "x": -17,
      "y": 1,
      "z": 9,
      "name": "Empty"
    },
    {
      "x": -17,
      "y": 2,
      "z": 9,
      "name": "Empty"
    },
    {
      "x": -17,
      "y": 3,
      "z": 9,
      "name": "Empty"
    },
    {
      "x": -17,
      "y": 4,
      "z": 9,
      "name": "Empty"
    },
    {
      "x": -17,
      "y": 5,
      "z": 9,
      "name": "Empty"
    },
    {
      "x": -17,
      "y": 6,
      "z": 9,
      "name": "Empty"
    },
    {
      "x": -17,
      "y": 7,
      "z": 9,
      "name": "Empty"
    },
    {
      "x": -17,
      "y": 1,
      "z": 10,
      "name": "Empty"
    },
    {
      "x": -17,
      "y": 2,
      "z": 10,
      "name": "Empty"
    },
    {
      "x": -17,
      "y": 3,
      "z": 10,
      "name": "Empty"
    },
    {
      "x": -17,
      "y": 4,
      "z": 10,
      "name": "Empty"
    },
    {
      "x": -17,
      "y": 5,
      "z": 10,
      "name": "Empty"
    },
    {
      "x": -17,
      "y": 6,
      "z": 10,
      "name": "Empty"
    },
    {
      "x": -17,
      "y": 7,
      "z": 10,
      "name": "Empty"
    },
    {
      "x": -16,
      "y": 0,
      "z": -3,
      "name": "Wood_Oak_Trunk",
      "rotation": 5
    },
    {
      "x": -16,
      "y": 6,
      "z": -3,
      "name": "Wood_Deadwood_Roof_Flat"
    },
    {
      "x": -16,
      "y": 0,
      "z": -2,
      "name": "Wood_Beech_Trunk",
      "rotation": 5
    },
    {
      "x": -16,
      "y": 1,
      "z": -2,
      "name": "Wood_Softwood_Decorative"
    },
    {
      "x": -16,
      "y": 2,
      "z": -2,
      "name": "Wood_Softwood_Decorative"
    },
    {
      "x": -16,
      "y": 3,
      "z": -2,
      "name": "Wood_Softwood_Decorative"
    },
    {
      "x": -16,
      "y": 4,
      "z": -2,
      "name": "Wood_Softwood_Decorative"
    },
    {
      "x": -16,
      "y": 5,
      "z": -2,
      "name": "Wood_Softwood_Decorative"
    },
    {
      "x": -16,
      "y": 6,
      "z": -2,
      "name": "Wood_Deadwood_Roof_Flat"
    },
    {
      "x": -16,
      "y": 0,
      "z": -1,
      "name": "Wood_Softwood_Planks"
    },
    {
      "x": -16,
      "y": 1,
      "z": -1,
      "name": "Empty"
    },
    {
      "x": -16,
      "y": 2,
      "z": -1,
      "name": "Empty"
    },
    {
      "x": -16,
      "y": 3,
      "z": -1,
      "name": "Empty"
    },
    {
      "x": -16,
      "y": 4,
      "z": -1,
      "name": "Empty"
    },
    {
      "x": -16,
      "y": 5,
      "z": -1,
      "name": "Wood_Softwood_Planks"
    },
    {
      "x": -16,
      "y": 0,
      "z": 0,
      "name": "Wood_Softwood_Planks"
    },
    {
      "x": -16,
      "y": 1,
      "z": 0,
      "name": "Empty"
    },
    {
      "x": -16,
      "y": 2,
      "z": 0,
      "name": "Empty"
    },
    {
      "x": -16,
      "y": 3,
      "z": 0,
      "name": "Empty"
    },
    {
      "x": -16,
      "y": 4,
      "z": 0,
      "name": "Empty"
    },
    {
      "x": -16,
      "y": 5,
      "z": 0,
      "name": "Empty"
    },
    {
      "x": -16,
      "y": 0,
      "z": 1,
      "name": "Wood_Softwood_Planks"
    },
    {
      "x": -16,
      "y": 1,
      "z": 1,
      "name": "Empty"
    },
    {
      "x": -16,
      "y": 2,
      "z": 1,
      "name": "Empty"
    },
    {
      "x": -16,
      "y": 3,
      "z": 1,
      "name": "Empty"
    },
    {
      "x": -16,
      "y": 4,
      "z": 1,
      "name": "Empty"
    },
    {
      "x": -16,
      "y": 5,
      "z": 1,
      "name": "Empty"
    },
    {
      "x": -16,
      "y": 6,
      "z": 1,
      "name": "Empty"
    },
    {
      "x": -16,
      "y": 7,
      "z": 1,
      "name": "Empty"
    },
    {
      "x": -16,
      "y": 0,
      "z": 2,
      "name": "Wood_Softwood_Planks"
    },
    {
      "x": -16,
      "y": 1,
      "z": 2,
      "name": "Empty"
    },
    {
      "x": -16,
      "y": 2,
      "z": 2,
      "name": "Empty"
    },
    {
      "x": -16,
      "y": 3,
      "z": 2,
      "name": "Empty"
    },
    {
      "x": -16,
      "y": 4,
      "z": 2,
      "name": "Empty"
    },
    {
      "x": -16,
      "y": 5,
      "z": 2,
      "name": "Empty"
    },
    {
      "x": -16,
      "y": 6,
      "z": 2,
      "name": "Empty"
    },
    {
      "x": -16,
      "y": 7,
      "z": 2,
      "name": "Empty"
    },
    {
      "x": -16,
      "y": 0,
      "z": 3,
      "name": "Wood_Deadwood_Planks"
    },
    {
      "x": -16,
      "y": 1,
      "z": 3,
      "name": "Empty"
    },
    {
      "x": -16,
      "y": 2,
      "z": 3,
      "name": "Empty"
    },
    {
      "x": -16,
      "y": 3,
      "z": 3,
      "name": "Empty"
    },
    {
      "x": -16,
      "y": 4,
      "z": 3,
      "name": "Empty"
    },
    {
      "x": -16,
      "y": 5,
      "z": 3,
      "name": "Empty"
    },
    {
      "x": -16,
      "y": 6,
      "z": 3,
      "name": "Empty"
    },
    {
      "x": -16,
      "y": 7,
      "z": 3,
      "name": "Empty"
    },
    {
      "x": -16,
      "y": -1,
      "z": 4,
      "name": "Wood_Softwood_Planks_Half",
      "rotation": 8
    },
    {
      "x": -16,
      "y": 0,
      "z": 4,
      "name": "Wood_Softwood_Planks"
    },
    {
      "x": -16,
      "y": 1,
      "z": 4,
      "name": "Empty"
    },
    {
      "x": -16,
      "y": 2,
      "z": 4,
      "name": "Empty"
    },
    {
      "x": -16,
      "y": 3,
      "z": 4,
      "name": "Empty"
    },
    {
      "x": -16,
      "y": 4,
      "z": 4,
      "name": "Empty"
    },
    {
      "x": -16,
      "y": 5,
      "z": 4,
      "name": "Empty"
    },
    {
      "x": -16,
      "y": 6,
      "z": 4,
      "name": "Empty"
    },
    {
      "x": -16,
      "y": 7,
      "z": 4,
      "name": "Empty"
    },
    {
      "x": -16,
      "y": -1,
      "z": 5,
      "name": "Wood_Softwood_Planks_Half",
      "rotation": 8
    },
    {
      "x": -16,
      "y": 0,
      "z": 5,
      "name": "Wood_Softwood_Planks"
    },
    {
      "x": -16,
      "y": 1,
      "z": 5,
      "name": "Empty"
    },
    {
      "x": -16,
      "y": 2,
      "z": 5,
      "name": "Empty"
    },
    {
      "x": -16,
      "y": 3,
      "z": 5,
      "name": "Empty"
    },
    {
      "x": -16,
      "y": 4,
      "z": 5,
      "name": "Empty"
    },
    {
      "x": -16,
      "y": 5,
      "z": 5,
      "name": "Empty"
    },
    {
      "x": -16,
      "y": 6,
      "z": 5,
      "name": "Empty"
    },
    {
      "x": -16,
      "y": 7,
      "z": 5,
      "name": "Empty"
    },
    {
      "x": -16,
      "y": -1,
      "z": 6,
      "name": "Wood_Softwood_Planks_Half",
      "rotation": 8
    },
    {
      "x": -16,
      "y": 1,
      "z": 6,
      "name": "Plant_Grass_Sharp"
    },
    {
      "x": -16,
      "y": 2,
      "z": 6,
      "name": "Empty"
    },
    {
      "x": -16,
      "y": 3,
      "z": 6,
      "name": "Empty"
    },
    {
      "x": -16,
      "y": 4,
      "z": 6,
      "name": "Empty"
    },
    {
      "x": -16,
      "y": 5,
      "z": 6,
      "name": "Empty"
    },
    {
      "x": -16,
      "y": 6,
      "z": 6,
      "name": "Empty"
    },
    {
      "x": -16,
      "y": 7,
      "z": 6,
      "name": "Empty"
    },
    {
      "x": -16,
      "y": 0,
      "z": 7,
      "name": "Wood_Softwood_Planks"
    },
    {
      "x": -16,
      "y": 1,
      "z": 7,
      "name": "Wood_Softwood_Decorative"
    },
    {
      "x": -16,
      "y": 2,
      "z": 7,
      "name": "Wood_Softwood_Decorative"
    },
    {
      "x": -16,
      "y": 3,
      "z": 7,
      "name": "Wood_Softwood_Decorative"
    },
    {
      "x": -16,
      "y": 4,
      "z": 7,
      "name": "Wood_Softwood_Decorative"
    },
    {
      "x": -16,
      "y": 5,
      "z": 7,
      "name": "Wood_Softwood_Decorative"
    },
    {
      "x": -16,
      "y": 6,
      "z": 7,
      "name": "Empty"
    },
    {
      "x": -16,
      "y": 7,
      "z": 7,
      "name": "Empty"
    },
    {
      "x": -16,
      "y": -1,
      "z": 8,
      "name": "Wood_Softwood_Fence",
      "rotation": 2
    },
    {
      "x": -16,
      "y": 0,
      "z": 8,
      "name": "Wood_Oak_Trunk",
      "rotation": 5
    },
    {
      "x": -16,
      "y": 1,
      "z": 8,
      "name": "Empty"
    },
    {
      "x": -16,
      "y": 2,
      "z": 8,
      "name": "Empty"
    },
    {
      "x": -16,
      "y": 3,
      "z": 8,
      "name": "Empty"
    },
    {
      "x": -16,
      "y": 4,
      "z": 8,
      "name": "Empty"
    },
    {
      "x": -16,
      "y": 5,
      "z": 8,
      "name": "Plant_Vine_Wall"
    },
    {
      "x": -16,
      "y": 6,
      "z": 8,
      "name": "Wood_Deadwood_Roof_Flat"
    },
    {
      "x": -16,
      "y": 7,
      "z": 8,
      "name": "Empty"
    },
    {
      "x": -16,
      "y": 1,
      "z": 9,
      "name": "Empty"
    },
    {
      "x": -16,
      "y": 2,
      "z": 9,
      "name": "Empty"
    },
    {
      "x": -16,
      "y": 3,
      "z": 9,
      "name": "Empty"
    },
    {
      "x": -16,
      "y": 4,
      "z": 9,
      "name": "Empty"
    },
    {
      "x": -16,
      "y": 5,
      "z": 9,
      "name": "Wood_Deadwood_Roof_Hollow",
      "rotation": 3
    },
    {
      "x": -16,
      "y": 6,
      "z": 9,
      "name": "Empty"
    },
    {
      "x": -16,
      "y": 7,
      "z": 9,
      "name": "Empty"
    },
    {
      "x": -16,
      "y": 1,
      "z": 10,
      "name": "Empty"
    },
    {
      "x": -16,
      "y": 2,
      "z": 10,
      "name": "Empty"
    },
    {
      "x": -16,
      "y": 3,
      "z": 10,
      "name": "Empty"
    },
    {
      "x": -16,
      "y": 4,
      "z": 10,
      "name": "Empty"
    },
    {
      "x": -16,
      "y": 5,
      "z": 10,
      "name": "Wood_Deadwood_Roof_Hollow",
      "rotation": 3
    },
    {
      "x": -16,
      "y": 6,
      "z": 10,
      "name": "Empty"
    },
    {
      "x": -16,
      "y": 7,
      "z": 10,
      "name": "Empty"
    },
    {
      "x": -15,
      "y": 0,
      "z": -3,
      "name": "Wood_Oak_Trunk"
    },
    {
      "x": -15,
      "y": 1,
      "z": -3,
      "name": "Wood_Oak_Trunk"
    },
    {
      "x": -15,
      "y": 2,
      "z": -3,
      "name": "Wood_Oak_Trunk"
    },
    {
      "x": -15,
      "y": 3,
      "z": -3,
      "name": "Wood_Oak_Trunk"
    },
    {
      "x": -15,
      "y": 4,
      "z": -3,
      "name": "Wood_Oak_Trunk"
    },
    {
      "x": -15,
      "y": 5,
      "z": -3,
      "name": "Wood_Oak_Trunk"
    },
    {
      "x": -15,
      "y": 6,
      "z": -3,
      "name": "Wood_Deadwood_Roof",
      "rotation": 3
    },
    {
      "x": -15,
      "y": -1,
      "z": -2,
      "name": "Wood_Softwood_Fence",
      "rotation": 3
    },
    {
      "x": -15,
      "y": 0,
      "z": -2,
      "name": "Wood_Oak_Trunk",
      "rotation": 4
    },
    {
      "x": -15,
      "y": 1,
      "z": -2,
      "name": "Wood_Softwood_Planks"
    },
    {
      "x": -15,
      "y": 2,
      "z": -2,
      "name": "Wood_Softwood_Planks"
    },
    {
      "x": -15,
      "y": 3,
      "z": -2,
      "name": "Wood_Softwood_Planks"
    },
    {
      "x": -15,
      "y": 4,
      "z": -2,
      "name": "Wood_Softwood_Planks"
    },
    {
      "x": -15,
      "y": 5,
      "z": -2,
      "name": "Wood_Softwood_Planks"
    },
    {
      "x": -15,
      "y": 6,
      "z": -2,
      "name": "Wood_Deadwood_Roof",
      "rotation": 3
    },
    {
      "x": -15,
      "y": -1,
      "z": -1,
      "name": "Wood_Softwood_Fence",
      "rotation": 3
    },
    {
      "x": -15,
      "y": 0,
      "z": -1,
      "name": "Wood_Oak_Trunk",
      "rotation": 4
    },
    {
      "x": -15,
      "y": 1,
      "z": -1,
      "name": "Wood_Softwood_Planks"
    },
    {
      "x": -15,
      "y": 2,
      "z": -1,
      "name": "Wood_Softwood_Planks"
    },
    {
      "x": -15,
      "y": 3,
      "z": -1,
      "name": "Wood_Softwood_Planks"
    },
    {
      "x": -15,
      "y": 4,
      "z": -1,
      "name": "Wood_Softwood_Planks"
    },
    {
      "x": -15,
      "y": 5,
      "z": -1,
      "name": "Wood_Softwood_Planks"
    },
    {
      "x": -15,
      "y": 6,
      "z": -1,
      "name": "Wood_Deadwood_Roof",
      "rotation": 3
    },
    {
      "x": -15,
      "y": -2,
      "z": 0,
      "name": "Wood_Oak_Trunk"
    },
    {
      "x": -15,
      "y": -1,
      "z": 0,
      "name": "Wood_Oak_Trunk"
    },
    {
      "x": -15,
      "y": 0,
      "z": 0,
      "name": "Wood_Oak_Trunk"
    },
    {
      "x": -15,
      "y": 1,
      "z": 0,
      "name": "Wood_Oak_Trunk"
    },
    {
      "x": -15,
      "y": 2,
      "z": 0,
      "name": "Wood_Oak_Trunk"
    },
    {
      "x": -15,
      "y": 3,
      "z": 0,
      "name": "Wood_Oak_Trunk"
    },
    {
      "x": -15,
      "y": 4,
      "z": 0,
      "name": "Wood_Oak_Trunk"
    },
    {
      "x": -15,
      "y": 5,
      "z": 0,
      "name": "Wood_Oak_Trunk"
    },
    {
      "x": -15,
      "y": 6,
      "z": 0,
      "name": "Wood_Deadwood_Roof",
      "rotation": 3
    },
    {
      "x": -15,
      "y": -1,
      "z": 1,
      "name": "Rock_Stone"
    },
    {
      "x": -15,
      "y": 0,
      "z": 1,
      "name": "Wood_Softwood_Planks"
    },
    {
      "x": -15,
      "y": 1,
      "z": 1,
      "name": "Empty"
    },
    {
      "x": -15,
      "y": 2,
      "z": 1,
      "name": "Empty"
    },
    {
      "x": -15,
      "y": 3,
      "z": 1,
      "name": "Empty"
    },
    {
      "x": -15,
      "y": 4,
      "z": 1,
      "name": "Empty"
    },
    {
      "x": -15,
      "y": 5,
      "z": 1,
      "name": "Empty"
    },
    {
      "x": -15,
      "y": 6,
      "z": 1,
      "name": "Empty"
    },
    {
      "x": -15,
      "y": 7,
      "z": 1,
      "name": "Empty"
    },
    {
      "x": -15,
      "y": -1,
      "z": 2,
      "name": "Rock_Stone"
    },
    {
      "x": -15,
      "y": 0,
      "z": 2,
      "name": "Wood_Softwood_Planks"
    },
    {
      "x": -15,
      "y": 1,
      "z": 2,
      "name": "Empty"
    },
    {
      "x": -15,
      "y": 2,
      "z": 2,
      "name": "Empty"
    },
    {
      "x": -15,
      "y": 3,
      "z": 2,
      "name": "Empty"
    },
    {
      "x": -15,
      "y": 4,
      "z": 2,
      "name": "Empty"
    },
    {
      "x": -15,
      "y": 5,
      "z": 2,
      "name": "Empty"
    },
    {
      "x": -15,
      "y": 6,
      "z": 2,
      "name": "Empty"
    },
    {
      "x": -15,
      "y": 7,
      "z": 2,
      "name": "Empty"
    },
    {
      "x": -15,
      "y": -1,
      "z": 3,
      "name": "Rock_Stone"
    },
    {
      "x": -15,
      "y": 0,
      "z": 3,
      "name": "Wood_Deadwood_Planks"
    },
    {
      "x": -15,
      "y": 1,
      "z": 3,
      "name": "Empty"
    },
    {
      "x": -15,
      "y": 2,
      "z": 3,
      "name": "Empty"
    },
    {
      "x": -15,
      "y": 3,
      "z": 3,
      "name": "Empty"
    },
    {
      "x": -15,
      "y": 4,
      "z": 3,
      "name": "Empty"
    },
    {
      "x": -15,
      "y": 5,
      "z": 3,
      "name": "Empty"
    },
    {
      "x": -15,
      "y": 6,
      "z": 3,
      "name": "Empty"
    },
    {
      "x": -15,
      "y": 7,
      "z": 3,
      "name": "Empty"
    },
    {
      "x": -15,
      "y": -1,
      "z": 4,
      "name": "Rock_Stone"
    },
    {
      "x": -15,
      "y": 0,
      "z": 4,
      "name": "Wood_Deadwood_Planks"
    },
    {
      "x": -15,
      "y": 1,
      "z": 4,
      "name": "Empty"
    },
    {
      "x": -15,
      "y": 2,
      "z": 4,
      "name": "Empty"
    },
    {
      "x": -15,
      "y": 3,
      "z": 4,
      "name": "Empty"
    },
    {
      "x": -15,
      "y": 4,
      "z": 4,
      "name": "Empty"
    },
    {
      "x": -15,
      "y": 5,
      "z": 4,
      "name": "Empty"
    },
    {
      "x": -15,
      "y": 6,
      "z": 4,
      "name": "Empty"
    },
    {
      "x": -15,
      "y": 7,
      "z": 4,
      "name": "Empty"
    },
    {
      "x": -15,
      "y": -1,
      "z": 5,
      "name": "Wood_Softwood_Planks_Half",
      "rotation": 8
    },
    {
      "x": -15,
      "y": 0,
      "z": 5,
      "name": "Wood_Softwood_Planks"
    },
    {
      "x": -15,
      "y": 1,
      "z": 5,
      "name": "Empty"
    },
    {
      "x": -15,
      "y": 2,
      "z": 5,
      "name": "Empty"
    },
    {
      "x": -15,
      "y": 3,
      "z": 5,
      "name": "Empty"
    },
    {
      "x": -15,
      "y": 4,
      "z": 5,
      "name": "Empty"
    },
    {
      "x": -15,
      "y": 5,
      "z": 5,
      "name": "Empty"
    },
    {
      "x": -15,
      "y": 6,
      "z": 5,
      "name": "Empty"
    },
    {
      "x": -15,
      "y": 7,
      "z": 5,
      "name": "Empty"
    },
    {
      "x": -15,
      "y": -1,
      "z": 6,
      "name": "Wood_Softwood_Planks_Half",
      "rotation": 8
    },
    {
      "x": -15,
      "y": 0,
      "z": 6,
      "name": "Wood_Deadwood_Planks"
    },
    {
      "x": -15,
      "y": 1,
      "z": 6,
      "name": "Empty"
    },
    {
      "x": -15,
      "y": 2,
      "z": 6,
      "name": "Empty"
    },
    {
      "x": -15,
      "y": 3,
      "z": 6,
      "name": "Empty"
    },
    {
      "x": -15,
      "y": 4,
      "z": 6,
      "name": "Empty"
    },
    {
      "x": -15,
      "y": 5,
      "z": 6,
      "name": "Empty"
    },
    {
      "x": -15,
      "y": 6,
      "z": 6,
      "name": "Empty"
    },
    {
      "x": -15,
      "y": 7,
      "z": 6,
      "name": "Empty"
    },
    {
      "x": -15,
      "y": -1,
      "z": 7,
      "name": "Wood_Softwood_Planks_Half",
      "rotation": 8
    },
    {
      "x": -15,
      "y": 0,
      "z": 7,
      "name": "Wood_Deadwood_Planks"
    },
    {
      "x": -15,
      "y": 1,
      "z": 7,
      "name": "Empty"
    },
    {
      "x": -15,
      "y": 2,
      "z": 7,
      "name": "Empty"
    },
    {
      "x": -15,
      "y": 3,
      "z": 7,
      "name": "Empty"
    },
    {
      "x": -15,
      "y": 4,
      "z": 7,
      "name": "Plant_Vine_Wall",
      "rotation": 2
    },
    {
      "x": -15,
      "y": 5,
      "z": 7,
      "name": "Wood_Softwood_Planks_Half",
      "rotation": 8
    },
    {
      "x": -15,
      "y": 6,
      "z": 7,
      "name": "Wood_Softwood_Planks_Half"
    },
    {
      "x": -15,
      "y": 7,
      "z": 7,
      "name": "Empty"
    },
    {
      "x": -15,
      "y": -3,
      "z": 8,
      "name": "Wood_Oak_Trunk"
    },
    {
      "x": -15,
      "y": -2,
      "z": 8,
      "name": "Wood_Oak_Trunk"
    },
    {
      "x": -15,
      "y": -1,
      "z": 8,
      "name": "Wood_Oak_Trunk"
    },
    {
      "x": -15,
      "y": 0,
      "z": 8,
      "name": "Wood_Oak_Trunk"
    },
    {
      "x": -15,
      "y": 1,
      "z": 8,
      "name": "Wood_Oak_Trunk"
    },
    {
      "x": -15,
      "y": 2,
      "z": 8,
      "name": "Wood_Oak_Trunk"
    },
    {
      "x": -15,
      "y": 3,
      "z": 8,
      "name": "Wood_Oak_Trunk"
    },
    {
      "x": -15,
      "y": 4,
      "z": 8,
      "name": "Wood_Oak_Trunk"
    },
    {
      "x": -15,
      "y": 5,
      "z": 8,
      "name": "Wood_Oak_Trunk"
    },
    {
      "x": -15,
      "y": 6,
      "z": 8,
      "name": "Wood_Deadwood_Roof",
      "rotation": 3
    },
    {
      "x": -15,
      "y": 7,
      "z": 8,
      "name": "Empty"
    },
    {
      "x": -15,
      "y": -1,
      "z": 9,
      "name": "Wood_Softwood_Fence",
      "rotation": 1
    },
    {
      "x": -15,
      "y": 0,
      "z": 9,
      "name": "Wood_Oak_Trunk",
      "rotation": 4
    },
    {
      "x": -15,
      "y": 1,
      "z": 9,
      "name": "Wood_Softwood_Planks"
    },
    {
      "x": -15,
      "y": 2,
      "z": 9,
      "name": "Wood_Softwood_Planks"
    },
    {
      "x": -15,
      "y": 3,
      "z": 9,
      "name": "Wood_Softwood_Planks"
    },
    {
      "x": -15,
      "y": 4,
      "z": 9,
      "name": "Wood_Softwood_Planks"
    },
    {
      "x": -15,
      "y": 5,
      "z": 9,
      "name": "Wood_Softwood_Planks"
    },
    {
      "x": -15,
      "y": 6,
      "z": 9,
      "name": "Wood_Deadwood_Roof",
      "rotation": 3
    },
    {
      "x": -15,
      "y": 7,
      "z": 9,
      "name": "Empty"
    },
    {
      "x": -15,
      "y": -3,
      "z": 10,
      "name": "Wood_Oak_Trunk"
    },
    {
      "x": -15,
      "y": -2,
      "z": 10,
      "name": "Wood_Oak_Trunk"
    },
    {
      "x": -15,
      "y": -1,
      "z": 10,
      "name": "Wood_Oak_Trunk"
    },
    {
      "x": -15,
      "y": 0,
      "z": 10,
      "name": "Wood_Oak_Trunk"
    },
    {
      "x": -15,
      "y": 1,
      "z": 10,
      "name": "Wood_Oak_Trunk"
    },
    {
      "x": -15,
      "y": 2,
      "z": 10,
      "name": "Wood_Oak_Trunk"
    },
    {
      "x": -15,
      "y": 3,
      "z": 10,
      "name": "Wood_Oak_Trunk"
    },
    {
      "x": -15,
      "y": 4,
      "z": 10,
      "name": "Wood_Oak_Trunk"
    },
    {
      "x": -15,
      "y": 5,
      "z": 10,
      "name": "Wood_Oak_Trunk"
    },
    {
      "x": -15,
      "y": 6,
      "z": 10,
      "name": "Wood_Deadwood_Roof",
      "rotation": 3
    },
    {
      "x": -15,
      "y": 7,
      "z": 10,
      "name": "Empty"
    },
    {
      "x": -14,
      "y": 7,
      "z": -2,
      "name": "Wood_Deadwood_Roof_Flat"
    },
    {
      "x": -14,
      "y": 5,
      "z": -1,
      "name": "Wood_Softwood_Planks"
    },
    {
      "x": -14,
      "y": 6,
      "z": -1,
      "name": "Wood_Softwood_Planks"
    },
    {
      "x": -14,
      "y": 7,
      "z": -1,
      "name": "Wood_Deadwood_Roof_Flat"
    },
    {
      "x": -14,
      "y": -1,
      "z": 0,
      "name": "Wood_Softwood_Fence"
    },
    {
      "x": -14,
      "y": 0,
      "z": 0,
      "name": "Wood_Oak_Trunk",
      "rotation": 5
    },
    {
      "x": -14,
      "y": 1,
      "z": 0,
      "name": "Wood_Softwood_Planks"
    },
    {
      "x": -14,
      "y": 2,
      "z": 0,
      "name": "Wood_Softwood_Planks"
    },
    {
      "x": -14,
      "y": 3,
      "z": 0,
      "name": "Wood_Softwood_Planks"
    },
    {
      "x": -14,
      "y": 4,
      "z": 0,
      "name": "Wood_Softwood_Planks"
    },
    {
      "x": -14,
      "y": 5,
      "z": 0,
      "name": "Wood_Softwood_Planks"
    },
    {
      "x": -14,
      "y": 6,
      "z": 0,
      "name": "Wood_Softwood_Planks"
    },
    {
      "x": -14,
      "y": 7,
      "z": 0,
      "name": "Wood_Deadwood_Roof_Flat"
    },
    {
      "x": -14,
      "y": -1,
      "z": 1,
      "name": "Rock_Stone"
    },
    {
      "x": -14,
      "y": 0,
      "z": 1,
      "name": "Wood_Softwood_Planks"
    },
    {
      "x": -14,
      "y": 1,
      "z": 1,
      "name": "Wood_Softwood_Stairs",
      "rotation": 3
    },
    {
      "x": -14,
      "y": 2,
      "z": 1,
      "name": "Empty"
    },
    {
      "x": -14,
      "y": 3,
      "z": 1,
      "name": "Empty"
    },
    {
      "x": -14,
      "y": 4,
      "z": 1,
      "name": "Empty"
    },
    {
      "x": -14,
      "y": 5,
      "z": 1,
      "name": "Empty"
    },
    {
      "x": -14,
      "y": 6,
      "z": 1,
      "name": "Empty"
    },
    {
      "x": -14,
      "y": 7,
      "z": 1,
      "name": "Wood_Deadwood_Roof_Flat"
    },
    {
      "x": -14,
      "y": -1,
      "z": 2,
      "name": "Rock_Stone"
    },
    {
      "x": -14,
      "y": 0,
      "z": 2,
      "name": "Wood_Deadwood_Planks"
    },
    {
      "x": -14,
      "y": 1,
      "z": 2,
      "name": "Furniture_Village_Crate",
      "components": {
        "Components": {
          "container": {
            "Position": {
              "X": -14,
              "Y": 1,
              "Z": 2
            },
            "Custom": false,
            "AllowViewing": true,
            "ItemContainer": {
              "Capacity": 20,
              "Items": {}
            }
          }
        }
      }
    },
    {
      "x": -14,
      "y": 2,
      "z": 2,
      "name": "Furniture_Village_Crate",
      "components": {
        "Components": {
          "container": {
            "Position": {
              "X": -14,
              "Y": 2,
              "Z": 2
            },
            "Custom": false,
            "AllowViewing": true,
            "ItemContainer": {
              "Capacity": 20,
              "Items": {}
            }
          }
        }
      }
    },
    {
      "x": -14,
      "y": 3,
      "z": 2,
      "name": "Empty"
    },
    {
      "x": -14,
      "y": 4,
      "z": 2,
      "name": "Empty"
    },
    {
      "x": -14,
      "y": 5,
      "z": 2,
      "name": "Empty"
    },
    {
      "x": -14,
      "y": 6,
      "z": 2,
      "name": "Empty"
    },
    {
      "x": -14,
      "y": 7,
      "z": 2,
      "name": "Empty"
    },
    {
      "x": -14,
      "y": -1,
      "z": 3,
      "name": "Rock_Stone"
    },
    {
      "x": -14,
      "y": 0,
      "z": 3,
      "name": "Wood_Deadwood_Planks"
    },
    {
      "x": -14,
      "y": 1,
      "z": 3,
      "name": "Furniture_Village_Crate",
      "components": {
        "Components": {
          "container": {
            "Position": {
              "X": -14,
              "Y": 1,
              "Z": 3
            },
            "Custom": false,
            "AllowViewing": true,
            "ItemContainer": {
              "Capacity": 20,
              "Items": {}
            }
          }
        }
      }
    },
    {
      "x": -14,
      "y": 2,
      "z": 3,
      "name": "Empty"
    },
    {
      "x": -14,
      "y": 3,
      "z": 3,
      "name": "Empty"
    },
    {
      "x": -14,
      "y": 4,
      "z": 3,
      "name": "Empty"
    },
    {
      "x": -14,
      "y": 5,
      "z": 3,
      "name": "Empty"
    },
    {
      "x": -14,
      "y": 6,
      "z": 3,
      "name": "Empty"
    },
    {
      "x": -14,
      "y": 7,
      "z": 3,
      "name": "Empty"
    },
    {
      "x": -14,
      "y": -1,
      "z": 4,
      "name": "Rock_Stone"
    },
    {
      "x": -14,
      "y": 0,
      "z": 4,
      "name": "Wood_Deadwood_Planks"
    },
    {
      "x": -14,
      "y": 1,
      "z": 4,
      "name": "Empty"
    },
    {
      "x": -14,
      "y": 2,
      "z": 4,
      "name": "Empty"
    },
    {
      "x": -14,
      "y": 3,
      "z": 4,
      "name": "Empty"
    },
    {
      "x": -14,
      "y": 4,
      "z": 4,
      "name": "Empty"
    },
    {
      "x": -14,
      "y": 5,
      "z": 4,
      "name": "Empty"
    },
    {
      "x": -14,
      "y": 6,
      "z": 4,
      "name": "Empty"
    },
    {
      "x": -14,
      "y": 7,
      "z": 4,
      "name": "Empty"
    },
    {
      "x": -14,
      "y": -1,
      "z": 5,
      "name": "Wood_Softwood_Planks_Half",
      "rotation": 8
    },
    {
      "x": -14,
      "y": 0,
      "z": 5,
      "name": "Wood_Softwood_Planks"
    },
    {
      "x": -14,
      "y": 1,
      "z": 5,
      "name": "Empty"
    },
    {
      "x": -14,
      "y": 2,
      "z": 5,
      "name": "Empty"
    },
    {
      "x": -14,
      "y": 3,
      "z": 5,
      "name": "Empty"
    },
    {
      "x": -14,
      "y": 4,
      "z": 5,
      "name": "Empty"
    },
    {
      "x": -14,
      "y": 5,
      "z": 5,
      "name": "Empty"
    },
    {
      "x": -14,
      "y": 6,
      "z": 5,
      "name": "Empty"
    },
    {
      "x": -14,
      "y": 7,
      "z": 5,
      "name": "Empty"
    },
    {
      "x": -14,
      "y": -1,
      "z": 6,
      "name": "Wood_Softwood_Planks_Half",
      "rotation": 8
    },
    {
      "x": -14,
      "y": 0,
      "z": 6,
      "name": "Wood_Deadwood_Planks"
    },
    {
      "x": -14,
      "y": 1,
      "z": 6,
      "name": "Empty"
    },
    {
      "x": -14,
      "y": 2,
      "z": 6,
      "name": "Empty"
    },
    {
      "x": -14,
      "y": 3,
      "z": 6,
      "name": "Empty"
    },
    {
      "x": -14,
      "y": 4,
      "z": 6,
      "name": "Empty"
    },
    {
      "x": -14,
      "y": 5,
      "z": 6,
      "name": "Empty"
    },
    {
      "x": -14,
      "y": 6,
      "z": 6,
      "name": "Empty"
    },
    {
      "x": -14,
      "y": 7,
      "z": 6,
      "name": "Empty"
    },
    {
      "x": -14,
      "y": -1,
      "z": 7,
      "name": "Wood_Softwood_Planks_Half",
      "rotation": 8
    },
    {
      "x": -14,
      "y": 0,
      "z": 7,
      "name": "Wood_Deadwood_Planks"
    },
    {
      "x": -14,
      "y": 1,
      "z": 7,
      "name": "Empty"
    },
    {
      "x": -14,
      "y": 2,
      "z": 7,
      "name": "Empty"
    },
    {
      "x": -14,
      "y": 3,
      "z": 7,
      "name": "Empty"
    },
    {
      "x": -14,
      "y": 4,
      "z": 7,
      "name": "Empty"
    },
    {
      "x": -14,
      "y": 5,
      "z": 7,
      "name": "Empty"
    },
    {
      "x": -14,
      "y": 6,
      "z": 7,
      "name": "Empty"
    },
    {
      "x": -14,
      "y": 7,
      "z": 7,
      "name": "Empty"
    },
    {
      "x": -14,
      "y": -2,
      "z": 8,
      "name": "Rock_Stone_Cobble"
    },
    {
      "x": -14,
      "y": -1,
      "z": 8,
      "name": "Rock_Stone_Cobble"
    },
    {
      "x": -14,
      "y": 0,
      "z": 8,
      "name": "Rock_Stone_Cobble"
    },
    {
      "x": -14,
      "y": 1,
      "z": 8,
      "name": "Rock_Stone_Cobble"
    },
    {
      "x": -14,
      "y": 2,
      "z": 8,
      "name": "Rock_Stone_Cobble"
    },
    {
      "x": -14,
      "y": 3,
      "z": 8,
      "name": "Empty"
    },
    {
      "x": -14,
      "y": 4,
      "z": 8,
      "name": "Empty"
    },
    {
      "x": -14,
      "y": 5,
      "z": 8,
      "name": "Plant_Vine_Wall",
      "rotation": 1
    },
    {
      "x": -14,
      "y": 6,
      "z": 8,
      "name": "Wood_Softwood_Planks"
    },
    {
      "x": -14,
      "y": 7,
      "z": 8,
      "name": "Wood_Deadwood_Roof_Flat"
    },
    {
      "x": -14,
      "y": -3,
      "z": 9,
      "name": "Rock_Stone_Cobble"
    },
    {
      "x": -14,
      "y": -2,
      "z": 9,
      "name": "Rock_Stone_Cobble"
    },
    {
      "x": -14,
      "y": -1,
      "z": 9,
      "name": "Rock_Stone_Cobble"
    },
    {
      "x": -14,
      "y": 0,
      "z": 9,
      "name": "Rock_Stone_Cobble"
    },
    {
      "x": -14,
      "y": 1,
      "z": 9,
      "name": "Rock_Stone_Cobble"
    },
    {
      "x": -14,
      "y": 2,
      "z": 9,
      "name": "Rock_Stone_Cobble"
    },
    {
      "x": -14,
      "y": 3,
      "z": 9,
      "name": "Rock_Stone_Cobble"
    },
    {
      "x": -14,
      "y": 4,
      "z": 9,
      "name": "Empty"
    },
    {
      "x": -14,
      "y": 5,
      "z": 9,
      "name": "Empty"
    },
    {
      "x": -14,
      "y": 6,
      "z": 9,
      "name": "Wood_Softwood_Planks"
    },
    {
      "x": -14,
      "y": 7,
      "z": 9,
      "name": "Wood_Deadwood_Roof_Flat"
    },
    {
      "x": -14,
      "y": -3,
      "z": 10,
      "name": "Rock_Stone_Cobble"
    },
    {
      "x": -14,
      "y": -2,
      "z": 10,
      "name": "Rock_Stone_Cobble"
    },
    {
      "x": -14,
      "y": -1,
      "z": 10,
      "name": "Rock_Stone_Cobble"
    },
    {
      "x": -14,
      "y": 0,
      "z": 10,
      "name": "Rock_Stone_Cobble"
    },
    {
      "x": -14,
      "y": 1,
      "z": 10,
      "name": "Rock_Stone_Cobble"
    },
    {
      "x": -14,
      "y": 2,
      "z": 10,
      "name": "Rock_Stone_Cobble"
    },
    {
      "x": -14,
      "y": 3,
      "z": 10,
      "name": "Wood_Softwood_Planks"
    },
    {
      "x": -14,
      "y": 4,
      "z": 10,
      "name": "Wood_Softwood_Planks"
    },
    {
      "x": -14,
      "y": 5,
      "z": 10,
      "name": "Wood_Softwood_Planks"
    },
    {
      "x": -14,
      "y": 6,
      "z": 10,
      "name": "Wood_Softwood_Planks"
    },
    {
      "x": -14,
      "y": 7,
      "z": 10,
      "name": "Wood_Deadwood_Roof_Flat"
    },
    {
      "x": -14,
      "y": -2,
      "z": 11,
      "name": "Rock_Stone_Cobble"
    },
    {
      "x": -14,
      "y": -1,
      "z": 11,
      "name": "Rock_Stone_Cobble"
    },
    {
      "x": -14,
      "y": 0,
      "z": 11,
      "name": "Rock_Stone_Cobble"
    },
    {
      "x": -14,
      "y": 1,
      "z": 11,
      "name": "Rock_Stone_Cobble"
    },
    {
      "x": -14,
      "y": 2,
      "z": 11,
      "name": "Rock_Stone_Cobble"
    },
    {
      "x": -14,
      "y": 3,
      "z": 11,
      "name": "Rock_Stone_Cobble"
    },
    {
      "x": -13,
      "y": 7,
      "z": -2,
      "name": "Wood_Deadwood_Roof_Flat"
    },
    {
      "x": -13,
      "y": 5,
      "z": -1,
      "name": "Wood_Softwood_Planks"
    },
    {
      "x": -13,
      "y": 6,
      "z": -1,
      "name": "Wood_Softwood_Planks"
    },
    {
      "x": -13,
      "y": 7,
      "z": -1,
      "name": "Wood_Deadwood_Roof_Flat"
    },
    {
      "x": -13,
      "y": -1,
      "z": 0,
      "name": "Wood_Softwood_Fence"
    },
    {
      "x": -13,
      "y": 0,
      "z": 0,
      "name": "Wood_Oak_Trunk",
      "rotation": 5
    },
    {
      "x": -13,
      "y": 1,
      "z": 0,
      "name": "Wood_Softwood_Planks"
    },
    {
      "x": -13,
      "y": 2,
      "z": 0,
      "name": "Wood_Softwood_Planks"
    },
    {
      "x": -13,
      "y": 3,
      "z": 0,
      "name": "Wood_Softwood_Planks"
    },
    {
      "x": -13,
      "y": 4,
      "z": 0,
      "name": "Wood_Softwood_Planks"
    },
    {
      "x": -13,
      "y": 5,
      "z": 0,
      "name": "Wood_Softwood_Planks"
    },
    {
      "x": -13,
      "y": 6,
      "z": 0,
      "name": "Wood_Softwood_Planks"
    },
    {
      "x": -13,
      "y": 7,
      "z": 0,
      "name": "Wood_Deadwood_Roof_Flat"
    },
    {
      "x": -13,
      "y": -1,
      "z": 1,
      "name": "Rock_Stone"
    },
    {
      "x": -13,
      "y": 0,
      "z": 1,
      "name": "Wood_Softwood_Planks"
    },
    {
      "x": -13,
      "y": 1,
      "z": 1,
      "name": "Wood_Softwood_Planks"
    },
    {
      "x": -13,
      "y": 2,
      "z": 1,
      "name": "Wood_Softwood_Stairs",
      "rotation": 3
    },
    {
      "x": -13,
      "y": 3,
      "z": 1,
      "name": "Empty"
    },
    {
      "x": -13,
      "y": 4,
      "z": 1,
      "name": "Empty"
    },
    {
      "x": -13,
      "y": 5,
      "z": 1,
      "name": "Empty"
    },
    {
      "x": -13,
      "y": 6,
      "z": 1,
      "name": "Wood_Softwood_Planks"
    },
    {
      "x": -13,
      "y": 7,
      "z": 1,
      "name": "Wood_Deadwood_Roof_Flat"
    },
    {
      "x": -13,
      "y": -1,
      "z": 2,
      "name": "Rock_Stone"
    },
    {
      "x": -13,
      "y": 0,
      "z": 2,
      "name": "Wood_Softwood_Planks"
    },
    {
      "x": -13,
      "y": 1,
      "z": 2,
      "name": "Plant_Moss_Rug_Green"
    },
    {
      "x": -13,
      "y": 2,
      "z": 2,
      "name": "Empty"
    },
    {
      "x": -13,
      "y": 3,
      "z": 2,
      "name": "Empty"
    },
    {
      "x": -13,
      "y": 4,
      "z": 2,
      "name": "Empty"
    },
    {
      "x": -13,
      "y": 5,
      "z": 2,
      "name": "Empty"
    },
    {
      "x": -13,
      "y": 6,
      "z": 2,
      "name": "Wood_Softwood_Planks"
    },
    {
      "x": -13,
      "y": 7,
      "z": 2,
      "name": "Wood_Deadwood_Roof_Flat"
    },
    {
      "x": -13,
      "y": -1,
      "z": 3,
      "name": "Soil_Grass"
    },
    {
      "x": -13,
      "y": 0,
      "z": 3,
      "name": "Plant_Grass_Sharp"
    },
    {
      "x": -13,
      "y": 1,
      "z": 3,
      "name": "Empty"
    },
    {
      "x": -13,
      "y": 2,
      "z": 3,
      "name": "Empty"
    },
    {
      "x": -13,
      "y": 3,
      "z": 3,
      "name": "Empty"
    },
    {
      "x": -13,
      "y": 4,
      "z": 3,
      "name": "Empty"
    },
    {
      "x": -13,
      "y": 5,
      "z": 3,
      "name": "Empty"
    },
    {
      "x": -13,
      "y": 6,
      "z": 3,
      "name": "Wood_Softwood_Planks"
    },
    {
      "x": -13,
      "y": 7,
      "z": 3,
      "name": "Wood_Softwood_Planks_Half"
    },
    {
      "x": -13,
      "y": -1,
      "z": 4,
      "name": "Rock_Stone"
    },
    {
      "x": -13,
      "y": 0,
      "z": 4,
      "name": "Wood_Softwood_Planks"
    },
    {
      "x": -13,
      "y": 1,
      "z": 4,
      "name": "Empty"
    },
    {
      "x": -13,
      "y": 2,
      "z": 4,
      "name": "Empty"
    },
    {
      "x": -13,
      "y": 3,
      "z": 4,
      "name": "Empty"
    },
    {
      "x": -13,
      "y": 4,
      "z": 4,
      "name": "Empty"
    },
    {
      "x": -13,
      "y": 5,
      "z": 4,
      "name": "Empty"
    },
    {
      "x": -13,
      "y": 6,
      "z": 4,
      "name": "Empty"
    },
    {
      "x": -13,
      "y": 7,
      "z": 4,
      "name": "Empty"
    },
    {
      "x": -13,
      "y": -1,
      "z": 5,
      "name": "Wood_Softwood_Planks_Half",
      "rotation": 8
    },
    {
      "x": -13,
      "y": 0,
      "z": 5,
      "name": "Wood_Softwood_Planks"
    },
    {
      "x": -13,
      "y": 1,
      "z": 5,
      "name": "Empty"
    },
    {
      "x": -13,
      "y": 2,
      "z": 5,
      "name": "Empty"
    },
    {
      "x": -13,
      "y": 3,
      "z": 5,
      "name": "Empty"
    },
    {
      "x": -13,
      "y": 4,
      "z": 5,
      "name": "Empty"
    },
    {
      "x": -13,
      "y": 5,
      "z": 5,
      "name": "Empty"
    },
    {
      "x": -13,
      "y": 6,
      "z": 5,
      "name": "Empty"
    },
    {
      "x": -13,
      "y": 7,
      "z": 5,
      "name": "Empty"
    },
    {
      "x": -13,
      "y": -1,
      "z": 6,
      "name": "Wood_Softwood_Planks_Half",
      "rotation": 8
    },
    {
      "x": -13,
      "y": 0,
      "z": 6,
      "name": "Wood_Deadwood_Planks"
    },
    {
      "x": -13,
      "y": 1,
      "z": 6,
      "name": "Empty"
    },
    {
      "x": -13,
      "y": 2,
      "z": 6,
      "name": "Empty"
    },
    {
      "x": -13,
      "y": 3,
      "z": 6,
      "name": "Empty"
    },
    {
      "x": -13,
      "y": 4,
      "z": 6,
      "name": "Empty"
    },
    {
      "x": -13,
      "y": 5,
      "z": 6,
      "name": "Empty"
    },
    {
      "x": -13,
      "y": 6,
      "z": 6,
      "name": "Empty"
    },
    {
      "x": -13,
      "y": 7,
      "z": 6,
      "name": "Empty"
    },
    {
      "x": -13,
      "y": 0,
      "z": 7,
      "name": "Wood_Softwood_Planks"
    },
    {
      "x": -13,
      "y": 1,
      "z": 7,
      "name": "Empty"
    },
    {
      "x": -13,
      "y": 2,
      "z": 7,
      "name": "Empty"
    },
    {
      "x": -13,
      "y": 3,
      "z": 7,
      "name": "Empty"
    },
    {
      "x": -13,
      "y": 4,
      "z": 7,
      "name": "Empty"
    },
    {
      "x": -13,
      "y": 5,
      "z": 7,
      "name": "Empty"
    },
    {
      "x": -13,
      "y": 6,
      "z": 7,
      "name": "Empty"
    },
    {
      "x": -13,
      "y": 7,
      "z": 7,
      "name": "Empty"
    },
    {
      "x": -13,
      "y": -3,
      "z": 8,
      "name": "Rock_Stone_Cobble"
    },
    {
      "x": -13,
      "y": -2,
      "z": 8,
      "name": "Rock_Stone_Cobble"
    },
    {
      "x": -13,
      "y": -1,
      "z": 8,
      "name": "Rock_Stone_Cobble"
    },
    {
      "x": -13,
      "y": 0,
      "z": 8,
      "name": "Rock_Stone_Cobble"
    },
    {
      "x": -13,
      "y": 1,
      "z": 8,
      "name": "Empty"
    },
    {
      "x": -13,
      "y": 2,
      "z": 8,
      "name": "Empty"
    },
    {
      "x": -13,
      "y": 3,
      "z": 8,
      "name": "Empty"
    },
    {
      "x": -13,
      "y": 4,
      "z": 8,
      "name": "Empty"
    },
    {
      "x": -13,
      "y": 5,
      "z": 8,
      "name": "Empty"
    },
    {
      "x": -13,
      "y": 6,
      "z": 8,
      "name": "Wood_Softwood_Planks"
    },
    {
      "x": -13,
      "y": 7,
      "z": 8,
      "name": "Wood_Deadwood_Roof_Flat"
    },
    {
      "x": -13,
      "y": -3,
      "z": 9,
      "name": "Rock_Stone_Cobble"
    },
    {
      "x": -13,
      "y": -2,
      "z": 9,
      "name": "Rock_Stone_Cobble"
    },
    {
      "x": -13,
      "y": -1,
      "z": 9,
      "name": "Rock_Stone_Cobble"
    },
    {
      "x": -13,
      "y": 0,
      "z": 9,
      "name": "Rock_Stone_Cobble"
    },
    {
      "x": -13,
      "y": 1,
      "z": 9,
      "name": "Empty"
    },
    {
      "x": -13,
      "y": 2,
      "z": 9,
      "name": "Rock_Stone_Cobble"
    },
    {
      "x": -13,
      "y": 3,
      "z": 9,
      "name": "Rock_Stone_Cobble"
    },
    {
      "x": -13,
      "y": 4,
      "z": 9,
      "name": "Rock_Stone_Cobble"
    },
    {
      "x": -13,
      "y": 5,
      "z": 9,
      "name": "Rock_Stone_Cobble"
    },
    {
      "x": -13,
      "y": 6,
      "z": 9,
      "name": "Rock_Stone_Cobble"
    },
    {
      "x": -13,
      "y": 7,
      "z": 9,
      "name": "Rock_Stone_Cobble"
    },
    {
      "x": -13,
      "y": 8,
      "z": 9,
      "name": "Rock_Stone_Cobble"
    },
    {
      "x": -13,
      "y": -3,
      "z": 10,
      "name": "Rock_Stone_Cobble"
    },
    {
      "x": -13,
      "y": -2,
      "z": 10,
      "name": "Rock_Stone_Cobble"
    },
    {
      "x": -13,
      "y": -1,
      "z": 10,
      "name": "Rock_Stone_Cobble"
    },
    {
      "x": -13,
      "y": 0,
      "z": 10,
      "name": "Rock_Stone_Cobble"
    },
    {
      "x": -13,
      "y": 1,
      "z": 10,
      "name": "Plant_Moss_Rug_Green"
    },
    {
      "x": -13,
      "y": 2,
      "z": 10,
      "name": "Rock_Stone_Cobble"
    },
    {
      "x": -13,
      "y": 3,
      "z": 10,
      "name": "Rock_Stone_Cobble"
    },
    {
      "x": -13,
      "y": 4,
      "z": 10,
      "name": "Rock_Stone_Cobble"
    },
    {
      "x": -13,
      "y": 5,
      "z": 10,
      "name": "Rock_Stone_Cobble"
    },
    {
      "x": -13,
      "y": 6,
      "z": 10,
      "name": "Rock_Stone_Cobble"
    },
    {
      "x": -13,
      "y": 7,
      "z": 10,
      "name": "Rock_Stone_Cobble"
    },
    {
      "x": -13,
      "y": 8,
      "z": 10,
      "name": "Rock_Stone_Cobble"
    },
    {
      "x": -13,
      "y": -3,
      "z": 11,
      "name": "Rock_Stone_Cobble"
    },
    {
      "x": -13,
      "y": -2,
      "z": 11,
      "name": "Rock_Stone_Cobble"
    },
    {
      "x": -13,
      "y": -1,
      "z": 11,
      "name": "Rock_Stone_Cobble"
    },
    {
      "x": -13,
      "y": 0,
      "z": 11,
      "name": "Rock_Stone_Cobble"
    },
    {
      "x": -13,
      "y": 1,
      "z": 11,
      "name": "Rock_Stone_Cobble"
    },
    {
      "x": -13,
      "y": 2,
      "z": 11,
      "name": "Rock_Stone_Cobble"
    },
    {
      "x": -13,
      "y": 3,
      "z": 11,
      "name": "Rock_Stone_Cobble"
    },
    {
      "x": -13,
      "y": 4,
      "z": 11,
      "name": "Rock_Stone_Cobble"
    },
    {
      "x": -13,
      "y": 5,
      "z": 11,
      "name": "Rock_Stone_Cobble"
    },
    {
      "x": -13,
      "y": 6,
      "z": 11,
      "name": "Rock_Stone_Cobble"
    },
    {
      "x": -13,
      "y": 7,
      "z": 11,
      "name": "Rock_Stone_Cobble"
    },
    {
      "x": -13,
      "y": 8,
      "z": 11,
      "name": "Rock_Stone_Cobble"
    },
    {
      "x": -13,
      "y": 9,
      "z": 11,
      "name": "Rock_Stone_Cobble"
    },
    {
      "x": -12,
      "y": 7,
      "z": -2,
      "name": "Wood_Deadwood_Roof_Hollow",
      "rotation": 3
    },
    {
      "x": -12,
      "y": 5,
      "z": -1,
      "name": "Wood_Softwood_Planks"
    },
    {
      "x": -12,
      "y": 6,
      "z": -1,
      "name": "Wood_Softwood_Planks"
    },
    {
      "x": -12,
      "y": 7,
      "z": -1,
      "name": "Wood_Deadwood_Roof",
      "rotation": 3
    },
    {
      "x": -12,
      "y": -1,
      "z": 0,
      "name": "Wood_Softwood_Fence"
    },
    {
      "x": -12,
      "y": 0,
      "z": 0,
      "name": "Wood_Oak_Trunk",
      "rotation": 5
    },
    {
      "x": -12,
      "y": 1,
      "z": 0,
      "name": "Wood_Softwood_Planks"
    },
    {
      "x": -12,
      "y": 2,
      "z": 0,
      "name": "Wood_Softwood_Planks"
    },
    {
      "x": -12,
      "y": 3,
      "z": 0,
      "name": "Wood_Softwood_Planks"
    },
    {
      "x": -12,
      "y": 4,
      "z": 0,
      "name": "Wood_Softwood_Planks"
    },
    {
      "x": -12,
      "y": 5,
      "z": 0,
      "name": "Wood_Softwood_Planks"
    },
    {
      "x": -12,
      "y": 6,
      "z": 0,
      "name": "Wood_Softwood_Planks"
    },
    {
      "x": -12,
      "y": 7,
      "z": 0,
      "name": "Wood_Deadwood_Roof",
      "rotation": 3
    },
    {
      "x": -12,
      "y": -1,
      "z": 1,
      "name": "Rock_Stone"
    },
    {
      "x": -12,
      "y": 0,
      "z": 1,
      "name": "Wood_Softwood_Planks"
    },
    {
      "x": -12,
      "y": 1,
      "z": 1,
      "name": "Wood_Softwood_Planks"
    },
    {
      "x": -12,
      "y": 2,
      "z": 1,
      "name": "Wood_Softwood_Planks"
    },
    {
      "x": -12,
      "y": 3,
      "z": 1,
      "name": "Empty"
    },
    {
      "x": -12,
      "y": 4,
      "z": 1,
      "name": "Empty"
    },
    {
      "x": -12,
      "y": 5,
      "z": 1,
      "name": "Empty"
    },
    {
      "x": -12,
      "y": 6,
      "z": 1,
      "name": "Wood_Softwood_Planks"
    },
    {
      "x": -12,
      "y": 7,
      "z": 1,
      "name": "Wood_Deadwood_Roof",
      "rotation": 3
    },
    {
      "x": -12,
      "y": -1,
      "z": 2,
      "name": "Soil_Grass"
    },
    {
      "x": -12,
      "y": 0,
      "z": 2,
      "name": "Plant_Moss_Rug_Green"
    },
    {
      "x": -12,
      "y": 1,
      "z": 2,
      "name": "Empty"
    },
    {
      "x": -12,
      "y": 2,
      "z": 2,
      "name": "Empty"
    },
    {
      "x": -12,
      "y": 3,
      "z": 2,
      "name": "Empty"
    },
    {
      "x": -12,
      "y": 4,
      "z": 2,
      "name": "Empty"
    },
    {
      "x": -12,
      "y": 5,
      "z": 2,
      "name": "Empty"
    },
    {
      "x": -12,
      "y": 6,
      "z": 2,
      "name": "Wood_Softwood_Planks"
    },
    {
      "x": -12,
      "y": 7,
      "z": 2,
      "name": "Wood_Deadwood_Roof",
      "rotation": 3
    },
    {
      "x": -12,
      "y": -1,
      "z": 3,
      "name": "Soil_Grass"
    },
    {
      "x": -12,
      "y": 0,
      "z": 3,
      "name": "Empty"
    },
    {
      "x": -12,
      "y": 1,
      "z": 3,
      "name": "Empty"
    },
    {
      "x": -12,
      "y": 2,
      "z": 3,
      "name": "Empty"
    },
    {
      "x": -12,
      "y": 3,
      "z": 3,
      "name": "Empty"
    },
    {
      "x": -12,
      "y": 4,
      "z": 3,
      "name": "Empty"
    },
    {
      "x": -12,
      "y": 5,
      "z": 3,
      "name": "Empty"
    },
    {
      "x": -12,
      "y": 6,
      "z": 3,
      "name": "Wood_Softwood_Planks"
    },
    {
      "x": -12,
      "y": 7,
      "z": 3,
      "name": "Wood_Deadwood_Roof",
      "rotation": 3
    },
    {
      "x": -12,
      "y": -1,
      "z": 4,
      "name": "Rock_Stone"
    },
    {
      "x": -12,
      "y": 0,
      "z": 4,
      "name": "Wood_Softwood_Planks"
    },
    {
      "x": -12,
      "y": 1,
      "z": 4,
      "name": "Empty"
    },
    {
      "x": -12,
      "y": 2,
      "z": 4,
      "name": "Empty"
    },
    {
      "x": -12,
      "y": 3,
      "z": 4,
      "name": "Empty"
    },
    {
      "x": -12,
      "y": 4,
      "z": 4,
      "name": "Empty"
    },
    {
      "x": -12,
      "y": 5,
      "z": 4,
      "name": "Empty"
    },
    {
      "x": -12,
      "y": 6,
      "z": 4,
      "name": "Wood_Softwood_Planks"
    },
    {
      "x": -12,
      "y": 7,
      "z": 4,
      "name": "Empty"
    },
    {
      "x": -12,
      "y": -1,
      "z": 5,
      "name": "Wood_Softwood_Planks_Half",
      "rotation": 8
    },
    {
      "x": -12,
      "y": 0,
      "z": 5,
      "name": "Wood_Softwood_Planks"
    },
    {
      "x": -12,
      "y": 1,
      "z": 5,
      "name": "Empty"
    },
    {
      "x": -12,
      "y": 2,
      "z": 5,
      "name": "Empty"
    },
    {
      "x": -12,
      "y": 3,
      "z": 5,
      "name": "Empty"
    },
    {
      "x": -12,
      "y": 4,
      "z": 5,
      "name": "Empty"
    },
    {
      "x": -12,
      "y": 5,
      "z": 5,
      "name": "Empty"
    },
    {
      "x": -12,
      "y": 6,
      "z": 5,
      "name": "Empty"
    },
    {
      "x": -12,
      "y": 7,
      "z": 5,
      "name": "Empty"
    },
    {
      "x": -12,
      "y": 1,
      "z": 6,
      "name": "Empty"
    },
    {
      "x": -12,
      "y": 2,
      "z": 6,
      "name": "Empty"
    },
    {
      "x": -12,
      "y": 3,
      "z": 6,
      "name": "Empty"
    },
    {
      "x": -12,
      "y": 4,
      "z": 6,
      "name": "Empty"
    },
    {
      "x": -12,
      "y": 5,
      "z": 6,
      "name": "Empty"
    },
    {
      "x": -12,
      "y": 6,
      "z": 6,
      "name": "Empty"
    },
    {
      "x": -12,
      "y": 7,
      "z": 6,
      "name": "Empty"
    },
    {
      "x": -12,
      "y": 1,
      "z": 7,
      "name": "Plant_Grass_Sharp"
    },
    {
      "x": -12,
      "y": 2,
      "z": 7,
      "name": "Empty"
    },
    {
      "x": -12,
      "y": 3,
      "z": 7,
      "name": "Empty"
    },
    {
      "x": -12,
      "y": 4,
      "z": 7,
      "name": "Empty"
    },
    {
      "x": -12,
      "y": 5,
      "z": 7,
      "name": "Empty"
    },
    {
      "x": -12,
      "y": 6,
      "z": 7,
      "name": "Empty"
    },
    {
      "x": -12,
      "y": 7,
      "z": 7,
      "name": "Empty"
    },
    {
      "x": -12,
      "y": -3,
      "z": 8,
      "name": "Rock_Stone_Cobble"
    },
    {
      "x": -12,
      "y": -2,
      "z": 8,
      "name": "Rock_Stone_Cobble"
    },
    {
      "x": -12,
      "y": -1,
      "z": 8,
      "name": "Rock_Stone_Cobble"
    },
    {
      "x": -12,
      "y": 1,
      "z": 8,
      "name": "Plant_Grass_Sharp"
    },
    {
      "x": -12,
      "y": 2,
      "z": 8,
      "name": "Empty"
    },
    {
      "x": -12,
      "y": 3,
      "z": 8,
      "name": "Empty"
    },
    {
      "x": -12,
      "y": 4,
      "z": 8,
      "name": "Empty"
    },
    {
      "x": -12,
      "y": 5,
      "z": 8,
      "name": "Empty"
    },
    {
      "x": -12,
      "y": 6,
      "z": 8,
      "name": "Empty"
    },
    {
      "x": -12,
      "y": 7,
      "z": 8,
      "name": "Empty"
    },
    {
      "x": -12,
      "y": -3,
      "z": 9,
      "name": "Rock_Stone_Cobble"
    },
    {
      "x": -12,
      "y": -2,
      "z": 9,
      "name": "Rock_Stone_Cobble"
    },
    {
      "x": -12,
      "y": -1,
      "z": 9,
      "name": "Rock_Stone_Cobble"
    },
    {
      "x": -12,
      "y": 0,
      "z": 9,
      "name": "Rock_Stone_Cobble"
    },
    {
      "x": -12,
      "y": 1,
      "z": 9,
      "name": "Rubble_Stone_Mossy"
    },
    {
      "x": -12,
      "y": 2,
      "z": 9,
      "name": "Empty"
    },
    {
      "x": -12,
      "y": 3,
      "z": 9,
      "name": "Empty"
    },
    {
      "x": -12,
      "y": 4,
      "z": 9,
      "name": "Empty"
    },
    {
      "x": -12,
      "y": 5,
      "z": 9,
      "name": "Rock_Stone_Cobble"
    },
    {
      "x": -12,
      "y": 6,
      "z": 9,
      "name": "Rock_Stone_Cobble"
    },
    {
      "x": -12,
      "y": 7,
      "z": 9,
      "name": "Empty"
    },
    {
      "x": -12,
      "y": -3,
      "z": 10,
      "name": "Rock_Stone_Cobble"
    },
    {
      "x": -12,
      "y": -2,
      "z": 10,
      "name": "Rock_Stone_Cobble"
    },
    {
      "x": -12,
      "y": -1,
      "z": 10,
      "name": "Rock_Stone_Cobble"
    },
    {
      "x": -12,
      "y": 0,
      "z": 10,
      "name": "Rock_Stone_Cobble"
    },
    {
      "x": -12,
      "y": 1,
      "z": 10,
      "name": "Plant_Moss_Rug_Green"
    },
    {
      "x": -12,
      "y": 2,
      "z": 10,
      "name": "Empty"
    },
    {
      "x": -12,
      "y": 3,
      "z": 10,
      "name": "Empty"
    },
    {
      "x": -12,
      "y": 4,
      "z": 10,
      "name": "Empty"
    },
    {
      "x": -12,
      "y": 5,
      "z": 10,
      "name": "Empty"
    },
    {
      "x": -12,
      "y": 6,
      "z": 10,
      "name": "Empty"
    },
    {
      "x": -12,
      "y": 7,
      "z": 10,
      "name": "Empty"
    },
    {
      "x": -12,
      "y": -3,
      "z": 11,
      "name": "Rock_Stone_Cobble"
    },
    {
      "x": -12,
      "y": -2,
      "z": 11,
      "name": "Rock_Stone_Cobble"
    },
    {
      "x": -12,
      "y": -1,
      "z": 11,
      "name": "Rock_Stone_Cobble"
    },
    {
      "x": -12,
      "y": 0,
      "z": 11,
      "name": "Rock_Stone_Cobble"
    },
    {
      "x": -12,
      "y": 1,
      "z": 11,
      "name": "Rock_Stone_Cobble"
    },
    {
      "x": -12,
      "y": 2,
      "z": 11,
      "name": "Rock_Stone_Cobble"
    },
    {
      "x": -12,
      "y": 3,
      "z": 11,
      "name": "Rock_Stone_Cobble"
    },
    {
      "x": -12,
      "y": 4,
      "z": 11,
      "name": "Rock_Stone_Cobble"
    },
    {
      "x": -12,
      "y": 5,
      "z": 11,
      "name": "Rock_Stone_Cobble"
    },
    {
      "x": -12,
      "y": 6,
      "z": 11,
      "name": "Rock_Stone_Cobble"
    },
    {
      "x": -12,
      "y": 7,
      "z": 11,
      "name": "Rock_Stone_Cobble"
    },
    {
      "x": -11,
      "y": 8,
      "z": -2,
      "name": "Wood_Deadwood_Roof_Hollow",
      "rotation": 3
    },
    {
      "x": -11,
      "y": 5,
      "z": -1,
      "name": "Wood_Softwood_Planks"
    },
    {
      "x": -11,
      "y": 6,
      "z": -1,
      "name": "Wood_Softwood_Planks"
    },
    {
      "x": -11,
      "y": 7,
      "z": -1,
      "name": "Wood_Softwood_Planks"
    },
    {
      "x": -11,
      "y": 8,
      "z": -1,
      "name": "Wood_Deadwood_Roof",
      "rotation": 3
    },
    {
      "x": -11,
      "y": -1,
      "z": 0,
      "name": "Wood_Softwood_Fence"
    },
    {
      "x": -11,
      "y": 0,
      "z": 0,
      "name": "Wood_Oak_Trunk",
      "rotation": 5
    },
    {
      "x": -11,
      "y": 1,
      "z": 0,
      "name": "Wood_Softwood_Planks"
    },
    {
      "x": -11,
      "y": 2,
      "z": 0,
      "name": "Wood_Softwood_Planks"
    },
    {
      "x": -11,
      "y": 3,
      "z": 0,
      "name": "Wood_Softwood_Planks"
    },
    {
      "x": -11,
      "y": 4,
      "z": 0,
      "name": "Wood_Softwood_Planks"
    },
    {
      "x": -11,
      "y": 5,
      "z": 0,
      "name": "Wood_Softwood_Planks"
    },
    {
      "x": -11,
      "y": 6,
      "z": 0,
      "name": "Wood_Softwood_Planks"
    },
    {
      "x": -11,
      "y": 7,
      "z": 0,
      "name": "Wood_Softwood_Planks"
    },
    {
      "x": -11,
      "y": 8,
      "z": 0,
      "name": "Wood_Deadwood_Roof",
      "rotation": 3
    },
    {
      "x": -11,
      "y": -1,
      "z": 1,
      "name": "Rock_Stone"
    },
    {
      "x": -11,
      "y": 0,
      "z": 1,
      "name": "Wood_Softwood_Planks"
    },
    {
      "x": -11,
      "y": 1,
      "z": 1,
      "name": "Wood_Softwood_Planks"
    },
    {
      "x": -11,
      "y": 2,
      "z": 1,
      "name": "Wood_Softwood_Planks"
    },
    {
      "x": -11,
      "y": 3,
      "z": 1,
      "name": "Empty"
    },
    {
      "x": -11,
      "y": 4,
      "z": 1,
      "name": "Empty"
    },
    {
      "x": -11,
      "y": 5,
      "z": 1,
      "name": "Empty"
    },
    {
      "x": -11,
      "y": 6,
      "z": 1,
      "name": "Wood_Softwood_Planks"
    },
    {
      "x": -11,
      "y": 7,
      "z": 1,
      "name": "Wood_Softwood_Planks"
    },
    {
      "x": -11,
      "y": 8,
      "z": 1,
      "name": "Wood_Deadwood_Roof",
      "rotation": 3
    },
    {
      "x": -11,
      "y": -1,
      "z": 2,
      "name": "Soil_Grass"
    },
    {
      "x": -11,
      "y": 0,
      "z": 2,
      "name": "Plant_Grass_Sharp"
    },
    {
      "x": -11,
      "y": 1,
      "z": 2,
      "name": "Empty"
    },
    {
      "x": -11,
      "y": 2,
      "z": 2,
      "name": "Empty"
    },
    {
      "x": -11,
      "y": 3,
      "z": 2,
      "name": "Empty"
    },
    {
      "x": -11,
      "y": 4,
      "z": 2,
      "name": "Empty"
    },
    {
      "x": -11,
      "y": 5,
      "z": 2,
      "name": "Empty"
    },
    {
      "x": -11,
      "y": 6,
      "z": 2,
      "name": "Wood_Softwood_Planks"
    },
    {
      "x": -11,
      "y": 7,
      "z": 2,
      "name": "Wood_Softwood_Planks"
    },
    {
      "x": -11,
      "y": 8,
      "z": 2,
      "name": "Wood_Deadwood_Roof",
      "rotation": 3
    },
    {
      "x": -11,
      "y": -1,
      "z": 3,
      "name": "Soil_Grass"
    },
    {
      "x": -11,
      "y": 0,
      "z": 3,
      "name": "Empty"
    },
    {
      "x": -11,
      "y": 1,
      "z": 3,
      "name": "Empty"
    },
    {
      "x": -11,
      "y": 2,
      "z": 3,
      "name": "Empty"
    },
    {
      "x": -11,
      "y": 3,
      "z": 3,
      "name": "Empty"
    },
    {
      "x": -11,
      "y": 4,
      "z": 3,
      "name": "Empty"
    },
    {
      "x": -11,
      "y": 5,
      "z": 3,
      "name": "Empty"
    },
    {
      "x": -11,
      "y": 6,
      "z": 3,
      "name": "Wood_Softwood_Planks"
    },
    {
      "x": -11,
      "y": 7,
      "z": 3,
      "name": "Wood_Softwood_Planks"
    },
    {
      "x": -11,
      "y": -1,
      "z": 4,
      "name": "Soil_Grass"
    },
    {
      "x": -11,
      "y": 0,
      "z": 4,
      "name": "Plant_Grass_Sharp"
    },
    {
      "x": -11,
      "y": 1,
      "z": 4,
      "name": "Empty"
    },
    {
      "x": -11,
      "y": 2,
      "z": 4,
      "name": "Empty"
    },
    {
      "x": -11,
      "y": 3,
      "z": 4,
      "name": "Empty"
    },
    {
      "x": -11,
      "y": 4,
      "z": 4,
      "name": "Empty"
    },
    {
      "x": -11,
      "y": 5,
      "z": 4,
      "name": "Empty"
    },
    {
      "x": -11,
      "y": 6,
      "z": 4,
      "name": "Wood_Softwood_Planks"
    },
    {
      "x": -11,
      "y": 7,
      "z": 4,
      "name": "Empty"
    },
    {
      "x": -11,
      "y": 1,
      "z": 5,
      "name": "Plant_Grass_Sharp"
    },
    {
      "x": -11,
      "y": 2,
      "z": 5,
      "name": "Empty"
    },
    {
      "x": -11,
      "y": 3,
      "z": 5,
      "name": "Empty"
    },
    {
      "x": -11,
      "y": 4,
      "z": 5,
      "name": "Empty"
    },
    {
      "x": -11,
      "y": 5,
      "z": 5,
      "name": "Empty"
    },
    {
      "x": -11,
      "y": 6,
      "z": 5,
      "name": "Empty"
    },
    {
      "x": -11,
      "y": 7,
      "z": 5,
      "name": "Empty"
    },
    {
      "x": -11,
      "y": 1,
      "z": 6,
      "name": "Rubble_Stone_Mossy"
    },
    {
      "x": -11,
      "y": 2,
      "z": 6,
      "name": "Empty"
    },
    {
      "x": -11,
      "y": 3,
      "z": 6,
      "name": "Empty"
    },
    {
      "x": -11,
      "y": 4,
      "z": 6,
      "name": "Empty"
    },
    {
      "x": -11,
      "y": 5,
      "z": 6,
      "name": "Empty"
    },
    {
      "x": -11,
      "y": 6,
      "z": 6,
      "name": "Empty"
    },
    {
      "x": -11,
      "y": 7,
      "z": 6,
      "name": "Empty"
    },
    {
      "x": -11,
      "y": 1,
      "z": 7,
      "name": "Plant_Grass_Sharp"
    },
    {
      "x": -11,
      "y": 2,
      "z": 7,
      "name": "Empty"
    },
    {
      "x": -11,
      "y": 3,
      "z": 7,
      "name": "Empty"
    },
    {
      "x": -11,
      "y": 4,
      "z": 7,
      "name": "Empty"
    },
    {
      "x": -11,
      "y": 5,
      "z": 7,
      "name": "Empty"
    },
    {
      "x": -11,
      "y": 6,
      "z": 7,
      "name": "Empty"
    },
    {
      "x": -11,
      "y": 7,
      "z": 7,
      "name": "Empty"
    },
    {
      "x": -11,
      "y": -3,
      "z": 8,
      "name": "Rock_Stone_Cobble"
    },
    {
      "x": -11,
      "y": -2,
      "z": 8,
      "name": "Rock_Stone_Cobble"
    },
    {
      "x": -11,
      "y": -1,
      "z": 8,
      "name": "Rock_Stone_Cobble"
    },
    {
      "x": -11,
      "y": 1,
      "z": 8,
      "name": "Plant_Moss_Rug_Green"
    },
    {
      "x": -11,
      "y": 2,
      "z": 8,
      "name": "Empty"
    },
    {
      "x": -11,
      "y": 3,
      "z": 8,
      "name": "Empty"
    },
    {
      "x": -11,
      "y": 4,
      "z": 8,
      "name": "Empty"
    },
    {
      "x": -11,
      "y": 5,
      "z": 8,
      "name": "Empty"
    },
    {
      "x": -11,
      "y": 6,
      "z": 8,
      "name": "Empty"
    },
    {
      "x": -11,
      "y": 7,
      "z": 8,
      "name": "Empty"
    },
    {
      "x": -11,
      "y": -3,
      "z": 9,
      "name": "Rock_Stone_Cobble"
    },
    {
      "x": -11,
      "y": -2,
      "z": 9,
      "name": "Rock_Stone_Cobble"
    },
    {
      "x": -11,
      "y": -1,
      "z": 9,
      "name": "Rock_Stone_Cobble"
    },
    {
      "x": -11,
      "y": 0,
      "z": 9,
      "name": "Rock_Stone_Cobble"
    },
    {
      "x": -11,
      "y": 1,
      "z": 9,
      "name": "Rubble_Stone_Mossy"
    },
    {
      "x": -11,
      "y": 2,
      "z": 9,
      "name": "Empty"
    },
    {
      "x": -11,
      "y": 3,
      "z": 9,
      "name": "Rock_Stone_Cobble"
    },
    {
      "x": -11,
      "y": 4,
      "z": 9,
      "name": "Rock_Stone_Cobble"
    },
    {
      "x": -11,
      "y": 5,
      "z": 9,
      "name": "Rock_Stone_Cobble"
    },
    {
      "x": -11,
      "y": 6,
      "z": 9,
      "name": "Rock_Stone_Cobble"
    },
    {
      "x": -11,
      "y": 7,
      "z": 9,
      "name": "Empty"
    },
    {
      "x": -11,
      "y": -3,
      "z": 10,
      "name": "Rock_Stone_Cobble"
    },
    {
      "x": -11,
      "y": -2,
      "z": 10,
      "name": "Rock_Stone_Cobble"
    },
    {
      "x": -11,
      "y": -1,
      "z": 10,
      "name": "Rock_Stone_Cobble"
    },
    {
      "x": -11,
      "y": 0,
      "z": 10,
      "name": "Rock_Stone_Cobble"
    },
    {
      "x": -11,
      "y": 1,
      "z": 10,
      "name": "Rubble_Stone_Mossy"
    },
    {
      "x": -11,
      "y": 2,
      "z": 10,
      "name": "Rock_Stone_Cobble"
    },
    {
      "x": -11,
      "y": 3,
      "z": 10,
      "name": "Rock_Stone_Cobble"
    },
    {
      "x": -11,
      "y": 4,
      "z": 10,
      "name": "Rock_Stone_Cobble"
    },
    {
      "x": -11,
      "y": 5,
      "z": 10,
      "name": "Rock_Stone_Cobble"
    },
    {
      "x": -11,
      "y": 6,
      "z": 10,
      "name": "Rock_Stone_Cobble"
    },
    {
      "x": -11,
      "y": 7,
      "z": 10,
      "name": "Empty"
    },
    {
      "x": -11,
      "y": -3,
      "z": 11,
      "name": "Rock_Stone_Cobble"
    },
    {
      "x": -11,
      "y": -2,
      "z": 11,
      "name": "Rock_Stone_Cobble"
    },
    {
      "x": -11,
      "y": -1,
      "z": 11,
      "name": "Rock_Stone_Cobble"
    },
    {
      "x": -11,
      "y": 0,
      "z": 11,
      "name": "Rock_Stone_Cobble"
    },
    {
      "x": -11,
      "y": 1,
      "z": 11,
      "name": "Rock_Stone_Cobble"
    },
    {
      "x": -11,
      "y": 2,
      "z": 11,
      "name": "Rock_Stone_Cobble"
    },
    {
      "x": -11,
      "y": 3,
      "z": 11,
      "name": "Rock_Stone_Cobble"
    },
    {
      "x": -11,
      "y": 4,
      "z": 11,
      "name": "Rock_Stone_Cobble"
    },
    {
      "x": -11,
      "y": 5,
      "z": 11,
      "name": "Rock_Stone_Cobble"
    },
    {
      "x": -11,
      "y": 6,
      "z": 11,
      "name": "Rock_Stone_Cobble"
    },
    {
      "x": -11,
      "y": 7,
      "z": 11,
      "name": "Rock_Stone_Cobble"
    },
    {
      "x": -10,
      "y": -3,
      "z": -2,
      "name": "Rock_Stone_Cobble"
    },
    {
      "x": -10,
      "y": -2,
      "z": -2,
      "name": "Rock_Stone_Cobble"
    },
    {
      "x": -10,
      "y": -1,
      "z": -2,
      "name": "Rock_Stone_Cobble"
    },
    {
      "x": -10,
      "y": 0,
      "z": -2,
      "name": "Rock_Stone_Cobble"
    },
    {
      "x": -10,
      "y": 1,
      "z": -2,
      "name": "Rock_Stone_Cobble"
    },
    {
      "x": -10,
      "y": 2,
      "z": -2,
      "name": "Rock_Stone_Cobble"
    },
    {
      "x": -10,
      "y": 3,
      "z": -2,
      "name": "Wood_Softwood_Planks"
    },
    {
      "x": -10,
      "y": 4,
      "z": -2,
      "name": "Wood_Softwood_Planks"
    },
    {
      "x": -10,
      "y": 5,
      "z": -2,
      "name": "Wood_Softwood_Planks"
    },
    {
      "x": -10,
      "y": 6,
      "z": -2,
      "name": "Wood_Softwood_Planks"
    },
    {
      "x": -10,
      "y": 7,
      "z": -2,
      "name": "Wood_Softwood_Planks"
    },
    {
      "x": -10,
      "y": 8,
      "z": -2,
      "name": "Wood_Softwood_Planks"
    },
    {
      "x": -10,
      "y": -4,
      "z": -1,
      "name": "Rock_Stone_Cobble"
    },
    {
      "x": -10,
      "y": -3,
      "z": -1,
      "name": "Rock_Stone_Cobble"
    },
    {
      "x": -10,
      "y": -2,
      "z": -1,
      "name": "Rock_Stone_Cobble"
    },
    {
      "x": -10,
      "y": -1,
      "z": -1,
      "name": "Rock_Stone_Cobble"
    },
    {
      "x": -10,
      "y": 0,
      "z": -1,
      "name": "Rock_Stone_Cobble"
    },
    {
      "x": -10,
      "y": 1,
      "z": -1,
      "name": "Rock_Stone_Cobble"
    },
    {
      "x": -10,
      "y": 2,
      "z": -1,
      "name": "Wood_Softwood_Planks"
    },
    {
      "x": -10,
      "y": 3,
      "z": -1,
      "name": "Wood_Softwood_Planks"
    },
    {
      "x": -10,
      "y": 4,
      "z": -1,
      "name": "Wood_Softwood_Planks"
    },
    {
      "x": -10,
      "y": 5,
      "z": -1,
      "name": "Wood_Softwood_Planks"
    },
    {
      "x": -10,
      "y": 6,
      "z": -1,
      "name": "Wood_Softwood_Planks"
    },
    {
      "x": -10,
      "y": 7,
      "z": -1,
      "name": "Wood_Softwood_Planks"
    },
    {
      "x": -10,
      "y": 8,
      "z": -1,
      "name": "Wood_Softwood_Planks"
    },
    {
      "x": -10,
      "y": -4,
      "z": 0,
      "name": "Rock_Stone_Cobble"
    },
    {
      "x": -10,
      "y": -3,
      "z": 0,
      "name": "Rock_Stone_Cobble"
    },
    {
      "x": -10,
      "y": -2,
      "z": 0,
      "name": "Rock_Stone_Cobble"
    },
    {
      "x": -10,
      "y": -1,
      "z": 0,
      "name": "Rock_Stone_Cobble"
    },
    {
      "x": -10,
      "y": 0,
      "z": 0,
      "name": "Wood_Oak_Trunk",
      "rotation": 5
    },
    {
      "x": -10,
      "y": 1,
      "z": 0,
      "name": "Rock_Stone_Cobble"
    },
    {
      "x": -10,
      "y": 2,
      "z": 0,
      "name": "Wood_Softwood_Planks"
    },
    {
      "x": -10,
      "y": 3,
      "z": 0,
      "name": "Wood_Softwood_Planks"
    },
    {
      "x": -10,
      "y": 4,
      "z": 0,
      "name": "Wood_Softwood_Planks"
    },
    {
      "x": -10,
      "y": 5,
      "z": 0,
      "name": "Wood_Softwood_Planks"
    },
    {
      "x": -10,
      "y": 6,
      "z": 0,
      "name": "Wood_Softwood_Planks"
    },
    {
      "x": -10,
      "y": 7,
      "z": 0,
      "name": "Wood_Softwood_Planks"
    },
    {
      "x": -10,
      "y": 8,
      "z": 0,
      "name": "Wood_Softwood_Planks"
    },
    {
      "x": -10,
      "y": -3,
      "z": 1,
      "name": "Rock_Stone_Cobble"
    },
    {
      "x": -10,
      "y": -2,
      "z": 1,
      "name": "Rock_Stone_Cobble"
    },
    {
      "x": -10,
      "y": -1,
      "z": 1,
      "name": "Rock_Stone"
    },
    {
      "x": -10,
      "y": 0,
      "z": 1,
      "name": "Wood_Softwood_Planks"
    },
    {
      "x": -10,
      "y": 1,
      "z": 1,
      "name": "Wood_Softwood_Planks"
    },
    {
      "x": -10,
      "y": 2,
      "z": 1,
      "name": "Wood_Softwood_Planks"
    },
    {
      "x": -10,
      "y": 3,
      "z": 1,
      "name": "Wood_Softwood_Planks"
    },
    {
      "x": -10,
      "y": 4,
      "z": 1,
      "name": "Empty"
    },
    {
      "x": -10,
      "y": 5,
      "z": 1,
      "name": "Empty"
    },
    {
      "x": -10,
      "y": 6,
      "z": 1,
      "name": "Wood_Softwood_Planks"
    },
    {
      "x": -10,
      "y": 7,
      "z": 1,
      "name": "Wood_Softwood_Planks"
    },
    {
      "x": -10,
      "y": 8,
      "z": 1,
      "name": "Wood_Softwood_Planks"
    },
    {
      "x": -10,
      "y": -1,
      "z": 2,
      "name": "Soil_Grass"
    },
    {
      "x": -10,
      "y": 0,
      "z": 2,
      "name": "Rubble_Stone_Mossy"
    },
    {
      "x": -10,
      "y": 1,
      "z": 2,
      "name": "Empty"
    },
    {
      "x": -10,
      "y": 2,
      "z": 2,
      "name": "Empty"
    },
    {
      "x": -10,
      "y": 3,
      "z": 2,
      "name": "Empty"
    },
    {
      "x": -10,
      "y": 4,
      "z": 2,
      "name": "Empty"
    },
    {
      "x": -10,
      "y": 5,
      "z": 2,
      "name": "Empty"
    },
    {
      "x": -10,
      "y": 6,
      "z": 2,
      "name": "Wood_Softwood_Planks"
    },
    {
      "x": -10,
      "y": 7,
      "z": 2,
      "name": "Wood_Softwood_Planks"
    },
    {
