{
  "version": 8,
  "blockIdVersion": 9,
  "anchorX": 2,
  "anchorY": 18,
  "anchorZ": 2,
  "blocks": [
    {
      "x": -34,
      "y": 39,
      "z": 2,
      "name": "Rock_Volcanic_Cracked_Lava"
    },
    {
      "x": -34,
      "y": 40,
      "z": 2,
      "name": "Rock_Volcanic"
    },
    {
      "x": -34,
      "y": 41,
      "z": 2,
      "name": "Rock_Volcanic"
    },
    {
      "x": -34,
      "y": 42,
      "z": 2,
      "name": "Rock_Volcanic"
    },
    {
      "x": -34,
      "y": 43,
      "z": 2,
      "name": "Rock_Volcanic"
    },
    {
      "x": -33,
      "y": 37,
      "z": 1,
      "name": "Rock_Volcanic"
    },
    {
      "x": -33,
      "y": 38,
      "z": 1,
      "name": "Rock_Volcanic"
    },
    {
      "x": -33,
      "y": 39,
      "z": 1,
      "name": "Rock_Volcanic"
    },
    {
      "x": -33,
      "y": 40,
      "z": 1,
      "name": "Rock_Volcanic"
    },
    {
      "x": -33,
      "y": 41,
      "z": 1,
      "name": "Rock_Volcanic"
    },
    {
      "x": -33,
      "y": 34,
      "z": 2,
      "name": "Rock_Volcanic"
    },
    {
      "x": -33,
      "y": 35,
      "z": 2,
      "name": "Rock_Volcanic"
    },
    {
      "x": -33,
      "y": 36,
      "z": 2,
      "name": "Rock_Volcanic"
    },
    {
      "x": -33,
      "y": 37,
      "z": 2,
      "name": "Rock_Volcanic"
    },
    {
      "x": -33,
      "y": 38,
      "z": 2,
      "name": "Rock_Volcanic"
    },
    {
      "x": -33,
      "y": 39,
      "z": 2,
      "name": "Rock_Volcanic"
    },
    {
      "x": -33,
      "y": 40,
      "z": 2,
      "name": "Rock_Volcanic"
    },
    {
      "x": -33,
      "y": 41,
      "z": 2,
      "name": "Rock_Volcanic"
    },
    {
      "x": -33,
      "y": 42,
      "z": 2,
      "name": "Rock_Volcanic"
    },
    {
      "x": -33,
      "y": 36,
      "z": 3,
      "name": "Rock_Volcanic"
    },
    {
      "x": -33,
      "y": 37,
      "z": 3,
      "name": "Rock_Volcanic"
    },
    {
      "x": -33,
      "y": 38,
      "z": 3,
      "name": "Rock_Volcanic"
    },
    {
      "x": -33,
      "y": 39,
      "z": 3,
      "name": "Rock_Volcanic"
    },
    {
      "x": -33,
      "y": 40,
      "z": 3,
      "name": "Rock_Volcanic"
    },
    {
      "x": -33,
      "y": 41,
      "z": 3,
      "name": "Rock_Volcanic"
    },
    {
      "x": -33,
      "y": 38,
      "z": 4,
      "name": "Rock_Volcanic_Cracked_Lava"
    },
    {
      "x": -33,
      "y": 39,
      "z": 4,
      "name": "Rock_Volcanic_Cracked_Lava"
    },
    {
      "x": -33,
      "y": 40,
      "z": 4,
      "name": "Rock_Volcanic_Cracked_Lava"
    },
    {
      "x": -32,
      "y": 32,
      "z": 1,
      "name": "Rock_Volcanic"
    },
    {
      "x": -32,
      "y": 33,
      "z": 1,
      "name": "Rock_Volcanic"
    },
    {
      "x": -32,
      "y": 34,
      "z": 1,
      "name": "Rock_Volcanic"
    },
    {
      "x": -32,
      "y": 35,
      "z": 1,
      "name": "Rock_Volcanic"
    },
    {
      "x": -32,
      "y": 36,
      "z": 1,
      "name": "Rock_Volcanic"
    },
    {
      "x": -32,
      "y": 37,
      "z": 1,
      "name": "Rock_Volcanic"
    },
    {
      "x": -32,
      "y": 38,
      "z": 1,
      "name": "Rock_Volcanic"
    },
    {
      "x": -32,
      "y": 39,
      "z": 1,
      "name": "Rock_Volcanic"
    },
    {
      "x": -32,
      "y": 40,
      "z": 1,
      "name": "Rock_Volcanic"
    },
    {
      "x": -32,
      "y": 27,
      "z": 2,
      "name": "Rock_Volcanic"
    },
    {
      "x": -32,
      "y": 28,
      "z": 2,
      "name": "Rock_Volcanic"
    },
    {
      "x": -32,
      "y": 29,
      "z": 2,
      "name": "Rock_Volcanic"
    },
    {
      "x": -32,
      "y": 30,
      "z": 2,
      "name": "Rock_Volcanic"
    },
    {
      "x": -32,
      "y": 31,
      "z": 2,
      "name": "Rock_Volcanic"
    },
    {
      "x": -32,
      "y": 32,
      "z": 2,
      "name": "Rock_Volcanic"
    },
    {
      "x": -32,
      "y": 33,
      "z": 2,
      "name": "Rock_Volcanic"
    },
    {
      "x": -32,
      "y": 34,
      "z": 2,
      "name": "Rock_Volcanic"
    },
    {
      "x": -32,
      "y": 35,
      "z": 2,
      "name": "Rock_Volcanic"
    },
    {
      "x": -32,
      "y": 36,
      "z": 2,
      "name": "Rock_Volcanic"
    },
    {
      "x": -32,
      "y": 37,
      "z": 2,
      "name": "Rock_Volcanic"
    },
    {
      "x": -32,
      "y": 38,
      "z": 2,
      "name": "Rock_Volcanic"
    },
    {
      "x": -32,
      "y": 39,
      "z": 2,
      "name": "Rock_Volcanic"
    },
    {
      "x": -32,
      "y": 40,
      "z": 2,
      "name": "Rock_Volcanic"
    },
    {
      "x": -32,
      "y": 41,
      "z": 2,
      "name": "Rock_Volcanic"
    },
    {
      "x": -32,
      "y": 31,
      "z": 3,
      "name": "Rock_Volcanic"
    },
    {
      "x": -32,
      "y": 32,
      "z": 3,
      "name": "Rock_Volcanic"
    },
    {
      "x": -32,
      "y": 33,
      "z": 3,
      "name": "Rock_Volcanic"
    },
    {
      "x": -32,
      "y": 34,
      "z": 3,
      "name": "Rock_Volcanic"
    },
    {
      "x": -32,
      "y": 35,
      "z": 3,
      "name": "Rock_Volcanic"
    },
    {
      "x": -32,
      "y": 36,
      "z": 3,
      "name": "Rock_Volcanic"
    },
    {
      "x": -32,
      "y": 37,
      "z": 3,
      "name": "Rock_Volcanic"
    },
    {
      "x": -32,
      "y": 38,
      "z": 3,
      "name": "Rock_Volcanic"
    },
    {
      "x": -32,
      "y": 39,
      "z": 3,
      "name": "Rock_Volcanic"
    },
    {
      "x": -32,
      "y": 40,
      "z": 3,
      "name": "Rock_Volcanic"
    },
    {
      "x": -32,
      "y": 41,
      "z": 3,
      "name": "Rock_Volcanic"
    },
    {
      "x": -32,
      "y": 34,
      "z": 4,
      "name": "Rock_Volcanic"
    },
    {
      "x": -32,
      "y": 35,
      "z": 4,
      "name": "Rock_Volcanic"
    },
    {
      "x": -32,
      "y": 36,
      "z": 4,
      "name": "Rock_Volcanic"
    },
    {
      "x": -32,
      "y": 37,
      "z": 4,
      "name": "Rock_Volcanic_Cracked_Lava"
    },
    {
      "x": -32,
      "y": 38,
      "z": 4,
      "name": "Rock_Volcanic_Cracked_Lava"
    },
    {
      "x": -32,
      "y": 39,
      "z": 4,
      "name": "Rock_Volcanic_Cracked_Lava"
    },
    {
      "x": -31,
      "y": 30,
      "z": 0,
      "name": "Rock_Volcanic"
    },
    {
      "x": -31,
      "y": 31,
      "z": 0,
      "name": "Rock_Volcanic"
    },
    {
      "x": -31,
      "y": 32,
      "z": 0,
      "name": "Rock_Volcanic"
    },
    {
      "x": -31,
      "y": 33,
      "z": 0,
      "name": "Rock_Volcanic"
    },
    {
      "x": -31,
      "y": 34,
      "z": 0,
      "name": "Rock_Volcanic"
    },
    {
      "x": -31,
      "y": 35,
      "z": 0,
      "name": "Rock_Volcanic"
    },
    {
      "x": -31,
      "y": 36,
      "z": 0,
      "name": "Rock_Volcanic"
    },
    {
      "x": -31,
      "y": 25,
      "z": 1,
      "name": "Rock_Volcanic"
    },
    {
      "x": -31,
      "y": 26,
      "z": 1,
      "name": "Rock_Volcanic"
    },
    {
      "x": -31,
      "y": 27,
      "z": 1,
      "name": "Rock_Volcanic"
    },
    {
      "x": -31,
      "y": 28,
      "z": 1,
      "name": "Rock_Volcanic"
    },
    {
      "x": -31,
      "y": 29,
      "z": 1,
      "name": "Rock_Volcanic"
    },
    {
      "x": -31,
      "y": 30,
      "z": 1,
      "name": "Rock_Volcanic"
    },
    {
      "x": -31,
      "y": 31,
      "z": 1,
      "name": "Rock_Volcanic"
    },
    {
      "x": -31,
      "y": 32,
      "z": 1,
      "name": "Rock_Volcanic"
    },
    {
      "x": -31,
      "y": 33,
      "z": 1,
      "name": "Rock_Volcanic"
    },
    {
      "x": -31,
      "y": 34,
      "z": 1,
      "name": "Rock_Volcanic"
    },
    {
      "x": -31,
      "y": 35,
      "z": 1,
      "name": "Rock_Volcanic"
    },
    {
      "x": -31,
      "y": 36,
      "z": 1,
      "name": "Rock_Volcanic"
    },
    {
      "x": -31,
      "y": 37,
      "z": 1,
      "name": "Rock_Volcanic"
    },
    {
      "x": -31,
      "y": 38,
      "z": 1,
      "name": "Rock_Volcanic"
    },
    {
      "x": -31,
      "y": 39,
      "z": 1,
      "name": "Rock_Volcanic"
    },
    {
      "x": -31,
      "y": 40,
      "z": 1,
      "name": "Rock_Volcanic"
    },
    {
      "x": -31,
      "y": 20,
      "z": 2,
      "name": "Rock_Volcanic"
    },
    {
      "x": -31,
      "y": 21,
      "z": 2,
      "name": "Rock_Volcanic"
    },
    {
      "x": -31,
      "y": 22,
      "z": 2,
      "name": "Rock_Volcanic"
    },
    {
      "x": -31,
      "y": 23,
      "z": 2,
      "name": "Rock_Volcanic"
    },
    {
      "x": -31,
      "y": 24,
      "z": 2,
      "name": "Rock_Volcanic"
    },
    {
      "x": -31,
      "y": 25,
      "z": 2,
      "name": "Rock_Volcanic"
    },
    {
      "x": -31,
      "y": 26,
      "z": 2,
      "name": "Rock_Volcanic"
    },
    {
      "x": -31,
      "y": 27,
      "z": 2,
      "name": "Rock_Volcanic"
    },
    {
      "x": -31,
      "y": 28,
      "z": 2,
      "name": "Rock_Volcanic"
    },
    {
      "x": -31,
      "y": 29,
      "z": 2,
      "name": "Rock_Volcanic"
    },
    {
      "x": -31,
      "y": 30,
      "z": 2,
      "name": "Rock_Volcanic"
    },
    {
      "x": -31,
      "y": 31,
      "z": 2,
      "name": "Rock_Volcanic"
    },
    {
      "x": -31,
      "y": 32,
      "z": 2,
      "name": "Rock_Volcanic"
    },
    {
      "x": -31,
      "y": 33,
      "z": 2,
      "name": "Rock_Volcanic"
    },
    {
      "x": -31,
      "y": 34,
      "z": 2,
      "name": "Rock_Volcanic"
    },
    {
      "x": -31,
      "y": 35,
      "z": 2,
      "name": "Rock_Volcanic"
    },
    {
      "x": -31,
      "y": 36,
      "z": 2,
      "name": "Rock_Volcanic"
    },
    {
      "x": -31,
      "y": 37,
      "z": 2,
      "name": "Rock_Volcanic"
    },
    {
      "x": -31,
      "y": 38,
      "z": 2,
      "name": "Rock_Volcanic"
    },
    {
      "x": -31,
      "y": 39,
      "z": 2,
      "name": "Rock_Volcanic"
    },
    {
      "x": -31,
      "y": 40,
      "z": 2,
      "name": "Rock_Volcanic"
    },
    {
      "x": -31,
      "y": 22,
      "z": 3,
      "name": "Rock_Volcanic"
    },
    {
      "x": -31,
      "y": 23,
      "z": 3,
      "name": "Rock_Volcanic"
    },
    {
      "x": -31,
      "y": 24,
      "z": 3,
      "name": "Rock_Volcanic"
    },
    {
      "x": -31,
      "y": 25,
      "z": 3,
      "name": "Rock_Volcanic"
    },
    {
      "x": -31,
      "y": 26,
      "z": 3,
      "name": "Rock_Volcanic"
    },
    {
      "x": -31,
      "y": 27,
      "z": 3,
      "name": "Rock_Volcanic"
    },
    {
      "x": -31,
      "y": 28,
      "z": 3,
      "name": "Rock_Volcanic"
    },
    {
      "x": -31,
      "y": 29,
      "z": 3,
      "name": "Rock_Volcanic"
    },
    {
      "x": -31,
      "y": 30,
      "z": 3,
      "name": "Rock_Volcanic"
    },
    {
      "x": -31,
      "y": 31,
      "z": 3,
      "name": "Rock_Volcanic"
    },
    {
      "x": -31,
      "y": 32,
      "z": 3,
      "name": "Rock_Volcanic"
    },
    {
      "x": -31,
      "y": 33,
      "z": 3,
      "name": "Rock_Volcanic"
    },
    {
      "x": -31,
      "y": 34,
      "z": 3,
      "name": "Rock_Volcanic"
    },
    {
      "x": -31,
      "y": 35,
      "z": 3,
      "name": "Rock_Volcanic"
    },
    {
      "x": -31,
      "y": 36,
      "z": 3,
      "name": "Rock_Volcanic"
    },
    {
      "x": -31,
      "y": 37,
      "z": 3,
      "name": "Rock_Volcanic"
    },
    {
      "x": -31,
      "y": 38,
      "z": 3,
      "name": "Rock_Volcanic_Cracked_Lava"
    },
    {
      "x": -31,
      "y": 39,
      "z": 3,
      "name": "Rock_Volcanic"
    },
    {
      "x": -31,
      "y": 40,
      "z": 3,
      "name": "Rock_Volcanic"
    },
    {
      "x": -31,
      "y": 25,
      "z": 4,
      "name": "Rock_Volcanic"
    },
    {
      "x": -31,
      "y": 26,
      "z": 4,
      "name": "Rock_Volcanic"
    },
    {
      "x": -31,
      "y": 27,
      "z": 4,
      "name": "Rock_Volcanic"
    },
    {
      "x": -31,
      "y": 28,
      "z": 4,
      "name": "Rock_Volcanic"
    },
    {
      "x": -31,
      "y": 29,
      "z": 4,
      "name": "Rock_Volcanic"
    },
    {
      "x": -31,
      "y": 30,
      "z": 4,
      "name": "Rock_Volcanic"
    },
    {
      "x": -31,
      "y": 31,
      "z": 4,
      "name": "Rock_Volcanic"
    },
    {
      "x": -31,
      "y": 32,
      "z": 4,
      "name": "Rock_Volcanic"
    },
    {
      "x": -31,
      "y": 33,
      "z": 4,
      "name": "Rock_Volcanic"
    },
    {
      "x": -31,
      "y": 34,
      "z": 4,
      "name": "Rock_Volcanic"
    },
    {
      "x": -31,
      "y": 35,
      "z": 4,
      "name": "Rock_Volcanic"
    },
    {
      "x": -31,
      "y": 36,
      "z": 4,
      "name": "Rock_Volcanic"
    },
    {
      "x": -31,
      "y": 37,
      "z": 4,
      "name": "Rock_Volcanic"
    },
    {
      "x": -31,
      "y": 38,
      "z": 4,
      "name": "Rock_Volcanic_Cracked_Lava"
    },
    {
      "x": -31,
      "y": 39,
      "z": 4,
      "name": "Rock_Volcanic_Cracked_Lava"
    },
    {
      "x": -31,
      "y": 29,
      "z": 5,
      "name": "Rock_Volcanic"
    },
    {
      "x": -31,
      "y": 30,
      "z": 5,
      "name": "Rock_Volcanic"
    },
    {
      "x": -31,
      "y": 31,
      "z": 5,
      "name": "Rock_Volcanic"
    },
    {
      "x": -31,
      "y": 32,
      "z": 5,
      "name": "Rock_Volcanic"
    },
    {
      "x": -31,
      "y": 33,
      "z": 5,
      "name": "Rock_Volcanic"
    },
    {
      "x": -31,
      "y": 34,
      "z": 5,
      "name": "Rock_Volcanic"
    },
    {
      "x": -31,
      "y": 35,
      "z": 5,
      "name": "Rock_Volcanic"
    },
    {
      "x": -31,
      "y": 36,
      "z": 5,
      "name": "Rock_Volcanic_Cracked_Lava"
    },
    {
      "x": -31,
      "y": 37,
      "z": 5,
      "name": "Rock_Volcanic_Cracked_Lava"
    },
    {
      "x": -31,
      "y": 38,
      "z": 5,
      "name": "Rock_Volcanic_Cracked_Lava"
    },
    {
      "x": -30,
      "y": 23,
      "z": 0,
      "name": "Rock_Volcanic"
    },
    {
      "x": -30,
      "y": 24,
      "z": 0,
      "name": "Rock_Volcanic"
    },
    {
      "x": -30,
      "y": 25,
      "z": 0,
      "name": "Rock_Volcanic"
    },
    {
      "x": -30,
      "y": 26,
      "z": 0,
      "name": "Rock_Volcanic"
    },
    {
      "x": -30,
      "y": 27,
      "z": 0,
      "name": "Rock_Volcanic"
    },
    {
      "x": -30,
      "y": 28,
      "z": 0,
      "name": "Rock_Volcanic"
    },
    {
      "x": -30,
      "y": 29,
      "z": 0,
      "name": "Rock_Volcanic"
    },
    {
      "x": -30,
      "y": 30,
      "z": 0,
      "name": "Rock_Volcanic"
    },
    {
      "x": -30,
      "y": 31,
      "z": 0,
      "name": "Rock_Volcanic"
    },
    {
      "x": -30,
      "y": 32,
      "z": 0,
      "name": "Rock_Volcanic"
    },
    {
      "x": -30,
      "y": 33,
      "z": 0,
      "name": "Rock_Volcanic"
    },
    {
      "x": -30,
      "y": 34,
      "z": 0,
      "name": "Rock_Volcanic"
    },
    {
      "x": -30,
      "y": 35,
      "z": 0,
      "name": "Rock_Volcanic"
    },
    {
      "x": -30,
      "y": 36,
      "z": 0,
      "name": "Rock_Volcanic"
    },
    {
      "x": -30,
      "y": 37,
      "z": 0,
      "name": "Rock_Volcanic_Cracked_Lava"
    },
    {
      "x": -30,
      "y": 21,
      "z": 1,
      "name": "Rock_Volcanic"
    },
    {
      "x": -30,
      "y": 22,
      "z": 1,
      "name": "Rock_Volcanic"
    },
    {
      "x": -30,
      "y": 23,
      "z": 1,
      "name": "Rock_Volcanic"
    },
    {
      "x": -30,
      "y": 24,
      "z": 1,
      "name": "Rock_Volcanic"
    },
    {
      "x": -30,
      "y": 25,
      "z": 1,
      "name": "Rock_Volcanic"
    },
    {
      "x": -30,
      "y": 26,
      "z": 1,
      "name": "Rock_Volcanic"
    },
    {
      "x": -30,
      "y": 27,
      "z": 1,
      "name": "Rock_Volcanic"
    },
    {
      "x": -30,
      "y": 28,
      "z": 1,
      "name": "Rock_Volcanic"
    },
    {
      "x": -30,
      "y": 29,
      "z": 1,
      "name": "Rock_Volcanic"
    },
    {
      "x": -30,
      "y": 30,
      "z": 1,
      "name": "Rock_Volcanic"
    },
    {
      "x": -30,
      "y": 31,
      "z": 1,
      "name": "Rock_Volcanic"
    },
    {
      "x": -30,
      "y": 32,
      "z": 1,
      "name": "Rock_Volcanic"
    },
    {
      "x": -30,
      "y": 33,
      "z": 1,
      "name": "Rock_Volcanic"
    },
    {
      "x": -30,
      "y": 34,
      "z": 1,
      "name": "Rock_Volcanic"
    },
    {
      "x": -30,
      "y": 35,
      "z": 1,
      "name": "Rock_Volcanic"
    },
    {
      "x": -30,
      "y": 36,
      "z": 1,
      "name": "Rock_Volcanic"
    },
    {
      "x": -30,
      "y": 37,
      "z": 1,
      "name": "Rock_Volcanic"
    },
    {
      "x": -30,
      "y": 38,
      "z": 1,
      "name": "Rock_Volcanic"
    },
    {
      "x": -30,
      "y": 39,
      "z": 1,
      "name": "Rock_Volcanic"
    },
    {
      "x": -30,
      "y": 14,
      "z": 2,
      "name": "Rock_Volcanic"
    },
    {
      "x": -30,
      "y": 15,
      "z": 2,
      "name": "Rock_Volcanic"
    },
    {
      "x": -30,
      "y": 16,
      "z": 2,
      "name": "Rock_Volcanic"
    },
    {
      "x": -30,
      "y": 17,
      "z": 2,
      "name": "Rock_Volcanic"
    },
    {
      "x": -30,
      "y": 18,
      "z": 2,
      "name": "Rock_Volcanic"
    },
    {
      "x": -30,
      "y": 19,
      "z": 2,
      "name": "Rock_Volcanic"
    },
    {
      "x": -30,
      "y": 20,
      "z": 2,
      "name": "Rock_Volcanic"
    },
    {
      "x": -30,
      "y": 21,
      "z": 2,
      "name": "Rock_Volcanic"
    },
    {
      "x": -30,
      "y": 22,
      "z": 2,
      "name": "Rock_Volcanic"
    },
    {
      "x": -30,
      "y": 23,
      "z": 2,
      "name": "Rock_Volcanic"
    },
    {
      "x": -30,
      "y": 24,
      "z": 2,
      "name": "Rock_Volcanic"
    },
    {
      "x": -30,
      "y": 25,
      "z": 2,
      "name": "Rock_Volcanic"
    },
    {
      "x": -30,
      "y": 26,
      "z": 2,
      "name": "Rock_Volcanic"
    },
    {
      "x": -30,
      "y": 27,
      "z": 2,
      "name": "Rock_Volcanic"
    },
    {
      "x": -30,
      "y": 28,
      "z": 2,
      "name": "Rock_Volcanic"
    },
    {
      "x": -30,
      "y": 29,
      "z": 2,
      "name": "Rock_Volcanic"
    },
    {
      "x": -30,
      "y": 30,
      "z": 2,
      "name": "Rock_Volcanic"
    },
    {
      "x": -30,
      "y": 31,
      "z": 2,
      "name": "Rock_Volcanic"
    },
    {
      "x": -30,
      "y": 32,
      "z": 2,
      "name": "Rock_Volcanic"
    },
    {
      "x": -30,
      "y": 33,
      "z": 2,
      "name": "Rock_Volcanic"
    },
    {
      "x": -30,
      "y": 34,
      "z": 2,
      "name": "Rock_Volcanic"
    },
    {
      "x": -30,
      "y": 35,
      "z": 2,
      "name": "Rock_Volcanic_Cracked_Lava"
    },
    {
      "x": -30,
      "y": 36,
      "z": 2,
      "name": "Rock_Volcanic_Cracked_Lava"
    },
    {
      "x": -30,
      "y": 37,
      "z": 2,
      "name": "Rock_Volcanic_Cracked_Lava"
    },
    {
      "x": -30,
      "y": 38,
      "z": 2,
      "name": "Rock_Volcanic"
    },
    {
      "x": -30,
      "y": 39,
      "z": 2,
      "name": "Rock_Volcanic"
    },
    {
      "x": -30,
      "y": 16,
      "z": 3,
      "name": "Rock_Volcanic"
    },
    {
      "x": -30,
      "y": 17,
      "z": 3,
      "name": "Rock_Volcanic"
    },
    {
      "x": -30,
      "y": 18,
      "z": 3,
      "name": "Rock_Volcanic"
    },
    {
      "x": -30,
      "y": 19,
      "z": 3,
      "name": "Rock_Volcanic"
    },
    {
      "x": -30,
      "y": 20,
      "z": 3,
      "name": "Rock_Volcanic"
    },
    {
      "x": -30,
      "y": 21,
      "z": 3,
      "name": "Rock_Volcanic"
    },
    {
      "x": -30,
      "y": 22,
      "z": 3,
      "name": "Rock_Volcanic"
    },
    {
      "x": -30,
      "y": 23,
      "z": 3,
      "name": "Rock_Volcanic"
    },
    {
      "x": -30,
      "y": 24,
      "z": 3,
      "name": "Rock_Volcanic"
    },
    {
      "x": -30,
      "y": 25,
      "z": 3,
      "name": "Rock_Volcanic"
    },
    {
      "x": -30,
      "y": 26,
      "z": 3,
      "name": "Rock_Volcanic"
    },
    {
      "x": -30,
      "y": 27,
      "z": 3,
      "name": "Rock_Volcanic"
    },
    {
      "x": -30,
      "y": 28,
      "z": 3,
      "name": "Rock_Volcanic"
    },
    {
      "x": -30,
      "y": 29,
      "z": 3,
      "name": "Rock_Volcanic"
    },
    {
      "x": -30,
      "y": 30,
      "z": 3,
      "name": "Rock_Volcanic"
    },
    {
      "x": -30,
      "y": 31,
      "z": 3,
      "name": "Rock_Volcanic"
    },
    {
      "x": -30,
      "y": 32,
      "z": 3,
      "name": "Rock_Volcanic"
    },
    {
      "x": -30,
      "y": 33,
      "z": 3,
      "name": "Rock_Volcanic"
    },
    {
      "x": -30,
      "y": 34,
      "z": 3,
      "name": "Rock_Volcanic"
    },
    {
      "x": -30,
      "y": 35,
      "z": 3,
      "name": "Rock_Volcanic"
    },
    {
      "x": -30,
      "y": 36,
      "z": 3,
      "name": "Rock_Volcanic_Cracked_Lava"
    },
    {
      "x": -30,
      "y": 37,
      "z": 3,
      "name": "Rock_Volcanic_Cracked_Lava"
    },
    {
      "x": -30,
      "y": 38,
      "z": 3,
      "name": "Rock_Volcanic"
    },
    {
      "x": -30,
      "y": 39,
      "z": 3,
      "name": "Rock_Volcanic"
    },
    {
      "x": -30,
      "y": 20,
      "z": 4,
      "name": "Rock_Volcanic"
    },
    {
      "x": -30,
      "y": 21,
      "z": 4,
      "name": "Rock_Volcanic"
    },
    {
      "x": -30,
      "y": 22,
      "z": 4,
      "name": "Rock_Volcanic"
    },
    {
      "x": -30,
      "y": 23,
      "z": 4,
      "name": "Rock_Volcanic"
    },
    {
      "x": -30,
      "y": 24,
      "z": 4,
      "name": "Rock_Volcanic"
    },
    {
      "x": -30,
      "y": 25,
      "z": 4,
      "name": "Rock_Volcanic"
    },
    {
      "x": -30,
      "y": 26,
      "z": 4,
      "name": "Rock_Volcanic"
    },
    {
      "x": -30,
      "y": 27,
      "z": 4,
      "name": "Rock_Volcanic"
    },
    {
      "x": -30,
      "y": 28,
      "z": 4,
      "name": "Rock_Volcanic"
    },
    {
      "x": -30,
      "y": 29,
      "z": 4,
      "name": "Rock_Volcanic"
    },
    {
      "x": -30,
      "y": 30,
      "z": 4,
      "name": "Rock_Volcanic"
    },
    {
      "x": -30,
      "y": 31,
      "z": 4,
      "name": "Rock_Volcanic"
    },
    {
      "x": -30,
      "y": 32,
      "z": 4,
      "name": "Rock_Volcanic"
    },
    {
      "x": -30,
      "y": 33,
      "z": 4,
      "name": "Rock_Volcanic"
    },
    {
      "x": -30,
      "y": 34,
      "z": 4,
      "name": "Rock_Volcanic"
    },
    {
      "x": -30,
      "y": 35,
      "z": 4,
      "name": "Rock_Volcanic"
    },
    {
      "x": -30,
      "y": 36,
      "z": 4,
      "name": "Rock_Volcanic_Cracked_Lava"
    },
    {
      "x": -30,
      "y": 37,
      "z": 4,
      "name": "Rock_Volcanic_Cracked_Lava"
    },
    {
      "x": -30,
      "y": 38,
      "z": 4,
      "name": "Rock_Volcanic_Cracked_Lava"
    },
    {
      "x": -30,
      "y": 39,
      "z": 4,
      "name": "Rock_Volcanic_Cracked_Lava"
    },
    {
      "x": -30,
      "y": 22,
      "z": 5,
      "name": "Rock_Volcanic"
    },
    {
      "x": -30,
      "y": 23,
      "z": 5,
      "name": "Rock_Volcanic"
    },
    {
      "x": -30,
      "y": 24,
      "z": 5,
      "name": "Rock_Volcanic"
    },
    {
      "x": -30,
      "y": 25,
      "z": 5,
      "name": "Rock_Volcanic"
    },
    {
      "x": -30,
      "y": 26,
      "z": 5,
      "name": "Rock_Volcanic"
    },
    {
      "x": -30,
      "y": 27,
      "z": 5,
      "name": "Rock_Volcanic"
    },
    {
      "x": -30,
      "y": 28,
      "z": 5,
      "name": "Rock_Volcanic"
    },
    {
      "x": -30,
      "y": 29,
      "z": 5,
      "name": "Rock_Volcanic"
    },
    {
      "x": -30,
      "y": 30,
      "z": 5,
      "name": "Rock_Volcanic"
    },
    {
      "x": -30,
      "y": 31,
      "z": 5,
      "name": "Rock_Volcanic"
    },
    {
      "x": -30,
      "y": 32,
      "z": 5,
      "name": "Rock_Volcanic"
    },
    {
      "x": -30,
      "y": 33,
      "z": 5,
      "name": "Rock_Volcanic"
    },
    {
      "x": -30,
      "y": 34,
      "z": 5,
      "name": "Rock_Volcanic"
    },
    {
      "x": -30,
      "y": 35,
      "z": 5,
      "name": "Rock_Volcanic"
    },
    {
      "x": -30,
      "y": 36,
      "z": 5,
      "name": "Rock_Volcanic"
    },
    {
      "x": -30,
      "y": 37,
      "z": 5,
      "name": "Rock_Volcanic"
    },
    {
      "x": -29,
      "y": 25,
      "z": -1,
      "name": "Rock_Volcanic"
    },
    {
      "x": -29,
      "y": 26,
      "z": -1,
      "name": "Rock_Volcanic"
    },
    {
      "x": -29,
      "y": 27,
      "z": -1,
      "name": "Rock_Volcanic"
    },
    {
      "x": -29,
      "y": 28,
      "z": -1,
      "name": "Rock_Volcanic"
    },
    {
      "x": -29,
      "y": 29,
      "z": -1,
      "name": "Rock_Volcanic"
    },
    {
      "x": -29,
      "y": 30,
      "z": -1,
      "name": "Rock_Volcanic"
    },
    {
      "x": -29,
      "y": 31,
      "z": -1,
      "name": "Rock_Volcanic"
    },
    {
      "x": -29,
      "y": 32,
      "z": -1,
      "name": "Rock_Volcanic"
    },
    {
      "x": -29,
      "y": 18,
      "z": 0,
      "name": "Rock_Volcanic"
    },
    {
      "x": -29,
      "y": 19,
      "z": 0,
      "name": "Rock_Volcanic"
    },
    {
      "x": -29,
      "y": 20,
      "z": 0,
      "name": "Rock_Volcanic"
    },
    {
      "x": -29,
      "y": 21,
      "z": 0,
      "name": "Rock_Volcanic"
    },
    {
      "x": -29,
      "y": 22,
      "z": 0,
      "name": "Rock_Volcanic"
    },
    {
      "x": -29,
      "y": 23,
      "z": 0,
      "name": "Rock_Volcanic"
    },
    {
      "x": -29,
      "y": 24,
      "z": 0,
      "name": "Rock_Volcanic"
    },
    {
      "x": -29,
      "y": 25,
      "z": 0,
      "name": "Rock_Volcanic"
    },
    {
      "x": -29,
      "y": 26,
      "z": 0,
      "name": "Rock_Volcanic"
    },
    {
      "x": -29,
      "y": 27,
      "z": 0,
      "name": "Rock_Volcanic"
    },
    {
      "x": -29,
      "y": 28,
      "z": 0,
      "name": "Rock_Volcanic"
    },
    {
      "x": -29,
      "y": 29,
      "z": 0,
      "name": "Rock_Volcanic"
    },
    {
      "x": -29,
      "y": 30,
      "z": 0,
      "name": "Rock_Volcanic"
    },
    {
      "x": -29,
      "y": 31,
      "z": 0,
      "name": "Rock_Volcanic"
    },
    {
      "x": -29,
      "y": 32,
      "z": 0,
      "name": "Rock_Volcanic"
    },
    {
      "x": -29,
      "y": 33,
      "z": 0,
      "name": "Rock_Volcanic"
    },
    {
      "x": -29,
      "y": 34,
      "z": 0,
      "name": "Rock_Volcanic"
    },
    {
      "x": -29,
      "y": 35,
      "z": 0,
      "name": "Rock_Volcanic"
    },
    {
      "x": -29,
      "y": 36,
      "z": 0,
      "name": "Rock_Volcanic_Cracked_Lava"
    },
    {
      "x": -29,
      "y": 13,
      "z": 1,
      "name": "Rock_Volcanic"
    },
    {
      "x": -29,
      "y": 14,
      "z": 1,
      "name": "Rock_Volcanic"
    },
    {
      "x": -29,
      "y": 15,
      "z": 1,
      "name": "Rock_Volcanic"
    },
    {
      "x": -29,
      "y": 16,
      "z": 1,
      "name": "Rock_Volcanic"
    },
    {
      "x": -29,
      "y": 17,
      "z": 1,
      "name": "Rock_Volcanic"
    },
    {
      "x": -29,
      "y": 18,
      "z": 1,
      "name": "Rock_Volcanic"
    },
    {
      "x": -29,
      "y": 19,
      "z": 1,
      "name": "Rock_Volcanic"
    },
    {
      "x": -29,
      "y": 20,
      "z": 1,
      "name": "Rock_Volcanic"
    },
    {
      "x": -29,
      "y": 21,
      "z": 1,
      "name": "Rock_Volcanic"
    },
    {
      "x": -29,
      "y": 22,
      "z": 1,
      "name": "Rock_Volcanic"
    },
    {
      "x": -29,
      "y": 23,
      "z": 1,
      "name": "Rock_Volcanic"
    },
    {
      "x": -29,
      "y": 24,
      "z": 1,
      "name": "Rock_Volcanic"
    },
    {
      "x": -29,
      "y": 25,
      "z": 1,
      "name": "Rock_Volcanic"
    },
    {
      "x": -29,
      "y": 26,
      "z": 1,
      "name": "Rock_Volcanic"
    },
    {
      "x": -29,
      "y": 27,
      "z": 1,
      "name": "Rock_Volcanic"
    },
    {
      "x": -29,
      "y": 28,
      "z": 1,
      "name": "Rock_Volcanic"
    },
    {
      "x": -29,
      "y": 29,
      "z": 1,
      "name": "Rock_Volcanic"
    },
    {
      "x": -29,
      "y": 30,
      "z": 1,
      "name": "Rock_Volcanic"
    },
    {
      "x": -29,
      "y": 31,
      "z": 1,
      "name": "Rock_Volcanic"
    },
    {
      "x": -29,
      "y": 32,
      "z": 1,
      "name": "Rock_Volcanic"
    },
    {
      "x": -29,
      "y": 33,
      "z": 1,
      "name": "Rock_Volcanic"
    },
    {
      "x": -29,
      "y": 34,
      "z": 1,
      "name": "Rock_Volcanic"
    },
    {
      "x": -29,
      "y": 35,
      "z": 1,
      "name": "Rock_Volcanic"
    },
    {
      "x": -29,
      "y": 36,
      "z": 1,
      "name": "Rock_Volcanic"
    },
    {
      "x": -29,
      "y": 37,
      "z": 1,
      "name": "Rock_Volcanic"
    },
    {
      "x": -29,
      "y": 38,
      "z": 1,
      "name": "Rock_Volcanic"
    },
    {
      "x": -29,
      "y": 7,
      "z": 2,
      "name": "Rock_Volcanic"
    },
    {
      "x": -29,
      "y": 8,
      "z": 2,
      "name": "Rock_Volcanic"
    },
    {
      "x": -29,
      "y": 9,
      "z": 2,
      "name": "Rock_Volcanic"
    },
    {
      "x": -29,
      "y": 10,
      "z": 2,
      "name": "Rock_Volcanic"
    },
    {
      "x": -29,
      "y": 11,
      "z": 2,
      "name": "Rock_Volcanic"
    },
    {
      "x": -29,
      "y": 12,
      "z": 2,
      "name": "Rock_Volcanic"
    },
    {
      "x": -29,
      "y": 13,
      "z": 2,
      "name": "Rock_Volcanic"
    },
    {
      "x": -29,
      "y": 14,
      "z": 2,
      "name": "Rock_Volcanic"
    },
    {
      "x": -29,
      "y": 15,
      "z": 2,
      "name": "Rock_Volcanic"
    },
    {
      "x": -29,
      "y": 16,
      "z": 2,
      "name": "Rock_Volcanic"
    },
    {
      "x": -29,
      "y": 17,
      "z": 2,
      "name": "Rock_Volcanic"
    },
    {
      "x": -29,
      "y": 18,
      "z": 2,
      "name": "Rock_Volcanic"
    },
    {
      "x": -29,
      "y": 19,
      "z": 2,
      "name": "Rock_Volcanic"
    },
    {
      "x": -29,
      "y": 20,
      "z": 2,
      "name": "Rock_Volcanic"
    },
    {
      "x": -29,
      "y": 21,
      "z": 2,
      "name": "Rock_Volcanic"
    },
    {
      "x": -29,
      "y": 22,
      "z": 2,
      "name": "Rock_Volcanic"
    },
    {
      "x": -29,
      "y": 23,
      "z": 2,
      "name": "Rock_Volcanic"
    },
    {
      "x": -29,
      "y": 24,
      "z": 2,
      "name": "Rock_Volcanic"
    },
    {
      "x": -29,
      "y": 25,
      "z": 2,
      "name": "Rock_Volcanic"
    },
    {
      "x": -29,
      "y": 26,
      "z": 2,
      "name": "Rock_Volcanic"
    },
    {
      "x": -29,
      "y": 27,
      "z": 2,
      "name": "Rock_Volcanic"
    },
    {
      "x": -29,
      "y": 28,
      "z": 2,
      "name": "Rock_Volcanic"
    },
    {
      "x": -29,
      "y": 29,
      "z": 2,
      "name": "Rock_Volcanic"
    },
    {
      "x": -29,
      "y": 30,
      "z": 2,
      "name": "Rock_Volcanic"
    },
    {
      "x": -29,
      "y": 31,
      "z": 2,
      "name": "Rock_Volcanic"
    },
    {
      "x": -29,
      "y": 32,
      "z": 2,
      "name": "Rock_Volcanic"
    },
    {
      "x": -29,
      "y": 33,
      "z": 2,
      "name": "Rock_Volcanic"
    },
    {
      "x": -29,
      "y": 34,
      "z": 2,
      "name": "Rock_Volcanic"
    },
    {
      "x": -29,
      "y": 35,
      "z": 2,
      "name": "Rock_Volcanic_Cracked_Lava"
    },
    {
      "x": -29,
      "y": 36,
      "z": 2,
      "name": "Rock_Volcanic_Cracked_Lava"
    },
    {
      "x": -29,
      "y": 37,
      "z": 2,
      "name": "Rock_Volcanic_Cracked_Lava"
    },
    {
      "x": -29,
      "y": 38,
      "z": 2,
      "name": "Rock_Volcanic"
    },
    {
      "x": -29,
      "y": 9,
      "z": 3,
      "name": "Rock_Volcanic"
    },
    {
      "x": -29,
      "y": 10,
      "z": 3,
      "name": "Rock_Volcanic"
    },
    {
      "x": -29,
      "y": 11,
      "z": 3,
      "name": "Rock_Volcanic"
    },
    {
      "x": -29,
      "y": 12,
      "z": 3,
      "name": "Rock_Volcanic"
    },
    {
      "x": -29,
      "y": 13,
      "z": 3,
      "name": "Rock_Volcanic"
    },
    {
      "x": -29,
      "y": 14,
      "z": 3,
      "name": "Rock_Volcanic"
    },
    {
      "x": -29,
      "y": 15,
      "z": 3,
      "name": "Rock_Volcanic"
    },
    {
      "x": -29,
      "y": 16,
      "z": 3,
      "name": "Rock_Volcanic"
    },
    {
      "x": -29,
      "y": 17,
      "z": 3,
      "name": "Rock_Volcanic"
    },
    {
      "x": -29,
      "y": 18,
      "z": 3,
      "name": "Rock_Volcanic"
    },
    {
      "x": -29,
      "y": 19,
      "z": 3,
      "name": "Rock_Volcanic"
    },
    {
      "x": -29,
      "y": 20,
      "z": 3,
      "name": "Rock_Volcanic"
    },
    {
      "x": -29,
      "y": 21,
      "z": 3,
      "name": "Rock_Volcanic"
    },
    {
      "x": -29,
      "y": 22,
      "z": 3,
      "name": "Rock_Volcanic"
    },
    {
      "x": -29,
      "y": 23,
      "z": 3,
      "name": "Rock_Volcanic"
    },
    {
      "x": -29,
      "y": 24,
      "z": 3,
      "name": "Rock_Volcanic"
    },
    {
      "x": -29,
      "y": 25,
      "z": 3,
      "name": "Rock_Volcanic"
    },
    {
      "x": -29,
      "y": 26,
      "z": 3,
      "name": "Rock_Volcanic"
    },
    {
      "x": -29,
      "y": 27,
      "z": 3,
      "name": "Rock_Volcanic"
    },
    {
      "x": -29,
      "y": 28,
      "z": 3,
      "name": "Rock_Volcanic"
    },
    {
      "x": -29,
      "y": 29,
      "z": 3,
      "name": "Rock_Volcanic"
    },
    {
      "x": -29,
      "y": 30,
      "z": 3,
      "name": "Rock_Volcanic"
    },
    {
      "x": -29,
      "y": 31,
      "z": 3,
      "name": "Rock_Volcanic"
    },
    {
      "x": -29,
      "y": 32,
      "z": 3,
      "name": "Rock_Volcanic"
    },
    {
      "x": -29,
      "y": 33,
      "z": 3,
      "name": "Rock_Volcanic"
    },
    {
      "x": -29,
      "y": 34,
      "z": 3,
      "name": "Rock_Volcanic"
    },
    {
      "x": -29,
      "y": 35,
      "z": 3,
      "name": "Rock_Volcanic"
    },
    {
      "x": -29,
      "y": 36,
      "z": 3,
      "name": "Rock_Volcanic_Cracked_Lava"
    },
    {
      "x": -29,
      "y": 37,
      "z": 3,
      "name": "Rock_Volcanic"
    },
    {
      "x": -29,
      "y": 38,
      "z": 3,
      "name": "Rock_Volcanic"
    },
    {
      "x": -29,
      "y": 12,
      "z": 4,
      "name": "Rock_Volcanic"
    },
    {
      "x": -29,
      "y": 13,
      "z": 4,
      "name": "Rock_Volcanic"
    },
    {
      "x": -29,
      "y": 14,
      "z": 4,
      "name": "Rock_Volcanic"
    },
    {
      "x": -29,
      "y": 15,
      "z": 4,
      "name": "Rock_Volcanic"
    },
    {
      "x": -29,
      "y": 16,
      "z": 4,
      "name": "Rock_Volcanic"
    },
    {
      "x": -29,
      "y": 17,
      "z": 4,
      "name": "Rock_Volcanic"
    },
    {
      "x": -29,
      "y": 18,
      "z": 4,
      "name": "Rock_Volcanic"
    },
    {
      "x": -29,
      "y": 19,
      "z": 4,
      "name": "Rock_Volcanic"
    },
    {
      "x": -29,
      "y": 20,
      "z": 4,
      "name": "Rock_Volcanic"
    },
    {
      "x": -29,
      "y": 21,
      "z": 4,
      "name": "Rock_Volcanic"
    },
    {
      "x": -29,
      "y": 22,
      "z": 4,
      "name": "Rock_Volcanic"
    },
    {
      "x": -29,
      "y": 23,
      "z": 4,
      "name": "Rock_Volcanic"
    },
    {
      "x": -29,
      "y": 24,
      "z": 4,
      "name": "Rock_Volcanic"
    },
    {
      "x": -29,
      "y": 25,
      "z": 4,
      "name": "Rock_Volcanic"
    },
    {
      "x": -29,
      "y": 26,
      "z": 4,
      "name": "Rock_Volcanic"
    },
    {
      "x": -29,
      "y": 27,
      "z": 4,
      "name": "Rock_Volcanic"
    },
    {
      "x": -29,
      "y": 28,
      "z": 4,
      "name": "Rock_Volcanic"
    },
    {
      "x": -29,
      "y": 29,
      "z": 4,
      "name": "Rock_Volcanic"
    },
    {
      "x": -29,
      "y": 30,
      "z": 4,
      "name": "Rock_Volcanic"
    },
    {
      "x": -29,
      "y": 31,
      "z": 4,
      "name": "Rock_Volcanic"
    },
    {
      "x": -29,
      "y": 32,
      "z": 4,
      "name": "Rock_Volcanic"
    },
    {
      "x": -29,
      "y": 33,
      "z": 4,
      "name": "Rock_Volcanic"
    },
    {
      "x": -29,
      "y": 34,
      "z": 4,
      "name": "Rock_Volcanic"
    },
    {
      "x": -29,
      "y": 35,
      "z": 4,
      "name": "Rock_Volcanic"
    },
    {
      "x": -29,
      "y": 36,
      "z": 4,
      "name": "Rock_Volcanic_Cracked_Lava"
    },
    {
      "x": -29,
      "y": 37,
      "z": 4,
      "name": "Rock_Volcanic"
    },
    {
      "x": -29,
      "y": 15,
      "z": 5,
      "name": "Rock_Volcanic"
    },
    {
      "x": -29,
      "y": 16,
      "z": 5,
      "name": "Rock_Volcanic"
    },
    {
      "x": -29,
      "y": 17,
      "z": 5,
      "name": "Rock_Volcanic"
    },
    {
      "x": -29,
      "y": 18,
      "z": 5,
      "name": "Rock_Volcanic"
    },
    {
      "x": -29,
      "y": 19,
      "z": 5,
      "name": "Rock_Volcanic"
    },
    {
      "x": -29,
      "y": 20,
      "z": 5,
      "name": "Rock_Volcanic"
    },
    {
      "x": -29,
      "y": 21,
      "z": 5,
      "name": "Rock_Volcanic"
    },
    {
      "x": -29,
      "y": 22,
      "z": 5,
      "name": "Rock_Volcanic"
    },
    {
      "x": -29,
      "y": 23,
      "z": 5,
      "name": "Rock_Volcanic"
    },
    {
      "x": -29,
      "y": 24,
      "z": 5,
      "name": "Rock_Volcanic"
    },
    {
      "x": -29,
      "y": 25,
      "z": 5,
      "name": "Rock_Volcanic"
    },
    {
      "x": -29,
      "y": 26,
      "z": 5,
      "name": "Rock_Volcanic"
    },
    {
      "x": -29,
      "y": 27,
      "z": 5,
      "name": "Rock_Volcanic"
    },
    {
      "x": -29,
      "y": 28,
      "z": 5,
      "name": "Rock_Volcanic"
    },
    {
      "x": -29,
      "y": 29,
      "z": 5,
      "name": "Rock_Volcanic"
    },
    {
      "x": -29,
      "y": 30,
      "z": 5,
      "name": "Rock_Volcanic"
    },
    {
      "x": -29,
      "y": 31,
      "z": 5,
      "name": "Rock_Volcanic"
    },
    {
      "x": -29,
      "y": 32,
      "z": 5,
      "name": "Rock_Volcanic"
    },
    {
      "x": -29,
      "y": 33,
      "z": 5,
      "name": "Rock_Volcanic"
    },
    {
      "x": -29,
      "y": 34,
      "z": 5,
      "name": "Rock_Volcanic"
    },
    {
      "x": -29,
      "y": 35,
      "z": 5,
      "name": "Rock_Volcanic"
    },
    {
      "x": -29,
      "y": 18,
      "z": 6,
      "name": "Rock_Volcanic"
    },
    {
      "x": -29,
      "y": 19,
      "z": 6,
      "name": "Rock_Volcanic"
    },
    {
      "x": -29,
      "y": 20,
      "z": 6,
      "name": "Rock_Volcanic"
    },
    {
      "x": -29,
      "y": 21,
      "z": 6,
      "name": "Rock_Volcanic"
    },
    {
      "x": -29,
      "y": 22,
      "z": 6,
      "name": "Rock_Volcanic"
    },
    {
      "x": -29,
      "y": 23,
      "z": 6,
      "name": "Rock_Volcanic"
    },
    {
      "x": -29,
      "y": 24,
      "z": 6,
      "name": "Rock_Volcanic"
    },
    {
      "x": -29,
      "y": 25,
      "z": 6,
      "name": "Rock_Volcanic"
    },
    {
      "x": -28,
      "y": 21,
      "z": -2,
      "name": "Rock_Volcanic"
    },
    {
      "x": -28,
      "y": 22,
      "z": -2,
      "name": "Rock_Volcanic"
    },
    {
      "x": -28,
      "y": 23,
      "z": -2,
      "name": "Rock_Volcanic"
    },
    {
      "x": -28,
      "y": 24,
      "z": -2,
      "name": "Rock_Volcanic"
    },
    {
      "x": -28,
      "y": 25,
      "z": -2,
      "name": "Rock_Volcanic"
    },
    {
      "x": -28,
      "y": 26,
      "z": -2,
      "name": "Rock_Volcanic"
    },
    {
      "x": -28,
      "y": 27,
      "z": -2,
      "name": "Rock_Volcanic"
    },
    {
      "x": -28,
      "y": 28,
      "z": -2,
      "name": "Rock_Volcanic"
    },
    {
      "x": -28,
      "y": 14,
      "z": -1,
      "name": "Rock_Volcanic"
    },
    {
      "x": -28,
      "y": 15,
      "z": -1,
      "name": "Rock_Volcanic"
    },
    {
      "x": -28,
      "y": 16,
      "z": -1,
      "name": "Rock_Volcanic"
    },
    {
      "x": -28,
      "y": 17,
      "z": -1,
      "name": "Rock_Volcanic"
    },
    {
      "x": -28,
      "y": 18,
      "z": -1,
      "name": "Rock_Volcanic"
    },
    {
      "x": -28,
      "y": 19,
      "z": -1,
      "name": "Rock_Volcanic"
    },
    {
      "x": -28,
      "y": 20,
      "z": -1,
      "name": "Rock_Volcanic"
    },
    {
      "x": -28,
      "y": 21,
      "z": -1,
      "name": "Rock_Volcanic"
    },
    {
      "x": -28,
      "y": 22,
      "z": -1,
      "name": "Rock_Volcanic"
    },
    {
      "x": -28,
      "y": 23,
      "z": -1,
      "name": "Rock_Volcanic"
    },
    {
      "x": -28,
      "y": 24,
      "z": -1,
      "name": "Rock_Volcanic"
    },
    {
      "x": -28,
      "y": 25,
      "z": -1,
      "name": "Rock_Volcanic"
    },
    {
      "x": -28,
      "y": 26,
      "z": -1,
      "name": "Rock_Volcanic"
    },
    {
      "x": -28,
      "y": 27,
      "z": -1,
      "name": "Rock_Volcanic"
    },
    {
      "x": -28,
      "y": 28,
      "z": -1,
      "name": "Rock_Volcanic"
    },
    {
      "x": -28,
      "y": 29,
      "z": -1,
      "name": "Rock_Volcanic"
    },
    {
      "x": -28,
      "y": 30,
      "z": -1,
      "name": "Rock_Volcanic"
    },
    {
      "x": -28,
      "y": 31,
      "z": -1,
      "name": "Rock_Volcanic"
    },
    {
      "x": -28,
      "y": 10,
      "z": 0,
      "name": "Rock_Volcanic"
    },
    {
      "x": -28,
      "y": 11,
      "z": 0,
      "name": "Rock_Volcanic"
    },
    {
      "x": -28,
      "y": 12,
      "z": 0,
      "name": "Rock_Volcanic"
    },
    {
      "x": -28,
      "y": 13,
      "z": 0,
      "name": "Rock_Volcanic"
    },
    {
      "x": -28,
      "y": 14,
      "z": 0,
      "name": "Rock_Volcanic"
    },
    {
      "x": -28,
      "y": 15,
      "z": 0,
      "name": "Rock_Volcanic"
    },
    {
      "x": -28,
      "y": 16,
      "z": 0,
      "name": "Rock_Volcanic"
    },
    {
      "x": -28,
      "y": 17,
      "z": 0,
      "name": "Rock_Volcanic"
    },
    {
      "x": -28,
      "y": 18,
      "z": 0,
      "name": "Rock_Volcanic"
    },
    {
      "x": -28,
      "y": 19,
      "z": 0,
      "name": "Rock_Volcanic"
    },
    {
      "x": -28,
      "y": 20,
      "z": 0,
      "name": "Rock_Volcanic"
    },
    {
      "x": -28,
      "y": 21,
      "z": 0,
      "name": "Rock_Volcanic"
    },
    {
      "x": -28,
      "y": 22,
      "z": 0,
      "name": "Rock_Volcanic"
    },
    {
      "x": -28,
      "y": 23,
      "z": 0,
      "name": "Rock_Volcanic"
    },
    {
      "x": -28,
      "y": 24,
      "z": 0,
      "name": "Rock_Volcanic"
    },
    {
      "x": -28,
      "y": 25,
      "z": 0,
      "name": "Rock_Volcanic"
    },
    {
      "x": -28,
      "y": 26,
      "z": 0,
      "name": "Rock_Volcanic"
    },
    {
      "x": -28,
      "y": 27,
      "z": 0,
      "name": "Rock_Volcanic"
    },
    {
      "x": -28,
      "y": 28,
      "z": 0,
      "name": "Rock_Volcanic"
    },
    {
      "x": -28,
      "y": 29,
      "z": 0,
      "name": "Rock_Volcanic"
    },
    {
      "x": -28,
      "y": 30,
      "z": 0,
      "name": "Rock_Volcanic"
    },
    {
      "x": -28,
      "y": 31,
      "z": 0,
      "name": "Rock_Volcanic"
    },
    {
      "x": -28,
      "y": 32,
      "z": 0,
      "name": "Rock_Volcanic"
    },
    {
      "x": -28,
      "y": 33,
      "z": 0,
      "name": "Rock_Volcanic"
    },
    {
      "x": -28,
      "y": 34,
      "z": 0,
      "name": "Rock_Volcanic"
    },
    {
      "x": -28,
      "y": 35,
      "z": 0,
      "name": "Rock_Volcanic"
    },
    {
      "x": -28,
      "y": 5,
      "z": 1,
      "name": "Rock_Volcanic"
    },
    {
      "x": -28,
      "y": 6,
      "z": 1,
      "name": "Rock_Volcanic"
    },
    {
      "x": -28,
      "y": 7,
      "z": 1,
      "name": "Rock_Volcanic"
    },
    {
      "x": -28,
      "y": 8,
      "z": 1,
      "name": "Rock_Volcanic"
    },
    {
      "x": -28,
      "y": 9,
      "z": 1,
      "name": "Rock_Volcanic"
    },
    {
      "x": -28,
      "y": 10,
      "z": 1,
      "name": "Rock_Volcanic"
    },
    {
      "x": -28,
      "y": 11,
      "z": 1,
      "name": "Rock_Volcanic"
    },
    {
      "x": -28,
      "y": 12,
      "z": 1,
      "name": "Rock_Volcanic"
    },
    {
      "x": -28,
      "y": 13,
      "z": 1,
      "name": "Rock_Volcanic"
    },
    {
      "x": -28,
      "y": 14,
      "z": 1,
      "name": "Rock_Volcanic"
    },
    {
      "x": -28,
      "y": 15,
      "z": 1,
      "name": "Rock_Volcanic"
    },
    {
      "x": -28,
      "y": 16,
      "z": 1,
      "name": "Rock_Volcanic"
    },
    {
      "x": -28,
      "y": 17,
      "z": 1,
      "name": "Rock_Volcanic"
    },
    {
      "x": -28,
      "y": 18,
      "z": 1,
      "name": "Rock_Volcanic"
    },
    {
      "x": -28,
      "y": 19,
      "z": 1,
      "name": "Rock_Volcanic"
    },
    {
      "x": -28,
      "y": 20,
      "z": 1,
      "name": "Rock_Volcanic"
    },
    {
      "x": -28,
      "y": 21,
      "z": 1,
      "name": "Rock_Volcanic"
    },
    {
      "x": -28,
      "y": 22,
      "z": 1,
      "name": "Rock_Volcanic"
    },
    {
      "x": -28,
      "y": 23,
      "z": 1,
      "name": "Rock_Volcanic"
    },
    {
      "x": -28,
      "y": 24,
      "z": 1,
      "name": "Rock_Volcanic"
    },
    {
      "x": -28,
      "y": 25,
      "z": 1,
      "name": "Rock_Volcanic"
    },
    {
      "x": -28,
      "y": 26,
      "z": 1,
      "name": "Rock_Volcanic"
    },
    {
      "x": -28,
      "y": 27,
      "z": 1,
      "name": "Rock_Volcanic"
    },
    {
      "x": -28,
      "y": 28,
      "z": 1,
      "name": "Rock_Volcanic"
    },
    {
      "x": -28,
      "y": 29,
      "z": 1,
      "name": "Rock_Volcanic"
    },
    {
      "x": -28,
      "y": 30,
      "z": 1,
      "name": "Rock_Volcanic"
    },
    {
      "x": -28,
      "y": 31,
      "z": 1,
      "name": "Rock_Volcanic"
    },
    {
      "x": -28,
      "y": 32,
      "z": 1,
      "name": "Rock_Volcanic"
    },
    {
      "x": -28,
      "y": 33,
      "z": 1,
      "name": "Rock_Volcanic"
    },
    {
      "x": -28,
      "y": 34,
      "z": 1,
      "name": "Rock_Volcanic"
    },
    {
      "x": -28,
      "y": 35,
      "z": 1,
      "name": "Rock_Volcanic_Cracked_Lava"
    },
    {
      "x": -28,
      "y": 36,
      "z": 1,
      "name": "Rock_Volcanic"
    },
    {
      "x": -28,
      "y": 3,
      "z": 2,
      "name": "Rock_Volcanic"
    },
    {
      "x": -28,
      "y": 4,
      "z": 2,
      "name": "Rock_Volcanic"
    },
    {
      "x": -28,
      "y": 5,
      "z": 2,
      "name": "Rock_Volcanic"
    },
    {
      "x": -28,
      "y": 6,
      "z": 2,
      "name": "Rock_Volcanic"
    },
    {
      "x": -28,
      "y": 7,
      "z": 2,
      "name": "Rock_Volcanic"
    },
    {
      "x": -28,
      "y": 8,
      "z": 2,
      "name": "Rock_Volcanic"
    },
    {
      "x": -28,
      "y": 9,
      "z": 2,
      "name": "Rock_Volcanic"
    },
    {
      "x": -28,
      "y": 10,
      "z": 2,
      "name": "Rock_Volcanic"
    },
    {
      "x": -28,
      "y": 11,
      "z": 2,
      "name": "Rock_Volcanic"
    },
    {
      "x": -28,
      "y": 12,
      "z": 2,
      "name": "Rock_Volcanic"
    },
    {
      "x": -28,
      "y": 13,
      "z": 2,
      "name": "Rock_Volcanic"
    },
    {
      "x": -28,
      "y": 14,
      "z": 2,
      "name": "Rock_Volcanic"
    },
    {
      "x": -28,
      "y": 15,
      "z": 2,
      "name": "Rock_Volcanic"
    },
    {
      "x": -28,
      "y": 16,
      "z": 2,
      "name": "Rock_Volcanic"
    },
    {
      "x": -28,
      "y": 17,
      "z": 2,
      "name": "Rock_Volcanic"
    },
    {
      "x": -28,
      "y": 18,
      "z": 2,
      "name": "Rock_Volcanic"
    },
    {
      "x": -28,
      "y": 19,
      "z": 2,
      "name": "Rock_Volcanic"
    },
    {
      "x": -28,
      "y": 20,
      "z": 2,
      "name": "Rock_Volcanic"
    },
    {
      "x": -28,
      "y": 21,
      "z": 2,
      "name": "Rock_Volcanic"
    },
    {
      "x": -28,
      "y": 22,
      "z": 2,
      "name": "Rock_Volcanic"
    },
    {
      "x": -28,
      "y": 23,
      "z": 2,
      "name": "Rock_Volcanic"
    },
    {
      "x": -28,
      "y": 24,
      "z": 2,
      "name": "Rock_Volcanic"
    },
    {
      "x": -28,
      "y": 25,
      "z": 2,
      "name": "Rock_Volcanic"
    },
    {
      "x": -28,
      "y": 26,
      "z": 2,
      "name": "Rock_Volcanic"
    },
    {
      "x": -28,
      "y": 27,
      "z": 2,
      "name": "Rock_Volcanic"
    },
    {
      "x": -28,
      "y": 28,
      "z": 2,
      "name": "Rock_Volcanic"
    },
    {
      "x": -28,
      "y": 29,
      "z": 2,
      "name": "Rock_Volcanic"
    },
    {
      "x": -28,
      "y": 30,
      "z": 2,
      "name": "Rock_Volcanic"
    },
    {
      "x": -28,
      "y": 31,
      "z": 2,
      "name": "Rock_Volcanic"
    },
    {
      "x": -28,
      "y": 32,
      "z": 2,
      "name": "Rock_Volcanic"
    },
    {
      "x": -28,
      "y": 33,
      "z": 2,
      "name": "Rock_Volcanic"
    },
    {
      "x": -28,
      "y": 34,
      "z": 2,
      "name": "Rock_Volcanic"
    },
    {
      "x": -28,
      "y": 35,
      "z": 2,
      "name": "Rock_Volcanic_Cracked_Lava"
    },
    {
      "x": -28,
      "y": 36,
      "z": 2,
      "name": "Rock_Volcanic"
    },
    {
      "x": -28,
      "y": 37,
      "z": 2,
      "name": "Rock_Volcanic"
    },
    {
      "x": -28,
      "y": 1,
      "z": 3,
      "name": "Rock_Volcanic"
    },
    {
      "x": -28,
      "y": 2,
      "z": 3,
      "name": "Rock_Volcanic"
    },
    {
      "x": -28,
      "y": 3,
      "z": 3,
      "name": "Rock_Volcanic"
    },
    {
      "x": -28,
      "y": 4,
      "z": 3,
      "name": "Rock_Volcanic"
    },
    {
      "x": -28,
      "y": 5,
      "z": 3,
      "name": "Rock_Volcanic"
    },
    {
      "x": -28,
      "y": 6,
      "z": 3,
      "name": "Rock_Volcanic"
    },
    {
      "x": -28,
      "y": 7,
      "z": 3,
      "name": "Rock_Volcanic"
    },
    {
      "x": -28,
      "y": 8,
      "z": 3,
      "name": "Rock_Volcanic"
    },
    {
      "x": -28,
      "y": 9,
      "z": 3,
      "name": "Rock_Volcanic"
    },
    {
      "x": -28,
      "y": 10,
      "z": 3,
      "name": "Rock_Volcanic"
    },
    {
      "x": -28,
      "y": 11,
      "z": 3,
      "name": "Rock_Volcanic"
    },
    {
      "x": -28,
      "y": 12,
      "z": 3,
      "name": "Rock_Volcanic"
    },
    {
      "x": -28,
      "y": 13,
      "z": 3,
      "name": "Rock_Volcanic"
    },
    {
      "x": -28,
      "y": 14,
      "z": 3,
      "name": "Rock_Volcanic"
    },
    {
      "x": -28,
      "y": 15,
      "z": 3,
      "name": "Rock_Volcanic"
    },
    {
      "x": -28,
      "y": 16,
      "z": 3,
      "name": "Rock_Volcanic"
    },
    {
      "x": -28,
      "y": 17,
      "z": 3,
      "name": "Rock_Volcanic"
    },
    {
      "x": -28,
      "y": 18,
      "z": 3,
      "name": "Rock_Volcanic"
    },
    {
      "x": -28,
      "y": 19,
      "z": 3,
      "name": "Rock_Volcanic"
    },
    {
      "x": -28,
      "y": 20,
      "z": 3,
      "name": "Rock_Volcanic"
    },
    {
      "x": -28,
      "y": 21,
      "z": 3,
      "name": "Rock_Volcanic"
    },
    {
      "x": -28,
      "y": 22,
      "z": 3,
      "name": "Rock_Volcanic"
    },
    {
      "x": -28,
      "y": 23,
      "z": 3,
      "name": "Rock_Volcanic"
    },
    {
      "x": -28,
      "y": 24,
      "z": 3,
      "name": "Rock_Volcanic"
    },
    {
      "x": -28,
      "y": 25,
      "z": 3,
      "name": "Rock_Volcanic"
    },
    {
      "x": -28,
      "y": 26,
      "z": 3,
      "name": "Rock_Volcanic"
    },
    {
      "x": -28,
      "y": 27,
      "z": 3,
      "name": "Rock_Volcanic"
    },
    {
      "x": -28,
      "y": 28,
      "z": 3,
      "name": "Rock_Volcanic"
    },
    {
      "x": -28,
      "y": 29,
      "z": 3,
      "name": "Rock_Volcanic"
    },
    {
      "x": -28,
      "y": 30,
      "z": 3,
      "name": "Rock_Volcanic"
    },
    {
      "x": -28,
      "y": 31,
      "z": 3,
      "name": "Rock_Volcanic"
    },
    {
      "x": -28,
      "y": 32,
      "z": 3,
      "name": "Rock_Volcanic"
    },
    {
      "x": -28,
      "y": 33,
      "z": 3,
      "name": "Rock_Volcanic"
    },
    {
      "x": -28,
      "y": 34,
      "z": 3,
      "name": "Rock_Volcanic"
    },
    {
      "x": -28,
      "y": 35,
      "z": 3,
      "name": "Rock_Volcanic"
    },
    {
      "x": -28,
      "y": 36,
      "z": 3,
      "name": "Rock_Volcanic"
    },
    {
      "x": -28,
      "y": 37,
      "z": 3,
      "name": "Rock_Volcanic"
    },
    {
      "x": -28,
      "y": 8,
      "z": 4,
      "name": "Rock_Volcanic"
    },
    {
      "x": -28,
      "y": 9,
      "z": 4,
      "name": "Rock_Volcanic"
    },
    {
      "x": -28,
      "y": 10,
      "z": 4,
      "name": "Rock_Volcanic"
    },
    {
      "x": -28,
      "y": 11,
      "z": 4,
      "name": "Rock_Volcanic"
    },
    {
      "x": -28,
      "y": 12,
      "z": 4,
      "name": "Rock_Volcanic"
    },
    {
      "x": -28,
      "y": 13,
      "z": 4,
      "name": "Rock_Volcanic"
    },
    {
      "x": -28,
      "y": 14,
      "z": 4,
      "name": "Rock_Volcanic"
    },
    {
      "x": -28,
      "y": 15,
      "z": 4,
      "name": "Rock_Volcanic"
    },
    {
      "x": -28,
      "y": 16,
      "z": 4,
      "name": "Rock_Volcanic"
    },
    {
      "x": -28,
      "y": 17,
      "z": 4,
      "name": "Rock_Volcanic"
    },
    {
      "x": -28,
      "y": 18,
      "z": 4,
      "name": "Rock_Volcanic"
    },
    {
      "x": -28,
      "y": 19,
      "z": 4,
      "name": "Rock_Volcanic"
    },
    {
      "x": -28,
      "y": 20,
      "z": 4,
      "name": "Rock_Volcanic"
    },
    {
      "x": -28,
      "y": 21,
      "z": 4,
      "name": "Rock_Volcanic"
    },
    {
      "x": -28,
      "y": 22,
      "z": 4,
      "name": "Rock_Volcanic"
    },
    {
      "x": -28,
      "y": 23,
      "z": 4,
      "name": "Rock_Volcanic"
    },
    {
      "x": -28,
      "y": 24,
      "z": 4,
      "name": "Rock_Volcanic"
    },
    {
      "x": -28,
      "y": 25,
      "z": 4,
      "name": "Rock_Volcanic"
    },
    {
      "x": -28,
      "y": 26,
      "z": 4,
      "name": "Rock_Volcanic"
    },
    {
      "x": -28,
      "y": 27,
      "z": 4,
      "name": "Rock_Volcanic"
    },
    {
      "x": -28,
      "y": 28,
      "z": 4,
      "name": "Rock_Volcanic"
    },
    {
      "x": -28,
      "y": 29,
      "z": 4,
      "name": "Rock_Volcanic"
    },
    {
      "x": -28,
      "y": 30,
      "z": 4,
      "name": "Rock_Volcanic"
    },
    {
      "x": -28,
      "y": 31,
      "z": 4,
      "name": "Rock_Volcanic"
    },
    {
      "x": -28,
      "y": 32,
      "z": 4,
      "name": "Rock_Volcanic"
    },
    {
      "x": -28,
      "y": 33,
      "z": 4,
      "name": "Rock_Volcanic"
    },
    {
      "x": -28,
      "y": 34,
      "z": 4,
      "name": "Rock_Volcanic"
    },
    {
      "x": -28,
      "y": 35,
      "z": 4,
      "name": "Rock_Volcanic"
    },
    {
      "x": -28,
      "y": 36,
      "z": 4,
      "name": "Rock_Volcanic"
    },
    {
      "x": -28,
      "y": 37,
      "z": 4,
      "name": "Rock_Volcanic_Cracked_Lava"
    },
    {
      "x": -28,
      "y": 10,
      "z": 5,
      "name": "Rock_Volcanic"
    },
    {
      "x": -28,
      "y": 11,
      "z": 5,
      "name": "Rock_Volcanic"
    },
    {
      "x": -28,
      "y": 12,
      "z": 5,
      "name": "Rock_Volcanic"
    },
    {
      "x": -28,
      "y": 13,
      "z": 5,
      "name": "Rock_Volcanic"
    },
    {
      "x": -28,
      "y": 14,
      "z": 5,
      "name": "Rock_Volcanic"
    },
    {
      "x": -28,
      "y": 15,
      "z": 5,
      "name": "Rock_Volcanic"
    },
    {
      "x": -28,
      "y": 16,
      "z": 5,
      "name": "Rock_Volcanic"
    },
    {
      "x": -28,
      "y": 17,
      "z": 5,
      "name": "Rock_Volcanic"
    },
    {
      "x": -28,
      "y": 18,
      "z": 5,
      "name": "Rock_Volcanic"
    },
    {
      "x": -28,
      "y": 19,
      "z": 5,
      "name": "Rock_Volcanic"
    },
    {
      "x": -28,
      "y": 20,
      "z": 5,
      "name": "Rock_Volcanic"
    },
    {
      "x": -28,
      "y": 21,
      "z": 5,
      "name": "Rock_Volcanic"
    },
    {
      "x": -28,
      "y": 22,
      "z": 5,
      "name": "Rock_Volcanic"
    },
    {
      "x": -28,
      "y": 23,
      "z": 5,
      "name": "Rock_Volcanic"
    },
    {
      "x": -28,
      "y": 24,
      "z": 5,
      "name": "Rock_Volcanic"
    },
    {
      "x": -28,
      "y": 25,
      "z": 5,
      "name": "Rock_Volcanic"
    },
    {
      "x": -28,
      "y": 26,
      "z": 5,
      "name": "Rock_Volcanic"
    },
    {
      "x": -28,
      "y": 27,
      "z": 5,
      "name": "Rock_Volcanic"
    },
    {
      "x": -28,
      "y": 28,
      "z": 5,
      "name": "Rock_Volcanic"
    },
    {
      "x": -28,
      "y": 29,
      "z": 5,
      "name": "Rock_Volcanic"
    },
    {
      "x": -28,
      "y": 30,
      "z": 5,
      "name": "Rock_Volcanic"
    },
    {
      "x": -28,
      "y": 31,
      "z": 5,
      "name": "Rock_Volcanic"
    },
    {
      "x": -28,
      "y": 32,
      "z": 5,
      "name": "Rock_Volcanic"
    },
    {
      "x": -28,
      "y": 33,
      "z": 5,
      "name": "Rock_Volcanic"
    },
    {
      "x": -28,
      "y": 34,
      "z": 5,
      "name": "Rock_Volcanic"
    },
    {
      "x": -28,
      "y": 13,
      "z": 6,
      "name": "Rock_Volcanic"
    },
    {
      "x": -28,
      "y": 14,
      "z": 6,
      "name": "Rock_Volcanic"
    },
    {
      "x": -28,
      "y": 15,
      "z": 6,
      "name": "Rock_Volcanic"
    },
    {
      "x": -28,
      "y": 16,
      "z": 6,
      "name": "Rock_Volcanic"
    },
    {
      "x": -28,
      "y": 17,
      "z": 6,
      "name": "Rock_Volcanic"
    },
    {
      "x": -28,
      "y": 18,
      "z": 6,
      "name": "Rock_Volcanic"
    },
    {
      "x": -28,
      "y": 19,
      "z": 6,
      "name": "Rock_Volcanic"
    },
    {
      "x": -28,
      "y": 20,
      "z": 6,
      "name": "Rock_Volcanic"
    },
    {
      "x": -28,
      "y": 21,
      "z": 6,
      "name": "Rock_Volcanic"
    },
    {
      "x": -28,
      "y": 22,
      "z": 6,
      "name": "Rock_Volcanic"
    },
    {
      "x": -28,
      "y": 23,
      "z": 6,
      "name": "Rock_Volcanic"
    },
    {
      "x": -28,
      "y": 24,
      "z": 6,
      "name": "Rock_Volcanic"
    },
    {
      "x": -28,
      "y": 25,
      "z": 6,
      "name": "Rock_Volcanic"
    },
    {
      "x": -28,
      "y": 26,
      "z": 6,
      "name": "Rock_Volcanic"
    },
    {
      "x": -28,
      "y": 27,
      "z": 6,
      "name": "Rock_Volcanic"
    },
    {
      "x": -28,
      "y": 28,
      "z": 6,
      "name": "Rock_Volcanic"
    },
    {
      "x": -28,
      "y": 29,
      "z": 6,
      "name": "Rock_Volcanic"
    },
    {
      "x": -28,
      "y": 30,
      "z": 6,
      "name": "Rock_Volcanic"
    },
    {
      "x": -28,
      "y": 31,
      "z": 6,
      "name": "Rock_Volcanic"
    },
    {
      "x": -28,
      "y": 17,
      "z": 7,
      "name": "Rock_Volcanic"
    },
    {
      "x": -28,
      "y": 18,
      "z": 7,
      "name": "Rock_Volcanic"
    },
    {
      "x": -28,
      "y": 19,
      "z": 7,
      "name": "Rock_Volcanic"
    },
    {
      "x": -28,
      "y": 20,
      "z": 7,
      "name": "Rock_Volcanic"
    },
    {
      "x": -28,
      "y": 21,
      "z": 7,
      "name": "Rock_Volcanic"
    },
    {
      "x": -28,
      "y": 22,
      "z": 7,
      "name": "Rock_Volcanic"
    },
    {
      "x": -27,
      "y": 13,
      "z": -2,
      "name": "Rock_Volcanic"
    },
    {
      "x": -27,
      "y": 14,
      "z": -2,
      "name": "Rock_Volcanic"
    },
    {
      "x": -27,
      "y": 15,
      "z": -2,
      "name": "Rock_Volcanic"
    },
    {
      "x": -27,
      "y": 16,
      "z": -2,
      "name": "Rock_Volcanic"
    },
    {
      "x": -27,
      "y": 17,
      "z": -2,
      "name": "Rock_Volcanic"
    },
    {
      "x": -27,
      "y": 18,
      "z": -2,
      "name": "Rock_Volcanic"
    },
    {
      "x": -27,
      "y": 19,
      "z": -2,
      "name": "Rock_Volcanic"
    },
    {
      "x": -27,
      "y": 20,
      "z": -2,
      "name": "Rock_Volcanic"
    },
    {
      "x": -27,
      "y": 21,
      "z": -2,
      "name": "Rock_Volcanic"
    },
    {
      "x": -27,
      "y": 22,
      "z": -2,
      "name": "Rock_Volcanic"
    },
    {
      "x": -27,
      "y": 23,
      "z": -2,
      "name": "Rock_Volcanic"
    },
    {
      "x": -27,
      "y": 24,
      "z": -2,
      "name": "Rock_Volcanic"
    },
    {
      "x": -27,
      "y": 25,
      "z": -2,
      "name": "Rock_Volcanic"
    },
    {
      "x": -27,
      "y": 26,
      "z": -2,
      "name": "Rock_Volcanic"
    },
    {
      "x": -27,
      "y": 27,
      "z": -2,
      "name": "Rock_Volcanic"
    },
    {
      "x": -27,
      "y": 28,
      "z": -2,
      "name": "Rock_Volcanic"
    },
    {
      "x": -27,
      "y": 8,
      "z": -1,
      "name": "Rock_Volcanic"
    },
    {
      "x": -27,
      "y": 9,
      "z": -1,
      "name": "Rock_Volcanic"
    },
    {
      "x": -27,
      "y": 10,
      "z": -1,
      "name": "Rock_Volcanic"
    },
    {
      "x": -27,
      "y": 11,
      "z": -1,
      "name": "Rock_Volcanic"
    },
    {
      "x": -27,
      "y": 12,
      "z": -1,
      "name": "Rock_Volcanic"
    },
    {
      "x": -27,
      "y": 13,
      "z": -1,
      "name": "Rock_Volcanic"
    },
    {
      "x": -27,
      "y": 14,
      "z": -1,
      "name": "Rock_Volcanic"
    },
    {
      "x": -27,
      "y": 15,
      "z": -1,
      "name": "Rock_Volcanic"
    },
    {
      "x": -27,
      "y": 16,
      "z": -1,
      "name": "Rock_Volcanic"
    },
    {
      "x": -27,
      "y": 17,
      "z": -1,
      "name": "Rock_Volcanic"
    },
    {
      "x": -27,
      "y": 18,
      "z": -1,
      "name": "Rock_Volcanic"
    },
    {
      "x": -27,
      "y": 19,
      "z": -1,
      "name": "Rock_Volcanic"
    },
    {
      "x": -27,
      "y": 20,
      "z": -1,
      "name": "Rock_Volcanic"
    },
    {
      "x": -27,
      "y": 21,
      "z": -1,
      "name": "Rock_Volcanic"
    },
    {
      "x": -27,
      "y": 22,
      "z": -1,
      "name": "Rock_Volcanic"
    },
    {
      "x": -27,
      "y": 23,
      "z": -1,
      "name": "Rock_Volcanic"
    },
    {
      "x": -27,
      "y": 24,
      "z": -1,
      "name": "Rock_Volcanic"
    },
    {
      "x": -27,
      "y": 25,
      "z": -1,
      "name": "Rock_Volcanic"
    },
    {
      "x": -27,
      "y": 26,
      "z": -1,
      "name": "Rock_Volcanic"
    },
    {
      "x": -27,
      "y": 27,
      "z": -1,
      "name": "Rock_Volcanic"
    },
    {
      "x": -27,
      "y": 28,
      "z": -1,
      "name": "Rock_Volcanic"
    },
    {
      "x": -27,
      "y": 29,
      "z": -1,
      "name": "Rock_Volcanic"
    },
    {
      "x": -27,
      "y": 30,
      "z": -1,
      "name": "Rock_Volcanic"
    },
    {
      "x": -27,
      "y": 31,
      "z": -1,
      "name": "Rock_Volcanic"
    },
    {
      "x": -27,
      "y": 3,
      "z": 0,
      "name": "Rock_Volcanic"
    },
    {
      "x": -27,
      "y": 4,
      "z": 0,
      "name": "Rock_Volcanic"
    },
    {
      "x": -27,
      "y": 5,
      "z": 0,
      "name": "Rock_Volcanic"
    },
    {
      "x": -27,
      "y": 6,
      "z": 0,
      "name": "Rock_Volcanic"
    },
    {
      "x": -27,
      "y": 7,
      "z": 0,
      "name": "Rock_Volcanic"
    },
    {
      "x": -27,
      "y": 8,
      "z": 0,
      "name": "Rock_Volcanic"
    },
    {
      "x": -27,
      "y": 9,
      "z": 0,
      "name": "Rock_Volcanic"
    },
    {
      "x": -27,
      "y": 10,
      "z": 0,
      "name": "Rock_Volcanic"
    },
    {
      "x": -27,
      "y": 11,
      "z": 0,
      "name": "Rock_Volcanic"
    },
    {
      "x": -27,
      "y": 12,
      "z": 0,
      "name": "Rock_Volcanic"
    },
    {
      "x": -27,
      "y": 13,
      "z": 0,
      "name": "Rock_Volcanic"
    },
    {
      "x": -27,
      "y": 14,
      "z": 0,
      "name": "Rock_Volcanic"
    },
    {
      "x": -27,
      "y": 15,
      "z": 0,
      "name": "Rock_Volcanic"
    },
    {
      "x": -27,
      "y": 16,
      "z": 0,
      "name": "Rock_Volcanic"
    },
    {
      "x": -27,
      "y": 17,
      "z": 0,
      "name": "Rock_Volcanic"
    },
    {
      "x": -27,
      "y": 18,
      "z": 0,
      "name": "Rock_Volcanic"
    },
    {
      "x": -27,
      "y": 19,
      "z": 0,
      "name": "Rock_Volcanic"
    },
    {
      "x": -27,
      "y": 20,
      "z": 0,
      "name": "Rock_Volcanic"
    },
    {
      "x": -27,
      "y": 21,
      "z": 0,
      "name": "Rock_Volcanic"
    },
    {
      "x": -27,
      "y": 22,
      "z": 0,
      "name": "Rock_Volcanic"
    },
    {
      "x": -27,
      "y": 23,
      "z": 0,
      "name": "Rock_Volcanic"
    },
    {
      "x": -27,
      "y": 24,
      "z": 0,
      "name": "Rock_Volcanic"
    },
    {
      "x": -27,
      "y": 25,
      "z": 0,
      "name": "Rock_Volcanic"
    },
    {
      "x": -27,
      "y": 26,
      "z": 0,
      "name": "Rock_Volcanic"
    },
    {
      "x": -27,
      "y": 27,
      "z": 0,
      "name": "Rock_Volcanic"
    },
    {
      "x": -27,
      "y": 28,
      "z": 0,
      "name": "Rock_Volcanic"
    },
    {
      "x": -27,
      "y": 29,
      "z": 0,
      "name": "Rock_Volcanic"
    },
    {
      "x": -27,
      "y": 30,
      "z": 0,
      "name": "Rock_Volcanic"
    },
    {
      "x": -27,
      "y": 31,
      "z": 0,
      "name": "Rock_Volcanic"
    },
    {
      "x": -27,
      "y": 32,
      "z": 0,
      "name": "Rock_Volcanic"
    },
    {
      "x": -27,
      "y": 33,
      "z": 0,
      "name": "Rock_Volcanic"
    },
    {
      "x": -27,
      "y": 34,
      "z": 0,
      "name": "Rock_Volcanic"
    },
    {
      "x": -27,
      "y": 0,
      "z": 1,
      "name": "Rock_Volcanic"
    },
    {
      "x": -27,
      "y": 1,
      "z": 1,
      "name": "Rock_Volcanic"
    },
    {
      "x": -27,
      "y": 2,
      "z": 1,
      "name": "Rock_Volcanic"
    },
    {
      "x": -27,
      "y": 3,
      "z": 1,
      "name": "Rock_Volcanic"
    },
    {
      "x": -27,
      "y": 4,
      "z": 1,
      "name": "Rock_Volcanic"
    },
    {
      "x": -27,
      "y": 5,
      "z": 1,
      "name": "Rock_Volcanic"
    },
    {
      "x": -27,
      "y": 6,
      "z": 1,
      "name": "Rock_Volcanic"
    },
    {
      "x": -27,
      "y": 7,
      "z": 1,
      "name": "Rock_Volcanic"
    },
    {
      "x": -27,
      "y": 8,
      "z": 1,
      "name": "Rock_Volcanic"
    },
    {
      "x": -27,
      "y": 9,
      "z": 1,
      "name": "Rock_Volcanic"
    },
    {
      "x": -27,
      "y": 10,
      "z": 1,
      "name": "Rock_Volcanic"
    },
    {
      "x": -27,
      "y": 11,
      "z": 1,
      "name": "Rock_Volcanic"
    },
    {
      "x": -27,
      "y": 12,
      "z": 1,
      "name": "Rock_Volcanic"
    },
    {
      "x": -27,
      "y": 13,
      "z": 1,
      "name": "Rock_Volcanic"
    },
    {
      "x": -27,
      "y": 14,
      "z": 1,
      "name": "Rock_Volcanic"
    },
    {
      "x": -27,
      "y": 15,
      "z": 1,
      "name": "Rock_Volcanic"
    },
    {
      "x": -27,
      "y": 16,
      "z": 1,
      "name": "Rock_Volcanic"
    },
    {
      "x": -27,
      "y": 17,
      "z": 1,
      "name": "Rock_Volcanic"
    },
    {
      "x": -27,
      "y": 18,
      "z": 1,
      "name": "Rock_Volcanic"
    },
    {
      "x": -27,
      "y": 19,
      "z": 1,
      "name": "Rock_Volcanic"
    },
    {
      "x": -27,
      "y": 20,
      "z": 1,
      "name": "Rock_Volcanic"
    },
    {
      "x": -27,
      "y": 21,
      "z": 1,
      "name": "Rock_Volcanic"
    },
    {
      "x": -27,
      "y": 22,
      "z": 1,
      "name": "Rock_Volcanic"
    },
    {
      "x": -27,
      "y": 23,
      "z": 1,
      "name": "Rock_Volcanic"
    },
    {
      "x": -27,
      "y": 24,
      "z": 1,
      "name": "Rock_Volcanic"
    },
    {
      "x": -27,
      "y": 25,
      "z": 1,
      "name": "Rock_Volcanic"
    },
    {
      "x": -27,
      "y": 26,
      "z": 1,
      "name": "Rock_Volcanic"
    },
    {
      "x": -27,
      "y": 27,
      "z": 1,
      "name": "Rock_Volcanic"
    },
    {
      "x": -27,
      "y": 28,
      "z": 1,
      "name": "Rock_Volcanic"
    },
    {
      "x": -27,
      "y": 29,
      "z": 1,
      "name": "Rock_Volcanic"
    },
    {
      "x": -27,
      "y": 30,
      "z": 1,
      "name": "Rock_Volcanic"
    },
    {
      "x": -27,
      "y": 31,
      "z": 1,
      "name": "Rock_Volcanic"
    },
    {
      "x": -27,
      "y": 32,
      "z": 1,
      "name": "Rock_Volcanic_Cracked_Lava"
    },
    {
      "x": -27,
      "y": 33,
      "z": 1,
      "name": "Rock_Volcanic"
    },
    {
      "x": -27,
      "y": 34,
      "z": 1,
      "name": "Rock_Volcanic_Cracked_Lava"
    },
    {
      "x": -27,
      "y": 35,
      "z": 1,
      "name": "Rock_Volcanic"
    },
    {
      "x": -27,
      "y": 0,
      "z": 2,
      "name": "Rock_Volcanic"
    },
    {
      "x": -27,
      "y": 1,
      "z": 2,
      "name": "Rock_Volcanic"
    },
    {
      "x": -27,
      "y": 2,
      "z": 2,
      "name": "Rock_Volcanic"
    },
    {
      "x": -27,
      "y": 3,
      "z": 2,
      "name": "Rock_Volcanic"
    },
    {
      "x": -27,
      "y": 4,
      "z": 2,
      "name": "Rock_Volcanic"
    },
    {
      "x": -27,
      "y": 5,
      "z": 2,
      "name": "Rock_Volcanic"
    },
    {
      "x": -27,
      "y": 6,
      "z": 2,
      "name": "Rock_Volcanic"
    },
    {
      "x": -27,
      "y": 7,
      "z": 2,
      "name": "Rock_Volcanic"
    },
    {
      "x": -27,
      "y": 8,
      "z": 2,
      "name": "Rock_Volcanic"
    },
    {
      "x": -27,
      "y": 9,
      "z": 2,
      "name": "Rock_Volcanic"
    },
    {
      "x": -27,
      "y": 10,
      "z": 2,
      "name": "Rock_Volcanic"
    },
    {
      "x": -27,
      "y": 11,
      "z": 2,
      "name": "Rock_Volcanic"
    },
    {
      "x": -27,
      "y": 12,
      "z": 2,
      "name": "Rock_Volcanic"
    },
    {
      "x": -27,
      "y": 13,
      "z": 2,
      "name": "Rock_Volcanic"
    },
    {
      "x": -27,
      "y": 14,
      "z": 2,
      "name": "Rock_Volcanic"
    },
    {
      "x": -27,
      "y": 15,
      "z": 2,
      "name": "Rock_Volcanic"
    },
    {
      "x": -27,
      "y": 16,
      "z": 2,
      "name": "Rock_Volcanic"
    },
    {
      "x": -27,
      "y": 17,
      "z": 2,
      "name": "Rock_Volcanic"
    },
    {
      "x": -27,
      "y": 18,
      "z": 2,
      "name": "Rock_Volcanic"
    },
    {
      "x": -27,
      "y": 19,
      "z": 2,
      "name": "Rock_Volcanic"
    },
    {
      "x": -27,
      "y": 20,
      "z": 2,
      "name": "Rock_Volcanic"
    },
    {
      "x": -27,
      "y": 21,
      "z": 2,
      "name": "Rock_Volcanic"
    },
    {
      "x": -27,
      "y": 22,
      "z": 2,
      "name": "Rock_Volcanic"
    },
    {
      "x": -27,
      "y": 23,
      "z": 2,
      "name": "Rock_Volcanic"
    },
    {
      "x": -27,
      "y": 24,
      "z": 2,
      "name": "Rock_Volcanic"
    },
    {
      "x": -27,
      "y": 25,
      "z": 2,
      "name": "Rock_Volcanic"
    },
    {
      "x": -27,
      "y": 26,
      "z": 2,
      "name": "Rock_Volcanic"
    },
    {
      "x": -27,
      "y": 27,
      "z": 2,
      "name": "Rock_Volcanic"
    },
    {
      "x": -27,
      "y": 28,
      "z": 2,
      "name": "Rock_Volcanic"
    },
    {
      "x": -27,
      "y": 29,
      "z": 2,
      "name": "Rock_Volcanic"
    },
    {
      "x": -27,
      "y": 30,
      "z": 2,
      "name": "Rock_Volcanic"
    },
    {
      "x": -27,
      "y": 31,
      "z": 2,
      "name": "Rock_Volcanic"
    },
    {
      "x": -27,
      "y": 32,
      "z": 2,
      "name": "Rock_Volcanic_Cracked_Lava"
    },
    {
      "x": -27,
      "y": 33,
      "z": 2,
      "name": "Rock_Volcanic"
    },
    {
      "x": -27,
      "y": 34,
      "z": 2,
      "name": "Rock_Volcanic_Cracked_Lava"
    },
    {
      "x": -27,
      "y": 35,
      "z": 2,
      "name": "Rock_Volcanic"
    },
    {
      "x": -27,
      "y": 0,
      "z": 3,
      "name": "Rock_Volcanic"
    },
    {
      "x": -27,
      "y": 1,
      "z": 3,
      "name": "Rock_Volcanic"
    },
    {
      "x": -27,
      "y": 2,
      "z": 3,
      "name": "Rock_Volcanic"
    },
    {
      "x": -27,
      "y": 3,
      "z": 3,
      "name": "Rock_Volcanic"
    },
    {
      "x": -27,
      "y": 4,
      "z": 3,
      "name": "Rock_Volcanic"
    },
    {
      "x": -27,
      "y": 5,
      "z": 3,
      "name": "Rock_Volcanic"
    },
    {
      "x": -27,
      "y": 6,
      "z": 3,
      "name": "Rock_Volcanic"
    },
    {
      "x": -27,
      "y": 7,
      "z": 3,
      "name": "Rock_Volcanic"
    },
    {
      "x": -27,
      "y": 8,
      "z": 3,
      "name": "Rock_Volcanic"
    },
    {
      "x": -27,
      "y": 9,
      "z": 3,
      "name": "Rock_Volcanic"
    },
    {
      "x": -27,
      "y": 10,
      "z": 3,
      "name": "Rock_Volcanic"
    },
    {
      "x": -27,
      "y": 11,
      "z": 3,
      "name": "Rock_Volcanic"
    },
    {
      "x": -27,
      "y": 12,
      "z": 3,
      "name": "Rock_Volcanic"
    },
    {
      "x": -27,
      "y": 13,
      "z": 3,
      "name": "Rock_Volcanic"
    },
    {
      "x": -27,
      "y": 14,
      "z": 3,
      "name": "Rock_Volcanic"
    },
    {
      "x": -27,
      "y": 15,
      "z": 3,
      "name": "Rock_Volcanic"
    },
    {
      "x": -27,
      "y": 16,
      "z": 3,
      "name": "Rock_Volcanic"
    },
    {
      "x": -27,
      "y": 17,
      "z": 3,
      "name": "Rock_Volcanic"
    },
    {
      "x": -27,
      "y": 18,
      "z": 3,
      "name": "Rock_Volcanic"
    },
    {
      "x": -27,
      "y": 19,
      "z": 3,
      "name": "Rock_Volcanic"
    },
    {
      "x": -27,
      "y": 20,
      "z": 3,
      "name": "Rock_Volcanic"
    },
    {
      "x": -27,
      "y": 21,
      "z": 3,
      "name": "Rock_Volcanic"
    },
    {
      "x": -27,
      "y": 22,
      "z": 3,
      "name": "Rock_Volcanic"
    },
    {
      "x": -27,
      "y": 23,
      "z": 3,
      "name": "Rock_Volcanic"
    },
    {
      "x": -27,
      "y": 24,
      "z": 3,
      "name": "Rock_Volcanic"
    },
    {
      "x": -27,
      "y": 25,
      "z": 3,
      "name": "Rock_Volcanic"
    },
    {
      "x": -27,
      "y": 26,
      "z": 3,
      "name": "Rock_Volcanic"
    },
    {
      "x": -27,
      "y": 27,
      "z": 3,
      "name": "Rock_Volcanic"
    },
    {
      "x": -27,
      "y": 28,
      "z": 3,
      "name": "Rock_Volcanic"
    },
    {
      "x": -27,
      "y": 29,
      "z": 3,
      "name": "Rock_Volcanic"
    },
    {
      "x": -27,
      "y": 30,
      "z": 3,
      "name": "Rock_Volcanic"
    },
    {
      "x": -27,
      "y": 31,
      "z": 3,
      "name": "Rock_Volcanic"
    },
    {
      "x": -27,
      "y": 32,
      "z": 3,
      "name": "Rock_Volcanic"
    },
    {
      "x": -27,
      "y": 33,
      "z": 3,
      "name": "Rock_Volcanic"
    },
    {
      "x": -27,
      "y": 34,
      "z": 3,
      "name": "Rock_Volcanic"
    },
    {
      "x": -27,
      "y": 35,
      "z": 3,
      "name": "Rock_Volcanic"
    },
    {
      "x": -27,
      "y": 36,
      "z": 3,
      "name": "Rock_Volcanic"
    },
    {
      "x": -27,
      "y": 0,
      "z": 4,
      "name": "Rock_Volcanic"
    },
    {
      "x": -27,
      "y": 1,
      "z": 4,
      "name": "Rock_Volcanic"
    },
    {
      "x": -27,
      "y": 2,
      "z": 4,
      "name": "Rock_Volcanic"
    },
    {
      "x": -27,
      "y": 3,
      "z": 4,
      "name": "Rock_Volcanic"
    },
    {
      "x": -27,
      "y": 4,
      "z": 4,
      "name": "Rock_Volcanic"
    },
    {
      "x": -27,
      "y": 5,
      "z": 4,
      "name": "Rock_Volcanic"
    },
    {
      "x": -27,
      "y": 6,
      "z": 4,
      "name": "Rock_Volcanic"
    },
    {
      "x": -27,
      "y": 7,
      "z": 4,
      "name": "Rock_Volcanic"
    },
    {
      "x": -27,
      "y": 8,
      "z": 4,
      "name": "Rock_Volcanic"
    },
    {
      "x": -27,
      "y": 9,
      "z": 4,
      "name": "Rock_Volcanic"
    },
    {
      "x": -27,
      "y": 10,
      "z": 4,
      "name": "Rock_Volcanic"
    },
    {
      "x": -27,
      "y": 11,
      "z": 4,
      "name": "Rock_Volcanic"
    },
    {
      "x": -27,
      "y": 12,
      "z": 4,
      "name": "Rock_Volcanic"
    },
    {
      "x": -27,
      "y": 13,
      "z": 4,
      "name": "Rock_Volcanic"
    },
    {
      "x": -27,
      "y": 14,
      "z": 4,
      "name": "Rock_Volcanic"
    },
    {
      "x": -27,
      "y": 15,
      "z": 4,
      "name": "Rock_Volcanic"
    },
    {
      "x": -27,
      "y": 16,
      "z": 4,
      "name": "Rock_Volcanic"
    },
    {
      "x": -27,
      "y": 17,
      "z": 4,
      "name": "Rock_Volcanic"
    },
    {
      "x": -27,
      "y": 18,
      "z": 4,
      "name": "Rock_Volcanic"
    },
    {
      "x": -27,
      "y": 19,
      "z": 4,
      "name": "Rock_Volcanic"
    },
    {
      "x": -27,
      "y": 20,
      "z": 4,
      "name": "Rock_Volcanic"
    },
    {
      "x": -27,
      "y": 21,
      "z": 4,
      "name": "Rock_Volcanic"
    },
    {
      "x": -27,
      "y": 22,
      "z": 4,
      "name": "Rock_Volcanic"
    },
    {
      "x": -27,
      "y": 23,
      "z": 4,
      "name": "Rock_Volcanic"
    },
    {
      "x": -27,
      "y": 24,
      "z": 4,
      "name": "Rock_Volcanic"
    },
    {
      "x": -27,
      "y": 25,
      "z": 4,
      "name": "Rock_Volcanic"
    },
    {
      "x": -27,
      "y": 26,
      "z": 4,
      "name": "Rock_Volcanic"
    },
    {
      "x": -27,
      "y": 27,
      "z": 4,
      "name": "Rock_Volcanic"
    },
    {
      "x": -27,
      "y": 28,
      "z": 4,
      "name": "Rock_Volcanic"
    },
    {
      "x": -27,
      "y": 29,
      "z": 4,
      "name": "Rock_Volcanic"
    },
    {
      "x": -27,
      "y": 30,
      "z": 4,
      "name": "Rock_Volcanic"
    },
    {
      "x": -27,
      "y": 31,
      "z": 4,
      "name": "Rock_Volcanic"
    },
    {
      "x": -27,
      "y": 32,
      "z": 4,
      "name": "Rock_Volcanic"
    },
    {
      "x": -27,
      "y": 33,
      "z": 4,
      "name": "Rock_Volcanic"
    },
    {
      "x": -27,
      "y": 34,
      "z": 4,
      "name": "Rock_Volcanic"
    },
    {
      "x": -27,
      "y": 35,
      "z": 4,
      "name": "Rock_Volcanic"
    },
    {
      "x": -27,
      "y": 0,
      "z": 5,
      "name": "Rock_Volcanic"
    },
    {
      "x": -27,
      "y": 1,
      "z": 5,
      "name": "Rock_Volcanic"
    },
    {
      "x": -27,
      "y": 2,
      "z": 5,
      "name": "Rock_Volcanic"
    },
    {
      "x": -27,
      "y": 3,
      "z": 5,
      "name": "Rock_Volcanic"
    },
    {
      "x": -27,
      "y": 4,
      "z": 5,
      "name": "Rock_Volcanic"
    },
    {
      "x": -27,
      "y": 5,
      "z": 5,
      "name": "Rock_Volcanic"
    },
    {
      "x": -27,
      "y": 6,
      "z": 5,
      "name": "Rock_Volcanic"
    },
    {
      "x": -27,
      "y": 7,
      "z": 5,
      "name": "Rock_Volcanic"
    },
    {
      "x": -27,
      "y": 8,
      "z": 5,
      "name": "Rock_Volcanic"
    },
    {
      "x": -27,
      "y": 9,
      "z": 5,
      "name": "Rock_Volcanic"
    },
    {
      "x": -27,
      "y": 10,
      "z": 5,
      "name": "Rock_Volcanic"
    },
    {
      "x": -27,
      "y": 11,
      "z": 5,
      "name": "Rock_Volcanic"
    },
    {
      "x": -27,
      "y": 12,
      "z": 5,
      "name": "Rock_Volcanic"
    },
    {
      "x": -27,
      "y": 13,
      "z": 5,
      "name": "Rock_Volcanic"
    },
    {
      "x": -27,
      "y": 14,
      "z": 5,
      "name": "Rock_Volcanic"
    },
    {
      "x": -27,
      "y": 15,
      "z": 5,
      "name": "Rock_Volcanic"
    },
    {
      "x": -27,
      "y": 16,
      "z": 5,
      "name": "Rock_Volcanic"
    },
    {
      "x": -27,
      "y": 17,
      "z": 5,
      "name": "Rock_Volcanic"
    },
    {
      "x": -27,
      "y": 18,
      "z": 5,
      "name": "Rock_Volcanic"
    },
    {
      "x": -27,
      "y": 19,
      "z": 5,
      "name": "Rock_Volcanic"
    },
    {
      "x": -27,
      "y": 20,
      "z": 5,
      "name": "Rock_Volcanic"
    },
    {
      "x": -27,
      "y": 21,
      "z": 5,
      "name": "Rock_Volcanic"
    },
    {
      "x": -27,
      "y": 22,
      "z": 5,
      "name": "Rock_Volcanic"
    },
    {
      "x": -27,
      "y": 23,
      "z": 5,
      "name": "Rock_Volcanic"
    },
    {
      "x": -27,
      "y": 24,
      "z": 5,
      "name": "Rock_Volcanic"
    },
    {
      "x": -27,
      "y": 25,
      "z": 5,
      "name": "Rock_Volcanic"
    },
    {
      "x": -27,
      "y": 26,
      "z": 5,
      "name": "Rock_Volcanic"
    },
    {
      "x": -27,
      "y": 27,
      "z": 5,
      "name": "Rock_Volcanic"
    },
    {
      "x": -27,
      "y": 28,
      "z": 5,
      "name": "Rock_Volcanic"
    },
    {
      "x": -27,
      "y": 29,
      "z": 5,
      "name": "Rock_Volcanic"
    },
    {
      "x": -27,
      "y": 30,
      "z": 5,
      "name": "Rock_Volcanic"
    },
    {
      "x": -27,
      "y": 31,
      "z": 5,
      "name": "Rock_Volcanic"
    },
    {
      "x": -27,
      "y": 32,
      "z": 5,
      "name": "Rock_Volcanic"
    },
    {
      "x": -27,
      "y": 33,
      "z": 5,
      "name": "Rock_Volcanic"
    },
    {
      "x": -27,
      "y": 6,
      "z": 6,
      "name": "Rock_Volcanic"
    },
    {
      "x": -27,
      "y": 7,
      "z": 6,
      "name": "Rock_Volcanic"
    },
    {
      "x": -27,
      "y": 8,
      "z": 6,
      "name": "Rock_Volcanic"
    },
    {
      "x": -27,
      "y": 9,
      "z": 6,
      "name": "Rock_Volcanic"
    },
    {
      "x": -27,
      "y": 10,
      "z": 6,
      "name": "Rock_Volcanic"
    },
    {
      "x": -27,
      "y": 11,
      "z": 6,
      "name": "Rock_Volcanic"
    },
    {
      "x": -27,
      "y": 12,
      "z": 6,
      "name": "Rock_Volcanic"
    },
    {
      "x": -27,
      "y": 13,
      "z": 6,
      "name": "Rock_Volcanic"
    },
    {
      "x": -27,
      "y": 14,
      "z": 6,
      "name": "Rock_Volcanic"
    },
    {
      "x": -27,
      "y": 15,
      "z": 6,
      "name": "Rock_Volcanic"
    },
    {
      "x": -27,
      "y": 16,
      "z": 6,
      "name": "Rock_Volcanic"
    },
    {
      "x": -27,
      "y": 17,
      "z": 6,
      "name": "Rock_Volcanic"
    },
    {
      "x": -27,
      "y": 18,
      "z": 6,
      "name": "Rock_Volcanic"
    },
    {
      "x": -27,
      "y": 19,
      "z": 6,
      "name": "Rock_Volcanic"
    },
    {
      "x": -27,
      "y": 20,
      "z": 6,
      "name": "Rock_Volcanic"
    },
    {
      "x": -27,
      "y": 21,
      "z": 6,
      "name": "Rock_Volcanic"
    },
    {
      "x": -27,
      "y": 22,
      "z": 6,
      "name": "Rock_Volcanic"
    },
    {
      "x": -27,
      "y": 23,
      "z": 6,
      "name": "Rock_Volcanic"
    },
    {
      "x": -27,
      "y": 24,
      "z": 6,
      "name": "Rock_Volcanic"
    },
    {
      "x": -27,
      "y": 25,
      "z": 6,
      "name": "Rock_Volcanic"
    },
    {
      "x": -27,
      "y": 26,
      "z": 6,
      "name": "Rock_Volcanic"
    },
    {
      "x": -27,
      "y": 27,
      "z": 6,
      "name": "Rock_Volcanic"
    },
    {
      "x": -27,
      "y": 28,
      "z": 6,
      "name": "Rock_Volcanic"
    },
    {
      "x": -27,
      "y": 29,
      "z": 6,
      "name": "Rock_Volcanic"
    },
    {
      "x": -27,
      "y": 30,
      "z": 6,
      "name": "Rock_Volcanic"
    },
    {
      "x": -27,
      "y": 31,
      "z": 6,
      "name": "Rock_Volcanic"
    },
    {
      "x": -27,
      "y": 15,
      "z": 7,
      "name": "Rock_Volcanic"
    },
    {
      "x": -27,
      "y": 16,
      "z": 7,
      "name": "Rock_Volcanic"
    },
    {
      "x": -27,
      "y": 17,
      "z": 7,
      "name": "Rock_Volcanic"
    },
    {
      "x": -27,
      "y": 18,
      "z": 7,
      "name": "Rock_Volcanic"
    },
    {
      "x": -27,
      "y": 19,
      "z": 7,
      "name": "Rock_Volcanic"
    },
    {
      "x": -27,
      "y": 20,
      "z": 7,
      "name": "Rock_Volcanic"
    },
    {
      "x": -27,
      "y": 21,
      "z": 7,
      "name": "Rock_Volcanic"
    },
    {
      "x": -27,
      "y": 22,
      "z": 7,
      "name": "Rock_Volcanic"
    },
    {
      "x": -27,
      "y": 23,
      "z": 7,
      "name": "Rock_Volcanic"
    },
    {
      "x": -27,
      "y": 24,
      "z": 7,
      "name": "Rock_Volcanic"
    },
    {
      "x": -27,
      "y": 25,
      "z": 7,
      "name": "Rock_Volcanic"
    },
    {
      "x": -27,
      "y": 26,
      "z": 7,
      "name": "Rock_Volcanic"
    },
    {
      "x": -27,
      "y": 27,
      "z": 7,
      "name": "Rock_Volcanic"
    },
    {
      "x": -27,
      "y": 28,
      "z": 7,
      "name": "Rock_Volcanic"
    },
    {
      "x": -27,
      "y": 29,
      "z": 7,
      "name": "Rock_Volcanic"
    },
    {
      "x": -26,
      "y": 37,
      "z": -24,
      "name": "Rock_Volcanic"
    },
    {
      "x": -26,
      "y": 38,
      "z": -24,
      "name": "Rock_Volcanic"
    },
    {
      "x": -26,
      "y": 39,
      "z": -24,
      "name": "Rock_Volcanic"
    },
    {
      "x": -26,
      "y": 40,
      "z": -24,
      "name": "Rock_Volcanic"
    },
    {
      "x": -26,
      "y": 35,
      "z": -23,
      "name": "Rock_Volcanic"
    },
    {
      "x": -26,
      "y": 36,
      "z": -23,
      "name": "Rock_Volcanic"
    },
    {
      "x": -26,
      "y": 37,
      "z": -23,
      "name": "Rock_Volcanic"
    },
    {
      "x": -26,
      "y": 38,
      "z": -23,
      "name": "Rock_Volcanic"
    },
    {
      "x": -26,
      "y": 39,
      "z": -23,
      "name": "Rock_Volcanic"
    },
    {
      "x": -26,
      "y": 13,
      "z": -3,
      "name": "Rock_Volcanic"
    },
    {
      "x": -26,
      "y": 14,
      "z": -3,
      "name": "Rock_Volcanic"
    },
    {
      "x": -26,
      "y": 15,
      "z": -3,
      "name": "Rock_Volcanic"
    },
    {
      "x": -26,
      "y": 16,
      "z": -3,
      "name": "Rock_Volcanic"
    },
    {
      "x": -26,
      "y": 17,
      "z": -3,
      "name": "Rock_Volcanic"
    },
    {
      "x": -26,
      "y": 18,
      "z": -3,
      "name": "Rock_Volcanic"
    },
    {
      "x": -26,
      "y": 19,
      "z": -3,
      "name": "Rock_Volcanic"
    },
    {
      "x": -26,
      "y": 20,
      "z": -3,
      "name": "Rock_Volcanic"
    },
    {
      "x": -26,
      "y": 21,
      "z": -3,
      "name": "Rock_Volcanic"
    },
    {
      "x": -26,
      "y": 22,
      "z": -3,
      "name": "Rock_Volcanic"
    },
    {
      "x": -26,
      "y": 23,
      "z": -3,
      "name": "Rock_Volcanic"
    },
    {
      "x": -26,
      "y": 24,
      "z": -3,
      "name": "Rock_Volcanic"
    },
    {
      "x": -26,
      "y": 10,
      "z": -2,
      "name": "Rock_Volcanic"
    },
    {
      "x": -26,
      "y": 11,
      "z": -2,
      "name": "Rock_Volcanic"
    },
    {
      "x": -26,
      "y": 12,
      "z": -2,
      "name": "Rock_Volcanic"
    },
    {
      "x": -26,
      "y": 13,
      "z": -2,
      "name": "Rock_Volcanic"
    },
    {
      "x": -26,
      "y": 14,
      "z": -2,
      "name": "Rock_Volcanic"
    },
    {
      "x": -26,
      "y": 15,
      "z": -2,
      "name": "Rock_Volcanic"
    },
    {
      "x": -26,
      "y": 16,
      "z": -2,
      "name": "Rock_Volcanic"
    },
    {
      "x": -26,
      "y": 17,
      "z": -2,
      "name": "Rock_Volcanic"
    },
    {
      "x": -26,
      "y": 18,
      "z": -2,
      "name": "Rock_Volcanic"
    },
    {
      "x": -26,
      "y": 19,
      "z": -2,
      "name": "Rock_Volcanic"
    },
    {
      "x": -26,
      "y": 20,
      "z": -2,
      "name": "Rock_Volcanic"
    },
    {
      "x": -26,
      "y": 21,
      "z": -2,
      "name": "Rock_Volcanic"
    },
    {
      "x": -26,
      "y": 22,
      "z": -2,
      "name": "Rock_Volcanic"
    },
    {
      "x": -26,
      "y": 23,
      "z": -2,
      "name": "Rock_Volcanic"
    },
    {
      "x": -26,
      "y": 24,
      "z": -2,
      "name": "Rock_Volcanic"
    },
    {
      "x": -26,
      "y": 25,
      "z": -2,
      "name": "Rock_Volcanic"
    },
    {
      "x": -26,
      "y": 26,
      "z": -2,
      "name": "Rock_Volcanic"
    },
    {
      "x": -26,
      "y": 27,
      "z": -2,
      "name": "Rock_Volcanic"
    },
    {
      "x": -26,
      "y": 2,
      "z": -1,
      "name": "Rock_Volcanic"
    },
    {
      "x": -26,
      "y": 3,
      "z": -1,
      "name": "Rock_Volcanic"
    },
    {
      "x": -26,
      "y": 4,
      "z": -1,
      "name": "Rock_Volcanic"
    },
    {
      "x": -26,
      "y": 5,
      "z": -1,
      "name": "Rock_Volcanic"
    },
    {
      "x": -26,
      "y": 6,
      "z": -1,
      "name": "Rock_Volcanic"
    },
    {
      "x": -26,
      "y": 7,
      "z": -1,
      "name": "Rock_Volcanic"
    },
    {
      "x": -26,
      "y": 8,
      "z": -1,
      "name": "Rock_Volcanic"
    },
    {
      "x": -26,
      "y": 9,
      "z": -1,
      "name": "Rock_Volcanic"
    },
    {
      "x": -26,
      "y": 10,
      "z": -1,
      "name": "Rock_Volcanic"
    },
    {
      "x": -26,
      "y": 11,
      "z": -1,
      "name": "Rock_Volcanic"
    },
    {
      "x": -26,
      "y": 12,
      "z": -1,
      "name": "Rock_Volcanic"
    },
    {
      "x": -26,
      "y": 13,
      "z": -1,
      "name": "Rock_Volcanic"
    },
    {
      "x": -26,
      "y": 14,
      "z": -1,
      "name": "Rock_Volcanic"
    },
    {
      "x": -26,
      "y": 15,
      "z": -1,
      "name": "Rock_Volcanic"
    },
    {
      "x": -26,
      "y": 16,
      "z": -1,
      "name": "Rock_Volcanic"
    },
    {
      "x": -26,
      "y": 17,
      "z": -1,
      "name": "Rock_Volcanic"
    },
    {
      "x": -26,
      "y": 18,
      "z": -1,
      "name": "Rock_Volcanic"
    },
    {
      "x": -26,
      "y": 19,
      "z": -1,
      "name": "Rock_Volcanic"
    },
    {
      "x": -26,
      "y": 20,
      "z": -1,
      "name": "Rock_Volcanic"
    },
    {
      "x": -26,
      "y": 21,
      "z": -1,
      "name": "Rock_Volcanic"
    },
    {
      "x": -26,
      "y": 22,
      "z": -1,
      "name": "Rock_Volcanic"
    },
    {
      "x": -26,
      "y": 23,
      "z": -1,
      "name": "Rock_Volcanic"
    },
    {
      "x": -26,
      "y": 24,
      "z": -1,
      "name": "Rock_Volcanic"
    },
    {
      "x": -26,
      "y": 25,
      "z": -1,
      "name": "Rock_Volcanic"
    },
    {
      "x": -26,
      "y": 26,
      "z": -1,
      "name": "Rock_Volcanic"
    },
    {
      "x": -26,
      "y": 27,
      "z": -1,
      "name": "Rock_Volcanic"
    },
    {
      "x": -26,
      "y": 28,
      "z": -1,
      "name": "Rock_Volcanic"
    },
    {
      "x": -26,
      "y": 29,
      "z": -1,
      "name": "Rock_Volcanic"
    },
    {
      "x": -26,
      "y": 30,
      "z": -1,
      "name": "Rock_Volcanic"
    },
    {
      "x": -26,
      "y": 0,
      "z": 0,
      "name": "Rock_Volcanic"
    },
    {
      "x": -26,
      "y": 1,
      "z": 0,
      "name": "Rock_Volcanic"
    },
    {
      "x": -26,
      "y": 2,
      "z": 0,
      "name": "Rock_Volcanic"
    },
    {
      "x": -26,
      "y": 3,
      "z": 0,
      "name": "Rock_Volcanic"
    },
    {
      "x": -26,
      "y": 4,
      "z": 0,
      "name": "Rock_Volcanic"
    },
    {
      "x": -26,
      "y": 5,
      "z": 0,
      "name": "Rock_Volcanic"
    },
    {
      "x": -26,
      "y": 6,
      "z": 0,
      "name": "Rock_Volcanic"
    },
    {
      "x": -26,
      "y": 7,
      "z": 0,
      "name": "Rock_Volcanic"
    },
    {
      "x": -26,
      "y": 8,
      "z": 0,
      "name": "Rock_Volcanic"
    },
    {
      "x": -26,
      "y": 9,
      "z": 0,
      "name": "Rock_Volcanic"
    },
    {
      "x": -26,
      "y": 10,
      "z": 0,
      "name": "Rock_Volcanic"
    },
    {
      "x": -26,
      "y": 11,
      "z": 0,
      "name": "Rock_Volcanic"
    },
    {
      "x": -26,
      "y": 12,
      "z": 0,
      "name": "Rock_Volcanic"
    },
    {
      "x": -26,
      "y": 13,
      "z": 0,
      "name": "Rock_Volcanic"
    },
    {
      "x": -26,
      "y": 14,
      "z": 0,
      "name": "Rock_Volcanic"
    },
    {
      "x": -26,
      "y": 15,
      "z": 0,
      "name": "Rock_Volcanic"
    },
    {
      "x": -26,
      "y": 16,
      "z": 0,
      "name": "Rock_Volcanic"
    },
    {
      "x": -26,
      "y": 17,
      "z": 0,
      "name": "Rock_Volcanic"
    },
    {
      "x": -26,
      "y": 18,
      "z": 0,
      "name": "Rock_Volcanic"
    },
    {
      "x": -26,
      "y": 19,
      "z": 0,
      "name": "Rock_Volcanic"
    },
    {
      "x": -26,
      "y": 20,
      "z": 0,
      "name": "Rock_Volcanic"
    },
    {
      "x": -26,
      "y": 21,
      "z": 0,
      "name": "Rock_Volcanic"
    },
    {
      "x": -26,
      "y": 22,
      "z": 0,
      "name": "Rock_Volcanic"
    },
    {
      "x": -26,
      "y": 23,
      "z": 0,
      "name": "Rock_Volcanic"
    },
    {
      "x": -26,
      "y": 24,
      "z": 0,
      "name": "Rock_Volcanic"
    },
    {
      "x": -26,
      "y": 25,
      "z": 0,
      "name": "Rock_Volcanic"
    },
    {
      "x": -26,
      "y": 26,
      "z": 0,
      "name": "Rock_Volcanic"
    },
    {
      "x": -26,
      "y": 27,
      "z": 0,
      "name": "Rock_Volcanic"
    },
    {
      "x": -26,
      "y": 28,
      "z": 0,
      "name": "Rock_Volcanic"
    },
    {
      "x": -26,
      "y": 29,
      "z": 0,
      "name": "Rock_Volcanic"
    },
    {
      "x": -26,
      "y": 30,
      "z": 0,
      "name": "Rock_Volcanic"
    },
    {
      "x": -26,
      "y": 31,
      "z": 0,
      "name": "Rock_Volcanic"
    },
    {
      "x": -26,
      "y": 32,
      "z": 0,
      "name": "Rock_Volcanic"
    },
    {
      "x": -26,
      "y": 33,
      "z": 0,
      "name": "Rock_Volcanic"
    },
    {
      "x": -26,
      "y": 0,
      "z": 1,
      "name": "Rock_Volcanic"
    },
    {
      "x": -26,
      "y": 1,
      "z": 1,
      "name": "Rock_Volcanic"
    },
    {
      "x": -26,
      "y": 2,
      "z": 1,
      "name": "Rock_Volcanic"
    },
    {
      "x": -26,
      "y": 3,
      "z": 1,
      "name": "Rock_Volcanic"
    },
    {
      "x": -26,
      "y": 4,
      "z": 1,
      "name": "Rock_Volcanic"
    },
    {
      "x": -26,
      "y": 5,
      "z": 1,
      "name": "Rock_Volcanic"
    },
    {
      "x": -26,
      "y": 6,
      "z": 1,
      "name": "Rock_Volcanic"
    },
    {
      "x": -26,
      "y": 7,
      "z": 1,
      "name": "Rock_Volcanic"
    },
    {
      "x": -26,
      "y": 8,
      "z": 1,
      "name": "Rock_Volcanic"
    },
    {
      "x": -26,
      "y": 9,
      "z": 1,
      "name": "Rock_Volcanic"
    },
    {
      "x": -26,
      "y": 10,
      "z": 1,
      "name": "Rock_Volcanic"
    },
    {
      "x": -26,
      "y": 11,
      "z": 1,
      "name": "Rock_Volcanic"
    },
    {
      "x": -26,
      "y": 12,
      "z": 1,
      "name": "Rock_Volcanic"
    },
    {
      "x": -26,
      "y": 13,
      "z": 1,
      "name": "Rock_Volcanic"
    },
    {
      "x": -26,
      "y": 14,
      "z": 1,
      "name": "Rock_Volcanic"
    },
    {
      "x": -26,
      "y": 15,
      "z": 1,
      "name": "Rock_Volcanic"
    },
    {
      "x": -26,
      "y": 16,
      "z": 1,
      "name": "Rock_Volcanic"
    },
    {
      "x": -26,
      "y": 17,
      "z": 1,
      "name": "Rock_Volcanic"
    },
    {
      "x": -26,
      "y": 18,
      "z": 1,
      "name": "Rock_Volcanic"
    },
    {
      "x": -26,
      "y": 19,
      "z": 1,
      "name": "Rock_Volcanic"
    },
    {
      "x": -26,
      "y": 20,
      "z": 1,
      "name": "Rock_Volcanic"
    },
    {
      "x": -26,
      "y": 21,
      "z": 1,
      "name": "Rock_Volcanic"
    },
    {
      "x": -26,
      "y": 22,
      "z": 1,
      "name": "Rock_Volcanic"
    },
    {
      "x": -26,
      "y": 23,
      "z": 1,
      "name": "Rock_Volcanic"
    },
    {
      "x": -26,
      "y": 24,
      "z": 1,
      "name": "Rock_Volcanic"
    },
    {
      "x": -26,
      "y": 25,
      "z": 1,
      "name": "Rock_Volcanic"
    },
    {
      "x": -26,
      "y": 26,
      "z": 1,
      "name": "Rock_Volcanic"
    },
    {
      "x": -26,
      "y": 27,
      "z": 1,
      "name": "Rock_Volcanic"
    },
    {
      "x": -26,
      "y": 28,
      "z": 1,
      "name": "Rock_Volcanic"
    },
    {
      "x": -26,
      "y": 29,
      "z": 1,
      "name": "Rock_Volcanic"
    },
    {
      "x": -26,
      "y": 30,
      "z": 1,
      "name": "Rock_Volcanic"
    },
    {
      "x": -26,
      "y": 31,
      "z": 1,
      "name": "Rock_Volcanic_Cracked_Lava"
    },
    {
      "x": -26,
      "y": 32,
      "z": 1,
      "name": "Rock_Volcanic_Cracked_Lava"
    },
    {
      "x": -26,
      "y": 33,
      "z": 1,
      "name": "Rock_Volcanic_Cracked_Lava"
    },
    {
      "x": -26,
      "y": 34,
      "z": 1,
      "name": "Rock_Volcanic"
    },
    {
      "x": -26,
      "y": 35,
      "z": 1,
      "name": "Rock_Volcanic_Cracked_Lava"
    },
    {
      "x": -26,
      "y": 0,
      "z": 2,
      "name": "Rock_Volcanic"
    },
    {
      "x": -26,
      "y": 1,
      "z": 2,
      "name": "Rock_Volcanic"
    },
    {
      "x": -26,
      "y": 2,
      "z": 2,
      "name": "Rock_Volcanic"
    },
    {
      "x": -26,
      "y": 3,
      "z": 2,
      "name": "Rock_Volcanic"
    },
    {
      "x": -26,
      "y": 4,
      "z": 2,
      "name": "Rock_Volcanic"
    },
    {
      "x": -26,
      "y": 5,
      "z": 2,
      "name": "Rock_Volcanic"
    },
    {
      "x": -26,
      "y": 6,
      "z": 2,
      "name": "Rock_Volcanic"
    },
    {
      "x": -26,
      "y": 7,
      "z": 2,
      "name": "Rock_Volcanic"
    },
    {
      "x": -26,
      "y": 8,
      "z": 2,
      "name": "Rock_Volcanic"
    },
    {
      "x": -26,
      "y": 9,
      "z": 2,
      "name": "Rock_Volcanic"
    },
    {
      "x": -26,
      "y": 10,
      "z": 2,
      "name": "Rock_Volcanic"
    },
    {
      "x": -26,
      "y": 11,
      "z": 2,
      "name": "Rock_Volcanic"
    },
    {
      "x": -26,
      "y": 12,
      "z": 2,
      "name": "Rock_Volcanic"
    },
    {
      "x": -26,
      "y": 13,
      "z": 2,
      "name": "Rock_Volcanic"
    },
    {
      "x": -26,
      "y": 14,
      "z": 2,
      "name": "Rock_Volcanic"
    },
    {
      "x": -26,
      "y": 15,
      "z": 2,
      "name": "Rock_Volcanic"
    },
