{
  "version": 8,
  "blockIdVersion": 8,
  "anchorX": 1,
  "anchorY": 3,
  "anchorZ": 0,
  "blocks": [
    {
      "x": -3,
      "y": 3,
      "z": -2,
      "name": "Rock_Volcanic"
    },
    {
      "x": -3,
      "y": 4,
      "z": -2,
      "name": "Rock_Volcanic"
    },
    {
      "x": -3,
      "y": 3,
      "z": -1,
      "name": "Rock_Volcanic"
    },
    {
      "x": -3,
      "y": 4,
      "z": -1,
      "name": "Rock_Volcanic"
    },
    {
      "x": -2,
      "y": 2,
      "z": -3,
      "name": "Rock_Volcanic"
    },
    {
      "x": -2,
      "y": 3,
      "z": -3,
      "name": "Rock_Volcanic"
    },
    {
      "x": -2,
      "y": 4,
      "z": -3,
      "name": "Rock_Volcanic"
    },
    {
      "x": -2,
      "y": 2,
      "z": -2,
      "name": "Rock_Volcanic"
    },
    {
      "x": -2,
      "y": 3,
      "z": -2,
      "name": "Rock_Volcanic"
    },
    {
      "x": -2,
      "y": 4,
      "z": -2,
      "name": "Rock_Volcanic"
    },
    {
      "x": -2,
      "y": 2,
      "z": -1,
      "name": "Rock_Volcanic_Cracked_Lava"
    },
    {
      "x": -2,
      "y": 3,
      "z": -1,
      "name": "Rock_Volcanic"
    },
    {
      "x": -2,
      "y": 4,
      "z": -1,
      "name": "Rock_Volcanic"
    },
    {
      "x": -1,
      "y": 2,
      "z": -3,
      "name": "Rock_Volcanic"
    },
    {
      "x": -1,
      "y": 3,
      "z": -3,
      "name": "Rock_Volcanic"
    },
    {
      "x": -1,
      "y": 1,
      "z": -2,
      "name": "Rock_Volcanic_Cracked_Lava"
    },
    {
      "x": -1,
      "y": 2,
      "z": -2,
      "name": "Rock_Volcanic"
    },
    {
      "x": -1,
      "y": 3,
      "z": -2,
      "name": "Rock_Volcanic"
    },
    {
      "x": -1,
      "y": 4,
      "z": -2,
      "name": "Rock_Volcanic"
    },
    {
      "x": -1,
      "y": 1,
      "z": -1,
      "name": "Rock_Volcanic_Cracked_Lava"
    },
    {
      "x": -1,
      "y": 2,
      "z": -1,
      "name": "Rock_Volcanic"
    },
    {
      "x": -1,
      "y": 3,
      "z": -1,
      "name": "Ore_Adamantite_Volcanic"
    },
    {
      "x": -1,
      "y": 3,
      "z": 0,
      "name": "Ore_Adamantite_Volcanic"
    },
    {
      "x": -1,
      "y": 4,
      "z": 0,
      "name": "Rock_Crystal_Red_Medium",
      "rotation": 7
    },
    {
      "x": -1,
      "y": 2,
      "z": 2,
      "name": "Rock_Volcanic"
    },
    {
      "x": -1,
      "y": 3,
      "z": 2,
      "name": "Rock_Volcanic_Cracked_Lava"
    },
    {
      "x": -1,
      "y": 2,
      "z": 3,
      "name": "Rock_Volcanic"
    },
    {
      "x": -1,
      "y": 3,
      "z": 3,
      "name": "Rock_Volcanic_Cracked_Lava"
    },
    {
      "x": 0,
      "y": 1,
      "z": -2,
      "name": "Rock_Volcanic_Cracked_Lava"
    },
    {
      "x": 0,
      "y": 2,
      "z": -2,
      "name": "Rock_Volcanic_Cracked_Lava"
    },
    {
      "x": 0,
      "y": 3,
      "z": -2,
      "name": "Ore_Adamantite_Volcanic"
    },
    {
      "x": 0,
      "y": 1,
      "z": -1,
      "name": "Rock_Volcanic_Cracked_Lava"
    },
    {
      "x": 0,
      "y": 2,
      "z": -1,
      "name": "Rock_Volcanic"
    },
    {
      "x": 0,
      "y": 3,
      "z": -1,
      "name": "Ore_Adamantite_Volcanic"
    },
    {
      "x": 0,
      "y": 5,
      "z": -1,
      "name": "Rock_Crystal_Red_Small",
      "rotation": 6
    },
    {
      "x": 0,
      "y": 1,
      "z": 0,
      "name": "Rock_Volcanic"
    },
    {
      "x": 0,
      "y": 2,
      "z": 0,
      "name": "Ore_Adamantite_Volcanic"
    },
    {
      "x": 0,
      "y": 3,
      "z": 0,
      "name": "Rock_Volcanic"
    },
    {
      "x": 0,
      "y": 4,
      "z": 0,
      "name": "Rock_Volcanic_Cracked_Lava"
    },
    {
      "x": 0,
      "y": 5,
      "z": 0,
      "name": "Rock_Volcanic_Cracked_Lava"
    },
    {
      "x": 0,
      "y": 2,
      "z": 1,
      "name": "Ore_Adamantite_Volcanic"
    },
    {
      "x": 0,
      "y": 3,
      "z": 1,
      "name": "Rock_Volcanic"
    },
    {
      "x": 0,
      "y": 4,
      "z": 1,
      "name": "Rock_Volcanic"
    },
    {
      "x": 0,
      "y": 2,
      "z": 2,
      "name": "Rock_Volcanic"
    },
    {
      "x": 0,
      "y": 3,
      "z": 2,
      "name": "Rock_Volcanic_Cracked_Lava"
    },
    {
      "x": 0,
      "y": 2,
      "z": 3,
      "name": "Rock_Volcanic"
    },
    {
      "x": 0,
      "y": 3,
      "z": 3,
      "name": "Rock_Volcanic_Cracked_Lava"
    },
    {
      "x": 1,
      "y": 2,
      "z": -2,
      "name": "Rock_Volcanic"
    },
    {
      "x": 1,
      "y": 3,
      "z": -2,
      "name": "Rock_Volcanic_Cracked_Lava"
    },
    {
      "x": 1,
      "y": 4,
      "z": -2,
      "name": "Ore_Adamantite_Volcanic"
    },
    {
      "x": 1,
      "y": 5,
      "z": -2,
      "name": "Rock_Volcanic"
    },
    {
      "x": 1,
      "y": 1,
      "z": -1,
      "name": "Rock_Volcanic"
    },
    {
      "x": 1,
      "y": 2,
      "z": -1,
      "name": "Rock_Volcanic"
    },
    {
      "x": 1,
      "y": 3,
      "z": -1,
      "name": "Rock_Volcanic"
    },
    {
      "x": 1,
      "y": 4,
      "z": -1,
      "name": "Ore_Adamantite_Volcanic"
    },
    {
      "x": 1,
      "y": 5,
      "z": -1,
      "name": "Rock_Volcanic_Cracked_Lava"
    },
    {
      "x": 1,
      "y": 1,
      "z": 0,
      "name": "Rock_Volcanic"
    },
    {
      "x": 1,
      "y": 2,
      "z": 0,
      "name": "Rock_Volcanic"
    },
    {
      "x": 1,
      "y": 3,
      "z": 0,
      "name": "Rock_Volcanic"
    },
    {
      "x": 1,
      "y": 4,
      "z": 0,
      "name": "Rock_Volcanic"
    },
    {
      "x": 1,
      "y": 5,
      "z": 0,
      "name": "Rock_Volcanic"
    },
    {
      "x": 1,
      "y": 6,
      "z": 0,
      "name": "Rubble_Volcanic_Medium"
    },
    {
      "x": 1,
      "y": 1,
      "z": 1,
      "name": "Rock_Volcanic"
    },
    {
      "x": 1,
      "y": 2,
      "z": 1,
      "name": "Rock_Volcanic"
    },
    {
      "x": 1,
      "y": 3,
      "z": 1,
      "name": "Rock_Volcanic"
    },
    {
      "x": 1,
      "y": 4,
      "z": 1,
      "name": "Rock_Volcanic"
    },
    {
      "x": 1,
      "y": 5,
      "z": 1,
      "name": "Rock_Volcanic"
    },
    {
      "x": 1,
      "y": 2,
      "z": 2,
      "name": "Rock_Volcanic"
    },
    {
      "x": 1,
      "y": 3,
      "z": 2,
      "name": "Rock_Volcanic"
    },
    {
      "x": 1,
      "y": 4,
      "z": 2,
      "name": "Rock_Volcanic"
    },
    {
      "x": 1,
      "y": 2,
      "z": 3,
      "name": "Rock_Volcanic"
    },
    {
      "x": 1,
      "y": 3,
      "z": 3,
      "name": "Rock_Volcanic_Cracked_Lava"
    },
    {
      "x": 2,
      "y": 3,
      "z": -2,
      "name": "Rock_Volcanic"
    },
    {
      "x": 2,
      "y": 4,
      "z": -2,
      "name": "Rock_Volcanic"
    },
    {
      "x": 2,
      "y": 5,
      "z": -2,
      "name": "Rock_Volcanic"
    },
    {
      "x": 2,
      "y": 2,
      "z": -1,
      "name": "Rock_Volcanic"
    },
    {
      "x": 2,
      "y": 3,
      "z": -1,
      "name": "Rock_Volcanic"
    },
    {
      "x": 2,
      "y": 4,
      "z": -1,
      "name": "Rock_Volcanic"
    },
    {
      "x": 2,
      "y": 5,
      "z": -1,
      "name": "Rock_Volcanic"
    },
    {
      "x": 2,
      "y": 6,
      "z": -1,
      "name": "Rubble_Volcanic"
    },
    {
      "x": 2,
      "y": 1,
      "z": 0,
      "name": "Rock_Volcanic"
    },
    {
      "x": 2,
      "y": 2,
      "z": 0,
      "name": "Rock_Volcanic"
    },
    {
      "x": 2,
      "y": 3,
      "z": 0,
      "name": "Rock_Volcanic"
    },
    {
      "x": 2,
      "y": 4,
      "z": 0,
      "name": "Rock_Volcanic"
    },
    {
      "x": 2,
      "y": 5,
      "z": 0,
      "name": "Rock_Volcanic"
    },
    {
      "x": 2,
      "y": 2,
      "z": 1,
      "name": "Rock_Volcanic"
    },
    {
      "x": 2,
      "y": 3,
      "z": 1,
      "name": "Rock_Volcanic"
    },
    {
      "x": 2,
      "y": 4,
      "z": 1,
      "name": "Rock_Volcanic"
    },
    {
      "x": 2,
      "y": 3,
      "z": 2,
      "name": "Rock_Volcanic"
    },
    {
      "x": 2,
      "y": 4,
      "z": 2,
      "name": "Rock_Volcanic"
    },
    {
      "x": 3,
      "y": 3,
      "z": -1,
      "name": "Rock_Volcanic"
    },
    {
      "x": 3,
      "y": 4,
      "z": -1,
      "name": "Rock_Volcanic"
    },
    {
      "x": 3,
      "y": 5,
      "z": -1,
      "name": "Rock_Volcanic"
    },
    {
      "x": 3,
      "y": 2,
      "z": 0,
      "name": "Rock_Volcanic"
    },
    {
      "x": 3,
      "y": 3,
      "z": 0,
      "name": "Rock_Volcanic"
    },
    {
      "x": 3,
      "y": 4,
      "z": 0,
      "name": "Rock_Volcanic_Cracked_Lava"
    },
    {
      "x": 3,
      "y": 5,
      "z": 0,
      "name": "Rock_Volcanic"
    },
    {
      "x": 3,
      "y": 3,
      "z": 1,
      "name": "Rock_Volcanic"
    },
    {
      "x": 4,
      "y": 4,
      "z": 0,
      "name": "Rock_Crystal_Red_Small",
      "rotation": 5
    }
  ]
}