{
  "version": 8,
  "blockIdVersion": 8,
  "anchorX": 1,
  "anchorY": 1,
  "anchorZ": 0,
  "blocks": [
    {
      "x": -1,
      "y": 15,
      "z": 0,
      "name": "Plant_Leaves_Bamboo"
    },
    {
      "x": -1,
      "y": 16,
      "z": 0,
      "name": "Plant_Leaves_Bamboo"
    },
    {
      "x": 0,
      "y": 15,
      "z": -2,
      "name": "Plant_Leaves_Bamboo"
    },
    {
      "x": 0,
      "y": 15,
      "z": -1,
      "name": "Plant_Leaves_Bamboo"
    },
    {
      "x": 0,
      "y": 16,
      "z": -1,
      "name": "Plant_Leaves_Bamboo"
    },
    {
      "x": 0,
      "y": 17,
      "z": -1,
      "name": "Plant_Leaves_Bamboo"
    },
    {
      "x": 0,
      "y": 13,
      "z": 0,
      "name": "Plant_Leaves_Bamboo"
    },
    {
      "x": 0,
      "y": 15,
      "z": 0,
      "name": "Plant_Leaves_Bamboo"
    },
    {
      "x": 0,
      "y": 16,
      "z": 0,
      "name": "Plant_Leaves_Bamboo"
    },
    {
      "x": 0,
      "y": 17,
      "z": 0,
      "name": "Plant_Leaves_Bamboo"
    },
    {
      "x": 0,
      "y": 18,
      "z": 0,
      "name": "Plant_Leaves_Bamboo"
    },
    {
      "x": 0,
      "y": 13,
      "z": 1,
      "name": "Plant_Leaves_Bamboo"
    },
    {
      "x": 0,
      "y": 14,
      "z": 1,
      "name": "Plant_Leaves_Bamboo"
    },
    {
      "x": 0,
      "y": 15,
      "z": 1,
      "name": "Plant_Leaves_Bamboo"
    },
    {
      "x": 0,
      "y": 16,
      "z": 1,
      "name": "Plant_Leaves_Bamboo"
    },
    {
      "x": 0,
      "y": 17,
      "z": 1,
      "name": "Plant_Leaves_Bamboo"
    },
    {
      "x": 1,
      "y": 15,
      "z": -2,
      "name": "Plant_Leaves_Bamboo"
    },
    {
      "x": 1,
      "y": 16,
      "z": -2,
      "name": "Plant_Leaves_Bamboo"
    },
    {
      "x": 1,
      "y": 12,
      "z": -1,
      "name": "Plant_Leaves_Bamboo"
    },
    {
      "x": 1,
      "y": 13,
      "z": -1,
      "name": "Plant_Leaves_Bamboo"
    },
    {
      "x": 1,
      "y": 14,
      "z": -1,
      "name": "Plant_Leaves_Bamboo"
    },
    {
      "x": 1,
      "y": 15,
      "z": -1,
      "name": "Plant_Leaves_Bamboo"
    },
    {
      "x": 1,
      "y": 16,
      "z": -1,
      "name": "Plant_Leaves_Bamboo"
    },
    {
      "x": 1,
      "y": 17,
      "z": -1,
      "name": "Plant_Leaves_Bamboo"
    },
    {
      "x": 1,
      "y": 18,
      "z": -1,
      "name": "Plant_Leaves_Bamboo"
    },
    {
      "x": 1,
      "y": 19,
      "z": -1,
      "name": "Plant_Leaves_Bamboo"
    },
    {
      "x": 1,
      "y": 20,
      "z": -1,
      "name": "Plant_Leaves_Bamboo"
    },
    {
      "x": 1,
      "y": 1,
      "z": 0,
      "name": "Wood_Bamboo_Branch_Long"
    },
    {
      "x": 1,
      "y": 2,
      "z": 0,
      "name": "Wood_Bamboo_Branch_Long"
    },
    {
      "x": 1,
      "y": 3,
      "z": 0,
      "name": "Wood_Bamboo_Branch_Long"
    },
    {
      "x": 1,
      "y": 4,
      "z": 0,
      "name": "Wood_Bamboo_Branch_Long"
    },
    {
      "x": 1,
      "y": 5,
      "z": 0,
      "name": "Wood_Bamboo_Branch_Long"
    },
    {
      "x": 1,
      "y": 6,
      "z": 0,
      "name": "Wood_Bamboo_Branch_Long"
    },
    {
      "x": 1,
      "y": 7,
      "z": 0,
      "name": "Wood_Bamboo_Branch_Long"
    },
    {
      "x": 1,
      "y": 8,
      "z": 0,
      "name": "Wood_Bamboo_Branch_Long"
    },
    {
      "x": 1,
      "y": 9,
      "z": 0,
      "name": "Wood_Bamboo_Branch_Long"
    },
    {
      "x": 1,
      "y": 10,
      "z": 0,
      "name": "Wood_Bamboo_Branch_Long"
    },
    {
      "x": 1,
      "y": 11,
      "z": 0,
      "name": "Wood_Bamboo_Branch_Long"
    },
    {
      "x": 1,
      "y": 12,
      "z": 0,
      "name": "Wood_Bamboo_Branch_Long"
    },
    {
      "x": 1,
      "y": 13,
      "z": 0,
      "name": "Wood_Bamboo_Branch_Long"
    },
    {
      "x": 1,
      "y": 14,
      "z": 0,
      "name": "Wood_Bamboo_Branch_Long"
    },
    {
      "x": 1,
      "y": 15,
      "z": 0,
      "name": "Wood_Bamboo_Branch_Long"
    },
    {
      "x": 1,
      "y": 16,
      "z": 0,
      "name": "Wood_Bamboo_Branch_Long"
    },
    {
      "x": 1,
      "y": 17,
      "z": 0,
      "name": "Wood_Bamboo_Branch_Long"
    },
    {
      "x": 1,
      "y": 18,
      "z": 0,
      "name": "Wood_Bamboo_Branch_Long"
    },
    {
      "x": 1,
      "y": 19,
      "z": 0,
      "name": "Plant_Leaves_Bamboo"
    },
    {
      "x": 1,
      "y": 20,
      "z": 0,
      "name": "Plant_Leaves_Bamboo"
    },
    {
      "x": 1,
      "y": 8,
      "z": 1,
      "name": "Plant_Leaves_Bamboo"
    },
    {
      "x": 1,
      "y": 9,
      "z": 1,
      "name": "Plant_Leaves_Bamboo"
    },
    {
      "x": 1,
      "y": 13,
      "z": 1,
      "name": "Plant_Leaves_Bamboo"
    },
    {
      "x": 1,
      "y": 14,
      "z": 1,
      "name": "Plant_Leaves_Bamboo"
    },
    {
      "x": 1,
      "y": 15,
      "z": 1,
      "name": "Plant_Leaves_Bamboo"
    },
    {
      "x": 1,
      "y": 16,
      "z": 1,
      "name": "Plant_Leaves_Bamboo"
    },
    {
      "x": 1,
      "y": 17,
      "z": 1,
      "name": "Plant_Leaves_Bamboo"
    },
    {
      "x": 1,
      "y": 18,
      "z": 1,
      "name": "Plant_Leaves_Bamboo"
    },
    {
      "x": 1,
      "y": 19,
      "z": 1,
      "name": "Plant_Leaves_Bamboo"
    },
    {
      "x": 1,
      "y": 13,
      "z": 2,
      "name": "Plant_Leaves_Bamboo"
    },
    {
      "x": 1,
      "y": 14,
      "z": 2,
      "name": "Plant_Leaves_Bamboo"
    },
    {
      "x": 1,
      "y": 15,
      "z": 2,
      "name": "Plant_Leaves_Bamboo"
    },
    {
      "x": 1,
      "y": 16,
      "z": 2,
      "name": "Plant_Leaves_Bamboo"
    },
    {
      "x": 2,
      "y": 11,
      "z": -1,
      "name": "Plant_Leaves_Bamboo"
    },
    {
      "x": 2,
      "y": 12,
      "z": -1,
      "name": "Plant_Leaves_Bamboo"
    },
    {
      "x": 2,
      "y": 14,
      "z": -1,
      "name": "Plant_Leaves_Bamboo"
    },
    {
      "x": 2,
      "y": 15,
      "z": -1,
      "name": "Plant_Leaves_Bamboo"
    },
    {
      "x": 2,
      "y": 16,
      "z": -1,
      "name": "Plant_Leaves_Bamboo"
    },
    {
      "x": 2,
      "y": 18,
      "z": -1,
      "name": "Plant_Leaves_Bamboo"
    },
    {
      "x": 2,
      "y": 8,
      "z": 0,
      "name": "Plant_Leaves_Bamboo"
    },
    {
      "x": 2,
      "y": 12,
      "z": 0,
      "name": "Wood_Bamboo_Branch_Long",
      "rotation": 5
    },
    {
      "x": 2,
      "y": 14,
      "z": 0,
      "name": "Plant_Leaves_Bamboo"
    },
    {
      "x": 2,
      "y": 15,
      "z": 0,
      "name": "Plant_Leaves_Bamboo"
    },
    {
      "x": 2,
      "y": 16,
      "z": 0,
      "name": "Plant_Leaves_Bamboo"
    },
    {
      "x": 2,
      "y": 17,
      "z": 0,
      "name": "Plant_Leaves_Bamboo"
    },
    {
      "x": 2,
      "y": 18,
      "z": 0,
      "name": "Plant_Leaves_Bamboo"
    },
    {
      "x": 2,
      "y": 19,
      "z": 0,
      "name": "Plant_Leaves_Bamboo"
    },
    {
      "x": 2,
      "y": 12,
      "z": 1,
      "name": "Plant_Leaves_Bamboo"
    },
    {
      "x": 2,
      "y": 14,
      "z": 1,
      "name": "Plant_Leaves_Bamboo"
    },
    {
      "x": 2,
      "y": 15,
      "z": 1,
      "name": "Plant_Leaves_Bamboo"
    },
    {
      "x": 2,
      "y": 16,
      "z": 1,
      "name": "Plant_Leaves_Bamboo"
    },
    {
      "x": 2,
      "y": 17,
      "z": 1,
      "name": "Plant_Leaves_Bamboo"
    },
    {
      "x": 2,
      "y": 18,
      "z": 1,
      "name": "Plant_Leaves_Bamboo"
    },
    {
      "x": 3,
      "y": 16,
      "z": -1,
      "name": "Plant_Leaves_Bamboo"
    },
    {
      "x": 3,
      "y": 10,
      "z": 0,
      "name": "Plant_Leaves_Bamboo"
    },
    {
      "x": 3,
      "y": 11,
      "z": 0,
      "name": "Plant_Leaves_Bamboo"
    },
    {
      "x": 3,
      "y": 12,
      "z": 0,
      "name": "Plant_Leaves_Bamboo"
    },
    {
      "x": 3,
      "y": 13,
      "z": 0,
      "name": "Plant_Leaves_Bamboo"
    },
    {
      "x": 3,
      "y": 14,
      "z": 0,
      "name": "Plant_Leaves_Bamboo"
    },
    {
      "x": 3,
      "y": 15,
      "z": 0,
      "name": "Plant_Leaves_Bamboo"
    },
    {
      "x": 3,
      "y": 16,
      "z": 0,
      "name": "Plant_Leaves_Bamboo"
    },
    {
      "x": 3,
      "y": 12,
      "z": 1,
      "name": "Plant_Leaves_Bamboo"
    },
    {
      "x": 3,
      "y": 16,
      "z": 1,
      "name": "Plant_Leaves_Bamboo"
    },
    {
      "x": 4,
      "y": 12,
      "z": 0,
      "name": "Plant_Leaves_Bamboo"
    }
  ]
}