{
  "version": 8,
  "blockIdVersion": 10,
  "anchorX": 0,
  "anchorY": 7,
  "anchorZ": 0,
  "blocks": [
    {
      "x": -3,
      "y": 4,
      "z": 0,
      "name": "Deco_Bone_Full"
    },
    {
      "x": -3,
      "y": 5,
      "z": 0,
      "name": "Deco_Bone_Full"
    },
    {
      "x": -3,
      "y": 6,
      "z": 0,
      "name": "Deco_Bone_Full"
    },
    {
      "x": -3,
      "y": 3,
      "z": 1,
      "name": "Deco_Bone_Full"
    },
    {
      "x": -3,
      "y": 4,
      "z": 1,
      "name": "Deco_Bone_Full"
    },
    {
      "x": -3,
      "y": 5,
      "z": 1,
      "name": "Deco_Bone_Full"
    },
    {
      "x": -3,
      "y": 7,
      "z": 1,
      "name": "Rock_Sandstone_Cobble"
    },
    {
      "x": -3,
      "y": 8,
      "z": 1,
      "name": "Rock_Sandstone_Cobble"
    },
    {
      "x": -3,
      "y": 9,
      "z": 1,
      "name": "Rock_Sandstone_Cobble"
    },
    {
      "x": -2,
      "y": 3,
      "z": -1,
      "name": "Deco_Bone_Full"
    },
    {
      "x": -2,
      "y": 4,
      "z": -1,
      "name": "Deco_Bone_Full"
    },
    {
      "x": -2,
      "y": 5,
      "z": -1,
      "name": "Deco_Bone_Full"
    },
    {
      "x": -2,
      "y": 6,
      "z": -1,
      "name": "Deco_Bone_Full"
    },
    {
      "x": -2,
      "y": 7,
      "z": -1,
      "name": "Deco_Bone_Full"
    },
    {
      "x": -2,
      "y": 2,
      "z": 0,
      "name": "Deco_Bone_Full"
    },
    {
      "x": -2,
      "y": 3,
      "z": 0,
      "name": "Deco_Bone_Full"
    },
    {
      "x": -2,
      "y": 4,
      "z": 0,
      "name": "Deco_Bone_Full"
    },
    {
      "x": -2,
      "y": 5,
      "z": 0,
      "name": "Deco_Bone_Full"
    },
    {
      "x": -2,
      "y": 6,
      "z": 0,
      "name": "Deco_Bone_Full"
    },
    {
      "x": -2,
      "y": 7,
      "z": 0,
      "name": "Deco_Bone_Full"
    },
    {
      "x": -2,
      "y": 8,
      "z": 0,
      "name": "Deco_Bone_Full"
    },
    {
      "x": -2,
      "y": 9,
      "z": 0,
      "name": "Deco_Bone_Full"
    },
    {
      "x": -2,
      "y": 10,
      "z": 0,
      "name": "Deco_Bone_Full"
    },
    {
      "x": -2,
      "y": 11,
      "z": 0,
      "name": "Deco_Bone_Full"
    },
    {
      "x": -2,
      "y": 12,
      "z": 0,
      "name": "Deco_Bone_Full"
    },
    {
      "x": -2,
      "y": 13,
      "z": 0,
      "name": "Deco_Bone_Full"
    },
    {
      "x": -2,
      "y": 14,
      "z": 0,
      "name": "Deco_Bone_Full"
    },
    {
      "x": -2,
      "y": 15,
      "z": 0,
      "name": "Deco_Bone_Full"
    },
    {
      "x": -2,
      "y": 16,
      "z": 0,
      "name": "Deco_Bone_Full"
    },
    {
      "x": -2,
      "y": 2,
      "z": 1,
      "name": "Deco_Bone_Full"
    },
    {
      "x": -2,
      "y": 3,
      "z": 1,
      "name": "Deco_Bone_Full"
    },
    {
      "x": -2,
      "y": 4,
      "z": 1,
      "name": "Deco_Bone_Full"
    },
    {
      "x": -2,
      "y": 5,
      "z": 1,
      "name": "Deco_Bone_Full"
    },
    {
      "x": -2,
      "y": 6,
      "z": 1,
      "name": "Deco_Bone_Full"
    },
    {
      "x": -2,
      "y": 7,
      "z": 1,
      "name": "Deco_Bone_Full"
    },
    {
      "x": -2,
      "y": 8,
      "z": 1,
      "name": "Deco_Bone_Full"
    },
    {
      "x": -2,
      "y": 9,
      "z": 1,
      "name": "Rock_Sandstone_Cobble"
    },
    {
      "x": -2,
      "y": 10,
      "z": 1,
      "name": "Rock_Sandstone_Cobble"
    },
    {
      "x": -2,
      "y": 3,
      "z": 2,
      "name": "Deco_Bone_Full"
    },
    {
      "x": -2,
      "y": 4,
      "z": 2,
      "name": "Deco_Bone_Full"
    },
    {
      "x": -2,
      "y": 5,
      "z": 2,
      "name": "Deco_Bone_Full"
    },
    {
      "x": -1,
      "y": 4,
      "z": -1,
      "name": "Deco_Bone_Full"
    },
    {
      "x": -1,
      "y": 5,
      "z": -1,
      "name": "Deco_Bone_Full"
    },
    {
      "x": -1,
      "y": 6,
      "z": -1,
      "name": "Deco_Bone_Full"
    },
    {
      "x": -1,
      "y": 7,
      "z": -1,
      "name": "Deco_Bone_Full"
    },
    {
      "x": -1,
      "y": 8,
      "z": -1,
      "name": "Deco_Bone_Full"
    },
    {
      "x": -1,
      "y": 9,
      "z": -1,
      "name": "Deco_Bone_Full"
    },
    {
      "x": -1,
      "y": 3,
      "z": 0,
      "name": "Deco_Bone_Full"
    },
    {
      "x": -1,
      "y": 4,
      "z": 0,
      "name": "Deco_Bone_Full"
    },
    {
      "x": -1,
      "y": 5,
      "z": 0,
      "name": "Deco_Bone_Full"
    },
    {
      "x": -1,
      "y": 6,
      "z": 0,
      "name": "Deco_Bone_Full"
    },
    {
      "x": -1,
      "y": 7,
      "z": 0,
      "name": "Deco_Bone_Full"
    },
    {
      "x": -1,
      "y": 8,
      "z": 0,
      "name": "Deco_Bone_Full"
    },
    {
      "x": -1,
      "y": 9,
      "z": 0,
      "name": "Deco_Bone_Full"
    },
    {
      "x": -1,
      "y": 10,
      "z": 0,
      "name": "Deco_Bone_Full"
    },
    {
      "x": -1,
      "y": 11,
      "z": 0,
      "name": "Deco_Bone_Full"
    },
    {
      "x": -1,
      "y": 12,
      "z": 0,
      "name": "Deco_Bone_Full"
    },
    {
      "x": -1,
      "y": 2,
      "z": 1,
      "name": "Deco_Bone_Full"
    },
    {
      "x": -1,
      "y": 3,
      "z": 1,
      "name": "Deco_Bone_Full"
    },
    {
      "x": -1,
      "y": 4,
      "z": 1,
      "name": "Deco_Bone_Full"
    },
    {
      "x": -1,
      "y": 5,
      "z": 1,
      "name": "Deco_Bone_Full"
    },
    {
      "x": -1,
      "y": 6,
      "z": 1,
      "name": "Deco_Bone_Full"
    },
    {
      "x": -1,
      "y": 7,
      "z": 1,
      "name": "Deco_Bone_Full"
    },
    {
      "x": -1,
      "y": 8,
      "z": 1,
      "name": "Deco_Bone_Full"
    },
    {
      "x": -1,
      "y": 9,
      "z": 1,
      "name": "Deco_Bone_Full"
    },
    {
      "x": -1,
      "y": 10,
      "z": 1,
      "name": "Deco_Bone_Full"
    },
    {
      "x": -1,
      "y": 11,
      "z": 1,
      "name": "Deco_Bone_Full"
    },
    {
      "x": -1,
      "y": 12,
      "z": 1,
      "name": "Deco_Bone_Full"
    },
    {
      "x": -1,
      "y": 13,
      "z": 1,
      "name": "Deco_Bone_Full"
    },
    {
      "x": -1,
      "y": 14,
      "z": 1,
      "name": "Deco_Bone_Full"
    },
    {
      "x": -1,
      "y": 3,
      "z": 2,
      "name": "Deco_Bone_Full"
    },
    {
      "x": -1,
      "y": 4,
      "z": 2,
      "name": "Deco_Bone_Full"
    },
    {
      "x": -1,
      "y": 5,
      "z": 2,
      "name": "Deco_Bone_Full"
    },
    {
      "x": -1,
      "y": 6,
      "z": 2,
      "name": "Deco_Bone_Full"
    },
    {
      "x": 0,
      "y": 5,
      "z": 0,
      "name": "Deco_Bone_Full"
    },
    {
      "x": 0,
      "y": 6,
      "z": 0,
      "name": "Deco_Bone_Full"
    },
    {
      "x": 0,
      "y": 7,
      "z": 0,
      "name": "Deco_Bone_Full"
    },
    {
      "x": 0,
      "y": 8,
      "z": 0,
      "name": "Deco_Bone_Full"
    },
    {
      "x": 0,
      "y": 9,
      "z": 0,
      "name": "Deco_Bone_Full"
    },
    {
      "x": 0,
      "y": 10,
      "z": 0,
      "name": "Deco_Bone_Full"
    },
    {
      "x": 0,
      "y": 3,
      "z": 1,
      "name": "Deco_Bone_Full"
    },
    {
      "x": 0,
      "y": 4,
      "z": 1,
      "name": "Deco_Bone_Full"
    },
    {
      "x": 0,
      "y": 5,
      "z": 1,
      "name": "Deco_Bone_Full"
    },
    {
      "x": 0,
      "y": 6,
      "z": 1,
      "name": "Deco_Bone_Full"
    },
    {
      "x": 0,
      "y": 7,
      "z": 1,
      "name": "Deco_Bone_Full"
    },
    {
      "x": 0,
      "y": 4,
      "z": 2,
      "name": "Deco_Bone_Full"
    },
    {
      "x": 0,
      "y": 5,
      "z": 2,
      "name": "Deco_Bone_Full"
    },
    {
      "x": 1,
      "y": 7,
      "z": 0,
      "name": "Rock_Sandstone_Cobble"
    },
    {
      "x": 1,
      "y": 8,
      "z": 0,
      "name": "Rock_Sandstone_Cobble"
    },
    {
      "x": 1,
      "y": 9,
      "z": 0,
      "name": "Rock_Sandstone_Cobble"
    },
    {
      "x": 1,
      "y": 10,
      "z": 0,
      "name": "Rock_Sandstone_Cobble"
    },
    {
      "x": 2,
      "y": 7,
      "z": 0,
      "name": "Rock_Sandstone_Cobble"
    },
    {
      "x": 2,
      "y": 8,
      "z": 0,
      "name": "Rock_Sandstone_Cobble"
    }
  ]
}