{
  "version": 8,
  "blockIdVersion": 8,
  "anchorX": 22,
  "anchorY": 11,
  "anchorZ": 8,
  "blocks": [
    {
      "x": 9,
      "y": 16,
      "z": 5,
      "name": "Rock_Basalt"
    },
    {
      "x": 9,
      "y": 17,
      "z": 5,
      "name": "Soil_Dirt_Burnt"
    },
    {
      "x": 9,
      "y": 18,
      "z": 5,
      "name": "Soil_Mud_Dry"
    },
    {
      "x": 9,
      "y": 19,
      "z": 5,
      "name": "Soil_Mud_Dry"
    },
    {
      "x": 9,
      "y": 20,
      "z": 5,
      "name": "Soil_Mud_Dry"
    },
    {
      "x": 9,
      "y": 18,
      "z": 6,
      "name": "Soil_Mud_Dry"
    },
    {
      "x": 9,
      "y": 19,
      "z": 6,
      "name": "Soil_Mud_Dry"
    },
    {
      "x": 9,
      "y": 20,
      "z": 6,
      "name": "Soil_Mud_Dry"
    },
    {
      "x": 10,
      "y": 15,
      "z": 4,
      "name": "Rock_Basalt"
    },
    {
      "x": 10,
      "y": 16,
      "z": 4,
      "name": "Rock_Basalt"
    },
    {
      "x": 10,
      "y": 17,
      "z": 4,
      "name": "Soil_Dirt_Burnt"
    },
    {
      "x": 10,
      "y": 18,
      "z": 4,
      "name": "Soil_Mud_Dry"
    },
    {
      "x": 10,
      "y": 19,
      "z": 4,
      "name": "Soil_Mud_Dry"
    },
    {
      "x": 10,
      "y": 15,
      "z": 5,
      "name": "Rock_Basalt"
    },
    {
      "x": 10,
      "y": 16,
      "z": 5,
      "name": "Rock_Basalt"
    },
    {
      "x": 10,
      "y": 17,
      "z": 5,
      "name": "Soil_Dirt_Burnt"
    },
    {
      "x": 10,
      "y": 18,
      "z": 5,
      "name": "Soil_Mud_Dry"
    },
    {
      "x": 10,
      "y": 19,
      "z": 5,
      "name": "Soil_Mud_Dry"
    },
    {
      "x": 10,
      "y": 20,
      "z": 5,
      "name": "Soil_Mud_Dry"
    },
    {
      "x": 10,
      "y": 21,
      "z": 5,
      "name": "Soil_Mud_Dry"
    },
    {
      "x": 10,
      "y": 15,
      "z": 6,
      "name": "Rock_Basalt"
    },
    {
      "x": 10,
      "y": 16,
      "z": 6,
      "name": "Rock_Basalt"
    },
    {
      "x": 10,
      "y": 17,
      "z": 6,
      "name": "Soil_Dirt_Burnt"
    },
    {
      "x": 10,
      "y": 18,
      "z": 6,
      "name": "Soil_Mud_Dry"
    },
    {
      "x": 10,
      "y": 19,
      "z": 6,
      "name": "Soil_Mud_Dry"
    },
    {
      "x": 10,
      "y": 20,
      "z": 6,
      "name": "Soil_Mud_Dry"
    },
    {
      "x": 10,
      "y": 21,
      "z": 6,
      "name": "Soil_Mud_Dry"
    },
    {
      "x": 10,
      "y": 17,
      "z": 7,
      "name": "Soil_Dirt_Burnt"
    },
    {
      "x": 10,
      "y": 18,
      "z": 7,
      "name": "Soil_Mud_Dry"
    },
    {
      "x": 10,
      "y": 19,
      "z": 7,
      "name": "Soil_Mud_Dry"
    },
    {
      "x": 11,
      "y": 16,
      "z": 3,
      "name": "Rock_Basalt"
    },
    {
      "x": 11,
      "y": 17,
      "z": 3,
      "name": "Soil_Dirt_Burnt"
    },
    {
      "x": 11,
      "y": 18,
      "z": 3,
      "name": "Soil_Mud_Dry"
    },
    {
      "x": 11,
      "y": 19,
      "z": 3,
      "name": "Soil_Mud_Dry"
    },
    {
      "x": 11,
      "y": 20,
      "z": 3,
      "name": "Soil_Mud_Dry"
    },
    {
      "x": 11,
      "y": 15,
      "z": 4,
      "name": "Rock_Basalt"
    },
    {
      "x": 11,
      "y": 16,
      "z": 4,
      "name": "Rock_Basalt"
    },
    {
      "x": 11,
      "y": 17,
      "z": 4,
      "name": "Soil_Dirt_Burnt"
    },
    {
      "x": 11,
      "y": 18,
      "z": 4,
      "name": "Soil_Mud_Dry"
    },
    {
      "x": 11,
      "y": 19,
      "z": 4,
      "name": "Soil_Mud_Dry"
    },
    {
      "x": 11,
      "y": 20,
      "z": 4,
      "name": "Soil_Mud_Dry"
    },
    {
      "x": 11,
      "y": 21,
      "z": 4,
      "name": "Soil_Mud_Dry"
    },
    {
      "x": 11,
      "y": 14,
      "z": 5,
      "name": "Rock_Basalt"
    },
    {
      "x": 11,
      "y": 15,
      "z": 5,
      "name": "Rock_Basalt"
    },
    {
      "x": 11,
      "y": 16,
      "z": 5,
      "name": "Rock_Basalt"
    },
    {
      "x": 11,
      "y": 17,
      "z": 5,
      "name": "Soil_Dirt_Burnt"
    },
    {
      "x": 11,
      "y": 18,
      "z": 5,
      "name": "Soil_Mud_Dry"
    },
    {
      "x": 11,
      "y": 19,
      "z": 5,
      "name": "Soil_Mud_Dry"
    },
    {
      "x": 11,
      "y": 20,
      "z": 5,
      "name": "Soil_Mud_Dry"
    },
    {
      "x": 11,
      "y": 21,
      "z": 5,
      "name": "Soil_Mud_Dry"
    },
    {
      "x": 11,
      "y": 22,
      "z": 5,
      "name": "Soil_Dirt_Burnt"
    },
    {
      "x": 11,
      "y": 14,
      "z": 6,
      "name": "Rock_Basalt"
    },
    {
      "x": 11,
      "y": 15,
      "z": 6,
      "name": "Rock_Basalt"
    },
    {
      "x": 11,
      "y": 16,
      "z": 6,
      "name": "Rock_Basalt"
    },
    {
      "x": 11,
      "y": 17,
      "z": 6,
      "name": "Soil_Dirt_Burnt"
    },
    {
      "x": 11,
      "y": 18,
      "z": 6,
      "name": "Soil_Mud_Dry"
    },
    {
      "x": 11,
      "y": 19,
      "z": 6,
      "name": "Soil_Mud_Dry"
    },
    {
      "x": 11,
      "y": 20,
      "z": 6,
      "name": "Soil_Mud_Dry"
    },
    {
      "x": 11,
      "y": 21,
      "z": 6,
      "name": "Soil_Mud_Dry"
    },
    {
      "x": 11,
      "y": 22,
      "z": 6,
      "name": "Soil_Dirt_Burnt"
    },
    {
      "x": 11,
      "y": 14,
      "z": 7,
      "name": "Rock_Basalt"
    },
    {
      "x": 11,
      "y": 15,
      "z": 7,
      "name": "Rock_Basalt"
    },
    {
      "x": 11,
      "y": 16,
      "z": 7,
      "name": "Rock_Basalt"
    },
    {
      "x": 11,
      "y": 17,
      "z": 7,
      "name": "Soil_Dirt_Burnt"
    },
    {
      "x": 11,
      "y": 18,
      "z": 7,
      "name": "Rock_Basalt"
    },
    {
      "x": 11,
      "y": 19,
      "z": 7,
      "name": "Soil_Mud_Dry"
    },
    {
      "x": 11,
      "y": 20,
      "z": 7,
      "name": "Soil_Mud_Dry"
    },
    {
      "x": 11,
      "y": 21,
      "z": 7,
      "name": "Soil_Mud_Dry"
    },
    {
      "x": 11,
      "y": 22,
      "z": 7,
      "name": "Soil_Dirt_Burnt"
    },
    {
      "x": 12,
      "y": 16,
      "z": 3,
      "name": "Rock_Basalt"
    },
    {
      "x": 12,
      "y": 17,
      "z": 3,
      "name": "Soil_Dirt_Burnt"
    },
    {
      "x": 12,
      "y": 18,
      "z": 3,
      "name": "Soil_Mud_Dry"
    },
    {
      "x": 12,
      "y": 19,
      "z": 3,
      "name": "Soil_Mud_Dry"
    },
    {
      "x": 12,
      "y": 20,
      "z": 3,
      "name": "Soil_Mud_Dry"
    },
    {
      "x": 12,
      "y": 15,
      "z": 4,
      "name": "Rock_Basalt"
    },
    {
      "x": 12,
      "y": 16,
      "z": 4,
      "name": "Rock_Basalt"
    },
    {
      "x": 12,
      "y": 17,
      "z": 4,
      "name": "Soil_Dirt_Burnt"
    },
    {
      "x": 12,
      "y": 18,
      "z": 4,
      "name": "Soil_Mud_Dry"
    },
    {
      "x": 12,
      "y": 19,
      "z": 4,
      "name": "Soil_Mud_Dry"
    },
    {
      "x": 12,
      "y": 20,
      "z": 4,
      "name": "Soil_Mud_Dry"
    },
    {
      "x": 12,
      "y": 21,
      "z": 4,
      "name": "Soil_Mud_Dry"
    },
    {
      "x": 12,
      "y": 22,
      "z": 4,
      "name": "Soil_Dirt_Burnt"
    },
    {
      "x": 12,
      "y": 14,
      "z": 5,
      "name": "Rock_Basalt"
    },
    {
      "x": 12,
      "y": 15,
      "z": 5,
      "name": "Rock_Basalt"
    },
    {
      "x": 12,
      "y": 16,
      "z": 5,
      "name": "Rock_Basalt"
    },
    {
      "x": 12,
      "y": 17,
      "z": 5,
      "name": "Soil_Dirt_Burnt"
    },
    {
      "x": 12,
      "y": 18,
      "z": 5,
      "name": "Rock_Basalt"
    },
    {
      "x": 12,
      "y": 19,
      "z": 5,
      "name": "Soil_Mud_Dry"
    },
    {
      "x": 12,
      "y": 20,
      "z": 5,
      "name": "Soil_Mud_Dry"
    },
    {
      "x": 12,
      "y": 21,
      "z": 5,
      "name": "Soil_Mud_Dry"
    },
    {
      "x": 12,
      "y": 22,
      "z": 5,
      "name": "Soil_Dirt_Burnt"
    },
    {
      "x": 12,
      "y": 13,
      "z": 6,
      "name": "Rock_Basalt"
    },
    {
      "x": 12,
      "y": 14,
      "z": 6,
      "name": "Rock_Basalt"
    },
    {
      "x": 12,
      "y": 15,
      "z": 6,
      "name": "Rock_Basalt"
    },
    {
      "x": 12,
      "y": 16,
      "z": 6,
      "name": "Rock_Basalt"
    },
    {
      "x": 12,
      "y": 17,
      "z": 6,
      "name": "Soil_Dirt_Burnt"
    },
    {
      "x": 12,
      "y": 18,
      "z": 6,
      "name": "Rock_Basalt"
    },
    {
      "x": 12,
      "y": 19,
      "z": 6,
      "name": "Rock_Basalt"
    },
    {
      "x": 12,
      "y": 20,
      "z": 6,
      "name": "Soil_Mud_Dry"
    },
    {
      "x": 12,
      "y": 21,
      "z": 6,
      "name": "Soil_Mud_Dry"
    },
    {
      "x": 12,
      "y": 22,
      "z": 6,
      "name": "Soil_Dirt_Burnt"
    },
    {
      "x": 12,
      "y": 23,
      "z": 6,
      "name": "Soil_Dirt_Burnt"
    },
    {
      "x": 12,
      "y": 13,
      "z": 7,
      "name": "Rock_Basalt"
    },
    {
      "x": 12,
      "y": 14,
      "z": 7,
      "name": "Rock_Basalt"
    },
    {
      "x": 12,
      "y": 15,
      "z": 7,
      "name": "Rock_Basalt"
    },
    {
      "x": 12,
      "y": 16,
      "z": 7,
      "name": "Rock_Basalt"
    },
    {
      "x": 12,
      "y": 17,
      "z": 7,
      "name": "Soil_Dirt_Burnt"
    },
    {
      "x": 12,
      "y": 18,
      "z": 7,
      "name": "Rock_Basalt"
    },
    {
      "x": 12,
      "y": 19,
      "z": 7,
      "name": "Rock_Basalt"
    },
    {
      "x": 12,
      "y": 20,
      "z": 7,
      "name": "Rock_Basalt"
    },
    {
      "x": 12,
      "y": 21,
      "z": 7,
      "name": "Soil_Mud_Dry"
    },
    {
      "x": 12,
      "y": 22,
      "z": 7,
      "name": "Soil_Dirt_Burnt"
    },
    {
      "x": 12,
      "y": 23,
      "z": 7,
      "name": "Soil_Mud_Dry"
    },
    {
      "x": 12,
      "y": 13,
      "z": 8,
      "name": "Rock_Basalt"
    },
    {
      "x": 12,
      "y": 14,
      "z": 8,
      "name": "Rock_Basalt"
    },
    {
      "x": 12,
      "y": 15,
      "z": 8,
      "name": "Rock_Basalt"
    },
    {
      "x": 12,
      "y": 22,
      "z": 8,
      "name": "Soil_Dirt_Burnt"
    },
    {
      "x": 12,
      "y": 23,
      "z": 8,
      "name": "Soil_Mud_Dry"
    },
    {
      "x": 13,
      "y": 18,
      "z": 3,
      "name": "Soil_Mud_Dry"
    },
    {
      "x": 13,
      "y": 19,
      "z": 3,
      "name": "Soil_Mud_Dry"
    },
    {
      "x": 13,
      "y": 20,
      "z": 3,
      "name": "Soil_Mud_Dry"
    },
    {
      "x": 13,
      "y": 21,
      "z": 3,
      "name": "Soil_Mud_Dry"
    },
    {
      "x": 13,
      "y": 15,
      "z": 4,
      "name": "Rock_Basalt"
    },
    {
      "x": 13,
      "y": 16,
      "z": 4,
      "name": "Rock_Basalt"
    },
    {
      "x": 13,
      "y": 17,
      "z": 4,
      "name": "Soil_Dirt_Burnt"
    },
    {
      "x": 13,
      "y": 18,
      "z": 4,
      "name": "Rock_Basalt"
    },
    {
      "x": 13,
      "y": 19,
      "z": 4,
      "name": "Soil_Mud_Dry"
    },
    {
      "x": 13,
      "y": 20,
      "z": 4,
      "name": "Soil_Mud_Dry"
    },
    {
      "x": 13,
      "y": 21,
      "z": 4,
      "name": "Soil_Mud_Dry"
    },
    {
      "x": 13,
      "y": 22,
      "z": 4,
      "name": "Soil_Dirt_Burnt"
    },
    {
      "x": 13,
      "y": 14,
      "z": 5,
      "name": "Rock_Basalt"
    },
    {
      "x": 13,
      "y": 15,
      "z": 5,
      "name": "Rock_Basalt"
    },
    {
      "x": 13,
      "y": 16,
      "z": 5,
      "name": "Rock_Basalt"
    },
    {
      "x": 13,
      "y": 17,
      "z": 5,
      "name": "Soil_Dirt_Burnt"
    },
    {
      "x": 13,
      "y": 18,
      "z": 5,
      "name": "Rock_Basalt"
    },
    {
      "x": 13,
      "y": 19,
      "z": 5,
      "name": "Rock_Basalt"
    },
    {
      "x": 13,
      "y": 20,
      "z": 5,
      "name": "Soil_Mud_Dry"
    },
    {
      "x": 13,
      "y": 21,
      "z": 5,
      "name": "Rock_Basalt"
    },
    {
      "x": 13,
      "y": 22,
      "z": 5,
      "name": "Soil_Dirt_Burnt"
    },
    {
      "x": 13,
      "y": 23,
      "z": 5,
      "name": "Soil_Dirt_Burnt"
    },
    {
      "x": 13,
      "y": 12,
      "z": 6,
      "name": "Rock_Basalt"
    },
    {
      "x": 13,
      "y": 13,
      "z": 6,
      "name": "Rock_Basalt"
    },
    {
      "x": 13,
      "y": 14,
      "z": 6,
      "name": "Rock_Basalt"
    },
    {
      "x": 13,
      "y": 15,
      "z": 6,
      "name": "Rock_Basalt"
    },
    {
      "x": 13,
      "y": 16,
      "z": 6,
      "name": "Rock_Basalt"
    },
    {
      "x": 13,
      "y": 17,
      "z": 6,
      "name": "Soil_Dirt_Burnt"
    },
    {
      "x": 13,
      "y": 18,
      "z": 6,
      "name": "Rock_Basalt"
    },
    {
      "x": 13,
      "y": 19,
      "z": 6,
      "name": "Rock_Basalt"
    },
    {
      "x": 13,
      "y": 20,
      "z": 6,
      "name": "Rock_Basalt"
    },
    {
      "x": 13,
      "y": 21,
      "z": 6,
      "name": "Soil_Mud_Dry"
    },
    {
      "x": 13,
      "y": 22,
      "z": 6,
      "name": "Soil_Dirt_Burnt"
    },
    {
      "x": 13,
      "y": 23,
      "z": 6,
      "name": "Soil_Dirt_Burnt"
    },
    {
      "x": 13,
      "y": 11,
      "z": 7,
      "name": "Rock_Basalt"
    },
    {
      "x": 13,
      "y": 12,
      "z": 7,
      "name": "Rock_Basalt"
    },
    {
      "x": 13,
      "y": 13,
      "z": 7,
      "name": "Rock_Basalt"
    },
    {
      "x": 13,
      "y": 14,
      "z": 7,
      "name": "Rock_Basalt"
    },
    {
      "x": 13,
      "y": 15,
      "z": 7,
      "name": "Rock_Basalt"
    },
    {
      "x": 13,
      "y": 16,
      "z": 7,
      "name": "Rock_Basalt"
    },
    {
      "x": 13,
      "y": 20,
      "z": 7,
      "name": "Rock_Basalt"
    },
    {
      "x": 13,
      "y": 21,
      "z": 7,
      "name": "Rock_Basalt"
    },
    {
      "x": 13,
      "y": 22,
      "z": 7,
      "name": "Soil_Dirt_Burnt"
    },
    {
      "x": 13,
      "y": 23,
      "z": 7,
      "name": "Soil_Dirt_Burnt"
    },
    {
      "x": 13,
      "y": 11,
      "z": 8,
      "name": "Rock_Basalt"
    },
    {
      "x": 13,
      "y": 12,
      "z": 8,
      "name": "Rock_Basalt"
    },
    {
      "x": 13,
      "y": 13,
      "z": 8,
      "name": "Rock_Basalt"
    },
    {
      "x": 13,
      "y": 14,
      "z": 8,
      "name": "Rock_Basalt"
    },
    {
      "x": 13,
      "y": 15,
      "z": 8,
      "name": "Rock_Basalt"
    },
    {
      "x": 13,
      "y": 20,
      "z": 8,
      "name": "Rock_Basalt"
    },
    {
      "x": 13,
      "y": 21,
      "z": 8,
      "name": "Rock_Basalt"
    },
    {
      "x": 13,
      "y": 22,
      "z": 8,
      "name": "Soil_Dirt_Burnt"
    },
    {
      "x": 13,
      "y": 23,
      "z": 8,
      "name": "Soil_Dirt_Burnt"
    },
    {
      "x": 13,
      "y": 13,
      "z": 9,
      "name": "Rock_Basalt"
    },
    {
      "x": 13,
      "y": 14,
      "z": 9,
      "name": "Rock_Basalt"
    },
    {
      "x": 13,
      "y": 21,
      "z": 9,
      "name": "Soil_Mud_Dry"
    },
    {
      "x": 13,
      "y": 22,
      "z": 9,
      "name": "Soil_Dirt_Burnt"
    },
    {
      "x": 14,
      "y": 19,
      "z": 3,
      "name": "Soil_Mud_Dry"
    },
    {
      "x": 14,
      "y": 20,
      "z": 3,
      "name": "Soil_Mud_Dry"
    },
    {
      "x": 14,
      "y": 21,
      "z": 3,
      "name": "Soil_Mud_Dry"
    },
    {
      "x": 14,
      "y": 19,
      "z": 4,
      "name": "Rock_Basalt"
    },
    {
      "x": 14,
      "y": 20,
      "z": 4,
      "name": "Soil_Mud_Dry"
    },
    {
      "x": 14,
      "y": 21,
      "z": 4,
      "name": "Soil_Mud_Dry"
    },
    {
      "x": 14,
      "y": 22,
      "z": 4,
      "name": "Soil_Dirt_Burnt"
    },
    {
      "x": 14,
      "y": 13,
      "z": 5,
      "name": "Rock_Basalt"
    },
    {
      "x": 14,
      "y": 14,
      "z": 5,
      "name": "Rock_Basalt"
    },
    {
      "x": 14,
      "y": 15,
      "z": 5,
      "name": "Rock_Basalt"
    },
    {
      "x": 14,
      "y": 16,
      "z": 5,
      "name": "Rock_Basalt"
    },
    {
      "x": 14,
      "y": 19,
      "z": 5,
      "name": "Rock_Basalt"
    },
    {
      "x": 14,
      "y": 20,
      "z": 5,
      "name": "Rock_Basalt"
    },
    {
      "x": 14,
      "y": 21,
      "z": 5,
      "name": "Soil_Mud_Dry"
    },
    {
      "x": 14,
      "y": 22,
      "z": 5,
      "name": "Soil_Dirt_Burnt"
    },
    {
      "x": 14,
      "y": 23,
      "z": 5,
      "name": "Soil_Dirt_Burnt"
    },
    {
      "x": 14,
      "y": 12,
      "z": 6,
      "name": "Rock_Basalt"
    },
    {
      "x": 14,
      "y": 13,
      "z": 6,
      "name": "Rock_Basalt"
    },
    {
      "x": 14,
      "y": 14,
      "z": 6,
      "name": "Rock_Basalt"
    },
    {
      "x": 14,
      "y": 15,
      "z": 6,
      "name": "Rock_Basalt"
    },
    {
      "x": 14,
      "y": 16,
      "z": 6,
      "name": "Rock_Basalt"
    },
    {
      "x": 14,
      "y": 17,
      "z": 6,
      "name": "Soil_Dirt_Burnt"
    },
    {
      "x": 14,
      "y": 20,
      "z": 6,
      "name": "Rock_Basalt"
    },
    {
      "x": 14,
      "y": 21,
      "z": 6,
      "name": "Rock_Basalt"
    },
    {
      "x": 14,
      "y": 22,
      "z": 6,
      "name": "Soil_Dirt_Burnt"
    },
    {
      "x": 14,
      "y": 23,
      "z": 6,
      "name": "Soil_Dirt_Burnt"
    },
    {
      "x": 14,
      "y": 11,
      "z": 7,
      "name": "Rock_Basalt"
    },
    {
      "x": 14,
      "y": 12,
      "z": 7,
      "name": "Rock_Basalt"
    },
    {
      "x": 14,
      "y": 13,
      "z": 7,
      "name": "Rock_Basalt"
    },
    {
      "x": 14,
      "y": 14,
      "z": 7,
      "name": "Rock_Basalt"
    },
    {
      "x": 14,
      "y": 15,
      "z": 7,
      "name": "Rock_Basalt"
    },
    {
      "x": 14,
      "y": 20,
      "z": 7,
      "name": "Rock_Basalt"
    },
    {
      "x": 14,
      "y": 21,
      "z": 7,
      "name": "Rock_Basalt"
    },
    {
      "x": 14,
      "y": 22,
      "z": 7,
      "name": "Soil_Dirt_Burnt"
    },
    {
      "x": 14,
      "y": 23,
      "z": 7,
      "name": "Soil_Dirt_Burnt"
    },
    {
      "x": 14,
      "y": 10,
      "z": 8,
      "name": "Rock_Basalt"
    },
    {
      "x": 14,
      "y": 11,
      "z": 8,
      "name": "Rock_Basalt"
    },
    {
      "x": 14,
      "y": 12,
      "z": 8,
      "name": "Rock_Basalt"
    },
    {
      "x": 14,
      "y": 13,
      "z": 8,
      "name": "Rock_Basalt"
    },
    {
      "x": 14,
      "y": 14,
      "z": 8,
      "name": "Rock_Basalt"
    },
    {
      "x": 14,
      "y": 15,
      "z": 8,
      "name": "Rock_Basalt"
    },
    {
      "x": 14,
      "y": 20,
      "z": 8,
      "name": "Rock_Basalt"
    },
    {
      "x": 14,
      "y": 21,
      "z": 8,
      "name": "Soil_Mud_Dry"
    },
    {
      "x": 14,
      "y": 22,
      "z": 8,
      "name": "Soil_Dirt_Burnt"
    },
    {
      "x": 14,
      "y": 23,
      "z": 8,
      "name": "Soil_Dirt_Burnt"
    },
    {
      "x": 14,
      "y": 10,
      "z": 9,
      "name": "Rock_Basalt"
    },
    {
      "x": 14,
      "y": 11,
      "z": 9,
      "name": "Rock_Basalt"
    },
    {
      "x": 14,
      "y": 12,
      "z": 9,
      "name": "Rock_Basalt"
    },
    {
      "x": 14,
      "y": 13,
      "z": 9,
      "name": "Rock_Basalt"
    },
    {
      "x": 14,
      "y": 21,
      "z": 9,
      "name": "Soil_Mud_Dry"
    },
    {
      "x": 14,
      "y": 22,
      "z": 9,
      "name": "Soil_Dirt_Burnt"
    },
    {
      "x": 14,
      "y": 23,
      "z": 9,
      "name": "Soil_Dirt_Burnt"
    },
    {
      "x": 14,
      "y": 21,
      "z": 10,
      "name": "Soil_Mud_Dry"
    },
    {
      "x": 14,
      "y": 22,
      "z": 10,
      "name": "Soil_Dirt_Burnt"
    },
    {
      "x": 15,
      "y": 20,
      "z": 3,
      "name": "Soil_Mud_Dry"
    },
    {
      "x": 15,
      "y": 21,
      "z": 3,
      "name": "Soil_Mud_Dry"
    },
    {
      "x": 15,
      "y": 22,
      "z": 3,
      "name": "Soil_Dirt_Burnt"
    },
    {
      "x": 15,
      "y": 20,
      "z": 4,
      "name": "Soil_Mud_Dry"
    },
    {
      "x": 15,
      "y": 21,
      "z": 4,
      "name": "Soil_Mud_Dry"
    },
    {
      "x": 15,
      "y": 22,
      "z": 4,
      "name": "Soil_Dirt_Burnt"
    },
    {
      "x": 15,
      "y": 20,
      "z": 5,
      "name": "Soil_Mud_Dry"
    },
    {
      "x": 15,
      "y": 21,
      "z": 5,
      "name": "Soil_Mud_Dry"
    },
    {
      "x": 15,
      "y": 22,
      "z": 5,
      "name": "Soil_Dirt_Burnt"
    },
    {
      "x": 15,
      "y": 23,
      "z": 5,
      "name": "Soil_Dirt_Burnt"
    },
    {
      "x": 15,
      "y": 12,
      "z": 6,
      "name": "Rock_Basalt"
    },
    {
      "x": 15,
      "y": 13,
      "z": 6,
      "name": "Rock_Basalt"
    },
    {
      "x": 15,
      "y": 14,
      "z": 6,
      "name": "Rock_Basalt"
    },
    {
      "x": 15,
      "y": 20,
      "z": 6,
      "name": "Rock_Basalt"
    },
    {
      "x": 15,
      "y": 21,
      "z": 6,
      "name": "Soil_Mud_Dry"
    },
    {
      "x": 15,
      "y": 22,
      "z": 6,
      "name": "Soil_Dirt_Burnt"
    },
    {
      "x": 15,
      "y": 23,
      "z": 6,
      "name": "Soil_Dirt_Burnt"
    },
    {
      "x": 15,
      "y": 10,
      "z": 7,
      "name": "Rock_Basalt"
    },
    {
      "x": 15,
      "y": 11,
      "z": 7,
      "name": "Rock_Basalt"
    },
    {
      "x": 15,
      "y": 12,
      "z": 7,
      "name": "Rock_Basalt"
    },
    {
      "x": 15,
      "y": 13,
      "z": 7,
      "name": "Rock_Basalt"
    },
    {
      "x": 15,
      "y": 14,
      "z": 7,
      "name": "Rock_Basalt"
    },
    {
      "x": 15,
      "y": 19,
      "z": 7,
      "name": "Rock_Basalt"
    },
    {
      "x": 15,
      "y": 20,
      "z": 7,
      "name": "Rock_Basalt"
    },
    {
      "x": 15,
      "y": 21,
      "z": 7,
      "name": "Rock_Basalt"
    },
    {
      "x": 15,
      "y": 22,
      "z": 7,
      "name": "Soil_Dirt_Burnt"
    },
    {
      "x": 15,
      "y": 23,
      "z": 7,
      "name": "Soil_Dirt_Burnt"
    },
    {
      "x": 15,
      "y": 24,
      "z": 7,
      "name": "Soil_Mud_Dry"
    },
    {
      "x": 15,
      "y": 9,
      "z": 8,
      "name": "Rock_Basalt"
    },
    {
      "x": 15,
      "y": 10,
      "z": 8,
      "name": "Rock_Basalt"
    },
    {
      "x": 15,
      "y": 11,
      "z": 8,
      "name": "Rock_Basalt"
    },
    {
      "x": 15,
      "y": 12,
      "z": 8,
      "name": "Rock_Basalt"
    },
    {
      "x": 15,
      "y": 13,
      "z": 8,
      "name": "Rock_Basalt"
    },
    {
      "x": 15,
      "y": 14,
      "z": 8,
      "name": "Rock_Basalt"
    },
    {
      "x": 15,
      "y": 19,
      "z": 8,
      "name": "Rock_Basalt"
    },
    {
      "x": 15,
      "y": 20,
      "z": 8,
      "name": "Rock_Basalt"
    },
    {
      "x": 15,
      "y": 21,
      "z": 8,
      "name": "Rock_Basalt"
    },
    {
      "x": 15,
      "y": 22,
      "z": 8,
      "name": "Soil_Dirt_Burnt"
    },
    {
      "x": 15,
      "y": 23,
      "z": 8,
      "name": "Soil_Dirt_Burnt"
    },
    {
      "x": 15,
      "y": 24,
      "z": 8,
      "name": "Soil_Mud_Dry"
    },
    {
      "x": 15,
      "y": 9,
      "z": 9,
      "name": "Rock_Basalt"
    },
    {
      "x": 15,
      "y": 10,
      "z": 9,
      "name": "Rock_Basalt"
    },
    {
      "x": 15,
      "y": 11,
      "z": 9,
      "name": "Rock_Basalt"
    },
    {
      "x": 15,
      "y": 12,
      "z": 9,
      "name": "Rock_Basalt"
    },
    {
      "x": 15,
      "y": 13,
      "z": 9,
      "name": "Rock_Basalt"
    },
    {
      "x": 15,
      "y": 20,
      "z": 9,
      "name": "Rock_Basalt"
    },
    {
      "x": 15,
      "y": 21,
      "z": 9,
      "name": "Soil_Mud_Dry"
    },
    {
      "x": 15,
      "y": 22,
      "z": 9,
      "name": "Soil_Dirt_Burnt"
    },
    {
      "x": 15,
      "y": 23,
      "z": 9,
      "name": "Soil_Dirt_Burnt"
    },
    {
      "x": 15,
      "y": 24,
      "z": 9,
      "name": "Soil_Mud_Dry"
    },
    {
      "x": 15,
      "y": 11,
      "z": 10,
      "name": "Rock_Basalt"
    },
    {
      "x": 15,
      "y": 12,
      "z": 10,
      "name": "Rock_Basalt"
    },
    {
      "x": 15,
      "y": 13,
      "z": 10,
      "name": "Rock_Basalt"
    },
    {
      "x": 15,
      "y": 20,
      "z": 10,
      "name": "Rock_Basalt"
    },
    {
      "x": 15,
      "y": 21,
      "z": 10,
      "name": "Rock_Basalt"
    },
    {
      "x": 15,
      "y": 22,
      "z": 10,
      "name": "Soil_Dirt_Burnt"
    },
    {
      "x": 15,
      "y": 23,
      "z": 10,
      "name": "Soil_Dirt_Burnt"
    },
    {
      "x": 16,
      "y": 20,
      "z": 3,
      "name": "Rock_Basalt"
    },
    {
      "x": 16,
      "y": 21,
      "z": 3,
      "name": "Soil_Mud_Dry"
    },
    {
      "x": 16,
      "y": 22,
      "z": 3,
      "name": "Soil_Dirt_Burnt"
    },
    {
      "x": 16,
      "y": 20,
      "z": 4,
      "name": "Soil_Mud_Dry"
    },
    {
      "x": 16,
      "y": 21,
      "z": 4,
      "name": "Soil_Mud_Dry"
    },
    {
      "x": 16,
      "y": 22,
      "z": 4,
      "name": "Soil_Dirt_Burnt"
    },
    {
      "x": 16,
      "y": 19,
      "z": 5,
      "name": "Rock_Basalt"
    },
    {
      "x": 16,
      "y": 20,
      "z": 5,
      "name": "Rock_Basalt"
    },
    {
      "x": 16,
      "y": 21,
      "z": 5,
      "name": "Soil_Mud_Dry"
    },
    {
      "x": 16,
      "y": 22,
      "z": 5,
      "name": "Soil_Dirt_Burnt"
    },
    {
      "x": 16,
      "y": 23,
      "z": 5,
      "name": "Soil_Dirt_Burnt"
    },
    {
      "x": 16,
      "y": 12,
      "z": 6,
      "name": "Rock_Basalt"
    },
    {
      "x": 16,
      "y": 13,
      "z": 6,
      "name": "Rock_Basalt"
    },
    {
      "x": 16,
      "y": 19,
      "z": 6,
      "name": "Rock_Basalt"
    },
    {
      "x": 16,
      "y": 20,
      "z": 6,
      "name": "Rock_Basalt"
    },
    {
      "x": 16,
      "y": 21,
      "z": 6,
      "name": "Rock_Basalt"
    },
    {
      "x": 16,
      "y": 22,
      "z": 6,
      "name": "Soil_Dirt_Burnt"
    },
    {
      "x": 16,
      "y": 23,
      "z": 6,
      "name": "Soil_Dirt_Burnt"
    },
    {
      "x": 16,
      "y": 8,
      "z": 7,
      "name": "Rock_Basalt"
    },
    {
      "x": 16,
      "y": 9,
      "z": 7,
      "name": "Rock_Basalt"
    },
    {
      "x": 16,
      "y": 10,
      "z": 7,
      "name": "Rock_Basalt"
    },
    {
      "x": 16,
      "y": 11,
      "z": 7,
      "name": "Rock_Basalt"
    },
    {
      "x": 16,
      "y": 12,
      "z": 7,
      "name": "Rock_Basalt"
    },
    {
      "x": 16,
      "y": 13,
      "z": 7,
      "name": "Rock_Basalt"
    },
    {
      "x": 16,
      "y": 19,
      "z": 7,
      "name": "Rock_Basalt"
    },
    {
      "x": 16,
      "y": 20,
      "z": 7,
      "name": "Rock_Basalt"
    },
    {
      "x": 16,
      "y": 21,
      "z": 7,
      "name": "Rock_Basalt"
    },
    {
      "x": 16,
      "y": 22,
      "z": 7,
      "name": "Soil_Dirt_Burnt"
    },
    {
      "x": 16,
      "y": 23,
      "z": 7,
      "name": "Soil_Dirt_Burnt"
    },
    {
      "x": 16,
      "y": 24,
      "z": 7,
      "name": "Soil_Mud_Dry"
    },
    {
      "x": 16,
      "y": 7,
      "z": 8,
      "name": "Rock_Basalt"
    },
    {
      "x": 16,
      "y": 8,
      "z": 8,
      "name": "Rock_Basalt"
    },
    {
      "x": 16,
      "y": 9,
      "z": 8,
      "name": "Rock_Basalt"
    },
    {
      "x": 16,
      "y": 10,
      "z": 8,
      "name": "Rock_Basalt"
    },
    {
      "x": 16,
      "y": 11,
      "z": 8,
      "name": "Rock_Basalt"
    },
    {
      "x": 16,
      "y": 12,
      "z": 8,
      "name": "Rock_Basalt"
    },
    {
      "x": 16,
      "y": 13,
      "z": 8,
      "name": "Rock_Basalt"
    },
    {
      "x": 16,
      "y": 19,
      "z": 8,
      "name": "Rock_Basalt"
    },
    {
      "x": 16,
      "y": 20,
      "z": 8,
      "name": "Rock_Basalt"
    },
    {
      "x": 16,
      "y": 21,
      "z": 8,
      "name": "Rock_Basalt"
    },
    {
      "x": 16,
      "y": 22,
      "z": 8,
      "name": "Soil_Dirt_Burnt"
    },
    {
      "x": 16,
      "y": 23,
      "z": 8,
      "name": "Soil_Dirt_Burnt"
    },
    {
      "x": 16,
      "y": 24,
      "z": 8,
      "name": "Soil_Mud_Dry"
    },
    {
      "x": 16,
      "y": 6,
      "z": 9,
      "name": "Rock_Basalt"
    },
    {
      "x": 16,
      "y": 7,
      "z": 9,
      "name": "Rock_Basalt"
    },
    {
      "x": 16,
      "y": 8,
      "z": 9,
      "name": "Rock_Basalt"
    },
    {
      "x": 16,
      "y": 9,
      "z": 9,
      "name": "Rock_Basalt"
    },
    {
      "x": 16,
      "y": 10,
      "z": 9,
      "name": "Rock_Basalt"
    },
    {
      "x": 16,
      "y": 11,
      "z": 9,
      "name": "Rock_Basalt"
    },
    {
      "x": 16,
      "y": 12,
      "z": 9,
      "name": "Rock_Basalt"
    },
    {
      "x": 16,
      "y": 20,
      "z": 9,
      "name": "Rock_Basalt"
    },
    {
      "x": 16,
      "y": 21,
      "z": 9,
      "name": "Rock_Basalt"
    },
    {
      "x": 16,
      "y": 22,
      "z": 9,
      "name": "Soil_Dirt_Burnt"
    },
    {
      "x": 16,
      "y": 23,
      "z": 9,
      "name": "Soil_Dirt_Burnt"
    },
    {
      "x": 16,
      "y": 24,
      "z": 9,
      "name": "Soil_Mud_Dry"
    },
    {
      "x": 16,
      "y": 8,
      "z": 10,
      "name": "Rock_Basalt"
    },
    {
      "x": 16,
      "y": 9,
      "z": 10,
      "name": "Rock_Basalt"
    },
    {
      "x": 16,
      "y": 10,
      "z": 10,
      "name": "Rock_Basalt"
    },
    {
      "x": 16,
      "y": 20,
      "z": 10,
      "name": "Rock_Basalt"
    },
    {
      "x": 16,
      "y": 21,
      "z": 10,
      "name": "Rock_Basalt"
    },
    {
      "x": 16,
      "y": 22,
      "z": 10,
      "name": "Soil_Dirt_Burnt"
    },
    {
      "x": 16,
      "y": 23,
      "z": 10,
      "name": "Soil_Dirt_Burnt"
    },
    {
      "x": 16,
      "y": 21,
      "z": 11,
      "name": "Rock_Basalt"
    },
    {
      "x": 16,
      "y": 22,
      "z": 11,
      "name": "Soil_Dirt_Burnt"
    },
    {
      "x": 17,
      "y": 21,
      "z": 3,
      "name": "Rock_Basalt"
    },
    {
      "x": 17,
      "y": 22,
      "z": 3,
      "name": "Soil_Dirt_Burnt"
    },
    {
      "x": 17,
      "y": 19,
      "z": 4,
      "name": "Rock_Basalt"
    },
    {
      "x": 17,
      "y": 20,
      "z": 4,
      "name": "Rock_Basalt"
    },
    {
      "x": 17,
      "y": 21,
      "z": 4,
      "name": "Soil_Mud_Dry"
    },
    {
      "x": 17,
      "y": 22,
      "z": 4,
      "name": "Soil_Dirt_Burnt"
    },
    {
      "x": 17,
      "y": 23,
      "z": 4,
      "name": "Soil_Dirt_Burnt"
    },
    {
      "x": 17,
      "y": 19,
      "z": 5,
      "name": "Rock_Basalt"
    },
    {
      "x": 17,
      "y": 20,
      "z": 5,
      "name": "Rock_Basalt"
    },
    {
      "x": 17,
      "y": 21,
      "z": 5,
      "name": "Rock_Basalt"
    },
    {
      "x": 17,
      "y": 22,
      "z": 5,
      "name": "Soil_Dirt_Burnt"
    },
    {
      "x": 17,
      "y": 23,
      "z": 5,
      "name": "Soil_Dirt_Burnt"
    },
    {
      "x": 17,
      "y": 19,
      "z": 6,
      "name": "Rock_Basalt"
    },
    {
      "x": 17,
      "y": 20,
      "z": 6,
      "name": "Rock_Basalt"
    },
    {
      "x": 17,
      "y": 21,
      "z": 6,
      "name": "Rock_Basalt"
    },
    {
      "x": 17,
      "y": 22,
      "z": 6,
      "name": "Soil_Dirt_Burnt"
    },
    {
      "x": 17,
      "y": 23,
      "z": 6,
      "name": "Soil_Dirt_Burnt"
    },
    {
      "x": 17,
      "y": 24,
      "z": 6,
      "name": "Soil_Mud_Dry"
    },
    {
      "x": 17,
      "y": 7,
      "z": 7,
      "name": "Rock_Basalt"
    },
    {
      "x": 17,
      "y": 8,
      "z": 7,
      "name": "Rock_Basalt"
    },
    {
      "x": 17,
      "y": 9,
      "z": 7,
      "name": "Rock_Basalt"
    },
    {
      "x": 17,
      "y": 10,
      "z": 7,
      "name": "Rock_Basalt"
    },
    {
      "x": 17,
      "y": 11,
      "z": 7,
      "name": "Rock_Basalt"
    },
    {
      "x": 17,
      "y": 12,
      "z": 7,
      "name": "Rock_Basalt"
    },
    {
      "x": 17,
      "y": 19,
      "z": 7,
      "name": "Rock_Basalt"
    },
    {
      "x": 17,
      "y": 20,
      "z": 7,
      "name": "Rock_Basalt"
    },
    {
      "x": 17,
      "y": 21,
      "z": 7,
      "name": "Rock_Basalt"
    },
    {
      "x": 17,
      "y": 22,
      "z": 7,
      "name": "Soil_Dirt_Burnt"
    },
    {
      "x": 17,
      "y": 23,
      "z": 7,
      "name": "Soil_Dirt_Burnt"
    },
    {
      "x": 17,
      "y": 24,
      "z": 7,
      "name": "Soil_Mud_Dry"
    },
    {
      "x": 17,
      "y": 6,
      "z": 8,
      "name": "Rock_Basalt"
    },
    {
      "x": 17,
      "y": 7,
      "z": 8,
      "name": "Rock_Basalt"
    },
    {
      "x": 17,
      "y": 8,
      "z": 8,
      "name": "Rock_Basalt"
    },
    {
      "x": 17,
      "y": 9,
      "z": 8,
      "name": "Rock_Basalt"
    },
    {
      "x": 17,
      "y": 10,
      "z": 8,
      "name": "Rock_Basalt"
    },
    {
      "x": 17,
      "y": 11,
      "z": 8,
      "name": "Rock_Basalt"
    },
    {
      "x": 17,
      "y": 19,
      "z": 8,
      "name": "Rock_Basalt"
    },
    {
      "x": 17,
      "y": 20,
      "z": 8,
      "name": "Rock_Basalt"
    },
    {
      "x": 17,
      "y": 21,
      "z": 8,
      "name": "Rock_Basalt"
    },
    {
      "x": 17,
      "y": 22,
      "z": 8,
      "name": "Soil_Dirt_Burnt"
    },
    {
      "x": 17,
      "y": 23,
      "z": 8,
      "name": "Soil_Dirt_Burnt"
    },
    {
      "x": 17,
      "y": 24,
      "z": 8,
      "name": "Soil_Mud_Dry"
    },
    {
      "x": 17,
      "y": 6,
      "z": 9,
      "name": "Rock_Basalt"
    },
    {
      "x": 17,
      "y": 7,
      "z": 9,
      "name": "Rock_Basalt"
    },
    {
      "x": 17,
      "y": 8,
      "z": 9,
      "name": "Rock_Basalt"
    },
    {
      "x": 17,
      "y": 9,
      "z": 9,
      "name": "Rock_Basalt"
    },
    {
      "x": 17,
      "y": 10,
      "z": 9,
      "name": "Rock_Basalt"
    },
    {
      "x": 17,
      "y": 11,
      "z": 9,
      "name": "Rock_Basalt"
    },
    {
      "x": 17,
      "y": 19,
      "z": 9,
      "name": "Rock_Basalt"
    },
    {
      "x": 17,
      "y": 20,
      "z": 9,
      "name": "Rock_Basalt"
    },
    {
      "x": 17,
      "y": 21,
      "z": 9,
      "name": "Rock_Basalt"
    },
    {
      "x": 17,
      "y": 22,
      "z": 9,
      "name": "Soil_Dirt_Burnt"
    },
    {
      "x": 17,
      "y": 23,
      "z": 9,
      "name": "Soil_Dirt_Burnt"
    },
    {
      "x": 17,
      "y": 24,
      "z": 9,
      "name": "Soil_Mud_Dry"
    },
    {
      "x": 17,
      "y": 6,
      "z": 10,
      "name": "Rock_Basalt"
    },
    {
      "x": 17,
      "y": 7,
      "z": 10,
      "name": "Rock_Basalt"
    },
    {
      "x": 17,
      "y": 8,
      "z": 10,
      "name": "Rock_Basalt"
    },
    {
      "x": 17,
      "y": 9,
      "z": 10,
      "name": "Rock_Basalt"
    },
    {
      "x": 17,
      "y": 10,
      "z": 10,
      "name": "Rock_Basalt"
    },
    {
      "x": 17,
      "y": 20,
      "z": 10,
      "name": "Rock_Basalt"
    },
    {
      "x": 17,
      "y": 21,
      "z": 10,
      "name": "Rock_Basalt"
    },
    {
      "x": 17,
      "y": 22,
      "z": 10,
      "name": "Soil_Dirt_Burnt"
    },
    {
      "x": 17,
      "y": 23,
      "z": 10,
      "name": "Soil_Dirt_Burnt"
    },
    {
      "x": 17,
      "y": 24,
      "z": 10,
      "name": "Soil_Mud_Dry"
    },
    {
      "x": 17,
      "y": 20,
      "z": 11,
      "name": "Rock_Basalt"
    },
    {
      "x": 17,
      "y": 21,
      "z": 11,
      "name": "Rock_Basalt"
    },
    {
      "x": 17,
      "y": 22,
      "z": 11,
      "name": "Soil_Dirt_Burnt"
    },
    {
      "x": 17,
      "y": 23,
      "z": 11,
      "name": "Soil_Dirt_Burnt"
    },
    {
      "x": 18,
      "y": 21,
      "z": 3,
      "name": "Rock_Basalt"
    },
    {
      "x": 18,
      "y": 22,
      "z": 3,
      "name": "Soil_Dirt_Burnt"
    },
    {
      "x": 18,
      "y": 19,
      "z": 4,
      "name": "Rock_Basalt"
    },
    {
      "x": 18,
      "y": 20,
      "z": 4,
      "name": "Rock_Basalt"
    },
    {
      "x": 18,
      "y": 21,
      "z": 4,
      "name": "Soil_Mud_Dry"
    },
    {
      "x": 18,
      "y": 22,
      "z": 4,
      "name": "Soil_Dirt_Burnt"
    },
    {
      "x": 18,
      "y": 23,
      "z": 4,
      "name": "Soil_Dirt_Burnt"
    },
    {
      "x": 18,
      "y": 19,
      "z": 5,
      "name": "Rock_Basalt"
    },
    {
      "x": 18,
      "y": 20,
      "z": 5,
      "name": "Rock_Basalt"
    },
    {
      "x": 18,
      "y": 21,
      "z": 5,
      "name": "Rock_Basalt"
    },
    {
      "x": 18,
      "y": 22,
      "z": 5,
      "name": "Soil_Dirt_Burnt"
    },
    {
      "x": 18,
      "y": 23,
      "z": 5,
      "name": "Soil_Dirt_Burnt"
    },
    {
      "x": 18,
      "y": 19,
      "z": 6,
      "name": "Rock_Basalt"
    },
    {
      "x": 18,
      "y": 20,
      "z": 6,
      "name": "Rock_Basalt"
    },
    {
      "x": 18,
      "y": 21,
      "z": 6,
      "name": "Rock_Basalt"
    },
    {
      "x": 18,
      "y": 22,
      "z": 6,
      "name": "Soil_Dirt_Burnt"
    },
    {
      "x": 18,
      "y": 23,
      "z": 6,
      "name": "Soil_Dirt_Burnt"
    },
    {
      "x": 18,
      "y": 24,
      "z": 6,
      "name": "Soil_Mud_Dry"
    },
    {
      "x": 18,
      "y": 6,
      "z": 7,
      "name": "Rock_Basalt"
    },
    {
      "x": 18,
      "y": 7,
      "z": 7,
      "name": "Rock_Basalt"
    },
    {
      "x": 18,
      "y": 8,
      "z": 7,
      "name": "Rock_Basalt"
    },
    {
      "x": 18,
      "y": 19,
      "z": 7,
      "name": "Rock_Basalt"
    },
    {
      "x": 18,
      "y": 20,
      "z": 7,
      "name": "Rock_Basalt"
    },
    {
      "x": 18,
      "y": 21,
      "z": 7,
      "name": "Rock_Basalt"
    },
    {
      "x": 18,
      "y": 22,
      "z": 7,
      "name": "Soil_Dirt_Burnt"
    },
    {
      "x": 18,
      "y": 23,
      "z": 7,
      "name": "Soil_Dirt_Burnt"
    },
    {
      "x": 18,
      "y": 24,
      "z": 7,
      "name": "Soil_Mud_Dry"
    },
    {
      "x": 18,
      "y": 5,
      "z": 8,
      "name": "Rock_Basalt"
    },
    {
      "x": 18,
      "y": 6,
      "z": 8,
      "name": "Rock_Basalt"
    },
    {
      "x": 18,
      "y": 7,
      "z": 8,
      "name": "Rock_Basalt"
    },
    {
      "x": 18,
      "y": 8,
      "z": 8,
      "name": "Rock_Basalt"
    },
    {
      "x": 18,
      "y": 9,
      "z": 8,
      "name": "Rock_Basalt"
    },
    {
      "x": 18,
      "y": 10,
      "z": 8,
      "name": "Rock_Basalt"
    },
    {
      "x": 18,
      "y": 19,
      "z": 8,
      "name": "Rock_Basalt"
    },
    {
      "x": 18,
      "y": 20,
      "z": 8,
      "name": "Rock_Basalt"
    },
    {
      "x": 18,
      "y": 21,
      "z": 8,
      "name": "Rock_Basalt"
    },
    {
      "x": 18,
      "y": 22,
      "z": 8,
      "name": "Soil_Dirt_Burnt"
    },
    {
      "x": 18,
      "y": 23,
      "z": 8,
      "name": "Soil_Dirt_Burnt"
    },
    {
      "x": 18,
      "y": 24,
      "z": 8,
      "name": "Soil_Dirt_Burnt"
    },
    {
      "x": 18,
      "y": 5,
      "z": 9,
      "name": "Rock_Basalt"
    },
    {
      "x": 18,
      "y": 6,
      "z": 9,
      "name": "Rock_Basalt"
    },
    {
      "x": 18,
      "y": 7,
      "z": 9,
      "name": "Rock_Basalt"
    },
    {
      "x": 18,
      "y": 8,
      "z": 9,
      "name": "Rock_Basalt"
    },
    {
      "x": 18,
      "y": 9,
      "z": 9,
      "name": "Rock_Basalt"
    },
    {
      "x": 18,
      "y": 19,
      "z": 9,
      "name": "Rock_Basalt"
    },
    {
      "x": 18,
      "y": 20,
      "z": 9,
      "name": "Rock_Basalt"
    },
    {
      "x": 18,
      "y": 21,
      "z": 9,
      "name": "Rock_Basalt"
    },
    {
      "x": 18,
      "y": 22,
      "z": 9,
      "name": "Soil_Dirt_Burnt"
    },
    {
      "x": 18,
      "y": 23,
      "z": 9,
      "name": "Soil_Dirt_Burnt"
    },
    {
      "x": 18,
      "y": 24,
      "z": 9,
      "name": "Soil_Dirt_Burnt"
    },
    {
      "x": 18,
      "y": 5,
      "z": 10,
      "name": "Rock_Basalt"
    },
    {
      "x": 18,
      "y": 6,
      "z": 10,
      "name": "Rock_Basalt"
    },
    {
      "x": 18,
      "y": 7,
      "z": 10,
      "name": "Rock_Basalt"
    },
    {
      "x": 18,
      "y": 20,
      "z": 10,
      "name": "Rock_Basalt"
    },
    {
      "x": 18,
      "y": 21,
      "z": 10,
      "name": "Rock_Basalt"
    },
    {
      "x": 18,
      "y": 22,
      "z": 10,
      "name": "Soil_Dirt_Burnt"
    },
    {
      "x": 18,
      "y": 23,
      "z": 10,
      "name": "Soil_Dirt_Burnt"
    },
    {
      "x": 18,
      "y": 24,
      "z": 10,
      "name": "Soil_Dirt_Burnt"
    },
    {
      "x": 18,
      "y": 20,
      "z": 11,
      "name": "Rock_Basalt"
    },
    {
      "x": 18,
      "y": 21,
      "z": 11,
      "name": "Rock_Basalt"
    },
    {
      "x": 18,
      "y": 22,
      "z": 11,
      "name": "Soil_Dirt_Burnt"
    },
    {
      "x": 18,
      "y": 23,
      "z": 11,
      "name": "Soil_Dirt_Burnt"
    },
    {
      "x": 18,
      "y": 24,
      "z": 11,
      "name": "Soil_Dirt_Burnt"
    },
    {
      "x": 18,
      "y": 21,
      "z": 12,
      "name": "Rock_Basalt"
    },
    {
      "x": 18,
      "y": 22,
      "z": 12,
      "name": "Soil_Dirt_Burnt"
    },
    {
      "x": 19,
      "y": 21,
      "z": 3,
      "name": "Soil_Mud_Dry"
    },
    {
      "x": 19,
      "y": 22,
      "z": 3,
      "name": "Soil_Dirt_Burnt"
    },
    {
      "x": 19,
      "y": 19,
      "z": 4,
      "name": "Rock_Basalt"
    },
    {
      "x": 19,
      "y": 20,
      "z": 4,
      "name": "Rock_Basalt"
    },
    {
      "x": 19,
      "y": 21,
      "z": 4,
      "name": "Soil_Mud_Dry"
    },
    {
      "x": 19,
      "y": 22,
      "z": 4,
      "name": "Soil_Dirt_Burnt"
    },
    {
      "x": 19,
      "y": 23,
      "z": 4,
      "name": "Soil_Dirt_Burnt"
    },
    {
      "x": 19,
      "y": 19,
      "z": 5,
      "name": "Rock_Basalt"
    },
    {
      "x": 19,
      "y": 20,
      "z": 5,
      "name": "Rock_Basalt"
    },
    {
      "x": 19,
      "y": 21,
      "z": 5,
      "name": "Soil_Mud_Dry"
    },
    {
      "x": 19,
      "y": 22,
      "z": 5,
      "name": "Soil_Dirt_Burnt"
    },
    {
      "x": 19,
      "y": 23,
      "z": 5,
      "name": "Soil_Dirt_Burnt"
    },
    {
      "x": 19,
      "y": 19,
      "z": 6,
      "name": "Rock_Basalt"
    },
    {
      "x": 19,
      "y": 20,
      "z": 6,
      "name": "Rock_Basalt"
    },
    {
      "x": 19,
      "y": 21,
      "z": 6,
      "name": "Rock_Basalt"
    },
    {
      "x": 19,
      "y": 22,
      "z": 6,
      "name": "Soil_Dirt_Burnt"
    },
    {
      "x": 19,
      "y": 23,
      "z": 6,
      "name": "Soil_Dirt_Burnt"
    },
    {
      "x": 19,
      "y": 24,
      "z": 6,
      "name": "Soil_Dirt_Burnt"
    },
    {
      "x": 19,
      "y": 19,
      "z": 7,
      "name": "Rock_Basalt"
    },
    {
      "x": 19,
      "y": 20,
      "z": 7,
      "name": "Rock_Basalt"
    },
    {
      "x": 19,
      "y": 21,
      "z": 7,
      "name": "Rock_Basalt"
    },
    {
      "x": 19,
      "y": 22,
      "z": 7,
      "name": "Soil_Dirt_Burnt"
    },
    {
      "x": 19,
      "y": 23,
      "z": 7,
      "name": "Soil_Dirt_Burnt"
    },
    {
      "x": 19,
      "y": 24,
      "z": 7,
      "name": "Soil_Dirt_Burnt"
    },
    {
      "x": 19,
      "y": 7,
      "z": 8,
      "name": "Rock_Basalt"
    },
    {
      "x": 19,
      "y": 8,
      "z": 8,
      "name": "Rock_Basalt"
    },
    {
      "x": 19,
      "y": 19,
      "z": 8,
      "name": "Rock_Basalt"
    },
    {
      "x": 19,
      "y": 20,
      "z": 8,
      "name": "Rock_Basalt"
    },
    {
      "x": 19,
      "y": 21,
      "z": 8,
      "name": "Rock_Basalt"
    },
    {
      "x": 19,
      "y": 22,
      "z": 8,
      "name": "Soil_Dirt_Burnt"
    },
    {
      "x": 19,
      "y": 23,
      "z": 8,
      "name": "Soil_Dirt_Burnt"
    },
    {
      "x": 19,
      "y": 24,
      "z": 8,
      "name": "Soil_Dirt_Burnt"
    },
    {
      "x": 19,
      "y": 25,
      "z": 8,
      "name": "Soil_Mud_Dry"
    },
    {
      "x": 19,
      "y": 5,
      "z": 9,
      "name": "Rock_Basalt"
    },
    {
      "x": 19,
      "y": 6,
      "z": 9,
      "name": "Rock_Basalt"
    },
    {
      "x": 19,
      "y": 7,
      "z": 9,
      "name": "Rock_Basalt"
    },
    {
      "x": 19,
      "y": 19,
      "z": 9,
      "name": "Rock_Basalt"
    },
    {
      "x": 19,
      "y": 20,
      "z": 9,
      "name": "Rock_Basalt"
    },
    {
      "x": 19,
      "y": 21,
      "z": 9,
      "name": "Rock_Basalt"
    },
    {
      "x": 19,
      "y": 22,
      "z": 9,
      "name": "Soil_Dirt_Burnt"
    },
    {
      "x": 19,
      "y": 23,
      "z": 9,
      "name": "Soil_Dirt_Burnt"
    },
    {
      "x": 19,
      "y": 24,
      "z": 9,
      "name": "Soil_Dirt_Burnt"
    },
    {
      "x": 19,
      "y": 25,
      "z": 9,
      "name": "Soil_Mud_Dry"
    },
    {
      "x": 19,
      "y": 5,
      "z": 10,
      "name": "Rock_Basalt"
    },
    {
      "x": 19,
      "y": 20,
      "z": 10,
      "name": "Rock_Basalt"
    },
    {
      "x": 19,
      "y": 21,
      "z": 10,
      "name": "Rock_Basalt"
    },
    {
      "x": 19,
      "y": 22,
      "z": 10,
      "name": "Soil_Dirt_Burnt"
    },
    {
      "x": 19,
      "y": 23,
      "z": 10,
      "name": "Soil_Dirt_Burnt"
    },
    {
      "x": 19,
      "y": 24,
      "z": 10,
      "name": "Soil_Dirt_Burnt"
    },
    {
      "x": 19,
      "y": 25,
      "z": 10,
      "name": "Soil_Mud_Dry"
    },
    {
      "x": 19,
      "y": 20,
      "z": 11,
      "name": "Rock_Basalt"
    },
    {
      "x": 19,
      "y": 21,
      "z": 11,
      "name": "Rock_Basalt"
    },
    {
      "x": 19,
      "y": 22,
      "z": 11,
      "name": "Soil_Dirt_Burnt"
    },
    {
      "x": 19,
      "y": 23,
      "z": 11,
      "name": "Soil_Dirt_Burnt"
    },
    {
      "x": 19,
      "y": 24,
      "z": 11,
      "name": "Soil_Dirt_Burnt"
    },
    {
      "x": 19,
      "y": 20,
      "z": 12,
      "name": "Rock_Basalt"
    },
    {
      "x": 19,
      "y": 21,
      "z": 12,
      "name": "Rock_Basalt"
    },
    {
      "x": 19,
      "y": 22,
      "z": 12,
      "name": "Soil_Dirt_Burnt"
    },
    {
      "x": 19,
      "y": 23,
      "z": 12,
      "name": "Soil_Dirt_Burnt"
    },
    {
      "x": 20,
      "y": 21,
      "z": 3,
      "name": "Rock_Basalt"
    },
    {
      "x": 20,
      "y": 20,
      "z": 4,
      "name": "Rock_Basalt"
    },
    {
      "x": 20,
      "y": 21,
      "z": 4,
      "name": "Soil_Mud_Dry"
    },
    {
      "x": 20,
      "y": 22,
      "z": 4,
      "name": "Soil_Dirt_Burnt"
    },
    {
      "x": 20,
      "y": 23,
      "z": 4,
      "name": "Soil_Dirt_Burnt"
    },
    {
      "x": 20,
      "y": 20,
      "z": 5,
      "name": "Rock_Basalt"
    },
    {
      "x": 20,
      "y": 21,
      "z": 5,
      "name": "Rock_Basalt"
    },
    {
      "x": 20,
      "y": 22,
      "z": 5,
      "name": "Soil_Dirt_Burnt"
    },
    {
      "x": 20,
      "y": 23,
      "z": 5,
      "name": "Soil_Dirt_Burnt"
    },
    {
      "x": 20,
      "y": 24,
      "z": 5,
      "name": "Soil_Dirt_Burnt"
    },
    {
      "x": 20,
      "y": 19,
      "z": 6,
      "name": "Rock_Basalt"
    },
    {
      "x": 20,
      "y": 20,
      "z": 6,
      "name": "Rock_Basalt"
    },
    {
      "x": 20,
      "y": 21,
      "z": 6,
      "name": "Rock_Basalt"
    },
    {
      "x": 20,
      "y": 22,
      "z": 6,
      "name": "Soil_Dirt_Burnt"
    },
    {
      "x": 20,
      "y": 23,
      "z": 6,
      "name": "Soil_Dirt_Burnt"
    },
    {
      "x": 20,
      "y": 24,
      "z": 6,
      "name": "Soil_Dirt_Burnt"
    },
    {
      "x": 20,
      "y": 19,
      "z": 7,
      "name": "Rock_Basalt"
    },
    {
      "x": 20,
      "y": 20,
      "z": 7,
      "name": "Rock_Basalt"
    },
    {
      "x": 20,
      "y": 21,
      "z": 7,
      "name": "Rock_Basalt"
    },
    {
      "x": 20,
      "y": 22,
      "z": 7,
      "name": "Soil_Dirt_Burnt"
    },
    {
      "x": 20,
      "y": 23,
      "z": 7,
      "name": "Soil_Dirt_Burnt"
    },
    {
      "x": 20,
      "y": 24,
      "z": 7,
      "name": "Soil_Dirt_Burnt"
    },
    {
      "x": 20,
      "y": 19,
      "z": 8,
      "name": "Rock_Basalt"
    },
    {
      "x": 20,
      "y": 20,
      "z": 8,
      "name": "Rock_Basalt"
    },
    {
      "x": 20,
      "y": 21,
      "z": 8,
      "name": "Rock_Basalt"
    },
    {
      "x": 20,
      "y": 22,
      "z": 8,
      "name": "Soil_Dirt_Burnt"
    },
    {
      "x": 20,
      "y": 23,
      "z": 8,
      "name": "Soil_Dirt_Burnt"
    },
    {
      "x": 20,
      "y": 24,
      "z": 8,
      "name": "Soil_Dirt_Burnt"
    },
    {
      "x": 20,
      "y": 25,
      "z": 8,
      "name": "Soil_Mud_Dry"
    },
    {
      "x": 20,
      "y": 19,
      "z": 9,
      "name": "Rock_Basalt"
    },
    {
      "x": 20,
      "y": 20,
      "z": 9,
      "name": "Rock_Basalt"
    },
    {
      "x": 20,
      "y": 21,
      "z": 9,
      "name": "Rock_Basalt"
    },
    {
      "x": 20,
      "y": 22,
      "z": 9,
      "name": "Soil_Dirt_Burnt"
    },
    {
      "x": 20,
      "y": 23,
      "z": 9,
      "name": "Soil_Dirt_Burnt"
    },
    {
      "x": 20,
      "y": 24,
      "z": 9,
      "name": "Soil_Dirt_Burnt"
    },
    {
      "x": 20,
      "y": 25,
      "z": 9,
      "name": "Soil_Mud_Dry"
    },
    {
      "x": 20,
      "y": 20,
      "z": 10,
      "name": "Rock_Basalt"
    },
    {
      "x": 20,
      "y": 21,
      "z": 10,
      "name": "Rock_Basalt"
    },
    {
      "x": 20,
      "y": 22,
      "z": 10,
      "name": "Soil_Dirt_Burnt"
    },
    {
      "x": 20,
      "y": 23,
      "z": 10,
      "name": "Soil_Dirt_Burnt"
    },
    {
      "x": 20,
      "y": 24,
      "z": 10,
      "name": "Soil_Dirt_Burnt"
    },
    {
      "x": 20,
      "y": 25,
      "z": 10,
      "name": "Soil_Mud_Dry"
    },
    {
      "x": 20,
      "y": 20,
      "z": 11,
      "name": "Rock_Basalt"
    },
    {
      "x": 20,
      "y": 21,
      "z": 11,
      "name": "Rock_Basalt"
    },
    {
      "x": 20,
      "y": 22,
      "z": 11,
      "name": "Soil_Dirt_Burnt"
    },
    {
      "x": 20,
      "y": 23,
      "z": 11,
      "name": "Soil_Dirt_Burnt"
    },
    {
      "x": 20,
      "y": 24,
      "z": 11,
      "name": "Soil_Dirt_Burnt"
    },
    {
      "x": 20,
      "y": 20,
      "z": 12,
      "name": "Rock_Basalt"
    },
    {
      "x": 20,
      "y": 21,
      "z": 12,
      "name": "Rock_Basalt"
    },
    {
      "x": 20,
      "y": 22,
      "z": 12,
      "name": "Soil_Dirt_Burnt"
    },
    {
      "x": 20,
      "y": 23,
      "z": 12,
      "name": "Soil_Dirt_Burnt"
    },
    {
      "x": 20,
      "y": 24,
      "z": 12,
      "name": "Soil_Dirt_Burnt"
    },
    {
      "x": 20,
      "y": 22,
      "z": 13,
      "name": "Rock_Basalt"
    },
    {
      "x": 20,
      "y": 23,
      "z": 13,
      "name": "Soil_Dirt_Burnt"
    },
    {
      "x": 21,
      "y": 20,
      "z": 3,
      "name": "Rock_Basalt"
    },
    {
      "x": 21,
      "y": 21,
      "z": 3,
      "name": "Rock_Basalt"
    },
    {
      "x": 21,
      "y": 20,
      "z": 4,
      "name": "Rock_Basalt"
    },
    {
      "x": 21,
      "y": 21,
      "z": 4,
      "name": "Rock_Basalt"
    },
    {
      "x": 21,
      "y": 22,
      "z": 4,
      "name": "Soil_Dirt_Burnt"
    },
    {
      "x": 21,
      "y": 23,
      "z": 4,
      "name": "Soil_Dirt_Burnt"
    },
    {
      "x": 21,
      "y": 19,
      "z": 5,
      "name": "Rock_Basalt"
    },
    {
      "x": 21,
      "y": 20,
      "z": 5,
      "name": "Rock_Basalt"
    },
    {
      "x": 21,
      "y": 21,
      "z": 5,
      "name": "Rock_Basalt"
    },
    {
      "x": 21,
      "y": 22,
      "z": 5,
      "name": "Soil_Dirt_Burnt"
    },
    {
      "x": 21,
      "y": 23,
      "z": 5,
      "name": "Soil_Dirt_Burnt"
    },
    {
      "x": 21,
      "y": 24,
      "z": 5,
      "name": "Soil_Dirt_Burnt"
    },
    {
      "x": 21,
      "y": 19,
      "z": 6,
      "name": "Rock_Basalt"
    },
    {
      "x": 21,
      "y": 20,
      "z": 6,
      "name": "Rock_Basalt"
    },
    {
      "x": 21,
      "y": 21,
      "z": 6,
      "name": "Rock_Basalt"
    },
    {
      "x": 21,
      "y": 22,
      "z": 6,
      "name": "Soil_Dirt_Burnt"
    },
    {
      "x": 21,
      "y": 23,
      "z": 6,
      "name": "Soil_Dirt_Burnt"
    },
    {
      "x": 21,
      "y": 24,
      "z": 6,
      "name": "Soil_Dirt_Burnt"
    },
    {
      "x": 21,
      "y": 19,
      "z": 7,
      "name": "Rock_Basalt"
    },
    {
      "x": 21,
      "y": 20,
      "z": 7,
      "name": "Rock_Basalt"
    },
    {
      "x": 21,
      "y": 21,
      "z": 7,
      "name": "Rock_Basalt"
    },
    {
      "x": 21,
      "y": 22,
      "z": 7,
      "name": "Soil_Dirt_Burnt"
    },
    {
      "x": 21,
      "y": 23,
      "z": 7,
      "name": "Soil_Dirt_Burnt"
    },
    {
      "x": 21,
      "y": 24,
      "z": 7,
      "name": "Soil_Dirt_Burnt"
    },
    {
      "x": 21,
      "y": 19,
      "z": 8,
      "name": "Rock_Basalt"
    },
    {
      "x": 21,
      "y": 20,
      "z": 8,
      "name": "Rock_Basalt"
    },
    {
      "x": 21,
      "y": 21,
      "z": 8,
      "name": "Rock_Basalt"
    },
    {
      "x": 21,
      "y": 22,
      "z": 8,
      "name": "Soil_Dirt_Burnt"
    },
    {
      "x": 21,
      "y": 23,
      "z": 8,
      "name": "Soil_Dirt_Burnt"
    },
    {
      "x": 21,
      "y": 24,
      "z": 8,
      "name": "Soil_Dirt_Burnt"
    },
    {
      "x": 21,
      "y": 25,
      "z": 8,
      "name": "Soil_Mud_Dry"
    },
    {
      "x": 21,
      "y": 19,
      "z": 9,
      "name": "Rock_Basalt"
    },
    {
      "x": 21,
      "y": 20,
      "z": 9,
      "name": "Rock_Basalt"
    },
    {
      "x": 21,
      "y": 21,
      "z": 9,
      "name": "Rock_Basalt"
    },
    {
      "x": 21,
      "y": 22,
      "z": 9,
      "name": "Soil_Dirt_Burnt"
    },
    {
      "x": 21,
      "y": 23,
      "z": 9,
      "name": "Soil_Dirt_Burnt"
    },
    {
      "x": 21,
      "y": 24,
      "z": 9,
      "name": "Soil_Dirt_Burnt"
    },
    {
      "x": 21,
      "y": 25,
      "z": 9,
      "name": "Soil_Mud_Dry"
    },
    {
      "x": 21,
      "y": 20,
      "z": 10,
      "name": "Rock_Basalt"
    },
    {
      "x": 21,
      "y": 21,
      "z": 10,
      "name": "Rock_Basalt"
    },
    {
      "x": 21,
      "y": 22,
      "z": 10,
      "name": "Soil_Dirt_Burnt"
    },
    {
      "x": 21,
      "y": 23,
      "z": 10,
      "name": "Soil_Dirt_Burnt"
    },
    {
      "x": 21,
      "y": 24,
      "z": 10,
      "name": "Soil_Dirt_Burnt"
    },
    {
      "x": 21,
      "y": 25,
      "z": 10,
      "name": "Soil_Mud_Dry"
    },
    {
      "x": 21,
      "y": 20,
      "z": 11,
      "name": "Soil_Dirt_Burnt"
    },
    {
      "x": 21,
      "y": 21,
      "z": 11,
      "name": "Rock_Basalt"
    },
    {
      "x": 21,
      "y": 22,
      "z": 11,
      "name": "Soil_Dirt_Burnt"
    },
    {
      "x": 21,
      "y": 23,
      "z": 11,
      "name": "Soil_Dirt_Burnt"
    },
    {
      "x": 21,
      "y": 24,
      "z": 11,
      "name": "Soil_Dirt_Burnt"
    },
    {
      "x": 21,
      "y": 20,
      "z": 12,
      "name": "Soil_Dirt_Burnt"
    },
    {
      "x": 21,
      "y": 21,
      "z": 12,
      "name": "Rock_Basalt"
    },
    {
      "x": 21,
      "y": 22,
      "z": 12,
      "name": "Rock_Basalt"
    },
    {
      "x": 21,
      "y": 23,
      "z": 12,
      "name": "Soil_Dirt_Burnt"
    },
    {
      "x": 21,
      "y": 24,
      "z": 12,
      "name": "Soil_Dirt_Burnt"
    },
    {
      "x": 21,
      "y": 22,
      "z": 13,
      "name": "Rock_Basalt"
    },
    {
      "x": 21,
      "y": 23,
      "z": 13,
      "name": "Soil_Dirt_Burnt"
    },
    {
      "x": 22,
      "y": 21,
      "z": 3,
      "name": "Rock_Basalt"
    },
    {
      "x": 22,
      "y": 20,
      "z": 4,
      "name": "Rock_Basalt"
    },
    {
      "x": 22,
      "y": 21,
      "z": 4,
      "name": "Rock_Basalt"
    },
    {
      "x": 22,
      "y": 22,
      "z": 4,
      "name": "Soil_Dirt_Burnt"
    },
    {
      "x": 22,
      "y": 19,
      "z": 5,
      "name": "Rock_Basalt"
    },
    {
      "x": 22,
      "y": 20,
      "z": 5,
      "name": "Rock_Basalt"
    },
    {
      "x": 22,
      "y": 21,
      "z": 5,
      "name": "Rock_Basalt"
    },
    {
      "x": 22,
      "y": 22,
      "z": 5,
      "name": "Soil_Dirt_Burnt"
    },
    {
      "x": 22,
      "y": 23,
      "z": 5,
      "name": "Soil_Dirt_Burnt"
    },
    {
      "x": 22,
      "y": 24,
      "z": 5,
      "name": "Soil_Dirt_Burnt"
    },
    {
      "x": 22,
      "y": 19,
      "z": 6,
      "name": "Rock_Basalt"
    },
    {
      "x": 22,
      "y": 20,
      "z": 6,
      "name": "Rock_Basalt"
    },
    {
      "x": 22,
      "y": 21,
      "z": 6,
      "name": "Rock_Basalt"
    },
    {
      "x": 22,
      "y": 22,
      "z": 6,
      "name": "Soil_Dirt_Burnt"
    },
    {
      "x": 22,
      "y": 23,
      "z": 6,
      "name": "Soil_Dirt_Burnt"
    },
    {
      "x": 22,
      "y": 24,
      "z": 6,
      "name": "Soil_Dirt_Burnt"
    },
    {
      "x": 22,
      "y": 19,
      "z": 7,
      "name": "Rock_Basalt"
    },
    {
      "x": 22,
      "y": 20,
      "z": 7,
      "name": "Rock_Basalt"
    },
    {
      "x": 22,
      "y": 21,
      "z": 7,
      "name": "Rock_Basalt"
    },
    {
      "x": 22,
      "y": 22,
      "z": 7,
      "name": "Soil_Dirt_Burnt"
    },
    {
      "x": 22,
      "y": 23,
      "z": 7,
      "name": "Soil_Dirt_Burnt"
    },
    {
      "x": 22,
      "y": 24,
      "z": 7,
      "name": "Soil_Dirt_Burnt"
    },
    {
      "x": 22,
      "y": 19,
      "z": 8,
      "name": "Rock_Basalt"
    },
    {
      "x": 22,
      "y": 20,
      "z": 8,
      "name": "Rock_Basalt"
    },
    {
      "x": 22,
      "y": 21,
      "z": 8,
      "name": "Rock_Basalt"
    },
    {
      "x": 22,
      "y": 22,
      "z": 8,
      "name": "Soil_Dirt_Burnt"
    },
    {
      "x": 22,
      "y": 23,
      "z": 8,
      "name": "Soil_Dirt_Burnt"
    },
    {
      "x": 22,
      "y": 24,
      "z": 8,
      "name": "Soil_Dirt_Burnt"
    },
    {
      "x": 22,
      "y": 25,
      "z": 8,
      "name": "Soil_Mud_Dry"
    },
    {
      "x": 22,
      "y": 19,
      "z": 9,
      "name": "Rock_Basalt"
    },
    {
      "x": 22,
      "y": 20,
      "z": 9,
      "name": "Soil_Dirt_Burnt"
    },
    {
      "x": 22,
      "y": 21,
      "z": 9,
      "name": "Rock_Basalt"
    },
    {
      "x": 22,
      "y": 22,
      "z": 9,
      "name": "Soil_Dirt_Burnt"
    },
    {
      "x": 22,
      "y": 23,
      "z": 9,
      "name": "Soil_Dirt_Burnt"
    },
    {
      "x": 22,
      "y": 24,
      "z": 9,
      "name": "Soil_Dirt_Burnt"
    },
    {
      "x": 22,
      "y": 25,
      "z": 9,
      "name": "Soil_Mud_Dry"
    },
    {
      "x": 22,
      "y": 19,
      "z": 10,
      "name": "Rock_Basalt"
    },
    {
      "x": 22,
      "y": 20,
      "z": 10,
      "name": "Soil_Dirt_Burnt"
    },
    {
      "x": 22,
      "y": 21,
      "z": 10,
      "name": "Rock_Basalt"
    },
    {
      "x": 22,
      "y": 22,
      "z": 10,
      "name": "Soil_Dirt_Burnt"
    },
    {
      "x": 22,
      "y": 23,
      "z": 10,
      "name": "Soil_Dirt_Burnt"
    },
    {
      "x": 22,
      "y": 24,
      "z": 10,
      "name": "Soil_Dirt_Burnt"
    },
    {
      "x": 22,
      "y": 25,
      "z": 10,
      "name": "Soil_Mud_Dry"
    },
    {
      "x": 22,
      "y": 20,
      "z": 11,
      "name": "Soil_Dirt_Burnt"
    },
    {
      "x": 22,
      "y": 21,
      "z": 11,
      "name": "Rock_Basalt"
    },
    {
      "x": 22,
      "y": 22,
      "z": 11,
      "name": "Soil_Dirt_Burnt"
    },
    {
      "x": 22,
      "y": 23,
      "z": 11,
      "name": "Soil_Dirt_Burnt"
    },
    {
      "x": 22,
      "y": 24,
      "z": 11,
      "name": "Soil_Dirt_Burnt"
    },
    {
      "x": 22,
      "y": 25,
      "z": 11,
      "name": "Soil_Mud_Dry"
    },
    {
      "x": 22,
      "y": 20,
      "z": 12,
      "name": "Soil_Dirt_Burnt"
    },
    {
      "x": 22,
      "y": 21,
      "z": 12,
      "name": "Rock_Basalt"
    },
    {
      "x": 22,
      "y": 22,
      "z": 12,
      "name": "Rock_Basalt"
    },
    {
      "x": 22,
      "y": 23,
      "z": 12,
      "name": "Soil_Dirt_Burnt"
    },
    {
      "x": 22,
      "y": 24,
      "z": 12,
      "name": "Soil_Dirt_Burnt"
    },
    {
      "x": 22,
      "y": 22,
      "z": 13,
      "name": "Rock_Basalt"
    },
    {
      "x": 22,
      "y": 23,
      "z": 13,
      "name": "Soil_Dirt_Burnt"
    },
    {
      "x": 23,
      "y": 21,
      "z": 3,
      "name": "Rock_Basalt"
    },
    {
      "x": 23,
      "y": 20,
      "z": 4,
      "name": "Rock_Basalt"
    },
    {
      "x": 23,
      "y": 21,
      "z": 4,
      "name": "Rock_Basalt"
    },
    {
      "x": 23,
      "y": 20,
      "z": 5,
      "name": "Rock_Basalt"
    },
    {
      "x": 23,
      "y": 21,
      "z": 5,
      "name": "Rock_Basalt"
    },
    {
      "x": 23,
      "y": 22,
      "z": 5,
      "name": "Soil_Dirt_Burnt"
    },
    {
      "x": 23,
      "y": 23,
      "z": 5,
      "name": "Soil_Dirt_Burnt"
    },
    {
      "x": 23,
      "y": 24,
      "z": 5,
      "name": "Soil_Dirt_Burnt"
    },
    {
      "x": 23,
      "y": 19,
      "z": 6,
      "name": "Rock_Basalt"
    },
    {
      "x": 23,
      "y": 20,
      "z": 6,
      "name": "Rock_Basalt"
    },
    {
      "x": 23,
      "y": 21,
      "z": 6,
      "name": "Rock_Basalt"
    },
    {
      "x": 23,
      "y": 22,
      "z": 6,
      "name": "Soil_Dirt_Burnt"
    },
    {
      "x": 23,
      "y": 23,
      "z": 6,
      "name": "Soil_Dirt_Burnt"
    },
    {
      "x": 23,
      "y": 24,
      "z": 6,
      "name": "Soil_Dirt_Burnt"
    },
    {
      "x": 23,
      "y": 19,
      "z": 7,
      "name": "Rock_Basalt"
    },
    {
      "x": 23,
      "y": 20,
      "z": 7,
      "name": "Rock_Basalt"
    },
    {
      "x": 23,
      "y": 21,
      "z": 7,
      "name": "Rock_Basalt"
    },
    {
      "x": 23,
      "y": 22,
      "z": 7,
      "name": "Soil_Dirt_Burnt"
    },
    {
      "x": 23,
      "y": 23,
      "z": 7,
      "name": "Soil_Dirt_Burnt"
    },
    {
      "x": 23,
      "y": 24,
      "z": 7,
      "name": "Soil_Dirt_Burnt"
    },
    {
      "x": 23,
      "y": 19,
      "z": 8,
      "name": "Rock_Basalt"
    },
    {
      "x": 23,
      "y": 20,
      "z": 8,
      "name": "Soil_Dirt_Burnt"
    },
    {
      "x": 23,
      "y": 21,
      "z": 8,
      "name": "Rock_Basalt"
    },
    {
      "x": 23,
      "y": 22,
      "z": 8,
      "name": "Soil_Dirt_Burnt"
    },
    {
      "x": 23,
      "y": 23,
      "z": 8,
      "name": "Soil_Dirt_Burnt"
    },
    {
      "x": 23,
      "y": 24,
      "z": 8,
      "name": "Soil_Dirt_Burnt"
    },
    {
      "x": 23,
      "y": 25,
      "z": 8,
      "name": "Soil_Mud_Dry"
    },
    {
      "x": 23,
      "y": 19,
      "z": 9,
      "name": "Rock_Basalt"
    },
    {
      "x": 23,
      "y": 20,
      "z": 9,
      "name": "Soil_Dirt_Burnt"
    },
    {
      "x": 23,
      "y": 21,
      "z": 9,
      "name": "Rock_Basalt"
    },
    {
      "x": 23,
      "y": 22,
      "z": 9,
      "name": "Soil_Dirt_Burnt"
    },
    {
      "x": 23,
      "y": 23,
      "z": 9,
      "name": "Soil_Dirt_Burnt"
    },
    {
      "x": 23,
      "y": 24,
      "z": 9,
      "name": "Soil_Dirt_Burnt"
    },
    {
      "x": 23,
      "y": 25,
      "z": 9,
      "name": "Soil_Mud_Dry"
    },
    {
      "x": 23,
      "y": 19,
      "z": 10,
      "name": "Rock_Basalt"
    },
    {
      "x": 23,
      "y": 20,
      "z": 10,
      "name": "Soil_Dirt_Burnt"
    },
    {
      "x": 23,
      "y": 21,
      "z": 10,
      "name": "Soil_Dirt_Burnt"
    },
    {
      "x": 23,
      "y": 22,
      "z": 10,
      "name": "Soil_Dirt_Burnt"
    },
    {
      "x": 23,
      "y": 23,
      "z": 10,
      "name": "Soil_Dirt_Burnt"
    },
    {
      "x": 23,
      "y": 24,
      "z": 10,
      "name": "Soil_Dirt_Burnt"
    },
    {
      "x": 23,
      "y": 25,
      "z": 10,
      "name": "Soil_Mud_Dry"
    },
    {
      "x": 23,
      "y": 20,
      "z": 11,
      "name": "Soil_Dirt_Burnt"
    },
    {
      "x": 23,
      "y": 21,
      "z": 11,
      "name": "Soil_Dirt_Burnt"
    },
    {
      "x": 23,
      "y": 22,
      "z": 11,
      "name": "Rock_Basalt"
    },
    {
      "x": 23,
      "y": 23,
      "z": 11,
      "name": "Soil_Dirt_Burnt"
    },
    {
      "x": 23,
      "y": 24,
      "z": 11,
      "name": "Soil_Dirt_Burnt"
    },
    {
      "x": 23,
      "y": 25,
      "z": 11,
      "name": "Soil_Mud_Dry"
    },
    {
      "x": 23,
      "y": 20,
      "z": 12,
      "name": "Soil_Dirt_Burnt"
    },
    {
      "x": 23,
      "y": 21,
      "z": 12,
      "name": "Soil_Dirt_Burnt"
    },
    {
      "x": 23,
      "y": 22,
      "z": 12,
      "name": "Rock_Basalt"
    },
    {
      "x": 23,
      "y": 23,
      "z": 12,
      "name": "Soil_Dirt_Burnt"
    },
    {
      "x": 23,
      "y": 24,
      "z": 12,
      "name": "Soil_Dirt_Burnt"
    },
    {
      "x": 23,
      "y": 21,
      "z": 13,
      "name": "Soil_Dirt_Burnt"
    },
    {
      "x": 23,
      "y": 22,
      "z": 13,
      "name": "Rock_Basalt"
    },
    {
      "x": 23,
      "y": 23,
      "z": 13,
      "name": "Soil_Dirt_Burnt"
    },
    {
      "x": 24,
      "y": 20,
      "z": 4,
      "name": "Rock_Basalt"
    },
    {
      "x": 24,
      "y": 21,
      "z": 4,
      "name": "Rock_Basalt"
    },
    {
      "x": 24,
      "y": 20,
      "z": 5,
      "name": "Rock_Basalt"
    },
    {
      "x": 24,
      "y": 21,
      "z": 5,
      "name": "Rock_Basalt"
    },
    {
      "x": 24,
      "y": 22,
      "z": 5,
      "name": "Soil_Dirt_Burnt"
    },
    {
      "x": 24,
      "y": 23,
      "z": 5,
      "name": "Soil_Dirt_Burnt"
    },
    {
      "x": 24,
      "y": 24,
      "z": 5,
      "name": "Soil_Dirt_Burnt"
    },
    {
      "x": 24,
      "y": 20,
      "z": 6,
      "name": "Rock_Basalt"
    },
    {
      "x": 24,
      "y": 21,
      "z": 6,
      "name": "Rock_Basalt"
    },
    {
      "x": 24,
      "y": 22,
      "z": 6,
      "name": "Soil_Dirt_Burnt"
    },
    {
      "x": 24,
      "y": 23,
      "z": 6,
      "name": "Soil_Dirt_Burnt"
    },
    {
      "x": 24,
      "y": 24,
      "z": 6,
      "name": "Soil_Dirt_Burnt"
    },
    {
      "x": 24,
      "y": 19,
      "z": 7,
      "name": "Rock_Basalt"
    },
    {
      "x": 24,
      "y": 20,
      "z": 7,
      "name": "Rock_Basalt"
    },
    {
      "x": 24,
      "y": 21,
      "z": 7,
      "name": "Rock_Basalt"
    },
    {
      "x": 24,
      "y": 22,
      "z": 7,
      "name": "Soil_Dirt_Burnt"
    },
    {
      "x": 24,
      "y": 23,
      "z": 7,
      "name": "Soil_Dirt_Burnt"
    },
    {
      "x": 24,
      "y": 24,
      "z": 7,
      "name": "Soil_Dirt_Burnt"
    },
    {
      "x": 24,
      "y": 19,
      "z": 8,
      "name": "Rock_Basalt"
    },
    {
      "x": 24,
      "y": 20,
      "z": 8,
      "name": "Soil_Dirt_Burnt"
    },
    {
      "x": 24,
      "y": 21,
      "z": 8,
      "name": "Soil_Dirt_Burnt"
    },
    {
      "x": 24,
      "y": 22,
      "z": 8,
      "name": "Soil_Dirt_Burnt"
    },
    {
      "x": 24,
      "y": 23,
      "z": 8,
      "name": "Soil_Dirt_Burnt"
    },
    {
      "x": 24,
      "y": 24,
      "z": 8,
      "name": "Soil_Dirt_Burnt"
    },
    {
      "x": 24,
      "y": 19,
      "z": 9,
      "name": "Rock_Basalt"
    },
    {
      "x": 24,
      "y": 20,
      "z": 9,
      "name": "Soil_Dirt_Burnt"
    },
    {
      "x": 24,
      "y": 21,
      "z": 9,
      "name": "Soil_Dirt_Burnt"
    },
    {
      "x": 24,
      "y": 22,
      "z": 9,
      "name": "Soil_Dirt_Burnt"
    },
    {
      "x": 24,
      "y": 23,
      "z": 9,
      "name": "Soil_Dirt_Burnt"
    },
    {
      "x": 24,
      "y": 24,
      "z": 9,
      "name": "Soil_Dirt_Burnt"
    },
    {
      "x": 24,
      "y": 25,
      "z": 9,
      "name": "Soil_Mud_Dry"
    },
    {
      "x": 24,
      "y": 19,
      "z": 10,
      "name": "Rock_Basalt"
    },
    {
      "x": 24,
      "y": 20,
      "z": 10,
      "name": "Soil_Dirt_Burnt"
    },
    {
      "x": 24,
      "y": 21,
      "z": 10,
      "name": "Soil_Dirt_Burnt"
    },
    {
      "x": 24,
      "y": 22,
      "z": 10,
      "name": "Soil_Dirt_Burnt"
    },
    {
      "x": 24,
      "y": 23,
      "z": 10,
      "name": "Soil_Dirt_Burnt"
    },
    {
      "x": 24,
      "y": 24,
      "z": 10,
      "name": "Soil_Dirt_Burnt"
    },
    {
      "x": 24,
      "y": 25,
      "z": 10,
      "name": "Soil_Mud_Dry"
    },
    {
      "x": 24,
      "y": 4,
      "z": 11,
      "name": "Rock_Basalt"
    },
    {
      "x": 24,
      "y": 5,
      "z": 11,
      "name": "Rock_Basalt"
    },
    {
      "x": 24,
      "y": 20,
      "z": 11,
      "name": "Soil_Dirt_Burnt"
    },
    {
      "x": 24,
      "y": 21,
      "z": 11,
      "name": "Soil_Dirt_Burnt"
    },
    {
      "x": 24,
      "y": 22,
      "z": 11,
      "name": "Rock_Basalt"
    },
    {
      "x": 24,
      "y": 23,
      "z": 11,
      "name": "Soil_Dirt_Burnt"
    },
    {
      "x": 24,
      "y": 24,
      "z": 11,
      "name": "Soil_Dirt_Burnt"
    },
    {
      "x": 24,
      "y": 20,
      "z": 12,
      "name": "Soil_Dirt_Burnt"
    },
    {
      "x": 24,
      "y": 21,
      "z": 12,
      "name": "Soil_Dirt_Burnt"
    },
    {
      "x": 24,
      "y": 22,
      "z": 12,
      "name": "Soil_Mud_Dry"
    },
    {
      "x": 24,
      "y": 23,
      "z": 12,
      "name": "Soil_Dirt_Burnt"
    },
    {
      "x": 24,
      "y": 24,
      "z": 12,
      "name": "Soil_Dirt_Burnt"
    },
    {
      "x": 24,
      "y": 21,
      "z": 13,
      "name": "Soil_Dirt_Burnt"
    },
    {
      "x": 24,
      "y": 22,
      "z": 13,
      "name": "Rock_Basalt"
    },
    {
      "x": 24,
      "y": 23,
      "z": 13,
      "name": "Soil_Mud_Dry"
    },
    {
      "x": 24,
      "y": 21,
      "z": 14,
      "name": "Soil_Dirt_Burnt"
    },
    {
      "x": 24,
      "y": 22,
      "z": 14,
      "name": "Soil_Mud_Dry"
    },
    {
      "x": 25,
      "y": 20,
      "z": 5,
      "name": "Rock_Basalt"
    },
    {
      "x": 25,
      "y": 21,
      "z": 5,
      "name": "Rock_Basalt"
    },
    {
      "x": 25,
      "y": 22,
      "z": 5,
      "name": "Soil_Dirt_Burnt"
    },
    {
      "x": 25,
      "y": 23,
      "z": 5,
      "name": "Soil_Dirt_Burnt"
    },
    {
      "x": 25,
      "y": 20,
      "z": 6,
      "name": "Rock_Basalt"
    },
    {
      "x": 25,
      "y": 21,
      "z": 6,
      "name": "Soil_Dirt_Burnt"
    },
    {
      "x": 25,
      "y": 22,
      "z": 6,
      "name": "Soil_Dirt_Burnt"
    },
    {
      "x": 25,
      "y": 23,
      "z": 6,
      "name": "Soil_Dirt_Burnt"
    },
    {
      "x": 25,
      "y": 24,
      "z": 6,
      "name": "Soil_Dirt_Burnt"
    },
    {
      "x": 25,
      "y": 20,
      "z": 7,
      "name": "Soil_Dirt_Burnt"
    },
    {
      "x": 25,
      "y": 21,
      "z": 7,
      "name": "Soil_Dirt_Burnt"
    },
    {
      "x": 25,
      "y": 22,
      "z": 7,
      "name": "Soil_Dirt_Burnt"
    },
    {
      "x": 25,
      "y": 23,
      "z": 7,
      "name": "Soil_Dirt_Burnt"
    },
    {
      "x": 25,
      "y": 24,
      "z": 7,
      "name": "Soil_Dirt_Burnt"
    },
    {
      "x": 25,
      "y": 20,
      "z": 8,
      "name": "Soil_Dirt_Burnt"
    },
    {
      "x": 25,
      "y": 21,
      "z": 8,
      "name": "Soil_Dirt_Burnt"
    },
    {
      "x": 25,
      "y": 22,
      "z": 8,
      "name": "Soil_Dirt_Burnt"
    },
    {
      "x": 25,
      "y": 23,
      "z": 8,
      "name": "Soil_Dirt_Burnt"
    },
    {
      "x": 25,
      "y": 24,
      "z": 8,
      "name": "Soil_Dirt_Burnt"
    },
    {
      "x": 25,
      "y": 20,
      "z": 9,
      "name": "Soil_Dirt_Burnt"
    },
    {
      "x": 25,
      "y": 21,
      "z": 9,
      "name": "Soil_Dirt_Burnt"
    },
    {
      "x": 25,
      "y": 22,
      "z": 9,
      "name": "Soil_Dirt_Burnt"
    },
    {
      "x": 25,
      "y": 23,
      "z": 9,
      "name": "Soil_Dirt_Burnt"
    },
    {
      "x": 25,
      "y": 24,
      "z": 9,
      "name": "Soil_Dirt_Burnt"
    },
    {
      "x": 25,
      "y": 3,
      "z": 10,
      "name": "Rock_Basalt"
    },
    {
      "x": 25,
      "y": 4,
      "z": 10,
      "name": "Rock_Basalt"
    },
    {
      "x": 25,
      "y": 19,
      "z": 10,
      "name": "Rock_Basalt"
    },
    {
      "x": 25,
      "y": 20,
      "z": 10,
      "name": "Soil_Dirt_Burnt"
    },
    {
      "x": 25,
      "y": 21,
      "z": 10,
      "name": "Soil_Dirt_Burnt"
    },
    {
      "x": 25,
      "y": 22,
      "z": 10,
      "name": "Rock_Basalt"
    },
    {
      "x": 25,
      "y": 23,
      "z": 10,
      "name": "Soil_Dirt_Burnt"
    },
    {
      "x": 25,
      "y": 24,
      "z": 10,
      "name": "Soil_Dirt_Burnt"
    },
    {
      "x": 25,
      "y": 4,
      "z": 11,
      "name": "Rock_Basalt"
    },
    {
      "x": 25,
      "y": 5,
      "z": 11,
      "name": "Rock_Basalt"
    },
    {
      "x": 25,
      "y": 19,
      "z": 11,
      "name": "Rock_Basalt"
    },
    {
      "x": 25,
      "y": 20,
      "z": 11,
      "name": "Soil_Dirt_Burnt"
    },
    {
      "x": 25,
      "y": 21,
      "z": 11,
      "name": "Soil_Dirt_Burnt"
    },
    {
      "x": 25,
      "y": 22,
      "z": 11,
      "name": "Soil_Mud_Dry"
    },
    {
      "x": 25,
      "y": 23,
      "z": 11,
      "name": "Soil_Dirt_Burnt"
    },
    {
      "x": 25,
      "y": 24,
      "z": 11,
      "name": "Soil_Dirt_Burnt"
    },
    {
      "x": 25,
      "y": 5,
      "z": 12,
      "name": "Rock_Basalt"
    },
    {
      "x": 25,
      "y": 6,
      "z": 12,
      "name": "Rock_Basalt"
    },
    {
      "x": 25,
      "y": 7,
      "z": 12,
      "name": "Rock_Basalt"
    },
    {
      "x": 25,
      "y": 19,
      "z": 12,
      "name": "Rock_Basalt"
    },
    {
      "x": 25,
      "y": 20,
      "z": 12,
      "name": "Soil_Dirt_Burnt"
    },
    {
      "x": 25,
      "y": 21,
      "z": 12,
      "name": "Soil_Dirt_Burnt"
    },
    {
      "x": 25,
      "y": 22,
      "z": 12,
      "name": "Soil_Mud_Dry"
    },
    {
      "x": 25,
      "y": 23,
      "z": 12,
      "name": "Soil_Dirt_Burnt"
    },
    {
      "x": 25,
      "y": 24,
      "z": 12,
      "name": "Soil_Dirt_Burnt"
    },
    {
      "x": 25,
      "y": 19,
      "z": 13,
      "name": "Rock_Basalt"
    },
    {
      "x": 25,
      "y": 20,
      "z": 13,
      "name": "Soil_Dirt_Burnt"
    },
    {
      "x": 25,
      "y": 21,
      "z": 13,
      "name": "Soil_Dirt_Burnt"
    },
    {
      "x": 25,
      "y": 22,
      "z": 13,
      "name": "Soil_Mud_Dry"
    },
    {
      "x": 25,
      "y": 23,
      "z": 13,
      "name": "Soil_Mud_Dry"
    },
    {
      "x": 25,
      "y": 20,
      "z": 14,
      "name": "Soil_Dirt_Burnt"
    },
    {
      "x": 25,
      "y": 21,
      "z": 14,
      "name": "Soil_Dirt_Burnt"
    },
    {
      "x": 25,
      "y": 22,
      "z": 14,
      "name": "Soil_Mud_Dry"
    },
    {
      "x": 25,
      "y": 20,
      "z": 15,
      "name": "Soil_Dirt_Burnt"
    },
    {
      "x": 25,
      "y": 21,
      "z": 15,
      "name": "Soil_Dirt_Burnt"
    },
    {
      "x": 25,
      "y": 22,
      "z": 15,
      "name": "Soil_Mud_Dry"
    },
    {
      "x": 26,
      "y": 21,
      "z": 5,
      "name": "Soil_Dirt_Burnt"
    },
    {
      "x": 26,
      "y": 22,
      "z": 5,
      "name": "Soil_Dirt_Burnt"
    },
    {
      "x": 26,
      "y": 20,
      "z": 6,
      "name": "Rock_Basalt"
    },
    {
      "x": 26,
      "y": 21,
      "z": 6,
      "name": "Soil_Dirt_Burnt"
    },
    {
      "x": 26,
      "y": 22,
      "z": 6,
      "name": "Soil_Dirt_Burnt"
    },
    {
      "x": 26,
      "y": 23,
      "z": 6,
      "name": "Soil_Dirt_Burnt"
    },
    {
      "x": 26,
      "y": 24,
      "z": 6,
      "name": "Soil_Dirt_Burnt"
    },
    {
      "x": 26,
      "y": 20,
      "z": 7,
      "name": "Soil_Dirt_Burnt"
    },
    {
      "x": 26,
      "y": 21,
      "z": 7,
      "name": "Soil_Dirt_Burnt"
    },
    {
      "x": 26,
      "y": 22,
      "z": 7,
      "name": "Soil_Dirt_Burnt"
    },
    {
      "x": 26,
      "y": 23,
      "z": 7,
      "name": "Soil_Dirt_Burnt"
    },
    {
      "x": 26,
      "y": 24,
      "z": 7,
      "name": "Soil_Dirt_Burnt"
    },
    {
      "x": 26,
      "y": 20,
      "z": 8,
      "name": "Soil_Dirt_Burnt"
    },
    {
      "x": 26,
      "y": 21,
      "z": 8,
      "name": "Soil_Dirt_Burnt"
    },
    {
      "x": 26,
      "y": 22,
      "z": 8,
      "name": "Rock_Basalt"
    },
    {
      "x": 26,
      "y": 23,
      "z": 8,
      "name": "Soil_Dirt_Burnt"
    },
    {
      "x": 26,
      "y": 24,
      "z": 8,
      "name": "Soil_Dirt_Burnt"
    },
    {
      "x": 26,
      "y": 19,
      "z": 9,
      "name": "Rock_Basalt"
    },
    {
      "x": 26,
      "y": 20,
      "z": 9,
      "name": "Soil_Dirt_Burnt"
    },
    {
      "x": 26,
      "y": 21,
      "z": 9,
      "name": "Soil_Dirt_Burnt"
    },
    {
      "x": 26,
      "y": 22,
      "z": 9,
      "name": "Rock_Basalt"
    },
    {
      "x": 26,
      "y": 23,
      "z": 9,
      "name": "Soil_Dirt_Burnt"
    },
    {
      "x": 26,
      "y": 24,
      "z": 9,
      "name": "Soil_Dirt_Burnt"
    },
    {
      "x": 26,
      "y": 4,
      "z": 10,
      "name": "Rock_Basalt"
    },
    {
      "x": 26,
      "y": 5,
      "z": 10,
      "name": "Rock_Basalt"
    },
    {
      "x": 26,
      "y": 6,
      "z": 10,
      "name": "Rock_Basalt"
    },
    {
      "x": 26,
      "y": 19,
      "z": 10,
      "name": "Rock_Basalt"
    },
    {
      "x": 26,
      "y": 20,
      "z": 10,
      "name": "Soil_Dirt_Burnt"
    },
    {
      "x": 26,
      "y": 21,
      "z": 10,
      "name": "Soil_Dirt_Burnt"
    },
    {
      "x": 26,
      "y": 22,
      "z": 10,
      "name": "Soil_Mud_Dry"
    },
    {
      "x": 26,
      "y": 23,
      "z": 10,
      "name": "Soil_Dirt_Burnt"
    },
    {
      "x": 26,
      "y": 24,
      "z": 10,
      "name": "Soil_Dirt_Burnt"
    },
    {
      "x": 26,
      "y": 4,
      "z": 11,
      "name": "Rock_Basalt"
    },
    {
      "x": 26,
      "y": 5,
      "z": 11,
      "name": "Rock_Basalt"
    },
    {
      "x": 26,
      "y": 6,
      "z": 11,
      "name": "Rock_Basalt"
    },
    {
      "x": 26,
      "y": 7,
      "z": 11,
      "name": "Rock_Basalt"
    },
    {
      "x": 26,
      "y": 8,
      "z": 11,
      "name": "Rock_Basalt"
    },
    {
      "x": 26,
      "y": 19,
      "z": 11,
      "name": "Rock_Basalt"
    },
    {
      "x": 26,
      "y": 20,
      "z": 11,
      "name": "Soil_Dirt_Burnt"
    },
    {
      "x": 26,
      "y": 21,
      "z": 11,
      "name": "Soil_Dirt_Burnt"
    },
    {
      "x": 26,
      "y": 22,
      "z": 11,
      "name": "Soil_Mud_Dry"
    },
    {
      "x": 26,
      "y": 23,
      "z": 11,
      "name": "Soil_Dirt_Burnt"
    },
    {
      "x": 26,
      "y": 24,
      "z": 11,
      "name": "Soil_Dirt_Burnt"
    },
    {
      "x": 26,
      "y": 5,
      "z": 12,
      "name": "Rock_Basalt"
    },
    {
      "x": 26,
      "y": 6,
      "z": 12,
      "name": "Rock_Basalt"
    },
    {
      "x": 26,
      "y": 7,
      "z": 12,
      "name": "Rock_Basalt"
    },
    {
      "x": 26,
      "y": 8,
      "z": 12,
      "name": "Rock_Basalt"
    },
    {
      "x": 26,
      "y": 19,
      "z": 12,
      "name": "Rock_Basalt"
    },
    {
      "x": 26,
      "y": 20,
      "z": 12,
      "name": "Soil_Dirt_Burnt"
    },
    {
      "x": 26,
      "y": 21,
      "z": 12,
      "name": "Soil_Dirt_Burnt"
    },
    {
      "x": 26,
      "y": 22,
      "z": 12,
      "name": "Soil_Mud_Dry"
    },
    {
      "x": 26,
      "y": 23,
      "z": 12,
      "name": "Soil_Mud_Dry"
    },
    {
      "x": 26,
      "y": 6,
      "z": 13,
      "name": "Rock_Basalt"
    },
    {
      "x": 26,
      "y": 19,
      "z": 13,
      "name": "Rock_Basalt"
    },
    {
      "x": 26,
      "y": 20,
      "z": 13,
      "name": "Soil_Dirt_Burnt"
    },
    {
      "x": 26,
      "y": 21,
      "z": 13,
      "name": "Soil_Dirt_Burnt"
    },
    {
      "x": 26,
      "y": 22,
      "z": 13,
      "name": "Soil_Mud_Dry"
    },
    {
      "x": 26,
      "y": 23,
      "z": 13,
      "name": "Soil_Mud_Dry"
    },
    {
      "x": 26,
      "y": 19,
      "z": 14,
      "name": "Rock_Basalt"
    },
    {
      "x": 26,
      "y": 20,
      "z": 14,
      "name": "Soil_Dirt_Burnt"
    },
    {
      "x": 26,
      "y": 21,
      "z": 14,
      "name": "Soil_Dirt_Burnt"
    },
    {
      "x": 26,
      "y": 22,
      "z": 14,
      "name": "Soil_Mud_Dry"
    },
    {
      "x": 26,
      "y": 23,
      "z": 14,
      "name": "Soil_Mud_Dry"
    },
    {
      "x": 26,
      "y": 20,
      "z": 15,
      "name": "Soil_Dirt_Burnt"
    },
    {
      "x": 26,
      "y": 21,
      "z": 15,
      "name": "Soil_Dirt_Burnt"
    },
    {
      "x": 26,
      "y": 22,
      "z": 15,
      "name": "Soil_Mud_Dry"
    },
    {
      "x": 27,
      "y": 20,
      "z": 6,
      "name": "Soil_Dirt_Burnt"
    },
    {
      "x": 27,
      "y": 21,
      "z": 6,
      "name": "Soil_Dirt_Burnt"
    },
    {
      "x": 27,
      "y": 22,
      "z": 6,
      "name": "Soil_Mud_Dry"
    },
    {
      "x": 27,
      "y": 20,
      "z": 7,
      "name": "Soil_Dirt_Burnt"
    },
    {
      "x": 27,
      "y": 21,
      "z": 7,
      "name": "Soil_Dirt_Burnt"
    },
    {
      "x": 27,
      "y": 22,
      "z": 7,
      "name": "Soil_Mud_Dry"
    },
    {
      "x": 27,
      "y": 23,
      "z": 7,
      "name": "Soil_Dirt_Burnt"
    },
    {
      "x": 27,
      "y": 20,
      "z": 8,
      "name": "Soil_Dirt_Burnt"
    },
    {
      "x": 27,
      "y": 21,
      "z": 8,
      "name": "Soil_Dirt_Burnt"
    },
    {
      "x": 27,
      "y": 22,
      "z": 8,
      "name": "Soil_Mud_Dry"
    },
    {
      "x": 27,
      "y": 23,
      "z": 8,
      "name": "Soil_Dirt_Burnt"
    },
    {
      "x": 27,
      "y": 24,
      "z": 8,
      "name": "Soil_Dirt_Burnt"
    },
    {
      "x": 27,
      "y": 6,
      "z": 9,
      "name": "Rock_Basalt"
    },
    {
      "x": 27,
      "y": 7,
      "z": 9,
      "name": "Rock_Basalt"
    },
    {
      "x": 27,
      "y": 19,
      "z": 9,
      "name": "Rock_Basalt"
    },
    {
      "x": 27,
      "y": 20,
      "z": 9,
      "name": "Soil_Dirt_Burnt"
    },
    {
      "x": 27,
      "y": 21,
      "z": 9,
      "name": "Soil_Dirt_Burnt"
    },
    {
      "x": 27,
      "y": 22,
      "z": 9,
      "name": "Rock_Basalt"
    },
    {
      "x": 27,
      "y": 23,
      "z": 9,
      "name": "Soil_Dirt_Burnt"
    },
    {
      "x": 27,
      "y": 24,
      "z": 9,
      "name": "Soil_Dirt_Burnt"
    },
    {
      "x": 27,
      "y": 5,
      "z": 10,
      "name": "Rock_Basalt"
    },
    {
      "x": 27,
      "y": 6,
      "z": 10,
      "name": "Rock_Basalt"
    },
    {
      "x": 27,
      "y": 7,
      "z": 10,
      "name": "Rock_Basalt"
    },
    {
      "x": 27,
      "y": 8,
      "z": 10,
      "name": "Rock_Basalt"
    },
    {
      "x": 27,
      "y": 9,
      "z": 10,
      "name": "Rock_Basalt"
    },
    {
      "x": 27,
      "y": 19,
      "z": 10,
      "name": "Rock_Basalt"
    },
    {
      "x": 27,
      "y": 20,
      "z": 10,
      "name": "Soil_Dirt_Burnt"
    },
    {
      "x": 27,
      "y": 21,
      "z": 10,
      "name": "Soil_Dirt_Burnt"
    },
    {
      "x": 27,
      "y": 22,
      "z": 10,
      "name": "Rock_Basalt"
    },
    {
      "x": 27,
      "y": 23,
      "z": 10,
      "name": "Soil_Dirt_Burnt"
    },
    {
      "x": 27,
      "y": 24,
      "z": 10,
      "name": "Soil_Dirt_Burnt"
    },
    {
      "x": 27,
      "y": 5,
      "z": 11,
      "name": "Rock_Basalt"
    },
    {
      "x": 27,
      "y": 6,
      "z": 11,
      "name": "Rock_Basalt"
    },
    {
      "x": 27,
      "y": 7,
      "z": 11,
      "name": "Rock_Basalt"
    },
    {
      "x": 27,
      "y": 8,
      "z": 11,
      "name": "Rock_Basalt"
    },
    {
      "x": 27,
      "y": 9,
      "z": 11,
      "name": "Rock_Basalt"
    },
    {
      "x": 27,
      "y": 19,
      "z": 11,
      "name": "Rock_Basalt"
    },
    {
      "x": 27,
      "y": 20,
      "z": 11,
      "name": "Soil_Dirt_Burnt"
    },
    {
      "x": 27,
      "y": 21,
      "z": 11,
      "name": "Soil_Dirt_Burnt"
    },
    {
      "x": 27,
      "y": 22,
      "z": 11,
      "name": "Soil_Mud_Dry"
    },
    {
      "x": 27,
      "y": 23,
      "z": 11,
      "name": "Soil_Dirt_Burnt"
    },
    {
      "x": 27,
      "y": 24,
      "z": 11,
      "name": "Soil_Dirt_Burnt"
    },
    {
      "x": 27,
      "y": 5,
      "z": 12,
      "name": "Rock_Basalt"
    },
    {
      "x": 27,
      "y": 6,
      "z": 12,
      "name": "Rock_Basalt"
    },
    {
      "x": 27,
      "y": 7,
      "z": 12,
      "name": "Rock_Basalt"
    },
    {
      "x": 27,
      "y": 8,
      "z": 12,
      "name": "Rock_Basalt"
    },
    {
      "x": 27,
      "y": 18,
      "z": 12,
      "name": "Rock_Basalt"
    },
    {
      "x": 27,
      "y": 19,
      "z": 12,
      "name": "Rock_Basalt"
    },
    {
      "x": 27,
      "y": 20,
      "z": 12,
      "name": "Soil_Dirt_Burnt"
    },
    {
      "x": 27,
      "y": 21,
      "z": 12,
      "name": "Soil_Dirt_Burnt"
    },
    {
      "x": 27,
      "y": 22,
      "z": 12,
      "name": "Soil_Mud_Dry"
    },
    {
      "x": 27,
      "y": 23,
      "z": 12,
      "name": "Soil_Mud_Dry"
    },
    {
      "x": 27,
      "y": 6,
      "z": 13,
      "name": "Rock_Basalt"
    },
    {
      "x": 27,
      "y": 7,
      "z": 13,
      "name": "Rock_Basalt"
    },
    {
      "x": 27,
      "y": 18,
      "z": 13,
      "name": "Rock_Basalt"
    },
    {
      "x": 27,
      "y": 19,
      "z": 13,
      "name": "Rock_Basalt"
    },
    {
      "x": 27,
      "y": 20,
      "z": 13,
      "name": "Soil_Dirt_Burnt"
    },
    {
      "x": 27,
      "y": 21,
      "z": 13,
      "name": "Soil_Dirt_Burnt"
    },
    {
      "x": 27,
      "y": 22,
      "z": 13,
      "name": "Soil_Mud_Dry"
    },
    {
      "x": 27,
      "y": 23,
      "z": 13,
      "name": "Soil_Mud_Dry"
    },
    {
      "x": 27,
      "y": 18,
      "z": 14,
      "name": "Rock_Basalt"
    },
    {
      "x": 27,
      "y": 19,
      "z": 14,
      "name": "Rock_Basalt"
    },
    {
      "x": 27,
      "y": 20,
      "z": 14,
      "name": "Soil_Dirt_Burnt"
    },
    {
      "x": 27,
      "y": 21,
      "z": 14,
      "name": "Soil_Dirt_Burnt"
    },
    {
      "x": 27,
      "y": 22,
      "z": 14,
      "name": "Soil_Mud_Dry"
    },
    {
      "x": 27,
      "y": 23,
      "z": 14,
      "name": "Soil_Mud_Dry"
    },
    {
      "x": 27,
      "y": 20,
      "z": 15,
      "name": "Soil_Dirt_Burnt"
    },
    {
      "x": 27,
      "y": 21,
      "z": 15,
      "name": "Soil_Dirt_Burnt"
    },
    {
      "x": 27,
      "y": 22,
      "z": 15,
      "name": "Soil_Mud_Dry"
    },
    {
      "x": 28,
      "y": 21,
      "z": 6,
      "name": "Soil_Dirt_Burnt"
    },
    {
      "x": 28,
      "y": 20,
      "z": 7,
      "name": "Soil_Dirt_Burnt"
    },
    {
      "x": 28,
      "y": 21,
      "z": 7,
      "name": "Soil_Dirt_Burnt"
    },
    {
      "x": 28,
      "y": 22,
      "z": 7,
      "name": "Soil_Mud_Dry"
    },
    {
      "x": 28,
      "y": 23,
      "z": 7,
      "name": "Soil_Dirt_Burnt"
    },
    {
      "x": 28,
      "y": 20,
      "z": 8,
      "name": "Soil_Dirt_Burnt"
    },
    {
      "x": 28,
      "y": 21,
      "z": 8,
      "name": "Soil_Dirt_Burnt"
    },
    {
      "x": 28,
      "y": 22,
      "z": 8,
      "name": "Soil_Mud_Dry"
    },
    {
      "x": 28,
      "y": 23,
      "z": 8,
      "name": "Soil_Dirt_Burnt"
    },
    {
      "x": 28,
      "y": 6,
      "z": 9,
      "name": "Rock_Basalt"
    },
    {
      "x": 28,
      "y": 7,
      "z": 9,
      "name": "Rock_Basalt"
    },
    {
      "x": 28,
      "y": 8,
      "z": 9,
      "name": "Rock_Basalt"
    },
    {
      "x": 28,
      "y": 9,
      "z": 9,
      "name": "Rock_Basalt"
    },
    {
      "x": 28,
      "y": 19,
      "z": 9,
      "name": "Rock_Basalt"
    },
    {
      "x": 28,
      "y": 20,
      "z": 9,
      "name": "Soil_Dirt_Burnt"
    },
    {
      "x": 28,
      "y": 21,
      "z": 9,
      "name": "Soil_Dirt_Burnt"
    },
    {
      "x": 28,
      "y": 22,
      "z": 9,
      "name": "Soil_Mud_Dry"
    },
    {
      "x": 28,
      "y": 23,
      "z": 9,
      "name": "Soil_Dirt_Burnt"
    },
    {
      "x": 28,
      "y": 6,
      "z": 10,
      "name": "Rock_Basalt"
    },
    {
      "x": 28,
      "y": 7,
      "z": 10,
      "name": "Rock_Basalt"
    },
    {
      "x": 28,
      "y": 8,
      "z": 10,
      "name": "Rock_Basalt"
    },
    {
      "x": 28,
      "y": 9,
      "z": 10,
      "name": "Rock_Basalt"
    },
    {
      "x": 28,
      "y": 10,
      "z": 10,
      "name": "Rock_Basalt"
    },
    {
      "x": 28,
      "y": 19,
      "z": 10,
      "name": "Rock_Basalt"
    },
    {
      "x": 28,
      "y": 20,
      "z": 10,
      "name": "Soil_Dirt_Burnt"
    },
    {
      "x": 28,
      "y": 21,
      "z": 10,
      "name": "Soil_Dirt_Burnt"
    },
    {
      "x": 28,
      "y": 22,
      "z": 10,
      "name": "Soil_Mud_Dry"
    },
    {
      "x": 28,
      "y": 23,
      "z": 10,
      "name": "Soil_Dirt_Burnt"
    },
    {
      "x": 28,
      "y": 5,
      "z": 11,
      "name": "Rock_Basalt"
    },
    {
      "x": 28,
      "y": 6,
      "z": 11,
      "name": "Rock_Basalt"
    },
    {
      "x": 28,
      "y": 7,
      "z": 11,
      "name": "Rock_Basalt"
    },
    {
      "x": 28,
      "y": 8,
      "z": 11,
      "name": "Rock_Basalt"
    },
    {
      "x": 28,
      "y": 9,
      "z": 11,
      "name": "Rock_Basalt"
    },
    {
      "x": 28,
      "y": 10,
      "z": 11,
      "name": "Rock_Basalt"
    },
    {
      "x": 28,
      "y": 11,
      "z": 11,
      "name": "Rock_Basalt"
    },
    {
      "x": 28,
      "y": 18,
      "z": 11,
      "name": "Rock_Basalt"
    },
    {
      "x": 28,
      "y": 19,
      "z": 11,
      "name": "Rock_Basalt"
    },
    {
      "x": 28,
      "y": 20,
      "z": 11,
      "name": "Soil_Dirt_Burnt"
    },
    {
      "x": 28,
      "y": 21,
      "z": 11,
      "name": "Soil_Dirt_Burnt"
    },
    {
      "x": 28,
      "y": 22,
      "z": 11,
      "name": "Soil_Mud_Dry"
    },
    {
      "x": 28,
      "y": 23,
      "z": 11,
      "name": "Soil_Mud_Dry"
    },
    {
      "x": 28,
      "y": 5,
      "z": 12,
      "name": "Rock_Basalt"
    },
    {
      "x": 28,
      "y": 6,
      "z": 12,
      "name": "Rock_Basalt"
    },
    {
      "x": 28,
      "y": 7,
      "z": 12,
      "name": "Rock_Basalt"
    },
    {
      "x": 28,
      "y": 8,
      "z": 12,
      "name": "Rock_Basalt"
    },
    {
      "x": 28,
      "y": 18,
      "z": 12,
      "name": "Rock_Basalt"
    },
    {
      "x": 28,
      "y": 19,
      "z": 12,
      "name": "Rock_Basalt"
    },
    {
      "x": 28,
      "y": 20,
      "z": 12,
      "name": "Soil_Dirt_Burnt"
    },
    {
      "x": 28,
      "y": 21,
      "z": 12,
      "name": "Soil_Dirt_Burnt"
    },
    {
      "x": 28,
      "y": 22,
      "z": 12,
      "name": "Soil_Mud_Dry"
    },
    {
      "x": 28,
      "y": 23,
      "z": 12,
      "name": "Soil_Mud_Dry"
    },
    {
      "x": 28,
      "y": 6,
      "z": 13,
      "name": "Rock_Basalt"
    },
    {
      "x": 28,
      "y": 7,
      "z": 13,
      "name": "Rock_Basalt"
    },
    {
      "x": 28,
      "y": 8,
      "z": 13,
      "name": "Rock_Basalt"
    },
    {
      "x": 28,
      "y": 17,
      "z": 13,
      "name": "Rock_Basalt"
    },
    {
      "x": 28,
      "y": 18,
      "z": 13,
      "name": "Rock_Basalt"
    },
    {
      "x": 28,
      "y": 19,
      "z": 13,
      "name": "Rock_Basalt"
    },
    {
      "x": 28,
      "y": 20,
      "z": 13,
      "name": "Soil_Dirt_Burnt"
    },
    {
      "x": 28,
      "y": 21,
      "z": 13,
      "name": "Soil_Dirt_Burnt"
    },
    {
      "x": 28,
      "y": 22,
      "z": 13,
      "name": "Soil_Mud_Dry"
    },
    {
      "x": 28,
      "y": 23,
      "z": 13,
      "name": "Soil_Mud_Dry"
    },
    {
      "x": 28,
      "y": 17,
      "z": 14,
      "name": "Rock_Basalt"
    },
    {
      "x": 28,
      "y": 18,
      "z": 14,
      "name": "Rock_Basalt"
    },
    {
      "x": 28,
      "y": 19,
      "z": 14,
      "name": "Rock_Basalt"
    },
    {
      "x": 28,
      "y": 20,
      "z": 14,
      "name": "Soil_Dirt_Burnt"
    },
    {
      "x": 28,
      "y": 21,
      "z": 14,
      "name": "Soil_Dirt_Burnt"
    },
    {
      "x": 28,
      "y": 22,
      "z": 14,
      "name": "Soil_Mud_Dry"
    },
    {
      "x": 28,
      "y": 19,
      "z": 15,
      "name": "Rock_Basalt"
    },
    {
      "x": 28,
      "y": 20,
      "z": 15,
      "name": "Soil_Dirt_Burnt"
    },
    {
      "x": 28,
      "y": 21,
      "z": 15,
      "name": "Soil_Dirt_Burnt"
    },
    {
      "x": 28,
      "y": 22,
      "z": 15,
      "name": "Soil_Mud_Dry"
    },
    {
      "x": 29,
      "y": 21,
      "z": 7,
      "name": "Soil_Dirt_Burnt"
    },
    {
      "x": 29,
      "y": 22,
      "z": 7,
      "name": "Soil_Mud_Dry"
    },
    {
      "x": 29,
      "y": 19,
      "z": 8,
      "name": "Rock_Basalt"
    },
    {
      "x": 29,
      "y": 20,
      "z": 8,
      "name": "Soil_Dirt_Burnt"
    },
    {
      "x": 29,
      "y": 21,
      "z": 8,
      "name": "Soil_Dirt_Burnt"
    },
    {
      "x": 29,
      "y": 22,
      "z": 8,
      "name": "Soil_Mud_Dry"
    },
    {
      "x": 29,
      "y": 23,
      "z": 8,
      "name": "Soil_Dirt_Burnt"
    },
    {
      "x": 29,
      "y": 7,
      "z": 9,
      "name": "Rock_Basalt"
    },
    {
      "x": 29,
      "y": 8,
      "z": 9,
      "name": "Rock_Basalt"
    },
    {
      "x": 29,
      "y": 9,
      "z": 9,
      "name": "Rock_Basalt"
    },
    {
      "x": 29,
      "y": 10,
      "z": 9,
      "name": "Rock_Basalt"
    },
    {
      "x": 29,
      "y": 19,
      "z": 9,
      "name": "Rock_Basalt"
    },
    {
      "x": 29,
      "y": 20,
      "z": 9,
      "name": "Soil_Dirt_Burnt"
    },
    {
      "x": 29,
      "y": 21,
      "z": 9,
      "name": "Soil_Dirt_Burnt"
    },
    {
      "x": 29,
      "y": 22,
      "z": 9,
      "name": "Soil_Mud_Dry"
    },
    {
      "x": 29,
      "y": 23,
      "z": 9,
      "name": "Soil_Mud_Dry"
    },
    {
      "x": 29,
      "y": 6,
      "z": 10,
      "name": "Rock_Basalt"
    },
    {
      "x": 29,
      "y": 7,
      "z": 10,
      "name": "Rock_Basalt"
    },
    {
      "x": 29,
      "y": 8,
      "z": 10,
      "name": "Rock_Basalt"
    },
    {
      "x": 29,
      "y": 9,
      "z": 10,
      "name": "Rock_Basalt"
    },
    {
      "x": 29,
      "y": 10,
      "z": 10,
      "name": "Rock_Basalt"
    },
    {
      "x": 29,
      "y": 11,
      "z": 10,
      "name": "Rock_Basalt"
    },
    {
      "x": 29,
      "y": 12,
      "z": 10,
      "name": "Rock_Basalt"
    },
    {
      "x": 29,
      "y": 19,
      "z": 10,
      "name": "Rock_Basalt"
    },
    {
      "x": 29,
      "y": 20,
      "z": 10,
      "name": "Soil_Dirt_Burnt"
    },
    {
      "x": 29,
      "y": 21,
      "z": 10,
      "name": "Soil_Dirt_Burnt"
    },
    {
      "x": 29,
      "y": 22,
      "z": 10,
      "name": "Soil_Mud_Dry"
    },
    {
      "x": 29,
      "y": 23,
      "z": 10,
      "name": "Soil_Mud_Dry"
    },
    {
      "x": 29,
      "y": 5,
      "z": 11,
      "name": "Rock_Basalt"
    },
    {
      "x": 29,
      "y": 6,
      "z": 11,
      "name": "Rock_Basalt"
    },
    {
      "x": 29,
      "y": 7,
      "z": 11,
      "name": "Rock_Basalt"
    },
    {
      "x": 29,
      "y": 8,
      "z": 11,
      "name": "Rock_Basalt"
    },
    {
      "x": 29,
      "y": 9,
      "z": 11,
      "name": "Rock_Basalt"
    },
    {
      "x": 29,
      "y": 10,
      "z": 11,
      "name": "Rock_Basalt"
    },
    {
      "x": 29,
      "y": 11,
      "z": 11,
      "name": "Rock_Basalt"
    },
    {
      "x": 29,
      "y": 12,
      "z": 11,
      "name": "Rock_Basalt"
    },
    {
      "x": 29,
      "y": 13,
      "z": 11,
      "name": "Rock_Basalt"
    },
    {
      "x": 29,
      "y": 17,
      "z": 11,
      "name": "Rock_Basalt"
    },
    {
      "x": 29,
      "y": 18,
      "z": 11,
      "name": "Rock_Basalt"
    },
    {
      "x": 29,
      "y": 19,
      "z": 11,
      "name": "Rock_Basalt"
    },
    {
      "x": 29,
      "y": 20,
      "z": 11,
      "name": "Soil_Dirt_Burnt"
    },
    {
      "x": 29,
      "y": 21,
      "z": 11,
      "name": "Soil_Dirt_Burnt"
    },
    {
      "x": 29,
      "y": 22,
      "z": 11,
      "name": "Soil_Mud_Dry"
    },
    {
      "x": 29,
      "y": 5,
      "z": 12,
      "name": "Rock_Basalt"
    },
    {
      "x": 29,
      "y": 6,
      "z": 12,
      "name": "Rock_Basalt"
    },
    {
      "x": 29,
      "y": 7,
      "z": 12,
      "name": "Rock_Basalt"
    },
    {
      "x": 29,
      "y": 8,
      "z": 12,
      "name": "Rock_Basalt"
    },
    {
      "x": 29,
      "y": 9,
      "z": 12,
      "name": "Rock_Basalt"
    },
    {
      "x": 29,
      "y": 16,
      "z": 12,
      "name": "Soil_Dirt_Burnt"
    },
    {
      "x": 29,
      "y": 17,
      "z": 12,
      "name": "Rock_Basalt"
    },
    {
      "x": 29,
      "y": 18,
      "z": 12,
      "name": "Rock_Basalt"
    },
    {
      "x": 29,
      "y": 19,
      "z": 12,
      "name": "Rock_Basalt"
    },
    {
      "x": 29,
      "y": 20,
      "z": 12,
      "name": "Soil_Dirt_Burnt"
    },
    {
      "x": 29,
      "y": 21,
      "z": 12,
      "name": "Soil_Dirt_Burnt"
    },
    {
      "x": 29,
      "y": 22,
      "z": 12,
      "name": "Soil_Mud_Dry"
    },
    {
      "x": 29,
      "y": 16,
      "z": 13,
      "name": "Soil_Dirt_Burnt"
    },
    {
      "x": 29,
      "y": 17,
      "z": 13,
      "name": "Rock_Basalt"
    },
    {
      "x": 29,
      "y": 18,
      "z": 13,
      "name": "Rock_Basalt"
    },
    {
      "x": 29,
      "y": 19,
      "z": 13,
      "name": "Rock_Basalt"
    },
    {
      "x": 29,
      "y": 20,
      "z": 13,
      "name": "Soil_Dirt_Burnt"
    },
    {
      "x": 29,
      "y": 21,
      "z": 13,
      "name": "Soil_Dirt_Burnt"
    },
    {
      "x": 29,
      "y": 22,
      "z": 13,
      "name": "Soil_Mud_Dry"
    },
    {
      "x": 29,
      "y": 16,
      "z": 14,
      "name": "Soil_Dirt_Burnt"
    },
    {
      "x": 29,
      "y": 17,
      "z": 14,
      "name": "Rock_Basalt"
    },
    {
      "x": 29,
      "y": 18,
      "z": 14,
      "name": "Rock_Basalt"
    },
    {
      "x": 29,
      "y": 19,
      "z": 14,
