{
  "version": 8,
  "blockIdVersion": 8,
  "anchorX": 0,
  "anchorY": 0,
  "anchorZ": 0,
  "blocks": [
    {
      "x": -8,
      "y": 0,
      "z": -16,
      "name": "Rock_Ice"
    },
    {
      "x": -8,
      "y": 1,
      "z": -16,
      "name": "Rock_Ice"
    },
    {
      "x": -8,
      "y": 2,
      "z": -16,
      "name": "Rock_Ice"
    },
    {
      "x": -8,
      "y": 3,
      "z": -16,
      "name": "Rock_Ice"
    },
    {
      "x": -8,
      "y": 4,
      "z": -16,
      "name": "Rock_Ice"
    },
    {
      "x": -8,
      "y": 5,
      "z": -16,
      "name": "Rock_Ice"
    },
    {
      "x": -8,
      "y": 0,
      "z": -15,
      "name": "Rock_Ice"
    },
    {
      "x": -8,
      "y": 1,
      "z": -15,
      "name": "Rock_Ice"
    },
    {
      "x": -8,
      "y": 2,
      "z": -15,
      "name": "Rock_Ice"
    },
    {
      "x": -8,
      "y": 3,
      "z": -15,
      "name": "Rock_Ice"
    },
    {
      "x": -8,
      "y": 4,
      "z": -15,
      "name": "Rock_Ice"
    },
    {
      "x": -8,
      "y": 5,
      "z": -15,
      "name": "Rock_Ice"
    },
    {
      "x": -8,
      "y": 0,
      "z": -14,
      "name": "Rock_Ice"
    },
    {
      "x": -8,
      "y": 1,
      "z": -14,
      "name": "Rock_Ice"
    },
    {
      "x": -8,
      "y": 2,
      "z": -14,
      "name": "Rock_Ice"
    },
    {
      "x": -8,
      "y": 3,
      "z": -14,
      "name": "Rock_Ice"
    },
    {
      "x": -8,
      "y": 4,
      "z": -14,
      "name": "Rock_Ice"
    },
    {
      "x": -8,
      "y": 5,
      "z": -14,
      "name": "Rock_Ice"
    },
    {
      "x": -8,
      "y": 0,
      "z": -13,
      "name": "Rock_Ice"
    },
    {
      "x": -8,
      "y": 1,
      "z": -13,
      "name": "Rock_Ice"
    },
    {
      "x": -8,
      "y": 2,
      "z": -13,
      "name": "Rock_Ice"
    },
    {
      "x": -8,
      "y": 3,
      "z": -13,
      "name": "Rock_Ice"
    },
    {
      "x": -8,
      "y": 4,
      "z": -13,
      "name": "Rock_Ice"
    },
    {
      "x": -8,
      "y": 5,
      "z": -13,
      "name": "Rock_Ice"
    },
    {
      "x": -8,
      "y": 0,
      "z": -12,
      "name": "Rock_Ice"
    },
    {
      "x": -8,
      "y": 1,
      "z": -12,
      "name": "Rock_Ice"
    },
    {
      "x": -8,
      "y": 2,
      "z": -12,
      "name": "Rock_Ice"
    },
    {
      "x": -8,
      "y": 3,
      "z": -12,
      "name": "Rock_Ice"
    },
    {
      "x": -8,
      "y": 4,
      "z": -12,
      "name": "Rock_Ice"
    },
    {
      "x": -8,
      "y": 5,
      "z": -12,
      "name": "Rock_Ice"
    },
    {
      "x": -8,
      "y": 0,
      "z": -11,
      "name": "Rock_Ice"
    },
    {
      "x": -8,
      "y": 1,
      "z": -11,
      "name": "Rock_Ice"
    },
    {
      "x": -8,
      "y": 2,
      "z": -11,
      "name": "Rock_Ice"
    },
    {
      "x": -8,
      "y": 3,
      "z": -11,
      "name": "Rock_Ice"
    },
    {
      "x": -8,
      "y": 4,
      "z": -11,
      "name": "Rock_Ice"
    },
    {
      "x": -8,
      "y": 5,
      "z": -11,
      "name": "Rock_Ice"
    },
    {
      "x": -8,
      "y": 0,
      "z": -10,
      "name": "Rock_Ice"
    },
    {
      "x": -8,
      "y": 1,
      "z": -10,
      "name": "Rock_Ice"
    },
    {
      "x": -8,
      "y": 2,
      "z": -10,
      "name": "Rock_Ice"
    },
    {
      "x": -8,
      "y": 3,
      "z": -10,
      "name": "Rock_Ice"
    },
    {
      "x": -8,
      "y": 4,
      "z": -10,
      "name": "Rock_Ice"
    },
    {
      "x": -8,
      "y": 5,
      "z": -10,
      "name": "Rock_Ice"
    },
    {
      "x": -8,
      "y": 0,
      "z": -9,
      "name": "Rock_Basalt_Cobble"
    },
    {
      "x": -8,
      "y": 1,
      "z": -9,
      "name": "Empty"
    },
    {
      "x": -8,
      "y": 2,
      "z": -9,
      "name": "Empty"
    },
    {
      "x": -8,
      "y": 3,
      "z": -9,
      "name": "Empty"
    },
    {
      "x": -8,
      "y": 4,
      "z": -9,
      "name": "*Rock_Shale_Brick_Stairs_State_Definitions_Corner_Right",
      "rotation": 9
    },
    {
      "x": -8,
      "y": 5,
      "z": -9,
      "name": "Rock_Ice"
    },
    {
      "x": -8,
      "y": 0,
      "z": -8,
      "name": "Rock_Basalt_Cobble"
    },
    {
      "x": -8,
      "y": 1,
      "z": -8,
      "name": "Empty"
    },
    {
      "x": -8,
      "y": 2,
      "z": -8,
      "name": "Empty"
    },
    {
      "x": -8,
      "y": 3,
      "z": -8,
      "name": "Empty"
    },
    {
      "x": -8,
      "y": 4,
      "z": -8,
      "name": "Empty"
    },
    {
      "x": -8,
      "y": 5,
      "z": -8,
      "name": "Rock_Ice"
    },
    {
      "x": -8,
      "y": 0,
      "z": -7,
      "name": "Rock_Basalt_Cobble"
    },
    {
      "x": -8,
      "y": 1,
      "z": -7,
      "name": "Empty"
    },
    {
      "x": -8,
      "y": 2,
      "z": -7,
      "name": "Empty"
    },
    {
      "x": -8,
      "y": 3,
      "z": -7,
      "name": "Empty"
    },
    {
      "x": -8,
      "y": 4,
      "z": -7,
      "name": "Rock_Ice"
    },
    {
      "x": -8,
      "y": 5,
      "z": -7,
      "name": "Rock_Ice"
    },
    {
      "x": -8,
      "y": 0,
      "z": -6,
      "name": "Rock_Ice"
    },
    {
      "x": -8,
      "y": 1,
      "z": -6,
      "name": "Rock_Ice"
    },
    {
      "x": -8,
      "y": 2,
      "z": -6,
      "name": "Rock_Ice"
    },
    {
      "x": -8,
      "y": 3,
      "z": -6,
      "name": "Rock_Ice"
    },
    {
      "x": -8,
      "y": 4,
      "z": -6,
      "name": "Rock_Ice"
    },
    {
      "x": -8,
      "y": 5,
      "z": -6,
      "name": "Rock_Ice"
    },
    {
      "x": -8,
      "y": 0,
      "z": -5,
      "name": "Rock_Ice"
    },
    {
      "x": -8,
      "y": 1,
      "z": -5,
      "name": "Rock_Ice"
    },
    {
      "x": -8,
      "y": 2,
      "z": -5,
      "name": "Rock_Ice"
    },
    {
      "x": -8,
      "y": 3,
      "z": -5,
      "name": "Rock_Ice"
    },
    {
      "x": -8,
      "y": 4,
      "z": -5,
      "name": "Rock_Ice"
    },
    {
      "x": -8,
      "y": 5,
      "z": -5,
      "name": "Rock_Ice"
    },
    {
      "x": -8,
      "y": 0,
      "z": -4,
      "name": "Rock_Ice"
    },
    {
      "x": -8,
      "y": 1,
      "z": -4,
      "name": "Rock_Ice"
    },
    {
      "x": -8,
      "y": 2,
      "z": -4,
      "name": "Rock_Ice"
    },
    {
      "x": -8,
      "y": 3,
      "z": -4,
      "name": "Rock_Ice"
    },
    {
      "x": -8,
      "y": 4,
      "z": -4,
      "name": "Rock_Ice"
    },
    {
      "x": -8,
      "y": 5,
      "z": -4,
      "name": "Rock_Ice"
    },
    {
      "x": -8,
      "y": 0,
      "z": -3,
      "name": "Rock_Ice"
    },
    {
      "x": -8,
      "y": 1,
      "z": -3,
      "name": "Rock_Ice"
    },
    {
      "x": -8,
      "y": 2,
      "z": -3,
      "name": "Rock_Ice"
    },
    {
      "x": -8,
      "y": 3,
      "z": -3,
      "name": "Rock_Ice"
    },
    {
      "x": -8,
      "y": 4,
      "z": -3,
      "name": "Rock_Ice"
    },
    {
      "x": -8,
      "y": 5,
      "z": -3,
      "name": "Rock_Ice"
    },
    {
      "x": -8,
      "y": 0,
      "z": -2,
      "name": "Rock_Ice"
    },
    {
      "x": -8,
      "y": 1,
      "z": -2,
      "name": "Rock_Ice"
    },
    {
      "x": -8,
      "y": 2,
      "z": -2,
      "name": "Rock_Ice"
    },
    {
      "x": -8,
      "y": 3,
      "z": -2,
      "name": "Rock_Ice"
    },
    {
      "x": -8,
      "y": 4,
      "z": -2,
      "name": "Rock_Ice"
    },
    {
      "x": -8,
      "y": 5,
      "z": -2,
      "name": "Rock_Ice"
    },
    {
      "x": -8,
      "y": 0,
      "z": -1,
      "name": "Rock_Ice"
    },
    {
      "x": -8,
      "y": 1,
      "z": -1,
      "name": "Rock_Ice"
    },
    {
      "x": -8,
      "y": 2,
      "z": -1,
      "name": "Rock_Ice"
    },
    {
      "x": -8,
      "y": 3,
      "z": -1,
      "name": "Rock_Ice"
    },
    {
      "x": -8,
      "y": 4,
      "z": -1,
      "name": "Rock_Ice"
    },
    {
      "x": -8,
      "y": 5,
      "z": -1,
      "name": "Rock_Ice"
    },
    {
      "x": -8,
      "y": 0,
      "z": 0,
      "name": "Rock_Ice"
    },
    {
      "x": -8,
      "y": 1,
      "z": 0,
      "name": "Rock_Ice"
    },
    {
      "x": -8,
      "y": 2,
      "z": 0,
      "name": "Rock_Ice"
    },
    {
      "x": -8,
      "y": 3,
      "z": 0,
      "name": "Rock_Ice"
    },
    {
      "x": -8,
      "y": 4,
      "z": 0,
      "name": "Rock_Ice"
    },
    {
      "x": -8,
      "y": 5,
      "z": 0,
      "name": "Rock_Ice"
    },
    {
      "x": -7,
      "y": 0,
      "z": -16,
      "name": "Rock_Ice"
    },
    {
      "x": -7,
      "y": 1,
      "z": -16,
      "name": "Rock_Ice"
    },
    {
      "x": -7,
      "y": 2,
      "z": -16,
      "name": "Rock_Ice"
    },
    {
      "x": -7,
      "y": 3,
      "z": -16,
      "name": "Rock_Ice"
    },
    {
      "x": -7,
      "y": 4,
      "z": -16,
      "name": "Rock_Ice"
    },
    {
      "x": -7,
      "y": 5,
      "z": -16,
      "name": "Rock_Ice"
    },
    {
      "x": -7,
      "y": 0,
      "z": -15,
      "name": "Rock_Shale_Brick"
    },
    {
      "x": -7,
      "y": 1,
      "z": -15,
      "name": "Rock_Shale_Brick_Ornate"
    },
    {
      "x": -7,
      "y": 2,
      "z": -15,
      "name": "Rock_Shale"
    },
    {
      "x": -7,
      "y": 3,
      "z": -15,
      "name": "Rock_Shale"
    },
    {
      "x": -7,
      "y": 4,
      "z": -15,
      "name": "Rock_Shale_Brick"
    },
    {
      "x": -7,
      "y": 5,
      "z": -15,
      "name": "Rock_Ice"
    },
    {
      "x": -7,
      "y": 0,
      "z": -14,
      "name": "Rock_Shale_Brick"
    },
    {
      "x": -7,
      "y": 1,
      "z": -14,
      "name": "Rock_Shale_Brick_Ornate"
    },
    {
      "x": -7,
      "y": 2,
      "z": -14,
      "name": "Rock_Shale"
    },
    {
      "x": -7,
      "y": 3,
      "z": -14,
      "name": "Rock_Shale"
    },
    {
      "x": -7,
      "y": 4,
      "z": -14,
      "name": "Rock_Shale_Brick"
    },
    {
      "x": -7,
      "y": 5,
      "z": -14,
      "name": "Rock_Ice"
    },
    {
      "x": -7,
      "y": 0,
      "z": -13,
      "name": "Soil_Snow"
    },
    {
      "x": -7,
      "y": 1,
      "z": -13,
      "name": "Empty"
    },
    {
      "x": -7,
      "y": 2,
      "z": -13,
      "name": "Empty"
    },
    {
      "x": -7,
      "y": 3,
      "z": -13,
      "name": "Empty"
    },
    {
      "x": -7,
      "y": 4,
      "z": -13,
      "name": "Rock_Ice"
    },
    {
      "x": -7,
      "y": 5,
      "z": -13,
      "name": "Rock_Ice"
    },
    {
      "x": -7,
      "y": 0,
      "z": -12,
      "name": "Soil_Snow"
    },
    {
      "x": -7,
      "y": 1,
      "z": -12,
      "name": "Empty"
    },
    {
      "x": -7,
      "y": 2,
      "z": -12,
      "name": "Empty"
    },
    {
      "x": -7,
      "y": 3,
      "z": -12,
      "name": "Empty"
    },
    {
      "x": -7,
      "y": 4,
      "z": -12,
      "name": "Rock_Ice"
    },
    {
      "x": -7,
      "y": 5,
      "z": -12,
      "name": "Rock_Ice"
    },
    {
      "x": -7,
      "y": 0,
      "z": -11,
      "name": "Rock_Shale_Brick"
    },
    {
      "x": -7,
      "y": 1,
      "z": -11,
      "name": "Rock_Shale_Brick_Ornate"
    },
    {
      "x": -7,
      "y": 2,
      "z": -11,
      "name": "Rock_Shale"
    },
    {
      "x": -7,
      "y": 3,
      "z": -11,
      "name": "Rock_Shale"
    },
    {
      "x": -7,
      "y": 4,
      "z": -11,
      "name": "Rock_Shale_Brick"
    },
    {
      "x": -7,
      "y": 5,
      "z": -11,
      "name": "Rock_Ice"
    },
    {
      "x": -7,
      "y": 0,
      "z": -10,
      "name": "Rock_Shale_Brick"
    },
    {
      "x": -7,
      "y": 1,
      "z": -10,
      "name": "Rock_Shale_Brick_Ornate"
    },
    {
      "x": -7,
      "y": 2,
      "z": -10,
      "name": "Rock_Shale"
    },
    {
      "x": -7,
      "y": 3,
      "z": -10,
      "name": "Rock_Shale"
    },
    {
      "x": -7,
      "y": 4,
      "z": -10,
      "name": "Rock_Shale_Brick"
    },
    {
      "x": -7,
      "y": 5,
      "z": -10,
      "name": "Rock_Ice"
    },
    {
      "x": -7,
      "y": 0,
      "z": -9,
      "name": "Soil_Dirt_Cold"
    },
    {
      "x": -7,
      "y": 1,
      "z": -9,
      "name": "Empty"
    },
    {
      "x": -7,
      "y": 2,
      "z": -9,
      "name": "Empty"
    },
    {
      "x": -7,
      "y": 3,
      "z": -9,
      "name": "Empty"
    },
    {
      "x": -7,
      "y": 4,
      "z": -9,
      "name": "Rock_Shale_Brick_Stairs",
      "rotation": 10
    },
    {
      "x": -7,
      "y": 5,
      "z": -9,
      "name": "Rock_Ice"
    },
    {
      "x": -7,
      "y": 0,
      "z": -8,
      "name": "Rock_Basalt_Cobble"
    },
    {
      "x": -7,
      "y": 1,
      "z": -8,
      "name": "Empty"
    },
    {
      "x": -7,
      "y": 2,
      "z": -8,
      "name": "Empty"
    },
    {
      "x": -7,
      "y": 3,
      "z": -8,
      "name": "Empty"
    },
    {
      "x": -7,
      "y": 4,
      "z": -8,
      "name": "Empty"
    },
    {
      "x": -7,
      "y": 5,
      "z": -8,
      "name": "Rock_Ice"
    },
    {
      "x": -7,
      "y": 0,
      "z": -7,
      "name": "Rock_Ice"
    },
    {
      "x": -7,
      "y": 1,
      "z": -7,
      "name": "Empty"
    },
    {
      "x": -7,
      "y": 2,
      "z": -7,
      "name": "Empty"
    },
    {
      "x": -7,
      "y": 3,
      "z": -7,
      "name": "Rock_Ice_Icicles",
      "rotation": 8
    },
    {
      "x": -7,
      "y": 4,
      "z": -7,
      "name": "Rock_Ice"
    },
    {
      "x": -7,
      "y": 5,
      "z": -7,
      "name": "Rock_Ice"
    },
    {
      "x": -7,
      "y": 0,
      "z": -6,
      "name": "Rock_Shale_Brick"
    },
    {
      "x": -7,
      "y": 1,
      "z": -6,
      "name": "Rock_Ice"
    },
    {
      "x": -7,
      "y": 2,
      "z": -6,
      "name": "Rock_Ice"
    },
    {
      "x": -7,
      "y": 3,
      "z": -6,
      "name": "Rock_Ice"
    },
    {
      "x": -7,
      "y": 4,
      "z": -6,
      "name": "Rock_Ice"
    },
    {
      "x": -7,
      "y": 5,
      "z": -6,
      "name": "Rock_Ice"
    },
    {
      "x": -7,
      "y": 0,
      "z": -5,
      "name": "Rock_Shale_Brick"
    },
    {
      "x": -7,
      "y": 1,
      "z": -5,
      "name": "Rock_Ice"
    },
    {
      "x": -7,
      "y": 2,
      "z": -5,
      "name": "Rock_Ice"
    },
    {
      "x": -7,
      "y": 3,
      "z": -5,
      "name": "Rock_Ice"
    },
    {
      "x": -7,
      "y": 4,
      "z": -5,
      "name": "Rock_Ice"
    },
    {
      "x": -7,
      "y": 5,
      "z": -5,
      "name": "Rock_Ice"
    },
    {
      "x": -7,
      "y": 0,
      "z": -4,
      "name": "Soil_Snow"
    },
    {
      "x": -7,
      "y": 1,
      "z": -4,
      "name": "Soil_Snow_Half"
    },
    {
      "x": -7,
      "y": 2,
      "z": -4,
      "name": "Empty"
    },
    {
      "x": -7,
      "y": 3,
      "z": -4,
      "name": "Empty"
    },
    {
      "x": -7,
      "y": 4,
      "z": -4,
      "name": "Rock_Ice"
    },
    {
      "x": -7,
      "y": 5,
      "z": -4,
      "name": "Rock_Ice"
    },
    {
      "x": -7,
      "y": 0,
      "z": -3,
      "name": "Soil_Snow"
    },
    {
      "x": -7,
      "y": 1,
      "z": -3,
      "name": "Soil_Snow_Half"
    },
    {
      "x": -7,
      "y": 2,
      "z": -3,
      "name": "Empty"
    },
    {
      "x": -7,
      "y": 3,
      "z": -3,
      "name": "Empty"
    },
    {
      "x": -7,
      "y": 4,
      "z": -3,
      "name": "Rock_Ice"
    },
    {
      "x": -7,
      "y": 5,
      "z": -3,
      "name": "Rock_Ice"
    },
    {
      "x": -7,
      "y": 0,
      "z": -2,
      "name": "Rock_Shale_Brick"
    },
    {
      "x": -7,
      "y": 1,
      "z": -2,
      "name": "Rock_Shale_Brick_Ornate"
    },
    {
      "x": -7,
      "y": 2,
      "z": -2,
      "name": "Rock_Ice"
    },
    {
      "x": -7,
      "y": 3,
      "z": -2,
      "name": "Rock_Ice"
    },
    {
      "x": -7,
      "y": 4,
      "z": -2,
      "name": "Rock_Ice"
    },
    {
      "x": -7,
      "y": 5,
      "z": -2,
      "name": "Rock_Ice"
    },
    {
      "x": -7,
      "y": 0,
      "z": -1,
      "name": "Rock_Shale_Brick"
    },
    {
      "x": -7,
      "y": 1,
      "z": -1,
      "name": "Rock_Shale_Brick_Ornate"
    },
    {
      "x": -7,
      "y": 2,
      "z": -1,
      "name": "Rock_Shale"
    },
    {
      "x": -7,
      "y": 3,
      "z": -1,
      "name": "Rock_Ice"
    },
    {
      "x": -7,
      "y": 4,
      "z": -1,
      "name": "Rock_Ice"
    },
    {
      "x": -7,
      "y": 5,
      "z": -1,
      "name": "Rock_Ice"
    },
    {
      "x": -7,
      "y": 0,
      "z": 0,
      "name": "Rock_Ice"
    },
    {
      "x": -7,
      "y": 1,
      "z": 0,
      "name": "Rock_Ice"
    },
    {
      "x": -7,
      "y": 2,
      "z": 0,
      "name": "Rock_Ice"
    },
    {
      "x": -7,
      "y": 3,
      "z": 0,
      "name": "Rock_Ice"
    },
    {
      "x": -7,
      "y": 4,
      "z": 0,
      "name": "Rock_Ice"
    },
    {
      "x": -7,
      "y": 5,
      "z": 0,
      "name": "Rock_Ice"
    },
    {
      "x": -6,
      "y": 0,
      "z": -16,
      "name": "Rock_Ice"
    },
    {
      "x": -6,
      "y": 1,
      "z": -16,
      "name": "Rock_Ice"
    },
    {
      "x": -6,
      "y": 2,
      "z": -16,
      "name": "Rock_Ice"
    },
    {
      "x": -6,
      "y": 3,
      "z": -16,
      "name": "Rock_Ice"
    },
    {
      "x": -6,
      "y": 4,
      "z": -16,
      "name": "Rock_Ice"
    },
    {
      "x": -6,
      "y": 5,
      "z": -16,
      "name": "Rock_Ice"
    },
    {
      "x": -6,
      "y": 0,
      "z": -15,
      "name": "Rock_Shale_Brick"
    },
    {
      "x": -6,
      "y": 1,
      "z": -15,
      "name": "Rock_Shale_Brick_Ornate"
    },
    {
      "x": -6,
      "y": 2,
      "z": -15,
      "name": "Rock_Shale"
    },
    {
      "x": -6,
      "y": 3,
      "z": -15,
      "name": "Rock_Shale"
    },
    {
      "x": -6,
      "y": 4,
      "z": -15,
      "name": "Rock_Shale_Brick"
    },
    {
      "x": -6,
      "y": 5,
      "z": -15,
      "name": "Rock_Ice"
    },
    {
      "x": -6,
      "y": 0,
      "z": -14,
      "name": "Rock_Shale_Brick"
    },
    {
      "x": -6,
      "y": 1,
      "z": -14,
      "name": "Rock_Shale_Brick_Ornate"
    },
    {
      "x": -6,
      "y": 2,
      "z": -14,
      "name": "Rock_Shale"
    },
    {
      "x": -6,
      "y": 3,
      "z": -14,
      "name": "Rock_Shale"
    },
    {
      "x": -6,
      "y": 4,
      "z": -14,
      "name": "Rock_Shale_Brick"
    },
    {
      "x": -6,
      "y": 5,
      "z": -14,
      "name": "Rock_Ice"
    },
    {
      "x": -6,
      "y": 0,
      "z": -13,
      "name": "Soil_Snow"
    },
    {
      "x": -6,
      "y": 1,
      "z": -13,
      "name": "Empty"
    },
    {
      "x": -6,
      "y": 2,
      "z": -13,
      "name": "Empty"
    },
    {
      "x": -6,
      "y": 3,
      "z": -13,
      "name": "Empty"
    },
    {
      "x": -6,
      "y": 4,
      "z": -13,
      "name": "Rock_Ice"
    },
    {
      "x": -6,
      "y": 5,
      "z": -13,
      "name": "Rock_Ice"
    },
    {
      "x": -6,
      "y": 0,
      "z": -12,
      "name": "Soil_Snow"
    },
    {
      "x": -6,
      "y": 1,
      "z": -12,
      "name": "Empty"
    },
    {
      "x": -6,
      "y": 2,
      "z": -12,
      "name": "Empty"
    },
    {
      "x": -6,
      "y": 3,
      "z": -12,
      "name": "Empty"
    },
    {
      "x": -6,
      "y": 4,
      "z": -12,
      "name": "Rock_Ice"
    },
    {
      "x": -6,
      "y": 5,
      "z": -12,
      "name": "Rock_Ice"
    },
    {
      "x": -6,
      "y": 0,
      "z": -11,
      "name": "Rock_Shale_Brick"
    },
    {
      "x": -6,
      "y": 1,
      "z": -11,
      "name": "Rock_Shale_Brick_Ornate"
    },
    {
      "x": -6,
      "y": 2,
      "z": -11,
      "name": "Rock_Shale"
    },
    {
      "x": -6,
      "y": 3,
      "z": -11,
      "name": "Rock_Shale"
    },
    {
      "x": -6,
      "y": 4,
      "z": -11,
      "name": "Rock_Shale_Brick"
    },
    {
      "x": -6,
      "y": 5,
      "z": -11,
      "name": "Rock_Ice"
    },
    {
      "x": -6,
      "y": 0,
      "z": -10,
      "name": "Rock_Shale_Brick"
    },
    {
      "x": -6,
      "y": 1,
      "z": -10,
      "name": "Rock_Shale_Brick_Ornate"
    },
    {
      "x": -6,
      "y": 2,
      "z": -10,
      "name": "Rock_Shale"
    },
    {
      "x": -6,
      "y": 3,
      "z": -10,
      "name": "Rock_Shale"
    },
    {
      "x": -6,
      "y": 4,
      "z": -10,
      "name": "Rock_Shale_Brick"
    },
    {
      "x": -6,
      "y": 5,
      "z": -10,
      "name": "Rock_Ice"
    },
    {
      "x": -6,
      "y": 0,
      "z": -9,
      "name": "Soil_Snow"
    },
    {
      "x": -6,
      "y": 1,
      "z": -9,
      "name": "Empty"
    },
    {
      "x": -6,
      "y": 2,
      "z": -9,
      "name": "Empty"
    },
    {
      "x": -6,
      "y": 3,
      "z": -9,
      "name": "Empty"
    },
    {
      "x": -6,
      "y": 4,
      "z": -9,
      "name": "Rock_Shale_Brick_Stairs",
      "rotation": 10
    },
    {
      "x": -6,
      "y": 5,
      "z": -9,
      "name": "Rock_Ice"
    },
    {
      "x": -6,
      "y": 0,
      "z": -8,
      "name": "Soil_Dirt_Cold"
    },
    {
      "x": -6,
      "y": 1,
      "z": -8,
      "name": "Empty"
    },
    {
      "x": -6,
      "y": 2,
      "z": -8,
      "name": "Empty"
    },
    {
      "x": -6,
      "y": 3,
      "z": -8,
      "name": "Empty"
    },
    {
      "x": -6,
      "y": 4,
      "z": -8,
      "name": "Rock_Ice"
    },
    {
      "x": -6,
      "y": 5,
      "z": -8,
      "name": "Rock_Ice"
    },
    {
      "x": -6,
      "y": 0,
      "z": -7,
      "name": "Rock_Ice"
    },
    {
      "x": -6,
      "y": 1,
      "z": -7,
      "name": "Rock_Ice"
    },
    {
      "x": -6,
      "y": 2,
      "z": -7,
      "name": "Rock_Ice"
    },
    {
      "x": -6,
      "y": 3,
      "z": -7,
      "name": "Rock_Ice"
    },
    {
      "x": -6,
      "y": 4,
      "z": -7,
      "name": "Rock_Ice"
    },
    {
      "x": -6,
      "y": 5,
      "z": -7,
      "name": "Rock_Ice"
    },
    {
      "x": -6,
      "y": 0,
      "z": -6,
      "name": "Rock_Ice"
    },
    {
      "x": -6,
      "y": 1,
      "z": -6,
      "name": "Rock_Ice"
    },
    {
      "x": -6,
      "y": 2,
      "z": -6,
      "name": "Rock_Ice"
    },
    {
      "x": -6,
      "y": 3,
      "z": -6,
      "name": "Rock_Ice"
    },
    {
      "x": -6,
      "y": 4,
      "z": -6,
      "name": "Rock_Ice"
    },
    {
      "x": -6,
      "y": 5,
      "z": -6,
      "name": "Rock_Ice"
    },
    {
      "x": -6,
      "y": 0,
      "z": -5,
      "name": "Rock_Shale_Brick"
    },
    {
      "x": -6,
      "y": 1,
      "z": -5,
      "name": "Rock_Ice"
    },
    {
      "x": -6,
      "y": 2,
      "z": -5,
      "name": "Rock_Ice"
    },
    {
      "x": -6,
      "y": 3,
      "z": -5,
      "name": "Rock_Ice"
    },
    {
      "x": -6,
      "y": 4,
      "z": -5,
      "name": "Rock_Ice"
    },
    {
      "x": -6,
      "y": 5,
      "z": -5,
      "name": "Rock_Ice"
    },
    {
      "x": -6,
      "y": 0,
      "z": -4,
      "name": "Soil_Snow"
    },
    {
      "x": -6,
      "y": 1,
      "z": -4,
      "name": "Empty"
    },
    {
      "x": -6,
      "y": 2,
      "z": -4,
      "name": "Empty"
    },
    {
      "x": -6,
      "y": 3,
      "z": -4,
      "name": "Empty"
    },
    {
      "x": -6,
      "y": 4,
      "z": -4,
      "name": "Rock_Ice"
    },
    {
      "x": -6,
      "y": 5,
      "z": -4,
      "name": "Rock_Ice"
    },
    {
      "x": -6,
      "y": 0,
      "z": -3,
      "name": "Soil_Snow"
    },
    {
      "x": -6,
      "y": 1,
      "z": -3,
      "name": "Empty"
    },
    {
      "x": -6,
      "y": 2,
      "z": -3,
      "name": "Rock_Ice_Stalactite_Large",
      "filler": 31744,
      "rotation": 8
    },
    {
      "x": -6,
      "y": 3,
      "z": -3,
      "name": "Rock_Ice_Stalactite_Large",
      "rotation": 8
    },
    {
      "x": -6,
      "y": 4,
      "z": -3,
      "name": "Rock_Ice"
    },
    {
      "x": -6,
      "y": 5,
      "z": -3,
      "name": "Rock_Ice"
    },
    {
      "x": -6,
      "y": 0,
      "z": -2,
      "name": "Rock_Shale_Brick"
    },
    {
      "x": -6,
      "y": 1,
      "z": -2,
      "name": "Rock_Shale_Brick_Ornate"
    },
    {
      "x": -6,
      "y": 2,
      "z": -2,
      "name": "Rock_Shale"
    },
    {
      "x": -6,
      "y": 3,
      "z": -2,
      "name": "Rock_Ice"
    },
    {
      "x": -6,
      "y": 4,
      "z": -2,
      "name": "Rock_Ice"
    },
    {
      "x": -6,
      "y": 5,
      "z": -2,
      "name": "Rock_Ice"
    },
    {
      "x": -6,
      "y": 0,
      "z": -1,
      "name": "Rock_Shale_Brick"
    },
    {
      "x": -6,
      "y": 1,
      "z": -1,
      "name": "Rock_Shale_Brick_Ornate"
    },
    {
      "x": -6,
      "y": 2,
      "z": -1,
      "name": "Rock_Shale"
    },
    {
      "x": -6,
      "y": 3,
      "z": -1,
      "name": "Rock_Ice"
    },
    {
      "x": -6,
      "y": 4,
      "z": -1,
      "name": "Rock_Ice"
    },
    {
      "x": -6,
      "y": 5,
      "z": -1,
      "name": "Rock_Ice"
    },
    {
      "x": -6,
      "y": 0,
      "z": 0,
      "name": "Rock_Ice"
    },
    {
      "x": -6,
      "y": 1,
      "z": 0,
      "name": "Rock_Ice"
    },
    {
      "x": -6,
      "y": 2,
      "z": 0,
      "name": "Rock_Ice"
    },
    {
      "x": -6,
      "y": 3,
      "z": 0,
      "name": "Rock_Ice"
    },
    {
      "x": -6,
      "y": 4,
      "z": 0,
      "name": "Rock_Ice"
    },
    {
      "x": -6,
      "y": 5,
      "z": 0,
      "name": "Rock_Ice"
    },
    {
      "x": -5,
      "y": 0,
      "z": -16,
      "name": "Rock_Ice"
    },
    {
      "x": -5,
      "y": 1,
      "z": -16,
      "name": "Rock_Ice"
    },
    {
      "x": -5,
      "y": 2,
      "z": -16,
      "name": "Rock_Ice"
    },
    {
      "x": -5,
      "y": 3,
      "z": -16,
      "name": "Rock_Ice"
    },
    {
      "x": -5,
      "y": 4,
      "z": -16,
      "name": "Rock_Ice"
    },
    {
      "x": -5,
      "y": 5,
      "z": -16,
      "name": "Rock_Ice"
    },
    {
      "x": -5,
      "y": 0,
      "z": -15,
      "name": "Soil_Snow"
    },
    {
      "x": -5,
      "y": 1,
      "z": -15,
      "name": "Empty"
    },
    {
      "x": -5,
      "y": 2,
      "z": -15,
      "name": "Empty"
    },
    {
      "x": -5,
      "y": 3,
      "z": -15,
      "name": "Empty"
    },
    {
      "x": -5,
      "y": 4,
      "z": -15,
      "name": "Rock_Shale_Brick_Stairs",
      "rotation": 11
    },
    {
      "x": -5,
      "y": 5,
      "z": -15,
      "name": "Rock_Ice"
    },
    {
      "x": -5,
      "y": 0,
      "z": -14,
      "name": "Soil_Snow"
    },
    {
      "x": -5,
      "y": 1,
      "z": -14,
      "name": "Empty"
    },
    {
      "x": -5,
      "y": 2,
      "z": -14,
      "name": "Empty"
    },
    {
      "x": -5,
      "y": 3,
      "z": -14,
      "name": "Empty"
    },
    {
      "x": -5,
      "y": 4,
      "z": -14,
      "name": "Rock_Shale_Brick_Stairs",
      "rotation": 11
    },
    {
      "x": -5,
      "y": 5,
      "z": -14,
      "name": "Rock_Ice"
    },
    {
      "x": -5,
      "y": 0,
      "z": -13,
      "name": "Soil_Snow"
    },
    {
      "x": -5,
      "y": 1,
      "z": -13,
      "name": "Empty"
    },
    {
      "x": -5,
      "y": 2,
      "z": -13,
      "name": "Empty"
    },
    {
      "x": -5,
      "y": 3,
      "z": -13,
      "name": "Empty"
    },
    {
      "x": -5,
      "y": 4,
      "z": -13,
      "name": "Rock_Ice"
    },
    {
      "x": -5,
      "y": 5,
      "z": -13,
      "name": "Rock_Ice"
    },
    {
      "x": -5,
      "y": 0,
      "z": -12,
      "name": "Soil_Snow"
    },
    {
      "x": -5,
      "y": 1,
      "z": -12,
      "name": "Empty"
    },
    {
      "x": -5,
      "y": 2,
      "z": -12,
      "name": "Empty"
    },
    {
      "x": -5,
      "y": 3,
      "z": -12,
      "name": "Empty"
    },
    {
      "x": -5,
      "y": 4,
      "z": -12,
      "name": "Rock_Ice"
    },
    {
      "x": -5,
      "y": 5,
      "z": -12,
      "name": "Rock_Ice"
    },
    {
      "x": -5,
      "y": 0,
      "z": -11,
      "name": "Rock_Ice"
    },
    {
      "x": -5,
      "y": 1,
      "z": -11,
      "name": "Rock_Ice"
    },
    {
      "x": -5,
      "y": 2,
      "z": -11,
      "name": "Empty"
    },
    {
      "x": -5,
      "y": 3,
      "z": -11,
      "name": "Empty"
    },
    {
      "x": -5,
      "y": 4,
      "z": -11,
      "name": "Rock_Ice"
    },
    {
      "x": -5,
      "y": 5,
      "z": -11,
      "name": "Rock_Ice"
    },
    {
      "x": -5,
      "y": 0,
      "z": -10,
      "name": "Rock_Ice"
    },
    {
      "x": -5,
      "y": 1,
      "z": -10,
      "name": "Rock_Ice"
    },
    {
      "x": -5,
      "y": 2,
      "z": -10,
      "name": "Rock_Ice"
    },
    {
      "x": -5,
      "y": 3,
      "z": -10,
      "name": "Empty"
    },
    {
      "x": -5,
      "y": 4,
      "z": -10,
      "name": "Rock_Shale_Brick_Stairs",
      "rotation": 11
    },
    {
      "x": -5,
      "y": 5,
      "z": -10,
      "name": "Rock_Ice"
    },
    {
      "x": -5,
      "y": 0,
      "z": -9,
      "name": "Soil_Snow"
    },
    {
      "x": -5,
      "y": 1,
      "z": -9,
      "name": "Empty"
    },
    {
      "x": -5,
      "y": 2,
      "z": -9,
      "name": "Empty"
    },
    {
      "x": -5,
      "y": 3,
      "z": -9,
      "name": "Empty"
    },
    {
      "x": -5,
      "y": 4,
      "z": -9,
      "name": "*Rock_Shale_Brick_Stairs_State_Definitions_Corner_Right",
      "rotation": 10
    },
    {
      "x": -5,
      "y": 5,
      "z": -9,
      "name": "Rock_Ice"
    },
    {
      "x": -5,
      "y": 0,
      "z": -8,
      "name": "Soil_Dirt_Cold"
    },
    {
      "x": -5,
      "y": 1,
      "z": -8,
      "name": "Empty"
    },
    {
      "x": -5,
      "y": 2,
      "z": -8,
      "name": "Empty"
    },
    {
      "x": -5,
      "y": 3,
      "z": -8,
      "name": "Empty"
    },
    {
      "x": -5,
      "y": 4,
      "z": -8,
      "name": "Rock_Ice"
    },
    {
      "x": -5,
      "y": 5,
      "z": -8,
      "name": "Rock_Ice"
    },
    {
      "x": -5,
      "y": 0,
      "z": -7,
      "name": "Rock_Ice"
    },
    {
      "x": -5,
      "y": 1,
      "z": -7,
      "name": "Rock_Ice"
    },
    {
      "x": -5,
      "y": 2,
      "z": -7,
      "name": "Rock_Ice"
    },
    {
      "x": -5,
      "y": 3,
      "z": -7,
      "name": "Rock_Ice"
    },
    {
      "x": -5,
      "y": 4,
      "z": -7,
      "name": "Rock_Ice"
    },
    {
      "x": -5,
      "y": 5,
      "z": -7,
      "name": "Rock_Ice"
    },
    {
      "x": -5,
      "y": 0,
      "z": -6,
      "name": "Rock_Ice"
    },
    {
      "x": -5,
      "y": 1,
      "z": -6,
      "name": "Rock_Ice"
    },
    {
      "x": -5,
      "y": 2,
      "z": -6,
      "name": "Rock_Ice"
    },
    {
      "x": -5,
      "y": 3,
      "z": -6,
      "name": "Rock_Ice"
    },
    {
      "x": -5,
      "y": 4,
      "z": -6,
      "name": "Rock_Ice"
    },
    {
      "x": -5,
      "y": 5,
      "z": -6,
      "name": "Rock_Ice"
    },
    {
      "x": -5,
      "y": 0,
      "z": -5,
      "name": "Soil_Snow"
    },
    {
      "x": -5,
      "y": 1,
      "z": -5,
      "name": "Empty"
    },
    {
      "x": -5,
      "y": 2,
      "z": -5,
      "name": "Empty"
    },
    {
      "x": -5,
      "y": 3,
      "z": -5,
      "name": "Empty"
    },
    {
      "x": -5,
      "y": 4,
      "z": -5,
      "name": "Rock_Ice"
    },
    {
      "x": -5,
      "y": 5,
      "z": -5,
      "name": "Rock_Ice"
    },
    {
      "x": -5,
      "y": 0,
      "z": -4,
      "name": "Soil_Snow"
    },
    {
      "x": -5,
      "y": 1,
      "z": -4,
      "name": "Empty"
    },
    {
      "x": -5,
      "y": 2,
      "z": -4,
      "name": "Empty"
    },
    {
      "x": -5,
      "y": 3,
      "z": -4,
      "name": "Empty"
    },
    {
      "x": -5,
      "y": 4,
      "z": -4,
      "name": "Rock_Ice"
    },
    {
      "x": -5,
      "y": 5,
      "z": -4,
      "name": "Rock_Ice"
    },
    {
      "x": -5,
      "y": 0,
      "z": -3,
      "name": "Soil_Snow"
    },
    {
      "x": -5,
      "y": 1,
      "z": -3,
      "name": "Empty"
    },
    {
      "x": -5,
      "y": 2,
      "z": -3,
      "name": "Empty"
    },
    {
      "x": -5,
      "y": 3,
      "z": -3,
      "name": "Empty"
    },
    {
      "x": -5,
      "y": 4,
      "z": -3,
      "name": "Rock_Ice"
    },
    {
      "x": -5,
      "y": 5,
      "z": -3,
      "name": "Rock_Ice"
    },
    {
      "x": -5,
      "y": 0,
      "z": -2,
      "name": "Soil_Snow"
    },
    {
      "x": -5,
      "y": 1,
      "z": -2,
      "name": "Soil_Snow_Half"
    },
    {
      "x": -5,
      "y": 2,
      "z": -2,
      "name": "Empty"
    },
    {
      "x": -5,
      "y": 3,
      "z": -2,
      "name": "Empty"
    },
    {
      "x": -5,
      "y": 4,
      "z": -2,
      "name": "Rock_Ice"
    },
    {
      "x": -5,
      "y": 5,
      "z": -2,
      "name": "Rock_Ice"
    },
    {
      "x": -5,
      "y": 0,
      "z": -1,
      "name": "Soil_Snow"
    },
    {
      "x": -5,
      "y": 1,
      "z": -1,
      "name": "Soil_Snow"
    },
    {
      "x": -5,
      "y": 2,
      "z": -1,
      "name": "Soil_Snow_Half",
      "rotation": 6
    },
    {
      "x": -5,
      "y": 3,
      "z": -1,
      "name": "Empty"
    },
    {
      "x": -5,
      "y": 4,
      "z": -1,
      "name": "Rock_Ice"
    },
    {
      "x": -5,
      "y": 5,
      "z": -1,
      "name": "Rock_Ice"
    },
    {
      "x": -5,
      "y": 0,
      "z": 0,
      "name": "Rock_Ice"
    },
    {
      "x": -5,
      "y": 1,
      "z": 0,
      "name": "Rock_Ice"
    },
    {
      "x": -5,
      "y": 2,
      "z": 0,
      "name": "Rock_Ice"
    },
    {
      "x": -5,
      "y": 3,
      "z": 0,
      "name": "Rock_Ice"
    },
    {
      "x": -5,
      "y": 4,
      "z": 0,
      "name": "Rock_Ice"
    },
    {
      "x": -5,
      "y": 5,
      "z": 0,
      "name": "Rock_Ice"
    },
    {
      "x": -4,
      "y": 0,
      "z": -16,
      "name": "Rock_Ice"
    },
    {
      "x": -4,
      "y": 1,
      "z": -16,
      "name": "Rock_Ice"
    },
    {
      "x": -4,
      "y": 2,
      "z": -16,
      "name": "Rock_Ice"
    },
    {
      "x": -4,
      "y": 3,
      "z": -16,
      "name": "Rock_Ice"
    },
    {
      "x": -4,
      "y": 4,
      "z": -16,
      "name": "Rock_Ice"
    },
    {
      "x": -4,
      "y": 5,
      "z": -16,
      "name": "Rock_Ice"
    },
    {
      "x": -4,
      "y": 0,
      "z": -15,
      "name": "Soil_Snow"
    },
    {
      "x": -4,
      "y": 1,
      "z": -15,
      "name": "Empty"
    },
    {
      "x": -4,
      "y": 2,
      "z": -15,
      "name": "Empty"
    },
    {
      "x": -4,
      "y": 3,
      "z": -15,
      "name": "Empty"
    },
    {
      "x": -4,
      "y": 4,
      "z": -15,
      "name": "Rock_Ice"
    },
    {
      "x": -4,
      "y": 5,
      "z": -15,
      "name": "Rock_Ice"
    },
    {
      "x": -4,
      "y": 0,
      "z": -14,
      "name": "Soil_Snow"
    },
    {
      "x": -4,
      "y": 1,
      "z": -14,
      "name": "Empty"
    },
    {
      "x": -4,
      "y": 2,
      "z": -14,
      "name": "Empty"
    },
    {
      "x": -4,
      "y": 3,
      "z": -14,
      "name": "Empty"
    },
    {
      "x": -4,
      "y": 4,
      "z": -14,
      "name": "Rock_Ice"
    },
    {
      "x": -4,
      "y": 5,
      "z": -14,
      "name": "Rock_Ice"
    },
    {
      "x": -4,
      "y": 0,
      "z": -13,
      "name": "Soil_Snow"
    },
    {
      "x": -4,
      "y": 1,
      "z": -13,
      "name": "Empty"
    },
    {
      "x": -4,
      "y": 2,
      "z": -13,
      "name": "Empty"
    },
    {
      "x": -4,
      "y": 3,
      "z": -13,
      "name": "Empty"
    },
    {
      "x": -4,
      "y": 4,
      "z": -13,
      "name": "Rock_Ice"
    },
    {
      "x": -4,
      "y": 5,
      "z": -13,
      "name": "Rock_Ice"
    },
    {
      "x": -4,
      "y": 0,
      "z": -12,
      "name": "Soil_Snow"
    },
    {
      "x": -4,
      "y": 1,
      "z": -12,
      "name": "Empty"
    },
    {
      "x": -4,
      "y": 2,
      "z": -12,
      "name": "Empty"
    },
    {
      "x": -4,
      "y": 3,
      "z": -12,
      "name": "Plant_Flower_Orchid_Blue",
      "rotation": 8
    },
    {
      "x": -4,
      "y": 4,
      "z": -12,
      "name": "Rock_Ice"
    },
    {
      "x": -4,
      "y": 5,
      "z": -12,
      "name": "Rock_Ice"
    },
    {
      "x": -4,
      "y": 0,
      "z": -11,
      "name": "Soil_Snow"
    },
    {
      "x": -4,
      "y": 1,
      "z": -11,
      "name": "Empty"
    },
    {
      "x": -4,
      "y": 2,
      "z": -11,
      "name": "Empty"
    },
    {
      "x": -4,
      "y": 3,
      "z": -11,
      "name": "Empty"
    },
    {
      "x": -4,
      "y": 4,
      "z": -11,
      "name": "Rock_Ice"
    },
    {
      "x": -4,
      "y": 5,
      "z": -11,
      "name": "Rock_Ice"
    },
    {
      "x": -4,
      "y": 0,
      "z": -10,
      "name": "Soil_Snow"
    },
    {
      "x": -4,
      "y": 1,
      "z": -10,
      "name": "Empty"
    },
    {
      "x": -4,
      "y": 2,
      "z": -10,
      "name": "Empty"
    },
    {
      "x": -4,
      "y": 3,
      "z": -10,
      "name": "Empty"
    },
    {
      "x": -4,
      "y": 4,
      "z": -10,
      "name": "Rock_Ice"
    },
    {
      "x": -4,
      "y": 5,
      "z": -10,
      "name": "Rock_Ice"
    },
    {
      "x": -4,
      "y": 0,
      "z": -9,
      "name": "Soil_Snow"
    },
    {
      "x": -4,
      "y": 1,
      "z": -9,
      "name": "Empty"
    },
    {
      "x": -4,
      "y": 2,
      "z": -9,
      "name": "Empty"
    },
    {
      "x": -4,
      "y": 3,
      "z": -9,
      "name": "Empty"
    },
    {
      "x": -4,
      "y": 4,
      "z": -9,
      "name": "Rock_Ice"
    },
    {
      "x": -4,
      "y": 5,
      "z": -9,
      "name": "Rock_Ice"
    },
    {
      "x": -4,
      "y": 0,
      "z": -8,
      "name": "Soil_Snow"
    },
    {
      "x": -4,
      "y": 1,
      "z": -8,
      "name": "Empty"
    },
    {
      "x": -4,
      "y": 2,
      "z": -8,
      "name": "Empty"
    },
    {
      "x": -4,
      "y": 3,
      "z": -8,
      "name": "Empty"
    },
    {
      "x": -4,
      "y": 4,
      "z": -8,
      "name": "Rock_Ice"
    },
    {
      "x": -4,
      "y": 5,
      "z": -8,
      "name": "Rock_Ice"
    },
    {
      "x": -4,
      "y": 0,
      "z": -7,
      "name": "Soil_Snow"
    },
    {
      "x": -4,
      "y": 1,
      "z": -7,
      "name": "Empty"
    },
    {
      "x": -4,
      "y": 2,
      "z": -7,
      "name": "Empty"
    },
    {
      "x": -4,
      "y": 3,
      "z": -7,
      "name": "Empty"
    },
    {
      "x": -4,
      "y": 4,
      "z": -7,
      "name": "*Rock_Shale_Brick_Stairs_State_Definitions_Corner_Right",
      "rotation": 8
    },
    {
      "x": -4,
      "y": 5,
      "z": -7,
      "name": "Rock_Ice"
    },
    {
      "x": -4,
      "y": 0,
      "z": -6,
      "name": "Soil_Snow"
    },
    {
      "x": -4,
      "y": 1,
      "z": -6,
      "name": "Empty"
    },
    {
      "x": -4,
      "y": 2,
      "z": -6,
      "name": "Empty"
    },
    {
      "x": -4,
      "y": 3,
      "z": -6,
      "name": "Empty"
    },
    {
      "x": -4,
      "y": 4,
      "z": -6,
      "name": "Rock_Shale_Brick_Stairs",
      "rotation": 9
    },
    {
      "x": -4,
      "y": 5,
      "z": -6,
      "name": "Rock_Ice"
    },
    {
      "x": -4,
      "y": 0,
      "z": -5,
      "name": "Soil_Snow"
    },
    {
      "x": -4,
      "y": 1,
      "z": -5,
      "name": "Empty"
    },
    {
      "x": -4,
      "y": 2,
      "z": -5,
      "name": "Empty"
    },
    {
      "x": -4,
      "y": 3,
      "z": -5,
      "name": "Empty"
    },
    {
      "x": -4,
      "y": 4,
      "z": -5,
      "name": "Rock_Shale_Brick_Stairs",
      "rotation": 9
    },
    {
      "x": -4,
      "y": 5,
      "z": -5,
      "name": "Rock_Ice"
    },
    {
      "x": -4,
      "y": 0,
      "z": -4,
      "name": "Soil_Snow"
    },
    {
      "x": -4,
      "y": 1,
      "z": -4,
      "name": "Empty"
    },
    {
      "x": -4,
      "y": 2,
      "z": -4,
      "name": "Empty"
    },
    {
      "x": -4,
      "y": 3,
      "z": -4,
      "name": "Empty"
    },
    {
      "x": -4,
      "y": 4,
      "z": -4,
      "name": "*Rock_Shale_Brick_Stairs_State_Definitions_Corner_Right",
      "rotation": 9
    },
    {
      "x": -4,
      "y": 5,
      "z": -4,
      "name": "Rock_Ice"
    },
    {
      "x": -4,
      "y": 0,
      "z": -3,
      "name": "Soil_Snow"
    },
    {
      "x": -4,
      "y": 1,
      "z": -3,
      "name": "Empty"
    },
    {
      "x": -4,
      "y": 2,
      "z": -3,
      "name": "Empty"
    },
    {
      "x": -4,
      "y": 3,
      "z": -3,
      "name": "Plant_Flower_Orchid_Blue",
      "rotation": 8
    },
    {
      "x": -4,
      "y": 4,
      "z": -3,
      "name": "Rock_Ice"
    },
    {
      "x": -4,
      "y": 5,
      "z": -3,
      "name": "Rock_Ice"
    },
    {
      "x": -4,
      "y": 0,
      "z": -2,
      "name": "Soil_Snow"
    },
    {
      "x": -4,
      "y": 1,
      "z": -2,
      "name": "Soil_Snow_Half"
    },
    {
      "x": -4,
      "y": 2,
      "z": -2,
      "name": "Empty"
    },
    {
      "x": -4,
      "y": 3,
      "z": -2,
      "name": "Empty"
    },
    {
      "x": -4,
      "y": 4,
      "z": -2,
      "name": "Rock_Ice"
    },
    {
      "x": -4,
      "y": 5,
      "z": -2,
      "name": "Rock_Ice"
    },
    {
      "x": -4,
      "y": 0,
      "z": -1,
      "name": "Soil_Snow"
    },
    {
      "x": -4,
      "y": 1,
      "z": -1,
      "name": "Soil_Snow"
    },
    {
      "x": -4,
      "y": 2,
      "z": -1,
      "name": "Soil_Snow"
    },
    {
      "x": -4,
      "y": 3,
      "z": -1,
      "name": "Empty"
    },
    {
      "x": -4,
      "y": 4,
      "z": -1,
      "name": "Rock_Ice"
    },
    {
      "x": -4,
      "y": 5,
      "z": -1,
      "name": "Rock_Ice"
    },
    {
      "x": -4,
      "y": 0,
      "z": 0,
      "name": "Rock_Shale"
    },
    {
      "x": -4,
      "y": 1,
      "z": 0,
      "name": "Rock_Shale"
    },
    {
      "x": -4,
      "y": 2,
      "z": 0,
      "name": "Rock_Shale"
    },
    {
      "x": -4,
      "y": 3,
      "z": 0,
      "name": "Rock_Ice"
    },
    {
      "x": -4,
      "y": 4,
      "z": 0,
      "name": "Rock_Ice"
    },
    {
      "x": -4,
      "y": 5,
      "z": 0,
      "name": "Rock_Ice"
    },
    {
      "x": -3,
      "y": 0,
      "z": -16,
      "name": "Rock_Ice"
    },
    {
      "x": -3,
      "y": 1,
      "z": -16,
      "name": "Rock_Ice"
    },
    {
      "x": -3,
      "y": 2,
      "z": -16,
      "name": "Rock_Ice"
    },
    {
      "x": -3,
      "y": 3,
      "z": -16,
      "name": "Rock_Ice"
    },
    {
      "x": -3,
      "y": 4,
      "z": -16,
      "name": "Rock_Ice"
    },
    {
      "x": -3,
      "y": 5,
      "z": -16,
      "name": "Rock_Ice"
    },
    {
      "x": -3,
      "y": 0,
      "z": -15,
      "name": "Rock_Shale_Brick"
    },
    {
      "x": -3,
      "y": 1,
      "z": -15,
      "name": "Rock_Ice"
    },
    {
      "x": -3,
      "y": 2,
      "z": -15,
      "name": "Rock_Ice"
    },
    {
      "x": -3,
      "y": 3,
      "z": -15,
      "name": "Rock_Ice"
    },
    {
      "x": -3,
      "y": 4,
      "z": -15,
      "name": "Rock_Ice"
    },
    {
      "x": -3,
      "y": 5,
      "z": -15,
      "name": "Rock_Ice"
    },
    {
      "x": -3,
      "y": 0,
      "z": -14,
      "name": "Rock_Shale_Brick"
    },
    {
      "x": -3,
      "y": 1,
      "z": -14,
      "name": "Rock_Ice"
    },
    {
      "x": -3,
      "y": 2,
      "z": -14,
      "name": "Rock_Ice"
    },
    {
      "x": -3,
      "y": 3,
      "z": -14,
      "name": "Rock_Ice"
    },
    {
      "x": -3,
      "y": 4,
      "z": -14,
      "name": "Rock_Ice"
    },
    {
      "x": -3,
      "y": 5,
      "z": -14,
      "name": "Rock_Ice"
    },
    {
      "x": -3,
      "y": 0,
      "z": -13,
      "name": "Soil_Snow"
    },
    {
      "x": -3,
      "y": 1,
      "z": -13,
      "name": "Empty"
    },
    {
      "x": -3,
      "y": 2,
      "z": -13,
      "name": "Empty"
    },
    {
      "x": -3,
      "y": 3,
      "z": -13,
      "name": "Empty"
    },
    {
      "x": -3,
      "y": 4,
      "z": -13,
      "name": "Rock_Ice"
    },
    {
      "x": -3,
      "y": 5,
      "z": -13,
      "name": "Rock_Ice"
    },
    {
      "x": -3,
      "y": 0,
      "z": -12,
      "name": "Soil_Snow"
    },
    {
      "x": -3,
      "y": 1,
      "z": -12,
      "name": "Empty"
    },
    {
      "x": -3,
      "y": 2,
      "z": -12,
      "name": "Empty"
    },
    {
      "x": -3,
      "y": 3,
      "z": -12,
      "name": "Empty"
    },
    {
      "x": -3,
      "y": 4,
      "z": -12,
      "name": "Rock_Ice"
    },
    {
      "x": -3,
      "y": 5,
      "z": -12,
      "name": "Rock_Ice"
    },
    {
      "x": -3,
      "y": 0,
      "z": -11,
      "name": "Rock_Shale_Brick"
    },
    {
      "x": -3,
      "y": 1,
      "z": -11,
      "name": "Rock_Ice"
    },
    {
      "x": -3,
      "y": 2,
      "z": -11,
      "name": "Rock_Ice"
    },
    {
      "x": -3,
      "y": 3,
      "z": -11,
      "name": "Rock_Ice"
    },
    {
      "x": -3,
      "y": 4,
      "z": -11,
      "name": "Rock_Ice"
    },
    {
      "x": -3,
      "y": 5,
      "z": -11,
      "name": "Rock_Ice"
    },
    {
      "x": -3,
      "y": 0,
      "z": -10,
      "name": "Rock_Shale_Brick"
    },
    {
      "x": -3,
      "y": 1,
      "z": -10,
      "name": "Rock_Ice"
    },
    {
      "x": -3,
      "y": 2,
      "z": -10,
      "name": "Rock_Ice"
    },
    {
      "x": -3,
      "y": 3,
      "z": -10,
      "name": "Rock_Ice"
    },
    {
      "x": -3,
      "y": 4,
      "z": -10,
      "name": "Rock_Ice"
    },
    {
      "x": -3,
      "y": 5,
      "z": -10,
      "name": "Rock_Ice"
    },
    {
      "x": -3,
      "y": 0,
      "z": -9,
      "name": "Soil_Snow"
    },
    {
      "x": -3,
      "y": 1,
      "z": -9,
      "name": "Empty"
    },
    {
      "x": -3,
      "y": 2,
      "z": -9,
      "name": "Empty"
    },
    {
      "x": -3,
      "y": 3,
      "z": -9,
      "name": "Empty"
    },
    {
      "x": -3,
      "y": 4,
      "z": -9,
      "name": "Rock_Ice"
    },
    {
      "x": -3,
      "y": 5,
      "z": -9,
      "name": "Rock_Ice"
    },
    {
      "x": -3,
      "y": 0,
      "z": -8,
      "name": "Soil_Snow"
    },
    {
      "x": -3,
      "y": 1,
      "z": -8,
      "name": "Empty"
    },
    {
      "x": -3,
      "y": 2,
      "z": -8,
      "name": "Empty"
    },
    {
      "x": -3,
      "y": 3,
      "z": -8,
      "name": "Empty"
    },
    {
      "x": -3,
      "y": 4,
      "z": -8,
      "name": "Rock_Ice"
    },
    {
      "x": -3,
      "y": 5,
      "z": -8,
      "name": "Rock_Ice"
    },
    {
      "x": -3,
      "y": 0,
      "z": -7,
      "name": "Soil_Snow"
    },
    {
      "x": -3,
      "y": 1,
      "z": -7,
      "name": "Wood_Deadwood_Beam"
    },
    {
      "x": -3,
      "y": 2,
      "z": -7,
      "name": "*Furniture_Human_Ruins_Torch_State_Definitions_Off",
      "rotation": 2
    },
    {
      "x": -3,
      "y": 3,
      "z": -7,
      "name": "Empty"
    },
    {
      "x": -3,
      "y": 4,
      "z": -7,
      "name": "Rock_Shale_Brick_Stairs",
      "rotation": 8
    },
    {
      "x": -3,
      "y": 5,
      "z": -7,
      "name": "Rock_Ice"
    },
    {
      "x": -3,
      "y": 0,
      "z": -6,
      "name": "Rock_Shale_Brick"
    },
    {
      "x": -3,
      "y": 1,
      "z": -6,
      "name": "Rock_Shale_Brick_Ornate"
    },
    {
      "x": -3,
      "y": 2,
      "z": -6,
      "name": "Rock_Shale"
    },
    {
      "x": -3,
      "y": 3,
      "z": -6,
      "name": "Rock_Shale"
    },
    {
      "x": -3,
      "y": 4,
      "z": -6,
      "name": "Rock_Shale_Brick"
    },
    {
      "x": -3,
      "y": 5,
      "z": -6,
      "name": "Rock_Ice"
    },
    {
      "x": -3,
      "y": 0,
      "z": -5,
      "name": "Rock_Shale_Brick"
    },
    {
      "x": -3,
      "y": 1,
      "z": -5,
      "name": "Rock_Shale_Brick_Ornate"
    },
    {
      "x": -3,
      "y": 2,
      "z": -5,
      "name": "Rock_Shale"
    },
    {
      "x": -3,
      "y": 3,
      "z": -5,
      "name": "Rock_Shale"
    },
    {
      "x": -3,
      "y": 4,
      "z": -5,
      "name": "Rock_Shale_Brick"
    },
    {
      "x": -3,
      "y": 5,
      "z": -5,
      "name": "Rock_Ice"
    },
    {
      "x": -3,
      "y": 0,
      "z": -4,
      "name": "Soil_Snow"
    },
    {
      "x": -3,
      "y": 1,
      "z": -4,
      "name": "Empty"
    },
    {
      "x": -3,
      "y": 2,
      "z": -4,
      "name": "Empty"
    },
    {
      "x": -3,
      "y": 3,
      "z": -4,
      "name": "Empty"
    },
    {
      "x": -3,
      "y": 4,
      "z": -4,
      "name": "Rock_Shale_Brick_Stairs",
      "rotation": 10
    },
    {
      "x": -3,
      "y": 5,
      "z": -4,
      "name": "Rock_Ice"
    },
    {
      "x": -3,
      "y": 0,
      "z": -3,
      "name": "Soil_Snow"
    },
    {
      "x": -3,
      "y": 1,
      "z": -3,
      "name": "Empty"
    },
    {
      "x": -3,
      "y": 2,
      "z": -3,
      "name": "Empty"
    },
    {
      "x": -3,
      "y": 3,
      "z": -3,
      "name": "Empty"
    },
    {
      "x": -3,
      "y": 4,
      "z": -3,
      "name": "Rock_Ice"
    },
    {
      "x": -3,
      "y": 5,
      "z": -3,
      "name": "Rock_Ice"
    },
    {
      "x": -3,
      "y": 0,
      "z": -2,
      "name": "Rock_Shale_Brick"
    },
    {
      "x": -3,
      "y": 1,
      "z": -2,
      "name": "Rock_Shale_Brick_Ornate"
    },
    {
      "x": -3,
      "y": 2,
      "z": -2,
      "name": "Rock_Ice"
    },
    {
      "x": -3,
      "y": 3,
      "z": -2,
      "name": "Rock_Ice"
    },
    {
      "x": -3,
      "y": 4,
      "z": -2,
      "name": "Rock_Ice"
    },
    {
      "x": -3,
      "y": 5,
      "z": -2,
      "name": "Rock_Ice"
    },
    {
      "x": -3,
      "y": 0,
      "z": -1,
      "name": "Rock_Shale_Brick"
    },
    {
      "x": -3,
      "y": 1,
      "z": -1,
      "name": "Rock_Shale_Brick_Ornate"
    },
    {
      "x": -3,
      "y": 2,
      "z": -1,
      "name": "Rock_Ice"
    },
    {
      "x": -3,
      "y": 3,
      "z": -1,
      "name": "Rock_Ice"
    },
    {
      "x": -3,
      "y": 4,
      "z": -1,
      "name": "Rock_Ice"
    },
    {
      "x": -3,
      "y": 5,
      "z": -1,
      "name": "Rock_Ice"
    },
    {
      "x": -3,
      "y": 0,
      "z": 0,
      "name": "Rock_Shale"
    },
    {
      "x": -3,
      "y": 1,
      "z": 0,
      "name": "Rock_Shale"
    },
    {
      "x": -3,
      "y": 2,
      "z": 0,
      "name": "Rock_Shale"
    },
    {
      "x": -3,
      "y": 3,
      "z": 0,
      "name": "Rock_Shale"
    },
    {
      "x": -3,
      "y": 4,
      "z": 0,
      "name": "Rock_Shale"
    },
    {
      "x": -3,
      "y": 5,
      "z": 0,
      "name": "Rock_Shale"
    },
    {
      "x": -2,
      "y": 0,
      "z": -16,
      "name": "Rock_Ice"
    },
    {
      "x": -2,
      "y": 1,
      "z": -16,
      "name": "Rock_Ice"
    },
    {
      "x": -2,
      "y": 2,
      "z": -16,
      "name": "Rock_Ice"
    },
    {
      "x": -2,
      "y": 3,
      "z": -16,
      "name": "Rock_Ice"
    },
    {
      "x": -2,
      "y": 4,
      "z": -16,
      "name": "Rock_Ice"
    },
    {
      "x": -2,
      "y": 5,
      "z": -16,
      "name": "Rock_Ice"
    },
    {
      "x": -2,
      "y": 0,
      "z": -15,
      "name": "Rock_Shale_Brick"
    },
    {
      "x": -2,
      "y": 1,
      "z": -15,
      "name": "Rock_Ice"
    },
    {
      "x": -2,
      "y": 2,
      "z": -15,
      "name": "Rock_Ice"
    },
    {
      "x": -2,
      "y": 3,
      "z": -15,
      "name": "Rock_Ice"
    },
    {
      "x": -2,
      "y": 4,
      "z": -15,
      "name": "Rock_Ice"
    },
    {
      "x": -2,
      "y": 5,
      "z": -15,
      "name": "Rock_Ice"
    },
    {
      "x": -2,
      "y": 0,
      "z": -14,
      "name": "Rock_Shale_Brick"
    },
    {
      "x": -2,
      "y": 1,
      "z": -14,
      "name": "Rock_Ice"
    },
    {
      "x": -2,
      "y": 2,
      "z": -14,
      "name": "Rock_Ice"
    },
    {
      "x": -2,
      "y": 3,
      "z": -14,
      "name": "Rock_Ice"
    },
    {
      "x": -2,
      "y": 4,
      "z": -14,
      "name": "Rock_Ice"
    },
    {
      "x": -2,
      "y": 5,
      "z": -14,
      "name": "Rock_Ice"
    },
    {
      "x": -2,
      "y": 0,
      "z": -13,
      "name": "Soil_Snow"
    },
    {
      "x": -2,
      "y": 1,
      "z": -13,
      "name": "Empty"
    },
    {
      "x": -2,
      "y": 2,
      "z": -13,
      "name": "Empty"
    },
    {
      "x": -2,
      "y": 3,
      "z": -13,
      "name": "Empty"
    },
    {
      "x": -2,
      "y": 4,
      "z": -13,
      "name": "Rock_Ice"
    },
    {
      "x": -2,
      "y": 5,
      "z": -13,
      "name": "Rock_Ice"
    },
    {
      "x": -2,
      "y": 0,
      "z": -12,
      "name": "Soil_Snow"
    },
    {
      "x": -2,
      "y": 1,
      "z": -12,
      "name": "Empty"
    },
    {
      "x": -2,
      "y": 2,
      "z": -12,
      "name": "Empty"
    },
    {
      "x": -2,
      "y": 3,
      "z": -12,
      "name": "Empty"
    },
    {
      "x": -2,
      "y": 4,
      "z": -12,
      "name": "Rock_Ice"
    },
    {
      "x": -2,
      "y": 5,
      "z": -12,
      "name": "Rock_Ice"
    },
    {
      "x": -2,
      "y": 0,
      "z": -11,
      "name": "Rock_Shale_Brick"
    },
    {
      "x": -2,
      "y": 1,
      "z": -11,
      "name": "Rock_Ice"
    },
    {
      "x": -2,
      "y": 2,
      "z": -11,
      "name": "Rock_Ice"
    },
    {
      "x": -2,
      "y": 3,
      "z": -11,
      "name": "Rock_Ice"
    },
    {
      "x": -2,
      "y": 4,
      "z": -11,
      "name": "Rock_Ice"
    },
    {
      "x": -2,
      "y": 5,
      "z": -11,
      "name": "Rock_Ice"
    },
    {
      "x": -2,
      "y": 0,
      "z": -10,
      "name": "Soil_Snow"
    },
    {
      "x": -2,
      "y": 1,
      "z": -10,
      "name": "Soil_Snow_Half"
    },
    {
      "x": -2,
      "y": 2,
      "z": -10,
      "name": "Empty"
    },
    {
      "x": -2,
      "y": 3,
      "z": -10,
      "name": "Rock_Ice"
    },
    {
      "x": -2,
      "y": 4,
      "z": -10,
      "name": "Rock_Ice"
    },
    {
      "x": -2,
      "y": 5,
      "z": -10,
      "name": "Rock_Ice"
    },
    {
      "x": -2,
      "y": 0,
      "z": -9,
      "name": "Soil_Snow"
    },
    {
      "x": -2,
      "y": 1,
      "z": -9,
      "name": "Empty"
    },
    {
      "x": -2,
      "y": 2,
      "z": -9,
      "name": "Empty"
    },
    {
      "x": -2,
      "y": 3,
      "z": -9,
      "name": "Empty"
    },
    {
      "x": -2,
      "y": 4,
      "z": -9,
      "name": "Rock_Ice"
    },
    {
      "x": -2,
      "y": 5,
      "z": -9,
      "name": "Rock_Ice"
    },
    {
      "x": -2,
      "y": 0,
      "z": -8,
      "name": "Soil_Snow"
    },
    {
      "x": -2,
      "y": 1,
      "z": -8,
      "name": "Empty"
    },
    {
      "x": -2,
      "y": 2,
      "z": -8,
      "name": "Empty"
    },
    {
      "x": -2,
      "y": 3,
      "z": -8,
      "name": "Empty"
    },
    {
      "x": -2,
      "y": 4,
      "z": -8,
      "name": "Empty"
    },
    {
      "x": -2,
      "y": 5,
      "z": -8,
      "name": "Rock_Ice"
    },
    {
      "x": -2,
      "y": 0,
      "z": -7,
      "name": "Soil_Snow"
    },
    {
      "x": -2,
      "y": 1,
      "z": -7,
      "name": "Empty"
    },
    {
      "x": -2,
      "y": 2,
      "z": -7,
      "name": "Empty"
    },
    {
      "x": -2,
      "y": 3,
      "z": -7,
      "name": "Empty"
    },
    {
      "x": -2,
      "y": 4,
      "z": -7,
      "name": "Rock_Shale_Brick_Stairs",
      "rotation": 8
    },
    {
      "x": -2,
      "y": 5,
      "z": -7,
      "name": "Rock_Ice"
    },
    {
      "x": -2,
      "y": 0,
      "z": -6,
      "name": "Rock_Shale_Brick"
    },
    {
      "x": -2,
      "y": 1,
      "z": -6,
      "name": "Rock_Shale_Brick_Ornate"
    },
    {
      "x": -2,
      "y": 2,
      "z": -6,
      "name": "Rock_Shale"
    },
    {
      "x": -2,
      "y": 3,
      "z": -6,
      "name": "Rock_Shale"
    },
    {
      "x": -2,
      "y": 4,
      "z": -6,
      "name": "Rock_Shale_Brick"
    },
    {
      "x": -2,
      "y": 5,
      "z": -6,
      "name": "Rock_Ice"
    },
    {
      "x": -2,
      "y": 0,
      "z": -5,
      "name": "Rock_Shale_Brick"
    },
    {
      "x": -2,
      "y": 1,
      "z": -5,
      "name": "Rock_Shale_Brick_Ornate"
    },
    {
      "x": -2,
      "y": 2,
      "z": -5,
      "name": "Rock_Shale"
    },
    {
      "x": -2,
      "y": 3,
      "z": -5,
      "name": "Rock_Shale"
    },
    {
      "x": -2,
      "y": 4,
      "z": -5,
      "name": "Rock_Shale_Brick"
    },
    {
      "x": -2,
      "y": 5,
      "z": -5,
      "name": "Rock_Ice"
    },
    {
      "x": -2,
      "y": 0,
      "z": -4,
      "name": "Soil_Snow"
    },
    {
      "x": -2,
      "y": 1,
      "z": -4,
      "name": "Empty"
    },
    {
      "x": -2,
      "y": 2,
      "z": -4,
      "name": "Empty"
    },
    {
      "x": -2,
      "y": 3,
      "z": -4,
      "name": "Empty"
    },
    {
      "x": -2,
      "y": 4,
      "z": -4,
      "name": "Rock_Shale_Brick_Stairs",
      "rotation": 10
    },
    {
      "x": -2,
      "y": 5,
      "z": -4,
      "name": "Rock_Ice"
    },
    {
      "x": -2,
      "y": 0,
      "z": -3,
      "name": "Soil_Snow"
    },
    {
      "x": -2,
      "y": 1,
      "z": -3,
      "name": "Empty"
    },
    {
      "x": -2,
      "y": 2,
      "z": -3,
      "name": "Empty"
    },
    {
      "x": -2,
      "y": 3,
      "z": -3,
      "name": "Empty"
    },
    {
      "x": -2,
      "y": 4,
      "z": -3,
      "name": "Rock_Ice"
    },
    {
      "x": -2,
      "y": 5,
      "z": -3,
      "name": "Rock_Ice"
    },
    {
      "x": -2,
      "y": 0,
      "z": -2,
      "name": "Rock_Shale_Brick"
    },
    {
      "x": -2,
      "y": 1,
      "z": -2,
      "name": "Rock_Shale_Brick_Ornate"
    },
    {
      "x": -2,
      "y": 2,
      "z": -2,
      "name": "Rock_Shale"
    },
    {
      "x": -2,
      "y": 3,
      "z": -2,
      "name": "Rock_Ice"
    },
    {
      "x": -2,
      "y": 4,
      "z": -2,
      "name": "Rock_Ice"
    },
    {
      "x": -2,
      "y": 5,
      "z": -2,
      "name": "Rock_Ice"
    },
    {
      "x": -2,
      "y": 0,
      "z": -1,
      "name": "Rock_Shale_Brick"
    },
    {
      "x": -2,
      "y": 1,
      "z": -1,
      "name": "Rock_Shale_Brick_Ornate"
    },
    {
      "x": -2,
      "y": 2,
      "z": -1,
      "name": "Rock_Shale"
    },
    {
      "x": -2,
      "y": 3,
      "z": -1,
      "name": "Rock_Shale"
    },
    {
      "x": -2,
      "y": 4,
      "z": -1,
      "name": "Rock_Ice"
    },
    {
      "x": -2,
      "y": 5,
      "z": -1,
      "name": "Rock_Ice"
    },
    {
      "x": -2,
      "y": 0,
      "z": 0,
      "name": "Rock_Basalt_Cobble"
    },
    {
      "x": -2,
      "y": 1,
      "z": 0,
      "name": "Empty"
    },
    {
      "x": -2,
      "y": 2,
      "z": 0,
      "name": "Empty"
    },
    {
      "x": -2,
      "y": 3,
      "z": 0,
      "name": "Empty"
    },
    {
      "x": -2,
      "y": 4,
      "z": 0,
      "name": "Empty"
    },
    {
      "x": -2,
      "y": 5,
      "z": 0,
      "name": "Rock_Shale"
    },
    {
      "x": -1,
      "y": 0,
      "z": -16,
      "name": "Rock_Ice"
    },
    {
      "x": -1,
      "y": 1,
      "z": -16,
      "name": "Rock_Ice"
    },
    {
      "x": -1,
      "y": 2,
      "z": -16,
      "name": "Rock_Ice"
    },
    {
      "x": -1,
      "y": 3,
      "z": -16,
      "name": "Rock_Ice"
    },
    {
      "x": -1,
      "y": 4,
      "z": -16,
      "name": "Rock_Ice"
    },
    {
      "x": -1,
      "y": 5,
      "z": -16,
      "name": "Rock_Ice"
    },
    {
      "x": -1,
      "y": 0,
      "z": -15,
      "name": "Soil_Snow"
    },
    {
      "x": -1,
      "y": 1,
      "z": -15,
      "name": "Empty"
    },
    {
      "x": -1,
      "y": 2,
      "z": -15,
      "name": "Empty"
    },
    {
      "x": -1,
      "y": 3,
      "z": -15,
      "name": "Empty"
    },
    {
      "x": -1,
      "y": 4,
      "z": -15,
      "name": "Rock_Ice"
    },
    {
      "x": -1,
      "y": 5,
      "z": -15,
      "name": "Rock_Ice"
    },
    {
      "x": -1,
      "y": 0,
      "z": -14,
      "name": "Soil_Snow"
    },
    {
      "x": -1,
      "y": 1,
      "z": -14,
      "name": "Empty"
    },
    {
      "x": -1,
      "y": 2,
      "z": -14,
      "name": "Empty"
    },
    {
      "x": -1,
      "y": 3,
      "z": -14,
      "name": "Empty"
    },
    {
      "x": -1,
      "y": 4,
      "z": -14,
      "name": "Rock_Ice"
    },
    {
      "x": -1,
      "y": 5,
      "z": -14,
      "name": "Rock_Ice"
    },
    {
      "x": -1,
      "y": 0,
      "z": -13,
      "name": "Soil_Snow"
    },
    {
      "x": -1,
      "y": 1,
      "z": -13,
      "name": "Empty"
    },
    {
      "x": -1,
      "y": 2,
      "z": -13,
      "name": "Empty"
    },
    {
      "x": -1,
      "y": 3,
      "z": -13,
      "name": "Rock_Ice_Icicles",
      "rotation": 8
    },
    {
      "x": -1,
      "y": 4,
      "z": -13,
      "name": "Rock_Ice"
    },
    {
      "x": -1,
      "y": 5,
      "z": -13,
      "name": "Rock_Ice"
    },
    {
      "x": -1,
      "y": 0,
      "z": -12,
      "name": "Soil_Snow"
    },
    {
      "x": -1,
      "y": 1,
      "z": -12,
      "name": "Empty"
    },
    {
      "x": -1,
      "y": 2,
      "z": -12,
      "name": "Empty"
    },
    {
      "x": -1,
      "y": 3,
      "z": -12,
      "name": "Empty"
    },
    {
      "x": -1,
      "y": 4,
      "z": -12,
      "name": "Empty"
    },
    {
      "x": -1,
      "y": 5,
      "z": -12,
      "name": "Rock_Ice"
    },
    {
      "x": -1,
      "y": 0,
      "z": -11,
      "name": "Soil_Snow"
    },
    {
      "x": -1,
      "y": 1,
      "z": -11,
      "name": "Empty"
    },
    {
      "x": -1,
      "y": 2,
      "z": -11,
      "name": "Empty"
    },
    {
      "x": -1,
      "y": 3,
      "z": -11,
      "name": "Empty"
    },
    {
      "x": -1,
      "y": 4,
      "z": -11,
      "name": "Empty"
    },
    {
      "x": -1,
      "y": 5,
      "z": -11,
      "name": "Rock_Ice"
    },
    {
      "x": -1,
      "y": 0,
      "z": -10,
      "name": "Soil_Snow"
    },
    {
      "x": -1,
      "y": 1,
      "z": -10,
      "name": "Empty"
    },
    {
      "x": -1,
      "y": 2,
      "z": -10,
      "name": "Empty"
    },
    {
      "x": -1,
      "y": 3,
      "z": -10,
      "name": "Empty"
    },
    {
      "x": -1,
      "y": 4,
      "z": -10,
      "name": "Empty"
    },
    {
      "x": -1,
      "y": 5,
      "z": -10,
      "name": "Rock_Ice"
    },
    {
      "x": -1,
      "y": 0,
      "z": -9,
      "name": "Soil_Snow"
    },
    {
      "x": -1,
      "y": 1,
      "z": -9,
      "name": "Empty"
    },
    {
      "x": -1,
      "y": 2,
      "z": -9,
      "name": "Empty"
    },
    {
      "x": -1,
      "y": 3,
      "z": -9,
      "name": "Empty"
    },
    {
      "x": -1,
      "y": 4,
      "z": -9,
      "name": "Empty"
    },
    {
      "x": -1,
      "y": 5,
      "z": -9,
      "name": "Rock_Ice"
    },
    {
      "x": -1,
      "y": 0,
      "z": -8,
      "name": "Soil_Snow"
    },
    {
      "x": -1,
      "y": 1,
      "z": -8,
      "name": "Empty"
    },
    {
      "x": -1,
      "y": 2,
      "z": -8,
      "name": "Empty"
    },
    {
      "x": -1,
      "y": 3,
      "z": -8,
      "name": "Empty"
    },
    {
      "x": -1,
      "y": 4,
      "z": -8,
      "name": "Empty"
    },
    {
      "x": -1,
      "y": 5,
      "z": -8,
      "name": "Rock_Ice"
    },
    {
      "x": -1,
      "y": 0,
      "z": -7,
      "name": "Soil_Snow"
    },
    {
      "x": -1,
      "y": 1,
      "z": -7,
      "name": "Empty"
    },
    {
      "x": -1,
      "y": 2,
      "z": -7,
      "name": "Empty"
    },
    {
      "x": -1,
      "y": 3,
      "z": -7,
      "name": "Empty"
    },
    {
      "x": -1,
      "y": 4,
      "z": -7,
      "name": "*Rock_Shale_Brick_Stairs_State_Definitions_Corner_Right",
      "rotation": 11
    },
    {
      "x": -1,
      "y": 5,
      "z": -7,
      "name": "Rock_Ice"
    },
    {
      "x": -1,
      "y": 0,
      "z": -6,
      "name": "Soil_Snow"
    },
    {
      "x": -1,
      "y": 1,
      "z": -6,
      "name": "Empty"
    },
    {
      "x": -1,
      "y": 2,
      "z": -6,
      "name": "Empty"
    },
    {
      "x": -1,
      "y": 3,
      "z": -6,
      "name": "Empty"
    },
    {
      "x": -1,
      "y": 4,
      "z": -6,
      "name": "Rock_Shale_Brick_Stairs",
      "rotation": 11
    },
    {
      "x": -1,
      "y": 5,
      "z": -6,
      "name": "Rock_Ice"
    },
    {
      "x": -1,
      "y": 0,
      "z": -5,
      "name": "Soil_Snow"
    },
    {
      "x": -1,
      "y": 1,
      "z": -5,
      "name": "Empty"
    },
    {
      "x": -1,
      "y": 2,
      "z": -5,
      "name": "Empty"
    },
    {
      "x": -1,
      "y": 3,
      "z": -5,
      "name": "Empty"
    },
    {
      "x": -1,
      "y": 4,
      "z": -5,
      "name": "Rock_Shale_Brick_Stairs",
      "rotation": 11
    },
    {
      "x": -1,
      "y": 5,
      "z": -5,
      "name": "Rock_Ice"
    },
    {
      "x": -1,
      "y": 0,
      "z": -4,
      "name": "Soil_Snow"
    },
    {
      "x": -1,
      "y": 1,
      "z": -4,
      "name": "Empty"
    },
    {
      "x": -1,
      "y": 2,
      "z": -4,
      "name": "Empty"
    },
    {
      "x": -1,
      "y": 3,
      "z": -4,
      "name": "Empty"
    },
    {
      "x": -1,
      "y": 4,
      "z": -4,
      "name": "*Rock_Shale_Brick_Stairs_State_Definitions_Corner_Right",
      "rotation": 10
    },
    {
      "x": -1,
      "y": 5,
      "z": -4,
      "name": "Rock_Ice"
    },
    {
      "x": -1,
      "y": 0,
      "z": -3,
      "name": "Soil_Snow"
    },
    {
      "x": -1,
      "y": 1,
      "z": -3,
      "name": "Empty"
    },
    {
      "x": -1,
      "y": 2,
      "z": -3,
      "name": "Empty"
    },
    {
      "x": -1,
      "y": 3,
      "z": -3,
      "name": "Empty"
    },
    {
      "x": -1,
      "y": 4,
      "z": -3,
      "name": "*Rock_Shale_Brick_Stairs_State_Definitions_Corner_Right",
      "rotation": 11
    },
    {
      "x": -1,
      "y": 5,
      "z": -3,
      "name": "Rock_Ice"
    },
    {
      "x": -1,
      "y": 0,
      "z": -2,
      "name": "Rock_Basalt_Cobble"
    },
    {
      "x": -1,
      "y": 1,
      "z": -2,
      "name": "Empty"
    },
    {
      "x": -1,
      "y": 2,
      "z": -2,
      "name": "Empty"
    },
    {
      "x": -1,
      "y": 3,
      "z": -2,
      "name": "Empty"
    },
    {
      "x": -1,
      "y": 4,
      "z": -2,
      "name": "Rock_Shale_Brick_Stairs",
      "rotation": 11
    },
    {
      "x": -1,
      "y": 5,
      "z": -2,
      "name": "Rock_Ice"
    },
    {
      "x": -1,
      "y": 0,
      "z": -1,
      "name": "Rock_Basalt_Cobble"
    },
    {
      "x": -1,
      "y": 1,
      "z": -1,
      "name": "Empty"
    },
    {
      "x": -1,
      "y": 2,
      "z": -1,
      "name": "Empty"
    },
    {
      "x": -1,
      "y": 3,
      "z": -1,
      "name": "Empty"
    },
    {
      "x": -1,
      "y": 4,
      "z": -1,
      "name": "Rock_Shale_Brick_Stairs",
      "rotation": 11
    },
    {
      "x": -1,
      "y": 5,
      "z": -1,
      "name": "Rock_Ice"
    },
    {
      "x": -1,
      "y": 0,
      "z": 0,
      "name": "Rock_Basalt_Cobble"
    },
    {
      "x": -1,
      "y": 1,
      "z": 0,
      "name": "Empty"
    },
    {
      "x": -1,
      "y": 2,
      "z": 0,
      "name": "Empty"
    },
    {
      "x": -1,
      "y": 3,
      "z": 0,
      "name": "Empty"
    },
    {
      "x": -1,
      "y": 4,
      "z": 0,
      "name": "Empty"
    },
    {
      "x": -1,
      "y": 5,
      "z": 0,
      "name": "Rock_Ice"
    },
    {
      "x": 0,
      "y": 0,
      "z": -16,
      "name": "Rock_Ice"
    },
    {
      "x": 0,
      "y": 1,
      "z": -16,
      "name": "Rock_Ice"
    },
    {
      "x": 0,
      "y": 2,
      "z": -16,
      "name": "Rock_Ice"
    },
    {
      "x": 0,
      "y": 3,
      "z": -16,
      "name": "Rock_Ice"
    },
    {
      "x": 0,
      "y": 4,
      "z": -16,
      "name": "Rock_Ice"
    },
    {
      "x": 0,
      "y": 5,
      "z": -16,
      "name": "Rock_Ice"
    },
    {
      "x": 0,
      "y": 0,
      "z": -15,
      "name": "Soil_Snow"
    },
    {
      "x": 0,
      "y": 1,
      "z": -15,
      "name": "Empty"
    },
    {
      "x": 0,
      "y": 2,
      "z": -15,
      "name": "Empty"
    },
    {
      "x": 0,
      "y": 3,
      "z": -15,
      "name": "Empty"
    },
    {
      "x": 0,
      "y": 4,
      "z": -15,
      "name": "Empty"
    },
    {
      "x": 0,
      "y": 5,
      "z": -15,
      "name": "Rock_Ice"
    },
    {
      "x": 0,
      "y": 0,
      "z": -14,
      "name": "Soil_Snow"
    },
    {
      "x": 0,
      "y": 1,
      "z": -14,
      "name": "Wood_Deadwood_Beam"
    },
    {
      "x": 0,
      "y": 2,
      "z": -14,
      "name": "*Furniture_Human_Ruins_Torch_State_Definitions_Off",
      "rotation": 2
    },
    {
      "x": 0,
      "y": 3,
      "z": -14,
      "name": "Empty"
    },
    {
      "x": 0,
      "y": 4,
      "z": -14,
      "name": "Empty"
    },
    {
      "x": 0,
      "y": 5,
      "z": -14,
      "name": "Rock_Ice"
    },
    {
      "x": 0,
      "y": 0,
      "z": -13,
      "name": "Soil_Snow"
    },
    {
      "x": 0,
      "y": 1,
      "z": -13,
      "name": "Empty"
    },
    {
      "x": 0,
      "y": 2,
      "z": -13,
      "name": "Empty"
    },
    {
      "x": 0,
      "y": 3,
      "z": -13,
      "name": "Rock_Ice_Stalactite_Large",
      "filler": 31744,
      "rotation": 8
    },
    {
      "x": 0,
      "y": 4,
      "z": -13,
      "name": "Rock_Ice_Stalactite_Large",
      "rotation": 8
    },
    {
      "x": 0,
      "y": 5,
      "z": -13,
      "name": "Rock_Ice"
    },
    {
      "x": 0,
      "y": 0,
      "z": -12,
      "name": "Soil_Snow"
    },
    {
      "x": 0,
      "y": 1,
      "z": -12,
      "name": "Empty"
    },
    {
      "x": 0,
      "y": 2,
      "z": -12,
      "name": "Empty"
    },
    {
      "x": 0,
      "y": 3,
      "z": -12,
      "name": "Empty"
    },
    {
      "x": 0,
      "y": 4,
      "z": -12,
      "name": "Empty"
    },
    {
      "x": 0,
      "y": 5,
      "z": -12,
      "name": "Rock_Ice"
    },
    {
      "x": 0,
      "y": 0,
      "z": -11,
      "name": "Soil_Snow"
    },
    {
      "x": 0,
      "y": 1,
      "z": -11,
      "name": "Empty"
    },
    {
      "x": 0,
      "y": 2,
      "z": -11,
      "name": "Empty"
    },
    {
      "x": 0,
      "y": 3,
      "z": -11,
      "name": "Empty"
    },
    {
      "x": 0,
      "y": 4,
      "z": -11,
      "name": "Empty"
    },
    {
      "x": 0,
      "y": 5,
      "z": -11,
      "name": "Rock_Ice"
    },
    {
      "x": 0,
      "y": 0,
      "z": -10,
      "name": "Soil_Snow"
    },
    {
      "x": 0,
      "y": 1,
      "z": -10,
      "name": "Empty"
    },
    {
      "x": 0,
      "y": 2,
      "z": -10,
      "name": "Empty"
    },
    {
      "x": 0,
      "y": 3,
      "z": -10,
      "name": "Empty"
    },
    {
      "x": 0,
      "y": 4,
      "z": -10,
      "name": "Empty"
    },
    {
      "x": 0,
      "y": 5,
      "z": -10,
      "name": "Rock_Ice"
    },
    {
      "x": 0,
      "y": 0,
      "z": -9,
      "name": "Soil_Snow"
    },
    {
      "x": 0,
      "y": 1,
      "z": -9,
      "name": "Empty"
    },
    {
      "x": 0,
      "y": 2,
      "z": -9,
      "name": "Empty"
    },
    {
      "x": 0,
      "y": 3,
      "z": -9,
      "name": "Empty"
    },
    {
      "x": 0,
      "y": 4,
      "z": -9,
      "name": "Empty"
    },
    {
      "x": 0,
      "y": 5,
      "z": -9,
      "name": "Rock_Ice"
    },
    {
      "x": 0,
      "y": 0,
      "z": -8,
      "name": "Soil_Snow"
    },
    {
      "x": 0,
      "y": 1,
      "z": -8,
      "name": "Empty"
    },
    {
      "x": 0,
      "y": 2,
      "z": -8,
      "name": "Empty"
    },
    {
      "x": 0,
      "y": 3,
      "z": -8,
      "name": "Empty"
    },
    {
      "x": 0,
      "y": 4,
      "z": -8,
      "name": "Empty"
    },
    {
      "x": 0,
      "y": 5,
      "z": -8,
      "name": "Rock_Ice"
    },
    {
      "x": 0,
      "y": 0,
      "z": -7,
      "name": "Soil_Snow"
    },
    {
      "x": 0,
      "y": 1,
      "z": -7,
      "name": "Empty"
    },
    {
      "x": 0,
      "y": 2,
      "z": -7,
      "name": "Empty"
    },
    {
      "x": 0,
      "y": 3,
      "z": -7,
      "name": "Empty"
    },
    {
      "x": 0,
      "y": 4,
      "z": -7,
      "name": "Empty"
    },
    {
      "x": 0,
      "y": 5,
      "z": -7,
      "name": "Rock_Ice"
    },
    {
      "x": 0,
      "y": 0,
      "z": -6,
      "name": "Soil_Snow"
    },
    {
      "x": 0,
      "y": 1,
      "z": -6,
      "name": "Empty"
    },
    {
      "x": 0,
      "y": 2,
      "z": -6,
      "name": "Empty"
    },
    {
      "x": 0,
      "y": 3,
      "z": -6,
      "name": "Empty"
    },
    {
      "x": 0,
      "y": 4,
      "z": -6,
      "name": "Empty"
    },
    {
      "x": 0,
      "y": 5,
      "z": -6,
      "name": "Rock_Ice"
    },
    {
      "x": 0,
      "y": 0,
      "z": -5,
      "name": "Soil_Snow"
    },
    {
      "x": 0,
      "y": 1,
      "z": -5,
      "name": "Empty"
    },
    {
      "x": 0,
      "y": 2,
      "z": -5,
      "name": "Empty"
    },
    {
      "x": 0,
      "y": 3,
      "z": -5,
      "name": "Empty"
    },
    {
      "x": 0,
      "y": 4,
      "z": -5,
      "name": "Empty"
    },
    {
      "x": 0,
      "y": 5,
      "z": -5,
      "name": "Rock_Ice"
    },
    {
      "x": 0,
      "y": 0,
      "z": -4,
      "name": "Soil_Snow"
    },
    {
      "x": 0,
      "y": 1,
      "z": -4,
      "name": "Empty"
    },
    {
      "x": 0,
      "y": 2,
      "z": -4,
      "name": "Empty"
    },
    {
      "x": 0,
      "y": 3,
      "z": -4,
      "name": "Empty"
    },
    {
      "x": 0,
      "y": 4,
      "z": -4,
      "name": "Empty"
    },
    {
      "x": 0,
      "y": 5,
      "z": -4,
      "name": "Rock_Ice"
    },
    {
      "x": 0,
      "y": 0,
      "z": -3,
      "name": "Soil_Dirt_Cold"
    },
    {
      "x": 0,
      "y": 1,
      "z": -3,
      "name": "Empty"
    },
    {
      "x": 0,
      "y": 2,
      "z": -3,
      "name": "Empty"
    },
    {
      "x": 0,
      "y": 3,
      "z": -3,
      "name": "Empty"
    },
    {
      "x": 0,
      "y": 4,
      "z": -3,
      "name": "Empty"
    },
    {
      "x": 0,
      "y": 5,
      "z": -3,
      "name": "Rock_Ice"
    },
    {
      "x": 0,
      "y": 0,
      "z": -2,
      "name": "Rock_Basalt_Cobble"
    },
    {
      "x": 0,
      "y": 1,
      "z": -2,
      "name": "Empty"
    },
    {
      "x": 0,
      "y": 2,
      "z": -2,
      "name": "Empty"
    },
    {
      "x": 0,
      "y": 3,
      "z": -2,
      "name": "Empty"
    },
    {
      "x": 0,
      "y": 4,
      "z": -2,
      "name": "Empty"
    },
    {
      "x": 0,
      "y": 5,
      "z": -2,
      "name": "Rock_Ice"
    },
    {
      "x": 0,
      "y": 0,
      "z": -1,
      "name": "Rock_Basalt_Cobble"
    },
    {
      "x": 0,
      "y": 1,
      "z": -1,
      "name": "Empty"
    },
    {
      "x": 0,
      "y": 2,
      "z": -1,
      "name": "Empty"
    },
    {
      "x": 0,
      "y": 3,
      "z": -1,
      "name": "Empty"
    },
    {
      "x": 0,
      "y": 4,
      "z": -1,
      "name": "Empty"
    },
    {
      "x": 0,
      "y": 5,
      "z": -1,
      "name": "Rock_Ice"
    },
    {
      "x": 0,
      "y": 0,
      "z": 0,
      "name": "Rock_Basalt_Cobble"
    },
    {
      "x": 0,
      "y": 1,
      "z": 0,
      "name": "Empty"
    },
    {
      "x": 0,
      "y": 2,
      "z": 0,
      "name": "Empty"
    },
    {
      "x": 0,
      "y": 3,
      "z": 0,
      "name": "Empty"
    },
    {
      "x": 0,
      "y": 4,
      "z": 0,
      "name": "Empty"
    },
    {
      "x": 0,
      "y": 5,
      "z": 0,
      "name": "Rock_Ice"
    },
    {
      "x": 1,
      "y": 0,
      "z": -16,
      "name": "Rock_Ice"
    },
    {
      "x": 1,
      "y": 1,
      "z": -16,
      "name": "Rock_Ice"
    },
    {
      "x": 1,
      "y": 2,
      "z": -16,
      "name": "Rock_Ice"
    },
    {
      "x": 1,
      "y": 3,
      "z": -16,
      "name": "Rock_Ice"
    },
    {
      "x": 1,
      "y": 4,
      "z": -16,
      "name": "Rock_Ice"
    },
    {
      "x": 1,
      "y": 5,
      "z": -16,
      "name": "Rock_Ice"
    },
    {
      "x": 1,
      "y": 0,
      "z": -15,
      "name": "Soil_Snow"
    },
    {
      "x": 1,
      "y": 1,
      "z": -15,
      "name": "Empty"
    },
    {
      "x": 1,
      "y": 2,
      "z": -15,
      "name": "Empty"
    },
    {
      "x": 1,
      "y": 3,
      "z": -15,
      "name": "Empty"
    },
    {
      "x": 1,
      "y": 4,
      "z": -15,
      "name": "Rock_Shale_Brick_Stairs",
      "rotation": 9
    },
    {
      "x": 1,
      "y": 5,
      "z": -15,
      "name": "Rock_Ice"
    },
    {
      "x": 1,
      "y": 0,
      "z": -14,
      "name": "Soil_Snow"
    },
    {
      "x": 1,
      "y": 1,
      "z": -14,
      "name": "Empty"
    },
    {
      "x": 1,
      "y": 2,
      "z": -14,
      "name": "Empty"
    },
    {
      "x": 1,
      "y": 3,
      "z": -14,
      "name": "Empty"
    },
    {
      "x": 1,
      "y": 4,
      "z": -14,
      "name": "Rock_Shale_Brick_Stairs",
      "rotation": 9
    },
    {
      "x": 1,
      "y": 5,
      "z": -14,
      "name": "Rock_Ice"
    },
    {
      "x": 1,
      "y": 0,
      "z": -13,
      "name": "Soil_Snow"
    },
    {
      "x": 1,
      "y": 1,
      "z": -13,
      "name": "Empty"
    },
    {
      "x": 1,
      "y": 2,
      "z": -13,
      "name": "Empty"
    },
    {
      "x": 1,
      "y": 3,
      "z": -13,
      "name": "Empty"
    },
    {
      "x": 1,
      "y": 4,
      "z": -13,
      "name": "*Rock_Shale_Brick_Stairs_State_Definitions_Corner_Right",
      "rotation": 9
    },
    {
      "x": 1,
      "y": 5,
      "z": -13,
      "name": "Rock_Ice"
    },
    {
      "x": 1,
      "y": 0,
      "z": -12,
      "name": "Soil_Snow"
    },
    {
      "x": 1,
      "y": 1,
      "z": -12,
      "name": "Empty"
    },
    {
      "x": 1,
      "y": 2,
      "z": -12,
      "name": "Empty"
    },
    {
      "x": 1,
      "y": 3,
      "z": -12,
      "name": "Empty"
    },
    {
      "x": 1,
      "y": 4,
      "z": -12,
      "name": "*Rock_Shale_Brick_Stairs_State_Definitions_Corner_Right",
      "rotation": 8
    },
    {
      "x": 1,
      "y": 5,
      "z": -12,
      "name": "Rock_Ice"
    },
    {
      "x": 1,
      "y": 0,
      "z": -11,
      "name": "Soil_Snow"
    },
    {
      "x": 1,
      "y": 1,
      "z": -11,
      "name": "Empty"
    },
    {
      "x": 1,
      "y": 2,
      "z": -11,
      "name": "Empty"
    },
    {
      "x": 1,
      "y": 3,
      "z": -11,
      "name": "Empty"
    },
    {
      "x": 1,
      "y": 4,
      "z": -11,
      "name": "Rock_Shale_Brick_Stairs",
      "rotation": 9
    },
    {
      "x": 1,
      "y": 5,
      "z": -11,
      "name": "Rock_Ice"
    },
    {
      "x": 1,
      "y": 0,
      "z": -10,
      "name": "Rock_Ice"
    },
    {
      "x": 1,
      "y": 1,
      "z": -10,
      "name": "Soil_Snow_Half"
    },
    {
      "x": 1,
      "y": 2,
      "z": -10,
      "name": "Empty"
    },
    {
      "x": 1,
      "y": 3,
      "z": -10,
      "name": "Empty"
    },
    {
      "x": 1,
      "y": 4,
      "z": -10,
      "name": "Rock_Shale_Brick_Stairs",
      "rotation": 9
    },
    {
      "x": 1,
      "y": 5,
      "z": -10,
      "name": "Rock_Ice"
    },
    {
      "x": 1,
      "y": 0,
      "z": -9,
      "name": "Rock_Ice"
    },
    {
      "x": 1,
      "y": 1,
      "z": -9,
      "name": "Soil_Snow_Half"
    },
    {
      "x": 1,
      "y": 2,
      "z": -9,
      "name": "Empty"
    },
    {
      "x": 1,
      "y": 3,
      "z": -9,
      "name": "Empty"
    },
    {
      "x": 1,
      "y": 4,
      "z": -9,
      "name": "*Rock_Shale_Brick_Stairs_State_Definitions_Corner_Right",
      "rotation": 9
    },
    {
      "x": 1,
      "y": 5,
      "z": -9,
      "name": "Rock_Ice"
    },
    {
      "x": 1,
      "y": 0,
      "z": -8,
      "name": "Soil_Snow"
    },
    {
      "x": 1,
      "y": 1,
      "z": -8,
      "name": "Soil_Snow_Half"
    },
    {
      "x": 1,
      "y": 2,
      "z": -8,
      "name": "Empty"
    },
    {
      "x": 1,
      "y": 3,
      "z": -8,
      "name": "Empty"
    },
    {
      "x": 1,
      "y": 4,
      "z": -8,
      "name": "Empty"
    },
    {
      "x": 1,
      "y": 5,
      "z": -8,
      "name": "Rock_Ice"
    },
    {
      "x": 1,
      "y": 0,
      "z": -7,
      "name": "Soil_Snow"
    },
    {
      "x": 1,
      "y": 1,
      "z": -7,
      "name": "Rubble_Ice"
    },
    {
      "x": 1,
      "y": 2,
      "z": -7,
      "name": "Empty"
    },
    {
      "x": 1,
      "y": 3,
      "z": -7,
      "name": "Empty"
    },
    {
      "x": 1,
      "y": 4,
      "z": -7,
      "name": "*Rock_Shale_Brick_Stairs_State_Definitions_Corner_Right",
      "rotation": 8
    },
    {
      "x": 1,
      "y": 5,
      "z": -7,
      "name": "Rock_Ice"
    },
    {
      "x": 1,
      "y": 0,
      "z": -6,
      "name": "Soil_Snow"
    },
    {
      "x": 1,
      "y": 1,
      "z": -6,
      "name": "Empty"
    },
    {
      "x": 1,
      "y": 2,
      "z": -6,
      "name": "Empty"
    },
    {
      "x": 1,
      "y": 3,
      "z": -6,
      "name": "Empty"
    },
    {
      "x": 1,
      "y": 4,
      "z": -6,
      "name": "Rock_Shale_Brick_Stairs",
      "rotation": 9
    },
    {
      "x": 1,
      "y": 5,
      "z": -6,
      "name": "Rock_Ice"
    },
    {
      "x": 1,
      "y": 0,
      "z": -5,
      "name": "Soil_Snow"
    },
    {
      "x": 1,
      "y": 1,
      "z": -5,
      "name": "Empty"
    },
    {
      "x": 1,
      "y": 2,
      "z": -5,
      "name": "Empty"
    },
    {
      "x": 1,
      "y": 3,
      "z": -5,
      "name": "Empty"
    },
    {
      "x": 1,
      "y": 4,
      "z": -5,
      "name": "Rock_Shale_Brick_Stairs",
      "rotation": 9
    },
    {
      "x": 1,
      "y": 5,
      "z": -5,
      "name": "Rock_Ice"
    },
    {
      "x": 1,
      "y": 0,
      "z": -4,
      "name": "Soil_Snow"
    },
    {
      "x": 1,
      "y": 1,
      "z": -4,
      "name": "Empty"
    },
    {
      "x": 1,
      "y": 2,
      "z": -4,
      "name": "Empty"
    },
    {
      "x": 1,
      "y": 3,
      "z": -4,
      "name": "Empty"
    },
    {
      "x": 1,
      "y": 4,
      "z": -4,
      "name": "*Rock_Shale_Brick_Stairs_State_Definitions_Corner_Right",
      "rotation": 9
    },
    {
      "x": 1,
      "y": 5,
      "z": -4,
      "name": "Rock_Ice"
    },
    {
      "x": 1,
      "y": 0,
      "z": -3,
      "name": "Soil_Snow"
    },
    {
      "x": 1,
      "y": 1,
      "z": -3,
      "name": "Empty"
    },
    {
      "x": 1,
      "y": 2,
      "z": -3,
      "name": "Empty"
    },
    {
      "x": 1,
      "y": 3,
      "z": -3,
      "name": "Empty"
    },
    {
      "x": 1,
      "y": 4,
      "z": -3,
      "name": "*Rock_Shale_Brick_Stairs_State_Definitions_Corner_Right",
      "rotation": 8
    },
    {
      "x": 1,
      "y": 5,
      "z": -3,
      "name": "Rock_Ice"
    },
    {
      "x": 1,
      "y": 0,
      "z": -2,
      "name": "Soil_Dirt_Cold"
    },
    {
      "x": 1,
      "y": 1,
      "z": -2,
      "name": "Empty"
    },
    {
      "x": 1,
      "y": 2,
      "z": -2,
      "name": "Empty"
    },
    {
      "x": 1,
      "y": 3,
      "z": -2,
      "name": "Empty"
    },
    {
      "x": 1,
      "y": 4,
      "z": -2,
      "name": "Rock_Shale_Brick_Stairs",
      "rotation": 9
    },
    {
      "x": 1,
      "y": 5,
      "z": -2,
      "name": "Rock_Ice"
    },
    {
      "x": 1,
      "y": 0,
      "z": -1,
      "name": "Rock_Basalt_Cobble"
    },
    {
      "x": 1,
      "y": 1,
      "z": -1,
      "name": "Empty"
    },
    {
      "x": 1,
      "y": 2,
      "z": -1,
      "name": "Empty"
    },
    {
      "x": 1,
      "y": 3,
      "z": -1,
      "name": "Empty"
    },
    {
      "x": 1,
      "y": 4,
      "z": -1,
      "name": "Rock_Shale_Brick_Stairs",
      "rotation": 9
    },
    {
      "x": 1,
      "y": 5,
      "z": -1,
      "name": "Rock_Ice"
    },
    {
      "x": 1,
      "y": 0,
      "z": 0,
      "name": "Rock_Basalt_Cobble"
    },
    {
      "x": 1,
      "y": 1,
      "z": 0,
      "name": "Empty"
    },
    {
      "x": 1,
      "y": 2,
      "z": 0,
      "name": "Empty"
    },
    {
      "x": 1,
      "y": 3,
      "z": 0,
      "name": "Empty"
    },
    {
      "x": 1,
      "y": 4,
      "z": 0,
      "name": "Empty"
    },
    {
      "x": 1,
      "y": 5,
      "z": 0,
      "name": "Rock_Ice"
    },
    {
      "x": 2,
      "y": 0,
      "z": -16,
      "name": "Rock_Ice"
    },
    {
      "x": 2,
      "y": 1,
      "z": -16,
      "name": "Rock_Ice"
    },
    {
      "x": 2,
      "y": 2,
      "z": -16,
      "name": "Rock_Ice"
    },
    {
      "x": 2,
      "y": 3,
      "z": -16,
      "name": "Rock_Ice"
    },
    {
      "x": 2,
      "y": 4,
      "z": -16,
      "name": "Rock_Ice"
    },
    {
      "x": 2,
      "y": 5,
      "z": -16,
      "name": "Rock_Ice"
    },
    {
      "x": 2,
      "y": 0,
      "z": -15,
      "name": "Rock_Shale_Brick"
    },
    {
      "x": 2,
      "y": 1,
      "z": -15,
      "name": "Rock_Shale_Brick_Ornate"
    },
    {
      "x": 2,
      "y": 2,
      "z": -15,
      "name": "Rock_Shale"
    },
    {
      "x": 2,
      "y": 3,
      "z": -15,
      "name": "Rock_Shale"
    },
    {
      "x": 2,
      "y": 4,
      "z": -15,
      "name": "Rock_Shale_Brick"
    },
    {
      "x": 2,
      "y": 5,
      "z": -15,
      "name": "Rock_Ice"
    },
    {
      "x": 2,
      "y": 0,
      "z": -14,
      "name": "Rock_Shale_Brick"
    },
    {
      "x": 2,
      "y": 1,
      "z": -14,
      "name": "Rock_Shale_Brick_Ornate"
    },
    {
      "x": 2,
      "y": 2,
      "z": -14,
      "name": "Rock_Shale"
    },
    {
      "x": 2,
      "y": 3,
      "z": -14,
      "name": "Rock_Shale"
    },
    {
      "x": 2,
      "y": 4,
      "z": -14,
      "name": "Rock_Shale_Brick"
    },
    {
      "x": 2,
      "y": 5,
      "z": -14,
      "name": "Rock_Ice"
    },
    {
      "x": 2,
      "y": 0,
      "z": -13,
      "name": "Soil_Snow"
    },
    {
      "x": 2,
      "y": 1,
      "z": -13,
      "name": "Empty"
    },
    {
      "x": 2,
      "y": 2,
      "z": -13,
      "name": "Empty"
    },
    {
      "x": 2,
      "y": 3,
      "z": -13,
      "name": "Empty"
    },
    {
      "x": 2,
      "y": 4,
      "z": -13,
      "name": "Rock_Shale_Brick_Stairs",
      "rotation": 10
    },
    {
      "x": 2,
      "y": 5,
      "z": -13,
      "name": "Rock_Ice"
    },
    {
      "x": 2,
      "y": 0,
      "z": -12,
      "name": "Soil_Snow"
    },
    {
      "x": 2,
      "y": 1,
      "z": -12,
      "name": "Empty"
    },
    {
      "x": 2,
      "y": 2,
      "z": -12,
      "name": "Empty"
    },
    {
      "x": 2,
      "y": 3,
      "z": -12,
      "name": "Empty"
    },
    {
      "x": 2,
      "y": 4,
      "z": -12,
      "name": "Rock_Shale_Brick_Stairs",
      "rotation": 8
    },
    {
      "x": 2,
      "y": 5,
      "z": -12,
      "name": "Rock_Ice"
    },
    {
      "x": 2,
      "y": 0,
      "z": -11,
      "name": "Rock_Shale_Brick"
    },
    {
      "x": 2,
      "y": 1,
      "z": -11,
      "name": "Rock_Shale_Brick_Ornate"
    },
    {
      "x": 2,
      "y": 2,
      "z": -11,
      "name": "Rock_Shale"
    },
    {
      "x": 2,
      "y": 3,
      "z": -11,
      "name": "Rock_Shale"
    },
    {
      "x": 2,
      "y": 4,
      "z": -11,
      "name": "Rock_Shale_Brick"
    },
    {
      "x": 2,
      "y": 5,
      "z": -11,
      "name": "Rock_Ice"
    },
    {
      "x": 2,
      "y": 0,
      "z": -10,
      "name": "Rock_Shale_Brick"
    },
    {
      "x": 2,
      "y": 1,
      "z": -10,
      "name": "Rock_Shale_Brick_Ornate"
    },
    {
      "x": 2,
      "y": 2,
      "z": -10,
      "name": "Rock_Shale"
    },
    {
      "x": 2,
      "y": 3,
      "z": -10,
      "name": "Rock_Shale"
    },
    {
      "x": 2,
      "y": 4,
      "z": -10,
      "name": "Rock_Ice"
    },
    {
      "x": 2,
      "y": 5,
      "z": -10,
      "name": "Rock_Ice"
    },
    {
      "x": 2,
      "y": 0,
      "z": -9,
      "name": "Rock_Ice"
    },
    {
      "x": 2,
      "y": 1,
      "z": -9,
      "name": "Soil_Snow"
    },
    {
      "x": 2,
      "y": 2,
      "z": -9,
      "name": "Soil_Snow_Half",
      "rotation": 7
    },
    {
      "x": 2,
      "y": 3,
      "z": -9,
      "name": "Empty"
    },
    {
      "x": 2,
      "y": 4,
      "z": -9,
      "name": "Rock_Ice"
    },
    {
      "x": 2,
      "y": 5,
      "z": -9,
      "name": "Rock_Ice"
    },
    {
      "x": 2,
      "y": 0,
      "z": -8,
      "name": "Rock_Ice"
    },
    {
      "x": 2,
      "y": 1,
      "z": -8,
      "name": "Soil_Snow_Half"
    },
    {
      "x": 2,
      "y": 2,
      "z": -8,
      "name": "Empty"
    },
    {
      "x": 2,
      "y": 3,
      "z": -8,
      "name": "Rock_Ice_Stalactite_Large",
      "filler": 31744,
      "rotation": 8
    },
    {
      "x": 2,
      "y": 4,
      "z": -8,
      "name": "Rock_Ice_Stalactite_Large",
      "rotation": 8
    },
    {
      "x": 2,
      "y": 5,
      "z": -8,
      "name": "Rock_Ice"
    },
    {
      "x": 2,
      "y": 0,
      "z": -7,
      "name": "Rock_Ice"
    },
    {
      "x": 2,
      "y": 1,
      "z": -7,
      "name": "Rock_Ice"
    },
    {
      "x": 2,
      "y": 2,
      "z": -7,
      "name": "Soil_Snow_Half"
    },
    {
      "x": 2,
      "y": 3,
      "z": -7,
      "name": "Rock_Ice_Icicles",
      "rotation": 8
    },
    {
      "x": 2,
      "y": 4,
      "z": -7,
      "name": "Rock_Ice"
    },
    {
      "x": 2,
      "y": 5,
      "z": -7,
      "name": "Rock_Ice"
    },
    {
      "x": 2,
      "y": 0,
      "z": -6,
      "name": "Rock_Shale_Brick"
    },
    {
      "x": 2,
      "y": 1,
      "z": -6,
      "name": "Rock_Ice"
    },
    {
      "x": 2,
      "y": 2,
      "z": -6,
      "name": "Rock_Ice"
    },
    {
      "x": 2,
      "y": 3,
      "z": -6,
      "name": "Rock_Shale"
    },
    {
      "x": 2,
      "y": 4,
      "z": -6,
      "name": "Rock_Shale_Brick"
    },
    {
      "x": 2,
      "y": 5,
      "z": -6,
      "name": "Rock_Ice"
    },
    {
      "x": 2,
      "y": 0,
      "z": -5,
      "name": "Rock_Shale_Brick"
    },
    {
      "x": 2,
      "y": 1,
      "z": -5,
      "name": "Rock_Shale_Brick_Ornate"
    },
    {
      "x": 2,
      "y": 2,
      "z": -5,
      "name": "Rock_Shale"
    },
    {
      "x": 2,
      "y": 3,
      "z": -5,
      "name": "Rock_Shale"
    },
    {
      "x": 2,
      "y": 4,
      "z": -5,
      "name": "Rock_Shale_Brick"
    },
    {
      "x": 2,
      "y": 5,
      "z": -5,
      "name": "Rock_Ice"
    },
    {
      "x": 2,
      "y": 0,
      "z": -4,
      "name": "Soil_Snow"
    },
    {
      "x": 2,
      "y": 1,
      "z": -4,
      "name": "Empty"
    },
    {
      "x": 2,
      "y": 2,
      "z": -4,
      "name": "Empty"
    },
    {
      "x": 2,
      "y": 3,
      "z": -4,
      "name": "Empty"
    },
    {
      "x": 2,
      "y": 4,
      "z": -4,
      "name": "Rock_Shale_Brick_Stairs",
      "rotation": 10
    },
    {
      "x": 2,
      "y": 5,
      "z": -4,
      "name": "Rock_Ice"
    },
    {
      "x": 2,
      "y": 0,
      "z": -3,
      "name": "Soil_Snow"
    },
    {
      "x": 2,
      "y": 1,
      "z": -3,
      "name": "Empty"
    },
    {
      "x": 2,
      "y": 2,
      "z": -3,
      "name": "Empty"
    },
    {
      "x": 2,
      "y": 3,
      "z": -3,
      "name": "Empty"
    },
    {
      "x": 2,
      "y": 4,
      "z": -3,
      "name": "Rock_Shale_Brick_Stairs",
      "rotation": 8
    },
    {
      "x": 2,
      "y": 5,
      "z": -3,
      "name": "Rock_Ice"
    },
    {
      "x": 2,
      "y": 0,
      "z": -2,
      "name": "Rock_Shale_Brick"
    },
    {
      "x": 2,
      "y": 1,
      "z": -2,
      "name": "Rock_Shale_Brick_Ornate"
    },
    {
      "x": 2,
      "y": 2,
      "z": -2,
      "name": "Rock_Shale"
    },
    {
      "x": 2,
      "y": 3,
      "z": -2,
      "name": "Rock_Shale"
    },
    {
      "x": 2,
      "y": 4,
      "z": -2,
      "name": "Rock_Shale_Brick"
    },
    {
      "x": 2,
      "y": 5,
      "z": -2,
      "name": "Rock_Ice"
    },
    {
      "x": 2,
      "y": 0,
      "z": -1,
      "name": "Rock_Shale_Brick"
    },
    {
      "x": 2,
      "y": 1,
      "z": -1,
      "name": "Rock_Shale_Brick_Ornate"
    },
    {
      "x": 2,
      "y": 2,
      "z": -1,
      "name": "Rock_Shale"
    },
    {
      "x": 2,
      "y": 3,
      "z": -1,
      "name": "Rock_Shale"
    },
    {
      "x": 2,
      "y": 4,
      "z": -1,
      "name": "Rock_Shale_Brick"
    },
    {
      "x": 2,
      "y": 5,
      "z": -1,
      "name": "Rock_Ice"
    },
    {
      "x": 2,
      "y": 0,
      "z": 0,
      "name": "Rock_Basalt_Cobble"
    },
    {
      "x": 2,
      "y": 1,
      "z": 0,
      "name": "Empty"
    },
    {
      "x": 2,
      "y": 2,
      "z": 0,
      "name": "Empty"
    },
    {
      "x": 2,
      "y": 3,
      "z": 0,
      "name": "Empty"
    },
    {
      "x": 2,
      "y": 4,
      "z": 0,
      "name": "Empty"
    },
    {
      "x": 2,
      "y": 5,
      "z": 0,
      "name": "Rock_Ice"
    },
    {
      "x": 3,
      "y": 0,
      "z": -16,
      "name": "Rock_Ice"
    },
    {
      "x": 3,
      "y": 1,
      "z": -16,
      "name": "Rock_Ice"
    },
    {
      "x": 3,
      "y": 2,
      "z": -16,
      "name": "Rock_Ice"
    },
    {
      "x": 3,
      "y": 3,
      "z": -16,
      "name": "Rock_Ice"
    },
    {
      "x": 3,
      "y": 4,
      "z": -16,
      "name": "Rock_Ice"
    },
    {
      "x": 3,
      "y": 5,
      "z": -16,
      "name": "Rock_Ice"
    },
    {
      "x": 3,
      "y": 0,
      "z": -15,
      "name": "Rock_Shale_Brick"
    },
    {
      "x": 3,
      "y": 1,
      "z": -15,
      "name": "Rock_Shale_Brick_Ornate"
    },
    {
      "x": 3,
      "y": 2,
      "z": -15,
      "name": "Rock_Shale"
    },
    {
      "x": 3,
      "y": 3,
      "z": -15,
      "name": "Rock_Shale"
    },
    {
      "x": 3,
      "y": 4,
      "z": -15,
      "name": "Rock_Shale_Brick"
    },
    {
      "x": 3,
      "y": 5,
      "z": -15,
      "name": "Rock_Ice"
    },
    {
      "x": 3,
      "y": 0,
      "z": -14,
      "name": "Rock_Shale_Brick"
    },
    {
      "x": 3,
      "y": 1,
      "z": -14,
      "name": "Rock_Shale_Brick_Ornate"
    },
    {
      "x": 3,
      "y": 2,
      "z": -14,
      "name": "Rock_Shale"
    },
    {
      "x": 3,
      "y": 3,
      "z": -14,
      "name": "Rock_Shale"
    },
    {
      "x": 3,
      "y": 4,
      "z": -14,
      "name": "Rock_Shale_Brick"
    },
    {
      "x": 3,
      "y": 5,
      "z": -14,
      "name": "Rock_Ice"
    },
    {
      "x": 3,
      "y": 0,
      "z": -13,
      "name": "Soil_Snow"
    },
    {
      "x": 3,
      "y": 1,
      "z": -13,
      "name": "Empty"
    },
    {
      "x": 3,
      "y": 2,
      "z": -13,
      "name": "Empty"
    },
    {
      "x": 3,
      "y": 3,
      "z": -13,
      "name": "Empty"
    },
    {
      "x": 3,
      "y": 4,
      "z": -13,
      "name": "Rock_Shale_Brick_Stairs",
      "rotation": 10
    },
    {
      "x": 3,
      "y": 5,
      "z": -13,
      "name": "Rock_Ice"
    },
    {
      "x": 3,
      "y": 0,
      "z": -12,
      "name": "Soil_Snow"
    },
    {
      "x": 3,
      "y": 1,
      "z": -12,
      "name": "Empty"
    },
    {
      "x": 3,
      "y": 2,
      "z": -12,
      "name": "Empty"
    },
    {
      "x": 3,
      "y": 3,
      "z": -12,
      "name": "Empty"
    },
    {
      "x": 3,
      "y": 4,
      "z": -12,
      "name": "Rock_Shale_Brick_Stairs",
      "rotation": 8
    },
    {
      "x": 3,
      "y": 5,
      "z": -12,
      "name": "Rock_Ice"
    },
    {
      "x": 3,
      "y": 0,
      "z": -11,
      "name": "Rock_Shale_Brick"
    },
    {
      "x": 3,
      "y": 1,
      "z": -11,
      "name": "Rock_Shale_Brick_Ornate"
    },
    {
      "x": 3,
      "y": 2,
      "z": -11,
      "name": "Rock_Shale"
    },
    {
      "x": 3,
      "y": 3,
      "z": -11,
      "name": "Rock_Shale"
    },
    {
      "x": 3,
      "y": 4,
      "z": -11,
      "name": "Rock_Shale_Brick"
    },
    {
      "x": 3,
      "y": 5,
      "z": -11,
      "name": "Rock_Ice"
    },
    {
      "x": 3,
      "y": 0,
      "z": -10,
      "name": "Rock_Shale_Brick"
    },
    {
      "x": 3,
      "y": 1,
      "z": -10,
      "name": "Rock_Shale_Brick_Ornate"
    },
    {
      "x": 3,
      "y": 2,
      "z": -10,
      "name": "Rock_Shale"
    },
    {
      "x": 3,
      "y": 3,
      "z": -10,
      "name": "Rock_Shale"
    },
    {
      "x": 3,
      "y": 4,
      "z": -10,
      "name": "Rock_Ice"
    },
    {
      "x": 3,
      "y": 5,
      "z": -10,
      "name": "Rock_Ice"
    },
    {
      "x": 3,
      "y": 0,
      "z": -9,
      "name": "Rock_Ice"
    },
    {
      "x": 3,
      "y": 1,
      "z": -9,
      "name": "Rock_Ice"
    },
    {
      "x": 3,
      "y": 2,
      "z": -9,
      "name": "Rock_Ice"
    },
    {
      "x": 3,
      "y": 3,
      "z": -9,
      "name": "Rock_Ice"
    },
    {
      "x": 3,
      "y": 4,
      "z": -9,
      "name": "Rock_Ice"
    },
    {
      "x": 3,
      "y": 5,
      "z": -9,
      "name": "Rock_Ice"
    },
    {
      "x": 3,
      "y": 0,
      "z": -8,
      "name": "Rock_Ice"
    },
    {
      "x": 3,
      "y": 1,
      "z": -8,
      "name": "Soil_Snow"
    },
    {
      "x": 3,
      "y": 2,
      "z": -8,
      "name": "Rubble_Ice_Medium"
    },
    {
      "x": 3,
      "y": 3,
      "z": -8,
      "name": "Empty"
    },
    {
      "x": 3,
      "y": 4,
      "z": -8,
      "name": "Plant_Flower_Orchid_Blue",
      "rotation": 8
    },
    {
      "x": 3,
      "y": 5,
      "z": -8,
      "name": "Rock_Ice"
    },
    {
      "x": 3,
      "y": 0,
      "z": -7,
      "name": "Rock_Ice"
    },
    {
      "x": 3,
      "y": 1,
      "z": -7,
      "name": "Rock_Ice"
    },
    {
      "x": 3,
      "y": 2,
      "z": -7,
      "name": "Rock_Ice"
    },
    {
      "x": 3,
      "y": 3,
      "z": -7,
      "name": "Rock_Ice"
    },
    {
      "x": 3,
