{
  "version": 8,
  "blockIdVersion": 8,
  "anchorX": 0,
  "anchorY": 0,
  "anchorZ": 0,
  "blocks": [
    {
      "x": -4,
      "y": 11,
      "z": -4,
      "name": "Rock_Stone"
    },
    {
      "x": -4,
      "y": 12,
      "z": -4,
      "name": "Rock_Stone"
    },
    {
      "x": -4,
      "y": 13,
      "z": -4,
      "name": "Rock_Stone"
    },
    {
      "x": -4,
      "y": 14,
      "z": -4,
      "name": "Rock_Stone"
    },
    {
      "x": -4,
      "y": 15,
      "z": -4,
      "name": "Rock_Stone"
    },
    {
      "x": -4,
      "y": 16,
      "z": -4,
      "name": "Rock_Stone"
    },
    {
      "x": -4,
      "y": 17,
      "z": -4,
      "name": "Rock_Stone"
    },
    {
      "x": -4,
      "y": 18,
      "z": -4,
      "name": "Rock_Stone"
    },
    {
      "x": -4,
      "y": 19,
      "z": -4,
      "name": "Rock_Stone"
    },
    {
      "x": -4,
      "y": 20,
      "z": -4,
      "name": "Rock_Stone"
    },
    {
      "x": -4,
      "y": 21,
      "z": -4,
      "name": "Rock_Stone"
    },
    {
      "x": -4,
      "y": 22,
      "z": -4,
      "name": "Rock_Stone"
    },
    {
      "x": -4,
      "y": 23,
      "z": -4,
      "name": "Rock_Stone"
    },
    {
      "x": -4,
      "y": 24,
      "z": -4,
      "name": "Rock_Stone"
    },
    {
      "x": -4,
      "y": 25,
      "z": -4,
      "name": "Rock_Stone"
    },
    {
      "x": -4,
      "y": 11,
      "z": -3,
      "name": "Rock_Stone"
    },
    {
      "x": -4,
      "y": 12,
      "z": -3,
      "name": "Rock_Stone"
    },
    {
      "x": -4,
      "y": 13,
      "z": -3,
      "name": "Rock_Stone"
    },
    {
      "x": -4,
      "y": 14,
      "z": -3,
      "name": "Rock_Stone"
    },
    {
      "x": -4,
      "y": 15,
      "z": -3,
      "name": "Rock_Stone"
    },
    {
      "x": -4,
      "y": 16,
      "z": -3,
      "name": "Rock_Stone"
    },
    {
      "x": -4,
      "y": 17,
      "z": -3,
      "name": "Rock_Stone"
    },
    {
      "x": -4,
      "y": 18,
      "z": -3,
      "name": "Rock_Stone"
    },
    {
      "x": -4,
      "y": 19,
      "z": -3,
      "name": "Rock_Stone"
    },
    {
      "x": -4,
      "y": 20,
      "z": -3,
      "name": "Rock_Stone"
    },
    {
      "x": -4,
      "y": 21,
      "z": -3,
      "name": "Rock_Stone"
    },
    {
      "x": -4,
      "y": 22,
      "z": -3,
      "name": "Rock_Stone"
    },
    {
      "x": -4,
      "y": 23,
      "z": -3,
      "name": "Rock_Stone"
    },
    {
      "x": -4,
      "y": 24,
      "z": -3,
      "name": "Rock_Stone"
    },
    {
      "x": -4,
      "y": 25,
      "z": -3,
      "name": "Rock_Stone"
    },
    {
      "x": -4,
      "y": 11,
      "z": -2,
      "name": "Rock_Stone"
    },
    {
      "x": -4,
      "y": 12,
      "z": -2,
      "name": "Rock_Stone"
    },
    {
      "x": -4,
      "y": 13,
      "z": -2,
      "name": "Rock_Stone"
    },
    {
      "x": -4,
      "y": 14,
      "z": -2,
      "name": "Rock_Stone"
    },
    {
      "x": -4,
      "y": 15,
      "z": -2,
      "name": "Rock_Stone"
    },
    {
      "x": -4,
      "y": 16,
      "z": -2,
      "name": "Rock_Stone"
    },
    {
      "x": -4,
      "y": 17,
      "z": -2,
      "name": "Rock_Stone"
    },
    {
      "x": -4,
      "y": 18,
      "z": -2,
      "name": "Rock_Stone"
    },
    {
      "x": -4,
      "y": 19,
      "z": -2,
      "name": "Rock_Stone"
    },
    {
      "x": -4,
      "y": 20,
      "z": -2,
      "name": "Rock_Stone"
    },
    {
      "x": -4,
      "y": 21,
      "z": -2,
      "name": "Rock_Stone"
    },
    {
      "x": -4,
      "y": 22,
      "z": -2,
      "name": "Rock_Stone"
    },
    {
      "x": -4,
      "y": 23,
      "z": -2,
      "name": "Rock_Stone"
    },
    {
      "x": -4,
      "y": 24,
      "z": -2,
      "name": "Rock_Stone"
    },
    {
      "x": -4,
      "y": 25,
      "z": -2,
      "name": "Rock_Stone"
    },
    {
      "x": -4,
      "y": 11,
      "z": -1,
      "name": "Rock_Stone"
    },
    {
      "x": -4,
      "y": 12,
      "z": -1,
      "name": "Rock_Stone"
    },
    {
      "x": -4,
      "y": 13,
      "z": -1,
      "name": "Rock_Stone"
    },
    {
      "x": -4,
      "y": 14,
      "z": -1,
      "name": "Rock_Stone"
    },
    {
      "x": -4,
      "y": 15,
      "z": -1,
      "name": "Rock_Stone"
    },
    {
      "x": -4,
      "y": 16,
      "z": -1,
      "name": "Rock_Stone"
    },
    {
      "x": -4,
      "y": 17,
      "z": -1,
      "name": "Rock_Stone"
    },
    {
      "x": -4,
      "y": 18,
      "z": -1,
      "name": "Rock_Stone"
    },
    {
      "x": -4,
      "y": 19,
      "z": -1,
      "name": "Rock_Stone"
    },
    {
      "x": -4,
      "y": 20,
      "z": -1,
      "name": "Rock_Stone"
    },
    {
      "x": -4,
      "y": 21,
      "z": -1,
      "name": "Rock_Stone"
    },
    {
      "x": -4,
      "y": 22,
      "z": -1,
      "name": "Rock_Stone"
    },
    {
      "x": -4,
      "y": 23,
      "z": -1,
      "name": "Rock_Stone"
    },
    {
      "x": -4,
      "y": 24,
      "z": -1,
      "name": "Rock_Stone"
    },
    {
      "x": -4,
      "y": 25,
      "z": -1,
      "name": "Rock_Stone"
    },
    {
      "x": -4,
      "y": 11,
      "z": 0,
      "name": "Rock_Stone"
    },
    {
      "x": -4,
      "y": 12,
      "z": 0,
      "name": "Rock_Stone"
    },
    {
      "x": -4,
      "y": 13,
      "z": 0,
      "name": "Rock_Stone"
    },
    {
      "x": -4,
      "y": 14,
      "z": 0,
      "name": "Rock_Stone"
    },
    {
      "x": -4,
      "y": 15,
      "z": 0,
      "name": "Rock_Stone"
    },
    {
      "x": -4,
      "y": 16,
      "z": 0,
      "name": "Rock_Stone"
    },
    {
      "x": -4,
      "y": 17,
      "z": 0,
      "name": "Rock_Stone"
    },
    {
      "x": -4,
      "y": 18,
      "z": 0,
      "name": "Rock_Stone"
    },
    {
      "x": -4,
      "y": 19,
      "z": 0,
      "name": "Rock_Stone"
    },
    {
      "x": -4,
      "y": 20,
      "z": 0,
      "name": "Rock_Stone"
    },
    {
      "x": -4,
      "y": 21,
      "z": 0,
      "name": "Rock_Stone"
    },
    {
      "x": -4,
      "y": 22,
      "z": 0,
      "name": "Rock_Stone"
    },
    {
      "x": -4,
      "y": 23,
      "z": 0,
      "name": "Rock_Stone"
    },
    {
      "x": -4,
      "y": 24,
      "z": 0,
      "name": "Rock_Stone"
    },
    {
      "x": -4,
      "y": 25,
      "z": 0,
      "name": "Rock_Stone"
    },
    {
      "x": -4,
      "y": 11,
      "z": 1,
      "name": "Rock_Stone"
    },
    {
      "x": -4,
      "y": 12,
      "z": 1,
      "name": "Rock_Stone"
    },
    {
      "x": -4,
      "y": 13,
      "z": 1,
      "name": "Rock_Stone"
    },
    {
      "x": -4,
      "y": 14,
      "z": 1,
      "name": "Rock_Stone"
    },
    {
      "x": -4,
      "y": 15,
      "z": 1,
      "name": "Rock_Stone"
    },
    {
      "x": -4,
      "y": 16,
      "z": 1,
      "name": "Rock_Stone"
    },
    {
      "x": -4,
      "y": 17,
      "z": 1,
      "name": "Rock_Stone"
    },
    {
      "x": -4,
      "y": 18,
      "z": 1,
      "name": "Rock_Stone"
    },
    {
      "x": -4,
      "y": 19,
      "z": 1,
      "name": "Rock_Stone"
    },
    {
      "x": -4,
      "y": 20,
      "z": 1,
      "name": "Rock_Stone"
    },
    {
      "x": -4,
      "y": 21,
      "z": 1,
      "name": "Rock_Stone"
    },
    {
      "x": -4,
      "y": 22,
      "z": 1,
      "name": "Rock_Stone"
    },
    {
      "x": -4,
      "y": 23,
      "z": 1,
      "name": "Rock_Stone"
    },
    {
      "x": -4,
      "y": 24,
      "z": 1,
      "name": "Rock_Stone"
    },
    {
      "x": -4,
      "y": 25,
      "z": 1,
      "name": "Rock_Stone"
    },
    {
      "x": -4,
      "y": 11,
      "z": 2,
      "name": "Rock_Stone"
    },
    {
      "x": -4,
      "y": 12,
      "z": 2,
      "name": "Rock_Stone"
    },
    {
      "x": -4,
      "y": 13,
      "z": 2,
      "name": "Rock_Stone"
    },
    {
      "x": -4,
      "y": 14,
      "z": 2,
      "name": "Rock_Stone"
    },
    {
      "x": -4,
      "y": 15,
      "z": 2,
      "name": "Rock_Stone"
    },
    {
      "x": -4,
      "y": 16,
      "z": 2,
      "name": "Rock_Stone"
    },
    {
      "x": -4,
      "y": 17,
      "z": 2,
      "name": "Rock_Stone"
    },
    {
      "x": -4,
      "y": 18,
      "z": 2,
      "name": "Rock_Stone"
    },
    {
      "x": -4,
      "y": 19,
      "z": 2,
      "name": "Rock_Stone"
    },
    {
      "x": -4,
      "y": 20,
      "z": 2,
      "name": "Rock_Stone"
    },
    {
      "x": -4,
      "y": 21,
      "z": 2,
      "name": "Rock_Stone"
    },
    {
      "x": -4,
      "y": 22,
      "z": 2,
      "name": "Rock_Stone"
    },
    {
      "x": -4,
      "y": 23,
      "z": 2,
      "name": "Rock_Stone"
    },
    {
      "x": -4,
      "y": 24,
      "z": 2,
      "name": "Rock_Stone"
    },
    {
      "x": -4,
      "y": 25,
      "z": 2,
      "name": "Rock_Stone"
    },
    {
      "x": -4,
      "y": 11,
      "z": 3,
      "name": "Rock_Stone"
    },
    {
      "x": -4,
      "y": 12,
      "z": 3,
      "name": "Rock_Stone"
    },
    {
      "x": -4,
      "y": 13,
      "z": 3,
      "name": "Rock_Stone"
    },
    {
      "x": -4,
      "y": 14,
      "z": 3,
      "name": "Rock_Stone"
    },
    {
      "x": -4,
      "y": 15,
      "z": 3,
      "name": "Rock_Stone"
    },
    {
      "x": -4,
      "y": 16,
      "z": 3,
      "name": "Rock_Stone"
    },
    {
      "x": -4,
      "y": 17,
      "z": 3,
      "name": "Rock_Stone"
    },
    {
      "x": -4,
      "y": 18,
      "z": 3,
      "name": "Rock_Stone"
    },
    {
      "x": -4,
      "y": 19,
      "z": 3,
      "name": "Rock_Stone"
    },
    {
      "x": -4,
      "y": 20,
      "z": 3,
      "name": "Rock_Stone"
    },
    {
      "x": -4,
      "y": 21,
      "z": 3,
      "name": "Rock_Stone"
    },
    {
      "x": -4,
      "y": 22,
      "z": 3,
      "name": "Rock_Stone"
    },
    {
      "x": -4,
      "y": 23,
      "z": 3,
      "name": "Rock_Stone"
    },
    {
      "x": -4,
      "y": 24,
      "z": 3,
      "name": "Rock_Stone"
    },
    {
      "x": -4,
      "y": 25,
      "z": 3,
      "name": "Rock_Stone"
    },
    {
      "x": -4,
      "y": 11,
      "z": 4,
      "name": "Rock_Stone"
    },
    {
      "x": -4,
      "y": 12,
      "z": 4,
      "name": "Rock_Stone"
    },
    {
      "x": -4,
      "y": 13,
      "z": 4,
      "name": "Rock_Stone"
    },
    {
      "x": -4,
      "y": 14,
      "z": 4,
      "name": "Rock_Stone"
    },
    {
      "x": -4,
      "y": 15,
      "z": 4,
      "name": "Rock_Stone"
    },
    {
      "x": -4,
      "y": 16,
      "z": 4,
      "name": "Rock_Stone"
    },
    {
      "x": -4,
      "y": 17,
      "z": 4,
      "name": "Rock_Stone"
    },
    {
      "x": -4,
      "y": 18,
      "z": 4,
      "name": "Rock_Stone"
    },
    {
      "x": -4,
      "y": 19,
      "z": 4,
      "name": "Rock_Stone"
    },
    {
      "x": -4,
      "y": 20,
      "z": 4,
      "name": "Rock_Stone"
    },
    {
      "x": -4,
      "y": 21,
      "z": 4,
      "name": "Rock_Stone"
    },
    {
      "x": -4,
      "y": 22,
      "z": 4,
      "name": "Rock_Stone"
    },
    {
      "x": -4,
      "y": 23,
      "z": 4,
      "name": "Rock_Stone"
    },
    {
      "x": -4,
      "y": 24,
      "z": 4,
      "name": "Rock_Stone"
    },
    {
      "x": -4,
      "y": 25,
      "z": 4,
      "name": "Rock_Stone"
    },
    {
      "x": -3,
      "y": 11,
      "z": -4,
      "name": "Rock_Stone"
    },
    {
      "x": -3,
      "y": 12,
      "z": -4,
      "name": "Rock_Stone"
    },
    {
      "x": -3,
      "y": 13,
      "z": -4,
      "name": "Rock_Stone"
    },
    {
      "x": -3,
      "y": 14,
      "z": -4,
      "name": "Rock_Stone"
    },
    {
      "x": -3,
      "y": 15,
      "z": -4,
      "name": "Rock_Stone"
    },
    {
      "x": -3,
      "y": 16,
      "z": -4,
      "name": "Rock_Stone"
    },
    {
      "x": -3,
      "y": 17,
      "z": -4,
      "name": "Rock_Stone"
    },
    {
      "x": -3,
      "y": 18,
      "z": -4,
      "name": "Rock_Stone"
    },
    {
      "x": -3,
      "y": 19,
      "z": -4,
      "name": "Rock_Stone"
    },
    {
      "x": -3,
      "y": 20,
      "z": -4,
      "name": "Rock_Stone"
    },
    {
      "x": -3,
      "y": 21,
      "z": -4,
      "name": "Rock_Stone"
    },
    {
      "x": -3,
      "y": 22,
      "z": -4,
      "name": "Rock_Stone"
    },
    {
      "x": -3,
      "y": 23,
      "z": -4,
      "name": "Rock_Stone"
    },
    {
      "x": -3,
      "y": 24,
      "z": -4,
      "name": "Rock_Stone"
    },
    {
      "x": -3,
      "y": 25,
      "z": -4,
      "name": "Rock_Stone"
    },
    {
      "x": -3,
      "y": 11,
      "z": -3,
      "name": "Rock_Stone"
    },
    {
      "x": -3,
      "y": 12,
      "z": -3,
      "name": "Rock_Stone"
    },
    {
      "x": -3,
      "y": 13,
      "z": -3,
      "name": "Rock_Stone"
    },
    {
      "x": -3,
      "y": 14,
      "z": -3,
      "name": "Rock_Stone"
    },
    {
      "x": -3,
      "y": 15,
      "z": -3,
      "name": "Rock_Stone"
    },
    {
      "x": -3,
      "y": 16,
      "z": -3,
      "name": "Rock_Stone"
    },
    {
      "x": -3,
      "y": 17,
      "z": -3,
      "name": "Rock_Stone"
    },
    {
      "x": -3,
      "y": 18,
      "z": -3,
      "name": "Rock_Stone"
    },
    {
      "x": -3,
      "y": 19,
      "z": -3,
      "name": "Rock_Stone"
    },
    {
      "x": -3,
      "y": 20,
      "z": -3,
      "name": "Rock_Stone"
    },
    {
      "x": -3,
      "y": 21,
      "z": -3,
      "name": "Rock_Stone"
    },
    {
      "x": -3,
      "y": 22,
      "z": -3,
      "name": "Rock_Stone"
    },
    {
      "x": -3,
      "y": 23,
      "z": -3,
      "name": "Rock_Stone"
    },
    {
      "x": -3,
      "y": 24,
      "z": -3,
      "name": "Rock_Stone"
    },
    {
      "x": -3,
      "y": 25,
      "z": -3,
      "name": "Rock_Stone"
    },
    {
      "x": -3,
      "y": 11,
      "z": -2,
      "name": "Rock_Stone"
    },
    {
      "x": -3,
      "y": 12,
      "z": -2,
      "name": "Rock_Stone"
    },
    {
      "x": -3,
      "y": 13,
      "z": -2,
      "name": "Rock_Stone"
    },
    {
      "x": -3,
      "y": 14,
      "z": -2,
      "name": "Rock_Stone"
    },
    {
      "x": -3,
      "y": 15,
      "z": -2,
      "name": "Rock_Stone"
    },
    {
      "x": -3,
      "y": 16,
      "z": -2,
      "name": "Rock_Stone"
    },
    {
      "x": -3,
      "y": 17,
      "z": -2,
      "name": "Rock_Stone"
    },
    {
      "x": -3,
      "y": 18,
      "z": -2,
      "name": "Rock_Stone"
    },
    {
      "x": -3,
      "y": 19,
      "z": -2,
      "name": "Rock_Stone"
    },
    {
      "x": -3,
      "y": 20,
      "z": -2,
      "name": "Rock_Stone"
    },
    {
      "x": -3,
      "y": 21,
      "z": -2,
      "name": "Rock_Stone"
    },
    {
      "x": -3,
      "y": 22,
      "z": -2,
      "name": "Rock_Stone"
    },
    {
      "x": -3,
      "y": 23,
      "z": -2,
      "name": "Rock_Stone"
    },
    {
      "x": -3,
      "y": 24,
      "z": -2,
      "name": "Rock_Stone"
    },
    {
      "x": -3,
      "y": 25,
      "z": -2,
      "name": "Rock_Stone"
    },
    {
      "x": -3,
      "y": 11,
      "z": -1,
      "name": "Rock_Stone"
    },
    {
      "x": -3,
      "y": 12,
      "z": -1,
      "name": "Rock_Stone"
    },
    {
      "x": -3,
      "y": 13,
      "z": -1,
      "name": "Rock_Stone"
    },
    {
      "x": -3,
      "y": 14,
      "z": -1,
      "name": "Rock_Stone"
    },
    {
      "x": -3,
      "y": 15,
      "z": -1,
      "name": "Rock_Stone"
    },
    {
      "x": -3,
      "y": 16,
      "z": -1,
      "name": "Rock_Stone"
    },
    {
      "x": -3,
      "y": 17,
      "z": -1,
      "name": "Rock_Stone"
    },
    {
      "x": -3,
      "y": 18,
      "z": -1,
      "name": "Rock_Stone"
    },
    {
      "x": -3,
      "y": 19,
      "z": -1,
      "name": "Rock_Stone"
    },
    {
      "x": -3,
      "y": 20,
      "z": -1,
      "name": "Rock_Stone"
    },
    {
      "x": -3,
      "y": 21,
      "z": -1,
      "name": "Rock_Stone"
    },
    {
      "x": -3,
      "y": 22,
      "z": -1,
      "name": "Rock_Stone"
    },
    {
      "x": -3,
      "y": 23,
      "z": -1,
      "name": "Rock_Stone"
    },
    {
      "x": -3,
      "y": 24,
      "z": -1,
      "name": "Rock_Stone"
    },
    {
      "x": -3,
      "y": 25,
      "z": -1,
      "name": "Rock_Stone"
    },
    {
      "x": -3,
      "y": 11,
      "z": 0,
      "name": "Rock_Stone"
    },
    {
      "x": -3,
      "y": 12,
      "z": 0,
      "name": "Rock_Stone"
    },
    {
      "x": -3,
      "y": 13,
      "z": 0,
      "name": "Rock_Stone"
    },
    {
      "x": -3,
      "y": 14,
      "z": 0,
      "name": "Rock_Stone"
    },
    {
      "x": -3,
      "y": 15,
      "z": 0,
      "name": "Rock_Stone"
    },
    {
      "x": -3,
      "y": 16,
      "z": 0,
      "name": "Rock_Stone"
    },
    {
      "x": -3,
      "y": 17,
      "z": 0,
      "name": "Rock_Stone"
    },
    {
      "x": -3,
      "y": 18,
      "z": 0,
      "name": "Rock_Stone"
    },
    {
      "x": -3,
      "y": 19,
      "z": 0,
      "name": "Rock_Stone"
    },
    {
      "x": -3,
      "y": 20,
      "z": 0,
      "name": "Rock_Stone"
    },
    {
      "x": -3,
      "y": 21,
      "z": 0,
      "name": "Rock_Stone"
    },
    {
      "x": -3,
      "y": 22,
      "z": 0,
      "name": "Rock_Stone"
    },
    {
      "x": -3,
      "y": 23,
      "z": 0,
      "name": "Rock_Stone"
    },
    {
      "x": -3,
      "y": 24,
      "z": 0,
      "name": "Rock_Stone"
    },
    {
      "x": -3,
      "y": 25,
      "z": 0,
      "name": "Rock_Stone"
    },
    {
      "x": -3,
      "y": 11,
      "z": 1,
      "name": "Rock_Stone"
    },
    {
      "x": -3,
      "y": 12,
      "z": 1,
      "name": "Rock_Stone"
    },
    {
      "x": -3,
      "y": 13,
      "z": 1,
      "name": "Rock_Stone"
    },
    {
      "x": -3,
      "y": 14,
      "z": 1,
      "name": "Rock_Stone"
    },
    {
      "x": -3,
      "y": 15,
      "z": 1,
      "name": "Rock_Stone"
    },
    {
      "x": -3,
      "y": 16,
      "z": 1,
      "name": "Rock_Stone"
    },
    {
      "x": -3,
      "y": 17,
      "z": 1,
      "name": "Rock_Stone"
    },
    {
      "x": -3,
      "y": 18,
      "z": 1,
      "name": "Rock_Stone"
    },
    {
      "x": -3,
      "y": 19,
      "z": 1,
      "name": "Rock_Stone"
    },
    {
      "x": -3,
      "y": 20,
      "z": 1,
      "name": "Rock_Stone"
    },
    {
      "x": -3,
      "y": 21,
      "z": 1,
      "name": "Rock_Stone"
    },
    {
      "x": -3,
      "y": 22,
      "z": 1,
      "name": "Rock_Stone"
    },
    {
      "x": -3,
      "y": 23,
      "z": 1,
      "name": "Rock_Stone"
    },
    {
      "x": -3,
      "y": 24,
      "z": 1,
      "name": "Rock_Stone"
    },
    {
      "x": -3,
      "y": 25,
      "z": 1,
      "name": "Rock_Stone"
    },
    {
      "x": -3,
      "y": 11,
      "z": 2,
      "name": "Rock_Stone"
    },
    {
      "x": -3,
      "y": 12,
      "z": 2,
      "name": "Rock_Stone"
    },
    {
      "x": -3,
      "y": 13,
      "z": 2,
      "name": "Rock_Stone"
    },
    {
      "x": -3,
      "y": 14,
      "z": 2,
      "name": "Rock_Stone"
    },
    {
      "x": -3,
      "y": 15,
      "z": 2,
      "name": "Rock_Stone"
    },
    {
      "x": -3,
      "y": 16,
      "z": 2,
      "name": "Rock_Stone"
    },
    {
      "x": -3,
      "y": 17,
      "z": 2,
      "name": "Rock_Stone"
    },
    {
      "x": -3,
      "y": 18,
      "z": 2,
      "name": "Rock_Stone"
    },
    {
      "x": -3,
      "y": 19,
      "z": 2,
      "name": "Rock_Stone"
    },
    {
      "x": -3,
      "y": 20,
      "z": 2,
      "name": "Rock_Stone"
    },
    {
      "x": -3,
      "y": 21,
      "z": 2,
      "name": "Rock_Stone"
    },
    {
      "x": -3,
      "y": 22,
      "z": 2,
      "name": "Rock_Stone"
    },
    {
      "x": -3,
      "y": 23,
      "z": 2,
      "name": "Rock_Stone"
    },
    {
      "x": -3,
      "y": 24,
      "z": 2,
      "name": "Rock_Stone"
    },
    {
      "x": -3,
      "y": 25,
      "z": 2,
      "name": "Rock_Stone"
    },
    {
      "x": -3,
      "y": 11,
      "z": 3,
      "name": "Rock_Stone"
    },
    {
      "x": -3,
      "y": 12,
      "z": 3,
      "name": "Rock_Stone"
    },
    {
      "x": -3,
      "y": 13,
      "z": 3,
      "name": "Rock_Stone"
    },
    {
      "x": -3,
      "y": 14,
      "z": 3,
      "name": "Rock_Stone"
    },
    {
      "x": -3,
      "y": 15,
      "z": 3,
      "name": "Rock_Stone"
    },
    {
      "x": -3,
      "y": 16,
      "z": 3,
      "name": "Rock_Stone"
    },
    {
      "x": -3,
      "y": 17,
      "z": 3,
      "name": "Rock_Stone"
    },
    {
      "x": -3,
      "y": 18,
      "z": 3,
      "name": "Rock_Stone"
    },
    {
      "x": -3,
      "y": 19,
      "z": 3,
      "name": "Rock_Stone"
    },
    {
      "x": -3,
      "y": 20,
      "z": 3,
      "name": "Rock_Stone"
    },
    {
      "x": -3,
      "y": 21,
      "z": 3,
      "name": "Rock_Stone"
    },
    {
      "x": -3,
      "y": 22,
      "z": 3,
      "name": "Rock_Stone"
    },
    {
      "x": -3,
      "y": 23,
      "z": 3,
      "name": "Rock_Stone"
    },
    {
      "x": -3,
      "y": 24,
      "z": 3,
      "name": "Rock_Stone"
    },
    {
      "x": -3,
      "y": 25,
      "z": 3,
      "name": "Rock_Stone"
    },
    {
      "x": -3,
      "y": 26,
      "z": 3,
      "name": "Block_Spawner_Block",
      "components": {
        "Components": {
          "BlockSpawner": {
            "BlockSpawnerId": "Zone3_Encounters_Tier3"
          }
        }
      },
      "rotation": 2
    },
    {
      "x": -3,
      "y": 11,
      "z": 4,
      "name": "Rock_Stone"
    },
    {
      "x": -3,
      "y": 12,
      "z": 4,
      "name": "Rock_Stone"
    },
    {
      "x": -3,
      "y": 13,
      "z": 4,
      "name": "Rock_Stone"
    },
    {
      "x": -3,
      "y": 14,
      "z": 4,
      "name": "Rock_Stone"
    },
    {
      "x": -3,
      "y": 15,
      "z": 4,
      "name": "Rock_Stone"
    },
    {
      "x": -3,
      "y": 16,
      "z": 4,
      "name": "Rock_Stone"
    },
    {
      "x": -3,
      "y": 17,
      "z": 4,
      "name": "Rock_Stone"
    },
    {
      "x": -3,
      "y": 18,
      "z": 4,
      "name": "Rock_Stone"
    },
    {
      "x": -3,
      "y": 19,
      "z": 4,
      "name": "Rock_Stone"
    },
    {
      "x": -3,
      "y": 20,
      "z": 4,
      "name": "Rock_Stone"
    },
    {
      "x": -3,
      "y": 21,
      "z": 4,
      "name": "Rock_Stone"
    },
    {
      "x": -3,
      "y": 22,
      "z": 4,
      "name": "Rock_Stone"
    },
    {
      "x": -3,
      "y": 23,
      "z": 4,
      "name": "Rock_Stone"
    },
    {
      "x": -3,
      "y": 24,
      "z": 4,
      "name": "Rock_Stone"
    },
    {
      "x": -3,
      "y": 25,
      "z": 4,
      "name": "Rock_Stone"
    },
    {
      "x": -2,
      "y": 11,
      "z": -4,
      "name": "Rock_Stone"
    },
    {
      "x": -2,
      "y": 12,
      "z": -4,
      "name": "Rock_Stone"
    },
    {
      "x": -2,
      "y": 13,
      "z": -4,
      "name": "Rock_Stone"
    },
    {
      "x": -2,
      "y": 14,
      "z": -4,
      "name": "Rock_Stone"
    },
    {
      "x": -2,
      "y": 15,
      "z": -4,
      "name": "Rock_Stone"
    },
    {
      "x": -2,
      "y": 16,
      "z": -4,
      "name": "Rock_Stone"
    },
    {
      "x": -2,
      "y": 17,
      "z": -4,
      "name": "Rock_Stone"
    },
    {
      "x": -2,
      "y": 18,
      "z": -4,
      "name": "Rock_Stone"
    },
    {
      "x": -2,
      "y": 19,
      "z": -4,
      "name": "Rock_Stone"
    },
    {
      "x": -2,
      "y": 20,
      "z": -4,
      "name": "Rock_Stone"
    },
    {
      "x": -2,
      "y": 21,
      "z": -4,
      "name": "Rock_Stone"
    },
    {
      "x": -2,
      "y": 22,
      "z": -4,
      "name": "Rock_Stone"
    },
    {
      "x": -2,
      "y": 23,
      "z": -4,
      "name": "Rock_Stone"
    },
    {
      "x": -2,
      "y": 24,
      "z": -4,
      "name": "Rock_Stone"
    },
    {
      "x": -2,
      "y": 25,
      "z": -4,
      "name": "Rock_Stone"
    },
    {
      "x": -2,
      "y": 11,
      "z": -3,
      "name": "Rock_Stone"
    },
    {
      "x": -2,
      "y": 12,
      "z": -3,
      "name": "Rock_Stone"
    },
    {
      "x": -2,
      "y": 13,
      "z": -3,
      "name": "Rock_Stone"
    },
    {
      "x": -2,
      "y": 14,
      "z": -3,
      "name": "Rock_Stone"
    },
    {
      "x": -2,
      "y": 15,
      "z": -3,
      "name": "Rock_Stone"
    },
    {
      "x": -2,
      "y": 16,
      "z": -3,
      "name": "Rock_Stone"
    },
    {
      "x": -2,
      "y": 17,
      "z": -3,
      "name": "Rock_Stone"
    },
    {
      "x": -2,
      "y": 18,
      "z": -3,
      "name": "Rock_Stone"
    },
    {
      "x": -2,
      "y": 19,
      "z": -3,
      "name": "Rock_Stone"
    },
    {
      "x": -2,
      "y": 20,
      "z": -3,
      "name": "Rock_Stone"
    },
    {
      "x": -2,
      "y": 21,
      "z": -3,
      "name": "Rock_Stone"
    },
    {
      "x": -2,
      "y": 22,
      "z": -3,
      "name": "Rock_Stone"
    },
    {
      "x": -2,
      "y": 23,
      "z": -3,
      "name": "Rock_Stone"
    },
    {
      "x": -2,
      "y": 24,
      "z": -3,
      "name": "Rock_Stone"
    },
    {
      "x": -2,
      "y": 25,
      "z": -3,
      "name": "Rock_Stone"
    },
    {
      "x": -2,
      "y": 11,
      "z": -2,
      "name": "Rock_Stone"
    },
    {
      "x": -2,
      "y": 12,
      "z": -2,
      "name": "Rock_Stone"
    },
    {
      "x": -2,
      "y": 13,
      "z": -2,
      "name": "Rock_Stone"
    },
    {
      "x": -2,
      "y": 14,
      "z": -2,
      "name": "Rock_Stone"
    },
    {
      "x": -2,
      "y": 15,
      "z": -2,
      "name": "Rock_Stone"
    },
    {
      "x": -2,
      "y": 16,
      "z": -2,
      "name": "Rock_Stone"
    },
    {
      "x": -2,
      "y": 17,
      "z": -2,
      "name": "Rock_Stone"
    },
    {
      "x": -2,
      "y": 18,
      "z": -2,
      "name": "Rock_Stone"
    },
    {
      "x": -2,
      "y": 19,
      "z": -2,
      "name": "Rock_Stone"
    },
    {
      "x": -2,
      "y": 20,
      "z": -2,
      "name": "Rock_Stone"
    },
    {
      "x": -2,
      "y": 21,
      "z": -2,
      "name": "Rock_Stone"
    },
    {
      "x": -2,
      "y": 22,
      "z": -2,
      "name": "Rock_Stone"
    },
    {
      "x": -2,
      "y": 23,
      "z": -2,
      "name": "Rock_Stone"
    },
    {
      "x": -2,
      "y": 24,
      "z": -2,
      "name": "Rock_Stone"
    },
    {
      "x": -2,
      "y": 25,
      "z": -2,
      "name": "Rock_Stone"
    },
    {
      "x": -2,
      "y": 11,
      "z": -1,
      "name": "Rock_Stone"
    },
    {
      "x": -2,
      "y": 12,
      "z": -1,
      "name": "Rock_Stone"
    },
    {
      "x": -2,
      "y": 13,
      "z": -1,
      "name": "Rock_Stone"
    },
    {
      "x": -2,
      "y": 14,
      "z": -1,
      "name": "Rock_Stone"
    },
    {
      "x": -2,
      "y": 15,
      "z": -1,
      "name": "Rock_Stone"
    },
    {
      "x": -2,
      "y": 16,
      "z": -1,
      "name": "Rock_Stone"
    },
    {
      "x": -2,
      "y": 17,
      "z": -1,
      "name": "Rock_Stone"
    },
    {
      "x": -2,
      "y": 18,
      "z": -1,
      "name": "Rock_Stone"
    },
    {
      "x": -2,
      "y": 19,
      "z": -1,
      "name": "Rock_Stone"
    },
    {
      "x": -2,
      "y": 20,
      "z": -1,
      "name": "Rock_Stone"
    },
    {
      "x": -2,
      "y": 21,
      "z": -1,
      "name": "Rock_Stone"
    },
    {
      "x": -2,
      "y": 22,
      "z": -1,
      "name": "Rock_Stone"
    },
    {
      "x": -2,
      "y": 23,
      "z": -1,
      "name": "Rock_Stone"
    },
    {
      "x": -2,
      "y": 24,
      "z": -1,
      "name": "Rock_Stone"
    },
    {
      "x": -2,
      "y": 25,
      "z": -1,
      "name": "Rock_Stone"
    },
    {
      "x": -2,
      "y": 11,
      "z": 0,
      "name": "Rock_Stone"
    },
    {
      "x": -2,
      "y": 12,
      "z": 0,
      "name": "Rock_Stone"
    },
    {
      "x": -2,
      "y": 13,
      "z": 0,
      "name": "Rock_Stone"
    },
    {
      "x": -2,
      "y": 14,
      "z": 0,
      "name": "Rock_Stone"
    },
    {
      "x": -2,
      "y": 15,
      "z": 0,
      "name": "Rock_Stone"
    },
    {
      "x": -2,
      "y": 16,
      "z": 0,
      "name": "Rock_Stone"
    },
    {
      "x": -2,
      "y": 17,
      "z": 0,
      "name": "Rock_Stone"
    },
    {
      "x": -2,
      "y": 18,
      "z": 0,
      "name": "Rock_Stone"
    },
    {
      "x": -2,
      "y": 19,
      "z": 0,
      "name": "Rock_Stone"
    },
    {
      "x": -2,
      "y": 20,
      "z": 0,
      "name": "Rock_Stone"
    },
    {
      "x": -2,
      "y": 21,
      "z": 0,
      "name": "Rock_Stone"
    },
    {
      "x": -2,
      "y": 22,
      "z": 0,
      "name": "Rock_Stone"
    },
    {
      "x": -2,
      "y": 23,
      "z": 0,
      "name": "Rock_Stone"
    },
    {
      "x": -2,
      "y": 24,
      "z": 0,
      "name": "Rock_Stone"
    },
    {
      "x": -2,
      "y": 25,
      "z": 0,
      "name": "Rock_Stone"
    },
    {
      "x": -2,
      "y": 11,
      "z": 1,
      "name": "Rock_Stone"
    },
    {
      "x": -2,
      "y": 12,
      "z": 1,
      "name": "Rock_Stone"
    },
    {
      "x": -2,
      "y": 13,
      "z": 1,
      "name": "Rock_Stone"
    },
    {
      "x": -2,
      "y": 14,
      "z": 1,
      "name": "Rock_Stone"
    },
    {
      "x": -2,
      "y": 15,
      "z": 1,
      "name": "Rock_Stone"
    },
    {
      "x": -2,
      "y": 16,
      "z": 1,
      "name": "Rock_Stone"
    },
    {
      "x": -2,
      "y": 17,
      "z": 1,
      "name": "Rock_Stone"
    },
    {
      "x": -2,
      "y": 18,
      "z": 1,
      "name": "Rock_Stone"
    },
    {
      "x": -2,
      "y": 19,
      "z": 1,
      "name": "Rock_Stone"
    },
    {
      "x": -2,
      "y": 20,
      "z": 1,
      "name": "Rock_Stone"
    },
    {
      "x": -2,
      "y": 21,
      "z": 1,
      "name": "Rock_Stone"
    },
    {
      "x": -2,
      "y": 22,
      "z": 1,
      "name": "Rock_Stone"
    },
    {
      "x": -2,
      "y": 23,
      "z": 1,
      "name": "Rock_Stone"
    },
    {
      "x": -2,
      "y": 24,
      "z": 1,
      "name": "Rock_Stone"
    },
    {
      "x": -2,
      "y": 25,
      "z": 1,
      "name": "Rock_Stone"
    },
    {
      "x": -2,
      "y": 11,
      "z": 2,
      "name": "Rock_Stone"
    },
    {
      "x": -2,
      "y": 12,
      "z": 2,
      "name": "Rock_Stone"
    },
    {
      "x": -2,
      "y": 13,
      "z": 2,
      "name": "Rock_Stone"
    },
    {
      "x": -2,
      "y": 14,
      "z": 2,
      "name": "Rock_Stone"
    },
    {
      "x": -2,
      "y": 15,
      "z": 2,
      "name": "Rock_Stone"
    },
    {
      "x": -2,
      "y": 16,
      "z": 2,
      "name": "Rock_Stone"
    },
    {
      "x": -2,
      "y": 17,
      "z": 2,
      "name": "Rock_Stone"
    },
    {
      "x": -2,
      "y": 18,
      "z": 2,
      "name": "Rock_Stone"
    },
    {
      "x": -2,
      "y": 19,
      "z": 2,
      "name": "Rock_Stone"
    },
    {
      "x": -2,
      "y": 20,
      "z": 2,
      "name": "Rock_Stone"
    },
    {
      "x": -2,
      "y": 21,
      "z": 2,
      "name": "Rock_Stone"
    },
    {
      "x": -2,
      "y": 22,
      "z": 2,
      "name": "Rock_Stone"
    },
    {
      "x": -2,
      "y": 23,
      "z": 2,
      "name": "Rock_Stone"
    },
    {
      "x": -2,
      "y": 24,
      "z": 2,
      "name": "Rock_Stone"
    },
    {
      "x": -2,
      "y": 25,
      "z": 2,
      "name": "Rock_Stone"
    },
    {
      "x": -2,
      "y": 11,
      "z": 3,
      "name": "Rock_Stone"
    },
    {
      "x": -2,
      "y": 12,
      "z": 3,
      "name": "Rock_Stone"
    },
    {
      "x": -2,
      "y": 13,
      "z": 3,
      "name": "Rock_Stone"
    },
    {
      "x": -2,
      "y": 14,
      "z": 3,
      "name": "Rock_Stone"
    },
    {
      "x": -2,
      "y": 15,
      "z": 3,
      "name": "Rock_Stone"
    },
    {
      "x": -2,
      "y": 16,
      "z": 3,
      "name": "Rock_Stone"
    },
    {
      "x": -2,
      "y": 17,
      "z": 3,
      "name": "Rock_Stone"
    },
    {
      "x": -2,
      "y": 18,
      "z": 3,
      "name": "Rock_Stone"
    },
    {
      "x": -2,
      "y": 19,
      "z": 3,
      "name": "Rock_Stone"
    },
    {
      "x": -2,
      "y": 20,
      "z": 3,
      "name": "Rock_Stone"
    },
    {
      "x": -2,
      "y": 21,
      "z": 3,
      "name": "Rock_Stone"
    },
    {
      "x": -2,
      "y": 22,
      "z": 3,
      "name": "Rock_Stone"
    },
    {
      "x": -2,
      "y": 23,
      "z": 3,
      "name": "Rock_Stone"
    },
    {
      "x": -2,
      "y": 24,
      "z": 3,
      "name": "Rock_Stone"
    },
    {
      "x": -2,
      "y": 25,
      "z": 3,
      "name": "Rock_Stone"
    },
    {
      "x": -2,
      "y": 11,
      "z": 4,
      "name": "Rock_Stone"
    },
    {
      "x": -2,
      "y": 12,
      "z": 4,
      "name": "Rock_Stone"
    },
    {
      "x": -2,
      "y": 13,
      "z": 4,
      "name": "Rock_Stone"
    },
    {
      "x": -2,
      "y": 14,
      "z": 4,
      "name": "Rock_Stone"
    },
    {
      "x": -2,
      "y": 15,
      "z": 4,
      "name": "Rock_Stone"
    },
    {
      "x": -2,
      "y": 16,
      "z": 4,
      "name": "Rock_Stone"
    },
    {
      "x": -2,
      "y": 17,
      "z": 4,
      "name": "Rock_Stone"
    },
    {
      "x": -2,
      "y": 18,
      "z": 4,
      "name": "Rock_Stone"
    },
    {
      "x": -2,
      "y": 19,
      "z": 4,
      "name": "Rock_Stone"
    },
    {
      "x": -2,
      "y": 20,
      "z": 4,
      "name": "Rock_Stone"
    },
    {
      "x": -2,
      "y": 21,
      "z": 4,
      "name": "Rock_Stone"
    },
    {
      "x": -2,
      "y": 22,
      "z": 4,
      "name": "Rock_Stone"
    },
    {
      "x": -2,
      "y": 23,
      "z": 4,
      "name": "Rock_Stone"
    },
    {
      "x": -2,
      "y": 24,
      "z": 4,
      "name": "Rock_Stone"
    },
    {
      "x": -2,
      "y": 25,
      "z": 4,
      "name": "Rock_Stone"
    },
    {
      "x": -1,
      "y": 11,
      "z": -4,
      "name": "Rock_Stone"
    },
    {
      "x": -1,
      "y": 12,
      "z": -4,
      "name": "Rock_Stone"
    },
    {
      "x": -1,
      "y": 13,
      "z": -4,
      "name": "Rock_Stone"
    },
    {
      "x": -1,
      "y": 14,
      "z": -4,
      "name": "Rock_Stone"
    },
    {
      "x": -1,
      "y": 15,
      "z": -4,
      "name": "Rock_Stone"
    },
    {
      "x": -1,
      "y": 16,
      "z": -4,
      "name": "Rock_Stone"
    },
    {
      "x": -1,
      "y": 17,
      "z": -4,
      "name": "Rock_Stone"
    },
    {
      "x": -1,
      "y": 18,
      "z": -4,
      "name": "Rock_Stone"
    },
    {
      "x": -1,
      "y": 19,
      "z": -4,
      "name": "Rock_Stone"
    },
    {
      "x": -1,
      "y": 20,
      "z": -4,
      "name": "Rock_Stone"
    },
    {
      "x": -1,
      "y": 21,
      "z": -4,
      "name": "Rock_Stone"
    },
    {
      "x": -1,
      "y": 22,
      "z": -4,
      "name": "Rock_Stone"
    },
    {
      "x": -1,
      "y": 23,
      "z": -4,
      "name": "Rock_Stone"
    },
    {
      "x": -1,
      "y": 24,
      "z": -4,
      "name": "Rock_Stone"
    },
    {
      "x": -1,
      "y": 25,
      "z": -4,
      "name": "Rock_Stone"
    },
    {
      "x": -1,
      "y": 11,
      "z": -3,
      "name": "Rock_Stone"
    },
    {
      "x": -1,
      "y": 12,
      "z": -3,
      "name": "Rock_Stone"
    },
    {
      "x": -1,
      "y": 13,
      "z": -3,
      "name": "Rock_Stone"
    },
    {
      "x": -1,
      "y": 14,
      "z": -3,
      "name": "Rock_Stone"
    },
    {
      "x": -1,
      "y": 15,
      "z": -3,
      "name": "Rock_Stone"
    },
    {
      "x": -1,
      "y": 16,
      "z": -3,
      "name": "Rock_Stone"
    },
    {
      "x": -1,
      "y": 17,
      "z": -3,
      "name": "Rock_Stone"
    },
    {
      "x": -1,
      "y": 18,
      "z": -3,
      "name": "Rock_Stone"
    },
    {
      "x": -1,
      "y": 19,
      "z": -3,
      "name": "Rock_Stone"
    },
    {
      "x": -1,
      "y": 20,
      "z": -3,
      "name": "Rock_Stone"
    },
    {
      "x": -1,
      "y": 21,
      "z": -3,
      "name": "Rock_Stone"
    },
    {
      "x": -1,
      "y": 22,
      "z": -3,
      "name": "Rock_Stone"
    },
    {
      "x": -1,
      "y": 23,
      "z": -3,
      "name": "Rock_Stone"
    },
    {
      "x": -1,
      "y": 24,
      "z": -3,
      "name": "Rock_Stone"
    },
    {
      "x": -1,
      "y": 25,
      "z": -3,
      "name": "Rock_Stone"
    },
    {
      "x": -1,
      "y": 11,
      "z": -2,
      "name": "Rock_Stone"
    },
    {
      "x": -1,
      "y": 12,
      "z": -2,
      "name": "Rock_Stone"
    },
    {
      "x": -1,
      "y": 13,
      "z": -2,
      "name": "Rock_Stone"
    },
    {
      "x": -1,
      "y": 14,
      "z": -2,
      "name": "Rock_Stone"
    },
    {
      "x": -1,
      "y": 15,
      "z": -2,
      "name": "Rock_Stone"
    },
    {
      "x": -1,
      "y": 16,
      "z": -2,
      "name": "Rock_Stone"
    },
    {
      "x": -1,
      "y": 17,
      "z": -2,
      "name": "Rock_Stone"
    },
    {
      "x": -1,
      "y": 18,
      "z": -2,
      "name": "Rock_Stone"
    },
    {
      "x": -1,
      "y": 19,
      "z": -2,
      "name": "Rock_Stone"
    },
    {
      "x": -1,
      "y": 20,
      "z": -2,
      "name": "Rock_Stone"
    },
    {
      "x": -1,
      "y": 21,
      "z": -2,
      "name": "Rock_Stone"
    },
    {
      "x": -1,
      "y": 22,
      "z": -2,
      "name": "Rock_Stone"
    },
    {
      "x": -1,
      "y": 23,
      "z": -2,
      "name": "Rock_Stone"
    },
    {
      "x": -1,
      "y": 24,
      "z": -2,
      "name": "Rock_Stone"
    },
    {
      "x": -1,
      "y": 25,
      "z": -2,
      "name": "Rock_Stone"
    },
    {
      "x": -1,
      "y": 11,
      "z": -1,
      "name": "Rock_Stone"
    },
    {
      "x": -1,
      "y": 12,
      "z": -1,
      "name": "Rock_Stone"
    },
    {
      "x": -1,
      "y": 13,
      "z": -1,
      "name": "Rock_Stone"
    },
    {
      "x": -1,
      "y": 14,
      "z": -1,
      "name": "Rock_Stone"
    },
    {
      "x": -1,
      "y": 15,
      "z": -1,
      "name": "Rock_Stone"
    },
    {
      "x": -1,
      "y": 16,
      "z": -1,
      "name": "Rock_Stone"
    },
    {
      "x": -1,
      "y": 17,
      "z": -1,
      "name": "Rock_Stone"
    },
    {
      "x": -1,
      "y": 18,
      "z": -1,
      "name": "Rock_Stone"
    },
    {
      "x": -1,
      "y": 19,
      "z": -1,
      "name": "Rock_Stone"
    },
    {
      "x": -1,
      "y": 20,
      "z": -1,
      "name": "Rock_Stone"
    },
    {
      "x": -1,
      "y": 21,
      "z": -1,
      "name": "Rock_Stone"
    },
    {
      "x": -1,
      "y": 22,
      "z": -1,
      "name": "Rock_Stone"
    },
    {
      "x": -1,
      "y": 23,
      "z": -1,
      "name": "Rock_Stone"
    },
    {
      "x": -1,
      "y": 24,
      "z": -1,
      "name": "Rock_Stone"
    },
    {
      "x": -1,
      "y": 25,
      "z": -1,
      "name": "Rock_Stone"
    },
    {
      "x": -1,
      "y": 11,
      "z": 0,
      "name": "Rock_Stone"
    },
    {
      "x": -1,
      "y": 12,
      "z": 0,
      "name": "Rock_Stone"
    },
    {
      "x": -1,
      "y": 13,
      "z": 0,
      "name": "Rock_Stone"
    },
    {
      "x": -1,
      "y": 14,
      "z": 0,
      "name": "Rock_Stone"
    },
    {
      "x": -1,
      "y": 15,
      "z": 0,
      "name": "Rock_Stone"
    },
    {
      "x": -1,
      "y": 16,
      "z": 0,
      "name": "Rock_Stone"
    },
    {
      "x": -1,
      "y": 17,
      "z": 0,
      "name": "Rock_Stone"
    },
    {
      "x": -1,
      "y": 18,
      "z": 0,
      "name": "Rock_Stone"
    },
    {
      "x": -1,
      "y": 19,
      "z": 0,
      "name": "Rock_Stone"
    },
    {
      "x": -1,
      "y": 20,
      "z": 0,
      "name": "Rock_Stone"
    },
    {
      "x": -1,
      "y": 21,
      "z": 0,
      "name": "Rock_Stone"
    },
    {
      "x": -1,
      "y": 22,
      "z": 0,
      "name": "Rock_Stone"
    },
    {
      "x": -1,
      "y": 23,
      "z": 0,
      "name": "Rock_Stone"
    },
    {
      "x": -1,
      "y": 24,
      "z": 0,
      "name": "Rock_Stone"
    },
    {
      "x": -1,
      "y": 25,
      "z": 0,
      "name": "Rock_Stone"
    },
    {
      "x": -1,
      "y": 11,
      "z": 1,
      "name": "Rock_Stone"
    },
    {
      "x": -1,
      "y": 12,
      "z": 1,
      "name": "Rock_Stone"
    },
    {
      "x": -1,
      "y": 13,
      "z": 1,
      "name": "Rock_Stone"
    },
    {
      "x": -1,
      "y": 14,
      "z": 1,
      "name": "Rock_Stone"
    },
    {
      "x": -1,
      "y": 15,
      "z": 1,
      "name": "Rock_Stone"
    },
    {
      "x": -1,
      "y": 16,
      "z": 1,
      "name": "Rock_Stone"
    },
    {
      "x": -1,
      "y": 17,
      "z": 1,
      "name": "Rock_Stone"
    },
    {
      "x": -1,
      "y": 18,
      "z": 1,
      "name": "Rock_Stone"
    },
    {
      "x": -1,
      "y": 19,
      "z": 1,
      "name": "Rock_Stone"
    },
    {
      "x": -1,
      "y": 20,
      "z": 1,
      "name": "Rock_Stone"
    },
    {
      "x": -1,
      "y": 21,
      "z": 1,
      "name": "Rock_Stone"
    },
    {
      "x": -1,
      "y": 22,
      "z": 1,
      "name": "Rock_Stone"
    },
    {
      "x": -1,
      "y": 23,
      "z": 1,
      "name": "Rock_Stone"
    },
    {
      "x": -1,
      "y": 24,
      "z": 1,
      "name": "Rock_Stone"
    },
    {
      "x": -1,
      "y": 25,
      "z": 1,
      "name": "Rock_Stone"
    },
    {
      "x": -1,
      "y": 11,
      "z": 2,
      "name": "Rock_Stone"
    },
    {
      "x": -1,
      "y": 12,
      "z": 2,
      "name": "Rock_Stone"
    },
    {
      "x": -1,
      "y": 13,
      "z": 2,
      "name": "Rock_Stone"
    },
    {
      "x": -1,
      "y": 14,
      "z": 2,
      "name": "Rock_Stone"
    },
    {
      "x": -1,
      "y": 15,
      "z": 2,
      "name": "Rock_Stone"
    },
    {
      "x": -1,
      "y": 16,
      "z": 2,
      "name": "Rock_Stone"
    },
    {
      "x": -1,
      "y": 17,
      "z": 2,
      "name": "Rock_Stone"
    },
    {
      "x": -1,
      "y": 18,
      "z": 2,
      "name": "Rock_Stone"
    },
    {
      "x": -1,
      "y": 19,
      "z": 2,
      "name": "Rock_Stone"
    },
    {
      "x": -1,
      "y": 20,
      "z": 2,
      "name": "Rock_Stone"
    },
    {
      "x": -1,
      "y": 21,
      "z": 2,
      "name": "Rock_Stone"
    },
    {
      "x": -1,
      "y": 22,
      "z": 2,
      "name": "Rock_Stone"
    },
    {
      "x": -1,
      "y": 23,
      "z": 2,
      "name": "Rock_Stone"
    },
    {
      "x": -1,
      "y": 24,
      "z": 2,
      "name": "Rock_Stone"
    },
    {
      "x": -1,
      "y": 25,
      "z": 2,
      "name": "Rock_Stone"
    },
    {
      "x": -1,
      "y": 11,
      "z": 3,
      "name": "Rock_Stone"
    },
    {
      "x": -1,
      "y": 12,
      "z": 3,
      "name": "Rock_Stone"
    },
    {
      "x": -1,
      "y": 13,
      "z": 3,
      "name": "Rock_Stone"
    },
    {
      "x": -1,
      "y": 14,
      "z": 3,
      "name": "Rock_Stone"
    },
    {
      "x": -1,
      "y": 15,
      "z": 3,
      "name": "Rock_Stone"
    },
    {
      "x": -1,
      "y": 16,
      "z": 3,
      "name": "Rock_Stone"
    },
    {
      "x": -1,
      "y": 17,
      "z": 3,
      "name": "Rock_Stone"
    },
    {
      "x": -1,
      "y": 18,
      "z": 3,
      "name": "Rock_Stone"
    },
    {
      "x": -1,
      "y": 19,
      "z": 3,
      "name": "Rock_Stone"
    },
    {
      "x": -1,
      "y": 20,
      "z": 3,
      "name": "Rock_Stone"
    },
    {
      "x": -1,
      "y": 21,
      "z": 3,
      "name": "Rock_Stone"
    },
    {
      "x": -1,
      "y": 22,
      "z": 3,
      "name": "Rock_Stone"
    },
    {
      "x": -1,
      "y": 23,
      "z": 3,
      "name": "Rock_Stone"
    },
    {
      "x": -1,
      "y": 24,
      "z": 3,
      "name": "Rock_Stone"
    },
    {
      "x": -1,
      "y": 25,
      "z": 3,
      "name": "Rock_Stone"
    },
    {
      "x": -1,
      "y": 11,
      "z": 4,
      "name": "Rock_Stone"
    },
    {
      "x": -1,
      "y": 12,
      "z": 4,
      "name": "Rock_Stone"
    },
    {
      "x": -1,
      "y": 13,
      "z": 4,
      "name": "Rock_Stone"
    },
    {
      "x": -1,
      "y": 14,
      "z": 4,
      "name": "Rock_Stone"
    },
    {
      "x": -1,
      "y": 15,
      "z": 4,
      "name": "Rock_Stone"
    },
    {
      "x": -1,
      "y": 16,
      "z": 4,
      "name": "Rock_Stone"
    },
    {
      "x": -1,
      "y": 17,
      "z": 4,
      "name": "Rock_Stone"
    },
    {
      "x": -1,
      "y": 18,
      "z": 4,
      "name": "Rock_Stone"
    },
    {
      "x": -1,
      "y": 19,
      "z": 4,
      "name": "Rock_Stone"
    },
    {
      "x": -1,
      "y": 20,
      "z": 4,
      "name": "Rock_Stone"
    },
    {
      "x": -1,
      "y": 21,
      "z": 4,
      "name": "Rock_Stone"
    },
    {
      "x": -1,
      "y": 22,
      "z": 4,
      "name": "Rock_Stone"
    },
    {
      "x": -1,
      "y": 23,
      "z": 4,
      "name": "Rock_Stone"
    },
    {
      "x": -1,
      "y": 24,
      "z": 4,
      "name": "Rock_Stone"
    },
    {
      "x": -1,
      "y": 25,
      "z": 4,
      "name": "Rock_Stone"
    },
    {
      "x": 0,
      "y": 11,
      "z": -4,
      "name": "Rock_Stone"
    },
    {
      "x": 0,
      "y": 12,
      "z": -4,
      "name": "Rock_Stone"
    },
    {
      "x": 0,
      "y": 13,
      "z": -4,
      "name": "Rock_Stone"
    },
    {
      "x": 0,
      "y": 14,
      "z": -4,
      "name": "Rock_Stone"
    },
    {
      "x": 0,
      "y": 15,
      "z": -4,
      "name": "Rock_Stone"
    },
    {
      "x": 0,
      "y": 16,
      "z": -4,
      "name": "Rock_Stone"
    },
    {
      "x": 0,
      "y": 17,
      "z": -4,
      "name": "Rock_Stone"
    },
    {
      "x": 0,
      "y": 18,
      "z": -4,
      "name": "Rock_Stone"
    },
    {
      "x": 0,
      "y": 19,
      "z": -4,
      "name": "Rock_Stone"
    },
    {
      "x": 0,
      "y": 20,
      "z": -4,
      "name": "Rock_Stone"
    },
    {
      "x": 0,
      "y": 21,
      "z": -4,
      "name": "Rock_Stone"
    },
    {
      "x": 0,
      "y": 22,
      "z": -4,
      "name": "Rock_Stone"
    },
    {
      "x": 0,
      "y": 23,
      "z": -4,
      "name": "Rock_Stone"
    },
    {
      "x": 0,
      "y": 24,
      "z": -4,
      "name": "Rock_Stone"
    },
    {
      "x": 0,
      "y": 25,
      "z": -4,
      "name": "Rock_Stone"
    },
    {
      "x": 0,
      "y": 11,
      "z": -3,
      "name": "Rock_Stone"
    },
    {
      "x": 0,
      "y": 12,
      "z": -3,
      "name": "Rock_Stone"
    },
    {
      "x": 0,
      "y": 13,
      "z": -3,
      "name": "Rock_Stone"
    },
    {
      "x": 0,
      "y": 14,
      "z": -3,
      "name": "Rock_Stone"
    },
    {
      "x": 0,
      "y": 15,
      "z": -3,
      "name": "Rock_Stone"
    },
    {
      "x": 0,
      "y": 16,
      "z": -3,
      "name": "Rock_Stone"
    },
    {
      "x": 0,
      "y": 17,
      "z": -3,
      "name": "Rock_Stone"
    },
    {
      "x": 0,
      "y": 18,
      "z": -3,
      "name": "Rock_Stone"
    },
    {
      "x": 0,
      "y": 19,
      "z": -3,
      "name": "Rock_Stone"
    },
    {
      "x": 0,
      "y": 20,
      "z": -3,
      "name": "Rock_Stone"
    },
    {
      "x": 0,
      "y": 21,
      "z": -3,
      "name": "Rock_Stone"
    },
    {
      "x": 0,
      "y": 22,
      "z": -3,
      "name": "Rock_Stone"
    },
    {
      "x": 0,
      "y": 23,
      "z": -3,
      "name": "Rock_Stone"
    },
    {
      "x": 0,
      "y": 24,
      "z": -3,
      "name": "Rock_Stone"
    },
    {
      "x": 0,
      "y": 25,
      "z": -3,
      "name": "Rock_Stone"
    },
    {
      "x": 0,
      "y": 11,
      "z": -2,
      "name": "Rock_Stone"
    },
    {
      "x": 0,
      "y": 12,
      "z": -2,
      "name": "Rock_Stone"
    },
    {
      "x": 0,
      "y": 13,
      "z": -2,
      "name": "Rock_Stone"
    },
    {
      "x": 0,
      "y": 14,
      "z": -2,
      "name": "Rock_Stone"
    },
    {
      "x": 0,
      "y": 15,
      "z": -2,
      "name": "Rock_Stone"
    },
    {
      "x": 0,
      "y": 16,
      "z": -2,
      "name": "Rock_Stone"
    },
    {
      "x": 0,
      "y": 17,
      "z": -2,
      "name": "Rock_Stone"
    },
    {
      "x": 0,
      "y": 18,
      "z": -2,
      "name": "Rock_Stone"
    },
    {
      "x": 0,
      "y": 19,
      "z": -2,
      "name": "Rock_Stone"
    },
    {
      "x": 0,
      "y": 20,
      "z": -2,
      "name": "Rock_Stone"
    },
    {
      "x": 0,
      "y": 21,
      "z": -2,
      "name": "Rock_Stone"
    },
    {
      "x": 0,
      "y": 22,
      "z": -2,
      "name": "Rock_Stone"
    },
    {
      "x": 0,
      "y": 23,
      "z": -2,
      "name": "Rock_Stone"
    },
    {
      "x": 0,
      "y": 24,
      "z": -2,
      "name": "Rock_Stone"
    },
    {
      "x": 0,
      "y": 25,
      "z": -2,
      "name": "Rock_Stone"
    },
    {
      "x": 0,
      "y": 11,
      "z": -1,
      "name": "Rock_Stone"
    },
    {
      "x": 0,
      "y": 12,
      "z": -1,
      "name": "Rock_Stone"
    },
    {
      "x": 0,
      "y": 13,
      "z": -1,
      "name": "Rock_Stone"
    },
    {
      "x": 0,
      "y": 14,
      "z": -1,
      "name": "Rock_Stone"
    },
    {
      "x": 0,
      "y": 15,
      "z": -1,
      "name": "Rock_Stone"
    },
    {
      "x": 0,
      "y": 16,
      "z": -1,
      "name": "Rock_Stone"
    },
    {
      "x": 0,
      "y": 17,
      "z": -1,
      "name": "Rock_Stone"
    },
    {
      "x": 0,
      "y": 18,
      "z": -1,
      "name": "Rock_Stone"
    },
    {
      "x": 0,
      "y": 19,
      "z": -1,
      "name": "Rock_Stone"
    },
    {
      "x": 0,
      "y": 20,
      "z": -1,
      "name": "Rock_Stone"
    },
    {
      "x": 0,
      "y": 21,
      "z": -1,
      "name": "Rock_Stone"
    },
    {
      "x": 0,
      "y": 22,
      "z": -1,
      "name": "Rock_Stone"
    },
    {
      "x": 0,
      "y": 23,
      "z": -1,
      "name": "Rock_Stone"
    },
    {
      "x": 0,
      "y": 24,
      "z": -1,
      "name": "Rock_Stone"
    },
    {
      "x": 0,
      "y": 25,
      "z": -1,
      "name": "Rock_Stone"
    },
    {
      "x": 0,
      "y": 11,
      "z": 0,
      "name": "Rock_Stone"
    },
    {
      "x": 0,
      "y": 12,
      "z": 0,
      "name": "Rock_Stone"
    },
    {
      "x": 0,
      "y": 13,
      "z": 0,
      "name": "Rock_Stone"
    },
    {
      "x": 0,
      "y": 14,
      "z": 0,
      "name": "Rock_Stone"
    },
    {
      "x": 0,
      "y": 15,
      "z": 0,
      "name": "Rock_Stone"
    },
    {
      "x": 0,
      "y": 16,
      "z": 0,
      "name": "Rock_Stone"
    },
    {
      "x": 0,
      "y": 17,
      "z": 0,
      "name": "Rock_Stone"
    },
    {
      "x": 0,
      "y": 18,
      "z": 0,
      "name": "Rock_Stone"
    },
    {
      "x": 0,
      "y": 19,
      "z": 0,
      "name": "Rock_Stone"
    },
    {
      "x": 0,
      "y": 20,
      "z": 0,
      "name": "Rock_Stone"
    },
    {
      "x": 0,
      "y": 21,
      "z": 0,
      "name": "Rock_Stone"
    },
    {
      "x": 0,
      "y": 22,
      "z": 0,
      "name": "Rock_Stone"
    },
    {
      "x": 0,
      "y": 23,
      "z": 0,
      "name": "Rock_Stone"
    },
    {
      "x": 0,
      "y": 24,
      "z": 0,
      "name": "Rock_Stone"
    },
    {
      "x": 0,
      "y": 25,
      "z": 0,
      "name": "Rock_Stone"
    },
    {
      "x": 0,
      "y": 11,
      "z": 1,
      "name": "Rock_Stone"
    },
    {
      "x": 0,
      "y": 12,
      "z": 1,
      "name": "Rock_Stone"
    },
    {
      "x": 0,
      "y": 13,
      "z": 1,
      "name": "Rock_Stone"
    },
    {
      "x": 0,
      "y": 14,
      "z": 1,
      "name": "Rock_Stone"
    },
    {
      "x": 0,
      "y": 15,
      "z": 1,
      "name": "Rock_Stone"
    },
    {
      "x": 0,
      "y": 16,
      "z": 1,
      "name": "Rock_Stone"
    },
    {
      "x": 0,
      "y": 17,
      "z": 1,
      "name": "Rock_Stone"
    },
    {
      "x": 0,
      "y": 18,
      "z": 1,
      "name": "Rock_Stone"
    },
    {
      "x": 0,
      "y": 19,
      "z": 1,
      "name": "Rock_Stone"
    },
    {
      "x": 0,
      "y": 20,
      "z": 1,
      "name": "Rock_Stone"
    },
    {
      "x": 0,
      "y": 21,
      "z": 1,
      "name": "Rock_Stone"
    },
    {
      "x": 0,
      "y": 22,
      "z": 1,
      "name": "Rock_Stone"
    },
    {
      "x": 0,
      "y": 23,
      "z": 1,
      "name": "Rock_Stone"
    },
    {
      "x": 0,
      "y": 24,
      "z": 1,
      "name": "Rock_Stone"
    },
    {
      "x": 0,
      "y": 25,
      "z": 1,
      "name": "Rock_Stone"
    },
    {
      "x": 0,
      "y": 11,
      "z": 2,
      "name": "Rock_Stone"
    },
    {
      "x": 0,
      "y": 12,
      "z": 2,
      "name": "Rock_Stone"
    },
    {
      "x": 0,
      "y": 13,
      "z": 2,
      "name": "Rock_Stone"
    },
    {
      "x": 0,
      "y": 14,
      "z": 2,
      "name": "Rock_Stone"
    },
    {
      "x": 0,
      "y": 15,
      "z": 2,
      "name": "Rock_Stone"
    },
    {
      "x": 0,
      "y": 16,
      "z": 2,
      "name": "Rock_Stone"
    },
    {
      "x": 0,
      "y": 17,
      "z": 2,
      "name": "Rock_Stone"
    },
    {
      "x": 0,
      "y": 18,
      "z": 2,
      "name": "Rock_Stone"
    },
    {
      "x": 0,
      "y": 19,
      "z": 2,
      "name": "Rock_Stone"
    },
    {
      "x": 0,
      "y": 20,
      "z": 2,
      "name": "Rock_Stone"
    },
    {
      "x": 0,
      "y": 21,
      "z": 2,
      "name": "Rock_Stone"
    },
    {
      "x": 0,
      "y": 22,
      "z": 2,
      "name": "Rock_Stone"
    },
    {
      "x": 0,
      "y": 23,
      "z": 2,
      "name": "Rock_Stone"
    },
    {
      "x": 0,
      "y": 24,
      "z": 2,
      "name": "Rock_Stone"
    },
    {
      "x": 0,
      "y": 25,
      "z": 2,
      "name": "Rock_Stone"
    },
    {
      "x": 0,
      "y": 11,
      "z": 3,
      "name": "Rock_Stone"
    },
    {
      "x": 0,
      "y": 12,
      "z": 3,
      "name": "Rock_Stone"
    },
    {
      "x": 0,
      "y": 13,
      "z": 3,
      "name": "Rock_Stone"
    },
    {
      "x": 0,
      "y": 14,
      "z": 3,
      "name": "Rock_Stone"
    },
    {
      "x": 0,
      "y": 15,
      "z": 3,
      "name": "Rock_Stone"
    },
    {
      "x": 0,
      "y": 16,
      "z": 3,
      "name": "Rock_Stone"
    },
    {
      "x": 0,
      "y": 17,
      "z": 3,
      "name": "Rock_Stone"
    },
    {
      "x": 0,
      "y": 18,
      "z": 3,
      "name": "Rock_Stone"
    },
    {
      "x": 0,
      "y": 19,
      "z": 3,
      "name": "Rock_Stone"
    },
    {
      "x": 0,
      "y": 20,
      "z": 3,
      "name": "Rock_Stone"
    },
    {
      "x": 0,
      "y": 21,
      "z": 3,
      "name": "Rock_Stone"
    },
    {
      "x": 0,
      "y": 22,
      "z": 3,
      "name": "Rock_Stone"
    },
    {
      "x": 0,
      "y": 23,
      "z": 3,
      "name": "Rock_Stone"
    },
    {
      "x": 0,
      "y": 24,
      "z": 3,
      "name": "Rock_Stone"
    },
    {
      "x": 0,
      "y": 25,
      "z": 3,
      "name": "Rock_Stone"
    },
    {
      "x": 0,
      "y": 26,
      "z": 3,
      "name": "Block_Spawner_Block",
      "components": {
        "Components": {
          "BlockSpawner": {
            "BlockSpawnerId": "Zone1_Encounters_Tier3"
          }
        }
      },
      "rotation": 2
    },
    {
      "x": 0,
      "y": 11,
      "z": 4,
      "name": "Rock_Stone"
    },
    {
      "x": 0,
      "y": 12,
      "z": 4,
      "name": "Rock_Stone"
    },
    {
      "x": 0,
      "y": 13,
      "z": 4,
      "name": "Rock_Stone"
    },
    {
      "x": 0,
      "y": 14,
      "z": 4,
      "name": "Rock_Stone"
    },
    {
      "x": 0,
      "y": 15,
      "z": 4,
      "name": "Rock_Stone"
    },
    {
      "x": 0,
      "y": 16,
      "z": 4,
      "name": "Rock_Stone"
    },
    {
      "x": 0,
      "y": 17,
      "z": 4,
      "name": "Rock_Stone"
    },
    {
      "x": 0,
      "y": 18,
      "z": 4,
      "name": "Rock_Stone"
    },
    {
      "x": 0,
      "y": 19,
      "z": 4,
      "name": "Rock_Stone"
    },
    {
      "x": 0,
      "y": 20,
      "z": 4,
      "name": "Rock_Stone"
    },
    {
      "x": 0,
      "y": 21,
      "z": 4,
      "name": "Rock_Stone"
    },
    {
      "x": 0,
      "y": 22,
      "z": 4,
      "name": "Rock_Stone"
    },
    {
      "x": 0,
      "y": 23,
      "z": 4,
      "name": "Rock_Stone"
    },
    {
      "x": 0,
      "y": 24,
      "z": 4,
      "name": "Rock_Stone"
    },
    {
      "x": 0,
      "y": 25,
      "z": 4,
      "name": "Rock_Stone"
    },
    {
      "x": 1,
      "y": 11,
      "z": -4,
      "name": "Rock_Stone"
    },
    {
      "x": 1,
      "y": 12,
      "z": -4,
      "name": "Rock_Stone"
    },
    {
      "x": 1,
      "y": 13,
      "z": -4,
      "name": "Rock_Stone"
    },
    {
      "x": 1,
      "y": 14,
      "z": -4,
      "name": "Rock_Stone"
    },
    {
      "x": 1,
      "y": 15,
      "z": -4,
      "name": "Rock_Stone"
    },
    {
      "x": 1,
      "y": 16,
      "z": -4,
      "name": "Rock_Stone"
    },
    {
      "x": 1,
      "y": 17,
      "z": -4,
      "name": "Rock_Stone"
    },
    {
      "x": 1,
      "y": 18,
      "z": -4,
      "name": "Rock_Stone"
    },
    {
      "x": 1,
      "y": 19,
      "z": -4,
      "name": "Rock_Stone"
    },
    {
      "x": 1,
      "y": 20,
      "z": -4,
      "name": "Rock_Stone"
    },
    {
      "x": 1,
      "y": 21,
      "z": -4,
      "name": "Rock_Stone"
    },
    {
      "x": 1,
      "y": 22,
      "z": -4,
      "name": "Rock_Stone"
    },
    {
      "x": 1,
      "y": 23,
      "z": -4,
      "name": "Rock_Stone"
    },
    {
      "x": 1,
      "y": 24,
      "z": -4,
      "name": "Rock_Stone"
    },
    {
      "x": 1,
      "y": 25,
      "z": -4,
      "name": "Rock_Stone"
    },
    {
      "x": 1,
      "y": 11,
      "z": -3,
      "name": "Rock_Stone"
    },
    {
      "x": 1,
      "y": 12,
      "z": -3,
      "name": "Rock_Stone"
    },
    {
      "x": 1,
      "y": 13,
      "z": -3,
      "name": "Rock_Stone"
    },
    {
      "x": 1,
      "y": 14,
      "z": -3,
      "name": "Rock_Stone"
    },
    {
      "x": 1,
      "y": 15,
      "z": -3,
      "name": "Rock_Stone"
    },
    {
      "x": 1,
      "y": 16,
      "z": -3,
      "name": "Rock_Stone"
    },
    {
      "x": 1,
      "y": 17,
      "z": -3,
      "name": "Rock_Stone"
    },
    {
      "x": 1,
      "y": 18,
      "z": -3,
      "name": "Rock_Stone"
    },
    {
      "x": 1,
      "y": 19,
      "z": -3,
      "name": "Rock_Stone"
    },
    {
      "x": 1,
      "y": 20,
      "z": -3,
      "name": "Rock_Stone"
    },
    {
      "x": 1,
      "y": 21,
      "z": -3,
      "name": "Rock_Stone"
    },
    {
      "x": 1,
      "y": 22,
      "z": -3,
      "name": "Rock_Stone"
    },
    {
      "x": 1,
      "y": 23,
      "z": -3,
      "name": "Rock_Stone"
    },
    {
      "x": 1,
      "y": 24,
      "z": -3,
      "name": "Rock_Stone"
    },
    {
      "x": 1,
      "y": 25,
      "z": -3,
      "name": "Rock_Stone"
    },
    {
      "x": 1,
      "y": 11,
      "z": -2,
      "name": "Rock_Stone"
    },
    {
      "x": 1,
      "y": 12,
      "z": -2,
      "name": "Rock_Stone"
    },
    {
      "x": 1,
      "y": 13,
      "z": -2,
      "name": "Rock_Stone"
    },
    {
      "x": 1,
      "y": 14,
      "z": -2,
      "name": "Rock_Stone"
    },
    {
      "x": 1,
      "y": 15,
      "z": -2,
      "name": "Rock_Stone"
    },
    {
      "x": 1,
      "y": 16,
      "z": -2,
      "name": "Rock_Stone"
    },
    {
      "x": 1,
      "y": 17,
      "z": -2,
      "name": "Rock_Stone"
    },
    {
      "x": 1,
      "y": 18,
      "z": -2,
      "name": "Rock_Stone"
    },
    {
      "x": 1,
      "y": 19,
      "z": -2,
      "name": "Rock_Stone"
    },
    {
      "x": 1,
      "y": 20,
      "z": -2,
      "name": "Rock_Stone"
    },
    {
      "x": 1,
      "y": 21,
      "z": -2,
      "name": "Rock_Stone"
    },
    {
      "x": 1,
      "y": 22,
      "z": -2,
      "name": "Rock_Stone"
    },
    {
      "x": 1,
      "y": 23,
      "z": -2,
      "name": "Rock_Stone"
    },
    {
      "x": 1,
      "y": 24,
      "z": -2,
      "name": "Rock_Stone"
    },
    {
      "x": 1,
      "y": 25,
      "z": -2,
      "name": "Rock_Stone"
    },
    {
      "x": 1,
      "y": 11,
      "z": -1,
      "name": "Rock_Stone"
    },
    {
      "x": 1,
      "y": 12,
      "z": -1,
      "name": "Rock_Stone"
    },
    {
      "x": 1,
      "y": 13,
      "z": -1,
      "name": "Rock_Stone"
    },
    {
      "x": 1,
      "y": 14,
      "z": -1,
      "name": "Rock_Stone"
    },
    {
      "x": 1,
      "y": 15,
      "z": -1,
      "name": "Rock_Stone"
    },
    {
      "x": 1,
      "y": 16,
      "z": -1,
      "name": "Rock_Stone"
    },
    {
      "x": 1,
      "y": 17,
      "z": -1,
      "name": "Rock_Stone"
    },
    {
      "x": 1,
      "y": 18,
      "z": -1,
      "name": "Rock_Stone"
    },
    {
      "x": 1,
      "y": 19,
      "z": -1,
      "name": "Rock_Stone"
    },
    {
      "x": 1,
      "y": 20,
      "z": -1,
      "name": "Rock_Stone"
    },
    {
      "x": 1,
      "y": 21,
      "z": -1,
      "name": "Rock_Stone"
    },
    {
      "x": 1,
      "y": 22,
      "z": -1,
      "name": "Rock_Stone"
    },
    {
      "x": 1,
      "y": 23,
      "z": -1,
      "name": "Rock_Stone"
    },
    {
      "x": 1,
      "y": 24,
      "z": -1,
      "name": "Rock_Stone"
    },
    {
      "x": 1,
      "y": 25,
      "z": -1,
      "name": "Rock_Stone"
    },
    {
      "x": 1,
      "y": 11,
      "z": 0,
      "name": "Rock_Stone"
    },
    {
      "x": 1,
      "y": 12,
      "z": 0,
      "name": "Rock_Stone"
    },
    {
      "x": 1,
      "y": 13,
      "z": 0,
      "name": "Rock_Stone"
    },
    {
      "x": 1,
      "y": 14,
      "z": 0,
      "name": "Rock_Stone"
    },
    {
      "x": 1,
      "y": 15,
      "z": 0,
      "name": "Rock_Stone"
    },
    {
      "x": 1,
      "y": 16,
      "z": 0,
      "name": "Rock_Stone"
    },
    {
      "x": 1,
      "y": 17,
      "z": 0,
      "name": "Rock_Stone"
    },
    {
      "x": 1,
      "y": 18,
      "z": 0,
      "name": "Rock_Stone"
    },
    {
      "x": 1,
      "y": 19,
      "z": 0,
      "name": "Rock_Stone"
    },
    {
      "x": 1,
      "y": 20,
      "z": 0,
      "name": "Rock_Stone"
    },
    {
      "x": 1,
      "y": 21,
      "z": 0,
      "name": "Rock_Stone"
    },
    {
      "x": 1,
      "y": 22,
      "z": 0,
      "name": "Rock_Stone"
    },
    {
      "x": 1,
      "y": 23,
      "z": 0,
      "name": "Rock_Stone"
    },
    {
      "x": 1,
      "y": 24,
      "z": 0,
      "name": "Rock_Stone"
    },
    {
      "x": 1,
      "y": 25,
      "z": 0,
      "name": "Rock_Stone"
    },
    {
      "x": 1,
      "y": 11,
      "z": 1,
      "name": "Rock_Stone"
    },
    {
      "x": 1,
      "y": 12,
      "z": 1,
      "name": "Rock_Stone"
    },
    {
      "x": 1,
      "y": 13,
      "z": 1,
      "name": "Rock_Stone"
    },
    {
      "x": 1,
      "y": 14,
      "z": 1,
      "name": "Rock_Stone"
    },
    {
      "x": 1,
      "y": 15,
      "z": 1,
      "name": "Rock_Stone"
    },
    {
      "x": 1,
      "y": 16,
      "z": 1,
      "name": "Rock_Stone"
    },
    {
      "x": 1,
      "y": 17,
      "z": 1,
      "name": "Rock_Stone"
    },
    {
      "x": 1,
      "y": 18,
      "z": 1,
      "name": "Rock_Stone"
    },
    {
      "x": 1,
      "y": 19,
      "z": 1,
      "name": "Rock_Stone"
    },
    {
      "x": 1,
      "y": 20,
      "z": 1,
      "name": "Rock_Stone"
    },
    {
      "x": 1,
      "y": 21,
      "z": 1,
      "name": "Rock_Stone"
    },
    {
      "x": 1,
      "y": 22,
      "z": 1,
      "name": "Rock_Stone"
    },
    {
      "x": 1,
      "y": 23,
      "z": 1,
      "name": "Rock_Stone"
    },
    {
      "x": 1,
      "y": 24,
      "z": 1,
      "name": "Rock_Stone"
    },
    {
      "x": 1,
      "y": 25,
      "z": 1,
      "name": "Rock_Stone"
    },
    {
      "x": 1,
      "y": 11,
      "z": 2,
      "name": "Rock_Stone"
    },
    {
      "x": 1,
      "y": 12,
      "z": 2,
      "name": "Rock_Stone"
    },
    {
      "x": 1,
      "y": 13,
      "z": 2,
      "name": "Rock_Stone"
    },
    {
      "x": 1,
      "y": 14,
      "z": 2,
      "name": "Rock_Stone"
    },
    {
      "x": 1,
      "y": 15,
      "z": 2,
      "name": "Rock_Stone"
    },
    {
      "x": 1,
      "y": 16,
      "z": 2,
      "name": "Rock_Stone"
    },
    {
      "x": 1,
      "y": 17,
      "z": 2,
      "name": "Rock_Stone"
    },
    {
      "x": 1,
      "y": 18,
      "z": 2,
      "name": "Rock_Stone"
    },
    {
      "x": 1,
      "y": 19,
      "z": 2,
      "name": "Rock_Stone"
    },
    {
      "x": 1,
      "y": 20,
      "z": 2,
      "name": "Rock_Stone"
    },
    {
      "x": 1,
      "y": 21,
      "z": 2,
      "name": "Rock_Stone"
    },
    {
      "x": 1,
      "y": 22,
      "z": 2,
      "name": "Rock_Stone"
    },
    {
      "x": 1,
      "y": 23,
      "z": 2,
      "name": "Rock_Stone"
    },
    {
      "x": 1,
      "y": 24,
      "z": 2,
      "name": "Rock_Stone"
    },
    {
      "x": 1,
      "y": 25,
      "z": 2,
      "name": "Rock_Stone"
    },
    {
      "x": 1,
      "y": 11,
      "z": 3,
      "name": "Rock_Stone"
    },
    {
      "x": 1,
      "y": 12,
      "z": 3,
      "name": "Rock_Stone"
    },
    {
      "x": 1,
      "y": 13,
      "z": 3,
      "name": "Rock_Stone"
    },
    {
      "x": 1,
      "y": 14,
      "z": 3,
      "name": "Rock_Stone"
    },
    {
      "x": 1,
      "y": 15,
      "z": 3,
      "name": "Rock_Stone"
    },
    {
      "x": 1,
      "y": 16,
      "z": 3,
      "name": "Rock_Stone"
    },
    {
      "x": 1,
      "y": 17,
      "z": 3,
      "name": "Rock_Stone"
    },
    {
      "x": 1,
      "y": 18,
      "z": 3,
      "name": "Rock_Stone"
    },
    {
      "x": 1,
      "y": 19,
      "z": 3,
      "name": "Rock_Stone"
    },
    {
      "x": 1,
      "y": 20,
      "z": 3,
      "name": "Rock_Stone"
    },
    {
      "x": 1,
      "y": 21,
      "z": 3,
      "name": "Rock_Stone"
    },
    {
      "x": 1,
      "y": 22,
      "z": 3,
      "name": "Rock_Stone"
    },
    {
      "x": 1,
      "y": 23,
      "z": 3,
      "name": "Rock_Stone"
    },
    {
      "x": 1,
      "y": 24,
      "z": 3,
      "name": "Rock_Stone"
    },
    {
      "x": 1,
      "y": 25,
      "z": 3,
      "name": "Rock_Stone"
    },
    {
      "x": 1,
      "y": 11,
      "z": 4,
      "name": "Rock_Stone"
    },
    {
      "x": 1,
      "y": 12,
      "z": 4,
      "name": "Rock_Stone"
    },
    {
      "x": 1,
      "y": 13,
      "z": 4,
      "name": "Rock_Stone"
    },
    {
      "x": 1,
      "y": 14,
      "z": 4,
      "name": "Rock_Stone"
    },
    {
      "x": 1,
      "y": 15,
      "z": 4,
      "name": "Rock_Stone"
    },
    {
      "x": 1,
      "y": 16,
      "z": 4,
      "name": "Rock_Stone"
    },
    {
      "x": 1,
      "y": 17,
      "z": 4,
      "name": "Rock_Stone"
    },
    {
      "x": 1,
      "y": 18,
      "z": 4,
      "name": "Rock_Stone"
    },
    {
      "x": 1,
      "y": 19,
      "z": 4,
      "name": "Rock_Stone"
    },
    {
      "x": 1,
      "y": 20,
      "z": 4,
      "name": "Rock_Stone"
    },
    {
      "x": 1,
      "y": 21,
      "z": 4,
      "name": "Rock_Stone"
    },
    {
      "x": 1,
      "y": 22,
      "z": 4,
      "name": "Rock_Stone"
    },
    {
      "x": 1,
      "y": 23,
      "z": 4,
      "name": "Rock_Stone"
    },
    {
      "x": 1,
      "y": 24,
      "z": 4,
      "name": "Rock_Stone"
    },
    {
      "x": 1,
      "y": 25,
      "z": 4,
      "name": "Rock_Stone"
    },
    {
      "x": 2,
      "y": 11,
      "z": -4,
      "name": "Rock_Stone"
    },
    {
      "x": 2,
      "y": 12,
      "z": -4,
      "name": "Rock_Stone"
    },
    {
      "x": 2,
      "y": 13,
      "z": -4,
      "name": "Rock_Stone"
    },
    {
      "x": 2,
      "y": 14,
      "z": -4,
      "name": "Rock_Stone"
    },
    {
      "x": 2,
      "y": 15,
      "z": -4,
      "name": "Rock_Stone"
    },
    {
      "x": 2,
      "y": 16,
      "z": -4,
      "name": "Rock_Stone"
    },
    {
      "x": 2,
      "y": 17,
      "z": -4,
      "name": "Rock_Stone"
    },
    {
      "x": 2,
      "y": 18,
      "z": -4,
      "name": "Rock_Stone"
    },
    {
      "x": 2,
      "y": 19,
      "z": -4,
      "name": "Rock_Stone"
    },
    {
      "x": 2,
      "y": 20,
      "z": -4,
      "name": "Rock_Stone"
    },
    {
      "x": 2,
      "y": 21,
      "z": -4,
      "name": "Rock_Stone"
    },
    {
      "x": 2,
      "y": 22,
      "z": -4,
      "name": "Rock_Stone"
    },
    {
      "x": 2,
      "y": 23,
      "z": -4,
      "name": "Rock_Stone"
    },
    {
      "x": 2,
      "y": 24,
      "z": -4,
      "name": "Rock_Stone"
    },
    {
      "x": 2,
      "y": 25,
      "z": -4,
      "name": "Rock_Stone"
    },
    {
      "x": 2,
      "y": 11,
      "z": -3,
      "name": "Rock_Stone"
    },
    {
      "x": 2,
      "y": 12,
      "z": -3,
      "name": "Rock_Stone"
    },
    {
      "x": 2,
      "y": 13,
      "z": -3,
      "name": "Rock_Stone"
    },
    {
      "x": 2,
      "y": 14,
      "z": -3,
      "name": "Rock_Stone"
    },
    {
      "x": 2,
      "y": 15,
      "z": -3,
      "name": "Rock_Stone"
    },
    {
      "x": 2,
      "y": 16,
      "z": -3,
      "name": "Rock_Stone"
    },
    {
      "x": 2,
      "y": 17,
      "z": -3,
      "name": "Rock_Stone"
    },
    {
      "x": 2,
      "y": 18,
      "z": -3,
      "name": "Rock_Stone"
    },
    {
      "x": 2,
      "y": 19,
      "z": -3,
      "name": "Rock_Stone"
    },
    {
      "x": 2,
      "y": 20,
      "z": -3,
      "name": "Rock_Stone"
    },
    {
      "x": 2,
      "y": 21,
      "z": -3,
      "name": "Rock_Stone"
    },
    {
      "x": 2,
      "y": 22,
      "z": -3,
      "name": "Rock_Stone"
    },
    {
      "x": 2,
      "y": 23,
      "z": -3,
      "name": "Rock_Stone"
    },
    {
      "x": 2,
      "y": 24,
      "z": -3,
      "name": "Rock_Stone"
    },
    {
      "x": 2,
      "y": 25,
      "z": -3,
      "name": "Rock_Stone"
    },
    {
      "x": 2,
      "y": 11,
      "z": -2,
      "name": "Rock_Stone"
    },
    {
      "x": 2,
      "y": 12,
      "z": -2,
      "name": "Rock_Stone"
    },
    {
      "x": 2,
      "y": 13,
      "z": -2,
      "name": "Rock_Stone"
    },
    {
      "x": 2,
      "y": 14,
      "z": -2,
      "name": "Rock_Stone"
    },
    {
      "x": 2,
      "y": 15,
      "z": -2,
      "name": "Rock_Stone"
    },
    {
      "x": 2,
      "y": 16,
      "z": -2,
      "name": "Rock_Stone"
    },
    {
      "x": 2,
      "y": 17,
      "z": -2,
      "name": "Rock_Stone"
    },
    {
      "x": 2,
      "y": 18,
      "z": -2,
      "name": "Rock_Stone"
    },
    {
      "x": 2,
      "y": 19,
      "z": -2,
      "name": "Rock_Stone"
    },
    {
      "x": 2,
      "y": 20,
      "z": -2,
      "name": "Rock_Stone"
    },
    {
      "x": 2,
      "y": 21,
      "z": -2,
      "name": "Rock_Stone"
    },
    {
      "x": 2,
      "y": 22,
      "z": -2,
      "name": "Rock_Stone"
    },
    {
      "x": 2,
      "y": 23,
      "z": -2,
      "name": "Rock_Stone"
    },
    {
      "x": 2,
      "y": 24,
      "z": -2,
      "name": "Rock_Stone"
    },
    {
      "x": 2,
      "y": 25,
      "z": -2,
      "name": "Rock_Stone"
    },
    {
      "x": 2,
      "y": 11,
      "z": -1,
      "name": "Rock_Stone"
    },
    {
      "x": 2,
      "y": 12,
      "z": -1,
      "name": "Rock_Stone"
    },
    {
      "x": 2,
      "y": 13,
      "z": -1,
      "name": "Rock_Stone"
    },
    {
      "x": 2,
      "y": 14,
      "z": -1,
      "name": "Rock_Stone"
    },
    {
      "x": 2,
      "y": 15,
      "z": -1,
      "name": "Rock_Stone"
    },
    {
      "x": 2,
      "y": 16,
      "z": -1,
      "name": "Rock_Stone"
    },
    {
      "x": 2,
      "y": 17,
      "z": -1,
      "name": "Rock_Stone"
    },
    {
      "x": 2,
      "y": 18,
      "z": -1,
      "name": "Rock_Stone"
    },
    {
      "x": 2,
      "y": 19,
      "z": -1,
      "name": "Rock_Stone"
    },
    {
      "x": 2,
      "y": 20,
      "z": -1,
      "name": "Rock_Stone"
    },
    {
      "x": 2,
      "y": 21,
      "z": -1,
      "name": "Rock_Stone"
    },
    {
      "x": 2,
      "y": 22,
      "z": -1,
      "name": "Rock_Stone"
    },
    {
      "x": 2,
      "y": 23,
      "z": -1,
      "name": "Rock_Stone"
    },
    {
      "x": 2,
      "y": 24,
      "z": -1,
      "name": "Rock_Stone"
    },
    {
      "x": 2,
      "y": 25,
      "z": -1,
      "name": "Rock_Stone"
    },
    {
      "x": 2,
      "y": 11,
      "z": 0,
      "name": "Rock_Stone"
    },
    {
      "x": 2,
      "y": 12,
      "z": 0,
      "name": "Rock_Stone"
    },
    {
      "x": 2,
      "y": 13,
      "z": 0,
      "name": "Rock_Stone"
    },
    {
      "x": 2,
      "y": 14,
      "z": 0,
      "name": "Rock_Stone"
    },
    {
      "x": 2,
      "y": 15,
      "z": 0,
      "name": "Rock_Stone"
    },
    {
      "x": 2,
      "y": 16,
      "z": 0,
      "name": "Rock_Stone"
    },
    {
      "x": 2,
      "y": 17,
      "z": 0,
      "name": "Rock_Stone"
    },
    {
      "x": 2,
      "y": 18,
      "z": 0,
      "name": "Rock_Stone"
    },
    {
      "x": 2,
      "y": 19,
      "z": 0,
      "name": "Rock_Stone"
    },
    {
      "x": 2,
      "y": 20,
      "z": 0,
      "name": "Rock_Stone"
    },
    {
      "x": 2,
      "y": 21,
      "z": 0,
      "name": "Rock_Stone"
    },
    {
      "x": 2,
      "y": 22,
      "z": 0,
      "name": "Rock_Stone"
    },
    {
      "x": 2,
      "y": 23,
      "z": 0,
      "name": "Rock_Stone"
    },
    {
      "x": 2,
      "y": 24,
      "z": 0,
      "name": "Rock_Stone"
    },
    {
      "x": 2,
      "y": 25,
      "z": 0,
      "name": "Rock_Stone"
    },
    {
      "x": 2,
      "y": 11,
      "z": 1,
      "name": "Rock_Stone"
    },
    {
      "x": 2,
      "y": 12,
      "z": 1,
      "name": "Rock_Stone"
    },
    {
      "x": 2,
      "y": 13,
      "z": 1,
      "name": "Rock_Stone"
    },
    {
      "x": 2,
      "y": 14,
      "z": 1,
      "name": "Rock_Stone"
    },
    {
      "x": 2,
      "y": 15,
      "z": 1,
      "name": "Rock_Stone"
    },
    {
      "x": 2,
      "y": 16,
      "z": 1,
      "name": "Rock_Stone"
    },
    {
      "x": 2,
      "y": 17,
      "z": 1,
      "name": "Rock_Stone"
    },
    {
      "x": 2,
      "y": 18,
      "z": 1,
      "name": "Rock_Stone"
    },
    {
      "x": 2,
      "y": 19,
      "z": 1,
      "name": "Rock_Stone"
    },
    {
      "x": 2,
      "y": 20,
      "z": 1,
      "name": "Rock_Stone"
    },
    {
      "x": 2,
      "y": 21,
      "z": 1,
      "name": "Rock_Stone"
    },
    {
      "x": 2,
      "y": 22,
      "z": 1,
      "name": "Rock_Stone"
    },
    {
      "x": 2,
      "y": 23,
      "z": 1,
      "name": "Rock_Stone"
    },
    {
      "x": 2,
      "y": 24,
      "z": 1,
      "name": "Rock_Stone"
    },
    {
      "x": 2,
      "y": 25,
      "z": 1,
      "name": "Rock_Stone"
    },
    {
      "x": 2,
      "y": 11,
      "z": 2,
      "name": "Rock_Stone"
    },
    {
      "x": 2,
      "y": 12,
      "z": 2,
      "name": "Rock_Stone"
    },
    {
      "x": 2,
      "y": 13,
      "z": 2,
      "name": "Rock_Stone"
    },
    {
      "x": 2,
      "y": 14,
      "z": 2,
      "name": "Rock_Stone"
    },
    {
      "x": 2,
      "y": 15,
      "z": 2,
      "name": "Rock_Stone"
    },
    {
      "x": 2,
      "y": 16,
      "z": 2,
      "name": "Rock_Stone"
    },
    {
      "x": 2,
      "y": 17,
      "z": 2,
      "name": "Rock_Stone"
    },
    {
      "x": 2,
      "y": 18,
      "z": 2,
      "name": "Rock_Stone"
    },
    {
      "x": 2,
      "y": 19,
      "z": 2,
      "name": "Rock_Stone"
    },
    {
      "x": 2,
      "y": 20,
      "z": 2,
      "name": "Rock_Stone"
    },
    {
      "x": 2,
      "y": 21,
      "z": 2,
      "name": "Rock_Stone"
    },
    {
      "x": 2,
      "y": 22,
      "z": 2,
      "name": "Rock_Stone"
    },
    {
      "x": 2,
      "y": 23,
      "z": 2,
      "name": "Rock_Stone"
    },
    {
      "x": 2,
      "y": 24,
      "z": 2,
      "name": "Rock_Stone"
    },
    {
      "x": 2,
      "y": 25,
      "z": 2,
      "name": "Rock_Stone"
    },
    {
      "x": 2,
      "y": 11,
      "z": 3,
      "name": "Rock_Stone"
    },
    {
      "x": 2,
      "y": 12,
      "z": 3,
      "name": "Rock_Stone"
    },
    {
      "x": 2,
      "y": 13,
      "z": 3,
      "name": "Rock_Stone"
    },
    {
      "x": 2,
      "y": 14,
      "z": 3,
      "name": "Rock_Stone"
    },
    {
      "x": 2,
      "y": 15,
      "z": 3,
      "name": "Rock_Stone"
    },
    {
      "x": 2,
      "y": 16,
      "z": 3,
      "name": "Rock_Stone"
    },
    {
      "x": 2,
      "y": 17,
      "z": 3,
      "name": "Rock_Stone"
    },
    {
      "x": 2,
      "y": 18,
      "z": 3,
      "name": "Rock_Stone"
    },
    {
      "x": 2,
      "y": 19,
      "z": 3,
      "name": "Rock_Stone"
    },
    {
      "x": 2,
      "y": 20,
      "z": 3,
      "name": "Rock_Stone"
    },
    {
      "x": 2,
      "y": 21,
      "z": 3,
      "name": "Rock_Stone"
    },
    {
      "x": 2,
      "y": 22,
      "z": 3,
      "name": "Rock_Stone"
    },
    {
      "x": 2,
      "y": 23,
      "z": 3,
      "name": "Rock_Stone"
    },
    {
      "x": 2,
      "y": 24,
      "z": 3,
      "name": "Rock_Stone"
    },
    {
      "x": 2,
      "y": 25,
      "z": 3,
      "name": "Rock_Stone"
    },
    {
      "x": 2,
      "y": 11,
      "z": 4,
      "name": "Rock_Stone"
    },
    {
      "x": 2,
      "y": 12,
      "z": 4,
      "name": "Rock_Stone"
    },
    {
      "x": 2,
      "y": 13,
      "z": 4,
      "name": "Rock_Stone"
    },
    {
      "x": 2,
      "y": 14,
      "z": 4,
      "name": "Rock_Stone"
    },
    {
      "x": 2,
      "y": 15,
      "z": 4,
      "name": "Rock_Stone"
    },
    {
      "x": 2,
      "y": 16,
      "z": 4,
      "name": "Rock_Stone"
    },
    {
      "x": 2,
      "y": 17,
      "z": 4,
      "name": "Rock_Stone"
    },
    {
      "x": 2,
      "y": 18,
      "z": 4,
      "name": "Rock_Stone"
    },
    {
      "x": 2,
      "y": 19,
      "z": 4,
      "name": "Rock_Stone"
    },
    {
      "x": 2,
      "y": 20,
      "z": 4,
      "name": "Rock_Stone"
    },
    {
      "x": 2,
      "y": 21,
      "z": 4,
      "name": "Rock_Stone"
    },
    {
      "x": 2,
      "y": 22,
      "z": 4,
      "name": "Rock_Stone"
    },
    {
      "x": 2,
      "y": 23,
      "z": 4,
      "name": "Rock_Stone"
    },
    {
      "x": 2,
      "y": 24,
      "z": 4,
      "name": "Rock_Stone"
    },
    {
      "x": 2,
      "y": 25,
      "z": 4,
      "name": "Rock_Stone"
    },
    {
      "x": 3,
      "y": 11,
      "z": -4,
      "name": "Rock_Stone"
    },
    {
      "x": 3,
      "y": 12,
      "z": -4,
      "name": "Rock_Stone"
    },
    {
      "x": 3,
      "y": 13,
      "z": -4,
      "name": "Rock_Stone"
    },
    {
      "x": 3,
      "y": 14,
      "z": -4,
      "name": "Rock_Stone"
    },
    {
      "x": 3,
      "y": 15,
      "z": -4,
      "name": "Rock_Stone"
    },
    {
      "x": 3,
      "y": 16,
      "z": -4,
      "name": "Rock_Stone"
    },
    {
      "x": 3,
      "y": 17,
      "z": -4,
      "name": "Rock_Stone"
    },
    {
      "x": 3,
      "y": 18,
      "z": -4,
      "name": "Rock_Stone"
    },
    {
      "x": 3,
      "y": 19,
      "z": -4,
      "name": "Rock_Stone"
    },
    {
      "x": 3,
      "y": 20,
      "z": -4,
      "name": "Rock_Stone"
    },
    {
      "x": 3,
      "y": 21,
      "z": -4,
      "name": "Rock_Stone"
    },
    {
      "x": 3,
      "y": 22,
      "z": -4,
      "name": "Rock_Stone"
    },
    {
      "x": 3,
      "y": 23,
      "z": -4,
      "name": "Rock_Stone"
    },
    {
      "x": 3,
      "y": 24,
      "z": -4,
      "name": "Rock_Stone"
    },
    {
      "x": 3,
      "y": 25,
      "z": -4,
      "name": "Rock_Stone"
    },
    {
      "x": 3,
      "y": 11,
      "z": -3,
      "name": "Rock_Stone"
    },
    {
      "x": 3,
      "y": 12,
      "z": -3,
      "name": "Rock_Stone"
    },
    {
      "x": 3,
      "y": 13,
      "z": -3,
      "name": "Rock_Stone"
    },
    {
      "x": 3,
      "y": 14,
      "z": -3,
      "name": "Rock_Stone"
    },
    {
      "x": 3,
      "y": 15,
      "z": -3,
      "name": "Rock_Stone"
    },
    {
      "x": 3,
      "y": 16,
      "z": -3,
      "name": "Rock_Stone"
    },
    {
      "x": 3,
      "y": 17,
      "z": -3,
      "name": "Rock_Stone"
    },
    {
      "x": 3,
      "y": 18,
      "z": -3,
      "name": "Rock_Stone"
    },
    {
      "x": 3,
      "y": 19,
      "z": -3,
      "name": "Rock_Stone"
    },
    {
      "x": 3,
      "y": 20,
      "z": -3,
      "name": "Rock_Stone"
    },
    {
      "x": 3,
      "y": 21,
      "z": -3,
      "name": "Rock_Stone"
    },
    {
      "x": 3,
      "y": 22,
      "z": -3,
      "name": "Rock_Stone"
    },
    {
      "x": 3,
      "y": 23,
      "z": -3,
      "name": "Rock_Stone"
    },
    {
      "x": 3,
      "y": 24,
      "z": -3,
      "name": "Rock_Stone"
    },
    {
      "x": 3,
      "y": 25,
      "z": -3,
      "name": "Rock_Stone"
    },
    {
      "x": 3,
      "y": 11,
      "z": -2,
      "name": "Rock_Stone"
    },
    {
      "x": 3,
      "y": 12,
      "z": -2,
      "name": "Rock_Stone"
    },
    {
      "x": 3,
      "y": 13,
      "z": -2,
      "name": "Rock_Stone"
    },
    {
      "x": 3,
      "y": 14,
      "z": -2,
      "name": "Rock_Stone"
    },
    {
      "x": 3,
      "y": 15,
      "z": -2,
      "name": "Rock_Stone"
    },
    {
      "x": 3,
      "y": 16,
      "z": -2,
      "name": "Rock_Stone"
    },
    {
      "x": 3,
      "y": 17,
      "z": -2,
      "name": "Rock_Stone"
    },
    {
      "x": 3,
      "y": 18,
      "z": -2,
      "name": "Rock_Stone"
    },
    {
      "x": 3,
      "y": 19,
      "z": -2,
      "name": "Rock_Stone"
    },
    {
      "x": 3,
      "y": 20,
      "z": -2,
      "name": "Rock_Stone"
    },
    {
      "x": 3,
      "y": 21,
      "z": -2,
      "name": "Rock_Stone"
    },
    {
      "x": 3,
      "y": 22,
      "z": -2,
      "name": "Rock_Stone"
    },
    {
      "x": 3,
      "y": 23,
      "z": -2,
      "name": "Rock_Stone"
    },
    {
      "x": 3,
      "y": 24,
      "z": -2,
      "name": "Rock_Stone"
    },
    {
      "x": 3,
      "y": 25,
      "z": -2,
      "name": "Rock_Stone"
    },
    {
      "x": 3,
      "y": 11,
      "z": -1,
      "name": "Rock_Stone"
    },
    {
      "x": 3,
      "y": 12,
      "z": -1,
      "name": "Rock_Stone"
    },
    {
      "x": 3,
      "y": 13,
      "z": -1,
      "name": "Rock_Stone"
    },
    {
      "x": 3,
      "y": 14,
      "z": -1,
      "name": "Rock_Stone"
    },
    {
      "x": 3,
      "y": 15,
      "z": -1,
      "name": "Rock_Stone"
    },
    {
      "x": 3,
      "y": 16,
      "z": -1,
      "name": "Rock_Stone"
    },
    {
      "x": 3,
      "y": 17,
      "z": -1,
      "name": "Rock_Stone"
    },
    {
      "x": 3,
      "y": 18,
      "z": -1,
      "name": "Rock_Stone"
    },
    {
      "x": 3,
      "y": 19,
      "z": -1,
      "name": "Rock_Stone"
    },
    {
      "x": 3,
      "y": 20,
      "z": -1,
      "name": "Rock_Stone"
    },
    {
      "x": 3,
      "y": 21,
      "z": -1,
      "name": "Rock_Stone"
    },
    {
      "x": 3,
      "y": 22,
      "z": -1,
      "name": "Rock_Stone"
    },
    {
      "x": 3,
      "y": 23,
      "z": -1,
      "name": "Rock_Stone"
    },
    {
      "x": 3,
      "y": 24,
      "z": -1,
      "name": "Rock_Stone"
    },
    {
      "x": 3,
      "y": 25,
      "z": -1,
      "name": "Rock_Stone"
    },
    {
      "x": 3,
      "y": 11,
      "z": 0,
      "name": "Rock_Stone"
    },
    {
      "x": 3,
      "y": 12,
      "z": 0,
      "name": "Rock_Stone"
    },
    {
      "x": 3,
      "y": 13,
      "z": 0,
      "name": "Rock_Stone"
    },
    {
      "x": 3,
      "y": 14,
      "z": 0,
      "name": "Rock_Stone"
    },
    {
      "x": 3,
      "y": 15,
      "z": 0,
      "name": "Rock_Stone"
    },
    {
      "x": 3,
      "y": 16,
      "z": 0,
      "name": "Rock_Stone"
    },
    {
      "x": 3,
      "y": 17,
      "z": 0,
      "name": "Rock_Stone"
    },
    {
      "x": 3,
      "y": 18,
      "z": 0,
      "name": "Rock_Stone"
    },
    {
      "x": 3,
      "y": 19,
      "z": 0,
      "name": "Rock_Stone"
    },
    {
      "x": 3,
      "y": 20,
      "z": 0,
      "name": "Rock_Stone"
    },
    {
      "x": 3,
      "y": 21,
      "z": 0,
      "name": "Rock_Stone"
    },
    {
      "x": 3,
      "y": 22,
      "z": 0,
      "name": "Rock_Stone"
    },
    {
      "x": 3,
      "y": 23,
      "z": 0,
      "name": "Rock_Stone"
    },
    {
      "x": 3,
      "y": 24,
      "z": 0,
      "name": "Rock_Stone"
    },
    {
      "x": 3,
      "y": 25,
      "z": 0,
      "name": "Rock_Stone"
    },
    {
      "x": 3,
      "y": 11,
      "z": 1,
      "name": "Rock_Stone"
    },
    {
      "x": 3,
      "y": 12,
      "z": 1,
      "name": "Rock_Stone"
    },
    {
      "x": 3,
      "y": 13,
      "z": 1,
      "name": "Rock_Stone"
    },
    {
      "x": 3,
      "y": 14,
      "z": 1,
      "name": "Rock_Stone"
    },
    {
      "x": 3,
      "y": 15,
      "z": 1,
      "name": "Rock_Stone"
    },
    {
      "x": 3,
      "y": 16,
      "z": 1,
      "name": "Rock_Stone"
    },
    {
      "x": 3,
      "y": 17,
      "z": 1,
      "name": "Rock_Stone"
    },
    {
      "x": 3,
      "y": 18,
      "z": 1,
      "name": "Rock_Stone"
    },
    {
      "x": 3,
      "y": 19,
      "z": 1,
      "name": "Rock_Stone"
    },
    {
      "x": 3,
      "y": 20,
      "z": 1,
      "name": "Rock_Stone"
    },
    {
      "x": 3,
      "y": 21,
      "z": 1,
      "name": "Rock_Stone"
    },
    {
      "x": 3,
      "y": 22,
      "z": 1,
      "name": "Rock_Stone"
    },
    {
      "x": 3,
      "y": 23,
      "z": 1,
      "name": "Rock_Stone"
    },
    {
      "x": 3,
      "y": 24,
      "z": 1,
      "name": "Rock_Stone"
    },
    {
      "x": 3,
      "y": 25,
      "z": 1,
      "name": "Rock_Stone"
    },
    {
      "x": 3,
      "y": 11,
      "z": 2,
      "name": "Rock_Stone"
    },
    {
      "x": 3,
      "y": 12,
      "z": 2,
      "name": "Rock_Stone"
    },
    {
      "x": 3,
      "y": 13,
      "z": 2,
      "name": "Rock_Stone"
    },
    {
      "x": 3,
      "y": 14,
      "z": 2,
      "name": "Rock_Stone"
    },
    {
      "x": 3,
      "y": 15,
      "z": 2,
      "name": "Rock_Stone"
    },
    {
      "x": 3,
      "y": 16,
      "z": 2,
      "name": "Rock_Stone"
    },
    {
      "x": 3,
      "y": 17,
      "z": 2,
      "name": "Rock_Stone"
    },
    {
      "x": 3,
      "y": 18,
      "z": 2,
      "name": "Rock_Stone"
    },
    {
      "x": 3,
      "y": 19,
      "z": 2,
      "name": "Rock_Stone"
    },
    {
      "x": 3,
      "y": 20,
      "z": 2,
      "name": "Rock_Stone"
    },
    {
      "x": 3,
      "y": 21,
      "z": 2,
      "name": "Rock_Stone"
    },
    {
      "x": 3,
      "y": 22,
      "z": 2,
      "name": "Rock_Stone"
    },
    {
      "x": 3,
      "y": 23,
      "z": 2,
      "name": "Rock_Stone"
    },
    {
      "x": 3,
      "y": 24,
      "z": 2,
      "name": "Rock_Stone"
    },
    {
      "x": 3,
      "y": 25,
      "z": 2,
      "name": "Rock_Stone"
    },
    {
      "x": 3,
      "y": 11,
      "z": 3,
      "name": "Rock_Stone"
    },
    {
      "x": 3,
      "y": 12,
      "z": 3,
      "name": "Rock_Stone"
    },
    {
      "x": 3,
      "y": 13,
      "z": 3,
      "name": "Rock_Stone"
    },
    {
      "x": 3,
      "y": 14,
      "z": 3,
      "name": "Rock_Stone"
    },
    {
      "x": 3,
      "y": 15,
      "z": 3,
      "name": "Rock_Stone"
    },
    {
      "x": 3,
      "y": 16,
      "z": 3,
      "name": "Rock_Stone"
    },
    {
      "x": 3,
      "y": 17,
      "z": 3,
      "name": "Rock_Stone"
    },
    {
      "x": 3,
      "y": 18,
      "z": 3,
      "name": "Rock_Stone"
    },
    {
      "x": 3,
      "y": 19,
      "z": 3,
      "name": "Rock_Stone"
    },
    {
      "x": 3,
      "y": 20,
      "z": 3,
      "name": "Rock_Stone"
    },
    {
      "x": 3,
      "y": 21,
      "z": 3,
      "name": "Rock_Stone"
    },
    {
      "x": 3,
      "y": 22,
      "z": 3,
      "name": "Rock_Stone"
    },
    {
      "x": 3,
      "y": 23,
      "z": 3,
      "name": "Rock_Stone"
    },
    {
      "x": 3,
      "y": 24,
      "z": 3,
      "name": "Rock_Stone"
    },
    {
      "x": 3,
      "y": 25,
      "z": 3,
      "name": "Rock_Stone"
    },
    {
      "x": 3,
      "y": 26,
      "z": 3,
      "name": "Block_Spawner_Block",
      "components": {
        "Components": {
          "BlockSpawner": {
            "BlockSpawnerId": "Zone2_Encounters_Tier2"
          }
        }
      },
      "rotation": 2
    },
    {
      "x": 3,
      "y": 11,
      "z": 4,
      "name": "Rock_Stone"
    },
    {
      "x": 3,
      "y": 12,
      "z": 4,
      "name": "Rock_Stone"
    },
    {
      "x": 3,
      "y": 13,
      "z": 4,
      "name": "Rock_Stone"
    },
    {
      "x": 3,
      "y": 14,
      "z": 4,
      "name": "Rock_Stone"
    },
    {
      "x": 3,
      "y": 15,
      "z": 4,
      "name": "Rock_Stone"
    },
    {
      "x": 3,
      "y": 16,
      "z": 4,
      "name": "Rock_Stone"
    },
    {
      "x": 3,
      "y": 17,
      "z": 4,
      "name": "Rock_Stone"
    },
    {
      "x": 3,
      "y": 18,
      "z": 4,
      "name": "Rock_Stone"
    },
    {
      "x": 3,
      "y": 19,
      "z": 4,
      "name": "Rock_Stone"
    },
    {
      "x": 3,
      "y": 20,
      "z": 4,
      "name": "Rock_Stone"
    },
    {
      "x": 3,
      "y": 21,
      "z": 4,
      "name": "Rock_Stone"
    },
    {
      "x": 3,
      "y": 22,
      "z": 4,
      "name": "Rock_Stone"
    },
    {
      "x": 3,
      "y": 23,
      "z": 4,
      "name": "Rock_Stone"
    },
    {
      "x": 3,
      "y": 24,
      "z": 4,
      "name": "Rock_Stone"
    },
    {
      "x": 3,
      "y": 25,
      "z": 4,
      "name": "Rock_Stone"
    },
    {
      "x": 4,
      "y": 11,
      "z": -4,
      "name": "Rock_Stone"
    },
    {
      "x": 4,
      "y": 12,
      "z": -4,
      "name": "Rock_Stone"
    },
    {
      "x": 4,
      "y": 13,
      "z": -4,
      "name": "Rock_Stone"
    },
    {
      "x": 4,
      "y": 14,
      "z": -4,
      "name": "Rock_Stone"
    },
    {
      "x": 4,
      "y": 15,
      "z": -4,
      "name": "Rock_Stone"
    },
    {
      "x": 4,
      "y": 16,
      "z": -4,
      "name": "Rock_Stone"
    },
    {
      "x": 4,
      "y": 17,
      "z": -4,
      "name": "Rock_Stone"
    },
    {
      "x": 4,
      "y": 18,
      "z": -4,
      "name": "Rock_Stone"
    },
    {
      "x": 4,
      "y": 19,
      "z": -4,
      "name": "Rock_Stone"
    },
    {
      "x": 4,
      "y": 20,
      "z": -4,
      "name": "Rock_Stone"
    },
    {
      "x": 4,
      "y": 21,
      "z": -4,
      "name": "Rock_Stone"
    },
    {
      "x": 4,
      "y": 22,
      "z": -4,
      "name": "Rock_Stone"
    },
    {
      "x": 4,
      "y": 23,
      "z": -4,
      "name": "Rock_Stone"
    },
    {
      "x": 4,
      "y": 24,
      "z": -4,
      "name": "Rock_Stone"
    },
    {
      "x": 4,
      "y": 25,
      "z": -4,
      "name": "Rock_Stone"
    },
    {
      "x": 4,
      "y": 11,
      "z": -3,
      "name": "Rock_Stone"
    },
    {
      "x": 4,
      "y": 12,
      "z": -3,
      "name": "Rock_Stone"
    },
    {
      "x": 4,
      "y": 13,
      "z": -3,
      "name": "Rock_Stone"
    },
    {
      "x": 4,
      "y": 14,
      "z": -3,
      "name": "Rock_Stone"
    },
    {
      "x": 4,
      "y": 15,
      "z": -3,
      "name": "Rock_Stone"
    },
    {
      "x": 4,
      "y": 16,
      "z": -3,
      "name": "Rock_Stone"
    },
    {
      "x": 4,
      "y": 17,
      "z": -3,
      "name": "Rock_Stone"
    },
    {
      "x": 4,
      "y": 18,
      "z": -3,
      "name": "Rock_Stone"
    },
    {
      "x": 4,
      "y": 19,
      "z": -3,
      "name": "Rock_Stone"
    },
    {
      "x": 4,
      "y": 20,
      "z": -3,
      "name": "Rock_Stone"
    },
    {
      "x": 4,
      "y": 21,
      "z": -3,
      "name": "Rock_Stone"
    },
    {
      "x": 4,
      "y": 22,
      "z": -3,
      "name": "Rock_Stone"
    },
    {
      "x": 4,
      "y": 23,
      "z": -3,
      "name": "Rock_Stone"
    },
    {
      "x": 4,
      "y": 24,
      "z": -3,
      "name": "Rock_Stone"
    },
    {
      "x": 4,
      "y": 25,
      "z": -3,
      "name": "Rock_Stone"
    },
    {
      "x": 4,
      "y": 11,
      "z": -2,
      "name": "Rock_Stone"
    },
    {
      "x": 4,
      "y": 12,
      "z": -2,
      "name": "Rock_Stone"
    },
    {
      "x": 4,
      "y": 13,
      "z": -2,
      "name": "Rock_Stone"
    },
    {
      "x": 4,
      "y": 14,
      "z": -2,
      "name": "Rock_Stone"
    },
    {
      "x": 4,
      "y": 15,
      "z": -2,
      "name": "Rock_Stone"
    },
    {
      "x": 4,
      "y": 16,
      "z": -2,
      "name": "Rock_Stone"
    },
    {
      "x": 4,
      "y": 17,
      "z": -2,
      "name": "Rock_Stone"
    },
    {
      "x": 4,
      "y": 18,
      "z": -2,
      "name": "Rock_Stone"
    },
    {
      "x": 4,
      "y": 19,
      "z": -2,
      "name": "Rock_Stone"
    },
    {
      "x": 4,
      "y": 20,
      "z": -2,
      "name": "Rock_Stone"
    },
    {
      "x": 4,
      "y": 21,
      "z": -2,
      "name": "Rock_Stone"
    },
    {
      "x": 4,
      "y": 22,
      "z": -2,
      "name": "Rock_Stone"
    },
    {
      "x": 4,
      "y": 23,
      "z": -2,
      "name": "Rock_Stone"
    },
    {
      "x": 4,
      "y": 24,
      "z": -2,
      "name": "Rock_Stone"
    },
    {
      "x": 4,
      "y": 25,
      "z": -2,
      "name": "Rock_Stone"
    },
    {
      "x": 4,
      "y": 11,
      "z": -1,
      "name": "Rock_Stone"
    },
    {
      "x": 4,
      "y": 12,
      "z": -1,
      "name": "Rock_Stone"
    },
    {
      "x": 4,
      "y": 13,
      "z": -1,
      "name": "Rock_Stone"
    },
    {
      "x": 4,
      "y": 14,
      "z": -1,
      "name": "Rock_Stone"
    },
    {
      "x": 4,
      "y": 15,
      "z": -1,
      "name": "Rock_Stone"
    },
    {
      "x": 4,
      "y": 16,
      "z": -1,
      "name": "Rock_Stone"
    },
    {
      "x": 4,
      "y": 17,
      "z": -1,
      "name": "Rock_Stone"
    },
    {
      "x": 4,
      "y": 18,
      "z": -1,
      "name": "Rock_Stone"
    },
    {
      "x": 4,
      "y": 19,
      "z": -1,
      "name": "Rock_Stone"
    },
    {
      "x": 4,
      "y": 20,
      "z": -1,
      "name": "Rock_Stone"
    },
    {
      "x": 4,
      "y": 21,
      "z": -1,
      "name": "Rock_Stone"
    },
    {
      "x": 4,
      "y": 22,
      "z": -1,
      "name": "Rock_Stone"
    },
    {
      "x": 4,
      "y": 23,
      "z": -1,
      "name": "Rock_Stone"
    },
    {
      "x": 4,
      "y": 24,
      "z": -1,
      "name": "Rock_Stone"
    },
    {
      "x": 4,
      "y": 25,
      "z": -1,
      "name": "Rock_Stone"
    },
    {
      "x": 4,
      "y": 11,
      "z": 0,
      "name": "Rock_Stone"
    },
    {
      "x": 4,
      "y": 12,
      "z": 0,
      "name": "Rock_Stone"
    },
    {
      "x": 4,
      "y": 13,
      "z": 0,
      "name": "Rock_Stone"
    },
    {
      "x": 4,
      "y": 14,
      "z": 0,
      "name": "Rock_Stone"
    },
    {
      "x": 4,
      "y": 15,
      "z": 0,
      "name": "Rock_Stone"
    },
    {
      "x": 4,
      "y": 16,
      "z": 0,
      "name": "Rock_Stone"
    },
    {
      "x": 4,
      "y": 17,
      "z": 0,
      "name": "Rock_Stone"
    },
    {
      "x": 4,
      "y": 18,
      "z": 0,
      "name": "Rock_Stone"
    },
    {
      "x": 4,
      "y": 19,
      "z": 0,
      "name": "Rock_Stone"
    },
    {
      "x": 4,
      "y": 20,
      "z": 0,
      "name": "Rock_Stone"
    },
    {
      "x": 4,
      "y": 21,
      "z": 0,
      "name": "Rock_Stone"
    },
    {
      "x": 4,
      "y": 22,
      "z": 0,
      "name": "Rock_Stone"
    },
    {
      "x": 4,
      "y": 23,
      "z": 0,
      "name": "Rock_Stone"
    },
    {
      "x": 4,
      "y": 24,
      "z": 0,
      "name": "Rock_Stone"
    },
    {
      "x": 4,
      "y": 25,
      "z": 0,
      "name": "Rock_Stone"
    },
    {
      "x": 4,
      "y": 11,
      "z": 1,
      "name": "Rock_Stone"
    },
    {
      "x": 4,
      "y": 12,
      "z": 1,
      "name": "Rock_Stone"
    },
    {
      "x": 4,
      "y": 13,
      "z": 1,
      "name": "Rock_Stone"
    },
    {
      "x": 4,
      "y": 14,
      "z": 1,
      "name": "Rock_Stone"
    },
    {
      "x": 4,
      "y": 15,
      "z": 1,
      "name": "Rock_Stone"
    },
    {
      "x": 4,
      "y": 16,
      "z": 1,
      "name": "Rock_Stone"
    },
    {
      "x": 4,
      "y": 17,
      "z": 1,
      "name": "Rock_Stone"
    },
    {
      "x": 4,
      "y": 18,
      "z": 1,
      "name": "Rock_Stone"
    },
    {
      "x": 4,
      "y": 19,
      "z": 1,
      "name": "Rock_Stone"
    },
    {
      "x": 4,
      "y": 20,
      "z": 1,
      "name": "Rock_Stone"
    },
    {
      "x": 4,
      "y": 21,
      "z": 1,
      "name": "Rock_Stone"
    },
    {
      "x": 4,
      "y": 22,
      "z": 1,
      "name": "Rock_Stone"
    },
    {
      "x": 4,
      "y": 23,
      "z": 1,
      "name": "Rock_Stone"
    },
    {
      "x": 4,
      "y": 24,
      "z": 1,
      "name": "Rock_Stone"
    },
    {
      "x": 4,
      "y": 25,
      "z": 1,
      "name": "Rock_Stone"
    },
    {
      "x": 4,
      "y": 11,
      "z": 2,
      "name": "Rock_Stone"
    },
    {
      "x": 4,
      "y": 12,
      "z": 2,
      "name": "Rock_Stone"
    },
    {
      "x": 4,
      "y": 13,
      "z": 2,
      "name": "Rock_Stone"
    },
    {
      "x": 4,
      "y": 14,
      "z": 2,
      "name": "Rock_Stone"
    },
    {
      "x": 4,
      "y": 15,
      "z": 2,
      "name": "Rock_Stone"
    },
    {
      "x": 4,
      "y": 16,
      "z": 2,
      "name": "Rock_Stone"
    },
    {
      "x": 4,
      "y": 17,
      "z": 2,
      "name": "Rock_Stone"
    },
    {
      "x": 4,
      "y": 18,
      "z": 2,
      "name": "Rock_Stone"
    },
    {
      "x": 4,
      "y": 19,
      "z": 2,
      "name": "Rock_Stone"
    },
    {
      "x": 4,
      "y": 20,
      "z": 2,
      "name": "Rock_Stone"
    },
    {
      "x": 4,
      "y": 21,
      "z": 2,
