{
  "version": 8,
  "blockIdVersion": 8,
  "anchorX": 0,
  "anchorY": 4,
  "anchorZ": 0,
  "blocks": [
    {
      "x": -4,
      "y": 7,
      "z": -1,
      "name": "Wood_Ash_Branch_Corner",
      "rotation": 2
    },
    {
      "x": -4,
      "y": 8,
      "z": -1,
      "name": "Wood_Ash_Branch_Long"
    },
    {
      "x": -4,
      "y": 6,
      "z": 0,
      "name": "Wood_Ash_Branch_Corner",
      "rotation": 3
    },
    {
      "x": -4,
      "y": 7,
      "z": 0,
      "name": "Wood_Ash_Branch_Corner",
      "rotation": 10
    },
    {
      "x": -3,
      "y": 10,
      "z": -1,
      "name": "Wood_Ash_Branch_Corner",
      "rotation": 3
    },
    {
      "x": -3,
      "y": 11,
      "z": -1,
      "name": "Wood_Ash_Branch_Long"
    },
    {
      "x": -3,
      "y": 6,
      "z": 0,
      "name": "Wood_Ash_Branch_Long",
      "rotation": 5
    },
    {
      "x": -2,
      "y": 9,
      "z": -1,
      "name": "Wood_Ash_Trunk_Full"
    },
    {
      "x": -2,
      "y": 10,
      "z": -1,
      "name": "Wood_Ash_Trunk_Full"
    },
    {
      "x": -2,
      "y": 6,
      "z": 0,
      "name": "Wood_Ash_Trunk_Full"
    },
    {
      "x": -2,
      "y": 7,
      "z": 0,
      "name": "Wood_Ash_Trunk"
    },
    {
      "x": -2,
      "y": 8,
      "z": 0,
      "name": "Wood_Ash_Trunk"
    },
    {
      "x": -2,
      "y": 9,
      "z": 0,
      "name": "Wood_Ash_Trunk_Full"
    },
    {
      "x": -2,
      "y": 9,
      "z": 1,
      "name": "Wood_Ash_Branch_Long",
      "rotation": 5
    },
    {
      "x": -1,
      "y": 10,
      "z": -1,
      "name": "Wood_Ash_Trunk",
      "rotation": 5
    },
    {
      "x": -1,
      "y": 11,
      "z": -1,
      "name": "Wood_Ash_Branch_Long"
    },
    {
      "x": -1,
      "y": 12,
      "z": -1,
      "name": "Wood_Ash_Branch_Corner",
      "rotation": 9
    },
    {
      "x": -1,
      "y": 3,
      "z": 0,
      "name": "Wood_Ash_Trunk_Full"
    },
    {
      "x": -1,
      "y": 4,
      "z": 0,
      "name": "Wood_Ash_Trunk"
    },
    {
      "x": -1,
      "y": 5,
      "z": 0,
      "name": "Wood_Ash_Trunk"
    },
    {
      "x": -1,
      "y": 6,
      "z": 0,
      "name": "Wood_Ash_Trunk"
    },
    {
      "x": -1,
      "y": 7,
      "z": 0,
      "name": "Wood_Ash_Trunk_Full"
    },
    {
      "x": -1,
      "y": 8,
      "z": 0,
      "name": "Wood_Ash_Branch_Corner",
      "rotation": 8
    },
    {
      "x": -1,
      "y": 5,
      "z": 1,
      "name": "Wood_Ash_Trunk_Full"
    },
    {
      "x": -1,
      "y": 6,
      "z": 1,
      "name": "Wood_Ash_Trunk_Full",
      "rotation": 4
    },
    {
      "x": -1,
      "y": 8,
      "z": 1,
      "name": "Wood_Ash_Branch_Corner"
    },
    {
      "x": -1,
      "y": 9,
      "z": 1,
      "name": "Wood_Ash_Branch_Corner",
      "rotation": 11
    },
    {
      "x": 0,
      "y": 10,
      "z": -1,
      "name": "Wood_Ash_Trunk_Full",
      "rotation": 5
    },
    {
      "x": 0,
      "y": 12,
      "z": -1,
      "name": "Wood_Ash_Branch_Corner",
      "rotation": 1
    },
    {
      "x": 0,
      "y": 13,
      "z": -1,
      "name": "Wood_Ash_Branch_Long"
    },
    {
      "x": 0,
      "y": 4,
      "z": 0,
      "name": "Wood_Ash_Trunk_Full"
    },
    {
      "x": 0,
      "y": 4,
      "z": 1,
      "name": "Wood_Ash_Trunk_Full"
    },
    {
      "x": 0,
      "y": 5,
      "z": 1,
      "name": "Wood_Ash_Trunk_Full"
    },
    {
      "x": 1,
      "y": 10,
      "z": -1,
      "name": "Wood_Ash_Branch_Corner",
      "rotation": 1
    },
    {
      "x": 1,
      "y": 11,
      "z": -1,
      "name": "Wood_Ash_Branch_Corner",
      "rotation": 9
    },
    {
      "x": 1,
      "y": 3,
      "z": 1,
      "name": "Wood_Ash_Trunk_Full"
    },
    {
      "x": 1,
      "y": 4,
      "z": 1,
      "name": "Wood_Ash_Trunk"
    },
    {
      "x": 1,
      "y": 5,
      "z": 1,
      "name": "Wood_Ash_Trunk"
    },
    {
      "x": 1,
      "y": 6,
      "z": 1,
      "name": "Wood_Ash_Trunk_Full"
    },
    {
      "x": 1,
      "y": 5,
      "z": 2,
      "name": "Wood_Ash_Trunk_Full"
    },
    {
      "x": 1,
      "y": 6,
      "z": 2,
      "name": "Wood_Ash_Trunk_Full"
    },
    {
      "x": 2,
      "y": 11,
      "z": -1,
      "name": "Wood_Ash_Branch_Long",
      "rotation": 5
    },
    {
      "x": 2,
      "y": 6,
      "z": 2,
      "name": "Wood_Ash_Trunk_Full"
    },
    {
      "x": 2,
      "y": 7,
      "z": 2,
      "name": "Wood_Ash_Trunk"
    },
    {
      "x": 2,
      "y": 8,
      "z": 2,
      "name": "Wood_Ash_Trunk_Full"
    },
    {
      "x": 2,
      "y": 9,
      "z": 2,
      "name": "Wood_Ash_Branch_Long"
    }
  ]
}