{
  "version": 8,
  "blockIdVersion": 8,
  "anchorX": 0,
  "anchorY": 0,
  "anchorZ": 0,
  "blocks": [
    {
      "x": -11,
      "y": 17,
      "z": -4,
      "name": "Furniture_Lumberjack_Platform"
    },
    {
      "x": -11,
      "y": 17,
      "z": -3,
      "name": "Furniture_Lumberjack_Platform",
      "rotation": 1
    },
    {
      "x": -11,
      "y": 17,
      "z": -2,
      "name": "Furniture_Lumberjack_Platform",
      "rotation": 1
    },
    {
      "x": -11,
      "y": 17,
      "z": -1,
      "name": "Furniture_Lumberjack_Platform",
      "rotation": 1
    },
    {
      "x": -11,
      "y": 17,
      "z": 0,
      "name": "Furniture_Lumberjack_Platform"
    },
    {
      "x": -11,
      "y": 18,
      "z": 0,
      "name": "Wood_Softwood_Fence"
    },
    {
      "x": -11,
      "y": 19,
      "z": 0,
      "name": "Furniture_Crude_Torch"
    },
    {
      "x": -11,
      "y": 0,
      "z": 6,
      "name": "Wood_Fir_Trunk",
      "support": 15
    },
    {
      "x": -11,
      "y": 1,
      "z": 6,
      "name": "Wood_Fir_Trunk",
      "support": 15
    },
    {
      "x": -11,
      "y": 2,
      "z": 6,
      "name": "Wood_Fir_Trunk",
      "support": 15
    },
    {
      "x": -11,
      "y": 3,
      "z": 6,
      "name": "Wood_Fir_Trunk",
      "support": 15
    },
    {
      "x": -11,
      "y": 4,
      "z": 6,
      "name": "Wood_Fir_Trunk",
      "support": 15
    },
    {
      "x": -11,
      "y": 5,
      "z": 6,
      "name": "Wood_Fir_Trunk",
      "support": 15
    },
    {
      "x": -11,
      "y": 6,
      "z": 6,
      "name": "Wood_Fir_Trunk",
      "support": 15
    },
    {
      "x": -11,
      "y": 7,
      "z": 6,
      "name": "Wood_Fir_Trunk",
      "support": 15
    },
    {
      "x": -11,
      "y": 8,
      "z": 6,
      "name": "Wood_Fir_Trunk",
      "support": 15
    },
    {
      "x": -11,
      "y": 9,
      "z": 6,
      "name": "Wood_Fir_Trunk",
      "support": 15
    },
    {
      "x": -11,
      "y": 10,
      "z": 6,
      "name": "Wood_Fir_Trunk",
      "support": 15
    },
    {
      "x": -11,
      "y": 11,
      "z": 6,
      "name": "Wood_Fir_Trunk",
      "support": 15
    },
    {
      "x": -11,
      "y": 12,
      "z": 6,
      "name": "Wood_Fir_Trunk",
      "support": 15
    },
    {
      "x": -11,
      "y": 0,
      "z": 7,
      "name": "Wood_Fir_Trunk",
      "support": 15
    },
    {
      "x": -11,
      "y": 1,
      "z": 7,
      "name": "Wood_Fir_Trunk",
      "support": 15
    },
    {
      "x": -11,
      "y": 2,
      "z": 7,
      "name": "Wood_Fir_Trunk",
      "support": 15
    },
    {
      "x": -11,
      "y": 3,
      "z": 7,
      "name": "Wood_Fir_Trunk",
      "support": 15
    },
    {
      "x": -11,
      "y": 4,
      "z": 7,
      "name": "Wood_Fir_Trunk",
      "support": 15
    },
    {
      "x": -11,
      "y": 5,
      "z": 7,
      "name": "Wood_Fir_Trunk",
      "support": 15
    },
    {
      "x": -11,
      "y": 6,
      "z": 7,
      "name": "Wood_Fir_Trunk",
      "support": 15
    },
    {
      "x": -11,
      "y": 7,
      "z": 7,
      "name": "Wood_Fir_Trunk",
      "support": 15
    },
    {
      "x": -11,
      "y": 8,
      "z": 7,
      "name": "Wood_Fir_Trunk",
      "support": 15
    },
    {
      "x": -11,
      "y": 9,
      "z": 7,
      "name": "Wood_Fir_Trunk",
      "support": 15
    },
    {
      "x": -11,
      "y": 10,
      "z": 7,
      "name": "Wood_Fir_Trunk",
      "support": 15
    },
    {
      "x": -11,
      "y": 11,
      "z": 7,
      "name": "Wood_Fir_Trunk",
      "support": 15
    },
    {
      "x": -11,
      "y": 12,
      "z": 7,
      "name": "Wood_Fir_Trunk",
      "support": 15
    },
    {
      "x": -11,
      "y": 13,
      "z": 7,
      "name": "Wood_Fir_Trunk",
      "support": 15
    },
    {
      "x": -11,
      "y": 14,
      "z": 7,
      "name": "Survival_Trap_Spike_Wood_Large"
    },
    {
      "x": -11,
      "y": 0,
      "z": 8,
      "name": "Furniture_Tavern_Ladder",
      "rotation": 3
    },
    {
      "x": -11,
      "y": 1,
      "z": 8,
      "name": "Furniture_Tavern_Ladder",
      "rotation": 3
    },
    {
      "x": -11,
      "y": 2,
      "z": 8,
      "name": "Furniture_Tavern_Ladder",
      "rotation": 3
    },
    {
      "x": -11,
      "y": 3,
      "z": 8,
      "name": "Furniture_Tavern_Ladder",
      "rotation": 3
    },
    {
      "x": -11,
      "y": 4,
      "z": 8,
      "name": "Furniture_Tavern_Ladder",
      "rotation": 3
    },
    {
      "x": -11,
      "y": 5,
      "z": 8,
      "name": "Furniture_Tavern_Ladder",
      "rotation": 3
    },
    {
      "x": -11,
      "y": 6,
      "z": 8,
      "name": "Furniture_Tavern_Ladder",
      "rotation": 3
    },
    {
      "x": -11,
      "y": 7,
      "z": 8,
      "name": "Furniture_Tavern_Ladder",
      "rotation": 3
    },
    {
      "x": -11,
      "y": 8,
      "z": 8,
      "name": "Furniture_Tavern_Ladder",
      "rotation": 3
    },
    {
      "x": -11,
      "y": 9,
      "z": 8,
      "name": "Furniture_Tavern_Ladder",
      "rotation": 3
    },
    {
      "x": -11,
      "y": 10,
      "z": 8,
      "name": "Furniture_Tavern_Ladder",
      "rotation": 3
    },
    {
      "x": -11,
      "y": 11,
      "z": 8,
      "name": "Furniture_Tavern_Ladder",
      "rotation": 3
    },
    {
      "x": -11,
      "y": 0,
      "z": 9,
      "name": "Wood_Fir_Trunk",
      "support": 15
    },
    {
      "x": -11,
      "y": 1,
      "z": 9,
      "name": "Wood_Fir_Trunk",
      "support": 15
    },
    {
      "x": -11,
      "y": 2,
      "z": 9,
      "name": "Wood_Fir_Trunk",
      "support": 15
    },
    {
      "x": -11,
      "y": 3,
      "z": 9,
      "name": "Wood_Fir_Trunk",
      "support": 15
    },
    {
      "x": -11,
      "y": 4,
      "z": 9,
      "name": "Wood_Fir_Trunk",
      "support": 15
    },
    {
      "x": -11,
      "y": 5,
      "z": 9,
      "name": "Wood_Fir_Trunk",
      "support": 15
    },
    {
      "x": -11,
      "y": 6,
      "z": 9,
      "name": "Wood_Fir_Trunk",
      "support": 15
    },
    {
      "x": -11,
      "y": 7,
      "z": 9,
      "name": "Wood_Fir_Trunk",
      "support": 15
    },
    {
      "x": -11,
      "y": 8,
      "z": 9,
      "name": "Wood_Fir_Trunk",
      "support": 15
    },
    {
      "x": -11,
      "y": 9,
      "z": 9,
      "name": "Wood_Fir_Trunk",
      "support": 15
    },
    {
      "x": -11,
      "y": 10,
      "z": 9,
      "name": "Wood_Fir_Trunk",
      "support": 15
    },
    {
      "x": -11,
      "y": 11,
      "z": 9,
      "name": "Wood_Fir_Trunk",
      "support": 15
    },
    {
      "x": -11,
      "y": 12,
      "z": 9,
      "name": "Wood_Fir_Trunk",
      "support": 15
    },
    {
      "x": -11,
      "y": 13,
      "z": 9,
      "name": "Wood_Fir_Branch_Long",
      "support": 15
    },
    {
      "x": -11,
      "y": 0,
      "z": 10,
      "name": "Wood_Fir_Trunk",
      "support": 15
    },
    {
      "x": -11,
      "y": 1,
      "z": 10,
      "name": "Wood_Fir_Trunk",
      "support": 15
    },
    {
      "x": -11,
      "y": 2,
      "z": 10,
      "name": "Wood_Fir_Trunk",
      "support": 15
    },
    {
      "x": -11,
      "y": 3,
      "z": 10,
      "name": "Wood_Fir_Trunk",
      "support": 15
    },
    {
      "x": -11,
      "y": 4,
      "z": 10,
      "name": "Wood_Fir_Trunk",
      "support": 15
    },
    {
      "x": -11,
      "y": 5,
      "z": 10,
      "name": "Wood_Fir_Trunk",
      "support": 15
    },
    {
      "x": -11,
      "y": 6,
      "z": 10,
      "name": "Wood_Fir_Trunk",
      "support": 15
    },
    {
      "x": -11,
      "y": 7,
      "z": 10,
      "name": "Wood_Fir_Trunk",
      "support": 15
    },
    {
      "x": -11,
      "y": 8,
      "z": 10,
      "name": "Wood_Fir_Trunk",
      "support": 15
    },
    {
      "x": -11,
      "y": 9,
      "z": 10,
      "name": "Wood_Fir_Trunk",
      "support": 15
    },
    {
      "x": -11,
      "y": 10,
      "z": 10,
      "name": "Wood_Fir_Trunk",
      "support": 15
    },
    {
      "x": -10,
      "y": 17,
      "z": -7,
      "name": "Wood_Redwood_Trunk",
      "rotation": 5
    },
    {
      "x": -10,
      "y": 17,
      "z": -4,
      "name": "Furniture_Lumberjack_Platform"
    },
    {
      "x": -10,
      "y": 18,
      "z": -4,
      "name": "Wood_Softwood_Fence",
      "rotation": 2
    },
    {
      "x": -10,
      "y": 17,
      "z": -3,
      "name": "Furniture_Lumberjack_Platform",
      "rotation": 1
    },
    {
      "x": -10,
      "y": 17,
      "z": -2,
      "name": "Furniture_Lumberjack_Platform",
      "rotation": 1
    },
    {
      "x": -10,
      "y": 21,
      "z": -2,
      "name": "Wood_Redwood_Stairs",
      "rotation": 9
    },
    {
      "x": -10,
      "y": 22,
      "z": -2,
      "name": "Wood_Redwood_Trunk",
      "rotation": 5
    },
    {
      "x": -10,
      "y": 17,
      "z": -1,
      "name": "Furniture_Lumberjack_Platform",
      "rotation": 1
    },
    {
      "x": -10,
      "y": 17,
      "z": 0,
      "name": "Furniture_Lumberjack_Platform"
    },
    {
      "x": -10,
      "y": 18,
      "z": 0,
      "name": "Wood_Softwood_Fence"
    },
    {
      "x": -10,
      "y": 17,
      "z": 3,
      "name": "Wood_Redwood_Trunk",
      "rotation": 5
    },
    {
      "x": -10,
      "y": 0,
      "z": 5,
      "name": "Wood_Fir_Trunk",
      "support": 15
    },
    {
      "x": -10,
      "y": 1,
      "z": 5,
      "name": "Wood_Fir_Trunk",
      "support": 15
    },
    {
      "x": -10,
      "y": 2,
      "z": 5,
      "name": "Wood_Fir_Trunk",
      "support": 15
    },
    {
      "x": -10,
      "y": 3,
      "z": 5,
      "name": "Wood_Fir_Trunk",
      "support": 15
    },
    {
      "x": -10,
      "y": 4,
      "z": 5,
      "name": "Wood_Fir_Trunk",
      "support": 15
    },
    {
      "x": -10,
      "y": 5,
      "z": 5,
      "name": "Wood_Fir_Trunk",
      "support": 15
    },
    {
      "x": -10,
      "y": 6,
      "z": 5,
      "name": "Wood_Fir_Trunk",
      "support": 15
    },
    {
      "x": -10,
      "y": 7,
      "z": 5,
      "name": "Wood_Fir_Trunk",
      "support": 15
    },
    {
      "x": -10,
      "y": 8,
      "z": 5,
      "name": "Wood_Fir_Trunk",
      "support": 15
    },
    {
      "x": -10,
      "y": 9,
      "z": 5,
      "name": "Wood_Fir_Trunk",
      "support": 15
    },
    {
      "x": -10,
      "y": 10,
      "z": 5,
      "name": "Wood_Fir_Trunk",
      "support": 15
    },
    {
      "x": -10,
      "y": 11,
      "z": 5,
      "name": "Wood_Fir_Trunk",
      "support": 15
    },
    {
      "x": -10,
      "y": 12,
      "z": 5,
      "name": "Wood_Fir_Trunk",
      "support": 15
    },
    {
      "x": -10,
      "y": 0,
      "z": 6,
      "name": "Soil_Dirt_Cold"
    },
    {
      "x": -10,
      "y": 1,
      "z": 6,
      "name": "Soil_Dirt_Cold"
    },
    {
      "x": -10,
      "y": 2,
      "z": 6,
      "name": "Soil_Dirt_Cold"
    },
    {
      "x": -10,
      "y": 3,
      "z": 6,
      "name": "Soil_Dirt_Cold"
    },
    {
      "x": -10,
      "y": 4,
      "z": 6,
      "name": "Soil_Dirt_Cold"
    },
    {
      "x": -10,
      "y": 5,
      "z": 6,
      "name": "Soil_Dirt_Cold"
    },
    {
      "x": -10,
      "y": 6,
      "z": 6,
      "name": "Soil_Dirt_Cold"
    },
    {
      "x": -10,
      "y": 7,
      "z": 6,
      "name": "Soil_Dirt_Cold"
    },
    {
      "x": -10,
      "y": 8,
      "z": 6,
      "name": "Soil_Dirt_Cold"
    },
    {
      "x": -10,
      "y": 9,
      "z": 6,
      "name": "Soil_Dirt_Cold"
    },
    {
      "x": -10,
      "y": 10,
      "z": 6,
      "name": "Soil_Dirt_Cold"
    },
    {
      "x": -10,
      "y": 11,
      "z": 6,
      "name": "Soil_Dirt_Cold"
    },
    {
      "x": -10,
      "y": 0,
      "z": 7,
      "name": "Soil_Dirt_Cold"
    },
    {
      "x": -10,
      "y": 1,
      "z": 7,
      "name": "Soil_Dirt_Cold"
    },
    {
      "x": -10,
      "y": 2,
      "z": 7,
      "name": "Soil_Dirt_Cold"
    },
    {
      "x": -10,
      "y": 3,
      "z": 7,
      "name": "Soil_Dirt_Cold"
    },
    {
      "x": -10,
      "y": 4,
      "z": 7,
      "name": "Soil_Dirt_Cold"
    },
    {
      "x": -10,
      "y": 5,
      "z": 7,
      "name": "Soil_Dirt_Cold"
    },
    {
      "x": -10,
      "y": 6,
      "z": 7,
      "name": "Soil_Dirt_Cold"
    },
    {
      "x": -10,
      "y": 7,
      "z": 7,
      "name": "Soil_Dirt_Cold"
    },
    {
      "x": -10,
      "y": 8,
      "z": 7,
      "name": "Soil_Dirt_Cold"
    },
    {
      "x": -10,
      "y": 9,
      "z": 7,
      "name": "Soil_Dirt_Cold"
    },
    {
      "x": -10,
      "y": 10,
      "z": 7,
      "name": "Soil_Dirt_Cold"
    },
    {
      "x": -10,
      "y": 11,
      "z": 7,
      "name": "Wood_Fir_Trunk",
      "support": 15,
      "rotation": 4
    },
    {
      "x": -10,
      "y": 0,
      "z": 8,
      "name": "Soil_Dirt_Cold"
    },
    {
      "x": -10,
      "y": 1,
      "z": 8,
      "name": "Soil_Dirt_Cold"
    },
    {
      "x": -10,
      "y": 2,
      "z": 8,
      "name": "Soil_Dirt_Cold"
    },
    {
      "x": -10,
      "y": 3,
      "z": 8,
      "name": "Soil_Dirt_Cold"
    },
    {
      "x": -10,
      "y": 4,
      "z": 8,
      "name": "Soil_Dirt_Cold"
    },
    {
      "x": -10,
      "y": 5,
      "z": 8,
      "name": "Soil_Dirt_Cold"
    },
    {
      "x": -10,
      "y": 6,
      "z": 8,
      "name": "Soil_Dirt_Cold"
    },
    {
      "x": -10,
      "y": 7,
      "z": 8,
      "name": "Soil_Dirt_Cold"
    },
    {
      "x": -10,
      "y": 8,
      "z": 8,
      "name": "Soil_Dirt_Cold"
    },
    {
      "x": -10,
      "y": 9,
      "z": 8,
      "name": "Soil_Dirt_Cold"
    },
    {
      "x": -10,
      "y": 10,
      "z": 8,
      "name": "Soil_Dirt_Cold"
    },
    {
      "x": -10,
      "y": 11,
      "z": 8,
      "name": "Wood_Fir_Trunk",
      "support": 15,
      "rotation": 4
    },
    {
      "x": -10,
      "y": 0,
      "z": 9,
      "name": "Soil_Dirt_Cold"
    },
    {
      "x": -10,
      "y": 1,
      "z": 9,
      "name": "Soil_Dirt_Cold"
    },
    {
      "x": -10,
      "y": 2,
      "z": 9,
      "name": "Soil_Dirt_Cold"
    },
    {
      "x": -10,
      "y": 3,
      "z": 9,
      "name": "Soil_Dirt_Cold"
    },
    {
      "x": -10,
      "y": 4,
      "z": 9,
      "name": "Soil_Dirt_Cold"
    },
    {
      "x": -10,
      "y": 5,
      "z": 9,
      "name": "Soil_Dirt_Cold"
    },
    {
      "x": -10,
      "y": 6,
      "z": 9,
      "name": "Soil_Dirt_Cold"
    },
    {
      "x": -10,
      "y": 7,
      "z": 9,
      "name": "Soil_Dirt_Cold"
    },
    {
      "x": -10,
      "y": 8,
      "z": 9,
      "name": "Soil_Dirt_Cold"
    },
    {
      "x": -10,
      "y": 9,
      "z": 9,
      "name": "Soil_Dirt_Cold"
    },
    {
      "x": -10,
      "y": 10,
      "z": 9,
      "name": "Soil_Dirt_Cold"
    },
    {
      "x": -10,
      "y": 11,
      "z": 9,
      "name": "Wood_Fir_Trunk",
      "support": 15,
      "rotation": 4
    },
    {
      "x": -10,
      "y": 0,
      "z": 10,
      "name": "Wood_Fir_Trunk",
      "support": 15
    },
    {
      "x": -10,
      "y": 1,
      "z": 10,
      "name": "Wood_Fir_Trunk",
      "support": 15
    },
    {
      "x": -10,
      "y": 2,
      "z": 10,
      "name": "Wood_Fir_Trunk",
      "support": 15
    },
    {
      "x": -10,
      "y": 3,
      "z": 10,
      "name": "Wood_Fir_Trunk",
      "support": 15
    },
    {
      "x": -10,
      "y": 4,
      "z": 10,
      "name": "Wood_Fir_Trunk",
      "support": 15
    },
    {
      "x": -10,
      "y": 5,
      "z": 10,
      "name": "Wood_Fir_Trunk",
      "support": 15
    },
    {
      "x": -10,
      "y": 6,
      "z": 10,
      "name": "Wood_Fir_Trunk",
      "support": 15
    },
    {
      "x": -10,
      "y": 7,
      "z": 10,
      "name": "Wood_Fir_Trunk",
      "support": 15
    },
    {
      "x": -10,
      "y": 8,
      "z": 10,
      "name": "Wood_Fir_Trunk",
      "support": 15
    },
    {
      "x": -10,
      "y": 9,
      "z": 10,
      "name": "Wood_Fir_Trunk",
      "support": 15
    },
    {
      "x": -10,
      "y": 10,
      "z": 10,
      "name": "Wood_Fir_Trunk",
      "support": 15
    },
    {
      "x": -10,
      "y": 11,
      "z": 10,
      "name": "Wood_Fir_Trunk",
      "support": 15
    },
    {
      "x": -10,
      "y": 12,
      "z": 10,
      "name": "Wood_Fir_Trunk",
      "support": 15
    },
    {
      "x": -9,
      "y": 0,
      "z": -9,
      "name": "Wood_Fir_Trunk",
      "support": 15
    },
    {
      "x": -9,
      "y": 1,
      "z": -9,
      "name": "Wood_Fir_Trunk",
      "support": 15
    },
    {
      "x": -9,
      "y": 2,
      "z": -9,
      "name": "Wood_Fir_Trunk",
      "support": 15
    },
    {
      "x": -9,
      "y": 3,
      "z": -9,
      "name": "Wood_Fir_Trunk",
      "support": 15
    },
    {
      "x": -9,
      "y": 4,
      "z": -9,
      "name": "Wood_Fir_Trunk",
      "support": 15
    },
    {
      "x": -9,
      "y": 5,
      "z": -9,
      "name": "Wood_Fir_Trunk",
      "support": 15
    },
    {
      "x": -9,
      "y": 6,
      "z": -9,
      "name": "Wood_Fir_Trunk",
      "support": 15
    },
    {
      "x": -9,
      "y": 7,
      "z": -9,
      "name": "Wood_Fir_Trunk",
      "support": 15
    },
    {
      "x": -9,
      "y": 8,
      "z": -9,
      "name": "Wood_Fir_Trunk",
      "support": 15
    },
    {
      "x": -9,
      "y": 9,
      "z": -9,
      "name": "Wood_Fir_Trunk",
      "support": 15
    },
    {
      "x": -9,
      "y": 10,
      "z": -9,
      "name": "Wood_Fir_Trunk",
      "support": 15
    },
    {
      "x": -9,
      "y": 11,
      "z": -9,
      "name": "Wood_Fir_Trunk",
      "support": 15
    },
    {
      "x": -9,
      "y": 12,
      "z": -9,
      "name": "Wood_Fir_Trunk",
      "support": 15
    },
    {
      "x": -9,
      "y": 13,
      "z": -9,
      "name": "Wood_Fir_Trunk",
      "support": 15
    },
    {
      "x": -9,
      "y": 14,
      "z": -9,
      "name": "Survival_Trap_Spike_Wood_Large"
    },
    {
      "x": -9,
      "y": 0,
      "z": -8,
      "name": "Wood_Fir_Trunk",
      "support": 15
    },
    {
      "x": -9,
      "y": 1,
      "z": -8,
      "name": "Wood_Fir_Trunk",
      "support": 15
    },
    {
      "x": -9,
      "y": 2,
      "z": -8,
      "name": "Wood_Fir_Trunk",
      "support": 15
    },
    {
      "x": -9,
      "y": 3,
      "z": -8,
      "name": "Wood_Fir_Trunk",
      "support": 15
    },
    {
      "x": -9,
      "y": 4,
      "z": -8,
      "name": "Wood_Fir_Trunk",
      "support": 15
    },
    {
      "x": -9,
      "y": 5,
      "z": -8,
      "name": "Wood_Fir_Trunk",
      "support": 15
    },
    {
      "x": -9,
      "y": 6,
      "z": -8,
      "name": "Wood_Fir_Trunk",
      "support": 15
    },
    {
      "x": -9,
      "y": 7,
      "z": -8,
      "name": "Wood_Fir_Trunk",
      "support": 15
    },
    {
      "x": -9,
      "y": 8,
      "z": -8,
      "name": "Wood_Fir_Trunk",
      "support": 15
    },
    {
      "x": -9,
      "y": 9,
      "z": -8,
      "name": "Wood_Fir_Trunk",
      "support": 15
    },
    {
      "x": -9,
      "y": 10,
      "z": -8,
      "name": "Wood_Fir_Trunk",
      "support": 15
    },
    {
      "x": -9,
      "y": 11,
      "z": -8,
      "name": "Wood_Fir_Trunk",
      "support": 15
    },
    {
      "x": -9,
      "y": 12,
      "z": -8,
      "name": "Wood_Fir_Trunk",
      "support": 15
    },
    {
      "x": -9,
      "y": 13,
      "z": -8,
      "name": "Wood_Fir_Trunk",
      "support": 15
    },
    {
      "x": -9,
      "y": 16,
      "z": -8,
      "name": "Wood_Redwood_Trunk",
      "rotation": 4
    },
    {
      "x": -9,
      "y": 0,
      "z": -7,
      "name": "Wood_Fir_Trunk",
      "support": 15
    },
    {
      "x": -9,
      "y": 1,
      "z": -7,
      "name": "Wood_Fir_Trunk",
      "support": 15
    },
    {
      "x": -9,
      "y": 2,
      "z": -7,
      "name": "Wood_Fir_Trunk",
      "support": 15
    },
    {
      "x": -9,
      "y": 3,
      "z": -7,
      "name": "Wood_Fir_Trunk",
      "support": 15
    },
    {
      "x": -9,
      "y": 4,
      "z": -7,
      "name": "Wood_Fir_Trunk",
      "support": 15
    },
    {
      "x": -9,
      "y": 5,
      "z": -7,
      "name": "Wood_Fir_Trunk",
      "support": 15
    },
    {
      "x": -9,
      "y": 6,
      "z": -7,
      "name": "Wood_Fir_Trunk",
      "support": 15
    },
    {
      "x": -9,
      "y": 7,
      "z": -7,
      "name": "Wood_Fir_Trunk",
      "support": 15
    },
    {
      "x": -9,
      "y": 8,
      "z": -7,
      "name": "Wood_Fir_Trunk",
      "support": 15
    },
    {
      "x": -9,
      "y": 9,
      "z": -7,
      "name": "Wood_Fir_Trunk",
      "support": 15
    },
    {
      "x": -9,
      "y": 10,
      "z": -7,
      "name": "Wood_Fir_Trunk",
      "support": 15
    },
    {
      "x": -9,
      "y": 11,
      "z": -7,
      "name": "Wood_Fir_Trunk",
      "support": 15
    },
    {
      "x": -9,
      "y": 12,
      "z": -7,
      "name": "Wood_Redwood_Trunk",
      "rotation": 4
    },
    {
      "x": -9,
      "y": 16,
      "z": -7,
      "name": "Wood_Redwood_Trunk",
      "rotation": 4
    },
    {
      "x": -9,
      "y": 17,
      "z": -7,
      "name": "Wood_Redwood_Trunk",
      "rotation": 5
    },
    {
      "x": -9,
      "y": 18,
      "z": -7,
      "name": "Rock_Basalt_Cobble_Roof",
      "rotation": 2
    },
    {
      "x": -9,
      "y": 0,
      "z": -6,
      "name": "Wood_Fir_Trunk",
      "support": 15
    },
    {
      "x": -9,
      "y": 1,
      "z": -6,
      "name": "Wood_Fir_Trunk",
      "support": 15
    },
    {
      "x": -9,
      "y": 2,
      "z": -6,
      "name": "Wood_Fir_Trunk",
      "support": 15
    },
    {
      "x": -9,
      "y": 3,
      "z": -6,
      "name": "Wood_Fir_Trunk",
      "support": 15
    },
    {
      "x": -9,
      "y": 4,
      "z": -6,
      "name": "Wood_Fir_Trunk",
      "support": 15
    },
    {
      "x": -9,
      "y": 5,
      "z": -6,
      "name": "Wood_Fir_Trunk",
      "support": 15
    },
    {
      "x": -9,
      "y": 6,
      "z": -6,
      "name": "Wood_Fir_Trunk",
      "support": 15
    },
    {
      "x": -9,
      "y": 7,
      "z": -6,
      "name": "Wood_Fir_Trunk",
      "support": 15
    },
    {
      "x": -9,
      "y": 8,
      "z": -6,
      "name": "Wood_Fir_Trunk",
      "support": 15
    },
    {
      "x": -9,
      "y": 9,
      "z": -6,
      "name": "Wood_Fir_Trunk",
      "support": 15
    },
    {
      "x": -9,
      "y": 10,
      "z": -6,
      "name": "Wood_Fir_Trunk",
      "support": 15
    },
    {
      "x": -9,
      "y": 11,
      "z": -6,
      "name": "Wood_Redwood_Trunk"
    },
    {
      "x": -9,
      "y": 12,
      "z": -6,
      "name": "Wood_Redwood_Trunk",
      "rotation": 4
    },
    {
      "x": -9,
      "y": 13,
      "z": -6,
      "name": "Wood_Redwood_Trunk"
    },
    {
      "x": -9,
      "y": 14,
      "z": -6,
      "name": "Wood_Redwood_Trunk"
    },
    {
      "x": -9,
      "y": 15,
      "z": -6,
      "name": "Wood_Redwood_Trunk"
    },
    {
      "x": -9,
      "y": 16,
      "z": -6,
      "name": "Wood_Redwood_Trunk",
      "rotation": 4
    },
    {
      "x": -9,
      "y": 17,
      "z": -6,
      "name": "Wood_Redwood_Stairs",
      "rotation": 10
    },
    {
      "x": -9,
      "y": 18,
      "z": -6,
      "name": "Wood_Redwood_Planks"
    },
    {
      "x": -9,
      "y": 19,
      "z": -6,
      "name": "Rock_Basalt_Cobble_Roof",
      "rotation": 2
    },
    {
      "x": -9,
      "y": 0,
      "z": -5,
      "name": "Rock_Shale"
    },
    {
      "x": -9,
      "y": 1,
      "z": -5,
      "name": "Rock_Shale"
    },
    {
      "x": -9,
      "y": 2,
      "z": -5,
      "name": "Rock_Shale"
    },
    {
      "x": -9,
      "y": 3,
      "z": -5,
      "name": "Rock_Shale"
    },
    {
      "x": -9,
      "y": 4,
      "z": -5,
      "name": "Rock_Shale"
    },
    {
      "x": -9,
      "y": 5,
      "z": -5,
      "name": "Rock_Shale_Cobble"
    },
    {
      "x": -9,
      "y": 6,
      "z": -5,
      "name": "Rock_Shale_Cobble"
    },
    {
      "x": -9,
      "y": 7,
      "z": -5,
      "name": "Rock_Shale_Cobble"
    },
    {
      "x": -9,
      "y": 8,
      "z": -5,
      "name": "Rock_Shale_Brick"
    },
    {
      "x": -9,
      "y": 9,
      "z": -5,
      "name": "Rock_Shale_Brick"
    },
    {
      "x": -9,
      "y": 10,
      "z": -5,
      "name": "Rock_Shale_Brick"
    },
    {
      "x": -9,
      "y": 11,
      "z": -5,
      "name": "Rock_Shale_Brick"
    },
    {
      "x": -9,
      "y": 12,
      "z": -5,
      "name": "Wood_Redwood_Trunk",
      "rotation": 4
    },
    {
      "x": -9,
      "y": 13,
      "z": -5,
      "name": "Rock_Shale_Brick_Half",
      "rotation": 7
    },
    {
      "x": -9,
      "y": 14,
      "z": -5,
      "name": "Rock_Shale_Brick_Half",
      "rotation": 7
    },
    {
      "x": -9,
      "y": 16,
      "z": -5,
      "name": "Wood_Redwood_Trunk",
      "rotation": 4
    },
    {
      "x": -9,
      "y": 18,
      "z": -5,
      "name": "Wood_Redwood_Stairs",
      "rotation": 10
    },
    {
      "x": -9,
      "y": 19,
      "z": -5,
      "name": "Wood_Redwood_Planks"
    },
    {
      "x": -9,
      "y": 20,
      "z": -5,
      "name": "Rock_Basalt_Cobble_Roof",
      "rotation": 2
    },
    {
      "x": -9,
      "y": 0,
      "z": -4,
      "name": "Rock_Shale"
    },
    {
      "x": -9,
      "y": 1,
      "z": -4,
      "name": "Rock_Shale"
    },
    {
      "x": -9,
      "y": 2,
      "z": -4,
      "name": "Rock_Shale"
    },
    {
      "x": -9,
      "y": 3,
      "z": -4,
      "name": "Rock_Shale"
    },
    {
      "x": -9,
      "y": 4,
      "z": -4,
      "name": "Rock_Shale_Cobble"
    },
    {
      "x": -9,
      "y": 5,
      "z": -4,
      "name": "Rock_Shale_Cobble"
    },
    {
      "x": -9,
      "y": 6,
      "z": -4,
      "name": "Rock_Shale_Cobble"
    },
    {
      "x": -9,
      "y": 7,
      "z": -4,
      "name": "Rock_Shale_Cobble"
    },
    {
      "x": -9,
      "y": 8,
      "z": -4,
      "name": "Rock_Shale_Cobble"
    },
    {
      "x": -9,
      "y": 9,
      "z": -4,
      "name": "Rock_Shale_Brick"
    },
    {
      "x": -9,
      "y": 10,
      "z": -4,
      "name": "Rock_Shale_Brick"
    },
    {
      "x": -9,
      "y": 11,
      "z": -4,
      "name": "Rock_Shale_Brick"
    },
    {
      "x": -9,
      "y": 12,
      "z": -4,
      "name": "Wood_Redwood_Trunk",
      "rotation": 4
    },
    {
      "x": -9,
      "y": 16,
      "z": -4,
      "name": "Wood_Redwood_Trunk",
      "rotation": 4
    },
    {
      "x": -9,
      "y": 17,
      "z": -4,
      "name": "Furniture_Lumberjack_Platform"
    },
    {
      "x": -9,
      "y": 18,
      "z": -4,
      "name": "Wood_Softwood_Fence",
      "rotation": 2
    },
    {
      "x": -9,
      "y": 19,
      "z": -4,
      "name": "Wood_Redwood_Stairs",
      "rotation": 10
    },
    {
      "x": -9,
      "y": 20,
      "z": -4,
      "name": "Wood_Redwood_Stairs",
      "rotation": 2
    },
    {
      "x": -9,
      "y": 23,
      "z": -4,
      "name": "Wood_Redwood_Planks_Half",
      "rotation": 6
    },
    {
      "x": -9,
      "y": 0,
      "z": -3,
      "name": "Rock_Shale"
    },
    {
      "x": -9,
      "y": 1,
      "z": -3,
      "name": "Rock_Shale"
    },
    {
      "x": -9,
      "y": 2,
      "z": -3,
      "name": "Rock_Shale"
    },
    {
      "x": -9,
      "y": 3,
      "z": -3,
      "name": "Rock_Shale"
    },
    {
      "x": -9,
      "y": 4,
      "z": -3,
      "name": "Rock_Shale_Cobble"
    },
    {
      "x": -9,
      "y": 5,
      "z": -3,
      "name": "Rock_Shale_Cobble"
    },
    {
      "x": -9,
      "y": 6,
      "z": -3,
      "name": "Rock_Shale_Cobble"
    },
    {
      "x": -9,
      "y": 7,
      "z": -3,
      "name": "Rock_Shale_Cobble"
    },
    {
      "x": -9,
      "y": 8,
      "z": -3,
      "name": "Rock_Shale_Cobble"
    },
    {
      "x": -9,
      "y": 9,
      "z": -3,
      "name": "Rock_Shale_Brick"
    },
    {
      "x": -9,
      "y": 10,
      "z": -3,
      "name": "Rock_Shale_Brick"
    },
    {
      "x": -9,
      "y": 11,
      "z": -3,
      "name": "Rock_Shale_Brick"
    },
    {
      "x": -9,
      "y": 12,
      "z": -3,
      "name": "Wood_Redwood_Trunk",
      "rotation": 4
    },
    {
      "x": -9,
      "y": 16,
      "z": -3,
      "name": "Wood_Redwood_Trunk",
      "rotation": 4
    },
    {
      "x": -9,
      "y": 17,
      "z": -3,
      "name": "Furniture_Lumberjack_Platform",
      "rotation": 1
    },
    {
      "x": -9,
      "y": 18,
      "z": -3,
      "name": "Wood_Redwood_Branch_Long"
    },
    {
      "x": -9,
      "y": 19,
      "z": -3,
      "name": "Wood_Redwood_Branch_Long"
    },
    {
      "x": -9,
      "y": 20,
      "z": -3,
      "name": "Wood_Redwood_Stairs",
      "rotation": 10
    },
    {
      "x": -9,
      "y": 21,
      "z": -3,
      "name": "Wood_Redwood_Stairs",
      "rotation": 2
    },
    {
      "x": -9,
      "y": 22,
      "z": -3,
      "name": "Wood_Redwood_Planks"
    },
    {
      "x": -9,
      "y": 23,
      "z": -3,
      "name": "Wood_Redwood_Stairs"
    },
    {
      "x": -9,
      "y": 0,
      "z": -2,
      "name": "Rock_Shale"
    },
    {
      "x": -9,
      "y": 1,
      "z": -2,
      "name": "Rock_Shale"
    },
    {
      "x": -9,
      "y": 2,
      "z": -2,
      "name": "Rock_Shale"
    },
    {
      "x": -9,
      "y": 3,
      "z": -2,
      "name": "Rock_Shale"
    },
    {
      "x": -9,
      "y": 4,
      "z": -2,
      "name": "Rock_Shale_Cobble"
    },
    {
      "x": -9,
      "y": 5,
      "z": -2,
      "name": "Rock_Shale_Cobble"
    },
    {
      "x": -9,
      "y": 6,
      "z": -2,
      "name": "Rock_Shale_Cobble"
    },
    {
      "x": -9,
      "y": 7,
      "z": -2,
      "name": "Rock_Shale_Cobble"
    },
    {
      "x": -9,
      "y": 8,
      "z": -2,
      "name": "Rock_Shale_Cobble"
    },
    {
      "x": -9,
      "y": 9,
      "z": -2,
      "name": "Rock_Shale_Brick"
    },
    {
      "x": -9,
      "y": 10,
      "z": -2,
      "name": "Rock_Shale_Brick"
    },
    {
      "x": -9,
      "y": 11,
      "z": -2,
      "name": "Rock_Shale_Brick"
    },
    {
      "x": -9,
      "y": 12,
      "z": -2,
      "name": "Wood_Redwood_Trunk",
      "rotation": 4
    },
    {
      "x": -9,
      "y": 14,
      "z": -2,
      "name": "Wood_Torch_Wall",
      "rotation": 3
    },
    {
      "x": -9,
      "y": 16,
      "z": -2,
      "name": "Wood_Redwood_Trunk",
      "rotation": 4
    },
    {
      "x": -9,
      "y": 17,
      "z": -2,
      "name": "Furniture_Lumberjack_Platform",
      "rotation": 1
    },
    {
      "x": -9,
      "y": 21,
      "z": -2,
      "name": "Wood_Redwood_Planks"
    },
    {
      "x": -9,
      "y": 22,
      "z": -2,
      "name": "Wood_Redwood_Trunk",
      "rotation": 5
    },
    {
      "x": -9,
      "y": 0,
      "z": -1,
      "name": "Rock_Shale"
    },
    {
      "x": -9,
      "y": 1,
      "z": -1,
      "name": "Rock_Shale"
    },
    {
      "x": -9,
      "y": 2,
      "z": -1,
      "name": "Rock_Shale"
    },
    {
      "x": -9,
      "y": 3,
      "z": -1,
      "name": "Rock_Shale"
    },
    {
      "x": -9,
      "y": 4,
      "z": -1,
      "name": "Rock_Shale"
    },
    {
      "x": -9,
      "y": 5,
      "z": -1,
      "name": "Rock_Shale_Cobble"
    },
    {
      "x": -9,
      "y": 6,
      "z": -1,
      "name": "Rock_Shale_Cobble"
    },
    {
      "x": -9,
      "y": 7,
      "z": -1,
      "name": "Rock_Shale_Cobble"
    },
    {
      "x": -9,
      "y": 8,
      "z": -1,
      "name": "Rock_Shale_Cobble"
    },
    {
      "x": -9,
      "y": 9,
      "z": -1,
      "name": "Rock_Shale_Brick"
    },
    {
      "x": -9,
      "y": 10,
      "z": -1,
      "name": "Rock_Shale_Brick"
    },
    {
      "x": -9,
      "y": 11,
      "z": -1,
      "name": "Rock_Shale_Brick"
    },
    {
      "x": -9,
      "y": 12,
      "z": -1,
      "name": "Wood_Redwood_Trunk_Full",
      "rotation": 4
    },
    {
      "x": -9,
      "y": 13,
      "z": -1,
      "name": "Wood_Redwood_Trunk_Full",
      "rotation": 4
    },
    {
      "x": -9,
      "y": 16,
      "z": -1,
      "name": "Wood_Redwood_Trunk",
      "rotation": 4
    },
    {
      "x": -9,
      "y": 17,
      "z": -1,
      "name": "Furniture_Lumberjack_Platform",
      "rotation": 1
    },
    {
      "x": -9,
      "y": 20,
      "z": -1,
      "name": "Wood_Redwood_Stairs",
      "rotation": 8
    },
    {
      "x": -9,
      "y": 21,
      "z": -1,
      "name": "Wood_Redwood_Stairs"
    },
    {
      "x": -9,
      "y": 22,
      "z": -1,
      "name": "Wood_Redwood_Planks"
    },
    {
      "x": -9,
      "y": 23,
      "z": -1,
      "name": "Wood_Redwood_Stairs",
      "rotation": 2
    },
    {
      "x": -9,
      "y": 0,
      "z": 0,
      "name": "Rock_Shale"
    },
    {
      "x": -9,
      "y": 1,
      "z": 0,
      "name": "Rock_Shale"
    },
    {
      "x": -9,
      "y": 2,
      "z": 0,
      "name": "Rock_Shale"
    },
    {
      "x": -9,
      "y": 3,
      "z": 0,
      "name": "Rock_Shale"
    },
    {
      "x": -9,
      "y": 4,
      "z": 0,
      "name": "Rock_Shale"
    },
    {
      "x": -9,
      "y": 5,
      "z": 0,
      "name": "Rock_Shale_Cobble"
    },
    {
      "x": -9,
      "y": 6,
      "z": 0,
      "name": "Rock_Shale_Cobble"
    },
    {
      "x": -9,
      "y": 7,
      "z": 0,
      "name": "Rock_Shale_Cobble"
    },
    {
      "x": -9,
      "y": 8,
      "z": 0,
      "name": "Rock_Shale_Cobble"
    },
    {
      "x": -9,
      "y": 9,
      "z": 0,
      "name": "Rock_Shale_Cobble"
    },
    {
      "x": -9,
      "y": 10,
      "z": 0,
      "name": "Rock_Shale_Brick"
    },
    {
      "x": -9,
      "y": 11,
      "z": 0,
      "name": "Rock_Shale_Brick"
    },
    {
      "x": -9,
      "y": 12,
      "z": 0,
      "name": "Rock_Shale_Brick_Half",
      "rotation": 7
    },
    {
      "x": -9,
      "y": 13,
      "z": 0,
      "name": "Wood_Redwood_Trunk",
      "rotation": 4
    },
    {
      "x": -9,
      "y": 14,
      "z": 0,
      "name": "Rock_Shale_Brick_Half",
      "rotation": 7
    },
    {
      "x": -9,
      "y": 16,
      "z": 0,
      "name": "Wood_Redwood_Trunk",
      "rotation": 4
    },
    {
      "x": -9,
      "y": 17,
      "z": 0,
      "name": "Furniture_Lumberjack_Platform"
    },
    {
      "x": -9,
      "y": 18,
      "z": 0,
      "name": "Wood_Redwood_Branch_Long"
    },
    {
      "x": -9,
      "y": 19,
      "z": 0,
      "name": "Wood_Redwood_Stairs",
      "rotation": 8
    },
    {
      "x": -9,
      "y": 20,
      "z": 0,
      "name": "Wood_Redwood_Planks"
    },
    {
      "x": -9,
      "y": 21,
      "z": 0,
      "name": "Rock_Basalt_Cobble_Roof"
    },
    {
      "x": -9,
      "y": 23,
      "z": 0,
      "name": "Wood_Redwood_Planks_Half",
      "rotation": 4
    },
    {
      "x": -9,
      "y": 0,
      "z": 1,
      "name": "Rock_Shale"
    },
    {
      "x": -9,
      "y": 1,
      "z": 1,
      "name": "Rock_Shale"
    },
    {
      "x": -9,
      "y": 2,
      "z": 1,
      "name": "Rock_Shale"
    },
    {
      "x": -9,
      "y": 3,
      "z": 1,
      "name": "Rock_Shale"
    },
    {
      "x": -9,
      "y": 4,
      "z": 1,
      "name": "Rock_Shale"
    },
    {
      "x": -9,
      "y": 5,
      "z": 1,
      "name": "Rock_Shale_Cobble"
    },
    {
      "x": -9,
      "y": 6,
      "z": 1,
      "name": "Rock_Shale_Cobble"
    },
    {
      "x": -9,
      "y": 7,
      "z": 1,
      "name": "Rock_Shale_Cobble"
    },
    {
      "x": -9,
      "y": 8,
      "z": 1,
      "name": "Rock_Shale_Cobble"
    },
    {
      "x": -9,
      "y": 9,
      "z": 1,
      "name": "Rock_Shale_Cobble"
    },
    {
      "x": -9,
      "y": 10,
      "z": 1,
      "name": "Rock_Shale_Brick"
    },
    {
      "x": -9,
      "y": 11,
      "z": 1,
      "name": "Rock_Shale_Brick"
    },
    {
      "x": -9,
      "y": 12,
      "z": 1,
      "name": "Rock_Shale_Brick_Half",
      "rotation": 7
    },
    {
      "x": -9,
      "y": 13,
      "z": 1,
      "name": "Wood_Redwood_Trunk",
      "rotation": 4
    },
    {
      "x": -9,
      "y": 14,
      "z": 1,
      "name": "Rock_Shale_Brick_Half",
      "rotation": 7
    },
    {
      "x": -9,
      "y": 15,
      "z": 1,
      "name": "Rock_Shale_Brick_Half",
      "rotation": 7
    },
    {
      "x": -9,
      "y": 16,
      "z": 1,
      "name": "Wood_Redwood_Trunk",
      "rotation": 4
    },
    {
      "x": -9,
      "y": 18,
      "z": 1,
      "name": "Wood_Redwood_Stairs",
      "rotation": 8
    },
    {
      "x": -9,
      "y": 19,
      "z": 1,
      "name": "Wood_Redwood_Stairs"
    },
    {
      "x": -9,
      "y": 20,
      "z": 1,
      "name": "Rock_Basalt_Cobble_Roof"
    },
    {
      "x": -9,
      "y": 0,
      "z": 2,
      "name": "Wood_Fir_Trunk",
      "support": 15
    },
    {
      "x": -9,
      "y": 1,
      "z": 2,
      "name": "Wood_Fir_Trunk",
      "support": 15
    },
    {
      "x": -9,
      "y": 2,
      "z": 2,
      "name": "Wood_Fir_Trunk",
      "support": 15
    },
    {
      "x": -9,
      "y": 3,
      "z": 2,
      "name": "Wood_Fir_Trunk",
      "support": 15
    },
    {
      "x": -9,
      "y": 4,
      "z": 2,
      "name": "Wood_Fir_Trunk",
      "support": 15
    },
    {
      "x": -9,
      "y": 5,
      "z": 2,
      "name": "Wood_Fir_Trunk",
      "support": 15
    },
    {
      "x": -9,
      "y": 6,
      "z": 2,
      "name": "Wood_Fir_Trunk",
      "support": 15
    },
    {
      "x": -9,
      "y": 7,
      "z": 2,
      "name": "Wood_Fir_Trunk",
      "support": 15
    },
    {
      "x": -9,
      "y": 8,
      "z": 2,
      "name": "Wood_Fir_Trunk",
      "support": 15
    },
    {
      "x": -9,
      "y": 9,
      "z": 2,
      "name": "Wood_Fir_Trunk",
      "support": 15
    },
    {
      "x": -9,
      "y": 10,
      "z": 2,
      "name": "Wood_Redwood_Trunk"
    },
    {
      "x": -9,
      "y": 11,
      "z": 2,
      "name": "Wood_Redwood_Trunk"
    },
    {
      "x": -9,
      "y": 12,
      "z": 2,
      "name": "Wood_Redwood_Trunk"
    },
    {
      "x": -9,
      "y": 13,
      "z": 2,
      "name": "Wood_Redwood_Trunk"
    },
    {
      "x": -9,
      "y": 14,
      "z": 2,
      "name": "Wood_Redwood_Trunk"
    },
    {
      "x": -9,
      "y": 15,
      "z": 2,
      "name": "Wood_Redwood_Trunk"
    },
    {
      "x": -9,
      "y": 16,
      "z": 2,
      "name": "Wood_Redwood_Trunk",
      "rotation": 4
    },
    {
      "x": -9,
      "y": 17,
      "z": 2,
      "name": "Wood_Redwood_Stairs",
      "rotation": 8
    },
    {
      "x": -9,
      "y": 18,
      "z": 2,
      "name": "Wood_Redwood_Stairs"
    },
    {
      "x": -9,
      "y": 0,
      "z": 3,
      "name": "Wood_Fir_Trunk",
      "support": 15
    },
    {
      "x": -9,
      "y": 1,
      "z": 3,
      "name": "Wood_Fir_Trunk",
      "support": 15
    },
    {
      "x": -9,
      "y": 2,
      "z": 3,
      "name": "Wood_Fir_Trunk",
      "support": 15
    },
    {
      "x": -9,
      "y": 3,
      "z": 3,
      "name": "Wood_Fir_Trunk",
      "support": 15
    },
    {
      "x": -9,
      "y": 4,
      "z": 3,
      "name": "Wood_Fir_Trunk",
      "support": 15
    },
    {
      "x": -9,
      "y": 5,
      "z": 3,
      "name": "Wood_Fir_Trunk",
      "support": 15
    },
    {
      "x": -9,
      "y": 6,
      "z": 3,
      "name": "Wood_Fir_Trunk",
      "support": 15
    },
    {
      "x": -9,
      "y": 7,
      "z": 3,
      "name": "Wood_Fir_Trunk",
      "support": 15
    },
    {
      "x": -9,
      "y": 8,
      "z": 3,
      "name": "Wood_Fir_Trunk",
      "support": 15
    },
    {
      "x": -9,
      "y": 9,
      "z": 3,
      "name": "Wood_Fir_Trunk",
      "support": 15
    },
    {
      "x": -9,
      "y": 10,
      "z": 3,
      "name": "Wood_Fir_Trunk",
      "support": 15
    },
    {
      "x": -9,
      "y": 11,
      "z": 3,
      "name": "Wood_Fir_Trunk",
      "support": 15
    },
    {
      "x": -9,
      "y": 12,
      "z": 3,
      "name": "Wood_Fir_Trunk",
      "support": 15
    },
    {
      "x": -9,
      "y": 13,
      "z": 3,
      "name": "Wood_Fir_Trunk",
      "support": 15
    },
    {
      "x": -9,
      "y": 14,
      "z": 3,
      "name": "Wood_Fir_Trunk",
      "support": 15
    },
    {
      "x": -9,
      "y": 16,
      "z": 3,
      "name": "Wood_Redwood_Trunk",
      "rotation": 4
    },
    {
      "x": -9,
      "y": 17,
      "z": 3,
      "name": "Wood_Redwood_Trunk",
      "rotation": 5
    },
    {
      "x": -9,
      "y": 18,
      "z": 3,
      "name": "Rock_Basalt_Cobble_Roof"
    },
    {
      "x": -9,
      "y": 0,
      "z": 4,
      "name": "Wood_Fir_Trunk",
      "support": 15
    },
    {
      "x": -9,
      "y": 1,
      "z": 4,
      "name": "Wood_Fir_Trunk",
      "support": 15
    },
    {
      "x": -9,
      "y": 2,
      "z": 4,
      "name": "Wood_Fir_Trunk",
      "support": 15
    },
    {
      "x": -9,
      "y": 3,
      "z": 4,
      "name": "Wood_Fir_Trunk",
      "support": 15
    },
    {
      "x": -9,
      "y": 4,
      "z": 4,
      "name": "Wood_Fir_Trunk",
      "support": 15
    },
    {
      "x": -9,
      "y": 5,
      "z": 4,
      "name": "Wood_Fir_Trunk",
      "support": 15
    },
    {
      "x": -9,
      "y": 6,
      "z": 4,
      "name": "Wood_Fir_Trunk",
      "support": 15
    },
    {
      "x": -9,
      "y": 7,
      "z": 4,
      "name": "Wood_Fir_Trunk",
      "support": 15
    },
    {
      "x": -9,
      "y": 8,
      "z": 4,
      "name": "Wood_Fir_Trunk",
      "support": 15
    },
    {
      "x": -9,
      "y": 9,
      "z": 4,
      "name": "Wood_Fir_Trunk",
      "support": 15
    },
    {
      "x": -9,
      "y": 10,
      "z": 4,
      "name": "Wood_Fir_Trunk",
      "support": 15
    },
    {
      "x": -9,
      "y": 11,
      "z": 4,
      "name": "Wood_Fir_Trunk",
      "support": 15
    },
    {
      "x": -9,
      "y": 12,
      "z": 4,
      "name": "Wood_Fir_Branch_Long",
      "support": 15
    },
    {
      "x": -9,
      "y": 16,
      "z": 4,
      "name": "Wood_Redwood_Trunk",
      "rotation": 4
    },
    {
      "x": -9,
      "y": 0,
      "z": 5,
      "name": "Wood_Fir_Trunk",
      "support": 15
    },
    {
      "x": -9,
      "y": 1,
      "z": 5,
      "name": "Wood_Fir_Trunk",
      "support": 15
    },
    {
      "x": -9,
      "y": 2,
      "z": 5,
      "name": "Wood_Fir_Trunk",
      "support": 15
    },
    {
      "x": -9,
      "y": 3,
      "z": 5,
      "name": "Wood_Fir_Trunk",
      "support": 15
    },
    {
      "x": -9,
      "y": 4,
      "z": 5,
      "name": "Wood_Fir_Trunk",
      "support": 15
    },
    {
      "x": -9,
      "y": 5,
      "z": 5,
      "name": "Wood_Fir_Trunk",
      "support": 15
    },
    {
      "x": -9,
      "y": 6,
      "z": 5,
      "name": "Wood_Fir_Trunk",
      "support": 15
    },
    {
      "x": -9,
      "y": 7,
      "z": 5,
      "name": "Wood_Fir_Trunk",
      "support": 15
    },
    {
      "x": -9,
      "y": 8,
      "z": 5,
      "name": "Wood_Fir_Trunk",
      "support": 15
    },
    {
      "x": -9,
      "y": 9,
      "z": 5,
      "name": "Wood_Fir_Trunk",
      "support": 15
    },
    {
      "x": -9,
      "y": 10,
      "z": 5,
      "name": "Wood_Fir_Trunk",
      "support": 15
    },
    {
      "x": -9,
      "y": 11,
      "z": 5,
      "name": "Wood_Fir_Trunk",
      "support": 15
    },
    {
      "x": -9,
      "y": 12,
      "z": 5,
      "name": "Wood_Fir_Trunk",
      "support": 15
    },
    {
      "x": -9,
      "y": 13,
      "z": 5,
      "name": "Wood_Fir_Trunk",
      "support": 15
    },
    {
      "x": -9,
      "y": 14,
      "z": 5,
      "name": "Wood_Fir_Branch_Long",
      "support": 15
    },
    {
      "x": -9,
      "y": 15,
      "z": 5,
      "name": "Survival_Trap_Spike_Wood_Large"
    },
    {
      "x": -9,
      "y": 0,
      "z": 6,
      "name": "Rock_Shale"
    },
    {
      "x": -9,
      "y": 1,
      "z": 6,
      "name": "Rock_Shale"
    },
    {
      "x": -9,
      "y": 2,
      "z": 6,
      "name": "Rock_Shale"
    },
    {
      "x": -9,
      "y": 3,
      "z": 6,
      "name": "Rock_Shale"
    },
    {
      "x": -9,
      "y": 4,
      "z": 6,
      "name": "Rock_Shale"
    },
    {
      "x": -9,
      "y": 5,
      "z": 6,
      "name": "Rock_Shale"
    },
    {
      "x": -9,
      "y": 6,
      "z": 6,
      "name": "Rock_Shale"
    },
    {
      "x": -9,
      "y": 7,
      "z": 6,
      "name": "Rock_Shale"
    },
    {
      "x": -9,
      "y": 8,
      "z": 6,
      "name": "Rock_Shale"
    },
    {
      "x": -9,
      "y": 9,
      "z": 6,
      "name": "Soil_Dirt_Cold"
    },
    {
      "x": -9,
      "y": 10,
      "z": 6,
      "name": "Soil_Dirt_Cold"
    },
    {
      "x": -9,
      "y": 11,
      "z": 6,
      "name": "Soil_Dirt_Cold"
    },
    {
      "x": -9,
      "y": 0,
      "z": 7,
      "name": "Rock_Shale"
    },
    {
      "x": -9,
      "y": 1,
      "z": 7,
      "name": "Rock_Shale"
    },
    {
      "x": -9,
      "y": 2,
      "z": 7,
      "name": "Rock_Shale"
    },
    {
      "x": -9,
      "y": 3,
      "z": 7,
      "name": "Rock_Shale"
    },
    {
      "x": -9,
      "y": 4,
      "z": 7,
      "name": "Rock_Shale"
    },
    {
      "x": -9,
      "y": 5,
      "z": 7,
      "name": "Rock_Shale"
    },
    {
      "x": -9,
      "y": 6,
      "z": 7,
      "name": "Rock_Shale"
    },
    {
      "x": -9,
      "y": 7,
      "z": 7,
      "name": "Rock_Shale"
    },
    {
      "x": -9,
      "y": 8,
      "z": 7,
      "name": "Rock_Shale"
    },
    {
      "x": -9,
      "y": 9,
      "z": 7,
      "name": "Soil_Dirt_Cold"
    },
    {
      "x": -9,
      "y": 10,
      "z": 7,
      "name": "Soil_Dirt_Cold"
    },
    {
      "x": -9,
      "y": 11,
      "z": 7,
      "name": "Soil_Dirt_Cold"
    },
    {
      "x": -9,
      "y": 0,
      "z": 8,
      "name": "Rock_Shale"
    },
    {
      "x": -9,
      "y": 1,
      "z": 8,
      "name": "Rock_Shale"
    },
    {
      "x": -9,
      "y": 2,
      "z": 8,
      "name": "Rock_Shale"
    },
    {
      "x": -9,
      "y": 3,
      "z": 8,
      "name": "Rock_Shale"
    },
    {
      "x": -9,
      "y": 4,
      "z": 8,
      "name": "Rock_Shale"
    },
    {
      "x": -9,
      "y": 5,
      "z": 8,
      "name": "Rock_Shale"
    },
    {
      "x": -9,
      "y": 6,
      "z": 8,
      "name": "Rock_Shale"
    },
    {
      "x": -9,
      "y": 7,
      "z": 8,
      "name": "Rock_Shale"
    },
    {
      "x": -9,
      "y": 8,
      "z": 8,
      "name": "Rock_Shale"
    },
    {
      "x": -9,
      "y": 9,
      "z": 8,
      "name": "Rock_Shale"
    },
    {
      "x": -9,
      "y": 10,
      "z": 8,
      "name": "Soil_Dirt_Cold"
    },
    {
      "x": -9,
      "y": 11,
      "z": 8,
      "name": "Soil_Dirt_Cold"
    },
    {
      "x": -9,
      "y": 0,
      "z": 9,
      "name": "Rock_Shale"
    },
    {
      "x": -9,
      "y": 1,
      "z": 9,
      "name": "Rock_Shale"
    },
    {
      "x": -9,
      "y": 2,
      "z": 9,
      "name": "Rock_Shale"
    },
    {
      "x": -9,
      "y": 3,
      "z": 9,
      "name": "Rock_Shale"
    },
    {
      "x": -9,
      "y": 4,
      "z": 9,
      "name": "Rock_Shale"
    },
    {
      "x": -9,
      "y": 5,
      "z": 9,
      "name": "Rock_Shale"
    },
    {
      "x": -9,
      "y": 6,
      "z": 9,
      "name": "Rock_Shale"
    },
    {
      "x": -9,
      "y": 7,
      "z": 9,
      "name": "Rock_Shale"
    },
    {
      "x": -9,
      "y": 8,
      "z": 9,
      "name": "Rock_Shale"
    },
    {
      "x": -9,
      "y": 9,
      "z": 9,
      "name": "Rock_Shale"
    },
    {
      "x": -9,
      "y": 10,
      "z": 9,
      "name": "Soil_Dirt_Cold"
    },
    {
      "x": -9,
      "y": 11,
      "z": 9,
      "name": "Soil_Dirt_Cold"
    },
    {
      "x": -9,
      "y": 0,
      "z": 10,
      "name": "Wood_Fir_Trunk",
      "support": 15
    },
    {
      "x": -9,
      "y": 1,
      "z": 10,
      "name": "Wood_Fir_Trunk",
      "support": 15
    },
    {
      "x": -9,
      "y": 2,
      "z": 10,
      "name": "Wood_Fir_Trunk",
      "support": 15
    },
    {
      "x": -9,
      "y": 3,
      "z": 10,
      "name": "Wood_Fir_Trunk",
      "support": 15
    },
    {
      "x": -9,
      "y": 4,
      "z": 10,
      "name": "Wood_Fir_Trunk",
      "support": 15
    },
    {
      "x": -9,
      "y": 5,
      "z": 10,
      "name": "Wood_Fir_Trunk",
      "support": 15
    },
    {
      "x": -9,
      "y": 6,
      "z": 10,
      "name": "Wood_Fir_Trunk",
      "support": 15
    },
    {
      "x": -9,
      "y": 7,
      "z": 10,
      "name": "Wood_Fir_Trunk",
      "support": 15
    },
    {
      "x": -9,
      "y": 8,
      "z": 10,
      "name": "Wood_Fir_Trunk",
      "support": 15
    },
    {
      "x": -9,
      "y": 9,
      "z": 10,
      "name": "Wood_Fir_Trunk",
      "support": 15
    },
    {
      "x": -9,
      "y": 10,
      "z": 10,
      "name": "Wood_Fir_Trunk",
      "support": 15
    },
    {
      "x": -9,
      "y": 11,
      "z": 10,
      "name": "Wood_Fir_Trunk",
      "support": 15
    },
    {
      "x": -9,
      "y": 12,
      "z": 10,
      "name": "Wood_Fir_Trunk",
      "support": 15
    },
    {
      "x": -9,
      "y": 13,
      "z": 10,
      "name": "Wood_Fir_Trunk",
      "support": 15
    },
    {
      "x": -9,
      "y": 14,
      "z": 10,
      "name": "Wood_Fir_Branch_Long",
      "support": 15
    },
    {
      "x": -9,
      "y": 15,
      "z": 10,
      "name": "Survival_Trap_Spike_Wood_Large"
    },
    {
      "x": -8,
      "y": 0,
      "z": -11,
      "name": "Wood_Fir_Trunk",
      "support": 15
    },
    {
      "x": -8,
      "y": 1,
      "z": -11,
      "name": "Wood_Fir_Trunk",
      "support": 15
    },
    {
      "x": -8,
      "y": 2,
      "z": -11,
      "name": "Wood_Fir_Trunk",
      "support": 15
    },
    {
      "x": -8,
      "y": 3,
      "z": -11,
      "name": "Wood_Fir_Trunk",
      "support": 15
    },
    {
      "x": -8,
      "y": 4,
      "z": -11,
      "name": "Wood_Fir_Trunk",
      "support": 15
    },
    {
      "x": -8,
      "y": 5,
      "z": -11,
      "name": "Wood_Fir_Trunk",
      "support": 15
    },
    {
      "x": -8,
      "y": 6,
      "z": -11,
      "name": "Wood_Fir_Trunk",
      "support": 15
    },
    {
      "x": -8,
      "y": 7,
      "z": -11,
      "name": "Wood_Fir_Trunk",
      "support": 15
    },
    {
      "x": -8,
      "y": 8,
      "z": -11,
      "name": "Wood_Fir_Trunk",
      "support": 15
    },
    {
      "x": -8,
      "y": 9,
      "z": -11,
      "name": "Wood_Fir_Trunk",
      "support": 15
    },
    {
      "x": -8,
      "y": 10,
      "z": -11,
      "name": "Wood_Fir_Trunk",
      "support": 15
    },
    {
      "x": -8,
      "y": 11,
      "z": -11,
      "name": "Wood_Fir_Trunk",
      "support": 15
    },
    {
      "x": -8,
      "y": 12,
      "z": -11,
      "name": "Wood_Fir_Trunk",
      "support": 15
    },
    {
      "x": -8,
      "y": 13,
      "z": -11,
      "name": "Wood_Fir_Trunk",
      "support": 15
    },
    {
      "x": -8,
      "y": 14,
      "z": -11,
      "name": "Wood_Fir_Trunk",
      "support": 15
    },
    {
      "x": -8,
      "y": 15,
      "z": -11,
      "name": "Wood_Fir_Branch_Long",
      "support": 15
    },
    {
      "x": -8,
      "y": 0,
      "z": -10,
      "name": "Wood_Fir_Trunk",
      "support": 15
    },
    {
      "x": -8,
      "y": 1,
      "z": -10,
      "name": "Wood_Fir_Trunk",
      "support": 15
    },
    {
      "x": -8,
      "y": 2,
      "z": -10,
      "name": "Wood_Fir_Trunk",
      "support": 15
    },
    {
      "x": -8,
      "y": 3,
      "z": -10,
      "name": "Wood_Fir_Trunk",
      "support": 15
    },
    {
      "x": -8,
      "y": 4,
      "z": -10,
      "name": "Wood_Fir_Trunk",
      "support": 15
    },
    {
      "x": -8,
      "y": 5,
      "z": -10,
      "name": "Wood_Fir_Trunk",
      "support": 15
    },
    {
      "x": -8,
      "y": 6,
      "z": -10,
      "name": "Wood_Fir_Trunk",
      "support": 15
    },
    {
      "x": -8,
      "y": 7,
      "z": -10,
      "name": "Wood_Fir_Trunk",
      "support": 15
    },
    {
      "x": -8,
      "y": 8,
      "z": -10,
      "name": "Wood_Fir_Trunk",
      "support": 15
    },
    {
      "x": -8,
      "y": 9,
      "z": -10,
      "name": "Wood_Fir_Trunk",
      "support": 15
    },
    {
      "x": -8,
      "y": 10,
      "z": -10,
      "name": "Wood_Fir_Trunk",
      "support": 15
    },
    {
      "x": -8,
      "y": 11,
      "z": -10,
      "name": "Wood_Fir_Trunk",
      "support": 15
    },
    {
      "x": -8,
      "y": 12,
      "z": -10,
      "name": "Wood_Fir_Trunk",
      "support": 15
    },
    {
      "x": -8,
      "y": 0,
      "z": -9,
      "name": "Soil_Dirt_Cold"
    },
    {
      "x": -8,
      "y": 1,
      "z": -9,
      "name": "Soil_Dirt_Cold"
    },
    {
      "x": -8,
      "y": 2,
      "z": -9,
      "name": "Soil_Dirt_Cold"
    },
    {
      "x": -8,
      "y": 3,
      "z": -9,
      "name": "Soil_Dirt_Cold"
    },
    {
      "x": -8,
      "y": 4,
      "z": -9,
      "name": "Soil_Dirt_Cold"
    },
    {
      "x": -8,
      "y": 5,
      "z": -9,
      "name": "Soil_Dirt_Cold"
    },
    {
      "x": -8,
      "y": 6,
      "z": -9,
      "name": "Soil_Dirt_Cold"
    },
    {
      "x": -8,
      "y": 7,
      "z": -9,
      "name": "Soil_Dirt_Cold"
    },
    {
      "x": -8,
      "y": 8,
      "z": -9,
      "name": "Soil_Dirt_Cold"
    },
    {
      "x": -8,
      "y": 9,
      "z": -9,
      "name": "Soil_Dirt_Cold"
    },
    {
      "x": -8,
      "y": 10,
      "z": -9,
      "name": "Soil_Dirt_Cold"
    },
    {
      "x": -8,
      "y": 11,
      "z": -9,
      "name": "Soil_Dirt_Cold"
    },
    {
      "x": -8,
      "y": 0,
      "z": -8,
      "name": "Rock_Shale"
    },
    {
      "x": -8,
      "y": 1,
      "z": -8,
      "name": "Rock_Shale"
    },
    {
      "x": -8,
      "y": 2,
      "z": -8,
      "name": "Rock_Shale"
    },
    {
      "x": -8,
      "y": 3,
      "z": -8,
      "name": "Rock_Shale"
    },
    {
      "x": -8,
      "y": 4,
      "z": -8,
      "name": "Rock_Shale"
    },
    {
      "x": -8,
      "y": 5,
      "z": -8,
      "name": "Rock_Shale"
    },
    {
      "x": -8,
      "y": 6,
      "z": -8,
      "name": "Rock_Shale"
    },
    {
      "x": -8,
      "y": 7,
      "z": -8,
      "name": "Rock_Shale"
    },
    {
      "x": -8,
      "y": 8,
      "z": -8,
      "name": "Rock_Shale"
    },
    {
      "x": -8,
      "y": 9,
      "z": -8,
      "name": "Rock_Shale"
    },
    {
      "x": -8,
      "y": 10,
      "z": -8,
      "name": "Rock_Shale"
    },
    {
      "x": -8,
      "y": 11,
      "z": -8,
      "name": "Rock_Shale"
    },
    {
      "x": -8,
      "y": 17,
      "z": -8,
      "name": "Rock_Basalt_Cobble_Roof",
      "rotation": 2
    },
    {
      "x": -8,
      "y": 0,
      "z": -7,
      "name": "Rock_Shale"
    },
    {
      "x": -8,
      "y": 1,
      "z": -7,
      "name": "Rock_Shale"
    },
    {
      "x": -8,
      "y": 2,
      "z": -7,
      "name": "Rock_Shale"
    },
    {
      "x": -8,
      "y": 3,
      "z": -7,
      "name": "Rock_Shale"
    },
    {
      "x": -8,
      "y": 4,
      "z": -7,
      "name": "Rock_Shale"
    },
    {
      "x": -8,
      "y": 5,
      "z": -7,
      "name": "Rock_Shale"
    },
    {
      "x": -8,
      "y": 6,
      "z": -7,
      "name": "Rock_Shale"
    },
    {
      "x": -8,
      "y": 7,
      "z": -7,
      "name": "Rock_Shale"
    },
    {
      "x": -8,
      "y": 8,
      "z": -7,
      "name": "Rock_Shale"
    },
    {
      "x": -8,
      "y": 9,
      "z": -7,
      "name": "Soil_Dirt_Cold"
    },
    {
      "x": -8,
      "y": 10,
      "z": -7,
      "name": "Soil_Dirt_Cold"
    },
    {
      "x": -8,
      "y": 11,
      "z": -7,
      "name": "Rock_Shale"
    },
    {
      "x": -8,
      "y": 12,
      "z": -7,
      "name": "Rock_Shale_Brick_Half",
      "rotation": 6
    },
    {
      "x": -8,
      "y": 13,
      "z": -7,
      "name": "Rock_Shale_Brick_Half",
      "rotation": 6
    },
    {
      "x": -8,
      "y": 14,
      "z": -7,
      "name": "Rock_Shale_Brick_Half",
      "rotation": 6
    },
    {
      "x": -8,
      "y": 15,
      "z": -7,
      "name": "Rock_Shale_Brick_Half",
      "rotation": 6
    },
    {
      "x": -8,
      "y": 16,
      "z": -7,
      "name": "Wood_Redwood_Trunk",
      "rotation": 5
    },
    {
      "x": -8,
      "y": 17,
      "z": -7,
      "name": "Wood_Redwood_Trunk",
      "rotation": 5
    },
    {
      "x": -8,
      "y": 18,
      "z": -7,
      "name": "Rock_Basalt_Cobble_Roof",
      "rotation": 2
    },
    {
      "x": -8,
      "y": 0,
      "z": -6,
      "name": "Rock_Shale"
    },
    {
      "x": -8,
      "y": 1,
      "z": -6,
      "name": "Rock_Shale"
    },
    {
      "x": -8,
      "y": 2,
      "z": -6,
      "name": "Rock_Shale"
    },
    {
      "x": -8,
      "y": 3,
      "z": -6,
      "name": "Rock_Shale"
    },
    {
      "x": -8,
      "y": 4,
      "z": -6,
      "name": "Rock_Shale"
    },
    {
      "x": -8,
      "y": 5,
      "z": -6,
      "name": "Rock_Shale"
    },
    {
      "x": -8,
      "y": 6,
      "z": -6,
      "name": "Rock_Shale"
    },
    {
      "x": -8,
      "y": 7,
      "z": -6,
      "name": "Rock_Shale"
    },
    {
      "x": -8,
      "y": 8,
      "z": -6,
      "name": "Rock_Shale"
    },
    {
      "x": -8,
      "y": 9,
      "z": -6,
      "name": "Soil_Dirt_Cold"
    },
    {
      "x": -8,
      "y": 10,
      "z": -6,
      "name": "Soil_Dirt_Cold"
    },
    {
      "x": -8,
      "y": 11,
      "z": -6,
      "name": "Rock_Shale_Brick"
    },
    {
      "x": -8,
      "y": 12,
      "z": -6,
      "name": "Rock_Shale_Brick"
    },
    {
      "x": -8,
      "y": 13,
      "z": -6,
      "name": "Rock_Shale_Brick"
    },
    {
      "x": -8,
      "y": 14,
      "z": -6,
      "name": "Rock_Shale_Brick"
    },
    {
      "x": -8,
      "y": 15,
      "z": -6,
      "name": "Rock_Shale_Brick"
    },
    {
      "x": -8,
      "y": 16,
      "z": -6,
      "name": "Wood_Redwood_Planks"
    },
    {
      "x": -8,
      "y": 17,
      "z": -6,
      "name": "Wood_Redwood_Planks"
    },
    {
      "x": -8,
      "y": 18,
      "z": -6,
      "name": "Wood_Redwood_Planks"
    },
    {
      "x": -8,
      "y": 19,
      "z": -6,
      "name": "Rock_Basalt_Cobble_Roof",
      "rotation": 2
    },
    {
      "x": -8,
      "y": 0,
      "z": -5,
      "name": "Rock_Shale"
    },
    {
      "x": -8,
      "y": 1,
      "z": -5,
      "name": "Rock_Shale"
    },
    {
      "x": -8,
      "y": 2,
      "z": -5,
      "name": "Rock_Shale"
    },
    {
      "x": -8,
      "y": 3,
      "z": -5,
      "name": "Rock_Shale"
    },
    {
      "x": -8,
      "y": 4,
      "z": -5,
      "name": "Rock_Shale"
    },
    {
      "x": -8,
      "y": 5,
      "z": -5,
      "name": "Rock_Shale"
    },
    {
      "x": -8,
      "y": 6,
      "z": -5,
      "name": "Rock_Shale_Cobble"
    },
    {
      "x": -8,
      "y": 7,
      "z": -5,
      "name": "Rock_Shale"
    },
    {
      "x": -8,
      "y": 8,
      "z": -5,
      "name": "Soil_Dirt_Cold"
    },
    {
      "x": -8,
      "y": 9,
      "z": -5,
      "name": "Soil_Dirt_Cold"
    },
    {
      "x": -8,
      "y": 10,
      "z": -5,
      "name": "Soil_Dirt_Cold"
    },
    {
      "x": -8,
      "y": 11,
      "z": -5,
      "name": "Rock_Shale_Brick"
    },
    {
      "x": -8,
      "y": 12,
      "z": -5,
      "name": "Rock_Shale_Brick"
    },
    {
      "x": -8,
      "y": 13,
      "z": -5,
      "name": "Rock_Shale_Brick"
    },
    {
      "x": -8,
      "y": 14,
      "z": -5,
      "name": "Rock_Shale_Brick"
    },
    {
      "x": -8,
      "y": 15,
      "z": -5,
      "name": "Rock_Shale_Brick"
    },
    {
      "x": -8,
      "y": 16,
      "z": -5,
      "name": "Wood_Redwood_Planks"
    },
    {
      "x": -8,
      "y": 17,
      "z": -5,
      "name": "Wood_Redwood_Planks"
    },
    {
      "x": -8,
      "y": 18,
      "z": -5,
      "name": "Wood_Redwood_Trunk",
      "rotation": 4
    },
    {
      "x": -8,
      "y": 19,
      "z": -5,
      "name": "Wood_Redwood_Planks"
    },
    {
      "x": -8,
      "y": 20,
      "z": -5,
      "name": "Rock_Basalt_Cobble_Roof",
      "rotation": 2
    },
    {
      "x": -8,
      "y": 0,
      "z": -4,
      "name": "Rock_Shale"
    },
    {
      "x": -8,
      "y": 1,
      "z": -4,
      "name": "Rock_Shale"
    },
    {
      "x": -8,
      "y": 2,
      "z": -4,
      "name": "Rock_Shale"
    },
    {
      "x": -8,
      "y": 3,
      "z": -4,
      "name": "Rock_Shale"
    },
    {
      "x": -8,
      "y": 4,
      "z": -4,
      "name": "Rock_Shale"
    },
    {
      "x": -8,
      "y": 5,
      "z": -4,
      "name": "Rock_Shale_Cobble"
    },
    {
      "x": -8,
      "y": 6,
      "z": -4,
      "name": "Rock_Shale_Cobble"
    },
    {
      "x": -8,
      "y": 7,
      "z": -4,
      "name": "Rock_Shale_Cobble"
    },
    {
      "x": -8,
      "y": 8,
      "z": -4,
      "name": "Soil_Dirt_Cold"
    },
    {
      "x": -8,
      "y": 9,
      "z": -4,
      "name": "Soil_Dirt_Cold"
    },
    {
      "x": -8,
      "y": 10,
      "z": -4,
      "name": "Soil_Dirt_Cold"
    },
    {
      "x": -8,
      "y": 11,
      "z": -4,
      "name": "Rock_Shale_Brick"
    },
    {
      "x": -8,
      "y": 12,
      "z": -4,
      "name": "Rock_Shale_Brick"
    },
    {
      "x": -8,
      "y": 13,
      "z": -4,
      "name": "Rock_Shale_Cobble"
    },
    {
      "x": -8,
      "y": 14,
      "z": -4,
      "name": "Rock_Shale_Brick"
    },
    {
      "x": -8,
      "y": 15,
      "z": -4,
      "name": "Rock_Shale_Brick"
    },
    {
      "x": -8,
      "y": 16,
      "z": -4,
      "name": "Wood_Redwood_Planks"
    },
    {
      "x": -8,
      "y": 17,
      "z": -4,
      "name": "Wood_Redwood_Planks"
    },
    {
      "x": -8,
      "y": 18,
      "z": -4,
      "name": "Wood_Redwood_Trunk",
      "rotation": 4
    },
    {
      "x": -8,
      "y": 19,
      "z": -4,
      "name": "Wood_Redwood_Trunk",
      "rotation": 4
    },
    {
      "x": -8,
      "y": 20,
      "z": -4,
      "name": "Wood_Redwood_Planks"
    },
    {
      "x": -8,
      "y": 21,
      "z": -4,
      "name": "Rock_Basalt_Cobble_Roof",
      "rotation": 2
    },
    {
      "x": -8,
      "y": 0,
      "z": -3,
      "name": "Rock_Shale"
    },
    {
      "x": -8,
      "y": 1,
      "z": -3,
      "name": "Rock_Shale"
    },
    {
      "x": -8,
      "y": 2,
      "z": -3,
      "name": "Rock_Shale"
    },
    {
      "x": -8,
      "y": 3,
      "z": -3,
      "name": "Rock_Shale"
    },
    {
      "x": -8,
      "y": 4,
      "z": -3,
      "name": "Rock_Shale_Cobble"
    },
    {
      "x": -8,
      "y": 5,
      "z": -3,
      "name": "Rock_Shale_Cobble"
    },
    {
      "x": -8,
      "y": 6,
      "z": -3,
      "name": "Rock_Shale_Cobble"
    },
    {
      "x": -8,
      "y": 7,
      "z": -3,
      "name": "Rock_Shale_Cobble"
    },
    {
      "x": -8,
      "y": 8,
      "z": -3,
      "name": "Rock_Shale_Cobble"
    },
    {
      "x": -8,
      "y": 9,
      "z": -3,
      "name": "Soil_Dirt_Cold"
    },
    {
      "x": -8,
      "y": 10,
      "z": -3,
      "name": "Soil_Dirt_Cold"
    },
    {
      "x": -8,
      "y": 11,
      "z": -3,
      "name": "Rock_Shale_Brick"
    },
    {
      "x": -8,
      "y": 12,
      "z": -3,
      "name": "Rock_Shale_Brick"
    },
    {
      "x": -8,
      "y": 13,
      "z": -3,
      "name": "Furniture_Lumberjack_Window",
      "rotation": 1
    },
    {
      "x": -8,
      "y": 14,
      "z": -3,
      "name": "Rock_Shale_Brick"
    },
    {
      "x": -8,
      "y": 15,
      "z": -3,
      "name": "Rock_Shale_Brick"
    },
    {
      "x": -8,
      "y": 16,
      "z": -3,
      "name": "Wood_Redwood_Planks"
    },
    {
      "x": -8,
      "y": 17,
      "z": -3,
      "name": "Wood_Redwood_Trunk_Full",
      "rotation": 4
    },
    {
      "x": -8,
      "y": 18,
      "z": -3,
      "name": "Wood_Redwood_Trunk_Full",
      "rotation": 4
    },
    {
      "x": -8,
      "y": 19,
      "z": -3,
      "name": "Wood_Redwood_Trunk",
      "rotation": 4
    },
    {
      "x": -8,
      "y": 20,
      "z": -3,
      "name": "Wood_Redwood_Planks"
    },
    {
      "x": -8,
      "y": 21,
      "z": -3,
      "name": "Wood_Redwood_Planks"
    },
    {
      "x": -8,
      "y": 22,
      "z": -3,
      "name": "Rock_Basalt_Cobble_Roof",
      "rotation": 2
    },
    {
      "x": -8,
      "y": 0,
      "z": -2,
      "name": "Rock_Shale"
    },
    {
      "x": -8,
      "y": 1,
      "z": -2,
      "name": "Rock_Shale"
    },
    {
      "x": -8,
      "y": 2,
      "z": -2,
      "name": "Rock_Shale"
    },
    {
      "x": -8,
      "y": 3,
      "z": -2,
      "name": "Rock_Shale"
    },
    {
      "x": -8,
      "y": 4,
      "z": -2,
      "name": "Rock_Shale"
    },
    {
      "x": -8,
      "y": 5,
      "z": -2,
      "name": "Rock_Shale_Cobble"
    },
    {
      "x": -8,
      "y": 6,
      "z": -2,
      "name": "Rock_Shale_Cobble"
    },
    {
      "x": -8,
      "y": 7,
      "z": -2,
      "name": "Rock_Shale_Cobble"
    },
    {
      "x": -8,
      "y": 8,
      "z": -2,
      "name": "Soil_Dirt_Cold"
    },
    {
      "x": -8,
      "y": 9,
      "z": -2,
      "name": "Soil_Dirt_Cold"
    },
    {
      "x": -8,
      "y": 10,
      "z": -2,
      "name": "Soil_Dirt_Cold"
    },
    {
      "x": -8,
      "y": 11,
      "z": -2,
      "name": "Rock_Shale_Brick"
    },
    {
      "x": -8,
      "y": 12,
      "z": -2,
      "name": "Rock_Shale_Brick"
    },
    {
      "x": -8,
      "y": 13,
      "z": -2,
      "name": "Rock_Shale_Cobble"
    },
    {
      "x": -8,
      "y": 14,
      "z": -2,
      "name": "Rock_Shale_Cobble"
    },
    {
      "x": -8,
      "y": 15,
      "z": -2,
      "name": "Rock_Shale_Brick"
    },
    {
      "x": -8,
      "y": 16,
      "z": -2,
      "name": "Wood_Redwood_Planks"
    },
    {
      "x": -8,
      "y": 17,
      "z": -2,
      "name": "Wood_Redwood_Trunk",
      "rotation": 4
    },
    {
      "x": -8,
      "y": 18,
      "z": -2,
      "name": "Furniture_Lumberjack_Door",
      "rotation": 3
    },
    {
      "x": -8,
      "y": 19,
      "z": -2,
      "name": "Furniture_Lumberjack_Door",
      "filler": 1024,
      "rotation": 3
    },
    {
      "x": -8,
      "y": 20,
      "z": -2,
      "name": "Wood_Redwood_Planks"
    },
    {
      "x": -8,
      "y": 21,
      "z": -2,
      "name": "Wood_Redwood_Planks"
    },
    {
      "x": -8,
      "y": 22,
      "z": -2,
      "name": "Wood_Redwood_Trunk",
      "rotation": 5
    },
    {
      "x": -8,
      "y": 23,
      "z": -2,
      "name": "Rock_Basalt_Cobble_Roof_Flat"
    },
    {
      "x": -8,
      "y": 0,
      "z": -1,
      "name": "Rock_Shale"
    },
    {
      "x": -8,
      "y": 1,
      "z": -1,
      "name": "Rock_Shale"
    },
    {
      "x": -8,
      "y": 2,
      "z": -1,
      "name": "Rock_Shale"
    },
    {
      "x": -8,
      "y": 3,
      "z": -1,
      "name": "Rock_Shale"
    },
    {
      "x": -8,
      "y": 4,
      "z": -1,
      "name": "Rock_Shale"
    },
    {
      "x": -8,
      "y": 5,
      "z": -1,
      "name": "Rock_Shale"
    },
    {
      "x": -8,
      "y": 6,
      "z": -1,
      "name": "Rock_Shale_Cobble"
    },
    {
      "x": -8,
      "y": 7,
      "z": -1,
      "name": "Rock_Shale_Cobble"
    },
    {
      "x": -8,
      "y": 8,
      "z": -1,
      "name": "Soil_Dirt_Cold"
    },
    {
      "x": -8,
      "y": 9,
      "z": -1,
      "name": "Soil_Dirt_Cold"
    },
    {
      "x": -8,
      "y": 10,
      "z": -1,
      "name": "Soil_Dirt_Cold"
    },
    {
      "x": -8,
      "y": 11,
      "z": -1,
      "name": "Rock_Shale_Brick"
    },
    {
      "x": -8,
      "y": 12,
      "z": -1,
      "name": "Rock_Shale_Brick"
    },
    {
      "x": -8,
      "y": 13,
      "z": -1,
      "name": "Rock_Shale_Brick"
    },
    {
      "x": -8,
      "y": 14,
      "z": -1,
      "name": "Rock_Shale_Cobble"
    },
    {
      "x": -8,
      "y": 15,
      "z": -1,
      "name": "Rock_Shale_Brick"
    },
    {
      "x": -8,
      "y": 16,
      "z": -1,
      "name": "Wood_Redwood_Planks"
    },
    {
      "x": -8,
      "y": 17,
      "z": -1,
      "name": "Wood_Redwood_Trunk",
      "rotation": 4
    },
    {
      "x": -8,
      "y": 18,
      "z": -1,
      "name": "Wood_Redwood_Planks"
    },
    {
      "x": -8,
      "y": 19,
      "z": -1,
      "name": "Wood_Redwood_Trunk",
      "rotation": 4
    },
    {
      "x": -8,
      "y": 20,
      "z": -1,
      "name": "Wood_Redwood_Planks"
    },
    {
      "x": -8,
      "y": 21,
      "z": -1,
      "name": "Wood_Redwood_Planks"
    },
    {
      "x": -8,
      "y": 22,
      "z": -1,
      "name": "Rock_Basalt_Cobble_Roof"
    },
    {
      "x": -8,
      "y": 0,
      "z": 0,
      "name": "Rock_Shale"
    },
    {
      "x": -8,
      "y": 1,
      "z": 0,
      "name": "Rock_Shale"
    },
    {
      "x": -8,
      "y": 2,
      "z": 0,
      "name": "Rock_Shale"
    },
    {
      "x": -8,
      "y": 3,
      "z": 0,
      "name": "Rock_Shale"
    },
    {
      "x": -8,
      "y": 4,
      "z": 0,
      "name": "Rock_Shale"
    },
    {
      "x": -8,
      "y": 5,
      "z": 0,
      "name": "Rock_Shale"
    },
    {
      "x": -8,
      "y": 6,
      "z": 0,
      "name": "Rock_Shale_Cobble"
    },
    {
      "x": -8,
      "y": 7,
      "z": 0,
      "name": "Rock_Shale_Cobble"
    },
    {
      "x": -8,
      "y": 8,
      "z": 0,
      "name": "Rock_Shale_Cobble"
    },
    {
      "x": -8,
      "y": 9,
      "z": 0,
      "name": "Soil_Dirt_Cold"
    },
    {
      "x": -8,
      "y": 10,
      "z": 0,
      "name": "Soil_Dirt_Cold"
    },
    {
      "x": -8,
      "y": 11,
      "z": 0,
      "name": "Rock_Shale_Brick"
    },
    {
      "x": -8,
      "y": 12,
      "z": 0,
      "name": "Rock_Shale_Brick"
    },
    {
      "x": -8,
      "y": 13,
      "z": 0,
      "name": "Rock_Shale_Brick"
    },
    {
      "x": -8,
      "y": 14,
      "z": 0,
      "name": "Rock_Shale_Brick"
    },
    {
      "x": -8,
      "y": 15,
      "z": 0,
      "name": "Rock_Shale_Brick"
    },
    {
      "x": -8,
      "y": 16,
      "z": 0,
      "name": "Wood_Redwood_Planks"
    },
    {
      "x": -8,
      "y": 17,
      "z": 0,
      "name": "Wood_Redwood_Trunk",
      "rotation": 4
    },
    {
      "x": -8,
      "y": 18,
      "z": 0,
      "name": "Wood_Redwood_Planks"
    },
    {
      "x": -8,
      "y": 19,
      "z": 0,
      "name": "Wood_Redwood_Trunk",
      "rotation": 4
    },
    {
      "x": -8,
      "y": 20,
      "z": 0,
      "name": "Wood_Redwood_Planks"
    },
    {
      "x": -8,
      "y": 21,
      "z": 0,
      "name": "Rock_Basalt_Cobble_Roof"
    },
    {
      "x": -8,
      "y": 0,
      "z": 1,
      "name": "Rock_Shale"
    },
    {
      "x": -8,
      "y": 1,
      "z": 1,
      "name": "Rock_Shale"
    },
    {
      "x": -8,
      "y": 2,
      "z": 1,
      "name": "Rock_Shale"
    },
    {
      "x": -8,
      "y": 3,
      "z": 1,
      "name": "Rock_Shale"
    },
    {
      "x": -8,
      "y": 4,
      "z": 1,
      "name": "Rock_Shale"
    },
    {
      "x": -8,
      "y": 5,
      "z": 1,
      "name": "Rock_Shale_Cobble"
    },
    {
      "x": -8,
      "y": 6,
      "z": 1,
      "name": "Rock_Shale_Cobble"
    },
    {
      "x": -8,
      "y": 7,
      "z": 1,
      "name": "Rock_Shale_Cobble"
    },
    {
      "x": -8,
      "y": 8,
      "z": 1,
      "name": "Rock_Shale_Cobble"
    },
    {
      "x": -8,
      "y": 9,
      "z": 1,
      "name": "Rock_Shale_Cobble"
    },
    {
      "x": -8,
      "y": 10,
      "z": 1,
      "name": "Soil_Dirt_Cold"
    },
    {
      "x": -8,
      "y": 11,
      "z": 1,
      "name": "Rock_Shale_Brick"
    },
    {
      "x": -8,
      "y": 12,
      "z": 1,
      "name": "Rock_Shale_Brick"
    },
    {
      "x": -8,
      "y": 13,
      "z": 1,
      "name": "Rock_Shale_Brick"
    },
    {
      "x": -8,
      "y": 14,
      "z": 1,
      "name": "Rock_Shale_Brick"
    },
    {
      "x": -8,
      "y": 15,
      "z": 1,
      "name": "Rock_Shale_Brick"
    },
    {
      "x": -8,
      "y": 16,
      "z": 1,
      "name": "Wood_Redwood_Planks"
    },
    {
      "x": -8,
      "y": 17,
      "z": 1,
      "name": "Wood_Redwood_Trunk",
      "rotation": 4
    },
    {
      "x": -8,
      "y": 18,
      "z": 1,
      "name": "Wood_Redwood_Planks"
    },
    {
      "x": -8,
      "y": 19,
      "z": 1,
      "name": "Wood_Redwood_Planks"
    },
    {
      "x": -8,
      "y": 20,
      "z": 1,
      "name": "Rock_Basalt_Cobble_Roof"
    },
    {
      "x": -8,
      "y": 0,
      "z": 2,
      "name": "Rock_Shale"
    },
    {
      "x": -8,
      "y": 1,
      "z": 2,
      "name": "Rock_Shale"
    },
    {
      "x": -8,
      "y": 2,
      "z": 2,
      "name": "Rock_Shale"
    },
    {
      "x": -8,
      "y": 3,
      "z": 2,
      "name": "Rock_Shale"
    },
    {
      "x": -8,
      "y": 4,
      "z": 2,
      "name": "Rock_Shale"
    },
    {
      "x": -8,
      "y": 5,
      "z": 2,
      "name": "Rock_Shale"
    },
    {
      "x": -8,
      "y": 6,
      "z": 2,
      "name": "Rock_Shale_Cobble"
    },
    {
      "x": -8,
      "y": 7,
      "z": 2,
      "name": "Rock_Shale_Cobble"
    },
    {
      "x": -8,
      "y": 8,
      "z": 2,
      "name": "Rock_Shale_Cobble"
    },
    {
      "x": -8,
      "y": 9,
      "z": 2,
      "name": "Soil_Dirt_Cold"
    },
    {
      "x": -8,
      "y": 10,
      "z": 2,
      "name": "Soil_Dirt_Cold"
    },
    {
      "x": -8,
      "y": 11,
      "z": 2,
      "name": "Rock_Shale_Brick"
    },
    {
      "x": -8,
      "y": 12,
      "z": 2,
      "name": "Rock_Shale_Brick"
    },
    {
      "x": -8,
      "y": 13,
      "z": 2,
      "name": "Rock_Shale_Brick"
    },
    {
      "x": -8,
      "y": 14,
      "z": 2,
      "name": "Rock_Shale_Brick"
    },
    {
      "x": -8,
      "y": 15,
      "z": 2,
      "name": "Rock_Shale_Brick"
    },
    {
      "x": -8,
      "y": 16,
      "z": 2,
      "name": "Wood_Redwood_Planks"
    },
    {
      "x": -8,
      "y": 17,
      "z": 2,
      "name": "Wood_Redwood_Trunk",
      "rotation": 4
    },
    {
      "x": -8,
      "y": 18,
      "z": 2,
      "name": "Wood_Redwood_Planks"
    },
    {
      "x": -8,
      "y": 19,
      "z": 2,
      "name": "Rock_Basalt_Cobble_Roof"
    },
    {
      "x": -8,
      "y": 0,
      "z": 3,
      "name": "Rock_Shale"
    },
    {
      "x": -8,
      "y": 1,
      "z": 3,
      "name": "Rock_Shale"
    },
    {
      "x": -8,
      "y": 2,
      "z": 3,
      "name": "Rock_Shale"
    },
    {
      "x": -8,
      "y": 3,
      "z": 3,
      "name": "Rock_Shale"
    },
    {
      "x": -8,
      "y": 4,
      "z": 3,
      "name": "Rock_Shale"
    },
    {
      "x": -8,
      "y": 5,
      "z": 3,
      "name": "Rock_Shale"
    },
    {
      "x": -8,
      "y": 6,
      "z": 3,
      "name": "Rock_Shale"
    },
    {
      "x": -8,
      "y": 7,
      "z": 3,
      "name": "Rock_Shale_Cobble"
    },
    {
      "x": -8,
      "y": 8,
      "z": 3,
      "name": "Rock_Shale"
    },
    {
      "x": -8,
      "y": 9,
      "z": 3,
      "name": "Soil_Dirt_Cold"
    },
    {
      "x": -8,
      "y": 10,
      "z": 3,
      "name": "Soil_Dirt_Cold"
    },
    {
      "x": -8,
      "y": 11,
      "z": 3,
      "name": "Rock_Shale_Brick"
    },
    {
      "x": -8,
      "y": 12,
      "z": 3,
      "name": "Rock_Shale_Brick"
    },
    {
      "x": -8,
      "y": 13,
      "z": 3,
      "name": "Rock_Shale_Brick"
    },
    {
      "x": -8,
      "y": 14,
      "z": 3,
      "name": "Rock_Shale"
    },
    {
      "x": -8,
      "y": 15,
      "z": 3,
      "name": "Rock_Shale"
    },
    {
      "x": -8,
      "y": 16,
      "z": 3,
      "name": "Wood_Redwood_Trunk",
      "rotation": 5
    },
    {
      "x": -8,
      "y": 17,
      "z": 3,
      "name": "Wood_Redwood_Trunk",
      "rotation": 5
    },
    {
      "x": -8,
      "y": 18,
      "z": 3,
      "name": "Rock_Basalt_Cobble_Roof"
    },
    {
      "x": -8,
      "y": 0,
      "z": 4,
      "name": "Rock_Shale"
    },
    {
      "x": -8,
      "y": 1,
      "z": 4,
      "name": "Rock_Shale"
    },
    {
      "x": -8,
      "y": 2,
      "z": 4,
      "name": "Rock_Shale"
    },
    {
      "x": -8,
      "y": 3,
      "z": 4,
      "name": "Rock_Shale"
    },
    {
      "x": -8,
      "y": 4,
      "z": 4,
      "name": "Rock_Shale"
    },
    {
      "x": -8,
      "y": 5,
      "z": 4,
      "name": "Rock_Shale"
    },
    {
      "x": -8,
      "y": 6,
      "z": 4,
      "name": "Rock_Shale"
    },
    {
      "x": -8,
      "y": 7,
      "z": 4,
      "name": "Rock_Shale"
    },
    {
      "x": -8,
      "y": 8,
      "z": 4,
      "name": "Rock_Shale"
    },
    {
      "x": -8,
      "y": 9,
      "z": 4,
      "name": "Soil_Dirt_Cold"
    },
    {
      "x": -8,
      "y": 10,
      "z": 4,
      "name": "Soil_Dirt_Cold"
    },
    {
      "x": -8,
      "y": 11,
      "z": 4,
      "name": "Soil_Dirt_Cold"
    },
    {
      "x": -8,
      "y": 17,
      "z": 4,
      "name": "Rock_Basalt_Cobble_Roof"
    },
    {
      "x": -8,
      "y": 0,
      "z": 5,
      "name": "Rock_Shale"
    },
    {
      "x": -8,
      "y": 1,
      "z": 5,
      "name": "Rock_Shale"
    },
    {
      "x": -8,
      "y": 2,
      "z": 5,
      "name": "Rock_Shale"
    },
    {
      "x": -8,
      "y": 3,
      "z": 5,
      "name": "Rock_Shale"
    },
    {
      "x": -8,
      "y": 4,
      "z": 5,
      "name": "Rock_Shale"
    },
    {
      "x": -8,
      "y": 5,
      "z": 5,
      "name": "Rock_Shale"
    },
    {
      "x": -8,
      "y": 6,
      "z": 5,
      "name": "Rock_Shale"
    },
    {
      "x": -8,
      "y": 7,
      "z": 5,
      "name": "Rock_Shale"
    },
    {
      "x": -8,
      "y": 8,
      "z": 5,
      "name": "Rock_Shale"
    },
    {
      "x": -8,
      "y": 9,
      "z": 5,
      "name": "Soil_Dirt_Cold"
    },
    {
      "x": -8,
      "y": 10,
      "z": 5,
      "name": "Soil_Dirt_Cold"
    },
    {
      "x": -8,
      "y": 11,
      "z": 5,
      "name": "Soil_Dirt_Cold"
    },
    {
      "x": -8,
      "y": 0,
      "z": 6,
      "name": "Rock_Shale"
    },
    {
      "x": -8,
      "y": 1,
      "z": 6,
      "name": "Rock_Shale"
    },
    {
      "x": -8,
      "y": 2,
      "z": 6,
      "name": "Rock_Shale"
    },
    {
      "x": -8,
      "y": 3,
      "z": 6,
      "name": "Rock_Shale"
    },
    {
      "x": -8,
      "y": 4,
      "z": 6,
      "name": "Rock_Shale"
    },
    {
      "x": -8,
      "y": 5,
      "z": 6,
      "name": "Rock_Shale"
    },
    {
      "x": -8,
      "y": 6,
      "z": 6,
      "name": "Rock_Shale"
    },
    {
      "x": -8,
      "y": 7,
      "z": 6,
      "name": "Rock_Shale"
    },
    {
      "x": -8,
      "y": 8,
      "z": 6,
      "name": "Rock_Shale"
    },
    {
      "x": -8,
      "y": 9,
      "z": 6,
      "name": "Soil_Dirt_Cold"
    },
    {
      "x": -8,
      "y": 10,
      "z": 6,
      "name": "Soil_Dirt_Cold"
    },
    {
      "x": -8,
      "y": 11,
      "z": 6,
      "name": "Soil_Dirt_Cold"
    },
    {
      "x": -8,
      "y": 0,
      "z": 7,
      "name": "Rock_Shale"
    },
    {
      "x": -8,
      "y": 1,
      "z": 7,
      "name": "Rock_Shale"
    },
    {
      "x": -8,
      "y": 2,
      "z": 7,
      "name": "Rock_Shale"
    },
    {
      "x": -8,
      "y": 3,
      "z": 7,
      "name": "Rock_Shale"
    },
    {
      "x": -8,
      "y": 4,
      "z": 7,
      "name": "Rock_Shale"
    },
    {
      "x": -8,
      "y": 5,
      "z": 7,
      "name": "Rock_Shale"
    },
    {
      "x": -8,
      "y": 6,
      "z": 7,
      "name": "Rock_Shale"
    },
    {
      "x": -8,
      "y": 7,
      "z": 7,
      "name": "Rock_Shale"
    },
    {
      "x": -8,
      "y": 8,
      "z": 7,
      "name": "Rock_Shale"
    },
    {
      "x": -8,
      "y": 9,
      "z": 7,
      "name": "Soil_Dirt_Cold"
    },
    {
      "x": -8,
      "y": 10,
      "z": 7,
      "name": "Soil_Dirt_Cold"
    },
    {
      "x": -8,
      "y": 11,
      "z": 7,
      "name": "Soil_Dirt_Cold"
    },
    {
      "x": -8,
      "y": 0,
      "z": 8,
      "name": "Rock_Shale"
    },
    {
      "x": -8,
      "y": 1,
      "z": 8,
      "name": "Rock_Shale"
    },
    {
      "x": -8,
      "y": 2,
      "z": 8,
      "name": "Rock_Shale"
    },
    {
      "x": -8,
      "y": 3,
      "z": 8,
      "name": "Rock_Shale"
    },
    {
      "x": -8,
      "y": 4,
      "z": 8,
      "name": "Rock_Shale"
    },
    {
      "x": -8,
      "y": 5,
      "z": 8,
      "name": "Rock_Shale"
    },
    {
      "x": -8,
      "y": 6,
      "z": 8,
      "name": "Rock_Shale"
    },
    {
      "x": -8,
      "y": 7,
      "z": 8,
      "name": "Rock_Shale"
    },
    {
      "x": -8,
      "y": 8,
      "z": 8,
      "name": "Rock_Shale"
    },
    {
      "x": -8,
      "y": 9,
      "z": 8,
      "name": "Rock_Shale"
    },
    {
      "x": -8,
      "y": 10,
      "z": 8,
      "name": "Soil_Dirt_Cold"
    },
    {
      "x": -8,
      "y": 11,
      "z": 8,
      "name": "Soil_Dirt_Cold"
    },
    {
      "x": -8,
      "y": 0,
      "z": 9,
      "name": "Rock_Shale"
    },
    {
      "x": -8,
      "y": 1,
      "z": 9,
      "name": "Rock_Shale"
    },
    {
      "x": -8,
      "y": 2,
      "z": 9,
      "name": "Rock_Shale"
    },
    {
      "x": -8,
      "y": 3,
      "z": 9,
      "name": "Rock_Shale"
    },
    {
      "x": -8,
      "y": 4,
      "z": 9,
      "name": "Rock_Shale"
    },
    {
      "x": -8,
      "y": 5,
      "z": 9,
      "name": "Rock_Shale"
    },
    {
      "x": -8,
      "y": 6,
      "z": 9,
      "name": "Rock_Shale"
    },
    {
      "x": -8,
      "y": 7,
      "z": 9,
      "name": "Rock_Shale"
    },
    {
      "x": -8,
      "y": 8,
      "z": 9,
      "name": "Rock_Shale"
    },
    {
      "x": -8,
      "y": 9,
      "z": 9,
      "name": "Rock_Shale"
    },
    {
      "x": -8,
      "y": 10,
      "z": 9,
      "name": "Soil_Dirt_Cold"
    },
    {
      "x": -8,
      "y": 11,
      "z": 9,
      "name": "Soil_Dirt_Cold"
    },
    {
      "x": -8,
      "y": 0,
      "z": 10,
      "name": "Wood_Fir_Trunk",
      "support": 15
    },
    {
      "x": -8,
      "y": 1,
      "z": 10,
      "name": "Wood_Fir_Trunk",
      "support": 15
    },
    {
      "x": -8,
      "y": 2,
      "z": 10,
      "name": "Wood_Fir_Trunk",
      "support": 15
    },
    {
      "x": -8,
      "y": 3,
      "z": 10,
      "name": "Wood_Fir_Trunk",
      "support": 15
    },
    {
      "x": -8,
      "y": 4,
      "z": 10,
      "name": "Wood_Fir_Trunk",
      "support": 15,
      "rotation": 4
    },
    {
      "x": -8,
      "y": 0,
      "z": 11,
      "name": "Wood_Fir_Trunk",
      "support": 15
    },
    {
      "x": -8,
      "y": 1,
      "z": 11,
      "name": "Wood_Fir_Trunk",
      "support": 15
    },
    {
      "x": -8,
      "y": 2,
      "z": 11,
      "name": "Wood_Fir_Trunk",
      "support": 15
    },
    {
      "x": -8,
      "y": 3,
      "z": 11,
      "name": "Wood_Fir_Trunk",
      "support": 15
    },
    {
      "x": -8,
      "y": 4,
      "z": 11,
      "name": "Wood_Fir_Trunk",
      "support": 15,
      "rotation": 4
    },
    {
      "x": -7,
      "y": 0,
      "z": -11,
      "name": "Wood_Fir_Trunk",
      "support": 15
    },
    {
      "x": -7,
      "y": 1,
      "z": -11,
      "name": "Wood_Fir_Trunk",
      "support": 15
    },
    {
      "x": -7,
      "y": 2,
      "z": -11,
      "name": "Wood_Fir_Trunk",
      "support": 15
    },
    {
      "x": -7,
      "y": 3,
      "z": -11,
      "name": "Wood_Fir_Trunk",
      "support": 15
    },
    {
      "x": -7,
      "y": 4,
      "z": -11,
      "name": "Wood_Fir_Trunk",
      "support": 15
    },
    {
      "x": -7,
      "y": 5,
      "z": -11,
      "name": "Wood_Fir_Trunk",
      "support": 15
    },
    {
      "x": -7,
      "y": 6,
      "z": -11,
      "name": "Wood_Fir_Trunk",
      "support": 15
    },
    {
      "x": -7,
      "y": 7,
      "z": -11,
      "name": "Wood_Fir_Trunk",
      "support": 15
    },
    {
      "x": -7,
      "y": 8,
      "z": -11,
      "name": "Wood_Fir_Trunk",
      "support": 15
    },
    {
      "x": -7,
      "y": 9,
      "z": -11,
      "name": "Wood_Fir_Trunk",
      "support": 15
    },
    {
      "x": -7,
      "y": 10,
      "z": -11,
      "name": "Wood_Fir_Trunk",
      "support": 15
    },
    {
      "x": -7,
      "y": 11,
      "z": -11,
      "name": "Wood_Fir_Trunk",
      "support": 15
    },
    {
      "x": -7,
      "y": 12,
      "z": -11,
      "name": "Wood_Fir_Trunk",
      "support": 15
    },
    {
      "x": -7,
      "y": 13,
      "z": -11,
      "name": "Wood_Fir_Trunk",
      "support": 15
    },
    {
      "x": -7,
      "y": 0,
      "z": -10,
      "name": "Soil_Dirt_Cold"
    },
    {
      "x": -7,
      "y": 1,
      "z": -10,
      "name": "Soil_Dirt_Cold"
    },
    {
      "x": -7,
      "y": 2,
      "z": -10,
      "name": "Soil_Dirt_Cold"
    },
    {
      "x": -7,
      "y": 3,
      "z": -10,
      "name": "Soil_Dirt_Cold"
    },
    {
      "x": -7,
      "y": 4,
      "z": -10,
      "name": "Soil_Dirt_Cold"
    },
    {
      "x": -7,
      "y": 5,
      "z": -10,
      "name": "Soil_Dirt_Cold"
    },
    {
      "x": -7,
      "y": 6,
      "z": -10,
      "name": "Soil_Dirt_Cold"
    },
    {
      "x": -7,
      "y": 7,
      "z": -10,
      "name": "Soil_Dirt_Cold"
    },
    {
      "x": -7,
      "y": 8,
      "z": -10,
      "name": "Soil_Dirt_Cold"
    },
    {
      "x": -7,
      "y": 9,
      "z": -10,
      "name": "Soil_Dirt_Cold"
    },
    {
      "x": -7,
      "y": 10,
      "z": -10,
      "name": "Soil_Dirt_Cold"
    },
    {
      "x": -7,
      "y": 11,
      "z": -10,
      "name": "Soil_Dirt_Cold"
    },
    {
      "x": -7,
      "y": 0,
      "z": -9,
      "name": "Soil_Dirt_Cold"
    },
    {
      "x": -7,
      "y": 1,
      "z": -9,
      "name": "Soil_Dirt_Cold"
    },
    {
      "x": -7,
      "y": 2,
      "z": -9,
      "name": "Soil_Dirt_Cold"
    },
    {
      "x": -7,
      "y": 3,
      "z": -9,
      "name": "Soil_Dirt_Cold"
    },
    {
      "x": -7,
      "y": 4,
      "z": -9,
      "name": "Soil_Dirt_Cold"
    },
    {
      "x": -7,
      "y": 5,
      "z": -9,
      "name": "Soil_Dirt_Cold"
    },
    {
      "x": -7,
      "y": 6,
      "z": -9,
      "name": "Soil_Dirt_Cold"
    },
    {
      "x": -7,
      "y": 7,
      "z": -9,
      "name": "Soil_Dirt_Cold"
    },
    {
      "x": -7,
      "y": 8,
      "z": -9,
      "name": "Soil_Dirt_Cold"
    },
    {
      "x": -7,
      "y": 9,
      "z": -9,
      "name": "Soil_Dirt_Cold"
    },
    {
      "x": -7,
      "y": 10,
      "z": -9,
      "name": "Soil_Dirt_Cold"
    },
    {
      "x": -7,
      "y": 11,
      "z": -9,
      "name": "Soil_Dirt_Cold"
    },
    {
      "x": -7,
      "y": 0,
      "z": -8,
      "name": "Rock_Shale"
    },
    {
      "x": -7,
      "y": 1,
      "z": -8,
      "name": "Rock_Shale"
    },
    {
      "x": -7,
      "y": 2,
      "z": -8,
      "name": "Rock_Shale"
    },
    {
      "x": -7,
      "y": 3,
      "z": -8,
      "name": "Rock_Shale"
    },
    {
      "x": -7,
      "y": 4,
      "z": -8,
      "name": "Rock_Shale"
    },
    {
      "x": -7,
      "y": 5,
      "z": -8,
      "name": "Rock_Shale"
    },
    {
      "x": -7,
      "y": 6,
      "z": -8,
      "name": "Rock_Shale"
    },
    {
      "x": -7,
      "y": 7,
      "z": -8,
      "name": "Rock_Shale"
    },
    {
      "x": -7,
      "y": 8,
      "z": -8,
      "name": "Rock_Shale"
    },
    {
      "x": -7,
      "y": 9,
      "z": -8,
      "name": "Rock_Shale"
    },
    {
      "x": -7,
      "y": 10,
      "z": -8,
      "name": "Rock_Shale"
    },
    {
      "x": -7,
      "y": 11,
      "z": -8,
      "name": "Rock_Shale"
    },
    {
      "x": -7,
      "y": 17,
      "z": -8,
      "name": "Rock_Basalt_Cobble_Roof",
      "rotation": 2
    },
    {
      "x": -7,
      "y": 0,
      "z": -7,
      "name": "Rock_Shale"
    },
    {
      "x": -7,
      "y": 1,
      "z": -7,
      "name": "Rock_Shale"
    },
    {
      "x": -7,
      "y": 2,
      "z": -7,
      "name": "Rock_Shale"
    },
    {
      "x": -7,
      "y": 3,
      "z": -7,
      "name": "Rock_Shale"
    },
    {
      "x": -7,
      "y": 4,
      "z": -7,
      "name": "Rock_Shale"
    },
    {
      "x": -7,
      "y": 5,
      "z": -7,
      "name": "Rock_Shale"
    },
    {
      "x": -7,
      "y": 6,
      "z": -7,
      "name": "Rock_Shale"
    },
    {
      "x": -7,
      "y": 7,
      "z": -7,
      "name": "Rock_Shale"
    },
    {
      "x": -7,
      "y": 8,
      "z": -7,
      "name": "Rock_Shale"
    },
    {
      "x": -7,
      "y": 9,
      "z": -7,
      "name": "Rock_Shale"
    },
    {
      "x": -7,
      "y": 10,
      "z": -7,
      "name": "Rock_Shale"
    },
    {
      "x": -7,
      "y": 11,
      "z": -7,
      "name": "Rock_Shale"
    },
    {
      "x": -7,
      "y": 14,
      "z": -7,
      "name": "Rock_Shale_Brick_Half",
      "rotation": 6
    },
    {
      "x": -7,
      "y": 15,
      "z": -7,
      "name": "Rock_Shale_Brick_Half",
      "rotation": 6
    },
    {
      "x": -7,
      "y": 16,
      "z": -7,
      "name": "Wood_Redwood_Trunk",
      "rotation": 5
    },
    {
      "x": -7,
      "y": 17,
      "z": -7,
      "name": "Wood_Redwood_Trunk",
      "rotation": 5
    },
    {
      "x": -7,
      "y": 18,
      "z": -7,
      "name": "Rock_Basalt_Cobble_Roof",
      "rotation": 2
    },
    {
      "x": -7,
      "y": 0,
      "z": -6,
      "name": "Rock_Shale"
    },
    {
      "x": -7,
      "y": 1,
      "z": -6,
      "name": "Rock_Shale"
    },
    {
      "x": -7,
      "y": 2,
      "z": -6,
      "name": "Rock_Shale"
    },
    {
      "x": -7,
      "y": 3,
      "z": -6,
      "name": "Rock_Shale"
    },
    {
      "x": -7,
      "y": 4,
      "z": -6,
      "name": "Rock_Shale"
    },
    {
      "x": -7,
      "y": 5,
      "z": -6,
      "name": "Rock_Shale"
    },
    {
      "x": -7,
      "y": 6,
      "z": -6,
      "name": "Rock_Shale"
    },
    {
      "x": -7,
      "y": 7,
      "z": -6,
      "name": "Rock_Shale"
    },
    {
      "x": -7,
      "y": 8,
      "z": -6,
      "name": "Rock_Shale"
    },
    {
      "x": -7,
      "y": 9,
      "z": -6,
      "name": "Soil_Dirt_Cold"
    },
    {
      "x": -7,
      "y": 10,
      "z": -6,
      "name": "Soil_Dirt_Cold"
    },
    {
      "x": -7,
      "y": 11,
      "z": -6,
      "name": "Rock_Shale"
    },
    {
      "x": -7,
      "y": 12,
      "z": -6,
      "name": "Rock_Shale"
    },
    {
      "x": -7,
      "y": 13,
      "z": -6,
      "name": "Rock_Shale"
    },
    {
      "x": -7,
      "y": 14,
      "z": -6,
      "name": "Rock_Shale_Brick"
    },
    {
      "x": -7,
      "y": 15,
      "z": -6,
      "name": "Rock_Shale_Brick"
    },
    {
      "x": -7,
      "y": 16,
      "z": -6,
      "name": "Rock_Shale_Brick"
    },
    {
      "x": -7,
      "y": 17,
      "z": -6,
      "name": "Wood_Redwood_Planks"
    },
    {
      "x": -7,
      "y": 18,
      "z": -6,
      "name": "Wood_Redwood_Planks"
    },
    {
      "x": -7,
      "y": 19,
      "z": -6,
      "name": "Rock_Basalt_Cobble_Roof",
      "rotation": 2
    },
    {
      "x": -7,
      "y": 0,
      "z": -5,
      "name": "Rock_Shale"
    },
    {
      "x": -7,
      "y": 1,
      "z": -5,
      "name": "Rock_Shale"
    },
    {
      "x": -7,
      "y": 2,
      "z": -5,
      "name": "Rock_Shale"
    },
    {
      "x": -7,
      "y": 3,
      "z": -5,
      "name": "Rock_Shale"
    },
    {
      "x": -7,
      "y": 4,
      "z": -5,
      "name": "Rock_Shale"
    },
    {
      "x": -7,
      "y": 5,
      "z": -5,
      "name": "Rock_Shale"
    },
    {
      "x": -7,
      "y": 6,
      "z": -5,
      "name": "Rock_Shale"
    },
    {
      "x": -7,
      "y": 7,
      "z": -5,
      "name": "Rock_Shale"
    },
    {
      "x": -7,
      "y": 8,
      "z": -5,
      "name": "Soil_Dirt_Cold"
    },
    {
      "x": -7,
      "y": 9,
      "z": -5,
      "name": "Soil_Dirt_Cold"
    },
    {
      "x": -7,
      "y": 10,
      "z": -5,
      "name": "Soil_Dirt_Cold"
    },
    {
      "x": -7,
      "y": 11,
      "z": -5,
      "name": "Soil_Dirt_Cold"
    },
    {
      "x": -7,
      "y": 12,
      "z": -5,
      "name": "Furniture_Village_Crate"
    },
    {
      "x": -7,
      "y": 13,
      "z": -5,
      "name": "Furniture_Village_Crate"
    },
    {
      "x": -7,
      "y": 16,
      "z": -5,
      "name": "Wood_Redwood_Trunk",
      "rotation": 4
    },
    {
      "x": -7,
      "y": 17,
      "z": -5,
      "name": "Wood_Redwood_Planks"
    },
    {
      "x": -7,
      "y": 18,
      "z": -5,
      "name": "Wood_Redwood_Planks"
    },
    {
      "x": -7,
      "y": 19,
      "z": -5,
      "name": "Wood_Redwood_Planks"
    },
    {
      "x": -7,
      "y": 20,
      "z": -5,
      "name": "Rock_Basalt_Cobble_Roof",
      "rotation": 2
    },
    {
      "x": -7,
      "y": 0,
      "z": -4,
      "name": "Rock_Shale"
    },
    {
      "x": -7,
      "y": 1,
      "z": -4,
      "name": "Rock_Shale"
    },
    {
      "x": -7,
      "y": 2,
      "z": -4,
      "name": "Rock_Shale"
    },
    {
      "x": -7,
      "y": 3,
      "z": -4,
      "name": "Rock_Shale"
    },
    {
      "x": -7,
      "y": 4,
      "z": -4,
      "name": "Rock_Shale"
    },
    {
      "x": -7,
      "y": 5,
      "z": -4,
      "name": "Rock_Shale"
    },
    {
      "x": -7,
      "y": 6,
      "z": -4,
      "name": "Rock_Shale_Cobble"
    },
    {
      "x": -7,
      "y": 7,
      "z": -4,
      "name": "Rock_Shale"
    },
    {
      "x": -7,
      "y": 8,
      "z": -4,
      "name": "Soil_Dirt_Cold"
    },
    {
      "x": -7,
      "y": 9,
      "z": -4,
      "name": "Soil_Dirt_Cold"
    },
    {
      "x": -7,
      "y": 10,
      "z": -4,
      "name": "Soil_Dirt_Cold"
    },
    {
      "x": -7,
      "y": 11,
      "z": -4,
      "name": "Soil_Dirt_Cold"
    },
    {
      "x": -7,
      "y": 12,
      "z": -4,
      "name": "Furniture_Village_Crate"
    },
    {
      "x": -7,
      "y": 16,
      "z": -4,
      "name": "Wood_Redwood_Trunk",
      "rotation": 4
    },
    {
      "x": -7,
      "y": 17,
      "z": -4,
      "name": "Wood_Redwood_Planks"
    },
    {
      "x": -7,
      "y": 19,
      "z": -4,
      "name": "Furniture_Lumberjack_Platform"
    },
    {
      "x": -7,
      "y": 20,
      "z": -4,
      "name": "Wood_Redwood_Planks"
    },
    {
      "x": -7,
      "y": 21,
      "z": -4,
      "name": "Rock_Basalt_Cobble_Roof",
      "rotation": 2
    },
    {
      "x": -7,
      "y": 0,
      "z": -3,
      "name": "Rock_Shale"
    },
    {
      "x": -7,
      "y": 1,
      "z": -3,
      "name": "Rock_Shale"
    },
    {
      "x": -7,
      "y": 2,
      "z": -3,
      "name": "Rock_Shale"
    },
    {
      "x": -7,
      "y": 3,
      "z": -3,
      "name": "Rock_Shale"
    },
    {
      "x": -7,
      "y": 4,
      "z": -3,
      "name": "Rock_Shale"
    },
    {
      "x": -7,
      "y": 5,
      "z": -3,
      "name": "Rock_Shale_Cobble"
    },
    {
      "x": -7,
      "y": 6,
      "z": -3,
      "name": "Rock_Shale_Cobble"
    },
    {
      "x": -7,
      "y": 7,
      "z": -3,
      "name": "Rock_Shale_Cobble"
    },
    {
      "x": -7,
      "y": 8,
      "z": -3,
      "name": "Soil_Dirt_Cold"
    },
    {
      "x": -7,
      "y": 9,
      "z": -3,
      "name": "Soil_Dirt_Cold"
    },
    {
      "x": -7,
      "y": 10,
      "z": -3,
      "name": "Soil_Dirt_Cold"
    },
    {
      "x": -7,
      "y": 11,
      "z": -3,
      "name": "Soil_Dirt_Cold"
    },
    {
      "x": -7,
      "y": 12,
      "z": -3,
      "name": "Furniture_Lumberjack_Platform",
      "rotation": 1
    },
    {
      "x": -7,
      "y": 16,
      "z": -3,
      "name": "Wood_Redwood_Trunk",
      "rotation": 4
    },
    {
      "x": -7,
      "y": 17,
      "z": -3,
      "name": "Wood_Redwood_Planks"
    },
    {
      "x": -7,
      "y": 21,
      "z": -3,
      "name": "Wood_Redwood_Planks"
    },
    {
      "x": -7,
      "y": 22,
      "z": -3,
      "name": "Rock_Basalt_Cobble_Roof",
      "rotation": 2
    },
    {
      "x": -7,
      "y": 0,
      "z": -2,
      "name": "Rock_Shale"
    },
    {
      "x": -7,
      "y": 1,
      "z": -2,
      "name": "Rock_Shale"
    },
    {
      "x": -7,
      "y": 2,
      "z": -2,
      "name": "Rock_Shale"
    },
    {
      "x": -7,
      "y": 3,
      "z": -2,
      "name": "Rock_Shale"
    },
    {
      "x": -7,
      "y": 4,
      "z": -2,
      "name": "Rock_Shale"
    },
    {
      "x": -7,
      "y": 5,
      "z": -2,
      "name": "Rock_Shale"
    },
    {
      "x": -7,
      "y": 6,
      "z": -2,
      "name": "Rock_Shale_Cobble"
    },
    {
      "x": -7,
      "y": 7,
      "z": -2,
      "name": "Rock_Shale"
    },
    {
      "x": -7,
      "y": 8,
      "z": -2,
      "name": "Soil_Dirt_Cold"
    },
    {
      "x": -7,
      "y": 9,
      "z": -2,
      "name": "Soil_Dirt_Cold"
    },
    {
      "x": -7,
      "y": 10,
      "z": -2,
      "name": "Soil_Dirt_Cold"
    },
    {
      "x": -7,
      "y": 11,
      "z": -2,
      "name": "Soil_Dirt_Cold"
    },
    {
      "x": -7,
      "y": 12,
      "z": -2,
      "name": "Furniture_Lumberjack_Platform",
      "rotation": 1
    },
    {
      "x": -7,
      "y": 13,
      "z": -2,
      "name": "Deco_Mug"
    },
    {
      "x": -7,
      "y": 16,
      "z": -2,
      "name": "Wood_Redwood_Trunk",
      "rotation": 4
    },
    {
      "x": -7,
      "y": 17,
      "z": -2,
      "name": "Wood_Redwood_Planks"
    },
    {
      "x": -7,
      "y": 22,
      "z": -2,
      "name": "Wood_Redwood_Trunk",
      "rotation": 5
    },
    {
      "x": -7,
      "y": 23,
      "z": -2,
      "name": "Rock_Basalt_Cobble_Roof_Flat"
    },
    {
      "x": -7,
      "y": 0,
      "z": -1,
      "name": "Rock_Shale"
    },
    {
      "x": -7,
      "y": 1,
      "z": -1,
      "name": "Rock_Shale"
    },
    {
      "x": -7,
      "y": 2,
      "z": -1,
      "name": "Rock_Shale"
    },
    {
      "x": -7,
      "y": 3,
      "z": -1,
      "name": "Rock_Shale"
    },
    {
      "x": -7,
      "y": 4,
      "z": -1,
      "name": "Rock_Shale"
    },
    {
      "x": -7,
      "y": 5,
      "z": -1,
      "name": "Rock_Shale"
    },
    {
      "x": -7,
      "y": 6,
      "z": -1,
      "name": "Rock_Shale"
    },
    {
      "x": -7,
      "y": 7,
      "z": -1,
      "name": "Rock_Shale"
    },
    {
      "x": -7,
      "y": 8,
      "z": -1,
      "name": "Soil_Dirt_Cold"
    },
    {
      "x": -7,
