{
  "version": 8,
  "blockIdVersion": 8,
  "anchorX": 0,
  "anchorY": 17,
  "anchorZ": 1,
  "blocks": [
    {
      "x": -5,
      "y": 24,
      "z": 0,
      "name": "Soil_Dirt_Cold"
    },
    {
      "x": -5,
      "y": 25,
      "z": 0,
      "name": "Soil_Dirt_Cold"
    },
    {
      "x": -5,
      "y": 26,
      "z": 0,
      "name": "Soil_Grass_Cold"
    },
    {
      "x": -5,
      "y": 21,
      "z": 1,
      "name": "Rock_Shale"
    },
    {
      "x": -5,
      "y": 22,
      "z": 1,
      "name": "Rock_Shale"
    },
    {
      "x": -5,
      "y": 23,
      "z": 1,
      "name": "Rock_Shale"
    },
    {
      "x": -5,
      "y": 24,
      "z": 1,
      "name": "Soil_Dirt_Cold"
    },
    {
      "x": -5,
      "y": 25,
      "z": 1,
      "name": "Soil_Dirt_Cold"
    },
    {
      "x": -5,
      "y": 26,
      "z": 1,
      "name": "Soil_Grass_Cold"
    },
    {
      "x": -5,
      "y": 23,
      "z": 2,
      "name": "Rock_Shale"
    },
    {
      "x": -5,
      "y": 24,
      "z": 2,
      "name": "Soil_Dirt_Cold"
    },
    {
      "x": -5,
      "y": 25,
      "z": 2,
      "name": "Soil_Dirt_Cold"
    },
    {
      "x": -5,
      "y": 26,
      "z": 2,
      "name": "Soil_Grass_Cold"
    },
    {
      "x": -4,
      "y": 21,
      "z": -1,
      "name": "Rock_Shale"
    },
    {
      "x": -4,
      "y": 22,
      "z": -1,
      "name": "Rock_Shale"
    },
    {
      "x": -4,
      "y": 23,
      "z": -1,
      "name": "Rock_Shale"
    },
    {
      "x": -4,
      "y": 24,
      "z": -1,
      "name": "Soil_Dirt_Cold"
    },
    {
      "x": -4,
      "y": 25,
      "z": -1,
      "name": "Soil_Grass_Cold"
    },
    {
      "x": -4,
      "y": 18,
      "z": 0,
      "name": "Rock_Shale"
    },
    {
      "x": -4,
      "y": 19,
      "z": 0,
      "name": "Rock_Basalt"
    },
    {
      "x": -4,
      "y": 20,
      "z": 0,
      "name": "Rock_Shale"
    },
    {
      "x": -4,
      "y": 21,
      "z": 0,
      "name": "Rock_Shale"
    },
    {
      "x": -4,
      "y": 22,
      "z": 0,
      "name": "Rock_Shale"
    },
    {
      "x": -4,
      "y": 23,
      "z": 0,
      "name": "Rock_Shale"
    },
    {
      "x": -4,
      "y": 24,
      "z": 0,
      "name": "Soil_Dirt_Cold"
    },
    {
      "x": -4,
      "y": 25,
      "z": 0,
      "name": "Soil_Dirt_Cold"
    },
    {
      "x": -4,
      "y": 26,
      "z": 0,
      "name": "Soil_Grass_Cold"
    },
    {
      "x": -4,
      "y": 19,
      "z": 1,
      "name": "Rock_Shale"
    },
    {
      "x": -4,
      "y": 20,
      "z": 1,
      "name": "Rock_Shale"
    },
    {
      "x": -4,
      "y": 21,
      "z": 1,
      "name": "Rock_Shale"
    },
    {
      "x": -4,
      "y": 22,
      "z": 1,
      "name": "Rock_Shale"
    },
    {
      "x": -4,
      "y": 23,
      "z": 1,
      "name": "Rock_Shale"
    },
    {
      "x": -4,
      "y": 24,
      "z": 1,
      "name": "Soil_Dirt_Cold"
    },
    {
      "x": -4,
      "y": 25,
      "z": 1,
      "name": "Soil_Dirt_Cold"
    },
    {
      "x": -4,
      "y": 26,
      "z": 1,
      "name": "Soil_Grass_Cold"
    },
    {
      "x": -4,
      "y": 27,
      "z": 1,
      "name": "Plant_Grass_Winter"
    },
    {
      "x": -4,
      "y": 22,
      "z": 2,
      "name": "Rock_Shale"
    },
    {
      "x": -4,
      "y": 23,
      "z": 2,
      "name": "Rock_Shale"
    },
    {
      "x": -4,
      "y": 24,
      "z": 2,
      "name": "Soil_Dirt_Cold"
    },
    {
      "x": -4,
      "y": 25,
      "z": 2,
      "name": "Soil_Dirt_Cold"
    },
    {
      "x": -4,
      "y": 26,
      "z": 2,
      "name": "Soil_Grass_Cold"
    },
    {
      "x": -4,
      "y": 27,
      "z": 2,
      "name": "Plant_Grass_Winter"
    },
    {
      "x": -3,
      "y": 22,
      "z": -2,
      "name": "Soil_Grass"
    },
    {
      "x": -3,
      "y": 23,
      "z": -2,
      "name": "Plant_Grass_Lush_Short"
    },
    {
      "x": -3,
      "y": 19,
      "z": -1,
      "name": "Rock_Basalt"
    },
    {
      "x": -3,
      "y": 20,
      "z": -1,
      "name": "Rock_Shale"
    },
    {
      "x": -3,
      "y": 21,
      "z": -1,
      "name": "Rock_Shale"
    },
    {
      "x": -3,
      "y": 22,
      "z": -1,
      "name": "Rock_Shale"
    },
    {
      "x": -3,
      "y": 23,
      "z": -1,
      "name": "Rock_Shale"
    },
    {
      "x": -3,
      "y": 24,
      "z": -1,
      "name": "Soil_Dirt_Cold"
    },
    {
      "x": -3,
      "y": 25,
      "z": -1,
      "name": "Soil_Dirt_Cold"
    },
    {
      "x": -3,
      "y": 26,
      "z": -1,
      "name": "Soil_Grass_Cold"
    },
    {
      "x": -3,
      "y": 11,
      "z": 0,
      "name": "Rock_Basalt"
    },
    {
      "x": -3,
      "y": 12,
      "z": 0,
      "name": "Rock_Basalt"
    },
    {
      "x": -3,
      "y": 13,
      "z": 0,
      "name": "Rock_Basalt"
    },
    {
      "x": -3,
      "y": 14,
      "z": 0,
      "name": "Rock_Basalt"
    },
    {
      "x": -3,
      "y": 15,
      "z": 0,
      "name": "Rock_Basalt"
    },
    {
      "x": -3,
      "y": 16,
      "z": 0,
      "name": "Rock_Basalt"
    },
    {
      "x": -3,
      "y": 17,
      "z": 0,
      "name": "Rock_Shale"
    },
    {
      "x": -3,
      "y": 18,
      "z": 0,
      "name": "Rock_Shale"
    },
    {
      "x": -3,
      "y": 19,
      "z": 0,
      "name": "Rock_Shale"
    },
    {
      "x": -3,
      "y": 20,
      "z": 0,
      "name": "Rock_Shale"
    },
    {
      "x": -3,
      "y": 21,
      "z": 0,
      "name": "Rock_Shale"
    },
    {
      "x": -3,
      "y": 22,
      "z": 0,
      "name": "Rock_Shale"
    },
    {
      "x": -3,
      "y": 23,
      "z": 0,
      "name": "Rock_Shale"
    },
    {
      "x": -3,
      "y": 24,
      "z": 0,
      "name": "Soil_Dirt_Cold"
    },
    {
      "x": -3,
      "y": 25,
      "z": 0,
      "name": "Soil_Dirt_Cold"
    },
    {
      "x": -3,
      "y": 26,
      "z": 0,
      "name": "Soil_Grass_Cold"
    },
    {
      "x": -3,
      "y": 11,
      "z": 1,
      "name": "Rock_Basalt"
    },
    {
      "x": -3,
      "y": 12,
      "z": 1,
      "name": "Rock_Basalt"
    },
    {
      "x": -3,
      "y": 13,
      "z": 1,
      "name": "Rock_Basalt"
    },
    {
      "x": -3,
      "y": 14,
      "z": 1,
      "name": "Rock_Basalt"
    },
    {
      "x": -3,
      "y": 15,
      "z": 1,
      "name": "Rock_Basalt"
    },
    {
      "x": -3,
      "y": 16,
      "z": 1,
      "name": "Rock_Basalt"
    },
    {
      "x": -3,
      "y": 17,
      "z": 1,
      "name": "Rock_Shale"
    },
    {
      "x": -3,
      "y": 18,
      "z": 1,
      "name": "Rock_Shale"
    },
    {
      "x": -3,
      "y": 19,
      "z": 1,
      "name": "Rock_Shale"
    },
    {
      "x": -3,
      "y": 20,
      "z": 1,
      "name": "Rock_Shale"
    },
    {
      "x": -3,
      "y": 21,
      "z": 1,
      "name": "Rock_Shale"
    },
    {
      "x": -3,
      "y": 22,
      "z": 1,
      "name": "Rock_Shale"
    },
    {
      "x": -3,
      "y": 23,
      "z": 1,
      "name": "Rock_Shale"
    },
    {
      "x": -3,
      "y": 24,
      "z": 1,
      "name": "Rock_Shale"
    },
    {
      "x": -3,
      "y": 25,
      "z": 1,
      "name": "Soil_Dirt_Cold"
    },
    {
      "x": -3,
      "y": 26,
      "z": 1,
      "name": "Soil_Grass_Cold"
    },
    {
      "x": -3,
      "y": 27,
      "z": 1,
      "name": "Plant_Grass_Winter"
    },
    {
      "x": -3,
      "y": 11,
      "z": 2,
      "name": "Rock_Basalt"
    },
    {
      "x": -3,
      "y": 12,
      "z": 2,
      "name": "Rock_Basalt"
    },
    {
      "x": -3,
      "y": 13,
      "z": 2,
      "name": "Rock_Basalt"
    },
    {
      "x": -3,
      "y": 14,
      "z": 2,
      "name": "Rock_Basalt"
    },
    {
      "x": -3,
      "y": 15,
      "z": 2,
      "name": "Rock_Basalt"
    },
    {
      "x": -3,
      "y": 16,
      "z": 2,
      "name": "Rock_Shale"
    },
    {
      "x": -3,
      "y": 17,
      "z": 2,
      "name": "Rock_Shale"
    },
    {
      "x": -3,
      "y": 18,
      "z": 2,
      "name": "Rock_Shale"
    },
    {
      "x": -3,
      "y": 19,
      "z": 2,
      "name": "Rock_Shale"
    },
    {
      "x": -3,
      "y": 20,
      "z": 2,
      "name": "Rock_Shale"
    },
    {
      "x": -3,
      "y": 21,
      "z": 2,
      "name": "Rock_Shale"
    },
    {
      "x": -3,
      "y": 22,
      "z": 2,
      "name": "Rock_Shale"
    },
    {
      "x": -3,
      "y": 23,
      "z": 2,
      "name": "Rock_Shale"
    },
    {
      "x": -3,
      "y": 24,
      "z": 2,
      "name": "Rock_Shale"
    },
    {
      "x": -3,
      "y": 25,
      "z": 2,
      "name": "Soil_Dirt_Cold"
    },
    {
      "x": -3,
      "y": 26,
      "z": 2,
      "name": "Soil_Grass_Cold"
    },
    {
      "x": -3,
      "y": 27,
      "z": 2,
      "name": "Plant_Grass_Winter_Tall"
    },
    {
      "x": -3,
      "y": 28,
      "z": 2,
      "name": "Plant_Grass_Winter_Tall",
      "filler": 1024
    },
    {
      "x": -3,
      "y": 16,
      "z": 3,
      "name": "Rock_Shale"
    },
    {
      "x": -3,
      "y": 17,
      "z": 3,
      "name": "Rock_Shale"
    },
    {
      "x": -3,
      "y": 18,
      "z": 3,
      "name": "Rock_Shale"
    },
    {
      "x": -3,
      "y": 19,
      "z": 3,
      "name": "Rock_Shale"
    },
    {
      "x": -3,
      "y": 20,
      "z": 3,
      "name": "Rock_Shale"
    },
    {
      "x": -3,
      "y": 21,
      "z": 3,
      "name": "Rock_Shale"
    },
    {
      "x": -3,
      "y": 22,
      "z": 3,
      "name": "Rock_Shale"
    },
    {
      "x": -3,
      "y": 23,
      "z": 3,
      "name": "Rock_Shale"
    },
    {
      "x": -3,
      "y": 24,
      "z": 3,
      "name": "Rock_Shale"
    },
    {
      "x": -3,
      "y": 25,
      "z": 3,
      "name": "Soil_Dirt_Cold"
    },
    {
      "x": -3,
      "y": 26,
      "z": 3,
      "name": "Soil_Grass_Cold"
    },
    {
      "x": -3,
      "y": 27,
      "z": 3,
      "name": "Plant_Grass_Winter_Tall"
    },
    {
      "x": -3,
      "y": 28,
      "z": 3,
      "name": "Plant_Grass_Winter_Tall",
      "filler": 1024
    },
    {
      "x": -3,
      "y": 18,
      "z": 4,
      "name": "Rock_Shale"
    },
    {
      "x": -3,
      "y": 19,
      "z": 4,
      "name": "Rock_Shale"
    },
    {
      "x": -3,
      "y": 20,
      "z": 4,
      "name": "Rock_Shale"
    },
    {
      "x": -3,
      "y": 21,
      "z": 4,
      "name": "Rock_Shale"
    },
    {
      "x": -3,
      "y": 22,
      "z": 4,
      "name": "Rock_Shale"
    },
    {
      "x": -3,
      "y": 23,
      "z": 4,
      "name": "Rock_Shale"
    },
    {
      "x": -2,
      "y": 20,
      "z": -3,
      "name": "Soil_Dirt"
    },
    {
      "x": -2,
      "y": 21,
      "z": -3,
      "name": "Soil_Grass"
    },
    {
      "x": -2,
      "y": 13,
      "z": -2,
      "name": "Rock_Basalt"
    },
    {
      "x": -2,
      "y": 14,
      "z": -2,
      "name": "Rock_Basalt"
    },
    {
      "x": -2,
      "y": 15,
      "z": -2,
      "name": "Rock_Basalt"
    },
    {
      "x": -2,
      "y": 16,
      "z": -2,
      "name": "Rock_Basalt"
    },
    {
      "x": -2,
      "y": 17,
      "z": -2,
      "name": "Rock_Basalt"
    },
    {
      "x": -2,
      "y": 18,
      "z": -2,
      "name": "Rock_Basalt"
    },
    {
      "x": -2,
      "y": 19,
      "z": -2,
      "name": "Soil_Dirt"
    },
    {
      "x": -2,
      "y": 20,
      "z": -2,
      "name": "Soil_Dirt"
    },
    {
      "x": -2,
      "y": 21,
      "z": -2,
      "name": "Soil_Dirt"
    },
    {
      "x": -2,
      "y": 22,
      "z": -2,
      "name": "Soil_Grass"
    },
    {
      "x": -2,
      "y": 23,
      "z": -2,
      "name": "Plant_Grass_Sharp"
    },
    {
      "x": -2,
      "y": 10,
      "z": -1,
      "name": "Rock_Basalt"
    },
    {
      "x": -2,
      "y": 11,
      "z": -1,
      "name": "Rock_Basalt"
    },
    {
      "x": -2,
      "y": 12,
      "z": -1,
      "name": "Rock_Basalt"
    },
    {
      "x": -2,
      "y": 13,
      "z": -1,
      "name": "Rock_Basalt"
    },
    {
      "x": -2,
      "y": 14,
      "z": -1,
      "name": "Rock_Basalt"
    },
    {
      "x": -2,
      "y": 15,
      "z": -1,
      "name": "Rock_Basalt"
    },
    {
      "x": -2,
      "y": 16,
      "z": -1,
      "name": "Rock_Basalt"
    },
    {
      "x": -2,
      "y": 17,
      "z": -1,
      "name": "Rock_Basalt"
    },
    {
      "x": -2,
      "y": 18,
      "z": -1,
      "name": "Rock_Basalt"
    },
    {
      "x": -2,
      "y": 19,
      "z": -1,
      "name": "Rock_Basalt"
    },
    {
      "x": -2,
      "y": 20,
      "z": -1,
      "name": "Soil_Dirt"
    },
    {
      "x": -2,
      "y": 21,
      "z": -1,
      "name": "Soil_Dirt"
    },
    {
      "x": -2,
      "y": 22,
      "z": -1,
      "name": "Rock_Shale"
    },
    {
      "x": -2,
      "y": 23,
      "z": -1,
      "name": "Rock_Shale"
    },
    {
      "x": -2,
      "y": 24,
      "z": -1,
      "name": "Rock_Shale"
    },
    {
      "x": -2,
      "y": 25,
      "z": -1,
      "name": "Soil_Dirt_Cold"
    },
    {
      "x": -2,
      "y": 26,
      "z": -1,
      "name": "Soil_Grass_Cold"
    },
    {
      "x": -2,
      "y": 8,
      "z": 0,
      "name": "Rock_Basalt"
    },
    {
      "x": -2,
      "y": 9,
      "z": 0,
      "name": "Rock_Basalt"
    },
    {
      "x": -2,
      "y": 10,
      "z": 0,
      "name": "Rock_Basalt"
    },
    {
      "x": -2,
      "y": 11,
      "z": 0,
      "name": "Rock_Basalt"
    },
    {
      "x": -2,
      "y": 12,
      "z": 0,
      "name": "Rock_Basalt"
    },
    {
      "x": -2,
      "y": 13,
      "z": 0,
      "name": "Rock_Basalt"
    },
    {
      "x": -2,
      "y": 14,
      "z": 0,
      "name": "Rock_Basalt"
    },
    {
      "x": -2,
      "y": 15,
      "z": 0,
      "name": "Rock_Basalt"
    },
    {
      "x": -2,
      "y": 16,
      "z": 0,
      "name": "Rock_Basalt"
    },
    {
      "x": -2,
      "y": 17,
      "z": 0,
      "name": "Rock_Basalt"
    },
    {
      "x": -2,
      "y": 18,
      "z": 0,
      "name": "Rock_Shale"
    },
    {
      "x": -2,
      "y": 19,
      "z": 0,
      "name": "Rock_Basalt"
    },
    {
      "x": -2,
      "y": 20,
      "z": 0,
      "name": "Rock_Shale"
    },
    {
      "x": -2,
      "y": 21,
      "z": 0,
      "name": "Rock_Shale"
    },
    {
      "x": -2,
      "y": 22,
      "z": 0,
      "name": "Rock_Shale"
    },
    {
      "x": -2,
      "y": 23,
      "z": 0,
      "name": "Rock_Shale"
    },
    {
      "x": -2,
      "y": 24,
      "z": 0,
      "name": "Rock_Shale"
    },
    {
      "x": -2,
      "y": 25,
      "z": 0,
      "name": "Soil_Dirt_Cold"
    },
    {
      "x": -2,
      "y": 26,
      "z": 0,
      "name": "Soil_Dirt"
    },
    {
      "x": -2,
      "y": 27,
      "z": 0,
      "name": "Soil_Dirt_Cold"
    },
    {
      "x": -2,
      "y": 28,
      "z": 0,
      "name": "Soil_Dirt_Cold"
    },
    {
      "x": -2,
      "y": 29,
      "z": 0,
      "name": "Soil_Grass_Cold"
    },
    {
      "x": -2,
      "y": 7,
      "z": 1,
      "name": "Rock_Basalt"
    },
    {
      "x": -2,
      "y": 8,
      "z": 1,
      "name": "Rock_Basalt"
    },
    {
      "x": -2,
      "y": 9,
      "z": 1,
      "name": "Rock_Basalt"
    },
    {
      "x": -2,
      "y": 10,
      "z": 1,
      "name": "Rock_Basalt"
    },
    {
      "x": -2,
      "y": 11,
      "z": 1,
      "name": "Rock_Basalt"
    },
    {
      "x": -2,
      "y": 12,
      "z": 1,
      "name": "Rock_Basalt"
    },
    {
      "x": -2,
      "y": 13,
      "z": 1,
      "name": "Rock_Basalt"
    },
    {
      "x": -2,
      "y": 14,
      "z": 1,
      "name": "Rock_Basalt"
    },
    {
      "x": -2,
      "y": 15,
      "z": 1,
      "name": "Rock_Basalt"
    },
    {
      "x": -2,
      "y": 16,
      "z": 1,
      "name": "Rock_Basalt"
    },
    {
      "x": -2,
      "y": 17,
      "z": 1,
      "name": "Rock_Shale"
    },
    {
      "x": -2,
      "y": 18,
      "z": 1,
      "name": "Rock_Shale"
    },
    {
      "x": -2,
      "y": 19,
      "z": 1,
      "name": "Rock_Shale"
    },
    {
      "x": -2,
      "y": 20,
      "z": 1,
      "name": "Rock_Shale"
    },
    {
      "x": -2,
      "y": 21,
      "z": 1,
      "name": "Rock_Shale"
    },
    {
      "x": -2,
      "y": 22,
      "z": 1,
      "name": "Rock_Shale"
    },
    {
      "x": -2,
      "y": 23,
      "z": 1,
      "name": "Rock_Shale"
    },
    {
      "x": -2,
      "y": 24,
      "z": 1,
      "name": "Rock_Shale"
    },
    {
      "x": -2,
      "y": 25,
      "z": 1,
      "name": "Rock_Shale"
    },
    {
      "x": -2,
      "y": 26,
      "z": 1,
      "name": "Soil_Dirt"
    },
    {
      "x": -2,
      "y": 27,
      "z": 1,
      "name": "Rock_Shale"
    },
    {
      "x": -2,
      "y": 28,
      "z": 1,
      "name": "Soil_Dirt_Cold"
    },
    {
      "x": -2,
      "y": 29,
      "z": 1,
      "name": "Soil_Dirt_Cold"
    },
    {
      "x": -2,
      "y": 30,
      "z": 1,
      "name": "Soil_Grass_Cold"
    },
    {
      "x": -2,
      "y": 8,
      "z": 2,
      "name": "Rock_Basalt"
    },
    {
      "x": -2,
      "y": 9,
      "z": 2,
      "name": "Rock_Basalt"
    },
    {
      "x": -2,
      "y": 10,
      "z": 2,
      "name": "Rock_Basalt"
    },
    {
      "x": -2,
      "y": 11,
      "z": 2,
      "name": "Rock_Basalt"
    },
    {
      "x": -2,
      "y": 12,
      "z": 2,
      "name": "Rock_Basalt"
    },
    {
      "x": -2,
      "y": 13,
      "z": 2,
      "name": "Rock_Basalt"
    },
    {
      "x": -2,
      "y": 14,
      "z": 2,
      "name": "Rock_Basalt"
    },
    {
      "x": -2,
      "y": 15,
      "z": 2,
      "name": "Rock_Basalt"
    },
    {
      "x": -2,
      "y": 16,
      "z": 2,
      "name": "Rock_Shale"
    },
    {
      "x": -2,
      "y": 17,
      "z": 2,
      "name": "Rock_Shale"
    },
    {
      "x": -2,
      "y": 18,
      "z": 2,
      "name": "Rock_Shale"
    },
    {
      "x": -2,
      "y": 19,
      "z": 2,
      "name": "Rock_Shale"
    },
    {
      "x": -2,
      "y": 20,
      "z": 2,
      "name": "Rock_Shale"
    },
    {
      "x": -2,
      "y": 21,
      "z": 2,
      "name": "Rock_Shale"
    },
    {
      "x": -2,
      "y": 22,
      "z": 2,
      "name": "Rock_Shale"
    },
    {
      "x": -2,
      "y": 23,
      "z": 2,
      "name": "Rock_Shale"
    },
    {
      "x": -2,
      "y": 24,
      "z": 2,
      "name": "Rock_Shale"
    },
    {
      "x": -2,
      "y": 25,
      "z": 2,
      "name": "Rock_Shale"
    },
    {
      "x": -2,
      "y": 26,
      "z": 2,
      "name": "Rock_Shale"
    },
    {
      "x": -2,
      "y": 27,
      "z": 2,
      "name": "Rock_Shale"
    },
    {
      "x": -2,
      "y": 28,
      "z": 2,
      "name": "Soil_Dirt_Cold"
    },
    {
      "x": -2,
      "y": 29,
      "z": 2,
      "name": "Soil_Dirt_Cold"
    },
    {
      "x": -2,
      "y": 30,
      "z": 2,
      "name": "Soil_Grass_Cold"
    },
    {
      "x": -2,
      "y": 10,
      "z": 3,
      "name": "Rock_Basalt"
    },
    {
      "x": -2,
      "y": 11,
      "z": 3,
      "name": "Rock_Basalt"
    },
    {
      "x": -2,
      "y": 12,
      "z": 3,
      "name": "Rock_Basalt"
    },
    {
      "x": -2,
      "y": 13,
      "z": 3,
      "name": "Rock_Basalt"
    },
    {
      "x": -2,
      "y": 14,
      "z": 3,
      "name": "Rock_Basalt"
    },
    {
      "x": -2,
      "y": 15,
      "z": 3,
      "name": "Rock_Basalt"
    },
    {
      "x": -2,
      "y": 16,
      "z": 3,
      "name": "Rock_Shale"
    },
    {
      "x": -2,
      "y": 17,
      "z": 3,
      "name": "Rock_Shale"
    },
    {
      "x": -2,
      "y": 18,
      "z": 3,
      "name": "Rock_Shale"
    },
    {
      "x": -2,
      "y": 19,
      "z": 3,
      "name": "Rock_Shale"
    },
    {
      "x": -2,
      "y": 20,
      "z": 3,
      "name": "Rock_Shale"
    },
    {
      "x": -2,
      "y": 21,
      "z": 3,
      "name": "Rock_Shale"
    },
    {
      "x": -2,
      "y": 22,
      "z": 3,
      "name": "Rock_Shale"
    },
    {
      "x": -2,
      "y": 23,
      "z": 3,
      "name": "Rock_Shale"
    },
    {
      "x": -2,
      "y": 24,
      "z": 3,
      "name": "Rock_Shale"
    },
    {
      "x": -2,
      "y": 25,
      "z": 3,
      "name": "Rock_Shale"
    },
    {
      "x": -2,
      "y": 26,
      "z": 3,
      "name": "Rock_Shale"
    },
    {
      "x": -2,
      "y": 27,
      "z": 3,
      "name": "Rock_Shale"
    },
    {
      "x": -2,
      "y": 28,
      "z": 3,
      "name": "Soil_Dirt_Cold"
    },
    {
      "x": -2,
      "y": 29,
      "z": 3,
      "name": "Soil_Dirt_Cold"
    },
    {
      "x": -2,
      "y": 30,
      "z": 3,
      "name": "Soil_Grass_Cold"
    },
    {
      "x": -2,
      "y": 11,
      "z": 4,
      "name": "Rock_Basalt"
    },
    {
      "x": -2,
      "y": 12,
      "z": 4,
      "name": "Rock_Basalt"
    },
    {
      "x": -2,
      "y": 13,
      "z": 4,
      "name": "Rock_Basalt"
    },
    {
      "x": -2,
      "y": 14,
      "z": 4,
      "name": "Rock_Basalt"
    },
    {
      "x": -2,
      "y": 15,
      "z": 4,
      "name": "Rock_Basalt"
    },
    {
      "x": -2,
      "y": 16,
      "z": 4,
      "name": "Rock_Shale"
    },
    {
      "x": -2,
      "y": 17,
      "z": 4,
      "name": "Rock_Shale"
    },
    {
      "x": -2,
      "y": 18,
      "z": 4,
      "name": "Rock_Shale"
    },
    {
      "x": -2,
      "y": 19,
      "z": 4,
      "name": "Rock_Shale"
    },
    {
      "x": -2,
      "y": 20,
      "z": 4,
      "name": "Rock_Shale"
    },
    {
      "x": -2,
      "y": 21,
      "z": 4,
      "name": "Rock_Shale"
    },
    {
      "x": -2,
      "y": 22,
      "z": 4,
      "name": "Rock_Shale"
    },
    {
      "x": -2,
      "y": 23,
      "z": 4,
      "name": "Rock_Shale"
    },
    {
      "x": -2,
      "y": 24,
      "z": 4,
      "name": "Rock_Shale"
    },
    {
      "x": -2,
      "y": 25,
      "z": 4,
      "name": "Rock_Shale"
    },
    {
      "x": -2,
      "y": 26,
      "z": 4,
      "name": "Rock_Shale"
    },
    {
      "x": -2,
      "y": 27,
      "z": 4,
      "name": "Rock_Shale"
    },
    {
      "x": -2,
      "y": 28,
      "z": 4,
      "name": "Rock_Shale"
    },
    {
      "x": -2,
      "y": 29,
      "z": 4,
      "name": "Soil_Dirt_Cold"
    },
    {
      "x": -2,
      "y": 30,
      "z": 4,
      "name": "Soil_Grass_Cold"
    },
    {
      "x": -2,
      "y": 31,
      "z": 4,
      "name": "Plant_Grass_Winter_Tall"
    },
    {
      "x": -2,
      "y": 32,
      "z": 4,
      "name": "Plant_Grass_Winter_Tall",
      "filler": 1024
    },
    {
      "x": -2,
      "y": 20,
      "z": 5,
      "name": "Rock_Shale"
    },
    {
      "x": -2,
      "y": 21,
      "z": 5,
      "name": "Rock_Shale"
    },
    {
      "x": -2,
      "y": 22,
      "z": 5,
      "name": "Rock_Shale"
    },
    {
      "x": -2,
      "y": 23,
      "z": 5,
      "name": "Soil_Dirt_Cold"
    },
    {
      "x": -2,
      "y": 24,
      "z": 5,
      "name": "Soil_Dirt_Cold"
    },
    {
      "x": -2,
      "y": 25,
      "z": 5,
      "name": "Soil_Dirt_Cold"
    },
    {
      "x": -2,
      "y": 26,
      "z": 5,
      "name": "Soil_Grass_Cold"
    },
    {
      "x": -1,
      "y": 18,
      "z": -3,
      "name": "Rock_Basalt"
    },
    {
      "x": -1,
      "y": 19,
      "z": -3,
      "name": "Soil_Dirt"
    },
    {
      "x": -1,
      "y": 20,
      "z": -3,
      "name": "Soil_Dirt"
    },
    {
      "x": -1,
      "y": 21,
      "z": -3,
      "name": "Soil_Grass"
    },
    {
      "x": -1,
      "y": 9,
      "z": -2,
      "name": "Rock_Basalt"
    },
    {
      "x": -1,
      "y": 10,
      "z": -2,
      "name": "Rock_Basalt"
    },
    {
      "x": -1,
      "y": 11,
      "z": -2,
      "name": "Rock_Basalt"
    },
    {
      "x": -1,
      "y": 12,
      "z": -2,
      "name": "Rock_Basalt"
    },
    {
      "x": -1,
      "y": 13,
      "z": -2,
      "name": "Rock_Basalt"
    },
    {
      "x": -1,
      "y": 14,
      "z": -2,
      "name": "Rock_Basalt"
    },
    {
      "x": -1,
      "y": 15,
      "z": -2,
      "name": "Rock_Basalt"
    },
    {
      "x": -1,
      "y": 16,
      "z": -2,
      "name": "Rock_Basalt"
    },
    {
      "x": -1,
      "y": 17,
      "z": -2,
      "name": "Rock_Basalt"
    },
    {
      "x": -1,
      "y": 18,
      "z": -2,
      "name": "Rock_Basalt"
    },
    {
      "x": -1,
      "y": 19,
      "z": -2,
      "name": "Soil_Dirt"
    },
    {
      "x": -1,
      "y": 20,
      "z": -2,
      "name": "Soil_Dirt"
    },
    {
      "x": -1,
      "y": 21,
      "z": -2,
      "name": "Soil_Dirt"
    },
    {
      "x": -1,
      "y": 22,
      "z": -2,
      "name": "Soil_Grass"
    },
    {
      "x": -1,
      "y": 26,
      "z": -2,
      "name": "Soil_Dirt_Cold"
    },
    {
      "x": -1,
      "y": 27,
      "z": -2,
      "name": "Soil_Grass_Cold"
    },
    {
      "x": -1,
      "y": 7,
      "z": -1,
      "name": "Rock_Basalt"
    },
    {
      "x": -1,
      "y": 8,
      "z": -1,
      "name": "Rock_Basalt"
    },
    {
      "x": -1,
      "y": 9,
      "z": -1,
      "name": "Rock_Basalt"
    },
    {
      "x": -1,
      "y": 10,
      "z": -1,
      "name": "Rock_Basalt"
    },
    {
      "x": -1,
      "y": 11,
      "z": -1,
      "name": "Rock_Basalt"
    },
    {
      "x": -1,
      "y": 12,
      "z": -1,
      "name": "Rock_Basalt"
    },
    {
      "x": -1,
      "y": 13,
      "z": -1,
      "name": "Rock_Basalt"
    },
    {
      "x": -1,
      "y": 14,
      "z": -1,
      "name": "Rock_Basalt"
    },
    {
      "x": -1,
      "y": 15,
      "z": -1,
      "name": "Rock_Basalt"
    },
    {
      "x": -1,
      "y": 16,
      "z": -1,
      "name": "Rock_Basalt"
    },
    {
      "x": -1,
      "y": 17,
      "z": -1,
      "name": "Rock_Basalt"
    },
    {
      "x": -1,
      "y": 18,
      "z": -1,
      "name": "Rock_Basalt"
    },
    {
      "x": -1,
      "y": 19,
      "z": -1,
      "name": "Rock_Basalt"
    },
    {
      "x": -1,
      "y": 20,
      "z": -1,
      "name": "Soil_Dirt"
    },
    {
      "x": -1,
      "y": 21,
      "z": -1,
      "name": "Soil_Dirt"
    },
    {
      "x": -1,
      "y": 22,
      "z": -1,
      "name": "Rock_Shale"
    },
    {
      "x": -1,
      "y": 23,
      "z": -1,
      "name": "Rock_Shale"
    },
    {
      "x": -1,
      "y": 24,
      "z": -1,
      "name": "Rock_Shale"
    },
    {
      "x": -1,
      "y": 25,
      "z": -1,
      "name": "Rock_Shale"
    },
    {
      "x": -1,
      "y": 26,
      "z": -1,
      "name": "Soil_Dirt_Cold"
    },
    {
      "x": -1,
      "y": 27,
      "z": -1,
      "name": "Soil_Dirt_Cold"
    },
    {
      "x": -1,
      "y": 28,
      "z": -1,
      "name": "Soil_Grass_Cold"
    },
    {
      "x": -1,
      "y": 7,
      "z": 0,
      "name": "Rock_Basalt"
    },
    {
      "x": -1,
      "y": 8,
      "z": 0,
      "name": "Rock_Basalt"
    },
    {
      "x": -1,
      "y": 9,
      "z": 0,
      "name": "Rock_Basalt"
    },
    {
      "x": -1,
      "y": 10,
      "z": 0,
      "name": "Rock_Basalt"
    },
    {
      "x": -1,
      "y": 11,
      "z": 0,
      "name": "Rock_Basalt"
    },
    {
      "x": -1,
      "y": 12,
      "z": 0,
      "name": "Rock_Basalt"
    },
    {
      "x": -1,
      "y": 13,
      "z": 0,
      "name": "Rock_Basalt"
    },
    {
      "x": -1,
      "y": 14,
      "z": 0,
      "name": "Rock_Basalt"
    },
    {
      "x": -1,
      "y": 15,
      "z": 0,
      "name": "Rock_Basalt"
    },
    {
      "x": -1,
      "y": 16,
      "z": 0,
      "name": "Rock_Basalt"
    },
    {
      "x": -1,
      "y": 17,
      "z": 0,
      "name": "Rock_Basalt"
    },
    {
      "x": -1,
      "y": 18,
      "z": 0,
      "name": "Rock_Basalt"
    },
    {
      "x": -1,
      "y": 19,
      "z": 0,
      "name": "Rock_Basalt"
    },
    {
      "x": -1,
      "y": 20,
      "z": 0,
      "name": "Rock_Shale"
    },
    {
      "x": -1,
      "y": 21,
      "z": 0,
      "name": "Rock_Shale"
    },
    {
      "x": -1,
      "y": 22,
      "z": 0,
      "name": "Rock_Shale"
    },
    {
      "x": -1,
      "y": 23,
      "z": 0,
      "name": "Rock_Shale"
    },
    {
      "x": -1,
      "y": 24,
      "z": 0,
      "name": "Rock_Shale"
    },
    {
      "x": -1,
      "y": 25,
      "z": 0,
      "name": "Rock_Shale"
    },
    {
      "x": -1,
      "y": 26,
      "z": 0,
      "name": "Soil_Dirt_Cold"
    },
    {
      "x": -1,
      "y": 27,
      "z": 0,
      "name": "Rock_Shale"
    },
    {
      "x": -1,
      "y": 28,
      "z": 0,
      "name": "Soil_Dirt_Cold"
    },
    {
      "x": -1,
      "y": 29,
      "z": 0,
      "name": "Soil_Dirt_Cold"
    },
    {
      "x": -1,
      "y": 30,
      "z": 0,
      "name": "Soil_Grass_Cold"
    },
    {
      "x": -1,
      "y": 31,
      "z": 0,
      "name": "Plant_Grass_Cave_Short"
    },
    {
      "x": -1,
      "y": 7,
      "z": 1,
      "name": "Rock_Basalt"
    },
    {
      "x": -1,
      "y": 8,
      "z": 1,
      "name": "Rock_Basalt"
    },
    {
      "x": -1,
      "y": 9,
      "z": 1,
      "name": "Rock_Basalt"
    },
    {
      "x": -1,
      "y": 10,
      "z": 1,
      "name": "Rock_Basalt"
    },
    {
      "x": -1,
      "y": 11,
      "z": 1,
      "name": "Rock_Basalt"
    },
    {
      "x": -1,
      "y": 12,
      "z": 1,
      "name": "Rock_Basalt"
    },
    {
      "x": -1,
      "y": 13,
      "z": 1,
      "name": "Rock_Basalt"
    },
    {
      "x": -1,
      "y": 14,
      "z": 1,
      "name": "Rock_Basalt"
    },
    {
      "x": -1,
      "y": 15,
      "z": 1,
      "name": "Rock_Basalt"
    },
    {
      "x": -1,
      "y": 16,
      "z": 1,
      "name": "Rock_Basalt"
    },
    {
      "x": -1,
      "y": 17,
      "z": 1,
      "name": "Rock_Shale"
    },
    {
      "x": -1,
      "y": 18,
      "z": 1,
      "name": "Rock_Shale"
    },
    {
      "x": -1,
      "y": 19,
      "z": 1,
      "name": "Rock_Shale"
    },
    {
      "x": -1,
      "y": 20,
      "z": 1,
      "name": "Rock_Shale"
    },
    {
      "x": -1,
      "y": 21,
      "z": 1,
      "name": "Rock_Shale"
    },
    {
      "x": -1,
      "y": 22,
      "z": 1,
      "name": "Rock_Shale"
    },
    {
      "x": -1,
      "y": 23,
      "z": 1,
      "name": "Rock_Shale"
    },
    {
      "x": -1,
      "y": 24,
      "z": 1,
      "name": "Rock_Shale"
    },
    {
      "x": -1,
      "y": 25,
      "z": 1,
      "name": "Rock_Shale"
    },
    {
      "x": -1,
      "y": 26,
      "z": 1,
      "name": "Rock_Shale"
    },
    {
      "x": -1,
      "y": 27,
      "z": 1,
      "name": "Rock_Shale"
    },
    {
      "x": -1,
      "y": 28,
      "z": 1,
      "name": "Soil_Dirt_Cold"
    },
    {
      "x": -1,
      "y": 29,
      "z": 1,
      "name": "Soil_Dirt_Cold"
    },
    {
      "x": -1,
      "y": 30,
      "z": 1,
      "name": "Soil_Grass_Cold"
    },
    {
      "x": -1,
      "y": 31,
      "z": 1,
      "name": "Plant_Grass_Winter"
    },
    {
      "x": -1,
      "y": 7,
      "z": 2,
      "name": "Rock_Basalt"
    },
    {
      "x": -1,
      "y": 8,
      "z": 2,
      "name": "Rock_Basalt"
    },
    {
      "x": -1,
      "y": 9,
      "z": 2,
      "name": "Rock_Basalt"
    },
    {
      "x": -1,
      "y": 10,
      "z": 2,
      "name": "Rock_Basalt"
    },
    {
      "x": -1,
      "y": 11,
      "z": 2,
      "name": "Rock_Basalt"
    },
    {
      "x": -1,
      "y": 12,
      "z": 2,
      "name": "Rock_Basalt"
    },
    {
      "x": -1,
      "y": 13,
      "z": 2,
      "name": "Rock_Basalt"
    },
    {
      "x": -1,
      "y": 14,
      "z": 2,
      "name": "Rock_Basalt"
    },
    {
      "x": -1,
      "y": 15,
      "z": 2,
      "name": "Rock_Basalt"
    },
    {
      "x": -1,
      "y": 16,
      "z": 2,
      "name": "Rock_Basalt"
    },
    {
      "x": -1,
      "y": 17,
      "z": 2,
      "name": "Rock_Shale"
    },
    {
      "x": -1,
      "y": 18,
      "z": 2,
      "name": "Rock_Shale"
    },
    {
      "x": -1,
      "y": 19,
      "z": 2,
      "name": "Rock_Shale"
    },
    {
      "x": -1,
      "y": 20,
      "z": 2,
      "name": "Rock_Shale"
    },
    {
      "x": -1,
      "y": 21,
      "z": 2,
      "name": "Rock_Shale"
    },
    {
      "x": -1,
      "y": 22,
      "z": 2,
      "name": "Rock_Shale"
    },
    {
      "x": -1,
      "y": 23,
      "z": 2,
      "name": "Rock_Shale"
    },
    {
      "x": -1,
      "y": 24,
      "z": 2,
      "name": "Rock_Shale"
    },
    {
      "x": -1,
      "y": 25,
      "z": 2,
      "name": "Rock_Shale"
    },
    {
      "x": -1,
      "y": 26,
      "z": 2,
      "name": "Rock_Shale"
    },
    {
      "x": -1,
      "y": 27,
      "z": 2,
      "name": "Rock_Shale"
    },
    {
      "x": -1,
      "y": 28,
      "z": 2,
      "name": "Soil_Dirt_Cold"
    },
    {
      "x": -1,
      "y": 29,
      "z": 2,
      "name": "Soil_Dirt_Cold"
    },
    {
      "x": -1,
      "y": 30,
      "z": 2,
      "name": "Soil_Grass_Cold"
    },
    {
      "x": -1,
      "y": 31,
      "z": 2,
      "name": "Plant_Grass_Winter"
    },
    {
      "x": -1,
      "y": 7,
      "z": 3,
      "name": "Rock_Basalt"
    },
    {
      "x": -1,
      "y": 8,
      "z": 3,
      "name": "Rock_Basalt"
    },
    {
      "x": -1,
      "y": 9,
      "z": 3,
      "name": "Rock_Basalt"
    },
    {
      "x": -1,
      "y": 10,
      "z": 3,
      "name": "Rock_Basalt"
    },
    {
      "x": -1,
      "y": 11,
      "z": 3,
      "name": "Rock_Basalt"
    },
    {
      "x": -1,
      "y": 12,
      "z": 3,
      "name": "Rock_Basalt"
    },
    {
      "x": -1,
      "y": 13,
      "z": 3,
      "name": "Rock_Basalt"
    },
    {
      "x": -1,
      "y": 14,
      "z": 3,
      "name": "Rock_Basalt"
    },
    {
      "x": -1,
      "y": 15,
      "z": 3,
      "name": "Rock_Basalt"
    },
    {
      "x": -1,
      "y": 16,
      "z": 3,
      "name": "Rock_Shale"
    },
    {
      "x": -1,
      "y": 17,
      "z": 3,
      "name": "Rock_Shale"
    },
    {
      "x": -1,
      "y": 18,
      "z": 3,
      "name": "Rock_Shale"
    },
    {
      "x": -1,
      "y": 19,
      "z": 3,
      "name": "Rock_Shale"
    },
    {
      "x": -1,
      "y": 20,
      "z": 3,
      "name": "Rock_Shale"
    },
    {
      "x": -1,
      "y": 21,
      "z": 3,
      "name": "Rock_Shale"
    },
    {
      "x": -1,
      "y": 22,
      "z": 3,
      "name": "Rock_Shale"
    },
    {
      "x": -1,
      "y": 23,
      "z": 3,
      "name": "Rock_Shale"
    },
    {
      "x": -1,
      "y": 24,
      "z": 3,
      "name": "Rock_Shale"
    },
    {
      "x": -1,
      "y": 25,
      "z": 3,
      "name": "Rock_Shale"
    },
    {
      "x": -1,
      "y": 26,
      "z": 3,
      "name": "Rock_Shale"
    },
    {
      "x": -1,
      "y": 27,
      "z": 3,
      "name": "Rock_Shale"
    },
    {
      "x": -1,
      "y": 28,
      "z": 3,
      "name": "Soil_Dirt_Cold"
    },
    {
      "x": -1,
      "y": 29,
      "z": 3,
      "name": "Soil_Dirt_Cold"
    },
    {
      "x": -1,
      "y": 30,
      "z": 3,
      "name": "Soil_Grass_Cold"
    },
    {
      "x": -1,
      "y": 9,
      "z": 4,
      "name": "Rock_Basalt"
    },
    {
      "x": -1,
      "y": 10,
      "z": 4,
      "name": "Rock_Basalt"
    },
    {
      "x": -1,
      "y": 11,
      "z": 4,
      "name": "Rock_Basalt"
    },
    {
      "x": -1,
      "y": 12,
      "z": 4,
      "name": "Rock_Basalt"
    },
    {
      "x": -1,
      "y": 13,
      "z": 4,
      "name": "Rock_Basalt"
    },
    {
      "x": -1,
      "y": 14,
      "z": 4,
      "name": "Rock_Basalt"
    },
    {
      "x": -1,
      "y": 15,
      "z": 4,
      "name": "Rock_Basalt"
    },
    {
      "x": -1,
      "y": 16,
      "z": 4,
      "name": "Rock_Shale"
    },
    {
      "x": -1,
      "y": 17,
      "z": 4,
      "name": "Rock_Shale"
    },
    {
      "x": -1,
      "y": 18,
      "z": 4,
      "name": "Rock_Shale"
    },
    {
      "x": -1,
      "y": 19,
      "z": 4,
      "name": "Rock_Shale"
    },
    {
      "x": -1,
      "y": 20,
      "z": 4,
      "name": "Rock_Shale"
    },
    {
      "x": -1,
      "y": 21,
      "z": 4,
      "name": "Rock_Shale"
    },
    {
      "x": -1,
      "y": 22,
      "z": 4,
      "name": "Rock_Shale"
    },
    {
      "x": -1,
      "y": 23,
      "z": 4,
      "name": "Rock_Shale"
    },
    {
      "x": -1,
      "y": 24,
      "z": 4,
      "name": "Rock_Shale"
    },
    {
      "x": -1,
      "y": 25,
      "z": 4,
      "name": "Rock_Shale"
    },
    {
      "x": -1,
      "y": 26,
      "z": 4,
      "name": "Rock_Shale"
    },
    {
      "x": -1,
      "y": 27,
      "z": 4,
      "name": "Rock_Shale"
    },
    {
      "x": -1,
      "y": 28,
      "z": 4,
      "name": "Rock_Shale"
    },
    {
      "x": -1,
      "y": 29,
      "z": 4,
      "name": "Soil_Dirt_Cold"
    },
    {
      "x": -1,
      "y": 30,
      "z": 4,
      "name": "Soil_Grass_Cold"
    },
    {
      "x": -1,
      "y": 31,
      "z": 4,
      "name": "Plant_Grass_Winter"
    },
    {
      "x": -1,
      "y": 16,
      "z": 5,
      "name": "Rock_Shale"
    },
    {
      "x": -1,
      "y": 17,
      "z": 5,
      "name": "Rock_Shale"
    },
    {
      "x": -1,
      "y": 18,
      "z": 5,
      "name": "Rock_Shale"
    },
    {
      "x": -1,
      "y": 19,
      "z": 5,
      "name": "Rock_Shale"
    },
    {
      "x": -1,
      "y": 20,
      "z": 5,
      "name": "Rock_Shale"
    },
    {
      "x": -1,
      "y": 21,
      "z": 5,
      "name": "Rock_Shale"
    },
    {
      "x": -1,
      "y": 22,
      "z": 5,
      "name": "Rock_Shale"
    },
    {
      "x": -1,
      "y": 23,
      "z": 5,
      "name": "Soil_Dirt_Cold"
    },
    {
      "x": -1,
      "y": 24,
      "z": 5,
      "name": "Soil_Dirt_Cold"
    },
    {
      "x": -1,
      "y": 25,
      "z": 5,
      "name": "Soil_Dirt_Cold"
    },
    {
      "x": -1,
      "y": 26,
      "z": 5,
      "name": "Soil_Grass_Cold"
    },
    {
      "x": -1,
      "y": 27,
      "z": 5,
      "name": "Plant_Grass_Winter_Tall"
    },
    {
      "x": -1,
      "y": 28,
      "z": 5,
      "name": "Plant_Grass_Winter_Tall",
      "filler": 1024
    },
    {
      "x": 0,
      "y": 13,
      "z": -3,
      "name": "Rock_Basalt"
    },
    {
      "x": 0,
      "y": 14,
      "z": -3,
      "name": "Rock_Basalt"
    },
    {
      "x": 0,
      "y": 15,
      "z": -3,
      "name": "Rock_Basalt"
    },
    {
      "x": 0,
      "y": 16,
      "z": -3,
      "name": "Rock_Basalt"
    },
    {
      "x": 0,
      "y": 17,
      "z": -3,
      "name": "Rock_Basalt"
    },
    {
      "x": 0,
      "y": 18,
      "z": -3,
      "name": "Rock_Basalt"
    },
    {
      "x": 0,
      "y": 19,
      "z": -3,
      "name": "Soil_Dirt"
    },
    {
      "x": 0,
      "y": 20,
      "z": -3,
      "name": "Soil_Dirt"
    },
    {
      "x": 0,
      "y": 21,
      "z": -3,
      "name": "Soil_Grass"
    },
    {
      "x": 0,
      "y": 22,
      "z": -3,
      "name": "Plant_Grass_Lush_Short"
    },
    {
      "x": 0,
      "y": 8,
      "z": -2,
      "name": "Rock_Basalt"
    },
    {
      "x": 0,
      "y": 9,
      "z": -2,
      "name": "Rock_Basalt"
    },
    {
      "x": 0,
      "y": 10,
      "z": -2,
      "name": "Rock_Basalt"
    },
    {
      "x": 0,
      "y": 11,
      "z": -2,
      "name": "Rock_Basalt"
    },
    {
      "x": 0,
      "y": 12,
      "z": -2,
      "name": "Rock_Basalt"
    },
    {
      "x": 0,
      "y": 13,
      "z": -2,
      "name": "Rock_Basalt"
    },
    {
      "x": 0,
      "y": 14,
      "z": -2,
      "name": "Rock_Basalt"
    },
    {
      "x": 0,
      "y": 15,
      "z": -2,
      "name": "Rock_Basalt"
    },
    {
      "x": 0,
      "y": 16,
      "z": -2,
      "name": "Rock_Basalt"
    },
    {
      "x": 0,
      "y": 17,
      "z": -2,
      "name": "Rock_Basalt"
    },
    {
      "x": 0,
      "y": 18,
      "z": -2,
      "name": "Rock_Basalt"
    },
    {
      "x": 0,
      "y": 19,
      "z": -2,
      "name": "Soil_Dirt"
    },
    {
      "x": 0,
      "y": 20,
      "z": -2,
      "name": "Soil_Dirt"
    },
    {
      "x": 0,
      "y": 21,
      "z": -2,
      "name": "Soil_Grass"
    },
    {
      "x": 0,
      "y": 22,
      "z": -2,
      "name": "Plant_Grass_Sharp"
    },
    {
      "x": 0,
      "y": 24,
      "z": -2,
      "name": "Rock_Shale"
    },
    {
      "x": 0,
      "y": 25,
      "z": -2,
      "name": "Rock_Shale"
    },
    {
      "x": 0,
      "y": 26,
      "z": -2,
      "name": "Soil_Dirt_Cold"
    },
    {
      "x": 0,
      "y": 27,
      "z": -2,
      "name": "Soil_Dirt_Cold"
    },
    {
      "x": 0,
      "y": 28,
      "z": -2,
      "name": "Soil_Grass_Cold"
    },
    {
      "x": 0,
      "y": 29,
      "z": -2,
      "name": "Plant_Grass_Winter"
    },
    {
      "x": 0,
      "y": 7,
      "z": -1,
      "name": "Rock_Basalt"
    },
    {
      "x": 0,
      "y": 8,
      "z": -1,
      "name": "Rock_Basalt"
    },
    {
      "x": 0,
      "y": 9,
      "z": -1,
      "name": "Rock_Basalt"
    },
    {
      "x": 0,
      "y": 10,
      "z": -1,
      "name": "Rock_Basalt"
    },
    {
      "x": 0,
      "y": 11,
      "z": -1,
      "name": "Rock_Basalt"
    },
    {
      "x": 0,
      "y": 12,
      "z": -1,
      "name": "Rock_Basalt"
    },
    {
      "x": 0,
      "y": 13,
      "z": -1,
      "name": "Rock_Basalt"
    },
    {
      "x": 0,
      "y": 14,
      "z": -1,
      "name": "Rock_Basalt"
    },
    {
      "x": 0,
      "y": 15,
      "z": -1,
      "name": "Rock_Basalt"
    },
    {
      "x": 0,
      "y": 16,
      "z": -1,
      "name": "Rock_Basalt"
    },
    {
      "x": 0,
      "y": 17,
      "z": -1,
      "name": "Rock_Basalt"
    },
    {
      "x": 0,
      "y": 18,
      "z": -1,
      "name": "Rock_Basalt"
    },
    {
      "x": 0,
      "y": 19,
      "z": -1,
      "name": "Rock_Basalt"
    },
    {
      "x": 0,
      "y": 20,
      "z": -1,
      "name": "Soil_Dirt"
    },
    {
      "x": 0,
      "y": 21,
      "z": -1,
      "name": "Soil_Dirt"
    },
    {
      "x": 0,
      "y": 22,
      "z": -1,
      "name": "Rock_Shale"
    },
    {
      "x": 0,
      "y": 23,
      "z": -1,
      "name": "Rock_Shale"
    },
    {
      "x": 0,
      "y": 24,
      "z": -1,
      "name": "Rock_Shale"
    },
    {
      "x": 0,
      "y": 25,
      "z": -1,
      "name": "Rock_Shale"
    },
    {
      "x": 0,
      "y": 26,
      "z": -1,
      "name": "Soil_Dirt_Cold"
    },
    {
      "x": 0,
      "y": 27,
      "z": -1,
      "name": "Soil_Dirt_Cold"
    },
    {
      "x": 0,
      "y": 28,
      "z": -1,
      "name": "Soil_Grass_Cold"
    },
    {
      "x": 0,
      "y": 29,
      "z": -1,
      "name": "Plant_Grass_Winter_Tall"
    },
    {
      "x": 0,
      "y": 30,
      "z": -1,
      "name": "Plant_Grass_Winter_Tall",
      "filler": 1024
    },
    {
      "x": 0,
      "y": 6,
      "z": 0,
      "name": "Rock_Basalt"
    },
    {
      "x": 0,
      "y": 7,
      "z": 0,
      "name": "Rock_Basalt"
    },
    {
      "x": 0,
      "y": 8,
      "z": 0,
      "name": "Rock_Basalt"
    },
    {
      "x": 0,
      "y": 9,
      "z": 0,
      "name": "Rock_Basalt"
    },
    {
      "x": 0,
      "y": 10,
      "z": 0,
      "name": "Rock_Basalt"
    },
    {
      "x": 0,
      "y": 11,
      "z": 0,
      "name": "Rock_Basalt"
    },
    {
      "x": 0,
      "y": 12,
      "z": 0,
      "name": "Rock_Basalt"
    },
    {
      "x": 0,
      "y": 13,
      "z": 0,
      "name": "Rock_Basalt"
    },
    {
      "x": 0,
      "y": 14,
      "z": 0,
      "name": "Rock_Basalt"
    },
    {
      "x": 0,
      "y": 15,
      "z": 0,
      "name": "Rock_Basalt"
    },
    {
      "x": 0,
      "y": 16,
      "z": 0,
      "name": "Rock_Basalt"
    },
    {
      "x": 0,
      "y": 17,
      "z": 0,
      "name": "Rock_Basalt"
    },
    {
      "x": 0,
      "y": 18,
      "z": 0,
      "name": "Rock_Basalt"
    },
    {
      "x": 0,
      "y": 19,
      "z": 0,
      "name": "Rock_Basalt"
    },
    {
      "x": 0,
      "y": 20,
      "z": 0,
      "name": "Rock_Basalt"
    },
    {
      "x": 0,
      "y": 21,
      "z": 0,
      "name": "Rock_Shale"
    },
    {
      "x": 0,
      "y": 22,
      "z": 0,
      "name": "Rock_Shale"
    },
    {
      "x": 0,
      "y": 23,
      "z": 0,
      "name": "Rock_Shale"
    },
    {
      "x": 0,
      "y": 24,
      "z": 0,
      "name": "Rock_Shale"
    },
    {
      "x": 0,
      "y": 25,
      "z": 0,
      "name": "Rock_Shale"
    },
    {
      "x": 0,
      "y": 26,
      "z": 0,
      "name": "Rock_Shale"
    },
    {
      "x": 0,
      "y": 27,
      "z": 0,
      "name": "Soil_Dirt_Cold"
    },
    {
      "x": 0,
      "y": 28,
      "z": 0,
      "name": "Soil_Dirt_Cold"
    },
    {
      "x": 0,
      "y": 29,
      "z": 0,
      "name": "Soil_Dirt_Cold"
    },
    {
      "x": 0,
      "y": 30,
      "z": 0,
      "name": "Soil_Grass_Cold"
    },
    {
      "x": 0,
      "y": 6,
      "z": 1,
      "name": "Rock_Basalt"
    },
    {
      "x": 0,
      "y": 7,
      "z": 1,
      "name": "Rock_Basalt"
    },
    {
      "x": 0,
      "y": 8,
      "z": 1,
      "name": "Rock_Basalt"
    },
    {
      "x": 0,
      "y": 9,
      "z": 1,
      "name": "Rock_Basalt"
    },
    {
      "x": 0,
      "y": 10,
      "z": 1,
      "name": "Rock_Basalt"
    },
    {
      "x": 0,
      "y": 11,
      "z": 1,
      "name": "Rock_Basalt"
    },
    {
      "x": 0,
      "y": 12,
      "z": 1,
      "name": "Rock_Basalt"
    },
    {
      "x": 0,
      "y": 13,
      "z": 1,
      "name": "Rock_Basalt"
    },
    {
      "x": 0,
      "y": 14,
      "z": 1,
      "name": "Rock_Basalt"
    },
    {
      "x": 0,
      "y": 15,
      "z": 1,
      "name": "Rock_Basalt"
    },
    {
      "x": 0,
      "y": 16,
      "z": 1,
      "name": "Rock_Basalt"
    },
    {
      "x": 0,
      "y": 17,
      "z": 1,
      "name": "Rock_Shale"
    },
    {
      "x": 0,
      "y": 18,
      "z": 1,
      "name": "Rock_Shale"
    },
    {
      "x": 0,
      "y": 19,
      "z": 1,
      "name": "Rock_Basalt"
    },
    {
      "x": 0,
      "y": 20,
      "z": 1,
      "name": "Rock_Shale"
    },
    {
      "x": 0,
      "y": 21,
      "z": 1,
      "name": "Rock_Shale"
    },
    {
      "x": 0,
      "y": 22,
      "z": 1,
      "name": "Rock_Shale"
    },
    {
      "x": 0,
      "y": 23,
      "z": 1,
      "name": "Rock_Shale"
    },
    {
      "x": 0,
      "y": 24,
      "z": 1,
      "name": "Rock_Shale"
    },
    {
      "x": 0,
      "y": 25,
      "z": 1,
      "name": "Rock_Shale"
    },
    {
      "x": 0,
      "y": 26,
      "z": 1,
      "name": "Rock_Shale"
    },
    {
      "x": 0,
      "y": 27,
      "z": 1,
      "name": "Rock_Shale"
    },
    {
      "x": 0,
      "y": 28,
      "z": 1,
      "name": "Rock_Shale"
    },
    {
      "x": 0,
      "y": 29,
      "z": 1,
      "name": "Soil_Dirt_Cold"
    },
    {
      "x": 0,
      "y": 30,
      "z": 1,
      "name": "Soil_Grass_Cold"
    },
    {
      "x": 0,
      "y": 31,
      "z": 1,
      "name": "Plant_Bush_Winter_Red"
    },
    {
      "x": 0,
      "y": 6,
      "z": 2,
      "name": "Rock_Basalt"
    },
    {
      "x": 0,
      "y": 7,
      "z": 2,
      "name": "Rock_Basalt"
    },
    {
      "x": 0,
      "y": 8,
      "z": 2,
      "name": "Rock_Basalt"
    },
    {
      "x": 0,
      "y": 9,
      "z": 2,
      "name": "Rock_Basalt"
    },
    {
      "x": 0,
      "y": 10,
      "z": 2,
      "name": "Rock_Basalt"
    },
    {
      "x": 0,
      "y": 11,
      "z": 2,
      "name": "Rock_Basalt"
    },
    {
      "x": 0,
      "y": 12,
      "z": 2,
      "name": "Rock_Basalt"
    },
    {
      "x": 0,
      "y": 13,
      "z": 2,
      "name": "Rock_Basalt"
    },
    {
      "x": 0,
      "y": 14,
      "z": 2,
      "name": "Rock_Basalt"
    },
    {
      "x": 0,
      "y": 15,
      "z": 2,
      "name": "Rock_Basalt"
    },
    {
      "x": 0,
      "y": 16,
      "z": 2,
      "name": "Rock_Basalt"
    },
    {
      "x": 0,
      "y": 17,
      "z": 2,
      "name": "Rock_Shale"
    },
    {
      "x": 0,
      "y": 18,
      "z": 2,
      "name": "Rock_Shale"
    },
    {
      "x": 0,
      "y": 19,
      "z": 2,
      "name": "Rock_Shale"
    },
    {
      "x": 0,
      "y": 20,
      "z": 2,
      "name": "Rock_Shale"
    },
    {
      "x": 0,
      "y": 21,
      "z": 2,
      "name": "Rock_Shale"
    },
    {
      "x": 0,
      "y": 22,
      "z": 2,
      "name": "Rock_Shale"
    },
    {
      "x": 0,
      "y": 23,
      "z": 2,
      "name": "Rock_Shale"
    },
    {
      "x": 0,
      "y": 24,
      "z": 2,
      "name": "Rock_Shale"
    },
    {
      "x": 0,
      "y": 25,
      "z": 2,
      "name": "Rock_Shale"
    },
    {
      "x": 0,
      "y": 26,
      "z": 2,
      "name": "Rock_Shale"
    },
    {
      "x": 0,
      "y": 27,
      "z": 2,
      "name": "Rock_Shale"
    },
    {
      "x": 0,
      "y": 28,
      "z": 2,
      "name": "Rock_Shale"
    },
    {
      "x": 0,
      "y": 29,
      "z": 2,
      "name": "Soil_Dirt_Cold"
    },
    {
      "x": 0,
      "y": 30,
      "z": 2,
      "name": "Soil_Grass_Cold"
    },
    {
      "x": 0,
      "y": 31,
      "z": 2,
      "name": "Plant_Grass_Winter_Tall"
    },
    {
      "x": 0,
      "y": 32,
      "z": 2,
      "name": "Plant_Grass_Winter_Tall",
      "filler": 1024
    },
    {
      "x": 0,
      "y": 7,
      "z": 3,
      "name": "Rock_Basalt"
    },
    {
      "x": 0,
      "y": 8,
      "z": 3,
      "name": "Rock_Basalt"
    },
    {
      "x": 0,
      "y": 9,
      "z": 3,
      "name": "Rock_Basalt"
    },
    {
      "x": 0,
      "y": 10,
      "z": 3,
      "name": "Rock_Basalt"
    },
    {
      "x": 0,
      "y": 11,
      "z": 3,
      "name": "Rock_Basalt"
    },
    {
      "x": 0,
      "y": 12,
      "z": 3,
      "name": "Rock_Basalt"
    },
    {
      "x": 0,
      "y": 13,
      "z": 3,
      "name": "Rock_Basalt"
    },
    {
      "x": 0,
      "y": 14,
      "z": 3,
      "name": "Rock_Basalt"
    },
    {
      "x": 0,
      "y": 15,
      "z": 3,
      "name": "Rock_Basalt"
    },
    {
      "x": 0,
      "y": 16,
      "z": 3,
      "name": "Rock_Basalt"
    },
    {
      "x": 0,
      "y": 17,
      "z": 3,
      "name": "Rock_Shale"
    },
    {
      "x": 0,
      "y": 18,
      "z": 3,
      "name": "Rock_Shale"
    },
    {
      "x": 0,
      "y": 19,
      "z": 3,
      "name": "Rock_Shale"
    },
    {
      "x": 0,
      "y": 20,
      "z": 3,
      "name": "Rock_Shale"
    },
    {
      "x": 0,
      "y": 21,
      "z": 3,
      "name": "Rock_Shale"
    },
    {
      "x": 0,
      "y": 22,
      "z": 3,
      "name": "Rock_Shale"
    },
    {
      "x": 0,
      "y": 23,
      "z": 3,
      "name": "Rock_Shale"
    },
    {
      "x": 0,
      "y": 24,
      "z": 3,
      "name": "Rock_Shale"
    },
    {
      "x": 0,
      "y": 25,
      "z": 3,
      "name": "Rock_Shale"
    },
    {
      "x": 0,
      "y": 26,
      "z": 3,
      "name": "Rock_Shale"
    },
    {
      "x": 0,
      "y": 27,
      "z": 3,
      "name": "Rock_Shale"
    },
    {
      "x": 0,
      "y": 28,
      "z": 3,
      "name": "Soil_Dirt_Cold"
    },
    {
      "x": 0,
      "y": 29,
      "z": 3,
      "name": "Soil_Dirt_Cold"
    },
    {
      "x": 0,
      "y": 30,
      "z": 3,
      "name": "Soil_Grass_Cold"
    },
    {
      "x": 0,
      "y": 31,
      "z": 3,
      "name": "Plant_Grass_Winter"
    },
    {
      "x": 0,
      "y": 8,
      "z": 4,
      "name": "Rock_Basalt"
    },
    {
      "x": 0,
      "y": 9,
      "z": 4,
      "name": "Rock_Basalt"
    },
    {
      "x": 0,
      "y": 10,
      "z": 4,
      "name": "Rock_Basalt"
    },
    {
      "x": 0,
      "y": 11,
      "z": 4,
      "name": "Rock_Basalt"
    },
    {
      "x": 0,
      "y": 12,
      "z": 4,
      "name": "Rock_Basalt"
    },
    {
      "x": 0,
      "y": 13,
      "z": 4,
      "name": "Rock_Basalt"
    },
    {
      "x": 0,
      "y": 14,
      "z": 4,
      "name": "Rock_Basalt"
    },
    {
      "x": 0,
      "y": 15,
      "z": 4,
      "name": "Rock_Basalt"
    },
    {
      "x": 0,
      "y": 16,
      "z": 4,
      "name": "Rock_Basalt"
    },
    {
      "x": 0,
      "y": 17,
      "z": 4,
      "name": "Rock_Shale"
    },
    {
      "x": 0,
      "y": 18,
      "z": 4,
      "name": "Rock_Shale"
    },
    {
      "x": 0,
      "y": 19,
      "z": 4,
      "name": "Rock_Shale"
    },
    {
      "x": 0,
      "y": 20,
      "z": 4,
      "name": "Rock_Shale"
    },
    {
      "x": 0,
      "y": 21,
      "z": 4,
      "name": "Rock_Shale"
    },
    {
      "x": 0,
      "y": 22,
      "z": 4,
      "name": "Rock_Shale"
    },
    {
      "x": 0,
      "y": 23,
      "z": 4,
      "name": "Rock_Shale"
    },
    {
      "x": 0,
      "y": 24,
      "z": 4,
      "name": "Rock_Shale"
    },
    {
      "x": 0,
      "y": 25,
      "z": 4,
      "name": "Rock_Shale"
    },
    {
      "x": 0,
      "y": 26,
      "z": 4,
      "name": "Rock_Shale"
    },
    {
      "x": 0,
      "y": 27,
      "z": 4,
      "name": "Rock_Shale"
    },
    {
      "x": 0,
      "y": 28,
      "z": 4,
      "name": "Soil_Dirt_Cold"
    },
    {
      "x": 0,
      "y": 29,
      "z": 4,
      "name": "Soil_Dirt_Cold"
    },
    {
      "x": 0,
      "y": 30,
      "z": 4,
      "name": "Soil_Grass_Cold"
    },
    {
      "x": 0,
      "y": 11,
      "z": 5,
      "name": "Rock_Basalt"
    },
    {
      "x": 0,
      "y": 12,
      "z": 5,
      "name": "Rock_Basalt"
    },
    {
      "x": 0,
      "y": 13,
      "z": 5,
      "name": "Rock_Basalt"
    },
    {
      "x": 0,
      "y": 14,
      "z": 5,
      "name": "Rock_Basalt"
    },
    {
      "x": 0,
      "y": 15,
      "z": 5,
      "name": "Rock_Basalt"
    },
    {
      "x": 0,
      "y": 16,
      "z": 5,
      "name": "Rock_Basalt"
    },
    {
      "x": 0,
      "y": 17,
      "z": 5,
      "name": "Rock_Shale"
    },
    {
      "x": 0,
      "y": 18,
      "z": 5,
      "name": "Rock_Shale"
    },
    {
      "x": 0,
      "y": 19,
      "z": 5,
      "name": "Rock_Shale"
    },
    {
      "x": 0,
      "y": 20,
      "z": 5,
      "name": "Soil_Dirt"
    },
    {
      "x": 0,
      "y": 21,
      "z": 5,
      "name": "Rock_Shale"
    },
    {
      "x": 0,
      "y": 22,
      "z": 5,
      "name": "Rock_Shale"
    },
    {
      "x": 0,
      "y": 23,
      "z": 5,
      "name": "Rock_Shale"
    },
    {
      "x": 0,
      "y": 24,
      "z": 5,
      "name": "Soil_Dirt_Cold"
    },
    {
      "x": 0,
      "y": 25,
      "z": 5,
      "name": "Soil_Dirt_Cold"
    },
    {
      "x": 0,
      "y": 26,
      "z": 5,
      "name": "Soil_Grass_Cold"
    },
    {
      "x": 0,
      "y": 27,
      "z": 5,
      "name": "Plant_Grass_Winter"
    },
    {
      "x": 0,
      "y": 19,
      "z": 6,
      "name": "Rock_Shale"
    },
    {
      "x": 0,
      "y": 20,
      "z": 6,
      "name": "Soil_Dirt"
    },
    {
      "x": 0,
      "y": 21,
      "z": 6,
      "name": "Soil_Grass"
    },
    {
      "x": 1,
      "y": 11,
      "z": -3,
      "name": "Rock_Basalt"
    },
    {
      "x": 1,
      "y": 12,
      "z": -3,
      "name": "Rock_Basalt"
    },
    {
      "x": 1,
      "y": 13,
      "z": -3,
      "name": "Rock_Basalt"
    },
    {
      "x": 1,
      "y": 14,
      "z": -3,
      "name": "Rock_Basalt"
    },
    {
      "x": 1,
      "y": 15,
      "z": -3,
      "name": "Rock_Basalt"
    },
    {
      "x": 1,
      "y": 16,
      "z": -3,
      "name": "Rock_Basalt"
    },
    {
      "x": 1,
      "y": 17,
      "z": -3,
      "name": "Rock_Basalt"
    },
    {
      "x": 1,
      "y": 18,
      "z": -3,
      "name": "Rock_Basalt"
    },
    {
      "x": 1,
      "y": 19,
      "z": -3,
      "name": "Rock_Basalt"
    },
    {
      "x": 1,
      "y": 20,
      "z": -3,
      "name": "Soil_Dirt"
    },
    {
      "x": 1,
      "y": 21,
      "z": -3,
      "name": "Soil_Grass"
    },
    {
      "x": 1,
      "y": 22,
      "z": -3,
      "name": "Plant_Grass_Sharp_Tall"
    },
    {
      "x": 1,
      "y": 23,
      "z": -3,
      "name": "Plant_Grass_Sharp_Tall",
      "filler": 1024
    },
    {
      "x": 1,
      "y": 8,
      "z": -2,
      "name": "Rock_Basalt"
    },
    {
      "x": 1,
      "y": 9,
      "z": -2,
      "name": "Rock_Basalt"
    },
    {
      "x": 1,
      "y": 10,
      "z": -2,
      "name": "Rock_Basalt"
    },
    {
      "x": 1,
      "y": 11,
      "z": -2,
      "name": "Rock_Basalt"
    },
    {
      "x": 1,
      "y": 12,
      "z": -2,
      "name": "Rock_Basalt"
    },
    {
      "x": 1,
      "y": 13,
      "z": -2,
      "name": "Rock_Basalt"
    },
    {
      "x": 1,
      "y": 14,
      "z": -2,
      "name": "Rock_Basalt"
    },
    {
      "x": 1,
      "y": 15,
      "z": -2,
      "name": "Rock_Basalt"
    },
    {
      "x": 1,
      "y": 16,
      "z": -2,
      "name": "Rock_Basalt"
    },
    {
      "x": 1,
      "y": 17,
      "z": -2,
      "name": "Rock_Basalt"
    },
    {
      "x": 1,
      "y": 18,
      "z": -2,
      "name": "Rock_Basalt"
    },
    {
      "x": 1,
      "y": 19,
      "z": -2,
      "name": "Rock_Basalt"
    },
    {
      "x": 1,
      "y": 20,
      "z": -2,
      "name": "Soil_Dirt"
    },
    {
      "x": 1,
      "y": 21,
      "z": -2,
      "name": "Soil_Grass"
    },
    {
      "x": 1,
      "y": 25,
      "z": -2,
      "name": "Rock_Shale"
    },
    {
      "x": 1,
      "y": 26,
      "z": -2,
      "name": "Soil_Dirt_Cold"
    },
    {
      "x": 1,
      "y": 27,
      "z": -2,
      "name": "Soil_Dirt_Cold"
    },
    {
      "x": 1,
      "y": 28,
      "z": -2,
      "name": "Soil_Grass_Cold"
    },
    {
      "x": 1,
      "y": 7,
      "z": -1,
      "name": "Rock_Basalt"
    },
    {
      "x": 1,
      "y": 8,
      "z": -1,
      "name": "Rock_Basalt"
    },
    {
      "x": 1,
      "y": 9,
      "z": -1,
      "name": "Rock_Basalt"
    },
    {
      "x": 1,
      "y": 10,
      "z": -1,
      "name": "Rock_Basalt"
    },
    {
      "x": 1,
      "y": 11,
      "z": -1,
      "name": "Rock_Basalt"
    },
    {
      "x": 1,
      "y": 12,
      "z": -1,
      "name": "Rock_Basalt"
    },
    {
      "x": 1,
      "y": 13,
      "z": -1,
      "name": "Rock_Basalt"
    },
    {
      "x": 1,
      "y": 14,
      "z": -1,
      "name": "Rock_Basalt"
    },
    {
      "x": 1,
      "y": 15,
      "z": -1,
      "name": "Rock_Basalt"
    },
    {
      "x": 1,
      "y": 16,
      "z": -1,
      "name": "Rock_Basalt"
    },
    {
      "x": 1,
      "y": 17,
      "z": -1,
      "name": "Rock_Basalt"
    },
    {
      "x": 1,
      "y": 18,
      "z": -1,
      "name": "Rock_Basalt"
    },
    {
      "x": 1,
      "y": 19,
      "z": -1,
      "name": "Rock_Basalt"
    },
    {
      "x": 1,
      "y": 20,
      "z": -1,
      "name": "Rock_Basalt"
    },
    {
      "x": 1,
      "y": 21,
      "z": -1,
      "name": "Soil_Dirt"
    },
    {
      "x": 1,
      "y": 22,
      "z": -1,
      "name": "Rock_Shale"
    },
    {
      "x": 1,
      "y": 23,
      "z": -1,
      "name": "Rock_Shale"
    },
    {
      "x": 1,
      "y": 24,
      "z": -1,
      "name": "Rock_Shale"
    },
    {
      "x": 1,
      "y": 25,
      "z": -1,
      "name": "Rock_Shale"
    },
    {
      "x": 1,
      "y": 26,
      "z": -1,
      "name": "Soil_Dirt_Cold"
    },
    {
      "x": 1,
      "y": 27,
      "z": -1,
      "name": "Soil_Dirt_Cold"
    },
    {
      "x": 1,
      "y": 28,
      "z": -1,
      "name": "Soil_Grass_Cold"
    },
    {
      "x": 1,
      "y": 29,
      "z": -1,
      "name": "Plant_Grass_Winter_Tall"
    },
    {
      "x": 1,
      "y": 30,
      "z": -1,
      "name": "Plant_Grass_Winter_Tall",
      "filler": 1024
    },
    {
      "x": 1,
      "y": 6,
      "z": 0,
      "name": "Rock_Basalt"
    },
    {
      "x": 1,
      "y": 7,
      "z": 0,
      "name": "Rock_Basalt"
    },
    {
      "x": 1,
      "y": 8,
      "z": 0,
      "name": "Rock_Basalt"
    },
    {
      "x": 1,
      "y": 9,
      "z": 0,
      "name": "Rock_Basalt"
    },
    {
      "x": 1,
      "y": 10,
      "z": 0,
      "name": "Rock_Basalt"
    },
    {
      "x": 1,
      "y": 11,
      "z": 0,
      "name": "Rock_Basalt"
    },
    {
      "x": 1,
      "y": 12,
      "z": 0,
      "name": "Rock_Basalt"
    },
    {
      "x": 1,
      "y": 13,
      "z": 0,
      "name": "Rock_Basalt"
    },
    {
      "x": 1,
      "y": 14,
      "z": 0,
      "name": "Rock_Basalt"
    },
    {
      "x": 1,
      "y": 15,
      "z": 0,
      "name": "Rock_Basalt"
    },
    {
      "x": 1,
      "y": 16,
      "z": 0,
      "name": "Rock_Basalt"
    },
    {
      "x": 1,
      "y": 17,
      "z": 0,
      "name": "Rock_Basalt"
    },
    {
      "x": 1,
      "y": 18,
      "z": 0,
      "name": "Rock_Basalt"
    },
    {
      "x": 1,
      "y": 19,
      "z": 0,
      "name": "Rock_Basalt"
    },
    {
      "x": 1,
      "y": 20,
      "z": 0,
      "name": "Rock_Basalt"
    },
    {
      "x": 1,
      "y": 21,
      "z": 0,
      "name": "Rock_Shale"
    },
    {
      "x": 1,
      "y": 22,
      "z": 0,
      "name": "Rock_Shale"
    },
    {
      "x": 1,
      "y": 23,
      "z": 0,
      "name": "Rock_Shale"
    },
    {
      "x": 1,
      "y": 24,
      "z": 0,
      "name": "Rock_Shale"
    },
    {
      "x": 1,
      "y": 25,
      "z": 0,
      "name": "Rock_Shale"
    },
    {
      "x": 1,
      "y": 26,
      "z": 0,
      "name": "Rock_Shale"
    },
    {
      "x": 1,
      "y": 27,
      "z": 0,
      "name": "Soil_Dirt_Cold"
    },
    {
      "x": 1,
      "y": 28,
      "z": 0,
      "name": "Soil_Grass_Cold"
    },
    {
      "x": 1,
      "y": 30,
      "z": 0,
      "name": "Soil_Grass_Cold"
    },
    {
      "x": 1,
      "y": 6,
      "z": 1,
      "name": "Rock_Basalt"
    },
    {
      "x": 1,
      "y": 7,
      "z": 1,
      "name": "Rock_Basalt"
    },
    {
      "x": 1,
      "y": 8,
      "z": 1,
      "name": "Rock_Basalt"
    },
    {
      "x": 1,
      "y": 9,
      "z": 1,
      "name": "Rock_Basalt"
    },
    {
      "x": 1,
      "y": 10,
      "z": 1,
      "name": "Rock_Basalt"
    },
    {
      "x": 1,
      "y": 11,
      "z": 1,
      "name": "Rock_Basalt"
    },
    {
      "x": 1,
      "y": 12,
      "z": 1,
      "name": "Rock_Basalt"
    },
    {
      "x": 1,
      "y": 13,
      "z": 1,
      "name": "Rock_Basalt"
    },
    {
      "x": 1,
      "y": 14,
      "z": 1,
      "name": "Rock_Basalt"
    },
    {
      "x": 1,
      "y": 15,
      "z": 1,
      "name": "Rock_Basalt"
    },
    {
      "x": 1,
      "y": 16,
      "z": 1,
      "name": "Rock_Basalt"
    },
    {
      "x": 1,
      "y": 17,
      "z": 1,
      "name": "Rock_Basalt"
    },
    {
      "x": 1,
      "y": 18,
      "z": 1,
      "name": "Rock_Basalt"
    },
    {
      "x": 1,
      "y": 19,
      "z": 1,
      "name": "Rock_Basalt"
    },
    {
      "x": 1,
      "y": 20,
      "z": 1,
      "name": "Rock_Basalt"
    },
    {
      "x": 1,
      "y": 21,
      "z": 1,
      "name": "Rock_Shale"
    },
    {
      "x": 1,
      "y": 22,
      "z": 1,
      "name": "Rock_Shale"
    },
    {
      "x": 1,
      "y": 23,
      "z": 1,
      "name": "Rock_Shale"
    },
    {
      "x": 1,
      "y": 24,
      "z": 1,
      "name": "Rock_Shale"
    },
    {
      "x": 1,
      "y": 25,
      "z": 1,
      "name": "Rock_Shale"
    },
    {
      "x": 1,
      "y": 26,
      "z": 1,
      "name": "Rock_Shale"
    },
    {
      "x": 1,
      "y": 27,
      "z": 1,
      "name": "Soil_Dirt_Cold"
    },
    {
      "x": 1,
      "y": 28,
      "z": 1,
      "name": "Soil_Dirt"
    },
    {
      "x": 1,
      "y": 29,
      "z": 1,
      "name": "Soil_Dirt_Cold"
    },
    {
      "x": 1,
      "y": 30,
      "z": 1,
      "name": "Soil_Grass_Cold"
    },
    {
      "x": 1,
      "y": 31,
      "z": 1,
      "name": "Plant_Bush_Winter_Red"
    },
    {
      "x": 1,
      "y": 6,
      "z": 2,
      "name": "Rock_Basalt"
    },
    {
      "x": 1,
      "y": 7,
      "z": 2,
      "name": "Rock_Basalt"
    },
    {
      "x": 1,
      "y": 8,
      "z": 2,
      "name": "Rock_Basalt"
    },
    {
      "x": 1,
      "y": 9,
      "z": 2,
      "name": "Rock_Basalt"
    },
    {
      "x": 1,
      "y": 10,
      "z": 2,
      "name": "Rock_Basalt"
    },
    {
      "x": 1,
      "y": 11,
      "z": 2,
      "name": "Rock_Basalt"
    },
    {
      "x": 1,
      "y": 12,
      "z": 2,
      "name": "Rock_Basalt"
    },
    {
      "x": 1,
      "y": 13,
      "z": 2,
      "name": "Rock_Basalt"
    },
    {
      "x": 1,
      "y": 14,
      "z": 2,
      "name": "Rock_Basalt"
    },
    {
      "x": 1,
      "y": 15,
      "z": 2,
      "name": "Rock_Basalt"
    },
    {
      "x": 1,
      "y": 16,
      "z": 2,
      "name": "Rock_Basalt"
    },
    {
      "x": 1,
      "y": 17,
      "z": 2,
      "name": "Rock_Basalt"
    },
    {
      "x": 1,
      "y": 18,
      "z": 2,
      "name": "Rock_Basalt"
    },
    {
      "x": 1,
      "y": 19,
      "z": 2,
      "name": "Rock_Basalt"
    },
    {
      "x": 1,
      "y": 20,
      "z": 2,
      "name": "Rock_Basalt"
    },
    {
      "x": 1,
      "y": 21,
      "z": 2,
      "name": "Rock_Shale"
    },
    {
      "x": 1,
      "y": 22,
      "z": 2,
      "name": "Rock_Shale"
    },
    {
      "x": 1,
      "y": 23,
      "z": 2,
      "name": "Rock_Shale"
    },
    {
      "x": 1,
      "y": 24,
      "z": 2,
      "name": "Rock_Shale"
    },
    {
      "x": 1,
      "y": 25,
      "z": 2,
      "name": "Rock_Shale"
    },
    {
      "x": 1,
      "y": 26,
      "z": 2,
      "name": "Rock_Shale"
    },
    {
      "x": 1,
      "y": 27,
      "z": 2,
      "name": "Rock_Shale"
    },
    {
      "x": 1,
      "y": 28,
      "z": 2,
      "name": "Soil_Dirt_Cold"
    },
    {
      "x": 1,
      "y": 29,
      "z": 2,
      "name": "Soil_Dirt_Cold"
    },
    {
      "x": 1,
      "y": 30,
      "z": 2,
      "name": "Soil_Grass_Cold"
    },
    {
      "x": 1,
      "y": 31,
      "z": 2,
      "name": "Plant_Bush_Winter_Red"
    },
    {
      "x": 1,
      "y": 7,
      "z": 3,
      "name": "Rock_Basalt"
    },
    {
      "x": 1,
      "y": 8,
      "z": 3,
      "name": "Rock_Basalt"
    },
    {
      "x": 1,
      "y": 9,
      "z": 3,
      "name": "Rock_Basalt"
    },
    {
      "x": 1,
      "y": 10,
      "z": 3,
      "name": "Rock_Basalt"
    },
    {
      "x": 1,
      "y": 11,
      "z": 3,
      "name": "Rock_Basalt"
    },
    {
      "x": 1,
      "y": 12,
      "z": 3,
      "name": "Rock_Basalt"
    },
    {
      "x": 1,
      "y": 13,
      "z": 3,
      "name": "Rock_Basalt"
    },
    {
      "x": 1,
      "y": 14,
      "z": 3,
      "name": "Rock_Basalt"
    },
    {
      "x": 1,
      "y": 15,
      "z": 3,
      "name": "Rock_Basalt"
    },
    {
      "x": 1,
      "y": 16,
      "z": 3,
      "name": "Rock_Basalt"
    },
    {
      "x": 1,
      "y": 17,
      "z": 3,
      "name": "Rock_Basalt"
    },
    {
      "x": 1,
      "y": 18,
      "z": 3,
      "name": "Rock_Shale"
    },
    {
      "x": 1,
      "y": 19,
      "z": 3,
      "name": "Rock_Basalt"
    },
    {
      "x": 1,
      "y": 20,
      "z": 3,
      "name": "Rock_Shale"
    },
    {
      "x": 1,
      "y": 21,
      "z": 3,
      "name": "Rock_Shale"
    },
    {
      "x": 1,
      "y": 22,
      "z": 3,
      "name": "Rock_Shale"
    },
    {
      "x": 1,
      "y": 23,
      "z": 3,
      "name": "Rock_Shale"
    },
    {
      "x": 1,
      "y": 24,
      "z": 3,
      "name": "Rock_Shale"
    },
    {
      "x": 1,
      "y": 25,
      "z": 3,
      "name": "Rock_Shale"
    },
    {
      "x": 1,
      "y": 26,
      "z": 3,
      "name": "Rock_Shale"
    },
    {
      "x": 1,
      "y": 27,
      "z": 3,
      "name": "Rock_Shale"
    },
    {
      "x": 1,
      "y": 28,
      "z": 3,
      "name": "Soil_Dirt_Cold"
    },
    {
      "x": 1,
      "y": 29,
      "z": 3,
      "name": "Soil_Dirt_Cold"
    },
    {
      "x": 1,
      "y": 30,
      "z": 3,
      "name": "Soil_Grass_Cold"
    },
    {
      "x": 1,
      "y": 31,
      "z": 3,
      "name": "Plant_Grass_Cave_Short"
    },
    {
      "x": 1,
      "y": 8,
      "z": 4,
      "name": "Rock_Basalt"
    },
    {
      "x": 1,
      "y": 9,
      "z": 4,
      "name": "Rock_Basalt"
    },
    {
      "x": 1,
      "y": 10,
      "z": 4,
      "name": "Rock_Basalt"
    },
    {
      "x": 1,
      "y": 11,
      "z": 4,
      "name": "Rock_Basalt"
    },
    {
      "x": 1,
      "y": 12,
      "z": 4,
      "name": "Rock_Basalt"
    },
    {
      "x": 1,
      "y": 13,
      "z": 4,
      "name": "Rock_Basalt"
    },
    {
      "x": 1,
      "y": 14,
      "z": 4,
      "name": "Rock_Basalt"
    },
    {
      "x": 1,
      "y": 15,
      "z": 4,
      "name": "Rock_Basalt"
    },
    {
      "x": 1,
      "y": 16,
      "z": 4,
      "name": "Rock_Basalt"
    },
    {
      "x": 1,
      "y": 17,
      "z": 4,
      "name": "Rock_Shale"
    },
    {
      "x": 1,
      "y": 18,
      "z": 4,
      "name": "Rock_Shale"
    },
    {
      "x": 1,
      "y": 19,
      "z": 4,
      "name": "Rock_Shale"
    },
    {
      "x": 1,
      "y": 20,
      "z": 4,
      "name": "Rock_Basalt"
    },
    {
      "x": 1,
      "y": 21,
      "z": 4,
      "name": "Rock_Shale"
    },
    {
      "x": 1,
      "y": 22,
      "z": 4,
      "name": "Rock_Basalt"
    },
    {
      "x": 1,
      "y": 23,
      "z": 4,
      "name": "Rock_Shale"
    },
    {
      "x": 1,
      "y": 24,
      "z": 4,
      "name": "Rock_Shale"
    },
    {
      "x": 1,
      "y": 25,
      "z": 4,
      "name": "Rock_Shale"
    },
    {
      "x": 1,
      "y": 26,
      "z": 4,
      "name": "Rock_Shale"
    },
    {
      "x": 1,
      "y": 27,
      "z": 4,
      "name": "Rock_Shale"
    },
    {
      "x": 1,
      "y": 28,
      "z": 4,
      "name": "Soil_Dirt_Cold"
    },
    {
      "x": 1,
      "y": 29,
      "z": 4,
      "name": "Soil_Grass_Cold"
    },
    {
      "x": 1,
      "y": 9,
      "z": 5,
      "name": "Rock_Basalt"
    },
    {
      "x": 1,
      "y": 10,
      "z": 5,
      "name": "Rock_Basalt"
    },
    {
      "x": 1,
      "y": 11,
      "z": 5,
      "name": "Rock_Basalt"
    },
    {
      "x": 1,
      "y": 12,
      "z": 5,
      "name": "Rock_Basalt"
    },
    {
      "x": 1,
      "y": 13,
      "z": 5,
      "name": "Rock_Basalt"
    },
    {
      "x": 1,
      "y": 14,
      "z": 5,
      "name": "Rock_Basalt"
    },
    {
      "x": 1,
      "y": 15,
      "z": 5,
      "name": "Rock_Basalt"
    },
    {
      "x": 1,
      "y": 16,
      "z": 5,
      "name": "Rock_Basalt"
    },
    {
      "x": 1,
      "y": 17,
      "z": 5,
      "name": "Rock_Basalt"
    },
    {
      "x": 1,
      "y": 18,
      "z": 5,
      "name": "Rock_Shale"
    },
    {
      "x": 1,
      "y": 19,
      "z": 5,
      "name": "Rock_Basalt"
    },
    {
      "x": 1,
      "y": 20,
      "z": 5,
      "name": "Soil_Dirt"
    },
    {
      "x": 1,
      "y": 21,
      "z": 5,
      "name": "Rock_Basalt"
    },
    {
      "x": 1,
      "y": 22,
      "z": 5,
      "name": "Rock_Basalt"
    },
    {
      "x": 1,
      "y": 23,
      "z": 5,
      "name": "Rock_Shale"
    },
    {
      "x": 1,
      "y": 24,
      "z": 5,
      "name": "Soil_Dirt_Cold"
    },
    {
      "x": 1,
      "y": 25,
      "z": 5,
      "name": "Soil_Grass_Cold"
    },
    {
      "x": 1,
      "y": 17,
      "z": 6,
      "name": "Rock_Basalt"
    },
    {
      "x": 1,
      "y": 18,
      "z": 6,
      "name": "Rock_Basalt"
    },
    {
      "x": 1,
      "y": 19,
      "z": 6,
      "name": "Rock_Basalt"
    },
    {
      "x": 1,
      "y": 20,
      "z": 6,
      "name": "Soil_Dirt"
    },
    {
      "x": 1,
      "y": 21,
      "z": 6,
      "name": "Soil_Grass"
    },
    {
      "x": 1,
      "y": 22,
      "z": 6,
      "name": "Plant_Grass_Lush_Short"
    },
    {
      "x": 2,
      "y": 14,
      "z": -3,
      "name": "Rock_Basalt"
    },
    {
      "x": 2,
      "y": 15,
      "z": -3,
      "name": "Rock_Basalt"
    },
    {
      "x": 2,
      "y": 16,
      "z": -3,
      "name": "Rock_Basalt"
    },
    {
      "x": 2,
      "y": 17,
      "z": -3,
      "name": "Rock_Basalt"
    },
    {
      "x": 2,
      "y": 18,
      "z": -3,
      "name": "Rock_Basalt"
    },
    {
      "x": 2,
      "y": 19,
      "z": -3,
      "name": "Rock_Basalt"
    },
    {
      "x": 2,
      "y": 20,
      "z": -3,
      "name": "Soil_Dirt"
    },
    {
      "x": 2,
      "y": 21,
      "z": -3,
      "name": "Soil_Grass"
    },
    {
      "x": 2,
      "y": 9,
      "z": -2,
      "name": "Rock_Basalt"
    },
    {
      "x": 2,
      "y": 10,
      "z": -2,
      "name": "Rock_Basalt"
    },
    {
      "x": 2,
      "y": 11,
      "z": -2,
      "name": "Rock_Basalt"
    },
    {
      "x": 2,
      "y": 12,
      "z": -2,
      "name": "Rock_Basalt"
    },
    {
      "x": 2,
      "y": 13,
      "z": -2,
      "name": "Rock_Basalt"
    },
    {
      "x": 2,
      "y": 14,
      "z": -2,
      "name": "Rock_Basalt"
    },
    {
      "x": 2,
      "y": 15,
      "z": -2,
      "name": "Rock_Basalt"
    },
    {
      "x": 2,
      "y": 16,
      "z": -2,
      "name": "Rock_Basalt"
    },
    {
      "x": 2,
      "y": 17,
      "z": -2,
      "name": "Rock_Basalt"
    },
    {
      "x": 2,
      "y": 18,
      "z": -2,
      "name": "Rock_Basalt"
    },
    {
      "x": 2,
      "y": 19,
      "z": -2,
      "name": "Rock_Basalt"
    },
    {
      "x": 2,
      "y": 20,
      "z": -2,
      "name": "Soil_Dirt"
    },
    {
      "x": 2,
      "y": 21,
      "z": -2,
      "name": "Soil_Grass"
    },
    {
      "x": 2,
      "y": 22,
      "z": -2,
      "name": "Plant_Grass_Lush"
    },
    {
      "x": 2,
      "y": 7,
      "z": -1,
      "name": "Rock_Basalt"
    },
    {
      "x": 2,
      "y": 8,
      "z": -1,
      "name": "Rock_Basalt"
    },
    {
      "x": 2,
      "y": 9,
      "z": -1,
      "name": "Rock_Basalt"
    },
    {
      "x": 2,
      "y": 10,
      "z": -1,
      "name": "Rock_Basalt"
    },
    {
      "x": 2,
      "y": 11,
      "z": -1,
      "name": "Rock_Basalt"
    },
    {
      "x": 2,
      "y": 12,
      "z": -1,
      "name": "Rock_Basalt"
    },
    {
      "x": 2,
      "y": 13,
      "z": -1,
      "name": "Rock_Basalt"
    },
    {
      "x": 2,
      "y": 14,
      "z": -1,
      "name": "Rock_Basalt"
    },
    {
      "x": 2,
      "y": 15,
      "z": -1,
      "name": "Rock_Basalt"
    },
    {
      "x": 2,
      "y": 16,
      "z": -1,
      "name": "Rock_Basalt"
    },
    {
      "x": 2,
      "y": 17,
      "z": -1,
      "name": "Rock_Basalt"
    },
    {
      "x": 2,
      "y": 18,
      "z": -1,
      "name": "Rock_Basalt"
    },
    {
      "x": 2,
      "y": 19,
      "z": -1,
      "name": "Rock_Basalt"
    },
    {
      "x": 2,
      "y": 20,
      "z": -1,
      "name": "Soil_Dirt"
    },
    {
      "x": 2,
      "y": 21,
      "z": -1,
      "name": "Soil_Grass"
    },
    {
      "x": 2,
      "y": 22,
      "z": -1,
      "name": "Plant_Grass_Sharp_Tall"
    },
    {
      "x": 2,
      "y": 23,
      "z": -1,
      "name": "Plant_Grass_Sharp_Tall",
      "filler": 1024
    },
    {
      "x": 2,
      "y": 26,
      "z": -1,
      "name": "Soil_Dirt_Cold"
    },
    {
      "x": 2,
      "y": 27,
      "z": -1,
      "name": "Soil_Dirt_Cold"
    },
    {
      "x": 2,
      "y": 28,
      "z": -1,
      "name": "Soil_Grass_Cold"
    },
    {
      "x": 2,
      "y": 6,
      "z": 0,
      "name": "Rock_Basalt"
    },
    {
      "x": 2,
      "y": 7,
      "z": 0,
      "name": "Rock_Basalt"
    },
    {
      "x": 2,
      "y": 8,
      "z": 0,
      "name": "Rock_Basalt"
    },
    {
      "x": 2,
      "y": 9,
      "z": 0,
      "name": "Rock_Basalt"
    },
    {
      "x": 2,
      "y": 10,
      "z": 0,
      "name": "Rock_Basalt"
    },
    {
      "x": 2,
      "y": 11,
      "z": 0,
      "name": "Rock_Basalt"
    },
    {
      "x": 2,
      "y": 12,
      "z": 0,
      "name": "Rock_Basalt"
    },
    {
      "x": 2,
      "y": 13,
      "z": 0,
      "name": "Rock_Basalt"
    },
    {
      "x": 2,
      "y": 14,
      "z": 0,
      "name": "Rock_Basalt"
    },
    {
      "x": 2,
      "y": 15,
      "z": 0,
      "name": "Rock_Basalt"
    },
    {
      "x": 2,
      "y": 16,
      "z": 0,
      "name": "Rock_Basalt"
    },
    {
      "x": 2,
      "y": 17,
      "z": 0,
      "name": "Rock_Basalt"
    },
    {
      "x": 2,
      "y": 18,
      "z": 0,
      "name": "Rock_Basalt"
    },
    {
      "x": 2,
      "y": 19,
      "z": 0,
      "name": "Rock_Basalt"
    },
    {
      "x": 2,
      "y": 20,
      "z": 0,
      "name": "Soil_Dirt"
    },
    {
      "x": 2,
      "y": 21,
      "z": 0,
      "name": "Rock_Shale"
    },
    {
      "x": 2,
      "y": 22,
      "z": 0,
      "name": "Rock_Shale"
    },
    {
      "x": 2,
      "y": 23,
      "z": 0,
      "name": "Rock_Shale"
    },
    {
      "x": 2,
      "y": 24,
      "z": 0,
      "name": "Rock_Shale"
    },
    {
      "x": 2,
      "y": 25,
      "z": 0,
      "name": "Rock_Shale"
    },
    {
      "x": 2,
      "y": 26,
      "z": 0,
      "name": "Soil_Dirt_Cold"
    },
    {
      "x": 2,
      "y": 27,
      "z": 0,
      "name": "Soil_Dirt_Cold"
    },
    {
      "x": 2,
      "y": 28,
      "z": 0,
      "name": "Soil_Grass_Cold"
    },
    {
      "x": 2,
      "y": 6,
      "z": 1,
      "name": "Rock_Basalt"
    },
    {
      "x": 2,
      "y": 7,
      "z": 1,
      "name": "Rock_Basalt"
    },
    {
      "x": 2,
      "y": 8,
      "z": 1,
      "name": "Rock_Basalt"
    },
    {
      "x": 2,
      "y": 9,
      "z": 1,
      "name": "Rock_Basalt"
    },
    {
      "x": 2,
      "y": 10,
      "z": 1,
      "name": "Rock_Basalt"
    },
    {
      "x": 2,
      "y": 11,
      "z": 1,
      "name": "Rock_Basalt"
    },
    {
      "x": 2,
      "y": 12,
      "z": 1,
      "name": "Rock_Basalt"
    },
    {
      "x": 2,
      "y": 13,
      "z": 1,
      "name": "Rock_Basalt"
    },
    {
      "x": 2,
      "y": 14,
      "z": 1,
      "name": "Rock_Basalt"
    },
    {
      "x": 2,
      "y": 15,
      "z": 1,
      "name": "Rock_Basalt"
    },
    {
      "x": 2,
      "y": 16,
      "z": 1,
      "name": "Rock_Basalt"
    },
    {
      "x": 2,
      "y": 17,
      "z": 1,
      "name": "Rock_Basalt"
    },
    {
      "x": 2,
      "y": 18,
      "z": 1,
      "name": "Rock_Basalt"
    },
    {
      "x": 2,
      "y": 19,
      "z": 1,
      "name": "Rock_Basalt"
    },
    {
      "x": 2,
      "y": 20,
      "z": 1,
      "name": "Rock_Basalt"
    },
    {
      "x": 2,
      "y": 21,
      "z": 1,
      "name": "Rock_Shale"
    },
    {
      "x": 2,
      "y": 22,
      "z": 1,
      "name": "Rock_Shale"
    },
    {
      "x": 2,
      "y": 23,
      "z": 1,
      "name": "Rock_Shale"
    },
    {
      "x": 2,
      "y": 24,
      "z": 1,
      "name": "Rock_Shale"
    },
    {
      "x": 2,
      "y": 25,
      "z": 1,
      "name": "Rock_Shale"
    },
    {
      "x": 2,
      "y": 26,
      "z": 1,
      "name": "Soil_Dirt_Cold"
    },
    {
      "x": 2,
      "y": 27,
      "z": 1,
      "name": "Soil_Dirt_Cold"
    },
    {
      "x": 2,
      "y": 28,
      "z": 1,
      "name": "Soil_Dirt_Cold"
    },
    {
      "x": 2,
      "y": 29,
      "z": 1,
      "name": "Soil_Dirt_Cold"
    },
    {
      "x": 2,
      "y": 30,
      "z": 1,
      "name": "Soil_Grass_Cold"
    },
    {
      "x": 2,
      "y": 6,
      "z": 2,
      "name": "Rock_Basalt"
    },
    {
      "x": 2,
      "y": 7,
      "z": 2,
      "name": "Rock_Basalt"
    },
    {
      "x": 2,
      "y": 8,
      "z": 2,
      "name": "Rock_Basalt"
    },
    {
      "x": 2,
      "y": 9,
      "z": 2,
      "name": "Rock_Basalt"
    },
    {
      "x": 2,
      "y": 10,
      "z": 2,
      "name": "Rock_Basalt"
    },
    {
      "x": 2,
      "y": 11,
      "z": 2,
      "name": "Rock_Basalt"
    },
    {
      "x": 2,
      "y": 12,
      "z": 2,
      "name": "Rock_Basalt"
    },
    {
      "x": 2,
      "y": 13,
      "z": 2,
      "name": "Rock_Basalt"
    },
    {
      "x": 2,
      "y": 14,
      "z": 2,
      "name": "Rock_Basalt"
    },
    {
      "x": 2,
      "y": 15,
      "z": 2,
      "name": "Rock_Basalt"
    },
    {
      "x": 2,
      "y": 16,
      "z": 2,
      "name": "Rock_Basalt"
    },
    {
      "x": 2,
      "y": 17,
      "z": 2,
      "name": "Rock_Basalt"
    },
    {
      "x": 2,
      "y": 18,
      "z": 2,
      "name": "Rock_Basalt"
    },
    {
      "x": 2,
      "y": 19,
      "z": 2,
      "name": "Rock_Basalt"
    },
    {
      "x": 2,
      "y": 20,
      "z": 2,
      "name": "Rock_Basalt"
    },
    {
      "x": 2,
      "y": 21,
      "z": 2,
      "name": "Rock_Basalt"
    },
    {
      "x": 2,
      "y": 22,
      "z": 2,
      "name": "Rock_Shale"
    },
    {
      "x": 2,
      "y": 23,
      "z": 2,
      "name": "Rock_Shale"
    },
    {
      "x": 2,
      "y": 24,
      "z": 2,
      "name": "Rock_Shale"
    },
    {
      "x": 2,
      "y": 25,
      "z": 2,
      "name": "Rock_Shale"
    },
    {
      "x": 2,
      "y": 26,
      "z": 2,
      "name": "Rock_Shale"
    },
    {
      "x": 2,
      "y": 27,
      "z": 2,
      "name": "Soil_Dirt_Cold"
    },
    {
      "x": 2,
      "y": 28,
      "z": 2,
      "name": "Soil_Dirt_Cold"
    },
    {
      "x": 2,
      "y": 29,
      "z": 2,
      "name": "Soil_Dirt_Cold"
    },
    {
      "x": 2,
      "y": 30,
      "z": 2,
      "name": "Soil_Grass_Cold"
    },
    {
      "x": 2,
      "y": 31,
      "z": 2,
      "name": "Plant_Grass_Cave_Short"
    },
    {
      "x": 2,
      "y": 7,
      "z": 3,
      "name": "Rock_Basalt"
    },
    {
      "x": 2,
      "y": 8,
      "z": 3,
      "name": "Rock_Basalt"
    },
    {
      "x": 2,
      "y": 9,
      "z": 3,
      "name": "Rock_Basalt"
    },
    {
      "x": 2,
      "y": 10,
      "z": 3,
      "name": "Rock_Basalt"
    },
    {
      "x": 2,
      "y": 11,
      "z": 3,
      "name": "Rock_Basalt"
    },
    {
      "x": 2,
      "y": 12,
      "z": 3,
      "name": "Rock_Basalt"
    },
    {
      "x": 2,
      "y": 13,
      "z": 3,
      "name": "Rock_Basalt"
    },
    {
      "x": 2,
      "y": 14,
      "z": 3,
      "name": "Rock_Basalt"
    },
    {
      "x": 2,
      "y": 15,
      "z": 3,
      "name": "Rock_Basalt"
    },
    {
      "x": 2,
      "y": 16,
      "z": 3,
      "name": "Rock_Basalt"
    },
    {
      "x": 2,
      "y": 17,
      "z": 3,
      "name": "Rock_Basalt"
    },
    {
      "x": 2,
      "y": 18,
      "z": 3,
      "name": "Rock_Basalt"
    },
    {
      "x": 2,
      "y": 19,
      "z": 3,
      "name": "Rock_Basalt"
    },
    {
      "x": 2,
      "y": 20,
      "z": 3,
      "name": "Soil_Dirt"
    },
    {
      "x": 2,
      "y": 21,
      "z": 3,
      "name": "Rock_Basalt"
    },
    {
      "x": 2,
      "y": 22,
      "z": 3,
      "name": "Rock_Basalt"
    },
    {
      "x": 2,
      "y": 23,
      "z": 3,
      "name": "Rock_Shale"
    },
    {
      "x": 2,
      "y": 24,
      "z": 3,
      "name": "Rock_Shale"
    },
    {
      "x": 2,
      "y": 25,
      "z": 3,
      "name": "Rock_Shale"
    },
    {
      "x": 2,
      "y": 26,
      "z": 3,
      "name": "Rock_Shale"
    },
    {
      "x": 2,
      "y": 27,
      "z": 3,
      "name": "Soil_Dirt_Cold"
    },
    {
      "x": 2,
      "y": 28,
      "z": 3,
      "name": "Soil_Dirt_Cold"
    },
    {
      "x": 2,
      "y": 29,
      "z": 3,
      "name": "Soil_Dirt_Cold"
    },
    {
      "x": 2,
      "y": 30,
      "z": 3,
      "name": "Soil_Grass_Cold"
    },
    {
      "x": 2,
      "y": 8,
      "z": 4,
      "name": "Rock_Basalt"
    },
    {
      "x": 2,
      "y": 9,
      "z": 4,
      "name": "Rock_Basalt"
    },
    {
      "x": 2,
      "y": 10,
      "z": 4,
      "name": "Rock_Basalt"
    },
    {
      "x": 2,
      "y": 11,
      "z": 4,
      "name": "Rock_Basalt"
    },
    {
      "x": 2,
      "y": 12,
      "z": 4,
      "name": "Rock_Basalt"
    },
    {
      "x": 2,
      "y": 13,
      "z": 4,
      "name": "Rock_Basalt"
    },
    {
      "x": 2,
      "y": 14,
      "z": 4,
      "name": "Rock_Basalt"
    },
    {
      "x": 2,
      "y": 15,
      "z": 4,
      "name": "Rock_Basalt"
    },
    {
      "x": 2,
      "y": 16,
      "z": 4,
      "name": "Rock_Basalt"
    },
    {
      "x": 2,
      "y": 17,
      "z": 4,
      "name": "Rock_Basalt"
    },
    {
      "x": 2,
      "y": 18,
      "z": 4,
      "name": "Rock_Basalt"
    },
    {
      "x": 2,
      "y": 19,
      "z": 4,
      "name": "Rock_Basalt"
    },
    {
      "x": 2,
      "y": 20,
      "z": 4,
      "name": "Soil_Dirt"
    },
    {
      "x": 2,
      "y": 21,
      "z": 4,
      "name": "Soil_Dirt"
    },
    {
      "x": 2,
      "y": 22,
      "z": 4,
      "name": "Rock_Basalt"
    },
    {
      "x": 2,
      "y": 23,
      "z": 4,
      "name": "Rock_Shale"
    },
    {
      "x": 2,
      "y": 10,
      "z": 5,
      "name": "Rock_Basalt"
    },
    {
      "x": 2,
      "y": 11,
      "z": 5,
      "name": "Rock_Basalt"
    },
    {
      "x": 2,
      "y": 12,
      "z": 5,
      "name": "Rock_Basalt"
    },
    {
      "x": 2,
      "y": 13,
      "z": 5,
      "name": "Rock_Basalt"
    },
    {
      "x": 2,
      "y": 14,
      "z": 5,
      "name": "Rock_Basalt"
    },
    {
      "x": 2,
      "y": 15,
      "z": 5,
      "name": "Rock_Basalt"
    },
    {
      "x": 2,
      "y": 16,
      "z": 5,
      "name": "Rock_Basalt"
    },
    {
      "x": 2,
      "y": 17,
      "z": 5,
      "name": "Rock_Basalt"
    },
    {
      "x": 2,
      "y": 18,
      "z": 5,
      "name": "Rock_Basalt"
    },
    {
      "x": 2,
      "y": 19,
      "z": 5,
      "name": "Rock_Basalt"
    },
    {
      "x": 2,
      "y": 20,
      "z": 5,
      "name": "Soil_Dirt"
    },
    {
      "x": 2,
      "y": 21,
      "z": 5,
      "name": "Soil_Grass"
    },
    {
      "x": 2,
      "y": 22,
      "z": 5,
      "name": "Plant_Grass_Sharp_Tall"
    },
    {
      "x": 2,
      "y": 23,
      "z": 5,
      "name": "Plant_Grass_Sharp_Tall",
      "filler": 1024
    },
    {
      "x": 2,
      "y": 18,
      "z": 6,
      "name": "Rock_Basalt"
    },
    {
      "x": 2,
      "y": 19,
      "z": 6,
      "name": "Rock_Basalt"
    },
    {
      "x": 2,
      "y": 20,
      "z": 6,
      "name": "Soil_Dirt"
    },
    {
      "x": 2,
      "y": 21,
      "z": 6,
      "name": "Soil_Grass"
    },
    {
      "x": 3,
      "y": 18,
      "z": -3,
      "name": "Rock_Basalt"
    },
    {
      "x": 3,
      "y": 19,
      "z": -3,
      "name": "Rock_Basalt"
    },
    {
      "x": 3,
      "y": 20,
      "z": -3,
      "name": "Soil_Dirt"
    },
    {
      "x": 3,
      "y": 21,
      "z": -3,
      "name": "Soil_Grass"
    },
    {
      "x": 3,
      "y": 10,
      "z": -2,
      "name": "Rock_Basalt"
    },
    {
      "x": 3,
      "y": 11,
      "z": -2,
      "name": "Rock_Basalt"
    },
    {
      "x": 3,
      "y": 12,
      "z": -2,
      "name": "Rock_Basalt"
    },
    {
      "x": 3,
      "y": 13,
      "z": -2,
      "name": "Rock_Basalt"
    },
    {
      "x": 3,
      "y": 14,
      "z": -2,
      "name": "Rock_Basalt"
    },
    {
      "x": 3,
      "y": 15,
      "z": -2,
      "name": "Rock_Basalt"
    },
    {
      "x": 3,
      "y": 16,
      "z": -2,
      "name": "Rock_Basalt"
    },
    {
      "x": 3,
      "y": 17,
      "z": -2,
      "name": "Rock_Basalt"
    },
    {
      "x": 3,
      "y": 18,
      "z": -2,
      "name": "Rock_Basalt"
    },
    {
      "x": 3,
      "y": 19,
      "z": -2,
      "name": "Soil_Dirt"
    },
    {
      "x": 3,
      "y": 20,
      "z": -2,
      "name": "Soil_Dirt"
    },
    {
      "x": 3,
      "y": 21,
      "z": -2,
      "name": "Soil_Grass"
    },
    {
      "x": 3,
      "y": 8,
      "z": -1,
      "name": "Rock_Basalt"
    },
    {
      "x": 3,
      "y": 9,
      "z": -1,
      "name": "Rock_Basalt"
    },
    {
      "x": 3,
      "y": 10,
      "z": -1,
      "name": "Rock_Basalt"
    },
    {
      "x": 3,
      "y": 11,
      "z": -1,
      "name": "Rock_Basalt"
    },
    {
      "x": 3,
      "y": 12,
      "z": -1,
      "name": "Rock_Basalt"
    },
    {
      "x": 3,
      "y": 13,
      "z": -1,
      "name": "Rock_Basalt"
    },
    {
      "x": 3,
      "y": 14,
      "z": -1,
      "name": "Rock_Basalt"
    },
    {
      "x": 3,
      "y": 15,
      "z": -1,
      "name": "Rock_Basalt"
    },
    {
      "x": 3,
      "y": 16,
      "z": -1,
      "name": "Rock_Basalt"
    },
    {
      "x": 3,
      "y": 17,
      "z": -1,
      "name": "Rock_Basalt"
    },
    {
      "x": 3,
      "y": 18,
      "z": -1,
      "name": "Rock_Basalt"
    },
    {
      "x": 3,
      "y": 19,
      "z": -1,
      "name": "Soil_Dirt"
    },
    {
      "x": 3,
      "y": 20,
      "z": -1,
      "name": "Soil_Dirt"
    },
    {
      "x": 3,
      "y": 21,
      "z": -1,
      "name": "Soil_Grass"
    },
    {
      "x": 3,
      "y": 22,
      "z": -1,
      "name": "Plant_Grass_Sharp"
    },
    {
      "x": 3,
      "y": 8,
      "z": 0,
      "name": "Rock_Basalt"
    },
    {
      "x": 3,
      "y": 9,
      "z": 0,
      "name": "Rock_Basalt"
    },
    {
      "x": 3,
      "y": 10,
      "z": 0,
      "name": "Rock_Basalt"
    },
    {
      "x": 3,
      "y": 11,
      "z": 0,
      "name": "Rock_Basalt"
    },
    {
      "x": 3,
      "y": 12,
      "z": 0,
      "name": "Rock_Basalt"
    },
    {
      "x": 3,
      "y": 13,
      "z": 0,
      "name": "Rock_Basalt"
    },
    {
      "x": 3,
      "y": 14,
      "z": 0,
      "name": "Rock_Basalt"
    },
    {
      "x": 3,
      "y": 15,
      "z": 0,
      "name": "Rock_Basalt"
    },
    {
      "x": 3,
      "y": 16,
      "z": 0,
      "name": "Rock_Basalt"
    },
    {
      "x": 3,
      "y": 17,
      "z": 0,
      "name": "Rock_Basalt"
    },
    {
      "x": 3,
      "y": 18,
      "z": 0,
      "name": "Rock_Basalt"
    },
    {
      "x": 3,
      "y": 19,
      "z": 0,
      "name": "Soil_Dirt"
    },
    {
      "x": 3,
      "y": 20,
      "z": 0,
      "name": "Soil_Dirt"
    },
    {
      "x": 3,
      "y": 21,
      "z": 0,
      "name": "Soil_Dirt"
    },
    {
      "x": 3,
      "y": 22,
      "z": 0,
      "name": "Soil_Grass"
    },
    {
      "x": 3,
      "y": 25,
      "z": 0,
      "name": "Rock_Shale"
    },
    {
      "x": 3,
      "y": 26,
      "z": 0,
      "name": "Soil_Dirt_Cold"
    },
    {
      "x": 3,
      "y": 27,
      "z": 0,
      "name": "Soil_Grass_Cold"
    },
    {
      "x": 3,
      "y": 28,
      "z": 0,
      "name": "Plant_Grass_Cave_Short"
    },
    {
      "x": 3,
      "y": 8,
      "z": 1,
      "name": "Rock_Basalt"
    },
    {
      "x": 3,
      "y": 9,
      "z": 1,
      "name": "Rock_Basalt"
    },
    {
      "x": 3,
      "y": 10,
      "z": 1,
      "name": "Rock_Basalt"
    },
    {
      "x": 3,
      "y": 11,
      "z": 1,
      "name": "Rock_Basalt"
    },
    {
      "x": 3,
      "y": 12,
      "z": 1,
      "name": "Rock_Basalt"
    },
    {
      "x": 3,
      "y": 13,
      "z": 1,
      "name": "Rock_Basalt"
    },
    {
      "x": 3,
      "y": 14,
      "z": 1,
      "name": "Rock_Basalt"
    },
    {
      "x": 3,
      "y": 15,
      "z": 1,
      "name": "Rock_Basalt"
    },
    {
      "x": 3,
      "y": 16,
      "z": 1,
      "name": "Rock_Basalt"
    },
    {
      "x": 3,
      "y": 17,
      "z": 1,
      "name": "Soil_Dirt"
    },
    {
      "x": 3,
      "y": 18,
      "z": 1,
      "name": "Soil_Dirt"
    },
    {
      "x": 3,
      "y": 19,
      "z": 1,
      "name": "Rock_Basalt"
    },
    {
      "x": 3,
      "y": 20,
      "z": 1,
      "name": "Soil_Dirt"
    },
    {
      "x": 3,
      "y": 21,
      "z": 1,
      "name": "Rock_Basalt"
    },
    {
      "x": 3,
      "y": 22,
      "z": 1,
      "name": "Rock_Shale"
    },
    {
      "x": 3,
      "y": 23,
      "z": 1,
      "name": "Rock_Shale"
    },
    {
      "x": 3,
      "y": 24,
      "z": 1,
      "name": "Rock_Shale"
    },
    {
      "x": 3,
      "y": 25,
      "z": 1,
      "name": "Rock_Shale"
    },
    {
      "x": 3,
      "y": 26,
      "z": 1,
      "name": "Soil_Dirt_Cold"
    },
    {
      "x": 3,
      "y": 27,
      "z": 1,
      "name": "Soil_Grass_Cold"
    },
    {
      "x": 3,
      "y": 28,
      "z": 1,
      "name": "Plant_Bush_Winter_Red"
    },
    {
      "x": 3,
      "y": 9,
      "z": 2,
      "name": "Rock_Basalt"
    },
    {
      "x": 3,
      "y": 10,
      "z": 2,
      "name": "Rock_Basalt"
    },
    {
      "x": 3,
      "y": 11,
      "z": 2,
      "name": "Rock_Basalt"
    },
    {
      "x": 3,
      "y": 12,
      "z": 2,
      "name": "Rock_Basalt"
    },
    {
      "x": 3,
      "y": 13,
      "z": 2,
      "name": "Rock_Basalt"
    },
    {
      "x": 3,
      "y": 14,
      "z": 2,
      "name": "Rock_Basalt"
    },
    {
      "x": 3,
      "y": 15,
      "z": 2,
      "name": "Rock_Basalt"
    },
    {
      "x": 3,
      "y": 16,
      "z": 2,
      "name": "Rock_Basalt"
    },
    {
      "x": 3,
      "y": 17,
      "z": 2,
      "name": "Soil_Dirt"
    },
    {
      "x": 3,
      "y": 18,
      "z": 2,
      "name": "Soil_Dirt"
    },
    {
      "x": 3,
      "y": 19,
      "z": 2,
      "name": "Rock_Basalt"
    },
    {
      "x": 3,
      "y": 20,
      "z": 2,
      "name": "Soil_Dirt"
    },
    {
      "x": 3,
      "y": 21,
      "z": 2,
      "name": "Rock_Basalt"
    },
    {
      "x": 3,
      "y": 22,
      "z": 2,
      "name": "Rock_Shale"
    },
    {
      "x": 3,
      "y": 23,
      "z": 2,
      "name": "Rock_Shale"
    },
    {
      "x": 3,
      "y": 24,
      "z": 2,
      "name": "Rock_Shale"
    },
    {
      "x": 3,
      "y": 25,
      "z": 2,
      "name": "Rock_Shale"
    },
    {
      "x": 3,
      "y": 26,
      "z": 2,
      "name": "Rock_Shale"
    },
    {
      "x": 3,
      "y": 27,
      "z": 2,
      "name": "Soil_Dirt_Cold"
    },
    {
      "x": 3,
      "y": 28,
      "z": 2,
      "name": "Soil_Grass_Cold"
    },
    {
      "x": 3,
      "y": 29,
      "z": 2,
      "name": "Plant_Grass_Winter"
    },
    {
      "x": 3,
      "y": 9,
      "z": 3,
      "name": "Rock_Basalt"
    },
    {
      "x": 3,
      "y": 10,
      "z": 3,
      "name": "Rock_Basalt"
    },
    {
      "x": 3,
      "y": 11,
      "z": 3,
      "name": "Rock_Basalt"
    },
    {
      "x": 3,
      "y": 12,
      "z": 3,
      "name": "Rock_Basalt"
    },
    {
      "x": 3,
      "y": 13,
      "z": 3,
      "name": "Rock_Basalt"
    },
    {
      "x": 3,
      "y": 14,
      "z": 3,
      "name": "Rock_Basalt"
    },
    {
      "x": 3,
      "y": 15,
      "z": 3,
      "name": "Rock_Basalt"
    },
    {
      "x": 3,
      "y": 16,
      "z": 3,
      "name": "Rock_Basalt"
    },
    {
      "x": 3,
      "y": 17,
      "z": 3,
      "name": "Soil_Dirt"
    },
    {
      "x": 3,
      "y": 18,
      "z": 3,
      "name": "Soil_Dirt"
    },
    {
      "x": 3,
      "y": 19,
      "z": 3,
      "name": "Soil_Dirt"
    },
    {
      "x": 3,
      "y": 20,
      "z": 3,
      "name": "Soil_Dirt"
    },
    {
      "x": 3,
      "y": 21,
      "z": 3,
      "name": "Soil_Dirt"
    },
    {
      "x": 3,
      "y": 22,
      "z": 3,
      "name": "Rock_Basalt"
    },
    {
      "x": 3,
      "y": 23,
      "z": 3,
      "name": "Rock_Shale"
    },
    {
      "x": 3,
      "y": 24,
      "z": 3,
      "name": "Rock_Shale"
    },
    {
      "x": 3,
      "y": 25,
      "z": 3,
      "name": "Rock_Shale"
    },
    {
      "x": 3,
      "y": 26,
      "z": 3,
      "name": "Rock_Shale"
    },
    {
      "x": 3,
      "y": 27,
      "z": 3,
      "name": "Soil_Dirt_Cold"
    },
    {
      "x": 3,
      "y": 28,
      "z": 3,
      "name": "Soil_Grass_Cold"
    },
    {
      "x": 3,
      "y": 11,
      "z": 4,
      "name": "Rock_Basalt"
    },
    {
      "x": 3,
      "y": 12,
      "z": 4,
      "name": "Rock_Basalt"
    },
    {
      "x": 3,
      "y": 13,
      "z": 4,
      "name": "Rock_Basalt"
    },
    {
      "x": 3,
      "y": 14,
      "z": 4,
      "name": "Rock_Basalt"
    },
    {
      "x": 3,
      "y": 15,
      "z": 4,
      "name": "Rock_Basalt"
    },
    {
      "x": 3,
      "y": 16,
      "z": 4,
      "name": "Rock_Basalt"
    },
    {
      "x": 3,
      "y": 17,
      "z": 4,
      "name": "Rock_Basalt"
    },
    {
      "x": 3,
      "y": 18,
      "z": 4,
      "name": "Rock_Basalt"
    },
    {
      "x": 3,
      "y": 19,
      "z": 4,
      "name": "Soil_Dirt"
    },
    {
      "x": 3,
      "y": 20,
      "z": 4,
      "name": "Soil_Dirt"
    },
    {
      "x": 3,
      "y": 21,
      "z": 4,
      "name": "Soil_Grass"
    },
    {
      "x": 3,
      "y": 22,
      "z": 4,
      "name": "Plant_Grass_Sharp"
    },
    {
      "x": 3,
      "y": 17,
      "z": 5,
      "name": "Rock_Basalt"
    },
    {
      "x": 3,
      "y": 18,
      "z": 5,
      "name": "Rock_Basalt"
    },
    {
      "x": 3,
      "y": 19,
      "z": 5,
      "name": "Soil_Dirt"
    },
    {
      "x": 3,
      "y": 20,
      "z": 5,
      "name": "Soil_Dirt"
    },
    {
      "x": 3,
      "y": 21,
      "z": 5,
      "name": "Soil_Grass"
    },
    {
      "x": 3,
      "y": 22,
      "z": 5,
      "name": "Plant_Grass_Sharp"
    },
    {
      "x": 3,
      "y": 19,
      "z": 6,
      "name": "Rock_Basalt"
    },
    {
      "x": 3,
      "y": 20,
      "z": 6,
      "name": "Soil_Dirt"
    },
    {
      "x": 3,
      "y": 21,
      "z": 6,
      "name": "Soil_Grass"
    },
    {
      "x": 3,
      "y": 22,
      "z": 6,
      "name": "Plant_Grass_Sharp"
    },
    {
      "x": 4,
      "y": 17,
      "z": -2,
      "name": "Rock_Basalt"
    },
    {
      "x": 4,
      "y": 18,
      "z": -2,
      "name": "Rock_Basalt"
    },
    {
      "x": 4,
      "y": 19,
      "z": -2,
      "name": "Soil_Dirt"
    },
    {
      "x": 4,
      "y": 20,
      "z": -2,
      "name": "Soil_Dirt"
    },
    {
      "x": 4,
      "y": 21,
      "z": -2,
      "name": "Soil_Grass"
    },
    {
      "x": 4,
      "y": 13,
      "z": -1,
      "name": "Rock_Basalt"
    },
    {
      "x": 4,
      "y": 14,
      "z": -1,
      "name": "Rock_Basalt"
    },
    {
      "x": 4,
      "y": 15,
      "z": -1,
      "name": "Rock_Basalt"
    },
    {
      "x": 4,
      "y": 16,
      "z": -1,
      "name": "Rock_Basalt"
    },
    {
      "x": 4,
      "y": 17,
      "z": -1,
      "name": "Rock_Basalt"
    },
    {
      "x": 4,
      "y": 18,
      "z": -1,
      "name": "Rock_Basalt"
    },
    {
      "x": 4,
      "y": 19,
      "z": -1,
      "name": "Soil_Dirt"
    },
    {
      "x": 4,
      "y": 20,
      "z": -1,
      "name": "Soil_Dirt"
    },
    {
      "x": 4,
      "y": 21,
      "z": -1,
      "name": "Soil_Grass"
    },
    {
      "x": 4,
      "y": 11,
      "z": 0,
      "name": "Rock_Basalt"
    },
    {
      "x": 4,
