{
  "version": 8,
  "blockIdVersion": 10,
  "anchorX": 5,
  "anchorY": 8,
  "anchorZ": 4,
  "blocks": [
    {
      "x": 1,
      "y": 15,
      "z": 1,
      "name": "Plant_Leaves_Autumn"
    },
    {
      "x": 1,
      "y": 15,
      "z": 2,
      "name": "Plant_Leaves_Autumn"
    },
    {
      "x": 1,
      "y": 16,
      "z": 2,
      "name": "Plant_Leaves_Autumn"
    },
    {
      "x": 1,
      "y": 14,
      "z": 3,
      "name": "Plant_Leaves_Autumn"
    },
    {
      "x": 1,
      "y": 15,
      "z": 3,
      "name": "Plant_Leaves_Autumn"
    },
    {
      "x": 1,
      "y": 16,
      "z": 3,
      "name": "Plant_Leaves_Autumn"
    },
    {
      "x": 1,
      "y": 15,
      "z": 4,
      "name": "Plant_Leaves_Autumn"
    },
    {
      "x": 2,
      "y": 15,
      "z": 1,
      "name": "Plant_Leaves_Autumn"
    },
    {
      "x": 2,
      "y": 16,
      "z": 1,
      "name": "Plant_Leaves_Autumn"
    },
    {
      "x": 2,
      "y": 17,
      "z": 1,
      "name": "Plant_Leaves_Autumn"
    },
    {
      "x": 2,
      "y": 14,
      "z": 2,
      "name": "Plant_Leaves_Autumn"
    },
    {
      "x": 2,
      "y": 15,
      "z": 2,
      "name": "Plant_Leaves_Autumn"
    },
    {
      "x": 2,
      "y": 16,
      "z": 2,
      "name": "Plant_Leaves_Autumn"
    },
    {
      "x": 2,
      "y": 17,
      "z": 2,
      "name": "Plant_Leaves_Autumn"
    },
    {
      "x": 2,
      "y": 14,
      "z": 3,
      "name": "Plant_Leaves_Autumn"
    },
    {
      "x": 2,
      "y": 15,
      "z": 3,
      "name": "Wood_Oak_Branch_Long",
      "rotation": 5
    },
    {
      "x": 2,
      "y": 16,
      "z": 3,
      "name": "Plant_Leaves_Autumn"
    },
    {
      "x": 2,
      "y": 17,
      "z": 3,
      "name": "Plant_Leaves_Autumn"
    },
    {
      "x": 2,
      "y": 14,
      "z": 4,
      "name": "Plant_Leaves_Autumn"
    },
    {
      "x": 2,
      "y": 15,
      "z": 4,
      "name": "Plant_Leaves_Autumn"
    },
    {
      "x": 2,
      "y": 16,
      "z": 4,
      "name": "Plant_Leaves_Autumn"
    },
    {
      "x": 2,
      "y": 14,
      "z": 5,
      "name": "Plant_Leaves_Autumn"
    },
    {
      "x": 2,
      "y": 15,
      "z": 5,
      "name": "Plant_Leaves_Autumn"
    },
    {
      "x": 3,
      "y": 14,
      "z": 0,
      "name": "Plant_Leaves_Autumn"
    },
    {
      "x": 3,
      "y": 15,
      "z": 0,
      "name": "Plant_Leaves_Autumn"
    },
    {
      "x": 3,
      "y": 16,
      "z": 0,
      "name": "Plant_Leaves_Autumn"
    },
    {
      "x": 3,
      "y": 17,
      "z": 1,
      "name": "Plant_Leaves_Autumn"
    },
    {
      "x": 3,
      "y": 18,
      "z": 1,
      "name": "Plant_Leaves_Autumn"
    },
    {
      "x": 3,
      "y": 19,
      "z": 1,
      "name": "Plant_Leaves_Autumn"
    },
    {
      "x": 3,
      "y": 17,
      "z": 2,
      "name": "Plant_Leaves_Autumn"
    },
    {
      "x": 3,
      "y": 18,
      "z": 2,
      "name": "Plant_Leaves_Autumn"
    },
    {
      "x": 3,
      "y": 19,
      "z": 2,
      "name": "Plant_Leaves_Autumn"
    },
    {
      "x": 3,
      "y": 20,
      "z": 2,
      "name": "Plant_Leaves_Autumn"
    },
    {
      "x": 3,
      "y": 15,
      "z": 3,
      "name": "Wood_Oak_Branch_Long",
      "rotation": 5
    },
    {
      "x": 3,
      "y": 17,
      "z": 3,
      "name": "Plant_Leaves_Autumn"
    },
    {
      "x": 3,
      "y": 19,
      "z": 3,
      "name": "Plant_Leaves_Autumn"
    },
    {
      "x": 3,
      "y": 17,
      "z": 4,
      "name": "Plant_Leaves_Autumn"
    },
    {
      "x": 3,
      "y": 14,
      "z": 5,
      "name": "Plant_Leaves_Autumn"
    },
    {
      "x": 3,
      "y": 15,
      "z": 5,
      "name": "Plant_Leaves_Autumn"
    },
    {
      "x": 3,
      "y": 16,
      "z": 5,
      "name": "Plant_Leaves_Autumn"
    },
    {
      "x": 3,
      "y": 15,
      "z": 6,
      "name": "Plant_Leaves_Autumn"
    },
    {
      "x": 4,
      "y": 15,
      "z": -1,
      "name": "Plant_Leaves_Autumn"
    },
    {
      "x": 4,
      "y": 16,
      "z": -1,
      "name": "Plant_Leaves_Autumn"
    },
    {
      "x": 4,
      "y": 14,
      "z": 0,
      "name": "Plant_Leaves_Autumn"
    },
    {
      "x": 4,
      "y": 15,
      "z": 0,
      "name": "Wood_Oak_Branch_Corner",
      "rotation": 2
    },
    {
      "x": 4,
      "y": 16,
      "z": 0,
      "name": "Plant_Leaves_Autumn"
    },
    {
      "x": 4,
      "y": 17,
      "z": 0,
      "name": "Plant_Leaves_Autumn"
    },
    {
      "x": 4,
      "y": 19,
      "z": 0,
      "name": "Plant_Leaves_Autumn"
    },
    {
      "x": 4,
      "y": 15,
      "z": 1,
      "name": "Wood_Oak_Branch_Long",
      "rotation": 4
    },
    {
      "x": 4,
      "y": 20,
      "z": 1,
      "name": "Plant_Leaves_Autumn"
    },
    {
      "x": 4,
      "y": 13,
      "z": 2,
      "name": "Wood_Oak_Trunk_Full"
    },
    {
      "x": 4,
      "y": 14,
      "z": 2,
      "name": "Wood_Oak_Trunk"
    },
    {
      "x": 4,
      "y": 15,
      "z": 2,
      "name": "Wood_Oak_Trunk_Full"
    },
    {
      "x": 4,
      "y": 20,
      "z": 2,
      "name": "Plant_Leaves_Autumn"
    },
    {
      "x": 4,
      "y": 15,
      "z": 3,
      "name": "Wood_Oak_Trunk_Full"
    },
    {
      "x": 4,
      "y": 20,
      "z": 3,
      "name": "Plant_Leaves_Autumn"
    },
    {
      "x": 4,
      "y": 6,
      "z": 4,
      "name": "Wood_Oak_Roots"
    },
    {
      "x": 4,
      "y": 7,
      "z": 4,
      "name": "Wood_Oak_Trunk_Full"
    },
    {
      "x": 4,
      "y": 8,
      "z": 4,
      "name": "Wood_Oak_Trunk"
    },
    {
      "x": 4,
      "y": 9,
      "z": 4,
      "name": "Wood_Oak_Trunk"
    },
    {
      "x": 4,
      "y": 10,
      "z": 4,
      "name": "Wood_Oak_Trunk_Full"
    },
    {
      "x": 4,
      "y": 15,
      "z": 4,
      "name": "Wood_Oak_Branch_Long",
      "rotation": 4
    },
    {
      "x": 4,
      "y": 18,
      "z": 4,
      "name": "Plant_Leaves_Autumn"
    },
    {
      "x": 4,
      "y": 19,
      "z": 4,
      "name": "Plant_Leaves_Autumn"
    },
    {
      "x": 4,
      "y": 14,
      "z": 5,
      "name": "Plant_Leaves_Autumn"
    },
    {
      "x": 4,
      "y": 15,
      "z": 5,
      "name": "Wood_Oak_Branch_Long",
      "rotation": 4
    },
    {
      "x": 4,
      "y": 16,
      "z": 5,
      "name": "Plant_Leaves_Autumn"
    },
    {
      "x": 4,
      "y": 14,
      "z": 6,
      "name": "Plant_Leaves_Autumn"
    },
    {
      "x": 4,
      "y": 15,
      "z": 6,
      "name": "Plant_Leaves_Autumn"
    },
    {
      "x": 4,
      "y": 16,
      "z": 6,
      "name": "Plant_Leaves_Autumn"
    },
    {
      "x": 5,
      "y": 15,
      "z": -1,
      "name": "Plant_Leaves_Autumn"
    },
    {
      "x": 5,
      "y": 16,
      "z": -1,
      "name": "Plant_Leaves_Autumn"
    },
    {
      "x": 5,
      "y": 17,
      "z": -1,
      "name": "Plant_Leaves_Autumn"
    },
    {
      "x": 5,
      "y": 19,
      "z": 0,
      "name": "Plant_Leaves_Autumn"
    },
    {
      "x": 5,
      "y": 17,
      "z": 1,
      "name": "Wood_Oak_Trunk_Full"
    },
    {
      "x": 5,
      "y": 19,
      "z": 1,
      "name": "Plant_Leaves_Autumn"
    },
    {
      "x": 5,
      "y": 20,
      "z": 1,
      "name": "Plant_Leaves_Autumn"
    },
    {
      "x": 5,
      "y": 12,
      "z": 2,
      "name": "Wood_Oak_Trunk_Full"
    },
    {
      "x": 5,
      "y": 13,
      "z": 2,
      "name": "Wood_Oak_Trunk"
    },
    {
      "x": 5,
      "y": 14,
      "z": 2,
      "name": "Wood_Oak_Trunk"
    },
    {
      "x": 5,
      "y": 15,
      "z": 2,
      "name": "Wood_Oak_Trunk"
    },
    {
      "x": 5,
      "y": 16,
      "z": 2,
      "name": "Wood_Oak_Trunk"
    },
    {
      "x": 5,
      "y": 17,
      "z": 2,
      "name": "Wood_Oak_Trunk"
    },
    {
      "x": 5,
      "y": 18,
      "z": 2,
      "name": "Wood_Oak_Trunk_Full"
    },
    {
      "x": 5,
      "y": 19,
      "z": 2,
      "name": "Wood_Oak_Branch_Long"
    },
    {
      "x": 5,
      "y": 20,
      "z": 2,
      "name": "Plant_Leaves_Autumn"
    },
    {
      "x": 5,
      "y": 9,
      "z": 3,
      "name": "Wood_Oak_Trunk_Full"
    },
    {
      "x": 5,
      "y": 10,
      "z": 3,
      "name": "Wood_Oak_Trunk"
    },
    {
      "x": 5,
      "y": 11,
      "z": 3,
      "name": "Wood_Oak_Trunk"
    },
    {
      "x": 5,
      "y": 12,
      "z": 3,
      "name": "Wood_Oak_Trunk"
    },
    {
      "x": 5,
      "y": 13,
      "z": 3,
      "name": "Wood_Oak_Trunk"
    },
    {
      "x": 5,
      "y": 14,
      "z": 3,
      "name": "Wood_Oak_Trunk"
    },
    {
      "x": 5,
      "y": 17,
      "z": 3,
      "name": "Wood_Oak_Trunk_Full"
    },
    {
      "x": 5,
      "y": 20,
      "z": 3,
      "name": "Plant_Leaves_Autumn"
    },
    {
      "x": 5,
      "y": 5,
      "z": 4,
      "name": "Wood_Oak_Roots"
    },
    {
      "x": 5,
      "y": 6,
      "z": 4,
      "name": "Wood_Oak_Trunk_Full"
    },
    {
      "x": 5,
      "y": 7,
      "z": 4,
      "name": "Wood_Oak_Trunk"
    },
    {
      "x": 5,
      "y": 8,
      "z": 4,
      "name": "Wood_Oak_Trunk"
    },
    {
      "x": 5,
      "y": 9,
      "z": 4,
      "name": "Wood_Oak_Trunk"
    },
    {
      "x": 5,
      "y": 10,
      "z": 4,
      "name": "Wood_Oak_Trunk"
    },
    {
      "x": 5,
      "y": 11,
      "z": 4,
      "name": "Wood_Oak_Trunk"
    },
    {
      "x": 5,
      "y": 12,
      "z": 4,
      "name": "Wood_Oak_Trunk_Full"
    },
    {
      "x": 5,
      "y": 17,
      "z": 4,
      "name": "Wood_Oak_Branch_Corner"
    },
    {
      "x": 5,
      "y": 18,
      "z": 4,
      "name": "Plant_Leaves_Autumn"
    },
    {
      "x": 5,
      "y": 19,
      "z": 4,
      "name": "Plant_Leaves_Autumn"
    },
    {
      "x": 5,
      "y": 4,
      "z": 5,
      "name": "Wood_Oak_Roots"
    },
    {
      "x": 5,
      "y": 5,
      "z": 5,
      "name": "Wood_Oak_Trunk_Full"
    },
    {
      "x": 5,
      "y": 6,
      "z": 5,
      "name": "Wood_Oak_Trunk"
    },
    {
      "x": 5,
      "y": 7,
      "z": 5,
      "name": "Wood_Oak_Trunk"
    },
    {
      "x": 5,
      "y": 8,
      "z": 5,
      "name": "Wood_Oak_Trunk"
    },
    {
      "x": 5,
      "y": 9,
      "z": 5,
      "name": "Wood_Oak_Trunk_Full"
    },
    {
      "x": 5,
      "y": 13,
      "z": 5,
      "name": "Plant_Leaves_Autumn"
    },
    {
      "x": 5,
      "y": 14,
      "z": 5,
      "name": "Plant_Leaves_Autumn"
    },
    {
      "x": 5,
      "y": 15,
      "z": 5,
      "name": "Plant_Leaves_Autumn"
    },
    {
      "x": 5,
      "y": 17,
      "z": 5,
      "name": "Plant_Leaves_Autumn"
    },
    {
      "x": 5,
      "y": 18,
      "z": 5,
      "name": "Plant_Leaves_Autumn"
    },
    {
      "x": 5,
      "y": 14,
      "z": 6,
      "name": "Plant_Leaves_Autumn"
    },
    {
      "x": 5,
      "y": 15,
      "z": 6,
      "name": "Plant_Leaves_Autumn"
    },
    {
      "x": 6,
      "y": 17,
      "z": -1,
      "name": "Plant_Leaves_Autumn"
    },
    {
      "x": 6,
      "y": 18,
      "z": -1,
      "name": "Plant_Leaves_Autumn"
    },
    {
      "x": 6,
      "y": 15,
      "z": 0,
      "name": "Plant_Leaves_Autumn"
    },
    {
      "x": 6,
      "y": 17,
      "z": 1,
      "name": "Wood_Oak_Trunk_Full"
    },
    {
      "x": 6,
      "y": 19,
      "z": 1,
      "name": "Plant_Leaves_Autumn"
    },
    {
      "x": 6,
      "y": 20,
      "z": 1,
      "name": "Plant_Leaves_Autumn"
    },
    {
      "x": 6,
      "y": 20,
      "z": 2,
      "name": "Plant_Leaves_Autumn"
    },
    {
      "x": 6,
      "y": 14,
      "z": 3,
      "name": "Wood_Oak_Trunk_Full"
    },
    {
      "x": 6,
      "y": 20,
      "z": 3,
      "name": "Plant_Leaves_Autumn"
    },
    {
      "x": 6,
      "y": 14,
      "z": 4,
      "name": "Wood_Oak_Branch_Long",
      "rotation": 4
    },
    {
      "x": 6,
      "y": 17,
      "z": 4,
      "name": "Plant_Leaves_Autumn"
    },
    {
      "x": 6,
      "y": 18,
      "z": 4,
      "name": "Plant_Leaves_Autumn"
    },
    {
      "x": 6,
      "y": 19,
      "z": 4,
      "name": "Plant_Leaves_Autumn"
    },
    {
      "x": 6,
      "y": 13,
      "z": 5,
      "name": "Plant_Leaves_Autumn"
    },
    {
      "x": 6,
      "y": 14,
      "z": 5,
      "name": "Wood_Oak_Branch_Long",
      "rotation": 4
    },
    {
      "x": 6,
      "y": 15,
      "z": 5,
      "name": "Plant_Leaves_Autumn"
    },
    {
      "x": 6,
      "y": 17,
      "z": 5,
      "name": "Plant_Leaves_Autumn"
    },
    {
      "x": 6,
      "y": 13,
      "z": 6,
      "name": "Plant_Leaves_Autumn"
    },
    {
      "x": 6,
      "y": 14,
      "z": 6,
      "name": "Plant_Leaves_Autumn"
    },
    {
      "x": 6,
      "y": 15,
      "z": 6,
      "name": "Plant_Leaves_Autumn"
    },
    {
      "x": 7,
      "y": 16,
      "z": -1,
      "name": "Plant_Leaves_Autumn"
    },
    {
      "x": 7,
      "y": 17,
      "z": -1,
      "name": "Plant_Leaves_Autumn"
    },
    {
      "x": 7,
      "y": 18,
      "z": -1,
      "name": "Plant_Leaves_Autumn"
    },
    {
      "x": 7,
      "y": 15,
      "z": 0,
      "name": "Plant_Leaves_Autumn"
    },
    {
      "x": 7,
      "y": 16,
      "z": 0,
      "name": "Plant_Leaves_Autumn"
    },
    {
      "x": 7,
      "y": 17,
      "z": 0,
      "name": "Wood_Oak_Branch_Long",
      "rotation": 4
    },
    {
      "x": 7,
      "y": 18,
      "z": 0,
      "name": "Plant_Leaves_Autumn"
    },
    {
      "x": 7,
      "y": 17,
      "z": 1,
      "name": "Wood_Oak_Trunk_Full"
    },
    {
      "x": 7,
      "y": 19,
      "z": 1,
      "name": "Plant_Leaves_Autumn"
    },
    {
      "x": 7,
      "y": 20,
      "z": 2,
      "name": "Plant_Leaves_Autumn"
    },
    {
      "x": 7,
      "y": 14,
      "z": 3,
      "name": "Wood_Oak_Branch_Long",
      "rotation": 5
    },
    {
      "x": 7,
      "y": 16,
      "z": 4,
      "name": "Plant_Leaves_Autumn"
    },
    {
      "x": 7,
      "y": 17,
      "z": 4,
      "name": "Plant_Leaves_Autumn"
    },
    {
      "x": 7,
      "y": 13,
      "z": 5,
      "name": "Plant_Leaves_Autumn"
    },
    {
      "x": 7,
      "y": 14,
      "z": 5,
      "name": "Plant_Leaves_Autumn"
    },
    {
      "x": 7,
      "y": 15,
      "z": 5,
      "name": "Plant_Leaves_Autumn"
    },
    {
      "x": 7,
      "y": 14,
      "z": 6,
      "name": "Plant_Leaves_Autumn"
    },
    {
      "x": 8,
      "y": 17,
      "z": -1,
      "name": "Plant_Leaves_Autumn"
    },
    {
      "x": 8,
      "y": 15,
      "z": 0,
      "name": "Plant_Leaves_Autumn"
    },
    {
      "x": 8,
      "y": 16,
      "z": 0,
      "name": "Plant_Leaves_Autumn"
    },
    {
      "x": 8,
      "y": 17,
      "z": 0,
      "name": "Plant_Leaves_Autumn"
    },
    {
      "x": 8,
      "y": 18,
      "z": 0,
      "name": "Plant_Leaves_Autumn"
    },
    {
      "x": 8,
      "y": 16,
      "z": 1,
      "name": "Plant_Leaves_Autumn"
    },
    {
      "x": 8,
      "y": 17,
      "z": 1,
      "name": "Wood_Oak_Branch_Corner",
      "rotation": 1
    },
    {
      "x": 8,
      "y": 18,
      "z": 1,
      "name": "Plant_Leaves_Autumn"
    },
    {
      "x": 8,
      "y": 14,
      "z": 2,
      "name": "Plant_Leaves_Autumn"
    },
    {
      "x": 8,
      "y": 17,
      "z": 2,
      "name": "Plant_Leaves_Autumn"
    },
    {
      "x": 8,
      "y": 18,
      "z": 2,
      "name": "Plant_Leaves_Autumn"
    },
    {
      "x": 8,
      "y": 19,
      "z": 2,
      "name": "Plant_Leaves_Autumn"
    },
    {
      "x": 8,
      "y": 13,
      "z": 3,
      "name": "Plant_Leaves_Autumn"
    },
    {
      "x": 8,
      "y": 14,
      "z": 3,
      "name": "Wood_Oak_Branch_Long",
      "rotation": 5
    },
    {
      "x": 8,
      "y": 15,
      "z": 3,
      "name": "Plant_Leaves_Autumn"
    },
    {
      "x": 8,
      "y": 17,
      "z": 3,
      "name": "Plant_Leaves_Autumn"
    },
    {
      "x": 8,
      "y": 18,
      "z": 3,
      "name": "Plant_Leaves_Autumn"
    },
    {
      "x": 8,
      "y": 19,
      "z": 3,
      "name": "Plant_Leaves_Autumn"
    },
    {
      "x": 8,
      "y": 13,
      "z": 4,
      "name": "Plant_Leaves_Autumn"
    },
    {
      "x": 8,
      "y": 14,
      "z": 4,
      "name": "Plant_Leaves_Autumn"
    },
    {
      "x": 8,
      "y": 15,
      "z": 4,
      "name": "Plant_Leaves_Autumn"
    },
    {
      "x": 8,
      "y": 13,
      "z": 5,
      "name": "Plant_Leaves_Autumn"
    },
    {
      "x": 8,
      "y": 14,
      "z": 5,
      "name": "Plant_Leaves_Autumn"
    },
    {
      "x": 9,
      "y": 17,
      "z": 0,
      "name": "Plant_Leaves_Autumn"
    },
    {
      "x": 9,
      "y": 15,
      "z": 1,
      "name": "Plant_Leaves_Autumn"
    },
    {
      "x": 9,
      "y": 16,
      "z": 1,
      "name": "Plant_Leaves_Autumn"
    },
    {
      "x": 9,
      "y": 17,
      "z": 1,
      "name": "Plant_Leaves_Autumn"
    },
    {
      "x": 9,
      "y": 18,
      "z": 1,
      "name": "Plant_Leaves_Autumn"
    },
    {
      "x": 9,
      "y": 16,
      "z": 2,
      "name": "Plant_Leaves_Autumn"
    },
    {
      "x": 9,
      "y": 17,
      "z": 2,
      "name": "Plant_Leaves_Autumn"
    },
    {
      "x": 9,
      "y": 18,
      "z": 2,
      "name": "Plant_Leaves_Autumn"
    },
    {
      "x": 9,
      "y": 14,
      "z": 3,
      "name": "Plant_Leaves_Autumn"
    },
    {
      "x": 9,
      "y": 15,
      "z": 3,
      "name": "Plant_Leaves_Autumn"
    },
    {
      "x": 9,
      "y": 14,
      "z": 4,
      "name": "Plant_Leaves_Autumn"
    }
  ]
}