{
  "version": 8,
  "blockIdVersion": 8,
  "anchorX": 0,
  "anchorY": 0,
  "anchorZ": 0,
  "blocks": [
    {
      "x": -13,
      "y": -8,
      "z": 1,
      "name": "Wood_Fig_Blue_Trunk_Full"
    },
    {
      "x": -13,
      "y": -8,
      "z": 2,
      "name": "Wood_Fig_Blue_Trunk_Full"
    },
    {
      "x": -13,
      "y": -7,
      "z": 2,
      "name": "Wood_Fig_Blue_Trunk"
    },
    {
      "x": -13,
      "y": -6,
      "z": 2,
      "name": "Wood_Fig_Blue_Trunk_Full"
    },
    {
      "x": -12,
      "y": -8,
      "z": 1,
      "name": "Wood_Fig_Blue_Trunk_Full"
    },
    {
      "x": -12,
      "y": -7,
      "z": 1,
      "name": "Wood_Fig_Blue_Trunk"
    },
    {
      "x": -12,
      "y": -6,
      "z": 1,
      "name": "Wood_Fig_Blue_Trunk"
    },
    {
      "x": -12,
      "y": -5,
      "z": 1,
      "name": "Wood_Fig_Blue_Trunk_Full"
    },
    {
      "x": -12,
      "y": -8,
      "z": 2,
      "name": "Wood_Fig_Blue_Trunk_Full"
    },
    {
      "x": -12,
      "y": -7,
      "z": 2,
      "name": "Wood_Fig_Blue_Trunk"
    },
    {
      "x": -12,
      "y": -6,
      "z": 2,
      "name": "Wood_Fig_Blue_Trunk"
    },
    {
      "x": -12,
      "y": -5,
      "z": 2,
      "name": "Wood_Fig_Blue_Trunk"
    },
    {
      "x": -12,
      "y": -4,
      "z": 2,
      "name": "Wood_Fig_Blue_Trunk"
    },
    {
      "x": -12,
      "y": -3,
      "z": 2,
      "name": "Wood_Fig_Blue_Trunk_Full"
    },
    {
      "x": -12,
      "y": -6,
      "z": 3,
      "name": "Wood_Fig_Blue_Trunk_Full"
    },
    {
      "x": -12,
      "y": -5,
      "z": 3,
      "name": "Wood_Fig_Blue_Trunk"
    },
    {
      "x": -12,
      "y": -4,
      "z": 3,
      "name": "Wood_Fig_Blue_Trunk"
    },
    {
      "x": -12,
      "y": -3,
      "z": 3,
      "name": "Wood_Fig_Blue_Trunk_Full"
    },
    {
      "x": -11,
      "y": -8,
      "z": 1,
      "name": "Wood_Fig_Blue_Trunk_Full"
    },
    {
      "x": -11,
      "y": -7,
      "z": 1,
      "name": "Wood_Fig_Blue_Trunk"
    },
    {
      "x": -11,
      "y": -6,
      "z": 1,
      "name": "Wood_Fig_Blue_Trunk"
    },
    {
      "x": -11,
      "y": -5,
      "z": 1,
      "name": "Wood_Fig_Blue_Trunk"
    },
    {
      "x": -11,
      "y": -4,
      "z": 1,
      "name": "Wood_Fig_Blue_Trunk"
    },
    {
      "x": -11,
      "y": -3,
      "z": 1,
      "name": "Wood_Fig_Blue_Trunk"
    },
    {
      "x": -11,
      "y": -2,
      "z": 1,
      "name": "Wood_Fig_Blue_Trunk_Full"
    },
    {
      "x": -11,
      "y": -8,
      "z": 2,
      "name": "Wood_Fig_Blue_Trunk_Full"
    },
    {
      "x": -11,
      "y": -7,
      "z": 2,
      "name": "Wood_Fig_Blue_Trunk"
    },
    {
      "x": -11,
      "y": -6,
      "z": 2,
      "name": "Wood_Fig_Blue_Trunk"
    },
    {
      "x": -11,
      "y": -5,
      "z": 2,
      "name": "Wood_Fig_Blue_Trunk"
    },
    {
      "x": -11,
      "y": -4,
      "z": 2,
      "name": "Wood_Fig_Blue_Trunk"
    },
    {
      "x": -11,
      "y": -3,
      "z": 2,
      "name": "Wood_Fig_Blue_Trunk"
    },
    {
      "x": -11,
      "y": -2,
      "z": 2,
      "name": "Wood_Fig_Blue_Trunk"
    },
    {
      "x": -11,
      "y": -1,
      "z": 2,
      "name": "Wood_Fig_Blue_Trunk_Full"
    },
    {
      "x": -11,
      "y": -8,
      "z": 3,
      "name": "Wood_Fig_Blue_Trunk_Full"
    },
    {
      "x": -11,
      "y": -7,
      "z": 3,
      "name": "Wood_Fig_Blue_Trunk"
    },
    {
      "x": -11,
      "y": -6,
      "z": 3,
      "name": "Wood_Fig_Blue_Trunk"
    },
    {
      "x": -11,
      "y": -5,
      "z": 3,
      "name": "Wood_Fig_Blue_Trunk"
    },
    {
      "x": -11,
      "y": -4,
      "z": 3,
      "name": "Wood_Fig_Blue_Trunk"
    },
    {
      "x": -11,
      "y": -3,
      "z": 3,
      "name": "Wood_Fig_Blue_Trunk"
    },
    {
      "x": -11,
      "y": -2,
      "z": 3,
      "name": "Wood_Fig_Blue_Trunk"
    },
    {
      "x": -11,
      "y": -1,
      "z": 3,
      "name": "Wood_Fig_Blue_Trunk_Full"
    },
    {
      "x": -11,
      "y": -4,
      "z": 4,
      "name": "Wood_Fig_Blue_Trunk_Full"
    },
    {
      "x": -11,
      "y": -3,
      "z": 4,
      "name": "Wood_Fig_Blue_Trunk"
    },
    {
      "x": -11,
      "y": -2,
      "z": 4,
      "name": "Wood_Fig_Blue_Trunk_Full"
    },
    {
      "x": -11,
      "y": -6,
      "z": 8,
      "name": "Wood_Fig_Blue_Trunk_Full"
    },
    {
      "x": -11,
      "y": -5,
      "z": 8,
      "name": "Wood_Fig_Blue_Trunk"
    },
    {
      "x": -11,
      "y": -4,
      "z": 8,
      "name": "Wood_Fig_Blue_Trunk_Full"
    },
    {
      "x": -11,
      "y": -8,
      "z": 9,
      "name": "Wood_Fig_Blue_Trunk_Full"
    },
    {
      "x": -11,
      "y": -7,
      "z": 9,
      "name": "Wood_Fig_Blue_Trunk"
    },
    {
      "x": -11,
      "y": -6,
      "z": 9,
      "name": "Wood_Fig_Blue_Trunk_Full"
    },
    {
      "x": -11,
      "y": -10,
      "z": 10,
      "name": "Wood_Fig_Blue_Trunk_Full"
    },
    {
      "x": -11,
      "y": -9,
      "z": 10,
      "name": "Wood_Fig_Blue_Trunk"
    },
    {
      "x": -11,
      "y": -8,
      "z": 10,
      "name": "Wood_Fig_Blue_Trunk_Full"
    },
    {
      "x": -11,
      "y": -10,
      "z": 11,
      "name": "Wood_Fig_Blue_Trunk_Full"
    },
    {
      "x": -10,
      "y": -5,
      "z": 1,
      "name": "Wood_Fig_Blue_Trunk_Full"
    },
    {
      "x": -10,
      "y": -4,
      "z": 1,
      "name": "Wood_Fig_Blue_Trunk"
    },
    {
      "x": -10,
      "y": -3,
      "z": 1,
      "name": "Wood_Fig_Blue_Trunk"
    },
    {
      "x": -10,
      "y": -2,
      "z": 1,
      "name": "Wood_Fig_Blue_Trunk_Full"
    },
    {
      "x": -10,
      "y": -7,
      "z": 2,
      "name": "Wood_Fig_Blue_Trunk_Full"
    },
    {
      "x": -10,
      "y": -6,
      "z": 2,
      "name": "Wood_Fig_Blue_Trunk"
    },
    {
      "x": -10,
      "y": -5,
      "z": 2,
      "name": "Wood_Fig_Blue_Trunk"
    },
    {
      "x": -10,
      "y": -4,
      "z": 2,
      "name": "Wood_Fig_Blue_Trunk"
    },
    {
      "x": -10,
      "y": -3,
      "z": 2,
      "name": "Wood_Fig_Blue_Trunk"
    },
    {
      "x": -10,
      "y": -2,
      "z": 2,
      "name": "Wood_Fig_Blue_Trunk"
    },
    {
      "x": -10,
      "y": -1,
      "z": 2,
      "name": "Wood_Fig_Blue_Trunk"
    },
    {
      "x": -10,
      "y": 0,
      "z": 2,
      "name": "Wood_Fig_Blue_Trunk_Full"
    },
    {
      "x": -10,
      "y": -6,
      "z": 3,
      "name": "Wood_Fig_Blue_Trunk_Full"
    },
    {
      "x": -10,
      "y": -5,
      "z": 3,
      "name": "Wood_Fig_Blue_Trunk"
    },
    {
      "x": -10,
      "y": -4,
      "z": 3,
      "name": "Wood_Fig_Blue_Trunk"
    },
    {
      "x": -10,
      "y": -3,
      "z": 3,
      "name": "Wood_Fig_Blue_Trunk"
    },
    {
      "x": -10,
      "y": -2,
      "z": 3,
      "name": "Wood_Fig_Blue_Trunk"
    },
    {
      "x": -10,
      "y": -1,
      "z": 3,
      "name": "Wood_Fig_Blue_Trunk"
    },
    {
      "x": -10,
      "y": 0,
      "z": 3,
      "name": "Wood_Fig_Blue_Trunk_Full"
    },
    {
      "x": -10,
      "y": -4,
      "z": 4,
      "name": "Wood_Fig_Blue_Trunk_Full"
    },
    {
      "x": -10,
      "y": -3,
      "z": 4,
      "name": "Wood_Fig_Blue_Trunk"
    },
    {
      "x": -10,
      "y": -2,
      "z": 4,
      "name": "Wood_Fig_Blue_Trunk"
    },
    {
      "x": -10,
      "y": -1,
      "z": 4,
      "name": "Wood_Fig_Blue_Trunk_Full"
    },
    {
      "x": -10,
      "y": -8,
      "z": 8,
      "name": "Wood_Fig_Blue_Trunk_Full"
    },
    {
      "x": -10,
      "y": -7,
      "z": 8,
      "name": "Wood_Fig_Blue_Trunk"
    },
    {
      "x": -10,
      "y": -6,
      "z": 8,
      "name": "Wood_Fig_Blue_Trunk"
    },
    {
      "x": -10,
      "y": -5,
      "z": 8,
      "name": "Wood_Fig_Blue_Trunk"
    },
    {
      "x": -10,
      "y": -4,
      "z": 8,
      "name": "Wood_Fig_Blue_Trunk"
    },
    {
      "x": -10,
      "y": -3,
      "z": 8,
      "name": "Wood_Fig_Blue_Trunk_Full"
    },
    {
      "x": -10,
      "y": -10,
      "z": 9,
      "name": "Wood_Fig_Blue_Trunk_Full"
    },
    {
      "x": -10,
      "y": -9,
      "z": 9,
      "name": "Wood_Fig_Blue_Trunk"
    },
    {
      "x": -10,
      "y": -8,
      "z": 9,
      "name": "Wood_Fig_Blue_Trunk"
    },
    {
      "x": -10,
      "y": -7,
      "z": 9,
      "name": "Wood_Fig_Blue_Trunk"
    },
    {
      "x": -10,
      "y": -6,
      "z": 9,
      "name": "Wood_Fig_Blue_Trunk"
    },
    {
      "x": -10,
      "y": -5,
      "z": 9,
      "name": "Wood_Fig_Blue_Trunk"
    },
    {
      "x": -10,
      "y": -4,
      "z": 9,
      "name": "Wood_Fig_Blue_Trunk"
    },
    {
      "x": -10,
      "y": -3,
      "z": 9,
      "name": "Wood_Fig_Blue_Trunk_Full"
    },
    {
      "x": -10,
      "y": -10,
      "z": 10,
      "name": "Wood_Fig_Blue_Trunk_Full"
    },
    {
      "x": -10,
      "y": -9,
      "z": 10,
      "name": "Wood_Fig_Blue_Trunk"
    },
    {
      "x": -10,
      "y": -8,
      "z": 10,
      "name": "Wood_Fig_Blue_Trunk"
    },
    {
      "x": -10,
      "y": -7,
      "z": 10,
      "name": "Wood_Fig_Blue_Trunk"
    },
    {
      "x": -10,
      "y": -6,
      "z": 10,
      "name": "Wood_Fig_Blue_Trunk_Full"
    },
    {
      "x": -10,
      "y": -10,
      "z": 11,
      "name": "Wood_Fig_Blue_Trunk_Full"
    },
    {
      "x": -10,
      "y": -9,
      "z": 11,
      "name": "Wood_Fig_Blue_Trunk"
    },
    {
      "x": -10,
      "y": -8,
      "z": 11,
      "name": "Wood_Fig_Blue_Trunk_Full"
    },
    {
      "x": -9,
      "y": -6,
      "z": -5,
      "name": "Wood_Fig_Blue_Trunk_Full"
    },
    {
      "x": -9,
      "y": -5,
      "z": -5,
      "name": "Wood_Fig_Blue_Trunk_Full"
    },
    {
      "x": -9,
      "y": 0,
      "z": -1,
      "name": "Wood_Fig_Blue_Trunk_Full"
    },
    {
      "x": -9,
      "y": 1,
      "z": -1,
      "name": "Wood_Fig_Blue_Trunk"
    },
    {
      "x": -9,
      "y": 2,
      "z": -1,
      "name": "Wood_Fig_Blue_Trunk_Full"
    },
    {
      "x": -9,
      "y": -1,
      "z": 0,
      "name": "Wood_Fig_Blue_Trunk_Full"
    },
    {
      "x": -9,
      "y": 0,
      "z": 0,
      "name": "Wood_Fig_Blue_Trunk"
    },
    {
      "x": -9,
      "y": 1,
      "z": 0,
      "name": "Wood_Fig_Blue_Trunk"
    },
    {
      "x": -9,
      "y": 2,
      "z": 0,
      "name": "Wood_Fig_Blue_Trunk_Full"
    },
    {
      "x": -9,
      "y": 4,
      "z": 0,
      "name": "Plant_Moss_Wall_Red",
      "rotation": 3
    },
    {
      "x": -9,
      "y": -4,
      "z": 1,
      "name": "Wood_Fig_Blue_Trunk_Full"
    },
    {
      "x": -9,
      "y": -3,
      "z": 1,
      "name": "Wood_Fig_Blue_Trunk"
    },
    {
      "x": -9,
      "y": -2,
      "z": 1,
      "name": "Wood_Fig_Blue_Trunk"
    },
    {
      "x": -9,
      "y": -1,
      "z": 1,
      "name": "Wood_Fig_Blue_Trunk"
    },
    {
      "x": -9,
      "y": 0,
      "z": 1,
      "name": "Wood_Fig_Blue_Trunk"
    },
    {
      "x": -9,
      "y": 1,
      "z": 1,
      "name": "Wood_Fig_Blue_Trunk"
    },
    {
      "x": -9,
      "y": 2,
      "z": 1,
      "name": "Wood_Fig_Blue_Trunk_Full"
    },
    {
      "x": -9,
      "y": 11,
      "z": 1,
      "name": "Plant_Crop_Mushroom_Block_White"
    },
    {
      "x": -9,
      "y": -5,
      "z": 2,
      "name": "Wood_Fig_Blue_Trunk_Full"
    },
    {
      "x": -9,
      "y": -4,
      "z": 2,
      "name": "Wood_Fig_Blue_Trunk"
    },
    {
      "x": -9,
      "y": -3,
      "z": 2,
      "name": "Wood_Fig_Blue_Trunk"
    },
    {
      "x": -9,
      "y": -2,
      "z": 2,
      "name": "Wood_Fig_Blue_Trunk"
    },
    {
      "x": -9,
      "y": -1,
      "z": 2,
      "name": "Wood_Fig_Blue_Trunk"
    },
    {
      "x": -9,
      "y": 0,
      "z": 2,
      "name": "Wood_Fig_Blue_Trunk"
    },
    {
      "x": -9,
      "y": 1,
      "z": 2,
      "name": "Wood_Fig_Blue_Trunk_Full"
    },
    {
      "x": -9,
      "y": 11,
      "z": 2,
      "name": "Plant_Crop_Mushroom_Block_White"
    },
    {
      "x": -9,
      "y": -5,
      "z": 3,
      "name": "Wood_Fig_Blue_Trunk_Full"
    },
    {
      "x": -9,
      "y": -4,
      "z": 3,
      "name": "Wood_Fig_Blue_Trunk"
    },
    {
      "x": -9,
      "y": -3,
      "z": 3,
      "name": "Wood_Fig_Blue_Trunk"
    },
    {
      "x": -9,
      "y": -2,
      "z": 3,
      "name": "Wood_Fig_Blue_Trunk"
    },
    {
      "x": -9,
      "y": -1,
      "z": 3,
      "name": "Wood_Fig_Blue_Trunk"
    },
    {
      "x": -9,
      "y": 0,
      "z": 3,
      "name": "Wood_Fig_Blue_Trunk"
    },
    {
      "x": -9,
      "y": 1,
      "z": 3,
      "name": "Plant_Moss_Block_Red"
    },
    {
      "x": -9,
      "y": 11,
      "z": 3,
      "name": "Plant_Crop_Mushroom_Block_White"
    },
    {
      "x": -9,
      "y": -4,
      "z": 4,
      "name": "Wood_Fig_Blue_Trunk_Full"
    },
    {
      "x": -9,
      "y": -3,
      "z": 4,
      "name": "Wood_Fig_Blue_Trunk"
    },
    {
      "x": -9,
      "y": -2,
      "z": 4,
      "name": "Wood_Fig_Blue_Trunk"
    },
    {
      "x": -9,
      "y": -1,
      "z": 4,
      "name": "Wood_Fig_Blue_Trunk"
    },
    {
      "x": -9,
      "y": 0,
      "z": 4,
      "name": "Wood_Fig_Blue_Trunk_Full"
    },
    {
      "x": -9,
      "y": -2,
      "z": 5,
      "name": "Wood_Fig_Blue_Trunk_Full"
    },
    {
      "x": -9,
      "y": -1,
      "z": 5,
      "name": "Wood_Fig_Blue_Trunk"
    },
    {
      "x": -9,
      "y": 0,
      "z": 5,
      "name": "Wood_Fig_Blue_Trunk_Full"
    },
    {
      "x": -9,
      "y": 7,
      "z": 5,
      "name": "Plant_Crop_Mushroom_Block_Red"
    },
    {
      "x": -9,
      "y": 7,
      "z": 6,
      "name": "Plant_Crop_Mushroom_Block_Red"
    },
    {
      "x": -9,
      "y": -6,
      "z": 7,
      "name": "Wood_Fig_Blue_Trunk_Full"
    },
    {
      "x": -9,
      "y": -5,
      "z": 7,
      "name": "Wood_Fig_Blue_Trunk"
    },
    {
      "x": -9,
      "y": -4,
      "z": 7,
      "name": "Wood_Fig_Blue_Trunk"
    },
    {
      "x": -9,
      "y": -3,
      "z": 7,
      "name": "Wood_Fig_Blue_Trunk_Full"
    },
    {
      "x": -9,
      "y": 7,
      "z": 7,
      "name": "Plant_Crop_Mushroom_Block_Red"
    },
    {
      "x": -9,
      "y": -8,
      "z": 8,
      "name": "Wood_Fig_Blue_Trunk_Full"
    },
    {
      "x": -9,
      "y": -7,
      "z": 8,
      "name": "Wood_Fig_Blue_Trunk"
    },
    {
      "x": -9,
      "y": -6,
      "z": 8,
      "name": "Wood_Fig_Blue_Trunk"
    },
    {
      "x": -9,
      "y": -5,
      "z": 8,
      "name": "Wood_Fig_Blue_Trunk"
    },
    {
      "x": -9,
      "y": -4,
      "z": 8,
      "name": "Wood_Fig_Blue_Trunk"
    },
    {
      "x": -9,
      "y": -3,
      "z": 8,
      "name": "Wood_Fig_Blue_Trunk"
    },
    {
      "x": -9,
      "y": -2,
      "z": 8,
      "name": "Wood_Fig_Blue_Trunk_Full"
    },
    {
      "x": -9,
      "y": 7,
      "z": 8,
      "name": "Plant_Crop_Mushroom_Block_Red"
    },
    {
      "x": -9,
      "y": -9,
      "z": 9,
      "name": "Wood_Fig_Blue_Trunk_Full"
    },
    {
      "x": -9,
      "y": -8,
      "z": 9,
      "name": "Wood_Fig_Blue_Trunk"
    },
    {
      "x": -9,
      "y": -7,
      "z": 9,
      "name": "Wood_Fig_Blue_Trunk"
    },
    {
      "x": -9,
      "y": -6,
      "z": 9,
      "name": "Wood_Fig_Blue_Trunk"
    },
    {
      "x": -9,
      "y": -5,
      "z": 9,
      "name": "Wood_Fig_Blue_Trunk"
    },
    {
      "x": -9,
      "y": -4,
      "z": 9,
      "name": "Wood_Fig_Blue_Trunk"
    },
    {
      "x": -9,
      "y": -3,
      "z": 9,
      "name": "Wood_Fig_Blue_Trunk"
    },
    {
      "x": -9,
      "y": -2,
      "z": 9,
      "name": "Wood_Fig_Blue_Trunk"
    },
    {
      "x": -9,
      "y": -1,
      "z": 9,
      "name": "Wood_Fig_Blue_Trunk_Full"
    },
    {
      "x": -9,
      "y": -9,
      "z": 10,
      "name": "Wood_Fig_Blue_Trunk_Full"
    },
    {
      "x": -9,
      "y": -8,
      "z": 10,
      "name": "Wood_Fig_Blue_Trunk"
    },
    {
      "x": -9,
      "y": -7,
      "z": 10,
      "name": "Wood_Fig_Blue_Trunk"
    },
    {
      "x": -9,
      "y": -6,
      "z": 10,
      "name": "Wood_Fig_Blue_Trunk"
    },
    {
      "x": -9,
      "y": -5,
      "z": 10,
      "name": "Wood_Fig_Blue_Trunk"
    },
    {
      "x": -9,
      "y": -4,
      "z": 10,
      "name": "Wood_Fig_Blue_Trunk"
    },
    {
      "x": -9,
      "y": -3,
      "z": 10,
      "name": "Wood_Fig_Blue_Trunk"
    },
    {
      "x": -9,
      "y": -2,
      "z": 10,
      "name": "Wood_Fig_Blue_Trunk_Full"
    },
    {
      "x": -8,
      "y": -6,
      "z": -6,
      "name": "Wood_Fig_Blue_Trunk_Full"
    },
    {
      "x": -8,
      "y": -5,
      "z": -6,
      "name": "Wood_Fig_Blue_Trunk_Full"
    },
    {
      "x": -8,
      "y": -7,
      "z": -5,
      "name": "Wood_Fig_Blue_Trunk_Full"
    },
    {
      "x": -8,
      "y": -6,
      "z": -5,
      "name": "Wood_Fig_Blue_Trunk"
    },
    {
      "x": -8,
      "y": -5,
      "z": -5,
      "name": "Wood_Fig_Blue_Trunk"
    },
    {
      "x": -8,
      "y": -4,
      "z": -5,
      "name": "Wood_Fig_Blue_Trunk_Full"
    },
    {
      "x": -8,
      "y": -6,
      "z": -4,
      "name": "Wood_Fig_Blue_Trunk_Full"
    },
    {
      "x": -8,
      "y": -5,
      "z": -4,
      "name": "Wood_Fig_Blue_Trunk"
    },
    {
      "x": -8,
      "y": -4,
      "z": -4,
      "name": "Wood_Fig_Blue_Trunk"
    },
    {
      "x": -8,
      "y": -3,
      "z": -4,
      "name": "Wood_Fig_Blue_Trunk"
    },
    {
      "x": -8,
      "y": -2,
      "z": -4,
      "name": "Wood_Fig_Blue_Trunk"
    },
    {
      "x": -8,
      "y": -1,
      "z": -4,
      "name": "Wood_Fig_Blue_Trunk_Full"
    },
    {
      "x": -8,
      "y": -3,
      "z": -3,
      "name": "Wood_Fig_Blue_Trunk_Full"
    },
    {
      "x": -8,
      "y": -2,
      "z": -3,
      "name": "Wood_Fig_Blue_Trunk"
    },
    {
      "x": -8,
      "y": -1,
      "z": -3,
      "name": "Wood_Fig_Blue_Trunk"
    },
    {
      "x": -8,
      "y": 0,
      "z": -3,
      "name": "Wood_Fig_Blue_Trunk"
    },
    {
      "x": -8,
      "y": 1,
      "z": -3,
      "name": "Wood_Fig_Blue_Trunk_Full"
    },
    {
      "x": -8,
      "y": -2,
      "z": -2,
      "name": "Wood_Fig_Blue_Trunk_Full"
    },
    {
      "x": -8,
      "y": -1,
      "z": -2,
      "name": "Wood_Fig_Blue_Trunk"
    },
    {
      "x": -8,
      "y": 0,
      "z": -2,
      "name": "Wood_Fig_Blue_Trunk"
    },
    {
      "x": -8,
      "y": 1,
      "z": -2,
      "name": "Wood_Fig_Blue_Trunk"
    },
    {
      "x": -8,
      "y": 2,
      "z": -2,
      "name": "Wood_Fig_Blue_Trunk"
    },
    {
      "x": -8,
      "y": 3,
      "z": -2,
      "name": "Wood_Fig_Blue_Trunk_Full"
    },
    {
      "x": -8,
      "y": -1,
      "z": -1,
      "name": "Wood_Fig_Blue_Trunk_Full"
    },
    {
      "x": -8,
      "y": 0,
      "z": -1,
      "name": "Wood_Fig_Blue_Trunk"
    },
    {
      "x": -8,
      "y": 1,
      "z": -1,
      "name": "Wood_Fig_Blue_Trunk"
    },
    {
      "x": -8,
      "y": 2,
      "z": -1,
      "name": "Wood_Fig_Blue_Trunk"
    },
    {
      "x": -8,
      "y": 3,
      "z": -1,
      "name": "Wood_Fig_Blue_Trunk"
    },
    {
      "x": -8,
      "y": 4,
      "z": -1,
      "name": "Plant_Moss_Block_Red"
    },
    {
      "x": -8,
      "y": -1,
      "z": 0,
      "name": "Wood_Fig_Blue_Trunk_Full"
    },
    {
      "x": -8,
      "y": 0,
      "z": 0,
      "name": "Wood_Fig_Blue_Trunk"
    },
    {
      "x": -8,
      "y": 1,
      "z": 0,
      "name": "Wood_Fig_Blue_Trunk"
    },
    {
      "x": -8,
      "y": 2,
      "z": 0,
      "name": "Wood_Fig_Blue_Trunk"
    },
    {
      "x": -8,
      "y": 3,
      "z": 0,
      "name": "Plant_Moss_Block_Red"
    },
    {
      "x": -8,
      "y": 4,
      "z": 0,
      "name": "Plant_Moss_Block_Red"
    },
    {
      "x": -8,
      "y": 5,
      "z": 0,
      "name": "Plant_Moss_Red"
    },
    {
      "x": -8,
      "y": 10,
      "z": 0,
      "name": "Plant_Crop_Mushroom_Block_Red_Mycelium"
    },
    {
      "x": -8,
      "y": 11,
      "z": 0,
      "name": "Plant_Crop_Mushroom_Block_White"
    },
    {
      "x": -8,
      "y": -2,
      "z": 1,
      "name": "Wood_Fig_Blue_Trunk_Full"
    },
    {
      "x": -8,
      "y": -1,
      "z": 1,
      "name": "Wood_Fig_Blue_Trunk"
    },
    {
      "x": -8,
      "y": 0,
      "z": 1,
      "name": "Wood_Fig_Blue_Trunk"
    },
    {
      "x": -8,
      "y": 1,
      "z": 1,
      "name": "Wood_Fig_Blue_Trunk"
    },
    {
      "x": -8,
      "y": 2,
      "z": 1,
      "name": "Wood_Fig_Blue_Trunk"
    },
    {
      "x": -8,
      "y": 3,
      "z": 1,
      "name": "Plant_Moss_Block_Red"
    },
    {
      "x": -8,
      "y": 4,
      "z": 1,
      "name": "Plant_Moss_Rug_Red"
    },
    {
      "x": -8,
      "y": 11,
      "z": 1,
      "name": "Plant_Crop_Mushroom_Block_White"
    },
    {
      "x": -8,
      "y": -4,
      "z": 2,
      "name": "Wood_Fig_Blue_Trunk_Full"
    },
    {
      "x": -8,
      "y": -3,
      "z": 2,
      "name": "Wood_Fig_Blue_Trunk"
    },
    {
      "x": -8,
      "y": -2,
      "z": 2,
      "name": "Wood_Fig_Blue_Trunk"
    },
    {
      "x": -8,
      "y": -1,
      "z": 2,
      "name": "Wood_Fig_Blue_Trunk"
    },
    {
      "x": -8,
      "y": 0,
      "z": 2,
      "name": "Wood_Fig_Blue_Trunk"
    },
    {
      "x": -8,
      "y": 1,
      "z": 2,
      "name": "Wood_Fig_Blue_Trunk"
    },
    {
      "x": -8,
      "y": 2,
      "z": 2,
      "name": "Plant_Moss_Block_Red"
    },
    {
      "x": -8,
      "y": 3,
      "z": 2,
      "name": "Plant_Moss_Block_Red"
    },
    {
      "x": -8,
      "y": 4,
      "z": 2,
      "name": "Plant_Moss_Rug_Red"
    },
    {
      "x": -8,
      "y": 10,
      "z": 2,
      "name": "Plant_Crop_Mushroom_Block_Red_Mycelium"
    },
    {
      "x": -8,
      "y": 11,
      "z": 2,
      "name": "Plant_Crop_Mushroom_Block_White"
    },
    {
      "x": -8,
      "y": 12,
      "z": 2,
      "name": "Plant_Crop_Mushroom_Cap_White",
      "components": {
        "Components": {
          "FarmingBlock": {}
        }
      }
    },
    {
      "x": -8,
      "y": 14,
      "z": 2,
      "name": "Wood_Fig_Blue_Trunk_Full"
    },
    {
      "x": -8,
      "y": -5,
      "z": 3,
      "name": "Wood_Fig_Blue_Trunk_Full"
    },
    {
      "x": -8,
      "y": -4,
      "z": 3,
      "name": "Wood_Fig_Blue_Trunk"
    },
    {
      "x": -8,
      "y": -3,
      "z": 3,
      "name": "Wood_Fig_Blue_Trunk"
    },
    {
      "x": -8,
      "y": -2,
      "z": 3,
      "name": "Wood_Fig_Blue_Trunk"
    },
    {
      "x": -8,
      "y": -1,
      "z": 3,
      "name": "Wood_Fig_Blue_Trunk"
    },
    {
      "x": -8,
      "y": 0,
      "z": 3,
      "name": "Wood_Fig_Blue_Trunk"
    },
    {
      "x": -8,
      "y": 1,
      "z": 3,
      "name": "Wood_Fig_Blue_Trunk"
    },
    {
      "x": -8,
      "y": 2,
      "z": 3,
      "name": "Plant_Moss_Block_Red"
    },
    {
      "x": -8,
      "y": 3,
      "z": 3,
      "name": "Plant_Moss_Rug_Red"
    },
    {
      "x": -8,
      "y": 10,
      "z": 3,
      "name": "Plant_Crop_Mushroom_Block_Red_Mycelium"
    },
    {
      "x": -8,
      "y": 11,
      "z": 3,
      "name": "Plant_Crop_Mushroom_Block_White"
    },
    {
      "x": -8,
      "y": 14,
      "z": 3,
      "name": "Wood_Fig_Blue_Trunk_Full"
    },
    {
      "x": -8,
      "y": -3,
      "z": 4,
      "name": "Wood_Fig_Blue_Trunk_Full"
    },
    {
      "x": -8,
      "y": -2,
      "z": 4,
      "name": "Wood_Fig_Blue_Trunk"
    },
    {
      "x": -8,
      "y": -1,
      "z": 4,
      "name": "Wood_Fig_Blue_Trunk"
    },
    {
      "x": -8,
      "y": 0,
      "z": 4,
      "name": "Wood_Fig_Blue_Trunk"
    },
    {
      "x": -8,
      "y": 1,
      "z": 4,
      "name": "Wood_Fig_Blue_Trunk_Full"
    },
    {
      "x": -8,
      "y": 7,
      "z": 4,
      "name": "Plant_Crop_Mushroom_Block_Red"
    },
    {
      "x": -8,
      "y": 13,
      "z": 4,
      "name": "Wood_Fig_Blue_Trunk_Full"
    },
    {
      "x": -8,
      "y": 14,
      "z": 4,
      "name": "Wood_Fig_Blue_Trunk"
    },
    {
      "x": -8,
      "y": -2,
      "z": 5,
      "name": "Wood_Fig_Blue_Trunk_Full"
    },
    {
      "x": -8,
      "y": -1,
      "z": 5,
      "name": "Wood_Fig_Blue_Trunk"
    },
    {
      "x": -8,
      "y": 0,
      "z": 5,
      "name": "Wood_Fig_Blue_Trunk"
    },
    {
      "x": -8,
      "y": 1,
      "z": 5,
      "name": "Wood_Fig_Blue_Trunk_Full"
    },
    {
      "x": -8,
      "y": 6,
      "z": 5,
      "name": "Plant_Crop_Mushroom_Block_Red_Mycelium"
    },
    {
      "x": -8,
      "y": 7,
      "z": 5,
      "name": "Plant_Crop_Mushroom_Block_Red"
    },
    {
      "x": -8,
      "y": 13,
      "z": 5,
      "name": "Wood_Fig_Blue_Trunk_Full"
    },
    {
      "x": -8,
      "y": 14,
      "z": 5,
      "name": "Wood_Fig_Blue_Trunk"
    },
    {
      "x": -8,
      "y": 6,
      "z": 6,
      "name": "Plant_Crop_Mushroom_Block_Red_Mycelium"
    },
    {
      "x": -8,
      "y": 7,
      "z": 6,
      "name": "Plant_Crop_Mushroom_Block_Red"
    },
    {
      "x": -8,
      "y": 13,
      "z": 6,
      "name": "Wood_Fig_Blue_Trunk_Full"
    },
    {
      "x": -8,
      "y": -6,
      "z": 7,
      "name": "Wood_Fig_Blue_Trunk_Full"
    },
    {
      "x": -8,
      "y": -5,
      "z": 7,
      "name": "Wood_Fig_Blue_Trunk"
    },
    {
      "x": -8,
      "y": -4,
      "z": 7,
      "name": "Wood_Fig_Blue_Trunk"
    },
    {
      "x": -8,
      "y": -3,
      "z": 7,
      "name": "Wood_Fig_Blue_Trunk"
    },
    {
      "x": -8,
      "y": -2,
      "z": 7,
      "name": "Wood_Fig_Blue_Trunk"
    },
    {
      "x": -8,
      "y": -1,
      "z": 7,
      "name": "Wood_Fig_Blue_Trunk_Full"
    },
    {
      "x": -8,
      "y": 6,
      "z": 7,
      "name": "Plant_Crop_Mushroom_Block_Red_Mycelium"
    },
    {
      "x": -8,
      "y": 7,
      "z": 7,
      "name": "Plant_Crop_Mushroom_Block_Red"
    },
    {
      "x": -8,
      "y": 8,
      "z": 7,
      "name": "Plant_Crop_Mushroom_Cap_Red",
      "components": {
        "Components": {
          "FarmingBlock": {}
        }
      }
    },
    {
      "x": -8,
      "y": -7,
      "z": 8,
      "name": "Wood_Fig_Blue_Trunk_Full"
    },
    {
      "x": -8,
      "y": -6,
      "z": 8,
      "name": "Wood_Fig_Blue_Trunk"
    },
    {
      "x": -8,
      "y": -5,
      "z": 8,
      "name": "Wood_Fig_Blue_Trunk"
    },
    {
      "x": -8,
      "y": -4,
      "z": 8,
      "name": "Wood_Fig_Blue_Trunk"
    },
    {
      "x": -8,
      "y": -3,
      "z": 8,
      "name": "Wood_Fig_Blue_Trunk"
    },
    {
      "x": -8,
      "y": -2,
      "z": 8,
      "name": "Wood_Fig_Blue_Trunk"
    },
    {
      "x": -8,
      "y": -1,
      "z": 8,
      "name": "Wood_Fig_Blue_Trunk"
    },
    {
      "x": -8,
      "y": 0,
      "z": 8,
      "name": "Wood_Fig_Blue_Trunk_Full"
    },
    {
      "x": -8,
      "y": 7,
      "z": 8,
      "name": "Plant_Crop_Mushroom_Block_Red"
    },
    {
      "x": -8,
      "y": -7,
      "z": 9,
      "name": "Wood_Fig_Blue_Trunk_Full"
    },
    {
      "x": -8,
      "y": -6,
      "z": 9,
      "name": "Wood_Fig_Blue_Trunk"
    },
    {
      "x": -8,
      "y": -5,
      "z": 9,
      "name": "Wood_Fig_Blue_Trunk"
    },
    {
      "x": -8,
      "y": -4,
      "z": 9,
      "name": "Wood_Fig_Blue_Trunk"
    },
    {
      "x": -8,
      "y": -3,
      "z": 9,
      "name": "Wood_Fig_Blue_Trunk"
    },
    {
      "x": -8,
      "y": -2,
      "z": 9,
      "name": "Wood_Fig_Blue_Trunk"
    },
    {
      "x": -8,
      "y": -1,
      "z": 9,
      "name": "Wood_Fig_Blue_Trunk_Full"
    },
    {
      "x": -8,
      "y": 7,
      "z": 9,
      "name": "Plant_Crop_Mushroom_Block_Red"
    },
    {
      "x": -8,
      "y": 9,
      "z": 9,
      "name": "Plant_Crop_Mushroom_Block_Red"
    },
    {
      "x": -8,
      "y": -6,
      "z": 10,
      "name": "Wood_Fig_Blue_Trunk_Full"
    },
    {
      "x": -8,
      "y": -5,
      "z": 10,
      "name": "Wood_Fig_Blue_Trunk"
    },
    {
      "x": -8,
      "y": -4,
      "z": 10,
      "name": "Wood_Fig_Blue_Trunk"
    },
    {
      "x": -8,
      "y": -3,
      "z": 10,
      "name": "Wood_Fig_Blue_Trunk"
    },
    {
      "x": -8,
      "y": -2,
      "z": 10,
      "name": "Wood_Fig_Blue_Trunk"
    },
    {
      "x": -8,
      "y": -1,
      "z": 10,
      "name": "Wood_Fig_Blue_Trunk_Full"
    },
    {
      "x": -8,
      "y": 9,
      "z": 10,
      "name": "Plant_Crop_Mushroom_Block_Red"
    },
    {
      "x": -8,
      "y": -3,
      "z": 11,
      "name": "Wood_Fig_Blue_Trunk_Full"
    },
    {
      "x": -8,
      "y": -2,
      "z": 11,
      "name": "Wood_Fig_Blue_Trunk_Full"
    },
    {
      "x": -8,
      "y": 9,
      "z": 11,
      "name": "Plant_Crop_Mushroom_Block_Red"
    },
    {
      "x": -7,
      "y": -6,
      "z": -6,
      "name": "Wood_Fig_Blue_Trunk_Full"
    },
    {
      "x": -7,
      "y": -5,
      "z": -6,
      "name": "Wood_Fig_Blue_Trunk"
    },
    {
      "x": -7,
      "y": -4,
      "z": -6,
      "name": "Wood_Fig_Blue_Trunk_Full"
    },
    {
      "x": -7,
      "y": -7,
      "z": -5,
      "name": "Wood_Fig_Blue_Trunk_Full"
    },
    {
      "x": -7,
      "y": -6,
      "z": -5,
      "name": "Wood_Fig_Blue_Trunk"
    },
    {
      "x": -7,
      "y": -5,
      "z": -5,
      "name": "Wood_Fig_Blue_Trunk"
    },
    {
      "x": -7,
      "y": -4,
      "z": -5,
      "name": "Wood_Fig_Blue_Trunk"
    },
    {
      "x": -7,
      "y": -3,
      "z": -5,
      "name": "Wood_Fig_Blue_Trunk"
    },
    {
      "x": -7,
      "y": -2,
      "z": -5,
      "name": "Wood_Fig_Blue_Trunk"
    },
    {
      "x": -7,
      "y": -1,
      "z": -5,
      "name": "Wood_Fig_Blue_Trunk"
    },
    {
      "x": -7,
      "y": 0,
      "z": -5,
      "name": "Wood_Fig_Blue_Trunk_Full"
    },
    {
      "x": -7,
      "y": -6,
      "z": -4,
      "name": "Wood_Fig_Blue_Trunk_Full"
    },
    {
      "x": -7,
      "y": -5,
      "z": -4,
      "name": "Wood_Fig_Blue_Trunk"
    },
    {
      "x": -7,
      "y": -4,
      "z": -4,
      "name": "Wood_Fig_Blue_Trunk"
    },
    {
      "x": -7,
      "y": -3,
      "z": -4,
      "name": "Wood_Fig_Blue_Trunk"
    },
    {
      "x": -7,
      "y": -2,
      "z": -4,
      "name": "Wood_Fig_Blue_Trunk"
    },
    {
      "x": -7,
      "y": -1,
      "z": -4,
      "name": "Wood_Fig_Blue_Trunk"
    },
    {
      "x": -7,
      "y": 0,
      "z": -4,
      "name": "Wood_Fig_Blue_Trunk"
    },
    {
      "x": -7,
      "y": 1,
      "z": -4,
      "name": "Wood_Fig_Blue_Trunk"
    },
    {
      "x": -7,
      "y": 2,
      "z": -4,
      "name": "Wood_Fig_Blue_Trunk_Full"
    },
    {
      "x": -7,
      "y": 4,
      "z": -4,
      "name": "Plant_Moss_Wall_Red",
      "rotation": 2
    },
    {
      "x": -7,
      "y": -4,
      "z": -3,
      "name": "Wood_Fig_Blue_Trunk_Full"
    },
    {
      "x": -7,
      "y": -3,
      "z": -3,
      "name": "Wood_Fig_Blue_Trunk"
    },
    {
      "x": -7,
      "y": -2,
      "z": -3,
      "name": "Wood_Fig_Blue_Trunk"
    },
    {
      "x": -7,
      "y": -1,
      "z": -3,
      "name": "Wood_Fig_Blue_Trunk"
    },
    {
      "x": -7,
      "y": 0,
      "z": -3,
      "name": "Wood_Fig_Blue_Trunk"
    },
    {
      "x": -7,
      "y": 1,
      "z": -3,
      "name": "Wood_Fig_Blue_Trunk"
    },
    {
      "x": -7,
      "y": 2,
      "z": -3,
      "name": "Wood_Fig_Blue_Trunk"
    },
    {
      "x": -7,
      "y": 3,
      "z": -3,
      "name": "Wood_Fig_Blue_Trunk"
    },
    {
      "x": -7,
      "y": 4,
      "z": -3,
      "name": "Plant_Moss_Block_Red"
    },
    {
      "x": -7,
      "y": 5,
      "z": -3,
      "name": "Plant_Moss_Rug_Red"
    },
    {
      "x": -7,
      "y": -3,
      "z": -2,
      "name": "Wood_Fig_Blue_Trunk_Full"
    },
    {
      "x": -7,
      "y": -2,
      "z": -2,
      "name": "Wood_Fig_Blue_Trunk"
    },
    {
      "x": -7,
      "y": -1,
      "z": -2,
      "name": "Wood_Fig_Blue_Trunk"
    },
    {
      "x": -7,
      "y": 0,
      "z": -2,
      "name": "Wood_Fig_Blue_Trunk"
    },
    {
      "x": -7,
      "y": 1,
      "z": -2,
      "name": "Wood_Fig_Blue_Trunk"
    },
    {
      "x": -7,
      "y": 2,
      "z": -2,
      "name": "Wood_Fig_Blue_Trunk"
    },
    {
      "x": -7,
      "y": 3,
      "z": -2,
      "name": "Wood_Fig_Blue_Trunk"
    },
    {
      "x": -7,
      "y": 4,
      "z": -2,
      "name": "Plant_Moss_Block_Red"
    },
    {
      "x": -7,
      "y": 5,
      "z": -2,
      "name": "Plant_Moss_Block_Red"
    },
    {
      "x": -7,
      "y": -2,
      "z": -1,
      "name": "Wood_Fig_Blue_Trunk_Full"
    },
    {
      "x": -7,
      "y": -1,
      "z": -1,
      "name": "Wood_Fig_Blue_Trunk"
    },
    {
      "x": -7,
      "y": 0,
      "z": -1,
      "name": "Wood_Fig_Blue_Trunk"
    },
    {
      "x": -7,
      "y": 1,
      "z": -1,
      "name": "Wood_Fig_Blue_Trunk"
    },
    {
      "x": -7,
      "y": 2,
      "z": -1,
      "name": "Wood_Fig_Blue_Trunk"
    },
    {
      "x": -7,
      "y": 3,
      "z": -1,
      "name": "Wood_Fig_Blue_Trunk"
    },
    {
      "x": -7,
      "y": 4,
      "z": -1,
      "name": "Wood_Fig_Blue_Trunk"
    },
    {
      "x": -7,
      "y": 5,
      "z": -1,
      "name": "Plant_Moss_Block_Red"
    },
    {
      "x": -7,
      "y": -1,
      "z": 0,
      "name": "Wood_Fig_Blue_Trunk_Full"
    },
    {
      "x": -7,
      "y": 0,
      "z": 0,
      "name": "Wood_Fig_Blue_Trunk"
    },
    {
      "x": -7,
      "y": 1,
      "z": 0,
      "name": "Wood_Fig_Blue_Trunk"
    },
    {
      "x": -7,
      "y": 2,
      "z": 0,
      "name": "Wood_Fig_Blue_Trunk"
    },
    {
      "x": -7,
      "y": 3,
      "z": 0,
      "name": "Wood_Fig_Blue_Trunk"
    },
    {
      "x": -7,
      "y": 4,
      "z": 0,
      "name": "Wood_Fig_Blue_Trunk"
    },
    {
      "x": -7,
      "y": 5,
      "z": 0,
      "name": "Plant_Moss_Block_Red"
    },
    {
      "x": -7,
      "y": 6,
      "z": 0,
      "name": "Plant_Moss_Rug_Red"
    },
    {
      "x": -7,
      "y": 11,
      "z": 0,
      "name": "Plant_Crop_Mushroom_Block_White"
    },
    {
      "x": -7,
      "y": -2,
      "z": 1,
      "name": "Wood_Fig_Blue_Trunk_Full"
    },
    {
      "x": -7,
      "y": -1,
      "z": 1,
      "name": "Wood_Fig_Blue_Trunk"
    },
    {
      "x": -7,
      "y": 0,
      "z": 1,
      "name": "Wood_Fig_Blue_Trunk"
    },
    {
      "x": -7,
      "y": 1,
      "z": 1,
      "name": "Wood_Fig_Blue_Trunk"
    },
    {
      "x": -7,
      "y": 2,
      "z": 1,
      "name": "Wood_Fig_Blue_Trunk"
    },
    {
      "x": -7,
      "y": 3,
      "z": 1,
      "name": "Wood_Fig_Blue_Trunk"
    },
    {
      "x": -7,
      "y": 4,
      "z": 1,
      "name": "Plant_Moss_Block_Red"
    },
    {
      "x": -7,
      "y": 5,
      "z": 1,
      "name": "Plant_Moss_Block_Red"
    },
    {
      "x": -7,
      "y": 6,
      "z": 1,
      "name": "Plant_Moss_Rug_Red"
    },
    {
      "x": -7,
      "y": 11,
      "z": 1,
      "name": "Plant_Crop_Mushroom_Block_White"
    },
    {
      "x": -7,
      "y": 12,
      "z": 1,
      "name": "Plant_Crop_Mushroom_Cap_White",
      "components": {
        "Components": {
          "FarmingBlock": {}
        }
      }
    },
    {
      "x": -7,
      "y": -2,
      "z": 2,
      "name": "Wood_Fig_Blue_Trunk_Full"
    },
    {
      "x": -7,
      "y": -1,
      "z": 2,
      "name": "Wood_Fig_Blue_Trunk"
    },
    {
      "x": -7,
      "y": 0,
      "z": 2,
      "name": "Wood_Fig_Blue_Trunk"
    },
    {
      "x": -7,
      "y": 1,
      "z": 2,
      "name": "Wood_Fig_Blue_Trunk"
    },
    {
      "x": -7,
      "y": 2,
      "z": 2,
      "name": "Wood_Fig_Blue_Trunk"
    },
    {
      "x": -7,
      "y": 3,
      "z": 2,
      "name": "Wood_Fig_Blue_Trunk"
    },
    {
      "x": -7,
      "y": 4,
      "z": 2,
      "name": "Plant_Moss_Block_Red"
    },
    {
      "x": -7,
      "y": 10,
      "z": 2,
      "name": "Plant_Crop_Mushroom_Block_Red_Mycelium"
    },
    {
      "x": -7,
      "y": 11,
      "z": 2,
      "name": "Plant_Crop_Mushroom_Block_White"
    },
    {
      "x": -7,
      "y": 12,
      "z": 2,
      "name": "Plant_Crop_Mushroom_Cap_White",
      "components": {
        "Components": {
          "FarmingBlock": {}
        }
      }
    },
    {
      "x": -7,
      "y": 13,
      "z": 2,
      "name": "Wood_Fig_Blue_Trunk_Full"
    },
    {
      "x": -7,
      "y": 14,
      "z": 2,
      "name": "Wood_Fig_Blue_Trunk"
    },
    {
      "x": -7,
      "y": -4,
      "z": 3,
      "name": "Wood_Fig_Blue_Trunk_Full"
    },
    {
      "x": -7,
      "y": -3,
      "z": 3,
      "name": "Wood_Fig_Blue_Trunk"
    },
    {
      "x": -7,
      "y": -2,
      "z": 3,
      "name": "Wood_Fig_Blue_Trunk"
    },
    {
      "x": -7,
      "y": -1,
      "z": 3,
      "name": "Wood_Fig_Blue_Trunk"
    },
    {
      "x": -7,
      "y": 0,
      "z": 3,
      "name": "Wood_Fig_Blue_Trunk"
    },
    {
      "x": -7,
      "y": 1,
      "z": 3,
      "name": "Wood_Fig_Blue_Trunk"
    },
    {
      "x": -7,
      "y": 2,
      "z": 3,
      "name": "Wood_Fig_Blue_Trunk"
    },
    {
      "x": -7,
      "y": 3,
      "z": 3,
      "name": "Wood_Fig_Blue_Trunk_Full"
    },
    {
      "x": -7,
      "y": 4,
      "z": 3,
      "name": "Plant_Moss_Rug_Red"
    },
    {
      "x": -7,
      "y": 10,
      "z": 3,
      "name": "Wood_Fig_Blue_Trunk_Full"
    },
    {
      "x": -7,
      "y": 11,
      "z": 3,
      "name": "Wood_Fig_Blue_Trunk"
    },
    {
      "x": -7,
      "y": 12,
      "z": 3,
      "name": "Wood_Fig_Blue_Trunk"
    },
    {
      "x": -7,
      "y": 13,
      "z": 3,
      "name": "Wood_Fig_Blue_Trunk"
    },
    {
      "x": -7,
      "y": 14,
      "z": 3,
      "name": "Wood_Fig_Blue_Trunk"
    },
    {
      "x": -7,
      "y": -3,
      "z": 4,
      "name": "Wood_Fig_Blue_Trunk_Full"
    },
    {
      "x": -7,
      "y": -2,
      "z": 4,
      "name": "Wood_Fig_Blue_Trunk"
    },
    {
      "x": -7,
      "y": -1,
      "z": 4,
      "name": "Wood_Fig_Blue_Trunk"
    },
    {
      "x": -7,
      "y": 0,
      "z": 4,
      "name": "Wood_Fig_Blue_Trunk"
    },
    {
      "x": -7,
      "y": 1,
      "z": 4,
      "name": "Wood_Fig_Blue_Trunk_Full"
    },
    {
      "x": -7,
      "y": 7,
      "z": 4,
      "name": "Plant_Crop_Mushroom_Block_Red"
    },
    {
      "x": -7,
      "y": 9,
      "z": 4,
      "name": "Wood_Fig_Blue_Trunk_Full"
    },
    {
      "x": -7,
      "y": 10,
      "z": 4,
      "name": "Wood_Fig_Blue_Trunk"
    },
    {
      "x": -7,
      "y": 11,
      "z": 4,
      "name": "Wood_Fig_Blue_Trunk"
    },
    {
      "x": -7,
      "y": 12,
      "z": 4,
      "name": "Wood_Fig_Blue_Trunk"
    },
    {
      "x": -7,
      "y": 13,
      "z": 4,
      "name": "Wood_Fig_Blue_Trunk"
    },
    {
      "x": -7,
      "y": 14,
      "z": 4,
      "name": "Wood_Fig_Blue_Trunk"
    },
    {
      "x": -7,
      "y": -2,
      "z": 5,
      "name": "Wood_Fig_Blue_Trunk_Full"
    },
    {
      "x": -7,
      "y": -1,
      "z": 5,
      "name": "Wood_Fig_Blue_Trunk"
    },
    {
      "x": -7,
      "y": 0,
      "z": 5,
      "name": "Wood_Fig_Blue_Trunk"
    },
    {
      "x": -7,
      "y": 1,
      "z": 5,
      "name": "Wood_Fig_Blue_Trunk"
    },
    {
      "x": -7,
      "y": 2,
      "z": 5,
      "name": "Wood_Fig_Blue_Trunk_Full"
    },
    {
      "x": -7,
      "y": 7,
      "z": 5,
      "name": "Wood_Fig_Blue_Trunk_Full"
    },
    {
      "x": -7,
      "y": 8,
      "z": 5,
      "name": "Wood_Fig_Blue_Trunk"
    },
    {
      "x": -7,
      "y": 9,
      "z": 5,
      "name": "Wood_Fig_Blue_Trunk"
    },
    {
      "x": -7,
      "y": 10,
      "z": 5,
      "name": "Wood_Fig_Blue_Trunk"
    },
    {
      "x": -7,
      "y": 11,
      "z": 5,
      "name": "Wood_Fig_Blue_Trunk"
    },
    {
      "x": -7,
      "y": 12,
      "z": 5,
      "name": "Wood_Fig_Blue_Trunk"
    },
    {
      "x": -7,
      "y": 13,
      "z": 5,
      "name": "Wood_Fig_Blue_Trunk"
    },
    {
      "x": -7,
      "y": 14,
      "z": 5,
      "name": "Wood_Fig_Blue_Trunk"
    },
    {
      "x": -7,
      "y": -2,
      "z": 6,
      "name": "Wood_Fig_Blue_Trunk_Full"
    },
    {
      "x": -7,
      "y": -1,
      "z": 6,
      "name": "Wood_Fig_Blue_Trunk_Full"
    },
    {
      "x": -7,
      "y": 7,
      "z": 6,
      "name": "Wood_Fig_Blue_Trunk_Full"
    },
    {
      "x": -7,
      "y": 8,
      "z": 6,
      "name": "Wood_Fig_Blue_Trunk"
    },
    {
      "x": -7,
      "y": 9,
      "z": 6,
      "name": "Wood_Fig_Blue_Trunk"
    },
    {
      "x": -7,
      "y": 10,
      "z": 6,
      "name": "Wood_Fig_Blue_Trunk"
    },
    {
      "x": -7,
      "y": 11,
      "z": 6,
      "name": "Wood_Fig_Blue_Trunk_Full"
    },
    {
      "x": -7,
      "y": 12,
      "z": 6,
      "name": "Wood_Fig_Blue_Trunk"
    },
    {
      "x": -7,
      "y": 13,
      "z": 6,
      "name": "Wood_Fig_Blue_Trunk"
    },
    {
      "x": -7,
      "y": -4,
      "z": 7,
      "name": "Wood_Fig_Blue_Trunk_Full"
    },
    {
      "x": -7,
      "y": -3,
      "z": 7,
      "name": "Wood_Fig_Blue_Trunk"
    },
    {
      "x": -7,
      "y": -2,
      "z": 7,
      "name": "Wood_Fig_Blue_Trunk"
    },
    {
      "x": -7,
      "y": -1,
      "z": 7,
      "name": "Wood_Fig_Blue_Trunk"
    },
    {
      "x": -7,
      "y": 0,
      "z": 7,
      "name": "Wood_Fig_Blue_Trunk"
    },
    {
      "x": -7,
      "y": 1,
      "z": 7,
      "name": "Wood_Fig_Blue_Trunk_Full"
    },
    {
      "x": -7,
      "y": 6,
      "z": 7,
      "name": "Plant_Crop_Mushroom_Block_Red_Mycelium"
    },
    {
      "x": -7,
      "y": 7,
      "z": 7,
      "name": "Plant_Crop_Mushroom_Block_Red"
    },
    {
      "x": -7,
      "y": 8,
      "z": 7,
      "name": "Wood_Fig_Blue_Trunk_Full"
    },
    {
      "x": -7,
      "y": 9,
      "z": 7,
      "name": "Wood_Fig_Blue_Trunk_Full"
    },
    {
      "x": -7,
      "y": 12,
      "z": 7,
      "name": "Wood_Fig_Blue_Trunk_Full"
    },
    {
      "x": -7,
      "y": 13,
      "z": 7,
      "name": "Wood_Fig_Blue_Trunk"
    },
    {
      "x": -7,
      "y": -5,
      "z": 8,
      "name": "Wood_Fig_Blue_Trunk_Full"
    },
    {
      "x": -7,
      "y": -4,
      "z": 8,
      "name": "Wood_Fig_Blue_Trunk"
    },
    {
      "x": -7,
      "y": -3,
      "z": 8,
      "name": "Wood_Fig_Blue_Trunk"
    },
    {
      "x": -7,
      "y": -2,
      "z": 8,
      "name": "Wood_Fig_Blue_Trunk"
    },
    {
      "x": -7,
      "y": -1,
      "z": 8,
      "name": "Wood_Fig_Blue_Trunk"
    },
    {
      "x": -7,
      "y": 0,
      "z": 8,
      "name": "Wood_Fig_Blue_Trunk"
    },
    {
      "x": -7,
      "y": 1,
      "z": 8,
      "name": "Wood_Fig_Blue_Trunk_Full"
    },
    {
      "x": -7,
      "y": 7,
      "z": 8,
      "name": "Plant_Crop_Mushroom_Block_Red"
    },
    {
      "x": -7,
      "y": 9,
      "z": 8,
      "name": "Plant_Crop_Mushroom_Block_Red"
    },
    {
      "x": -7,
      "y": -5,
      "z": 9,
      "name": "Wood_Fig_Blue_Trunk_Full"
    },
    {
      "x": -7,
      "y": -4,
      "z": 9,
      "name": "Wood_Fig_Blue_Trunk"
    },
    {
      "x": -7,
      "y": -3,
      "z": 9,
      "name": "Wood_Fig_Blue_Trunk"
    },
    {
      "x": -7,
      "y": -2,
      "z": 9,
      "name": "Wood_Fig_Blue_Trunk"
    },
    {
      "x": -7,
      "y": -1,
      "z": 9,
      "name": "Wood_Fig_Blue_Trunk"
    },
    {
      "x": -7,
      "y": 0,
      "z": 9,
      "name": "Wood_Fig_Blue_Trunk"
    },
    {
      "x": -7,
      "y": 1,
      "z": 9,
      "name": "Wood_Fig_Blue_Trunk_Full"
    },
    {
      "x": -7,
      "y": 6,
      "z": 9,
      "name": "Plant_Crop_Mushroom_Block_Red_Mycelium"
    },
    {
      "x": -7,
      "y": 7,
      "z": 9,
      "name": "Plant_Crop_Mushroom_Block_Red"
    },
    {
      "x": -7,
      "y": 8,
      "z": 9,
      "name": "Plant_Crop_Mushroom_Block_Red_Mycelium"
    },
    {
      "x": -7,
      "y": 9,
      "z": 9,
      "name": "Plant_Crop_Mushroom_Block_Red"
    },
    {
      "x": -7,
      "y": -4,
      "z": 10,
      "name": "Wood_Fig_Blue_Trunk_Full"
    },
    {
      "x": -7,
      "y": -3,
      "z": 10,
      "name": "Wood_Fig_Blue_Trunk"
    },
    {
      "x": -7,
      "y": -2,
      "z": 10,
      "name": "Wood_Fig_Blue_Trunk"
    },
    {
      "x": -7,
      "y": -1,
      "z": 10,
      "name": "Wood_Fig_Blue_Trunk"
    },
    {
      "x": -7,
      "y": 0,
      "z": 10,
      "name": "Wood_Fig_Blue_Trunk_Full"
    },
    {
      "x": -7,
      "y": 9,
      "z": 10,
      "name": "Plant_Crop_Mushroom_Block_Red"
    },
    {
      "x": -7,
      "y": 10,
      "z": 10,
      "name": "Plant_Crop_Mushroom_Cap_Red",
      "components": {
        "Components": {
          "FarmingBlock": {}
        }
      }
    },
    {
      "x": -7,
      "y": -4,
      "z": 11,
      "name": "Wood_Fig_Blue_Trunk_Full"
    },
    {
      "x": -7,
      "y": -3,
      "z": 11,
      "name": "Wood_Fig_Blue_Trunk"
    },
    {
      "x": -7,
      "y": -2,
      "z": 11,
      "name": "Wood_Fig_Blue_Trunk"
    },
    {
      "x": -7,
      "y": -1,
      "z": 11,
      "name": "Wood_Fig_Blue_Trunk_Full"
    },
    {
      "x": -7,
      "y": 9,
      "z": 11,
      "name": "Plant_Crop_Mushroom_Block_Red"
    },
    {
      "x": -7,
      "y": 10,
      "z": 11,
      "name": "Plant_Crop_Mushroom_Cap_Red",
      "components": {
        "Components": {
          "FarmingBlock": {}
        }
      }
    },
    {
      "x": -7,
      "y": 9,
      "z": 12,
      "name": "Plant_Crop_Mushroom_Block_Red"
    },
    {
      "x": -6,
      "y": -7,
      "z": -13,
      "name": "Wood_Fig_Blue_Trunk_Full"
    },
    {
      "x": -6,
      "y": -6,
      "z": -13,
      "name": "Wood_Fig_Blue_Trunk"
    },
    {
      "x": -6,
      "y": -5,
      "z": -13,
      "name": "Wood_Fig_Blue_Trunk"
    },
    {
      "x": -6,
      "y": -4,
      "z": -13,
      "name": "Wood_Fig_Blue_Trunk_Full"
    },
    {
      "x": -6,
      "y": -6,
      "z": -12,
      "name": "Wood_Fig_Blue_Trunk_Full"
    },
    {
      "x": -6,
      "y": -5,
      "z": -12,
      "name": "Wood_Fig_Blue_Trunk"
    },
    {
      "x": -6,
      "y": -4,
      "z": -12,
      "name": "Wood_Fig_Blue_Trunk_Full"
    },
    {
      "x": -6,
      "y": -6,
      "z": -5,
      "name": "Wood_Fig_Blue_Trunk_Full"
    },
    {
      "x": -6,
      "y": -5,
      "z": -5,
      "name": "Wood_Fig_Blue_Trunk"
    },
    {
      "x": -6,
      "y": -4,
      "z": -5,
      "name": "Wood_Fig_Blue_Trunk"
    },
    {
      "x": -6,
      "y": -3,
      "z": -5,
      "name": "Wood_Fig_Blue_Trunk"
    },
    {
      "x": -6,
      "y": -2,
      "z": -5,
      "name": "Wood_Fig_Blue_Trunk"
    },
    {
      "x": -6,
      "y": -1,
      "z": -5,
      "name": "Wood_Fig_Blue_Trunk_Full"
    },
    {
      "x": -6,
      "y": -5,
      "z": -4,
      "name": "Wood_Fig_Blue_Trunk_Full"
    },
    {
      "x": -6,
      "y": -4,
      "z": -4,
      "name": "Wood_Fig_Blue_Trunk"
    },
    {
      "x": -6,
      "y": -3,
      "z": -4,
      "name": "Wood_Fig_Blue_Trunk"
    },
    {
      "x": -6,
      "y": -2,
      "z": -4,
      "name": "Wood_Fig_Blue_Trunk"
    },
    {
      "x": -6,
      "y": -1,
      "z": -4,
      "name": "Wood_Fig_Blue_Trunk"
    },
    {
      "x": -6,
      "y": 0,
      "z": -4,
      "name": "Wood_Fig_Blue_Trunk"
    },
    {
      "x": -6,
      "y": 1,
      "z": -4,
      "name": "Wood_Fig_Blue_Trunk"
    },
    {
      "x": -6,
      "y": 2,
      "z": -4,
      "name": "Wood_Fig_Blue_Trunk"
    },
    {
      "x": -6,
      "y": 3,
      "z": -4,
      "name": "Wood_Fig_Blue_Trunk"
    },
    {
      "x": -6,
      "y": 4,
      "z": -4,
      "name": "Wood_Fig_Blue_Trunk_Full"
    },
    {
      "x": -6,
      "y": 5,
      "z": -4,
      "name": "Plant_Moss_Rug_Red"
    },
    {
      "x": -6,
      "y": -4,
      "z": -3,
      "name": "Wood_Fig_Blue_Trunk_Full"
    },
    {
      "x": -6,
      "y": -3,
      "z": -3,
      "name": "Wood_Fig_Blue_Trunk"
    },
    {
      "x": -6,
      "y": -2,
      "z": -3,
      "name": "Wood_Fig_Blue_Trunk"
    },
    {
      "x": -6,
      "y": -1,
      "z": -3,
      "name": "Wood_Fig_Blue_Trunk"
    },
    {
      "x": -6,
      "y": 0,
      "z": -3,
      "name": "Wood_Fig_Blue_Trunk"
    },
    {
      "x": -6,
      "y": 1,
      "z": -3,
      "name": "Wood_Fig_Blue_Trunk"
    },
    {
      "x": -6,
      "y": 2,
      "z": -3,
      "name": "Wood_Fig_Blue_Trunk"
    },
    {
      "x": -6,
      "y": 3,
      "z": -3,
      "name": "Wood_Fig_Blue_Trunk"
    },
    {
      "x": -6,
      "y": 4,
      "z": -3,
      "name": "Wood_Fig_Blue_Trunk"
    },
    {
      "x": -6,
      "y": 5,
      "z": -3,
      "name": "Plant_Moss_Block_Red"
    },
    {
      "x": -6,
      "y": 6,
      "z": -3,
      "name": "Plant_Moss_Rug_Red"
    },
    {
      "x": -6,
      "y": -3,
      "z": -2,
      "name": "Wood_Fig_Blue_Trunk_Full"
    },
    {
      "x": -6,
      "y": -2,
      "z": -2,
      "name": "Wood_Fig_Blue_Trunk"
    },
    {
      "x": -6,
      "y": -1,
      "z": -2,
      "name": "Wood_Fig_Blue_Trunk"
    },
    {
      "x": -6,
      "y": 0,
      "z": -2,
      "name": "Wood_Fig_Blue_Trunk"
    },
    {
      "x": -6,
      "y": 1,
      "z": -2,
      "name": "Wood_Fig_Blue_Trunk"
    },
    {
      "x": -6,
      "y": 2,
      "z": -2,
      "name": "Wood_Fig_Blue_Trunk"
    },
    {
      "x": -6,
      "y": 3,
      "z": -2,
      "name": "Wood_Fig_Blue_Trunk"
    },
    {
      "x": -6,
      "y": 4,
      "z": -2,
      "name": "Wood_Fig_Blue_Trunk"
    },
    {
      "x": -6,
      "y": 5,
      "z": -2,
      "name": "Wood_Fig_Blue_Trunk"
    },
    {
      "x": -6,
      "y": 6,
      "z": -2,
      "name": "Plant_Moss_Block_Red"
    },
    {
      "x": -6,
      "y": -2,
      "z": -1,
      "name": "Wood_Fig_Blue_Trunk_Full"
    },
    {
      "x": -6,
      "y": -1,
      "z": -1,
      "name": "Wood_Fig_Blue_Trunk"
    },
    {
      "x": -6,
      "y": 0,
      "z": -1,
      "name": "Wood_Fig_Blue_Trunk"
    },
    {
      "x": -6,
      "y": 1,
      "z": -1,
      "name": "Wood_Fig_Blue_Trunk"
    },
    {
      "x": -6,
      "y": 2,
      "z": -1,
      "name": "Wood_Fig_Blue_Trunk"
    },
    {
      "x": -6,
      "y": 3,
      "z": -1,
      "name": "Wood_Fig_Blue_Trunk"
    },
    {
      "x": -6,
      "y": 4,
      "z": -1,
      "name": "Wood_Fig_Blue_Trunk"
    },
    {
      "x": -6,
      "y": 5,
      "z": -1,
      "name": "Wood_Fig_Blue_Trunk"
    },
    {
      "x": -6,
      "y": 6,
      "z": -1,
      "name": "Plant_Moss_Block_Red"
    },
    {
      "x": -6,
      "y": 7,
      "z": -1,
      "name": "Plant_Moss_Red"
    },
    {
      "x": -6,
      "y": -1,
      "z": 0,
      "name": "Wood_Fig_Blue_Trunk_Full"
    },
    {
      "x": -6,
      "y": 0,
      "z": 0,
      "name": "Wood_Fig_Blue_Trunk"
    },
    {
      "x": -6,
      "y": 1,
      "z": 0,
      "name": "Wood_Fig_Blue_Trunk"
    },
    {
      "x": -6,
      "y": 2,
      "z": 0,
      "name": "Wood_Fig_Blue_Trunk"
    },
    {
      "x": -6,
      "y": 3,
      "z": 0,
      "name": "Wood_Fig_Blue_Trunk"
    },
    {
      "x": -6,
      "y": 4,
      "z": 0,
      "name": "Wood_Fig_Blue_Trunk"
    },
    {
      "x": -6,
      "y": 5,
      "z": 0,
      "name": "Wood_Fig_Blue_Trunk"
    },
    {
      "x": -6,
      "y": 6,
      "z": 0,
      "name": "Plant_Moss_Block_Red"
    },
    {
      "x": -6,
      "y": 11,
      "z": 0,
      "name": "Plant_Crop_Mushroom_Block_White"
    },
    {
      "x": -6,
      "y": -2,
      "z": 1,
      "name": "Wood_Fig_Blue_Trunk_Full"
    },
    {
      "x": -6,
      "y": -1,
      "z": 1,
      "name": "Wood_Fig_Blue_Trunk"
    },
    {
      "x": -6,
      "y": 0,
      "z": 1,
      "name": "Wood_Fig_Blue_Trunk"
    },
    {
      "x": -6,
      "y": 1,
      "z": 1,
      "name": "Wood_Fig_Blue_Trunk"
    },
    {
      "x": -6,
      "y": 2,
      "z": 1,
      "name": "Wood_Fig_Blue_Trunk"
    },
    {
      "x": -6,
      "y": 3,
      "z": 1,
      "name": "Wood_Fig_Blue_Trunk"
    },
    {
      "x": -6,
      "y": 4,
      "z": 1,
      "name": "Wood_Fig_Blue_Trunk"
    },
    {
      "x": -6,
      "y": 5,
      "z": 1,
      "name": "Wood_Fig_Blue_Trunk"
    },
    {
      "x": -6,
      "y": 6,
      "z": 1,
      "name": "Wood_Fig_Blue_Trunk_Full"
    },
    {
      "x": -6,
      "y": 8,
      "z": 1,
      "name": "Plant_Moss_Wall_Red",
      "rotation": 3
    },
    {
      "x": -6,
      "y": 11,
      "z": 1,
      "name": "Plant_Crop_Mushroom_Block_White"
    },
    {
      "x": -6,
      "y": 13,
      "z": 1,
      "name": "Wood_Fig_Blue_Trunk_Full"
    },
    {
      "x": -6,
      "y": -3,
      "z": 2,
      "name": "Wood_Fig_Blue_Trunk_Full"
    },
    {
      "x": -6,
      "y": -2,
      "z": 2,
      "name": "Wood_Fig_Blue_Trunk"
    },
    {
      "x": -6,
      "y": -1,
      "z": 2,
      "name": "Wood_Fig_Blue_Trunk"
    },
    {
      "x": -6,
      "y": 0,
      "z": 2,
      "name": "Wood_Fig_Blue_Trunk"
    },
    {
      "x": -6,
      "y": 1,
      "z": 2,
      "name": "Wood_Fig_Blue_Trunk"
    },
    {
      "x": -6,
      "y": 2,
      "z": 2,
      "name": "Wood_Fig_Blue_Trunk"
    },
    {
      "x": -6,
      "y": 3,
      "z": 2,
      "name": "Wood_Fig_Blue_Trunk"
    },
    {
      "x": -6,
      "y": 4,
      "z": 2,
      "name": "Wood_Fig_Blue_Trunk"
    },
    {
      "x": -6,
      "y": 5,
      "z": 2,
      "name": "Wood_Fig_Blue_Trunk_Full"
    },
    {
      "x": -6,
      "y": 8,
      "z": 2,
      "name": "Wood_Fig_Blue_Trunk_Full"
    },
    {
      "x": -6,
      "y": 9,
      "z": 2,
      "name": "Wood_Fig_Blue_Trunk"
    },
    {
      "x": -6,
      "y": 10,
      "z": 2,
      "name": "Wood_Fig_Blue_Trunk"
    },
    {
      "x": -6,
      "y": 11,
      "z": 2,
      "name": "Wood_Fig_Blue_Trunk"
    },
    {
      "x": -6,
      "y": 12,
      "z": 2,
      "name": "Wood_Fig_Blue_Trunk"
    },
    {
      "x": -6,
      "y": 13,
      "z": 2,
      "name": "Wood_Fig_Blue_Trunk"
    },
    {
      "x": -6,
      "y": -2,
      "z": 3,
      "name": "Wood_Fig_Blue_Trunk_Full"
    },
    {
      "x": -6,
      "y": -1,
      "z": 3,
      "name": "Wood_Fig_Blue_Trunk"
    },
    {
      "x": -6,
      "y": 0,
      "z": 3,
      "name": "Wood_Fig_Blue_Trunk"
    },
    {
      "x": -6,
      "y": 1,
      "z": 3,
      "name": "Wood_Fig_Blue_Trunk"
    },
    {
      "x": -6,
      "y": 2,
      "z": 3,
      "name": "Wood_Fig_Blue_Trunk"
    },
    {
      "x": -6,
      "y": 3,
      "z": 3,
      "name": "Wood_Fig_Blue_Trunk"
    },
    {
      "x": -6,
      "y": 4,
      "z": 3,
      "name": "Wood_Fig_Blue_Trunk_Full"
    },
    {
      "x": -6,
      "y": 7,
      "z": 3,
      "name": "Wood_Fig_Blue_Trunk_Full"
    },
    {
      "x": -6,
      "y": 8,
      "z": 3,
      "name": "Wood_Fig_Blue_Trunk"
    },
    {
      "x": -6,
      "y": 9,
      "z": 3,
      "name": "Wood_Fig_Blue_Trunk"
    },
    {
      "x": -6,
      "y": 10,
      "z": 3,
      "name": "Wood_Fig_Blue_Trunk"
    },
    {
      "x": -6,
      "y": 11,
      "z": 3,
      "name": "Wood_Fig_Blue_Trunk"
    },
    {
      "x": -6,
      "y": 12,
      "z": 3,
      "name": "Wood_Fig_Blue_Trunk"
    },
    {
      "x": -6,
      "y": 13,
      "z": 3,
      "name": "Wood_Fig_Blue_Trunk"
    },
    {
      "x": -6,
      "y": 14,
      "z": 3,
      "name": "Wood_Fig_Blue_Trunk"
    },
    {
      "x": -6,
      "y": -3,
      "z": 4,
      "name": "Wood_Fig_Blue_Trunk_Full"
    },
    {
      "x": -6,
      "y": -2,
      "z": 4,
      "name": "Wood_Fig_Blue_Trunk"
    },
    {
      "x": -6,
      "y": -1,
      "z": 4,
      "name": "Wood_Fig_Blue_Trunk"
    },
    {
      "x": -6,
      "y": 0,
      "z": 4,
      "name": "Wood_Fig_Blue_Trunk"
    },
    {
      "x": -6,
      "y": 1,
      "z": 4,
      "name": "Wood_Fig_Blue_Trunk"
    },
    {
      "x": -6,
      "y": 2,
      "z": 4,
      "name": "Wood_Fig_Blue_Trunk"
    },
    {
      "x": -6,
      "y": 3,
      "z": 4,
      "name": "Wood_Fig_Blue_Trunk"
    },
    {
      "x": -6,
      "y": 4,
      "z": 4,
      "name": "Wood_Fig_Blue_Trunk"
    },
    {
      "x": -6,
      "y": 5,
      "z": 4,
      "name": "Wood_Fig_Blue_Trunk"
    },
    {
      "x": -6,
      "y": 6,
      "z": 4,
      "name": "Wood_Fig_Blue_Trunk"
    },
    {
      "x": -6,
      "y": 7,
      "z": 4,
      "name": "Wood_Fig_Blue_Trunk"
    },
    {
      "x": -6,
      "y": 8,
      "z": 4,
      "name": "Wood_Fig_Blue_Trunk"
    },
    {
      "x": -6,
      "y": 9,
      "z": 4,
      "name": "Wood_Fig_Blue_Trunk"
    },
    {
      "x": -6,
      "y": 10,
      "z": 4,
      "name": "Wood_Fig_Blue_Trunk"
    },
    {
      "x": -6,
      "y": 11,
      "z": 4,
      "name": "Wood_Fig_Blue_Trunk"
    },
    {
      "x": -6,
      "y": 12,
      "z": 4,
      "name": "Wood_Fig_Blue_Trunk"
    },
    {
      "x": -6,
      "y": 13,
      "z": 4,
      "name": "Wood_Fig_Blue_Trunk"
    },
    {
      "x": -6,
      "y": 14,
      "z": 4,
      "name": "Wood_Fig_Blue_Trunk"
    },
    {
      "x": -6,
      "y": -3,
      "z": 5,
      "name": "Wood_Fig_Blue_Trunk_Full"
    },
    {
      "x": -6,
      "y": -2,
      "z": 5,
      "name": "Wood_Fig_Blue_Trunk"
    },
    {
      "x": -6,
      "y": -1,
      "z": 5,
      "name": "Wood_Fig_Blue_Trunk"
    },
    {
      "x": -6,
      "y": 0,
      "z": 5,
      "name": "Wood_Fig_Blue_Trunk"
    },
    {
      "x": -6,
      "y": 1,
      "z": 5,
      "name": "Wood_Fig_Blue_Trunk"
    },
    {
      "x": -6,
      "y": 2,
      "z": 5,
      "name": "Wood_Fig_Blue_Trunk"
    },
    {
      "x": -6,
      "y": 3,
      "z": 5,
      "name": "Wood_Fig_Blue_Trunk"
    },
    {
      "x": -6,
      "y": 4,
      "z": 5,
      "name": "Wood_Fig_Blue_Trunk"
    },
    {
      "x": -6,
      "y": 5,
      "z": 5,
      "name": "Wood_Fig_Blue_Trunk"
    },
    {
      "x": -6,
      "y": 6,
      "z": 5,
      "name": "Wood_Fig_Blue_Trunk"
    },
    {
      "x": -6,
      "y": 7,
      "z": 5,
      "name": "Wood_Fig_Blue_Trunk"
    },
    {
      "x": -6,
      "y": 8,
      "z": 5,
      "name": "Wood_Fig_Blue_Trunk"
    },
    {
      "x": -6,
      "y": 9,
      "z": 5,
      "name": "Wood_Fig_Blue_Trunk"
    },
    {
      "x": -6,
      "y": 10,
      "z": 5,
      "name": "Wood_Fig_Blue_Trunk"
    },
    {
      "x": -6,
      "y": 11,
      "z": 5,
      "name": "Wood_Fig_Blue_Trunk"
    },
    {
      "x": -6,
      "y": 12,
      "z": 5,
      "name": "Wood_Fig_Blue_Trunk"
    },
    {
      "x": -6,
      "y": 13,
      "z": 5,
      "name": "Wood_Fig_Blue_Trunk"
    },
    {
      "x": -6,
      "y": -3,
      "z": 6,
      "name": "Wood_Fig_Blue_Trunk_Full"
    },
    {
      "x": -6,
      "y": -2,
      "z": 6,
      "name": "Wood_Fig_Blue_Trunk"
    },
    {
      "x": -6,
      "y": -1,
      "z": 6,
      "name": "Wood_Fig_Blue_Trunk"
    },
    {
      "x": -6,
      "y": 0,
      "z": 6,
      "name": "Wood_Fig_Blue_Trunk"
    },
    {
      "x": -6,
      "y": 1,
      "z": 6,
      "name": "Wood_Fig_Blue_Trunk"
    },
    {
      "x": -6,
      "y": 2,
      "z": 6,
      "name": "Wood_Fig_Blue_Trunk"
    },
    {
      "x": -6,
      "y": 3,
      "z": 6,
      "name": "Wood_Fig_Blue_Trunk"
    },
    {
      "x": -6,
      "y": 4,
      "z": 6,
      "name": "Wood_Fig_Blue_Trunk"
    },
    {
      "x": -6,
      "y": 5,
      "z": 6,
      "name": "Wood_Fig_Blue_Trunk"
    },
    {
      "x": -6,
      "y": 6,
      "z": 6,
      "name": "Wood_Fig_Blue_Trunk"
    },
    {
      "x": -6,
      "y": 7,
      "z": 6,
      "name": "Wood_Fig_Blue_Trunk"
    },
    {
      "x": -6,
      "y": 8,
      "z": 6,
      "name": "Wood_Fig_Blue_Trunk"
    },
    {
      "x": -6,
      "y": 9,
      "z": 6,
      "name": "Wood_Fig_Blue_Trunk"
    },
    {
      "x": -6,
      "y": 10,
      "z": 6,
      "name": "Wood_Fig_Blue_Trunk"
    },
    {
      "x": -6,
      "y": 11,
      "z": 6,
      "name": "Wood_Fig_Blue_Trunk"
    },
    {
      "x": -6,
      "y": 12,
      "z": 6,
      "name": "Wood_Fig_Blue_Trunk"
    },
    {
      "x": -6,
      "y": 13,
      "z": 6,
      "name": "Wood_Fig_Blue_Trunk"
    },
    {
      "x": -6,
      "y": -3,
      "z": 7,
      "name": "Wood_Fig_Blue_Trunk_Full"
    },
    {
      "x": -6,
      "y": -2,
      "z": 7,
      "name": "Wood_Fig_Blue_Trunk"
    },
    {
      "x": -6,
      "y": -1,
      "z": 7,
      "name": "Wood_Fig_Blue_Trunk"
    },
    {
      "x": -6,
      "y": 0,
      "z": 7,
      "name": "Wood_Fig_Blue_Trunk"
    },
    {
      "x": -6,
      "y": 1,
      "z": 7,
      "name": "Wood_Fig_Blue_Trunk"
    },
    {
      "x": -6,
      "y": 2,
      "z": 7,
      "name": "Wood_Fig_Blue_Trunk"
    },
    {
      "x": -6,
      "y": 3,
      "z": 7,
      "name": "Wood_Fig_Blue_Trunk"
    },
    {
      "x": -6,
      "y": 4,
      "z": 7,
      "name": "Wood_Fig_Blue_Trunk"
    },
    {
      "x": -6,
      "y": 5,
      "z": 7,
      "name": "Wood_Fig_Blue_Trunk"
    },
    {
      "x": -6,
      "y": 6,
      "z": 7,
      "name": "Wood_Fig_Blue_Trunk"
    },
    {
      "x": -6,
      "y": 7,
      "z": 7,
      "name": "Wood_Fig_Blue_Trunk"
    },
    {
      "x": -6,
      "y": 8,
      "z": 7,
      "name": "Wood_Fig_Blue_Trunk"
    },
    {
      "x": -6,
      "y": 9,
      "z": 7,
      "name": "Wood_Fig_Blue_Trunk"
    },
    {
      "x": -6,
      "y": 10,
      "z": 7,
      "name": "Wood_Fig_Blue_Trunk"
    },
    {
      "x": -6,
      "y": 11,
      "z": 7,
      "name": "Wood_Fig_Blue_Trunk"
    },
    {
      "x": -6,
      "y": 12,
      "z": 7,
      "name": "Wood_Fig_Blue_Trunk"
    },
    {
      "x": -6,
      "y": 13,
      "z": 7,
      "name": "Wood_Fig_Blue_Trunk"
    },
    {
      "x": -6,
      "y": -4,
      "z": 8,
      "name": "Wood_Fig_Blue_Trunk_Full"
    },
    {
      "x": -6,
      "y": -3,
      "z": 8,
      "name": "Wood_Fig_Blue_Trunk"
    },
    {
      "x": -6,
      "y": -2,
      "z": 8,
      "name": "Wood_Fig_Blue_Trunk"
    },
    {
      "x": -6,
      "y": -1,
      "z": 8,
      "name": "Wood_Fig_Blue_Trunk"
    },
    {
      "x": -6,
      "y": 0,
      "z": 8,
      "name": "Wood_Fig_Blue_Trunk"
    },
    {
      "x": -6,
      "y": 1,
      "z": 8,
      "name": "Wood_Fig_Blue_Trunk"
    },
    {
      "x": -6,
      "y": 2,
      "z": 8,
      "name": "Wood_Fig_Blue_Trunk"
    },
    {
      "x": -6,
      "y": 3,
      "z": 8,
      "name": "Wood_Fig_Blue_Trunk"
    },
    {
      "x": -6,
      "y": 4,
      "z": 8,
      "name": "Wood_Fig_Blue_Trunk"
    },
    {
      "x": -6,
      "y": 5,
      "z": 8,
      "name": "Wood_Fig_Blue_Trunk"
    },
    {
      "x": -6,
      "y": 6,
      "z": 8,
      "name": "Wood_Fig_Blue_Trunk"
    },
    {
      "x": -6,
      "y": 7,
      "z": 8,
      "name": "Wood_Fig_Blue_Trunk"
    },
    {
      "x": -6,
      "y": 8,
      "z": 8,
      "name": "Wood_Fig_Blue_Trunk"
    },
    {
      "x": -6,
      "y": 9,
      "z": 8,
      "name": "Wood_Fig_Blue_Trunk"
    },
    {
      "x": -6,
      "y": 10,
      "z": 8,
      "name": "Wood_Fig_Blue_Trunk_Full"
    },
    {
      "x": -6,
      "y": -4,
      "z": 9,
      "name": "Wood_Fig_Blue_Trunk_Full"
    },
    {
      "x": -6,
      "y": -3,
      "z": 9,
      "name": "Wood_Fig_Blue_Trunk"
    },
    {
      "x": -6,
      "y": -2,
      "z": 9,
      "name": "Wood_Fig_Blue_Trunk"
    },
    {
      "x": -6,
      "y": -1,
      "z": 9,
      "name": "Wood_Fig_Blue_Trunk"
    },
    {
      "x": -6,
      "y": 0,
      "z": 9,
      "name": "Wood_Fig_Blue_Trunk"
    },
    {
      "x": -6,
      "y": 1,
      "z": 9,
      "name": "Wood_Fig_Blue_Trunk"
    },
    {
      "x": -6,
      "y": 2,
      "z": 9,
      "name": "Wood_Fig_Blue_Trunk"
    },
    {
      "x": -6,
      "y": 3,
      "z": 9,
      "name": "Wood_Fig_Blue_Trunk"
    },
    {
      "x": -6,
      "y": 4,
      "z": 9,
      "name": "Wood_Fig_Blue_Trunk"
    },
    {
      "x": -6,
      "y": 5,
      "z": 9,
      "name": "Wood_Fig_Blue_Trunk_Full"
    },
    {
      "x": -6,
      "y": 7,
      "z": 9,
      "name": "Plant_Crop_Mushroom_Block_Red"
    },
    {
      "x": -6,
      "y": 9,
      "z": 9,
      "name": "Plant_Crop_Mushroom_Block_Red"
    },
    {
      "x": -6,
      "y": -4,
      "z": 10,
      "name": "Wood_Fig_Blue_Trunk_Full"
    },
    {
      "x": -6,
      "y": -3,
      "z": 10,
      "name": "Wood_Fig_Blue_Trunk"
    },
    {
      "x": -6,
      "y": -2,
      "z": 10,
      "name": "Wood_Fig_Blue_Trunk"
    },
    {
      "x": -6,
      "y": -1,
      "z": 10,
      "name": "Wood_Fig_Blue_Trunk"
    },
    {
      "x": -6,
      "y": 0,
      "z": 10,
      "name": "Wood_Fig_Blue_Trunk"
    },
    {
      "x": -6,
      "y": 1,
      "z": 10,
      "name": "Wood_Fig_Blue_Trunk"
    },
    {
      "x": -6,
      "y": 2,
      "z": 10,
      "name": "Wood_Fig_Blue_Trunk_Full"
    },
    {
      "x": -6,
      "y": 8,
      "z": 10,
      "name": "Plant_Crop_Mushroom_Block_Red_Mycelium"
    },
    {
      "x": -6,
      "y": 9,
      "z": 10,
      "name": "Plant_Crop_Mushroom_Block_Red"
    },
    {
      "x": -6,
      "y": 10,
      "z": 10,
      "name": "Plant_Crop_Mushroom_Cap_Red",
      "components": {
        "Components": {
          "FarmingBlock": {}
        }
      }
    },
    {
      "x": -6,
      "y": -2,
      "z": 11,
      "name": "Wood_Fig_Blue_Trunk_Full"
    },
    {
      "x": -6,
      "y": -1,
      "z": 11,
      "name": "Wood_Fig_Blue_Trunk"
    },
    {
      "x": -6,
      "y": 0,
      "z": 11,
      "name": "Wood_Fig_Blue_Trunk"
    },
    {
      "x": -6,
      "y": 1,
      "z": 11,
      "name": "Wood_Fig_Blue_Trunk_Full"
    },
    {
      "x": -6,
      "y": 8,
      "z": 11,
      "name": "Plant_Crop_Mushroom_Block_Red_Mycelium"
    },
    {
      "x": -6,
      "y": 9,
      "z": 11,
      "name": "Plant_Crop_Mushroom_Block_Red"
    },
    {
      "x": -6,
      "y": -2,
      "z": 12,
      "name": "Wood_Fig_Blue_Trunk_Full"
    },
    {
      "x": -6,
      "y": -1,
      "z": 12,
      "name": "Wood_Fig_Blue_Trunk_Full"
    },
    {
      "x": -6,
      "y": 8,
      "z": 12,
      "name": "Plant_Crop_Mushroom_Block_Red_Mycelium"
    },
    {
      "x": -6,
      "y": 9,
      "z": 12,
      "name": "Plant_Crop_Mushroom_Block_Red"
    },
    {
      "x": -5,
      "y": -7,
      "z": -14,
      "name": "Wood_Fig_Blue_Trunk_Full"
    },
    {
      "x": -5,
      "y": -6,
      "z": -14,
      "name": "Wood_Fig_Blue_Trunk"
    },
    {
      "x": -5,
      "y": -5,
      "z": -14,
      "name": "Wood_Fig_Blue_Trunk"
    },
    {
      "x": -5,
      "y": -4,
      "z": -14,
      "name": "Wood_Fig_Blue_Trunk_Full"
    },
    {
      "x": -5,
      "y": -8,
      "z": -13,
      "name": "Wood_Fig_Blue_Trunk_Full"
    },
    {
      "x": -5,
      "y": -7,
      "z": -13,
      "name": "Wood_Fig_Blue_Trunk"
    },
    {
      "x": -5,
      "y": -6,
      "z": -13,
      "name": "Wood_Fig_Blue_Trunk"
    },
    {
      "x": -5,
      "y": -5,
      "z": -13,
      "name": "Wood_Fig_Blue_Trunk"
    },
    {
      "x": -5,
      "y": -4,
      "z": -13,
      "name": "Wood_Fig_Blue_Trunk"
    },
    {
      "x": -5,
      "y": -3,
      "z": -13,
      "name": "Wood_Fig_Blue_Trunk_Full"
    },
    {
      "x": -5,
      "y": -7,
      "z": -12,
      "name": "Wood_Fig_Blue_Trunk_Full"
    },
    {
      "x": -5,
      "y": -6,
      "z": -12,
      "name": "Wood_Fig_Blue_Trunk"
    },
    {
      "x": -5,
      "y": -5,
      "z": -12,
      "name": "Wood_Fig_Blue_Trunk"
    },
    {
      "x": -5,
      "y": -4,
      "z": -12,
      "name": "Wood_Fig_Blue_Trunk"
    },
    {
      "x": -5,
      "y": -3,
      "z": -12,
      "name": "Wood_Fig_Blue_Trunk"
    },
    {
      "x": -5,
      "y": -2,
      "z": -12,
      "name": "Wood_Fig_Blue_Trunk"
    },
    {
      "x": -5,
      "y": -1,
      "z": -12,
      "name": "Wood_Fig_Blue_Trunk"
    },
    {
      "x": -5,
      "y": 0,
      "z": -12,
      "name": "Wood_Fig_Blue_Trunk_Full"
    },
    {
      "x": -5,
      "y": -4,
      "z": -11,
      "name": "Wood_Fig_Blue_Trunk_Full"
    },
    {
      "x": -5,
      "y": 1,
      "z": -5,
      "name": "Wood_Fig_Blue_Trunk_Full"
    },
    {
      "x": -5,
      "y": 2,
      "z": -5,
      "name": "Wood_Fig_Blue_Trunk"
    },
    {
      "x": -5,
      "y": 3,
      "z": -5,
      "name": "Wood_Fig_Blue_Trunk"
    },
    {
      "x": -5,
      "y": 4,
      "z": -5,
      "name": "Wood_Fig_Blue_Trunk_Full"
    },
    {
      "x": -5,
      "y": -3,
      "z": -4,
      "name": "Wood_Fig_Blue_Trunk_Full"
    },
    {
      "x": -5,
      "y": -2,
      "z": -4,
      "name": "Wood_Fig_Blue_Trunk"
    },
    {
      "x": -5,
      "y": -1,
      "z": -4,
      "name": "Wood_Fig_Blue_Trunk"
    },
    {
      "x": -5,
      "y": 0,
      "z": -4,
      "name": "Wood_Fig_Blue_Trunk"
    },
    {
      "x": -5,
      "y": 1,
      "z": -4,
      "name": "Wood_Fig_Blue_Trunk"
    },
    {
      "x": -5,
      "y": 2,
      "z": -4,
      "name": "Wood_Fig_Blue_Trunk"
    },
    {
      "x": -5,
      "y": 3,
      "z": -4,
      "name": "Wood_Fig_Blue_Trunk"
    },
    {
      "x": -5,
      "y": 4,
      "z": -4,
      "name": "Wood_Fig_Blue_Trunk"
    },
    {
      "x": -5,
      "y": 5,
      "z": -4,
      "name": "Wood_Fig_Blue_Trunk"
    },
    {
      "x": -5,
      "y": 6,
      "z": -4,
      "name": "Wood_Fig_Blue_Trunk_Full"
    },
    {
      "x": -5,
      "y": -3,
      "z": -3,
      "name": "Wood_Fig_Blue_Trunk_Full"
    },
    {
      "x": -5,
      "y": -2,
      "z": -3,
      "name": "Wood_Fig_Blue_Trunk"
    },
    {
      "x": -5,
      "y": -1,
      "z": -3,
      "name": "Wood_Fig_Blue_Trunk"
    },
    {
      "x": -5,
      "y": 0,
      "z": -3,
      "name": "Wood_Fig_Blue_Trunk"
    },
    {
      "x": -5,
      "y": 1,
      "z": -3,
      "name": "Wood_Fig_Blue_Trunk"
    },
    {
      "x": -5,
      "y": 2,
      "z": -3,
      "name": "Wood_Fig_Blue_Trunk"
    },
    {
      "x": -5,
      "y": 3,
      "z": -3,
      "name": "Wood_Fig_Blue_Trunk"
    },
    {
      "x": -5,
      "y": 4,
      "z": -3,
      "name": "Wood_Fig_Blue_Trunk"
    },
    {
      "x": -5,
      "y": 5,
      "z": -3,
      "name": "Wood_Fig_Blue_Trunk"
    },
    {
      "x": -5,
      "y": 6,
      "z": -3,
      "name": "Plant_Moss_Block_Red"
    },
    {
      "x": -5,
      "y": 7,
      "z": -3,
      "name": "Plant_Moss_Block_Red"
    },
    {
      "x": -5,
      "y": -2,
      "z": -2,
      "name": "Wood_Fig_Blue_Trunk_Full"
    },
    {
      "x": -5,
      "y": -1,
      "z": -2,
      "name": "Wood_Fig_Blue_Trunk"
    },
    {
      "x": -5,
      "y": 0,
      "z": -2,
      "name": "Wood_Fig_Blue_Trunk"
    },
    {
      "x": -5,
      "y": 1,
      "z": -2,
      "name": "Wood_Fig_Blue_Trunk"
    },
    {
      "x": -5,
      "y": 2,
      "z": -2,
      "name": "Wood_Fig_Blue_Trunk"
    },
    {
      "x": -5,
      "y": 3,
      "z": -2,
      "name": "Wood_Fig_Blue_Trunk"
    },
    {
      "x": -5,
      "y": 4,
      "z": -2,
      "name": "Wood_Fig_Blue_Trunk"
    },
    {
      "x": -5,
      "y": 5,
      "z": -2,
      "name": "Wood_Fig_Blue_Trunk"
    },
    {
      "x": -5,
      "y": 6,
      "z": -2,
      "name": "Wood_Fig_Blue_Trunk"
    },
    {
      "x": -5,
      "y": 7,
      "z": -2,
      "name": "Plant_Moss_Block_Red"
    },
    {
      "x": -5,
      "y": 8,
      "z": -2,
      "name": "Plant_Moss_Red"
    },
    {
      "x": -5,
      "y": -1,
      "z": -1,
      "name": "Wood_Fig_Blue_Trunk_Full"
    },
    {
      "x": -5,
      "y": 0,
      "z": -1,
      "name": "Wood_Fig_Blue_Trunk"
    },
    {
      "x": -5,
      "y": 1,
      "z": -1,
      "name": "Wood_Fig_Blue_Trunk"
    },
    {
      "x": -5,
      "y": 2,
      "z": -1,
      "name": "Wood_Fig_Blue_Trunk"
    },
    {
      "x": -5,
      "y": 3,
      "z": -1,
      "name": "Wood_Fig_Blue_Trunk"
    },
    {
      "x": -5,
      "y": 4,
      "z": -1,
      "name": "Wood_Fig_Blue_Trunk"
    },
    {
      "x": -5,
      "y": 5,
      "z": -1,
      "name": "Wood_Fig_Blue_Trunk"
    },
    {
      "x": -5,
      "y": 6,
      "z": -1,
      "name": "Wood_Fig_Blue_Trunk"
    },
    {
      "x": -5,
      "y": 7,
      "z": -1,
      "name": "Plant_Moss_Block_Red"
    },
    {
      "x": -5,
      "y": 8,
      "z": -1,
      "name": "Plant_Moss_Rug_Red"
    },
    {
      "x": -5,
      "y": -1,
      "z": 0,
      "name": "Wood_Fig_Blue_Trunk_Full"
    },
    {
      "x": -5,
      "y": 0,
      "z": 0,
      "name": "Wood_Fig_Blue_Trunk"
    },
    {
      "x": -5,
      "y": 1,
      "z": 0,
      "name": "Wood_Fig_Blue_Trunk"
    },
    {
      "x": -5,
      "y": 2,
      "z": 0,
      "name": "Wood_Fig_Blue_Trunk"
    },
    {
      "x": -5,
      "y": 3,
      "z": 0,
      "name": "Wood_Fig_Blue_Trunk"
    },
    {
      "x": -5,
      "y": 4,
      "z": 0,
      "name": "Wood_Fig_Blue_Trunk"
    },
    {
      "x": -5,
      "y": 5,
      "z": 0,
      "name": "Wood_Fig_Blue_Trunk"
    },
    {
      "x": -5,
      "y": 6,
      "z": 0,
      "name": "Wood_Fig_Blue_Trunk"
    },
    {
      "x": -5,
      "y": 7,
      "z": 0,
      "name": "Plant_Moss_Block_Red"
    },
    {
      "x": -5,
      "y": 8,
      "z": 0,
      "name": "Plant_Moss_Block_Red"
    },
    {
      "x": -5,
      "y": 9,
      "z": 0,
      "name": "Plant_Moss_Red"
    },
    {
      "x": -5,
      "y": -1,
      "z": 1,
      "name": "Wood_Fig_Blue_Trunk_Full"
    },
    {
      "x": -5,
      "y": 0,
      "z": 1,
      "name": "Wood_Fig_Blue_Trunk"
    },
    {
      "x": -5,
      "y": 1,
      "z": 1,
      "name": "Wood_Fig_Blue_Trunk"
    },
    {
      "x": -5,
      "y": 2,
      "z": 1,
      "name": "Wood_Fig_Blue_Trunk"
    },
    {
      "x": -5,
      "y": 3,
      "z": 1,
      "name": "Wood_Fig_Blue_Trunk"
    },
    {
      "x": -5,
      "y": 4,
      "z": 1,
      "name": "Wood_Fig_Blue_Trunk"
    },
    {
      "x": -5,
      "y": 5,
      "z": 1,
      "name": "Wood_Fig_Blue_Trunk"
    },
    {
      "x": -5,
      "y": 6,
      "z": 1,
      "name": "Wood_Fig_Blue_Trunk"
    },
    {
      "x": -5,
      "y": 7,
      "z": 1,
      "name": "Wood_Fig_Blue_Trunk"
    },
    {
      "x": -5,
      "y": 8,
      "z": 1,
      "name": "Plant_Moss_Block_Red"
    },
    {
      "x": -5,
      "y": 10,
      "z": 1,
      "name": "Wood_Fig_Blue_Trunk_Full"
    },
    {
      "x": -5,
      "y": 11,
      "z": 1,
      "name": "Wood_Fig_Blue_Trunk"
    },
    {
      "x": -5,
      "y": 12,
      "z": 1,
      "name": "Wood_Fig_Blue_Trunk"
    },
    {
      "x": -5,
      "y": 13,
      "z": 1,
      "name": "Wood_Fig_Blue_Trunk"
    },
    {
      "x": -5,
      "y": -2,
      "z": 2,
      "name": "Wood_Fig_Blue_Trunk_Full"
    },
    {
      "x": -5,
      "y": -1,
      "z": 2,
      "name": "Wood_Fig_Blue_Trunk"
    },
    {
      "x": -5,
      "y": 0,
      "z": 2,
      "name": "Wood_Fig_Blue_Trunk"
    },
    {
      "x": -5,
      "y": 1,
      "z": 2,
      "name": "Wood_Fig_Blue_Trunk"
    },
    {
      "x": -5,
      "y": 2,
      "z": 2,
      "name": "Wood_Fig_Blue_Trunk"
    },
    {
      "x": -5,
      "y": 3,
      "z": 2,
      "name": "Wood_Fig_Blue_Trunk"
    },
    {
      "x": -5,
      "y": 4,
      "z": 2,
      "name": "Wood_Fig_Blue_Trunk"
    },
    {
      "x": -5,
      "y": 5,
      "z": 2,
      "name": "Wood_Fig_Blue_Trunk"
    },
    {
      "x": -5,
      "y": 6,
      "z": 2,
      "name": "Wood_Fig_Blue_Trunk"
    },
    {
      "x": -5,
      "y": 7,
      "z": 2,
      "name": "Wood_Fig_Blue_Trunk"
    },
    {
      "x": -5,
      "y": 8,
      "z": 2,
      "name": "Wood_Fig_Blue_Trunk"
    },
    {
      "x": -5,
      "y": 9,
      "z": 2,
      "name": "Wood_Fig_Blue_Trunk"
    },
    {
      "x": -5,
      "y": 10,
      "z": 2,
      "name": "Wood_Fig_Blue_Trunk"
    },
    {
      "x": -5,
      "y": 11,
      "z": 2,
      "name": "Wood_Fig_Blue_Trunk"
    },
    {
      "x": -5,
      "y": 12,
      "z": 2,
      "name": "Wood_Fig_Blue_Trunk"
    },
    {
      "x": -5,
      "y": 13,
      "z": 2,
      "name": "Wood_Fig_Blue_Trunk"
    },
    {
      "x": -5,
      "y": -2,
      "z": 3,
      "name": "Wood_Fig_Blue_Trunk_Full"
    },
    {
      "x": -5,
      "y": -1,
      "z": 3,
      "name": "Wood_Fig_Blue_Trunk"
    },
    {
      "x": -5,
      "y": 0,
      "z": 3,
      "name": "Wood_Fig_Blue_Trunk"
    },
    {
      "x": -5,
      "y": 1,
      "z": 3,
      "name": "Wood_Fig_Blue_Trunk"
    },
    {
      "x": -5,
      "y": 2,
      "z": 3,
      "name": "Wood_Fig_Blue_Trunk"
    },
    {
      "x": -5,
      "y": 3,
      "z": 3,
      "name": "Wood_Fig_Blue_Trunk"
    },
    {
      "x": -5,
      "y": 4,
      "z": 3,
      "name": "Wood_Fig_Blue_Trunk"
    },
    {
      "x": -5,
      "y": 5,
      "z": 3,
      "name": "Wood_Fig_Blue_Trunk"
    },
    {
      "x": -5,
      "y": 6,
      "z": 3,
      "name": "Wood_Fig_Blue_Trunk"
    },
    {
      "x": -5,
      "y": 7,
      "z": 3,
      "name": "Wood_Fig_Blue_Trunk"
    },
    {
      "x": -5,
      "y": 8,
      "z": 3,
      "name": "Wood_Fig_Blue_Trunk"
    },
    {
      "x": -5,
      "y": 9,
      "z": 3,
      "name": "Wood_Fig_Blue_Trunk"
    },
    {
      "x": -5,
      "y": 10,
      "z": 3,
      "name": "Wood_Fig_Blue_Trunk"
    },
    {
      "x": -5,
      "y": 11,
      "z": 3,
      "name": "Wood_Fig_Blue_Trunk"
    },
    {
      "x": -5,
      "y": -3,
      "z": 4,
      "name": "Wood_Fig_Blue_Trunk_Full"
    },
    {
      "x": -5,
      "y": -2,
      "z": 4,
      "name": "Wood_Fig_Blue_Trunk"
    },
    {
      "x": -5,
      "y": -1,
      "z": 4,
      "name": "Wood_Fig_Blue_Trunk"
    },
    {
      "x": -5,
      "y": 0,
      "z": 4,
      "name": "Wood_Fig_Blue_Trunk"
    },
    {
      "x": -5,
      "y": 1,
      "z": 4,
      "name": "Wood_Fig_Blue_Trunk"
    },
    {
      "x": -5,
      "y": 2,
      "z": 4,
      "name": "Wood_Fig_Blue_Trunk"
    },
    {
      "x": -5,
      "y": 3,
      "z": 4,
      "name": "Wood_Fig_Blue_Trunk"
    },
    {
      "x": -5,
      "y": 4,
      "z": 4,
      "name": "Wood_Fig_Blue_Trunk"
    },
    {
      "x": -5,
      "y": 5,
      "z": 4,
      "name": "Wood_Fig_Blue_Trunk"
    },
    {
      "x": -5,
      "y": 6,
      "z": 4,
      "name": "Wood_Fig_Blue_Trunk"
    },
    {
      "x": -5,
      "y": 7,
      "z": 4,
      "name": "Wood_Fig_Blue_Trunk"
    },
    {
      "x": -5,
      "y": 8,
      "z": 4,
      "name": "Wood_Fig_Blue_Trunk"
    },
    {
      "x": -5,
      "y": 9,
      "z": 4,
      "name": "Wood_Fig_Blue_Trunk"
    },
    {
      "x": -5,
      "y": 10,
      "z": 4,
      "name": "Wood_Fig_Blue_Trunk"
    },
    {
      "x": -5,
      "y": -3,
      "z": 5,
      "name": "Wood_Fig_Blue_Trunk_Full"
    },
    {
      "x": -5,
      "y": -2,
      "z": 5,
      "name": "Wood_Fig_Blue_Trunk"
    },
    {
      "x": -5,
      "y": -1,
      "z": 5,
      "name": "Wood_Fig_Blue_Trunk"
    },
    {
      "x": -5,
      "y": 0,
      "z": 5,
      "name": "Wood_Fig_Blue_Trunk"
    },
    {
      "x": -5,
      "y": 1,
      "z": 5,
      "name": "Wood_Fig_Blue_Trunk"
    },
    {
      "x": -5,
      "y": 2,
      "z": 5,
      "name": "Wood_Fig_Blue_Trunk"
    },
    {
      "x": -5,
      "y": 3,
      "z": 5,
      "name": "Wood_Fig_Blue_Trunk"
    },
    {
      "x": -5,
      "y": 4,
      "z": 5,
      "name": "Wood_Fig_Blue_Trunk"
    },
    {
      "x": -5,
      "y": 5,
      "z": 5,
      "name": "Wood_Fig_Blue_Trunk"
    },
    {
      "x": -5,
      "y": 6,
      "z": 5,
      "name": "Wood_Fig_Blue_Trunk"
    },
    {
      "x": -5,
      "y": 7,
      "z": 5,
      "name": "Wood_Fig_Blue_Trunk"
    },
    {
      "x": -5,
      "y": 8,
      "z": 5,
      "name": "Wood_Fig_Blue_Trunk"
    },
    {
      "x": -5,
      "y": 9,
      "z": 5,
      "name": "Wood_Fig_Blue_Trunk"
    },
    {
      "x": -5,
      "y": 10,
      "z": 5,
      "name": "Wood_Fig_Blue_Trunk"
    },
    {
      "x": -5,
      "y": 11,
      "z": 5,
      "name": "Wood_Fig_Blue_Trunk"
    },
    {
      "x": -5,
      "y": -3,
      "z": 6,
      "name": "Wood_Fig_Blue_Trunk_Full"
    },
    {
      "x": -5,
      "y": -2,
      "z": 6,
      "name": "Wood_Fig_Blue_Trunk"
    },
    {
      "x": -5,
      "y": -1,
      "z": 6,
      "name": "Wood_Fig_Blue_Trunk"
    },
    {
      "x": -5,
      "y": 0,
      "z": 6,
      "name": "Wood_Fig_Blue_Trunk"
    },
    {
      "x": -5,
      "y": 1,
      "z": 6,
      "name": "Wood_Fig_Blue_Trunk"
    },
    {
      "x": -5,
      "y": 2,
      "z": 6,
      "name": "Wood_Fig_Blue_Trunk"
    },
    {
      "x": -5,
      "y": 3,
      "z": 6,
      "name": "Wood_Fig_Blue_Trunk"
    },
    {
      "x": -5,
      "y": 4,
      "z": 6,
      "name": "Wood_Fig_Blue_Trunk"
    },
    {
      "x": -5,
      "y": 5,
      "z": 6,
      "name": "Wood_Fig_Blue_Trunk"
    },
    {
      "x": -5,
      "y": 6,
      "z": 6,
      "name": "Wood_Fig_Blue_Trunk"
    },
    {
      "x": -5,
      "y": 7,
      "z": 6,
      "name": "Wood_Fig_Blue_Trunk"
    },
    {
      "x": -5,
      "y": 8,
      "z": 6,
      "name": "Wood_Fig_Blue_Trunk"
    },
    {
      "x": -5,
      "y": 9,
      "z": 6,
      "name": "Wood_Fig_Blue_Trunk"
    },
    {
      "x": -5,
      "y": 10,
      "z": 6,
      "name": "Wood_Fig_Blue_Trunk"
    },
    {
      "x": -5,
      "y": 11,
      "z": 6,
      "name": "Wood_Fig_Blue_Trunk"
    },
    {
      "x": -5,
      "y": 12,
      "z": 6,
      "name": "Wood_Fig_Blue_Trunk"
    },
    {
      "x": -5,
      "y": 13,
      "z": 6,
      "name": "Wood_Fig_Blue_Trunk"
    },
    {
      "x": -5,
      "y": -3,
      "z": 7,
      "name": "Wood_Fig_Blue_Trunk_Full"
    },
    {
      "x": -5,
      "y": -2,
      "z": 7,
      "name": "Wood_Fig_Blue_Trunk"
    },
    {
      "x": -5,
      "y": -1,
      "z": 7,
      "name": "Wood_Fig_Blue_Trunk"
    },
    {
      "x": -5,
      "y": 0,
      "z": 7,
      "name": "Wood_Fig_Blue_Trunk"
    },
    {
      "x": -5,
      "y": 1,
      "z": 7,
      "name": "Wood_Fig_Blue_Trunk"
    },
    {
      "x": -5,
      "y": 2,
      "z": 7,
      "name": "Wood_Fig_Blue_Trunk"
    },
    {
      "x": -5,
      "y": 3,
      "z": 7,
      "name": "Wood_Fig_Blue_Trunk"
    },
    {
      "x": -5,
      "y": 4,
      "z": 7,
      "name": "Wood_Fig_Blue_Trunk"
    },
    {
      "x": -5,
      "y": 5,
      "z": 7,
      "name": "Wood_Fig_Blue_Trunk"
    },
    {
      "x": -5,
      "y": 6,
      "z": 7,
      "name": "Wood_Fig_Blue_Trunk"
    },
    {
      "x": -5,
      "y": 7,
      "z": 7,
      "name": "Wood_Fig_Blue_Trunk"
    },
    {
      "x": -5,
      "y": 8,
      "z": 7,
      "name": "Wood_Fig_Blue_Trunk"
    },
    {
      "x": -5,
      "y": 9,
      "z": 7,
      "name": "Wood_Fig_Blue_Trunk"
    },
    {
      "x": -5,
      "y": 10,
      "z": 7,
      "name": "Wood_Fig_Blue_Trunk"
    },
    {
      "x": -5,
      "y": 11,
      "z": 7,
      "name": "Wood_Fig_Blue_Trunk"
    },
    {
      "x": -5,
      "y": 12,
      "z": 7,
      "name": "Wood_Fig_Blue_Trunk"
    },
    {
      "x": -5,
      "y": -4,
      "z": 8,
      "name": "Wood_Fig_Blue_Trunk_Full"
    },
    {
      "x": -5,
      "y": -3,
      "z": 8,
      "name": "Wood_Fig_Blue_Trunk"
    },
    {
      "x": -5,
      "y": -2,
      "z": 8,
      "name": "Wood_Fig_Blue_Trunk"
    },
    {
      "x": -5,
      "y": -1,
      "z": 8,
      "name": "Wood_Fig_Blue_Trunk"
    },
    {
      "x": -5,
      "y": 0,
      "z": 8,
      "name": "Wood_Fig_Blue_Trunk"
    },
    {
      "x": -5,
      "y": 1,
      "z": 8,
      "name": "Wood_Fig_Blue_Trunk"
    },
    {
      "x": -5,
      "y": 2,
      "z": 8,
      "name": "Wood_Fig_Blue_Trunk"
    },
    {
      "x": -5,
      "y": 3,
      "z": 8,
      "name": "Wood_Fig_Blue_Trunk"
    },
    {
      "x": -5,
      "y": 4,
      "z": 8,
      "name": "Wood_Fig_Blue_Trunk"
    },
    {
      "x": -5,
      "y": 5,
      "z": 8,
      "name": "Wood_Fig_Blue_Trunk"
    },
    {
      "x": -5,
      "y": 6,
      "z": 8,
      "name": "Wood_Fig_Blue_Trunk"
    },
    {
      "x": -5,
      "y": 7,
      "z": 8,
      "name": "Wood_Fig_Blue_Trunk"
    },
    {
      "x": -5,
      "y": 8,
      "z": 8,
      "name": "Wood_Fig_Blue_Trunk"
    },
    {
      "x": -5,
      "y": 9,
      "z": 8,
      "name": "Wood_Fig_Blue_Trunk"
    },
    {
      "x": -5,
      "y": 10,
      "z": 8,
      "name": "Wood_Fig_Blue_Trunk"
    },
    {
      "x": -5,
      "y": -3,
      "z": 9,
      "name": "Wood_Fig_Blue_Trunk_Full"
    },
    {
      "x": -5,
      "y": -2,
      "z": 9,
      "name": "Wood_Fig_Blue_Trunk"
    },
    {
      "x": -5,
      "y": -1,
      "z": 9,
      "name": "Wood_Fig_Blue_Trunk"
    },
    {
      "x": -5,
      "y": 0,
      "z": 9,
      "name": "Wood_Fig_Blue_Trunk"
    },
    {
      "x": -5,
      "y": 1,
      "z": 9,
      "name": "Wood_Fig_Blue_Trunk"
    },
    {
      "x": -5,
      "y": 2,
      "z": 9,
      "name": "Wood_Fig_Blue_Trunk"
    },
    {
      "x": -5,
      "y": 3,
      "z": 9,
      "name": "Wood_Fig_Blue_Trunk"
    },
    {
      "x": -5,
      "y": 4,
      "z": 9,
      "name": "Wood_Fig_Blue_Trunk"
    },
    {
      "x": -5,
      "y": 5,
      "z": 9,
      "name": "Wood_Fig_Blue_Trunk"
    },
    {
      "x": -5,
      "y": 6,
      "z": 9,
      "name": "Wood_Fig_Blue_Trunk"
    },
    {
      "x": -5,
      "y": 7,
      "z": 9,
      "name": "Wood_Fig_Blue_Trunk"
    },
    {
      "x": -5,
      "y": 8,
      "z": 9,
      "name": "Wood_Fig_Blue_Trunk"
    },
    {
      "x": -5,
      "y": 9,
      "z": 9,
      "name": "Wood_Fig_Blue_Trunk_Full"
    },
    {
      "x": -5,
      "y": -2,
      "z": 10,
      "name": "Wood_Fig_Blue_Trunk_Full"
    },
    {
      "x": -5,
      "y": -1,
      "z": 10,
      "name": "Wood_Fig_Blue_Trunk"
    },
    {
      "x": -5,
      "y": 0,
      "z": 10,
      "name": "Wood_Fig_Blue_Trunk"
    },
    {
      "x": -5,
      "y": 1,
      "z": 10,
      "name": "Wood_Fig_Blue_Trunk"
    },
    {
      "x": -5,
      "y": 2,
      "z": 10,
      "name": "Wood_Fig_Blue_Trunk"
    },
    {
      "x": -5,
      "y": 3,
      "z": 10,
      "name": "Wood_Fig_Blue_Trunk"
    },
    {
      "x": -5,
      "y": 4,
      "z": 10,
      "name": "Wood_Fig_Blue_Trunk"
    },
    {
      "x": -5,
      "y": 5,
      "z": 10,
      "name": "Wood_Fig_Blue_Trunk"
    },
    {
      "x": -5,
      "y": 6,
      "z": 10,
      "name": "Wood_Fig_Blue_Trunk_Full"
    },
    {
      "x": -5,
      "y": 9,
      "z": 10,
      "name": "Plant_Crop_Mushroom_Block_Red"
    },
    {
      "x": -5,
      "y": -3,
      "z": 11,
      "name": "Wood_Fig_Blue_Trunk_Full"
    },
    {
      "x": -5,
      "y": -2,
      "z": 11,
      "name": "Wood_Fig_Blue_Trunk"
    },
    {
      "x": -5,
      "y": -1,
      "z": 11,
      "name": "Wood_Fig_Blue_Trunk"
    },
    {
      "x": -5,
      "y": 0,
      "z": 11,
      "name": "Wood_Fig_Blue_Trunk"
    },
    {
      "x": -5,
      "y": 1,
      "z": 11,
      "name": "Wood_Fig_Blue_Trunk"
    },
    {
      "x": -5,
      "y": 2,
      "z": 11,
      "name": "Wood_Fig_Blue_Trunk_Full"
    },
    {
      "x": -5,
      "y": 8,
      "z": 11,
      "name": "Plant_Crop_Mushroom_Block_Red_Mycelium"
    },
    {
      "x": -5,
      "y": 9,
      "z": 11,
      "name": "Plant_Crop_Mushroom_Block_Red"
    },
    {
      "x": -5,
      "y": -4,
      "z": 12,
      "name": "Wood_Fig_Blue_Trunk_Full"
    },
    {
      "x": -5,
      "y": -3,
      "z": 12,
      "name": "Wood_Fig_Blue_Trunk"
    },
    {
      "x": -5,
      "y": -2,
      "z": 12,
      "name": "Wood_Fig_Blue_Trunk"
    },
    {
      "x": -5,
      "y": -1,
      "z": 12,
      "name": "Wood_Fig_Blue_Trunk"
    },
    {
      "x": -5,
      "y": 0,
      "z": 12,
      "name": "Wood_Fig_Blue_Trunk"
    },
    {
      "x": -5,
      "y": 1,
      "z": 12,
      "name": "Wood_Fig_Blue_Trunk"
    },
    {
      "x": -5,
      "y": 2,
      "z": 12,
      "name": "Wood_Fig_Blue_Trunk_Full"
    },
    {
      "x": -5,
      "y": 9,
      "z": 12,
      "name": "Plant_Crop_Mushroom_Block_Red"
    },
    {
      "x": -5,
      "y": -4,
      "z": 13,
      "name": "Wood_Fig_Blue_Trunk_Full"
    },
    {
      "x": -5,
      "y": -3,
      "z": 13,
      "name": "Wood_Fig_Blue_Trunk"
    },
    {
      "x": -5,
      "y": -2,
      "z": 13,
      "name": "Wood_Fig_Blue_Trunk"
    },
    {
      "x": -5,
      "y": -1,
      "z": 13,
      "name": "Wood_Fig_Blue_Trunk"
    },
    {
      "x": -5,
      "y": 0,
      "z": 13,
      "name": "Wood_Fig_Blue_Trunk_Full"
    },
    {
      "x": -4,
      "y": -7,
      "z": -13,
      "name": "Wood_Fig_Blue_Trunk_Full"
    },
    {
      "x": -4,
      "y": -6,
      "z": -13,
      "name": "Wood_Fig_Blue_Trunk_Full"
    },
    {
      "x": -4,
      "y": -4,
      "z": -13,
      "name": "Wood_Fig_Blue_Trunk_Full"
    },
    {
      "x": -4,
      "y": -3,
      "z": -13,
      "name": "Wood_Fig_Blue_Trunk"
    },
    {
      "x": -4,
      "y": -2,
      "z": -13,
      "name": "Wood_Fig_Blue_Trunk"
    },
    {
      "x": -4,
      "y": -1,
      "z": -13,
      "name": "Wood_Fig_Blue_Trunk"
    },
    {
      "x": -4,
      "y": 0,
      "z": -13,
      "name": "Wood_Fig_Blue_Trunk_Full"
    },
    {
      "x": -4,
      "y": -6,
      "z": -12,
      "name": "Wood_Fig_Blue_Trunk_Full"
    },
    {
      "x": -4,
      "y": -5,
      "z": -12,
      "name": "Wood_Fig_Blue_Trunk"
    },
    {
      "x": -4,
      "y": -4,
      "z": -12,
      "name": "Wood_Fig_Blue_Trunk"
    },
    {
      "x": -4,
      "y": -3,
      "z": -12,
      "name": "Wood_Fig_Blue_Trunk"
    },
    {
      "x": -4,
      "y": -2,
      "z": -12,
      "name": "Wood_Fig_Blue_Trunk"
    },
    {
      "x": -4,
      "y": -1,
      "z": -12,
      "name": "Wood_Fig_Blue_Trunk"
    },
    {
      "x": -4,
      "y": 0,
      "z": -12,
      "name": "Wood_Fig_Blue_Trunk"
    },
    {
      "x": -4,
      "y": 1,
      "z": -12,
      "name": "Wood_Fig_Blue_Trunk_Full"
    },
    {
      "x": -4,
      "y": -4,
      "z": -11,
      "name": "Wood_Fig_Blue_Trunk_Full"
    },
    {
      "x": -4,
      "y": -3,
      "z": -11,
      "name": "Wood_Fig_Blue_Trunk"
    },
    {
      "x": -4,
      "y": -2,
      "z": -11,
      "name": "Wood_Fig_Blue_Trunk"
    },
    {
      "x": -4,
      "y": -1,
      "z": -11,
      "name": "Wood_Fig_Blue_Trunk"
    },
    {
      "x": -4,
      "y": 0,
      "z": -11,
      "name": "Wood_Fig_Blue_Trunk_Full"
    },
    {
      "x": -4,
      "y": 0,
      "z": -10,
      "name": "Wood_Fig_Blue_Trunk_Full"
    },
    {
      "x": -4,
      "y": 1,
      "z": -5,
      "name": "Wood_Fig_Blue_Trunk_Full"
    },
    {
      "x": -4,
      "y": 2,
      "z": -5,
      "name": "Wood_Fig_Blue_Trunk"
    },
    {
      "x": -4,
      "y": 3,
      "z": -5,
      "name": "Wood_Fig_Blue_Trunk"
    },
    {
      "x": -4,
      "y": 4,
      "z": -5,
      "name": "Wood_Fig_Blue_Trunk"
    },
    {
      "x": -4,
      "y": 5,
      "z": -5,
      "name": "Wood_Fig_Blue_Trunk_Full"
    },
    {
      "x": -4,
      "y": -1,
      "z": -4,
      "name": "Wood_Fig_Blue_Trunk_Full"
    },
    {
      "x": -4,
      "y": 0,
      "z": -4,
      "name": "Wood_Fig_Blue_Trunk"
    },
    {
      "x": -4,
      "y": 1,
      "z": -4,
      "name": "Wood_Fig_Blue_Trunk"
    },
    {
      "x": -4,
      "y": 2,
      "z": -4,
      "name": "Wood_Fig_Blue_Trunk"
    },
    {
      "x": -4,
      "y": 3,
      "z": -4,
      "name": "Wood_Fig_Blue_Trunk"
    },
    {
      "x": -4,
      "y": 4,
      "z": -4,
      "name": "Wood_Fig_Blue_Trunk"
    },
    {
      "x": -4,
      "y": 5,
      "z": -4,
      "name": "Wood_Fig_Blue_Trunk"
    },
    {
      "x": -4,
      "y": 6,
      "z": -4,
      "name": "Wood_Fig_Blue_Trunk"
    },
    {
      "x": -4,
      "y": 7,
      "z": -4,
      "name": "Wood_Fig_Blue_Trunk_Full"
    },
    {
      "x": -4,
      "y": -1,
      "z": -3,
      "name": "Wood_Fig_Blue_Trunk_Full"
    },
    {
      "x": -4,
      "y": 0,
      "z": -3,
      "name": "Wood_Fig_Blue_Trunk"
    },
    {
      "x": -4,
      "y": 1,
      "z": -3,
      "name": "Wood_Fig_Blue_Trunk"
    },
    {
      "x": -4,
      "y": 2,
      "z": -3,
      "name": "Wood_Fig_Blue_Trunk"
    },
    {
      "x": -4,
      "y": 3,
      "z": -3,
      "name": "Wood_Fig_Blue_Trunk"
    },
    {
      "x": -4,
      "y": 4,
      "z": -3,
      "name": "Wood_Fig_Blue_Trunk"
    },
    {
      "x": -4,
      "y": 5,
      "z": -3,
      "name": "Wood_Fig_Blue_Trunk"
    },
    {
      "x": -4,
      "y": 6,
      "z": -3,
      "name": "Wood_Fig_Blue_Trunk"
    },
    {
      "x": -4,
      "y": 7,
      "z": -3,
      "name": "Wood_Fig_Blue_Trunk"
    },
    {
      "x": -4,
      "y": 8,
      "z": -3,
      "name": "Wood_Fig_Blue_Trunk_Full"
    },
    {
      "x": -4,
      "y": -1,
      "z": -2,
      "name": "Wood_Fig_Blue_Trunk_Full"
    },
    {
      "x": -4,
      "y": 0,
      "z": -2,
      "name": "Wood_Fig_Blue_Trunk"
    },
    {
      "x": -4,
      "y": 1,
      "z": -2,
      "name": "Wood_Fig_Blue_Trunk"
    },
    {
      "x": -4,
      "y": 2,
      "z": -2,
      "name": "Wood_Fig_Blue_Trunk"
    },
    {
      "x": -4,
      "y": 3,
      "z": -2,
      "name": "Wood_Fig_Blue_Trunk"
    },
    {
      "x": -4,
      "y": 4,
      "z": -2,
      "name": "Wood_Fig_Blue_Trunk"
    },
    {
      "x": -4,
      "y": 5,
      "z": -2,
      "name": "Wood_Fig_Blue_Trunk"
    },
    {
      "x": -4,
      "y": 6,
      "z": -2,
      "name": "Wood_Fig_Blue_Trunk"
    },
    {
      "x": -4,
      "y": 7,
      "z": -2,
      "name": "Wood_Fig_Blue_Trunk"
    },
    {
      "x": -4,
      "y": 8,
      "z": -2,
      "name": "Wood_Fig_Blue_Trunk_Full"
    },
    {
      "x": -4,
      "y": 9,
      "z": -2,
      "name": "Plant_Moss_Rug_Red"
    },
    {
      "x": -4,
      "y": -1,
      "z": -1,
      "name": "Wood_Fig_Blue_Trunk_Full"
    },
    {
      "x": -4,
      "y": 0,
      "z": -1,
      "name": "Wood_Fig_Blue_Trunk"
    },
    {
      "x": -4,
      "y": 1,
      "z": -1,
      "name": "Wood_Fig_Blue_Trunk"
    },
    {
      "x": -4,
      "y": 2,
      "z": -1,
      "name": "Wood_Fig_Blue_Trunk"
    },
    {
      "x": -4,
      "y": 3,
      "z": -1,
      "name": "Wood_Fig_Blue_Trunk"
    },
    {
      "x": -4,
      "y": 4,
      "z": -1,
      "name": "Wood_Fig_Blue_Trunk"
    },
    {
      "x": -4,
      "y": 5,
      "z": -1,
      "name": "Wood_Fig_Blue_Trunk"
    },
    {
      "x": -4,
      "y": 6,
      "z": -1,
      "name": "Wood_Fig_Blue_Trunk"
    },
    {
      "x": -4,
      "y": 7,
      "z": -1,
      "name": "Wood_Fig_Blue_Trunk"
    },
    {
      "x": -4,
      "y": 8,
      "z": -1,
      "name": "Plant_Moss_Block_Red"
    },
    {
      "x": -4,
      "y": 9,
      "z": -1,
      "name": "Plant_Moss_Rug_Red"
    },
    {
      "x": -4,
      "y": -1,
      "z": 0,
      "name": "Wood_Fig_Blue_Trunk_Full"
    },
    {
      "x": -4,
      "y": 0,
      "z": 0,
      "name": "Wood_Fig_Blue_Trunk"
    },
    {
      "x": -4,
      "y": 1,
      "z": 0,
      "name": "Wood_Fig_Blue_Trunk"
    },
    {
      "x": -4,
      "y": 2,
      "z": 0,
      "name": "Wood_Fig_Blue_Trunk"
    },
    {
      "x": -4,
      "y": 3,
      "z": 0,
      "name": "Wood_Fig_Blue_Trunk"
    },
    {
      "x": -4,
      "y": 4,
      "z": 0,
      "name": "Wood_Fig_Blue_Trunk"
    },
    {
      "x": -4,
      "y": 5,
      "z": 0,
      "name": "Wood_Fig_Blue_Trunk"
    },
    {
      "x": -4,
      "y": 6,
      "z": 0,
      "name": "Wood_Fig_Blue_Trunk"
    },
    {
      "x": -4,
      "y": 7,
      "z": 0,
      "name": "Wood_Fig_Blue_Trunk"
    },
    {
      "x": -4,
      "y": 8,
      "z": 0,
      "name": "Plant_Moss_Block_Red"
    },
    {
      "x": -4,
      "y": 9,
      "z": 0,
      "name": "Plant_Moss_Red"
    },
    {
      "x": -4,
      "y": -1,
      "z": 1,
      "name": "Wood_Fig_Blue_Trunk_Full"
    },
    {
      "x": -4,
      "y": 0,
      "z": 1,
      "name": "Wood_Fig_Blue_Trunk"
    },
    {
      "x": -4,
      "y": 1,
      "z": 1,
      "name": "Wood_Fig_Blue_Trunk"
    },
    {
      "x": -4,
      "y": 2,
      "z": 1,
      "name": "Wood_Fig_Blue_Trunk"
    },
    {
      "x": -4,
      "y": 3,
      "z": 1,
      "name": "Wood_Fig_Blue_Trunk"
    },
    {
      "x": -4,
      "y": 4,
      "z": 1,
      "name": "Wood_Fig_Blue_Trunk"
    },
    {
      "x": -4,
      "y": 5,
      "z": 1,
      "name": "Wood_Fig_Blue_Trunk"
    },
    {
      "x": -4,
      "y": 6,
      "z": 1,
      "name": "Wood_Fig_Blue_Trunk"
    },
    {
      "x": -4,
      "y": 7,
      "z": 1,
      "name": "Wood_Fig_Blue_Trunk"
    },
    {
      "x": -4,
      "y": 8,
      "z": 1,
      "name": "Plant_Moss_Block_Red"
    },
    {
      "x": -4,
      "y": 9,
      "z": 1,
      "name": "Plant_Moss_Red"
    },
    {
      "x": -4,
      "y": 11,
      "z": 1,
      "name": "Wood_Fig_Blue_Trunk_Full"
    },
    {
      "x": -4,
      "y": 12,
      "z": 1,
      "name": "Wood_Fig_Blue_Trunk"
    },
    {
      "x": -4,
      "y": 13,
      "z": 1,
      "name": "Wood_Fig_Blue_Trunk"
    },
    {
      "x": -4,
      "y": -2,
      "z": 2,
      "name": "Wood_Fig_Blue_Trunk_Full"
    },
    {
      "x": -4,
      "y": -1,
      "z": 2,
      "name": "Wood_Fig_Blue_Trunk"
    },
    {
      "x": -4,
      "y": 0,
      "z": 2,
      "name": "Wood_Fig_Blue_Trunk"
    },
    {
      "x": -4,
      "y": 1,
      "z": 2,
      "name": "Wood_Fig_Blue_Trunk"
    },
    {
      "x": -4,
      "y": 2,
      "z": 2,
      "name": "Wood_Fig_Blue_Trunk"
    },
    {
      "x": -4,
      "y": 3,
      "z": 2,
      "name": "Wood_Fig_Blue_Trunk"
    },
    {
      "x": -4,
      "y": 4,
      "z": 2,
      "name": "Wood_Fig_Blue_Trunk"
    },
    {
      "x": -4,
      "y": 5,
      "z": 2,
      "name": "Wood_Fig_Blue_Trunk"
    },
    {
      "x": -4,
      "y": 6,
      "z": 2,
      "name": "Wood_Fig_Blue_Trunk_Full"
    },
    {
      "x": -4,
      "y": 7,
      "z": 2,
      "name": "Wood_Fig_Blue_Trunk"
    },
    {
      "x": -4,
      "y": 8,
      "z": 2,
      "name": "Wood_Fig_Blue_Trunk_Full"
    },
    {
      "x": -4,
      "y": -3,
      "z": 3,
      "name": "Wood_Fig_Blue_Trunk_Full"
    },
    {
      "x": -4,
      "y": -2,
      "z": 3,
      "name": "Wood_Fig_Blue_Trunk"
    },
    {
      "x": -4,
      "y": -1,
      "z": 3,
      "name": "Wood_Fig_Blue_Trunk"
    },
    {
      "x": -4,
      "y": 0,
      "z": 3,
      "name": "Wood_Fig_Blue_Trunk"
    },
    {
      "x": -4,
      "y": 1,
      "z": 3,
      "name": "Wood_Fig_Blue_Trunk"
    },
    {
      "x": -4,
      "y": 2,
      "z": 3,
