{
  "version": 8,
  "blockIdVersion": 8,
  "anchorX": 1,
  "anchorY": 8,
  "anchorZ": 1,
  "blocks": [
    {
      "x": -14,
      "y": 22,
      "z": -5,
      "name": "Plant_Leaves_Oak"
    },
    {
      "x": -14,
      "y": 23,
      "z": -5,
      "name": "Plant_Leaves_Oak"
    },
    {
      "x": -14,
      "y": 22,
      "z": -4,
      "name": "Plant_Leaves_Oak"
    },
    {
      "x": -14,
      "y": 23,
      "z": -4,
      "name": "Plant_Leaves_Oak"
    },
    {
      "x": -14,
      "y": 22,
      "z": -3,
      "name": "Plant_Leaves_Oak"
    },
    {
      "x": -14,
      "y": 23,
      "z": -3,
      "name": "Plant_Leaves_Oak"
    },
    {
      "x": -14,
      "y": 22,
      "z": -2,
      "name": "Plant_Leaves_Oak"
    },
    {
      "x": -14,
      "y": 22,
      "z": -1,
      "name": "Plant_Leaves_Oak"
    },
    {
      "x": -13,
      "y": 22,
      "z": -6,
      "name": "Plant_Leaves_Oak"
    },
    {
      "x": -13,
      "y": 22,
      "z": -5,
      "name": "Plant_Leaves_Oak"
    },
    {
      "x": -13,
      "y": 21,
      "z": -4,
      "name": "Plant_Leaves_Oak"
    },
    {
      "x": -13,
      "y": 22,
      "z": -4,
      "name": "Plant_Leaves_Oak"
    },
    {
      "x": -13,
      "y": 23,
      "z": -4,
      "name": "Plant_Leaves_Oak"
    },
    {
      "x": -13,
      "y": 21,
      "z": -3,
      "name": "Plant_Leaves_Oak"
    },
    {
      "x": -13,
      "y": 22,
      "z": -3,
      "name": "Plant_Leaves_Oak"
    },
    {
      "x": -13,
      "y": 22,
      "z": -2,
      "name": "Plant_Leaves_Oak"
    },
    {
      "x": -13,
      "y": 23,
      "z": -2,
      "name": "Plant_Leaves_Oak"
    },
    {
      "x": -13,
      "y": 22,
      "z": -1,
      "name": "Plant_Leaves_Oak"
    },
    {
      "x": -13,
      "y": 22,
      "z": 0,
      "name": "Plant_Leaves_Oak"
    },
    {
      "x": -13,
      "y": 23,
      "z": 1,
      "name": "Plant_Leaves_Oak"
    },
    {
      "x": -13,
      "y": 23,
      "z": 2,
      "name": "Plant_Leaves_Oak"
    },
    {
      "x": -13,
      "y": 23,
      "z": 3,
      "name": "Plant_Leaves_Oak"
    },
    {
      "x": -12,
      "y": 22,
      "z": -6,
      "name": "Plant_Leaves_Oak"
    },
    {
      "x": -12,
      "y": 22,
      "z": -5,
      "name": "Plant_Leaves_Oak"
    },
    {
      "x": -12,
      "y": 23,
      "z": -5,
      "name": "Plant_Leaves_Oak"
    },
    {
      "x": -12,
      "y": 21,
      "z": -4,
      "name": "Plant_Leaves_Oak"
    },
    {
      "x": -12,
      "y": 22,
      "z": -4,
      "name": "Plant_Leaves_Oak"
    },
    {
      "x": -12,
      "y": 23,
      "z": -4,
      "name": "Plant_Leaves_Oak"
    },
    {
      "x": -12,
      "y": 21,
      "z": -3,
      "name": "Wood_Oak_Branch_Corner",
      "rotation": 3
    },
    {
      "x": -12,
      "y": 22,
      "z": -3,
      "name": "Plant_Leaves_Oak"
    },
    {
      "x": -12,
      "y": 23,
      "z": -3,
      "name": "Plant_Leaves_Oak"
    },
    {
      "x": -12,
      "y": 21,
      "z": -2,
      "name": "Plant_Leaves_Oak"
    },
    {
      "x": -12,
      "y": 22,
      "z": -2,
      "name": "Plant_Leaves_Oak"
    },
    {
      "x": -12,
      "y": 23,
      "z": -2,
      "name": "Plant_Leaves_Oak"
    },
    {
      "x": -12,
      "y": 22,
      "z": -1,
      "name": "Plant_Leaves_Oak"
    },
    {
      "x": -12,
      "y": 23,
      "z": 0,
      "name": "Plant_Leaves_Oak"
    },
    {
      "x": -12,
      "y": 23,
      "z": 1,
      "name": "Plant_Leaves_Oak"
    },
    {
      "x": -12,
      "y": 22,
      "z": 2,
      "name": "Plant_Leaves_Oak"
    },
    {
      "x": -12,
      "y": 23,
      "z": 2,
      "name": "Plant_Leaves_Oak"
    },
    {
      "x": -12,
      "y": 24,
      "z": 2,
      "name": "Plant_Leaves_Oak"
    },
    {
      "x": -12,
      "y": 23,
      "z": 3,
      "name": "Plant_Leaves_Oak"
    },
    {
      "x": -12,
      "y": 24,
      "z": 3,
      "name": "Plant_Leaves_Oak"
    },
    {
      "x": -12,
      "y": 27,
      "z": 3,
      "name": "Plant_Leaves_Oak"
    },
    {
      "x": -12,
      "y": 23,
      "z": 4,
      "name": "Plant_Leaves_Oak"
    },
    {
      "x": -12,
      "y": 27,
      "z": 4,
      "name": "Plant_Leaves_Oak"
    },
    {
      "x": -12,
      "y": 23,
      "z": 5,
      "name": "Plant_Leaves_Oak"
    },
    {
      "x": -12,
      "y": 27,
      "z": 5,
      "name": "Plant_Leaves_Oak"
    },
    {
      "x": -11,
      "y": 22,
      "z": -7,
      "name": "Plant_Leaves_Oak"
    },
    {
      "x": -11,
      "y": 21,
      "z": -6,
      "name": "Plant_Leaves_Oak"
    },
    {
      "x": -11,
      "y": 22,
      "z": -6,
      "name": "Plant_Leaves_Oak"
    },
    {
      "x": -11,
      "y": 23,
      "z": -6,
      "name": "Plant_Leaves_Oak"
    },
    {
      "x": -11,
      "y": 21,
      "z": -5,
      "name": "Plant_Leaves_Oak"
    },
    {
      "x": -11,
      "y": 22,
      "z": -5,
      "name": "Plant_Leaves_Oak"
    },
    {
      "x": -11,
      "y": 23,
      "z": -5,
      "name": "Plant_Leaves_Oak"
    },
    {
      "x": -11,
      "y": 21,
      "z": -4,
      "name": "Plant_Leaves_Oak"
    },
    {
      "x": -11,
      "y": 22,
      "z": -4,
      "name": "Plant_Leaves_Oak"
    },
    {
      "x": -11,
      "y": 23,
      "z": -4,
      "name": "Plant_Leaves_Oak"
    },
    {
      "x": -11,
      "y": 26,
      "z": -4,
      "name": "Plant_Leaves_Oak"
    },
    {
      "x": -11,
      "y": 21,
      "z": -3,
      "name": "Wood_Oak_Branch_Long",
      "rotation": 5
    },
    {
      "x": -11,
      "y": 22,
      "z": -3,
      "name": "Plant_Leaves_Oak"
    },
    {
      "x": -11,
      "y": 23,
      "z": -3,
      "name": "Plant_Leaves_Oak"
    },
    {
      "x": -11,
      "y": 21,
      "z": -2,
      "name": "Plant_Leaves_Oak"
    },
    {
      "x": -11,
      "y": 22,
      "z": -2,
      "name": "Plant_Leaves_Oak"
    },
    {
      "x": -11,
      "y": 23,
      "z": -2,
      "name": "Plant_Leaves_Oak"
    },
    {
      "x": -11,
      "y": 22,
      "z": -1,
      "name": "Plant_Leaves_Oak"
    },
    {
      "x": -11,
      "y": 26,
      "z": -1,
      "name": "Plant_Leaves_Oak"
    },
    {
      "x": -11,
      "y": 22,
      "z": 0,
      "name": "Plant_Leaves_Oak"
    },
    {
      "x": -11,
      "y": 23,
      "z": 0,
      "name": "Plant_Leaves_Oak"
    },
    {
      "x": -11,
      "y": 26,
      "z": 0,
      "name": "Plant_Leaves_Oak"
    },
    {
      "x": -11,
      "y": 22,
      "z": 1,
      "name": "Plant_Leaves_Oak"
    },
    {
      "x": -11,
      "y": 23,
      "z": 1,
      "name": "Plant_Leaves_Oak"
    },
    {
      "x": -11,
      "y": 26,
      "z": 1,
      "name": "Plant_Leaves_Oak"
    },
    {
      "x": -11,
      "y": 22,
      "z": 2,
      "name": "Plant_Leaves_Oak"
    },
    {
      "x": -11,
      "y": 23,
      "z": 2,
      "name": "Plant_Leaves_Oak"
    },
    {
      "x": -11,
      "y": 24,
      "z": 2,
      "name": "Plant_Leaves_Oak"
    },
    {
      "x": -11,
      "y": 27,
      "z": 2,
      "name": "Plant_Leaves_Oak"
    },
    {
      "x": -11,
      "y": 22,
      "z": 3,
      "name": "Plant_Leaves_Oak"
    },
    {
      "x": -11,
      "y": 23,
      "z": 3,
      "name": "Plant_Leaves_Oak"
    },
    {
      "x": -11,
      "y": 24,
      "z": 3,
      "name": "Plant_Leaves_Oak"
    },
    {
      "x": -11,
      "y": 27,
      "z": 3,
      "name": "Plant_Leaves_Oak"
    },
    {
      "x": -11,
      "y": 21,
      "z": 4,
      "name": "Plant_Leaves_Oak"
    },
    {
      "x": -11,
      "y": 23,
      "z": 4,
      "name": "Plant_Leaves_Oak"
    },
    {
      "x": -11,
      "y": 24,
      "z": 4,
      "name": "Plant_Leaves_Oak"
    },
    {
      "x": -11,
      "y": 27,
      "z": 4,
      "name": "Plant_Leaves_Oak"
    },
    {
      "x": -11,
      "y": 28,
      "z": 4,
      "name": "Plant_Leaves_Oak"
    },
    {
      "x": -11,
      "y": 21,
      "z": 5,
      "name": "Plant_Leaves_Oak"
    },
    {
      "x": -11,
      "y": 23,
      "z": 5,
      "name": "Plant_Leaves_Oak"
    },
    {
      "x": -11,
      "y": 27,
      "z": 5,
      "name": "Plant_Leaves_Oak"
    },
    {
      "x": -11,
      "y": 21,
      "z": 6,
      "name": "Plant_Leaves_Oak"
    },
    {
      "x": -11,
      "y": 27,
      "z": 6,
      "name": "Plant_Leaves_Oak"
    },
    {
      "x": -10,
      "y": 22,
      "z": -7,
      "name": "Plant_Leaves_Oak"
    },
    {
      "x": -10,
      "y": 22,
      "z": -6,
      "name": "Plant_Leaves_Oak"
    },
    {
      "x": -10,
      "y": 23,
      "z": -6,
      "name": "Plant_Leaves_Oak"
    },
    {
      "x": -10,
      "y": 21,
      "z": -5,
      "name": "Plant_Leaves_Oak"
    },
    {
      "x": -10,
      "y": 22,
      "z": -5,
      "name": "Plant_Leaves_Oak"
    },
    {
      "x": -10,
      "y": 23,
      "z": -5,
      "name": "Plant_Leaves_Oak"
    },
    {
      "x": -10,
      "y": 26,
      "z": -5,
      "name": "Plant_Leaves_Oak"
    },
    {
      "x": -10,
      "y": 21,
      "z": -4,
      "name": "Wood_Oak_Branch_Corner",
      "rotation": 2
    },
    {
      "x": -10,
      "y": 22,
      "z": -4,
      "name": "Plant_Leaves_Oak"
    },
    {
      "x": -10,
      "y": 23,
      "z": -4,
      "name": "Plant_Leaves_Oak"
    },
    {
      "x": -10,
      "y": 25,
      "z": -4,
      "name": "Plant_Leaves_Oak"
    },
    {
      "x": -10,
      "y": 26,
      "z": -4,
      "name": "Plant_Leaves_Oak"
    },
    {
      "x": -10,
      "y": 21,
      "z": -3,
      "name": "Wood_Oak_Trunk_Full"
    },
    {
      "x": -10,
      "y": 22,
      "z": -3,
      "name": "Plant_Leaves_Oak"
    },
    {
      "x": -10,
      "y": 23,
      "z": -3,
      "name": "Plant_Leaves_Oak"
    },
    {
      "x": -10,
      "y": 25,
      "z": -3,
      "name": "Plant_Leaves_Oak"
    },
    {
      "x": -10,
      "y": 22,
      "z": -2,
      "name": "Plant_Leaves_Oak"
    },
    {
      "x": -10,
      "y": 26,
      "z": -2,
      "name": "Plant_Leaves_Oak"
    },
    {
      "x": -10,
      "y": 18,
      "z": -1,
      "name": "Plant_Leaves_Oak"
    },
    {
      "x": -10,
      "y": 22,
      "z": -1,
      "name": "Plant_Leaves_Oak"
    },
    {
      "x": -10,
      "y": 23,
      "z": -1,
      "name": "Plant_Leaves_Oak"
    },
    {
      "x": -10,
      "y": 25,
      "z": -1,
      "name": "Plant_Leaves_Oak"
    },
    {
      "x": -10,
      "y": 26,
      "z": -1,
      "name": "Plant_Leaves_Oak"
    },
    {
      "x": -10,
      "y": 27,
      "z": -1,
      "name": "Plant_Leaves_Oak"
    },
    {
      "x": -10,
      "y": 18,
      "z": 0,
      "name": "Plant_Leaves_Oak"
    },
    {
      "x": -10,
      "y": 22,
      "z": 0,
      "name": "Plant_Leaves_Oak"
    },
    {
      "x": -10,
      "y": 23,
      "z": 0,
      "name": "Plant_Leaves_Oak"
    },
    {
      "x": -10,
      "y": 26,
      "z": 0,
      "name": "Plant_Leaves_Oak"
    },
    {
      "x": -10,
      "y": 22,
      "z": 1,
      "name": "Plant_Leaves_Oak"
    },
    {
      "x": -10,
      "y": 23,
      "z": 1,
      "name": "Plant_Leaves_Oak"
    },
    {
      "x": -10,
      "y": 24,
      "z": 1,
      "name": "Plant_Leaves_Oak"
    },
    {
      "x": -10,
      "y": 26,
      "z": 1,
      "name": "Plant_Leaves_Oak"
    },
    {
      "x": -10,
      "y": 27,
      "z": 1,
      "name": "Plant_Leaves_Oak"
    },
    {
      "x": -10,
      "y": 22,
      "z": 2,
      "name": "Plant_Leaves_Oak"
    },
    {
      "x": -10,
      "y": 23,
      "z": 2,
      "name": "Plant_Leaves_Oak"
    },
    {
      "x": -10,
      "y": 24,
      "z": 2,
      "name": "Plant_Leaves_Oak"
    },
    {
      "x": -10,
      "y": 26,
      "z": 2,
      "name": "Plant_Leaves_Oak"
    },
    {
      "x": -10,
      "y": 27,
      "z": 2,
      "name": "Plant_Leaves_Oak"
    },
    {
      "x": -10,
      "y": 28,
      "z": 2,
      "name": "Plant_Leaves_Oak"
    },
    {
      "x": -10,
      "y": 21,
      "z": 3,
      "name": "Plant_Leaves_Oak"
    },
    {
      "x": -10,
      "y": 22,
      "z": 3,
      "name": "Plant_Leaves_Oak"
    },
    {
      "x": -10,
      "y": 23,
      "z": 3,
      "name": "Plant_Leaves_Oak"
    },
    {
      "x": -10,
      "y": 24,
      "z": 3,
      "name": "Plant_Leaves_Oak"
    },
    {
      "x": -10,
      "y": 26,
      "z": 3,
      "name": "Plant_Leaves_Oak"
    },
    {
      "x": -10,
      "y": 27,
      "z": 3,
      "name": "Plant_Leaves_Oak"
    },
    {
      "x": -10,
      "y": 21,
      "z": 4,
      "name": "Plant_Leaves_Oak"
    },
    {
      "x": -10,
      "y": 23,
      "z": 4,
      "name": "Plant_Leaves_Oak"
    },
    {
      "x": -10,
      "y": 24,
      "z": 4,
      "name": "Plant_Leaves_Oak"
    },
    {
      "x": -10,
      "y": 27,
      "z": 4,
      "name": "Plant_Leaves_Oak"
    },
    {
      "x": -10,
      "y": 28,
      "z": 4,
      "name": "Plant_Leaves_Oak"
    },
    {
      "x": -10,
      "y": 20,
      "z": 5,
      "name": "Plant_Leaves_Oak"
    },
    {
      "x": -10,
      "y": 21,
      "z": 5,
      "name": "Plant_Leaves_Oak"
    },
    {
      "x": -10,
      "y": 23,
      "z": 5,
      "name": "Plant_Leaves_Oak"
    },
    {
      "x": -10,
      "y": 24,
      "z": 5,
      "name": "Plant_Leaves_Oak"
    },
    {
      "x": -10,
      "y": 27,
      "z": 5,
      "name": "Plant_Leaves_Oak"
    },
    {
      "x": -10,
      "y": 28,
      "z": 5,
      "name": "Plant_Leaves_Oak"
    },
    {
      "x": -10,
      "y": 21,
      "z": 6,
      "name": "Plant_Leaves_Oak"
    },
    {
      "x": -10,
      "y": 23,
      "z": 6,
      "name": "Plant_Leaves_Oak"
    },
    {
      "x": -10,
      "y": 27,
      "z": 6,
      "name": "Plant_Leaves_Oak"
    },
    {
      "x": -10,
      "y": 21,
      "z": 7,
      "name": "Plant_Leaves_Oak"
    },
    {
      "x": -10,
      "y": 27,
      "z": 7,
      "name": "Plant_Leaves_Oak"
    },
    {
      "x": -9,
      "y": 22,
      "z": -6,
      "name": "Plant_Leaves_Oak"
    },
    {
      "x": -9,
      "y": 22,
      "z": -5,
      "name": "Plant_Leaves_Oak"
    },
    {
      "x": -9,
      "y": 26,
      "z": -5,
      "name": "Plant_Leaves_Oak"
    },
    {
      "x": -9,
      "y": 21,
      "z": -4,
      "name": "Plant_Leaves_Oak"
    },
    {
      "x": -9,
      "y": 22,
      "z": -4,
      "name": "Plant_Leaves_Oak"
    },
    {
      "x": -9,
      "y": 23,
      "z": -4,
      "name": "Plant_Leaves_Oak"
    },
    {
      "x": -9,
      "y": 25,
      "z": -4,
      "name": "Plant_Leaves_Oak"
    },
    {
      "x": -9,
      "y": 26,
      "z": -4,
      "name": "Plant_Leaves_Oak"
    },
    {
      "x": -9,
      "y": 21,
      "z": -3,
      "name": "Wood_Oak_Trunk_Full"
    },
    {
      "x": -9,
      "y": 22,
      "z": -3,
      "name": "Plant_Leaves_Oak"
    },
    {
      "x": -9,
      "y": 25,
      "z": -3,
      "name": "Plant_Leaves_Oak"
    },
    {
      "x": -9,
      "y": 26,
      "z": -3,
      "name": "Plant_Leaves_Oak"
    },
    {
      "x": -9,
      "y": 27,
      "z": -3,
      "name": "Plant_Leaves_Oak"
    },
    {
      "x": -9,
      "y": 18,
      "z": -2,
      "name": "Plant_Leaves_Oak"
    },
    {
      "x": -9,
      "y": 22,
      "z": -2,
      "name": "Wood_Oak_Trunk_Full"
    },
    {
      "x": -9,
      "y": 25,
      "z": -2,
      "name": "Plant_Leaves_Oak"
    },
    {
      "x": -9,
      "y": 26,
      "z": -2,
      "name": "Plant_Leaves_Oak"
    },
    {
      "x": -9,
      "y": 27,
      "z": -2,
      "name": "Plant_Leaves_Oak"
    },
    {
      "x": -9,
      "y": 28,
      "z": -2,
      "name": "Plant_Leaves_Oak"
    },
    {
      "x": -9,
      "y": 18,
      "z": -1,
      "name": "Plant_Leaves_Oak"
    },
    {
      "x": -9,
      "y": 22,
      "z": -1,
      "name": "Plant_Leaves_Oak"
    },
    {
      "x": -9,
      "y": 23,
      "z": -1,
      "name": "Plant_Leaves_Oak"
    },
    {
      "x": -9,
      "y": 25,
      "z": -1,
      "name": "Plant_Leaves_Oak"
    },
    {
      "x": -9,
      "y": 26,
      "z": -1,
      "name": "Plant_Leaves_Oak"
    },
    {
      "x": -9,
      "y": 18,
      "z": 0,
      "name": "Plant_Leaves_Oak"
    },
    {
      "x": -9,
      "y": 23,
      "z": 0,
      "name": "Plant_Leaves_Oak"
    },
    {
      "x": -9,
      "y": 26,
      "z": 0,
      "name": "Plant_Leaves_Oak"
    },
    {
      "x": -9,
      "y": 23,
      "z": 1,
      "name": "Plant_Leaves_Oak"
    },
    {
      "x": -9,
      "y": 24,
      "z": 1,
      "name": "Plant_Leaves_Oak"
    },
    {
      "x": -9,
      "y": 26,
      "z": 1,
      "name": "Plant_Leaves_Oak"
    },
    {
      "x": -9,
      "y": 27,
      "z": 1,
      "name": "Plant_Leaves_Oak"
    },
    {
      "x": -9,
      "y": 21,
      "z": 2,
      "name": "Plant_Leaves_Oak"
    },
    {
      "x": -9,
      "y": 22,
      "z": 2,
      "name": "Wood_Oak_Branch_Long",
      "rotation": 5
    },
    {
      "x": -9,
      "y": 23,
      "z": 2,
      "name": "Plant_Leaves_Oak"
    },
    {
      "x": -9,
      "y": 24,
      "z": 2,
      "name": "Plant_Leaves_Oak"
    },
    {
      "x": -9,
      "y": 26,
      "z": 2,
      "name": "Plant_Leaves_Oak"
    },
    {
      "x": -9,
      "y": 27,
      "z": 2,
      "name": "Plant_Leaves_Oak"
    },
    {
      "x": -9,
      "y": 21,
      "z": 3,
      "name": "Plant_Leaves_Oak"
    },
    {
      "x": -9,
      "y": 23,
      "z": 3,
      "name": "Plant_Leaves_Oak"
    },
    {
      "x": -9,
      "y": 24,
      "z": 3,
      "name": "Plant_Leaves_Oak"
    },
    {
      "x": -9,
      "y": 26,
      "z": 3,
      "name": "Plant_Leaves_Oak"
    },
    {
      "x": -9,
      "y": 27,
      "z": 3,
      "name": "Plant_Leaves_Oak"
    },
    {
      "x": -9,
      "y": 28,
      "z": 3,
      "name": "Plant_Leaves_Oak"
    },
    {
      "x": -9,
      "y": 20,
      "z": 4,
      "name": "Plant_Leaves_Oak"
    },
    {
      "x": -9,
      "y": 21,
      "z": 4,
      "name": "Plant_Leaves_Oak"
    },
    {
      "x": -9,
      "y": 22,
      "z": 4,
      "name": "Plant_Leaves_Oak"
    },
    {
      "x": -9,
      "y": 23,
      "z": 4,
      "name": "Plant_Leaves_Oak"
    },
    {
      "x": -9,
      "y": 24,
      "z": 4,
      "name": "Plant_Leaves_Oak"
    },
    {
      "x": -9,
      "y": 26,
      "z": 4,
      "name": "Plant_Leaves_Oak"
    },
    {
      "x": -9,
      "y": 27,
      "z": 4,
      "name": "Plant_Leaves_Oak"
    },
    {
      "x": -9,
      "y": 28,
      "z": 4,
      "name": "Plant_Leaves_Oak"
    },
    {
      "x": -9,
      "y": 21,
      "z": 5,
      "name": "Plant_Leaves_Oak"
    },
    {
      "x": -9,
      "y": 22,
      "z": 5,
      "name": "Plant_Leaves_Oak"
    },
    {
      "x": -9,
      "y": 23,
      "z": 5,
      "name": "Plant_Leaves_Oak"
    },
    {
      "x": -9,
      "y": 24,
      "z": 5,
      "name": "Plant_Leaves_Oak"
    },
    {
      "x": -9,
      "y": 26,
      "z": 5,
      "name": "Plant_Leaves_Oak"
    },
    {
      "x": -9,
      "y": 27,
      "z": 5,
      "name": "Plant_Leaves_Oak"
    },
    {
      "x": -9,
      "y": 28,
      "z": 5,
      "name": "Plant_Leaves_Oak"
    },
    {
      "x": -9,
      "y": 21,
      "z": 6,
      "name": "Plant_Leaves_Oak"
    },
    {
      "x": -9,
      "y": 23,
      "z": 6,
      "name": "Plant_Leaves_Oak"
    },
    {
      "x": -9,
      "y": 27,
      "z": 6,
      "name": "Plant_Leaves_Oak"
    },
    {
      "x": -9,
      "y": 28,
      "z": 6,
      "name": "Plant_Leaves_Oak"
    },
    {
      "x": -9,
      "y": 21,
      "z": 7,
      "name": "Plant_Leaves_Oak"
    },
    {
      "x": -9,
      "y": 27,
      "z": 7,
      "name": "Plant_Leaves_Oak"
    },
    {
      "x": -9,
      "y": 21,
      "z": 8,
      "name": "Plant_Leaves_Oak"
    },
    {
      "x": -8,
      "y": 22,
      "z": -6,
      "name": "Plant_Leaves_Oak"
    },
    {
      "x": -8,
      "y": 25,
      "z": -6,
      "name": "Plant_Leaves_Oak"
    },
    {
      "x": -8,
      "y": 22,
      "z": -5,
      "name": "Plant_Leaves_Oak"
    },
    {
      "x": -8,
      "y": 23,
      "z": -5,
      "name": "Plant_Leaves_Oak"
    },
    {
      "x": -8,
      "y": 25,
      "z": -5,
      "name": "Plant_Leaves_Oak"
    },
    {
      "x": -8,
      "y": 26,
      "z": -5,
      "name": "Plant_Leaves_Oak"
    },
    {
      "x": -8,
      "y": 22,
      "z": -4,
      "name": "Plant_Leaves_Oak"
    },
    {
      "x": -8,
      "y": 25,
      "z": -4,
      "name": "Plant_Leaves_Oak"
    },
    {
      "x": -8,
      "y": 26,
      "z": -4,
      "name": "Plant_Leaves_Oak"
    },
    {
      "x": -8,
      "y": 27,
      "z": -4,
      "name": "Plant_Leaves_Oak"
    },
    {
      "x": -8,
      "y": 22,
      "z": -3,
      "name": "Plant_Leaves_Oak"
    },
    {
      "x": -8,
      "y": 25,
      "z": -3,
      "name": "Plant_Leaves_Oak"
    },
    {
      "x": -8,
      "y": 26,
      "z": -3,
      "name": "Plant_Leaves_Oak"
    },
    {
      "x": -8,
      "y": 27,
      "z": -3,
      "name": "Plant_Leaves_Oak"
    },
    {
      "x": -8,
      "y": 28,
      "z": -3,
      "name": "Plant_Leaves_Oak"
    },
    {
      "x": -8,
      "y": 18,
      "z": -2,
      "name": "Plant_Leaves_Oak"
    },
    {
      "x": -8,
      "y": 22,
      "z": -2,
      "name": "Wood_Oak_Trunk_Full"
    },
    {
      "x": -8,
      "y": 25,
      "z": -2,
      "name": "Plant_Leaves_Oak"
    },
    {
      "x": -8,
      "y": 26,
      "z": -2,
      "name": "Plant_Leaves_Oak"
    },
    {
      "x": -8,
      "y": 27,
      "z": -2,
      "name": "Plant_Leaves_Oak"
    },
    {
      "x": -8,
      "y": 17,
      "z": -1,
      "name": "Plant_Leaves_Oak"
    },
    {
      "x": -8,
      "y": 18,
      "z": -1,
      "name": "Plant_Leaves_Oak"
    },
    {
      "x": -8,
      "y": 19,
      "z": -1,
      "name": "Plant_Leaves_Oak"
    },
    {
      "x": -8,
      "y": 22,
      "z": -1,
      "name": "Wood_Oak_Trunk_Full"
    },
    {
      "x": -8,
      "y": 25,
      "z": -1,
      "name": "Plant_Leaves_Oak"
    },
    {
      "x": -8,
      "y": 26,
      "z": -1,
      "name": "Plant_Leaves_Oak"
    },
    {
      "x": -8,
      "y": 27,
      "z": -1,
      "name": "Plant_Leaves_Oak"
    },
    {
      "x": -8,
      "y": 17,
      "z": 0,
      "name": "Plant_Leaves_Oak"
    },
    {
      "x": -8,
      "y": 18,
      "z": 1,
      "name": "Plant_Leaves_Oak"
    },
    {
      "x": -8,
      "y": 23,
      "z": 1,
      "name": "Plant_Leaves_Oak"
    },
    {
      "x": -8,
      "y": 26,
      "z": 1,
      "name": "Plant_Leaves_Oak"
    },
    {
      "x": -8,
      "y": 27,
      "z": 1,
      "name": "Plant_Leaves_Oak"
    },
    {
      "x": -8,
      "y": 28,
      "z": 1,
      "name": "Plant_Leaves_Oak"
    },
    {
      "x": -8,
      "y": 21,
      "z": 2,
      "name": "Plant_Leaves_Oak"
    },
    {
      "x": -8,
      "y": 22,
      "z": 2,
      "name": "Wood_Oak_Trunk_Full"
    },
    {
      "x": -8,
      "y": 23,
      "z": 2,
      "name": "Plant_Leaves_Oak"
    },
    {
      "x": -8,
      "y": 26,
      "z": 2,
      "name": "Plant_Leaves_Oak"
    },
    {
      "x": -8,
      "y": 27,
      "z": 2,
      "name": "Plant_Leaves_Oak"
    },
    {
      "x": -8,
      "y": 21,
      "z": 3,
      "name": "Plant_Leaves_Oak"
    },
    {
      "x": -8,
      "y": 23,
      "z": 3,
      "name": "Plant_Leaves_Oak"
    },
    {
      "x": -8,
      "y": 24,
      "z": 3,
      "name": "Plant_Leaves_Oak"
    },
    {
      "x": -8,
      "y": 27,
      "z": 3,
      "name": "Plant_Leaves_Oak"
    },
    {
      "x": -8,
      "y": 20,
      "z": 4,
      "name": "Plant_Leaves_Oak"
    },
    {
      "x": -8,
      "y": 21,
      "z": 4,
      "name": "Plant_Leaves_Oak"
    },
    {
      "x": -8,
      "y": 23,
      "z": 4,
      "name": "Plant_Leaves_Oak"
    },
    {
      "x": -8,
      "y": 24,
      "z": 4,
      "name": "Plant_Leaves_Oak"
    },
    {
      "x": -8,
      "y": 25,
      "z": 4,
      "name": "Plant_Leaves_Oak"
    },
    {
      "x": -8,
      "y": 26,
      "z": 4,
      "name": "Wood_Oak_Branch_Long",
      "rotation": 5
    },
    {
      "x": -8,
      "y": 27,
      "z": 4,
      "name": "Plant_Leaves_Oak"
    },
    {
      "x": -8,
      "y": 28,
      "z": 4,
      "name": "Plant_Leaves_Oak"
    },
    {
      "x": -8,
      "y": 20,
      "z": 5,
      "name": "Wood_Oak_Branch_Corner",
      "rotation": 3
    },
    {
      "x": -8,
      "y": 21,
      "z": 5,
      "name": "Plant_Leaves_Oak"
    },
    {
      "x": -8,
      "y": 23,
      "z": 5,
      "name": "Plant_Leaves_Oak"
    },
    {
      "x": -8,
      "y": 26,
      "z": 5,
      "name": "Plant_Leaves_Oak"
    },
    {
      "x": -8,
      "y": 27,
      "z": 5,
      "name": "Plant_Leaves_Oak"
    },
    {
      "x": -8,
      "y": 28,
      "z": 5,
      "name": "Plant_Leaves_Oak"
    },
    {
      "x": -8,
      "y": 20,
      "z": 6,
      "name": "Plant_Leaves_Oak"
    },
    {
      "x": -8,
      "y": 21,
      "z": 6,
      "name": "Plant_Leaves_Oak"
    },
    {
      "x": -8,
      "y": 23,
      "z": 6,
      "name": "Plant_Leaves_Oak"
    },
    {
      "x": -8,
      "y": 26,
      "z": 6,
      "name": "Plant_Leaves_Oak"
    },
    {
      "x": -8,
      "y": 27,
      "z": 6,
      "name": "Plant_Leaves_Oak"
    },
    {
      "x": -8,
      "y": 28,
      "z": 6,
      "name": "Plant_Leaves_Oak"
    },
    {
      "x": -8,
      "y": 20,
      "z": 7,
      "name": "Plant_Leaves_Oak"
    },
    {
      "x": -8,
      "y": 21,
      "z": 7,
      "name": "Plant_Leaves_Oak"
    },
    {
      "x": -8,
      "y": 27,
      "z": 7,
      "name": "Plant_Leaves_Oak"
    },
    {
      "x": -8,
      "y": 21,
      "z": 8,
      "name": "Plant_Leaves_Oak"
    },
    {
      "x": -8,
      "y": 21,
      "z": 9,
      "name": "Plant_Leaves_Oak"
    },
    {
      "x": -8,
      "y": 22,
      "z": 9,
      "name": "Plant_Leaves_Oak"
    },
    {
      "x": -8,
      "y": 21,
      "z": 10,
      "name": "Plant_Leaves_Oak"
    },
    {
      "x": -8,
      "y": 21,
      "z": 11,
      "name": "Plant_Leaves_Oak"
    },
    {
      "x": -7,
      "y": 22,
      "z": -7,
      "name": "Plant_Leaves_Oak"
    },
    {
      "x": -7,
      "y": 25,
      "z": -7,
      "name": "Plant_Leaves_Oak"
    },
    {
      "x": -7,
      "y": 26,
      "z": -7,
      "name": "Plant_Leaves_Oak"
    },
    {
      "x": -7,
      "y": 21,
      "z": -6,
      "name": "Plant_Leaves_Oak"
    },
    {
      "x": -7,
      "y": 22,
      "z": -6,
      "name": "Plant_Leaves_Oak"
    },
    {
      "x": -7,
      "y": 23,
      "z": -6,
      "name": "Plant_Leaves_Oak"
    },
    {
      "x": -7,
      "y": 25,
      "z": -6,
      "name": "Plant_Leaves_Oak"
    },
    {
      "x": -7,
      "y": 26,
      "z": -6,
      "name": "Plant_Leaves_Oak"
    },
    {
      "x": -7,
      "y": 27,
      "z": -6,
      "name": "Plant_Leaves_Oak"
    },
    {
      "x": -7,
      "y": 21,
      "z": -5,
      "name": "Plant_Leaves_Oak"
    },
    {
      "x": -7,
      "y": 22,
      "z": -5,
      "name": "Plant_Leaves_Oak"
    },
    {
      "x": -7,
      "y": 23,
      "z": -5,
      "name": "Plant_Leaves_Oak"
    },
    {
      "x": -7,
      "y": 25,
      "z": -5,
      "name": "Plant_Leaves_Oak"
    },
    {
      "x": -7,
      "y": 26,
      "z": -5,
      "name": "Plant_Leaves_Oak"
    },
    {
      "x": -7,
      "y": 22,
      "z": -4,
      "name": "Plant_Leaves_Oak"
    },
    {
      "x": -7,
      "y": 25,
      "z": -4,
      "name": "Plant_Leaves_Oak"
    },
    {
      "x": -7,
      "y": 18,
      "z": -3,
      "name": "Plant_Leaves_Oak"
    },
    {
      "x": -7,
      "y": 21,
      "z": -3,
      "name": "Wood_Oak_Trunk_Full"
    },
    {
      "x": -7,
      "y": 24,
      "z": -3,
      "name": "Wood_Oak_Branch_Corner",
      "rotation": 3
    },
    {
      "x": -7,
      "y": 25,
      "z": -3,
      "name": "Plant_Leaves_Oak"
    },
    {
      "x": -7,
      "y": 26,
      "z": -3,
      "name": "Plant_Leaves_Oak"
    },
    {
      "x": -7,
      "y": 18,
      "z": -2,
      "name": "Plant_Leaves_Oak"
    },
    {
      "x": -7,
      "y": 21,
      "z": -2,
      "name": "Wood_Oak_Trunk_Full"
    },
    {
      "x": -7,
      "y": 25,
      "z": -2,
      "name": "Plant_Leaves_Oak"
    },
    {
      "x": -7,
      "y": 26,
      "z": -2,
      "name": "Plant_Leaves_Oak"
    },
    {
      "x": -7,
      "y": 17,
      "z": -1,
      "name": "Wood_Oak_Branch_Corner",
      "rotation": 3
    },
    {
      "x": -7,
      "y": 18,
      "z": -1,
      "name": "Plant_Leaves_Oak"
    },
    {
      "x": -7,
      "y": 19,
      "z": -1,
      "name": "Plant_Leaves_Oak"
    },
    {
      "x": -7,
      "y": 21,
      "z": -1,
      "name": "Wood_Oak_Trunk_Full"
    },
    {
      "x": -7,
      "y": 22,
      "z": -1,
      "name": "Wood_Oak_Trunk_Full"
    },
    {
      "x": -7,
      "y": 25,
      "z": -1,
      "name": "Plant_Leaves_Oak"
    },
    {
      "x": -7,
      "y": 26,
      "z": -1,
      "name": "Plant_Leaves_Oak"
    },
    {
      "x": -7,
      "y": 28,
      "z": -1,
      "name": "Plant_Leaves_Oak"
    },
    {
      "x": -7,
      "y": 17,
      "z": 0,
      "name": "Plant_Leaves_Oak"
    },
    {
      "x": -7,
      "y": 18,
      "z": 0,
      "name": "Plant_Leaves_Oak"
    },
    {
      "x": -7,
      "y": 19,
      "z": 0,
      "name": "Plant_Leaves_Oak"
    },
    {
      "x": -7,
      "y": 25,
      "z": 0,
      "name": "Plant_Leaves_Oak"
    },
    {
      "x": -7,
      "y": 26,
      "z": 0,
      "name": "Plant_Leaves_Oak"
    },
    {
      "x": -7,
      "y": 28,
      "z": 0,
      "name": "Plant_Leaves_Oak"
    },
    {
      "x": -7,
      "y": 29,
      "z": 0,
      "name": "Plant_Leaves_Oak"
    },
    {
      "x": -7,
      "y": 18,
      "z": 1,
      "name": "Plant_Leaves_Oak"
    },
    {
      "x": -7,
      "y": 22,
      "z": 1,
      "name": "Wood_Oak_Trunk_Full"
    },
    {
      "x": -7,
      "y": 25,
      "z": 1,
      "name": "Wood_Oak_Branch_Corner",
      "rotation": 3
    },
    {
      "x": -7,
      "y": 26,
      "z": 1,
      "name": "Plant_Leaves_Oak"
    },
    {
      "x": -7,
      "y": 28,
      "z": 1,
      "name": "Plant_Leaves_Oak"
    },
    {
      "x": -7,
      "y": 21,
      "z": 2,
      "name": "Plant_Leaves_Oak"
    },
    {
      "x": -7,
      "y": 22,
      "z": 2,
      "name": "Wood_Oak_Trunk_Full"
    },
    {
      "x": -7,
      "y": 26,
      "z": 2,
      "name": "Plant_Leaves_Oak"
    },
    {
      "x": -7,
      "y": 27,
      "z": 2,
      "name": "Plant_Leaves_Oak"
    },
    {
      "x": -7,
      "y": 28,
      "z": 2,
      "name": "Plant_Leaves_Oak"
    },
    {
      "x": -7,
      "y": 29,
      "z": 2,
      "name": "Plant_Leaves_Oak"
    },
    {
      "x": -7,
      "y": 21,
      "z": 3,
      "name": "Plant_Leaves_Oak"
    },
    {
      "x": -7,
      "y": 22,
      "z": 3,
      "name": "Plant_Leaves_Oak"
    },
    {
      "x": -7,
      "y": 23,
      "z": 3,
      "name": "Plant_Leaves_Oak"
    },
    {
      "x": -7,
      "y": 27,
      "z": 3,
      "name": "Plant_Leaves_Oak"
    },
    {
      "x": -7,
      "y": 21,
      "z": 4,
      "name": "Plant_Leaves_Oak"
    },
    {
      "x": -7,
      "y": 23,
      "z": 4,
      "name": "Plant_Leaves_Oak"
    },
    {
      "x": -7,
      "y": 26,
      "z": 4,
      "name": "Wood_Oak_Trunk_Full"
    },
    {
      "x": -7,
      "y": 27,
      "z": 4,
      "name": "Plant_Leaves_Oak"
    },
    {
      "x": -7,
      "y": 20,
      "z": 5,
      "name": "Wood_Oak_Trunk_Full"
    },
    {
      "x": -7,
      "y": 21,
      "z": 5,
      "name": "Plant_Leaves_Oak"
    },
    {
      "x": -7,
      "y": 26,
      "z": 5,
      "name": "Plant_Leaves_Oak"
    },
    {
      "x": -7,
      "y": 27,
      "z": 5,
      "name": "Plant_Leaves_Oak"
    },
    {
      "x": -7,
      "y": 5,
      "z": 6,
      "name": "Wood_Oak_Trunk_Full"
    },
    {
      "x": -7,
      "y": 20,
      "z": 6,
      "name": "Plant_Leaves_Oak"
    },
    {
      "x": -7,
      "y": 21,
      "z": 6,
      "name": "Plant_Leaves_Oak"
    },
    {
      "x": -7,
      "y": 26,
      "z": 6,
      "name": "Plant_Leaves_Oak"
    },
    {
      "x": -7,
      "y": 27,
      "z": 6,
      "name": "Plant_Leaves_Oak"
    },
    {
      "x": -7,
      "y": 21,
      "z": 7,
      "name": "Plant_Leaves_Oak"
    },
    {
      "x": -7,
      "y": 22,
      "z": 7,
      "name": "Plant_Leaves_Oak"
    },
    {
      "x": -7,
      "y": 27,
      "z": 7,
      "name": "Plant_Leaves_Oak"
    },
    {
      "x": -7,
      "y": 21,
      "z": 8,
      "name": "Plant_Leaves_Oak"
    },
    {
      "x": -7,
      "y": 22,
      "z": 8,
      "name": "Plant_Leaves_Oak"
    },
    {
      "x": -7,
      "y": 23,
      "z": 8,
      "name": "Plant_Leaves_Oak"
    },
    {
      "x": -7,
      "y": 21,
      "z": 9,
      "name": "Plant_Leaves_Oak"
    },
    {
      "x": -7,
      "y": 22,
      "z": 9,
      "name": "Plant_Leaves_Oak"
    },
    {
      "x": -7,
      "y": 23,
      "z": 9,
      "name": "Plant_Leaves_Oak"
    },
    {
      "x": -7,
      "y": 20,
      "z": 10,
      "name": "Plant_Leaves_Oak"
    },
    {
      "x": -7,
      "y": 21,
      "z": 10,
      "name": "Plant_Leaves_Oak"
    },
    {
      "x": -7,
      "y": 22,
      "z": 10,
      "name": "Plant_Leaves_Oak"
    },
    {
      "x": -7,
      "y": 21,
      "z": 11,
      "name": "Plant_Leaves_Oak"
    },
    {
      "x": -7,
      "y": 22,
      "z": 11,
      "name": "Plant_Leaves_Oak"
    },
    {
      "x": -7,
      "y": 21,
      "z": 12,
      "name": "Plant_Leaves_Oak"
    },
    {
      "x": -6,
      "y": 22,
      "z": -8,
      "name": "Plant_Leaves_Oak"
    },
    {
      "x": -6,
      "y": 26,
      "z": -8,
      "name": "Plant_Leaves_Oak"
    },
    {
      "x": -6,
      "y": 22,
      "z": -7,
      "name": "Plant_Leaves_Oak"
    },
    {
      "x": -6,
      "y": 23,
      "z": -7,
      "name": "Plant_Leaves_Oak"
    },
    {
      "x": -6,
      "y": 26,
      "z": -7,
      "name": "Plant_Leaves_Oak"
    },
    {
      "x": -6,
      "y": 22,
      "z": -6,
      "name": "Plant_Leaves_Oak"
    },
    {
      "x": -6,
      "y": 23,
      "z": -6,
      "name": "Plant_Leaves_Oak"
    },
    {
      "x": -6,
      "y": 26,
      "z": -6,
      "name": "Plant_Leaves_Oak"
    },
    {
      "x": -6,
      "y": 27,
      "z": -6,
      "name": "Plant_Leaves_Oak"
    },
    {
      "x": -6,
      "y": 21,
      "z": -5,
      "name": "Wood_Oak_Branch_Corner",
      "rotation": 2
    },
    {
      "x": -6,
      "y": 22,
      "z": -5,
      "name": "Plant_Leaves_Oak"
    },
    {
      "x": -6,
      "y": 23,
      "z": -5,
      "name": "Plant_Leaves_Oak"
    },
    {
      "x": -6,
      "y": 25,
      "z": -5,
      "name": "Plant_Leaves_Oak"
    },
    {
      "x": -6,
      "y": 26,
      "z": -5,
      "name": "Plant_Leaves_Oak"
    },
    {
      "x": -6,
      "y": 21,
      "z": -4,
      "name": "Wood_Oak_Trunk_Full"
    },
    {
      "x": -6,
      "y": 22,
      "z": -4,
      "name": "Plant_Leaves_Oak"
    },
    {
      "x": -6,
      "y": 23,
      "z": -4,
      "name": "Plant_Leaves_Oak"
    },
    {
      "x": -6,
      "y": 25,
      "z": -4,
      "name": "Plant_Leaves_Oak"
    },
    {
      "x": -6,
      "y": 18,
      "z": -3,
      "name": "Plant_Leaves_Oak"
    },
    {
      "x": -6,
      "y": 21,
      "z": -3,
      "name": "Wood_Oak_Trunk_Full"
    },
    {
      "x": -6,
      "y": 24,
      "z": -3,
      "name": "Wood_Oak_Trunk_Full"
    },
    {
      "x": -6,
      "y": 25,
      "z": -3,
      "name": "Plant_Leaves_Oak"
    },
    {
      "x": -6,
      "y": 26,
      "z": -3,
      "name": "Plant_Leaves_Oak"
    },
    {
      "x": -6,
      "y": 27,
      "z": -3,
      "name": "Plant_Leaves_Oak"
    },
    {
      "x": -6,
      "y": 17,
      "z": -2,
      "name": "Plant_Leaves_Oak"
    },
    {
      "x": -6,
      "y": 18,
      "z": -2,
      "name": "Plant_Leaves_Oak"
    },
    {
      "x": -6,
      "y": 19,
      "z": -2,
      "name": "Plant_Leaves_Oak"
    },
    {
      "x": -6,
      "y": 25,
      "z": -2,
      "name": "Plant_Leaves_Oak"
    },
    {
      "x": -6,
      "y": 26,
      "z": -2,
      "name": "Plant_Leaves_Oak"
    },
    {
      "x": -6,
      "y": 28,
      "z": -2,
      "name": "Plant_Leaves_Oak"
    },
    {
      "x": -6,
      "y": 3,
      "z": -1,
      "name": "Soil_Dirt"
    },
    {
      "x": -6,
      "y": 4,
      "z": -1,
      "name": "Soil_Dirt"
    },
    {
      "x": -6,
      "y": 5,
      "z": -1,
      "name": "Soil_Dirt"
    },
    {
      "x": -6,
      "y": 6,
      "z": -1,
      "name": "Soil_Dirt"
    },
    {
      "x": -6,
      "y": 7,
      "z": -1,
      "name": "Soil_Dirt"
    },
    {
      "x": -6,
      "y": 8,
      "z": -1,
      "name": "Soil_Grass_Deep"
    },
    {
      "x": -6,
      "y": 17,
      "z": -1,
      "name": "Wood_Oak_Branch_Long",
      "rotation": 5
    },
    {
      "x": -6,
      "y": 18,
      "z": -1,
      "name": "Plant_Leaves_Oak"
    },
    {
      "x": -6,
      "y": 19,
      "z": -1,
      "name": "Plant_Leaves_Oak"
    },
    {
      "x": -6,
      "y": 22,
      "z": -1,
      "name": "Wood_Oak_Trunk_Full"
    },
    {
      "x": -6,
      "y": 25,
      "z": -1,
      "name": "Plant_Leaves_Oak"
    },
    {
      "x": -6,
      "y": 26,
      "z": -1,
      "name": "Plant_Leaves_Oak"
    },
    {
      "x": -6,
      "y": 28,
      "z": -1,
      "name": "Plant_Leaves_Oak"
    },
    {
      "x": -6,
      "y": 3,
      "z": 0,
      "name": "Soil_Dirt"
    },
    {
      "x": -6,
      "y": 4,
      "z": 0,
      "name": "Soil_Dirt"
    },
    {
      "x": -6,
      "y": 5,
      "z": 0,
      "name": "Soil_Dirt"
    },
    {
      "x": -6,
      "y": 6,
      "z": 0,
      "name": "Soil_Dirt"
    },
    {
      "x": -6,
      "y": 7,
      "z": 0,
      "name": "Soil_Dirt"
    },
    {
      "x": -6,
      "y": 8,
      "z": 0,
      "name": "Soil_Grass_Deep"
    },
    {
      "x": -6,
      "y": 22,
      "z": 0,
      "name": "Wood_Oak_Trunk_Full"
    },
    {
      "x": -6,
      "y": 26,
      "z": 0,
      "name": "Plant_Leaves_Oak"
    },
    {
      "x": -6,
      "y": 28,
      "z": 0,
      "name": "Plant_Leaves_Oak"
    },
    {
      "x": -6,
      "y": 29,
      "z": 0,
      "name": "Plant_Leaves_Oak"
    },
    {
      "x": -6,
      "y": 3,
      "z": 1,
      "name": "Soil_Dirt"
    },
    {
      "x": -6,
      "y": 4,
      "z": 1,
      "name": "Soil_Dirt"
    },
    {
      "x": -6,
      "y": 5,
      "z": 1,
      "name": "Soil_Dirt"
    },
    {
      "x": -6,
      "y": 6,
      "z": 1,
      "name": "Soil_Dirt"
    },
    {
      "x": -6,
      "y": 7,
      "z": 1,
      "name": "Soil_Dirt"
    },
    {
      "x": -6,
      "y": 8,
      "z": 1,
      "name": "Soil_Grass_Deep"
    },
    {
      "x": -6,
      "y": 22,
      "z": 1,
      "name": "Wood_Oak_Trunk_Full"
    },
    {
      "x": -6,
      "y": 25,
      "z": 1,
      "name": "Wood_Oak_Trunk_Full"
    },
    {
      "x": -6,
      "y": 26,
      "z": 1,
      "name": "Plant_Leaves_Oak"
    },
    {
      "x": -6,
      "y": 28,
      "z": 1,
      "name": "Plant_Leaves_Oak"
    },
    {
      "x": -6,
      "y": 29,
      "z": 1,
      "name": "Plant_Leaves_Oak"
    },
    {
      "x": -6,
      "y": 3,
      "z": 2,
      "name": "Soil_Dirt"
    },
    {
      "x": -6,
      "y": 4,
      "z": 2,
      "name": "Soil_Dirt"
    },
    {
      "x": -6,
      "y": 5,
      "z": 2,
      "name": "Soil_Dirt"
    },
    {
      "x": -6,
      "y": 6,
      "z": 2,
      "name": "Soil_Dirt"
    },
    {
      "x": -6,
      "y": 7,
      "z": 2,
      "name": "Soil_Dirt"
    },
    {
      "x": -6,
      "y": 8,
      "z": 2,
      "name": "Soil_Leaves"
    },
    {
      "x": -6,
      "y": 28,
      "z": 2,
      "name": "Plant_Leaves_Oak"
    },
    {
      "x": -6,
      "y": 3,
      "z": 3,
      "name": "Soil_Dirt"
    },
    {
      "x": -6,
      "y": 4,
      "z": 3,
      "name": "Soil_Dirt"
    },
    {
      "x": -6,
      "y": 5,
      "z": 3,
      "name": "Soil_Dirt"
    },
    {
      "x": -6,
      "y": 6,
      "z": 3,
      "name": "Soil_Dirt"
    },
    {
      "x": -6,
      "y": 7,
      "z": 3,
      "name": "Soil_Dirt"
    },
    {
      "x": -6,
      "y": 8,
      "z": 3,
      "name": "Soil_Leaves"
    },
    {
      "x": -6,
      "y": 21,
      "z": 3,
      "name": "Plant_Leaves_Oak"
    },
    {
      "x": -6,
      "y": 26,
      "z": 3,
      "name": "Wood_Oak_Trunk_Full"
    },
    {
      "x": -6,
      "y": 28,
      "z": 3,
      "name": "Plant_Leaves_Oak"
    },
    {
      "x": -6,
      "y": 29,
      "z": 3,
      "name": "Plant_Leaves_Oak"
    },
    {
      "x": -6,
      "y": 26,
      "z": 4,
      "name": "Wood_Oak_Trunk_Full"
    },
    {
      "x": -6,
      "y": 20,
      "z": 5,
      "name": "Wood_Oak_Trunk_Full"
    },
    {
      "x": -6,
      "y": 21,
      "z": 5,
      "name": "Wood_Oak_Trunk_Full"
    },
    {
      "x": -6,
      "y": 27,
      "z": 5,
      "name": "Plant_Leaves_Oak"
    },
    {
      "x": -6,
      "y": 5,
      "z": 6,
      "name": "Wood_Oak_Trunk_Full"
    },
    {
      "x": -6,
      "y": 25,
      "z": 7,
      "name": "Plant_Leaves_Oak"
    },
    {
      "x": -6,
      "y": 21,
      "z": 8,
      "name": "Plant_Leaves_Oak"
    },
    {
      "x": -6,
      "y": 25,
      "z": 8,
      "name": "Plant_Leaves_Oak"
    },
    {
      "x": -6,
      "y": 20,
      "z": 9,
      "name": "Plant_Leaves_Oak"
    },
    {
      "x": -6,
      "y": 21,
      "z": 9,
      "name": "Plant_Leaves_Oak"
    },
    {
      "x": -6,
      "y": 22,
      "z": 9,
      "name": "Plant_Leaves_Oak"
    },
    {
      "x": -6,
      "y": 23,
      "z": 9,
      "name": "Plant_Leaves_Oak"
    },
    {
      "x": -6,
      "y": 25,
      "z": 9,
      "name": "Plant_Leaves_Oak"
    },
    {
      "x": -6,
      "y": 20,
      "z": 10,
      "name": "Plant_Leaves_Oak"
    },
    {
      "x": -6,
      "y": 21,
      "z": 10,
      "name": "Plant_Leaves_Oak"
    },
    {
      "x": -6,
      "y": 22,
      "z": 10,
      "name": "Plant_Leaves_Oak"
    },
    {
      "x": -6,
      "y": 23,
      "z": 10,
      "name": "Plant_Leaves_Oak"
    },
    {
      "x": -6,
      "y": 20,
      "z": 11,
      "name": "Plant_Leaves_Oak"
    },
    {
      "x": -6,
      "y": 21,
      "z": 11,
      "name": "Plant_Leaves_Oak"
    },
    {
      "x": -6,
      "y": 22,
      "z": 11,
      "name": "Plant_Leaves_Oak"
    },
    {
      "x": -6,
      "y": 21,
      "z": 12,
      "name": "Plant_Leaves_Oak"
    },
    {
      "x": -6,
      "y": 22,
      "z": 12,
      "name": "Plant_Leaves_Oak"
    },
    {
      "x": -6,
      "y": 21,
      "z": 13,
      "name": "Plant_Leaves_Oak"
    },
    {
      "x": -5,
      "y": 26,
      "z": -9,
      "name": "Plant_Leaves_Oak"
    },
    {
      "x": -5,
      "y": 22,
      "z": -8,
      "name": "Plant_Leaves_Oak"
    },
    {
      "x": -5,
      "y": 25,
      "z": -8,
      "name": "Plant_Leaves_Oak"
    },
    {
      "x": -5,
      "y": 26,
      "z": -8,
      "name": "Plant_Leaves_Oak"
    },
    {
      "x": -5,
      "y": 22,
      "z": -7,
      "name": "Plant_Leaves_Oak"
    },
    {
      "x": -5,
      "y": 23,
      "z": -7,
      "name": "Plant_Leaves_Oak"
    },
    {
      "x": -5,
      "y": 25,
      "z": -7,
      "name": "Plant_Leaves_Oak"
    },
    {
      "x": -5,
      "y": 26,
      "z": -7,
      "name": "Plant_Leaves_Oak"
    },
    {
      "x": -5,
      "y": 27,
      "z": -7,
      "name": "Plant_Leaves_Oak"
    },
    {
      "x": -5,
      "y": 21,
      "z": -6,
      "name": "Plant_Leaves_Oak"
    },
    {
      "x": -5,
      "y": 22,
      "z": -6,
      "name": "Plant_Leaves_Oak"
    },
    {
      "x": -5,
      "y": 23,
      "z": -6,
      "name": "Plant_Leaves_Oak"
    },
    {
      "x": -5,
      "y": 25,
      "z": -6,
      "name": "Plant_Leaves_Oak"
    },
    {
      "x": -5,
      "y": 26,
      "z": -6,
      "name": "Plant_Leaves_Oak"
    },
    {
      "x": -5,
      "y": 27,
      "z": -6,
      "name": "Plant_Leaves_Oak"
    },
    {
      "x": -5,
      "y": 21,
      "z": -5,
      "name": "Plant_Leaves_Oak"
    },
    {
      "x": -5,
      "y": 22,
      "z": -5,
      "name": "Plant_Leaves_Oak"
    },
    {
      "x": -5,
      "y": 23,
      "z": -5,
      "name": "Plant_Leaves_Oak"
    },
    {
      "x": -5,
      "y": 26,
      "z": -5,
      "name": "Plant_Leaves_Oak"
    },
    {
      "x": -5,
      "y": 27,
      "z": -5,
      "name": "Plant_Leaves_Oak"
    },
    {
      "x": -5,
      "y": 22,
      "z": -4,
      "name": "Plant_Leaves_Oak"
    },
    {
      "x": -5,
      "y": 23,
      "z": -4,
      "name": "Wood_Oak_Trunk_Full"
    },
    {
      "x": -5,
      "y": 25,
      "z": -4,
      "name": "Plant_Leaves_Oak"
    },
    {
      "x": -5,
      "y": 3,
      "z": -3,
      "name": "Soil_Dirt"
    },
    {
      "x": -5,
      "y": 4,
      "z": -3,
      "name": "Soil_Dirt"
    },
    {
      "x": -5,
      "y": 5,
      "z": -3,
      "name": "Soil_Dirt"
    },
    {
      "x": -5,
      "y": 6,
      "z": -3,
      "name": "Soil_Dirt"
    },
    {
      "x": -5,
      "y": 7,
      "z": -3,
      "name": "Soil_Dirt"
    },
    {
      "x": -5,
      "y": 8,
      "z": -3,
      "name": "Soil_Grass_Deep"
    },
    {
      "x": -5,
      "y": 18,
      "z": -3,
      "name": "Plant_Leaves_Oak"
    },
    {
      "x": -5,
      "y": 23,
      "z": -3,
      "name": "Wood_Oak_Trunk_Full"
    },
    {
      "x": -5,
      "y": 24,
      "z": -3,
      "name": "Wood_Oak_Trunk_Full"
    },
    {
      "x": -5,
      "y": 3,
      "z": -2,
      "name": "Soil_Dirt"
    },
    {
      "x": -5,
      "y": 4,
      "z": -2,
      "name": "Soil_Dirt"
    },
    {
      "x": -5,
      "y": 5,
      "z": -2,
      "name": "Soil_Dirt"
    },
    {
      "x": -5,
      "y": 6,
      "z": -2,
      "name": "Soil_Dirt"
    },
    {
      "x": -5,
      "y": 7,
      "z": -2,
      "name": "Soil_Dirt"
    },
    {
      "x": -5,
      "y": 8,
      "z": -2,
      "name": "Soil_Grass_Deep"
    },
    {
      "x": -5,
      "y": 26,
      "z": -2,
      "name": "Plant_Leaves_Oak"
    },
    {
      "x": -5,
      "y": 28,
      "z": -2,
      "name": "Plant_Leaves_Oak"
    },
    {
      "x": -5,
      "y": 29,
      "z": -2,
      "name": "Plant_Leaves_Oak"
    },
    {
      "x": -5,
      "y": 3,
      "z": -1,
      "name": "Soil_Dirt"
    },
    {
      "x": -5,
      "y": 4,
      "z": -1,
      "name": "Soil_Dirt"
    },
    {
      "x": -5,
      "y": 5,
      "z": -1,
      "name": "Soil_Dirt"
    },
    {
      "x": -5,
      "y": 6,
      "z": -1,
      "name": "Soil_Dirt"
    },
    {
      "x": -5,
      "y": 7,
      "z": -1,
      "name": "Soil_Dirt"
    },
    {
      "x": -5,
      "y": 8,
      "z": -1,
      "name": "Soil_Grass_Deep"
    },
    {
      "x": -5,
      "y": 17,
      "z": -1,
      "name": "Wood_Oak_Trunk_Full"
    },
    {
      "x": -5,
      "y": 22,
      "z": -1,
      "name": "Wood_Oak_Trunk_Full"
    },
    {
      "x": -5,
      "y": 26,
      "z": -1,
      "name": "Plant_Leaves_Oak"
    },
    {
      "x": -5,
      "y": 28,
      "z": -1,
      "name": "Plant_Leaves_Oak"
    },
    {
      "x": -5,
      "y": 29,
      "z": -1,
      "name": "Plant_Leaves_Oak"
    },
    {
      "x": -5,
      "y": 30,
      "z": -1,
      "name": "Plant_Leaves_Oak"
    },
    {
      "x": -5,
      "y": 3,
      "z": 0,
      "name": "Soil_Dirt"
    },
    {
      "x": -5,
      "y": 4,
      "z": 0,
      "name": "Soil_Dirt"
    },
    {
      "x": -5,
      "y": 5,
      "z": 0,
      "name": "Soil_Dirt"
    },
    {
      "x": -5,
      "y": 6,
      "z": 0,
      "name": "Soil_Dirt"
    },
    {
      "x": -5,
      "y": 7,
      "z": 0,
      "name": "Soil_Dirt"
    },
    {
      "x": -5,
      "y": 8,
      "z": 0,
      "name": "Soil_Leaves"
    },
    {
      "x": -5,
      "y": 22,
      "z": 0,
      "name": "Wood_Oak_Trunk_Full"
    },
    {
      "x": -5,
      "y": 26,
      "z": 0,
      "name": "Plant_Leaves_Oak"
    },
    {
      "x": -5,
      "y": 28,
      "z": 0,
      "name": "Plant_Leaves_Oak"
    },
    {
      "x": -5,
      "y": 30,
      "z": 0,
      "name": "Plant_Leaves_Oak"
    },
    {
      "x": -5,
      "y": 3,
      "z": 1,
      "name": "Soil_Dirt"
    },
    {
      "x": -5,
      "y": 4,
      "z": 1,
      "name": "Soil_Dirt"
    },
    {
      "x": -5,
      "y": 5,
      "z": 1,
      "name": "Soil_Dirt"
    },
    {
      "x": -5,
      "y": 6,
      "z": 1,
      "name": "Soil_Dirt"
    },
    {
      "x": -5,
      "y": 7,
      "z": 1,
      "name": "Soil_Dirt"
    },
    {
      "x": -5,
      "y": 8,
      "z": 1,
      "name": "Soil_Leaves"
    },
    {
      "x": -5,
      "y": 25,
      "z": 1,
      "name": "Wood_Oak_Trunk_Full"
    },
    {
      "x": -5,
      "y": 28,
      "z": 1,
      "name": "Plant_Leaves_Oak"
    },
    {
      "x": -5,
      "y": 3,
      "z": 2,
      "name": "Soil_Dirt"
    },
    {
      "x": -5,
      "y": 4,
      "z": 2,
      "name": "Soil_Dirt"
    },
    {
      "x": -5,
      "y": 5,
      "z": 2,
      "name": "Soil_Dirt"
    },
    {
      "x": -5,
      "y": 6,
      "z": 2,
      "name": "Soil_Dirt"
    },
    {
      "x": -5,
      "y": 7,
      "z": 2,
      "name": "Soil_Dirt"
    },
    {
      "x": -5,
      "y": 8,
      "z": 2,
      "name": "Soil_Leaves"
    },
    {
      "x": -5,
      "y": 25,
      "z": 2,
      "name": "Wood_Oak_Trunk_Full"
    },
    {
      "x": -5,
      "y": 28,
      "z": 2,
      "name": "Plant_Leaves_Oak"
    },
    {
      "x": -5,
      "y": 3,
      "z": 3,
      "name": "Soil_Dirt"
    },
    {
      "x": -5,
      "y": 4,
      "z": 3,
      "name": "Soil_Dirt"
    },
    {
      "x": -5,
      "y": 5,
      "z": 3,
      "name": "Soil_Dirt"
    },
    {
      "x": -5,
      "y": 6,
      "z": 3,
      "name": "Soil_Dirt"
    },
    {
      "x": -5,
      "y": 7,
      "z": 3,
      "name": "Soil_Dirt"
    },
    {
      "x": -5,
      "y": 8,
      "z": 3,
      "name": "Soil_Leaves"
    },
    {
      "x": -5,
      "y": 25,
      "z": 3,
      "name": "Wood_Oak_Trunk_Full"
    },
    {
      "x": -5,
      "y": 26,
      "z": 3,
      "name": "Wood_Oak_Trunk_Full"
    },
    {
      "x": -5,
      "y": 28,
      "z": 3,
      "name": "Plant_Leaves_Oak"
    },
    {
      "x": -5,
      "y": 3,
      "z": 4,
      "name": "Soil_Dirt"
    },
    {
      "x": -5,
      "y": 4,
      "z": 4,
      "name": "Soil_Dirt"
    },
    {
      "x": -5,
      "y": 5,
      "z": 4,
      "name": "Soil_Dirt"
    },
    {
      "x": -5,
      "y": 6,
      "z": 4,
      "name": "Soil_Dirt"
    },
    {
      "x": -5,
      "y": 7,
      "z": 4,
      "name": "Soil_Dirt"
    },
    {
      "x": -5,
      "y": 8,
      "z": 4,
      "name": "Soil_Leaves"
    },
    {
      "x": -5,
      "y": 28,
      "z": 4,
      "name": "Plant_Leaves_Oak"
    },
    {
      "x": -5,
      "y": 29,
      "z": 4,
      "name": "Plant_Leaves_Oak"
    },
    {
      "x": -5,
      "y": 3,
      "z": 5,
      "name": "Soil_Dirt"
    },
    {
      "x": -5,
      "y": 4,
      "z": 5,
      "name": "Soil_Dirt"
    },
    {
      "x": -5,
      "y": 5,
      "z": 5,
      "name": "Soil_Dirt"
    },
    {
      "x": -5,
      "y": 6,
      "z": 5,
      "name": "Soil_Dirt"
    },
    {
      "x": -5,
      "y": 7,
      "z": 5,
      "name": "Soil_Dirt"
    },
    {
      "x": -5,
      "y": 8,
      "z": 5,
      "name": "Soil_Leaves"
    },
    {
      "x": -5,
      "y": 21,
      "z": 5,
      "name": "Wood_Oak_Trunk_Full"
    },
    {
      "x": -5,
      "y": 28,
      "z": 5,
      "name": "Plant_Leaves_Oak"
    },
    {
      "x": -5,
      "y": 5,
      "z": 6,
      "name": "Wood_Oak_Trunk_Full"
    },
    {
      "x": -5,
      "y": 21,
      "z": 6,
      "name": "Wood_Oak_Trunk_Full"
    },
    {
      "x": -5,
      "y": 25,
      "z": 6,
      "name": "Plant_Leaves_Oak"
    },
    {
      "x": -5,
      "y": 28,
      "z": 6,
      "name": "Plant_Leaves_Oak"
    },
    {
      "x": -5,
      "y": 5,
      "z": 7,
      "name": "Wood_Oak_Trunk_Full"
    },
    {
      "x": -5,
      "y": 6,
      "z": 7,
      "name": "Wood_Oak_Trunk_Full"
    },
    {
      "x": -5,
      "y": 17,
      "z": 7,
      "name": "Furniture_Kweebec_Lantern"
    },
    {
      "x": -5,
      "y": 18,
      "z": 7,
      "name": "Deco_Rope"
    },
    {
      "x": -5,
      "y": 19,
      "z": 7,
      "name": "Deco_Rope"
    },
    {
      "x": -5,
      "y": 20,
      "z": 7,
      "name": "Wood_Oak_Trunk_Full"
    },
    {
      "x": -5,
      "y": 21,
      "z": 7,
      "name": "Wood_Oak_Trunk_Full"
    },
    {
      "x": -5,
      "y": 25,
      "z": 7,
      "name": "Plant_Leaves_Oak"
    },
    {
      "x": -5,
      "y": 20,
      "z": 8,
      "name": "Wood_Oak_Trunk_Full"
    },
    {
      "x": -5,
      "y": 25,
      "z": 8,
      "name": "Plant_Leaves_Oak"
    },
    {
      "x": -5,
      "y": 26,
      "z": 8,
      "name": "Plant_Leaves_Oak"
    },
    {
      "x": -5,
      "y": 20,
      "z": 9,
      "name": "Wood_Oak_Trunk_Full"
    },
    {
      "x": -5,
      "y": 21,
      "z": 9,
      "name": "Plant_Leaves_Oak"
    },
    {
      "x": -5,
      "y": 22,
      "z": 9,
      "name": "Plant_Leaves_Oak"
    },
    {
      "x": -5,
      "y": 23,
      "z": 9,
      "name": "Plant_Leaves_Oak"
    },
    {
      "x": -5,
      "y": 25,
      "z": 9,
      "name": "Plant_Leaves_Oak"
    },
    {
      "x": -5,
      "y": 26,
      "z": 9,
      "name": "Plant_Leaves_Oak"
    },
    {
      "x": -5,
      "y": 20,
      "z": 10,
      "name": "Wood_Oak_Branch_Long",
      "rotation": 4
    },
    {
      "x": -5,
      "y": 21,
      "z": 10,
      "name": "Plant_Leaves_Oak"
    },
    {
      "x": -5,
      "y": 23,
      "z": 10,
      "name": "Plant_Leaves_Oak"
    },
    {
      "x": -5,
      "y": 25,
      "z": 10,
      "name": "Plant_Leaves_Oak"
    },
    {
      "x": -5,
      "y": 20,
      "z": 11,
      "name": "Plant_Leaves_Oak"
    },
    {
      "x": -5,
      "y": 21,
      "z": 11,
      "name": "Plant_Leaves_Oak"
    },
    {
      "x": -5,
      "y": 22,
      "z": 11,
      "name": "Plant_Leaves_Oak"
    },
    {
      "x": -5,
      "y": 21,
      "z": 12,
      "name": "Plant_Leaves_Oak"
    },
    {
      "x": -5,
      "y": 21,
      "z": 13,
      "name": "Plant_Leaves_Oak"
    },
    {
      "x": -4,
      "y": 26,
      "z": -9,
      "name": "Plant_Leaves_Oak"
    },
    {
      "x": -4,
      "y": 21,
      "z": -8,
      "name": "Plant_Leaves_Oak"
    },
    {
      "x": -4,
      "y": 22,
      "z": -8,
      "name": "Plant_Leaves_Oak"
    },
    {
      "x": -4,
      "y": 24,
      "z": -8,
      "name": "Plant_Leaves_Oak"
    },
    {
      "x": -4,
      "y": 25,
      "z": -8,
      "name": "Plant_Leaves_Oak"
    },
    {
      "x": -4,
      "y": 26,
      "z": -8,
      "name": "Plant_Leaves_Oak"
    },
    {
      "x": -4,
      "y": 27,
      "z": -8,
      "name": "Plant_Leaves_Oak"
    },
    {
      "x": -4,
      "y": 21,
      "z": -7,
      "name": "Plant_Leaves_Oak"
    },
    {
      "x": -4,
      "y": 22,
      "z": -7,
      "name": "Plant_Leaves_Oak"
    },
    {
      "x": -4,
      "y": 25,
      "z": -7,
      "name": "Plant_Leaves_Oak"
    },
    {
      "x": -4,
      "y": 26,
      "z": -7,
      "name": "Plant_Leaves_Oak"
    },
    {
      "x": -4,
      "y": 27,
      "z": -7,
      "name": "Plant_Leaves_Oak"
    },
    {
      "x": -4,
      "y": 21,
      "z": -6,
      "name": "Plant_Leaves_Oak"
    },
    {
      "x": -4,
      "y": 22,
      "z": -6,
      "name": "Plant_Leaves_Oak"
    },
    {
      "x": -4,
      "y": 23,
      "z": -6,
      "name": "Plant_Leaves_Oak"
    },
    {
      "x": -4,
      "y": 25,
      "z": -6,
      "name": "Wood_Oak_Branch_Corner",
      "rotation": 2
    },
    {
      "x": -4,
      "y": 26,
      "z": -6,
      "name": "Plant_Leaves_Oak"
    },
    {
      "x": -4,
      "y": 27,
      "z": -6,
      "name": "Plant_Leaves_Oak"
    },
    {
      "x": -4,
      "y": 22,
      "z": -5,
      "name": "Plant_Leaves_Oak"
    },
    {
      "x": -4,
      "y": 23,
      "z": -5,
      "name": "Wood_Oak_Trunk_Full"
    },
    {
      "x": -4,
      "y": 24,
      "z": -5,
      "name": "Wood_Oak_Trunk_Full"
    },
    {
      "x": -4,
      "y": 25,
      "z": -5,
      "name": "Wood_Oak_Trunk_Full"
    },
    {
      "x": -4,
      "y": 26,
      "z": -5,
      "name": "Plant_Leaves_Oak"
    },
    {
      "x": -4,
      "y": 5,
      "z": -4,
      "name": "Wood_Oak_Trunk_Full"
    },
    {
      "x": -4,
      "y": 6,
      "z": -4,
      "name": "Wood_Oak_Trunk_Full"
    },
    {
      "x": -4,
      "y": 7,
      "z": -4,
      "name": "Wood_Oak_Trunk_Full"
    },
    {
      "x": -4,
      "y": 22,
      "z": -4,
      "name": "Plant_Leaves_Oak"
    },
    {
      "x": -4,
      "y": 23,
      "z": -4,
      "name": "Wood_Oak_Trunk_Full"
    },
    {
      "x": -4,
      "y": 24,
      "z": -4,
      "name": "Wood_Oak_Trunk_Full"
    },
    {
      "x": -4,
      "y": 3,
      "z": -3,
      "name": "Soil_Dirt"
    },
    {
      "x": -4,
      "y": 4,
      "z": -3,
      "name": "Soil_Dirt"
    },
    {
      "x": -4,
      "y": 5,
      "z": -3,
      "name": "Soil_Dirt"
    },
    {
      "x": -4,
      "y": 6,
      "z": -3,
      "name": "Soil_Dirt"
    },
    {
      "x": -4,
      "y": 7,
      "z": -3,
      "name": "Soil_Dirt"
    },
    {
      "x": -4,
      "y": 8,
      "z": -3,
      "name": "Soil_Grass_Deep"
    },
    {
      "x": -4,
      "y": 3,
      "z": -2,
      "name": "Soil_Dirt"
    },
    {
      "x": -4,
      "y": 4,
      "z": -2,
      "name": "Soil_Dirt"
    },
    {
      "x": -4,
      "y": 5,
      "z": -2,
      "name": "Soil_Dirt"
    },
    {
      "x": -4,
      "y": 6,
      "z": -2,
      "name": "Soil_Dirt"
    },
    {
      "x": -4,
      "y": 7,
      "z": -2,
      "name": "Soil_Dirt"
    },
    {
      "x": -4,
      "y": 8,
      "z": -2,
      "name": "Soil_Grass_Deep"
    },
    {
      "x": -4,
      "y": 28,
      "z": -2,
      "name": "Plant_Leaves_Oak"
    },
    {
      "x": -4,
      "y": 3,
      "z": -1,
      "name": "Soil_Dirt"
    },
    {
      "x": -4,
      "y": 4,
      "z": -1,
      "name": "Soil_Dirt"
    },
    {
      "x": -4,
      "y": 5,
      "z": -1,
      "name": "Soil_Dirt"
    },
    {
      "x": -4,
      "y": 6,
      "z": -1,
      "name": "Soil_Dirt"
    },
    {
      "x": -4,
      "y": 7,
      "z": -1,
      "name": "Soil_Dirt"
    },
    {
      "x": -4,
      "y": 8,
      "z": -1,
      "name": "Soil_Grass_Deep"
    },
    {
      "x": -4,
      "y": 17,
      "z": -1,
      "name": "Wood_Oak_Trunk_Full"
    },
    {
      "x": -4,
      "y": 26,
      "z": -1,
      "name": "Plant_Leaves_Oak"
    },
    {
      "x": -4,
      "y": 28,
      "z": -1,
      "name": "Plant_Leaves_Oak"
    },
    {
      "x": -4,
      "y": 3,
      "z": 0,
      "name": "Soil_Dirt"
    },
    {
      "x": -4,
      "y": 4,
      "z": 0,
      "name": "Soil_Dirt"
    },
    {
      "x": -4,
      "y": 5,
      "z": 0,
      "name": "Soil_Dirt"
    },
    {
      "x": -4,
      "y": 6,
      "z": 0,
      "name": "Soil_Dirt"
    },
    {
      "x": -4,
      "y": 7,
      "z": 0,
      "name": "Soil_Dirt"
    },
    {
      "x": -4,
      "y": 8,
      "z": 0,
      "name": "Soil_Leaves"
    },
    {
      "x": -4,
      "y": 22,
      "z": 0,
      "name": "Wood_Oak_Trunk_Full"
    },
    {
      "x": -4,
      "y": 26,
      "z": 0,
      "name": "Plant_Leaves_Oak"
    },
    {
      "x": -4,
      "y": 28,
      "z": 0,
      "name": "Plant_Leaves_Oak"
    },
    {
      "x": -4,
      "y": 29,
      "z": 0,
      "name": "Plant_Leaves_Oak"
    },
    {
      "x": -4,
      "y": 30,
      "z": 0,
      "name": "Plant_Leaves_Oak"
    },
    {
      "x": -4,
      "y": 3,
      "z": 1,
      "name": "Soil_Dirt"
    },
    {
      "x": -4,
      "y": 4,
      "z": 1,
      "name": "Soil_Dirt"
    },
    {
      "x": -4,
      "y": 5,
      "z": 1,
      "name": "Soil_Dirt"
    },
    {
      "x": -4,
      "y": 6,
      "z": 1,
      "name": "Soil_Dirt"
    },
    {
      "x": -4,
      "y": 7,
      "z": 1,
      "name": "Soil_Dirt"
    },
    {
      "x": -4,
      "y": 8,
      "z": 1,
      "name": "Soil_Leaves"
    },
    {
      "x": -4,
      "y": 21,
      "z": 1,
      "name": "Wood_Oak_Trunk_Full"
    },
    {
      "x": -4,
      "y": 22,
      "z": 1,
      "name": "Wood_Oak_Trunk_Full"
    },
    {
      "x": -4,
      "y": 28,
      "z": 1,
      "name": "Plant_Leaves_Oak"
    },
    {
      "x": -4,
      "y": 29,
      "z": 1,
      "name": "Plant_Leaves_Oak"
    },
    {
      "x": -4,
      "y": 30,
      "z": 1,
      "name": "Plant_Leaves_Oak"
    },
    {
      "x": -4,
      "y": 3,
      "z": 2,
      "name": "Soil_Dirt"
    },
    {
      "x": -4,
      "y": 4,
      "z": 2,
      "name": "Soil_Dirt"
    },
    {
      "x": -4,
      "y": 5,
      "z": 2,
      "name": "Wood_Oak_Trunk_Full"
    },
    {
      "x": -4,
      "y": 6,
      "z": 2,
      "name": "Wood_Oak_Trunk_Full"
    },
    {
      "x": -4,
      "y": 7,
      "z": 2,
      "name": "Wood_Oak_Trunk_Full"
    },
    {
      "x": -4,
      "y": 8,
      "z": 2,
      "name": "Wood_Oak_Trunk_Full"
    },
    {
      "x": -4,
      "y": 24,
      "z": 2,
      "name": "Wood_Oak_Trunk_Full"
    },
    {
      "x": -4,
      "y": 25,
      "z": 2,
      "name": "Wood_Oak_Trunk_Full"
    },
    {
      "x": -4,
      "y": 27,
      "z": 2,
      "name": "Wood_Oak_Branch_Corner",
      "rotation": 3
    },
    {
      "x": -4,
      "y": 28,
      "z": 2,
      "name": "Plant_Leaves_Oak"
    },
    {
      "x": -4,
      "y": 29,
      "z": 2,
      "name": "Plant_Leaves_Oak"
    },
    {
      "x": -4,
      "y": 30,
      "z": 2,
      "name": "Plant_Leaves_Oak"
    },
    {
      "x": -4,
      "y": 3,
      "z": 3,
      "name": "Soil_Dirt"
    },
    {
      "x": -4,
      "y": 4,
      "z": 3,
      "name": "Soil_Dirt"
    },
    {
      "x": -4,
      "y": 5,
      "z": 3,
      "name": "Soil_Dirt"
    },
    {
      "x": -4,
      "y": 6,
      "z": 3,
      "name": "Soil_Dirt"
    },
    {
      "x": -4,
      "y": 7,
      "z": 3,
      "name": "Soil_Dirt"
    },
    {
      "x": -4,
      "y": 8,
      "z": 3,
      "name": "Soil_Leaves"
    },
    {
      "x": -4,
      "y": 3,
      "z": 4,
      "name": "Soil_Dirt"
    },
    {
      "x": -4,
      "y": 4,
      "z": 4,
      "name": "Soil_Dirt"
    },
    {
      "x": -4,
      "y": 5,
      "z": 4,
      "name": "Soil_Dirt"
    },
    {
      "x": -4,
      "y": 6,
      "z": 4,
      "name": "Soil_Dirt"
    },
    {
      "x": -4,
      "y": 7,
      "z": 4,
      "name": "Soil_Dirt"
    },
    {
      "x": -4,
      "y": 8,
      "z": 4,
      "name": "Soil_Grass_Deep"
    },
    {
      "x": -4,
      "y": 21,
      "z": 4,
      "name": "Wood_Oak_Trunk_Full"
    },
    {
      "x": -4,
      "y": 28,
      "z": 4,
      "name": "Plant_Leaves_Oak"
    },
    {
      "x": -4,
      "y": 29,
      "z": 4,
      "name": "Plant_Leaves_Oak"
    },
    {
      "x": -4,
      "y": 3,
      "z": 5,
      "name": "Soil_Dirt"
    },
    {
      "x": -4,
      "y": 4,
      "z": 5,
      "name": "Soil_Dirt"
    },
    {
      "x": -4,
      "y": 5,
      "z": 5,
      "name": "Soil_Dirt"
    },
    {
      "x": -4,
      "y": 6,
      "z": 5,
      "name": "Soil_Dirt"
    },
    {
      "x": -4,
      "y": 7,
      "z": 5,
      "name": "Soil_Dirt"
    },
    {
      "x": -4,
      "y": 8,
      "z": 5,
      "name": "Soil_Grass_Deep"
    },
    {
      "x": -4,
      "y": 9,
      "z": 5,
      "name": "Wood_Oak_Trunk_Full"
    },
    {
      "x": -4,
      "y": 21,
      "z": 5,
      "name": "Wood_Oak_Trunk_Full"
    },
    {
      "x": -4,
      "y": 25,
      "z": 5,
      "name": "Plant_Leaves_Oak"
    },
    {
      "x": -4,
      "y": 28,
      "z": 5,
      "name": "Plant_Leaves_Oak"
    },
    {
      "x": -4,
      "y": 30,
      "z": 5,
      "name": "Plant_Leaves_Oak"
    },
    {
      "x": -4,
      "y": 3,
      "z": 6,
      "name": "Soil_Dirt"
    },
    {
      "x": -4,
      "y": 4,
      "z": 6,
      "name": "Soil_Dirt"
    },
    {
      "x": -4,
      "y": 5,
      "z": 6,
      "name": "Soil_Dirt"
    },
    {
      "x": -4,
      "y": 6,
      "z": 6,
      "name": "Soil_Dirt"
    },
    {
      "x": -4,
      "y": 7,
      "z": 6,
      "name": "Soil_Dirt"
    },
    {
      "x": -4,
      "y": 8,
      "z": 6,
      "name": "Soil_Grass_Deep"
    },
    {
      "x": -4,
      "y": 9,
      "z": 6,
      "name": "Wood_Oak_Trunk_Full"
    },
    {
      "x": -4,
      "y": 21,
      "z": 6,
      "name": "Wood_Oak_Trunk_Full"
    },
    {
      "x": -4,
      "y": 25,
      "z": 6,
      "name": "Plant_Leaves_Oak"
    },
    {
      "x": -4,
      "y": 26,
      "z": 6,
      "name": "Plant_Leaves_Oak"
    },
    {
      "x": -4,
      "y": 28,
      "z": 6,
      "name": "Plant_Leaves_Oak"
    },
    {
      "x": -4,
      "y": 29,
      "z": 6,
      "name": "Plant_Leaves_Oak"
    },
    {
      "x": -4,
      "y": 6,
      "z": 7,
      "name": "Wood_Oak_Trunk_Full"
    },
    {
      "x": -4,
      "y": 25,
      "z": 7,
      "name": "Plant_Leaves_Oak"
    },
    {
      "x": -4,
      "y": 26,
      "z": 7,
      "name": "Plant_Leaves_Oak"
    },
    {
      "x": -4,
      "y": 28,
      "z": 7,
      "name": "Plant_Leaves_Oak"
    },
    {
      "x": -4,
      "y": 6,
      "z": 8,
      "name": "Wood_Oak_Trunk_Full"
    },
    {
      "x": -4,
      "y": 7,
      "z": 8,
      "name": "Wood_Oak_Trunk_Full"
    },
    {
      "x": -4,
      "y": 21,
      "z": 8,
      "name": "Plant_Leaves_Oak"
    },
    {
      "x": -4,
      "y": 25,
      "z": 8,
      "name": "Plant_Leaves_Oak"
    },
    {
      "x": -4,
      "y": 20,
      "z": 9,
      "name": "Plant_Leaves_Oak"
    },
    {
      "x": -4,
      "y": 21,
      "z": 9,
      "name": "Plant_Leaves_Oak"
    },
    {
      "x": -4,
      "y": 25,
      "z": 9,
      "name": "Plant_Leaves_Oak"
    },
    {
      "x": -4,
      "y": 26,
      "z": 9,
      "name": "Plant_Leaves_Oak"
    },
    {
      "x": -4,
      "y": 21,
      "z": 10,
      "name": "Plant_Leaves_Oak"
    },
    {
      "x": -4,
      "y": 22,
      "z": 10,
      "name": "Plant_Leaves_Oak"
    },
    {
      "x": -4,
      "y": 23,
      "z": 10,
      "name": "Plant_Leaves_Oak"
    },
    {
      "x": -4,
      "y": 25,
      "z": 10,
      "name": "Plant_Leaves_Oak"
    },
    {
      "x": -4,
      "y": 21,
      "z": 11,
      "name": "Plant_Leaves_Oak"
    },
    {
      "x": -4,
      "y": 22,
      "z": 11,
      "name": "Plant_Leaves_Oak"
    },
    {
      "x": -4,
      "y": 25,
      "z": 11,
      "name": "Plant_Leaves_Oak"
    },
    {
      "x": -4,
      "y": 20,
      "z": 12,
      "name": "Plant_Leaves_Oak"
    },
    {
      "x": -4,
      "y": 21,
      "z": 12,
      "name": "Plant_Leaves_Oak"
    },
    {
      "x": -4,
      "y": 22,
      "z": 12,
      "name": "Plant_Leaves_Oak"
    },
    {
      "x": -4,
      "y": 21,
      "z": 13,
      "name": "Plant_Leaves_Oak"
    },
    {
      "x": -3,
      "y": 21,
      "z": -9,
      "name": "Plant_Leaves_Oak"
    },
    {
      "x": -3,
      "y": 22,
      "z": -9,
      "name": "Plant_Leaves_Oak"
    },
    {
      "x": -3,
      "y": 26,
      "z": -9,
      "name": "Plant_Leaves_Oak"
    },
    {
      "x": -3,
      "y": 20,
      "z": -8,
      "name": "Plant_Leaves_Oak"
    },
    {
      "x": -3,
      "y": 21,
      "z": -8,
      "name": "Plant_Leaves_Oak"
    },
    {
      "x": -3,
      "y": 22,
      "z": -8,
      "name": "Plant_Leaves_Oak"
    },
    {
      "x": -3,
      "y": 26,
      "z": -8,
      "name": "Plant_Leaves_Oak"
    },
    {
      "x": -3,
      "y": 21,
      "z": -7,
      "name": "Plant_Leaves_Oak"
    },
    {
      "x": -3,
      "y": 22,
      "z": -7,
      "name": "Plant_Leaves_Oak"
    },
    {
      "x": -3,
      "y": 23,
      "z": -7,
      "name": "Plant_Leaves_Oak"
    },
    {
      "x": -3,
      "y": 25,
      "z": -7,
      "name": "Plant_Leaves_Oak"
    },
    {
      "x": -3,
      "y": 26,
      "z": -7,
      "name": "Plant_Leaves_Oak"
    },
    {
      "x": -3,
      "y": 27,
      "z": -7,
      "name": "Plant_Leaves_Oak"
    },
    {
      "x": -3,
      "y": 20,
      "z": -6,
      "name": "Plant_Leaves_Oak"
    },
    {
      "x": -3,
      "y": 21,
      "z": -6,
      "name": "Plant_Leaves_Oak"
    },
    {
      "x": -3,
      "y": 22,
      "z": -6,
      "name": "Plant_Leaves_Oak"
    },
    {
      "x": -3,
      "y": 23,
      "z": -6,
      "name": "Plant_Leaves_Oak"
    },
    {
      "x": -3,
      "y": 25,
      "z": -6,
      "name": "Plant_Leaves_Oak"
    },
    {
      "x": -3,
      "y": 26,
      "z": -6,
      "name": "Plant_Leaves_Oak"
    },
    {
      "x": -3,
      "y": 27,
      "z": -6,
      "name": "Plant_Leaves_Oak"
    },
    {
      "x": -3,
      "y": 7,
      "z": -5,
      "name": "Wood_Oak_Trunk_Full"
    },
    {
      "x": -3,
      "y": 21,
      "z": -5,
      "name": "Plant_Leaves_Oak"
    },
    {
      "x": -3,
      "y": 22,
      "z": -5,
      "name": "Plant_Leaves_Oak"
    },
    {
      "x": -3,
      "y": 26,
      "z": -5,
      "name": "Plant_Leaves_Oak"
    },
    {
      "x": -3,
      "y": 7,
      "z": -4,
      "name": "Wood_Oak_Trunk_Full"
    },
    {
      "x": -3,
      "y": 8,
      "z": -4,
      "name": "Wood_Oak_Trunk_Full"
    },
    {
      "x": -3,
      "y": 22,
      "z": -4,
      "name": "Plant_Leaves_Oak"
    },
    {
      "x": -3,
      "y": 23,
      "z": -4,
      "name": "Wood_Oak_Trunk_Full"
    },
    {
      "x": -3,
      "y": 26,
      "z": -4,
      "name": "Plant_Leaves_Oak"
    },
    {
      "x": -3,
      "y": 4,
      "z": -3,
      "name": "Soil_Dirt"
    },
    {
      "x": -3,
      "y": 5,
      "z": -3,
      "name": "Soil_Dirt"
    },
    {
      "x": -3,
      "y": 6,
      "z": -3,
      "name": "Soil_Dirt"
    },
    {
      "x": -3,
      "y": 7,
      "z": -3,
      "name": "Soil_Dirt"
    },
    {
      "x": -3,
      "y": 8,
      "z": -3,
      "name": "Wood_Oak_Trunk_Full"
    },
    {
      "x": -3,
      "y": 9,
      "z": -3,
      "name": "Wood_Oak_Trunk_Full"
    },
    {
      "x": -3,
      "y": 22,
      "z": -3,
      "name": "Wood_Oak_Trunk_Full"
    },
    {
      "x": -3,
      "y": 23,
      "z": -3,
      "name": "Wood_Oak_Trunk_Full"
    },
    {
      "x": -3,
      "y": 28,
      "z": -3,
      "name": "Plant_Leaves_Oak"
    },
    {
      "x": -3,
      "y": 29,
      "z": -3,
      "name": "Plant_Leaves_Oak"
    },
    {
      "x": -3,
      "y": 3,
      "z": -2,
      "name": "Soil_Dirt"
    },
    {
      "x": -3,
      "y": 4,
      "z": -2,
      "name": "Soil_Dirt"
    },
    {
      "x": -3,
      "y": 5,
      "z": -2,
      "name": "Soil_Dirt"
    },
    {
      "x": -3,
      "y": 6,
      "z": -2,
      "name": "Soil_Dirt"
    },
    {
      "x": -3,
      "y": 7,
      "z": -2,
      "name": "Soil_Dirt"
    },
    {
      "x": -3,
      "y": 8,
      "z": -2,
      "name": "Soil_Grass_Deep"
    },
    {
      "x": -3,
      "y": 13,
      "z": -2,
      "name": "Furniture_Kweebec_Lantern"
    },
    {
      "x": -3,
      "y": 14,
      "z": -2,
      "name": "Deco_Rope"
    },
    {
      "x": -3,
      "y": 15,
      "z": -2,
      "name": "Deco_Rope"
    },
    {
      "x": -3,
      "y": 16,
      "z": -2,
      "name": "Deco_Rope"
    },
    {
      "x": -3,
      "y": 17,
      "z": -2,
      "name": "Wood_Oak_Trunk_Full"
    },
    {
      "x": -3,
      "y": 22,
      "z": -2,
      "name": "Wood_Oak_Trunk_Full"
    },
    {
      "x": -3,
      "y": 28,
      "z": -2,
      "name": "Plant_Leaves_Oak"
    },
    {
      "x": -3,
      "y": 29,
      "z": -2,
      "name": "Plant_Leaves_Oak"
    },
    {
      "x": -3,
      "y": 3,
      "z": -1,
      "name": "Soil_Dirt"
    },
    {
      "x": -3,
      "y": 4,
      "z": -1,
      "name": "Soil_Dirt"
    },
    {
      "x": -3,
      "y": 5,
      "z": -1,
      "name": "Soil_Dirt"
    },
    {
      "x": -3,
      "y": 6,
      "z": -1,
      "name": "Soil_Dirt"
    },
    {
      "x": -3,
      "y": 7,
      "z": -1,
      "name": "Soil_Dirt"
    },
    {
      "x": -3,
      "y": 8,
      "z": -1,
      "name": "Soil_Grass_Deep"
    },
    {
      "x": -3,
      "y": 17,
      "z": -1,
      "name": "Wood_Oak_Trunk_Full"
    },
    {
      "x": -3,
      "y": 28,
      "z": -1,
      "name": "Plant_Leaves_Oak"
    },
    {
      "x": -3,
      "y": 29,
      "z": -1,
      "name": "Plant_Leaves_Oak"
    },
    {
      "x": -3,
      "y": 30,
      "z": -1,
      "name": "Plant_Leaves_Oak"
    },
    {
      "x": -3,
      "y": 3,
      "z": 0,
      "name": "Soil_Dirt"
    },
    {
      "x": -3,
      "y": 4,
      "z": 0,
      "name": "Soil_Dirt"
    },
    {
      "x": -3,
      "y": 5,
      "z": 0,
      "name": "Soil_Dirt"
    },
    {
      "x": -3,
      "y": 6,
      "z": 0,
      "name": "Soil_Dirt"
    },
    {
      "x": -3,
      "y": 7,
      "z": 0,
      "name": "Soil_Dirt"
    },
    {
      "x": -3,
      "y": 8,
      "z": 0,
      "name": "Soil_Leaves"
    },
    {
      "x": -3,
      "y": 16,
      "z": 0,
      "name": "Wood_Oak_Trunk_Full"
    },
    {
      "x": -3,
      "y": 17,
      "z": 0,
      "name": "Wood_Oak_Trunk_Full"
    },
    {
      "x": -3,
      "y": 19,
      "z": 0,
      "name": "Wood_Oak_Trunk_Full"
    },
    {
      "x": -3,
      "y": 20,
      "z": 0,
      "name": "Wood_Oak_Trunk_Full"
    },
    {
      "x": -3,
      "y": 21,
      "z": 0,
      "name": "Wood_Oak_Trunk_Full"
    },
    {
      "x": -3,
      "y": 22,
      "z": 0,
      "name": "Wood_Oak_Trunk_Full"
    },
    {
      "x": -3,
      "y": 28,
      "z": 0,
      "name": "Plant_Leaves_Oak"
    },
    {
      "x": -3,
      "y": 29,
      "z": 0,
      "name": "Plant_Leaves_Oak"
    },
    {
      "x": -3,
      "y": 30,
      "z": 0,
      "name": "Plant_Leaves_Oak"
    },
    {
      "x": -3,
      "y": 3,
      "z": 1,
      "name": "Soil_Dirt"
    },
    {
      "x": -3,
      "y": 4,
      "z": 1,
      "name": "Soil_Dirt"
    },
    {
      "x": -3,
      "y": 5,
      "z": 1,
      "name": "Soil_Dirt"
    },
    {
      "x": -3,
      "y": 6,
      "z": 1,
      "name": "Soil_Dirt"
    },
    {
      "x": -3,
      "y": 7,
      "z": 1,
      "name": "Soil_Dirt"
    },
    {
      "x": -3,
      "y": 8,
      "z": 1,
      "name": "Wood_Oak_Trunk_Full",
      "rotation": 5
    },
    {
      "x": -3,
      "y": 9,
      "z": 1,
      "name": "Wood_Oak_Trunk_Full"
    },
    {
      "x": -3,
      "y": 10,
      "z": 1,
      "name": "Wood_Oak_Trunk_Full",
      "rotation": 5
    },
    {
      "x": -3,
      "y": 18,
      "z": 1,
      "name": "Wood_Oak_Trunk_Full"
    },
    {
      "x": -3,
      "y": 19,
      "z": 1,
      "name": "Wood_Oak_Trunk_Full"
    },
    {
      "x": -3,
      "y": 20,
      "z": 1,
      "name": "Wood_Oak_Trunk_Full"
    },
    {
      "x": -3,
      "y": 21,
      "z": 1,
      "name": "Wood_Oak_Trunk_Full"
    },
    {
      "x": -3,
      "y": 22,
      "z": 1,
      "name": "Wood_Oak_Trunk_Full"
    },
    {
      "x": -3,
      "y": 23,
      "z": 1,
      "name": "Wood_Oak_Trunk_Full"
    },
    {
      "x": -3,
      "y": 28,
      "z": 1,
      "name": "Plant_Leaves_Oak"
    },
    {
      "x": -3,
      "y": 29,
      "z": 1,
      "name": "Plant_Leaves_Oak"
    },
    {
      "x": -3,
      "y": 30,
      "z": 1,
      "name": "Plant_Leaves_Oak"
    },
    {
      "x": -3,
      "y": 3,
      "z": 2,
      "name": "Soil_Dirt"
    },
    {
      "x": -3,
      "y": 4,
      "z": 2,
      "name": "Soil_Dirt"
    },
    {
      "x": -3,
      "y": 5,
      "z": 2,
      "name": "Soil_Dirt"
    },
    {
      "x": -3,
      "y": 6,
      "z": 2,
      "name": "Soil_Dirt"
    },
    {
      "x": -3,
      "y": 7,
      "z": 2,
      "name": "Soil_Dirt"
    },
    {
      "x": -3,
      "y": 8,
      "z": 2,
      "name": "Wood_Oak_Trunk_Full"
    },
    {
      "x": -3,
      "y": 9,
      "z": 2,
      "name": "Wood_Oak_Trunk_Full"
    },
    {
      "x": -3,
      "y": 10,
      "z": 2,
      "name": "Furniture_Kweebec_Window",
      "rotation": 1
    },
    {
      "x": -3,
      "y": 11,
      "z": 2,
      "name": "Wood_Oak_Trunk_Full",
      "rotation": 5
    },
    {
      "x": -3,
      "y": 20,
      "z": 2,
      "name": "Wood_Oak_Trunk_Full"
    },
    {
      "x": -3,
      "y": 21,
      "z": 2,
      "name": "Wood_Oak_Trunk_Full"
    },
    {
      "x": -3,
      "y": 22,
      "z": 2,
      "name": "Wood_Oak_Trunk_Full"
    },
    {
      "x": -3,
      "y": 23,
      "z": 2,
      "name": "Wood_Oak_Trunk_Full"
    },
    {
      "x": -3,
      "y": 24,
      "z": 2,
      "name": "Wood_Oak_Trunk_Full"
    },
    {
      "x": -3,
      "y": 27,
      "z": 2,
      "name": "Wood_Oak_Trunk_Full"
    },
    {
      "x": -3,
      "y": 28,
      "z": 2,
      "name": "Plant_Leaves_Oak"
    },
    {
      "x": -3,
      "y": 29,
      "z": 2,
      "name": "Plant_Leaves_Oak"
    },
    {
      "x": -3,
      "y": 3,
      "z": 3,
      "name": "Soil_Dirt"
    },
    {
      "x": -3,
      "y": 4,
      "z": 3,
      "name": "Soil_Dirt"
    },
    {
      "x": -3,
      "y": 5,
      "z": 3,
      "name": "Soil_Dirt"
    },
    {
      "x": -3,
      "y": 6,
      "z": 3,
      "name": "Soil_Dirt"
    },
    {
      "x": -3,
      "y": 7,
      "z": 3,
      "name": "Soil_Dirt"
    },
    {
      "x": -3,
      "y": 8,
      "z": 3,
      "name": "Wood_Oak_Trunk_Full",
      "rotation": 5
    },
    {
      "x": -3,
      "y": 9,
      "z": 3,
      "name": "Wood_Oak_Trunk_Full",
      "rotation": 5
    },
    {
      "x": -3,
      "y": 10,
      "z": 3,
      "name": "Wood_Oak_Trunk_Full",
      "rotation": 5
    },
    {
      "x": -3,
      "y": 11,
      "z": 3,
      "name": "Wood_Oak_Trunk_Full",
      "rotation": 5
    },
    {
      "x": -3,
      "y": 21,
      "z": 3,
      "name": "Wood_Oak_Trunk_Full"
    },
    {
      "x": -3,
      "y": 22,
      "z": 3,
      "name": "Wood_Oak_Trunk_Full"
    },
    {
      "x": -3,
      "y": 28,
      "z": 3,
      "name": "Plant_Leaves_Oak"
    },
    {
      "x": -3,
      "y": 29,
      "z": 3,
      "name": "Plant_Leaves_Oak"
    },
    {
      "x": -3,
      "y": 3,
      "z": 4,
      "name": "Soil_Dirt"
    },
    {
      "x": -3,
      "y": 4,
      "z": 4,
      "name": "Soil_Dirt"
    },
    {
      "x": -3,
      "y": 5,
      "z": 4,
      "name": "Soil_Dirt"
    },
    {
      "x": -3,
      "y": 6,
      "z": 4,
      "name": "Soil_Dirt"
    },
    {
      "x": -3,
      "y": 7,
      "z": 4,
      "name": "Soil_Dirt"
    },
    {
      "x": -3,
      "y": 8,
      "z": 4,
      "name": "Soil_Grass_Deep"
    },
    {
      "x": -3,
      "y": 21,
      "z": 4,
      "name": "Wood_Oak_Trunk_Full"
    },
    {
      "x": -3,
      "y": 28,
      "z": 4,
      "name": "Plant_Leaves_Oak"
    },
    {
      "x": -3,
      "y": 29,
      "z": 4,
      "name": "Plant_Leaves_Oak"
    },
    {
      "x": -3,
      "y": 30,
      "z": 4,
      "name": "Plant_Leaves_Oak"
    },
    {
      "x": -3,
      "y": 3,
      "z": 5,
      "name": "Soil_Dirt"
    },
    {
      "x": -3,
      "y": 4,
      "z": 5,
      "name": "Soil_Dirt"
    },
    {
      "x": -3,
      "y": 5,
      "z": 5,
      "name": "Soil_Dirt"
    },
    {
      "x": -3,
      "y": 6,
      "z": 5,
      "name": "Soil_Dirt"
    },
    {
      "x": -3,
      "y": 7,
      "z": 5,
      "name": "Soil_Dirt"
    },
    {
      "x": -3,
      "y": 8,
      "z": 5,
      "name": "Soil_Grass_Deep"
    },
    {
      "x": -3,
      "y": 9,
      "z": 5,
      "name": "Wood_Oak_Trunk_Full"
    },
    {
      "x": -3,
      "y": 25,
      "z": 5,
      "name": "Plant_Leaves_Oak"
    },
    {
      "x": -3,
      "y": 28,
      "z": 5,
      "name": "Plant_Leaves_Oak"
    },
    {
      "x": -3,
      "y": 29,
      "z": 5,
      "name": "Plant_Leaves_Oak"
    },
    {
      "x": -3,
      "y": 30,
      "z": 5,
      "name": "Plant_Leaves_Oak"
    },
    {
      "x": -3,
      "y": 3,
      "z": 6,
      "name": "Soil_Dirt"
    },
    {
      "x": -3,
      "y": 4,
      "z": 6,
      "name": "Soil_Dirt"
    },
    {
      "x": -3,
      "y": 5,
      "z": 6,
      "name": "Soil_Dirt"
    },
    {
      "x": -3,
      "y": 6,
      "z": 6,
      "name": "Soil_Dirt"
    },
    {
      "x": -3,
      "y": 7,
      "z": 6,
      "name": "Soil_Dirt"
    },
    {
      "x": -3,
      "y": 8,
      "z": 6,
      "name": "Soil_Grass_Deep"
    },
    {
      "x": -3,
      "y": 9,
      "z": 6,
      "name": "Wood_Oak_Trunk_Full"
    },
    {
      "x": -3,
      "y": 21,
      "z": 6,
      "name": "Wood_Oak_Trunk_Full"
    },
    {
      "x": -3,
      "y": 25,
      "z": 6,
      "name": "Plant_Leaves_Oak"
    },
    {
      "x": -3,
      "y": 28,
      "z": 6,
      "name": "Plant_Leaves_Oak"
    },
    {
      "x": -3,
      "y": 29,
      "z": 6,
      "name": "Plant_Leaves_Oak"
    },
    {
      "x": -3,
      "y": 8,
      "z": 7,
      "name": "Wood_Oak_Trunk_Full"
    },
    {
      "x": -3,
      "y": 20,
      "z": 7,
      "name": "Wood_Oak_Trunk_Full"
    },
    {
      "x": -3,
      "y": 25,
      "z": 7,
      "name": "Plant_Leaves_Oak"
    },
    {
      "x": -3,
      "y": 26,
      "z": 7,
      "name": "Plant_Leaves_Oak"
    },
    {
      "x": -3,
      "y": 28,
      "z": 7,
      "name": "Plant_Leaves_Oak"
    },
    {
      "x": -3,
      "y": 6,
      "z": 8,
      "name": "Wood_Oak_Trunk_Full"
    },
    {
      "x": -3,
      "y": 7,
      "z": 8,
      "name": "Wood_Oak_Trunk_Full"
    },
    {
      "x": -3,
      "y": 21,
      "z": 8,
      "name": "Plant_Leaves_Oak"
    },
    {
      "x": -3,
      "y": 22,
      "z": 8,
      "name": "Plant_Leaves_Oak"
    },
    {
      "x": -3,
      "y": 25,
      "z": 8,
      "name": "Plant_Leaves_Oak"
    },
    {
      "x": -3,
      "y": 26,
      "z": 8,
      "name": "Plant_Leaves_Oak"
    },
    {
      "x": -3,
      "y": 21,
      "z": 9,
      "name": "Plant_Leaves_Oak"
    },
    {
      "x": -3,
      "y": 22,
      "z": 9,
      "name": "Plant_Leaves_Oak"
    },
    {
      "x": -3,
      "y": 24,
      "z": 9,
      "name": "Plant_Leaves_Oak"
    },
    {
      "x": -3,
      "y": 25,
      "z": 9,
      "name": "Plant_Leaves_Oak"
    },
    {
      "x": -3,
      "y": 26,
      "z": 9,
      "name": "Plant_Leaves_Oak"
    },
    {
      "x": -3,
      "y": 21,
      "z": 10,
      "name": "Plant_Leaves_Oak"
    },
    {
      "x": -3,
      "y": 22,
      "z": 10,
      "name": "Plant_Leaves_Oak"
    },
    {
      "x": -3,
      "y": 24,
      "z": 10,
      "name": "Plant_Leaves_Oak"
    },
    {
      "x": -3,
      "y": 25,
      "z": 10,
      "name": "Plant_Leaves_Oak"
    },
    {
      "x": -3,
      "y": 20,
      "z": 11,
      "name": "Plant_Leaves_Oak"
    },
    {
      "x": -3,
      "y": 21,
      "z": 11,
      "name": "Plant_Leaves_Oak"
    },
    {
      "x": -3,
      "y": 22,
      "z": 11,
      "name": "Plant_Leaves_Oak"
    },
    {
      "x": -3,
      "y": 25,
      "z": 11,
      "name": "Plant_Leaves_Oak"
    },
    {
      "x": -3,
      "y": 21,
      "z": 12,
      "name": "Plant_Leaves_Oak"
    },
    {
      "x": -3,
      "y": 22,
      "z": 12,
      "name": "Plant_Leaves_Oak"
    },
    {
      "x": -3,
      "y": 21,
      "z": 13,
      "name": "Plant_Leaves_Oak"
    },
    {
      "x": -2,
      "y": 21,
      "z": -10,
      "name": "Plant_Leaves_Oak"
    },
    {
      "x": -2,
      "y": 22,
      "z": -10,
      "name": "Plant_Leaves_Oak"
    },
    {
      "x": -2,
      "y": 21,
      "z": -9,
      "name": "Plant_Leaves_Oak"
    },
    {
      "x": -2,
      "y": 22,
      "z": -9,
      "name": "Plant_Leaves_Oak"
    },
    {
      "x": -2,
      "y": 21,
      "z": -8,
      "name": "Plant_Leaves_Oak"
    },
    {
      "x": -2,
      "y": 22,
      "z": -8,
      "name": "Plant_Leaves_Oak"
    },
    {
      "x": -2,
      "y": 23,
      "z": -8,
      "name": "Plant_Leaves_Oak"
    },
    {
      "x": -2,
      "y": 26,
      "z": -8,
      "name": "Plant_Leaves_Oak"
    },
    {
      "x": -2,
      "y": 6,
      "z": -7,
      "name": "Wood_Oak_Trunk_Full"
    },
    {
      "x": -2,
      "y": 6,
      "z": -6,
      "name": "Wood_Oak_Trunk_Full"
    },
    {
      "x": -2,
      "y": 20,
      "z": -6,
      "name": "Plant_Leaves_Oak"
    },
    {
      "x": -2,
      "y": 21,
      "z": -6,
      "name": "Plant_Leaves_Oak"
    },
    {
      "x": -2,
      "y": 26,
      "z": -6,
      "name": "Plant_Leaves_Oak"
    },
    {
      "x": -2,
      "y": 6,
      "z": -5,
      "name": "Wood_Oak_Trunk_Full"
    },
    {
      "x": -2,
      "y": 7,
      "z": -5,
      "name": "Wood_Oak_Trunk_Full"
    },
    {
      "x": -2,
      "y": 20,
      "z": -5,
      "name": "Plant_Leaves_Oak"
    },
    {
      "x": -2,
      "y": 21,
      "z": -5,
      "name": "Plant_Leaves_Oak"
    },
    {
      "x": -2,
      "y": 26,
      "z": -5,
      "name": "Plant_Leaves_Oak"
    },
    {
      "x": -2,
      "y": 3,
      "z": -4,
      "name": "Soil_Dirt"
    },
    {
      "x": -2,
      "y": 4,
      "z": -4,
      "name": "Soil_Dirt"
    },
    {
      "x": -2,
      "y": 5,
      "z": -4,
      "name": "Soil_Dirt"
    },
    {
      "x": -2,
      "y": 6,
      "z": -4,
      "name": "Soil_Dirt"
    },
    {
      "x": -2,
      "y": 7,
      "z": -4,
      "name": "Soil_Dirt"
    },
    {
      "x": -2,
      "y": 8,
      "z": -4,
      "name": "Soil_Grass_Deep"
    },
    {
      "x": -2,
      "y": 23,
      "z": -4,
      "name": "Wood_Oak_Trunk_Full"
    },
    {
      "x": -2,
      "y": 26,
      "z": -4,
      "name": "Plant_Leaves_Oak"
    },
    {
      "x": -2,
      "y": 3,
      "z": -3,
      "name": "Soil_Dirt"
    },
    {
      "x": -2,
      "y": 4,
      "z": -3,
      "name": "Soil_Dirt"
    },
    {
      "x": -2,
      "y": 5,
      "z": -3,
      "name": "Soil_Dirt"
    },
    {
      "x": -2,
      "y": 6,
      "z": -3,
      "name": "Soil_Dirt"
    },
    {
      "x": -2,
      "y": 7,
      "z": -3,
      "name": "Soil_Dirt"
    },
    {
      "x": -2,
      "y": 8,
      "z": -3,
      "name": "Soil_Grass_Deep"
    },
    {
      "x": -2,
      "y": 28,
      "z": -3,
      "name": "Plant_Leaves_Oak"
    },
    {
      "x": -2,
      "y": 3,
      "z": -2,
      "name": "Soil_Dirt"
    },
    {
      "x": -2,
      "y": 4,
      "z": -2,
      "name": "Soil_Dirt"
    },
    {
      "x": -2,
      "y": 5,
      "z": -2,
      "name": "Soil_Dirt"
    },
    {
      "x": -2,
      "y": 6,
      "z": -2,
      "name": "Soil_Dirt"
    },
    {
      "x": -2,
      "y": 7,
      "z": -2,
      "name": "Wood_Oak_Trunk_Full"
    },
    {
      "x": -2,
      "y": 8,
      "z": -2,
      "name": "Wood_Oak_Trunk_Full"
    },
    {
      "x": -2,
      "y": 9,
      "z": -2,
      "name": "Wood_Oak_Trunk_Full"
    },
    {
      "x": -2,
      "y": 22,
      "z": -2,
      "name": "Wood_Oak_Trunk_Full"
    },
    {
      "x": -2,
      "y": 28,
      "z": -2,
      "name": "Plant_Leaves_Oak"
    },
    {
      "x": -2,
      "y": 3,
      "z": -1,
      "name": "Soil_Dirt"
    },
    {
      "x": -2,
      "y": 4,
      "z": -1,
      "name": "Soil_Dirt"
    },
    {
      "x": -2,
      "y": 5,
      "z": -1,
      "name": "Soil_Dirt"
    },
    {
      "x": -2,
      "y": 6,
      "z": -1,
      "name": "Soil_Dirt"
    },
    {
      "x": -2,
      "y": 7,
      "z": -1,
      "name": "Wood_Oak_Trunk_Full"
    },
    {
      "x": -2,
      "y": 8,
      "z": -1,
      "name": "Wood_Oak_Trunk_Full"
    },
    {
      "x": -2,
      "y": 9,
      "z": -1,
      "name": "Wood_Oak_Trunk_Full"
    },
    {
      "x": -2,
      "y": 10,
      "z": -1,
      "name": "Furniture_Kweebec_Window",
      "rotation": 1
    },
    {
      "x": -2,
      "y": 11,
      "z": -1,
      "name": "Wood_Oak_Trunk_Full",
      "rotation": 4
    },
    {
      "x": -2,
      "y": 21,
      "z": -1,
      "name": "Wood_Oak_Trunk_Full"
    },
    {
      "x": -2,
      "y": 22,
      "z": -1,
      "name": "Wood_Oak_Trunk_Full"
    },
    {
      "x": -2,
      "y": 28,
      "z": -1,
      "name": "Plant_Leaves_Oak"
    },
    {
      "x": -2,
      "y": 29,
      "z": -1,
      "name": "Plant_Leaves_Oak"
    },
    {
      "x": -2,
      "y": 3,
      "z": 0,
      "name": "Soil_Dirt"
    },
    {
      "x": -2,
      "y": 4,
      "z": 0,
      "name": "Soil_Dirt"
    },
    {
      "x": -2,
      "y": 5,
      "z": 0,
      "name": "Soil_Dirt"
    },
    {
      "x": -2,
      "y": 6,
      "z": 0,
      "name": "Soil_Dirt"
    },
    {
      "x": -2,
      "y": 7,
      "z": 0,
      "name": "Wood_Oak_Trunk_Full"
    },
    {
      "x": -2,
      "y": 8,
      "z": 0,
      "name": "Wood_Oak_Trunk_Full"
    },
    {
      "x": -2,
      "y": 9,
      "z": 0,
      "name": "Wood_Oak_Trunk_Full"
    },
    {
      "x": -2,
      "y": 10,
      "z": 0,
      "name": "Wood_Oak_Trunk_Full"
    },
    {
      "x": -2,
      "y": 11,
      "z": 0,
      "name": "Wood_Oak_Trunk_Full"
    },
    {
      "x": -2,
      "y": 12,
      "z": 0,
      "name": "Wood_Oak_Trunk_Full",
      "rotation": 5
    },
    {
      "x": -2,
      "y": 13,
      "z": 0,
      "name": "Wood_Oak_Trunk_Full",
      "rotation": 5
    },
    {
      "x": -2,
      "y": 16,
      "z": 0,
      "name": "Wood_Oak_Trunk_Full"
    },
    {
      "x": -2,
      "y": 17,
      "z": 0,
      "name": "Wood_Oak_Trunk_Full"
    },
    {
      "x": -2,
      "y": 18,
      "z": 0,
      "name": "Wood_Oak_Trunk_Full"
    },
    {
      "x": -2,
      "y": 19,
      "z": 0,
      "name": "Wood_Oak_Trunk_Full"
    },
    {
      "x": -2,
      "y": 20,
      "z": 0,
      "name": "Wood_Oak_Trunk_Full"
    },
    {
      "x": -2,
      "y": 21,
      "z": 0,
      "name": "Wood_Oak_Trunk_Full"
    },
    {
      "x": -2,
      "y": 28,
      "z": 0,
      "name": "Plant_Leaves_Oak"
    },
    {
      "x": -2,
      "y": 29,
      "z": 0,
      "name": "Plant_Leaves_Oak"
    },
    {
      "x": -2,
      "y": 30,
      "z": 0,
      "name": "Plant_Leaves_Oak"
    },
    {
      "x": -2,
      "y": 3,
      "z": 1,
      "name": "Soil_Dirt"
    },
    {
      "x": -2,
      "y": 4,
      "z": 1,
      "name": "Soil_Dirt"
    },
    {
      "x": -2,
      "y": 5,
      "z": 1,
      "name": "Soil_Dirt"
    },
    {
      "x": -2,
      "y": 6,
      "z": 1,
      "name": "Soil_Dirt"
    },
    {
      "x": -2,
      "y": 7,
      "z": 1,
      "name": "Soil_Dirt"
    },
    {
      "x": -2,
      "y": 8,
      "z": 1,
      "name": "Soil_Pathway"
    },
    {
      "x": -2,
      "y": 9,
      "z": 1,
      "name": "Wood_Oak_Trunk_Full"
    },
    {
      "x": -2,
      "y": 10,
      "z": 1,
      "name": "Wood_Oak_Trunk_Full"
    },
    {
      "x": -2,
      "y": 11,
      "z": 1,
      "name": "Wood_Oak_Trunk_Full"
    },
    {
      "x": -2,
      "y": 12,
      "z": 1,
      "name": "Wood_Oak_Trunk_Full",
      "rotation": 5
    },
    {
      "x": -2,
      "y": 13,
      "z": 1,
      "name": "Wood_Oak_Trunk_Full",
      "rotation": 5
    },
    {
      "x": -2,
      "y": 14,
      "z": 1,
      "name": "Wood_Oak_Trunk_Full",
      "rotation": 5
    },
    {
      "x": -2,
      "y": 15,
      "z": 1,
      "name": "Wood_Oak_Trunk_Full"
    },
    {
      "x": -2,
      "y": 16,
      "z": 1,
      "name": "Wood_Oak_Trunk_Full"
    },
    {
      "x": -2,
      "y": 17,
      "z": 1,
      "name": "Wood_Oak_Trunk_Full"
    },
    {
      "x": -2,
      "y": 18,
      "z": 1,
      "name": "Wood_Oak_Trunk_Full"
    },
    {
      "x": -2,
      "y": 19,
      "z": 1,
      "name": "Wood_Oak_Trunk_Full"
    },
    {
      "x": -2,
      "y": 20,
      "z": 1,
      "name": "Wood_Oak_Trunk_Full"
    },
    {
      "x": -2,
      "y": 21,
      "z": 1,
      "name": "Wood_Oak_Trunk_Full"
    },
    {
      "x": -2,
      "y": 22,
      "z": 1,
      "name": "Wood_Oak_Trunk_Full"
    },
    {
      "x": -2,
      "y": 23,
      "z": 1,
      "name": "Wood_Oak_Trunk_Full"
    },
    {
      "x": -2,
      "y": 24,
      "z": 1,
      "name": "Wood_Oak_Trunk_Full"
    },
    {
      "x": -2,
      "y": 25,
      "z": 1,
      "name": "Wood_Oak_Trunk_Full"
    },
    {
      "x": -2,
      "y": 26,
      "z": 1,
      "name": "Wood_Oak_Trunk_Full"
    },
    {
      "x": -2,
      "y": 29,
      "z": 1,
      "name": "Plant_Leaves_Oak"
    },
    {
      "x": -2,
      "y": 30,
      "z": 1,
      "name": "Plant_Leaves_Oak"
    },
    {
      "x": -2,
      "y": 31,
      "z": 1,
      "name": "Plant_Leaves_Oak"
    },
    {
      "x": -2,
      "y": 3,
      "z": 2,
      "name": "Soil_Dirt"
    },
    {
      "x": -2,
      "y": 4,
      "z": 2,
      "name": "Soil_Dirt"
    },
    {
      "x": -2,
      "y": 5,
      "z": 2,
      "name": "Soil_Dirt"
    },
    {
      "x": -2,
      "y": 6,
      "z": 2,
      "name": "Soil_Dirt"
    },
    {
      "x": -2,
      "y": 7,
      "z": 2,
      "name": "Soil_Dirt"
    },
    {
      "x": -2,
      "y": 8,
      "z": 2,
      "name": "Soil_Pathway"
    },
    {
      "x": -2,
      "y": 9,
      "z": 2,
      "name": "Furniture_Kweebec_Bed",
      "components": {
        "Components": {
          "RespawnBlock": {}
        }
      },
      "rotation": 1
    },
    {
      "x": -2,
      "y": 10,
      "z": 2,
      "name": "Furniture_Kweebec_Bed",
      "components": {
        "Components": {
          "RespawnBlock": {}
        }
      },
      "filler": 1024,
      "rotation": 1
    },
    {
      "x": -2,
      "y": 11,
      "z": 2,
      "name": "Wood_Oak_Trunk_Full"
    },
    {
      "x": -2,
      "y": 12,
      "z": 2,
      "name": "Wood_Oak_Trunk_Full"
    },
    {
      "x": -2,
      "y": 13,
      "z": 2,
      "name": "Wood_Oak_Trunk_Full",
      "rotation": 5
    },
    {
      "x": -2,
      "y": 14,
      "z": 2,
      "name": "Wood_Oak_Trunk_Full",
      "rotation": 5
    },
    {
      "x": -2,
      "y": 17,
      "z": 2,
      "name": "Wood_Oak_Trunk_Full"
    },
    {
      "x": -2,
      "y": 18,
      "z": 2,
      "name": "Wood_Oak_Trunk_Full"
    },
    {
      "x": -2,
      "y": 19,
      "z": 2,
      "name": "Wood_Oak_Trunk_Full"
    },
    {
      "x": -2,
      "y": 20,
      "z": 2,
      "name": "Wood_Oak_Trunk_Full"
    },
    {
      "x": -2,
      "y": 21,
      "z": 2,
      "name": "Wood_Oak_Trunk_Full"
    },
    {
      "x": -2,
      "y": 22,
      "z": 2,
      "name": "Wood_Oak_Trunk_Full"
    },
    {
      "x": -2,
      "y": 25,
      "z": 2,
      "name": "Wood_Oak_Trunk_Full"
    },
    {
      "x": -2,
      "y": 27,
      "z": 2,
      "name": "Wood_Oak_Trunk_Full"
    },
    {
      "x": -2,
      "y": 29,
      "z": 2,
      "name": "Plant_Leaves_Oak"
    },
    {
      "x": -2,
      "y": 30,
      "z": 2,
      "name": "Plant_Leaves_Oak"
    },
    {
      "x": -2,
      "y": 31,
      "z": 2,
      "name": "Plant_Leaves_Oak"
    },
    {
      "x": -2,
      "y": 3,
      "z": 3,
      "name": "Soil_Dirt"
    },
    {
      "x": -2,
      "y": 4,
      "z": 3,
      "name": "Soil_Dirt"
    },
    {
      "x": -2,
      "y": 5,
      "z": 3,
      "name": "Soil_Dirt"
    },
    {
      "x": -2,
      "y": 6,
      "z": 3,
      "name": "Soil_Dirt"
    },
    {
      "x": -2,
      "y": 7,
      "z": 3,
      "name": "Soil_Dirt"
    },
    {
      "x": -2,
      "y": 8,
      "z": 3,
      "name": "Wood_Oak_Trunk_Full",
      "rotation": 5
    },
    {
      "x": -2,
      "y": 9,
      "z": 3,
      "name": "Wood_Oak_Trunk_Full"
    },
    {
      "x": -2,
      "y": 10,
      "z": 3,
      "name": "Wood_Oak_Trunk_Full"
    },
    {
      "x": -2,
      "y": 11,
      "z": 3,
      "name": "Wood_Oak_Trunk_Full"
    },
    {
      "x": -2,
      "y": 12,
      "z": 3,
      "name": "Wood_Oak_Trunk_Full"
    },
    {
      "x": -2,
      "y": 28,
      "z": 3,
      "name": "Plant_Leaves_Oak"
    },
    {
      "x": -2,
      "y": 29,
      "z": 3,
      "name": "Plant_Leaves_Oak"
    },
    {
      "x": -2,
      "y": 30,
      "z": 3,
      "name": "Plant_Leaves_Oak"
    },
    {
      "x": -2,
      "y": 3,
      "z": 4,
      "name": "Soil_Dirt"
    },
    {
      "x": -2,
      "y": 4,
      "z": 4,
      "name": "Soil_Dirt"
    },
    {
      "x": -2,
      "y": 5,
      "z": 4,
      "name": "Soil_Dirt"
    },
    {
      "x": -2,
      "y": 6,
      "z": 4,
      "name": "Soil_Dirt"
    },
    {
      "x": -2,
      "y": 7,
      "z": 4,
      "name": "Wood_Oak_Trunk_Full"
    },
    {
      "x": -2,
      "y": 8,
      "z": 4,
      "name": "Wood_Oak_Trunk_Full"
    },
    {
      "x": -2,
      "y": 9,
      "z": 4,
      "name": "Wood_Oak_Trunk_Full"
    },
    {
      "x": -2,
      "y": 10,
      "z": 4,
      "name": "Wood_Oak_Trunk_Full"
    },
    {
      "x": -2,
      "y": 28,
      "z": 4,
      "name": "Plant_Leaves_Oak"
    },
    {
      "x": -2,
      "y": 3,
      "z": 5,
      "name": "Soil_Dirt"
    },
    {
      "x": -2,
      "y": 4,
      "z": 5,
      "name": "Soil_Dirt"
    },
    {
      "x": -2,
      "y": 5,
      "z": 5,
      "name": "Soil_Dirt"
    },
    {
      "x": -2,
      "y": 6,
      "z": 5,
      "name": "Soil_Dirt"
    },
    {
      "x": -2,
      "y": 7,
      "z": 5,
      "name": "Soil_Dirt"
    },
    {
      "x": -2,
      "y": 8,
      "z": 5,
      "name": "Soil_Grass_Deep"
    },
    {
      "x": -2,
      "y": 28,
      "z": 5,
      "name": "Plant_Leaves_Oak"
    },
    {
      "x": -2,
      "y": 29,
      "z": 5,
      "name": "Plant_Leaves_Oak"
    },
    {
      "x": -2,
      "y": 30,
      "z": 5,
      "name": "Plant_Leaves_Oak"
    },
    {
      "x": -2,
      "y": 3,
      "z": 6,
      "name": "Soil_Dirt"
    },
    {
      "x": -2,
      "y": 4,
      "z": 6,
      "name": "Soil_Dirt"
    },
    {
      "x": -2,
      "y": 5,
      "z": 6,
      "name": "Soil_Dirt"
    },
    {
      "x": -2,
      "y": 6,
      "z": 6,
      "name": "Soil_Dirt"
    },
    {
      "x": -2,
      "y": 7,
      "z": 6,
      "name": "Soil_Dirt"
    },
    {
      "x": -2,
      "y": 8,
      "z": 6,
      "name": "Wood_Oak_Trunk_Full"
    },
    {
      "x": -2,
      "y": 9,
      "z": 6,
      "name": "Wood_Oak_Trunk_Full"
    },
    {
      "x": -2,
      "y": 25,
      "z": 6,
      "name": "Plant_Leaves_Oak"
    },
    {
      "x": -2,
      "y": 28,
      "z": 6,
      "name": "Plant_Leaves_Oak"
    },
    {
      "x": -2,
      "y": 29,
      "z": 6,
      "name": "Plant_Leaves_Oak"
    },
    {
      "x": -2,
      "y": 3,
      "z": 7,
      "name": "Soil_Dirt"
    },
    {
      "x": -2,
      "y": 4,
      "z": 7,
      "name": "Wood_Oak_Trunk_Full"
    },
    {
      "x": -2,
      "y": 5,
      "z": 7,
      "name": "Soil_Dirt"
    },
    {
      "x": -2,
      "y": 6,
      "z": 7,
      "name": "Soil_Dirt"
    },
