{
  "version": 8,
  "blockIdVersion": 8,
  "anchorX": 0,
  "anchorY": 7,
  "anchorZ": 1,
  "blocks": [
    {
      "x": -11,
      "y": 17,
      "z": -5,
      "name": "Plant_Leaves_Oak"
    },
    {
      "x": -11,
      "y": 16,
      "z": -4,
      "name": "Plant_Leaves_Oak"
    },
    {
      "x": -11,
      "y": 16,
      "z": -3,
      "name": "Plant_Leaves_Oak"
    },
    {
      "x": -10,
      "y": 17,
      "z": -6,
      "name": "Plant_Leaves_Oak"
    },
    {
      "x": -10,
      "y": 16,
      "z": -5,
      "name": "Plant_Leaves_Oak"
    },
    {
      "x": -10,
      "y": 17,
      "z": -5,
      "name": "Plant_Leaves_Oak"
    },
    {
      "x": -10,
      "y": 16,
      "z": -4,
      "name": "Plant_Leaves_Oak"
    },
    {
      "x": -10,
      "y": 17,
      "z": -4,
      "name": "Plant_Leaves_Oak"
    },
    {
      "x": -10,
      "y": 18,
      "z": -4,
      "name": "Plant_Leaves_Oak"
    },
    {
      "x": -10,
      "y": 16,
      "z": -3,
      "name": "Plant_Leaves_Oak"
    },
    {
      "x": -10,
      "y": 17,
      "z": -3,
      "name": "Plant_Leaves_Oak"
    },
    {
      "x": -10,
      "y": 17,
      "z": -2,
      "name": "Plant_Leaves_Oak"
    },
    {
      "x": -10,
      "y": 18,
      "z": -2,
      "name": "Plant_Leaves_Oak"
    },
    {
      "x": -10,
      "y": 17,
      "z": 3,
      "name": "Plant_Leaves_Oak"
    },
    {
      "x": -10,
      "y": 18,
      "z": 3,
      "name": "Plant_Leaves_Oak"
    },
    {
      "x": -10,
      "y": 17,
      "z": 4,
      "name": "Plant_Leaves_Oak"
    },
    {
      "x": -10,
      "y": 18,
      "z": 4,
      "name": "Plant_Leaves_Oak"
    },
    {
      "x": -10,
      "y": 18,
      "z": 5,
      "name": "Plant_Leaves_Oak"
    },
    {
      "x": -9,
      "y": 21,
      "z": -8,
      "name": "Plant_Leaves_Oak"
    },
    {
      "x": -9,
      "y": 17,
      "z": -7,
      "name": "Plant_Leaves_Oak"
    },
    {
      "x": -9,
      "y": 17,
      "z": -6,
      "name": "Plant_Leaves_Oak"
    },
    {
      "x": -9,
      "y": 18,
      "z": -6,
      "name": "Plant_Leaves_Oak"
    },
    {
      "x": -9,
      "y": 16,
      "z": -5,
      "name": "Plant_Leaves_Oak"
    },
    {
      "x": -9,
      "y": 17,
      "z": -5,
      "name": "Plant_Leaves_Oak"
    },
    {
      "x": -9,
      "y": 18,
      "z": -5,
      "name": "Plant_Leaves_Oak"
    },
    {
      "x": -9,
      "y": 17,
      "z": -4,
      "name": "Wood_Oak_Branch_Long",
      "rotation": 5
    },
    {
      "x": -9,
      "y": 18,
      "z": -4,
      "name": "Plant_Leaves_Oak"
    },
    {
      "x": -9,
      "y": 19,
      "z": -4,
      "name": "Plant_Leaves_Oak"
    },
    {
      "x": -9,
      "y": 16,
      "z": -3,
      "name": "Plant_Leaves_Oak"
    },
    {
      "x": -9,
      "y": 17,
      "z": -3,
      "name": "Plant_Leaves_Oak"
    },
    {
      "x": -9,
      "y": 18,
      "z": -3,
      "name": "Plant_Leaves_Oak"
    },
    {
      "x": -9,
      "y": 19,
      "z": -3,
      "name": "Plant_Leaves_Oak"
    },
    {
      "x": -9,
      "y": 17,
      "z": -2,
      "name": "Plant_Leaves_Oak"
    },
    {
      "x": -9,
      "y": 18,
      "z": -2,
      "name": "Plant_Leaves_Oak"
    },
    {
      "x": -9,
      "y": 18,
      "z": -1,
      "name": "Plant_Leaves_Oak"
    },
    {
      "x": -9,
      "y": 19,
      "z": -1,
      "name": "Plant_Leaves_Oak"
    },
    {
      "x": -9,
      "y": 20,
      "z": -1,
      "name": "Plant_Leaves_Oak"
    },
    {
      "x": -9,
      "y": 19,
      "z": 0,
      "name": "Plant_Leaves_Oak"
    },
    {
      "x": -9,
      "y": 20,
      "z": 0,
      "name": "Plant_Leaves_Oak"
    },
    {
      "x": -9,
      "y": 19,
      "z": 1,
      "name": "Plant_Leaves_Oak"
    },
    {
      "x": -9,
      "y": 18,
      "z": 2,
      "name": "Plant_Leaves_Oak"
    },
    {
      "x": -9,
      "y": 23,
      "z": 2,
      "name": "Plant_Leaves_Oak"
    },
    {
      "x": -9,
      "y": 17,
      "z": 3,
      "name": "Plant_Leaves_Oak"
    },
    {
      "x": -9,
      "y": 18,
      "z": 3,
      "name": "Plant_Leaves_Oak"
    },
    {
      "x": -9,
      "y": 19,
      "z": 3,
      "name": "Plant_Leaves_Oak"
    },
    {
      "x": -9,
      "y": 18,
      "z": 4,
      "name": "Plant_Leaves_Oak"
    },
    {
      "x": -9,
      "y": 19,
      "z": 4,
      "name": "Plant_Leaves_Oak"
    },
    {
      "x": -9,
      "y": 17,
      "z": 5,
      "name": "Plant_Leaves_Oak"
    },
    {
      "x": -9,
      "y": 18,
      "z": 5,
      "name": "Plant_Leaves_Oak"
    },
    {
      "x": -9,
      "y": 19,
      "z": 5,
      "name": "Plant_Leaves_Oak"
    },
    {
      "x": -9,
      "y": 18,
      "z": 6,
      "name": "Plant_Leaves_Oak"
    },
    {
      "x": -8,
      "y": 20,
      "z": -9,
      "name": "Plant_Leaves_Oak"
    },
    {
      "x": -8,
      "y": 21,
      "z": -9,
      "name": "Plant_Leaves_Oak"
    },
    {
      "x": -8,
      "y": 20,
      "z": -8,
      "name": "Plant_Leaves_Oak"
    },
    {
      "x": -8,
      "y": 21,
      "z": -8,
      "name": "Plant_Leaves_Oak"
    },
    {
      "x": -8,
      "y": 17,
      "z": -7,
      "name": "Plant_Leaves_Oak"
    },
    {
      "x": -8,
      "y": 18,
      "z": -7,
      "name": "Plant_Leaves_Oak"
    },
    {
      "x": -8,
      "y": 20,
      "z": -7,
      "name": "Plant_Leaves_Oak"
    },
    {
      "x": -8,
      "y": 21,
      "z": -7,
      "name": "Plant_Leaves_Oak"
    },
    {
      "x": -8,
      "y": 22,
      "z": -7,
      "name": "Plant_Leaves_Oak"
    },
    {
      "x": -8,
      "y": 17,
      "z": -6,
      "name": "Plant_Leaves_Oak"
    },
    {
      "x": -8,
      "y": 18,
      "z": -6,
      "name": "Plant_Leaves_Oak"
    },
    {
      "x": -8,
      "y": 21,
      "z": -6,
      "name": "Plant_Leaves_Oak"
    },
    {
      "x": -8,
      "y": 18,
      "z": -5,
      "name": "Plant_Leaves_Oak"
    },
    {
      "x": -8,
      "y": 19,
      "z": -5,
      "name": "Plant_Leaves_Oak"
    },
    {
      "x": -8,
      "y": 17,
      "z": -4,
      "name": "Wood_Oak_Trunk_Full"
    },
    {
      "x": -8,
      "y": 18,
      "z": -4,
      "name": "Plant_Leaves_Oak"
    },
    {
      "x": -8,
      "y": 19,
      "z": -4,
      "name": "Plant_Leaves_Oak"
    },
    {
      "x": -8,
      "y": 18,
      "z": -3,
      "name": "Plant_Leaves_Oak"
    },
    {
      "x": -8,
      "y": 19,
      "z": -3,
      "name": "Plant_Leaves_Oak"
    },
    {
      "x": -8,
      "y": 2,
      "z": -2,
      "name": "Wood_Oak_Trunk_Full"
    },
    {
      "x": -8,
      "y": 3,
      "z": -2,
      "name": "Wood_Oak_Trunk_Full"
    },
    {
      "x": -8,
      "y": 17,
      "z": -2,
      "name": "Plant_Leaves_Oak"
    },
    {
      "x": -8,
      "y": 18,
      "z": -2,
      "name": "Plant_Leaves_Oak"
    },
    {
      "x": -8,
      "y": 19,
      "z": -2,
      "name": "Plant_Leaves_Oak"
    },
    {
      "x": -8,
      "y": 20,
      "z": -2,
      "name": "Plant_Leaves_Oak"
    },
    {
      "x": -8,
      "y": 2,
      "z": -1,
      "name": "Wood_Oak_Trunk_Full"
    },
    {
      "x": -8,
      "y": 18,
      "z": -1,
      "name": "Plant_Leaves_Oak"
    },
    {
      "x": -8,
      "y": 19,
      "z": -1,
      "name": "Plant_Leaves_Oak"
    },
    {
      "x": -8,
      "y": 20,
      "z": -1,
      "name": "Plant_Leaves_Oak"
    },
    {
      "x": -8,
      "y": 21,
      "z": -1,
      "name": "Plant_Leaves_Oak"
    },
    {
      "x": -8,
      "y": 20,
      "z": 0,
      "name": "Plant_Leaves_Oak"
    },
    {
      "x": -8,
      "y": 21,
      "z": 0,
      "name": "Plant_Leaves_Oak"
    },
    {
      "x": -8,
      "y": 24,
      "z": 0,
      "name": "Plant_Leaves_Oak"
    },
    {
      "x": -8,
      "y": 20,
      "z": 1,
      "name": "Plant_Leaves_Oak"
    },
    {
      "x": -8,
      "y": 23,
      "z": 1,
      "name": "Plant_Leaves_Oak"
    },
    {
      "x": -8,
      "y": 24,
      "z": 1,
      "name": "Plant_Leaves_Oak"
    },
    {
      "x": -8,
      "y": 25,
      "z": 1,
      "name": "Plant_Leaves_Oak"
    },
    {
      "x": -8,
      "y": 18,
      "z": 2,
      "name": "Plant_Leaves_Oak"
    },
    {
      "x": -8,
      "y": 19,
      "z": 2,
      "name": "Plant_Leaves_Oak"
    },
    {
      "x": -8,
      "y": 23,
      "z": 2,
      "name": "Plant_Leaves_Oak"
    },
    {
      "x": -8,
      "y": 24,
      "z": 2,
      "name": "Plant_Leaves_Oak"
    },
    {
      "x": -8,
      "y": 18,
      "z": 3,
      "name": "Plant_Leaves_Oak"
    },
    {
      "x": -8,
      "y": 19,
      "z": 3,
      "name": "Plant_Leaves_Oak"
    },
    {
      "x": -8,
      "y": 20,
      "z": 3,
      "name": "Plant_Leaves_Oak"
    },
    {
      "x": -8,
      "y": 23,
      "z": 3,
      "name": "Plant_Leaves_Oak"
    },
    {
      "x": -8,
      "y": 24,
      "z": 3,
      "name": "Plant_Leaves_Oak"
    },
    {
      "x": -8,
      "y": 18,
      "z": 4,
      "name": "Plant_Leaves_Oak"
    },
    {
      "x": -8,
      "y": 19,
      "z": 4,
      "name": "Plant_Leaves_Oak"
    },
    {
      "x": -8,
      "y": 20,
      "z": 4,
      "name": "Plant_Leaves_Oak"
    },
    {
      "x": -8,
      "y": 23,
      "z": 4,
      "name": "Plant_Leaves_Oak"
    },
    {
      "x": -8,
      "y": 17,
      "z": 5,
      "name": "Plant_Leaves_Oak"
    },
    {
      "x": -8,
      "y": 18,
      "z": 5,
      "name": "Plant_Leaves_Oak"
    },
    {
      "x": -8,
      "y": 19,
      "z": 5,
      "name": "Plant_Leaves_Oak"
    },
    {
      "x": -8,
      "y": 20,
      "z": 5,
      "name": "Plant_Leaves_Oak"
    },
    {
      "x": -8,
      "y": 18,
      "z": 6,
      "name": "Plant_Leaves_Oak"
    },
    {
      "x": -8,
      "y": 19,
      "z": 6,
      "name": "Plant_Leaves_Oak"
    },
    {
      "x": -8,
      "y": 18,
      "z": 7,
      "name": "Plant_Leaves_Oak"
    },
    {
      "x": -7,
      "y": 20,
      "z": -10,
      "name": "Plant_Leaves_Oak"
    },
    {
      "x": -7,
      "y": 21,
      "z": -10,
      "name": "Plant_Leaves_Oak"
    },
    {
      "x": -7,
      "y": 20,
      "z": -9,
      "name": "Plant_Leaves_Oak"
    },
    {
      "x": -7,
      "y": 21,
      "z": -9,
      "name": "Plant_Leaves_Oak"
    },
    {
      "x": -7,
      "y": 22,
      "z": -9,
      "name": "Plant_Leaves_Oak"
    },
    {
      "x": -7,
      "y": 20,
      "z": -8,
      "name": "Plant_Leaves_Oak"
    },
    {
      "x": -7,
      "y": 21,
      "z": -8,
      "name": "Plant_Leaves_Oak"
    },
    {
      "x": -7,
      "y": 22,
      "z": -8,
      "name": "Plant_Leaves_Oak"
    },
    {
      "x": -7,
      "y": 1,
      "z": -7,
      "name": "Wood_Oak_Trunk_Full"
    },
    {
      "x": -7,
      "y": 18,
      "z": -7,
      "name": "Plant_Leaves_Oak"
    },
    {
      "x": -7,
      "y": 21,
      "z": -7,
      "name": "Plant_Leaves_Oak"
    },
    {
      "x": -7,
      "y": 22,
      "z": -7,
      "name": "Plant_Leaves_Oak"
    },
    {
      "x": -7,
      "y": 1,
      "z": -6,
      "name": "Wood_Oak_Trunk_Full"
    },
    {
      "x": -7,
      "y": 2,
      "z": -6,
      "name": "Wood_Oak_Trunk_Full"
    },
    {
      "x": -7,
      "y": 18,
      "z": -6,
      "name": "Plant_Leaves_Oak"
    },
    {
      "x": -7,
      "y": 19,
      "z": -6,
      "name": "Plant_Leaves_Oak"
    },
    {
      "x": -7,
      "y": 21,
      "z": -6,
      "name": "Plant_Leaves_Oak"
    },
    {
      "x": -7,
      "y": 22,
      "z": -6,
      "name": "Plant_Leaves_Oak"
    },
    {
      "x": -7,
      "y": 23,
      "z": -6,
      "name": "Plant_Leaves_Oak"
    },
    {
      "x": -7,
      "y": 18,
      "z": -5,
      "name": "Plant_Leaves_Oak"
    },
    {
      "x": -7,
      "y": 19,
      "z": -5,
      "name": "Plant_Leaves_Oak"
    },
    {
      "x": -7,
      "y": 22,
      "z": -5,
      "name": "Plant_Leaves_Oak"
    },
    {
      "x": -7,
      "y": 17,
      "z": -4,
      "name": "Wood_Oak_Trunk_Full"
    },
    {
      "x": -7,
      "y": 4,
      "z": -3,
      "name": "Wood_Oak_Trunk_Full"
    },
    {
      "x": -7,
      "y": 5,
      "z": -3,
      "name": "Wood_Oak_Trunk_Full"
    },
    {
      "x": -7,
      "y": 18,
      "z": -3,
      "name": "Plant_Leaves_Oak"
    },
    {
      "x": -7,
      "y": 3,
      "z": -2,
      "name": "Wood_Oak_Trunk_Full"
    },
    {
      "x": -7,
      "y": 4,
      "z": -2,
      "name": "Wood_Oak_Trunk_Full"
    },
    {
      "x": -7,
      "y": 20,
      "z": -2,
      "name": "Plant_Leaves_Oak"
    },
    {
      "x": -7,
      "y": 23,
      "z": -2,
      "name": "Plant_Leaves_Oak"
    },
    {
      "x": -7,
      "y": 20,
      "z": -1,
      "name": "Plant_Leaves_Oak"
    },
    {
      "x": -7,
      "y": 21,
      "z": -1,
      "name": "Plant_Leaves_Oak"
    },
    {
      "x": -7,
      "y": 23,
      "z": -1,
      "name": "Plant_Leaves_Oak"
    },
    {
      "x": -7,
      "y": 24,
      "z": -1,
      "name": "Plant_Leaves_Oak"
    },
    {
      "x": -7,
      "y": 20,
      "z": 0,
      "name": "Plant_Leaves_Oak"
    },
    {
      "x": -7,
      "y": 21,
      "z": 0,
      "name": "Plant_Leaves_Oak"
    },
    {
      "x": -7,
      "y": 22,
      "z": 0,
      "name": "Plant_Leaves_Oak"
    },
    {
      "x": -7,
      "y": 24,
      "z": 0,
      "name": "Plant_Leaves_Oak"
    },
    {
      "x": -7,
      "y": 25,
      "z": 0,
      "name": "Plant_Leaves_Oak"
    },
    {
      "x": -7,
      "y": 20,
      "z": 1,
      "name": "Plant_Leaves_Oak"
    },
    {
      "x": -7,
      "y": 21,
      "z": 1,
      "name": "Plant_Leaves_Oak"
    },
    {
      "x": -7,
      "y": 24,
      "z": 1,
      "name": "Plant_Leaves_Oak"
    },
    {
      "x": -7,
      "y": 25,
      "z": 1,
      "name": "Plant_Leaves_Oak"
    },
    {
      "x": -7,
      "y": 19,
      "z": 2,
      "name": "Plant_Leaves_Oak"
    },
    {
      "x": -7,
      "y": 20,
      "z": 2,
      "name": "Plant_Leaves_Oak"
    },
    {
      "x": -7,
      "y": 21,
      "z": 2,
      "name": "Plant_Leaves_Oak"
    },
    {
      "x": -7,
      "y": 23,
      "z": 2,
      "name": "Plant_Leaves_Oak"
    },
    {
      "x": -7,
      "y": 24,
      "z": 2,
      "name": "Plant_Leaves_Oak"
    },
    {
      "x": -7,
      "y": 25,
      "z": 2,
      "name": "Plant_Leaves_Oak"
    },
    {
      "x": -7,
      "y": 19,
      "z": 3,
      "name": "Plant_Leaves_Oak"
    },
    {
      "x": -7,
      "y": 20,
      "z": 3,
      "name": "Plant_Leaves_Oak"
    },
    {
      "x": -7,
      "y": 22,
      "z": 3,
      "name": "Plant_Leaves_Oak"
    },
    {
      "x": -7,
      "y": 23,
      "z": 3,
      "name": "Plant_Leaves_Oak"
    },
    {
      "x": -7,
      "y": 24,
      "z": 3,
      "name": "Plant_Leaves_Oak"
    },
    {
      "x": -7,
      "y": 25,
      "z": 3,
      "name": "Plant_Leaves_Oak"
    },
    {
      "x": -7,
      "y": 18,
      "z": 4,
      "name": "Plant_Leaves_Oak"
    },
    {
      "x": -7,
      "y": 19,
      "z": 4,
      "name": "Plant_Leaves_Oak"
    },
    {
      "x": -7,
      "y": 20,
      "z": 4,
      "name": "Plant_Leaves_Oak"
    },
    {
      "x": -7,
      "y": 22,
      "z": 4,
      "name": "Plant_Leaves_Oak"
    },
    {
      "x": -7,
      "y": 23,
      "z": 4,
      "name": "Plant_Leaves_Oak"
    },
    {
      "x": -7,
      "y": 24,
      "z": 4,
      "name": "Plant_Leaves_Oak"
    },
    {
      "x": -7,
      "y": 20,
      "z": 5,
      "name": "Plant_Leaves_Oak"
    },
    {
      "x": -7,
      "y": 23,
      "z": 5,
      "name": "Plant_Leaves_Oak"
    },
    {
      "x": -7,
      "y": 1,
      "z": 6,
      "name": "Wood_Oak_Trunk_Full"
    },
    {
      "x": -7,
      "y": 19,
      "z": 6,
      "name": "Plant_Leaves_Oak"
    },
    {
      "x": -7,
      "y": 1,
      "z": 7,
      "name": "Wood_Oak_Trunk_Full"
    },
    {
      "x": -7,
      "y": 19,
      "z": 7,
      "name": "Plant_Leaves_Oak"
    },
    {
      "x": -7,
      "y": 20,
      "z": 7,
      "name": "Plant_Leaves_Oak"
    },
    {
      "x": -7,
      "y": 19,
      "z": 8,
      "name": "Plant_Leaves_Oak"
    },
    {
      "x": -6,
      "y": 18,
      "z": -11,
      "name": "Plant_Leaves_Oak"
    },
    {
      "x": -6,
      "y": 21,
      "z": -11,
      "name": "Plant_Leaves_Oak"
    },
    {
      "x": -6,
      "y": 18,
      "z": -10,
      "name": "Plant_Leaves_Oak"
    },
    {
      "x": -6,
      "y": 19,
      "z": -10,
      "name": "Plant_Leaves_Oak"
    },
    {
      "x": -6,
      "y": 21,
      "z": -10,
      "name": "Plant_Leaves_Oak"
    },
    {
      "x": -6,
      "y": 22,
      "z": -10,
      "name": "Plant_Leaves_Oak"
    },
    {
      "x": -6,
      "y": 20,
      "z": -9,
      "name": "Plant_Leaves_Oak"
    },
    {
      "x": -6,
      "y": 21,
      "z": -9,
      "name": "Plant_Leaves_Oak"
    },
    {
      "x": -6,
      "y": 23,
      "z": -9,
      "name": "Plant_Leaves_Oak"
    },
    {
      "x": -6,
      "y": 21,
      "z": -8,
      "name": "Plant_Leaves_Oak"
    },
    {
      "x": -6,
      "y": 22,
      "z": -8,
      "name": "Plant_Leaves_Oak"
    },
    {
      "x": -6,
      "y": 23,
      "z": -8,
      "name": "Plant_Leaves_Oak"
    },
    {
      "x": -6,
      "y": 18,
      "z": -7,
      "name": "Plant_Leaves_Oak"
    },
    {
      "x": -6,
      "y": 21,
      "z": -7,
      "name": "Wood_Oak_Branch_Long",
      "rotation": 5
    },
    {
      "x": -6,
      "y": 22,
      "z": -7,
      "name": "Plant_Leaves_Oak"
    },
    {
      "x": -6,
      "y": 23,
      "z": -7,
      "name": "Plant_Leaves_Oak"
    },
    {
      "x": -6,
      "y": 2,
      "z": -6,
      "name": "Wood_Oak_Trunk_Full"
    },
    {
      "x": -6,
      "y": 3,
      "z": -6,
      "name": "Wood_Oak_Trunk_Full"
    },
    {
      "x": -6,
      "y": 18,
      "z": -6,
      "name": "Plant_Leaves_Oak"
    },
    {
      "x": -6,
      "y": 19,
      "z": -6,
      "name": "Plant_Leaves_Oak"
    },
    {
      "x": -6,
      "y": 22,
      "z": -6,
      "name": "Plant_Leaves_Oak"
    },
    {
      "x": -6,
      "y": 23,
      "z": -6,
      "name": "Plant_Leaves_Oak"
    },
    {
      "x": -6,
      "y": 4,
      "z": -5,
      "name": "Wood_Oak_Trunk_Full"
    },
    {
      "x": -6,
      "y": 5,
      "z": -5,
      "name": "Wood_Oak_Trunk_Full"
    },
    {
      "x": -6,
      "y": 6,
      "z": -5,
      "name": "Wood_Oak_Trunk_Full"
    },
    {
      "x": -6,
      "y": 5,
      "z": -4,
      "name": "Wood_Oak_Trunk_Full"
    },
    {
      "x": -6,
      "y": 6,
      "z": -4,
      "name": "Wood_Oak_Trunk_Full"
    },
    {
      "x": -6,
      "y": 7,
      "z": -4,
      "name": "Wood_Oak_Trunk_Full"
    },
    {
      "x": -6,
      "y": 17,
      "z": -4,
      "name": "Wood_Oak_Trunk_Full"
    },
    {
      "x": -6,
      "y": 5,
      "z": -3,
      "name": "Wood_Oak_Trunk_Full"
    },
    {
      "x": -6,
      "y": 6,
      "z": -3,
      "name": "Wood_Oak_Trunk_Full"
    },
    {
      "x": -6,
      "y": 17,
      "z": -3,
      "name": "Wood_Oak_Trunk_Full"
    },
    {
      "x": -6,
      "y": 2,
      "z": -2,
      "name": "Soil_Dirt"
    },
    {
      "x": -6,
      "y": 3,
      "z": -2,
      "name": "Soil_Dirt"
    },
    {
      "x": -6,
      "y": 4,
      "z": -2,
      "name": "Soil_Dirt"
    },
    {
      "x": -6,
      "y": 5,
      "z": -2,
      "name": "Soil_Dirt"
    },
    {
      "x": -6,
      "y": 6,
      "z": -2,
      "name": "Soil_Dirt"
    },
    {
      "x": -6,
      "y": 7,
      "z": -2,
      "name": "Soil_Grass_Deep"
    },
    {
      "x": -6,
      "y": 21,
      "z": -2,
      "name": "Plant_Leaves_Oak"
    },
    {
      "x": -6,
      "y": 24,
      "z": -2,
      "name": "Plant_Leaves_Oak"
    },
    {
      "x": -6,
      "y": 2,
      "z": -1,
      "name": "Soil_Dirt"
    },
    {
      "x": -6,
      "y": 3,
      "z": -1,
      "name": "Soil_Dirt"
    },
    {
      "x": -6,
      "y": 4,
      "z": -1,
      "name": "Soil_Dirt"
    },
    {
      "x": -6,
      "y": 5,
      "z": -1,
      "name": "Soil_Dirt"
    },
    {
      "x": -6,
      "y": 6,
      "z": -1,
      "name": "Soil_Dirt"
    },
    {
      "x": -6,
      "y": 7,
      "z": -1,
      "name": "Soil_Grass_Deep"
    },
    {
      "x": -6,
      "y": 21,
      "z": -1,
      "name": "Plant_Leaves_Oak"
    },
    {
      "x": -6,
      "y": 22,
      "z": -1,
      "name": "Plant_Leaves_Oak"
    },
    {
      "x": -6,
      "y": 24,
      "z": -1,
      "name": "Plant_Leaves_Oak"
    },
    {
      "x": -6,
      "y": 25,
      "z": -1,
      "name": "Plant_Leaves_Oak"
    },
    {
      "x": -6,
      "y": 2,
      "z": 0,
      "name": "Soil_Dirt"
    },
    {
      "x": -6,
      "y": 3,
      "z": 0,
      "name": "Soil_Dirt"
    },
    {
      "x": -6,
      "y": 4,
      "z": 0,
      "name": "Soil_Dirt"
    },
    {
      "x": -6,
      "y": 5,
      "z": 0,
      "name": "Soil_Dirt"
    },
    {
      "x": -6,
      "y": 6,
      "z": 0,
      "name": "Soil_Dirt"
    },
    {
      "x": -6,
      "y": 7,
      "z": 0,
      "name": "Soil_Grass_Deep"
    },
    {
      "x": -6,
      "y": 21,
      "z": 0,
      "name": "Plant_Leaves_Oak"
    },
    {
      "x": -6,
      "y": 22,
      "z": 0,
      "name": "Plant_Leaves_Oak"
    },
    {
      "x": -6,
      "y": 24,
      "z": 0,
      "name": "Plant_Leaves_Oak"
    },
    {
      "x": -6,
      "y": 25,
      "z": 0,
      "name": "Plant_Leaves_Oak"
    },
    {
      "x": -6,
      "y": 2,
      "z": 1,
      "name": "Soil_Dirt"
    },
    {
      "x": -6,
      "y": 3,
      "z": 1,
      "name": "Soil_Dirt"
    },
    {
      "x": -6,
      "y": 4,
      "z": 1,
      "name": "Soil_Dirt"
    },
    {
      "x": -6,
      "y": 5,
      "z": 1,
      "name": "Soil_Dirt"
    },
    {
      "x": -6,
      "y": 6,
      "z": 1,
      "name": "Soil_Dirt"
    },
    {
      "x": -6,
      "y": 7,
      "z": 1,
      "name": "Soil_Grass_Deep"
    },
    {
      "x": -6,
      "y": 20,
      "z": 1,
      "name": "Wood_Oak_Branch_Long",
      "rotation": 5
    },
    {
      "x": -6,
      "y": 21,
      "z": 1,
      "name": "Plant_Leaves_Oak"
    },
    {
      "x": -6,
      "y": 22,
      "z": 1,
      "name": "Plant_Leaves_Oak"
    },
    {
      "x": -6,
      "y": 24,
      "z": 1,
      "name": "Plant_Leaves_Oak"
    },
    {
      "x": -6,
      "y": 25,
      "z": 1,
      "name": "Plant_Leaves_Oak"
    },
    {
      "x": -6,
      "y": 2,
      "z": 2,
      "name": "Soil_Dirt"
    },
    {
      "x": -6,
      "y": 3,
      "z": 2,
      "name": "Soil_Dirt"
    },
    {
      "x": -6,
      "y": 4,
      "z": 2,
      "name": "Soil_Dirt"
    },
    {
      "x": -6,
      "y": 5,
      "z": 2,
      "name": "Soil_Dirt"
    },
    {
      "x": -6,
      "y": 6,
      "z": 2,
      "name": "Soil_Dirt"
    },
    {
      "x": -6,
      "y": 7,
      "z": 2,
      "name": "Soil_Grass_Deep"
    },
    {
      "x": -6,
      "y": 20,
      "z": 2,
      "name": "Plant_Leaves_Oak"
    },
    {
      "x": -6,
      "y": 21,
      "z": 2,
      "name": "Plant_Leaves_Oak"
    },
    {
      "x": -6,
      "y": 23,
      "z": 2,
      "name": "Plant_Leaves_Oak"
    },
    {
      "x": -6,
      "y": 24,
      "z": 2,
      "name": "Plant_Leaves_Oak"
    },
    {
      "x": -6,
      "y": 25,
      "z": 2,
      "name": "Plant_Leaves_Oak"
    },
    {
      "x": -6,
      "y": 20,
      "z": 3,
      "name": "Plant_Leaves_Oak"
    },
    {
      "x": -6,
      "y": 23,
      "z": 3,
      "name": "Plant_Leaves_Oak"
    },
    {
      "x": -6,
      "y": 24,
      "z": 3,
      "name": "Plant_Leaves_Oak"
    },
    {
      "x": -6,
      "y": 25,
      "z": 3,
      "name": "Plant_Leaves_Oak"
    },
    {
      "x": -6,
      "y": 19,
      "z": 4,
      "name": "Wood_Oak_Branch_Corner",
      "rotation": 3
    },
    {
      "x": -6,
      "y": 20,
      "z": 4,
      "name": "Plant_Leaves_Oak"
    },
    {
      "x": -6,
      "y": 23,
      "z": 4,
      "name": "Plant_Leaves_Oak"
    },
    {
      "x": -6,
      "y": 24,
      "z": 4,
      "name": "Plant_Leaves_Oak"
    },
    {
      "x": -6,
      "y": 25,
      "z": 4,
      "name": "Plant_Leaves_Oak"
    },
    {
      "x": -6,
      "y": 18,
      "z": 5,
      "name": "Plant_Leaves_Oak"
    },
    {
      "x": -6,
      "y": 19,
      "z": 5,
      "name": "Plant_Leaves_Oak"
    },
    {
      "x": -6,
      "y": 20,
      "z": 5,
      "name": "Plant_Leaves_Oak"
    },
    {
      "x": -6,
      "y": 23,
      "z": 5,
      "name": "Plant_Leaves_Oak"
    },
    {
      "x": -6,
      "y": 19,
      "z": 6,
      "name": "Plant_Leaves_Oak"
    },
    {
      "x": -6,
      "y": 20,
      "z": 6,
      "name": "Plant_Leaves_Oak"
    },
    {
      "x": -6,
      "y": 1,
      "z": 7,
      "name": "Wood_Oak_Trunk_Full"
    },
    {
      "x": -6,
      "y": 2,
      "z": 7,
      "name": "Wood_Oak_Trunk_Full"
    },
    {
      "x": -6,
      "y": 18,
      "z": 7,
      "name": "Plant_Leaves_Oak"
    },
    {
      "x": -6,
      "y": 19,
      "z": 7,
      "name": "Plant_Leaves_Oak"
    },
    {
      "x": -6,
      "y": 20,
      "z": 7,
      "name": "Plant_Leaves_Oak"
    },
    {
      "x": -6,
      "y": 2,
      "z": 8,
      "name": "Wood_Oak_Trunk_Full"
    },
    {
      "x": -6,
      "y": 18,
      "z": 8,
      "name": "Plant_Leaves_Oak"
    },
    {
      "x": -6,
      "y": 19,
      "z": 8,
      "name": "Plant_Leaves_Oak"
    },
    {
      "x": -6,
      "y": 19,
      "z": 9,
      "name": "Plant_Leaves_Oak"
    },
    {
      "x": -6,
      "y": 18,
      "z": 10,
      "name": "Plant_Leaves_Oak"
    },
    {
      "x": -6,
      "y": 18,
      "z": 11,
      "name": "Plant_Leaves_Oak"
    },
    {
      "x": -6,
      "y": 18,
      "z": 12,
      "name": "Plant_Leaves_Oak"
    },
    {
      "x": -5,
      "y": 18,
      "z": -12,
      "name": "Plant_Leaves_Oak"
    },
    {
      "x": -5,
      "y": 18,
      "z": -11,
      "name": "Plant_Leaves_Oak"
    },
    {
      "x": -5,
      "y": 19,
      "z": -11,
      "name": "Plant_Leaves_Oak"
    },
    {
      "x": -5,
      "y": 21,
      "z": -11,
      "name": "Plant_Leaves_Oak"
    },
    {
      "x": -5,
      "y": 22,
      "z": -11,
      "name": "Plant_Leaves_Oak"
    },
    {
      "x": -5,
      "y": 18,
      "z": -10,
      "name": "Plant_Leaves_Oak"
    },
    {
      "x": -5,
      "y": 19,
      "z": -10,
      "name": "Plant_Leaves_Oak"
    },
    {
      "x": -5,
      "y": 20,
      "z": -10,
      "name": "Plant_Leaves_Oak"
    },
    {
      "x": -5,
      "y": 21,
      "z": -10,
      "name": "Plant_Leaves_Oak"
    },
    {
      "x": -5,
      "y": 22,
      "z": -10,
      "name": "Plant_Leaves_Oak"
    },
    {
      "x": -5,
      "y": 18,
      "z": -9,
      "name": "Plant_Leaves_Oak"
    },
    {
      "x": -5,
      "y": 19,
      "z": -9,
      "name": "Plant_Leaves_Oak"
    },
    {
      "x": -5,
      "y": 21,
      "z": -9,
      "name": "Plant_Leaves_Oak"
    },
    {
      "x": -5,
      "y": 22,
      "z": -9,
      "name": "Plant_Leaves_Oak"
    },
    {
      "x": -5,
      "y": 23,
      "z": -9,
      "name": "Plant_Leaves_Oak"
    },
    {
      "x": -5,
      "y": 19,
      "z": -8,
      "name": "Plant_Leaves_Oak"
    },
    {
      "x": -5,
      "y": 21,
      "z": -8,
      "name": "Wood_Oak_Branch_Corner",
      "rotation": 2
    },
    {
      "x": -5,
      "y": 22,
      "z": -8,
      "name": "Plant_Leaves_Oak"
    },
    {
      "x": -5,
      "y": 23,
      "z": -8,
      "name": "Plant_Leaves_Oak"
    },
    {
      "x": -5,
      "y": 2,
      "z": -7,
      "name": "Wood_Oak_Trunk_Full"
    },
    {
      "x": -5,
      "y": 20,
      "z": -7,
      "name": "Wood_Oak_Trunk_Full"
    },
    {
      "x": -5,
      "y": 21,
      "z": -7,
      "name": "Wood_Oak_Trunk_Full"
    },
    {
      "x": -5,
      "y": 22,
      "z": -7,
      "name": "Plant_Leaves_Oak"
    },
    {
      "x": -5,
      "y": 23,
      "z": -7,
      "name": "Plant_Leaves_Oak"
    },
    {
      "x": -5,
      "y": 2,
      "z": -6,
      "name": "Wood_Oak_Trunk_Full"
    },
    {
      "x": -5,
      "y": 3,
      "z": -6,
      "name": "Wood_Oak_Trunk_Full"
    },
    {
      "x": -5,
      "y": 20,
      "z": -6,
      "name": "Wood_Oak_Trunk_Full"
    },
    {
      "x": -5,
      "y": 23,
      "z": -6,
      "name": "Plant_Leaves_Oak"
    },
    {
      "x": -5,
      "y": 20,
      "z": -5,
      "name": "Wood_Oak_Trunk_Full"
    },
    {
      "x": -5,
      "y": 2,
      "z": -4,
      "name": "Soil_Dirt"
    },
    {
      "x": -5,
      "y": 3,
      "z": -4,
      "name": "Soil_Dirt"
    },
    {
      "x": -5,
      "y": 4,
      "z": -4,
      "name": "Soil_Dirt"
    },
    {
      "x": -5,
      "y": 5,
      "z": -4,
      "name": "Soil_Dirt"
    },
    {
      "x": -5,
      "y": 6,
      "z": -4,
      "name": "Wood_Oak_Trunk_Full"
    },
    {
      "x": -5,
      "y": 7,
      "z": -4,
      "name": "Wood_Oak_Trunk_Full"
    },
    {
      "x": -5,
      "y": 8,
      "z": -4,
      "name": "Wood_Oak_Trunk_Full"
    },
    {
      "x": -5,
      "y": 2,
      "z": -3,
      "name": "Soil_Dirt"
    },
    {
      "x": -5,
      "y": 3,
      "z": -3,
      "name": "Soil_Dirt"
    },
    {
      "x": -5,
      "y": 4,
      "z": -3,
      "name": "Soil_Dirt"
    },
    {
      "x": -5,
      "y": 5,
      "z": -3,
      "name": "Soil_Dirt"
    },
    {
      "x": -5,
      "y": 6,
      "z": -3,
      "name": "Wood_Oak_Trunk_Full"
    },
    {
      "x": -5,
      "y": 7,
      "z": -3,
      "name": "Wood_Oak_Trunk_Full"
    },
    {
      "x": -5,
      "y": 8,
      "z": -3,
      "name": "Wood_Oak_Trunk_Full"
    },
    {
      "x": -5,
      "y": 17,
      "z": -3,
      "name": "Wood_Oak_Trunk_Full"
    },
    {
      "x": -5,
      "y": 23,
      "z": -3,
      "name": "Plant_Leaves_Oak"
    },
    {
      "x": -5,
      "y": 24,
      "z": -3,
      "name": "Plant_Leaves_Oak"
    },
    {
      "x": -5,
      "y": 2,
      "z": -2,
      "name": "Soil_Dirt"
    },
    {
      "x": -5,
      "y": 3,
      "z": -2,
      "name": "Soil_Dirt"
    },
    {
      "x": -5,
      "y": 4,
      "z": -2,
      "name": "Soil_Dirt"
    },
    {
      "x": -5,
      "y": 5,
      "z": -2,
      "name": "Soil_Dirt"
    },
    {
      "x": -5,
      "y": 6,
      "z": -2,
      "name": "Soil_Dirt"
    },
    {
      "x": -5,
      "y": 7,
      "z": -2,
      "name": "Soil_Grass_Deep"
    },
    {
      "x": -5,
      "y": 17,
      "z": -2,
      "name": "Wood_Oak_Trunk_Full"
    },
    {
      "x": -5,
      "y": 21,
      "z": -2,
      "name": "Plant_Leaves_Oak"
    },
    {
      "x": -5,
      "y": 23,
      "z": -2,
      "name": "Plant_Leaves_Oak"
    },
    {
      "x": -5,
      "y": 24,
      "z": -2,
      "name": "Plant_Leaves_Oak"
    },
    {
      "x": -5,
      "y": 25,
      "z": -2,
      "name": "Plant_Leaves_Oak"
    },
    {
      "x": -5,
      "y": 2,
      "z": -1,
      "name": "Soil_Dirt"
    },
    {
      "x": -5,
      "y": 3,
      "z": -1,
      "name": "Soil_Dirt"
    },
    {
      "x": -5,
      "y": 4,
      "z": -1,
      "name": "Soil_Dirt"
    },
    {
      "x": -5,
      "y": 5,
      "z": -1,
      "name": "Wood_Oak_Trunk_Full"
    },
    {
      "x": -5,
      "y": 6,
      "z": -1,
      "name": "Wood_Oak_Trunk_Full"
    },
    {
      "x": -5,
      "y": 7,
      "z": -1,
      "name": "Wood_Oak_Trunk_Full"
    },
    {
      "x": -5,
      "y": 16,
      "z": -1,
      "name": "Wood_Oak_Trunk_Full"
    },
    {
      "x": -5,
      "y": 21,
      "z": -1,
      "name": "Plant_Leaves_Oak"
    },
    {
      "x": -5,
      "y": 24,
      "z": -1,
      "name": "Plant_Leaves_Oak"
    },
    {
      "x": -5,
      "y": 25,
      "z": -1,
      "name": "Plant_Leaves_Oak"
    },
    {
      "x": -5,
      "y": 2,
      "z": 0,
      "name": "Soil_Dirt"
    },
    {
      "x": -5,
      "y": 3,
      "z": 0,
      "name": "Soil_Dirt"
    },
    {
      "x": -5,
      "y": 4,
      "z": 0,
      "name": "Soil_Dirt"
    },
    {
      "x": -5,
      "y": 5,
      "z": 0,
      "name": "Soil_Dirt"
    },
    {
      "x": -5,
      "y": 6,
      "z": 0,
      "name": "Soil_Dirt"
    },
    {
      "x": -5,
      "y": 7,
      "z": 0,
      "name": "Soil_Grass_Deep"
    },
    {
      "x": -5,
      "y": 21,
      "z": 0,
      "name": "Plant_Leaves_Oak"
    },
    {
      "x": -5,
      "y": 24,
      "z": 0,
      "name": "Plant_Leaves_Oak"
    },
    {
      "x": -5,
      "y": 25,
      "z": 0,
      "name": "Plant_Leaves_Oak"
    },
    {
      "x": -5,
      "y": 2,
      "z": 1,
      "name": "Soil_Dirt"
    },
    {
      "x": -5,
      "y": 3,
      "z": 1,
      "name": "Soil_Dirt"
    },
    {
      "x": -5,
      "y": 4,
      "z": 1,
      "name": "Soil_Dirt"
    },
    {
      "x": -5,
      "y": 5,
      "z": 1,
      "name": "Soil_Dirt"
    },
    {
      "x": -5,
      "y": 6,
      "z": 1,
      "name": "Soil_Dirt"
    },
    {
      "x": -5,
      "y": 7,
      "z": 1,
      "name": "Soil_Grass_Deep"
    },
    {
      "x": -5,
      "y": 20,
      "z": 1,
      "name": "Wood_Oak_Trunk_Full"
    },
    {
      "x": -5,
      "y": 21,
      "z": 1,
      "name": "Plant_Leaves_Oak"
    },
    {
      "x": -5,
      "y": 24,
      "z": 1,
      "name": "Wood_Oak_Trunk_Full"
    },
    {
      "x": -5,
      "y": 25,
      "z": 1,
      "name": "Plant_Leaves_Oak"
    },
    {
      "x": -5,
      "y": 2,
      "z": 2,
      "name": "Soil_Dirt"
    },
    {
      "x": -5,
      "y": 3,
      "z": 2,
      "name": "Soil_Dirt"
    },
    {
      "x": -5,
      "y": 4,
      "z": 2,
      "name": "Soil_Dirt"
    },
    {
      "x": -5,
      "y": 5,
      "z": 2,
      "name": "Soil_Dirt"
    },
    {
      "x": -5,
      "y": 6,
      "z": 2,
      "name": "Soil_Dirt"
    },
    {
      "x": -5,
      "y": 7,
      "z": 2,
      "name": "Soil_Grass_Deep"
    },
    {
      "x": -5,
      "y": 24,
      "z": 2,
      "name": "Plant_Leaves_Oak"
    },
    {
      "x": -5,
      "y": 25,
      "z": 2,
      "name": "Plant_Leaves_Oak"
    },
    {
      "x": -5,
      "y": 2,
      "z": 3,
      "name": "Soil_Dirt"
    },
    {
      "x": -5,
      "y": 3,
      "z": 3,
      "name": "Soil_Dirt"
    },
    {
      "x": -5,
      "y": 4,
      "z": 3,
      "name": "Soil_Dirt"
    },
    {
      "x": -5,
      "y": 5,
      "z": 3,
      "name": "Soil_Dirt"
    },
    {
      "x": -5,
      "y": 6,
      "z": 3,
      "name": "Soil_Dirt"
    },
    {
      "x": -5,
      "y": 7,
      "z": 3,
      "name": "Soil_Grass_Deep"
    },
    {
      "x": -5,
      "y": 24,
      "z": 3,
      "name": "Plant_Leaves_Oak"
    },
    {
      "x": -5,
      "y": 25,
      "z": 3,
      "name": "Plant_Leaves_Oak"
    },
    {
      "x": -5,
      "y": 2,
      "z": 4,
      "name": "Soil_Dirt"
    },
    {
      "x": -5,
      "y": 3,
      "z": 4,
      "name": "Soil_Dirt"
    },
    {
      "x": -5,
      "y": 4,
      "z": 4,
      "name": "Soil_Dirt"
    },
    {
      "x": -5,
      "y": 5,
      "z": 4,
      "name": "Soil_Dirt"
    },
    {
      "x": -5,
      "y": 6,
      "z": 4,
      "name": "Soil_Dirt"
    },
    {
      "x": -5,
      "y": 7,
      "z": 4,
      "name": "Soil_Grass_Deep"
    },
    {
      "x": -5,
      "y": 19,
      "z": 4,
      "name": "Wood_Oak_Trunk_Full"
    },
    {
      "x": -5,
      "y": 20,
      "z": 4,
      "name": "Plant_Leaves_Oak"
    },
    {
      "x": -5,
      "y": 24,
      "z": 4,
      "name": "Plant_Leaves_Oak"
    },
    {
      "x": -5,
      "y": 26,
      "z": 4,
      "name": "Plant_Leaves_Oak"
    },
    {
      "x": -5,
      "y": 2,
      "z": 5,
      "name": "Soil_Dirt"
    },
    {
      "x": -5,
      "y": 3,
      "z": 5,
      "name": "Soil_Dirt"
    },
    {
      "x": -5,
      "y": 4,
      "z": 5,
      "name": "Soil_Dirt"
    },
    {
      "x": -5,
      "y": 5,
      "z": 5,
      "name": "Soil_Dirt"
    },
    {
      "x": -5,
      "y": 6,
      "z": 5,
      "name": "Soil_Dirt"
    },
    {
      "x": -5,
      "y": 7,
      "z": 5,
      "name": "Soil_Grass_Deep"
    },
    {
      "x": -5,
      "y": 26,
      "z": 5,
      "name": "Plant_Leaves_Oak"
    },
    {
      "x": -5,
      "y": 5,
      "z": 6,
      "name": "Wood_Oak_Trunk_Full"
    },
    {
      "x": -5,
      "y": 20,
      "z": 6,
      "name": "Plant_Leaves_Oak"
    },
    {
      "x": -5,
      "y": 23,
      "z": 6,
      "name": "Plant_Leaves_Oak"
    },
    {
      "x": -5,
      "y": 26,
      "z": 6,
      "name": "Plant_Leaves_Oak"
    },
    {
      "x": -5,
      "y": 19,
      "z": 7,
      "name": "Wood_Oak_Branch_Long",
      "rotation": 5
    },
    {
      "x": -5,
      "y": 20,
      "z": 7,
      "name": "Plant_Leaves_Oak"
    },
    {
      "x": -5,
      "y": 23,
      "z": 7,
      "name": "Plant_Leaves_Oak"
    },
    {
      "x": -5,
      "y": 2,
      "z": 8,
      "name": "Wood_Oak_Trunk_Full"
    },
    {
      "x": -5,
      "y": 3,
      "z": 8,
      "name": "Wood_Oak_Trunk_Full"
    },
    {
      "x": -5,
      "y": 19,
      "z": 8,
      "name": "Plant_Leaves_Oak"
    },
    {
      "x": -5,
      "y": 20,
      "z": 8,
      "name": "Plant_Leaves_Oak"
    },
    {
      "x": -5,
      "y": 23,
      "z": 8,
      "name": "Plant_Leaves_Oak"
    },
    {
      "x": -5,
      "y": 24,
      "z": 8,
      "name": "Plant_Leaves_Oak"
    },
    {
      "x": -5,
      "y": 18,
      "z": 9,
      "name": "Plant_Leaves_Oak"
    },
    {
      "x": -5,
      "y": 19,
      "z": 9,
      "name": "Plant_Leaves_Oak"
    },
    {
      "x": -5,
      "y": 20,
      "z": 9,
      "name": "Plant_Leaves_Oak"
    },
    {
      "x": -5,
      "y": 23,
      "z": 9,
      "name": "Plant_Leaves_Oak"
    },
    {
      "x": -5,
      "y": 19,
      "z": 10,
      "name": "Plant_Leaves_Oak"
    },
    {
      "x": -5,
      "y": 17,
      "z": 11,
      "name": "Plant_Leaves_Oak"
    },
    {
      "x": -5,
      "y": 18,
      "z": 11,
      "name": "Plant_Leaves_Oak"
    },
    {
      "x": -5,
      "y": 19,
      "z": 11,
      "name": "Plant_Leaves_Oak"
    },
    {
      "x": -5,
      "y": 17,
      "z": 12,
      "name": "Plant_Leaves_Oak"
    },
    {
      "x": -5,
      "y": 18,
      "z": 12,
      "name": "Plant_Leaves_Oak"
    },
    {
      "x": -5,
      "y": 19,
      "z": 12,
      "name": "Plant_Leaves_Oak"
    },
    {
      "x": -5,
      "y": 18,
      "z": 13,
      "name": "Plant_Leaves_Oak"
    },
    {
      "x": -4,
      "y": 18,
      "z": -12,
      "name": "Plant_Leaves_Oak"
    },
    {
      "x": -4,
      "y": 18,
      "z": -11,
      "name": "Plant_Leaves_Oak"
    },
    {
      "x": -4,
      "y": 19,
      "z": -11,
      "name": "Plant_Leaves_Oak"
    },
    {
      "x": -4,
      "y": 20,
      "z": -11,
      "name": "Plant_Leaves_Oak"
    },
    {
      "x": -4,
      "y": 21,
      "z": -11,
      "name": "Plant_Leaves_Oak"
    },
    {
      "x": -4,
      "y": 22,
      "z": -11,
      "name": "Plant_Leaves_Oak"
    },
    {
      "x": -4,
      "y": 19,
      "z": -10,
      "name": "Plant_Leaves_Oak"
    },
    {
      "x": -4,
      "y": 20,
      "z": -10,
      "name": "Plant_Leaves_Oak"
    },
    {
      "x": -4,
      "y": 22,
      "z": -10,
      "name": "Plant_Leaves_Oak"
    },
    {
      "x": -4,
      "y": 23,
      "z": -10,
      "name": "Plant_Leaves_Oak"
    },
    {
      "x": -4,
      "y": 19,
      "z": -9,
      "name": "Plant_Leaves_Oak"
    },
    {
      "x": -4,
      "y": 20,
      "z": -9,
      "name": "Plant_Leaves_Oak"
    },
    {
      "x": -4,
      "y": 21,
      "z": -9,
      "name": "Plant_Leaves_Oak"
    },
    {
      "x": -4,
      "y": 22,
      "z": -9,
      "name": "Plant_Leaves_Oak"
    },
    {
      "x": -4,
      "y": 23,
      "z": -9,
      "name": "Plant_Leaves_Oak"
    },
    {
      "x": -4,
      "y": 19,
      "z": -8,
      "name": "Plant_Leaves_Oak"
    },
    {
      "x": -4,
      "y": 22,
      "z": -8,
      "name": "Plant_Leaves_Oak"
    },
    {
      "x": -4,
      "y": 23,
      "z": -8,
      "name": "Plant_Leaves_Oak"
    },
    {
      "x": -4,
      "y": 1,
      "z": -7,
      "name": "Wood_Oak_Trunk_Full"
    },
    {
      "x": -4,
      "y": 2,
      "z": -7,
      "name": "Wood_Oak_Trunk_Full"
    },
    {
      "x": -4,
      "y": 22,
      "z": -7,
      "name": "Plant_Leaves_Oak"
    },
    {
      "x": -4,
      "y": 23,
      "z": -7,
      "name": "Plant_Leaves_Oak"
    },
    {
      "x": -4,
      "y": 18,
      "z": -6,
      "name": "Wood_Oak_Trunk_Full"
    },
    {
      "x": -4,
      "y": 2,
      "z": -5,
      "name": "Soil_Dirt"
    },
    {
      "x": -4,
      "y": 3,
      "z": -5,
      "name": "Soil_Dirt"
    },
    {
      "x": -4,
      "y": 4,
      "z": -5,
      "name": "Soil_Dirt"
    },
    {
      "x": -4,
      "y": 5,
      "z": -5,
      "name": "Soil_Dirt"
    },
    {
      "x": -4,
      "y": 6,
      "z": -5,
      "name": "Soil_Dirt"
    },
    {
      "x": -4,
      "y": 7,
      "z": -5,
      "name": "Soil_Leaves"
    },
    {
      "x": -4,
      "y": 14,
      "z": -5,
      "name": "Furniture_Kweebec_Lantern"
    },
    {
      "x": -4,
      "y": 15,
      "z": -5,
      "name": "Deco_Rope"
    },
    {
      "x": -4,
      "y": 16,
      "z": -5,
      "name": "Deco_Rope"
    },
    {
      "x": -4,
      "y": 17,
      "z": -5,
      "name": "Wood_Oak_Trunk_Full"
    },
    {
      "x": -4,
      "y": 18,
      "z": -5,
      "name": "Wood_Oak_Trunk_Full"
    },
    {
      "x": -4,
      "y": 19,
      "z": -5,
      "name": "Wood_Oak_Trunk_Full"
    },
    {
      "x": -4,
      "y": 20,
      "z": -5,
      "name": "Wood_Oak_Trunk_Full"
    },
    {
      "x": -4,
      "y": 2,
      "z": -4,
      "name": "Soil_Dirt"
    },
    {
      "x": -4,
      "y": 3,
      "z": -4,
      "name": "Soil_Dirt"
    },
    {
      "x": -4,
      "y": 4,
      "z": -4,
      "name": "Soil_Dirt"
    },
    {
      "x": -4,
      "y": 5,
      "z": -4,
      "name": "Soil_Dirt"
    },
    {
      "x": -4,
      "y": 6,
      "z": -4,
      "name": "Soil_Dirt"
    },
    {
      "x": -4,
      "y": 7,
      "z": -4,
      "name": "Soil_Leaves"
    },
    {
      "x": -4,
      "y": 17,
      "z": -4,
      "name": "Wood_Oak_Trunk_Full"
    },
    {
      "x": -4,
      "y": 18,
      "z": -4,
      "name": "Wood_Oak_Trunk_Full"
    },
    {
      "x": -4,
      "y": 19,
      "z": -4,
      "name": "Wood_Oak_Trunk_Full"
    },
    {
      "x": -4,
      "y": 23,
      "z": -4,
      "name": "Plant_Leaves_Oak"
    },
    {
      "x": -4,
      "y": 2,
      "z": -3,
      "name": "Soil_Dirt"
    },
    {
      "x": -4,
      "y": 3,
      "z": -3,
      "name": "Soil_Dirt"
    },
    {
      "x": -4,
      "y": 4,
      "z": -3,
      "name": "Soil_Dirt"
    },
    {
      "x": -4,
      "y": 5,
      "z": -3,
      "name": "Soil_Dirt"
    },
    {
      "x": -4,
      "y": 6,
      "z": -3,
      "name": "Wood_Oak_Trunk_Full"
    },
    {
      "x": -4,
      "y": 7,
      "z": -3,
      "name": "Wood_Oak_Trunk_Full"
    },
    {
      "x": -4,
      "y": 8,
      "z": -3,
      "name": "Wood_Oak_Trunk_Full"
    },
    {
      "x": -4,
      "y": 17,
      "z": -3,
      "name": "Wood_Oak_Trunk_Full"
    },
    {
      "x": -4,
      "y": 18,
      "z": -3,
      "name": "Wood_Oak_Trunk_Full"
    },
    {
      "x": -4,
      "y": 23,
      "z": -3,
      "name": "Plant_Leaves_Oak"
    },
    {
      "x": -4,
      "y": 24,
      "z": -3,
      "name": "Plant_Leaves_Oak"
    },
    {
      "x": -4,
      "y": 25,
      "z": -3,
      "name": "Plant_Leaves_Oak"
    },
    {
      "x": -4,
      "y": 2,
      "z": -2,
      "name": "Soil_Dirt"
    },
    {
      "x": -4,
      "y": 3,
      "z": -2,
      "name": "Soil_Dirt"
    },
    {
      "x": -4,
      "y": 4,
      "z": -2,
      "name": "Soil_Dirt"
    },
    {
      "x": -4,
      "y": 5,
      "z": -2,
      "name": "Soil_Dirt"
    },
    {
      "x": -4,
      "y": 6,
      "z": -2,
      "name": "Wood_Oak_Trunk_Full"
    },
    {
      "x": -4,
      "y": 7,
      "z": -2,
      "name": "Wood_Oak_Trunk_Full"
    },
    {
      "x": -4,
      "y": 8,
      "z": -2,
      "name": "Wood_Oak_Trunk_Full"
    },
    {
      "x": -4,
      "y": 16,
      "z": -2,
      "name": "Wood_Oak_Trunk_Full"
    },
    {
      "x": -4,
      "y": 17,
      "z": -2,
      "name": "Wood_Oak_Trunk_Full"
    },
    {
      "x": -4,
      "y": 18,
      "z": -2,
      "name": "Wood_Oak_Trunk_Full"
    },
    {
      "x": -4,
      "y": 23,
      "z": -2,
      "name": "Plant_Leaves_Oak"
    },
    {
      "x": -4,
      "y": 24,
      "z": -2,
      "name": "Plant_Leaves_Oak"
    },
    {
      "x": -4,
      "y": 25,
      "z": -2,
      "name": "Plant_Leaves_Oak"
    },
    {
      "x": -4,
      "y": 2,
      "z": -1,
      "name": "Soil_Dirt"
    },
    {
      "x": -4,
      "y": 3,
      "z": -1,
      "name": "Soil_Dirt"
    },
    {
      "x": -4,
      "y": 4,
      "z": -1,
      "name": "Soil_Dirt"
    },
    {
      "x": -4,
      "y": 5,
      "z": -1,
      "name": "Soil_Dirt"
    },
    {
      "x": -4,
      "y": 6,
      "z": -1,
      "name": "Soil_Dirt"
    },
    {
      "x": -4,
      "y": 7,
      "z": -1,
      "name": "Wood_Oak_Trunk_Full"
    },
    {
      "x": -4,
      "y": 16,
      "z": -1,
      "name": "Wood_Oak_Trunk_Full"
    },
    {
      "x": -4,
      "y": 17,
      "z": -1,
      "name": "Wood_Oak_Trunk_Full"
    },
    {
      "x": -4,
      "y": 24,
      "z": -1,
      "name": "Plant_Leaves_Oak"
    },
    {
      "x": -4,
      "y": 25,
      "z": -1,
      "name": "Plant_Leaves_Oak"
    },
    {
      "x": -4,
      "y": 2,
      "z": 0,
      "name": "Soil_Dirt"
    },
    {
      "x": -4,
      "y": 3,
      "z": 0,
      "name": "Soil_Dirt"
    },
    {
      "x": -4,
      "y": 4,
      "z": 0,
      "name": "Soil_Dirt"
    },
    {
      "x": -4,
      "y": 5,
      "z": 0,
      "name": "Soil_Dirt"
    },
    {
      "x": -4,
      "y": 6,
      "z": 0,
      "name": "Soil_Dirt"
    },
    {
      "x": -4,
      "y": 7,
      "z": 0,
      "name": "Wood_Oak_Trunk_Full"
    },
    {
      "x": -4,
      "y": 15,
      "z": 0,
      "name": "Wood_Oak_Trunk_Full"
    },
    {
      "x": -4,
      "y": 16,
      "z": 0,
      "name": "Wood_Oak_Trunk_Full"
    },
    {
      "x": -4,
      "y": 17,
      "z": 0,
      "name": "Wood_Oak_Trunk_Full"
    },
    {
      "x": -4,
      "y": 21,
      "z": 0,
      "name": "Plant_Leaves_Oak"
    },
    {
      "x": -4,
      "y": 25,
      "z": 0,
      "name": "Plant_Leaves_Oak"
    },
    {
      "x": -4,
      "y": 2,
      "z": 1,
      "name": "Soil_Dirt"
    },
    {
      "x": -4,
      "y": 3,
      "z": 1,
      "name": "Soil_Dirt"
    },
    {
      "x": -4,
      "y": 4,
      "z": 1,
      "name": "Soil_Dirt"
    },
    {
      "x": -4,
      "y": 5,
      "z": 1,
      "name": "Soil_Dirt"
    },
    {
      "x": -4,
      "y": 6,
      "z": 1,
      "name": "Soil_Dirt"
    },
    {
      "x": -4,
      "y": 7,
      "z": 1,
      "name": "Soil_Grass_Deep"
    },
    {
      "x": -4,
      "y": 15,
      "z": 1,
      "name": "Wood_Oak_Trunk_Full"
    },
    {
      "x": -4,
      "y": 16,
      "z": 1,
      "name": "Wood_Oak_Trunk_Full"
    },
    {
      "x": -4,
      "y": 17,
      "z": 1,
      "name": "Plant_Moss_Rug_Green"
    },
    {
      "x": -4,
      "y": 24,
      "z": 1,
      "name": "Wood_Oak_Trunk_Full"
    },
    {
      "x": -4,
      "y": 25,
      "z": 1,
      "name": "Plant_Leaves_Oak"
    },
    {
      "x": -4,
      "y": 2,
      "z": 2,
      "name": "Soil_Dirt"
    },
    {
      "x": -4,
      "y": 3,
      "z": 2,
      "name": "Soil_Dirt"
    },
    {
      "x": -4,
      "y": 4,
      "z": 2,
      "name": "Soil_Dirt"
    },
    {
      "x": -4,
      "y": 5,
      "z": 2,
      "name": "Wood_Oak_Trunk_Full"
    },
    {
      "x": -4,
      "y": 6,
      "z": 2,
      "name": "Wood_Oak_Trunk_Full"
    },
    {
      "x": -4,
      "y": 7,
      "z": 2,
      "name": "Soil_Pathway"
    },
    {
      "x": -4,
      "y": 20,
      "z": 2,
      "name": "Wood_Oak_Trunk_Full"
    },
    {
      "x": -4,
      "y": 24,
      "z": 2,
      "name": "Plant_Leaves_Oak"
    },
    {
      "x": -4,
      "y": 25,
      "z": 2,
      "name": "Plant_Leaves_Oak"
    },
    {
      "x": -4,
      "y": 27,
      "z": 2,
      "name": "Plant_Leaves_Oak"
    },
    {
      "x": -4,
      "y": 2,
      "z": 3,
      "name": "Soil_Dirt"
    },
    {
      "x": -4,
      "y": 3,
      "z": 3,
      "name": "Soil_Dirt"
    },
    {
      "x": -4,
      "y": 4,
      "z": 3,
      "name": "Soil_Dirt"
    },
    {
      "x": -4,
      "y": 5,
      "z": 3,
      "name": "Soil_Dirt"
    },
    {
      "x": -4,
      "y": 6,
      "z": 3,
      "name": "Wood_Oak_Trunk_Full"
    },
    {
      "x": -4,
      "y": 7,
      "z": 3,
      "name": "Soil_Pathway"
    },
    {
      "x": -4,
      "y": 25,
      "z": 3,
      "name": "Plant_Leaves_Oak"
    },
    {
      "x": -4,
      "y": 26,
      "z": 3,
      "name": "Plant_Leaves_Oak"
    },
    {
      "x": -4,
      "y": 27,
      "z": 3,
      "name": "Plant_Leaves_Oak"
    },
    {
      "x": -4,
      "y": 2,
      "z": 4,
      "name": "Soil_Dirt"
    },
    {
      "x": -4,
      "y": 3,
      "z": 4,
      "name": "Soil_Dirt"
    },
    {
      "x": -4,
      "y": 4,
      "z": 4,
      "name": "Soil_Dirt"
    },
    {
      "x": -4,
      "y": 5,
      "z": 4,
      "name": "Soil_Dirt"
    },
    {
      "x": -4,
      "y": 6,
      "z": 4,
      "name": "Soil_Dirt"
    },
    {
      "x": -4,
      "y": 7,
      "z": 4,
      "name": "Soil_Grass_Deep"
    },
    {
      "x": -4,
      "y": 10,
      "z": 4,
      "name": "Furniture_Kweebec_Lantern"
    },
    {
      "x": -4,
      "y": 11,
      "z": 4,
      "name": "Deco_Rope"
    },
    {
      "x": -4,
      "y": 12,
      "z": 4,
      "name": "Deco_Rope"
    },
    {
      "x": -4,
      "y": 13,
      "z": 4,
      "name": "Wood_Oak_Branch_Corner",
      "rotation": 9
    },
    {
      "x": -4,
      "y": 19,
      "z": 4,
      "name": "Wood_Oak_Trunk_Full"
    },
    {
      "x": -4,
      "y": 25,
      "z": 4,
      "name": "Plant_Leaves_Oak"
    },
    {
      "x": -4,
      "y": 26,
      "z": 4,
      "name": "Plant_Leaves_Oak"
    },
    {
      "x": -4,
      "y": 2,
      "z": 5,
      "name": "Soil_Dirt"
    },
    {
      "x": -4,
      "y": 3,
      "z": 5,
      "name": "Soil_Dirt"
    },
    {
      "x": -4,
      "y": 4,
      "z": 5,
      "name": "Soil_Dirt"
    },
    {
      "x": -4,
      "y": 5,
      "z": 5,
      "name": "Soil_Dirt"
    },
    {
      "x": -4,
      "y": 6,
      "z": 5,
      "name": "Soil_Dirt"
    },
    {
      "x": -4,
      "y": 7,
      "z": 5,
      "name": "Soil_Leaves"
    },
    {
      "x": -4,
      "y": 26,
      "z": 5,
      "name": "Plant_Leaves_Oak"
    },
    {
      "x": -4,
      "y": 27,
      "z": 5,
      "name": "Plant_Leaves_Oak"
    },
    {
      "x": -4,
      "y": 2,
      "z": 6,
      "name": "Soil_Dirt"
    },
    {
      "x": -4,
      "y": 3,
      "z": 6,
      "name": "Soil_Dirt"
    },
    {
      "x": -4,
      "y": 4,
      "z": 6,
      "name": "Soil_Dirt"
    },
    {
      "x": -4,
      "y": 5,
      "z": 6,
      "name": "Soil_Dirt"
    },
    {
      "x": -4,
      "y": 6,
      "z": 6,
      "name": "Soil_Dirt"
    },
    {
      "x": -4,
      "y": 7,
      "z": 6,
      "name": "Soil_Grass_Deep"
    },
    {
      "x": -4,
      "y": 24,
      "z": 6,
      "name": "Plant_Leaves_Oak"
    },
    {
      "x": -4,
      "y": 26,
      "z": 6,
      "name": "Plant_Leaves_Oak"
    },
    {
      "x": -4,
      "y": 27,
      "z": 6,
      "name": "Plant_Leaves_Oak"
    },
    {
      "x": -4,
      "y": 3,
      "z": 7,
      "name": "Wood_Oak_Trunk_Full"
    },
    {
      "x": -4,
      "y": 4,
      "z": 7,
      "name": "Wood_Oak_Trunk_Full"
    },
    {
      "x": -4,
      "y": 19,
      "z": 7,
      "name": "Wood_Oak_Trunk_Full"
    },
    {
      "x": -4,
      "y": 20,
      "z": 7,
      "name": "Plant_Leaves_Oak"
    },
    {
      "x": -4,
      "y": 23,
      "z": 7,
      "name": "Plant_Leaves_Oak"
    },
    {
      "x": -4,
      "y": 24,
      "z": 7,
      "name": "Plant_Leaves_Oak"
    },
    {
      "x": -4,
      "y": 3,
      "z": 8,
      "name": "Wood_Oak_Trunk_Full"
    },
    {
      "x": -4,
      "y": 19,
      "z": 8,
      "name": "Plant_Leaves_Oak"
    },
    {
      "x": -4,
      "y": 20,
      "z": 8,
      "name": "Plant_Leaves_Oak"
    },
    {
      "x": -4,
      "y": 22,
      "z": 8,
      "name": "Plant_Leaves_Oak"
    },
    {
      "x": -4,
      "y": 23,
      "z": 8,
      "name": "Plant_Leaves_Oak"
    },
    {
      "x": -4,
      "y": 24,
      "z": 8,
      "name": "Plant_Leaves_Oak"
    },
    {
      "x": -4,
      "y": 25,
      "z": 8,
      "name": "Plant_Leaves_Oak"
    },
    {
      "x": -4,
      "y": 3,
      "z": 9,
      "name": "Wood_Oak_Trunk_Full"
    },
    {
      "x": -4,
      "y": 4,
      "z": 9,
      "name": "Wood_Oak_Trunk_Full"
    },
    {
      "x": -4,
      "y": 19,
      "z": 9,
      "name": "Plant_Leaves_Oak"
    },
    {
      "x": -4,
      "y": 20,
      "z": 9,
      "name": "Plant_Leaves_Oak"
    },
    {
      "x": -4,
      "y": 23,
      "z": 9,
      "name": "Plant_Leaves_Oak"
    },
    {
      "x": -4,
      "y": 24,
      "z": 9,
      "name": "Plant_Leaves_Oak"
    },
    {
      "x": -4,
      "y": 19,
      "z": 10,
      "name": "Plant_Leaves_Oak"
    },
    {
      "x": -4,
      "y": 20,
      "z": 10,
      "name": "Plant_Leaves_Oak"
    },
    {
      "x": -4,
      "y": 23,
      "z": 10,
      "name": "Plant_Leaves_Oak"
    },
    {
      "x": -4,
      "y": 24,
      "z": 10,
      "name": "Plant_Leaves_Oak"
    },
    {
      "x": -4,
      "y": 2,
      "z": 11,
      "name": "Wood_Oak_Trunk_Full"
    },
    {
      "x": -4,
      "y": 19,
      "z": 11,
      "name": "Plant_Leaves_Oak"
    },
    {
      "x": -4,
      "y": 23,
      "z": 11,
      "name": "Plant_Leaves_Oak"
    },
    {
      "x": -4,
      "y": 17,
      "z": 12,
      "name": "Plant_Leaves_Oak"
    },
    {
      "x": -4,
      "y": 18,
      "z": 12,
      "name": "Plant_Leaves_Oak"
    },
    {
      "x": -4,
      "y": 19,
      "z": 12,
      "name": "Plant_Leaves_Oak"
    },
    {
      "x": -4,
      "y": 17,
      "z": 13,
      "name": "Plant_Leaves_Oak"
    },
    {
      "x": -4,
      "y": 18,
      "z": 13,
      "name": "Plant_Leaves_Oak"
    },
    {
      "x": -4,
      "y": 19,
      "z": 13,
      "name": "Plant_Leaves_Oak"
    },
    {
      "x": -3,
      "y": 17,
      "z": -12,
      "name": "Plant_Leaves_Oak"
    },
    {
      "x": -3,
      "y": 18,
      "z": -12,
      "name": "Plant_Leaves_Oak"
    },
    {
      "x": -3,
      "y": 19,
      "z": -12,
      "name": "Plant_Leaves_Oak"
    },
    {
      "x": -3,
      "y": 18,
      "z": -11,
      "name": "Wood_Oak_Branch_Corner",
      "rotation": 2
    },
    {
      "x": -3,
      "y": 19,
      "z": -11,
      "name": "Plant_Leaves_Oak"
    },
    {
      "x": -3,
      "y": 20,
      "z": -11,
      "name": "Plant_Leaves_Oak"
    },
    {
      "x": -3,
      "y": 22,
      "z": -11,
      "name": "Plant_Leaves_Oak"
    },
    {
      "x": -3,
      "y": 18,
      "z": -10,
      "name": "Wood_Oak_Branch_Long",
      "rotation": 4
    },
    {
      "x": -3,
      "y": 19,
      "z": -10,
      "name": "Plant_Leaves_Oak"
    },
    {
      "x": -3,
      "y": 20,
      "z": -10,
      "name": "Plant_Leaves_Oak"
    },
    {
      "x": -3,
      "y": 22,
      "z": -10,
      "name": "Plant_Leaves_Oak"
    },
    {
      "x": -3,
      "y": 23,
      "z": -10,
      "name": "Plant_Leaves_Oak"
    },
    {
      "x": -3,
      "y": 18,
      "z": -9,
      "name": "Wood_Oak_Trunk_Full"
    },
    {
      "x": -3,
      "y": 19,
      "z": -9,
      "name": "Plant_Leaves_Oak"
    },
    {
      "x": -3,
      "y": 20,
      "z": -9,
      "name": "Plant_Leaves_Oak"
    },
    {
      "x": -3,
      "y": 21,
      "z": -9,
      "name": "Plant_Leaves_Oak"
    },
    {
      "x": -3,
      "y": 22,
      "z": -9,
      "name": "Plant_Leaves_Oak"
    },
    {
      "x": -3,
      "y": 23,
      "z": -9,
      "name": "Plant_Leaves_Oak"
    },
    {
      "x": -3,
      "y": 3,
      "z": -8,
      "name": "Wood_Oak_Trunk_Full"
    },
    {
      "x": -3,
      "y": 18,
      "z": -8,
      "name": "Wood_Oak_Trunk_Full"
    },
    {
      "x": -3,
      "y": 22,
      "z": -8,
      "name": "Plant_Leaves_Oak"
    },
    {
      "x": -3,
      "y": 23,
      "z": -8,
      "name": "Plant_Leaves_Oak"
    },
    {
      "x": -3,
      "y": 18,
      "z": -7,
      "name": "Wood_Oak_Trunk_Full"
    },
    {
      "x": -3,
      "y": 2,
      "z": -6,
      "name": "Soil_Dirt"
    },
    {
      "x": -3,
      "y": 3,
      "z": -6,
      "name": "Soil_Dirt"
    },
    {
      "x": -3,
      "y": 4,
      "z": -6,
      "name": "Soil_Dirt"
    },
    {
      "x": -3,
      "y": 5,
      "z": -6,
      "name": "Soil_Dirt"
    },
    {
      "x": -3,
      "y": 6,
      "z": -6,
      "name": "Soil_Dirt"
    },
    {
      "x": -3,
      "y": 7,
      "z": -6,
      "name": "Soil_Leaves"
    },
    {
      "x": -3,
      "y": 18,
      "z": -6,
      "name": "Wood_Oak_Trunk_Full"
    },
    {
      "x": -3,
      "y": 2,
      "z": -5,
      "name": "Soil_Dirt"
    },
    {
      "x": -3,
      "y": 3,
      "z": -5,
      "name": "Soil_Dirt"
    },
    {
      "x": -3,
      "y": 4,
      "z": -5,
      "name": "Soil_Dirt"
    },
    {
      "x": -3,
      "y": 5,
      "z": -5,
      "name": "Soil_Dirt"
    },
    {
      "x": -3,
      "y": 6,
      "z": -5,
      "name": "Soil_Dirt"
    },
    {
      "x": -3,
      "y": 7,
      "z": -5,
      "name": "Soil_Leaves"
    },
    {
      "x": -3,
      "y": 18,
      "z": -5,
      "name": "Wood_Oak_Trunk_Full"
    },
    {
      "x": -3,
      "y": 2,
      "z": -4,
      "name": "Soil_Dirt"
    },
    {
      "x": -3,
      "y": 3,
      "z": -4,
      "name": "Soil_Dirt"
    },
    {
      "x": -3,
      "y": 4,
      "z": -4,
      "name": "Soil_Dirt"
    },
    {
      "x": -3,
      "y": 5,
      "z": -4,
      "name": "Soil_Dirt"
    },
    {
      "x": -3,
      "y": 6,
      "z": -4,
      "name": "Wood_Oak_Trunk_Full"
    },
    {
      "x": -3,
      "y": 7,
      "z": -4,
      "name": "Wood_Oak_Trunk_Full"
    },
    {
      "x": -3,
      "y": 17,
      "z": -4,
      "name": "Wood_Oak_Trunk_Full"
    },
    {
      "x": -3,
      "y": 18,
      "z": -4,
      "name": "Wood_Oak_Trunk_Full"
    },
    {
      "x": -3,
      "y": 23,
      "z": -4,
      "name": "Plant_Leaves_Oak"
    },
    {
      "x": -3,
      "y": 24,
      "z": -4,
      "name": "Plant_Leaves_Oak"
    },
    {
      "x": -3,
      "y": 2,
      "z": -3,
      "name": "Soil_Dirt"
    },
    {
      "x": -3,
      "y": 3,
      "z": -3,
      "name": "Soil_Dirt"
    },
    {
      "x": -3,
      "y": 4,
      "z": -3,
      "name": "Soil_Dirt"
    },
    {
      "x": -3,
      "y": 5,
      "z": -3,
      "name": "Soil_Dirt"
    },
    {
      "x": -3,
      "y": 6,
      "z": -3,
      "name": "Wood_Oak_Trunk_Full"
    },
    {
      "x": -3,
      "y": 7,
      "z": -3,
      "name": "Wood_Oak_Trunk_Full"
    },
    {
      "x": -3,
      "y": 17,
      "z": -3,
      "name": "Wood_Oak_Trunk_Full"
    },
    {
      "x": -3,
      "y": 23,
      "z": -3,
      "name": "Plant_Leaves_Oak"
    },
    {
      "x": -3,
      "y": 24,
      "z": -3,
      "name": "Plant_Leaves_Oak"
    },
    {
      "x": -3,
      "y": 2,
      "z": -2,
      "name": "Soil_Dirt"
    },
    {
      "x": -3,
      "y": 3,
      "z": -2,
      "name": "Soil_Dirt"
    },
    {
      "x": -3,
      "y": 4,
      "z": -2,
      "name": "Soil_Dirt"
    },
    {
      "x": -3,
      "y": 5,
      "z": -2,
      "name": "Soil_Dirt"
    },
    {
      "x": -3,
      "y": 6,
      "z": -2,
      "name": "Soil_Dirt"
    },
    {
      "x": -3,
      "y": 7,
      "z": -2,
      "name": "Soil_Pathway"
    },
    {
      "x": -3,
      "y": 8,
      "z": -2,
      "name": "Wood_Oak_Trunk_Full"
    },
    {
      "x": -3,
      "y": 9,
      "z": -2,
      "name": "Wood_Oak_Trunk_Full"
    },
    {
      "x": -3,
      "y": 17,
      "z": -2,
      "name": "Wood_Oak_Trunk_Full"
    },
    {
      "x": -3,
      "y": 23,
      "z": -2,
      "name": "Plant_Leaves_Oak"
    },
    {
      "x": -3,
      "y": 24,
      "z": -2,
      "name": "Plant_Leaves_Oak"
    },
    {
      "x": -3,
      "y": 25,
      "z": -2,
      "name": "Plant_Leaves_Oak"
    },
    {
      "x": -3,
      "y": 2,
      "z": -1,
      "name": "Soil_Dirt"
    },
    {
      "x": -3,
      "y": 3,
      "z": -1,
      "name": "Soil_Dirt"
    },
    {
      "x": -3,
      "y": 4,
      "z": -1,
      "name": "Soil_Dirt"
    },
    {
      "x": -3,
      "y": 5,
      "z": -1,
      "name": "Soil_Dirt"
    },
    {
      "x": -3,
      "y": 6,
      "z": -1,
      "name": "Soil_Dirt"
    },
    {
      "x": -3,
      "y": 7,
      "z": -1,
      "name": "Soil_Pathway"
    },
    {
      "x": -3,
      "y": 8,
      "z": -1,
      "name": "Wood_Oak_Trunk_Full"
    },
    {
      "x": -3,
      "y": 9,
      "z": -1,
      "name": "Furniture_Kweebec_Window",
      "rotation": 1
    },
    {
      "x": -3,
      "y": 17,
      "z": -1,
      "name": "Wood_Oak_Trunk_Full"
    },
    {
      "x": -3,
      "y": 18,
      "z": -1,
      "name": "Plant_Moss_Rug_Green"
    },
    {
      "x": -3,
      "y": 24,
      "z": -1,
      "name": "Plant_Leaves_Oak"
    },
    {
      "x": -3,
      "y": 25,
      "z": -1,
      "name": "Plant_Leaves_Oak"
    },
    {
      "x": -3,
      "y": 26,
      "z": -1,
      "name": "Plant_Leaves_Oak"
    },
    {
      "x": -3,
      "y": 2,
      "z": 0,
      "name": "Soil_Dirt"
    },
    {
      "x": -3,
      "y": 3,
      "z": 0,
      "name": "Soil_Dirt"
    },
    {
      "x": -3,
      "y": 4,
      "z": 0,
      "name": "Soil_Dirt"
    },
    {
      "x": -3,
      "y": 5,
      "z": 0,
      "name": "Soil_Dirt"
    },
    {
      "x": -3,
      "y": 6,
      "z": 0,
      "name": "Soil_Dirt"
    },
    {
      "x": -3,
      "y": 7,
      "z": 0,
      "name": "Soil_Pathway"
    },
    {
      "x": -3,
      "y": 8,
      "z": 0,
      "name": "Wood_Oak_Trunk_Full"
    },
    {
      "x": -3,
      "y": 9,
      "z": 0,
      "name": "Wood_Oak_Trunk_Full"
    },
    {
      "x": -3,
      "y": 10,
      "z": 0,
      "name": "Wood_Oak_Trunk_Full"
    },
    {
      "x": -3,
      "y": 16,
      "z": 0,
      "name": "Wood_Oak_Trunk_Full"
    },
    {
      "x": -3,
      "y": 17,
      "z": 0,
      "name": "Plant_Moss_Rug_Green"
    },
    {
      "x": -3,
      "y": 25,
      "z": 0,
      "name": "Plant_Leaves_Oak"
    },
    {
      "x": -3,
      "y": 2,
      "z": 1,
      "name": "Soil_Dirt"
    },
    {
      "x": -3,
      "y": 3,
      "z": 1,
      "name": "Soil_Dirt"
    },
    {
      "x": -3,
      "y": 4,
      "z": 1,
      "name": "Soil_Dirt"
    },
    {
      "x": -3,
      "y": 5,
      "z": 1,
      "name": "Soil_Dirt"
    },
    {
      "x": -3,
      "y": 6,
      "z": 1,
      "name": "Soil_Dirt"
    },
    {
      "x": -3,
      "y": 7,
      "z": 1,
      "name": "Wood_Oak_Trunk_Full"
    },
    {
      "x": -3,
      "y": 8,
      "z": 1,
      "name": "Wood_Oak_Trunk_Full"
    },
    {
      "x": -3,
      "y": 9,
      "z": 1,
      "name": "Wood_Oak_Trunk_Full"
    },
    {
      "x": -3,
      "y": 10,
      "z": 1,
      "name": "Wood_Oak_Trunk_Full"
    },
    {
      "x": -3,
      "y": 11,
      "z": 1,
      "name": "Furniture_Kweebec_Lantern"
    },
    {
      "x": -3,
      "y": 12,
      "z": 1,
      "name": "Deco_Rope"
    },
    {
      "x": -3,
      "y": 13,
      "z": 1,
      "name": "Deco_Rope"
    },
    {
      "x": -3,
      "y": 14,
      "z": 1,
      "name": "Wood_Oak_Trunk_Full"
    },
    {
      "x": -3,
      "y": 15,
      "z": 1,
      "name": "Wood_Oak_Trunk_Full"
    },
    {
      "x": -3,
      "y": 16,
      "z": 1,
      "name": "Wood_Oak_Trunk_Full"
    },
    {
      "x": -3,
      "y": 17,
      "z": 1,
      "name": "Plant_Moss_Rug_Green"
    },
    {
      "x": -3,
      "y": 24,
      "z": 1,
      "name": "Wood_Oak_Trunk_Full"
    },
    {
      "x": -3,
      "y": 2,
      "z": 2,
      "name": "Soil_Dirt"
    },
    {
      "x": -3,
      "y": 3,
      "z": 2,
      "name": "Soil_Dirt"
    },
    {
      "x": -3,
      "y": 4,
      "z": 2,
      "name": "Soil_Dirt"
    },
    {
      "x": -3,
      "y": 5,
      "z": 2,
      "name": "Soil_Dirt"
    },
    {
      "x": -3,
      "y": 6,
      "z": 2,
      "name": "Soil_Dirt"
    },
    {
      "x": -3,
      "y": 7,
      "z": 2,
      "name": "Soil_Leaves"
    },
    {
      "x": -3,
      "y": 13,
      "z": 2,
      "name": "Wood_Oak_Trunk_Full"
    },
    {
      "x": -3,
      "y": 14,
      "z": 2,
      "name": "Wood_Oak_Trunk_Full"
    },
    {
      "x": -3,
      "y": 15,
      "z": 2,
      "name": "Wood_Oak_Trunk_Full"
    },
    {
      "x": -3,
      "y": 16,
      "z": 2,
      "name": "Wood_Oak_Trunk_Full"
    },
    {
      "x": -3,
      "y": 20,
      "z": 2,
      "name": "Wood_Oak_Trunk_Full"
    },
    {
      "x": -3,
      "y": 25,
      "z": 2,
      "name": "Plant_Leaves_Oak"
    },
    {
      "x": -3,
      "y": 27,
      "z": 2,
      "name": "Plant_Leaves_Oak"
    },
    {
      "x": -3,
      "y": 2,
      "z": 3,
      "name": "Soil_Dirt"
    },
    {
      "x": -3,
      "y": 3,
      "z": 3,
      "name": "Soil_Dirt"
    },
    {
      "x": -3,
      "y": 4,
      "z": 3,
      "name": "Soil_Dirt"
    },
    {
      "x": -3,
      "y": 5,
      "z": 3,
      "name": "Soil_Dirt"
    },
    {
      "x": -3,
      "y": 6,
      "z": 3,
      "name": "Wood_Oak_Trunk_Full"
    },
    {
      "x": -3,
      "y": 7,
      "z": 3,
      "name": "Soil_Pathway"
    },
    {
      "x": -3,
      "y": 15,
      "z": 3,
      "name": "Wood_Oak_Trunk_Full"
    },
    {
      "x": -3,
      "y": 19,
      "z": 3,
      "name": "Wood_Oak_Trunk_Full"
    },
    {
      "x": -3,
      "y": 20,
      "z": 3,
      "name": "Wood_Oak_Trunk_Full"
    },
    {
      "x": -3,
      "y": 27,
      "z": 3,
      "name": "Plant_Leaves_Oak"
    },
    {
      "x": -3,
      "y": 2,
      "z": 4,
      "name": "Soil_Dirt"
    },
    {
      "x": -3,
      "y": 3,
      "z": 4,
      "name": "Soil_Dirt"
    },
    {
      "x": -3,
      "y": 4,
      "z": 4,
      "name": "Soil_Dirt"
    },
    {
      "x": -3,
      "y": 5,
      "z": 4,
      "name": "Soil_Dirt"
    },
    {
      "x": -3,
      "y": 6,
      "z": 4,
      "name": "Soil_Dirt"
    },
    {
      "x": -3,
      "y": 7,
      "z": 4,
      "name": "Soil_Pathway"
    },
    {
      "x": -3,
      "y": 13,
      "z": 4,
      "name": "Wood_Oak_Branch_Long",
      "rotation": 5
    },
    {
      "x": -3,
      "y": 19,
      "z": 4,
      "name": "Wood_Oak_Trunk_Full"
    },
    {
      "x": -3,
      "y": 27,
      "z": 4,
      "name": "Plant_Leaves_Oak"
    },
    {
      "x": -3,
      "y": 2,
      "z": 5,
      "name": "Soil_Dirt"
    },
    {
      "x": -3,
      "y": 3,
      "z": 5,
      "name": "Soil_Dirt"
    },
    {
      "x": -3,
      "y": 4,
      "z": 5,
      "name": "Soil_Dirt"
    },
    {
      "x": -3,
      "y": 5,
      "z": 5,
      "name": "Soil_Dirt"
    },
    {
      "x": -3,
      "y": 6,
      "z": 5,
      "name": "Soil_Dirt"
    },
    {
      "x": -3,
      "y": 7,
      "z": 5,
      "name": "Soil_Leaves"
    },
    {
      "x": -3,
      "y": 24,
      "z": 5,
      "name": "Plant_Leaves_Oak"
    },
    {
      "x": -3,
      "y": 26,
      "z": 5,
      "name": "Plant_Leaves_Oak"
    },
    {
      "x": -3,
      "y": 27,
      "z": 5,
      "name": "Plant_Leaves_Oak"
    },
    {
      "x": -3,
      "y": 28,
      "z": 5,
      "name": "Plant_Leaves_Oak"
    },
    {
      "x": -3,
      "y": 2,
      "z": 6,
      "name": "Soil_Dirt"
    },
    {
      "x": -3,
      "y": 3,
      "z": 6,
      "name": "Soil_Dirt"
    },
    {
      "x": -3,
      "y": 4,
      "z": 6,
      "name": "Soil_Dirt"
    },
    {
      "x": -3,
      "y": 5,
      "z": 6,
      "name": "Soil_Dirt"
    },
    {
      "x": -3,
      "y": 6,
      "z": 6,
      "name": "Soil_Dirt"
    },
    {
      "x": -3,
      "y": 7,
      "z": 6,
      "name": "Soil_Grass_Deep"
    },
    {
      "x": -3,
      "y": 24,
      "z": 6,
      "name": "Plant_Leaves_Oak"
    },
    {
      "x": -3,
      "y": 25,
      "z": 6,
      "name": "Plant_Leaves_Oak"
    },
    {
      "x": -3,
      "y": 26,
      "z": 6,
      "name": "Plant_Leaves_Oak"
    },
    {
      "x": -3,
      "y": 27,
      "z": 6,
      "name": "Plant_Leaves_Oak"
    },
    {
      "x": -3,
      "y": 2,
      "z": 7,
      "name": "Soil_Dirt"
    },
    {
      "x": -3,
      "y": 3,
      "z": 7,
      "name": "Soil_Dirt"
    },
    {
      "x": -3,
      "y": 4,
      "z": 7,
      "name": "Soil_Dirt"
    },
    {
      "x": -3,
      "y": 5,
      "z": 7,
      "name": "Soil_Dirt"
    },
    {
      "x": -3,
      "y": 6,
      "z": 7,
      "name": "Soil_Dirt"
    },
    {
      "x": -3,
      "y": 7,
      "z": 7,
      "name": "Soil_Grass_Deep"
    },
    {
      "x": -3,
      "y": 19,
      "z": 7,
      "name": "Wood_Oak_Trunk_Full"
    },
    {
      "x": -3,
      "y": 24,
      "z": 7,
      "name": "Plant_Leaves_Oak"
    },
    {
      "x": -3,
      "y": 25,
      "z": 7,
      "name": "Plant_Leaves_Oak"
    },
    {
      "x": -3,
      "y": 26,
      "z": 7,
      "name": "Plant_Leaves_Oak"
    },
    {
      "x": -3,
      "y": 23,
      "z": 8,
      "name": "Plant_Leaves_Oak"
    },
    {
      "x": -3,
      "y": 24,
      "z": 8,
      "name": "Plant_Leaves_Oak"
    },
    {
      "x": -3,
      "y": 25,
      "z": 8,
      "name": "Plant_Leaves_Oak"
    },
    {
      "x": -3,
      "y": 3,
      "z": 9,
      "name": "Wood_Oak_Trunk_Full"
    },
    {
      "x": -3,
      "y": 4,
      "z": 9,
      "name": "Wood_Oak_Trunk_Full"
    },
    {
      "x": -3,
      "y": 5,
      "z": 9,
      "name": "Wood_Oak_Trunk_Full"
    },
    {
      "x": -3,
      "y": 22,
      "z": 9,
      "name": "Plant_Leaves_Oak"
    },
    {
      "x": -3,
      "y": 23,
      "z": 9,
      "name": "Plant_Leaves_Oak"
    },
    {
      "x": -3,
      "y": 24,
      "z": 9,
      "name": "Plant_Leaves_Oak"
    },
    {
      "x": -3,
      "y": 25,
      "z": 9,
      "name": "Plant_Leaves_Oak"
    },
    {
      "x": -3,
      "y": 2,
      "z": 10,
      "name": "Wood_Oak_Trunk_Full"
    },
    {
      "x": -3,
      "y": 3,
      "z": 10,
      "name": "Wood_Oak_Trunk_Full"
    },
    {
      "x": -3,
      "y": 4,
      "z": 10,
      "name": "Wood_Oak_Trunk_Full"
    },
    {
      "x": -3,
      "y": 18,
      "z": 10,
      "name": "Wood_Oak_Trunk_Full"
    },
    {
      "x": -3,
      "y": 19,
      "z": 10,
      "name": "Plant_Leaves_Oak"
    },
    {
      "x": -3,
      "y": 20,
      "z": 10,
      "name": "Plant_Leaves_Oak"
    },
    {
      "x": -3,
      "y": 22,
      "z": 10,
      "name": "Plant_Leaves_Oak"
    },
    {
      "x": -3,
      "y": 23,
      "z": 10,
      "name": "Plant_Leaves_Oak"
    },
    {
      "x": -3,
      "y": 24,
      "z": 10,
      "name": "Plant_Leaves_Oak"
    },
    {
      "x": -3,
      "y": 2,
      "z": 11,
      "name": "Wood_Oak_Trunk_Full"
    },
    {
      "x": -3,
      "y": 18,
      "z": 11,
      "name": "Wood_Oak_Trunk_Full"
    },
    {
      "x": -3,
      "y": 19,
      "z": 11,
      "name": "Plant_Leaves_Oak"
    },
    {
      "x": -3,
      "y": 20,
      "z": 11,
      "name": "Plant_Leaves_Oak"
    },
    {
      "x": -3,
      "y": 18,
      "z": 12,
      "name": "Wood_Oak_Branch_Corner"
    },
    {
      "x": -3,
      "y": 19,
      "z": 12,
      "name": "Plant_Leaves_Oak"
    },
    {
      "x": -3,
      "y": 20,
      "z": 12,
      "name": "Plant_Leaves_Oak"
    },
    {
      "x": -3,
      "y": 17,
      "z": 13,
      "name": "Plant_Leaves_Oak"
    },
    {
      "x": -3,
      "y": 18,
      "z": 13,
      "name": "Plant_Leaves_Oak"
    },
    {
      "x": -3,
      "y": 19,
      "z": 13,
      "name": "Plant_Leaves_Oak"
    },
    {
      "x": -2,
      "y": 17,
      "z": -12,
      "name": "Plant_Leaves_Oak"
    },
    {
      "x": -2,
      "y": 18,
      "z": -12,
      "name": "Plant_Leaves_Oak"
    },
    {
      "x": -2,
      "y": 19,
      "z": -12,
      "name": "Plant_Leaves_Oak"
    },
    {
      "x": -2,
      "y": 17,
      "z": -11,
      "name": "Plant_Leaves_Oak"
    },
    {
      "x": -2,
      "y": 18,
      "z": -11,
      "name": "Plant_Leaves_Oak"
    },
    {
      "x": -2,
      "y": 19,
      "z": -11,
      "name": "Plant_Leaves_Oak"
    },
    {
      "x": -2,
      "y": 22,
      "z": -11,
      "name": "Plant_Leaves_Oak"
    },
    {
      "x": -2,
      "y": 19,
      "z": -10,
      "name": "Plant_Leaves_Oak"
    },
    {
      "x": -2,
      "y": 20,
      "z": -10,
      "name": "Plant_Leaves_Oak"
    },
    {
      "x": -2,
      "y": 21,
      "z": -10,
      "name": "Plant_Leaves_Oak"
    },
    {
      "x": -2,
      "y": 22,
      "z": -10,
      "name": "Plant_Leaves_Oak"
    },
    {
      "x": -2,
      "y": 23,
      "z": -10,
      "name": "Plant_Leaves_Oak"
    },
    {
      "x": -2,
      "y": 19,
      "z": -9,
      "name": "Plant_Leaves_Oak"
    },
    {
      "x": -2,
      "y": 20,
      "z": -9,
      "name": "Plant_Leaves_Oak"
    },
    {
      "x": -2,
      "y": 21,
      "z": -9,
      "name": "Plant_Leaves_Oak"
    },
    {
      "x": -2,
      "y": 22,
      "z": -9,
      "name": "Plant_Leaves_Oak"
    },
    {
      "x": -2,
      "y": 23,
      "z": -9,
      "name": "Plant_Leaves_Oak"
    },
    {
      "x": -2,
      "y": 3,
      "z": -8,
      "name": "Wood_Oak_Trunk_Full"
    },
    {
      "x": -2,
      "y": 4,
      "z": -8,
      "name": "Wood_Oak_Trunk_Full"
    },
    {
      "x": -2,
      "y": 5,
      "z": -8,
      "name": "Wood_Oak_Trunk_Full"
    },
    {
      "x": -2,
      "y": 22,
      "z": -8,
      "name": "Plant_Leaves_Oak"
    },
    {
      "x": -2,
      "y": 23,
      "z": -8,
      "name": "Plant_Leaves_Oak"
    },
    {
      "x": -2,
      "y": 5,
      "z": -7,
      "name": "Wood_Oak_Trunk_Full"
    },
    {
      "x": -2,
      "y": 2,
      "z": -6,
      "name": "Soil_Dirt"
    },
    {
      "x": -2,
      "y": 3,
      "z": -6,
      "name": "Soil_Dirt"
    },
    {
      "x": -2,
      "y": 4,
      "z": -6,
      "name": "Soil_Dirt"
    },
    {
      "x": -2,
      "y": 5,
      "z": -6,
      "name": "Soil_Dirt"
    },
    {
      "x": -2,
      "y": 6,
      "z": -6,
      "name": "Soil_Dirt"
    },
    {
      "x": -2,
      "y": 7,
      "z": -6,
      "name": "Soil_Leaves"
    },
    {
      "x": -2,
      "y": 2,
      "z": -5,
      "name": "Soil_Dirt"
    },
    {
      "x": -2,
      "y": 3,
      "z": -5,
      "name": "Soil_Dirt"
    },
    {
      "x": -2,
      "y": 4,
      "z": -5,
      "name": "Soil_Dirt"
    },
    {
      "x": -2,
      "y": 5,
      "z": -5,
      "name": "Soil_Dirt"
    },
    {
      "x": -2,
      "y": 6,
      "z": -5,
      "name": "Soil_Dirt"
    },
    {
      "x": -2,
      "y": 7,
      "z": -5,
      "name": "Soil_Grass_Deep"
    },
    {
      "x": -2,
      "y": 18,
      "z": -5,
      "name": "Wood_Oak_Trunk_Full"
    },
    {
      "x": -2,
      "y": 2,
      "z": -4,
      "name": "Soil_Dirt"
    },
    {
      "x": -2,
      "y": 3,
      "z": -4,
      "name": "Soil_Dirt"
    },
    {
      "x": -2,
      "y": 4,
      "z": -4,
      "name": "Soil_Dirt"
    },
    {
      "x": -2,
      "y": 5,
      "z": -4,
      "name": "Soil_Dirt"
    },
    {
      "x": -2,
      "y": 6,
      "z": -4,
      "name": "Soil_Dirt"
    },
    {
      "x": -2,
      "y": 7,
      "z": -4,
      "name": "Soil_Grass_Deep"
    },
    {
      "x": -2,
      "y": 23,
      "z": -4,
      "name": "Plant_Leaves_Oak"
    },
    {
      "x": -2,
      "y": 26,
      "z": -4,
      "name": "Plant_Leaves_Oak"
    },
    {
      "x": -2,
      "y": 2,
      "z": -3,
      "name": "Soil_Dirt"
    },
    {
      "x": -2,
      "y": 3,
      "z": -3,
      "name": "Soil_Dirt"
    },
    {
      "x": -2,
      "y": 4,
      "z": -3,
      "name": "Soil_Dirt"
    },
    {
      "x": -2,
      "y": 5,
      "z": -3,
      "name": "Soil_Dirt"
    },
    {
      "x": -2,
      "y": 6,
      "z": -3,
      "name": "Soil_Dirt"
    },
    {
      "x": -2,
      "y": 7,
      "z": -3,
      "name": "Wood_Oak_Trunk_Full"
    },
    {
      "x": -2,
      "y": 8,
      "z": -3,
      "name": "Wood_Oak_Trunk_Full"
    },
    {
      "x": -2,
      "y": 9,
      "z": -3,
      "name": "Wood_Oak_Trunk_Full"
    },
    {
      "x": -2,
      "y": 10,
      "z": -3,
      "name": "Wood_Oak_Trunk_Full"
    },
    {
      "x": -2,
      "y": 23,
      "z": -3,
      "name": "Plant_Leaves_Oak"
    },
    {
      "x": -2,
      "y": 24,
      "z": -3,
      "name": "Plant_Leaves_Oak"
    },
    {
      "x": -2,
      "y": 26,
      "z": -3,
      "name": "Plant_Leaves_Oak"
    },
    {
      "x": -2,
      "y": 2,
      "z": -2,
      "name": "Soil_Dirt"
    },
    {
      "x": -2,
      "y": 3,
      "z": -2,
      "name": "Soil_Dirt"
    },
    {
      "x": -2,
      "y": 4,
      "z": -2,
      "name": "Soil_Dirt"
    },
    {
      "x": -2,
      "y": 5,
      "z": -2,
      "name": "Soil_Dirt"
    },
    {
      "x": -2,
      "y": 6,
      "z": -2,
      "name": "Soil_Dirt"
    },
    {
      "x": -2,
      "y": 7,
      "z": -2,
      "name": "Soil_Pathway"
    },
    {
      "x": -2,
      "y": 8,
      "z": -2,
      "name": "Furniture_Kweebec_Wardrobe",
      "rotation": 1
    },
    {
      "x": -2,
      "y": 9,
      "z": -2,
      "name": "Furniture_Kweebec_Wardrobe",
      "filler": 1024,
      "rotation": 1
    },
    {
      "x": -2,
      "y": 10,
      "z": -2,
      "name": "Wood_Oak_Trunk_Full"
    },
    {
      "x": -2,
      "y": 23,
      "z": -2,
      "name": "Plant_Leaves_Oak"
    },
    {
      "x": -2,
      "y": 24,
      "z": -2,
      "name": "Plant_Leaves_Oak"
    },
    {
      "x": -2,
      "y": 25,
      "z": -2,
      "name": "Plant_Leaves_Oak"
    },
    {
      "x": -2,
      "y": 2,
      "z": -1,
      "name": "Soil_Dirt"
    },
    {
      "x": -2,
      "y": 3,
      "z": -1,
      "name": "Soil_Dirt"
    },
    {
      "x": -2,
      "y": 4,
      "z": -1,
      "name": "Soil_Dirt"
    },
    {
      "x": -2,
      "y": 5,
      "z": -1,
      "name": "Soil_Dirt"
    },
    {
      "x": -2,
      "y": 6,
      "z": -1,
      "name": "Soil_Dirt"
    },
    {
      "x": -2,
      "y": 7,
      "z": -1,
      "name": "Soil_Pathway"
    },
    {
      "x": -2,
      "y": 8,
      "z": -1,
      "name": "Furniture_Kweebec_Wardrobe",
      "filler": 32,
      "rotation": 1
    },
    {
      "x": -2,
      "y": 9,
      "z": -1,
      "name": "Furniture_Kweebec_Wardrobe",
      "filler": 1056,
      "rotation": 1
    },
    {
      "x": -2,
      "y": 10,
      "z": -1,
      "name": "Wood_Oak_Trunk_Full"
    },
    {
      "x": -2,
      "y": 11,
      "z": -1,
      "name": "Wood_Oak_Trunk_Full"
    },
    {
      "x": -2,
      "y": 24,
      "z": -1,
      "name": "Plant_Leaves_Oak"
    },
    {
      "x": -2,
      "y": 26,
      "z": -1,
      "name": "Plant_Leaves_Oak"
    },
    {
      "x": -2,
      "y": 2,
      "z": 0,
      "name": "Soil_Dirt"
    },
    {
      "x": -2,
      "y": 3,
      "z": 0,
      "name": "Soil_Dirt"
    },
    {
      "x": -2,
      "y": 4,
      "z": 0,
      "name": "Soil_Dirt"
    },
    {
      "x": -2,
      "y": 5,
      "z": 0,
      "name": "Soil_Dirt"
    },
    {
      "x": -2,
      "y": 6,
      "z": 0,
      "name": "Soil_Dirt"
    },
    {
      "x": -2,
      "y": 7,
      "z": 0,
      "name": "Soil_Leaves"
    },
    {
      "x": -2,
      "y": 10,
      "z": 0,
      "name": "Plant_Vine",
      "rotation": 1
    },
    {
      "x": -2,
      "y": 11,
      "z": 0,
      "name": "Wood_Oak_Trunk_Full"
    },
    {
      "x": -2,
      "y": 2,
      "z": 1,
      "name": "Soil_Dirt"
    },
    {
      "x": -2,
      "y": 3,
      "z": 1,
      "name": "Soil_Dirt"
    },
    {
      "x": -2,
      "y": 4,
      "z": 1,
      "name": "Soil_Dirt"
    },
    {
      "x": -2,
      "y": 5,
      "z": 1,
      "name": "Soil_Dirt"
    },
    {
      "x": -2,
      "y": 6,
      "z": 1,
      "name": "Soil_Dirt"
    },
    {
      "x": -2,
      "y": 7,
      "z": 1,
      "name": "Soil_Grass_Deep"
    },
    {
      "x": -2,
      "y": 8,
      "z": 1,
      "name": "Soil_Clay_Brick_Half",
      "rotation": 5
    },
    {
      "x": -2,
      "y": 9,
      "z": 1,
      "name": "Soil_Clay_Brick_Half",
      "rotation": 5
    },
    {
      "x": -2,
      "y": 10,
      "z": 1,
      "name": "Soil_Clay_Brick"
    },
    {
      "x": -2,
      "y": 11,
      "z": 1,
      "name": "Wood_Oak_Trunk_Full"
    },
    {
      "x": -2,
      "y": 12,
      "z": 1,
      "name": "Wood_Oak_Trunk_Full"
    },
    {
      "x": -2,
      "y": 24,
      "z": 1,
      "name": "Wood_Oak_Trunk_Full"
    },
    {
      "x": -2,
      "y": 2,
      "z": 2,
      "name": "Soil_Dirt"
    },
    {
      "x": -2,
      "y": 3,
      "z": 2,
      "name": "Soil_Dirt"
    },
    {
      "x": -2,
      "y": 4,
      "z": 2,
      "name": "Soil_Dirt"
    },
    {
      "x": -2,
      "y": 5,
      "z": 2,
      "name": "Soil_Dirt"
    },
    {
      "x": -2,
      "y": 6,
      "z": 2,
      "name": "Soil_Dirt"
    },
    {
      "x": -2,
      "y": 7,
      "z": 2,
      "name": "Soil_Grass_Deep"
    },
    {
      "x": -2,
      "y": 10,
      "z": 2,
      "name": "Soil_Clay_Brick_Stairs",
      "rotation": 10
    },
    {
      "x": -2,
      "y": 11,
      "z": 2,
      "name": "Wood_Oak_Trunk_Full"
    },
    {
      "x": -2,
      "y": 12,
      "z": 2,
      "name": "Wood_Oak_Trunk_Full"
    },
    {
      "x": -2,
      "y": 13,
      "z": 2,
      "name": "Wood_Oak_Trunk_Full"
    },
    {
      "x": -2,
      "y": 14,
      "z": 2,
      "name": "Wood_Oak_Trunk_Full"
    },
    {
      "x": -2,
      "y": 15,
      "z": 2,
      "name": "Wood_Oak_Trunk_Full"
    },
    {
      "x": -2,
      "y": 16,
      "z": 2,
      "name": "Wood_Oak_Trunk_Full"
    },
    {
      "x": -2,
      "y": 17,
      "z": 2,
      "name": "Plant_Moss_Rug_Green"
    },
    {
      "x": -2,
      "y": 23,
      "z": 2,
      "name": "Wood_Oak_Trunk_Full"
    },
    {
      "x": -2,
      "y": 24,
      "z": 2,
      "name": "Wood_Oak_Trunk_Full"
    },
    {
      "x": -2,
      "y": 27,
      "z": 2,
      "name": "Plant_Leaves_Oak"
    },
    {
      "x": -2,
      "y": 2,
      "z": 3,
      "name": "Soil_Dirt"
    },
    {
      "x": -2,
      "y": 3,
      "z": 3,
      "name": "Soil_Dirt"
    },
    {
      "x": -2,
      "y": 4,
      "z": 3,
      "name": "Soil_Dirt"
    },
    {
      "x": -2,
      "y": 5,
      "z": 3,
      "name": "Soil_Dirt"
    },
    {
      "x": -2,
      "y": 6,
      "z": 3,
      "name": "Soil_Dirt"
    },
    {
      "x": -2,
      "y": 7,
      "z": 3,
      "name": "Soil_Pathway"
    },
    {
      "x": -2,
      "y": 10,
      "z": 3,
      "name": "Soil_Clay_Brick_Half",
      "rotation": 8
    },
    {
      "x": -2,
      "y": 11,
      "z": 3,
      "name": "Wood_Oak_Trunk_Full"
    },
    {
      "x": -2,
      "y": 12,
      "z": 3,
      "name": "Wood_Oak_Trunk_Full"
    },
    {
      "x": -2,
      "y": 13,
      "z": 3,
      "name": "Wood_Oak_Trunk_Full"
    },
    {
      "x": -2,
      "y": 14,
      "z": 3,
      "name": "Wood_Oak_Trunk_Full"
    },
    {
      "x": -2,
      "y": 15,
      "z": 3,
      "name": "Wood_Oak_Trunk_Full"
    },
    {
      "x": -2,
      "y": 16,
      "z": 3,
      "name": "Wood_Oak_Trunk_Full"
    },
    {
      "x": -2,
      "y": 19,
      "z": 3,
      "name": "Wood_Oak_Trunk_Full"
    },
    {
      "x": -2,
      "y": 20,
      "z": 3,
      "name": "Wood_Oak_Trunk_Full"
    },
    {
      "x": -2,
      "y": 27,
      "z": 3,
      "name": "Plant_Leaves_Oak"
    },
    {
      "x": -2,
      "y": 28,
      "z": 3,
      "name": "Plant_Leaves_Oak"
    },
    {
      "x": -2,
      "y": 2,
      "z": 4,
      "name": "Soil_Dirt"
    },
    {
      "x": -2,
      "y": 3,
      "z": 4,
      "name": "Soil_Dirt"
    },
    {
      "x": -2,
      "y": 4,
      "z": 4,
      "name": "Soil_Dirt"
    },
    {
      "x": -2,
      "y": 5,
      "z": 4,
      "name": "Soil_Dirt"
    },
    {
      "x": -2,
      "y": 6,
      "z": 4,
      "name": "Soil_Dirt"
    },
    {
      "x": -2,
      "y": 7,
      "z": 4,
      "name": "Soil_Leaves"
    },
    {
      "x": -2,
      "y": 8,
      "z": 4,
      "name": "Plant_Grass_Lush_Short"
    },
    {
      "x": -2,
      "y": 13,
      "z": 4,
      "name": "Wood_Oak_Trunk_Full"
    },
    {
      "x": -2,
      "y": 14,
      "z": 4,
      "name": "Wood_Oak_Trunk_Full"
    },
    {
      "x": -2,
      "y": 15,
      "z": 4,
      "name": "Wood_Oak_Trunk_Full"
    },
    {
      "x": -2,
      "y": 16,
      "z": 4,
      "name": "Wood_Oak_Trunk_Full"
    },
    {
      "x": -2,
      "y": 19,
      "z": 4,
      "name": "Wood_Oak_Trunk_Full"
    },
    {
      "x": -2,
      "y": 27,
      "z": 4,
      "name": "Plant_Leaves_Oak"
    },
    {
      "x": -2,
      "y": 28,
      "z": 4,
      "name": "Plant_Leaves_Oak"
    },
    {
      "x": -2,
      "y": 29,
      "z": 4,
      "name": "Plant_Leaves_Oak"
    },
    {
      "x": -2,
      "y": 2,
      "z": 5,
      "name": "Soil_Dirt"
    },
    {
      "x": -2,
      "y": 3,
      "z": 5,
      "name": "Soil_Dirt"
    },
    {
      "x": -2,
      "y": 4,
      "z": 5,
      "name": "Soil_Dirt"
    },
    {
      "x": -2,
      "y": 5,
      "z": 5,
      "name": "Soil_Dirt"
    },
    {
      "x": -2,
      "y": 6,
      "z": 5,
      "name": "Soil_Dirt"
    },
    {
      "x": -2,
      "y": 7,
      "z": 5,
      "name": "Soil_Leaves"
    },
    {
      "x": -2,
      "y": 8,
      "z": 5,
      "name": "Wood_Oak_Trunk_Full"
    },
    {
      "x": -2,
      "y": 14,
      "z": 5,
      "name": "Wood_Oak_Trunk_Full"
    },
    {
      "x": -2,
      "y": 15,
      "z": 5,
      "name": "Wood_Oak_Trunk_Full"
    },
    {
      "x": -2,
      "y": 27,
      "z": 5,
      "name": "Plant_Leaves_Oak"
    },
    {
      "x": -2,
      "y": 28,
      "z": 5,
      "name": "Plant_Leaves_Oak"
    },
    {
      "x": -2,
      "y": 2,
      "z": 6,
      "name": "Soil_Dirt"
    },
    {
      "x": -2,
      "y": 3,
      "z": 6,
      "name": "Soil_Dirt"
    },
    {
      "x": -2,
      "y": 4,
      "z": 6,
      "name": "Soil_Dirt"
    },
    {
      "x": -2,
      "y": 5,
      "z": 6,
      "name": "Soil_Dirt"
    },
    {
      "x": -2,
      "y": 6,
      "z": 6,
      "name": "Wood_Oak_Trunk_Full"
    },
    {
      "x": -2,
      "y": 7,
      "z": 6,
      "name": "Wood_Oak_Trunk_Full"
    },
    {
      "x": -2,
      "y": 8,
      "z": 6,
      "name": "Wood_Oak_Trunk_Full"
    },
    {
      "x": -2,
      "y": 9,
      "z": 6,
      "name": "Plant_Moss_Rug_Green"
    },
    {
      "x": -2,
      "y": 27,
      "z": 6,
      "name": "Plant_Leaves_Oak"
    },
    {
      "x": -2,
      "y": 2,
      "z": 7,
      "name": "Soil_Dirt"
    },
    {
      "x": -2,
      "y": 3,
      "z": 7,
      "name": "Soil_Dirt"
    },
    {
      "x": -2,
      "y": 4,
      "z": 7,
      "name": "Soil_Dirt"
    },
    {
      "x": -2,
      "y": 5,
      "z": 7,
      "name": "Soil_Dirt"
    },
    {
      "x": -2,
      "y": 6,
      "z": 7,
      "name": "Soil_Dirt"
    },
    {
      "x": -2,
      "y": 7,
      "z": 7,
      "name": "Soil_Grass_Deep"
    },
    {
      "x": -2,
      "y": 19,
      "z": 7,
      "name": "Wood_Oak_Trunk_Full"
    },
    {
      "x": -2,
      "y": 25,
      "z": 7,
      "name": "Plant_Leaves_Oak"
    },
    {
      "x": -2,
      "y": 27,
      "z": 7,
      "name": "Plant_Leaves_Oak"
    },
    {
      "x": -2,
      "y": 28,
      "z": 7,
      "name": "Plant_Leaves_Oak"
    },
    {
      "x": -2,
      "y": 5,
      "z": 8,
      "name": "Wood_Oak_Trunk_Full"
    },
    {
      "x": -2,
      "y": 6,
      "z": 8,
      "name": "Wood_Oak_Trunk_Full"
    },
    {
      "x": -2,
      "y": 7,
      "z": 8,
      "name": "Wood_Oak_Trunk_Full"
    },
    {
      "x": -2,
      "y": 18,
      "z": 8,
      "name": "Wood_Oak_Trunk_Full"
    },
    {
      "x": -2,
      "y": 19,
      "z": 8,
      "name": "Wood_Oak_Trunk_Full"
    },
    {
      "x": -2,
      "y": 23,
      "z": 8,
      "name": "Plant_Leaves_Oak"
    },
    {
      "x": -2,
      "y": 24,
      "z": 8,
      "name": "Wood_Oak_Branch_Corner",
      "rotation": 3
    },
    {
      "x": -2,
      "y": 25,
      "z": 8,
      "name": "Plant_Leaves_Oak"
    },
    {
      "x": -2,
      "y": 4,
      "z": 9,
      "name": "Wood_Oak_Roots"
    },
    {
      "x": -2,
      "y": 5,
      "z": 9,
      "name": "Wood_Oak_Trunk_Full"
    },
    {
      "x": -2,
      "y": 6,
      "z": 9,
      "name": "Wood_Oak_Trunk_Full"
    },
    {
      "x": -2,
      "y": 18,
      "z": 9,
      "name": "Wood_Oak_Trunk_Full"
    },
    {
      "x": -2,
      "y": 23,
      "z": 9,
      "name": "Plant_Leaves_Oak"
    },
    {
      "x": -2,
      "y": 24,
      "z": 9,
      "name": "Plant_Leaves_Oak"
    },
    {
      "x": -2,
      "y": 25,
      "z": 9,
      "name": "Plant_Leaves_Oak"
    },
    {
      "x": -2,
      "y": 26,
      "z": 9,
      "name": "Plant_Leaves_Oak"
    },
    {
      "x": -2,
      "y": 4,
      "z": 10,
      "name": "Wood_Oak_Trunk_Full"
    },
    {
      "x": -2,
      "y": 5,
      "z": 10,
      "name": "Wood_Oak_Trunk_Full"
    },
    {
      "x": -2,
      "y": 18,
      "z": 10,
      "name": "Wood_Oak_Trunk_Full"
    },
    {
      "x": -2,
      "y": 22,
      "z": 10,
      "name": "Plant_Leaves_Oak"
    },
    {
      "x": -2,
      "y": 23,
      "z": 10,
      "name": "Plant_Leaves_Oak"
    },
    {
      "x": -2,
      "y": 24,
      "z": 10,
      "name": "Plant_Leaves_Oak"
    },
    {
      "x": -2,
      "y": 19,
      "z": 11,
      "name": "Plant_Leaves_Oak"
    },
    {
      "x": -2,
      "y": 20,
      "z": 11,
      "name": "Plant_Leaves_Oak"
    },
    {
      "x": -2,
      "y": 24,
      "z": 11,
      "name": "Plant_Leaves_Oak"
    },
    {
      "x": -2,
      "y": 19,
      "z": 12,
      "name": "Plant_Leaves_Oak"
    },
    {
      "x": -2,
      "y": 20,
      "z": 12,
      "name": "Plant_Leaves_Oak"
    },
    {
      "x": -2,
      "y": 19,
      "z": 13,
      "name": "Plant_Leaves_Oak"
    },
    {
      "x": -1,
      "y": 17,
      "z": -12,
      "name": "Plant_Leaves_Oak"
    },
    {
      "x": -1,
      "y": 18,
      "z": -12,
      "name": "Plant_Leaves_Oak"
    },
    {
      "x": -1,
      "y": 17,
      "z": -11,
      "name": "Plant_Leaves_Oak"
    },
    {
      "x": -1,
      "y": 18,
      "z": -11,
      "name": "Plant_Leaves_Oak"
    },
    {
      "x": -1,
      "y": 19,
      "z": -11,
      "name": "Plant_Leaves_Oak"
    },
    {
      "x": -1,
      "y": 18,
      "z": -10,
      "name": "Plant_Leaves_Oak"
    },
    {
      "x": -1,
      "y": 19,
      "z": -10,
      "name": "Plant_Leaves_Oak"
    },
    {
      "x": -1,
      "y": 22,
      "z": -10,
      "name": "Plant_Leaves_Oak"
    },
    {
      "x": -1,
      "y": 19,
      "z": -9,
      "name": "Plant_Leaves_Oak"
    },
    {
      "x": -1,
      "y": 21,
      "z": -9,
      "name": "Plant_Leaves_Oak"
    },
    {
      "x": -1,
      "y": 22,
      "z": -9,
      "name": "Plant_Leaves_Oak"
    },
    {
      "x": -1,
      "y": 5,
      "z": -8,
      "name": "Wood_Oak_Trunk_Full"
    },
    {
      "x": -1,
      "y": 22,
      "z": -8,
      "name": "Plant_Leaves_Oak"
    },
    {
      "x": -1,
      "y": 23,
      "z": -8,
      "name": "Plant_Leaves_Oak"
    },
    {
      "x": -1,
      "y": 2,
      "z": -6,
      "name": "Soil_Dirt"
    },
    {
      "x": -1,
      "y": 3,
      "z": -6,
      "name": "Soil_Dirt"
    },
    {
      "x": -1,
      "y": 4,
      "z": -6,
      "name": "Soil_Dirt"
    },
    {
      "x": -1,
      "y": 5,
      "z": -6,
      "name": "Soil_Dirt"
    },
    {
      "x": -1,
      "y": 6,
      "z": -6,
      "name": "Soil_Dirt"
    },
    {
      "x": -1,
      "y": 7,
      "z": -6,
      "name": "Soil_Leaves"
    },
    {
      "x": -1,
      "y": 18,
      "z": -6,
      "name": "Wood_Oak_Trunk_Full"
    },
    {
      "x": -1,
      "y": 2,
      "z": -5,
      "name": "Soil_Dirt"
    },
    {
      "x": -1,
      "y": 3,
      "z": -5,
      "name": "Soil_Dirt"
    },
    {
      "x": -1,
      "y": 4,
      "z": -5,
      "name": "Soil_Dirt"
    },
    {
      "x": -1,
      "y": 5,
      "z": -5,
      "name": "Soil_Dirt"
    },
    {
      "x": -1,
      "y": 6,
      "z": -5,
      "name": "Soil_Dirt"
    },
    {
      "x": -1,
      "y": 7,
      "z": -5,
      "name": "Soil_Grass_Deep"
    },
    {
      "x": -1,
      "y": 18,
      "z": -5,
      "name": "Wood_Oak_Trunk_Full"
    },
    {
      "x": -1,
      "y": 24,
      "z": -5,
      "name": "Plant_Leaves_Oak"
    },
    {
      "x": -1,
      "y": 25,
      "z": -5,
      "name": "Plant_Leaves_Oak"
    },
    {
      "x": -1,
      "y": 2,
      "z": -4,
      "name": "Soil_Dirt"
    },
    {
      "x": -1,
      "y": 3,
      "z": -4,
      "name": "Soil_Dirt"
    },
    {
      "x": -1,
      "y": 4,
      "z": -4,
      "name": "Soil_Dirt"
    },
    {
      "x": -1,
      "y": 5,
      "z": -4,
      "name": "Soil_Dirt"
    },
    {
      "x": -1,
      "y": 6,
      "z": -4,
      "name": "Wood_Oak_Trunk_Full"
    },
    {
      "x": -1,
      "y": 7,
      "z": -4,
      "name": "Wood_Oak_Trunk_Full"
    },
    {
      "x": -1,
      "y": 8,
      "z": -4,
      "name": "Wood_Oak_Trunk_Full"
    },
    {
      "x": -1,
      "y": 9,
      "z": -4,
      "name": "Wood_Oak_Trunk_Full"
    },
    {
      "x": -1,
      "y": 25,
      "z": -4,
      "name": "Plant_Leaves_Oak"
    },
    {
      "x": -1,
      "y": 26,
      "z": -4,
      "name": "Plant_Leaves_Oak"
    },
    {
      "x": -1,
      "y": 2,
      "z": -3,
      "name": "Soil_Dirt"
    },
    {
      "x": -1,
      "y": 3,
      "z": -3,
      "name": "Soil_Dirt"
    },
    {
      "x": -1,
      "y": 4,
      "z": -3,
      "name": "Soil_Dirt"
    },
    {
      "x": -1,
      "y": 5,
      "z": -3,
      "name": "Soil_Dirt"
    },
    {
      "x": -1,
      "y": 6,
      "z": -3,
      "name": "Wood_Oak_Trunk_Full"
    },
    {
      "x": -1,
      "y": 7,
      "z": -3,
      "name": "Soil_Dirt_Tilled"
    },
    {
      "x": -1,
      "y": 8,
      "z": -3,
      "name": "Plant_Crop_Mushroom_Flatcap_Green",
      "components": {
        "Components": {
          "FarmingBlock": {}
        }
      }
    },
    {
      "x": -1,
      "y": 9,
      "z": -3,
      "name": "Furniture_Kweebec_Painting"
    },
    {
      "x": -1,
      "y": 10,
      "z": -3,
      "name": "Wood_Oak_Trunk_Full"
    },
    {
      "x": -1,
      "y": 11,
      "z": -3,
      "name": "Wood_Oak_Trunk_Full"
    },
    {
      "x": -1,
      "y": 23,
      "z": -3,
      "name": "Plant_Leaves_Oak"
    },
    {
      "x": -1,
      "y": 25,
      "z": -3,
      "name": "Plant_Leaves_Oak"
    },
    {
      "x": -1,
      "y": 26,
      "z": -3,
      "name": "Plant_Leaves_Oak"
    },
    {
      "x": -1,
      "y": 2,
      "z": -2,
      "name": "Soil_Dirt"
    },
    {
      "x": -1,
      "y": 3,
      "z": -2,
      "name": "Soil_Dirt"
    },
    {
      "x": -1,
      "y": 4,
      "z": -2,
      "name": "Soil_Dirt"
    },
    {
      "x": -1,
      "y": 5,
      "z": -2,
      "name": "Soil_Dirt"
    },
    {
      "x": -1,
      "y": 6,
      "z": -2,
      "name": "Wood_Oak_Trunk_Full"
    },
    {
      "x": -1,
      "y": 7,
      "z": -2,
      "name": "Soil_Pathway"
    },
    {
      "x": -1,
      "y": 11,
      "z": -2,
      "name": "Wood_Oak_Trunk_Full"
    },
    {
      "x": -1,
      "y": 26,
      "z": -2,
      "name": "Plant_Leaves_Oak"
    },
    {
      "x": -1,
      "y": 27,
      "z": -2,
      "name": "Plant_Leaves_Oak"
    },
    {
      "x": -1,
      "y": 2,
      "z": -1,
      "name": "Soil_Dirt"
    },
    {
      "x": -1,
      "y": 3,
      "z": -1,
      "name": "Soil_Dirt"
    },
    {
      "x": -1,
      "y": 4,
      "z": -1,
      "name": "Soil_Dirt"
    },
    {
      "x": -1,
      "y": 5,
      "z": -1,
      "name": "Soil_Dirt"
    },
    {
      "x": -1,
      "y": 6,
      "z": -1,
      "name": "Soil_Dirt"
    },
    {
      "x": -1,
      "y": 7,
      "z": -1,
      "name": "Soil_Leaves"
    },
    {
      "x": -1,
      "y": 11,
      "z": -1,
      "name": "Wood_Oak_Trunk_Full"
    },
    {
      "x": -1,
      "y": 26,
      "z": -1,
      "name": "Plant_Leaves_Oak"
    },
    {
      "x": -1,
      "y": 1,
      "z": 0,
      "name": "Wood_Oak_Trunk_Full"
    },
    {
      "x": -1,
      "y": 2,
      "z": 0,
      "name": "Soil_Dirt"
    },
    {
      "x": -1,
      "y": 3,
      "z": 0,
      "name": "Soil_Dirt"
    },
    {
      "x": -1,
      "y": 4,
      "z": 0,
      "name": "Soil_Dirt"
    },
    {
      "x": -1,
      "y": 5,
      "z": 0,
      "name": "Soil_Dirt"
    },
    {
      "x": -1,
      "y": 6,
      "z": 0,
      "name": "Soil_Dirt"
    },
    {
      "x": -1,
      "y": 7,
      "z": 0,
      "name": "Soil_Leaves"
    },
    {
      "x": -1,
      "y": 11,
      "z": 0,
      "name": "Wood_Oak_Trunk_Full"
    },
    {
      "x": -1,
      "y": 12,
      "z": 0,
      "name": "Wood_Oak_Trunk_Full"
    },
    {
      "x": -1,
      "y": 13,
      "z": 0,
      "name": "Wood_Oak_Trunk_Full"
    },
    {
      "x": -1,
      "y": 26,
      "z": 0,
      "name": "Plant_Leaves_Oak"
    },
    {
      "x": -1,
      "y": 1,
      "z": 1,
      "name": "Wood_Oak_Trunk_Full"
    },
    {
      "x": -1,
      "y": 2,
      "z": 1,
      "name": "Soil_Dirt"
    },
    {
      "x": -1,
      "y": 3,
      "z": 1,
      "name": "Soil_Dirt"
    },
    {
      "x": -1,
      "y": 4,
      "z": 1,
      "name": "Soil_Dirt"
    },
    {
      "x": -1,
      "y": 5,
      "z": 1,
      "name": "Soil_Dirt"
    },
    {
      "x": -1,
      "y": 6,
      "z": 1,
      "name": "Soil_Dirt"
    },
    {
      "x": -1,
      "y": 7,
      "z": 1,
      "name": "Soil_Grass_Deep"
    },
    {
      "x": -1,
      "y": 10,
      "z": 1,
      "name": "Soil_Clay_Brick_Stairs",
      "rotation": 11
    },
    {
      "x": -1,
      "y": 11,
      "z": 1,
      "name": "Wood_Oak_Trunk_Full"
    },
    {
      "x": -1,
      "y": 12,
      "z": 1,
      "name": "Wood_Oak_Trunk_Full"
    },
    {
      "x": -1,
      "y": 13,
      "z": 1,
      "name": "Wood_Oak_Trunk_Full"
    },
    {
      "x": -1,
      "y": 14,
      "z": 1,
      "name": "Wood_Oak_Trunk_Full"
    },
    {
      "x": -1,
      "y": 15,
      "z": 1,
      "name": "Wood_Oak_Trunk_Full"
    },
    {
      "x": -1,
      "y": 28,
