{
  "version": 8,
  "blockIdVersion": 8,
  "anchorX": 0,
  "anchorY": 6,
  "anchorZ": 0,
  "blocks": [
    {
      "x": -6,
      "y": 6,
      "z": -4,
      "name": "Wood_Deadwood_Planks_Half",
      "rotation": 6
    },
    {
      "x": -6,
      "y": 9,
      "z": -4,
      "name": "Wood_Deadwood_Roof",
      "rotation": 2
    },
    {
      "x": -6,
      "y": 0,
      "z": -3,
      "name": "Wood_Deadwood_Beam"
    },
    {
      "x": -6,
      "y": 1,
      "z": -3,
      "name": "Wood_Deadwood_Beam"
    },
    {
      "x": -6,
      "y": 2,
      "z": -3,
      "name": "Wood_Deadwood_Beam"
    },
    {
      "x": -6,
      "y": 3,
      "z": -3,
      "name": "Wood_Deadwood_Beam"
    },
    {
      "x": -6,
      "y": 4,
      "z": -3,
      "name": "Wood_Deadwood_Beam"
    },
    {
      "x": -6,
      "y": 5,
      "z": -3,
      "name": "Wood_Deadwood_Beam"
    },
    {
      "x": -6,
      "y": 6,
      "z": -3,
      "name": "Wood_Deadwood_Planks"
    },
    {
      "x": -6,
      "y": 7,
      "z": -3,
      "name": "Wood_Deadwood_Planks"
    },
    {
      "x": -6,
      "y": 8,
      "z": -3,
      "name": "Wood_Deadwood_Planks_Half",
      "rotation": 7
    },
    {
      "x": -6,
      "y": 9,
      "z": -3,
      "name": "Wood_Deadwood_Stairs",
      "rotation": 10
    },
    {
      "x": -6,
      "y": 10,
      "z": -3,
      "name": "Wood_Deadwood_Roof",
      "rotation": 2
    },
    {
      "x": -6,
      "y": 9,
      "z": -2,
      "name": "Wood_Deadwood_Planks_Half",
      "rotation": 8
    },
    {
      "x": -6,
      "y": 10,
      "z": -2,
      "name": "Wood_Deadwood_Planks_Half",
      "rotation": 4
    },
    {
      "x": -6,
      "y": 11,
      "z": -2,
      "name": "Wood_Deadwood_Roof_Steep",
      "rotation": 2
    },
    {
      "x": -6,
      "y": 12,
      "z": -2,
      "name": "Wood_Deadwood_Roof_Steep",
      "filler": 1024,
      "rotation": 2
    },
    {
      "x": -6,
      "y": 9,
      "z": -1,
      "name": "Wood_Deadwood_Planks_Half",
      "rotation": 8
    },
    {
      "x": -6,
      "y": 12,
      "z": -1,
      "name": "Wood_Deadwood_Planks_Half",
      "rotation": 4
    },
    {
      "x": -6,
      "y": 13,
      "z": -1,
      "name": "Wood_Deadwood_Roof_Steep",
      "rotation": 2
    },
    {
      "x": -6,
      "y": 14,
      "z": -1,
      "name": "Wood_Deadwood_Roof_Steep",
      "filler": 1024,
      "rotation": 2
    },
    {
      "x": -6,
      "y": 9,
      "z": 0,
      "name": "Wood_Deadwood_Planks_Half",
      "rotation": 8
    },
    {
      "x": -6,
      "y": 14,
      "z": 0,
      "name": "Wood_Deadwood_Planks"
    },
    {
      "x": -6,
      "y": 15,
      "z": 0,
      "name": "Wood_Deadwood_Roof_Flat"
    },
    {
      "x": -6,
      "y": 9,
      "z": 1,
      "name": "Wood_Deadwood_Planks_Half",
      "rotation": 8
    },
    {
      "x": -6,
      "y": 12,
      "z": 1,
      "name": "Wood_Deadwood_Planks_Half",
      "rotation": 6
    },
    {
      "x": -6,
      "y": 13,
      "z": 1,
      "name": "Wood_Deadwood_Roof_Steep"
    },
    {
      "x": -6,
      "y": 14,
      "z": 1,
      "name": "Wood_Deadwood_Roof_Steep",
      "filler": 1024
    },
    {
      "x": -6,
      "y": 9,
      "z": 2,
      "name": "Wood_Deadwood_Planks_Half",
      "rotation": 8
    },
    {
      "x": -6,
      "y": 10,
      "z": 2,
      "name": "Wood_Deadwood_Planks_Half",
      "rotation": 6
    },
    {
      "x": -6,
      "y": 11,
      "z": 2,
      "name": "Wood_Deadwood_Roof_Steep"
    },
    {
      "x": -6,
      "y": 12,
      "z": 2,
      "name": "Wood_Deadwood_Roof_Steep",
      "filler": 1024
    },
    {
      "x": -6,
      "y": 6,
      "z": 3,
      "name": "Wood_Deadwood_Planks"
    },
    {
      "x": -6,
      "y": 9,
      "z": 3,
      "name": "Wood_Deadwood_Stairs",
      "rotation": 8
    },
    {
      "x": -6,
      "y": 10,
      "z": 3,
      "name": "Wood_Deadwood_Roof"
    },
    {
      "x": -6,
      "y": 6,
      "z": 4,
      "name": "Wood_Deadwood_Planks"
    },
    {
      "x": -6,
      "y": 9,
      "z": 4,
      "name": "Wood_Deadwood_Roof"
    },
    {
      "x": -6,
      "y": 0,
      "z": 5,
      "name": "Wood_Deadwood_Beam"
    },
    {
      "x": -6,
      "y": 1,
      "z": 5,
      "name": "Wood_Deadwood_Beam"
    },
    {
      "x": -6,
      "y": 2,
      "z": 5,
      "name": "Wood_Deadwood_Beam"
    },
    {
      "x": -6,
      "y": 3,
      "z": 5,
      "name": "Wood_Deadwood_Beam"
    },
    {
      "x": -6,
      "y": 4,
      "z": 5,
      "name": "Wood_Deadwood_Beam"
    },
    {
      "x": -6,
      "y": 5,
      "z": 5,
      "name": "Wood_Deadwood_Beam"
    },
    {
      "x": -6,
      "y": 6,
      "z": 5,
      "name": "Wood_Deadwood_Planks"
    },
    {
      "x": -5,
      "y": 9,
      "z": -4,
      "name": "Wood_Deadwood_Roof",
      "rotation": 2
    },
    {
      "x": -5,
      "y": 6,
      "z": -3,
      "name": "Wood_Deadwood_Planks"
    },
    {
      "x": -5,
      "y": 7,
      "z": -3,
      "name": "Wood_Deadwood_Planks"
    },
    {
      "x": -5,
      "y": 8,
      "z": -3,
      "name": "Wood_Deadwood_Planks"
    },
    {
      "x": -5,
      "y": 9,
      "z": -3,
      "name": "Wood_Deadwood_Planks"
    },
    {
      "x": -5,
      "y": 10,
      "z": -3,
      "name": "Wood_Deadwood_Roof",
      "rotation": 2
    },
    {
      "x": -5,
      "y": 6,
      "z": -2,
      "name": "Wood_Deadwood_Planks"
    },
    {
      "x": -5,
      "y": 7,
      "z": -2,
      "name": "Wood_Deadwood_Planks"
    },
    {
      "x": -5,
      "y": 8,
      "z": -2,
      "name": "Wood_Deadwood_Planks"
    },
    {
      "x": -5,
      "y": 9,
      "z": -2,
      "name": "Wood_Deadwood_Planks"
    },
    {
      "x": -5,
      "y": 10,
      "z": -2,
      "name": "Wood_Deadwood_Ornate"
    },
    {
      "x": -5,
      "y": 11,
      "z": -2,
      "name": "Wood_Deadwood_Roof_Steep",
      "rotation": 2
    },
    {
      "x": -5,
      "y": 12,
      "z": -2,
      "name": "Wood_Deadwood_Roof_Steep",
      "filler": 1024,
      "rotation": 2
    },
    {
      "x": -5,
      "y": 6,
      "z": -1,
      "name": "Wood_Deadwood_Planks"
    },
    {
      "x": -5,
      "y": 7,
      "z": -1,
      "name": "Wood_Deadwood_Planks"
    },
    {
      "x": -5,
      "y": 8,
      "z": -1,
      "name": "Wood_Deadwood_Planks"
    },
    {
      "x": -5,
      "y": 9,
      "z": -1,
      "name": "Wood_Deadwood_Planks"
    },
    {
      "x": -5,
      "y": 10,
      "z": -1,
      "name": "Wood_Deadwood_Ornate"
    },
    {
      "x": -5,
      "y": 11,
      "z": -1,
      "name": "Wood_Deadwood_Ornate"
    },
    {
      "x": -5,
      "y": 12,
      "z": -1,
      "name": "Wood_Deadwood_Ornate"
    },
    {
      "x": -5,
      "y": 13,
      "z": -1,
      "name": "Wood_Deadwood_Roof_Steep",
      "rotation": 2
    },
    {
      "x": -5,
      "y": 14,
      "z": -1,
      "name": "Wood_Deadwood_Roof_Steep",
      "filler": 1024,
      "rotation": 2
    },
    {
      "x": -5,
      "y": 6,
      "z": 0,
      "name": "Wood_Deadwood_Planks"
    },
    {
      "x": -5,
      "y": 7,
      "z": 0,
      "name": "Wood_Deadwood_Planks"
    },
    {
      "x": -5,
      "y": 8,
      "z": 0,
      "name": "Furniture_Ancient_Window",
      "rotation": 1
    },
    {
      "x": -5,
      "y": 9,
      "z": 0,
      "name": "Wood_Deadwood_Planks"
    },
    {
      "x": -5,
      "y": 10,
      "z": 0,
      "name": "Wood_Deadwood_Ornate"
    },
    {
      "x": -5,
      "y": 11,
      "z": 0,
      "name": "Furniture_Ancient_Window",
      "rotation": 1
    },
    {
      "x": -5,
      "y": 12,
      "z": 0,
      "name": "Wood_Deadwood_Ornate"
    },
    {
      "x": -5,
      "y": 13,
      "z": 0,
      "name": "Wood_Deadwood_Ornate"
    },
    {
      "x": -5,
      "y": 14,
      "z": 0,
      "name": "Soil_Grass_Burnt"
    },
    {
      "x": -5,
      "y": 6,
      "z": 1,
      "name": "Wood_Deadwood_Planks"
    },
    {
      "x": -5,
      "y": 7,
      "z": 1,
      "name": "Wood_Deadwood_Planks"
    },
    {
      "x": -5,
      "y": 8,
      "z": 1,
      "name": "Wood_Deadwood_Planks"
    },
    {
      "x": -5,
      "y": 9,
      "z": 1,
      "name": "Wood_Deadwood_Planks"
    },
    {
      "x": -5,
      "y": 10,
      "z": 1,
      "name": "Wood_Deadwood_Ornate"
    },
    {
      "x": -5,
      "y": 11,
      "z": 1,
      "name": "Wood_Deadwood_Ornate"
    },
    {
      "x": -5,
      "y": 12,
      "z": 1,
      "name": "Wood_Deadwood_Ornate"
    },
    {
      "x": -5,
      "y": 13,
      "z": 1,
      "name": "Wood_Deadwood_Roof_Steep"
    },
    {
      "x": -5,
      "y": 14,
      "z": 1,
      "name": "Wood_Deadwood_Roof_Steep",
      "filler": 1024
    },
    {
      "x": -5,
      "y": 6,
      "z": 2,
      "name": "Wood_Deadwood_Planks"
    },
    {
      "x": -5,
      "y": 7,
      "z": 2,
      "name": "Wood_Deadwood_Planks"
    },
    {
      "x": -5,
      "y": 8,
      "z": 2,
      "name": "Wood_Deadwood_Planks"
    },
    {
      "x": -5,
      "y": 9,
      "z": 2,
      "name": "Wood_Deadwood_Planks"
    },
    {
      "x": -5,
      "y": 10,
      "z": 2,
      "name": "Wood_Deadwood_Planks"
    },
    {
      "x": -5,
      "y": 11,
      "z": 2,
      "name": "Wood_Deadwood_Roof_Steep"
    },
    {
      "x": -5,
      "y": 12,
      "z": 2,
      "name": "Wood_Deadwood_Roof_Steep",
      "filler": 1024
    },
    {
      "x": -5,
      "y": 6,
      "z": 3,
      "name": "Wood_Deadwood_Planks"
    },
    {
      "x": -5,
      "y": 7,
      "z": 3,
      "name": "Wood_Deadwood_Planks"
    },
    {
      "x": -5,
      "y": 8,
      "z": 3,
      "name": "Wood_Deadwood_Planks"
    },
    {
      "x": -5,
      "y": 9,
      "z": 3,
      "name": "Wood_Deadwood_Planks"
    },
    {
      "x": -5,
      "y": 10,
      "z": 3,
      "name": "Wood_Deadwood_Roof"
    },
    {
      "x": -5,
      "y": 6,
      "z": 4,
      "name": "Wood_Softwood_Planks"
    },
    {
      "x": -5,
      "y": 7,
      "z": 4,
      "name": "Wood_Deadwood_Planks_Half",
      "rotation": 4
    },
    {
      "x": -5,
      "y": 8,
      "z": 4,
      "name": "Wood_Deadwood_Planks_Half",
      "rotation": 4
    },
    {
      "x": -5,
      "y": 9,
      "z": 4,
      "name": "Wood_Deadwood_Roof"
    },
    {
      "x": -5,
      "y": 6,
      "z": 5,
      "name": "Wood_Softwood_Planks"
    },
    {
      "x": -4,
      "y": 9,
      "z": -4,
      "name": "Wood_Deadwood_Roof",
      "rotation": 2
    },
    {
      "x": -4,
      "y": 6,
      "z": -3,
      "name": "Wood_Deadwood_Planks"
    },
    {
      "x": -4,
      "y": 7,
      "z": -3,
      "name": "Wood_Deadwood_Planks"
    },
    {
      "x": -4,
      "y": 8,
      "z": -3,
      "name": "Wood_Deadwood_Planks"
    },
    {
      "x": -4,
      "y": 9,
      "z": -3,
      "name": "Wood_Deadwood_Planks"
    },
    {
      "x": -4,
      "y": 10,
      "z": -3,
      "name": "Wood_Deadwood_Roof",
      "rotation": 2
    },
    {
      "x": -4,
      "y": 6,
      "z": -2,
      "name": "Wood_Deadwood_Planks"
    },
    {
      "x": -4,
      "y": 7,
      "z": -2,
      "name": "Furniture_Ancient_Bed",
      "components": {
        "Components": {
          "RespawnBlock": {}
        }
      }
    },
    {
      "x": -4,
      "y": 8,
      "z": -2,
      "name": "Furniture_Ancient_Bed",
      "components": {
        "Components": {
          "RespawnBlock": {}
        }
      },
      "filler": 1024
    },
    {
      "x": -4,
      "y": 9,
      "z": -2,
      "name": "Empty"
    },
    {
      "x": -4,
      "y": 10,
      "z": -2,
      "name": "Wood_Deadwood_Planks_Half",
      "rotation": 4
    },
    {
      "x": -4,
      "y": 11,
      "z": -2,
      "name": "Wood_Deadwood_Roof",
      "rotation": 2
    },
    {
      "x": -4,
      "y": 12,
      "z": -2,
      "name": "Wood_Deadwood_Planks_Half",
      "rotation": 6
    },
    {
      "x": -4,
      "y": 6,
      "z": -1,
      "name": "Wood_Softwood_Planks"
    },
    {
      "x": -4,
      "y": 7,
      "z": -1,
      "name": "Furniture_Ancient_Bed",
      "components": {
        "Components": {
          "RespawnBlock": {}
        }
      },
      "filler": 32
    },
    {
      "x": -4,
      "y": 8,
      "z": -1,
      "name": "Furniture_Ancient_Bed",
      "components": {
        "Components": {
          "RespawnBlock": {}
        }
      },
      "filler": 1056
    },
    {
      "x": -4,
      "y": 9,
      "z": -1,
      "name": "Empty"
    },
    {
      "x": -4,
      "y": 10,
      "z": -1,
      "name": "Empty"
    },
    {
      "x": -4,
      "y": 11,
      "z": -1,
      "name": "Empty"
    },
    {
      "x": -4,
      "y": 12,
      "z": -1,
      "name": "Wood_Deadwood_Planks_Half",
      "rotation": 4
    },
    {
      "x": -4,
      "y": 13,
      "z": -1,
      "name": "Wood_Deadwood_Ornate"
    },
    {
      "x": -4,
      "y": 14,
      "z": -1,
      "name": "Soil_Grass_Burnt"
    },
    {
      "x": -4,
      "y": 15,
      "z": -1,
      "name": "Plant_Grass_Gnarled_Short"
    },
    {
      "x": -4,
      "y": 6,
      "z": 0,
      "name": "Soil_Dirt_Burnt"
    },
    {
      "x": -4,
      "y": 7,
      "z": 0,
      "name": "Furniture_Ancient_Bed",
      "components": {
        "Components": {
          "RespawnBlock": {}
        }
      },
      "filler": 64
    },
    {
      "x": -4,
      "y": 8,
      "z": 0,
      "name": "Furniture_Ancient_Bed",
      "components": {
        "Components": {
          "RespawnBlock": {}
        }
      },
      "filler": 1088
    },
    {
      "x": -4,
      "y": 9,
      "z": 0,
      "name": "Empty"
    },
    {
      "x": -4,
      "y": 10,
      "z": 0,
      "name": "Empty"
    },
    {
      "x": -4,
      "y": 11,
      "z": 0,
      "name": "Empty"
    },
    {
      "x": -4,
      "y": 12,
      "z": 0,
      "name": "Empty"
    },
    {
      "x": -4,
      "y": 14,
      "z": 0,
      "name": "Soil_Grass_Burnt"
    },
    {
      "x": -4,
      "y": 15,
      "z": 0,
      "name": "Plant_Grass_Gnarled_Tall"
    },
    {
      "x": -4,
      "y": 16,
      "z": 0,
      "name": "Plant_Grass_Gnarled_Tall",
      "filler": 1024
    },
    {
      "x": -4,
      "y": 6,
      "z": 1,
      "name": "Soil_Dirt_Burnt"
    },
    {
      "x": -4,
      "y": 7,
      "z": 1,
      "name": "Furniture_Ancient_Wardrobe",
      "rotation": 1
    },
    {
      "x": -4,
      "y": 8,
      "z": 1,
      "name": "Furniture_Ancient_Wardrobe",
      "filler": 1024,
      "rotation": 1
    },
    {
      "x": -4,
      "y": 9,
      "z": 1,
      "name": "Furniture_Ancient_Platform"
    },
    {
      "x": -4,
      "y": 10,
      "z": 1,
      "name": "Empty"
    },
    {
      "x": -4,
      "y": 11,
      "z": 1,
      "name": "Empty"
    },
    {
      "x": -4,
      "y": 12,
      "z": 1,
      "name": "Wood_Deadwood_Planks_Half",
      "rotation": 6
    },
    {
      "x": -4,
      "y": 13,
      "z": 1,
      "name": "Wood_Deadwood_Roof_Steep"
    },
    {
      "x": -4,
      "y": 14,
      "z": 1,
      "name": "Wood_Deadwood_Roof_Steep",
      "filler": 1024
    },
    {
      "x": -4,
      "y": 6,
      "z": 2,
      "name": "Soil_Dirt_Burnt"
    },
    {
      "x": -4,
      "y": 7,
      "z": 2,
      "name": "Furniture_Ancient_Wardrobe",
      "filler": 32,
      "rotation": 1
    },
    {
      "x": -4,
      "y": 8,
      "z": 2,
      "name": "Furniture_Ancient_Wardrobe",
      "filler": 1056,
      "rotation": 1
    },
    {
      "x": -4,
      "y": 9,
      "z": 2,
      "name": "Furniture_Ancient_Platform"
    },
    {
      "x": -4,
      "y": 10,
      "z": 2,
      "name": "Wood_Deadwood_Planks_Half",
      "rotation": 6
    },
    {
      "x": -4,
      "y": 11,
      "z": 2,
      "name": "Wood_Deadwood_Roof"
    },
    {
      "x": -4,
      "y": 12,
      "z": 2,
      "name": "Wood_Deadwood_Planks_Half",
      "rotation": 4
    },
    {
      "x": -4,
      "y": 6,
      "z": 3,
      "name": "Wood_Deadwood_Planks"
    },
    {
      "x": -4,
      "y": 7,
      "z": 3,
      "name": "Wood_Deadwood_Planks"
    },
    {
      "x": -4,
      "y": 8,
      "z": 3,
      "name": "Wood_Deadwood_Planks"
    },
    {
      "x": -4,
      "y": 9,
      "z": 3,
      "name": "Wood_Deadwood_Planks"
    },
    {
      "x": -4,
      "y": 10,
      "z": 3,
      "name": "Wood_Deadwood_Roof"
    },
    {
      "x": -4,
      "y": 6,
      "z": 4,
      "name": "Wood_Softwood_Planks"
    },
    {
      "x": -4,
      "y": 9,
      "z": 4,
      "name": "Wood_Deadwood_Roof"
    },
    {
      "x": -4,
      "y": 6,
      "z": 5,
      "name": "Wood_Softwood_Planks"
    },
    {
      "x": -3,
      "y": 9,
      "z": -4,
      "name": "Wood_Deadwood_Roof",
      "rotation": 2
    },
    {
      "x": -3,
      "y": 0,
      "z": -3,
      "name": "Wood_Deadwood_Beam"
    },
    {
      "x": -3,
      "y": 1,
      "z": -3,
      "name": "Wood_Deadwood_Beam"
    },
    {
      "x": -3,
      "y": 2,
      "z": -3,
      "name": "Wood_Deadwood_Beam"
    },
    {
      "x": -3,
      "y": 3,
      "z": -3,
      "name": "Wood_Deadwood_Beam"
    },
    {
      "x": -3,
      "y": 4,
      "z": -3,
      "name": "Wood_Deadwood_Beam"
    },
    {
      "x": -3,
      "y": 5,
      "z": -3,
      "name": "Wood_Deadwood_Beam"
    },
    {
      "x": -3,
      "y": 6,
      "z": -3,
      "name": "Wood_Deadwood_Planks"
    },
    {
      "x": -3,
      "y": 7,
      "z": -3,
      "name": "Wood_Deadwood_Planks"
    },
    {
      "x": -3,
      "y": 8,
      "z": -3,
      "name": "Wood_Deadwood_Planks"
    },
    {
      "x": -3,
      "y": 9,
      "z": -3,
      "name": "Wood_Deadwood_Planks"
    },
    {
      "x": -3,
      "y": 10,
      "z": -3,
      "name": "Wood_Deadwood_Roof",
      "rotation": 2
    },
    {
      "x": -3,
      "y": 6,
      "z": -2,
      "name": "Wood_Softwood_Planks"
    },
    {
      "x": -3,
      "y": 7,
      "z": -2,
      "name": "Furniture_Ancient_Bed",
      "components": {
        "Components": {
          "RespawnBlock": {}
        }
      },
      "filler": 1
    },
    {
      "x": -3,
      "y": 8,
      "z": -2,
      "name": "Furniture_Ancient_Bed",
      "components": {
        "Components": {
          "RespawnBlock": {}
        }
      },
      "filler": 1025
    },
    {
      "x": -3,
      "y": 9,
      "z": -2,
      "name": "Empty"
    },
    {
      "x": -3,
      "y": 10,
      "z": -2,
      "name": "Wood_Deadwood_Planks_Half",
      "rotation": 4
    },
    {
      "x": -3,
      "y": 11,
      "z": -2,
      "name": "Wood_Deadwood_Roof",
      "rotation": 2
    },
    {
      "x": -3,
      "y": 12,
      "z": -2,
      "name": "Wood_Deadwood_Planks_Half",
      "rotation": 6
    },
    {
      "x": -3,
      "y": 6,
      "z": -1,
      "name": "Wood_Softwood_Planks"
    },
    {
      "x": -3,
      "y": 7,
      "z": -1,
      "name": "Furniture_Ancient_Bed",
      "components": {
        "Components": {
          "RespawnBlock": {}
        }
      },
      "filler": 33
    },
    {
      "x": -3,
      "y": 8,
      "z": -1,
      "name": "Furniture_Ancient_Bed",
      "components": {
        "Components": {
          "RespawnBlock": {}
        }
      },
      "filler": 1057
    },
    {
      "x": -3,
      "y": 9,
      "z": -1,
      "name": "Empty"
    },
    {
      "x": -3,
      "y": 10,
      "z": -1,
      "name": "Empty"
    },
    {
      "x": -3,
      "y": 11,
      "z": -1,
      "name": "Empty"
    },
    {
      "x": -3,
      "y": 12,
      "z": -1,
      "name": "Wood_Deadwood_Planks_Half",
      "rotation": 4
    },
    {
      "x": -3,
      "y": 13,
      "z": -1,
      "name": "Wood_Deadwood_Ornate"
    },
    {
      "x": -3,
      "y": 6,
      "z": 0,
      "name": "Wood_Softwood_Planks"
    },
    {
      "x": -3,
      "y": 7,
      "z": 0,
      "name": "Furniture_Ancient_Bed",
      "components": {
        "Components": {
          "RespawnBlock": {}
        }
      },
      "filler": 65
    },
    {
      "x": -3,
      "y": 8,
      "z": 0,
      "name": "Furniture_Ancient_Bed",
      "components": {
        "Components": {
          "RespawnBlock": {}
        }
      },
      "filler": 1089
    },
    {
      "x": -3,
      "y": 9,
      "z": 0,
      "name": "Empty"
    },
    {
      "x": -3,
      "y": 10,
      "z": 0,
      "name": "Empty"
    },
    {
      "x": -3,
      "y": 11,
      "z": 0,
      "name": "Empty"
    },
    {
      "x": -3,
      "y": 12,
      "z": 0,
      "name": "Empty"
    },
    {
      "x": -3,
      "y": 14,
      "z": 0,
      "name": "Soil_Grass_Burnt"
    },
    {
      "x": -3,
      "y": 15,
      "z": 0,
      "name": "Plant_Grass_Gnarled_Short"
    },
    {
      "x": -3,
      "y": 6,
      "z": 1,
      "name": "Soil_Dirt_Burnt"
    },
    {
      "x": -3,
      "y": 7,
      "z": 1,
      "name": "Empty"
    },
    {
      "x": -3,
      "y": 8,
      "z": 1,
      "name": "Empty"
    },
    {
      "x": -3,
      "y": 9,
      "z": 1,
      "name": "Furniture_Ancient_Platform"
    },
    {
      "x": -3,
      "y": 10,
      "z": 1,
      "name": "Empty"
    },
    {
      "x": -3,
      "y": 11,
      "z": 1,
      "name": "Empty"
    },
    {
      "x": -3,
      "y": 12,
      "z": 1,
      "name": "Wood_Deadwood_Planks_Half",
      "rotation": 6
    },
    {
      "x": -3,
      "y": 13,
      "z": 1,
      "name": "Wood_Deadwood_Roof_Steep"
    },
    {
      "x": -3,
      "y": 14,
      "z": 1,
      "name": "Wood_Deadwood_Roof_Steep",
      "filler": 1024
    },
    {
      "x": -3,
      "y": 6,
      "z": 2,
      "name": "Soil_Dirt_Burnt"
    },
    {
      "x": -3,
      "y": 7,
      "z": 2,
      "name": "Empty"
    },
    {
      "x": -3,
      "y": 8,
      "z": 2,
      "name": "Empty"
    },
    {
      "x": -3,
      "y": 9,
      "z": 2,
      "name": "Furniture_Ancient_Platform"
    },
    {
      "x": -3,
      "y": 10,
      "z": 2,
      "name": "Wood_Deadwood_Planks_Half",
      "rotation": 6
    },
    {
      "x": -3,
      "y": 11,
      "z": 2,
      "name": "Wood_Deadwood_Roof"
    },
    {
      "x": -3,
      "y": 12,
      "z": 2,
      "name": "Wood_Deadwood_Planks_Half",
      "rotation": 4
    },
    {
      "x": -3,
      "y": 6,
      "z": 3,
      "name": "Wood_Deadwood_Planks"
    },
    {
      "x": -3,
      "y": 7,
      "z": 3,
      "name": "Wood_Deadwood_Planks"
    },
    {
      "x": -3,
      "y": 8,
      "z": 3,
      "name": "Furniture_Ancient_Window"
    },
    {
      "x": -3,
      "y": 9,
      "z": 3,
      "name": "Wood_Deadwood_Planks"
    },
    {
      "x": -3,
      "y": 10,
      "z": 3,
      "name": "Wood_Deadwood_Stairs"
    },
    {
      "x": -3,
      "y": 6,
      "z": 4,
      "name": "Soil_Dirt_Burnt"
    },
    {
      "x": -3,
      "y": 9,
      "z": 4,
      "name": "Wood_Deadwood_Roof"
    },
    {
      "x": -3,
      "y": 6,
      "z": 5,
      "name": "Wood_Softwood_Planks"
    },
    {
      "x": -2,
      "y": 9,
      "z": -4,
      "name": "Wood_Deadwood_Roof",
      "rotation": 2
    },
    {
      "x": -2,
      "y": 6,
      "z": -3,
      "name": "Wood_Deadwood_Planks"
    },
    {
      "x": -2,
      "y": 7,
      "z": -3,
      "name": "Wood_Deadwood_Planks"
    },
    {
      "x": -2,
      "y": 8,
      "z": -3,
      "name": "Furniture_Ancient_Window"
    },
    {
      "x": -2,
      "y": 9,
      "z": -3,
      "name": "Wood_Deadwood_Planks"
    },
    {
      "x": -2,
      "y": 10,
      "z": -3,
      "name": "Wood_Deadwood_Roof",
      "rotation": 2
    },
    {
      "x": -2,
      "y": 6,
      "z": -2,
      "name": "Wood_Softwood_Planks"
    },
    {
      "x": -2,
      "y": 7,
      "z": -2,
      "name": "Empty"
    },
    {
      "x": -2,
      "y": 8,
      "z": -2,
      "name": "Empty"
    },
    {
      "x": -2,
      "y": 9,
      "z": -2,
      "name": "Empty"
    },
    {
      "x": -2,
      "y": 10,
      "z": -2,
      "name": "Wood_Deadwood_Planks_Half",
      "rotation": 4
    },
    {
      "x": -2,
      "y": 11,
      "z": -2,
      "name": "Furniture_Ancient_Window"
    },
    {
      "x": -2,
      "y": 12,
      "z": -2,
      "name": "*Wood_Deadwood_Roof_State_Definitions_Inverted_Corner_Right",
      "rotation": 3
    },
    {
      "x": -2,
      "y": 6,
      "z": -1,
      "name": "Wood_Softwood_Planks"
    },
    {
      "x": -2,
      "y": 7,
      "z": -1,
      "name": "Empty"
    },
    {
      "x": -2,
      "y": 8,
      "z": -1,
      "name": "Empty"
    },
    {
      "x": -2,
      "y": 9,
      "z": -1,
      "name": "Empty"
    },
    {
      "x": -2,
      "y": 10,
      "z": -1,
      "name": "Empty"
    },
    {
      "x": -2,
      "y": 11,
      "z": -1,
      "name": "Empty"
    },
    {
      "x": -2,
      "y": 12,
      "z": -1,
      "name": "Wood_Deadwood_Planks_Half",
      "rotation": 4
    },
    {
      "x": -2,
      "y": 6,
      "z": 0,
      "name": "Wood_Softwood_Planks"
    },
    {
      "x": -2,
      "y": 7,
      "z": 0,
      "name": "Empty"
    },
    {
      "x": -2,
      "y": 8,
      "z": 0,
      "name": "Empty"
    },
    {
      "x": -2,
      "y": 9,
      "z": 0,
      "name": "Empty"
    },
    {
      "x": -2,
      "y": 10,
      "z": 0,
      "name": "Empty"
    },
    {
      "x": -2,
      "y": 11,
      "z": 0,
      "name": "Empty"
    },
    {
      "x": -2,
      "y": 12,
      "z": 0,
      "name": "Empty"
    },
    {
      "x": -2,
      "y": 6,
      "z": 1,
      "name": "Wood_Softwood_Planks"
    },
    {
      "x": -2,
      "y": 7,
      "z": 1,
      "name": "Empty"
    },
    {
      "x": -2,
      "y": 8,
      "z": 1,
      "name": "Empty"
    },
    {
      "x": -2,
      "y": 9,
      "z": 1,
      "name": "Empty"
    },
    {
      "x": -2,
      "y": 10,
      "z": 1,
      "name": "Empty"
    },
    {
      "x": -2,
      "y": 11,
      "z": 1,
      "name": "Empty"
    },
    {
      "x": -2,
      "y": 12,
      "z": 1,
      "name": "Empty"
    },
    {
      "x": -2,
      "y": 14,
      "z": 1,
      "name": "Wood_Deadwood_Beam",
      "rotation": 5
    },
    {
      "x": -2,
      "y": 6,
      "z": 2,
      "name": "Wood_Softwood_Planks"
    },
    {
      "x": -2,
      "y": 7,
      "z": 2,
      "name": "Empty"
    },
    {
      "x": -2,
      "y": 8,
      "z": 2,
      "name": "Empty"
    },
    {
      "x": -2,
      "y": 9,
      "z": 2,
      "name": "Furniture_Ancient_Platform"
    },
    {
      "x": -2,
      "y": 10,
      "z": 2,
      "name": "Empty"
    },
    {
      "x": -2,
      "y": 11,
      "z": 2,
      "name": "Empty"
    },
    {
      "x": -2,
      "y": 6,
      "z": 3,
      "name": "Wood_Deadwood_Planks"
    },
    {
      "x": -2,
      "y": 7,
      "z": 3,
      "name": "Wood_Deadwood_Planks"
    },
    {
      "x": -2,
      "y": 8,
      "z": 3,
      "name": "Wood_Deadwood_Planks"
    },
    {
      "x": -2,
      "y": 9,
      "z": 3,
      "name": "Wood_Deadwood_Planks"
    },
    {
      "x": -2,
      "y": 10,
      "z": 3,
      "name": "Wood_Deadwood_Beam",
      "rotation": 5
    },
    {
      "x": -2,
      "y": 6,
      "z": 4,
      "name": "Soil_Dirt_Burnt"
    },
    {
      "x": -2,
      "y": 9,
      "z": 4,
      "name": "Wood_Deadwood_Stairs"
    },
    {
      "x": -2,
      "y": 6,
      "z": 5,
      "name": "Wood_Softwood_Planks"
    },
    {
      "x": -1,
      "y": 9,
      "z": -4,
      "name": "Wood_Deadwood_Roof",
      "rotation": 2
    },
    {
      "x": -1,
      "y": 6,
      "z": -3,
      "name": "Wood_Deadwood_Planks"
    },
    {
      "x": -1,
      "y": 7,
      "z": -3,
      "name": "Wood_Deadwood_Planks"
    },
    {
      "x": -1,
      "y": 8,
      "z": -3,
      "name": "Wood_Deadwood_Planks"
    },
    {
      "x": -1,
      "y": 9,
      "z": -3,
      "name": "Wood_Deadwood_Planks"
    },
    {
      "x": -1,
      "y": 10,
      "z": -3,
      "name": "Wood_Deadwood_Roof",
      "rotation": 2
    },
    {
      "x": -1,
      "y": 6,
      "z": -2,
      "name": "Wood_Softwood_Planks"
    },
    {
      "x": -1,
      "y": 7,
      "z": -2,
      "name": "Furniture_Ancient_Barrel"
    },
    {
      "x": -1,
      "y": 8,
      "z": -2,
      "name": "Empty"
    },
    {
      "x": -1,
      "y": 9,
      "z": -2,
      "name": "Furniture_Ancient_Platform"
    },
    {
      "x": -1,
      "y": 10,
      "z": -2,
      "name": "Wood_Deadwood_Planks_Half",
      "rotation": 4
    },
    {
      "x": -1,
      "y": 11,
      "z": -2,
      "name": "Furniture_Ancient_Window"
    },
    {
      "x": -1,
      "y": 12,
      "z": -2,
      "name": "*Wood_Deadwood_Roof_State_Definitions_Inverted_Corner_Right",
      "rotation": 2
    },
    {
      "x": -1,
      "y": 6,
      "z": -1,
      "name": "Wood_Softwood_Planks"
    },
    {
      "x": -1,
      "y": 7,
      "z": -1,
      "name": "Empty"
    },
    {
      "x": -1,
      "y": 8,
      "z": -1,
      "name": "Empty"
    },
    {
      "x": -1,
      "y": 9,
      "z": -1,
      "name": "Empty"
    },
    {
      "x": -1,
      "y": 10,
      "z": -1,
      "name": "Empty"
    },
    {
      "x": -1,
      "y": 11,
      "z": -1,
      "name": "Empty"
    },
    {
      "x": -1,
      "y": 12,
      "z": -1,
      "name": "Wood_Deadwood_Planks_Half",
      "rotation": 4
    },
    {
      "x": -1,
      "y": 6,
      "z": 0,
      "name": "Wood_Softwood_Planks"
    },
    {
      "x": -1,
      "y": 7,
      "z": 0,
      "name": "Empty"
    },
    {
      "x": -1,
      "y": 8,
      "z": 0,
      "name": "Empty"
    },
    {
      "x": -1,
      "y": 9,
      "z": 0,
      "name": "Empty"
    },
    {
      "x": -1,
      "y": 10,
      "z": 0,
      "name": "Empty"
    },
    {
      "x": -1,
      "y": 11,
      "z": 0,
      "name": "Empty"
    },
    {
      "x": -1,
      "y": 12,
      "z": 0,
      "name": "Empty"
    },
    {
      "x": -1,
      "y": 6,
      "z": 1,
      "name": "Wood_Softwood_Planks"
    },
    {
      "x": -1,
      "y": 7,
      "z": 1,
      "name": "Empty"
    },
    {
      "x": -1,
      "y": 8,
      "z": 1,
      "name": "Empty"
    },
    {
      "x": -1,
      "y": 9,
      "z": 1,
      "name": "Empty"
    },
    {
      "x": -1,
      "y": 10,
      "z": 1,
      "name": "Empty"
    },
    {
      "x": -1,
      "y": 11,
      "z": 1,
      "name": "Empty"
    },
    {
      "x": -1,
      "y": 12,
      "z": 1,
      "name": "Empty"
    },
    {
      "x": -1,
      "y": 6,
      "z": 2,
      "name": "Wood_Softwood_Planks"
    },
    {
      "x": -1,
      "y": 7,
      "z": 2,
      "name": "Furniture_Ancient_Chair",
      "rotation": 1
    },
    {
      "x": -1,
      "y": 8,
      "z": 2,
      "name": "Empty"
    },
    {
      "x": -1,
      "y": 9,
      "z": 2,
      "name": "Empty"
    },
    {
      "x": -1,
      "y": 10,
      "z": 2,
      "name": "Empty"
    },
    {
      "x": -1,
      "y": 11,
      "z": 2,
      "name": "Empty"
    },
    {
      "x": -1,
      "y": 6,
      "z": 3,
      "name": "Wood_Deadwood_Planks"
    },
    {
      "x": -1,
      "y": 7,
      "z": 3,
      "name": "Rubble_Stone_Medium"
    },
    {
      "x": -1,
      "y": 8,
      "z": 3,
      "name": "Empty"
    },
    {
      "x": -1,
      "y": 9,
      "z": 3,
      "name": "Empty"
    },
    {
      "x": -1,
      "y": 10,
      "z": 3,
      "name": "Wood_Deadwood_Beam",
      "rotation": 5
    },
    {
      "x": -1,
      "y": 6,
      "z": 4,
      "name": "Soil_Dirt_Burnt"
    },
    {
      "x": -1,
      "y": 6,
      "z": 5,
      "name": "Soil_Dirt_Burnt"
    },
    {
      "x": 0,
      "y": 9,
      "z": -4,
      "name": "Wood_Deadwood_Roof",
      "rotation": 2
    },
    {
      "x": 0,
      "y": 6,
      "z": -3,
      "name": "Wood_Deadwood_Planks"
    },
    {
      "x": 0,
      "y": 7,
      "z": -3,
      "name": "Wood_Deadwood_Planks"
    },
    {
      "x": 0,
      "y": 8,
      "z": -3,
      "name": "Wood_Deadwood_Planks"
    },
    {
      "x": 0,
      "y": 9,
      "z": -3,
      "name": "Wood_Deadwood_Planks"
    },
    {
      "x": 0,
      "y": 10,
      "z": -3,
      "name": "Wood_Deadwood_Stairs",
      "rotation": 2
    },
    {
      "x": 0,
      "y": 6,
      "z": -2,
      "name": "Wood_Softwood_Planks"
    },
    {
      "x": 0,
      "y": 7,
      "z": -2,
      "name": "Furniture_Ancient_Crate"
    },
    {
      "x": 0,
      "y": 8,
      "z": -2,
      "name": "Empty"
    },
    {
      "x": 0,
      "y": 9,
      "z": -2,
      "name": "Furniture_Ancient_Platform"
    },
    {
      "x": 0,
      "y": 10,
      "z": -2,
      "name": "Wood_Deadwood_Planks_Half",
      "rotation": 4
    },
    {
      "x": 0,
      "y": 11,
      "z": -2,
      "name": "Wood_Deadwood_Planks"
    },
    {
      "x": 0,
      "y": 6,
      "z": -1,
      "name": "Wood_Softwood_Planks"
    },
    {
      "x": 0,
      "y": 7,
      "z": -1,
      "name": "Empty"
    },
    {
      "x": 0,
      "y": 8,
      "z": -1,
      "name": "Empty"
    },
    {
      "x": 0,
      "y": 9,
      "z": -1,
      "name": "Empty"
    },
    {
      "x": 0,
      "y": 10,
      "z": -1,
      "name": "Empty"
    },
    {
      "x": 0,
      "y": 11,
      "z": -1,
      "name": "Empty"
    },
    {
      "x": 0,
      "y": 12,
      "z": -1,
      "name": "Empty"
    },
    {
      "x": 0,
      "y": 6,
      "z": 0,
      "name": "Wood_Softwood_Planks"
    },
    {
      "x": 0,
      "y": 7,
      "z": 0,
      "name": "Empty"
    },
    {
      "x": 0,
      "y": 8,
      "z": 0,
      "name": "Empty"
    },
    {
      "x": 0,
      "y": 9,
      "z": 0,
      "name": "Empty"
    },
    {
      "x": 0,
      "y": 10,
      "z": 0,
      "name": "Empty"
    },
    {
      "x": 0,
      "y": 11,
      "z": 0,
      "name": "Empty"
    },
    {
      "x": 0,
      "y": 12,
      "z": 0,
      "name": "Empty"
    },
    {
      "x": 0,
      "y": 6,
      "z": 1,
      "name": "Wood_Softwood_Planks"
    },
    {
      "x": 0,
      "y": 7,
      "z": 1,
      "name": "Furniture_Ancient_Table"
    },
    {
      "x": 0,
      "y": 8,
      "z": 1,
      "name": "Empty"
    },
    {
      "x": 0,
      "y": 9,
      "z": 1,
      "name": "Empty"
    },
    {
      "x": 0,
      "y": 10,
      "z": 1,
      "name": "Empty"
    },
    {
      "x": 0,
      "y": 11,
      "z": 1,
      "name": "Empty"
    },
    {
      "x": 0,
      "y": 12,
      "z": 1,
      "name": "Empty"
    },
    {
      "x": 0,
      "y": 6,
      "z": 2,
      "name": "Wood_Softwood_Planks"
    },
    {
      "x": 0,
      "y": 7,
      "z": 2,
      "name": "Furniture_Ancient_Table",
      "filler": 32
    },
    {
      "x": 0,
      "y": 8,
      "z": 2,
      "name": "Empty"
    },
    {
      "x": 0,
      "y": 9,
      "z": 2,
      "name": "Empty"
    },
    {
      "x": 0,
      "y": 10,
      "z": 2,
      "name": "Empty"
    },
    {
      "x": 0,
      "y": 11,
      "z": 2,
      "name": "Empty"
    },
    {
      "x": 0,
      "y": 6,
      "z": 3,
      "name": "Wood_Deadwood_Planks"
    },
    {
      "x": 0,
      "y": 7,
      "z": 3,
      "name": "Empty"
    },
    {
      "x": 0,
      "y": 8,
      "z": 3,
      "name": "Empty"
    },
    {
      "x": 0,
      "y": 9,
      "z": 3,
      "name": "Empty"
    },
    {
      "x": 0,
      "y": 6,
      "z": 4,
      "name": "Soil_Dirt_Burnt"
    },
    {
      "x": 0,
      "y": 6,
      "z": 5,
      "name": "Soil_Dirt_Burnt"
    },
    {
      "x": 1,
      "y": 9,
      "z": -4,
      "name": "Wood_Deadwood_Stairs",
      "rotation": 2
    },
    {
      "x": 1,
      "y": 6,
      "z": -3,
      "name": "Wood_Deadwood_Planks"
    },
    {
      "x": 1,
      "y": 7,
      "z": -3,
      "name": "Wood_Deadwood_Planks"
    },
    {
      "x": 1,
      "y": 8,
      "z": -3,
      "name": "Furniture_Ancient_Window"
    },
    {
      "x": 1,
      "y": 9,
      "z": -3,
      "name": "Wood_Deadwood_Planks"
    },
    {
      "x": 1,
      "y": 10,
      "z": -3,
      "name": "Wood_Deadwood_Stairs",
      "rotation": 2
    },
    {
      "x": 1,
      "y": 6,
      "z": -2,
      "name": "Soil_Grass_Burnt"
    },
    {
      "x": 1,
      "y": 7,
      "z": -2,
      "name": "Empty"
    },
    {
      "x": 1,
      "y": 8,
      "z": -2,
      "name": "Empty"
    },
    {
      "x": 1,
      "y": 9,
      "z": -2,
      "name": "Furniture_Ancient_Platform"
    },
    {
      "x": 1,
      "y": 10,
      "z": -2,
      "name": "Wood_Deadwood_Planks_Half",
      "rotation": 4
    },
    {
      "x": 1,
      "y": 11,
      "z": -2,
      "name": "Wood_Deadwood_Planks"
    },
    {
      "x": 1,
      "y": 6,
      "z": -1,
      "name": "Soil_Grass_Burnt"
    },
    {
      "x": 1,
      "y": 7,
      "z": -1,
      "name": "Plant_Grass_Gnarled_Short"
    },
    {
      "x": 1,
      "y": 8,
      "z": -1,
      "name": "Empty"
    },
    {
      "x": 1,
      "y": 9,
      "z": -1,
      "name": "Empty"
    },
    {
      "x": 1,
      "y": 10,
      "z": -1,
      "name": "Empty"
    },
    {
      "x": 1,
      "y": 11,
      "z": -1,
      "name": "Empty"
    },
    {
      "x": 1,
      "y": 12,
      "z": -1,
      "name": "Empty"
    },
    {
      "x": 1,
      "y": 6,
      "z": 0,
      "name": "Wood_Softwood_Planks"
    },
    {
      "x": 1,
      "y": 7,
      "z": 0,
      "name": "Empty"
    },
    {
      "x": 1,
      "y": 8,
      "z": 0,
      "name": "Empty"
    },
    {
      "x": 1,
      "y": 9,
      "z": 0,
      "name": "Empty"
    },
    {
      "x": 1,
      "y": 10,
      "z": 0,
      "name": "Empty"
    },
    {
      "x": 1,
      "y": 11,
      "z": 0,
      "name": "Empty"
    },
    {
      "x": 1,
      "y": 12,
      "z": 0,
      "name": "Empty"
    },
    {
      "x": 1,
      "y": 6,
      "z": 1,
      "name": "Wood_Softwood_Planks"
    },
    {
      "x": 1,
      "y": 7,
      "z": 1,
      "name": "Furniture_Ancient_Table",
      "filler": 1
    },
    {
      "x": 1,
      "y": 8,
      "z": 1,
      "name": "Empty"
    },
    {
      "x": 1,
      "y": 9,
      "z": 1,
      "name": "Empty"
    },
    {
      "x": 1,
      "y": 10,
      "z": 1,
      "name": "Empty"
    },
    {
      "x": 1,
      "y": 11,
      "z": 1,
      "name": "Empty"
    },
    {
      "x": 1,
      "y": 12,
      "z": 1,
      "name": "Wood_Deadwood_Planks_Half",
      "rotation": 6
    },
    {
      "x": 1,
      "y": 6,
      "z": 2,
      "name": "Wood_Softwood_Planks"
    },
    {
      "x": 1,
      "y": 7,
      "z": 2,
      "name": "Furniture_Ancient_Table",
      "filler": 33
    },
    {
      "x": 1,
      "y": 8,
      "z": 2,
      "name": "Furniture_Ancient_Candle"
    },
    {
      "x": 1,
      "y": 9,
      "z": 2,
      "name": "Furniture_Ancient_Platform"
    },
    {
      "x": 1,
      "y": 10,
      "z": 2,
      "name": "Wood_Deadwood_Planks_Half",
      "rotation": 6
    },
    {
      "x": 1,
      "y": 11,
      "z": 2,
      "name": "Wood_Deadwood_Planks"
    },
    {
      "x": 1,
      "y": 12,
      "z": 2,
      "name": "Wood_Deadwood_Planks_Half",
      "rotation": 4
    },
    {
      "x": 1,
      "y": 0,
      "z": 3,
      "name": "Wood_Deadwood_Beam"
    },
    {
      "x": 1,
      "y": 1,
      "z": 3,
      "name": "Wood_Deadwood_Beam"
    },
    {
      "x": 1,
      "y": 2,
      "z": 3,
      "name": "Wood_Deadwood_Beam"
    },
    {
      "x": 1,
      "y": 3,
      "z": 3,
      "name": "Wood_Deadwood_Beam"
    },
    {
      "x": 1,
      "y": 4,
      "z": 3,
      "name": "Wood_Deadwood_Beam"
    },
    {
      "x": 1,
      "y": 5,
      "z": 3,
      "name": "Wood_Deadwood_Beam"
    },
    {
      "x": 1,
      "y": 6,
      "z": 3,
      "name": "Wood_Deadwood_Planks"
    },
    {
      "x": 1,
      "y": 7,
      "z": 3,
      "name": "Wood_Deadwood_Planks"
    },
    {
      "x": 1,
      "y": 8,
      "z": 3,
      "name": "Wood_Deadwood_Planks"
    },
    {
      "x": 1,
      "y": 9,
      "z": 3,
      "name": "Wood_Deadwood_Planks"
    },
    {
      "x": 1,
      "y": 10,
      "z": 3,
      "name": "Wood_Deadwood_Stairs"
    },
    {
      "x": 1,
      "y": 6,
      "z": 4,
      "name": "Wood_Softwood_Planks"
    },
    {
      "x": 1,
      "y": 7,
      "z": 4,
      "name": "Furniture_Ancient_Bench",
      "filler": 31
    },
    {
      "x": 1,
      "y": 9,
      "z": 4,
      "name": "Wood_Deadwood_Stairs"
    },
    {
      "x": 1,
      "y": 6,
      "z": 5,
      "name": "Wood_Softwood_Planks"
    },
    {
      "x": 2,
      "y": 6,
      "z": -3,
      "name": "Wood_Deadwood_Planks"
    },
    {
      "x": 2,
      "y": 7,
      "z": -3,
      "name": "Soil_Grass_Burnt"
    },
    {
      "x": 2,
      "y": 8,
      "z": -3,
      "name": "Plant_Grass_Gnarled_Tall"
    },
    {
      "x": 2,
      "y": 9,
      "z": -3,
      "name": "Plant_Grass_Gnarled_Tall",
      "filler": 1024
    },
    {
      "x": 2,
      "y": 6,
      "z": -2,
      "name": "Soil_Grass_Burnt"
    },
    {
      "x": 2,
      "y": 7,
      "z": -2,
      "name": "Soil_Grass_Burnt"
    },
    {
      "x": 2,
      "y": 8,
      "z": -2,
      "name": "Plant_Grass_Gnarled"
    },
    {
      "x": 2,
      "y": 9,
      "z": -2,
      "name": "Empty"
    },
    {
      "x": 2,
      "y": 10,
      "z": -2,
      "name": "Empty"
    },
    {
      "x": 2,
      "y": 11,
      "z": -2,
      "name": "Wood_Deadwood_Beam",
      "rotation": 5
    },
    {
      "x": 2,
      "y": 6,
      "z": -1,
      "name": "Soil_Dirt_Burnt"
    },
    {
      "x": 2,
      "y": 7,
      "z": -1,
      "name": "Empty"
    },
    {
      "x": 2,
      "y": 8,
      "z": -1,
      "name": "Empty"
    },
    {
      "x": 2,
      "y": 9,
      "z": -1,
      "name": "Empty"
    },
    {
      "x": 2,
      "y": 10,
      "z": -1,
      "name": "Empty"
    },
    {
      "x": 2,
      "y": 11,
      "z": -1,
      "name": "Empty"
    },
    {
      "x": 2,
      "y": 12,
      "z": -1,
      "name": "Empty"
    },
    {
      "x": 2,
      "y": 14,
      "z": -1,
      "name": "Wood_Deadwood_Beam",
      "rotation": 5
    },
    {
      "x": 2,
      "y": 6,
      "z": 0,
      "name": "Wood_Softwood_Planks"
    },
    {
      "x": 2,
      "y": 7,
      "z": 0,
      "name": "Empty"
    },
    {
      "x": 2,
      "y": 8,
      "z": 0,
      "name": "Empty"
    },
    {
      "x": 2,
      "y": 9,
      "z": 0,
      "name": "Empty"
    },
    {
      "x": 2,
      "y": 10,
      "z": 0,
      "name": "Empty"
    },
    {
      "x": 2,
      "y": 11,
      "z": 0,
      "name": "Empty"
    },
    {
      "x": 2,
      "y": 12,
      "z": 0,
      "name": "Empty"
    },
    {
      "x": 2,
      "y": 6,
      "z": 1,
      "name": "Wood_Softwood_Planks"
    },
    {
      "x": 2,
      "y": 7,
      "z": 1,
      "name": "Empty"
    },
    {
      "x": 2,
      "y": 8,
      "z": 1,
      "name": "Empty"
    },
    {
      "x": 2,
      "y": 9,
      "z": 1,
      "name": "Empty"
    },
    {
      "x": 2,
      "y": 10,
      "z": 1,
      "name": "Empty"
    },
    {
      "x": 2,
      "y": 11,
      "z": 1,
      "name": "Empty"
    },
    {
      "x": 2,
      "y": 12,
      "z": 1,
      "name": "Wood_Deadwood_Planks_Half",
      "rotation": 6
    },
    {
      "x": 2,
      "y": 6,
      "z": 2,
      "name": "Wood_Softwood_Planks"
    },
    {
      "x": 2,
      "y": 7,
      "z": 2,
      "name": "Empty"
    },
    {
      "x": 2,
      "y": 8,
      "z": 2,
      "name": "Empty"
    },
    {
      "x": 2,
      "y": 9,
      "z": 2,
      "name": "Furniture_Ancient_Platform"
    },
    {
      "x": 2,
      "y": 10,
      "z": 2,
      "name": "Wood_Deadwood_Planks_Half",
      "rotation": 6
    },
    {
      "x": 2,
      "y": 11,
      "z": 2,
      "name": "Furniture_Ancient_Window"
    },
    {
      "x": 2,
      "y": 12,
      "z": 2,
      "name": "*Wood_Deadwood_Roof_State_Definitions_Inverted_Corner_Right"
    },
    {
      "x": 2,
      "y": 6,
      "z": 3,
      "name": "Wood_Deadwood_Planks"
    },
    {
      "x": 2,
      "y": 7,
      "z": 3,
      "name": "Wood_Deadwood_Planks"
    },
    {
      "x": 2,
      "y": 8,
      "z": 3,
      "name": "Wood_Deadwood_Planks"
    },
    {
      "x": 2,
      "y": 9,
      "z": 3,
      "name": "Wood_Deadwood_Planks"
    },
    {
      "x": 2,
      "y": 10,
      "z": 3,
      "name": "Wood_Deadwood_Stairs"
    },
    {
      "x": 2,
      "y": 6,
      "z": 4,
      "name": "Wood_Softwood_Planks"
    },
    {
      "x": 2,
      "y": 7,
      "z": 4,
      "name": "Furniture_Ancient_Bench"
    },
    {
      "x": 2,
      "y": 9,
      "z": 4,
      "name": "Wood_Deadwood_Roof"
    },
    {
      "x": 2,
      "y": 6,
      "z": 5,
      "name": "Wood_Softwood_Planks"
    },
    {
      "x": 3,
      "y": 0,
      "z": -3,
      "name": "Wood_Deadwood_Beam"
    },
    {
      "x": 3,
      "y": 1,
      "z": -3,
      "name": "Wood_Deadwood_Beam"
    },
    {
      "x": 3,
      "y": 2,
      "z": -3,
      "name": "Wood_Deadwood_Beam"
    },
    {
      "x": 3,
      "y": 3,
      "z": -3,
      "name": "Wood_Deadwood_Beam"
    },
    {
      "x": 3,
      "y": 4,
      "z": -3,
      "name": "Wood_Deadwood_Beam"
    },
    {
      "x": 3,
      "y": 5,
      "z": -3,
      "name": "Wood_Deadwood_Beam"
    },
    {
      "x": 3,
      "y": 6,
      "z": -3,
      "name": "Wood_Deadwood_Planks"
    },
    {
      "x": 3,
      "y": 7,
      "z": -3,
      "name": "Soil_Dirt_Burnt"
    },
    {
      "x": 3,
      "y": 8,
      "z": -3,
      "name": "Soil_Grass_Burnt"
    },
    {
      "x": 3,
      "y": 9,
      "z": -3,
      "name": "Plant_Grass_Gnarled"
    },
    {
      "x": 3,
      "y": 6,
      "z": -2,
      "name": "Soil_Dirt_Burnt"
    },
    {
      "x": 3,
      "y": 7,
      "z": -2,
      "name": "Soil_Grass_Burnt"
    },
    {
      "x": 3,
      "y": 8,
      "z": -2,
      "name": "Empty"
    },
    {
      "x": 3,
      "y": 9,
      "z": -2,
      "name": "Empty"
    },
    {
      "x": 3,
      "y": 10,
      "z": -2,
      "name": "Empty"
    },
    {
      "x": 3,
      "y": 11,
      "z": -2,
      "name": "Wood_Deadwood_Beam",
      "rotation": 5
    },
    {
      "x": 3,
      "y": 6,
      "z": -1,
      "name": "Soil_Dirt_Burnt"
    },
    {
      "x": 3,
      "y": 7,
      "z": -1,
      "name": "Empty"
    },
    {
      "x": 3,
      "y": 8,
      "z": -1,
      "name": "Empty"
    },
    {
      "x": 3,
      "y": 9,
      "z": -1,
      "name": "Empty"
    },
    {
      "x": 3,
      "y": 10,
      "z": -1,
      "name": "Empty"
    },
    {
      "x": 3,
      "y": 11,
      "z": -1,
      "name": "Empty"
    },
    {
      "x": 3,
      "y": 12,
      "z": -1,
      "name": "Wood_Deadwood_Planks_Half",
      "rotation": 4
    },
    {
      "x": 3,
      "y": 14,
      "z": -1,
      "name": "Wood_Deadwood_Beam",
      "rotation": 5
    },
    {
      "x": 3,
      "y": 6,
      "z": 0,
      "name": "Wood_Softwood_Planks"
    },
    {
      "x": 3,
      "y": 7,
      "z": 0,
      "name": "Empty"
    },
    {
      "x": 3,
      "y": 8,
      "z": 0,
      "name": "Empty"
    },
    {
      "x": 3,
      "y": 9,
      "z": 0,
      "name": "Empty"
    },
    {
      "x": 3,
      "y": 10,
      "z": 0,
      "name": "Empty"
    },
    {
      "x": 3,
      "y": 11,
      "z": 0,
      "name": "Empty"
    },
    {
      "x": 3,
      "y": 12,
      "z": 0,
      "name": "Empty"
    },
    {
      "x": 3,
      "y": 14,
      "z": 0,
      "name": "Wood_Deadwood_Beam",
      "rotation": 5
    },
    {
      "x": 3,
      "y": 6,
      "z": 1,
      "name": "Wood_Softwood_Planks"
    },
    {
      "x": 3,
      "y": 7,
      "z": 1,
      "name": "Empty"
    },
    {
      "x": 3,
      "y": 8,
      "z": 1,
      "name": "Empty"
    },
    {
      "x": 3,
      "y": 9,
      "z": 1,
      "name": "Empty"
    },
    {
      "x": 3,
      "y": 10,
      "z": 1,
      "name": "Empty"
    },
    {
      "x": 3,
      "y": 11,
      "z": 1,
      "name": "Empty"
    },
    {
      "x": 3,
      "y": 12,
      "z": 1,
      "name": "Wood_Deadwood_Planks_Half",
      "rotation": 6
    },
    {
      "x": 3,
      "y": 6,
      "z": 2,
      "name": "Wood_Softwood_Planks"
    },
    {
      "x": 3,
      "y": 7,
      "z": 2,
      "name": "Empty"
    },
    {
      "x": 3,
      "y": 8,
      "z": 2,
      "name": "Empty"
    },
    {
      "x": 3,
      "y": 9,
      "z": 2,
      "name": "Furniture_Ancient_Platform"
    },
    {
      "x": 3,
      "y": 10,
      "z": 2,
      "name": "Wood_Deadwood_Planks_Half",
      "rotation": 6
    },
    {
      "x": 3,
      "y": 11,
      "z": 2,
      "name": "Furniture_Ancient_Window"
    },
    {
      "x": 3,
      "y": 12,
      "z": 2,
      "name": "*Wood_Deadwood_Roof_State_Definitions_Inverted_Corner_Right",
      "rotation": 1
    },
    {
      "x": 3,
      "y": 6,
      "z": 3,
      "name": "Wood_Deadwood_Planks"
    },
    {
      "x": 3,
      "y": 7,
      "z": 3,
      "name": "Furniture_Ancient_Door"
    },
    {
      "x": 3,
      "y": 8,
      "z": 3,
      "name": "Furniture_Ancient_Door",
      "filler": 1024
    },
    {
      "x": 3,
      "y": 9,
      "z": 3,
      "name": "Wood_Deadwood_Planks"
    },
    {
      "x": 3,
      "y": 10,
      "z": 3,
      "name": "Wood_Deadwood_Roof"
    },
    {
      "x": 3,
      "y": 6,
      "z": 4,
      "name": "Wood_Softwood_Planks"
    },
    {
      "x": 3,
      "y": 9,
      "z": 4,
      "name": "Wood_Deadwood_Roof"
    },
    {
      "x": 3,
      "y": 6,
      "z": 5,
      "name": "Wood_Softwood_Planks"
    },
    {
      "x": 4,
      "y": 9,
      "z": -4,
      "name": "Wood_Deadwood_Stairs",
      "rotation": 2
    },
    {
      "x": 4,
      "y": 6,
      "z": -3,
      "name": "Wood_Deadwood_Planks"
    },
    {
      "x": 4,
      "y": 7,
      "z": -3,
      "name": "Wood_Deadwood_Planks"
    },
    {
      "x": 4,
      "y": 8,
      "z": -3,
      "name": "Wood_Deadwood_Planks"
    },
    {
      "x": 4,
      "y": 9,
      "z": -3,
      "name": "Wood_Deadwood_Planks"
    },
    {
      "x": 4,
      "y": 10,
      "z": -3,
      "name": "Wood_Deadwood_Planks"
    },
    {
      "x": 4,
      "y": 11,
      "z": -3,
      "name": "Wood_Deadwood_Planks"
    },
    {
      "x": 4,
      "y": 12,
      "z": -3,
      "name": "Wood_Deadwood_Planks"
    },
    {
      "x": 4,
      "y": 13,
      "z": -3,
      "name": "Wood_Deadwood_Planks"
    },
    {
      "x": 4,
      "y": 14,
      "z": -3,
      "name": "Wood_Deadwood_Planks"
    },
    {
      "x": 4,
      "y": 15,
      "z": -3,
      "name": "Wood_Deadwood_Planks"
    },
    {
      "x": 4,
      "y": 16,
      "z": -3,
      "name": "Rock_Stone_Cobble_Wall"
    },
    {
      "x": 4,
      "y": 6,
      "z": -2,
      "name": "Soil_Dirt_Burnt"
    },
    {
      "x": 4,
      "y": 7,
      "z": -2,
      "name": "Bench_Furnace",
      "components": {
        "Components": {
          "processingBench": {
            "Position": {
              "X": 4,
              "Y": 7,
              "Z": 30
            },
            "TierLevel": 1,
            "UpgradeItems": [],
            "Progress": 0.0,
            "FuelTime": 0.0,
            "Active": false,
            "NextExtra": -1
          }
        }
      },
      "filler": 31
    },
    {
      "x": 4,
      "y": 8,
      "z": -2,
      "name": "Bench_Furnace",
      "components": {
        "Components": {
          "processingBench": {
            "Position": {
              "X": 4,
              "Y": 8,
              "Z": 30
            },
            "TierLevel": 1,
            "UpgradeItems": [],
            "Progress": 0.0,
            "FuelTime": 0.0,
            "Active": false,
            "NextExtra": -1
          }
        }
      },
      "filler": 1055
    },
    {
      "x": 4,
      "y": 9,
      "z": -2,
      "name": "Furniture_Ancient_Platform"
    },
    {
      "x": 4,
      "y": 10,
      "z": -2,
      "name": "Wood_Deadwood_Planks_Half",
      "rotation": 4
    },
    {
      "x": 4,
      "y": 11,
      "z": -2,
      "name": "Wood_Deadwood_Roof_Steep",
      "rotation": 2
    },
    {
      "x": 4,
      "y": 12,
      "z": -2,
      "name": "Wood_Deadwood_Roof_Steep",
      "filler": 1024,
      "rotation": 2
    },
    {
      "x": 4,
      "y": 6,
      "z": -1,
      "name": "Soil_Grass_Burnt"
    },
    {
      "x": 4,
      "y": 7,
      "z": -1,
      "name": "Empty"
    },
    {
      "x": 4,
      "y": 8,
      "z": -1,
      "name": "Empty"
    },
    {
      "x": 4,
      "y": 9,
      "z": -1,
      "name": "Empty"
    },
    {
      "x": 4,
      "y": 10,
      "z": -1,
      "name": "Empty"
    },
    {
      "x": 4,
      "y": 11,
      "z": -1,
      "name": "Empty"
    },
    {
      "x": 4,
      "y": 12,
      "z": -1,
      "name": "Wood_Deadwood_Planks_Half",
      "rotation": 4
    },
    {
      "x": 4,
      "y": 13,
      "z": -1,
      "name": "Wood_Deadwood_Roof_Steep",
      "rotation": 2
    },
    {
      "x": 4,
      "y": 14,
      "z": -1,
      "name": "Wood_Deadwood_Roof_Steep",
      "filler": 1024,
      "rotation": 2
    },
    {
      "x": 4,
      "y": 6,
      "z": 0,
      "name": "Soil_Dirt_Burnt"
    },
    {
      "x": 4,
      "y": 7,
      "z": 0,
      "name": "Empty"
    },
    {
      "x": 4,
      "y": 8,
      "z": 0,
      "name": "Empty"
    },
    {
      "x": 4,
      "y": 9,
      "z": 0,
      "name": "Empty"
    },
    {
      "x": 4,
      "y": 10,
      "z": 0,
      "name": "Empty"
    },
    {
      "x": 4,
      "y": 11,
      "z": 0,
      "name": "Empty"
    },
    {
      "x": 4,
      "y": 12,
      "z": 0,
      "name": "Empty"
    },
    {
      "x": 4,
      "y": 14,
      "z": 0,
      "name": "Wood_Deadwood_Planks"
    },
    {
      "x": 4,
      "y": 15,
      "z": 0,
      "name": "Wood_Deadwood_Roof_Flat"
    },
    {
      "x": 4,
      "y": 6,
      "z": 1,
      "name": "Wood_Softwood_Planks"
    },
    {
      "x": 4,
      "y": 7,
      "z": 1,
      "name": "Empty"
    },
    {
      "x": 4,
      "y": 8,
      "z": 1,
      "name": "Empty"
    },
    {
      "x": 4,
      "y": 9,
      "z": 1,
      "name": "Furniture_Ancient_Platform"
    },
    {
      "x": 4,
      "y": 10,
      "z": 1,
      "name": "Empty"
    },
    {
      "x": 4,
      "y": 11,
      "z": 1,
      "name": "Empty"
    },
    {
      "x": 4,
      "y": 12,
      "z": 1,
      "name": "Wood_Deadwood_Planks_Half",
      "rotation": 6
    },
    {
      "x": 4,
      "y": 13,
      "z": 1,
      "name": "Wood_Deadwood_Roof_Steep"
    },
    {
      "x": 4,
      "y": 14,
      "z": 1,
      "name": "Wood_Deadwood_Roof_Steep",
      "filler": 1024
    },
    {
      "x": 4,
      "y": 6,
      "z": 2,
      "name": "Wood_Softwood_Planks"
    },
    {
      "x": 4,
      "y": 7,
      "z": 2,
      "name": "Empty"
    },
    {
      "x": 4,
      "y": 8,
      "z": 2,
      "name": "Empty"
    },
    {
      "x": 4,
      "y": 9,
      "z": 2,
      "name": "Furniture_Ancient_Platform"
    },
    {
      "x": 4,
      "y": 10,
      "z": 2,
      "name": "Wood_Deadwood_Planks_Half",
      "rotation": 6
    },
    {
      "x": 4,
      "y": 11,
      "z": 2,
      "name": "Wood_Deadwood_Roof_Steep"
    },
    {
      "x": 4,
      "y": 12,
      "z": 2,
      "name": "Wood_Deadwood_Roof_Steep",
      "filler": 1024
    },
    {
      "x": 4,
      "y": 6,
      "z": 3,
      "name": "Wood_Deadwood_Planks"
    },
    {
      "x": 4,
      "y": 7,
      "z": 3,
      "name": "Furniture_Ancient_Door",
      "rotation": 2
    },
    {
      "x": 4,
      "y": 8,
      "z": 3,
      "name": "Furniture_Ancient_Door",
      "filler": 1024,
      "rotation": 2
    },
    {
      "x": 4,
      "y": 9,
      "z": 3,
      "name": "Wood_Deadwood_Planks"
    },
    {
      "x": 4,
      "y": 10,
      "z": 3,
      "name": "Wood_Deadwood_Roof"
    },
    {
      "x": 4,
      "y": 6,
      "z": 4,
      "name": "Soil_Dirt_Burnt"
    },
    {
      "x": 4,
      "y": 9,
      "z": 4,
      "name": "Wood_Deadwood_Roof"
    },
    {
      "x": 4,
      "y": 6,
      "z": 5,
      "name": "Wood_Softwood_Planks"
    },
    {
      "x": 5,
      "y": 9,
      "z": -4,
      "name": "Wood_Deadwood_Roof",
      "rotation": 2
    },
    {
      "x": 5,
      "y": 6,
      "z": -3,
      "name": "Wood_Deadwood_Planks"
    },
    {
      "x": 5,
      "y": 7,
      "z": -3,
      "name": "Wood_Deadwood_Planks"
    },
    {
      "x": 5,
      "y": 8,
      "z": -3,
      "name": "Wood_Deadwood_Planks"
    },
    {
      "x": 5,
      "y": 9,
      "z": -3,
      "name": "Wood_Deadwood_Planks"
    },
    {
      "x": 5,
      "y": 10,
      "z": -3,
      "name": "Wood_Deadwood_Planks"
    },
    {
      "x": 5,
      "y": 11,
      "z": -3,
      "name": "Wood_Deadwood_Planks"
    },
    {
      "x": 5,
      "y": 12,
      "z": -3,
      "name": "Wood_Deadwood_Planks"
    },
    {
      "x": 5,
      "y": 13,
      "z": -3,
      "name": "Wood_Deadwood_Planks"
    },
    {
      "x": 5,
      "y": 14,
      "z": -3,
      "name": "Wood_Deadwood_Planks"
    },
    {
      "x": 5,
      "y": 15,
      "z": -3,
      "name": "Wood_Deadwood_Planks"
    },
    {
      "x": 5,
      "y": 16,
      "z": -3,
      "name": "Rock_Stone_Cobble_Wall"
    },
    {
      "x": 5,
      "y": 6,
      "z": -2,
      "name": "Soil_Dirt_Burnt"
    },
    {
      "x": 5,
      "y": 7,
      "z": -2,
      "name": "Bench_Furnace",
      "components": {
        "Components": {
          "processingBench": {
            "Position": {
              "X": 18,
              "Y": 62,
              "Z": 30
            },
            "TierLevel": 1,
            "UpgradeItems": [],
            "InputContainer": {
              "Id": "Simple",
              "Capacity": 2,
              "Items": {}
            },
            "FuelContainer": {
              "Id": "Simple",
              "Capacity": 2,
              "Items": {}
            },
            "OutputContainer": {
              "Id": "Simple",
              "Capacity": 4,
              "Items": {}
            },
            "Progress": 0.0,
            "FuelTime": 0.0,
            "Active": false,
            "NextExtra": 4
          }
        }
      }
    },
    {
      "x": 5,
      "y": 8,
      "z": -2,
      "name": "Bench_Furnace",
      "components": {
        "Components": {
          "processingBench": {
            "Position": {
              "X": 5,
              "Y": 8,
              "Z": 30
            },
            "TierLevel": 1,
            "UpgradeItems": [],
            "Progress": 0.0,
            "FuelTime": 0.0,
            "Active": false,
            "NextExtra": -1
          }
        }
      },
      "filler": 1024
    },
    {
      "x": 5,
      "y": 9,
      "z": -2,
      "name": "Furniture_Ancient_Platform"
    },
    {
      "x": 5,
      "y": 10,
      "z": -2,
      "name": "Wood_Deadwood_Planks_Half",
      "rotation": 4
    },
    {
      "x": 5,
      "y": 11,
      "z": -2,
      "name": "Wood_Deadwood_Planks"
    },
    {
      "x": 5,
      "y": 12,
      "z": -2,
      "name": "Wood_Deadwood_Planks_Half",
      "rotation": 6
    },
    {
      "x": 5,
      "y": 6,
      "z": -1,
      "name": "Soil_Grass_Burnt"
    },
    {
      "x": 5,
      "y": 7,
      "z": -1,
      "name": "Plant_Grass_Gnarled"
    },
    {
      "x": 5,
      "y": 8,
      "z": -1,
      "name": "Empty"
    },
    {
      "x": 5,
      "y": 9,
      "z": -1,
      "name": "Empty"
    },
    {
      "x": 5,
      "y": 10,
      "z": -1,
      "name": "Empty"
    },
    {
      "x": 5,
      "y": 11,
      "z": -1,
      "name": "Empty"
    },
    {
      "x": 5,
      "y": 12,
      "z": -1,
      "name": "Wood_Deadwood_Planks_Half",
      "rotation": 4
    },
    {
      "x": 5,
      "y": 13,
      "z": -1,
      "name": "Wood_Deadwood_Roof_Steep",
      "rotation": 2
    },
    {
      "x": 5,
      "y": 14,
      "z": -1,
      "name": "Wood_Deadwood_Roof_Steep",
      "filler": 1024,
      "rotation": 2
    },
    {
      "x": 5,
      "y": 6,
      "z": 0,
      "name": "Soil_Grass_Burnt"
    },
    {
      "x": 5,
      "y": 7,
      "z": 0,
      "name": "Rubble_Stone"
    },
    {
      "x": 5,
      "y": 8,
      "z": 0,
      "name": "Empty"
    },
    {
      "x": 5,
      "y": 9,
      "z": 0,
      "name": "Furniture_Ancient_Platform"
    },
    {
      "x": 5,
      "y": 10,
      "z": 0,
      "name": "Empty"
    },
    {
      "x": 5,
      "y": 11,
      "z": 0,
      "name": "Empty"
    },
    {
      "x": 5,
      "y": 12,
      "z": 0,
      "name": "Empty"
    },
    {
      "x": 5,
      "y": 14,
      "z": 0,
      "name": "Wood_Deadwood_Planks"
    },
    {
      "x": 5,
      "y": 15,
      "z": 0,
      "name": "Wood_Deadwood_Roof_Flat"
    },
    {
      "x": 5,
      "y": 6,
      "z": 1,
      "name": "Soil_Grass_Burnt"
    },
    {
      "x": 5,
      "y": 7,
      "z": 1,
      "name": "Block_Spawner_Block",
      "components": {
        "Components": {
          "PlacedByInteraction": {
            "WhoPlacedUuid": {
              "$binary": "F2LgmhWMO1aBEZTjId79Qg==",
              "$type": "04"
            }
          },
          "BlockSpawner": {
            "BlockSpawnerId": "Zone4_Undead_Tier1"
          }
        }
      },
      "rotation": 3
    },
    {
      "x": 5,
      "y": 8,
      "z": 1,
      "name": "Empty"
    },
    {
      "x": 5,
      "y": 9,
      "z": 1,
      "name": "Furniture_Ancient_Platform"
    },
    {
      "x": 5,
      "y": 10,
      "z": 1,
      "name": "Empty"
    },
    {
      "x": 5,
      "y": 11,
      "z": 1,
      "name": "Empty"
    },
    {
      "x": 5,
      "y": 12,
      "z": 1,
      "name": "Wood_Deadwood_Planks_Half",
      "rotation": 6
    },
    {
      "x": 5,
      "y": 13,
      "z": 1,
      "name": "Wood_Deadwood_Roof_Steep"
    },
    {
      "x": 5,
      "y": 14,
      "z": 1,
      "name": "Wood_Deadwood_Roof_Steep",
      "filler": 1024
    },
    {
      "x": 5,
      "y": 6,
      "z": 2,
      "name": "Wood_Softwood_Planks"
    },
    {
      "x": 5,
      "y": 7,
      "z": 2,
      "name": "Furniture_Ancient_Pot",
      "rotation": 2
    },
    {
      "x": 5,
      "y": 8,
      "z": 2,
      "name": "Empty"
    },
    {
      "x": 5,
      "y": 9,
      "z": 2,
      "name": "Furniture_Ancient_Platform"
    },
    {
      "x": 5,
      "y": 10,
      "z": 2,
      "name": "Wood_Deadwood_Planks_Half",
      "rotation": 6
    },
    {
      "x": 5,
      "y": 11,
      "z": 2,
      "name": "*Wood_Deadwood_Planks_Half_State_Definitions_Block"
    },
    {
      "x": 5,
      "y": 12,
      "z": 2,
      "name": "Wood_Deadwood_Planks_Half",
      "rotation": 4
    },
    {
      "x": 5,
      "y": 6,
      "z": 3,
      "name": "Wood_Deadwood_Planks"
    },
    {
      "x": 5,
      "y": 7,
      "z": 3,
      "name": "Wood_Deadwood_Planks"
    },
    {
      "x": 5,
      "y": 8,
      "z": 3,
      "name": "Wood_Deadwood_Planks"
    },
    {
      "x": 5,
      "y": 9,
      "z": 3,
      "name": "Wood_Deadwood_Planks"
    },
    {
      "x": 5,
      "y": 10,
      "z": 3,
      "name": "Wood_Deadwood_Roof"
    },
    {
      "x": 5,
      "y": 6,
      "z": 4,
      "name": "Soil_Dirt_Burnt"
    },
    {
      "x": 5,
      "y": 9,
      "z": 4,
      "name": "Wood_Deadwood_Roof"
    },
    {
      "x": 5,
      "y": 6,
      "z": 5,
      "name": "Wood_Softwood_Planks"
    },
    {
      "x": 6,
      "y": 6,
      "z": -4,
      "name": "Wood_Deadwood_Planks_Half",
      "rotation": 6
    },
    {
      "x": 6,
      "y": 7,
      "z": -4,
      "name": "Wood_Deadwood_Planks_Half",
      "rotation": 6
    },
    {
      "x": 6,
      "y": 8,
      "z": -4,
      "name": "Wood_Deadwood_Planks_Half",
      "rotation": 6
    },
    {
      "x": 6,
      "y": 9,
      "z": -4,
      "name": "Wood_Deadwood_Roof",
      "rotation": 2
    },
    {
      "x": 6,
      "y": 0,
      "z": -3,
      "name": "Wood_Deadwood_Beam"
    },
    {
      "x": 6,
      "y": 1,
      "z": -3,
      "name": "Wood_Deadwood_Beam"
    },
    {
      "x": 6,
      "y": 2,
      "z": -3,
      "name": "Wood_Deadwood_Beam"
    },
    {
      "x": 6,
      "y": 3,
      "z": -3,
      "name": "Wood_Deadwood_Beam"
    },
    {
      "x": 6,
      "y": 4,
      "z": -3,
      "name": "Wood_Deadwood_Beam"
    },
    {
      "x": 6,
      "y": 5,
      "z": -3,
      "name": "Wood_Deadwood_Beam"
    },
    {
      "x": 6,
      "y": 6,
      "z": -3,
      "name": "Wood_Deadwood_Planks"
    },
    {
      "x": 6,
      "y": 7,
      "z": -3,
      "name": "Wood_Deadwood_Planks"
    },
    {
      "x": 6,
      "y": 8,
      "z": -3,
      "name": "Wood_Deadwood_Planks"
    },
    {
      "x": 6,
      "y": 9,
      "z": -3,
      "name": "Wood_Deadwood_Planks"
    },
    {
      "x": 6,
      "y": 10,
      "z": -3,
      "name": "Wood_Deadwood_Roof",
      "rotation": 2
    },
    {
      "x": 6,
      "y": 6,
      "z": -2,
      "name": "Wood_Deadwood_Planks"
    },
    {
      "x": 6,
      "y": 7,
      "z": -2,
      "name": "Wood_Deadwood_Planks"
    },
    {
      "x": 6,
      "y": 8,
      "z": -2,
      "name": "Wood_Deadwood_Planks"
    },
    {
      "x": 6,
      "y": 9,
      "z": -2,
      "name": "Wood_Deadwood_Planks"
    },
    {
      "x": 6,
      "y": 10,
      "z": -2,
      "name": "Soil_Grass_Burnt"
    },
    {
      "x": 6,
      "y": 11,
      "z": -2,
      "name": "Plant_Grass_Gnarled_Tall"
    },
    {
      "x": 6,
      "y": 12,
      "z": -2,
      "name": "Plant_Grass_Gnarled_Tall",
      "filler": 1024
    },
    {
      "x": 6,
      "y": 6,
      "z": -1,
      "name": "Wood_Deadwood_Planks"
    },
    {
      "x": 6,
      "y": 7,
      "z": -1,
      "name": "Soil_Grass_Burnt"
    },
    {
      "x": 6,
      "y": 8,
      "z": -1,
      "name": "Plant_Grass_Gnarled_Tall"
    },
    {
      "x": 6,
      "y": 9,
      "z": -1,
      "name": "Plant_Grass_Gnarled_Tall",
      "filler": 1024
    },
    {
      "x": 6,
      "y": 6,
      "z": 0,
      "name": "Wood_Deadwood_Planks"
    },
    {
      "x": 6,
      "y": 7,
      "z": 0,
      "name": "Wood_Deadwood_Planks"
    },
    {
      "x": 6,
      "y": 8,
      "z": 0,
      "name": "Wood_Deadwood_Planks"
    },
    {
      "x": 6,
      "y": 9,
      "z": 0,
      "name": "Wood_Deadwood_Planks"
    },
    {
      "x": 6,
      "y": 10,
      "z": 0,
      "name": "Wood_Deadwood_Planks_Half",
      "rotation": 6
    },
    {
      "x": 6,
      "y": 11,
      "z": 0,
      "name": "Wood_Deadwood_Planks_Half",
      "rotation": 6
    },
    {
      "x": 6,
      "y": 12,
      "z": 0,
      "name": "Wood_Deadwood_Stairs",
      "rotation": 8
    },
    {
      "x": 6,
      "y": 13,
      "z": 0,
      "name": "Wood_Deadwood_Ornate"
    },
    {
      "x": 6,
      "y": 14,
      "z": 0,
      "name": "Soil_Grass_Burnt"
    },
    {
      "x": 6,
      "y": 15,
      "z": 0,
      "name": "Plant_Grass_Gnarled"
    },
    {
      "x": 6,
      "y": 6,
      "z": 1,
      "name": "Wood_Deadwood_Planks"
    },
    {
      "x": 6,
      "y": 7,
      "z": 1,
      "name": "Wood_Deadwood_Planks"
    },
    {
      "x": 6,
      "y": 8,
      "z": 1,
      "name": "Wood_Deadwood_Planks"
    },
    {
      "x": 6,
      "y": 9,
      "z": 1,
      "name": "Wood_Deadwood_Planks"
    },
    {
      "x": 6,
      "y": 10,
      "z": 1,
      "name": "Wood_Deadwood_Ornate"
    },
    {
      "x": 6,
      "y": 11,
      "z": 1,
      "name": "Wood_Deadwood_Ornate"
    },
    {
      "x": 6,
      "y": 12,
      "z": 1,
      "name": "Wood_Deadwood_Ornate"
    },
    {
      "x": 6,
      "y": 13,
      "z": 1,
      "name": "Wood_Deadwood_Roof_Steep"
    },
    {
      "x": 6,
      "y": 14,
      "z": 1,
      "name": "Wood_Deadwood_Roof_Steep",
      "filler": 1024
    },
    {
      "x": 6,
      "y": 6,
      "z": 2,
      "name": "Wood_Deadwood_Planks"
    },
    {
      "x": 6,
      "y": 7,
      "z": 2,
      "name": "Wood_Deadwood_Planks"
    },
    {
      "x": 6,
      "y": 8,
      "z": 2,
      "name": "Wood_Deadwood_Planks"
    },
    {
      "x": 6,
      "y": 9,
      "z": 2,
      "name": "Wood_Deadwood_Planks"
    },
    {
      "x": 6,
      "y": 10,
      "z": 2,
      "name": "Wood_Deadwood_Ornate"
    },
    {
      "x": 6,
      "y": 11,
      "z": 2,
      "name": "*Wood_Deadwood_Planks_Half_State_Definitions_Block"
    },
    {
      "x": 6,
      "y": 12,
      "z": 2,
      "name": "Wood_Deadwood_Planks_Half",
      "rotation": 4
    },
    {
      "x": 6,
      "y": 6,
      "z": 3,
      "name": "Wood_Deadwood_Planks"
    },
    {
      "x": 6,
      "y": 7,
      "z": 3,
      "name": "Wood_Deadwood_Planks"
    },
    {
      "x": 6,
      "y": 8,
      "z": 3,
      "name": "Wood_Deadwood_Planks"
    },
    {
      "x": 6,
      "y": 9,
      "z": 3,
      "name": "Wood_Deadwood_Planks"
    },
    {
      "x": 6,
      "y": 10,
      "z": 3,
      "name": "Wood_Deadwood_Roof"
    },
    {
      "x": 6,
      "y": 6,
      "z": 4,
      "name": "Soil_Dirt_Burnt"
    },
    {
      "x": 6,
      "y": 7,
      "z": 4,
      "name": "Wood_Deadwood_Planks_Half",
      "rotation": 4
    },
    {
      "x": 6,
      "y": 8,
      "z": 4,
      "name": "Wood_Deadwood_Planks_Half",
      "rotation": 4
    },
    {
      "x": 6,
      "y": 9,
      "z": 4,
      "name": "Wood_Deadwood_Roof"
    },
    {
      "x": 6,
      "y": 6,
      "z": 5,
      "name": "Wood_Softwood_Planks"
    },
    {
      "x": 7,
      "y": 9,
      "z": -4,
      "name": "Wood_Deadwood_Roof",
      "rotation": 2
    },
    {
      "x": 7,
      "y": 7,
      "z": -3,
      "name": "Wood_Deadwood_Planks_Half",
      "rotation": 5
    },
    {
      "x": 7,
      "y": 9,
      "z": -3,
      "name": "Wood_Deadwood_Stairs",
      "rotation": 10
    },
    {
      "x": 7,
      "y": 10,
      "z": -3,
      "name": "Wood_Deadwood_Roof",
      "rotation": 2
    },
    {
      "x": 7,
      "y": 7,
      "z": -2,
      "name": "Plant_Grass_Gnarled"
    },
    {
      "x": 7,
      "y": 9,
      "z": -2,
      "name": "Wood_Deadwood_Planks_Half",
      "rotation": 8
    },
    {
      "x": 7,
      "y": 10,
      "z": -2,
      "name": "Wood_Deadwood_Planks_Half",
      "rotation": 4
    },
    {
      "x": 7,
      "y": 7,
      "z": -1,
      "name": "Soil_Grass_Burnt"
    },
    {
      "x": 7,
      "y": 8,
      "z": -1,
      "name": "Plant_Grass_Gnarled"
    },
    {
      "x": 7,
      "y": 9,
      "z": 1,
      "name": "Wood_Deadwood_Planks_Half",
      "rotation": 8
    },
    {
      "x": 7,
      "y": 12,
      "z": 1,
      "name": "Wood_Deadwood_Planks_Half",
      "rotation": 6
    },
    {
      "x": 7,
      "y": 13,
      "z": 1,
      "name": "Wood_Deadwood_Roof_Steep"
    },
    {
      "x": 7,
      "y": 14,
      "z": 1,
      "name": "Wood_Deadwood_Roof_Steep",
      "filler": 1024
    },
    {
      "x": 7,
      "y": 9,
      "z": 2,
      "name": "Wood_Deadwood_Planks_Half",
      "rotation": 8
    },
    {
      "x": 7,
      "y": 10,
      "z": 2,
      "name": "Wood_Deadwood_Planks_Half",
      "rotation": 6
    },
    {
      "x": 7,
      "y": 11,
      "z": 2,
      "name": "Wood_Deadwood_Roof"
    },
    {
      "x": 7,
      "y": 12,
      "z": 2,
      "name": "Wood_Deadwood_Planks_Half",
      "rotation": 4
    },
    {
      "x": 7,
      "y": 6,
      "z": 3,
      "name": "Wood_Deadwood_Planks"
    },
    {
      "x": 7,
      "y": 7,
      "z": 3,
      "name": "Wood_Deadwood_Planks"
    },
    {
      "x": 7,
      "y": 8,
      "z": 3,
      "name": "Wood_Deadwood_Planks_Half",
      "rotation": 5
    },
    {
      "x": 7,
      "y": 9,
      "z": 3,
      "name": "Wood_Deadwood_Stairs",
      "rotation": 8
    },
    {
      "x": 7,
      "y": 10,
      "z": 3,
      "name": "Wood_Deadwood_Roof"
    },
    {
      "x": 7,
      "y": 6,
      "z": 4,
      "name": "Wood_Deadwood_Planks"
    },
    {
      "x": 7,
      "y": 9,
      "z": 4,
      "name": "Wood_Deadwood_Roof"
    },
    {
      "x": 7,
      "y": 0,
      "z": 5,
      "name": "Wood_Deadwood_Beam"
    },
    {
      "x": 7,
      "y": 1,
      "z": 5,
      "name": "Wood_Deadwood_Beam"
    },
    {
      "x": 7,
      "y": 2,
      "z": 5,
      "name": "Wood_Deadwood_Beam"
    },
    {
      "x": 7,
      "y": 3,
      "z": 5,
      "name": "Wood_Deadwood_Beam"
    },
    {
      "x": 7,
      "y": 4,
      "z": 5,
      "name": "Wood_Deadwood_Beam"
    },
    {
      "x": 7,
      "y": 5,
      "z": 5,
      "name": "Wood_Deadwood_Beam"
    },
    {
      "x": 7,
      "y": 6,
      "z": 5,
      "name": "Wood_Deadwood_Planks"
    }
  ]
}
