{
  "version": 8,
  "blockIdVersion": 8,
  "anchorX": 0,
  "anchorY": 15,
  "anchorZ": 0,
  "blocks": [
    {
      "x": -1,
      "y": 11,
      "z": 1,
      "name": "Rock_Marble"
    },
    {
      "x": -1,
      "y": 12,
      "z": 1,
      "name": "Rock_Marble"
    },
    {
      "x": -1,
      "y": 13,
      "z": 1,
      "name": "Rock_Marble"
    },
    {
      "x": -1,
      "y": 11,
      "z": 2,
      "name": "Rock_Marble"
    },
    {
      "x": -1,
      "y": 12,
      "z": 2,
      "name": "Rock_Marble"
    },
    {
      "x": -1,
      "y": 13,
      "z": 2,
      "name": "Rock_Marble"
    },
    {
      "x": 0,
      "y": 12,
      "z": -1,
      "name": "Rock_Marble"
    },
    {
      "x": 0,
      "y": 11,
      "z": 0,
      "name": "Rock_Marble"
    },
    {
      "x": 0,
      "y": 12,
      "z": 0,
      "name": "Rock_Marble"
    },
    {
      "x": 0,
      "y": 13,
      "z": 0,
      "name": "Rock_Marble"
    },
    {
      "x": 0,
      "y": 14,
      "z": 0,
      "name": "Rock_Marble"
    },
    {
      "x": 0,
      "y": 10,
      "z": 1,
      "name": "Rock_Marble"
    },
    {
      "x": 0,
      "y": 11,
      "z": 1,
      "name": "Rock_Marble"
    },
    {
      "x": 0,
      "y": 12,
      "z": 1,
      "name": "Rock_Marble"
    },
    {
      "x": 0,
      "y": 13,
      "z": 1,
      "name": "Rock_Marble"
    },
    {
      "x": 0,
      "y": 14,
      "z": 1,
      "name": "Rock_Marble"
    },
    {
      "x": 0,
      "y": 10,
      "z": 2,
      "name": "Rock_Marble"
    },
    {
      "x": 0,
      "y": 11,
      "z": 2,
      "name": "Rock_Marble"
    },
    {
      "x": 0,
      "y": 12,
      "z": 2,
      "name": "Rock_Marble"
    },
    {
      "x": 0,
      "y": 13,
      "z": 2,
      "name": "Rock_Marble"
    },
    {
      "x": 0,
      "y": 14,
      "z": 2,
      "name": "Rock_Marble"
    },
    {
      "x": 0,
      "y": 11,
      "z": 3,
      "name": "Rock_Marble"
    },
    {
      "x": 0,
      "y": 12,
      "z": 3,
      "name": "Rock_Marble"
    },
    {
      "x": 0,
      "y": 13,
      "z": 3,
      "name": "Rock_Marble"
    },
    {
      "x": 0,
      "y": 14,
      "z": 3,
      "name": "Rock_Marble"
    },
    {
      "x": 1,
      "y": 11,
      "z": -1,
      "name": "Rock_Chalk"
    },
    {
      "x": 1,
      "y": 12,
      "z": -1,
      "name": "Rock_Chalk"
    },
    {
      "x": 1,
      "y": 13,
      "z": -1,
      "name": "Rock_Chalk"
    },
    {
      "x": 1,
      "y": 10,
      "z": 0,
      "name": "Rock_Chalk"
    },
    {
      "x": 1,
      "y": 11,
      "z": 0,
      "name": "Rock_Chalk"
    },
    {
      "x": 1,
      "y": 12,
      "z": 0,
      "name": "Rock_Chalk"
    },
    {
      "x": 1,
      "y": 13,
      "z": 0,
      "name": "Rock_Chalk"
    },
    {
      "x": 1,
      "y": 14,
      "z": 0,
      "name": "Rock_Chalk"
    },
    {
      "x": 1,
      "y": 10,
      "z": 1,
      "name": "Rock_Chalk"
    },
    {
      "x": 1,
      "y": 11,
      "z": 1,
      "name": "Rock_Chalk"
    },
    {
      "x": 1,
      "y": 12,
      "z": 1,
      "name": "Rock_Chalk"
    },
    {
      "x": 1,
      "y": 13,
      "z": 1,
      "name": "Rock_Chalk"
    },
    {
      "x": 1,
      "y": 14,
      "z": 1,
      "name": "Rock_Chalk"
    },
    {
      "x": 1,
      "y": 15,
      "z": 1,
      "name": "Rock_Chalk"
    },
    {
      "x": 1,
      "y": 10,
      "z": 2,
      "name": "Rock_Chalk"
    },
    {
      "x": 1,
      "y": 11,
      "z": 2,
      "name": "Rock_Chalk"
    },
    {
      "x": 1,
      "y": 12,
      "z": 2,
      "name": "Rock_Chalk"
    },
    {
      "x": 1,
      "y": 13,
      "z": 2,
      "name": "Rock_Chalk"
    },
    {
      "x": 1,
      "y": 14,
      "z": 2,
      "name": "Rock_Chalk"
    },
    {
      "x": 1,
      "y": 15,
      "z": 2,
      "name": "Rock_Chalk"
    },
    {
      "x": 1,
      "y": 10,
      "z": 3,
      "name": "Rock_Chalk"
    },
    {
      "x": 1,
      "y": 11,
      "z": 3,
      "name": "Rock_Chalk"
    },
    {
      "x": 1,
      "y": 12,
      "z": 3,
      "name": "Rock_Chalk"
    },
    {
      "x": 1,
      "y": 13,
      "z": 3,
      "name": "Rock_Chalk"
    },
    {
      "x": 1,
      "y": 14,
      "z": 3,
      "name": "Rock_Chalk"
    },
    {
      "x": 1,
      "y": 11,
      "z": 4,
      "name": "Rock_Marble"
    },
    {
      "x": 1,
      "y": 12,
      "z": 4,
      "name": "Rock_Marble"
    },
    {
      "x": 1,
      "y": 13,
      "z": 4,
      "name": "Rock_Marble"
    },
    {
      "x": 1,
      "y": 14,
      "z": 4,
      "name": "Rock_Marble"
    },
    {
      "x": 2,
      "y": 11,
      "z": -1,
      "name": "Rock_Chalk"
    },
    {
      "x": 2,
      "y": 12,
      "z": -1,
      "name": "Rock_Chalk"
    },
    {
      "x": 2,
      "y": 13,
      "z": -1,
      "name": "Rock_Chalk"
    },
    {
      "x": 2,
      "y": 14,
      "z": -1,
      "name": "Rock_Chalk"
    },
    {
      "x": 2,
      "y": 10,
      "z": 0,
      "name": "Rock_Chalk"
    },
    {
      "x": 2,
      "y": 11,
      "z": 0,
      "name": "Rock_Chalk"
    },
    {
      "x": 2,
      "y": 12,
      "z": 0,
      "name": "Rock_Chalk"
    },
    {
      "x": 2,
      "y": 13,
      "z": 0,
      "name": "Rock_Chalk"
    },
    {
      "x": 2,
      "y": 14,
      "z": 0,
      "name": "Rock_Chalk"
    },
    {
      "x": 2,
      "y": 15,
      "z": 0,
      "name": "Rock_Chalk"
    },
    {
      "x": 2,
      "y": 10,
      "z": 1,
      "name": "Rock_Chalk"
    },
    {
      "x": 2,
      "y": 11,
      "z": 1,
      "name": "Rock_Chalk"
    },
    {
      "x": 2,
      "y": 12,
      "z": 1,
      "name": "Rock_Chalk"
    },
    {
      "x": 2,
      "y": 13,
      "z": 1,
      "name": "Rock_Chalk"
    },
    {
      "x": 2,
      "y": 14,
      "z": 1,
      "name": "Rock_Chalk"
    },
    {
      "x": 2,
      "y": 15,
      "z": 1,
      "name": "Rock_Chalk"
    },
    {
      "x": 2,
      "y": 10,
      "z": 2,
      "name": "Rock_Chalk"
    },
    {
      "x": 2,
      "y": 11,
      "z": 2,
      "name": "Rock_Chalk"
    },
    {
      "x": 2,
      "y": 12,
      "z": 2,
      "name": "Rock_Chalk"
    },
    {
      "x": 2,
      "y": 13,
      "z": 2,
      "name": "Rock_Chalk"
    },
    {
      "x": 2,
      "y": 14,
      "z": 2,
      "name": "Rock_Chalk"
    },
    {
      "x": 2,
      "y": 15,
      "z": 2,
      "name": "Rock_Chalk"
    },
    {
      "x": 2,
      "y": 10,
      "z": 3,
      "name": "Rock_Chalk"
    },
    {
      "x": 2,
      "y": 11,
      "z": 3,
      "name": "Rock_Chalk"
    },
    {
      "x": 2,
      "y": 12,
      "z": 3,
      "name": "Rock_Chalk"
    },
    {
      "x": 2,
      "y": 13,
      "z": 3,
      "name": "Rock_Chalk"
    },
    {
      "x": 2,
      "y": 14,
      "z": 3,
      "name": "Rock_Chalk"
    },
    {
      "x": 2,
      "y": 15,
      "z": 3,
      "name": "Rock_Chalk"
    },
    {
      "x": 2,
      "y": 10,
      "z": 4,
      "name": "Rock_Chalk"
    },
    {
      "x": 2,
      "y": 11,
      "z": 4,
      "name": "Rock_Chalk"
    },
    {
      "x": 2,
      "y": 12,
      "z": 4,
      "name": "Rock_Chalk"
    },
    {
      "x": 2,
      "y": 13,
      "z": 4,
      "name": "Rock_Chalk"
    },
    {
      "x": 2,
      "y": 14,
      "z": 4,
      "name": "Rock_Chalk"
    },
    {
      "x": 3,
      "y": 11,
      "z": -1,
      "name": "Rock_Chalk"
    },
    {
      "x": 3,
      "y": 12,
      "z": -1,
      "name": "Rock_Chalk"
    },
    {
      "x": 3,
      "y": 13,
      "z": -1,
      "name": "Rock_Chalk"
    },
    {
      "x": 3,
      "y": 10,
      "z": 0,
      "name": "Rock_Chalk"
    },
    {
      "x": 3,
      "y": 11,
      "z": 0,
      "name": "Rock_Chalk"
    },
    {
      "x": 3,
      "y": 12,
      "z": 0,
      "name": "Rock_Chalk"
    },
    {
      "x": 3,
      "y": 13,
      "z": 0,
      "name": "Rock_Chalk"
    },
    {
      "x": 3,
      "y": 14,
      "z": 0,
      "name": "Rock_Chalk"
    },
    {
      "x": 3,
      "y": 10,
      "z": 1,
      "name": "Rock_Chalk"
    },
    {
      "x": 3,
      "y": 11,
      "z": 1,
      "name": "Rock_Chalk"
    },
    {
      "x": 3,
      "y": 12,
      "z": 1,
      "name": "Rock_Chalk"
    },
    {
      "x": 3,
      "y": 13,
      "z": 1,
      "name": "Rock_Chalk"
    },
    {
      "x": 3,
      "y": 14,
      "z": 1,
      "name": "Rock_Chalk"
    },
    {
      "x": 3,
      "y": 15,
      "z": 1,
      "name": "Rock_Chalk"
    },
    {
      "x": 3,
      "y": 10,
      "z": 2,
      "name": "Rock_Chalk"
    },
    {
      "x": 3,
      "y": 11,
      "z": 2,
      "name": "Rock_Chalk"
    },
    {
      "x": 3,
      "y": 12,
      "z": 2,
      "name": "Rock_Chalk"
    },
    {
      "x": 3,
      "y": 13,
      "z": 2,
      "name": "Rock_Chalk"
    },
    {
      "x": 3,
      "y": 14,
      "z": 2,
      "name": "Rock_Chalk"
    },
    {
      "x": 3,
      "y": 15,
      "z": 2,
      "name": "Rock_Chalk"
    },
    {
      "x": 3,
      "y": 10,
      "z": 3,
      "name": "Rock_Chalk"
    },
    {
      "x": 3,
      "y": 11,
      "z": 3,
      "name": "Rock_Chalk"
    },
    {
      "x": 3,
      "y": 12,
      "z": 3,
      "name": "Rock_Chalk"
    },
    {
      "x": 3,
      "y": 13,
      "z": 3,
      "name": "Rock_Chalk"
    },
    {
      "x": 3,
      "y": 14,
      "z": 3,
      "name": "Rock_Chalk"
    },
    {
      "x": 3,
      "y": 15,
      "z": 3,
      "name": "Rock_Chalk"
    },
    {
      "x": 3,
      "y": 11,
      "z": 4,
      "name": "Rock_Chalk"
    },
    {
      "x": 3,
      "y": 12,
      "z": 4,
      "name": "Rock_Chalk"
    },
    {
      "x": 3,
      "y": 13,
      "z": 4,
      "name": "Rock_Chalk"
    },
    {
      "x": 3,
      "y": 14,
      "z": 4,
      "name": "Rock_Chalk"
    },
    {
      "x": 4,
      "y": 12,
      "z": -1,
      "name": "Rock_Chalk"
    },
    {
      "x": 4,
      "y": 11,
      "z": 0,
      "name": "Rock_Chalk"
    },
    {
      "x": 4,
      "y": 12,
      "z": 0,
      "name": "Rock_Chalk"
    },
    {
      "x": 4,
      "y": 13,
      "z": 0,
      "name": "Rock_Chalk"
    },
    {
      "x": 4,
      "y": 14,
      "z": 0,
      "name": "Rock_Chalk"
    },
    {
      "x": 4,
      "y": 10,
      "z": 1,
      "name": "Rock_Chalk"
    },
    {
      "x": 4,
      "y": 11,
      "z": 1,
      "name": "Rock_Chalk"
    },
    {
      "x": 4,
      "y": 12,
      "z": 1,
      "name": "Rock_Chalk"
    },
    {
      "x": 4,
      "y": 13,
      "z": 1,
      "name": "Rock_Chalk"
    },
    {
      "x": 4,
      "y": 14,
      "z": 1,
      "name": "Rock_Chalk"
    },
    {
      "x": 4,
      "y": 10,
      "z": 2,
      "name": "Rock_Chalk"
    },
    {
      "x": 4,
      "y": 11,
      "z": 2,
      "name": "Rock_Chalk"
    },
    {
      "x": 4,
      "y": 12,
      "z": 2,
      "name": "Rock_Chalk"
    },
    {
      "x": 4,
      "y": 13,
      "z": 2,
      "name": "Rock_Chalk"
    },
    {
      "x": 4,
      "y": 14,
      "z": 2,
      "name": "Rock_Chalk"
    },
    {
      "x": 4,
      "y": 11,
      "z": 3,
      "name": "Rock_Chalk"
    },
    {
      "x": 4,
      "y": 12,
      "z": 3,
      "name": "Rock_Chalk"
    },
    {
      "x": 4,
      "y": 13,
      "z": 3,
      "name": "Rock_Chalk"
    },
    {
      "x": 4,
      "y": 14,
      "z": 3,
      "name": "Rock_Chalk"
    },
    {
      "x": 4,
      "y": 12,
      "z": 4,
      "name": "Rock_Chalk"
    },
    {
      "x": 4,
      "y": 13,
      "z": 4,
      "name": "Rock_Chalk"
    },
    {
      "x": 5,
      "y": 11,
      "z": 1,
      "name": "Rock_Chalk"
    },
    {
      "x": 5,
      "y": 12,
      "z": 1,
      "name": "Rock_Chalk"
    },
    {
      "x": 5,
      "y": 13,
      "z": 1,
      "name": "Rock_Chalk"
    },
    {
      "x": 5,
      "y": 12,
      "z": 2,
      "name": "Rock_Chalk"
    },
    {
      "x": 5,
      "y": 13,
      "z": 2,
      "name": "Rock_Chalk"
    }
  ]
}