{
  "version": 8,
  "blockIdVersion": 8,
  "anchorX": -1,
  "anchorY": 18,
  "anchorZ": 0,
  "blocks": [
    {
      "x": -17,
      "y": 11,
      "z": 0,
      "name": "Rock_Ice"
    },
    {
      "x": -17,
      "y": 12,
      "z": 0,
      "name": "Rock_Ice"
    },
    {
      "x": -17,
      "y": 13,
      "z": 0,
      "name": "Rock_Ice"
    },
    {
      "x": -17,
      "y": 11,
      "z": 1,
      "name": "Rock_Ice"
    },
    {
      "x": -17,
      "y": 12,
      "z": 1,
      "name": "Rock_Ice"
    },
    {
      "x": -17,
      "y": 13,
      "z": 1,
      "name": "Rock_Ice"
    },
    {
      "x": -17,
      "y": 14,
      "z": 1,
      "name": "Rock_Ice"
    },
    {
      "x": -17,
      "y": 15,
      "z": 1,
      "name": "Rock_Ice"
    },
    {
      "x": -17,
      "y": 11,
      "z": 2,
      "name": "Rock_Ice"
    },
    {
      "x": -17,
      "y": 12,
      "z": 2,
      "name": "Rock_Ice"
    },
    {
      "x": -17,
      "y": 13,
      "z": 2,
      "name": "Rock_Ice"
    },
    {
      "x": -16,
      "y": 13,
      "z": -1,
      "name": "Rock_Ice"
    },
    {
      "x": -16,
      "y": 12,
      "z": 0,
      "name": "Rock_Ice"
    },
    {
      "x": -16,
      "y": 13,
      "z": 0,
      "name": "Rock_Ice"
    },
    {
      "x": -16,
      "y": 14,
      "z": 0,
      "name": "Rock_Ice"
    },
    {
      "x": -16,
      "y": 11,
      "z": 1,
      "name": "Rock_Ice"
    },
    {
      "x": -16,
      "y": 12,
      "z": 1,
      "name": "Rock_Ice"
    },
    {
      "x": -16,
      "y": 13,
      "z": 1,
      "name": "Rock_Ice"
    },
    {
      "x": -16,
      "y": 14,
      "z": 1,
      "name": "Rock_Ice"
    },
    {
      "x": -16,
      "y": 15,
      "z": 1,
      "name": "Rock_Ice"
    },
    {
      "x": -16,
      "y": 16,
      "z": 1,
      "name": "Rock_Ice"
    },
    {
      "x": -16,
      "y": 12,
      "z": 2,
      "name": "Rock_Ice"
    },
    {
      "x": -16,
      "y": 13,
      "z": 2,
      "name": "Rock_Ice"
    },
    {
      "x": -16,
      "y": 14,
      "z": 2,
      "name": "Rock_Ice"
    },
    {
      "x": -16,
      "y": 15,
      "z": 2,
      "name": "Rock_Ice"
    },
    {
      "x": -15,
      "y": 14,
      "z": -1,
      "name": "Rock_Ice"
    },
    {
      "x": -15,
      "y": 15,
      "z": -1,
      "name": "Rock_Ice"
    },
    {
      "x": -15,
      "y": 13,
      "z": 0,
      "name": "Rock_Ice"
    },
    {
      "x": -15,
      "y": 14,
      "z": 0,
      "name": "Rock_Ice"
    },
    {
      "x": -15,
      "y": 15,
      "z": 0,
      "name": "Rock_Ice"
    },
    {
      "x": -15,
      "y": 16,
      "z": 0,
      "name": "Rock_Ice"
    },
    {
      "x": -15,
      "y": 12,
      "z": 1,
      "name": "Rock_Ice"
    },
    {
      "x": -15,
      "y": 13,
      "z": 1,
      "name": "Rock_Ice"
    },
    {
      "x": -15,
      "y": 14,
      "z": 1,
      "name": "Rock_Ice"
    },
    {
      "x": -15,
      "y": 15,
      "z": 1,
      "name": "Rock_Ice"
    },
    {
      "x": -15,
      "y": 16,
      "z": 1,
      "name": "Rock_Ice"
    },
    {
      "x": -15,
      "y": 17,
      "z": 1,
      "name": "Rock_Ice"
    },
    {
      "x": -15,
      "y": 13,
      "z": 2,
      "name": "Rock_Ice"
    },
    {
      "x": -15,
      "y": 14,
      "z": 2,
      "name": "Rock_Ice"
    },
    {
      "x": -15,
      "y": 15,
      "z": 2,
      "name": "Rock_Ice"
    },
    {
      "x": -15,
      "y": 16,
      "z": 2,
      "name": "Rock_Ice"
    },
    {
      "x": -15,
      "y": 14,
      "z": 3,
      "name": "Rock_Ice"
    },
    {
      "x": -15,
      "y": 15,
      "z": 3,
      "name": "Rock_Ice"
    },
    {
      "x": -14,
      "y": 15,
      "z": -1,
      "name": "Rock_Ice"
    },
    {
      "x": -14,
      "y": 16,
      "z": -1,
      "name": "Rock_Ice"
    },
    {
      "x": -14,
      "y": 14,
      "z": 0,
      "name": "Rock_Ice"
    },
    {
      "x": -14,
      "y": 15,
      "z": 0,
      "name": "Rock_Ice"
    },
    {
      "x": -14,
      "y": 16,
      "z": 0,
      "name": "Rock_Ice"
    },
    {
      "x": -14,
      "y": 17,
      "z": 0,
      "name": "Rock_Ice"
    },
    {
      "x": -14,
      "y": 13,
      "z": 1,
      "name": "Rock_Ice"
    },
    {
      "x": -14,
      "y": 14,
      "z": 1,
      "name": "Rock_Ice"
    },
    {
      "x": -14,
      "y": 15,
      "z": 1,
      "name": "Rock_Ice"
    },
    {
      "x": -14,
      "y": 16,
      "z": 1,
      "name": "Rock_Ice"
    },
    {
      "x": -14,
      "y": 17,
      "z": 1,
      "name": "Rock_Ice"
    },
    {
      "x": -14,
      "y": 18,
      "z": 1,
      "name": "Rock_Ice"
    },
    {
      "x": -14,
      "y": 14,
      "z": 2,
      "name": "Rock_Ice"
    },
    {
      "x": -14,
      "y": 15,
      "z": 2,
      "name": "Rock_Ice"
    },
    {
      "x": -14,
      "y": 16,
      "z": 2,
      "name": "Rock_Ice"
    },
    {
      "x": -14,
      "y": 17,
      "z": 2,
      "name": "Rock_Ice"
    },
    {
      "x": -14,
      "y": 15,
      "z": 3,
      "name": "Rock_Ice"
    },
    {
      "x": -14,
      "y": 16,
      "z": 3,
      "name": "Rock_Ice"
    },
    {
      "x": -13,
      "y": 9,
      "z": -5,
      "name": "Soil_Pebbles"
    },
    {
      "x": -13,
      "y": 9,
      "z": -4,
      "name": "Soil_Pebbles"
    },
    {
      "x": -13,
      "y": 9,
      "z": -3,
      "name": "Soil_Pebbles"
    },
    {
      "x": -13,
      "y": 9,
      "z": -2,
      "name": "Soil_Pebbles"
    },
    {
      "x": -13,
      "y": 9,
      "z": -1,
      "name": "Soil_Pebbles"
    },
    {
      "x": -13,
      "y": 16,
      "z": -1,
      "name": "Rock_Ice"
    },
    {
      "x": -13,
      "y": 9,
      "z": 0,
      "name": "Soil_Pebbles"
    },
    {
      "x": -13,
      "y": 15,
      "z": 0,
      "name": "Rock_Ice"
    },
    {
      "x": -13,
      "y": 16,
      "z": 0,
      "name": "Rock_Ice"
    },
    {
      "x": -13,
      "y": 17,
      "z": 0,
      "name": "Rock_Ice"
    },
    {
      "x": -13,
      "y": 14,
      "z": 1,
      "name": "Rock_Ice"
    },
    {
      "x": -13,
      "y": 15,
      "z": 1,
      "name": "Rock_Ice"
    },
    {
      "x": -13,
      "y": 16,
      "z": 1,
      "name": "Rock_Ice"
    },
    {
      "x": -13,
      "y": 17,
      "z": 1,
      "name": "Rock_Ice"
    },
    {
      "x": -13,
      "y": 18,
      "z": 1,
      "name": "Rock_Ice"
    },
    {
      "x": -13,
      "y": 19,
      "z": 1,
      "name": "Rock_Ice"
    },
    {
      "x": -13,
      "y": 15,
      "z": 2,
      "name": "Rock_Ice"
    },
    {
      "x": -13,
      "y": 16,
      "z": 2,
      "name": "Rock_Ice"
    },
    {
      "x": -13,
      "y": 17,
      "z": 2,
      "name": "Rock_Ice"
    },
    {
      "x": -13,
      "y": 16,
      "z": 3,
      "name": "Rock_Ice"
    },
    {
      "x": -13,
      "y": 17,
      "z": 3,
      "name": "Rock_Ice"
    },
    {
      "x": -12,
      "y": 9,
      "z": -6,
      "name": "Soil_Pebbles"
    },
    {
      "x": -12,
      "y": 8,
      "z": -5,
      "name": "Soil_Pebbles"
    },
    {
      "x": -12,
      "y": 8,
      "z": -4,
      "name": "Soil_Pebbles"
    },
    {
      "x": -12,
      "y": 8,
      "z": -3,
      "name": "Soil_Pebbles"
    },
    {
      "x": -12,
      "y": 8,
      "z": -2,
      "name": "Soil_Pebbles"
    },
    {
      "x": -12,
      "y": 8,
      "z": -1,
      "name": "Soil_Pebbles"
    },
    {
      "x": -12,
      "y": 17,
      "z": -1,
      "name": "Rock_Ice"
    },
    {
      "x": -12,
      "y": 9,
      "z": 0,
      "name": "Soil_Pebbles"
    },
    {
      "x": -12,
      "y": 16,
      "z": 0,
      "name": "Rock_Ice"
    },
    {
      "x": -12,
      "y": 17,
      "z": 0,
      "name": "Rock_Ice"
    },
    {
      "x": -12,
      "y": 18,
      "z": 0,
      "name": "Rock_Ice"
    },
    {
      "x": -12,
      "y": 10,
      "z": 1,
      "name": "Soil_Pebbles"
    },
    {
      "x": -12,
      "y": 15,
      "z": 1,
      "name": "Rock_Ice"
    },
    {
      "x": -12,
      "y": 16,
      "z": 1,
      "name": "Rock_Ice"
    },
    {
      "x": -12,
      "y": 17,
      "z": 1,
      "name": "Rock_Ice"
    },
    {
      "x": -12,
      "y": 18,
      "z": 1,
      "name": "Rock_Ice"
    },
    {
      "x": -12,
      "y": 19,
      "z": 1,
      "name": "Rock_Ice"
    },
    {
      "x": -12,
      "y": 16,
      "z": 2,
      "name": "Rock_Ice"
    },
    {
      "x": -12,
      "y": 17,
      "z": 2,
      "name": "Rock_Ice"
    },
    {
      "x": -12,
      "y": 18,
      "z": 2,
      "name": "Rock_Ice"
    },
    {
      "x": -11,
      "y": 8,
      "z": -6,
      "name": "Soil_Pebbles"
    },
    {
      "x": -11,
      "y": 7,
      "z": -5,
      "name": "Soil_Pebbles"
    },
    {
      "x": -11,
      "y": 7,
      "z": -4,
      "name": "Soil_Pebbles"
    },
    {
      "x": -11,
      "y": 7,
      "z": -3,
      "name": "Soil_Pebbles"
    },
    {
      "x": -11,
      "y": 8,
      "z": -3,
      "name": "Rubble_Shale"
    },
    {
      "x": -11,
      "y": 7,
      "z": -2,
      "name": "Soil_Pebbles"
    },
    {
      "x": -11,
      "y": 8,
      "z": -1,
      "name": "Soil_Pebbles"
    },
    {
      "x": -11,
      "y": 8,
      "z": 0,
      "name": "Soil_Pebbles"
    },
    {
      "x": -11,
      "y": 17,
      "z": 0,
      "name": "Rock_Ice"
    },
    {
      "x": -11,
      "y": 18,
      "z": 0,
      "name": "Rock_Ice"
    },
    {
      "x": -11,
      "y": 9,
      "z": 1,
      "name": "Soil_Pebbles"
    },
    {
      "x": -11,
      "y": 16,
      "z": 1,
      "name": "Rock_Ice"
    },
    {
      "x": -11,
      "y": 17,
      "z": 1,
      "name": "Rock_Ice"
    },
    {
      "x": -11,
      "y": 18,
      "z": 1,
      "name": "Rock_Ice"
    },
    {
      "x": -11,
      "y": 19,
      "z": 1,
      "name": "Rock_Ice"
    },
    {
      "x": -11,
      "y": 20,
      "z": 1,
      "name": "Rock_Ice"
    },
    {
      "x": -11,
      "y": 9,
      "z": 2,
      "name": "Soil_Pebbles"
    },
    {
      "x": -11,
      "y": 17,
      "z": 2,
      "name": "Rock_Ice"
    },
    {
      "x": -11,
      "y": 18,
      "z": 2,
      "name": "Rock_Ice"
    },
    {
      "x": -11,
      "y": 19,
      "z": 2,
      "name": "Rock_Ice"
    },
    {
      "x": -10,
      "y": 8,
      "z": -7,
      "name": "Soil_Pebbles"
    },
    {
      "x": -10,
      "y": 8,
      "z": -6,
      "name": "Soil_Pebbles"
    },
    {
      "x": -10,
      "y": 32,
      "z": -6,
      "name": "Rock_Ice"
    },
    {
      "x": -10,
      "y": 33,
      "z": -6,
      "name": "Rock_Ice"
    },
    {
      "x": -10,
      "y": 34,
      "z": -6,
      "name": "Rock_Ice"
    },
    {
      "x": -10,
      "y": 35,
      "z": -6,
      "name": "Rock_Ice"
    },
    {
      "x": -10,
      "y": 7,
      "z": -5,
      "name": "Soil_Pebbles"
    },
    {
      "x": -10,
      "y": 30,
      "z": -5,
      "name": "Rock_Ice"
    },
    {
      "x": -10,
      "y": 31,
      "z": -5,
      "name": "Rock_Ice"
    },
    {
      "x": -10,
      "y": 32,
      "z": -5,
      "name": "Rock_Ice"
    },
    {
      "x": -10,
      "y": 33,
      "z": -5,
      "name": "Rock_Ice"
    },
    {
      "x": -10,
      "y": 7,
      "z": -4,
      "name": "Soil_Pebbles"
    },
    {
      "x": -10,
      "y": 8,
      "z": -4,
      "name": "Plant_Seaweed_Winter_Tall"
    },
    {
      "x": -10,
      "y": 9,
      "z": -4,
      "name": "Plant_Seaweed_Winter_Tall",
      "filler": 1024
    },
    {
      "x": -10,
      "y": 30,
      "z": -4,
      "name": "Rock_Ice"
    },
    {
      "x": -10,
      "y": 31,
      "z": -4,
      "name": "Rock_Ice"
    },
    {
      "x": -10,
      "y": 32,
      "z": -4,
      "name": "Rock_Ice"
    },
    {
      "x": -10,
      "y": 33,
      "z": -4,
      "name": "Rock_Ice"
    },
    {
      "x": -10,
      "y": 34,
      "z": -4,
      "name": "Rock_Ice"
    },
    {
      "x": -10,
      "y": 35,
      "z": -4,
      "name": "Rock_Ice"
    },
    {
      "x": -10,
      "y": 36,
      "z": -4,
      "name": "Rock_Ice"
    },
    {
      "x": -10,
      "y": 7,
      "z": -3,
      "name": "Soil_Pebbles"
    },
    {
      "x": -10,
      "y": 8,
      "z": -3,
      "name": "Plant_Seaweed_Winter_Tall"
    },
    {
      "x": -10,
      "y": 9,
      "z": -3,
      "name": "Plant_Seaweed_Winter_Tall",
      "filler": 1024
    },
    {
      "x": -10,
      "y": 32,
      "z": -3,
      "name": "Rock_Ice"
    },
    {
      "x": -10,
      "y": 33,
      "z": -3,
      "name": "Rock_Ice"
    },
    {
      "x": -10,
      "y": 34,
      "z": -3,
      "name": "Rock_Ice"
    },
    {
      "x": -10,
      "y": 35,
      "z": -3,
      "name": "Rock_Ice"
    },
    {
      "x": -10,
      "y": 36,
      "z": -3,
      "name": "Rock_Ice"
    },
    {
      "x": -10,
      "y": 7,
      "z": -2,
      "name": "Soil_Pebbles"
    },
    {
      "x": -10,
      "y": 7,
      "z": -1,
      "name": "Soil_Pebbles"
    },
    {
      "x": -10,
      "y": 8,
      "z": 0,
      "name": "Soil_Pebbles"
    },
    {
      "x": -10,
      "y": 18,
      "z": 0,
      "name": "Rock_Ice"
    },
    {
      "x": -10,
      "y": 19,
      "z": 0,
      "name": "Rock_Ice"
    },
    {
      "x": -10,
      "y": 8,
      "z": 1,
      "name": "Soil_Pebbles"
    },
    {
      "x": -10,
      "y": 17,
      "z": 1,
      "name": "Rock_Ice"
    },
    {
      "x": -10,
      "y": 18,
      "z": 1,
      "name": "Rock_Ice"
    },
    {
      "x": -10,
      "y": 19,
      "z": 1,
      "name": "Rock_Ice"
    },
    {
      "x": -10,
      "y": 20,
      "z": 1,
      "name": "Rock_Ice"
    },
    {
      "x": -10,
      "y": 9,
      "z": 2,
      "name": "Soil_Pebbles"
    },
    {
      "x": -10,
      "y": 18,
      "z": 2,
      "name": "Rock_Ice"
    },
    {
      "x": -10,
      "y": 19,
      "z": 2,
      "name": "Rock_Ice"
    },
    {
      "x": -10,
      "y": 9,
      "z": 3,
      "name": "Soil_Pebbles"
    },
    {
      "x": -10,
      "y": 9,
      "z": 4,
      "name": "Soil_Pebbles"
    },
    {
      "x": -10,
      "y": 9,
      "z": 5,
      "name": "Soil_Pebbles"
    },
    {
      "x": -10,
      "y": 9,
      "z": 6,
      "name": "Soil_Pebbles"
    },
    {
      "x": -10,
      "y": 9,
      "z": 7,
      "name": "Soil_Pebbles"
    },
    {
      "x": -10,
      "y": 7,
      "z": 10,
      "name": "Rock_Ice"
    },
    {
      "x": -10,
      "y": 8,
      "z": 10,
      "name": "Rock_Ice"
    },
    {
      "x": -10,
      "y": 9,
      "z": 10,
      "name": "Rock_Ice"
    },
    {
      "x": -10,
      "y": 10,
      "z": 10,
      "name": "Rock_Ice"
    },
    {
      "x": -10,
      "y": 5,
      "z": 11,
      "name": "Rock_Ice"
    },
    {
      "x": -10,
      "y": 6,
      "z": 11,
      "name": "Rock_Ice"
    },
    {
      "x": -10,
      "y": 7,
      "z": 11,
      "name": "Rock_Ice"
    },
    {
      "x": -10,
      "y": 8,
      "z": 11,
      "name": "Rock_Ice"
    },
    {
      "x": -9,
      "y": 2,
      "z": -10,
      "name": "Rock_Ice"
    },
    {
      "x": -9,
      "y": 3,
      "z": -10,
      "name": "Rock_Ice"
    },
    {
      "x": -9,
      "y": 4,
      "z": -10,
      "name": "Rock_Ice"
    },
    {
      "x": -9,
      "y": 5,
      "z": -10,
      "name": "Rock_Ice"
    },
    {
      "x": -9,
      "y": 3,
      "z": -9,
      "name": "Rock_Ice"
    },
    {
      "x": -9,
      "y": 4,
      "z": -9,
      "name": "Rock_Ice"
    },
    {
      "x": -9,
      "y": 5,
      "z": -9,
      "name": "Rock_Ice"
    },
    {
      "x": -9,
      "y": 6,
      "z": -9,
      "name": "Rock_Ice"
    },
    {
      "x": -9,
      "y": 7,
      "z": -9,
      "name": "Rock_Ice"
    },
    {
      "x": -9,
      "y": 8,
      "z": -9,
      "name": "Rock_Ice"
    },
    {
      "x": -9,
      "y": 5,
      "z": -8,
      "name": "Rock_Ice"
    },
    {
      "x": -9,
      "y": 6,
      "z": -8,
      "name": "Rock_Ice"
    },
    {
      "x": -9,
      "y": 7,
      "z": -8,
      "name": "Rock_Ice"
    },
    {
      "x": -9,
      "y": 8,
      "z": -8,
      "name": "Rock_Ice"
    },
    {
      "x": -9,
      "y": 9,
      "z": -8,
      "name": "Rock_Ice"
    },
    {
      "x": -9,
      "y": 10,
      "z": -8,
      "name": "Rock_Ice"
    },
    {
      "x": -9,
      "y": 11,
      "z": -8,
      "name": "Rock_Ice"
    },
    {
      "x": -9,
      "y": 12,
      "z": -8,
      "name": "Rock_Ice"
    },
    {
      "x": -9,
      "y": 13,
      "z": -8,
      "name": "Rock_Ice"
    },
    {
      "x": -9,
      "y": 14,
      "z": -8,
      "name": "Rock_Ice"
    },
    {
      "x": -9,
      "y": 7,
      "z": -7,
      "name": "Soil_Pebbles"
    },
    {
      "x": -9,
      "y": 11,
      "z": -7,
      "name": "Rock_Ice"
    },
    {
      "x": -9,
      "y": 12,
      "z": -7,
      "name": "Rock_Ice"
    },
    {
      "x": -9,
      "y": 13,
      "z": -7,
      "name": "Rock_Ice"
    },
    {
      "x": -9,
      "y": 14,
      "z": -7,
      "name": "Rock_Ice"
    },
    {
      "x": -9,
      "y": 15,
      "z": -7,
      "name": "Rock_Ice"
    },
    {
      "x": -9,
      "y": 7,
      "z": -6,
      "name": "Soil_Pebbles"
    },
    {
      "x": -9,
      "y": 29,
      "z": -6,
      "name": "Rock_Ice"
    },
    {
      "x": -9,
      "y": 30,
      "z": -6,
      "name": "Rock_Ice"
    },
    {
      "x": -9,
      "y": 31,
      "z": -6,
      "name": "Rock_Ice"
    },
    {
      "x": -9,
      "y": 32,
      "z": -6,
      "name": "Rock_Ice"
    },
    {
      "x": -9,
      "y": 33,
      "z": -6,
      "name": "Rock_Ice"
    },
    {
      "x": -9,
      "y": 34,
      "z": -6,
      "name": "Rock_Ice"
    },
    {
      "x": -9,
      "y": 7,
      "z": -5,
      "name": "Soil_Pebbles"
    },
    {
      "x": -9,
      "y": 27,
      "z": -5,
      "name": "Rock_Ice"
    },
    {
      "x": -9,
      "y": 28,
      "z": -5,
      "name": "Rock_Ice"
    },
    {
      "x": -9,
      "y": 29,
      "z": -5,
      "name": "Rock_Ice"
    },
    {
      "x": -9,
      "y": 30,
      "z": -5,
      "name": "Rock_Ice"
    },
    {
      "x": -9,
      "y": 31,
      "z": -5,
      "name": "Rock_Ice"
    },
    {
      "x": -9,
      "y": 32,
      "z": -5,
      "name": "Rock_Ice"
    },
    {
      "x": -9,
      "y": 33,
      "z": -5,
      "name": "Rock_Ice"
    },
    {
      "x": -9,
      "y": 34,
      "z": -5,
      "name": "Rock_Ice"
    },
    {
      "x": -9,
      "y": 7,
      "z": -4,
      "name": "Soil_Pebbles"
    },
    {
      "x": -9,
      "y": 8,
      "z": -4,
      "name": "Plant_Seaweed_Winter_Tall"
    },
    {
      "x": -9,
      "y": 9,
      "z": -4,
      "name": "Plant_Seaweed_Winter_Tall",
      "filler": 1024
    },
    {
      "x": -9,
      "y": 27,
      "z": -4,
      "name": "Rock_Ice"
    },
    {
      "x": -9,
      "y": 28,
      "z": -4,
      "name": "Rock_Ice"
    },
    {
      "x": -9,
      "y": 29,
      "z": -4,
      "name": "Rock_Ice"
    },
    {
      "x": -9,
      "y": 30,
      "z": -4,
      "name": "Rock_Ice"
    },
    {
      "x": -9,
      "y": 31,
      "z": -4,
      "name": "Rock_Ice"
    },
    {
      "x": -9,
      "y": 32,
      "z": -4,
      "name": "Rock_Ice"
    },
    {
      "x": -9,
      "y": 33,
      "z": -4,
      "name": "Rock_Ice"
    },
    {
      "x": -9,
      "y": 34,
      "z": -4,
      "name": "Rock_Ice"
    },
    {
      "x": -9,
      "y": 35,
      "z": -4,
      "name": "Rock_Ice"
    },
    {
      "x": -9,
      "y": 7,
      "z": -3,
      "name": "Soil_Pebbles"
    },
    {
      "x": -9,
      "y": 8,
      "z": -3,
      "name": "Plant_Seaweed_Winter_Tall"
    },
    {
      "x": -9,
      "y": 9,
      "z": -3,
      "name": "Plant_Seaweed_Winter_Tall",
      "filler": 1024
    },
    {
      "x": -9,
      "y": 31,
      "z": -3,
      "name": "Rock_Ice"
    },
    {
      "x": -9,
      "y": 32,
      "z": -3,
      "name": "Rock_Ice"
    },
    {
      "x": -9,
      "y": 33,
      "z": -3,
      "name": "Rock_Ice"
    },
    {
      "x": -9,
      "y": 34,
      "z": -3,
      "name": "Rock_Ice"
    },
    {
      "x": -9,
      "y": 35,
      "z": -3,
      "name": "Rock_Ice"
    },
    {
      "x": -9,
      "y": 36,
      "z": -3,
      "name": "Rock_Ice"
    },
    {
      "x": -9,
      "y": 7,
      "z": -2,
      "name": "Soil_Pebbles"
    },
    {
      "x": -9,
      "y": 8,
      "z": -2,
      "name": "Plant_Seaweed_Winter_Tall"
    },
    {
      "x": -9,
      "y": 9,
      "z": -2,
      "name": "Plant_Seaweed_Winter_Tall",
      "filler": 1024
    },
    {
      "x": -9,
      "y": 7,
      "z": -1,
      "name": "Soil_Pebbles"
    },
    {
      "x": -9,
      "y": 7,
      "z": 0,
      "name": "Soil_Pebbles"
    },
    {
      "x": -9,
      "y": 19,
      "z": 0,
      "name": "Rock_Ice"
    },
    {
      "x": -9,
      "y": 8,
      "z": 1,
      "name": "Soil_Pebbles"
    },
    {
      "x": -9,
      "y": 18,
      "z": 1,
      "name": "Rock_Ice"
    },
    {
      "x": -9,
      "y": 19,
      "z": 1,
      "name": "Rock_Ice"
    },
    {
      "x": -9,
      "y": 20,
      "z": 1,
      "name": "Rock_Ice"
    },
    {
      "x": -9,
      "y": 8,
      "z": 2,
      "name": "Soil_Pebbles"
    },
    {
      "x": -9,
      "y": 8,
      "z": 3,
      "name": "Soil_Pebbles"
    },
    {
      "x": -9,
      "y": 8,
      "z": 4,
      "name": "Soil_Pebbles"
    },
    {
      "x": -9,
      "y": 9,
      "z": 4,
      "name": "Plant_Seaweed_Winter_Tall"
    },
    {
      "x": -9,
      "y": 10,
      "z": 4,
      "name": "Plant_Seaweed_Winter_Tall",
      "filler": 1024
    },
    {
      "x": -9,
      "y": 8,
      "z": 5,
      "name": "Soil_Pebbles"
    },
    {
      "x": -9,
      "y": 9,
      "z": 5,
      "name": "Plant_Seaweed_Winter_Tall"
    },
    {
      "x": -9,
      "y": 10,
      "z": 5,
      "name": "Plant_Seaweed_Winter_Tall",
      "filler": 1024
    },
    {
      "x": -9,
      "y": 8,
      "z": 6,
      "name": "Soil_Pebbles"
    },
    {
      "x": -9,
      "y": 9,
      "z": 7,
      "name": "Soil_Pebbles"
    },
    {
      "x": -9,
      "y": 9,
      "z": 8,
      "name": "Soil_Pebbles"
    },
    {
      "x": -9,
      "y": 8,
      "z": 9,
      "name": "Rock_Ice"
    },
    {
      "x": -9,
      "y": 9,
      "z": 9,
      "name": "Rock_Ice"
    },
    {
      "x": -9,
      "y": 10,
      "z": 9,
      "name": "Rock_Ice"
    },
    {
      "x": -9,
      "y": 11,
      "z": 9,
      "name": "Rock_Ice"
    },
    {
      "x": -9,
      "y": 12,
      "z": 9,
      "name": "Rock_Ice"
    },
    {
      "x": -9,
      "y": 6,
      "z": 10,
      "name": "Rock_Ice"
    },
    {
      "x": -9,
      "y": 7,
      "z": 10,
      "name": "Rock_Ice"
    },
    {
      "x": -9,
      "y": 8,
      "z": 10,
      "name": "Rock_Ice"
    },
    {
      "x": -9,
      "y": 9,
      "z": 10,
      "name": "Rock_Ice"
    },
    {
      "x": -9,
      "y": 10,
      "z": 10,
      "name": "Rock_Ice"
    },
    {
      "x": -9,
      "y": 11,
      "z": 10,
      "name": "Rock_Ice"
    },
    {
      "x": -9,
      "y": 12,
      "z": 10,
      "name": "Rock_Ice"
    },
    {
      "x": -9,
      "y": 6,
      "z": 11,
      "name": "Rock_Ice"
    },
    {
      "x": -9,
      "y": 7,
      "z": 11,
      "name": "Rock_Ice"
    },
    {
      "x": -9,
      "y": 8,
      "z": 11,
      "name": "Rock_Ice"
    },
    {
      "x": -9,
      "y": 9,
      "z": 11,
      "name": "Rock_Ice"
    },
    {
      "x": -9,
      "y": 10,
      "z": 11,
      "name": "Rock_Ice"
    },
    {
      "x": -9,
      "y": 11,
      "z": 11,
      "name": "Rock_Ice"
    },
    {
      "x": -8,
      "y": 9,
      "z": -11,
      "name": "Soil_Pebbles"
    },
    {
      "x": -8,
      "y": 4,
      "z": -10,
      "name": "Rock_Ice"
    },
    {
      "x": -8,
      "y": 5,
      "z": -10,
      "name": "Rock_Ice"
    },
    {
      "x": -8,
      "y": 6,
      "z": -10,
      "name": "Rock_Ice"
    },
    {
      "x": -8,
      "y": 7,
      "z": -10,
      "name": "Rock_Ice"
    },
    {
      "x": -8,
      "y": 8,
      "z": -10,
      "name": "Rock_Ice"
    },
    {
      "x": -8,
      "y": 9,
      "z": -10,
      "name": "Rock_Ice"
    },
    {
      "x": -8,
      "y": 3,
      "z": -9,
      "name": "Rock_Ice"
    },
    {
      "x": -8,
      "y": 4,
      "z": -9,
      "name": "Rock_Ice"
    },
    {
      "x": -8,
      "y": 5,
      "z": -9,
      "name": "Rock_Ice"
    },
    {
      "x": -8,
      "y": 6,
      "z": -9,
      "name": "Rock_Ice"
    },
    {
      "x": -8,
      "y": 7,
      "z": -9,
      "name": "Rock_Ice"
    },
    {
      "x": -8,
      "y": 8,
      "z": -9,
      "name": "Rock_Ice"
    },
    {
      "x": -8,
      "y": 9,
      "z": -9,
      "name": "Rock_Ice"
    },
    {
      "x": -8,
      "y": 10,
      "z": -9,
      "name": "Rock_Ice"
    },
    {
      "x": -8,
      "y": 11,
      "z": -9,
      "name": "Rock_Ice"
    },
    {
      "x": -8,
      "y": 12,
      "z": -9,
      "name": "Rock_Ice"
    },
    {
      "x": -8,
      "y": 4,
      "z": -8,
      "name": "Rock_Ice"
    },
    {
      "x": -8,
      "y": 5,
      "z": -8,
      "name": "Rock_Ice"
    },
    {
      "x": -8,
      "y": 6,
      "z": -8,
      "name": "Rock_Ice"
    },
    {
      "x": -8,
      "y": 7,
      "z": -8,
      "name": "Rock_Ice"
    },
    {
      "x": -8,
      "y": 8,
      "z": -8,
      "name": "Rock_Ice"
    },
    {
      "x": -8,
      "y": 9,
      "z": -8,
      "name": "Rock_Ice"
    },
    {
      "x": -8,
      "y": 10,
      "z": -8,
      "name": "Rock_Ice"
    },
    {
      "x": -8,
      "y": 11,
      "z": -8,
      "name": "Rock_Ice"
    },
    {
      "x": -8,
      "y": 12,
      "z": -8,
      "name": "Rock_Ice"
    },
    {
      "x": -8,
      "y": 6,
      "z": -7,
      "name": "Rock_Ice"
    },
    {
      "x": -8,
      "y": 7,
      "z": -7,
      "name": "Rock_Ice"
    },
    {
      "x": -8,
      "y": 8,
      "z": -7,
      "name": "Rock_Ice"
    },
    {
      "x": -8,
      "y": 9,
      "z": -7,
      "name": "Rock_Ice"
    },
    {
      "x": -8,
      "y": 10,
      "z": -7,
      "name": "Rock_Ice"
    },
    {
      "x": -8,
      "y": 11,
      "z": -7,
      "name": "Rock_Ice"
    },
    {
      "x": -8,
      "y": 12,
      "z": -7,
      "name": "Rock_Ice"
    },
    {
      "x": -8,
      "y": 13,
      "z": -7,
      "name": "Rock_Ice"
    },
    {
      "x": -8,
      "y": 7,
      "z": -6,
      "name": "Soil_Pebbles"
    },
    {
      "x": -8,
      "y": 25,
      "z": -6,
      "name": "Rock_Ice"
    },
    {
      "x": -8,
      "y": 26,
      "z": -6,
      "name": "Rock_Ice"
    },
    {
      "x": -8,
      "y": 27,
      "z": -6,
      "name": "Rock_Ice"
    },
    {
      "x": -8,
      "y": 28,
      "z": -6,
      "name": "Rock_Ice"
    },
    {
      "x": -8,
      "y": 29,
      "z": -6,
      "name": "Rock_Ice"
    },
    {
      "x": -8,
      "y": 30,
      "z": -6,
      "name": "Rock_Ice"
    },
    {
      "x": -8,
      "y": 31,
      "z": -6,
      "name": "Rock_Ice"
    },
    {
      "x": -8,
      "y": 32,
      "z": -6,
      "name": "Rock_Ice"
    },
    {
      "x": -8,
      "y": 7,
      "z": -5,
      "name": "Soil_Pebbles"
    },
    {
      "x": -8,
      "y": 27,
      "z": -5,
      "name": "Rock_Ice"
    },
    {
      "x": -8,
      "y": 28,
      "z": -5,
      "name": "Rock_Ice"
    },
    {
      "x": -8,
      "y": 29,
      "z": -5,
      "name": "Rock_Ice"
    },
    {
      "x": -8,
      "y": 30,
      "z": -5,
      "name": "Rock_Ice"
    },
    {
      "x": -8,
      "y": 31,
      "z": -5,
      "name": "Rock_Ice"
    },
    {
      "x": -8,
      "y": 32,
      "z": -5,
      "name": "Rock_Ice"
    },
    {
      "x": -8,
      "y": 33,
      "z": -5,
      "name": "Rock_Ice"
    },
    {
      "x": -8,
      "y": 6,
      "z": -4,
      "name": "Soil_Pebbles"
    },
    {
      "x": -8,
      "y": 26,
      "z": -4,
      "name": "Rock_Ice"
    },
    {
      "x": -8,
      "y": 27,
      "z": -4,
      "name": "Rock_Ice"
    },
    {
      "x": -8,
      "y": 28,
      "z": -4,
      "name": "Rock_Ice"
    },
    {
      "x": -8,
      "y": 29,
      "z": -4,
      "name": "Rock_Ice"
    },
    {
      "x": -8,
      "y": 30,
      "z": -4,
      "name": "Rock_Ice"
    },
    {
      "x": -8,
      "y": 31,
      "z": -4,
      "name": "Rock_Ice"
    },
    {
      "x": -8,
      "y": 32,
      "z": -4,
      "name": "Rock_Ice"
    },
    {
      "x": -8,
      "y": 33,
      "z": -4,
      "name": "Rock_Ice"
    },
    {
      "x": -8,
      "y": 34,
      "z": -4,
      "name": "Rock_Ice"
    },
    {
      "x": -8,
      "y": 7,
      "z": -3,
      "name": "Soil_Pebbles"
    },
    {
      "x": -8,
      "y": 27,
      "z": -3,
      "name": "Rock_Ice"
    },
    {
      "x": -8,
      "y": 28,
      "z": -3,
      "name": "Rock_Ice"
    },
    {
      "x": -8,
      "y": 29,
      "z": -3,
      "name": "Rock_Ice"
    },
    {
      "x": -8,
      "y": 30,
      "z": -3,
      "name": "Rock_Ice"
    },
    {
      "x": -8,
      "y": 31,
      "z": -3,
      "name": "Rock_Ice"
    },
    {
      "x": -8,
      "y": 32,
      "z": -3,
      "name": "Rock_Ice"
    },
    {
      "x": -8,
      "y": 7,
      "z": -2,
      "name": "Soil_Pebbles"
    },
    {
      "x": -8,
      "y": 8,
      "z": -2,
      "name": "Plant_Seaweed_Winter_Tall"
    },
    {
      "x": -8,
      "y": 9,
      "z": -2,
      "name": "Plant_Seaweed_Winter_Tall",
      "filler": 1024
    },
    {
      "x": -8,
      "y": 7,
      "z": -1,
      "name": "Soil_Pebbles"
    },
    {
      "x": -8,
      "y": 8,
      "z": -1,
      "name": "Plant_Seaweed_Winter_Short"
    },
    {
      "x": -8,
      "y": 7,
      "z": 0,
      "name": "Soil_Pebbles"
    },
    {
      "x": -8,
      "y": 8,
      "z": 1,
      "name": "Soil_Pebbles"
    },
    {
      "x": -8,
      "y": 19,
      "z": 1,
      "name": "Rock_Ice"
    },
    {
      "x": -8,
      "y": 20,
      "z": 1,
      "name": "Rock_Ice"
    },
    {
      "x": -8,
      "y": 8,
      "z": 2,
      "name": "Soil_Pebbles"
    },
    {
      "x": -8,
      "y": 8,
      "z": 3,
      "name": "Soil_Pebbles"
    },
    {
      "x": -8,
      "y": 8,
      "z": 4,
      "name": "Soil_Pebbles"
    },
    {
      "x": -8,
      "y": 9,
      "z": 4,
      "name": "Plant_Seaweed_Winter_Tall"
    },
    {
      "x": -8,
      "y": 10,
      "z": 4,
      "name": "Plant_Seaweed_Winter_Tall",
      "filler": 1024
    },
    {
      "x": -8,
      "y": 8,
      "z": 5,
      "name": "Soil_Pebbles"
    },
    {
      "x": -8,
      "y": 9,
      "z": 5,
      "name": "Plant_Seaweed_Winter_Tall"
    },
    {
      "x": -8,
      "y": 10,
      "z": 5,
      "name": "Plant_Seaweed_Winter_Tall",
      "filler": 1024
    },
    {
      "x": -8,
      "y": 8,
      "z": 6,
      "name": "Soil_Pebbles"
    },
    {
      "x": -8,
      "y": 8,
      "z": 7,
      "name": "Soil_Pebbles"
    },
    {
      "x": -8,
      "y": 9,
      "z": 8,
      "name": "Rock_Ice"
    },
    {
      "x": -8,
      "y": 10,
      "z": 8,
      "name": "Rock_Ice"
    },
    {
      "x": -8,
      "y": 11,
      "z": 8,
      "name": "Rock_Ice"
    },
    {
      "x": -8,
      "y": 12,
      "z": 8,
      "name": "Rock_Ice"
    },
    {
      "x": -8,
      "y": 13,
      "z": 8,
      "name": "Rock_Ice"
    },
    {
      "x": -8,
      "y": 8,
      "z": 9,
      "name": "Rock_Ice"
    },
    {
      "x": -8,
      "y": 9,
      "z": 9,
      "name": "Rock_Ice"
    },
    {
      "x": -8,
      "y": 10,
      "z": 9,
      "name": "Rock_Ice"
    },
    {
      "x": -8,
      "y": 11,
      "z": 9,
      "name": "Rock_Ice"
    },
    {
      "x": -8,
      "y": 12,
      "z": 9,
      "name": "Rock_Ice"
    },
    {
      "x": -8,
      "y": 13,
      "z": 9,
      "name": "Rock_Ice"
    },
    {
      "x": -8,
      "y": 14,
      "z": 9,
      "name": "Rock_Ice"
    },
    {
      "x": -8,
      "y": 8,
      "z": 10,
      "name": "Rock_Ice"
    },
    {
      "x": -8,
      "y": 9,
      "z": 10,
      "name": "Rock_Ice"
    },
    {
      "x": -8,
      "y": 10,
      "z": 10,
      "name": "Rock_Ice"
    },
    {
      "x": -8,
      "y": 11,
      "z": 10,
      "name": "Rock_Ice"
    },
    {
      "x": -8,
      "y": 12,
      "z": 10,
      "name": "Rock_Ice"
    },
    {
      "x": -8,
      "y": 8,
      "z": 11,
      "name": "Rock_Ice"
    },
    {
      "x": -8,
      "y": 9,
      "z": 11,
      "name": "Rock_Ice"
    },
    {
      "x": -8,
      "y": 10,
      "z": 11,
      "name": "Rock_Ice"
    },
    {
      "x": -8,
      "y": 11,
      "z": 11,
      "name": "Rock_Ice"
    },
    {
      "x": -8,
      "y": 16,
      "z": 12,
      "name": "Soil_Pebbles"
    },
    {
      "x": -8,
      "y": 17,
      "z": 12,
      "name": "Soil_Pebbles"
    },
    {
      "x": -8,
      "y": 17,
      "z": 13,
      "name": "Soil_Pebbles"
    },
    {
      "x": -7,
      "y": 9,
      "z": -12,
      "name": "Soil_Pebbles"
    },
    {
      "x": -7,
      "y": 8,
      "z": -11,
      "name": "Soil_Pebbles"
    },
    {
      "x": -7,
      "y": 3,
      "z": -10,
      "name": "Rock_Ice"
    },
    {
      "x": -7,
      "y": 4,
      "z": -10,
      "name": "Rock_Ice"
    },
    {
      "x": -7,
      "y": 5,
      "z": -10,
      "name": "Rock_Ice"
    },
    {
      "x": -7,
      "y": 6,
      "z": -10,
      "name": "Rock_Ice"
    },
    {
      "x": -7,
      "y": 7,
      "z": -10,
      "name": "Rock_Ice"
    },
    {
      "x": -7,
      "y": 8,
      "z": -10,
      "name": "Rock_Ice"
    },
    {
      "x": -7,
      "y": 9,
      "z": -10,
      "name": "Rock_Ice"
    },
    {
      "x": -7,
      "y": 4,
      "z": -9,
      "name": "Rock_Ice"
    },
    {
      "x": -7,
      "y": 5,
      "z": -9,
      "name": "Rock_Ice"
    },
    {
      "x": -7,
      "y": 6,
      "z": -9,
      "name": "Rock_Ice"
    },
    {
      "x": -7,
      "y": 7,
      "z": -9,
      "name": "Rock_Ice"
    },
    {
      "x": -7,
      "y": 8,
      "z": -9,
      "name": "Rock_Ice"
    },
    {
      "x": -7,
      "y": 9,
      "z": -9,
      "name": "Rock_Ice"
    },
    {
      "x": -7,
      "y": 10,
      "z": -9,
      "name": "Rock_Ice"
    },
    {
      "x": -7,
      "y": 11,
      "z": -9,
      "name": "Rock_Ice"
    },
    {
      "x": -7,
      "y": 12,
      "z": -9,
      "name": "Rock_Ice"
    },
    {
      "x": -7,
      "y": 5,
      "z": -8,
      "name": "Rock_Ice"
    },
    {
      "x": -7,
      "y": 6,
      "z": -8,
      "name": "Rock_Ice"
    },
    {
      "x": -7,
      "y": 7,
      "z": -8,
      "name": "Rock_Ice"
    },
    {
      "x": -7,
      "y": 8,
      "z": -8,
      "name": "Rock_Ice"
    },
    {
      "x": -7,
      "y": 9,
      "z": -8,
      "name": "Rock_Ice"
    },
    {
      "x": -7,
      "y": 10,
      "z": -8,
      "name": "Rock_Ice"
    },
    {
      "x": -7,
      "y": 11,
      "z": -8,
      "name": "Rock_Ice"
    },
    {
      "x": -7,
      "y": 6,
      "z": -7,
      "name": "Rock_Ice"
    },
    {
      "x": -7,
      "y": 7,
      "z": -7,
      "name": "Rock_Ice"
    },
    {
      "x": -7,
      "y": 8,
      "z": -7,
      "name": "Rock_Ice"
    },
    {
      "x": -7,
      "y": 9,
      "z": -7,
      "name": "Rock_Ice"
    },
    {
      "x": -7,
      "y": 10,
      "z": -7,
      "name": "Rock_Ice"
    },
    {
      "x": -7,
      "y": 11,
      "z": -7,
      "name": "Rock_Ice"
    },
    {
      "x": -7,
      "y": 7,
      "z": -6,
      "name": "Soil_Pebbles"
    },
    {
      "x": -7,
      "y": 9,
      "z": -6,
      "name": "Rock_Ice"
    },
    {
      "x": -7,
      "y": 10,
      "z": -6,
      "name": "Rock_Ice"
    },
    {
      "x": -7,
      "y": 11,
      "z": -6,
      "name": "Rock_Ice"
    },
    {
      "x": -7,
      "y": 12,
      "z": -6,
      "name": "Rock_Ice"
    },
    {
      "x": -7,
      "y": 24,
      "z": -6,
      "name": "Rock_Ice"
    },
    {
      "x": -7,
      "y": 25,
      "z": -6,
      "name": "Rock_Ice"
    },
    {
      "x": -7,
      "y": 26,
      "z": -6,
      "name": "Rock_Ice"
    },
    {
      "x": -7,
      "y": 27,
      "z": -6,
      "name": "Rock_Ice"
    },
    {
      "x": -7,
      "y": 28,
      "z": -6,
      "name": "Rock_Ice"
    },
    {
      "x": -7,
      "y": 7,
      "z": -5,
      "name": "Soil_Pebbles"
    },
    {
      "x": -7,
      "y": 26,
      "z": -5,
      "name": "Rock_Ice"
    },
    {
      "x": -7,
      "y": 27,
      "z": -5,
      "name": "Rock_Ice"
    },
    {
      "x": -7,
      "y": 28,
      "z": -5,
      "name": "Rock_Ice"
    },
    {
      "x": -7,
      "y": 29,
      "z": -5,
      "name": "Rock_Ice"
    },
    {
      "x": -7,
      "y": 30,
      "z": -5,
      "name": "Rock_Ice"
    },
    {
      "x": -7,
      "y": 31,
      "z": -5,
      "name": "Rock_Ice"
    },
    {
      "x": -7,
      "y": 6,
      "z": -4,
      "name": "Soil_Pebbles"
    },
    {
      "x": -7,
      "y": 26,
      "z": -4,
      "name": "Rock_Ice"
    },
    {
      "x": -7,
      "y": 27,
      "z": -4,
      "name": "Rock_Ice"
    },
    {
      "x": -7,
      "y": 28,
      "z": -4,
      "name": "Rock_Ice"
    },
    {
      "x": -7,
      "y": 29,
      "z": -4,
      "name": "Rock_Ice"
    },
    {
      "x": -7,
      "y": 30,
      "z": -4,
      "name": "Rock_Ice"
    },
    {
      "x": -7,
      "y": 31,
      "z": -4,
      "name": "Rock_Ice"
    },
    {
      "x": -7,
      "y": 6,
      "z": -3,
      "name": "Soil_Pebbles"
    },
    {
      "x": -7,
      "y": 25,
      "z": -3,
      "name": "Rock_Ice"
    },
    {
      "x": -7,
      "y": 26,
      "z": -3,
      "name": "Rock_Ice"
    },
    {
      "x": -7,
      "y": 27,
      "z": -3,
      "name": "Rock_Ice"
    },
    {
      "x": -7,
      "y": 28,
      "z": -3,
      "name": "Rock_Ice"
    },
    {
      "x": -7,
      "y": 29,
      "z": -3,
      "name": "Rock_Ice"
    },
    {
      "x": -7,
      "y": 6,
      "z": -2,
      "name": "Soil_Pebbles"
    },
    {
      "x": -7,
      "y": 7,
      "z": -1,
      "name": "Soil_Pebbles"
    },
    {
      "x": -7,
      "y": 8,
      "z": -1,
      "name": "Plant_Seaweed_Winter_Short"
    },
    {
      "x": -7,
      "y": 7,
      "z": 0,
      "name": "Soil_Pebbles"
    },
    {
      "x": -7,
      "y": 8,
      "z": 0,
      "name": "Plant_Seaweed_Winter_Short"
    },
    {
      "x": -7,
      "y": 7,
      "z": 1,
      "name": "Soil_Pebbles"
    },
    {
      "x": -7,
      "y": 8,
      "z": 2,
      "name": "Soil_Pebbles"
    },
    {
      "x": -7,
      "y": 9,
      "z": 2,
      "name": "Plant_Seaweed_Winter_Tall"
    },
    {
      "x": -7,
      "y": 10,
      "z": 2,
      "name": "Plant_Seaweed_Winter_Tall",
      "filler": 1024
    },
    {
      "x": -7,
      "y": 8,
      "z": 3,
      "name": "Soil_Pebbles"
    },
    {
      "x": -7,
      "y": 9,
      "z": 3,
      "name": "Plant_Seaweed_Winter_Tall"
    },
    {
      "x": -7,
      "y": 10,
      "z": 3,
      "name": "Plant_Seaweed_Winter_Tall",
      "filler": 1024
    },
    {
      "x": -7,
      "y": 7,
      "z": 4,
      "name": "Soil_Pebbles"
    },
    {
      "x": -7,
      "y": 8,
      "z": 4,
      "name": "Plant_Seaweed_Winter_Tall"
    },
    {
      "x": -7,
      "y": 9,
      "z": 4,
      "name": "Plant_Seaweed_Winter_Tall",
      "filler": 1024
    },
    {
      "x": -7,
      "y": 7,
      "z": 5,
      "name": "Soil_Pebbles"
    },
    {
      "x": -7,
      "y": 7,
      "z": 6,
      "name": "Soil_Pebbles"
    },
    {
      "x": -7,
      "y": 7,
      "z": 7,
      "name": "Soil_Pebbles"
    },
    {
      "x": -7,
      "y": 8,
      "z": 8,
      "name": "Soil_Pebbles"
    },
    {
      "x": -7,
      "y": 11,
      "z": 8,
      "name": "Rock_Ice"
    },
    {
      "x": -7,
      "y": 12,
      "z": 8,
      "name": "Rock_Ice"
    },
    {
      "x": -7,
      "y": 13,
      "z": 8,
      "name": "Rock_Ice"
    },
    {
      "x": -7,
      "y": 14,
      "z": 8,
      "name": "Rock_Ice"
    },
    {
      "x": -7,
      "y": 15,
      "z": 8,
      "name": "Rock_Ice"
    },
    {
      "x": -7,
      "y": 8,
      "z": 9,
      "name": "Soil_Pebbles"
    },
    {
      "x": -7,
      "y": 10,
      "z": 9,
      "name": "Rock_Ice"
    },
    {
      "x": -7,
      "y": 11,
      "z": 9,
      "name": "Rock_Ice"
    },
    {
      "x": -7,
      "y": 12,
      "z": 9,
      "name": "Rock_Ice"
    },
    {
      "x": -7,
      "y": 13,
      "z": 9,
      "name": "Rock_Ice"
    },
    {
      "x": -7,
      "y": 14,
      "z": 9,
      "name": "Rock_Ice"
    },
    {
      "x": -7,
      "y": 9,
      "z": 10,
      "name": "Rock_Ice"
    },
    {
      "x": -7,
      "y": 10,
      "z": 10,
      "name": "Rock_Ice"
    },
    {
      "x": -7,
      "y": 11,
      "z": 10,
      "name": "Rock_Ice"
    },
    {
      "x": -7,
      "y": 12,
      "z": 10,
      "name": "Rock_Ice"
    },
    {
      "x": -7,
      "y": 13,
      "z": 10,
      "name": "Rock_Ice"
    },
    {
      "x": -7,
      "y": 15,
      "z": 12,
      "name": "Soil_Pebbles"
    },
    {
      "x": -7,
      "y": 16,
      "z": 12,
      "name": "Soil_Pebbles"
    },
    {
      "x": -7,
      "y": 17,
      "z": 13,
      "name": "Soil_Pebbles"
    },
    {
      "x": -7,
      "y": 17,
      "z": 14,
      "name": "Soil_Pebbles"
    },
    {
      "x": -7,
      "y": 18,
      "z": 15,
      "name": "Soil_Pebbles"
    },
    {
      "x": -7,
      "y": 18,
      "z": 16,
      "name": "Soil_Pebbles"
    },
    {
      "x": -6,
      "y": 9,
      "z": -12,
      "name": "Soil_Pebbles"
    },
    {
      "x": -6,
      "y": 8,
      "z": -11,
      "name": "Soil_Pebbles"
    },
    {
      "x": -6,
      "y": 3,
      "z": -10,
      "name": "Rock_Ice"
    },
    {
      "x": -6,
      "y": 4,
      "z": -10,
      "name": "Rock_Ice"
    },
    {
      "x": -6,
      "y": 5,
      "z": -10,
      "name": "Rock_Ice"
    },
    {
      "x": -6,
      "y": 6,
      "z": -10,
      "name": "Rock_Ice"
    },
    {
      "x": -6,
      "y": 7,
      "z": -10,
      "name": "Rock_Ice"
    },
    {
      "x": -6,
      "y": 8,
      "z": -10,
      "name": "Soil_Pebbles"
    },
    {
      "x": -6,
      "y": 3,
      "z": -9,
      "name": "Rock_Ice"
    },
    {
      "x": -6,
      "y": 4,
      "z": -9,
      "name": "Rock_Ice"
    },
    {
      "x": -6,
      "y": 5,
      "z": -9,
      "name": "Rock_Ice"
    },
    {
      "x": -6,
      "y": 6,
      "z": -9,
      "name": "Rock_Ice"
    },
    {
      "x": -6,
      "y": 7,
      "z": -9,
      "name": "Rock_Ice"
    },
    {
      "x": -6,
      "y": 8,
      "z": -9,
      "name": "Rock_Ice"
    },
    {
      "x": -6,
      "y": 6,
      "z": -8,
      "name": "Rock_Ice"
    },
    {
      "x": -6,
      "y": 7,
      "z": -8,
      "name": "Rock_Ice"
    },
    {
      "x": -6,
      "y": 8,
      "z": -8,
      "name": "Rock_Ice"
    },
    {
      "x": -6,
      "y": 9,
      "z": -8,
      "name": "Rock_Ice"
    },
    {
      "x": -6,
      "y": 10,
      "z": -8,
      "name": "Rock_Ice"
    },
    {
      "x": -6,
      "y": 8,
      "z": -7,
      "name": "Rock_Ice"
    },
    {
      "x": -6,
      "y": 9,
      "z": -7,
      "name": "Rock_Ice"
    },
    {
      "x": -6,
      "y": 10,
      "z": -7,
      "name": "Rock_Ice"
    },
    {
      "x": -6,
      "y": 11,
      "z": -7,
      "name": "Rock_Ice"
    },
    {
      "x": -6,
      "y": 12,
      "z": -7,
      "name": "Rock_Ice"
    },
    {
      "x": -6,
      "y": 7,
      "z": -6,
      "name": "Soil_Pebbles"
    },
    {
      "x": -6,
      "y": 10,
      "z": -6,
      "name": "Rock_Ice"
    },
    {
      "x": -6,
      "y": 11,
      "z": -6,
      "name": "Rock_Ice"
    },
    {
      "x": -6,
      "y": 12,
      "z": -6,
      "name": "Rock_Ice"
    },
    {
      "x": -6,
      "y": 13,
      "z": -6,
      "name": "Rock_Ice"
    },
    {
      "x": -6,
      "y": 6,
      "z": -5,
      "name": "Soil_Pebbles"
    },
    {
      "x": -6,
      "y": 6,
      "z": -4,
      "name": "Soil_Pebbles"
    },
    {
      "x": -6,
      "y": 25,
      "z": -4,
      "name": "Rock_Ice"
    },
    {
      "x": -6,
      "y": 26,
      "z": -4,
      "name": "Rock_Ice"
    },
    {
      "x": -6,
      "y": 27,
      "z": -4,
      "name": "Rock_Ice"
    },
    {
      "x": -6,
      "y": 28,
      "z": -4,
      "name": "Rock_Ice"
    },
    {
      "x": -6,
      "y": 6,
      "z": -3,
      "name": "Soil_Pebbles"
    },
    {
      "x": -6,
      "y": 24,
      "z": -3,
      "name": "Rock_Ice"
    },
    {
      "x": -6,
      "y": 25,
      "z": -3,
      "name": "Rock_Ice"
    },
    {
      "x": -6,
      "y": 26,
      "z": -3,
      "name": "Rock_Ice"
    },
    {
      "x": -6,
      "y": 27,
      "z": -3,
      "name": "Rock_Ice"
    },
    {
      "x": -6,
      "y": 6,
      "z": -2,
      "name": "Soil_Pebbles"
    },
    {
      "x": -6,
      "y": 7,
      "z": -1,
      "name": "Soil_Pebbles"
    },
    {
      "x": -6,
      "y": 7,
      "z": 0,
      "name": "Soil_Pebbles"
    },
    {
      "x": -6,
      "y": 7,
      "z": 1,
      "name": "Soil_Pebbles"
    },
    {
      "x": -6,
      "y": 7,
      "z": 2,
      "name": "Soil_Pebbles"
    },
    {
      "x": -6,
      "y": 8,
      "z": 2,
      "name": "Plant_Seaweed_Winter_Tall"
    },
    {
      "x": -6,
      "y": 9,
      "z": 2,
      "name": "Plant_Seaweed_Winter_Tall",
      "filler": 1024
    },
    {
      "x": -6,
      "y": 7,
      "z": 3,
      "name": "Soil_Pebbles"
    },
    {
      "x": -6,
      "y": 8,
      "z": 3,
      "name": "Plant_Seaweed_Winter_Tall"
    },
    {
      "x": -6,
      "y": 9,
      "z": 3,
      "name": "Plant_Seaweed_Winter_Tall",
      "filler": 1024
    },
    {
      "x": -6,
      "y": 7,
      "z": 4,
      "name": "Soil_Pebbles"
    },
    {
      "x": -6,
      "y": 8,
      "z": 4,
      "name": "Plant_Seaweed_Winter_Tall"
    },
    {
      "x": -6,
      "y": 9,
      "z": 4,
      "name": "Plant_Seaweed_Winter_Tall",
      "filler": 1024
    },
    {
      "x": -6,
      "y": 7,
      "z": 5,
      "name": "Soil_Pebbles"
    },
    {
      "x": -6,
      "y": 7,
      "z": 6,
      "name": "Soil_Pebbles"
    },
    {
      "x": -6,
      "y": 7,
      "z": 7,
      "name": "Soil_Pebbles"
    },
    {
      "x": -6,
      "y": 7,
      "z": 8,
      "name": "Soil_Pebbles"
    },
    {
      "x": -6,
      "y": 13,
      "z": 8,
      "name": "Rock_Ice"
    },
    {
      "x": -6,
      "y": 14,
      "z": 8,
      "name": "Rock_Ice"
    },
    {
      "x": -6,
      "y": 15,
      "z": 8,
      "name": "Rock_Ice"
    },
    {
      "x": -6,
      "y": 16,
      "z": 8,
      "name": "Rock_Ice"
    },
    {
      "x": -6,
      "y": 7,
      "z": 9,
      "name": "Soil_Pebbles"
    },
    {
      "x": -6,
      "y": 12,
      "z": 9,
      "name": "Rock_Ice"
    },
    {
      "x": -6,
      "y": 13,
      "z": 9,
      "name": "Rock_Ice"
    },
    {
      "x": -6,
      "y": 14,
      "z": 9,
      "name": "Rock_Ice"
    },
    {
      "x": -6,
      "y": 15,
      "z": 9,
      "name": "Rock_Ice"
    },
    {
      "x": -6,
      "y": 8,
      "z": 10,
      "name": "Soil_Pebbles"
    },
    {
      "x": -6,
      "y": 15,
      "z": 12,
      "name": "Soil_Pebbles"
    },
    {
      "x": -6,
      "y": 16,
      "z": 12,
      "name": "Soil_Pebbles"
    },
    {
      "x": -6,
      "y": 17,
      "z": 13,
      "name": "Soil_Pebbles"
    },
    {
      "x": -6,
      "y": 17,
      "z": 14,
      "name": "Soil_Pebbles"
    },
    {
      "x": -6,
      "y": 17,
      "z": 15,
      "name": "Soil_Pebbles"
    },
    {
      "x": -6,
      "y": 17,
      "z": 16,
      "name": "Soil_Pebbles"
    },
    {
      "x": -6,
      "y": 18,
      "z": 17,
      "name": "Soil_Pebbles"
    },
    {
      "x": -5,
      "y": 9,
      "z": -12,
      "name": "Soil_Pebbles"
    },
    {
      "x": -5,
      "y": 9,
      "z": -11,
      "name": "Soil_Pebbles"
    },
    {
      "x": -5,
      "y": 8,
      "z": -10,
      "name": "Soil_Pebbles"
    },
    {
      "x": -5,
      "y": 8,
      "z": -9,
      "name": "Soil_Pebbles"
    },
    {
      "x": -5,
      "y": 9,
      "z": -9,
      "name": "Rubble_Shale"
    },
    {
      "x": -5,
      "y": 7,
      "z": -8,
      "name": "Soil_Pebbles"
    },
    {
      "x": -5,
      "y": 7,
      "z": -7,
      "name": "Soil_Pebbles"
    },
    {
      "x": -5,
      "y": 7,
      "z": -6,
      "name": "Soil_Pebbles"
    },
    {
      "x": -5,
      "y": 6,
      "z": -5,
      "name": "Soil_Pebbles"
    },
    {
      "x": -5,
      "y": 6,
      "z": -4,
      "name": "Soil_Pebbles"
    },
    {
      "x": -5,
      "y": 6,
      "z": -3,
      "name": "Soil_Pebbles"
    },
    {
      "x": -5,
      "y": 6,
      "z": -2,
      "name": "Soil_Pebbles"
    },
    {
      "x": -5,
      "y": 6,
      "z": -1,
      "name": "Soil_Pebbles"
    },
    {
      "x": -5,
      "y": 7,
      "z": 0,
      "name": "Soil_Pebbles"
    },
    {
      "x": -5,
      "y": 7,
      "z": 1,
      "name": "Soil_Pebbles"
    },
    {
      "x": -5,
      "y": 8,
      "z": 2,
      "name": "Rubble_Shale"
    },
    {
      "x": -5,
      "y": 7,
      "z": 3,
      "name": "Soil_Pebbles"
    },
    {
      "x": -5,
      "y": 8,
      "z": 3,
      "name": "Plant_Seaweed_Winter_Tall"
    },
    {
      "x": -5,
      "y": 9,
      "z": 3,
      "name": "Plant_Seaweed_Winter_Tall",
      "filler": 1024
    },
    {
      "x": -5,
      "y": 7,
      "z": 4,
      "name": "Soil_Pebbles"
    },
    {
      "x": -5,
      "y": 8,
      "z": 4,
      "name": "Plant_Seaweed_Winter_Tall"
    },
    {
      "x": -5,
      "y": 9,
      "z": 4,
      "name": "Plant_Seaweed_Winter_Tall",
      "filler": 1024
    },
    {
      "x": -5,
      "y": 7,
      "z": 5,
      "name": "Soil_Pebbles"
    },
    {
      "x": -5,
      "y": 7,
      "z": 6,
      "name": "Soil_Pebbles"
    },
    {
      "x": -5,
      "y": 6,
      "z": 7,
      "name": "Soil_Pebbles"
    },
    {
      "x": -5,
      "y": 6,
      "z": 8,
      "name": "Soil_Pebbles"
    },
    {
      "x": -5,
      "y": 7,
      "z": 9,
      "name": "Soil_Pebbles"
    },
    {
      "x": -5,
      "y": 8,
      "z": 10,
      "name": "Soil_Pebbles"
    },
    {
      "x": -5,
      "y": 15,
      "z": 12,
      "name": "Soil_Pebbles"
    },
    {
      "x": -5,
      "y": 16,
      "z": 12,
      "name": "Soil_Pebbles"
    },
    {
      "x": -5,
      "y": 16,
      "z": 13,
      "name": "Soil_Pebbles"
    },
    {
      "x": -5,
      "y": 16,
      "z": 14,
      "name": "Soil_Pebbles"
    },
    {
      "x": -5,
      "y": 17,
      "z": 15,
      "name": "Soil_Pebbles"
    },
    {
      "x": -5,
      "y": 18,
      "z": 15,
      "name": "Plant_Seaweed_Winter_Short"
    },
    {
      "x": -5,
      "y": 17,
      "z": 16,
      "name": "Soil_Pebbles"
    },
    {
      "x": -5,
      "y": 18,
      "z": 16,
      "name": "Plant_Seaweed_Winter_Tall"
    },
    {
      "x": -5,
      "y": 19,
      "z": 16,
      "name": "Plant_Seaweed_Winter_Tall",
      "filler": 1024
    },
    {
      "x": -5,
      "y": 18,
      "z": 17,
      "name": "Soil_Pebbles"
    },
    {
      "x": -5,
      "y": 18,
      "z": 18,
      "name": "Soil_Pebbles"
    },
    {
      "x": -4,
      "y": 10,
      "z": -12,
      "name": "Soil_Pebbles"
    },
    {
      "x": -4,
      "y": 9,
      "z": -11,
      "name": "Soil_Pebbles"
    },
    {
      "x": -4,
      "y": 9,
      "z": -10,
      "name": "Soil_Pebbles"
    },
    {
      "x": -4,
      "y": 8,
      "z": -9,
      "name": "Soil_Pebbles"
    },
    {
      "x": -4,
      "y": 8,
      "z": -8,
      "name": "Soil_Pebbles"
    },
    {
      "x": -4,
      "y": 7,
      "z": -7,
      "name": "Soil_Pebbles"
    },
    {
      "x": -4,
      "y": 7,
      "z": -6,
      "name": "Soil_Pebbles"
    },
    {
      "x": -4,
      "y": 6,
      "z": -5,
      "name": "Soil_Pebbles"
    },
    {
      "x": -4,
      "y": 6,
      "z": -4,
      "name": "Soil_Pebbles"
    },
    {
      "x": -4,
      "y": 6,
      "z": -3,
      "name": "Soil_Pebbles"
    },
    {
      "x": -4,
      "y": 6,
      "z": -2,
      "name": "Soil_Pebbles"
    },
    {
      "x": -4,
      "y": 6,
      "z": -1,
      "name": "Soil_Pebbles"
    },
    {
      "x": -4,
      "y": 7,
      "z": 0,
      "name": "Soil_Pebbles"
    },
    {
      "x": -4,
      "y": 7,
      "z": 1,
      "name": "Soil_Pebbles"
    },
    {
      "x": -4,
      "y": 7,
      "z": 2,
      "name": "Soil_Pebbles"
    },
    {
      "x": -4,
      "y": 7,
      "z": 3,
      "name": "Soil_Pebbles"
    },
    {
      "x": -4,
      "y": 7,
      "z": 4,
      "name": "Soil_Pebbles"
    },
    {
      "x": -4,
      "y": 6,
      "z": 5,
      "name": "Soil_Pebbles"
    },
    {
      "x": -4,
      "y": 6,
      "z": 6,
      "name": "Soil_Pebbles"
    },
    {
      "x": -4,
      "y": 5,
      "z": 7,
      "name": "Soil_Pebbles"
    },
    {
      "x": -4,
      "y": 6,
      "z": 8,
      "name": "Soil_Pebbles"
    },
    {
      "x": -4,
      "y": 7,
      "z": 9,
      "name": "Soil_Pebbles"
    },
    {
      "x": -4,
      "y": 8,
      "z": 10,
      "name": "Soil_Pebbles"
    },
    {
      "x": -4,
      "y": 14,
      "z": 12,
      "name": "Soil_Pebbles"
    },
    {
      "x": -4,
      "y": 15,
      "z": 12,
      "name": "Soil_Pebbles"
    },
    {
      "x": -4,
      "y": 16,
      "z": 13,
      "name": "Soil_Pebbles"
    },
    {
      "x": -4,
      "y": 17,
      "z": 14,
      "name": "Soil_Pebbles"
    },
    {
      "x": -4,
      "y": 18,
      "z": 14,
      "name": "Plant_Seaweed_Winter_Tall"
    },
    {
      "x": -4,
      "y": 19,
      "z": 14,
      "name": "Plant_Seaweed_Winter_Tall",
      "filler": 1024
    },
    {
      "x": -4,
      "y": 17,
      "z": 15,
      "name": "Soil_Pebbles"
    },
    {
      "x": -4,
      "y": 18,
      "z": 15,
      "name": "Plant_Seaweed_Winter_Tall"
    },
    {
      "x": -4,
      "y": 19,
      "z": 15,
      "name": "Plant_Seaweed_Winter_Tall",
      "filler": 1024
    },
    {
      "x": -4,
      "y": 17,
      "z": 16,
      "name": "Soil_Pebbles"
    },
    {
      "x": -4,
      "y": 18,
      "z": 16,
      "name": "Plant_Seaweed_Winter_Tall"
    },
    {
      "x": -4,
      "y": 19,
      "z": 16,
      "name": "Plant_Seaweed_Winter_Tall",
      "filler": 1024
    },
    {
      "x": -4,
      "y": 17,
      "z": 17,
      "name": "Soil_Pebbles"
    },
    {
      "x": -4,
      "y": 18,
      "z": 17,
      "name": "Plant_Seaweed_Winter_Tall"
    },
    {
      "x": -4,
      "y": 19,
      "z": 17,
      "name": "Plant_Seaweed_Winter_Tall",
      "filler": 1024
    },
    {
      "x": -4,
      "y": 18,
      "z": 18,
      "name": "Soil_Pebbles"
    },
    {
      "x": -3,
      "y": 11,
      "z": -13,
      "name": "Soil_Pebbles"
    },
    {
      "x": -3,
      "y": 10,
      "z": -12,
      "name": "Soil_Pebbles"
    },
    {
      "x": -3,
      "y": 11,
      "z": -12,
      "name": "Soil_Pebbles"
    },
    {
      "x": -3,
      "y": 12,
      "z": -12,
      "name": "Soil_Pebbles"
    },
    {
      "x": -3,
      "y": 9,
      "z": -11,
      "name": "Soil_Pebbles"
    },
    {
      "x": -3,
      "y": 10,
      "z": -11,
      "name": "Plant_Seaweed_Winter_Tall"
    },
    {
      "x": -3,
      "y": 11,
      "z": -11,
      "name": "Plant_Seaweed_Winter_Tall",
      "filler": 1024
    },
    {
      "x": -3,
      "y": 9,
      "z": -10,
      "name": "Soil_Pebbles"
    },
    {
      "x": -3,
      "y": 10,
      "z": -10,
      "name": "Plant_Seaweed_Winter_Tall"
    },
    {
      "x": -3,
      "y": 11,
      "z": -10,
      "name": "Plant_Seaweed_Winter_Tall",
      "filler": 1024
    },
    {
      "x": -3,
      "y": 9,
      "z": -9,
      "name": "Soil_Pebbles"
    },
    {
      "x": -3,
      "y": 8,
      "z": -8,
      "name": "Soil_Pebbles"
    },
    {
      "x": -3,
      "y": 7,
      "z": -7,
      "name": "Soil_Pebbles"
    },
    {
      "x": -3,
      "y": 7,
      "z": -6,
      "name": "Soil_Pebbles"
    },
    {
      "x": -3,
      "y": 6,
      "z": -5,
      "name": "Soil_Pebbles"
    },
    {
      "x": -3,
      "y": 6,
      "z": -4,
      "name": "Soil_Pebbles"
    },
    {
      "x": -3,
      "y": 6,
      "z": -3,
      "name": "Soil_Pebbles"
    },
    {
      "x": -3,
      "y": 6,
      "z": -2,
      "name": "Soil_Pebbles"
    },
    {
      "x": -3,
      "y": 6,
      "z": -1,
      "name": "Soil_Pebbles"
    },
    {
      "x": -3,
      "y": 7,
      "z": 0,
      "name": "Soil_Pebbles"
    },
    {
      "x": -3,
      "y": 7,
      "z": 1,
      "name": "Soil_Pebbles"
    },
    {
      "x": -3,
      "y": 7,
      "z": 2,
      "name": "Soil_Pebbles"
    },
    {
      "x": -3,
      "y": 7,
      "z": 3,
      "name": "Soil_Pebbles"
    },
    {
      "x": -3,
      "y": 7,
      "z": 4,
      "name": "Soil_Pebbles"
    },
    {
      "x": -3,
      "y": 6,
      "z": 5,
      "name": "Soil_Pebbles"
    },
    {
      "x": -3,
      "y": 7,
      "z": 5,
      "name": "Plant_Seaweed_Winter_Short"
    },
    {
      "x": -3,
      "y": 5,
      "z": 6,
      "name": "Soil_Pebbles"
    },
    {
      "x": -3,
      "y": 5,
      "z": 7,
      "name": "Soil_Pebbles"
    },
    {
      "x": -3,
      "y": 6,
      "z": 8,
      "name": "Soil_Pebbles"
    },
    {
      "x": -3,
      "y": 6,
      "z": 9,
      "name": "Soil_Pebbles"
    },
    {
      "x": -3,
      "y": 7,
      "z": 10,
      "name": "Soil_Pebbles"
    },
    {
      "x": -3,
      "y": 8,
      "z": 10,
      "name": "Soil_Pebbles"
    },
    {
      "x": -3,
      "y": 14,
      "z": 12,
      "name": "Soil_Pebbles"
    },
    {
      "x": -3,
      "y": 15,
      "z": 12,
      "name": "Soil_Pebbles"
    },
    {
      "x": -3,
      "y": 16,
      "z": 13,
      "name": "Soil_Pebbles"
    },
    {
      "x": -3,
      "y": 17,
      "z": 13,
      "name": "Plant_Seaweed_Winter_Tall"
    },
    {
      "x": -3,
      "y": 18,
      "z": 13,
      "name": "Plant_Seaweed_Winter_Tall",
      "filler": 1024
    },
    {
      "x": -3,
      "y": 17,
      "z": 14,
      "name": "Soil_Pebbles"
    },
    {
      "x": -3,
      "y": 18,
      "z": 14,
      "name": "Plant_Seaweed_Winter_Tall"
    },
    {
      "x": -3,
      "y": 19,
      "z": 14,
      "name": "Plant_Seaweed_Winter_Tall",
      "filler": 1024
    },
    {
      "x": -3,
      "y": 17,
      "z": 15,
      "name": "Soil_Pebbles"
    },
    {
      "x": -3,
      "y": 18,
      "z": 15,
      "name": "Plant_Seaweed_Winter_Short"
    },
    {
      "x": -3,
      "y": 17,
      "z": 16,
      "name": "Soil_Pebbles"
    },
    {
      "x": -3,
      "y": 18,
      "z": 16,
      "name": "Plant_Seaweed_Winter_Tall"
    },
    {
      "x": -3,
      "y": 19,
      "z": 16,
      "name": "Plant_Seaweed_Winter_Tall",
      "filler": 1024
    },
    {
      "x": -3,
      "y": 17,
      "z": 17,
      "name": "Soil_Pebbles"
    },
    {
      "x": -3,
      "y": 18,
      "z": 18,
      "name": "Soil_Pebbles"
    },
    {
      "x": -2,
      "y": 13,
      "z": -14,
      "name": "Soil_Pebbles"
    },
    {
      "x": -2,
      "y": 13,
      "z": -13,
      "name": "Soil_Pebbles"
    },
    {
      "x": -2,
      "y": 11,
      "z": -12,
      "name": "Soil_Pebbles"
    },
    {
      "x": -2,
      "y": 12,
      "z": -12,
      "name": "Soil_Pebbles"
    },
    {
      "x": -2,
      "y": 10,
      "z": -11,
      "name": "Soil_Pebbles"
    },
    {
      "x": -2,
      "y": 9,
      "z": -10,
      "name": "Soil_Pebbles"
    },
    {
      "x": -2,
      "y": 10,
      "z": -10,
      "name": "Plant_Seaweed_Winter_Tall"
    },
    {
      "x": -2,
      "y": 11,
      "z": -10,
      "name": "Plant_Seaweed_Winter_Tall",
      "filler": 1024
    },
    {
      "x": -2,
      "y": 9,
      "z": -9,
      "name": "Soil_Pebbles"
    },
    {
      "x": -2,
      "y": 10,
      "z": -9,
      "name": "Plant_Seaweed_Winter_Tall"
    },
    {
      "x": -2,
      "y": 11,
      "z": -9,
      "name": "Plant_Seaweed_Winter_Tall",
      "filler": 1024
    },
    {
      "x": -2,
      "y": 8,
      "z": -8,
      "name": "Soil_Pebbles"
    },
    {
      "x": -2,
      "y": 7,
      "z": -7,
      "name": "Soil_Pebbles"
    },
    {
      "x": -2,
      "y": 7,
      "z": -6,
      "name": "Soil_Pebbles"
    },
    {
      "x": -2,
      "y": 6,
      "z": -5,
      "name": "Soil_Pebbles"
    },
    {
      "x": -2,
      "y": 6,
      "z": -4,
      "name": "Soil_Pebbles"
    },
    {
      "x": -2,
      "y": 6,
      "z": -3,
      "name": "Soil_Pebbles"
    },
    {
      "x": -2,
      "y": 6,
      "z": -2,
      "name": "Soil_Pebbles"
    },
    {
      "x": -2,
      "y": 6,
      "z": -1,
      "name": "Soil_Pebbles"
    },
    {
      "x": -2,
      "y": 6,
      "z": 0,
      "name": "Soil_Pebbles"
    },
    {
      "x": -2,
      "y": 7,
      "z": 1,
      "name": "Soil_Pebbles"
    },
    {
      "x": -2,
      "y": 7,
      "z": 2,
      "name": "Soil_Pebbles"
    },
    {
      "x": -2,
      "y": 8,
      "z": 2,
      "name": "Plant_Seaweed_Winter_Tall"
    },
    {
      "x": -2,
      "y": 9,
      "z": 2,
      "name": "Plant_Seaweed_Winter_Tall",
      "filler": 1024
    },
    {
      "x": -2,
      "y": 7,
      "z": 3,
      "name": "Soil_Pebbles"
    },
    {
      "x": -2,
      "y": 8,
      "z": 3,
      "name": "Plant_Seaweed_Winter_Tall"
    },
    {
      "x": -2,
      "y": 9,
      "z": 3,
      "name": "Plant_Seaweed_Winter_Tall",
      "filler": 1024
    },
    {
      "x": -2,
      "y": 7,
      "z": 4,
      "name": "Soil_Pebbles"
    },
    {
      "x": -2,
      "y": 8,
      "z": 4,
      "name": "Plant_Seaweed_Winter_Tall"
    },
    {
      "x": -2,
      "y": 9,
      "z": 4,
      "name": "Plant_Seaweed_Winter_Tall",
      "filler": 1024
    },
    {
      "x": -2,
      "y": 6,
      "z": 5,
      "name": "Soil_Pebbles"
    },
    {
      "x": -2,
      "y": 7,
      "z": 5,
      "name": "Plant_Seaweed_Winter_Short"
    },
    {
      "x": -2,
      "y": 5,
      "z": 6,
      "name": "Soil_Pebbles"
    },
    {
      "x": -2,
      "y": 6,
      "z": 7,
      "name": "Soil_Pebbles"
    },
    {
      "x": -2,
      "y": 6,
      "z": 8,
      "name": "Soil_Pebbles"
    },
    {
      "x": -2,
      "y": 7,
      "z": 8,
      "name": "Rubble_Shale"
    },
    {
      "x": -2,
      "y": 6,
      "z": 9,
      "name": "Soil_Pebbles"
    },
    {
      "x": -2,
      "y": 7,
      "z": 10,
      "name": "Soil_Pebbles"
    },
    {
      "x": -2,
      "y": 8,
      "z": 10,
      "name": "Soil_Pebbles"
    },
    {
      "x": -2,
      "y": 9,
      "z": 10,
      "name": "Soil_Pebbles"
    },
    {
      "x": -2,
      "y": 15,
      "z": 12,
      "name": "Soil_Pebbles"
    },
    {
      "x": -2,
      "y": 16,
      "z": 12,
      "name": "Soil_Pebbles"
    },
    {
      "x": -2,
      "y": 16,
      "z": 13,
      "name": "Soil_Pebbles"
    },
    {
      "x": -2,
      "y": 17,
      "z": 13,
      "name": "Plant_Seaweed_Winter_Tall"
    },
    {
      "x": -2,
      "y": 18,
      "z": 13,
      "name": "Plant_Seaweed_Winter_Tall",
      "filler": 1024
    },
    {
      "x": -2,
      "y": 17,
      "z": 14,
      "name": "Soil_Pebbles"
    },
    {
      "x": -2,
      "y": 18,
      "z": 14,
      "name": "Plant_Seaweed_Winter_Tall"
    },
    {
      "x": -2,
      "y": 19,
      "z": 14,
      "name": "Plant_Seaweed_Winter_Tall",
      "filler": 1024
    },
    {
      "x": -2,
      "y": 17,
      "z": 15,
      "name": "Soil_Pebbles"
    },
    {
      "x": -2,
      "y": 18,
      "z": 15,
      "name": "Plant_Seaweed_Winter_Tall"
    },
    {
      "x": -2,
      "y": 19,
      "z": 15,
      "name": "Plant_Seaweed_Winter_Tall",
      "filler": 1024
    },
    {
      "x": -2,
      "y": 17,
      "z": 16,
      "name": "Soil_Pebbles"
    },
    {
      "x": -2,
      "y": 17,
      "z": 17,
      "name": "Soil_Pebbles"
    },
    {
      "x": -2,
      "y": 18,
      "z": 18,
      "name": "Soil_Pebbles"
    },
    {
      "x": -1,
      "y": 13,
      "z": -15,
      "name": "Soil_Pebbles"
    },
    {
      "x": -1,
      "y": 13,
      "z": -14,
      "name": "Soil_Pebbles"
    },
    {
      "x": -1,
      "y": 14,
      "z": -14,
      "name": "Plant_Seaweed_Winter_Short"
    },
    {
      "x": -1,
      "y": 12,
      "z": -13,
      "name": "Soil_Pebbles"
    },
    {
      "x": -1,
      "y": 13,
      "z": -13,
      "name": "Soil_Pebbles"
    },
    {
      "x": -1,
      "y": 28,
      "z": -13,
      "name": "Rock_Ice"
    },
    {
      "x": -1,
      "y": 11,
      "z": -12,
      "name": "Soil_Pebbles"
    },
    {
      "x": -1,
      "y": 26,
      "z": -12,
      "name": "Rock_Ice"
    },
    {
      "x": -1,
      "y": 27,
      "z": -12,
      "name": "Rock_Ice"
    },
    {
      "x": -1,
      "y": 28,
      "z": -12,
      "name": "Rock_Ice"
    },
    {
      "x": -1,
      "y": 10,
      "z": -11,
      "name": "Soil_Pebbles"
    },
    {
      "x": -1,
      "y": 24,
      "z": -11,
      "name": "Rock_Ice"
    },
    {
      "x": -1,
      "y": 25,
      "z": -11,
      "name": "Rock_Ice"
    },
    {
      "x": -1,
      "y": 26,
      "z": -11,
      "name": "Rock_Ice"
    },
    {
      "x": -1,
      "y": 27,
      "z": -11,
      "name": "Rock_Ice"
    },
    {
      "x": -1,
      "y": 28,
      "z": -11,
      "name": "Rock_Ice"
    },
    {
      "x": -1,
      "y": 9,
      "z": -10,
      "name": "Soil_Pebbles"
    },
    {
      "x": -1,
      "y": 10,
      "z": -10,
      "name": "Plant_Seaweed_Winter_Tall"
    },
    {
      "x": -1,
      "y": 11,
      "z": -10,
      "name": "Plant_Seaweed_Winter_Tall",
      "filler": 1024
    },
    {
      "x": -1,
      "y": 23,
      "z": -10,
      "name": "Rock_Ice"
    },
    {
      "x": -1,
      "y": 24,
      "z": -10,
      "name": "Rock_Ice"
    },
    {
      "x": -1,
      "y": 25,
      "z": -10,
      "name": "Rock_Ice"
    },
    {
      "x": -1,
      "y": 26,
      "z": -10,
      "name": "Rock_Ice"
    },
    {
      "x": -1,
      "y": 8,
      "z": -9,
      "name": "Soil_Pebbles"
    },
    {
      "x": -1,
      "y": 9,
      "z": -9,
      "name": "Plant_Seaweed_Winter_Tall"
    },
    {
      "x": -1,
      "y": 10,
      "z": -9,
      "name": "Plant_Seaweed_Winter_Tall",
      "filler": 1024
    },
    {
      "x": -1,
      "y": 11,
      "z": -9,
      "name": "Empty"
    },
    {
      "x": -1,
      "y": 24,
      "z": -9,
      "name": "Rock_Ice"
    },
    {
      "x": -1,
      "y": 8,
      "z": -8,
      "name": "Soil_Pebbles"
    },
    {
      "x": -1,
      "y": 9,
      "z": -8,
      "name": "Plant_Seaweed_Winter_Tall"
    },
    {
      "x": -1,
      "y": 10,
      "z": -8,
      "name": "Plant_Seaweed_Winter_Tall",
      "filler": 1024
    },
    {
      "x": -1,
      "y": 7,
      "z": -7,
      "name": "Soil_Pebbles"
    },
    {
      "x": -1,
      "y": 7,
      "z": -6,
      "name": "Soil_Pebbles"
    },
    {
      "x": -1,
      "y": 6,
      "z": -5,
      "name": "Soil_Pebbles"
    },
    {
      "x": -1,
      "y": 6,
      "z": -4,
      "name": "Soil_Pebbles"
    },
    {
      "x": -1,
      "y": 6,
      "z": -3,
      "name": "Soil_Pebbles"
    },
    {
      "x": -1,
      "y": 6,
      "z": -2,
      "name": "Soil_Pebbles"
    },
    {
      "x": -1,
      "y": 7,
      "z": -2,
      "name": "Rubble_Shale"
    },
    {
      "x": -1,
      "y": 6,
      "z": -1,
      "name": "Soil_Pebbles"
    },
    {
      "x": -1,
      "y": 6,
      "z": 0,
      "name": "Soil_Pebbles"
    },
    {
      "x": -1,
      "y": 7,
      "z": 1,
      "name": "Soil_Pebbles"
    },
    {
      "x": -1,
      "y": 7,
      "z": 2,
      "name": "Soil_Pebbles"
    },
    {
      "x": -1,
      "y": 8,
      "z": 2,
      "name": "Plant_Seaweed_Winter_Tall"
    },
    {
      "x": -1,
      "y": 9,
      "z": 2,
      "name": "Plant_Seaweed_Winter_Tall",
      "filler": 1024
    },
    {
      "x": -1,
      "y": 7,
      "z": 3,
      "name": "Soil_Pebbles"
    },
    {
      "x": -1,
      "y": 8,
      "z": 3,
      "name": "Plant_Seaweed_Winter_Tall"
    },
    {
      "x": -1,
      "y": 9,
      "z": 3,
      "name": "Plant_Seaweed_Winter_Tall",
      "filler": 1024
    },
    {
      "x": -1,
      "y": 7,
      "z": 4,
      "name": "Soil_Pebbles"
    },
    {
      "x": -1,
      "y": 8,
      "z": 4,
      "name": "Plant_Seaweed_Winter_Tall"
    },
    {
      "x": -1,
      "y": 9,
      "z": 4,
      "name": "Plant_Seaweed_Winter_Tall",
      "filler": 1024
    },
    {
      "x": -1,
      "y": 6,
      "z": 5,
      "name": "Soil_Pebbles"
    },
    {
      "x": -1,
      "y": 5,
      "z": 6,
      "name": "Soil_Pebbles"
    },
    {
      "x": -1,
      "y": 6,
      "z": 6,
      "name": "Plant_Seaweed_Winter_Aurora"
    },
    {
      "x": -1,
      "y": 7,
      "z": 6,
      "name": "Plant_Seaweed_Winter_Aurora",
      "filler": 1024
    },
    {
      "x": -1,
      "y": 6,
      "z": 7,
      "name": "Soil_Pebbles"
    },
    {
      "x": -1,
      "y": 7,
      "z": 7,
      "name": "Plant_Seaweed_Winter_Short"
    },
    {
      "x": -1,
      "y": 6,
      "z": 8,
      "name": "Soil_Pebbles"
    },
    {
      "x": -1,
      "y": 7,
      "z": 9,
      "name": "Soil_Pebbles"
    },
    {
      "x": -1,
      "y": 8,
      "z": 9,
      "name": "Soil_Pebbles"
    },
    {
      "x": -1,
      "y": 9,
      "z": 10,
      "name": "Soil_Pebbles"
    },
    {
      "x": -1,
      "y": 10,
      "z": 10,
      "name": "Soil_Pebbles"
    },
    {
      "x": -1,
      "y": 15,
      "z": 11,
      "name": "Soil_Pebbles"
    },
    {
      "x": -1,
      "y": 16,
      "z": 11,
      "name": "Soil_Pebbles"
    },
    {
      "x": -1,
      "y": 17,
      "z": 12,
      "name": "Soil_Pebbles"
    },
    {
      "x": -1,
      "y": 17,
      "z": 13,
      "name": "Soil_Pebbles"
    },
    {
      "x": -1,
      "y": 17,
      "z": 14,
      "name": "Soil_Pebbles"
    },
    {
      "x": -1,
      "y": 17,
      "z": 15,
      "name": "Soil_Pebbles"
    },
    {
      "x": -1,
      "y": 17,
      "z": 16,
      "name": "Soil_Pebbles"
    },
    {
      "x": -1,
      "y": 18,
      "z": 17,
      "name": "Soil_Pebbles"
    },
    {
      "x": 0,
      "y": 13,
      "z": -16,
      "name": "Soil_Pebbles"
    },
    {
      "x": 0,
      "y": 14,
      "z": -16,
      "name": "Plant_Seaweed_Winter_Tall"
    },
    {
      "x": 0,
      "y": 15,
      "z": -16,
      "name": "Plant_Seaweed_Winter_Tall",
      "filler": 1024
    },
    {
      "x": 0,
      "y": 13,
      "z": -15,
      "name": "Soil_Pebbles"
    },
    {
      "x": 0,
      "y": 14,
      "z": -15,
      "name": "Plant_Seaweed_Winter_Tall"
    },
    {
      "x": 0,
      "y": 15,
      "z": -15,
      "name": "Plant_Seaweed_Winter_Tall",
      "filler": 1024
    },
    {
      "x": 0,
      "y": 12,
      "z": -14,
      "name": "Soil_Pebbles"
    },
    {
      "x": 0,
      "y": 13,
      "z": -14,
      "name": "Soil_Pebbles"
    },
    {
      "x": 0,
      "y": 11,
      "z": -13,
      "name": "Soil_Pebbles"
    },
    {
      "x": 0,
      "y": 27,
      "z": -13,
      "name": "Rock_Ice"
    },
    {
      "x": 0,
      "y": 28,
      "z": -13,
      "name": "Rock_Ice"
    },
    {
      "x": 0,
      "y": 11,
      "z": -12,
      "name": "Soil_Pebbles"
    },
    {
      "x": 0,
      "y": 25,
      "z": -12,
      "name": "Rock_Ice"
    },
    {
      "x": 0,
      "y": 26,
      "z": -12,
      "name": "Rock_Ice"
    },
    {
      "x": 0,
      "y": 27,
      "z": -12,
      "name": "Rock_Ice"
    },
    {
      "x": 0,
      "y": 28,
      "z": -12,
      "name": "Rock_Ice"
    },
    {
      "x": 0,
      "y": 10,
      "z": -11,
      "name": "Soil_Pebbles"
    },
    {
      "x": 0,
      "y": 24,
      "z": -11,
      "name": "Rock_Ice"
    },
    {
      "x": 0,
      "y": 25,
      "z": -11,
      "name": "Rock_Ice"
    },
    {
      "x": 0,
      "y": 26,
      "z": -11,
      "name": "Rock_Ice"
    },
    {
      "x": 0,
      "y": 27,
      "z": -11,
      "name": "Rock_Ice"
    },
    {
      "x": 0,
      "y": 28,
      "z": -11,
      "name": "Rock_Ice"
    },
    {
      "x": 0,
      "y": 9,
      "z": -10,
      "name": "Soil_Pebbles"
    },
    {
      "x": 0,
      "y": 23,
      "z": -10,
      "name": "Rock_Ice"
    },
    {
      "x": 0,
      "y": 24,
      "z": -10,
      "name": "Rock_Ice"
    },
    {
      "x": 0,
      "y": 25,
      "z": -10,
      "name": "Rock_Ice"
    },
    {
      "x": 0,
      "y": 26,
      "z": -10,
      "name": "Rock_Ice"
    },
    {
      "x": 0,
      "y": 27,
      "z": -10,
      "name": "Rock_Ice"
    },
    {
      "x": 0,
      "y": 8,
      "z": -9,
      "name": "Soil_Pebbles"
    },
    {
      "x": 0,
      "y": 9,
      "z": -9,
      "name": "Plant_Seaweed_Winter_Tall"
    },
    {
      "x": 0,
      "y": 10,
      "z": -9,
      "name": "Plant_Seaweed_Winter_Tall",
      "filler": 1024
    },
    {
      "x": 0,
      "y": 22,
      "z": -9,
      "name": "Rock_Ice"
    },
    {
      "x": 0,
      "y": 23,
      "z": -9,
      "name": "Rock_Ice"
    },
    {
      "x": 0,
      "y": 24,
      "z": -9,
      "name": "Rock_Ice"
    },
    {
      "x": 0,
      "y": 25,
      "z": -9,
      "name": "Rock_Ice"
    },
    {
      "x": 0,
      "y": 8,
      "z": -8,
      "name": "Soil_Pebbles"
    },
    {
      "x": 0,
      "y": 7,
      "z": -7,
      "name": "Soil_Pebbles"
    },
    {
      "x": 0,
      "y": 7,
      "z": -6,
      "name": "Soil_Pebbles"
    },
    {
      "x": 0,
      "y": 7,
      "z": -5,
      "name": "Soil_Pebbles"
    },
    {
      "x": 0,
      "y": 6,
      "z": -4,
      "name": "Soil_Pebbles"
    },
    {
      "x": 0,
      "y": 6,
      "z": -3,
      "name": "Soil_Pebbles"
    },
    {
      "x": 0,
      "y": 6,
      "z": -2,
      "name": "Soil_Pebbles"
    },
    {
      "x": 0,
      "y": 6,
      "z": -1,
      "name": "Soil_Pebbles"
    },
    {
      "x": 0,
      "y": 6,
      "z": 0,
      "name": "Soil_Pebbles"
    },
    {
      "x": 0,
      "y": 6,
      "z": 1,
      "name": "Soil_Pebbles"
    },
    {
      "x": 0,
      "y": 7,
      "z": 2,
      "name": "Soil_Pebbles"
    },
    {
      "x": 0,
      "y": 7,
      "z": 3,
      "name": "Soil_Pebbles"
    },
    {
      "x": 0,
      "y": 8,
      "z": 3,
      "name": "Plant_Seaweed_Winter_Tall"
    },
    {
      "x": 0,
      "y": 9,
      "z": 3,
      "name": "Plant_Seaweed_Winter_Tall",
      "filler": 1024
    },
    {
      "x": 0,
      "y": 7,
      "z": 4,
      "name": "Soil_Pebbles"
    },
    {
      "x": 0,
      "y": 8,
      "z": 4,
      "name": "Plant_Seaweed_Winter_Tall"
    },
    {
      "x": 0,
      "y": 9,
      "z": 4,
      "name": "Plant_Seaweed_Winter_Tall",
      "filler": 1024
    },
    {
      "x": 0,
      "y": 7,
      "z": 5,
      "name": "Soil_Pebbles"
    },
    {
      "x": 0,
      "y": 6,
      "z": 6,
      "name": "Soil_Pebbles"
    },
    {
      "x": 0,
      "y": 7,
      "z": 6,
      "name": "Soil_Pebbles"
    },
    {
      "x": 0,
      "y": 7,
      "z": 7,
      "name": "Soil_Pebbles"
    },
    {
      "x": 0,
      "y": 17,
      "z": 7,
      "name": "Rock_Ice"
    },
    {
      "x": 0,
      "y": 7,
      "z": 8,
      "name": "Soil_Pebbles"
    },
    {
      "x": 0,
      "y": 8,
      "z": 8,
      "name": "Soil_Pebbles"
    },
    {
      "x": 0,
      "y": 16,
      "z": 8,
      "name": "Rock_Ice"
    },
    {
      "x": 0,
      "y": 9,
      "z": 9,
      "name": "Soil_Pebbles"
    },
    {
      "x": 0,
      "y": 15,
      "z": 9,
      "name": "Rock_Ice"
    },
    {
      "x": 0,
      "y": 16,
      "z": 9,
      "name": "Rock_Ice"
    },
    {
      "x": 0,
      "y": 14,
      "z": 10,
      "name": "Rock_Ice"
    },
    {
      "x": 0,
      "y": 15,
      "z": 10,
      "name": "Rock_Ice"
    },
    {
      "x": 0,
      "y": 16,
      "z": 10,
      "name": "Soil_Pebbles"
    },
    {
      "x": 0,
      "y": 13,
      "z": 11,
      "name": "Rock_Ice"
    },
    {
      "x": 0,
      "y": 17,
      "z": 11,
      "name": "Soil_Pebbles"
    },
    {
      "x": 0,
      "y": 18,
      "z": 11,
      "name": "Soil_Pebbles"
    },
    {
      "x": 0,
      "y": 18,
      "z": 12,
      "name": "Soil_Pebbles"
    },
    {
      "x": 0,
      "y": 17,
      "z": 13,
      "name": "Soil_Pebbles"
    },
    {
      "x": 0,
      "y": 17,
      "z": 14,
      "name": "Soil_Pebbles"
    },
    {
      "x": 0,
      "y": 18,
      "z": 15,
      "name": "Soil_Pebbles"
    },
    {
      "x": 0,
      "y": 18,
      "z": 16,
      "name": "Soil_Pebbles"
    },
    {
      "x": 0,
      "y": 18,
      "z": 17,
      "name": "Soil_Pebbles"
    },
    {
      "x": 1,
      "y": 13,
      "z": -16,
      "name": "Soil_Pebbles"
    },
    {
      "x": 1,
      "y": 14,
      "z": -16,
      "name": "Plant_Seaweed_Winter_Tall"
    },
    {
      "x": 1,
      "y": 15,
      "z": -16,
      "name": "Plant_Seaweed_Winter_Tall",
      "filler": 1024
    },
    {
      "x": 1,
      "y": 13,
      "z": -15,
      "name": "Soil_Pebbles"
    },
    {
      "x": 1,
      "y": 14,
      "z": -15,
      "name": "Plant_Seaweed_Winter_Tall"
    },
    {
      "x": 1,
      "y": 15,
      "z": -15,
      "name": "Plant_Seaweed_Winter_Tall",
      "filler": 1024
    },
    {
      "x": 1,
      "y": 12,
      "z": -14,
      "name": "Soil_Pebbles"
    },
    {
      "x": 1,
      "y": 13,
      "z": -14,
      "name": "Soil_Pebbles"
    },
    {
      "x": 1,
      "y": 14,
      "z": -14,
      "name": "Plant_Seaweed_Winter_Tall"
    },
    {
      "x": 1,
      "y": 15,
      "z": -14,
      "name": "Plant_Seaweed_Winter_Tall",
      "filler": 1024
    },
    {
      "x": 1,
      "y": 11,
      "z": -13,
      "name": "Soil_Pebbles"
    },
    {
      "x": 1,
      "y": 28,
      "z": -13,
      "name": "Rock_Ice"
    },
    {
      "x": 1,
      "y": 10,
      "z": -12,
      "name": "Soil_Pebbles"
    },
    {
      "x": 1,
      "y": 11,
      "z": -12,
      "name": "Plant_Seaweed_Winter_Aurora"
    },
    {
      "x": 1,
      "y": 12,
      "z": -12,
      "name": "Plant_Seaweed_Winter_Aurora",
      "filler": 1024
    },
    {
      "x": 1,
      "y": 26,
      "z": -12,
      "name": "Rock_Ice"
    },
    {
      "x": 1,
      "y": 27,
      "z": -12,
      "name": "Rock_Ice"
    },
    {
      "x": 1,
      "y": 28,
      "z": -12,
      "name": "Rock_Ice"
    },
    {
      "x": 1,
      "y": 9,
      "z": -11,
      "name": "Soil_Pebbles"
    },
    {
      "x": 1,
      "y": 25,
      "z": -11,
      "name": "Rock_Ice"
    },
    {
      "x": 1,
      "y": 26,
      "z": -11,
      "name": "Rock_Ice"
    },
    {
      "x": 1,
      "y": 27,
      "z": -11,
      "name": "Rock_Ice"
    },
    {
      "x": 1,
      "y": 28,
      "z": -11,
      "name": "Rock_Ice"
    },
    {
      "x": 1,
      "y": 8,
      "z": -10,
      "name": "Soil_Pebbles"
    },
    {
      "x": 1,
      "y": 24,
      "z": -10,
      "name": "Rock_Ice"
    },
    {
      "x": 1,
      "y": 25,
      "z": -10,
      "name": "Rock_Ice"
    },
    {
      "x": 1,
      "y": 26,
      "z": -10,
      "name": "Rock_Ice"
    },
    {
      "x": 1,
      "y": 8,
      "z": -9,
      "name": "Soil_Pebbles"
    },
    {
      "x": 1,
      "y": 23,
      "z": -9,
      "name": "Rock_Ice"
    },
    {
      "x": 1,
      "y": 24,
      "z": -9,
      "name": "Rock_Ice"
    },
    {
      "x": 1,
      "y": 7,
      "z": -8,
      "name": "Soil_Pebbles"
    },
    {
      "x": 1,
      "y": 7,
      "z": -7,
      "name": "Soil_Pebbles"
    },
    {
      "x": 1,
      "y": 7,
      "z": -6,
      "name": "Soil_Pebbles"
    },
    {
      "x": 1,
      "y": 7,
      "z": -5,
      "name": "Soil_Pebbles"
    },
    {
      "x": 1,
      "y": 6,
      "z": -4,
      "name": "Soil_Pebbles"
    },
    {
      "x": 1,
      "y": 7,
      "z": -4,
      "name": "Plant_Seaweed_Winter_Tall"
    },
    {
      "x": 1,
      "y": 8,
      "z": -4,
      "name": "Plant_Seaweed_Winter_Tall",
      "filler": 1024
    },
    {
      "x": 1,
      "y": 6,
      "z": -3,
      "name": "Soil_Pebbles"
    },
    {
      "x": 1,
      "y": 7,
      "z": -3,
      "name": "Plant_Seaweed_Winter_Tall"
    },
    {
      "x": 1,
      "y": 8,
      "z": -3,
      "name": "Plant_Seaweed_Winter_Tall",
      "filler": 1024
    },
    {
      "x": 1,
      "y": 6,
      "z": -2,
      "name": "Soil_Pebbles"
    },
    {
      "x": 1,
      "y": 7,
      "z": -2,
      "name": "Plant_Seaweed_Winter_Tall"
    },
    {
      "x": 1,
      "y": 8,
      "z": -2,
      "name": "Plant_Seaweed_Winter_Tall",
      "filler": 1024
    },
    {
      "x": 1,
      "y": 6,
      "z": -1,
      "name": "Soil_Pebbles"
    },
    {
      "x": 1,
      "y": 6,
      "z": 0,
      "name": "Soil_Pebbles"
    },
    {
      "x": 1,
      "y": 6,
      "z": 1,
      "name": "Soil_Pebbles"
    },
    {
      "x": 1,
      "y": 7,
      "z": 2,
      "name": "Soil_Pebbles"
    },
    {
      "x": 1,
      "y": 7,
      "z": 3,
      "name": "Soil_Pebbles"
    },
    {
      "x": 1,
      "y": 7,
      "z": 4,
      "name": "Soil_Pebbles"
    },
    {
      "x": 1,
      "y": 8,
      "z": 4,
      "name": "Plant_Seaweed_Winter_Tall"
    },
    {
      "x": 1,
      "y": 9,
      "z": 4,
      "name": "Plant_Seaweed_Winter_Tall",
      "filler": 1024
    },
    {
      "x": 1,
      "y": 19,
      "z": 4,
      "name": "Rock_Ice"
    },
    {
      "x": 1,
      "y": 7,
      "z": 5,
      "name": "Soil_Pebbles"
    },
    {
      "x": 1,
      "y": 8,
      "z": 5,
      "name": "Plant_Seaweed_Winter_Tall"
    },
    {
      "x": 1,
      "y": 9,
      "z": 5,
      "name": "Plant_Seaweed_Winter_Tall",
      "filler": 1024
    },
    {
      "x": 1,
      "y": 18,
      "z": 5,
      "name": "Rock_Ice"
    },
    {
      "x": 1,
      "y": 19,
      "z": 5,
      "name": "Rock_Ice"
    },
    {
      "x": 1,
      "y": 7,
      "z": 6,
      "name": "Soil_Pebbles"
    },
    {
      "x": 1,
      "y": 8,
      "z": 6,
      "name": "Plant_Seaweed_Winter_Tall"
    },
    {
      "x": 1,
      "y": 9,
      "z": 6,
      "name": "Plant_Seaweed_Winter_Tall",
      "filler": 1024
    },
    {
      "x": 1,
      "y": 17,
      "z": 6,
      "name": "Rock_Ice"
    },
    {
      "x": 1,
      "y": 18,
      "z": 6,
      "name": "Rock_Ice"
    },
    {
      "x": 1,
      "y": 8,
      "z": 7,
      "name": "Soil_Pebbles"
    },
    {
      "x": 1,
      "y": 16,
      "z": 7,
      "name": "Rock_Ice"
    },
    {
      "x": 1,
      "y": 17,
      "z": 7,
      "name": "Rock_Ice"
    },
    {
      "x": 1,
      "y": 18,
      "z": 7,
      "name": "Rock_Ice"
    },
    {
      "x": 1,
      "y": 9,
      "z": 8,
      "name": "Soil_Pebbles"
    },
    {
      "x": 1,
      "y": 15,
      "z": 8,
      "name": "Rock_Ice"
    },
    {
      "x": 1,
      "y": 16,
      "z": 8,
      "name": "Rock_Ice"
    },
    {
      "x": 1,
      "y": 17,
      "z": 8,
      "name": "Rock_Ice"
    },
    {
      "x": 1,
      "y": 14,
      "z": 9,
      "name": "Rock_Ice"
    },
    {
      "x": 1,
      "y": 15,
      "z": 9,
      "name": "Rock_Ice"
    },
    {
      "x": 1,
      "y": 16,
      "z": 9,
      "name": "Rock_Ice"
    },
    {
      "x": 1,
      "y": 17,
      "z": 9,
      "name": "Rock_Ice"
    },
    {
      "x": 1,
      "y": 13,
      "z": 10,
      "name": "Rock_Ice"
    },
    {
      "x": 1,
      "y": 14,
      "z": 10,
      "name": "Rock_Ice"
    },
    {
      "x": 1,
      "y": 15,
      "z": 10,
      "name": "Rock_Ice"
    },
    {
      "x": 1,
      "y": 16,
      "z": 10,
      "name": "Rock_Ice"
    },
    {
      "x": 1,
      "y": 17,
      "z": 10,
      "name": "Soil_Pebbles"
    },
    {
      "x": 1,
      "y": 18,
      "z": 10,
      "name": "Soil_Pebbles"
    },
    {
      "x": 1,
      "y": 12,
      "z": 11,
      "name": "Rock_Ice"
    },
    {
      "x": 1,
      "y": 13,
      "z": 11,
      "name": "Rock_Ice"
    },
    {
      "x": 1,
      "y": 14,
      "z": 11,
      "name": "Rock_Ice"
    },
    {
      "x": 1,
      "y": 18,
      "z": 11,
      "name": "Soil_Pebbles"
    },
    {
      "x": 1,
      "y": 11,
      "z": 12,
      "name": "Rock_Ice"
    },
    {
      "x": 1,
      "y": 12,
      "z": 12,
      "name": "Rock_Ice"
    },
    {
      "x": 1,
      "y": 13,
      "z": 12,
      "name": "Rock_Ice"
    },
    {
      "x": 1,
      "y": 18,
      "z": 12,
      "name": "Soil_Pebbles"
    },
    {
      "x": 1,
      "y": 12,
      "z": 13,
      "name": "Rock_Ice"
    },
    {
      "x": 1,
      "y": 18,
      "z": 13,
      "name": "Soil_Pebbles"
    },
    {
      "x": 1,
      "y": 18,
      "z": 14,
      "name": "Soil_Pebbles"
    },
    {
      "x": 1,
      "y": 18,
      "z": 15,
      "name": "Soil_Pebbles"
    },
    {
      "x": 2,
      "y": 13,
      "z": -16,
      "name": "Soil_Pebbles"
    },
    {
      "x": 2,
      "y": 13,
      "z": -15,
      "name": "Soil_Pebbles"
    },
    {
      "x": 2,
      "y": 14,
      "z": -15,
      "name": "Plant_Seaweed_Winter_Tall"
    },
    {
      "x": 2,
      "y": 15,
      "z": -15,
      "name": "Plant_Seaweed_Winter_Tall",
      "filler": 1024
    },
    {
      "x": 2,
      "y": 12,
      "z": -14,
      "name": "Soil_Pebbles"
    },
    {
      "x": 2,
      "y": 13,
      "z": -14,
      "name": "Soil_Pebbles"
    },
    {
      "x": 2,
      "y": 14,
      "z": -14,
      "name": "Plant_Seaweed_Winter_Tall"
    },
    {
      "x": 2,
      "y": 15,
      "z": -14,
      "name": "Plant_Seaweed_Winter_Tall",
      "filler": 1024
    },
    {
      "x": 2,
      "y": 11,
      "z": -13,
      "name": "Soil_Pebbles"
    },
    {
      "x": 2,
      "y": 12,
      "z": -13,
      "name": "Plant_Seaweed_Winter_Short"
    },
    {
      "x": 2,
      "y": 10,
      "z": -12,
      "name": "Soil_Pebbles"
    },
    {
      "x": 2,
      "y": 9,
      "z": -11,
      "name": "Soil_Pebbles"
    },
    {
      "x": 2,
      "y": 10,
      "z": -11,
      "name": "Plant_Seaweed_Winter_Short"
    },
    {
      "x": 2,
      "y": 8,
      "z": -10,
      "name": "Soil_Pebbles"
    },
    {
      "x": 2,
      "y": 7,
      "z": -9,
      "name": "Soil_Pebbles"
    },
    {
      "x": 2,
      "y": 7,
      "z": -8,
      "name": "Soil_Pebbles"
    },
    {
      "x": 2,
      "y": 8,
      "z": -8,
      "name": "Plant_Seaweed_Winter_Short"
    },
    {
      "x": 2,
      "y": 7,
      "z": -7,
      "name": "Soil_Pebbles"
    },
    {
      "x": 2,
      "y": 7,
      "z": -6,
      "name": "Soil_Pebbles"
    },
    {
      "x": 2,
      "y": 7,
      "z": -5,
      "name": "Soil_Pebbles"
    },
    {
      "x": 2,
      "y": 7,
      "z": -4,
      "name": "Soil_Pebbles"
    },
    {
      "x": 2,
      "y": 8,
      "z": -4,
      "name": "Plant_Seaweed_Winter_Tall"
    },
    {
      "x": 2,
      "y": 9,
      "z": -4,
      "name": "Plant_Seaweed_Winter_Tall",
      "filler": 1024
    },
    {
      "x": 2,
      "y": 6,
      "z": -3,
      "name": "Soil_Pebbles"
    },
    {
      "x": 2,
      "y": 7,
      "z": -3,
      "name": "Plant_Seaweed_Winter_Tall"
    },
    {
      "x": 2,
      "y": 8,
      "z": -3,
      "name": "Plant_Seaweed_Winter_Tall",
      "filler": 1024
    },
    {
      "x": 2,
      "y": 6,
      "z": -2,
      "name": "Soil_Pebbles"
    },
    {
      "x": 2,
      "y": 7,
      "z": -2,
      "name": "Plant_Seaweed_Winter_Tall"
    },
    {
      "x": 2,
      "y": 8,
      "z": -2,
      "name": "Plant_Seaweed_Winter_Tall",
      "filler": 1024
    },
    {
      "x": 2,
      "y": 6,
      "z": -1,
      "name": "Soil_Pebbles"
    },
    {
      "x": 2,
      "y": 22,
      "z": -1,
      "name": "Rock_Ice"
    },
    {
      "x": 2,
      "y": 23,
      "z": -1,
      "name": "Rock_Ice"
    },
    {
      "x": 2,
      "y": 6,
      "z": 0,
      "name": "Soil_Pebbles"
    },
    {
      "x": 2,
      "y": 6,
      "z": 1,
      "name": "Soil_Pebbles"
    },
    {
      "x": 2,
      "y": 6,
      "z": 2,
      "name": "Soil_Pebbles"
    },
    {
      "x": 2,
      "y": 7,
      "z": 3,
      "name": "Soil_Pebbles"
    },
    {
      "x": 2,
      "y": 19,
      "z": 3,
      "name": "Rock_Ice"
    },
    {
      "x": 2,
      "y": 20,
      "z": 3,
      "name": "Rock_Ice"
    },
    {
      "x": 2,
      "y": 7,
      "z": 4,
      "name": "Soil_Pebbles"
    },
    {
      "x": 2,
      "y": 18,
      "z": 4,
      "name": "Rock_Ice"
    },
    {
      "x": 2,
      "y": 19,
      "z": 4,
      "name": "Rock_Ice"
    },
    {
      "x": 2,
      "y": 20,
      "z": 4,
      "name": "Rock_Ice"
    },
    {
      "x": 2,
      "y": 8,
      "z": 5,
      "name": "Soil_Pebbles"
    },
    {
      "x": 2,
      "y": 17,
      "z": 5,
      "name": "Rock_Ice"
    },
    {
      "x": 2,
      "y": 18,
      "z": 5,
      "name": "Rock_Ice"
    },
    {
      "x": 2,
      "y": 19,
      "z": 5,
      "name": "Rock_Ice"
    },
    {
      "x": 2,
      "y": 20,
      "z": 5,
      "name": "Rock_Ice"
    },
    {
      "x": 2,
      "y": 8,
      "z": 6,
      "name": "Soil_Pebbles"
    },
    {
      "x": 2,
      "y": 16,
      "z": 6,
      "name": "Rock_Ice"
    },
    {
      "x": 2,
      "y": 17,
      "z": 6,
      "name": "Rock_Ice"
    },
    {
      "x": 2,
      "y": 18,
      "z": 6,
      "name": "Rock_Ice"
    },
    {
      "x": 2,
      "y": 19,
      "z": 6,
      "name": "Rock_Ice"
    },
    {
      "x": 2,
      "y": 20,
      "z": 6,
      "name": "Rock_Ice"
    },
    {
      "x": 2,
      "y": 9,
      "z": 7,
      "name": "Soil_Pebbles"
    },
    {
      "x": 2,
      "y": 15,
      "z": 7,
      "name": "Rock_Ice"
    },
    {
      "x": 2,
      "y": 16,
      "z": 7,
      "name": "Rock_Ice"
    },
    {
      "x": 2,
      "y": 17,
      "z": 7,
      "name": "Rock_Ice"
    },
    {
      "x": 2,
      "y": 18,
      "z": 7,
      "name": "Rock_Ice"
    },
    {
      "x": 2,
      "y": 19,
      "z": 7,
      "name": "Rock_Ice"
    },
    {
      "x": 2,
      "y": 14,
      "z": 8,
      "name": "Rock_Ice"
    },
    {
      "x": 2,
      "y": 15,
      "z": 8,
      "name": "Rock_Ice"
    },
    {
      "x": 2,
      "y": 16,
      "z": 8,
      "name": "Rock_Ice"
    },
    {
      "x": 2,
      "y": 17,
      "z": 8,
      "name": "Rock_Ice"
    },
    {
      "x": 2,
      "y": 18,
      "z": 8,
      "name": "Rock_Ice"
    },
    {
      "x": 2,
      "y": 19,
      "z": 8,
      "name": "Rock_Ice"
    },
    {
      "x": 2,
      "y": 13,
      "z": 9,
      "name": "Rock_Ice"
    },
    {
      "x": 2,
      "y": 14,
      "z": 9,
      "name": "Rock_Ice"
    },
    {
      "x": 2,
      "y": 15,
      "z": 9,
      "name": "Rock_Ice"
    },
    {
      "x": 2,
      "y": 16,
      "z": 9,
      "name": "Rock_Ice"
    },
    {
      "x": 2,
      "y": 17,
      "z": 9,
      "name": "Rock_Ice"
    },
    {
      "x": 2,
      "y": 18,
      "z": 9,
      "name": "Rock_Ice"
    },
    {
      "x": 2,
      "y": 12,
      "z": 10,
      "name": "Rock_Ice"
    },
    {
      "x": 2,
      "y": 13,
      "z": 10,
      "name": "Rock_Ice"
    },
    {
      "x": 2,
      "y": 14,
      "z": 10,
      "name": "Rock_Ice"
    },
    {
      "x": 2,
      "y": 15,
      "z": 10,
      "name": "Rock_Ice"
    },
    {
      "x": 2,
      "y": 16,
      "z": 10,
      "name": "Rock_Ice"
    },
    {
      "x": 2,
      "y": 17,
      "z": 10,
      "name": "Rock_Ice"
    },
    {
      "x": 2,
      "y": 11,
      "z": 11,
      "name": "Rock_Ice"
    },
    {
      "x": 2,
      "y": 12,
      "z": 11,
      "name": "Rock_Ice"
    },
    {
      "x": 2,
      "y": 13,
      "z": 11,
      "name": "Rock_Ice"
    },
    {
      "x": 2,
      "y": 14,
      "z": 11,
      "name": "Rock_Ice"
    },
    {
      "x": 2,
      "y": 15,
      "z": 11,
      "name": "Rock_Ice"
    },
    {
      "x": 2,
      "y": 16,
      "z": 11,
      "name": "Rock_Ice"
    },
    {
      "x": 2,
      "y": 11,
      "z": 12,
      "name": "Rock_Ice"
    },
    {
      "x": 2,
      "y": 12,
      "z": 12,
      "name": "Rock_Ice"
    },
    {
      "x": 2,
      "y": 13,
      "z": 12,
      "name": "Rock_Ice"
    },
    {
      "x": 2,
      "y": 14,
      "z": 12,
      "name": "Rock_Ice"
    },
    {
      "x": 2,
      "y": 15,
      "z": 12,
      "name": "Rock_Ice"
    },
    {
      "x": 2,
      "y": 11,
      "z": 13,
      "name": "Rock_Ice"
    },
    {
      "x": 2,
      "y": 12,
      "z": 13,
      "name": "Rock_Ice"
    },
    {
      "x": 2,
      "y": 13,
      "z": 13,
      "name": "Rock_Ice"
    },
    {
      "x": 2,
      "y": 18,
      "z": 13,
      "name": "Soil_Pebbles"
    },
    {
      "x": 3,
      "y": 13,
      "z": -15,
      "name": "Soil_Pebbles"
    },
    {
      "x": 3,
      "y": 12,
      "z": -14,
      "name": "Soil_Pebbles"
    },
    {
      "x": 3,
      "y": 13,
      "z": -14,
      "name": "Soil_Pebbles"
    },
    {
      "x": 3,
      "y": 10,
      "z": -13,
      "name": "Soil_Pebbles"
    },
    {
      "x": 3,
      "y": 11,
      "z": -13,
      "name": "Soil_Pebbles"
    },
    {
      "x": 3,
      "y": 9,
      "z": -12,
      "name": "Soil_Pebbles"
    },
    {
      "x": 3,
      "y": 8,
      "z": -11,
      "name": "Soil_Pebbles"
    },
    {
      "x": 3,
      "y": 8,
      "z": -10,
      "name": "Soil_Pebbles"
    },
    {
      "x": 3,
      "y": 7,
      "z": -9,
      "name": "Soil_Pebbles"
    },
    {
      "x": 3,
      "y": 8,
      "z": -9,
      "name": "Plant_Seaweed_Winter_Short"
    },
    {
      "x": 3,
      "y": 7,
      "z": -8,
      "name": "Soil_Pebbles"
    },
    {
      "x": 3,
      "y": 7,
      "z": -7,
      "name": "Soil_Pebbles"
    },
    {
      "x": 3,
      "y": 8,
      "z": -7,
      "name": "Plant_Seaweed_Winter_Short"
    },
    {
      "x": 3,
      "y": 7,
      "z": -6,
      "name": "Soil_Pebbles"
    },
    {
      "x": 3,
      "y": 7,
      "z": -5,
      "name": "Soil_Pebbles"
    },
    {
      "x": 3,
      "y": 8,
      "z": -5,
      "name": "Plant_Seaweed_Winter_Tall"
    },
    {
      "x": 3,
      "y": 9,
      "z": -5,
      "name": "Plant_Seaweed_Winter_Tall",
      "filler": 1024
    },
    {
      "x": 3,
      "y": 7,
      "z": -4,
      "name": "Soil_Pebbles"
    },
    {
      "x": 3,
      "y": 8,
      "z": -4,
      "name": "Plant_Seaweed_Winter_Tall"
    },
    {
      "x": 3,
      "y": 9,
      "z": -4,
      "name": "Plant_Seaweed_Winter_Tall",
      "filler": 1024
    },
    {
      "x": 3,
      "y": 6,
      "z": -3,
      "name": "Soil_Pebbles"
    },
    {
      "x": 3,
      "y": 7,
      "z": -3,
      "name": "Plant_Seaweed_Winter_Tall"
    },
    {
      "x": 3,
      "y": 8,
      "z": -3,
      "name": "Plant_Seaweed_Winter_Tall",
      "filler": 1024
    },
    {
      "x": 3,
      "y": 6,
      "z": -2,
      "name": "Soil_Pebbles"
    },
    {
      "x": 3,
      "y": 7,
      "z": -2,
      "name": "Plant_Seaweed_Winter_Tall"
    },
    {
      "x": 3,
      "y": 8,
      "z": -2,
      "name": "Plant_Seaweed_Winter_Tall",
      "filler": 1024
    },
    {
      "x": 3,
      "y": 24,
      "z": -2,
      "name": "Rock_Ice"
    },
    {
      "x": 3,
      "y": 6,
      "z": -1,
      "name": "Soil_Pebbles"
    },
    {
      "x": 3,
      "y": 10,
      "z": -1,
      "name": "Rock_Ice"
    },
    {
      "x": 3,
      "y": 11,
      "z": -1,
      "name": "Rock_Ice"
    },
    {
      "x": 3,
      "y": 12,
      "z": -1,
      "name": "Rock_Ice"
    },
    {
      "x": 3,
      "y": 13,
      "z": -1,
      "name": "Rock_Ice"
    },
    {
      "x": 3,
      "y": 22,
      "z": -1,
      "name": "Rock_Ice"
    },
    {
      "x": 3,
      "y": 23,
      "z": -1,
      "name": "Rock_Ice"
    },
    {
      "x": 3,
      "y": 24,
      "z": -1,
      "name": "Rock_Ice"
    },
    {
      "x": 3,
      "y": 25,
      "z": -1,
      "name": "Rock_Ice"
    },
    {
      "x": 3,
      "y": 6,
      "z": 0,
      "name": "Soil_Pebbles"
    },
    {
      "x": 3,
      "y": 8,
      "z": 0,
      "name": "Rock_Ice"
    },
    {
      "x": 3,
      "y": 9,
      "z": 0,
      "name": "Rock_Ice"
    },
    {
      "x": 3,
      "y": 10,
      "z": 0,
      "name": "Rock_Ice"
    },
    {
      "x": 3,
      "y": 11,
      "z": 0,
      "name": "Rock_Ice"
    },
    {
      "x": 3,
      "y": 12,
      "z": 0,
      "name": "Rock_Ice"
    },
    {
      "x": 3,
      "y": 5,
      "z": 1,
      "name": "Rock_Ice"
    },
    {
      "x": 3,
      "y": 6,
      "z": 1,
      "name": "Rock_Ice"
    },
    {
      "x": 3,
      "y": 7,
      "z": 1,
      "name": "Rock_Ice"
    },
    {
      "x": 3,
      "y": 8,
      "z": 1,
      "name": "Rock_Ice"
    },
    {
      "x": 3,
      "y": 9,
      "z": 1,
      "name": "Rock_Ice"
    },
    {
      "x": 3,
      "y": 10,
      "z": 1,
      "name": "Rock_Ice"
    },
    {
      "x": 3,
      "y": 1,
      "z": 2,
      "name": "Rock_Ice"
    },
    {
      "x": 3,
      "y": 2,
      "z": 2,
      "name": "Rock_Ice"
    },
    {
      "x": 3,
      "y": 3,
      "z": 2,
      "name": "Rock_Ice"
    },
    {
      "x": 3,
      "y": 4,
      "z": 2,
      "name": "Rock_Ice"
    },
    {
      "x": 3,
      "y": 5,
      "z": 2,
      "name": "Rock_Ice"
    },
    {
      "x": 3,
      "y": 6,
      "z": 2,
      "name": "Rock_Ice"
    },
    {
      "x": 3,
      "y": 1,
      "z": 3,
      "name": "Rock_Ice"
    },
    {
      "x": 3,
      "y": 2,
      "z": 3,
      "name": "Rock_Ice"
    },
    {
      "x": 3,
      "y": 3,
      "z": 3,
      "name": "Rock_Ice"
    },
    {
      "x": 3,
      "y": 4,
      "z": 3,
      "name": "Rock_Ice"
    },
    {
      "x": 3,
      "y": 5,
      "z": 3,
      "name": "Rock_Ice"
    },
    {
      "x": 3,
      "y": 7,
      "z": 3,
      "name": "Soil_Pebbles"
    },
    {
      "x": 3,
      "y": 8,
      "z": 4,
      "name": "Soil_Pebbles"
    },
    {
      "x": 3,
      "y": 8,
      "z": 5,
      "name": "Soil_Pebbles"
    },
    {
      "x": 3,
      "y": 18,
      "z": 5,
      "name": "Rock_Ice"
    },
    {
      "x": 3,
      "y": 19,
      "z": 5,
      "name": "Rock_Ice"
    },
    {
      "x": 3,
      "y": 17,
      "z": 6,
      "name": "Rock_Ice"
    },
    {
      "x": 3,
      "y": 18,
      "z": 6,
      "name": "Rock_Ice"
    },
    {
      "x": 3,
      "y": 19,
      "z": 6,
      "name": "Rock_Ice"
    },
    {
      "x": 3,
      "y": 16,
      "z": 7,
      "name": "Rock_Ice"
    },
    {
      "x": 3,
      "y": 17,
      "z": 7,
      "name": "Rock_Ice"
    },
    {
      "x": 3,
      "y": 18,
      "z": 7,
      "name": "Rock_Ice"
    },
    {
      "x": 3,
      "y": 15,
      "z": 8,
      "name": "Rock_Ice"
    },
    {
      "x": 3,
      "y": 16,
      "z": 8,
      "name": "Rock_Ice"
    },
    {
      "x": 3,
      "y": 17,
      "z": 8,
      "name": "Rock_Ice"
    },
    {
      "x": 3,
