{
  "version": 8,
  "blockIdVersion": 8,
  "anchorX": 1,
  "anchorY": 16,
  "anchorZ": 1,
  "blocks": [
    {
      "x": -22,
      "y": 16,
      "z": 2,
      "name": "Soil_Dirt_Dry"
    },
    {
      "x": -22,
      "y": 16,
      "z": 3,
      "name": "Soil_Dirt_Dry"
    },
    {
      "x": -22,
      "y": 16,
      "z": 4,
      "name": "Soil_Dirt_Dry"
    },
    {
      "x": -22,
      "y": 16,
      "z": 5,
      "name": "Soil_Dirt_Dry"
    },
    {
      "x": -21,
      "y": 16,
      "z": 0,
      "name": "Soil_Dirt_Dry"
    },
    {
      "x": -21,
      "y": 16,
      "z": 1,
      "name": "Soil_Dirt_Dry"
    },
    {
      "x": -21,
      "y": 17,
      "z": 1,
      "name": "Soil_Dirt_Dry"
    },
    {
      "x": -21,
      "y": 16,
      "z": 2,
      "name": "Soil_Dirt_Dry"
    },
    {
      "x": -21,
      "y": 17,
      "z": 2,
      "name": "Soil_Dirt_Dry"
    },
    {
      "x": -21,
      "y": 16,
      "z": 3,
      "name": "Soil_Dirt_Dry"
    },
    {
      "x": -21,
      "y": 17,
      "z": 3,
      "name": "Soil_Dirt_Dry"
    },
    {
      "x": -21,
      "y": 15,
      "z": 4,
      "name": "Rock_Sandstone_Stalactite_Small",
      "rotation": 8
    },
    {
      "x": -21,
      "y": 16,
      "z": 4,
      "name": "Soil_Dirt_Dry"
    },
    {
      "x": -21,
      "y": 17,
      "z": 4,
      "name": "Soil_Dirt_Dry"
    },
    {
      "x": -21,
      "y": 16,
      "z": 5,
      "name": "Soil_Dirt_Dry"
    },
    {
      "x": -21,
      "y": 17,
      "z": 5,
      "name": "Soil_Dirt_Dry"
    },
    {
      "x": -21,
      "y": 15,
      "z": 6,
      "name": "Rock_Sandstone"
    },
    {
      "x": -21,
      "y": 16,
      "z": 6,
      "name": "Soil_Dirt_Dry"
    },
    {
      "x": -21,
      "y": 17,
      "z": 6,
      "name": "Soil_Dirt_Dry"
    },
    {
      "x": -20,
      "y": 16,
      "z": -2,
      "name": "Soil_Dirt_Dry"
    },
    {
      "x": -20,
      "y": 16,
      "z": -1,
      "name": "Soil_Dirt_Dry"
    },
    {
      "x": -20,
      "y": 17,
      "z": -1,
      "name": "Soil_Dirt_Dry"
    },
    {
      "x": -20,
      "y": 16,
      "z": 0,
      "name": "Soil_Dirt_Dry"
    },
    {
      "x": -20,
      "y": 17,
      "z": 0,
      "name": "Soil_Dirt_Dry"
    },
    {
      "x": -20,
      "y": 16,
      "z": 1,
      "name": "Soil_Dirt_Dry"
    },
    {
      "x": -20,
      "y": 17,
      "z": 1,
      "name": "Soil_Dirt_Dry"
    },
    {
      "x": -20,
      "y": 16,
      "z": 2,
      "name": "Soil_Dirt_Dry"
    },
    {
      "x": -20,
      "y": 17,
      "z": 2,
      "name": "Soil_Dirt_Dry"
    },
    {
      "x": -20,
      "y": 16,
      "z": 3,
      "name": "Soil_Dirt_Dry"
    },
    {
      "x": -20,
      "y": 17,
      "z": 3,
      "name": "Soil_Dirt_Dry"
    },
    {
      "x": -20,
      "y": 16,
      "z": 4,
      "name": "Soil_Dirt_Dry"
    },
    {
      "x": -20,
      "y": 17,
      "z": 4,
      "name": "Soil_Dirt_Dry"
    },
    {
      "x": -20,
      "y": 16,
      "z": 5,
      "name": "Soil_Dirt_Dry"
    },
    {
      "x": -20,
      "y": 17,
      "z": 5,
      "name": "Soil_Dirt_Dry"
    },
    {
      "x": -20,
      "y": 15,
      "z": 6,
      "name": "Rock_Sandstone"
    },
    {
      "x": -20,
      "y": 16,
      "z": 6,
      "name": "Soil_Dirt_Dry"
    },
    {
      "x": -20,
      "y": 17,
      "z": 6,
      "name": "Soil_Dirt_Dry"
    },
    {
      "x": -20,
      "y": 13,
      "z": 7,
      "name": "Rock_Sandstone_Stalactite_Large",
      "filler": 31744,
      "rotation": 8
    },
    {
      "x": -20,
      "y": 14,
      "z": 7,
      "name": "Rock_Sandstone_Stalactite_Large",
      "rotation": 8
    },
    {
      "x": -20,
      "y": 15,
      "z": 7,
      "name": "Rock_Sandstone"
    },
    {
      "x": -20,
      "y": 16,
      "z": 7,
      "name": "Soil_Dirt_Dry"
    },
    {
      "x": -20,
      "y": 17,
      "z": 7,
      "name": "Soil_Dirt_Dry"
    },
    {
      "x": -20,
      "y": 16,
      "z": 8,
      "name": "Soil_Dirt_Dry"
    },
    {
      "x": -19,
      "y": 16,
      "z": -3,
      "name": "Soil_Dirt_Dry"
    },
    {
      "x": -19,
      "y": 16,
      "z": -2,
      "name": "Soil_Dirt_Dry"
    },
    {
      "x": -19,
      "y": 17,
      "z": -2,
      "name": "Soil_Dirt_Dry"
    },
    {
      "x": -19,
      "y": 16,
      "z": -1,
      "name": "Soil_Dirt_Dry"
    },
    {
      "x": -19,
      "y": 17,
      "z": -1,
      "name": "Soil_Dirt_Dry"
    },
    {
      "x": -19,
      "y": 16,
      "z": 0,
      "name": "Soil_Dirt_Dry"
    },
    {
      "x": -19,
      "y": 17,
      "z": 0,
      "name": "Soil_Dirt_Dry"
    },
    {
      "x": -19,
      "y": 16,
      "z": 1,
      "name": "Soil_Dirt_Dry"
    },
    {
      "x": -19,
      "y": 17,
      "z": 1,
      "name": "Soil_Sand_White"
    },
    {
      "x": -19,
      "y": 16,
      "z": 2,
      "name": "Soil_Dirt_Dry"
    },
    {
      "x": -19,
      "y": 17,
      "z": 2,
      "name": "Soil_Sand_White"
    },
    {
      "x": -19,
      "y": 16,
      "z": 3,
      "name": "Soil_Dirt_Dry"
    },
    {
      "x": -19,
      "y": 17,
      "z": 3,
      "name": "Soil_Sand_White"
    },
    {
      "x": -19,
      "y": 16,
      "z": 4,
      "name": "Soil_Dirt_Dry"
    },
    {
      "x": -19,
      "y": 17,
      "z": 4,
      "name": "Soil_Sand_White"
    },
    {
      "x": -19,
      "y": 16,
      "z": 5,
      "name": "Soil_Dirt_Dry"
    },
    {
      "x": -19,
      "y": 17,
      "z": 5,
      "name": "Soil_Sand_White"
    },
    {
      "x": -19,
      "y": 18,
      "z": 5,
      "name": "Soil_Sand_White"
    },
    {
      "x": -19,
      "y": 16,
      "z": 6,
      "name": "Soil_Dirt_Dry"
    },
    {
      "x": -19,
      "y": 17,
      "z": 6,
      "name": "Soil_Sand_White"
    },
    {
      "x": -19,
      "y": 18,
      "z": 6,
      "name": "Soil_Sand_White"
    },
    {
      "x": -19,
      "y": 15,
      "z": 7,
      "name": "Rock_Sandstone"
    },
    {
      "x": -19,
      "y": 16,
      "z": 7,
      "name": "Soil_Dirt_Dry"
    },
    {
      "x": -19,
      "y": 17,
      "z": 7,
      "name": "Soil_Dirt_Dry"
    },
    {
      "x": -19,
      "y": 14,
      "z": 8,
      "name": "Rock_Sandstone"
    },
    {
      "x": -19,
      "y": 15,
      "z": 8,
      "name": "Rock_Sandstone"
    },
    {
      "x": -19,
      "y": 16,
      "z": 8,
      "name": "Soil_Dirt_Dry"
    },
    {
      "x": -19,
      "y": 17,
      "z": 8,
      "name": "Soil_Dirt_Dry"
    },
    {
      "x": -19,
      "y": 12,
      "z": 9,
      "name": "Rock_Sandstone_Stalactite_Large",
      "filler": 31744,
      "rotation": 8
    },
    {
      "x": -19,
      "y": 13,
      "z": 9,
      "name": "Rock_Sandstone_Stalactite_Large",
      "rotation": 8
    },
    {
      "x": -19,
      "y": 14,
      "z": 9,
      "name": "Rock_Sandstone"
    },
    {
      "x": -19,
      "y": 15,
      "z": 9,
      "name": "Rock_Sandstone"
    },
    {
      "x": -19,
      "y": 16,
      "z": 9,
      "name": "Soil_Dirt_Dry"
    },
    {
      "x": -18,
      "y": 16,
      "z": -3,
      "name": "Soil_Dirt_Dry"
    },
    {
      "x": -18,
      "y": 17,
      "z": -3,
      "name": "Soil_Dirt_Dry"
    },
    {
      "x": -18,
      "y": 16,
      "z": -2,
      "name": "Soil_Dirt_Dry"
    },
    {
      "x": -18,
      "y": 17,
      "z": -2,
      "name": "Soil_Sand_White"
    },
    {
      "x": -18,
      "y": 16,
      "z": -1,
      "name": "Soil_Dirt_Dry"
    },
    {
      "x": -18,
      "y": 17,
      "z": -1,
      "name": "Soil_Sand_White"
    },
    {
      "x": -18,
      "y": 16,
      "z": 0,
      "name": "Soil_Dirt_Dry"
    },
    {
      "x": -18,
      "y": 17,
      "z": 0,
      "name": "Soil_Sand_White"
    },
    {
      "x": -18,
      "y": 16,
      "z": 1,
      "name": "Soil_Dirt_Dry"
    },
    {
      "x": -18,
      "y": 17,
      "z": 1,
      "name": "Soil_Sand_White"
    },
    {
      "x": -18,
      "y": 16,
      "z": 2,
      "name": "Soil_Dirt_Dry"
    },
    {
      "x": -18,
      "y": 17,
      "z": 2,
      "name": "Soil_Sand_White"
    },
    {
      "x": -18,
      "y": 16,
      "z": 3,
      "name": "Soil_Dirt_Dry"
    },
    {
      "x": -18,
      "y": 17,
      "z": 3,
      "name": "Soil_Sand_White"
    },
    {
      "x": -18,
      "y": 16,
      "z": 4,
      "name": "Soil_Dirt_Dry"
    },
    {
      "x": -18,
      "y": 17,
      "z": 4,
      "name": "Soil_Sand_White"
    },
    {
      "x": -18,
      "y": 18,
      "z": 4,
      "name": "Soil_Sand_White"
    },
    {
      "x": -18,
      "y": 16,
      "z": 5,
      "name": "Soil_Dirt_Dry"
    },
    {
      "x": -18,
      "y": 17,
      "z": 5,
      "name": "Soil_Sand_White"
    },
    {
      "x": -18,
      "y": 18,
      "z": 5,
      "name": "Soil_Sand_White"
    },
    {
      "x": -18,
      "y": 16,
      "z": 6,
      "name": "Soil_Dirt_Dry"
    },
    {
      "x": -18,
      "y": 17,
      "z": 6,
      "name": "Soil_Sand_White"
    },
    {
      "x": -18,
      "y": 18,
      "z": 6,
      "name": "Soil_Sand_White"
    },
    {
      "x": -18,
      "y": 15,
      "z": 7,
      "name": "Rock_Sandstone"
    },
    {
      "x": -18,
      "y": 16,
      "z": 7,
      "name": "Soil_Dirt_Dry"
    },
    {
      "x": -18,
      "y": 17,
      "z": 7,
      "name": "Soil_Sand_White"
    },
    {
      "x": -18,
      "y": 18,
      "z": 7,
      "name": "Soil_Sand_White"
    },
    {
      "x": -18,
      "y": 14,
      "z": 8,
      "name": "Rock_Sandstone"
    },
    {
      "x": -18,
      "y": 15,
      "z": 8,
      "name": "Rock_Sandstone"
    },
    {
      "x": -18,
      "y": 16,
      "z": 8,
      "name": "Soil_Dirt_Dry"
    },
    {
      "x": -18,
      "y": 17,
      "z": 8,
      "name": "Soil_Sand_White"
    },
    {
      "x": -18,
      "y": 14,
      "z": 9,
      "name": "Rock_Sandstone"
    },
    {
      "x": -18,
      "y": 15,
      "z": 9,
      "name": "Rock_Sandstone"
    },
    {
      "x": -18,
      "y": 16,
      "z": 9,
      "name": "Soil_Dirt_Dry"
    },
    {
      "x": -18,
      "y": 16,
      "z": 10,
      "name": "Soil_Dirt_Dry"
    },
    {
      "x": -17,
      "y": 16,
      "z": -4,
      "name": "Soil_Dirt_Dry"
    },
    {
      "x": -17,
      "y": 16,
      "z": -3,
      "name": "Soil_Dirt_Dry"
    },
    {
      "x": -17,
      "y": 17,
      "z": -3,
      "name": "Soil_Sand_White"
    },
    {
      "x": -17,
      "y": 16,
      "z": -2,
      "name": "Soil_Dirt_Dry"
    },
    {
      "x": -17,
      "y": 17,
      "z": -2,
      "name": "Soil_Sand_White"
    },
    {
      "x": -17,
      "y": 16,
      "z": -1,
      "name": "Soil_Dirt_Dry"
    },
    {
      "x": -17,
      "y": 17,
      "z": -1,
      "name": "Soil_Sand_White"
    },
    {
      "x": -17,
      "y": 16,
      "z": 0,
      "name": "Soil_Dirt_Dry"
    },
    {
      "x": -17,
      "y": 17,
      "z": 0,
      "name": "Soil_Sand_White"
    },
    {
      "x": -17,
      "y": 18,
      "z": 0,
      "name": "Empty"
    },
    {
      "x": -17,
      "y": 19,
      "z": 0,
      "name": "Empty"
    },
    {
      "x": -17,
      "y": 20,
      "z": 0,
      "name": "Empty"
    },
    {
      "x": -17,
      "y": 21,
      "z": 0,
      "name": "Empty"
    },
    {
      "x": -17,
      "y": 22,
      "z": 0,
      "name": "Empty"
    },
    {
      "x": -17,
      "y": 16,
      "z": 1,
      "name": "Soil_Dirt_Dry"
    },
    {
      "x": -17,
      "y": 17,
      "z": 1,
      "name": "Soil_Sand_White"
    },
    {
      "x": -17,
      "y": 18,
      "z": 1,
      "name": "Empty"
    },
    {
      "x": -17,
      "y": 19,
      "z": 1,
      "name": "Empty"
    },
    {
      "x": -17,
      "y": 20,
      "z": 1,
      "name": "Empty"
    },
    {
      "x": -17,
      "y": 21,
      "z": 1,
      "name": "Empty"
    },
    {
      "x": -17,
      "y": 22,
      "z": 1,
      "name": "Empty"
    },
    {
      "x": -17,
      "y": 23,
      "z": 1,
      "name": "Empty"
    },
    {
      "x": -17,
      "y": 16,
      "z": 2,
      "name": "Soil_Dirt_Dry"
    },
    {
      "x": -17,
      "y": 17,
      "z": 2,
      "name": "Soil_Sand_White"
    },
    {
      "x": -17,
      "y": 18,
      "z": 2,
      "name": "Soil_Sand_White"
    },
    {
      "x": -17,
      "y": 19,
      "z": 2,
      "name": "Empty"
    },
    {
      "x": -17,
      "y": 20,
      "z": 2,
      "name": "Empty"
    },
    {
      "x": -17,
      "y": 21,
      "z": 2,
      "name": "Empty"
    },
    {
      "x": -17,
      "y": 22,
      "z": 2,
      "name": "Empty"
    },
    {
      "x": -17,
      "y": 16,
      "z": 3,
      "name": "Soil_Dirt_Dry"
    },
    {
      "x": -17,
      "y": 17,
      "z": 3,
      "name": "Soil_Sand_White"
    },
    {
      "x": -17,
      "y": 18,
      "z": 3,
      "name": "Soil_Sand_White"
    },
    {
      "x": -17,
      "y": 16,
      "z": 4,
      "name": "Soil_Dirt_Dry"
    },
    {
      "x": -17,
      "y": 17,
      "z": 4,
      "name": "Soil_Sand_White"
    },
    {
      "x": -17,
      "y": 18,
      "z": 4,
      "name": "Soil_Sand_White"
    },
    {
      "x": -17,
      "y": 16,
      "z": 5,
      "name": "Soil_Dirt_Dry"
    },
    {
      "x": -17,
      "y": 17,
      "z": 5,
      "name": "Soil_Sand_White"
    },
    {
      "x": -17,
      "y": 18,
      "z": 5,
      "name": "Soil_Sand_White"
    },
    {
      "x": -17,
      "y": 16,
      "z": 6,
      "name": "Soil_Dirt_Dry"
    },
    {
      "x": -17,
      "y": 17,
      "z": 6,
      "name": "Soil_Sand_White"
    },
    {
      "x": -17,
      "y": 18,
      "z": 6,
      "name": "Soil_Sand_White"
    },
    {
      "x": -17,
      "y": 19,
      "z": 6,
      "name": "Soil_Sand_White"
    },
    {
      "x": -17,
      "y": 16,
      "z": 7,
      "name": "Soil_Dirt_Dry"
    },
    {
      "x": -17,
      "y": 17,
      "z": 7,
      "name": "Soil_Sand_White"
    },
    {
      "x": -17,
      "y": 18,
      "z": 7,
      "name": "Soil_Sand_White"
    },
    {
      "x": -17,
      "y": 19,
      "z": 7,
      "name": "Soil_Sand_White"
    },
    {
      "x": -17,
      "y": 16,
      "z": 8,
      "name": "Soil_Dirt_Dry"
    },
    {
      "x": -17,
      "y": 17,
      "z": 8,
      "name": "Soil_Sand_White"
    },
    {
      "x": -17,
      "y": 18,
      "z": 8,
      "name": "Soil_Sand_White"
    },
    {
      "x": -17,
      "y": 13,
      "z": 9,
      "name": "Rock_Sandstone_Stalactite_Small",
      "rotation": 8
    },
    {
      "x": -17,
      "y": 14,
      "z": 9,
      "name": "Rock_Sandstone"
    },
    {
      "x": -17,
      "y": 15,
      "z": 9,
      "name": "Rock_Sandstone"
    },
    {
      "x": -17,
      "y": 16,
      "z": 9,
      "name": "Soil_Dirt_Dry"
    },
    {
      "x": -17,
      "y": 17,
      "z": 9,
      "name": "Soil_Sand_White"
    },
    {
      "x": -17,
      "y": 15,
      "z": 10,
      "name": "Rock_Sandstone"
    },
    {
      "x": -17,
      "y": 16,
      "z": 10,
      "name": "Soil_Dirt_Dry"
    },
    {
      "x": -16,
      "y": 16,
      "z": -4,
      "name": "Soil_Dirt_Dry"
    },
    {
      "x": -16,
      "y": 17,
      "z": -4,
      "name": "Soil_Sand_White"
    },
    {
      "x": -16,
      "y": 16,
      "z": -3,
      "name": "Soil_Dirt_Dry"
    },
    {
      "x": -16,
      "y": 17,
      "z": -3,
      "name": "Soil_Sand_White"
    },
    {
      "x": -16,
      "y": 16,
      "z": -2,
      "name": "Soil_Dirt_Dry"
    },
    {
      "x": -16,
      "y": 17,
      "z": -2,
      "name": "Soil_Sand_White"
    },
    {
      "x": -16,
      "y": 16,
      "z": -1,
      "name": "Soil_Dirt_Dry"
    },
    {
      "x": -16,
      "y": 17,
      "z": -1,
      "name": "Soil_Sand_White"
    },
    {
      "x": -16,
      "y": 18,
      "z": -1,
      "name": "Empty"
    },
    {
      "x": -16,
      "y": 19,
      "z": -1,
      "name": "Empty"
    },
    {
      "x": -16,
      "y": 20,
      "z": -1,
      "name": "Empty"
    },
    {
      "x": -16,
      "y": 21,
      "z": -1,
      "name": "Empty"
    },
    {
      "x": -16,
      "y": 22,
      "z": -1,
      "name": "Empty"
    },
    {
      "x": -16,
      "y": 16,
      "z": 0,
      "name": "Soil_Dirt_Dry"
    },
    {
      "x": -16,
      "y": 17,
      "z": 0,
      "name": "Soil_Sand_White"
    },
    {
      "x": -16,
      "y": 18,
      "z": 0,
      "name": "Soil_Sand_White"
    },
    {
      "x": -16,
      "y": 19,
      "z": 0,
      "name": "Empty"
    },
    {
      "x": -16,
      "y": 20,
      "z": 0,
      "name": "Empty"
    },
    {
      "x": -16,
      "y": 21,
      "z": 0,
      "name": "Empty"
    },
    {
      "x": -16,
      "y": 22,
      "z": 0,
      "name": "Empty"
    },
    {
      "x": -16,
      "y": 23,
      "z": 0,
      "name": "Empty"
    },
    {
      "x": -16,
      "y": 24,
      "z": 0,
      "name": "Empty"
    },
    {
      "x": -16,
      "y": 25,
      "z": 0,
      "name": "Empty"
    },
    {
      "x": -16,
      "y": 16,
      "z": 1,
      "name": "Soil_Dirt_Dry"
    },
    {
      "x": -16,
      "y": 17,
      "z": 1,
      "name": "Soil_Sand_White"
    },
    {
      "x": -16,
      "y": 18,
      "z": 1,
      "name": "Soil_Sand_White"
    },
    {
      "x": -16,
      "y": 19,
      "z": 1,
      "name": "Empty"
    },
    {
      "x": -16,
      "y": 20,
      "z": 1,
      "name": "Empty"
    },
    {
      "x": -16,
      "y": 21,
      "z": 1,
      "name": "Empty"
    },
    {
      "x": -16,
      "y": 22,
      "z": 1,
      "name": "Empty"
    },
    {
      "x": -16,
      "y": 23,
      "z": 1,
      "name": "Empty"
    },
    {
      "x": -16,
      "y": 24,
      "z": 1,
      "name": "Empty"
    },
    {
      "x": -16,
      "y": 25,
      "z": 1,
      "name": "Empty"
    },
    {
      "x": -16,
      "y": 16,
      "z": 2,
      "name": "Soil_Dirt_Dry"
    },
    {
      "x": -16,
      "y": 17,
      "z": 2,
      "name": "Soil_Sand_White"
    },
    {
      "x": -16,
      "y": 18,
      "z": 2,
      "name": "Soil_Sand_White"
    },
    {
      "x": -16,
      "y": 19,
      "z": 2,
      "name": "Empty"
    },
    {
      "x": -16,
      "y": 20,
      "z": 2,
      "name": "Empty"
    },
    {
      "x": -16,
      "y": 21,
      "z": 2,
      "name": "Empty"
    },
    {
      "x": -16,
      "y": 22,
      "z": 2,
      "name": "Empty"
    },
    {
      "x": -16,
      "y": 23,
      "z": 2,
      "name": "Empty"
    },
    {
      "x": -16,
      "y": 24,
      "z": 2,
      "name": "Empty"
    },
    {
      "x": -16,
      "y": 25,
      "z": 2,
      "name": "Empty"
    },
    {
      "x": -16,
      "y": 16,
      "z": 3,
      "name": "Soil_Dirt_Dry"
    },
    {
      "x": -16,
      "y": 17,
      "z": 3,
      "name": "Soil_Sand_White"
    },
    {
      "x": -16,
      "y": 18,
      "z": 3,
      "name": "Soil_Sand_White"
    },
    {
      "x": -16,
      "y": 19,
      "z": 3,
      "name": "Empty"
    },
    {
      "x": -16,
      "y": 20,
      "z": 3,
      "name": "Empty"
    },
    {
      "x": -16,
      "y": 21,
      "z": 3,
      "name": "Empty"
    },
    {
      "x": -16,
      "y": 22,
      "z": 3,
      "name": "Empty"
    },
    {
      "x": -16,
      "y": 23,
      "z": 3,
      "name": "Empty"
    },
    {
      "x": -16,
      "y": 24,
      "z": 3,
      "name": "Empty"
    },
    {
      "x": -16,
      "y": 16,
      "z": 4,
      "name": "Soil_Dirt_Dry"
    },
    {
      "x": -16,
      "y": 17,
      "z": 4,
      "name": "Soil_Sand_White"
    },
    {
      "x": -16,
      "y": 18,
      "z": 4,
      "name": "Soil_Grass_Dry"
    },
    {
      "x": -16,
      "y": 19,
      "z": 4,
      "name": "Plant_Grass_Arid"
    },
    {
      "x": -16,
      "y": 20,
      "z": 4,
      "name": "Empty"
    },
    {
      "x": -16,
      "y": 21,
      "z": 4,
      "name": "Empty"
    },
    {
      "x": -16,
      "y": 22,
      "z": 4,
      "name": "Empty"
    },
    {
      "x": -16,
      "y": 16,
      "z": 5,
      "name": "Soil_Dirt_Dry"
    },
    {
      "x": -16,
      "y": 17,
      "z": 5,
      "name": "Soil_Sand_White"
    },
    {
      "x": -16,
      "y": 18,
      "z": 5,
      "name": "Soil_Sand_White"
    },
    {
      "x": -16,
      "y": 19,
      "z": 5,
      "name": "Soil_Sand_White"
    },
    {
      "x": -16,
      "y": 16,
      "z": 6,
      "name": "Soil_Dirt_Dry"
    },
    {
      "x": -16,
      "y": 17,
      "z": 6,
      "name": "Soil_Sand_White"
    },
    {
      "x": -16,
      "y": 18,
      "z": 6,
      "name": "Soil_Sand_White"
    },
    {
      "x": -16,
      "y": 19,
      "z": 6,
      "name": "Soil_Sand_White"
    },
    {
      "x": -16,
      "y": 16,
      "z": 7,
      "name": "Soil_Dirt_Dry"
    },
    {
      "x": -16,
      "y": 17,
      "z": 7,
      "name": "Soil_Sand_White"
    },
    {
      "x": -16,
      "y": 18,
      "z": 7,
      "name": "Soil_Sand_White"
    },
    {
      "x": -16,
      "y": 19,
      "z": 7,
      "name": "Soil_Sand_White"
    },
    {
      "x": -16,
      "y": 16,
      "z": 8,
      "name": "Soil_Dirt_Dry"
    },
    {
      "x": -16,
      "y": 17,
      "z": 8,
      "name": "Soil_Sand_White"
    },
    {
      "x": -16,
      "y": 18,
      "z": 8,
      "name": "Soil_Sand_White"
    },
    {
      "x": -16,
      "y": 19,
      "z": 8,
      "name": "Soil_Sand_White"
    },
    {
      "x": -16,
      "y": 16,
      "z": 9,
      "name": "Soil_Dirt_Dry"
    },
    {
      "x": -16,
      "y": 17,
      "z": 9,
      "name": "Soil_Sand_White"
    },
    {
      "x": -16,
      "y": 18,
      "z": 9,
      "name": "Soil_Sand_White"
    },
    {
      "x": -16,
      "y": 15,
      "z": 10,
      "name": "Rock_Sandstone"
    },
    {
      "x": -16,
      "y": 16,
      "z": 10,
      "name": "Soil_Dirt_Dry"
    },
    {
      "x": -16,
      "y": 17,
      "z": 10,
      "name": "Soil_Sand_White"
    },
    {
      "x": -16,
      "y": 15,
      "z": 11,
      "name": "Rock_Sandstone"
    },
    {
      "x": -16,
      "y": 16,
      "z": 11,
      "name": "Soil_Dirt_Dry"
    },
    {
      "x": -16,
      "y": 16,
      "z": 12,
      "name": "Soil_Dirt_Dry"
    },
    {
      "x": -15,
      "y": 16,
      "z": -5,
      "name": "Soil_Dirt_Dry"
    },
    {
      "x": -15,
      "y": 16,
      "z": -4,
      "name": "Soil_Dirt_Dry"
    },
    {
      "x": -15,
      "y": 17,
      "z": -4,
      "name": "Soil_Sand_White"
    },
    {
      "x": -15,
      "y": 16,
      "z": -3,
      "name": "Soil_Dirt_Dry"
    },
    {
      "x": -15,
      "y": 17,
      "z": -3,
      "name": "Soil_Sand_White"
    },
    {
      "x": -15,
      "y": 16,
      "z": -2,
      "name": "Soil_Dirt_Dry"
    },
    {
      "x": -15,
      "y": 17,
      "z": -2,
      "name": "Soil_Sand_White"
    },
    {
      "x": -15,
      "y": 16,
      "z": -1,
      "name": "Soil_Dirt_Dry"
    },
    {
      "x": -15,
      "y": 17,
      "z": -1,
      "name": "Soil_Sand_White"
    },
    {
      "x": -15,
      "y": 18,
      "z": -1,
      "name": "Soil_Sand_White"
    },
    {
      "x": -15,
      "y": 19,
      "z": -1,
      "name": "Empty"
    },
    {
      "x": -15,
      "y": 20,
      "z": -1,
      "name": "Empty"
    },
    {
      "x": -15,
      "y": 21,
      "z": -1,
      "name": "Empty"
    },
    {
      "x": -15,
      "y": 22,
      "z": -1,
      "name": "Empty"
    },
    {
      "x": -15,
      "y": 23,
      "z": -1,
      "name": "Empty"
    },
    {
      "x": -15,
      "y": 16,
      "z": 0,
      "name": "Soil_Dirt_Dry"
    },
    {
      "x": -15,
      "y": 17,
      "z": 0,
      "name": "Soil_Sand_White"
    },
    {
      "x": -15,
      "y": 18,
      "z": 0,
      "name": "Soil_Sand_White"
    },
    {
      "x": -15,
      "y": 19,
      "z": 0,
      "name": "Empty"
    },
    {
      "x": -15,
      "y": 20,
      "z": 0,
      "name": "Empty"
    },
    {
      "x": -15,
      "y": 21,
      "z": 0,
      "name": "Empty"
    },
    {
      "x": -15,
      "y": 22,
      "z": 0,
      "name": "Empty"
    },
    {
      "x": -15,
      "y": 23,
      "z": 0,
      "name": "Empty"
    },
    {
      "x": -15,
      "y": 24,
      "z": 0,
      "name": "Empty"
    },
    {
      "x": -15,
      "y": 25,
      "z": 0,
      "name": "Empty"
    },
    {
      "x": -15,
      "y": 16,
      "z": 1,
      "name": "Soil_Dirt_Dry"
    },
    {
      "x": -15,
      "y": 17,
      "z": 1,
      "name": "Soil_Sand_White"
    },
    {
      "x": -15,
      "y": 18,
      "z": 1,
      "name": "Soil_Sand_White"
    },
    {
      "x": -15,
      "y": 19,
      "z": 1,
      "name": "Empty"
    },
    {
      "x": -15,
      "y": 20,
      "z": 1,
      "name": "Empty"
    },
    {
      "x": -15,
      "y": 21,
      "z": 1,
      "name": "Empty"
    },
    {
      "x": -15,
      "y": 22,
      "z": 1,
      "name": "Empty"
    },
    {
      "x": -15,
      "y": 23,
      "z": 1,
      "name": "Empty"
    },
    {
      "x": -15,
      "y": 24,
      "z": 1,
      "name": "Empty"
    },
    {
      "x": -15,
      "y": 25,
      "z": 1,
      "name": "Empty"
    },
    {
      "x": -15,
      "y": 26,
      "z": 1,
      "name": "Empty"
    },
    {
      "x": -15,
      "y": 16,
      "z": 2,
      "name": "Soil_Dirt_Dry"
    },
    {
      "x": -15,
      "y": 17,
      "z": 2,
      "name": "Soil_Sand_White"
    },
    {
      "x": -15,
      "y": 18,
      "z": 2,
      "name": "Soil_Sand_White"
    },
    {
      "x": -15,
      "y": 19,
      "z": 2,
      "name": "Empty"
    },
    {
      "x": -15,
      "y": 20,
      "z": 2,
      "name": "Empty"
    },
    {
      "x": -15,
      "y": 21,
      "z": 2,
      "name": "Empty"
    },
    {
      "x": -15,
      "y": 22,
      "z": 2,
      "name": "Empty"
    },
    {
      "x": -15,
      "y": 23,
      "z": 2,
      "name": "Empty"
    },
    {
      "x": -15,
      "y": 24,
      "z": 2,
      "name": "Empty"
    },
    {
      "x": -15,
      "y": 25,
      "z": 2,
      "name": "Empty"
    },
    {
      "x": -15,
      "y": 16,
      "z": 3,
      "name": "Soil_Dirt_Dry"
    },
    {
      "x": -15,
      "y": 17,
      "z": 3,
      "name": "Soil_Sand_White"
    },
    {
      "x": -15,
      "y": 18,
      "z": 3,
      "name": "Soil_Grass_Dry"
    },
    {
      "x": -15,
      "y": 19,
      "z": 3,
      "name": "Plant_Flower_Common_Cyan"
    },
    {
      "x": -15,
      "y": 20,
      "z": 3,
      "name": "Empty"
    },
    {
      "x": -15,
      "y": 21,
      "z": 3,
      "name": "Empty"
    },
    {
      "x": -15,
      "y": 22,
      "z": 3,
      "name": "Empty"
    },
    {
      "x": -15,
      "y": 23,
      "z": 3,
      "name": "Empty"
    },
    {
      "x": -15,
      "y": 24,
      "z": 3,
      "name": "Empty"
    },
    {
      "x": -15,
      "y": 25,
      "z": 3,
      "name": "Empty"
    },
    {
      "x": -15,
      "y": 16,
      "z": 4,
      "name": "Soil_Dirt_Dry"
    },
    {
      "x": -15,
      "y": 17,
      "z": 4,
      "name": "Soil_Sand_White"
    },
    {
      "x": -15,
      "y": 18,
      "z": 4,
      "name": "Soil_Grass_Dry"
    },
    {
      "x": -15,
      "y": 19,
      "z": 4,
      "name": "Plant_Grass_Arid_Tall"
    },
    {
      "x": -15,
      "y": 20,
      "z": 4,
      "name": "Empty"
    },
    {
      "x": -15,
      "y": 21,
      "z": 4,
      "name": "Empty"
    },
    {
      "x": -15,
      "y": 22,
      "z": 4,
      "name": "Empty"
    },
    {
      "x": -15,
      "y": 23,
      "z": 4,
      "name": "Empty"
    },
    {
      "x": -15,
      "y": 24,
      "z": 4,
      "name": "Empty"
    },
    {
      "x": -15,
      "y": 25,
      "z": 4,
      "name": "Empty"
    },
    {
      "x": -15,
      "y": 16,
      "z": 5,
      "name": "Soil_Dirt_Dry"
    },
    {
      "x": -15,
      "y": 17,
      "z": 5,
      "name": "Soil_Sand_White"
    },
    {
      "x": -15,
      "y": 18,
      "z": 5,
      "name": "Soil_Sand_White"
    },
    {
      "x": -15,
      "y": 19,
      "z": 5,
      "name": "Soil_Sand_White"
    },
    {
      "x": -15,
      "y": 20,
      "z": 5,
      "name": "Empty"
    },
    {
      "x": -15,
      "y": 21,
      "z": 5,
      "name": "Empty"
    },
    {
      "x": -15,
      "y": 22,
      "z": 5,
      "name": "Empty"
    },
    {
      "x": -15,
      "y": 16,
      "z": 6,
      "name": "Soil_Dirt_Dry"
    },
    {
      "x": -15,
      "y": 17,
      "z": 6,
      "name": "Soil_Sand_White"
    },
    {
      "x": -15,
      "y": 18,
      "z": 6,
      "name": "Soil_Sand_White"
    },
    {
      "x": -15,
      "y": 19,
      "z": 6,
      "name": "Soil_Sand_White"
    },
    {
      "x": -15,
      "y": 20,
      "z": 6,
      "name": "Soil_Sand_White"
    },
    {
      "x": -15,
      "y": 16,
      "z": 7,
      "name": "Soil_Dirt_Dry"
    },
    {
      "x": -15,
      "y": 17,
      "z": 7,
      "name": "Soil_Sand_White"
    },
    {
      "x": -15,
      "y": 18,
      "z": 7,
      "name": "Soil_Sand_White"
    },
    {
      "x": -15,
      "y": 19,
      "z": 7,
      "name": "Soil_Sand_White"
    },
    {
      "x": -15,
      "y": 20,
      "z": 7,
      "name": "Soil_Sand_White"
    },
    {
      "x": -15,
      "y": 16,
      "z": 8,
      "name": "Soil_Dirt_Dry"
    },
    {
      "x": -15,
      "y": 17,
      "z": 8,
      "name": "Soil_Sand_White"
    },
    {
      "x": -15,
      "y": 18,
      "z": 8,
      "name": "Soil_Sand_White"
    },
    {
      "x": -15,
      "y": 19,
      "z": 8,
      "name": "Soil_Sand_White"
    },
    {
      "x": -15,
      "y": 16,
      "z": 9,
      "name": "Soil_Dirt_Dry"
    },
    {
      "x": -15,
      "y": 17,
      "z": 9,
      "name": "Soil_Sand_White"
    },
    {
      "x": -15,
      "y": 18,
      "z": 9,
      "name": "Soil_Sand_White"
    },
    {
      "x": -15,
      "y": 19,
      "z": 9,
      "name": "Soil_Sand_White"
    },
    {
      "x": -15,
      "y": 16,
      "z": 10,
      "name": "Soil_Dirt_Dry"
    },
    {
      "x": -15,
      "y": 17,
      "z": 10,
      "name": "Soil_Sand_White"
    },
    {
      "x": -15,
      "y": 18,
      "z": 10,
      "name": "Soil_Sand_White"
    },
    {
      "x": -15,
      "y": 16,
      "z": 11,
      "name": "Soil_Dirt_Dry"
    },
    {
      "x": -15,
      "y": 17,
      "z": 11,
      "name": "Soil_Sand_White"
    },
    {
      "x": -15,
      "y": 15,
      "z": 12,
      "name": "Rock_Sandstone"
    },
    {
      "x": -15,
      "y": 16,
      "z": 12,
      "name": "Soil_Dirt_Dry"
    },
    {
      "x": -15,
      "y": 17,
      "z": 12,
      "name": "Soil_Sand_White"
    },
    {
      "x": -15,
      "y": 16,
      "z": 13,
      "name": "Soil_Dirt_Dry"
    },
    {
      "x": -15,
      "y": 17,
      "z": 13,
      "name": "Soil_Dirt_Dry"
    },
    {
      "x": -15,
      "y": 16,
      "z": 14,
      "name": "Soil_Dirt_Dry"
    },
    {
      "x": -14,
      "y": 16,
      "z": -6,
      "name": "Rock_Sandstone"
    },
    {
      "x": -14,
      "y": 16,
      "z": -5,
      "name": "Rock_Sandstone"
    },
    {
      "x": -14,
      "y": 17,
      "z": -5,
      "name": "Rock_Sandstone"
    },
    {
      "x": -14,
      "y": 18,
      "z": -5,
      "name": "Rock_Sandstone"
    },
    {
      "x": -14,
      "y": 19,
      "z": -5,
      "name": "Rock_Sandstone"
    },
    {
      "x": -14,
      "y": 14,
      "z": -4,
      "name": "Rock_Sandstone_Stalactite_Large",
      "filler": 31744,
      "rotation": 8
    },
    {
      "x": -14,
      "y": 15,
      "z": -4,
      "name": "Rock_Sandstone_Stalactite_Large",
      "rotation": 8
    },
    {
      "x": -14,
      "y": 16,
      "z": -4,
      "name": "Rock_Sandstone"
    },
    {
      "x": -14,
      "y": 17,
      "z": -4,
      "name": "Rock_Sandstone"
    },
    {
      "x": -14,
      "y": 18,
      "z": -4,
      "name": "Rock_Sandstone"
    },
    {
      "x": -14,
      "y": 19,
      "z": -4,
      "name": "Rock_Sandstone"
    },
    {
      "x": -14,
      "y": 20,
      "z": -4,
      "name": "Rock_Sandstone"
    },
    {
      "x": -14,
      "y": 16,
      "z": -3,
      "name": "Soil_Dirt_Dry"
    },
    {
      "x": -14,
      "y": 17,
      "z": -3,
      "name": "Rock_Sandstone"
    },
    {
      "x": -14,
      "y": 18,
      "z": -3,
      "name": "Rock_Sandstone"
    },
    {
      "x": -14,
      "y": 19,
      "z": -3,
      "name": "Rock_Sandstone"
    },
    {
      "x": -14,
      "y": 20,
      "z": -3,
      "name": "Rock_Sandstone"
    },
    {
      "x": -14,
      "y": 16,
      "z": -2,
      "name": "Soil_Dirt_Dry"
    },
    {
      "x": -14,
      "y": 17,
      "z": -2,
      "name": "Soil_Sand_White"
    },
    {
      "x": -14,
      "y": 18,
      "z": -2,
      "name": "Soil_Sand_White"
    },
    {
      "x": -14,
      "y": 19,
      "z": -2,
      "name": "Rubble_Sandstone_White_Medium"
    },
    {
      "x": -14,
      "y": 16,
      "z": -1,
      "name": "Soil_Dirt_Dry"
    },
    {
      "x": -14,
      "y": 17,
      "z": -1,
      "name": "Soil_Sand_White"
    },
    {
      "x": -14,
      "y": 18,
      "z": -1,
      "name": "Soil_Sand_White"
    },
    {
      "x": -14,
      "y": 19,
      "z": -1,
      "name": "Empty"
    },
    {
      "x": -14,
      "y": 20,
      "z": -1,
      "name": "Empty"
    },
    {
      "x": -14,
      "y": 21,
      "z": -1,
      "name": "Empty"
    },
    {
      "x": -14,
      "y": 22,
      "z": -1,
      "name": "Empty"
    },
    {
      "x": -14,
      "y": 16,
      "z": 0,
      "name": "Soil_Dirt_Dry"
    },
    {
      "x": -14,
      "y": 17,
      "z": 0,
      "name": "Soil_Sand_White"
    },
    {
      "x": -14,
      "y": 18,
      "z": 0,
      "name": "Soil_Sand_White"
    },
    {
      "x": -14,
      "y": 19,
      "z": 0,
      "name": "Empty"
    },
    {
      "x": -14,
      "y": 20,
      "z": 0,
      "name": "Empty"
    },
    {
      "x": -14,
      "y": 21,
      "z": 0,
      "name": "Empty"
    },
    {
      "x": -14,
      "y": 22,
      "z": 0,
      "name": "Empty"
    },
    {
      "x": -14,
      "y": 23,
      "z": 0,
      "name": "Empty"
    },
    {
      "x": -14,
      "y": 24,
      "z": 0,
      "name": "Empty"
    },
    {
      "x": -14,
      "y": 25,
      "z": 0,
      "name": "Empty"
    },
    {
      "x": -14,
      "y": 16,
      "z": 1,
      "name": "Soil_Dirt_Dry"
    },
    {
      "x": -14,
      "y": 17,
      "z": 1,
      "name": "Soil_Sand_White"
    },
    {
      "x": -14,
      "y": 18,
      "z": 1,
      "name": "Soil_Grass_Dry"
    },
    {
      "x": -14,
      "y": 19,
      "z": 1,
      "name": "Plant_Flower_Flax_Purple"
    },
    {
      "x": -14,
      "y": 20,
      "z": 1,
      "name": "Empty"
    },
    {
      "x": -14,
      "y": 21,
      "z": 1,
      "name": "Empty"
    },
    {
      "x": -14,
      "y": 22,
      "z": 1,
      "name": "Empty"
    },
    {
      "x": -14,
      "y": 23,
      "z": 1,
      "name": "Empty"
    },
    {
      "x": -14,
      "y": 24,
      "z": 1,
      "name": "Empty"
    },
    {
      "x": -14,
      "y": 25,
      "z": 1,
      "name": "Empty"
    },
    {
      "x": -14,
      "y": 26,
      "z": 1,
      "name": "Empty"
    },
    {
      "x": -14,
      "y": 27,
      "z": 1,
      "name": "Empty"
    },
    {
      "x": -14,
      "y": 16,
      "z": 2,
      "name": "Soil_Dirt_Dry"
    },
    {
      "x": -14,
      "y": 17,
      "z": 2,
      "name": "Soil_Sand_White"
    },
    {
      "x": -14,
      "y": 18,
      "z": 2,
      "name": "Soil_Grass_Dry"
    },
    {
      "x": -14,
      "y": 19,
      "z": 2,
      "name": "Plant_Grass_Arid"
    },
    {
      "x": -14,
      "y": 20,
      "z": 2,
      "name": "Empty"
    },
    {
      "x": -14,
      "y": 21,
      "z": 2,
      "name": "Empty"
    },
    {
      "x": -14,
      "y": 22,
      "z": 2,
      "name": "Empty"
    },
    {
      "x": -14,
      "y": 23,
      "z": 2,
      "name": "Empty"
    },
    {
      "x": -14,
      "y": 24,
      "z": 2,
      "name": "Empty"
    },
    {
      "x": -14,
      "y": 25,
      "z": 2,
      "name": "Empty"
    },
    {
      "x": -14,
      "y": 26,
      "z": 2,
      "name": "Empty"
    },
    {
      "x": -14,
      "y": 27,
      "z": 2,
      "name": "Empty"
    },
    {
      "x": -14,
      "y": 16,
      "z": 3,
      "name": "Soil_Dirt_Dry"
    },
    {
      "x": -14,
      "y": 17,
      "z": 3,
      "name": "Soil_Sand_White"
    },
    {
      "x": -14,
      "y": 18,
      "z": 3,
      "name": "Soil_Grass_Dry"
    },
    {
      "x": -14,
      "y": 19,
      "z": 3,
      "name": "Empty"
    },
    {
      "x": -14,
      "y": 20,
      "z": 3,
      "name": "Empty"
    },
    {
      "x": -14,
      "y": 21,
      "z": 3,
      "name": "Empty"
    },
    {
      "x": -14,
      "y": 22,
      "z": 3,
      "name": "Empty"
    },
    {
      "x": -14,
      "y": 23,
      "z": 3,
      "name": "Empty"
    },
    {
      "x": -14,
      "y": 24,
      "z": 3,
      "name": "Empty"
    },
    {
      "x": -14,
      "y": 25,
      "z": 3,
      "name": "Empty"
    },
    {
      "x": -14,
      "y": 26,
      "z": 3,
      "name": "Empty"
    },
    {
      "x": -14,
      "y": 27,
      "z": 3,
      "name": "Empty"
    },
    {
      "x": -14,
      "y": 16,
      "z": 4,
      "name": "Soil_Dirt_Dry"
    },
    {
      "x": -14,
      "y": 17,
      "z": 4,
      "name": "Soil_Sand_White"
    },
    {
      "x": -14,
      "y": 18,
      "z": 4,
      "name": "Soil_Grass_Dry"
    },
    {
      "x": -14,
      "y": 19,
      "z": 4,
      "name": "Empty"
    },
    {
      "x": -14,
      "y": 20,
      "z": 4,
      "name": "Empty"
    },
    {
      "x": -14,
      "y": 21,
      "z": 4,
      "name": "Empty"
    },
    {
      "x": -14,
      "y": 22,
      "z": 4,
      "name": "Empty"
    },
    {
      "x": -14,
      "y": 23,
      "z": 4,
      "name": "Empty"
    },
    {
      "x": -14,
      "y": 24,
      "z": 4,
      "name": "Empty"
    },
    {
      "x": -14,
      "y": 25,
      "z": 4,
      "name": "Empty"
    },
    {
      "x": -14,
      "y": 16,
      "z": 5,
      "name": "Soil_Dirt_Dry"
    },
    {
      "x": -14,
      "y": 17,
      "z": 5,
      "name": "Soil_Sand_White"
    },
    {
      "x": -14,
      "y": 18,
      "z": 5,
      "name": "Soil_Sand_White"
    },
    {
      "x": -14,
      "y": 19,
      "z": 5,
      "name": "Soil_Sand_White"
    },
    {
      "x": -14,
      "y": 20,
      "z": 5,
      "name": "Empty"
    },
    {
      "x": -14,
      "y": 21,
      "z": 5,
      "name": "Empty"
    },
    {
      "x": -14,
      "y": 22,
      "z": 5,
      "name": "Empty"
    },
    {
      "x": -14,
      "y": 23,
      "z": 5,
      "name": "Empty"
    },
    {
      "x": -14,
      "y": 16,
      "z": 6,
      "name": "Soil_Dirt_Dry"
    },
    {
      "x": -14,
      "y": 17,
      "z": 6,
      "name": "Soil_Sand_White"
    },
    {
      "x": -14,
      "y": 18,
      "z": 6,
      "name": "Soil_Sand_White"
    },
    {
      "x": -14,
      "y": 19,
      "z": 6,
      "name": "Soil_Sand_White"
    },
    {
      "x": -14,
      "y": 20,
      "z": 6,
      "name": "Soil_Sand_White"
    },
    {
      "x": -14,
      "y": 16,
      "z": 7,
      "name": "Soil_Dirt_Dry"
    },
    {
      "x": -14,
      "y": 17,
      "z": 7,
      "name": "Soil_Sand_White"
    },
    {
      "x": -14,
      "y": 18,
      "z": 7,
      "name": "Soil_Sand_White"
    },
    {
      "x": -14,
      "y": 19,
      "z": 7,
      "name": "Soil_Sand_White"
    },
    {
      "x": -14,
      "y": 20,
      "z": 7,
      "name": "Soil_Sand_White"
    },
    {
      "x": -14,
      "y": 16,
      "z": 8,
      "name": "Soil_Dirt_Dry"
    },
    {
      "x": -14,
      "y": 17,
      "z": 8,
      "name": "Soil_Sand_White"
    },
    {
      "x": -14,
      "y": 18,
      "z": 8,
      "name": "Soil_Sand_White"
    },
    {
      "x": -14,
      "y": 19,
      "z": 8,
      "name": "Soil_Sand_White"
    },
    {
      "x": -14,
      "y": 20,
      "z": 8,
      "name": "Soil_Sand_White"
    },
    {
      "x": -14,
      "y": 16,
      "z": 9,
      "name": "Soil_Dirt_Dry"
    },
    {
      "x": -14,
      "y": 17,
      "z": 9,
      "name": "Soil_Sand_White"
    },
    {
      "x": -14,
      "y": 18,
      "z": 9,
      "name": "Soil_Sand_White"
    },
    {
      "x": -14,
      "y": 19,
      "z": 9,
      "name": "Soil_Sand_White"
    },
    {
      "x": -14,
      "y": 20,
      "z": 9,
      "name": "Soil_Sand_White"
    },
    {
      "x": -14,
      "y": 16,
      "z": 10,
      "name": "Soil_Dirt_Dry"
    },
    {
      "x": -14,
      "y": 17,
      "z": 10,
      "name": "Soil_Sand_White"
    },
    {
      "x": -14,
      "y": 18,
      "z": 10,
      "name": "Soil_Sand_White"
    },
    {
      "x": -14,
      "y": 19,
      "z": 10,
      "name": "Soil_Sand_White"
    },
    {
      "x": -14,
      "y": 16,
      "z": 11,
      "name": "Soil_Dirt_Dry"
    },
    {
      "x": -14,
      "y": 17,
      "z": 11,
      "name": "Soil_Sand_White"
    },
    {
      "x": -14,
      "y": 18,
      "z": 11,
      "name": "Soil_Sand_White"
    },
    {
      "x": -14,
      "y": 16,
      "z": 12,
      "name": "Soil_Dirt_Dry"
    },
    {
      "x": -14,
      "y": 17,
      "z": 12,
      "name": "Soil_Sand_White"
    },
    {
      "x": -14,
      "y": 14,
      "z": 13,
      "name": "Rock_Sandstone_Stalactite_Large",
      "filler": 31744,
      "rotation": 8
    },
    {
      "x": -14,
      "y": 15,
      "z": 13,
      "name": "Rock_Sandstone_Stalactite_Large",
      "rotation": 8
    },
    {
      "x": -14,
      "y": 16,
      "z": 13,
      "name": "Soil_Dirt_Dry"
    },
    {
      "x": -14,
      "y": 17,
      "z": 13,
      "name": "Soil_Sand_White"
    },
    {
      "x": -14,
      "y": 16,
      "z": 14,
      "name": "Soil_Dirt_Dry"
    },
    {
      "x": -14,
      "y": 17,
      "z": 14,
      "name": "Soil_Dirt_Dry"
    },
    {
      "x": -14,
      "y": 16,
      "z": 15,
      "name": "Soil_Dirt_Dry"
    },
    {
      "x": -13,
      "y": 16,
      "z": -9,
      "name": "Rock_Sandstone"
    },
    {
      "x": -13,
      "y": 17,
      "z": -9,
      "name": "Soil_Dirt_Dry"
    },
    {
      "x": -13,
      "y": 15,
      "z": -8,
      "name": "Rock_Sandstone_Stalactite_Small",
      "rotation": 8
    },
    {
      "x": -13,
      "y": 16,
      "z": -8,
      "name": "Rock_Sandstone"
    },
    {
      "x": -13,
      "y": 17,
      "z": -8,
      "name": "Soil_Dirt_Dry"
    },
    {
      "x": -13,
      "y": 18,
      "z": -8,
      "name": "Rock_Sandstone"
    },
    {
      "x": -13,
      "y": 19,
      "z": -8,
      "name": "Rock_Sandstone"
    },
    {
      "x": -13,
      "y": 20,
      "z": -8,
      "name": "Rock_Sandstone"
    },
    {
      "x": -13,
      "y": 16,
      "z": -7,
      "name": "Rock_Sandstone"
    },
    {
      "x": -13,
      "y": 17,
      "z": -7,
      "name": "Soil_Dirt_Dry"
    },
    {
      "x": -13,
      "y": 18,
      "z": -7,
      "name": "Rock_Sandstone"
    },
    {
      "x": -13,
      "y": 19,
      "z": -7,
      "name": "Rock_Sandstone"
    },
    {
      "x": -13,
      "y": 20,
      "z": -7,
      "name": "Rock_Sandstone"
    },
    {
      "x": -13,
      "y": 15,
      "z": -6,
      "name": "Rock_Sandstone"
    },
    {
      "x": -13,
      "y": 16,
      "z": -6,
      "name": "Rock_Sandstone"
    },
    {
      "x": -13,
      "y": 17,
      "z": -6,
      "name": "Rock_Sandstone"
    },
    {
      "x": -13,
      "y": 18,
      "z": -6,
      "name": "Rock_Sandstone"
    },
    {
      "x": -13,
      "y": 19,
      "z": -6,
      "name": "Rock_Sandstone"
    },
    {
      "x": -13,
      "y": 20,
      "z": -6,
      "name": "Rock_Sandstone"
    },
    {
      "x": -13,
      "y": 21,
      "z": -6,
      "name": "Rock_Sandstone"
    },
    {
      "x": -13,
      "y": 22,
      "z": -6,
      "name": "Rock_Sandstone"
    },
    {
      "x": -13,
      "y": 23,
      "z": -6,
      "name": "Rock_Sandstone"
    },
    {
      "x": -13,
      "y": 13,
      "z": -5,
      "name": "Rock_Sandstone_Stalactite_Large",
      "filler": 31744,
      "rotation": 8
    },
    {
      "x": -13,
      "y": 14,
      "z": -5,
      "name": "Rock_Sandstone_Stalactite_Large",
      "rotation": 8
    },
    {
      "x": -13,
      "y": 15,
      "z": -5,
      "name": "Rock_Sandstone"
    },
    {
      "x": -13,
      "y": 16,
      "z": -5,
      "name": "Rock_Sandstone"
    },
    {
      "x": -13,
      "y": 17,
      "z": -5,
      "name": "Rock_Sandstone"
    },
    {
      "x": -13,
      "y": 18,
      "z": -5,
      "name": "Rock_Sandstone"
    },
    {
      "x": -13,
      "y": 19,
      "z": -5,
      "name": "Rock_Sandstone"
    },
    {
      "x": -13,
      "y": 20,
      "z": -5,
      "name": "Rock_Sandstone"
    },
    {
      "x": -13,
      "y": 21,
      "z": -5,
      "name": "Rock_Sandstone"
    },
    {
      "x": -13,
      "y": 22,
      "z": -5,
      "name": "Rock_Sandstone"
    },
    {
      "x": -13,
      "y": 23,
      "z": -5,
      "name": "Rock_Sandstone"
    },
    {
      "x": -13,
      "y": 24,
      "z": -5,
      "name": "Rock_Sandstone"
    },
    {
      "x": -13,
      "y": 25,
      "z": -5,
      "name": "Rock_Sandstone"
    },
    {
      "x": -13,
      "y": 14,
      "z": -4,
      "name": "Rock_Sandstone"
    },
    {
      "x": -13,
      "y": 15,
      "z": -4,
      "name": "Rock_Sandstone"
    },
    {
      "x": -13,
      "y": 16,
      "z": -4,
      "name": "Rock_Sandstone"
    },
    {
      "x": -13,
      "y": 17,
      "z": -4,
      "name": "Rock_Sandstone"
    },
    {
      "x": -13,
      "y": 18,
      "z": -4,
      "name": "Rock_Sandstone"
    },
    {
      "x": -13,
      "y": 19,
      "z": -4,
      "name": "Rock_Sandstone"
    },
    {
      "x": -13,
      "y": 20,
      "z": -4,
      "name": "Rock_Sandstone"
    },
    {
      "x": -13,
      "y": 21,
      "z": -4,
      "name": "Rock_Sandstone"
    },
    {
      "x": -13,
      "y": 22,
      "z": -4,
      "name": "Rock_Sandstone"
    },
    {
      "x": -13,
      "y": 14,
      "z": -3,
      "name": "Rock_Sandstone"
    },
    {
      "x": -13,
      "y": 15,
      "z": -3,
      "name": "Rock_Sandstone"
    },
    {
      "x": -13,
      "y": 16,
      "z": -3,
      "name": "Rock_Sandstone"
    },
    {
      "x": -13,
      "y": 17,
      "z": -3,
      "name": "Rock_Sandstone"
    },
    {
      "x": -13,
      "y": 18,
      "z": -3,
      "name": "Rock_Sandstone"
    },
    {
      "x": -13,
      "y": 19,
      "z": -3,
      "name": "Rock_Sandstone"
    },
    {
      "x": -13,
      "y": 20,
      "z": -3,
      "name": "Rock_Sandstone"
    },
    {
      "x": -13,
      "y": 21,
      "z": -3,
      "name": "Rock_Sandstone"
    },
    {
      "x": -13,
      "y": 22,
      "z": -3,
      "name": "Empty"
    },
    {
      "x": -13,
      "y": 23,
      "z": -3,
      "name": "Empty"
    },
    {
      "x": -13,
      "y": 14,
      "z": -2,
      "name": "Rock_Sandstone"
    },
    {
      "x": -13,
      "y": 15,
      "z": -2,
      "name": "Rock_Sandstone"
    },
    {
      "x": -13,
      "y": 16,
      "z": -2,
      "name": "Rock_Sandstone"
    },
    {
      "x": -13,
      "y": 17,
      "z": -2,
      "name": "Rock_Sandstone"
    },
    {
      "x": -13,
      "y": 18,
      "z": -2,
      "name": "Rock_Sandstone"
    },
    {
      "x": -13,
      "y": 19,
      "z": -2,
      "name": "Rock_Sandstone"
    },
    {
      "x": -13,
      "y": 20,
      "z": -2,
      "name": "Rock_Sandstone"
    },
    {
      "x": -13,
      "y": 21,
      "z": -2,
      "name": "Empty"
    },
    {
      "x": -13,
      "y": 22,
      "z": -2,
      "name": "Empty"
    },
    {
      "x": -13,
      "y": 23,
      "z": -2,
      "name": "Empty"
    },
    {
      "x": -13,
      "y": 24,
      "z": -2,
      "name": "Empty"
    },
    {
      "x": -13,
      "y": 25,
      "z": -2,
      "name": "Empty"
    },
    {
      "x": -13,
      "y": 14,
      "z": -1,
      "name": "Rock_Sandstone"
    },
    {
      "x": -13,
      "y": 15,
      "z": -1,
      "name": "Rock_Sandstone"
    },
    {
      "x": -13,
      "y": 16,
      "z": -1,
      "name": "Rock_Sandstone"
    },
    {
      "x": -13,
      "y": 17,
      "z": -1,
      "name": "Rock_Sandstone"
    },
    {
      "x": -13,
      "y": 18,
      "z": -1,
      "name": "Soil_Grass_Dry"
    },
    {
      "x": -13,
      "y": 19,
      "z": -1,
      "name": "Empty"
    },
    {
      "x": -13,
      "y": 20,
      "z": -1,
      "name": "Empty"
    },
    {
      "x": -13,
      "y": 21,
      "z": -1,
      "name": "Empty"
    },
    {
      "x": -13,
      "y": 22,
      "z": -1,
      "name": "Empty"
    },
    {
      "x": -13,
      "y": 23,
      "z": -1,
      "name": "Empty"
    },
    {
      "x": -13,
      "y": 24,
      "z": -1,
      "name": "Empty"
    },
    {
      "x": -13,
      "y": 25,
      "z": -1,
      "name": "Empty"
    },
    {
      "x": -13,
      "y": 14,
      "z": 0,
      "name": "Rock_Sandstone"
    },
    {
      "x": -13,
      "y": 15,
      "z": 0,
      "name": "Rock_Sandstone"
    },
    {
      "x": -13,
      "y": 16,
      "z": 0,
      "name": "Rock_Sandstone"
    },
    {
      "x": -13,
      "y": 17,
      "z": 0,
      "name": "Rock_Sandstone"
    },
    {
      "x": -13,
      "y": 18,
      "z": 0,
      "name": "Soil_Grass_Dry"
    },
    {
      "x": -13,
      "y": 19,
      "z": 0,
      "name": "Plant_Grass_Arid"
    },
    {
      "x": -13,
      "y": 20,
      "z": 0,
      "name": "Empty"
    },
    {
      "x": -13,
      "y": 21,
      "z": 0,
      "name": "Empty"
    },
    {
      "x": -13,
      "y": 22,
      "z": 0,
      "name": "Empty"
    },
    {
      "x": -13,
      "y": 23,
      "z": 0,
      "name": "Empty"
    },
    {
      "x": -13,
      "y": 24,
      "z": 0,
      "name": "Empty"
    },
    {
      "x": -13,
      "y": 25,
      "z": 0,
      "name": "Empty"
    },
    {
      "x": -13,
      "y": 26,
      "z": 0,
      "name": "Empty"
    },
    {
      "x": -13,
      "y": 15,
      "z": 1,
      "name": "Rock_Sandstone"
    },
    {
      "x": -13,
      "y": 16,
      "z": 1,
      "name": "Rock_Sandstone"
    },
    {
      "x": -13,
      "y": 17,
      "z": 1,
      "name": "Rock_Sandstone"
    },
    {
      "x": -13,
      "y": 18,
      "z": 1,
      "name": "Soil_Grass_Dry"
    },
    {
      "x": -13,
      "y": 19,
      "z": 1,
      "name": "Empty"
    },
    {
      "x": -13,
      "y": 20,
      "z": 1,
      "name": "Empty"
    },
    {
      "x": -13,
      "y": 21,
      "z": 1,
      "name": "Empty"
    },
    {
      "x": -13,
      "y": 22,
      "z": 1,
      "name": "Empty"
    },
    {
      "x": -13,
      "y": 23,
      "z": 1,
      "name": "Empty"
    },
    {
      "x": -13,
      "y": 24,
      "z": 1,
      "name": "Empty"
    },
    {
      "x": -13,
      "y": 25,
      "z": 1,
      "name": "Empty"
    },
    {
      "x": -13,
      "y": 26,
      "z": 1,
      "name": "Empty"
    },
    {
      "x": -13,
      "y": 27,
      "z": 1,
      "name": "Empty"
    },
    {
      "x": -13,
      "y": 15,
      "z": 2,
      "name": "Rock_Sandstone"
    },
    {
      "x": -13,
      "y": 16,
      "z": 2,
      "name": "Rock_Sandstone"
    },
    {
      "x": -13,
      "y": 17,
      "z": 2,
      "name": "Rock_Sandstone"
    },
    {
      "x": -13,
      "y": 18,
      "z": 2,
      "name": "Soil_Grass_Dry"
    },
    {
      "x": -13,
      "y": 19,
      "z": 2,
      "name": "Plant_Flower_Flax_Purple"
    },
    {
      "x": -13,
      "y": 20,
      "z": 2,
      "name": "Empty"
    },
    {
      "x": -13,
      "y": 21,
      "z": 2,
      "name": "Empty"
    },
    {
      "x": -13,
      "y": 22,
      "z": 2,
      "name": "Empty"
    },
    {
      "x": -13,
      "y": 23,
      "z": 2,
      "name": "Empty"
    },
    {
      "x": -13,
      "y": 24,
      "z": 2,
      "name": "Empty"
    },
    {
      "x": -13,
      "y": 25,
      "z": 2,
      "name": "Empty"
    },
    {
      "x": -13,
      "y": 26,
      "z": 2,
      "name": "Empty"
    },
    {
      "x": -13,
      "y": 27,
      "z": 2,
      "name": "Empty"
    },
    {
      "x": -13,
      "y": 28,
      "z": 2,
      "name": "Empty"
    },
    {
      "x": -13,
      "y": 16,
      "z": 3,
      "name": "Rock_Sandstone"
    },
    {
      "x": -13,
      "y": 17,
      "z": 3,
      "name": "Soil_Sand_White"
    },
    {
      "x": -13,
      "y": 18,
      "z": 3,
      "name": "Soil_Grass_Dry"
    },
    {
      "x": -13,
      "y": 19,
      "z": 3,
      "name": "Empty"
    },
    {
      "x": -13,
      "y": 20,
      "z": 3,
      "name": "Empty"
    },
    {
      "x": -13,
      "y": 21,
      "z": 3,
      "name": "Empty"
    },
    {
      "x": -13,
      "y": 22,
      "z": 3,
      "name": "Empty"
    },
    {
      "x": -13,
      "y": 23,
      "z": 3,
      "name": "Empty"
    },
    {
      "x": -13,
      "y": 24,
      "z": 3,
      "name": "Empty"
    },
    {
      "x": -13,
      "y": 25,
      "z": 3,
      "name": "Empty"
    },
    {
      "x": -13,
      "y": 26,
      "z": 3,
      "name": "Empty"
    },
    {
      "x": -13,
      "y": 27,
      "z": 3,
      "name": "Empty"
    },
    {
      "x": -13,
      "y": 16,
      "z": 4,
      "name": "Soil_Dirt_Dry"
    },
    {
      "x": -13,
      "y": 17,
      "z": 4,
      "name": "Soil_Sand_White"
    },
    {
      "x": -13,
      "y": 18,
      "z": 4,
      "name": "Soil_Grass_Dry"
    },
    {
      "x": -13,
      "y": 19,
      "z": 4,
      "name": "Empty"
    },
    {
      "x": -13,
      "y": 20,
      "z": 4,
      "name": "Empty"
    },
    {
      "x": -13,
      "y": 21,
      "z": 4,
      "name": "Empty"
    },
    {
      "x": -13,
      "y": 22,
      "z": 4,
      "name": "Empty"
    },
    {
      "x": -13,
      "y": 23,
      "z": 4,
      "name": "Empty"
    },
    {
      "x": -13,
      "y": 24,
      "z": 4,
      "name": "Empty"
    },
    {
      "x": -13,
      "y": 25,
      "z": 4,
      "name": "Empty"
    },
    {
      "x": -13,
      "y": 26,
      "z": 4,
      "name": "Empty"
    },
    {
      "x": -13,
      "y": 16,
      "z": 5,
      "name": "Soil_Dirt_Dry"
    },
    {
      "x": -13,
      "y": 17,
      "z": 5,
      "name": "Soil_Sand_White"
    },
    {
      "x": -13,
      "y": 18,
      "z": 5,
      "name": "Soil_Sand_White"
    },
    {
      "x": -13,
      "y": 19,
      "z": 5,
      "name": "Soil_Sand_White"
    },
    {
      "x": -13,
      "y": 20,
      "z": 5,
      "name": "Soil_Sand_White"
    },
    {
      "x": -13,
      "y": 21,
      "z": 5,
      "name": "Empty"
    },
    {
      "x": -13,
      "y": 22,
      "z": 5,
      "name": "Empty"
    },
    {
      "x": -13,
      "y": 23,
      "z": 5,
      "name": "Empty"
    },
    {
      "x": -13,
      "y": 16,
      "z": 6,
      "name": "Soil_Dirt_Dry"
    },
    {
      "x": -13,
      "y": 17,
      "z": 6,
      "name": "Soil_Sand_White"
    },
    {
      "x": -13,
      "y": 18,
      "z": 6,
      "name": "Soil_Sand_White"
    },
    {
      "x": -13,
      "y": 19,
      "z": 6,
      "name": "Soil_Sand_White"
    },
    {
      "x": -13,
      "y": 20,
      "z": 6,
      "name": "Soil_Sand_White"
    },
    {
      "x": -13,
      "y": 21,
      "z": 6,
      "name": "Soil_Sand_White"
    },
    {
      "x": -13,
      "y": 22,
      "z": 6,
      "name": "Empty"
    },
    {
      "x": -13,
      "y": 16,
      "z": 7,
      "name": "Soil_Dirt_Dry"
    },
    {
      "x": -13,
      "y": 17,
      "z": 7,
      "name": "Soil_Sand_White"
    },
    {
      "x": -13,
      "y": 18,
      "z": 7,
      "name": "Soil_Sand_White"
    },
    {
      "x": -13,
      "y": 19,
      "z": 7,
      "name": "Soil_Sand_White"
    },
    {
      "x": -13,
      "y": 20,
      "z": 7,
      "name": "Soil_Sand_White"
    },
    {
      "x": -13,
      "y": 21,
      "z": 7,
      "name": "Soil_Sand_White"
    },
    {
      "x": -13,
      "y": 16,
      "z": 8,
      "name": "Soil_Dirt_Dry"
    },
    {
      "x": -13,
      "y": 17,
      "z": 8,
      "name": "Soil_Sand_White"
    },
    {
      "x": -13,
      "y": 18,
      "z": 8,
      "name": "Soil_Sand_White"
    },
    {
      "x": -13,
      "y": 19,
      "z": 8,
      "name": "Soil_Sand_White"
    },
    {
      "x": -13,
      "y": 20,
      "z": 8,
      "name": "Soil_Sand_White"
    },
    {
      "x": -13,
      "y": 21,
      "z": 8,
      "name": "Soil_Sand_White"
    },
    {
      "x": -13,
      "y": 16,
      "z": 9,
      "name": "Soil_Dirt_Dry"
    },
    {
      "x": -13,
      "y": 17,
      "z": 9,
      "name": "Soil_Sand_White"
    },
    {
      "x": -13,
      "y": 18,
      "z": 9,
      "name": "Soil_Sand_White"
    },
    {
      "x": -13,
      "y": 19,
      "z": 9,
      "name": "Soil_Sand_White"
    },
    {
      "x": -13,
      "y": 20,
      "z": 9,
      "name": "Soil_Sand_White"
    },
    {
      "x": -13,
      "y": 16,
      "z": 10,
      "name": "Soil_Dirt_Dry"
    },
    {
      "x": -13,
      "y": 17,
      "z": 10,
      "name": "Soil_Sand_White"
    },
    {
      "x": -13,
      "y": 18,
      "z": 10,
      "name": "Soil_Sand_White"
    },
    {
      "x": -13,
      "y": 19,
      "z": 10,
      "name": "Soil_Sand_White"
    },
    {
      "x": -13,
      "y": 20,
      "z": 10,
      "name": "Soil_Sand_White"
    },
    {
      "x": -13,
      "y": 16,
      "z": 11,
      "name": "Soil_Dirt_Dry"
    },
    {
      "x": -13,
      "y": 17,
      "z": 11,
      "name": "Soil_Sand_White"
    },
    {
      "x": -13,
      "y": 18,
      "z": 11,
      "name": "Soil_Sand_White"
    },
    {
      "x": -13,
      "y": 19,
      "z": 11,
      "name": "Soil_Sand_White"
    },
    {
      "x": -13,
      "y": 16,
      "z": 12,
      "name": "Soil_Dirt_Dry"
    },
    {
      "x": -13,
      "y": 17,
      "z": 12,
      "name": "Soil_Sand_White"
    },
    {
      "x": -13,
      "y": 16,
      "z": 13,
      "name": "Soil_Dirt_Dry"
    },
    {
      "x": -13,
      "y": 17,
      "z": 13,
      "name": "Soil_Sand_White"
    },
    {
      "x": -13,
      "y": 16,
      "z": 14,
      "name": "Soil_Dirt_Dry"
    },
    {
      "x": -13,
      "y": 17,
      "z": 14,
      "name": "Soil_Sand_White"
    },
    {
      "x": -13,
      "y": 16,
      "z": 15,
      "name": "Soil_Dirt_Dry"
    },
    {
      "x": -13,
      "y": 17,
      "z": 15,
      "name": "Soil_Dirt_Dry"
    },
    {
      "x": -13,
      "y": 16,
      "z": 16,
      "name": "Soil_Dirt_Dry"
    },
    {
      "x": -12,
      "y": 17,
      "z": -10,
      "name": "Soil_Dirt_Dry"
    },
    {
      "x": -12,
      "y": 17,
      "z": -9,
      "name": "Rock_Sandstone"
    },
    {
      "x": -12,
      "y": 18,
      "z": -9,
      "name": "Rock_Sandstone"
    },
    {
      "x": -12,
      "y": 19,
      "z": -9,
      "name": "Rock_Sandstone"
    },
    {
      "x": -12,
      "y": 20,
      "z": -9,
      "name": "Rock_Sandstone"
    },
    {
      "x": -12,
      "y": 31,
      "z": -9,
      "name": "Soil_Dirt_Dry"
    },
    {
      "x": -12,
      "y": 17,
      "z": -8,
      "name": "Rock_Sandstone"
    },
    {
      "x": -12,
      "y": 18,
      "z": -8,
      "name": "Rock_Sandstone"
    },
    {
      "x": -12,
      "y": 19,
      "z": -8,
      "name": "Rock_Sandstone"
    },
    {
      "x": -12,
      "y": 20,
      "z": -8,
      "name": "Rock_Sandstone"
    },
    {
      "x": -12,
      "y": 21,
      "z": -8,
      "name": "Rock_Sandstone"
    },
    {
      "x": -12,
      "y": 31,
      "z": -8,
      "name": "Soil_Dirt_Dry"
    },
    {
      "x": -12,
      "y": 16,
      "z": -7,
      "name": "Rock_Sandstone"
    },
    {
      "x": -12,
      "y": 17,
      "z": -7,
      "name": "Rock_Sandstone"
    },
    {
      "x": -12,
      "y": 18,
      "z": -7,
      "name": "Rock_Sandstone"
    },
    {
      "x": -12,
      "y": 19,
      "z": -7,
      "name": "Rock_Sandstone"
    },
    {
      "x": -12,
      "y": 20,
      "z": -7,
      "name": "Rock_Sandstone"
    },
    {
      "x": -12,
      "y": 21,
      "z": -7,
      "name": "Rock_Sandstone"
    },
    {
      "x": -12,
      "y": 22,
      "z": -7,
      "name": "Rock_Sandstone"
    },
    {
      "x": -12,
      "y": 23,
      "z": -7,
      "name": "Rock_Sandstone"
    },
    {
      "x": -12,
      "y": 31,
      "z": -7,
      "name": "Soil_Dirt_Dry"
    },
    {
      "x": -12,
      "y": 16,
      "z": -6,
      "name": "Rock_Sandstone"
    },
    {
      "x": -12,
      "y": 17,
      "z": -6,
      "name": "Rock_Sandstone"
    },
    {
      "x": -12,
      "y": 18,
      "z": -6,
      "name": "Rock_Sandstone"
    },
    {
      "x": -12,
      "y": 19,
      "z": -6,
      "name": "Rock_Sandstone"
    },
    {
      "x": -12,
      "y": 20,
      "z": -6,
      "name": "Rock_Sandstone"
    },
    {
      "x": -12,
      "y": 21,
      "z": -6,
      "name": "Rock_Sandstone"
    },
    {
      "x": -12,
      "y": 22,
      "z": -6,
      "name": "Rock_Sandstone"
    },
    {
      "x": -12,
      "y": 23,
      "z": -6,
      "name": "Rock_Sandstone"
    },
    {
      "x": -12,
      "y": 24,
      "z": -6,
      "name": "Rock_Sandstone"
    },
    {
      "x": -12,
      "y": 25,
      "z": -6,
      "name": "Rock_Sandstone"
    },
    {
      "x": -12,
      "y": 26,
      "z": -6,
      "name": "Rock_Sandstone"
    },
    {
      "x": -12,
      "y": 31,
      "z": -6,
      "name": "Soil_Dirt_Dry"
    },
    {
      "x": -12,
      "y": 14,
      "z": -5,
      "name": "Rock_Sandstone"
    },
    {
      "x": -12,
      "y": 15,
      "z": -5,
      "name": "Rock_Sandstone"
    },
    {
      "x": -12,
      "y": 16,
      "z": -5,
      "name": "Rock_Sandstone"
    },
    {
      "x": -12,
      "y": 17,
      "z": -5,
      "name": "Rock_Sandstone"
    },
    {
      "x": -12,
      "y": 18,
      "z": -5,
      "name": "Rock_Sandstone"
    },
    {
      "x": -12,
      "y": 19,
      "z": -5,
      "name": "Rock_Sandstone"
    },
    {
      "x": -12,
      "y": 20,
      "z": -5,
      "name": "Rock_Sandstone"
    },
    {
      "x": -12,
      "y": 21,
      "z": -5,
      "name": "Rock_Sandstone"
    },
    {
      "x": -12,
      "y": 22,
      "z": -5,
      "name": "Rock_Sandstone"
    },
    {
      "x": -12,
      "y": 23,
      "z": -5,
      "name": "Rock_Sandstone"
    },
    {
      "x": -12,
      "y": 24,
      "z": -5,
      "name": "Rock_Sandstone"
    },
    {
      "x": -12,
      "y": 25,
      "z": -5,
      "name": "Rock_Sandstone"
    },
    {
      "x": -12,
      "y": 26,
      "z": -5,
      "name": "Rock_Sandstone"
    },
    {
      "x": -12,
      "y": 27,
      "z": -5,
      "name": "Rock_Sandstone"
    },
    {
      "x": -12,
      "y": 31,
      "z": -5,
      "name": "Soil_Dirt_Dry"
    },
    {
      "x": -12,
      "y": 14,
      "z": -4,
      "name": "Rock_Sandstone"
    },
    {
      "x": -12,
      "y": 15,
      "z": -4,
      "name": "Rock_Sandstone"
    },
    {
      "x": -12,
      "y": 16,
      "z": -4,
      "name": "Rock_Sandstone"
    },
    {
      "x": -12,
      "y": 17,
      "z": -4,
      "name": "Rock_Sandstone"
    },
    {
      "x": -12,
      "y": 18,
      "z": -4,
      "name": "Rock_Sandstone"
    },
    {
      "x": -12,
      "y": 19,
      "z": -4,
      "name": "Rock_Sandstone"
    },
    {
      "x": -12,
      "y": 20,
      "z": -4,
      "name": "Rock_Sandstone"
    },
    {
      "x": -12,
      "y": 21,
      "z": -4,
      "name": "Rock_Sandstone"
    },
    {
      "x": -12,
      "y": 22,
      "z": -4,
      "name": "Rock_Sandstone"
    },
    {
      "x": -12,
      "y": 23,
      "z": -4,
      "name": "Rock_Sandstone"
    },
    {
      "x": -12,
      "y": 24,
      "z": -4,
      "name": "Rock_Sandstone"
    },
    {
      "x": -12,
      "y": 25,
      "z": -4,
      "name": "Rock_Sandstone"
    },
    {
      "x": -12,
      "y": 26,
      "z": -4,
      "name": "Rock_Sandstone"
    },
    {
      "x": -12,
      "y": 30,
      "z": -4,
      "name": "Rock_Sandstone"
    },
    {
      "x": -12,
      "y": 31,
      "z": -4,
      "name": "Soil_Dirt_Dry"
    },
    {
      "x": -12,
      "y": 13,
      "z": -3,
      "name": "Rock_Sandstone"
    },
    {
      "x": -12,
      "y": 14,
      "z": -3,
      "name": "Rock_Sandstone"
    },
    {
      "x": -12,
      "y": 15,
      "z": -3,
      "name": "Rock_Sandstone"
    },
    {
      "x": -12,
      "y": 16,
      "z": -3,
      "name": "Rock_Sandstone"
    },
    {
      "x": -12,
      "y": 17,
      "z": -3,
      "name": "Rock_Sandstone"
    },
    {
      "x": -12,
      "y": 18,
      "z": -3,
      "name": "Rock_Sandstone"
    },
    {
      "x": -12,
      "y": 19,
      "z": -3,
      "name": "Rock_Sandstone"
    },
    {
      "x": -12,
      "y": 20,
      "z": -3,
      "name": "Rock_Sandstone"
    },
    {
      "x": -12,
      "y": 21,
      "z": -3,
      "name": "Rock_Sandstone"
    },
    {
      "x": -12,
      "y": 22,
      "z": -3,
      "name": "Rock_Sandstone"
    },
    {
      "x": -12,
      "y": 23,
      "z": -3,
      "name": "Empty"
    },
    {
      "x": -12,
      "y": 24,
      "z": -3,
      "name": "Empty"
    },
    {
      "x": -12,
      "y": 25,
      "z": -3,
      "name": "Empty"
    },
    {
      "x": -12,
      "y": 26,
      "z": -3,
      "name": "Empty"
    },
    {
      "x": -12,
      "y": 27,
      "z": -3,
      "name": "Rock_Sandstone_Stalactite_Large",
      "filler": 31744,
      "rotation": 8
    },
    {
      "x": -12,
      "y": 28,
      "z": -3,
      "name": "Rock_Sandstone_Stalactite_Large",
      "rotation": 8
    },
    {
      "x": -12,
      "y": 29,
      "z": -3,
      "name": "Rock_Sandstone"
    },
    {
      "x": -12,
      "y": 30,
      "z": -3,
      "name": "Rock_Sandstone"
    },
    {
      "x": -12,
      "y": 31,
      "z": -3,
      "name": "Soil_Dirt_Dry"
    },
    {
      "x": -12,
      "y": 13,
      "z": -2,
      "name": "Rock_Sandstone"
    },
    {
      "x": -12,
      "y": 14,
      "z": -2,
      "name": "Rock_Sandstone"
    },
    {
      "x": -12,
      "y": 15,
      "z": -2,
      "name": "Rock_Sandstone"
    },
    {
      "x": -12,
      "y": 16,
      "z": -2,
      "name": "Rock_Sandstone"
    },
    {
      "x": -12,
      "y": 17,
      "z": -2,
      "name": "Rock_Sandstone"
    },
    {
      "x": -12,
      "y": 18,
      "z": -2,
      "name": "Rock_Sandstone"
    },
    {
      "x": -12,
      "y": 19,
      "z": -2,
      "name": "Rock_Sandstone"
    },
    {
      "x": -12,
      "y": 20,
      "z": -2,
      "name": "Rock_Sandstone"
    },
    {
      "x": -12,
      "y": 21,
      "z": -2,
      "name": "Empty"
    },
    {
      "x": -12,
      "y": 22,
      "z": -2,
      "name": "Empty"
    },
    {
      "x": -12,
      "y": 23,
      "z": -2,
      "name": "Empty"
    },
    {
      "x": -12,
      "y": 24,
      "z": -2,
      "name": "Empty"
    },
    {
      "x": -12,
      "y": 25,
      "z": -2,
      "name": "Empty"
    },
    {
      "x": -12,
      "y": 26,
      "z": -2,
      "name": "Empty"
    },
    {
      "x": -12,
      "y": 27,
      "z": -2,
      "name": "Empty"
    },
    {
      "x": -12,
      "y": 28,
      "z": -2,
      "name": "Empty"
    },
    {
      "x": -12,
      "y": 30,
      "z": -2,
      "name": "Rock_Sandstone"
    },
    {
      "x": -12,
      "y": 31,
      "z": -2,
      "name": "Soil_Dirt_Dry"
    },
    {
      "x": -12,
      "y": 13,
      "z": -1,
      "name": "Rock_Sandstone"
    },
    {
      "x": -12,
      "y": 14,
      "z": -1,
      "name": "Rock_Sandstone"
    },
    {
      "x": -12,
      "y": 15,
      "z": -1,
      "name": "Rock_Sandstone"
    },
    {
      "x": -12,
      "y": 16,
      "z": -1,
      "name": "Rock_Sandstone"
    },
    {
      "x": -12,
      "y": 17,
      "z": -1,
      "name": "Soil_Gravel_Sand_White"
    },
    {
      "x": -12,
      "y": 18,
      "z": -1,
      "name": "Empty"
    },
    {
      "x": -12,
      "y": 19,
      "z": -1,
      "name": "Empty"
    },
    {
      "x": -12,
      "y": 20,
      "z": -1,
      "name": "Empty"
    },
    {
      "x": -12,
      "y": 21,
      "z": -1,
      "name": "Empty"
    },
    {
      "x": -12,
      "y": 22,
      "z": -1,
      "name": "Empty"
    },
    {
      "x": -12,
      "y": 23,
      "z": -1,
      "name": "Empty"
    },
    {
      "x": -12,
      "y": 24,
      "z": -1,
      "name": "Empty"
    },
    {
      "x": -12,
      "y": 25,
      "z": -1,
      "name": "Empty"
    },
    {
      "x": -12,
      "y": 26,
      "z": -1,
      "name": "Empty"
    },
    {
      "x": -12,
      "y": 27,
      "z": -1,
      "name": "Empty"
    },
    {
      "x": -12,
      "y": 28,
      "z": -1,
      "name": "Empty"
    },
    {
      "x": -12,
      "y": 30,
      "z": -1,
      "name": "Rock_Sandstone"
    },
    {
      "x": -12,
      "y": 31,
      "z": -1,
      "name": "Soil_Dirt_Dry"
    },
    {
      "x": -12,
      "y": 13,
      "z": 0,
      "name": "Rock_Sandstone"
    },
    {
      "x": -12,
      "y": 14,
      "z": 0,
      "name": "Rock_Sandstone"
    },
    {
      "x": -12,
      "y": 15,
      "z": 0,
      "name": "Rock_Sandstone"
    },
    {
      "x": -12,
      "y": 16,
      "z": 0,
      "name": "Rock_Sandstone"
    },
    {
      "x": -12,
      "y": 17,
      "z": 0,
      "name": "Soil_Gravel_Sand_White"
    },
    {
      "x": -12,
      "y": 18,
      "z": 0,
      "name": "Empty"
    },
    {
      "x": -12,
      "y": 19,
      "z": 0,
      "name": "Empty"
    },
    {
      "x": -12,
      "y": 20,
      "z": 0,
      "name": "Empty"
    },
    {
      "x": -12,
      "y": 21,
      "z": 0,
      "name": "Empty"
    },
    {
      "x": -12,
      "y": 22,
      "z": 0,
      "name": "Empty"
    },
    {
      "x": -12,
      "y": 23,
      "z": 0,
      "name": "Empty"
    },
    {
      "x": -12,
      "y": 24,
      "z": 0,
      "name": "Empty"
    },
    {
      "x": -12,
      "y": 25,
      "z": 0,
      "name": "Empty"
    },
    {
      "x": -12,
      "y": 26,
      "z": 0,
      "name": "Empty"
    },
    {
      "x": -12,
      "y": 27,
      "z": 0,
      "name": "Empty"
    },
    {
      "x": -12,
      "y": 28,
      "z": 0,
      "name": "Empty"
    },
    {
      "x": -12,
      "y": 29,
      "z": 0,
      "name": "Empty"
    },
    {
      "x": -12,
      "y": 13,
      "z": 1,
      "name": "Rock_Sandstone"
    },
    {
      "x": -12,
      "y": 14,
      "z": 1,
      "name": "Rock_Sandstone"
    },
    {
      "x": -12,
      "y": 15,
      "z": 1,
      "name": "Rock_Sandstone"
    },
    {
      "x": -12,
      "y": 16,
      "z": 1,
      "name": "Rock_Sandstone"
    },
    {
      "x": -12,
      "y": 17,
      "z": 1,
      "name": "Soil_Gravel_Sand_White"
    },
    {
      "x": -12,
      "y": 18,
      "z": 1,
      "name": "Empty"
    },
    {
      "x": -12,
      "y": 19,
      "z": 1,
      "name": "Empty"
    },
    {
      "x": -12,
      "y": 20,
      "z": 1,
      "name": "Empty"
    },
    {
      "x": -12,
      "y": 21,
      "z": 1,
      "name": "Empty"
    },
    {
      "x": -12,
      "y": 22,
      "z": 1,
      "name": "Empty"
    },
    {
      "x": -12,
      "y": 23,
      "z": 1,
      "name": "Empty"
    },
    {
      "x": -12,
      "y": 24,
      "z": 1,
      "name": "Empty"
    },
    {
      "x": -12,
      "y": 25,
      "z": 1,
      "name": "Empty"
    },
    {
      "x": -12,
      "y": 26,
      "z": 1,
      "name": "Empty"
    },
    {
      "x": -12,
      "y": 27,
      "z": 1,
      "name": "Empty"
    },
    {
      "x": -12,
      "y": 28,
      "z": 1,
      "name": "Empty"
    },
    {
      "x": -12,
      "y": 29,
      "z": 1,
      "name": "Empty"
    },
    {
      "x": -12,
      "y": 13,
      "z": 2,
      "name": "Rock_Sandstone"
    },
    {
      "x": -12,
      "y": 14,
      "z": 2,
      "name": "Rock_Sandstone"
    },
    {
      "x": -12,
      "y": 15,
      "z": 2,
      "name": "Rock_Sandstone"
    },
    {
      "x": -12,
      "y": 16,
      "z": 2,
      "name": "Rock_Sandstone"
    },
    {
      "x": -12,
      "y": 17,
      "z": 2,
      "name": "Soil_Gravel_Sand_White"
    },
    {
      "x": -12,
      "y": 18,
      "z": 2,
      "name": "Empty"
    },
    {
      "x": -12,
      "y": 19,
      "z": 2,
      "name": "Empty"
    },
    {
      "x": -12,
      "y": 20,
      "z": 2,
      "name": "Empty"
    },
    {
      "x": -12,
      "y": 21,
      "z": 2,
      "name": "Empty"
    },
    {
      "x": -12,
      "y": 22,
      "z": 2,
      "name": "Empty"
    },
    {
      "x": -12,
      "y": 23,
      "z": 2,
      "name": "Empty"
    },
    {
      "x": -12,
      "y": 24,
      "z": 2,
      "name": "Empty"
    },
    {
      "x": -12,
      "y": 25,
      "z": 2,
      "name": "Empty"
    },
    {
      "x": -12,
      "y": 26,
      "z": 2,
      "name": "Empty"
    },
    {
      "x": -12,
      "y": 27,
      "z": 2,
      "name": "Empty"
    },
    {
      "x": -12,
      "y": 28,
      "z": 2,
      "name": "Empty"
    },
    {
      "x": -12,
      "y": 29,
      "z": 2,
      "name": "Empty"
    },
    {
      "x": -12,
      "y": 13,
      "z": 3,
      "name": "Rock_Sandstone"
    },
    {
      "x": -12,
      "y": 14,
      "z": 3,
      "name": "Rock_Sandstone"
    },
    {
      "x": -12,
      "y": 15,
      "z": 3,
      "name": "Rock_Sandstone"
    },
    {
      "x": -12,
      "y": 16,
      "z": 3,
      "name": "Rock_Sandstone"
    },
    {
      "x": -12,
      "y": 17,
      "z": 3,
      "name": "Rock_Sandstone"
    },
    {
      "x": -12,
      "y": 18,
      "z": 3,
      "name": "Soil_Grass_Dry"
    },
    {
      "x": -12,
      "y": 19,
      "z": 3,
      "name": "Plant_Grass_Dry"
    },
    {
      "x": -12,
      "y": 20,
      "z": 3,
      "name": "Empty"
    },
    {
      "x": -12,
      "y": 21,
      "z": 3,
      "name": "Empty"
    },
    {
      "x": -12,
      "y": 22,
      "z": 3,
      "name": "Empty"
    },
    {
      "x": -12,
      "y": 23,
      "z": 3,
      "name": "Empty"
    },
    {
      "x": -12,
      "y": 24,
      "z": 3,
      "name": "Empty"
    },
    {
      "x": -12,
      "y": 25,
      "z": 3,
      "name": "Empty"
    },
    {
      "x": -12,
      "y": 26,
      "z": 3,
      "name": "Empty"
    },
    {
      "x": -12,
      "y": 27,
      "z": 3,
      "name": "Empty"
    },
    {
      "x": -12,
      "y": 28,
      "z": 3,
      "name": "Empty"
    },
    {
      "x": -12,
      "y": 13,
      "z": 4,
      "name": "Rock_Sandstone"
    },
    {
      "x": -12,
      "y": 14,
      "z": 4,
      "name": "Rock_Sandstone"
    },
    {
      "x": -12,
      "y": 15,
      "z": 4,
      "name": "Rock_Sandstone"
    },
    {
      "x": -12,
      "y": 16,
      "z": 4,
      "name": "Rock_Sandstone"
    },
    {
      "x": -12,
      "y": 17,
      "z": 4,
      "name": "Rock_Sandstone"
    },
    {
      "x": -12,
      "y": 18,
      "z": 4,
      "name": "Soil_Sand_White"
    },
    {
      "x": -12,
      "y": 19,
      "z": 4,
      "name": "Soil_Sand_White"
    },
    {
      "x": -12,
      "y": 20,
      "z": 4,
      "name": "Empty"
    },
    {
      "x": -12,
      "y": 21,
      "z": 4,
      "name": "Empty"
    },
    {
      "x": -12,
      "y": 22,
      "z": 4,
      "name": "Empty"
    },
    {
      "x": -12,
      "y": 23,
      "z": 4,
      "name": "Empty"
    },
    {
      "x": -12,
      "y": 24,
      "z": 4,
      "name": "Empty"
    },
    {
      "x": -12,
      "y": 25,
      "z": 4,
      "name": "Empty"
    },
    {
      "x": -12,
      "y": 26,
      "z": 4,
      "name": "Empty"
    },
    {
      "x": -12,
      "y": 27,
      "z": 4,
      "name": "Empty"
    },
    {
      "x": -12,
      "y": 28,
      "z": 4,
      "name": "Empty"
    },
    {
      "x": -12,
      "y": 14,
      "z": 5,
      "name": "Rock_Sandstone"
    },
    {
      "x": -12,
      "y": 15,
      "z": 5,
      "name": "Rock_Sandstone"
    },
    {
      "x": -12,
      "y": 16,
      "z": 5,
      "name": "Rock_Sandstone"
    },
    {
      "x": -12,
      "y": 17,
      "z": 5,
      "name": "Rock_Sandstone"
    },
    {
      "x": -12,
      "y": 18,
      "z": 5,
      "name": "Soil_Sand_White"
    },
    {
      "x": -12,
      "y": 19,
      "z": 5,
      "name": "Soil_Sand_White"
    },
    {
      "x": -12,
      "y": 20,
      "z": 5,
      "name": "Soil_Sand_White"
    },
    {
      "x": -12,
      "y": 21,
      "z": 5,
      "name": "Empty"
    },
    {
      "x": -12,
      "y": 22,
      "z": 5,
      "name": "Empty"
    },
    {
      "x": -12,
      "y": 23,
      "z": 5,
      "name": "Empty"
    },
    {
      "x": -12,
      "y": 24,
      "z": 5,
      "name": "Empty"
    },
    {
      "x": -12,
      "y": 25,
      "z": 5,
      "name": "Empty"
    },
    {
      "x": -12,
      "y": 26,
      "z": 5,
      "name": "Empty"
    },
    {
      "x": -12,
      "y": 27,
      "z": 5,
      "name": "Empty"
    },
    {
      "x": -12,
      "y": 16,
      "z": 6,
      "name": "Soil_Dirt_Dry"
    },
    {
      "x": -12,
      "y": 17,
      "z": 6,
      "name": "Soil_Dirt_Dry"
    },
    {
      "x": -12,
      "y": 18,
      "z": 6,
      "name": "Soil_Sand_White"
    },
    {
      "x": -12,
      "y": 19,
      "z": 6,
      "name": "Soil_Sand_White"
    },
    {
      "x": -12,
      "y": 20,
      "z": 6,
      "name": "Soil_Sand_White"
    },
    {
      "x": -12,
      "y": 21,
      "z": 6,
      "name": "Soil_Sand_White"
    },
    {
      "x": -12,
      "y": 22,
      "z": 6,
      "name": "Soil_Sand_White"
    },
    {
      "x": -12,
      "y": 23,
      "z": 6,
      "name": "Empty"
    },
    {
      "x": -12,
      "y": 24,
      "z": 6,
      "name": "Empty"
    },
    {
      "x": -12,
      "y": 25,
      "z": 6,
      "name": "Empty"
    },
    {
      "x": -12,
      "y": 26,
      "z": 6,
      "name": "Empty"
    },
    {
      "x": -12,
      "y": 14,
      "z": 7,
      "name": "Rock_Sandstone"
    },
    {
      "x": -12,
      "y": 15,
      "z": 7,
      "name": "Rock_Sandstone"
    },
    {
      "x": -12,
      "y": 16,
      "z": 7,
      "name": "Rock_Sandstone"
    },
    {
      "x": -12,
      "y": 17,
      "z": 7,
      "name": "Rock_Sandstone"
    },
    {
      "x": -12,
      "y": 18,
      "z": 7,
      "name": "Rock_Sandstone"
    },
    {
      "x": -12,
      "y": 19,
      "z": 7,
      "name": "Rock_Sandstone"
    },
    {
      "x": -12,
      "y": 20,
      "z": 7,
      "name": "Rock_Sandstone"
    },
    {
      "x": -12,
      "y": 21,
      "z": 7,
      "name": "Rock_Sandstone"
    },
    {
      "x": -12,
      "y": 22,
      "z": 7,
      "name": "Rock_Sandstone"
    },
    {
      "x": -12,
      "y": 23,
      "z": 7,
      "name": "Rock_Sandstone"
    },
    {
      "x": -12,
      "y": 24,
      "z": 7,
      "name": "Rock_Sandstone"
    },
    {
      "x": -12,
      "y": 25,
      "z": 7,
      "name": "Empty"
    },
    {
      "x": -12,
      "y": 14,
      "z": 8,
      "name": "Rock_Sandstone"
    },
    {
      "x": -12,
      "y": 15,
      "z": 8,
      "name": "Rock_Sandstone"
    },
    {
      "x": -12,
      "y": 16,
      "z": 8,
      "name": "Rock_Sandstone"
    },
    {
      "x": -12,
      "y": 17,
      "z": 8,
      "name": "Rock_Sandstone"
    },
    {
      "x": -12,
      "y": 18,
      "z": 8,
      "name": "Rock_Sandstone"
    },
    {
      "x": -12,
      "y": 19,
      "z": 8,
      "name": "Rock_Sandstone"
    },
    {
      "x": -12,
      "y": 20,
      "z": 8,
      "name": "Rock_Sandstone"
    },
    {
      "x": -12,
      "y": 21,
      "z": 8,
      "name": "Rock_Sandstone"
    },
    {
      "x": -12,
      "y": 22,
      "z": 8,
      "name": "Rock_Sandstone"
    },
    {
      "x": -12,
      "y": 23,
      "z": 8,
      "name": "Rock_Sandstone"
    },
    {
      "x": -12,
      "y": 24,
      "z": 8,
      "name": "Rock_Sandstone"
    },
    {
      "x": -12,
      "y": 16,
      "z": 9,
      "name": "Soil_Dirt_Dry"
    },
    {
      "x": -12,
      "y": 17,
      "z": 9,
      "name": "Rock_Sandstone"
    },
    {
      "x": -12,
      "y": 18,
      "z": 9,
      "name": "Rock_Sandstone"
    },
    {
      "x": -12,
      "y": 19,
      "z": 9,
      "name": "Rock_Sandstone"
    },
    {
      "x": -12,
      "y": 20,
      "z": 9,
      "name": "Rock_Sandstone"
    },
    {
      "x": -12,
      "y": 21,
      "z": 9,
      "name": "Rock_Sandstone"
    },
    {
      "x": -12,
      "y": 16,
      "z": 10,
      "name": "Rock_Sandstone"
    },
    {
      "x": -12,
      "y": 17,
      "z": 10,
      "name": "Rock_Sandstone"
    },
    {
      "x": -12,
      "y": 18,
      "z": 10,
      "name": "Rock_Sandstone"
    },
    {
      "x": -12,
      "y": 19,
      "z": 10,
      "name": "Rock_Sandstone"
    },
    {
      "x": -12,
      "y": 20,
      "z": 10,
      "name": "Rock_Sandstone"
    },
    {
      "x": -12,
      "y": 16,
      "z": 11,
      "name": "Soil_Dirt_Dry"
    },
    {
      "x": -12,
      "y": 17,
      "z": 11,
      "name": "Rock_Sandstone"
    },
    {
      "x": -12,
      "y": 18,
      "z": 11,
      "name": "Rock_Sandstone"
    },
    {
      "x": -12,
      "y": 19,
      "z": 11,
      "name": "Rock_Sandstone"
    },
    {
      "x": -12,
      "y": 16,
      "z": 12,
      "name": "Soil_Dirt_Dry"
    },
    {
      "x": -12,
      "y": 17,
      "z": 12,
      "name": "Soil_Sand_White"
    },
    {
      "x": -12,
      "y": 18,
      "z": 12,
      "name": "Soil_Sand_White"
    },
    {
      "x": -12,
      "y": 19,
      "z": 12,
      "name": "Soil_Sand_White"
    },
    {
      "x": -12,
      "y": 16,
      "z": 13,
      "name": "Soil_Dirt_Dry"
    },
    {
      "x": -12,
      "y": 17,
      "z": 13,
      "name": "Soil_Sand_White"
    },
    {
      "x": -12,
      "y": 16,
      "z": 14,
      "name": "Soil_Dirt_Dry"
    },
    {
      "x": -12,
      "y": 17,
      "z": 14,
      "name": "Soil_Sand_White"
    },
    {
      "x": -12,
      "y": 16,
      "z": 15,
      "name": "Soil_Dirt_Dry"
    },
    {
      "x": -12,
      "y": 17,
      "z": 15,
      "name": "Soil_Dirt_Dry"
    },
    {
      "x": -12,
      "y": 16,
      "z": 16,
      "name": "Soil_Dirt_Dry"
    },
    {
      "x": -11,
      "y": 17,
      "z": -11,
      "name": "Soil_Dirt_Dry"
    },
    {
      "x": -11,
      "y": 31,
      "z": -11,
      "name": "Soil_Dirt_Dry"
    },
    {
      "x": -11,
      "y": 17,
      "z": -10,
      "name": "Rock_Sandstone"
    },
    {
      "x": -11,
      "y": 18,
      "z": -10,
      "name": "Rock_Sandstone"
    },
    {
      "x": -11,
      "y": 19,
      "z": -10,
      "name": "Rock_Sandstone"
    },
    {
      "x": -11,
      "y": 31,
      "z": -10,
      "name": "Soil_Dirt_Dry"
    },
    {
      "x": -11,
      "y": 17,
      "z": -9,
      "name": "Rock_Sandstone"
    },
    {
      "x": -11,
      "y": 18,
      "z": -9,
      "name": "Rock_Sandstone"
    },
    {
      "x": -11,
      "y": 19,
      "z": -9,
      "name": "Rock_Sandstone"
    },
    {
      "x": -11,
      "y": 20,
      "z": -9,
      "name": "Rock_Sandstone"
    },
    {
      "x": -11,
      "y": 31,
      "z": -9,
      "name": "Soil_Dirt_Dry"
    },
    {
      "x": -11,
      "y": 32,
      "z": -9,
      "name": "Rubble_Sandstone"
    },
    {
      "x": -11,
      "y": 17,
      "z": -8,
      "name": "Rock_Sandstone"
    },
    {
      "x": -11,
      "y": 18,
      "z": -8,
      "name": "Rock_Sandstone"
    },
    {
      "x": -11,
      "y": 19,
      "z": -8,
      "name": "Rock_Sandstone"
    },
    {
      "x": -11,
      "y": 20,
      "z": -8,
      "name": "Rock_Sandstone"
    },
    {
      "x": -11,
      "y": 21,
      "z": -8,
      "name": "Rock_Sandstone"
    },
    {
      "x": -11,
      "y": 22,
      "z": -8,
      "name": "Rock_Sandstone"
    },
    {
      "x": -11,
      "y": 23,
      "z": -8,
      "name": "Rock_Sandstone"
    },
    {
      "x": -11,
      "y": 31,
      "z": -8,
      "name": "Soil_Dirt_Dry"
    },
    {
      "x": -11,
      "y": 14,
      "z": -7,
      "name": "Rock_Sandstone"
    },
    {
      "x": -11,
      "y": 15,
      "z": -7,
      "name": "Rock_Sandstone"
    },
    {
      "x": -11,
      "y": 16,
      "z": -7,
      "name": "Rock_Sandstone"
    },
    {
      "x": -11,
      "y": 17,
      "z": -7,
      "name": "Rock_Sandstone"
    },
    {
      "x": -11,
      "y": 18,
      "z": -7,
      "name": "Rock_Sandstone"
    },
    {
      "x": -11,
      "y": 19,
      "z": -7,
      "name": "Rock_Sandstone"
    },
    {
      "x": -11,
      "y": 20,
      "z": -7,
      "name": "Rock_Sandstone"
    },
    {
      "x": -11,
      "y": 21,
      "z": -7,
      "name": "Rock_Sandstone"
    },
    {
      "x": -11,
      "y": 22,
      "z": -7,
      "name": "Rock_Sandstone"
    },
    {
      "x": -11,
      "y": 23,
      "z": -7,
      "name": "Rock_Sandstone"
    },
    {
      "x": -11,
      "y": 24,
      "z": -7,
      "name": "Rock_Sandstone"
    },
    {
      "x": -11,
      "y": 25,
      "z": -7,
      "name": "Rock_Sandstone"
    },
    {
      "x": -11,
      "y": 26,
      "z": -7,
      "name": "Rock_Sandstone"
    },
    {
      "x": -11,
      "y": 31,
      "z": -7,
      "name": "Soil_Dirt_Dry"
    },
    {
      "x": -11,
      "y": 14,
      "z": -6,
      "name": "Rock_Sandstone"
    },
    {
      "x": -11,
      "y": 15,
      "z": -6,
      "name": "Rock_Sandstone"
    },
    {
      "x": -11,
      "y": 16,
      "z": -6,
      "name": "Rock_Sandstone"
    },
    {
      "x": -11,
      "y": 17,
      "z": -6,
      "name": "Rock_Sandstone"
    },
    {
      "x": -11,
      "y": 18,
      "z": -6,
      "name": "Rock_Sandstone"
    },
    {
      "x": -11,
      "y": 19,
      "z": -6,
      "name": "Rock_Sandstone"
    },
    {
      "x": -11,
      "y": 20,
      "z": -6,
      "name": "Rock_Sandstone"
    },
    {
      "x": -11,
      "y": 21,
      "z": -6,
      "name": "Rock_Sandstone"
    },
    {
      "x": -11,
      "y": 22,
      "z": -6,
      "name": "Rock_Sandstone"
    },
    {
      "x": -11,
      "y": 23,
      "z": -6,
      "name": "Rock_Sandstone"
    },
    {
      "x": -11,
      "y": 24,
      "z": -6,
      "name": "Rock_Sandstone"
    },
    {
      "x": -11,
      "y": 25,
      "z": -6,
      "name": "Rock_Sandstone"
    },
    {
      "x": -11,
      "y": 26,
      "z": -6,
      "name": "Rock_Sandstone"
    },
    {
      "x": -11,
      "y": 27,
      "z": -6,
      "name": "Rock_Sandstone"
    },
    {
      "x": -11,
      "y": 31,
      "z": -6,
      "name": "Soil_Dirt_Dry"
    },
    {
      "x": -11,
      "y": 32,
      "z": -6,
      "name": "Soil_Dirt_Dry"
    },
    {
      "x": -11,
      "y": 13,
      "z": -5,
      "name": "Rock_Sandstone"
    },
    {
      "x": -11,
      "y": 14,
      "z": -5,
      "name": "Rock_Sandstone"
    },
    {
      "x": -11,
      "y": 15,
      "z": -5,
      "name": "Rock_Sandstone"
    },
    {
      "x": -11,
      "y": 16,
      "z": -5,
      "name": "Rock_Sandstone"
    },
    {
      "x": -11,
      "y": 17,
      "z": -5,
      "name": "Rock_Sandstone"
    },
    {
      "x": -11,
      "y": 18,
      "z": -5,
      "name": "Rock_Sandstone"
    },
    {
      "x": -11,
      "y": 19,
      "z": -5,
      "name": "Rock_Sandstone"
    },
    {
      "x": -11,
      "y": 20,
      "z": -5,
      "name": "Rock_Sandstone"
    },
    {
      "x": -11,
      "y": 21,
      "z": -5,
      "name": "Rock_Sandstone"
    },
    {
      "x": -11,
      "y": 22,
      "z": -5,
      "name": "Rock_Sandstone"
    },
    {
      "x": -11,
      "y": 23,
      "z": -5,
      "name": "Rock_Sandstone"
    },
    {
      "x": -11,
      "y": 24,
      "z": -5,
      "name": "Rock_Sandstone"
    },
    {
      "x": -11,
      "y": 25,
      "z": -5,
      "name": "Rock_Sandstone"
    },
    {
      "x": -11,
      "y": 26,
      "z": -5,
      "name": "Rock_Sandstone"
    },
    {
      "x": -11,
      "y": 27,
      "z": -5,
      "name": "Rock_Sandstone"
    },
    {
      "x": -11,
      "y": 28,
      "z": -5,
      "name": "Rock_Sandstone"
    },
    {
      "x": -11,
      "y": 31,
      "z": -5,
      "name": "Soil_Dirt_Dry"
    },
    {
      "x": -11,
      "y": 32,
      "z": -5,
      "name": "Soil_Dirt_Dry"
    },
    {
      "x": -11,
      "y": 12,
      "z": -4,
      "name": "Rock_Sandstone"
    },
    {
      "x": -11,
      "y": 13,
      "z": -4,
      "name": "Rock_Sandstone"
    },
    {
      "x": -11,
      "y": 14,
      "z": -4,
      "name": "Rock_Sandstone"
    },
    {
      "x": -11,
      "y": 15,
      "z": -4,
      "name": "Rock_Sandstone"
    },
    {
      "x": -11,
      "y": 16,
      "z": -4,
      "name": "Rock_Sandstone"
    },
    {
      "x": -11,
      "y": 17,
      "z": -4,
      "name": "Rock_Sandstone"
    },
    {
      "x": -11,
      "y": 18,
      "z": -4,
      "name": "Rock_Sandstone"
    },
    {
      "x": -11,
      "y": 19,
      "z": -4,
      "name": "Rock_Sandstone"
    },
    {
      "x": -11,
      "y": 20,
      "z": -4,
      "name": "Rock_Sandstone"
    },
    {
      "x": -11,
      "y": 21,
      "z": -4,
      "name": "Rock_Sandstone"
    },
    {
      "x": -11,
      "y": 22,
      "z": -4,
      "name": "Rock_Sandstone"
    },
    {
      "x": -11,
      "y": 23,
      "z": -4,
      "name": "Rock_Sandstone"
    },
    {
      "x": -11,
      "y": 24,
      "z": -4,
      "name": "Rock_Sandstone"
    },
    {
      "x": -11,
      "y": 25,
      "z": -4,
      "name": "Rock_Sandstone"
    },
    {
      "x": -11,
      "y": 26,
      "z": -4,
      "name": "Rock_Sandstone"
    },
    {
      "x": -11,
      "y": 27,
      "z": -4,
      "name": "Rock_Sandstone"
    },
    {
      "x": -11,
      "y": 31,
      "z": -4,
      "name": "Soil_Dirt_Dry"
    },
    {
      "x": -11,
      "y": 32,
      "z": -4,
      "name": "Soil_Dirt_Dry"
    },
    {
      "x": -11,
      "y": 12,
      "z": -3,
      "name": "Rock_Sandstone"
    },
    {
      "x": -11,
      "y": 13,
      "z": -3,
      "name": "Rock_Sandstone"
    },
    {
      "x": -11,
      "y": 14,
      "z": -3,
      "name": "Rock_Sandstone"
    },
    {
      "x": -11,
      "y": 15,
      "z": -3,
      "name": "Rock_Sandstone"
    },
    {
      "x": -11,
      "y": 16,
      "z": -3,
      "name": "Rock_Sandstone"
    },
    {
      "x": -11,
      "y": 17,
      "z": -3,
      "name": "Rock_Sandstone"
    },
    {
      "x": -11,
      "y": 18,
      "z": -3,
      "name": "Rock_Sandstone"
    },
    {
      "x": -11,
      "y": 19,
      "z": -3,
      "name": "Rock_Sandstone"
    },
    {
      "x": -11,
      "y": 20,
      "z": -3,
      "name": "Rock_Sandstone"
    },
    {
      "x": -11,
      "y": 21,
      "z": -3,
      "name": "Rock_Sandstone"
    },
    {
      "x": -11,
      "y": 22,
      "z": -3,
      "name": "Rock_Sandstone"
    },
    {
      "x": -11,
      "y": 23,
      "z": -3,
      "name": "Rock_Sandstone"
    },
    {
      "x": -11,
      "y": 24,
      "z": -3,
      "name": "Rock_Sandstone"
    },
    {
      "x": -11,
      "y": 25,
      "z": -3,
      "name": "Empty"
    },
    {
      "x": -11,
      "y": 26,
      "z": -3,
      "name": "Empty"
    },
    {
      "x": -11,
      "y": 27,
      "z": -3,
      "name": "Empty"
    },
    {
      "x": -11,
      "y": 28,
      "z": -3,
      "name": "Empty"
    },
    {
      "x": -11,
      "y": 29,
      "z": -3,
      "name": "Empty"
    },
    {
      "x": -11,
      "y": 30,
      "z": -3,
      "name": "Rock_Sandstone"
    },
    {
      "x": -11,
      "y": 31,
      "z": -3,
      "name": "Soil_Dirt_Dry"
    },
    {
      "x": -11,
      "y": 32,
      "z": -3,
      "name": "Soil_Sand_White"
    },
    {
      "x": -11,
      "y": 12,
      "z": -2,
      "name": "Rock_Sandstone"
    },
    {
      "x": -11,
      "y": 13,
      "z": -2,
      "name": "Rock_Sandstone"
    },
    {
      "x": -11,
      "y": 14,
      "z": -2,
      "name": "Rock_Sandstone"
    },
    {
      "x": -11,
      "y": 15,
      "z": -2,
      "name": "Rock_Sandstone"
    },
    {
      "x": -11,
      "y": 16,
      "z": -2,
      "name": "Rock_Sandstone"
    },
    {
      "x": -11,
      "y": 17,
      "z": -2,
      "name": "Rock_Sandstone"
    },
    {
      "x": -11,
      "y": 18,
      "z": -2,
      "name": "Rock_Sandstone"
    },
    {
      "x": -11,
      "y": 19,
      "z": -2,
      "name": "Rock_Sandstone"
    },
    {
      "x": -11,
      "y": 20,
      "z": -2,
      "name": "Rock_Sandstone"
    },
    {
      "x": -11,
      "y": 21,
      "z": -2,
      "name": "Rock_Sandstone"
    },
    {
      "x": -11,
      "y": 22,
      "z": -2,
      "name": "Rock_Sandstone"
    },
    {
      "x": -11,
      "y": 23,
      "z": -2,
      "name": "Empty"
    },
    {
      "x": -11,
      "y": 24,
      "z": -2,
      "name": "Empty"
    },
    {
      "x": -11,
      "y": 25,
      "z": -2,
      "name": "Empty"
    },
    {
      "x": -11,
      "y": 26,
      "z": -2,
      "name": "Empty"
    },
    {
      "x": -11,
      "y": 27,
      "z": -2,
      "name": "Empty"
    },
    {
      "x": -11,
      "y": 28,
      "z": -2,
      "name": "Empty"
    },
    {
      "x": -11,
      "y": 29,
      "z": -2,
      "name": "Rock_Sandstone"
    },
    {
      "x": -11,
      "y": 30,
      "z": -2,
      "name": "Rock_Sandstone"
    },
    {
      "x": -11,
      "y": 31,
      "z": -2,
      "name": "Soil_Dirt_Dry"
    },
    {
      "x": -11,
      "y": 32,
      "z": -2,
      "name": "Soil_Sand_White"
    },
    {
      "x": -11,
      "y": 12,
      "z": -1,
      "name": "Rock_Sandstone"
    },
    {
      "x": -11,
      "y": 13,
      "z": -1,
      "name": "Rock_Sandstone"
    },
    {
      "x": -11,
      "y": 14,
      "z": -1,
      "name": "Rock_Sandstone"
    },
    {
      "x": -11,
      "y": 15,
      "z": -1,
      "name": "Rock_Sandstone"
    },
    {
      "x": -11,
      "y": 16,
      "z": -1,
      "name": "Soil_Gravel_Sand_White"
    },
    {
      "x": -11,
      "y": 17,
      "z": -1,
      "name": "Empty"
    },
    {
      "x": -11,
      "y": 18,
      "z": -1,
      "name": "Empty"
    },
    {
      "x": -11,
      "y": 19,
      "z": -1,
      "name": "Empty"
    },
    {
      "x": -11,
      "y": 20,
      "z": -1,
      "name": "Empty"
    },
    {
      "x": -11,
      "y": 21,
      "z": -1,
      "name": "Empty"
    },
    {
      "x": -11,
      "y": 22,
      "z": -1,
      "name": "Empty"
    },
    {
      "x": -11,
      "y": 23,
      "z": -1,
      "name": "Empty"
    },
    {
      "x": -11,
      "y": 24,
      "z": -1,
      "name": "Empty"
    },
    {
      "x": -11,
      "y": 25,
      "z": -1,
      "name": "Empty"
    },
    {
      "x": -11,
      "y": 26,
      "z": -1,
      "name": "Empty"
    },
    {
      "x": -11,
      "y": 27,
      "z": -1,
      "name": "Empty"
    },
    {
      "x": -11,
      "y": 28,
      "z": -1,
      "name": "Rock_Sandstone_Stalactite_Small",
      "rotation": 8
    },
    {
      "x": -11,
      "y": 29,
      "z": -1,
      "name": "Rock_Sandstone"
    },
    {
      "x": -11,
      "y": 30,
      "z": -1,
      "name": "Rock_Sandstone"
    },
    {
      "x": -11,
      "y": 31,
      "z": -1,
      "name": "Soil_Dirt_Dry"
    },
    {
      "x": -11,
      "y": 32,
      "z": -1,
      "name": "Soil_Sand_White"
    },
    {
      "x": -11,
      "y": 12,
      "z": 0,
      "name": "Rock_Sandstone"
    },
    {
      "x": -11,
      "y": 13,
      "z": 0,
      "name": "Rock_Sandstone"
    },
    {
      "x": -11,
      "y": 14,
      "z": 0,
      "name": "Rock_Sandstone"
    },
    {
      "x": -11,
      "y": 15,
      "z": 0,
      "name": "Rock_Sandstone"
    },
    {
      "x": -11,
      "y": 16,
      "z": 0,
      "name": "Soil_Gravel_Sand_White"
    },
    {
      "x": -11,
      "y": 17,
      "z": 0,
      "name": "Soil_Gravel_Sand_White_Half"
    },
    {
      "x": -11,
      "y": 18,
      "z": 0,
      "name": "Empty"
    },
    {
      "x": -11,
      "y": 19,
      "z": 0,
      "name": "Empty"
    },
    {
      "x": -11,
      "y": 20,
      "z": 0,
      "name": "Empty"
    },
    {
      "x": -11,
      "y": 21,
      "z": 0,
      "name": "Empty"
    },
    {
      "x": -11,
      "y": 22,
      "z": 0,
      "name": "Empty"
    },
    {
      "x": -11,
      "y": 23,
      "z": 0,
      "name": "Empty"
    },
    {
      "x": -11,
      "y": 24,
      "z": 0,
      "name": "Empty"
    },
    {
      "x": -11,
      "y": 25,
      "z": 0,
      "name": "Empty"
    },
    {
      "x": -11,
      "y": 26,
      "z": 0,
      "name": "Empty"
    },
    {
      "x": -11,
      "y": 27,
      "z": 0,
      "name": "Empty"
    },
    {
      "x": -11,
      "y": 28,
      "z": 0,
      "name": "Empty"
    },
    {
      "x": -11,
      "y": 29,
      "z": 0,
      "name": "Empty"
    },
    {
      "x": -11,
      "y": 30,
      "z": 0,
      "name": "Rock_Sandstone"
    },
    {
      "x": -11,
      "y": 31,
      "z": 0,
      "name": "Soil_Dirt_Dry"
    },
    {
      "x": -11,
      "y": 12,
      "z": 1,
      "name": "Rock_Sandstone"
    },
    {
      "x": -11,
      "y": 13,
      "z": 1,
      "name": "Rock_Sandstone"
    },
    {
      "x": -11,
      "y": 14,
      "z": 1,
      "name": "Rock_Sandstone"
    },
    {
      "x": -11,
      "y": 15,
      "z": 1,
      "name": "Rock_Sandstone"
    },
    {
      "x": -11,
      "y": 16,
      "z": 1,
      "name": "Soil_Gravel_Sand_White"
    },
    {
      "x": -11,
      "y": 17,
      "z": 1,
      "name": "Soil_Gravel_Sand_White_Half"
    },
    {
      "x": -11,
      "y": 18,
      "z": 1,
      "name": "Empty"
    },
    {
      "x": -11,
      "y": 19,
      "z": 1,
      "name": "Empty"
    },
    {
      "x": -11,
      "y": 20,
      "z": 1,
      "name": "Empty"
    },
    {
      "x": -11,
      "y": 21,
      "z": 1,
      "name": "Empty"
    },
    {
      "x": -11,
      "y": 22,
      "z": 1,
      "name": "Empty"
    },
    {
      "x": -11,
      "y": 23,
      "z": 1,
      "name": "Empty"
    },
    {
      "x": -11,
      "y": 24,
      "z": 1,
      "name": "Empty"
    },
    {
      "x": -11,
      "y": 25,
      "z": 1,
      "name": "Empty"
    },
    {
      "x": -11,
      "y": 26,
      "z": 1,
      "name": "Empty"
    },
    {
      "x": -11,
      "y": 27,
      "z": 1,
      "name": "Empty"
    },
    {
      "x": -11,
      "y": 28,
      "z": 1,
      "name": "Empty"
    },
    {
      "x": -11,
      "y": 29,
      "z": 1,
      "name": "Empty"
    },
    {
      "x": -11,
      "y": 30,
      "z": 1,
      "name": "Rock_Sandstone"
    },
    {
      "x": -11,
      "y": 31,
      "z": 1,
      "name": "Soil_Dirt_Dry"
    },
    {
      "x": -11,
      "y": 12,
      "z": 2,
      "name": "Rock_Sandstone"
    },
    {
      "x": -11,
      "y": 13,
      "z": 2,
      "name": "Rock_Sandstone"
    },
    {
      "x": -11,
      "y": 14,
      "z": 2,
      "name": "Rock_Sandstone"
    },
    {
      "x": -11,
      "y": 15,
      "z": 2,
      "name": "Rock_Sandstone"
    },
    {
      "x": -11,
      "y": 16,
      "z": 2,
