{
  "version": 8,
  "blockIdVersion": 8,
  "anchorX": 0,
  "anchorY": 13,
  "anchorZ": 0,
  "blocks": [
    {
      "x": -13,
      "y": 12,
      "z": -4,
      "name": "Rock_Marble"
    },
    {
      "x": -13,
      "y": 13,
      "z": -4,
      "name": "Rock_Marble"
    },
    {
      "x": -13,
      "y": 14,
      "z": -4,
      "name": "Rock_Marble"
    },
    {
      "x": -13,
      "y": 15,
      "z": -4,
      "name": "Rock_Marble"
    },
    {
      "x": -13,
      "y": 10,
      "z": -3,
      "name": "Rock_Marble"
    },
    {
      "x": -13,
      "y": 11,
      "z": -3,
      "name": "Rock_Marble"
    },
    {
      "x": -13,
      "y": 12,
      "z": -3,
      "name": "Rock_Marble"
    },
    {
      "x": -13,
      "y": 13,
      "z": -3,
      "name": "Rock_Marble"
    },
    {
      "x": -13,
      "y": 14,
      "z": -3,
      "name": "Rock_Marble"
    },
    {
      "x": -13,
      "y": 15,
      "z": -3,
      "name": "Rock_Marble"
    },
    {
      "x": -13,
      "y": 16,
      "z": -3,
      "name": "Rock_Marble"
    },
    {
      "x": -13,
      "y": 17,
      "z": -3,
      "name": "Rock_Marble"
    },
    {
      "x": -13,
      "y": 10,
      "z": -2,
      "name": "Rock_Marble"
    },
    {
      "x": -13,
      "y": 11,
      "z": -2,
      "name": "Rock_Marble"
    },
    {
      "x": -13,
      "y": 12,
      "z": -2,
      "name": "Rock_Marble"
    },
    {
      "x": -13,
      "y": 13,
      "z": -2,
      "name": "Rock_Marble"
    },
    {
      "x": -13,
      "y": 14,
      "z": -2,
      "name": "Rock_Marble"
    },
    {
      "x": -13,
      "y": 15,
      "z": -2,
      "name": "Rock_Marble"
    },
    {
      "x": -13,
      "y": 16,
      "z": -2,
      "name": "Rock_Marble"
    },
    {
      "x": -13,
      "y": 17,
      "z": -2,
      "name": "Rock_Marble"
    },
    {
      "x": -13,
      "y": 10,
      "z": -1,
      "name": "Rock_Marble"
    },
    {
      "x": -13,
      "y": 11,
      "z": -1,
      "name": "Rock_Marble"
    },
    {
      "x": -13,
      "y": 12,
      "z": -1,
      "name": "Rock_Marble"
    },
    {
      "x": -13,
      "y": 13,
      "z": -1,
      "name": "Rock_Marble"
    },
    {
      "x": -13,
      "y": 14,
      "z": -1,
      "name": "Rock_Marble"
    },
    {
      "x": -13,
      "y": 15,
      "z": -1,
      "name": "Rock_Marble"
    },
    {
      "x": -13,
      "y": 16,
      "z": -1,
      "name": "Rock_Marble"
    },
    {
      "x": -13,
      "y": 10,
      "z": 0,
      "name": "Rock_Marble"
    },
    {
      "x": -13,
      "y": 11,
      "z": 0,
      "name": "Rock_Marble"
    },
    {
      "x": -13,
      "y": 12,
      "z": 0,
      "name": "Rock_Marble"
    },
    {
      "x": -13,
      "y": 13,
      "z": 0,
      "name": "Rock_Marble"
    },
    {
      "x": -13,
      "y": 14,
      "z": 0,
      "name": "Rock_Marble"
    },
    {
      "x": -13,
      "y": 15,
      "z": 0,
      "name": "Rock_Marble"
    },
    {
      "x": -13,
      "y": 27,
      "z": 0,
      "name": "Rock_Marble"
    },
    {
      "x": -13,
      "y": 28,
      "z": 0,
      "name": "Rock_Marble"
    },
    {
      "x": -13,
      "y": 10,
      "z": 1,
      "name": "Rock_Marble"
    },
    {
      "x": -13,
      "y": 11,
      "z": 1,
      "name": "Rock_Marble"
    },
    {
      "x": -13,
      "y": 12,
      "z": 1,
      "name": "Rock_Marble"
    },
    {
      "x": -13,
      "y": 13,
      "z": 1,
      "name": "Rock_Marble"
    },
    {
      "x": -13,
      "y": 24,
      "z": 1,
      "name": "Rock_Marble"
    },
    {
      "x": -13,
      "y": 25,
      "z": 1,
      "name": "Rock_Marble"
    },
    {
      "x": -13,
      "y": 26,
      "z": 1,
      "name": "Rock_Marble"
    },
    {
      "x": -13,
      "y": 27,
      "z": 1,
      "name": "Rock_Marble"
    },
    {
      "x": -13,
      "y": 28,
      "z": 1,
      "name": "Soil_Grass"
    },
    {
      "x": -13,
      "y": 21,
      "z": 2,
      "name": "Rock_Marble"
    },
    {
      "x": -13,
      "y": 22,
      "z": 2,
      "name": "Rock_Marble"
    },
    {
      "x": -13,
      "y": 23,
      "z": 2,
      "name": "Rock_Marble"
    },
    {
      "x": -13,
      "y": 24,
      "z": 2,
      "name": "Rock_Marble"
    },
    {
      "x": -13,
      "y": 25,
      "z": 2,
      "name": "Rock_Marble"
    },
    {
      "x": -13,
      "y": 26,
      "z": 2,
      "name": "Rock_Marble"
    },
    {
      "x": -13,
      "y": 27,
      "z": 2,
      "name": "Rock_Marble"
    },
    {
      "x": -13,
      "y": 28,
      "z": 2,
      "name": "Rock_Marble"
    },
    {
      "x": -13,
      "y": 23,
      "z": 3,
      "name": "Rock_Marble"
    },
    {
      "x": -13,
      "y": 24,
      "z": 3,
      "name": "Rock_Marble"
    },
    {
      "x": -13,
      "y": 25,
      "z": 3,
      "name": "Rock_Marble"
    },
    {
      "x": -13,
      "y": 26,
      "z": 3,
      "name": "Rock_Marble"
    },
    {
      "x": -13,
      "y": 27,
      "z": 3,
      "name": "Rock_Marble"
    },
    {
      "x": -13,
      "y": 28,
      "z": 3,
      "name": "Rock_Marble"
    },
    {
      "x": -12,
      "y": 11,
      "z": -5,
      "name": "Rock_Marble"
    },
    {
      "x": -12,
      "y": 12,
      "z": -5,
      "name": "Rock_Marble"
    },
    {
      "x": -12,
      "y": 13,
      "z": -5,
      "name": "Rock_Marble"
    },
    {
      "x": -12,
      "y": 14,
      "z": -5,
      "name": "Rock_Marble"
    },
    {
      "x": -12,
      "y": 15,
      "z": -5,
      "name": "Rock_Marble"
    },
    {
      "x": -12,
      "y": 16,
      "z": -5,
      "name": "Rock_Marble"
    },
    {
      "x": -12,
      "y": 17,
      "z": -5,
      "name": "Rock_Marble"
    },
    {
      "x": -12,
      "y": 18,
      "z": -5,
      "name": "Rock_Chalk"
    },
    {
      "x": -12,
      "y": 10,
      "z": -4,
      "name": "Rock_Marble"
    },
    {
      "x": -12,
      "y": 11,
      "z": -4,
      "name": "Rock_Marble"
    },
    {
      "x": -12,
      "y": 12,
      "z": -4,
      "name": "Rock_Marble"
    },
    {
      "x": -12,
      "y": 13,
      "z": -4,
      "name": "Rock_Marble"
    },
    {
      "x": -12,
      "y": 14,
      "z": -4,
      "name": "Rock_Marble"
    },
    {
      "x": -12,
      "y": 15,
      "z": -4,
      "name": "Rock_Marble"
    },
    {
      "x": -12,
      "y": 16,
      "z": -4,
      "name": "Rock_Marble"
    },
    {
      "x": -12,
      "y": 17,
      "z": -4,
      "name": "Rock_Marble"
    },
    {
      "x": -12,
      "y": 18,
      "z": -4,
      "name": "Rock_Marble"
    },
    {
      "x": -12,
      "y": 19,
      "z": -4,
      "name": "Rock_Marble"
    },
    {
      "x": -12,
      "y": 20,
      "z": -4,
      "name": "Rock_Marble"
    },
    {
      "x": -12,
      "y": 21,
      "z": -4,
      "name": "Rock_Marble"
    },
    {
      "x": -12,
      "y": 9,
      "z": -3,
      "name": "Rock_Marble"
    },
    {
      "x": -12,
      "y": 10,
      "z": -3,
      "name": "Rock_Marble"
    },
    {
      "x": -12,
      "y": 11,
      "z": -3,
      "name": "Rock_Marble"
    },
    {
      "x": -12,
      "y": 12,
      "z": -3,
      "name": "Rock_Marble"
    },
    {
      "x": -12,
      "y": 13,
      "z": -3,
      "name": "Rock_Marble"
    },
    {
      "x": -12,
      "y": 14,
      "z": -3,
      "name": "Rock_Marble"
    },
    {
      "x": -12,
      "y": 15,
      "z": -3,
      "name": "Rock_Marble"
    },
    {
      "x": -12,
      "y": 16,
      "z": -3,
      "name": "Rock_Marble"
    },
    {
      "x": -12,
      "y": 17,
      "z": -3,
      "name": "Rock_Marble"
    },
    {
      "x": -12,
      "y": 18,
      "z": -3,
      "name": "Rock_Marble"
    },
    {
      "x": -12,
      "y": 19,
      "z": -3,
      "name": "Rock_Marble"
    },
    {
      "x": -12,
      "y": 20,
      "z": -3,
      "name": "Rock_Marble"
    },
    {
      "x": -12,
      "y": 21,
      "z": -3,
      "name": "Rock_Marble"
    },
    {
      "x": -12,
      "y": 22,
      "z": -3,
      "name": "Rock_Marble"
    },
    {
      "x": -12,
      "y": 9,
      "z": -2,
      "name": "Rock_Marble"
    },
    {
      "x": -12,
      "y": 10,
      "z": -2,
      "name": "Rock_Marble"
    },
    {
      "x": -12,
      "y": 11,
      "z": -2,
      "name": "Rock_Marble"
    },
    {
      "x": -12,
      "y": 12,
      "z": -2,
      "name": "Rock_Marble"
    },
    {
      "x": -12,
      "y": 13,
      "z": -2,
      "name": "Rock_Marble"
    },
    {
      "x": -12,
      "y": 14,
      "z": -2,
      "name": "Rock_Marble"
    },
    {
      "x": -12,
      "y": 15,
      "z": -2,
      "name": "Rock_Marble"
    },
    {
      "x": -12,
      "y": 16,
      "z": -2,
      "name": "Rock_Marble"
    },
    {
      "x": -12,
      "y": 17,
      "z": -2,
      "name": "Rock_Marble"
    },
    {
      "x": -12,
      "y": 18,
      "z": -2,
      "name": "Rock_Marble"
    },
    {
      "x": -12,
      "y": 19,
      "z": -2,
      "name": "Rock_Marble"
    },
    {
      "x": -12,
      "y": 20,
      "z": -2,
      "name": "Rock_Marble"
    },
    {
      "x": -12,
      "y": 21,
      "z": -2,
      "name": "Rock_Marble"
    },
    {
      "x": -12,
      "y": 22,
      "z": -2,
      "name": "Rock_Marble"
    },
    {
      "x": -12,
      "y": 28,
      "z": -2,
      "name": "Soil_Grass"
    },
    {
      "x": -12,
      "y": 9,
      "z": -1,
      "name": "Rock_Marble"
    },
    {
      "x": -12,
      "y": 10,
      "z": -1,
      "name": "Rock_Marble"
    },
    {
      "x": -12,
      "y": 11,
      "z": -1,
      "name": "Rock_Marble"
    },
    {
      "x": -12,
      "y": 12,
      "z": -1,
      "name": "Rock_Marble"
    },
    {
      "x": -12,
      "y": 13,
      "z": -1,
      "name": "Rock_Marble"
    },
    {
      "x": -12,
      "y": 14,
      "z": -1,
      "name": "Rock_Marble"
    },
    {
      "x": -12,
      "y": 15,
      "z": -1,
      "name": "Rock_Marble"
    },
    {
      "x": -12,
      "y": 16,
      "z": -1,
      "name": "Rock_Marble"
    },
    {
      "x": -12,
      "y": 17,
      "z": -1,
      "name": "Rock_Marble"
    },
    {
      "x": -12,
      "y": 18,
      "z": -1,
      "name": "Rock_Marble"
    },
    {
      "x": -12,
      "y": 19,
      "z": -1,
      "name": "Rock_Marble"
    },
    {
      "x": -12,
      "y": 20,
      "z": -1,
      "name": "Rock_Marble"
    },
    {
      "x": -12,
      "y": 21,
      "z": -1,
      "name": "Rock_Marble"
    },
    {
      "x": -12,
      "y": 22,
      "z": -1,
      "name": "Rock_Marble"
    },
    {
      "x": -12,
      "y": 23,
      "z": -1,
      "name": "Rock_Marble"
    },
    {
      "x": -12,
      "y": 24,
      "z": -1,
      "name": "Rock_Marble"
    },
    {
      "x": -12,
      "y": 25,
      "z": -1,
      "name": "Rock_Marble"
    },
    {
      "x": -12,
      "y": 26,
      "z": -1,
      "name": "Rock_Marble"
    },
    {
      "x": -12,
      "y": 27,
      "z": -1,
      "name": "Rock_Marble"
    },
    {
      "x": -12,
      "y": 28,
      "z": -1,
      "name": "Soil_Grass"
    },
    {
      "x": -12,
      "y": 9,
      "z": 0,
      "name": "Rock_Marble"
    },
    {
      "x": -12,
      "y": 10,
      "z": 0,
      "name": "Rock_Marble"
    },
    {
      "x": -12,
      "y": 11,
      "z": 0,
      "name": "Rock_Marble"
    },
    {
      "x": -12,
      "y": 12,
      "z": 0,
      "name": "Rock_Marble"
    },
    {
      "x": -12,
      "y": 13,
      "z": 0,
      "name": "Rock_Marble"
    },
    {
      "x": -12,
      "y": 14,
      "z": 0,
      "name": "Rock_Marble"
    },
    {
      "x": -12,
      "y": 15,
      "z": 0,
      "name": "Rock_Marble"
    },
    {
      "x": -12,
      "y": 16,
      "z": 0,
      "name": "Rock_Marble"
    },
    {
      "x": -12,
      "y": 17,
      "z": 0,
      "name": "Rock_Marble"
    },
    {
      "x": -12,
      "y": 18,
      "z": 0,
      "name": "Rock_Marble"
    },
    {
      "x": -12,
      "y": 19,
      "z": 0,
      "name": "Rock_Marble"
    },
    {
      "x": -12,
      "y": 20,
      "z": 0,
      "name": "Rock_Marble"
    },
    {
      "x": -12,
      "y": 21,
      "z": 0,
      "name": "Rock_Marble"
    },
    {
      "x": -12,
      "y": 22,
      "z": 0,
      "name": "Rock_Marble"
    },
    {
      "x": -12,
      "y": 23,
      "z": 0,
      "name": "Rock_Marble"
    },
    {
      "x": -12,
      "y": 24,
      "z": 0,
      "name": "Rock_Marble"
    },
    {
      "x": -12,
      "y": 25,
      "z": 0,
      "name": "Rock_Marble"
    },
    {
      "x": -12,
      "y": 26,
      "z": 0,
      "name": "Rock_Marble"
    },
    {
      "x": -12,
      "y": 27,
      "z": 0,
      "name": "Rock_Marble"
    },
    {
      "x": -12,
      "y": 28,
      "z": 0,
      "name": "Soil_Grass"
    },
    {
      "x": -12,
      "y": 8,
      "z": 1,
      "name": "Rock_Marble"
    },
    {
      "x": -12,
      "y": 9,
      "z": 1,
      "name": "Rock_Marble"
    },
    {
      "x": -12,
      "y": 10,
      "z": 1,
      "name": "Rock_Marble"
    },
    {
      "x": -12,
      "y": 11,
      "z": 1,
      "name": "Rock_Marble"
    },
    {
      "x": -12,
      "y": 12,
      "z": 1,
      "name": "Rock_Marble"
    },
    {
      "x": -12,
      "y": 13,
      "z": 1,
      "name": "Rock_Marble"
    },
    {
      "x": -12,
      "y": 14,
      "z": 1,
      "name": "Rock_Marble"
    },
    {
      "x": -12,
      "y": 15,
      "z": 1,
      "name": "Rock_Marble"
    },
    {
      "x": -12,
      "y": 16,
      "z": 1,
      "name": "Rock_Marble"
    },
    {
      "x": -12,
      "y": 17,
      "z": 1,
      "name": "Rock_Marble"
    },
    {
      "x": -12,
      "y": 18,
      "z": 1,
      "name": "Rock_Marble"
    },
    {
      "x": -12,
      "y": 19,
      "z": 1,
      "name": "Rock_Marble"
    },
    {
      "x": -12,
      "y": 20,
      "z": 1,
      "name": "Rock_Marble"
    },
    {
      "x": -12,
      "y": 21,
      "z": 1,
      "name": "Rock_Marble"
    },
    {
      "x": -12,
      "y": 22,
      "z": 1,
      "name": "Rock_Marble"
    },
    {
      "x": -12,
      "y": 23,
      "z": 1,
      "name": "Rock_Marble"
    },
    {
      "x": -12,
      "y": 24,
      "z": 1,
      "name": "Rock_Marble"
    },
    {
      "x": -12,
      "y": 25,
      "z": 1,
      "name": "Rock_Marble"
    },
    {
      "x": -12,
      "y": 26,
      "z": 1,
      "name": "Rock_Marble"
    },
    {
      "x": -12,
      "y": 27,
      "z": 1,
      "name": "Rock_Marble"
    },
    {
      "x": -12,
      "y": 28,
      "z": 1,
      "name": "Soil_Grass"
    },
    {
      "x": -12,
      "y": 9,
      "z": 2,
      "name": "Rock_Marble"
    },
    {
      "x": -12,
      "y": 10,
      "z": 2,
      "name": "Rock_Marble"
    },
    {
      "x": -12,
      "y": 11,
      "z": 2,
      "name": "Rock_Marble"
    },
    {
      "x": -12,
      "y": 12,
      "z": 2,
      "name": "Rock_Marble"
    },
    {
      "x": -12,
      "y": 13,
      "z": 2,
      "name": "Rock_Marble"
    },
    {
      "x": -12,
      "y": 14,
      "z": 2,
      "name": "Rock_Marble"
    },
    {
      "x": -12,
      "y": 15,
      "z": 2,
      "name": "Rock_Marble"
    },
    {
      "x": -12,
      "y": 16,
      "z": 2,
      "name": "Rock_Marble"
    },
    {
      "x": -12,
      "y": 17,
      "z": 2,
      "name": "Rock_Marble"
    },
    {
      "x": -12,
      "y": 18,
      "z": 2,
      "name": "Rock_Marble"
    },
    {
      "x": -12,
      "y": 19,
      "z": 2,
      "name": "Rock_Marble"
    },
    {
      "x": -12,
      "y": 20,
      "z": 2,
      "name": "Rock_Marble"
    },
    {
      "x": -12,
      "y": 21,
      "z": 2,
      "name": "Rock_Marble"
    },
    {
      "x": -12,
      "y": 22,
      "z": 2,
      "name": "Rock_Marble"
    },
    {
      "x": -12,
      "y": 23,
      "z": 2,
      "name": "Rock_Marble"
    },
    {
      "x": -12,
      "y": 24,
      "z": 2,
      "name": "Rock_Marble"
    },
    {
      "x": -12,
      "y": 25,
      "z": 2,
      "name": "Rock_Marble"
    },
    {
      "x": -12,
      "y": 26,
      "z": 2,
      "name": "Rock_Marble"
    },
    {
      "x": -12,
      "y": 27,
      "z": 2,
      "name": "Rock_Marble"
    },
    {
      "x": -12,
      "y": 28,
      "z": 2,
      "name": "Soil_Grass"
    },
    {
      "x": -12,
      "y": 10,
      "z": 3,
      "name": "Rock_Marble"
    },
    {
      "x": -12,
      "y": 11,
      "z": 3,
      "name": "Rock_Marble"
    },
    {
      "x": -12,
      "y": 12,
      "z": 3,
      "name": "Rock_Marble"
    },
    {
      "x": -12,
      "y": 13,
      "z": 3,
      "name": "Rock_Marble"
    },
    {
      "x": -12,
      "y": 14,
      "z": 3,
      "name": "Rock_Marble"
    },
    {
      "x": -12,
      "y": 15,
      "z": 3,
      "name": "Rock_Marble"
    },
    {
      "x": -12,
      "y": 16,
      "z": 3,
      "name": "Rock_Marble"
    },
    {
      "x": -12,
      "y": 17,
      "z": 3,
      "name": "Rock_Marble"
    },
    {
      "x": -12,
      "y": 18,
      "z": 3,
      "name": "Rock_Marble"
    },
    {
      "x": -12,
      "y": 19,
      "z": 3,
      "name": "Rock_Marble"
    },
    {
      "x": -12,
      "y": 20,
      "z": 3,
      "name": "Rock_Marble"
    },
    {
      "x": -12,
      "y": 21,
      "z": 3,
      "name": "Rock_Marble"
    },
    {
      "x": -12,
      "y": 22,
      "z": 3,
      "name": "Rock_Marble"
    },
    {
      "x": -12,
      "y": 23,
      "z": 3,
      "name": "Rock_Marble"
    },
    {
      "x": -12,
      "y": 24,
      "z": 3,
      "name": "Rock_Marble"
    },
    {
      "x": -12,
      "y": 25,
      "z": 3,
      "name": "Rock_Marble"
    },
    {
      "x": -12,
      "y": 26,
      "z": 3,
      "name": "Rock_Marble"
    },
    {
      "x": -12,
      "y": 27,
      "z": 3,
      "name": "Rock_Marble"
    },
    {
      "x": -12,
      "y": 28,
      "z": 3,
      "name": "Rock_Marble"
    },
    {
      "x": -12,
      "y": 29,
      "z": 3,
      "name": "Soil_Grass"
    },
    {
      "x": -12,
      "y": 16,
      "z": 4,
      "name": "Rock_Marble"
    },
    {
      "x": -12,
      "y": 17,
      "z": 4,
      "name": "Rock_Marble"
    },
    {
      "x": -12,
      "y": 18,
      "z": 4,
      "name": "Rock_Marble"
    },
    {
      "x": -12,
      "y": 19,
      "z": 4,
      "name": "Rock_Marble"
    },
    {
      "x": -12,
      "y": 20,
      "z": 4,
      "name": "Rock_Marble"
    },
    {
      "x": -12,
      "y": 21,
      "z": 4,
      "name": "Rock_Marble"
    },
    {
      "x": -12,
      "y": 22,
      "z": 4,
      "name": "Rock_Marble"
    },
    {
      "x": -12,
      "y": 23,
      "z": 4,
      "name": "Rock_Marble"
    },
    {
      "x": -12,
      "y": 24,
      "z": 4,
      "name": "Rock_Marble"
    },
    {
      "x": -12,
      "y": 25,
      "z": 4,
      "name": "Rock_Marble"
    },
    {
      "x": -12,
      "y": 26,
      "z": 4,
      "name": "Rock_Marble"
    },
    {
      "x": -12,
      "y": 27,
      "z": 4,
      "name": "Rock_Marble"
    },
    {
      "x": -12,
      "y": 28,
      "z": 4,
      "name": "Rock_Marble"
    },
    {
      "x": -12,
      "y": 29,
      "z": 4,
      "name": "Soil_Grass"
    },
    {
      "x": -12,
      "y": 21,
      "z": 5,
      "name": "Rock_Marble"
    },
    {
      "x": -12,
      "y": 22,
      "z": 5,
      "name": "Rock_Marble"
    },
    {
      "x": -12,
      "y": 23,
      "z": 5,
      "name": "Rock_Marble"
    },
    {
      "x": -12,
      "y": 24,
      "z": 5,
      "name": "Rock_Marble"
    },
    {
      "x": -12,
      "y": 25,
      "z": 5,
      "name": "Rock_Marble"
    },
    {
      "x": -12,
      "y": 26,
      "z": 5,
      "name": "Rock_Marble"
    },
    {
      "x": -11,
      "y": 10,
      "z": -6,
      "name": "Rock_Marble"
    },
    {
      "x": -11,
      "y": 11,
      "z": -6,
      "name": "Rock_Marble"
    },
    {
      "x": -11,
      "y": 12,
      "z": -6,
      "name": "Rock_Marble"
    },
    {
      "x": -11,
      "y": 13,
      "z": -6,
      "name": "Rock_Marble"
    },
    {
      "x": -11,
      "y": 14,
      "z": -6,
      "name": "Rock_Marble"
    },
    {
      "x": -11,
      "y": 15,
      "z": -6,
      "name": "Rock_Marble"
    },
    {
      "x": -11,
      "y": 16,
      "z": -6,
      "name": "Rock_Marble"
    },
    {
      "x": -11,
      "y": 17,
      "z": -6,
      "name": "Rock_Chalk"
    },
    {
      "x": -11,
      "y": 18,
      "z": -6,
      "name": "Rock_Chalk"
    },
    {
      "x": -11,
      "y": 19,
      "z": -6,
      "name": "Rock_Chalk"
    },
    {
      "x": -11,
      "y": 20,
      "z": -6,
      "name": "Rock_Chalk"
    },
    {
      "x": -11,
      "y": 10,
      "z": -5,
      "name": "Rock_Marble"
    },
    {
      "x": -11,
      "y": 11,
      "z": -5,
      "name": "Rock_Marble"
    },
    {
      "x": -11,
      "y": 12,
      "z": -5,
      "name": "Rock_Marble"
    },
    {
      "x": -11,
      "y": 13,
      "z": -5,
      "name": "Rock_Marble"
    },
    {
      "x": -11,
      "y": 14,
      "z": -5,
      "name": "Rock_Marble"
    },
    {
      "x": -11,
      "y": 15,
      "z": -5,
      "name": "Rock_Marble"
    },
    {
      "x": -11,
      "y": 16,
      "z": -5,
      "name": "Rock_Marble"
    },
    {
      "x": -11,
      "y": 17,
      "z": -5,
      "name": "Rock_Marble"
    },
    {
      "x": -11,
      "y": 18,
      "z": -5,
      "name": "Rock_Marble"
    },
    {
      "x": -11,
      "y": 19,
      "z": -5,
      "name": "Rock_Marble"
    },
    {
      "x": -11,
      "y": 20,
      "z": -5,
      "name": "Rock_Marble"
    },
    {
      "x": -11,
      "y": 21,
      "z": -5,
      "name": "Rock_Marble"
    },
    {
      "x": -11,
      "y": 22,
      "z": -5,
      "name": "Rock_Marble"
    },
    {
      "x": -11,
      "y": 23,
      "z": -5,
      "name": "Rock_Marble"
    },
    {
      "x": -11,
      "y": 24,
      "z": -5,
      "name": "Rock_Marble"
    },
    {
      "x": -11,
      "y": 25,
      "z": -5,
      "name": "Rock_Marble"
    },
    {
      "x": -11,
      "y": 9,
      "z": -4,
      "name": "Rock_Marble"
    },
    {
      "x": -11,
      "y": 10,
      "z": -4,
      "name": "Rock_Marble"
    },
    {
      "x": -11,
      "y": 11,
      "z": -4,
      "name": "Rock_Marble"
    },
    {
      "x": -11,
      "y": 12,
      "z": -4,
      "name": "Rock_Marble"
    },
    {
      "x": -11,
      "y": 13,
      "z": -4,
      "name": "Rock_Marble"
    },
    {
      "x": -11,
      "y": 14,
      "z": -4,
      "name": "Rock_Marble"
    },
    {
      "x": -11,
      "y": 15,
      "z": -4,
      "name": "Rock_Marble"
    },
    {
      "x": -11,
      "y": 16,
      "z": -4,
      "name": "Rock_Marble"
    },
    {
      "x": -11,
      "y": 17,
      "z": -4,
      "name": "Rock_Marble"
    },
    {
      "x": -11,
      "y": 18,
      "z": -4,
      "name": "Rock_Marble"
    },
    {
      "x": -11,
      "y": 19,
      "z": -4,
      "name": "Rock_Marble"
    },
    {
      "x": -11,
      "y": 20,
      "z": -4,
      "name": "Rock_Marble"
    },
    {
      "x": -11,
      "y": 21,
      "z": -4,
      "name": "Rock_Marble"
    },
    {
      "x": -11,
      "y": 22,
      "z": -4,
      "name": "Rock_Marble"
    },
    {
      "x": -11,
      "y": 23,
      "z": -4,
      "name": "Rock_Marble"
    },
    {
      "x": -11,
      "y": 24,
      "z": -4,
      "name": "Rock_Marble"
    },
    {
      "x": -11,
      "y": 25,
      "z": -4,
      "name": "Rock_Marble"
    },
    {
      "x": -11,
      "y": 26,
      "z": -4,
      "name": "Rock_Marble"
    },
    {
      "x": -11,
      "y": 27,
      "z": -4,
      "name": "Rock_Marble"
    },
    {
      "x": -11,
      "y": 9,
      "z": -3,
      "name": "Rock_Marble"
    },
    {
      "x": -11,
      "y": 10,
      "z": -3,
      "name": "Rock_Marble"
    },
    {
      "x": -11,
      "y": 11,
      "z": -3,
      "name": "Rock_Marble"
    },
    {
      "x": -11,
      "y": 12,
      "z": -3,
      "name": "Rock_Marble"
    },
    {
      "x": -11,
      "y": 13,
      "z": -3,
      "name": "Rock_Marble"
    },
    {
      "x": -11,
      "y": 14,
      "z": -3,
      "name": "Rock_Marble"
    },
    {
      "x": -11,
      "y": 15,
      "z": -3,
      "name": "Rock_Marble"
    },
    {
      "x": -11,
      "y": 16,
      "z": -3,
      "name": "Rock_Marble"
    },
    {
      "x": -11,
      "y": 17,
      "z": -3,
      "name": "Rock_Marble"
    },
    {
      "x": -11,
      "y": 18,
      "z": -3,
      "name": "Rock_Marble"
    },
    {
      "x": -11,
      "y": 19,
      "z": -3,
      "name": "Rock_Marble"
    },
    {
      "x": -11,
      "y": 20,
      "z": -3,
      "name": "Rock_Marble"
    },
    {
      "x": -11,
      "y": 21,
      "z": -3,
      "name": "Rock_Marble"
    },
    {
      "x": -11,
      "y": 22,
      "z": -3,
      "name": "Rock_Marble"
    },
    {
      "x": -11,
      "y": 23,
      "z": -3,
      "name": "Rock_Marble"
    },
    {
      "x": -11,
      "y": 24,
      "z": -3,
      "name": "Rock_Marble"
    },
    {
      "x": -11,
      "y": 25,
      "z": -3,
      "name": "Rock_Marble"
    },
    {
      "x": -11,
      "y": 26,
      "z": -3,
      "name": "Rock_Marble"
    },
    {
      "x": -11,
      "y": 27,
      "z": -3,
      "name": "Rock_Marble"
    },
    {
      "x": -11,
      "y": 28,
      "z": -3,
      "name": "Soil_Grass"
    },
    {
      "x": -11,
      "y": 8,
      "z": -2,
      "name": "Rock_Marble"
    },
    {
      "x": -11,
      "y": 9,
      "z": -2,
      "name": "Rock_Marble"
    },
    {
      "x": -11,
      "y": 10,
      "z": -2,
      "name": "Rock_Marble"
    },
    {
      "x": -11,
      "y": 11,
      "z": -2,
      "name": "Rock_Marble"
    },
    {
      "x": -11,
      "y": 12,
      "z": -2,
      "name": "Rock_Marble"
    },
    {
      "x": -11,
      "y": 13,
      "z": -2,
      "name": "Rock_Marble"
    },
    {
      "x": -11,
      "y": 14,
      "z": -2,
      "name": "Rock_Marble"
    },
    {
      "x": -11,
      "y": 15,
      "z": -2,
      "name": "Rock_Marble"
    },
    {
      "x": -11,
      "y": 16,
      "z": -2,
      "name": "Rock_Marble"
    },
    {
      "x": -11,
      "y": 17,
      "z": -2,
      "name": "Rock_Marble"
    },
    {
      "x": -11,
      "y": 18,
      "z": -2,
      "name": "Rock_Marble"
    },
    {
      "x": -11,
      "y": 19,
      "z": -2,
      "name": "Rock_Marble"
    },
    {
      "x": -11,
      "y": 20,
      "z": -2,
      "name": "Rock_Marble"
    },
    {
      "x": -11,
      "y": 21,
      "z": -2,
      "name": "Rock_Marble"
    },
    {
      "x": -11,
      "y": 22,
      "z": -2,
      "name": "Rock_Marble"
    },
    {
      "x": -11,
      "y": 23,
      "z": -2,
      "name": "Rock_Marble"
    },
    {
      "x": -11,
      "y": 24,
      "z": -2,
      "name": "Rock_Marble"
    },
    {
      "x": -11,
      "y": 25,
      "z": -2,
      "name": "Rock_Marble"
    },
    {
      "x": -11,
      "y": 26,
      "z": -2,
      "name": "Rock_Marble"
    },
    {
      "x": -11,
      "y": 27,
      "z": -2,
      "name": "Rock_Marble"
    },
    {
      "x": -11,
      "y": 28,
      "z": -2,
      "name": "Soil_Grass"
    },
    {
      "x": -11,
      "y": 8,
      "z": -1,
      "name": "Rock_Marble"
    },
    {
      "x": -11,
      "y": 9,
      "z": -1,
      "name": "Rock_Marble"
    },
    {
      "x": -11,
      "y": 10,
      "z": -1,
      "name": "Rock_Marble"
    },
    {
      "x": -11,
      "y": 11,
      "z": -1,
      "name": "Rock_Marble"
    },
    {
      "x": -11,
      "y": 12,
      "z": -1,
      "name": "Rock_Marble"
    },
    {
      "x": -11,
      "y": 13,
      "z": -1,
      "name": "Rock_Marble"
    },
    {
      "x": -11,
      "y": 14,
      "z": -1,
      "name": "Rock_Marble"
    },
    {
      "x": -11,
      "y": 15,
      "z": -1,
      "name": "Rock_Marble"
    },
    {
      "x": -11,
      "y": 16,
      "z": -1,
      "name": "Rock_Marble"
    },
    {
      "x": -11,
      "y": 17,
      "z": -1,
      "name": "Rock_Marble"
    },
    {
      "x": -11,
      "y": 18,
      "z": -1,
      "name": "Rock_Marble"
    },
    {
      "x": -11,
      "y": 19,
      "z": -1,
      "name": "Rock_Marble"
    },
    {
      "x": -11,
      "y": 20,
      "z": -1,
      "name": "Rock_Marble"
    },
    {
      "x": -11,
      "y": 21,
      "z": -1,
      "name": "Rock_Marble"
    },
    {
      "x": -11,
      "y": 22,
      "z": -1,
      "name": "Rock_Marble"
    },
    {
      "x": -11,
      "y": 23,
      "z": -1,
      "name": "Rock_Marble"
    },
    {
      "x": -11,
      "y": 24,
      "z": -1,
      "name": "Rock_Marble"
    },
    {
      "x": -11,
      "y": 25,
      "z": -1,
      "name": "Rock_Marble"
    },
    {
      "x": -11,
      "y": 26,
      "z": -1,
      "name": "Rock_Marble"
    },
    {
      "x": -11,
      "y": 27,
      "z": -1,
      "name": "Rock_Marble"
    },
    {
      "x": -11,
      "y": 28,
      "z": -1,
      "name": "Soil_Grass"
    },
    {
      "x": -11,
      "y": 8,
      "z": 0,
      "name": "Rock_Marble"
    },
    {
      "x": -11,
      "y": 9,
      "z": 0,
      "name": "Rock_Marble"
    },
    {
      "x": -11,
      "y": 10,
      "z": 0,
      "name": "Rock_Marble"
    },
    {
      "x": -11,
      "y": 11,
      "z": 0,
      "name": "Rock_Marble"
    },
    {
      "x": -11,
      "y": 12,
      "z": 0,
      "name": "Rock_Marble"
    },
    {
      "x": -11,
      "y": 13,
      "z": 0,
      "name": "Rock_Marble"
    },
    {
      "x": -11,
      "y": 14,
      "z": 0,
      "name": "Rock_Marble"
    },
    {
      "x": -11,
      "y": 15,
      "z": 0,
      "name": "Rock_Marble"
    },
    {
      "x": -11,
      "y": 16,
      "z": 0,
      "name": "Rock_Marble"
    },
    {
      "x": -11,
      "y": 17,
      "z": 0,
      "name": "Rock_Marble"
    },
    {
      "x": -11,
      "y": 18,
      "z": 0,
      "name": "Rock_Marble"
    },
    {
      "x": -11,
      "y": 19,
      "z": 0,
      "name": "Rock_Marble"
    },
    {
      "x": -11,
      "y": 20,
      "z": 0,
      "name": "Rock_Marble"
    },
    {
      "x": -11,
      "y": 21,
      "z": 0,
      "name": "Rock_Marble"
    },
    {
      "x": -11,
      "y": 22,
      "z": 0,
      "name": "Rock_Marble"
    },
    {
      "x": -11,
      "y": 23,
      "z": 0,
      "name": "Rock_Marble"
    },
    {
      "x": -11,
      "y": 24,
      "z": 0,
      "name": "Rock_Marble"
    },
    {
      "x": -11,
      "y": 25,
      "z": 0,
      "name": "Rock_Marble"
    },
    {
      "x": -11,
      "y": 26,
      "z": 0,
      "name": "Rock_Marble"
    },
    {
      "x": -11,
      "y": 27,
      "z": 0,
      "name": "Soil_Dirt"
    },
    {
      "x": -11,
      "y": 28,
      "z": 0,
      "name": "Soil_Grass"
    },
    {
      "x": -11,
      "y": 7,
      "z": 1,
      "name": "Rock_Marble"
    },
    {
      "x": -11,
      "y": 8,
      "z": 1,
      "name": "Rock_Marble"
    },
    {
      "x": -11,
      "y": 9,
      "z": 1,
      "name": "Rock_Marble"
    },
    {
      "x": -11,
      "y": 10,
      "z": 1,
      "name": "Rock_Marble"
    },
    {
      "x": -11,
      "y": 11,
      "z": 1,
      "name": "Rock_Marble"
    },
    {
      "x": -11,
      "y": 12,
      "z": 1,
      "name": "Rock_Marble"
    },
    {
      "x": -11,
      "y": 13,
      "z": 1,
      "name": "Rock_Marble"
    },
    {
      "x": -11,
      "y": 14,
      "z": 1,
      "name": "Rock_Marble"
    },
    {
      "x": -11,
      "y": 15,
      "z": 1,
      "name": "Rock_Marble"
    },
    {
      "x": -11,
      "y": 16,
      "z": 1,
      "name": "Rock_Marble"
    },
    {
      "x": -11,
      "y": 17,
      "z": 1,
      "name": "Rock_Marble"
    },
    {
      "x": -11,
      "y": 18,
      "z": 1,
      "name": "Rock_Marble"
    },
    {
      "x": -11,
      "y": 19,
      "z": 1,
      "name": "Rock_Marble"
    },
    {
      "x": -11,
      "y": 20,
      "z": 1,
      "name": "Rock_Marble"
    },
    {
      "x": -11,
      "y": 21,
      "z": 1,
      "name": "Rock_Marble"
    },
    {
      "x": -11,
      "y": 22,
      "z": 1,
      "name": "Rock_Marble"
    },
    {
      "x": -11,
      "y": 23,
      "z": 1,
      "name": "Rock_Marble"
    },
    {
      "x": -11,
      "y": 24,
      "z": 1,
      "name": "Rock_Marble"
    },
    {
      "x": -11,
      "y": 25,
      "z": 1,
      "name": "Rock_Marble"
    },
    {
      "x": -11,
      "y": 26,
      "z": 1,
      "name": "Rock_Marble"
    },
    {
      "x": -11,
      "y": 27,
      "z": 1,
      "name": "Soil_Dirt"
    },
    {
      "x": -11,
      "y": 28,
      "z": 1,
      "name": "Soil_Grass"
    },
    {
      "x": -11,
      "y": 7,
      "z": 2,
      "name": "Rock_Marble"
    },
    {
      "x": -11,
      "y": 8,
      "z": 2,
      "name": "Rock_Marble"
    },
    {
      "x": -11,
      "y": 9,
      "z": 2,
      "name": "Rock_Marble"
    },
    {
      "x": -11,
      "y": 10,
      "z": 2,
      "name": "Rock_Marble"
    },
    {
      "x": -11,
      "y": 11,
      "z": 2,
      "name": "Rock_Marble"
    },
    {
      "x": -11,
      "y": 12,
      "z": 2,
      "name": "Rock_Marble"
    },
    {
      "x": -11,
      "y": 13,
      "z": 2,
      "name": "Rock_Marble"
    },
    {
      "x": -11,
      "y": 14,
      "z": 2,
      "name": "Rock_Marble"
    },
    {
      "x": -11,
      "y": 15,
      "z": 2,
      "name": "Rock_Marble"
    },
    {
      "x": -11,
      "y": 16,
      "z": 2,
      "name": "Rock_Marble"
    },
    {
      "x": -11,
      "y": 17,
      "z": 2,
      "name": "Rock_Marble"
    },
    {
      "x": -11,
      "y": 18,
      "z": 2,
      "name": "Rock_Marble"
    },
    {
      "x": -11,
      "y": 19,
      "z": 2,
      "name": "Rock_Marble"
    },
    {
      "x": -11,
      "y": 20,
      "z": 2,
      "name": "Rock_Marble"
    },
    {
      "x": -11,
      "y": 21,
      "z": 2,
      "name": "Rock_Marble"
    },
    {
      "x": -11,
      "y": 22,
      "z": 2,
      "name": "Rock_Marble"
    },
    {
      "x": -11,
      "y": 23,
      "z": 2,
      "name": "Rock_Marble"
    },
    {
      "x": -11,
      "y": 24,
      "z": 2,
      "name": "Rock_Marble"
    },
    {
      "x": -11,
      "y": 25,
      "z": 2,
      "name": "Rock_Marble"
    },
    {
      "x": -11,
      "y": 26,
      "z": 2,
      "name": "Rock_Marble"
    },
    {
      "x": -11,
      "y": 27,
      "z": 2,
      "name": "Rock_Marble"
    },
    {
      "x": -11,
      "y": 28,
      "z": 2,
      "name": "Soil_Dirt"
    },
    {
      "x": -11,
      "y": 29,
      "z": 2,
      "name": "Soil_Grass"
    },
    {
      "x": -11,
      "y": 8,
      "z": 3,
      "name": "Rock_Marble"
    },
    {
      "x": -11,
      "y": 9,
      "z": 3,
      "name": "Rock_Marble"
    },
    {
      "x": -11,
      "y": 10,
      "z": 3,
      "name": "Rock_Marble"
    },
    {
      "x": -11,
      "y": 11,
      "z": 3,
      "name": "Rock_Marble"
    },
    {
      "x": -11,
      "y": 12,
      "z": 3,
      "name": "Rock_Marble"
    },
    {
      "x": -11,
      "y": 13,
      "z": 3,
      "name": "Rock_Marble"
    },
    {
      "x": -11,
      "y": 14,
      "z": 3,
      "name": "Rock_Marble"
    },
    {
      "x": -11,
      "y": 15,
      "z": 3,
      "name": "Rock_Marble"
    },
    {
      "x": -11,
      "y": 16,
      "z": 3,
      "name": "Rock_Marble"
    },
    {
      "x": -11,
      "y": 17,
      "z": 3,
      "name": "Rock_Marble"
    },
    {
      "x": -11,
      "y": 18,
      "z": 3,
      "name": "Rock_Marble"
    },
    {
      "x": -11,
      "y": 19,
      "z": 3,
      "name": "Rock_Marble"
    },
    {
      "x": -11,
      "y": 20,
      "z": 3,
      "name": "Rock_Marble"
    },
    {
      "x": -11,
      "y": 21,
      "z": 3,
      "name": "Rock_Marble"
    },
    {
      "x": -11,
      "y": 22,
      "z": 3,
      "name": "Rock_Marble"
    },
    {
      "x": -11,
      "y": 23,
      "z": 3,
      "name": "Rock_Marble"
    },
    {
      "x": -11,
      "y": 24,
      "z": 3,
      "name": "Rock_Marble"
    },
    {
      "x": -11,
      "y": 25,
      "z": 3,
      "name": "Rock_Marble"
    },
    {
      "x": -11,
      "y": 26,
      "z": 3,
      "name": "Rock_Marble"
    },
    {
      "x": -11,
      "y": 27,
      "z": 3,
      "name": "Rock_Marble"
    },
    {
      "x": -11,
      "y": 28,
      "z": 3,
      "name": "Soil_Dirt"
    },
    {
      "x": -11,
      "y": 29,
      "z": 3,
      "name": "Soil_Grass"
    },
    {
      "x": -11,
      "y": 7,
      "z": 4,
      "name": "Rock_Marble"
    },
    {
      "x": -11,
      "y": 8,
      "z": 4,
      "name": "Rock_Marble"
    },
    {
      "x": -11,
      "y": 9,
      "z": 4,
      "name": "Rock_Marble"
    },
    {
      "x": -11,
      "y": 10,
      "z": 4,
      "name": "Rock_Marble"
    },
    {
      "x": -11,
      "y": 11,
      "z": 4,
      "name": "Rock_Marble"
    },
    {
      "x": -11,
      "y": 12,
      "z": 4,
      "name": "Rock_Marble"
    },
    {
      "x": -11,
      "y": 13,
      "z": 4,
      "name": "Rock_Marble"
    },
    {
      "x": -11,
      "y": 14,
      "z": 4,
      "name": "Rock_Marble"
    },
    {
      "x": -11,
      "y": 15,
      "z": 4,
      "name": "Rock_Marble"
    },
    {
      "x": -11,
      "y": 16,
      "z": 4,
      "name": "Rock_Marble"
    },
    {
      "x": -11,
      "y": 17,
      "z": 4,
      "name": "Rock_Marble"
    },
    {
      "x": -11,
      "y": 18,
      "z": 4,
      "name": "Rock_Marble"
    },
    {
      "x": -11,
      "y": 19,
      "z": 4,
      "name": "Rock_Marble"
    },
    {
      "x": -11,
      "y": 20,
      "z": 4,
      "name": "Rock_Marble"
    },
    {
      "x": -11,
      "y": 21,
      "z": 4,
      "name": "Rock_Marble"
    },
    {
      "x": -11,
      "y": 22,
      "z": 4,
      "name": "Rock_Marble"
    },
    {
      "x": -11,
      "y": 23,
      "z": 4,
      "name": "Rock_Marble"
    },
    {
      "x": -11,
      "y": 24,
      "z": 4,
      "name": "Rock_Marble"
    },
    {
      "x": -11,
      "y": 25,
      "z": 4,
      "name": "Rock_Marble"
    },
    {
      "x": -11,
      "y": 26,
      "z": 4,
      "name": "Rock_Marble"
    },
    {
      "x": -11,
      "y": 27,
      "z": 4,
      "name": "Rock_Marble"
    },
    {
      "x": -11,
      "y": 28,
      "z": 4,
      "name": "Rock_Marble"
    },
    {
      "x": -11,
      "y": 29,
      "z": 4,
      "name": "Soil_Grass"
    },
    {
      "x": -11,
      "y": 8,
      "z": 5,
      "name": "Rock_Marble"
    },
    {
      "x": -11,
      "y": 9,
      "z": 5,
      "name": "Rock_Marble"
    },
    {
      "x": -11,
      "y": 10,
      "z": 5,
      "name": "Rock_Marble"
    },
    {
      "x": -11,
      "y": 11,
      "z": 5,
      "name": "Rock_Marble"
    },
    {
      "x": -11,
      "y": 12,
      "z": 5,
      "name": "Rock_Marble"
    },
    {
      "x": -11,
      "y": 13,
      "z": 5,
      "name": "Rock_Marble"
    },
    {
      "x": -11,
      "y": 14,
      "z": 5,
      "name": "Rock_Marble"
    },
    {
      "x": -11,
      "y": 15,
      "z": 5,
      "name": "Rock_Marble"
    },
    {
      "x": -11,
      "y": 16,
      "z": 5,
      "name": "Rock_Marble"
    },
    {
      "x": -11,
      "y": 17,
      "z": 5,
      "name": "Rock_Marble"
    },
    {
      "x": -11,
      "y": 18,
      "z": 5,
      "name": "Rock_Marble"
    },
    {
      "x": -11,
      "y": 19,
      "z": 5,
      "name": "Rock_Marble"
    },
    {
      "x": -11,
      "y": 20,
      "z": 5,
      "name": "Rock_Marble"
    },
    {
      "x": -11,
      "y": 21,
      "z": 5,
      "name": "Rock_Marble"
    },
    {
      "x": -11,
      "y": 22,
      "z": 5,
      "name": "Rock_Marble"
    },
    {
      "x": -11,
      "y": 23,
      "z": 5,
      "name": "Rock_Marble"
    },
    {
      "x": -11,
      "y": 24,
      "z": 5,
      "name": "Rock_Marble"
    },
    {
      "x": -11,
      "y": 25,
      "z": 5,
      "name": "Rock_Marble"
    },
    {
      "x": -11,
      "y": 26,
      "z": 5,
      "name": "Rock_Marble"
    },
    {
      "x": -11,
      "y": 27,
      "z": 5,
      "name": "Rock_Marble"
    },
    {
      "x": -11,
      "y": 28,
      "z": 5,
      "name": "Rock_Marble"
    },
    {
      "x": -11,
      "y": 29,
      "z": 5,
      "name": "Rock_Marble"
    },
    {
      "x": -11,
      "y": 17,
      "z": 6,
      "name": "Rock_Marble"
    },
    {
      "x": -11,
      "y": 18,
      "z": 6,
      "name": "Rock_Marble"
    },
    {
      "x": -11,
      "y": 19,
      "z": 6,
      "name": "Rock_Marble"
    },
    {
      "x": -11,
      "y": 20,
      "z": 6,
      "name": "Rock_Marble"
    },
    {
      "x": -11,
      "y": 21,
      "z": 6,
      "name": "Rock_Marble"
    },
    {
      "x": -11,
      "y": 22,
      "z": 6,
      "name": "Rock_Marble"
    },
    {
      "x": -11,
      "y": 23,
      "z": 6,
      "name": "Rock_Marble"
    },
    {
      "x": -11,
      "y": 24,
      "z": 6,
      "name": "Rock_Marble"
    },
    {
      "x": -11,
      "y": 25,
      "z": 6,
      "name": "Rock_Marble"
    },
    {
      "x": -10,
      "y": 11,
      "z": -7,
      "name": "Rock_Marble"
    },
    {
      "x": -10,
      "y": 12,
      "z": -7,
      "name": "Rock_Marble"
    },
    {
      "x": -10,
      "y": 13,
      "z": -7,
      "name": "Rock_Marble"
    },
    {
      "x": -10,
      "y": 14,
      "z": -7,
      "name": "Rock_Marble"
    },
    {
      "x": -10,
      "y": 15,
      "z": -7,
      "name": "Rock_Marble"
    },
    {
      "x": -10,
      "y": 16,
      "z": -7,
      "name": "Rock_Chalk"
    },
    {
      "x": -10,
      "y": 17,
      "z": -7,
      "name": "Rock_Chalk"
    },
    {
      "x": -10,
      "y": 18,
      "z": -7,
      "name": "Rock_Chalk"
    },
    {
      "x": -10,
      "y": 19,
      "z": -7,
      "name": "Rock_Chalk"
    },
    {
      "x": -10,
      "y": 20,
      "z": -7,
      "name": "Rock_Chalk"
    },
    {
      "x": -10,
      "y": 10,
      "z": -6,
      "name": "Rock_Marble"
    },
    {
      "x": -10,
      "y": 11,
      "z": -6,
      "name": "Rock_Marble"
    },
    {
      "x": -10,
      "y": 12,
      "z": -6,
      "name": "Rock_Marble"
    },
    {
      "x": -10,
      "y": 13,
      "z": -6,
      "name": "Rock_Marble"
    },
    {
      "x": -10,
      "y": 14,
      "z": -6,
      "name": "Rock_Marble"
    },
    {
      "x": -10,
      "y": 15,
      "z": -6,
      "name": "Rock_Marble"
    },
    {
      "x": -10,
      "y": 16,
      "z": -6,
      "name": "Rock_Marble"
    },
    {
      "x": -10,
      "y": 17,
      "z": -6,
      "name": "Rock_Marble"
    },
    {
      "x": -10,
      "y": 18,
      "z": -6,
      "name": "Rock_Marble"
    },
    {
      "x": -10,
      "y": 19,
      "z": -6,
      "name": "Rock_Marble"
    },
    {
      "x": -10,
      "y": 20,
      "z": -6,
      "name": "Rock_Marble"
    },
    {
      "x": -10,
      "y": 21,
      "z": -6,
      "name": "Rock_Marble"
    },
    {
      "x": -10,
      "y": 22,
      "z": -6,
      "name": "Rock_Marble"
    },
    {
      "x": -10,
      "y": 23,
      "z": -6,
      "name": "Rock_Marble"
    },
    {
      "x": -10,
      "y": 24,
      "z": -6,
      "name": "Rock_Marble"
    },
    {
      "x": -10,
      "y": 25,
      "z": -6,
      "name": "Rock_Marble"
    },
    {
      "x": -10,
      "y": 26,
      "z": -6,
      "name": "Rock_Marble"
    },
    {
      "x": -10,
      "y": 9,
      "z": -5,
      "name": "Rock_Marble"
    },
    {
      "x": -10,
      "y": 10,
      "z": -5,
      "name": "Rock_Marble"
    },
    {
      "x": -10,
      "y": 11,
      "z": -5,
      "name": "Rock_Marble"
    },
    {
      "x": -10,
      "y": 12,
      "z": -5,
      "name": "Rock_Marble"
    },
    {
      "x": -10,
      "y": 13,
      "z": -5,
      "name": "Rock_Marble"
    },
    {
      "x": -10,
      "y": 14,
      "z": -5,
      "name": "Rock_Marble"
    },
    {
      "x": -10,
      "y": 15,
      "z": -5,
      "name": "Rock_Marble"
    },
    {
      "x": -10,
      "y": 16,
      "z": -5,
      "name": "Rock_Marble"
    },
    {
      "x": -10,
      "y": 17,
      "z": -5,
      "name": "Rock_Marble"
    },
    {
      "x": -10,
      "y": 18,
      "z": -5,
      "name": "Rock_Marble"
    },
    {
      "x": -10,
      "y": 19,
      "z": -5,
      "name": "Rock_Marble"
    },
    {
      "x": -10,
      "y": 20,
      "z": -5,
      "name": "Rock_Marble"
    },
    {
      "x": -10,
      "y": 21,
      "z": -5,
      "name": "Rock_Marble"
    },
    {
      "x": -10,
      "y": 22,
      "z": -5,
      "name": "Rock_Marble"
    },
    {
      "x": -10,
      "y": 23,
      "z": -5,
      "name": "Rock_Marble"
    },
    {
      "x": -10,
      "y": 24,
      "z": -5,
      "name": "Rock_Marble"
    },
    {
      "x": -10,
      "y": 25,
      "z": -5,
      "name": "Rock_Marble"
    },
    {
      "x": -10,
      "y": 26,
      "z": -5,
      "name": "Rock_Marble"
    },
    {
      "x": -10,
      "y": 27,
      "z": -5,
      "name": "Rock_Marble"
    },
    {
      "x": -10,
      "y": 28,
      "z": -5,
      "name": "Soil_Grass"
    },
    {
      "x": -10,
      "y": 8,
      "z": -4,
      "name": "Rock_Marble"
    },
    {
      "x": -10,
      "y": 9,
      "z": -4,
      "name": "Rock_Marble"
    },
    {
      "x": -10,
      "y": 10,
      "z": -4,
      "name": "Rock_Marble"
    },
    {
      "x": -10,
      "y": 11,
      "z": -4,
      "name": "Rock_Marble"
    },
    {
      "x": -10,
      "y": 12,
      "z": -4,
      "name": "Rock_Marble"
    },
    {
      "x": -10,
      "y": 13,
      "z": -4,
      "name": "Rock_Marble"
    },
    {
      "x": -10,
      "y": 14,
      "z": -4,
      "name": "Rock_Marble"
    },
    {
      "x": -10,
      "y": 15,
      "z": -4,
      "name": "Rock_Marble"
    },
    {
      "x": -10,
      "y": 16,
      "z": -4,
      "name": "Rock_Marble"
    },
    {
      "x": -10,
      "y": 17,
      "z": -4,
      "name": "Rock_Marble"
    },
    {
      "x": -10,
      "y": 18,
      "z": -4,
      "name": "Rock_Marble"
    },
    {
      "x": -10,
      "y": 19,
      "z": -4,
      "name": "Rock_Marble"
    },
    {
      "x": -10,
      "y": 20,
      "z": -4,
      "name": "Rock_Marble"
    },
    {
      "x": -10,
      "y": 21,
      "z": -4,
      "name": "Rock_Marble"
    },
    {
      "x": -10,
      "y": 22,
      "z": -4,
      "name": "Rock_Marble"
    },
    {
      "x": -10,
      "y": 23,
      "z": -4,
      "name": "Rock_Marble"
    },
    {
      "x": -10,
      "y": 24,
      "z": -4,
      "name": "Rock_Marble"
    },
    {
      "x": -10,
      "y": 25,
      "z": -4,
      "name": "Rock_Marble"
    },
    {
      "x": -10,
      "y": 26,
      "z": -4,
      "name": "Rock_Marble"
    },
    {
      "x": -10,
      "y": 27,
      "z": -4,
      "name": "Rock_Marble"
    },
    {
      "x": -10,
      "y": 28,
      "z": -4,
      "name": "Soil_Grass"
    },
    {
      "x": -10,
      "y": 8,
      "z": -3,
      "name": "Rock_Marble"
    },
    {
      "x": -10,
      "y": 9,
      "z": -3,
      "name": "Rock_Marble"
    },
    {
      "x": -10,
      "y": 10,
      "z": -3,
      "name": "Rock_Marble"
    },
    {
      "x": -10,
      "y": 11,
      "z": -3,
      "name": "Rock_Marble"
    },
    {
      "x": -10,
      "y": 12,
      "z": -3,
      "name": "Rock_Marble"
    },
    {
      "x": -10,
      "y": 13,
      "z": -3,
      "name": "Rock_Marble"
    },
    {
      "x": -10,
      "y": 14,
      "z": -3,
      "name": "Rock_Marble"
    },
    {
      "x": -10,
      "y": 15,
      "z": -3,
      "name": "Rock_Marble"
    },
    {
      "x": -10,
      "y": 16,
      "z": -3,
      "name": "Rock_Marble"
    },
    {
      "x": -10,
      "y": 17,
      "z": -3,
      "name": "Rock_Marble"
    },
    {
      "x": -10,
      "y": 18,
      "z": -3,
      "name": "Rock_Marble"
    },
    {
      "x": -10,
      "y": 19,
      "z": -3,
      "name": "Rock_Marble"
    },
    {
      "x": -10,
      "y": 20,
      "z": -3,
      "name": "Rock_Marble"
    },
    {
      "x": -10,
      "y": 21,
      "z": -3,
      "name": "Rock_Marble"
    },
    {
      "x": -10,
      "y": 22,
      "z": -3,
      "name": "Rock_Marble"
    },
    {
      "x": -10,
      "y": 23,
      "z": -3,
      "name": "Rock_Marble"
    },
    {
      "x": -10,
      "y": 24,
      "z": -3,
      "name": "Rock_Marble"
    },
    {
      "x": -10,
      "y": 25,
      "z": -3,
      "name": "Rock_Marble"
    },
    {
      "x": -10,
      "y": 26,
      "z": -3,
      "name": "Rock_Marble"
    },
    {
      "x": -10,
      "y": 27,
      "z": -3,
      "name": "Rock_Marble"
    },
    {
      "x": -10,
      "y": 28,
      "z": -3,
      "name": "Soil_Grass"
    },
    {
      "x": -10,
      "y": 8,
      "z": -2,
      "name": "Rock_Marble"
    },
    {
      "x": -10,
      "y": 9,
      "z": -2,
      "name": "Rock_Marble"
    },
    {
      "x": -10,
      "y": 10,
      "z": -2,
      "name": "Rock_Marble"
    },
    {
      "x": -10,
      "y": 11,
      "z": -2,
      "name": "Rock_Marble"
    },
    {
      "x": -10,
      "y": 12,
      "z": -2,
      "name": "Rock_Marble"
    },
    {
      "x": -10,
      "y": 13,
      "z": -2,
      "name": "Rock_Marble"
    },
    {
      "x": -10,
      "y": 14,
      "z": -2,
      "name": "Rock_Marble"
    },
    {
      "x": -10,
      "y": 15,
      "z": -2,
      "name": "Rock_Marble"
    },
    {
      "x": -10,
      "y": 16,
      "z": -2,
      "name": "Rock_Marble"
    },
    {
      "x": -10,
      "y": 17,
      "z": -2,
      "name": "Rock_Marble"
    },
    {
      "x": -10,
      "y": 18,
      "z": -2,
      "name": "Rock_Marble"
    },
    {
      "x": -10,
      "y": 19,
      "z": -2,
      "name": "Rock_Marble"
    },
    {
      "x": -10,
      "y": 20,
      "z": -2,
      "name": "Rock_Marble"
    },
    {
      "x": -10,
      "y": 21,
      "z": -2,
      "name": "Rock_Marble"
    },
    {
      "x": -10,
      "y": 22,
      "z": -2,
      "name": "Rock_Marble"
    },
    {
      "x": -10,
      "y": 23,
      "z": -2,
      "name": "Rock_Marble"
    },
    {
      "x": -10,
      "y": 24,
      "z": -2,
      "name": "Rock_Marble"
    },
    {
      "x": -10,
      "y": 25,
      "z": -2,
      "name": "Rock_Marble"
    },
    {
      "x": -10,
      "y": 26,
      "z": -2,
      "name": "Rock_Marble"
    },
    {
      "x": -10,
      "y": 27,
      "z": -2,
      "name": "Soil_Dirt"
    },
    {
      "x": -10,
      "y": 28,
      "z": -2,
      "name": "Soil_Grass"
    },
    {
      "x": -10,
      "y": 7,
      "z": -1,
      "name": "Rock_Marble"
    },
    {
      "x": -10,
      "y": 8,
      "z": -1,
      "name": "Rock_Marble"
    },
    {
      "x": -10,
      "y": 9,
      "z": -1,
      "name": "Rock_Marble"
    },
    {
      "x": -10,
      "y": 10,
      "z": -1,
      "name": "Rock_Marble"
    },
    {
      "x": -10,
      "y": 11,
      "z": -1,
      "name": "Rock_Marble"
    },
    {
      "x": -10,
      "y": 12,
      "z": -1,
      "name": "Rock_Marble"
    },
    {
      "x": -10,
      "y": 13,
      "z": -1,
      "name": "Rock_Marble"
    },
    {
      "x": -10,
      "y": 14,
      "z": -1,
      "name": "Rock_Marble"
    },
    {
      "x": -10,
      "y": 15,
      "z": -1,
      "name": "Rock_Marble"
    },
    {
      "x": -10,
      "y": 16,
      "z": -1,
      "name": "Rock_Marble"
    },
    {
      "x": -10,
      "y": 17,
      "z": -1,
      "name": "Rock_Marble"
    },
    {
      "x": -10,
      "y": 18,
      "z": -1,
      "name": "Rock_Marble"
    },
    {
      "x": -10,
      "y": 19,
      "z": -1,
      "name": "Rock_Marble"
    },
    {
      "x": -10,
      "y": 20,
      "z": -1,
      "name": "Rock_Marble"
    },
    {
      "x": -10,
      "y": 21,
      "z": -1,
      "name": "Rock_Marble"
    },
    {
      "x": -10,
      "y": 22,
      "z": -1,
      "name": "Rock_Marble"
    },
    {
      "x": -10,
      "y": 23,
      "z": -1,
      "name": "Rock_Marble"
    },
    {
      "x": -10,
      "y": 24,
      "z": -1,
      "name": "Rock_Marble"
    },
    {
      "x": -10,
      "y": 25,
      "z": -1,
      "name": "Rock_Marble"
    },
    {
      "x": -10,
      "y": 26,
      "z": -1,
      "name": "Rock_Marble"
    },
    {
      "x": -10,
      "y": 27,
      "z": -1,
      "name": "Soil_Dirt"
    },
    {
      "x": -10,
      "y": 28,
      "z": -1,
      "name": "Soil_Grass"
    },
    {
      "x": -10,
      "y": 7,
      "z": 0,
      "name": "Rock_Marble"
    },
    {
      "x": -10,
      "y": 8,
      "z": 0,
      "name": "Rock_Marble"
    },
    {
      "x": -10,
      "y": 9,
      "z": 0,
      "name": "Rock_Marble"
    },
    {
      "x": -10,
      "y": 10,
      "z": 0,
      "name": "Rock_Marble"
    },
    {
      "x": -10,
      "y": 11,
      "z": 0,
      "name": "Rock_Marble"
    },
    {
      "x": -10,
      "y": 12,
      "z": 0,
      "name": "Rock_Marble"
    },
    {
      "x": -10,
      "y": 13,
      "z": 0,
      "name": "Rock_Marble"
    },
    {
      "x": -10,
      "y": 14,
      "z": 0,
      "name": "Rock_Marble"
    },
    {
      "x": -10,
      "y": 15,
      "z": 0,
      "name": "Rock_Marble"
    },
    {
      "x": -10,
      "y": 16,
      "z": 0,
      "name": "Rock_Marble"
    },
    {
      "x": -10,
      "y": 17,
      "z": 0,
      "name": "Rock_Marble"
    },
    {
      "x": -10,
      "y": 18,
      "z": 0,
      "name": "Rock_Marble"
    },
    {
      "x": -10,
      "y": 19,
      "z": 0,
      "name": "Rock_Marble"
    },
    {
      "x": -10,
      "y": 20,
      "z": 0,
      "name": "Rock_Marble"
    },
    {
      "x": -10,
      "y": 21,
      "z": 0,
      "name": "Rock_Marble"
    },
    {
      "x": -10,
      "y": 22,
      "z": 0,
      "name": "Rock_Marble"
    },
    {
      "x": -10,
      "y": 23,
      "z": 0,
      "name": "Rock_Marble"
    },
    {
      "x": -10,
      "y": 24,
      "z": 0,
      "name": "Rock_Marble"
    },
    {
      "x": -10,
      "y": 25,
      "z": 0,
      "name": "Rock_Marble"
    },
    {
      "x": -10,
      "y": 26,
      "z": 0,
      "name": "Rock_Marble"
    },
    {
      "x": -10,
      "y": 27,
      "z": 0,
      "name": "Soil_Dirt"
    },
    {
      "x": -10,
      "y": 28,
      "z": 0,
      "name": "Soil_Grass"
    },
    {
      "x": -10,
      "y": 7,
      "z": 1,
      "name": "Rock_Marble"
    },
    {
      "x": -10,
      "y": 8,
      "z": 1,
      "name": "Rock_Marble"
    },
    {
      "x": -10,
      "y": 9,
      "z": 1,
      "name": "Rock_Marble"
    },
    {
      "x": -10,
      "y": 10,
      "z": 1,
      "name": "Rock_Marble"
    },
    {
      "x": -10,
      "y": 11,
      "z": 1,
      "name": "Rock_Marble"
    },
    {
      "x": -10,
      "y": 12,
      "z": 1,
      "name": "Rock_Marble"
    },
    {
      "x": -10,
      "y": 13,
      "z": 1,
      "name": "Rock_Marble"
    },
    {
      "x": -10,
      "y": 14,
      "z": 1,
      "name": "Rock_Marble"
    },
    {
      "x": -10,
      "y": 15,
      "z": 1,
      "name": "Rock_Marble"
    },
    {
      "x": -10,
      "y": 16,
      "z": 1,
      "name": "Rock_Marble"
    },
    {
      "x": -10,
      "y": 17,
      "z": 1,
      "name": "Rock_Marble"
    },
    {
      "x": -10,
      "y": 18,
      "z": 1,
      "name": "Rock_Marble"
    },
    {
      "x": -10,
      "y": 19,
      "z": 1,
      "name": "Rock_Marble"
    },
    {
      "x": -10,
      "y": 20,
      "z": 1,
      "name": "Rock_Marble"
    },
    {
      "x": -10,
      "y": 21,
      "z": 1,
      "name": "Rock_Marble"
    },
    {
      "x": -10,
      "y": 22,
      "z": 1,
      "name": "Rock_Marble"
    },
    {
      "x": -10,
      "y": 23,
      "z": 1,
      "name": "Rock_Marble"
    },
    {
      "x": -10,
      "y": 24,
      "z": 1,
      "name": "Rock_Marble"
    },
    {
      "x": -10,
      "y": 25,
      "z": 1,
      "name": "Rock_Marble"
    },
    {
      "x": -10,
      "y": 26,
      "z": 1,
      "name": "Rock_Marble"
    },
    {
      "x": -10,
      "y": 27,
      "z": 1,
      "name": "Soil_Dirt"
    },
    {
      "x": -10,
      "y": 28,
      "z": 1,
      "name": "Soil_Grass"
    },
    {
      "x": -10,
      "y": 6,
      "z": 2,
      "name": "Rock_Marble"
    },
    {
      "x": -10,
      "y": 7,
      "z": 2,
      "name": "Rock_Marble"
    },
    {
      "x": -10,
      "y": 8,
      "z": 2,
      "name": "Rock_Marble"
    },
    {
      "x": -10,
      "y": 9,
      "z": 2,
      "name": "Rock_Marble"
    },
    {
      "x": -10,
      "y": 10,
      "z": 2,
      "name": "Rock_Marble"
    },
    {
      "x": -10,
      "y": 11,
      "z": 2,
      "name": "Rock_Marble"
    },
    {
      "x": -10,
      "y": 12,
      "z": 2,
      "name": "Rock_Marble"
    },
    {
      "x": -10,
      "y": 13,
      "z": 2,
      "name": "Rock_Marble"
    },
    {
      "x": -10,
      "y": 14,
      "z": 2,
      "name": "Rock_Marble"
    },
    {
      "x": -10,
      "y": 15,
      "z": 2,
      "name": "Rock_Marble"
    },
    {
      "x": -10,
      "y": 16,
      "z": 2,
      "name": "Rock_Marble"
    },
    {
      "x": -10,
      "y": 17,
      "z": 2,
      "name": "Rock_Marble"
    },
    {
      "x": -10,
      "y": 18,
      "z": 2,
      "name": "Rock_Marble"
    },
    {
      "x": -10,
      "y": 19,
      "z": 2,
      "name": "Rock_Marble"
    },
    {
      "x": -10,
      "y": 20,
      "z": 2,
      "name": "Rock_Marble"
    },
    {
      "x": -10,
      "y": 21,
      "z": 2,
      "name": "Rock_Marble"
    },
    {
      "x": -10,
      "y": 22,
      "z": 2,
      "name": "Rock_Marble"
    },
    {
      "x": -10,
      "y": 23,
      "z": 2,
      "name": "Rock_Marble"
    },
    {
      "x": -10,
      "y": 24,
      "z": 2,
      "name": "Rock_Marble"
    },
    {
      "x": -10,
      "y": 25,
      "z": 2,
      "name": "Rock_Marble"
    },
    {
      "x": -10,
      "y": 26,
      "z": 2,
      "name": "Rock_Marble"
    },
    {
      "x": -10,
      "y": 27,
      "z": 2,
      "name": "Soil_Dirt"
    },
    {
      "x": -10,
      "y": 28,
      "z": 2,
      "name": "Soil_Dirt"
    },
    {
      "x": -10,
      "y": 29,
      "z": 2,
      "name": "Soil_Grass"
    },
    {
      "x": -10,
      "y": 6,
      "z": 3,
      "name": "Rock_Marble"
    },
    {
      "x": -10,
      "y": 7,
      "z": 3,
      "name": "Rock_Marble"
    },
    {
      "x": -10,
      "y": 8,
      "z": 3,
      "name": "Rock_Marble"
    },
    {
      "x": -10,
      "y": 9,
      "z": 3,
      "name": "Rock_Marble"
    },
    {
      "x": -10,
      "y": 10,
      "z": 3,
      "name": "Rock_Marble"
    },
    {
      "x": -10,
      "y": 11,
      "z": 3,
      "name": "Rock_Marble"
    },
    {
      "x": -10,
      "y": 12,
      "z": 3,
      "name": "Rock_Marble"
    },
    {
      "x": -10,
      "y": 13,
      "z": 3,
      "name": "Rock_Marble"
    },
    {
      "x": -10,
      "y": 14,
      "z": 3,
      "name": "Rock_Marble"
    },
    {
      "x": -10,
      "y": 15,
      "z": 3,
      "name": "Rock_Marble"
    },
    {
      "x": -10,
      "y": 16,
      "z": 3,
      "name": "Rock_Marble"
    },
    {
      "x": -10,
      "y": 17,
      "z": 3,
      "name": "Rock_Marble"
    },
    {
      "x": -10,
      "y": 18,
      "z": 3,
      "name": "Rock_Marble"
    },
    {
      "x": -10,
      "y": 19,
      "z": 3,
      "name": "Rock_Marble"
    },
    {
      "x": -10,
      "y": 20,
      "z": 3,
      "name": "Rock_Marble"
    },
    {
      "x": -10,
      "y": 21,
      "z": 3,
      "name": "Rock_Marble"
    },
    {
      "x": -10,
      "y": 22,
      "z": 3,
      "name": "Rock_Marble"
    },
    {
      "x": -10,
      "y": 23,
      "z": 3,
      "name": "Rock_Marble"
    },
    {
      "x": -10,
      "y": 24,
      "z": 3,
      "name": "Rock_Marble"
    },
    {
      "x": -10,
      "y": 25,
      "z": 3,
      "name": "Rock_Marble"
    },
    {
      "x": -10,
      "y": 26,
      "z": 3,
      "name": "Rock_Marble"
    },
    {
      "x": -10,
      "y": 27,
      "z": 3,
      "name": "Rock_Marble"
    },
    {
      "x": -10,
      "y": 28,
      "z": 3,
      "name": "Soil_Dirt"
    },
    {
      "x": -10,
      "y": 29,
      "z": 3,
      "name": "Soil_Grass"
    },
    {
      "x": -10,
      "y": 6,
      "z": 4,
      "name": "Rock_Marble"
    },
    {
      "x": -10,
      "y": 7,
      "z": 4,
      "name": "Rock_Marble"
    },
    {
      "x": -10,
      "y": 8,
      "z": 4,
      "name": "Rock_Marble"
    },
    {
      "x": -10,
      "y": 9,
      "z": 4,
      "name": "Rock_Marble"
    },
    {
      "x": -10,
      "y": 10,
      "z": 4,
      "name": "Rock_Marble"
    },
    {
      "x": -10,
      "y": 11,
      "z": 4,
      "name": "Rock_Marble"
    },
    {
      "x": -10,
      "y": 12,
      "z": 4,
      "name": "Rock_Marble"
    },
    {
      "x": -10,
      "y": 13,
      "z": 4,
      "name": "Rock_Marble"
    },
    {
      "x": -10,
      "y": 14,
      "z": 4,
      "name": "Rock_Marble"
    },
    {
      "x": -10,
      "y": 15,
      "z": 4,
      "name": "Rock_Marble"
    },
    {
      "x": -10,
      "y": 16,
      "z": 4,
      "name": "Rock_Marble"
    },
    {
      "x": -10,
      "y": 17,
      "z": 4,
      "name": "Rock_Marble"
    },
    {
      "x": -10,
      "y": 18,
      "z": 4,
      "name": "Rock_Marble"
    },
    {
      "x": -10,
      "y": 19,
      "z": 4,
      "name": "Rock_Marble"
    },
    {
      "x": -10,
      "y": 20,
      "z": 4,
      "name": "Rock_Marble"
    },
    {
      "x": -10,
      "y": 21,
      "z": 4,
      "name": "Rock_Marble"
    },
    {
      "x": -10,
      "y": 22,
      "z": 4,
      "name": "Rock_Marble"
    },
    {
      "x": -10,
      "y": 23,
      "z": 4,
      "name": "Rock_Marble"
    },
    {
      "x": -10,
      "y": 24,
      "z": 4,
      "name": "Rock_Marble"
    },
    {
      "x": -10,
      "y": 25,
      "z": 4,
      "name": "Rock_Marble"
    },
    {
      "x": -10,
      "y": 26,
      "z": 4,
      "name": "Rock_Marble"
    },
    {
      "x": -10,
      "y": 27,
      "z": 4,
      "name": "Rock_Marble"
    },
    {
      "x": -10,
      "y": 28,
      "z": 4,
      "name": "Rock_Marble"
    },
    {
      "x": -10,
      "y": 29,
      "z": 4,
      "name": "Soil_Grass"
    },
    {
      "x": -10,
      "y": 7,
      "z": 5,
      "name": "Rock_Marble"
    },
    {
      "x": -10,
      "y": 8,
      "z": 5,
      "name": "Rock_Marble"
    },
    {
      "x": -10,
      "y": 9,
      "z": 5,
      "name": "Rock_Marble"
    },
    {
      "x": -10,
      "y": 10,
      "z": 5,
      "name": "Rock_Marble"
    },
    {
      "x": -10,
      "y": 11,
      "z": 5,
      "name": "Rock_Marble"
    },
    {
      "x": -10,
      "y": 12,
      "z": 5,
      "name": "Rock_Marble"
    },
    {
      "x": -10,
      "y": 13,
      "z": 5,
      "name": "Rock_Marble"
    },
    {
      "x": -10,
      "y": 14,
      "z": 5,
      "name": "Rock_Marble"
    },
    {
      "x": -10,
      "y": 15,
      "z": 5,
      "name": "Rock_Marble"
    },
    {
      "x": -10,
      "y": 16,
      "z": 5,
      "name": "Rock_Marble"
    },
    {
      "x": -10,
      "y": 17,
      "z": 5,
      "name": "Rock_Marble"
    },
    {
      "x": -10,
      "y": 18,
      "z": 5,
      "name": "Rock_Marble"
    },
    {
      "x": -10,
      "y": 19,
      "z": 5,
      "name": "Rock_Marble"
    },
    {
      "x": -10,
      "y": 20,
      "z": 5,
      "name": "Rock_Marble"
    },
    {
      "x": -10,
      "y": 21,
      "z": 5,
      "name": "Rock_Marble"
    },
    {
      "x": -10,
      "y": 22,
      "z": 5,
      "name": "Rock_Marble"
    },
    {
      "x": -10,
      "y": 23,
      "z": 5,
      "name": "Rock_Marble"
    },
    {
      "x": -10,
      "y": 24,
      "z": 5,
      "name": "Rock_Marble"
    },
    {
      "x": -10,
      "y": 25,
      "z": 5,
      "name": "Rock_Marble"
    },
    {
      "x": -10,
      "y": 26,
      "z": 5,
      "name": "Rock_Marble"
    },
    {
      "x": -10,
      "y": 27,
      "z": 5,
      "name": "Rock_Marble"
    },
    {
      "x": -10,
      "y": 28,
      "z": 5,
      "name": "Rock_Marble"
    },
    {
      "x": -10,
      "y": 29,
      "z": 5,
      "name": "Soil_Grass"
    },
    {
      "x": -10,
      "y": 7,
      "z": 6,
      "name": "Rock_Marble"
    },
    {
      "x": -10,
      "y": 8,
      "z": 6,
      "name": "Rock_Marble"
    },
    {
      "x": -10,
      "y": 9,
      "z": 6,
      "name": "Rock_Marble"
    },
    {
      "x": -10,
      "y": 10,
      "z": 6,
      "name": "Rock_Marble"
    },
    {
      "x": -10,
      "y": 11,
      "z": 6,
      "name": "Rock_Marble"
    },
    {
      "x": -10,
      "y": 12,
      "z": 6,
      "name": "Rock_Marble"
    },
    {
      "x": -10,
      "y": 13,
      "z": 6,
      "name": "Rock_Marble"
    },
    {
      "x": -10,
      "y": 14,
      "z": 6,
      "name": "Rock_Marble"
    },
    {
      "x": -10,
      "y": 15,
      "z": 6,
      "name": "Rock_Marble"
    },
    {
      "x": -10,
      "y": 16,
      "z": 6,
      "name": "Rock_Marble"
    },
    {
      "x": -10,
      "y": 17,
      "z": 6,
      "name": "Rock_Marble"
    },
    {
      "x": -10,
      "y": 18,
      "z": 6,
      "name": "Rock_Marble"
    },
    {
      "x": -10,
      "y": 19,
      "z": 6,
      "name": "Rock_Marble"
    },
    {
      "x": -10,
      "y": 20,
      "z": 6,
      "name": "Rock_Marble"
    },
    {
      "x": -10,
      "y": 21,
      "z": 6,
      "name": "Rock_Marble"
    },
    {
      "x": -10,
      "y": 22,
      "z": 6,
      "name": "Rock_Marble"
    },
    {
      "x": -10,
      "y": 23,
      "z": 6,
      "name": "Rock_Marble"
    },
    {
      "x": -10,
      "y": 24,
      "z": 6,
      "name": "Rock_Marble"
    },
    {
      "x": -10,
      "y": 25,
      "z": 6,
      "name": "Rock_Marble"
    },
    {
      "x": -10,
      "y": 26,
      "z": 6,
      "name": "Rock_Marble"
    },
    {
      "x": -10,
      "y": 27,
      "z": 6,
      "name": "Rock_Marble"
    },
    {
      "x": -10,
      "y": 28,
      "z": 6,
      "name": "Rock_Marble"
    },
    {
      "x": -10,
      "y": 29,
      "z": 6,
      "name": "Rock_Marble"
    },
    {
      "x": -10,
      "y": 30,
      "z": 6,
      "name": "Soil_Grass"
    },
    {
      "x": -10,
      "y": 10,
      "z": 7,
      "name": "Rock_Marble"
    },
    {
      "x": -10,
      "y": 11,
      "z": 7,
      "name": "Rock_Marble"
    },
    {
      "x": -10,
      "y": 12,
      "z": 7,
      "name": "Rock_Marble"
    },
    {
      "x": -10,
      "y": 13,
      "z": 7,
      "name": "Rock_Marble"
    },
    {
      "x": -10,
      "y": 14,
      "z": 7,
      "name": "Rock_Marble"
    },
    {
      "x": -10,
      "y": 16,
      "z": 7,
      "name": "Rock_Marble"
    },
    {
      "x": -10,
      "y": 17,
      "z": 7,
      "name": "Rock_Marble"
    },
    {
      "x": -10,
      "y": 18,
      "z": 7,
      "name": "Rock_Marble"
    },
    {
      "x": -10,
      "y": 19,
      "z": 7,
      "name": "Rock_Marble"
    },
    {
      "x": -10,
      "y": 20,
      "z": 7,
      "name": "Rock_Marble"
    },
    {
      "x": -10,
      "y": 21,
      "z": 7,
      "name": "Rock_Marble"
    },
    {
      "x": -10,
      "y": 27,
      "z": 7,
      "name": "Rock_Marble"
    },
    {
      "x": -10,
      "y": 28,
      "z": 7,
      "name": "Rock_Marble"
    },
    {
      "x": -10,
      "y": 29,
      "z": 7,
      "name": "Rock_Marble"
    },
    {
      "x": -10,
      "y": 30,
      "z": 7,
      "name": "Soil_Grass"
    },
    {
      "x": -9,
      "y": 10,
      "z": -7,
      "name": "Rock_Marble"
    },
    {
      "x": -9,
      "y": 11,
      "z": -7,
      "name": "Rock_Marble"
    },
    {
      "x": -9,
      "y": 12,
      "z": -7,
      "name": "Rock_Marble"
    },
    {
      "x": -9,
      "y": 13,
      "z": -7,
      "name": "Rock_Marble"
    },
    {
      "x": -9,
      "y": 14,
      "z": -7,
      "name": "Rock_Marble"
    },
    {
      "x": -9,
      "y": 15,
      "z": -7,
      "name": "Rock_Marble"
    },
    {
      "x": -9,
      "y": 16,
      "z": -7,
      "name": "Rock_Marble"
    },
    {
      "x": -9,
      "y": 17,
      "z": -7,
      "name": "Rock_Marble"
    },
    {
      "x": -9,
      "y": 18,
      "z": -7,
      "name": "Rock_Marble"
    },
    {
      "x": -9,
      "y": 19,
      "z": -7,
      "name": "Rock_Marble"
    },
    {
      "x": -9,
      "y": 20,
      "z": -7,
      "name": "Rock_Chalk"
    },
    {
      "x": -9,
      "y": 21,
      "z": -7,
      "name": "Rock_Chalk"
    },
    {
      "x": -9,
      "y": 22,
      "z": -7,
      "name": "Rock_Chalk"
    },
    {
      "x": -9,
      "y": 23,
      "z": -7,
      "name": "Rock_Chalk"
    },
    {
      "x": -9,
      "y": 24,
      "z": -7,
      "name": "Rock_Chalk"
    },
    {
      "x": -9,
      "y": 25,
      "z": -7,
      "name": "Rock_Chalk"
    },
    {
      "x": -9,
      "y": 9,
      "z": -6,
      "name": "Rock_Marble"
    },
    {
      "x": -9,
      "y": 10,
      "z": -6,
      "name": "Rock_Marble"
    },
    {
      "x": -9,
      "y": 11,
      "z": -6,
      "name": "Rock_Marble"
    },
    {
      "x": -9,
      "y": 12,
      "z": -6,
      "name": "Rock_Marble"
    },
    {
      "x": -9,
      "y": 13,
      "z": -6,
      "name": "Rock_Marble"
    },
    {
      "x": -9,
      "y": 14,
      "z": -6,
      "name": "Rock_Marble"
    },
    {
      "x": -9,
      "y": 15,
      "z": -6,
      "name": "Rock_Marble"
    },
    {
      "x": -9,
      "y": 16,
      "z": -6,
      "name": "Rock_Marble"
    },
    {
      "x": -9,
      "y": 17,
      "z": -6,
      "name": "Rock_Marble"
    },
    {
      "x": -9,
      "y": 18,
      "z": -6,
      "name": "Rock_Marble"
    },
    {
      "x": -9,
      "y": 19,
      "z": -6,
      "name": "Rock_Marble"
    },
    {
      "x": -9,
      "y": 20,
      "z": -6,
      "name": "Rock_Marble"
    },
    {
      "x": -9,
      "y": 21,
      "z": -6,
      "name": "Rock_Marble"
    },
    {
      "x": -9,
      "y": 22,
      "z": -6,
      "name": "Rock_Marble"
    },
    {
      "x": -9,
      "y": 23,
      "z": -6,
      "name": "Rock_Marble"
    },
    {
      "x": -9,
      "y": 24,
      "z": -6,
      "name": "Rock_Marble"
    },
    {
      "x": -9,
      "y": 25,
      "z": -6,
      "name": "Rock_Marble"
    },
    {
      "x": -9,
      "y": 26,
      "z": -6,
      "name": "Rock_Marble"
    },
    {
      "x": -9,
      "y": 27,
      "z": -6,
      "name": "Rock_Marble"
    },
    {
      "x": -9,
      "y": 28,
      "z": -6,
      "name": "Soil_Grass"
    },
    {
      "x": -9,
      "y": 8,
      "z": -5,
      "name": "Rock_Marble"
    },
    {
      "x": -9,
      "y": 9,
      "z": -5,
      "name": "Rock_Marble"
    },
    {
      "x": -9,
      "y": 10,
      "z": -5,
      "name": "Rock_Marble"
    },
    {
      "x": -9,
      "y": 11,
      "z": -5,
      "name": "Rock_Marble"
    },
    {
      "x": -9,
      "y": 12,
      "z": -5,
      "name": "Rock_Marble"
    },
    {
      "x": -9,
      "y": 13,
      "z": -5,
      "name": "Rock_Marble"
    },
    {
      "x": -9,
      "y": 14,
      "z": -5,
      "name": "Rock_Marble"
    },
    {
      "x": -9,
      "y": 15,
      "z": -5,
      "name": "Rock_Marble"
    },
    {
      "x": -9,
      "y": 16,
      "z": -5,
      "name": "Rock_Marble"
    },
    {
      "x": -9,
      "y": 17,
      "z": -5,
      "name": "Rock_Marble"
    },
    {
      "x": -9,
      "y": 18,
      "z": -5,
      "name": "Rock_Marble"
    },
    {
      "x": -9,
      "y": 19,
      "z": -5,
      "name": "Rock_Marble"
    },
    {
      "x": -9,
      "y": 20,
      "z": -5,
      "name": "Rock_Marble"
    },
    {
      "x": -9,
      "y": 21,
      "z": -5,
      "name": "Rock_Marble"
    },
    {
      "x": -9,
      "y": 22,
      "z": -5,
      "name": "Rock_Marble"
    },
    {
      "x": -9,
      "y": 23,
      "z": -5,
      "name": "Rock_Marble"
    },
    {
      "x": -9,
      "y": 24,
      "z": -5,
      "name": "Rock_Marble"
    },
    {
      "x": -9,
      "y": 25,
      "z": -5,
      "name": "Rock_Marble"
    },
    {
      "x": -9,
      "y": 26,
      "z": -5,
      "name": "Rock_Marble"
    },
    {
      "x": -9,
      "y": 27,
      "z": -5,
      "name": "Soil_Dirt"
    },
    {
      "x": -9,
      "y": 28,
      "z": -5,
      "name": "Soil_Grass"
    },
    {
      "x": -9,
      "y": 8,
      "z": -4,
      "name": "Rock_Marble"
    },
    {
      "x": -9,
      "y": 9,
      "z": -4,
      "name": "Rock_Marble"
    },
    {
      "x": -9,
      "y": 10,
      "z": -4,
      "name": "Rock_Marble"
    },
    {
      "x": -9,
      "y": 11,
      "z": -4,
      "name": "Rock_Marble"
    },
    {
      "x": -9,
      "y": 12,
      "z": -4,
      "name": "Rock_Marble"
    },
    {
      "x": -9,
      "y": 13,
      "z": -4,
      "name": "Rock_Marble"
    },
    {
      "x": -9,
      "y": 14,
      "z": -4,
      "name": "Rock_Marble"
    },
    {
      "x": -9,
      "y": 15,
      "z": -4,
      "name": "Rock_Marble"
    },
    {
      "x": -9,
      "y": 16,
      "z": -4,
      "name": "Rock_Marble"
    },
    {
      "x": -9,
      "y": 17,
      "z": -4,
      "name": "Rock_Marble"
    },
    {
      "x": -9,
      "y": 18,
      "z": -4,
      "name": "Rock_Marble"
    },
    {
      "x": -9,
      "y": 19,
      "z": -4,
      "name": "Rock_Marble"
    },
    {
      "x": -9,
      "y": 20,
      "z": -4,
      "name": "Rock_Marble"
    },
    {
      "x": -9,
      "y": 21,
      "z": -4,
      "name": "Rock_Marble"
    },
    {
      "x": -9,
      "y": 22,
      "z": -4,
      "name": "Rock_Marble"
    },
    {
      "x": -9,
      "y": 23,
      "z": -4,
      "name": "Rock_Marble"
    },
    {
      "x": -9,
      "y": 24,
      "z": -4,
      "name": "Rock_Marble"
    },
    {
      "x": -9,
      "y": 25,
      "z": -4,
      "name": "Rock_Marble"
    },
    {
      "x": -9,
      "y": 26,
      "z": -4,
      "name": "Rock_Marble"
    },
    {
      "x": -9,
      "y": 27,
      "z": -4,
      "name": "Soil_Dirt"
    },
    {
      "x": -9,
      "y": 28,
      "z": -4,
      "name": "Soil_Grass"
    },
    {
      "x": -9,
      "y": 7,
      "z": -3,
      "name": "Rock_Marble"
    },
    {
      "x": -9,
      "y": 8,
      "z": -3,
      "name": "Rock_Marble"
    },
    {
      "x": -9,
      "y": 9,
      "z": -3,
      "name": "Rock_Marble"
    },
    {
      "x": -9,
      "y": 10,
      "z": -3,
      "name": "Rock_Marble"
    },
    {
      "x": -9,
      "y": 11,
      "z": -3,
      "name": "Rock_Marble"
    },
    {
      "x": -9,
      "y": 12,
      "z": -3,
      "name": "Rock_Marble"
    },
    {
      "x": -9,
      "y": 13,
      "z": -3,
      "name": "Rock_Marble"
    },
    {
      "x": -9,
      "y": 14,
      "z": -3,
      "name": "Rock_Marble"
    },
    {
      "x": -9,
      "y": 15,
      "z": -3,
      "name": "Rock_Marble"
    },
    {
      "x": -9,
      "y": 16,
      "z": -3,
      "name": "Rock_Marble"
    },
    {
      "x": -9,
      "y": 17,
      "z": -3,
      "name": "Rock_Marble"
    },
    {
      "x": -9,
      "y": 18,
      "z": -3,
      "name": "Rock_Marble"
    },
    {
      "x": -9,
      "y": 19,
      "z": -3,
      "name": "Rock_Marble"
    },
    {
      "x": -9,
      "y": 20,
      "z": -3,
      "name": "Rock_Marble"
    },
    {
      "x": -9,
      "y": 21,
      "z": -3,
      "name": "Rock_Marble"
    },
    {
      "x": -9,
      "y": 22,
      "z": -3,
      "name": "Rock_Marble"
    },
    {
      "x": -9,
      "y": 23,
      "z": -3,
      "name": "Rock_Marble"
    },
    {
      "x": -9,
      "y": 24,
      "z": -3,
      "name": "Rock_Marble"
    },
    {
      "x": -9,
      "y": 25,
      "z": -3,
      "name": "Rock_Marble"
    },
    {
      "x": -9,
      "y": 26,
      "z": -3,
      "name": "Rock_Marble"
    },
    {
      "x": -9,
      "y": 27,
      "z": -3,
      "name": "Soil_Dirt"
    },
    {
      "x": -9,
      "y": 28,
      "z": -3,
      "name": "Soil_Grass"
    },
    {
      "x": -9,
      "y": 7,
      "z": -2,
      "name": "Rock_Marble"
    },
    {
      "x": -9,
      "y": 8,
      "z": -2,
      "name": "Rock_Marble"
    },
    {
      "x": -9,
      "y": 9,
      "z": -2,
      "name": "Rock_Marble"
    },
    {
      "x": -9,
      "y": 10,
      "z": -2,
      "name": "Rock_Marble"
    },
    {
      "x": -9,
      "y": 11,
      "z": -2,
      "name": "Rock_Marble"
    },
    {
      "x": -9,
      "y": 12,
      "z": -2,
      "name": "Rock_Marble"
    },
    {
      "x": -9,
      "y": 13,
      "z": -2,
      "name": "Rock_Marble"
    },
    {
      "x": -9,
      "y": 14,
      "z": -2,
      "name": "Rock_Marble"
    },
    {
      "x": -9,
      "y": 15,
      "z": -2,
      "name": "Rock_Marble"
    },
    {
      "x": -9,
      "y": 16,
      "z": -2,
      "name": "Rock_Marble"
    },
    {
      "x": -9,
      "y": 17,
      "z": -2,
      "name": "Rock_Marble"
    },
    {
      "x": -9,
      "y": 18,
      "z": -2,
      "name": "Rock_Marble"
    },
    {
      "x": -9,
      "y": 19,
      "z": -2,
      "name": "Rock_Marble"
    },
    {
      "x": -9,
      "y": 20,
      "z": -2,
      "name": "Rock_Marble"
    },
    {
      "x": -9,
      "y": 21,
      "z": -2,
      "name": "Rock_Marble"
    },
    {
      "x": -9,
      "y": 22,
      "z": -2,
      "name": "Rock_Marble"
    },
    {
      "x": -9,
      "y": 23,
      "z": -2,
      "name": "Rock_Marble"
    },
    {
      "x": -9,
      "y": 24,
      "z": -2,
      "name": "Rock_Marble"
    },
    {
      "x": -9,
      "y": 25,
      "z": -2,
      "name": "Rock_Marble"
    },
    {
      "x": -9,
      "y": 26,
      "z": -2,
      "name": "Rock_Marble"
    },
    {
      "x": -9,
      "y": 27,
      "z": -2,
      "name": "Soil_Dirt"
    },
    {
      "x": -9,
      "y": 28,
      "z": -2,
      "name": "Soil_Grass"
    },
    {
      "x": -9,
      "y": 7,
      "z": -1,
      "name": "Rock_Marble"
    },
    {
      "x": -9,
      "y": 8,
      "z": -1,
      "name": "Rock_Marble"
    },
    {
      "x": -9,
      "y": 9,
      "z": -1,
      "name": "Rock_Marble"
    },
    {
      "x": -9,
      "y": 10,
      "z": -1,
      "name": "Rock_Marble"
    },
    {
      "x": -9,
      "y": 11,
      "z": -1,
      "name": "Rock_Marble"
    },
    {
      "x": -9,
      "y": 12,
      "z": -1,
      "name": "Rock_Marble"
    },
    {
      "x": -9,
      "y": 13,
      "z": -1,
      "name": "Rock_Marble"
    },
    {
      "x": -9,
      "y": 14,
      "z": -1,
      "name": "Rock_Marble"
    },
    {
      "x": -9,
      "y": 15,
      "z": -1,
      "name": "Rock_Marble"
    },
    {
      "x": -9,
      "y": 16,
      "z": -1,
      "name": "Rock_Marble"
    },
    {
      "x": -9,
      "y": 17,
      "z": -1,
      "name": "Rock_Marble"
    },
    {
      "x": -9,
      "y": 18,
      "z": -1,
      "name": "Rock_Marble"
    },
    {
      "x": -9,
      "y": 19,
      "z": -1,
      "name": "Rock_Marble"
    },
    {
      "x": -9,
      "y": 20,
      "z": -1,
      "name": "Rock_Marble"
    },
    {
      "x": -9,
      "y": 21,
      "z": -1,
      "name": "Rock_Marble"
    },
    {
      "x": -9,
      "y": 22,
      "z": -1,
      "name": "Rock_Marble"
    },
    {
      "x": -9,
      "y": 23,
      "z": -1,
      "name": "Rock_Marble"
    },
    {
      "x": -9,
      "y": 24,
      "z": -1,
      "name": "Rock_Marble"
    },
    {
      "x": -9,
      "y": 25,
      "z": -1,
      "name": "Rock_Marble"
    },
    {
      "x": -9,
      "y": 26,
      "z": -1,
      "name": "Soil_Dirt"
    },
    {
      "x": -9,
      "y": 27,
      "z": -1,
      "name": "Soil_Dirt"
    },
    {
      "x": -9,
      "y": 28,
      "z": -1,
      "name": "Soil_Grass"
    },
    {
      "x": -9,
      "y": 6,
      "z": 0,
      "name": "Rock_Marble"
    },
    {
      "x": -9,
      "y": 7,
      "z": 0,
      "name": "Rock_Marble"
    },
    {
      "x": -9,
      "y": 8,
      "z": 0,
      "name": "Rock_Marble"
    },
    {
      "x": -9,
      "y": 9,
      "z": 0,
      "name": "Rock_Marble"
    },
    {
      "x": -9,
      "y": 10,
      "z": 0,
      "name": "Rock_Marble"
    },
    {
      "x": -9,
      "y": 11,
      "z": 0,
      "name": "Rock_Marble"
    },
    {
      "x": -9,
      "y": 12,
      "z": 0,
      "name": "Rock_Marble"
    },
    {
      "x": -9,
      "y": 13,
      "z": 0,
      "name": "Rock_Marble"
    },
    {
      "x": -9,
      "y": 14,
      "z": 0,
      "name": "Rock_Marble"
    },
    {
      "x": -9,
      "y": 15,
      "z": 0,
      "name": "Rock_Marble"
    },
    {
      "x": -9,
      "y": 16,
      "z": 0,
      "name": "Rock_Marble"
    },
    {
      "x": -9,
      "y": 17,
      "z": 0,
      "name": "Rock_Marble"
    },
    {
      "x": -9,
      "y": 18,
      "z": 0,
      "name": "Rock_Marble"
    },
    {
      "x": -9,
      "y": 19,
      "z": 0,
      "name": "Rock_Marble"
    },
    {
      "x": -9,
      "y": 20,
      "z": 0,
      "name": "Rock_Marble"
    },
    {
      "x": -9,
      "y": 21,
      "z": 0,
      "name": "Rock_Marble"
    },
    {
      "x": -9,
      "y": 22,
      "z": 0,
      "name": "Rock_Marble"
    },
    {
      "x": -9,
      "y": 23,
      "z": 0,
      "name": "Rock_Marble"
    },
    {
      "x": -9,
      "y": 24,
      "z": 0,
      "name": "Rock_Marble"
    },
    {
      "x": -9,
      "y": 25,
      "z": 0,
      "name": "Rock_Marble"
    },
    {
      "x": -9,
      "y": 26,
      "z": 0,
      "name": "Soil_Dirt"
    },
    {
      "x": -9,
      "y": 27,
      "z": 0,
      "name": "Soil_Dirt"
    },
    {
      "x": -9,
      "y": 28,
      "z": 0,
      "name": "Soil_Grass"
    },
    {
      "x": -9,
      "y": 6,
      "z": 1,
      "name": "Rock_Marble"
    },
    {
      "x": -9,
      "y": 7,
      "z": 1,
      "name": "Rock_Marble"
    },
    {
      "x": -9,
      "y": 8,
      "z": 1,
      "name": "Rock_Marble"
    },
    {
      "x": -9,
      "y": 9,
      "z": 1,
      "name": "Rock_Marble"
    },
    {
      "x": -9,
      "y": 10,
      "z": 1,
      "name": "Rock_Marble"
    },
    {
      "x": -9,
      "y": 11,
      "z": 1,
      "name": "Rock_Marble"
    },
    {
      "x": -9,
      "y": 12,
      "z": 1,
      "name": "Rock_Marble"
    },
    {
      "x": -9,
      "y": 13,
      "z": 1,
      "name": "Rock_Marble"
    },
    {
      "x": -9,
      "y": 14,
      "z": 1,
      "name": "Rock_Marble"
    },
    {
      "x": -9,
      "y": 15,
      "z": 1,
      "name": "Rock_Marble"
    },
    {
      "x": -9,
      "y": 16,
      "z": 1,
      "name": "Rock_Marble"
    },
    {
      "x": -9,
      "y": 17,
      "z": 1,
      "name": "Rock_Marble"
    },
    {
      "x": -9,
      "y": 18,
      "z": 1,
      "name": "Rock_Marble"
    },
    {
      "x": -9,
      "y": 19,
      "z": 1,
      "name": "Rock_Marble"
    },
    {
      "x": -9,
      "y": 20,
      "z": 1,
      "name": "Rock_Marble"
    },
    {
      "x": -9,
      "y": 21,
      "z": 1,
      "name": "Rock_Marble"
    },
    {
      "x": -9,
      "y": 22,
      "z": 1,
      "name": "Rock_Marble"
    },
    {
      "x": -9,
      "y": 23,
      "z": 1,
      "name": "Rock_Marble"
    },
    {
      "x": -9,
      "y": 24,
      "z": 1,
      "name": "Rock_Marble"
    },
    {
      "x": -9,
      "y": 25,
      "z": 1,
      "name": "Rock_Marble"
    },
    {
      "x": -9,
      "y": 26,
      "z": 1,
      "name": "Soil_Dirt"
    },
    {
      "x": -9,
      "y": 27,
      "z": 1,
      "name": "Soil_Dirt"
    },
    {
      "x": -9,
      "y": 28,
      "z": 1,
      "name": "Soil_Grass"
    },
    {
      "x": -9,
      "y": 6,
      "z": 2,
      "name": "Rock_Marble"
    },
    {
      "x": -9,
      "y": 7,
      "z": 2,
      "name": "Rock_Marble"
    },
    {
      "x": -9,
      "y": 8,
      "z": 2,
      "name": "Rock_Marble"
    },
    {
      "x": -9,
      "y": 9,
      "z": 2,
      "name": "Rock_Marble"
    },
    {
      "x": -9,
      "y": 10,
      "z": 2,
      "name": "Rock_Marble"
    },
    {
      "x": -9,
      "y": 11,
      "z": 2,
      "name": "Rock_Marble"
    },
    {
      "x": -9,
      "y": 12,
      "z": 2,
      "name": "Rock_Marble"
    },
    {
      "x": -9,
      "y": 13,
      "z": 2,
      "name": "Rock_Marble"
    },
    {
      "x": -9,
      "y": 14,
      "z": 2,
      "name": "Rock_Marble"
    },
    {
      "x": -9,
      "y": 15,
      "z": 2,
      "name": "Rock_Marble"
    },
    {
      "x": -9,
      "y": 16,
      "z": 2,
      "name": "Rock_Marble"
    },
    {
      "x": -9,
      "y": 17,
      "z": 2,
      "name": "Rock_Marble"
    },
    {
      "x": -9,
      "y": 18,
      "z": 2,
      "name": "Rock_Marble"
    },
    {
      "x": -9,
      "y": 19,
      "z": 2,
      "name": "Rock_Marble"
    },
    {
      "x": -9,
      "y": 20,
      "z": 2,
      "name": "Rock_Marble"
    },
    {
      "x": -9,
      "y": 21,
      "z": 2,
      "name": "Rock_Marble"
    },
    {
      "x": -9,
      "y": 22,
      "z": 2,
      "name": "Rock_Marble"
    },
    {
      "x": -9,
      "y": 23,
      "z": 2,
      "name": "Rock_Marble"
    },
    {
      "x": -9,
      "y": 24,
      "z": 2,
      "name": "Rock_Marble"
    },
    {
      "x": -9,
      "y": 25,
      "z": 2,
      "name": "Rock_Marble"
    },
    {
      "x": -9,
      "y": 26,
      "z": 2,
      "name": "Rock_Marble"
    },
    {
      "x": -9,
      "y": 27,
      "z": 2,
      "name": "Soil_Dirt"
    },
    {
      "x": -9,
      "y": 28,
      "z": 2,
      "name": "Soil_Dirt"
    },
    {
      "x": -9,
      "y": 29,
      "z": 2,
      "name": "Soil_Grass"
    },
    {
      "x": -9,
      "y": 6,
      "z": 3,
      "name": "Rock_Marble"
    },
    {
      "x": -9,
      "y": 7,
      "z": 3,
      "name": "Rock_Marble"
    },
    {
      "x": -9,
      "y": 8,
      "z": 3,
      "name": "Rock_Marble"
    },
    {
      "x": -9,
      "y": 9,
      "z": 3,
      "name": "Rock_Marble"
    },
    {
      "x": -9,
      "y": 10,
      "z": 3,
      "name": "Rock_Marble"
    },
    {
      "x": -9,
      "y": 11,
      "z": 3,
      "name": "Rock_Marble"
    },
    {
      "x": -9,
      "y": 12,
      "z": 3,
      "name": "Rock_Marble"
    },
    {
      "x": -9,
      "y": 13,
      "z": 3,
      "name": "Rock_Marble"
    },
    {
      "x": -9,
      "y": 14,
      "z": 3,
      "name": "Rock_Marble"
    },
    {
      "x": -9,
      "y": 15,
      "z": 3,
      "name": "Rock_Marble"
    },
    {
      "x": -9,
      "y": 16,
      "z": 3,
      "name": "Rock_Marble"
    },
    {
      "x": -9,
      "y": 17,
      "z": 3,
      "name": "Rock_Marble"
    },
    {
      "x": -9,
      "y": 18,
      "z": 3,
      "name": "Rock_Marble"
    },
    {
      "x": -9,
      "y": 19,
      "z": 3,
      "name": "Rock_Marble"
    },
    {
      "x": -9,
      "y": 20,
      "z": 3,
      "name": "Rock_Marble"
    },
    {
      "x": -9,
      "y": 21,
      "z": 3,
      "name": "Rock_Marble"
    },
    {
      "x": -9,
      "y": 22,
      "z": 3,
      "name": "Rock_Marble"
    },
    {
      "x": -9,
      "y": 23,
      "z": 3,
      "name": "Rock_Marble"
    },
    {
      "x": -9,
      "y": 24,
      "z": 3,
      "name": "Rock_Marble"
    },
    {
      "x": -9,
      "y": 25,
      "z": 3,
      "name": "Rock_Marble"
    },
    {
      "x": -9,
      "y": 26,
      "z": 3,
      "name": "Rock_Marble"
    },
    {
      "x": -9,
      "y": 27,
      "z": 3,
      "name": "Soil_Dirt"
    },
    {
      "x": -9,
      "y": 28,
      "z": 3,
      "name": "Soil_Dirt"
    },
    {
      "x": -9,
      "y": 29,
      "z": 3,
      "name": "Soil_Grass"
    },
    {
      "x": -9,
      "y": 6,
      "z": 4,
      "name": "Rock_Marble"
    },
    {
      "x": -9,
      "y": 7,
      "z": 4,
      "name": "Rock_Marble"
    },
    {
      "x": -9,
      "y": 8,
      "z": 4,
      "name": "Rock_Marble"
    },
    {
      "x": -9,
      "y": 9,
      "z": 4,
      "name": "Rock_Marble"
    },
    {
      "x": -9,
      "y": 10,
      "z": 4,
      "name": "Rock_Marble"
    },
    {
      "x": -9,
      "y": 11,
      "z": 4,
      "name": "Rock_Marble"
    },
    {
      "x": -9,
      "y": 12,
      "z": 4,
      "name": "Rock_Marble"
    },
    {
      "x": -9,
      "y": 13,
      "z": 4,
      "name": "Rock_Marble"
    },
    {
      "x": -9,
      "y": 14,
      "z": 4,
      "name": "Rock_Marble"
    },
    {
      "x": -9,
      "y": 15,
      "z": 4,
      "name": "Rock_Marble"
    },
    {
      "x": -9,
      "y": 16,
      "z": 4,
      "name": "Rock_Marble"
    },
    {
      "x": -9,
      "y": 17,
      "z": 4,
      "name": "Rock_Marble"
    },
    {
      "x": -9,
      "y": 18,
      "z": 4,
      "name": "Rock_Marble"
    },
    {
      "x": -9,
      "y": 19,
      "z": 4,
      "name": "Rock_Marble"
    },
    {
      "x": -9,
      "y": 20,
      "z": 4,
      "name": "Rock_Marble"
    },
    {
      "x": -9,
      "y": 21,
      "z": 4,
      "name": "Rock_Marble"
    },
    {
      "x": -9,
      "y": 22,
      "z": 4,
      "name": "Rock_Marble"
    },
    {
      "x": -9,
      "y": 23,
      "z": 4,
      "name": "Rock_Marble"
    },
    {
      "x": -9,
      "y": 24,
      "z": 4,
      "name": "Rock_Marble"
    },
    {
      "x": -9,
      "y": 25,
      "z": 4,
      "name": "Rock_Marble"
    },
    {
      "x": -9,
      "y": 26,
      "z": 4,
      "name": "Rock_Marble"
    },
    {
      "x": -9,
      "y": 27,
      "z": 4,
      "name": "Rock_Marble"
    },
    {
      "x": -9,
      "y": 28,
      "z": 4,
      "name": "Soil_Dirt"
    },
    {
      "x": -9,
      "y": 29,
      "z": 4,
      "name": "Soil_Grass"
    },
    {
      "x": -9,
      "y": 6,
      "z": 5,
      "name": "Rock_Marble"
    },
    {
      "x": -9,
      "y": 7,
      "z": 5,
      "name": "Rock_Marble"
    },
    {
      "x": -9,
      "y": 8,
      "z": 5,
      "name": "Rock_Marble"
    },
    {
      "x": -9,
      "y": 9,
      "z": 5,
      "name": "Rock_Marble"
    },
    {
      "x": -9,
      "y": 10,
      "z": 5,
      "name": "Rock_Marble"
    },
    {
      "x": -9,
      "y": 11,
      "z": 5,
      "name": "Rock_Marble"
    },
    {
      "x": -9,
      "y": 12,
      "z": 5,
      "name": "Rock_Marble"
    },
    {
      "x": -9,
      "y": 13,
      "z": 5,
      "name": "Rock_Marble"
    },
    {
      "x": -9,
      "y": 14,
      "z": 5,
      "name": "Rock_Marble"
    },
    {
      "x": -9,
      "y": 15,
      "z": 5,
      "name": "Rock_Marble"
    },
    {
      "x": -9,
      "y": 16,
      "z": 5,
      "name": "Rock_Marble"
    },
    {
      "x": -9,
      "y": 17,
      "z": 5,
      "name": "Rock_Marble"
    },
    {
      "x": -9,
      "y": 18,
      "z": 5,
      "name": "Rock_Marble"
    },
    {
      "x": -9,
      "y": 19,
      "z": 5,
      "name": "Rock_Marble"
    },
    {
      "x": -9,
      "y": 20,
      "z": 5,
      "name": "Rock_Marble"
    },
    {
      "x": -9,
      "y": 21,
      "z": 5,
      "name": "Rock_Marble"
    },
    {
      "x": -9,
      "y": 22,
      "z": 5,
      "name": "Rock_Marble"
    },
    {
      "x": -9,
      "y": 23,
      "z": 5,
      "name": "Rock_Marble"
    },
    {
      "x": -9,
      "y": 24,
      "z": 5,
      "name": "Rock_Marble"
    },
    {
      "x": -9,
      "y": 25,
      "z": 5,
      "name": "Rock_Marble"
    },
    {
      "x": -9,
      "y": 26,
      "z": 5,
      "name": "Rock_Marble"
    },
    {
      "x": -9,
      "y": 27,
      "z": 5,
      "name": "Rock_Marble"
    },
    {
      "x": -9,
      "y": 28,
      "z": 5,
      "name": "Rock_Marble"
    },
    {
      "x": -9,
      "y": 29,
      "z": 5,
      "name": "Soil_Grass"
    },
    {
      "x": -9,
      "y": 6,
      "z": 6,
      "name": "Rock_Marble"
    },
    {
      "x": -9,
      "y": 7,
      "z": 6,
      "name": "Rock_Marble"
    },
    {
      "x": -9,
      "y": 8,
      "z": 6,
      "name": "Rock_Marble"
    },
    {
      "x": -9,
      "y": 9,
      "z": 6,
      "name": "Rock_Marble"
    },
    {
      "x": -9,
      "y": 10,
      "z": 6,
      "name": "Rock_Marble"
    },
    {
      "x": -9,
      "y": 11,
      "z": 6,
      "name": "Rock_Marble"
    },
    {
      "x": -9,
      "y": 12,
      "z": 6,
      "name": "Rock_Marble"
    },
    {
      "x": -9,
      "y": 13,
      "z": 6,
      "name": "Rock_Marble"
    },
    {
      "x": -9,
      "y": 14,
      "z": 6,
      "name": "Rock_Marble"
    },
    {
      "x": -9,
      "y": 15,
      "z": 6,
      "name": "Rock_Marble"
    },
    {
      "x": -9,
      "y": 16,
      "z": 6,
      "name": "Rock_Marble"
    },
    {
      "x": -9,
      "y": 17,
      "z": 6,
      "name": "Rock_Marble"
    },
    {
      "x": -9,
      "y": 18,
      "z": 6,
      "name": "Rock_Marble"
    },
    {
      "x": -9,
      "y": 19,
      "z": 6,
      "name": "Rock_Marble"
    },
    {
      "x": -9,
      "y": 20,
      "z": 6,
      "name": "Rock_Marble"
    },
    {
      "x": -9,
      "y": 21,
      "z": 6,
      "name": "Rock_Marble"
    },
    {
      "x": -9,
      "y": 22,
      "z": 6,
      "name": "Rock_Marble"
    },
    {
      "x": -9,
      "y": 23,
      "z": 6,
      "name": "Rock_Marble"
    },
    {
      "x": -9,
      "y": 24,
      "z": 6,
      "name": "Rock_Marble"
    },
    {
      "x": -9,
      "y": 25,
      "z": 6,
      "name": "Rock_Marble"
    },
    {
      "x": -9,
      "y": 26,
      "z": 6,
      "name": "Rock_Marble"
    },
    {
      "x": -9,
      "y": 27,
      "z": 6,
      "name": "Rock_Marble"
    },
    {
      "x": -9,
      "y": 28,
      "z": 6,
      "name": "Rock_Marble"
    },
    {
      "x": -9,
      "y": 29,
      "z": 6,
      "name": "Soil_Dirt"
    },
    {
      "x": -9,
      "y": 30,
      "z": 6,
      "name": "Soil_Grass"
    },
    {
      "x": -9,
      "y": 7,
      "z": 7,
      "name": "Rock_Marble"
    },
    {
      "x": -9,
      "y": 8,
      "z": 7,
      "name": "Rock_Marble"
    },
    {
      "x": -9,
      "y": 9,
      "z": 7,
      "name": "Rock_Marble"
    },
    {
      "x": -9,
      "y": 10,
      "z": 7,
      "name": "Rock_Marble"
    },
    {
      "x": -9,
      "y": 11,
      "z": 7,
      "name": "Rock_Marble"
    },
    {
      "x": -9,
      "y": 12,
      "z": 7,
      "name": "Rock_Marble"
    },
    {
      "x": -9,
      "y": 13,
      "z": 7,
      "name": "Rock_Marble"
    },
    {
      "x": -9,
      "y": 14,
      "z": 7,
      "name": "Rock_Marble"
    },
    {
      "x": -9,
      "y": 15,
      "z": 7,
      "name": "Rock_Marble"
    },
    {
      "x": -9,
      "y": 16,
      "z": 7,
      "name": "Rock_Marble"
    },
    {
      "x": -9,
      "y": 17,
      "z": 7,
      "name": "Rock_Marble"
    },
    {
      "x": -9,
      "y": 18,
      "z": 7,
      "name": "Rock_Marble"
    },
    {
      "x": -9,
      "y": 19,
      "z": 7,
      "name": "Rock_Marble"
    },
    {
      "x": -9,
      "y": 20,
      "z": 7,
      "name": "Rock_Marble"
    },
    {
      "x": -9,
      "y": 21,
      "z": 7,
      "name": "Rock_Marble"
    },
    {
      "x": -9,
      "y": 22,
      "z": 7,
      "name": "Rock_Marble"
    },
    {
      "x": -9,
      "y": 23,
      "z": 7,
      "name": "Rock_Marble"
    },
    {
      "x": -9,
      "y": 24,
      "z": 7,
      "name": "Rock_Marble"
    },
    {
      "x": -9,
      "y": 25,
      "z": 7,
      "name": "Rock_Marble"
    },
    {
      "x": -9,
      "y": 26,
      "z": 7,
      "name": "Rock_Marble"
    },
    {
      "x": -9,
      "y": 27,
      "z": 7,
      "name": "Rock_Marble"
    },
    {
      "x": -9,
      "y": 28,
      "z": 7,
      "name": "Rock_Marble"
    },
    {
      "x": -9,
      "y": 29,
      "z": 7,
      "name": "Rock_Marble"
    },
    {
      "x": -9,
      "y": 30,
      "z": 7,
      "name": "Soil_Grass"
    },
    {
      "x": -9,
      "y": 9,
      "z": 8,
      "name": "Rock_Marble"
    },
    {
      "x": -9,
      "y": 10,
      "z": 8,
      "name": "Rock_Marble"
    },
    {
      "x": -9,
      "y": 11,
      "z": 8,
      "name": "Rock_Marble"
    },
    {
      "x": -9,
      "y": 12,
      "z": 8,
      "name": "Rock_Marble"
    },
    {
      "x": -9,
      "y": 13,
      "z": 8,
      "name": "Rock_Marble"
    },
    {
      "x": -9,
      "y": 14,
      "z": 8,
      "name": "Rock_Marble"
    },
    {
      "x": -9,
      "y": 15,
      "z": 8,
      "name": "Rock_Marble"
    },
    {
      "x": -9,
      "y": 16,
      "z": 8,
      "name": "Rock_Marble"
    },
    {
      "x": -9,
      "y": 17,
      "z": 8,
      "name": "Rock_Marble"
    },
    {
      "x": -9,
      "y": 18,
      "z": 8,
      "name": "Rock_Marble"
    },
    {
      "x": -9,
      "y": 19,
      "z": 8,
      "name": "Rock_Marble"
    },
    {
      "x": -9,
      "y": 20,
      "z": 8,
      "name": "Rock_Marble"
    },
    {
      "x": -9,
      "y": 21,
      "z": 8,
      "name": "Rock_Marble"
    },
    {
      "x": -9,
      "y": 22,
      "z": 8,
      "name": "Rock_Marble"
    },
    {
      "x": -9,
      "y": 23,
      "z": 8,
      "name": "Rock_Marble"
    },
    {
      "x": -9,
      "y": 24,
      "z": 8,
      "name": "Rock_Marble"
    },
    {
      "x": -9,
      "y": 25,
      "z": 8,
      "name": "Rock_Marble"
    },
    {
      "x": -9,
      "y": 26,
      "z": 8,
      "name": "Rock_Marble"
    },
    {
      "x": -9,
      "y": 27,
      "z": 8,
      "name": "Rock_Marble"
    },
    {
      "x": -9,
      "y": 28,
      "z": 8,
      "name": "Rock_Marble"
    },
    {
      "x": -9,
      "y": 29,
      "z": 8,
      "name": "Rock_Marble"
    },
    {
      "x": -9,
      "y": 30,
      "z": 8,
      "name": "Soil_Grass"
    },
    {
      "x": -9,
      "y": 25,
      "z": 9,
      "name": "Rock_Marble"
    },
    {
      "x": -9,
      "y": 26,
      "z": 9,
      "name": "Rock_Marble"
    },
    {
      "x": -9,
      "y": 27,
      "z": 9,
      "name": "Rock_Marble"
    },
    {
      "x": -9,
      "y": 28,
      "z": 9,
      "name": "Rock_Marble"
    },
    {
      "x": -9,
      "y": 29,
      "z": 9,
      "name": "Rock_Marble"
    },
    {
      "x": -9,
      "y": 30,
      "z": 9,
      "name": "Rock_Marble"
    },
    {
      "x": -8,
      "y": 11,
      "z": -8,
      "name": "Rock_Marble"
    },
    {
      "x": -8,
      "y": 12,
      "z": -8,
      "name": "Rock_Marble"
    },
    {
      "x": -8,
      "y": 13,
      "z": -8,
      "name": "Rock_Marble"
    },
    {
      "x": -8,
      "y": 14,
      "z": -8,
      "name": "Rock_Marble"
    },
    {
      "x": -8,
      "y": 15,
      "z": -8,
      "name": "Rock_Marble"
    },
    {
      "x": -8,
      "y": 16,
      "z": -8,
      "name": "Rock_Marble"
    },
    {
      "x": -8,
      "y": 17,
      "z": -8,
      "name": "Rock_Chalk"
    },
    {
      "x": -8,
      "y": 18,
      "z": -8,
      "name": "Rock_Chalk"
    },
    {
      "x": -8,
      "y": 19,
      "z": -8,
      "name": "Rock_Chalk"
    },
    {
      "x": -8,
      "y": 20,
      "z": -8,
      "name": "Rock_Chalk"
    },
    {
      "x": -8,
      "y": 21,
      "z": -8,
      "name": "Rock_Chalk"
    },
    {
      "x": -8,
      "y": 22,
      "z": -8,
