{
  "version": 8,
  "blockIdVersion": 8,
  "anchorX": -1,
  "anchorY": 7,
  "anchorZ": 0,
  "blocks": [
    {
      "x": -9,
      "y": 7,
      "z": -12,
      "name": "Rock_Sandstone"
    },
    {
      "x": -9,
      "y": 8,
      "z": -12,
      "name": "Rock_Sandstone"
    },
    {
      "x": -9,
      "y": 9,
      "z": -12,
      "name": "Rock_Sandstone"
    },
    {
      "x": -9,
      "y": 10,
      "z": -12,
      "name": "Rock_Sandstone"
    },
    {
      "x": -9,
      "y": 11,
      "z": -12,
      "name": "Rock_Sandstone"
    },
    {
      "x": -9,
      "y": 12,
      "z": -12,
      "name": "Rock_Sandstone"
    },
    {
      "x": -9,
      "y": 13,
      "z": -12,
      "name": "Rock_Sandstone"
    },
    {
      "x": -9,
      "y": 6,
      "z": -11,
      "name": "Rock_Sandstone"
    },
    {
      "x": -9,
      "y": 7,
      "z": -11,
      "name": "Rock_Sandstone"
    },
    {
      "x": -9,
      "y": 8,
      "z": -11,
      "name": "Rock_Sandstone"
    },
    {
      "x": -9,
      "y": 9,
      "z": -11,
      "name": "Rock_Sandstone"
    },
    {
      "x": -9,
      "y": 10,
      "z": -11,
      "name": "Rock_Sandstone"
    },
    {
      "x": -9,
      "y": 11,
      "z": -11,
      "name": "Rock_Sandstone"
    },
    {
      "x": -9,
      "y": 12,
      "z": -11,
      "name": "Rock_Sandstone"
    },
    {
      "x": -9,
      "y": 13,
      "z": -11,
      "name": "Rock_Sandstone"
    },
    {
      "x": -9,
      "y": 14,
      "z": -11,
      "name": "Rock_Sandstone"
    },
    {
      "x": -9,
      "y": 15,
      "z": -11,
      "name": "Soil_Clay"
    },
    {
      "x": -9,
      "y": 16,
      "z": -11,
      "name": "Soil_Clay"
    },
    {
      "x": -9,
      "y": 17,
      "z": -11,
      "name": "Soil_Clay"
    },
    {
      "x": -9,
      "y": 18,
      "z": -11,
      "name": "Soil_Clay"
    },
    {
      "x": -9,
      "y": 19,
      "z": -11,
      "name": "Rock_Sandstone_Red"
    },
    {
      "x": -9,
      "y": 20,
      "z": -11,
      "name": "Rock_Sandstone"
    },
    {
      "x": -9,
      "y": 21,
      "z": -11,
      "name": "Rock_Sandstone_White"
    },
    {
      "x": -9,
      "y": 6,
      "z": -10,
      "name": "Rock_Sandstone"
    },
    {
      "x": -9,
      "y": 7,
      "z": -10,
      "name": "Rock_Sandstone"
    },
    {
      "x": -9,
      "y": 8,
      "z": -10,
      "name": "Rock_Sandstone"
    },
    {
      "x": -9,
      "y": 9,
      "z": -10,
      "name": "Rock_Sandstone"
    },
    {
      "x": -9,
      "y": 10,
      "z": -10,
      "name": "Rock_Sandstone"
    },
    {
      "x": -9,
      "y": 11,
      "z": -10,
      "name": "Rock_Sandstone"
    },
    {
      "x": -9,
      "y": 12,
      "z": -10,
      "name": "Rock_Sandstone"
    },
    {
      "x": -9,
      "y": 13,
      "z": -10,
      "name": "Rock_Sandstone"
    },
    {
      "x": -9,
      "y": 14,
      "z": -10,
      "name": "Rock_Sandstone"
    },
    {
      "x": -9,
      "y": 15,
      "z": -10,
      "name": "Soil_Clay"
    },
    {
      "x": -9,
      "y": 16,
      "z": -10,
      "name": "Soil_Clay"
    },
    {
      "x": -9,
      "y": 17,
      "z": -10,
      "name": "Soil_Clay"
    },
    {
      "x": -9,
      "y": 18,
      "z": -10,
      "name": "Rock_Sandstone_Red"
    },
    {
      "x": -9,
      "y": 19,
      "z": -10,
      "name": "Rock_Sandstone_Red"
    },
    {
      "x": -9,
      "y": 20,
      "z": -10,
      "name": "Rock_Sandstone"
    },
    {
      "x": -9,
      "y": 21,
      "z": -10,
      "name": "Rock_Sandstone_White"
    },
    {
      "x": -9,
      "y": 7,
      "z": -9,
      "name": "Rock_Sandstone"
    },
    {
      "x": -9,
      "y": 8,
      "z": -9,
      "name": "Rock_Sandstone"
    },
    {
      "x": -9,
      "y": 9,
      "z": -9,
      "name": "Rock_Sandstone"
    },
    {
      "x": -9,
      "y": 10,
      "z": -9,
      "name": "Rock_Sandstone"
    },
    {
      "x": -9,
      "y": 11,
      "z": -9,
      "name": "Rock_Sandstone"
    },
    {
      "x": -9,
      "y": 12,
      "z": -9,
      "name": "Rock_Sandstone"
    },
    {
      "x": -9,
      "y": 13,
      "z": -9,
      "name": "Rock_Sandstone"
    },
    {
      "x": -9,
      "y": 14,
      "z": -9,
      "name": "Soil_Clay"
    },
    {
      "x": -9,
      "y": 15,
      "z": -9,
      "name": "Soil_Clay"
    },
    {
      "x": -9,
      "y": 16,
      "z": -9,
      "name": "Soil_Clay"
    },
    {
      "x": -9,
      "y": 17,
      "z": -9,
      "name": "Rock_Sandstone_Red"
    },
    {
      "x": -9,
      "y": 18,
      "z": -9,
      "name": "Rock_Sandstone_Red"
    },
    {
      "x": -9,
      "y": 19,
      "z": -9,
      "name": "Rock_Sandstone_Red"
    },
    {
      "x": -9,
      "y": 20,
      "z": -9,
      "name": "Rock_Sandstone"
    },
    {
      "x": -9,
      "y": 21,
      "z": -9,
      "name": "Rock_Sandstone_White"
    },
    {
      "x": -9,
      "y": 7,
      "z": -8,
      "name": "Rock_Sandstone"
    },
    {
      "x": -9,
      "y": 8,
      "z": -8,
      "name": "Rock_Sandstone"
    },
    {
      "x": -9,
      "y": 9,
      "z": -8,
      "name": "Rock_Sandstone"
    },
    {
      "x": -9,
      "y": 10,
      "z": -8,
      "name": "Rock_Sandstone"
    },
    {
      "x": -9,
      "y": 11,
      "z": -8,
      "name": "Rock_Sandstone"
    },
    {
      "x": -9,
      "y": 12,
      "z": -8,
      "name": "Rock_Sandstone"
    },
    {
      "x": -9,
      "y": 13,
      "z": -8,
      "name": "Rock_Sandstone"
    },
    {
      "x": -9,
      "y": 14,
      "z": -8,
      "name": "Soil_Clay"
    },
    {
      "x": -9,
      "y": 15,
      "z": -8,
      "name": "Soil_Clay"
    },
    {
      "x": -9,
      "y": 16,
      "z": -8,
      "name": "Soil_Clay"
    },
    {
      "x": -9,
      "y": 17,
      "z": -8,
      "name": "Rock_Sandstone_Red"
    },
    {
      "x": -9,
      "y": 18,
      "z": -8,
      "name": "Rock_Sandstone_Red"
    },
    {
      "x": -9,
      "y": 19,
      "z": -8,
      "name": "Rock_Sandstone_Red"
    },
    {
      "x": -9,
      "y": 20,
      "z": -8,
      "name": "Rock_Sandstone_White"
    },
    {
      "x": -9,
      "y": 7,
      "z": -7,
      "name": "Rock_Sandstone"
    },
    {
      "x": -9,
      "y": 8,
      "z": -7,
      "name": "Rock_Sandstone"
    },
    {
      "x": -9,
      "y": 9,
      "z": -7,
      "name": "Rock_Sandstone"
    },
    {
      "x": -9,
      "y": 10,
      "z": -7,
      "name": "Rock_Sandstone"
    },
    {
      "x": -9,
      "y": 11,
      "z": -7,
      "name": "Rock_Sandstone"
    },
    {
      "x": -9,
      "y": 12,
      "z": -7,
      "name": "Rock_Sandstone"
    },
    {
      "x": -9,
      "y": 13,
      "z": -7,
      "name": "Rock_Sandstone"
    },
    {
      "x": -8,
      "y": 6,
      "z": -14,
      "name": "Rock_Sandstone"
    },
    {
      "x": -8,
      "y": 7,
      "z": -14,
      "name": "Rock_Sandstone"
    },
    {
      "x": -8,
      "y": 8,
      "z": -14,
      "name": "Rock_Sandstone"
    },
    {
      "x": -8,
      "y": 9,
      "z": -14,
      "name": "Rock_Sandstone"
    },
    {
      "x": -8,
      "y": 10,
      "z": -14,
      "name": "Rock_Sandstone"
    },
    {
      "x": -8,
      "y": 11,
      "z": -14,
      "name": "Rock_Sandstone"
    },
    {
      "x": -8,
      "y": 12,
      "z": -14,
      "name": "Rock_Sandstone"
    },
    {
      "x": -8,
      "y": 13,
      "z": -14,
      "name": "Rock_Sandstone"
    },
    {
      "x": -8,
      "y": 14,
      "z": -14,
      "name": "Rock_Sandstone"
    },
    {
      "x": -8,
      "y": 15,
      "z": -14,
      "name": "Rock_Sandstone"
    },
    {
      "x": -8,
      "y": 16,
      "z": -14,
      "name": "Rock_Sandstone"
    },
    {
      "x": -8,
      "y": 5,
      "z": -13,
      "name": "Rock_Sandstone"
    },
    {
      "x": -8,
      "y": 6,
      "z": -13,
      "name": "Rock_Sandstone"
    },
    {
      "x": -8,
      "y": 7,
      "z": -13,
      "name": "Rock_Sandstone"
    },
    {
      "x": -8,
      "y": 8,
      "z": -13,
      "name": "Rock_Sandstone"
    },
    {
      "x": -8,
      "y": 9,
      "z": -13,
      "name": "Rock_Sandstone"
    },
    {
      "x": -8,
      "y": 10,
      "z": -13,
      "name": "Rock_Sandstone"
    },
    {
      "x": -8,
      "y": 11,
      "z": -13,
      "name": "Rock_Sandstone"
    },
    {
      "x": -8,
      "y": 12,
      "z": -13,
      "name": "Rock_Sandstone"
    },
    {
      "x": -8,
      "y": 13,
      "z": -13,
      "name": "Rock_Sandstone"
    },
    {
      "x": -8,
      "y": 14,
      "z": -13,
      "name": "Rock_Sandstone"
    },
    {
      "x": -8,
      "y": 15,
      "z": -13,
      "name": "Rock_Sandstone"
    },
    {
      "x": -8,
      "y": 16,
      "z": -13,
      "name": "Soil_Clay"
    },
    {
      "x": -8,
      "y": 17,
      "z": -13,
      "name": "Soil_Clay"
    },
    {
      "x": -8,
      "y": 18,
      "z": -13,
      "name": "Soil_Clay"
    },
    {
      "x": -8,
      "y": 19,
      "z": -13,
      "name": "Rock_Sandstone_Red"
    },
    {
      "x": -8,
      "y": 4,
      "z": -12,
      "name": "Rock_Sandstone"
    },
    {
      "x": -8,
      "y": 5,
      "z": -12,
      "name": "Rock_Sandstone"
    },
    {
      "x": -8,
      "y": 6,
      "z": -12,
      "name": "Rock_Sandstone"
    },
    {
      "x": -8,
      "y": 7,
      "z": -12,
      "name": "Rock_Sandstone"
    },
    {
      "x": -8,
      "y": 8,
      "z": -12,
      "name": "Rock_Sandstone"
    },
    {
      "x": -8,
      "y": 9,
      "z": -12,
      "name": "Rock_Sandstone"
    },
    {
      "x": -8,
      "y": 10,
      "z": -12,
      "name": "Rock_Sandstone"
    },
    {
      "x": -8,
      "y": 11,
      "z": -12,
      "name": "Rock_Sandstone"
    },
    {
      "x": -8,
      "y": 12,
      "z": -12,
      "name": "Rock_Sandstone"
    },
    {
      "x": -8,
      "y": 13,
      "z": -12,
      "name": "Rock_Sandstone"
    },
    {
      "x": -8,
      "y": 14,
      "z": -12,
      "name": "Rock_Sandstone"
    },
    {
      "x": -8,
      "y": 15,
      "z": -12,
      "name": "Rock_Sandstone"
    },
    {
      "x": -8,
      "y": 16,
      "z": -12,
      "name": "Soil_Clay"
    },
    {
      "x": -8,
      "y": 17,
      "z": -12,
      "name": "Soil_Clay"
    },
    {
      "x": -8,
      "y": 18,
      "z": -12,
      "name": "Soil_Clay"
    },
    {
      "x": -8,
      "y": 19,
      "z": -12,
      "name": "Rock_Sandstone_Red"
    },
    {
      "x": -8,
      "y": 20,
      "z": -12,
      "name": "Rock_Sandstone_Red"
    },
    {
      "x": -8,
      "y": 21,
      "z": -12,
      "name": "Rock_Sandstone"
    },
    {
      "x": -8,
      "y": 4,
      "z": -11,
      "name": "Rock_Sandstone"
    },
    {
      "x": -8,
      "y": 5,
      "z": -11,
      "name": "Rock_Sandstone"
    },
    {
      "x": -8,
      "y": 6,
      "z": -11,
      "name": "Rock_Sandstone"
    },
    {
      "x": -8,
      "y": 7,
      "z": -11,
      "name": "Rock_Sandstone"
    },
    {
      "x": -8,
      "y": 8,
      "z": -11,
      "name": "Rock_Sandstone"
    },
    {
      "x": -8,
      "y": 9,
      "z": -11,
      "name": "Rock_Sandstone"
    },
    {
      "x": -8,
      "y": 10,
      "z": -11,
      "name": "Rock_Sandstone"
    },
    {
      "x": -8,
      "y": 11,
      "z": -11,
      "name": "Rock_Sandstone"
    },
    {
      "x": -8,
      "y": 12,
      "z": -11,
      "name": "Rock_Sandstone"
    },
    {
      "x": -8,
      "y": 13,
      "z": -11,
      "name": "Rock_Sandstone"
    },
    {
      "x": -8,
      "y": 14,
      "z": -11,
      "name": "Rock_Sandstone"
    },
    {
      "x": -8,
      "y": 15,
      "z": -11,
      "name": "Soil_Clay"
    },
    {
      "x": -8,
      "y": 16,
      "z": -11,
      "name": "Soil_Clay"
    },
    {
      "x": -8,
      "y": 17,
      "z": -11,
      "name": "Soil_Clay"
    },
    {
      "x": -8,
      "y": 18,
      "z": -11,
      "name": "Soil_Clay"
    },
    {
      "x": -8,
      "y": 19,
      "z": -11,
      "name": "Rock_Sandstone_Red"
    },
    {
      "x": -8,
      "y": 20,
      "z": -11,
      "name": "Rock_Sandstone"
    },
    {
      "x": -8,
      "y": 21,
      "z": -11,
      "name": "Rock_Sandstone_White"
    },
    {
      "x": -8,
      "y": 4,
      "z": -10,
      "name": "Rock_Sandstone"
    },
    {
      "x": -8,
      "y": 5,
      "z": -10,
      "name": "Rock_Sandstone"
    },
    {
      "x": -8,
      "y": 6,
      "z": -10,
      "name": "Rock_Sandstone"
    },
    {
      "x": -8,
      "y": 7,
      "z": -10,
      "name": "Rock_Sandstone"
    },
    {
      "x": -8,
      "y": 8,
      "z": -10,
      "name": "Rock_Sandstone"
    },
    {
      "x": -8,
      "y": 9,
      "z": -10,
      "name": "Rock_Sandstone"
    },
    {
      "x": -8,
      "y": 10,
      "z": -10,
      "name": "Rock_Sandstone"
    },
    {
      "x": -8,
      "y": 11,
      "z": -10,
      "name": "Rock_Sandstone"
    },
    {
      "x": -8,
      "y": 12,
      "z": -10,
      "name": "Rock_Sandstone"
    },
    {
      "x": -8,
      "y": 13,
      "z": -10,
      "name": "Rock_Sandstone"
    },
    {
      "x": -8,
      "y": 14,
      "z": -10,
      "name": "Soil_Clay"
    },
    {
      "x": -8,
      "y": 15,
      "z": -10,
      "name": "Soil_Clay"
    },
    {
      "x": -8,
      "y": 16,
      "z": -10,
      "name": "Soil_Clay"
    },
    {
      "x": -8,
      "y": 17,
      "z": -10,
      "name": "Soil_Clay"
    },
    {
      "x": -8,
      "y": 18,
      "z": -10,
      "name": "Rock_Sandstone_Red"
    },
    {
      "x": -8,
      "y": 19,
      "z": -10,
      "name": "Rock_Sandstone_Red"
    },
    {
      "x": -8,
      "y": 20,
      "z": -10,
      "name": "Rock_Sandstone"
    },
    {
      "x": -8,
      "y": 21,
      "z": -10,
      "name": "Rock_Sandstone_White"
    },
    {
      "x": -8,
      "y": 22,
      "z": -10,
      "name": "Rock_Sandstone_White"
    },
    {
      "x": -8,
      "y": 23,
      "z": -10,
      "name": "Rock_Sandstone_White"
    },
    {
      "x": -8,
      "y": 24,
      "z": -10,
      "name": "Rock_Sandstone_White"
    },
    {
      "x": -8,
      "y": 25,
      "z": -10,
      "name": "Soil_Dirt_Dry"
    },
    {
      "x": -8,
      "y": 26,
      "z": -10,
      "name": "Soil_Clay"
    },
    {
      "x": -8,
      "y": 4,
      "z": -9,
      "name": "Rock_Sandstone"
    },
    {
      "x": -8,
      "y": 5,
      "z": -9,
      "name": "Rock_Sandstone"
    },
    {
      "x": -8,
      "y": 6,
      "z": -9,
      "name": "Rock_Sandstone"
    },
    {
      "x": -8,
      "y": 7,
      "z": -9,
      "name": "Rock_Sandstone"
    },
    {
      "x": -8,
      "y": 8,
      "z": -9,
      "name": "Rock_Sandstone"
    },
    {
      "x": -8,
      "y": 9,
      "z": -9,
      "name": "Rock_Sandstone"
    },
    {
      "x": -8,
      "y": 10,
      "z": -9,
      "name": "Rock_Sandstone"
    },
    {
      "x": -8,
      "y": 11,
      "z": -9,
      "name": "Rock_Sandstone"
    },
    {
      "x": -8,
      "y": 12,
      "z": -9,
      "name": "Rock_Sandstone"
    },
    {
      "x": -8,
      "y": 13,
      "z": -9,
      "name": "Rock_Sandstone"
    },
    {
      "x": -8,
      "y": 14,
      "z": -9,
      "name": "Soil_Clay"
    },
    {
      "x": -8,
      "y": 15,
      "z": -9,
      "name": "Soil_Clay"
    },
    {
      "x": -8,
      "y": 16,
      "z": -9,
      "name": "Soil_Clay"
    },
    {
      "x": -8,
      "y": 17,
      "z": -9,
      "name": "Rock_Sandstone_Red"
    },
    {
      "x": -8,
      "y": 18,
      "z": -9,
      "name": "Rock_Sandstone_Red"
    },
    {
      "x": -8,
      "y": 19,
      "z": -9,
      "name": "Rock_Sandstone_Red"
    },
    {
      "x": -8,
      "y": 20,
      "z": -9,
      "name": "Rock_Sandstone"
    },
    {
      "x": -8,
      "y": 21,
      "z": -9,
      "name": "Rock_Sandstone_White"
    },
    {
      "x": -8,
      "y": 22,
      "z": -9,
      "name": "Rock_Sandstone_White"
    },
    {
      "x": -8,
      "y": 23,
      "z": -9,
      "name": "Rock_Sandstone_White"
    },
    {
      "x": -8,
      "y": 24,
      "z": -9,
      "name": "Soil_Dirt_Dry"
    },
    {
      "x": -8,
      "y": 25,
      "z": -9,
      "name": "Soil_Dirt_Dry"
    },
    {
      "x": -8,
      "y": 26,
      "z": -9,
      "name": "Soil_Clay"
    },
    {
      "x": -8,
      "y": 27,
      "z": -9,
      "name": "Rock_Sandstone"
    },
    {
      "x": -8,
      "y": 28,
      "z": -9,
      "name": "Rock_Sandstone"
    },
    {
      "x": -8,
      "y": 29,
      "z": -9,
      "name": "Rock_Sandstone"
    },
    {
      "x": -8,
      "y": 4,
      "z": -8,
      "name": "Rock_Sandstone"
    },
    {
      "x": -8,
      "y": 5,
      "z": -8,
      "name": "Rock_Sandstone"
    },
    {
      "x": -8,
      "y": 6,
      "z": -8,
      "name": "Rock_Sandstone"
    },
    {
      "x": -8,
      "y": 7,
      "z": -8,
      "name": "Rock_Sandstone"
    },
    {
      "x": -8,
      "y": 8,
      "z": -8,
      "name": "Rock_Sandstone"
    },
    {
      "x": -8,
      "y": 9,
      "z": -8,
      "name": "Rock_Sandstone"
    },
    {
      "x": -8,
      "y": 10,
      "z": -8,
      "name": "Rock_Sandstone"
    },
    {
      "x": -8,
      "y": 11,
      "z": -8,
      "name": "Rock_Sandstone"
    },
    {
      "x": -8,
      "y": 12,
      "z": -8,
      "name": "Rock_Sandstone"
    },
    {
      "x": -8,
      "y": 13,
      "z": -8,
      "name": "Rock_Sandstone"
    },
    {
      "x": -8,
      "y": 14,
      "z": -8,
      "name": "Soil_Clay"
    },
    {
      "x": -8,
      "y": 15,
      "z": -8,
      "name": "Soil_Clay"
    },
    {
      "x": -8,
      "y": 16,
      "z": -8,
      "name": "Soil_Clay"
    },
    {
      "x": -8,
      "y": 17,
      "z": -8,
      "name": "Rock_Sandstone_Red"
    },
    {
      "x": -8,
      "y": 18,
      "z": -8,
      "name": "Rock_Sandstone_Red"
    },
    {
      "x": -8,
      "y": 19,
      "z": -8,
      "name": "Rock_Sandstone_Red"
    },
    {
      "x": -8,
      "y": 20,
      "z": -8,
      "name": "Rock_Sandstone_White"
    },
    {
      "x": -8,
      "y": 21,
      "z": -8,
      "name": "Rock_Sandstone_White"
    },
    {
      "x": -8,
      "y": 22,
      "z": -8,
      "name": "Rock_Sandstone_White"
    },
    {
      "x": -8,
      "y": 23,
      "z": -8,
      "name": "Rock_Sandstone_White"
    },
    {
      "x": -8,
      "y": 24,
      "z": -8,
      "name": "Soil_Dirt_Dry"
    },
    {
      "x": -8,
      "y": 25,
      "z": -8,
      "name": "Soil_Dirt_Dry"
    },
    {
      "x": -8,
      "y": 26,
      "z": -8,
      "name": "Soil_Clay"
    },
    {
      "x": -8,
      "y": 27,
      "z": -8,
      "name": "Rock_Sandstone"
    },
    {
      "x": -8,
      "y": 28,
      "z": -8,
      "name": "Rock_Sandstone"
    },
    {
      "x": -8,
      "y": 29,
      "z": -8,
      "name": "Rock_Sandstone"
    },
    {
      "x": -8,
      "y": 4,
      "z": -7,
      "name": "Rock_Sandstone"
    },
    {
      "x": -8,
      "y": 5,
      "z": -7,
      "name": "Rock_Sandstone"
    },
    {
      "x": -8,
      "y": 6,
      "z": -7,
      "name": "Rock_Sandstone"
    },
    {
      "x": -8,
      "y": 7,
      "z": -7,
      "name": "Rock_Sandstone"
    },
    {
      "x": -8,
      "y": 8,
      "z": -7,
      "name": "Rock_Sandstone"
    },
    {
      "x": -8,
      "y": 9,
      "z": -7,
      "name": "Rock_Sandstone"
    },
    {
      "x": -8,
      "y": 10,
      "z": -7,
      "name": "Rock_Sandstone"
    },
    {
      "x": -8,
      "y": 11,
      "z": -7,
      "name": "Rock_Sandstone"
    },
    {
      "x": -8,
      "y": 12,
      "z": -7,
      "name": "Rock_Sandstone"
    },
    {
      "x": -8,
      "y": 13,
      "z": -7,
      "name": "Rock_Sandstone"
    },
    {
      "x": -8,
      "y": 14,
      "z": -7,
      "name": "Soil_Clay"
    },
    {
      "x": -8,
      "y": 15,
      "z": -7,
      "name": "Soil_Clay"
    },
    {
      "x": -8,
      "y": 16,
      "z": -7,
      "name": "Rock_Sandstone_Red"
    },
    {
      "x": -8,
      "y": 17,
      "z": -7,
      "name": "Rock_Sandstone_Red"
    },
    {
      "x": -8,
      "y": 18,
      "z": -7,
      "name": "Rock_Sandstone_Red"
    },
    {
      "x": -8,
      "y": 19,
      "z": -7,
      "name": "Rock_Sandstone"
    },
    {
      "x": -8,
      "y": 20,
      "z": -7,
      "name": "Rock_Sandstone_White"
    },
    {
      "x": -8,
      "y": 21,
      "z": -7,
      "name": "Rock_Sandstone_White"
    },
    {
      "x": -8,
      "y": 22,
      "z": -7,
      "name": "Rock_Sandstone_White"
    },
    {
      "x": -8,
      "y": 23,
      "z": -7,
      "name": "Rock_Sandstone_White"
    },
    {
      "x": -8,
      "y": 24,
      "z": -7,
      "name": "Soil_Dirt_Dry"
    },
    {
      "x": -8,
      "y": 25,
      "z": -7,
      "name": "Soil_Clay"
    },
    {
      "x": -8,
      "y": 26,
      "z": -7,
      "name": "Soil_Clay"
    },
    {
      "x": -8,
      "y": 27,
      "z": -7,
      "name": "Rock_Sandstone"
    },
    {
      "x": -8,
      "y": 28,
      "z": -7,
      "name": "Rock_Sandstone"
    },
    {
      "x": -8,
      "y": 29,
      "z": -7,
      "name": "Rock_Sandstone"
    },
    {
      "x": -8,
      "y": 4,
      "z": -6,
      "name": "Rock_Sandstone"
    },
    {
      "x": -8,
      "y": 5,
      "z": -6,
      "name": "Rock_Sandstone"
    },
    {
      "x": -8,
      "y": 6,
      "z": -6,
      "name": "Rock_Sandstone"
    },
    {
      "x": -8,
      "y": 7,
      "z": -6,
      "name": "Rock_Sandstone"
    },
    {
      "x": -8,
      "y": 8,
      "z": -6,
      "name": "Rock_Sandstone"
    },
    {
      "x": -8,
      "y": 9,
      "z": -6,
      "name": "Rock_Sandstone"
    },
    {
      "x": -8,
      "y": 10,
      "z": -6,
      "name": "Rock_Sandstone"
    },
    {
      "x": -8,
      "y": 11,
      "z": -6,
      "name": "Rock_Sandstone"
    },
    {
      "x": -8,
      "y": 12,
      "z": -6,
      "name": "Rock_Sandstone"
    },
    {
      "x": -8,
      "y": 13,
      "z": -6,
      "name": "Rock_Sandstone"
    },
    {
      "x": -8,
      "y": 14,
      "z": -6,
      "name": "Soil_Clay"
    },
    {
      "x": -8,
      "y": 18,
      "z": -6,
      "name": "Rock_Sandstone_Red"
    },
    {
      "x": -8,
      "y": 19,
      "z": -6,
      "name": "Rock_Sandstone"
    },
    {
      "x": -8,
      "y": 20,
      "z": -6,
      "name": "Rock_Sandstone_White"
    },
    {
      "x": -8,
      "y": 21,
      "z": -6,
      "name": "Rock_Sandstone_White"
    },
    {
      "x": -8,
      "y": 22,
      "z": -6,
      "name": "Rock_Sandstone_White"
    },
    {
      "x": -8,
      "y": 23,
      "z": -6,
      "name": "Rock_Sandstone"
    },
    {
      "x": -8,
      "y": 24,
      "z": -6,
      "name": "Soil_Dirt_Dry"
    },
    {
      "x": -8,
      "y": 25,
      "z": -6,
      "name": "Soil_Clay"
    },
    {
      "x": -8,
      "y": 26,
      "z": -6,
      "name": "Soil_Clay"
    },
    {
      "x": -8,
      "y": 27,
      "z": -6,
      "name": "Rock_Sandstone"
    },
    {
      "x": -8,
      "y": 28,
      "z": -6,
      "name": "Rock_Sandstone"
    },
    {
      "x": -8,
      "y": 29,
      "z": -6,
      "name": "Rock_Sandstone"
    },
    {
      "x": -8,
      "y": 6,
      "z": -5,
      "name": "Rock_Sandstone"
    },
    {
      "x": -8,
      "y": 7,
      "z": -5,
      "name": "Rock_Sandstone"
    },
    {
      "x": -8,
      "y": 8,
      "z": -5,
      "name": "Rock_Sandstone"
    },
    {
      "x": -8,
      "y": 9,
      "z": -5,
      "name": "Rock_Sandstone"
    },
    {
      "x": -8,
      "y": 10,
      "z": -5,
      "name": "Rock_Sandstone"
    },
    {
      "x": -8,
      "y": 11,
      "z": -5,
      "name": "Rock_Sandstone"
    },
    {
      "x": -8,
      "y": 21,
      "z": -5,
      "name": "Rock_Sandstone_White"
    },
    {
      "x": -8,
      "y": 22,
      "z": -5,
      "name": "Rock_Sandstone_White"
    },
    {
      "x": -8,
      "y": 23,
      "z": -5,
      "name": "Soil_Dirt_Dry"
    },
    {
      "x": -8,
      "y": 24,
      "z": -5,
      "name": "Soil_Dirt_Dry"
    },
    {
      "x": -8,
      "y": 25,
      "z": -5,
      "name": "Soil_Clay"
    },
    {
      "x": -8,
      "y": 26,
      "z": -5,
      "name": "Soil_Clay"
    },
    {
      "x": -8,
      "y": 27,
      "z": -5,
      "name": "Rock_Sandstone"
    },
    {
      "x": -8,
      "y": 28,
      "z": -5,
      "name": "Rock_Sandstone"
    },
    {
      "x": -8,
      "y": 21,
      "z": -4,
      "name": "Rock_Sandstone_White"
    },
    {
      "x": -8,
      "y": 22,
      "z": -4,
      "name": "Rock_Sandstone_White"
    },
    {
      "x": -8,
      "y": 23,
      "z": -4,
      "name": "Soil_Dirt_Dry"
    },
    {
      "x": -8,
      "y": 24,
      "z": -4,
      "name": "Soil_Clay"
    },
    {
      "x": -8,
      "y": 25,
      "z": -4,
      "name": "Soil_Clay"
    },
    {
      "x": -8,
      "y": 26,
      "z": -4,
      "name": "Rock_Sandstone"
    },
    {
      "x": -8,
      "y": 27,
      "z": -4,
      "name": "Rock_Sandstone"
    },
    {
      "x": -8,
      "y": 28,
      "z": -4,
      "name": "Rock_Sandstone"
    },
    {
      "x": -8,
      "y": 21,
      "z": -3,
      "name": "Rock_Sandstone_White"
    },
    {
      "x": -8,
      "y": 22,
      "z": -3,
      "name": "Rock_Sandstone_White"
    },
    {
      "x": -8,
      "y": 23,
      "z": -3,
      "name": "Soil_Dirt_Dry"
    },
    {
      "x": -8,
      "y": 24,
      "z": -3,
      "name": "Soil_Clay"
    },
    {
      "x": -8,
      "y": 25,
      "z": -3,
      "name": "Soil_Clay"
    },
    {
      "x": -8,
      "y": 26,
      "z": -3,
      "name": "Rock_Sandstone"
    },
    {
      "x": -8,
      "y": 27,
      "z": -3,
      "name": "Rock_Sandstone"
    },
    {
      "x": -8,
      "y": 28,
      "z": -3,
      "name": "Rock_Sandstone"
    },
    {
      "x": -8,
      "y": 22,
      "z": -2,
      "name": "Soil_Dirt_Dry"
    },
    {
      "x": -8,
      "y": 23,
      "z": -2,
      "name": "Soil_Clay"
    },
    {
      "x": -8,
      "y": 24,
      "z": -2,
      "name": "Soil_Clay"
    },
    {
      "x": -8,
      "y": 25,
      "z": -2,
      "name": "Soil_Clay"
    },
    {
      "x": -8,
      "y": 26,
      "z": -2,
      "name": "Rock_Sandstone"
    },
    {
      "x": -8,
      "y": 27,
      "z": -2,
      "name": "Rock_Sandstone"
    },
    {
      "x": -8,
      "y": 28,
      "z": -2,
      "name": "Rock_Sandstone"
    },
    {
      "x": -8,
      "y": 29,
      "z": -2,
      "name": "Rock_Sandstone"
    },
    {
      "x": -8,
      "y": 22,
      "z": -1,
      "name": "Soil_Dirt_Dry"
    },
    {
      "x": -8,
      "y": 23,
      "z": -1,
      "name": "Soil_Clay"
    },
    {
      "x": -8,
      "y": 24,
      "z": -1,
      "name": "Soil_Clay"
    },
    {
      "x": -8,
      "y": 25,
      "z": -1,
      "name": "Soil_Clay"
    },
    {
      "x": -8,
      "y": 26,
      "z": -1,
      "name": "Rock_Sandstone"
    },
    {
      "x": -8,
      "y": 27,
      "z": -1,
      "name": "Rock_Sandstone"
    },
    {
      "x": -8,
      "y": 28,
      "z": -1,
      "name": "Rock_Sandstone"
    },
    {
      "x": -8,
      "y": 29,
      "z": -1,
      "name": "Rock_Sandstone"
    },
    {
      "x": -8,
      "y": 22,
      "z": 0,
      "name": "Soil_Dirt_Dry"
    },
    {
      "x": -8,
      "y": 23,
      "z": 0,
      "name": "Soil_Clay"
    },
    {
      "x": -8,
      "y": 24,
      "z": 0,
      "name": "Soil_Clay"
    },
    {
      "x": -8,
      "y": 25,
      "z": 0,
      "name": "Rock_Sandstone"
    },
    {
      "x": -8,
      "y": 26,
      "z": 0,
      "name": "Rock_Sandstone"
    },
    {
      "x": -8,
      "y": 27,
      "z": 0,
      "name": "Rock_Sandstone"
    },
    {
      "x": -8,
      "y": 28,
      "z": 0,
      "name": "Rock_Sandstone"
    },
    {
      "x": -8,
      "y": 29,
      "z": 0,
      "name": "Rock_Sandstone"
    },
    {
      "x": -8,
      "y": 22,
      "z": 1,
      "name": "Soil_Dirt_Dry"
    },
    {
      "x": -8,
      "y": 23,
      "z": 1,
      "name": "Soil_Clay"
    },
    {
      "x": -8,
      "y": 24,
      "z": 1,
      "name": "Soil_Clay"
    },
    {
      "x": -8,
      "y": 25,
      "z": 1,
      "name": "Rock_Sandstone"
    },
    {
      "x": -8,
      "y": 26,
      "z": 1,
      "name": "Rock_Sandstone"
    },
    {
      "x": -8,
      "y": 27,
      "z": 1,
      "name": "Rock_Sandstone"
    },
    {
      "x": -8,
      "y": 28,
      "z": 1,
      "name": "Rock_Sandstone"
    },
    {
      "x": -8,
      "y": 29,
      "z": 1,
      "name": "Rock_Sandstone"
    },
    {
      "x": -8,
      "y": 22,
      "z": 2,
      "name": "Soil_Dirt_Dry"
    },
    {
      "x": -8,
      "y": 23,
      "z": 2,
      "name": "Soil_Clay"
    },
    {
      "x": -8,
      "y": 24,
      "z": 2,
      "name": "Soil_Clay"
    },
    {
      "x": -8,
      "y": 25,
      "z": 2,
      "name": "Rock_Sandstone"
    },
    {
      "x": -8,
      "y": 26,
      "z": 2,
      "name": "Rock_Sandstone"
    },
    {
      "x": -8,
      "y": 27,
      "z": 2,
      "name": "Rock_Sandstone"
    },
    {
      "x": -8,
      "y": 28,
      "z": 2,
      "name": "Rock_Sandstone"
    },
    {
      "x": -8,
      "y": 29,
      "z": 2,
      "name": "Rock_Sandstone"
    },
    {
      "x": -8,
      "y": 22,
      "z": 3,
      "name": "Soil_Dirt_Dry"
    },
    {
      "x": -8,
      "y": 23,
      "z": 3,
      "name": "Soil_Clay"
    },
    {
      "x": -8,
      "y": 24,
      "z": 3,
      "name": "Soil_Clay"
    },
    {
      "x": -8,
      "y": 25,
      "z": 3,
      "name": "Rock_Sandstone"
    },
    {
      "x": -8,
      "y": 26,
      "z": 3,
      "name": "Rock_Sandstone"
    },
    {
      "x": -8,
      "y": 27,
      "z": 3,
      "name": "Rock_Sandstone"
    },
    {
      "x": -8,
      "y": 28,
      "z": 3,
      "name": "Rock_Sandstone"
    },
    {
      "x": -8,
      "y": 29,
      "z": 3,
      "name": "Rock_Sandstone"
    },
    {
      "x": -8,
      "y": 22,
      "z": 4,
      "name": "Soil_Dirt_Dry"
    },
    {
      "x": -8,
      "y": 23,
      "z": 4,
      "name": "Soil_Clay"
    },
    {
      "x": -8,
      "y": 24,
      "z": 4,
      "name": "Rock_Sandstone"
    },
    {
      "x": -8,
      "y": 25,
      "z": 4,
      "name": "Rock_Sandstone"
    },
    {
      "x": -8,
      "y": 26,
      "z": 4,
      "name": "Rock_Sandstone"
    },
    {
      "x": -8,
      "y": 27,
      "z": 4,
      "name": "Rock_Sandstone"
    },
    {
      "x": -8,
      "y": 28,
      "z": 4,
      "name": "Rock_Sandstone"
    },
    {
      "x": -8,
      "y": 21,
      "z": 5,
      "name": "Rock_Sandstone"
    },
    {
      "x": -8,
      "y": 22,
      "z": 5,
      "name": "Soil_Dirt_Dry"
    },
    {
      "x": -8,
      "y": 23,
      "z": 5,
      "name": "Soil_Clay"
    },
    {
      "x": -8,
      "y": 24,
      "z": 5,
      "name": "Rock_Sandstone"
    },
    {
      "x": -8,
      "y": 25,
      "z": 5,
      "name": "Rock_Sandstone"
    },
    {
      "x": -8,
      "y": 26,
      "z": 5,
      "name": "Rock_Sandstone"
    },
    {
      "x": -8,
      "y": 27,
      "z": 5,
      "name": "Rock_Sandstone"
    },
    {
      "x": -8,
      "y": 28,
      "z": 5,
      "name": "Rock_Sandstone"
    },
    {
      "x": -8,
      "y": 21,
      "z": 6,
      "name": "Soil_Dirt_Dry"
    },
    {
      "x": -8,
      "y": 22,
      "z": 6,
      "name": "Soil_Dirt_Dry"
    },
    {
      "x": -8,
      "y": 23,
      "z": 6,
      "name": "Soil_Clay"
    },
    {
      "x": -8,
      "y": 24,
      "z": 6,
      "name": "Rock_Sandstone"
    },
    {
      "x": -8,
      "y": 25,
      "z": 6,
      "name": "Rock_Sandstone"
    },
    {
      "x": -8,
      "y": 26,
      "z": 6,
      "name": "Rock_Sandstone"
    },
    {
      "x": -8,
      "y": 27,
      "z": 6,
      "name": "Rock_Sandstone"
    },
    {
      "x": -8,
      "y": 28,
      "z": 6,
      "name": "Rock_Sandstone"
    },
    {
      "x": -8,
      "y": 21,
      "z": 7,
      "name": "Soil_Dirt_Dry"
    },
    {
      "x": -8,
      "y": 22,
      "z": 7,
      "name": "Soil_Dirt_Dry"
    },
    {
      "x": -8,
      "y": 23,
      "z": 7,
      "name": "Soil_Clay"
    },
    {
      "x": -8,
      "y": 24,
      "z": 7,
      "name": "Rock_Sandstone"
    },
    {
      "x": -8,
      "y": 25,
      "z": 7,
      "name": "Rock_Sandstone"
    },
    {
      "x": -7,
      "y": 8,
      "z": -15,
      "name": "Rock_Sandstone"
    },
    {
      "x": -7,
      "y": 9,
      "z": -15,
      "name": "Rock_Sandstone"
    },
    {
      "x": -7,
      "y": 10,
      "z": -15,
      "name": "Rock_Sandstone"
    },
    {
      "x": -7,
      "y": 11,
      "z": -15,
      "name": "Rock_Sandstone"
    },
    {
      "x": -7,
      "y": 12,
      "z": -15,
      "name": "Rock_Sandstone"
    },
    {
      "x": -7,
      "y": 13,
      "z": -15,
      "name": "Rock_Sandstone"
    },
    {
      "x": -7,
      "y": 14,
      "z": -15,
      "name": "Rock_Sandstone"
    },
    {
      "x": -7,
      "y": 15,
      "z": -15,
      "name": "Rock_Sandstone"
    },
    {
      "x": -7,
      "y": 5,
      "z": -14,
      "name": "Rock_Sandstone"
    },
    {
      "x": -7,
      "y": 6,
      "z": -14,
      "name": "Rock_Sandstone"
    },
    {
      "x": -7,
      "y": 7,
      "z": -14,
      "name": "Rock_Sandstone"
    },
    {
      "x": -7,
      "y": 8,
      "z": -14,
      "name": "Rock_Sandstone"
    },
    {
      "x": -7,
      "y": 9,
      "z": -14,
      "name": "Rock_Sandstone"
    },
    {
      "x": -7,
      "y": 10,
      "z": -14,
      "name": "Rock_Sandstone"
    },
    {
      "x": -7,
      "y": 11,
      "z": -14,
      "name": "Rock_Sandstone"
    },
    {
      "x": -7,
      "y": 12,
      "z": -14,
      "name": "Rock_Sandstone"
    },
    {
      "x": -7,
      "y": 13,
      "z": -14,
      "name": "Rock_Sandstone"
    },
    {
      "x": -7,
      "y": 14,
      "z": -14,
      "name": "Rock_Sandstone"
    },
    {
      "x": -7,
      "y": 15,
      "z": -14,
      "name": "Rock_Sandstone"
    },
    {
      "x": -7,
      "y": 16,
      "z": -14,
      "name": "Rock_Sandstone"
    },
    {
      "x": -7,
      "y": 17,
      "z": -14,
      "name": "Soil_Clay"
    },
    {
      "x": -7,
      "y": 18,
      "z": -14,
      "name": "Soil_Clay"
    },
    {
      "x": -7,
      "y": 19,
      "z": -14,
      "name": "Rock_Sandstone_Red"
    },
    {
      "x": -7,
      "y": 5,
      "z": -13,
      "name": "Rock_Sandstone"
    },
    {
      "x": -7,
      "y": 6,
      "z": -13,
      "name": "Rock_Sandstone"
    },
    {
      "x": -7,
      "y": 7,
      "z": -13,
      "name": "Rock_Sandstone"
    },
    {
      "x": -7,
      "y": 8,
      "z": -13,
      "name": "Rock_Sandstone"
    },
    {
      "x": -7,
      "y": 9,
      "z": -13,
      "name": "Rock_Sandstone"
    },
    {
      "x": -7,
      "y": 10,
      "z": -13,
      "name": "Rock_Sandstone"
    },
    {
      "x": -7,
      "y": 11,
      "z": -13,
      "name": "Rock_Sandstone"
    },
    {
      "x": -7,
      "y": 12,
      "z": -13,
      "name": "Rock_Sandstone"
    },
    {
      "x": -7,
      "y": 13,
      "z": -13,
      "name": "Rock_Sandstone"
    },
    {
      "x": -7,
      "y": 14,
      "z": -13,
      "name": "Rock_Sandstone"
    },
    {
      "x": -7,
      "y": 15,
      "z": -13,
      "name": "Rock_Sandstone"
    },
    {
      "x": -7,
      "y": 16,
      "z": -13,
      "name": "Soil_Clay"
    },
    {
      "x": -7,
      "y": 17,
      "z": -13,
      "name": "Soil_Clay"
    },
    {
      "x": -7,
      "y": 18,
      "z": -13,
      "name": "Soil_Clay"
    },
    {
      "x": -7,
      "y": 19,
      "z": -13,
      "name": "Rock_Sandstone_Red"
    },
    {
      "x": -7,
      "y": 4,
      "z": -12,
      "name": "Rock_Sandstone"
    },
    {
      "x": -7,
      "y": 5,
      "z": -12,
      "name": "Rock_Sandstone"
    },
    {
      "x": -7,
      "y": 6,
      "z": -12,
      "name": "Rock_Sandstone"
    },
    {
      "x": -7,
      "y": 7,
      "z": -12,
      "name": "Rock_Sandstone"
    },
    {
      "x": -7,
      "y": 8,
      "z": -12,
      "name": "Rock_Sandstone"
    },
    {
      "x": -7,
      "y": 9,
      "z": -12,
      "name": "Rock_Sandstone"
    },
    {
      "x": -7,
      "y": 10,
      "z": -12,
      "name": "Rock_Sandstone"
    },
    {
      "x": -7,
      "y": 11,
      "z": -12,
      "name": "Rock_Sandstone"
    },
    {
      "x": -7,
      "y": 12,
      "z": -12,
      "name": "Rock_Sandstone"
    },
    {
      "x": -7,
      "y": 13,
      "z": -12,
      "name": "Rock_Sandstone"
    },
    {
      "x": -7,
      "y": 14,
      "z": -12,
      "name": "Rock_Sandstone"
    },
    {
      "x": -7,
      "y": 15,
      "z": -12,
      "name": "Rock_Sandstone"
    },
    {
      "x": -7,
      "y": 16,
      "z": -12,
      "name": "Soil_Clay"
    },
    {
      "x": -7,
      "y": 17,
      "z": -12,
      "name": "Soil_Clay"
    },
    {
      "x": -7,
      "y": 18,
      "z": -12,
      "name": "Soil_Clay"
    },
    {
      "x": -7,
      "y": 19,
      "z": -12,
      "name": "Rock_Sandstone_Red"
    },
    {
      "x": -7,
      "y": 20,
      "z": -12,
      "name": "Rock_Sandstone_Red"
    },
    {
      "x": -7,
      "y": 21,
      "z": -12,
      "name": "Rock_Sandstone"
    },
    {
      "x": -7,
      "y": 22,
      "z": -12,
      "name": "Rock_Sandstone_White"
    },
    {
      "x": -7,
      "y": 23,
      "z": -12,
      "name": "Rock_Sandstone_White"
    },
    {
      "x": -7,
      "y": 24,
      "z": -12,
      "name": "Rock_Sandstone_White"
    },
    {
      "x": -7,
      "y": 4,
      "z": -11,
      "name": "Rock_Sandstone"
    },
    {
      "x": -7,
      "y": 5,
      "z": -11,
      "name": "Rock_Sandstone"
    },
    {
      "x": -7,
      "y": 6,
      "z": -11,
      "name": "Rock_Sandstone"
    },
    {
      "x": -7,
      "y": 7,
      "z": -11,
      "name": "Rock_Sandstone"
    },
    {
      "x": -7,
      "y": 8,
      "z": -11,
      "name": "Rock_Sandstone"
    },
    {
      "x": -7,
      "y": 9,
      "z": -11,
      "name": "Rock_Sandstone"
    },
    {
      "x": -7,
      "y": 10,
      "z": -11,
      "name": "Rock_Sandstone"
    },
    {
      "x": -7,
      "y": 11,
      "z": -11,
      "name": "Rock_Sandstone"
    },
    {
      "x": -7,
      "y": 12,
      "z": -11,
      "name": "Rock_Sandstone"
    },
    {
      "x": -7,
      "y": 13,
      "z": -11,
      "name": "Rock_Sandstone"
    },
    {
      "x": -7,
      "y": 14,
      "z": -11,
      "name": "Rock_Sandstone"
    },
    {
      "x": -7,
      "y": 15,
      "z": -11,
      "name": "Soil_Clay"
    },
    {
      "x": -7,
      "y": 16,
      "z": -11,
      "name": "Soil_Clay"
    },
    {
      "x": -7,
      "y": 17,
      "z": -11,
      "name": "Soil_Clay"
    },
    {
      "x": -7,
      "y": 18,
      "z": -11,
      "name": "Soil_Clay"
    },
    {
      "x": -7,
      "y": 19,
      "z": -11,
      "name": "Rock_Sandstone_Red"
    },
    {
      "x": -7,
      "y": 20,
      "z": -11,
      "name": "Rock_Sandstone_Red"
    },
    {
      "x": -7,
      "y": 21,
      "z": -11,
      "name": "Rock_Sandstone_White"
    },
    {
      "x": -7,
      "y": 22,
      "z": -11,
      "name": "Rock_Sandstone_White"
    },
    {
      "x": -7,
      "y": 23,
      "z": -11,
      "name": "Rock_Sandstone_White"
    },
    {
      "x": -7,
      "y": 24,
      "z": -11,
      "name": "Rock_Sandstone_White"
    },
    {
      "x": -7,
      "y": 4,
      "z": -10,
      "name": "Rock_Sandstone"
    },
    {
      "x": -7,
      "y": 5,
      "z": -10,
      "name": "Rock_Sandstone"
    },
    {
      "x": -7,
      "y": 6,
      "z": -10,
      "name": "Rock_Sandstone"
    },
    {
      "x": -7,
      "y": 7,
      "z": -10,
      "name": "Rock_Sandstone"
    },
    {
      "x": -7,
      "y": 8,
      "z": -10,
      "name": "Rock_Sandstone"
    },
    {
      "x": -7,
      "y": 9,
      "z": -10,
      "name": "Rock_Sandstone"
    },
    {
      "x": -7,
      "y": 10,
      "z": -10,
      "name": "Rock_Sandstone"
    },
    {
      "x": -7,
      "y": 11,
      "z": -10,
      "name": "Rock_Sandstone"
    },
    {
      "x": -7,
      "y": 12,
      "z": -10,
      "name": "Rock_Sandstone"
    },
    {
      "x": -7,
      "y": 13,
      "z": -10,
      "name": "Rock_Sandstone"
    },
    {
      "x": -7,
      "y": 14,
      "z": -10,
      "name": "Rock_Sandstone"
    },
    {
      "x": -7,
      "y": 15,
      "z": -10,
      "name": "Soil_Clay"
    },
    {
      "x": -7,
      "y": 16,
      "z": -10,
      "name": "Soil_Clay"
    },
    {
      "x": -7,
      "y": 17,
      "z": -10,
      "name": "Soil_Clay"
    },
    {
      "x": -7,
      "y": 18,
      "z": -10,
      "name": "Soil_Clay"
    },
    {
      "x": -7,
      "y": 19,
      "z": -10,
      "name": "Rock_Sandstone_Red"
    },
    {
      "x": -7,
      "y": 20,
      "z": -10,
      "name": "Rock_Sandstone"
    },
    {
      "x": -7,
      "y": 21,
      "z": -10,
      "name": "Rock_Sandstone_White"
    },
    {
      "x": -7,
      "y": 22,
      "z": -10,
      "name": "Rock_Sandstone_White"
    },
    {
      "x": -7,
      "y": 23,
      "z": -10,
      "name": "Rock_Sandstone_White"
    },
    {
      "x": -7,
      "y": 24,
      "z": -10,
      "name": "Rock_Sandstone_White"
    },
    {
      "x": -7,
      "y": 25,
      "z": -10,
      "name": "Soil_Dirt_Dry"
    },
    {
      "x": -7,
      "y": 26,
      "z": -10,
      "name": "Soil_Clay"
    },
    {
      "x": -7,
      "y": 27,
      "z": -10,
      "name": "Soil_Clay"
    },
    {
      "x": -7,
      "y": 28,
      "z": -10,
      "name": "Rock_Sandstone"
    },
    {
      "x": -7,
      "y": 29,
      "z": -10,
      "name": "Rock_Sandstone"
    },
    {
      "x": -7,
      "y": 4,
      "z": -9,
      "name": "Rock_Sandstone"
    },
    {
      "x": -7,
      "y": 5,
      "z": -9,
      "name": "Rock_Sandstone"
    },
    {
      "x": -7,
      "y": 6,
      "z": -9,
      "name": "Rock_Sandstone"
    },
    {
      "x": -7,
      "y": 7,
      "z": -9,
      "name": "Rock_Sandstone"
    },
    {
      "x": -7,
      "y": 8,
      "z": -9,
      "name": "Rock_Sandstone"
    },
    {
      "x": -7,
      "y": 9,
      "z": -9,
      "name": "Rock_Sandstone"
    },
    {
      "x": -7,
      "y": 10,
      "z": -9,
      "name": "Rock_Sandstone"
    },
    {
      "x": -7,
      "y": 11,
      "z": -9,
      "name": "Rock_Sandstone"
    },
    {
      "x": -7,
      "y": 12,
      "z": -9,
      "name": "Rock_Sandstone"
    },
    {
      "x": -7,
      "y": 13,
      "z": -9,
      "name": "Rock_Sandstone"
    },
    {
      "x": -7,
      "y": 14,
      "z": -9,
      "name": "Soil_Clay"
    },
    {
      "x": -7,
      "y": 15,
      "z": -9,
      "name": "Soil_Clay"
    },
    {
      "x": -7,
      "y": 16,
      "z": -9,
      "name": "Soil_Clay"
    },
    {
      "x": -7,
      "y": 17,
      "z": -9,
      "name": "Rock_Sandstone_Red"
    },
    {
      "x": -7,
      "y": 18,
      "z": -9,
      "name": "Rock_Sandstone_Red"
    },
    {
      "x": -7,
      "y": 19,
      "z": -9,
      "name": "Rock_Sandstone_Red"
    },
    {
      "x": -7,
      "y": 20,
      "z": -9,
      "name": "Rock_Sandstone"
    },
    {
      "x": -7,
      "y": 21,
      "z": -9,
      "name": "Rock_Sandstone_White"
    },
    {
      "x": -7,
      "y": 22,
      "z": -9,
      "name": "Rock_Sandstone_White"
    },
    {
      "x": -7,
      "y": 23,
      "z": -9,
      "name": "Rock_Sandstone_White"
    },
    {
      "x": -7,
      "y": 24,
      "z": -9,
      "name": "Soil_Dirt_Dry"
    },
    {
      "x": -7,
      "y": 25,
      "z": -9,
      "name": "Soil_Dirt_Dry"
    },
    {
      "x": -7,
      "y": 26,
      "z": -9,
      "name": "Soil_Clay"
    },
    {
      "x": -7,
      "y": 27,
      "z": -9,
      "name": "Rock_Sandstone"
    },
    {
      "x": -7,
      "y": 28,
      "z": -9,
      "name": "Rock_Sandstone"
    },
    {
      "x": -7,
      "y": 29,
      "z": -9,
      "name": "Rock_Sandstone"
    },
    {
      "x": -7,
      "y": 4,
      "z": -8,
      "name": "Rock_Sandstone"
    },
    {
      "x": -7,
      "y": 5,
      "z": -8,
      "name": "Rock_Sandstone"
    },
    {
      "x": -7,
      "y": 6,
      "z": -8,
      "name": "Rock_Sandstone"
    },
    {
      "x": -7,
      "y": 7,
      "z": -8,
      "name": "Rock_Sandstone"
    },
    {
      "x": -7,
      "y": 8,
      "z": -8,
      "name": "Rock_Sandstone"
    },
    {
      "x": -7,
      "y": 9,
      "z": -8,
      "name": "Rock_Sandstone"
    },
    {
      "x": -7,
      "y": 10,
      "z": -8,
      "name": "Rock_Sandstone"
    },
    {
      "x": -7,
      "y": 11,
      "z": -8,
      "name": "Rock_Sandstone"
    },
    {
      "x": -7,
      "y": 12,
      "z": -8,
      "name": "Rock_Sandstone"
    },
    {
      "x": -7,
      "y": 13,
      "z": -8,
      "name": "Rock_Sandstone"
    },
    {
      "x": -7,
      "y": 14,
      "z": -8,
      "name": "Soil_Clay"
    },
    {
      "x": -7,
      "y": 15,
      "z": -8,
      "name": "Soil_Clay"
    },
    {
      "x": -7,
      "y": 16,
      "z": -8,
      "name": "Soil_Clay"
    },
    {
      "x": -7,
      "y": 17,
      "z": -8,
      "name": "Rock_Sandstone_Red"
    },
    {
      "x": -7,
      "y": 18,
      "z": -8,
      "name": "Rock_Sandstone_Red"
    },
    {
      "x": -7,
      "y": 19,
      "z": -8,
      "name": "Rock_Sandstone"
    },
    {
      "x": -7,
      "y": 20,
      "z": -8,
      "name": "Rock_Sandstone_White"
    },
    {
      "x": -7,
      "y": 21,
      "z": -8,
      "name": "Rock_Sandstone_White"
    },
    {
      "x": -7,
      "y": 22,
      "z": -8,
      "name": "Rock_Sandstone_White"
    },
    {
      "x": -7,
      "y": 23,
      "z": -8,
      "name": "Rock_Sandstone_White"
    },
    {
      "x": -7,
      "y": 24,
      "z": -8,
      "name": "Soil_Dirt_Dry"
    },
    {
      "x": -7,
      "y": 25,
      "z": -8,
      "name": "Soil_Dirt_Dry"
    },
    {
      "x": -7,
      "y": 26,
      "z": -8,
      "name": "Soil_Clay"
    },
    {
      "x": -7,
      "y": 27,
      "z": -8,
      "name": "Rock_Sandstone"
    },
    {
      "x": -7,
      "y": 28,
      "z": -8,
      "name": "Rock_Sandstone"
    },
    {
      "x": -7,
      "y": 29,
      "z": -8,
      "name": "Rock_Sandstone"
    },
    {
      "x": -7,
      "y": 4,
      "z": -7,
      "name": "Rock_Sandstone"
    },
    {
      "x": -7,
      "y": 5,
      "z": -7,
      "name": "Rock_Sandstone"
    },
    {
      "x": -7,
      "y": 6,
      "z": -7,
      "name": "Rock_Sandstone"
    },
    {
      "x": -7,
      "y": 7,
      "z": -7,
      "name": "Rock_Sandstone"
    },
    {
      "x": -7,
      "y": 8,
      "z": -7,
      "name": "Rock_Sandstone"
    },
    {
      "x": -7,
      "y": 9,
      "z": -7,
      "name": "Rock_Sandstone"
    },
    {
      "x": -7,
      "y": 10,
      "z": -7,
      "name": "Rock_Sandstone"
    },
    {
      "x": -7,
      "y": 11,
      "z": -7,
      "name": "Rock_Sandstone"
    },
    {
      "x": -7,
      "y": 12,
      "z": -7,
      "name": "Rock_Sandstone"
    },
    {
      "x": -7,
      "y": 13,
      "z": -7,
      "name": "Rock_Sandstone"
    },
    {
      "x": -7,
      "y": 14,
      "z": -7,
      "name": "Soil_Clay"
    },
    {
      "x": -7,
      "y": 15,
      "z": -7,
      "name": "Soil_Clay"
    },
    {
      "x": -7,
      "y": 16,
      "z": -7,
      "name": "Rock_Sandstone_Red"
    },
    {
      "x": -7,
      "y": 17,
      "z": -7,
      "name": "Rock_Sandstone_Red"
    },
    {
      "x": -7,
      "y": 18,
      "z": -7,
      "name": "Rock_Sandstone_Red"
    },
    {
      "x": -7,
      "y": 19,
      "z": -7,
      "name": "Rock_Sandstone"
    },
    {
      "x": -7,
      "y": 20,
      "z": -7,
      "name": "Rock_Sandstone_White"
    },
    {
      "x": -7,
      "y": 21,
      "z": -7,
      "name": "Rock_Sandstone_White"
    },
    {
      "x": -7,
      "y": 22,
      "z": -7,
      "name": "Rock_Sandstone_White"
    },
    {
      "x": -7,
      "y": 23,
      "z": -7,
      "name": "Rock_Sandstone_White"
    },
    {
      "x": -7,
      "y": 24,
      "z": -7,
      "name": "Soil_Dirt_Dry"
    },
    {
      "x": -7,
      "y": 25,
      "z": -7,
      "name": "Soil_Clay"
    },
    {
      "x": -7,
      "y": 26,
      "z": -7,
      "name": "Soil_Clay"
    },
    {
      "x": -7,
      "y": 27,
      "z": -7,
      "name": "Rock_Sandstone"
    },
    {
      "x": -7,
      "y": 28,
      "z": -7,
      "name": "Rock_Sandstone"
    },
    {
      "x": -7,
      "y": 29,
      "z": -7,
      "name": "Rock_Sandstone"
    },
    {
      "x": -7,
      "y": 4,
      "z": -6,
      "name": "Rock_Sandstone"
    },
    {
      "x": -7,
      "y": 5,
      "z": -6,
      "name": "Rock_Sandstone"
    },
    {
      "x": -7,
      "y": 6,
      "z": -6,
      "name": "Rock_Sandstone"
    },
    {
      "x": -7,
      "y": 7,
      "z": -6,
      "name": "Rock_Sandstone"
    },
    {
      "x": -7,
      "y": 8,
      "z": -6,
      "name": "Rock_Sandstone"
    },
    {
      "x": -7,
      "y": 9,
      "z": -6,
      "name": "Rock_Sandstone"
    },
    {
      "x": -7,
      "y": 10,
      "z": -6,
      "name": "Rock_Sandstone"
    },
    {
      "x": -7,
      "y": 11,
      "z": -6,
      "name": "Rock_Sandstone"
    },
    {
      "x": -7,
      "y": 12,
      "z": -6,
      "name": "Rock_Sandstone"
    },
    {
      "x": -7,
      "y": 13,
      "z": -6,
      "name": "Rock_Sandstone"
    },
    {
      "x": -7,
      "y": 14,
      "z": -6,
      "name": "Soil_Clay"
    },
    {
      "x": -7,
      "y": 15,
      "z": -6,
      "name": "Soil_Clay"
    },
    {
      "x": -7,
      "y": 16,
      "z": -6,
      "name": "Rock_Sandstone_Red"
    },
    {
      "x": -7,
      "y": 17,
      "z": -6,
      "name": "Rock_Sandstone_Red"
    },
    {
      "x": -7,
      "y": 18,
      "z": -6,
      "name": "Rock_Sandstone"
    },
    {
      "x": -7,
      "y": 19,
      "z": -6,
      "name": "Rock_Sandstone"
    },
    {
      "x": -7,
      "y": 20,
      "z": -6,
      "name": "Rock_Sandstone_White"
    },
    {
      "x": -7,
      "y": 21,
      "z": -6,
      "name": "Rock_Sandstone_White"
    },
    {
      "x": -7,
      "y": 22,
      "z": -6,
      "name": "Rock_Sandstone_White"
    },
    {
      "x": -7,
      "y": 23,
      "z": -6,
      "name": "Rock_Sandstone"
    },
    {
      "x": -7,
      "y": 24,
      "z": -6,
      "name": "Soil_Dirt_Dry"
    },
    {
      "x": -7,
      "y": 25,
      "z": -6,
      "name": "Soil_Clay"
    },
    {
      "x": -7,
      "y": 26,
      "z": -6,
      "name": "Soil_Clay"
    },
    {
      "x": -7,
      "y": 27,
      "z": -6,
      "name": "Rock_Sandstone"
    },
    {
      "x": -7,
      "y": 28,
      "z": -6,
      "name": "Rock_Sandstone"
    },
    {
      "x": -7,
      "y": 29,
      "z": -6,
      "name": "Rock_Sandstone"
    },
    {
      "x": -7,
      "y": 4,
      "z": -5,
      "name": "Rock_Sandstone"
    },
    {
      "x": -7,
      "y": 5,
      "z": -5,
      "name": "Rock_Sandstone"
    },
    {
      "x": -7,
      "y": 6,
      "z": -5,
      "name": "Rock_Sandstone"
    },
    {
      "x": -7,
      "y": 7,
      "z": -5,
      "name": "Rock_Sandstone"
    },
    {
      "x": -7,
      "y": 8,
      "z": -5,
      "name": "Rock_Sandstone"
    },
    {
      "x": -7,
      "y": 9,
      "z": -5,
      "name": "Rock_Sandstone"
    },
    {
      "x": -7,
      "y": 10,
      "z": -5,
      "name": "Rock_Sandstone"
    },
    {
      "x": -7,
      "y": 11,
      "z": -5,
      "name": "Rock_Sandstone"
    },
    {
      "x": -7,
      "y": 12,
      "z": -5,
      "name": "Rock_Sandstone"
    },
    {
      "x": -7,
      "y": 13,
      "z": -5,
      "name": "Rock_Sandstone"
    },
    {
      "x": -7,
      "y": 14,
      "z": -5,
      "name": "Soil_Clay"
    },
    {
      "x": -7,
      "y": 15,
      "z": -5,
      "name": "Soil_Clay"
    },
    {
      "x": -7,
      "y": 16,
      "z": -5,
      "name": "Rock_Sandstone_Red"
    },
    {
      "x": -7,
      "y": 17,
      "z": -5,
      "name": "Rock_Sandstone_Red"
    },
    {
      "x": -7,
      "y": 18,
      "z": -5,
      "name": "Rock_Sandstone"
    },
    {
      "x": -7,
      "y": 19,
      "z": -5,
      "name": "Rock_Sandstone"
    },
    {
      "x": -7,
      "y": 20,
      "z": -5,
      "name": "Rock_Sandstone_White"
    },
    {
      "x": -7,
      "y": 21,
      "z": -5,
      "name": "Rock_Sandstone_White"
    },
    {
      "x": -7,
      "y": 22,
      "z": -5,
      "name": "Rock_Sandstone_White"
    },
    {
      "x": -7,
      "y": 23,
      "z": -5,
      "name": "Soil_Dirt_Dry"
    },
    {
      "x": -7,
      "y": 24,
      "z": -5,
      "name": "Soil_Dirt_Dry"
    },
    {
      "x": -7,
      "y": 25,
      "z": -5,
      "name": "Soil_Clay"
    },
    {
      "x": -7,
      "y": 26,
      "z": -5,
      "name": "Soil_Clay"
    },
    {
      "x": -7,
      "y": 27,
      "z": -5,
      "name": "Rock_Sandstone"
    },
    {
      "x": -7,
      "y": 28,
      "z": -5,
      "name": "Rock_Sandstone"
    },
    {
      "x": -7,
      "y": 29,
      "z": -5,
      "name": "Rock_Sandstone"
    },
    {
      "x": -7,
      "y": 20,
      "z": -4,
      "name": "Rock_Sandstone_White"
    },
    {
      "x": -7,
      "y": 21,
      "z": -4,
      "name": "Rock_Sandstone_White"
    },
    {
      "x": -7,
      "y": 22,
      "z": -4,
      "name": "Rock_Sandstone_White"
    },
    {
      "x": -7,
      "y": 23,
      "z": -4,
      "name": "Soil_Dirt_Dry"
    },
    {
      "x": -7,
      "y": 24,
      "z": -4,
      "name": "Soil_Clay"
    },
    {
      "x": -7,
      "y": 25,
      "z": -4,
      "name": "Soil_Clay"
    },
    {
      "x": -7,
      "y": 26,
      "z": -4,
      "name": "Rock_Sandstone"
    },
    {
      "x": -7,
      "y": 27,
      "z": -4,
      "name": "Rock_Sandstone"
    },
    {
      "x": -7,
      "y": 28,
      "z": -4,
      "name": "Rock_Sandstone"
    },
    {
      "x": -7,
      "y": 29,
      "z": -4,
      "name": "Rock_Sandstone"
    },
    {
      "x": -7,
      "y": 20,
      "z": -3,
      "name": "Rock_Sandstone_White"
    },
    {
      "x": -7,
      "y": 21,
      "z": -3,
      "name": "Rock_Sandstone_White"
    },
    {
      "x": -7,
      "y": 22,
      "z": -3,
      "name": "Rock_Sandstone_White"
    },
    {
      "x": -7,
      "y": 23,
      "z": -3,
      "name": "Soil_Dirt_Dry"
    },
    {
      "x": -7,
      "y": 24,
      "z": -3,
      "name": "Soil_Clay"
    },
    {
      "x": -7,
      "y": 25,
      "z": -3,
      "name": "Soil_Clay"
    },
    {
      "x": -7,
      "y": 26,
      "z": -3,
      "name": "Rock_Sandstone"
    },
    {
      "x": -7,
      "y": 27,
      "z": -3,
      "name": "Rock_Sandstone"
    },
    {
      "x": -7,
      "y": 28,
      "z": -3,
      "name": "Rock_Sandstone"
    },
    {
      "x": -7,
      "y": 20,
      "z": -2,
      "name": "Rock_Sandstone_White"
    },
    {
      "x": -7,
      "y": 21,
      "z": -2,
      "name": "Rock_Sandstone_White"
    },
    {
      "x": -7,
      "y": 22,
      "z": -2,
      "name": "Soil_Dirt_Dry"
    },
    {
      "x": -7,
      "y": 23,
      "z": -2,
      "name": "Soil_Clay"
    },
    {
      "x": -7,
      "y": 24,
      "z": -2,
      "name": "Soil_Clay"
    },
    {
      "x": -7,
      "y": 25,
      "z": -2,
      "name": "Soil_Clay"
    },
    {
      "x": -7,
      "y": 26,
      "z": -2,
      "name": "Rock_Sandstone"
    },
    {
      "x": -7,
      "y": 27,
      "z": -2,
      "name": "Rock_Sandstone"
    },
    {
      "x": -7,
      "y": 28,
      "z": -2,
      "name": "Rock_Sandstone"
    },
    {
      "x": -7,
      "y": 29,
      "z": -2,
      "name": "Rock_Sandstone"
    },
    {
      "x": -7,
      "y": 30,
      "z": -2,
      "name": "Rock_Sandstone"
    },
    {
      "x": -7,
      "y": 21,
      "z": -1,
      "name": "Rock_Sandstone_White"
    },
    {
      "x": -7,
      "y": 22,
      "z": -1,
      "name": "Soil_Dirt_Dry"
    },
    {
      "x": -7,
      "y": 23,
      "z": -1,
      "name": "Soil_Clay"
    },
    {
      "x": -7,
      "y": 24,
      "z": -1,
      "name": "Soil_Clay"
    },
    {
      "x": -7,
      "y": 25,
      "z": -1,
      "name": "Soil_Clay"
    },
    {
      "x": -7,
      "y": 26,
      "z": -1,
      "name": "Rock_Sandstone"
    },
    {
      "x": -7,
      "y": 27,
      "z": -1,
      "name": "Rock_Sandstone"
    },
    {
      "x": -7,
      "y": 28,
      "z": -1,
      "name": "Rock_Sandstone"
    },
    {
      "x": -7,
      "y": 29,
      "z": -1,
      "name": "Rock_Sandstone"
    },
    {
      "x": -7,
      "y": 30,
      "z": -1,
      "name": "Rock_Sandstone"
    },
    {
      "x": -7,
      "y": 21,
      "z": 0,
      "name": "Rock_Sandstone_White"
    },
    {
      "x": -7,
      "y": 22,
      "z": 0,
      "name": "Soil_Dirt_Dry"
    },
    {
      "x": -7,
      "y": 23,
      "z": 0,
      "name": "Soil_Clay"
    },
    {
      "x": -7,
      "y": 24,
      "z": 0,
      "name": "Soil_Clay"
    },
    {
      "x": -7,
      "y": 25,
      "z": 0,
      "name": "Rock_Sandstone"
    },
    {
      "x": -7,
      "y": 26,
      "z": 0,
      "name": "Rock_Sandstone"
    },
    {
      "x": -7,
      "y": 27,
      "z": 0,
      "name": "Rock_Sandstone"
    },
    {
      "x": -7,
      "y": 28,
      "z": 0,
      "name": "Rock_Sandstone"
    },
    {
      "x": -7,
      "y": 29,
      "z": 0,
      "name": "Rock_Sandstone"
    },
    {
      "x": -7,
      "y": 30,
      "z": 0,
      "name": "Rock_Sandstone"
    },
    {
      "x": -7,
      "y": 21,
      "z": 1,
      "name": "Rock_Sandstone_White"
    },
    {
      "x": -7,
      "y": 22,
      "z": 1,
      "name": "Soil_Dirt_Dry"
    },
    {
      "x": -7,
      "y": 23,
      "z": 1,
      "name": "Soil_Clay"
    },
    {
      "x": -7,
      "y": 24,
      "z": 1,
      "name": "Soil_Clay"
    },
    {
      "x": -7,
      "y": 25,
      "z": 1,
      "name": "Rock_Sandstone"
    },
    {
      "x": -7,
      "y": 26,
      "z": 1,
      "name": "Rock_Sandstone"
    },
    {
      "x": -7,
      "y": 27,
      "z": 1,
      "name": "Rock_Sandstone"
    },
    {
      "x": -7,
      "y": 28,
      "z": 1,
      "name": "Rock_Sandstone"
    },
    {
      "x": -7,
      "y": 29,
      "z": 1,
      "name": "Rock_Sandstone"
    },
    {
      "x": -7,
      "y": 30,
      "z": 1,
      "name": "Rock_Sandstone"
    },
    {
      "x": -7,
      "y": 20,
      "z": 2,
      "name": "Rock_Sandstone_White"
    },
    {
      "x": -7,
      "y": 21,
      "z": 2,
      "name": "Rock_Sandstone_White"
    },
    {
      "x": -7,
      "y": 22,
      "z": 2,
      "name": "Soil_Dirt_Dry"
    },
    {
      "x": -7,
      "y": 23,
      "z": 2,
      "name": "Soil_Clay"
    },
    {
      "x": -7,
      "y": 24,
      "z": 2,
      "name": "Soil_Clay"
    },
    {
      "x": -7,
      "y": 25,
      "z": 2,
      "name": "Rock_Sandstone"
    },
    {
      "x": -7,
      "y": 26,
      "z": 2,
      "name": "Rock_Sandstone"
    },
    {
      "x": -7,
      "y": 27,
      "z": 2,
      "name": "Rock_Sandstone"
    },
    {
      "x": -7,
      "y": 28,
      "z": 2,
      "name": "Rock_Sandstone"
    },
    {
      "x": -7,
      "y": 29,
      "z": 2,
      "name": "Rock_Sandstone"
    },
    {
      "x": -7,
      "y": 30,
      "z": 2,
      "name": "Rock_Sandstone"
    },
    {
      "x": -7,
      "y": 19,
      "z": 3,
      "name": "Rock_Sandstone_White"
    },
    {
      "x": -7,
      "y": 20,
      "z": 3,
      "name": "Rock_Sandstone_White"
    },
    {
      "x": -7,
      "y": 21,
      "z": 3,
      "name": "Rock_Sandstone_White"
    },
    {
      "x": -7,
      "y": 22,
      "z": 3,
      "name": "Soil_Dirt_Dry"
    },
    {
      "x": -7,
      "y": 23,
      "z": 3,
      "name": "Soil_Clay"
    },
    {
      "x": -7,
      "y": 24,
      "z": 3,
      "name": "Soil_Clay"
    },
    {
      "x": -7,
      "y": 25,
      "z": 3,
      "name": "Rock_Sandstone"
    },
    {
      "x": -7,
      "y": 26,
      "z": 3,
      "name": "Rock_Sandstone"
    },
    {
      "x": -7,
      "y": 27,
      "z": 3,
      "name": "Rock_Sandstone"
    },
    {
      "x": -7,
      "y": 28,
      "z": 3,
      "name": "Rock_Sandstone"
    },
    {
      "x": -7,
      "y": 29,
      "z": 3,
      "name": "Rock_Sandstone"
    },
    {
      "x": -7,
      "y": 30,
      "z": 3,
      "name": "Rock_Sandstone"
    },
    {
      "x": -7,
      "y": 19,
      "z": 4,
      "name": "Rock_Sandstone_White"
    },
    {
      "x": -7,
      "y": 20,
      "z": 4,
      "name": "Rock_Sandstone_White"
    },
    {
      "x": -7,
      "y": 21,
      "z": 4,
      "name": "Rock_Sandstone_White"
    },
    {
      "x": -7,
      "y": 22,
      "z": 4,
      "name": "Soil_Dirt_Dry"
    },
    {
      "x": -7,
      "y": 23,
      "z": 4,
      "name": "Soil_Clay"
    },
    {
      "x": -7,
      "y": 24,
      "z": 4,
      "name": "Rock_Sandstone"
    },
    {
      "x": -7,
      "y": 25,
      "z": 4,
      "name": "Rock_Sandstone"
    },
    {
      "x": -7,
      "y": 26,
      "z": 4,
      "name": "Rock_Sandstone"
    },
    {
      "x": -7,
      "y": 27,
      "z": 4,
      "name": "Rock_Sandstone"
    },
    {
      "x": -7,
      "y": 28,
      "z": 4,
      "name": "Rock_Sandstone"
    },
    {
      "x": -7,
      "y": 2,
      "z": 5,
      "name": "Rock_Sandstone"
    },
    {
      "x": -7,
      "y": 3,
      "z": 5,
      "name": "Rock_Sandstone"
    },
    {
      "x": -7,
      "y": 4,
      "z": 5,
      "name": "Rock_Sandstone"
    },
    {
      "x": -7,
      "y": 5,
      "z": 5,
      "name": "Rock_Sandstone"
    },
    {
      "x": -7,
      "y": 19,
      "z": 5,
      "name": "Rock_Sandstone_White"
    },
    {
      "x": -7,
      "y": 20,
      "z": 5,
      "name": "Rock_Sandstone_White"
    },
    {
      "x": -7,
      "y": 21,
      "z": 5,
      "name": "Rock_Sandstone"
    },
    {
      "x": -7,
      "y": 22,
      "z": 5,
      "name": "Soil_Dirt_Dry"
    },
    {
      "x": -7,
      "y": 23,
      "z": 5,
      "name": "Soil_Clay"
    },
    {
      "x": -7,
      "y": 24,
      "z": 5,
      "name": "Rock_Sandstone"
    },
    {
      "x": -7,
      "y": 25,
      "z": 5,
      "name": "Rock_Sandstone"
    },
    {
      "x": -7,
      "y": 26,
      "z": 5,
      "name": "Rock_Sandstone"
    },
    {
      "x": -7,
      "y": 27,
      "z": 5,
      "name": "Rock_Sandstone"
    },
    {
      "x": -7,
      "y": 28,
      "z": 5,
      "name": "Rock_Sandstone"
    },
    {
      "x": -7,
      "y": 1,
      "z": 6,
      "name": "Rock_Sandstone"
    },
    {
      "x": -7,
      "y": 2,
      "z": 6,
      "name": "Rock_Sandstone"
    },
    {
      "x": -7,
      "y": 3,
      "z": 6,
      "name": "Rock_Sandstone"
    },
    {
      "x": -7,
      "y": 4,
      "z": 6,
      "name": "Rock_Sandstone"
    },
    {
      "x": -7,
      "y": 5,
      "z": 6,
      "name": "Rock_Sandstone"
    },
    {
      "x": -7,
      "y": 16,
      "z": 6,
      "name": "Rock_Sandstone"
    },
    {
      "x": -7,
      "y": 17,
      "z": 6,
      "name": "Rock_Sandstone"
    },
    {
      "x": -7,
      "y": 18,
      "z": 6,
      "name": "Rock_Sandstone_White"
    },
    {
      "x": -7,
      "y": 19,
      "z": 6,
      "name": "Rock_Sandstone_White"
    },
    {
      "x": -7,
      "y": 20,
      "z": 6,
      "name": "Rock_Sandstone_White"
    },
    {
      "x": -7,
      "y": 21,
      "z": 6,
      "name": "Soil_Dirt_Dry"
    },
    {
      "x": -7,
      "y": 22,
      "z": 6,
      "name": "Soil_Dirt_Dry"
    },
    {
      "x": -7,
      "y": 23,
      "z": 6,
      "name": "Soil_Clay"
    },
    {
      "x": -7,
      "y": 24,
      "z": 6,
      "name": "Rock_Sandstone"
    },
    {
      "x": -7,
      "y": 25,
      "z": 6,
      "name": "Rock_Sandstone"
    },
    {
      "x": -7,
      "y": 26,
      "z": 6,
      "name": "Rock_Sandstone"
    },
    {
      "x": -7,
      "y": 27,
      "z": 6,
      "name": "Rock_Sandstone"
    },
    {
      "x": -7,
      "y": 28,
      "z": 6,
      "name": "Rock_Sandstone"
    },
    {
      "x": -7,
      "y": 1,
      "z": 7,
      "name": "Rock_Sandstone"
    },
    {
      "x": -7,
      "y": 2,
      "z": 7,
      "name": "Rock_Sandstone"
    },
    {
      "x": -7,
      "y": 3,
      "z": 7,
      "name": "Rock_Sandstone"
    },
    {
      "x": -7,
      "y": 4,
      "z": 7,
      "name": "Rock_Sandstone"
    },
    {
      "x": -7,
      "y": 5,
      "z": 7,
      "name": "Rock_Sandstone"
    },
    {
      "x": -7,
      "y": 6,
      "z": 7,
      "name": "Rock_Sandstone"
    },
    {
      "x": -7,
      "y": 7,
      "z": 7,
      "name": "Rock_Sandstone"
    },
    {
      "x": -7,
      "y": 8,
      "z": 7,
      "name": "Rock_Sandstone"
    },
    {
      "x": -7,
      "y": 9,
      "z": 7,
      "name": "Rock_Sandstone"
    },
    {
      "x": -7,
      "y": 10,
      "z": 7,
      "name": "Rock_Sandstone"
    },
    {
      "x": -7,
      "y": 16,
      "z": 7,
      "name": "Rock_Sandstone"
    },
    {
      "x": -7,
      "y": 17,
      "z": 7,
      "name": "Rock_Sandstone_White"
    },
    {
      "x": -7,
      "y": 18,
      "z": 7,
      "name": "Rock_Sandstone_White"
    },
    {
      "x": -7,
      "y": 19,
      "z": 7,
      "name": "Rock_Sandstone_White"
    },
    {
      "x": -7,
      "y": 20,
      "z": 7,
      "name": "Rock_Sandstone_White"
    },
    {
      "x": -7,
      "y": 21,
      "z": 7,
      "name": "Soil_Dirt_Dry"
    },
    {
      "x": -7,
      "y": 22,
      "z": 7,
      "name": "Soil_Dirt_Dry"
    },
    {
      "x": -7,
      "y": 23,
      "z": 7,
      "name": "Soil_Clay"
    },
    {
      "x": -7,
      "y": 24,
      "z": 7,
      "name": "Rock_Sandstone"
    },
    {
      "x": -7,
      "y": 25,
      "z": 7,
      "name": "Rock_Sandstone"
    },
    {
      "x": -7,
      "y": 26,
      "z": 7,
      "name": "Rock_Sandstone"
    },
    {
      "x": -7,
      "y": 27,
      "z": 7,
      "name": "Rock_Sandstone"
    },
    {
      "x": -7,
      "y": 28,
      "z": 7,
      "name": "Rock_Sandstone"
    },
    {
      "x": -7,
      "y": 1,
      "z": 8,
      "name": "Rock_Sandstone"
    },
    {
      "x": -7,
      "y": 2,
      "z": 8,
      "name": "Rock_Sandstone"
    },
    {
      "x": -7,
      "y": 3,
      "z": 8,
      "name": "Rock_Sandstone"
    },
    {
      "x": -7,
      "y": 4,
      "z": 8,
      "name": "Rock_Sandstone"
    },
    {
      "x": -7,
      "y": 5,
      "z": 8,
      "name": "Rock_Sandstone"
    },
    {
      "x": -7,
      "y": 6,
      "z": 8,
      "name": "Rock_Sandstone"
    },
    {
      "x": -7,
      "y": 7,
      "z": 8,
      "name": "Rock_Sandstone"
    },
    {
      "x": -7,
      "y": 8,
      "z": 8,
      "name": "Rock_Sandstone"
    },
    {
      "x": -7,
      "y": 9,
      "z": 8,
      "name": "Rock_Sandstone"
    },
    {
      "x": -7,
      "y": 10,
      "z": 8,
      "name": "Rock_Sandstone"
    },
    {
      "x": -7,
      "y": 11,
      "z": 8,
      "name": "Rock_Sandstone"
    },
    {
      "x": -7,
      "y": 16,
      "z": 8,
      "name": "Rock_Sandstone"
    },
    {
      "x": -7,
      "y": 17,
      "z": 8,
      "name": "Rock_Sandstone_White"
    },
    {
      "x": -7,
      "y": 18,
      "z": 8,
      "name": "Rock_Sandstone_White"
    },
    {
      "x": -7,
      "y": 19,
      "z": 8,
      "name": "Rock_Sandstone_White"
    },
    {
      "x": -7,
      "y": 20,
      "z": 8,
      "name": "Rock_Sandstone_White"
    },
    {
      "x": -7,
      "y": 21,
      "z": 8,
      "name": "Soil_Dirt_Dry"
    },
    {
      "x": -7,
      "y": 22,
      "z": 8,
      "name": "Soil_Dirt_Dry"
    },
    {
      "x": -7,
      "y": 23,
      "z": 8,
      "name": "Soil_Clay"
    },
    {
      "x": -7,
      "y": 24,
      "z": 8,
      "name": "Rock_Sandstone"
    },
    {
      "x": -7,
      "y": 25,
      "z": 8,
      "name": "Rock_Sandstone"
    },
    {
      "x": -7,
      "y": 26,
      "z": 8,
      "name": "Rock_Sandstone"
    },
    {
      "x": -7,
      "y": 27,
      "z": 8,
      "name": "Rock_Sandstone"
    },
    {
      "x": -7,
      "y": 1,
      "z": 9,
      "name": "Rock_Sandstone"
    },
    {
      "x": -7,
      "y": 2,
      "z": 9,
      "name": "Rock_Sandstone"
    },
    {
      "x": -7,
      "y": 3,
      "z": 9,
      "name": "Rock_Sandstone"
    },
    {
      "x": -7,
      "y": 4,
      "z": 9,
      "name": "Rock_Sandstone"
    },
    {
      "x": -7,
      "y": 5,
      "z": 9,
      "name": "Rock_Sandstone"
    },
    {
      "x": -7,
      "y": 6,
      "z": 9,
      "name": "Rock_Sandstone"
    },
    {
      "x": -7,
      "y": 7,
      "z": 9,
      "name": "Rock_Sandstone"
    },
    {
      "x": -7,
      "y": 8,
      "z": 9,
      "name": "Rock_Sandstone"
    },
    {
      "x": -7,
      "y": 9,
      "z": 9,
      "name": "Rock_Sandstone"
    },
    {
      "x": -7,
      "y": 10,
      "z": 9,
      "name": "Rock_Sandstone"
    },
    {
      "x": -7,
      "y": 11,
      "z": 9,
      "name": "Soil_Clay"
    },
    {
      "x": -7,
      "y": 23,
      "z": 9,
      "name": "Soil_Clay"
    },
    {
      "x": -7,
      "y": 24,
      "z": 9,
      "name": "Rock_Sandstone"
    },
    {
      "x": -7,
      "y": 25,
      "z": 9,
      "name": "Rock_Sandstone"
    },
    {
      "x": -7,
      "y": 26,
      "z": 9,
      "name": "Rock_Sandstone"
    },
    {
      "x": -7,
      "y": 27,
      "z": 9,
      "name": "Rock_Sandstone"
    },
    {
      "x": -7,
      "y": 1,
      "z": 10,
      "name": "Rock_Sandstone"
    },
    {
      "x": -7,
      "y": 2,
      "z": 10,
      "name": "Rock_Sandstone"
    },
    {
      "x": -7,
      "y": 3,
      "z": 10,
      "name": "Rock_Sandstone"
    },
    {
      "x": -7,
      "y": 4,
      "z": 10,
      "name": "Rock_Sandstone"
    },
    {
      "x": -6,
      "y": 7,
      "z": -15,
      "name": "Rock_Sandstone"
    },
    {
      "x": -6,
      "y": 8,
      "z": -15,
      "name": "Rock_Sandstone"
    },
    {
      "x": -6,
      "y": 9,
      "z": -15,
      "name": "Rock_Sandstone"
    },
    {
      "x": -6,
      "y": 10,
      "z": -15,
      "name": "Rock_Sandstone"
    },
    {
      "x": -6,
      "y": 11,
      "z": -15,
      "name": "Rock_Sandstone"
    },
    {
      "x": -6,
      "y": 12,
      "z": -15,
      "name": "Rock_Sandstone"
    },
    {
      "x": -6,
      "y": 13,
      "z": -15,
      "name": "Rock_Sandstone"
    },
    {
      "x": -6,
      "y": 14,
      "z": -15,
      "name": "Rock_Sandstone"
    },
    {
      "x": -6,
      "y": 15,
      "z": -15,
      "name": "Rock_Sandstone"
    },
    {
      "x": -6,
      "y": 16,
      "z": -15,
      "name": "Rock_Sandstone"
    },
    {
      "x": -6,
      "y": 6,
      "z": -14,
      "name": "Rock_Sandstone"
    },
    {
      "x": -6,
      "y": 7,
      "z": -14,
      "name": "Rock_Sandstone"
    },
    {
      "x": -6,
      "y": 8,
      "z": -14,
      "name": "Rock_Sandstone"
    },
    {
      "x": -6,
      "y": 9,
      "z": -14,
      "name": "Rock_Sandstone"
    },
    {
      "x": -6,
      "y": 10,
      "z": -14,
      "name": "Rock_Sandstone"
    },
    {
      "x": -6,
      "y": 11,
      "z": -14,
      "name": "Rock_Sandstone"
    },
    {
      "x": -6,
      "y": 12,
      "z": -14,
      "name": "Rock_Sandstone"
    },
    {
      "x": -6,
      "y": 13,
      "z": -14,
      "name": "Rock_Sandstone"
    },
    {
      "x": -6,
      "y": 14,
      "z": -14,
      "name": "Rock_Sandstone"
    },
    {
      "x": -6,
      "y": 15,
      "z": -14,
      "name": "Rock_Sandstone"
    },
    {
      "x": -6,
      "y": 16,
      "z": -14,
      "name": "Rock_Sandstone"
    },
    {
      "x": -6,
      "y": 17,
      "z": -14,
      "name": "Soil_Clay"
    },
    {
      "x": -6,
      "y": 18,
      "z": -14,
      "name": "Soil_Clay"
    },
    {
      "x": -6,
      "y": 19,
      "z": -14,
      "name": "Rock_Sandstone_Red"
    },
    {
      "x": -6,
      "y": 5,
      "z": -13,
      "name": "Rock_Sandstone"
    },
    {
      "x": -6,
      "y": 6,
      "z": -13,
      "name": "Rock_Sandstone"
    },
    {
      "x": -6,
      "y": 7,
      "z": -13,
      "name": "Rock_Sandstone"
    },
    {
      "x": -6,
      "y": 8,
      "z": -13,
      "name": "Rock_Sandstone"
    },
    {
      "x": -6,
      "y": 9,
      "z": -13,
      "name": "Rock_Sandstone"
    },
    {
      "x": -6,
      "y": 10,
      "z": -13,
      "name": "Rock_Sandstone"
    },
    {
      "x": -6,
      "y": 11,
      "z": -13,
      "name": "Rock_Sandstone"
    },
    {
      "x": -6,
      "y": 12,
      "z": -13,
      "name": "Rock_Sandstone"
    },
    {
      "x": -6,
      "y": 13,
      "z": -13,
      "name": "Rock_Sandstone"
    },
    {
      "x": -6,
      "y": 14,
      "z": -13,
      "name": "Rock_Sandstone"
    },
    {
      "x": -6,
      "y": 15,
      "z": -13,
      "name": "Rock_Sandstone"
    },
    {
      "x": -6,
      "y": 16,
      "z": -13,
      "name": "Rock_Sandstone"
    },
    {
      "x": -6,
      "y": 17,
      "z": -13,
      "name": "Soil_Clay"
    },
    {
      "x": -6,
      "y": 18,
      "z": -13,
      "name": "Soil_Clay"
    },
    {
      "x": -6,
      "y": 19,
      "z": -13,
      "name": "Rock_Sandstone_Red"
    },
    {
      "x": -6,
      "y": 20,
      "z": -13,
      "name": "Rock_Sandstone_Red"
    },
    {
      "x": -6,
      "y": 4,
      "z": -12,
      "name": "Rock_Sandstone"
    },
    {
      "x": -6,
      "y": 5,
      "z": -12,
      "name": "Rock_Sandstone"
    },
    {
      "x": -6,
      "y": 6,
      "z": -12,
      "name": "Rock_Sandstone"
    },
    {
      "x": -6,
      "y": 7,
      "z": -12,
      "name": "Rock_Sandstone"
    },
    {
      "x": -6,
      "y": 8,
      "z": -12,
      "name": "Rock_Sandstone"
    },
    {
      "x": -6,
      "y": 9,
      "z": -12,
      "name": "Rock_Sandstone"
    },
    {
      "x": -6,
      "y": 10,
      "z": -12,
      "name": "Rock_Sandstone"
    },
    {
      "x": -6,
      "y": 11,
      "z": -12,
      "name": "Rock_Sandstone"
    },
    {
      "x": -6,
      "y": 12,
      "z": -12,
      "name": "Rock_Sandstone"
    },
    {
      "x": -6,
      "y": 13,
      "z": -12,
      "name": "Rock_Sandstone"
    },
    {
      "x": -6,
      "y": 14,
      "z": -12,
      "name": "Rock_Sandstone"
    },
    {
      "x": -6,
      "y": 15,
      "z": -12,
      "name": "Rock_Sandstone"
    },
    {
      "x": -6,
      "y": 16,
      "z": -12,
      "name": "Soil_Clay"
    },
    {
      "x": -6,
      "y": 17,
      "z": -12,
      "name": "Soil_Clay"
    },
    {
      "x": -6,
      "y": 18,
      "z": -12,
      "name": "Soil_Clay"
    },
    {
      "x": -6,
      "y": 19,
      "z": -12,
      "name": "Rock_Sandstone_Red"
    },
    {
      "x": -6,
      "y": 20,
      "z": -12,
      "name": "Rock_Sandstone_Red"
    },
    {
      "x": -6,
      "y": 21,
      "z": -12,
      "name": "Rock_Sandstone"
    },
    {
      "x": -6,
      "y": 22,
      "z": -12,
      "name": "Rock_Sandstone_White"
    },
    {
      "x": -6,
      "y": 23,
      "z": -12,
      "name": "Rock_Sandstone_White"
    },
    {
      "x": -6,
      "y": 24,
      "z": -12,
      "name": "Rock_Sandstone_White"
    },
    {
      "x": -6,
      "y": 4,
      "z": -11,
      "name": "Rock_Sandstone"
    },
    {
      "x": -6,
      "y": 5,
      "z": -11,
      "name": "Rock_Sandstone"
    },
    {
      "x": -6,
      "y": 6,
      "z": -11,
      "name": "Rock_Sandstone"
    },
    {
      "x": -6,
      "y": 7,
      "z": -11,
      "name": "Rock_Sandstone"
    },
    {
      "x": -6,
      "y": 8,
      "z": -11,
      "name": "Rock_Sandstone"
    },
    {
      "x": -6,
      "y": 9,
      "z": -11,
      "name": "Rock_Sandstone"
    },
    {
      "x": -6,
      "y": 10,
      "z": -11,
      "name": "Rock_Sandstone"
    },
    {
      "x": -6,
      "y": 11,
      "z": -11,
      "name": "Rock_Sandstone"
    },
    {
      "x": -6,
      "y": 12,
      "z": -11,
      "name": "Rock_Sandstone"
    },
    {
      "x": -6,
      "y": 13,
      "z": -11,
      "name": "Rock_Sandstone"
    },
    {
      "x": -6,
      "y": 14,
      "z": -11,
      "name": "Rock_Sandstone"
    },
    {
      "x": -6,
      "y": 15,
      "z": -11,
      "name": "Rock_Sandstone"
    },
    {
      "x": -6,
      "y": 16,
      "z": -11,
      "name": "Soil_Clay"
    },
    {
      "x": -6,
      "y": 17,
      "z": -11,
      "name": "Soil_Clay"
    },
    {
      "x": -6,
      "y": 18,
      "z": -11,
      "name": "Soil_Clay"
    },
    {
      "x": -6,
      "y": 19,
      "z": -11,
      "name": "Soil_Clay"
    },
    {
      "x": -6,
      "y": 20,
      "z": -11,
      "name": "Rock_Sandstone_Red"
    },
    {
      "x": -6,
      "y": 21,
      "z": -11,
      "name": "Rock_Sandstone"
    },
    {
      "x": -6,
      "y": 22,
      "z": -11,
      "name": "Rock_Sandstone_White"
    },
    {
      "x": -6,
      "y": 23,
      "z": -11,
      "name": "Rock_Sandstone_White"
    },
    {
      "x": -6,
      "y": 24,
      "z": -11,
      "name": "Rock_Sandstone_White"
    },
    {
      "x": -6,
      "y": 25,
      "z": -11,
      "name": "Soil_Dirt_Dry"
    },
    {
      "x": -6,
      "y": 26,
      "z": -11,
      "name": "Soil_Clay"
    },
    {
      "x": -6,
      "y": 27,
      "z": -11,
      "name": "Soil_Clay"
    },
    {
      "x": -6,
      "y": 3,
      "z": -10,
      "name": "Rock_Sandstone"
    },
    {
      "x": -6,
      "y": 4,
      "z": -10,
      "name": "Rock_Sandstone"
    },
    {
      "x": -6,
      "y": 5,
      "z": -10,
      "name": "Rock_Sandstone"
    },
    {
      "x": -6,
      "y": 6,
      "z": -10,
      "name": "Rock_Sandstone"
    },
    {
      "x": -6,
      "y": 7,
      "z": -10,
      "name": "Rock_Sandstone"
    },
    {
      "x": -6,
      "y": 8,
      "z": -10,
      "name": "Rock_Sandstone"
    },
    {
      "x": -6,
      "y": 9,
      "z": -10,
      "name": "Rock_Sandstone"
    },
    {
      "x": -6,
      "y": 10,
      "z": -10,
      "name": "Rock_Sandstone"
    },
    {
      "x": -6,
      "y": 11,
      "z": -10,
      "name": "Rock_Sandstone"
    },
    {
      "x": -6,
      "y": 12,
      "z": -10,
      "name": "Rock_Sandstone"
    },
    {
      "x": -6,
      "y": 13,
      "z": -10,
      "name": "Rock_Sandstone"
    },
    {
      "x": -6,
      "y": 14,
      "z": -10,
      "name": "Rock_Sandstone"
    },
    {
      "x": -6,
      "y": 15,
      "z": -10,
      "name": "Soil_Clay"
    },
    {
      "x": -6,
      "y": 16,
      "z": -10,
      "name": "Soil_Clay"
    },
    {
      "x": -6,
      "y": 17,
      "z": -10,
      "name": "Soil_Clay"
    },
    {
      "x": -6,
      "y": 18,
      "z": -10,
      "name": "Soil_Clay"
    },
    {
      "x": -6,
      "y": 19,
      "z": -10,
      "name": "Rock_Sandstone"
    },
    {
      "x": -6,
      "y": 20,
      "z": -10,
      "name": "Rock_Sandstone"
    },
    {
      "x": -6,
      "y": 21,
      "z": -10,
      "name": "Rock_Sandstone_White"
    },
    {
      "x": -6,
      "y": 22,
      "z": -10,
      "name": "Rock_Sandstone_White"
    },
    {
      "x": -6,
      "y": 23,
      "z": -10,
      "name": "Rock_Sandstone_White"
    },
    {
      "x": -6,
      "y": 24,
      "z": -10,
      "name": "Rock_Sandstone_White"
    },
    {
      "x": -6,
      "y": 25,
      "z": -10,
      "name": "Soil_Dirt_Dry"
    },
    {
      "x": -6,
      "y": 26,
      "z": -10,
      "name": "Soil_Clay"
    },
    {
      "x": -6,
      "y": 27,
      "z": -10,
      "name": "Soil_Clay"
    },
    {
      "x": -6,
      "y": 28,
      "z": -10,
      "name": "Rock_Sandstone"
    },
    {
      "x": -6,
      "y": 29,
      "z": -10,
      "name": "Rock_Sandstone"
    },
    {
      "x": -6,
      "y": 2,
      "z": -9,
      "name": "Rock_Sandstone"
    },
    {
      "x": -6,
      "y": 3,
      "z": -9,
      "name": "Rock_Sandstone"
    },
    {
      "x": -6,
      "y": 4,
      "z": -9,
      "name": "Rock_Sandstone"
    },
    {
      "x": -6,
      "y": 5,
      "z": -9,
      "name": "Rock_Sandstone"
    },
    {
      "x": -6,
      "y": 6,
      "z": -9,
      "name": "Rock_Sandstone"
    },
    {
      "x": -6,
      "y": 7,
      "z": -9,
      "name": "Rock_Sandstone"
    },
    {
      "x": -6,
      "y": 8,
      "z": -9,
      "name": "Rock_Sandstone"
    },
    {
      "x": -6,
      "y": 9,
      "z": -9,
      "name": "Rock_Sandstone"
    },
    {
      "x": -6,
      "y": 10,
      "z": -9,
      "name": "Rock_Sandstone"
    },
    {
      "x": -6,
      "y": 11,
      "z": -9,
      "name": "Rock_Sandstone"
    },
    {
      "x": -6,
      "y": 12,
      "z": -9,
      "name": "Rock_Sandstone"
    },
    {
      "x": -6,
      "y": 13,
      "z": -9,
      "name": "Rock_Sandstone"
    },
    {
      "x": -6,
      "y": 14,
      "z": -9,
      "name": "Soil_Clay"
    },
    {
      "x": -6,
      "y": 15,
      "z": -9,
      "name": "Soil_Clay"
    },
    {
      "x": -6,
      "y": 16,
      "z": -9,
      "name": "Soil_Clay"
    },
    {
      "x": -6,
      "y": 17,
      "z": -9,
      "name": "Soil_Clay"
    },
    {
      "x": -6,
      "y": 18,
      "z": -9,
      "name": "Rock_Sandstone"
    },
    {
      "x": -6,
      "y": 19,
      "z": -9,
      "name": "Rock_Sandstone"
    },
    {
      "x": -6,
      "y": 20,
      "z": -9,
      "name": "Rock_Sandstone"
    },
    {
      "x": -6,
      "y": 21,
      "z": -9,
      "name": "Rock_Sandstone_White"
    },
    {
      "x": -6,
      "y": 22,
      "z": -9,
      "name": "Rock_Sandstone_White"
    },
    {
      "x": -6,
      "y": 23,
      "z": -9,
      "name": "Rock_Sandstone_White"
    },
    {
      "x": -6,
      "y": 24,
      "z": -9,
      "name": "Rock_Sandstone"
    },
    {
      "x": -6,
      "y": 25,
      "z": -9,
      "name": "Soil_Dirt_Dry"
    },
    {
      "x": -6,
      "y": 26,
      "z": -9,
      "name": "Soil_Clay"
    },
    {
      "x": -6,
      "y": 27,
      "z": -9,
      "name": "Soil_Clay"
    },
    {
      "x": -6,
      "y": 28,
      "z": -9,
      "name": "Rock_Sandstone"
    },
    {
      "x": -6,
      "y": 29,
      "z": -9,
      "name": "Rock_Sandstone"
    },
    {
      "x": -6,
      "y": 2,
      "z": -8,
      "name": "Rock_Sandstone"
    },
    {
      "x": -6,
      "y": 3,
      "z": -8,
      "name": "Rock_Sandstone"
    },
    {
      "x": -6,
      "y": 4,
      "z": -8,
      "name": "Rock_Sandstone"
    },
    {
      "x": -6,
      "y": 5,
      "z": -8,
      "name": "Rock_Sandstone"
    },
    {
      "x": -6,
      "y": 6,
      "z": -8,
      "name": "Rock_Sandstone"
    },
    {
      "x": -6,
      "y": 7,
      "z": -8,
      "name": "Rock_Sandstone"
    },
    {
      "x": -6,
      "y": 8,
      "z": -8,
      "name": "Rock_Sandstone"
    },
    {
      "x": -6,
      "y": 9,
      "z": -8,
      "name": "Rock_Sandstone"
    },
    {
      "x": -6,
      "y": 10,
      "z": -8,
      "name": "Rock_Sandstone"
    },
    {
      "x": -6,
      "y": 11,
      "z": -8,
      "name": "Rock_Sandstone"
    },
    {
      "x": -6,
      "y": 12,
      "z": -8,
      "name": "Rock_Sandstone"
    },
    {
      "x": -6,
      "y": 13,
      "z": -8,
      "name": "Rock_Sandstone"
    },
    {
      "x": -6,
      "y": 14,
      "z": -8,
      "name": "Soil_Clay"
    },
    {
      "x": -6,
      "y": 15,
      "z": -8,
      "name": "Soil_Clay"
    },
    {
      "x": -6,
      "y": 16,
      "z": -8,
      "name": "Soil_Clay"
    },
    {
      "x": -6,
      "y": 17,
      "z": -8,
      "name": "Rock_Sandstone_Red"
    },
    {
      "x": -6,
      "y": 18,
      "z": -8,
      "name": "Rock_Sandstone"
    },
    {
      "x": -6,
      "y": 19,
      "z": -8,
      "name": "Rock_Sandstone"
    },
    {
      "x": -6,
      "y": 20,
      "z": -8,
      "name": "Rock_Sandstone"
    },
    {
      "x": -6,
      "y": 21,
      "z": -8,
      "name": "Rock_Sandstone_White"
    },
    {
      "x": -6,
      "y": 22,
      "z": -8,
      "name": "Rock_Sandstone_White"
    },
    {
      "x": -6,
      "y": 23,
      "z": -8,
      "name": "Rock_Sandstone_White"
    },
    {
      "x": -6,
      "y": 24,
      "z": -8,
      "name": "Soil_Dirt_Dry"
    },
    {
      "x": -6,
      "y": 25,
      "z": -8,
      "name": "Soil_Dirt_Dry"
    },
    {
      "x": -6,
      "y": 26,
      "z": -8,
      "name": "Soil_Clay"
    },
    {
      "x": -6,
      "y": 27,
      "z": -8,
      "name": "Rock_Sandstone"
    },
    {
      "x": -6,
      "y": 28,
      "z": -8,
      "name": "Rock_Sandstone"
    },
    {
      "x": -6,
      "y": 29,
      "z": -8,
      "name": "Rock_Sandstone"
    },
    {
      "x": -6,
      "y": 3,
      "z": -7,
      "name": "Rock_Sandstone"
    },
    {
      "x": -6,
      "y": 4,
      "z": -7,
      "name": "Rock_Sandstone"
    },
    {
      "x": -6,
      "y": 5,
      "z": -7,
      "name": "Rock_Sandstone"
    },
    {
      "x": -6,
      "y": 6,
      "z": -7,
      "name": "Rock_Sandstone"
    },
    {
      "x": -6,
      "y": 7,
      "z": -7,
      "name": "Rock_Sandstone"
    },
    {
      "x": -6,
      "y": 8,
      "z": -7,
      "name": "Rock_Sandstone"
    },
    {
      "x": -6,
      "y": 9,
      "z": -7,
      "name": "Rock_Sandstone"
    },
    {
      "x": -6,
      "y": 10,
      "z": -7,
      "name": "Rock_Sandstone"
    },
    {
      "x": -6,
      "y": 11,
      "z": -7,
      "name": "Rock_Sandstone"
    },
    {
      "x": -6,
      "y": 12,
      "z": -7,
      "name": "Rock_Sandstone"
    },
    {
      "x": -6,
      "y": 13,
      "z": -7,
      "name": "Rock_Sandstone"
    },
    {
      "x": -6,
      "y": 14,
      "z": -7,
      "name": "Soil_Clay"
    },
    {
      "x": -6,
      "y": 15,
      "z": -7,
      "name": "Soil_Clay"
    },
    {
      "x": -6,
      "y": 16,
      "z": -7,
      "name": "Rock_Sandstone_Red"
    },
    {
      "x": -6,
      "y": 17,
      "z": -7,
      "name": "Rock_Sandstone_Red"
    },
    {
      "x": -6,
      "y": 18,
      "z": -7,
      "name": "Rock_Sandstone"
    },
    {
      "x": -6,
      "y": 19,
      "z": -7,
      "name": "Rock_Sandstone"
    },
    {
      "x": -6,
      "y": 20,
      "z": -7,
      "name": "Rock_Sandstone_White"
    },
    {
      "x": -6,
      "y": 21,
      "z": -7,
      "name": "Rock_Sandstone_White"
    },
    {
      "x": -6,
      "y": 22,
      "z": -7,
      "name": "Rock_Sandstone_White"
    },
    {
      "x": -6,
      "y": 23,
      "z": -7,
      "name": "Rock_Sandstone"
    },
    {
      "x": -6,
      "y": 24,
      "z": -7,
      "name": "Soil_Dirt_Dry"
    },
    {
      "x": -6,
      "y": 25,
      "z": -7,
      "name": "Soil_Dirt_Dry"
    },
    {
      "x": -6,
      "y": 26,
      "z": -7,
      "name": "Soil_Clay"
    },
    {
      "x": -6,
      "y": 27,
      "z": -7,
      "name": "Rock_Sandstone"
    },
    {
      "x": -6,
      "y": 28,
      "z": -7,
      "name": "Rock_Sandstone"
    },
    {
      "x": -6,
      "y": 29,
      "z": -7,
      "name": "Rock_Sandstone"
    },
    {
      "x": -6,
      "y": 3,
      "z": -6,
      "name": "Rock_Sandstone"
    },
    {
      "x": -6,
      "y": 4,
      "z": -6,
      "name": "Rock_Sandstone"
    },
    {
      "x": -6,
      "y": 5,
      "z": -6,
      "name": "Rock_Sandstone"
    },
    {
      "x": -6,
      "y": 6,
      "z": -6,
      "name": "Rock_Sandstone"
    },
    {
      "x": -6,
      "y": 7,
      "z": -6,
      "name": "Rock_Sandstone"
    },
    {
      "x": -6,
      "y": 8,
      "z": -6,
      "name": "Rock_Sandstone"
    },
    {
      "x": -6,
      "y": 9,
      "z": -6,
      "name": "Rock_Sandstone"
    },
    {
      "x": -6,
      "y": 10,
      "z": -6,
      "name": "Rock_Sandstone"
    },
    {
      "x": -6,
      "y": 11,
      "z": -6,
      "name": "Rock_Sandstone"
    },
    {
      "x": -6,
      "y": 12,
      "z": -6,
      "name": "Rock_Sandstone"
    },
    {
      "x": -6,
      "y": 13,
      "z": -6,
      "name": "Rock_Sandstone"
    },
    {
      "x": -6,
      "y": 14,
      "z": -6,
      "name": "Soil_Clay"
    },
    {
      "x": -6,
      "y": 15,
      "z": -6,
      "name": "Soil_Clay"
    },
    {
      "x": -6,
      "y": 16,
      "z": -6,
      "name": "Rock_Sandstone_Red"
    },
    {
      "x": -6,
      "y": 17,
      "z": -6,
      "name": "Rock_Sandstone_Red"
    },
    {
      "x": -6,
      "y": 18,
      "z": -6,
      "name": "Rock_Sandstone"
    },
    {
      "x": -6,
      "y": 19,
      "z": -6,
      "name": "Rock_Sandstone"
    },
    {
      "x": -6,
      "y": 20,
      "z": -6,
      "name": "Rock_Sandstone_White"
    },
    {
      "x": -6,
      "y": 21,
      "z": -6,
      "name": "Rock_Sandstone_White"
    },
    {
      "x": -6,
      "y": 22,
      "z": -6,
      "name": "Rock_Sandstone_White"
    },
    {
      "x": -6,
      "y": 23,
      "z": -6,
      "name": "Rock_Sandstone"
    },
    {
      "x": -6,
      "y": 24,
      "z": -6,
      "name": "Soil_Dirt_Dry"
    },
    {
      "x": -6,
      "y": 25,
      "z": -6,
      "name": "Soil_Clay"
    },
    {
      "x": -6,
      "y": 26,
      "z": -6,
      "name": "Soil_Clay"
    },
    {
      "x": -6,
      "y": 27,
      "z": -6,
      "name": "Rock_Sandstone"
    },
    {
      "x": -6,
      "y": 28,
      "z": -6,
      "name": "Rock_Sandstone"
    },
    {
      "x": -6,
      "y": 29,
      "z": -6,
      "name": "Rock_Sandstone"
    },
    {
      "x": -6,
      "y": 3,
      "z": -5,
      "name": "Rock_Sandstone"
    },
    {
      "x": -6,
      "y": 4,
      "z": -5,
      "name": "Rock_Sandstone"
    },
    {
      "x": -6,
      "y": 5,
      "z": -5,
      "name": "Rock_Sandstone"
    },
    {
      "x": -6,
      "y": 6,
      "z": -5,
      "name": "Rock_Sandstone"
    },
    {
      "x": -6,
      "y": 7,
      "z": -5,
      "name": "Rock_Sandstone"
    },
    {
      "x": -6,
      "y": 8,
      "z": -5,
      "name": "Rock_Sandstone"
    },
    {
      "x": -6,
      "y": 9,
      "z": -5,
      "name": "Rock_Sandstone"
    },
    {
      "x": -6,
      "y": 10,
      "z": -5,
      "name": "Rock_Sandstone"
    },
    {
      "x": -6,
      "y": 11,
      "z": -5,
      "name": "Rock_Sandstone"
    },
    {
      "x": -6,
      "y": 12,
      "z": -5,
      "name": "Rock_Sandstone"
    },
    {
      "x": -6,
      "y": 13,
      "z": -5,
      "name": "Rock_Sandstone"
    },
    {
      "x": -6,
      "y": 14,
      "z": -5,
      "name": "Soil_Clay"
    },
    {
      "x": -6,
      "y": 15,
      "z": -5,
      "name": "Soil_Clay"
    },
    {
      "x": -6,
      "y": 16,
      "z": -5,
      "name": "Rock_Sandstone_Red"
    },
    {
      "x": -6,
      "y": 17,
      "z": -5,
      "name": "Rock_Sandstone"
    },
    {
      "x": -6,
      "y": 18,
      "z": -5,
      "name": "Rock_Sandstone"
    },
    {
      "x": -6,
      "y": 19,
      "z": -5,
      "name": "Rock_Sandstone"
    },
    {
      "x": -6,
      "y": 20,
      "z": -5,
      "name": "Rock_Sandstone_White"
    },
    {
      "x": -6,
      "y": 21,
      "z": -5,
      "name": "Rock_Sandstone_White"
    },
    {
      "x": -6,
      "y": 22,
      "z": -5,
      "name": "Rock_Sandstone_White"
    },
    {
      "x": -6,
      "y": 23,
      "z": -5,
      "name": "Rock_Sandstone"
    },
    {
      "x": -6,
      "y": 24,
      "z": -5,
      "name": "Rock_Sandstone"
    },
    {
      "x": -6,
      "y": 25,
      "z": -5,
      "name": "Soil_Clay"
    },
    {
      "x": -6,
      "y": 26,
      "z": -5,
      "name": "Rock_Sandstone"
    },
    {
      "x": -6,
      "y": 27,
      "z": -5,
      "name": "Rock_Sandstone"
    },
    {
      "x": -6,
      "y": 28,
      "z": -5,
      "name": "Rock_Sandstone"
    },
    {
      "x": -6,
      "y": 29,
      "z": -5,
      "name": "Rock_Sandstone"
    },
    {
      "x": -6,
      "y": 20,
      "z": -4,
      "name": "Rock_Sandstone_White"
    },
    {
      "x": -6,
      "y": 21,
      "z": -4,
      "name": "Rock_Sandstone_White"
    },
    {
      "x": -6,
      "y": 22,
      "z": -4,
      "name": "Rock_Sandstone_White"
    },
    {
      "x": -6,
      "y": 23,
      "z": -4,
      "name": "Soil_Dirt_Dry"
    },
    {
      "x": -6,
      "y": 24,
      "z": -4,
      "name": "Rock_Sandstone"
    },
    {
      "x": -6,
      "y": 25,
      "z": -4,
      "name": "Soil_Clay"
    },
    {
      "x": -6,
      "y": 26,
      "z": -4,
      "name": "Rock_Sandstone"
    },
    {
      "x": -6,
      "y": 27,
      "z": -4,
      "name": "Rock_Sandstone"
    },
    {
      "x": -6,
      "y": 28,
      "z": -4,
      "name": "Rock_Sandstone"
    },
    {
      "x": -6,
      "y": 29,
      "z": -4,
      "name": "Rock_Sandstone"
    },
    {
      "x": -6,
      "y": 30,
      "z": -4,
      "name": "Rock_Sandstone"
    },
    {
      "x": -6,
      "y": 20,
      "z": -3,
      "name": "Rock_Sandstone_White"
    },
    {
      "x": -6,
      "y": 21,
      "z": -3,
      "name": "Rock_Sandstone_White"
    },
    {
      "x": -6,
      "y": 22,
      "z": -3,
      "name": "Rock_Sandstone_White"
    },
    {
      "x": -6,
      "y": 23,
      "z": -3,
      "name": "Soil_Dirt_Dry"
    },
    {
      "x": -6,
      "y": 24,
      "z": -3,
      "name": "Soil_Clay"
    },
    {
      "x": -6,
      "y": 25,
      "z": -3,
      "name": "Soil_Clay"
    },
    {
      "x": -6,
      "y": 26,
      "z": -3,
      "name": "Rock_Sandstone"
    },
    {
      "x": -6,
      "y": 27,
      "z": -3,
      "name": "Rock_Sandstone"
    },
    {
      "x": -6,
      "y": 28,
      "z": -3,
      "name": "Rock_Sandstone"
    },
    {
      "x": -6,
      "y": 29,
      "z": -3,
      "name": "Rock_Sandstone"
    },
    {
      "x": -6,
      "y": 30,
      "z": -3,
      "name": "Rock_Sandstone"
    },
    {
      "x": -6,
      "y": 20,
      "z": -2,
      "name": "Rock_Sandstone_White"
    },
    {
      "x": -6,
      "y": 21,
      "z": -2,
      "name": "Rock_Sandstone_White"
    },
    {
      "x": -6,
      "y": 22,
      "z": -2,
      "name": "Rock_Sandstone_White"
    },
    {
      "x": -6,
      "y": 23,
      "z": -2,
      "name": "Soil_Dirt_Dry"
    },
    {
      "x": -6,
      "y": 24,
      "z": -2,
      "name": "Soil_Clay"
    },
    {
      "x": -6,
      "y": 25,
      "z": -2,
      "name": "Soil_Clay"
    },
    {
      "x": -6,
      "y": 26,
      "z": -2,
      "name": "Rock_Sandstone"
    },
    {
      "x": -6,
      "y": 27,
      "z": -2,
      "name": "Rock_Sandstone"
    },
    {
      "x": -6,
      "y": 28,
      "z": -2,
      "name": "Rock_Sandstone"
    },
    {
      "x": -6,
      "y": 29,
      "z": -2,
      "name": "Rock_Sandstone"
    },
    {
      "x": -6,
      "y": 30,
      "z": -2,
      "name": "Rock_Sandstone"
    },
    {
      "x": -6,
      "y": 20,
      "z": -1,
      "name": "Rock_Sandstone_White"
    },
    {
      "x": -6,
      "y": 21,
      "z": -1,
      "name": "Rock_Sandstone_White"
    },
    {
      "x": -6,
      "y": 22,
      "z": -1,
      "name": "Soil_Dirt_Dry"
    },
    {
      "x": -6,
      "y": 23,
      "z": -1,
      "name": "Soil_Clay"
    },
    {
      "x": -6,
      "y": 24,
      "z": -1,
      "name": "Soil_Clay"
    },
    {
      "x": -6,
      "y": 25,
      "z": -1,
      "name": "Rock_Sandstone"
    },
    {
      "x": -6,
      "y": 26,
      "z": -1,
      "name": "Rock_Sandstone"
    },
    {
      "x": -6,
      "y": 27,
      "z": -1,
      "name": "Rock_Sandstone"
    },
    {
      "x": -6,
      "y": 28,
      "z": -1,
      "name": "Rock_Sandstone"
    },
    {
      "x": -6,
      "y": 29,
      "z": -1,
      "name": "Rock_Sandstone"
    },
    {
      "x": -6,
      "y": 30,
      "z": -1,
      "name": "Rock_Sandstone"
    },
    {
      "x": -6,
      "y": 20,
      "z": 0,
      "name": "Rock_Sandstone_White"
    },
    {
      "x": -6,
      "y": 21,
      "z": 0,
      "name": "Rock_Sandstone_White"
    },
    {
      "x": -6,
      "y": 22,
      "z": 0,
      "name": "Soil_Dirt_Dry"
    },
    {
      "x": -6,
      "y": 23,
      "z": 0,
      "name": "Soil_Clay"
    },
    {
      "x": -6,
      "y": 24,
      "z": 0,
      "name": "Soil_Clay"
    },
    {
      "x": -6,
      "y": 25,
      "z": 0,
      "name": "Rock_Sandstone"
    },
    {
      "x": -6,
      "y": 26,
      "z": 0,
      "name": "Rock_Sandstone"
    },
    {
      "x": -6,
      "y": 27,
      "z": 0,
      "name": "Rock_Sandstone"
    },
    {
      "x": -6,
      "y": 28,
      "z": 0,
      "name": "Rock_Sandstone"
    },
    {
      "x": -6,
      "y": 29,
      "z": 0,
      "name": "Rock_Sandstone"
    },
    {
      "x": -6,
      "y": 30,
      "z": 0,
      "name": "Rock_Sandstone"
    },
    {
      "x": -6,
      "y": 19,
      "z": 1,
      "name": "Rock_Sandstone_White"
    },
    {
      "x": -6,
      "y": 20,
      "z": 1,
      "name": "Rock_Sandstone_White"
    },
    {
      "x": -6,
      "y": 21,
      "z": 1,
      "name": "Rock_Sandstone_White"
    },
    {
      "x": -6,
      "y": 22,
      "z": 1,
      "name": "Soil_Dirt_Dry"
    },
    {
      "x": -6,
      "y": 23,
      "z": 1,
      "name": "Soil_Clay"
    },
    {
      "x": -6,
      "y": 24,
      "z": 1,
      "name": "Soil_Clay"
    },
    {
      "x": -6,
      "y": 25,
      "z": 1,
      "name": "Rock_Sandstone"
    },
    {
      "x": -6,
      "y": 26,
      "z": 1,
      "name": "Rock_Sandstone"
    },
    {
      "x": -6,
      "y": 27,
      "z": 1,
      "name": "Rock_Sandstone"
    },
    {
      "x": -6,
      "y": 28,
      "z": 1,
      "name": "Rock_Sandstone"
    },
    {
      "x": -6,
      "y": 29,
      "z": 1,
      "name": "Rock_Sandstone"
    },
    {
      "x": -6,
      "y": 30,
      "z": 1,
      "name": "Rock_Sandstone"
    },
    {
      "x": -6,
      "y": 19,
      "z": 2,
      "name": "Rock_Sandstone_White"
    },
    {
      "x": -6,
      "y": 20,
      "z": 2,
      "name": "Rock_Sandstone_White"
    },
    {
      "x": -6,
      "y": 21,
      "z": 2,
      "name": "Rock_Sandstone_White"
    },
    {
      "x": -6,
      "y": 22,
      "z": 2,
      "name": "Soil_Dirt_Dry"
    },
    {
      "x": -6,
      "y": 23,
      "z": 2,
      "name": "Soil_Clay"
    },
    {
      "x": -6,
      "y": 24,
      "z": 2,
      "name": "Soil_Clay"
    },
    {
      "x": -6,
      "y": 25,
      "z": 2,
      "name": "Rock_Sandstone"
    },
    {
      "x": -6,
      "y": 26,
      "z": 2,
      "name": "Rock_Sandstone"
    },
    {
      "x": -6,
      "y": 27,
      "z": 2,
      "name": "Rock_Sandstone"
    },
    {
      "x": -6,
      "y": 28,
      "z": 2,
      "name": "Rock_Sandstone"
    },
    {
      "x": -6,
      "y": 29,
      "z": 2,
      "name": "Rock_Sandstone"
    },
    {
      "x": -6,
      "y": 30,
      "z": 2,
      "name": "Rock_Sandstone"
    },
    {
      "x": -6,
      "y": 19,
      "z": 3,
      "name": "Rock_Sandstone_White"
    },
    {
      "x": -6,
      "y": 20,
