{
  "version": 8,
  "blockIdVersion": 8,
  "anchorX": 0,
  "anchorY": 0,
  "anchorZ": 0,
  "blocks": [
    {
      "x": -11,
      "y": -2,
      "z": -25,
      "name": "Rock_Stone"
    },
    {
      "x": -11,
      "y": -1,
      "z": -25,
      "name": "Rock_Stone"
    },
    {
      "x": -11,
      "y": -3,
      "z": -24,
      "name": "Rock_Stone"
    },
    {
      "x": -11,
      "y": -2,
      "z": -24,
      "name": "Rock_Stone"
    },
    {
      "x": -11,
      "y": -1,
      "z": -24,
      "name": "Rock_Stone"
    },
    {
      "x": -11,
      "y": 0,
      "z": -24,
      "name": "Rock_Stone"
    },
    {
      "x": -11,
      "y": 1,
      "z": -24,
      "name": "Empty"
    },
    {
      "x": -11,
      "y": -3,
      "z": -23,
      "name": "Rock_Stone"
    },
    {
      "x": -11,
      "y": -2,
      "z": -23,
      "name": "Rock_Stone"
    },
    {
      "x": -11,
      "y": -1,
      "z": -23,
      "name": "Rock_Stone"
    },
    {
      "x": -11,
      "y": 0,
      "z": -23,
      "name": "Empty"
    },
    {
      "x": -11,
      "y": 1,
      "z": -23,
      "name": "Empty"
    },
    {
      "x": -11,
      "y": 2,
      "z": -23,
      "name": "Empty"
    },
    {
      "x": -11,
      "y": 3,
      "z": -23,
      "name": "Empty"
    },
    {
      "x": -11,
      "y": -3,
      "z": -22,
      "name": "Rock_Stone"
    },
    {
      "x": -11,
      "y": -2,
      "z": -22,
      "name": "Rock_Stone"
    },
    {
      "x": -11,
      "y": -1,
      "z": -22,
      "name": "Rock_Stone_Cobble"
    },
    {
      "x": -11,
      "y": 0,
      "z": -22,
      "name": "Empty"
    },
    {
      "x": -11,
      "y": 1,
      "z": -22,
      "name": "Empty"
    },
    {
      "x": -11,
      "y": 2,
      "z": -22,
      "name": "Empty"
    },
    {
      "x": -11,
      "y": 3,
      "z": -22,
      "name": "Empty"
    },
    {
      "x": -11,
      "y": 4,
      "z": -22,
      "name": "Empty"
    },
    {
      "x": -11,
      "y": -3,
      "z": -21,
      "name": "Rock_Stone"
    },
    {
      "x": -11,
      "y": -2,
      "z": -21,
      "name": "Rock_Stone"
    },
    {
      "x": -11,
      "y": -1,
      "z": -21,
      "name": "Rock_Stone_Cobble"
    },
    {
      "x": -11,
      "y": 0,
      "z": -21,
      "name": "Empty"
    },
    {
      "x": -11,
      "y": 1,
      "z": -21,
      "name": "Empty"
    },
    {
      "x": -11,
      "y": -2,
      "z": -20,
      "name": "Rock_Stone"
    },
    {
      "x": -11,
      "y": -1,
      "z": -20,
      "name": "Rock_Stone"
    },
    {
      "x": -10,
      "y": -2,
      "z": -28,
      "name": "Rock_Stone"
    },
    {
      "x": -10,
      "y": -1,
      "z": -28,
      "name": "Rock_Stone"
    },
    {
      "x": -10,
      "y": -3,
      "z": -27,
      "name": "Rock_Stone"
    },
    {
      "x": -10,
      "y": -2,
      "z": -27,
      "name": "Rock_Stone"
    },
    {
      "x": -10,
      "y": -1,
      "z": -27,
      "name": "Rock_Stone"
    },
    {
      "x": -10,
      "y": 0,
      "z": -27,
      "name": "Rock_Stone"
    },
    {
      "x": -10,
      "y": -3,
      "z": -26,
      "name": "Rock_Stone"
    },
    {
      "x": -10,
      "y": -2,
      "z": -26,
      "name": "Rock_Stone"
    },
    {
      "x": -10,
      "y": -1,
      "z": -26,
      "name": "Rock_Stone"
    },
    {
      "x": -10,
      "y": 0,
      "z": -26,
      "name": "Rock_Stone"
    },
    {
      "x": -10,
      "y": -4,
      "z": -25,
      "name": "Rock_Stone"
    },
    {
      "x": -10,
      "y": -3,
      "z": -25,
      "name": "Rock_Stone"
    },
    {
      "x": -10,
      "y": -2,
      "z": -25,
      "name": "Rock_Stone"
    },
    {
      "x": -10,
      "y": -1,
      "z": -25,
      "name": "Rock_Stone"
    },
    {
      "x": -10,
      "y": 0,
      "z": -25,
      "name": "Rock_Stone"
    },
    {
      "x": -10,
      "y": -4,
      "z": -24,
      "name": "Rock_Stone"
    },
    {
      "x": -10,
      "y": -3,
      "z": -24,
      "name": "Rock_Stone"
    },
    {
      "x": -10,
      "y": -2,
      "z": -24,
      "name": "Rock_Stone"
    },
    {
      "x": -10,
      "y": -1,
      "z": -24,
      "name": "Rock_Stone"
    },
    {
      "x": -10,
      "y": 0,
      "z": -24,
      "name": "Empty"
    },
    {
      "x": -10,
      "y": 1,
      "z": -24,
      "name": "Empty"
    },
    {
      "x": -10,
      "y": 2,
      "z": -24,
      "name": "Empty"
    },
    {
      "x": -10,
      "y": -4,
      "z": -23,
      "name": "Rock_Stone"
    },
    {
      "x": -10,
      "y": -3,
      "z": -23,
      "name": "Rock_Stone"
    },
    {
      "x": -10,
      "y": -2,
      "z": -23,
      "name": "Rock_Stone"
    },
    {
      "x": -10,
      "y": -1,
      "z": -23,
      "name": "Rock_Stone"
    },
    {
      "x": -10,
      "y": 0,
      "z": -23,
      "name": "Rock_Stone_Stalactite_Small"
    },
    {
      "x": -10,
      "y": 1,
      "z": -23,
      "name": "Empty"
    },
    {
      "x": -10,
      "y": 2,
      "z": -23,
      "name": "Empty"
    },
    {
      "x": -10,
      "y": 3,
      "z": -23,
      "name": "Rock_Stone_Stalactite_Large",
      "filler": 31744,
      "rotation": 8
    },
    {
      "x": -10,
      "y": 4,
      "z": -23,
      "name": "Rock_Stone_Stalactite_Large",
      "rotation": 8
    },
    {
      "x": -10,
      "y": -4,
      "z": -22,
      "name": "Rock_Stone"
    },
    {
      "x": -10,
      "y": -3,
      "z": -22,
      "name": "Rock_Stone"
    },
    {
      "x": -10,
      "y": -2,
      "z": -22,
      "name": "Rock_Stone"
    },
    {
      "x": -10,
      "y": -1,
      "z": -22,
      "name": "Rock_Stone_Cobble"
    },
    {
      "x": -10,
      "y": 0,
      "z": -22,
      "name": "Empty"
    },
    {
      "x": -10,
      "y": 1,
      "z": -22,
      "name": "Empty"
    },
    {
      "x": -10,
      "y": 2,
      "z": -22,
      "name": "Empty"
    },
    {
      "x": -10,
      "y": 3,
      "z": -22,
      "name": "Empty"
    },
    {
      "x": -10,
      "y": 4,
      "z": -22,
      "name": "Empty"
    },
    {
      "x": -10,
      "y": 5,
      "z": -22,
      "name": "Empty"
    },
    {
      "x": -10,
      "y": 6,
      "z": -22,
      "name": "Empty"
    },
    {
      "x": -10,
      "y": -4,
      "z": -21,
      "name": "Rock_Stone"
    },
    {
      "x": -10,
      "y": -3,
      "z": -21,
      "name": "Rock_Stone"
    },
    {
      "x": -10,
      "y": -2,
      "z": -21,
      "name": "Rock_Stone"
    },
    {
      "x": -10,
      "y": -1,
      "z": -21,
      "name": "Rock_Stone_Cobble"
    },
    {
      "x": -10,
      "y": 0,
      "z": -21,
      "name": "Empty"
    },
    {
      "x": -10,
      "y": 1,
      "z": -21,
      "name": "Empty"
    },
    {
      "x": -10,
      "y": 2,
      "z": -21,
      "name": "Empty"
    },
    {
      "x": -10,
      "y": 3,
      "z": -21,
      "name": "Empty"
    },
    {
      "x": -10,
      "y": 4,
      "z": -21,
      "name": "Empty"
    },
    {
      "x": -10,
      "y": -4,
      "z": -20,
      "name": "Rock_Stone"
    },
    {
      "x": -10,
      "y": -3,
      "z": -20,
      "name": "Rock_Stone"
    },
    {
      "x": -10,
      "y": -2,
      "z": -20,
      "name": "Rock_Stone"
    },
    {
      "x": -10,
      "y": -1,
      "z": -20,
      "name": "Rock_Stone"
    },
    {
      "x": -10,
      "y": 0,
      "z": -20,
      "name": "Empty"
    },
    {
      "x": -10,
      "y": 1,
      "z": -20,
      "name": "Empty"
    },
    {
      "x": -10,
      "y": -4,
      "z": -19,
      "name": "Rock_Stone"
    },
    {
      "x": -10,
      "y": -3,
      "z": -19,
      "name": "Rock_Stone"
    },
    {
      "x": -10,
      "y": -2,
      "z": -19,
      "name": "Rock_Stone"
    },
    {
      "x": -10,
      "y": -1,
      "z": -19,
      "name": "Rock_Stone"
    },
    {
      "x": -10,
      "y": -3,
      "z": -18,
      "name": "Rock_Stone"
    },
    {
      "x": -10,
      "y": -2,
      "z": -18,
      "name": "Rock_Stone"
    },
    {
      "x": -10,
      "y": -1,
      "z": -18,
      "name": "Rock_Stone"
    },
    {
      "x": -10,
      "y": -3,
      "z": -17,
      "name": "Rock_Stone"
    },
    {
      "x": -10,
      "y": -2,
      "z": -17,
      "name": "Rock_Stone"
    },
    {
      "x": -10,
      "y": -1,
      "z": -17,
      "name": "Rock_Stone"
    },
    {
      "x": -10,
      "y": -3,
      "z": -16,
      "name": "Rock_Stone"
    },
    {
      "x": -10,
      "y": -2,
      "z": -16,
      "name": "Rock_Stone"
    },
    {
      "x": -10,
      "y": -1,
      "z": -16,
      "name": "Rock_Stone"
    },
    {
      "x": -9,
      "y": -3,
      "z": -30,
      "name": "Rock_Stone"
    },
    {
      "x": -9,
      "y": -2,
      "z": -30,
      "name": "Rock_Stone"
    },
    {
      "x": -9,
      "y": -4,
      "z": -29,
      "name": "Rock_Stone"
    },
    {
      "x": -9,
      "y": -3,
      "z": -29,
      "name": "Rock_Stone"
    },
    {
      "x": -9,
      "y": -2,
      "z": -29,
      "name": "Rock_Stone"
    },
    {
      "x": -9,
      "y": -1,
      "z": -29,
      "name": "Rock_Stone"
    },
    {
      "x": -9,
      "y": -4,
      "z": -28,
      "name": "Rock_Stone"
    },
    {
      "x": -9,
      "y": -3,
      "z": -28,
      "name": "Rock_Stone"
    },
    {
      "x": -9,
      "y": -2,
      "z": -28,
      "name": "Rock_Stone"
    },
    {
      "x": -9,
      "y": -1,
      "z": -28,
      "name": "Rock_Stone"
    },
    {
      "x": -9,
      "y": 0,
      "z": -28,
      "name": "Rock_Stone"
    },
    {
      "x": -9,
      "y": -4,
      "z": -27,
      "name": "Rock_Stone"
    },
    {
      "x": -9,
      "y": -3,
      "z": -27,
      "name": "Rock_Stone"
    },
    {
      "x": -9,
      "y": -2,
      "z": -27,
      "name": "Rock_Stone"
    },
    {
      "x": -9,
      "y": -1,
      "z": -27,
      "name": "Rock_Stone"
    },
    {
      "x": -9,
      "y": 0,
      "z": -27,
      "name": "Rock_Stone"
    },
    {
      "x": -9,
      "y": 1,
      "z": -27,
      "name": "Rock_Stone"
    },
    {
      "x": -9,
      "y": -4,
      "z": -26,
      "name": "Rock_Stone"
    },
    {
      "x": -9,
      "y": -3,
      "z": -26,
      "name": "Rock_Stone"
    },
    {
      "x": -9,
      "y": -2,
      "z": -26,
      "name": "Rock_Stone"
    },
    {
      "x": -9,
      "y": -1,
      "z": -26,
      "name": "Rock_Stone"
    },
    {
      "x": -9,
      "y": 0,
      "z": -26,
      "name": "Plant_Moss_Block_Blue"
    },
    {
      "x": -9,
      "y": 1,
      "z": -26,
      "name": "Empty"
    },
    {
      "x": -9,
      "y": 2,
      "z": -26,
      "name": "Empty"
    },
    {
      "x": -9,
      "y": 3,
      "z": -26,
      "name": "Empty"
    },
    {
      "x": -9,
      "y": 11,
      "z": -26,
      "name": "Plant_Moss_Rug_Blue"
    },
    {
      "x": -9,
      "y": -4,
      "z": -25,
      "name": "Rock_Stone"
    },
    {
      "x": -9,
      "y": -3,
      "z": -25,
      "name": "Rock_Stone"
    },
    {
      "x": -9,
      "y": -2,
      "z": -25,
      "name": "Rock_Stone"
    },
    {
      "x": -9,
      "y": -1,
      "z": -25,
      "name": "Rock_Stone"
    },
    {
      "x": -9,
      "y": 0,
      "z": -25,
      "name": "Rubble_Stone"
    },
    {
      "x": -9,
      "y": 1,
      "z": -25,
      "name": "Empty"
    },
    {
      "x": -9,
      "y": 2,
      "z": -25,
      "name": "Empty"
    },
    {
      "x": -9,
      "y": 3,
      "z": -25,
      "name": "Empty"
    },
    {
      "x": -9,
      "y": 4,
      "z": -25,
      "name": "Empty"
    },
    {
      "x": -9,
      "y": 10,
      "z": -25,
      "name": "Plant_Moss_Block_Blue"
    },
    {
      "x": -9,
      "y": 11,
      "z": -25,
      "name": "Plant_Moss_Rug_Blue"
    },
    {
      "x": -9,
      "y": -4,
      "z": -24,
      "name": "Rock_Stone"
    },
    {
      "x": -9,
      "y": -3,
      "z": -24,
      "name": "Rock_Stone"
    },
    {
      "x": -9,
      "y": -2,
      "z": -24,
      "name": "Rock_Stone"
    },
    {
      "x": -9,
      "y": -1,
      "z": -24,
      "name": "Rock_Stone"
    },
    {
      "x": -9,
      "y": 0,
      "z": -24,
      "name": "Empty"
    },
    {
      "x": -9,
      "y": 1,
      "z": -24,
      "name": "Empty"
    },
    {
      "x": -9,
      "y": 2,
      "z": -24,
      "name": "Empty"
    },
    {
      "x": -9,
      "y": 3,
      "z": -24,
      "name": "Empty"
    },
    {
      "x": -9,
      "y": 4,
      "z": -24,
      "name": "Empty"
    },
    {
      "x": -9,
      "y": 5,
      "z": -24,
      "name": "Empty"
    },
    {
      "x": -9,
      "y": -4,
      "z": -23,
      "name": "Rock_Stone"
    },
    {
      "x": -9,
      "y": -3,
      "z": -23,
      "name": "Rock_Stone"
    },
    {
      "x": -9,
      "y": -2,
      "z": -23,
      "name": "Rock_Stone"
    },
    {
      "x": -9,
      "y": -1,
      "z": -23,
      "name": "Rock_Stone_Cobble"
    },
    {
      "x": -9,
      "y": 0,
      "z": -23,
      "name": "Empty"
    },
    {
      "x": -9,
      "y": 1,
      "z": -23,
      "name": "Empty"
    },
    {
      "x": -9,
      "y": 2,
      "z": -23,
      "name": "Empty"
    },
    {
      "x": -9,
      "y": 3,
      "z": -23,
      "name": "Empty"
    },
    {
      "x": -9,
      "y": 4,
      "z": -23,
      "name": "Empty"
    },
    {
      "x": -9,
      "y": 5,
      "z": -23,
      "name": "Empty"
    },
    {
      "x": -9,
      "y": 6,
      "z": -23,
      "name": "Empty"
    },
    {
      "x": -9,
      "y": 7,
      "z": -23,
      "name": "Empty"
    },
    {
      "x": -9,
      "y": 8,
      "z": -23,
      "name": "Empty"
    },
    {
      "x": -9,
      "y": 9,
      "z": -23,
      "name": "Empty"
    },
    {
      "x": -9,
      "y": -4,
      "z": -22,
      "name": "Rock_Stone"
    },
    {
      "x": -9,
      "y": -3,
      "z": -22,
      "name": "Rock_Stone"
    },
    {
      "x": -9,
      "y": -2,
      "z": -22,
      "name": "Rock_Stone"
    },
    {
      "x": -9,
      "y": -1,
      "z": -22,
      "name": "Rock_Stone_Cobble"
    },
    {
      "x": -9,
      "y": 0,
      "z": -22,
      "name": "Empty"
    },
    {
      "x": -9,
      "y": 1,
      "z": -22,
      "name": "Empty"
    },
    {
      "x": -9,
      "y": 2,
      "z": -22,
      "name": "Empty"
    },
    {
      "x": -9,
      "y": 3,
      "z": -22,
      "name": "Empty"
    },
    {
      "x": -9,
      "y": 4,
      "z": -22,
      "name": "Empty"
    },
    {
      "x": -9,
      "y": 5,
      "z": -22,
      "name": "Empty"
    },
    {
      "x": -9,
      "y": 6,
      "z": -22,
      "name": "Empty"
    },
    {
      "x": -9,
      "y": 7,
      "z": -22,
      "name": "Empty"
    },
    {
      "x": -9,
      "y": 8,
      "z": -22,
      "name": "Empty"
    },
    {
      "x": -9,
      "y": 9,
      "z": -22,
      "name": "Empty"
    },
    {
      "x": -9,
      "y": -4,
      "z": -21,
      "name": "Rock_Stone"
    },
    {
      "x": -9,
      "y": -3,
      "z": -21,
      "name": "Rock_Stone"
    },
    {
      "x": -9,
      "y": -2,
      "z": -21,
      "name": "Rock_Stone"
    },
    {
      "x": -9,
      "y": -1,
      "z": -21,
      "name": "Rock_Stone_Cobble"
    },
    {
      "x": -9,
      "y": 0,
      "z": -21,
      "name": "Empty"
    },
    {
      "x": -9,
      "y": 1,
      "z": -21,
      "name": "Empty"
    },
    {
      "x": -9,
      "y": 2,
      "z": -21,
      "name": "Empty"
    },
    {
      "x": -9,
      "y": 3,
      "z": -21,
      "name": "Empty"
    },
    {
      "x": -9,
      "y": 4,
      "z": -21,
      "name": "Empty"
    },
    {
      "x": -9,
      "y": 5,
      "z": -21,
      "name": "Empty"
    },
    {
      "x": -9,
      "y": 6,
      "z": -21,
      "name": "Empty"
    },
    {
      "x": -9,
      "y": 7,
      "z": -21,
      "name": "Empty"
    },
    {
      "x": -9,
      "y": 8,
      "z": -21,
      "name": "Empty"
    },
    {
      "x": -9,
      "y": -4,
      "z": -20,
      "name": "Rock_Stone"
    },
    {
      "x": -9,
      "y": -3,
      "z": -20,
      "name": "Rock_Stone"
    },
    {
      "x": -9,
      "y": -2,
      "z": -20,
      "name": "Rock_Stone"
    },
    {
      "x": -9,
      "y": -1,
      "z": -20,
      "name": "Rock_Stone"
    },
    {
      "x": -9,
      "y": 0,
      "z": -20,
      "name": "Empty"
    },
    {
      "x": -9,
      "y": 1,
      "z": -20,
      "name": "Empty"
    },
    {
      "x": -9,
      "y": 2,
      "z": -20,
      "name": "Empty"
    },
    {
      "x": -9,
      "y": 3,
      "z": -20,
      "name": "Empty"
    },
    {
      "x": -9,
      "y": 4,
      "z": -20,
      "name": "Empty"
    },
    {
      "x": -9,
      "y": 5,
      "z": -20,
      "name": "Empty"
    },
    {
      "x": -9,
      "y": 6,
      "z": -20,
      "name": "Empty"
    },
    {
      "x": -9,
      "y": -5,
      "z": -19,
      "name": "Rock_Stone"
    },
    {
      "x": -9,
      "y": -4,
      "z": -19,
      "name": "Rock_Stone"
    },
    {
      "x": -9,
      "y": -3,
      "z": -19,
      "name": "Rock_Stone"
    },
    {
      "x": -9,
      "y": -2,
      "z": -19,
      "name": "Rock_Stone"
    },
    {
      "x": -9,
      "y": -1,
      "z": -19,
      "name": "Plant_Moss_Block_Blue"
    },
    {
      "x": -9,
      "y": 0,
      "z": -19,
      "name": "Plant_Moss_Rug_Blue"
    },
    {
      "x": -9,
      "y": 1,
      "z": -19,
      "name": "Empty"
    },
    {
      "x": -9,
      "y": 2,
      "z": -19,
      "name": "Empty"
    },
    {
      "x": -9,
      "y": -5,
      "z": -18,
      "name": "Rock_Stone"
    },
    {
      "x": -9,
      "y": -4,
      "z": -18,
      "name": "Rock_Stone"
    },
    {
      "x": -9,
      "y": -3,
      "z": -18,
      "name": "Rock_Stone"
    },
    {
      "x": -9,
      "y": -2,
      "z": -18,
      "name": "Rock_Stone"
    },
    {
      "x": -9,
      "y": -1,
      "z": -18,
      "name": "Rock_Stone"
    },
    {
      "x": -9,
      "y": 0,
      "z": -18,
      "name": "Rock_Stone"
    },
    {
      "x": -9,
      "y": -4,
      "z": -17,
      "name": "Rock_Stone"
    },
    {
      "x": -9,
      "y": -3,
      "z": -17,
      "name": "Rock_Stone"
    },
    {
      "x": -9,
      "y": -2,
      "z": -17,
      "name": "Rock_Stone"
    },
    {
      "x": -9,
      "y": -1,
      "z": -17,
      "name": "Rock_Stone"
    },
    {
      "x": -9,
      "y": 0,
      "z": -17,
      "name": "Rock_Stone"
    },
    {
      "x": -9,
      "y": 1,
      "z": -17,
      "name": "Rock_Stone"
    },
    {
      "x": -9,
      "y": 2,
      "z": -17,
      "name": "Rock_Stone"
    },
    {
      "x": -9,
      "y": -4,
      "z": -16,
      "name": "Rock_Stone"
    },
    {
      "x": -9,
      "y": -3,
      "z": -16,
      "name": "Rock_Stone"
    },
    {
      "x": -9,
      "y": -2,
      "z": -16,
      "name": "Rock_Stone"
    },
    {
      "x": -9,
      "y": -1,
      "z": -16,
      "name": "Rock_Stone"
    },
    {
      "x": -9,
      "y": 0,
      "z": -16,
      "name": "Rock_Stone"
    },
    {
      "x": -9,
      "y": 1,
      "z": -16,
      "name": "Rock_Stone"
    },
    {
      "x": -9,
      "y": 2,
      "z": -16,
      "name": "Rock_Stone"
    },
    {
      "x": -9,
      "y": -3,
      "z": -15,
      "name": "Rock_Stone"
    },
    {
      "x": -9,
      "y": -2,
      "z": -15,
      "name": "Rock_Stone"
    },
    {
      "x": -9,
      "y": -1,
      "z": -15,
      "name": "Rock_Stone"
    },
    {
      "x": -9,
      "y": 0,
      "z": -15,
      "name": "Rock_Stone"
    },
    {
      "x": -9,
      "y": 1,
      "z": -15,
      "name": "Rock_Stone"
    },
    {
      "x": -9,
      "y": 2,
      "z": -15,
      "name": "Rock_Stone"
    },
    {
      "x": -9,
      "y": -1,
      "z": -14,
      "name": "Rock_Stone"
    },
    {
      "x": -9,
      "y": 0,
      "z": -14,
      "name": "Rock_Stone"
    },
    {
      "x": -9,
      "y": 1,
      "z": -14,
      "name": "Rock_Stone"
    },
    {
      "x": -9,
      "y": 2,
      "z": -9,
      "name": "Plant_Moss_Block_Blue"
    },
    {
      "x": -9,
      "y": 3,
      "z": -9,
      "name": "Empty"
    },
    {
      "x": -9,
      "y": 4,
      "z": -9,
      "name": "Empty"
    },
    {
      "x": -9,
      "y": 5,
      "z": -9,
      "name": "Empty"
    },
    {
      "x": -9,
      "y": 6,
      "z": -9,
      "name": "Empty"
    },
    {
      "x": -9,
      "y": 1,
      "z": -8,
      "name": "Plant_Moss_Block_Blue"
    },
    {
      "x": -9,
      "y": 2,
      "z": -8,
      "name": "Plant_Moss_Block_Blue"
    },
    {
      "x": -9,
      "y": 3,
      "z": -8,
      "name": "Empty"
    },
    {
      "x": -9,
      "y": 4,
      "z": -8,
      "name": "Empty"
    },
    {
      "x": -9,
      "y": 5,
      "z": -8,
      "name": "Empty"
    },
    {
      "x": -9,
      "y": 6,
      "z": -8,
      "name": "Empty"
    },
    {
      "x": -9,
      "y": 7,
      "z": -8,
      "name": "Empty"
    },
    {
      "x": -9,
      "y": 4,
      "z": -7,
      "name": "Empty"
    },
    {
      "x": -9,
      "y": 5,
      "z": -7,
      "name": "Empty"
    },
    {
      "x": -8,
      "y": -3,
      "z": -32,
      "name": "Rock_Stone"
    },
    {
      "x": -8,
      "y": -4,
      "z": -31,
      "name": "Rock_Stone"
    },
    {
      "x": -8,
      "y": -3,
      "z": -31,
      "name": "Rock_Stone"
    },
    {
      "x": -8,
      "y": -2,
      "z": -31,
      "name": "Rock_Stone"
    },
    {
      "x": -8,
      "y": -5,
      "z": -30,
      "name": "Rock_Stone"
    },
    {
      "x": -8,
      "y": -4,
      "z": -30,
      "name": "Rock_Stone"
    },
    {
      "x": -8,
      "y": -3,
      "z": -30,
      "name": "Rock_Stone"
    },
    {
      "x": -8,
      "y": -2,
      "z": -30,
      "name": "Rock_Stone"
    },
    {
      "x": -8,
      "y": -1,
      "z": -30,
      "name": "Rock_Stone"
    },
    {
      "x": -8,
      "y": -5,
      "z": -29,
      "name": "Rock_Stone"
    },
    {
      "x": -8,
      "y": -4,
      "z": -29,
      "name": "Rock_Stone"
    },
    {
      "x": -8,
      "y": -3,
      "z": -29,
      "name": "Rock_Stone"
    },
    {
      "x": -8,
      "y": -2,
      "z": -29,
      "name": "Rock_Stone"
    },
    {
      "x": -8,
      "y": -1,
      "z": -29,
      "name": "Rock_Stone"
    },
    {
      "x": -8,
      "y": 0,
      "z": -29,
      "name": "Rock_Stone"
    },
    {
      "x": -8,
      "y": 10,
      "z": -29,
      "name": "Empty"
    },
    {
      "x": -8,
      "y": -5,
      "z": -28,
      "name": "Rock_Stone"
    },
    {
      "x": -8,
      "y": -4,
      "z": -28,
      "name": "Rock_Stone"
    },
    {
      "x": -8,
      "y": -3,
      "z": -28,
      "name": "Rock_Stone"
    },
    {
      "x": -8,
      "y": -2,
      "z": -28,
      "name": "Rock_Stone"
    },
    {
      "x": -8,
      "y": -1,
      "z": -28,
      "name": "Rock_Stone"
    },
    {
      "x": -8,
      "y": 0,
      "z": -28,
      "name": "Plant_Moss_Block_Blue"
    },
    {
      "x": -8,
      "y": 1,
      "z": -28,
      "name": "Plant_Moss_Rug_Blue"
    },
    {
      "x": -8,
      "y": 2,
      "z": -28,
      "name": "Empty"
    },
    {
      "x": -8,
      "y": 3,
      "z": -28,
      "name": "Empty"
    },
    {
      "x": -8,
      "y": 10,
      "z": -28,
      "name": "Rock_Crystal_Green_Small",
      "components": {
        "Components": {
          "FarmingBlock": {}
        }
      }
    },
    {
      "x": -8,
      "y": 11,
      "z": -28,
      "name": "Empty"
    },
    {
      "x": -8,
      "y": -5,
      "z": -27,
      "name": "Rock_Stone"
    },
    {
      "x": -8,
      "y": -4,
      "z": -27,
      "name": "Rock_Stone"
    },
    {
      "x": -8,
      "y": -3,
      "z": -27,
      "name": "Rock_Stone"
    },
    {
      "x": -8,
      "y": -2,
      "z": -27,
      "name": "Rock_Stone"
    },
    {
      "x": -8,
      "y": -1,
      "z": -27,
      "name": "Rock_Stone"
    },
    {
      "x": -8,
      "y": 0,
      "z": -27,
      "name": "Plant_Moss_Block_Blue"
    },
    {
      "x": -8,
      "y": 1,
      "z": -27,
      "name": "Empty"
    },
    {
      "x": -8,
      "y": 2,
      "z": -27,
      "name": "Empty"
    },
    {
      "x": -8,
      "y": 3,
      "z": -27,
      "name": "Empty"
    },
    {
      "x": -8,
      "y": 4,
      "z": -27,
      "name": "Empty"
    },
    {
      "x": -8,
      "y": 5,
      "z": -27,
      "name": "Empty"
    },
    {
      "x": -8,
      "y": 9,
      "z": -27,
      "name": "Plant_Moss_Block_Blue"
    },
    {
      "x": -8,
      "y": 10,
      "z": -27,
      "name": "Empty"
    },
    {
      "x": -8,
      "y": 11,
      "z": -27,
      "name": "Empty"
    },
    {
      "x": -8,
      "y": -4,
      "z": -26,
      "name": "Rock_Stone"
    },
    {
      "x": -8,
      "y": -3,
      "z": -26,
      "name": "Rock_Stone"
    },
    {
      "x": -8,
      "y": -2,
      "z": -26,
      "name": "Rock_Stone"
    },
    {
      "x": -8,
      "y": -1,
      "z": -26,
      "name": "Rock_Stone"
    },
    {
      "x": -8,
      "y": 0,
      "z": -26,
      "name": "Plant_Moss_Rug_Blue"
    },
    {
      "x": -8,
      "y": 1,
      "z": -26,
      "name": "Empty"
    },
    {
      "x": -8,
      "y": 2,
      "z": -26,
      "name": "Empty"
    },
    {
      "x": -8,
      "y": 3,
      "z": -26,
      "name": "Empty"
    },
    {
      "x": -8,
      "y": 4,
      "z": -26,
      "name": "Empty"
    },
    {
      "x": -8,
      "y": 5,
      "z": -26,
      "name": "Empty"
    },
    {
      "x": -8,
      "y": 6,
      "z": -26,
      "name": "Empty"
    },
    {
      "x": -8,
      "y": 9,
      "z": -26,
      "name": "Plant_Moss_Block_Blue"
    },
    {
      "x": -8,
      "y": 10,
      "z": -26,
      "name": "Plant_Moss_Block_Blue"
    },
    {
      "x": -8,
      "y": 11,
      "z": -26,
      "name": "Empty"
    },
    {
      "x": -8,
      "y": -4,
      "z": -25,
      "name": "Rock_Stone"
    },
    {
      "x": -8,
      "y": -3,
      "z": -25,
      "name": "Rock_Stone"
    },
    {
      "x": -8,
      "y": -2,
      "z": -25,
      "name": "Rock_Stone"
    },
    {
      "x": -8,
      "y": -1,
      "z": -25,
      "name": "Rock_Stone"
    },
    {
      "x": -8,
      "y": 0,
      "z": -25,
      "name": "Empty"
    },
    {
      "x": -8,
      "y": 1,
      "z": -25,
      "name": "Empty"
    },
    {
      "x": -8,
      "y": 2,
      "z": -25,
      "name": "Empty"
    },
    {
      "x": -8,
      "y": 3,
      "z": -25,
      "name": "Empty"
    },
    {
      "x": -8,
      "y": 4,
      "z": -25,
      "name": "Empty"
    },
    {
      "x": -8,
      "y": 5,
      "z": -25,
      "name": "Empty"
    },
    {
      "x": -8,
      "y": 6,
      "z": -25,
      "name": "Empty"
    },
    {
      "x": -8,
      "y": 10,
      "z": -25,
      "name": "Plant_Moss_Block_Blue"
    },
    {
      "x": -8,
      "y": 11,
      "z": -25,
      "name": "Plant_Moss_Rug_Blue"
    },
    {
      "x": -8,
      "y": -4,
      "z": -24,
      "name": "Rock_Stone"
    },
    {
      "x": -8,
      "y": -3,
      "z": -24,
      "name": "Rock_Stone"
    },
    {
      "x": -8,
      "y": -2,
      "z": -24,
      "name": "Rock_Stone"
    },
    {
      "x": -8,
      "y": -1,
      "z": -24,
      "name": "Rock_Stone_Cobble"
    },
    {
      "x": -8,
      "y": 0,
      "z": -24,
      "name": "Empty"
    },
    {
      "x": -8,
      "y": 1,
      "z": -24,
      "name": "Empty"
    },
    {
      "x": -8,
      "y": 2,
      "z": -24,
      "name": "Empty"
    },
    {
      "x": -8,
      "y": 3,
      "z": -24,
      "name": "Empty"
    },
    {
      "x": -8,
      "y": 4,
      "z": -24,
      "name": "Empty"
    },
    {
      "x": -8,
      "y": 5,
      "z": -24,
      "name": "Empty"
    },
    {
      "x": -8,
      "y": 6,
      "z": -24,
      "name": "Empty"
    },
    {
      "x": -8,
      "y": 7,
      "z": -24,
      "name": "Empty"
    },
    {
      "x": -8,
      "y": 8,
      "z": -24,
      "name": "Empty"
    },
    {
      "x": -8,
      "y": 11,
      "z": -24,
      "name": "Plant_Moss_Block_Blue"
    },
    {
      "x": -8,
      "y": 12,
      "z": -24,
      "name": "Rock_Crystal_Green_Medium"
    },
    {
      "x": -8,
      "y": -4,
      "z": -23,
      "name": "Rock_Stone"
    },
    {
      "x": -8,
      "y": -3,
      "z": -23,
      "name": "Rock_Stone"
    },
    {
      "x": -8,
      "y": -2,
      "z": -23,
      "name": "Rock_Stone"
    },
    {
      "x": -8,
      "y": -1,
      "z": -23,
      "name": "Rock_Stone"
    },
    {
      "x": -8,
      "y": 0,
      "z": -23,
      "name": "Empty"
    },
    {
      "x": -8,
      "y": 1,
      "z": -23,
      "name": "Empty"
    },
    {
      "x": -8,
      "y": 2,
      "z": -23,
      "name": "Empty"
    },
    {
      "x": -8,
      "y": 3,
      "z": -23,
      "name": "Empty"
    },
    {
      "x": -8,
      "y": 4,
      "z": -23,
      "name": "Empty"
    },
    {
      "x": -8,
      "y": 5,
      "z": -23,
      "name": "Empty"
    },
    {
      "x": -8,
      "y": 6,
      "z": -23,
      "name": "Empty"
    },
    {
      "x": -8,
      "y": 7,
      "z": -23,
      "name": "Empty"
    },
    {
      "x": -8,
      "y": 8,
      "z": -23,
      "name": "Empty"
    },
    {
      "x": -8,
      "y": 9,
      "z": -23,
      "name": "Empty"
    },
    {
      "x": -8,
      "y": 11,
      "z": -23,
      "name": "Plant_Moss_Block_Blue"
    },
    {
      "x": -8,
      "y": 12,
      "z": -23,
      "name": "Plant_Moss_Rug_Blue"
    },
    {
      "x": -8,
      "y": -5,
      "z": -22,
      "name": "Rock_Stone"
    },
    {
      "x": -8,
      "y": -4,
      "z": -22,
      "name": "Rock_Stone"
    },
    {
      "x": -8,
      "y": -3,
      "z": -22,
      "name": "Rock_Stone"
    },
    {
      "x": -8,
      "y": -2,
      "z": -22,
      "name": "Rock_Stone"
    },
    {
      "x": -8,
      "y": -1,
      "z": -22,
      "name": "Rock_Stone_Cobble"
    },
    {
      "x": -8,
      "y": 0,
      "z": -22,
      "name": "Empty"
    },
    {
      "x": -8,
      "y": 1,
      "z": -22,
      "name": "Empty"
    },
    {
      "x": -8,
      "y": 2,
      "z": -22,
      "name": "Empty"
    },
    {
      "x": -8,
      "y": 3,
      "z": -22,
      "name": "Empty"
    },
    {
      "x": -8,
      "y": 4,
      "z": -22,
      "name": "Empty"
    },
    {
      "x": -8,
      "y": 5,
      "z": -22,
      "name": "Empty"
    },
    {
      "x": -8,
      "y": 6,
      "z": -22,
      "name": "Empty"
    },
    {
      "x": -8,
      "y": 7,
      "z": -22,
      "name": "Empty"
    },
    {
      "x": -8,
      "y": 8,
      "z": -22,
      "name": "Empty"
    },
    {
      "x": -8,
      "y": 9,
      "z": -22,
      "name": "Empty"
    },
    {
      "x": -8,
      "y": 10,
      "z": -22,
      "name": "Empty"
    },
    {
      "x": -8,
      "y": 12,
      "z": -22,
      "name": "Plant_Moss_Block_Blue"
    },
    {
      "x": -8,
      "y": 13,
      "z": -22,
      "name": "Empty"
    },
    {
      "x": -8,
      "y": -5,
      "z": -21,
      "name": "Rock_Stone"
    },
    {
      "x": -8,
      "y": -4,
      "z": -21,
      "name": "Rock_Stone"
    },
    {
      "x": -8,
      "y": -3,
      "z": -21,
      "name": "Rock_Stone"
    },
    {
      "x": -8,
      "y": -2,
      "z": -21,
      "name": "Rock_Stone"
    },
    {
      "x": -8,
      "y": -1,
      "z": -21,
      "name": "Rock_Stone"
    },
    {
      "x": -8,
      "y": 0,
      "z": -21,
      "name": "Empty"
    },
    {
      "x": -8,
      "y": 1,
      "z": -21,
      "name": "Empty"
    },
    {
      "x": -8,
      "y": 2,
      "z": -21,
      "name": "Empty"
    },
    {
      "x": -8,
      "y": 3,
      "z": -21,
      "name": "Empty"
    },
    {
      "x": -8,
      "y": 4,
      "z": -21,
      "name": "Empty"
    },
    {
      "x": -8,
      "y": 5,
      "z": -21,
      "name": "Empty"
    },
    {
      "x": -8,
      "y": 6,
      "z": -21,
      "name": "Empty"
    },
    {
      "x": -8,
      "y": 7,
      "z": -21,
      "name": "Empty"
    },
    {
      "x": -8,
      "y": 8,
      "z": -21,
      "name": "Empty"
    },
    {
      "x": -8,
      "y": 9,
      "z": -21,
      "name": "Empty"
    },
    {
      "x": -8,
      "y": 10,
      "z": -21,
      "name": "Empty"
    },
    {
      "x": -8,
      "y": -5,
      "z": -20,
      "name": "Rock_Stone"
    },
    {
      "x": -8,
      "y": -4,
      "z": -20,
      "name": "Rock_Stone"
    },
    {
      "x": -8,
      "y": -3,
      "z": -20,
      "name": "Rock_Stone"
    },
    {
      "x": -8,
      "y": -2,
      "z": -20,
      "name": "Rock_Stone"
    },
    {
      "x": -8,
      "y": -1,
      "z": -20,
      "name": "Rock_Stone"
    },
    {
      "x": -8,
      "y": 0,
      "z": -20,
      "name": "Empty"
    },
    {
      "x": -8,
      "y": 1,
      "z": -20,
      "name": "Empty"
    },
    {
      "x": -8,
      "y": 2,
      "z": -20,
      "name": "Empty"
    },
    {
      "x": -8,
      "y": 3,
      "z": -20,
      "name": "Empty"
    },
    {
      "x": -8,
      "y": 4,
      "z": -20,
      "name": "Empty"
    },
    {
      "x": -8,
      "y": 5,
      "z": -20,
      "name": "Empty"
    },
    {
      "x": -8,
      "y": 6,
      "z": -20,
      "name": "Empty"
    },
    {
      "x": -8,
      "y": 7,
      "z": -20,
      "name": "Empty"
    },
    {
      "x": -8,
      "y": 8,
      "z": -20,
      "name": "Empty"
    },
    {
      "x": -8,
      "y": 9,
      "z": -20,
      "name": "Empty"
    },
    {
      "x": -8,
      "y": 10,
      "z": -20,
      "name": "Empty"
    },
    {
      "x": -8,
      "y": -5,
      "z": -19,
      "name": "Rock_Stone"
    },
    {
      "x": -8,
      "y": -4,
      "z": -19,
      "name": "Rock_Stone"
    },
    {
      "x": -8,
      "y": -3,
      "z": -19,
      "name": "Rock_Stone"
    },
    {
      "x": -8,
      "y": -2,
      "z": -19,
      "name": "Rock_Stone"
    },
    {
      "x": -8,
      "y": -1,
      "z": -19,
      "name": "Rock_Stone"
    },
    {
      "x": -8,
      "y": 0,
      "z": -19,
      "name": "Plant_Moss_Rug_Blue"
    },
    {
      "x": -8,
      "y": 1,
      "z": -19,
      "name": "Empty"
    },
    {
      "x": -8,
      "y": 2,
      "z": -19,
      "name": "Empty"
    },
    {
      "x": -8,
      "y": 3,
      "z": -19,
      "name": "Empty"
    },
    {
      "x": -8,
      "y": 4,
      "z": -19,
      "name": "Empty"
    },
    {
      "x": -8,
      "y": 5,
      "z": -19,
      "name": "Empty"
    },
    {
      "x": -8,
      "y": 6,
      "z": -19,
      "name": "Empty"
    },
    {
      "x": -8,
      "y": 7,
      "z": -19,
      "name": "Empty"
    },
    {
      "x": -8,
      "y": 8,
      "z": -19,
      "name": "Empty"
    },
    {
      "x": -8,
      "y": 9,
      "z": -19,
      "name": "Empty"
    },
    {
      "x": -8,
      "y": -5,
      "z": -18,
      "name": "Rock_Stone"
    },
    {
      "x": -8,
      "y": -4,
      "z": -18,
      "name": "Rock_Stone"
    },
    {
      "x": -8,
      "y": -3,
      "z": -18,
      "name": "Rock_Stone"
    },
    {
      "x": -8,
      "y": -2,
      "z": -18,
      "name": "Rock_Stone"
    },
    {
      "x": -8,
      "y": -1,
      "z": -18,
      "name": "Plant_Moss_Block_Blue"
    },
    {
      "x": -8,
      "y": 0,
      "z": -18,
      "name": "Plant_Moss_Block_Blue"
    },
    {
      "x": -8,
      "y": 1,
      "z": -18,
      "name": "Empty"
    },
    {
      "x": -8,
      "y": 2,
      "z": -18,
      "name": "Empty"
    },
    {
      "x": -8,
      "y": 3,
      "z": -18,
      "name": "Empty"
    },
    {
      "x": -8,
      "y": 4,
      "z": -18,
      "name": "Empty"
    },
    {
      "x": -8,
      "y": 5,
      "z": -18,
      "name": "Empty"
    },
    {
      "x": -8,
      "y": 6,
      "z": -18,
      "name": "Empty"
    },
    {
      "x": -8,
      "y": 7,
      "z": -18,
      "name": "Empty"
    },
    {
      "x": -8,
      "y": -5,
      "z": -17,
      "name": "Rock_Stone"
    },
    {
      "x": -8,
      "y": -4,
      "z": -17,
      "name": "Rock_Stone"
    },
    {
      "x": -8,
      "y": -3,
      "z": -17,
      "name": "Rock_Stone"
    },
    {
      "x": -8,
      "y": -2,
      "z": -17,
      "name": "Rock_Stone"
    },
    {
      "x": -8,
      "y": -1,
      "z": -17,
      "name": "Rock_Stone"
    },
    {
      "x": -8,
      "y": 0,
      "z": -17,
      "name": "Plant_Moss_Block_Blue"
    },
    {
      "x": -8,
      "y": 1,
      "z": -17,
      "name": "Plant_Moss_Rug_Blue"
    },
    {
      "x": -8,
      "y": 2,
      "z": -17,
      "name": "Rock_Stone"
    },
    {
      "x": -8,
      "y": 3,
      "z": -17,
      "name": "Rock_Stone"
    },
    {
      "x": -8,
      "y": -4,
      "z": -16,
      "name": "Rock_Stone"
    },
    {
      "x": -8,
      "y": -3,
      "z": -16,
      "name": "Rock_Stone"
    },
    {
      "x": -8,
      "y": -2,
      "z": -16,
      "name": "Rock_Stone"
    },
    {
      "x": -8,
      "y": -1,
      "z": -16,
      "name": "Rock_Stone"
    },
    {
      "x": -8,
      "y": 0,
      "z": -16,
      "name": "Rock_Stone"
    },
    {
      "x": -8,
      "y": 1,
      "z": -16,
      "name": "Rock_Stone"
    },
    {
      "x": -8,
      "y": 2,
      "z": -16,
      "name": "Rock_Stone"
    },
    {
      "x": -8,
      "y": 3,
      "z": -16,
      "name": "Rock_Stone"
    },
    {
      "x": -8,
      "y": -4,
      "z": -15,
      "name": "Rock_Stone"
    },
    {
      "x": -8,
      "y": -3,
      "z": -15,
      "name": "Rock_Stone"
    },
    {
      "x": -8,
      "y": -2,
      "z": -15,
      "name": "Rock_Stone"
    },
    {
      "x": -8,
      "y": -1,
      "z": -15,
      "name": "Rock_Stone"
    },
    {
      "x": -8,
      "y": 0,
      "z": -15,
      "name": "Rock_Stone"
    },
    {
      "x": -8,
      "y": 1,
      "z": -15,
      "name": "Rock_Stone"
    },
    {
      "x": -8,
      "y": 2,
      "z": -15,
      "name": "Rock_Stone"
    },
    {
      "x": -8,
      "y": 3,
      "z": -15,
      "name": "Rock_Stone"
    },
    {
      "x": -8,
      "y": -3,
      "z": -14,
      "name": "Rock_Stone"
    },
    {
      "x": -8,
      "y": -2,
      "z": -14,
      "name": "Rock_Stone"
    },
    {
      "x": -8,
      "y": -1,
      "z": -14,
      "name": "Rock_Stone"
    },
    {
      "x": -8,
      "y": 0,
      "z": -14,
      "name": "Rock_Stone"
    },
    {
      "x": -8,
      "y": 1,
      "z": -14,
      "name": "Rock_Stone"
    },
    {
      "x": -8,
      "y": 2,
      "z": -14,
      "name": "Rock_Stone"
    },
    {
      "x": -8,
      "y": 3,
      "z": -14,
      "name": "Rock_Stone"
    },
    {
      "x": -8,
      "y": 0,
      "z": -13,
      "name": "Rock_Stone"
    },
    {
      "x": -8,
      "y": 1,
      "z": -13,
      "name": "Rock_Stone"
    },
    {
      "x": -8,
      "y": 2,
      "z": -13,
      "name": "Rock_Stone"
    },
    {
      "x": -8,
      "y": 1,
      "z": -10,
      "name": "Rock_Stone"
    },
    {
      "x": -8,
      "y": 2,
      "z": -10,
      "name": "Rock_Stone"
    },
    {
      "x": -8,
      "y": 5,
      "z": -10,
      "name": "Empty"
    },
    {
      "x": -8,
      "y": 6,
      "z": -10,
      "name": "Empty"
    },
    {
      "x": -8,
      "y": 7,
      "z": -10,
      "name": "Empty"
    },
    {
      "x": -8,
      "y": 8,
      "z": -10,
      "name": "Empty"
    },
    {
      "x": -8,
      "y": 0,
      "z": -9,
      "name": "Rock_Stone"
    },
    {
      "x": -8,
      "y": 1,
      "z": -9,
      "name": "Plant_Moss_Block_Blue"
    },
    {
      "x": -8,
      "y": 2,
      "z": -9,
      "name": "Plant_Moss_Block_Blue"
    },
    {
      "x": -8,
      "y": 3,
      "z": -9,
      "name": "Plant_Moss_Rug_Blue"
    },
    {
      "x": -8,
      "y": 4,
      "z": -9,
      "name": "Empty"
    },
    {
      "x": -8,
      "y": 5,
      "z": -9,
      "name": "Empty"
    },
    {
      "x": -8,
      "y": 6,
      "z": -9,
      "name": "Empty"
    },
    {
      "x": -8,
      "y": 7,
      "z": -9,
      "name": "Empty"
    },
    {
      "x": -8,
      "y": 8,
      "z": -9,
      "name": "Empty"
    },
    {
      "x": -8,
      "y": 9,
      "z": -9,
      "name": "Empty"
    },
    {
      "x": -8,
      "y": 10,
      "z": -9,
      "name": "Empty"
    },
    {
      "x": -8,
      "y": 0,
      "z": -8,
      "name": "Rock_Stone"
    },
    {
      "x": -8,
      "y": 1,
      "z": -8,
      "name": "Plant_Moss_Block_Blue"
    },
    {
      "x": -8,
      "y": 2,
      "z": -8,
      "name": "Plant_Moss_Rug_Blue"
    },
    {
      "x": -8,
      "y": 3,
      "z": -8,
      "name": "Empty"
    },
    {
      "x": -8,
      "y": 4,
      "z": -8,
      "name": "Empty"
    },
    {
      "x": -8,
      "y": 5,
      "z": -8,
      "name": "Empty"
    },
    {
      "x": -8,
      "y": 6,
      "z": -8,
      "name": "Empty"
    },
    {
      "x": -8,
      "y": 7,
      "z": -8,
      "name": "Empty"
    },
    {
      "x": -8,
      "y": 8,
      "z": -8,
      "name": "Empty"
    },
    {
      "x": -8,
      "y": 9,
      "z": -8,
      "name": "Empty"
    },
    {
      "x": -8,
      "y": -1,
      "z": -7,
      "name": "Rock_Stone"
    },
    {
      "x": -8,
      "y": 0,
      "z": -7,
      "name": "Rock_Stone"
    },
    {
      "x": -8,
      "y": 1,
      "z": -7,
      "name": "Rock_Quartzite_Cobble"
    },
    {
      "x": -8,
      "y": 2,
      "z": -7,
      "name": "Rock_Quartzite_Brick"
    },
    {
      "x": -8,
      "y": 3,
      "z": -7,
      "name": "Rock_Quartzite_Brick"
    },
    {
      "x": -8,
      "y": 4,
      "z": -7,
      "name": "Rock_Quartzite_Brick_Smooth"
    },
    {
      "x": -8,
      "y": 5,
      "z": -7,
      "name": "Empty"
    },
    {
      "x": -8,
      "y": 6,
      "z": -7,
      "name": "Empty"
    },
    {
      "x": -8,
      "y": 7,
      "z": -7,
      "name": "Empty"
    },
    {
      "x": -8,
      "y": 8,
      "z": -7,
      "name": "Empty"
    },
    {
      "x": -8,
      "y": -1,
      "z": -6,
      "name": "Rock_Stone"
    },
    {
      "x": -8,
      "y": 0,
      "z": -6,
      "name": "Rock_Stone"
    },
    {
      "x": -8,
      "y": 1,
      "z": -6,
      "name": "Rock_Quartzite_Cobble"
    },
    {
      "x": -8,
      "y": 2,
      "z": -6,
      "name": "Rock_Quartzite_Cobble"
    },
    {
      "x": -8,
      "y": 3,
      "z": -6,
      "name": "Rock_Quartzite_Brick"
    },
    {
      "x": -8,
      "y": 4,
      "z": -6,
      "name": "Rock_Quartzite_Brick_Smooth"
    },
    {
      "x": -8,
      "y": 5,
      "z": -6,
      "name": "Empty"
    },
    {
      "x": -8,
      "y": 6,
      "z": -6,
      "name": "Empty"
    },
    {
      "x": -8,
      "y": -1,
      "z": -5,
      "name": "Rock_Stone"
    },
    {
      "x": -8,
      "y": 0,
      "z": -5,
      "name": "Rock_Stone"
    },
    {
      "x": -8,
      "y": 1,
      "z": -5,
      "name": "Rock_Stone"
    },
    {
      "x": -8,
      "y": 2,
      "z": -5,
      "name": "Rock_Stone"
    },
    {
      "x": -8,
      "y": 3,
      "z": -5,
      "name": "Rock_Stone"
    },
    {
      "x": -8,
      "y": 0,
      "z": -4,
      "name": "Rock_Stone"
    },
    {
      "x": -8,
      "y": 1,
      "z": -4,
      "name": "Rock_Stone"
    },
    {
      "x": -8,
      "y": 2,
      "z": -4,
      "name": "Rock_Stone"
    },
    {
      "x": -8,
      "y": 3,
      "z": -4,
      "name": "Rock_Stone"
    },
    {
      "x": -8,
      "y": 0,
      "z": -3,
      "name": "Rock_Stone"
    },
    {
      "x": -8,
      "y": 1,
      "z": -3,
      "name": "Rock_Stone"
    },
    {
      "x": -8,
      "y": 2,
      "z": -3,
      "name": "Rock_Stone"
    },
    {
      "x": -7,
      "y": -4,
      "z": -32,
      "name": "Rock_Stone"
    },
    {
      "x": -7,
      "y": -3,
      "z": -32,
      "name": "Rock_Stone"
    },
    {
      "x": -7,
      "y": -2,
      "z": -32,
      "name": "Rock_Stone"
    },
    {
      "x": -7,
      "y": -5,
      "z": -31,
      "name": "Rock_Stone"
    },
    {
      "x": -7,
      "y": -4,
      "z": -31,
      "name": "Rock_Stone"
    },
    {
      "x": -7,
      "y": -3,
      "z": -31,
      "name": "Rock_Stone"
    },
    {
      "x": -7,
      "y": -2,
      "z": -31,
      "name": "Rock_Stone"
    },
    {
      "x": -7,
      "y": -1,
      "z": -31,
      "name": "Rock_Stone"
    },
    {
      "x": -7,
      "y": -5,
      "z": -30,
      "name": "Rock_Stone"
    },
    {
      "x": -7,
      "y": -4,
      "z": -30,
      "name": "Rock_Stone"
    },
    {
      "x": -7,
      "y": -3,
      "z": -30,
      "name": "Rock_Stone"
    },
    {
      "x": -7,
      "y": -2,
      "z": -30,
      "name": "Rock_Stone"
    },
    {
      "x": -7,
      "y": -1,
      "z": -30,
      "name": "Rock_Stone"
    },
    {
      "x": -7,
      "y": 0,
      "z": -30,
      "name": "Rock_Stone"
    },
    {
      "x": -7,
      "y": 1,
      "z": -30,
      "name": "Rock_Stone"
    },
    {
      "x": -7,
      "y": 3,
      "z": -30,
      "name": "Empty"
    },
    {
      "x": -7,
      "y": 4,
      "z": -30,
      "name": "Empty"
    },
    {
      "x": -7,
      "y": 5,
      "z": -30,
      "name": "Empty"
    },
    {
      "x": -7,
      "y": -5,
      "z": -29,
      "name": "Rock_Stone"
    },
    {
      "x": -7,
      "y": -4,
      "z": -29,
      "name": "Rock_Stone"
    },
    {
      "x": -7,
      "y": -3,
      "z": -29,
      "name": "Rock_Stone"
    },
    {
      "x": -7,
      "y": -2,
      "z": -29,
      "name": "Rock_Stone"
    },
    {
      "x": -7,
      "y": -1,
      "z": -29,
      "name": "Plant_Moss_Block_Blue"
    },
    {
      "x": -7,
      "y": 0,
      "z": -29,
      "name": "Plant_Moss_Rug_Blue"
    },
    {
      "x": -7,
      "y": 1,
      "z": -29,
      "name": "Empty"
    },
    {
      "x": -7,
      "y": 2,
      "z": -29,
      "name": "Empty"
    },
    {
      "x": -7,
      "y": 3,
      "z": -29,
      "name": "Empty"
    },
    {
      "x": -7,
      "y": 4,
      "z": -29,
      "name": "Empty"
    },
    {
      "x": -7,
      "y": 5,
      "z": -29,
      "name": "Empty"
    },
    {
      "x": -7,
      "y": 6,
      "z": -29,
      "name": "Empty"
    },
    {
      "x": -7,
      "y": 9,
      "z": -29,
      "name": "Plant_Moss_Block_Blue"
    },
    {
      "x": -7,
      "y": 10,
      "z": -29,
      "name": "Empty"
    },
    {
      "x": -7,
      "y": -5,
      "z": -28,
      "name": "Rock_Stone"
    },
    {
      "x": -7,
      "y": -4,
      "z": -28,
      "name": "Rock_Stone"
    },
    {
      "x": -7,
      "y": -3,
      "z": -28,
      "name": "Rock_Stone"
    },
    {
      "x": -7,
      "y": -2,
      "z": -28,
      "name": "Rock_Stone"
    },
    {
      "x": -7,
      "y": -1,
      "z": -28,
      "name": "Plant_Moss_Block_Blue"
    },
    {
      "x": -7,
      "y": 0,
      "z": -28,
      "name": "Plant_Moss_Rug_Blue"
    },
    {
      "x": -7,
      "y": 1,
      "z": -28,
      "name": "Empty"
    },
    {
      "x": -7,
      "y": 2,
      "z": -28,
      "name": "Empty"
    },
    {
      "x": -7,
      "y": 3,
      "z": -28,
      "name": "Empty"
    },
    {
      "x": -7,
      "y": 4,
      "z": -28,
      "name": "Empty"
    },
    {
      "x": -7,
      "y": 5,
      "z": -28,
      "name": "Empty"
    },
    {
      "x": -7,
      "y": 6,
      "z": -28,
      "name": "Empty"
    },
    {
      "x": -7,
      "y": 8,
      "z": -28,
      "name": "Plant_Moss_Block_Blue"
    },
    {
      "x": -7,
      "y": 9,
      "z": -28,
      "name": "Plant_Moss_Block_Blue"
    },
    {
      "x": -7,
      "y": 10,
      "z": -28,
      "name": "Empty"
    },
    {
      "x": -7,
      "y": -5,
      "z": -27,
      "name": "Rock_Stone"
    },
    {
      "x": -7,
      "y": -4,
      "z": -27,
      "name": "Rock_Stone"
    },
    {
      "x": -7,
      "y": -3,
      "z": -27,
      "name": "Rock_Stone"
    },
    {
      "x": -7,
      "y": -2,
      "z": -27,
      "name": "Rock_Stone"
    },
    {
      "x": -7,
      "y": -1,
      "z": -27,
      "name": "Rock_Stone"
    },
    {
      "x": -7,
      "y": 0,
      "z": -27,
      "name": "Plant_Moss_Rug_Blue"
    },
    {
      "x": -7,
      "y": 1,
      "z": -27,
      "name": "Empty"
    },
    {
      "x": -7,
      "y": 2,
      "z": -27,
      "name": "Empty"
    },
    {
      "x": -7,
      "y": 3,
      "z": -27,
      "name": "Empty"
    },
    {
      "x": -7,
      "y": 4,
      "z": -27,
      "name": "Empty"
    },
    {
      "x": -7,
      "y": 5,
      "z": -27,
      "name": "Empty"
    },
    {
      "x": -7,
      "y": 6,
      "z": -27,
      "name": "Empty"
    },
    {
      "x": -7,
      "y": 9,
      "z": -27,
      "name": "Plant_Moss_Block_Blue"
    },
    {
      "x": -7,
      "y": 10,
      "z": -27,
      "name": "Empty"
    },
    {
      "x": -7,
      "y": 11,
      "z": -27,
      "name": "Empty"
    },
    {
      "x": -7,
      "y": -5,
      "z": -26,
      "name": "Rock_Stone"
    },
    {
      "x": -7,
      "y": -4,
      "z": -26,
      "name": "Rock_Stone"
    },
    {
      "x": -7,
      "y": -3,
      "z": -26,
      "name": "Rock_Stone"
    },
    {
      "x": -7,
      "y": -2,
      "z": -26,
      "name": "Rock_Stone"
    },
    {
      "x": -7,
      "y": -1,
      "z": -26,
      "name": "Rock_Stone"
    },
    {
      "x": -7,
      "y": 0,
      "z": -26,
      "name": "Empty"
    },
    {
      "x": -7,
      "y": 1,
      "z": -26,
      "name": "Empty"
    },
    {
      "x": -7,
      "y": 2,
      "z": -26,
      "name": "Empty"
    },
    {
      "x": -7,
      "y": 3,
      "z": -26,
      "name": "Empty"
    },
    {
      "x": -7,
      "y": 4,
      "z": -26,
      "name": "Empty"
    },
    {
      "x": -7,
      "y": 5,
      "z": -26,
      "name": "Empty"
    },
    {
      "x": -7,
      "y": 6,
      "z": -26,
      "name": "Empty"
    },
    {
      "x": -7,
      "y": 7,
      "z": -26,
      "name": "Empty"
    },
    {
      "x": -7,
      "y": 9,
      "z": -26,
      "name": "Plant_Moss_Block_Blue"
    },
    {
      "x": -7,
      "y": 10,
      "z": -26,
      "name": "Plant_Moss_Rug_Blue"
    },
    {
      "x": -7,
      "y": 11,
      "z": -26,
      "name": "Plant_Moss_Cave_Blue",
      "rotation": 8
    },
    {
      "x": -7,
      "y": -5,
      "z": -25,
      "name": "Rock_Stone"
    },
    {
      "x": -7,
      "y": -4,
      "z": -25,
      "name": "Rock_Stone"
    },
    {
      "x": -7,
      "y": -3,
      "z": -25,
      "name": "Rock_Stone"
    },
    {
      "x": -7,
      "y": -2,
      "z": -25,
      "name": "Rock_Stone"
    },
    {
      "x": -7,
      "y": -1,
      "z": -25,
      "name": "Rock_Stone"
    },
    {
      "x": -7,
      "y": 0,
      "z": -25,
      "name": "Empty"
    },
    {
      "x": -7,
      "y": 1,
      "z": -25,
      "name": "Empty"
    },
    {
      "x": -7,
      "y": 2,
      "z": -25,
      "name": "Empty"
    },
    {
      "x": -7,
      "y": 3,
      "z": -25,
      "name": "Empty"
    },
    {
      "x": -7,
      "y": 4,
      "z": -25,
      "name": "Empty"
    },
    {
      "x": -7,
      "y": 5,
      "z": -25,
      "name": "Empty"
    },
    {
      "x": -7,
      "y": 6,
      "z": -25,
      "name": "Empty"
    },
    {
      "x": -7,
      "y": 7,
      "z": -25,
      "name": "Empty"
    },
    {
      "x": -7,
      "y": 8,
      "z": -25,
      "name": "Empty"
    },
    {
      "x": -7,
      "y": 10,
      "z": -25,
      "name": "Plant_Moss_Rug_Blue"
    },
    {
      "x": -7,
      "y": 11,
      "z": -25,
      "name": "Empty"
    },
    {
      "x": -7,
      "y": -5,
      "z": -24,
      "name": "Rock_Stone"
    },
    {
      "x": -7,
      "y": -4,
      "z": -24,
      "name": "Rock_Stone"
    },
    {
      "x": -7,
      "y": -3,
      "z": -24,
      "name": "Rock_Stone"
    },
    {
      "x": -7,
      "y": -2,
      "z": -24,
      "name": "Rock_Stone"
    },
    {
      "x": -7,
      "y": -1,
      "z": -24,
      "name": "Rock_Stone"
    },
    {
      "x": -7,
      "y": 0,
      "z": -24,
      "name": "Empty"
    },
    {
      "x": -7,
      "y": 1,
      "z": -24,
      "name": "Empty"
    },
    {
      "x": -7,
      "y": 2,
      "z": -24,
      "name": "Empty"
    },
    {
      "x": -7,
      "y": 3,
      "z": -24,
      "name": "Empty"
    },
    {
      "x": -7,
      "y": 4,
      "z": -24,
      "name": "Empty"
    },
    {
      "x": -7,
      "y": 5,
      "z": -24,
      "name": "Empty"
    },
    {
      "x": -7,
      "y": 6,
      "z": -24,
      "name": "Empty"
    },
    {
      "x": -7,
      "y": 7,
      "z": -24,
      "name": "Empty"
    },
    {
      "x": -7,
      "y": 8,
      "z": -24,
      "name": "Empty"
    },
    {
      "x": -7,
      "y": 9,
      "z": -24,
      "name": "Empty"
    },
    {
      "x": -7,
      "y": 10,
      "z": -24,
      "name": "Empty"
    },
    {
      "x": -7,
      "y": 11,
      "z": -24,
      "name": "Empty"
    },
    {
      "x": -7,
      "y": 12,
      "z": -24,
      "name": "Empty"
    },
    {
      "x": -7,
      "y": -5,
      "z": -23,
      "name": "Rock_Stone"
    },
    {
      "x": -7,
      "y": -4,
      "z": -23,
      "name": "Rock_Stone"
    },
    {
      "x": -7,
      "y": -3,
      "z": -23,
      "name": "Rock_Stone"
    },
    {
      "x": -7,
      "y": -2,
      "z": -23,
      "name": "Rock_Stone"
    },
    {
      "x": -7,
      "y": -1,
      "z": -23,
      "name": "Rock_Stone"
    },
    {
      "x": -7,
      "y": 0,
      "z": -23,
      "name": "Empty"
    },
    {
      "x": -7,
      "y": 1,
      "z": -23,
      "name": "Empty"
    },
    {
      "x": -7,
      "y": 2,
      "z": -23,
      "name": "Empty"
    },
    {
      "x": -7,
      "y": 3,
      "z": -23,
      "name": "Empty"
    },
    {
      "x": -7,
      "y": 4,
      "z": -23,
      "name": "Empty"
    },
    {
      "x": -7,
      "y": 5,
      "z": -23,
      "name": "Empty"
    },
    {
      "x": -7,
      "y": 6,
      "z": -23,
      "name": "Empty"
    },
    {
      "x": -7,
      "y": 7,
      "z": -23,
      "name": "Empty"
    },
    {
      "x": -7,
      "y": 8,
      "z": -23,
      "name": "Empty"
    },
    {
      "x": -7,
      "y": 9,
      "z": -23,
      "name": "Empty"
    },
    {
      "x": -7,
      "y": 10,
      "z": -23,
      "name": "Empty"
    },
    {
      "x": -7,
      "y": 11,
      "z": -23,
      "name": "Empty"
    },
    {
      "x": -7,
      "y": 12,
      "z": -23,
      "name": "Empty"
    },
    {
      "x": -7,
      "y": 13,
      "z": -23,
      "name": "Empty"
    },
    {
      "x": -7,
      "y": -5,
      "z": -22,
      "name": "Rock_Stone"
    },
    {
      "x": -7,
      "y": -4,
      "z": -22,
      "name": "Rock_Stone"
    },
    {
      "x": -7,
      "y": -3,
      "z": -22,
      "name": "Rock_Stone"
    },
    {
      "x": -7,
      "y": -2,
      "z": -22,
      "name": "Rock_Stone"
    },
    {
      "x": -7,
      "y": -1,
      "z": -22,
      "name": "Rock_Stone"
    },
    {
      "x": -7,
      "y": 0,
      "z": -22,
      "name": "Empty"
    },
    {
      "x": -7,
      "y": 1,
      "z": -22,
      "name": "Empty"
    },
    {
      "x": -7,
      "y": 2,
      "z": -22,
      "name": "Empty"
    },
    {
      "x": -7,
      "y": 3,
      "z": -22,
      "name": "Empty"
    },
    {
      "x": -7,
      "y": 4,
      "z": -22,
      "name": "Empty"
    },
    {
      "x": -7,
      "y": 5,
      "z": -22,
      "name": "Empty"
    },
    {
      "x": -7,
      "y": 6,
      "z": -22,
      "name": "Empty"
    },
    {
      "x": -7,
      "y": 7,
      "z": -22,
      "name": "Empty"
    },
    {
      "x": -7,
      "y": 8,
      "z": -22,
      "name": "Empty"
    },
    {
      "x": -7,
      "y": 9,
      "z": -22,
      "name": "Empty"
    },
    {
      "x": -7,
      "y": 10,
      "z": -22,
      "name": "Empty"
    },
    {
      "x": -7,
      "y": 11,
      "z": -22,
      "name": "Empty"
    },
    {
      "x": -7,
      "y": 12,
      "z": -22,
      "name": "Empty"
    },
    {
      "x": -7,
      "y": 13,
      "z": -22,
      "name": "Empty"
    },
    {
      "x": -7,
      "y": -5,
      "z": -21,
      "name": "Rock_Stone"
    },
    {
      "x": -7,
      "y": -4,
      "z": -21,
      "name": "Rock_Stone"
    },
    {
      "x": -7,
      "y": -3,
      "z": -21,
      "name": "Rock_Stone"
    },
    {
      "x": -7,
      "y": -2,
      "z": -21,
      "name": "Rock_Stone"
    },
    {
      "x": -7,
      "y": -1,
      "z": -21,
      "name": "Rock_Stone"
    },
    {
      "x": -7,
      "y": 0,
      "z": -21,
      "name": "Empty"
    },
    {
      "x": -7,
      "y": 1,
      "z": -21,
      "name": "Empty"
    },
    {
      "x": -7,
      "y": 2,
      "z": -21,
      "name": "Empty"
    },
    {
      "x": -7,
      "y": 3,
      "z": -21,
      "name": "Empty"
    },
    {
      "x": -7,
      "y": 4,
      "z": -21,
      "name": "Empty"
    },
    {
      "x": -7,
      "y": 5,
      "z": -21,
      "name": "Empty"
    },
    {
      "x": -7,
      "y": 6,
      "z": -21,
      "name": "Empty"
    },
    {
      "x": -7,
      "y": 7,
      "z": -21,
      "name": "Empty"
    },
    {
      "x": -7,
      "y": 8,
      "z": -21,
      "name": "Empty"
    },
    {
      "x": -7,
      "y": 9,
      "z": -21,
      "name": "Empty"
    },
    {
      "x": -7,
      "y": 10,
      "z": -21,
      "name": "Empty"
    },
    {
      "x": -7,
      "y": 11,
      "z": -21,
      "name": "Plant_Moss_Cave_Blue",
      "rotation": 8
    },
    {
      "x": -7,
      "y": 12,
      "z": -21,
      "name": "Plant_Moss_Block_Blue"
    },
    {
      "x": -7,
      "y": 13,
      "z": -21,
      "name": "Empty"
    },
    {
      "x": -7,
      "y": 14,
      "z": -21,
      "name": "Empty"
    },
    {
      "x": -7,
      "y": -5,
      "z": -20,
      "name": "Rock_Stone"
    },
    {
      "x": -7,
      "y": -4,
      "z": -20,
      "name": "Rock_Stone"
    },
    {
      "x": -7,
      "y": -3,
      "z": -20,
      "name": "Rock_Stone"
    },
    {
      "x": -7,
      "y": -2,
      "z": -20,
      "name": "Rock_Stone"
    },
    {
      "x": -7,
      "y": -1,
      "z": -20,
      "name": "Rock_Stone"
    },
    {
      "x": -7,
      "y": 0,
      "z": -20,
      "name": "Empty"
    },
    {
      "x": -7,
      "y": 1,
      "z": -20,
      "name": "Empty"
    },
    {
      "x": -7,
      "y": 2,
      "z": -20,
      "name": "Empty"
    },
    {
      "x": -7,
      "y": 3,
      "z": -20,
      "name": "Empty"
    },
    {
      "x": -7,
      "y": 4,
      "z": -20,
      "name": "Empty"
    },
    {
      "x": -7,
      "y": 5,
      "z": -20,
      "name": "Empty"
    },
    {
      "x": -7,
      "y": 6,
      "z": -20,
      "name": "Empty"
    },
    {
      "x": -7,
      "y": 7,
      "z": -20,
      "name": "Empty"
    },
    {
      "x": -7,
      "y": 8,
      "z": -20,
      "name": "Empty"
    },
    {
      "x": -7,
      "y": 9,
      "z": -20,
      "name": "Empty"
    },
    {
      "x": -7,
      "y": 10,
      "z": -20,
      "name": "Empty"
    },
    {
      "x": -7,
      "y": 11,
      "z": -20,
      "name": "Empty"
    },
    {
      "x": -7,
      "y": -5,
      "z": -19,
      "name": "Rock_Stone"
    },
    {
      "x": -7,
      "y": -4,
      "z": -19,
      "name": "Rock_Stone"
    },
    {
      "x": -7,
      "y": -3,
      "z": -19,
      "name": "Rock_Stone"
    },
    {
      "x": -7,
      "y": -2,
      "z": -19,
      "name": "Rock_Stone"
    },
    {
      "x": -7,
      "y": -1,
      "z": -19,
      "name": "Rock_Stone"
    },
    {
      "x": -7,
      "y": 0,
      "z": -19,
      "name": "Rubble_Stone"
    },
    {
      "x": -7,
      "y": 1,
      "z": -19,
      "name": "Empty"
    },
    {
      "x": -7,
      "y": 2,
      "z": -19,
      "name": "Empty"
    },
    {
      "x": -7,
      "y": 3,
      "z": -19,
      "name": "Empty"
    },
    {
      "x": -7,
      "y": 4,
      "z": -19,
      "name": "Empty"
    },
    {
      "x": -7,
      "y": 5,
      "z": -19,
      "name": "Empty"
    },
    {
      "x": -7,
      "y": 6,
      "z": -19,
      "name": "Empty"
    },
    {
      "x": -7,
      "y": 7,
      "z": -19,
      "name": "Empty"
    },
    {
      "x": -7,
      "y": 8,
      "z": -19,
      "name": "Empty"
    },
    {
      "x": -7,
      "y": 9,
      "z": -19,
      "name": "Empty"
    },
    {
      "x": -7,
      "y": 10,
      "z": -19,
      "name": "Empty"
    },
    {
      "x": -7,
      "y": 11,
      "z": -19,
      "name": "Empty"
    },
    {
      "x": -7,
      "y": -5,
      "z": -18,
      "name": "Rock_Stone"
    },
    {
      "x": -7,
      "y": -4,
      "z": -18,
      "name": "Rock_Stone"
    },
    {
      "x": -7,
      "y": -3,
      "z": -18,
      "name": "Rock_Stone"
    },
    {
      "x": -7,
      "y": -2,
      "z": -18,
      "name": "Rock_Stone"
    },
    {
      "x": -7,
      "y": -1,
      "z": -18,
      "name": "Plant_Moss_Block_Blue"
    },
    {
      "x": -7,
      "y": 0,
      "z": -18,
      "name": "Empty"
    },
    {
      "x": -7,
      "y": 1,
      "z": -18,
      "name": "Empty"
    },
    {
      "x": -7,
      "y": 2,
      "z": -18,
      "name": "Empty"
    },
    {
      "x": -7,
      "y": 3,
      "z": -18,
      "name": "Empty"
    },
    {
      "x": -7,
      "y": 4,
      "z": -18,
      "name": "Empty"
    },
    {
      "x": -7,
      "y": 5,
      "z": -18,
      "name": "Empty"
    },
    {
      "x": -7,
      "y": 6,
      "z": -18,
      "name": "Empty"
    },
    {
      "x": -7,
      "y": 7,
      "z": -18,
      "name": "Empty"
    },
    {
      "x": -7,
      "y": 8,
      "z": -18,
      "name": "Empty"
    },
    {
      "x": -7,
      "y": 9,
      "z": -18,
      "name": "Empty"
    },
    {
      "x": -7,
      "y": 10,
      "z": -18,
      "name": "Empty"
    },
    {
      "x": -7,
      "y": -5,
      "z": -17,
      "name": "Rock_Stone"
    },
    {
      "x": -7,
      "y": -4,
      "z": -17,
      "name": "Rock_Stone"
    },
    {
      "x": -7,
      "y": -3,
      "z": -17,
      "name": "Rock_Stone"
    },
    {
      "x": -7,
      "y": -2,
      "z": -17,
      "name": "Rock_Stone"
    },
    {
      "x": -7,
      "y": -1,
      "z": -17,
      "name": "Rock_Stone"
    },
    {
      "x": -7,
      "y": 0,
      "z": -17,
      "name": "Plant_Moss_Block_Blue"
    },
    {
      "x": -7,
      "y": 1,
      "z": -17,
      "name": "Empty"
    },
    {
      "x": -7,
      "y": 2,
      "z": -17,
      "name": "Empty"
    },
    {
      "x": -7,
      "y": 3,
      "z": -17,
      "name": "Empty"
    },
    {
      "x": -7,
      "y": 4,
      "z": -17,
      "name": "Empty"
    },
    {
      "x": -7,
      "y": 5,
      "z": -17,
      "name": "Empty"
    },
    {
      "x": -7,
      "y": 6,
      "z": -17,
      "name": "Empty"
    },
    {
      "x": -7,
      "y": 7,
      "z": -17,
      "name": "Empty"
    },
    {
      "x": -7,
      "y": 8,
      "z": -17,
      "name": "Empty"
    },
    {
      "x": -7,
      "y": -5,
      "z": -16,
      "name": "Rock_Stone"
    },
    {
      "x": -7,
      "y": -4,
      "z": -16,
      "name": "Rock_Stone"
    },
    {
      "x": -7,
      "y": -3,
      "z": -16,
      "name": "Rock_Stone"
    },
    {
      "x": -7,
      "y": -2,
      "z": -16,
      "name": "Rock_Stone"
    },
    {
      "x": -7,
      "y": -1,
      "z": -16,
      "name": "Rock_Stone"
    },
    {
      "x": -7,
      "y": 0,
      "z": -16,
      "name": "Rock_Stone"
    },
    {
      "x": -7,
      "y": 1,
      "z": -16,
      "name": "Rock_Stone"
    },
    {
      "x": -7,
      "y": 2,
      "z": -16,
      "name": "Rock_Stone"
    },
    {
      "x": -7,
      "y": 3,
      "z": -16,
      "name": "Rock_Stone"
    },
    {
      "x": -7,
      "y": 4,
      "z": -16,
      "name": "Empty"
    },
    {
      "x": -7,
      "y": 5,
      "z": -16,
      "name": "Empty"
    },
    {
      "x": -7,
      "y": 6,
      "z": -16,
      "name": "Empty"
    },
    {
      "x": -7,
      "y": -4,
      "z": -15,
      "name": "Rock_Stone"
    },
    {
      "x": -7,
      "y": -3,
      "z": -15,
      "name": "Rock_Stone"
    },
    {
      "x": -7,
      "y": -2,
      "z": -15,
      "name": "Rock_Stone"
    },
    {
      "x": -7,
      "y": -1,
      "z": -15,
      "name": "Rock_Stone"
    },
    {
      "x": -7,
      "y": 0,
      "z": -15,
      "name": "Rock_Stone"
    },
    {
      "x": -7,
      "y": 1,
      "z": -15,
      "name": "Rock_Stone"
    },
    {
      "x": -7,
      "y": 2,
      "z": -15,
      "name": "Rock_Stone"
    },
    {
      "x": -7,
      "y": 3,
      "z": -15,
      "name": "Rock_Stone"
    },
    {
      "x": -7,
      "y": 4,
      "z": -15,
      "name": "Rock_Stone"
    },
    {
      "x": -7,
      "y": 5,
      "z": -15,
      "name": "Empty"
    },
    {
      "x": -7,
      "y": -4,
      "z": -14,
      "name": "Rock_Stone"
    },
    {
      "x": -7,
      "y": -3,
      "z": -14,
      "name": "Rock_Stone"
    },
    {
      "x": -7,
      "y": -2,
      "z": -14,
      "name": "Rock_Stone"
    },
    {
      "x": -7,
      "y": -1,
      "z": -14,
      "name": "Rock_Stone"
    },
    {
      "x": -7,
      "y": 0,
      "z": -14,
      "name": "Rock_Stone"
    },
    {
      "x": -7,
      "y": 1,
      "z": -14,
      "name": "Rock_Stone"
    },
    {
      "x": -7,
      "y": 2,
      "z": -14,
      "name": "Rock_Stone"
    },
    {
      "x": -7,
      "y": 3,
      "z": -14,
      "name": "Rock_Stone"
    },
    {
      "x": -7,
      "y": 4,
      "z": -14,
      "name": "Rock_Stone"
    },
    {
      "x": -7,
      "y": -3,
      "z": -13,
      "name": "Rock_Stone"
    },
    {
      "x": -7,
      "y": -2,
      "z": -13,
      "name": "Rock_Stone"
    },
    {
      "x": -7,
      "y": -1,
      "z": -13,
      "name": "Rock_Stone"
    },
    {
      "x": -7,
      "y": 0,
      "z": -13,
      "name": "Rock_Stone"
    },
    {
      "x": -7,
      "y": 1,
      "z": -13,
      "name": "Rock_Stone"
    },
    {
      "x": -7,
      "y": 2,
      "z": -13,
      "name": "Rock_Stone"
    },
    {
      "x": -7,
      "y": 3,
      "z": -13,
      "name": "Rock_Stone"
    },
    {
      "x": -7,
      "y": 4,
      "z": -13,
      "name": "Rock_Stone"
    },
    {
      "x": -7,
      "y": -2,
      "z": -12,
      "name": "Rock_Stone"
    },
    {
      "x": -7,
      "y": -1,
      "z": -12,
      "name": "Rock_Stone"
    },
    {
      "x": -7,
      "y": 0,
      "z": -12,
      "name": "Rock_Stone"
    },
    {
      "x": -7,
      "y": 1,
      "z": -12,
      "name": "Rock_Stone"
    },
    {
      "x": -7,
      "y": 2,
      "z": -12,
      "name": "Rock_Stone"
    },
    {
      "x": -7,
      "y": 3,
      "z": -12,
      "name": "Rock_Stone"
    },
    {
      "x": -7,
      "y": -1,
      "z": -11,
      "name": "Rock_Stone"
    },
    {
      "x": -7,
      "y": 0,
      "z": -11,
      "name": "Rock_Stone"
    },
    {
      "x": -7,
      "y": 1,
      "z": -11,
      "name": "Rock_Stone"
    },
    {
      "x": -7,
      "y": 2,
      "z": -11,
      "name": "Rock_Stone"
    },
    {
      "x": -7,
      "y": 3,
      "z": -11,
      "name": "Rock_Stone"
    },
    {
      "x": -7,
      "y": -1,
      "z": -10,
      "name": "Rock_Stone"
    },
    {
      "x": -7,
      "y": 0,
      "z": -10,
      "name": "Rock_Stone"
    },
    {
      "x": -7,
      "y": 1,
      "z": -10,
      "name": "Plant_Moss_Block_Blue"
    },
    {
      "x": -7,
      "y": 2,
      "z": -10,
      "name": "Plant_Moss_Block_Blue"
    },
    {
      "x": -7,
      "y": 3,
      "z": -10,
      "name": "Plant_Crop_Mushroom_Common_Blue",
      "components": {
        "Components": {
          "FarmingBlock": {}
        }
      }
    },
    {
      "x": -7,
      "y": 4,
      "z": -10,
      "name": "Empty"
    },
    {
      "x": -7,
      "y": 5,
      "z": -10,
      "name": "Empty"
    },
    {
      "x": -7,
      "y": 6,
      "z": -10,
      "name": "Empty"
    },
    {
      "x": -7,
      "y": 7,
      "z": -10,
      "name": "Empty"
    },
    {
      "x": -7,
      "y": 8,
      "z": -10,
      "name": "Empty"
    },
    {
      "x": -7,
      "y": 9,
      "z": -10,
      "name": "Empty"
    },
    {
      "x": -7,
      "y": -1,
      "z": -9,
      "name": "Rock_Stone"
    },
    {
      "x": -7,
      "y": 0,
      "z": -9,
      "name": "Rock_Stone"
    },
    {
      "x": -7,
      "y": 1,
      "z": -9,
      "name": "Plant_Moss_Block_Blue"
    },
    {
      "x": -7,
      "y": 2,
      "z": -9,
      "name": "Furniture_Ancient_Barrel"
    },
    {
      "x": -7,
      "y": 3,
      "z": -9,
      "name": "Empty"
    },
    {
      "x": -7,
      "y": 4,
      "z": -9,
      "name": "Empty"
    },
    {
      "x": -7,
      "y": 5,
      "z": -9,
      "name": "Empty"
    },
    {
      "x": -7,
      "y": 6,
      "z": -9,
      "name": "Empty"
    },
    {
      "x": -7,
      "y": 7,
      "z": -9,
      "name": "Empty"
    },
    {
      "x": -7,
      "y": 8,
      "z": -9,
      "name": "Empty"
    },
    {
      "x": -7,
      "y": 9,
      "z": -9,
      "name": "Empty"
    },
    {
      "x": -7,
      "y": 10,
      "z": -9,
      "name": "Empty"
    },
    {
      "x": -7,
      "y": 11,
      "z": -9,
      "name": "Empty"
    },
    {
      "x": -7,
      "y": -1,
      "z": -8,
      "name": "Rock_Stone"
    },
    {
      "x": -7,
      "y": 0,
      "z": -8,
      "name": "Rock_Stone"
    },
    {
      "x": -7,
      "y": 1,
      "z": -8,
      "name": "Rock_Stone_Brick"
    },
    {
      "x": -7,
      "y": 2,
      "z": -8,
      "name": "Block_Spawner_Block",
      "components": {
        "Components": {
          "BlockSpawner": {
            "BlockSpawnerId": "Zone1_Encounters_Tier3"
          }
        }
      },
      "rotation": 1
    },
    {
      "x": -7,
      "y": 3,
      "z": -8,
      "name": "Empty"
    },
    {
      "x": -7,
      "y": 4,
      "z": -8,
      "name": "Empty"
    },
    {
      "x": -7,
      "y": 5,
      "z": -8,
      "name": "Empty"
    },
    {
      "x": -7,
      "y": 6,
      "z": -8,
      "name": "Empty"
    },
    {
      "x": -7,
      "y": 7,
      "z": -8,
      "name": "Empty"
    },
    {
      "x": -7,
      "y": 8,
      "z": -8,
      "name": "Empty"
    },
    {
      "x": -7,
      "y": 9,
      "z": -8,
      "name": "Empty"
    },
    {
      "x": -7,
      "y": 10,
      "z": -8,
      "name": "Empty"
    },
    {
      "x": -7,
      "y": 11,
      "z": -8,
      "name": "Empty"
    },
    {
      "x": -7,
      "y": -1,
      "z": -7,
      "name": "Rock_Stone"
    },
    {
      "x": -7,
      "y": 0,
      "z": -7,
      "name": "Rock_Stone"
    },
    {
      "x": -7,
      "y": 1,
      "z": -7,
      "name": "Rock_Stone_Brick"
    },
    {
      "x": -7,
      "y": 2,
      "z": -7,
      "name": "Furniture_Ancient_Bookshelf",
      "rotation": 1
    },
    {
      "x": -7,
      "y": 3,
      "z": -7,
      "name": "Empty"
    },
    {
      "x": -7,
      "y": 4,
      "z": -7,
      "name": "Empty"
    },
    {
      "x": -7,
      "y": 5,
      "z": -7,
      "name": "Empty"
    },
    {
      "x": -7,
      "y": 6,
      "z": -7,
      "name": "Empty"
    },
    {
      "x": -7,
      "y": 7,
      "z": -7,
      "name": "Empty"
    },
    {
      "x": -7,
      "y": 8,
      "z": -7,
      "name": "Empty"
    },
    {
      "x": -7,
      "y": 9,
      "z": -7,
      "name": "Empty"
    },
    {
      "x": -7,
      "y": 10,
      "z": -7,
      "name": "Empty"
    },
    {
      "x": -7,
      "y": -1,
      "z": -6,
      "name": "Rock_Stone"
    },
    {
      "x": -7,
      "y": 0,
      "z": -6,
      "name": "Rock_Stone"
    },
    {
      "x": -7,
      "y": 1,
      "z": -6,
      "name": "Rock_Stone_Brick"
    },
    {
      "x": -7,
      "y": 2,
      "z": -6,
      "name": "Empty"
    },
    {
      "x": -7,
      "y": 3,
      "z": -6,
      "name": "Empty"
    },
    {
      "x": -7,
      "y": 4,
      "z": -6,
      "name": "Empty"
    },
    {
      "x": -7,
      "y": 5,
      "z": -6,
      "name": "Empty"
    },
    {
      "x": -7,
      "y": 6,
      "z": -6,
      "name": "Empty"
    },
    {
      "x": -7,
      "y": 7,
      "z": -6,
      "name": "Empty"
    },
    {
      "x": -7,
      "y": 8,
      "z": -6,
      "name": "Empty"
    },
    {
      "x": -7,
      "y": -1,
      "z": -5,
      "name": "Rock_Stone"
    },
    {
      "x": -7,
      "y": 0,
      "z": -5,
      "name": "Rock_Stone"
    },
    {
      "x": -7,
      "y": 1,
      "z": -5,
      "name": "Rock_Quartzite_Cobble"
    },
    {
      "x": -7,
      "y": 2,
      "z": -5,
      "name": "Rock_Quartzite_Cobble"
    },
    {
      "x": -7,
      "y": 3,
      "z": -5,
      "name": "Rock_Quartzite_Brick"
    },
    {
      "x": -7,
      "y": 4,
      "z": -5,
      "name": "Rock_Quartzite_Brick_Smooth"
    },
    {
      "x": -7,
      "y": 5,
      "z": -5,
      "name": "Rock_Quartzite_Brick_Pillar_Base"
    },
    {
      "x": -7,
      "y": 6,
      "z": -5,
      "name": "Rock_Quartzite_Brick_Pillar_Middle"
    },
    {
      "x": -7,
      "y": 7,
      "z": -5,
      "name": "Empty"
    },
    {
      "x": -7,
      "y": -1,
      "z": -4,
      "name": "Rock_Stone"
    },
    {
      "x": -7,
      "y": 0,
      "z": -4,
      "name": "Rock_Stone"
    },
    {
      "x": -7,
      "y": 1,
      "z": -4,
      "name": "Rock_Quartzite_Cobble"
    },
    {
      "x": -7,
      "y": 2,
      "z": -4,
      "name": "Rock_Quartzite_Brick"
    },
    {
      "x": -7,
      "y": 3,
      "z": -4,
      "name": "Rock_Quartzite_Brick"
    },
    {
      "x": -7,
      "y": 0,
      "z": -3,
      "name": "Rock_Stone"
    },
    {
      "x": -7,
      "y": 1,
      "z": -3,
      "name": "Rock_Stone"
    },
    {
      "x": -7,
      "y": 2,
      "z": -3,
      "name": "Rock_Stone"
    },
    {
      "x": -7,
      "y": 0,
      "z": -2,
      "name": "Rock_Stone"
    },
    {
      "x": -7,
      "y": 1,
      "z": -2,
      "name": "Rock_Stone"
    },
    {
      "x": -6,
      "y": -2,
      "z": -33,
      "name": "Rock_Stone"
    },
    {
      "x": -6,
      "y": -1,
      "z": -33,
      "name": "Rock_Stone"
    },
    {
      "x": -6,
      "y": -5,
      "z": -32,
      "name": "Rock_Stone"
    },
    {
      "x": -6,
      "y": -4,
      "z": -32,
      "name": "Rock_Stone"
    },
    {
      "x": -6,
      "y": -3,
      "z": -32,
      "name": "Rock_Stone"
    },
    {
      "x": -6,
      "y": -2,
      "z": -32,
      "name": "Rock_Stone"
    },
    {
      "x": -6,
      "y": -1,
      "z": -32,
      "name": "Rock_Stone"
    },
    {
      "x": -6,
      "y": 0,
      "z": -32,
      "name": "Rock_Stone"
    },
    {
      "x": -6,
      "y": -5,
      "z": -31,
      "name": "Rock_Stone"
    },
    {
      "x": -6,
      "y": -4,
      "z": -31,
      "name": "Rock_Stone"
    },
    {
      "x": -6,
      "y": -3,
      "z": -31,
      "name": "Rock_Stone"
    },
    {
      "x": -6,
      "y": -2,
      "z": -31,
      "name": "Rock_Stone"
    },
    {
      "x": -6,
      "y": 3,
      "z": -31,
      "name": "Empty"
    },
    {
      "x": -6,
      "y": 4,
      "z": -31,
      "name": "Empty"
    },
    {
      "x": -6,
      "y": 5,
      "z": -31,
      "name": "Empty"
    },
    {
      "x": -6,
      "y": 6,
      "z": -31,
      "name": "Empty"
    },
    {
      "x": -6,
      "y": -5,
      "z": -30,
      "name": "Rock_Stone"
    },
    {
      "x": -6,
      "y": -4,
      "z": -30,
      "name": "Rock_Stone"
    },
    {
      "x": -6,
      "y": -3,
      "z": -30,
      "name": "Rock_Stone"
    },
    {
      "x": -6,
      "y": 0,
      "z": -30,
      "name": "Empty"
    },
    {
      "x": -6,
      "y": 1,
      "z": -30,
      "name": "Empty"
    },
    {
      "x": -6,
      "y": 2,
      "z": -30,
      "name": "Empty"
    },
    {
      "x": -6,
      "y": 3,
      "z": -30,
      "name": "Empty"
    },
    {
      "x": -6,
      "y": 4,
      "z": -30,
      "name": "Empty"
    },
    {
      "x": -6,
      "y": 5,
      "z": -30,
      "name": "Empty"
    },
    {
      "x": -6,
      "y": 6,
      "z": -30,
      "name": "Empty"
    },
    {
      "x": -6,
      "y": 7,
      "z": -30,
      "name": "Empty"
    },
    {
      "x": -6,
      "y": 9,
      "z": -30,
      "name": "Plant_Moss_Block_Blue"
    },
    {
      "x": -6,
      "y": -5,
      "z": -29,
      "name": "Rock_Stone"
    },
    {
      "x": -6,
      "y": -4,
      "z": -29,
      "name": "Rock_Stone"
    },
    {
      "x": -6,
      "y": -3,
      "z": -29,
      "name": "Rock_Stone"
    },
    {
      "x": -6,
      "y": -1,
      "z": -29,
      "name": "Empty"
    },
    {
      "x": -6,
      "y": 0,
      "z": -29,
      "name": "Empty"
    },
    {
      "x": -6,
      "y": 1,
      "z": -29,
      "name": "Empty"
    },
    {
      "x": -6,
      "y": 2,
      "z": -29,
      "name": "Empty"
    },
    {
      "x": -6,
      "y": 3,
      "z": -29,
      "name": "Empty"
    },
    {
      "x": -6,
      "y": 4,
      "z": -29,
      "name": "Empty"
    },
    {
      "x": -6,
      "y": 5,
      "z": -29,
      "name": "Empty"
    },
    {
      "x": -6,
      "y": 6,
      "z": -29,
      "name": "Empty"
    },
    {
      "x": -6,
      "y": 7,
      "z": -29,
      "name": "Plant_Moss_Cave_Blue",
      "rotation": 8
    },
    {
      "x": -6,
      "y": 8,
      "z": -29,
      "name": "Plant_Moss_Block_Blue"
    },
    {
      "x": -6,
      "y": 9,
      "z": -29,
      "name": "Plant_Moss_Rug_Blue"
    },
    {
      "x": -6,
      "y": 10,
      "z": -29,
      "name": "Empty"
    },
    {
      "x": -6,
      "y": -5,
      "z": -28,
      "name": "Rock_Stone"
    },
    {
      "x": -6,
      "y": -4,
      "z": -28,
      "name": "Rock_Stone"
    },
    {
      "x": -6,
      "y": -3,
      "z": -28,
      "name": "Rock_Stone"
    },
    {
      "x": -6,
      "y": -1,
      "z": -28,
      "name": "Empty"
    },
    {
      "x": -6,
      "y": 0,
      "z": -28,
      "name": "Empty"
    },
    {
      "x": -6,
      "y": 1,
      "z": -28,
      "name": "Empty"
    },
    {
      "x": -6,
      "y": 2,
      "z": -28,
      "name": "Empty"
    },
    {
      "x": -6,
      "y": 3,
      "z": -28,
      "name": "Empty"
    },
    {
      "x": -6,
      "y": 4,
      "z": -28,
      "name": "Empty"
    },
    {
      "x": -6,
      "y": 5,
      "z": -28,
      "name": "Empty"
    },
    {
      "x": -6,
      "y": 6,
      "z": -28,
      "name": "Empty"
    },
    {
      "x": -6,
      "y": 7,
      "z": -28,
      "name": "Empty"
    },
    {
      "x": -6,
      "y": 8,
      "z": -28,
      "name": "Empty"
    },
    {
      "x": -6,
      "y": 9,
      "z": -28,
      "name": "Empty"
    },
    {
      "x": -6,
      "y": 10,
      "z": -28,
      "name": "Empty"
    },
    {
      "x": -6,
      "y": -5,
      "z": -27,
      "name": "Rock_Stone"
    },
    {
      "x": -6,
      "y": -4,
      "z": -27,
      "name": "Rock_Stone"
    },
    {
      "x": -6,
      "y": -3,
      "z": -27,
      "name": "Rock_Stone"
    },
    {
      "x": -6,
      "y": -2,
      "z": -27,
      "name": "Rock_Stone"
    },
    {
      "x": -6,
      "y": -1,
      "z": -27,
      "name": "Rock_Stone"
    },
    {
      "x": -6,
      "y": 0,
      "z": -27,
      "name": "Empty"
    },
    {
      "x": -6,
      "y": 1,
      "z": -27,
      "name": "Empty"
    },
    {
      "x": -6,
      "y": 2,
      "z": -27,
      "name": "Empty"
    },
    {
      "x": -6,
      "y": 3,
      "z": -27,
      "name": "Empty"
    },
    {
      "x": -6,
      "y": 4,
      "z": -27,
      "name": "Empty"
    },
    {
      "x": -6,
      "y": 5,
      "z": -27,
      "name": "Empty"
    },
    {
      "x": -6,
      "y": 6,
      "z": -27,
      "name": "Empty"
    },
    {
      "x": -6,
      "y": 7,
      "z": -27,
      "name": "Empty"
    },
    {
      "x": -6,
      "y": 8,
      "z": -27,
      "name": "Empty"
    },
    {
      "x": -6,
      "y": 9,
      "z": -27,
      "name": "Empty"
    },
    {
      "x": -6,
      "y": 10,
      "z": -27,
      "name": "Empty"
    },
    {
      "x": -6,
      "y": -5,
      "z": -26,
      "name": "Rock_Stone"
    },
    {
      "x": -6,
      "y": -4,
      "z": -26,
      "name": "Rock_Stone"
    },
    {
      "x": -6,
      "y": -3,
      "z": -26,
      "name": "Rock_Stone"
    },
    {
      "x": -6,
      "y": -2,
      "z": -26,
      "name": "Rock_Stone"
    },
    {
      "x": -6,
      "y": -1,
      "z": -26,
      "name": "Rock_Stone"
    },
    {
      "x": -6,
      "y": 0,
      "z": -26,
      "name": "Empty"
    },
    {
      "x": -6,
      "y": 1,
      "z": -26,
      "name": "Empty"
    },
    {
      "x": -6,
      "y": 2,
      "z": -26,
      "name": "Empty"
    },
    {
      "x": -6,
      "y": 3,
      "z": -26,
      "name": "Empty"
    },
    {
      "x": -6,
      "y": 4,
      "z": -26,
      "name": "Empty"
    },
    {
      "x": -6,
      "y": 5,
      "z": -26,
      "name": "Empty"
    },
    {
      "x": -6,
      "y": 6,
      "z": -26,
      "name": "Empty"
    },
    {
      "x": -6,
      "y": 7,
      "z": -26,
      "name": "Empty"
    },
    {
      "x": -6,
      "y": 8,
      "z": -26,
      "name": "Empty"
    },
    {
      "x": -6,
      "y": 9,
      "z": -26,
      "name": "Empty"
    },
    {
      "x": -6,
      "y": 10,
      "z": -26,
      "name": "Empty"
    },
    {
      "x": -6,
      "y": 11,
      "z": -26,
      "name": "Empty"
    },
    {
      "x": -6,
      "y": -5,
      "z": -25,
      "name": "Rock_Stone"
    },
    {
      "x": -6,
      "y": -4,
      "z": -25,
      "name": "Rock_Stone"
    },
    {
      "x": -6,
      "y": -3,
      "z": -25,
      "name": "Rock_Stone"
    },
    {
      "x": -6,
      "y": -2,
      "z": -25,
      "name": "Rock_Stone"
    },
    {
      "x": -6,
      "y": -1,
      "z": -25,
      "name": "Rock_Stone"
    },
    {
      "x": -6,
      "y": 0,
      "z": -25,
      "name": "Empty"
    },
    {
      "x": -6,
      "y": 1,
      "z": -25,
      "name": "Empty"
    },
    {
      "x": -6,
      "y": 2,
      "z": -25,
      "name": "Empty"
    },
    {
      "x": -6,
      "y": 3,
      "z": -25,
      "name": "Empty"
    },
    {
      "x": -6,
      "y": 4,
      "z": -25,
      "name": "Empty"
    },
    {
      "x": -6,
      "y": 5,
      "z": -25,
      "name": "Empty"
    },
    {
      "x": -6,
      "y": 6,
      "z": -25,
      "name": "Empty"
    },
    {
      "x": -6,
      "y": 7,
      "z": -25,
      "name": "Empty"
    },
    {
      "x": -6,
      "y": 8,
      "z": -25,
      "name": "Empty"
    },
    {
      "x": -6,
      "y": 9,
      "z": -25,
      "name": "Empty"
    },
    {
      "x": -6,
      "y": 10,
      "z": -25,
      "name": "Empty"
    },
    {
      "x": -6,
      "y": 11,
      "z": -25,
      "name": "Empty"
    },
    {
      "x": -6,
      "y": -5,
      "z": -24,
      "name": "Rock_Stone"
    },
    {
      "x": -6,
      "y": -4,
      "z": -24,
      "name": "Rock_Stone"
    },
    {
      "x": -6,
      "y": -3,
      "z": -24,
      "name": "Rock_Stone"
    },
    {
      "x": -6,
      "y": -2,
      "z": -24,
      "name": "Rock_Stone"
    },
    {
      "x": -6,
      "y": -1,
      "z": -24,
      "name": "Rock_Stone"
    },
    {
      "x": -6,
      "y": 0,
      "z": -24,
      "name": "Empty"
    },
    {
      "x": -6,
      "y": 1,
      "z": -24,
      "name": "Empty"
    },
    {
      "x": -6,
      "y": 2,
      "z": -24,
      "name": "Empty"
    },
    {
      "x": -6,
      "y": 3,
      "z": -24,
      "name": "Empty"
    },
    {
      "x": -6,
      "y": 4,
      "z": -24,
      "name": "Empty"
    },
    {
      "x": -6,
      "y": 5,
      "z": -24,
      "name": "Empty"
    },
    {
      "x": -6,
      "y": 6,
      "z": -24,
      "name": "Empty"
    },
    {
      "x": -6,
      "y": 7,
      "z": -24,
      "name": "Empty"
    },
    {
      "x": -6,
      "y": 8,
      "z": -24,
      "name": "Empty"
    },
    {
      "x": -6,
      "y": 9,
      "z": -24,
      "name": "Empty"
    },
    {
      "x": -6,
      "y": 10,
      "z": -24,
      "name": "Empty"
    },
    {
      "x": -6,
      "y": 11,
      "z": -24,
      "name": "Empty"
    },
    {
      "x": -6,
      "y": 12,
      "z": -24,
      "name": "Empty"
    },
    {
      "x": -6,
      "y": -5,
      "z": -23,
      "name": "Rock_Stone"
    },
    {
      "x": -6,
      "y": -4,
      "z": -23,
      "name": "Rock_Stone"
    },
    {
      "x": -6,
      "y": -3,
      "z": -23,
      "name": "Rock_Stone"
    },
    {
      "x": -6,
      "y": -2,
      "z": -23,
      "name": "Rock_Stone"
    },
    {
      "x": -6,
      "y": -1,
      "z": -23,
      "name": "Rock_Stone"
    },
    {
      "x": -6,
      "y": 0,
      "z": -23,
      "name": "Empty"
    },
    {
      "x": -6,
      "y": 1,
      "z": -23,
      "name": "Empty"
    },
    {
      "x": -6,
      "y": 2,
      "z": -23,
      "name": "Empty"
    },
    {
      "x": -6,
      "y": 3,
      "z": -23,
      "name": "Empty"
    },
    {
      "x": -6,
      "y": 4,
      "z": -23,
      "name": "Empty"
    },
    {
      "x": -6,
      "y": 5,
      "z": -23,
      "name": "Empty"
    },
    {
      "x": -6,
      "y": 6,
      "z": -23,
      "name": "Empty"
    },
    {
      "x": -6,
      "y": 7,
      "z": -23,
      "name": "Empty"
    },
    {
      "x": -6,
      "y": 8,
      "z": -23,
      "name": "Empty"
    },
    {
      "x": -6,
      "y": 9,
      "z": -23,
      "name": "Empty"
    },
    {
      "x": -6,
      "y": 10,
      "z": -23,
      "name": "Empty"
    },
    {
      "x": -6,
      "y": 11,
      "z": -23,
      "name": "Empty"
    },
    {
      "x": -6,
      "y": 12,
      "z": -23,
      "name": "Empty"
    },
    {
      "x": -6,
      "y": -5,
      "z": -22,
      "name": "Rock_Stone"
    },
    {
      "x": -6,
      "y": -4,
      "z": -22,
      "name": "Rock_Stone"
    },
    {
      "x": -6,
      "y": -3,
      "z": -22,
      "name": "Rock_Stone"
    },
    {
      "x": -6,
      "y": -2,
      "z": -22,
      "name": "Rock_Stone"
    },
    {
      "x": -6,
      "y": -1,
      "z": -22,
      "name": "Rock_Stone"
    },
    {
      "x": -6,
      "y": 0,
      "z": -22,
      "name": "Rock_Stone_Brick_Wall",
      "rotation": 1
    },
    {
      "x": -6,
      "y": 1,
      "z": -22,
      "name": "Empty"
    },
    {
      "x": -6,
      "y": 2,
      "z": -22,
      "name": "Empty"
    },
    {
      "x": -6,
      "y": 3,
      "z": -22,
      "name": "Empty"
    },
    {
      "x": -6,
      "y": 4,
      "z": -22,
      "name": "Empty"
    },
    {
      "x": -6,
      "y": 5,
      "z": -22,
      "name": "Empty"
    },
    {
      "x": -6,
      "y": 6,
      "z": -22,
      "name": "Empty"
    },
    {
      "x": -6,
      "y": 7,
      "z": -22,
      "name": "Empty"
    },
    {
      "x": -6,
      "y": 8,
      "z": -22,
      "name": "Empty"
    },
    {
      "x": -6,
      "y": 9,
      "z": -22,
      "name": "Empty"
    },
    {
      "x": -6,
      "y": 10,
      "z": -22,
      "name": "Empty"
    },
    {
      "x": -6,
      "y": 11,
      "z": -22,
      "name": "Empty"
    },
    {
      "x": -6,
      "y": 12,
      "z": -22,
      "name": "Empty"
    },
    {
      "x": -6,
      "y": 13,
      "z": -22,
      "name": "Empty"
    },
    {
      "x": -6,
      "y": -5,
      "z": -21,
      "name": "Rock_Stone"
    },
    {
      "x": -6,
      "y": -4,
      "z": -21,
      "name": "Rock_Stone"
    },
    {
      "x": -6,
      "y": -3,
      "z": -21,
      "name": "Rock_Stone"
    },
    {
      "x": -6,
      "y": -2,
      "z": -21,
      "name": "Rock_Stone"
    },
    {
      "x": -6,
      "y": -1,
      "z": -21,
      "name": "Rock_Stone"
    },
    {
      "x": -6,
      "y": 0,
      "z": -21,
      "name": "Rock_Stone_Brick_Wall",
      "rotation": 1
    },
    {
      "x": -6,
      "y": 1,
      "z": -21,
      "name": "Empty"
    },
    {
      "x": -6,
      "y": 2,
      "z": -21,
      "name": "Empty"
    },
    {
      "x": -6,
      "y": 3,
      "z": -21,
      "name": "Empty"
    },
    {
      "x": -6,
      "y": 4,
      "z": -21,
      "name": "Empty"
    },
    {
      "x": -6,
      "y": 5,
      "z": -21,
      "name": "Empty"
    },
    {
      "x": -6,
      "y": 6,
      "z": -21,
      "name": "Empty"
    },
    {
      "x": -6,
      "y": 7,
      "z": -21,
      "name": "Empty"
    },
    {
      "x": -6,
      "y": 8,
      "z": -21,
      "name": "Empty"
    },
    {
      "x": -6,
      "y": 9,
      "z": -21,
      "name": "Empty"
    },
    {
      "x": -6,
      "y": 10,
      "z": -21,
      "name": "Empty"
    },
    {
      "x": -6,
      "y": 11,
      "z": -21,
      "name": "Empty"
    },
    {
      "x": -6,
      "y": 12,
      "z": -21,
      "name": "Empty"
    },
    {
      "x": -6,
      "y": 13,
      "z": -21,
      "name": "Empty"
    },
    {
      "x": -6,
      "y": 14,
      "z": -21,
      "name": "Empty"
    },
    {
      "x": -6,
      "y": -6,
      "z": -20,
      "name": "Rock_Stone"
    },
    {
      "x": -6,
      "y": -5,
      "z": -20,
      "name": "Rock_Stone"
    },
    {
      "x": -6,
      "y": -4,
      "z": -20,
      "name": "Rock_Stone"
    },
    {
      "x": -6,
      "y": -3,
      "z": -20,
      "name": "Rock_Stone"
    },
    {
      "x": -6,
      "y": -2,
      "z": -20,
      "name": "Rock_Stone"
    },
    {
      "x": -6,
      "y": -1,
      "z": -20,
      "name": "Rock_Stone"
    },
    {
      "x": -6,
      "y": 0,
      "z": -20,
      "name": "Rock_Stone_Brick_Pillar_Base"
    },
    {
      "x": -6,
      "y": 1,
      "z": -20,
      "name": "Rock_Stone_Brick_Pillar_Middle"
    },
    {
      "x": -6,
      "y": 2,
      "z": -20,
      "name": "Empty"
    },
    {
      "x": -6,
      "y": 3,
      "z": -20,
      "name": "Empty"
    },
    {
      "x": -6,
      "y": 4,
      "z": -20,
      "name": "Empty"
    },
    {
      "x": -6,
      "y": 5,
      "z": -20,
      "name": "Empty"
    },
    {
      "x": -6,
      "y": 6,
      "z": -20,
      "name": "Empty"
    },
    {
      "x": -6,
      "y": 7,
      "z": -20,
      "name": "Empty"
    },
    {
      "x": -6,
      "y": 8,
      "z": -20,
      "name": "Empty"
    },
    {
      "x": -6,
      "y": 9,
      "z": -20,
      "name": "Empty"
    },
    {
      "x": -6,
      "y": 10,
      "z": -20,
      "name": "Empty"
    },
    {
      "x": -6,
      "y": 11,
      "z": -20,
      "name": "Empty"
    },
    {
      "x": -6,
      "y": 12,
      "z": -20,
      "name": "Empty"
    },
    {
      "x": -6,
      "y": -6,
      "z": -19,
      "name": "Rock_Stone"
    },
    {
      "x": -6,
      "y": -5,
      "z": -19,
      "name": "Rock_Stone"
    },
    {
      "x": -6,
      "y": -4,
      "z": -19,
      "name": "Rock_Stone"
    },
    {
      "x": -6,
      "y": -3,
      "z": -19,
      "name": "Rock_Stone"
    },
    {
      "x": -6,
      "y": -1,
      "z": -19,
      "name": "Empty"
    },
    {
      "x": -6,
      "y": 0,
      "z": -19,
      "name": "Empty"
    },
    {
      "x": -6,
      "y": 1,
      "z": -19,
      "name": "Empty"
    },
    {
      "x": -6,
      "y": 2,
      "z": -19,
      "name": "Empty"
    },
    {
      "x": -6,
      "y": 3,
      "z": -19,
      "name": "Empty"
    },
    {
      "x": -6,
      "y": 4,
      "z": -19,
      "name": "Empty"
    },
    {
      "x": -6,
      "y": 5,
      "z": -19,
      "name": "Empty"
    },
    {
      "x": -6,
      "y": 6,
      "z": -19,
      "name": "Empty"
    },
    {
      "x": -6,
      "y": 7,
      "z": -19,
      "name": "Empty"
    },
    {
      "x": -6,
      "y": 8,
      "z": -19,
      "name": "Empty"
    },
    {
      "x": -6,
      "y": 9,
      "z": -19,
      "name": "Empty"
    },
    {
      "x": -6,
      "y": 10,
      "z": -19,
      "name": "Empty"
    },
    {
      "x": -6,
      "y": 11,
      "z": -19,
      "name": "Empty"
    },
    {
      "x": -6,
      "y": 12,
      "z": -19,
      "name": "Empty"
    },
    {
      "x": -6,
      "y": -6,
      "z": -18,
      "name": "Rock_Stone"
    },
    {
      "x": -6,
      "y": -5,
      "z": -18,
      "name": "Rock_Stone"
    },
    {
      "x": -6,
      "y": -4,
      "z": -18,
      "name": "Rock_Stone"
    },
    {
      "x": -6,
      "y": -3,
      "z": -18,
      "name": "Rock_Stone"
    },
    {
      "x": -6,
      "y": -1,
      "z": -18,
      "name": "Empty"
    },
    {
      "x": -6,
      "y": 0,
      "z": -18,
      "name": "Empty"
    },
    {
      "x": -6,
      "y": 1,
      "z": -18,
      "name": "Empty"
    },
    {
      "x": -6,
      "y": 2,
      "z": -18,
      "name": "Empty"
    },
    {
      "x": -6,
      "y": 3,
      "z": -18,
      "name": "Empty"
    },
    {
      "x": -6,
      "y": 4,
      "z": -18,
      "name": "Empty"
    },
    {
      "x": -6,
      "y": 5,
      "z": -18,
      "name": "Empty"
    },
    {
      "x": -6,
      "y": 6,
      "z": -18,
      "name": "Empty"
    },
    {
      "x": -6,
      "y": 7,
      "z": -18,
      "name": "Empty"
    },
    {
      "x": -6,
      "y": 8,
      "z": -18,
      "name": "Empty"
    },
    {
      "x": -6,
      "y": 9,
      "z": -18,
      "name": "Empty"
    },
    {
      "x": -6,
      "y": 10,
      "z": -18,
      "name": "Empty"
    },
    {
      "x": -6,
      "y": 11,
      "z": -18,
      "name": "Empty"
    },
    {
      "x": -6,
      "y": -5,
      "z": -17,
      "name": "Rock_Stone"
    },
    {
      "x": -6,
      "y": -4,
      "z": -17,
      "name": "Rock_Stone"
    },
    {
      "x": -6,
      "y": -3,
      "z": -17,
      "name": "Rock_Stone"
    },
    {
      "x": -6,
      "y": -2,
      "z": -17,
      "name": "Rock_Stone"
    },
    {
      "x": -6,
      "y": -1,
      "z": -17,
      "name": "Rock_Stone"
    },
    {
      "x": -6,
      "y": 0,
      "z": -17,
      "name": "Rock_Stone"
    },
    {
      "x": -6,
      "y": 1,
      "z": -17,
      "name": "Empty"
    },
    {
      "x": -6,
      "y": 2,
      "z": -17,
      "name": "Empty"
    },
    {
      "x": -6,
      "y": 3,
      "z": -17,
      "name": "Empty"
    },
    {
      "x": -6,
      "y": 4,
      "z": -17,
      "name": "Empty"
    },
    {
      "x": -6,
      "y": 5,
      "z": -17,
      "name": "Empty"
    },
    {
      "x": -6,
      "y": 6,
      "z": -17,
      "name": "Empty"
    },
    {
      "x": -6,
      "y": 7,
      "z": -17,
      "name": "Empty"
    },
    {
      "x": -6,
      "y": 8,
      "z": -17,
      "name": "Empty"
    },
    {
      "x": -6,
      "y": 9,
      "z": -17,
      "name": "Empty"
    },
    {
      "x": -6,
      "y": -5,
      "z": -16,
      "name": "Rock_Stone"
    },
    {
      "x": -6,
      "y": -4,
      "z": -16,
      "name": "Rock_Stone"
    },
    {
      "x": -6,
      "y": -3,
      "z": -16,
      "name": "Rock_Stone"
    },
    {
      "x": -6,
      "y": -2,
      "z": -16,
      "name": "Rock_Stone"
    },
    {
      "x": -6,
      "y": -1,
      "z": -16,
      "name": "Rock_Stone"
    },
    {
      "x": -6,
      "y": 0,
      "z": -16,
      "name": "Rock_Stone"
    },
    {
      "x": -6,
      "y": 1,
      "z": -16,
      "name": "Rock_Stone"
    },
    {
      "x": -6,
      "y": 2,
      "z": -16,
      "name": "Rock_Stone"
    },
    {
      "x": -6,
      "y": 3,
      "z": -16,
      "name": "Rock_Stone"
    },
    {
      "x": -6,
      "y": 4,
      "z": -16,
      "name": "Empty"
    },
    {
      "x": -6,
      "y": 5,
      "z": -16,
      "name": "Empty"
    },
    {
      "x": -6,
      "y": 6,
      "z": -16,
      "name": "Empty"
    },
    {
      "x": -6,
      "y": 7,
      "z": -16,
      "name": "Empty"
    },
    {
      "x": -6,
      "y": -5,
      "z": -15,
      "name": "Rock_Stone"
    },
    {
      "x": -6,
      "y": -4,
      "z": -15,
      "name": "Rock_Stone"
    },
    {
      "x": -6,
      "y": -3,
      "z": -15,
      "name": "Rock_Stone"
    },
    {
      "x": -6,
      "y": -2,
      "z": -15,
      "name": "Rock_Stone"
    },
    {
      "x": -6,
      "y": -1,
      "z": -15,
      "name": "Rock_Stone"
    },
    {
      "x": -6,
      "y": 0,
      "z": -15,
      "name": "Rock_Stone"
    },
    {
      "x": -6,
      "y": 1,
      "z": -15,
      "name": "Rock_Stone"
    },
    {
      "x": -6,
      "y": 2,
      "z": -15,
      "name": "Rock_Stone"
    },
    {
      "x": -6,
      "y": 3,
      "z": -15,
      "name": "Rock_Stone"
    },
    {
      "x": -6,
      "y": 4,
      "z": -15,
      "name": "Rock_Stone"
    },
    {
      "x": -6,
      "y": 5,
      "z": -15,
      "name": "Empty"
    },
    {
      "x": -6,
      "y": 6,
      "z": -15,
      "name": "Empty"
    },
    {
      "x": -6,
      "y": -4,
      "z": -14,
      "name": "Rock_Stone"
    },
    {
      "x": -6,
      "y": -3,
      "z": -14,
      "name": "Rock_Stone"
    },
    {
      "x": -6,
      "y": -2,
      "z": -14,
      "name": "Rock_Stone"
    },
    {
      "x": -6,
      "y": -1,
      "z": -14,
      "name": "Rock_Stone"
    },
    {
      "x": -6,
      "y": 0,
      "z": -14,
      "name": "Rock_Stone"
    },
    {
      "x": -6,
      "y": 1,
      "z": -14,
      "name": "Rock_Stone"
    },
    {
      "x": -6,
      "y": 2,
      "z": -14,
      "name": "Rock_Stone"
    },
    {
      "x": -6,
      "y": 3,
      "z": -14,
      "name": "Rock_Stone"
    },
    {
      "x": -6,
      "y": 4,
      "z": -14,
      "name": "Rock_Stone"
    },
    {
      "x": -6,
      "y": -4,
      "z": -13,
      "name": "Rock_Stone"
    },
    {
      "x": -6,
      "y": -3,
      "z": -13,
      "name": "Rock_Stone"
    },
    {
      "x": -6,
      "y": -2,
      "z": -13,
      "name": "Rock_Stone"
    },
    {
      "x": -6,
      "y": -1,
      "z": -13,
      "name": "Rock_Stone"
    },
    {
      "x": -6,
      "y": 0,
      "z": -13,
      "name": "Rock_Stone"
    },
    {
      "x": -6,
      "y": 1,
      "z": -13,
      "name": "Rock_Stone"
    },
    {
      "x": -6,
      "y": 2,
      "z": -13,
      "name": "Rock_Stone"
    },
    {
      "x": -6,
      "y": 3,
      "z": -13,
      "name": "Rock_Stone"
    },
    {
      "x": -6,
      "y": 4,
      "z": -13,
      "name": "Rock_Stone"
    },
    {
      "x": -6,
      "y": -2,
      "z": -12,
      "name": "Rock_Stone"
    },
    {
      "x": -6,
      "y": -1,
      "z": -12,
      "name": "Rock_Stone"
    },
    {
      "x": -6,
      "y": 0,
      "z": -12,
      "name": "Rock_Stone"
    },
    {
      "x": -6,
      "y": 1,
      "z": -12,
      "name": "Rock_Stone"
    },
    {
      "x": -6,
      "y": 2,
      "z": -12,
      "name": "Rock_Stone"
    },
    {
      "x": -6,
      "y": 3,
      "z": -12,
      "name": "Rock_Stone"
    },
    {
      "x": -6,
      "y": 4,
      "z": -12,
      "name": "Rock_Stone"
    },
    {
      "x": -6,
      "y": 7,
      "z": -12,
      "name": "Empty"
    },
    {
      "x": -6,
      "y": -2,
      "z": -11,
