{
  "version": 8,
  "blockIdVersion": 8,
  "anchorX": 1,
  "anchorY": 11,
  "anchorZ": 5,
  "blocks": [
    {
      "x": -13,
      "y": 13,
      "z": -14,
      "name": "Plant_Vine_Wall",
      "rotation": 3
    },
    {
      "x": -13,
      "y": 13,
      "z": -13,
      "name": "Plant_Vine",
      "rotation": 3
    },
    {
      "x": -13,
      "y": 11,
      "z": -12,
      "name": "Plant_Vine_Wall",
      "rotation": 3
    },
    {
      "x": -13,
      "y": 12,
      "z": -12,
      "name": "Plant_Vine",
      "rotation": 3
    },
    {
      "x": -13,
      "y": 13,
      "z": -12,
      "name": "Plant_Vine",
      "rotation": 3
    },
    {
      "x": -13,
      "y": 14,
      "z": -12,
      "name": "Plant_Vine",
      "rotation": 3
    },
    {
      "x": -13,
      "y": 13,
      "z": 7,
      "name": "Plant_Vine_Wall",
      "rotation": 3
    },
    {
      "x": -13,
      "y": 12,
      "z": 8,
      "name": "Plant_Vine",
      "rotation": 3
    },
    {
      "x": -13,
      "y": 13,
      "z": 8,
      "name": "Plant_Vine",
      "rotation": 3
    },
    {
      "x": -13,
      "y": 11,
      "z": 9,
      "name": "Plant_Vine_Wall",
      "rotation": 3
    },
    {
      "x": -13,
      "y": 12,
      "z": 9,
      "name": "Plant_Vine",
      "rotation": 3
    },
    {
      "x": -13,
      "y": 11,
      "z": 10,
      "name": "Plant_Vine",
      "rotation": 3
    },
    {
      "x": -13,
      "y": 12,
      "z": 10,
      "name": "Plant_Vine",
      "rotation": 3
    },
    {
      "x": -12,
      "y": 9,
      "z": -14,
      "name": "Rock_Quartzite_Cobble"
    },
    {
      "x": -12,
      "y": 10,
      "z": -14,
      "name": "Rock_Quartzite_Cobble"
    },
    {
      "x": -12,
      "y": 11,
      "z": -14,
      "name": "Rock_Quartzite_Brick"
    },
    {
      "x": -12,
      "y": 12,
      "z": -14,
      "name": "Rock_Quartzite"
    },
    {
      "x": -12,
      "y": 13,
      "z": -14,
      "name": "Soil_Grass"
    },
    {
      "x": -12,
      "y": 8,
      "z": -13,
      "name": "Rock_Quartzite"
    },
    {
      "x": -12,
      "y": 9,
      "z": -13,
      "name": "Rock_Quartzite_Brick"
    },
    {
      "x": -12,
      "y": 10,
      "z": -13,
      "name": "Rock_Quartzite_Brick"
    },
    {
      "x": -12,
      "y": 11,
      "z": -13,
      "name": "Rock_Quartzite_Brick"
    },
    {
      "x": -12,
      "y": 12,
      "z": -13,
      "name": "Rock_Quartzite"
    },
    {
      "x": -12,
      "y": 13,
      "z": -13,
      "name": "Soil_Grass"
    },
    {
      "x": -12,
      "y": 14,
      "z": -13,
      "name": "Plant_Grass_Lush"
    },
    {
      "x": -12,
      "y": 7,
      "z": -12,
      "name": "Rock_Quartzite"
    },
    {
      "x": -12,
      "y": 8,
      "z": -12,
      "name": "Rock_Quartzite"
    },
    {
      "x": -12,
      "y": 9,
      "z": -12,
      "name": "Rock_Quartzite_Brick"
    },
    {
      "x": -12,
      "y": 10,
      "z": -12,
      "name": "Rock_Quartzite_Brick"
    },
    {
      "x": -12,
      "y": 11,
      "z": -12,
      "name": "Rock_Quartzite_Brick"
    },
    {
      "x": -12,
      "y": 12,
      "z": -12,
      "name": "Rock_Quartzite"
    },
    {
      "x": -12,
      "y": 13,
      "z": -12,
      "name": "Soil_Dirt"
    },
    {
      "x": -12,
      "y": 14,
      "z": -12,
      "name": "Soil_Grass"
    },
    {
      "x": -12,
      "y": 15,
      "z": -12,
      "name": "Plant_Moss_Rug_Green"
    },
    {
      "x": -12,
      "y": 7,
      "z": -11,
      "name": "Rock_Quartzite"
    },
    {
      "x": -12,
      "y": 8,
      "z": -11,
      "name": "Rock_Quartzite"
    },
    {
      "x": -12,
      "y": 9,
      "z": -11,
      "name": "Rock_Quartzite"
    },
    {
      "x": -12,
      "y": 10,
      "z": -11,
      "name": "Rock_Quartzite_Brick"
    },
    {
      "x": -12,
      "y": 11,
      "z": -11,
      "name": "Rock_Quartzite_Brick"
    },
    {
      "x": -12,
      "y": 12,
      "z": -11,
      "name": "Rock_Quartzite"
    },
    {
      "x": -12,
      "y": 13,
      "z": -11,
      "name": "Soil_Dirt"
    },
    {
      "x": -12,
      "y": 14,
      "z": -11,
      "name": "Soil_Grass"
    },
    {
      "x": -12,
      "y": 15,
      "z": -11,
      "name": "Plant_Moss_Rug_Green"
    },
    {
      "x": -12,
      "y": 5,
      "z": -6,
      "name": "Rock_Quartzite"
    },
    {
      "x": -12,
      "y": 6,
      "z": -6,
      "name": "Rock_Quartzite"
    },
    {
      "x": -12,
      "y": 7,
      "z": -6,
      "name": "Rock_Quartzite_Cobble"
    },
    {
      "x": -12,
      "y": 8,
      "z": -6,
      "name": "Rock_Quartzite_Cobble"
    },
    {
      "x": -12,
      "y": 9,
      "z": -6,
      "name": "Rock_Quartzite_Cobble"
    },
    {
      "x": -12,
      "y": 10,
      "z": -6,
      "name": "Rock_Quartzite_Cobble"
    },
    {
      "x": -12,
      "y": 11,
      "z": -6,
      "name": "Rock_Quartzite_Brick"
    },
    {
      "x": -12,
      "y": 12,
      "z": -6,
      "name": "Rock_Quartzite"
    },
    {
      "x": -12,
      "y": 13,
      "z": -6,
      "name": "Soil_Dirt"
    },
    {
      "x": -12,
      "y": 14,
      "z": -6,
      "name": "Soil_Grass"
    },
    {
      "x": -12,
      "y": 6,
      "z": -5,
      "name": "Rock_Quartzite"
    },
    {
      "x": -12,
      "y": 7,
      "z": -5,
      "name": "Rock_Quartzite"
    },
    {
      "x": -12,
      "y": 8,
      "z": -5,
      "name": "Rock_Quartzite"
    },
    {
      "x": -12,
      "y": 9,
      "z": -5,
      "name": "Rock_Quartzite_Cobble"
    },
    {
      "x": -12,
      "y": 10,
      "z": -5,
      "name": "Rock_Quartzite_Cobble"
    },
    {
      "x": -12,
      "y": 11,
      "z": -5,
      "name": "Rock_Quartzite_Brick"
    },
    {
      "x": -12,
      "y": 12,
      "z": -5,
      "name": "Rock_Quartzite"
    },
    {
      "x": -12,
      "y": 13,
      "z": -5,
      "name": "Soil_Dirt"
    },
    {
      "x": -12,
      "y": 14,
      "z": -5,
      "name": "Soil_Grass"
    },
    {
      "x": -12,
      "y": 15,
      "z": -5,
      "name": "Plant_Grass_Sharp"
    },
    {
      "x": -12,
      "y": 6,
      "z": -4,
      "name": "Rock_Quartzite"
    },
    {
      "x": -12,
      "y": 7,
      "z": -4,
      "name": "Rock_Quartzite"
    },
    {
      "x": -12,
      "y": 8,
      "z": -4,
      "name": "Rock_Quartzite"
    },
    {
      "x": -12,
      "y": 9,
      "z": -4,
      "name": "Rock_Quartzite"
    },
    {
      "x": -12,
      "y": 10,
      "z": -4,
      "name": "Rock_Quartzite_Brick"
    },
    {
      "x": -12,
      "y": 11,
      "z": -4,
      "name": "Rock_Quartzite_Brick"
    },
    {
      "x": -12,
      "y": 12,
      "z": -4,
      "name": "Soil_Dirt"
    },
    {
      "x": -12,
      "y": 13,
      "z": -4,
      "name": "Soil_Grass"
    },
    {
      "x": -12,
      "y": 14,
      "z": -4,
      "name": "Plant_Grass_Sharp_Tall"
    },
    {
      "x": -12,
      "y": 15,
      "z": -4,
      "name": "Plant_Grass_Sharp_Tall",
      "filler": 1024
    },
    {
      "x": -12,
      "y": 8,
      "z": -3,
      "name": "Rock_Quartzite"
    },
    {
      "x": -12,
      "y": 9,
      "z": -3,
      "name": "Rock_Quartzite"
    },
    {
      "x": -12,
      "y": 10,
      "z": -3,
      "name": "Rock_Quartzite_Brick"
    },
    {
      "x": -12,
      "y": 11,
      "z": -3,
      "name": "Rock_Quartzite_Brick"
    },
    {
      "x": -12,
      "y": 12,
      "z": -3,
      "name": "Soil_Dirt"
    },
    {
      "x": -12,
      "y": 13,
      "z": -3,
      "name": "Soil_Grass"
    },
    {
      "x": -12,
      "y": 14,
      "z": -3,
      "name": "Plant_Grass_Lush_Short"
    },
    {
      "x": -12,
      "y": 9,
      "z": 3,
      "name": "Rock_Quartzite"
    },
    {
      "x": -12,
      "y": 10,
      "z": 3,
      "name": "Rock_Quartzite_Brick"
    },
    {
      "x": -12,
      "y": 11,
      "z": 3,
      "name": "Rock_Quartzite_Brick"
    },
    {
      "x": -12,
      "y": 12,
      "z": 3,
      "name": "Rock_Quartzite"
    },
    {
      "x": -12,
      "y": 13,
      "z": 3,
      "name": "Soil_Grass"
    },
    {
      "x": -12,
      "y": 7,
      "z": 4,
      "name": "Rock_Quartzite"
    },
    {
      "x": -12,
      "y": 8,
      "z": 4,
      "name": "Rock_Quartzite"
    },
    {
      "x": -12,
      "y": 9,
      "z": 4,
      "name": "Rock_Quartzite"
    },
    {
      "x": -12,
      "y": 10,
      "z": 4,
      "name": "Rock_Quartzite_Brick"
    },
    {
      "x": -12,
      "y": 11,
      "z": 4,
      "name": "Rock_Quartzite_Brick"
    },
    {
      "x": -12,
      "y": 12,
      "z": 4,
      "name": "Rock_Quartzite"
    },
    {
      "x": -12,
      "y": 13,
      "z": 4,
      "name": "Soil_Grass"
    },
    {
      "x": -12,
      "y": 14,
      "z": 4,
      "name": "Plant_Grass_Sharp"
    },
    {
      "x": -12,
      "y": 8,
      "z": 5,
      "name": "Rock_Quartzite"
    },
    {
      "x": -12,
      "y": 9,
      "z": 5,
      "name": "Rock_Quartzite"
    },
    {
      "x": -12,
      "y": 10,
      "z": 5,
      "name": "Rock_Quartzite"
    },
    {
      "x": -12,
      "y": 11,
      "z": 5,
      "name": "Rock_Quartzite_Brick"
    },
    {
      "x": -12,
      "y": 12,
      "z": 5,
      "name": "Soil_Dirt"
    },
    {
      "x": -12,
      "y": 13,
      "z": 5,
      "name": "Soil_Grass"
    },
    {
      "x": -12,
      "y": 14,
      "z": 5,
      "name": "Plant_Fern_Winter"
    },
    {
      "x": -12,
      "y": 9,
      "z": 6,
      "name": "Rock_Quartzite"
    },
    {
      "x": -12,
      "y": 10,
      "z": 6,
      "name": "Rock_Quartzite"
    },
    {
      "x": -12,
      "y": 11,
      "z": 6,
      "name": "Rock_Quartzite_Brick"
    },
    {
      "x": -12,
      "y": 12,
      "z": 6,
      "name": "Soil_Dirt"
    },
    {
      "x": -12,
      "y": 13,
      "z": 6,
      "name": "Soil_Grass"
    },
    {
      "x": -12,
      "y": 14,
      "z": 6,
      "name": "Plant_Fern_Winter"
    },
    {
      "x": -12,
      "y": 9,
      "z": 7,
      "name": "Rock_Quartzite"
    },
    {
      "x": -12,
      "y": 10,
      "z": 7,
      "name": "Rock_Quartzite_Brick"
    },
    {
      "x": -12,
      "y": 11,
      "z": 7,
      "name": "Rock_Quartzite_Brick"
    },
    {
      "x": -12,
      "y": 12,
      "z": 7,
      "name": "Soil_Dirt"
    },
    {
      "x": -12,
      "y": 13,
      "z": 7,
      "name": "Soil_Grass"
    },
    {
      "x": -12,
      "y": 14,
      "z": 7,
      "name": "Plant_Bush"
    },
    {
      "x": -12,
      "y": 7,
      "z": 8,
      "name": "Rock_Quartzite_Brick"
    },
    {
      "x": -12,
      "y": 8,
      "z": 8,
      "name": "Rock_Quartzite_Brick"
    },
    {
      "x": -12,
      "y": 9,
      "z": 8,
      "name": "Rock_Quartzite_Brick"
    },
    {
      "x": -12,
      "y": 10,
      "z": 8,
      "name": "Rock_Quartzite_Brick"
    },
    {
      "x": -12,
      "y": 11,
      "z": 8,
      "name": "Rock_Quartzite_Brick"
    },
    {
      "x": -12,
      "y": 12,
      "z": 8,
      "name": "Soil_Dirt"
    },
    {
      "x": -12,
      "y": 13,
      "z": 8,
      "name": "Soil_Grass"
    },
    {
      "x": -12,
      "y": 14,
      "z": 8,
      "name": "Plant_Grass_Lush_Short"
    },
    {
      "x": -12,
      "y": 6,
      "z": 9,
      "name": "Rock_Quartzite_Brick"
    },
    {
      "x": -12,
      "y": 7,
      "z": 9,
      "name": "Rock_Quartzite_Brick"
    },
    {
      "x": -12,
      "y": 8,
      "z": 9,
      "name": "Rock_Quartzite_Brick"
    },
    {
      "x": -12,
      "y": 9,
      "z": 9,
      "name": "Rock_Quartzite_Brick"
    },
    {
      "x": -12,
      "y": 10,
      "z": 9,
      "name": "Rock_Quartzite_Brick"
    },
    {
      "x": -12,
      "y": 11,
      "z": 9,
      "name": "Rock_Quartzite_Brick"
    },
    {
      "x": -12,
      "y": 12,
      "z": 9,
      "name": "Soil_Grass"
    },
    {
      "x": -12,
      "y": 13,
      "z": 9,
      "name": "Plant_Moss_Rug_Green"
    },
    {
      "x": -12,
      "y": 8,
      "z": 10,
      "name": "Rock_Quartzite_Cobble"
    },
    {
      "x": -12,
      "y": 9,
      "z": 10,
      "name": "Rock_Quartzite_Cobble"
    },
    {
      "x": -12,
      "y": 10,
      "z": 10,
      "name": "Rock_Quartzite_Cobble"
    },
    {
      "x": -12,
      "y": 11,
      "z": 10,
      "name": "Soil_Dirt"
    },
    {
      "x": -12,
      "y": 12,
      "z": 10,
      "name": "Soil_Grass"
    },
    {
      "x": -12,
      "y": 13,
      "z": 10,
      "name": "Plant_Moss_Rug_Green"
    },
    {
      "x": -12,
      "y": 8,
      "z": 11,
      "name": "Rock_Quartzite_Cobble"
    },
    {
      "x": -12,
      "y": 9,
      "z": 11,
      "name": "Rock_Quartzite_Cobble"
    },
    {
      "x": -12,
      "y": 10,
      "z": 11,
      "name": "Rock_Quartzite_Brick"
    },
    {
      "x": -12,
      "y": 11,
      "z": 11,
      "name": "Soil_Dirt"
    },
    {
      "x": -12,
      "y": 12,
      "z": 11,
      "name": "Soil_Grass"
    },
    {
      "x": -12,
      "y": 7,
      "z": 12,
      "name": "Rock_Quartzite_Brick"
    },
    {
      "x": -12,
      "y": 8,
      "z": 12,
      "name": "Rock_Quartzite_Brick"
    },
    {
      "x": -12,
      "y": 9,
      "z": 12,
      "name": "Rock_Quartzite_Brick"
    },
    {
      "x": -12,
      "y": 10,
      "z": 12,
      "name": "Rock_Quartzite_Brick"
    },
    {
      "x": -12,
      "y": 11,
      "z": 12,
      "name": "Soil_Grass"
    },
    {
      "x": -12,
      "y": 12,
      "z": 12,
      "name": "Plant_Grass_Lush_Short"
    },
    {
      "x": -11,
      "y": 8,
      "z": -14,
      "name": "Rock_Quartzite"
    },
    {
      "x": -11,
      "y": 9,
      "z": -14,
      "name": "Rock_Quartzite"
    },
    {
      "x": -11,
      "y": 10,
      "z": -14,
      "name": "Rock_Quartzite_Brick"
    },
    {
      "x": -11,
      "y": 11,
      "z": -14,
      "name": "Rock_Quartzite_Brick"
    },
    {
      "x": -11,
      "y": 12,
      "z": -14,
      "name": "Soil_Dirt"
    },
    {
      "x": -11,
      "y": 13,
      "z": -14,
      "name": "Soil_Grass"
    },
    {
      "x": -11,
      "y": 14,
      "z": -14,
      "name": "Plant_Grass_Sharp_Tall"
    },
    {
      "x": -11,
      "y": 15,
      "z": -14,
      "name": "Plant_Grass_Sharp_Tall",
      "filler": 1024
    },
    {
      "x": -11,
      "y": 5,
      "z": -13,
      "name": "Rock_Quartzite"
    },
    {
      "x": -11,
      "y": 6,
      "z": -13,
      "name": "Rock_Quartzite"
    },
    {
      "x": -11,
      "y": 7,
      "z": -13,
      "name": "Rock_Quartzite"
    },
    {
      "x": -11,
      "y": 8,
      "z": -13,
      "name": "Rock_Quartzite"
    },
    {
      "x": -11,
      "y": 9,
      "z": -13,
      "name": "Rock_Quartzite"
    },
    {
      "x": -11,
      "y": 10,
      "z": -13,
      "name": "Rock_Quartzite_Brick"
    },
    {
      "x": -11,
      "y": 11,
      "z": -13,
      "name": "Rock_Quartzite_Brick"
    },
    {
      "x": -11,
      "y": 12,
      "z": -13,
      "name": "Rock_Quartzite"
    },
    {
      "x": -11,
      "y": 13,
      "z": -13,
      "name": "Rock_Quartzite"
    },
    {
      "x": -11,
      "y": 14,
      "z": -13,
      "name": "Soil_Grass"
    },
    {
      "x": -11,
      "y": 15,
      "z": -13,
      "name": "Plant_Grass_Sharp"
    },
    {
      "x": -11,
      "y": 5,
      "z": -12,
      "name": "Rock_Quartzite"
    },
    {
      "x": -11,
      "y": 6,
      "z": -12,
      "name": "Rock_Quartzite"
    },
    {
      "x": -11,
      "y": 7,
      "z": -12,
      "name": "Rock_Quartzite_Brick"
    },
    {
      "x": -11,
      "y": 8,
      "z": -12,
      "name": "Rock_Quartzite_Brick"
    },
    {
      "x": -11,
      "y": 9,
      "z": -12,
      "name": "Rock_Quartzite_Brick"
    },
    {
      "x": -11,
      "y": 10,
      "z": -12,
      "name": "Rock_Quartzite_Brick"
    },
    {
      "x": -11,
      "y": 11,
      "z": -12,
      "name": "Rock_Quartzite_Brick"
    },
    {
      "x": -11,
      "y": 12,
      "z": -12,
      "name": "Rock_Quartzite"
    },
    {
      "x": -11,
      "y": 13,
      "z": -12,
      "name": "Soil_Dirt"
    },
    {
      "x": -11,
      "y": 14,
      "z": -12,
      "name": "Soil_Grass"
    },
    {
      "x": -11,
      "y": 15,
      "z": -12,
      "name": "Plant_Fern_Winter"
    },
    {
      "x": -11,
      "y": 5,
      "z": -11,
      "name": "Rock_Quartzite"
    },
    {
      "x": -11,
      "y": 6,
      "z": -11,
      "name": "Rock_Quartzite"
    },
    {
      "x": -11,
      "y": 7,
      "z": -11,
      "name": "Rock_Quartzite"
    },
    {
      "x": -11,
      "y": 8,
      "z": -11,
      "name": "Rock_Quartzite"
    },
    {
      "x": -11,
      "y": 9,
      "z": -11,
      "name": "Rock_Quartzite_Brick"
    },
    {
      "x": -11,
      "y": 10,
      "z": -11,
      "name": "Rock_Quartzite_Brick"
    },
    {
      "x": -11,
      "y": 11,
      "z": -11,
      "name": "Rock_Quartzite_Brick"
    },
    {
      "x": -11,
      "y": 12,
      "z": -11,
      "name": "Rock_Quartzite"
    },
    {
      "x": -11,
      "y": 13,
      "z": -11,
      "name": "Rock_Quartzite"
    },
    {
      "x": -11,
      "y": 14,
      "z": -11,
      "name": "Soil_Grass"
    },
    {
      "x": -11,
      "y": 15,
      "z": -11,
      "name": "Plant_Moss_Rug_Green"
    },
    {
      "x": -11,
      "y": 8,
      "z": -6,
      "name": "Rock_Quartzite_Cobble"
    },
    {
      "x": -11,
      "y": 9,
      "z": -6,
      "name": "Rock_Quartzite_Cobble"
    },
    {
      "x": -11,
      "y": 10,
      "z": -6,
      "name": "Rock_Quartzite_Cobble"
    },
    {
      "x": -11,
      "y": 11,
      "z": -6,
      "name": "Rock_Quartzite_Brick"
    },
    {
      "x": -11,
      "y": 12,
      "z": -6,
      "name": "Rock_Quartzite"
    },
    {
      "x": -11,
      "y": 13,
      "z": -6,
      "name": "Rock_Quartzite"
    },
    {
      "x": -11,
      "y": 14,
      "z": -6,
      "name": "Soil_Grass"
    },
    {
      "x": -11,
      "y": 15,
      "z": -6,
      "name": "Plant_Grass_Lush"
    },
    {
      "x": -11,
      "y": 7,
      "z": -5,
      "name": "Rock_Quartzite"
    },
    {
      "x": -11,
      "y": 8,
      "z": -5,
      "name": "Rock_Quartzite"
    },
    {
      "x": -11,
      "y": 9,
      "z": -5,
      "name": "Rock_Quartzite_Cobble"
    },
    {
      "x": -11,
      "y": 10,
      "z": -5,
      "name": "Rock_Quartzite_Cobble"
    },
    {
      "x": -11,
      "y": 11,
      "z": -5,
      "name": "Rock_Quartzite_Brick"
    },
    {
      "x": -11,
      "y": 12,
      "z": -5,
      "name": "Rock_Quartzite"
    },
    {
      "x": -11,
      "y": 13,
      "z": -5,
      "name": "Soil_Dirt"
    },
    {
      "x": -11,
      "y": 14,
      "z": -5,
      "name": "Soil_Grass"
    },
    {
      "x": -11,
      "y": 15,
      "z": -5,
      "name": "Plant_Moss_Rug_Green"
    },
    {
      "x": -11,
      "y": 6,
      "z": -4,
      "name": "Rock_Quartzite"
    },
    {
      "x": -11,
      "y": 7,
      "z": -4,
      "name": "Rock_Quartzite"
    },
    {
      "x": -11,
      "y": 8,
      "z": -4,
      "name": "Rock_Quartzite"
    },
    {
      "x": -11,
      "y": 9,
      "z": -4,
      "name": "Rock_Quartzite"
    },
    {
      "x": -11,
      "y": 10,
      "z": -4,
      "name": "Rock_Quartzite_Brick"
    },
    {
      "x": -11,
      "y": 11,
      "z": -4,
      "name": "Rock_Quartzite_Brick"
    },
    {
      "x": -11,
      "y": 12,
      "z": -4,
      "name": "Rock_Quartzite"
    },
    {
      "x": -11,
      "y": 13,
      "z": -4,
      "name": "Soil_Dirt"
    },
    {
      "x": -11,
      "y": 14,
      "z": -4,
      "name": "Soil_Grass"
    },
    {
      "x": -11,
      "y": 15,
      "z": -4,
      "name": "Plant_Moss_Rug_Green"
    },
    {
      "x": -11,
      "y": 5,
      "z": -3,
      "name": "Rock_Quartzite"
    },
    {
      "x": -11,
      "y": 6,
      "z": -3,
      "name": "Rock_Quartzite"
    },
    {
      "x": -11,
      "y": 7,
      "z": -3,
      "name": "Rock_Quartzite"
    },
    {
      "x": -11,
      "y": 8,
      "z": -3,
      "name": "Rock_Quartzite"
    },
    {
      "x": -11,
      "y": 9,
      "z": -3,
      "name": "Rock_Quartzite_Brick"
    },
    {
      "x": -11,
      "y": 10,
      "z": -3,
      "name": "Rock_Quartzite_Brick"
    },
    {
      "x": -11,
      "y": 11,
      "z": -3,
      "name": "Rock_Quartzite_Brick"
    },
    {
      "x": -11,
      "y": 12,
      "z": -3,
      "name": "Rock_Quartzite"
    },
    {
      "x": -11,
      "y": 13,
      "z": -3,
      "name": "Soil_Grass"
    },
    {
      "x": -11,
      "y": 14,
      "z": -3,
      "name": "Plant_Grass_Lush_Short"
    },
    {
      "x": -11,
      "y": 13,
      "z": -2,
      "name": "Plant_Vine_Wall"
    },
    {
      "x": -11,
      "y": 8,
      "z": 3,
      "name": "Rock_Quartzite"
    },
    {
      "x": -11,
      "y": 9,
      "z": 3,
      "name": "Rock_Quartzite"
    },
    {
      "x": -11,
      "y": 10,
      "z": 3,
      "name": "Rock_Quartzite_Brick"
    },
    {
      "x": -11,
      "y": 11,
      "z": 3,
      "name": "Rock_Quartzite_Brick"
    },
    {
      "x": -11,
      "y": 12,
      "z": 3,
      "name": "Rock_Quartzite"
    },
    {
      "x": -11,
      "y": 13,
      "z": 3,
      "name": "Soil_Grass"
    },
    {
      "x": -11,
      "y": 14,
      "z": 3,
      "name": "Plant_Grass_Lush"
    },
    {
      "x": -11,
      "y": 7,
      "z": 4,
      "name": "Rock_Quartzite"
    },
    {
      "x": -11,
      "y": 8,
      "z": 4,
      "name": "Rock_Quartzite"
    },
    {
      "x": -11,
      "y": 9,
      "z": 4,
      "name": "Rock_Quartzite"
    },
    {
      "x": -11,
      "y": 10,
      "z": 4,
      "name": "Rock_Quartzite_Brick"
    },
    {
      "x": -11,
      "y": 11,
      "z": 4,
      "name": "Rock_Quartzite_Brick"
    },
    {
      "x": -11,
      "y": 12,
      "z": 4,
      "name": "Rock_Quartzite"
    },
    {
      "x": -11,
      "y": 13,
      "z": 4,
      "name": "Soil_Grass"
    },
    {
      "x": -11,
      "y": 7,
      "z": 5,
      "name": "Rock_Quartzite"
    },
    {
      "x": -11,
      "y": 8,
      "z": 5,
      "name": "Rock_Quartzite"
    },
    {
      "x": -11,
      "y": 9,
      "z": 5,
      "name": "Rock_Quartzite"
    },
    {
      "x": -11,
      "y": 10,
      "z": 5,
      "name": "Rock_Quartzite_Brick"
    },
    {
      "x": -11,
      "y": 11,
      "z": 5,
      "name": "Rock_Quartzite_Brick"
    },
    {
      "x": -11,
      "y": 12,
      "z": 5,
      "name": "Rock_Quartzite"
    },
    {
      "x": -11,
      "y": 13,
      "z": 5,
      "name": "Soil_Grass"
    },
    {
      "x": -11,
      "y": 8,
      "z": 6,
      "name": "Rock_Quartzite"
    },
    {
      "x": -11,
      "y": 9,
      "z": 6,
      "name": "Rock_Quartzite"
    },
    {
      "x": -11,
      "y": 10,
      "z": 6,
      "name": "Rock_Quartzite"
    },
    {
      "x": -11,
      "y": 11,
      "z": 6,
      "name": "Rock_Quartzite_Brick"
    },
    {
      "x": -11,
      "y": 12,
      "z": 6,
      "name": "Soil_Dirt"
    },
    {
      "x": -11,
      "y": 13,
      "z": 6,
      "name": "Soil_Grass"
    },
    {
      "x": -11,
      "y": 14,
      "z": 6,
      "name": "Plant_Grass_Sharp_Tall"
    },
    {
      "x": -11,
      "y": 15,
      "z": 6,
      "name": "Plant_Grass_Sharp_Tall",
      "filler": 1024
    },
    {
      "x": -11,
      "y": 8,
      "z": 7,
      "name": "Rock_Quartzite"
    },
    {
      "x": -11,
      "y": 9,
      "z": 7,
      "name": "Rock_Quartzite_Brick"
    },
    {
      "x": -11,
      "y": 10,
      "z": 7,
      "name": "Rock_Quartzite_Brick"
    },
    {
      "x": -11,
      "y": 11,
      "z": 7,
      "name": "Rock_Quartzite_Brick"
    },
    {
      "x": -11,
      "y": 12,
      "z": 7,
      "name": "Soil_Dirt"
    },
    {
      "x": -11,
      "y": 13,
      "z": 7,
      "name": "Soil_Grass"
    },
    {
      "x": -11,
      "y": 14,
      "z": 7,
      "name": "Plant_Bush"
    },
    {
      "x": -11,
      "y": 6,
      "z": 8,
      "name": "Rock_Quartzite"
    },
    {
      "x": -11,
      "y": 7,
      "z": 8,
      "name": "Rock_Quartzite"
    },
    {
      "x": -11,
      "y": 8,
      "z": 8,
      "name": "Rock_Quartzite"
    },
    {
      "x": -11,
      "y": 9,
      "z": 8,
      "name": "Rock_Quartzite_Brick"
    },
    {
      "x": -11,
      "y": 10,
      "z": 8,
      "name": "Rock_Quartzite_Brick"
    },
    {
      "x": -11,
      "y": 11,
      "z": 8,
      "name": "Rock_Quartzite_Brick"
    },
    {
      "x": -11,
      "y": 12,
      "z": 8,
      "name": "Soil_Dirt"
    },
    {
      "x": -11,
      "y": 13,
      "z": 8,
      "name": "Soil_Grass"
    },
    {
      "x": -11,
      "y": 14,
      "z": 8,
      "name": "Plant_Grass_Sharp"
    },
    {
      "x": -11,
      "y": 5,
      "z": 9,
      "name": "Rock_Quartzite"
    },
    {
      "x": -11,
      "y": 6,
      "z": 9,
      "name": "Rock_Quartzite"
    },
    {
      "x": -11,
      "y": 7,
      "z": 9,
      "name": "Rock_Quartzite"
    },
    {
      "x": -11,
      "y": 8,
      "z": 9,
      "name": "Rock_Quartzite_Brick"
    },
    {
      "x": -11,
      "y": 9,
      "z": 9,
      "name": "Rock_Quartzite_Brick"
    },
    {
      "x": -11,
      "y": 10,
      "z": 9,
      "name": "Rock_Quartzite_Brick"
    },
    {
      "x": -11,
      "y": 11,
      "z": 9,
      "name": "Soil_Dirt"
    },
    {
      "x": -11,
      "y": 12,
      "z": 9,
      "name": "Soil_Grass"
    },
    {
      "x": -11,
      "y": 13,
      "z": 9,
      "name": "Plant_Grass_Sharp_Tall"
    },
    {
      "x": -11,
      "y": 14,
      "z": 9,
      "name": "Plant_Grass_Sharp_Tall",
      "filler": 1024
    },
    {
      "x": -11,
      "y": 5,
      "z": 10,
      "name": "Rock_Quartzite"
    },
    {
      "x": -11,
      "y": 6,
      "z": 10,
      "name": "Rock_Quartzite"
    },
    {
      "x": -11,
      "y": 7,
      "z": 10,
      "name": "Rock_Quartzite_Cobble"
    },
    {
      "x": -11,
      "y": 8,
      "z": 10,
      "name": "Rock_Quartzite_Cobble"
    },
    {
      "x": -11,
      "y": 9,
      "z": 10,
      "name": "Rock_Quartzite_Cobble"
    },
    {
      "x": -11,
      "y": 10,
      "z": 10,
      "name": "Rock_Quartzite_Cobble"
    },
    {
      "x": -11,
      "y": 11,
      "z": 10,
      "name": "Soil_Dirt"
    },
    {
      "x": -11,
      "y": 12,
      "z": 10,
      "name": "Soil_Grass"
    },
    {
      "x": -11,
      "y": 13,
      "z": 10,
      "name": "Plant_Grass_Sharp"
    },
    {
      "x": -11,
      "y": 6,
      "z": 11,
      "name": "Rock_Quartzite"
    },
    {
      "x": -11,
      "y": 7,
      "z": 11,
      "name": "Rock_Quartzite"
    },
    {
      "x": -11,
      "y": 8,
      "z": 11,
      "name": "Rock_Quartzite"
    },
    {
      "x": -11,
      "y": 9,
      "z": 11,
      "name": "Rock_Quartzite"
    },
    {
      "x": -11,
      "y": 10,
      "z": 11,
      "name": "Rock_Quartzite_Brick"
    },
    {
      "x": -11,
      "y": 11,
      "z": 11,
      "name": "Soil_Grass"
    },
    {
      "x": -11,
      "y": 12,
      "z": 11,
      "name": "Plant_Grass_Lush"
    },
    {
      "x": -11,
      "y": 8,
      "z": 12,
      "name": "Rock_Quartzite_Brick"
    },
    {
      "x": -11,
      "y": 9,
      "z": 12,
      "name": "Rock_Quartzite_Brick"
    },
    {
      "x": -11,
      "y": 10,
      "z": 12,
      "name": "Rock_Quartzite_Brick"
    },
    {
      "x": -11,
      "y": 11,
      "z": 12,
      "name": "Soil_Grass"
    },
    {
      "x": -11,
      "y": 12,
      "z": 12,
      "name": "Plant_Grass_Lush_Short"
    },
    {
      "x": -10,
      "y": 6,
      "z": -14,
      "name": "Rock_Quartzite"
    },
    {
      "x": -10,
      "y": 7,
      "z": -14,
      "name": "Rock_Quartzite"
    },
    {
      "x": -10,
      "y": 8,
      "z": -14,
      "name": "Rock_Quartzite"
    },
    {
      "x": -10,
      "y": 9,
      "z": -14,
      "name": "Rock_Quartzite_Brick"
    },
    {
      "x": -10,
      "y": 10,
      "z": -14,
      "name": "Rock_Quartzite_Brick"
    },
    {
      "x": -10,
      "y": 11,
      "z": -14,
      "name": "Rock_Quartzite_Brick"
    },
    {
      "x": -10,
      "y": 12,
      "z": -14,
      "name": "Soil_Dirt"
    },
    {
      "x": -10,
      "y": 13,
      "z": -14,
      "name": "Soil_Grass"
    },
    {
      "x": -10,
      "y": 14,
      "z": -14,
      "name": "Plant_Grass_Lush"
    },
    {
      "x": -10,
      "y": 5,
      "z": -13,
      "name": "Rock_Quartzite"
    },
    {
      "x": -10,
      "y": 6,
      "z": -13,
      "name": "Rock_Quartzite"
    },
    {
      "x": -10,
      "y": 7,
      "z": -13,
      "name": "Rock_Quartzite"
    },
    {
      "x": -10,
      "y": 8,
      "z": -13,
      "name": "Rock_Quartzite_Brick"
    },
    {
      "x": -10,
      "y": 9,
      "z": -13,
      "name": "Rock_Quartzite_Brick"
    },
    {
      "x": -10,
      "y": 10,
      "z": -13,
      "name": "Rock_Quartzite_Brick"
    },
    {
      "x": -10,
      "y": 11,
      "z": -13,
      "name": "Rock_Quartzite_Brick"
    },
    {
      "x": -10,
      "y": 12,
      "z": -13,
      "name": "Soil_Dirt"
    },
    {
      "x": -10,
      "y": 13,
      "z": -13,
      "name": "Soil_Grass"
    },
    {
      "x": -10,
      "y": 14,
      "z": -13,
      "name": "Plant_Fern_Winter"
    },
    {
      "x": -10,
      "y": 13,
      "z": -4,
      "name": "Plant_Vine",
      "rotation": 1
    },
    {
      "x": -10,
      "y": 14,
      "z": -4,
      "name": "Plant_Vine",
      "rotation": 1
    },
    {
      "x": -10,
      "y": 11,
      "z": -3,
      "name": "Plant_Vine_Wall",
      "rotation": 1
    },
    {
      "x": -10,
      "y": 12,
      "z": -3,
      "name": "Plant_Vine",
      "rotation": 1
    },
    {
      "x": -10,
      "y": 13,
      "z": -3,
      "name": "Plant_Vine",
      "rotation": 1
    },
    {
      "x": -10,
      "y": 7,
      "z": 11,
      "name": "Rock_Quartzite"
    },
    {
      "x": -10,
      "y": 8,
      "z": 11,
      "name": "Rock_Quartzite"
    },
    {
      "x": -10,
      "y": 9,
      "z": 11,
      "name": "Rock_Quartzite_Brick"
    },
    {
      "x": -10,
      "y": 10,
      "z": 11,
      "name": "Rock_Quartzite_Brick"
    },
    {
      "x": -10,
      "y": 8,
      "z": 12,
      "name": "Rock_Quartzite"
    },
    {
      "x": -10,
      "y": 9,
      "z": 12,
      "name": "Rock_Quartzite"
    },
    {
      "x": -10,
      "y": 10,
      "z": 12,
      "name": "Rock_Quartzite_Brick"
    },
    {
      "x": -9,
      "y": 6,
      "z": -14,
      "name": "Rock_Quartzite"
    },
    {
      "x": -9,
      "y": 7,
      "z": -14,
      "name": "Rock_Quartzite_Brick"
    },
    {
      "x": -9,
      "y": 8,
      "z": -14,
      "name": "Rock_Quartzite_Brick"
    },
    {
      "x": -9,
      "y": 9,
      "z": -14,
      "name": "Rock_Quartzite_Brick"
    },
    {
      "x": -9,
      "y": 10,
      "z": -14,
      "name": "Rock_Quartzite_Brick"
    },
    {
      "x": -9,
      "y": 11,
      "z": -14,
      "name": "Rock_Quartzite_Brick"
    },
    {
      "x": -9,
      "y": 12,
      "z": -14,
      "name": "Soil_Grass"
    },
    {
      "x": -9,
      "y": 5,
      "z": -13,
      "name": "Rock_Quartzite"
    },
    {
      "x": -9,
      "y": 6,
      "z": -13,
      "name": "Rock_Quartzite"
    },
    {
      "x": -9,
      "y": 7,
      "z": -13,
      "name": "Rock_Quartzite"
    },
    {
      "x": -9,
      "y": 8,
      "z": -13,
      "name": "Rock_Quartzite_Brick"
    },
    {
      "x": -9,
      "y": 9,
      "z": -13,
      "name": "Rock_Quartzite_Brick"
    },
    {
      "x": -9,
      "y": 10,
      "z": -13,
      "name": "Rock_Quartzite_Brick"
    },
    {
      "x": -9,
      "y": 11,
      "z": -13,
      "name": "Rock_Quartzite_Brick"
    },
    {
      "x": -9,
      "y": 12,
      "z": -13,
      "name": "Soil_Dirt"
    },
    {
      "x": -9,
      "y": 13,
      "z": -13,
      "name": "Soil_Grass"
    },
    {
      "x": -9,
      "y": 7,
      "z": 11,
      "name": "Rock_Quartzite"
    },
    {
      "x": -9,
      "y": 8,
      "z": 11,
      "name": "Rock_Quartzite"
    },
    {
      "x": -9,
      "y": 9,
      "z": 11,
      "name": "Rock_Quartzite"
    },
    {
      "x": -9,
      "y": 7,
      "z": 12,
      "name": "Rock_Quartzite"
    },
    {
      "x": -9,
      "y": 8,
      "z": 12,
      "name": "Rock_Quartzite"
    },
    {
      "x": -9,
      "y": 9,
      "z": 12,
      "name": "Rock_Quartzite"
    },
    {
      "x": -8,
      "y": 7,
      "z": -14,
      "name": "Rock_Quartzite_Brick"
    },
    {
      "x": -8,
      "y": 8,
      "z": -14,
      "name": "Rock_Quartzite_Brick"
    },
    {
      "x": -8,
      "y": 9,
      "z": -14,
      "name": "Rock_Quartzite_Brick"
    },
    {
      "x": -8,
      "y": 10,
      "z": -14,
      "name": "Rock_Quartzite_Brick"
    },
    {
      "x": -8,
      "y": 11,
      "z": -14,
      "name": "Rock_Quartzite_Brick"
    },
    {
      "x": -8,
      "y": 12,
      "z": -14,
      "name": "Soil_Grass"
    },
    {
      "x": -8,
      "y": 13,
      "z": -14,
      "name": "Plant_Grass_Lush_Short"
    },
    {
      "x": -8,
      "y": 5,
      "z": -13,
      "name": "Rock_Quartzite"
    },
    {
      "x": -8,
      "y": 6,
      "z": -13,
      "name": "Rock_Quartzite"
    },
    {
      "x": -8,
      "y": 7,
      "z": -13,
      "name": "Rock_Quartzite"
    },
    {
      "x": -8,
      "y": 8,
      "z": -13,
      "name": "Rock_Quartzite"
    },
    {
      "x": -8,
      "y": 9,
      "z": -13,
      "name": "Rock_Quartzite_Brick"
    },
    {
      "x": -8,
      "y": 10,
      "z": -13,
      "name": "Rock_Quartzite_Brick"
    },
    {
      "x": -8,
      "y": 11,
      "z": -13,
      "name": "Rock_Quartzite_Brick"
    },
    {
      "x": -8,
      "y": 12,
      "z": -13,
      "name": "Soil_Grass"
    },
    {
      "x": -8,
      "y": 5,
      "z": 11,
      "name": "Rock_Quartzite"
    },
    {
      "x": -8,
      "y": 6,
      "z": 11,
      "name": "Rock_Quartzite"
    },
    {
      "x": -8,
      "y": 7,
      "z": 11,
      "name": "Rock_Quartzite"
    },
    {
      "x": -8,
      "y": 8,
      "z": 11,
      "name": "Rock_Quartzite"
    },
    {
      "x": -8,
      "y": 9,
      "z": 11,
      "name": "Rock_Quartzite_Brick"
    },
    {
      "x": -8,
      "y": 10,
      "z": 11,
      "name": "Rock_Quartzite_Brick"
    },
    {
      "x": -8,
      "y": 11,
      "z": 11,
      "name": "Rock_Quartzite_Brick"
    },
    {
      "x": -8,
      "y": 12,
      "z": 11,
      "name": "Rock_Quartzite"
    },
    {
      "x": -8,
      "y": 13,
      "z": 11,
      "name": "Rock_Quartzite"
    },
    {
      "x": -8,
      "y": 14,
      "z": 11,
      "name": "Soil_Grass"
    },
    {
      "x": -8,
      "y": 15,
      "z": 11,
      "name": "Plant_Grass_Sharp"
    },
    {
      "x": -8,
      "y": 6,
      "z": 12,
      "name": "Rock_Quartzite"
    },
    {
      "x": -8,
      "y": 7,
      "z": 12,
      "name": "Rock_Quartzite"
    },
    {
      "x": -8,
      "y": 8,
      "z": 12,
      "name": "Rock_Quartzite"
    },
    {
      "x": -8,
      "y": 9,
      "z": 12,
      "name": "Rock_Quartzite"
    },
    {
      "x": -8,
      "y": 10,
      "z": 12,
      "name": "Rock_Quartzite_Brick"
    },
    {
      "x": -8,
      "y": 11,
      "z": 12,
      "name": "Rock_Quartzite_Brick"
    },
    {
      "x": -8,
      "y": 12,
      "z": 12,
      "name": "Rock_Quartzite"
    },
    {
      "x": -8,
      "y": 13,
      "z": 12,
      "name": "Soil_Grass"
    },
    {
      "x": -8,
      "y": 14,
      "z": 12,
      "name": "Plant_Grass_Sharp_Tall"
    },
    {
      "x": -8,
      "y": 15,
      "z": 12,
      "name": "Plant_Grass_Sharp_Tall",
      "filler": 1024
    },
    {
      "x": -8,
      "y": 12,
      "z": 13,
      "name": "Plant_Vine_Wall"
    },
    {
      "x": -8,
      "y": 13,
      "z": 13,
      "name": "Plant_Vine"
    },
    {
      "x": -7,
      "y": 6,
      "z": 11,
      "name": "Rock_Quartzite"
    },
    {
      "x": -7,
      "y": 7,
      "z": 11,
      "name": "Rock_Quartzite"
    },
    {
      "x": -7,
      "y": 8,
      "z": 11,
      "name": "Rock_Quartzite"
    },
    {
      "x": -7,
      "y": 9,
      "z": 11,
      "name": "Rock_Quartzite"
    },
    {
      "x": -7,
      "y": 10,
      "z": 11,
      "name": "Rock_Quartzite_Brick"
    },
    {
      "x": -7,
      "y": 11,
      "z": 11,
      "name": "Rock_Quartzite_Brick"
    },
    {
      "x": -7,
      "y": 12,
      "z": 11,
      "name": "Rock_Quartzite"
    },
    {
      "x": -7,
      "y": 13,
      "z": 11,
      "name": "Rock_Quartzite"
    },
    {
      "x": -7,
      "y": 14,
      "z": 11,
      "name": "Soil_Grass"
    },
    {
      "x": -7,
      "y": 15,
      "z": 11,
      "name": "Plant_Moss_Rug_Green"
    },
    {
      "x": -7,
      "y": 8,
      "z": 12,
      "name": "Rock_Quartzite"
    },
    {
      "x": -7,
      "y": 9,
      "z": 12,
      "name": "Rock_Quartzite"
    },
    {
      "x": -7,
      "y": 10,
      "z": 12,
      "name": "Rock_Quartzite_Brick"
    },
    {
      "x": -7,
      "y": 11,
      "z": 12,
      "name": "Rock_Quartzite_Brick"
    },
    {
      "x": -7,
      "y": 12,
      "z": 12,
      "name": "Rock_Quartzite"
    },
    {
      "x": -7,
      "y": 13,
      "z": 12,
      "name": "Soil_Dirt"
    },
    {
      "x": -7,
      "y": 14,
      "z": 12,
      "name": "Soil_Grass"
    },
    {
      "x": -7,
      "y": 15,
      "z": 12,
      "name": "Plant_Moss_Rug_Green"
    },
    {
      "x": -7,
      "y": 13,
      "z": 13,
      "name": "Plant_Vine_Wall"
    },
    {
      "x": -7,
      "y": 14,
      "z": 13,
      "name": "Plant_Vine"
    },
    {
      "x": -6,
      "y": 14,
      "z": 12,
      "name": "Plant_Vine_Wall",
      "rotation": 1
    },
    {
      "x": 10,
      "y": 14,
      "z": -14,
      "name": "Plant_Vine",
      "rotation": 3
    },
    {
      "x": 10,
      "y": 13,
      "z": -13,
      "name": "Plant_Vine_Wall",
      "rotation": 3
    },
    {
      "x": 10,
      "y": 14,
      "z": -13,
      "name": "Plant_Vine",
      "rotation": 3
    },
    {
      "x": 11,
      "y": 14,
      "z": -15,
      "name": "Plant_Vine_Wall",
      "rotation": 2
    },
    {
      "x": 11,
      "y": 12,
      "z": -14,
      "name": "Plant_Roots_Cave"
    },
    {
      "x": 11,
      "y": 13,
      "z": -14,
      "name": "Soil_Dirt"
    },
    {
      "x": 11,
      "y": 14,
      "z": -14,
      "name": "Soil_Grass"
    },
    {
      "x": 11,
      "y": 15,
      "z": -14,
      "name": "Plant_Moss_Rug_Green"
    },
    {
      "x": 11,
      "y": 11,
      "z": -13,
      "name": "Plant_Roots_Cave_Small",
      "rotation": 8
    },
    {
      "x": 11,
      "y": 12,
      "z": -13,
      "name": "Soil_Dirt"
    },
    {
      "x": 11,
      "y": 13,
      "z": -13,
      "name": "Soil_Dirt"
    },
    {
      "x": 11,
      "y": 14,
      "z": -13,
      "name": "Soil_Grass"
    },
    {
      "x": 11,
      "y": 15,
      "z": -13,
      "name": "Plant_Grass_Lush"
    },
    {
      "x": 11,
      "y": 5,
      "z": 11,
      "name": "Rock_Quartzite"
    },
    {
      "x": 11,
      "y": 6,
      "z": 11,
      "name": "Rock_Quartzite"
    },
    {
      "x": 11,
      "y": 7,
      "z": 11,
      "name": "Rock_Quartzite"
    },
    {
      "x": 11,
      "y": 8,
      "z": 11,
      "name": "Rock_Quartzite"
    },
    {
      "x": 11,
      "y": 9,
      "z": 11,
      "name": "Rock_Quartzite_Brick"
    },
    {
      "x": 11,
      "y": 10,
      "z": 11,
      "name": "Rock_Quartzite_Brick"
    },
    {
      "x": 11,
      "y": 11,
      "z": 11,
      "name": "Rock_Quartzite_Brick"
    },
    {
      "x": 11,
      "y": 12,
      "z": 11,
      "name": "Soil_Grass"
    },
    {
      "x": 11,
      "y": 13,
      "z": 11,
      "name": "Plant_Grass_Lush"
    },
    {
      "x": 11,
      "y": 6,
      "z": 12,
      "name": "Rock_Quartzite"
    },
    {
      "x": 11,
      "y": 7,
      "z": 12,
      "name": "Rock_Quartzite"
    },
    {
      "x": 11,
      "y": 8,
      "z": 12,
      "name": "Rock_Quartzite"
    },
    {
      "x": 11,
      "y": 9,
      "z": 12,
      "name": "Rock_Quartzite_Brick"
    },
    {
      "x": 11,
      "y": 10,
      "z": 12,
      "name": "Rock_Quartzite_Brick"
    },
    {
      "x": 11,
      "y": 11,
      "z": 12,
      "name": "Soil_Dirt"
    },
    {
      "x": 11,
      "y": 12,
      "z": 12,
      "name": "Soil_Grass"
    },
    {
      "x": 12,
      "y": 6,
      "z": -14,
      "name": "Rock_Quartzite"
    },
    {
      "x": 12,
      "y": 7,
      "z": -14,
      "name": "Rock_Quartzite"
    },
    {
      "x": 12,
      "y": 8,
      "z": -14,
      "name": "Rock_Quartzite"
    },
    {
      "x": 12,
      "y": 9,
      "z": -14,
      "name": "Rock_Quartzite"
    },
    {
      "x": 12,
      "y": 10,
      "z": -14,
      "name": "Rock_Quartzite_Brick"
    },
    {
      "x": 12,
      "y": 11,
      "z": -14,
      "name": "Rock_Quartzite_Brick"
    },
    {
      "x": 12,
      "y": 12,
      "z": -14,
      "name": "Rock_Quartzite"
    },
    {
      "x": 12,
      "y": 13,
      "z": -14,
      "name": "Soil_Dirt"
    },
    {
      "x": 12,
      "y": 14,
      "z": -14,
      "name": "Soil_Grass"
    },
    {
      "x": 12,
      "y": 5,
      "z": -13,
      "name": "Rock_Quartzite"
    },
    {
      "x": 12,
      "y": 6,
      "z": -13,
      "name": "Rock_Quartzite"
    },
    {
      "x": 12,
      "y": 7,
      "z": -13,
      "name": "Rock_Quartzite"
    },
    {
      "x": 12,
      "y": 8,
      "z": -13,
      "name": "Rock_Quartzite_Cobble"
    },
    {
      "x": 12,
      "y": 9,
      "z": -13,
      "name": "Rock_Quartzite_Brick"
    },
    {
      "x": 12,
      "y": 10,
      "z": -13,
      "name": "Rock_Quartzite_Brick"
    },
    {
      "x": 12,
      "y": 11,
      "z": -13,
      "name": "Rock_Quartzite_Brick"
    },
    {
      "x": 12,
      "y": 12,
      "z": -13,
      "name": "Rock_Quartzite"
    },
    {
      "x": 12,
      "y": 13,
      "z": -13,
      "name": "Soil_Dirt"
    },
    {
      "x": 12,
      "y": 14,
      "z": -13,
      "name": "Soil_Grass"
    },
    {
      "x": 12,
      "y": 15,
      "z": -13,
      "name": "Plant_Grass_Lush_Short"
    },
    {
      "x": 12,
      "y": 5,
      "z": 11,
      "name": "Rock_Quartzite"
    },
    {
      "x": 12,
      "y": 6,
      "z": 11,
      "name": "Rock_Quartzite"
    },
    {
      "x": 12,
      "y": 7,
      "z": 11,
      "name": "Rock_Quartzite"
    },
    {
      "x": 12,
      "y": 8,
      "z": 11,
      "name": "Rock_Quartzite"
    },
    {
      "x": 12,
      "y": 9,
      "z": 11,
      "name": "Rock_Quartzite_Brick"
    },
    {
      "x": 12,
      "y": 10,
      "z": 11,
      "name": "Rock_Quartzite_Brick"
    },
    {
      "x": 12,
      "y": 11,
      "z": 11,
      "name": "Rock_Quartzite_Brick"
    },
    {
      "x": 12,
      "y": 12,
      "z": 11,
      "name": "Soil_Dirt"
    },
    {
      "x": 12,
      "y": 13,
      "z": 11,
      "name": "Soil_Grass"
    },
    {
      "x": 12,
      "y": 6,
      "z": 12,
      "name": "Rock_Quartzite"
    },
    {
      "x": 12,
      "y": 7,
      "z": 12,
      "name": "Rock_Quartzite"
    },
    {
      "x": 12,
      "y": 8,
      "z": 12,
      "name": "Rock_Quartzite"
    },
    {
      "x": 12,
      "y": 9,
      "z": 12,
      "name": "Rock_Quartzite_Cobble"
    },
    {
      "x": 12,
      "y": 10,
      "z": 12,
      "name": "Rock_Quartzite_Brick"
    },
    {
      "x": 12,
      "y": 11,
      "z": 12,
      "name": "Soil_Dirt"
    },
    {
      "x": 12,
      "y": 12,
      "z": 12,
      "name": "Soil_Grass"
    },
    {
      "x": 12,
      "y": 13,
      "z": 12,
      "name": "Plant_Grass_Lush_Short"
    },
    {
      "x": 13,
      "y": 8,
      "z": -14,
      "name": "Rock_Quartzite_Cobble"
    },
    {
      "x": 13,
      "y": 9,
      "z": -14,
      "name": "Rock_Quartzite_Cobble"
    },
    {
      "x": 13,
      "y": 10,
      "z": -14,
      "name": "Rock_Quartzite_Cobble"
    },
    {
      "x": 13,
      "y": 11,
      "z": -14,
      "name": "Rock_Quartzite_Brick"
    },
    {
      "x": 13,
      "y": 12,
      "z": -14,
      "name": "Rock_Quartzite"
    },
    {
      "x": 13,
      "y": 13,
      "z": -14,
      "name": "Soil_Grass"
    },
    {
      "x": 13,
      "y": 14,
      "z": -14,
      "name": "Plant_Fern_Winter"
    },
    {
      "x": 13,
      "y": 5,
      "z": -13,
      "name": "Rock_Quartzite"
    },
    {
      "x": 13,
      "y": 6,
      "z": -13,
      "name": "Rock_Quartzite"
    },
    {
      "x": 13,
      "y": 7,
      "z": -13,
      "name": "Rock_Quartzite"
    },
    {
      "x": 13,
      "y": 8,
      "z": -13,
      "name": "Rock_Quartzite_Brick"
    },
    {
      "x": 13,
      "y": 9,
      "z": -13,
      "name": "Rock_Quartzite_Brick"
    },
    {
      "x": 13,
      "y": 10,
      "z": -13,
      "name": "Rock_Quartzite_Brick"
    },
    {
      "x": 13,
      "y": 11,
      "z": -13,
      "name": "Rock_Quartzite_Brick"
    },
    {
      "x": 13,
      "y": 12,
      "z": -13,
      "name": "Rock_Quartzite"
    },
    {
      "x": 13,
      "y": 13,
      "z": -13,
      "name": "Soil_Grass"
    },
    {
      "x": 13,
      "y": 14,
      "z": -13,
      "name": "Plant_Grass_Sharp_Tall"
    },
    {
      "x": 13,
      "y": 15,
      "z": -13,
      "name": "Plant_Grass_Sharp_Tall",
      "filler": 1024
    },
    {
      "x": 13,
      "y": 11,
      "z": -8,
      "name": "Rock_Quartzite_Brick"
    },
    {
      "x": 13,
      "y": 12,
      "z": -8,
      "name": "Rock_Quartzite"
    },
    {
      "x": 13,
      "y": 13,
      "z": -8,
      "name": "Soil_Grass"
    },
    {
      "x": 13,
      "y": 14,
      "z": -8,
      "name": "Plant_Grass_Lush_Short"
    },
    {
      "x": 13,
      "y": 8,
      "z": -7,
      "name": "Rock_Quartzite_Brick"
    },
    {
      "x": 13,
      "y": 9,
      "z": -7,
      "name": "Rock_Quartzite_Brick"
    },
    {
      "x": 13,
      "y": 10,
      "z": -7,
      "name": "Rock_Quartzite_Brick"
    },
    {
      "x": 13,
      "y": 11,
      "z": -7,
      "name": "Rock_Quartzite_Brick"
    },
    {
      "x": 13,
      "y": 12,
      "z": -7,
      "name": "Rock_Quartzite"
    },
    {
      "x": 13,
      "y": 13,
      "z": -7,
      "name": "Soil_Grass"
    },
    {
      "x": 13,
      "y": 14,
      "z": -7,
      "name": "Plant_Grass_Sharp_Tall"
    },
    {
      "x": 13,
      "y": 15,
      "z": -7,
      "name": "Plant_Grass_Sharp_Tall",
      "filler": 1024
    },
    {
      "x": 13,
      "y": 9,
      "z": -6,
      "name": "Rock_Quartzite_Brick"
    },
    {
      "x": 13,
      "y": 10,
      "z": -6,
      "name": "Rock_Quartzite_Brick"
    },
    {
      "x": 13,
      "y": 11,
      "z": -6,
      "name": "Rock_Quartzite_Brick"
    },
    {
      "x": 13,
      "y": 12,
      "z": -6,
      "name": "Rock_Quartzite"
    },
    {
      "x": 13,
      "y": 13,
      "z": -6,
      "name": "Soil_Grass"
    },
    {
      "x": 13,
      "y": 14,
      "z": -6,
      "name": "Plant_Grass_Sharp_Tall"
    },
    {
      "x": 13,
      "y": 15,
      "z": -6,
      "name": "Plant_Grass_Sharp_Tall",
      "filler": 1024
    },
    {
      "x": 13,
      "y": 8,
      "z": -5,
      "name": "Rock_Quartzite_Cobble"
    },
    {
      "x": 13,
      "y": 9,
      "z": -5,
      "name": "Rock_Quartzite_Brick"
    },
    {
      "x": 13,
      "y": 10,
      "z": -5,
      "name": "Rock_Quartzite_Brick"
    },
    {
      "x": 13,
      "y": 11,
      "z": -5,
      "name": "Rock_Quartzite_Brick"
    },
    {
      "x": 13,
      "y": 12,
      "z": -5,
      "name": "Rock_Quartzite"
    },
    {
      "x": 13,
      "y": 13,
      "z": -5,
      "name": "Soil_Grass"
    },
    {
      "x": 13,
      "y": 6,
      "z": -4,
      "name": "Rock_Quartzite"
    },
    {
      "x": 13,
      "y": 7,
      "z": -4,
      "name": "Rock_Quartzite_Cobble"
    },
    {
      "x": 13,
      "y": 8,
      "z": -4,
      "name": "Rock_Quartzite_Cobble"
    },
    {
      "x": 13,
      "y": 9,
      "z": -4,
      "name": "Rock_Quartzite_Cobble"
    },
    {
      "x": 13,
      "y": 10,
      "z": -4,
      "name": "Rock_Quartzite_Brick"
    },
    {
      "x": 13,
      "y": 11,
      "z": -4,
      "name": "Rock_Quartzite_Brick"
    },
    {
      "x": 13,
      "y": 12,
      "z": -4,
      "name": "Soil_Dirt"
    },
    {
      "x": 13,
      "y": 13,
      "z": -4,
      "name": "Soil_Grass"
    },
    {
      "x": 13,
      "y": 5,
      "z": -3,
      "name": "Rock_Quartzite"
    },
    {
      "x": 13,
      "y": 6,
      "z": -3,
      "name": "Rock_Quartzite"
    },
    {
      "x": 13,
      "y": 7,
      "z": -3,
      "name": "Rock_Quartzite"
    },
    {
      "x": 13,
      "y": 8,
      "z": -3,
      "name": "Rock_Quartzite"
    },
    {
      "x": 13,
      "y": 9,
      "z": -3,
      "name": "Rock_Quartzite_Cobble"
    },
    {
      "x": 13,
      "y": 10,
      "z": -3,
      "name": "Rock_Quartzite_Brick"
    },
    {
      "x": 13,
      "y": 11,
      "z": -3,
      "name": "Rock_Quartzite_Brick"
    },
    {
      "x": 13,
      "y": 12,
      "z": -3,
      "name": "Soil_Dirt"
    },
    {
      "x": 13,
      "y": 13,
      "z": -3,
      "name": "Soil_Grass"
    },
    {
      "x": 13,
      "y": 14,
      "z": -3,
      "name": "Plant_Grass_Lush_Short"
    },
    {
      "x": 13,
      "y": 5,
      "z": -2,
      "name": "Rock_Quartzite"
    },
    {
      "x": 13,
      "y": 6,
      "z": -2,
      "name": "Rock_Quartzite"
    },
    {
      "x": 13,
      "y": 7,
      "z": -2,
      "name": "Rock_Quartzite"
    },
    {
      "x": 13,
      "y": 8,
      "z": -2,
      "name": "Rock_Quartzite"
    },
    {
      "x": 13,
      "y": 9,
      "z": -2,
      "name": "Rock_Quartzite"
    },
    {
      "x": 13,
      "y": 10,
      "z": -2,
      "name": "Rock_Quartzite_Brick"
    },
    {
      "x": 13,
      "y": 11,
      "z": -2,
      "name": "Rock_Quartzite_Brick"
    },
    {
      "x": 13,
      "y": 12,
      "z": -2,
      "name": "Soil_Dirt"
    },
    {
      "x": 13,
      "y": 13,
      "z": -2,
      "name": "Soil_Grass"
    },
    {
      "x": 13,
      "y": 14,
      "z": -2,
      "name": "Plant_Grass_Lush_Short"
    },
    {
      "x": 13,
      "y": 5,
      "z": -1,
      "name": "Rock_Quartzite"
    },
    {
      "x": 13,
      "y": 6,
      "z": -1,
      "name": "Rock_Quartzite"
    },
    {
      "x": 13,
      "y": 7,
      "z": -1,
      "name": "Rock_Quartzite"
    },
    {
      "x": 13,
      "y": 8,
      "z": -1,
      "name": "Rock_Quartzite"
    },
    {
      "x": 13,
      "y": 9,
      "z": -1,
      "name": "Rock_Quartzite_Brick"
    },
    {
      "x": 13,
      "y": 10,
      "z": -1,
      "name": "Rock_Quartzite_Brick"
    },
    {
      "x": 13,
      "y": 11,
      "z": -1,
      "name": "Soil_Dirt"
    },
    {
      "x": 13,
      "y": 12,
      "z": -1,
      "name": "Soil_Grass"
    },
    {
      "x": 13,
      "y": 6,
      "z": 0,
      "name": "Rock_Quartzite"
    },
    {
      "x": 13,
      "y": 7,
      "z": 0,
      "name": "Rock_Quartzite"
    },
    {
      "x": 13,
      "y": 8,
      "z": 0,
      "name": "Rock_Quartzite"
    },
    {
      "x": 13,
      "y": 9,
      "z": 0,
      "name": "Rock_Quartzite_Brick"
    },
    {
      "x": 13,
      "y": 10,
      "z": 0,
      "name": "Rock_Quartzite_Brick"
    },
    {
      "x": 13,
      "y": 11,
      "z": 0,
      "name": "Rock_Quartzite_Brick"
    },
    {
      "x": 13,
      "y": 8,
      "z": 1,
      "name": "Rock_Quartzite"
    },
    {
      "x": 13,
      "y": 9,
      "z": 1,
      "name": "Rock_Quartzite_Brick"
    },
    {
      "x": 13,
      "y": 10,
      "z": 1,
      "name": "Rock_Quartzite_Brick"
    },
    {
      "x": 13,
      "y": 9,
      "z": 2,
      "name": "Rock_Quartzite_Brick"
    },
    {
      "x": 13,
      "y": 10,
      "z": 2,
      "name": "Rock_Quartzite_Brick"
    },
    {
      "x": 13,
      "y": 5,
      "z": 3,
      "name": "Rock_Quartzite"
    },
    {
      "x": 13,
      "y": 6,
      "z": 3,
      "name": "Rock_Quartzite_Cobble"
    },
    {
      "x": 13,
      "y": 7,
      "z": 3,
      "name": "Rock_Quartzite_Cobble"
    },
    {
      "x": 13,
      "y": 8,
      "z": 3,
      "name": "Rock_Quartzite_Cobble"
    },
    {
      "x": 13,
      "y": 9,
      "z": 3,
      "name": "Rock_Quartzite_Cobble"
    },
    {
      "x": 13,
      "y": 10,
      "z": 3,
      "name": "Rock_Quartzite_Brick"
    },
    {
      "x": 13,
      "y": 11,
      "z": 3,
      "name": "Soil_Grass"
    },
    {
      "x": 13,
      "y": 5,
      "z": 4,
      "name": "Rock_Quartzite"
    },
    {
      "x": 13,
      "y": 6,
      "z": 4,
      "name": "Rock_Quartzite"
    },
    {
      "x": 13,
      "y": 7,
      "z": 4,
      "name": "Rock_Quartzite"
    },
    {
      "x": 13,
      "y": 8,
      "z": 4,
      "name": "Rock_Quartzite"
    },
    {
      "x": 13,
      "y": 9,
      "z": 4,
      "name": "Rock_Quartzite_Cobble"
    },
    {
      "x": 13,
      "y": 10,
      "z": 4,
      "name": "Rock_Quartzite_Brick"
    },
    {
      "x": 13,
      "y": 11,
      "z": 4,
      "name": "Soil_Dirt"
    },
    {
      "x": 13,
      "y": 12,
      "z": 4,
      "name": "Soil_Grass"
    },
    {
      "x": 13,
      "y": 13,
      "z": 4,
      "name": "Plant_Grass_Lush_Short"
    },
    {
      "x": 13,
      "y": 5,
      "z": 5,
      "name": "Rock_Quartzite"
    },
    {
      "x": 13,
      "y": 6,
      "z": 5,
      "name": "Rock_Quartzite"
    },
    {
      "x": 13,
      "y": 7,
      "z": 5,
      "name": "Rock_Quartzite"
    },
    {
      "x": 13,
      "y": 8,
      "z": 5,
      "name": "Rock_Quartzite"
    },
    {
      "x": 13,
      "y": 9,
      "z": 5,
      "name": "Rock_Quartzite"
    },
    {
      "x": 13,
      "y": 10,
      "z": 5,
      "name": "Rock_Quartzite_Brick"
    },
    {
      "x": 13,
      "y": 11,
      "z": 5,
      "name": "Soil_Dirt"
    },
    {
      "x": 13,
      "y": 12,
      "z": 5,
      "name": "Soil_Grass"
    },
    {
      "x": 13,
      "y": 8,
      "z": 6,
      "name": "Rock_Quartzite"
    },
    {
      "x": 13,
      "y": 9,
      "z": 6,
      "name": "Rock_Quartzite"
    },
    {
      "x": 13,
      "y": 10,
      "z": 6,
      "name": "Rock_Quartzite_Brick"
    },
    {
      "x": 13,
      "y": 11,
      "z": 6,
      "name": "Rock_Quartzite_Brick"
    },
    {
      "x": 13,
      "y": 12,
      "z": 6,
      "name": "Soil_Dirt"
    },
    {
      "x": 13,
      "y": 13,
      "z": 6,
      "name": "Soil_Grass"
    },
    {
      "x": 13,
      "y": 14,
      "z": 6,
      "name": "Plant_Grass_Sharp"
    },
    {
      "x": 13,
      "y": 8,
      "z": 7,
      "name": "Rock_Quartzite"
    },
    {
      "x": 13,
      "y": 9,
      "z": 7,
      "name": "Rock_Quartzite"
    },
    {
      "x": 13,
      "y": 10,
      "z": 7,
      "name": "Rock_Quartzite"
    },
    {
      "x": 13,
      "y": 11,
      "z": 7,
      "name": "Rock_Quartzite_Brick"
    },
    {
      "x": 13,
      "y": 12,
      "z": 7,
      "name": "Soil_Dirt"
    },
    {
      "x": 13,
      "y": 13,
      "z": 7,
      "name": "Soil_Grass"
    },
    {
      "x": 13,
      "y": 14,
      "z": 7,
      "name": "Plant_Grass_Sharp_Tall"
    },
    {
      "x": 13,
      "y": 15,
      "z": 7,
      "name": "Plant_Grass_Sharp_Tall",
      "filler": 1024
    },
    {
      "x": 13,
      "y": 9,
      "z": 8,
      "name": "Rock_Quartzite"
    },
    {
      "x": 13,
      "y": 10,
      "z": 8,
      "name": "Rock_Quartzite"
    },
    {
      "x": 13,
      "y": 11,
      "z": 8,
      "name": "Rock_Quartzite_Brick"
    },
    {
      "x": 13,
      "y": 12,
      "z": 8,
      "name": "Rock_Quartzite"
    },
    {
      "x": 13,
      "y": 13,
      "z": 8,
      "name": "Soil_Dirt"
    },
    {
      "x": 13,
      "y": 14,
      "z": 8,
      "name": "Soil_Grass"
    },
    {
      "x": 13,
      "y": 15,
      "z": 8,
      "name": "Plant_Moss_Rug_Green"
    },
    {
      "x": 13,
      "y": 9,
      "z": 9,
      "name": "Rock_Quartzite_Cobble"
    },
    {
      "x": 13,
      "y": 10,
      "z": 9,
      "name": "Rock_Quartzite_Cobble"
    },
    {
      "x": 13,
      "y": 11,
      "z": 9,
      "name": "Rock_Quartzite_Brick"
    },
    {
      "x": 13,
      "y": 12,
      "z": 9,
      "name": "Rock_Quartzite"
    },
    {
      "x": 13,
      "y": 13,
      "z": 9,
      "name": "Soil_Dirt"
    },
    {
      "x": 13,
      "y": 14,
      "z": 9,
      "name": "Soil_Grass"
    },
    {
      "x": 13,
      "y": 15,
      "z": 9,
      "name": "Plant_Fern_Winter"
    },
    {
      "x": 13,
      "y": 8,
      "z": 10,
      "name": "Rock_Quartzite_Cobble"
    },
    {
      "x": 13,
      "y": 9,
      "z": 10,
      "name": "Rock_Quartzite_Cobble"
    },
    {
      "x": 13,
      "y": 10,
      "z": 10,
      "name": "Rock_Quartzite_Cobble"
    },
    {
      "x": 13,
      "y": 11,
      "z": 10,
      "name": "Rock_Quartzite_Brick"
    },
    {
      "x": 13,
      "y": 12,
      "z": 10,
      "name": "Soil_Dirt"
    },
    {
      "x": 13,
      "y": 13,
      "z": 10,
      "name": "Soil_Dirt"
    },
    {
      "x": 13,
      "y": 14,
      "z": 10,
      "name": "Soil_Grass"
    },
    {
      "x": 13,
      "y": 15,
      "z": 10,
      "name": "Plant_Fern_Winter"
    },
    {
      "x": 13,
      "y": 5,
      "z": 11,
      "name": "Rock_Quartzite"
    },
    {
      "x": 13,
      "y": 6,
      "z": 11,
      "name": "Rock_Quartzite"
    },
    {
      "x": 13,
      "y": 7,
      "z": 11,
      "name": "Rock_Quartzite"
    },
    {
      "x": 13,
      "y": 8,
      "z": 11,
      "name": "Rock_Quartzite"
    },
    {
      "x": 13,
      "y": 9,
      "z": 11,
      "name": "Rock_Quartzite"
    },
    {
      "x": 13,
      "y": 10,
      "z": 11,
      "name": "Rock_Quartzite_Brick"
    },
    {
      "x": 13,
      "y": 11,
      "z": 11,
      "name": "Rock_Quartzite_Brick"
    },
    {
      "x": 13,
      "y": 12,
      "z": 11,
      "name": "Rock_Quartzite"
    },
    {
      "x": 13,
      "y": 13,
      "z": 11,
      "name": "Soil_Grass"
    },
    {
      "x": 13,
      "y": 14,
      "z": 11,
      "name": "Plant_Grass_Sharp"
    },
    {
      "x": 13,
      "y": 6,
      "z": 12,
      "name": "Rock_Quartzite"
    },
    {
      "x": 13,
      "y": 7,
      "z": 12,
      "name": "Rock_Quartzite_Cobble"
    },
    {
      "x": 13,
      "y": 8,
      "z": 12,
      "name": "Rock_Quartzite_Cobble"
    },
    {
      "x": 13,
      "y": 9,
      "z": 12,
      "name": "Rock_Quartzite_Cobble"
    },
    {
      "x": 13,
      "y": 10,
      "z": 12,
      "name": "Rock_Quartzite_Brick"
    },
    {
      "x": 13,
      "y": 11,
      "z": 12,
      "name": "Rock_Quartzite_Brick"
    },
    {
      "x": 13,
      "y": 12,
      "z": 12,
      "name": "Soil_Dirt"
    },
    {
      "x": 13,
      "y": 13,
      "z": 12,
      "name": "Soil_Grass"
    },
    {
      "x": 13,
      "y": 14,
      "z": 12,
      "name": "Plant_Grass_Lush"
    },
    {
      "x": 14,
      "y": 8,
      "z": -14,
      "name": "Rock_Quartzite_Brick"
    },
    {
      "x": 14,
      "y": 9,
      "z": -14,
      "name": "Rock_Quartzite_Brick"
    },
    {
      "x": 14,
      "y": 10,
      "z": -14,
      "name": "Rock_Quartzite_Brick"
    },
    {
      "x": 14,
      "y": 11,
      "z": -14,
      "name": "Rock_Quartzite_Brick"
    },
    {
      "x": 14,
      "y": 12,
      "z": -14,
      "name": "Rock_Quartzite"
    },
    {
      "x": 14,
      "y": 13,
      "z": -14,
      "name": "Soil_Grass"
    },
    {
      "x": 14,
      "y": 14,
      "z": -14,
      "name": "Plant_Grass_Lush"
    },
    {
      "x": 14,
      "y": 7,
      "z": -13,
      "name": "Rock_Quartzite_Brick"
    },
    {
      "x": 14,
      "y": 8,
      "z": -13,
      "name": "Rock_Quartzite_Brick"
    },
    {
      "x": 14,
      "y": 9,
      "z": -13,
      "name": "Rock_Quartzite_Brick"
    },
    {
      "x": 14,
      "y": 10,
      "z": -13,
      "name": "Rock_Quartzite_Brick"
    },
    {
      "x": 14,
      "y": 11,
      "z": -13,
      "name": "Rock_Quartzite_Brick"
    },
    {
      "x": 14,
      "y": 12,
      "z": -13,
      "name": "Rock_Quartzite"
    },
    {
      "x": 14,
      "y": 13,
      "z": -13,
      "name": "Soil_Grass"
    },
    {
      "x": 14,
      "y": 13,
      "z": -9,
      "name": "Plant_Vine_Wall",
      "rotation": 2
    },
    {
      "x": 14,
      "y": 11,
      "z": -8,
      "name": "Rock_Quartzite_Brick"
    },
    {
      "x": 14,
      "y": 12,
      "z": -8,
      "name": "Rock_Quartzite"
    },
    {
      "x": 14,
      "y": 13,
      "z": -8,
      "name": "Soil_Grass"
    },
    {
      "x": 14,
      "y": 14,
      "z": -8,
      "name": "Plant_Moss_Rug_Green"
    },
    {
      "x": 14,
      "y": 8,
      "z": -7,
      "name": "Rock_Quartzite"
    },
    {
      "x": 14,
      "y": 9,
      "z": -7,
      "name": "Rock_Quartzite"
    },
    {
      "x": 14,
      "y": 10,
      "z": -7,
      "name": "Rock_Quartzite_Cobble"
    },
    {
      "x": 14,
      "y": 11,
      "z": -7,
      "name": "Rock_Quartzite_Brick"
    },
    {
      "x": 14,
      "y": 12,
      "z": -7,
      "name": "Rock_Quartzite"
    },
    {
      "x": 14,
      "y": 13,
      "z": -7,
      "name": "Soil_Grass"
    },
    {
      "x": 14,
      "y": 14,
      "z": -7,
      "name": "Plant_Moss_Rug_Green"
    },
    {
      "x": 14,
      "y": 6,
      "z": -6,
      "name": "Rock_Quartzite"
    },
    {
      "x": 14,
      "y": 7,
      "z": -6,
      "name": "Rock_Quartzite"
    },
    {
      "x": 14,
      "y": 8,
      "z": -6,
      "name": "Rock_Quartzite"
    },
    {
      "x": 14,
      "y": 9,
      "z": -6,
      "name": "Rock_Quartzite_Brick"
    },
    {
      "x": 14,
      "y": 10,
      "z": -6,
      "name": "Rock_Quartzite_Brick"
    },
    {
      "x": 14,
      "y": 11,
      "z": -6,
      "name": "Rock_Quartzite_Brick"
    },
    {
      "x": 14,
      "y": 12,
      "z": -6,
      "name": "Soil_Dirt"
    },
    {
      "x": 14,
      "y": 13,
      "z": -6,
      "name": "Soil_Grass"
    },
    {
      "x": 14,
      "y": 14,
      "z": -6,
      "name": "Plant_Grass_Sharp"
    },
    {
      "x": 14,
      "y": 5,
      "z": -5,
      "name": "Rock_Quartzite"
    },
    {
      "x": 14,
      "y": 6,
      "z": -5,
      "name": "Rock_Quartzite"
    },
    {
      "x": 14,
      "y": 7,
      "z": -5,
      "name": "Rock_Quartzite"
    },
    {
      "x": 14,
      "y": 8,
      "z": -5,
      "name": "Rock_Quartzite"
    },
    {
      "x": 14,
      "y": 9,
      "z": -5,
      "name": "Rock_Quartzite_Brick"
    },
    {
      "x": 14,
      "y": 10,
      "z": -5,
      "name": "Rock_Quartzite_Brick"
    },
    {
      "x": 14,
      "y": 11,
      "z": -5,
      "name": "Rock_Quartzite_Brick"
    },
    {
      "x": 14,
      "y": 12,
      "z": -5,
      "name": "Soil_Dirt"
    },
    {
      "x": 14,
      "y": 13,
      "z": -5,
      "name": "Soil_Grass"
    },
    {
      "x": 14,
      "y": 14,
      "z": -5,
      "name": "Plant_Grass_Sharp"
    },
    {
      "x": 14,
      "y": 5,
      "z": -4,
      "name": "Rock_Quartzite"
    },
    {
      "x": 14,
      "y": 6,
      "z": -4,
      "name": "Rock_Quartzite"
    },
    {
      "x": 14,
      "y": 7,
      "z": -4,
      "name": "Rock_Quartzite"
    },
    {
      "x": 14,
      "y": 8,
      "z": -4,
      "name": "Rock_Quartzite"
    },
    {
      "x": 14,
      "y": 9,
      "z": -4,
      "name": "Rock_Quartzite"
    },
    {
      "x": 14,
      "y": 10,
      "z": -4,
      "name": "Rock_Quartzite_Brick"
    },
    {
      "x": 14,
      "y": 11,
      "z": -4,
      "name": "Rock_Quartzite_Brick"
    },
    {
      "x": 14,
      "y": 12,
      "z": -4,
      "name": "Soil_Dirt"
    },
    {
      "x": 14,
      "y": 13,
      "z": -4,
      "name": "Soil_Grass"
    },
    {
      "x": 14,
      "y": 14,
      "z": -4,
      "name": "Plant_Grass_Lush"
    },
    {
      "x": 14,
      "y": 5,
      "z": -3,
      "name": "Rock_Quartzite"
    },
    {
      "x": 14,
      "y": 6,
      "z": -3,
      "name": "Rock_Quartzite"
    },
    {
      "x": 14,
      "y": 7,
      "z": -3,
      "name": "Rock_Quartzite"
    },
    {
      "x": 14,
      "y": 8,
      "z": -3,
      "name": "Rock_Quartzite"
    },
    {
      "x": 14,
      "y": 9,
      "z": -3,
      "name": "Rock_Quartzite"
    },
    {
      "x": 14,
      "y": 10,
      "z": -3,
      "name": "Rock_Quartzite_Brick"
    },
    {
      "x": 14,
      "y": 11,
      "z": -3,
      "name": "Soil_Dirt"
    },
    {
      "x": 14,
      "y": 12,
      "z": -3,
      "name": "Soil_Dirt"
    },
    {
      "x": 14,
      "y": 13,
      "z": -3,
      "name": "Soil_Grass"
    },
    {
      "x": 14,
      "y": 9,
      "z": -2,
      "name": "Rock_Quartzite_Brick"
    },
    {
      "x": 14,
      "y": 10,
      "z": -2,
      "name": "Rock_Quartzite_Brick"
    },
    {
      "x": 14,
      "y": 11,
      "z": -2,
      "name": "Soil_Dirt"
    },
    {
      "x": 14,
      "y": 12,
      "z": -2,
      "name": "Soil_Grass"
    },
    {
      "x": 14,
      "y": 13,
      "z": -2,
      "name": "Plant_Grass_Sharp"
    },
    {
      "x": 14,
      "y": 7,
      "z": -1,
      "name": "Rock_Quartzite"
    },
    {
      "x": 14,
      "y": 8,
      "z": -1,
      "name": "Rock_Quartzite_Brick"
    },
    {
      "x": 14,
      "y": 9,
      "z": -1,
      "name": "Rock_Quartzite_Brick"
    },
    {
      "x": 14,
      "y": 10,
      "z": -1,
      "name": "Rock_Quartzite_Brick"
    },
    {
      "x": 14,
      "y": 11,
      "z": -1,
      "name": "Soil_Dirt"
    },
    {
      "x": 14,
      "y": 12,
      "z": -1,
      "name": "Soil_Grass"
    },
    {
      "x": 14,
      "y": 13,
      "z": -1,
      "name": "Plant_Grass_Lush"
    },
    {
      "x": 14,
      "y": 5,
      "z": 0,
      "name": "Rock_Quartzite"
    },
    {
      "x": 14,
      "y": 6,
      "z": 0,
      "name": "Rock_Quartzite"
    },
    {
      "x": 14,
      "y": 7,
      "z": 0,
      "name": "Rock_Quartzite"
    },
    {
      "x": 14,
      "y": 8,
      "z": 0,
      "name": "Rock_Quartzite_Brick"
    },
    {
      "x": 14,
      "y": 9,
      "z": 0,
      "name": "Rock_Quartzite_Brick"
    },
    {
      "x": 14,
      "y": 10,
      "z": 0,
      "name": "Rock_Quartzite_Brick"
    },
    {
      "x": 14,
      "y": 11,
      "z": 0,
      "name": "Rock_Quartzite_Brick"
    },
    {
      "x": 14,
      "y": 5,
      "z": 1,
      "name": "Rock_Quartzite"
    },
    {
      "x": 14,
      "y": 6,
      "z": 1,
      "name": "Rock_Quartzite"
    },
    {
      "x": 14,
      "y": 7,
      "z": 1,
      "name": "Rock_Quartzite"
    },
    {
      "x": 14,
      "y": 8,
      "z": 1,
      "name": "Rock_Quartzite_Cobble"
    },
    {
      "x": 14,
      "y": 9,
      "z": 1,
      "name": "Rock_Quartzite_Brick"
    },
    {
      "x": 14,
      "y": 5,
      "z": 2,
      "name": "Rock_Quartzite"
    },
    {
      "x": 14,
      "y": 6,
      "z": 2,
      "name": "Rock_Quartzite_Cobble"
    },
    {
      "x": 14,
      "y": 7,
      "z": 2,
      "name": "Rock_Quartzite_Cobble"
    },
    {
      "x": 14,
      "y": 8,
      "z": 2,
      "name": "Rock_Quartzite_Cobble"
    },
    {
      "x": 14,
      "y": 9,
      "z": 2,
      "name": "Rock_Quartzite_Cobble"
    },
    {
      "x": 14,
      "y": 10,
      "z": 2,
      "name": "Rock_Quartzite_Cobble"
    },
    {
      "x": 14,
      "y": 6,
      "z": 3,
      "name": "Rock_Quartzite"
    },
    {
      "x": 14,
      "y": 7,
      "z": 3,
      "name": "Rock_Quartzite_Brick"
    },
    {
      "x": 14,
      "y": 8,
      "z": 3,
      "name": "Rock_Quartzite_Brick"
    },
    {
      "x": 14,
      "y": 9,
      "z": 3,
      "name": "Rock_Quartzite_Brick"
    },
    {
      "x": 14,
      "y": 10,
      "z": 3,
      "name": "Rock_Quartzite_Brick"
    },
    {
      "x": 14,
      "y": 7,
      "z": 4,
      "name": "Rock_Quartzite_Brick"
    },
    {
      "x": 14,
      "y": 8,
      "z": 4,
      "name": "Rock_Quartzite_Brick"
    },
    {
      "x": 14,
      "y": 9,
      "z": 4,
      "name": "Rock_Quartzite_Brick"
    },
    {
      "x": 14,
      "y": 10,
      "z": 4,
      "name": "Rock_Quartzite_Brick"
    },
    {
      "x": 14,
      "y": 11,
      "z": 4,
      "name": "Rock_Quartzite_Brick"
    },
    {
      "x": 14,
      "y": 12,
      "z": 4,
      "name": "Soil_Grass"
    },
    {
      "x": 14,
      "y": 7,
      "z": 5,
      "name": "Rock_Quartzite"
    },
    {
      "x": 14,
      "y": 8,
      "z": 5,
      "name": "Rock_Quartzite"
    },
    {
      "x": 14,
      "y": 9,
      "z": 5,
      "name": "Rock_Quartzite_Brick"
    },
    {
      "x": 14,
      "y": 10,
      "z": 5,
      "name": "Rock_Quartzite_Brick"
    },
    {
      "x": 14,
      "y": 11,
      "z": 5,
      "name": "Rock_Quartzite_Brick"
    },
    {
      "x": 14,
      "y": 12,
      "z": 5,
      "name": "Soil_Grass"
    },
    {
      "x": 14,
      "y": 13,
      "z": 5,
      "name": "Plant_Grass_Lush"
    },
    {
      "x": 14,
      "y": 8,
      "z": 6,
      "name": "Rock_Quartzite"
    },
    {
      "x": 14,
      "y": 9,
      "z": 6,
      "name": "Rock_Quartzite"
    },
    {
      "x": 14,
      "y": 10,
      "z": 6,
      "name": "Rock_Quartzite_Brick"
    },
    {
      "x": 14,
      "y": 11,
      "z": 6,
      "name": "Rock_Quartzite_Brick"
    },
    {
      "x": 14,
      "y": 12,
      "z": 6,
      "name": "Soil_Grass"
    },
    {
      "x": 14,
      "y": 9,
      "z": 7,
      "name": "Rock_Quartzite"
    },
    {
      "x": 14,
      "y": 10,
      "z": 7,
      "name": "Rock_Quartzite"
    },
    {
      "x": 14,
      "y": 11,
      "z": 7,
      "name": "Rock_Quartzite_Brick"
    },
    {
      "x": 14,
      "y": 12,
      "z": 7,
      "name": "Soil_Dirt"
    },
    {
      "x": 14,
      "y": 13,
      "z": 7,
      "name": "Soil_Grass"
    },
    {
      "x": 14,
      "y": 9,
      "z": 8,
      "name": "Rock_Quartzite"
    },
    {
      "x": 14,
      "y": 10,
      "z": 8,
      "name": "Rock_Quartzite"
    },
    {
      "x": 14,
      "y": 11,
      "z": 8,
      "name": "Rock_Quartzite_Brick"
    },
    {
      "x": 14,
      "y": 12,
      "z": 8,
      "name": "Rock_Quartzite"
    },
    {
      "x": 14,
      "y": 13,
      "z": 8,
      "name": "Soil_Dirt"
    },
    {
      "x": 14,
      "y": 14,
      "z": 8,
      "name": "Soil_Grass"
    },
    {
      "x": 14,
      "y": 15,
      "z": 8,
      "name": "Plant_Moss_Rug_Green"
    },
    {
      "x": 14,
      "y": 9,
      "z": 9,
      "name": "Rock_Quartzite"
    },
    {
      "x": 14,
      "y": 10,
      "z": 9,
      "name": "Rock_Quartzite_Brick"
    },
    {
      "x": 14,
      "y": 11,
      "z": 9,
      "name": "Rock_Quartzite_Brick"
    },
    {
      "x": 14,
      "y": 12,
      "z": 9,
      "name": "Soil_Dirt"
    },
    {
      "x": 14,
      "y": 13,
      "z": 9,
      "name": "Soil_Dirt"
    },
    {
      "x": 14,
      "y": 14,
      "z": 9,
      "name": "Soil_Grass"
    },
    {
      "x": 14,
      "y": 15,
      "z": 9,
      "name": "Plant_Moss_Rug_Green"
    },
    {
      "x": 14,
      "y": 7,
      "z": 10,
      "name": "Rock_Quartzite"
    },
    {
      "x": 14,
      "y": 8,
      "z": 10,
      "name": "Rock_Quartzite"
    },
    {
      "x": 14,
      "y": 9,
      "z": 10,
      "name": "Rock_Quartzite_Brick"
    },
    {
      "x": 14,
      "y": 10,
      "z": 10,
      "name": "Rock_Quartzite_Brick"
    },
    {
      "x": 14,
      "y": 11,
      "z": 10,
      "name": "Rock_Quartzite_Brick"
    },
    {
      "x": 14,
      "y": 12,
      "z": 10,
      "name": "Soil_Dirt"
    },
    {
      "x": 14,
      "y": 13,
      "z": 10,
      "name": "Soil_Grass"
    },
    {
      "x": 14,
      "y": 14,
      "z": 10,
      "name": "Plant_Grass_Sharp_Tall"
    },
    {
      "x": 14,
      "y": 15,
      "z": 10,
      "name": "Plant_Grass_Sharp_Tall",
      "filler": 1024
    },
    {
      "x": 14,
      "y": 6,
      "z": 11,
      "name": "Rock_Quartzite"
    },
    {
      "x": 14,
      "y": 7,
      "z": 11,
      "name": "Rock_Quartzite"
    },
    {
      "x": 14,
      "y": 8,
      "z": 11,
      "name": "Rock_Quartzite_Brick"
    },
    {
      "x": 14,
      "y": 9,
      "z": 11,
      "name": "Rock_Quartzite_Brick"
    },
    {
      "x": 14,
      "y": 10,
      "z": 11,
      "name": "Rock_Quartzite_Brick"
    },
    {
      "x": 14,
      "y": 11,
      "z": 11,
      "name": "Rock_Quartzite_Brick"
    },
    {
      "x": 14,
      "y": 12,
      "z": 11,
      "name": "Rock_Quartzite"
    },
    {
      "x": 14,
      "y": 13,
      "z": 11,
      "name": "Soil_Grass"
    },
    {
      "x": 14,
      "y": 14,
      "z": 11,
      "name": "Plant_Grass_Sharp"
    },
    {
      "x": 14,
      "y": 7,
      "z": 12,
      "name": "Rock_Quartzite"
    },
    {
      "x": 14,
      "y": 8,
      "z": 12,
      "name": "Rock_Quartzite_Brick"
    },
    {
      "x": 14,
      "y": 9,
      "z": 12,
      "name": "Rock_Quartzite_Brick"
    },
    {
      "x": 14,
      "y": 10,
      "z": 12,
      "name": "Rock_Quartzite_Brick"
    },
    {
      "x": 14,
      "y": 11,
      "z": 12,
      "name": "Rock_Quartzite_Brick"
    },
    {
      "x": 14,
      "y": 12,
      "z": 12,
      "name": "Rock_Quartzite"
    },
    {
      "x": 14,
      "y": 13,
      "z": 12,
      "name": "Soil_Grass"
    },
    {
      "x": 15,
      "y": 13,
      "z": -8,
      "name": "Plant_Vine",
      "rotation": 1
    },
    {
      "x": 15,
      "y": 11,
      "z": -7,
      "name": "Plant_Vine_Wall",
      "rotation": 1
    },
    {
      "x": 15,
      "y": 12,
      "z": -7,
      "name": "Plant_Vine",
      "rotation": 1
    },
    {
      "x": 15,
      "y": 13,
      "z": -7,
      "name": "Plant_Vine",
      "rotation": 1
    },
    {
      "x": 15,
      "y": 13,
      "z": -6,
      "name": "Plant_Vine",
      "rotation": 1
    },
    {
      "x": 15,
      "y": 14,
      "z": 8,
      "name": "Plant_Vine",
      "rotation": 1
    },
    {
      "x": 15,
      "y": 12,
      "z": 9,
      "name": "Plant_Vine_Wall",
      "rotation": 1
    },
    {
      "x": 15,
      "y": 13,
      "z": 9,
      "name": "Plant_Vine",
      "rotation": 1
    },
    {
      "x": 15,
      "y": 14,
      "z": 9,
      "name": "Plant_Vine",
      "rotation": 1
    },
    {
      "x": 15,
      "y": 13,
      "z": 10,
      "name": "Plant_Vine",
      "rotation": 1
    },
    {
      "x": 15,
      "y": 13,
      "z": 11,
      "name": "Plant_Vine_Wall",
      "rotation": 1
    }
  ]
}