{
  "version": 8,
  "blockIdVersion": 8,
  "anchorX": 25,
  "anchorY": 13,
  "anchorZ": 16,
  "blocks": [
    {
      "x": 15,
      "y": 17,
      "z": 15,
      "name": "Rock_Basalt"
    },
    {
      "x": 15,
      "y": 18,
      "z": 15,
      "name": "Rock_Basalt"
    },
    {
      "x": 15,
      "y": 19,
      "z": 15,
      "name": "Rock_Basalt"
    },
    {
      "x": 15,
      "y": 15,
      "z": 16,
      "name": "Rock_Basalt"
    },
    {
      "x": 15,
      "y": 16,
      "z": 16,
      "name": "Rock_Basalt"
    },
    {
      "x": 15,
      "y": 17,
      "z": 16,
      "name": "Rock_Basalt"
    },
    {
      "x": 15,
      "y": 18,
      "z": 16,
      "name": "Rock_Basalt"
    },
    {
      "x": 15,
      "y": 19,
      "z": 16,
      "name": "Rock_Basalt"
    },
    {
      "x": 15,
      "y": 20,
      "z": 16,
      "name": "Rock_Basalt"
    },
    {
      "x": 15,
      "y": 21,
      "z": 16,
      "name": "Rock_Basalt"
    },
    {
      "x": 15,
      "y": 22,
      "z": 16,
      "name": "Soil_Dirt"
    },
    {
      "x": 15,
      "y": 17,
      "z": 17,
      "name": "Rock_Basalt"
    },
    {
      "x": 15,
      "y": 18,
      "z": 17,
      "name": "Rock_Basalt"
    },
    {
      "x": 15,
      "y": 19,
      "z": 17,
      "name": "Rock_Basalt"
    },
    {
      "x": 15,
      "y": 20,
      "z": 17,
      "name": "Rock_Basalt"
    },
    {
      "x": 15,
      "y": 21,
      "z": 17,
      "name": "Rock_Basalt"
    },
    {
      "x": 15,
      "y": 24,
      "z": 17,
      "name": "Soil_Snow"
    },
    {
      "x": 15,
      "y": 25,
      "z": 17,
      "name": "Soil_Snow"
    },
    {
      "x": 16,
      "y": 17,
      "z": 14,
      "name": "Rock_Basalt"
    },
    {
      "x": 16,
      "y": 18,
      "z": 14,
      "name": "Rock_Basalt"
    },
    {
      "x": 16,
      "y": 19,
      "z": 14,
      "name": "Rock_Basalt"
    },
    {
      "x": 16,
      "y": 20,
      "z": 14,
      "name": "Rock_Basalt"
    },
    {
      "x": 16,
      "y": 21,
      "z": 14,
      "name": "Rock_Basalt"
    },
    {
      "x": 16,
      "y": 22,
      "z": 14,
      "name": "Rock_Basalt"
    },
    {
      "x": 16,
      "y": 14,
      "z": 15,
      "name": "Rock_Basalt"
    },
    {
      "x": 16,
      "y": 15,
      "z": 15,
      "name": "Rock_Basalt"
    },
    {
      "x": 16,
      "y": 16,
      "z": 15,
      "name": "Rock_Basalt"
    },
    {
      "x": 16,
      "y": 17,
      "z": 15,
      "name": "Rock_Basalt"
    },
    {
      "x": 16,
      "y": 18,
      "z": 15,
      "name": "Rock_Basalt"
    },
    {
      "x": 16,
      "y": 19,
      "z": 15,
      "name": "Rock_Basalt"
    },
    {
      "x": 16,
      "y": 20,
      "z": 15,
      "name": "Rock_Basalt"
    },
    {
      "x": 16,
      "y": 21,
      "z": 15,
      "name": "Rock_Basalt"
    },
    {
      "x": 16,
      "y": 22,
      "z": 15,
      "name": "Soil_Dirt"
    },
    {
      "x": 16,
      "y": 23,
      "z": 15,
      "name": "Soil_Dirt"
    },
    {
      "x": 16,
      "y": 14,
      "z": 16,
      "name": "Rock_Basalt"
    },
    {
      "x": 16,
      "y": 15,
      "z": 16,
      "name": "Rock_Basalt"
    },
    {
      "x": 16,
      "y": 16,
      "z": 16,
      "name": "Rock_Basalt"
    },
    {
      "x": 16,
      "y": 17,
      "z": 16,
      "name": "Rock_Basalt"
    },
    {
      "x": 16,
      "y": 18,
      "z": 16,
      "name": "Rock_Basalt"
    },
    {
      "x": 16,
      "y": 19,
      "z": 16,
      "name": "Rock_Basalt"
    },
    {
      "x": 16,
      "y": 20,
      "z": 16,
      "name": "Rock_Basalt"
    },
    {
      "x": 16,
      "y": 21,
      "z": 16,
      "name": "Rock_Basalt"
    },
    {
      "x": 16,
      "y": 22,
      "z": 16,
      "name": "Soil_Dirt"
    },
    {
      "x": 16,
      "y": 23,
      "z": 16,
      "name": "Soil_Dirt"
    },
    {
      "x": 16,
      "y": 24,
      "z": 16,
      "name": "Soil_Dirt"
    },
    {
      "x": 16,
      "y": 25,
      "z": 16,
      "name": "Soil_Dirt"
    },
    {
      "x": 16,
      "y": 15,
      "z": 17,
      "name": "Rock_Basalt"
    },
    {
      "x": 16,
      "y": 16,
      "z": 17,
      "name": "Rock_Basalt"
    },
    {
      "x": 16,
      "y": 17,
      "z": 17,
      "name": "Rock_Basalt"
    },
    {
      "x": 16,
      "y": 18,
      "z": 17,
      "name": "Rock_Basalt"
    },
    {
      "x": 16,
      "y": 19,
      "z": 17,
      "name": "Rock_Basalt"
    },
    {
      "x": 16,
      "y": 20,
      "z": 17,
      "name": "Rock_Basalt"
    },
    {
      "x": 16,
      "y": 21,
      "z": 17,
      "name": "Soil_Dirt"
    },
    {
      "x": 16,
      "y": 22,
      "z": 17,
      "name": "Soil_Dirt"
    },
    {
      "x": 16,
      "y": 23,
      "z": 17,
      "name": "Soil_Dirt"
    },
    {
      "x": 16,
      "y": 24,
      "z": 17,
      "name": "Soil_Dirt"
    },
    {
      "x": 16,
      "y": 25,
      "z": 17,
      "name": "Soil_Dirt"
    },
    {
      "x": 16,
      "y": 26,
      "z": 17,
      "name": "Soil_Snow"
    },
    {
      "x": 16,
      "y": 27,
      "z": 17,
      "name": "Soil_Snow"
    },
    {
      "x": 16,
      "y": 18,
      "z": 18,
      "name": "Rock_Basalt"
    },
    {
      "x": 16,
      "y": 19,
      "z": 18,
      "name": "Rock_Basalt"
    },
    {
      "x": 16,
      "y": 20,
      "z": 18,
      "name": "Rock_Basalt"
    },
    {
      "x": 16,
      "y": 26,
      "z": 18,
      "name": "Soil_Snow"
    },
    {
      "x": 17,
      "y": 15,
      "z": 14,
      "name": "Rock_Basalt"
    },
    {
      "x": 17,
      "y": 17,
      "z": 14,
      "name": "Rock_Basalt"
    },
    {
      "x": 17,
      "y": 18,
      "z": 14,
      "name": "Rock_Basalt"
    },
    {
      "x": 17,
      "y": 19,
      "z": 14,
      "name": "Rock_Basalt"
    },
    {
      "x": 17,
      "y": 20,
      "z": 14,
      "name": "Rock_Basalt"
    },
    {
      "x": 17,
      "y": 21,
      "z": 14,
      "name": "Rock_Basalt"
    },
    {
      "x": 17,
      "y": 22,
      "z": 14,
      "name": "Rock_Basalt"
    },
    {
      "x": 17,
      "y": 23,
      "z": 14,
      "name": "Soil_Dirt"
    },
    {
      "x": 17,
      "y": 13,
      "z": 15,
      "name": "Rock_Basalt"
    },
    {
      "x": 17,
      "y": 14,
      "z": 15,
      "name": "Rock_Basalt"
    },
    {
      "x": 17,
      "y": 15,
      "z": 15,
      "name": "Rock_Basalt"
    },
    {
      "x": 17,
      "y": 16,
      "z": 15,
      "name": "Rock_Basalt"
    },
    {
      "x": 17,
      "y": 17,
      "z": 15,
      "name": "Rock_Basalt"
    },
    {
      "x": 17,
      "y": 18,
      "z": 15,
      "name": "Rock_Basalt"
    },
    {
      "x": 17,
      "y": 19,
      "z": 15,
      "name": "Rock_Basalt"
    },
    {
      "x": 17,
      "y": 20,
      "z": 15,
      "name": "Rock_Basalt"
    },
    {
      "x": 17,
      "y": 21,
      "z": 15,
      "name": "Rock_Basalt"
    },
    {
      "x": 17,
      "y": 22,
      "z": 15,
      "name": "Soil_Dirt"
    },
    {
      "x": 17,
      "y": 23,
      "z": 15,
      "name": "Soil_Dirt"
    },
    {
      "x": 17,
      "y": 24,
      "z": 15,
      "name": "Soil_Dirt"
    },
    {
      "x": 17,
      "y": 25,
      "z": 15,
      "name": "Soil_Dirt"
    },
    {
      "x": 17,
      "y": 27,
      "z": 15,
      "name": "Soil_Snow"
    },
    {
      "x": 17,
      "y": 12,
      "z": 16,
      "name": "Rock_Basalt"
    },
    {
      "x": 17,
      "y": 13,
      "z": 16,
      "name": "Rock_Basalt"
    },
    {
      "x": 17,
      "y": 14,
      "z": 16,
      "name": "Rock_Basalt"
    },
    {
      "x": 17,
      "y": 15,
      "z": 16,
      "name": "Rock_Basalt"
    },
    {
      "x": 17,
      "y": 16,
      "z": 16,
      "name": "Rock_Basalt"
    },
    {
      "x": 17,
      "y": 17,
      "z": 16,
      "name": "Rock_Basalt"
    },
    {
      "x": 17,
      "y": 18,
      "z": 16,
      "name": "Rock_Basalt"
    },
    {
      "x": 17,
      "y": 19,
      "z": 16,
      "name": "Rock_Basalt"
    },
    {
      "x": 17,
      "y": 20,
      "z": 16,
      "name": "Rock_Basalt"
    },
    {
      "x": 17,
      "y": 21,
      "z": 16,
      "name": "Rock_Basalt"
    },
    {
      "x": 17,
      "y": 22,
      "z": 16,
      "name": "Soil_Dirt"
    },
    {
      "x": 17,
      "y": 23,
      "z": 16,
      "name": "Soil_Dirt"
    },
    {
      "x": 17,
      "y": 24,
      "z": 16,
      "name": "Soil_Dirt"
    },
    {
      "x": 17,
      "y": 25,
      "z": 16,
      "name": "Soil_Dirt"
    },
    {
      "x": 17,
      "y": 26,
      "z": 16,
      "name": "Soil_Dirt"
    },
    {
      "x": 17,
      "y": 27,
      "z": 16,
      "name": "Soil_Snow"
    },
    {
      "x": 17,
      "y": 12,
      "z": 17,
      "name": "Rock_Basalt"
    },
    {
      "x": 17,
      "y": 13,
      "z": 17,
      "name": "Rock_Basalt"
    },
    {
      "x": 17,
      "y": 14,
      "z": 17,
      "name": "Rock_Basalt"
    },
    {
      "x": 17,
      "y": 15,
      "z": 17,
      "name": "Rock_Basalt"
    },
    {
      "x": 17,
      "y": 16,
      "z": 17,
      "name": "Rock_Basalt"
    },
    {
      "x": 17,
      "y": 17,
      "z": 17,
      "name": "Rock_Basalt"
    },
    {
      "x": 17,
      "y": 18,
      "z": 17,
      "name": "Rock_Basalt"
    },
    {
      "x": 17,
      "y": 19,
      "z": 17,
      "name": "Rock_Basalt"
    },
    {
      "x": 17,
      "y": 20,
      "z": 17,
      "name": "Rock_Basalt"
    },
    {
      "x": 17,
      "y": 21,
      "z": 17,
      "name": "Rock_Basalt"
    },
    {
      "x": 17,
      "y": 22,
      "z": 17,
      "name": "Soil_Dirt"
    },
    {
      "x": 17,
      "y": 23,
      "z": 17,
      "name": "Soil_Dirt"
    },
    {
      "x": 17,
      "y": 24,
      "z": 17,
      "name": "Soil_Dirt"
    },
    {
      "x": 17,
      "y": 25,
      "z": 17,
      "name": "Soil_Dirt"
    },
    {
      "x": 17,
      "y": 26,
      "z": 17,
      "name": "Soil_Dirt"
    },
    {
      "x": 17,
      "y": 27,
      "z": 17,
      "name": "Soil_Snow"
    },
    {
      "x": 17,
      "y": 14,
      "z": 18,
      "name": "Rock_Basalt"
    },
    {
      "x": 17,
      "y": 15,
      "z": 18,
      "name": "Rock_Basalt"
    },
    {
      "x": 17,
      "y": 16,
      "z": 18,
      "name": "Rock_Basalt"
    },
    {
      "x": 17,
      "y": 17,
      "z": 18,
      "name": "Rock_Basalt"
    },
    {
      "x": 17,
      "y": 18,
      "z": 18,
      "name": "Rock_Basalt"
    },
    {
      "x": 17,
      "y": 19,
      "z": 18,
      "name": "Rock_Basalt"
    },
    {
      "x": 17,
      "y": 20,
      "z": 18,
      "name": "Rock_Basalt"
    },
    {
      "x": 17,
      "y": 21,
      "z": 18,
      "name": "Rock_Basalt"
    },
    {
      "x": 17,
      "y": 22,
      "z": 18,
      "name": "Soil_Dirt"
    },
    {
      "x": 17,
      "y": 23,
      "z": 18,
      "name": "Soil_Dirt"
    },
    {
      "x": 17,
      "y": 27,
      "z": 18,
      "name": "Soil_Snow"
    },
    {
      "x": 18,
      "y": 13,
      "z": 14,
      "name": "Rock_Basalt"
    },
    {
      "x": 18,
      "y": 14,
      "z": 14,
      "name": "Rock_Basalt"
    },
    {
      "x": 18,
      "y": 15,
      "z": 14,
      "name": "Rock_Basalt"
    },
    {
      "x": 18,
      "y": 17,
      "z": 14,
      "name": "Rock_Basalt"
    },
    {
      "x": 18,
      "y": 20,
      "z": 14,
      "name": "Rock_Basalt"
    },
    {
      "x": 18,
      "y": 21,
      "z": 14,
      "name": "Rock_Basalt"
    },
    {
      "x": 18,
      "y": 22,
      "z": 14,
      "name": "Rock_Basalt"
    },
    {
      "x": 18,
      "y": 23,
      "z": 14,
      "name": "Rock_Basalt"
    },
    {
      "x": 18,
      "y": 11,
      "z": 15,
      "name": "Rock_Basalt"
    },
    {
      "x": 18,
      "y": 12,
      "z": 15,
      "name": "Rock_Basalt"
    },
    {
      "x": 18,
      "y": 13,
      "z": 15,
      "name": "Rock_Basalt"
    },
    {
      "x": 18,
      "y": 14,
      "z": 15,
      "name": "Rock_Basalt"
    },
    {
      "x": 18,
      "y": 15,
      "z": 15,
      "name": "Rock_Basalt"
    },
    {
      "x": 18,
      "y": 16,
      "z": 15,
      "name": "Rock_Basalt"
    },
    {
      "x": 18,
      "y": 17,
      "z": 15,
      "name": "Rock_Basalt"
    },
    {
      "x": 18,
      "y": 18,
      "z": 15,
      "name": "Rock_Basalt"
    },
    {
      "x": 18,
      "y": 19,
      "z": 15,
      "name": "Rock_Basalt"
    },
    {
      "x": 18,
      "y": 20,
      "z": 15,
      "name": "Rock_Basalt"
    },
    {
      "x": 18,
      "y": 21,
      "z": 15,
      "name": "Rock_Basalt"
    },
    {
      "x": 18,
      "y": 22,
      "z": 15,
      "name": "Rock_Basalt"
    },
    {
      "x": 18,
      "y": 23,
      "z": 15,
      "name": "Soil_Dirt"
    },
    {
      "x": 18,
      "y": 24,
      "z": 15,
      "name": "Soil_Dirt"
    },
    {
      "x": 18,
      "y": 25,
      "z": 15,
      "name": "Soil_Dirt"
    },
    {
      "x": 18,
      "y": 26,
      "z": 15,
      "name": "Soil_Dirt"
    },
    {
      "x": 18,
      "y": 27,
      "z": 15,
      "name": "Soil_Snow"
    },
    {
      "x": 18,
      "y": 11,
      "z": 16,
      "name": "Rock_Basalt"
    },
    {
      "x": 18,
      "y": 12,
      "z": 16,
      "name": "Rock_Basalt"
    },
    {
      "x": 18,
      "y": 13,
      "z": 16,
      "name": "Rock_Basalt"
    },
    {
      "x": 18,
      "y": 14,
      "z": 16,
      "name": "Rock_Basalt"
    },
    {
      "x": 18,
      "y": 15,
      "z": 16,
      "name": "Rock_Basalt"
    },
    {
      "x": 18,
      "y": 16,
      "z": 16,
      "name": "Rock_Basalt"
    },
    {
      "x": 18,
      "y": 17,
      "z": 16,
      "name": "Rock_Basalt"
    },
    {
      "x": 18,
      "y": 18,
      "z": 16,
      "name": "Rock_Basalt"
    },
    {
      "x": 18,
      "y": 19,
      "z": 16,
      "name": "Rock_Basalt"
    },
    {
      "x": 18,
      "y": 20,
      "z": 16,
      "name": "Rock_Basalt"
    },
    {
      "x": 18,
      "y": 21,
      "z": 16,
      "name": "Rock_Basalt"
    },
    {
      "x": 18,
      "y": 22,
      "z": 16,
      "name": "Soil_Dirt"
    },
    {
      "x": 18,
      "y": 23,
      "z": 16,
      "name": "Soil_Dirt"
    },
    {
      "x": 18,
      "y": 24,
      "z": 16,
      "name": "Soil_Dirt"
    },
    {
      "x": 18,
      "y": 25,
      "z": 16,
      "name": "Soil_Dirt"
    },
    {
      "x": 18,
      "y": 26,
      "z": 16,
      "name": "Soil_Dirt"
    },
    {
      "x": 18,
      "y": 27,
      "z": 16,
      "name": "Soil_Dirt"
    },
    {
      "x": 18,
      "y": 28,
      "z": 16,
      "name": "Soil_Snow"
    },
    {
      "x": 18,
      "y": 10,
      "z": 17,
      "name": "Rock_Basalt"
    },
    {
      "x": 18,
      "y": 11,
      "z": 17,
      "name": "Rock_Basalt"
    },
    {
      "x": 18,
      "y": 12,
      "z": 17,
      "name": "Rock_Basalt"
    },
    {
      "x": 18,
      "y": 13,
      "z": 17,
      "name": "Rock_Basalt"
    },
    {
      "x": 18,
      "y": 14,
      "z": 17,
      "name": "Rock_Basalt"
    },
    {
      "x": 18,
      "y": 15,
      "z": 17,
      "name": "Rock_Basalt"
    },
    {
      "x": 18,
      "y": 16,
      "z": 17,
      "name": "Rock_Basalt"
    },
    {
      "x": 18,
      "y": 17,
      "z": 17,
      "name": "Rock_Basalt"
    },
    {
      "x": 18,
      "y": 18,
      "z": 17,
      "name": "Rock_Basalt"
    },
    {
      "x": 18,
      "y": 19,
      "z": 17,
      "name": "Rock_Basalt"
    },
    {
      "x": 18,
      "y": 20,
      "z": 17,
      "name": "Rock_Basalt"
    },
    {
      "x": 18,
      "y": 21,
      "z": 17,
      "name": "Rock_Basalt"
    },
    {
      "x": 18,
      "y": 22,
      "z": 17,
      "name": "Soil_Dirt"
    },
    {
      "x": 18,
      "y": 23,
      "z": 17,
      "name": "Soil_Dirt"
    },
    {
      "x": 18,
      "y": 24,
      "z": 17,
      "name": "Soil_Dirt"
    },
    {
      "x": 18,
      "y": 25,
      "z": 17,
      "name": "Soil_Dirt"
    },
    {
      "x": 18,
      "y": 26,
      "z": 17,
      "name": "Soil_Dirt"
    },
    {
      "x": 18,
      "y": 27,
      "z": 17,
      "name": "Soil_Dirt"
    },
    {
      "x": 18,
      "y": 28,
      "z": 17,
      "name": "Soil_Snow"
    },
    {
      "x": 18,
      "y": 11,
      "z": 18,
      "name": "Rock_Basalt"
    },
    {
      "x": 18,
      "y": 12,
      "z": 18,
      "name": "Rock_Basalt"
    },
    {
      "x": 18,
      "y": 13,
      "z": 18,
      "name": "Rock_Basalt"
    },
    {
      "x": 18,
      "y": 14,
      "z": 18,
      "name": "Rock_Basalt"
    },
    {
      "x": 18,
      "y": 15,
      "z": 18,
      "name": "Rock_Basalt"
    },
    {
      "x": 18,
      "y": 21,
      "z": 18,
      "name": "Rock_Basalt"
    },
    {
      "x": 18,
      "y": 22,
      "z": 18,
      "name": "Soil_Dirt"
    },
    {
      "x": 18,
      "y": 23,
      "z": 18,
      "name": "Soil_Dirt"
    },
    {
      "x": 18,
      "y": 24,
      "z": 18,
      "name": "Soil_Dirt"
    },
    {
      "x": 18,
      "y": 26,
      "z": 18,
      "name": "Soil_Snow"
    },
    {
      "x": 18,
      "y": 27,
      "z": 18,
      "name": "Soil_Snow"
    },
    {
      "x": 19,
      "y": 12,
      "z": 5,
      "name": "Rock_Basalt"
    },
    {
      "x": 19,
      "y": 13,
      "z": 5,
      "name": "Rock_Basalt"
    },
    {
      "x": 19,
      "y": 14,
      "z": 5,
      "name": "Rock_Basalt"
    },
    {
      "x": 19,
      "y": 15,
      "z": 5,
      "name": "Rock_Basalt"
    },
    {
      "x": 19,
      "y": 16,
      "z": 5,
      "name": "Rock_Basalt"
    },
    {
      "x": 19,
      "y": 17,
      "z": 5,
      "name": "Rock_Basalt"
    },
    {
      "x": 19,
      "y": 10,
      "z": 6,
      "name": "Rock_Basalt"
    },
    {
      "x": 19,
      "y": 11,
      "z": 6,
      "name": "Rock_Basalt"
    },
    {
      "x": 19,
      "y": 12,
      "z": 6,
      "name": "Rock_Basalt"
    },
    {
      "x": 19,
      "y": 13,
      "z": 6,
      "name": "Rock_Basalt"
    },
    {
      "x": 19,
      "y": 14,
      "z": 6,
      "name": "Rock_Basalt"
    },
    {
      "x": 19,
      "y": 15,
      "z": 6,
      "name": "Rock_Basalt"
    },
    {
      "x": 19,
      "y": 16,
      "z": 6,
      "name": "Rock_Basalt"
    },
    {
      "x": 19,
      "y": 11,
      "z": 7,
      "name": "Rock_Basalt"
    },
    {
      "x": 19,
      "y": 12,
      "z": 7,
      "name": "Rock_Basalt"
    },
    {
      "x": 19,
      "y": 14,
      "z": 14,
      "name": "Rock_Basalt"
    },
    {
      "x": 19,
      "y": 15,
      "z": 14,
      "name": "Rock_Basalt"
    },
    {
      "x": 19,
      "y": 27,
      "z": 14,
      "name": "Soil_Pathway"
    },
    {
      "x": 19,
      "y": 11,
      "z": 15,
      "name": "Rock_Basalt"
    },
    {
      "x": 19,
      "y": 12,
      "z": 15,
      "name": "Rock_Basalt"
    },
    {
      "x": 19,
      "y": 13,
      "z": 15,
      "name": "Rock_Basalt"
    },
    {
      "x": 19,
      "y": 14,
      "z": 15,
      "name": "Rock_Basalt"
    },
    {
      "x": 19,
      "y": 15,
      "z": 15,
      "name": "Rock_Basalt"
    },
    {
      "x": 19,
      "y": 16,
      "z": 15,
      "name": "Rock_Basalt"
    },
    {
      "x": 19,
      "y": 17,
      "z": 15,
      "name": "Rock_Basalt"
    },
    {
      "x": 19,
      "y": 22,
      "z": 15,
      "name": "Rock_Basalt"
    },
    {
      "x": 19,
      "y": 23,
      "z": 15,
      "name": "Rock_Basalt"
    },
    {
      "x": 19,
      "y": 24,
      "z": 15,
      "name": "Soil_Dirt"
    },
    {
      "x": 19,
      "y": 25,
      "z": 15,
      "name": "Soil_Dirt"
    },
    {
      "x": 19,
      "y": 26,
      "z": 15,
      "name": "Soil_Dirt"
    },
    {
      "x": 19,
      "y": 27,
      "z": 15,
      "name": "Soil_Dirt"
    },
    {
      "x": 19,
      "y": 28,
      "z": 15,
      "name": "Soil_Snow"
    },
    {
      "x": 19,
      "y": 9,
      "z": 16,
      "name": "Rock_Basalt"
    },
    {
      "x": 19,
      "y": 10,
      "z": 16,
      "name": "Rock_Basalt"
    },
    {
      "x": 19,
      "y": 11,
      "z": 16,
      "name": "Rock_Basalt"
    },
    {
      "x": 19,
      "y": 12,
      "z": 16,
      "name": "Rock_Basalt"
    },
    {
      "x": 19,
      "y": 13,
      "z": 16,
      "name": "Rock_Basalt"
    },
    {
      "x": 19,
      "y": 14,
      "z": 16,
      "name": "Rock_Basalt"
    },
    {
      "x": 19,
      "y": 15,
      "z": 16,
      "name": "Rock_Basalt"
    },
    {
      "x": 19,
      "y": 16,
      "z": 16,
      "name": "Rock_Basalt"
    },
    {
      "x": 19,
      "y": 17,
      "z": 16,
      "name": "Rock_Basalt"
    },
    {
      "x": 19,
      "y": 18,
      "z": 16,
      "name": "Rock_Basalt"
    },
    {
      "x": 19,
      "y": 19,
      "z": 16,
      "name": "Rock_Basalt"
    },
    {
      "x": 19,
      "y": 20,
      "z": 16,
      "name": "Rock_Basalt"
    },
    {
      "x": 19,
      "y": 21,
      "z": 16,
      "name": "Rock_Basalt"
    },
    {
      "x": 19,
      "y": 22,
      "z": 16,
      "name": "Rock_Basalt"
    },
    {
      "x": 19,
      "y": 23,
      "z": 16,
      "name": "Soil_Dirt"
    },
    {
      "x": 19,
      "y": 24,
      "z": 16,
      "name": "Soil_Dirt"
    },
    {
      "x": 19,
      "y": 25,
      "z": 16,
      "name": "Soil_Dirt"
    },
    {
      "x": 19,
      "y": 26,
      "z": 16,
      "name": "Soil_Dirt"
    },
    {
      "x": 19,
      "y": 27,
      "z": 16,
      "name": "Soil_Dirt"
    },
    {
      "x": 19,
      "y": 28,
      "z": 16,
      "name": "Soil_Dirt"
    },
    {
      "x": 19,
      "y": 29,
      "z": 16,
      "name": "Soil_Snow"
    },
    {
      "x": 19,
      "y": 9,
      "z": 17,
      "name": "Rock_Basalt"
    },
    {
      "x": 19,
      "y": 10,
      "z": 17,
      "name": "Rock_Basalt"
    },
    {
      "x": 19,
      "y": 11,
      "z": 17,
      "name": "Rock_Basalt"
    },
    {
      "x": 19,
      "y": 13,
      "z": 17,
      "name": "Rock_Basalt"
    },
    {
      "x": 19,
      "y": 14,
      "z": 17,
      "name": "Rock_Basalt"
    },
    {
      "x": 19,
      "y": 15,
      "z": 17,
      "name": "Rock_Basalt"
    },
    {
      "x": 19,
      "y": 16,
      "z": 17,
      "name": "Rock_Basalt"
    },
    {
      "x": 19,
      "y": 20,
      "z": 17,
      "name": "Rock_Basalt"
    },
    {
      "x": 19,
      "y": 21,
      "z": 17,
      "name": "Rock_Basalt"
    },
    {
      "x": 19,
      "y": 22,
      "z": 17,
      "name": "Rock_Basalt"
    },
    {
      "x": 19,
      "y": 23,
      "z": 17,
      "name": "Soil_Dirt"
    },
    {
      "x": 19,
      "y": 24,
      "z": 17,
      "name": "Soil_Dirt"
    },
    {
      "x": 19,
      "y": 25,
      "z": 17,
      "name": "Soil_Dirt"
    },
    {
      "x": 19,
      "y": 26,
      "z": 17,
      "name": "Soil_Dirt"
    },
    {
      "x": 19,
      "y": 27,
      "z": 17,
      "name": "Soil_Dirt"
    },
    {
      "x": 19,
      "y": 28,
      "z": 17,
      "name": "Soil_Snow"
    },
    {
      "x": 19,
      "y": 9,
      "z": 18,
      "name": "Rock_Basalt"
    },
    {
      "x": 19,
      "y": 10,
      "z": 18,
      "name": "Rock_Basalt"
    },
    {
      "x": 19,
      "y": 11,
      "z": 18,
      "name": "Rock_Basalt"
    },
    {
      "x": 19,
      "y": 22,
      "z": 18,
      "name": "Rock_Basalt"
    },
    {
      "x": 19,
      "y": 23,
      "z": 18,
      "name": "Soil_Dirt"
    },
    {
      "x": 19,
      "y": 28,
      "z": 18,
      "name": "Soil_Snow"
    },
    {
      "x": 20,
      "y": 15,
      "z": 3,
      "name": "Rock_Basalt"
    },
    {
      "x": 20,
      "y": 16,
      "z": 3,
      "name": "Rock_Basalt"
    },
    {
      "x": 20,
      "y": 13,
      "z": 4,
      "name": "Rock_Basalt"
    },
    {
      "x": 20,
      "y": 14,
      "z": 4,
      "name": "Rock_Basalt"
    },
    {
      "x": 20,
      "y": 15,
      "z": 4,
      "name": "Rock_Basalt"
    },
    {
      "x": 20,
      "y": 16,
      "z": 4,
      "name": "Rock_Basalt"
    },
    {
      "x": 20,
      "y": 17,
      "z": 4,
      "name": "Rock_Basalt"
    },
    {
      "x": 20,
      "y": 11,
      "z": 5,
      "name": "Rock_Basalt"
    },
    {
      "x": 20,
      "y": 12,
      "z": 5,
      "name": "Rock_Basalt"
    },
    {
      "x": 20,
      "y": 13,
      "z": 5,
      "name": "Rock_Basalt"
    },
    {
      "x": 20,
      "y": 14,
      "z": 5,
      "name": "Rock_Basalt"
    },
    {
      "x": 20,
      "y": 15,
      "z": 5,
      "name": "Rock_Basalt"
    },
    {
      "x": 20,
      "y": 16,
      "z": 5,
      "name": "Rock_Basalt"
    },
    {
      "x": 20,
      "y": 17,
      "z": 5,
      "name": "Rock_Basalt"
    },
    {
      "x": 20,
      "y": 18,
      "z": 5,
      "name": "Rock_Basalt"
    },
    {
      "x": 20,
      "y": 9,
      "z": 6,
      "name": "Rock_Basalt"
    },
    {
      "x": 20,
      "y": 10,
      "z": 6,
      "name": "Rock_Basalt"
    },
    {
      "x": 20,
      "y": 11,
      "z": 6,
      "name": "Rock_Basalt"
    },
    {
      "x": 20,
      "y": 12,
      "z": 6,
      "name": "Rock_Basalt"
    },
    {
      "x": 20,
      "y": 13,
      "z": 6,
      "name": "Rock_Basalt"
    },
    {
      "x": 20,
      "y": 14,
      "z": 6,
      "name": "Rock_Basalt"
    },
    {
      "x": 20,
      "y": 15,
      "z": 6,
      "name": "Rock_Basalt"
    },
    {
      "x": 20,
      "y": 16,
      "z": 6,
      "name": "Rock_Basalt"
    },
    {
      "x": 20,
      "y": 17,
      "z": 6,
      "name": "Rock_Basalt"
    },
    {
      "x": 20,
      "y": 18,
      "z": 6,
      "name": "Rock_Basalt"
    },
    {
      "x": 20,
      "y": 9,
      "z": 7,
      "name": "Rock_Basalt"
    },
    {
      "x": 20,
      "y": 10,
      "z": 7,
      "name": "Rock_Basalt"
    },
    {
      "x": 20,
      "y": 11,
      "z": 7,
      "name": "Rock_Basalt"
    },
    {
      "x": 20,
      "y": 12,
      "z": 7,
      "name": "Rock_Basalt"
    },
    {
      "x": 20,
      "y": 13,
      "z": 7,
      "name": "Rock_Basalt"
    },
    {
      "x": 20,
      "y": 14,
      "z": 7,
      "name": "Rock_Basalt"
    },
    {
      "x": 20,
      "y": 15,
      "z": 7,
      "name": "Rock_Basalt"
    },
    {
      "x": 20,
      "y": 16,
      "z": 7,
      "name": "Rock_Basalt"
    },
    {
      "x": 20,
      "y": 9,
      "z": 8,
      "name": "Rock_Basalt"
    },
    {
      "x": 20,
      "y": 10,
      "z": 8,
      "name": "Rock_Basalt"
    },
    {
      "x": 20,
      "y": 11,
      "z": 8,
      "name": "Rock_Basalt"
    },
    {
      "x": 20,
      "y": 12,
      "z": 8,
      "name": "Rock_Basalt"
    },
    {
      "x": 20,
      "y": 13,
      "z": 8,
      "name": "Rock_Basalt"
    },
    {
      "x": 20,
      "y": 10,
      "z": 9,
      "name": "Rock_Basalt"
    },
    {
      "x": 20,
      "y": 11,
      "z": 9,
      "name": "Rock_Basalt"
    },
    {
      "x": 20,
      "y": 10,
      "z": 15,
      "name": "Rock_Basalt"
    },
    {
      "x": 20,
      "y": 11,
      "z": 15,
      "name": "Rock_Basalt"
    },
    {
      "x": 20,
      "y": 23,
      "z": 15,
      "name": "Rock_Basalt"
    },
    {
      "x": 20,
      "y": 24,
      "z": 15,
      "name": "Rock_Basalt"
    },
    {
      "x": 20,
      "y": 25,
      "z": 15,
      "name": "Soil_Dirt"
    },
    {
      "x": 20,
      "y": 26,
      "z": 15,
      "name": "Soil_Pathway"
    },
    {
      "x": 20,
      "y": 27,
      "z": 15,
      "name": "Soil_Pathway"
    },
    {
      "x": 20,
      "y": 28,
      "z": 15,
      "name": "Soil_Pathway"
    },
    {
      "x": 20,
      "y": 29,
      "z": 15,
      "name": "Soil_Snow"
    },
    {
      "x": 20,
      "y": 9,
      "z": 16,
      "name": "Rock_Basalt"
    },
    {
      "x": 20,
      "y": 10,
      "z": 16,
      "name": "Rock_Basalt"
    },
    {
      "x": 20,
      "y": 11,
      "z": 16,
      "name": "Rock_Basalt"
    },
    {
      "x": 20,
      "y": 12,
      "z": 16,
      "name": "Rock_Basalt"
    },
    {
      "x": 20,
      "y": 22,
      "z": 16,
      "name": "Rock_Basalt"
    },
    {
      "x": 20,
      "y": 23,
      "z": 16,
      "name": "Rock_Basalt"
    },
    {
      "x": 20,
      "y": 24,
      "z": 16,
      "name": "Rock_Basalt"
    },
    {
      "x": 20,
      "y": 25,
      "z": 16,
      "name": "Soil_Dirt"
    },
    {
      "x": 20,
      "y": 26,
      "z": 16,
      "name": "Soil_Dirt"
    },
    {
      "x": 20,
      "y": 27,
      "z": 16,
      "name": "Soil_Dirt"
    },
    {
      "x": 20,
      "y": 28,
      "z": 16,
      "name": "Soil_Dirt"
    },
    {
      "x": 20,
      "y": 29,
      "z": 16,
      "name": "Soil_Snow"
    },
    {
      "x": 20,
      "y": 8,
      "z": 17,
      "name": "Rock_Basalt"
    },
    {
      "x": 20,
      "y": 9,
      "z": 17,
      "name": "Rock_Basalt"
    },
    {
      "x": 20,
      "y": 10,
      "z": 17,
      "name": "Rock_Basalt"
    },
    {
      "x": 20,
      "y": 23,
      "z": 17,
      "name": "Rock_Basalt"
    },
    {
      "x": 20,
      "y": 24,
      "z": 17,
      "name": "Soil_Dirt"
    },
    {
      "x": 20,
      "y": 25,
      "z": 17,
      "name": "Soil_Dirt"
    },
    {
      "x": 20,
      "y": 26,
      "z": 17,
      "name": "Soil_Dirt"
    },
    {
      "x": 20,
      "y": 27,
      "z": 17,
      "name": "Soil_Dirt"
    },
    {
      "x": 20,
      "y": 28,
      "z": 17,
      "name": "Soil_Dirt"
    },
    {
      "x": 20,
      "y": 29,
      "z": 17,
      "name": "Soil_Snow"
    },
    {
      "x": 20,
      "y": 8,
      "z": 18,
      "name": "Rock_Basalt"
    },
    {
      "x": 20,
      "y": 9,
      "z": 18,
      "name": "Rock_Basalt"
    },
    {
      "x": 20,
      "y": 24,
      "z": 18,
      "name": "Rock_Basalt"
    },
    {
      "x": 20,
      "y": 25,
      "z": 18,
      "name": "Soil_Dirt"
    },
    {
      "x": 20,
      "y": 26,
      "z": 18,
      "name": "Soil_Dirt"
    },
    {
      "x": 20,
      "y": 27,
      "z": 18,
      "name": "Soil_Dirt"
    },
    {
      "x": 20,
      "y": 28,
      "z": 18,
      "name": "Soil_Dirt"
    },
    {
      "x": 20,
      "y": 29,
      "z": 18,
      "name": "Soil_Snow"
    },
    {
      "x": 20,
      "y": 8,
      "z": 19,
      "name": "Rock_Basalt"
    },
    {
      "x": 20,
      "y": 27,
      "z": 19,
      "name": "Soil_Snow"
    },
    {
      "x": 20,
      "y": 28,
      "z": 19,
      "name": "Soil_Snow"
    },
    {
      "x": 21,
      "y": 12,
      "z": 4,
      "name": "Rock_Basalt"
    },
    {
      "x": 21,
      "y": 13,
      "z": 4,
      "name": "Rock_Basalt"
    },
    {
      "x": 21,
      "y": 14,
      "z": 4,
      "name": "Rock_Basalt"
    },
    {
      "x": 21,
      "y": 15,
      "z": 4,
      "name": "Rock_Basalt"
    },
    {
      "x": 21,
      "y": 16,
      "z": 4,
      "name": "Rock_Basalt"
    },
    {
      "x": 21,
      "y": 17,
      "z": 4,
      "name": "Rock_Basalt"
    },
    {
      "x": 21,
      "y": 18,
      "z": 4,
      "name": "Rock_Basalt"
    },
    {
      "x": 21,
      "y": 10,
      "z": 5,
      "name": "Rock_Basalt"
    },
    {
      "x": 21,
      "y": 11,
      "z": 5,
      "name": "Rock_Basalt"
    },
    {
      "x": 21,
      "y": 12,
      "z": 5,
      "name": "Rock_Basalt"
    },
    {
      "x": 21,
      "y": 13,
      "z": 5,
      "name": "Rock_Basalt"
    },
    {
      "x": 21,
      "y": 14,
      "z": 5,
      "name": "Rock_Basalt"
    },
    {
      "x": 21,
      "y": 15,
      "z": 5,
      "name": "Rock_Basalt"
    },
    {
      "x": 21,
      "y": 16,
      "z": 5,
      "name": "Rock_Basalt"
    },
    {
      "x": 21,
      "y": 17,
      "z": 5,
      "name": "Rock_Basalt"
    },
    {
      "x": 21,
      "y": 18,
      "z": 5,
      "name": "Rock_Basalt"
    },
    {
      "x": 21,
      "y": 19,
      "z": 5,
      "name": "Rock_Basalt"
    },
    {
      "x": 21,
      "y": 9,
      "z": 6,
      "name": "Rock_Basalt"
    },
    {
      "x": 21,
      "y": 10,
      "z": 6,
      "name": "Rock_Basalt"
    },
    {
      "x": 21,
      "y": 11,
      "z": 6,
      "name": "Rock_Basalt"
    },
    {
      "x": 21,
      "y": 12,
      "z": 6,
      "name": "Rock_Basalt"
    },
    {
      "x": 21,
      "y": 13,
      "z": 6,
      "name": "Rock_Basalt"
    },
    {
      "x": 21,
      "y": 14,
      "z": 6,
      "name": "Rock_Basalt"
    },
    {
      "x": 21,
      "y": 15,
      "z": 6,
      "name": "Rock_Basalt"
    },
    {
      "x": 21,
      "y": 16,
      "z": 6,
      "name": "Rock_Basalt"
    },
    {
      "x": 21,
      "y": 17,
      "z": 6,
      "name": "Rock_Basalt"
    },
    {
      "x": 21,
      "y": 18,
      "z": 6,
      "name": "Rock_Basalt"
    },
    {
      "x": 21,
      "y": 19,
      "z": 6,
      "name": "Rock_Basalt"
    },
    {
      "x": 21,
      "y": 8,
      "z": 7,
      "name": "Rock_Basalt"
    },
    {
      "x": 21,
      "y": 9,
      "z": 7,
      "name": "Rock_Basalt"
    },
    {
      "x": 21,
      "y": 10,
      "z": 7,
      "name": "Rock_Basalt"
    },
    {
      "x": 21,
      "y": 11,
      "z": 7,
      "name": "Rock_Basalt"
    },
    {
      "x": 21,
      "y": 12,
      "z": 7,
      "name": "Rock_Basalt"
    },
    {
      "x": 21,
      "y": 13,
      "z": 7,
      "name": "Rock_Basalt"
    },
    {
      "x": 21,
      "y": 14,
      "z": 7,
      "name": "Rock_Basalt"
    },
    {
      "x": 21,
      "y": 15,
      "z": 7,
      "name": "Rock_Basalt"
    },
    {
      "x": 21,
      "y": 16,
      "z": 7,
      "name": "Rock_Basalt"
    },
    {
      "x": 21,
      "y": 17,
      "z": 7,
      "name": "Rock_Basalt"
    },
    {
      "x": 21,
      "y": 18,
      "z": 7,
      "name": "Rock_Basalt"
    },
    {
      "x": 21,
      "y": 8,
      "z": 8,
      "name": "Rock_Basalt"
    },
    {
      "x": 21,
      "y": 9,
      "z": 8,
      "name": "Rock_Basalt"
    },
    {
      "x": 21,
      "y": 10,
      "z": 8,
      "name": "Rock_Basalt"
    },
    {
      "x": 21,
      "y": 11,
      "z": 8,
      "name": "Rock_Basalt"
    },
    {
      "x": 21,
      "y": 12,
      "z": 8,
      "name": "Rock_Basalt"
    },
    {
      "x": 21,
      "y": 13,
      "z": 8,
      "name": "Rock_Basalt"
    },
    {
      "x": 21,
      "y": 14,
      "z": 8,
      "name": "Rock_Basalt"
    },
    {
      "x": 21,
      "y": 8,
      "z": 9,
      "name": "Rock_Basalt"
    },
    {
      "x": 21,
      "y": 9,
      "z": 9,
      "name": "Rock_Basalt"
    },
    {
      "x": 21,
      "y": 10,
      "z": 9,
      "name": "Rock_Basalt"
    },
    {
      "x": 21,
      "y": 11,
      "z": 9,
      "name": "Rock_Basalt"
    },
    {
      "x": 21,
      "y": 12,
      "z": 9,
      "name": "Rock_Basalt"
    },
    {
      "x": 21,
      "y": 8,
      "z": 10,
      "name": "Rock_Basalt"
    },
    {
      "x": 21,
      "y": 9,
      "z": 10,
      "name": "Rock_Basalt"
    },
    {
      "x": 21,
      "y": 10,
      "z": 10,
      "name": "Rock_Basalt"
    },
    {
      "x": 21,
      "y": 11,
      "z": 10,
      "name": "Rock_Basalt"
    },
    {
      "x": 21,
      "y": 25,
      "z": 14,
      "name": "Soil_Pathway"
    },
    {
      "x": 21,
      "y": 26,
      "z": 14,
      "name": "Soil_Pathway"
    },
    {
      "x": 21,
      "y": 27,
      "z": 14,
      "name": "Soil_Pathway"
    },
    {
      "x": 21,
      "y": 28,
      "z": 14,
      "name": "Soil_Pathway"
    },
    {
      "x": 21,
      "y": 24,
      "z": 15,
      "name": "Rock_Basalt"
    },
    {
      "x": 21,
      "y": 25,
      "z": 15,
      "name": "Soil_Dirt"
    },
    {
      "x": 21,
      "y": 26,
      "z": 15,
      "name": "Soil_Pathway"
    },
    {
      "x": 21,
      "y": 27,
      "z": 15,
      "name": "Soil_Pathway"
    },
    {
      "x": 21,
      "y": 28,
      "z": 15,
      "name": "Soil_Pathway"
    },
    {
      "x": 21,
      "y": 29,
      "z": 15,
      "name": "Soil_Snow"
    },
    {
      "x": 21,
      "y": 9,
      "z": 16,
      "name": "Rock_Basalt"
    },
    {
      "x": 21,
      "y": 24,
      "z": 16,
      "name": "Rock_Basalt"
    },
    {
      "x": 21,
      "y": 25,
      "z": 16,
      "name": "Soil_Dirt"
    },
    {
      "x": 21,
      "y": 26,
      "z": 16,
      "name": "Soil_Dirt"
    },
    {
      "x": 21,
      "y": 27,
      "z": 16,
      "name": "Soil_Pathway"
    },
    {
      "x": 21,
      "y": 28,
      "z": 16,
      "name": "Soil_Dirt"
    },
    {
      "x": 21,
      "y": 29,
      "z": 16,
      "name": "Soil_Snow"
    },
    {
      "x": 21,
      "y": 8,
      "z": 17,
      "name": "Rock_Basalt"
    },
    {
      "x": 21,
      "y": 9,
      "z": 17,
      "name": "Rock_Basalt"
    },
    {
      "x": 21,
      "y": 25,
      "z": 17,
      "name": "Soil_Dirt"
    },
    {
      "x": 21,
      "y": 26,
      "z": 17,
      "name": "Soil_Dirt"
    },
    {
      "x": 21,
      "y": 27,
      "z": 17,
      "name": "Soil_Dirt"
    },
    {
      "x": 21,
      "y": 28,
      "z": 17,
      "name": "Soil_Dirt"
    },
    {
      "x": 21,
      "y": 29,
      "z": 17,
      "name": "Soil_Dirt"
    },
    {
      "x": 21,
      "y": 30,
      "z": 17,
      "name": "Soil_Snow"
    },
    {
      "x": 21,
      "y": 8,
      "z": 18,
      "name": "Rock_Basalt"
    },
    {
      "x": 21,
      "y": 25,
      "z": 18,
      "name": "Soil_Dirt"
    },
    {
      "x": 21,
      "y": 26,
      "z": 18,
      "name": "Soil_Dirt"
    },
    {
      "x": 21,
      "y": 27,
      "z": 18,
      "name": "Soil_Dirt"
    },
    {
      "x": 21,
      "y": 28,
      "z": 18,
      "name": "Soil_Dirt"
    },
    {
      "x": 21,
      "y": 29,
      "z": 18,
      "name": "Soil_Snow"
    },
    {
      "x": 21,
      "y": 8,
      "z": 19,
      "name": "Rock_Basalt"
    },
    {
      "x": 21,
      "y": 28,
      "z": 19,
      "name": "Soil_Snow"
    },
    {
      "x": 21,
      "y": 29,
      "z": 19,
      "name": "Soil_Snow"
    },
    {
      "x": 22,
      "y": 14,
      "z": 4,
      "name": "Rock_Basalt"
    },
    {
      "x": 22,
      "y": 15,
      "z": 4,
      "name": "Rock_Basalt"
    },
    {
      "x": 22,
      "y": 11,
      "z": 5,
      "name": "Rock_Basalt"
    },
    {
      "x": 22,
      "y": 12,
      "z": 5,
      "name": "Rock_Basalt"
    },
    {
      "x": 22,
      "y": 13,
      "z": 5,
      "name": "Rock_Basalt"
    },
    {
      "x": 22,
      "y": 14,
      "z": 5,
      "name": "Rock_Basalt"
    },
    {
      "x": 22,
      "y": 15,
      "z": 5,
      "name": "Rock_Basalt"
    },
    {
      "x": 22,
      "y": 16,
      "z": 5,
      "name": "Rock_Basalt"
    },
    {
      "x": 22,
      "y": 18,
      "z": 5,
      "name": "Rock_Basalt"
    },
    {
      "x": 22,
      "y": 19,
      "z": 5,
      "name": "Rock_Basalt"
    },
    {
      "x": 22,
      "y": 9,
      "z": 6,
      "name": "Rock_Basalt"
    },
    {
      "x": 22,
      "y": 10,
      "z": 6,
      "name": "Rock_Basalt"
    },
    {
      "x": 22,
      "y": 11,
      "z": 6,
      "name": "Rock_Basalt"
    },
    {
      "x": 22,
      "y": 12,
      "z": 6,
      "name": "Rock_Basalt"
    },
    {
      "x": 22,
      "y": 13,
      "z": 6,
      "name": "Rock_Basalt"
    },
    {
      "x": 22,
      "y": 14,
      "z": 6,
      "name": "Rock_Basalt"
    },
    {
      "x": 22,
      "y": 15,
      "z": 6,
      "name": "Rock_Basalt"
    },
    {
      "x": 22,
      "y": 16,
      "z": 6,
      "name": "Rock_Basalt"
    },
    {
      "x": 22,
      "y": 17,
      "z": 6,
      "name": "Rock_Basalt"
    },
    {
      "x": 22,
      "y": 18,
      "z": 6,
      "name": "Rock_Basalt"
    },
    {
      "x": 22,
      "y": 19,
      "z": 6,
      "name": "Rock_Basalt"
    },
    {
      "x": 22,
      "y": 20,
      "z": 6,
      "name": "Rock_Basalt"
    },
    {
      "x": 22,
      "y": 8,
      "z": 7,
      "name": "Rock_Basalt"
    },
    {
      "x": 22,
      "y": 9,
      "z": 7,
      "name": "Rock_Basalt"
    },
    {
      "x": 22,
      "y": 10,
      "z": 7,
      "name": "Rock_Basalt"
    },
    {
      "x": 22,
      "y": 11,
      "z": 7,
      "name": "Rock_Basalt"
    },
    {
      "x": 22,
      "y": 12,
      "z": 7,
      "name": "Rock_Basalt"
    },
    {
      "x": 22,
      "y": 13,
      "z": 7,
      "name": "Rock_Basalt"
    },
    {
      "x": 22,
      "y": 14,
      "z": 7,
      "name": "Rock_Basalt"
    },
    {
      "x": 22,
      "y": 15,
      "z": 7,
      "name": "Rock_Basalt"
    },
    {
      "x": 22,
      "y": 16,
      "z": 7,
      "name": "Rock_Basalt"
    },
    {
      "x": 22,
      "y": 17,
      "z": 7,
      "name": "Rock_Basalt"
    },
    {
      "x": 22,
      "y": 18,
      "z": 7,
      "name": "Rock_Basalt"
    },
    {
      "x": 22,
      "y": 19,
      "z": 7,
      "name": "Rock_Basalt"
    },
    {
      "x": 22,
      "y": 8,
      "z": 8,
      "name": "Rock_Basalt"
    },
    {
      "x": 22,
      "y": 9,
      "z": 8,
      "name": "Rock_Basalt"
    },
    {
      "x": 22,
      "y": 10,
      "z": 8,
      "name": "Rock_Basalt"
    },
    {
      "x": 22,
      "y": 11,
      "z": 8,
      "name": "Rock_Basalt"
    },
    {
      "x": 22,
      "y": 12,
      "z": 8,
      "name": "Rock_Basalt"
    },
    {
      "x": 22,
      "y": 13,
      "z": 8,
      "name": "Rock_Basalt"
    },
    {
      "x": 22,
      "y": 14,
      "z": 8,
      "name": "Rock_Basalt"
    },
    {
      "x": 22,
      "y": 8,
      "z": 9,
      "name": "Rock_Basalt"
    },
    {
      "x": 22,
      "y": 9,
      "z": 9,
      "name": "Rock_Basalt"
    },
    {
      "x": 22,
      "y": 10,
      "z": 9,
      "name": "Rock_Basalt"
    },
    {
      "x": 22,
      "y": 11,
      "z": 9,
      "name": "Rock_Basalt"
    },
    {
      "x": 22,
      "y": 12,
      "z": 9,
      "name": "Rock_Basalt"
    },
    {
      "x": 22,
      "y": 8,
      "z": 10,
      "name": "Rock_Basalt"
    },
    {
      "x": 22,
      "y": 9,
      "z": 10,
      "name": "Rock_Basalt"
    },
    {
      "x": 22,
      "y": 10,
      "z": 10,
      "name": "Rock_Basalt"
    },
    {
      "x": 22,
      "y": 8,
      "z": 11,
      "name": "Rock_Basalt"
    },
    {
      "x": 22,
      "y": 9,
      "z": 11,
      "name": "Rock_Basalt"
    },
    {
      "x": 22,
      "y": 26,
      "z": 13,
      "name": "Soil_Pathway"
    },
    {
      "x": 22,
      "y": 27,
      "z": 13,
      "name": "Soil_Pathway"
    },
    {
      "x": 22,
      "y": 25,
      "z": 14,
      "name": "Rock_Basalt"
    },
    {
      "x": 22,
      "y": 26,
      "z": 14,
      "name": "Soil_Pathway"
    },
    {
      "x": 22,
      "y": 27,
      "z": 14,
      "name": "Soil_Pathway"
    },
    {
      "x": 22,
      "y": 28,
      "z": 14,
      "name": "Soil_Pathway"
    },
    {
      "x": 22,
      "y": 29,
      "z": 14,
      "name": "Soil_Pathway"
    },
    {
      "x": 22,
      "y": 24,
      "z": 15,
      "name": "Rock_Basalt"
    },
    {
      "x": 22,
      "y": 25,
      "z": 15,
      "name": "Rock_Basalt"
    },
    {
      "x": 22,
      "y": 26,
      "z": 15,
      "name": "Soil_Pathway"
    },
    {
      "x": 22,
      "y": 27,
      "z": 15,
      "name": "Soil_Pathway"
    },
    {
      "x": 22,
      "y": 28,
      "z": 15,
      "name": "Soil_Pathway"
    },
    {
      "x": 22,
      "y": 29,
      "z": 15,
      "name": "Soil_Pathway"
    },
    {
      "x": 22,
      "y": 25,
      "z": 16,
      "name": "Soil_Dirt"
    },
    {
      "x": 22,
      "y": 26,
      "z": 16,
      "name": "Soil_Dirt"
    },
    {
      "x": 22,
      "y": 27,
      "z": 16,
      "name": "Soil_Dirt"
    },
    {
      "x": 22,
      "y": 28,
      "z": 16,
      "name": "Soil_Dirt"
    },
    {
      "x": 22,
      "y": 29,
      "z": 16,
      "name": "Soil_Pathway"
    },
    {
      "x": 22,
      "y": 30,
      "z": 16,
      "name": "Soil_Snow"
    },
    {
      "x": 22,
      "y": 25,
      "z": 17,
      "name": "Soil_Dirt"
    },
    {
      "x": 22,
      "y": 26,
      "z": 17,
      "name": "Soil_Dirt"
    },
    {
      "x": 22,
      "y": 27,
      "z": 17,
      "name": "Soil_Dirt"
    },
    {
      "x": 22,
      "y": 28,
      "z": 17,
      "name": "Soil_Dirt"
    },
    {
      "x": 22,
      "y": 29,
      "z": 17,
      "name": "Soil_Dirt"
    },
    {
      "x": 22,
      "y": 30,
      "z": 17,
      "name": "Soil_Snow"
    },
    {
      "x": 22,
      "y": 7,
      "z": 18,
      "name": "Rock_Basalt"
    },
    {
      "x": 22,
      "y": 8,
      "z": 18,
      "name": "Rock_Basalt"
    },
    {
      "x": 22,
      "y": 26,
      "z": 18,
      "name": "Soil_Dirt"
    },
    {
      "x": 22,
      "y": 27,
      "z": 18,
      "name": "Soil_Dirt"
    },
    {
      "x": 22,
      "y": 28,
      "z": 18,
      "name": "Soil_Dirt"
    },
    {
      "x": 22,
      "y": 29,
      "z": 18,
      "name": "Soil_Dirt"
    },
    {
      "x": 22,
      "y": 30,
      "z": 18,
      "name": "Soil_Snow"
    },
    {
      "x": 22,
      "y": 7,
      "z": 19,
      "name": "Rock_Basalt"
    },
    {
      "x": 22,
      "y": 27,
      "z": 19,
      "name": "Soil_Dirt"
    },
    {
      "x": 22,
      "y": 28,
      "z": 19,
      "name": "Soil_Snow"
    },
    {
      "x": 22,
      "y": 29,
      "z": 19,
      "name": "Soil_Snow"
    },
    {
      "x": 22,
      "y": 7,
      "z": 20,
      "name": "Rock_Basalt"
    },
    {
      "x": 23,
      "y": 14,
      "z": 5,
      "name": "Rock_Basalt"
    },
    {
      "x": 23,
      "y": 15,
      "z": 5,
      "name": "Rock_Basalt"
    },
    {
      "x": 23,
      "y": 10,
      "z": 6,
      "name": "Rock_Basalt"
    },
    {
      "x": 23,
      "y": 11,
      "z": 6,
      "name": "Rock_Basalt"
    },
    {
      "x": 23,
      "y": 12,
      "z": 6,
      "name": "Rock_Basalt"
    },
    {
      "x": 23,
      "y": 13,
      "z": 6,
      "name": "Rock_Basalt"
    },
    {
      "x": 23,
      "y": 14,
      "z": 6,
      "name": "Rock_Basalt"
    },
    {
      "x": 23,
      "y": 15,
      "z": 6,
      "name": "Rock_Basalt"
    },
    {
      "x": 23,
      "y": 16,
      "z": 6,
      "name": "Rock_Basalt"
    },
    {
      "x": 23,
      "y": 19,
      "z": 6,
      "name": "Rock_Basalt"
    },
    {
      "x": 23,
      "y": 20,
      "z": 6,
      "name": "Rock_Basalt"
    },
    {
      "x": 23,
      "y": 10,
      "z": 7,
      "name": "Rock_Basalt"
    },
    {
      "x": 23,
      "y": 11,
      "z": 7,
      "name": "Rock_Basalt"
    },
    {
      "x": 23,
      "y": 12,
      "z": 7,
      "name": "Rock_Basalt"
    },
    {
      "x": 23,
      "y": 13,
      "z": 7,
      "name": "Rock_Basalt"
    },
    {
      "x": 23,
      "y": 18,
      "z": 7,
      "name": "Rock_Basalt"
    },
    {
      "x": 23,
      "y": 19,
      "z": 7,
      "name": "Rock_Basalt"
    },
    {
      "x": 23,
      "y": 20,
      "z": 7,
      "name": "Rock_Basalt"
    },
    {
      "x": 23,
      "y": 21,
      "z": 7,
      "name": "Rock_Basalt"
    },
    {
      "x": 23,
      "y": 8,
      "z": 8,
      "name": "Rock_Basalt"
    },
    {
      "x": 23,
      "y": 9,
      "z": 8,
      "name": "Rock_Basalt"
    },
    {
      "x": 23,
      "y": 10,
      "z": 8,
      "name": "Rock_Basalt"
    },
    {
      "x": 23,
      "y": 11,
      "z": 8,
      "name": "Rock_Basalt"
    },
    {
      "x": 23,
      "y": 12,
      "z": 8,
      "name": "Rock_Basalt"
    },
    {
      "x": 23,
      "y": 13,
      "z": 8,
      "name": "Rock_Basalt"
    },
    {
      "x": 23,
      "y": 21,
      "z": 8,
      "name": "Rock_Basalt"
    },
    {
      "x": 23,
      "y": 7,
      "z": 9,
      "name": "Rock_Basalt"
    },
    {
      "x": 23,
      "y": 8,
      "z": 9,
      "name": "Rock_Basalt"
    },
    {
      "x": 23,
      "y": 9,
      "z": 9,
      "name": "Rock_Basalt"
    },
    {
      "x": 23,
      "y": 10,
      "z": 9,
      "name": "Rock_Basalt"
    },
    {
      "x": 23,
      "y": 11,
      "z": 9,
      "name": "Rock_Basalt"
    },
    {
      "x": 23,
      "y": 7,
      "z": 10,
      "name": "Rock_Basalt"
    },
    {
      "x": 23,
      "y": 8,
      "z": 10,
      "name": "Rock_Basalt"
    },
    {
      "x": 23,
      "y": 9,
      "z": 10,
      "name": "Rock_Basalt"
    },
    {
      "x": 23,
      "y": 10,
      "z": 10,
      "name": "Rock_Basalt"
    },
    {
      "x": 23,
      "y": 8,
      "z": 11,
      "name": "Rock_Basalt"
    },
    {
      "x": 23,
      "y": 9,
      "z": 11,
      "name": "Rock_Basalt"
    },
    {
      "x": 23,
      "y": 10,
      "z": 11,
      "name": "Rock_Basalt"
    },
    {
      "x": 23,
      "y": 8,
      "z": 12,
      "name": "Rock_Basalt"
    },
    {
      "x": 23,
      "y": 9,
      "z": 12,
      "name": "Rock_Basalt"
    },
    {
      "x": 23,
      "y": 10,
      "z": 12,
      "name": "Rock_Basalt"
    },
    {
      "x": 23,
      "y": 26,
      "z": 13,
      "name": "Soil_Dirt"
    },
    {
      "x": 23,
      "y": 27,
      "z": 13,
      "name": "Soil_Dirt"
    },
    {
      "x": 23,
      "y": 28,
      "z": 13,
      "name": "Soil_Pathway"
    },
    {
      "x": 23,
      "y": 25,
      "z": 14,
      "name": "Rock_Basalt"
    },
    {
      "x": 23,
      "y": 26,
      "z": 14,
      "name": "Soil_Dirt"
    },
    {
      "x": 23,
      "y": 27,
      "z": 14,
      "name": "Soil_Pathway"
    },
    {
      "x": 23,
      "y": 28,
      "z": 14,
      "name": "Soil_Pathway"
    },
    {
      "x": 23,
      "y": 29,
      "z": 14,
      "name": "Soil_Pathway"
    },
    {
      "x": 23,
      "y": 24,
      "z": 15,
      "name": "Rock_Basalt"
    },
    {
      "x": 23,
      "y": 25,
      "z": 15,
      "name": "Rock_Basalt"
    },
    {
      "x": 23,
      "y": 26,
      "z": 15,
      "name": "Soil_Dirt"
    },
    {
      "x": 23,
      "y": 27,
      "z": 15,
      "name": "Soil_Dirt"
    },
    {
      "x": 23,
      "y": 28,
      "z": 15,
      "name": "Soil_Pathway"
    },
    {
      "x": 23,
      "y": 29,
      "z": 15,
      "name": "Soil_Pathway"
    },
    {
      "x": 23,
      "y": 30,
      "z": 15,
      "name": "Soil_Pathway"
    },
    {
      "x": 23,
      "y": 31,
      "z": 15,
      "name": "Plant_Fern_Winter"
    },
    {
      "x": 23,
      "y": 25,
      "z": 16,
      "name": "Rock_Basalt"
    },
    {
      "x": 23,
      "y": 26,
      "z": 16,
      "name": "Soil_Dirt"
    },
    {
      "x": 23,
      "y": 27,
      "z": 16,
      "name": "Soil_Dirt"
    },
    {
      "x": 23,
      "y": 28,
      "z": 16,
      "name": "Soil_Dirt"
    },
    {
      "x": 23,
      "y": 29,
      "z": 16,
      "name": "Soil_Dirt"
    },
    {
      "x": 23,
      "y": 30,
      "z": 16,
      "name": "Soil_Grass"
    },
    {
      "x": 23,
      "y": 25,
      "z": 17,
      "name": "Rock_Basalt"
    },
    {
      "x": 23,
      "y": 26,
      "z": 17,
      "name": "Soil_Dirt"
    },
    {
      "x": 23,
      "y": 27,
      "z": 17,
      "name": "Soil_Dirt"
    },
    {
      "x": 23,
      "y": 28,
      "z": 17,
      "name": "Soil_Dirt"
    },
    {
      "x": 23,
      "y": 29,
      "z": 17,
      "name": "Soil_Dirt"
    },
    {
      "x": 23,
      "y": 30,
      "z": 17,
      "name": "Soil_Grass"
    },
    {
      "x": 23,
      "y": 26,
      "z": 18,
      "name": "Soil_Dirt"
    },
    {
      "x": 23,
      "y": 27,
      "z": 18,
      "name": "Soil_Dirt"
    },
    {
      "x": 23,
      "y": 28,
      "z": 18,
      "name": "Soil_Dirt"
    },
    {
      "x": 23,
      "y": 29,
      "z": 18,
      "name": "Soil_Dirt"
    },
    {
      "x": 23,
      "y": 7,
      "z": 19,
      "name": "Rock_Basalt"
    },
    {
      "x": 23,
      "y": 26,
      "z": 19,
      "name": "Rock_Basalt"
    },
    {
      "x": 23,
      "y": 27,
      "z": 19,
      "name": "Soil_Dirt"
    },
    {
      "x": 23,
      "y": 28,
      "z": 19,
      "name": "Soil_Dirt"
    },
    {
      "x": 23,
      "y": 7,
      "z": 20,
      "name": "Rock_Basalt"
    },
    {
      "x": 23,
      "y": 43,
      "z": 20,
      "name": "Plant_Leaves_Cedar",
      "support": 15
    },
    {
      "x": 24,
      "y": 11,
      "z": 7,
      "name": "Rock_Basalt"
    },
    {
      "x": 24,
      "y": 12,
      "z": 7,
      "name": "Rock_Basalt"
    },
    {
      "x": 24,
      "y": 9,
      "z": 8,
      "name": "Rock_Basalt"
    },
    {
      "x": 24,
      "y": 10,
      "z": 8,
      "name": "Rock_Basalt"
    },
    {
      "x": 24,
      "y": 11,
      "z": 8,
      "name": "Rock_Basalt"
    },
    {
      "x": 24,
      "y": 20,
      "z": 8,
      "name": "Rock_Basalt"
    },
    {
      "x": 24,
      "y": 21,
      "z": 8,
      "name": "Rock_Basalt"
    },
    {
      "x": 24,
      "y": 22,
      "z": 8,
      "name": "Rock_Basalt"
    },
    {
      "x": 24,
      "y": 7,
      "z": 9,
      "name": "Rock_Basalt"
    },
    {
      "x": 24,
      "y": 8,
      "z": 9,
      "name": "Rock_Basalt"
    },
    {
      "x": 24,
      "y": 9,
      "z": 9,
      "name": "Rock_Basalt"
    },
    {
      "x": 24,
      "y": 10,
      "z": 9,
      "name": "Rock_Basalt"
    },
    {
      "x": 24,
      "y": 22,
      "z": 9,
      "name": "Rock_Basalt"
    },
    {
      "x": 24,
      "y": 23,
      "z": 9,
      "name": "Rock_Basalt"
    },
    {
      "x": 24,
      "y": 7,
      "z": 10,
      "name": "Rock_Basalt"
    },
    {
      "x": 24,
      "y": 8,
      "z": 10,
      "name": "Rock_Basalt"
    },
    {
      "x": 24,
      "y": 9,
      "z": 10,
      "name": "Rock_Basalt"
    },
    {
      "x": 24,
      "y": 10,
      "z": 10,
      "name": "Rock_Basalt"
    },
    {
      "x": 24,
      "y": 7,
      "z": 11,
      "name": "Rock_Basalt"
    },
    {
      "x": 24,
      "y": 8,
      "z": 11,
      "name": "Rock_Basalt"
    },
    {
      "x": 24,
      "y": 9,
      "z": 11,
      "name": "Rock_Basalt"
    },
    {
      "x": 24,
      "y": 10,
      "z": 11,
      "name": "Rock_Basalt"
    },
    {
      "x": 24,
      "y": 7,
      "z": 12,
      "name": "Rock_Basalt"
    },
    {
      "x": 24,
      "y": 8,
      "z": 12,
      "name": "Rock_Basalt"
    },
    {
      "x": 24,
      "y": 9,
      "z": 12,
      "name": "Rock_Basalt"
    },
    {
      "x": 24,
      "y": 10,
      "z": 12,
      "name": "Rock_Basalt"
    },
    {
      "x": 24,
      "y": 27,
      "z": 12,
      "name": "Soil_Dirt"
    },
    {
      "x": 24,
      "y": 28,
      "z": 12,
      "name": "Soil_Dirt"
    },
    {
      "x": 24,
      "y": 8,
      "z": 13,
      "name": "Rock_Basalt"
    },
    {
      "x": 24,
      "y": 9,
      "z": 13,
      "name": "Rock_Basalt"
    },
    {
      "x": 24,
      "y": 25,
      "z": 13,
      "name": "Rock_Basalt"
    },
    {
      "x": 24,
      "y": 26,
      "z": 13,
      "name": "Soil_Dirt"
    },
    {
      "x": 24,
      "y": 27,
      "z": 13,
      "name": "Soil_Dirt"
    },
    {
      "x": 24,
      "y": 28,
      "z": 13,
      "name": "Soil_Dirt"
    },
    {
      "x": 24,
      "y": 29,
      "z": 13,
      "name": "Plant_Fern_Winter"
    },
    {
      "x": 24,
      "y": 25,
      "z": 14,
      "name": "Rock_Basalt"
    },
    {
      "x": 24,
      "y": 26,
      "z": 14,
      "name": "Soil_Dirt"
    },
    {
      "x": 24,
      "y": 27,
      "z": 14,
      "name": "Soil_Dirt"
    },
    {
      "x": 24,
      "y": 28,
      "z": 14,
      "name": "Soil_Dirt"
    },
    {
      "x": 24,
      "y": 29,
      "z": 14,
      "name": "Soil_Grass"
    },
    {
      "x": 24,
      "y": 30,
      "z": 14,
      "name": "Plant_Grass_Sharp_Tall"
    },
    {
      "x": 24,
      "y": 31,
      "z": 14,
      "name": "Plant_Grass_Sharp_Tall",
      "filler": 1024
    },
    {
      "x": 24,
      "y": 24,
      "z": 15,
      "name": "Rock_Basalt"
    },
    {
      "x": 24,
      "y": 25,
      "z": 15,
      "name": "Rock_Basalt"
    },
    {
      "x": 24,
      "y": 26,
      "z": 15,
      "name": "Soil_Dirt"
    },
    {
      "x": 24,
      "y": 27,
      "z": 15,
      "name": "Soil_Dirt"
    },
    {
      "x": 24,
      "y": 28,
      "z": 15,
      "name": "Soil_Dirt"
    },
    {
      "x": 24,
      "y": 29,
      "z": 15,
      "name": "Soil_Dirt"
    },
    {
      "x": 24,
      "y": 30,
      "z": 15,
      "name": "Soil_Dirt"
    },
    {
      "x": 24,
      "y": 24,
      "z": 16,
      "name": "Rock_Basalt"
    },
    {
      "x": 24,
      "y": 25,
      "z": 16,
      "name": "Rock_Basalt"
    },
    {
      "x": 24,
      "y": 26,
      "z": 16,
      "name": "Soil_Dirt"
    },
    {
      "x": 24,
      "y": 27,
      "z": 16,
      "name": "Soil_Dirt"
    },
    {
      "x": 24,
      "y": 28,
      "z": 16,
      "name": "Soil_Dirt"
    },
    {
      "x": 24,
      "y": 29,
      "z": 16,
      "name": "Soil_Dirt"
    },
    {
      "x": 24,
      "y": 30,
      "z": 16,
      "name": "Soil_Grass"
    },
    {
      "x": 24,
      "y": 31,
      "z": 16,
      "name": "Plant_Fern_Winter"
    },
    {
      "x": 24,
      "y": 44,
      "z": 16,
      "name": "Plant_Leaves_Cedar",
      "support": 15
    },
    {
      "x": 24,
      "y": 25,
      "z": 17,
      "name": "Rock_Basalt"
    },
    {
      "x": 24,
      "y": 26,
      "z": 17,
      "name": "Soil_Dirt"
    },
    {
      "x": 24,
      "y": 27,
      "z": 17,
      "name": "Soil_Dirt"
    },
    {
      "x": 24,
      "y": 28,
      "z": 17,
      "name": "Soil_Dirt"
    },
    {
      "x": 24,
      "y": 29,
      "z": 17,
      "name": "Soil_Dirt"
    },
    {
      "x": 24,
      "y": 30,
      "z": 17,
      "name": "Soil_Grass"
    },
    {
      "x": 24,
      "y": 45,
      "z": 17,
      "name": "Plant_Leaves_Cedar",
      "support": 15
    },
    {
      "x": 24,
      "y": 26,
      "z": 18,
      "name": "Rock_Basalt"
    },
    {
      "x": 24,
      "y": 27,
      "z": 18,
      "name": "Soil_Dirt"
    },
    {
      "x": 24,
      "y": 28,
      "z": 18,
      "name": "Soil_Dirt"
    },
    {
      "x": 24,
      "y": 29,
      "z": 18,
      "name": "Soil_Dirt"
    },
    {
      "x": 24,
      "y": 30,
      "z": 18,
      "name": "Soil_Grass"
    },
    {
      "x": 24,
      "y": 46,
      "z": 18,
      "name": "Plant_Leaves_Cedar",
      "support": 15
    },
    {
      "x": 24,
      "y": 26,
      "z": 19,
      "name": "Rock_Basalt"
    },
    {
      "x": 24,
      "y": 27,
      "z": 19,
      "name": "Soil_Dirt"
    },
    {
      "x": 24,
      "y": 28,
      "z": 19,
      "name": "Soil_Dirt"
    },
    {
      "x": 24,
      "y": 29,
      "z": 19,
      "name": "Soil_Dirt"
    },
    {
      "x": 24,
      "y": 43,
      "z": 19,
      "name": "Plant_Leaves_Cedar",
      "support": 15
    },
    {
      "x": 24,
      "y": 44,
      "z": 19,
      "name": "Plant_Leaves_Cedar",
      "support": 15
    },
    {
      "x": 24,
      "y": 43,
      "z": 20,
      "name": "Plant_Leaves_Cedar",
      "support": 15
    },
    {
      "x": 24,
      "y": 44,
      "z": 20,
      "name": "Plant_Leaves_Cedar",
      "support": 15
    },
    {
      "x": 24,
      "y": 44,
      "z": 21,
      "name": "Plant_Leaves_Cedar",
      "support": 15
    },
    {
      "x": 25,
      "y": 10,
      "z": 9,
      "name": "Rock_Basalt"
    },
    {
      "x": 25,
      "y": 8,
      "z": 10,
      "name": "Rock_Basalt"
    },
    {
      "x": 25,
      "y": 9,
      "z": 10,
      "name": "Rock_Basalt"
    },
    {
      "x": 25,
      "y": 10,
      "z": 10,
      "name": "Rock_Basalt"
    },
    {
      "x": 25,
      "y": 7,
      "z": 11,
      "name": "Rock_Basalt"
    },
    {
      "x": 25,
      "y": 8,
      "z": 11,
      "name": "Rock_Basalt"
    },
    {
      "x": 25,
      "y": 9,
      "z": 11,
      "name": "Rock_Basalt"
    },
    {
      "x": 25,
      "y": 10,
      "z": 11,
      "name": "Rock_Basalt"
    },
    {
      "x": 25,
      "y": 7,
      "z": 12,
      "name": "Rock_Basalt"
    },
    {
      "x": 25,
      "y": 8,
      "z": 12,
      "name": "Rock_Basalt"
    },
    {
      "x": 25,
      "y": 9,
      "z": 12,
      "name": "Rock_Basalt"
    },
    {
      "x": 25,
      "y": 10,
      "z": 12,
      "name": "Rock_Basalt"
    },
    {
      "x": 25,
      "y": 26,
      "z": 12,
      "name": "Soil_Dirt"
    },
    {
      "x": 25,
      "y": 27,
      "z": 12,
      "name": "Soil_Dirt"
    },
    {
      "x": 25,
      "y": 28,
      "z": 12,
      "name": "Soil_Grass"
    },
    {
      "x": 25,
      "y": 8,
      "z": 13,
      "name": "Rock_Basalt"
    },
    {
      "x": 25,
      "y": 9,
      "z": 13,
      "name": "Rock_Basalt"
    },
    {
      "x": 25,
      "y": 10,
      "z": 13,
      "name": "Rock_Basalt"
    },
    {
      "x": 25,
      "y": 25,
      "z": 13,
      "name": "Rock_Basalt"
    },
    {
      "x": 25,
      "y": 26,
      "z": 13,
      "name": "Soil_Dirt"
    },
    {
      "x": 25,
      "y": 27,
      "z": 13,
      "name": "Soil_Dirt"
    },
    {
      "x": 25,
      "y": 28,
      "z": 13,
      "name": "Soil_Dirt"
    },
    {
      "x": 25,
      "y": 24,
      "z": 14,
      "name": "Rock_Basalt"
    },
    {
      "x": 25,
      "y": 25,
      "z": 14,
      "name": "Soil_Dirt"
    },
    {
      "x": 25,
      "y": 26,
      "z": 14,
      "name": "Soil_Dirt"
    },
    {
      "x": 25,
      "y": 27,
      "z": 14,
      "name": "Soil_Dirt"
    },
    {
      "x": 25,
      "y": 28,
      "z": 14,
      "name": "Soil_Dirt"
    },
    {
      "x": 25,
      "y": 29,
      "z": 14,
      "name": "Soil_Grass"
    },
    {
      "x": 25,
      "y": 24,
      "z": 15,
      "name": "Rock_Basalt"
    },
    {
      "x": 25,
      "y": 25,
      "z": 15,
      "name": "Rock_Basalt"
    },
    {
      "x": 25,
      "y": 26,
      "z": 15,
      "name": "Soil_Dirt"
    },
    {
      "x": 25,
      "y": 27,
      "z": 15,
      "name": "Soil_Dirt"
    },
    {
      "x": 25,
      "y": 28,
      "z": 15,
      "name": "Soil_Dirt"
    },
    {
      "x": 25,
      "y": 29,
      "z": 15,
      "name": "Soil_Dirt"
    },
    {
      "x": 25,
      "y": 30,
      "z": 15,
      "name": "Soil_Grass"
    },
    {
      "x": 25,
      "y": 24,
      "z": 16,
      "name": "Rock_Basalt"
    },
    {
      "x": 25,
      "y": 25,
      "z": 16,
      "name": "Rock_Basalt"
    },
    {
      "x": 25,
      "y": 26,
      "z": 16,
      "name": "Soil_Dirt"
    },
    {
      "x": 25,
      "y": 27,
      "z": 16,
      "name": "Soil_Dirt"
    },
    {
      "x": 25,
      "y": 28,
      "z": 16,
      "name": "Soil_Dirt"
    },
    {
      "x": 25,
      "y": 29,
      "z": 16,
      "name": "Soil_Dirt"
    },
    {
      "x": 25,
      "y": 30,
      "z": 16,
      "name": "Soil_Grass"
    },
    {
      "x": 25,
      "y": 31,
      "z": 16,
      "name": "Plant_Grass_Sharp_Tall"
    },
    {
      "x": 25,
      "y": 32,
      "z": 16,
      "name": "Plant_Grass_Sharp_Tall",
      "filler": 1024
    },
    {
      "x": 25,
      "y": 45,
      "z": 16,
      "name": "Plant_Leaves_Cedar",
      "support": 15
    },
    {
      "x": 25,
      "y": 26,
      "z": 17,
      "name": "Rock_Basalt"
    },
    {
      "x": 25,
      "y": 27,
      "z": 17,
      "name": "Soil_Dirt"
    },
    {
      "x": 25,
      "y": 28,
      "z": 17,
      "name": "Soil_Dirt"
    },
    {
      "x": 25,
      "y": 29,
      "z": 17,
      "name": "Rock_Stone"
    },
    {
      "x": 25,
      "y": 30,
      "z": 17,
      "name": "Soil_Grass"
    },
    {
      "x": 25,
      "y": 45,
      "z": 17,
      "name": "Plant_Leaves_Cedar",
      "support": 15
    },
    {
      "x": 25,
      "y": 26,
      "z": 18,
      "name": "Rock_Basalt"
    },
    {
      "x": 25,
      "y": 27,
      "z": 18,
      "name": "Soil_Dirt"
    },
    {
      "x": 25,
      "y": 28,
      "z": 18,
      "name": "Soil_Dirt"
    },
    {
      "x": 25,
      "y": 29,
      "z": 18,
      "name": "Soil_Dirt"
    },
    {
      "x": 25,
      "y": 30,
      "z": 18,
      "name": "Soil_Dirt"
    },
    {
      "x": 25,
      "y": 45,
      "z": 18,
      "name": "Plant_Leaves_Cedar",
      "support": 15
    },
    {
      "x": 25,
      "y": 46,
      "z": 18,
      "name": "Plant_Leaves_Cedar",
      "support": 15
    },
    {
      "x": 25,
      "y": 49,
      "z": 18,
      "name": "Plant_Leaves_Cedar",
      "support": 15
    },
    {
      "x": 25,
      "y": 26,
      "z": 19,
      "name": "Rock_Basalt"
    },
    {
      "x": 25,
      "y": 27,
      "z": 19,
      "name": "Soil_Dirt"
    },
    {
      "x": 25,
      "y": 28,
      "z": 19,
      "name": "Soil_Dirt"
    },
    {
      "x": 25,
      "y": 29,
      "z": 19,
      "name": "Soil_Dirt"
    },
    {
      "x": 25,
      "y": 44,
      "z": 19,
      "name": "Plant_Leaves_Cedar",
      "support": 15
    },
    {
      "x": 25,
      "y": 46,
      "z": 19,
      "name": "Plant_Leaves_Cedar",
      "support": 15
    },
    {
      "x": 25,
      "y": 48,
      "z": 19,
      "name": "Plant_Leaves_Cedar",
      "support": 15
    },
    {
      "x": 25,
      "y": 49,
      "z": 19,
      "name": "Plant_Leaves_Cedar",
      "support": 15
    },
    {
      "x": 25,
      "y": 26,
      "z": 20,
      "name": "Rock_Basalt"
    },
    {
      "x": 25,
      "y": 27,
      "z": 20,
      "name": "Rock_Basalt"
    },
    {
      "x": 25,
      "y": 44,
      "z": 20,
      "name": "Wood_Cedar_Branch_Long",
      "support": 15,
      "rotation": 5
    },
    {
      "x": 25,
      "y": 46,
      "z": 20,
      "name": "Plant_Leaves_Cedar",
      "support": 15
    },
    {
      "x": 25,
      "y": 44,
      "z": 21,
      "name": "Plant_Leaves_Cedar",
      "support": 15
    },
    {
      "x": 25,
      "y": 44,
      "z": 22,
      "name": "Plant_Leaves_Cedar",
      "support": 15
    },
    {
      "x": 26,
      "y": 9,
      "z": 10,
      "name": "Rock_Basalt"
    },
    {
      "x": 26,
      "y": 10,
      "z": 10,
      "name": "Rock_Basalt"
    },
    {
      "x": 26,
      "y": 8,
      "z": 11,
      "name": "Rock_Basalt"
    },
    {
      "x": 26,
      "y": 9,
      "z": 11,
      "name": "Rock_Basalt"
    },
    {
      "x": 26,
      "y": 10,
      "z": 11,
      "name": "Rock_Basalt"
    },
    {
      "x": 26,
      "y": 8,
      "z": 12,
      "name": "Rock_Basalt"
    },
    {
      "x": 26,
      "y": 9,
      "z": 12,
      "name": "Rock_Basalt"
    },
    {
      "x": 26,
      "y": 10,
      "z": 12,
      "name": "Rock_Basalt"
    },
    {
      "x": 26,
      "y": 11,
      "z": 12,
      "name": "Rock_Basalt"
    },
    {
      "x": 26,
      "y": 25,
      "z": 12,
      "name": "Rock_Basalt"
    },
    {
      "x": 26,
      "y": 26,
      "z": 12,
      "name": "Soil_Dirt"
    },
    {
      "x": 26,
      "y": 27,
      "z": 12,
      "name": "Soil_Dirt"
    },
    {
      "x": 26,
      "y": 28,
      "z": 12,
      "name": "Soil_Grass"
    },
    {
      "x": 26,
      "y": 8,
      "z": 13,
      "name": "Rock_Basalt"
    },
    {
      "x": 26,
      "y": 9,
      "z": 13,
      "name": "Rock_Basalt"
    },
    {
      "x": 26,
      "y": 10,
      "z": 13,
      "name": "Rock_Basalt"
    },
    {
      "x": 26,
      "y": 11,
      "z": 13,
      "name": "Rock_Basalt"
    },
    {
      "x": 26,
      "y": 25,
      "z": 13,
      "name": "Rock_Basalt"
    },
    {
      "x": 26,
      "y": 26,
      "z": 13,
      "name": "Soil_Dirt"
    },
    {
      "x": 26,
      "y": 27,
      "z": 13,
      "name": "Soil_Dirt"
    },
    {
      "x": 26,
      "y": 28,
      "z": 13,
      "name": "Soil_Grass"
    },
    {
      "x": 26,
      "y": 29,
      "z": 13,
      "name": "Plant_Grass_Sharp_Tall"
    },
    {
      "x": 26,
      "y": 30,
      "z": 13,
      "name": "Plant_Grass_Sharp_Tall",
      "filler": 1024
    },
    {
      "x": 26,
      "y": 24,
      "z": 14,
      "name": "Rock_Basalt"
    },
    {
      "x": 26,
      "y": 25,
      "z": 14,
      "name": "Rock_Basalt"
    },
    {
      "x": 26,
      "y": 26,
      "z": 14,
      "name": "Soil_Dirt"
    },
    {
      "x": 26,
      "y": 27,
      "z": 14,
      "name": "Soil_Dirt"
    },
    {
      "x": 26,
      "y": 28,
      "z": 14,
      "name": "Soil_Dirt"
    },
    {
      "x": 26,
      "y": 29,
      "z": 14,
      "name": "Soil_Grass"
    },
    {
      "x": 26,
      "y": 24,
      "z": 15,
      "name": "Rock_Basalt"
    },
    {
      "x": 26,
      "y": 25,
      "z": 15,
      "name": "Rock_Basalt"
    },
    {
      "x": 26,
      "y": 26,
      "z": 15,
      "name": "Soil_Dirt"
    },
    {
      "x": 26,
      "y": 27,
      "z": 15,
      "name": "Soil_Dirt"
    },
    {
      "x": 26,
      "y": 28,
      "z": 15,
      "name": "Soil_Dirt"
    },
    {
      "x": 26,
      "y": 29,
      "z": 15,
      "name": "Soil_Grass"
    },
    {
      "x": 26,
      "y": 30,
      "z": 15,
      "name": "Plant_Grass_Sharp_Tall"
    },
    {
      "x": 26,
      "y": 31,
      "z": 15,
      "name": "Plant_Grass_Sharp_Tall",
      "filler": 1024
    },
    {
      "x": 26,
      "y": 24,
      "z": 16,
      "name": "Rock_Basalt"
    },
    {
      "x": 26,
      "y": 25,
      "z": 16,
      "name": "Rock_Basalt"
    },
    {
      "x": 26,
      "y": 26,
      "z": 16,
      "name": "Soil_Dirt"
    },
    {
      "x": 26,
      "y": 27,
      "z": 16,
      "name": "Soil_Dirt"
    },
    {
      "x": 26,
      "y": 28,
      "z": 16,
      "name": "Rock_Stone"
    },
    {
      "x": 26,
      "y": 29,
      "z": 16,
      "name": "Rock_Stone"
    },
    {
      "x": 26,
      "y": 30,
      "z": 16,
      "name": "Soil_Grass"
    },
    {
      "x": 26,
      "y": 25,
      "z": 17,
      "name": "Rock_Basalt"
    },
    {
      "x": 26,
      "y": 26,
      "z": 17,
      "name": "Rock_Basalt"
    },
    {
      "x": 26,
      "y": 27,
      "z": 17,
      "name": "Soil_Dirt"
    },
    {
      "x": 26,
      "y": 28,
      "z": 17,
      "name": "Rock_Stone"
    },
    {
      "x": 26,
      "y": 29,
      "z": 17,
      "name": "Rock_Stone"
    },
    {
      "x": 26,
      "y": 30,
      "z": 17,
      "name": "Rock_Stone"
    },
    {
      "x": 26,
      "y": 46,
      "z": 17,
      "name": "Plant_Leaves_Cedar",
      "support": 15
    },
    {
      "x": 26,
      "y": 26,
      "z": 18,
      "name": "Soil_Dirt"
    },
    {
      "x": 26,
      "y": 27,
      "z": 18,
      "name": "Soil_Dirt"
    },
    {
      "x": 26,
      "y": 28,
      "z": 18,
      "name": "Rock_Stone"
    },
    {
      "x": 26,
      "y": 29,
      "z": 18,
      "name": "Rock_Stone"
    },
    {
      "x": 26,
      "y": 30,
      "z": 18,
      "name": "Rock_Stone"
    },
    {
      "x": 26,
      "y": 44,
      "z": 18,
      "name": "Plant_Leaves_Cedar",
      "support": 15
    },
    {
      "x": 26,
      "y": 46,
      "z": 18,
      "name": "Plant_Leaves_Cedar",
      "support": 15
    },
    {
      "x": 26,
      "y": 49,
      "z": 18,
      "name": "Plant_Leaves_Cedar",
      "support": 15
    },
    {
      "x": 26,
      "y": 7,
      "z": 19,
      "name": "Rock_Basalt"
    },
    {
      "x": 26,
      "y": 26,
      "z": 19,
      "name": "Soil_Dirt"
    },
    {
      "x": 26,
      "y": 27,
      "z": 19,
      "name": "Soil_Dirt"
    },
    {
      "x": 26,
      "y": 28,
      "z": 19,
      "name": "Rock_Stone"
    },
    {
      "x": 26,
      "y": 29,
      "z": 19,
      "name": "Soil_Dirt"
    },
    {
      "x": 26,
      "y": 41,
      "z": 19,
      "name": "Wood_Cedar_Branch_Long",
      "support": 15,
      "rotation": 5
    },
    {
      "x": 26,
      "y": 44,
      "z": 19,
      "name": "Plant_Leaves_Cedar",
      "support": 15
    },
    {
      "x": 26,
      "y": 46,
      "z": 19,
      "name": "Wood_Cedar_Branch_Long",
      "support": 15,
      "rotation": 5
    },
    {
      "x": 26,
      "y": 47,
      "z": 19,
      "name": "Plant_Leaves_Cedar",
      "support": 15
    },
    {
      "x": 26,
      "y": 49,
      "z": 19,
      "name": "Plant_Leaves_Cedar",
      "support": 15
    },
    {
      "x": 26,
      "y": 50,
      "z": 19,
      "name": "Plant_Leaves_Cedar",
      "support": 15
    },
    {
      "x": 26,
      "y": 52,
      "z": 19,
      "name": "Plant_Leaves_Cedar",
      "support": 15
    },
    {
      "x": 26,
      "y": 8,
      "z": 20,
      "name": "Rock_Basalt"
    },
    {
      "x": 26,
      "y": 25,
      "z": 20,
      "name": "Rock_Basalt"
    },
    {
      "x": 26,
      "y": 26,
      "z": 20,
      "name": "Soil_Dirt"
    },
    {
      "x": 26,
      "y": 44,
      "z": 20,
      "name": "Wood_Cedar_Branch_Long",
      "support": 15,
      "rotation": 5
    },
    {
      "x": 26,
      "y": 46,
      "z": 20,
      "name": "Plant_Leaves_Cedar",
      "support": 15
    },
    {
      "x": 26,
      "y": 47,
      "z": 20,
      "name": "Plant_Leaves_Cedar",
      "support": 15
    },
    {
      "x": 26,
      "y": 49,
      "z": 20,
      "name": "Plant_Leaves_Cedar",
      "support": 15
    },
    {
      "x": 26,
      "y": 44,
      "z": 21,
      "name": "Plant_Leaves_Cedar",
      "support": 15
    },
    {
      "x": 26,
      "y": 46,
      "z": 21,
      "name": "Plant_Leaves_Cedar",
      "support": 15
    },
    {
      "x": 26,
      "y": 44,
      "z": 22,
      "name": "Plant_Leaves_Cedar",
      "support": 15
    },
    {
      "x": 26,
      "y": 44,
      "z": 24,
      "name": "Plant_Leaves_Cedar",
      "support": 15
    },
    {
      "x": 27,
      "y": 9,
      "z": 11,
      "name": "Rock_Basalt"
    },
    {
      "x": 27,
      "y": 8,
      "z": 12,
      "name": "Rock_Basalt"
    },
    {
      "x": 27,
      "y": 9,
      "z": 12,
      "name": "Rock_Basalt"
    },
    {
      "x": 27,
      "y": 10,
      "z": 12,
      "name": "Rock_Basalt"
    },
    {
      "x": 27,
      "y": 25,
      "z": 12,
      "name": "Rock_Basalt"
    },
    {
      "x": 27,
      "y": 26,
      "z": 12,
      "name": "Rock_Basalt"
    },
    {
      "x": 27,
      "y": 27,
      "z": 12,
      "name": "Soil_Dirt"
    },
    {
      "x": 27,
      "y": 28,
      "z": 12,
      "name": "Soil_Grass"
    },
    {
      "x": 27,
      "y": 8,
      "z": 13,
      "name": "Rock_Basalt"
    },
    {
      "x": 27,
      "y": 9,
      "z": 13,
      "name": "Rock_Basalt"
    },
    {
      "x": 27,
      "y": 10,
      "z": 13,
      "name": "Rock_Basalt"
    },
    {
      "x": 27,
      "y": 11,
      "z": 13,
      "name": "Rock_Basalt"
    },
    {
      "x": 27,
      "y": 12,
      "z": 13,
      "name": "Rock_Basalt"
    },
    {
      "x": 27,
      "y": 24,
      "z": 13,
      "name": "Rock_Basalt"
    },
    {
      "x": 27,
      "y": 25,
      "z": 13,
      "name": "Rock_Basalt"
    },
    {
      "x": 27,
      "y": 26,
      "z": 13,
      "name": "Soil_Dirt"
    },
    {
      "x": 27,
      "y": 27,
      "z": 13,
      "name": "Soil_Dirt"
    },
    {
      "x": 27,
      "y": 28,
      "z": 13,
      "name": "Soil_Grass"
    },
    {
      "x": 27,
      "y": 29,
      "z": 13,
      "name": "Plant_Fern_Winter"
    },
    {
      "x": 27,
      "y": 9,
      "z": 14,
      "name": "Rock_Basalt"
    },
    {
      "x": 27,
      "y": 10,
      "z": 14,
      "name": "Rock_Basalt"
    },
    {
      "x": 27,
      "y": 11,
      "z": 14,
      "name": "Rock_Basalt"
    },
    {
      "x": 27,
      "y": 12,
      "z": 14,
      "name": "Rock_Basalt"
    },
    {
      "x": 27,
      "y": 24,
      "z": 14,
      "name": "Rock_Basalt"
    },
    {
      "x": 27,
      "y": 25,
      "z": 14,
      "name": "Rock_Basalt"
    },
    {
      "x": 27,
      "y": 26,
      "z": 14,
      "name": "Soil_Dirt"
    },
    {
      "x": 27,
      "y": 27,
      "z": 14,
      "name": "Soil_Dirt"
    },
    {
      "x": 27,
      "y": 28,
      "z": 14,
      "name": "Soil_Grass"
    },
    {
      "x": 27,
      "y": 12,
      "z": 15,
      "name": "Rock_Basalt"
    },
    {
      "x": 27,
      "y": 23,
      "z": 15,
      "name": "Rock_Basalt"
    },
    {
      "x": 27,
      "y": 24,
      "z": 15,
      "name": "Rock_Basalt"
    },
    {
      "x": 27,
      "y": 25,
      "z": 15,
      "name": "Rock_Basalt"
    },
    {
      "x": 27,
      "y": 26,
      "z": 15,
      "name": "Soil_Dirt"
    },
    {
      "x": 27,
      "y": 27,
      "z": 15,
      "name": "Rock_Stone"
    },
    {
      "x": 27,
      "y": 28,
      "z": 15,
      "name": "Rock_Stone"
    },
    {
      "x": 27,
      "y": 29,
      "z": 15,
      "name": "Rock_Stone"
    },
    {
      "x": 27,
      "y": 30,
      "z": 15,
      "name": "Rock_Stone"
    },
    {
      "x": 27,
      "y": 43,
      "z": 15,
      "name": "Plant_Leaves_Cedar",
      "support": 15
    },
    {
      "x": 27,
      "y": 25,
      "z": 16,
      "name": "Rock_Basalt"
    },
    {
      "x": 27,
      "y": 26,
      "z": 16,
      "name": "Soil_Dirt"
    },
    {
      "x": 27,
      "y": 27,
      "z": 16,
      "name": "Rock_Stone"
    },
    {
      "x": 27,
      "y": 28,
      "z": 16,
      "name": "Rock_Stone"
    },
    {
      "x": 27,
      "y": 29,
      "z": 16,
      "name": "Rock_Stone"
    },
    {
      "x": 27,
      "y": 30,
      "z": 16,
      "name": "Rock_Stone"
    },
    {
      "x": 27,
      "y": 43,
      "z": 16,
      "name": "Plant_Leaves_Cedar",
      "support": 15
    },
    {
      "x": 27,
      "y": 24,
      "z": 17,
      "name": "Rock_Basalt"
    },
    {
      "x": 27,
      "y": 25,
      "z": 17,
      "name": "Rock_Basalt"
    },
    {
      "x": 27,
      "y": 26,
      "z": 17,
      "name": "Soil_Dirt"
    },
    {
      "x": 27,
      "y": 27,
      "z": 17,
      "name": "Rock_Stone"
    },
    {
      "x": 27,
      "y": 28,
      "z": 17,
      "name": "Rock_Stone"
    },
    {
      "x": 27,
      "y": 29,
      "z": 17,
      "name": "Rock_Stone"
    },
    {
      "x": 27,
      "y": 30,
      "z": 17,
      "name": "Rock_Stone"
    },
    {
      "x": 27,
      "y": 31,
      "z": 17,
      "name": "Rock_Stone"
    },
    {
      "x": 27,
      "y": 46,
      "z": 17,
      "name": "Plant_Leaves_Cedar",
      "support": 15
    },
    {
      "x": 27,
      "y": 49,
      "z": 17,
      "name": "Plant_Leaves_Cedar",
      "support": 15
    },
    {
      "x": 27,
      "y": 24,
      "z": 18,
      "name": "Rock_Basalt"
    },
    {
      "x": 27,
      "y": 25,
      "z": 18,
      "name": "Soil_Dirt"
    },
    {
      "x": 27,
      "y": 26,
      "z": 18,
      "name": "Soil_Dirt"
    },
    {
      "x": 27,
      "y": 27,
      "z": 18,
      "name": "Rock_Stone"
    },
    {
      "x": 27,
      "y": 28,
      "z": 18,
      "name": "Rock_Stone"
    },
    {
      "x": 27,
      "y": 29,
      "z": 18,
      "name": "Rock_Stone"
    },
    {
      "x": 27,
      "y": 30,
      "z": 18,
      "name": "Rock_Stone"
    },
    {
      "x": 27,
      "y": 31,
      "z": 18,
      "name": "Rock_Stone"
    },
    {
      "x": 27,
      "y": 44,
      "z": 18,
      "name": "Plant_Leaves_Cedar",
      "support": 15
    },
    {
      "x": 27,
      "y": 46,
      "z": 18,
      "name": "Plant_Leaves_Cedar",
      "support": 15
    },
    {
      "x": 27,
      "y": 49,
      "z": 18,
      "name": "Plant_Leaves_Cedar",
      "support": 15
    },
    {
      "x": 27,
      "y": 50,
      "z": 18,
      "name": "Plant_Leaves_Cedar",
      "support": 15
    },
    {
      "x": 27,
      "y": 52,
      "z": 18,
      "name": "Plant_Leaves_Cedar",
      "support": 15
    },
    {
      "x": 27,
      "y": 24,
      "z": 19,
      "name": "Rock_Basalt"
    },
    {
      "x": 27,
      "y": 25,
      "z": 19,
      "name": "Soil_Dirt"
    },
    {
      "x": 27,
      "y": 26,
      "z": 19,
      "name": "Soil_Dirt"
    },
    {
      "x": 27,
      "y": 27,
      "z": 19,
      "name": "Rock_Stone"
    },
    {
      "x": 27,
      "y": 28,
      "z": 19,
      "name": "Rock_Stone"
    },
    {
      "x": 27,
      "y": 29,
      "z": 19,
      "name": "Rock_Stone"
    },
    {
      "x": 27,
      "y": 30,
      "z": 19,
      "name": "Rubble_Basalt"
    },
    {
      "x": 27,
      "y": 41,
      "z": 19,
      "name": "Wood_Cedar_Branch_Long",
      "support": 15,
      "rotation": 5
    },
    {
      "x": 27,
      "y": 44,
      "z": 19,
      "name": "Plant_Leaves_Cedar",
      "support": 15
    },
    {
      "x": 27,
      "y": 46,
      "z": 19,
      "name": "Wood_Cedar_Branch_Long",
      "support": 15,
      "rotation": 5
    },
    {
      "x": 27,
      "y": 49,
      "z": 19,
      "name": "Wood_Cedar_Branch_Long",
      "support": 15,
      "rotation": 5
    },
    {
      "x": 27,
      "y": 50,
      "z": 19,
      "name": "Plant_Leaves_Cedar",
      "support": 15
    },
    {
      "x": 27,
      "y": 52,
      "z": 19,
      "name": "Plant_Leaves_Cedar",
      "support": 15
    },
    {
      "x": 27,
      "y": 53,
      "z": 19,
      "name": "Plant_Leaves_Cedar",
      "support": 15
    },
    {
      "x": 27,
      "y": 8,
      "z": 20,
      "name": "Rock_Basalt"
    },
    {
      "x": 27,
      "y": 9,
      "z": 20,
      "name": "Rock_Basalt"
    },
    {
      "x": 27,
      "y": 10,
      "z": 20,
      "name": "Rock_Basalt"
    },
    {
      "x": 27,
      "y": 24,
      "z": 20,
      "name": "Wood_Cedar_Roots"
    },
    {
      "x": 27,
      "y": 25,
      "z": 20,
      "name": "Wood_Cedar_Trunk_Full",
      "support": 15
    },
    {
      "x": 27,
      "y": 26,
      "z": 20,
      "name": "Wood_Cedar_Trunk_Full",
      "support": 15
    },
    {
      "x": 27,
      "y": 27,
      "z": 20,
      "name": "Rock_Stone"
    },
    {
      "x": 27,
      "y": 28,
      "z": 20,
      "name": "Rock_Stone"
    },
    {
      "x": 27,
      "y": 37,
      "z": 20,
      "name": "Wood_Cedar_Branch_Long",
      "support": 15,
      "rotation": 5
    },
    {
      "x": 27,
      "y": 44,
      "z": 20,
      "name": "Wood_Cedar_Branch_Long",
      "support": 15,
      "rotation": 5
    },
    {
      "x": 27,
      "y": 46,
      "z": 20,
      "name": "Plant_Leaves_Cedar",
      "support": 15
    },
    {
      "x": 27,
      "y": 49,
      "z": 20,
      "name": "Plant_Leaves_Cedar",
      "support": 15
    },
    {
      "x": 27,
      "y": 50,
      "z": 20,
      "name": "Plant_Leaves_Cedar",
      "support": 15
    },
    {
      "x": 27,
      "y": 52,
      "z": 20,
      "name": "Plant_Leaves_Cedar",
      "support": 15
    },
    {
      "x": 27,
      "y": 55,
      "z": 20,
      "name": "Plant_Leaves_Cedar",
      "support": 15
    },
    {
      "x": 27,
      "y": 9,
      "z": 21,
      "name": "Rock_Basalt"
    },
    {
      "x": 27,
      "y": 10,
      "z": 21,
      "name": "Rock_Basalt"
    },
    {
      "x": 27,
      "y": 25,
      "z": 21,
      "name": "Soil_Dirt"
    },
    {
      "x": 27,
      "y": 26,
      "z": 21,
      "name": "Soil_Dirt"
    },
    {
      "x": 27,
      "y": 44,
      "z": 21,
      "name": "Plant_Leaves_Cedar",
      "support": 15
    },
    {
      "x": 27,
      "y": 11,
      "z": 22,
      "name": "Rock_Basalt"
    },
    {
      "x": 27,
      "y": 44,
      "z": 22,
      "name": "Plant_Leaves_Cedar",
      "support": 15
    },
    {
      "x": 27,
      "y": 12,
      "z": 23,
      "name": "Rock_Basalt"
    },
    {
      "x": 27,
      "y": 45,
      "z": 23,
      "name": "Plant_Leaves_Cedar",
      "support": 15
    },
    {
      "x": 27,
      "y": 44,
      "z": 24,
      "name": "Plant_Leaves_Cedar",
      "support": 15
    },
    {
      "x": 28,
      "y": 25,
      "z": 12,
      "name": "Rock_Basalt"
    },
    {
      "x": 28,
      "y": 26,
      "z": 12,
      "name": "Rock_Basalt"
    },
    {
      "x": 28,
      "y": 27,
      "z": 12,
      "name": "Soil_Dirt"
    },
    {
      "x": 28,
      "y": 28,
      "z": 12,
      "name": "Soil_Dirt"
    },
    {
      "x": 28,
      "y": 10,
      "z": 13,
      "name": "Rock_Basalt"
    },
    {
      "x": 28,
      "y": 11,
      "z": 13,
      "name": "Rock_Basalt"
    },
    {
      "x": 28,
      "y": 24,
      "z": 13,
      "name": "Rock_Basalt"
    },
    {
      "x": 28,
      "y": 25,
      "z": 13,
      "name": "Rock_Basalt"
    },
    {
      "x": 28,
      "y": 26,
      "z": 13,
      "name": "Soil_Dirt"
    },
    {
      "x": 28,
      "y": 27,
      "z": 13,
      "name": "Soil_Dirt"
    },
    {
      "x": 28,
      "y": 28,
      "z": 13,
      "name": "Soil_Grass"
    },
    {
      "x": 28,
      "y": 29,
      "z": 13,
      "name": "Plant_Grass_Sharp_Tall"
    },
    {
      "x": 28,
      "y": 30,
      "z": 13,
      "name": "Plant_Grass_Sharp_Tall",
      "filler": 1024
    },
    {
      "x": 28,
      "y": 9,
      "z": 14,
      "name": "Rock_Basalt"
    },
    {
      "x": 28,
      "y": 10,
      "z": 14,
      "name": "Rock_Basalt"
    },
    {
      "x": 28,
      "y": 11,
      "z": 14,
      "name": "Rock_Basalt"
    },
    {
      "x": 28,
      "y": 12,
      "z": 14,
      "name": "Rock_Basalt"
    },
    {
      "x": 28,
      "y": 23,
      "z": 14,
      "name": "Rock_Basalt"
    },
    {
      "x": 28,
      "y": 24,
      "z": 14,
      "name": "Rock_Basalt"
    },
    {
      "x": 28,
      "y": 25,
      "z": 14,
      "name": "Soil_Dirt"
    },
    {
      "x": 28,
      "y": 26,
      "z": 14,
      "name": "Soil_Dirt"
    },
    {
      "x": 28,
      "y": 27,
      "z": 14,
      "name": "Soil_Dirt"
    },
    {
      "x": 28,
      "y": 28,
      "z": 14,
      "name": "Rock_Stone"
    },
    {
      "x": 28,
      "y": 42,
      "z": 14,
      "name": "Plant_Leaves_Cedar",
      "support": 15
    },
    {
      "x": 28,
      "y": 11,
      "z": 15,
      "name": "Rock_Basalt"
    },
    {
      "x": 28,
      "y": 12,
      "z": 15,
      "name": "Rock_Basalt"
    },
    {
      "x": 28,
      "y": 13,
      "z": 15,
      "name": "Rock_Basalt"
    },
    {
      "x": 28,
      "y": 23,
      "z": 15,
      "name": "Rock_Basalt"
    },
    {
      "x": 28,
      "y": 24,
      "z": 15,
      "name": "Rock_Basalt"
    },
    {
      "x": 28,
      "y": 25,
      "z": 15,
      "name": "Soil_Dirt"
    },
    {
      "x": 28,
      "y": 26,
      "z": 15,
      "name": "Soil_Dirt"
    },
    {
      "x": 28,
      "y": 27,
      "z": 15,
      "name": "Rock_Stone"
    },
    {
      "x": 28,
      "y": 28,
      "z": 15,
      "name": "Rock_Stone"
    },
    {
      "x": 28,
      "y": 29,
      "z": 15,
      "name": "Rock_Stone"
    },
    {
      "x": 28,
      "y": 30,
      "z": 15,
      "name": "Rock_Stone"
    },
    {
      "x": 28,
      "y": 31,
      "z": 15,
      "name": "Rubble_Basalt"
    },
    {
      "x": 28,
      "y": 43,
      "z": 15,
      "name": "Plant_Leaves_Cedar",
      "support": 15
    },
    {
      "x": 28,
      "y": 24,
      "z": 16,
      "name": "Rock_Basalt"
    },
    {
      "x": 28,
      "y": 25,
      "z": 16,
      "name": "Soil_Dirt"
    },
    {
      "x": 28,
      "y": 26,
      "z": 16,
      "name": "Rock_Stone"
    },
    {
      "x": 28,
      "y": 27,
      "z": 16,
      "name": "Rock_Stone"
    },
    {
      "x": 28,
      "y": 28,
      "z": 16,
      "name": "Rock_Stone"
    },
    {
      "x": 28,
      "y": 29,
      "z": 16,
      "name": "Rock_Stone"
    },
    {
      "x": 28,
      "y": 30,
      "z": 16,
      "name": "Rock_Stone"
    },
    {
      "x": 28,
      "y": 31,
      "z": 16,
      "name": "Rock_Stone"
    },
    {
      "x": 28,
      "y": 43,
      "z": 16,
      "name": "Plant_Leaves_Cedar",
      "support": 15
    },
    {
      "x": 28,
      "y": 47,
      "z": 16,
      "name": "Plant_Leaves_Cedar",
      "support": 15
    },
    {
      "x": 28,
      "y": 24,
      "z": 17,
      "name": "Rock_Basalt"
    },
    {
      "x": 28,
      "y": 25,
      "z": 17,
      "name": "Soil_Dirt"
    },
    {
      "x": 28,
      "y": 26,
      "z": 17,
      "name": "Soil_Dirt"
    },
    {
      "x": 28,
      "y": 27,
      "z": 17,
      "name": "Rock_Stone"
    },
    {
      "x": 28,
      "y": 28,
      "z": 17,
      "name": "Rock_Stone"
    },
    {
      "x": 28,
      "y": 29,
      "z": 17,
      "name": "Rock_Stone"
    },
    {
      "x": 28,
      "y": 30,
      "z": 17,
      "name": "Rock_Stone"
    },
    {
      "x": 28,
      "y": 31,
      "z": 17,
      "name": "Rock_Stone_Mossy"
    },
    {
      "x": 28,
      "y": 43,
      "z": 17,
      "name": "Plant_Leaves_Cedar",
      "support": 15
    },
    {
      "x": 28,
      "y": 47,
      "z": 17,
      "name": "Plant_Leaves_Cedar",
      "support": 15
    },
    {
      "x": 28,
      "y": 49,
      "z": 17,
      "name": "Plant_Leaves_Cedar",
      "support": 15
    },
    {
      "x": 28,
      "y": 53,
      "z": 17,
      "name": "Plant_Leaves_Cedar",
      "support": 15
    },
    {
      "x": 28,
      "y": 24,
      "z": 18,
      "name": "Rock_Basalt"
    },
    {
      "x": 28,
      "y": 25,
      "z": 18,
      "name": "Soil_Dirt"
    },
    {
      "x": 28,
      "y": 26,
      "z": 18,
      "name": "Soil_Dirt"
    },
    {
      "x": 28,
      "y": 27,
      "z": 18,
      "name": "Rock_Stone"
    },
    {
      "x": 28,
      "y": 28,
      "z": 18,
      "name": "Rock_Stone"
    },
    {
      "x": 28,
      "y": 29,
      "z": 18,
      "name": "Rock_Stone"
    },
    {
      "x": 28,
      "y": 30,
      "z": 18,
      "name": "Rock_Stone"
    },
    {
      "x": 28,
      "y": 50,
      "z": 18,
      "name": "Plant_Leaves_Cedar",
      "support": 15
    },
    {
      "x": 28,
      "y": 53,
      "z": 18,
      "name": "Plant_Leaves_Cedar",
      "support": 15
    },
    {
      "x": 28,
      "y": 55,
      "z": 18,
      "name": "Plant_Leaves_Cedar",
      "support": 15
    },
    {
      "x": 28,
      "y": 24,
      "z": 19,
      "name": "Rock_Basalt"
    },
    {
      "x": 28,
      "y": 25,
      "z": 19,
      "name": "Soil_Dirt"
    },
    {
      "x": 28,
      "y": 26,
      "z": 19,
      "name": "Wood_Cedar_Roots"
    },
    {
      "x": 28,
      "y": 27,
      "z": 19,
      "name": "Wood_Cedar_Trunk_Full",
      "support": 15
    },
    {
      "x": 28,
      "y": 28,
      "z": 19,
      "name": "Wood_Cedar_Trunk",
      "support": 15
    },
    {
      "x": 28,
      "y": 29,
      "z": 19,
      "name": "Wood_Cedar_Trunk",
      "support": 15
    },
    {
      "x": 28,
      "y": 30,
      "z": 19,
      "name": "Wood_Cedar_Trunk_Full",
      "support": 15
    },
    {
      "x": 28,
      "y": 35,
      "z": 19,
      "name": "Wood_Cedar_Branch_Long",
      "support": 15,
      "rotation": 5
    },
    {
      "x": 28,
      "y": 41,
      "z": 19,
      "name": "Wood_Cedar_Branch_Long",
      "support": 15,
      "rotation": 5
    },
    {
      "x": 28,
      "y": 46,
      "z": 19,
      "name": "Wood_Cedar_Branch_Long",
      "support": 15,
      "rotation": 5
    },
    {
      "x": 28,
      "y": 49,
      "z": 19,
      "name": "Wood_Cedar_Branch_Long",
      "support": 15,
      "rotation": 5
    },
    {
      "x": 28,
      "y": 52,
      "z": 19,
      "name": "Wood_Cedar_Branch_Long",
      "support": 15,
      "rotation": 5
    },
    {
      "x": 28,
      "y": 53,
      "z": 19,
      "name": "Plant_Leaves_Cedar",
      "support": 15
    },
    {
      "x": 28,
      "y": 55,
      "z": 19,
      "name": "Plant_Leaves_Cedar",
      "support": 15
    },
    {
      "x": 28,
      "y": 56,
      "z": 19,
      "name": "Plant_Leaves_Cedar",
      "support": 15
    },
    {
      "x": 28,
      "y": 10,
      "z": 20,
      "name": "Rock_Basalt"
    },
    {
      "x": 28,
      "y": 24,
      "z": 20,
      "name": "Soil_Dirt"
    },
    {
      "x": 28,
      "y": 25,
      "z": 20,
      "name": "Soil_Dirt"
    },
    {
      "x": 28,
      "y": 26,
      "z": 20,
      "name": "Wood_Cedar_Trunk_Full",
      "support": 15
    },
    {
      "x": 28,
      "y": 27,
      "z": 20,
      "name": "Wood_Cedar_Trunk",
      "support": 15
    },
    {
      "x": 28,
      "y": 28,
      "z": 20,
      "name": "Wood_Cedar_Trunk",
      "support": 15
    },
    {
      "x": 28,
      "y": 29,
      "z": 20,
      "name": "Wood_Cedar_Trunk",
      "support": 15
    },
    {
      "x": 28,
      "y": 30,
      "z": 20,
      "name": "Wood_Cedar_Trunk",
      "support": 15
    },
    {
      "x": 28,
      "y": 31,
      "z": 20,
      "name": "Wood_Cedar_Trunk",
      "support": 15
    },
    {
      "x": 28,
      "y": 32,
      "z": 20,
      "name": "Wood_Cedar_Trunk_Full",
      "support": 15
    },
    {
      "x": 28,
      "y": 37,
      "z": 20,
      "name": "Wood_Cedar_Branch_Long",
      "support": 15,
      "rotation": 5
    },
    {
      "x": 28,
      "y": 44,
      "z": 20,
      "name": "Wood_Cedar_Branch_Long",
      "support": 15,
      "rotation": 5
    },
    {
      "x": 28,
      "y": 52,
      "z": 20,
      "name": "Plant_Leaves_Cedar",
      "support": 15
    },
    {
      "x": 28,
      "y": 55,
      "z": 20,
      "name": "Plant_Leaves_Cedar",
      "support": 15
    },
    {
      "x": 28,
      "y": 9,
      "z": 21,
      "name": "Rock_Basalt"
    },
    {
      "x": 28,
      "y": 10,
      "z": 21,
      "name": "Rock_Basalt"
    },
    {
      "x": 28,
      "y": 11,
      "z": 21,
      "name": "Rock_Basalt"
    },
    {
      "x": 28,
      "y": 24,
      "z": 21,
      "name": "Soil_Dirt"
    },
    {
      "x": 28,
      "y": 25,
      "z": 21,
      "name": "Soil_Dirt"
    },
    {
      "x": 28,
      "y": 26,
      "z": 21,
      "name": "Soil_Dirt"
    },
    {
      "x": 28,
      "y": 27,
      "z": 21,
      "name": "Soil_Dirt"
    },
    {
      "x": 28,
      "y": 28,
      "z": 21,
      "name": "Plant_Grass_Sharp"
    },
    {
      "x": 28,
      "y": 50,
      "z": 21,
      "name": "Plant_Leaves_Cedar",
      "support": 15
    },
    {
      "x": 28,
      "y": 51,
      "z": 21,
      "name": "Plant_Leaves_Cedar",
      "support": 15
    },
    {
      "x": 28,
      "y": 10,
      "z": 22,
      "name": "Rock_Basalt"
    },
    {
      "x": 28,
      "y": 11,
      "z": 22,
      "name": "Rock_Basalt"
    },
    {
      "x": 28,
      "y": 12,
      "z": 22,
      "name": "Rock_Basalt"
    },
    {
      "x": 28,
      "y": 13,
      "z": 22,
      "name": "Rock_Basalt"
    },
    {
      "x": 28,
      "y": 14,
      "z": 22,
      "name": "Rock_Basalt"
    },
    {
      "x": 28,
      "y": 24,
      "z": 22,
      "name": "Soil_Dirt"
    },
    {
      "x": 28,
      "y": 25,
      "z": 22,
      "name": "Soil_Dirt"
    },
    {
      "x": 28,
      "y": 26,
      "z": 22,
      "name": "Soil_Dirt"
    },
    {
      "x": 28,
      "y": 45,
      "z": 22,
      "name": "Plant_Leaves_Cedar",
      "support": 15
    },
    {
      "x": 28,
      "y": 48,
      "z": 22,
      "name": "Plant_Leaves_Cedar",
      "support": 15
    },
    {
      "x": 28,
      "y": 50,
      "z": 22,
      "name": "Plant_Leaves_Cedar",
      "support": 15
    },
    {
      "x": 28,
      "y": 11,
      "z": 23,
      "name": "Rock_Basalt"
    },
    {
      "x": 28,
      "y": 12,
      "z": 23,
      "name": "Rock_Basalt"
    },
    {
      "x": 28,
      "y": 14,
      "z": 23,
      "name": "Rock_Basalt"
    },
    {
      "x": 28,
      "y": 15,
      "z": 23,
      "name": "Rock_Basalt"
    },
    {
      "x": 28,
      "y": 16,
      "z": 23,
      "name": "Rock_Basalt"
    },
    {
      "x": 28,
      "y": 17,
      "z": 23,
      "name": "Rock_Basalt"
    },
    {
      "x": 28,
      "y": 45,
      "z": 23,
      "name": "Plant_Leaves_Cedar",
      "support": 15
    },
    {
      "x": 28,
      "y": 14,
      "z": 24,
      "name": "Rock_Basalt"
    },
    {
      "x": 28,
      "y": 15,
      "z": 24,
      "name": "Rock_Basalt"
    },
    {
      "x": 28,
      "y": 16,
      "z": 24,
      "name": "Rock_Basalt"
    },
    {
      "x": 28,
      "y": 44,
      "z": 24,
      "name": "Plant_Leaves_Cedar",
      "support": 15
    },
    {
      "x": 28,
      "y": 45,
      "z": 24,
      "name": "Plant_Leaves_Cedar",
      "support": 15
    },
    {
      "x": 28,
      "y": 44,
      "z": 25,
      "name": "Plant_Leaves_Cedar",
      "support": 15
    },
    {
      "x": 29,
      "y": 26,
      "z": 12,
      "name": "Soil_Dirt"
    },
    {
      "x": 29,
      "y": 27,
      "z": 12,
      "name": "Soil_Dirt"
    },
    {
      "x": 29,
      "y": 11,
      "z": 13,
      "name": "Rock_Basalt"
    },
    {
      "x": 29,
      "y": 23,
      "z": 13,
      "name": "Soil_Dirt"
    },
    {
      "x": 29,
      "y": 24,
      "z": 13,
      "name": "Soil_Dirt"
    },
    {
      "x": 29,
      "y": 25,
      "z": 13,
      "name": "Soil_Dirt"
    },
    {
      "x": 29,
      "y": 26,
      "z": 13,
      "name": "Soil_Dirt"
    },
    {
      "x": 29,
      "y": 27,
      "z": 13,
      "name": "Soil_Dirt"
    },
    {
      "x": 29,
      "y": 28,
      "z": 13,
      "name": "Soil_Dirt"
    },
    {
      "x": 29,
      "y": 42,
      "z": 13,
      "name": "Plant_Leaves_Cedar",
      "support": 15
    },
    {
      "x": 29,
      "y": 10,
      "z": 14,
      "name": "Rock_Basalt"
    },
    {
      "x": 29,
      "y": 11,
      "z": 14,
      "name": "Rock_Basalt"
    },
    {
      "x": 29,
      "y": 12,
      "z": 14,
      "name": "Rock_Basalt"
    },
    {
      "x": 29,
      "y": 13,
      "z": 14,
      "name": "Rock_Basalt"
    },
    {
      "x": 29,
      "y": 22,
      "z": 14,
      "name": "Rock_Basalt"
    },
    {
      "x": 29,
      "y": 23,
      "z": 14,
      "name": "Soil_Dirt"
    },
    {
      "x": 29,
      "y": 24,
      "z": 14,
      "name": "Soil_Dirt"
    },
    {
      "x": 29,
      "y": 25,
      "z": 14,
      "name": "Soil_Dirt"
    },
    {
      "x": 29,
      "y": 26,
      "z": 14,
      "name": "Soil_Dirt"
    },
    {
      "x": 29,
      "y": 27,
      "z": 14,
      "name": "Rock_Stone"
    },
    {
      "x": 29,
      "y": 28,
      "z": 14,
      "name": "Rock_Stone"
    },
    {
      "x": 29,
      "y": 29,
      "z": 14,
      "name": "Rock_Stone"
    },
    {
      "x": 29,
      "y": 42,
      "z": 14,
      "name": "Plant_Leaves_Cedar",
      "support": 15
    },
    {
      "x": 29,
      "y": 43,
      "z": 14,
      "name": "Plant_Leaves_Cedar",
      "support": 15
    },
    {
      "x": 29,
      "y": 11,
      "z": 15,
      "name": "Rock_Basalt"
    },
    {
      "x": 29,
      "y": 12,
      "z": 15,
      "name": "Rock_Basalt"
    },
    {
      "x": 29,
      "y": 13,
      "z": 15,
      "name": "Rock_Basalt"
    },
    {
      "x": 29,
      "y": 14,
      "z": 15,
      "name": "Rock_Basalt"
    },
    {
      "x": 29,
      "y": 22,
      "z": 15,
      "name": "Rock_Basalt"
    },
    {
      "x": 29,
      "y": 23,
      "z": 15,
      "name": "Rock_Basalt"
    },
    {
      "x": 29,
      "y": 24,
      "z": 15,
      "name": "Rock_Basalt"
    },
    {
      "x": 29,
      "y": 25,
      "z": 15,
      "name": "Soil_Dirt"
    },
    {
      "x": 29,
      "y": 26,
      "z": 15,
      "name": "Soil_Dirt"
    },
    {
      "x": 29,
      "y": 27,
      "z": 15,
      "name": "Rock_Stone"
    },
    {
      "x": 29,
      "y": 28,
      "z": 15,
      "name": "Rock_Stone"
    },
    {
      "x": 29,
      "y": 29,
      "z": 15,
      "name": "Rock_Stone"
    },
    {
      "x": 29,
      "y": 30,
      "z": 15,
      "name": "Rock_Stone"
    },
    {
      "x": 29,
      "y": 43,
      "z": 15,
      "name": "Plant_Leaves_Cedar",
      "support": 15
    },
    {
      "x": 29,
