{
  "version": 8,
  "blockIdVersion": 8,
  "anchorX": 26,
  "anchorY": 18,
  "anchorZ": 13,
  "blocks": [
    {
      "x": 15,
      "y": 21,
      "z": 13,
      "name": "Rock_Basalt"
    },
    {
      "x": 15,
      "y": 22,
      "z": 13,
      "name": "Rock_Basalt"
    },
    {
      "x": 15,
      "y": 23,
      "z": 13,
      "name": "Rock_Basalt"
    },
    {
      "x": 15,
      "y": 24,
      "z": 13,
      "name": "Rock_Basalt"
    },
    {
      "x": 15,
      "y": 22,
      "z": 14,
      "name": "Rock_Basalt"
    },
    {
      "x": 15,
      "y": 23,
      "z": 14,
      "name": "Rock_Basalt"
    },
    {
      "x": 15,
      "y": 24,
      "z": 14,
      "name": "Rock_Basalt"
    },
    {
      "x": 15,
      "y": 25,
      "z": 14,
      "name": "Rock_Basalt"
    },
    {
      "x": 16,
      "y": 20,
      "z": 12,
      "name": "Rock_Basalt"
    },
    {
      "x": 16,
      "y": 21,
      "z": 12,
      "name": "Rock_Basalt"
    },
    {
      "x": 16,
      "y": 22,
      "z": 12,
      "name": "Rock_Basalt"
    },
    {
      "x": 16,
      "y": 23,
      "z": 12,
      "name": "Rock_Basalt"
    },
    {
      "x": 16,
      "y": 24,
      "z": 12,
      "name": "Rock_Basalt"
    },
    {
      "x": 16,
      "y": 25,
      "z": 12,
      "name": "Rock_Basalt"
    },
    {
      "x": 16,
      "y": 18,
      "z": 13,
      "name": "Rock_Basalt"
    },
    {
      "x": 16,
      "y": 19,
      "z": 13,
      "name": "Rock_Basalt"
    },
    {
      "x": 16,
      "y": 20,
      "z": 13,
      "name": "Rock_Basalt"
    },
    {
      "x": 16,
      "y": 21,
      "z": 13,
      "name": "Rock_Basalt"
    },
    {
      "x": 16,
      "y": 22,
      "z": 13,
      "name": "Rock_Basalt"
    },
    {
      "x": 16,
      "y": 23,
      "z": 13,
      "name": "Rock_Basalt"
    },
    {
      "x": 16,
      "y": 24,
      "z": 13,
      "name": "Rock_Basalt"
    },
    {
      "x": 16,
      "y": 25,
      "z": 13,
      "name": "Rock_Basalt"
    },
    {
      "x": 16,
      "y": 26,
      "z": 13,
      "name": "Rock_Basalt"
    },
    {
      "x": 16,
      "y": 27,
      "z": 13,
      "name": "Rock_Basalt"
    },
    {
      "x": 16,
      "y": 17,
      "z": 14,
      "name": "Rock_Basalt"
    },
    {
      "x": 16,
      "y": 18,
      "z": 14,
      "name": "Rock_Basalt"
    },
    {
      "x": 16,
      "y": 19,
      "z": 14,
      "name": "Rock_Basalt"
    },
    {
      "x": 16,
      "y": 20,
      "z": 14,
      "name": "Rock_Basalt"
    },
    {
      "x": 16,
      "y": 21,
      "z": 14,
      "name": "Rock_Basalt"
    },
    {
      "x": 16,
      "y": 22,
      "z": 14,
      "name": "Rock_Basalt"
    },
    {
      "x": 16,
      "y": 23,
      "z": 14,
      "name": "Rock_Basalt"
    },
    {
      "x": 16,
      "y": 24,
      "z": 14,
      "name": "Rock_Basalt"
    },
    {
      "x": 16,
      "y": 25,
      "z": 14,
      "name": "Rock_Basalt"
    },
    {
      "x": 16,
      "y": 26,
      "z": 14,
      "name": "Rock_Basalt"
    },
    {
      "x": 16,
      "y": 27,
      "z": 14,
      "name": "Rock_Basalt"
    },
    {
      "x": 16,
      "y": 28,
      "z": 14,
      "name": "Soil_Dirt"
    },
    {
      "x": 16,
      "y": 29,
      "z": 14,
      "name": "Soil_Dirt"
    },
    {
      "x": 16,
      "y": 30,
      "z": 14,
      "name": "Soil_Dirt"
    },
    {
      "x": 16,
      "y": 19,
      "z": 15,
      "name": "Rock_Basalt"
    },
    {
      "x": 16,
      "y": 20,
      "z": 15,
      "name": "Rock_Basalt"
    },
    {
      "x": 16,
      "y": 21,
      "z": 15,
      "name": "Rock_Basalt"
    },
    {
      "x": 16,
      "y": 22,
      "z": 15,
      "name": "Rock_Basalt"
    },
    {
      "x": 16,
      "y": 23,
      "z": 15,
      "name": "Rock_Basalt"
    },
    {
      "x": 16,
      "y": 24,
      "z": 15,
      "name": "Rock_Basalt"
    },
    {
      "x": 16,
      "y": 25,
      "z": 15,
      "name": "Rock_Basalt"
    },
    {
      "x": 16,
      "y": 26,
      "z": 15,
      "name": "Rock_Basalt"
    },
    {
      "x": 16,
      "y": 27,
      "z": 15,
      "name": "Rock_Basalt"
    },
    {
      "x": 16,
      "y": 28,
      "z": 15,
      "name": "Soil_Dirt"
    },
    {
      "x": 16,
      "y": 29,
      "z": 15,
      "name": "Soil_Dirt"
    },
    {
      "x": 16,
      "y": 24,
      "z": 16,
      "name": "Rock_Basalt"
    },
    {
      "x": 16,
      "y": 25,
      "z": 16,
      "name": "Rock_Basalt"
    },
    {
      "x": 16,
      "y": 26,
      "z": 16,
      "name": "Rock_Basalt"
    },
    {
      "x": 16,
      "y": 27,
      "z": 16,
      "name": "Rock_Basalt"
    },
    {
      "x": 16,
      "y": 28,
      "z": 16,
      "name": "Rock_Basalt"
    },
    {
      "x": 17,
      "y": 19,
      "z": 11,
      "name": "Rock_Basalt"
    },
    {
      "x": 17,
      "y": 20,
      "z": 11,
      "name": "Rock_Basalt"
    },
    {
      "x": 17,
      "y": 21,
      "z": 11,
      "name": "Rock_Basalt"
    },
    {
      "x": 17,
      "y": 22,
      "z": 11,
      "name": "Rock_Basalt"
    },
    {
      "x": 17,
      "y": 23,
      "z": 11,
      "name": "Rock_Basalt"
    },
    {
      "x": 17,
      "y": 24,
      "z": 11,
      "name": "Rock_Basalt"
    },
    {
      "x": 17,
      "y": 25,
      "z": 11,
      "name": "Rock_Basalt"
    },
    {
      "x": 17,
      "y": 26,
      "z": 11,
      "name": "Rock_Basalt"
    },
    {
      "x": 17,
      "y": 16,
      "z": 12,
      "name": "Rock_Basalt"
    },
    {
      "x": 17,
      "y": 17,
      "z": 12,
      "name": "Rock_Basalt"
    },
    {
      "x": 17,
      "y": 18,
      "z": 12,
      "name": "Rock_Basalt"
    },
    {
      "x": 17,
      "y": 19,
      "z": 12,
      "name": "Rock_Basalt"
    },
    {
      "x": 17,
      "y": 20,
      "z": 12,
      "name": "Rock_Basalt"
    },
    {
      "x": 17,
      "y": 21,
      "z": 12,
      "name": "Rock_Basalt"
    },
    {
      "x": 17,
      "y": 22,
      "z": 12,
      "name": "Rock_Basalt"
    },
    {
      "x": 17,
      "y": 23,
      "z": 12,
      "name": "Rock_Basalt"
    },
    {
      "x": 17,
      "y": 24,
      "z": 12,
      "name": "Rock_Basalt"
    },
    {
      "x": 17,
      "y": 25,
      "z": 12,
      "name": "Rock_Basalt"
    },
    {
      "x": 17,
      "y": 26,
      "z": 12,
      "name": "Rock_Basalt"
    },
    {
      "x": 17,
      "y": 27,
      "z": 12,
      "name": "Rock_Basalt"
    },
    {
      "x": 17,
      "y": 28,
      "z": 12,
      "name": "Soil_Dirt"
    },
    {
      "x": 17,
      "y": 14,
      "z": 13,
      "name": "Rock_Basalt"
    },
    {
      "x": 17,
      "y": 15,
      "z": 13,
      "name": "Rock_Basalt"
    },
    {
      "x": 17,
      "y": 16,
      "z": 13,
      "name": "Rock_Basalt"
    },
    {
      "x": 17,
      "y": 17,
      "z": 13,
      "name": "Rock_Basalt"
    },
    {
      "x": 17,
      "y": 18,
      "z": 13,
      "name": "Rock_Basalt"
    },
    {
      "x": 17,
      "y": 19,
      "z": 13,
      "name": "Rock_Basalt"
    },
    {
      "x": 17,
      "y": 20,
      "z": 13,
      "name": "Rock_Basalt"
    },
    {
      "x": 17,
      "y": 21,
      "z": 13,
      "name": "Rock_Basalt"
    },
    {
      "x": 17,
      "y": 22,
      "z": 13,
      "name": "Rock_Basalt"
    },
    {
      "x": 17,
      "y": 23,
      "z": 13,
      "name": "Rock_Basalt"
    },
    {
      "x": 17,
      "y": 24,
      "z": 13,
      "name": "Rock_Basalt"
    },
    {
      "x": 17,
      "y": 25,
      "z": 13,
      "name": "Rock_Basalt"
    },
    {
      "x": 17,
      "y": 26,
      "z": 13,
      "name": "Rock_Basalt"
    },
    {
      "x": 17,
      "y": 27,
      "z": 13,
      "name": "Soil_Dirt"
    },
    {
      "x": 17,
      "y": 28,
      "z": 13,
      "name": "Soil_Dirt"
    },
    {
      "x": 17,
      "y": 29,
      "z": 13,
      "name": "Soil_Dirt"
    },
    {
      "x": 17,
      "y": 30,
      "z": 13,
      "name": "Soil_Pathway"
    },
    {
      "x": 17,
      "y": 31,
      "z": 13,
      "name": "Soil_Pathway"
    },
    {
      "x": 17,
      "y": 32,
      "z": 13,
      "name": "Soil_Pathway"
    },
    {
      "x": 17,
      "y": 15,
      "z": 14,
      "name": "Rock_Basalt"
    },
    {
      "x": 17,
      "y": 16,
      "z": 14,
      "name": "Rock_Basalt"
    },
    {
      "x": 17,
      "y": 17,
      "z": 14,
      "name": "Rock_Basalt"
    },
    {
      "x": 17,
      "y": 18,
      "z": 14,
      "name": "Rock_Basalt"
    },
    {
      "x": 17,
      "y": 19,
      "z": 14,
      "name": "Rock_Basalt"
    },
    {
      "x": 17,
      "y": 20,
      "z": 14,
      "name": "Rock_Basalt"
    },
    {
      "x": 17,
      "y": 21,
      "z": 14,
      "name": "Rock_Basalt"
    },
    {
      "x": 17,
      "y": 22,
      "z": 14,
      "name": "Rock_Basalt"
    },
    {
      "x": 17,
      "y": 23,
      "z": 14,
      "name": "Rock_Basalt"
    },
    {
      "x": 17,
      "y": 24,
      "z": 14,
      "name": "Rock_Basalt"
    },
    {
      "x": 17,
      "y": 25,
      "z": 14,
      "name": "Rock_Basalt"
    },
    {
      "x": 17,
      "y": 26,
      "z": 14,
      "name": "Rock_Basalt"
    },
    {
      "x": 17,
      "y": 27,
      "z": 14,
      "name": "Rock_Basalt"
    },
    {
      "x": 17,
      "y": 28,
      "z": 14,
      "name": "Soil_Dirt"
    },
    {
      "x": 17,
      "y": 29,
      "z": 14,
      "name": "Soil_Dirt"
    },
    {
      "x": 17,
      "y": 30,
      "z": 14,
      "name": "Soil_Pathway"
    },
    {
      "x": 17,
      "y": 31,
      "z": 14,
      "name": "Soil_Pathway"
    },
    {
      "x": 17,
      "y": 32,
      "z": 14,
      "name": "Soil_Pathway"
    },
    {
      "x": 17,
      "y": 15,
      "z": 15,
      "name": "Rock_Basalt"
    },
    {
      "x": 17,
      "y": 16,
      "z": 15,
      "name": "Rock_Basalt"
    },
    {
      "x": 17,
      "y": 17,
      "z": 15,
      "name": "Rock_Basalt"
    },
    {
      "x": 17,
      "y": 18,
      "z": 15,
      "name": "Rock_Basalt"
    },
    {
      "x": 17,
      "y": 19,
      "z": 15,
      "name": "Rock_Basalt"
    },
    {
      "x": 17,
      "y": 20,
      "z": 15,
      "name": "Rock_Basalt"
    },
    {
      "x": 17,
      "y": 21,
      "z": 15,
      "name": "Rock_Basalt"
    },
    {
      "x": 17,
      "y": 22,
      "z": 15,
      "name": "Rock_Basalt"
    },
    {
      "x": 17,
      "y": 23,
      "z": 15,
      "name": "Rock_Basalt"
    },
    {
      "x": 17,
      "y": 24,
      "z": 15,
      "name": "Rock_Basalt"
    },
    {
      "x": 17,
      "y": 25,
      "z": 15,
      "name": "Rock_Basalt"
    },
    {
      "x": 17,
      "y": 26,
      "z": 15,
      "name": "Rock_Basalt"
    },
    {
      "x": 17,
      "y": 27,
      "z": 15,
      "name": "Rock_Basalt"
    },
    {
      "x": 17,
      "y": 28,
      "z": 15,
      "name": "Soil_Dirt"
    },
    {
      "x": 17,
      "y": 29,
      "z": 15,
      "name": "Soil_Dirt"
    },
    {
      "x": 17,
      "y": 30,
      "z": 15,
      "name": "Soil_Dirt"
    },
    {
      "x": 17,
      "y": 31,
      "z": 15,
      "name": "Soil_Dirt"
    },
    {
      "x": 17,
      "y": 32,
      "z": 15,
      "name": "Soil_Dirt"
    },
    {
      "x": 17,
      "y": 22,
      "z": 16,
      "name": "Rock_Basalt"
    },
    {
      "x": 17,
      "y": 23,
      "z": 16,
      "name": "Rock_Basalt"
    },
    {
      "x": 17,
      "y": 24,
      "z": 16,
      "name": "Rock_Basalt"
    },
    {
      "x": 17,
      "y": 25,
      "z": 16,
      "name": "Rock_Basalt"
    },
    {
      "x": 17,
      "y": 26,
      "z": 16,
      "name": "Rock_Basalt"
    },
    {
      "x": 17,
      "y": 27,
      "z": 16,
      "name": "Rock_Basalt"
    },
    {
      "x": 17,
      "y": 28,
      "z": 16,
      "name": "Rock_Basalt"
    },
    {
      "x": 17,
      "y": 29,
      "z": 16,
      "name": "Soil_Dirt"
    },
    {
      "x": 17,
      "y": 30,
      "z": 16,
      "name": "Soil_Dirt"
    },
    {
      "x": 17,
      "y": 31,
      "z": 16,
      "name": "Soil_Dirt"
    },
    {
      "x": 17,
      "y": 32,
      "z": 16,
      "name": "Soil_Dirt"
    },
    {
      "x": 17,
      "y": 26,
      "z": 17,
      "name": "Rock_Basalt"
    },
    {
      "x": 17,
      "y": 27,
      "z": 17,
      "name": "Rock_Basalt"
    },
    {
      "x": 17,
      "y": 28,
      "z": 17,
      "name": "Rock_Basalt"
    },
    {
      "x": 17,
      "y": 29,
      "z": 17,
      "name": "Rock_Basalt"
    },
    {
      "x": 17,
      "y": 30,
      "z": 17,
      "name": "Rock_Basalt"
    },
    {
      "x": 17,
      "y": 31,
      "z": 17,
      "name": "Soil_Dirt"
    },
    {
      "x": 17,
      "y": 26,
      "z": 18,
      "name": "Rock_Basalt"
    },
    {
      "x": 17,
      "y": 27,
      "z": 18,
      "name": "Rock_Basalt"
    },
    {
      "x": 17,
      "y": 28,
      "z": 18,
      "name": "Rock_Basalt"
    },
    {
      "x": 17,
      "y": 29,
      "z": 18,
      "name": "Rock_Basalt"
    },
    {
      "x": 17,
      "y": 30,
      "z": 18,
      "name": "Rock_Basalt"
    },
    {
      "x": 17,
      "y": 29,
      "z": 19,
      "name": "Rock_Basalt"
    },
    {
      "x": 17,
      "y": 30,
      "z": 19,
      "name": "Rock_Basalt"
    },
    {
      "x": 18,
      "y": 25,
      "z": 10,
      "name": "Rock_Basalt"
    },
    {
      "x": 18,
      "y": 26,
      "z": 10,
      "name": "Rock_Basalt"
    },
    {
      "x": 18,
      "y": 18,
      "z": 11,
      "name": "Rock_Basalt"
    },
    {
      "x": 18,
      "y": 19,
      "z": 11,
      "name": "Rock_Basalt"
    },
    {
      "x": 18,
      "y": 20,
      "z": 11,
      "name": "Rock_Basalt"
    },
    {
      "x": 18,
      "y": 21,
      "z": 11,
      "name": "Rock_Basalt"
    },
    {
      "x": 18,
      "y": 22,
      "z": 11,
      "name": "Rock_Basalt"
    },
    {
      "x": 18,
      "y": 23,
      "z": 11,
      "name": "Rock_Basalt"
    },
    {
      "x": 18,
      "y": 24,
      "z": 11,
      "name": "Rock_Basalt"
    },
    {
      "x": 18,
      "y": 25,
      "z": 11,
      "name": "Rock_Basalt"
    },
    {
      "x": 18,
      "y": 26,
      "z": 11,
      "name": "Rock_Basalt"
    },
    {
      "x": 18,
      "y": 27,
      "z": 11,
      "name": "Rock_Basalt"
    },
    {
      "x": 18,
      "y": 28,
      "z": 11,
      "name": "Soil_Dirt"
    },
    {
      "x": 18,
      "y": 13,
      "z": 12,
      "name": "Rock_Basalt"
    },
    {
      "x": 18,
      "y": 14,
      "z": 12,
      "name": "Rock_Basalt"
    },
    {
      "x": 18,
      "y": 15,
      "z": 12,
      "name": "Rock_Basalt"
    },
    {
      "x": 18,
      "y": 16,
      "z": 12,
      "name": "Rock_Basalt"
    },
    {
      "x": 18,
      "y": 17,
      "z": 12,
      "name": "Rock_Basalt"
    },
    {
      "x": 18,
      "y": 18,
      "z": 12,
      "name": "Rock_Basalt"
    },
    {
      "x": 18,
      "y": 19,
      "z": 12,
      "name": "Rock_Basalt"
    },
    {
      "x": 18,
      "y": 20,
      "z": 12,
      "name": "Rock_Basalt"
    },
    {
      "x": 18,
      "y": 21,
      "z": 12,
      "name": "Rock_Basalt"
    },
    {
      "x": 18,
      "y": 22,
      "z": 12,
      "name": "Rock_Basalt"
    },
    {
      "x": 18,
      "y": 23,
      "z": 12,
      "name": "Rock_Basalt"
    },
    {
      "x": 18,
      "y": 24,
      "z": 12,
      "name": "Rock_Basalt"
    },
    {
      "x": 18,
      "y": 25,
      "z": 12,
      "name": "Rock_Basalt"
    },
    {
      "x": 18,
      "y": 26,
      "z": 12,
      "name": "Rock_Basalt"
    },
    {
      "x": 18,
      "y": 27,
      "z": 12,
      "name": "Rock_Basalt"
    },
    {
      "x": 18,
      "y": 28,
      "z": 12,
      "name": "Soil_Dirt"
    },
    {
      "x": 18,
      "y": 29,
      "z": 12,
      "name": "Soil_Dirt"
    },
    {
      "x": 18,
      "y": 30,
      "z": 12,
      "name": "Soil_Pathway"
    },
    {
      "x": 18,
      "y": 31,
      "z": 12,
      "name": "Plant_Grass_Sharp_Tall"
    },
    {
      "x": 18,
      "y": 32,
      "z": 12,
      "name": "Plant_Grass_Sharp_Tall",
      "filler": 1024
    },
    {
      "x": 18,
      "y": 13,
      "z": 13,
      "name": "Rock_Basalt"
    },
    {
      "x": 18,
      "y": 14,
      "z": 13,
      "name": "Rock_Basalt"
    },
    {
      "x": 18,
      "y": 15,
      "z": 13,
      "name": "Rock_Basalt"
    },
    {
      "x": 18,
      "y": 16,
      "z": 13,
      "name": "Rock_Basalt"
    },
    {
      "x": 18,
      "y": 17,
      "z": 13,
      "name": "Rock_Basalt"
    },
    {
      "x": 18,
      "y": 18,
      "z": 13,
      "name": "Rock_Basalt"
    },
    {
      "x": 18,
      "y": 19,
      "z": 13,
      "name": "Rock_Basalt"
    },
    {
      "x": 18,
      "y": 20,
      "z": 13,
      "name": "Rock_Basalt"
    },
    {
      "x": 18,
      "y": 21,
      "z": 13,
      "name": "Rock_Basalt"
    },
    {
      "x": 18,
      "y": 22,
      "z": 13,
      "name": "Rock_Basalt"
    },
    {
      "x": 18,
      "y": 23,
      "z": 13,
      "name": "Rock_Basalt"
    },
    {
      "x": 18,
      "y": 24,
      "z": 13,
      "name": "Rock_Basalt"
    },
    {
      "x": 18,
      "y": 25,
      "z": 13,
      "name": "Rock_Basalt"
    },
    {
      "x": 18,
      "y": 26,
      "z": 13,
      "name": "Rock_Basalt"
    },
    {
      "x": 18,
      "y": 27,
      "z": 13,
      "name": "Rock_Basalt"
    },
    {
      "x": 18,
      "y": 28,
      "z": 13,
      "name": "Soil_Dirt"
    },
    {
      "x": 18,
      "y": 29,
      "z": 13,
      "name": "Soil_Pathway"
    },
    {
      "x": 18,
      "y": 30,
      "z": 13,
      "name": "Soil_Pathway"
    },
    {
      "x": 18,
      "y": 31,
      "z": 13,
      "name": "Soil_Pathway"
    },
    {
      "x": 18,
      "y": 32,
      "z": 13,
      "name": "Soil_Pathway"
    },
    {
      "x": 18,
      "y": 33,
      "z": 13,
      "name": "Soil_Pathway"
    },
    {
      "x": 18,
      "y": 13,
      "z": 14,
      "name": "Rock_Basalt"
    },
    {
      "x": 18,
      "y": 14,
      "z": 14,
      "name": "Rock_Basalt"
    },
    {
      "x": 18,
      "y": 15,
      "z": 14,
      "name": "Rock_Basalt"
    },
    {
      "x": 18,
      "y": 16,
      "z": 14,
      "name": "Rock_Basalt"
    },
    {
      "x": 18,
      "y": 17,
      "z": 14,
      "name": "Rock_Basalt"
    },
    {
      "x": 18,
      "y": 18,
      "z": 14,
      "name": "Rock_Basalt"
    },
    {
      "x": 18,
      "y": 19,
      "z": 14,
      "name": "Rock_Basalt"
    },
    {
      "x": 18,
      "y": 20,
      "z": 14,
      "name": "Rock_Basalt"
    },
    {
      "x": 18,
      "y": 21,
      "z": 14,
      "name": "Rock_Basalt"
    },
    {
      "x": 18,
      "y": 22,
      "z": 14,
      "name": "Rock_Basalt"
    },
    {
      "x": 18,
      "y": 23,
      "z": 14,
      "name": "Rock_Basalt"
    },
    {
      "x": 18,
      "y": 24,
      "z": 14,
      "name": "Rock_Basalt"
    },
    {
      "x": 18,
      "y": 25,
      "z": 14,
      "name": "Rock_Basalt"
    },
    {
      "x": 18,
      "y": 26,
      "z": 14,
      "name": "Rock_Basalt"
    },
    {
      "x": 18,
      "y": 27,
      "z": 14,
      "name": "Rock_Basalt"
    },
    {
      "x": 18,
      "y": 28,
      "z": 14,
      "name": "Soil_Dirt"
    },
    {
      "x": 18,
      "y": 29,
      "z": 14,
      "name": "Soil_Dirt"
    },
    {
      "x": 18,
      "y": 30,
      "z": 14,
      "name": "Soil_Pathway"
    },
    {
      "x": 18,
      "y": 31,
      "z": 14,
      "name": "Soil_Pathway"
    },
    {
      "x": 18,
      "y": 32,
      "z": 14,
      "name": "Soil_Pathway"
    },
    {
      "x": 18,
      "y": 33,
      "z": 14,
      "name": "Soil_Dirt"
    },
    {
      "x": 18,
      "y": 14,
      "z": 15,
      "name": "Rock_Basalt"
    },
    {
      "x": 18,
      "y": 15,
      "z": 15,
      "name": "Rock_Basalt"
    },
    {
      "x": 18,
      "y": 17,
      "z": 15,
      "name": "Rock_Basalt"
    },
    {
      "x": 18,
      "y": 18,
      "z": 15,
      "name": "Rock_Basalt"
    },
    {
      "x": 18,
      "y": 19,
      "z": 15,
      "name": "Rock_Basalt"
    },
    {
      "x": 18,
      "y": 20,
      "z": 15,
      "name": "Rock_Basalt"
    },
    {
      "x": 18,
      "y": 21,
      "z": 15,
      "name": "Rock_Basalt"
    },
    {
      "x": 18,
      "y": 22,
      "z": 15,
      "name": "Rock_Basalt"
    },
    {
      "x": 18,
      "y": 23,
      "z": 15,
      "name": "Rock_Basalt"
    },
    {
      "x": 18,
      "y": 24,
      "z": 15,
      "name": "Rock_Basalt"
    },
    {
      "x": 18,
      "y": 25,
      "z": 15,
      "name": "Rock_Basalt"
    },
    {
      "x": 18,
      "y": 26,
      "z": 15,
      "name": "Rock_Basalt"
    },
    {
      "x": 18,
      "y": 27,
      "z": 15,
      "name": "Rock_Basalt"
    },
    {
      "x": 18,
      "y": 28,
      "z": 15,
      "name": "Soil_Dirt"
    },
    {
      "x": 18,
      "y": 29,
      "z": 15,
      "name": "Soil_Dirt"
    },
    {
      "x": 18,
      "y": 30,
      "z": 15,
      "name": "Soil_Dirt"
    },
    {
      "x": 18,
      "y": 31,
      "z": 15,
      "name": "Soil_Pathway"
    },
    {
      "x": 18,
      "y": 32,
      "z": 15,
      "name": "Soil_Dirt"
    },
    {
      "x": 18,
      "y": 33,
      "z": 15,
      "name": "Soil_Dirt"
    },
    {
      "x": 18,
      "y": 34,
      "z": 15,
      "name": "Plant_Grass_Sharp_Tall"
    },
    {
      "x": 18,
      "y": 35,
      "z": 15,
      "name": "Plant_Grass_Sharp_Tall",
      "filler": 1024
    },
    {
      "x": 18,
      "y": 20,
      "z": 16,
      "name": "Rock_Basalt"
    },
    {
      "x": 18,
      "y": 21,
      "z": 16,
      "name": "Rock_Basalt"
    },
    {
      "x": 18,
      "y": 22,
      "z": 16,
      "name": "Rock_Basalt"
    },
    {
      "x": 18,
      "y": 23,
      "z": 16,
      "name": "Rock_Basalt"
    },
    {
      "x": 18,
      "y": 24,
      "z": 16,
      "name": "Rock_Basalt"
    },
    {
      "x": 18,
      "y": 25,
      "z": 16,
      "name": "Rock_Basalt"
    },
    {
      "x": 18,
      "y": 26,
      "z": 16,
      "name": "Rock_Basalt"
    },
    {
      "x": 18,
      "y": 27,
      "z": 16,
      "name": "Rock_Basalt"
    },
    {
      "x": 18,
      "y": 28,
      "z": 16,
      "name": "Rock_Basalt"
    },
    {
      "x": 18,
      "y": 29,
      "z": 16,
      "name": "Soil_Dirt"
    },
    {
      "x": 18,
      "y": 30,
      "z": 16,
      "name": "Soil_Dirt"
    },
    {
      "x": 18,
      "y": 31,
      "z": 16,
      "name": "Soil_Dirt"
    },
    {
      "x": 18,
      "y": 32,
      "z": 16,
      "name": "Soil_Dirt"
    },
    {
      "x": 18,
      "y": 33,
      "z": 16,
      "name": "Soil_Dirt"
    },
    {
      "x": 18,
      "y": 23,
      "z": 17,
      "name": "Rock_Basalt"
    },
    {
      "x": 18,
      "y": 24,
      "z": 17,
      "name": "Rock_Basalt"
    },
    {
      "x": 18,
      "y": 25,
      "z": 17,
      "name": "Rock_Basalt"
    },
    {
      "x": 18,
      "y": 26,
      "z": 17,
      "name": "Rock_Basalt"
    },
    {
      "x": 18,
      "y": 27,
      "z": 17,
      "name": "Rock_Basalt"
    },
    {
      "x": 18,
      "y": 28,
      "z": 17,
      "name": "Rock_Basalt"
    },
    {
      "x": 18,
      "y": 29,
      "z": 17,
      "name": "Rock_Basalt"
    },
    {
      "x": 18,
      "y": 30,
      "z": 17,
      "name": "Rock_Basalt"
    },
    {
      "x": 18,
      "y": 31,
      "z": 17,
      "name": "Soil_Dirt"
    },
    {
      "x": 18,
      "y": 32,
      "z": 17,
      "name": "Soil_Dirt"
    },
    {
      "x": 18,
      "y": 33,
      "z": 17,
      "name": "Soil_Dirt"
    },
    {
      "x": 18,
      "y": 25,
      "z": 18,
      "name": "Rock_Basalt"
    },
    {
      "x": 18,
      "y": 26,
      "z": 18,
      "name": "Rock_Basalt"
    },
    {
      "x": 18,
      "y": 27,
      "z": 18,
      "name": "Rock_Basalt"
    },
    {
      "x": 18,
      "y": 28,
      "z": 18,
      "name": "Rock_Basalt"
    },
    {
      "x": 18,
      "y": 29,
      "z": 18,
      "name": "Rock_Basalt"
    },
    {
      "x": 18,
      "y": 30,
      "z": 18,
      "name": "Rock_Basalt"
    },
    {
      "x": 18,
      "y": 31,
      "z": 18,
      "name": "Soil_Dirt"
    },
    {
      "x": 18,
      "y": 32,
      "z": 18,
      "name": "Soil_Dirt"
    },
    {
      "x": 18,
      "y": 29,
      "z": 19,
      "name": "Rock_Basalt"
    },
    {
      "x": 18,
      "y": 30,
      "z": 19,
      "name": "Rock_Basalt"
    },
    {
      "x": 18,
      "y": 31,
      "z": 19,
      "name": "Soil_Dirt"
    },
    {
      "x": 18,
      "y": 32,
      "z": 19,
      "name": "Soil_Dirt"
    },
    {
      "x": 19,
      "y": 25,
      "z": 10,
      "name": "Rock_Basalt"
    },
    {
      "x": 19,
      "y": 26,
      "z": 10,
      "name": "Rock_Basalt"
    },
    {
      "x": 19,
      "y": 27,
      "z": 10,
      "name": "Rock_Basalt"
    },
    {
      "x": 19,
      "y": 28,
      "z": 10,
      "name": "Rock_Basalt"
    },
    {
      "x": 19,
      "y": 29,
      "z": 10,
      "name": "Rock_Basalt"
    },
    {
      "x": 19,
      "y": 23,
      "z": 11,
      "name": "Rock_Basalt"
    },
    {
      "x": 19,
      "y": 24,
      "z": 11,
      "name": "Rock_Basalt"
    },
    {
      "x": 19,
      "y": 25,
      "z": 11,
      "name": "Rock_Basalt"
    },
    {
      "x": 19,
      "y": 26,
      "z": 11,
      "name": "Rock_Basalt"
    },
    {
      "x": 19,
      "y": 27,
      "z": 11,
      "name": "Rock_Basalt"
    },
    {
      "x": 19,
      "y": 28,
      "z": 11,
      "name": "Rock_Basalt"
    },
    {
      "x": 19,
      "y": 29,
      "z": 11,
      "name": "Soil_Dirt"
    },
    {
      "x": 19,
      "y": 30,
      "z": 11,
      "name": "Soil_Dirt"
    },
    {
      "x": 19,
      "y": 31,
      "z": 11,
      "name": "Soil_Dirt"
    },
    {
      "x": 19,
      "y": 12,
      "z": 12,
      "name": "Rock_Basalt"
    },
    {
      "x": 19,
      "y": 13,
      "z": 12,
      "name": "Rock_Basalt"
    },
    {
      "x": 19,
      "y": 14,
      "z": 12,
      "name": "Rock_Basalt"
    },
    {
      "x": 19,
      "y": 15,
      "z": 12,
      "name": "Rock_Basalt"
    },
    {
      "x": 19,
      "y": 16,
      "z": 12,
      "name": "Rock_Basalt"
    },
    {
      "x": 19,
      "y": 17,
      "z": 12,
      "name": "Rock_Basalt"
    },
    {
      "x": 19,
      "y": 18,
      "z": 12,
      "name": "Rock_Basalt"
    },
    {
      "x": 19,
      "y": 19,
      "z": 12,
      "name": "Rock_Basalt"
    },
    {
      "x": 19,
      "y": 20,
      "z": 12,
      "name": "Rock_Basalt"
    },
    {
      "x": 19,
      "y": 21,
      "z": 12,
      "name": "Rock_Basalt"
    },
    {
      "x": 19,
      "y": 22,
      "z": 12,
      "name": "Rock_Basalt"
    },
    {
      "x": 19,
      "y": 23,
      "z": 12,
      "name": "Rock_Basalt"
    },
    {
      "x": 19,
      "y": 24,
      "z": 12,
      "name": "Rock_Basalt"
    },
    {
      "x": 19,
      "y": 25,
      "z": 12,
      "name": "Rock_Basalt"
    },
    {
      "x": 19,
      "y": 26,
      "z": 12,
      "name": "Rock_Basalt"
    },
    {
      "x": 19,
      "y": 27,
      "z": 12,
      "name": "Rock_Basalt"
    },
    {
      "x": 19,
      "y": 28,
      "z": 12,
      "name": "Soil_Dirt"
    },
    {
      "x": 19,
      "y": 29,
      "z": 12,
      "name": "Soil_Dirt"
    },
    {
      "x": 19,
      "y": 30,
      "z": 12,
      "name": "Soil_Pathway"
    },
    {
      "x": 19,
      "y": 31,
      "z": 12,
      "name": "Soil_Pathway"
    },
    {
      "x": 19,
      "y": 32,
      "z": 12,
      "name": "Soil_Pathway"
    },
    {
      "x": 19,
      "y": 33,
      "z": 12,
      "name": "Plant_Grass_Sharp_Tall"
    },
    {
      "x": 19,
      "y": 34,
      "z": 12,
      "name": "Plant_Grass_Sharp_Tall",
      "filler": 1024
    },
    {
      "x": 19,
      "y": 12,
      "z": 13,
      "name": "Rock_Basalt"
    },
    {
      "x": 19,
      "y": 13,
      "z": 13,
      "name": "Rock_Basalt"
    },
    {
      "x": 19,
      "y": 14,
      "z": 13,
      "name": "Rock_Basalt"
    },
    {
      "x": 19,
      "y": 15,
      "z": 13,
      "name": "Rock_Basalt"
    },
    {
      "x": 19,
      "y": 16,
      "z": 13,
      "name": "Rock_Basalt"
    },
    {
      "x": 19,
      "y": 17,
      "z": 13,
      "name": "Rock_Basalt"
    },
    {
      "x": 19,
      "y": 18,
      "z": 13,
      "name": "Rock_Basalt"
    },
    {
      "x": 19,
      "y": 19,
      "z": 13,
      "name": "Rock_Basalt"
    },
    {
      "x": 19,
      "y": 20,
      "z": 13,
      "name": "Rock_Basalt"
    },
    {
      "x": 19,
      "y": 21,
      "z": 13,
      "name": "Rock_Basalt"
    },
    {
      "x": 19,
      "y": 22,
      "z": 13,
      "name": "Rock_Basalt"
    },
    {
      "x": 19,
      "y": 23,
      "z": 13,
      "name": "Rock_Basalt"
    },
    {
      "x": 19,
      "y": 24,
      "z": 13,
      "name": "Rock_Basalt"
    },
    {
      "x": 19,
      "y": 25,
      "z": 13,
      "name": "Rock_Basalt"
    },
    {
      "x": 19,
      "y": 26,
      "z": 13,
      "name": "Rock_Basalt"
    },
    {
      "x": 19,
      "y": 27,
      "z": 13,
      "name": "Rock_Basalt"
    },
    {
      "x": 19,
      "y": 28,
      "z": 13,
      "name": "Soil_Dirt"
    },
    {
      "x": 19,
      "y": 29,
      "z": 13,
      "name": "Soil_Dirt"
    },
    {
      "x": 19,
      "y": 30,
      "z": 13,
      "name": "Soil_Pathway"
    },
    {
      "x": 19,
      "y": 31,
      "z": 13,
      "name": "Soil_Pathway"
    },
    {
      "x": 19,
      "y": 32,
      "z": 13,
      "name": "Soil_Pathway"
    },
    {
      "x": 19,
      "y": 33,
      "z": 13,
      "name": "Soil_Pathway"
    },
    {
      "x": 19,
      "y": 12,
      "z": 14,
      "name": "Rock_Basalt"
    },
    {
      "x": 19,
      "y": 13,
      "z": 14,
      "name": "Rock_Basalt"
    },
    {
      "x": 19,
      "y": 14,
      "z": 14,
      "name": "Rock_Basalt"
    },
    {
      "x": 19,
      "y": 17,
      "z": 14,
      "name": "Rock_Basalt"
    },
    {
      "x": 19,
      "y": 18,
      "z": 14,
      "name": "Rock_Basalt"
    },
    {
      "x": 19,
      "y": 19,
      "z": 14,
      "name": "Rock_Basalt"
    },
    {
      "x": 19,
      "y": 20,
      "z": 14,
      "name": "Rock_Basalt"
    },
    {
      "x": 19,
      "y": 21,
      "z": 14,
      "name": "Rock_Basalt"
    },
    {
      "x": 19,
      "y": 22,
      "z": 14,
      "name": "Rock_Basalt"
    },
    {
      "x": 19,
      "y": 23,
      "z": 14,
      "name": "Rock_Basalt"
    },
    {
      "x": 19,
      "y": 24,
      "z": 14,
      "name": "Rock_Basalt"
    },
    {
      "x": 19,
      "y": 25,
      "z": 14,
      "name": "Rock_Basalt"
    },
    {
      "x": 19,
      "y": 26,
      "z": 14,
      "name": "Rock_Basalt"
    },
    {
      "x": 19,
      "y": 27,
      "z": 14,
      "name": "Rock_Basalt"
    },
    {
      "x": 19,
      "y": 28,
      "z": 14,
      "name": "Soil_Dirt"
    },
    {
      "x": 19,
      "y": 29,
      "z": 14,
      "name": "Soil_Dirt"
    },
    {
      "x": 19,
      "y": 30,
      "z": 14,
      "name": "Soil_Pathway"
    },
    {
      "x": 19,
      "y": 31,
      "z": 14,
      "name": "Soil_Pathway"
    },
    {
      "x": 19,
      "y": 32,
      "z": 14,
      "name": "Soil_Pathway"
    },
    {
      "x": 19,
      "y": 33,
      "z": 14,
      "name": "Soil_Dirt"
    },
    {
      "x": 19,
      "y": 34,
      "z": 14,
      "name": "Soil_Dirt"
    },
    {
      "x": 19,
      "y": 13,
      "z": 15,
      "name": "Rock_Basalt"
    },
    {
      "x": 19,
      "y": 18,
      "z": 15,
      "name": "Rock_Basalt"
    },
    {
      "x": 19,
      "y": 19,
      "z": 15,
      "name": "Rock_Basalt"
    },
    {
      "x": 19,
      "y": 20,
      "z": 15,
      "name": "Rock_Basalt"
    },
    {
      "x": 19,
      "y": 21,
      "z": 15,
      "name": "Rock_Basalt"
    },
    {
      "x": 19,
      "y": 22,
      "z": 15,
      "name": "Rock_Basalt"
    },
    {
      "x": 19,
      "y": 23,
      "z": 15,
      "name": "Rock_Basalt"
    },
    {
      "x": 19,
      "y": 24,
      "z": 15,
      "name": "Rock_Basalt"
    },
    {
      "x": 19,
      "y": 25,
      "z": 15,
      "name": "Rock_Basalt"
    },
    {
      "x": 19,
      "y": 26,
      "z": 15,
      "name": "Rock_Basalt"
    },
    {
      "x": 19,
      "y": 27,
      "z": 15,
      "name": "Rock_Basalt"
    },
    {
      "x": 19,
      "y": 28,
      "z": 15,
      "name": "Rock_Basalt"
    },
    {
      "x": 19,
      "y": 29,
      "z": 15,
      "name": "Soil_Dirt"
    },
    {
      "x": 19,
      "y": 30,
      "z": 15,
      "name": "Soil_Dirt"
    },
    {
      "x": 19,
      "y": 31,
      "z": 15,
      "name": "Soil_Dirt"
    },
    {
      "x": 19,
      "y": 32,
      "z": 15,
      "name": "Soil_Dirt"
    },
    {
      "x": 19,
      "y": 33,
      "z": 15,
      "name": "Soil_Dirt"
    },
    {
      "x": 19,
      "y": 21,
      "z": 16,
      "name": "Rock_Basalt"
    },
    {
      "x": 19,
      "y": 22,
      "z": 16,
      "name": "Rock_Basalt"
    },
    {
      "x": 19,
      "y": 23,
      "z": 16,
      "name": "Rock_Basalt"
    },
    {
      "x": 19,
      "y": 24,
      "z": 16,
      "name": "Rock_Basalt"
    },
    {
      "x": 19,
      "y": 25,
      "z": 16,
      "name": "Rock_Basalt"
    },
    {
      "x": 19,
      "y": 26,
      "z": 16,
      "name": "Rock_Basalt"
    },
    {
      "x": 19,
      "y": 27,
      "z": 16,
      "name": "Rock_Basalt"
    },
    {
      "x": 19,
      "y": 28,
      "z": 16,
      "name": "Rock_Basalt"
    },
    {
      "x": 19,
      "y": 29,
      "z": 16,
      "name": "Rock_Basalt"
    },
    {
      "x": 19,
      "y": 30,
      "z": 16,
      "name": "Soil_Dirt"
    },
    {
      "x": 19,
      "y": 31,
      "z": 16,
      "name": "Soil_Dirt"
    },
    {
      "x": 19,
      "y": 32,
      "z": 16,
      "name": "Soil_Dirt"
    },
    {
      "x": 19,
      "y": 33,
      "z": 16,
      "name": "Soil_Dirt"
    },
    {
      "x": 19,
      "y": 24,
      "z": 17,
      "name": "Rock_Basalt"
    },
    {
      "x": 19,
      "y": 25,
      "z": 17,
      "name": "Rock_Basalt"
    },
    {
      "x": 19,
      "y": 26,
      "z": 17,
      "name": "Rock_Basalt"
    },
    {
      "x": 19,
      "y": 27,
      "z": 17,
      "name": "Rock_Basalt"
    },
    {
      "x": 19,
      "y": 28,
      "z": 17,
      "name": "Rock_Basalt"
    },
    {
      "x": 19,
      "y": 29,
      "z": 17,
      "name": "Rock_Basalt"
    },
    {
      "x": 19,
      "y": 30,
      "z": 17,
      "name": "Soil_Dirt"
    },
    {
      "x": 19,
      "y": 31,
      "z": 17,
      "name": "Soil_Dirt"
    },
    {
      "x": 19,
      "y": 32,
      "z": 17,
      "name": "Soil_Dirt"
    },
    {
      "x": 19,
      "y": 33,
      "z": 17,
      "name": "Soil_Dirt"
    },
    {
      "x": 19,
      "y": 34,
      "z": 17,
      "name": "Plant_Grass_Sharp_Tall"
    },
    {
      "x": 19,
      "y": 35,
      "z": 17,
      "name": "Plant_Grass_Sharp_Tall",
      "filler": 1024
    },
    {
      "x": 19,
      "y": 27,
      "z": 18,
      "name": "Rock_Basalt"
    },
    {
      "x": 19,
      "y": 28,
      "z": 18,
      "name": "Rock_Basalt"
    },
    {
      "x": 19,
      "y": 29,
      "z": 18,
      "name": "Rock_Basalt"
    },
    {
      "x": 19,
      "y": 30,
      "z": 18,
      "name": "Soil_Dirt"
    },
    {
      "x": 19,
      "y": 31,
      "z": 18,
      "name": "Soil_Dirt"
    },
    {
      "x": 19,
      "y": 32,
      "z": 18,
      "name": "Soil_Dirt"
    },
    {
      "x": 19,
      "y": 33,
      "z": 18,
      "name": "Soil_Dirt"
    },
    {
      "x": 19,
      "y": 28,
      "z": 19,
      "name": "Rock_Basalt"
    },
    {
      "x": 19,
      "y": 29,
      "z": 19,
      "name": "Rock_Basalt"
    },
    {
      "x": 19,
      "y": 30,
      "z": 19,
      "name": "Soil_Dirt"
    },
    {
      "x": 19,
      "y": 31,
      "z": 19,
      "name": "Soil_Dirt"
    },
    {
      "x": 19,
      "y": 32,
      "z": 19,
      "name": "Soil_Dirt"
    },
    {
      "x": 19,
      "y": 33,
      "z": 19,
      "name": "Soil_Dirt"
    },
    {
      "x": 19,
      "y": 30,
      "z": 20,
      "name": "Rock_Basalt"
    },
    {
      "x": 19,
      "y": 31,
      "z": 20,
      "name": "Soil_Dirt"
    },
    {
      "x": 19,
      "y": 32,
      "z": 20,
      "name": "Soil_Dirt"
    },
    {
      "x": 19,
      "y": 33,
      "z": 20,
      "name": "Soil_Dirt"
    },
    {
      "x": 20,
      "y": 27,
      "z": 10,
      "name": "Rock_Basalt"
    },
    {
      "x": 20,
      "y": 28,
      "z": 10,
      "name": "Rock_Basalt"
    },
    {
      "x": 20,
      "y": 29,
      "z": 10,
      "name": "Rock_Basalt"
    },
    {
      "x": 20,
      "y": 30,
      "z": 10,
      "name": "Rock_Basalt"
    },
    {
      "x": 20,
      "y": 31,
      "z": 10,
      "name": "Soil_Dirt"
    },
    {
      "x": 20,
      "y": 32,
      "z": 10,
      "name": "Soil_Dirt"
    },
    {
      "x": 20,
      "y": 33,
      "z": 10,
      "name": "Soil_Dirt"
    },
    {
      "x": 20,
      "y": 24,
      "z": 11,
      "name": "Rock_Basalt"
    },
    {
      "x": 20,
      "y": 25,
      "z": 11,
      "name": "Rock_Basalt"
    },
    {
      "x": 20,
      "y": 26,
      "z": 11,
      "name": "Rock_Basalt"
    },
    {
      "x": 20,
      "y": 27,
      "z": 11,
      "name": "Rock_Basalt"
    },
    {
      "x": 20,
      "y": 28,
      "z": 11,
      "name": "Rock_Basalt"
    },
    {
      "x": 20,
      "y": 29,
      "z": 11,
      "name": "Rock_Basalt"
    },
    {
      "x": 20,
      "y": 30,
      "z": 11,
      "name": "Soil_Dirt"
    },
    {
      "x": 20,
      "y": 31,
      "z": 11,
      "name": "Soil_Dirt"
    },
    {
      "x": 20,
      "y": 32,
      "z": 11,
      "name": "Soil_Dirt"
    },
    {
      "x": 20,
      "y": 33,
      "z": 11,
      "name": "Soil_Pathway"
    },
    {
      "x": 20,
      "y": 34,
      "z": 11,
      "name": "Soil_Pathway"
    },
    {
      "x": 20,
      "y": 12,
      "z": 12,
      "name": "Rock_Basalt"
    },
    {
      "x": 20,
      "y": 13,
      "z": 12,
      "name": "Rock_Basalt"
    },
    {
      "x": 20,
      "y": 17,
      "z": 12,
      "name": "Rock_Basalt"
    },
    {
      "x": 20,
      "y": 18,
      "z": 12,
      "name": "Rock_Basalt"
    },
    {
      "x": 20,
      "y": 21,
      "z": 12,
      "name": "Rock_Basalt"
    },
    {
      "x": 20,
      "y": 22,
      "z": 12,
      "name": "Rock_Basalt"
    },
    {
      "x": 20,
      "y": 23,
      "z": 12,
      "name": "Rock_Basalt"
    },
    {
      "x": 20,
      "y": 24,
      "z": 12,
      "name": "Rock_Basalt"
    },
    {
      "x": 20,
      "y": 25,
      "z": 12,
      "name": "Rock_Basalt"
    },
    {
      "x": 20,
      "y": 26,
      "z": 12,
      "name": "Rock_Basalt"
    },
    {
      "x": 20,
      "y": 27,
      "z": 12,
      "name": "Rock_Basalt"
    },
    {
      "x": 20,
      "y": 28,
      "z": 12,
      "name": "Rock_Basalt"
    },
    {
      "x": 20,
      "y": 29,
      "z": 12,
      "name": "Soil_Dirt"
    },
    {
      "x": 20,
      "y": 30,
      "z": 12,
      "name": "Soil_Dirt"
    },
    {
      "x": 20,
      "y": 31,
      "z": 12,
      "name": "Soil_Dirt"
    },
    {
      "x": 20,
      "y": 32,
      "z": 12,
      "name": "Soil_Pathway"
    },
    {
      "x": 20,
      "y": 33,
      "z": 12,
      "name": "Soil_Pathway"
    },
    {
      "x": 20,
      "y": 34,
      "z": 12,
      "name": "Soil_Pathway"
    },
    {
      "x": 20,
      "y": 11,
      "z": 13,
      "name": "Rock_Basalt"
    },
    {
      "x": 20,
      "y": 12,
      "z": 13,
      "name": "Rock_Basalt"
    },
    {
      "x": 20,
      "y": 13,
      "z": 13,
      "name": "Rock_Basalt"
    },
    {
      "x": 20,
      "y": 14,
      "z": 13,
      "name": "Rock_Basalt"
    },
    {
      "x": 20,
      "y": 15,
      "z": 13,
      "name": "Rock_Basalt"
    },
    {
      "x": 20,
      "y": 17,
      "z": 13,
      "name": "Rock_Basalt"
    },
    {
      "x": 20,
      "y": 18,
      "z": 13,
      "name": "Rock_Basalt"
    },
    {
      "x": 20,
      "y": 19,
      "z": 13,
      "name": "Rock_Basalt"
    },
    {
      "x": 20,
      "y": 20,
      "z": 13,
      "name": "Rock_Basalt"
    },
    {
      "x": 20,
      "y": 21,
      "z": 13,
      "name": "Rock_Basalt"
    },
    {
      "x": 20,
      "y": 22,
      "z": 13,
      "name": "Rock_Basalt"
    },
    {
      "x": 20,
      "y": 23,
      "z": 13,
      "name": "Rock_Basalt"
    },
    {
      "x": 20,
      "y": 24,
      "z": 13,
      "name": "Rock_Basalt"
    },
    {
      "x": 20,
      "y": 25,
      "z": 13,
      "name": "Rock_Basalt"
    },
    {
      "x": 20,
      "y": 26,
      "z": 13,
      "name": "Rock_Basalt"
    },
    {
      "x": 20,
      "y": 27,
      "z": 13,
      "name": "Rock_Basalt"
    },
    {
      "x": 20,
      "y": 28,
      "z": 13,
      "name": "Rock_Basalt"
    },
    {
      "x": 20,
      "y": 29,
      "z": 13,
      "name": "Soil_Dirt"
    },
    {
      "x": 20,
      "y": 30,
      "z": 13,
      "name": "Soil_Dirt"
    },
    {
      "x": 20,
      "y": 31,
      "z": 13,
      "name": "Soil_Pathway"
    },
    {
      "x": 20,
      "y": 32,
      "z": 13,
      "name": "Soil_Dirt"
    },
    {
      "x": 20,
      "y": 33,
      "z": 13,
      "name": "Soil_Pathway"
    },
    {
      "x": 20,
      "y": 34,
      "z": 13,
      "name": "Rock_Stone"
    },
    {
      "x": 20,
      "y": 11,
      "z": 14,
      "name": "Rock_Basalt"
    },
    {
      "x": 20,
      "y": 12,
      "z": 14,
      "name": "Rock_Basalt"
    },
    {
      "x": 20,
      "y": 18,
      "z": 14,
      "name": "Rock_Basalt"
    },
    {
      "x": 20,
      "y": 19,
      "z": 14,
      "name": "Rock_Basalt"
    },
    {
      "x": 20,
      "y": 20,
      "z": 14,
      "name": "Rock_Basalt"
    },
    {
      "x": 20,
      "y": 21,
      "z": 14,
      "name": "Rock_Basalt"
    },
    {
      "x": 20,
      "y": 22,
      "z": 14,
      "name": "Rock_Basalt"
    },
    {
      "x": 20,
      "y": 23,
      "z": 14,
      "name": "Rock_Basalt"
    },
    {
      "x": 20,
      "y": 24,
      "z": 14,
      "name": "Rock_Basalt"
    },
    {
      "x": 20,
      "y": 25,
      "z": 14,
      "name": "Rock_Basalt"
    },
    {
      "x": 20,
      "y": 26,
      "z": 14,
      "name": "Rock_Basalt"
    },
    {
      "x": 20,
      "y": 27,
      "z": 14,
      "name": "Rock_Basalt"
    },
    {
      "x": 20,
      "y": 28,
      "z": 14,
      "name": "Rock_Basalt"
    },
    {
      "x": 20,
      "y": 29,
      "z": 14,
      "name": "Soil_Dirt"
    },
    {
      "x": 20,
      "y": 30,
      "z": 14,
      "name": "Soil_Dirt"
    },
    {
      "x": 20,
      "y": 31,
      "z": 14,
      "name": "Soil_Dirt"
    },
    {
      "x": 20,
      "y": 32,
      "z": 14,
      "name": "Soil_Dirt"
    },
    {
      "x": 20,
      "y": 33,
      "z": 14,
      "name": "Soil_Dirt"
    },
    {
      "x": 20,
      "y": 34,
      "z": 14,
      "name": "Soil_Pathway"
    },
    {
      "x": 20,
      "y": 12,
      "z": 15,
      "name": "Rock_Basalt"
    },
    {
      "x": 20,
      "y": 22,
      "z": 15,
      "name": "Rock_Basalt"
    },
    {
      "x": 20,
      "y": 23,
      "z": 15,
      "name": "Rock_Basalt"
    },
    {
      "x": 20,
      "y": 24,
      "z": 15,
      "name": "Rock_Basalt"
    },
    {
      "x": 20,
      "y": 25,
      "z": 15,
      "name": "Rock_Basalt"
    },
    {
      "x": 20,
      "y": 26,
      "z": 15,
      "name": "Rock_Basalt"
    },
    {
      "x": 20,
      "y": 27,
      "z": 15,
      "name": "Rock_Basalt"
    },
    {
      "x": 20,
      "y": 28,
      "z": 15,
      "name": "Rock_Basalt"
    },
    {
      "x": 20,
      "y": 29,
      "z": 15,
      "name": "Rock_Basalt"
    },
    {
      "x": 20,
      "y": 30,
      "z": 15,
      "name": "Soil_Dirt"
    },
    {
      "x": 20,
      "y": 31,
      "z": 15,
      "name": "Soil_Dirt"
    },
    {
      "x": 20,
      "y": 32,
      "z": 15,
      "name": "Soil_Dirt"
    },
    {
      "x": 20,
      "y": 33,
      "z": 15,
      "name": "Soil_Dirt"
    },
    {
      "x": 20,
      "y": 34,
      "z": 15,
      "name": "Plant_Grass_Sharp_Tall"
    },
    {
      "x": 20,
      "y": 35,
      "z": 15,
      "name": "Plant_Grass_Sharp_Tall",
      "filler": 1024
    },
    {
      "x": 20,
      "y": 26,
      "z": 16,
      "name": "Rock_Basalt"
    },
    {
      "x": 20,
      "y": 27,
      "z": 16,
      "name": "Rock_Basalt"
    },
    {
      "x": 20,
      "y": 28,
      "z": 16,
      "name": "Rock_Basalt"
    },
    {
      "x": 20,
      "y": 29,
      "z": 16,
      "name": "Rock_Basalt"
    },
    {
      "x": 20,
      "y": 30,
      "z": 16,
      "name": "Soil_Dirt"
    },
    {
      "x": 20,
      "y": 31,
      "z": 16,
      "name": "Soil_Dirt"
    },
    {
      "x": 20,
      "y": 32,
      "z": 16,
      "name": "Soil_Dirt"
    },
    {
      "x": 20,
      "y": 33,
      "z": 16,
      "name": "Soil_Dirt"
    },
    {
      "x": 20,
      "y": 27,
      "z": 17,
      "name": "Rock_Basalt"
    },
    {
      "x": 20,
      "y": 28,
      "z": 17,
      "name": "Rock_Basalt"
    },
    {
      "x": 20,
      "y": 29,
      "z": 17,
      "name": "Rock_Basalt"
    },
    {
      "x": 20,
      "y": 30,
      "z": 17,
      "name": "Soil_Dirt"
    },
    {
      "x": 20,
      "y": 31,
      "z": 17,
      "name": "Soil_Dirt"
    },
    {
      "x": 20,
      "y": 32,
      "z": 17,
      "name": "Soil_Dirt"
    },
    {
      "x": 20,
      "y": 33,
      "z": 17,
      "name": "Soil_Dirt"
    },
    {
      "x": 20,
      "y": 34,
      "z": 17,
      "name": "Plant_Grass_Sharp_Tall"
    },
    {
      "x": 20,
      "y": 35,
      "z": 17,
      "name": "Plant_Grass_Sharp_Tall",
      "filler": 1024
    },
    {
      "x": 20,
      "y": 28,
      "z": 18,
      "name": "Rock_Basalt"
    },
    {
      "x": 20,
      "y": 29,
      "z": 18,
      "name": "Rock_Basalt"
    },
    {
      "x": 20,
      "y": 30,
      "z": 18,
      "name": "Soil_Dirt"
    },
    {
      "x": 20,
      "y": 31,
      "z": 18,
      "name": "Soil_Dirt"
    },
    {
      "x": 20,
      "y": 32,
      "z": 18,
      "name": "Soil_Dirt"
    },
    {
      "x": 20,
      "y": 33,
      "z": 18,
      "name": "Soil_Dirt"
    },
    {
      "x": 20,
      "y": 34,
      "z": 18,
      "name": "Plant_Grass_Sharp_Tall"
    },
    {
      "x": 20,
      "y": 35,
      "z": 18,
      "name": "Plant_Grass_Sharp_Tall",
      "filler": 1024
    },
    {
      "x": 20,
      "y": 29,
      "z": 19,
      "name": "Rock_Basalt"
    },
    {
      "x": 20,
      "y": 30,
      "z": 19,
      "name": "Soil_Dirt"
    },
    {
      "x": 20,
      "y": 31,
      "z": 19,
      "name": "Soil_Dirt"
    },
    {
      "x": 20,
      "y": 32,
      "z": 19,
      "name": "Soil_Dirt"
    },
    {
      "x": 20,
      "y": 33,
      "z": 19,
      "name": "Soil_Dirt"
    },
    {
      "x": 20,
      "y": 29,
      "z": 20,
      "name": "Rock_Basalt"
    },
    {
      "x": 20,
      "y": 30,
      "z": 20,
      "name": "Soil_Dirt"
    },
    {
      "x": 20,
      "y": 31,
      "z": 20,
      "name": "Soil_Dirt"
    },
    {
      "x": 20,
      "y": 32,
      "z": 20,
      "name": "Soil_Dirt"
    },
    {
      "x": 20,
      "y": 33,
      "z": 20,
      "name": "Soil_Dirt"
    },
    {
      "x": 20,
      "y": 30,
      "z": 21,
      "name": "Soil_Dirt"
    },
    {
      "x": 20,
      "y": 31,
      "z": 21,
      "name": "Soil_Dirt"
    },
    {
      "x": 20,
      "y": 32,
      "z": 21,
      "name": "Soil_Dirt"
    },
    {
      "x": 21,
      "y": 31,
      "z": 9,
      "name": "Rock_Basalt"
    },
    {
      "x": 21,
      "y": 32,
      "z": 9,
      "name": "Soil_Dirt"
    },
    {
      "x": 21,
      "y": 33,
      "z": 9,
      "name": "Soil_Dirt"
    },
    {
      "x": 21,
      "y": 34,
      "z": 9,
      "name": "Soil_Grass"
    },
    {
      "x": 21,
      "y": 29,
      "z": 10,
      "name": "Rock_Basalt"
    },
    {
      "x": 21,
      "y": 30,
      "z": 10,
      "name": "Rock_Basalt"
    },
    {
      "x": 21,
      "y": 31,
      "z": 10,
      "name": "Soil_Dirt"
    },
    {
      "x": 21,
      "y": 32,
      "z": 10,
      "name": "Soil_Dirt"
    },
    {
      "x": 21,
      "y": 33,
      "z": 10,
      "name": "Soil_Dirt"
    },
    {
      "x": 21,
      "y": 34,
      "z": 10,
      "name": "Soil_Dirt"
    },
    {
      "x": 21,
      "y": 35,
      "z": 10,
      "name": "Plant_Grass_Sharp_Tall"
    },
    {
      "x": 21,
      "y": 36,
      "z": 10,
      "name": "Plant_Grass_Sharp_Tall",
      "filler": 1024
    },
    {
      "x": 21,
      "y": 28,
      "z": 11,
      "name": "Rock_Basalt"
    },
    {
      "x": 21,
      "y": 29,
      "z": 11,
      "name": "Rock_Basalt"
    },
    {
      "x": 21,
      "y": 30,
      "z": 11,
      "name": "Rock_Basalt"
    },
    {
      "x": 21,
      "y": 31,
      "z": 11,
      "name": "Soil_Dirt"
    },
    {
      "x": 21,
      "y": 32,
      "z": 11,
      "name": "Soil_Dirt"
    },
    {
      "x": 21,
      "y": 33,
      "z": 11,
      "name": "Soil_Pathway"
    },
    {
      "x": 21,
      "y": 34,
      "z": 11,
      "name": "Soil_Pathway"
    },
    {
      "x": 21,
      "y": 26,
      "z": 12,
      "name": "Rock_Basalt"
    },
    {
      "x": 21,
      "y": 27,
      "z": 12,
      "name": "Rock_Basalt"
    },
    {
      "x": 21,
      "y": 28,
      "z": 12,
      "name": "Rock_Basalt"
    },
    {
      "x": 21,
      "y": 29,
      "z": 12,
      "name": "Rock_Basalt"
    },
    {
      "x": 21,
      "y": 30,
      "z": 12,
      "name": "Rock_Basalt"
    },
    {
      "x": 21,
      "y": 31,
      "z": 12,
      "name": "Soil_Dirt"
    },
    {
      "x": 21,
      "y": 32,
      "z": 12,
      "name": "Soil_Dirt"
    },
    {
      "x": 21,
      "y": 33,
      "z": 12,
      "name": "Rock_Stone"
    },
    {
      "x": 21,
      "y": 34,
      "z": 12,
      "name": "Rock_Stone"
    },
    {
      "x": 21,
      "y": 35,
      "z": 12,
      "name": "Rock_Stone"
    },
    {
      "x": 21,
      "y": 11,
      "z": 13,
      "name": "Rock_Basalt"
    },
    {
      "x": 21,
      "y": 26,
      "z": 13,
      "name": "Rock_Basalt"
    },
    {
      "x": 21,
      "y": 27,
      "z": 13,
      "name": "Rock_Basalt"
    },
    {
      "x": 21,
      "y": 28,
      "z": 13,
      "name": "Rock_Basalt"
    },
    {
      "x": 21,
      "y": 29,
      "z": 13,
      "name": "Rock_Basalt"
    },
    {
      "x": 21,
      "y": 30,
      "z": 13,
      "name": "Rock_Basalt"
    },
    {
      "x": 21,
      "y": 31,
      "z": 13,
      "name": "Soil_Dirt"
    },
    {
      "x": 21,
      "y": 32,
      "z": 13,
      "name": "Soil_Dirt"
    },
    {
      "x": 21,
      "y": 33,
      "z": 13,
      "name": "Rock_Stone"
    },
    {
      "x": 21,
      "y": 34,
      "z": 13,
      "name": "Rock_Stone"
    },
    {
      "x": 21,
      "y": 35,
      "z": 13,
      "name": "Rock_Stone"
    },
    {
      "x": 21,
      "y": 36,
      "z": 13,
      "name": "Rock_Stone_Mossy"
    },
    {
      "x": 21,
      "y": 11,
      "z": 14,
      "name": "Rock_Basalt"
    },
    {
      "x": 21,
      "y": 12,
      "z": 14,
      "name": "Rock_Basalt"
    },
    {
      "x": 21,
      "y": 26,
      "z": 14,
      "name": "Rock_Basalt"
    },
    {
      "x": 21,
      "y": 27,
      "z": 14,
      "name": "Rock_Basalt"
    },
    {
      "x": 21,
      "y": 28,
      "z": 14,
      "name": "Rock_Basalt"
    },
    {
      "x": 21,
      "y": 29,
      "z": 14,
      "name": "Rock_Basalt"
    },
    {
      "x": 21,
      "y": 30,
      "z": 14,
      "name": "Rock_Basalt"
    },
    {
      "x": 21,
      "y": 31,
      "z": 14,
      "name": "Soil_Dirt"
    },
    {
      "x": 21,
      "y": 32,
      "z": 14,
      "name": "Soil_Dirt"
    },
    {
      "x": 21,
      "y": 33,
      "z": 14,
      "name": "Rock_Stone"
    },
    {
      "x": 21,
      "y": 34,
      "z": 14,
      "name": "Rock_Stone"
    },
    {
      "x": 21,
      "y": 35,
      "z": 14,
      "name": "Rock_Stone_Mossy"
    },
    {
      "x": 21,
      "y": 36,
      "z": 14,
      "name": "Rock_Stone_Mossy"
    },
    {
      "x": 21,
      "y": 26,
      "z": 15,
      "name": "Rock_Basalt"
    },
    {
      "x": 21,
      "y": 27,
      "z": 15,
      "name": "Rock_Basalt"
    },
    {
      "x": 21,
      "y": 28,
      "z": 15,
      "name": "Rock_Basalt"
    },
    {
      "x": 21,
      "y": 29,
      "z": 15,
      "name": "Rock_Basalt"
    },
    {
      "x": 21,
      "y": 30,
      "z": 15,
      "name": "Rock_Basalt"
    },
    {
      "x": 21,
      "y": 31,
      "z": 15,
      "name": "Soil_Dirt"
    },
    {
      "x": 21,
      "y": 32,
      "z": 15,
      "name": "Soil_Dirt"
    },
    {
      "x": 21,
      "y": 33,
      "z": 15,
      "name": "Rock_Stone"
    },
    {
      "x": 21,
      "y": 34,
      "z": 15,
      "name": "Rock_Stone"
    },
    {
      "x": 21,
      "y": 35,
      "z": 15,
      "name": "Rock_Stone"
    },
    {
      "x": 21,
      "y": 27,
      "z": 16,
      "name": "Rock_Basalt"
    },
    {
      "x": 21,
      "y": 28,
      "z": 16,
      "name": "Rock_Basalt"
    },
    {
      "x": 21,
      "y": 29,
      "z": 16,
      "name": "Rock_Basalt"
    },
    {
      "x": 21,
      "y": 30,
      "z": 16,
      "name": "Soil_Dirt"
    },
    {
      "x": 21,
      "y": 31,
      "z": 16,
      "name": "Soil_Dirt"
    },
    {
      "x": 21,
      "y": 32,
      "z": 16,
      "name": "Soil_Dirt"
    },
    {
      "x": 21,
      "y": 33,
      "z": 16,
      "name": "Rock_Stone"
    },
    {
      "x": 21,
      "y": 34,
      "z": 16,
      "name": "Rock_Stone"
    },
    {
      "x": 21,
      "y": 35,
      "z": 16,
      "name": "Rock_Stone"
    },
    {
      "x": 21,
      "y": 28,
      "z": 17,
      "name": "Rock_Basalt"
    },
    {
      "x": 21,
      "y": 29,
      "z": 17,
      "name": "Rock_Basalt"
    },
    {
      "x": 21,
      "y": 30,
      "z": 17,
      "name": "Soil_Dirt"
    },
    {
      "x": 21,
      "y": 31,
      "z": 17,
      "name": "Soil_Dirt"
    },
    {
      "x": 21,
      "y": 32,
      "z": 17,
      "name": "Soil_Dirt"
    },
    {
      "x": 21,
      "y": 33,
      "z": 17,
      "name": "Soil_Dirt"
    },
    {
      "x": 21,
      "y": 28,
      "z": 18,
      "name": "Rock_Basalt"
    },
    {
      "x": 21,
      "y": 29,
      "z": 18,
      "name": "Soil_Dirt"
    },
    {
      "x": 21,
      "y": 30,
      "z": 18,
      "name": "Soil_Dirt"
    },
    {
      "x": 21,
      "y": 31,
      "z": 18,
      "name": "Soil_Dirt"
    },
    {
      "x": 21,
      "y": 32,
      "z": 18,
      "name": "Soil_Dirt"
    },
    {
      "x": 21,
      "y": 33,
      "z": 18,
      "name": "Soil_Dirt"
    },
    {
      "x": 21,
      "y": 29,
      "z": 19,
      "name": "Rock_Basalt"
    },
    {
      "x": 21,
      "y": 30,
      "z": 19,
      "name": "Soil_Dirt"
    },
    {
      "x": 21,
      "y": 31,
      "z": 19,
      "name": "Soil_Dirt"
    },
    {
      "x": 21,
      "y": 32,
      "z": 19,
      "name": "Soil_Dirt"
    },
    {
      "x": 21,
      "y": 33,
      "z": 19,
      "name": "Soil_Dirt"
    },
    {
      "x": 21,
      "y": 29,
      "z": 20,
      "name": "Soil_Dirt"
    },
    {
      "x": 21,
      "y": 30,
      "z": 20,
      "name": "Soil_Dirt"
    },
    {
      "x": 21,
      "y": 31,
      "z": 20,
      "name": "Soil_Dirt"
    },
    {
      "x": 21,
      "y": 32,
      "z": 20,
      "name": "Soil_Dirt"
    },
    {
      "x": 21,
      "y": 29,
      "z": 21,
      "name": "Soil_Dirt"
    },
    {
      "x": 21,
      "y": 30,
      "z": 21,
      "name": "Soil_Dirt"
    },
    {
      "x": 21,
      "y": 31,
      "z": 21,
      "name": "Soil_Dirt"
    },
    {
      "x": 21,
      "y": 32,
      "z": 21,
      "name": "Soil_Dirt"
    },
    {
      "x": 21,
      "y": 31,
      "z": 22,
      "name": "Soil_Dirt"
    },
    {
      "x": 21,
      "y": 32,
      "z": 22,
      "name": "Soil_Dirt"
    },
    {
      "x": 22,
      "y": 32,
      "z": 8,
      "name": "Soil_Dirt"
    },
    {
      "x": 22,
      "y": 33,
      "z": 8,
      "name": "Soil_Dirt"
    },
    {
      "x": 22,
      "y": 30,
      "z": 9,
      "name": "Rock_Basalt"
    },
    {
      "x": 22,
      "y": 31,
      "z": 9,
      "name": "Soil_Dirt"
    },
    {
      "x": 22,
      "y": 32,
      "z": 9,
      "name": "Soil_Dirt"
    },
    {
      "x": 22,
      "y": 33,
      "z": 9,
      "name": "Soil_Dirt"
    },
    {
      "x": 22,
      "y": 34,
      "z": 9,
      "name": "Soil_Grass"
    },
    {
      "x": 22,
      "y": 29,
      "z": 10,
      "name": "Rock_Basalt"
    },
    {
      "x": 22,
      "y": 30,
      "z": 10,
      "name": "Rock_Basalt"
    },
    {
      "x": 22,
      "y": 31,
      "z": 10,
      "name": "Soil_Dirt"
    },
    {
      "x": 22,
      "y": 32,
      "z": 10,
      "name": "Soil_Dirt"
    },
    {
      "x": 22,
      "y": 33,
      "z": 10,
      "name": "Soil_Dirt"
    },
    {
      "x": 22,
      "y": 34,
      "z": 10,
      "name": "Soil_Grass"
    },
    {
      "x": 22,
      "y": 28,
      "z": 11,
      "name": "Rock_Basalt"
    },
    {
      "x": 22,
      "y": 29,
      "z": 11,
      "name": "Rock_Basalt"
    },
    {
      "x": 22,
      "y": 30,
      "z": 11,
      "name": "Rock_Basalt"
    },
    {
      "x": 22,
      "y": 31,
      "z": 11,
      "name": "Soil_Dirt"
    },
    {
      "x": 22,
      "y": 32,
      "z": 11,
      "name": "Soil_Dirt"
    },
    {
      "x": 22,
      "y": 33,
      "z": 11,
      "name": "Soil_Dirt"
    },
    {
      "x": 22,
      "y": 34,
      "z": 11,
      "name": "Rock_Stone"
    },
    {
      "x": 22,
      "y": 35,
      "z": 11,
      "name": "Rubble_Basalt"
    },
    {
      "x": 22,
      "y": 27,
      "z": 12,
      "name": "Rock_Basalt"
    },
    {
      "x": 22,
      "y": 28,
      "z": 12,
      "name": "Rock_Basalt"
    },
    {
      "x": 22,
      "y": 29,
      "z": 12,
      "name": "Rock_Basalt"
    },
    {
      "x": 22,
      "y": 30,
      "z": 12,
      "name": "Rock_Basalt"
    },
    {
      "x": 22,
      "y": 31,
      "z": 12,
      "name": "Soil_Dirt"
    },
    {
      "x": 22,
      "y": 32,
      "z": 12,
      "name": "Soil_Dirt"
    },
    {
      "x": 22,
      "y": 33,
      "z": 12,
      "name": "Rock_Stone"
    },
    {
      "x": 22,
      "y": 34,
      "z": 12,
      "name": "Rock_Stone"
    },
    {
      "x": 22,
      "y": 35,
      "z": 12,
      "name": "Rock_Stone"
    },
    {
      "x": 22,
      "y": 36,
      "z": 12,
      "name": "Rock_Stone"
    },
    {
      "x": 22,
      "y": 10,
      "z": 13,
      "name": "Rock_Basalt"
    },
    {
      "x": 22,
      "y": 26,
      "z": 13,
      "name": "Rock_Basalt"
    },
    {
      "x": 22,
      "y": 27,
      "z": 13,
      "name": "Rock_Basalt"
    },
    {
      "x": 22,
      "y": 28,
      "z": 13,
      "name": "Rock_Basalt"
    },
    {
      "x": 22,
      "y": 29,
      "z": 13,
      "name": "Rock_Basalt"
    },
    {
      "x": 22,
      "y": 30,
      "z": 13,
      "name": "Rock_Basalt"
    },
    {
      "x": 22,
      "y": 31,
      "z": 13,
      "name": "Soil_Dirt"
    },
    {
      "x": 22,
      "y": 32,
      "z": 13,
      "name": "Rock_Stone"
    },
    {
      "x": 22,
      "y": 33,
      "z": 13,
      "name": "Rock_Stone"
    },
    {
      "x": 22,
      "y": 34,
      "z": 13,
      "name": "Rock_Stone"
    },
    {
      "x": 22,
      "y": 35,
      "z": 13,
      "name": "Rock_Stone"
    },
    {
      "x": 22,
      "y": 36,
      "z": 13,
      "name": "Rock_Stone"
    },
    {
      "x": 22,
      "y": 37,
      "z": 13,
      "name": "Rock_Stone"
    },
    {
      "x": 22,
      "y": 26,
      "z": 14,
      "name": "Rock_Basalt"
    },
    {
      "x": 22,
      "y": 27,
      "z": 14,
      "name": "Rock_Basalt"
    },
    {
      "x": 22,
      "y": 28,
      "z": 14,
      "name": "Rock_Basalt"
    },
    {
      "x": 22,
      "y": 29,
      "z": 14,
      "name": "Rock_Basalt"
    },
    {
      "x": 22,
      "y": 30,
      "z": 14,
      "name": "Rock_Basalt"
    },
    {
      "x": 22,
      "y": 31,
      "z": 14,
      "name": "Rock_Basalt"
    },
    {
      "x": 22,
      "y": 32,
      "z": 14,
      "name": "Soil_Dirt"
    },
    {
      "x": 22,
      "y": 33,
      "z": 14,
      "name": "Rock_Stone"
    },
    {
      "x": 22,
      "y": 34,
      "z": 14,
      "name": "Rock_Stone"
    },
    {
      "x": 22,
      "y": 35,
      "z": 14,
      "name": "Rock_Stone"
    },
    {
      "x": 22,
      "y": 36,
      "z": 14,
      "name": "Rock_Stone_Mossy"
    },
    {
      "x": 22,
      "y": 37,
      "z": 14,
      "name": "Rock_Stone"
    },
    {
      "x": 22,
      "y": 26,
      "z": 15,
      "name": "Rock_Basalt"
    },
    {
      "x": 22,
      "y": 27,
      "z": 15,
      "name": "Rock_Basalt"
    },
    {
      "x": 22,
      "y": 28,
      "z": 15,
      "name": "Rock_Basalt"
    },
    {
      "x": 22,
      "y": 29,
      "z": 15,
      "name": "Rock_Basalt"
    },
    {
      "x": 22,
      "y": 30,
      "z": 15,
      "name": "Rock_Basalt"
    },
    {
      "x": 22,
      "y": 31,
      "z": 15,
      "name": "Soil_Dirt"
    },
    {
      "x": 22,
      "y": 32,
      "z": 15,
      "name": "Rock_Stone"
    },
    {
      "x": 22,
      "y": 33,
      "z": 15,
      "name": "Rock_Stone"
    },
    {
      "x": 22,
      "y": 34,
      "z": 15,
      "name": "Rock_Stone"
    },
    {
      "x": 22,
      "y": 35,
      "z": 15,
      "name": "Rock_Stone"
    },
    {
      "x": 22,
      "y": 36,
      "z": 15,
      "name": "Rock_Stone_Mossy"
    },
    {
      "x": 22,
      "y": 37,
      "z": 15,
      "name": "Rock_Stone"
    },
    {
      "x": 22,
      "y": 28,
      "z": 16,
      "name": "Rock_Basalt"
    },
    {
      "x": 22,
      "y": 29,
      "z": 16,
      "name": "Rock_Basalt"
    },
    {
      "x": 22,
      "y": 30,
      "z": 16,
      "name": "Soil_Dirt"
    },
    {
      "x": 22,
      "y": 31,
      "z": 16,
      "name": "Soil_Dirt"
    },
    {
      "x": 22,
      "y": 32,
      "z": 16,
      "name": "Soil_Dirt"
    },
    {
      "x": 22,
      "y": 33,
      "z": 16,
      "name": "Rock_Stone"
    },
    {
      "x": 22,
      "y": 34,
      "z": 16,
      "name": "Rock_Stone"
    },
    {
      "x": 22,
      "y": 35,
      "z": 16,
      "name": "Rock_Stone_Mossy"
    },
    {
      "x": 22,
      "y": 36,
      "z": 16,
      "name": "Rock_Stone_Mossy"
    },
    {
      "x": 22,
      "y": 29,
      "z": 17,
      "name": "Rock_Basalt"
    },
    {
      "x": 22,
      "y": 30,
      "z": 17,
      "name": "Soil_Dirt"
    },
    {
      "x": 22,
      "y": 31,
      "z": 17,
      "name": "Soil_Dirt"
    },
    {
      "x": 22,
      "y": 32,
      "z": 17,
      "name": "Soil_Dirt"
    },
    {
      "x": 22,
      "y": 33,
      "z": 17,
      "name": "Soil_Dirt"
    },
    {
      "x": 22,
      "y": 30,
      "z": 18,
      "name": "Soil_Dirt"
    },
    {
      "x": 22,
      "y": 31,
      "z": 18,
      "name": "Soil_Dirt"
    },
    {
      "x": 22,
      "y": 32,
      "z": 18,
      "name": "Soil_Dirt"
    },
    {
      "x": 22,
      "y": 29,
      "z": 19,
      "name": "Soil_Dirt"
    },
    {
      "x": 22,
      "y": 30,
      "z": 19,
      "name": "Soil_Dirt"
    },
    {
      "x": 22,
      "y": 31,
      "z": 19,
      "name": "Soil_Dirt"
    },
    {
      "x": 22,
      "y": 32,
      "z": 19,
      "name": "Soil_Dirt"
    },
    {
      "x": 22,
      "y": 29,
      "z": 20,
      "name": "Soil_Dirt"
    },
    {
      "x": 22,
      "y": 30,
      "z": 20,
      "name": "Soil_Dirt"
    },
    {
      "x": 22,
      "y": 31,
      "z": 20,
      "name": "Soil_Dirt"
    },
    {
      "x": 22,
      "y": 32,
      "z": 20,
      "name": "Soil_Dirt"
    },
    {
      "x": 22,
      "y": 29,
      "z": 21,
      "name": "Soil_Dirt"
    },
    {
      "x": 22,
      "y": 30,
      "z": 21,
      "name": "Soil_Dirt"
    },
    {
      "x": 22,
      "y": 31,
      "z": 21,
      "name": "Soil_Dirt"
    },
    {
      "x": 22,
      "y": 32,
      "z": 21,
      "name": "Soil_Dirt"
    },
    {
      "x": 22,
      "y": 29,
      "z": 22,
      "name": "Soil_Dirt"
    },
    {
      "x": 22,
      "y": 30,
      "z": 22,
      "name": "Soil_Dirt"
    },
    {
      "x": 22,
      "y": 31,
      "z": 22,
      "name": "Soil_Dirt"
    },
    {
      "x": 22,
      "y": 32,
      "z": 22,
      "name": "Soil_Grass"
    },
    {
      "x": 22,
      "y": 33,
      "z": 22,
      "name": "Plant_Grass_Sharp_Tall"
    },
    {
      "x": 22,
      "y": 34,
      "z": 22,
      "name": "Plant_Grass_Sharp_Tall",
      "filler": 1024
    },
    {
      "x": 22,
      "y": 29,
      "z": 23,
      "name": "Soil_Dirt"
    },
    {
      "x": 22,
      "y": 30,
      "z": 23,
      "name": "Soil_Dirt"
    },
    {
      "x": 22,
      "y": 31,
      "z": 23,
      "name": "Soil_Dirt"
    },
    {
      "x": 22,
      "y": 32,
      "z": 23,
      "name": "Soil_Dirt"
    },
    {
      "x": 23,
      "y": 31,
      "z": 8,
      "name": "Soil_Dirt"
    },
    {
      "x": 23,
      "y": 32,
      "z": 8,
      "name": "Soil_Dirt"
    },
    {
      "x": 23,
      "y": 33,
      "z": 8,
      "name": "Soil_Dirt"
    },
    {
      "x": 23,
      "y": 34,
      "z": 8,
      "name": "Soil_Grass"
    },
    {
      "x": 23,
      "y": 35,
      "z": 8,
      "name": "Plant_Grass_Sharp_Tall"
    },
    {
      "x": 23,
      "y": 36,
      "z": 8,
      "name": "Plant_Grass_Sharp_Tall",
      "filler": 1024
    },
    {
      "x": 23,
      "y": 30,
      "z": 9,
      "name": "Rock_Basalt"
    },
    {
      "x": 23,
      "y": 31,
      "z": 9,
      "name": "Soil_Dirt"
    },
    {
      "x": 23,
      "y": 32,
      "z": 9,
      "name": "Soil_Dirt"
    },
    {
      "x": 23,
      "y": 33,
      "z": 9,
      "name": "Soil_Dirt"
    },
    {
      "x": 23,
      "y": 34,
      "z": 9,
      "name": "Soil_Grass"
    },
    {
      "x": 23,
      "y": 29,
      "z": 10,
      "name": "Rock_Basalt"
    },
    {
      "x": 23,
      "y": 30,
      "z": 10,
      "name": "Rock_Basalt"
    },
    {
      "x": 23,
      "y": 31,
      "z": 10,
      "name": "Soil_Dirt"
    },
    {
      "x": 23,
      "y": 32,
      "z": 10,
      "name": "Soil_Dirt"
    },
    {
      "x": 23,
      "y": 33,
      "z": 10,
      "name": "Soil_Dirt"
    },
    {
      "x": 23,
      "y": 34,
      "z": 10,
      "name": "Soil_Dirt"
    },
    {
      "x": 23,
      "y": 28,
      "z": 11,
      "name": "Rock_Basalt"
    },
    {
      "x": 23,
      "y": 29,
      "z": 11,
      "name": "Rock_Basalt"
    },
    {
      "x": 23,
      "y": 30,
      "z": 11,
      "name": "Rock_Basalt"
    },
    {
      "x": 23,
      "y": 31,
      "z": 11,
      "name": "Soil_Dirt"
    },
    {
      "x": 23,
      "y": 32,
      "z": 11,
      "name": "Soil_Dirt"
    },
    {
      "x": 23,
      "y": 33,
      "z": 11,
      "name": "Soil_Dirt"
    },
    {
      "x": 23,
      "y": 34,
      "z": 11,
      "name": "Soil_Dirt"
    },
    {
      "x": 23,
      "y": 35,
      "z": 11,
      "name": "Rock_Stone"
    },
    {
      "x": 23,
      "y": 36,
      "z": 11,
      "name": "Rubble_Basalt"
    },
    {
      "x": 23,
      "y": 28,
      "z": 12,
      "name": "Rock_Basalt"
    },
    {
      "x": 23,
      "y": 29,
      "z": 12,
      "name": "Rock_Basalt"
    },
    {
      "x": 23,
      "y": 30,
      "z": 12,
      "name": "Rock_Basalt"
    },
    {
      "x": 23,
      "y": 31,
      "z": 12,
      "name": "Soil_Dirt"
    },
    {
      "x": 23,
      "y": 32,
      "z": 12,
      "name": "Soil_Dirt"
    },
    {
      "x": 23,
      "y": 33,
      "z": 12,
      "name": "Rock_Stone"
    },
    {
      "x": 23,
      "y": 34,
      "z": 12,
      "name": "Rock_Stone"
    },
    {
      "x": 23,
      "y": 35,
      "z": 12,
      "name": "Rock_Stone"
    },
    {
      "x": 23,
      "y": 36,
      "z": 12,
      "name": "Rock_Stone"
    },
    {
      "x": 23,
      "y": 28,
      "z": 13,
      "name": "Rock_Basalt"
    },
    {
      "x": 23,
      "y": 29,
      "z": 13,
      "name": "Rock_Basalt"
    },
    {
      "x": 23,
      "y": 30,
      "z": 13,
      "name": "Rock_Basalt"
    },
    {
      "x": 23,
      "y": 31,
      "z": 13,
      "name": "Rock_Basalt"
    },
    {
      "x": 23,
      "y": 32,
      "z": 13,
      "name": "Soil_Dirt"
    },
    {
      "x": 23,
      "y": 33,
      "z": 13,
      "name": "Rock_Stone"
    },
    {
      "x": 23,
      "y": 34,
      "z": 13,
      "name": "Rock_Stone"
    },
    {
      "x": 23,
      "y": 35,
      "z": 13,
      "name": "Rock_Stone"
    },
    {
      "x": 23,
      "y": 36,
      "z": 13,
      "name": "Rock_Stone"
    },
    {
      "x": 23,
      "y": 37,
      "z": 13,
      "name": "Rock_Stone"
    },
    {
      "x": 23,
      "y": 28,
      "z": 14,
      "name": "Rock_Basalt"
    },
    {
      "x": 23,
      "y": 29,
      "z": 14,
      "name": "Rock_Basalt"
    },
    {
      "x": 23,
      "y": 30,
      "z": 14,
      "name": "Rock_Basalt"
    },
    {
      "x": 23,
      "y": 31,
      "z": 14,
      "name": "Rock_Basalt"
    },
    {
      "x": 23,
      "y": 32,
      "z": 14,
      "name": "Rock_Basalt"
    },
    {
      "x": 23,
      "y": 33,
      "z": 14,
      "name": "Rock_Stone"
    },
    {
      "x": 23,
      "y": 34,
      "z": 14,
      "name": "Rock_Stone"
    },
    {
      "x": 23,
      "y": 35,
      "z": 14,
      "name": "Rock_Stone"
    },
    {
      "x": 23,
      "y": 36,
      "z": 14,
      "name": "Rock_Stone"
    },
    {
      "x": 23,
      "y": 37,
      "z": 14,
      "name": "Rock_Stone_Mossy"
    },
    {
      "x": 23,
      "y": 28,
      "z": 15,
      "name": "Rock_Basalt"
    },
    {
      "x": 23,
      "y": 29,
      "z": 15,
      "name": "Rock_Basalt"
    },
    {
      "x": 23,
      "y": 30,
      "z": 15,
      "name": "Rock_Basalt"
    },
    {
      "x": 23,
      "y": 31,
      "z": 15,
      "name": "Rock_Basalt"
    },
    {
      "x": 23,
      "y": 32,
      "z": 15,
      "name": "Soil_Dirt"
    },
    {
      "x": 23,
      "y": 33,
      "z": 15,
      "name": "Rock_Stone"
    },
    {
      "x": 23,
      "y": 34,
      "z": 15,
      "name": "Rock_Stone"
    },
    {
      "x": 23,
      "y": 35,
      "z": 15,
      "name": "Rock_Stone"
    },
    {
      "x": 23,
      "y": 36,
      "z": 15,
      "name": "Rock_Stone"
    },
    {
      "x": 23,
      "y": 37,
      "z": 15,
      "name": "Rubble_Basalt"
    },
    {
      "x": 23,
      "y": 8,
      "z": 16,
      "name": "Rock_Basalt"
    },
    {
      "x": 23,
      "y": 29,
      "z": 16,
      "name": "Rock_Basalt"
    },
    {
      "x": 23,
      "y": 30,
      "z": 16,
      "name": "Rock_Basalt"
    },
    {
      "x": 23,
      "y": 31,
      "z": 16,
      "name": "Soil_Dirt"
    },
    {
      "x": 23,
      "y": 32,
      "z": 16,
      "name": "Soil_Dirt"
    },
    {
      "x": 23,
      "y": 33,
      "z": 16,
      "name": "Rock_Stone"
    },
    {
      "x": 23,
      "y": 34,
      "z": 16,
      "name": "Rock_Stone"
    },
    {
      "x": 23,
      "y": 35,
      "z": 16,
      "name": "Rock_Stone"
    },
    {
      "x": 23,
      "y": 36,
      "z": 16,
      "name": "Rock_Stone_Mossy"
    },
    {
      "x": 23,
      "y": 29,
      "z": 17,
      "name": "Rock_Basalt"
    },
    {
      "x": 23,
      "y": 30,
      "z": 17,
      "name": "Soil_Dirt"
    },
    {
      "x": 23,
      "y": 31,
      "z": 17,
      "name": "Soil_Dirt"
    },
    {
      "x": 23,
      "y": 32,
      "z": 17,
      "name": "Rock_Stone"
    },
    {
      "x": 23,
      "y": 33,
      "z": 17,
      "name": "Rock_Stone"
    },
    {
      "x": 23,
      "y": 34,
      "z": 17,
      "name": "Rock_Stone"
    },
    {
      "x": 23,
      "y": 30,
      "z": 18,
      "name": "Soil_Dirt"
    },
    {
      "x": 23,
      "y": 30,
      "z": 20,
      "name": "Soil_Dirt"
    },
    {
      "x": 23,
      "y": 31,
      "z": 20,
      "name": "Soil_Dirt"
    },
    {
      "x": 23,
      "y": 32,
      "z": 20,
      "name": "Soil_Dirt"
    },
    {
      "x": 23,
      "y": 29,
      "z": 21,
      "name": "Soil_Dirt"
    },
    {
      "x": 23,
      "y": 30,
      "z": 21,
      "name": "Soil_Dirt"
    },
    {
      "x": 23,
      "y": 31,
      "z": 21,
      "name": "Soil_Dirt"
    },
    {
      "x": 23,
      "y": 32,
      "z": 21,
      "name": "Soil_Grass"
    },
    {
      "x": 23,
      "y": 28,
      "z": 22,
      "name": "Rock_Basalt"
    },
    {
      "x": 23,
      "y": 29,
      "z": 22,
      "name": "Soil_Dirt"
    },
    {
      "x": 23,
      "y": 30,
      "z": 22,
      "name": "Soil_Dirt"
    },
    {
      "x": 23,
      "y": 31,
      "z": 22,
      "name": "Soil_Dirt"
    },
    {
      "x": 23,
      "y": 32,
      "z": 22,
      "name": "Soil_Grass"
    },
    {
      "x": 23,
      "y": 29,
      "z": 23,
      "name": "Soil_Dirt"
    },
    {
      "x": 23,
      "y": 30,
      "z": 23,
      "name": "Soil_Dirt"
    },
    {
      "x": 23,
      "y": 31,
      "z": 23,
      "name": "Soil_Dirt"
    },
    {
      "x": 23,
      "y": 32,
      "z": 23,
      "name": "Soil_Grass"
    },
    {
      "x": 23,
      "y": 33,
      "z": 23,
      "name": "Plant_Grass_Sharp_Tall"
    },
    {
      "x": 23,
      "y": 34,
      "z": 23,
      "name": "Plant_Grass_Sharp_Tall",
      "filler": 1024
    },
    {
      "x": 24,
      "y": 30,
      "z": 8,
      "name": "Rock_Basalt"
    },
    {
      "x": 24,
      "y": 31,
      "z": 8,
      "name": "Soil_Dirt"
    },
    {
      "x": 24,
      "y": 32,
      "z": 8,
      "name": "Soil_Dirt"
    },
    {
      "x": 24,
      "y": 33,
      "z": 8,
      "name": "Soil_Dirt"
    },
    {
      "x": 24,
      "y": 34,
      "z": 8,
      "name": "Soil_Grass"
    },
    {
      "x": 24,
      "y": 11,
      "z": 9,
      "name": "Rock_Basalt"
    },
    {
      "x": 24,
      "y": 30,
      "z": 9,
      "name": "Rock_Basalt"
    },
    {
      "x": 24,
      "y": 31,
      "z": 9,
      "name": "Soil_Dirt"
    },
    {
      "x": 24,
      "y": 32,
      "z": 9,
      "name": "Soil_Dirt"
    },
    {
      "x": 24,
      "y": 33,
      "z": 9,
      "name": "Soil_Dirt"
    },
    {
      "x": 24,
      "y": 34,
      "z": 9,
      "name": "Soil_Grass"
    },
    {
      "x": 24,
      "y": 11,
      "z": 10,
      "name": "Rock_Basalt"
    },
    {
      "x": 24,
      "y": 30,
      "z": 10,
      "name": "Soil_Dirt"
    },
    {
      "x": 24,
      "y": 31,
      "z": 10,
      "name": "Soil_Dirt"
    },
    {
      "x": 24,
      "y": 32,
      "z": 10,
      "name": "Soil_Dirt"
    },
    {
      "x": 24,
      "y": 33,
      "z": 10,
      "name": "Soil_Dirt"
    },
    {
      "x": 24,
      "y": 34,
      "z": 10,
      "name": "Soil_Grass"
    },
    {
      "x": 24,
      "y": 28,
      "z": 11,
      "name": "Rock_Basalt"
    },
    {
      "x": 24,
      "y": 29,
      "z": 11,
      "name": "Rock_Basalt"
    },
    {
      "x": 24,
      "y": 30,
      "z": 11,
      "name": "Rock_Basalt"
    },
    {
      "x": 24,
      "y": 31,
      "z": 11,
      "name": "Soil_Dirt"
    },
    {
      "x": 24,
      "y": 32,
      "z": 11,
      "name": "Soil_Dirt"
    },
    {
      "x": 24,
      "y": 33,
      "z": 11,
      "name": "Soil_Dirt"
    },
    {
      "x": 24,
      "y": 34,
      "z": 11,
      "name": "Rock_Stone"
    },
    {
      "x": 24,
      "y": 35,
      "z": 11,
      "name": "Rock_Stone"
    },
    {
      "x": 24,
      "y": 36,
      "z": 11,
      "name": "Rock_Stone"
    },
    {
      "x": 24,
      "y": 29,
      "z": 12,
      "name": "Rock_Basalt"
    },
    {
      "x": 24,
      "y": 30,
      "z": 12,
      "name": "Rock_Basalt"
    },
    {
      "x": 24,
      "y": 31,
      "z": 12,
      "name": "Soil_Dirt"
    },
    {
      "x": 24,
      "y": 32,
      "z": 12,
      "name": "Soil_Dirt"
    },
    {
      "x": 24,
      "y": 33,
      "z": 12,
      "name": "Soil_Dirt"
    },
    {
      "x": 24,
      "y": 34,
      "z": 12,
      "name": "Rock_Stone"
    },
    {
      "x": 24,
      "y": 35,
      "z": 12,
      "name": "Rock_Stone"
    },
    {
      "x": 24,
      "y": 36,
      "z": 12,
      "name": "Rock_Stone"
    },
    {
      "x": 24,
      "y": 37,
      "z": 12,
      "name": "Rock_Stone"
    },
    {
      "x": 24,
      "y": 28,
      "z": 13,
      "name": "Rock_Basalt"
    },
    {
      "x": 24,
      "y": 29,
      "z": 13,
      "name": "Rock_Basalt"
    },
    {
      "x": 24,
      "y": 30,
      "z": 13,
      "name": "Rock_Basalt"
    },
    {
      "x": 24,
      "y": 31,
      "z": 13,
      "name": "Rock_Basalt"
    },
    {
      "x": 24,
      "y": 32,
      "z": 13,
      "name": "Soil_Dirt"
    },
    {
      "x": 24,
      "y": 33,
      "z": 13,
      "name": "Soil_Dirt"
    },
    {
      "x": 24,
      "y": 34,
      "z": 13,
      "name": "Rock_Stone"
    },
    {
      "x": 24,
      "y": 35,
      "z": 13,
      "name": "Rock_Stone"
    },
    {
      "x": 24,
      "y": 36,
      "z": 13,
      "name": "Rock_Stone"
    },
    {
      "x": 24,
      "y": 37,
      "z": 13,
      "name": "Rock_Stone_Mossy"
    },
    {
      "x": 24,
      "y": 28,
      "z": 14,
      "name": "Rock_Basalt"
    },
    {
      "x": 24,
      "y": 29,
      "z": 14,
      "name": "Rock_Basalt"
    },
    {
      "x": 24,
      "y": 30,
      "z": 14,
      "name": "Rock_Basalt"
    },
    {
      "x": 24,
      "y": 31,
      "z": 14,
      "name": "Rock_Basalt"
    },
    {
      "x": 24,
      "y": 32,
      "z": 14,
      "name": "Soil_Dirt"
    },
    {
      "x": 24,
      "y": 33,
      "z": 14,
      "name": "Rock_Stone"
    },
    {
      "x": 24,
      "y": 34,
      "z": 14,
      "name": "Rock_Stone"
    },
    {
      "x": 24,
      "y": 35,
      "z": 14,
      "name": "Rock_Stone"
    },
    {
      "x": 24,
      "y": 36,
      "z": 14,
      "name": "Rock_Stone_Mossy"
    },
    {
      "x": 24,
      "y": 37,
      "z": 14,
      "name": "Rock_Stone_Mossy"
    },
    {
      "x": 24,
      "y": 28,
      "z": 15,
      "name": "Rock_Basalt"
    },
    {
      "x": 24,
      "y": 29,
      "z": 15,
      "name": "Rock_Basalt"
    },
    {
      "x": 24,
      "y": 30,
      "z": 15,
      "name": "Rock_Basalt"
    },
    {
      "x": 24,
      "y": 31,
      "z": 15,
      "name": "Soil_Dirt"
    },
    {
      "x": 24,
      "y": 32,
      "z": 15,
      "name": "Rock_Stone"
    },
    {
      "x": 24,
      "y": 33,
      "z": 15,
      "name": "Rock_Stone"
    },
    {
      "x": 24,
      "y": 34,
      "z": 15,
      "name": "Rock_Stone"
    },
    {
      "x": 24,
      "y": 35,
      "z": 15,
      "name": "Rock_Stone"
    },
    {
      "x": 24,
      "y": 36,
      "z": 15,
      "name": "Rock_Stone"
    },
    {
      "x": 24,
      "y": 37,
      "z": 15,
      "name": "Rubble_Basalt"
    },
    {
      "x": 24,
      "y": 8,
      "z": 16,
      "name": "Rock_Basalt"
    },
    {
      "x": 24,
      "y": 9,
      "z": 16,
      "name": "Rock_Basalt"
    },
    {
      "x": 24,
      "y": 30,
      "z": 16,
      "name": "Rock_Basalt"
    },
    {
      "x": 24,
      "y": 31,
      "z": 16,
      "name": "Soil_Dirt"
    },
    {
      "x": 24,
      "y": 32,
      "z": 16,
      "name": "Soil_Dirt"
    },
    {
      "x": 24,
      "y": 33,
      "z": 16,
      "name": "Rock_Stone"
    },
    {
      "x": 24,
      "y": 34,
      "z": 16,
      "name": "Rock_Stone"
    },
    {
      "x": 24,
      "y": 35,
      "z": 16,
      "name": "Rock_Stone"
    },
    {
      "x": 24,
      "y": 36,
      "z": 16,
      "name": "Rubble_Basalt"
    },
    {
      "x": 24,
      "y": 8,
      "z": 17,
      "name": "Rock_Basalt"
    },
    {
      "x": 24,
      "y": 9,
      "z": 17,
      "name": "Rock_Basalt"
    },
    {
      "x": 24,
      "y": 29,
      "z": 17,
      "name": "Rock_Basalt"
    },
    {
      "x": 24,
      "y": 30,
      "z": 17,
      "name": "Rock_Basalt"
    },
    {
      "x": 24,
      "y": 31,
      "z": 17,
      "name": "Soil_Dirt"
    },
    {
      "x": 24,
      "y": 32,
      "z": 17,
      "name": "Soil_Dirt"
    },
    {
      "x": 24,
      "y": 33,
      "z": 17,
      "name": "Soil_Dirt"
    },
    {
      "x": 24,
      "y": 34,
      "z": 17,
      "name": "Rock_Stone"
    },
    {
      "x": 24,
      "y": 9,
      "z": 18,
      "name": "Rock_Basalt"
    },
    {
      "x": 24,
      "y": 30,
      "z": 18,
      "name": "Soil_Dirt"
    },
    {
      "x": 24,
      "y": 31,
      "z": 18,
      "name": "Soil_Dirt"
    },
    {
      "x": 24,
      "y": 32,
      "z": 18,
      "name": "Soil_Dirt"
    },
    {
      "x": 24,
      "y": 33,
      "z": 18,
      "name": "Soil_Grass"
    },
    {
      "x": 24,
      "y": 29,
      "z": 21,
      "name": "Soil_Dirt"
    },
    {
      "x": 24,
      "y": 30,
      "z": 21,
      "name": "Soil_Dirt"
    },
    {
      "x": 24,
      "y": 31,
      "z": 21,
      "name": "Soil_Dirt"
    },
    {
      "x": 24,
      "y": 32,
      "z": 21,
      "name": "Soil_Grass"
    },
    {
      "x": 24,
      "y": 28,
      "z": 22,
      "name": "Rock_Basalt"
    },
    {
      "x": 24,
      "y": 29,
      "z": 22,
      "name": "Soil_Dirt"
    },
    {
      "x": 24,
      "y": 30,
      "z": 22,
      "name": "Soil_Dirt"
    },
    {
      "x": 24,
      "y": 31,
      "z": 22,
      "name": "Soil_Dirt"
    },
    {
      "x": 24,
      "y": 32,
      "z": 22,
      "name": "Soil_Grass"
    },
    {
      "x": 24,
      "y": 33,
      "z": 22,
      "name": "Plant_Grass_Sharp_Tall"
    },
    {
      "x": 24,
      "y": 34,
      "z": 22,
      "name": "Plant_Grass_Sharp_Tall",
      "filler": 1024
    },
    {
      "x": 24,
      "y": 29,
      "z": 23,
      "name": "Soil_Dirt"
    },
    {
      "x": 24,
      "y": 30,
      "z": 23,
      "name": "Soil_Dirt"
    },
    {
      "x": 24,
      "y": 31,
      "z": 23,
      "name": "Soil_Dirt"
    },
    {
      "x": 24,
      "y": 32,
      "z": 23,
      "name": "Soil_Grass"
    },
    {
      "x": 24,
      "y": 30,
      "z": 24,
      "name": "Soil_Dirt"
    },
    {
      "x": 24,
      "y": 31,
      "z": 24,
      "name": "Soil_Dirt"
    },
    {
      "x": 25,
      "y": 13,
      "z": 6,
      "name": "Rock_Basalt"
    },
    {
      "x": 25,
      "y": 12,
      "z": 7,
      "name": "Rock_Basalt"
    },
    {
      "x": 25,
      "y": 31,
      "z": 7,
      "name": "Rock_Basalt"
    },
    {
      "x": 25,
      "y": 32,
      "z": 7,
      "name": "Soil_Dirt"
    },
    {
      "x": 25,
      "y": 33,
      "z": 7,
      "name": "Soil_Grass"
    },
    {
      "x": 25,
      "y": 11,
      "z": 8,
      "name": "Rock_Basalt"
    },
    {
      "x": 25,
      "y": 12,
      "z": 8,
      "name": "Rock_Basalt"
    },
    {
      "x": 25,
      "y": 30,
      "z": 8,
      "name": "Rock_Basalt"
    },
    {
      "x": 25,
      "y": 31,
      "z": 8,
      "name": "Soil_Dirt"
    },
    {
      "x": 25,
      "y": 32,
      "z": 8,
      "name": "Soil_Dirt"
    },
    {
      "x": 25,
      "y": 33,
      "z": 8,
      "name": "Soil_Dirt"
    },
    {
      "x": 25,
      "y": 34,
      "z": 8,
      "name": "Soil_Grass"
    },
    {
      "x": 25,
      "y": 11,
      "z": 9,
      "name": "Rock_Basalt"
    },
    {
      "x": 25,
      "y": 30,
      "z": 9,
      "name": "Rock_Basalt"
    },
    {
      "x": 25,
      "y": 31,
      "z": 9,
      "name": "Soil_Dirt"
    },
    {
      "x": 25,
      "y": 32,
      "z": 9,
      "name": "Soil_Dirt"
    },
    {
      "x": 25,
      "y": 33,
      "z": 9,
      "name": "Soil_Dirt"
    },
    {
      "x": 25,
      "y": 34,
      "z": 9,
      "name": "Soil_Grass"
    },
    {
      "x": 25,
      "y": 35,
      "z": 9,
      "name": "Plant_Grass_Sharp_Tall"
    },
    {
      "x": 25,
      "y": 36,
      "z": 9,
      "name": "Plant_Grass_Sharp_Tall",
      "filler": 1024
    },
    {
      "x": 25,
      "y": 30,
      "z": 10,
      "name": "Rock_Basalt"
    },
    {
      "x": 25,
      "y": 31,
      "z": 10,
      "name": "Soil_Dirt"
    },
    {
      "x": 25,
      "y": 32,
      "z": 10,
      "name": "Soil_Dirt"
    },
    {
      "x": 25,
      "y": 33,
      "z": 10,
      "name": "Soil_Dirt"
    },
    {
      "x": 25,
      "y": 34,
      "z": 10,
      "name": "Soil_Dirt"
    },
    {
      "x": 25,
      "y": 35,
      "z": 10,
      "name": "Soil_Grass"
    },
    {
      "x": 25,
      "y": 29,
      "z": 11,
      "name": "Rock_Basalt"
    },
    {
      "x": 25,
      "y": 30,
      "z": 11,
      "name": "Rock_Basalt"
    },
    {
      "x": 25,
      "y": 31,
      "z": 11,
      "name": "Soil_Dirt"
    },
    {
      "x": 25,
      "y": 32,
      "z": 11,
      "name": "Soil_Dirt"
    },
    {
      "x": 25,
      "y": 33,
      "z": 11,
      "name": "Soil_Dirt"
    },
    {
      "x": 25,
      "y": 34,
      "z": 11,
      "name": "Rock_Stone"
    },
    {
      "x": 25,
      "y": 35,
      "z": 11,
      "name": "Rock_Stone"
    },
    {
      "x": 25,
      "y": 36,
      "z": 11,
      "name": "Rock_Stone"
    },
    {
      "x": 25,
      "y": 30,
      "z": 12,
      "name": "Rock_Basalt"
    },
    {
      "x": 25,
      "y": 31,
      "z": 12,
      "name": "Soil_Dirt"
    },
    {
      "x": 25,
      "y": 32,
      "z": 12,
      "name": "Soil_Dirt"
    },
    {
      "x": 25,
      "y": 33,
      "z": 12,
      "name": "Rock_Stone"
    },
    {
      "x": 25,
      "y": 34,
      "z": 12,
      "name": "Rock_Stone"
    },
    {
      "x": 25,
      "y": 35,
      "z": 12,
      "name": "Rock_Stone"
    },
    {
      "x": 25,
      "y": 36,
      "z": 12,
      "name": "Rock_Stone"
    },
    {
      "x": 25,
      "y": 37,
      "z": 12,
      "name": "Rock_Stone"
    },
    {
      "x": 25,
      "y": 30,
      "z": 13,
      "name": "Rock_Basalt"
    },
    {
      "x": 25,
      "y": 31,
      "z": 13,
      "name": "Rock_Basalt"
    },
    {
      "x": 25,
      "y": 32,
      "z": 13,
      "name": "Soil_Dirt"
    },
    {
      "x": 25,
      "y": 33,
      "z": 13,
      "name": "Soil_Dirt"
    },
    {
      "x": 25,
      "y": 34,
      "z": 13,
      "name": "Rock_Stone"
    },
    {
      "x": 25,
      "y": 35,
      "z": 13,
      "name": "Rock_Stone"
    },
    {
      "x": 25,
      "y": 36,
      "z": 13,
      "name": "Rock_Stone"
    },
    {
      "x": 25,
      "y": 37,
      "z": 13,
      "name": "Rock_Stone"
    },
    {
      "x": 25,
      "y": 38,
      "z": 13,
      "name": "Rubble_Basalt"
    },
    {
      "x": 25,
      "y": 29,
      "z": 14,
      "name": "Rock_Basalt"
    },
    {
      "x": 25,
      "y": 30,
      "z": 14,
      "name": "Rock_Basalt"
    },
    {
      "x": 25,
      "y": 31,
      "z": 14,
      "name": "Soil_Dirt"
    },
    {
      "x": 25,
      "y": 32,
      "z": 14,
      "name": "Soil_Dirt"
    },
    {
      "x": 25,
      "y": 33,
      "z": 14,
      "name": "Rock_Stone"
    },
    {
      "x": 25,
      "y": 34,
      "z": 14,
      "name": "Rock_Stone"
    },
    {
      "x": 25,
      "y": 35,
      "z": 14,
      "name": "Rock_Stone"
    },
    {
      "x": 25,
      "y": 36,
      "z": 14,
      "name": "Rock_Stone"
    },
    {
      "x": 25,
      "y": 37,
      "z": 14,
      "name": "Rock_Stone_Mossy"
    },
    {
      "x": 25,
      "y": 30,
      "z": 15,
      "name": "Rock_Basalt"
    },
    {
      "x": 25,
      "y": 31,
      "z": 15,
      "name": "Soil_Dirt"
    },
    {
      "x": 25,
      "y": 32,
      "z": 15,
      "name": "Soil_Dirt"
    },
    {
      "x": 25,
      "y": 33,
      "z": 15,
      "name": "Rock_Stone"
    },
    {
      "x": 25,
      "y": 34,
      "z": 15,
      "name": "Rock_Stone"
    },
    {
      "x": 25,
      "y": 35,
      "z": 15,
      "name": "Rock_Stone"
    },
    {
      "x": 25,
      "y": 30,
      "z": 16,
      "name": "Rock_Basalt"
    },
    {
      "x": 25,
      "y": 31,
      "z": 16,
      "name": "Soil_Dirt"
    },
    {
      "x": 25,
      "y": 32,
      "z": 16,
      "name": "Soil_Dirt"
    },
    {
      "x": 25,
      "y": 33,
      "z": 16,
      "name": "Rock_Stone"
    },
    {
      "x": 25,
      "y": 34,
      "z": 16,
      "name": "Rock_Stone"
    },
    {
      "x": 25,
      "y": 35,
      "z": 16,
      "name": "Rock_Stone"
    },
    {
      "x": 25,
      "y": 9,
      "z": 17,
      "name": "Rock_Basalt"
    },
    {
      "x": 25,
      "y": 30,
      "z": 17,
      "name": "Rock_Basalt"
    },
    {
      "x": 25,
      "y": 31,
      "z": 17,
      "name": "Soil_Dirt"
    },
    {
      "x": 25,
      "y": 32,
      "z": 17,
      "name": "Soil_Dirt"
    },
    {
      "x": 25,
      "y": 33,
      "z": 17,
      "name": "Soil_Dirt"
    },
    {
      "x": 25,
      "y": 34,
      "z": 17,
      "name": "Soil_Dirt"
    },
    {
      "x": 25,
      "y": 9,
      "z": 18,
      "name": "Rock_Basalt"
    },
    {
      "x": 25,
      "y": 30,
      "z": 18,
      "name": "Rock_Basalt"
    },
    {
      "x": 25,
      "y": 31,
      "z": 18,
      "name": "Soil_Dirt"
    },
    {
      "x": 25,
      "y": 32,
      "z": 18,
      "name": "Soil_Dirt"
    },
    {
      "x": 25,
      "y": 33,
      "z": 18,
      "name": "Soil_Grass"
    },
    {
      "x": 25,
      "y": 9,
      "z": 19,
      "name": "Rock_Basalt"
    },
    {
      "x": 25,
      "y": 31,
      "z": 19,
      "name": "Soil_Dirt"
    },
    {
      "x": 25,
      "y": 32,
      "z": 19,
      "name": "Soil_Dirt"
    },
    {
      "x": 25,
      "y": 33,
      "z": 19,
      "name": "Soil_Grass"
    },
    {
      "x": 25,
      "y": 28,
      "z": 22,
      "name": "Rock_Basalt"
    },
    {
      "x": 25,
      "y": 29,
      "z": 22,
      "name": "Soil_Dirt"
    },
    {
      "x": 25,
      "y": 30,
      "z": 22,
      "name": "Soil_Dirt"
    },
    {
      "x": 25,
      "y": 31,
      "z": 22,
      "name": "Soil_Dirt"
    },
    {
      "x": 25,
      "y": 28,
      "z": 23,
      "name": "Rock_Basalt"
    },
    {
      "x": 25,
      "y": 29,
      "z": 23,
      "name": "Soil_Dirt"
    },
    {
      "x": 25,
      "y": 30,
      "z": 23,
      "name": "Soil_Dirt"
    },
    {
      "x": 25,
      "y": 31,
      "z": 23,
      "name": "Soil_Dirt"
    },
    {
      "x": 25,
      "y": 32,
      "z": 23,
      "name": "Soil_Grass"
    },
    {
      "x": 25,
      "y": 29,
      "z": 24,
      "name": "Soil_Dirt"
    },
    {
      "x": 25,
      "y": 30,
      "z": 24,
      "name": "Soil_Dirt"
    },
    {
      "x": 25,
      "y": 31,
      "z": 24,
      "name": "Soil_Dirt"
    },
    {
      "x": 25,
      "y": 32,
      "z": 24,
      "name": "Soil_Grass"
    },
    {
      "x": 25,
      "y": 31,
      "z": 25,
      "name": "Soil_Dirt"
    },
    {
      "x": 26,
      "y": 13,
      "z": 5,
      "name": "Rock_Basalt"
    },
    {
      "x": 26,
      "y": 14,
      "z": 5,
      "name": "Rock_Basalt"
    },
    {
      "x": 26,
      "y": 12,
      "z": 6,
      "name": "Rock_Basalt"
    },
    {
      "x": 26,
      "y": 13,
      "z": 6,
      "name": "Rock_Basalt"
    },
    {
      "x": 26,
      "y": 14,
      "z": 6,
      "name": "Rock_Basalt"
    },
    {
      "x": 26,
      "y": 12,
      "z": 7,
      "name": "Rock_Basalt"
    },
    {
      "x": 26,
      "y": 13,
      "z": 7,
      "name": "Rock_Basalt"
    },
    {
      "x": 26,
      "y": 14,
      "z": 7,
      "name": "Rock_Basalt"
    },
    {
      "x": 26,
      "y": 30,
      "z": 7,
      "name": "Rock_Basalt"
    },
    {
      "x": 26,
      "y": 31,
      "z": 7,
      "name": "Rock_Basalt"
    },
    {
      "x": 26,
      "y": 32,
      "z": 7,
      "name": "Rock_Basalt"
    },
    {
      "x": 26,
      "y": 33,
      "z": 7,
      "name": "Soil_Grass"
    },
    {
      "x": 26,
      "y": 34,
      "z": 7,
      "name": "Plant_Grass_Sharp_Tall"
    },
    {
      "x": 26,
      "y": 35,
      "z": 7,
      "name": "Plant_Grass_Sharp_Tall",
      "filler": 1024
    },
    {
      "x": 26,
      "y": 12,
      "z": 8,
      "name": "Rock_Basalt"
    },
    {
      "x": 26,
      "y": 13,
      "z": 8,
      "name": "Rock_Basalt"
    },
    {
      "x": 26,
      "y": 29,
      "z": 8,
      "name": "Rock_Basalt"
    },
    {
      "x": 26,
      "y": 30,
      "z": 8,
      "name": "Rock_Basalt"
    },
    {
      "x": 26,
      "y": 31,
      "z": 8,
      "name": "Rock_Basalt"
    },
    {
      "x": 26,
      "y": 32,
      "z": 8,
      "name": "Soil_Dirt"
    },
    {
      "x": 26,
      "y": 33,
      "z": 8,
      "name": "Soil_Dirt"
    },
    {
      "x": 26,
      "y": 34,
      "z": 8,
      "name": "Soil_Dirt"
    },
    {
      "x": 26,
      "y": 35,
      "z": 8,
      "name": "Soil_Grass"
    },
    {
      "x": 26,
      "y": 30,
      "z": 9,
      "name": "Rock_Basalt"
    },
    {
      "x": 26,
      "y": 31,
      "z": 9,
      "name": "Soil_Dirt"
    },
    {
      "x": 26,
      "y": 32,
      "z": 9,
      "name": "Soil_Dirt"
    },
    {
      "x": 26,
      "y": 33,
      "z": 9,
      "name": "Soil_Dirt"
    },
    {
      "x": 26,
      "y": 34,
      "z": 9,
      "name": "Soil_Dirt"
    },
    {
      "x": 26,
      "y": 35,
      "z": 9,
      "name": "Soil_Grass"
    },
    {
      "x": 26,
      "y": 30,
      "z": 10,
      "name": "Rock_Basalt"
    },
    {
      "x": 26,
      "y": 31,
      "z": 10,
      "name": "Soil_Dirt"
    },
    {
      "x": 26,
      "y": 32,
      "z": 10,
      "name": "Soil_Dirt"
    },
    {
      "x": 26,
      "y": 33,
      "z": 10,
      "name": "Soil_Dirt"
    },
    {
      "x": 26,
      "y": 34,
      "z": 10,
      "name": "Soil_Dirt"
    },
    {
      "x": 26,
      "y": 35,
      "z": 10,
      "name": "Soil_Grass"
    },
    {
      "x": 26,
      "y": 30,
      "z": 11,
      "name": "Rock_Basalt"
    },
    {
      "x": 26,
      "y": 31,
      "z": 11,
      "name": "Soil_Dirt"
    },
    {
      "x": 26,
      "y": 32,
      "z": 11,
      "name": "Soil_Dirt"
    },
    {
      "x": 26,
      "y": 33,
      "z": 11,
      "name": "Soil_Dirt"
    },
    {
      "x": 26,
      "y": 34,
      "z": 11,
      "name": "Rock_Stone"
    },
    {
      "x": 26,
      "y": 35,
      "z": 11,
      "name": "Rock_Stone"
    },
    {
      "x": 26,
      "y": 36,
      "z": 11,
      "name": "Rock_Stone"
    },
    {
      "x": 26,
      "y": 30,
      "z": 12,
      "name": "Rock_Basalt"
    },
    {
      "x": 26,
      "y": 31,
      "z": 12,
      "name": "Rock_Basalt"
    },
    {
      "x": 26,
      "y": 32,
      "z": 12,
      "name": "Soil_Dirt"
    },
    {
      "x": 26,
      "y": 33,
      "z": 12,
      "name": "Soil_Dirt"
    },
    {
      "x": 26,
      "y": 34,
      "z": 12,
      "name": "Rock_Stone"
    },
    {
      "x": 26,
      "y": 35,
      "z": 12,
      "name": "Rock_Stone"
    },
    {
      "x": 26,
      "y": 36,
      "z": 12,
      "name": "Rock_Stone"
    },
    {
      "x": 26,
      "y": 30,
      "z": 13,
      "name": "Rock_Basalt"
    },
    {
      "x": 26,
      "y": 31,
      "z": 13,
      "name": "Rock_Basalt"
    },
    {
      "x": 26,
      "y": 32,
      "z": 13,
      "name": "Soil_Dirt"
    },
    {
      "x": 26,
      "y": 33,
      "z": 13,
      "name": "Soil_Dirt"
    },
    {
      "x": 26,
      "y": 34,
      "z": 13,
      "name": "Rock_Stone"
    },
    {
      "x": 26,
      "y": 35,
      "z": 13,
      "name": "Rock_Stone"
    },
    {
      "x": 26,
      "y": 36,
      "z": 13,
      "name": "Rock_Stone"
    },
    {
      "x": 26,
      "y": 30,
      "z": 14,
      "name": "Rock_Basalt"
    },
    {
      "x": 26,
      "y": 31,
      "z": 14,
      "name": "Soil_Dirt"
    },
    {
      "x": 26,
      "y": 32,
      "z": 14,
      "name": "Soil_Dirt"
    },
    {
      "x": 26,
      "y": 33,
      "z": 14,
      "name": "Soil_Dirt"
    },
    {
      "x": 26,
      "y": 34,
      "z": 14,
      "name": "Soil_Dirt"
    },
    {
      "x": 26,
      "y": 35,
      "z": 14,
      "name": "Soil_Dirt"
    },
    {
      "x": 26,
      "y": 36,
      "z": 14,
      "name": "Soil_Snow"
    },
    {
      "x": 26,
      "y": 30,
      "z": 15,
      "name": "Rock_Basalt"
    },
    {
      "x": 26,
      "y": 31,
      "z": 15,
      "name": "Soil_Dirt"
    },
    {
      "x": 26,
      "y": 32,
      "z": 15,
      "name": "Soil_Dirt"
    },
    {
      "x": 26,
      "y": 33,
      "z": 15,
      "name": "Soil_Dirt"
    },
    {
      "x": 26,
      "y": 34,
      "z": 15,
      "name": "Rock_Stone"
    },
    {
      "x": 26,
      "y": 35,
      "z": 15,
      "name": "Soil_Snow"
    },
    {
      "x": 26,
      "y": 29,
      "z": 16,
      "name": "Rock_Basalt"
    },
    {
      "x": 26,
      "y": 30,
      "z": 16,
      "name": "Soil_Dirt"
    },
    {
      "x": 26,
      "y": 31,
      "z": 16,
      "name": "Soil_Dirt"
    },
    {
      "x": 26,
      "y": 32,
      "z": 16,
      "name": "Soil_Dirt"
    },
    {
      "x": 26,
      "y": 33,
      "z": 16,
      "name": "Soil_Dirt"
    },
    {
      "x": 26,
      "y": 34,
      "z": 16,
      "name": "Soil_Dirt"
    },
    {
      "x": 26,
      "y": 35,
      "z": 16,
      "name": "Soil_Snow"
    },
    {
      "x": 26,
      "y": 10,
      "z": 17,
      "name": "Rock_Basalt"
    },
    {
      "x": 26,
      "y": 29,
      "z": 17,
      "name": "Rock_Basalt"
    },
    {
      "x": 26,
      "y": 30,
      "z": 17,
      "name": "Rock_Basalt"
    },
    {
      "x": 26,
      "y": 31,
      "z": 17,
      "name": "Soil_Dirt"
    },
    {
      "x": 26,
      "y": 32,
      "z": 17,
      "name": "Soil_Dirt"
    },
    {
      "x": 26,
      "y": 33,
      "z": 17,
      "name": "Soil_Grass"
    },
    {
      "x": 26,
      "y": 34,
      "z": 17,
      "name": "Soil_Snow"
    },
    {
      "x": 26,
      "y": 9,
      "z": 18,
      "name": "Rock_Basalt"
    },
    {
      "x": 26,
      "y": 10,
      "z": 18,
      "name": "Rock_Basalt"
    },
    {
      "x": 26,
      "y": 30,
      "z": 18,
      "name": "Rock_Basalt"
    },
    {
      "x": 26,
      "y": 31,
      "z": 18,
      "name": "Soil_Dirt"
    },
    {
      "x": 26,
      "y": 32,
      "z": 18,
      "name": "Soil_Dirt"
    },
    {
      "x": 26,
      "y": 33,
      "z": 18,
      "name": "Soil_Grass"
    },
    {
      "x": 26,
      "y": 34,
      "z": 18,
      "name": "Soil_Snow"
    },
    {
      "x": 26,
      "y": 9,
      "z": 19,
      "name": "Rock_Basalt"
    },
    {
      "x": 26,
      "y": 30,
      "z": 19,
      "name": "Rock_Basalt"
    },
    {
      "x": 26,
      "y": 31,
      "z": 19,
      "name": "Soil_Dirt"
    },
    {
      "x": 26,
      "y": 32,
      "z": 19,
      "name": "Soil_Dirt"
    },
    {
      "x": 26,
      "y": 33,
      "z": 19,
      "name": "Soil_Grass"
    },
    {
      "x": 26,
      "y": 9,
      "z": 20,
      "name": "Rock_Basalt"
    },
    {
      "x": 26,
      "y": 32,
