{
  "version": 8,
  "blockIdVersion": 8,
  "anchorX": 7,
  "anchorY": 2,
  "anchorZ": 6,
  "blocks": [
    {
      "x": -7,
      "y": 2,
      "z": -5,
      "name": "Rock_Stone_Cobble"
    },
    {
      "x": -7,
      "y": 3,
      "z": -5,
      "name": "Rock_Stone_Cobble"
    },
    {
      "x": -7,
      "y": 4,
      "z": -5,
      "name": "Rock_Stone_Brick_Decorative"
    },
    {
      "x": -7,
      "y": 5,
      "z": -5,
      "name": "Rock_Stone_Cobble"
    },
    {
      "x": -7,
      "y": 6,
      "z": -5,
      "name": "Rock_Stone_Cobble"
    },
    {
      "x": -7,
      "y": 7,
      "z": -5,
      "name": "Rock_Stone_Cobble"
    },
    {
      "x": -7,
      "y": 8,
      "z": -5,
      "name": "Rock_Stone_Cobble"
    },
    {
      "x": -7,
      "y": 2,
      "z": -4,
      "name": "Rock_Stone_Cobble"
    },
    {
      "x": -7,
      "y": 3,
      "z": -4,
      "name": "Rock_Stone_Cobble"
    },
    {
      "x": -7,
      "y": 4,
      "z": -4,
      "name": "Rock_Stone_Brick_Decorative"
    },
    {
      "x": -7,
      "y": 5,
      "z": -4,
      "name": "Rock_Stone_Cobble"
    },
    {
      "x": -7,
      "y": 6,
      "z": -4,
      "name": "Rock_Stone_Cobble"
    },
    {
      "x": -7,
      "y": 7,
      "z": -4,
      "name": "Rock_Stone_Cobble"
    },
    {
      "x": -7,
      "y": 8,
      "z": -4,
      "name": "Rock_Stone_Cobble"
    },
    {
      "x": -7,
      "y": 2,
      "z": -3,
      "name": "Rock_Stone_Cobble"
    },
    {
      "x": -7,
      "y": 3,
      "z": -3,
      "name": "Rock_Stone_Cobble"
    },
    {
      "x": -7,
      "y": 4,
      "z": -3,
      "name": "Rock_Stone_Brick_Decorative"
    },
    {
      "x": -7,
      "y": 5,
      "z": -3,
      "name": "Rock_Stone_Cobble"
    },
    {
      "x": -7,
      "y": 6,
      "z": -3,
      "name": "Rock_Stone_Cobble"
    },
    {
      "x": -7,
      "y": 7,
      "z": -3,
      "name": "Rock_Stone_Cobble"
    },
    {
      "x": -7,
      "y": 8,
      "z": -3,
      "name": "Rock_Stone_Cobble"
    },
    {
      "x": -7,
      "y": 2,
      "z": -2,
      "name": "Rock_Stone_Cobble"
    },
    {
      "x": -7,
      "y": 3,
      "z": -2,
      "name": "Rock_Stone_Cobble"
    },
    {
      "x": -7,
      "y": 4,
      "z": -2,
      "name": "Rock_Stone_Brick_Decorative"
    },
    {
      "x": -7,
      "y": 5,
      "z": -2,
      "name": "Rock_Stone_Cobble"
    },
    {
      "x": -7,
      "y": 6,
      "z": -2,
      "name": "Rock_Stone_Cobble"
    },
    {
      "x": -7,
      "y": 7,
      "z": -2,
      "name": "Rock_Stone_Cobble"
    },
    {
      "x": -7,
      "y": 8,
      "z": -2,
      "name": "Rock_Stone_Cobble"
    },
    {
      "x": -7,
      "y": 2,
      "z": -1,
      "name": "Rock_Stone_Cobble"
    },
    {
      "x": -7,
      "y": 3,
      "z": -1,
      "name": "Rock_Stone_Cobble"
    },
    {
      "x": -7,
      "y": 4,
      "z": -1,
      "name": "Rock_Stone_Brick_Decorative"
    },
    {
      "x": -7,
      "y": 5,
      "z": -1,
      "name": "Rock_Stone_Cobble"
    },
    {
      "x": -7,
      "y": 6,
      "z": -1,
      "name": "Rock_Stone_Cobble"
    },
    {
      "x": -7,
      "y": 7,
      "z": -1,
      "name": "Rock_Stone_Cobble"
    },
    {
      "x": -7,
      "y": 8,
      "z": -1,
      "name": "Rock_Stone_Cobble"
    },
    {
      "x": -7,
      "y": 2,
      "z": 0,
      "name": "Rock_Stone_Cobble"
    },
    {
      "x": -7,
      "y": 3,
      "z": 0,
      "name": "Rock_Stone_Cobble"
    },
    {
      "x": -7,
      "y": 4,
      "z": 0,
      "name": "Rock_Stone_Brick_Decorative"
    },
    {
      "x": -7,
      "y": 5,
      "z": 0,
      "name": "Rock_Stone_Cobble"
    },
    {
      "x": -7,
      "y": 6,
      "z": 0,
      "name": "Rock_Stone_Cobble"
    },
    {
      "x": -7,
      "y": 7,
      "z": 0,
      "name": "Rock_Stone_Cobble"
    },
    {
      "x": -7,
      "y": 8,
      "z": 0,
      "name": "Rock_Stone_Cobble"
    },
    {
      "x": -7,
      "y": 2,
      "z": 1,
      "name": "Rock_Stone_Cobble"
    },
    {
      "x": -7,
      "y": 3,
      "z": 1,
      "name": "Rock_Stone_Cobble"
    },
    {
      "x": -7,
      "y": 4,
      "z": 1,
      "name": "Rock_Stone_Brick_Decorative"
    },
    {
      "x": -7,
      "y": 5,
      "z": 1,
      "name": "Rock_Stone_Cobble"
    },
    {
      "x": -7,
      "y": 6,
      "z": 1,
      "name": "Rock_Stone_Cobble"
    },
    {
      "x": -7,
      "y": 7,
      "z": 1,
      "name": "Rock_Stone_Cobble"
    },
    {
      "x": -7,
      "y": 8,
      "z": 1,
      "name": "Rock_Stone_Cobble"
    },
    {
      "x": -7,
      "y": 2,
      "z": 2,
      "name": "Rock_Stone_Cobble"
    },
    {
      "x": -7,
      "y": 3,
      "z": 2,
      "name": "Rock_Stone_Cobble"
    },
    {
      "x": -7,
      "y": 4,
      "z": 2,
      "name": "Rock_Stone_Brick_Decorative"
    },
    {
      "x": -7,
      "y": 5,
      "z": 2,
      "name": "Rock_Stone_Cobble"
    },
    {
      "x": -7,
      "y": 6,
      "z": 2,
      "name": "Rock_Stone_Cobble"
    },
    {
      "x": -7,
      "y": 7,
      "z": 2,
      "name": "Rock_Stone_Cobble"
    },
    {
      "x": -7,
      "y": 8,
      "z": 2,
      "name": "Rock_Stone_Cobble"
    },
    {
      "x": -7,
      "y": 2,
      "z": 3,
      "name": "Rock_Stone_Cobble"
    },
    {
      "x": -7,
      "y": 3,
      "z": 3,
      "name": "Rock_Stone_Cobble"
    },
    {
      "x": -7,
      "y": 4,
      "z": 3,
      "name": "Rock_Stone_Brick_Decorative"
    },
    {
      "x": -7,
      "y": 5,
      "z": 3,
      "name": "Rock_Stone_Cobble"
    },
    {
      "x": -7,
      "y": 6,
      "z": 3,
      "name": "Rock_Stone_Cobble"
    },
    {
      "x": -7,
      "y": 7,
      "z": 3,
      "name": "Rock_Stone_Cobble"
    },
    {
      "x": -7,
      "y": 8,
      "z": 3,
      "name": "Rock_Stone_Cobble"
    },
    {
      "x": -7,
      "y": 2,
      "z": 4,
      "name": "Rock_Stone_Cobble"
    },
    {
      "x": -7,
      "y": 3,
      "z": 4,
      "name": "Rock_Stone_Cobble"
    },
    {
      "x": -7,
      "y": 4,
      "z": 4,
      "name": "Rock_Stone_Brick_Decorative"
    },
    {
      "x": -7,
      "y": 5,
      "z": 4,
      "name": "Rock_Stone_Cobble"
    },
    {
      "x": -7,
      "y": 6,
      "z": 4,
      "name": "Rock_Stone_Cobble"
    },
    {
      "x": -7,
      "y": 7,
      "z": 4,
      "name": "Rock_Stone_Cobble"
    },
    {
      "x": -7,
      "y": 8,
      "z": 4,
      "name": "Rock_Stone_Cobble"
    },
    {
      "x": -7,
      "y": 2,
      "z": 5,
      "name": "Rock_Stone_Cobble"
    },
    {
      "x": -7,
      "y": 3,
      "z": 5,
      "name": "Rock_Stone_Cobble"
    },
    {
      "x": -7,
      "y": 4,
      "z": 5,
      "name": "Rock_Stone_Brick_Decorative"
    },
    {
      "x": -7,
      "y": 5,
      "z": 5,
      "name": "Rock_Stone_Cobble"
    },
    {
      "x": -7,
      "y": 6,
      "z": 5,
      "name": "Rock_Stone_Cobble"
    },
    {
      "x": -7,
      "y": 7,
      "z": 5,
      "name": "Rock_Stone_Cobble"
    },
    {
      "x": -7,
      "y": 8,
      "z": 5,
      "name": "Rock_Stone_Cobble"
    },
    {
      "x": -7,
      "y": 2,
      "z": 6,
      "name": "Rock_Stone_Cobble"
    },
    {
      "x": -7,
      "y": 3,
      "z": 6,
      "name": "Rock_Stone_Cobble"
    },
    {
      "x": -7,
      "y": 4,
      "z": 6,
      "name": "Rock_Stone_Brick_Decorative"
    },
    {
      "x": -7,
      "y": 5,
      "z": 6,
      "name": "Rock_Stone_Cobble"
    },
    {
      "x": -7,
      "y": 6,
      "z": 6,
      "name": "Rock_Stone_Cobble"
    },
    {
      "x": -7,
      "y": 7,
      "z": 6,
      "name": "Rock_Stone_Cobble"
    },
    {
      "x": -7,
      "y": 8,
      "z": 6,
      "name": "Rock_Stone_Cobble"
    },
    {
      "x": -6,
      "y": 2,
      "z": -5,
      "name": "Rock_Stone_Cobble"
    },
    {
      "x": -6,
      "y": 3,
      "z": -5,
      "name": "Rock_Stone_Cobble"
    },
    {
      "x": -6,
      "y": 4,
      "z": -5,
      "name": "Rock_Stone_Brick_Decorative"
    },
    {
      "x": -6,
      "y": 5,
      "z": -5,
      "name": "Rock_Stone_Cobble"
    },
    {
      "x": -6,
      "y": 6,
      "z": -5,
      "name": "Rock_Stone_Cobble"
    },
    {
      "x": -6,
      "y": 7,
      "z": -5,
      "name": "Rock_Stone_Cobble"
    },
    {
      "x": -6,
      "y": 8,
      "z": -5,
      "name": "Rock_Stone_Cobble"
    },
    {
      "x": -6,
      "y": 2,
      "z": -4,
      "name": "Rock_Stone_Cobble"
    },
    {
      "x": -6,
      "y": 3,
      "z": -4,
      "name": "Wood_Hardwood_Planks"
    },
    {
      "x": -6,
      "y": 4,
      "z": -4,
      "name": "Empty"
    },
    {
      "x": -6,
      "y": 5,
      "z": -4,
      "name": "Empty"
    },
    {
      "x": -6,
      "y": 6,
      "z": -4,
      "name": "Empty"
    },
    {
      "x": -6,
      "y": 7,
      "z": -4,
      "name": "Wood_Hardwood_Planks"
    },
    {
      "x": -6,
      "y": 8,
      "z": -4,
      "name": "Wood_Hardwood_Planks"
    },
    {
      "x": -6,
      "y": 2,
      "z": -3,
      "name": "Rock_Stone_Cobble"
    },
    {
      "x": -6,
      "y": 3,
      "z": -3,
      "name": "Wood_Hardwood_Planks"
    },
    {
      "x": -6,
      "y": 4,
      "z": -3,
      "name": "Furniture_Tavern_Wardrobe",
      "rotation": 1
    },
    {
      "x": -6,
      "y": 5,
      "z": -3,
      "name": "Furniture_Tavern_Wardrobe",
      "filler": 1024,
      "rotation": 1
    },
    {
      "x": -6,
      "y": 6,
      "z": -3,
      "name": "Furniture_Village_Shelf_Full",
      "rotation": 1
    },
    {
      "x": -6,
      "y": 7,
      "z": -3,
      "name": "Wood_Hardwood_Planks_Half",
      "rotation": 5
    },
    {
      "x": -6,
      "y": 8,
      "z": -3,
      "name": "Wood_Hardwood_Planks"
    },
    {
      "x": -6,
      "y": 2,
      "z": -2,
      "name": "Rock_Stone_Cobble"
    },
    {
      "x": -6,
      "y": 3,
      "z": -2,
      "name": "Wood_Hardwood_Planks"
    },
    {
      "x": -6,
      "y": 4,
      "z": -2,
      "name": "Furniture_Tavern_Wardrobe",
      "filler": 32,
      "rotation": 1
    },
    {
      "x": -6,
      "y": 5,
      "z": -2,
      "name": "Furniture_Tavern_Wardrobe",
      "filler": 1056,
      "rotation": 1
    },
    {
      "x": -6,
      "y": 6,
      "z": -2,
      "name": "Deco_Lantern"
    },
    {
      "x": -6,
      "y": 7,
      "z": -2,
      "name": "Wood_Hardwood_Planks_Half",
      "rotation": 5
    },
    {
      "x": -6,
      "y": 8,
      "z": -2,
      "name": "Wood_Hardwood_Planks"
    },
    {
      "x": -6,
      "y": 2,
      "z": -1,
      "name": "Rock_Stone_Cobble"
    },
    {
      "x": -6,
      "y": 3,
      "z": -1,
      "name": "Wood_Hardwood_Planks"
    },
    {
      "x": -6,
      "y": 4,
      "z": -1,
      "name": "Furniture_Village_Planter"
    },
    {
      "x": -6,
      "y": 5,
      "z": -1,
      "name": "*Plant_Crop_Berry_Block_State_Definitions_StageFinal",
      "components": {
        "Components": {
          "FarmingBlock": {}
        }
      }
    },
    {
      "x": -6,
      "y": 6,
      "z": -1,
      "name": "*Plant_Crop_Berry_Block_State_Definitions_StageFinal",
      "components": {
        "Components": {
          "FarmingBlock": {}
        }
      }
    },
    {
      "x": -6,
      "y": 7,
      "z": -1,
      "name": "Wood_Hardwood_Planks_Half",
      "rotation": 5
    },
    {
      "x": -6,
      "y": 8,
      "z": -1,
      "name": "Wood_Hardwood_Planks"
    },
    {
      "x": -6,
      "y": 2,
      "z": 0,
      "name": "Rock_Stone_Cobble"
    },
    {
      "x": -6,
      "y": 3,
      "z": 0,
      "name": "Wood_Hardwood_Planks"
    },
    {
      "x": -6,
      "y": 4,
      "z": 0,
      "name": "Furniture_Village_Counter",
      "rotation": 1
    },
    {
      "x": -6,
      "y": 5,
      "z": 0,
      "name": "Furniture_Village_Bookcase",
      "rotation": 1
    },
    {
      "x": -6,
      "y": 6,
      "z": 0,
      "name": "Furniture_Village_Bookcase",
      "rotation": 1
    },
    {
      "x": -6,
      "y": 7,
      "z": 0,
      "name": "Wood_Hardwood_Planks_Half",
      "rotation": 5
    },
    {
      "x": -6,
      "y": 8,
      "z": 0,
      "name": "Wood_Hardwood_Planks"
    },
    {
      "x": -6,
      "y": 2,
      "z": 1,
      "name": "Rock_Stone_Cobble"
    },
    {
      "x": -6,
      "y": 3,
      "z": 1,
      "name": "Wood_Hardwood_Planks"
    },
    {
      "x": -6,
      "y": 4,
      "z": 1,
      "name": "Furniture_Village_Counter",
      "filler": 32,
      "rotation": 1
    },
    {
      "x": -6,
      "y": 5,
      "z": 1,
      "name": "Furniture_Village_Bookcase",
      "rotation": 1
    },
    {
      "x": -6,
      "y": 6,
      "z": 1,
      "name": "Furniture_Village_Bookcase",
      "rotation": 1
    },
    {
      "x": -6,
      "y": 7,
      "z": 1,
      "name": "Wood_Hardwood_Planks_Half",
      "rotation": 5
    },
    {
      "x": -6,
      "y": 8,
      "z": 1,
      "name": "Wood_Hardwood_Planks"
    },
    {
      "x": -6,
      "y": 2,
      "z": 2,
      "name": "Rock_Stone_Cobble"
    },
    {
      "x": -6,
      "y": 3,
      "z": 2,
      "name": "Wood_Hardwood_Planks"
    },
    {
      "x": -6,
      "y": 4,
      "z": 2,
      "name": "Furniture_Village_Shelf_Full",
      "rotation": 1
    },
    {
      "x": -6,
      "y": 5,
      "z": 2,
      "name": "Furniture_Village_Shelf_Full",
      "rotation": 1
    },
    {
      "x": -6,
      "y": 6,
      "z": 2,
      "name": "Furniture_Village_Shelf_Full",
      "rotation": 1
    },
    {
      "x": -6,
      "y": 7,
      "z": 2,
      "name": "Wood_Hardwood_Planks_Half",
      "rotation": 5
    },
    {
      "x": -6,
      "y": 8,
      "z": 2,
      "name": "Wood_Hardwood_Planks"
    },
    {
      "x": -6,
      "y": 2,
      "z": 3,
      "name": "Rock_Stone_Cobble"
    },
    {
      "x": -6,
      "y": 3,
      "z": 3,
      "name": "Wood_Hardwood_Planks"
    },
    {
      "x": -6,
      "y": 4,
      "z": 3,
      "name": "Furniture_Village_Shelf_Full",
      "rotation": 1
    },
    {
      "x": -6,
      "y": 5,
      "z": 3,
      "name": "Furniture_Village_Shelf_Full",
      "rotation": 1
    },
    {
      "x": -6,
      "y": 6,
      "z": 3,
      "name": "Furniture_Village_Shelf_Full",
      "rotation": 1
    },
    {
      "x": -6,
      "y": 7,
      "z": 3,
      "name": "Wood_Hardwood_Planks_Half",
      "rotation": 5
    },
    {
      "x": -6,
      "y": 8,
      "z": 3,
      "name": "Wood_Hardwood_Planks"
    },
    {
      "x": -6,
      "y": 2,
      "z": 4,
      "name": "Rock_Stone_Cobble"
    },
    {
      "x": -6,
      "y": 3,
      "z": 4,
      "name": "Wood_Hardwood_Planks"
    },
    {
      "x": -6,
      "y": 4,
      "z": 4,
      "name": "Empty"
    },
    {
      "x": -6,
      "y": 5,
      "z": 4,
      "name": "Empty"
    },
    {
      "x": -6,
      "y": 6,
      "z": 4,
      "name": "Empty"
    },
    {
      "x": -6,
      "y": 7,
      "z": 4,
      "name": "Wood_Hardwood_Planks_Half",
      "rotation": 5
    },
    {
      "x": -6,
      "y": 8,
      "z": 4,
      "name": "Wood_Hardwood_Planks"
    },
    {
      "x": -6,
      "y": 2,
      "z": 5,
      "name": "Rock_Stone_Cobble"
    },
    {
      "x": -6,
      "y": 3,
      "z": 5,
      "name": "Wood_Hardwood_Planks"
    },
    {
      "x": -6,
      "y": 4,
      "z": 5,
      "name": "Empty"
    },
    {
      "x": -6,
      "y": 5,
      "z": 5,
      "name": "Empty"
    },
    {
      "x": -6,
      "y": 6,
      "z": 5,
      "name": "Empty"
    },
    {
      "x": -6,
      "y": 7,
      "z": 5,
      "name": "Wood_Hardwood_Planks"
    },
    {
      "x": -6,
      "y": 8,
      "z": 5,
      "name": "Wood_Hardwood_Planks"
    },
    {
      "x": -6,
      "y": 2,
      "z": 6,
      "name": "Rock_Stone_Cobble"
    },
    {
      "x": -6,
      "y": 3,
      "z": 6,
      "name": "Rock_Stone_Cobble"
    },
    {
      "x": -6,
      "y": 4,
      "z": 6,
      "name": "Rock_Stone_Brick_Decorative"
    },
    {
      "x": -6,
      "y": 5,
      "z": 6,
      "name": "Rock_Stone_Cobble"
    },
    {
      "x": -6,
      "y": 6,
      "z": 6,
      "name": "Rock_Stone_Cobble"
    },
    {
      "x": -6,
      "y": 7,
      "z": 6,
      "name": "Rock_Stone_Cobble"
    },
    {
      "x": -6,
      "y": 8,
      "z": 6,
      "name": "Rock_Stone_Cobble"
    },
    {
      "x": -5,
      "y": 2,
      "z": -5,
      "name": "Rock_Stone_Cobble"
    },
    {
      "x": -5,
      "y": 3,
      "z": -5,
      "name": "Rock_Stone_Cobble"
    },
    {
      "x": -5,
      "y": 4,
      "z": -5,
      "name": "Rock_Stone_Brick_Decorative"
    },
    {
      "x": -5,
      "y": 5,
      "z": -5,
      "name": "Rock_Stone_Cobble"
    },
    {
      "x": -5,
      "y": 6,
      "z": -5,
      "name": "Rock_Stone_Cobble"
    },
    {
      "x": -5,
      "y": 7,
      "z": -5,
      "name": "Rock_Stone_Cobble"
    },
    {
      "x": -5,
      "y": 8,
      "z": -5,
      "name": "Rock_Stone_Cobble"
    },
    {
      "x": -5,
      "y": 2,
      "z": -4,
      "name": "Rock_Stone_Cobble"
    },
    {
      "x": -5,
      "y": 3,
      "z": -4,
      "name": "Wood_Hardwood_Planks"
    },
    {
      "x": -5,
      "y": 4,
      "z": -4,
      "name": "Empty"
    },
    {
      "x": -5,
      "y": 5,
      "z": -4,
      "name": "Empty"
    },
    {
      "x": -5,
      "y": 6,
      "z": -4,
      "name": "Empty"
    },
    {
      "x": -5,
      "y": 7,
      "z": -4,
      "name": "Wood_Hardwood_Planks_Half",
      "rotation": 4
    },
    {
      "x": -5,
      "y": 8,
      "z": -4,
      "name": "Wood_Hardwood_Planks"
    },
    {
      "x": -5,
      "y": 2,
      "z": -3,
      "name": "Rock_Stone_Cobble"
    },
    {
      "x": -5,
      "y": 3,
      "z": -3,
      "name": "Wood_Hardwood_Planks"
    },
    {
      "x": -5,
      "y": 4,
      "z": -3,
      "name": "Furniture_Tavern_Stool"
    },
    {
      "x": -5,
      "y": 5,
      "z": -3,
      "name": "Empty"
    },
    {
      "x": -5,
      "y": 6,
      "z": -3,
      "name": "Empty"
    },
    {
      "x": -5,
      "y": 7,
      "z": -3,
      "name": "Empty"
    },
    {
      "x": -5,
      "y": 8,
      "z": -3,
      "name": "Wood_Hardwood_Planks"
    },
    {
      "x": -5,
      "y": 2,
      "z": -2,
      "name": "Rock_Stone_Cobble"
    },
    {
      "x": -5,
      "y": 3,
      "z": -2,
      "name": "Wood_Hardwood_Planks"
    },
    {
      "x": -5,
      "y": 4,
      "z": -2,
      "name": "Empty"
    },
    {
      "x": -5,
      "y": 5,
      "z": -2,
      "name": "Empty"
    },
    {
      "x": -5,
      "y": 6,
      "z": -2,
      "name": "Empty"
    },
    {
      "x": -5,
      "y": 7,
      "z": -2,
      "name": "Empty"
    },
    {
      "x": -5,
      "y": 8,
      "z": -2,
      "name": "Wood_Hardwood_Planks"
    },
    {
      "x": -5,
      "y": 2,
      "z": -1,
      "name": "Rock_Stone_Cobble"
    },
    {
      "x": -5,
      "y": 3,
      "z": -1,
      "name": "Wood_Hardwood_Planks"
    },
    {
      "x": -5,
      "y": 4,
      "z": -1,
      "name": "Empty"
    },
    {
      "x": -5,
      "y": 5,
      "z": -1,
      "name": "Empty"
    },
    {
      "x": -5,
      "y": 6,
      "z": -1,
      "name": "Empty"
    },
    {
      "x": -5,
      "y": 7,
      "z": -1,
      "name": "Empty"
    },
    {
      "x": -5,
      "y": 8,
      "z": -1,
      "name": "Wood_Hardwood_Planks"
    },
    {
      "x": -5,
      "y": 2,
      "z": 0,
      "name": "Rock_Stone_Cobble"
    },
    {
      "x": -5,
      "y": 3,
      "z": 0,
      "name": "Wood_Hardwood_Planks"
    },
    {
      "x": -5,
      "y": 4,
      "z": 0,
      "name": "Empty"
    },
    {
      "x": -5,
      "y": 5,
      "z": 0,
      "name": "Empty"
    },
    {
      "x": -5,
      "y": 6,
      "z": 0,
      "name": "Empty"
    },
    {
      "x": -5,
      "y": 7,
      "z": 0,
      "name": "Empty"
    },
    {
      "x": -5,
      "y": 8,
      "z": 0,
      "name": "Wood_Hardwood_Planks"
    },
    {
      "x": -5,
      "y": 2,
      "z": 1,
      "name": "Rock_Stone_Cobble"
    },
    {
      "x": -5,
      "y": 3,
      "z": 1,
      "name": "Rock_Marble_Brick_Smooth"
    },
    {
      "x": -5,
      "y": 4,
      "z": 1,
      "name": "Empty"
    },
    {
      "x": -5,
      "y": 5,
      "z": 1,
      "name": "Empty"
    },
    {
      "x": -5,
      "y": 6,
      "z": 1,
      "name": "Empty"
    },
    {
      "x": -5,
      "y": 7,
      "z": 1,
      "name": "Empty"
    },
    {
      "x": -5,
      "y": 8,
      "z": 1,
      "name": "Wood_Hardwood_Planks"
    },
    {
      "x": -5,
      "y": 2,
      "z": 2,
      "name": "Rock_Stone_Cobble"
    },
    {
      "x": -5,
      "y": 3,
      "z": 2,
      "name": "Rock_Marble_Brick_Smooth"
    },
    {
      "x": -5,
      "y": 4,
      "z": 2,
      "name": "Furniture_Temple_Light_Bench",
      "rotation": 1
    },
    {
      "x": -5,
      "y": 5,
      "z": 2,
      "name": "Empty"
    },
    {
      "x": -5,
      "y": 6,
      "z": 2,
      "name": "Empty"
    },
    {
      "x": -5,
      "y": 7,
      "z": 2,
      "name": "Empty"
    },
    {
      "x": -5,
      "y": 8,
      "z": 2,
      "name": "Wood_Hardwood_Planks"
    },
    {
      "x": -5,
      "y": 2,
      "z": 3,
      "name": "Rock_Stone_Cobble"
    },
    {
      "x": -5,
      "y": 3,
      "z": 3,
      "name": "Rock_Marble_Brick_Smooth"
    },
    {
      "x": -5,
      "y": 4,
      "z": 3,
      "name": "Furniture_Temple_Light_Bench",
      "filler": 32,
      "rotation": 1
    },
    {
      "x": -5,
      "y": 5,
      "z": 3,
      "name": "Empty"
    },
    {
      "x": -5,
      "y": 6,
      "z": 3,
      "name": "Empty"
    },
    {
      "x": -5,
      "y": 7,
      "z": 3,
      "name": "Empty"
    },
    {
      "x": -5,
      "y": 8,
      "z": 3,
      "name": "Wood_Hardwood_Planks"
    },
    {
      "x": -5,
      "y": 2,
      "z": 4,
      "name": "Rock_Stone_Cobble"
    },
    {
      "x": -5,
      "y": 3,
      "z": 4,
      "name": "Rock_Marble_Brick_Smooth"
    },
    {
      "x": -5,
      "y": 4,
      "z": 4,
      "name": "Rock_Marble_Cobble_Wall",
      "rotation": 1
    },
    {
      "x": -5,
      "y": 5,
      "z": 4,
      "name": "Empty"
    },
    {
      "x": -5,
      "y": 6,
      "z": 4,
      "name": "Empty"
    },
    {
      "x": -5,
      "y": 7,
      "z": 4,
      "name": "Empty"
    },
    {
      "x": -5,
      "y": 8,
      "z": 4,
      "name": "Wood_Hardwood_Planks"
    },
    {
      "x": -5,
      "y": 2,
      "z": 5,
      "name": "Rock_Stone_Cobble"
    },
    {
      "x": -5,
      "y": 3,
      "z": 5,
      "name": "Rock_Marble_Brick_Smooth"
    },
    {
      "x": -5,
      "y": 4,
      "z": 5,
      "name": "Rock_Marble_Cobble_Wall",
      "rotation": 1
    },
    {
      "x": -5,
      "y": 5,
      "z": 5,
      "name": "Empty"
    },
    {
      "x": -5,
      "y": 6,
      "z": 5,
      "name": "Empty"
    },
    {
      "x": -5,
      "y": 7,
      "z": 5,
      "name": "Wood_Hardwood_Planks_Half",
      "rotation": 6
    },
    {
      "x": -5,
      "y": 8,
      "z": 5,
      "name": "Wood_Hardwood_Planks"
    },
    {
      "x": -5,
      "y": 2,
      "z": 6,
      "name": "Rock_Stone_Cobble"
    },
    {
      "x": -5,
      "y": 3,
      "z": 6,
      "name": "Rock_Marble_Brick_Smooth"
    },
    {
      "x": -5,
      "y": 4,
      "z": 6,
      "name": "Rock_Marble_Brick_Smooth"
    },
    {
      "x": -5,
      "y": 5,
      "z": 6,
      "name": "Rock_Marble_Brick_Smooth"
    },
    {
      "x": -5,
      "y": 6,
      "z": 6,
      "name": "Rock_Stone_Cobble"
    },
    {
      "x": -5,
      "y": 7,
      "z": 6,
      "name": "Rock_Stone_Cobble"
    },
    {
      "x": -5,
      "y": 8,
      "z": 6,
      "name": "Rock_Stone_Cobble"
    },
    {
      "x": -4,
      "y": 2,
      "z": -5,
      "name": "Rock_Stone_Cobble"
    },
    {
      "x": -4,
      "y": 3,
      "z": -5,
      "name": "Rock_Stone_Cobble"
    },
    {
      "x": -4,
      "y": 4,
      "z": -5,
      "name": "Rock_Stone_Brick_Decorative"
    },
    {
      "x": -4,
      "y": 5,
      "z": -5,
      "name": "Rock_Stone_Cobble"
    },
    {
      "x": -4,
      "y": 6,
      "z": -5,
      "name": "Rock_Stone_Cobble"
    },
    {
      "x": -4,
      "y": 7,
      "z": -5,
      "name": "Rock_Stone_Cobble"
    },
    {
      "x": -4,
      "y": 8,
      "z": -5,
      "name": "Rock_Stone_Cobble"
    },
    {
      "x": -4,
      "y": 2,
      "z": -4,
      "name": "Rock_Stone_Cobble"
    },
    {
      "x": -4,
      "y": 3,
      "z": -4,
      "name": "Wood_Hardwood_Planks"
    },
    {
      "x": -4,
      "y": 4,
      "z": -4,
      "name": "Alchemy_Cauldron"
    },
    {
      "x": -4,
      "y": 5,
      "z": -4,
      "name": "Empty"
    },
    {
      "x": -4,
      "y": 6,
      "z": -4,
      "name": "Empty"
    },
    {
      "x": -4,
      "y": 7,
      "z": -4,
      "name": "Wood_Hardwood_Planks_Half",
      "rotation": 4
    },
    {
      "x": -4,
      "y": 8,
      "z": -4,
      "name": "Wood_Hardwood_Planks"
    },
    {
      "x": -4,
      "y": 2,
      "z": -3,
      "name": "Rock_Stone_Cobble"
    },
    {
      "x": -4,
      "y": 3,
      "z": -3,
      "name": "Wood_Hardwood_Planks"
    },
    {
      "x": -4,
      "y": 4,
      "z": -3,
      "name": "Empty"
    },
    {
      "x": -4,
      "y": 5,
      "z": -3,
      "name": "Empty"
    },
    {
      "x": -4,
      "y": 6,
      "z": -3,
      "name": "Empty"
    },
    {
      "x": -4,
      "y": 7,
      "z": -3,
      "name": "Empty"
    },
    {
      "x": -4,
      "y": 8,
      "z": -3,
      "name": "Wood_Hardwood_Planks"
    },
    {
      "x": -4,
      "y": 2,
      "z": -2,
      "name": "Rock_Stone_Cobble"
    },
    {
      "x": -4,
      "y": 3,
      "z": -2,
      "name": "Wood_Hardwood_Planks"
    },
    {
      "x": -4,
      "y": 4,
      "z": -2,
      "name": "Empty"
    },
    {
      "x": -4,
      "y": 5,
      "z": -2,
      "name": "Empty"
    },
    {
      "x": -4,
      "y": 6,
      "z": -2,
      "name": "Empty"
    },
    {
      "x": -4,
      "y": 7,
      "z": -2,
      "name": "Empty"
    },
    {
      "x": -4,
      "y": 8,
      "z": -2,
      "name": "Wood_Hardwood_Planks"
    },
    {
      "x": -4,
      "y": 2,
      "z": -1,
      "name": "Rock_Stone_Cobble"
    },
    {
      "x": -4,
      "y": 3,
      "z": -1,
      "name": "Wood_Hardwood_Planks"
    },
    {
      "x": -4,
      "y": 4,
      "z": -1,
      "name": "Empty"
    },
    {
      "x": -4,
      "y": 5,
      "z": -1,
      "name": "Empty"
    },
    {
      "x": -4,
      "y": 6,
      "z": -1,
      "name": "Empty"
    },
    {
      "x": -4,
      "y": 7,
      "z": -1,
      "name": "Empty"
    },
    {
      "x": -4,
      "y": 8,
      "z": -1,
      "name": "Wood_Hardwood_Planks"
    },
    {
      "x": -4,
      "y": 2,
      "z": 0,
      "name": "Rock_Stone_Cobble"
    },
    {
      "x": -4,
      "y": 3,
      "z": 0,
      "name": "Wood_Hardwood_Planks"
    },
    {
      "x": -4,
      "y": 4,
      "z": 0,
      "name": "Empty"
    },
    {
      "x": -4,
      "y": 5,
      "z": 0,
      "name": "Empty"
    },
    {
      "x": -4,
      "y": 6,
      "z": 0,
      "name": "Empty"
    },
    {
      "x": -4,
      "y": 7,
      "z": 0,
      "name": "Empty"
    },
    {
      "x": -4,
      "y": 8,
      "z": 0,
      "name": "Wood_Hardwood_Planks"
    },
    {
      "x": -4,
      "y": 2,
      "z": 1,
      "name": "Rock_Stone_Cobble"
    },
    {
      "x": -4,
      "y": 3,
      "z": 1,
      "name": "Rock_Marble_Brick_Smooth"
    },
    {
      "x": -4,
      "y": 4,
      "z": 1,
      "name": "Empty"
    },
    {
      "x": -4,
      "y": 5,
      "z": 1,
      "name": "Empty"
    },
    {
      "x": -4,
      "y": 6,
      "z": 1,
      "name": "Empty"
    },
    {
      "x": -4,
      "y": 7,
      "z": 1,
      "name": "Empty"
    },
    {
      "x": -4,
      "y": 8,
      "z": 1,
      "name": "Wood_Hardwood_Planks"
    },
    {
      "x": -4,
      "y": 2,
      "z": 2,
      "name": "Rock_Marble_Brick_Smooth"
    },
    {
      "x": -4,
      "y": 4,
      "z": 2,
      "name": "Empty"
    },
    {
      "x": -4,
      "y": 5,
      "z": 2,
      "name": "Empty"
    },
    {
      "x": -4,
      "y": 6,
      "z": 2,
      "name": "Empty"
    },
    {
      "x": -4,
      "y": 7,
      "z": 2,
      "name": "Empty"
    },
    {
      "x": -4,
      "y": 8,
      "z": 2,
      "name": "Wood_Hardwood_Planks"
    },
    {
      "x": -4,
      "y": 2,
      "z": 3,
      "name": "Rock_Marble_Brick_Smooth"
    },
    {
      "x": -4,
      "y": 4,
      "z": 3,
      "name": "Empty"
    },
    {
      "x": -4,
      "y": 5,
      "z": 3,
      "name": "Empty"
    },
    {
      "x": -4,
      "y": 6,
      "z": 3,
      "name": "Empty"
    },
    {
      "x": -4,
      "y": 7,
      "z": 3,
      "name": "Empty"
    },
    {
      "x": -4,
      "y": 8,
      "z": 3,
      "name": "Wood_Hardwood_Planks"
    },
    {
      "x": -4,
      "y": 2,
      "z": 4,
      "name": "Rock_Marble_Brick_Smooth"
    },
    {
      "x": -4,
      "y": 4,
      "z": 4,
      "name": "Empty"
    },
    {
      "x": -4,
      "y": 5,
      "z": 4,
      "name": "Empty"
    },
    {
      "x": -4,
      "y": 6,
      "z": 4,
      "name": "Empty"
    },
    {
      "x": -4,
      "y": 7,
      "z": 4,
      "name": "Empty"
    },
    {
      "x": -4,
      "y": 8,
      "z": 4,
      "name": "Wood_Hardwood_Planks"
    },
    {
      "x": -4,
      "y": 2,
      "z": 5,
      "name": "Rock_Marble_Brick_Smooth"
    },
    {
      "x": -4,
      "y": 4,
      "z": 5,
      "name": "Empty"
    },
    {
      "x": -4,
      "y": 5,
      "z": 5,
      "name": "Empty"
    },
    {
      "x": -4,
      "y": 6,
      "z": 5,
      "name": "Empty"
    },
    {
      "x": -4,
      "y": 7,
      "z": 5,
      "name": "Wood_Hardwood_Planks_Half",
      "rotation": 6
    },
    {
      "x": -4,
      "y": 8,
      "z": 5,
      "name": "Wood_Hardwood_Planks"
    },
    {
      "x": -4,
      "y": 2,
      "z": 6,
      "name": "Rock_Stone_Cobble"
    },
    {
      "x": -4,
      "y": 3,
      "z": 6,
      "name": "Rock_Marble_Brick_Smooth"
    },
    {
      "x": -4,
      "y": 4,
      "z": 6,
      "name": "Rock_Marble_Brick_Smooth"
    },
    {
      "x": -4,
      "y": 5,
      "z": 6,
      "name": "Rock_Marble_Brick_Smooth"
    },
    {
      "x": -4,
      "y": 6,
      "z": 6,
      "name": "Rock_Marble_Brick_Smooth"
    },
    {
      "x": -4,
      "y": 7,
      "z": 6,
      "name": "Rock_Stone_Cobble"
    },
    {
      "x": -4,
      "y": 8,
      "z": 6,
      "name": "Rock_Stone_Cobble"
    },
    {
      "x": -3,
      "y": 2,
      "z": -5,
      "name": "Rock_Stone_Cobble"
    },
    {
      "x": -3,
      "y": 3,
      "z": -5,
      "name": "Rock_Stone_Cobble"
    },
    {
      "x": -3,
      "y": 4,
      "z": -5,
      "name": "Rock_Stone_Brick_Decorative"
    },
    {
      "x": -3,
      "y": 5,
      "z": -5,
      "name": "Rock_Stone_Cobble"
    },
    {
      "x": -3,
      "y": 6,
      "z": -5,
      "name": "Rock_Stone_Cobble"
    },
    {
      "x": -3,
      "y": 7,
      "z": -5,
      "name": "Rock_Stone_Cobble"
    },
    {
      "x": -3,
      "y": 8,
      "z": -5,
      "name": "Rock_Stone_Cobble"
    },
    {
      "x": -3,
      "y": 2,
      "z": -4,
      "name": "Rock_Stone_Cobble"
    },
    {
      "x": -3,
      "y": 3,
      "z": -4,
      "name": "Wood_Hardwood_Planks"
    },
    {
      "x": -3,
      "y": 4,
      "z": -4,
      "name": "Furniture_Lumberjack_Shelf"
    },
    {
      "x": -3,
      "y": 5,
      "z": -4,
      "name": "Potion_Purify"
    },
    {
      "x": -3,
      "y": 6,
      "z": -4,
      "name": "Empty"
    },
    {
      "x": -3,
      "y": 7,
      "z": -4,
      "name": "Wood_Hardwood_Planks_Half",
      "rotation": 4
    },
    {
      "x": -3,
      "y": 8,
      "z": -4,
      "name": "Wood_Hardwood_Planks"
    },
    {
      "x": -3,
      "y": 2,
      "z": -3,
      "name": "Rock_Stone_Cobble"
    },
    {
      "x": -3,
      "y": 3,
      "z": -3,
      "name": "Wood_Hardwood_Planks"
    },
    {
      "x": -3,
      "y": 4,
      "z": -3,
      "name": "Empty"
    },
    {
      "x": -3,
      "y": 5,
      "z": -3,
      "name": "Empty"
    },
    {
      "x": -3,
      "y": 6,
      "z": -3,
      "name": "Empty"
    },
    {
      "x": -3,
      "y": 7,
      "z": -3,
      "name": "Empty"
    },
    {
      "x": -3,
      "y": 8,
      "z": -3,
      "name": "Wood_Hardwood_Planks"
    },
    {
      "x": -3,
      "y": 2,
      "z": -2,
      "name": "Rock_Stone_Cobble"
    },
    {
      "x": -3,
      "y": 3,
      "z": -2,
      "name": "Wood_Hardwood_Planks"
    },
    {
      "x": -3,
      "y": 4,
      "z": -2,
      "name": "Empty"
    },
    {
      "x": -3,
      "y": 5,
      "z": -2,
      "name": "Empty"
    },
    {
      "x": -3,
      "y": 6,
      "z": -2,
      "name": "Empty"
    },
    {
      "x": -3,
      "y": 7,
      "z": -2,
      "name": "Empty"
    },
    {
      "x": -3,
      "y": 8,
      "z": -2,
      "name": "Wood_Hardwood_Planks"
    },
    {
      "x": -3,
      "y": 2,
      "z": -1,
      "name": "Rock_Stone_Cobble"
    },
    {
      "x": -3,
      "y": 3,
      "z": -1,
      "name": "Wood_Hardwood_Planks"
    },
    {
      "x": -3,
      "y": 4,
      "z": -1,
      "name": "Empty"
    },
    {
      "x": -3,
      "y": 5,
      "z": -1,
      "name": "Empty"
    },
    {
      "x": -3,
      "y": 6,
      "z": -1,
      "name": "Empty"
    },
    {
      "x": -3,
      "y": 7,
      "z": -1,
      "name": "Empty"
    },
    {
      "x": -3,
      "y": 8,
      "z": -1,
      "name": "Wood_Hardwood_Planks"
    },
    {
      "x": -3,
      "y": 2,
      "z": 0,
      "name": "Rock_Stone_Cobble"
    },
    {
      "x": -3,
      "y": 3,
      "z": 0,
      "name": "Wood_Hardwood_Planks"
    },
    {
      "x": -3,
      "y": 4,
      "z": 0,
      "name": "Empty"
    },
    {
      "x": -3,
      "y": 5,
      "z": 0,
      "name": "Empty"
    },
    {
      "x": -3,
      "y": 6,
      "z": 0,
      "name": "Empty"
    },
    {
      "x": -3,
      "y": 7,
      "z": 0,
      "name": "Empty"
    },
    {
      "x": -3,
      "y": 8,
      "z": 0,
      "name": "Wood_Hardwood_Planks"
    },
    {
      "x": -3,
      "y": 2,
      "z": 1,
      "name": "Rock_Stone_Cobble"
    },
    {
      "x": -3,
      "y": 3,
      "z": 1,
      "name": "Rock_Marble_Brick_Smooth"
    },
    {
      "x": -3,
      "y": 4,
      "z": 1,
      "name": "Empty"
    },
    {
      "x": -3,
      "y": 5,
      "z": 1,
      "name": "Empty"
    },
    {
      "x": -3,
      "y": 6,
      "z": 1,
      "name": "Empty"
    },
    {
      "x": -3,
      "y": 7,
      "z": 1,
      "name": "Empty"
    },
    {
      "x": -3,
      "y": 8,
      "z": 1,
      "name": "Wood_Hardwood_Planks"
    },
    {
      "x": -3,
      "y": 2,
      "z": 2,
      "name": "Rock_Marble_Brick_Smooth"
    },
    {
      "x": -3,
      "y": 4,
      "z": 2,
      "name": "Empty"
    },
    {
      "x": -3,
      "y": 5,
      "z": 2,
      "name": "Empty"
    },
    {
      "x": -3,
      "y": 6,
      "z": 2,
      "name": "Empty"
    },
    {
      "x": -3,
      "y": 7,
      "z": 2,
      "name": "Empty"
    },
    {
      "x": -3,
      "y": 8,
      "z": 2,
      "name": "Wood_Hardwood_Planks"
    },
    {
      "x": -3,
      "y": 2,
      "z": 3,
      "name": "Rock_Marble_Brick_Smooth"
    },
    {
      "x": -3,
      "y": 4,
      "z": 3,
      "name": "Empty"
    },
    {
      "x": -3,
      "y": 5,
      "z": 3,
      "name": "Empty"
    },
    {
      "x": -3,
      "y": 6,
      "z": 3,
      "name": "Empty"
    },
    {
      "x": -3,
      "y": 7,
      "z": 3,
      "name": "Empty"
    },
    {
      "x": -3,
      "y": 8,
      "z": 3,
      "name": "Wood_Hardwood_Planks"
    },
    {
      "x": -3,
      "y": 2,
      "z": 4,
      "name": "Rock_Marble_Brick_Smooth"
    },
    {
      "x": -3,
      "y": 4,
      "z": 4,
      "name": "Empty"
    },
    {
      "x": -3,
      "y": 5,
      "z": 4,
      "name": "Empty"
    },
    {
      "x": -3,
      "y": 6,
      "z": 4,
      "name": "Empty"
    },
    {
      "x": -3,
      "y": 7,
      "z": 4,
      "name": "Empty"
    },
    {
      "x": -3,
      "y": 8,
      "z": 4,
      "name": "Wood_Hardwood_Planks"
    },
    {
      "x": -3,
      "y": 2,
      "z": 5,
      "name": "Rock_Marble_Brick_Smooth"
    },
    {
      "x": -3,
      "y": 4,
      "z": 5,
      "name": "Empty"
    },
    {
      "x": -3,
      "y": 5,
      "z": 5,
      "name": "Empty"
    },
    {
      "x": -3,
      "y": 6,
      "z": 5,
      "name": "Empty"
    },
    {
      "x": -3,
      "y": 7,
      "z": 5,
      "name": "Wood_Hardwood_Planks_Half",
      "rotation": 6
    },
    {
      "x": -3,
      "y": 8,
      "z": 5,
      "name": "Wood_Hardwood_Planks"
    },
    {
      "x": -3,
      "y": 2,
      "z": 6,
      "name": "Rock_Stone_Cobble"
    },
    {
      "x": -3,
      "y": 3,
      "z": 6,
      "name": "Rock_Marble_Brick_Smooth"
    },
    {
      "x": -3,
      "y": 4,
      "z": 6,
      "name": "Rock_Marble_Brick_Smooth"
    },
    {
      "x": -3,
      "y": 5,
      "z": 6,
      "name": "Rock_Marble_Brick_Smooth"
    },
    {
      "x": -3,
      "y": 6,
      "z": 6,
      "name": "Rock_Marble_Brick_Smooth"
    },
    {
      "x": -3,
      "y": 7,
      "z": 6,
      "name": "Rock_Stone_Cobble"
    },
    {
      "x": -3,
      "y": 8,
      "z": 6,
      "name": "Rock_Stone_Cobble"
    },
    {
      "x": -2,
      "y": 2,
      "z": -5,
      "name": "Rock_Stone_Cobble"
    },
    {
      "x": -2,
      "y": 3,
      "z": -5,
      "name": "Rock_Stone_Cobble"
    },
    {
      "x": -2,
      "y": 4,
      "z": -5,
      "name": "Rock_Stone_Brick_Decorative"
    },
    {
      "x": -2,
      "y": 5,
      "z": -5,
      "name": "Rock_Stone_Cobble"
    },
    {
      "x": -2,
      "y": 6,
      "z": -5,
      "name": "Rock_Stone_Cobble"
    },
    {
      "x": -2,
      "y": 7,
      "z": -5,
      "name": "Rock_Stone_Cobble"
    },
    {
      "x": -2,
      "y": 8,
      "z": -5,
      "name": "Rock_Stone_Cobble"
    },
    {
      "x": -2,
      "y": 2,
      "z": -4,
      "name": "Rock_Stone_Cobble"
    },
    {
      "x": -2,
      "y": 3,
      "z": -4,
      "name": "Wood_Hardwood_Planks"
    },
    {
      "x": -2,
      "y": 4,
      "z": -4,
      "name": "Furniture_Lumberjack_Shelf"
    },
    {
      "x": -2,
      "y": 5,
      "z": -4,
      "name": "Empty"
    },
    {
      "x": -2,
      "y": 6,
      "z": -4,
      "name": "Empty"
    },
    {
      "x": -2,
      "y": 7,
      "z": -4,
      "name": "Wood_Hardwood_Planks_Half",
      "rotation": 4
    },
    {
      "x": -2,
      "y": 8,
      "z": -4,
      "name": "Wood_Hardwood_Planks"
    },
    {
      "x": -2,
      "y": 2,
      "z": -3,
      "name": "Rock_Stone_Cobble"
    },
    {
      "x": -2,
      "y": 3,
      "z": -3,
      "name": "Wood_Hardwood_Planks"
    },
    {
      "x": -2,
      "y": 4,
      "z": -3,
      "name": "Furniture_Tavern_Stool"
    },
    {
      "x": -2,
      "y": 5,
      "z": -3,
      "name": "Empty"
    },
    {
      "x": -2,
      "y": 6,
      "z": -3,
      "name": "Empty"
    },
    {
      "x": -2,
      "y": 7,
      "z": -3,
      "name": "Empty"
    },
    {
      "x": -2,
      "y": 8,
      "z": -3,
      "name": "Wood_Hardwood_Planks"
    },
    {
      "x": -2,
      "y": 2,
      "z": -2,
      "name": "Rock_Stone_Cobble"
    },
    {
      "x": -2,
      "y": 3,
      "z": -2,
      "name": "Wood_Hardwood_Planks"
    },
    {
      "x": -2,
      "y": 4,
      "z": -2,
      "name": "Furniture_Tavern_Stool"
    },
    {
      "x": -2,
      "y": 5,
      "z": -2,
      "name": "Empty"
    },
    {
      "x": -2,
      "y": 6,
      "z": -2,
      "name": "Empty"
    },
    {
      "x": -2,
      "y": 7,
      "z": -2,
      "name": "Empty"
    },
    {
      "x": -2,
      "y": 8,
      "z": -2,
      "name": "Wood_Hardwood_Planks"
    },
    {
      "x": -2,
      "y": 2,
      "z": -1,
      "name": "Rock_Stone_Cobble"
    },
    {
      "x": -2,
      "y": 3,
      "z": -1,
      "name": "Wood_Hardwood_Planks"
    },
    {
      "x": -2,
      "y": 4,
      "z": -1,
      "name": "Empty"
    },
    {
      "x": -2,
      "y": 5,
      "z": -1,
      "name": "Empty"
    },
    {
      "x": -2,
      "y": 6,
      "z": -1,
      "name": "Empty"
    },
    {
      "x": -2,
      "y": 7,
      "z": -1,
      "name": "Empty"
    },
    {
      "x": -2,
      "y": 8,
      "z": -1,
      "name": "Wood_Hardwood_Planks"
    },
    {
      "x": -2,
      "y": 2,
      "z": 0,
      "name": "Rock_Stone_Cobble"
    },
    {
      "x": -2,
      "y": 3,
      "z": 0,
      "name": "Wood_Hardwood_Planks"
    },
    {
      "x": -2,
      "y": 4,
      "z": 0,
      "name": "Empty"
    },
    {
      "x": -2,
      "y": 5,
      "z": 0,
      "name": "Empty"
    },
    {
      "x": -2,
      "y": 6,
      "z": 0,
      "name": "Empty"
    },
    {
      "x": -2,
      "y": 7,
      "z": 0,
      "name": "Empty"
    },
    {
      "x": -2,
      "y": 8,
      "z": 0,
      "name": "Wood_Hardwood_Planks"
    },
    {
      "x": -2,
      "y": 2,
      "z": 1,
      "name": "Rock_Stone_Cobble"
    },
    {
      "x": -2,
      "y": 3,
      "z": 1,
      "name": "Rock_Marble_Brick_Smooth"
    },
    {
      "x": -2,
      "y": 4,
      "z": 1,
      "name": "Empty"
    },
    {
      "x": -2,
      "y": 5,
      "z": 1,
      "name": "Empty"
    },
    {
      "x": -2,
      "y": 6,
      "z": 1,
      "name": "Empty"
    },
    {
      "x": -2,
      "y": 7,
      "z": 1,
      "name": "Empty"
    },
    {
      "x": -2,
      "y": 8,
      "z": 1,
      "name": "Wood_Hardwood_Planks"
    },
    {
      "x": -2,
      "y": 2,
      "z": 2,
      "name": "Rock_Stone_Cobble"
    },
    {
      "x": -2,
      "y": 3,
      "z": 2,
      "name": "Rock_Marble_Brick_Smooth"
    },
    {
      "x": -2,
      "y": 4,
      "z": 2,
      "name": "Rock_Marble_Cobble_Wall",
      "rotation": 1
    },
    {
      "x": -2,
      "y": 5,
      "z": 2,
      "name": "Empty"
    },
    {
      "x": -2,
      "y": 6,
      "z": 2,
      "name": "Empty"
    },
    {
      "x": -2,
      "y": 7,
      "z": 2,
      "name": "Empty"
    },
    {
      "x": -2,
      "y": 8,
      "z": 2,
      "name": "Wood_Hardwood_Planks"
    },
    {
      "x": -2,
      "y": 2,
      "z": 3,
      "name": "Rock_Stone_Cobble"
    },
    {
      "x": -2,
      "y": 3,
      "z": 3,
      "name": "Rock_Marble_Brick_Smooth"
    },
    {
      "x": -2,
      "y": 4,
      "z": 3,
      "name": "Rock_Marble_Cobble_Wall",
      "rotation": 1
    },
    {
      "x": -2,
      "y": 5,
      "z": 3,
      "name": "Empty"
    },
    {
      "x": -2,
      "y": 6,
      "z": 3,
      "name": "Empty"
    },
    {
      "x": -2,
      "y": 7,
      "z": 3,
      "name": "Empty"
    },
    {
      "x": -2,
      "y": 8,
      "z": 3,
      "name": "Wood_Hardwood_Planks"
    },
    {
      "x": -2,
      "y": 2,
      "z": 4,
      "name": "Rock_Stone_Cobble"
    },
    {
      "x": -2,
      "y": 3,
      "z": 4,
      "name": "Rock_Marble_Brick_Smooth"
    },
    {
      "x": -2,
      "y": 4,
      "z": 4,
      "name": "Rock_Marble_Cobble_Wall",
      "rotation": 1
    },
    {
      "x": -2,
      "y": 5,
      "z": 4,
      "name": "Empty"
    },
    {
      "x": -2,
      "y": 6,
      "z": 4,
      "name": "Empty"
    },
    {
      "x": -2,
      "y": 7,
      "z": 4,
      "name": "Empty"
    },
    {
      "x": -2,
      "y": 8,
      "z": 4,
      "name": "Wood_Hardwood_Planks"
    },
    {
      "x": -2,
      "y": 2,
      "z": 5,
      "name": "Rock_Stone_Cobble"
    },
    {
      "x": -2,
      "y": 3,
      "z": 5,
      "name": "Rock_Marble_Brick_Smooth"
    },
    {
      "x": -2,
      "y": 4,
      "z": 5,
      "name": "Rock_Marble_Cobble_Wall",
      "rotation": 1
    },
    {
      "x": -2,
      "y": 5,
      "z": 5,
      "name": "Empty"
    },
    {
      "x": -2,
      "y": 6,
      "z": 5,
      "name": "Empty"
    },
    {
      "x": -2,
      "y": 7,
      "z": 5,
      "name": "Wood_Hardwood_Planks_Half",
      "rotation": 6
    },
    {
      "x": -2,
      "y": 8,
      "z": 5,
      "name": "Wood_Hardwood_Planks"
    },
    {
      "x": -2,
      "y": 2,
      "z": 6,
      "name": "Rock_Stone_Cobble"
    },
    {
      "x": -2,
      "y": 3,
      "z": 6,
      "name": "Rock_Marble_Brick_Smooth"
    },
    {
      "x": -2,
      "y": 4,
      "z": 6,
      "name": "Rock_Marble_Brick_Smooth"
    },
    {
      "x": -2,
      "y": 5,
      "z": 6,
      "name": "Rock_Marble_Brick_Smooth"
    },
    {
      "x": -2,
      "y": 6,
      "z": 6,
      "name": "Rock_Stone_Cobble"
    },
    {
      "x": -2,
      "y": 7,
      "z": 6,
      "name": "Rock_Stone_Cobble"
    },
    {
      "x": -2,
      "y": 8,
      "z": 6,
      "name": "Rock_Stone_Cobble"
    },
    {
      "x": -1,
      "y": 2,
      "z": -5,
      "name": "Rock_Stone_Cobble"
    },
    {
      "x": -1,
      "y": 3,
      "z": -5,
      "name": "Rock_Stone_Cobble"
    },
    {
      "x": -1,
      "y": 4,
      "z": -5,
      "name": "Rock_Stone_Brick_Decorative"
    },
    {
      "x": -1,
      "y": 5,
      "z": -5,
      "name": "Rock_Stone_Cobble"
    },
    {
      "x": -1,
      "y": 6,
      "z": -5,
      "name": "Rock_Stone_Cobble"
    },
    {
      "x": -1,
      "y": 7,
      "z": -5,
      "name": "Rock_Stone_Cobble"
    },
    {
      "x": -1,
      "y": 8,
      "z": -5,
      "name": "Rock_Stone_Cobble"
    },
    {
      "x": -1,
      "y": 2,
      "z": -4,
      "name": "Rock_Stone_Cobble"
    },
    {
      "x": -1,
      "y": 3,
      "z": -4,
      "name": "Wood_Hardwood_Planks"
    },
    {
      "x": -1,
      "y": 4,
      "z": -4,
      "name": "Furniture_Village_Shelf_Full"
    },
    {
      "x": -1,
      "y": 5,
      "z": -4,
      "name": "Furniture_Village_Shelf_Full"
    },
    {
      "x": -1,
      "y": 6,
      "z": -4,
      "name": "Furniture_Village_Shelf_Full"
    },
    {
      "x": -1,
      "y": 7,
      "z": -4,
      "name": "Wood_Hardwood_Planks"
    },
    {
      "x": -1,
      "y": 8,
      "z": -4,
      "name": "Wood_Hardwood_Planks"
    },
    {
      "x": -1,
      "y": 2,
      "z": -3,
      "name": "Rock_Stone_Cobble"
    },
    {
      "x": -1,
      "y": 3,
      "z": -3,
      "name": "Wood_Hardwood_Planks"
    },
    {
      "x": -1,
      "y": 4,
      "z": -3,
      "name": "Furniture_Village_Counter",
      "filler": 992,
      "rotation": 3
    },
    {
      "x": -1,
      "y": 5,
      "z": -3,
      "name": "Furniture_Tavern_Candle"
    },
    {
      "x": -1,
      "y": 6,
      "z": -3,
      "name": "Empty"
    },
    {
      "x": -1,
      "y": 7,
      "z": -3,
      "name": "Wood_Hardwood_Planks_Half",
      "rotation": 7
    },
    {
      "x": -1,
      "y": 8,
      "z": -3,
      "name": "Wood_Hardwood_Planks"
    },
    {
      "x": -1,
      "y": 2,
      "z": -2,
      "name": "Rock_Stone_Cobble"
    },
    {
      "x": -1,
      "y": 3,
      "z": -2,
      "name": "Wood_Hardwood_Planks"
    },
    {
      "x": -1,
      "y": 4,
      "z": -2,
      "name": "Furniture_Village_Counter",
      "rotation": 3
    },
    {
      "x": -1,
      "y": 5,
      "z": -2,
      "name": "Potion_Health_Small"
    },
    {
      "x": -1,
      "y": 6,
      "z": -2,
      "name": "Empty"
    },
    {
      "x": -1,
      "y": 7,
      "z": -2,
      "name": "Wood_Hardwood_Planks_Half",
      "rotation": 7
    },
    {
      "x": -1,
      "y": 8,
      "z": -2,
      "name": "Wood_Hardwood_Planks"
    },
    {
      "x": -1,
      "y": 2,
      "z": -1,
      "name": "Rock_Stone_Cobble"
    },
    {
      "x": -1,
      "y": 3,
      "z": -1,
      "name": "Wood_Hardwood_Planks"
    },
    {
      "x": -1,
      "y": 4,
      "z": -1,
      "name": "Empty"
    },
    {
      "x": -1,
      "y": 5,
      "z": -1,
      "name": "Empty"
    },
    {
      "x": -1,
      "y": 6,
      "z": -1,
      "name": "Empty"
    },
    {
      "x": -1,
      "y": 7,
      "z": -1,
      "name": "Wood_Hardwood_Planks_Half",
      "rotation": 7
    },
    {
      "x": -1,
      "y": 8,
      "z": -1,
      "name": "Wood_Hardwood_Planks"
    },
    {
      "x": -1,
      "y": 2,
      "z": 0,
      "name": "Rock_Stone_Cobble"
    },
    {
      "x": -1,
      "y": 3,
      "z": 0,
      "name": "Wood_Hardwood_Planks"
    },
    {
      "x": -1,
      "y": 4,
      "z": 0,
      "name": "Empty"
    },
    {
      "x": -1,
      "y": 5,
      "z": 0,
      "name": "Empty"
    },
    {
      "x": -1,
      "y": 6,
      "z": 0,
      "name": "Empty"
    },
    {
      "x": -1,
      "y": 7,
      "z": 0,
      "name": "Wood_Hardwood_Planks_Half",
      "rotation": 7
    },
    {
      "x": -1,
      "y": 8,
      "z": 0,
      "name": "Wood_Hardwood_Planks"
    },
    {
      "x": -1,
      "y": 2,
      "z": 1,
      "name": "Rock_Stone_Cobble"
    },
    {
      "x": -1,
      "y": 3,
      "z": 1,
      "name": "Wood_Hardwood_Planks"
    },
    {
      "x": -1,
      "y": 4,
      "z": 1,
      "name": "Empty"
    },
    {
      "x": -1,
      "y": 5,
      "z": 1,
      "name": "Empty"
    },
    {
      "x": -1,
      "y": 6,
      "z": 1,
      "name": "Empty"
    },
    {
      "x": -1,
      "y": 7,
      "z": 1,
      "name": "Wood_Hardwood_Planks_Half",
      "rotation": 7
    },
    {
      "x": -1,
      "y": 8,
      "z": 1,
      "name": "Wood_Hardwood_Planks"
    },
    {
      "x": -1,
      "y": 2,
      "z": 2,
      "name": "Rock_Stone_Cobble"
    },
    {
      "x": -1,
      "y": 3,
      "z": 2,
      "name": "Wood_Hardwood_Planks"
    },
    {
      "x": -1,
      "y": 4,
      "z": 2,
      "name": "Empty"
    },
    {
      "x": -1,
      "y": 5,
      "z": 2,
      "name": "Empty"
    },
    {
      "x": -1,
      "y": 6,
      "z": 2,
      "name": "Empty"
    },
    {
      "x": -1,
      "y": 7,
      "z": 2,
      "name": "Wood_Hardwood_Planks_Half",
      "rotation": 7
    },
    {
      "x": -1,
      "y": 8,
      "z": 2,
      "name": "Wood_Hardwood_Planks"
    },
    {
      "x": -1,
      "y": 2,
      "z": 3,
      "name": "Rock_Stone_Cobble"
    },
    {
      "x": -1,
      "y": 3,
      "z": 3,
      "name": "Wood_Hardwood_Planks"
    },
    {
      "x": -1,
      "y": 4,
      "z": 3,
      "name": "Furniture_Village_Bookcase",
      "rotation": 3
    },
    {
      "x": -1,
      "y": 5,
      "z": 3,
      "name": "Furniture_Village_Bookcase",
      "rotation": 3
    },
    {
      "x": -1,
      "y": 6,
      "z": 3,
      "name": "Furniture_Village_Bookcase",
      "rotation": 3
    },
    {
      "x": -1,
      "y": 7,
      "z": 3,
      "name": "Wood_Hardwood_Planks_Half",
      "rotation": 7
    },
    {
      "x": -1,
      "y": 8,
      "z": 3,
      "name": "Wood_Hardwood_Planks"
    },
    {
      "x": -1,
      "y": 2,
      "z": 4,
      "name": "Rock_Stone_Cobble"
    },
    {
      "x": -1,
      "y": 3,
      "z": 4,
      "name": "Wood_Hardwood_Planks"
    },
    {
      "x": -1,
      "y": 4,
      "z": 4,
      "name": "Furniture_Village_Bookcase",
      "rotation": 3
    },
    {
      "x": -1,
      "y": 5,
      "z": 4,
      "name": "Furniture_Village_Bookcase",
      "rotation": 3
    },
    {
      "x": -1,
      "y": 6,
      "z": 4,
      "name": "Furniture_Village_Bookcase",
      "rotation": 3
    },
    {
      "x": -1,
      "y": 7,
      "z": 4,
      "name": "Wood_Hardwood_Planks_Half",
      "rotation": 7
    },
    {
      "x": -1,
      "y": 8,
      "z": 4,
      "name": "Wood_Hardwood_Planks"
    },
    {
      "x": -1,
      "y": 2,
      "z": 5,
      "name": "Rock_Stone_Cobble"
    },
    {
      "x": -1,
      "y": 3,
      "z": 5,
      "name": "Wood_Hardwood_Planks"
    },
    {
      "x": -1,
      "y": 4,
      "z": 5,
      "name": "Furniture_Temple_Light_Brazier"
    },
    {
      "x": -1,
      "y": 5,
      "z": 5,
      "name": "Rock_Crystal_Cyan_Small"
    },
    {
      "x": -1,
      "y": 6,
      "z": 5,
      "name": "Empty"
    },
    {
      "x": -1,
      "y": 7,
      "z": 5,
      "name": "Wood_Hardwood_Planks"
    },
    {
      "x": -1,
      "y": 8,
      "z": 5,
      "name": "Wood_Hardwood_Planks"
    },
    {
      "x": -1,
      "y": 2,
      "z": 6,
      "name": "Rock_Stone_Cobble"
    },
    {
      "x": -1,
      "y": 3,
      "z": 6,
      "name": "Rock_Stone_Cobble"
    },
    {
      "x": -1,
      "y": 4,
      "z": 6,
      "name": "Rock_Stone_Brick_Decorative"
    },
    {
      "x": -1,
      "y": 5,
      "z": 6,
      "name": "Rock_Stone_Cobble"
    },
    {
      "x": -1,
      "y": 6,
      "z": 6,
      "name": "Rock_Stone_Cobble"
    },
    {
      "x": -1,
      "y": 7,
      "z": 6,
      "name": "Rock_Stone_Cobble"
    },
    {
      "x": -1,
      "y": 8,
      "z": 6,
      "name": "Rock_Stone_Cobble"
    },
    {
      "x": 0,
      "y": 2,
      "z": -5,
      "name": "Rock_Stone_Cobble"
    },
    {
      "x": 0,
      "y": 3,
      "z": -5,
      "name": "Rock_Stone_Cobble"
    },
    {
      "x": 0,
      "y": 4,
      "z": -5,
      "name": "Rock_Stone_Brick_Decorative"
    },
    {
      "x": 0,
      "y": 5,
      "z": -5,
      "name": "Rock_Stone_Cobble"
    },
    {
      "x": 0,
      "y": 6,
      "z": -5,
      "name": "Rock_Stone_Cobble"
    },
    {
      "x": 0,
      "y": 7,
      "z": -5,
      "name": "Rock_Stone_Cobble"
    },
    {
      "x": 0,
      "y": 8,
      "z": -5,
      "name": "Rock_Stone_Cobble"
    },
    {
      "x": 0,
      "y": 2,
      "z": -4,
      "name": "Rock_Stone_Cobble"
    },
    {
      "x": 0,
      "y": 3,
      "z": -4,
      "name": "Wood_Hardwood_Planks"
    },
    {
      "x": 0,
      "y": 4,
      "z": -4,
      "name": "Rock_Stone_Brick_Decorative"
    },
    {
      "x": 0,
      "y": 5,
      "z": -4,
      "name": "Rock_Stone_Cobble"
    },
    {
      "x": 0,
      "y": 6,
      "z": -4,
      "name": "Rock_Stone_Cobble"
    },
    {
      "x": 0,
      "y": 7,
      "z": -4,
      "name": "Rock_Stone_Cobble"
    },
    {
      "x": 0,
      "y": 8,
      "z": -4,
      "name": "Wood_Hardwood_Planks"
    },
    {
      "x": 0,
      "y": 2,
      "z": -3,
      "name": "Rock_Stone_Cobble"
    },
    {
      "x": 0,
      "y": 3,
      "z": -3,
      "name": "Wood_Hardwood_Planks"
    },
    {
      "x": 0,
      "y": 4,
      "z": -3,
      "name": "Rock_Stone_Brick_Decorative"
    },
    {
      "x": 0,
      "y": 5,
      "z": -3,
      "name": "Rock_Stone_Cobble"
    },
    {
      "x": 0,
      "y": 6,
      "z": -3,
      "name": "Rock_Stone_Cobble"
    },
    {
      "x": 0,
      "y": 7,
      "z": -3,
      "name": "Rock_Stone_Cobble"
    },
    {
      "x": 0,
      "y": 8,
      "z": -3,
      "name": "Wood_Hardwood_Planks"
    },
    {
      "x": 0,
      "y": 2,
      "z": -2,
      "name": "Rock_Stone_Cobble"
    },
    {
      "x": 0,
      "y": 3,
      "z": -2,
      "name": "Wood_Hardwood_Planks"
    },
    {
      "x": 0,
      "y": 4,
      "z": -2,
      "name": "Rock_Stone_Brick_Decorative"
    },
    {
      "x": 0,
      "y": 5,
      "z": -2,
      "name": "Rock_Stone_Cobble"
    },
    {
      "x": 0,
      "y": 6,
      "z": -2,
      "name": "Rock_Stone_Cobble"
    },
    {
      "x": 0,
      "y": 7,
      "z": -2,
      "name": "Rock_Stone_Cobble"
    },
    {
      "x": 0,
      "y": 8,
      "z": -2,
      "name": "Wood_Hardwood_Planks"
    },
    {
      "x": 0,
      "y": 2,
      "z": -1,
      "name": "Rock_Stone_Cobble"
    },
    {
      "x": 0,
      "y": 3,
      "z": -1,
      "name": "Wood_Hardwood_Planks"
    },
    {
      "x": 0,
      "y": 4,
      "z": -1,
      "name": "Empty"
    },
    {
      "x": 0,
      "y": 5,
      "z": -1,
      "name": "Empty"
    },
    {
      "x": 0,
      "y": 6,
      "z": -1,
      "name": "Rock_Stone_Brick_Half",
      "rotation": 8
    },
    {
      "x": 0,
      "y": 7,
      "z": -1,
      "name": "Rock_Stone_Cobble"
    },
    {
      "x": 0,
      "y": 8,
      "z": -1,
      "name": "Wood_Hardwood_Planks"
    },
    {
      "x": 0,
      "y": 2,
      "z": 0,
      "name": "Rock_Stone_Cobble"
    },
    {
      "x": 0,
      "y": 3,
      "z": 0,
      "name": "Wood_Hardwood_Planks"
    },
    {
      "x": 0,
      "y": 4,
      "z": 0,
      "name": "Empty"
    },
    {
      "x": 0,
      "y": 5,
      "z": 0,
      "name": "Empty"
    },
    {
      "x": 0,
      "y": 6,
      "z": 0,
      "name": "Rock_Stone_Brick_Half",
      "rotation": 8
    },
    {
      "x": 0,
      "y": 7,
      "z": 0,
      "name": "Rock_Stone_Cobble"
    },
    {
      "x": 0,
      "y": 8,
      "z": 0,
      "name": "Wood_Hardwood_Planks"
    },
    {
      "x": 0,
      "y": 2,
      "z": 1,
      "name": "Rock_Stone_Cobble"
    },
    {
      "x": 0,
      "y": 3,
      "z": 1,
      "name": "Wood_Hardwood_Planks"
    },
    {
      "x": 0,
      "y": 4,
      "z": 1,
      "name": "Empty"
    },
    {
      "x": 0,
      "y": 5,
      "z": 1,
      "name": "Empty"
    },
    {
      "x": 0,
      "y": 6,
      "z": 1,
      "name": "Rock_Stone_Brick_Half",
      "rotation": 8
    },
    {
      "x": 0,
      "y": 7,
      "z": 1,
      "name": "Rock_Stone_Cobble"
    },
    {
      "x": 0,
      "y": 8,
      "z": 1,
      "name": "Wood_Hardwood_Planks"
    },
    {
      "x": 0,
      "y": 2,
      "z": 2,
      "name": "Rock_Stone_Cobble"
    },
    {
      "x": 0,
      "y": 3,
      "z": 2,
      "name": "Wood_Hardwood_Planks"
    },
    {
      "x": 0,
      "y": 4,
      "z": 2,
      "name": "Rock_Stone_Brick_Decorative"
    },
    {
      "x": 0,
      "y": 5,
      "z": 2,
      "name": "Rock_Stone_Cobble"
    },
    {
      "x": 0,
      "y": 6,
      "z": 2,
      "name": "Rock_Stone_Cobble"
    },
    {
      "x": 0,
      "y": 7,
      "z": 2,
      "name": "Rock_Stone_Cobble"
    },
    {
      "x": 0,
      "y": 8,
      "z": 2,
      "name": "Wood_Hardwood_Planks"
    },
    {
      "x": 0,
      "y": 2,
      "z": 3,
      "name": "Rock_Stone_Cobble"
    },
    {
      "x": 0,
      "y": 3,
      "z": 3,
      "name": "Wood_Hardwood_Planks"
    },
    {
      "x": 0,
      "y": 4,
      "z": 3,
      "name": "Rock_Stone_Brick_Decorative"
    },
    {
      "x": 0,
      "y": 5,
      "z": 3,
      "name": "Rock_Stone_Cobble"
    },
    {
      "x": 0,
      "y": 6,
      "z": 3,
      "name": "Rock_Stone_Cobble"
    },
    {
      "x": 0,
      "y": 7,
      "z": 3,
      "name": "Rock_Stone_Cobble"
    },
    {
      "x": 0,
      "y": 8,
      "z": 3,
      "name": "Wood_Hardwood_Planks"
    },
    {
      "x": 0,
      "y": 2,
      "z": 4,
      "name": "Rock_Stone_Cobble"
    },
    {
      "x": 0,
      "y": 3,
      "z": 4,
      "name": "Wood_Hardwood_Planks"
    },
    {
      "x": 0,
      "y": 4,
      "z": 4,
      "name": "Rock_Stone_Brick_Decorative"
    },
    {
      "x": 0,
      "y": 5,
      "z": 4,
      "name": "Rock_Stone_Cobble"
    },
    {
      "x": 0,
      "y": 6,
      "z": 4,
      "name": "Rock_Stone_Cobble"
    },
    {
      "x": 0,
      "y": 7,
      "z": 4,
      "name": "Rock_Stone_Cobble"
    },
    {
      "x": 0,
      "y": 8,
      "z": 4,
      "name": "Wood_Hardwood_Planks"
    },
    {
      "x": 0,
      "y": 2,
      "z": 5,
      "name": "Rock_Stone_Cobble"
    },
    {
      "x": 0,
      "y": 3,
      "z": 5,
      "name": "Wood_Hardwood_Planks"
    },
    {
      "x": 0,
      "y": 4,
      "z": 5,
      "name": "Rock_Stone_Brick_Decorative"
    },
    {
      "x": 0,
      "y": 5,
      "z": 5,
      "name": "Rock_Stone_Cobble"
    },
    {
      "x": 0,
      "y": 6,
      "z": 5,
      "name": "Rock_Stone_Cobble"
    },
    {
      "x": 0,
      "y": 7,
      "z": 5,
      "name": "Rock_Stone_Cobble"
    },
    {
      "x": 0,
      "y": 8,
      "z": 5,
      "name": "Wood_Hardwood_Planks"
    },
    {
      "x": 0,
      "y": 2,
      "z": 6,
      "name": "Rock_Stone_Cobble"
    },
    {
      "x": 0,
      "y": 3,
      "z": 6,
      "name": "Rock_Stone_Cobble"
    },
    {
      "x": 0,
      "y": 4,
      "z": 6,
      "name": "Rock_Stone_Brick_Decorative"
    },
    {
      "x": 0,
      "y": 5,
      "z": 6,
      "name": "Rock_Stone_Cobble"
    },
    {
      "x": 0,
      "y": 6,
      "z": 6,
      "name": "Rock_Stone_Cobble"
    },
    {
      "x": 0,
      "y": 7,
      "z": 6,
      "name": "Rock_Stone_Cobble"
    },
    {
      "x": 0,
      "y": 8,
      "z": 6,
      "name": "Rock_Stone_Cobble"
    },
    {
      "x": 1,
      "y": 2,
      "z": -5,
      "name": "Rock_Stone_Cobble"
    },
    {
      "x": 1,
      "y": 3,
      "z": -5,
      "name": "Rock_Stone_Cobble"
    },
    {
      "x": 1,
      "y": 4,
      "z": -5,
      "name": "Rock_Stone_Brick_Decorative"
    },
    {
      "x": 1,
      "y": 5,
      "z": -5,
      "name": "Rock_Stone_Cobble"
    },
    {
      "x": 1,
      "y": 6,
      "z": -5,
      "name": "Rock_Stone_Cobble"
    },
    {
      "x": 1,
      "y": 7,
      "z": -5,
      "name": "Rock_Stone_Cobble"
    },
    {
      "x": 1,
      "y": 8,
      "z": -5,
      "name": "Rock_Stone_Cobble"
    },
    {
      "x": 1,
      "y": 2,
      "z": -4,
      "name": "Rock_Stone_Cobble"
    },
    {
      "x": 1,
      "y": 3,
      "z": -4,
      "name": "Wood_Hardwood_Planks"
    },
    {
      "x": 1,
      "y": 4,
      "z": -4,
      "name": "Empty"
    },
    {
      "x": 1,
      "y": 5,
      "z": -4,
      "name": "Empty"
    },
    {
      "x": 1,
      "y": 6,
      "z": -4,
      "name": "Empty"
    },
    {
      "x": 1,
      "y": 7,
      "z": -4,
      "name": "Wood_Hardwood_Planks"
    },
    {
      "x": 1,
      "y": 8,
      "z": -4,
      "name": "Wood_Hardwood_Planks"
    },
    {
      "x": 1,
      "y": 2,
      "z": -3,
      "name": "Rock_Stone_Cobble"
    },
    {
      "x": 1,
      "y": 3,
      "z": -3,
      "name": "Wood_Hardwood_Planks"
    },
    {
      "x": 1,
      "y": 4,
      "z": -3,
      "name": "Furniture_Village_Counter",
      "rotation": 2
    },
    {
      "x": 1,
      "y": 5,
      "z": -3,
      "name": "Furniture_Temple_Wind_Candle"
    },
    {
      "x": 1,
      "y": 6,
      "z": -3,
      "name": "Empty"
    },
    {
      "x": 1,
      "y": 7,
      "z": -3,
      "name": "Wood_Hardwood_Planks_Half",
      "rotation": 5
    },
    {
      "x": 1,
      "y": 8,
      "z": -3,
      "name": "Wood_Hardwood_Planks"
    },
    {
      "x": 1,
      "y": 2,
      "z": -2,
      "name": "Rock_Stone_Cobble"
    },
    {
      "x": 1,
      "y": 3,
      "z": -2,
      "name": "Wood_Hardwood_Planks"
    },
    {
      "x": 1,
      "y": 4,
      "z": -2,
      "name": "Alchemy_Cauldron"
    },
    {
      "x": 1,
      "y": 5,
      "z": -2,
      "name": "Empty"
    },
    {
      "x": 1,
      "y": 6,
      "z": -2,
      "name": "Empty"
    },
    {
      "x": 1,
      "y": 7,
      "z": -2,
      "name": "Wood_Hardwood_Planks_Half",
      "rotation": 5
    },
    {
      "x": 1,
      "y": 8,
      "z": -2,
      "name": "Wood_Hardwood_Planks"
    },
    {
      "x": 1,
      "y": 2,
      "z": -1,
      "name": "Rock_Stone_Cobble"
    },
    {
      "x": 1,
      "y": 3,
      "z": -1,
      "name": "Wood_Hardwood_Planks"
    },
    {
      "x": 1,
      "y": 4,
      "z": -1,
      "name": "Empty"
    },
    {
      "x": 1,
      "y": 5,
      "z": -1,
      "name": "Empty"
    },
    {
      "x": 1,
      "y": 6,
      "z": -1,
      "name": "Empty"
    },
    {
      "x": 1,
      "y": 7,
      "z": -1,
      "name": "Wood_Hardwood_Planks_Half",
      "rotation": 5
    },
    {
      "x": 1,
      "y": 8,
      "z": -1,
      "name": "Wood_Hardwood_Planks"
    },
    {
      "x": 1,
      "y": 2,
      "z": 0,
      "name": "Rock_Stone_Cobble"
    },
    {
      "x": 1,
      "y": 3,
      "z": 0,
      "name": "Wood_Hardwood_Planks"
    },
    {
      "x": 1,
      "y": 4,
      "z": 0,
      "name": "Empty"
    },
    {
      "x": 1,
      "y": 5,
      "z": 0,
      "name": "Empty"
    },
    {
      "x": 1,
      "y": 6,
      "z": 0,
      "name": "Empty"
    },
    {
      "x": 1,
      "y": 7,
      "z": 0,
      "name": "Wood_Hardwood_Planks_Half",
      "rotation": 5
    },
    {
      "x": 1,
      "y": 8,
      "z": 0,
      "name": "Wood_Hardwood_Planks"
    },
    {
      "x": 1,
      "y": 2,
      "z": 1,
      "name": "Rock_Stone_Cobble"
    },
    {
      "x": 1,
      "y": 3,
      "z": 1,
      "name": "Wood_Hardwood_Planks"
    },
    {
      "x": 1,
      "y": 4,
      "z": 1,
      "name": "Empty"
    },
    {
      "x": 1,
      "y": 5,
      "z": 1,
      "name": "Empty"
    },
    {
      "x": 1,
      "y": 6,
      "z": 1,
      "name": "Empty"
    },
    {
      "x": 1,
      "y": 7,
      "z": 1,
      "name": "Wood_Hardwood_Planks_Half",
      "rotation": 5
    },
    {
      "x": 1,
      "y": 8,
      "z": 1,
      "name": "Wood_Hardwood_Planks"
    },
    {
      "x": 1,
      "y": 2,
      "z": 2,
      "name": "Rock_Stone_Cobble"
    },
    {
      "x": 1,
      "y": 3,
      "z": 2,
      "name": "Wood_Hardwood_Planks"
    },
    {
      "x": 1,
      "y": 4,
      "z": 2,
      "name": "Empty"
    },
    {
      "x": 1,
      "y": 5,
      "z": 2,
      "name": "Empty"
    },
    {
      "x": 1,
      "y": 6,
      "z": 2,
      "name": "Empty"
    },
    {
      "x": 1,
      "y": 7,
      "z": 2,
      "name": "Wood_Hardwood_Planks_Half",
      "rotation": 5
    },
    {
      "x": 1,
      "y": 8,
      "z": 2,
      "name": "Wood_Hardwood_Planks"
    },
    {
      "x": 1,
      "y": 2,
      "z": 3,
      "name": "Rock_Stone_Cobble"
    },
    {
      "x": 1,
      "y": 3,
      "z": 3,
      "name": "Wood_Hardwood_Planks"
    },
    {
      "x": 1,
      "y": 4,
      "z": 3,
      "name": "Furniture_Village_Planter"
    },
    {
      "x": 1,
      "y": 5,
      "z": 3,
      "name": "*Plant_Crop_Berry_Block_State_Definitions_StageFinal",
      "components": {
        "Components": {
          "FarmingBlock": {}
        }
      }
    },
    {
      "x": 1,
      "y": 6,
      "z": 3,
      "name": "Empty"
    },
    {
      "x": 1,
      "y": 7,
      "z": 3,
      "name": "Wood_Hardwood_Planks_Half",
      "rotation": 5
    },
    {
      "x": 1,
      "y": 8,
      "z": 3,
      "name": "Wood_Hardwood_Planks"
    },
    {
      "x": 1,
      "y": 2,
      "z": 4,
      "name": "Rock_Stone_Cobble"
    },
    {
      "x": 1,
      "y": 3,
      "z": 4,
      "name": "Wood_Hardwood_Planks"
    },
    {
      "x": 1,
      "y": 4,
      "z": 4,
      "name": "Furniture_Village_Counter",
      "rotation": 1
    },
    {
      "x": 1,
      "y": 5,
      "z": 4,
      "name": "Furniture_Tavern_Candle"
    },
    {
      "x": 1,
      "y": 6,
      "z": 4,
      "name": "Empty"
    },
    {
      "x": 1,
      "y": 7,
      "z": 4,
      "name": "Wood_Hardwood_Planks_Half",
      "rotation": 5
    },
    {
      "x": 1,
      "y": 8,
      "z": 4,
      "name": "Wood_Hardwood_Planks"
    },
    {
      "x": 1,
      "y": 2,
      "z": 5,
      "name": "Rock_Stone_Cobble"
    },
    {
      "x": 1,
      "y": 3,
      "z": 5,
      "name": "Wood_Hardwood_Planks"
    },
    {
      "x": 1,
      "y": 4,
      "z": 5,
      "name": "Furniture_Village_Counter",
      "filler": 32,
      "rotation": 1
    },
    {
      "x": 1,
      "y": 5,
      "z": 5,
      "name": "Furniture_Village_Shelf_Full",
      "rotation": 1
    },
    {
      "x": 1,
      "y": 6,
      "z": 5,
      "name": "Furniture_Village_Shelf_Full",
      "rotation": 1
    },
    {
      "x": 1,
      "y": 7,
      "z": 5,
      "name": "Wood_Hardwood_Planks"
    },
    {
      "x": 1,
      "y": 8,
      "z": 5,
      "name": "Wood_Hardwood_Planks"
    },
    {
      "x": 1,
      "y": 2,
      "z": 6,
      "name": "Rock_Stone_Cobble"
    },
    {
      "x": 1,
      "y": 3,
      "z": 6,
      "name": "Rock_Stone_Cobble"
    },
    {
      "x": 1,
      "y": 4,
      "z": 6,
      "name": "Rock_Stone_Brick_Decorative"
    },
    {
      "x": 1,
      "y": 5,
      "z": 6,
      "name": "Rock_Stone_Cobble"
    },
    {
      "x": 1,
      "y": 6,
      "z": 6,
      "name": "Rock_Stone_Cobble"
    },
    {
      "x": 1,
      "y": 7,
      "z": 6,
      "name": "Rock_Stone_Cobble"
    },
    {
      "x": 1,
      "y": 8,
      "z": 6,
      "name": "Rock_Stone_Cobble"
    },
    {
      "x": 2,
      "y": 2,
      "z": -5,
      "name": "Rock_Stone_Cobble"
    },
    {
      "x": 2,
      "y": 3,
      "z": -5,
      "name": "Rock_Stone_Cobble"
    },
    {
      "x": 2,
      "y": 4,
      "z": -5,
      "name": "Rock_Stone_Brick_Decorative"
    },
    {
      "x": 2,
      "y": 5,
      "z": -5,
      "name": "Rock_Stone_Cobble"
    },
    {
      "x": 2,
      "y": 6,
      "z": -5,
      "name": "Rock_Stone_Cobble"
    },
    {
      "x": 2,
      "y": 7,
      "z": -5,
      "name": "Rock_Stone_Cobble"
    },
    {
      "x": 2,
      "y": 8,
      "z": -5,
      "name": "Rock_Stone_Cobble"
    },
    {
      "x": 2,
      "y": 2,
      "z": -4,
      "name": "Rock_Stone_Cobble"
    },
    {
      "x": 2,
      "y": 3,
      "z": -4,
      "name": "Wood_Hardwood_Planks"
    },
    {
      "x": 2,
      "y": 4,
      "z": -4,
      "name": "Empty"
    },
    {
      "x": 2,
      "y": 5,
      "z": -4,
      "name": "Empty"
    },
    {
      "x": 2,
      "y": 6,
      "z": -4,
      "name": "Empty"
    },
    {
      "x": 2,
      "y": 7,
      "z": -4,
      "name": "Wood_Hardwood_Planks_Half",
      "rotation": 4
    },
    {
      "x": 2,
      "y": 8,
      "z": -4,
      "name": "Wood_Hardwood_Planks"
    },
    {
      "x": 2,
      "y": 2,
      "z": -3,
      "name": "Rock_Stone_Cobble"
    },
    {
      "x": 2,
      "y": 3,
      "z": -3,
      "name": "Wood_Hardwood_Planks"
    },
    {
      "x": 2,
      "y": 4,
      "z": -3,
      "name": "Furniture_Village_Counter",
      "filler": 1,
      "rotation": 2
    },
    {
      "x": 2,
      "y": 5,
      "z": -3,
      "name": "Empty"
    },
    {
      "x": 2,
      "y": 6,
      "z": -3,
      "name": "Empty"
    },
    {
      "x": 2,
      "y": 7,
      "z": -3,
      "name": "Empty"
    },
    {
      "x": 2,
      "y": 8,
      "z": -3,
      "name": "Wood_Hardwood_Planks"
    },
    {
      "x": 2,
      "y": 2,
      "z": -2,
      "name": "Rock_Stone_Cobble"
    },
    {
      "x": 2,
      "y": 3,
      "z": -2,
      "name": "Wood_Hardwood_Planks"
    },
    {
      "x": 2,
      "y": 4,
      "z": -2,
      "name": "Empty"
    },
    {
      "x": 2,
      "y": 5,
      "z": -2,
      "name": "Empty"
    },
    {
      "x": 2,
      "y": 6,
      "z": -2,
      "name": "Empty"
    },
    {
      "x": 2,
      "y": 7,
      "z": -2,
      "name": "Empty"
    },
    {
      "x": 2,
      "y": 8,
      "z": -2,
      "name": "Wood_Hardwood_Planks"
    },
    {
      "x": 2,
      "y": 2,
      "z": -1,
      "name": "Rock_Stone_Cobble"
    },
    {
      "x": 2,
      "y": 3,
      "z": -1,
      "name": "Wood_Hardwood_Planks"
    },
    {
      "x": 2,
      "y": 4,
      "z": -1,
      "name": "Empty"
    },
    {
      "x": 2,
      "y": 5,
      "z": -1,
      "name": "Empty"
    },
    {
      "x": 2,
      "y": 6,
      "z": -1,
      "name": "Empty"
    },
    {
      "x": 2,
      "y": 7,
      "z": -1,
      "name": "Empty"
    },
    {
      "x": 2,
      "y": 8,
      "z": -1,
      "name": "Wood_Hardwood_Planks"
    },
    {
      "x": 2,
      "y": 2,
      "z": 0,
      "name": "Rock_Stone_Cobble"
    },
    {
      "x": 2,
      "y": 3,
      "z": 0,
      "name": "Wood_Hardwood_Planks"
    },
    {
      "x": 2,
      "y": 4,
      "z": 0,
      "name": "Empty"
    },
    {
      "x": 2,
      "y": 5,
      "z": 0,
      "name": "Empty"
    },
    {
      "x": 2,
      "y": 6,
      "z": 0,
      "name": "Empty"
    },
    {
      "x": 2,
      "y": 7,
      "z": 0,
      "name": "Empty"
    },
    {
      "x": 2,
      "y": 8,
      "z": 0,
      "name": "Wood_Hardwood_Planks"
    },
    {
      "x": 2,
      "y": 2,
      "z": 1,
      "name": "Rock_Stone_Cobble"
    },
    {
      "x": 2,
      "y": 3,
      "z": 1,
      "name": "Wood_Hardwood_Planks"
    },
    {
      "x": 2,
      "y": 4,
      "z": 1,
      "name": "Empty"
    },
    {
      "x": 2,
      "y": 5,
      "z": 1,
      "name": "Empty"
    },
    {
      "x": 2,
      "y": 6,
      "z": 1,
      "name": "Empty"
    },
    {
      "x": 2,
      "y": 7,
      "z": 1,
      "name": "Empty"
    },
    {
      "x": 2,
      "y": 8,
      "z": 1,
      "name": "Wood_Hardwood_Planks"
    },
    {
      "x": 2,
      "y": 2,
      "z": 2,
      "name": "Rock_Stone_Cobble"
    },
    {
      "x": 2,
      "y": 3,
      "z": 2,
      "name": "Wood_Hardwood_Planks"
    },
    {
      "x": 2,
      "y": 4,
      "z": 2,
      "name": "Empty"
    },
    {
      "x": 2,
      "y": 5,
      "z": 2,
      "name": "Empty"
    },
    {
      "x": 2,
      "y": 6,
      "z": 2,
      "name": "Empty"
    },
    {
      "x": 2,
      "y": 7,
      "z": 2,
      "name": "Empty"
    },
    {
      "x": 2,
      "y": 8,
      "z": 2,
      "name": "Wood_Hardwood_Planks"
    },
    {
      "x": 2,
      "y": 2,
      "z": 3,
      "name": "Rock_Stone_Cobble"
    },
    {
      "x": 2,
      "y": 3,
      "z": 3,
      "name": "Wood_Hardwood_Planks"
    },
    {
      "x": 2,
      "y": 4,
      "z": 3,
      "name": "Empty"
    },
    {
      "x": 2,
      "y": 5,
      "z": 3,
      "name": "Empty"
    },
    {
      "x": 2,
      "y": 6,
      "z": 3,
      "name": "Empty"
    },
    {
      "x": 2,
      "y": 7,
      "z": 3,
      "name": "Empty"
    },
    {
      "x": 2,
      "y": 8,
      "z": 3,
      "name": "Wood_Hardwood_Planks"
    },
    {
      "x": 2,
      "y": 2,
      "z": 4,
      "name": "Rock_Stone_Cobble"
    },
    {
      "x": 2,
      "y": 3,
      "z": 4,
      "name": "Wood_Hardwood_Planks"
    },
    {
      "x": 2,
      "y": 4,
      "z": 4,
      "name": "Empty"
    },
    {
      "x": 2,
      "y": 5,
      "z": 4,
      "name": "Empty"
    },
    {
      "x": 2,
      "y": 6,
      "z": 4,
      "name": "Empty"
    },
    {
      "x": 2,
      "y": 7,
      "z": 4,
      "name": "Empty"
    },
    {
      "x": 2,
      "y": 8,
      "z": 4,
      "name": "Wood_Hardwood_Planks"
    },
    {
      "x": 2,
      "y": 2,
      "z": 5,
      "name": "Rock_Stone_Cobble"
    },
    {
      "x": 2,
      "y": 3,
      "z": 5,
      "name": "Wood_Hardwood_Planks"
    },
    {
      "x": 2,
      "y": 4,
      "z": 5,
      "name": "Furniture_Village_Planter"
    },
    {
      "x": 2,
      "y": 5,
      "z": 5,
      "name": "*Plant_Crop_Carrot_Block_State_Definitions_StageFinal",
      "components": {
        "Components": {
          "FarmingBlock": {}
        }
      }
    },
    {
      "x": 2,
      "y": 6,
      "z": 5,
      "name": "Empty"
    },
    {
      "x": 2,
      "y": 7,
      "z": 5,
      "name": "Wood_Hardwood_Planks_Half",
      "rotation": 6
    },
    {
      "x": 2,
      "y": 8,
      "z": 5,
      "name": "Wood_Hardwood_Planks"
    },
    {
      "x": 2,
      "y": 2,
      "z": 6,
      "name": "Rock_Stone_Brick_Decorative"
    },
    {
      "x": 2,
      "y": 3,
      "z": 6,
      "name": "Rock_Stone_Cobble"
    },
    {
      "x": 2,
      "y": 4,
      "z": 6,
      "name": "Rock_Stone_Brick_Decorative"
    },
    {
      "x": 2,
      "y": 5,
      "z": 6,
      "name": "Rock_Stone_Cobble"
    },
    {
      "x": 2,
      "y": 6,
      "z": 6,
      "name": "Rock_Stone_Cobble"
    },
    {
      "x": 2,
      "y": 7,
      "z": 6,
      "name": "Rock_Stone_Cobble"
    },
    {
      "x": 2,
      "y": 8,
      "z": 6,
      "name": "Rock_Stone_Cobble"
    },
    {
      "x": 3,
      "y": 2,
      "z": -5,
      "name": "Rock_Stone_Cobble"
    },
    {
      "x": 3,
      "y": 3,
      "z": -5,
      "name": "Rock_Stone_Cobble"
    },
    {
      "x": 3,
      "y": 4,
      "z": -5,
      "name": "Rock_Stone_Brick_Decorative"
    },
    {
      "x": 3,
      "y": 5,
      "z": -5,
      "name": "Rock_Stone_Cobble"
    },
    {
      "x": 3,
      "y": 6,
      "z": -5,
      "name": "Rock_Stone_Cobble"
    },
    {
      "x": 3,
      "y": 7,
      "z": -5,
      "name": "Rock_Stone_Cobble"
    },
    {
      "x": 3,
      "y": 8,
      "z": -5,
      "name": "Rock_Stone_Cobble"
    },
    {
      "x": 3,
      "y": 2,
      "z": -4,
      "name": "Rock_Stone_Cobble"
    },
    {
      "x": 3,
      "y": 3,
      "z": -4,
      "name": "Wood_Hardwood_Planks"
    },
    {
      "x": 3,
      "y": 4,
      "z": -4,
      "name": "Furniture_Tavern_Shelf"
    },
    {
      "x": 3,
      "y": 5,
      "z": -4,
      "name": "Rock_Crystal_Pink_Medium"
    },
    {
      "x": 3,
      "y": 6,
      "z": -4,
      "name": "Empty"
    },
    {
      "x": 3,
      "y": 7,
      "z": -4,
      "name": "Wood_Hardwood_Planks_Half",
      "rotation": 4
    },
    {
      "x": 3,
      "y": 8,
      "z": -4,
      "name": "Wood_Hardwood_Planks"
    },
    {
      "x": 3,
      "y": 2,
      "z": -3,
      "name": "Rock_Stone_Cobble"
    },
    {
      "x": 3,
      "y": 3,
      "z": -3,
      "name": "Wood_Hardwood_Planks"
    },
    {
      "x": 3,
      "y": 4,
      "z": -3,
      "name": "Empty"
    },
    {
      "x": 3,
      "y": 5,
      "z": -3,
      "name": "Empty"
    },
    {
      "x": 3,
      "y": 6,
      "z": -3,
      "name": "Empty"
    },
    {
      "x": 3,
      "y": 7,
      "z": -3,
      "name": "Empty"
    },
    {
      "x": 3,
      "y": 8,
      "z": -3,
      "name": "Wood_Hardwood_Planks"
    },
    {
      "x": 3,
      "y": 2,
      "z": -2,
      "name": "Rock_Stone_Cobble"
    },
    {
      "x": 3,
      "y": 3,
      "z": -2,
      "name": "Wood_Hardwood_Planks"
    },
    {
      "x": 3,
      "y": 4,
      "z": -2,
      "name": "Empty"
    },
    {
      "x": 3,
      "y": 5,
      "z": -2,
      "name": "Empty"
    },
    {
      "x": 3,
      "y": 6,
      "z": -2,
      "name": "Empty"
    },
    {
      "x": 3,
      "y": 7,
      "z": -2,
      "name": "Empty"
    },
    {
      "x": 3,
      "y": 8,
      "z": -2,
      "name": "Wood_Hardwood_Planks"
    },
    {
      "x": 3,
      "y": 2,
      "z": -1,
      "name": "Rock_Stone_Cobble"
    },
    {
      "x": 3,
      "y": 3,
      "z": -1,
      "name": "Wood_Hardwood_Planks"
    },
    {
      "x": 3,
      "y": 4,
      "z": -1,
      "name": "Empty"
    },
    {
      "x": 3,
      "y": 5,
      "z": -1,
      "name": "Empty"
    },
    {
      "x": 3,
      "y": 6,
      "z": -1,
      "name": "Empty"
    },
    {
      "x": 3,
      "y": 7,
      "z": -1,
      "name": "Empty"
    },
    {
      "x": 3,
      "y": 8,
      "z": -1,
      "name": "Wood_Hardwood_Planks"
    },
    {
      "x": 3,
      "y": 2,
      "z": 0,
      "name": "Rock_Stone_Cobble"
    },
    {
      "x": 3,
      "y": 3,
      "z": 0,
      "name": "Wood_Hardwood_Planks"
    },
    {
      "x": 3,
      "y": 4,
      "z": 0,
      "name": "Empty"
    },
    {
      "x": 3,
      "y": 5,
      "z": 0,
      "name": "Empty"
    },
    {
      "x": 3,
      "y": 6,
      "z": 0,
      "name": "Empty"
    },
    {
      "x": 3,
      "y": 7,
      "z": 0,
      "name": "Empty"
    },
    {
      "x": 3,
      "y": 8,
      "z": 0,
      "name": "Wood_Hardwood_Planks"
    },
    {
      "x": 3,
      "y": 2,
      "z": 1,
      "name": "Rock_Stone_Cobble"
    },
    {
      "x": 3,
      "y": 3,
      "z": 1,
      "name": "Wood_Hardwood_Planks"
    },
    {
      "x": 3,
      "y": 4,
      "z": 1,
      "name": "Empty"
    },
    {
      "x": 3,
      "y": 5,
      "z": 1,
      "name": "Empty"
    },
    {
      "x": 3,
      "y": 6,
      "z": 1,
      "name": "Empty"
    },
    {
      "x": 3,
      "y": 7,
      "z": 1,
      "name": "Empty"
    },
    {
      "x": 3,
      "y": 8,
      "z": 1,
      "name": "Wood_Hardwood_Planks"
    },
    {
      "x": 3,
      "y": 2,
      "z": 2,
      "name": "Rock_Stone_Cobble"
    },
    {
      "x": 3,
      "y": 3,
      "z": 2,
      "name": "Wood_Hardwood_Planks"
    },
    {
      "x": 3,
      "y": 4,
      "z": 2,
      "name": "Empty"
    },
    {
      "x": 3,
      "y": 5,
      "z": 2,
      "name": "Empty"
    },
    {
      "x": 3,
      "y": 6,
      "z": 2,
      "name": "Empty"
    },
    {
      "x": 3,
      "y": 7,
      "z": 2,
      "name": "Empty"
    },
    {
      "x": 3,
      "y": 8,
      "z": 2,
      "name": "Wood_Hardwood_Planks"
    },
    {
      "x": 3,
      "y": 2,
      "z": 3,
      "name": "Rock_Stone_Cobble"
    },
    {
      "x": 3,
      "y": 3,
      "z": 3,
      "name": "Wood_Hardwood_Planks"
    },
    {
      "x": 3,
      "y": 4,
      "z": 3,
      "name": "Empty"
    },
    {
      "x": 3,
      "y": 5,
      "z": 3,
      "name": "Empty"
    },
    {
      "x": 3,
      "y": 6,
      "z": 3,
      "name": "Empty"
    },
    {
      "x": 3,
      "y": 7,
      "z": 3,
      "name": "Empty"
    },
    {
      "x": 3,
      "y": 8,
      "z": 3,
      "name": "Wood_Hardwood_Planks"
    },
    {
      "x": 3,
      "y": 0,
      "z": 4,
      "name": "Rock_Stone_Cobble"
    },
    {
      "x": 3,
      "y": 1,
      "z": 4,
      "name": "Rock_Stone_Cobble"
    },
    {
      "x": 3,
      "y": 2,
      "z": 4,
      "name": "Rock_Stone_Cobble"
    },
    {
      "x": 3,
      "y": 3,
      "z": 4,
      "name": "Wood_Hardwood_Planks"
    },
    {
      "x": 3,
      "y": 4,
      "z": 4,
      "name": "Empty"
    },
    {
      "x": 3,
      "y": 5,
      "z": 4,
      "name": "Empty"
    },
    {
      "x": 3,
      "y": 6,
      "z": 4,
      "name": "Empty"
    },
    {
      "x": 3,
      "y": 7,
      "z": 4,
      "name": "Empty"
    },
    {
      "x": 3,
      "y": 8,
      "z": 4,
      "name": "Wood_Hardwood_Planks"
    },
    {
      "x": 3,
      "y": 0,
      "z": 5,
      "name": "Rock_Stone_Cobble"
    },
    {
      "x": 3,
      "y": 1,
      "z": 5,
      "name": "Rock_Stone_Cobble"
    },
    {
      "x": 3,
      "y": 2,
      "z": 5,
      "name": "Rock_Stone_Cobble"
    },
    {
      "x": 3,
      "y": 3,
      "z": 5,
      "name": "Wood_Hardwood_Planks"
    },
    {
      "x": 3,
      "y": 4,
      "z": 5,
      "name": "Empty"
    },
    {
      "x": 3,
      "y": 5,
      "z": 5,
      "name": "Empty"
    },
    {
      "x": 3,
      "y": 6,
      "z": 5,
      "name": "Empty"
    },
    {
      "x": 3,
      "y": 7,
      "z": 5,
      "name": "Wood_Hardwood_Planks_Half",
      "rotation": 6
    },
    {
      "x": 3,
      "y": 8,
      "z": 5,
      "name": "Wood_Hardwood_Planks"
    },
    {
      "x": 3,
      "y": 0,
      "z": 6,
      "name": "Rock_Stone_Cobble"
    },
    {
      "x": 3,
      "y": 1,
      "z": 6,
      "name": "Rock_Stone_Cobble"
    },
    {
      "x": 3,
      "y": 2,
      "z": 6,
      "name": "Rock_Stone_Brick_Decorative"
    },
    {
      "x": 3,
      "y": 3,
      "z": 6,
      "name": "Rock_Stone_Cobble"
    },
    {
      "x": 3,
      "y": 4,
      "z": 6,
      "name": "Rock_Stone_Brick_Decorative"
    },
    {
      "x": 3,
      "y": 5,
      "z": 6,
      "name": "Rock_Stone_Cobble"
    },
    {
      "x": 3,
      "y": 6,
      "z": 6,
      "name": "Rock_Stone_Cobble"
    },
    {
      "x": 3,
      "y": 7,
      "z": 6,
      "name": "Rock_Stone_Cobble"
    },
    {
      "x": 3,
      "y": 8,
      "z": 6,
      "name": "Rock_Stone_Cobble"
    },
    {
      "x": 4,
      "y": 2,
      "z": -5,
      "name": "Rock_Stone_Cobble"
    },
    {
      "x": 4,
      "y": 3,
      "z": -5,
      "name": "Rock_Stone_Cobble"
    },
    {
      "x": 4,
      "y": 4,
      "z": -5,
      "name": "Rock_Stone_Brick_Decorative"
    },
    {
      "x": 4,
      "y": 5,
      "z": -5,
      "name": "Rock_Stone_Cobble"
    },
    {
      "x": 4,
      "y": 6,
      "z": -5,
      "name": "Rock_Stone_Cobble"
    },
    {
      "x": 4,
      "y": 7,
      "z": -5,
      "name": "Rock_Stone_Cobble"
    },
    {
      "x": 4,
      "y": 8,
      "z": -5,
      "name": "Rock_Stone_Cobble"
    },
    {
      "x": 4,
      "y": 2,
      "z": -4,
      "name": "Rock_Stone_Cobble"
    },
    {
      "x": 4,
      "y": 3,
      "z": -4,
      "name": "Wood_Hardwood_Planks"
    },
    {
      "x": 4,
      "y": 4,
      "z": -4,
      "name": "Empty"
    },
    {
      "x": 4,
      "y": 5,
      "z": -4,
      "name": "Furniture_Village_Painting_2x2",
      "filler": 31
    },
    {
      "x": 4,
      "y": 6,
      "z": -4,
      "name": "Furniture_Village_Painting_2x2",
      "filler": 1055
    },
    {
      "x": 4,
      "y": 7,
      "z": -4,
      "name": "Wood_Hardwood_Planks_Half",
      "rotation": 4
    },
    {
      "x": 4,
      "y": 8,
      "z": -4,
      "name": "Wood_Hardwood_Planks"
    },
    {
      "x": 4,
      "y": 2,
      "z": -3,
      "name": "Rock_Stone_Cobble"
    },
    {
      "x": 4,
      "y": 3,
      "z": -3,
      "name": "Wood_Hardwood_Planks"
    },
    {
      "x": 4,
      "y": 4,
      "z": -3,
      "name": "Empty"
    },
    {
      "x": 4,
      "y": 5,
      "z": -3,
      "name": "Empty"
    },
    {
      "x": 4,
      "y": 6,
      "z": -3,
      "name": "Empty"
    },
    {
      "x": 4,
      "y": 7,
      "z": -3,
      "name": "Empty"
    },
    {
      "x": 4,
      "y": 8,
      "z": -3,
      "name": "Wood_Hardwood_Planks"
    },
    {
      "x": 4,
      "y": 2,
      "z": -2,
      "name": "Rock_Stone_Cobble"
    },
    {
      "x": 4,
      "y": 3,
      "z": -2,
      "name": "Wood_Hardwood_Planks"
    },
    {
      "x": 4,
      "y": 4,
      "z": -2,
      "name": "Furniture_Village_Bench",
      "rotation": 1
    },
    {
      "x": 4,
      "y": 5,
      "z": -2,
      "name": "Furniture_Village_Bench",
      "filler": 1024,
      "rotation": 1
    },
    {
      "x": 4,
      "y": 6,
      "z": -2,
      "name": "Empty"
    },
    {
      "x": 4,
      "y": 7,
      "z": -2,
      "name": "Empty"
    },
    {
      "x": 4,
      "y": 8,
      "z": -2,
      "name": "Wood_Hardwood_Planks"
    },
    {
      "x": 4,
      "y": 2,
      "z": -1,
      "name": "Rock_Stone_Cobble"
    },
    {
      "x": 4,
      "y": 3,
      "z": -1,
      "name": "Wood_Hardwood_Planks"
    },
    {
      "x": 4,
      "y": 4,
      "z": -1,
      "name": "Furniture_Village_Bench",
      "filler": 32,
      "rotation": 1
    },
    {
      "x": 4,
      "y": 5,
      "z": -1,
      "name": "Furniture_Village_Bench",
      "filler": 1056,
      "rotation": 1
    },
    {
      "x": 4,
      "y": 6,
      "z": -1,
      "name": "Empty"
    },
    {
      "x": 4,
      "y": 7,
      "z": -1,
      "name": "Empty"
    },
    {
      "x": 4,
      "y": 8,
      "z": -1,
      "name": "Wood_Hardwood_Planks"
    },
    {
      "x": 4,
      "y": 2,
      "z": 0,
      "name": "Rock_Stone_Cobble"
    },
    {
      "x": 4,
      "y": 3,
      "z": 0,
      "name": "Wood_Hardwood_Planks"
    },
    {
      "x": 4,
      "y": 4,
      "z": 0,
      "name": "Empty"
    },
    {
      "x": 4,
      "y": 5,
      "z": 0,
      "name": "Empty"
    },
    {
      "x": 4,
      "y": 6,
      "z": 0,
      "name": "Empty"
    },
    {
      "x": 4,
      "y": 7,
      "z": 0,
      "name": "Empty"
    },
    {
      "x": 4,
      "y": 8,
      "z": 0,
      "name": "Wood_Hardwood_Planks"
    },
    {
      "x": 4,
      "y": 2,
      "z": 1,
      "name": "Rock_Stone_Cobble"
    },
    {
      "x": 4,
      "y": 3,
      "z": 1,
      "name": "Wood_Hardwood_Planks"
    },
    {
      "x": 4,
      "y": 4,
      "z": 1,
      "name": "Empty"
    },
    {
      "x": 4,
      "y": 5,
      "z": 1,
      "name": "Empty"
    },
    {
      "x": 4,
      "y": 6,
      "z": 1,
      "name": "Empty"
    },
    {
      "x": 4,
      "y": 7,
      "z": 1,
      "name": "Empty"
    },
    {
      "x": 4,
      "y": 8,
      "z": 1,
      "name": "Wood_Hardwood_Planks"
    },
    {
      "x": 4,
      "y": 2,
      "z": 2,
      "name": "Rock_Stone_Cobble"
    },
    {
      "x": 4,
      "y": 3,
      "z": 2,
      "name": "Wood_Hardwood_Planks"
    },
    {
      "x": 4,
      "y": 4,
      "z": 2,
      "name": "Empty"
    },
    {
      "x": 4,
      "y": 5,
      "z": 2,
      "name": "Empty"
    },
    {
      "x": 4,
      "y": 6,
      "z": 2,
      "name": "Empty"
    },
    {
      "x": 4,
      "y": 7,
      "z": 2,
      "name": "Empty"
    },
    {
      "x": 4,
      "y": 8,
      "z": 2,
      "name": "Wood_Hardwood_Planks"
    },
    {
      "x": 4,
      "y": 2,
      "z": 3,
      "name": "Rock_Stone_Cobble"
    },
    {
      "x": 4,
      "y": 3,
      "z": 3,
      "name": "Wood_Hardwood_Planks"
    },
    {
      "x": 4,
      "y": 4,
      "z": 3,
      "name": "Empty"
    },
    {
      "x": 4,
      "y": 5,
      "z": 3,
      "name": "Empty"
    },
    {
      "x": 4,
      "y": 6,
      "z": 3,
      "name": "Empty"
    },
    {
      "x": 4,
      "y": 7,
      "z": 3,
      "name": "Empty"
    },
    {
      "x": 4,
      "y": 8,
      "z": 3,
      "name": "Wood_Hardwood_Planks"
    },
    {
      "x": 4,
      "y": 0,
      "z": 4,
      "name": "Rock_Stone_Cobble"
    },
    {
      "x": 4,
      "y": 1,
      "z": 4,
      "name": "Rock_Stone_Cobble"
    },
    {
      "x": 4,
      "y": 2,
      "z": 4,
      "name": "Rock_Stone_Cobble"
    },
    {
      "x": 4,
      "y": 3,
      "z": 4,
      "name": "Wood_Hardwood_Planks"
    },
    {
      "x": 4,
      "y": 4,
      "z": 4,
      "name": "Empty"
    },
    {
      "x": 4,
      "y": 5,
      "z": 4,
      "name": "Empty"
    },
    {
      "x": 4,
      "y": 6,
      "z": 4,
      "name": "Empty"
    },
    {
      "x": 4,
      "y": 7,
      "z": 4,
      "name": "Empty"
    },
    {
      "x": 4,
      "y": 8,
      "z": 4,
      "name": "Wood_Hardwood_Planks"
    },
    {
      "x": 4,
      "y": 0,
      "z": 5,
      "name": "Rock_Stone_Cobble"
    },
    {
      "x": 4,
      "y": 1,
      "z": 5,
      "name": "Rock_Stone_Cobble"
    },
    {
      "x": 4,
      "y": 2,
      "z": 5,
      "name": "Wood_Hardwood_Planks"
    },
    {
      "x": 4,
      "y": 3,
      "z": 5,
      "name": "Wood_Hardwood_Planks"
    },
    {
      "x": 4,
      "y": 4,
      "z": 5,
      "name": "Empty"
    },
    {
      "x": 4,
      "y": 5,
      "z": 5,
      "name": "Empty"
    },
    {
      "x": 4,
      "y": 6,
      "z": 5,
      "name": "Empty"
    },
    {
      "x": 4,
      "y": 7,
      "z": 5,
      "name": "Empty"
    },
    {
      "x": 4,
      "y": 8,
      "z": 5,
      "name": "Wood_Hardwood_Planks"
    },
    {
      "x": 4,
      "y": 0,
      "z": 6,
      "name": "Rock_Stone_Cobble"
    },
    {
      "x": 4,
      "y": 1,
      "z": 6,
      "name": "Wood_Hardwood_Planks"
    },
    {
      "x": 4,
      "y": 2,
      "z": 6,
      "name": "Wood_Hardwood_Planks"
    },
    {
      "x": 4,
      "y": 3,
      "z": 6,
      "name": "Wood_Hardwood_Planks"
    },
    {
      "x": 4,
      "y": 4,
      "z": 6,
      "name": "Empty"
    },
    {
      "x": 4,
      "y": 5,
      "z": 6,
      "name": "Empty"
    },
    {
      "x": 4,
      "y": 6,
      "z": 6,
      "name": "Empty"
    },
    {
      "x": 4,
      "y": 7,
      "z": 6,
      "name": "Empty"
    },
    {
      "x": 4,
      "y": 8,
      "z": 6,
      "name": "Rock_Stone_Cobble"
    },
    {
      "x": 5,
      "y": 2,
      "z": -5,
      "name": "Rock_Stone_Cobble"
    },
    {
      "x": 5,
      "y": 3,
      "z": -5,
      "name": "Rock_Stone_Cobble"
    },
    {
      "x": 5,
      "y": 4,
      "z": -5,
      "name": "Rock_Stone_Brick_Decorative"
    },
    {
      "x": 5,
      "y": 5,
      "z": -5,
      "name": "Rock_Stone_Cobble"
    },
    {
      "x": 5,
      "y": 6,
      "z": -5,
      "name": "Rock_Stone_Cobble"
    },
    {
      "x": 5,
      "y": 7,
      "z": -5,
      "name": "Rock_Stone_Cobble"
    },
    {
      "x": 5,
      "y": 8,
      "z": -5,
      "name": "Rock_Stone_Cobble"
    },
    {
      "x": 5,
      "y": 2,
      "z": -4,
      "name": "Rock_Stone_Cobble"
    },
    {
      "x": 5,
      "y": 3,
      "z": -4,
      "name": "Wood_Hardwood_Planks"
    },
    {
      "x": 5,
      "y": 4,
      "z": -4,
      "name": "Empty"
    },
    {
      "x": 5,
      "y": 5,
      "z": -4,
      "name": "Furniture_Village_Painting_2x2"
    },
    {
      "x": 5,
      "y": 6,
      "z": -4,
      "name": "Furniture_Village_Painting_2x2",
      "filler": 1024
    },
    {
      "x": 5,
      "y": 7,
      "z": -4,
      "name": "Wood_Hardwood_Planks_Half",
      "rotation": 4
    },
    {
      "x": 5,
      "y": 8,
      "z": -4,
      "name": "Wood_Hardwood_Planks"
    },
    {
      "x": 5,
      "y": 2,
      "z": -3,
      "name": "Rock_Stone_Cobble"
    },
    {
      "x": 5,
      "y": 3,
      "z": -3,
      "name": "Wood_Hardwood_Planks"
    },
    {
      "x": 5,
      "y": 4,
      "z": -3,
      "name": "Empty"
    },
    {
      "x": 5,
      "y": 5,
      "z": -3,
      "name": "Empty"
    },
    {
      "x": 5,
      "y": 6,
      "z": -3,
      "name": "Empty"
    },
    {
      "x": 5,
      "y": 7,
      "z": -3,
      "name": "Empty"
    },
    {
      "x": 5,
      "y": 8,
      "z": -3,
      "name": "Wood_Hardwood_Planks"
    },
    {
      "x": 5,
      "y": 2,
      "z": -2,
      "name": "Rock_Stone_Cobble"
    },
    {
      "x": 5,
      "y": 3,
      "z": -2,
      "name": "Wood_Hardwood_Planks"
    },
    {
      "x": 5,
      "y": 4,
      "z": -2,
      "name": "Empty"
    },
    {
      "x": 5,
      "y": 5,
      "z": -2,
      "name": "Empty"
    },
    {
      "x": 5,
      "y": 6,
      "z": -2,
      "name": "Empty"
    },
    {
      "x": 5,
      "y": 7,
      "z": -2,
      "name": "Empty"
    },
    {
      "x": 5,
      "y": 8,
      "z": -2,
      "name": "Wood_Hardwood_Planks"
    },
    {
      "x": 5,
      "y": 2,
      "z": -1,
      "name": "Rock_Stone_Cobble"
    },
    {
      "x": 5,
      "y": 3,
      "z": -1,
      "name": "Wood_Hardwood_Planks"
    },
    {
      "x": 5,
      "y": 4,
      "z": -1,
      "name": "Empty"
    },
    {
      "x": 5,
      "y": 5,
      "z": -1,
      "name": "Empty"
    },
    {
      "x": 5,
      "y": 6,
      "z": -1,
      "name": "Empty"
    },
    {
      "x": 5,
      "y": 7,
      "z": -1,
      "name": "Empty"
    },
    {
      "x": 5,
      "y": 8,
      "z": -1,
      "name": "Wood_Hardwood_Planks"
    },
    {
      "x": 5,
      "y": 2,
      "z": 0,
      "name": "Rock_Stone_Cobble"
    },
    {
      "x": 5,
      "y": 3,
      "z": 0,
      "name": "Wood_Hardwood_Planks"
    },
    {
      "x": 5,
      "y": 4,
      "z": 0,
      "name": "Empty"
    },
    {
      "x": 5,
      "y": 5,
      "z": 0,
      "name": "Empty"
    },
    {
      "x": 5,
      "y": 6,
      "z": 0,
      "name": "Empty"
    },
    {
      "x": 5,
      "y": 7,
      "z": 0,
      "name": "Empty"
    },
    {
      "x": 5,
      "y": 8,
      "z": 0,
      "name": "Wood_Hardwood_Planks"
    },
    {
      "x": 5,
      "y": 2,
      "z": 1,
      "name": "Rock_Stone_Cobble"
    },
    {
      "x": 5,
      "y": 3,
      "z": 1,
      "name": "Wood_Hardwood_Planks"
    },
    {
      "x": 5,
      "y": 4,
      "z": 1,
      "name": "Empty"
    },
    {
      "x": 5,
      "y": 5,
      "z": 1,
      "name": "Empty"
    },
    {
      "x": 5,
      "y": 6,
      "z": 1,
      "name": "Empty"
    },
    {
      "x": 5,
      "y": 7,
      "z": 1,
      "name": "Empty"
    },
    {
      "x": 5,
      "y": 8,
      "z": 1,
      "name": "Wood_Hardwood_Planks"
    },
    {
      "x": 5,
      "y": 2,
      "z": 2,
      "name": "Rock_Stone_Cobble"
    },
    {
      "x": 5,
      "y": 3,
      "z": 2,
      "name": "Wood_Hardwood_Planks"
    },
    {
      "x": 5,
      "y": 4,
      "z": 2,
      "name": "Empty"
    },
    {
      "x": 5,
      "y": 5,
      "z": 2,
      "name": "Empty"
    },
    {
      "x": 5,
      "y": 6,
      "z": 2,
      "name": "Empty"
    },
    {
      "x": 5,
      "y": 7,
      "z": 2,
      "name": "Empty"
    },
    {
      "x": 5,
      "y": 8,
      "z": 2,
      "name": "Wood_Hardwood_Planks"
    },
    {
      "x": 5,
      "y": 2,
      "z": 3,
      "name": "Rock_Stone_Cobble"
    },
    {
      "x": 5,
      "y": 3,
      "z": 3,
      "name": "Wood_Hardwood_Planks"
    },
    {
      "x": 5,
      "y": 4,
      "z": 3,
      "name": "Empty"
    },
    {
      "x": 5,
      "y": 5,
      "z": 3,
      "name": "Empty"
    },
    {
      "x": 5,
      "y": 6,
      "z": 3,
      "name": "Empty"
    },
    {
      "x": 5,
      "y": 7,
      "z": 3,
      "name": "Empty"
    },
    {
      "x": 5,
      "y": 8,
      "z": 3,
      "name": "Wood_Hardwood_Planks"
    },
    {
      "x": 5,
      "y": 0,
      "z": 4,
      "name": "Rock_Stone_Cobble"
    },
    {
      "x": 5,
      "y": 1,
      "z": 4,
      "name": "Rock_Stone_Cobble"
    },
    {
      "x": 5,
      "y": 2,
      "z": 4,
      "name": "Rock_Stone_Cobble"
    },
    {
      "x": 5,
      "y": 3,
      "z": 4,
      "name": "Wood_Hardwood_Planks"
    },
    {
      "x": 5,
      "y": 4,
      "z": 4,
      "name": "Empty"
    },
    {
      "x": 5,
      "y": 5,
      "z": 4,
      "name": "Empty"
    },
    {
      "x": 5,
      "y": 6,
      "z": 4,
      "name": "Empty"
    },
    {
      "x": 5,
      "y": 7,
      "z": 4,
      "name": "Empty"
    },
    {
      "x": 5,
      "y": 8,
      "z": 4,
      "name": "Wood_Hardwood_Planks"
    },
    {
      "x": 5,
      "y": 0,
      "z": 5,
      "name": "Rock_Stone_Cobble"
    },
    {
      "x": 5,
      "y": 1,
      "z": 5,
      "name": "Rock_Stone_Cobble"
    },
    {
      "x": 5,
      "y": 2,
      "z": 5,
      "name": "Wood_Hardwood_Planks"
    },
    {
      "x": 5,
      "y": 3,
      "z": 5,
      "name": "Wood_Hardwood_Planks"
    },
    {
      "x": 5,
      "y": 4,
      "z": 5,
      "name": "Empty"
    },
    {
      "x": 5,
      "y": 5,
      "z": 5,
      "name": "Empty"
    },
    {
      "x": 5,
      "y": 6,
      "z": 5,
      "name": "Empty"
    },
    {
      "x": 5,
      "y": 7,
      "z": 5,
      "name": "Empty"
    },
    {
      "x": 5,
      "y": 8,
      "z": 5,
      "name": "Wood_Hardwood_Planks"
    },
    {
      "x": 5,
      "y": 0,
      "z": 6,
      "name": "Rock_Stone_Cobble"
    },
    {
      "x": 5,
      "y": 1,
      "z": 6,
      "name": "Wood_Hardwood_Planks"
    },
    {
      "x": 5,
      "y": 2,
      "z": 6,
      "name": "Wood_Hardwood_Planks"
    },
    {
      "x": 5,
      "y": 3,
      "z": 6,
      "name": "Wood_Hardwood_Planks"
    },
    {
      "x": 5,
      "y": 4,
      "z": 6,
      "name": "Empty"
    },
    {
      "x": 5,
      "y": 5,
      "z": 6,
      "name": "Empty"
    },
    {
      "x": 5,
      "y": 6,
      "z": 6,
      "name": "Empty"
    },
    {
      "x": 5,
      "y": 7,
      "z": 6,
      "name": "Empty"
    },
    {
      "x": 5,
      "y": 8,
      "z": 6,
      "name": "Rock_Stone_Cobble"
    },
    {
      "x": 6,
      "y": 2,
