{
  "version": 8,
  "blockIdVersion": 8,
  "anchorX": 0,
  "anchorY": 0,
  "anchorZ": 0,
  "blocks": [
    {
      "x": -24,
      "y": 0,
      "z": -8,
      "name": "Rock_Stone"
    },
    {
      "x": -24,
      "y": 1,
      "z": -8,
      "name": "Rock_Stone"
    },
    {
      "x": -24,
      "y": 2,
      "z": -8,
      "name": "Rock_Stone"
    },
    {
      "x": -24,
      "y": 3,
      "z": -8,
      "name": "Rock_Stone"
    },
    {
      "x": -24,
      "y": 4,
      "z": -8,
      "name": "Rock_Stone"
    },
    {
      "x": -24,
      "y": 5,
      "z": -8,
      "name": "Rock_Stone"
    },
    {
      "x": -24,
      "y": 6,
      "z": -8,
      "name": "Rock_Stone"
    },
    {
      "x": -24,
      "y": 7,
      "z": -8,
      "name": "Rock_Stone"
    },
    {
      "x": -24,
      "y": 8,
      "z": -8,
      "name": "Rock_Stone"
    },
    {
      "x": -24,
      "y": 9,
      "z": -8,
      "name": "Rock_Stone"
    },
    {
      "x": -24,
      "y": 10,
      "z": -8,
      "name": "Rock_Stone"
    },
    {
      "x": -24,
      "y": 11,
      "z": -8,
      "name": "Rock_Stone"
    },
    {
      "x": -24,
      "y": 12,
      "z": -8,
      "name": "Rock_Stone"
    },
    {
      "x": -24,
      "y": 13,
      "z": -8,
      "name": "Rock_Stone"
    },
    {
      "x": -24,
      "y": 14,
      "z": -8,
      "name": "Rock_Stone"
    },
    {
      "x": -24,
      "y": 15,
      "z": -8,
      "name": "Rock_Stone"
    },
    {
      "x": -24,
      "y": 0,
      "z": -7,
      "name": "Rock_Stone"
    },
    {
      "x": -24,
      "y": 1,
      "z": -7,
      "name": "Rock_Stone"
    },
    {
      "x": -24,
      "y": 2,
      "z": -7,
      "name": "Rock_Stone"
    },
    {
      "x": -24,
      "y": 3,
      "z": -7,
      "name": "Rock_Stone"
    },
    {
      "x": -24,
      "y": 4,
      "z": -7,
      "name": "Rock_Stone"
    },
    {
      "x": -24,
      "y": 5,
      "z": -7,
      "name": "Rock_Stone"
    },
    {
      "x": -24,
      "y": 6,
      "z": -7,
      "name": "Rock_Stone"
    },
    {
      "x": -24,
      "y": 7,
      "z": -7,
      "name": "Rock_Stone"
    },
    {
      "x": -24,
      "y": 8,
      "z": -7,
      "name": "Rock_Stone"
    },
    {
      "x": -24,
      "y": 9,
      "z": -7,
      "name": "Rock_Stone"
    },
    {
      "x": -24,
      "y": 10,
      "z": -7,
      "name": "Rock_Stone"
    },
    {
      "x": -24,
      "y": 11,
      "z": -7,
      "name": "Rock_Stone"
    },
    {
      "x": -24,
      "y": 12,
      "z": -7,
      "name": "Rock_Stone"
    },
    {
      "x": -24,
      "y": 13,
      "z": -7,
      "name": "Rock_Stone"
    },
    {
      "x": -24,
      "y": 14,
      "z": -7,
      "name": "Rock_Stone"
    },
    {
      "x": -24,
      "y": 15,
      "z": -7,
      "name": "Rock_Stone"
    },
    {
      "x": -24,
      "y": 0,
      "z": -6,
      "name": "Rock_Stone"
    },
    {
      "x": -24,
      "y": 1,
      "z": -6,
      "name": "Rock_Stone"
    },
    {
      "x": -24,
      "y": 2,
      "z": -6,
      "name": "Rock_Stone"
    },
    {
      "x": -24,
      "y": 3,
      "z": -6,
      "name": "Rock_Stone"
    },
    {
      "x": -24,
      "y": 4,
      "z": -6,
      "name": "Rock_Stone"
    },
    {
      "x": -24,
      "y": 5,
      "z": -6,
      "name": "Rock_Stone"
    },
    {
      "x": -24,
      "y": 6,
      "z": -6,
      "name": "Rock_Stone"
    },
    {
      "x": -24,
      "y": 7,
      "z": -6,
      "name": "Rock_Stone"
    },
    {
      "x": -24,
      "y": 8,
      "z": -6,
      "name": "Rock_Stone"
    },
    {
      "x": -24,
      "y": 9,
      "z": -6,
      "name": "Rock_Stone"
    },
    {
      "x": -24,
      "y": 10,
      "z": -6,
      "name": "Rock_Stone"
    },
    {
      "x": -24,
      "y": 11,
      "z": -6,
      "name": "Rock_Stone"
    },
    {
      "x": -24,
      "y": 12,
      "z": -6,
      "name": "Rock_Stone"
    },
    {
      "x": -24,
      "y": 13,
      "z": -6,
      "name": "Rock_Stone"
    },
    {
      "x": -24,
      "y": 14,
      "z": -6,
      "name": "Rock_Stone"
    },
    {
      "x": -24,
      "y": 15,
      "z": -6,
      "name": "Rock_Stone"
    },
    {
      "x": -24,
      "y": 0,
      "z": -5,
      "name": "Rock_Stone"
    },
    {
      "x": -24,
      "y": 1,
      "z": -5,
      "name": "Rock_Stone"
    },
    {
      "x": -24,
      "y": 2,
      "z": -5,
      "name": "Rock_Stone"
    },
    {
      "x": -24,
      "y": 3,
      "z": -5,
      "name": "Rock_Stone"
    },
    {
      "x": -24,
      "y": 4,
      "z": -5,
      "name": "Rock_Stone"
    },
    {
      "x": -24,
      "y": 5,
      "z": -5,
      "name": "Rock_Stone"
    },
    {
      "x": -24,
      "y": 6,
      "z": -5,
      "name": "Rock_Stone"
    },
    {
      "x": -24,
      "y": 7,
      "z": -5,
      "name": "Rock_Stone"
    },
    {
      "x": -24,
      "y": 8,
      "z": -5,
      "name": "Rock_Stone"
    },
    {
      "x": -24,
      "y": 9,
      "z": -5,
      "name": "Rock_Stone"
    },
    {
      "x": -24,
      "y": 10,
      "z": -5,
      "name": "Rock_Stone"
    },
    {
      "x": -24,
      "y": 11,
      "z": -5,
      "name": "Rock_Stone"
    },
    {
      "x": -24,
      "y": 12,
      "z": -5,
      "name": "Rock_Stone"
    },
    {
      "x": -24,
      "y": 13,
      "z": -5,
      "name": "Rock_Stone"
    },
    {
      "x": -24,
      "y": 14,
      "z": -5,
      "name": "Rock_Stone"
    },
    {
      "x": -24,
      "y": 15,
      "z": -5,
      "name": "Rock_Stone"
    },
    {
      "x": -24,
      "y": 0,
      "z": -4,
      "name": "Rock_Stone"
    },
    {
      "x": -24,
      "y": 1,
      "z": -4,
      "name": "Rock_Stone"
    },
    {
      "x": -24,
      "y": 2,
      "z": -4,
      "name": "Rock_Stone"
    },
    {
      "x": -24,
      "y": 3,
      "z": -4,
      "name": "Rock_Stone"
    },
    {
      "x": -24,
      "y": 4,
      "z": -4,
      "name": "Rock_Stone"
    },
    {
      "x": -24,
      "y": 5,
      "z": -4,
      "name": "Rock_Stone"
    },
    {
      "x": -24,
      "y": 6,
      "z": -4,
      "name": "Rock_Stone"
    },
    {
      "x": -24,
      "y": 7,
      "z": -4,
      "name": "Rock_Stone"
    },
    {
      "x": -24,
      "y": 8,
      "z": -4,
      "name": "Rock_Stone"
    },
    {
      "x": -24,
      "y": 9,
      "z": -4,
      "name": "Rock_Stone"
    },
    {
      "x": -24,
      "y": 10,
      "z": -4,
      "name": "Rock_Stone"
    },
    {
      "x": -24,
      "y": 11,
      "z": -4,
      "name": "Rock_Stone"
    },
    {
      "x": -24,
      "y": 12,
      "z": -4,
      "name": "Rock_Stone"
    },
    {
      "x": -24,
      "y": 13,
      "z": -4,
      "name": "Rock_Stone"
    },
    {
      "x": -24,
      "y": 14,
      "z": -4,
      "name": "Rock_Stone"
    },
    {
      "x": -24,
      "y": 15,
      "z": -4,
      "name": "Rock_Stone"
    },
    {
      "x": -24,
      "y": 0,
      "z": -3,
      "name": "Rock_Stone"
    },
    {
      "x": -24,
      "y": 1,
      "z": -3,
      "name": "Rock_Stone"
    },
    {
      "x": -24,
      "y": 2,
      "z": -3,
      "name": "Rock_Stone"
    },
    {
      "x": -24,
      "y": 3,
      "z": -3,
      "name": "Rock_Stone"
    },
    {
      "x": -24,
      "y": 4,
      "z": -3,
      "name": "Rock_Stone"
    },
    {
      "x": -24,
      "y": 5,
      "z": -3,
      "name": "Rock_Stone"
    },
    {
      "x": -24,
      "y": 6,
      "z": -3,
      "name": "Rock_Stone"
    },
    {
      "x": -24,
      "y": 7,
      "z": -3,
      "name": "Rock_Stone"
    },
    {
      "x": -24,
      "y": 8,
      "z": -3,
      "name": "Rock_Stone"
    },
    {
      "x": -24,
      "y": 9,
      "z": -3,
      "name": "Rock_Stone"
    },
    {
      "x": -24,
      "y": 10,
      "z": -3,
      "name": "Rock_Stone"
    },
    {
      "x": -24,
      "y": 11,
      "z": -3,
      "name": "Rock_Stone"
    },
    {
      "x": -24,
      "y": 12,
      "z": -3,
      "name": "Rock_Stone"
    },
    {
      "x": -24,
      "y": 13,
      "z": -3,
      "name": "Rock_Stone"
    },
    {
      "x": -24,
      "y": 14,
      "z": -3,
      "name": "Rock_Stone"
    },
    {
      "x": -24,
      "y": 15,
      "z": -3,
      "name": "Rock_Stone"
    },
    {
      "x": -24,
      "y": 0,
      "z": -2,
      "name": "Rock_Stone"
    },
    {
      "x": -24,
      "y": 1,
      "z": -2,
      "name": "Rock_Stone"
    },
    {
      "x": -24,
      "y": 2,
      "z": -2,
      "name": "Rock_Stone"
    },
    {
      "x": -24,
      "y": 3,
      "z": -2,
      "name": "Rock_Stone"
    },
    {
      "x": -24,
      "y": 4,
      "z": -2,
      "name": "Rock_Stone"
    },
    {
      "x": -24,
      "y": 5,
      "z": -2,
      "name": "Rock_Stone"
    },
    {
      "x": -24,
      "y": 6,
      "z": -2,
      "name": "Rock_Stone"
    },
    {
      "x": -24,
      "y": 7,
      "z": -2,
      "name": "Rock_Stone"
    },
    {
      "x": -24,
      "y": 8,
      "z": -2,
      "name": "Rock_Stone"
    },
    {
      "x": -24,
      "y": 9,
      "z": -2,
      "name": "Rock_Stone"
    },
    {
      "x": -24,
      "y": 10,
      "z": -2,
      "name": "Rock_Stone"
    },
    {
      "x": -24,
      "y": 11,
      "z": -2,
      "name": "Rock_Stone"
    },
    {
      "x": -24,
      "y": 12,
      "z": -2,
      "name": "Rock_Stone"
    },
    {
      "x": -24,
      "y": 13,
      "z": -2,
      "name": "Rock_Stone"
    },
    {
      "x": -24,
      "y": 14,
      "z": -2,
      "name": "Rock_Stone"
    },
    {
      "x": -24,
      "y": 15,
      "z": -2,
      "name": "Rock_Stone"
    },
    {
      "x": -24,
      "y": 0,
      "z": -1,
      "name": "Rock_Stone"
    },
    {
      "x": -24,
      "y": 1,
      "z": -1,
      "name": "Rock_Stone"
    },
    {
      "x": -24,
      "y": 2,
      "z": -1,
      "name": "Rock_Stone"
    },
    {
      "x": -24,
      "y": 3,
      "z": -1,
      "name": "Rock_Stone"
    },
    {
      "x": -24,
      "y": 4,
      "z": -1,
      "name": "Rock_Stone"
    },
    {
      "x": -24,
      "y": 5,
      "z": -1,
      "name": "Rock_Stone"
    },
    {
      "x": -24,
      "y": 6,
      "z": -1,
      "name": "Rock_Stone"
    },
    {
      "x": -24,
      "y": 7,
      "z": -1,
      "name": "Rock_Stone"
    },
    {
      "x": -24,
      "y": 8,
      "z": -1,
      "name": "Rock_Stone"
    },
    {
      "x": -24,
      "y": 9,
      "z": -1,
      "name": "Rock_Stone"
    },
    {
      "x": -24,
      "y": 10,
      "z": -1,
      "name": "Rock_Stone"
    },
    {
      "x": -24,
      "y": 11,
      "z": -1,
      "name": "Rock_Stone"
    },
    {
      "x": -24,
      "y": 12,
      "z": -1,
      "name": "Rock_Stone"
    },
    {
      "x": -24,
      "y": 13,
      "z": -1,
      "name": "Rock_Stone"
    },
    {
      "x": -24,
      "y": 14,
      "z": -1,
      "name": "Rock_Stone"
    },
    {
      "x": -24,
      "y": 15,
      "z": -1,
      "name": "Rock_Stone"
    },
    {
      "x": -24,
      "y": 0,
      "z": 0,
      "name": "Rock_Stone"
    },
    {
      "x": -24,
      "y": 1,
      "z": 0,
      "name": "Rock_Stone"
    },
    {
      "x": -24,
      "y": 2,
      "z": 0,
      "name": "Rock_Stone"
    },
    {
      "x": -24,
      "y": 3,
      "z": 0,
      "name": "Rock_Stone"
    },
    {
      "x": -24,
      "y": 4,
      "z": 0,
      "name": "Rock_Stone"
    },
    {
      "x": -24,
      "y": 5,
      "z": 0,
      "name": "Rock_Stone"
    },
    {
      "x": -24,
      "y": 6,
      "z": 0,
      "name": "Rock_Stone"
    },
    {
      "x": -24,
      "y": 7,
      "z": 0,
      "name": "Rock_Stone"
    },
    {
      "x": -24,
      "y": 8,
      "z": 0,
      "name": "Rock_Stone"
    },
    {
      "x": -24,
      "y": 9,
      "z": 0,
      "name": "Rock_Stone"
    },
    {
      "x": -24,
      "y": 10,
      "z": 0,
      "name": "Rock_Stone"
    },
    {
      "x": -24,
      "y": 11,
      "z": 0,
      "name": "Rock_Stone"
    },
    {
      "x": -24,
      "y": 12,
      "z": 0,
      "name": "Rock_Stone"
    },
    {
      "x": -24,
      "y": 13,
      "z": 0,
      "name": "Rock_Stone"
    },
    {
      "x": -24,
      "y": 14,
      "z": 0,
      "name": "Rock_Stone"
    },
    {
      "x": -24,
      "y": 15,
      "z": 0,
      "name": "Rock_Stone"
    },
    {
      "x": -24,
      "y": 0,
      "z": 1,
      "name": "Rock_Stone"
    },
    {
      "x": -24,
      "y": 1,
      "z": 1,
      "name": "Rock_Stone"
    },
    {
      "x": -24,
      "y": 2,
      "z": 1,
      "name": "Rock_Stone"
    },
    {
      "x": -24,
      "y": 3,
      "z": 1,
      "name": "Rock_Stone"
    },
    {
      "x": -24,
      "y": 4,
      "z": 1,
      "name": "Rock_Stone"
    },
    {
      "x": -24,
      "y": 5,
      "z": 1,
      "name": "Rock_Stone"
    },
    {
      "x": -24,
      "y": 6,
      "z": 1,
      "name": "Rock_Stone"
    },
    {
      "x": -24,
      "y": 7,
      "z": 1,
      "name": "Rock_Stone"
    },
    {
      "x": -24,
      "y": 8,
      "z": 1,
      "name": "Rock_Stone"
    },
    {
      "x": -24,
      "y": 9,
      "z": 1,
      "name": "Rock_Stone"
    },
    {
      "x": -24,
      "y": 10,
      "z": 1,
      "name": "Rock_Stone"
    },
    {
      "x": -24,
      "y": 11,
      "z": 1,
      "name": "Rock_Stone"
    },
    {
      "x": -24,
      "y": 12,
      "z": 1,
      "name": "Rock_Stone"
    },
    {
      "x": -24,
      "y": 13,
      "z": 1,
      "name": "Rock_Stone"
    },
    {
      "x": -24,
      "y": 14,
      "z": 1,
      "name": "Rock_Stone"
    },
    {
      "x": -24,
      "y": 15,
      "z": 1,
      "name": "Rock_Stone"
    },
    {
      "x": -24,
      "y": 0,
      "z": 2,
      "name": "Rock_Stone"
    },
    {
      "x": -24,
      "y": 1,
      "z": 2,
      "name": "Rock_Stone"
    },
    {
      "x": -24,
      "y": 2,
      "z": 2,
      "name": "Rock_Stone"
    },
    {
      "x": -24,
      "y": 3,
      "z": 2,
      "name": "Rock_Stone"
    },
    {
      "x": -24,
      "y": 4,
      "z": 2,
      "name": "Rock_Stone"
    },
    {
      "x": -24,
      "y": 5,
      "z": 2,
      "name": "Rock_Stone"
    },
    {
      "x": -24,
      "y": 6,
      "z": 2,
      "name": "Rock_Stone"
    },
    {
      "x": -24,
      "y": 7,
      "z": 2,
      "name": "Rock_Stone"
    },
    {
      "x": -24,
      "y": 8,
      "z": 2,
      "name": "Rock_Stone"
    },
    {
      "x": -24,
      "y": 9,
      "z": 2,
      "name": "Rock_Stone"
    },
    {
      "x": -24,
      "y": 10,
      "z": 2,
      "name": "Rock_Stone"
    },
    {
      "x": -24,
      "y": 11,
      "z": 2,
      "name": "Rock_Stone"
    },
    {
      "x": -24,
      "y": 12,
      "z": 2,
      "name": "Rock_Stone"
    },
    {
      "x": -24,
      "y": 13,
      "z": 2,
      "name": "Rock_Stone"
    },
    {
      "x": -24,
      "y": 14,
      "z": 2,
      "name": "Rock_Stone"
    },
    {
      "x": -24,
      "y": 15,
      "z": 2,
      "name": "Rock_Stone"
    },
    {
      "x": -24,
      "y": 0,
      "z": 3,
      "name": "Rock_Stone"
    },
    {
      "x": -24,
      "y": 1,
      "z": 3,
      "name": "Rock_Stone"
    },
    {
      "x": -24,
      "y": 2,
      "z": 3,
      "name": "Rock_Stone"
    },
    {
      "x": -24,
      "y": 3,
      "z": 3,
      "name": "Rock_Stone"
    },
    {
      "x": -24,
      "y": 4,
      "z": 3,
      "name": "Rock_Stone"
    },
    {
      "x": -24,
      "y": 5,
      "z": 3,
      "name": "Rock_Stone"
    },
    {
      "x": -24,
      "y": 6,
      "z": 3,
      "name": "Rock_Stone"
    },
    {
      "x": -24,
      "y": 7,
      "z": 3,
      "name": "Rock_Stone"
    },
    {
      "x": -24,
      "y": 8,
      "z": 3,
      "name": "Rock_Stone"
    },
    {
      "x": -24,
      "y": 9,
      "z": 3,
      "name": "Rock_Stone"
    },
    {
      "x": -24,
      "y": 10,
      "z": 3,
      "name": "Rock_Stone"
    },
    {
      "x": -24,
      "y": 11,
      "z": 3,
      "name": "Rock_Stone"
    },
    {
      "x": -24,
      "y": 12,
      "z": 3,
      "name": "Rock_Stone"
    },
    {
      "x": -24,
      "y": 13,
      "z": 3,
      "name": "Rock_Stone"
    },
    {
      "x": -24,
      "y": 14,
      "z": 3,
      "name": "Rock_Stone"
    },
    {
      "x": -24,
      "y": 15,
      "z": 3,
      "name": "Rock_Stone"
    },
    {
      "x": -24,
      "y": 0,
      "z": 4,
      "name": "Rock_Stone"
    },
    {
      "x": -24,
      "y": 1,
      "z": 4,
      "name": "Rock_Stone"
    },
    {
      "x": -24,
      "y": 2,
      "z": 4,
      "name": "Rock_Stone"
    },
    {
      "x": -24,
      "y": 3,
      "z": 4,
      "name": "Rock_Stone"
    },
    {
      "x": -24,
      "y": 4,
      "z": 4,
      "name": "Rock_Stone"
    },
    {
      "x": -24,
      "y": 5,
      "z": 4,
      "name": "Rock_Stone"
    },
    {
      "x": -24,
      "y": 6,
      "z": 4,
      "name": "Rock_Stone"
    },
    {
      "x": -24,
      "y": 7,
      "z": 4,
      "name": "Rock_Stone"
    },
    {
      "x": -24,
      "y": 8,
      "z": 4,
      "name": "Rock_Stone"
    },
    {
      "x": -24,
      "y": 9,
      "z": 4,
      "name": "Rock_Stone"
    },
    {
      "x": -24,
      "y": 10,
      "z": 4,
      "name": "Rock_Stone"
    },
    {
      "x": -24,
      "y": 11,
      "z": 4,
      "name": "Rock_Stone"
    },
    {
      "x": -24,
      "y": 12,
      "z": 4,
      "name": "Rock_Stone"
    },
    {
      "x": -24,
      "y": 13,
      "z": 4,
      "name": "Rock_Stone"
    },
    {
      "x": -24,
      "y": 14,
      "z": 4,
      "name": "Rock_Stone"
    },
    {
      "x": -24,
      "y": 15,
      "z": 4,
      "name": "Rock_Stone"
    },
    {
      "x": -24,
      "y": 0,
      "z": 5,
      "name": "Rock_Stone"
    },
    {
      "x": -24,
      "y": 1,
      "z": 5,
      "name": "Rock_Stone"
    },
    {
      "x": -24,
      "y": 2,
      "z": 5,
      "name": "Rock_Stone"
    },
    {
      "x": -24,
      "y": 3,
      "z": 5,
      "name": "Rock_Stone"
    },
    {
      "x": -24,
      "y": 4,
      "z": 5,
      "name": "Rock_Stone"
    },
    {
      "x": -24,
      "y": 5,
      "z": 5,
      "name": "Rock_Stone"
    },
    {
      "x": -24,
      "y": 6,
      "z": 5,
      "name": "Rock_Stone"
    },
    {
      "x": -24,
      "y": 7,
      "z": 5,
      "name": "Rock_Stone"
    },
    {
      "x": -24,
      "y": 8,
      "z": 5,
      "name": "Rock_Stone"
    },
    {
      "x": -24,
      "y": 9,
      "z": 5,
      "name": "Rock_Stone"
    },
    {
      "x": -24,
      "y": 10,
      "z": 5,
      "name": "Rock_Stone"
    },
    {
      "x": -24,
      "y": 11,
      "z": 5,
      "name": "Rock_Stone"
    },
    {
      "x": -24,
      "y": 12,
      "z": 5,
      "name": "Rock_Stone"
    },
    {
      "x": -24,
      "y": 13,
      "z": 5,
      "name": "Rock_Stone"
    },
    {
      "x": -24,
      "y": 14,
      "z": 5,
      "name": "Rock_Stone"
    },
    {
      "x": -24,
      "y": 15,
      "z": 5,
      "name": "Rock_Stone"
    },
    {
      "x": -24,
      "y": 0,
      "z": 6,
      "name": "Rock_Stone"
    },
    {
      "x": -24,
      "y": 1,
      "z": 6,
      "name": "Rock_Stone"
    },
    {
      "x": -24,
      "y": 2,
      "z": 6,
      "name": "Rock_Stone"
    },
    {
      "x": -24,
      "y": 3,
      "z": 6,
      "name": "Rock_Stone"
    },
    {
      "x": -24,
      "y": 4,
      "z": 6,
      "name": "Rock_Stone"
    },
    {
      "x": -24,
      "y": 5,
      "z": 6,
      "name": "Rock_Stone"
    },
    {
      "x": -24,
      "y": 6,
      "z": 6,
      "name": "Rock_Stone"
    },
    {
      "x": -24,
      "y": 7,
      "z": 6,
      "name": "Rock_Stone"
    },
    {
      "x": -24,
      "y": 8,
      "z": 6,
      "name": "Rock_Stone"
    },
    {
      "x": -24,
      "y": 9,
      "z": 6,
      "name": "Rock_Stone"
    },
    {
      "x": -24,
      "y": 10,
      "z": 6,
      "name": "Rock_Stone"
    },
    {
      "x": -24,
      "y": 11,
      "z": 6,
      "name": "Rock_Stone"
    },
    {
      "x": -24,
      "y": 12,
      "z": 6,
      "name": "Rock_Stone"
    },
    {
      "x": -24,
      "y": 13,
      "z": 6,
      "name": "Rock_Stone"
    },
    {
      "x": -24,
      "y": 14,
      "z": 6,
      "name": "Rock_Stone"
    },
    {
      "x": -24,
      "y": 15,
      "z": 6,
      "name": "Rock_Stone"
    },
    {
      "x": -24,
      "y": 0,
      "z": 7,
      "name": "Rock_Stone"
    },
    {
      "x": -24,
      "y": 1,
      "z": 7,
      "name": "Rock_Stone"
    },
    {
      "x": -24,
      "y": 2,
      "z": 7,
      "name": "Rock_Stone"
    },
    {
      "x": -24,
      "y": 3,
      "z": 7,
      "name": "Rock_Stone"
    },
    {
      "x": -24,
      "y": 4,
      "z": 7,
      "name": "Rock_Stone"
    },
    {
      "x": -24,
      "y": 5,
      "z": 7,
      "name": "Rock_Stone"
    },
    {
      "x": -24,
      "y": 6,
      "z": 7,
      "name": "Rock_Stone"
    },
    {
      "x": -24,
      "y": 7,
      "z": 7,
      "name": "Rock_Stone"
    },
    {
      "x": -24,
      "y": 8,
      "z": 7,
      "name": "Rock_Stone"
    },
    {
      "x": -24,
      "y": 9,
      "z": 7,
      "name": "Rock_Stone"
    },
    {
      "x": -24,
      "y": 10,
      "z": 7,
      "name": "Rock_Stone"
    },
    {
      "x": -24,
      "y": 11,
      "z": 7,
      "name": "Rock_Stone"
    },
    {
      "x": -24,
      "y": 12,
      "z": 7,
      "name": "Rock_Stone"
    },
    {
      "x": -24,
      "y": 13,
      "z": 7,
      "name": "Rock_Stone"
    },
    {
      "x": -24,
      "y": 14,
      "z": 7,
      "name": "Rock_Stone"
    },
    {
      "x": -24,
      "y": 15,
      "z": 7,
      "name": "Rock_Stone"
    },
    {
      "x": -24,
      "y": 0,
      "z": 8,
      "name": "Rock_Stone"
    },
    {
      "x": -24,
      "y": 1,
      "z": 8,
      "name": "Rock_Stone"
    },
    {
      "x": -24,
      "y": 2,
      "z": 8,
      "name": "Rock_Stone"
    },
    {
      "x": -24,
      "y": 3,
      "z": 8,
      "name": "Rock_Stone"
    },
    {
      "x": -24,
      "y": 4,
      "z": 8,
      "name": "Rock_Stone"
    },
    {
      "x": -24,
      "y": 5,
      "z": 8,
      "name": "Rock_Stone"
    },
    {
      "x": -24,
      "y": 6,
      "z": 8,
      "name": "Rock_Stone"
    },
    {
      "x": -24,
      "y": 7,
      "z": 8,
      "name": "Rock_Stone"
    },
    {
      "x": -24,
      "y": 8,
      "z": 8,
      "name": "Rock_Stone"
    },
    {
      "x": -24,
      "y": 9,
      "z": 8,
      "name": "Rock_Stone"
    },
    {
      "x": -24,
      "y": 10,
      "z": 8,
      "name": "Rock_Stone"
    },
    {
      "x": -24,
      "y": 11,
      "z": 8,
      "name": "Rock_Stone"
    },
    {
      "x": -24,
      "y": 12,
      "z": 8,
      "name": "Rock_Stone"
    },
    {
      "x": -24,
      "y": 13,
      "z": 8,
      "name": "Rock_Stone"
    },
    {
      "x": -24,
      "y": 14,
      "z": 8,
      "name": "Rock_Stone"
    },
    {
      "x": -24,
      "y": 15,
      "z": 8,
      "name": "Rock_Stone"
    },
    {
      "x": -24,
      "y": 0,
      "z": 9,
      "name": "Rock_Stone"
    },
    {
      "x": -24,
      "y": 1,
      "z": 9,
      "name": "Rock_Stone"
    },
    {
      "x": -24,
      "y": 2,
      "z": 9,
      "name": "Rock_Stone"
    },
    {
      "x": -24,
      "y": 3,
      "z": 9,
      "name": "Rock_Stone"
    },
    {
      "x": -24,
      "y": 4,
      "z": 9,
      "name": "Rock_Stone"
    },
    {
      "x": -24,
      "y": 5,
      "z": 9,
      "name": "Rock_Stone"
    },
    {
      "x": -24,
      "y": 6,
      "z": 9,
      "name": "Rock_Stone"
    },
    {
      "x": -24,
      "y": 7,
      "z": 9,
      "name": "Rock_Stone"
    },
    {
      "x": -24,
      "y": 8,
      "z": 9,
      "name": "Rock_Stone"
    },
    {
      "x": -24,
      "y": 9,
      "z": 9,
      "name": "Rock_Stone"
    },
    {
      "x": -24,
      "y": 10,
      "z": 9,
      "name": "Rock_Stone"
    },
    {
      "x": -24,
      "y": 11,
      "z": 9,
      "name": "Rock_Stone"
    },
    {
      "x": -24,
      "y": 12,
      "z": 9,
      "name": "Rock_Stone"
    },
    {
      "x": -24,
      "y": 13,
      "z": 9,
      "name": "Rock_Stone"
    },
    {
      "x": -24,
      "y": 14,
      "z": 9,
      "name": "Rock_Stone"
    },
    {
      "x": -24,
      "y": 15,
      "z": 9,
      "name": "Rock_Stone"
    },
    {
      "x": -24,
      "y": 0,
      "z": 10,
      "name": "Rock_Stone"
    },
    {
      "x": -24,
      "y": 1,
      "z": 10,
      "name": "Rock_Stone"
    },
    {
      "x": -24,
      "y": 2,
      "z": 10,
      "name": "Rock_Stone"
    },
    {
      "x": -24,
      "y": 3,
      "z": 10,
      "name": "Rock_Stone"
    },
    {
      "x": -24,
      "y": 4,
      "z": 10,
      "name": "Rock_Stone"
    },
    {
      "x": -24,
      "y": 5,
      "z": 10,
      "name": "Rock_Stone"
    },
    {
      "x": -24,
      "y": 6,
      "z": 10,
      "name": "Rock_Stone"
    },
    {
      "x": -24,
      "y": 7,
      "z": 10,
      "name": "Rock_Stone"
    },
    {
      "x": -24,
      "y": 8,
      "z": 10,
      "name": "Rock_Stone"
    },
    {
      "x": -24,
      "y": 9,
      "z": 10,
      "name": "Rock_Stone"
    },
    {
      "x": -24,
      "y": 10,
      "z": 10,
      "name": "Rock_Stone"
    },
    {
      "x": -24,
      "y": 11,
      "z": 10,
      "name": "Rock_Stone"
    },
    {
      "x": -24,
      "y": 12,
      "z": 10,
      "name": "Rock_Stone"
    },
    {
      "x": -24,
      "y": 13,
      "z": 10,
      "name": "Rock_Stone"
    },
    {
      "x": -24,
      "y": 14,
      "z": 10,
      "name": "Rock_Stone"
    },
    {
      "x": -24,
      "y": 15,
      "z": 10,
      "name": "Rock_Stone"
    },
    {
      "x": -24,
      "y": 0,
      "z": 11,
      "name": "Rock_Stone"
    },
    {
      "x": -24,
      "y": 1,
      "z": 11,
      "name": "Rock_Stone"
    },
    {
      "x": -24,
      "y": 2,
      "z": 11,
      "name": "Rock_Stone"
    },
    {
      "x": -24,
      "y": 3,
      "z": 11,
      "name": "Rock_Stone"
    },
    {
      "x": -24,
      "y": 4,
      "z": 11,
      "name": "Rock_Stone"
    },
    {
      "x": -24,
      "y": 5,
      "z": 11,
      "name": "Rock_Stone"
    },
    {
      "x": -24,
      "y": 6,
      "z": 11,
      "name": "Rock_Stone"
    },
    {
      "x": -24,
      "y": 7,
      "z": 11,
      "name": "Rock_Stone"
    },
    {
      "x": -24,
      "y": 8,
      "z": 11,
      "name": "Rock_Stone"
    },
    {
      "x": -24,
      "y": 9,
      "z": 11,
      "name": "Rock_Stone"
    },
    {
      "x": -24,
      "y": 10,
      "z": 11,
      "name": "Rock_Stone"
    },
    {
      "x": -24,
      "y": 11,
      "z": 11,
      "name": "Rock_Stone"
    },
    {
      "x": -24,
      "y": 12,
      "z": 11,
      "name": "Rock_Stone"
    },
    {
      "x": -24,
      "y": 13,
      "z": 11,
      "name": "Rock_Stone"
    },
    {
      "x": -24,
      "y": 14,
      "z": 11,
      "name": "Rock_Stone"
    },
    {
      "x": -24,
      "y": 15,
      "z": 11,
      "name": "Rock_Stone"
    },
    {
      "x": -24,
      "y": 0,
      "z": 12,
      "name": "Rock_Stone"
    },
    {
      "x": -24,
      "y": 1,
      "z": 12,
      "name": "Rock_Stone"
    },
    {
      "x": -24,
      "y": 2,
      "z": 12,
      "name": "Rock_Stone"
    },
    {
      "x": -24,
      "y": 3,
      "z": 12,
      "name": "Rock_Stone"
    },
    {
      "x": -24,
      "y": 4,
      "z": 12,
      "name": "Rock_Stone"
    },
    {
      "x": -24,
      "y": 5,
      "z": 12,
      "name": "Rock_Stone"
    },
    {
      "x": -24,
      "y": 6,
      "z": 12,
      "name": "Rock_Stone"
    },
    {
      "x": -24,
      "y": 7,
      "z": 12,
      "name": "Rock_Stone"
    },
    {
      "x": -24,
      "y": 8,
      "z": 12,
      "name": "Rock_Stone"
    },
    {
      "x": -24,
      "y": 9,
      "z": 12,
      "name": "Rock_Stone"
    },
    {
      "x": -24,
      "y": 10,
      "z": 12,
      "name": "Rock_Stone"
    },
    {
      "x": -24,
      "y": 11,
      "z": 12,
      "name": "Rock_Stone"
    },
    {
      "x": -24,
      "y": 12,
      "z": 12,
      "name": "Rock_Stone"
    },
    {
      "x": -24,
      "y": 13,
      "z": 12,
      "name": "Rock_Stone"
    },
    {
      "x": -24,
      "y": 14,
      "z": 12,
      "name": "Rock_Stone"
    },
    {
      "x": -24,
      "y": 15,
      "z": 12,
      "name": "Rock_Stone"
    },
    {
      "x": -24,
      "y": 0,
      "z": 13,
      "name": "Rock_Stone"
    },
    {
      "x": -24,
      "y": 1,
      "z": 13,
      "name": "Rock_Stone"
    },
    {
      "x": -24,
      "y": 2,
      "z": 13,
      "name": "Rock_Stone"
    },
    {
      "x": -24,
      "y": 3,
      "z": 13,
      "name": "Rock_Stone"
    },
    {
      "x": -24,
      "y": 4,
      "z": 13,
      "name": "Rock_Stone"
    },
    {
      "x": -24,
      "y": 5,
      "z": 13,
      "name": "Rock_Stone"
    },
    {
      "x": -24,
      "y": 6,
      "z": 13,
      "name": "Rock_Stone"
    },
    {
      "x": -24,
      "y": 7,
      "z": 13,
      "name": "Rock_Stone"
    },
    {
      "x": -24,
      "y": 8,
      "z": 13,
      "name": "Rock_Stone"
    },
    {
      "x": -24,
      "y": 9,
      "z": 13,
      "name": "Rock_Stone"
    },
    {
      "x": -24,
      "y": 10,
      "z": 13,
      "name": "Rock_Stone"
    },
    {
      "x": -24,
      "y": 11,
      "z": 13,
      "name": "Rock_Stone"
    },
    {
      "x": -24,
      "y": 12,
      "z": 13,
      "name": "Rock_Stone"
    },
    {
      "x": -24,
      "y": 13,
      "z": 13,
      "name": "Rock_Stone"
    },
    {
      "x": -24,
      "y": 14,
      "z": 13,
      "name": "Rock_Stone"
    },
    {
      "x": -24,
      "y": 15,
      "z": 13,
      "name": "Rock_Stone"
    },
    {
      "x": -24,
      "y": 0,
      "z": 14,
      "name": "Rock_Stone"
    },
    {
      "x": -24,
      "y": 1,
      "z": 14,
      "name": "Rock_Stone"
    },
    {
      "x": -24,
      "y": 2,
      "z": 14,
      "name": "Rock_Stone"
    },
    {
      "x": -24,
      "y": 3,
      "z": 14,
      "name": "Rock_Stone"
    },
    {
      "x": -24,
      "y": 4,
      "z": 14,
      "name": "Rock_Stone"
    },
    {
      "x": -24,
      "y": 5,
      "z": 14,
      "name": "Rock_Stone"
    },
    {
      "x": -24,
      "y": 6,
      "z": 14,
      "name": "Rock_Stone"
    },
    {
      "x": -24,
      "y": 7,
      "z": 14,
      "name": "Rock_Stone"
    },
    {
      "x": -24,
      "y": 8,
      "z": 14,
      "name": "Rock_Stone"
    },
    {
      "x": -24,
      "y": 9,
      "z": 14,
      "name": "Rock_Stone"
    },
    {
      "x": -24,
      "y": 10,
      "z": 14,
      "name": "Rock_Stone"
    },
    {
      "x": -24,
      "y": 11,
      "z": 14,
      "name": "Rock_Stone"
    },
    {
      "x": -24,
      "y": 12,
      "z": 14,
      "name": "Rock_Stone"
    },
    {
      "x": -24,
      "y": 13,
      "z": 14,
      "name": "Rock_Stone"
    },
    {
      "x": -24,
      "y": 14,
      "z": 14,
      "name": "Rock_Stone"
    },
    {
      "x": -24,
      "y": 15,
      "z": 14,
      "name": "Rock_Stone"
    },
    {
      "x": -24,
      "y": 0,
      "z": 15,
      "name": "Rock_Stone"
    },
    {
      "x": -24,
      "y": 1,
      "z": 15,
      "name": "Rock_Stone"
    },
    {
      "x": -24,
      "y": 2,
      "z": 15,
      "name": "Rock_Stone"
    },
    {
      "x": -24,
      "y": 3,
      "z": 15,
      "name": "Rock_Stone"
    },
    {
      "x": -24,
      "y": 4,
      "z": 15,
      "name": "Rock_Stone"
    },
    {
      "x": -24,
      "y": 5,
      "z": 15,
      "name": "Rock_Stone"
    },
    {
      "x": -24,
      "y": 6,
      "z": 15,
      "name": "Rock_Stone"
    },
    {
      "x": -24,
      "y": 7,
      "z": 15,
      "name": "Rock_Stone"
    },
    {
      "x": -24,
      "y": 8,
      "z": 15,
      "name": "Rock_Stone"
    },
    {
      "x": -24,
      "y": 9,
      "z": 15,
      "name": "Rock_Stone"
    },
    {
      "x": -24,
      "y": 10,
      "z": 15,
      "name": "Rock_Stone"
    },
    {
      "x": -24,
      "y": 11,
      "z": 15,
      "name": "Rock_Stone"
    },
    {
      "x": -24,
      "y": 12,
      "z": 15,
      "name": "Rock_Stone"
    },
    {
      "x": -24,
      "y": 13,
      "z": 15,
      "name": "Rock_Stone"
    },
    {
      "x": -24,
      "y": 14,
      "z": 15,
      "name": "Rock_Stone"
    },
    {
      "x": -24,
      "y": 15,
      "z": 15,
      "name": "Rock_Stone"
    },
    {
      "x": -24,
      "y": 0,
      "z": 16,
      "name": "Rock_Stone"
    },
    {
      "x": -24,
      "y": 1,
      "z": 16,
      "name": "Rock_Stone"
    },
    {
      "x": -24,
      "y": 2,
      "z": 16,
      "name": "Rock_Stone"
    },
    {
      "x": -24,
      "y": 3,
      "z": 16,
      "name": "Rock_Stone"
    },
    {
      "x": -24,
      "y": 4,
      "z": 16,
      "name": "Rock_Stone"
    },
    {
      "x": -24,
      "y": 5,
      "z": 16,
      "name": "Rock_Stone"
    },
    {
      "x": -24,
      "y": 6,
      "z": 16,
      "name": "Rock_Stone"
    },
    {
      "x": -24,
      "y": 7,
      "z": 16,
      "name": "Rock_Stone"
    },
    {
      "x": -24,
      "y": 8,
      "z": 16,
      "name": "Rock_Stone"
    },
    {
      "x": -24,
      "y": 9,
      "z": 16,
      "name": "Rock_Stone"
    },
    {
      "x": -24,
      "y": 10,
      "z": 16,
      "name": "Rock_Stone"
    },
    {
      "x": -24,
      "y": 11,
      "z": 16,
      "name": "Rock_Stone"
    },
    {
      "x": -24,
      "y": 12,
      "z": 16,
      "name": "Rock_Stone"
    },
    {
      "x": -24,
      "y": 13,
      "z": 16,
      "name": "Rock_Stone"
    },
    {
      "x": -24,
      "y": 14,
      "z": 16,
      "name": "Rock_Stone"
    },
    {
      "x": -24,
      "y": 15,
      "z": 16,
      "name": "Rock_Stone"
    },
    {
      "x": -23,
      "y": 0,
      "z": -8,
      "name": "Rock_Stone"
    },
    {
      "x": -23,
      "y": 1,
      "z": -8,
      "name": "Rock_Stone"
    },
    {
      "x": -23,
      "y": 2,
      "z": -8,
      "name": "Rock_Stone"
    },
    {
      "x": -23,
      "y": 3,
      "z": -8,
      "name": "Rock_Stone"
    },
    {
      "x": -23,
      "y": 4,
      "z": -8,
      "name": "Rock_Stone"
    },
    {
      "x": -23,
      "y": 5,
      "z": -8,
      "name": "Rock_Stone"
    },
    {
      "x": -23,
      "y": 6,
      "z": -8,
      "name": "Rock_Stone"
    },
    {
      "x": -23,
      "y": 7,
      "z": -8,
      "name": "Rock_Stone"
    },
    {
      "x": -23,
      "y": 8,
      "z": -8,
      "name": "Rock_Stone"
    },
    {
      "x": -23,
      "y": 9,
      "z": -8,
      "name": "Rock_Stone"
    },
    {
      "x": -23,
      "y": 10,
      "z": -8,
      "name": "Rock_Stone"
    },
    {
      "x": -23,
      "y": 11,
      "z": -8,
      "name": "Rock_Stone"
    },
    {
      "x": -23,
      "y": 12,
      "z": -8,
      "name": "Rock_Stone"
    },
    {
      "x": -23,
      "y": 13,
      "z": -8,
      "name": "Rock_Stone"
    },
    {
      "x": -23,
      "y": 14,
      "z": -8,
      "name": "Rock_Stone"
    },
    {
      "x": -23,
      "y": 15,
      "z": -8,
      "name": "Rock_Stone"
    },
    {
      "x": -23,
      "y": 0,
      "z": -7,
      "name": "Rock_Stone"
    },
    {
      "x": -23,
      "y": 1,
      "z": -7,
      "name": "Rock_Stone"
    },
    {
      "x": -23,
      "y": 2,
      "z": -7,
      "name": "Rock_Stone"
    },
    {
      "x": -23,
      "y": 3,
      "z": -7,
      "name": "Rock_Stone"
    },
    {
      "x": -23,
      "y": 4,
      "z": -7,
      "name": "Rock_Stone"
    },
    {
      "x": -23,
      "y": 5,
      "z": -7,
      "name": "Rock_Stone"
    },
    {
      "x": -23,
      "y": 6,
      "z": -7,
      "name": "Rock_Stone"
    },
    {
      "x": -23,
      "y": 7,
      "z": -7,
      "name": "Rock_Stone"
    },
    {
      "x": -23,
      "y": 8,
      "z": -7,
      "name": "Rock_Stone"
    },
    {
      "x": -23,
      "y": 9,
      "z": -7,
      "name": "Rock_Stone"
    },
    {
      "x": -23,
      "y": 10,
      "z": -7,
      "name": "Rock_Stone"
    },
    {
      "x": -23,
      "y": 11,
      "z": -7,
      "name": "Rock_Stone"
    },
    {
      "x": -23,
      "y": 12,
      "z": -7,
      "name": "Rock_Stone"
    },
    {
      "x": -23,
      "y": 13,
      "z": -7,
      "name": "Rock_Stone"
    },
    {
      "x": -23,
      "y": 14,
      "z": -7,
      "name": "Rock_Stone"
    },
    {
      "x": -23,
      "y": 15,
      "z": -7,
      "name": "Rock_Stone"
    },
    {
      "x": -23,
      "y": 0,
      "z": -6,
      "name": "Rock_Stone"
    },
    {
      "x": -23,
      "y": 1,
      "z": -6,
      "name": "Rock_Stone"
    },
    {
      "x": -23,
      "y": 2,
      "z": -6,
      "name": "Rock_Stone"
    },
    {
      "x": -23,
      "y": 3,
      "z": -6,
      "name": "Rock_Stone"
    },
    {
      "x": -23,
      "y": 4,
      "z": -6,
      "name": "Rock_Stone"
    },
    {
      "x": -23,
      "y": 5,
      "z": -6,
      "name": "Rock_Stone"
    },
    {
      "x": -23,
      "y": 6,
      "z": -6,
      "name": "Rock_Stone"
    },
    {
      "x": -23,
      "y": 7,
      "z": -6,
      "name": "Rock_Stone"
    },
    {
      "x": -23,
      "y": 8,
      "z": -6,
      "name": "Rock_Stone"
    },
    {
      "x": -23,
      "y": 9,
      "z": -6,
      "name": "Rock_Stone"
    },
    {
      "x": -23,
      "y": 10,
      "z": -6,
      "name": "Rock_Stone"
    },
    {
      "x": -23,
      "y": 11,
      "z": -6,
      "name": "Rock_Stone"
    },
    {
      "x": -23,
      "y": 12,
      "z": -6,
      "name": "Rock_Stone"
    },
    {
      "x": -23,
      "y": 13,
      "z": -6,
      "name": "Rock_Stone"
    },
    {
      "x": -23,
      "y": 14,
      "z": -6,
      "name": "Rock_Stone"
    },
    {
      "x": -23,
      "y": 15,
      "z": -6,
      "name": "Rock_Stone"
    },
    {
      "x": -23,
      "y": 0,
      "z": -5,
      "name": "Rock_Stone"
    },
    {
      "x": -23,
      "y": 1,
      "z": -5,
      "name": "Rock_Stone"
    },
    {
      "x": -23,
      "y": 2,
      "z": -5,
      "name": "Rock_Stone"
    },
    {
      "x": -23,
      "y": 3,
      "z": -5,
      "name": "Rock_Stone"
    },
    {
      "x": -23,
      "y": 4,
      "z": -5,
      "name": "Rock_Stone"
    },
    {
      "x": -23,
      "y": 5,
      "z": -5,
      "name": "Rock_Stone"
    },
    {
      "x": -23,
      "y": 6,
      "z": -5,
      "name": "Rock_Stone"
    },
    {
      "x": -23,
      "y": 7,
      "z": -5,
      "name": "Rock_Stone"
    },
    {
      "x": -23,
      "y": 8,
      "z": -5,
      "name": "Rock_Stone"
    },
    {
      "x": -23,
      "y": 9,
      "z": -5,
      "name": "Rock_Stone"
    },
    {
      "x": -23,
      "y": 10,
      "z": -5,
      "name": "Rock_Stone"
    },
    {
      "x": -23,
      "y": 11,
      "z": -5,
      "name": "Rock_Stone"
    },
    {
      "x": -23,
      "y": 12,
      "z": -5,
      "name": "Rock_Stone"
    },
    {
      "x": -23,
      "y": 13,
      "z": -5,
      "name": "Rock_Stone"
    },
    {
      "x": -23,
      "y": 14,
      "z": -5,
      "name": "Rock_Stone"
    },
    {
      "x": -23,
      "y": 15,
      "z": -5,
      "name": "Rock_Stone"
    },
    {
      "x": -23,
      "y": 0,
      "z": -4,
      "name": "Rock_Stone"
    },
    {
      "x": -23,
      "y": 1,
      "z": -4,
      "name": "Rock_Stone"
    },
    {
      "x": -23,
      "y": 2,
      "z": -4,
      "name": "Rock_Stone"
    },
    {
      "x": -23,
      "y": 3,
      "z": -4,
      "name": "Rock_Stone"
    },
    {
      "x": -23,
      "y": 4,
      "z": -4,
      "name": "Rock_Stone"
    },
    {
      "x": -23,
      "y": 5,
      "z": -4,
      "name": "Rock_Stone"
    },
    {
      "x": -23,
      "y": 6,
      "z": -4,
      "name": "Rock_Stone"
    },
    {
      "x": -23,
      "y": 7,
      "z": -4,
      "name": "Rock_Stone"
    },
    {
      "x": -23,
      "y": 8,
      "z": -4,
      "name": "Rock_Stone"
    },
    {
      "x": -23,
      "y": 9,
      "z": -4,
      "name": "Rock_Stone"
    },
    {
      "x": -23,
      "y": 10,
      "z": -4,
      "name": "Rock_Stone"
    },
    {
      "x": -23,
      "y": 11,
      "z": -4,
      "name": "Rock_Stone"
    },
    {
      "x": -23,
      "y": 12,
      "z": -4,
      "name": "Rock_Stone"
    },
    {
      "x": -23,
      "y": 13,
      "z": -4,
      "name": "Rock_Stone"
    },
    {
      "x": -23,
      "y": 14,
      "z": -4,
      "name": "Rock_Stone"
    },
    {
      "x": -23,
      "y": 15,
      "z": -4,
      "name": "Rock_Stone"
    },
    {
      "x": -23,
      "y": 0,
      "z": -3,
      "name": "Rock_Stone"
    },
    {
      "x": -23,
      "y": 1,
      "z": -3,
      "name": "Rock_Stone"
    },
    {
      "x": -23,
      "y": 2,
      "z": -3,
      "name": "Rock_Stone"
    },
    {
      "x": -23,
      "y": 3,
      "z": -3,
      "name": "Rock_Stone"
    },
    {
      "x": -23,
      "y": 4,
      "z": -3,
      "name": "Rock_Stone"
    },
    {
      "x": -23,
      "y": 5,
      "z": -3,
      "name": "Rock_Stone"
    },
    {
      "x": -23,
      "y": 6,
      "z": -3,
      "name": "Rock_Stone"
    },
    {
      "x": -23,
      "y": 7,
      "z": -3,
      "name": "Rock_Stone"
    },
    {
      "x": -23,
      "y": 8,
      "z": -3,
      "name": "Rock_Stone"
    },
    {
      "x": -23,
      "y": 9,
      "z": -3,
      "name": "Rock_Stone"
    },
    {
      "x": -23,
      "y": 10,
      "z": -3,
      "name": "Rock_Stone"
    },
    {
      "x": -23,
      "y": 11,
      "z": -3,
      "name": "Rock_Stone"
    },
    {
      "x": -23,
      "y": 12,
      "z": -3,
      "name": "Rock_Stone"
    },
    {
      "x": -23,
      "y": 13,
      "z": -3,
      "name": "Rock_Stone"
    },
    {
      "x": -23,
      "y": 14,
      "z": -3,
      "name": "Rock_Stone"
    },
    {
      "x": -23,
      "y": 15,
      "z": -3,
      "name": "Rock_Stone"
    },
    {
      "x": -23,
      "y": 0,
      "z": -2,
      "name": "Rock_Stone"
    },
    {
      "x": -23,
      "y": 1,
      "z": -2,
      "name": "Rock_Stone"
    },
    {
      "x": -23,
      "y": 2,
      "z": -2,
      "name": "Rock_Stone"
    },
    {
      "x": -23,
      "y": 3,
      "z": -2,
      "name": "Rock_Stone"
    },
    {
      "x": -23,
      "y": 4,
      "z": -2,
      "name": "Rock_Stone"
    },
    {
      "x": -23,
      "y": 5,
      "z": -2,
      "name": "Rock_Stone"
    },
    {
      "x": -23,
      "y": 6,
      "z": -2,
      "name": "Rock_Stone"
    },
    {
      "x": -23,
      "y": 7,
      "z": -2,
      "name": "Rock_Stone"
    },
    {
      "x": -23,
      "y": 8,
      "z": -2,
      "name": "Rock_Stone"
    },
    {
      "x": -23,
      "y": 9,
      "z": -2,
      "name": "Rock_Stone"
    },
    {
      "x": -23,
      "y": 10,
      "z": -2,
      "name": "Rock_Stone"
    },
    {
      "x": -23,
      "y": 11,
      "z": -2,
      "name": "Rock_Stone"
    },
    {
      "x": -23,
      "y": 12,
      "z": -2,
      "name": "Rock_Stone"
    },
    {
      "x": -23,
      "y": 13,
      "z": -2,
      "name": "Rock_Stone"
    },
    {
      "x": -23,
      "y": 14,
      "z": -2,
      "name": "Rock_Stone"
    },
    {
      "x": -23,
      "y": 15,
      "z": -2,
      "name": "Rock_Stone"
    },
    {
      "x": -23,
      "y": 0,
      "z": -1,
      "name": "Rock_Stone"
    },
    {
      "x": -23,
      "y": 1,
      "z": -1,
      "name": "Rock_Stone"
    },
    {
      "x": -23,
      "y": 2,
      "z": -1,
      "name": "Rock_Stone"
    },
    {
      "x": -23,
      "y": 3,
      "z": -1,
      "name": "Rock_Stone"
    },
    {
      "x": -23,
      "y": 4,
      "z": -1,
      "name": "Rock_Stone"
    },
    {
      "x": -23,
      "y": 5,
      "z": -1,
      "name": "Rock_Stone"
    },
    {
      "x": -23,
      "y": 6,
      "z": -1,
      "name": "Rock_Stone"
    },
    {
      "x": -23,
      "y": 7,
      "z": -1,
      "name": "Rock_Stone"
    },
    {
      "x": -23,
      "y": 8,
      "z": -1,
      "name": "Rock_Stone"
    },
    {
      "x": -23,
      "y": 9,
      "z": -1,
      "name": "Rock_Stone"
    },
    {
      "x": -23,
      "y": 10,
      "z": -1,
      "name": "Rock_Stone"
    },
    {
      "x": -23,
      "y": 11,
      "z": -1,
      "name": "Rock_Stone"
    },
    {
      "x": -23,
      "y": 12,
      "z": -1,
      "name": "Rock_Stone"
    },
    {
      "x": -23,
      "y": 13,
      "z": -1,
      "name": "Rock_Stone"
    },
    {
      "x": -23,
      "y": 14,
      "z": -1,
      "name": "Rock_Stone"
    },
    {
      "x": -23,
      "y": 15,
      "z": -1,
      "name": "Rock_Stone"
    },
    {
      "x": -23,
      "y": 0,
      "z": 0,
      "name": "Rock_Stone"
    },
    {
      "x": -23,
      "y": 1,
      "z": 0,
      "name": "Rock_Stone"
    },
    {
      "x": -23,
      "y": 2,
      "z": 0,
      "name": "Rock_Stone"
    },
    {
      "x": -23,
      "y": 3,
      "z": 0,
      "name": "Rock_Stone"
    },
    {
      "x": -23,
      "y": 4,
      "z": 0,
      "name": "Rock_Stone"
    },
    {
      "x": -23,
      "y": 5,
      "z": 0,
      "name": "Rock_Stone"
    },
    {
      "x": -23,
      "y": 6,
      "z": 0,
      "name": "Rock_Stone"
    },
    {
      "x": -23,
      "y": 7,
      "z": 0,
      "name": "Rock_Stone"
    },
    {
      "x": -23,
      "y": 8,
      "z": 0,
      "name": "Rock_Stone"
    },
    {
      "x": -23,
      "y": 9,
      "z": 0,
      "name": "Rock_Stone"
    },
    {
      "x": -23,
      "y": 10,
      "z": 0,
      "name": "Rock_Stone"
    },
    {
      "x": -23,
      "y": 11,
      "z": 0,
      "name": "Rock_Stone"
    },
    {
      "x": -23,
      "y": 12,
      "z": 0,
      "name": "Rock_Stone"
    },
    {
      "x": -23,
      "y": 13,
      "z": 0,
      "name": "Rock_Stone"
    },
    {
      "x": -23,
      "y": 14,
      "z": 0,
      "name": "Rock_Stone"
    },
    {
      "x": -23,
      "y": 15,
      "z": 0,
      "name": "Rock_Stone"
    },
    {
      "x": -23,
      "y": 0,
      "z": 1,
      "name": "Rock_Stone"
    },
    {
      "x": -23,
      "y": 1,
      "z": 1,
      "name": "Rock_Stone"
    },
    {
      "x": -23,
      "y": 2,
      "z": 1,
      "name": "Rock_Stone"
    },
    {
      "x": -23,
      "y": 3,
      "z": 1,
      "name": "Rock_Stone"
    },
    {
      "x": -23,
      "y": 4,
      "z": 1,
      "name": "Rock_Stone"
    },
    {
      "x": -23,
      "y": 5,
      "z": 1,
      "name": "Rock_Stone"
    },
    {
      "x": -23,
      "y": 6,
      "z": 1,
      "name": "Rock_Stone"
    },
    {
      "x": -23,
      "y": 7,
      "z": 1,
      "name": "Empty"
    },
    {
      "x": -23,
      "y": 8,
      "z": 1,
      "name": "Rock_Stone"
    },
    {
      "x": -23,
      "y": 9,
      "z": 1,
      "name": "Rock_Stone"
    },
    {
      "x": -23,
      "y": 10,
      "z": 1,
      "name": "Rock_Stone"
    },
    {
      "x": -23,
      "y": 11,
      "z": 1,
      "name": "Rock_Stone"
    },
    {
      "x": -23,
      "y": 12,
      "z": 1,
      "name": "Rock_Stone"
    },
    {
      "x": -23,
      "y": 13,
      "z": 1,
      "name": "Rock_Stone"
    },
    {
      "x": -23,
      "y": 14,
      "z": 1,
      "name": "Rock_Stone"
    },
    {
      "x": -23,
      "y": 15,
      "z": 1,
      "name": "Rock_Stone"
    },
    {
      "x": -23,
      "y": 0,
      "z": 2,
      "name": "Rock_Stone"
    },
    {
      "x": -23,
      "y": 1,
      "z": 2,
      "name": "Rock_Stone"
    },
    {
      "x": -23,
      "y": 2,
      "z": 2,
      "name": "Rock_Stone"
    },
    {
      "x": -23,
      "y": 3,
      "z": 2,
      "name": "Rock_Stone"
    },
    {
      "x": -23,
      "y": 4,
      "z": 2,
      "name": "Rock_Stone"
    },
    {
      "x": -23,
      "y": 5,
      "z": 2,
      "name": "Rock_Stone"
    },
    {
      "x": -23,
      "y": 6,
      "z": 2,
      "name": "Rock_Stone"
    },
    {
      "x": -23,
      "y": 7,
      "z": 2,
      "name": "Empty"
    },
    {
      "x": -23,
      "y": 8,
      "z": 2,
      "name": "Rock_Stone"
    },
    {
      "x": -23,
      "y": 9,
      "z": 2,
      "name": "Rock_Stone"
    },
    {
      "x": -23,
      "y": 10,
      "z": 2,
      "name": "Rock_Stone"
    },
    {
      "x": -23,
      "y": 11,
      "z": 2,
      "name": "Rock_Stone"
    },
    {
      "x": -23,
      "y": 12,
      "z": 2,
      "name": "Rock_Stone"
    },
    {
      "x": -23,
      "y": 13,
      "z": 2,
      "name": "Rock_Stone"
    },
    {
      "x": -23,
      "y": 14,
      "z": 2,
      "name": "Rock_Stone"
    },
    {
      "x": -23,
      "y": 15,
      "z": 2,
      "name": "Rock_Stone"
    },
    {
      "x": -23,
      "y": 0,
      "z": 3,
      "name": "Rock_Stone"
    },
    {
      "x": -23,
      "y": 1,
      "z": 3,
      "name": "Rock_Stone"
    },
    {
      "x": -23,
      "y": 2,
      "z": 3,
      "name": "Rock_Stone"
    },
    {
      "x": -23,
      "y": 3,
      "z": 3,
      "name": "Rock_Stone"
    },
    {
      "x": -23,
      "y": 4,
      "z": 3,
      "name": "Rock_Stone"
    },
    {
      "x": -23,
      "y": 5,
      "z": 3,
      "name": "Rock_Stone"
    },
    {
      "x": -23,
      "y": 6,
      "z": 3,
      "name": "Rock_Stone_Cobble"
    },
    {
      "x": -23,
      "y": 7,
      "z": 3,
      "name": "Empty"
    },
    {
      "x": -23,
      "y": 8,
      "z": 3,
      "name": "Empty"
    },
    {
      "x": -23,
      "y": 9,
      "z": 3,
      "name": "Rock_Stone"
    },
    {
      "x": -23,
      "y": 10,
      "z": 3,
      "name": "Rock_Stone"
    },
    {
      "x": -23,
      "y": 11,
      "z": 3,
      "name": "Rock_Stone"
    },
    {
      "x": -23,
      "y": 12,
      "z": 3,
      "name": "Rock_Stone"
    },
    {
      "x": -23,
      "y": 13,
      "z": 3,
      "name": "Rock_Stone"
    },
    {
      "x": -23,
      "y": 14,
      "z": 3,
      "name": "Rock_Stone"
    },
    {
      "x": -23,
      "y": 15,
      "z": 3,
      "name": "Rock_Stone"
    },
    {
      "x": -23,
      "y": 0,
      "z": 4,
      "name": "Rock_Stone"
    },
    {
      "x": -23,
      "y": 1,
      "z": 4,
      "name": "Rock_Stone"
    },
    {
      "x": -23,
      "y": 2,
      "z": 4,
      "name": "Rock_Stone"
    },
    {
      "x": -23,
      "y": 3,
      "z": 4,
      "name": "Rock_Stone"
    },
    {
      "x": -23,
      "y": 4,
      "z": 4,
      "name": "Rock_Stone"
    },
    {
      "x": -23,
      "y": 5,
      "z": 4,
      "name": "Rock_Stone_Cobble"
    },
    {
      "x": -23,
      "y": 6,
      "z": 4,
      "name": "Rock_Stone_Cobble"
    },
    {
      "x": -23,
      "y": 7,
      "z": 4,
      "name": "Rock_Stone_Cobble"
    },
    {
      "x": -23,
      "y": 8,
      "z": 4,
      "name": "Empty"
    },
    {
      "x": -23,
      "y": 9,
      "z": 4,
      "name": "Rock_Stone"
    },
    {
      "x": -23,
      "y": 10,
      "z": 4,
      "name": "Rock_Stone"
    },
    {
      "x": -23,
      "y": 11,
      "z": 4,
      "name": "Rock_Stone"
    },
    {
      "x": -23,
      "y": 12,
      "z": 4,
      "name": "Rock_Stone"
    },
    {
      "x": -23,
      "y": 13,
      "z": 4,
      "name": "Rock_Stone"
    },
    {
      "x": -23,
      "y": 14,
      "z": 4,
      "name": "Rock_Stone"
    },
    {
      "x": -23,
      "y": 15,
      "z": 4,
      "name": "Rock_Stone"
    },
    {
      "x": -23,
      "y": 0,
      "z": 5,
      "name": "Rock_Stone"
    },
    {
      "x": -23,
      "y": 1,
      "z": 5,
      "name": "Rock_Stone"
    },
    {
      "x": -23,
      "y": 2,
      "z": 5,
      "name": "Rock_Stone"
    },
    {
      "x": -23,
      "y": 3,
      "z": 5,
      "name": "Rock_Stone"
    },
    {
      "x": -23,
      "y": 4,
      "z": 5,
      "name": "Rock_Stone"
    },
    {
      "x": -23,
      "y": 5,
      "z": 5,
      "name": "Rock_Stone_Cobble"
    },
    {
      "x": -23,
      "y": 6,
      "z": 5,
      "name": "Rock_Stone_Cobble"
    },
    {
      "x": -23,
      "y": 7,
      "z": 5,
      "name": "Rock_Stone_Cobble"
    },
    {
      "x": -23,
      "y": 8,
      "z": 5,
      "name": "Rock_Stone"
    },
    {
      "x": -23,
      "y": 9,
      "z": 5,
      "name": "Rock_Stone"
    },
    {
      "x": -23,
      "y": 10,
      "z": 5,
      "name": "Rock_Stone"
    },
    {
      "x": -23,
      "y": 11,
      "z": 5,
      "name": "Rock_Stone"
    },
    {
      "x": -23,
      "y": 12,
      "z": 5,
      "name": "Rock_Stone"
    },
    {
      "x": -23,
      "y": 13,
      "z": 5,
      "name": "Rock_Stone"
    },
    {
      "x": -23,
      "y": 14,
      "z": 5,
      "name": "Rock_Stone"
    },
    {
      "x": -23,
      "y": 15,
      "z": 5,
      "name": "Rock_Stone"
    },
    {
      "x": -23,
      "y": 0,
      "z": 6,
      "name": "Rock_Stone"
    },
    {
      "x": -23,
      "y": 1,
      "z": 6,
      "name": "Rock_Stone"
    },
    {
      "x": -23,
      "y": 2,
      "z": 6,
      "name": "Rock_Stone"
    },
    {
      "x": -23,
      "y": 3,
      "z": 6,
      "name": "Rock_Stone"
    },
    {
      "x": -23,
      "y": 4,
      "z": 6,
      "name": "Rock_Stone"
    },
    {
      "x": -23,
      "y": 5,
      "z": 6,
      "name": "Rock_Stone"
    },
    {
      "x": -23,
      "y": 6,
      "z": 6,
      "name": "Rock_Stone"
    },
    {
      "x": -23,
      "y": 7,
      "z": 6,
      "name": "Rock_Stone"
    },
    {
      "x": -23,
      "y": 8,
      "z": 6,
      "name": "Rock_Stone"
    },
    {
      "x": -23,
      "y": 9,
      "z": 6,
      "name": "Rock_Stone"
    },
    {
      "x": -23,
      "y": 10,
      "z": 6,
      "name": "Rock_Stone"
    },
    {
      "x": -23,
      "y": 11,
      "z": 6,
      "name": "Rock_Stone"
    },
    {
      "x": -23,
      "y": 12,
      "z": 6,
      "name": "Rock_Stone"
    },
    {
      "x": -23,
      "y": 13,
      "z": 6,
      "name": "Rock_Stone"
    },
    {
      "x": -23,
      "y": 14,
      "z": 6,
      "name": "Rock_Stone"
    },
    {
      "x": -23,
      "y": 15,
      "z": 6,
      "name": "Rock_Stone"
    },
    {
      "x": -23,
      "y": 0,
      "z": 7,
      "name": "Rock_Stone"
    },
    {
      "x": -23,
      "y": 1,
      "z": 7,
      "name": "Rock_Stone"
    },
    {
      "x": -23,
      "y": 2,
      "z": 7,
      "name": "Rock_Stone"
    },
    {
      "x": -23,
      "y": 3,
      "z": 7,
      "name": "Rock_Stone"
    },
    {
      "x": -23,
      "y": 4,
      "z": 7,
      "name": "Rock_Stone"
    },
    {
      "x": -23,
      "y": 5,
      "z": 7,
      "name": "Rock_Stone"
    },
    {
      "x": -23,
      "y": 6,
      "z": 7,
      "name": "Rock_Stone"
    },
    {
      "x": -23,
      "y": 7,
      "z": 7,
      "name": "Rock_Stone"
    },
    {
      "x": -23,
      "y": 8,
      "z": 7,
      "name": "Rock_Stone"
    },
    {
      "x": -23,
      "y": 9,
      "z": 7,
      "name": "Rock_Stone"
    },
    {
      "x": -23,
      "y": 10,
      "z": 7,
      "name": "Rock_Stone"
    },
    {
      "x": -23,
      "y": 11,
      "z": 7,
      "name": "Rock_Stone"
    },
    {
      "x": -23,
      "y": 12,
      "z": 7,
      "name": "Rock_Stone"
    },
    {
      "x": -23,
      "y": 13,
      "z": 7,
      "name": "Rock_Stone"
    },
    {
      "x": -23,
      "y": 14,
      "z": 7,
      "name": "Rock_Stone"
    },
    {
      "x": -23,
      "y": 15,
      "z": 7,
      "name": "Rock_Stone"
    },
    {
      "x": -23,
      "y": 0,
      "z": 8,
      "name": "Rock_Stone"
    },
    {
      "x": -23,
      "y": 1,
      "z": 8,
      "name": "Rock_Stone"
    },
    {
      "x": -23,
      "y": 2,
      "z": 8,
      "name": "Rock_Stone"
    },
    {
      "x": -23,
      "y": 3,
      "z": 8,
      "name": "Rock_Stone"
    },
    {
      "x": -23,
      "y": 4,
      "z": 8,
      "name": "Rock_Stone"
    },
    {
      "x": -23,
      "y": 5,
      "z": 8,
      "name": "Rock_Stone"
    },
    {
      "x": -23,
      "y": 6,
      "z": 8,
      "name": "Rock_Stone"
    },
    {
      "x": -23,
      "y": 7,
      "z": 8,
      "name": "Rock_Stone"
    },
    {
      "x": -23,
      "y": 8,
      "z": 8,
      "name": "Rock_Stone"
    },
    {
      "x": -23,
      "y": 9,
      "z": 8,
      "name": "Rock_Stone"
    },
    {
      "x": -23,
      "y": 10,
      "z": 8,
      "name": "Rock_Stone"
    },
    {
      "x": -23,
      "y": 11,
      "z": 8,
      "name": "Rock_Stone"
    },
    {
      "x": -23,
      "y": 12,
      "z": 8,
      "name": "Rock_Stone"
    },
    {
      "x": -23,
      "y": 13,
      "z": 8,
      "name": "Rock_Stone"
    },
    {
      "x": -23,
      "y": 14,
      "z": 8,
      "name": "Rock_Stone"
    },
    {
      "x": -23,
      "y": 15,
      "z": 8,
      "name": "Rock_Stone"
    },
    {
      "x": -23,
      "y": 0,
      "z": 9,
      "name": "Rock_Stone"
    },
    {
      "x": -23,
      "y": 1,
      "z": 9,
      "name": "Rock_Stone"
    },
    {
      "x": -23,
      "y": 2,
      "z": 9,
      "name": "Rock_Stone"
    },
    {
      "x": -23,
      "y": 3,
      "z": 9,
      "name": "Rock_Stone"
    },
    {
      "x": -23,
      "y": 4,
      "z": 9,
      "name": "Rock_Stone"
    },
    {
      "x": -23,
      "y": 5,
      "z": 9,
      "name": "Rock_Stone"
    },
    {
      "x": -23,
      "y": 6,
      "z": 9,
      "name": "Rock_Stone"
    },
    {
      "x": -23,
      "y": 7,
      "z": 9,
      "name": "Rock_Stone"
    },
    {
      "x": -23,
      "y": 8,
      "z": 9,
      "name": "Rock_Stone"
    },
    {
      "x": -23,
      "y": 9,
      "z": 9,
      "name": "Rock_Stone"
    },
    {
      "x": -23,
      "y": 10,
      "z": 9,
      "name": "Rock_Stone"
    },
    {
      "x": -23,
      "y": 11,
      "z": 9,
      "name": "Rock_Stone"
    },
    {
      "x": -23,
      "y": 12,
      "z": 9,
      "name": "Rock_Stone"
    },
    {
      "x": -23,
      "y": 13,
      "z": 9,
      "name": "Rock_Stone"
    },
    {
      "x": -23,
      "y": 14,
      "z": 9,
      "name": "Rock_Stone"
    },
    {
      "x": -23,
      "y": 15,
      "z": 9,
      "name": "Rock_Stone"
    },
    {
      "x": -23,
      "y": 0,
      "z": 10,
      "name": "Rock_Stone"
    },
    {
      "x": -23,
      "y": 1,
      "z": 10,
      "name": "Rock_Stone"
    },
    {
      "x": -23,
      "y": 2,
      "z": 10,
      "name": "Rock_Stone"
    },
    {
      "x": -23,
      "y": 3,
      "z": 10,
      "name": "Rock_Stone"
    },
    {
      "x": -23,
      "y": 4,
      "z": 10,
      "name": "Rock_Stone"
    },
    {
      "x": -23,
      "y": 5,
      "z": 10,
      "name": "Rock_Stone"
    },
    {
      "x": -23,
      "y": 6,
      "z": 10,
      "name": "Rock_Stone"
    },
    {
      "x": -23,
      "y": 7,
      "z": 10,
      "name": "Rock_Stone"
    },
    {
      "x": -23,
      "y": 8,
      "z": 10,
      "name": "Rock_Stone"
    },
    {
      "x": -23,
      "y": 9,
      "z": 10,
      "name": "Rock_Stone"
    },
    {
      "x": -23,
      "y": 10,
      "z": 10,
      "name": "Rock_Stone"
    },
    {
      "x": -23,
      "y": 11,
      "z": 10,
      "name": "Rock_Stone"
    },
    {
      "x": -23,
      "y": 12,
      "z": 10,
      "name": "Rock_Stone"
    },
    {
      "x": -23,
      "y": 13,
      "z": 10,
      "name": "Rock_Stone"
    },
    {
      "x": -23,
      "y": 14,
      "z": 10,
      "name": "Rock_Stone"
    },
    {
      "x": -23,
      "y": 15,
      "z": 10,
      "name": "Rock_Stone"
    },
    {
      "x": -23,
      "y": 0,
      "z": 11,
      "name": "Rock_Stone"
    },
    {
      "x": -23,
      "y": 1,
      "z": 11,
      "name": "Rock_Stone"
    },
    {
      "x": -23,
      "y": 2,
      "z": 11,
      "name": "Rock_Stone"
    },
    {
      "x": -23,
      "y": 3,
      "z": 11,
      "name": "Rock_Stone"
    },
    {
      "x": -23,
      "y": 4,
      "z": 11,
      "name": "Rock_Stone"
    },
    {
      "x": -23,
      "y": 5,
      "z": 11,
      "name": "Rock_Stone"
    },
    {
      "x": -23,
      "y": 6,
      "z": 11,
      "name": "Rock_Stone"
    },
    {
      "x": -23,
      "y": 7,
      "z": 11,
      "name": "Rock_Stone"
    },
    {
      "x": -23,
      "y": 8,
      "z": 11,
      "name": "Rock_Stone"
    },
    {
      "x": -23,
      "y": 9,
      "z": 11,
      "name": "Rock_Stone"
    },
    {
      "x": -23,
      "y": 10,
      "z": 11,
      "name": "Rock_Stone"
    },
    {
      "x": -23,
      "y": 11,
      "z": 11,
      "name": "Rock_Stone"
    },
    {
      "x": -23,
      "y": 12,
      "z": 11,
      "name": "Rock_Stone"
    },
    {
      "x": -23,
      "y": 13,
      "z": 11,
      "name": "Rock_Stone"
    },
    {
      "x": -23,
      "y": 14,
      "z": 11,
      "name": "Rock_Stone"
    },
    {
      "x": -23,
      "y": 15,
      "z": 11,
      "name": "Rock_Stone"
    },
    {
      "x": -23,
      "y": 0,
      "z": 12,
      "name": "Rock_Stone"
    },
    {
      "x": -23,
      "y": 1,
      "z": 12,
      "name": "Rock_Stone"
    },
    {
      "x": -23,
      "y": 2,
      "z": 12,
      "name": "Rock_Stone"
    },
    {
      "x": -23,
      "y": 3,
      "z": 12,
      "name": "Rock_Stone"
    },
    {
      "x": -23,
      "y": 4,
      "z": 12,
      "name": "Rock_Stone"
    },
    {
      "x": -23,
      "y": 5,
      "z": 12,
      "name": "Rock_Stone"
    },
    {
      "x": -23,
      "y": 6,
      "z": 12,
      "name": "Rock_Stone"
    },
    {
      "x": -23,
      "y": 7,
      "z": 12,
      "name": "Rock_Stone"
    },
    {
      "x": -23,
      "y": 8,
      "z": 12,
      "name": "Rock_Stone"
    },
    {
      "x": -23,
      "y": 9,
      "z": 12,
      "name": "Rock_Stone"
    },
    {
      "x": -23,
      "y": 10,
      "z": 12,
      "name": "Rock_Stone"
    },
    {
      "x": -23,
      "y": 11,
      "z": 12,
      "name": "Rock_Stone"
    },
    {
      "x": -23,
      "y": 12,
      "z": 12,
      "name": "Rock_Stone"
    },
    {
      "x": -23,
      "y": 13,
      "z": 12,
      "name": "Rock_Stone"
    },
    {
      "x": -23,
      "y": 14,
      "z": 12,
      "name": "Rock_Stone"
    },
    {
      "x": -23,
      "y": 15,
      "z": 12,
      "name": "Rock_Stone"
    },
    {
      "x": -23,
      "y": 0,
      "z": 13,
      "name": "Rock_Stone"
    },
    {
      "x": -23,
      "y": 1,
      "z": 13,
      "name": "Rock_Stone"
    },
    {
      "x": -23,
      "y": 2,
      "z": 13,
      "name": "Rock_Stone"
    },
    {
      "x": -23,
      "y": 3,
      "z": 13,
      "name": "Rock_Stone"
    },
    {
      "x": -23,
      "y": 4,
      "z": 13,
      "name": "Rock_Stone"
    },
    {
      "x": -23,
      "y": 5,
      "z": 13,
      "name": "Rock_Stone"
    },
    {
      "x": -23,
      "y": 6,
      "z": 13,
      "name": "Rock_Stone"
    },
    {
      "x": -23,
      "y": 7,
      "z": 13,
      "name": "Rock_Stone"
    },
    {
      "x": -23,
      "y": 8,
      "z": 13,
      "name": "Rock_Stone"
    },
    {
      "x": -23,
      "y": 9,
      "z": 13,
      "name": "Rock_Stone"
    },
    {
      "x": -23,
      "y": 10,
      "z": 13,
      "name": "Rock_Stone"
    },
    {
      "x": -23,
      "y": 11,
      "z": 13,
      "name": "Rock_Stone"
    },
    {
      "x": -23,
      "y": 12,
      "z": 13,
      "name": "Rock_Stone"
    },
    {
      "x": -23,
      "y": 13,
      "z": 13,
      "name": "Rock_Stone"
    },
    {
      "x": -23,
      "y": 14,
      "z": 13,
      "name": "Rock_Stone"
    },
    {
      "x": -23,
      "y": 15,
      "z": 13,
      "name": "Rock_Stone"
    },
    {
      "x": -23,
      "y": 0,
      "z": 14,
      "name": "Rock_Stone"
    },
    {
      "x": -23,
      "y": 1,
      "z": 14,
      "name": "Rock_Stone"
    },
    {
      "x": -23,
      "y": 2,
      "z": 14,
      "name": "Rock_Stone"
    },
    {
      "x": -23,
      "y": 3,
      "z": 14,
      "name": "Rock_Stone"
    },
    {
      "x": -23,
      "y": 4,
      "z": 14,
      "name": "Rock_Stone"
    },
    {
      "x": -23,
      "y": 5,
      "z": 14,
      "name": "Rock_Stone"
    },
    {
      "x": -23,
      "y": 6,
      "z": 14,
      "name": "Rock_Stone"
    },
    {
      "x": -23,
      "y": 7,
      "z": 14,
      "name": "Rock_Stone"
    },
    {
      "x": -23,
      "y": 8,
      "z": 14,
      "name": "Rock_Stone"
    },
    {
      "x": -23,
      "y": 9,
      "z": 14,
      "name": "Rock_Stone"
    },
    {
      "x": -23,
      "y": 10,
      "z": 14,
      "name": "Rock_Stone"
    },
    {
      "x": -23,
      "y": 11,
      "z": 14,
      "name": "Rock_Stone"
    },
    {
      "x": -23,
      "y": 12,
      "z": 14,
      "name": "Rock_Stone"
    },
    {
      "x": -23,
      "y": 13,
      "z": 14,
      "name": "Rock_Stone"
    },
    {
      "x": -23,
      "y": 14,
      "z": 14,
      "name": "Rock_Stone"
    },
    {
      "x": -23,
      "y": 15,
      "z": 14,
      "name": "Rock_Stone"
    },
    {
      "x": -23,
      "y": 0,
      "z": 15,
      "name": "Rock_Stone"
    },
    {
      "x": -23,
      "y": 1,
      "z": 15,
      "name": "Rock_Stone"
    },
    {
      "x": -23,
      "y": 2,
      "z": 15,
      "name": "Rock_Stone"
    },
    {
      "x": -23,
      "y": 3,
      "z": 15,
      "name": "Rock_Stone"
    },
    {
      "x": -23,
      "y": 4,
      "z": 15,
      "name": "Rock_Stone"
    },
    {
      "x": -23,
      "y": 5,
      "z": 15,
      "name": "Rock_Stone"
    },
    {
      "x": -23,
      "y": 6,
      "z": 15,
      "name": "Rock_Stone"
    },
    {
      "x": -23,
      "y": 7,
      "z": 15,
      "name": "Rock_Stone"
    },
    {
      "x": -23,
      "y": 8,
      "z": 15,
      "name": "Rock_Stone"
    },
    {
      "x": -23,
      "y": 9,
      "z": 15,
      "name": "Rock_Stone"
    },
    {
      "x": -23,
      "y": 10,
      "z": 15,
      "name": "Rock_Stone"
    },
    {
      "x": -23,
      "y": 11,
      "z": 15,
      "name": "Rock_Stone"
    },
    {
      "x": -23,
      "y": 12,
      "z": 15,
      "name": "Rock_Stone"
    },
    {
      "x": -23,
      "y": 13,
      "z": 15,
      "name": "Rock_Stone"
    },
    {
      "x": -23,
      "y": 14,
      "z": 15,
      "name": "Rock_Stone"
    },
    {
      "x": -23,
      "y": 15,
      "z": 15,
      "name": "Rock_Stone"
    },
    {
      "x": -23,
      "y": 0,
      "z": 16,
      "name": "Rock_Stone"
    },
    {
      "x": -23,
      "y": 1,
      "z": 16,
      "name": "Rock_Stone"
    },
    {
      "x": -23,
      "y": 2,
      "z": 16,
      "name": "Rock_Stone"
    },
    {
      "x": -23,
      "y": 3,
      "z": 16,
      "name": "Rock_Stone"
    },
    {
      "x": -23,
      "y": 4,
      "z": 16,
      "name": "Rock_Stone"
    },
    {
      "x": -23,
      "y": 5,
      "z": 16,
      "name": "Rock_Stone"
    },
    {
      "x": -23,
      "y": 6,
      "z": 16,
      "name": "Rock_Stone"
    },
    {
      "x": -23,
      "y": 7,
      "z": 16,
      "name": "Rock_Stone"
    },
    {
      "x": -23,
      "y": 8,
      "z": 16,
      "name": "Rock_Stone"
    },
    {
      "x": -23,
      "y": 9,
      "z": 16,
      "name": "Rock_Stone"
    },
    {
      "x": -23,
      "y": 10,
      "z": 16,
      "name": "Rock_Stone"
    },
    {
      "x": -23,
      "y": 11,
      "z": 16,
      "name": "Rock_Stone"
    },
    {
      "x": -23,
      "y": 12,
      "z": 16,
      "name": "Rock_Stone"
    },
    {
      "x": -23,
      "y": 13,
      "z": 16,
      "name": "Rock_Stone"
    },
    {
      "x": -23,
      "y": 14,
      "z": 16,
      "name": "Rock_Stone"
    },
    {
      "x": -23,
      "y": 15,
      "z": 16,
      "name": "Rock_Stone"
    },
    {
      "x": -22,
      "y": 0,
      "z": -8,
      "name": "Rock_Stone"
    },
    {
      "x": -22,
      "y": 1,
      "z": -8,
      "name": "Rock_Stone_Cobble"
    },
    {
      "x": -22,
      "y": 2,
      "z": -8,
      "name": "Rock_Stone"
    },
    {
      "x": -22,
      "y": 3,
      "z": -8,
      "name": "Rock_Stone"
    },
    {
      "x": -22,
      "y": 4,
      "z": -8,
      "name": "Rock_Stone"
    },
    {
      "x": -22,
      "y": 5,
      "z": -8,
      "name": "Rock_Stone"
    },
    {
      "x": -22,
      "y": 6,
      "z": -8,
      "name": "Rock_Stone"
    },
    {
      "x": -22,
      "y": 7,
      "z": -8,
      "name": "Rock_Stone"
    },
    {
      "x": -22,
      "y": 8,
      "z": -8,
      "name": "Rock_Stone"
    },
    {
      "x": -22,
      "y": 9,
      "z": -8,
      "name": "Rock_Stone"
    },
    {
      "x": -22,
      "y": 10,
      "z": -8,
      "name": "Rock_Stone"
    },
    {
      "x": -22,
      "y": 11,
      "z": -8,
      "name": "Rock_Stone"
    },
    {
      "x": -22,
      "y": 12,
      "z": -8,
      "name": "Rock_Stone"
    },
    {
      "x": -22,
      "y": 13,
      "z": -8,
      "name": "Rock_Stone"
    },
    {
      "x": -22,
      "y": 14,
      "z": -8,
      "name": "Rock_Stone"
    },
    {
      "x": -22,
      "y": 15,
      "z": -8,
      "name": "Rock_Stone"
    },
    {
      "x": -22,
      "y": 0,
      "z": -7,
      "name": "Rock_Stone"
    },
    {
      "x": -22,
      "y": 1,
      "z": -7,
      "name": "Rock_Stone"
    },
    {
      "x": -22,
      "y": 2,
      "z": -7,
      "name": "Rock_Stone"
    },
    {
      "x": -22,
      "y": 3,
      "z": -7,
      "name": "Rock_Stone"
    },
    {
      "x": -22,
      "y": 4,
      "z": -7,
      "name": "Rock_Stone"
    },
    {
      "x": -22,
      "y": 5,
      "z": -7,
      "name": "Rock_Stone"
    },
    {
      "x": -22,
      "y": 6,
      "z": -7,
      "name": "Rock_Stone"
    },
    {
      "x": -22,
      "y": 7,
      "z": -7,
      "name": "Rock_Stone"
    },
    {
      "x": -22,
      "y": 8,
      "z": -7,
      "name": "Rock_Stone"
    },
    {
      "x": -22,
      "y": 9,
      "z": -7,
      "name": "Rock_Stone"
    },
    {
      "x": -22,
      "y": 10,
      "z": -7,
      "name": "Rock_Stone"
    },
    {
      "x": -22,
      "y": 11,
      "z": -7,
      "name": "Rock_Stone"
    },
    {
      "x": -22,
      "y": 12,
      "z": -7,
      "name": "Rock_Stone"
    },
    {
      "x": -22,
      "y": 13,
      "z": -7,
      "name": "Rock_Stone"
    },
    {
      "x": -22,
      "y": 14,
      "z": -7,
      "name": "Rock_Stone"
    },
    {
      "x": -22,
      "y": 15,
      "z": -7,
      "name": "Rock_Stone"
    },
    {
      "x": -22,
      "y": 0,
      "z": -6,
      "name": "Rock_Stone"
    },
    {
      "x": -22,
      "y": 1,
      "z": -6,
      "name": "Rock_Stone"
    },
    {
      "x": -22,
      "y": 2,
      "z": -6,
      "name": "Rock_Stone"
    },
    {
      "x": -22,
      "y": 3,
      "z": -6,
      "name": "Rock_Stone"
    },
    {
      "x": -22,
      "y": 4,
      "z": -6,
      "name": "Rock_Stone"
    },
    {
      "x": -22,
      "y": 5,
      "z": -6,
      "name": "Rock_Stone"
    },
    {
      "x": -22,
      "y": 6,
      "z": -6,
      "name": "Rock_Stone"
    },
    {
      "x": -22,
      "y": 7,
      "z": -6,
      "name": "Rock_Stone"
    },
    {
      "x": -22,
      "y": 8,
      "z": -6,
      "name": "Rock_Stone"
    },
    {
      "x": -22,
      "y": 9,
      "z": -6,
      "name": "Rock_Stone"
    },
    {
      "x": -22,
      "y": 10,
      "z": -6,
      "name": "Rock_Stone"
    },
    {
      "x": -22,
      "y": 11,
      "z": -6,
      "name": "Rock_Stone"
    },
    {
      "x": -22,
      "y": 12,
      "z": -6,
      "name": "Rock_Stone"
    },
    {
      "x": -22,
      "y": 13,
      "z": -6,
      "name": "Rock_Stone"
    },
    {
      "x": -22,
      "y": 14,
      "z": -6,
      "name": "Rock_Stone"
    },
    {
      "x": -22,
      "y": 15,
      "z": -6,
      "name": "Rock_Stone"
    },
    {
      "x": -22,
      "y": 0,
      "z": -5,
      "name": "Rock_Stone"
    },
    {
      "x": -22,
      "y": 1,
      "z": -5,
      "name": "Rock_Stone"
    },
    {
      "x": -22,
      "y": 2,
      "z": -5,
      "name": "Rock_Stone"
    },
    {
      "x": -22,
      "y": 3,
      "z": -5,
      "name": "Rock_Stone"
    },
    {
      "x": -22,
      "y": 4,
      "z": -5,
      "name": "Rock_Stone"
    },
    {
      "x": -22,
      "y": 5,
      "z": -5,
      "name": "Rock_Stone"
    },
    {
      "x": -22,
      "y": 6,
      "z": -5,
      "name": "Rock_Stone"
    },
    {
      "x": -22,
      "y": 7,
      "z": -5,
      "name": "Rock_Stone"
    },
    {
      "x": -22,
      "y": 8,
      "z": -5,
      "name": "Rock_Stone"
    },
    {
      "x": -22,
      "y": 9,
      "z": -5,
      "name": "Rock_Stone"
    },
    {
      "x": -22,
      "y": 10,
      "z": -5,
      "name": "Rock_Stone"
    },
    {
      "x": -22,
      "y": 11,
      "z": -5,
      "name": "Rock_Stone"
    },
    {
      "x": -22,
      "y": 12,
      "z": -5,
      "name": "Rock_Stone"
    },
    {
      "x": -22,
      "y": 13,
      "z": -5,
      "name": "Rock_Stone"
    },
    {
      "x": -22,
      "y": 14,
      "z": -5,
      "name": "Rock_Stone"
    },
    {
      "x": -22,
      "y": 15,
      "z": -5,
      "name": "Rock_Stone"
    },
    {
      "x": -22,
      "y": 0,
      "z": -4,
      "name": "Rock_Stone"
    },
    {
      "x": -22,
      "y": 1,
      "z": -4,
      "name": "Rock_Stone"
    },
    {
      "x": -22,
      "y": 2,
      "z": -4,
      "name": "Rock_Stone"
    },
    {
      "x": -22,
      "y": 3,
      "z": -4,
      "name": "Rock_Stone"
    },
    {
      "x": -22,
      "y": 4,
      "z": -4,
      "name": "Rock_Stone"
    },
    {
      "x": -22,
      "y": 5,
      "z": -4,
      "name": "Rock_Stone"
    },
    {
      "x": -22,
      "y": 6,
      "z": -4,
      "name": "Rock_Stone"
    },
    {
      "x": -22,
      "y": 7,
      "z": -4,
      "name": "Rock_Stone"
    },
    {
      "x": -22,
      "y": 8,
      "z": -4,
      "name": "Rock_Stone"
    },
    {
      "x": -22,
      "y": 9,
      "z": -4,
      "name": "Rock_Stone"
    },
    {
      "x": -22,
      "y": 10,
      "z": -4,
      "name": "Rock_Stone"
    },
    {
      "x": -22,
      "y": 11,
      "z": -4,
      "name": "Rock_Stone"
    },
    {
      "x": -22,
      "y": 12,
      "z": -4,
      "name": "Rock_Stone"
    },
    {
      "x": -22,
      "y": 13,
      "z": -4,
      "name": "Rock_Stone"
    },
    {
      "x": -22,
      "y": 14,
      "z": -4,
      "name": "Rock_Stone"
    },
    {
      "x": -22,
      "y": 15,
      "z": -4,
      "name": "Rock_Stone"
    },
    {
      "x": -22,
      "y": 0,
      "z": -3,
      "name": "Rock_Stone"
    },
    {
      "x": -22,
      "y": 1,
      "z": -3,
      "name": "Rock_Stone"
    },
    {
      "x": -22,
      "y": 2,
      "z": -3,
      "name": "Rock_Stone"
    },
    {
      "x": -22,
      "y": 3,
      "z": -3,
      "name": "Rock_Stone_Cobble"
    },
    {
      "x": -22,
      "y": 4,
      "z": -3,
      "name": "Rock_Stone_Cobble"
    },
    {
      "x": -22,
      "y": 5,
      "z": -3,
      "name": "Rock_Stone"
    },
    {
      "x": -22,
      "y": 6,
      "z": -3,
      "name": "Rock_Stone"
    },
    {
      "x": -22,
      "y": 7,
      "z": -3,
      "name": "Rock_Stone"
    },
    {
      "x": -22,
      "y": 8,
      "z": -3,
      "name": "Rock_Stone"
    },
    {
      "x": -22,
      "y": 9,
      "z": -3,
      "name": "Rock_Stone"
    },
    {
      "x": -22,
      "y": 10,
      "z": -3,
      "name": "Rock_Stone"
    },
    {
      "x": -22,
      "y": 11,
      "z": -3,
      "name": "Rock_Stone"
    },
    {
      "x": -22,
      "y": 12,
      "z": -3,
      "name": "Rock_Stone"
    },
    {
      "x": -22,
      "y": 13,
      "z": -3,
      "name": "Rock_Stone"
    },
    {
      "x": -22,
      "y": 14,
      "z": -3,
      "name": "Rock_Stone"
    },
    {
      "x": -22,
      "y": 15,
      "z": -3,
      "name": "Rock_Stone"
    },
    {
      "x": -22,
      "y": 0,
      "z": -2,
      "name": "Rock_Stone"
    },
    {
      "x": -22,
      "y": 1,
      "z": -2,
      "name": "Rock_Stone"
    },
    {
      "x": -22,
      "y": 2,
      "z": -2,
      "name": "Rock_Stone"
    },
    {
      "x": -22,
      "y": 3,
      "z": -2,
      "name": "Rock_Stone_Cobble"
    },
    {
      "x": -22,
      "y": 4,
      "z": -2,
      "name": "Rock_Stone_Cobble"
    },
    {
      "x": -22,
      "y": 5,
      "z": -2,
      "name": "Rock_Stone"
    },
    {
      "x": -22,
      "y": 6,
      "z": -2,
      "name": "Rock_Stone"
    },
    {
      "x": -22,
      "y": 7,
      "z": -2,
      "name": "Rock_Stone"
    },
    {
      "x": -22,
      "y": 8,
      "z": -2,
      "name": "Rock_Stone"
    },
    {
      "x": -22,
      "y": 9,
      "z": -2,
      "name": "Rock_Stone"
    },
    {
      "x": -22,
      "y": 10,
      "z": -2,
      "name": "Rock_Stone"
    },
    {
      "x": -22,
      "y": 11,
      "z": -2,
      "name": "Rock_Stone"
    },
    {
      "x": -22,
      "y": 12,
      "z": -2,
      "name": "Rock_Stone"
    },
    {
      "x": -22,
      "y": 13,
      "z": -2,
      "name": "Rock_Stone"
    },
    {
      "x": -22,
      "y": 14,
      "z": -2,
      "name": "Rock_Stone"
    },
    {
      "x": -22,
      "y": 15,
      "z": -2,
      "name": "Rock_Stone"
    },
    {
      "x": -22,
      "y": 0,
      "z": -1,
      "name": "Rock_Stone"
    },
    {
      "x": -22,
      "y": 1,
      "z": -1,
      "name": "Rock_Stone"
    },
    {
      "x": -22,
      "y": 2,
      "z": -1,
      "name": "Rock_Stone"
    },
    {
      "x": -22,
      "y": 3,
      "z": -1,
      "name": "Rock_Stone"
    },
    {
      "x": -22,
      "y": 4,
      "z": -1,
      "name": "Rock_Stone"
    },
    {
      "x": -22,
      "y": 5,
      "z": -1,
      "name": "Rock_Stone"
    },
    {
      "x": -22,
      "y": 6,
      "z": -1,
      "name": "Rock_Stone"
    },
    {
      "x": -22,
      "y": 7,
      "z": -1,
      "name": "Rock_Stone"
    },
    {
      "x": -22,
      "y": 8,
      "z": -1,
      "name": "Rock_Stone"
    },
    {
      "x": -22,
      "y": 9,
      "z": -1,
      "name": "Rock_Stone"
    },
    {
      "x": -22,
      "y": 10,
      "z": -1,
      "name": "Rock_Stone"
    },
    {
      "x": -22,
      "y": 11,
      "z": -1,
      "name": "Rock_Stone"
    },
    {
      "x": -22,
      "y": 12,
      "z": -1,
      "name": "Rock_Stone"
    },
    {
      "x": -22,
      "y": 13,
      "z": -1,
      "name": "Rock_Stone"
    },
    {
      "x": -22,
      "y": 14,
      "z": -1,
      "name": "Rock_Stone"
    },
    {
      "x": -22,
      "y": 15,
      "z": -1,
      "name": "Rock_Stone"
    },
    {
      "x": -22,
      "y": 0,
      "z": 0,
      "name": "Rock_Stone"
    },
    {
      "x": -22,
      "y": 1,
      "z": 0,
      "name": "Rock_Stone"
    },
    {
      "x": -22,
      "y": 2,
      "z": 0,
      "name": "Rock_Stone"
    },
    {
      "x": -22,
      "y": 3,
      "z": 0,
      "name": "Rock_Stone"
    },
    {
      "x": -22,
      "y": 4,
      "z": 0,
      "name": "Rock_Stone"
    },
    {
      "x": -22,
      "y": 5,
      "z": 0,
      "name": "Rock_Stone"
    },
    {
      "x": -22,
      "y": 6,
      "z": 0,
      "name": "Rock_Stone"
    },
    {
      "x": -22,
      "y": 7,
      "z": 0,
      "name": "Rock_Stone"
    },
    {
      "x": -22,
      "y": 8,
      "z": 0,
      "name": "Rock_Stone"
    },
    {
      "x": -22,
      "y": 9,
      "z": 0,
      "name": "Rock_Stone"
    },
    {
      "x": -22,
      "y": 10,
      "z": 0,
      "name": "Rock_Stone"
    },
    {
      "x": -22,
      "y": 11,
      "z": 0,
      "name": "Rock_Stone"
    },
    {
      "x": -22,
      "y": 12,
      "z": 0,
      "name": "Rock_Stone"
    },
    {
      "x": -22,
      "y": 13,
      "z": 0,
      "name": "Rock_Stone"
    },
    {
      "x": -22,
      "y": 14,
      "z": 0,
      "name": "Rock_Stone"
    },
    {
      "x": -22,
      "y": 15,
      "z": 0,
      "name": "Rock_Stone"
    },
    {
      "x": -22,
      "y": 0,
      "z": 1,
      "name": "Rock_Stone"
    },
    {
      "x": -22,
      "y": 1,
      "z": 1,
      "name": "Rock_Stone"
    },
    {
      "x": -22,
      "y": 2,
      "z": 1,
      "name": "Rock_Stone"
    },
    {
      "x": -22,
      "y": 3,
      "z": 1,
      "name": "Rock_Stone"
    },
    {
      "x": -22,
      "y": 4,
      "z": 1,
      "name": "Rock_Stone"
    },
    {
      "x": -22,
      "y": 5,
      "z": 1,
      "name": "Rock_Stone_Cobble"
    },
    {
      "x": -22,
      "y": 6,
      "z": 1,
      "name": "Rock_Stone_Cobble"
    },
    {
      "x": -22,
      "y": 7,
      "z": 1,
      "name": "Empty"
    },
    {
      "x": -22,
      "y": 8,
      "z": 1,
      "name": "Empty"
    },
    {
      "x": -22,
      "y": 9,
      "z": 1,
      "name": "Rock_Stone"
    },
    {
      "x": -22,
      "y": 10,
      "z": 1,
      "name": "Wood_Beech_Trunk",
      "rotation": 4
    },
    {
      "x": -22,
      "y": 11,
      "z": 1,
      "name": "Rock_Stone"
    },
    {
      "x": -22,
      "y": 12,
      "z": 1,
      "name": "Rock_Stone"
    },
    {
      "x": -22,
      "y": 13,
      "z": 1,
      "name": "Rock_Stone"
    },
    {
      "x": -22,
      "y": 14,
      "z": 1,
      "name": "Rock_Stone"
    },
    {
      "x": -22,
      "y": 15,
      "z": 1,
      "name": "Rock_Stone"
    },
    {
      "x": -22,
      "y": 0,
      "z": 2,
      "name": "Rock_Stone"
    },
    {
      "x": -22,
      "y": 1,
      "z": 2,
      "name": "Rock_Stone"
    },
    {
      "x": -22,
      "y": 2,
      "z": 2,
      "name": "Rock_Stone"
    },
    {
      "x": -22,
      "y": 3,
      "z": 2,
      "name": "Rock_Stone"
    },
    {
      "x": -22,
      "y": 4,
      "z": 2,
      "name": "Rock_Stone"
    },
    {
      "x": -22,
      "y": 5,
      "z": 2,
      "name": "Rock_Stone_Cobble"
    },
    {
      "x": -22,
      "y": 6,
      "z": 2,
      "name": "Rock_Stone_Cobble"
    },
    {
      "x": -22,
      "y": 7,
      "z": 2,
      "name": "Empty"
    },
    {
      "x": -22,
      "y": 8,
      "z": 2,
      "name": "Empty"
    },
    {
      "x": -22,
      "y": 9,
      "z": 2,
      "name": "Empty"
    },
    {
      "x": -22,
      "y": 10,
      "z": 2,
      "name": "Wood_Beech_Trunk",
      "support": 1,
      "rotation": 4
    },
    {
      "x": -22,
      "y": 11,
      "z": 2,
      "name": "Rock_Stone"
    },
    {
      "x": -22,
      "y": 12,
      "z": 2,
      "name": "Rock_Stone"
    },
    {
      "x": -22,
      "y": 13,
      "z": 2,
      "name": "Rock_Stone"
    },
    {
      "x": -22,
      "y": 14,
      "z": 2,
      "name": "Rock_Stone"
    },
    {
      "x": -22,
      "y": 15,
      "z": 2,
      "name": "Rock_Stone"
    },
    {
      "x": -22,
      "y": 0,
      "z": 3,
      "name": "Rock_Stone"
    },
    {
      "x": -22,
      "y": 1,
      "z": 3,
      "name": "Rock_Stone"
    },
    {
      "x": -22,
      "y": 2,
      "z": 3,
      "name": "Rock_Stone"
    },
    {
      "x": -22,
      "y": 3,
      "z": 3,
      "name": "Rock_Stone"
    },
    {
      "x": -22,
      "y": 4,
      "z": 3,
      "name": "Rock_Stone"
    },
    {
      "x": -22,
      "y": 5,
      "z": 3,
      "name": "Rock_Stone_Cobble"
    },
    {
      "x": -22,
      "y": 6,
      "z": 3,
      "name": "Rock_Stone_Cobble_Half",
      "rotation": 4
    },
    {
      "x": -22,
      "y": 7,
      "z": 3,
      "name": "Empty"
    },
    {
      "x": -22,
      "y": 8,
      "z": 3,
      "name": "Empty"
    },
    {
      "x": -22,
      "y": 9,
      "z": 3,
      "name": "Empty"
    },
    {
      "x": -22,
      "y": 10,
      "z": 3,
      "name": "Wood_Beech_Trunk",
      "support": 2,
      "rotation": 4
    },
    {
      "x": -22,
      "y": 11,
      "z": 3,
      "name": "Rock_Stone"
    },
    {
      "x": -22,
      "y": 12,
      "z": 3,
      "name": "Rock_Stone"
    },
    {
      "x": -22,
      "y": 13,
      "z": 3,
      "name": "Rock_Stone"
    },
    {
      "x": -22,
      "y": 14,
      "z": 3,
      "name": "Rock_Stone"
    },
    {
      "x": -22,
      "y": 15,
      "z": 3,
      "name": "Rock_Stone"
    },
    {
      "x": -22,
      "y": 0,
      "z": 4,
      "name": "Rock_Stone"
    },
    {
      "x": -22,
      "y": 1,
      "z": 4,
      "name": "Rock_Stone"
    },
    {
      "x": -22,
      "y": 2,
      "z": 4,
      "name": "Rock_Stone"
    },
    {
      "x": -22,
      "y": 3,
      "z": 4,
      "name": "Rock_Stone"
    },
    {
      "x": -22,
      "y": 4,
      "z": 4,
      "name": "Rock_Stone"
    },
    {
      "x": -22,
      "y": 5,
      "z": 4,
      "name": "Rubble_Stone_Medium"
    },
    {
      "x": -22,
      "y": 6,
      "z": 4,
      "name": "Empty"
    },
    {
      "x": -22,
      "y": 7,
      "z": 4,
      "name": "Empty"
    },
    {
      "x": -22,
      "y": 8,
      "z": 4,
      "name": "Empty"
    },
    {
      "x": -22,
      "y": 9,
      "z": 4,
      "name": "Wood_Softwood_Planks_Half",
      "rotation": 8
    },
    {
      "x": -22,
      "y": 10,
      "z": 4,
      "name": "Wood_Beech_Trunk",
      "support": 1,
      "rotation": 4
    },
    {
      "x": -22,
      "y": 11,
      "z": 4,
      "name": "Rock_Stone"
    },
    {
      "x": -22,
      "y": 12,
      "z": 4,
      "name": "Rock_Stone"
    },
    {
      "x": -22,
      "y": 13,
      "z": 4,
      "name": "Rock_Stone"
    },
    {
      "x": -22,
      "y": 14,
      "z": 4,
      "name": "Rock_Stone"
    },
    {
      "x": -22,
      "y": 15,
      "z": 4,
      "name": "Rock_Stone"
    },
    {
      "x": -22,
      "y": 0,
      "z": 5,
      "name": "Rock_Stone"
    },
    {
      "x": -22,
      "y": 1,
      "z": 5,
      "name": "Rock_Stone"
    },
    {
      "x": -22,
      "y": 2,
      "z": 5,
      "name": "Rock_Stone"
    },
    {
      "x": -22,
      "y": 3,
      "z": 5,
      "name": "Rock_Stone"
    },
    {
      "x": -22,
      "y": 4,
      "z": 5,
      "name": "Rock_Stone"
    },
    {
      "x": -22,
      "y": 5,
      "z": 5,
      "name": "Furniture_Tavern_Barrel"
    },
    {
      "x": -22,
      "y": 6,
      "z": 5,
      "name": "Empty"
    },
    {
      "x": -22,
      "y": 7,
      "z": 5,
      "name": "Empty"
    },
    {
      "x": -22,
      "y": 8,
      "z": 5,
      "name": "Empty"
    },
    {
      "x": -22,
      "y": 9,
      "z": 5,
      "name": "*Wood_Softwood_Planks_Half_State_Definitions_Block",
      "rotation": 8
    },
    {
      "x": -22,
      "y": 10,
      "z": 5,
      "name": "Wood_Beech_Trunk",
      "rotation": 4
    },
    {
      "x": -22,
      "y": 11,
      "z": 5,
      "name": "Rock_Stone"
    },
    {
      "x": -22,
      "y": 12,
      "z": 5,
      "name": "Rock_Stone"
    },
    {
      "x": -22,
      "y": 13,
      "z": 5,
      "name": "Rock_Stone"
    },
    {
      "x": -22,
      "y": 14,
      "z": 5,
      "name": "Rock_Stone"
    },
    {
      "x": -22,
      "y": 15,
      "z": 5,
      "name": "Rock_Stone"
    },
    {
      "x": -22,
      "y": 0,
      "z": 6,
      "name": "Rock_Stone"
    },
    {
      "x": -22,
      "y": 1,
      "z": 6,
      "name": "Rock_Stone"
    },
    {
      "x": -22,
      "y": 2,
      "z": 6,
      "name": "Rock_Stone"
    },
    {
      "x": -22,
      "y": 3,
      "z": 6,
      "name": "Rock_Stone"
    },
    {
      "x": -22,
      "y": 4,
      "z": 6,
      "name": "Rock_Stone"
    },
    {
      "x": -22,
      "y": 5,
      "z": 6,
      "name": "Wood_Beech_Trunk"
    },
    {
      "x": -22,
      "y": 6,
      "z": 6,
      "name": "Wood_Beech_Trunk"
    },
    {
      "x": -22,
      "y": 7,
      "z": 6,
      "name": "Wood_Beech_Trunk"
    },
    {
      "x": -22,
      "y": 8,
      "z": 6,
      "name": "Wood_Beech_Trunk"
    },
    {
      "x": -22,
      "y": 9,
      "z": 6,
      "name": "Wood_Beech_Trunk"
    },
    {
      "x": -22,
      "y": 10,
      "z": 6,
      "name": "Wood_Beech_Trunk",
      "rotation": 4
    },
    {
      "x": -22,
      "y": 11,
      "z": 6,
      "name": "Rock_Stone"
    },
    {
      "x": -22,
      "y": 12,
      "z": 6,
      "name": "Rock_Stone"
    },
    {
      "x": -22,
      "y": 13,
      "z": 6,
      "name": "Rock_Stone"
    },
    {
      "x": -22,
      "y": 14,
      "z": 6,
      "name": "Rock_Stone"
    },
    {
      "x": -22,
      "y": 15,
      "z": 6,
      "name": "Rock_Stone"
    },
    {
      "x": -22,
      "y": 0,
      "z": 7,
      "name": "Rock_Stone"
    },
    {
      "x": -22,
      "y": 1,
      "z": 7,
      "name": "Rock_Stone"
    },
    {
      "x": -22,
      "y": 2,
      "z": 7,
      "name": "Rock_Stone"
    },
    {
      "x": -22,
      "y": 3,
      "z": 7,
      "name": "Rock_Stone"
    },
    {
      "x": -22,
      "y": 4,
      "z": 7,
      "name": "Rock_Stone"
    },
    {
      "x": -22,
      "y": 5,
      "z": 7,
      "name": "Rock_Stone_Cobble"
    },
    {
      "x": -22,
      "y": 6,
      "z": 7,
      "name": "Rock_Stone_Cobble"
    },
    {
      "x": -22,
      "y": 7,
      "z": 7,
      "name": "Empty"
    },
    {
      "x": -22,
      "y": 8,
      "z": 7,
      "name": "Empty"
    },
    {
      "x": -22,
      "y": 9,
      "z": 7,
      "name": "*Wood_Softwood_Planks_Half_State_Definitions_Block",
      "rotation": 8
    },
    {
      "x": -22,
      "y": 10,
      "z": 7,
      "name": "Wood_Beech_Trunk",
      "rotation": 4
    },
    {
      "x": -22,
      "y": 11,
      "z": 7,
      "name": "Rock_Stone"
    },
    {
      "x": -22,
      "y": 12,
      "z": 7,
      "name": "Rock_Stone"
    },
    {
      "x": -22,
      "y": 13,
      "z": 7,
      "name": "Rock_Stone"
    },
    {
      "x": -22,
      "y": 14,
      "z": 7,
      "name": "Rock_Stone"
    },
    {
      "x": -22,
      "y": 15,
      "z": 7,
      "name": "Rock_Stone"
    },
    {
      "x": -22,
      "y": 0,
      "z": 8,
      "name": "Rock_Stone"
    },
    {
      "x": -22,
      "y": 1,
      "z": 8,
      "name": "Rock_Stone"
    },
    {
      "x": -22,
      "y": 2,
      "z": 8,
      "name": "Rock_Stone"
    },
    {
      "x": -22,
      "y": 3,
      "z": 8,
      "name": "Rock_Stone"
    },
    {
      "x": -22,
      "y": 4,
      "z": 8,
      "name": "Rock_Stone"
    },
    {
      "x": -22,
      "y": 5,
      "z": 8,
      "name": "Rock_Stone_Cobble"
    },
    {
      "x": -22,
      "y": 6,
      "z": 8,
      "name": "Rock_Stone_Cobble_Half"
    },
    {
      "x": -22,
      "y": 7,
      "z": 8,
      "name": "Empty"
    },
    {
      "x": -22,
      "y": 8,
      "z": 8,
      "name": "Empty"
    },
    {
      "x": -22,
      "y": 9,
      "z": 8,
      "name": "Wood_Softwood_Planks_Half",
      "rotation": 8
    },
    {
      "x": -22,
      "y": 10,
      "z": 8,
      "name": "Wood_Beech_Trunk",
      "rotation": 4
    },
    {
      "x": -22,
      "y": 11,
      "z": 8,
      "name": "Rock_Stone"
    },
    {
      "x": -22,
      "y": 12,
      "z": 8,
      "name": "Rock_Stone"
    },
    {
      "x": -22,
      "y": 13,
      "z": 8,
      "name": "Rock_Stone"
    },
    {
      "x": -22,
      "y": 14,
      "z": 8,
      "name": "Rock_Stone"
    },
    {
      "x": -22,
      "y": 15,
      "z": 8,
      "name": "Rock_Stone"
    },
    {
      "x": -22,
      "y": 0,
      "z": 9,
      "name": "Rock_Stone"
    },
    {
      "x": -22,
      "y": 1,
      "z": 9,
      "name": "Rock_Stone"
    },
    {
      "x": -22,
      "y": 2,
      "z": 9,
      "name": "Rock_Stone"
    },
    {
      "x": -22,
      "y": 3,
      "z": 9,
      "name": "Rock_Stone"
    },
    {
      "x": -22,
      "y": 4,
      "z": 9,
      "name": "Rock_Stone"
    },
    {
      "x": -22,
      "y": 5,
      "z": 9,
      "name": "Rock_Stone"
    },
    {
      "x": -22,
      "y": 6,
      "z": 9,
      "name": "Empty"
    },
    {
      "x": -22,
      "y": 7,
      "z": 9,
      "name": "Empty"
    },
    {
      "x": -22,
      "y": 8,
      "z": 9,
      "name": "Empty"
    },
    {
      "x": -22,
      "y": 9,
      "z": 9,
      "name": "Rock_Stone"
    },
    {
      "x": -22,
      "y": 10,
      "z": 9,
      "name": "Rock_Stone"
    },
    {
      "x": -22,
      "y": 11,
      "z": 9,
      "name": "Rock_Stone"
    },
    {
      "x": -22,
      "y": 12,
      "z": 9,
      "name": "Rock_Stone"
    },
    {
      "x": -22,
      "y": 13,
      "z": 9,
      "name": "Rock_Stone"
    },
    {
      "x": -22,
      "y": 14,
      "z": 9,
      "name": "Rock_Stone"
    },
    {
      "x": -22,
      "y": 15,
      "z": 9,
      "name": "Rock_Stone"
    },
    {
      "x": -22,
      "y": 0,
      "z": 10,
      "name": "Rock_Stone"
    },
    {
      "x": -22,
      "y": 1,
      "z": 10,
      "name": "Rock_Stone"
    },
    {
      "x": -22,
      "y": 2,
      "z": 10,
      "name": "Rock_Stone"
    },
    {
      "x": -22,
      "y": 3,
      "z": 10,
      "name": "Rock_Stone"
    },
    {
      "x": -22,
      "y": 4,
      "z": 10,
      "name": "Rock_Stone"
    },
    {
      "x": -22,
      "y": 5,
      "z": 10,
      "name": "Rock_Stone"
    },
    {
      "x": -22,
      "y": 6,
      "z": 10,
      "name": "Rock_Stone"
    },
    {
      "x": -22,
      "y": 7,
      "z": 10,
      "name": "Empty"
    },
    {
      "x": -22,
      "y": 8,
      "z": 10,
      "name": "Rock_Stone"
    },
    {
      "x": -22,
      "y": 9,
      "z": 10,
      "name": "Rock_Stone"
    },
    {
      "x": -22,
      "y": 10,
      "z": 10,
      "name": "Rock_Stone"
    },
    {
      "x": -22,
      "y": 11,
      "z": 10,
      "name": "Rock_Stone"
    },
    {
      "x": -22,
      "y": 12,
      "z": 10,
      "name": "Rock_Stone"
    },
    {
      "x": -22,
      "y": 13,
      "z": 10,
      "name": "Rock_Stone"
    },
    {
      "x": -22,
      "y": 14,
      "z": 10,
      "name": "Rock_Stone"
    },
    {
      "x": -22,
      "y": 15,
      "z": 10,
      "name": "Rock_Stone"
    },
    {
      "x": -22,
      "y": 0,
      "z": 11,
      "name": "Rock_Stone"
    },
    {
      "x": -22,
      "y": 1,
      "z": 11,
      "name": "Rock_Stone"
    },
    {
      "x": -22,
      "y": 2,
      "z": 11,
      "name": "Rock_Stone"
    },
    {
      "x": -22,
      "y": 3,
      "z": 11,
      "name": "Rock_Stone"
    },
    {
      "x": -22,
      "y": 4,
      "z": 11,
      "name": "Rock_Stone"
    },
    {
      "x": -22,
      "y": 5,
      "z": 11,
      "name": "Rock_Stone"
    },
    {
      "x": -22,
      "y": 6,
      "z": 11,
      "name": "Rock_Stone"
    },
    {
      "x": -22,
      "y": 7,
      "z": 11,
      "name": "Rock_Stone"
    },
    {
      "x": -22,
      "y": 8,
      "z": 11,
      "name": "Rock_Stone"
    },
    {
      "x": -22,
      "y": 9,
      "z": 11,
      "name": "Rock_Stone"
    },
    {
      "x": -22,
      "y": 10,
      "z": 11,
      "name": "Rock_Stone"
    },
    {
      "x": -22,
      "y": 11,
      "z": 11,
      "name": "Rock_Stone"
    },
    {
      "x": -22,
      "y": 12,
      "z": 11,
      "name": "Rock_Stone"
    },
    {
      "x": -22,
      "y": 13,
      "z": 11,
      "name": "Rock_Stone"
    },
    {
      "x": -22,
      "y": 14,
      "z": 11,
      "name": "Rock_Stone"
    },
    {
      "x": -22,
      "y": 15,
      "z": 11,
      "name": "Rock_Stone"
    },
    {
      "x": -22,
      "y": 0,
      "z": 12,
      "name": "Rock_Stone"
    },
    {
      "x": -22,
      "y": 1,
      "z": 12,
      "name": "Rock_Stone"
    },
    {
      "x": -22,
      "y": 2,
      "z": 12,
      "name": "Rock_Stone"
    },
    {
      "x": -22,
      "y": 3,
      "z": 12,
      "name": "Rock_Stone"
    },
    {
      "x": -22,
      "y": 4,
      "z": 12,
      "name": "Rock_Stone"
    },
    {
      "x": -22,
      "y": 5,
      "z": 12,
      "name": "Rock_Stone"
    },
    {
      "x": -22,
      "y": 6,
      "z": 12,
      "name": "Rock_Stone"
    },
    {
      "x": -22,
      "y": 7,
      "z": 12,
      "name": "Rock_Stone"
    },
    {
      "x": -22,
      "y": 8,
      "z": 12,
      "name": "Rock_Stone"
    },
    {
      "x": -22,
      "y": 9,
      "z": 12,
      "name": "Rock_Stone"
    },
    {
      "x": -22,
      "y": 10,
      "z": 12,
      "name": "Rock_Stone"
    },
    {
      "x": -22,
      "y": 11,
      "z": 12,
      "name": "Rock_Stone"
    },
    {
      "x": -22,
      "y": 12,
      "z": 12,
      "name": "Rock_Stone"
    },
    {
      "x": -22,
      "y": 13,
      "z": 12,
      "name": "Rock_Stone"
    },
    {
      "x": -22,
      "y": 14,
      "z": 12,
      "name": "Rock_Stone"
    },
    {
      "x": -22,
      "y": 15,
      "z": 12,
      "name": "Rock_Stone"
    },
    {
      "x": -22,
      "y": 0,
      "z": 13,
      "name": "Rock_Stone"
    },
    {
      "x": -22,
      "y": 1,
      "z": 13,
      "name": "Rock_Stone"
    },
    {
      "x": -22,
      "y": 2,
      "z": 13,
      "name": "Rock_Stone"
    },
    {
      "x": -22,
      "y": 3,
      "z": 13,
      "name": "Rock_Stone"
    },
    {
      "x": -22,
      "y": 4,
      "z": 13,
      "name": "Rock_Stone"
    },
    {
      "x": -22,
      "y": 5,
      "z": 13,
      "name": "Rock_Stone"
    },
    {
      "x": -22,
      "y": 6,
      "z": 13,
      "name": "Rock_Stone"
    },
    {
      "x": -22,
      "y": 7,
      "z": 13,
      "name": "Rock_Stone"
    },
    {
      "x": -22,
      "y": 8,
      "z": 13,
      "name": "Rock_Stone"
    },
    {
      "x": -22,
      "y": 9,
      "z": 13,
      "name": "Rock_Stone"
    },
    {
      "x": -22,
      "y": 10,
      "z": 13,
      "name": "Rock_Stone"
    },
    {
      "x": -22,
      "y": 11,
      "z": 13,
      "name": "Rock_Stone"
    },
    {
      "x": -22,
      "y": 12,
      "z": 13,
      "name": "Rock_Stone"
    },
    {
      "x": -22,
      "y": 13,
      "z": 13,
      "name": "Rock_Stone"
    },
    {
      "x": -22,
      "y": 14,
      "z": 13,
      "name": "Rock_Stone"
    },
    {
      "x": -22,
      "y": 15,
      "z": 13,
      "name": "Rock_Stone"
    },
    {
      "x": -22,
      "y": 0,
      "z": 14,
      "name": "Rock_Stone"
    },
    {
      "x": -22,
      "y": 1,
      "z": 14,
      "name": "Rock_Stone"
    },
    {
      "x": -22,
      "y": 2,
      "z": 14,
      "name": "Rock_Stone"
    },
    {
      "x": -22,
      "y": 3,
      "z": 14,
      "name": "Rock_Stone"
    },
    {
      "x": -22,
      "y": 4,
      "z": 14,
      "name": "Rock_Stone"
    },
    {
      "x": -22,
      "y": 5,
      "z": 14,
      "name": "Rock_Stone"
    },
    {
      "x": -22,
      "y": 6,
      "z": 14,
      "name": "Rock_Stone"
    },
    {
      "x": -22,
      "y": 7,
      "z": 14,
      "name": "Rock_Stone"
    },
    {
      "x": -22,
      "y": 8,
      "z": 14,
      "name": "Rock_Stone"
    },
    {
      "x": -22,
      "y": 9,
      "z": 14,
      "name": "Rock_Stone"
    },
    {
      "x": -22,
      "y": 10,
      "z": 14,
      "name": "Rock_Stone"
    },
    {
      "x": -22,
      "y": 11,
      "z": 14,
      "name": "Rock_Stone"
    },
    {
      "x": -22,
      "y": 12,
      "z": 14,
      "name": "Rock_Stone"
    },
    {
      "x": -22,
      "y": 13,
      "z": 14,
      "name": "Rock_Stone"
    },
    {
      "x": -22,
      "y": 14,
      "z": 14,
      "name": "Rock_Stone"
    },
    {
      "x": -22,
      "y": 15,
      "z": 14,
      "name": "Rock_Stone"
    },
    {
      "x": -22,
      "y": 0,
      "z": 15,
      "name": "Rock_Stone"
    },
