{
  "version": 8,
  "blockIdVersion": 8,
  "anchorX": -1,
  "anchorY": 61,
  "anchorZ": 21,
  "blocks": [
    {
      "x": -13,
      "y": 60,
      "z": 5,
      "name": "Rock_Basalt_Brick_Smooth"
    },
    {
      "x": -13,
      "y": 61,
      "z": 5,
      "name": "Rock_Basalt_Brick_Smooth"
    },
    {
      "x": -13,
      "y": 62,
      "z": 5,
      "name": "Rock_Basalt_Brick_Smooth_Half"
    },
    {
      "x": -13,
      "y": 56,
      "z": 6,
      "name": "Rock_Shale"
    },
    {
      "x": -13,
      "y": 57,
      "z": 6,
      "name": "Rock_Shale"
    },
    {
      "x": -13,
      "y": 58,
      "z": 6,
      "name": "Rock_Shale"
    },
    {
      "x": -13,
      "y": 59,
      "z": 6,
      "name": "Rock_Shale"
    },
    {
      "x": -13,
      "y": 60,
      "z": 6,
      "name": "Rock_Shale"
    },
    {
      "x": -13,
      "y": 61,
      "z": 6,
      "name": "Rock_Shale"
    },
    {
      "x": -13,
      "y": 62,
      "z": 6,
      "name": "Rock_Basalt_Brick_Smooth_Half",
      "rotation": 7
    },
    {
      "x": -13,
      "y": 63,
      "z": 6,
      "name": "Rock_Basalt_Brick_Smooth_Half",
      "rotation": 7
    },
    {
      "x": -13,
      "y": 55,
      "z": 7,
      "name": "Rock_Shale"
    },
    {
      "x": -13,
      "y": 56,
      "z": 7,
      "name": "Rock_Shale"
    },
    {
      "x": -13,
      "y": 57,
      "z": 7,
      "name": "Rock_Shale"
    },
    {
      "x": -13,
      "y": 58,
      "z": 7,
      "name": "Rock_Shale"
    },
    {
      "x": -13,
      "y": 59,
      "z": 7,
      "name": "Rock_Shale"
    },
    {
      "x": -13,
      "y": 60,
      "z": 7,
      "name": "Rock_Shale"
    },
    {
      "x": -13,
      "y": 61,
      "z": 7,
      "name": "Rock_Shale"
    },
    {
      "x": -13,
      "y": 62,
      "z": 7,
      "name": "Rock_Basalt_Brick_Half",
      "rotation": 7
    },
    {
      "x": -13,
      "y": 63,
      "z": 7,
      "name": "Rock_Basalt_Brick_Half",
      "rotation": 7
    },
    {
      "x": -13,
      "y": 55,
      "z": 8,
      "name": "Rock_Shale"
    },
    {
      "x": -13,
      "y": 56,
      "z": 8,
      "name": "Rock_Shale"
    },
    {
      "x": -13,
      "y": 57,
      "z": 8,
      "name": "Rock_Shale"
    },
    {
      "x": -13,
      "y": 58,
      "z": 8,
      "name": "Rock_Shale"
    },
    {
      "x": -13,
      "y": 59,
      "z": 8,
      "name": "Rock_Shale"
    },
    {
      "x": -13,
      "y": 60,
      "z": 8,
      "name": "Rock_Shale"
    },
    {
      "x": -13,
      "y": 61,
      "z": 8,
      "name": "Rock_Shale"
    },
    {
      "x": -13,
      "y": 62,
      "z": 8,
      "name": "Rock_Basalt_Brick_Half",
      "rotation": 7
    },
    {
      "x": -13,
      "y": 63,
      "z": 8,
      "name": "Rock_Basalt_Brick_Half",
      "rotation": 7
    },
    {
      "x": -13,
      "y": 54,
      "z": 9,
      "name": "Rock_Shale"
    },
    {
      "x": -13,
      "y": 55,
      "z": 9,
      "name": "Rock_Shale"
    },
    {
      "x": -13,
      "y": 56,
      "z": 9,
      "name": "Rock_Shale"
    },
    {
      "x": -13,
      "y": 57,
      "z": 9,
      "name": "Rock_Shale"
    },
    {
      "x": -13,
      "y": 58,
      "z": 9,
      "name": "Rock_Shale"
    },
    {
      "x": -13,
      "y": 59,
      "z": 9,
      "name": "Rock_Shale"
    },
    {
      "x": -13,
      "y": 60,
      "z": 9,
      "name": "Rock_Shale"
    },
    {
      "x": -13,
      "y": 61,
      "z": 9,
      "name": "Rock_Shale"
    },
    {
      "x": -13,
      "y": 62,
      "z": 9,
      "name": "Rock_Shale"
    },
    {
      "x": -13,
      "y": 63,
      "z": 9,
      "name": "Rock_Basalt_Brick_Half",
      "rotation": 7
    },
    {
      "x": -13,
      "y": 54,
      "z": 10,
      "name": "Rock_Shale"
    },
    {
      "x": -13,
      "y": 55,
      "z": 10,
      "name": "Rock_Shale"
    },
    {
      "x": -13,
      "y": 56,
      "z": 10,
      "name": "Rock_Shale"
    },
    {
      "x": -13,
      "y": 57,
      "z": 10,
      "name": "Rock_Shale"
    },
    {
      "x": -13,
      "y": 58,
      "z": 10,
      "name": "Rock_Shale"
    },
    {
      "x": -13,
      "y": 59,
      "z": 10,
      "name": "Rock_Shale"
    },
    {
      "x": -13,
      "y": 60,
      "z": 10,
      "name": "Rock_Shale"
    },
    {
      "x": -13,
      "y": 61,
      "z": 10,
      "name": "Rock_Shale"
    },
    {
      "x": -13,
      "y": 62,
      "z": 10,
      "name": "Rock_Shale"
    },
    {
      "x": -13,
      "y": 63,
      "z": 10,
      "name": "Rock_Basalt_Brick_Half",
      "rotation": 7
    },
    {
      "x": -13,
      "y": 54,
      "z": 11,
      "name": "Rock_Shale"
    },
    {
      "x": -13,
      "y": 55,
      "z": 11,
      "name": "Rock_Shale"
    },
    {
      "x": -13,
      "y": 56,
      "z": 11,
      "name": "Rock_Shale"
    },
    {
      "x": -13,
      "y": 57,
      "z": 11,
      "name": "Rock_Shale"
    },
    {
      "x": -13,
      "y": 58,
      "z": 11,
      "name": "Rock_Shale"
    },
    {
      "x": -13,
      "y": 59,
      "z": 11,
      "name": "Rock_Shale"
    },
    {
      "x": -13,
      "y": 60,
      "z": 11,
      "name": "Rock_Shale"
    },
    {
      "x": -13,
      "y": 61,
      "z": 11,
      "name": "Rock_Shale"
    },
    {
      "x": -13,
      "y": 62,
      "z": 11,
      "name": "Rock_Shale"
    },
    {
      "x": -13,
      "y": 63,
      "z": 11,
      "name": "Rock_Basalt_Brick_Half",
      "rotation": 7
    },
    {
      "x": -13,
      "y": 54,
      "z": 12,
      "name": "Rock_Shale"
    },
    {
      "x": -13,
      "y": 55,
      "z": 12,
      "name": "Rock_Shale"
    },
    {
      "x": -13,
      "y": 56,
      "z": 12,
      "name": "Rock_Shale"
    },
    {
      "x": -13,
      "y": 57,
      "z": 12,
      "name": "Rock_Shale"
    },
    {
      "x": -13,
      "y": 58,
      "z": 12,
      "name": "Rock_Shale"
    },
    {
      "x": -13,
      "y": 59,
      "z": 12,
      "name": "Rock_Basalt_Brick_Smooth"
    },
    {
      "x": -13,
      "y": 60,
      "z": 12,
      "name": "Rock_Basalt_Brick_Smooth"
    },
    {
      "x": -13,
      "y": 61,
      "z": 12,
      "name": "Rock_Basalt_Brick_Smooth"
    },
    {
      "x": -13,
      "y": 62,
      "z": 12,
      "name": "Rock_Basalt_Brick_Smooth"
    },
    {
      "x": -13,
      "y": 63,
      "z": 12,
      "name": "Rock_Basalt_Brick_Smooth"
    },
    {
      "x": -13,
      "y": 64,
      "z": 12,
      "name": "Rock_Basalt_Brick_Smooth_Half",
      "rotation": 7
    },
    {
      "x": -13,
      "y": 65,
      "z": 12,
      "name": "Rock_Basalt_Brick_Smooth_Half",
      "rotation": 7
    },
    {
      "x": -13,
      "y": 56,
      "z": 13,
      "name": "Rock_Shale"
    },
    {
      "x": -13,
      "y": 57,
      "z": 13,
      "name": "Rock_Shale"
    },
    {
      "x": -13,
      "y": 58,
      "z": 13,
      "name": "Rock_Shale"
    },
    {
      "x": -13,
      "y": 59,
      "z": 13,
      "name": "Rock_Shale"
    },
    {
      "x": -13,
      "y": 60,
      "z": 13,
      "name": "Rock_Shale"
    },
    {
      "x": -13,
      "y": 61,
      "z": 13,
      "name": "Rock_Shale"
    },
    {
      "x": -13,
      "y": 62,
      "z": 13,
      "name": "Rock_Basalt_Brick_Half",
      "rotation": 7
    },
    {
      "x": -13,
      "y": 63,
      "z": 13,
      "name": "Rock_Basalt_Brick_Half",
      "rotation": 7
    },
    {
      "x": -13,
      "y": 57,
      "z": 14,
      "name": "Rock_Shale"
    },
    {
      "x": -13,
      "y": 58,
      "z": 14,
      "name": "Rock_Shale"
    },
    {
      "x": -13,
      "y": 59,
      "z": 14,
      "name": "Rock_Shale"
    },
    {
      "x": -13,
      "y": 60,
      "z": 14,
      "name": "Rock_Shale"
    },
    {
      "x": -13,
      "y": 61,
      "z": 14,
      "name": "Rock_Shale"
    },
    {
      "x": -13,
      "y": 62,
      "z": 14,
      "name": "Rock_Basalt_Brick_Half",
      "rotation": 7
    },
    {
      "x": -13,
      "y": 60,
      "z": 16,
      "name": "Rock_Basalt_Brick_Smooth"
    },
    {
      "x": -13,
      "y": 61,
      "z": 16,
      "name": "Rock_Basalt_Brick_Smooth"
    },
    {
      "x": -13,
      "y": 62,
      "z": 16,
      "name": "Rock_Basalt_Brick_Smooth"
    },
    {
      "x": -13,
      "y": 63,
      "z": 16,
      "name": "Rock_Basalt_Brick_Smooth"
    },
    {
      "x": -13,
      "y": 64,
      "z": 16,
      "name": "Rock_Basalt_Brick_Smooth_Half",
      "rotation": 7
    },
    {
      "x": -13,
      "y": 65,
      "z": 16,
      "name": "Rock_Basalt_Brick_Smooth_Half",
      "rotation": 7
    },
    {
      "x": -13,
      "y": 57,
      "z": 17,
      "name": "Rock_Shale"
    },
    {
      "x": -13,
      "y": 58,
      "z": 17,
      "name": "Rock_Shale"
    },
    {
      "x": -13,
      "y": 59,
      "z": 17,
      "name": "Rock_Shale"
    },
    {
      "x": -13,
      "y": 60,
      "z": 17,
      "name": "Rock_Shale"
    },
    {
      "x": -13,
      "y": 61,
      "z": 17,
      "name": "Rock_Shale"
    },
    {
      "x": -13,
      "y": 62,
      "z": 17,
      "name": "Rock_Shale"
    },
    {
      "x": -13,
      "y": 63,
      "z": 17,
      "name": "Rock_Basalt_Brick_Half",
      "rotation": 7
    },
    {
      "x": -13,
      "y": 64,
      "z": 17,
      "name": "Rock_Basalt_Brick_Half",
      "rotation": 7
    },
    {
      "x": -13,
      "y": 54,
      "z": 18,
      "name": "Rock_Shale"
    },
    {
      "x": -13,
      "y": 55,
      "z": 18,
      "name": "Rock_Shale"
    },
    {
      "x": -13,
      "y": 56,
      "z": 18,
      "name": "Rock_Shale"
    },
    {
      "x": -13,
      "y": 57,
      "z": 18,
      "name": "Rock_Shale"
    },
    {
      "x": -13,
      "y": 58,
      "z": 18,
      "name": "Rock_Shale"
    },
    {
      "x": -13,
      "y": 59,
      "z": 18,
      "name": "Rock_Shale"
    },
    {
      "x": -13,
      "y": 60,
      "z": 18,
      "name": "Rock_Shale"
    },
    {
      "x": -13,
      "y": 61,
      "z": 18,
      "name": "Rock_Shale"
    },
    {
      "x": -13,
      "y": 62,
      "z": 18,
      "name": "Rock_Shale"
    },
    {
      "x": -13,
      "y": 63,
      "z": 18,
      "name": "Rock_Basalt_Brick_Half",
      "rotation": 7
    },
    {
      "x": -13,
      "y": 64,
      "z": 18,
      "name": "Rock_Basalt_Brick_Half",
      "rotation": 7
    },
    {
      "x": -13,
      "y": 54,
      "z": 19,
      "name": "Rock_Shale"
    },
    {
      "x": -13,
      "y": 55,
      "z": 19,
      "name": "Rock_Shale"
    },
    {
      "x": -13,
      "y": 56,
      "z": 19,
      "name": "Rock_Shale"
    },
    {
      "x": -13,
      "y": 57,
      "z": 19,
      "name": "Rock_Shale"
    },
    {
      "x": -13,
      "y": 58,
      "z": 19,
      "name": "Rock_Shale"
    },
    {
      "x": -13,
      "y": 59,
      "z": 19,
      "name": "Rock_Shale"
    },
    {
      "x": -13,
      "y": 60,
      "z": 19,
      "name": "Rock_Shale"
    },
    {
      "x": -13,
      "y": 61,
      "z": 19,
      "name": "Rock_Shale"
    },
    {
      "x": -13,
      "y": 62,
      "z": 19,
      "name": "Rock_Shale"
    },
    {
      "x": -13,
      "y": 63,
      "z": 19,
      "name": "Rock_Basalt_Brick_Half",
      "rotation": 7
    },
    {
      "x": -13,
      "y": 64,
      "z": 19,
      "name": "Rock_Basalt_Brick_Half",
      "rotation": 7
    },
    {
      "x": -13,
      "y": 54,
      "z": 20,
      "name": "Rock_Shale"
    },
    {
      "x": -13,
      "y": 55,
      "z": 20,
      "name": "Rock_Shale"
    },
    {
      "x": -13,
      "y": 56,
      "z": 20,
      "name": "Rock_Shale"
    },
    {
      "x": -13,
      "y": 57,
      "z": 20,
      "name": "Rock_Shale"
    },
    {
      "x": -13,
      "y": 58,
      "z": 20,
      "name": "Rock_Shale"
    },
    {
      "x": -13,
      "y": 59,
      "z": 20,
      "name": "Rock_Shale"
    },
    {
      "x": -13,
      "y": 60,
      "z": 20,
      "name": "Rock_Shale"
    },
    {
      "x": -13,
      "y": 61,
      "z": 20,
      "name": "Rock_Basalt_Brick_Smooth"
    },
    {
      "x": -13,
      "y": 62,
      "z": 20,
      "name": "Rock_Basalt_Brick_Smooth"
    },
    {
      "x": -13,
      "y": 63,
      "z": 20,
      "name": "Rock_Basalt_Brick_Smooth"
    },
    {
      "x": -13,
      "y": 64,
      "z": 20,
      "name": "Rock_Basalt_Brick_Smooth_Half",
      "rotation": 7
    },
    {
      "x": -13,
      "y": 65,
      "z": 20,
      "name": "Rock_Basalt_Brick_Smooth_Half",
      "rotation": 7
    },
    {
      "x": -13,
      "y": 55,
      "z": 21,
      "name": "Rock_Shale"
    },
    {
      "x": -13,
      "y": 56,
      "z": 21,
      "name": "Rock_Shale"
    },
    {
      "x": -13,
      "y": 57,
      "z": 21,
      "name": "Rock_Shale"
    },
    {
      "x": -13,
      "y": 58,
      "z": 21,
      "name": "Rock_Shale"
    },
    {
      "x": -13,
      "y": 56,
      "z": 24,
      "name": "Rock_Shale"
    },
    {
      "x": -13,
      "y": 57,
      "z": 24,
      "name": "Rock_Shale"
    },
    {
      "x": -13,
      "y": 58,
      "z": 24,
      "name": "Rock_Shale"
    },
    {
      "x": -13,
      "y": 59,
      "z": 24,
      "name": "Rock_Shale"
    },
    {
      "x": -13,
      "y": 60,
      "z": 24,
      "name": "Rock_Basalt_Brick_Smooth"
    },
    {
      "x": -13,
      "y": 61,
      "z": 24,
      "name": "Rock_Basalt_Brick_Smooth"
    },
    {
      "x": -13,
      "y": 62,
      "z": 24,
      "name": "Rock_Basalt_Brick_Smooth"
    },
    {
      "x": -13,
      "y": 63,
      "z": 24,
      "name": "Rock_Basalt_Brick_Smooth"
    },
    {
      "x": -13,
      "y": 64,
      "z": 24,
      "name": "Rock_Basalt_Brick_Smooth_Half",
      "rotation": 7
    },
    {
      "x": -13,
      "y": 65,
      "z": 24,
      "name": "Rock_Basalt_Brick_Smooth_Half",
      "rotation": 7
    },
    {
      "x": -13,
      "y": 56,
      "z": 25,
      "name": "Rock_Shale"
    },
    {
      "x": -13,
      "y": 57,
      "z": 25,
      "name": "Rock_Shale"
    },
    {
      "x": -13,
      "y": 58,
      "z": 25,
      "name": "Rock_Shale"
    },
    {
      "x": -13,
      "y": 59,
      "z": 25,
      "name": "Rock_Shale"
    },
    {
      "x": -13,
      "y": 60,
      "z": 25,
      "name": "Rock_Shale"
    },
    {
      "x": -13,
      "y": 61,
      "z": 25,
      "name": "Rock_Shale"
    },
    {
      "x": -13,
      "y": 62,
      "z": 25,
      "name": "Rock_Basalt_Brick_Half",
      "rotation": 7
    },
    {
      "x": -13,
      "y": 63,
      "z": 25,
      "name": "Rock_Basalt_Brick_Half",
      "rotation": 7
    },
    {
      "x": -13,
      "y": 55,
      "z": 26,
      "name": "Rock_Shale"
    },
    {
      "x": -13,
      "y": 56,
      "z": 26,
      "name": "Rock_Shale"
    },
    {
      "x": -13,
      "y": 57,
      "z": 26,
      "name": "Rock_Shale"
    },
    {
      "x": -13,
      "y": 58,
      "z": 26,
      "name": "Rock_Shale"
    },
    {
      "x": -13,
      "y": 59,
      "z": 26,
      "name": "Rock_Shale"
    },
    {
      "x": -13,
      "y": 60,
      "z": 26,
      "name": "Rock_Shale"
    },
    {
      "x": -13,
      "y": 61,
      "z": 26,
      "name": "Rock_Shale"
    },
    {
      "x": -13,
      "y": 62,
      "z": 26,
      "name": "Rock_Basalt_Brick_Half",
      "rotation": 7
    },
    {
      "x": -13,
      "y": 63,
      "z": 26,
      "name": "Rock_Basalt_Brick_Half",
      "rotation": 7
    },
    {
      "x": -13,
      "y": 55,
      "z": 27,
      "name": "Rock_Shale"
    },
    {
      "x": -13,
      "y": 56,
      "z": 27,
      "name": "Rock_Shale"
    },
    {
      "x": -13,
      "y": 57,
      "z": 27,
      "name": "Rock_Shale"
    },
    {
      "x": -13,
      "y": 58,
      "z": 27,
      "name": "Rock_Shale"
    },
    {
      "x": -13,
      "y": 59,
      "z": 27,
      "name": "Rock_Shale"
    },
    {
      "x": -13,
      "y": 60,
      "z": 27,
      "name": "Rock_Shale"
    },
    {
      "x": -13,
      "y": 61,
      "z": 27,
      "name": "Rock_Shale"
    },
    {
      "x": -13,
      "y": 62,
      "z": 27,
      "name": "Rock_Basalt_Brick_Half",
      "rotation": 7
    },
    {
      "x": -13,
      "y": 63,
      "z": 27,
      "name": "Rock_Basalt_Brick_Half",
      "rotation": 7
    },
    {
      "x": -13,
      "y": 55,
      "z": 28,
      "name": "Rock_Shale"
    },
    {
      "x": -13,
      "y": 56,
      "z": 28,
      "name": "Rock_Shale"
    },
    {
      "x": -13,
      "y": 57,
      "z": 28,
      "name": "Rock_Shale"
    },
    {
      "x": -13,
      "y": 58,
      "z": 28,
      "name": "Rock_Shale"
    },
    {
      "x": -13,
      "y": 59,
      "z": 28,
      "name": "Rock_Shale"
    },
    {
      "x": -13,
      "y": 60,
      "z": 28,
      "name": "Rock_Shale"
    },
    {
      "x": -13,
      "y": 61,
      "z": 28,
      "name": "Rock_Shale"
    },
    {
      "x": -13,
      "y": 62,
      "z": 28,
      "name": "Rock_Basalt_Brick_Half",
      "rotation": 7
    },
    {
      "x": -13,
      "y": 63,
      "z": 28,
      "name": "Rock_Basalt_Brick_Half",
      "rotation": 7
    },
    {
      "x": -13,
      "y": 55,
      "z": 29,
      "name": "Rock_Shale"
    },
    {
      "x": -13,
      "y": 56,
      "z": 29,
      "name": "Rock_Shale"
    },
    {
      "x": -13,
      "y": 57,
      "z": 29,
      "name": "Rock_Shale"
    },
    {
      "x": -13,
      "y": 58,
      "z": 29,
      "name": "Rock_Shale"
    },
    {
      "x": -13,
      "y": 59,
      "z": 29,
      "name": "Rock_Shale"
    },
    {
      "x": -13,
      "y": 60,
      "z": 29,
      "name": "Rock_Shale"
    },
    {
      "x": -13,
      "y": 61,
      "z": 29,
      "name": "Rock_Shale"
    },
    {
      "x": -13,
      "y": 62,
      "z": 29,
      "name": "Rock_Basalt_Brick_Half",
      "rotation": 7
    },
    {
      "x": -13,
      "y": 63,
      "z": 29,
      "name": "Rock_Basalt_Brick_Half",
      "rotation": 7
    },
    {
      "x": -13,
      "y": 55,
      "z": 30,
      "name": "Rock_Shale"
    },
    {
      "x": -13,
      "y": 56,
      "z": 30,
      "name": "Rock_Shale"
    },
    {
      "x": -13,
      "y": 57,
      "z": 30,
      "name": "Rock_Shale"
    },
    {
      "x": -13,
      "y": 58,
      "z": 30,
      "name": "Rock_Shale"
    },
    {
      "x": -13,
      "y": 59,
      "z": 30,
      "name": "Rock_Shale"
    },
    {
      "x": -13,
      "y": 60,
      "z": 30,
      "name": "Rock_Shale"
    },
    {
      "x": -13,
      "y": 61,
      "z": 30,
      "name": "Rock_Shale"
    },
    {
      "x": -13,
      "y": 62,
      "z": 30,
      "name": "Rock_Basalt_Brick_Smooth_Half",
      "rotation": 7
    },
    {
      "x": -13,
      "y": 63,
      "z": 30,
      "name": "Rock_Basalt_Brick_Smooth_Half",
      "rotation": 7
    },
    {
      "x": -13,
      "y": 57,
      "z": 31,
      "name": "Rock_Shale"
    },
    {
      "x": -13,
      "y": 58,
      "z": 31,
      "name": "Rock_Shale"
    },
    {
      "x": -13,
      "y": 59,
      "z": 31,
      "name": "Rock_Basalt_Brick_Smooth"
    },
    {
      "x": -13,
      "y": 60,
      "z": 31,
      "name": "Rock_Basalt_Brick_Smooth"
    },
    {
      "x": -13,
      "y": 61,
      "z": 31,
      "name": "Rock_Basalt_Brick_Smooth"
    },
    {
      "x": -13,
      "y": 62,
      "z": 31,
      "name": "Rock_Basalt_Brick_Smooth_Half"
    },
    {
      "x": -12,
      "y": 58,
      "z": 5,
      "name": "Rock_Shale"
    },
    {
      "x": -12,
      "y": 59,
      "z": 5,
      "name": "Rock_Shale"
    },
    {
      "x": -12,
      "y": 60,
      "z": 5,
      "name": "Rock_Shale"
    },
    {
      "x": -12,
      "y": 61,
      "z": 5,
      "name": "Rock_Shale"
    },
    {
      "x": -12,
      "y": 62,
      "z": 5,
      "name": "Rock_Basalt_Brick_Smooth_Half",
      "rotation": 6
    },
    {
      "x": -12,
      "y": 63,
      "z": 5,
      "name": "Rock_Basalt_Brick_Smooth_Half",
      "rotation": 6
    },
    {
      "x": -12,
      "y": 54,
      "z": 6,
      "name": "Rock_Shale"
    },
    {
      "x": -12,
      "y": 55,
      "z": 6,
      "name": "Rock_Shale"
    },
    {
      "x": -12,
      "y": 56,
      "z": 6,
      "name": "Rock_Shale"
    },
    {
      "x": -12,
      "y": 57,
      "z": 6,
      "name": "Rock_Shale"
    },
    {
      "x": -12,
      "y": 58,
      "z": 6,
      "name": "Rock_Shale"
    },
    {
      "x": -12,
      "y": 59,
      "z": 6,
      "name": "Rock_Shale"
    },
    {
      "x": -12,
      "y": 60,
      "z": 6,
      "name": "Rock_Shale"
    },
    {
      "x": -12,
      "y": 61,
      "z": 6,
      "name": "Rock_Shale"
    },
    {
      "x": -12,
      "y": 62,
      "z": 6,
      "name": "Rock_Basalt_Brick"
    },
    {
      "x": -12,
      "y": 63,
      "z": 6,
      "name": "Rock_Basalt_Brick"
    },
    {
      "x": -12,
      "y": 64,
      "z": 6,
      "name": "Rock_Basalt_Brick_Smooth"
    },
    {
      "x": -12,
      "y": 65,
      "z": 6,
      "name": "Rock_Basalt_Brick_Smooth"
    },
    {
      "x": -12,
      "y": 66,
      "z": 6,
      "name": "Rock_Basalt_Brick_Smooth_Half"
    },
    {
      "x": -12,
      "y": 69,
      "z": 6,
      "name": "Rock_Basalt_Brick_Smooth_Half",
      "rotation": 8
    },
    {
      "x": -12,
      "y": 70,
      "z": 6,
      "name": "Soil_Snow"
    },
    {
      "x": -12,
      "y": 54,
      "z": 7,
      "name": "Rock_Shale"
    },
    {
      "x": -12,
      "y": 55,
      "z": 7,
      "name": "Rock_Shale"
    },
    {
      "x": -12,
      "y": 56,
      "z": 7,
      "name": "Rock_Shale"
    },
    {
      "x": -12,
      "y": 57,
      "z": 7,
      "name": "Rock_Shale"
    },
    {
      "x": -12,
      "y": 58,
      "z": 7,
      "name": "Rock_Shale"
    },
    {
      "x": -12,
      "y": 59,
      "z": 7,
      "name": "Rock_Shale"
    },
    {
      "x": -12,
      "y": 60,
      "z": 7,
      "name": "Rock_Shale"
    },
    {
      "x": -12,
      "y": 61,
      "z": 7,
      "name": "Rock_Shale"
    },
    {
      "x": -12,
      "y": 62,
      "z": 7,
      "name": "Rock_Basalt_Brick"
    },
    {
      "x": -12,
      "y": 63,
      "z": 7,
      "name": "Rock_Basalt_Brick"
    },
    {
      "x": -12,
      "y": 64,
      "z": 7,
      "name": "Rock_Basalt_Brick"
    },
    {
      "x": -12,
      "y": 65,
      "z": 7,
      "name": "Rock_Basalt_Brick"
    },
    {
      "x": -12,
      "y": 66,
      "z": 7,
      "name": "Rock_Basalt_Brick_Smooth_Half",
      "rotation": 7
    },
    {
      "x": -12,
      "y": 67,
      "z": 7,
      "name": "Rock_Basalt_Brick_Smooth_Half",
      "rotation": 7
    },
    {
      "x": -12,
      "y": 68,
      "z": 7,
      "name": "Rock_Basalt_Brick_Smooth_Half",
      "rotation": 7
    },
    {
      "x": -12,
      "y": 69,
      "z": 7,
      "name": "Rock_Ice"
    },
    {
      "x": -12,
      "y": 70,
      "z": 7,
      "name": "Soil_Snow"
    },
    {
      "x": -12,
      "y": 71,
      "z": 7,
      "name": "Soil_Snow"
    },
    {
      "x": -12,
      "y": 54,
      "z": 8,
      "name": "Rock_Shale"
    },
    {
      "x": -12,
      "y": 55,
      "z": 8,
      "name": "Rock_Shale"
    },
    {
      "x": -12,
      "y": 56,
      "z": 8,
      "name": "Rock_Shale"
    },
    {
      "x": -12,
      "y": 57,
      "z": 8,
      "name": "Rock_Shale"
    },
    {
      "x": -12,
      "y": 58,
      "z": 8,
      "name": "Rock_Shale"
    },
    {
      "x": -12,
      "y": 59,
      "z": 8,
      "name": "Rock_Shale"
    },
    {
      "x": -12,
      "y": 60,
      "z": 8,
      "name": "Rock_Shale"
    },
    {
      "x": -12,
      "y": 61,
      "z": 8,
      "name": "Rock_Shale"
    },
    {
      "x": -12,
      "y": 62,
      "z": 8,
      "name": "Rock_Basalt_Brick"
    },
    {
      "x": -12,
      "y": 63,
      "z": 8,
      "name": "Rock_Basalt_Brick"
    },
    {
      "x": -12,
      "y": 64,
      "z": 8,
      "name": "Rock_Basalt_Brick"
    },
    {
      "x": -12,
      "y": 65,
      "z": 8,
      "name": "Rock_Basalt_Brick"
    },
    {
      "x": -12,
      "y": 66,
      "z": 8,
      "name": "Rock_Shale_Brick_Half",
      "rotation": 7
    },
    {
      "x": -12,
      "y": 67,
      "z": 8,
      "name": "Rock_Shale_Brick_Half",
      "rotation": 7
    },
    {
      "x": -12,
      "y": 68,
      "z": 8,
      "name": "Rock_Ice_Icicles",
      "rotation": 8
    },
    {
      "x": -12,
      "y": 69,
      "z": 8,
      "name": "Rock_Ice"
    },
    {
      "x": -12,
      "y": 70,
      "z": 8,
      "name": "Soil_Snow"
    },
    {
      "x": -12,
      "y": 71,
      "z": 8,
      "name": "Soil_Snow"
    },
    {
      "x": -12,
      "y": 54,
      "z": 9,
      "name": "Rock_Shale"
    },
    {
      "x": -12,
      "y": 55,
      "z": 9,
      "name": "Rock_Shale"
    },
    {
      "x": -12,
      "y": 56,
      "z": 9,
      "name": "Rock_Shale"
    },
    {
      "x": -12,
      "y": 57,
      "z": 9,
      "name": "Rock_Shale"
    },
    {
      "x": -12,
      "y": 58,
      "z": 9,
      "name": "Rock_Shale"
    },
    {
      "x": -12,
      "y": 59,
      "z": 9,
      "name": "Rock_Shale"
    },
    {
      "x": -12,
      "y": 60,
      "z": 9,
      "name": "Rock_Shale"
    },
    {
      "x": -12,
      "y": 61,
      "z": 9,
      "name": "Rock_Shale"
    },
    {
      "x": -12,
      "y": 62,
      "z": 9,
      "name": "Rock_Shale"
    },
    {
      "x": -12,
      "y": 63,
      "z": 9,
      "name": "Rock_Basalt_Brick"
    },
    {
      "x": -12,
      "y": 64,
      "z": 9,
      "name": "Rock_Basalt_Brick"
    },
    {
      "x": -12,
      "y": 65,
      "z": 9,
      "name": "Rock_Basalt_Brick"
    },
    {
      "x": -12,
      "y": 66,
      "z": 9,
      "name": "Rock_Shale_Brick_Half",
      "rotation": 7
    },
    {
      "x": -12,
      "y": 67,
      "z": 9,
      "name": "Rock_Shale_Brick_Half",
      "rotation": 7
    },
    {
      "x": -12,
      "y": 69,
      "z": 9,
      "name": "Rock_Ice"
    },
    {
      "x": -12,
      "y": 70,
      "z": 9,
      "name": "Soil_Snow"
    },
    {
      "x": -12,
      "y": 71,
      "z": 9,
      "name": "Soil_Snow"
    },
    {
      "x": -12,
      "y": 54,
      "z": 10,
      "name": "Rock_Shale"
    },
    {
      "x": -12,
      "y": 55,
      "z": 10,
      "name": "Rock_Shale"
    },
    {
      "x": -12,
      "y": 56,
      "z": 10,
      "name": "Rock_Shale"
    },
    {
      "x": -12,
      "y": 57,
      "z": 10,
      "name": "Rock_Shale"
    },
    {
      "x": -12,
      "y": 58,
      "z": 10,
      "name": "Rock_Shale"
    },
    {
      "x": -12,
      "y": 59,
      "z": 10,
      "name": "Rock_Shale"
    },
    {
      "x": -12,
      "y": 60,
      "z": 10,
      "name": "Rock_Shale"
    },
    {
      "x": -12,
      "y": 61,
      "z": 10,
      "name": "Rock_Shale"
    },
    {
      "x": -12,
      "y": 62,
      "z": 10,
      "name": "Rock_Shale"
    },
    {
      "x": -12,
      "y": 63,
      "z": 10,
      "name": "Rock_Basalt_Brick"
    },
    {
      "x": -12,
      "y": 64,
      "z": 10,
      "name": "Rock_Basalt_Brick"
    },
    {
      "x": -12,
      "y": 65,
      "z": 10,
      "name": "Rock_Basalt_Brick"
    },
    {
      "x": -12,
      "y": 66,
      "z": 10,
      "name": "Rock_Shale_Brick_Half",
      "rotation": 7
    },
    {
      "x": -12,
      "y": 67,
      "z": 10,
      "name": "Rock_Shale_Brick_Half",
      "rotation": 7
    },
    {
      "x": -12,
      "y": 69,
      "z": 10,
      "name": "Rock_Basalt_Brick_Smooth_Half",
      "rotation": 8
    },
    {
      "x": -12,
      "y": 70,
      "z": 10,
      "name": "Soil_Snow"
    },
    {
      "x": -12,
      "y": 71,
      "z": 10,
      "name": "Soil_Snow"
    },
    {
      "x": -12,
      "y": 54,
      "z": 11,
      "name": "Rock_Shale"
    },
    {
      "x": -12,
      "y": 55,
      "z": 11,
      "name": "Rock_Shale"
    },
    {
      "x": -12,
      "y": 56,
      "z": 11,
      "name": "Rock_Shale"
    },
    {
      "x": -12,
      "y": 57,
      "z": 11,
      "name": "Rock_Shale"
    },
    {
      "x": -12,
      "y": 58,
      "z": 11,
      "name": "Rock_Shale"
    },
    {
      "x": -12,
      "y": 59,
      "z": 11,
      "name": "Rock_Shale"
    },
    {
      "x": -12,
      "y": 60,
      "z": 11,
      "name": "Rock_Shale"
    },
    {
      "x": -12,
      "y": 61,
      "z": 11,
      "name": "Rock_Shale"
    },
    {
      "x": -12,
      "y": 62,
      "z": 11,
      "name": "Rock_Shale"
    },
    {
      "x": -12,
      "y": 63,
      "z": 11,
      "name": "Rock_Basalt_Brick"
    },
    {
      "x": -12,
      "y": 64,
      "z": 11,
      "name": "Rock_Basalt_Brick"
    },
    {
      "x": -12,
      "y": 65,
      "z": 11,
      "name": "Rock_Basalt_Brick"
    },
    {
      "x": -12,
      "y": 66,
      "z": 11,
      "name": "Rock_Shale_Brick_Half",
      "rotation": 7
    },
    {
      "x": -12,
      "y": 67,
      "z": 11,
      "name": "Rock_Shale_Brick_Half",
      "rotation": 7
    },
    {
      "x": -12,
      "y": 69,
      "z": 11,
      "name": "Rock_Basalt_Brick_Smooth_Half",
      "rotation": 8
    },
    {
      "x": -12,
      "y": 70,
      "z": 11,
      "name": "Soil_Snow"
    },
    {
      "x": -12,
      "y": 54,
      "z": 12,
      "name": "Rock_Shale"
    },
    {
      "x": -12,
      "y": 55,
      "z": 12,
      "name": "Rock_Shale"
    },
    {
      "x": -12,
      "y": 56,
      "z": 12,
      "name": "Rock_Shale"
    },
    {
      "x": -12,
      "y": 57,
      "z": 12,
      "name": "Rock_Shale"
    },
    {
      "x": -12,
      "y": 58,
      "z": 12,
      "name": "Rock_Shale"
    },
    {
      "x": -12,
      "y": 59,
      "z": 12,
      "name": "Rock_Shale"
    },
    {
      "x": -12,
      "y": 60,
      "z": 12,
      "name": "Rock_Shale"
    },
    {
      "x": -12,
      "y": 61,
      "z": 12,
      "name": "Rock_Shale"
    },
    {
      "x": -12,
      "y": 62,
      "z": 12,
      "name": "Rock_Basalt_Brick"
    },
    {
      "x": -12,
      "y": 63,
      "z": 12,
      "name": "Rock_Basalt_Brick"
    },
    {
      "x": -12,
      "y": 64,
      "z": 12,
      "name": "Rock_Basalt_Brick_Smooth"
    },
    {
      "x": -12,
      "y": 65,
      "z": 12,
      "name": "Rock_Basalt_Brick_Smooth"
    },
    {
      "x": -12,
      "y": 69,
      "z": 12,
      "name": "Rock_Basalt_Brick_Smooth"
    },
    {
      "x": -12,
      "y": 70,
      "z": 12,
      "name": "Soil_Snow"
    },
    {
      "x": -12,
      "y": 54,
      "z": 13,
      "name": "Rock_Shale"
    },
    {
      "x": -12,
      "y": 55,
      "z": 13,
      "name": "Rock_Shale"
    },
    {
      "x": -12,
      "y": 56,
      "z": 13,
      "name": "Rock_Shale"
    },
    {
      "x": -12,
      "y": 57,
      "z": 13,
      "name": "Rock_Shale"
    },
    {
      "x": -12,
      "y": 58,
      "z": 13,
      "name": "Rock_Shale"
    },
    {
      "x": -12,
      "y": 59,
      "z": 13,
      "name": "Rock_Shale"
    },
    {
      "x": -12,
      "y": 60,
      "z": 13,
      "name": "Rock_Shale"
    },
    {
      "x": -12,
      "y": 61,
      "z": 13,
      "name": "Rock_Shale"
    },
    {
      "x": -12,
      "y": 62,
      "z": 13,
      "name": "Rock_Basalt_Brick"
    },
    {
      "x": -12,
      "y": 63,
      "z": 13,
      "name": "Rock_Basalt_Brick"
    },
    {
      "x": -12,
      "y": 64,
      "z": 13,
      "name": "Rock_Basalt_Brick"
    },
    {
      "x": -12,
      "y": 65,
      "z": 13,
      "name": "Rock_Basalt_Brick"
    },
    {
      "x": -12,
      "y": 66,
      "z": 13,
      "name": "Rock_Shale_Brick_Half",
      "rotation": 7
    },
    {
      "x": -12,
      "y": 67,
      "z": 13,
      "name": "Rock_Shale_Brick_Half",
      "rotation": 7
    },
    {
      "x": -12,
      "y": 69,
      "z": 13,
      "name": "Rock_Basalt_Brick_Smooth_Half",
      "rotation": 8
    },
    {
      "x": -12,
      "y": 70,
      "z": 13,
      "name": "Soil_Snow"
    },
    {
      "x": -12,
      "y": 54,
      "z": 14,
      "name": "Rock_Shale"
    },
    {
      "x": -12,
      "y": 55,
      "z": 14,
      "name": "Rock_Shale"
    },
    {
      "x": -12,
      "y": 56,
      "z": 14,
      "name": "Rock_Shale"
    },
    {
      "x": -12,
      "y": 57,
      "z": 14,
      "name": "Rock_Shale"
    },
    {
      "x": -12,
      "y": 58,
      "z": 14,
      "name": "Rock_Shale"
    },
    {
      "x": -12,
      "y": 59,
      "z": 14,
      "name": "Rock_Shale"
    },
    {
      "x": -12,
      "y": 60,
      "z": 14,
      "name": "Rock_Shale"
    },
    {
      "x": -12,
      "y": 61,
      "z": 14,
      "name": "Rock_Shale"
    },
    {
      "x": -12,
      "y": 62,
      "z": 14,
      "name": "Rock_Basalt_Brick"
    },
    {
      "x": -12,
      "y": 63,
      "z": 14,
      "name": "Rock_Basalt_Brick_Half",
      "rotation": 7
    },
    {
      "x": -12,
      "y": 64,
      "z": 14,
      "name": "Rock_Basalt_Brick_Half",
      "rotation": 7
    },
    {
      "x": -12,
      "y": 69,
      "z": 14,
      "name": "Rock_Basalt_Brick_Smooth_Half",
      "rotation": 8
    },
    {
      "x": -12,
      "y": 70,
      "z": 14,
      "name": "Soil_Snow"
    },
    {
      "x": -12,
      "y": 58,
      "z": 15,
      "name": "Rock_Shale"
    },
    {
      "x": -12,
      "y": 59,
      "z": 15,
      "name": "Rock_Shale"
    },
    {
      "x": -12,
      "y": 60,
      "z": 15,
      "name": "Rock_Shale"
    },
    {
      "x": -12,
      "y": 61,
      "z": 15,
      "name": "Rock_Shale"
    },
    {
      "x": -12,
      "y": 62,
      "z": 15,
      "name": "Rock_Basalt_Brick_Half",
      "rotation": 7
    },
    {
      "x": -12,
      "y": 63,
      "z": 15,
      "name": "Rock_Basalt_Brick_Half",
      "rotation": 7
    },
    {
      "x": -12,
      "y": 64,
      "z": 15,
      "name": "Rock_Basalt_Brick"
    },
    {
      "x": -12,
      "y": 65,
      "z": 15,
      "name": "Rock_Basalt_Brick"
    },
    {
      "x": -12,
      "y": 66,
      "z": 15,
      "name": "Rock_Shale_Brick_Half",
      "rotation": 7
    },
    {
      "x": -12,
      "y": 67,
      "z": 15,
      "name": "Rock_Shale_Brick_Half",
      "rotation": 7
    },
    {
      "x": -12,
      "y": 69,
      "z": 15,
      "name": "Rock_Basalt_Brick_Smooth_Half",
      "rotation": 8
    },
    {
      "x": -12,
      "y": 70,
      "z": 15,
      "name": "Soil_Snow"
    },
    {
      "x": -12,
      "y": 55,
      "z": 16,
      "name": "Rock_Shale"
    },
    {
      "x": -12,
      "y": 56,
      "z": 16,
      "name": "Rock_Shale"
    },
    {
      "x": -12,
      "y": 57,
      "z": 16,
      "name": "Rock_Shale"
    },
    {
      "x": -12,
      "y": 58,
      "z": 16,
      "name": "Rock_Shale"
    },
    {
      "x": -12,
      "y": 59,
      "z": 16,
      "name": "Rock_Shale"
    },
    {
      "x": -12,
      "y": 60,
      "z": 16,
      "name": "Rock_Shale"
    },
    {
      "x": -12,
      "y": 61,
      "z": 16,
      "name": "Rock_Shale"
    },
    {
      "x": -12,
      "y": 62,
      "z": 16,
      "name": "Rock_Basalt_Brick"
    },
    {
      "x": -12,
      "y": 63,
      "z": 16,
      "name": "Rock_Basalt_Brick"
    },
    {
      "x": -12,
      "y": 64,
      "z": 16,
      "name": "Rock_Basalt_Brick_Smooth"
    },
    {
      "x": -12,
      "y": 65,
      "z": 16,
      "name": "Rock_Basalt_Brick_Smooth"
    },
    {
      "x": -12,
      "y": 69,
      "z": 16,
      "name": "Rock_Basalt_Brick_Smooth"
    },
    {
      "x": -12,
      "y": 70,
      "z": 16,
      "name": "Rock_Basalt_Cobble_Roof",
      "rotation": 3
    },
    {
      "x": -12,
      "y": 54,
      "z": 17,
      "name": "Rock_Shale"
    },
    {
      "x": -12,
      "y": 55,
      "z": 17,
      "name": "Rock_Shale"
    },
    {
      "x": -12,
      "y": 56,
      "z": 17,
      "name": "Rock_Shale"
    },
    {
      "x": -12,
      "y": 57,
      "z": 17,
      "name": "Rock_Shale"
    },
    {
      "x": -12,
      "y": 58,
      "z": 17,
      "name": "Rock_Shale"
    },
    {
      "x": -12,
      "y": 59,
      "z": 17,
      "name": "Rock_Shale"
    },
    {
      "x": -12,
      "y": 60,
      "z": 17,
      "name": "Rock_Shale"
    },
    {
      "x": -12,
      "y": 61,
      "z": 17,
      "name": "Rock_Shale"
    },
    {
      "x": -12,
      "y": 62,
      "z": 17,
      "name": "Rock_Shale"
    },
    {
      "x": -12,
      "y": 63,
      "z": 17,
      "name": "Rock_Basalt_Brick"
    },
    {
      "x": -12,
      "y": 64,
      "z": 17,
      "name": "Rock_Basalt_Brick"
    },
    {
      "x": -12,
      "y": 65,
      "z": 17,
      "name": "Rock_Basalt_Brick"
    },
    {
      "x": -12,
      "y": 66,
      "z": 17,
      "name": "Rock_Shale_Brick_Half",
      "rotation": 7
    },
    {
      "x": -12,
      "y": 67,
      "z": 17,
      "name": "Rock_Shale_Brick_Half",
      "rotation": 7
    },
    {
      "x": -12,
      "y": 69,
      "z": 17,
      "name": "Rock_Basalt_Brick_Smooth_Half",
      "rotation": 8
    },
    {
      "x": -12,
      "y": 70,
      "z": 17,
      "name": "Rock_Basalt_Cobble_Roof",
      "rotation": 3
    },
    {
      "x": -12,
      "y": 54,
      "z": 18,
      "name": "Rock_Shale"
    },
    {
      "x": -12,
      "y": 55,
      "z": 18,
      "name": "Rock_Shale"
    },
    {
      "x": -12,
      "y": 56,
      "z": 18,
      "name": "Rock_Shale"
    },
    {
      "x": -12,
      "y": 57,
      "z": 18,
      "name": "Rock_Shale"
    },
    {
      "x": -12,
      "y": 58,
      "z": 18,
      "name": "Rock_Shale"
    },
    {
      "x": -12,
      "y": 59,
      "z": 18,
      "name": "Rock_Shale"
    },
    {
      "x": -12,
      "y": 60,
      "z": 18,
      "name": "Rock_Shale"
    },
    {
      "x": -12,
      "y": 61,
      "z": 18,
      "name": "Rock_Shale"
    },
    {
      "x": -12,
      "y": 62,
      "z": 18,
      "name": "Rock_Shale"
    },
    {
      "x": -12,
      "y": 63,
      "z": 18,
      "name": "Rock_Basalt_Brick"
    },
    {
      "x": -12,
      "y": 64,
      "z": 18,
      "name": "Rock_Basalt_Brick"
    },
    {
      "x": -12,
      "y": 65,
      "z": 18,
      "name": "Rock_Basalt_Brick"
    },
    {
      "x": -12,
      "y": 66,
      "z": 18,
      "name": "Rock_Shale_Brick_Half",
      "rotation": 7
    },
    {
      "x": -12,
      "y": 67,
      "z": 18,
      "name": "Rock_Shale_Brick_Half",
      "rotation": 7
    },
    {
      "x": -12,
      "y": 69,
      "z": 18,
      "name": "Rock_Basalt_Brick_Smooth_Half",
      "rotation": 8
    },
    {
      "x": -12,
      "y": 70,
      "z": 18,
      "name": "Rock_Basalt_Cobble_Roof",
      "rotation": 3
    },
    {
      "x": -12,
      "y": 54,
      "z": 19,
      "name": "Rock_Shale"
    },
    {
      "x": -12,
      "y": 55,
      "z": 19,
      "name": "Rock_Shale"
    },
    {
      "x": -12,
      "y": 56,
      "z": 19,
      "name": "Rock_Shale"
    },
    {
      "x": -12,
      "y": 57,
      "z": 19,
      "name": "Rock_Shale"
    },
    {
      "x": -12,
      "y": 58,
      "z": 19,
      "name": "Rock_Shale"
    },
    {
      "x": -12,
      "y": 59,
      "z": 19,
      "name": "Rock_Shale"
    },
    {
      "x": -12,
      "y": 60,
      "z": 19,
      "name": "Rock_Shale"
    },
    {
      "x": -12,
      "y": 61,
      "z": 19,
      "name": "Rock_Shale"
    },
    {
      "x": -12,
      "y": 62,
      "z": 19,
      "name": "Rock_Shale"
    },
    {
      "x": -12,
      "y": 63,
      "z": 19,
      "name": "Rock_Basalt_Brick"
    },
    {
      "x": -12,
      "y": 64,
      "z": 19,
      "name": "Rock_Basalt_Brick"
    },
    {
      "x": -12,
      "y": 65,
      "z": 19,
      "name": "Rock_Basalt_Brick"
    },
    {
      "x": -12,
      "y": 66,
      "z": 19,
      "name": "Rock_Shale_Brick_Half",
      "rotation": 7
    },
    {
      "x": -12,
      "y": 67,
      "z": 19,
      "name": "Rock_Shale_Brick_Half",
      "rotation": 7
    },
    {
      "x": -12,
      "y": 69,
      "z": 19,
      "name": "Rock_Basalt_Brick_Smooth_Half",
      "rotation": 8
    },
    {
      "x": -12,
      "y": 70,
      "z": 19,
      "name": "Rock_Basalt_Cobble_Roof",
      "rotation": 3
    },
    {
      "x": -12,
      "y": 54,
      "z": 20,
      "name": "Rock_Shale"
    },
    {
      "x": -12,
      "y": 55,
      "z": 20,
      "name": "Rock_Shale"
    },
    {
      "x": -12,
      "y": 56,
      "z": 20,
      "name": "Rock_Shale"
    },
    {
      "x": -12,
      "y": 57,
      "z": 20,
      "name": "Rock_Shale"
    },
    {
      "x": -12,
      "y": 58,
      "z": 20,
      "name": "Rock_Shale"
    },
    {
      "x": -12,
      "y": 59,
      "z": 20,
      "name": "Rock_Shale"
    },
    {
      "x": -12,
      "y": 60,
      "z": 20,
      "name": "Rock_Shale"
    },
    {
      "x": -12,
      "y": 61,
      "z": 20,
      "name": "Rock_Shale"
    },
    {
      "x": -12,
      "y": 62,
      "z": 20,
      "name": "Rock_Basalt_Brick"
    },
    {
      "x": -12,
      "y": 63,
      "z": 20,
      "name": "Rock_Basalt_Brick"
    },
    {
      "x": -12,
      "y": 64,
      "z": 20,
      "name": "Rock_Basalt_Brick_Smooth"
    },
    {
      "x": -12,
      "y": 65,
      "z": 20,
      "name": "Rock_Basalt_Brick_Smooth"
    },
    {
      "x": -12,
      "y": 69,
      "z": 20,
      "name": "Rock_Basalt_Brick_Smooth"
    },
    {
      "x": -12,
      "y": 70,
      "z": 20,
      "name": "Soil_Snow"
    },
    {
      "x": -12,
      "y": 54,
      "z": 21,
      "name": "Rock_Shale"
    },
    {
      "x": -12,
      "y": 55,
      "z": 21,
      "name": "Rock_Shale"
    },
    {
      "x": -12,
      "y": 56,
      "z": 21,
      "name": "Rock_Shale"
    },
    {
      "x": -12,
      "y": 57,
      "z": 21,
      "name": "Rock_Shale"
    },
    {
      "x": -12,
      "y": 58,
      "z": 21,
      "name": "Rock_Shale"
    },
    {
      "x": -12,
      "y": 59,
      "z": 21,
      "name": "Rock_Shale"
    },
    {
      "x": -12,
      "y": 60,
      "z": 21,
      "name": "Rock_Shale"
    },
    {
      "x": -12,
      "y": 61,
      "z": 21,
      "name": "Rock_Shale"
    },
    {
      "x": -12,
      "y": 62,
      "z": 21,
      "name": "Rock_Basalt_Brick"
    },
    {
      "x": -12,
      "y": 63,
      "z": 21,
      "name": "Rock_Basalt_Brick"
    },
    {
      "x": -12,
      "y": 64,
      "z": 21,
      "name": "Rock_Basalt_Brick_Half",
      "rotation": 7
    },
    {
      "x": -12,
      "y": 65,
      "z": 21,
      "name": "Rock_Basalt_Brick_Half",
      "rotation": 7
    },
    {
      "x": -12,
      "y": 66,
      "z": 21,
      "name": "Rock_Shale_Brick_Half",
      "rotation": 7
    },
    {
      "x": -12,
      "y": 67,
      "z": 21,
      "name": "Rock_Shale_Brick_Half",
      "rotation": 7
    },
    {
      "x": -12,
      "y": 68,
      "z": 21,
      "name": "Rock_Ice_Icicles",
      "rotation": 8
    },
    {
      "x": -12,
      "y": 69,
      "z": 21,
      "name": "Rock_Ice"
    },
    {
      "x": -12,
      "y": 70,
      "z": 21,
      "name": "Soil_Snow"
    },
    {
      "x": -12,
      "y": 54,
      "z": 22,
      "name": "Rock_Shale"
    },
    {
      "x": -12,
      "y": 55,
      "z": 22,
      "name": "Rock_Shale"
    },
    {
      "x": -12,
      "y": 56,
      "z": 22,
      "name": "Rock_Shale"
    },
    {
      "x": -12,
      "y": 57,
      "z": 22,
      "name": "Rock_Shale"
    },
    {
      "x": -12,
      "y": 58,
      "z": 22,
      "name": "Rock_Shale"
    },
    {
      "x": -12,
      "y": 59,
      "z": 22,
      "name": "Rock_Shale"
    },
    {
      "x": -12,
      "y": 60,
      "z": 22,
      "name": "Rock_Shale"
    },
    {
      "x": -12,
      "y": 61,
      "z": 22,
      "name": "Rock_Shale"
    },
    {
      "x": -12,
      "y": 62,
      "z": 22,
      "name": "Rock_Basalt_Brick"
    },
    {
      "x": -12,
      "y": 63,
      "z": 22,
      "name": "Rock_Basalt_Brick"
    },
    {
      "x": -12,
      "y": 64,
      "z": 22,
      "name": "Rock_Basalt_Brick_Half",
      "rotation": 7
    },
    {
      "x": -12,
      "y": 65,
      "z": 22,
      "name": "Rock_Basalt_Brick_Half",
      "rotation": 7
    },
    {
      "x": -12,
      "y": 66,
      "z": 22,
      "name": "Rock_Shale_Brick_Half",
      "rotation": 7
    },
    {
      "x": -12,
      "y": 67,
      "z": 22,
      "name": "Rock_Shale_Brick_Half",
      "rotation": 7
    },
    {
      "x": -12,
      "y": 69,
      "z": 22,
      "name": "Rock_Ice"
    },
    {
      "x": -12,
      "y": 70,
      "z": 22,
      "name": "Soil_Snow"
    },
    {
      "x": -12,
      "y": 58,
      "z": 23,
      "name": "Rock_Shale"
    },
    {
      "x": -12,
      "y": 59,
      "z": 23,
      "name": "Rock_Shale"
    },
    {
      "x": -12,
      "y": 60,
      "z": 23,
      "name": "Rock_Shale"
    },
    {
      "x": -12,
      "y": 61,
      "z": 23,
      "name": "Rock_Shale"
    },
    {
      "x": -12,
      "y": 62,
      "z": 23,
      "name": "Rock_Basalt_Brick"
    },
    {
      "x": -12,
      "y": 63,
      "z": 23,
      "name": "Rock_Basalt_Brick"
    },
    {
      "x": -12,
      "y": 64,
      "z": 23,
      "name": "Rock_Basalt_Brick"
    },
    {
      "x": -12,
      "y": 65,
      "z": 23,
      "name": "Rock_Basalt_Brick"
    },
    {
      "x": -12,
      "y": 66,
      "z": 23,
      "name": "Rock_Shale_Brick_Half",
      "rotation": 7
    },
    {
      "x": -12,
      "y": 67,
      "z": 23,
      "name": "Rock_Shale_Brick_Half",
      "rotation": 7
    },
    {
      "x": -12,
      "y": 68,
      "z": 23,
      "name": "Rock_Ice_Icicles",
      "rotation": 8
    },
    {
      "x": -12,
      "y": 69,
      "z": 23,
      "name": "Rock_Ice"
    },
    {
      "x": -12,
      "y": 70,
      "z": 23,
      "name": "Soil_Snow"
    },
    {
      "x": -12,
      "y": 55,
      "z": 24,
      "name": "Rock_Shale"
    },
    {
      "x": -12,
      "y": 56,
      "z": 24,
      "name": "Rock_Shale"
    },
    {
      "x": -12,
      "y": 57,
      "z": 24,
      "name": "Rock_Shale"
    },
    {
      "x": -12,
      "y": 58,
      "z": 24,
      "name": "Rock_Shale"
    },
    {
      "x": -12,
      "y": 59,
      "z": 24,
      "name": "Rock_Shale"
    },
    {
      "x": -12,
      "y": 60,
      "z": 24,
      "name": "Rock_Shale"
    },
    {
      "x": -12,
      "y": 61,
      "z": 24,
      "name": "Rock_Shale"
    },
    {
      "x": -12,
      "y": 62,
      "z": 24,
      "name": "Rock_Basalt_Brick"
    },
    {
      "x": -12,
      "y": 63,
      "z": 24,
      "name": "Rock_Basalt_Brick"
    },
    {
      "x": -12,
      "y": 64,
      "z": 24,
      "name": "Rock_Basalt_Brick_Smooth"
    },
    {
      "x": -12,
      "y": 65,
      "z": 24,
      "name": "Rock_Basalt_Brick_Smooth"
    },
    {
      "x": -12,
      "y": 68,
      "z": 24,
      "name": "Rock_Ice_Icicles",
      "rotation": 8
    },
    {
      "x": -12,
      "y": 69,
      "z": 24,
      "name": "Rock_Ice"
    },
    {
      "x": -12,
      "y": 70,
      "z": 24,
      "name": "Soil_Snow"
    },
    {
      "x": -12,
      "y": 54,
      "z": 25,
      "name": "Rock_Shale"
    },
    {
      "x": -12,
      "y": 55,
      "z": 25,
      "name": "Rock_Shale"
    },
    {
      "x": -12,
      "y": 56,
      "z": 25,
      "name": "Rock_Shale"
    },
    {
      "x": -12,
      "y": 57,
      "z": 25,
      "name": "Rock_Shale"
    },
    {
      "x": -12,
      "y": 58,
      "z": 25,
      "name": "Rock_Shale"
    },
    {
      "x": -12,
      "y": 59,
      "z": 25,
      "name": "Rock_Shale"
    },
    {
      "x": -12,
      "y": 60,
      "z": 25,
      "name": "Rock_Shale"
    },
    {
      "x": -12,
      "y": 61,
      "z": 25,
      "name": "Rock_Shale"
    },
    {
      "x": -12,
      "y": 62,
      "z": 25,
      "name": "Rock_Basalt_Brick"
    },
    {
      "x": -12,
      "y": 63,
      "z": 25,
      "name": "Rock_Basalt_Brick"
    },
    {
      "x": -12,
      "y": 64,
      "z": 25,
      "name": "Rock_Basalt_Brick"
    },
    {
      "x": -12,
      "y": 65,
      "z": 25,
      "name": "Rock_Basalt_Brick"
    },
    {
      "x": -12,
      "y": 66,
      "z": 25,
      "name": "Rock_Shale_Brick_Half",
      "rotation": 7
    },
    {
      "x": -12,
      "y": 67,
      "z": 25,
      "name": "Rock_Shale_Brick_Half",
      "rotation": 7
    },
    {
      "x": -12,
      "y": 69,
      "z": 25,
      "name": "Rock_Basalt_Brick_Smooth_Half",
      "rotation": 8
    },
    {
      "x": -12,
      "y": 70,
      "z": 25,
      "name": "Soil_Snow"
    },
    {
      "x": -12,
      "y": 54,
      "z": 26,
      "name": "Rock_Shale"
    },
    {
      "x": -12,
      "y": 55,
      "z": 26,
      "name": "Rock_Shale"
    },
    {
      "x": -12,
      "y": 56,
      "z": 26,
      "name": "Rock_Shale"
    },
    {
      "x": -12,
      "y": 57,
      "z": 26,
      "name": "Rock_Shale"
    },
    {
      "x": -12,
      "y": 58,
      "z": 26,
      "name": "Rock_Shale"
    },
    {
      "x": -12,
      "y": 59,
      "z": 26,
      "name": "Rock_Shale"
    },
    {
      "x": -12,
      "y": 60,
      "z": 26,
      "name": "Rock_Shale"
    },
    {
      "x": -12,
      "y": 61,
      "z": 26,
      "name": "Rock_Shale"
    },
    {
      "x": -12,
      "y": 62,
      "z": 26,
      "name": "Rock_Basalt_Brick"
    },
    {
      "x": -12,
      "y": 63,
      "z": 26,
      "name": "Rock_Basalt_Brick"
    },
    {
      "x": -12,
      "y": 64,
      "z": 26,
      "name": "Rock_Basalt_Brick"
    },
    {
      "x": -12,
      "y": 65,
      "z": 26,
      "name": "Rock_Basalt_Brick"
    },
    {
      "x": -12,
      "y": 66,
      "z": 26,
      "name": "Rock_Shale_Brick_Half",
      "rotation": 7
    },
    {
      "x": -12,
      "y": 67,
      "z": 26,
      "name": "Rock_Shale_Brick_Half",
      "rotation": 7
    },
    {
      "x": -12,
      "y": 69,
      "z": 26,
      "name": "Rock_Basalt_Brick_Smooth_Half",
      "rotation": 8
    },
    {
      "x": -12,
      "y": 70,
      "z": 26,
      "name": "Soil_Snow"
    },
    {
      "x": -12,
      "y": 54,
      "z": 27,
      "name": "Rock_Shale"
    },
    {
      "x": -12,
      "y": 55,
      "z": 27,
      "name": "Rock_Shale"
    },
    {
      "x": -12,
      "y": 56,
      "z": 27,
      "name": "Rock_Shale"
    },
    {
      "x": -12,
      "y": 57,
      "z": 27,
      "name": "Rock_Shale"
    },
    {
      "x": -12,
      "y": 58,
      "z": 27,
      "name": "Rock_Shale"
    },
    {
      "x": -12,
      "y": 59,
      "z": 27,
      "name": "Rock_Shale"
    },
    {
      "x": -12,
      "y": 60,
      "z": 27,
      "name": "Rock_Shale"
    },
    {
      "x": -12,
      "y": 61,
      "z": 27,
      "name": "Rock_Shale"
    },
    {
      "x": -12,
      "y": 62,
      "z": 27,
      "name": "Rock_Basalt_Brick"
    },
    {
      "x": -12,
      "y": 63,
      "z": 27,
      "name": "Rock_Basalt_Brick"
    },
    {
      "x": -12,
      "y": 64,
      "z": 27,
      "name": "Rock_Basalt_Brick"
    },
    {
      "x": -12,
      "y": 65,
      "z": 27,
      "name": "Rock_Basalt_Brick"
    },
    {
      "x": -12,
      "y": 66,
      "z": 27,
      "name": "Rock_Shale_Brick_Half",
      "rotation": 7
    },
    {
      "x": -12,
      "y": 67,
      "z": 27,
      "name": "Rock_Shale_Brick_Half",
      "rotation": 7
    },
    {
      "x": -12,
      "y": 69,
      "z": 27,
      "name": "Rock_Basalt_Brick_Smooth_Half",
      "rotation": 8
    },
    {
      "x": -12,
      "y": 70,
      "z": 27,
      "name": "Rock_Basalt_Cobble_Roof",
      "rotation": 3
    },
    {
      "x": -12,
      "y": 54,
      "z": 28,
      "name": "Rock_Shale"
    },
    {
      "x": -12,
      "y": 55,
      "z": 28,
      "name": "Rock_Shale"
    },
    {
      "x": -12,
      "y": 56,
      "z": 28,
      "name": "Rock_Shale"
    },
    {
      "x": -12,
      "y": 57,
      "z": 28,
      "name": "Rock_Shale"
    },
    {
      "x": -12,
      "y": 58,
      "z": 28,
      "name": "Rock_Shale"
    },
    {
      "x": -12,
      "y": 59,
      "z": 28,
      "name": "Rock_Shale"
    },
    {
      "x": -12,
      "y": 60,
      "z": 28,
      "name": "Rock_Shale"
    },
    {
      "x": -12,
      "y": 61,
      "z": 28,
      "name": "Rock_Shale"
    },
    {
      "x": -12,
      "y": 62,
      "z": 28,
      "name": "Rock_Basalt_Brick"
    },
    {
      "x": -12,
      "y": 63,
      "z": 28,
      "name": "Rock_Basalt_Brick"
    },
    {
      "x": -12,
      "y": 64,
      "z": 28,
      "name": "Rock_Basalt_Brick"
    },
    {
      "x": -12,
      "y": 65,
      "z": 28,
      "name": "Rock_Basalt_Brick"
    },
    {
      "x": -12,
      "y": 66,
      "z": 28,
      "name": "Rock_Shale_Brick_Half",
      "rotation": 7
    },
    {
      "x": -12,
      "y": 67,
      "z": 28,
      "name": "Rock_Shale_Brick_Half",
      "rotation": 7
    },
    {
      "x": -12,
      "y": 69,
      "z": 28,
      "name": "Rock_Basalt_Brick_Smooth_Half",
      "rotation": 8
    },
    {
      "x": -12,
      "y": 70,
      "z": 28,
      "name": "Rock_Basalt_Cobble_Roof",
      "rotation": 3
    },
    {
      "x": -12,
      "y": 54,
      "z": 29,
      "name": "Rock_Shale"
    },
    {
      "x": -12,
      "y": 55,
      "z": 29,
      "name": "Rock_Shale"
    },
    {
      "x": -12,
      "y": 56,
      "z": 29,
      "name": "Rock_Shale"
    },
    {
      "x": -12,
      "y": 57,
      "z": 29,
      "name": "Rock_Shale"
    },
    {
      "x": -12,
      "y": 58,
      "z": 29,
      "name": "Rock_Shale"
    },
    {
      "x": -12,
      "y": 59,
      "z": 29,
      "name": "Rock_Shale"
    },
    {
      "x": -12,
      "y": 60,
      "z": 29,
      "name": "Rock_Shale"
    },
    {
      "x": -12,
      "y": 61,
      "z": 29,
      "name": "Rock_Shale"
    },
    {
      "x": -12,
      "y": 62,
      "z": 29,
      "name": "Rock_Basalt_Brick"
    },
    {
      "x": -12,
      "y": 63,
      "z": 29,
      "name": "Rock_Basalt_Brick"
    },
    {
      "x": -12,
      "y": 64,
      "z": 29,
      "name": "Rock_Basalt_Brick"
    },
    {
      "x": -12,
      "y": 65,
      "z": 29,
      "name": "Rock_Basalt_Brick"
    },
    {
      "x": -12,
      "y": 66,
      "z": 29,
      "name": "Rock_Basalt_Brick_Smooth_Half",
      "rotation": 7
    },
    {
      "x": -12,
      "y": 67,
      "z": 29,
      "name": "Rock_Basalt_Brick_Smooth_Half",
      "rotation": 7
    },
    {
      "x": -12,
      "y": 68,
      "z": 29,
      "name": "Rock_Basalt_Brick_Smooth_Half",
      "rotation": 7
    },
    {
      "x": -12,
      "y": 69,
      "z": 29,
      "name": "Rock_Basalt_Brick_Smooth"
    },
    {
      "x": -12,
      "y": 70,
      "z": 29,
      "name": "Rock_Basalt_Cobble_Roof",
      "rotation": 3
    },
    {
      "x": -12,
      "y": 54,
      "z": 30,
      "name": "Rock_Shale"
    },
    {
      "x": -12,
      "y": 55,
      "z": 30,
      "name": "Rock_Shale"
    },
    {
      "x": -12,
      "y": 56,
      "z": 30,
      "name": "Rock_Shale"
    },
    {
      "x": -12,
      "y": 57,
      "z": 30,
      "name": "Rock_Shale"
    },
    {
      "x": -12,
      "y": 58,
      "z": 30,
      "name": "Rock_Shale"
    },
    {
      "x": -12,
      "y": 59,
      "z": 30,
      "name": "Rock_Shale"
    },
    {
      "x": -12,
      "y": 60,
      "z": 30,
      "name": "Rock_Shale"
    },
    {
      "x": -12,
      "y": 61,
      "z": 30,
      "name": "Rock_Shale"
    },
    {
      "x": -12,
      "y": 62,
      "z": 30,
      "name": "Rock_Basalt_Brick"
    },
    {
      "x": -12,
      "y": 63,
      "z": 30,
      "name": "Rock_Basalt_Brick"
    },
    {
      "x": -12,
      "y": 64,
      "z": 30,
      "name": "Rock_Basalt_Brick_Smooth"
    },
    {
      "x": -12,
      "y": 65,
      "z": 30,
      "name": "Rock_Basalt_Brick_Smooth"
    },
    {
      "x": -12,
      "y": 66,
      "z": 30,
      "name": "Rock_Basalt_Brick_Smooth_Half"
    },
    {
      "x": -12,
      "y": 69,
      "z": 30,
      "name": "Rock_Basalt_Brick_Smooth_Half",
      "rotation": 8
    },
    {
      "x": -12,
      "y": 70,
      "z": 30,
      "name": "*Rock_Basalt_Cobble_Roof_State_Definitions_Corner_Right"
    },
    {
      "x": -12,
      "y": 54,
      "z": 31,
      "name": "Rock_Shale"
    },
    {
      "x": -12,
      "y": 55,
      "z": 31,
      "name": "Rock_Shale"
    },
    {
      "x": -12,
      "y": 56,
      "z": 31,
      "name": "Rock_Shale"
    },
    {
      "x": -12,
      "y": 57,
      "z": 31,
      "name": "Rock_Shale"
    },
    {
      "x": -12,
      "y": 58,
      "z": 31,
      "name": "Rock_Shale"
    },
    {
      "x": -12,
      "y": 59,
      "z": 31,
      "name": "Rock_Shale"
    },
    {
      "x": -12,
      "y": 60,
      "z": 31,
      "name": "Rock_Shale"
    },
    {
      "x": -12,
      "y": 61,
      "z": 31,
      "name": "Rock_Shale"
    },
    {
      "x": -12,
      "y": 62,
      "z": 31,
      "name": "Rock_Basalt_Brick_Smooth_Half",
      "rotation": 4
    },
    {
      "x": -12,
      "y": 63,
      "z": 31,
      "name": "Rock_Basalt_Brick_Smooth_Half",
      "rotation": 4
    },
    {
      "x": -11,
      "y": 54,
      "z": 5,
      "name": "Rock_Shale"
    },
    {
      "x": -11,
      "y": 55,
      "z": 5,
      "name": "Rock_Shale"
    },
    {
      "x": -11,
      "y": 56,
      "z": 5,
      "name": "Rock_Shale"
    },
    {
      "x": -11,
      "y": 57,
      "z": 5,
      "name": "Rock_Shale"
    },
    {
      "x": -11,
      "y": 58,
      "z": 5,
      "name": "Rock_Shale"
    },
    {
      "x": -11,
      "y": 59,
      "z": 5,
      "name": "Rock_Shale"
    },
    {
      "x": -11,
      "y": 60,
      "z": 5,
      "name": "Rock_Shale"
    },
    {
      "x": -11,
      "y": 61,
      "z": 5,
      "name": "Rock_Shale"
    },
    {
      "x": -11,
      "y": 62,
      "z": 5,
      "name": "Rock_Basalt_Brick_Half",
      "rotation": 6
    },
    {
      "x": -11,
      "y": 63,
      "z": 5,
      "name": "Rock_Basalt_Brick_Half",
      "rotation": 6
    },
    {
      "x": -11,
      "y": 54,
      "z": 6,
      "name": "Rock_Shale"
    },
    {
      "x": -11,
      "y": 55,
      "z": 6,
      "name": "Rock_Shale"
    },
    {
      "x": -11,
      "y": 56,
      "z": 6,
      "name": "Rock_Shale"
    },
    {
      "x": -11,
      "y": 57,
      "z": 6,
      "name": "Rock_Shale"
    },
    {
      "x": -11,
      "y": 58,
      "z": 6,
      "name": "Rock_Shale"
    },
    {
      "x": -11,
      "y": 59,
      "z": 6,
      "name": "Rock_Shale"
    },
    {
      "x": -11,
      "y": 60,
      "z": 6,
      "name": "Rock_Shale"
    },
    {
      "x": -11,
      "y": 61,
      "z": 6,
      "name": "Rock_Shale"
    },
    {
      "x": -11,
      "y": 62,
      "z": 6,
      "name": "Rock_Basalt_Brick"
    },
    {
      "x": -11,
      "y": 63,
      "z": 6,
      "name": "Rock_Basalt_Brick"
    },
    {
      "x": -11,
      "y": 64,
      "z": 6,
      "name": "Rock_Basalt_Brick"
    },
    {
      "x": -11,
      "y": 65,
      "z": 6,
      "name": "Rock_Basalt_Brick"
    },
    {
      "x": -11,
      "y": 66,
      "z": 6,
      "name": "Rock_Basalt_Brick_Smooth_Half",
      "rotation": 6
    },
    {
      "x": -11,
      "y": 67,
      "z": 6,
      "name": "Rock_Basalt_Brick_Smooth_Half",
      "rotation": 6
    },
    {
      "x": -11,
      "y": 68,
      "z": 6,
      "name": "Rock_Basalt_Brick_Smooth_Half",
      "rotation": 6
    },
    {
      "x": -11,
      "y": 69,
      "z": 6,
      "name": "Rock_Basalt_Brick_Smooth"
    },
    {
      "x": -11,
      "y": 70,
      "z": 6,
      "name": "Soil_Snow"
    },
    {
      "x": -11,
      "y": 54,
      "z": 7,
      "name": "Rock_Shale"
    },
    {
      "x": -11,
      "y": 55,
      "z": 7,
      "name": "Rock_Shale"
    },
    {
      "x": -11,
      "y": 56,
      "z": 7,
      "name": "Rock_Shale"
    },
    {
      "x": -11,
      "y": 57,
      "z": 7,
      "name": "Rock_Shale"
    },
    {
      "x": -11,
      "y": 58,
      "z": 7,
      "name": "Rock_Shale"
    },
    {
      "x": -11,
      "y": 59,
      "z": 7,
      "name": "Rock_Shale"
    },
    {
      "x": -11,
      "y": 60,
      "z": 7,
      "name": "Rock_Shale"
    },
    {
      "x": -11,
      "y": 61,
      "z": 7,
      "name": "Rock_Shale"
    },
    {
      "x": -11,
      "y": 62,
      "z": 7,
      "name": "Rock_Basalt_Brick"
    },
    {
      "x": -11,
      "y": 63,
      "z": 7,
      "name": "Rock_Basalt_Brick"
    },
    {
      "x": -11,
      "y": 64,
      "z": 7,
      "name": "Rock_Basalt_Brick"
    },
    {
      "x": -11,
      "y": 65,
      "z": 7,
      "name": "Rock_Basalt_Brick"
    },
    {
      "x": -11,
      "y": 66,
      "z": 7,
      "name": "Rock_Basalt_Brick_Smooth"
    },
    {
      "x": -11,
      "y": 67,
      "z": 7,
      "name": "Rock_Basalt_Brick_Smooth"
    },
    {
      "x": -11,
      "y": 68,
      "z": 7,
      "name": "Rock_Basalt_Brick_Smooth"
    },
    {
      "x": -11,
      "y": 69,
      "z": 7,
      "name": "Rock_Basalt_Brick_Smooth"
    },
    {
      "x": -11,
      "y": 70,
      "z": 7,
      "name": "Wood_Fir_Trunk",
      "rotation": 4
    },
    {
      "x": -11,
      "y": 71,
      "z": 7,
      "name": "Soil_Snow"
    },
    {
      "x": -11,
      "y": 54,
      "z": 8,
      "name": "Rock_Shale"
    },
    {
      "x": -11,
      "y": 55,
      "z": 8,
      "name": "Rock_Shale"
    },
    {
      "x": -11,
      "y": 56,
      "z": 8,
      "name": "Rock_Shale"
    },
    {
      "x": -11,
      "y": 57,
      "z": 8,
      "name": "Rock_Shale"
    },
    {
      "x": -11,
      "y": 58,
      "z": 8,
      "name": "Rock_Shale"
    },
    {
      "x": -11,
      "y": 59,
      "z": 8,
      "name": "Rock_Shale"
    },
    {
      "x": -11,
      "y": 60,
      "z": 8,
      "name": "Rock_Shale"
    },
    {
      "x": -11,
      "y": 61,
      "z": 8,
      "name": "Rock_Shale"
    },
    {
      "x": -11,
      "y": 62,
      "z": 8,
      "name": "Rock_Basalt_Brick"
    },
    {
      "x": -11,
      "y": 63,
      "z": 8,
      "name": "Rock_Basalt_Brick"
    },
    {
      "x": -11,
      "y": 64,
      "z": 8,
      "name": "Rock_Basalt_Brick"
    },
    {
      "x": -11,
      "y": 65,
      "z": 8,
      "name": "Rock_Basalt_Brick"
    },
    {
      "x": -11,
      "y": 66,
      "z": 8,
      "name": "Rock_Basalt_Brick_Smooth"
    },
    {
      "x": -11,
      "y": 67,
      "z": 8,
      "name": "Rock_Shale_Brick"
    },
    {
      "x": -11,
      "y": 68,
      "z": 8,
      "name": "Rock_Shale_Brick"
    },
    {
      "x": -11,
      "y": 69,
      "z": 8,
      "name": "Rock_Shale_Brick"
    },
    {
      "x": -11,
      "y": 70,
      "z": 8,
      "name": "Wood_Fir_Trunk",
      "rotation": 4
    },
    {
      "x": -11,
      "y": 71,
      "z": 8,
      "name": "Soil_Snow"
    },
    {
      "x": -11,
      "y": 54,
      "z": 9,
      "name": "Rock_Shale"
    },
    {
      "x": -11,
      "y": 55,
      "z": 9,
      "name": "Rock_Shale"
    },
    {
      "x": -11,
      "y": 56,
      "z": 9,
      "name": "Rock_Shale"
    },
    {
      "x": -11,
      "y": 57,
      "z": 9,
      "name": "Rock_Shale"
    },
    {
      "x": -11,
      "y": 58,
      "z": 9,
      "name": "Rock_Shale"
    },
    {
      "x": -11,
      "y": 59,
      "z": 9,
      "name": "Rock_Shale"
    },
    {
      "x": -11,
      "y": 60,
      "z": 9,
      "name": "Rock_Shale"
    },
    {
      "x": -11,
      "y": 61,
      "z": 9,
      "name": "Rock_Shale"
    },
    {
      "x": -11,
      "y": 62,
      "z": 9,
      "name": "Rock_Basalt_Brick"
    },
    {
      "x": -11,
      "y": 63,
      "z": 9,
      "name": "Rock_Basalt_Brick"
    },
    {
      "x": -11,
      "y": 64,
      "z": 9,
      "name": "Rock_Basalt_Brick"
    },
    {
      "x": -11,
      "y": 65,
      "z": 9,
      "name": "Rock_Basalt_Brick"
    },
    {
      "x": -11,
      "y": 66,
      "z": 9,
      "name": "Rock_Basalt_Brick_Smooth"
    },
    {
      "x": -11,
      "y": 67,
      "z": 9,
      "name": "Rock_Shale_Brick"
    },
    {
      "x": -11,
      "y": 68,
      "z": 9,
      "name": "Rock_Shale_Brick"
    },
    {
      "x": -11,
      "y": 69,
      "z": 9,
      "name": "Rock_Shale_Brick"
    },
    {
      "x": -11,
      "y": 70,
      "z": 9,
      "name": "Wood_Fir_Trunk",
      "rotation": 4
    },
    {
      "x": -11,
      "y": 71,
      "z": 9,
      "name": "Soil_Snow"
    },
    {
      "x": -11,
      "y": 54,
      "z": 10,
      "name": "Rock_Shale"
    },
    {
      "x": -11,
      "y": 55,
      "z": 10,
      "name": "Rock_Shale"
    },
    {
      "x": -11,
      "y": 56,
      "z": 10,
      "name": "Rock_Shale"
    },
    {
      "x": -11,
      "y": 57,
      "z": 10,
      "name": "Rock_Shale"
    },
    {
      "x": -11,
      "y": 58,
      "z": 10,
      "name": "Rock_Shale"
    },
    {
      "x": -11,
      "y": 59,
      "z": 10,
      "name": "Rock_Shale"
    },
    {
      "x": -11,
      "y": 60,
      "z": 10,
      "name": "Rock_Shale"
    },
    {
      "x": -11,
      "y": 61,
      "z": 10,
      "name": "Rock_Shale"
    },
    {
      "x": -11,
      "y": 62,
      "z": 10,
      "name": "Rock_Basalt_Brick"
    },
    {
      "x": -11,
      "y": 63,
      "z": 10,
      "name": "Rock_Basalt_Brick"
    },
    {
      "x": -11,
      "y": 64,
      "z": 10,
      "name": "Rock_Basalt_Brick"
    },
    {
      "x": -11,
      "y": 65,
      "z": 10,
      "name": "Rock_Basalt_Brick"
    },
    {
      "x": -11,
      "y": 66,
      "z": 10,
      "name": "Rock_Basalt_Brick_Smooth"
    },
    {
      "x": -11,
      "y": 67,
      "z": 10,
      "name": "Rock_Shale_Brick"
    },
    {
      "x": -11,
      "y": 68,
      "z": 10,
      "name": "Rock_Shale_Brick"
    },
    {
      "x": -11,
      "y": 69,
      "z": 10,
      "name": "Rock_Shale_Brick"
    },
    {
      "x": -11,
      "y": 70,
      "z": 10,
      "name": "Wood_Fir_Trunk",
      "rotation": 4
    },
    {
      "x": -11,
      "y": 71,
      "z": 10,
      "name": "Soil_Snow"
    },
    {
      "x": -11,
      "y": 54,
      "z": 11,
      "name": "Rock_Shale"
    },
    {
      "x": -11,
      "y": 55,
      "z": 11,
      "name": "Rock_Shale"
    },
    {
      "x": -11,
      "y": 56,
      "z": 11,
      "name": "Rock_Shale"
    },
    {
      "x": -11,
      "y": 57,
      "z": 11,
      "name": "Rock_Shale"
    },
    {
      "x": -11,
      "y": 58,
      "z": 11,
      "name": "Rock_Shale"
    },
    {
      "x": -11,
      "y": 59,
      "z": 11,
      "name": "Rock_Shale"
    },
    {
      "x": -11,
      "y": 60,
      "z": 11,
      "name": "Rock_Shale"
    },
    {
      "x": -11,
      "y": 61,
      "z": 11,
      "name": "Rock_Shale"
    },
    {
      "x": -11,
      "y": 62,
      "z": 11,
      "name": "Rock_Basalt_Brick"
    },
    {
      "x": -11,
      "y": 63,
      "z": 11,
      "name": "Rock_Basalt_Brick"
    },
    {
      "x": -11,
      "y": 64,
      "z": 11,
      "name": "Rock_Basalt_Brick"
    },
    {
      "x": -11,
      "y": 65,
      "z": 11,
      "name": "Rock_Basalt_Brick"
    },
    {
      "x": -11,
      "y": 66,
      "z": 11,
      "name": "Rock_Basalt_Brick_Smooth"
    },
    {
      "x": -11,
      "y": 67,
      "z": 11,
      "name": "Rock_Shale_Brick"
    },
    {
      "x": -11,
      "y": 68,
      "z": 11,
      "name": "Rock_Shale_Brick"
    },
    {
      "x": -11,
      "y": 69,
      "z": 11,
      "name": "Rock_Shale_Brick"
    },
    {
      "x": -11,
      "y": 70,
      "z": 11,
      "name": "Wood_Fir_Trunk",
      "rotation": 4
    },
    {
      "x": -11,
      "y": 71,
      "z": 11,
      "name": "Soil_Snow"
    },
    {
      "x": -11,
      "y": 54,
      "z": 12,
      "name": "Rock_Shale"
    },
    {
      "x": -11,
      "y": 55,
      "z": 12,
      "name": "Rock_Shale"
    },
    {
      "x": -11,
      "y": 56,
      "z": 12,
      "name": "Rock_Shale"
    },
    {
      "x": -11,
      "y": 57,
      "z": 12,
      "name": "Rock_Shale"
    },
    {
      "x": -11,
      "y": 58,
      "z": 12,
      "name": "Rock_Shale"
    },
    {
      "x": -11,
      "y": 59,
      "z": 12,
      "name": "Rock_Shale"
    },
    {
      "x": -11,
      "y": 60,
      "z": 12,
      "name": "Rock_Shale"
    },
    {
      "x": -11,
      "y": 61,
      "z": 12,
      "name": "Rock_Shale"
    },
    {
      "x": -11,
      "y": 62,
      "z": 12,
      "name": "Rock_Basalt_Brick"
    },
    {
      "x": -11,
      "y": 63,
      "z": 12,
      "name": "Rock_Basalt_Brick"
    },
    {
      "x": -11,
      "y": 64,
      "z": 12,
      "name": "Rock_Basalt_Brick"
    },
    {
      "x": -11,
      "y": 65,
      "z": 12,
      "name": "Rock_Basalt_Brick"
    },
    {
      "x": -11,
      "y": 66,
      "z": 12,
      "name": "Furniture_Temple_Dark_Window",
      "rotation": 1
    },
    {
      "x": -11,
      "y": 67,
      "z": 12,
      "name": "Furniture_Temple_Dark_Window",
      "rotation": 1
    },
    {
      "x": -11,
      "y": 68,
      "z": 12,
      "name": "Furniture_Temple_Dark_Window",
      "rotation": 1
    },
    {
      "x": -11,
      "y": 69,
      "z": 12,
      "name": "Rock_Shale_Brick"
    },
    {
      "x": -11,
      "y": 70,
      "z": 12,
      "name": "Wood_Fir_Trunk",
      "rotation": 4
    },
    {
      "x": -11,
      "y": 71,
      "z": 12,
      "name": "Soil_Snow"
    },
    {
      "x": -11,
      "y": 54,
      "z": 13,
      "name": "Rock_Shale"
    },
    {
      "x": -11,
      "y": 55,
      "z": 13,
      "name": "Rock_Shale"
    },
    {
      "x": -11,
      "y": 56,
      "z": 13,
      "name": "Rock_Shale"
    },
    {
      "x": -11,
      "y": 57,
      "z": 13,
      "name": "Rock_Shale"
    },
    {
      "x": -11,
      "y": 58,
      "z": 13,
      "name": "Rock_Shale"
    },
    {
      "x": -11,
      "y": 59,
      "z": 13,
      "name": "Rock_Shale"
    },
    {
      "x": -11,
      "y": 60,
      "z": 13,
      "name": "Rock_Shale"
    },
    {
      "x": -11,
      "y": 61,
      "z": 13,
      "name": "Rock_Shale"
    },
    {
      "x": -11,
      "y": 62,
      "z": 13,
      "name": "Rock_Basalt_Brick"
    },
    {
      "x": -11,
      "y": 63,
      "z": 13,
      "name": "Rock_Basalt_Brick"
    },
    {
      "x": -11,
      "y": 64,
      "z": 13,
      "name": "Rock_Basalt_Brick"
    },
    {
      "x": -11,
      "y": 65,
      "z": 13,
      "name": "Rock_Basalt_Brick"
    },
    {
      "x": -11,
      "y": 66,
      "z": 13,
      "name": "Rock_Basalt_Brick_Smooth"
    },
    {
      "x": -11,
      "y": 67,
      "z": 13,
      "name": "Rock_Shale_Brick"
    },
    {
      "x": -11,
      "y": 68,
      "z": 13,
      "name": "Rock_Shale_Brick"
    },
    {
      "x": -11,
      "y": 69,
      "z": 13,
      "name": "Rock_Shale_Brick"
    },
    {
      "x": -11,
      "y": 70,
      "z": 13,
      "name": "Wood_Fir_Trunk",
      "rotation": 4
    },
    {
      "x": -11,
      "y": 71,
      "z": 13,
      "name": "Rock_Basalt_Cobble_Roof",
      "rotation": 3
    },
    {
      "x": -11,
      "y": 54,
      "z": 14,
      "name": "Rock_Shale"
    },
    {
      "x": -11,
      "y": 55,
      "z": 14,
      "name": "Rock_Shale"
    },
    {
      "x": -11,
      "y": 56,
      "z": 14,
      "name": "Rock_Shale"
    },
    {
      "x": -11,
      "y": 57,
      "z": 14,
      "name": "Rock_Shale"
    },
    {
      "x": -11,
      "y": 58,
      "z": 14,
      "name": "Rock_Shale"
    },
    {
      "x": -11,
      "y": 59,
      "z": 14,
      "name": "Rock_Shale"
    },
    {
      "x": -11,
      "y": 60,
      "z": 14,
      "name": "Rock_Shale"
    },
    {
      "x": -11,
      "y": 61,
      "z": 14,
      "name": "Rock_Shale"
    },
    {
      "x": -11,
      "y": 62,
      "z": 14,
      "name": "Rock_Basalt_Brick"
    },
    {
      "x": -11,
      "y": 63,
      "z": 14,
      "name": "Rock_Basalt_Brick"
    },
    {
      "x": -11,
      "y": 64,
      "z": 14,
      "name": "Rock_Basalt_Brick"
    },
    {
      "x": -11,
      "y": 65,
      "z": 14,
      "name": "Rock_Basalt_Brick"
    },
    {
      "x": -11,
      "y": 66,
      "z": 14,
      "name": "Rock_Basalt_Brick_Smooth"
    },
    {
      "x": -11,
      "y": 67,
      "z": 14,
      "name": "Rock_Shale_Brick"
    },
    {
      "x": -11,
      "y": 68,
      "z": 14,
      "name": "Rock_Shale_Brick"
    },
    {
      "x": -11,
      "y": 69,
      "z": 14,
      "name": "Rock_Shale_Brick"
    },
    {
      "x": -11,
      "y": 70,
      "z": 14,
      "name": "Wood_Fir_Trunk",
      "rotation": 4
    },
    {
      "x": -11,
      "y": 71,
      "z": 14,
      "name": "Rock_Basalt_Cobble_Roof",
      "rotation": 3
    },
    {
      "x": -11,
      "y": 54,
      "z": 15,
      "name": "Rock_Shale"
    },
    {
      "x": -11,
      "y": 55,
      "z": 15,
      "name": "Rock_Shale"
    },
    {
      "x": -11,
      "y": 56,
      "z": 15,
      "name": "Rock_Shale"
    },
    {
      "x": -11,
      "y": 57,
      "z": 15,
      "name": "Rock_Shale"
    },
    {
      "x": -11,
      "y": 58,
      "z": 15,
      "name": "Rock_Shale"
    },
    {
      "x": -11,
      "y": 59,
      "z": 15,
      "name": "Rock_Shale"
    },
    {
      "x": -11,
      "y": 60,
      "z": 15,
      "name": "Rock_Shale"
    },
    {
      "x": -11,
      "y": 61,
      "z": 15,
      "name": "Rock_Shale"
    },
    {
      "x": -11,
      "y": 62,
      "z": 15,
      "name": "Rock_Basalt_Brick"
    },
    {
      "x": -11,
      "y": 63,
      "z": 15,
      "name": "Rock_Basalt_Brick"
    },
    {
      "x": -11,
      "y": 64,
      "z": 15,
      "name": "Rock_Basalt_Brick"
    },
    {
      "x": -11,
      "y": 65,
      "z": 15,
      "name": "Rock_Basalt_Brick"
    },
    {
      "x": -11,
      "y": 66,
      "z": 15,
      "name": "Rock_Basalt_Brick_Smooth"
    },
    {
      "x": -11,
      "y": 67,
      "z": 15,
      "name": "Rock_Shale_Brick"
    },
    {
      "x": -11,
      "y": 68,
      "z": 15,
      "name": "Rock_Shale_Brick"
    },
    {
      "x": -11,
      "y": 69,
      "z": 15,
      "name": "Rock_Shale_Brick"
    },
    {
      "x": -11,
      "y": 70,
      "z": 15,
      "name": "Wood_Fir_Trunk",
      "rotation": 4
    },
    {
      "x": -11,
      "y": 71,
      "z": 15,
      "name": "Rock_Basalt_Cobble_Roof",
      "rotation": 3
    },
    {
      "x": -11,
      "y": 54,
      "z": 16,
      "name": "Rock_Shale"
    },
    {
      "x": -11,
      "y": 55,
      "z": 16,
      "name": "Rock_Shale"
    },
    {
      "x": -11,
      "y": 56,
      "z": 16,
      "name": "Rock_Shale"
    },
    {
      "x": -11,
      "y": 57,
      "z": 16,
      "name": "Rock_Shale"
    },
    {
      "x": -11,
      "y": 58,
      "z": 16,
      "name": "Rock_Shale"
    },
    {
      "x": -11,
      "y": 59,
      "z": 16,
      "name": "Rock_Shale"
    },
    {
      "x": -11,
      "y": 60,
      "z": 16,
      "name": "Rock_Shale"
    },
    {
      "x": -11,
      "y": 61,
      "z": 16,
      "name": "Rock_Shale"
    },
    {
      "x": -11,
      "y": 62,
      "z": 16,
      "name": "Rock_Basalt_Brick"
    },
    {
      "x": -11,
      "y": 63,
      "z": 16,
      "name": "Rock_Basalt_Brick"
    },
    {
      "x": -11,
      "y": 64,
      "z": 16,
      "name": "Rock_Basalt_Brick"
    },
    {
      "x": -11,
      "y": 65,
      "z": 16,
      "name": "Rock_Basalt_Brick"
    },
    {
      "x": -11,
      "y": 66,
      "z": 16,
      "name": "Furniture_Temple_Dark_Window",
      "rotation": 1
    },
    {
      "x": -11,
      "y": 67,
      "z": 16,
      "name": "Furniture_Temple_Dark_Window",
      "rotation": 1
    },
    {
      "x": -11,
      "y": 68,
      "z": 16,
      "name": "Furniture_Temple_Dark_Window",
      "rotation": 1
    },
    {
      "x": -11,
      "y": 69,
      "z": 16,
      "name": "Rock_Shale_Brick"
    },
    {
      "x": -11,
      "y": 70,
      "z": 16,
      "name": "Wood_Fir_Trunk",
      "rotation": 4
    },
    {
      "x": -11,
      "y": 71,
      "z": 16,
      "name": "Rock_Basalt_Cobble_Roof",
      "rotation": 3
    },
    {
      "x": -11,
      "y": 54,
      "z": 17,
      "name": "Rock_Shale"
    },
    {
      "x": -11,
      "y": 55,
      "z": 17,
      "name": "Rock_Shale"
    },
    {
      "x": -11,
      "y": 56,
      "z": 17,
      "name": "Rock_Shale"
    },
    {
      "x": -11,
      "y": 57,
      "z": 17,
      "name": "Rock_Shale"
    },
    {
      "x": -11,
      "y": 58,
      "z": 17,
      "name": "Rock_Shale"
    },
    {
      "x": -11,
      "y": 59,
      "z": 17,
      "name": "Rock_Shale"
    },
    {
      "x": -11,
      "y": 60,
      "z": 17,
      "name": "Rock_Shale"
    },
    {
      "x": -11,
      "y": 61,
      "z": 17,
      "name": "Rock_Shale"
    },
    {
      "x": -11,
      "y": 62,
      "z": 17,
      "name": "Rock_Basalt_Brick"
    },
    {
      "x": -11,
      "y": 63,
      "z": 17,
      "name": "Rock_Basalt_Brick"
    },
    {
      "x": -11,
      "y": 64,
      "z": 17,
      "name": "Rock_Basalt_Brick"
    },
    {
      "x": -11,
      "y": 65,
      "z": 17,
      "name": "Rock_Basalt_Brick"
    },
    {
      "x": -11,
      "y": 66,
      "z": 17,
      "name": "Rock_Basalt_Brick_Smooth"
    },
    {
      "x": -11,
      "y": 67,
      "z": 17,
      "name": "Rock_Shale_Brick"
    },
    {
      "x": -11,
      "y": 68,
      "z": 17,
      "name": "Rock_Shale_Brick"
    },
    {
      "x": -11,
      "y": 69,
      "z": 17,
      "name": "Rock_Shale_Brick"
    },
    {
      "x": -11,
      "y": 70,
      "z": 17,
      "name": "Wood_Fir_Trunk",
      "rotation": 4
    },
    {
      "x": -11,
      "y": 71,
      "z": 17,
      "name": "Rock_Basalt_Cobble_Roof",
      "rotation": 3
    },
    {
      "x": -11,
      "y": 54,
      "z": 18,
      "name": "Rock_Shale"
    },
    {
      "x": -11,
      "y": 55,
      "z": 18,
      "name": "Rock_Shale"
    },
    {
      "x": -11,
      "y": 56,
      "z": 18,
      "name": "Rock_Shale"
    },
    {
      "x": -11,
      "y": 57,
      "z": 18,
      "name": "Rock_Shale"
    },
    {
      "x": -11,
      "y": 58,
      "z": 18,
      "name": "Rock_Shale"
    },
    {
      "x": -11,
      "y": 59,
      "z": 18,
      "name": "Rock_Shale"
    },
    {
      "x": -11,
      "y": 60,
      "z": 18,
      "name": "Rock_Shale"
    },
    {
      "x": -11,
      "y": 61,
      "z": 18,
      "name": "Rock_Shale"
    },
    {
      "x": -11,
      "y": 62,
      "z": 18,
      "name": "Rock_Basalt_Brick"
    },
    {
      "x": -11,
      "y": 63,
      "z": 18,
      "name": "Rock_Basalt_Brick"
    },
    {
      "x": -11,
      "y": 64,
      "z": 18,
      "name": "Rock_Basalt_Brick"
    },
    {
      "x": -11,
      "y": 65,
      "z": 18,
      "name": "Rock_Basalt_Brick"
    },
    {
      "x": -11,
      "y": 66,
      "z": 18,
      "name": "Rock_Basalt_Brick_Smooth"
    },
    {
      "x": -11,
      "y": 67,
      "z": 18,
      "name": "Rock_Shale_Brick"
    },
    {
      "x": -11,
      "y": 68,
      "z": 18,
      "name": "Rock_Shale_Brick"
    },
    {
      "x": -11,
      "y": 69,
      "z": 18,
      "name": "Rock_Shale_Brick"
    },
    {
      "x": -11,
      "y": 70,
      "z": 18,
      "name": "Wood_Fir_Trunk",
      "rotation": 4
    },
    {
      "x": -11,
      "y": 71,
      "z": 18,
      "name": "Rock_Basalt_Cobble_Roof",
      "rotation": 3
    },
    {
      "x": -11,
      "y": 54,
      "z": 19,
      "name": "Rock_Shale"
    },
    {
      "x": -11,
      "y": 55,
      "z": 19,
      "name": "Rock_Shale"
    },
    {
      "x": -11,
      "y": 56,
      "z": 19,
      "name": "Rock_Shale"
    },
    {
      "x": -11,
      "y": 57,
      "z": 19,
      "name": "Rock_Shale"
    },
    {
      "x": -11,
      "y": 58,
      "z": 19,
      "name": "Rock_Shale"
    },
    {
      "x": -11,
      "y": 59,
      "z": 19,
      "name": "Rock_Shale"
    },
    {
      "x": -11,
      "y": 60,
      "z": 19,
      "name": "Rock_Shale"
    },
    {
      "x": -11,
      "y": 61,
      "z": 19,
      "name": "Rock_Shale"
    },
    {
      "x": -11,
      "y": 62,
      "z": 19,
      "name": "Rock_Basalt_Brick"
    },
    {
      "x": -11,
      "y": 63,
      "z": 19,
      "name": "Rock_Basalt_Brick"
    },
    {
      "x": -11,
      "y": 64,
      "z": 19,
      "name": "Rock_Basalt_Brick"
    },
    {
      "x": -11,
      "y": 65,
      "z": 19,
      "name": "Rock_Basalt_Brick"
    },
    {
      "x": -11,
      "y": 66,
      "z": 19,
      "name": "Rock_Basalt_Brick_Smooth"
    },
    {
      "x": -11,
      "y": 67,
      "z": 19,
      "name": "Rock_Shale_Brick"
    },
    {
      "x": -11,
      "y": 68,
      "z": 19,
      "name": "Rock_Shale_Brick"
    },
    {
      "x": -11,
      "y": 69,
      "z": 19,
      "name": "Rock_Shale_Brick"
    },
    {
      "x": -11,
      "y": 70,
      "z": 19,
      "name": "Wood_Fir_Trunk",
      "rotation": 4
    },
    {
      "x": -11,
      "y": 71,
      "z": 19,
      "name": "Soil_Snow"
    },
    {
      "x": -11,
      "y": 54,
      "z": 20,
      "name": "Rock_Shale"
    },
    {
      "x": -11,
      "y": 55,
      "z": 20,
      "name": "Rock_Shale"
    },
    {
      "x": -11,
      "y": 56,
      "z": 20,
      "name": "Rock_Shale"
    },
    {
      "x": -11,
      "y": 57,
      "z": 20,
      "name": "Rock_Shale"
    },
    {
      "x": -11,
      "y": 58,
      "z": 20,
      "name": "Rock_Shale"
    },
    {
      "x": -11,
      "y": 59,
      "z": 20,
      "name": "Rock_Shale"
    },
    {
      "x": -11,
      "y": 60,
      "z": 20,
      "name": "Rock_Shale"
    },
    {
      "x": -11,
      "y": 61,
      "z": 20,
      "name": "Rock_Shale"
    },
    {
      "x": -11,
      "y": 62,
      "z": 20,
      "name": "Rock_Basalt_Brick"
    },
    {
      "x": -11,
      "y": 63,
      "z": 20,
      "name": "Rock_Basalt_Brick"
    },
    {
      "x": -11,
      "y": 64,
      "z": 20,
      "name": "Rock_Basalt_Brick"
    },
    {
      "x": -11,
      "y": 65,
      "z": 20,
      "name": "Rock_Basalt_Brick"
    },
    {
      "x": -11,
      "y": 66,
      "z": 20,
      "name": "Furniture_Temple_Dark_Window",
      "rotation": 1
    },
    {
      "x": -11,
      "y": 67,
      "z": 20,
      "name": "Furniture_Temple_Dark_Window",
      "rotation": 1
    },
    {
      "x": -11,
      "y": 68,
      "z": 20,
      "name": "Furniture_Temple_Dark_Window",
      "rotation": 1
    },
    {
      "x": -11,
      "y": 69,
      "z": 20,
      "name": "Rock_Shale_Brick"
    },
    {
      "x": -11,
      "y": 70,
      "z": 20,
      "name": "Wood_Fir_Trunk",
      "rotation": 4
    },
    {
      "x": -11,
      "y": 71,
      "z": 20,
      "name": "Soil_Snow"
    },
    {
      "x": -11,
      "y": 54,
      "z": 21,
      "name": "Rock_Shale"
    },
    {
      "x": -11,
      "y": 55,
      "z": 21,
      "name": "Rock_Shale"
    },
    {
      "x": -11,
      "y": 56,
      "z": 21,
      "name": "Rock_Shale"
    },
    {
      "x": -11,
      "y": 57,
      "z": 21,
      "name": "Rock_Shale"
    },
    {
      "x": -11,
      "y": 58,
      "z": 21,
      "name": "Rock_Shale"
    },
    {
      "x": -11,
      "y": 59,
      "z": 21,
      "name": "Rock_Shale"
    },
    {
      "x": -11,
      "y": 60,
      "z": 21,
      "name": "Rock_Shale"
    },
    {
      "x": -11,
      "y": 61,
      "z": 21,
      "name": "Rock_Shale"
    },
    {
      "x": -11,
      "y": 62,
      "z": 21,
      "name": "Rock_Basalt_Brick"
    },
    {
      "x": -11,
      "y": 63,
      "z": 21,
      "name": "Rock_Basalt_Brick"
    },
    {
      "x": -11,
      "y": 64,
      "z": 21,
      "name": "Rock_Basalt_Brick"
    },
    {
      "x": -11,
      "y": 65,
      "z": 21,
      "name": "Rock_Basalt_Brick"
    },
    {
      "x": -11,
      "y": 66,
      "z": 21,
      "name": "Rock_Basalt_Brick_Smooth"
    },
    {
      "x": -11,
      "y": 67,
      "z": 21,
      "name": "Rock_Shale_Brick"
    },
    {
      "x": -11,
      "y": 68,
      "z": 21,
      "name": "Rock_Shale_Brick"
    },
    {
      "x": -11,
      "y": 69,
      "z": 21,
      "name": "Rock_Shale_Brick"
    },
    {
      "x": -11,
      "y": 70,
      "z": 21,
      "name": "Wood_Fir_Trunk",
      "rotation": 4
    },
    {
      "x": -11,
      "y": 71,
      "z": 21,
      "name": "Soil_Snow"
    },
    {
      "x": -11,
      "y": 54,
      "z": 22,
      "name": "Rock_Shale"
    },
    {
      "x": -11,
      "y": 55,
      "z": 22,
      "name": "Rock_Shale"
    },
    {
      "x": -11,
      "y": 56,
      "z": 22,
      "name": "Rock_Shale"
    },
    {
      "x": -11,
      "y": 57,
      "z": 22,
      "name": "Rock_Shale"
    },
    {
      "x": -11,
      "y": 58,
      "z": 22,
      "name": "Rock_Shale"
    },
    {
      "x": -11,
      "y": 59,
      "z": 22,
      "name": "Rock_Shale"
    },
    {
      "x": -11,
      "y": 60,
      "z": 22,
      "name": "Rock_Shale"
    },
    {
      "x": -11,
      "y": 61,
      "z": 22,
      "name": "Rock_Shale"
    },
    {
      "x": -11,
      "y": 62,
      "z": 22,
      "name": "Rock_Basalt_Brick"
    },
    {
      "x": -11,
      "y": 63,
      "z": 22,
      "name": "Rock_Basalt_Brick"
    },
    {
      "x": -11,
      "y": 64,
      "z": 22,
      "name": "Rock_Basalt_Brick"
    },
    {
      "x": -11,
      "y": 65,
      "z": 22,
      "name": "Rock_Basalt_Brick"
    },
    {
      "x": -11,
      "y": 66,
      "z": 22,
      "name": "Rock_Basalt_Brick_Smooth"
    },
    {
      "x": -11,
      "y": 67,
      "z": 22,
      "name": "Rock_Shale_Brick"
    },
    {
      "x": -11,
      "y": 68,
      "z": 22,
      "name": "Rock_Shale_Brick"
    },
    {
      "x": -11,
      "y": 69,
      "z": 22,
      "name": "Rock_Shale_Brick"
    },
    {
      "x": -11,
      "y": 70,
      "z": 22,
      "name": "Wood_Fir_Trunk",
      "rotation": 4
    },
    {
      "x": -11,
      "y": 71,
      "z": 22,
      "name": "Soil_Snow"
    },
    {
      "x": -11,
      "y": 54,
      "z": 23,
      "name": "Rock_Shale"
    },
    {
      "x": -11,
      "y": 55,
      "z": 23,
      "name": "Rock_Shale"
    },
    {
      "x": -11,
      "y": 56,
      "z": 23,
      "name": "Rock_Shale"
    },
    {
      "x": -11,
      "y": 57,
      "z": 23,
      "name": "Rock_Shale"
    },
    {
      "x": -11,
      "y": 58,
      "z": 23,
      "name": "Rock_Shale"
    },
    {
      "x": -11,
      "y": 59,
      "z": 23,
      "name": "Rock_Shale"
    },
    {
      "x": -11,
      "y": 60,
      "z": 23,
      "name": "Rock_Shale"
    },
    {
      "x": -11,
      "y": 61,
      "z": 23,
      "name": "Rock_Shale"
    },
    {
      "x": -11,
      "y": 62,
      "z": 23,
      "name": "Rock_Basalt_Brick"
    },
    {
      "x": -11,
      "y": 63,
      "z": 23,
      "name": "Rock_Basalt_Brick"
    },
    {
      "x": -11,
      "y": 64,
      "z": 23,
      "name": "Rock_Basalt_Brick"
    },
    {
      "x": -11,
      "y": 65,
      "z": 23,
      "name": "Rock_Basalt_Brick"
    },
    {
      "x": -11,
      "y": 66,
      "z": 23,
      "name": "Rock_Basalt_Brick_Smooth"
    },
    {
      "x": -11,
      "y": 67,
      "z": 23,
      "name": "Rock_Shale_Brick"
    },
    {
      "x": -11,
      "y": 68,
      "z": 23,
      "name": "Rock_Shale_Brick"
    },
    {
      "x": -11,
      "y": 69,
      "z": 23,
      "name": "Rock_Shale_Brick"
    },
    {
      "x": -11,
      "y": 70,
      "z": 23,
      "name": "Wood_Fir_Trunk",
      "rotation": 4
    },
    {
      "x": -11,
      "y": 71,
      "z": 23,
      "name": "Soil_Snow"
    },
    {
      "x": -11,
      "y": 55,
      "z": 24,
      "name": "Rock_Shale"
    },
    {
      "x": -11,
      "y": 56,
      "z": 24,
      "name": "Rock_Shale"
    },
    {
      "x": -11,
      "y": 57,
      "z": 24,
      "name": "Rock_Shale"
    },
    {
      "x": -11,
      "y": 58,
      "z": 24,
      "name": "Rock_Shale"
    },
    {
      "x": -11,
      "y": 59,
      "z": 24,
      "name": "Rock_Shale"
    },
    {
      "x": -11,
      "y": 60,
      "z": 24,
      "name": "Rock_Shale"
    },
    {
      "x": -11,
      "y": 61,
      "z": 24,
      "name": "Rock_Shale"
    },
    {
      "x": -11,
      "y": 62,
      "z": 24,
      "name": "Rock_Basalt_Brick"
    },
    {
      "x": -11,
      "y": 63,
      "z": 24,
      "name": "Rock_Basalt_Brick"
    },
    {
      "x": -11,
      "y": 64,
      "z": 24,
      "name": "Rock_Basalt_Brick"
    },
    {
      "x": -11,
      "y": 65,
      "z": 24,
      "name": "Rock_Basalt_Brick"
    },
    {
      "x": -11,
      "y": 66,
      "z": 24,
      "name": "Furniture_Temple_Dark_Window",
      "rotation": 1
    },
    {
      "x": -11,
      "y": 67,
      "z": 24,
      "name": "Furniture_Temple_Dark_Window",
      "rotation": 1
    },
    {
      "x": -11,
      "y": 68,
      "z": 24,
      "name": "Furniture_Temple_Dark_Window",
      "rotation": 1
    },
    {
      "x": -11,
      "y": 69,
      "z": 24,
      "name": "Rock_Shale_Brick"
    },
    {
      "x": -11,
      "y": 70,
      "z": 24,
      "name": "Wood_Fir_Trunk",
      "rotation": 4
    },
    {
      "x": -11,
      "y": 71,
      "z": 24,
      "name": "Soil_Snow"
    },
    {
      "x": -11,
      "y": 54,
      "z": 25,
      "name": "Rock_Shale"
    },
    {
      "x": -11,
      "y": 55,
      "z": 25,
      "name": "Rock_Shale"
    },
    {
      "x": -11,
      "y": 56,
      "z": 25,
      "name": "Rock_Shale"
    },
    {
      "x": -11,
      "y": 57,
      "z": 25,
      "name": "Rock_Shale"
    },
    {
      "x": -11,
      "y": 58,
      "z": 25,
      "name": "Rock_Shale"
    },
    {
      "x": -11,
      "y": 59,
      "z": 25,
      "name": "Rock_Shale"
    },
    {
      "x": -11,
      "y": 60,
      "z": 25,
      "name": "Rock_Shale"
    },
    {
      "x": -11,
      "y": 61,
      "z": 25,
      "name": "Rock_Shale"
    },
    {
      "x": -11,
      "y": 62,
      "z": 25,
      "name": "Rock_Basalt_Brick"
    },
    {
      "x": -11,
      "y": 63,
      "z": 25,
      "name": "Rock_Basalt_Brick"
    },
    {
      "x": -11,
      "y": 64,
      "z": 25,
      "name": "Rock_Basalt_Brick"
    },
    {
      "x": -11,
      "y": 65,
      "z": 25,
      "name": "Rock_Basalt_Brick"
    },
    {
      "x": -11,
      "y": 66,
      "z": 25,
      "name": "Rock_Basalt_Brick_Smooth"
    },
    {
      "x": -11,
      "y": 67,
      "z": 25,
      "name": "Rock_Shale_Brick"
    },
    {
      "x": -11,
      "y": 68,
      "z": 25,
      "name": "Rock_Shale_Brick"
    },
    {
      "x": -11,
      "y": 69,
      "z": 25,
      "name": "Rock_Shale_Brick"
    },
    {
      "x": -11,
      "y": 70,
      "z": 25,
      "name": "Wood_Fir_Trunk",
      "rotation": 4
    },
    {
      "x": -11,
      "y": 71,
      "z": 25,
      "name": "Rock_Basalt_Cobble_Roof",
      "rotation": 3
    },
    {
      "x": -11,
      "y": 54,
      "z": 26,
      "name": "Rock_Shale"
    },
    {
      "x": -11,
      "y": 55,
      "z": 26,
      "name": "Rock_Shale"
    },
    {
      "x": -11,
      "y": 56,
      "z": 26,
      "name": "Rock_Shale"
    },
    {
      "x": -11,
      "y": 57,
      "z": 26,
      "name": "Rock_Shale"
    },
    {
      "x": -11,
      "y": 58,
      "z": 26,
      "name": "Rock_Shale"
    },
    {
      "x": -11,
      "y": 59,
      "z": 26,
      "name": "Rock_Shale"
    },
    {
      "x": -11,
      "y": 60,
      "z": 26,
      "name": "Rock_Shale"
    },
    {
      "x": -11,
      "y": 61,
      "z": 26,
      "name": "Rock_Shale"
    },
    {
      "x": -11,
      "y": 62,
      "z": 26,
      "name": "Rock_Basalt_Brick"
    },
    {
      "x": -11,
      "y": 63,
      "z": 26,
      "name": "Rock_Basalt_Brick"
    },
    {
      "x": -11,
      "y": 64,
      "z": 26,
      "name": "Rock_Basalt_Brick"
    },
    {
      "x": -11,
      "y": 65,
      "z": 26,
      "name": "Rock_Basalt_Brick"
    },
    {
      "x": -11,
      "y": 66,
      "z": 26,
      "name": "Rock_Basalt_Brick_Smooth"
    },
    {
      "x": -11,
      "y": 67,
      "z": 26,
      "name": "Rock_Shale_Brick"
    },
    {
      "x": -11,
      "y": 68,
      "z": 26,
      "name": "Rock_Shale_Brick"
    },
    {
      "x": -11,
      "y": 69,
      "z": 26,
      "name": "Rock_Shale_Brick"
    },
    {
      "x": -11,
      "y": 70,
      "z": 26,
      "name": "Wood_Fir_Trunk",
      "rotation": 4
    },
    {
      "x": -11,
      "y": 71,
      "z": 26,
      "name": "Rock_Basalt_Cobble_Roof",
      "rotation": 3
    },
    {
      "x": -11,
      "y": 54,
      "z": 27,
      "name": "Rock_Shale"
    },
    {
      "x": -11,
      "y": 55,
      "z": 27,
      "name": "Rock_Shale"
    },
    {
      "x": -11,
      "y": 56,
      "z": 27,
      "name": "Rock_Shale"
    },
    {
      "x": -11,
      "y": 57,
      "z": 27,
      "name": "Rock_Shale"
    },
    {
      "x": -11,
      "y": 58,
      "z": 27,
      "name": "Rock_Shale"
    },
    {
      "x": -11,
      "y": 59,
      "z": 27,
      "name": "Rock_Shale"
    },
    {
      "x": -11,
      "y": 60,
      "z": 27,
      "name": "Rock_Shale"
    },
    {
      "x": -11,
      "y": 61,
      "z": 27,
      "name": "Rock_Shale"
    },
    {
      "x": -11,
      "y": 62,
      "z": 27,
      "name": "Rock_Basalt_Brick"
    },
    {
      "x": -11,
      "y": 63,
      "z": 27,
      "name": "Rock_Basalt_Brick"
    },
    {
      "x": -11,
      "y": 64,
      "z": 27,
      "name": "Rock_Basalt_Brick"
    },
    {
      "x": -11,
      "y": 65,
      "z": 27,
      "name": "Rock_Basalt_Brick"
    },
    {
      "x": -11,
      "y": 66,
      "z": 27,
      "name": "Rock_Basalt_Brick_Smooth"
    },
    {
      "x": -11,
      "y": 67,
      "z": 27,
      "name": "Rock_Shale_Brick"
    },
    {
      "x": -11,
      "y": 68,
      "z": 27,
      "name": "Rock_Shale_Brick"
    },
    {
      "x": -11,
      "y": 69,
      "z": 27,
      "name": "Rock_Shale_Brick"
    },
    {
      "x": -11,
      "y": 70,
      "z": 27,
      "name": "Wood_Fir_Trunk",
      "rotation": 4
    },
    {
      "x": -11,
      "y": 71,
      "z": 27,
      "name": "Rock_Basalt_Cobble_Roof",
      "rotation": 3
    },
    {
      "x": -11,
      "y": 54,
      "z": 28,
      "name": "Rock_Shale"
    },
    {
      "x": -11,
      "y": 55,
      "z": 28,
      "name": "Rock_Shale"
    },
    {
      "x": -11,
      "y": 56,
      "z": 28,
      "name": "Rock_Shale"
    },
    {
      "x": -11,
      "y": 57,
      "z": 28,
      "name": "Rock_Shale"
    },
    {
      "x": -11,
      "y": 58,
      "z": 28,
      "name": "Rock_Shale"
    },
    {
      "x": -11,
      "y": 59,
      "z": 28,
      "name": "Rock_Shale"
    },
    {
      "x": -11,
      "y": 60,
      "z": 28,
      "name": "Rock_Shale"
    },
    {
      "x": -11,
      "y": 61,
      "z": 28,
      "name": "Rock_Shale"
    },
    {
      "x": -11,
      "y": 62,
      "z": 28,
      "name": "Rock_Basalt_Brick"
    },
    {
      "x": -11,
      "y": 63,
      "z": 28,
      "name": "Rock_Basalt_Brick"
    },
    {
      "x": -11,
      "y": 64,
      "z": 28,
      "name": "Rock_Basalt_Brick"
    },
    {
      "x": -11,
      "y": 65,
      "z": 28,
      "name": "Rock_Basalt_Brick"
    },
    {
      "x": -11,
      "y": 66,
      "z": 28,
      "name": "Rock_Basalt_Brick_Smooth"
    },
    {
      "x": -11,
      "y": 67,
      "z": 28,
      "name": "Rock_Shale_Brick"
    },
    {
      "x": -11,
      "y": 68,
      "z": 28,
      "name": "Rock_Shale_Brick"
    },
    {
      "x": -11,
      "y": 69,
      "z": 28,
      "name": "Rock_Shale_Brick"
    },
    {
      "x": -11,
      "y": 70,
      "z": 28,
      "name": "Wood_Fir_Trunk",
      "rotation": 4
    },
    {
      "x": -11,
      "y": 71,
      "z": 28,
      "name": "Soil_Snow"
    },
    {
      "x": -11,
      "y": 54,
      "z": 29,
      "name": "Rock_Shale"
    },
    {
      "x": -11,
      "y": 55,
      "z": 29,
      "name": "Rock_Shale"
    },
    {
      "x": -11,
      "y": 56,
      "z": 29,
      "name": "Rock_Shale"
    },
    {
      "x": -11,
      "y": 57,
      "z": 29,
      "name": "Rock_Shale"
    },
    {
      "x": -11,
      "y": 58,
      "z": 29,
      "name": "Rock_Shale"
    },
    {
      "x": -11,
      "y": 59,
      "z": 29,
      "name": "Rock_Shale"
    },
    {
      "x": -11,
      "y": 60,
      "z": 29,
      "name": "Rock_Shale"
    },
    {
      "x": -11,
      "y": 61,
      "z": 29,
      "name": "Rock_Shale"
    },
    {
      "x": -11,
      "y": 62,
      "z": 29,
      "name": "Rock_Basalt_Brick"
    },
    {
      "x": -11,
      "y": 63,
      "z": 29,
      "name": "Rock_Basalt_Brick"
    },
    {
      "x": -11,
      "y": 64,
      "z": 29,
      "name": "Rock_Basalt_Brick"
    },
    {
      "x": -11,
      "y": 65,
      "z": 29,
      "name": "Rock_Basalt_Brick"
    },
    {
      "x": -11,
      "y": 66,
      "z": 29,
      "name": "Rock_Basalt_Brick_Smooth"
    },
    {
      "x": -11,
      "y": 67,
      "z": 29,
      "name": "Rock_Basalt_Brick_Smooth"
    },
    {
      "x": -11,
      "y": 68,
      "z": 29,
      "name": "Rock_Basalt_Brick_Smooth"
    },
    {
      "x": -11,
      "y": 69,
      "z": 29,
      "name": "Rock_Basalt_Brick_Smooth"
    },
    {
      "x": -11,
      "y": 70,
      "z": 29,
      "name": "Wood_Fir_Trunk",
      "rotation": 5
    },
    {
      "x": -11,
      "y": 71,
      "z": 29,
      "name": "Soil_Snow"
    },
    {
      "x": -11,
      "y": 54,
      "z": 30,
      "name": "Rock_Shale"
    },
    {
      "x": -11,
      "y": 55,
      "z": 30,
      "name": "Rock_Shale"
    },
    {
      "x": -11,
      "y": 56,
      "z": 30,
      "name": "Rock_Shale"
    },
    {
      "x": -11,
      "y": 57,
      "z": 30,
      "name": "Rock_Shale"
    },
    {
      "x": -11,
      "y": 58,
      "z": 30,
      "name": "Rock_Shale"
    },
    {
      "x": -11,
      "y": 59,
      "z": 30,
      "name": "Rock_Shale"
    },
    {
      "x": -11,
      "y": 60,
      "z": 30,
      "name": "Rock_Shale"
    },
    {
      "x": -11,
      "y": 61,
      "z": 30,
      "name": "Rock_Shale"
    },
    {
      "x": -11,
      "y": 62,
      "z": 30,
      "name": "Rock_Basalt_Brick"
    },
    {
      "x": -11,
      "y": 63,
      "z": 30,
      "name": "Rock_Basalt_Brick"
    },
    {
      "x": -11,
      "y": 64,
      "z": 30,
      "name": "Rock_Basalt_Brick"
    },
    {
      "x": -11,
      "y": 65,
      "z": 30,
      "name": "Rock_Basalt_Brick"
    },
    {
      "x": -11,
      "y": 66,
      "z": 30,
      "name": "Rock_Basalt_Brick_Smooth_Half",
      "rotation": 4
    },
    {
      "x": -11,
      "y": 67,
      "z": 30,
      "name": "Rock_Basalt_Brick_Smooth_Half",
      "rotation": 4
    },
    {
      "x": -11,
      "y": 68,
      "z": 30,
      "name": "Rock_Basalt_Brick_Smooth_Half",
      "rotation": 4
    },
    {
      "x": -11,
      "y": 69,
      "z": 30,
      "name": "Rock_Basalt_Brick_Smooth"
    },
    {
      "x": -11,
      "y": 70,
      "z": 30,
      "name": "Rock_Basalt_Cobble_Roof"
    },
    {
      "x": -11,
      "y": 54,
      "z": 31,
      "name": "Rock_Shale"
    },
    {
      "x": -11,
      "y": 55,
      "z": 31,
      "name": "Rock_Shale"
    },
    {
      "x": -11,
      "y": 56,
      "z": 31,
      "name": "Rock_Shale"
    },
    {
      "x": -11,
      "y": 57,
