{
  "version": 8,
  "blockIdVersion": 8,
  "anchorX": 0,
  "anchorY": 3,
  "anchorZ": 1,
  "blocks": [
    {
      "x": -3,
      "y": 9,
      "z": 0,
      "name": "Plant_Crop_Mushroom_Block_Red"
    },
    {
      "x": -3,
      "y": 10,
      "z": 0,
      "name": "Plant_Crop_Mushroom_Block_Red"
    },
    {
      "x": -3,
      "y": 9,
      "z": 1,
      "name": "Plant_Crop_Mushroom_Block_Red"
    },
    {
      "x": -3,
      "y": 10,
      "z": 1,
      "name": "Plant_Crop_Mushroom_Block_Red"
    },
    {
      "x": -3,
      "y": 11,
      "z": 1,
      "name": "Plant_Crop_Mushroom_Block_Red"
    },
    {
      "x": -3,
      "y": 12,
      "z": 1,
      "name": "Plant_Crop_Mushroom_Cap_Red",
      "components": {
        "Components": {
          "FarmingBlock": {}
        }
      }
    },
    {
      "x": -3,
      "y": 9,
      "z": 2,
      "name": "Plant_Crop_Mushroom_Block_Red"
    },
    {
      "x": -3,
      "y": 10,
      "z": 2,
      "name": "Plant_Crop_Mushroom_Block_Red"
    },
    {
      "x": -3,
      "y": 11,
      "z": 2,
      "name": "Plant_Crop_Mushroom_Block_Red"
    },
    {
      "x": -2,
      "y": 9,
      "z": -1,
      "name": "Plant_Crop_Mushroom_Block_Red"
    },
    {
      "x": -2,
      "y": 10,
      "z": -1,
      "name": "Plant_Crop_Mushroom_Block_Red"
    },
    {
      "x": -2,
      "y": 10,
      "z": 0,
      "name": "Plant_Crop_Mushroom_Block_Red_Mycelium"
    },
    {
      "x": -2,
      "y": 11,
      "z": 0,
      "name": "Plant_Crop_Mushroom_Block_Red"
    },
    {
      "x": -2,
      "y": 12,
      "z": 0,
      "name": "Plant_Crop_Mushroom_Block_Red"
    },
    {
      "x": -2,
      "y": 10,
      "z": 1,
      "name": "Plant_Crop_Mushroom_Block_Red_Mycelium"
    },
    {
      "x": -2,
      "y": 11,
      "z": 1,
      "name": "Plant_Crop_Mushroom_Block_Red"
    },
    {
      "x": -2,
      "y": 12,
      "z": 1,
      "name": "Plant_Crop_Mushroom_Block_Red"
    },
    {
      "x": -2,
      "y": 11,
      "z": 2,
      "name": "Plant_Crop_Mushroom_Block_Red"
    },
    {
      "x": -2,
      "y": 12,
      "z": 2,
      "name": "Plant_Crop_Mushroom_Block_Red"
    },
    {
      "x": -2,
      "y": 9,
      "z": 3,
      "name": "Plant_Crop_Mushroom_Block_Red"
    },
    {
      "x": -2,
      "y": 10,
      "z": 3,
      "name": "Plant_Crop_Mushroom_Block_Red"
    },
    {
      "x": -1,
      "y": 9,
      "z": -2,
      "name": "Plant_Crop_Mushroom_Block_Red"
    },
    {
      "x": -1,
      "y": 10,
      "z": -2,
      "name": "Plant_Crop_Mushroom_Block_Red"
    },
    {
      "x": -1,
      "y": 10,
      "z": -1,
      "name": "Rock_Crystal_Red_Small",
      "rotation": 8
    },
    {
      "x": -1,
      "y": 11,
      "z": -1,
      "name": "Plant_Crop_Mushroom_Block_Red"
    },
    {
      "x": -1,
      "y": 10,
      "z": 0,
      "name": "Plant_Crop_Mushroom_Block_Red_Mycelium"
    },
    {
      "x": -1,
      "y": 11,
      "z": 0,
      "name": "Plant_Crop_Mushroom_Block_Red"
    },
    {
      "x": -1,
      "y": 12,
      "z": 0,
      "name": "Plant_Crop_Mushroom_Block_Red"
    },
    {
      "x": -1,
      "y": 11,
      "z": 1,
      "name": "Plant_Crop_Mushroom_Block_Red"
    },
    {
      "x": -1,
      "y": 12,
      "z": 1,
      "name": "Plant_Crop_Mushroom_Block_Red"
    },
    {
      "x": -1,
      "y": 11,
      "z": 2,
      "name": "Plant_Crop_Mushroom_Block_Red"
    },
    {
      "x": -1,
      "y": 12,
      "z": 2,
      "name": "Plant_Crop_Mushroom_Block_Red"
    },
    {
      "x": -1,
      "y": 11,
      "z": 3,
      "name": "Plant_Crop_Mushroom_Block_Red"
    },
    {
      "x": -1,
      "y": 12,
      "z": 3,
      "name": "Plant_Crop_Mushroom_Block_Red"
    },
    {
      "x": -1,
      "y": 9,
      "z": 4,
      "name": "Plant_Crop_Mushroom_Block_Red"
    },
    {
      "x": -1,
      "y": 10,
      "z": 4,
      "name": "Plant_Crop_Mushroom_Block_Red"
    },
    {
      "x": -1,
      "y": 11,
      "z": 4,
      "name": "Plant_Crop_Mushroom_Block_Red"
    },
    {
      "x": 0,
      "y": 9,
      "z": -2,
      "name": "Plant_Crop_Mushroom_Block_Red"
    },
    {
      "x": 0,
      "y": 10,
      "z": -2,
      "name": "Plant_Crop_Mushroom_Block_Red"
    },
    {
      "x": 0,
      "y": 10,
      "z": -1,
      "name": "Rock_Crystal_Red_Small",
      "rotation": 8
    },
    {
      "x": 0,
      "y": 11,
      "z": -1,
      "name": "Plant_Crop_Mushroom_Block_Red"
    },
    {
      "x": 0,
      "y": 12,
      "z": -1,
      "name": "Plant_Crop_Mushroom_Block_Red"
    },
    {
      "x": 0,
      "y": 2,
      "z": 0,
      "name": "Plant_Crop_Mushroom_Block_Brown_Trunk"
    },
    {
      "x": 0,
      "y": 3,
      "z": 0,
      "name": "Plant_Crop_Mushroom_Block_Brown_Trunk"
    },
    {
      "x": 0,
      "y": 11,
      "z": 0,
      "name": "Plant_Crop_Mushroom_Block_Red"
    },
    {
      "x": 0,
      "y": 12,
      "z": 0,
      "name": "Plant_Crop_Mushroom_Block_Red"
    },
    {
      "x": 0,
      "y": 2,
      "z": 1,
      "name": "Plant_Crop_Mushroom_Block_Brown_Trunk"
    },
    {
      "x": 0,
      "y": 3,
      "z": 1,
      "name": "Plant_Crop_Mushroom_Block_Brown_Trunk"
    },
    {
      "x": 0,
      "y": 4,
      "z": 1,
      "name": "Plant_Crop_Mushroom_Block_Brown_Trunk"
    },
    {
      "x": 0,
      "y": 5,
      "z": 1,
      "name": "Plant_Crop_Mushroom_Block_Brown_Trunk"
    },
    {
      "x": 0,
      "y": 6,
      "z": 1,
      "name": "Plant_Crop_Mushroom_Block_Brown_Trunk"
    },
    {
      "x": 0,
      "y": 7,
      "z": 1,
      "name": "Plant_Crop_Mushroom_Block_Brown_Trunk"
    },
    {
      "x": 0,
      "y": 8,
      "z": 1,
      "name": "Plant_Crop_Mushroom_Block_Brown_Trunk"
    },
    {
      "x": 0,
      "y": 9,
      "z": 1,
      "name": "Plant_Crop_Mushroom_Block_Brown_Trunk"
    },
    {
      "x": 0,
      "y": 10,
      "z": 1,
      "name": "Plant_Crop_Mushroom_Block_Brown_Trunk"
    },
    {
      "x": 0,
      "y": 11,
      "z": 1,
      "name": "Plant_Crop_Mushroom_Block_Red"
    },
    {
      "x": 0,
      "y": 12,
      "z": 1,
      "name": "Plant_Crop_Mushroom_Block_Red"
    },
    {
      "x": 0,
      "y": 2,
      "z": 2,
      "name": "Plant_Crop_Mushroom_Block_Brown_Trunk"
    },
    {
      "x": 0,
      "y": 3,
      "z": 2,
      "name": "Plant_Crop_Mushroom_Block_Brown_Trunk"
    },
    {
      "x": 0,
      "y": 4,
      "z": 2,
      "name": "Plant_Crop_Mushroom_Block_Brown_Trunk"
    },
    {
      "x": 0,
      "y": 11,
      "z": 2,
      "name": "Rock_Crystal_Red_Block",
      "rotation": 4
    },
    {
      "x": 0,
      "y": 12,
      "z": 2,
      "name": "Plant_Crop_Mushroom_Block_Red"
    },
    {
      "x": 0,
      "y": 11,
      "z": 3,
      "name": "Plant_Crop_Mushroom_Block_Red"
    },
    {
      "x": 0,
      "y": 12,
      "z": 3,
      "name": "Plant_Crop_Mushroom_Block_Red"
    },
    {
      "x": 0,
      "y": 9,
      "z": 4,
      "name": "Plant_Crop_Mushroom_Block_Red"
    },
    {
      "x": 0,
      "y": 10,
      "z": 4,
      "name": "Plant_Crop_Mushroom_Block_Red"
    },
    {
      "x": 0,
      "y": 11,
      "z": 4,
      "name": "Plant_Crop_Mushroom_Block_Red"
    },
    {
      "x": 0,
      "y": 12,
      "z": 4,
      "name": "Plant_Crop_Mushroom_Block_Red"
    },
    {
      "x": 1,
      "y": 9,
      "z": -2,
      "name": "Plant_Crop_Mushroom_Block_Red"
    },
    {
      "x": 1,
      "y": 10,
      "z": -1,
      "name": "Plant_Crop_Mushroom_Block_Red"
    },
    {
      "x": 1,
      "y": 11,
      "z": -1,
      "name": "Plant_Crop_Mushroom_Block_Red"
    },
    {
      "x": 1,
      "y": 12,
      "z": -1,
      "name": "Plant_Crop_Mushroom_Block_Red"
    },
    {
      "x": 1,
      "y": 11,
      "z": 0,
      "name": "Plant_Crop_Mushroom_Block_Red"
    },
    {
      "x": 1,
      "y": 12,
      "z": 0,
      "name": "Plant_Crop_Mushroom_Block_Red"
    },
    {
      "x": 1,
      "y": 2,
      "z": 1,
      "name": "Plant_Crop_Mushroom_Block_Brown_Trunk"
    },
    {
      "x": 1,
      "y": 3,
      "z": 1,
      "name": "Plant_Crop_Mushroom_Block_Brown_Trunk"
    },
    {
      "x": 1,
      "y": 4,
      "z": 1,
      "name": "Plant_Crop_Mushroom_Block_Brown_Trunk"
    },
    {
      "x": 1,
      "y": 5,
      "z": 1,
      "name": "Plant_Crop_Mushroom_Block_Brown_Trunk"
    },
    {
      "x": 1,
      "y": 9,
      "z": 1,
      "name": "Plant_Crop_Mushroom_Block_Brown_Trunk"
    },
    {
      "x": 1,
      "y": 10,
      "z": 1,
      "name": "Plant_Crop_Mushroom_Block_Brown_Trunk"
    },
    {
      "x": 1,
      "y": 11,
      "z": 1,
      "name": "Plant_Crop_Mushroom_Block_Red"
    },
    {
      "x": 1,
      "y": 12,
      "z": 1,
      "name": "Plant_Crop_Mushroom_Block_Red"
    },
    {
      "x": 1,
      "y": 9,
      "z": 2,
      "name": "Plant_Crop_Mushroom_Block_Red_Mycelium"
    },
    {
      "x": 1,
      "y": 10,
      "z": 2,
      "name": "Plant_Crop_Mushroom_Block_Brown_Trunk"
    },
    {
      "x": 1,
      "y": 11,
      "z": 2,
      "name": "Plant_Crop_Mushroom_Block_Red"
    },
    {
      "x": 1,
      "y": 12,
      "z": 2,
      "name": "Plant_Crop_Mushroom_Block_Red"
    },
    {
      "x": 1,
      "y": 13,
      "z": 2,
      "name": "Plant_Crop_Mushroom_Cap_Red",
      "components": {
        "Components": {
          "FarmingBlock": {}
        }
      }
    },
    {
      "x": 1,
      "y": 10,
      "z": 3,
      "name": "Rock_Crystal_Red_Small",
      "rotation": 8
    },
    {
      "x": 1,
      "y": 11,
      "z": 3,
      "name": "Plant_Crop_Mushroom_Block_Red"
    },
    {
      "x": 1,
      "y": 12,
      "z": 3,
      "name": "Plant_Crop_Mushroom_Block_Red"
    },
    {
      "x": 1,
      "y": 13,
      "z": 3,
      "name": "Plant_Crop_Mushroom_Cap_Red",
      "components": {
        "Components": {
          "FarmingBlock": {}
        }
      }
    },
    {
      "x": 1,
      "y": 9,
      "z": 4,
      "name": "Plant_Crop_Mushroom_Block_Red"
    },
    {
      "x": 1,
      "y": 10,
      "z": 4,
      "name": "Plant_Crop_Mushroom_Block_Red"
    },
    {
      "x": 1,
      "y": 11,
      "z": 4,
      "name": "Plant_Crop_Mushroom_Block_Red"
    },
    {
      "x": 1,
      "y": 12,
      "z": 4,
      "name": "Plant_Crop_Mushroom_Cap_Red",
      "components": {
        "Components": {
          "FarmingBlock": {}
        }
      }
    },
    {
      "x": 2,
      "y": 9,
      "z": -1,
      "name": "Plant_Crop_Mushroom_Block_Red"
    },
    {
      "x": 2,
      "y": 10,
      "z": -1,
      "name": "Plant_Crop_Mushroom_Block_Red"
    },
    {
      "x": 2,
      "y": 11,
      "z": -1,
      "name": "Plant_Crop_Mushroom_Block_Red"
    },
    {
      "x": 2,
      "y": 10,
      "z": 0,
      "name": "Plant_Crop_Mushroom_Block_Red_Mycelium"
    },
    {
      "x": 2,
      "y": 11,
      "z": 0,
      "name": "Plant_Crop_Mushroom_Block_Red"
    },
    {
      "x": 2,
      "y": 9,
      "z": 1,
      "name": "Plant_Crop_Mushroom_Block_Red_Mycelium"
    },
    {
      "x": 2,
      "y": 10,
      "z": 1,
      "name": "Plant_Crop_Mushroom_Block_Red_Mycelium"
    },
    {
      "x": 2,
      "y": 11,
      "z": 1,
      "name": "Plant_Crop_Mushroom_Block_Red"
    },
    {
      "x": 2,
      "y": 12,
      "z": 1,
      "name": "Plant_Crop_Mushroom_Block_Red"
    },
    {
      "x": 2,
      "y": 10,
      "z": 2,
      "name": "Plant_Crop_Mushroom_Block_Red_Mycelium"
    },
    {
      "x": 2,
      "y": 11,
      "z": 2,
      "name": "Plant_Crop_Mushroom_Block_Red"
    },
    {
      "x": 2,
      "y": 12,
      "z": 2,
      "name": "Plant_Crop_Mushroom_Block_Red"
    },
    {
      "x": 2,
      "y": 9,
      "z": 3,
      "name": "Plant_Crop_Mushroom_Block_Red"
    },
    {
      "x": 2,
      "y": 10,
      "z": 3,
      "name": "Plant_Crop_Mushroom_Block_Red"
    },
    {
      "x": 2,
      "y": 11,
      "z": 3,
      "name": "Plant_Crop_Mushroom_Block_Red"
    },
    {
      "x": 2,
      "y": 12,
      "z": 3,
      "name": "Plant_Crop_Mushroom_Block_Red"
    },
    {
      "x": 2,
      "y": 13,
      "z": 3,
      "name": "Plant_Crop_Mushroom_Cap_Red",
      "components": {
        "Components": {
          "FarmingBlock": {}
        }
      }
    },
    {
      "x": 2,
      "y": 11,
      "z": 4,
      "name": "Plant_Crop_Mushroom_Block_Red"
    },
    {
      "x": 3,
      "y": 9,
      "z": 0,
      "name": "Plant_Crop_Mushroom_Block_Red"
    },
    {
      "x": 3,
      "y": 10,
      "z": 0,
      "name": "Plant_Crop_Mushroom_Block_Red"
    },
    {
      "x": 3,
      "y": 11,
      "z": 0,
      "name": "Plant_Crop_Mushroom_Block_Red"
    },
    {
      "x": 3,
      "y": 9,
      "z": 1,
      "name": "Plant_Crop_Mushroom_Block_Red"
    },
    {
      "x": 3,
      "y": 10,
      "z": 1,
      "name": "Plant_Crop_Mushroom_Block_Red"
    },
    {
      "x": 3,
      "y": 11,
      "z": 1,
      "name": "Plant_Crop_Mushroom_Block_Red"
    },
    {
      "x": 3,
      "y": 9,
      "z": 2,
      "name": "Plant_Crop_Mushroom_Block_Red"
    },
    {
      "x": 3,
      "y": 10,
      "z": 2,
      "name": "Plant_Crop_Mushroom_Block_Red"
    },
    {
      "x": 3,
      "y": 11,
      "z": 2,
      "name": "Plant_Crop_Mushroom_Block_Red"
    },
    {
      "x": 3,
      "y": 9,
      "z": 3,
      "name": "Plant_Crop_Mushroom_Block_Red"
    },
    {
      "x": 3,
      "y": 10,
      "z": 3,
      "name": "Plant_Crop_Mushroom_Block_Red"
    }
  ]
}