{
  "version": 8,
  "blockIdVersion": 8,
  "anchorX": 3,
  "anchorY": 3,
  "anchorZ": 1,
  "blocks": [
    {
      "x": 0,
      "y": 10,
      "z": 1,
      "name": "Plant_Crop_Mushroom_Block_Purple"
    },
    {
      "x": 0,
      "y": 10,
      "z": 2,
      "name": "Plant_Crop_Mushroom_Block_Purple"
    },
    {
      "x": 0,
      "y": 10,
      "z": 3,
      "name": "Plant_Crop_Mushroom_Block_Purple"
    },
    {
      "x": 1,
      "y": 10,
      "z": -1,
      "name": "Plant_Crop_Mushroom_Block_Purple"
    },
    {
      "x": 1,
      "y": 9,
      "z": 0,
      "name": "Plant_Crop_Mushroom_Block_Purple_Mycelium"
    },
    {
      "x": 1,
      "y": 10,
      "z": 0,
      "name": "Plant_Crop_Mushroom_Block_Purple"
    },
    {
      "x": 1,
      "y": 11,
      "z": 0,
      "name": "Plant_Crop_Mushroom_Block_Purple"
    },
    {
      "x": 1,
      "y": 10,
      "z": 1,
      "name": "Plant_Crop_Mushroom_Block_Purple"
    },
    {
      "x": 1,
      "y": 11,
      "z": 1,
      "name": "Plant_Crop_Mushroom_Block_Purple"
    },
    {
      "x": 1,
      "y": 9,
      "z": 2,
      "name": "Plant_Crop_Mushroom_Block_Purple_Mycelium"
    },
    {
      "x": 1,
      "y": 10,
      "z": 2,
      "name": "Rock_Crystal_Purple_Block"
    },
    {
      "x": 1,
      "y": 11,
      "z": 2,
      "name": "Plant_Crop_Mushroom_Block_Purple"
    },
    {
      "x": 1,
      "y": 12,
      "z": 2,
      "name": "Plant_Crop_Mushroom_Glowing_Purple"
    },
    {
      "x": 1,
      "y": 10,
      "z": 3,
      "name": "Plant_Crop_Mushroom_Block_Purple"
    },
    {
      "x": 1,
      "y": 10,
      "z": 4,
      "name": "Plant_Crop_Mushroom_Block_Purple"
    },
    {
      "x": 2,
      "y": 10,
      "z": -1,
      "name": "Plant_Crop_Mushroom_Block_Purple"
    },
    {
      "x": 2,
      "y": 11,
      "z": -1,
      "name": "Plant_Crop_Mushroom_Block_Purple"
    },
    {
      "x": 2,
      "y": 11,
      "z": 0,
      "name": "Plant_Crop_Mushroom_Block_Purple"
    },
    {
      "x": 2,
      "y": 11,
      "z": 1,
      "name": "Plant_Crop_Mushroom_Block_Purple"
    },
    {
      "x": 2,
      "y": 12,
      "z": 1,
      "name": "Plant_Crop_Mushroom_Block_Purple"
    },
    {
      "x": 2,
      "y": 10,
      "z": 2,
      "name": "Plant_Crop_Mushroom_Block_Purple_Mycelium"
    },
    {
      "x": 2,
      "y": 11,
      "z": 2,
      "name": "Plant_Crop_Mushroom_Block_Purple"
    },
    {
      "x": 2,
      "y": 12,
      "z": 2,
      "name": "Plant_Crop_Mushroom_Glowing_Purple"
    },
    {
      "x": 2,
      "y": 9,
      "z": 3,
      "name": "Plant_Crop_Mushroom_Block_Purple_Mycelium"
    },
    {
      "x": 2,
      "y": 10,
      "z": 3,
      "name": "Plant_Crop_Mushroom_Block_Purple"
    },
    {
      "x": 2,
      "y": 11,
      "z": 3,
      "name": "Plant_Crop_Mushroom_Block_Purple"
    },
    {
      "x": 2,
      "y": 12,
      "z": 3,
      "name": "Plant_Crop_Mushroom_Glowing_Purple"
    },
    {
      "x": 2,
      "y": 10,
      "z": 4,
      "name": "Plant_Crop_Mushroom_Block_Purple"
    },
    {
      "x": 3,
      "y": 10,
      "z": -2,
      "name": "Plant_Crop_Mushroom_Block_Purple"
    },
    {
      "x": 3,
      "y": 10,
      "z": -1,
      "name": "Plant_Crop_Mushroom_Block_Purple"
    },
    {
      "x": 3,
      "y": 11,
      "z": -1,
      "name": "Plant_Crop_Mushroom_Block_Purple"
    },
    {
      "x": 3,
      "y": 10,
      "z": 0,
      "name": "Plant_Crop_Mushroom_Block_Purple_Mycelium"
    },
    {
      "x": 3,
      "y": 11,
      "z": 0,
      "name": "Rock_Crystal_Purple_Block"
    },
    {
      "x": 3,
      "y": 12,
      "z": 0,
      "name": "Plant_Crop_Mushroom_Block_Purple"
    },
    {
      "x": 3,
      "y": 2,
      "z": 1,
      "name": "Plant_Crop_Mushroom_Block_Purple_Trunk"
    },
    {
      "x": 3,
      "y": 3,
      "z": 1,
      "name": "Plant_Crop_Mushroom_Block_Purple_Trunk"
    },
    {
      "x": 3,
      "y": 4,
      "z": 1,
      "name": "Plant_Crop_Mushroom_Block_Purple_Trunk"
    },
    {
      "x": 3,
      "y": 5,
      "z": 1,
      "name": "Plant_Crop_Mushroom_Block_Purple_Trunk"
    },
    {
      "x": 3,
      "y": 6,
      "z": 1,
      "name": "Plant_Crop_Mushroom_Block_Purple_Trunk"
    },
    {
      "x": 3,
      "y": 7,
      "z": 1,
      "name": "Plant_Crop_Mushroom_Block_Purple_Trunk"
    },
    {
      "x": 3,
      "y": 8,
      "z": 1,
      "name": "Plant_Crop_Mushroom_Block_Purple_Trunk"
    },
    {
      "x": 3,
      "y": 9,
      "z": 1,
      "name": "Plant_Crop_Mushroom_Block_Purple_Trunk"
    },
    {
      "x": 3,
      "y": 10,
      "z": 1,
      "name": "Plant_Crop_Mushroom_Block_Purple_Trunk"
    },
    {
      "x": 3,
      "y": 11,
      "z": 1,
      "name": "Plant_Crop_Mushroom_Block_Purple"
    },
    {
      "x": 3,
      "y": 12,
      "z": 1,
      "name": "Plant_Crop_Mushroom_Block_Purple"
    },
    {
      "x": 3,
      "y": 10,
      "z": 2,
      "name": "Plant_Crop_Mushroom_Block_Purple_Mycelium"
    },
    {
      "x": 3,
      "y": 11,
      "z": 2,
      "name": "Rock_Crystal_Purple_Block"
    },
    {
      "x": 3,
      "y": 12,
      "z": 2,
      "name": "Plant_Crop_Mushroom_Block_Purple"
    },
    {
      "x": 3,
      "y": 10,
      "z": 3,
      "name": "Plant_Crop_Mushroom_Block_Purple"
    },
    {
      "x": 3,
      "y": 11,
      "z": 3,
      "name": "Plant_Crop_Mushroom_Block_Purple"
    },
    {
      "x": 3,
      "y": 10,
      "z": 4,
      "name": "Plant_Crop_Mushroom_Block_Purple"
    },
    {
      "x": 4,
      "y": 10,
      "z": -2,
      "name": "Plant_Crop_Mushroom_Block_Purple"
    },
    {
      "x": 4,
      "y": 10,
      "z": -1,
      "name": "Plant_Crop_Mushroom_Block_Purple"
    },
    {
      "x": 4,
      "y": 11,
      "z": -1,
      "name": "Plant_Crop_Mushroom_Block_Purple"
    },
    {
      "x": 4,
      "y": 9,
      "z": 0,
      "name": "Plant_Crop_Mushroom_Block_Purple_Mycelium"
    },
    {
      "x": 4,
      "y": 10,
      "z": 0,
      "name": "Plant_Crop_Mushroom_Block_Purple"
    },
    {
      "x": 4,
      "y": 11,
      "z": 0,
      "name": "Plant_Crop_Mushroom_Block_Purple"
    },
    {
      "x": 4,
      "y": 11,
      "z": 1,
      "name": "Plant_Crop_Mushroom_Block_Purple"
    },
    {
      "x": 4,
      "y": 12,
      "z": 1,
      "name": "Plant_Crop_Mushroom_Block_Purple"
    },
    {
      "x": 4,
      "y": 10,
      "z": 2,
      "name": "Plant_Crop_Mushroom_Block_Purple_Mycelium"
    },
    {
      "x": 4,
      "y": 11,
      "z": 2,
      "name": "Plant_Crop_Mushroom_Block_Purple"
    },
    {
      "x": 4,
      "y": 9,
      "z": 3,
      "name": "Plant_Crop_Mushroom_Block_Purple_Mycelium"
    },
    {
      "x": 4,
      "y": 10,
      "z": 3,
      "name": "Plant_Crop_Mushroom_Block_Purple"
    },
    {
      "x": 4,
      "y": 11,
      "z": 3,
      "name": "Plant_Crop_Mushroom_Block_Purple"
    },
    {
      "x": 4,
      "y": 10,
      "z": 4,
      "name": "Plant_Crop_Mushroom_Block_Purple"
    },
    {
      "x": 5,
      "y": 10,
      "z": -2,
      "name": "Plant_Crop_Mushroom_Block_Purple"
    },
    {
      "x": 5,
      "y": 9,
      "z": -1,
      "name": "Plant_Crop_Mushroom_Block_Purple_Mycelium"
    },
    {
      "x": 5,
      "y": 10,
      "z": -1,
      "name": "Plant_Crop_Mushroom_Block_Purple"
    },
    {
      "x": 5,
      "y": 9,
      "z": 0,
      "name": "Plant_Crop_Mushroom_Block_Purple_Mycelium"
    },
    {
      "x": 5,
      "y": 10,
      "z": 0,
      "name": "Plant_Crop_Mushroom_Block_Purple"
    },
    {
      "x": 5,
      "y": 11,
      "z": 0,
      "name": "Plant_Crop_Mushroom_Block_Purple"
    },
    {
      "x": 5,
      "y": 10,
      "z": 1,
      "name": "Plant_Crop_Mushroom_Block_Purple"
    },
    {
      "x": 5,
      "y": 11,
      "z": 1,
      "name": "Plant_Crop_Mushroom_Block_Purple"
    },
    {
      "x": 5,
      "y": 12,
      "z": 1,
      "name": "Plant_Crop_Mushroom_Glowing_Purple"
    },
    {
      "x": 5,
      "y": 9,
      "z": 2,
      "name": "Plant_Crop_Mushroom_Block_Purple_Mycelium"
    },
    {
      "x": 5,
      "y": 10,
      "z": 2,
      "name": "Plant_Crop_Mushroom_Block_Purple"
    },
    {
      "x": 5,
      "y": 11,
      "z": 2,
      "name": "Plant_Crop_Mushroom_Block_Purple"
    },
    {
      "x": 5,
      "y": 9,
      "z": 3,
      "name": "Plant_Crop_Mushroom_Block_Purple_Mycelium"
    },
    {
      "x": 5,
      "y": 10,
      "z": 3,
      "name": "Plant_Crop_Mushroom_Block_Purple"
    },
    {
      "x": 5,
      "y": 10,
      "z": 4,
      "name": "Plant_Crop_Mushroom_Block_Purple"
    },
    {
      "x": 6,
      "y": 10,
      "z": 0,
      "name": "Plant_Crop_Mushroom_Block_Purple"
    },
    {
      "x": 6,
      "y": 10,
      "z": 1,
      "name": "Plant_Crop_Mushroom_Block_Purple"
    }
  ]
}