{
  "version": 8,
  "blockIdVersion": 8,
  "anchorX": 5,
  "anchorY": 22,
  "anchorZ": 0,
  "blocks": [
    {
      "x": -17,
      "y": 25,
      "z": -1,
      "name": "Rock_Stone"
    },
    {
      "x": -17,
      "y": 26,
      "z": -1,
      "name": "Rock_Stone"
    },
    {
      "x": -17,
      "y": 27,
      "z": -1,
      "name": "Rock_Stone"
    },
    {
      "x": -17,
      "y": 28,
      "z": -1,
      "name": "Rock_Stone"
    },
    {
      "x": -17,
      "y": 29,
      "z": -1,
      "name": "Rock_Stone"
    },
    {
      "x": -17,
      "y": 30,
      "z": -1,
      "name": "Rock_Stone"
    },
    {
      "x": -17,
      "y": 31,
      "z": -1,
      "name": "Rock_Stone"
    },
    {
      "x": -17,
      "y": 32,
      "z": -1,
      "name": "Rock_Stone"
    },
    {
      "x": -17,
      "y": 33,
      "z": -1,
      "name": "Soil_Grass"
    },
    {
      "x": -17,
      "y": 34,
      "z": -1,
      "name": "Plant_Grass_Sharp"
    },
    {
      "x": -17,
      "y": 24,
      "z": 0,
      "name": "Rock_Stone"
    },
    {
      "x": -17,
      "y": 25,
      "z": 0,
      "name": "Rock_Stone"
    },
    {
      "x": -17,
      "y": 26,
      "z": 0,
      "name": "Rock_Stone"
    },
    {
      "x": -17,
      "y": 27,
      "z": 0,
      "name": "Rock_Stone"
    },
    {
      "x": -17,
      "y": 28,
      "z": 0,
      "name": "Rock_Stone"
    },
    {
      "x": -17,
      "y": 29,
      "z": 0,
      "name": "Rock_Stone"
    },
    {
      "x": -17,
      "y": 30,
      "z": 0,
      "name": "Rock_Stone"
    },
    {
      "x": -17,
      "y": 31,
      "z": 0,
      "name": "Rock_Stone"
    },
    {
      "x": -17,
      "y": 32,
      "z": 0,
      "name": "Rock_Stone"
    },
    {
      "x": -17,
      "y": 33,
      "z": 0,
      "name": "Soil_Grass"
    },
    {
      "x": -17,
      "y": 34,
      "z": 0,
      "name": "Plant_Grass_Sharp"
    },
    {
      "x": -17,
      "y": 25,
      "z": 1,
      "name": "Rock_Stone"
    },
    {
      "x": -17,
      "y": 26,
      "z": 1,
      "name": "Rock_Stone"
    },
    {
      "x": -17,
      "y": 27,
      "z": 1,
      "name": "Rock_Stone"
    },
    {
      "x": -17,
      "y": 28,
      "z": 1,
      "name": "Rock_Stone"
    },
    {
      "x": -17,
      "y": 29,
      "z": 1,
      "name": "Rock_Stone"
    },
    {
      "x": -17,
      "y": 30,
      "z": 1,
      "name": "Rock_Stone"
    },
    {
      "x": -17,
      "y": 31,
      "z": 1,
      "name": "Rock_Stone"
    },
    {
      "x": -17,
      "y": 32,
      "z": 1,
      "name": "Soil_Grass"
    },
    {
      "x": -17,
      "y": 25,
      "z": 2,
      "name": "Rock_Stone"
    },
    {
      "x": -17,
      "y": 26,
      "z": 2,
      "name": "Rock_Stone"
    },
    {
      "x": -17,
      "y": 27,
      "z": 2,
      "name": "Rock_Stone"
    },
    {
      "x": -17,
      "y": 28,
      "z": 2,
      "name": "Rock_Stone"
    },
    {
      "x": -17,
      "y": 29,
      "z": 2,
      "name": "Rock_Stone"
    },
    {
      "x": -17,
      "y": 30,
      "z": 2,
      "name": "Rock_Stone"
    },
    {
      "x": -17,
      "y": 31,
      "z": 2,
      "name": "Rock_Stone"
    },
    {
      "x": -17,
      "y": 32,
      "z": 2,
      "name": "Soil_Grass"
    },
    {
      "x": -17,
      "y": 27,
      "z": 3,
      "name": "Rock_Stone"
    },
    {
      "x": -17,
      "y": 28,
      "z": 3,
      "name": "Rock_Stone"
    },
    {
      "x": -17,
      "y": 29,
      "z": 3,
      "name": "Rock_Stone"
    },
    {
      "x": -17,
      "y": 30,
      "z": 3,
      "name": "Rock_Stone"
    },
    {
      "x": -17,
      "y": 31,
      "z": 3,
      "name": "Rock_Stone"
    },
    {
      "x": -16,
      "y": 31,
      "z": -3,
      "name": "Rock_Stone"
    },
    {
      "x": -16,
      "y": 32,
      "z": -3,
      "name": "Rock_Stone"
    },
    {
      "x": -16,
      "y": 33,
      "z": -3,
      "name": "Rock_Stone"
    },
    {
      "x": -16,
      "y": 34,
      "z": -3,
      "name": "Soil_Grass"
    },
    {
      "x": -16,
      "y": 35,
      "z": -3,
      "name": "Plant_Grass_Sharp"
    },
    {
      "x": -16,
      "y": 27,
      "z": -2,
      "name": "Rock_Stone"
    },
    {
      "x": -16,
      "y": 28,
      "z": -2,
      "name": "Rock_Stone"
    },
    {
      "x": -16,
      "y": 29,
      "z": -2,
      "name": "Rock_Stone"
    },
    {
      "x": -16,
      "y": 30,
      "z": -2,
      "name": "Rock_Stone"
    },
    {
      "x": -16,
      "y": 31,
      "z": -2,
      "name": "Rock_Stone"
    },
    {
      "x": -16,
      "y": 32,
      "z": -2,
      "name": "Rock_Stone"
    },
    {
      "x": -16,
      "y": 33,
      "z": -2,
      "name": "Rock_Stone"
    },
    {
      "x": -16,
      "y": 34,
      "z": -2,
      "name": "Soil_Grass"
    },
    {
      "x": -16,
      "y": 35,
      "z": -2,
      "name": "Plant_Grass_Sharp"
    },
    {
      "x": -16,
      "y": 24,
      "z": -1,
      "name": "Rock_Stone"
    },
    {
      "x": -16,
      "y": 25,
      "z": -1,
      "name": "Rock_Stone"
    },
    {
      "x": -16,
      "y": 26,
      "z": -1,
      "name": "Rock_Stone"
    },
    {
      "x": -16,
      "y": 27,
      "z": -1,
      "name": "Rock_Stone"
    },
    {
      "x": -16,
      "y": 28,
      "z": -1,
      "name": "Rock_Stone"
    },
    {
      "x": -16,
      "y": 29,
      "z": -1,
      "name": "Rock_Stone"
    },
    {
      "x": -16,
      "y": 30,
      "z": -1,
      "name": "Rock_Stone"
    },
    {
      "x": -16,
      "y": 31,
      "z": -1,
      "name": "Rock_Stone"
    },
    {
      "x": -16,
      "y": 32,
      "z": -1,
      "name": "Rock_Stone"
    },
    {
      "x": -16,
      "y": 33,
      "z": -1,
      "name": "Soil_Dirt"
    },
    {
      "x": -16,
      "y": 34,
      "z": -1,
      "name": "Soil_Grass"
    },
    {
      "x": -16,
      "y": 35,
      "z": -1,
      "name": "Plant_Grass_Sharp"
    },
    {
      "x": -16,
      "y": 23,
      "z": 0,
      "name": "Rock_Stone"
    },
    {
      "x": -16,
      "y": 24,
      "z": 0,
      "name": "Rock_Stone"
    },
    {
      "x": -16,
      "y": 25,
      "z": 0,
      "name": "Rock_Stone"
    },
    {
      "x": -16,
      "y": 26,
      "z": 0,
      "name": "Rock_Stone"
    },
    {
      "x": -16,
      "y": 27,
      "z": 0,
      "name": "Rock_Stone"
    },
    {
      "x": -16,
      "y": 28,
      "z": 0,
      "name": "Rock_Stone"
    },
    {
      "x": -16,
      "y": 29,
      "z": 0,
      "name": "Rock_Stone"
    },
    {
      "x": -16,
      "y": 30,
      "z": 0,
      "name": "Rock_Stone"
    },
    {
      "x": -16,
      "y": 31,
      "z": 0,
      "name": "Rock_Stone"
    },
    {
      "x": -16,
      "y": 32,
      "z": 0,
      "name": "Soil_Dirt"
    },
    {
      "x": -16,
      "y": 33,
      "z": 0,
      "name": "Soil_Grass"
    },
    {
      "x": -16,
      "y": 34,
      "z": 0,
      "name": "Plant_Grass_Sharp"
    },
    {
      "x": -16,
      "y": 23,
      "z": 1,
      "name": "Rock_Stone"
    },
    {
      "x": -16,
      "y": 24,
      "z": 1,
      "name": "Rock_Stone"
    },
    {
      "x": -16,
      "y": 25,
      "z": 1,
      "name": "Rock_Stone"
    },
    {
      "x": -16,
      "y": 26,
      "z": 1,
      "name": "Rock_Stone"
    },
    {
      "x": -16,
      "y": 27,
      "z": 1,
      "name": "Rock_Stone"
    },
    {
      "x": -16,
      "y": 28,
      "z": 1,
      "name": "Rock_Stone"
    },
    {
      "x": -16,
      "y": 29,
      "z": 1,
      "name": "Rock_Stone"
    },
    {
      "x": -16,
      "y": 30,
      "z": 1,
      "name": "Rock_Stone"
    },
    {
      "x": -16,
      "y": 31,
      "z": 1,
      "name": "Rock_Stone"
    },
    {
      "x": -16,
      "y": 32,
      "z": 1,
      "name": "Soil_Dirt"
    },
    {
      "x": -16,
      "y": 33,
      "z": 1,
      "name": "Soil_Grass"
    },
    {
      "x": -16,
      "y": 34,
      "z": 1,
      "name": "Plant_Grass_Sharp"
    },
    {
      "x": -16,
      "y": 24,
      "z": 2,
      "name": "Rock_Stone"
    },
    {
      "x": -16,
      "y": 25,
      "z": 2,
      "name": "Rock_Stone"
    },
    {
      "x": -16,
      "y": 26,
      "z": 2,
      "name": "Rock_Stone"
    },
    {
      "x": -16,
      "y": 27,
      "z": 2,
      "name": "Rock_Stone"
    },
    {
      "x": -16,
      "y": 28,
      "z": 2,
      "name": "Rock_Stone"
    },
    {
      "x": -16,
      "y": 29,
      "z": 2,
      "name": "Rock_Stone"
    },
    {
      "x": -16,
      "y": 30,
      "z": 2,
      "name": "Rock_Stone"
    },
    {
      "x": -16,
      "y": 31,
      "z": 2,
      "name": "Soil_Dirt"
    },
    {
      "x": -16,
      "y": 32,
      "z": 2,
      "name": "Soil_Grass"
    },
    {
      "x": -16,
      "y": 25,
      "z": 3,
      "name": "Rock_Stone"
    },
    {
      "x": -16,
      "y": 26,
      "z": 3,
      "name": "Rock_Stone"
    },
    {
      "x": -16,
      "y": 27,
      "z": 3,
      "name": "Rock_Stone"
    },
    {
      "x": -16,
      "y": 28,
      "z": 3,
      "name": "Rock_Stone"
    },
    {
      "x": -16,
      "y": 29,
      "z": 3,
      "name": "Rock_Stone"
    },
    {
      "x": -16,
      "y": 30,
      "z": 3,
      "name": "Rock_Stone"
    },
    {
      "x": -16,
      "y": 31,
      "z": 3,
      "name": "Soil_Dirt"
    },
    {
      "x": -16,
      "y": 32,
      "z": 3,
      "name": "Soil_Grass"
    },
    {
      "x": -16,
      "y": 27,
      "z": 4,
      "name": "Rock_Stone"
    },
    {
      "x": -16,
      "y": 28,
      "z": 4,
      "name": "Rock_Stone"
    },
    {
      "x": -16,
      "y": 29,
      "z": 4,
      "name": "Rock_Stone"
    },
    {
      "x": -16,
      "y": 30,
      "z": 4,
      "name": "Rock_Stone"
    },
    {
      "x": -16,
      "y": 31,
      "z": 4,
      "name": "Soil_Grass"
    },
    {
      "x": -15,
      "y": 30,
      "z": -4,
      "name": "Rock_Stone"
    },
    {
      "x": -15,
      "y": 31,
      "z": -4,
      "name": "Rock_Stone"
    },
    {
      "x": -15,
      "y": 32,
      "z": -4,
      "name": "Rock_Stone"
    },
    {
      "x": -15,
      "y": 33,
      "z": -4,
      "name": "Rock_Stone"
    },
    {
      "x": -15,
      "y": 34,
      "z": -4,
      "name": "Soil_Dirt"
    },
    {
      "x": -15,
      "y": 35,
      "z": -4,
      "name": "Soil_Grass"
    },
    {
      "x": -15,
      "y": 28,
      "z": -3,
      "name": "Rock_Stone"
    },
    {
      "x": -15,
      "y": 29,
      "z": -3,
      "name": "Rock_Stone"
    },
    {
      "x": -15,
      "y": 30,
      "z": -3,
      "name": "Rock_Stone"
    },
    {
      "x": -15,
      "y": 31,
      "z": -3,
      "name": "Rock_Stone"
    },
    {
      "x": -15,
      "y": 32,
      "z": -3,
      "name": "Rock_Stone"
    },
    {
      "x": -15,
      "y": 33,
      "z": -3,
      "name": "Rock_Stone"
    },
    {
      "x": -15,
      "y": 34,
      "z": -3,
      "name": "Soil_Grass"
    },
    {
      "x": -15,
      "y": 25,
      "z": -2,
      "name": "Rock_Stone"
    },
    {
      "x": -15,
      "y": 26,
      "z": -2,
      "name": "Rock_Stone"
    },
    {
      "x": -15,
      "y": 27,
      "z": -2,
      "name": "Rock_Stone"
    },
    {
      "x": -15,
      "y": 28,
      "z": -2,
      "name": "Rock_Stone"
    },
    {
      "x": -15,
      "y": 29,
      "z": -2,
      "name": "Rock_Stone"
    },
    {
      "x": -15,
      "y": 30,
      "z": -2,
      "name": "Rock_Stone"
    },
    {
      "x": -15,
      "y": 31,
      "z": -2,
      "name": "Rock_Stone"
    },
    {
      "x": -15,
      "y": 32,
      "z": -2,
      "name": "Rock_Stone"
    },
    {
      "x": -15,
      "y": 33,
      "z": -2,
      "name": "Soil_Dirt"
    },
    {
      "x": -15,
      "y": 34,
      "z": -2,
      "name": "Soil_Grass"
    },
    {
      "x": -15,
      "y": 23,
      "z": -1,
      "name": "Rock_Stone"
    },
    {
      "x": -15,
      "y": 24,
      "z": -1,
      "name": "Rock_Stone"
    },
    {
      "x": -15,
      "y": 25,
      "z": -1,
      "name": "Rock_Stone"
    },
    {
      "x": -15,
      "y": 26,
      "z": -1,
      "name": "Rock_Stone"
    },
    {
      "x": -15,
      "y": 27,
      "z": -1,
      "name": "Rock_Stone"
    },
    {
      "x": -15,
      "y": 28,
      "z": -1,
      "name": "Rock_Stone"
    },
    {
      "x": -15,
      "y": 29,
      "z": -1,
      "name": "Rock_Stone"
    },
    {
      "x": -15,
      "y": 30,
      "z": -1,
      "name": "Rock_Stone"
    },
    {
      "x": -15,
      "y": 31,
      "z": -1,
      "name": "Rock_Stone"
    },
    {
      "x": -15,
      "y": 32,
      "z": -1,
      "name": "Soil_Dirt"
    },
    {
      "x": -15,
      "y": 33,
      "z": -1,
      "name": "Soil_Dirt"
    },
    {
      "x": -15,
      "y": 34,
      "z": -1,
      "name": "Soil_Grass"
    },
    {
      "x": -15,
      "y": 23,
      "z": 0,
      "name": "Rock_Stone"
    },
    {
      "x": -15,
      "y": 24,
      "z": 0,
      "name": "Rock_Stone"
    },
    {
      "x": -15,
      "y": 25,
      "z": 0,
      "name": "Rock_Stone"
    },
    {
      "x": -15,
      "y": 26,
      "z": 0,
      "name": "Rock_Stone"
    },
    {
      "x": -15,
      "y": 27,
      "z": 0,
      "name": "Rock_Stone"
    },
    {
      "x": -15,
      "y": 28,
      "z": 0,
      "name": "Rock_Stone"
    },
    {
      "x": -15,
      "y": 29,
      "z": 0,
      "name": "Rock_Stone"
    },
    {
      "x": -15,
      "y": 30,
      "z": 0,
      "name": "Rock_Stone"
    },
    {
      "x": -15,
      "y": 31,
      "z": 0,
      "name": "Rock_Stone"
    },
    {
      "x": -15,
      "y": 32,
      "z": 0,
      "name": "Soil_Dirt"
    },
    {
      "x": -15,
      "y": 33,
      "z": 0,
      "name": "Soil_Dirt"
    },
    {
      "x": -15,
      "y": 34,
      "z": 0,
      "name": "Soil_Grass"
    },
    {
      "x": -15,
      "y": 23,
      "z": 1,
      "name": "Rock_Stone"
    },
    {
      "x": -15,
      "y": 24,
      "z": 1,
      "name": "Rock_Stone"
    },
    {
      "x": -15,
      "y": 25,
      "z": 1,
      "name": "Rock_Stone"
    },
    {
      "x": -15,
      "y": 26,
      "z": 1,
      "name": "Rock_Stone"
    },
    {
      "x": -15,
      "y": 27,
      "z": 1,
      "name": "Rock_Stone"
    },
    {
      "x": -15,
      "y": 28,
      "z": 1,
      "name": "Rock_Stone"
    },
    {
      "x": -15,
      "y": 29,
      "z": 1,
      "name": "Rock_Stone"
    },
    {
      "x": -15,
      "y": 30,
      "z": 1,
      "name": "Rock_Stone"
    },
    {
      "x": -15,
      "y": 31,
      "z": 1,
      "name": "Soil_Dirt"
    },
    {
      "x": -15,
      "y": 32,
      "z": 1,
      "name": "Soil_Dirt"
    },
    {
      "x": -15,
      "y": 33,
      "z": 1,
      "name": "Soil_Grass"
    },
    {
      "x": -15,
      "y": 34,
      "z": 1,
      "name": "Plant_Grass_Sharp"
    },
    {
      "x": -15,
      "y": 23,
      "z": 2,
      "name": "Rock_Stone"
    },
    {
      "x": -15,
      "y": 24,
      "z": 2,
      "name": "Rock_Stone"
    },
    {
      "x": -15,
      "y": 25,
      "z": 2,
      "name": "Rock_Stone"
    },
    {
      "x": -15,
      "y": 26,
      "z": 2,
      "name": "Rock_Stone"
    },
    {
      "x": -15,
      "y": 27,
      "z": 2,
      "name": "Rock_Stone"
    },
    {
      "x": -15,
      "y": 28,
      "z": 2,
      "name": "Rock_Stone"
    },
    {
      "x": -15,
      "y": 29,
      "z": 2,
      "name": "Rock_Stone"
    },
    {
      "x": -15,
      "y": 30,
      "z": 2,
      "name": "Rock_Stone"
    },
    {
      "x": -15,
      "y": 31,
      "z": 2,
      "name": "Soil_Dirt"
    },
    {
      "x": -15,
      "y": 32,
      "z": 2,
      "name": "Soil_Dirt"
    },
    {
      "x": -15,
      "y": 33,
      "z": 2,
      "name": "Soil_Grass"
    },
    {
      "x": -15,
      "y": 24,
      "z": 3,
      "name": "Rock_Stone"
    },
    {
      "x": -15,
      "y": 25,
      "z": 3,
      "name": "Rock_Stone"
    },
    {
      "x": -15,
      "y": 26,
      "z": 3,
      "name": "Rock_Stone"
    },
    {
      "x": -15,
      "y": 27,
      "z": 3,
      "name": "Rock_Stone"
    },
    {
      "x": -15,
      "y": 28,
      "z": 3,
      "name": "Rock_Stone"
    },
    {
      "x": -15,
      "y": 29,
      "z": 3,
      "name": "Rock_Stone"
    },
    {
      "x": -15,
      "y": 30,
      "z": 3,
      "name": "Rock_Stone"
    },
    {
      "x": -15,
      "y": 31,
      "z": 3,
      "name": "Soil_Dirt"
    },
    {
      "x": -15,
      "y": 32,
      "z": 3,
      "name": "Soil_Grass"
    },
    {
      "x": -15,
      "y": 26,
      "z": 4,
      "name": "Rock_Stone"
    },
    {
      "x": -15,
      "y": 27,
      "z": 4,
      "name": "Rock_Stone"
    },
    {
      "x": -15,
      "y": 28,
      "z": 4,
      "name": "Rock_Stone"
    },
    {
      "x": -15,
      "y": 29,
      "z": 4,
      "name": "Rock_Stone"
    },
    {
      "x": -15,
      "y": 30,
      "z": 4,
      "name": "Rock_Stone"
    },
    {
      "x": -15,
      "y": 31,
      "z": 4,
      "name": "Soil_Grass"
    },
    {
      "x": -15,
      "y": 39,
      "z": 4,
      "name": "Plant_Leaves_Oak",
      "rotation": 1
    },
    {
      "x": -15,
      "y": 40,
      "z": 4,
      "name": "Plant_Leaves_Oak",
      "rotation": 1
    },
    {
      "x": -15,
      "y": 40,
      "z": 5,
      "name": "Plant_Leaves_Oak",
      "rotation": 1
    },
    {
      "x": -14,
      "y": 31,
      "z": -5,
      "name": "Rock_Stone"
    },
    {
      "x": -14,
      "y": 32,
      "z": -5,
      "name": "Rock_Stone"
    },
    {
      "x": -14,
      "y": 33,
      "z": -5,
      "name": "Rock_Stone"
    },
    {
      "x": -14,
      "y": 34,
      "z": -5,
      "name": "Rock_Stone"
    },
    {
      "x": -14,
      "y": 35,
      "z": -5,
      "name": "Soil_Grass"
    },
    {
      "x": -14,
      "y": 28,
      "z": -4,
      "name": "Rock_Stone"
    },
    {
      "x": -14,
      "y": 29,
      "z": -4,
      "name": "Rock_Stone"
    },
    {
      "x": -14,
      "y": 30,
      "z": -4,
      "name": "Rock_Stone"
    },
    {
      "x": -14,
      "y": 31,
      "z": -4,
      "name": "Rock_Stone"
    },
    {
      "x": -14,
      "y": 32,
      "z": -4,
      "name": "Rock_Stone"
    },
    {
      "x": -14,
      "y": 33,
      "z": -4,
      "name": "Rock_Stone"
    },
    {
      "x": -14,
      "y": 34,
      "z": -4,
      "name": "Soil_Dirt"
    },
    {
      "x": -14,
      "y": 35,
      "z": -4,
      "name": "Soil_Grass"
    },
    {
      "x": -14,
      "y": 26,
      "z": -3,
      "name": "Rock_Stone"
    },
    {
      "x": -14,
      "y": 27,
      "z": -3,
      "name": "Rock_Stone"
    },
    {
      "x": -14,
      "y": 28,
      "z": -3,
      "name": "Rock_Stone"
    },
    {
      "x": -14,
      "y": 29,
      "z": -3,
      "name": "Rock_Stone"
    },
    {
      "x": -14,
      "y": 30,
      "z": -3,
      "name": "Rock_Stone"
    },
    {
      "x": -14,
      "y": 31,
      "z": -3,
      "name": "Rock_Stone"
    },
    {
      "x": -14,
      "y": 32,
      "z": -3,
      "name": "Rock_Stone"
    },
    {
      "x": -14,
      "y": 33,
      "z": -3,
      "name": "Rock_Stone"
    },
    {
      "x": -14,
      "y": 34,
      "z": -3,
      "name": "Soil_Grass"
    },
    {
      "x": -14,
      "y": 24,
      "z": -2,
      "name": "Rock_Stone"
    },
    {
      "x": -14,
      "y": 25,
      "z": -2,
      "name": "Rock_Stone"
    },
    {
      "x": -14,
      "y": 26,
      "z": -2,
      "name": "Rock_Stone"
    },
    {
      "x": -14,
      "y": 27,
      "z": -2,
      "name": "Rock_Stone"
    },
    {
      "x": -14,
      "y": 28,
      "z": -2,
      "name": "Rock_Stone"
    },
    {
      "x": -14,
      "y": 29,
      "z": -2,
      "name": "Rock_Stone"
    },
    {
      "x": -14,
      "y": 30,
      "z": -2,
      "name": "Rock_Stone"
    },
    {
      "x": -14,
      "y": 31,
      "z": -2,
      "name": "Rock_Stone"
    },
    {
      "x": -14,
      "y": 32,
      "z": -2,
      "name": "Rock_Stone"
    },
    {
      "x": -14,
      "y": 33,
      "z": -2,
      "name": "Soil_Dirt"
    },
    {
      "x": -14,
      "y": 34,
      "z": -2,
      "name": "Soil_Grass"
    },
    {
      "x": -14,
      "y": 23,
      "z": -1,
      "name": "Rock_Stone"
    },
    {
      "x": -14,
      "y": 24,
      "z": -1,
      "name": "Rock_Stone"
    },
    {
      "x": -14,
      "y": 25,
      "z": -1,
      "name": "Rock_Stone"
    },
    {
      "x": -14,
      "y": 26,
      "z": -1,
      "name": "Rock_Stone"
    },
    {
      "x": -14,
      "y": 27,
      "z": -1,
      "name": "Rock_Stone"
    },
    {
      "x": -14,
      "y": 28,
      "z": -1,
      "name": "Rock_Stone"
    },
    {
      "x": -14,
      "y": 29,
      "z": -1,
      "name": "Rock_Stone"
    },
    {
      "x": -14,
      "y": 30,
      "z": -1,
      "name": "Rock_Stone"
    },
    {
      "x": -14,
      "y": 31,
      "z": -1,
      "name": "Rock_Stone"
    },
    {
      "x": -14,
      "y": 32,
      "z": -1,
      "name": "Soil_Dirt"
    },
    {
      "x": -14,
      "y": 33,
      "z": -1,
      "name": "Soil_Dirt"
    },
    {
      "x": -14,
      "y": 34,
      "z": -1,
      "name": "Soil_Grass"
    },
    {
      "x": -14,
      "y": 35,
      "z": -1,
      "name": "Plant_Grass_Sharp"
    },
    {
      "x": -14,
      "y": 22,
      "z": 0,
      "name": "Rock_Stone"
    },
    {
      "x": -14,
      "y": 23,
      "z": 0,
      "name": "Rock_Stone"
    },
    {
      "x": -14,
      "y": 24,
      "z": 0,
      "name": "Rock_Stone"
    },
    {
      "x": -14,
      "y": 25,
      "z": 0,
      "name": "Rock_Stone"
    },
    {
      "x": -14,
      "y": 26,
      "z": 0,
      "name": "Rock_Stone"
    },
    {
      "x": -14,
      "y": 27,
      "z": 0,
      "name": "Rock_Stone"
    },
    {
      "x": -14,
      "y": 28,
      "z": 0,
      "name": "Rock_Stone"
    },
    {
      "x": -14,
      "y": 29,
      "z": 0,
      "name": "Rock_Stone"
    },
    {
      "x": -14,
      "y": 30,
      "z": 0,
      "name": "Rock_Stone"
    },
    {
      "x": -14,
      "y": 31,
      "z": 0,
      "name": "Soil_Dirt"
    },
    {
      "x": -14,
      "y": 32,
      "z": 0,
      "name": "Soil_Dirt"
    },
    {
      "x": -14,
      "y": 33,
      "z": 0,
      "name": "Soil_Grass"
    },
    {
      "x": -14,
      "y": 22,
      "z": 1,
      "name": "Rock_Stone"
    },
    {
      "x": -14,
      "y": 23,
      "z": 1,
      "name": "Rock_Stone"
    },
    {
      "x": -14,
      "y": 24,
      "z": 1,
      "name": "Rock_Stone"
    },
    {
      "x": -14,
      "y": 25,
      "z": 1,
      "name": "Rock_Stone"
    },
    {
      "x": -14,
      "y": 26,
      "z": 1,
      "name": "Rock_Stone"
    },
    {
      "x": -14,
      "y": 27,
      "z": 1,
      "name": "Rock_Stone"
    },
    {
      "x": -14,
      "y": 28,
      "z": 1,
      "name": "Rock_Stone"
    },
    {
      "x": -14,
      "y": 29,
      "z": 1,
      "name": "Rock_Stone"
    },
    {
      "x": -14,
      "y": 30,
      "z": 1,
      "name": "Rock_Stone"
    },
    {
      "x": -14,
      "y": 31,
      "z": 1,
      "name": "Soil_Dirt"
    },
    {
      "x": -14,
      "y": 32,
      "z": 1,
      "name": "Soil_Dirt"
    },
    {
      "x": -14,
      "y": 33,
      "z": 1,
      "name": "Soil_Grass"
    },
    {
      "x": -14,
      "y": 34,
      "z": 1,
      "name": "Plant_Grass_Sharp"
    },
    {
      "x": -14,
      "y": 23,
      "z": 2,
      "name": "Rock_Stone"
    },
    {
      "x": -14,
      "y": 24,
      "z": 2,
      "name": "Rock_Stone"
    },
    {
      "x": -14,
      "y": 25,
      "z": 2,
      "name": "Rock_Stone"
    },
    {
      "x": -14,
      "y": 26,
      "z": 2,
      "name": "Rock_Stone"
    },
    {
      "x": -14,
      "y": 27,
      "z": 2,
      "name": "Rock_Stone"
    },
    {
      "x": -14,
      "y": 28,
      "z": 2,
      "name": "Rock_Stone"
    },
    {
      "x": -14,
      "y": 29,
      "z": 2,
      "name": "Rock_Stone"
    },
    {
      "x": -14,
      "y": 30,
      "z": 2,
      "name": "Rock_Stone"
    },
    {
      "x": -14,
      "y": 31,
      "z": 2,
      "name": "Soil_Dirt"
    },
    {
      "x": -14,
      "y": 32,
      "z": 2,
      "name": "Soil_Dirt"
    },
    {
      "x": -14,
      "y": 33,
      "z": 2,
      "name": "Soil_Grass"
    },
    {
      "x": -14,
      "y": 40,
      "z": 2,
      "name": "Plant_Leaves_Oak",
      "rotation": 1
    },
    {
      "x": -14,
      "y": 24,
      "z": 3,
      "name": "Rock_Stone"
    },
    {
      "x": -14,
      "y": 25,
      "z": 3,
      "name": "Rock_Stone"
    },
    {
      "x": -14,
      "y": 26,
      "z": 3,
      "name": "Rock_Stone"
    },
    {
      "x": -14,
      "y": 27,
      "z": 3,
      "name": "Rock_Stone"
    },
    {
      "x": -14,
      "y": 28,
      "z": 3,
      "name": "Rock_Stone"
    },
    {
      "x": -14,
      "y": 29,
      "z": 3,
      "name": "Rock_Stone"
    },
    {
      "x": -14,
      "y": 30,
      "z": 3,
      "name": "Rock_Stone"
    },
    {
      "x": -14,
      "y": 31,
      "z": 3,
      "name": "Soil_Dirt"
    },
    {
      "x": -14,
      "y": 32,
      "z": 3,
      "name": "Soil_Grass"
    },
    {
      "x": -14,
      "y": 37,
      "z": 3,
      "name": "Plant_Leaves_Oak",
      "rotation": 1
    },
    {
      "x": -14,
      "y": 39,
      "z": 3,
      "name": "Plant_Leaves_Oak",
      "rotation": 1
    },
    {
      "x": -14,
      "y": 40,
      "z": 3,
      "name": "Plant_Leaves_Oak",
      "rotation": 1
    },
    {
      "x": -14,
      "y": 26,
      "z": 4,
      "name": "Rock_Stone"
    },
    {
      "x": -14,
      "y": 27,
      "z": 4,
      "name": "Rock_Stone"
    },
    {
      "x": -14,
      "y": 28,
      "z": 4,
      "name": "Rock_Stone"
    },
    {
      "x": -14,
      "y": 29,
      "z": 4,
      "name": "Rock_Stone"
    },
    {
      "x": -14,
      "y": 30,
      "z": 4,
      "name": "Rock_Stone"
    },
    {
      "x": -14,
      "y": 31,
      "z": 4,
      "name": "Soil_Dirt"
    },
    {
      "x": -14,
      "y": 32,
      "z": 4,
      "name": "Soil_Grass"
    },
    {
      "x": -14,
      "y": 37,
      "z": 4,
      "name": "Plant_Leaves_Oak",
      "rotation": 1
    },
    {
      "x": -14,
      "y": 38,
      "z": 4,
      "name": "Plant_Leaves_Oak",
      "rotation": 1
    },
    {
      "x": -14,
      "y": 39,
      "z": 4,
      "name": "Plant_Leaves_Oak",
      "rotation": 1
    },
    {
      "x": -14,
      "y": 40,
      "z": 4,
      "name": "Plant_Leaves_Oak",
      "rotation": 1
    },
    {
      "x": -14,
      "y": 41,
      "z": 4,
      "name": "Plant_Leaves_Oak",
      "rotation": 1
    },
    {
      "x": -14,
      "y": 39,
      "z": 5,
      "name": "Plant_Leaves_Oak",
      "rotation": 1
    },
    {
      "x": -14,
      "y": 40,
      "z": 5,
      "name": "Plant_Leaves_Oak",
      "rotation": 1
    },
    {
      "x": -14,
      "y": 40,
      "z": 6,
      "name": "Plant_Leaves_Oak",
      "rotation": 1
    },
    {
      "x": -13,
      "y": 29,
      "z": -5,
      "name": "Rock_Stone"
    },
    {
      "x": -13,
      "y": 30,
      "z": -5,
      "name": "Rock_Stone"
    },
    {
      "x": -13,
      "y": 31,
      "z": -5,
      "name": "Rock_Stone"
    },
    {
      "x": -13,
      "y": 32,
      "z": -5,
      "name": "Rock_Stone"
    },
    {
      "x": -13,
      "y": 33,
      "z": -5,
      "name": "Rock_Stone"
    },
    {
      "x": -13,
      "y": 34,
      "z": -5,
      "name": "Soil_Dirt"
    },
    {
      "x": -13,
      "y": 35,
      "z": -5,
      "name": "Soil_Grass"
    },
    {
      "x": -13,
      "y": 36,
      "z": -5,
      "name": "Plant_Grass_Sharp"
    },
    {
      "x": -13,
      "y": 27,
      "z": -4,
      "name": "Rock_Stone"
    },
    {
      "x": -13,
      "y": 28,
      "z": -4,
      "name": "Rock_Stone"
    },
    {
      "x": -13,
      "y": 29,
      "z": -4,
      "name": "Rock_Stone"
    },
    {
      "x": -13,
      "y": 30,
      "z": -4,
      "name": "Rock_Stone"
    },
    {
      "x": -13,
      "y": 31,
      "z": -4,
      "name": "Rock_Stone"
    },
    {
      "x": -13,
      "y": 32,
      "z": -4,
      "name": "Rock_Stone"
    },
    {
      "x": -13,
      "y": 33,
      "z": -4,
      "name": "Rock_Stone"
    },
    {
      "x": -13,
      "y": 34,
      "z": -4,
      "name": "Soil_Dirt"
    },
    {
      "x": -13,
      "y": 35,
      "z": -4,
      "name": "Soil_Grass"
    },
    {
      "x": -13,
      "y": 36,
      "z": -4,
      "name": "Plant_Grass_Sharp"
    },
    {
      "x": -13,
      "y": 25,
      "z": -3,
      "name": "Rock_Stone"
    },
    {
      "x": -13,
      "y": 26,
      "z": -3,
      "name": "Rock_Stone"
    },
    {
      "x": -13,
      "y": 27,
      "z": -3,
      "name": "Rock_Stone"
    },
    {
      "x": -13,
      "y": 28,
      "z": -3,
      "name": "Rock_Stone"
    },
    {
      "x": -13,
      "y": 29,
      "z": -3,
      "name": "Rock_Stone"
    },
    {
      "x": -13,
      "y": 30,
      "z": -3,
      "name": "Rock_Stone"
    },
    {
      "x": -13,
      "y": 31,
      "z": -3,
      "name": "Rock_Stone"
    },
    {
      "x": -13,
      "y": 32,
      "z": -3,
      "name": "Rock_Stone"
    },
    {
      "x": -13,
      "y": 33,
      "z": -3,
      "name": "Soil_Dirt"
    },
    {
      "x": -13,
      "y": 34,
      "z": -3,
      "name": "Soil_Grass"
    },
    {
      "x": -13,
      "y": 22,
      "z": -2,
      "name": "Rock_Stone"
    },
    {
      "x": -13,
      "y": 23,
      "z": -2,
      "name": "Rock_Stone"
    },
    {
      "x": -13,
      "y": 24,
      "z": -2,
      "name": "Rock_Stone"
    },
    {
      "x": -13,
      "y": 25,
      "z": -2,
      "name": "Rock_Stone"
    },
    {
      "x": -13,
      "y": 26,
      "z": -2,
      "name": "Rock_Stone"
    },
    {
      "x": -13,
      "y": 27,
      "z": -2,
      "name": "Rock_Stone"
    },
    {
      "x": -13,
      "y": 28,
      "z": -2,
      "name": "Rock_Stone"
    },
    {
      "x": -13,
      "y": 29,
      "z": -2,
      "name": "Rock_Stone"
    },
    {
      "x": -13,
      "y": 30,
      "z": -2,
      "name": "Rock_Stone"
    },
    {
      "x": -13,
      "y": 31,
      "z": -2,
      "name": "Rock_Stone"
    },
    {
      "x": -13,
      "y": 32,
      "z": -2,
      "name": "Rock_Stone"
    },
    {
      "x": -13,
      "y": 33,
      "z": -2,
      "name": "Soil_Dirt"
    },
    {
      "x": -13,
      "y": 34,
      "z": -2,
      "name": "Soil_Grass"
    },
    {
      "x": -13,
      "y": 35,
      "z": -2,
      "name": "Plant_Grass_Sharp"
    },
    {
      "x": -13,
      "y": 21,
      "z": -1,
      "name": "Rock_Stone"
    },
    {
      "x": -13,
      "y": 22,
      "z": -1,
      "name": "Rock_Stone"
    },
    {
      "x": -13,
      "y": 23,
      "z": -1,
      "name": "Rock_Stone"
    },
    {
      "x": -13,
      "y": 24,
      "z": -1,
      "name": "Rock_Stone"
    },
    {
      "x": -13,
      "y": 25,
      "z": -1,
      "name": "Rock_Stone"
    },
    {
      "x": -13,
      "y": 26,
      "z": -1,
      "name": "Rock_Stone"
    },
    {
      "x": -13,
      "y": 27,
      "z": -1,
      "name": "Rock_Stone"
    },
    {
      "x": -13,
      "y": 28,
      "z": -1,
      "name": "Rock_Stone"
    },
    {
      "x": -13,
      "y": 29,
      "z": -1,
      "name": "Rock_Stone"
    },
    {
      "x": -13,
      "y": 30,
      "z": -1,
      "name": "Rock_Stone"
    },
    {
      "x": -13,
      "y": 31,
      "z": -1,
      "name": "Rock_Stone"
    },
    {
      "x": -13,
      "y": 32,
      "z": -1,
      "name": "Soil_Dirt"
    },
    {
      "x": -13,
      "y": 33,
      "z": -1,
      "name": "Soil_Dirt"
    },
    {
      "x": -13,
      "y": 34,
      "z": -1,
      "name": "Soil_Grass"
    },
    {
      "x": -13,
      "y": 35,
      "z": -1,
      "name": "Plant_Grass_Sharp"
    },
    {
      "x": -13,
      "y": 21,
      "z": 0,
      "name": "Rock_Stone"
    },
    {
      "x": -13,
      "y": 22,
      "z": 0,
      "name": "Rock_Stone"
    },
    {
      "x": -13,
      "y": 23,
      "z": 0,
      "name": "Rock_Stone"
    },
    {
      "x": -13,
      "y": 24,
      "z": 0,
      "name": "Rock_Stone"
    },
    {
      "x": -13,
      "y": 25,
      "z": 0,
      "name": "Rock_Stone"
    },
    {
      "x": -13,
      "y": 26,
      "z": 0,
      "name": "Rock_Stone"
    },
    {
      "x": -13,
      "y": 27,
      "z": 0,
      "name": "Rock_Stone"
    },
    {
      "x": -13,
      "y": 28,
      "z": 0,
      "name": "Rock_Stone"
    },
    {
      "x": -13,
      "y": 29,
      "z": 0,
      "name": "Rock_Stone"
    },
    {
      "x": -13,
      "y": 30,
      "z": 0,
      "name": "Rock_Stone"
    },
    {
      "x": -13,
      "y": 31,
      "z": 0,
      "name": "Soil_Dirt"
    },
    {
      "x": -13,
      "y": 32,
      "z": 0,
      "name": "Soil_Dirt"
    },
    {
      "x": -13,
      "y": 33,
      "z": 0,
      "name": "Soil_Grass"
    },
    {
      "x": -13,
      "y": 22,
      "z": 1,
      "name": "Rock_Stone"
    },
    {
      "x": -13,
      "y": 23,
      "z": 1,
      "name": "Rock_Stone"
    },
    {
      "x": -13,
      "y": 24,
      "z": 1,
      "name": "Rock_Stone"
    },
    {
      "x": -13,
      "y": 25,
      "z": 1,
      "name": "Rock_Stone"
    },
    {
      "x": -13,
      "y": 26,
      "z": 1,
      "name": "Rock_Stone"
    },
    {
      "x": -13,
      "y": 27,
      "z": 1,
      "name": "Rock_Stone"
    },
    {
      "x": -13,
      "y": 28,
      "z": 1,
      "name": "Rock_Stone"
    },
    {
      "x": -13,
      "y": 29,
      "z": 1,
      "name": "Rock_Stone"
    },
    {
      "x": -13,
      "y": 30,
      "z": 1,
      "name": "Rock_Stone"
    },
    {
      "x": -13,
      "y": 31,
      "z": 1,
      "name": "Soil_Dirt"
    },
    {
      "x": -13,
      "y": 32,
      "z": 1,
      "name": "Soil_Dirt"
    },
    {
      "x": -13,
      "y": 33,
      "z": 1,
      "name": "Soil_Grass"
    },
    {
      "x": -13,
      "y": 34,
      "z": 1,
      "name": "Plant_Grass_Sharp"
    },
    {
      "x": -13,
      "y": 38,
      "z": 1,
      "name": "Plant_Leaves_Oak",
      "rotation": 1
    },
    {
      "x": -13,
      "y": 39,
      "z": 1,
      "name": "Plant_Leaves_Oak",
      "rotation": 1
    },
    {
      "x": -13,
      "y": 40,
      "z": 1,
      "name": "Plant_Leaves_Oak",
      "rotation": 1
    },
    {
      "x": -13,
      "y": 22,
      "z": 2,
      "name": "Rock_Stone"
    },
    {
      "x": -13,
      "y": 23,
      "z": 2,
      "name": "Rock_Stone"
    },
    {
      "x": -13,
      "y": 24,
      "z": 2,
      "name": "Rock_Stone"
    },
    {
      "x": -13,
      "y": 25,
      "z": 2,
      "name": "Rock_Stone"
    },
    {
      "x": -13,
      "y": 26,
      "z": 2,
      "name": "Rock_Stone"
    },
    {
      "x": -13,
      "y": 27,
      "z": 2,
      "name": "Rock_Stone"
    },
    {
      "x": -13,
      "y": 28,
      "z": 2,
      "name": "Rock_Stone"
    },
    {
      "x": -13,
      "y": 29,
      "z": 2,
      "name": "Rock_Stone"
    },
    {
      "x": -13,
      "y": 30,
      "z": 2,
      "name": "Rock_Stone"
    },
    {
      "x": -13,
      "y": 31,
      "z": 2,
      "name": "Soil_Dirt"
    },
    {
      "x": -13,
      "y": 32,
      "z": 2,
      "name": "Soil_Grass"
    },
    {
      "x": -13,
      "y": 40,
      "z": 2,
      "name": "Plant_Leaves_Oak",
      "rotation": 1
    },
    {
      "x": -13,
      "y": 24,
      "z": 3,
      "name": "Rock_Stone"
    },
    {
      "x": -13,
      "y": 25,
      "z": 3,
      "name": "Rock_Stone"
    },
    {
      "x": -13,
      "y": 26,
      "z": 3,
      "name": "Rock_Stone"
    },
    {
      "x": -13,
      "y": 27,
      "z": 3,
      "name": "Rock_Stone"
    },
    {
      "x": -13,
      "y": 28,
      "z": 3,
      "name": "Rock_Stone"
    },
    {
      "x": -13,
      "y": 29,
      "z": 3,
      "name": "Rock_Stone"
    },
    {
      "x": -13,
      "y": 30,
      "z": 3,
      "name": "Rock_Stone"
    },
    {
      "x": -13,
      "y": 31,
      "z": 3,
      "name": "Soil_Dirt"
    },
    {
      "x": -13,
      "y": 32,
      "z": 3,
      "name": "Soil_Grass"
    },
    {
      "x": -13,
      "y": 37,
      "z": 3,
      "name": "Plant_Leaves_Oak",
      "rotation": 1
    },
    {
      "x": -13,
      "y": 38,
      "z": 3,
      "name": "Plant_Leaves_Oak",
      "rotation": 1
    },
    {
      "x": -13,
      "y": 40,
      "z": 3,
      "name": "Plant_Leaves_Oak",
      "rotation": 1
    },
    {
      "x": -13,
      "y": 41,
      "z": 3,
      "name": "Plant_Leaves_Oak",
      "rotation": 1
    },
    {
      "x": -13,
      "y": 42,
      "z": 3,
      "name": "Plant_Leaves_Oak",
      "rotation": 1
    },
    {
      "x": -13,
      "y": 25,
      "z": 4,
      "name": "Rock_Stone"
    },
    {
      "x": -13,
      "y": 26,
      "z": 4,
      "name": "Rock_Stone"
    },
    {
      "x": -13,
      "y": 27,
      "z": 4,
      "name": "Rock_Stone"
    },
    {
      "x": -13,
      "y": 28,
      "z": 4,
      "name": "Rock_Stone"
    },
    {
      "x": -13,
      "y": 29,
      "z": 4,
      "name": "Rock_Stone"
    },
    {
      "x": -13,
      "y": 30,
      "z": 4,
      "name": "Rock_Stone"
    },
    {
      "x": -13,
      "y": 31,
      "z": 4,
      "name": "Soil_Dirt"
    },
    {
      "x": -13,
      "y": 32,
      "z": 4,
      "name": "Soil_Grass"
    },
    {
      "x": -13,
      "y": 37,
      "z": 4,
      "name": "Plant_Leaves_Oak",
      "rotation": 1
    },
    {
      "x": -13,
      "y": 38,
      "z": 4,
      "name": "Plant_Leaves_Oak",
      "rotation": 1
    },
    {
      "x": -13,
      "y": 41,
      "z": 4,
      "name": "Plant_Leaves_Oak",
      "rotation": 1
    },
    {
      "x": -13,
      "y": 42,
      "z": 4,
      "name": "Plant_Leaves_Oak",
      "rotation": 1
    },
    {
      "x": -13,
      "y": 38,
      "z": 5,
      "name": "Plant_Leaves_Oak",
      "rotation": 1
    },
    {
      "x": -13,
      "y": 40,
      "z": 5,
      "name": "Plant_Leaves_Oak",
      "rotation": 1
    },
    {
      "x": -13,
      "y": 41,
      "z": 5,
      "name": "Plant_Leaves_Oak",
      "rotation": 1
    },
    {
      "x": -13,
      "y": 38,
      "z": 6,
      "name": "Plant_Leaves_Oak",
      "rotation": 1
    },
    {
      "x": -13,
      "y": 41,
      "z": 6,
      "name": "Plant_Leaves_Oak",
      "rotation": 1
    },
    {
      "x": -12,
      "y": 31,
      "z": -6,
      "name": "Rock_Stone"
    },
    {
      "x": -12,
      "y": 32,
      "z": -6,
      "name": "Rock_Stone"
    },
    {
      "x": -12,
      "y": 33,
      "z": -6,
      "name": "Rock_Stone"
    },
    {
      "x": -12,
      "y": 34,
      "z": -6,
      "name": "Rock_Stone"
    },
    {
      "x": -12,
      "y": 35,
      "z": -6,
      "name": "Soil_Grass"
    },
    {
      "x": -12,
      "y": 36,
      "z": -6,
      "name": "Plant_Grass_Sharp"
    },
    {
      "x": -12,
      "y": 27,
      "z": -5,
      "name": "Rock_Stone"
    },
    {
      "x": -12,
      "y": 28,
      "z": -5,
      "name": "Rock_Stone"
    },
    {
      "x": -12,
      "y": 29,
      "z": -5,
      "name": "Rock_Stone"
    },
    {
      "x": -12,
      "y": 30,
      "z": -5,
      "name": "Rock_Stone"
    },
    {
      "x": -12,
      "y": 31,
      "z": -5,
      "name": "Rock_Stone"
    },
    {
      "x": -12,
      "y": 32,
      "z": -5,
      "name": "Rock_Stone"
    },
    {
      "x": -12,
      "y": 33,
      "z": -5,
      "name": "Rock_Stone"
    },
    {
      "x": -12,
      "y": 34,
      "z": -5,
      "name": "Soil_Dirt"
    },
    {
      "x": -12,
      "y": 35,
      "z": -5,
      "name": "Soil_Grass"
    },
    {
      "x": -12,
      "y": 36,
      "z": -5,
      "name": "Plant_Grass_Sharp"
    },
    {
      "x": -12,
      "y": 24,
      "z": -4,
      "name": "Rock_Stone"
    },
    {
      "x": -12,
      "y": 25,
      "z": -4,
      "name": "Rock_Stone"
    },
    {
      "x": -12,
      "y": 26,
      "z": -4,
      "name": "Rock_Stone"
    },
    {
      "x": -12,
      "y": 27,
      "z": -4,
      "name": "Rock_Stone"
    },
    {
      "x": -12,
      "y": 28,
      "z": -4,
      "name": "Rock_Stone"
    },
    {
      "x": -12,
      "y": 29,
      "z": -4,
      "name": "Rock_Stone"
    },
    {
      "x": -12,
      "y": 30,
      "z": -4,
      "name": "Rock_Stone"
    },
    {
      "x": -12,
      "y": 31,
      "z": -4,
      "name": "Rock_Stone"
    },
    {
      "x": -12,
      "y": 32,
      "z": -4,
      "name": "Rock_Stone"
    },
    {
      "x": -12,
      "y": 33,
      "z": -4,
      "name": "Rock_Stone"
    },
    {
      "x": -12,
      "y": 34,
      "z": -4,
      "name": "Soil_Dirt"
    },
    {
      "x": -12,
      "y": 35,
      "z": -4,
      "name": "Soil_Grass"
    },
    {
      "x": -12,
      "y": 21,
      "z": -3,
      "name": "Rock_Stone"
    },
    {
      "x": -12,
      "y": 22,
      "z": -3,
      "name": "Rock_Stone"
    },
    {
      "x": -12,
      "y": 23,
      "z": -3,
      "name": "Rock_Stone"
    },
    {
      "x": -12,
      "y": 24,
      "z": -3,
      "name": "Rock_Stone"
    },
    {
      "x": -12,
      "y": 25,
      "z": -3,
      "name": "Rock_Stone"
    },
    {
      "x": -12,
      "y": 26,
      "z": -3,
      "name": "Rock_Stone"
    },
    {
      "x": -12,
      "y": 27,
      "z": -3,
      "name": "Rock_Stone"
    },
    {
      "x": -12,
      "y": 28,
      "z": -3,
      "name": "Rock_Stone"
    },
    {
      "x": -12,
      "y": 29,
      "z": -3,
      "name": "Rock_Stone"
    },
    {
      "x": -12,
      "y": 30,
      "z": -3,
      "name": "Rock_Stone"
    },
    {
      "x": -12,
      "y": 31,
      "z": -3,
      "name": "Rock_Stone"
    },
    {
      "x": -12,
      "y": 32,
      "z": -3,
      "name": "Rock_Stone"
    },
    {
      "x": -12,
      "y": 33,
      "z": -3,
      "name": "Soil_Dirt"
    },
    {
      "x": -12,
      "y": 34,
      "z": -3,
      "name": "Soil_Grass"
    },
    {
      "x": -12,
      "y": 35,
      "z": -3,
      "name": "Plant_Grass_Sharp"
    },
    {
      "x": -12,
      "y": 19,
      "z": -2,
      "name": "Rock_Stone"
    },
    {
      "x": -12,
      "y": 20,
      "z": -2,
      "name": "Rock_Stone"
    },
    {
      "x": -12,
      "y": 21,
      "z": -2,
      "name": "Rock_Stone"
    },
    {
      "x": -12,
      "y": 22,
      "z": -2,
      "name": "Rock_Stone"
    },
    {
      "x": -12,
      "y": 23,
      "z": -2,
      "name": "Rock_Stone"
    },
    {
      "x": -12,
      "y": 24,
      "z": -2,
      "name": "Rock_Stone"
    },
    {
      "x": -12,
      "y": 25,
      "z": -2,
      "name": "Rock_Stone"
    },
    {
      "x": -12,
      "y": 26,
      "z": -2,
      "name": "Rock_Stone"
    },
    {
      "x": -12,
      "y": 27,
      "z": -2,
      "name": "Rock_Stone"
    },
    {
      "x": -12,
      "y": 28,
      "z": -2,
      "name": "Rock_Stone"
    },
    {
      "x": -12,
      "y": 29,
      "z": -2,
      "name": "Rock_Stone"
    },
    {
      "x": -12,
      "y": 30,
      "z": -2,
      "name": "Rock_Stone"
    },
    {
      "x": -12,
      "y": 31,
      "z": -2,
      "name": "Rock_Stone"
    },
    {
      "x": -12,
      "y": 32,
      "z": -2,
      "name": "Soil_Dirt"
    },
    {
      "x": -12,
      "y": 33,
      "z": -2,
      "name": "Soil_Dirt"
    },
    {
      "x": -12,
      "y": 34,
      "z": -2,
      "name": "Soil_Grass"
    },
    {
      "x": -12,
      "y": 18,
      "z": -1,
      "name": "Rock_Stone"
    },
    {
      "x": -12,
      "y": 19,
      "z": -1,
      "name": "Rock_Stone"
    },
    {
      "x": -12,
      "y": 20,
      "z": -1,
      "name": "Rock_Stone"
    },
    {
      "x": -12,
      "y": 21,
      "z": -1,
      "name": "Rock_Stone"
    },
    {
      "x": -12,
      "y": 22,
      "z": -1,
      "name": "Rock_Stone"
    },
    {
      "x": -12,
      "y": 23,
      "z": -1,
      "name": "Rock_Stone"
    },
    {
      "x": -12,
      "y": 24,
      "z": -1,
      "name": "Rock_Stone"
    },
    {
      "x": -12,
      "y": 25,
      "z": -1,
      "name": "Rock_Stone"
    },
    {
      "x": -12,
      "y": 26,
      "z": -1,
      "name": "Rock_Stone"
    },
    {
      "x": -12,
      "y": 27,
      "z": -1,
      "name": "Rock_Stone"
    },
    {
      "x": -12,
      "y": 28,
      "z": -1,
      "name": "Rock_Stone"
    },
    {
      "x": -12,
      "y": 29,
      "z": -1,
      "name": "Rock_Stone"
    },
    {
      "x": -12,
      "y": 30,
      "z": -1,
      "name": "Rock_Stone"
    },
    {
      "x": -12,
      "y": 31,
      "z": -1,
      "name": "Rock_Stone"
    },
    {
      "x": -12,
      "y": 32,
      "z": -1,
      "name": "Soil_Dirt"
    },
    {
      "x": -12,
      "y": 33,
      "z": -1,
      "name": "Soil_Dirt"
    },
    {
      "x": -12,
      "y": 34,
      "z": -1,
      "name": "Soil_Grass"
    },
    {
      "x": -12,
      "y": 18,
      "z": 0,
      "name": "Rock_Stone"
    },
    {
      "x": -12,
      "y": 19,
      "z": 0,
      "name": "Rock_Stone"
    },
    {
      "x": -12,
      "y": 20,
      "z": 0,
      "name": "Rock_Stone"
    },
    {
      "x": -12,
      "y": 21,
      "z": 0,
      "name": "Rock_Stone"
    },
    {
      "x": -12,
      "y": 22,
      "z": 0,
      "name": "Rock_Stone"
    },
    {
      "x": -12,
      "y": 23,
      "z": 0,
      "name": "Rock_Stone"
    },
    {
      "x": -12,
      "y": 24,
      "z": 0,
      "name": "Rock_Stone"
    },
    {
      "x": -12,
      "y": 25,
      "z": 0,
      "name": "Rock_Stone"
    },
    {
      "x": -12,
      "y": 26,
      "z": 0,
      "name": "Rock_Stone"
    },
    {
      "x": -12,
      "y": 27,
      "z": 0,
      "name": "Rock_Stone"
    },
    {
      "x": -12,
      "y": 28,
      "z": 0,
      "name": "Rock_Stone"
    },
    {
      "x": -12,
      "y": 29,
      "z": 0,
      "name": "Rock_Stone"
    },
    {
      "x": -12,
      "y": 30,
      "z": 0,
      "name": "Rock_Stone"
    },
    {
      "x": -12,
      "y": 31,
      "z": 0,
      "name": "Soil_Dirt"
    },
    {
      "x": -12,
      "y": 32,
      "z": 0,
      "name": "Soil_Dirt"
    },
    {
      "x": -12,
      "y": 33,
      "z": 0,
      "name": "Soil_Grass"
    },
    {
      "x": -12,
      "y": 34,
      "z": 0,
      "name": "Plant_Grass_Sharp"
    },
    {
      "x": -12,
      "y": 39,
      "z": 0,
      "name": "Plant_Leaves_Oak",
      "rotation": 1
    },
    {
      "x": -12,
      "y": 9,
      "z": 1,
      "name": "Rock_Stone"
    },
    {
      "x": -12,
      "y": 10,
      "z": 1,
      "name": "Rock_Stone"
    },
    {
      "x": -12,
      "y": 11,
      "z": 1,
      "name": "Rock_Stone"
    },
    {
      "x": -12,
      "y": 19,
      "z": 1,
      "name": "Rock_Stone"
    },
    {
      "x": -12,
      "y": 20,
      "z": 1,
      "name": "Rock_Stone"
    },
    {
      "x": -12,
      "y": 21,
      "z": 1,
      "name": "Rock_Stone"
    },
    {
      "x": -12,
      "y": 22,
      "z": 1,
      "name": "Rock_Stone"
    },
    {
      "x": -12,
      "y": 23,
      "z": 1,
      "name": "Rock_Stone"
    },
    {
      "x": -12,
      "y": 24,
      "z": 1,
      "name": "Rock_Stone"
    },
    {
      "x": -12,
      "y": 25,
      "z": 1,
      "name": "Rock_Stone"
    },
    {
      "x": -12,
      "y": 26,
      "z": 1,
      "name": "Rock_Stone"
    },
    {
      "x": -12,
      "y": 27,
      "z": 1,
      "name": "Rock_Stone"
    },
    {
      "x": -12,
      "y": 28,
      "z": 1,
      "name": "Rock_Stone"
    },
    {
      "x": -12,
      "y": 29,
      "z": 1,
      "name": "Rock_Stone"
    },
    {
      "x": -12,
      "y": 30,
      "z": 1,
      "name": "Rock_Stone"
    },
    {
      "x": -12,
      "y": 31,
      "z": 1,
      "name": "Soil_Dirt"
    },
    {
      "x": -12,
      "y": 32,
      "z": 1,
      "name": "Soil_Dirt"
    },
    {
      "x": -12,
      "y": 33,
      "z": 1,
      "name": "Soil_Grass"
    },
    {
      "x": -12,
      "y": 34,
      "z": 1,
      "name": "Plant_Grass_Sharp"
    },
    {
      "x": -12,
      "y": 38,
      "z": 1,
      "name": "Plant_Leaves_Oak",
      "rotation": 1
    },
    {
      "x": -12,
      "y": 40,
      "z": 1,
      "name": "Plant_Leaves_Oak",
      "rotation": 1
    },
    {
      "x": -12,
      "y": 41,
      "z": 1,
      "name": "Plant_Leaves_Oak",
      "rotation": 1
    },
    {
      "x": -12,
      "y": 8,
      "z": 2,
      "name": "Rock_Stone"
    },
    {
      "x": -12,
      "y": 9,
      "z": 2,
      "name": "Rock_Stone"
    },
    {
      "x": -12,
      "y": 10,
      "z": 2,
      "name": "Rock_Stone"
    },
    {
      "x": -12,
      "y": 11,
      "z": 2,
      "name": "Rock_Stone"
    },
    {
      "x": -12,
      "y": 21,
      "z": 2,
      "name": "Rock_Stone"
    },
    {
      "x": -12,
      "y": 22,
      "z": 2,
      "name": "Rock_Stone"
    },
    {
      "x": -12,
      "y": 23,
      "z": 2,
      "name": "Rock_Stone"
    },
    {
      "x": -12,
      "y": 24,
      "z": 2,
      "name": "Rock_Stone"
    },
    {
      "x": -12,
      "y": 25,
      "z": 2,
      "name": "Rock_Stone"
    },
    {
      "x": -12,
      "y": 26,
      "z": 2,
      "name": "Rock_Stone"
    },
    {
      "x": -12,
      "y": 27,
      "z": 2,
      "name": "Rock_Stone"
    },
    {
      "x": -12,
      "y": 28,
      "z": 2,
      "name": "Rock_Stone"
    },
    {
      "x": -12,
      "y": 29,
      "z": 2,
      "name": "Rock_Stone"
    },
    {
      "x": -12,
      "y": 30,
      "z": 2,
      "name": "Rock_Stone"
    },
    {
      "x": -12,
      "y": 31,
      "z": 2,
      "name": "Soil_Dirt"
    },
    {
      "x": -12,
      "y": 32,
      "z": 2,
      "name": "Soil_Grass"
    },
    {
      "x": -12,
      "y": 38,
      "z": 2,
      "name": "Plant_Leaves_Oak",
      "rotation": 1
    },
    {
      "x": -12,
      "y": 41,
      "z": 2,
      "name": "Plant_Leaves_Oak",
      "rotation": 1
    },
    {
      "x": -12,
      "y": 42,
      "z": 2,
      "name": "Plant_Leaves_Oak",
      "rotation": 1
    },
    {
      "x": -12,
      "y": 6,
      "z": 3,
      "name": "Rock_Stone"
    },
    {
      "x": -12,
      "y": 7,
      "z": 3,
      "name": "Rock_Stone"
    },
    {
      "x": -12,
      "y": 8,
      "z": 3,
      "name": "Rock_Stone"
    },
    {
      "x": -12,
      "y": 9,
      "z": 3,
      "name": "Rock_Stone"
    },
    {
      "x": -12,
      "y": 10,
      "z": 3,
      "name": "Rock_Stone"
    },
    {
      "x": -12,
      "y": 11,
      "z": 3,
      "name": "Rock_Stone"
    },
    {
      "x": -12,
      "y": 23,
      "z": 3,
      "name": "Rock_Stone"
    },
    {
      "x": -12,
      "y": 24,
      "z": 3,
      "name": "Rock_Stone"
    },
    {
      "x": -12,
      "y": 25,
      "z": 3,
      "name": "Rock_Stone"
    },
    {
      "x": -12,
      "y": 26,
      "z": 3,
      "name": "Rock_Stone"
    },
    {
      "x": -12,
      "y": 27,
      "z": 3,
      "name": "Rock_Stone"
    },
    {
      "x": -12,
      "y": 28,
      "z": 3,
      "name": "Rock_Stone"
    },
    {
      "x": -12,
      "y": 29,
      "z": 3,
      "name": "Rock_Stone"
    },
    {
      "x": -12,
      "y": 30,
      "z": 3,
      "name": "Rock_Stone"
    },
    {
      "x": -12,
      "y": 31,
      "z": 3,
      "name": "Soil_Dirt"
    },
    {
      "x": -12,
      "y": 32,
      "z": 3,
      "name": "Soil_Grass"
    },
    {
      "x": -12,
      "y": 38,
      "z": 3,
      "name": "Wood_Oak_Branch_Long",
      "rotation": 5
    },
    {
      "x": -12,
      "y": 42,
      "z": 3,
      "name": "Plant_Leaves_Oak",
      "rotation": 1
    },
    {
      "x": -12,
      "y": 43,
      "z": 3,
      "name": "Plant_Leaves_Oak",
      "rotation": 1
    },
    {
      "x": -12,
      "y": 6,
      "z": 4,
      "name": "Rock_Stone"
    },
    {
      "x": -12,
      "y": 7,
      "z": 4,
      "name": "Rock_Stone"
    },
    {
      "x": -12,
      "y": 8,
      "z": 4,
      "name": "Rock_Stone"
    },
    {
      "x": -12,
      "y": 9,
      "z": 4,
      "name": "Rock_Stone"
    },
    {
      "x": -12,
      "y": 10,
      "z": 4,
      "name": "Rock_Stone"
    },
    {
      "x": -12,
      "y": 11,
      "z": 4,
      "name": "Rock_Stone"
    },
    {
      "x": -12,
      "y": 12,
      "z": 4,
      "name": "Rock_Stone"
    },
    {
      "x": -12,
      "y": 25,
      "z": 4,
      "name": "Rock_Stone"
    },
    {
      "x": -12,
      "y": 26,
      "z": 4,
      "name": "Rock_Stone"
    },
    {
      "x": -12,
      "y": 27,
      "z": 4,
      "name": "Rock_Stone"
    },
    {
      "x": -12,
      "y": 28,
      "z": 4,
      "name": "Rock_Stone"
    },
    {
      "x": -12,
      "y": 29,
      "z": 4,
      "name": "Rock_Stone"
    },
    {
      "x": -12,
      "y": 30,
      "z": 4,
      "name": "Rock_Stone"
    },
    {
      "x": -12,
      "y": 31,
      "z": 4,
      "name": "Soil_Dirt"
    },
    {
      "x": -12,
      "y": 32,
      "z": 4,
      "name": "Soil_Grass"
    },
    {
      "x": -12,
      "y": 36,
      "z": 4,
      "name": "Wood_Oak_Branch_Short",
      "rotation": 3
    },
    {
      "x": -12,
      "y": 38,
      "z": 4,
      "name": "Wood_Oak_Branch_Long",
      "rotation": 5
    },
    {
      "x": -12,
      "y": 43,
      "z": 4,
      "name": "Plant_Leaves_Oak",
      "rotation": 1
    },
    {
      "x": -12,
      "y": 7,
      "z": 5,
      "name": "Rock_Stone"
    },
    {
      "x": -12,
      "y": 8,
      "z": 5,
      "name": "Rock_Stone"
    },
    {
      "x": -12,
      "y": 9,
      "z": 5,
      "name": "Rock_Stone"
    },
    {
      "x": -12,
      "y": 10,
      "z": 5,
      "name": "Rock_Stone"
    },
    {
      "x": -12,
      "y": 11,
      "z": 5,
      "name": "Rock_Stone"
    },
    {
      "x": -12,
      "y": 40,
      "z": 5,
      "name": "Plant_Leaves_Oak",
      "rotation": 1
    },
    {
      "x": -12,
      "y": 42,
      "z": 5,
      "name": "Plant_Leaves_Oak",
      "rotation": 1
    },
    {
      "x": -12,
      "y": 38,
      "z": 6,
      "name": "Plant_Leaves_Oak",
      "rotation": 1
    },
    {
      "x": -12,
      "y": 40,
      "z": 6,
      "name": "Plant_Leaves_Oak",
      "rotation": 1
    },
    {
      "x": -12,
      "y": 38,
      "z": 7,
      "name": "Plant_Leaves_Oak",
      "rotation": 1
    },
    {
      "x": -12,
      "y": 39,
      "z": 7,
      "name": "Plant_Leaves_Oak",
      "rotation": 1
    },
    {
      "x": -12,
      "y": 40,
      "z": 7,
      "name": "Plant_Leaves_Oak",
      "rotation": 1
    },
    {
      "x": -11,
      "y": 33,
      "z": -7,
      "name": "Rock_Stone"
    },
    {
      "x": -11,
      "y": 34,
      "z": -7,
      "name": "Rock_Stone"
    },
    {
      "x": -11,
      "y": 22,
      "z": -6,
      "name": "Rock_Stone"
    },
    {
      "x": -11,
      "y": 23,
      "z": -6,
      "name": "Rock_Stone"
    },
    {
      "x": -11,
      "y": 24,
      "z": -6,
      "name": "Rock_Stone"
    },
    {
      "x": -11,
      "y": 27,
      "z": -6,
      "name": "Rock_Stone"
    },
    {
      "x": -11,
      "y": 28,
      "z": -6,
      "name": "Rock_Stone"
    },
    {
      "x": -11,
      "y": 29,
      "z": -6,
      "name": "Rock_Stone"
    },
    {
      "x": -11,
      "y": 30,
      "z": -6,
      "name": "Rock_Stone"
    },
    {
      "x": -11,
      "y": 31,
      "z": -6,
      "name": "Rock_Stone"
    },
    {
      "x": -11,
      "y": 32,
      "z": -6,
      "name": "Rock_Stone"
    },
    {
      "x": -11,
      "y": 33,
      "z": -6,
      "name": "Rock_Stone"
    },
    {
      "x": -11,
      "y": 34,
      "z": -6,
      "name": "Soil_Dirt"
    },
    {
      "x": -11,
      "y": 35,
      "z": -6,
      "name": "Soil_Grass"
    },
    {
      "x": -11,
      "y": 20,
      "z": -5,
      "name": "Rock_Stone"
    },
    {
      "x": -11,
      "y": 21,
      "z": -5,
      "name": "Rock_Stone"
    },
    {
      "x": -11,
      "y": 22,
      "z": -5,
      "name": "Rock_Stone"
    },
    {
      "x": -11,
      "y": 23,
      "z": -5,
      "name": "Rock_Stone"
    },
    {
      "x": -11,
      "y": 24,
      "z": -5,
      "name": "Rock_Stone"
    },
    {
      "x": -11,
      "y": 25,
      "z": -5,
      "name": "Rock_Stone"
    },
    {
      "x": -11,
      "y": 26,
      "z": -5,
      "name": "Rock_Stone"
    },
    {
      "x": -11,
      "y": 27,
      "z": -5,
      "name": "Rock_Stone"
    },
    {
      "x": -11,
      "y": 28,
      "z": -5,
      "name": "Rock_Stone"
    },
    {
      "x": -11,
      "y": 29,
      "z": -5,
      "name": "Rock_Stone"
    },
    {
      "x": -11,
      "y": 30,
      "z": -5,
      "name": "Rock_Stone"
    },
    {
      "x": -11,
      "y": 31,
      "z": -5,
      "name": "Rock_Stone"
    },
    {
      "x": -11,
      "y": 32,
      "z": -5,
      "name": "Rock_Stone"
    },
    {
      "x": -11,
      "y": 33,
      "z": -5,
      "name": "Rock_Stone"
    },
    {
      "x": -11,
      "y": 34,
      "z": -5,
      "name": "Soil_Dirt"
    },
    {
      "x": -11,
      "y": 35,
      "z": -5,
      "name": "Soil_Grass"
    },
    {
      "x": -11,
      "y": 19,
      "z": -4,
      "name": "Rock_Stone"
    },
    {
      "x": -11,
      "y": 20,
      "z": -4,
      "name": "Rock_Stone"
    },
    {
      "x": -11,
      "y": 21,
      "z": -4,
      "name": "Rock_Stone"
    },
    {
      "x": -11,
      "y": 22,
      "z": -4,
      "name": "Rock_Stone"
    },
    {
      "x": -11,
      "y": 23,
      "z": -4,
      "name": "Rock_Stone"
    },
    {
      "x": -11,
      "y": 24,
      "z": -4,
      "name": "Rock_Stone"
    },
    {
      "x": -11,
      "y": 25,
      "z": -4,
      "name": "Rock_Stone"
    },
    {
      "x": -11,
      "y": 26,
      "z": -4,
      "name": "Rock_Stone"
    },
    {
      "x": -11,
      "y": 27,
      "z": -4,
      "name": "Rock_Stone"
    },
    {
      "x": -11,
      "y": 28,
      "z": -4,
      "name": "Rock_Stone"
    },
    {
      "x": -11,
      "y": 29,
      "z": -4,
      "name": "Rock_Stone"
    },
    {
      "x": -11,
      "y": 30,
      "z": -4,
      "name": "Rock_Stone"
    },
    {
      "x": -11,
      "y": 31,
      "z": -4,
      "name": "Rock_Stone"
    },
    {
      "x": -11,
      "y": 32,
      "z": -4,
      "name": "Rock_Stone"
    },
    {
      "x": -11,
      "y": 33,
      "z": -4,
      "name": "Soil_Dirt"
    },
    {
      "x": -11,
      "y": 34,
      "z": -4,
      "name": "Soil_Dirt"
    },
    {
      "x": -11,
      "y": 35,
      "z": -4,
      "name": "Soil_Grass"
    },
    {
      "x": -11,
      "y": 7,
      "z": -3,
      "name": "Rock_Stone"
    },
    {
      "x": -11,
      "y": 16,
      "z": -3,
      "name": "Rock_Stone"
    },
    {
      "x": -11,
      "y": 17,
      "z": -3,
      "name": "Rock_Stone"
    },
    {
      "x": -11,
      "y": 18,
      "z": -3,
      "name": "Rock_Stone"
    },
    {
      "x": -11,
      "y": 19,
      "z": -3,
      "name": "Rock_Stone"
    },
    {
      "x": -11,
      "y": 20,
      "z": -3,
      "name": "Rock_Stone"
    },
    {
      "x": -11,
      "y": 21,
      "z": -3,
      "name": "Rock_Stone"
    },
    {
      "x": -11,
      "y": 22,
      "z": -3,
      "name": "Rock_Stone"
    },
    {
      "x": -11,
      "y": 23,
      "z": -3,
      "name": "Rock_Stone"
    },
    {
      "x": -11,
      "y": 24,
      "z": -3,
      "name": "Rock_Stone"
    },
    {
      "x": -11,
      "y": 25,
      "z": -3,
      "name": "Rock_Stone"
    },
    {
      "x": -11,
      "y": 26,
      "z": -3,
      "name": "Rock_Stone"
    },
    {
      "x": -11,
      "y": 27,
      "z": -3,
      "name": "Rock_Stone"
    },
    {
      "x": -11,
      "y": 28,
      "z": -3,
      "name": "Rock_Stone"
    },
    {
      "x": -11,
      "y": 29,
      "z": -3,
      "name": "Rock_Stone"
    },
    {
      "x": -11,
      "y": 30,
      "z": -3,
      "name": "Rock_Stone"
    },
    {
      "x": -11,
      "y": 31,
      "z": -3,
      "name": "Rock_Stone"
    },
    {
      "x": -11,
      "y": 32,
      "z": -3,
      "name": "Rock_Stone"
    },
    {
      "x": -11,
      "y": 33,
      "z": -3,
      "name": "Soil_Dirt"
    },
    {
      "x": -11,
      "y": 34,
      "z": -3,
      "name": "Soil_Grass"
    },
    {
      "x": -11,
      "y": 5,
      "z": -2,
      "name": "Rock_Stone"
    },
    {
      "x": -11,
      "y": 6,
      "z": -2,
      "name": "Rock_Stone"
    },
    {
      "x": -11,
      "y": 7,
      "z": -2,
      "name": "Rock_Stone"
    },
    {
      "x": -11,
      "y": 8,
      "z": -2,
      "name": "Rock_Stone"
    },
    {
      "x": -11,
      "y": 9,
      "z": -2,
      "name": "Rock_Stone"
    },
    {
      "x": -11,
      "y": 10,
      "z": -2,
      "name": "Rock_Stone"
    },
    {
      "x": -11,
      "y": 11,
      "z": -2,
      "name": "Rock_Stone"
    },
    {
      "x": -11,
      "y": 15,
      "z": -2,
      "name": "Rock_Stone"
    },
    {
      "x": -11,
      "y": 16,
      "z": -2,
      "name": "Rock_Stone"
    },
    {
      "x": -11,
      "y": 17,
      "z": -2,
      "name": "Rock_Stone"
    },
    {
      "x": -11,
      "y": 18,
      "z": -2,
      "name": "Rock_Stone"
    },
    {
      "x": -11,
      "y": 19,
      "z": -2,
      "name": "Rock_Stone"
    },
    {
      "x": -11,
      "y": 20,
      "z": -2,
      "name": "Rock_Stone"
    },
    {
      "x": -11,
      "y": 21,
      "z": -2,
      "name": "Rock_Stone"
    },
    {
      "x": -11,
      "y": 22,
      "z": -2,
      "name": "Rock_Stone"
    },
    {
      "x": -11,
      "y": 23,
      "z": -2,
      "name": "Rock_Stone"
    },
    {
      "x": -11,
      "y": 24,
      "z": -2,
      "name": "Rock_Stone"
    },
    {
      "x": -11,
      "y": 25,
      "z": -2,
      "name": "Rock_Stone"
    },
    {
      "x": -11,
      "y": 26,
      "z": -2,
      "name": "Rock_Stone"
    },
    {
      "x": -11,
      "y": 27,
      "z": -2,
      "name": "Rock_Stone"
    },
    {
      "x": -11,
      "y": 28,
      "z": -2,
      "name": "Rock_Stone"
    },
    {
      "x": -11,
      "y": 29,
      "z": -2,
      "name": "Rock_Stone"
    },
    {
      "x": -11,
      "y": 30,
      "z": -2,
      "name": "Rock_Stone"
    },
    {
      "x": -11,
      "y": 31,
      "z": -2,
      "name": "Rock_Stone"
    },
    {
      "x": -11,
      "y": 32,
      "z": -2,
      "name": "Soil_Dirt"
    },
    {
      "x": -11,
      "y": 33,
      "z": -2,
      "name": "Soil_Dirt"
    },
    {
      "x": -11,
      "y": 34,
      "z": -2,
      "name": "Soil_Grass"
    },
    {
      "x": -11,
      "y": 4,
      "z": -1,
      "name": "Rock_Stone"
    },
    {
      "x": -11,
      "y": 5,
      "z": -1,
      "name": "Rock_Stone"
    },
    {
      "x": -11,
      "y": 6,
      "z": -1,
      "name": "Rock_Stone"
    },
    {
      "x": -11,
      "y": 7,
      "z": -1,
      "name": "Rock_Stone"
    },
    {
      "x": -11,
      "y": 8,
      "z": -1,
      "name": "Rock_Stone"
    },
    {
      "x": -11,
      "y": 9,
      "z": -1,
      "name": "Rock_Stone"
    },
    {
      "x": -11,
      "y": 10,
      "z": -1,
      "name": "Rock_Stone"
    },
    {
      "x": -11,
      "y": 11,
      "z": -1,
      "name": "Rock_Stone"
    },
    {
      "x": -11,
      "y": 12,
      "z": -1,
      "name": "Rock_Stone"
    },
    {
      "x": -11,
      "y": 13,
      "z": -1,
      "name": "Rock_Stone"
    },
    {
      "x": -11,
      "y": 14,
      "z": -1,
      "name": "Rock_Stone"
    },
    {
      "x": -11,
      "y": 15,
      "z": -1,
      "name": "Rock_Stone"
    },
    {
      "x": -11,
      "y": 16,
      "z": -1,
      "name": "Rock_Stone"
    },
    {
      "x": -11,
      "y": 17,
      "z": -1,
      "name": "Rock_Stone"
    },
    {
      "x": -11,
      "y": 18,
      "z": -1,
      "name": "Rock_Stone"
    },
    {
      "x": -11,
      "y": 19,
      "z": -1,
      "name": "Rock_Stone"
    },
    {
      "x": -11,
      "y": 20,
      "z": -1,
      "name": "Rock_Stone"
    },
    {
      "x": -11,
      "y": 21,
      "z": -1,
      "name": "Rock_Stone"
    },
    {
      "x": -11,
      "y": 22,
      "z": -1,
      "name": "Rock_Stone"
    },
    {
      "x": -11,
      "y": 23,
      "z": -1,
      "name": "Rock_Stone"
    },
    {
      "x": -11,
      "y": 24,
      "z": -1,
      "name": "Rock_Stone"
    },
    {
      "x": -11,
      "y": 25,
      "z": -1,
      "name": "Rock_Stone"
    },
    {
      "x": -11,
      "y": 26,
      "z": -1,
      "name": "Rock_Stone"
    },
    {
      "x": -11,
      "y": 27,
      "z": -1,
      "name": "Rock_Stone"
    },
    {
      "x": -11,
      "y": 28,
      "z": -1,
      "name": "Rock_Stone"
    },
    {
      "x": -11,
      "y": 29,
      "z": -1,
      "name": "Rock_Stone"
    },
    {
      "x": -11,
      "y": 30,
      "z": -1,
      "name": "Rock_Stone"
    },
    {
      "x": -11,
      "y": 31,
      "z": -1,
      "name": "Rock_Stone"
    },
    {
      "x": -11,
      "y": 32,
      "z": -1,
      "name": "Soil_Dirt"
    },
    {
      "x": -11,
      "y": 33,
      "z": -1,
      "name": "Soil_Dirt"
    },
    {
      "x": -11,
      "y": 34,
      "z": -1,
      "name": "Soil_Grass"
    },
    {
      "x": -11,
      "y": 3,
      "z": 0,
      "name": "Rock_Stone"
    },
    {
      "x": -11,
      "y": 4,
      "z": 0,
      "name": "Rock_Stone"
    },
    {
      "x": -11,
      "y": 5,
      "z": 0,
      "name": "Rock_Stone"
    },
    {
      "x": -11,
      "y": 6,
      "z": 0,
      "name": "Rock_Stone"
    },
    {
      "x": -11,
      "y": 7,
      "z": 0,
      "name": "Rock_Stone"
    },
    {
      "x": -11,
      "y": 8,
      "z": 0,
      "name": "Rock_Stone"
    },
    {
      "x": -11,
      "y": 9,
      "z": 0,
      "name": "Rock_Stone"
    },
    {
      "x": -11,
      "y": 10,
      "z": 0,
      "name": "Rock_Stone"
    },
    {
      "x": -11,
      "y": 11,
      "z": 0,
      "name": "Rock_Stone"
    },
    {
      "x": -11,
      "y": 12,
      "z": 0,
      "name": "Rock_Stone"
    },
    {
      "x": -11,
      "y": 13,
      "z": 0,
      "name": "Rock_Stone"
    },
    {
      "x": -11,
      "y": 14,
      "z": 0,
      "name": "Rock_Stone"
    },
    {
      "x": -11,
      "y": 15,
      "z": 0,
      "name": "Rock_Stone"
    },
    {
      "x": -11,
      "y": 16,
      "z": 0,
      "name": "Rock_Stone"
    },
    {
      "x": -11,
      "y": 17,
      "z": 0,
      "name": "Rock_Stone"
    },
    {
      "x": -11,
      "y": 18,
      "z": 0,
      "name": "Rock_Stone"
    },
    {
      "x": -11,
      "y": 19,
      "z": 0,
      "name": "Rock_Stone"
    },
    {
      "x": -11,
      "y": 20,
      "z": 0,
      "name": "Rock_Stone"
    },
    {
      "x": -11,
      "y": 21,
      "z": 0,
      "name": "Rock_Stone"
    },
    {
      "x": -11,
      "y": 22,
      "z": 0,
      "name": "Rock_Stone"
    },
    {
      "x": -11,
      "y": 23,
      "z": 0,
      "name": "Rock_Stone"
    },
    {
      "x": -11,
      "y": 24,
      "z": 0,
      "name": "Rock_Stone"
    },
    {
      "x": -11,
      "y": 25,
      "z": 0,
      "name": "Rock_Stone"
    },
    {
      "x": -11,
      "y": 26,
      "z": 0,
      "name": "Rock_Stone"
    },
    {
      "x": -11,
      "y": 27,
      "z": 0,
      "name": "Rock_Stone"
    },
    {
      "x": -11,
      "y": 28,
      "z": 0,
      "name": "Rock_Stone"
    },
    {
      "x": -11,
      "y": 29,
      "z": 0,
      "name": "Rock_Stone"
    },
    {
      "x": -11,
      "y": 30,
      "z": 0,
      "name": "Rock_Stone"
    },
    {
      "x": -11,
      "y": 31,
      "z": 0,
      "name": "Soil_Dirt"
    },
    {
      "x": -11,
      "y": 32,
      "z": 0,
      "name": "Soil_Dirt"
    },
    {
      "x": -11,
      "y": 33,
      "z": 0,
      "name": "Soil_Grass"
    },
    {
      "x": -11,
      "y": 39,
      "z": 0,
      "name": "Plant_Leaves_Oak",
      "rotation": 1
    },
    {
      "x": -11,
      "y": 40,
      "z": 0,
      "name": "Plant_Leaves_Oak",
      "rotation": 1
    },
    {
      "x": -11,
      "y": 3,
      "z": 1,
      "name": "Rock_Stone"
    },
    {
      "x": -11,
      "y": 4,
      "z": 1,
      "name": "Rock_Stone"
    },
    {
      "x": -11,
      "y": 5,
      "z": 1,
      "name": "Rock_Stone"
    },
    {
      "x": -11,
      "y": 6,
      "z": 1,
      "name": "Rock_Stone"
    },
    {
      "x": -11,
      "y": 7,
      "z": 1,
      "name": "Rock_Stone"
    },
    {
      "x": -11,
      "y": 8,
      "z": 1,
      "name": "Rock_Stone"
    },
    {
      "x": -11,
      "y": 9,
      "z": 1,
      "name": "Rock_Stone"
    },
    {
      "x": -11,
      "y": 10,
      "z": 1,
      "name": "Rock_Stone"
    },
    {
      "x": -11,
      "y": 11,
      "z": 1,
      "name": "Rock_Stone"
    },
    {
      "x": -11,
      "y": 12,
      "z": 1,
      "name": "Rock_Stone"
    },
    {
      "x": -11,
      "y": 13,
      "z": 1,
      "name": "Rock_Stone"
    },
    {
      "x": -11,
      "y": 14,
      "z": 1,
      "name": "Rock_Stone"
    },
    {
      "x": -11,
      "y": 15,
      "z": 1,
      "name": "Rock_Stone"
    },
    {
      "x": -11,
      "y": 16,
      "z": 1,
      "name": "Rock_Stone"
    },
    {
      "x": -11,
      "y": 17,
      "z": 1,
      "name": "Rock_Stone"
    },
    {
      "x": -11,
      "y": 18,
      "z": 1,
      "name": "Rock_Stone"
    },
    {
      "x": -11,
      "y": 19,
      "z": 1,
      "name": "Rock_Stone"
    },
    {
      "x": -11,
      "y": 20,
      "z": 1,
      "name": "Rock_Stone"
    },
    {
      "x": -11,
      "y": 21,
      "z": 1,
      "name": "Rock_Stone"
    },
    {
      "x": -11,
      "y": 22,
      "z": 1,
      "name": "Rock_Stone"
    },
    {
      "x": -11,
      "y": 23,
      "z": 1,
      "name": "Rock_Stone"
    },
    {
      "x": -11,
      "y": 24,
      "z": 1,
      "name": "Rock_Stone"
    },
    {
      "x": -11,
      "y": 25,
      "z": 1,
      "name": "Rock_Stone"
    },
    {
      "x": -11,
      "y": 26,
      "z": 1,
      "name": "Rock_Stone"
    },
    {
      "x": -11,
      "y": 27,
      "z": 1,
      "name": "Rock_Stone"
    },
    {
      "x": -11,
      "y": 28,
      "z": 1,
      "name": "Rock_Stone"
    },
    {
      "x": -11,
      "y": 29,
      "z": 1,
      "name": "Rock_Stone"
    },
    {
      "x": -11,
      "y": 30,
      "z": 1,
      "name": "Rock_Stone"
    },
    {
      "x": -11,
      "y": 31,
      "z": 1,
      "name": "Soil_Dirt"
    },
    {
      "x": -11,
      "y": 32,
      "z": 1,
      "name": "Soil_Dirt"
    },
    {
      "x": -11,
      "y": 33,
      "z": 1,
      "name": "Soil_Grass"
    },
    {
      "x": -11,
      "y": 34,
      "z": 1,
      "name": "Plant_Grass_Sharp"
    },
    {
      "x": -11,
      "y": 38,
      "z": 1,
      "name": "Plant_Leaves_Oak",
      "rotation": 1
    },
    {
      "x": -11,
      "y": 39,
      "z": 1,
      "name": "Plant_Leaves_Oak",
      "rotation": 1
    },
    {
      "x": -11,
      "y": 40,
      "z": 1,
      "name": "Wood_Oak_Branch_Long",
      "rotation": 1
    },
    {
      "x": -11,
      "y": 41,
      "z": 1,
      "name": "Plant_Leaves_Oak",
      "rotation": 1
    },
    {
      "x": -11,
      "y": 2,
      "z": 2,
      "name": "Rock_Stone"
    },
    {
      "x": -11,
      "y": 3,
      "z": 2,
      "name": "Rock_Stone"
    },
    {
      "x": -11,
      "y": 4,
      "z": 2,
      "name": "Rock_Stone"
    },
    {
      "x": -11,
      "y": 5,
      "z": 2,
      "name": "Rock_Stone"
    },
    {
      "x": -11,
      "y": 6,
      "z": 2,
      "name": "Rock_Stone"
    },
    {
      "x": -11,
      "y": 7,
      "z": 2,
      "name": "Rock_Stone"
    },
    {
      "x": -11,
      "y": 8,
      "z": 2,
      "name": "Rock_Stone"
    },
    {
      "x": -11,
      "y": 9,
      "z": 2,
      "name": "Rock_Stone"
    },
    {
      "x": -11,
      "y": 10,
      "z": 2,
      "name": "Rock_Stone"
    },
    {
      "x": -11,
      "y": 11,
      "z": 2,
      "name": "Rock_Stone"
    },
    {
      "x": -11,
      "y": 12,
      "z": 2,
      "name": "Rock_Stone"
    },
    {
      "x": -11,
      "y": 13,
      "z": 2,
      "name": "Rock_Stone"
    },
    {
      "x": -11,
      "y": 14,
      "z": 2,
      "name": "Rock_Stone"
    },
    {
      "x": -11,
      "y": 15,
      "z": 2,
      "name": "Rock_Stone"
    },
    {
      "x": -11,
      "y": 16,
      "z": 2,
      "name": "Rock_Stone"
    },
    {
      "x": -11,
      "y": 17,
      "z": 2,
      "name": "Rock_Stone"
    },
    {
      "x": -11,
      "y": 18,
      "z": 2,
      "name": "Rock_Stone"
    },
    {
      "x": -11,
      "y": 19,
      "z": 2,
      "name": "Rock_Stone"
    },
    {
      "x": -11,
      "y": 20,
      "z": 2,
      "name": "Rock_Stone"
    },
    {
      "x": -11,
      "y": 21,
      "z": 2,
      "name": "Rock_Stone"
    },
    {
      "x": -11,
      "y": 22,
      "z": 2,
      "name": "Rock_Stone"
    },
    {
      "x": -11,
      "y": 23,
      "z": 2,
      "name": "Rock_Stone"
    },
    {
      "x": -11,
      "y": 24,
      "z": 2,
      "name": "Rock_Stone"
    },
    {
      "x": -11,
      "y": 25,
      "z": 2,
      "name": "Rock_Stone"
    },
    {
      "x": -11,
      "y": 26,
      "z": 2,
      "name": "Rock_Stone"
    },
    {
      "x": -11,
      "y": 27,
      "z": 2,
      "name": "Rock_Stone"
    },
    {
      "x": -11,
      "y": 28,
      "z": 2,
      "name": "Rock_Stone"
    },
    {
      "x": -11,
      "y": 29,
      "z": 2,
      "name": "Rock_Stone"
    },
    {
      "x": -11,
      "y": 30,
      "z": 2,
      "name": "Rock_Stone"
    },
    {
      "x": -11,
      "y": 31,
      "z": 2,
      "name": "Soil_Dirt"
    },
    {
      "x": -11,
      "y": 32,
      "z": 2,
      "name": "Soil_Grass"
    },
    {
      "x": -11,
      "y": 37,
      "z": 2,
      "name": "Plant_Leaves_Oak",
      "rotation": 1
    },
    {
      "x": -11,
      "y": 38,
      "z": 2,
      "name": "Wood_Oak_Branch_Corner",
      "rotation": 2
    },
    {
      "x": -11,
      "y": 39,
      "z": 2,
      "name": "Wood_Oak_Branch_Long",
      "rotation": 1
    },
    {
      "x": -11,
      "y": 40,
      "z": 2,
      "name": "Wood_Oak_Branch_Long",
      "rotation": 1
    },
    {
      "x": -11,
      "y": 41,
      "z": 2,
      "name": "Plant_Leaves_Oak",
      "rotation": 1
    },
    {
      "x": -11,
      "y": 42,
      "z": 2,
      "name": "Plant_Leaves_Oak",
      "rotation": 1
    },
    {
      "x": -11,
      "y": 43,
      "z": 2,
      "name": "Plant_Leaves_Oak",
      "rotation": 1
    },
    {
      "x": -11,
      "y": 3,
      "z": 3,
      "name": "Rock_Stone"
    },
    {
      "x": -11,
      "y": 4,
      "z": 3,
      "name": "Rock_Stone"
    },
    {
      "x": -11,
      "y": 5,
      "z": 3,
      "name": "Rock_Stone"
    },
    {
      "x": -11,
      "y": 6,
      "z": 3,
      "name": "Rock_Stone"
    },
    {
      "x": -11,
      "y": 7,
      "z": 3,
      "name": "Rock_Stone"
    },
    {
      "x": -11,
      "y": 8,
      "z": 3,
      "name": "Rock_Stone"
    },
    {
      "x": -11,
      "y": 9,
      "z": 3,
      "name": "Rock_Stone"
    },
    {
      "x": -11,
      "y": 10,
      "z": 3,
      "name": "Rock_Stone"
    },
    {
      "x": -11,
      "y": 11,
      "z": 3,
      "name": "Rock_Stone"
    },
    {
      "x": -11,
      "y": 12,
      "z": 3,
      "name": "Rock_Stone"
    },
    {
      "x": -11,
      "y": 13,
      "z": 3,
      "name": "Rock_Stone"
    },
    {
      "x": -11,
      "y": 14,
      "z": 3,
      "name": "Rock_Stone"
    },
    {
      "x": -11,
      "y": 15,
      "z": 3,
      "name": "Rock_Stone"
    },
    {
      "x": -11,
      "y": 16,
      "z": 3,
      "name": "Rock_Stone"
    },
    {
      "x": -11,
      "y": 18,
      "z": 3,
      "name": "Rock_Stone"
    },
    {
      "x": -11,
      "y": 19,
      "z": 3,
      "name": "Rock_Stone"
    },
    {
      "x": -11,
      "y": 20,
      "z": 3,
      "name": "Rock_Stone"
    },
    {
      "x": -11,
      "y": 21,
      "z": 3,
      "name": "Rock_Stone"
    },
    {
      "x": -11,
      "y": 22,
      "z": 3,
      "name": "Rock_Stone"
    },
    {
      "x": -11,
      "y": 23,
      "z": 3,
      "name": "Rock_Stone"
    },
    {
      "x": -11,
      "y": 24,
      "z": 3,
      "name": "Rock_Stone"
    },
    {
      "x": -11,
      "y": 25,
      "z": 3,
      "name": "Rock_Stone"
    },
    {
      "x": -11,
      "y": 26,
      "z": 3,
      "name": "Rock_Stone"
    },
    {
      "x": -11,
      "y": 27,
      "z": 3,
      "name": "Rock_Stone"
    },
    {
      "x": -11,
      "y": 28,
      "z": 3,
      "name": "Rock_Stone"
    },
    {
      "x": -11,
      "y": 29,
      "z": 3,
      "name": "Rock_Stone"
    },
    {
      "x": -11,
      "y": 30,
      "z": 3,
      "name": "Rock_Stone"
    },
    {
      "x": -11,
      "y": 31,
      "z": 3,
      "name": "Soil_Dirt"
    },
    {
      "x": -11,
      "y": 32,
      "z": 3,
      "name": "Soil_Grass"
    },
    {
      "x": -11,
      "y": 33,
      "z": 3,
      "name": "Plant_Grass_Lush_Short"
    },
    {
      "x": -11,
      "y": 38,
      "z": 3,
      "name": "Wood_Oak_Branch_Long",
      "rotation": 6
    },
    {
      "x": -11,
      "y": 41,
      "z": 3,
      "name": "Wood_Oak_Branch_Long",
      "rotation": 6
    },
    {
      "x": -11,
      "y": 43,
      "z": 3,
      "name": "Plant_Leaves_Oak",
      "rotation": 1
    },
    {
      "x": -11,
      "y": 4,
      "z": 4,
      "name": "Rock_Stone"
    },
    {
      "x": -11,
      "y": 5,
      "z": 4,
      "name": "Rock_Stone"
    },
    {
      "x": -11,
      "y": 6,
      "z": 4,
      "name": "Rock_Stone"
    },
    {
      "x": -11,
      "y": 7,
      "z": 4,
      "name": "Rock_Stone"
    },
    {
      "x": -11,
      "y": 8,
      "z": 4,
      "name": "Rock_Stone"
    },
    {
      "x": -11,
      "y": 9,
      "z": 4,
      "name": "Rock_Stone"
    },
    {
      "x": -11,
      "y": 10,
      "z": 4,
      "name": "Rock_Stone"
    },
    {
      "x": -11,
      "y": 11,
      "z": 4,
      "name": "Rock_Stone"
    },
    {
      "x": -11,
      "y": 12,
      "z": 4,
      "name": "Rock_Stone"
    },
    {
      "x": -11,
      "y": 13,
      "z": 4,
      "name": "Rock_Stone"
    },
    {
      "x": -11,
      "y": 14,
      "z": 4,
      "name": "Rock_Stone"
    },
    {
      "x": -11,
      "y": 15,
      "z": 4,
      "name": "Rock_Stone"
    },
    {
      "x": -11,
      "y": 24,
      "z": 4,
      "name": "Rock_Stone"
    },
    {
      "x": -11,
      "y": 25,
      "z": 4,
      "name": "Rock_Stone"
    },
    {
      "x": -11,
      "y": 26,
      "z": 4,
      "name": "Rock_Stone"
    },
    {
      "x": -11,
      "y": 27,
      "z": 4,
      "name": "Rock_Stone"
    },
    {
      "x": -11,
      "y": 28,
      "z": 4,
      "name": "Rock_Stone"
    },
    {
      "x": -11,
      "y": 29,
      "z": 4,
      "name": "Rock_Stone"
    },
    {
      "x": -11,
      "y": 30,
      "z": 4,
      "name": "Wood_Oak_Trunk",
      "rotation": 1
    },
    {
      "x": -11,
      "y": 31,
      "z": 4,
      "name": "Wood_Oak_Trunk",
      "rotation": 1
    },
    {
      "x": -11,
      "y": 32,
      "z": 4,
      "name": "Wood_Oak_Trunk",
      "rotation": 1
    },
    {
      "x": -11,
      "y": 33,
      "z": 4,
      "name": "Wood_Oak_Trunk",
      "rotation": 1
    },
    {
      "x": -11,
      "y": 34,
      "z": 4,
      "name": "Wood_Oak_Trunk",
      "rotation": 1
    },
    {
      "x": -11,
      "y": 35,
      "z": 4,
      "name": "Wood_Oak_Trunk",
      "rotation": 1
    },
    {
      "x": -11,
      "y": 36,
      "z": 4,
      "name": "Wood_Oak_Trunk",
      "rotation": 1
    },
    {
      "x": -11,
      "y": 37,
      "z": 4,
      "name": "Wood_Oak_Trunk",
      "rotation": 1
    },
    {
      "x": -11,
      "y": 38,
      "z": 4,
      "name": "Wood_Oak_Trunk",
      "rotation": 1
    },
    {
      "x": -11,
      "y": 39,
      "z": 4,
      "name": "Wood_Oak_Trunk",
      "rotation": 1
    },
    {
      "x": -11,
      "y": 40,
      "z": 4,
      "name": "Wood_Oak_Trunk",
      "rotation": 1
    },
    {
      "x": -11,
      "y": 41,
      "z": 4,
      "name": "Wood_Oak_Trunk",
      "rotation": 1
    },
    {
      "x": -11,
      "y": 42,
      "z": 4,
      "name": "Wood_Oak_Trunk",
      "rotation": 1
    },
    {
      "x": -11,
      "y": 43,
      "z": 4,
      "name": "Plant_Leaves_Oak",
      "rotation": 1
    },
    {
      "x": -11,
      "y": 5,
      "z": 5,
      "name": "Rock_Stone"
    },
    {
      "x": -11,
      "y": 6,
      "z": 5,
      "name": "Rock_Stone"
    },
    {
      "x": -11,
      "y": 7,
      "z": 5,
      "name": "Rock_Stone"
    },
    {
      "x": -11,
      "y": 8,
      "z": 5,
      "name": "Rock_Stone"
    },
    {
      "x": -11,
      "y": 9,
      "z": 5,
      "name": "Rock_Stone"
    },
    {
      "x": -11,
      "y": 10,
      "z": 5,
      "name": "Rock_Stone"
    },
    {
      "x": -11,
      "y": 11,
      "z": 5,
      "name": "Rock_Stone"
    },
    {
      "x": -11,
      "y": 12,
      "z": 5,
      "name": "Rock_Stone"
    },
    {
      "x": -11,
      "y": 13,
      "z": 5,
      "name": "Rock_Stone"
    },
    {
      "x": -11,
      "y": 14,
      "z": 5,
      "name": "Rock_Stone"
    },
    {
      "x": -11,
      "y": 38,
      "z": 5,
      "name": "Wood_Oak_Branch_Long",
      "rotation": 6
    },
    {
      "x": -11,
      "y": 39,
      "z": 5,
      "name": "Wood_Oak_Branch_Long",
      "rotation": 6
    },
    {
      "x": -11,
      "y": 42,
      "z": 5,
      "name": "Plant_Leaves_Oak",
      "rotation": 1
    },
    {
      "x": -11,
      "y": 43,
      "z": 5,
      "name": "Plant_Leaves_Oak",
      "rotation": 1
    },
    {
      "x": -11,
      "y": 8,
      "z": 6,
      "name": "Rock_Stone"
    },
    {
      "x": -11,
      "y": 9,
      "z": 6,
      "name": "Rock_Stone"
    },
    {
      "x": -11,
      "y": 10,
      "z": 6,
      "name": "Rock_Stone"
    },
    {
      "x": -11,
      "y": 11,
      "z": 6,
      "name": "Rock_Stone"
    },
    {
      "x": -11,
      "y": 12,
      "z": 6,
      "name": "Rock_Stone"
    },
    {
      "x": -11,
      "y": 38,
      "z": 6,
      "name": "Plant_Leaves_Oak",
      "rotation": 1
    },
    {
      "x": -11,
      "y": 39,
      "z": 6,
      "name": "Wood_Oak_Branch_Corner"
    },
    {
      "x": -11,
      "y": 40,
      "z": 6,
      "name": "Plant_Leaves_Oak",
      "rotation": 1
    },
    {
      "x": -11,
      "y": 41,
      "z": 6,
      "name": "Plant_Leaves_Oak",
      "rotation": 1
    },
    {
      "x": -11,
      "y": 42,
      "z": 6,
      "name": "Plant_Leaves_Oak",
      "rotation": 1
    },
    {
      "x": -11,
      "y": 38,
      "z": 7,
      "name": "Plant_Leaves_Oak",
      "rotation": 1
    },
    {
      "x": -11,
      "y": 39,
      "z": 7,
      "name": "Plant_Leaves_Oak",
      "rotation": 1
    },
    {
      "x": -11,
      "y": 40,
      "z": 7,
      "name": "Plant_Leaves_Oak",
      "rotation": 1
    },
    {
      "x": -11,
      "y": 41,
      "z": 7,
      "name": "Plant_Leaves_Oak",
      "rotation": 1
    },
    {
      "x": -10,
      "y": 30,
      "z": -7,
      "name": "Rock_Stone"
    },
    {
      "x": -10,
      "y": 31,
      "z": -7,
      "name": "Rock_Stone"
    },
    {
      "x": -10,
      "y": 32,
      "z": -7,
      "name": "Rock_Stone"
    },
    {
      "x": -10,
      "y": 33,
      "z": -7,
      "name": "Rock_Stone"
    },
    {
      "x": -10,
      "y": 34,
      "z": -7,
      "name": "Rock_Stone"
    },
    {
      "x": -10,
      "y": 35,
      "z": -7,
      "name": "Soil_Grass"
    },
    {
      "x": -10,
      "y": 36,
      "z": -7,
      "name": "Plant_Grass_Sharp"
    },
    {
      "x": -10,
      "y": 24,
      "z": -6,
      "name": "Rock_Stone"
    },
    {
      "x": -10,
      "y": 25,
      "z": -6,
      "name": "Rock_Stone"
    },
    {
      "x": -10,
      "y": 26,
      "z": -6,
      "name": "Rock_Stone"
    },
    {
      "x": -10,
      "y": 27,
      "z": -6,
      "name": "Rock_Stone"
    },
    {
      "x": -10,
      "y": 28,
      "z": -6,
      "name": "Rock_Stone"
    },
    {
      "x": -10,
      "y": 29,
      "z": -6,
      "name": "Rock_Stone"
    },
    {
      "x": -10,
      "y": 30,
      "z": -6,
      "name": "Rock_Stone"
    },
    {
      "x": -10,
      "y": 31,
      "z": -6,
      "name": "Rock_Stone"
    },
    {
      "x": -10,
      "y": 32,
      "z": -6,
      "name": "Rock_Stone"
    },
    {
      "x": -10,
      "y": 33,
      "z": -6,
      "name": "Rock_Stone"
    },
    {
      "x": -10,
      "y": 34,
      "z": -6,
      "name": "Soil_Dirt"
    },
    {
      "x": -10,
      "y": 35,
      "z": -6,
      "name": "Soil_Grass"
    },
    {
      "x": -10,
      "y": 22,
      "z": -5,
      "name": "Rock_Stone"
    },
    {
      "x": -10,
      "y": 23,
      "z": -5,
      "name": "Rock_Stone"
    },
    {
      "x": -10,
      "y": 24,
      "z": -5,
      "name": "Rock_Stone"
    },
    {
      "x": -10,
      "y": 25,
      "z": -5,
      "name": "Rock_Stone"
    },
    {
      "x": -10,
      "y": 26,
      "z": -5,
      "name": "Rock_Stone"
    },
    {
      "x": -10,
      "y": 27,
      "z": -5,
      "name": "Rock_Stone"
    },
    {
      "x": -10,
      "y": 28,
      "z": -5,
      "name": "Rock_Stone"
    },
    {
      "x": -10,
      "y": 29,
      "z": -5,
      "name": "Rock_Stone"
    },
    {
      "x": -10,
      "y": 30,
      "z": -5,
      "name": "Rock_Stone"
    },
    {
      "x": -10,
      "y": 31,
      "z": -5,
      "name": "Rock_Stone"
    },
    {
      "x": -10,
      "y": 32,
      "z": -5,
      "name": "Rock_Stone"
    },
    {
      "x": -10,
      "y": 33,
      "z": -5,
      "name": "Soil_Dirt"
    },
    {
      "x": -10,
      "y": 34,
      "z": -5,
      "name": "Soil_Dirt"
    },
    {
      "x": -10,
      "y": 35,
      "z": -5,
      "name": "Soil_Grass"
    },
    {
      "x": -10,
      "y": 6,
      "z": -4,
      "name": "Rock_Stone"
    },
    {
      "x": -10,
      "y": 7,
      "z": -4,
      "name": "Rock_Stone"
    },
    {
      "x": -10,
      "y": 8,
      "z": -4,
      "name": "Rock_Stone"
    },
    {
      "x": -10,
      "y": 9,
      "z": -4,
      "name": "Rock_Stone"
    },
    {
      "x": -10,
      "y": 12,
      "z": -4,
      "name": "Rock_Stone"
    },
    {
      "x": -10,
      "y": 13,
      "z": -4,
      "name": "Rock_Stone"
    },
    {
      "x": -10,
      "y": 14,
      "z": -4,
      "name": "Rock_Stone"
    },
    {
      "x": -10,
      "y": 15,
      "z": -4,
      "name": "Rock_Stone"
    },
    {
      "x": -10,
      "y": 20,
      "z": -4,
      "name": "Rock_Stone"
    },
    {
      "x": -10,
      "y": 21,
      "z": -4,
      "name": "Rock_Stone"
    },
    {
      "x": -10,
      "y": 22,
      "z": -4,
      "name": "Rock_Stone"
    },
    {
      "x": -10,
      "y": 23,
      "z": -4,
      "name": "Rock_Stone"
    },
    {
      "x": -10,
      "y": 24,
      "z": -4,
      "name": "Rock_Stone"
    },
    {
      "x": -10,
      "y": 25,
      "z": -4,
      "name": "Rock_Stone"
    },
    {
      "x": -10,
      "y": 26,
      "z": -4,
      "name": "Rock_Stone"
    },
    {
      "x": -10,
      "y": 27,
      "z": -4,
      "name": "Rock_Stone"
    },
    {
      "x": -10,
      "y": 28,
      "z": -4,
      "name": "Rock_Stone"
    },
    {
      "x": -10,
      "y": 29,
      "z": -4,
      "name": "Rock_Stone"
    },
    {
      "x": -10,
      "y": 30,
      "z": -4,
      "name": "Rock_Stone"
    },
    {
      "x": -10,
      "y": 31,
      "z": -4,
      "name": "Rock_Stone"
    },
    {
      "x": -10,
      "y": 32,
      "z": -4,
      "name": "Rock_Stone"
    },
    {
      "x": -10,
      "y": 33,
      "z": -4,
      "name": "Soil_Dirt"
    },
    {
      "x": -10,
      "y": 34,
      "z": -4,
      "name": "Soil_Dirt"
    },
    {
      "x": -10,
      "y": 35,
      "z": -4,
      "name": "Soil_Grass"
    },
    {
      "x": -10,
      "y": 36,
      "z": -4,
      "name": "Plant_Grass_Sharp"
    },
    {
      "x": -10,
      "y": 4,
      "z": -3,
      "name": "Rock_Stone"
    },
    {
      "x": -10,
      "y": 5,
      "z": -3,
      "name": "Rock_Stone"
    },
    {
      "x": -10,
      "y": 6,
      "z": -3,
      "name": "Rock_Stone"
    },
    {
      "x": -10,
      "y": 7,
      "z": -3,
      "name": "Rock_Stone"
    },
    {
      "x": -10,
      "y": 8,
      "z": -3,
      "name": "Rock_Stone"
    },
    {
      "x": -10,
      "y": 9,
      "z": -3,
      "name": "Rock_Stone"
    },
    {
      "x": -10,
      "y": 10,
      "z": -3,
      "name": "Rock_Stone"
    },
    {
      "x": -10,
      "y": 11,
      "z": -3,
      "name": "Rock_Stone"
    },
    {
      "x": -10,
      "y": 12,
      "z": -3,
      "name": "Rock_Stone"
    },
    {
      "x": -10,
      "y": 13,
      "z": -3,
      "name": "Rock_Stone"
    },
    {
      "x": -10,
      "y": 14,
      "z": -3,
      "name": "Rock_Stone"
    },
    {
      "x": -10,
      "y": 15,
      "z": -3,
      "name": "Rock_Stone"
    },
    {
      "x": -10,
      "y": 16,
      "z": -3,
      "name": "Rock_Stone"
    },
    {
      "x": -10,
      "y": 17,
      "z": -3,
      "name": "Rock_Stone"
    },
    {
      "x": -10,
      "y": 18,
      "z": -3,
      "name": "Rock_Stone"
    },
    {
      "x": -10,
      "y": 19,
      "z": -3,
      "name": "Rock_Stone"
    },
    {
      "x": -10,
      "y": 20,
      "z": -3,
      "name": "Rock_Stone"
    },
    {
      "x": -10,
      "y": 21,
      "z": -3,
      "name": "Rock_Stone"
    },
    {
      "x": -10,
      "y": 22,
      "z": -3,
      "name": "Rock_Stone"
    },
    {
      "x": -10,
      "y": 23,
      "z": -3,
      "name": "Rock_Stone"
    },
    {
      "x": -10,
      "y": 24,
      "z": -3,
      "name": "Rock_Stone"
    },
    {
      "x": -10,
      "y": 25,
      "z": -3,
      "name": "Rock_Stone"
    },
    {
      "x": -10,
      "y": 26,
      "z": -3,
      "name": "Rock_Stone"
    },
    {
      "x": -10,
      "y": 27,
      "z": -3,
      "name": "Rock_Stone"
    },
    {
      "x": -10,
      "y": 28,
      "z": -3,
      "name": "Rock_Stone"
    },
    {
      "x": -10,
      "y": 29,
      "z": -3,
      "name": "Rock_Stone"
    },
    {
      "x": -10,
      "y": 30,
      "z": -3,
      "name": "Rock_Stone"
    },
    {
      "x": -10,
      "y": 31,
      "z": -3,
      "name": "Rock_Stone"
    },
    {
      "x": -10,
      "y": 32,
      "z": -3,
      "name": "Soil_Dirt"
    },
    {
      "x": -10,
      "y": 33,
      "z": -3,
      "name": "Soil_Dirt"
    },
    {
      "x": -10,
      "y": 34,
      "z": -3,
      "name": "Soil_Grass"
    },
    {
      "x": -10,
      "y": 35,
      "z": -3,
      "name": "Plant_Grass_Sharp"
    },
    {
      "x": -10,
      "y": 2,
      "z": -2,
      "name": "Rock_Stone"
    },
    {
      "x": -10,
      "y": 3,
      "z": -2,
      "name": "Rock_Stone"
    },
    {
      "x": -10,
      "y": 4,
      "z": -2,
      "name": "Rock_Stone"
    },
    {
      "x": -10,
      "y": 5,
      "z": -2,
      "name": "Rock_Stone"
    },
    {
      "x": -10,
      "y": 6,
      "z": -2,
      "name": "Rock_Stone"
    },
    {
      "x": -10,
      "y": 7,
      "z": -2,
      "name": "Rock_Stone"
    },
    {
      "x": -10,
      "y": 8,
      "z": -2,
      "name": "Rock_Stone"
    },
    {
      "x": -10,
      "y": 9,
      "z": -2,
      "name": "Rock_Stone"
    },
    {
      "x": -10,
      "y": 10,
      "z": -2,
      "name": "Rock_Stone"
    },
    {
      "x": -10,
      "y": 11,
      "z": -2,
      "name": "Rock_Stone"
    },
    {
      "x": -10,
      "y": 12,
      "z": -2,
      "name": "Rock_Stone"
    },
    {
      "x": -10,
      "y": 13,
      "z": -2,
      "name": "Rock_Stone"
    },
    {
      "x": -10,
      "y": 14,
      "z": -2,
      "name": "Rock_Stone"
    },
    {
      "x": -10,
      "y": 15,
      "z": -2,
      "name": "Rock_Stone"
    },
    {
      "x": -10,
      "y": 16,
      "z": -2,
      "name": "Rock_Stone"
    },
    {
      "x": -10,
      "y": 17,
      "z": -2,
      "name": "Rock_Stone"
    },
    {
      "x": -10,
      "y": 18,
      "z": -2,
      "name": "Rock_Stone"
    },
    {
      "x": -10,
      "y": 19,
      "z": -2,
      "name": "Rock_Stone"
    },
    {
      "x": -10,
      "y": 20,
      "z": -2,
      "name": "Rock_Stone"
    },
    {
      "x": -10,
      "y": 21,
      "z": -2,
      "name": "Rock_Stone"
    },
    {
      "x": -10,
      "y": 22,
      "z": -2,
      "name": "Rock_Stone"
    },
    {
      "x": -10,
      "y": 23,
      "z": -2,
      "name": "Rock_Stone"
    },
    {
      "x": -10,
      "y": 24,
      "z": -2,
      "name": "Rock_Stone"
    },
    {
      "x": -10,
      "y": 25,
      "z": -2,
      "name": "Rock_Stone"
    },
    {
      "x": -10,
      "y": 26,
      "z": -2,
      "name": "Rock_Stone"
    },
    {
      "x": -10,
      "y": 27,
      "z": -2,
      "name": "Rock_Stone"
    },
    {
      "x": -10,
      "y": 28,
      "z": -2,
      "name": "Rock_Stone"
    },
    {
      "x": -10,
      "y": 29,
      "z": -2,
      "name": "Rock_Stone"
    },
    {
      "x": -10,
      "y": 30,
      "z": -2,
      "name": "Rock_Stone"
    },
    {
      "x": -10,
      "y": 31,
      "z": -2,
      "name": "Rock_Stone"
    },
    {
      "x": -10,
      "y": 32,
      "z": -2,
      "name": "Soil_Dirt"
    },
    {
      "x": -10,
      "y": 33,
      "z": -2,
      "name": "Soil_Dirt"
    },
    {
      "x": -10,
      "y": 34,
      "z": -2,
      "name": "Soil_Grass"
    },
    {
      "x": -10,
      "y": 35,
      "z": -2,
      "name": "Plant_Grass_Sharp"
    },
    {
      "x": -10,
      "y": 1,
      "z": -1,
      "name": "Rock_Stone"
    },
    {
      "x": -10,
      "y": 2,
      "z": -1,
      "name": "Rock_Stone"
    },
    {
      "x": -10,
      "y": 3,
      "z": -1,
      "name": "Rock_Stone"
    },
    {
      "x": -10,
      "y": 4,
      "z": -1,
      "name": "Rock_Stone"
    },
    {
      "x": -10,
      "y": 5,
      "z": -1,
      "name": "Rock_Stone"
    },
    {
      "x": -10,
      "y": 6,
      "z": -1,
      "name": "Rock_Stone"
    },
    {
      "x": -10,
      "y": 7,
      "z": -1,
      "name": "Rock_Stone"
    },
    {
      "x": -10,
      "y": 8,
      "z": -1,
      "name": "Rock_Stone"
    },
    {
      "x": -10,
      "y": 9,
      "z": -1,
      "name": "Rock_Stone"
    },
    {
      "x": -10,
      "y": 10,
      "z": -1,
      "name": "Rock_Stone"
    },
    {
      "x": -10,
      "y": 11,
      "z": -1,
      "name": "Rock_Stone"
    },
    {
      "x": -10,
      "y": 12,
      "z": -1,
      "name": "Rock_Stone"
    },
    {
      "x": -10,
      "y": 13,
      "z": -1,
      "name": "Rock_Stone"
    },
    {
      "x": -10,
      "y": 14,
      "z": -1,
      "name": "Rock_Stone"
    },
    {
      "x": -10,
      "y": 15,
      "z": -1,
      "name": "Rock_Stone"
    },
    {
      "x": -10,
      "y": 16,
      "z": -1,
      "name": "Rock_Stone"
    },
    {
      "x": -10,
      "y": 17,
      "z": -1,
      "name": "Rock_Stone"
    },
    {
      "x": -10,
      "y": 18,
      "z": -1,
      "name": "Rock_Stone"
    },
    {
      "x": -10,
      "y": 19,
      "z": -1,
      "name": "Rock_Stone"
    },
    {
      "x": -10,
      "y": 20,
      "z": -1,
      "name": "Rock_Stone"
    },
    {
      "x": -10,
      "y": 21,
      "z": -1,
      "name": "Rock_Stone"
    },
    {
      "x": -10,
      "y": 22,
      "z": -1,
      "name": "Rock_Stone"
    },
    {
      "x": -10,
      "y": 23,
      "z": -1,
      "name": "Rock_Stone"
    },
    {
      "x": -10,
      "y": 24,
      "z": -1,
      "name": "Rock_Stone"
    },
    {
      "x": -10,
      "y": 25,
      "z": -1,
      "name": "Rock_Stone"
    },
    {
      "x": -10,
      "y": 26,
      "z": -1,
      "name": "Rock_Stone"
    },
    {
      "x": -10,
      "y": 27,
      "z": -1,
      "name": "Rock_Stone"
    },
    {
      "x": -10,
      "y": 28,
      "z": -1,
      "name": "Rock_Stone"
    },
    {
      "x": -10,
      "y": 29,
      "z": -1,
      "name": "Rock_Stone"
    },
    {
      "x": -10,
      "y": 30,
      "z": -1,
      "name": "Rock_Stone"
    },
    {
      "x": -10,
      "y": 31,
      "z": -1,
      "name": "Rock_Stone"
    },
    {
      "x": -10,
      "y": 32,
      "z": -1,
      "name": "Soil_Dirt"
    },
    {
      "x": -10,
      "y": 33,
      "z": -1,
      "name": "Soil_Dirt"
    },
    {
      "x": -10,
      "y": 34,
      "z": -1,
      "name": "Soil_Grass"
    },
    {
      "x": -10,
      "y": 0,
      "z": 0,
      "name": "Rock_Stone"
    },
    {
      "x": -10,
      "y": 1,
      "z": 0,
      "name": "Rock_Stone"
    },
    {
      "x": -10,
      "y": 2,
      "z": 0,
      "name": "Rock_Stone"
    },
    {
      "x": -10,
      "y": 3,
      "z": 0,
      "name": "Rock_Stone"
    },
    {
      "x": -10,
      "y": 4,
      "z": 0,
      "name": "Rock_Stone"
    },
    {
      "x": -10,
      "y": 5,
      "z": 0,
      "name": "Rock_Stone"
    },
    {
      "x": -10,
      "y": 6,
      "z": 0,
      "name": "Rock_Stone"
    },
    {
      "x": -10,
      "y": 7,
      "z": 0,
      "name": "Rock_Stone"
    },
    {
      "x": -10,
      "y": 8,
      "z": 0,
      "name": "Rock_Stone"
    },
    {
      "x": -10,
      "y": 9,
      "z": 0,
      "name": "Rock_Stone"
    },
    {
      "x": -10,
      "y": 10,
      "z": 0,
      "name": "Rock_Stone"
    },
    {
      "x": -10,
      "y": 11,
      "z": 0,
      "name": "Rock_Stone"
    },
    {
      "x": -10,
      "y": 12,
      "z": 0,
      "name": "Rock_Stone"
    },
    {
      "x": -10,
      "y": 13,
      "z": 0,
      "name": "Rock_Stone"
    },
    {
      "x": -10,
      "y": 14,
      "z": 0,
      "name": "Rock_Stone"
    },
    {
      "x": -10,
      "y": 15,
      "z": 0,
      "name": "Rock_Stone"
    },
    {
      "x": -10,
      "y": 16,
      "z": 0,
      "name": "Rock_Stone"
    },
    {
      "x": -10,
      "y": 17,
      "z": 0,
      "name": "Rock_Stone"
    },
    {
      "x": -10,
      "y": 18,
      "z": 0,
      "name": "Rock_Stone"
    },
    {
      "x": -10,
      "y": 19,
      "z": 0,
      "name": "Rock_Stone"
    },
    {
      "x": -10,
      "y": 20,
      "z": 0,
      "name": "Rock_Stone"
    },
    {
      "x": -10,
      "y": 21,
      "z": 0,
      "name": "Rock_Stone"
    },
    {
      "x": -10,
      "y": 22,
      "z": 0,
      "name": "Rock_Stone"
    },
    {
      "x": -10,
      "y": 23,
      "z": 0,
      "name": "Rock_Stone"
    },
    {
      "x": -10,
      "y": 24,
      "z": 0,
      "name": "Rock_Stone"
    },
    {
      "x": -10,
      "y": 25,
      "z": 0,
      "name": "Rock_Stone"
    },
    {
      "x": -10,
      "y": 26,
      "z": 0,
      "name": "Rock_Stone"
    },
    {
      "x": -10,
      "y": 27,
      "z": 0,
      "name": "Rock_Stone"
    },
    {
      "x": -10,
      "y": 28,
      "z": 0,
      "name": "Rock_Stone"
    },
    {
      "x": -10,
      "y": 29,
      "z": 0,
      "name": "Rock_Stone"
    },
    {
      "x": -10,
