{
  "version": 8,
  "blockIdVersion": 8,
  "anchorX": 6,
  "anchorY": 21,
  "anchorZ": 0,
  "blocks": [
    {
      "x": -19,
      "y": 44,
      "z": 0,
      "name": "Plant_Leaves_Oak",
      "rotation": 2
    },
    {
      "x": -19,
      "y": 41,
      "z": 1,
      "name": "Plant_Leaves_Beech",
      "rotation": 3
    },
    {
      "x": -19,
      "y": 42,
      "z": 1,
      "name": "Plant_Leaves_Beech",
      "rotation": 3
    },
    {
      "x": -19,
      "y": 43,
      "z": 1,
      "name": "Plant_Leaves_Beech",
      "rotation": 3
    },
    {
      "x": -19,
      "y": 41,
      "z": 2,
      "name": "Plant_Leaves_Beech",
      "rotation": 3
    },
    {
      "x": -19,
      "y": 42,
      "z": 2,
      "name": "Plant_Leaves_Beech",
      "rotation": 3
    },
    {
      "x": -19,
      "y": 43,
      "z": 2,
      "name": "Plant_Leaves_Beech",
      "rotation": 3
    },
    {
      "x": -19,
      "y": 41,
      "z": 3,
      "name": "Plant_Leaves_Beech",
      "rotation": 3
    },
    {
      "x": -19,
      "y": 42,
      "z": 3,
      "name": "Plant_Leaves_Beech",
      "rotation": 3
    },
    {
      "x": -18,
      "y": 45,
      "z": -4,
      "name": "Plant_Leaves_Oak",
      "rotation": 2
    },
    {
      "x": -18,
      "y": 44,
      "z": -3,
      "name": "Plant_Leaves_Oak",
      "rotation": 2
    },
    {
      "x": -18,
      "y": 45,
      "z": -3,
      "name": "Plant_Leaves_Oak",
      "rotation": 2
    },
    {
      "x": -18,
      "y": 43,
      "z": -1,
      "name": "Plant_Leaves_Oak",
      "rotation": 2
    },
    {
      "x": -18,
      "y": 44,
      "z": -1,
      "name": "Plant_Leaves_Oak",
      "rotation": 2
    },
    {
      "x": -18,
      "y": 45,
      "z": -1,
      "name": "Plant_Leaves_Oak",
      "rotation": 2
    },
    {
      "x": -18,
      "y": 42,
      "z": 0,
      "name": "Plant_Leaves_Beech",
      "rotation": 3
    },
    {
      "x": -18,
      "y": 43,
      "z": 0,
      "name": "Plant_Leaves_Beech",
      "rotation": 3
    },
    {
      "x": -18,
      "y": 44,
      "z": 0,
      "name": "Plant_Leaves_Oak",
      "rotation": 2
    },
    {
      "x": -18,
      "y": 45,
      "z": 0,
      "name": "Plant_Leaves_Oak",
      "rotation": 2
    },
    {
      "x": -18,
      "y": 40,
      "z": 1,
      "name": "Plant_Leaves_Beech",
      "rotation": 3
    },
    {
      "x": -18,
      "y": 41,
      "z": 1,
      "name": "Plant_Leaves_Beech",
      "rotation": 3
    },
    {
      "x": -18,
      "y": 42,
      "z": 1,
      "name": "Plant_Leaves_Beech",
      "rotation": 3
    },
    {
      "x": -18,
      "y": 43,
      "z": 1,
      "name": "Plant_Leaves_Beech",
      "rotation": 3
    },
    {
      "x": -18,
      "y": 44,
      "z": 1,
      "name": "Plant_Leaves_Beech",
      "rotation": 3
    },
    {
      "x": -18,
      "y": 45,
      "z": 1,
      "name": "Plant_Leaves_Beech",
      "rotation": 3
    },
    {
      "x": -18,
      "y": 40,
      "z": 2,
      "name": "Plant_Leaves_Beech",
      "rotation": 3
    },
    {
      "x": -18,
      "y": 41,
      "z": 2,
      "name": "Plant_Leaves_Beech",
      "rotation": 3
    },
    {
      "x": -18,
      "y": 42,
      "z": 2,
      "name": "Wood_Beech_Branch_Long",
      "rotation": 7
    },
    {
      "x": -18,
      "y": 43,
      "z": 2,
      "name": "Plant_Leaves_Beech",
      "rotation": 3
    },
    {
      "x": -18,
      "y": 44,
      "z": 2,
      "name": "Plant_Leaves_Beech",
      "rotation": 3
    },
    {
      "x": -18,
      "y": 41,
      "z": 3,
      "name": "Plant_Leaves_Beech",
      "rotation": 3
    },
    {
      "x": -18,
      "y": 42,
      "z": 3,
      "name": "Plant_Leaves_Beech",
      "rotation": 3
    },
    {
      "x": -18,
      "y": 43,
      "z": 3,
      "name": "Plant_Leaves_Beech",
      "rotation": 3
    },
    {
      "x": -18,
      "y": 44,
      "z": 3,
      "name": "Plant_Leaves_Beech",
      "rotation": 3
    },
    {
      "x": -18,
      "y": 42,
      "z": 4,
      "name": "Plant_Leaves_Beech",
      "rotation": 3
    },
    {
      "x": -18,
      "y": 43,
      "z": 4,
      "name": "Plant_Leaves_Beech",
      "rotation": 3
    },
    {
      "x": -17,
      "y": 45,
      "z": -5,
      "name": "Plant_Leaves_Oak",
      "rotation": 2
    },
    {
      "x": -17,
      "y": 43,
      "z": -4,
      "name": "Plant_Leaves_Oak",
      "rotation": 2
    },
    {
      "x": -17,
      "y": 44,
      "z": -4,
      "name": "Plant_Leaves_Oak",
      "rotation": 2
    },
    {
      "x": -17,
      "y": 45,
      "z": -4,
      "name": "Plant_Leaves_Oak",
      "rotation": 2
    },
    {
      "x": -17,
      "y": 46,
      "z": -4,
      "name": "Plant_Leaves_Oak",
      "rotation": 2
    },
    {
      "x": -17,
      "y": 43,
      "z": -3,
      "name": "Plant_Leaves_Oak",
      "rotation": 2
    },
    {
      "x": -17,
      "y": 44,
      "z": -3,
      "name": "Plant_Leaves_Oak",
      "rotation": 2
    },
    {
      "x": -17,
      "y": 45,
      "z": -3,
      "name": "Plant_Leaves_Oak",
      "rotation": 2
    },
    {
      "x": -17,
      "y": 46,
      "z": -3,
      "name": "Plant_Leaves_Oak",
      "rotation": 2
    },
    {
      "x": -17,
      "y": 40,
      "z": -2,
      "name": "Plant_Leaves_Oak",
      "rotation": 2
    },
    {
      "x": -17,
      "y": 44,
      "z": -2,
      "name": "Plant_Leaves_Oak",
      "rotation": 2
    },
    {
      "x": -17,
      "y": 45,
      "z": -2,
      "name": "Plant_Leaves_Oak",
      "rotation": 2
    },
    {
      "x": -17,
      "y": 45,
      "z": -1,
      "name": "Plant_Leaves_Oak",
      "rotation": 2
    },
    {
      "x": -17,
      "y": 47,
      "z": -1,
      "name": "Plant_Leaves_Oak",
      "rotation": 2
    },
    {
      "x": -17,
      "y": 42,
      "z": 0,
      "name": "Plant_Leaves_Beech",
      "rotation": 3
    },
    {
      "x": -17,
      "y": 43,
      "z": 0,
      "name": "Plant_Leaves_Oak",
      "rotation": 2
    },
    {
      "x": -17,
      "y": 44,
      "z": 0,
      "name": "Plant_Leaves_Oak",
      "rotation": 2
    },
    {
      "x": -17,
      "y": 45,
      "z": 0,
      "name": "Plant_Leaves_Oak",
      "rotation": 2
    },
    {
      "x": -17,
      "y": 46,
      "z": 0,
      "name": "Plant_Leaves_Oak",
      "rotation": 2
    },
    {
      "x": -17,
      "y": 47,
      "z": 0,
      "name": "Plant_Leaves_Oak",
      "rotation": 2
    },
    {
      "x": -17,
      "y": 41,
      "z": 1,
      "name": "Plant_Leaves_Oak",
      "rotation": 2
    },
    {
      "x": -17,
      "y": 44,
      "z": 1,
      "name": "Plant_Leaves_Oak",
      "rotation": 2
    },
    {
      "x": -17,
      "y": 45,
      "z": 1,
      "name": "Plant_Leaves_Beech",
      "rotation": 3
    },
    {
      "x": -17,
      "y": 46,
      "z": 1,
      "name": "Plant_Leaves_Beech",
      "rotation": 3
    },
    {
      "x": -17,
      "y": 42,
      "z": 2,
      "name": "Wood_Beech_Branch_Long",
      "rotation": 7
    },
    {
      "x": -17,
      "y": 45,
      "z": 2,
      "name": "Plant_Leaves_Beech",
      "rotation": 3
    },
    {
      "x": -17,
      "y": 46,
      "z": 2,
      "name": "Plant_Leaves_Beech",
      "rotation": 3
    },
    {
      "x": -17,
      "y": 45,
      "z": 3,
      "name": "Plant_Leaves_Beech",
      "rotation": 3
    },
    {
      "x": -17,
      "y": 42,
      "z": 4,
      "name": "Plant_Leaves_Beech",
      "rotation": 3
    },
    {
      "x": -17,
      "y": 42,
      "z": 5,
      "name": "Plant_Leaves_Beech",
      "rotation": 3
    },
    {
      "x": -17,
      "y": 43,
      "z": 5,
      "name": "Plant_Leaves_Beech",
      "rotation": 3
    },
    {
      "x": -17,
      "y": 44,
      "z": 5,
      "name": "Plant_Leaves_Beech",
      "rotation": 3
    },
    {
      "x": -16,
      "y": 45,
      "z": -7,
      "name": "Plant_Leaves_Oak",
      "rotation": 2
    },
    {
      "x": -16,
      "y": 44,
      "z": -6,
      "name": "Plant_Leaves_Oak",
      "rotation": 2
    },
    {
      "x": -16,
      "y": 45,
      "z": -6,
      "name": "Plant_Leaves_Oak",
      "rotation": 2
    },
    {
      "x": -16,
      "y": 44,
      "z": -5,
      "name": "Plant_Leaves_Oak",
      "rotation": 2
    },
    {
      "x": -16,
      "y": 45,
      "z": -5,
      "name": "Plant_Leaves_Oak",
      "rotation": 2
    },
    {
      "x": -16,
      "y": 46,
      "z": -5,
      "name": "Plant_Leaves_Oak",
      "rotation": 2
    },
    {
      "x": -16,
      "y": 45,
      "z": -4,
      "name": "Plant_Leaves_Oak",
      "rotation": 2
    },
    {
      "x": -16,
      "y": 46,
      "z": -4,
      "name": "Plant_Leaves_Oak",
      "rotation": 2
    },
    {
      "x": -16,
      "y": 47,
      "z": -4,
      "name": "Plant_Leaves_Oak",
      "rotation": 2
    },
    {
      "x": -16,
      "y": 40,
      "z": -3,
      "name": "Plant_Leaves_Beech",
      "rotation": 3
    },
    {
      "x": -16,
      "y": 45,
      "z": -3,
      "name": "Wood_Oak_Branch_Long",
      "rotation": 7
    },
    {
      "x": -16,
      "y": 46,
      "z": -3,
      "name": "Plant_Leaves_Oak",
      "rotation": 2
    },
    {
      "x": -16,
      "y": 39,
      "z": -2,
      "name": "Plant_Leaves_Oak",
      "rotation": 2
    },
    {
      "x": -16,
      "y": 40,
      "z": -2,
      "name": "Plant_Leaves_Beech",
      "rotation": 3
    },
    {
      "x": -16,
      "y": 41,
      "z": -2,
      "name": "Plant_Leaves_Beech",
      "rotation": 3
    },
    {
      "x": -16,
      "y": 46,
      "z": -2,
      "name": "Plant_Leaves_Oak",
      "rotation": 2
    },
    {
      "x": -16,
      "y": 47,
      "z": -2,
      "name": "Plant_Leaves_Oak",
      "rotation": 2
    },
    {
      "x": -16,
      "y": 41,
      "z": -1,
      "name": "Plant_Leaves_Beech",
      "rotation": 3
    },
    {
      "x": -16,
      "y": 44,
      "z": -1,
      "name": "Plant_Leaves_Oak",
      "rotation": 2
    },
    {
      "x": -16,
      "y": 47,
      "z": -1,
      "name": "Plant_Leaves_Oak",
      "rotation": 2
    },
    {
      "x": -16,
      "y": 48,
      "z": -1,
      "name": "Plant_Leaves_Oak",
      "rotation": 2
    },
    {
      "x": -16,
      "y": 40,
      "z": 0,
      "name": "Plant_Leaves_Oak",
      "rotation": 2
    },
    {
      "x": -16,
      "y": 41,
      "z": 0,
      "name": "Plant_Leaves_Oak",
      "rotation": 2
    },
    {
      "x": -16,
      "y": 42,
      "z": 0,
      "name": "Plant_Leaves_Beech",
      "rotation": 3
    },
    {
      "x": -16,
      "y": 43,
      "z": 0,
      "name": "Plant_Leaves_Beech",
      "rotation": 3
    },
    {
      "x": -16,
      "y": 44,
      "z": 0,
      "name": "Plant_Leaves_Oak",
      "rotation": 2
    },
    {
      "x": -16,
      "y": 45,
      "z": 0,
      "name": "Plant_Leaves_Beech",
      "rotation": 3
    },
    {
      "x": -16,
      "y": 46,
      "z": 0,
      "name": "Plant_Leaves_Oak",
      "rotation": 2
    },
    {
      "x": -16,
      "y": 47,
      "z": 0,
      "name": "Plant_Leaves_Beech",
      "rotation": 3
    },
    {
      "x": -16,
      "y": 48,
      "z": 0,
      "name": "Plant_Leaves_Oak",
      "rotation": 2
    },
    {
      "x": -16,
      "y": 40,
      "z": 1,
      "name": "Plant_Leaves_Oak",
      "rotation": 2
    },
    {
      "x": -16,
      "y": 41,
      "z": 1,
      "name": "Plant_Leaves_Oak",
      "rotation": 2
    },
    {
      "x": -16,
      "y": 42,
      "z": 1,
      "name": "Wood_Beech_Branch_Long",
      "rotation": 4
    },
    {
      "x": -16,
      "y": 43,
      "z": 1,
      "name": "Plant_Leaves_Oak",
      "rotation": 2
    },
    {
      "x": -16,
      "y": 44,
      "z": 1,
      "name": "Plant_Leaves_Oak",
      "rotation": 2
    },
    {
      "x": -16,
      "y": 45,
      "z": 1,
      "name": "Plant_Leaves_Beech",
      "rotation": 3
    },
    {
      "x": -16,
      "y": 46,
      "z": 1,
      "name": "Plant_Leaves_Beech",
      "rotation": 3
    },
    {
      "x": -16,
      "y": 47,
      "z": 1,
      "name": "Plant_Leaves_Beech",
      "rotation": 3
    },
    {
      "x": -16,
      "y": 41,
      "z": 2,
      "name": "Wood_Beech_Trunk_Full",
      "rotation": 3
    },
    {
      "x": -16,
      "y": 42,
      "z": 2,
      "name": "Wood_Beech_Trunk_Full",
      "rotation": 3
    },
    {
      "x": -16,
      "y": 43,
      "z": 2,
      "name": "Wood_Beech_Branch_Long",
      "rotation": 3
    },
    {
      "x": -16,
      "y": 44,
      "z": 2,
      "name": "Wood_Beech_Branch_Long",
      "rotation": 3
    },
    {
      "x": -16,
      "y": 45,
      "z": 2,
      "name": "Plant_Leaves_Beech",
      "rotation": 3
    },
    {
      "x": -16,
      "y": 46,
      "z": 2,
      "name": "Plant_Leaves_Beech",
      "rotation": 3
    },
    {
      "x": -16,
      "y": 49,
      "z": 2,
      "name": "Plant_Leaves_Beech",
      "rotation": 3
    },
    {
      "x": -16,
      "y": 50,
      "z": 2,
      "name": "Plant_Leaves_Beech",
      "rotation": 3
    },
    {
      "x": -16,
      "y": 33,
      "z": 3,
      "name": "Soil_Grass"
    },
    {
      "x": -16,
      "y": 34,
      "z": 3,
      "name": "Plant_Grass_Sharp_Wild"
    },
    {
      "x": -16,
      "y": 35,
      "z": 3,
      "name": "Plant_Grass_Sharp_Wild",
      "filler": 1024
    },
    {
      "x": -16,
      "y": 45,
      "z": 3,
      "name": "Plant_Leaves_Beech",
      "rotation": 3
    },
    {
      "x": -16,
      "y": 47,
      "z": 3,
      "name": "Plant_Leaves_Beech",
      "rotation": 3
    },
    {
      "x": -16,
      "y": 48,
      "z": 3,
      "name": "Plant_Leaves_Beech",
      "rotation": 3
    },
    {
      "x": -16,
      "y": 49,
      "z": 3,
      "name": "Plant_Leaves_Beech",
      "rotation": 3
    },
    {
      "x": -16,
      "y": 42,
      "z": 4,
      "name": "Wood_Beech_Branch_Long",
      "rotation": 7
    },
    {
      "x": -16,
      "y": 43,
      "z": 4,
      "name": "Plant_Leaves_Beech",
      "rotation": 3
    },
    {
      "x": -16,
      "y": 43,
      "z": 5,
      "name": "Plant_Leaves_Beech",
      "rotation": 3
    },
    {
      "x": -16,
      "y": 44,
      "z": 5,
      "name": "Plant_Leaves_Beech",
      "rotation": 3
    },
    {
      "x": -16,
      "y": 42,
      "z": 6,
      "name": "Plant_Leaves_Beech",
      "rotation": 3
    },
    {
      "x": -16,
      "y": 43,
      "z": 6,
      "name": "Plant_Leaves_Beech",
      "rotation": 3
    },
    {
      "x": -16,
      "y": 44,
      "z": 6,
      "name": "Plant_Leaves_Beech",
      "rotation": 3
    },
    {
      "x": -15,
      "y": 44,
      "z": -7,
      "name": "Plant_Leaves_Oak",
      "rotation": 2
    },
    {
      "x": -15,
      "y": 45,
      "z": -7,
      "name": "Plant_Leaves_Oak",
      "rotation": 2
    },
    {
      "x": -15,
      "y": 43,
      "z": -6,
      "name": "Plant_Leaves_Oak",
      "rotation": 2
    },
    {
      "x": -15,
      "y": 44,
      "z": -6,
      "name": "Plant_Leaves_Oak",
      "rotation": 2
    },
    {
      "x": -15,
      "y": 46,
      "z": -6,
      "name": "Plant_Leaves_Oak",
      "rotation": 2
    },
    {
      "x": -15,
      "y": 44,
      "z": -5,
      "name": "Plant_Leaves_Oak",
      "rotation": 2
    },
    {
      "x": -15,
      "y": 45,
      "z": -5,
      "name": "Plant_Leaves_Oak",
      "rotation": 2
    },
    {
      "x": -15,
      "y": 46,
      "z": -5,
      "name": "Plant_Leaves_Oak",
      "rotation": 2
    },
    {
      "x": -15,
      "y": 39,
      "z": -4,
      "name": "Plant_Leaves_Oak",
      "rotation": 2
    },
    {
      "x": -15,
      "y": 40,
      "z": -4,
      "name": "Plant_Leaves_Oak",
      "rotation": 2
    },
    {
      "x": -15,
      "y": 44,
      "z": -4,
      "name": "Plant_Leaves_Oak",
      "rotation": 2
    },
    {
      "x": -15,
      "y": 48,
      "z": -4,
      "name": "Plant_Leaves_Oak",
      "rotation": 2
    },
    {
      "x": -15,
      "y": 39,
      "z": -3,
      "name": "Plant_Leaves_Oak",
      "rotation": 2
    },
    {
      "x": -15,
      "y": 40,
      "z": -3,
      "name": "Plant_Leaves_Beech",
      "rotation": 3
    },
    {
      "x": -15,
      "y": 41,
      "z": -3,
      "name": "Plant_Leaves_Beech",
      "rotation": 3
    },
    {
      "x": -15,
      "y": 45,
      "z": -3,
      "name": "Wood_Oak_Branch_Long",
      "rotation": 7
    },
    {
      "x": -15,
      "y": 46,
      "z": -3,
      "name": "Plant_Leaves_Oak",
      "rotation": 2
    },
    {
      "x": -15,
      "y": 48,
      "z": -3,
      "name": "Plant_Leaves_Oak",
      "rotation": 2
    },
    {
      "x": -15,
      "y": 49,
      "z": -3,
      "name": "Plant_Leaves_Oak",
      "rotation": 2
    },
    {
      "x": -15,
      "y": 39,
      "z": -2,
      "name": "Plant_Leaves_Beech",
      "rotation": 3
    },
    {
      "x": -15,
      "y": 40,
      "z": -2,
      "name": "Plant_Leaves_Beech",
      "rotation": 3
    },
    {
      "x": -15,
      "y": 41,
      "z": -2,
      "name": "Plant_Leaves_Beech",
      "rotation": 3
    },
    {
      "x": -15,
      "y": 42,
      "z": -2,
      "name": "Plant_Leaves_Beech",
      "rotation": 3
    },
    {
      "x": -15,
      "y": 44,
      "z": -2,
      "name": "Plant_Leaves_Beech",
      "rotation": 3
    },
    {
      "x": -15,
      "y": 45,
      "z": -2,
      "name": "Plant_Leaves_Beech",
      "rotation": 3
    },
    {
      "x": -15,
      "y": 47,
      "z": -2,
      "name": "Plant_Leaves_Oak",
      "rotation": 2
    },
    {
      "x": -15,
      "y": 48,
      "z": -2,
      "name": "Plant_Leaves_Oak",
      "rotation": 2
    },
    {
      "x": -15,
      "y": 33,
      "z": -1,
      "name": "Soil_Grass"
    },
    {
      "x": -15,
      "y": 34,
      "z": -1,
      "name": "Plant_Grass_Sharp_Tall"
    },
    {
      "x": -15,
      "y": 35,
      "z": -1,
      "name": "Plant_Grass_Sharp_Tall",
      "filler": 1024
    },
    {
      "x": -15,
      "y": 39,
      "z": -1,
      "name": "Plant_Leaves_Beech",
      "rotation": 3
    },
    {
      "x": -15,
      "y": 41,
      "z": -1,
      "name": "Plant_Leaves_Oak",
      "rotation": 2
    },
    {
      "x": -15,
      "y": 44,
      "z": -1,
      "name": "Plant_Leaves_Beech",
      "rotation": 3
    },
    {
      "x": -15,
      "y": 46,
      "z": -1,
      "name": "Plant_Leaves_Beech",
      "rotation": 3
    },
    {
      "x": -15,
      "y": 47,
      "z": -1,
      "name": "Plant_Leaves_Beech",
      "rotation": 3
    },
    {
      "x": -15,
      "y": 33,
      "z": 0,
      "name": "Soil_Grass"
    },
    {
      "x": -15,
      "y": 34,
      "z": 0,
      "name": "Plant_Grass_Sharp_Tall"
    },
    {
      "x": -15,
      "y": 35,
      "z": 0,
      "name": "Plant_Grass_Sharp_Tall",
      "filler": 1024
    },
    {
      "x": -15,
      "y": 41,
      "z": 0,
      "name": "Plant_Leaves_Oak",
      "rotation": 2
    },
    {
      "x": -15,
      "y": 43,
      "z": 0,
      "name": "Plant_Leaves_Oak",
      "rotation": 2
    },
    {
      "x": -15,
      "y": 44,
      "z": 0,
      "name": "Wood_Oak_Branch_Long",
      "rotation": 7
    },
    {
      "x": -15,
      "y": 47,
      "z": 0,
      "name": "Plant_Leaves_Beech",
      "rotation": 3
    },
    {
      "x": -15,
      "y": 48,
      "z": 0,
      "name": "Plant_Leaves_Beech",
      "rotation": 3
    },
    {
      "x": -15,
      "y": 32,
      "z": 1,
      "name": "Rock_Stone"
    },
    {
      "x": -15,
      "y": 33,
      "z": 1,
      "name": "Soil_Grass"
    },
    {
      "x": -15,
      "y": 34,
      "z": 1,
      "name": "Plant_Grass_Sharp_Tall"
    },
    {
      "x": -15,
      "y": 35,
      "z": 1,
      "name": "Plant_Grass_Sharp_Tall",
      "filler": 1024
    },
    {
      "x": -15,
      "y": 40,
      "z": 1,
      "name": "Plant_Leaves_Oak",
      "rotation": 2
    },
    {
      "x": -15,
      "y": 41,
      "z": 1,
      "name": "Wood_Oak_Branch_Long",
      "rotation": 7
    },
    {
      "x": -15,
      "y": 42,
      "z": 1,
      "name": "Plant_Leaves_Oak",
      "rotation": 2
    },
    {
      "x": -15,
      "y": 47,
      "z": 1,
      "name": "Plant_Leaves_Beech",
      "rotation": 3
    },
    {
      "x": -15,
      "y": 48,
      "z": 1,
      "name": "Plant_Leaves_Oak",
      "rotation": 2
    },
    {
      "x": -15,
      "y": 49,
      "z": 1,
      "name": "Plant_Leaves_Beech",
      "rotation": 3
    },
    {
      "x": -15,
      "y": 50,
      "z": 1,
      "name": "Plant_Leaves_Beech",
      "rotation": 3
    },
    {
      "x": -15,
      "y": 31,
      "z": 2,
      "name": "Rock_Stone"
    },
    {
      "x": -15,
      "y": 32,
      "z": 2,
      "name": "Rock_Stone"
    },
    {
      "x": -15,
      "y": 33,
      "z": 2,
      "name": "Soil_Grass"
    },
    {
      "x": -15,
      "y": 34,
      "z": 2,
      "name": "Plant_Grass_Sharp_Wild"
    },
    {
      "x": -15,
      "y": 35,
      "z": 2,
      "name": "Plant_Grass_Sharp_Wild",
      "filler": 1024
    },
    {
      "x": -15,
      "y": 41,
      "z": 2,
      "name": "Wood_Beech_Trunk_Full",
      "rotation": 3
    },
    {
      "x": -15,
      "y": 44,
      "z": 2,
      "name": "Plant_Leaves_Oak",
      "rotation": 2
    },
    {
      "x": -15,
      "y": 46,
      "z": 2,
      "name": "Wood_Beech_Branch_Corner",
      "rotation": 3
    },
    {
      "x": -15,
      "y": 47,
      "z": 2,
      "name": "Wood_Beech_Branch_Long",
      "rotation": 3
    },
    {
      "x": -15,
      "y": 48,
      "z": 2,
      "name": "Wood_Beech_Branch_Long",
      "rotation": 3
    },
    {
      "x": -15,
      "y": 49,
      "z": 2,
      "name": "Wood_Beech_Branch_Long",
      "rotation": 3
    },
    {
      "x": -15,
      "y": 50,
      "z": 2,
      "name": "Plant_Leaves_Beech",
      "rotation": 3
    },
    {
      "x": -15,
      "y": 31,
      "z": 3,
      "name": "Rock_Stone"
    },
    {
      "x": -15,
      "y": 32,
      "z": 3,
      "name": "Rock_Stone"
    },
    {
      "x": -15,
      "y": 33,
      "z": 3,
      "name": "Soil_Grass"
    },
    {
      "x": -15,
      "y": 34,
      "z": 3,
      "name": "Plant_Grass_Sharp_Tall"
    },
    {
      "x": -15,
      "y": 35,
      "z": 3,
      "name": "Plant_Grass_Sharp_Tall",
      "filler": 1024
    },
    {
      "x": -15,
      "y": 44,
      "z": 3,
      "name": "Plant_Leaves_Oak",
      "rotation": 2
    },
    {
      "x": -15,
      "y": 46,
      "z": 3,
      "name": "Plant_Leaves_Beech",
      "rotation": 3
    },
    {
      "x": -15,
      "y": 47,
      "z": 3,
      "name": "Plant_Leaves_Beech",
      "rotation": 3
    },
    {
      "x": -15,
      "y": 49,
      "z": 3,
      "name": "Plant_Leaves_Beech",
      "rotation": 3
    },
    {
      "x": -15,
      "y": 50,
      "z": 3,
      "name": "Plant_Leaves_Beech",
      "rotation": 3
    },
    {
      "x": -15,
      "y": 33,
      "z": 4,
      "name": "Rock_Stone"
    },
    {
      "x": -15,
      "y": 39,
      "z": 4,
      "name": "Plant_Leaves_Beech",
      "rotation": 3
    },
    {
      "x": -15,
      "y": 42,
      "z": 4,
      "name": "Wood_Beech_Branch_Long",
      "rotation": 7
    },
    {
      "x": -15,
      "y": 45,
      "z": 4,
      "name": "Plant_Leaves_Beech",
      "rotation": 3
    },
    {
      "x": -15,
      "y": 46,
      "z": 4,
      "name": "Plant_Leaves_Beech",
      "rotation": 3
    },
    {
      "x": -15,
      "y": 47,
      "z": 4,
      "name": "Plant_Leaves_Beech",
      "rotation": 3
    },
    {
      "x": -15,
      "y": 39,
      "z": 5,
      "name": "Plant_Leaves_Beech",
      "rotation": 3
    },
    {
      "x": -15,
      "y": 45,
      "z": 5,
      "name": "Plant_Leaves_Beech",
      "rotation": 3
    },
    {
      "x": -15,
      "y": 46,
      "z": 5,
      "name": "Plant_Leaves_Beech",
      "rotation": 3
    },
    {
      "x": -15,
      "y": 42,
      "z": 6,
      "name": "Plant_Leaves_Beech",
      "rotation": 3
    },
    {
      "x": -15,
      "y": 43,
      "z": 6,
      "name": "Plant_Leaves_Beech",
      "rotation": 3
    },
    {
      "x": -14,
      "y": 44,
      "z": -7,
      "name": "Plant_Leaves_Oak",
      "rotation": 2
    },
    {
      "x": -14,
      "y": 42,
      "z": -6,
      "name": "Plant_Leaves_Oak",
      "rotation": 2
    },
    {
      "x": -14,
      "y": 43,
      "z": -6,
      "name": "Plant_Leaves_Oak",
      "rotation": 2
    },
    {
      "x": -14,
      "y": 43,
      "z": -5,
      "name": "Plant_Leaves_Oak",
      "rotation": 2
    },
    {
      "x": -14,
      "y": 48,
      "z": -5,
      "name": "Plant_Leaves_Oak",
      "rotation": 2
    },
    {
      "x": -14,
      "y": 47,
      "z": -4,
      "name": "Plant_Leaves_Oak",
      "rotation": 2
    },
    {
      "x": -14,
      "y": 48,
      "z": -4,
      "name": "Plant_Leaves_Oak",
      "rotation": 2
    },
    {
      "x": -14,
      "y": 33,
      "z": -3,
      "name": "Soil_Grass"
    },
    {
      "x": -14,
      "y": 40,
      "z": -3,
      "name": "Plant_Leaves_Beech",
      "rotation": 3
    },
    {
      "x": -14,
      "y": 41,
      "z": -3,
      "name": "Plant_Leaves_Beech",
      "rotation": 3
    },
    {
      "x": -14,
      "y": 42,
      "z": -3,
      "name": "Plant_Leaves_Beech",
      "rotation": 3
    },
    {
      "x": -14,
      "y": 44,
      "z": -3,
      "name": "Wood_Oak_Branch_Corner",
      "rotation": 3
    },
    {
      "x": -14,
      "y": 45,
      "z": -3,
      "name": "Wood_Oak_Branch_Corner",
      "rotation": 11
    },
    {
      "x": -14,
      "y": 48,
      "z": -3,
      "name": "Plant_Leaves_Oak",
      "rotation": 2
    },
    {
      "x": -14,
      "y": 49,
      "z": -3,
      "name": "Plant_Leaves_Oak",
      "rotation": 2
    },
    {
      "x": -14,
      "y": 32,
      "z": -2,
      "name": "Soil_Dirt"
    },
    {
      "x": -14,
      "y": 33,
      "z": -2,
      "name": "Soil_Grass"
    },
    {
      "x": -14,
      "y": 39,
      "z": -2,
      "name": "Plant_Leaves_Beech",
      "rotation": 3
    },
    {
      "x": -14,
      "y": 40,
      "z": -2,
      "name": "Wood_Beech_Branch_Long",
      "rotation": 4
    },
    {
      "x": -14,
      "y": 41,
      "z": -2,
      "name": "Plant_Leaves_Beech",
      "rotation": 3
    },
    {
      "x": -14,
      "y": 42,
      "z": -2,
      "name": "Plant_Leaves_Beech",
      "rotation": 3
    },
    {
      "x": -14,
      "y": 44,
      "z": -2,
      "name": "Plant_Leaves_Beech",
      "rotation": 3
    },
    {
      "x": -14,
      "y": 45,
      "z": -2,
      "name": "Plant_Leaves_Beech",
      "rotation": 3
    },
    {
      "x": -14,
      "y": 48,
      "z": -2,
      "name": "Plant_Leaves_Oak",
      "rotation": 2
    },
    {
      "x": -14,
      "y": 49,
      "z": -2,
      "name": "Plant_Leaves_Oak",
      "rotation": 2
    },
    {
      "x": -14,
      "y": 50,
      "z": -2,
      "name": "Plant_Leaves_Oak",
      "rotation": 2
    },
    {
      "x": -14,
      "y": 31,
      "z": -1,
      "name": "Soil_Dirt"
    },
    {
      "x": -14,
      "y": 32,
      "z": -1,
      "name": "Rock_Stone"
    },
    {
      "x": -14,
      "y": 33,
      "z": -1,
      "name": "Soil_Grass"
    },
    {
      "x": -14,
      "y": 34,
      "z": -1,
      "name": "Plant_Grass_Sharp_Tall"
    },
    {
      "x": -14,
      "y": 35,
      "z": -1,
      "name": "Plant_Grass_Sharp_Tall",
      "filler": 1024
    },
    {
      "x": -14,
      "y": 39,
      "z": -1,
      "name": "Plant_Leaves_Beech",
      "rotation": 3
    },
    {
      "x": -14,
      "y": 40,
      "z": -1,
      "name": "Wood_Beech_Branch_Long",
      "rotation": 4
    },
    {
      "x": -14,
      "y": 44,
      "z": -1,
      "name": "Plant_Leaves_Beech",
      "rotation": 3
    },
    {
      "x": -14,
      "y": 45,
      "z": -1,
      "name": "Plant_Leaves_Beech",
      "rotation": 3
    },
    {
      "x": -14,
      "y": 46,
      "z": -1,
      "name": "Plant_Leaves_Beech",
      "rotation": 3
    },
    {
      "x": -14,
      "y": 47,
      "z": -1,
      "name": "Plant_Leaves_Beech",
      "rotation": 3
    },
    {
      "x": -14,
      "y": 48,
      "z": -1,
      "name": "Plant_Leaves_Beech",
      "rotation": 3
    },
    {
      "x": -14,
      "y": 49,
      "z": -1,
      "name": "Plant_Leaves_Oak",
      "rotation": 2
    },
    {
      "x": -14,
      "y": 30,
      "z": 0,
      "name": "Rock_Stone"
    },
    {
      "x": -14,
      "y": 31,
      "z": 0,
      "name": "Soil_Dirt"
    },
    {
      "x": -14,
      "y": 32,
      "z": 0,
      "name": "Rock_Stone"
    },
    {
      "x": -14,
      "y": 33,
      "z": 0,
      "name": "Soil_Grass"
    },
    {
      "x": -14,
      "y": 34,
      "z": 0,
      "name": "Plant_Grass_Sharp_Tall"
    },
    {
      "x": -14,
      "y": 35,
      "z": 0,
      "name": "Plant_Grass_Sharp_Tall",
      "filler": 1024
    },
    {
      "x": -14,
      "y": 40,
      "z": 0,
      "name": "Wood_Beech_Trunk_Full",
      "rotation": 3
    },
    {
      "x": -14,
      "y": 41,
      "z": 0,
      "name": "Wood_Beech_Branch_Long",
      "rotation": 3
    },
    {
      "x": -14,
      "y": 42,
      "z": 0,
      "name": "Wood_Beech_Branch_Long",
      "rotation": 3
    },
    {
      "x": -14,
      "y": 43,
      "z": 0,
      "name": "Wood_Beech_Branch_Long",
      "rotation": 3
    },
    {
      "x": -14,
      "y": 44,
      "z": 0,
      "name": "Wood_Beech_Branch_Long",
      "rotation": 3
    },
    {
      "x": -14,
      "y": 45,
      "z": 0,
      "name": "Plant_Leaves_Beech",
      "rotation": 3
    },
    {
      "x": -14,
      "y": 46,
      "z": 0,
      "name": "Plant_Leaves_Beech",
      "rotation": 3
    },
    {
      "x": -14,
      "y": 47,
      "z": 0,
      "name": "Plant_Leaves_Beech",
      "rotation": 3
    },
    {
      "x": -14,
      "y": 48,
      "z": 0,
      "name": "Plant_Leaves_Beech",
      "rotation": 3
    },
    {
      "x": -14,
      "y": 49,
      "z": 0,
      "name": "Plant_Leaves_Oak",
      "rotation": 2
    },
    {
      "x": -14,
      "y": 29,
      "z": 1,
      "name": "Rock_Stone"
    },
    {
      "x": -14,
      "y": 30,
      "z": 1,
      "name": "Rock_Stone"
    },
    {
      "x": -14,
      "y": 31,
      "z": 1,
      "name": "Rock_Stone"
    },
    {
      "x": -14,
      "y": 32,
      "z": 1,
      "name": "Rock_Stone"
    },
    {
      "x": -14,
      "y": 33,
      "z": 1,
      "name": "Soil_Grass"
    },
    {
      "x": -14,
      "y": 34,
      "z": 1,
      "name": "Plant_Grass_Sharp_Wild"
    },
    {
      "x": -14,
      "y": 35,
      "z": 1,
      "name": "Plant_Grass_Sharp_Wild",
      "filler": 1024
    },
    {
      "x": -14,
      "y": 40,
      "z": 1,
      "name": "Wood_Beech_Trunk_Full",
      "rotation": 3
    },
    {
      "x": -14,
      "y": 41,
      "z": 1,
      "name": "Wood_Oak_Branch_Long",
      "rotation": 7
    },
    {
      "x": -14,
      "y": 46,
      "z": 1,
      "name": "Wood_Beech_Branch_Corner",
      "rotation": 2
    },
    {
      "x": -14,
      "y": 47,
      "z": 1,
      "name": "Plant_Leaves_Beech",
      "rotation": 3
    },
    {
      "x": -14,
      "y": 48,
      "z": 1,
      "name": "Plant_Leaves_Beech",
      "rotation": 3
    },
    {
      "x": -14,
      "y": 50,
      "z": 1,
      "name": "Plant_Leaves_Beech",
      "rotation": 3
    },
    {
      "x": -14,
      "y": 28,
      "z": 2,
      "name": "Rock_Stone"
    },
    {
      "x": -14,
      "y": 29,
      "z": 2,
      "name": "Rock_Stone"
    },
    {
      "x": -14,
      "y": 30,
      "z": 2,
      "name": "Rock_Stone"
    },
    {
      "x": -14,
      "y": 31,
      "z": 2,
      "name": "Rock_Stone"
    },
    {
      "x": -14,
      "y": 32,
      "z": 2,
      "name": "Wood_Beech_Trunk",
      "rotation": 3
    },
    {
      "x": -14,
      "y": 33,
      "z": 2,
      "name": "Wood_Beech_Trunk",
      "rotation": 3
    },
    {
      "x": -14,
      "y": 34,
      "z": 2,
      "name": "Wood_Beech_Trunk",
      "rotation": 3
    },
    {
      "x": -14,
      "y": 35,
      "z": 2,
      "name": "Wood_Beech_Trunk",
      "rotation": 3
    },
    {
      "x": -14,
      "y": 36,
      "z": 2,
      "name": "Wood_Beech_Trunk",
      "rotation": 3
    },
    {
      "x": -14,
      "y": 37,
      "z": 2,
      "name": "Wood_Beech_Trunk",
      "rotation": 3
    },
    {
      "x": -14,
      "y": 38,
      "z": 2,
      "name": "Wood_Beech_Trunk",
      "rotation": 3
    },
    {
      "x": -14,
      "y": 39,
      "z": 2,
      "name": "Wood_Beech_Trunk",
      "rotation": 3
    },
    {
      "x": -14,
      "y": 40,
      "z": 2,
      "name": "Wood_Beech_Trunk",
      "rotation": 3
    },
    {
      "x": -14,
      "y": 41,
      "z": 2,
      "name": "Wood_Beech_Trunk",
      "rotation": 3
    },
    {
      "x": -14,
      "y": 42,
      "z": 2,
      "name": "Wood_Beech_Trunk",
      "rotation": 3
    },
    {
      "x": -14,
      "y": 43,
      "z": 2,
      "name": "Wood_Beech_Trunk",
      "rotation": 3
    },
    {
      "x": -14,
      "y": 44,
      "z": 2,
      "name": "Wood_Beech_Trunk",
      "rotation": 3
    },
    {
      "x": -14,
      "y": 45,
      "z": 2,
      "name": "Wood_Beech_Trunk",
      "rotation": 3
    },
    {
      "x": -14,
      "y": 46,
      "z": 2,
      "name": "Wood_Beech_Trunk_Full",
      "rotation": 3
    },
    {
      "x": -14,
      "y": 47,
      "z": 2,
      "name": "Plant_Leaves_Oak",
      "rotation": 2
    },
    {
      "x": -14,
      "y": 48,
      "z": 2,
      "name": "Plant_Leaves_Oak",
      "rotation": 2
    },
    {
      "x": -14,
      "y": 50,
      "z": 2,
      "name": "Plant_Leaves_Beech",
      "rotation": 3
    },
    {
      "x": -14,
      "y": 29,
      "z": 3,
      "name": "Rock_Stone"
    },
    {
      "x": -14,
      "y": 30,
      "z": 3,
      "name": "Rock_Stone"
    },
    {
      "x": -14,
      "y": 31,
      "z": 3,
      "name": "Rock_Stone"
    },
    {
      "x": -14,
      "y": 32,
      "z": 3,
      "name": "Rock_Stone"
    },
    {
      "x": -14,
      "y": 33,
      "z": 3,
      "name": "Soil_Dirt"
    },
    {
      "x": -14,
      "y": 34,
      "z": 3,
      "name": "Soil_Grass"
    },
    {
      "x": -14,
      "y": 35,
      "z": 3,
      "name": "Plant_Grass_Sharp_Wild"
    },
    {
      "x": -14,
      "y": 36,
      "z": 3,
      "name": "Plant_Grass_Sharp_Wild",
      "filler": 1024
    },
    {
      "x": -14,
      "y": 39,
      "z": 3,
      "name": "Wood_Beech_Branch_Long",
      "rotation": 4
    },
    {
      "x": -14,
      "y": 41,
      "z": 3,
      "name": "Wood_Beech_Trunk_Full",
      "rotation": 3
    },
    {
      "x": -14,
      "y": 43,
      "z": 3,
      "name": "Plant_Leaves_Oak",
      "rotation": 2
    },
    {
      "x": -14,
      "y": 44,
      "z": 3,
      "name": "Plant_Leaves_Oak",
      "rotation": 2
    },
    {
      "x": -14,
      "y": 45,
      "z": 3,
      "name": "Plant_Leaves_Oak",
      "rotation": 2
    },
    {
      "x": -14,
      "y": 46,
      "z": 3,
      "name": "Wood_Beech_Branch_Long",
      "rotation": 4
    },
    {
      "x": -14,
      "y": 47,
      "z": 3,
      "name": "Plant_Leaves_Oak",
      "rotation": 2
    },
    {
      "x": -14,
      "y": 49,
      "z": 3,
      "name": "Plant_Leaves_Beech",
      "rotation": 3
    },
    {
      "x": -14,
      "y": 32,
      "z": 4,
      "name": "Rock_Stone"
    },
    {
      "x": -14,
      "y": 33,
      "z": 4,
      "name": "Soil_Grass"
    },
    {
      "x": -14,
      "y": 34,
      "z": 4,
      "name": "Plant_Grass_Sharp_Tall"
    },
    {
      "x": -14,
      "y": 35,
      "z": 4,
      "name": "Plant_Grass_Sharp_Tall",
      "filler": 1024
    },
    {
      "x": -14,
      "y": 39,
      "z": 4,
      "name": "Wood_Beech_Branch_Long",
      "rotation": 4
    },
    {
      "x": -14,
      "y": 41,
      "z": 4,
      "name": "Wood_Beech_Trunk_Full",
      "rotation": 3
    },
    {
      "x": -14,
      "y": 42,
      "z": 4,
      "name": "Wood_Beech_Trunk_Full",
      "rotation": 3
    },
    {
      "x": -14,
      "y": 43,
      "z": 4,
      "name": "Wood_Beech_Branch_Long",
      "rotation": 3
    },
    {
      "x": -14,
      "y": 44,
      "z": 4,
      "name": "Wood_Beech_Branch_Long",
      "rotation": 3
    },
    {
      "x": -14,
      "y": 45,
      "z": 4,
      "name": "Plant_Leaves_Beech",
      "rotation": 3
    },
    {
      "x": -14,
      "y": 46,
      "z": 4,
      "name": "Plant_Leaves_Beech",
      "rotation": 3
    },
    {
      "x": -14,
      "y": 47,
      "z": 4,
      "name": "Plant_Leaves_Beech",
      "rotation": 3
    },
    {
      "x": -14,
      "y": 39,
      "z": 5,
      "name": "Plant_Leaves_Beech",
      "rotation": 3
    },
    {
      "x": -14,
      "y": 42,
      "z": 5,
      "name": "Wood_Beech_Branch_Long",
      "rotation": 4
    },
    {
      "x": -14,
      "y": 45,
      "z": 5,
      "name": "Plant_Leaves_Beech",
      "rotation": 3
    },
    {
      "x": -14,
      "y": 46,
      "z": 5,
      "name": "Plant_Leaves_Beech",
      "rotation": 3
    },
    {
      "x": -14,
      "y": 47,
      "z": 5,
      "name": "Plant_Leaves_Beech",
      "rotation": 3
    },
    {
      "x": -14,
      "y": 42,
      "z": 6,
      "name": "Plant_Leaves_Beech",
      "rotation": 3
    },
    {
      "x": -14,
      "y": 44,
      "z": 6,
      "name": "Plant_Leaves_Beech",
      "rotation": 3
    },
    {
      "x": -14,
      "y": 45,
      "z": 6,
      "name": "Plant_Leaves_Beech",
      "rotation": 3
    },
    {
      "x": -13,
      "y": 43,
      "z": -7,
      "name": "Plant_Leaves_Oak",
      "rotation": 2
    },
    {
      "x": -13,
      "y": 44,
      "z": -7,
      "name": "Plant_Leaves_Oak",
      "rotation": 2
    },
    {
      "x": -13,
      "y": 45,
      "z": -7,
      "name": "Plant_Leaves_Oak",
      "rotation": 2
    },
    {
      "x": -13,
      "y": 40,
      "z": -6,
      "name": "Plant_Leaves_Oak",
      "rotation": 2
    },
    {
      "x": -13,
      "y": 47,
      "z": -6,
      "name": "Plant_Leaves_Oak",
      "rotation": 2
    },
    {
      "x": -13,
      "y": 40,
      "z": -5,
      "name": "Plant_Leaves_Oak",
      "rotation": 2
    },
    {
      "x": -13,
      "y": 49,
      "z": -5,
      "name": "Plant_Leaves_Oak",
      "rotation": 2
    },
    {
      "x": -13,
      "y": 33,
      "z": -4,
      "name": "Soil_Grass"
    },
    {
      "x": -13,
      "y": 48,
      "z": -4,
      "name": "Plant_Leaves_Oak",
      "rotation": 2
    },
    {
      "x": -13,
      "y": 49,
      "z": -4,
      "name": "Plant_Leaves_Oak",
      "rotation": 2
    },
    {
      "x": -13,
      "y": 32,
      "z": -3,
      "name": "Soil_Dirt"
    },
    {
      "x": -13,
      "y": 33,
      "z": -3,
      "name": "Soil_Dirt"
    },
    {
      "x": -13,
      "y": 34,
      "z": -3,
      "name": "Soil_Grass"
    },
    {
      "x": -13,
      "y": 35,
      "z": -3,
      "name": "Plant_Grass_Sharp"
    },
    {
      "x": -13,
      "y": 40,
      "z": -3,
      "name": "Plant_Leaves_Beech",
      "rotation": 3
    },
    {
      "x": -13,
      "y": 41,
      "z": -3,
      "name": "Plant_Leaves_Beech",
      "rotation": 3
    },
    {
      "x": -13,
      "y": 42,
      "z": -3,
      "name": "Plant_Leaves_Beech",
      "rotation": 3
    },
    {
      "x": -13,
      "y": 44,
      "z": -3,
      "name": "Wood_Oak_Branch_Long",
      "rotation": 7
    },
    {
      "x": -13,
      "y": 49,
      "z": -3,
      "name": "Plant_Leaves_Oak",
      "rotation": 2
    },
    {
      "x": -13,
      "y": 50,
      "z": -3,
      "name": "Plant_Leaves_Oak",
      "rotation": 2
    },
    {
      "x": -13,
      "y": 31,
      "z": -2,
      "name": "Rock_Stone"
    },
    {
      "x": -13,
      "y": 32,
      "z": -2,
      "name": "Wood_Oak_Trunk",
      "rotation": 2
    },
    {
      "x": -13,
      "y": 33,
      "z": -2,
      "name": "Wood_Oak_Trunk",
      "rotation": 2
    },
    {
      "x": -13,
      "y": 34,
      "z": -2,
      "name": "Wood_Oak_Trunk",
      "rotation": 2
    },
    {
      "x": -13,
      "y": 35,
      "z": -2,
      "name": "Wood_Oak_Trunk",
      "rotation": 2
    },
    {
      "x": -13,
      "y": 36,
      "z": -2,
      "name": "Wood_Oak_Trunk",
      "rotation": 2
    },
    {
      "x": -13,
      "y": 37,
      "z": -2,
      "name": "Wood_Oak_Trunk_Full",
      "rotation": 2
    },
    {
      "x": -13,
      "y": 39,
      "z": -2,
      "name": "Plant_Leaves_Beech",
      "rotation": 3
    },
    {
      "x": -13,
      "y": 40,
      "z": -2,
      "name": "Plant_Leaves_Beech",
      "rotation": 3
    },
    {
      "x": -13,
      "y": 41,
      "z": -2,
      "name": "Plant_Leaves_Beech",
      "rotation": 3
    },
    {
      "x": -13,
      "y": 42,
      "z": -2,
      "name": "Plant_Leaves_Beech",
      "rotation": 3
    },
    {
      "x": -13,
      "y": 44,
      "z": -2,
      "name": "Plant_Leaves_Beech",
      "rotation": 3
    },
    {
      "x": -13,
      "y": 49,
      "z": -2,
      "name": "Plant_Leaves_Oak",
      "rotation": 2
    },
    {
      "x": -13,
      "y": 50,
      "z": -2,
      "name": "Plant_Leaves_Oak",
      "rotation": 2
    },
    {
      "x": -13,
      "y": 18,
      "z": -1,
      "name": "Rock_Stone"
    },
    {
      "x": -13,
      "y": 19,
      "z": -1,
      "name": "Rock_Stone"
    },
    {
      "x": -13,
      "y": 29,
      "z": -1,
      "name": "Rock_Stone"
    },
    {
      "x": -13,
      "y": 30,
      "z": -1,
      "name": "Rock_Stone"
    },
    {
      "x": -13,
      "y": 31,
      "z": -1,
      "name": "Rock_Stone"
    },
    {
      "x": -13,
      "y": 32,
      "z": -1,
      "name": "Rock_Stone"
    },
    {
      "x": -13,
      "y": 33,
      "z": -1,
      "name": "Soil_Dirt"
    },
    {
      "x": -13,
      "y": 34,
      "z": -1,
      "name": "Soil_Grass"
    },
    {
      "x": -13,
      "y": 35,
      "z": -1,
      "name": "Plant_Grass_Sharp"
    },
    {
      "x": -13,
      "y": 42,
      "z": -1,
      "name": "Wood_Oak_Trunk_Full",
      "rotation": 2
    },
    {
      "x": -13,
      "y": 43,
      "z": -1,
      "name": "Wood_Oak_Trunk_Full",
      "rotation": 2
    },
    {
      "x": -13,
      "y": 44,
      "z": -1,
      "name": "Plant_Leaves_Beech",
      "rotation": 3
    },
    {
      "x": -13,
      "y": 45,
      "z": -1,
      "name": "Plant_Leaves_Beech",
      "rotation": 3
    },
    {
      "x": -13,
      "y": 47,
      "z": -1,
      "name": "Plant_Leaves_Beech",
      "rotation": 3
    },
    {
      "x": -13,
      "y": 49,
      "z": -1,
      "name": "Plant_Leaves_Oak",
      "rotation": 2
    },
    {
      "x": -13,
      "y": 16,
      "z": 0,
      "name": "Rock_Stone"
    },
    {
      "x": -13,
      "y": 17,
      "z": 0,
      "name": "Rock_Stone"
    },
    {
      "x": -13,
      "y": 18,
      "z": 0,
      "name": "Rock_Stone"
    },
    {
      "x": -13,
      "y": 19,
      "z": 0,
      "name": "Rock_Stone"
    },
    {
      "x": -13,
      "y": 20,
      "z": 0,
      "name": "Rock_Stone"
    },
    {
      "x": -13,
      "y": 21,
      "z": 0,
      "name": "Rock_Stone"
    },
    {
      "x": -13,
      "y": 22,
      "z": 0,
      "name": "Rock_Stone"
    },
    {
      "x": -13,
      "y": 23,
      "z": 0,
      "name": "Rock_Stone"
    },
    {
      "x": -13,
      "y": 24,
      "z": 0,
      "name": "Rock_Stone"
    },
    {
      "x": -13,
      "y": 25,
      "z": 0,
      "name": "Rock_Stone"
    },
    {
      "x": -13,
      "y": 26,
      "z": 0,
      "name": "Rock_Stone"
    },
    {
      "x": -13,
      "y": 27,
      "z": 0,
      "name": "Rock_Stone"
    },
    {
      "x": -13,
      "y": 28,
      "z": 0,
      "name": "Rock_Stone"
    },
    {
      "x": -13,
      "y": 29,
      "z": 0,
      "name": "Rock_Stone"
    },
    {
      "x": -13,
      "y": 30,
      "z": 0,
      "name": "Rock_Stone"
    },
    {
      "x": -13,
      "y": 31,
      "z": 0,
      "name": "Rock_Stone"
    },
    {
      "x": -13,
      "y": 32,
      "z": 0,
      "name": "Rock_Stone"
    },
    {
      "x": -13,
      "y": 33,
      "z": 0,
      "name": "Soil_Dirt"
    },
    {
      "x": -13,
      "y": 34,
      "z": 0,
      "name": "Soil_Grass"
    },
    {
      "x": -13,
      "y": 40,
      "z": 0,
      "name": "Wood_Beech_Branch_Long",
      "rotation": 7
    },
    {
      "x": -13,
      "y": 42,
      "z": 0,
      "name": "Wood_Oak_Branch_Long",
      "rotation": 6
    },
    {
      "x": -13,
      "y": 43,
      "z": 0,
      "name": "Wood_Oak_Trunk_Full",
      "rotation": 2
    },
    {
      "x": -13,
      "y": 44,
      "z": 0,
      "name": "Wood_Oak_Trunk_Full",
      "rotation": 2
    },
    {
      "x": -13,
      "y": 45,
      "z": 0,
      "name": "Plant_Leaves_Beech",
      "rotation": 3
    },
    {
      "x": -13,
      "y": 46,
      "z": 0,
      "name": "Plant_Leaves_Beech",
      "rotation": 3
    },
    {
      "x": -13,
      "y": 47,
      "z": 0,
      "name": "Plant_Leaves_Beech",
      "rotation": 3
    },
    {
      "x": -13,
      "y": 48,
      "z": 0,
      "name": "Plant_Leaves_Beech",
      "rotation": 3
    },
    {
      "x": -13,
      "y": 49,
      "z": 0,
      "name": "Plant_Leaves_Oak",
      "rotation": 2
    },
    {
      "x": -13,
      "y": 15,
      "z": 1,
      "name": "Rock_Stone"
    },
    {
      "x": -13,
      "y": 16,
      "z": 1,
      "name": "Rock_Stone"
    },
    {
      "x": -13,
      "y": 17,
      "z": 1,
      "name": "Rock_Stone"
    },
    {
      "x": -13,
      "y": 18,
      "z": 1,
      "name": "Rock_Stone"
    },
    {
      "x": -13,
      "y": 19,
      "z": 1,
      "name": "Rock_Stone"
    },
    {
      "x": -13,
      "y": 20,
      "z": 1,
      "name": "Rock_Stone"
    },
    {
      "x": -13,
      "y": 21,
      "z": 1,
      "name": "Rock_Stone"
    },
    {
      "x": -13,
      "y": 22,
      "z": 1,
      "name": "Rock_Stone"
    },
    {
      "x": -13,
      "y": 23,
      "z": 1,
      "name": "Rock_Stone"
    },
    {
      "x": -13,
      "y": 24,
      "z": 1,
      "name": "Rock_Stone"
    },
    {
      "x": -13,
      "y": 25,
      "z": 1,
      "name": "Rock_Stone"
    },
    {
      "x": -13,
      "y": 26,
      "z": 1,
      "name": "Rock_Stone"
    },
    {
      "x": -13,
      "y": 27,
      "z": 1,
      "name": "Rock_Stone"
    },
    {
      "x": -13,
      "y": 28,
      "z": 1,
      "name": "Rock_Stone"
    },
    {
      "x": -13,
      "y": 29,
      "z": 1,
      "name": "Rock_Stone"
    },
    {
      "x": -13,
      "y": 30,
      "z": 1,
      "name": "Rock_Stone"
    },
    {
      "x": -13,
      "y": 31,
      "z": 1,
      "name": "Rock_Stone"
    },
    {
      "x": -13,
      "y": 32,
      "z": 1,
      "name": "Soil_Dirt"
    },
    {
      "x": -13,
      "y": 33,
      "z": 1,
      "name": "Soil_Dirt"
    },
    {
      "x": -13,
      "y": 34,
      "z": 1,
      "name": "Soil_Grass"
    },
    {
      "x": -13,
      "y": 41,
      "z": 1,
      "name": "Wood_Oak_Branch_Corner",
      "rotation": 1
    },
    {
      "x": -13,
      "y": 42,
      "z": 1,
      "name": "Wood_Oak_Branch_Corner",
      "rotation": 10
    },
    {
      "x": -13,
      "y": 44,
      "z": 1,
      "name": "Wood_Oak_Branch_Long",
      "rotation": 6
    },
    {
      "x": -13,
      "y": 45,
      "z": 1,
      "name": "Plant_Leaves_Beech",
      "rotation": 3
    },
    {
      "x": -13,
      "y": 48,
      "z": 1,
      "name": "Plant_Leaves_Beech",
      "rotation": 3
    },
    {
      "x": -13,
      "y": 49,
      "z": 1,
      "name": "Plant_Leaves_Beech",
      "rotation": 3
    },
    {
      "x": -13,
      "y": 14,
      "z": 2,
      "name": "Rock_Stone"
    },
    {
      "x": -13,
      "y": 15,
      "z": 2,
      "name": "Rock_Stone"
    },
    {
      "x": -13,
      "y": 16,
      "z": 2,
      "name": "Rock_Stone"
    },
    {
      "x": -13,
      "y": 17,
      "z": 2,
      "name": "Rock_Stone"
    },
    {
      "x": -13,
      "y": 18,
      "z": 2,
      "name": "Rock_Stone"
    },
    {
      "x": -13,
      "y": 19,
      "z": 2,
      "name": "Rock_Stone"
    },
    {
      "x": -13,
      "y": 20,
      "z": 2,
      "name": "Rock_Stone"
    },
    {
      "x": -13,
      "y": 21,
      "z": 2,
      "name": "Rock_Stone"
    },
    {
      "x": -13,
      "y": 22,
      "z": 2,
      "name": "Rock_Stone"
    },
    {
      "x": -13,
      "y": 23,
      "z": 2,
      "name": "Rock_Stone"
    },
    {
      "x": -13,
      "y": 24,
      "z": 2,
      "name": "Rock_Stone"
    },
    {
      "x": -13,
      "y": 25,
      "z": 2,
      "name": "Rock_Stone"
    },
    {
      "x": -13,
      "y": 26,
      "z": 2,
      "name": "Rock_Stone"
    },
    {
      "x": -13,
      "y": 27,
      "z": 2,
      "name": "Rock_Stone"
    },
    {
      "x": -13,
      "y": 28,
      "z": 2,
      "name": "Rock_Stone"
    },
    {
      "x": -13,
      "y": 29,
      "z": 2,
      "name": "Rock_Stone"
    },
    {
      "x": -13,
      "y": 30,
      "z": 2,
      "name": "Rock_Stone"
    },
    {
      "x": -13,
      "y": 31,
      "z": 2,
      "name": "Rock_Stone"
    },
    {
      "x": -13,
      "y": 32,
      "z": 2,
      "name": "Soil_Dirt"
    },
    {
      "x": -13,
      "y": 33,
      "z": 2,
      "name": "Soil_Dirt"
    },
    {
      "x": -13,
      "y": 34,
      "z": 2,
      "name": "Soil_Grass"
    },
    {
      "x": -13,
      "y": 40,
      "z": 2,
      "name": "Wood_Beech_Branch_Long",
      "rotation": 7
    },
    {
      "x": -13,
      "y": 41,
      "z": 2,
      "name": "Plant_Leaves_Oak",
      "rotation": 2
    },
    {
      "x": -13,
      "y": 43,
      "z": 2,
      "name": "Wood_Beech_Branch_Long",
      "rotation": 7
    },
    {
      "x": -13,
      "y": 44,
      "z": 2,
      "name": "Wood_Oak_Branch_Long",
      "rotation": 6
    },
    {
      "x": -13,
      "y": 45,
      "z": 2,
      "name": "Wood_Beech_Branch_Corner",
      "rotation": 1
    },
    {
      "x": -13,
      "y": 46,
      "z": 2,
      "name": "Wood_Beech_Branch_Long",
      "rotation": 3
    },
    {
      "x": -13,
      "y": 47,
      "z": 2,
      "name": "Wood_Beech_Branch_Long",
      "rotation": 3
    },
    {
      "x": -13,
      "y": 48,
      "z": 2,
      "name": "Wood_Beech_Branch_Long",
      "rotation": 3
    },
    {
      "x": -13,
      "y": 49,
      "z": 2,
      "name": "Plant_Leaves_Beech",
      "rotation": 3
    },
    {
      "x": -13,
      "y": 14,
      "z": 3,
      "name": "Rock_Stone"
    },
    {
      "x": -13,
      "y": 15,
      "z": 3,
      "name": "Rock_Stone"
    },
    {
      "x": -13,
      "y": 16,
      "z": 3,
      "name": "Rock_Stone"
    },
    {
      "x": -13,
      "y": 17,
      "z": 3,
      "name": "Rock_Stone"
    },
    {
      "x": -13,
      "y": 28,
      "z": 3,
      "name": "Rock_Stone"
    },
    {
      "x": -13,
      "y": 29,
      "z": 3,
      "name": "Rock_Stone"
    },
    {
      "x": -13,
      "y": 30,
      "z": 3,
      "name": "Rock_Stone"
    },
    {
      "x": -13,
      "y": 31,
      "z": 3,
      "name": "Rock_Stone"
    },
    {
      "x": -13,
      "y": 32,
      "z": 3,
      "name": "Rock_Stone"
    },
    {
      "x": -13,
      "y": 33,
      "z": 3,
      "name": "Soil_Dirt"
    },
    {
      "x": -13,
      "y": 34,
      "z": 3,
      "name": "Soil_Grass"
    },
    {
      "x": -13,
      "y": 43,
      "z": 3,
      "name": "Plant_Leaves_Oak",
      "rotation": 2
    },
    {
      "x": -13,
      "y": 44,
      "z": 3,
      "name": "Wood_Oak_Branch_Corner"
    },
    {
      "x": -13,
      "y": 45,
      "z": 3,
      "name": "Plant_Leaves_Beech",
      "rotation": 3
    },
    {
      "x": -13,
      "y": 46,
      "z": 3,
      "name": "Plant_Leaves_Oak",
      "rotation": 2
    },
    {
      "x": -13,
      "y": 47,
      "z": 3,
      "name": "Plant_Leaves_Beech",
      "rotation": 3
    },
    {
      "x": -13,
      "y": 48,
      "z": 3,
      "name": "Plant_Leaves_Beech",
      "rotation": 3
    },
    {
      "x": -13,
      "y": 31,
      "z": 4,
      "name": "Rock_Stone"
    },
    {
      "x": -13,
      "y": 32,
      "z": 4,
      "name": "Rock_Stone"
    },
    {
      "x": -13,
      "y": 33,
      "z": 4,
      "name": "Soil_Grass"
    },
    {
      "x": -13,
      "y": 39,
      "z": 4,
      "name": "Plant_Leaves_Beech",
      "rotation": 3
    },
    {
      "x": -13,
      "y": 42,
      "z": 4,
      "name": "Wood_Beech_Branch_Long",
      "rotation": 7
    },
    {
      "x": -13,
      "y": 43,
      "z": 4,
      "name": "Plant_Leaves_Oak",
      "rotation": 2
    },
    {
      "x": -13,
      "y": 44,
      "z": 4,
      "name": "Plant_Leaves_Oak",
      "rotation": 2
    },
    {
      "x": -13,
      "y": 45,
      "z": 4,
      "name": "Plant_Leaves_Beech",
      "rotation": 3
    },
    {
      "x": -13,
      "y": 46,
      "z": 4,
      "name": "Plant_Leaves_Beech",
      "rotation": 3
    },
    {
      "x": -13,
      "y": 39,
      "z": 5,
      "name": "Plant_Leaves_Beech",
      "rotation": 3
    },
    {
      "x": -13,
      "y": 44,
      "z": 5,
      "name": "Plant_Leaves_Beech",
      "rotation": 3
    },
    {
      "x": -13,
      "y": 45,
      "z": 5,
      "name": "Plant_Leaves_Beech",
      "rotation": 3
    },
    {
      "x": -13,
      "y": 40,
      "z": 6,
      "name": "Plant_Leaves_Beech",
      "rotation": 3
    },
    {
      "x": -13,
      "y": 41,
      "z": 6,
      "name": "Plant_Leaves_Beech",
      "rotation": 3
    },
    {
      "x": -13,
      "y": 42,
      "z": 6,
      "name": "Plant_Leaves_Beech",
      "rotation": 3
    },
    {
      "x": -13,
      "y": 43,
      "z": 6,
      "name": "Plant_Leaves_Beech",
      "rotation": 3
    },
    {
      "x": -13,
      "y": 44,
      "z": 6,
      "name": "Plant_Leaves_Beech",
      "rotation": 3
    },
    {
      "x": -12,
      "y": 43,
      "z": -8,
      "name": "Plant_Leaves_Oak",
      "rotation": 2
    },
    {
      "x": -12,
      "y": 44,
      "z": -8,
      "name": "Plant_Leaves_Oak",
      "rotation": 2
    },
    {
      "x": -12,
      "y": 45,
      "z": -8,
      "name": "Plant_Leaves_Oak",
      "rotation": 2
    },
    {
      "x": -12,
      "y": 40,
      "z": -7,
      "name": "Plant_Leaves_Oak",
      "rotation": 2
    },
    {
      "x": -12,
      "y": 43,
      "z": -7,
      "name": "Plant_Leaves_Oak",
      "rotation": 2
    },
    {
      "x": -12,
      "y": 44,
      "z": -7,
      "name": "Plant_Leaves_Oak",
      "rotation": 2
    },
    {
      "x": -12,
      "y": 45,
      "z": -7,
      "name": "Plant_Leaves_Oak",
      "rotation": 2
    },
    {
      "x": -12,
      "y": 47,
      "z": -7,
      "name": "Plant_Leaves_Oak",
      "rotation": 2
    },
    {
      "x": -12,
      "y": 40,
      "z": -6,
      "name": "Plant_Leaves_Oak",
      "rotation": 2
    },
    {
      "x": -12,
      "y": 41,
      "z": -6,
      "name": "Plant_Leaves_Oak",
      "rotation": 2
    },
    {
      "x": -12,
      "y": 43,
      "z": -6,
      "name": "Plant_Leaves_Oak",
      "rotation": 2
    },
    {
      "x": -12,
      "y": 44,
      "z": -6,
      "name": "Wood_Oak_Branch_Long",
      "rotation": 6
    },
    {
      "x": -12,
      "y": 46,
      "z": -6,
      "name": "Plant_Leaves_Oak",
      "rotation": 2
    },
    {
      "x": -12,
      "y": 48,
      "z": -6,
      "name": "Plant_Leaves_Oak",
      "rotation": 2
    },
    {
      "x": -12,
      "y": 39,
      "z": -5,
      "name": "Plant_Leaves_Oak",
      "rotation": 2
    },
    {
      "x": -12,
      "y": 40,
      "z": -5,
      "name": "Wood_Oak_Branch_Long",
      "rotation": 6
    },
    {
      "x": -12,
      "y": 44,
      "z": -5,
      "name": "Wood_Oak_Branch_Long",
      "rotation": 6
    },
    {
      "x": -12,
      "y": 48,
      "z": -5,
      "name": "Plant_Leaves_Oak",
      "rotation": 2
    },
    {
      "x": -12,
      "y": 32,
      "z": -4,
      "name": "Soil_Dirt"
    },
    {
      "x": -12,
      "y": 33,
      "z": -4,
      "name": "Soil_Grass"
    },
    {
      "x": -12,
      "y": 40,
      "z": -4,
      "name": "Wood_Oak_Branch_Long",
      "rotation": 6
    },
    {
      "x": -12,
      "y": 44,
      "z": -4,
      "name": "Wood_Oak_Branch_Long",
      "rotation": 6
    },
    {
      "x": -12,
      "y": 45,
      "z": -4,
      "name": "Wood_Oak_Trunk_Full",
      "rotation": 2
    },
    {
      "x": -12,
      "y": 46,
      "z": -4,
      "name": "Wood_Oak_Trunk_Full",
      "rotation": 2
    },
    {
      "x": -12,
      "y": 47,
      "z": -4,
      "name": "Wood_Oak_Branch_Long",
      "rotation": 2
    },
    {
      "x": -12,
      "y": 48,
      "z": -4,
      "name": "Wood_Oak_Branch_Long",
      "rotation": 2
    },
    {
      "x": -12,
      "y": 49,
      "z": -4,
      "name": "Plant_Leaves_Oak",
      "rotation": 2
    },
    {
      "x": -12,
      "y": 50,
      "z": -4,
      "name": "Plant_Leaves_Oak",
      "rotation": 2
    },
    {
      "x": -12,
      "y": 30,
      "z": -3,
      "name": "Rock_Stone"
    },
    {
      "x": -12,
      "y": 31,
      "z": -3,
      "name": "Rock_Stone"
    },
    {
      "x": -12,
      "y": 32,
      "z": -3,
      "name": "Wood_Oak_Trunk",
      "rotation": 2
    },
    {
      "x": -12,
      "y": 33,
      "z": -3,
      "name": "Wood_Oak_Trunk",
      "rotation": 2
    },
    {
      "x": -12,
      "y": 34,
      "z": -3,
      "name": "Wood_Oak_Trunk",
      "rotation": 2
    },
    {
      "x": -12,
      "y": 35,
      "z": -3,
      "name": "Wood_Oak_Trunk",
      "rotation": 2
    },
    {
      "x": -12,
      "y": 36,
      "z": -3,
      "name": "Wood_Oak_Trunk",
      "rotation": 2
    },
    {
      "x": -12,
      "y": 37,
      "z": -3,
      "name": "Wood_Oak_Trunk_Full",
      "rotation": 2
    },
    {
      "x": -12,
      "y": 39,
      "z": -3,
      "name": "Wood_Oak_Branch_Corner",
      "rotation": 2
    },
    {
      "x": -12,
      "y": 40,
      "z": -3,
      "name": "Wood_Oak_Branch_Corner",
      "rotation": 10
    },
    {
      "x": -12,
      "y": 44,
      "z": -3,
      "name": "Wood_Oak_Trunk_Full",
      "rotation": 2
    },
    {
      "x": -12,
      "y": 45,
      "z": -3,
      "name": "Wood_Oak_Trunk_Full",
      "rotation": 2
    },
    {
      "x": -12,
      "y": 50,
      "z": -3,
      "name": "Plant_Leaves_Oak",
      "rotation": 2
    },
    {
      "x": -12,
      "y": 17,
      "z": -2,
      "name": "Rock_Stone"
    },
    {
      "x": -12,
      "y": 18,
      "z": -2,
      "name": "Rock_Stone"
    },
    {
      "x": -12,
      "y": 19,
      "z": -2,
      "name": "Rock_Stone"
    },
    {
      "x": -12,
      "y": 20,
      "z": -2,
      "name": "Rock_Stone"
    },
    {
      "x": -12,
      "y": 27,
      "z": -2,
      "name": "Rock_Stone"
    },
    {
      "x": -12,
      "y": 28,
      "z": -2,
      "name": "Rock_Stone"
    },
    {
      "x": -12,
      "y": 29,
      "z": -2,
      "name": "Rock_Stone"
    },
    {
      "x": -12,
      "y": 30,
      "z": -2,
      "name": "Rock_Stone"
    },
    {
      "x": -12,
      "y": 31,
      "z": -2,
      "name": "Rock_Stone"
    },
    {
      "x": -12,
      "y": 32,
      "z": -2,
      "name": "Wood_Oak_Trunk",
      "rotation": 2
    },
    {
      "x": -12,
      "y": 33,
      "z": -2,
      "name": "Wood_Oak_Trunk",
      "rotation": 2
    },
    {
      "x": -12,
      "y": 34,
      "z": -2,
      "name": "Wood_Oak_Trunk",
      "rotation": 2
    },
    {
      "x": -12,
      "y": 35,
      "z": -2,
      "name": "Wood_Oak_Trunk",
      "rotation": 2
    },
    {
      "x": -12,
      "y": 36,
      "z": -2,
      "name": "Wood_Oak_Trunk",
      "rotation": 2
    },
    {
      "x": -12,
      "y": 37,
      "z": -2,
      "name": "Wood_Oak_Trunk",
      "rotation": 2
    },
    {
      "x": -12,
      "y": 38,
      "z": -2,
      "name": "Wood_Oak_Trunk",
      "rotation": 2
    },
    {
      "x": -12,
      "y": 39,
      "z": -2,
      "name": "Wood_Oak_Trunk",
      "rotation": 2
    },
    {
      "x": -12,
      "y": 40,
      "z": -2,
      "name": "Plant_Leaves_Beech",
      "rotation": 3
    },
    {
      "x": -12,
      "y": 41,
      "z": -2,
      "name": "Plant_Leaves_Beech",
      "rotation": 3
    },
    {
      "x": -12,
      "y": 42,
      "z": -2,
      "name": "Wood_Oak_Trunk",
      "rotation": 2
    },
    {
      "x": -12,
      "y": 43,
      "z": -2,
      "name": "Wood_Oak_Trunk",
      "rotation": 2
    },
    {
      "x": -12,
      "y": 44,
      "z": -2,
      "name": "Wood_Oak_Trunk_Full",
      "rotation": 2
    },
    {
      "x": -12,
      "y": 50,
      "z": -2,
      "name": "Plant_Leaves_Oak",
      "rotation": 2
    },
    {
      "x": -12,
      "y": 14,
      "z": -1,
      "name": "Rock_Stone"
    },
    {
      "x": -12,
      "y": 15,
      "z": -1,
      "name": "Rock_Stone"
    },
    {
      "x": -12,
      "y": 16,
      "z": -1,
      "name": "Rock_Stone"
    },
    {
      "x": -12,
      "y": 17,
      "z": -1,
      "name": "Rock_Stone"
    },
    {
      "x": -12,
      "y": 18,
      "z": -1,
      "name": "Rock_Stone"
    },
    {
      "x": -12,
      "y": 19,
      "z": -1,
      "name": "Rock_Stone"
    },
    {
      "x": -12,
      "y": 20,
      "z": -1,
      "name": "Rock_Stone"
    },
    {
      "x": -12,
      "y": 21,
      "z": -1,
      "name": "Rock_Stone"
    },
    {
      "x": -12,
      "y": 22,
      "z": -1,
      "name": "Rock_Stone"
    },
    {
      "x": -12,
      "y": 23,
      "z": -1,
      "name": "Rock_Stone"
    },
    {
      "x": -12,
      "y": 24,
      "z": -1,
      "name": "Rock_Stone"
    },
    {
      "x": -12,
      "y": 25,
      "z": -1,
      "name": "Rock_Stone"
    },
    {
      "x": -12,
      "y": 26,
      "z": -1,
      "name": "Rock_Stone"
    },
    {
      "x": -12,
      "y": 27,
      "z": -1,
      "name": "Rock_Stone"
    },
    {
      "x": -12,
      "y": 28,
      "z": -1,
      "name": "Rock_Stone"
    },
    {
      "x": -12,
      "y": 29,
      "z": -1,
      "name": "Rock_Stone"
    },
    {
      "x": -12,
      "y": 30,
      "z": -1,
      "name": "Rock_Stone"
    },
    {
      "x": -12,
      "y": 31,
      "z": -1,
      "name": "Rock_Stone"
    },
    {
      "x": -12,
      "y": 32,
      "z": -1,
      "name": "Wood_Oak_Trunk",
      "rotation": 2
    },
    {
      "x": -12,
      "y": 33,
      "z": -1,
      "name": "Wood_Oak_Trunk",
      "rotation": 2
    },
    {
      "x": -12,
      "y": 34,
      "z": -1,
      "name": "Wood_Oak_Trunk",
      "rotation": 2
    },
    {
      "x": -12,
      "y": 35,
      "z": -1,
      "name": "Wood_Oak_Trunk",
      "rotation": 2
    },
    {
      "x": -12,
      "y": 36,
      "z": -1,
      "name": "Wood_Oak_Trunk_Full",
      "rotation": 2
    },
    {
      "x": -12,
      "y": 39,
      "z": -1,
      "name": "Wood_Oak_Branch_Long",
      "rotation": 6
    },
    {
      "x": -12,
      "y": 40,
      "z": -1,
      "name": "Plant_Leaves_Beech",
      "rotation": 3
    },
    {
      "x": -12,
      "y": 41,
      "z": -1,
      "name": "Plant_Leaves_Beech",
      "rotation": 3
    },
    {
      "x": -12,
      "y": 42,
      "z": -1,
      "name": "Plant_Leaves_Beech",
      "rotation": 3
    },
    {
      "x": -12,
      "y": 44,
      "z": -1,
      "name": "Plant_Leaves_Beech",
      "rotation": 3
    },
    {
      "x": -12,
      "y": 45,
      "z": -1,
      "name": "Plant_Leaves_Beech",
      "rotation": 3
    },
    {
      "x": -12,
      "y": 48,
      "z": -1,
      "name": "Plant_Leaves_Oak",
      "rotation": 2
    },
    {
      "x": -12,
      "y": 49,
      "z": -1,
      "name": "Plant_Leaves_Oak",
      "rotation": 2
    },
    {
      "x": -12,
      "y": 50,
      "z": -1,
      "name": "Plant_Leaves_Oak",
      "rotation": 2
    },
    {
      "x": -12,
      "y": 12,
      "z": 0,
      "name": "Rock_Stone"
    },
    {
      "x": -12,
      "y": 13,
      "z": 0,
      "name": "Rock_Stone"
    },
    {
      "x": -12,
      "y": 14,
      "z": 0,
      "name": "Rock_Stone"
    },
    {
      "x": -12,
      "y": 15,
      "z": 0,
      "name": "Rock_Stone"
    },
    {
      "x": -12,
      "y": 16,
      "z": 0,
      "name": "Rock_Stone"
    },
    {
      "x": -12,
      "y": 17,
      "z": 0,
      "name": "Rock_Stone"
    },
    {
      "x": -12,
      "y": 18,
      "z": 0,
      "name": "Rock_Stone"
    },
    {
      "x": -12,
      "y": 19,
      "z": 0,
      "name": "Rock_Stone"
    },
    {
      "x": -12,
      "y": 20,
      "z": 0,
      "name": "Rock_Stone"
    },
    {
      "x": -12,
      "y": 21,
      "z": 0,
      "name": "Rock_Stone"
    },
    {
      "x": -12,
      "y": 22,
      "z": 0,
      "name": "Rock_Stone"
    },
    {
      "x": -12,
      "y": 23,
      "z": 0,
      "name": "Rock_Stone"
    },
    {
      "x": -12,
      "y": 24,
      "z": 0,
      "name": "Rock_Stone"
    },
    {
      "x": -12,
      "y": 25,
      "z": 0,
      "name": "Rock_Stone"
    },
    {
      "x": -12,
      "y": 26,
      "z": 0,
      "name": "Rock_Stone"
    },
    {
      "x": -12,
      "y": 27,
      "z": 0,
      "name": "Rock_Stone"
    },
    {
      "x": -12,
      "y": 28,
      "z": 0,
      "name": "Rock_Stone"
    },
    {
      "x": -12,
      "y": 29,
      "z": 0,
      "name": "Rock_Stone"
    },
    {
      "x": -12,
      "y": 30,
      "z": 0,
      "name": "Rock_Stone"
    },
    {
      "x": -12,
      "y": 31,
      "z": 0,
      "name": "Rock_Stone"
    },
    {
      "x": -12,
      "y": 32,
      "z": 0,
      "name": "Soil_Dirt"
    },
    {
      "x": -12,
      "y": 33,
      "z": 0,
      "name": "Soil_Dirt"
    },
    {
      "x": -12,
      "y": 34,
      "z": 0,
      "name": "Soil_Grass"
    },
    {
      "x": -12,
      "y": 39,
      "z": 0,
      "name": "Plant_Leaves_Oak",
      "rotation": 2
    },
    {
      "x": -12,
      "y": 40,
      "z": 0,
      "name": "Plant_Leaves_Beech",
      "rotation": 3
    },
    {
      "x": -12,
      "y": 41,
      "z": 0,
      "name": "Plant_Leaves_Beech",
      "rotation": 3
    },
    {
      "x": -12,
      "y": 42,
      "z": 0,
      "name": "Plant_Leaves_Beech",
      "rotation": 3
    },
    {
      "x": -12,
      "y": 43,
      "z": 0,
      "name": "Plant_Leaves_Beech",
      "rotation": 3
    },
    {
      "x": -12,
      "y": 44,
      "z": 0,
      "name": "Wood_Oak_Branch_Long",
      "rotation": 7
    },
    {
      "x": -12,
      "y": 45,
      "z": 0,
      "name": "Plant_Leaves_Beech",
      "rotation": 3
    },
    {
      "x": -12,
      "y": 48,
      "z": 0,
      "name": "Plant_Leaves_Oak",
      "rotation": 2
    },
    {
      "x": -12,
      "y": 10,
      "z": 1,
      "name": "Rock_Stone"
    },
    {
      "x": -12,
      "y": 11,
      "z": 1,
      "name": "Rock_Stone"
    },
    {
      "x": -12,
      "y": 12,
      "z": 1,
      "name": "Rock_Stone"
    },
    {
      "x": -12,
      "y": 13,
      "z": 1,
      "name": "Rock_Stone"
    },
    {
      "x": -12,
      "y": 14,
      "z": 1,
      "name": "Rock_Stone"
    },
    {
      "x": -12,
      "y": 15,
      "z": 1,
      "name": "Rock_Stone"
    },
    {
      "x": -12,
      "y": 16,
      "z": 1,
      "name": "Rock_Stone"
    },
    {
      "x": -12,
      "y": 17,
      "z": 1,
      "name": "Rock_Stone"
    },
    {
      "x": -12,
      "y": 18,
      "z": 1,
      "name": "Rock_Stone"
    },
    {
      "x": -12,
      "y": 19,
      "z": 1,
      "name": "Rock_Stone"
    },
    {
      "x": -12,
      "y": 20,
      "z": 1,
      "name": "Rock_Stone"
    },
    {
      "x": -12,
      "y": 21,
      "z": 1,
      "name": "Rock_Stone"
    },
    {
      "x": -12,
      "y": 22,
      "z": 1,
      "name": "Rock_Stone"
    },
    {
      "x": -12,
      "y": 23,
      "z": 1,
      "name": "Rock_Stone"
    },
    {
      "x": -12,
      "y": 24,
      "z": 1,
      "name": "Rock_Stone"
    },
    {
      "x": -12,
      "y": 25,
      "z": 1,
      "name": "Rock_Stone"
    },
    {
      "x": -12,
      "y": 26,
      "z": 1,
      "name": "Rock_Stone"
    },
    {
      "x": -12,
      "y": 27,
      "z": 1,
      "name": "Rock_Stone"
    },
    {
      "x": -12,
      "y": 28,
      "z": 1,
      "name": "Rock_Stone"
    },
    {
      "x": -12,
      "y": 29,
      "z": 1,
      "name": "Rock_Stone"
    },
    {
      "x": -12,
      "y": 30,
      "z": 1,
      "name": "Rock_Stone"
    },
    {
      "x": -12,
      "y": 31,
      "z": 1,
      "name": "Rock_Stone"
    },
    {
      "x": -12,
      "y": 32,
      "z": 1,
      "name": "Soil_Dirt"
    },
    {
      "x": -12,
      "y": 33,
      "z": 1,
      "name": "Soil_Dirt"
    },
    {
      "x": -12,
      "y": 34,
      "z": 1,
      "name": "Soil_Grass"
    },
    {
      "x": -12,
      "y": 35,
      "z": 1,
      "name": "Plant_Grass_Sharp"
    },
    {
      "x": -12,
      "y": 39,
      "z": 1,
      "name": "Plant_Leaves_Oak",
      "rotation": 2
    },
    {
      "x": -12,
      "y": 40,
      "z": 1,
      "name": "Plant_Leaves_Beech",
      "rotation": 3
    },
    {
      "x": -12,
      "y": 41,
      "z": 1,
      "name": "Plant_Leaves_Oak",
      "rotation": 2
    },
    {
      "x": -12,
      "y": 42,
      "z": 1,
      "name": "Plant_Leaves_Beech",
      "rotation": 3
    },
    {
      "x": -12,
      "y": 43,
      "z": 1,
      "name": "Plant_Leaves_Beech",
      "rotation": 3
    },
    {
      "x": -12,
      "y": 45,
      "z": 1,
      "name": "Plant_Leaves_Beech",
      "rotation": 3
    },
    {
      "x": -12,
      "y": 48,
      "z": 1,
      "name": "Plant_Leaves_Beech",
      "rotation": 3
    },
    {
      "x": -12,
      "y": 8,
      "z": 2,
      "name": "Rock_Stone"
    },
    {
      "x": -12,
      "y": 9,
      "z": 2,
      "name": "Rock_Stone"
    },
    {
      "x": -12,
      "y": 10,
      "z": 2,
      "name": "Rock_Stone"
    },
    {
      "x": -12,
      "y": 11,
      "z": 2,
      "name": "Rock_Stone"
    },
    {
      "x": -12,
      "y": 12,
      "z": 2,
      "name": "Rock_Stone"
    },
    {
      "x": -12,
      "y": 13,
      "z": 2,
      "name": "Rock_Stone"
    },
    {
      "x": -12,
      "y": 14,
      "z": 2,
      "name": "Rock_Stone"
    },
    {
      "x": -12,
      "y": 15,
      "z": 2,
      "name": "Rock_Stone"
    },
    {
      "x": -12,
      "y": 16,
      "z": 2,
      "name": "Rock_Stone"
    },
    {
      "x": -12,
      "y": 17,
      "z": 2,
      "name": "Rock_Stone"
    },
    {
      "x": -12,
      "y": 18,
      "z": 2,
      "name": "Rock_Stone"
    },
    {
      "x": -12,
      "y": 19,
      "z": 2,
      "name": "Rock_Stone"
    },
    {
      "x": -12,
      "y": 20,
      "z": 2,
      "name": "Rock_Stone"
    },
    {
      "x": -12,
      "y": 21,
      "z": 2,
      "name": "Rock_Stone"
    },
    {
      "x": -12,
      "y": 22,
      "z": 2,
      "name": "Rock_Stone"
    },
    {
      "x": -12,
      "y": 23,
      "z": 2,
      "name": "Rock_Stone"
    },
    {
      "x": -12,
      "y": 24,
      "z": 2,
      "name": "Rock_Stone"
    },
    {
      "x": -12,
      "y": 25,
      "z": 2,
      "name": "Rock_Stone"
    },
    {
      "x": -12,
      "y": 26,
      "z": 2,
      "name": "Rock_Stone"
    },
    {
      "x": -12,
      "y": 27,
      "z": 2,
      "name": "Rock_Stone"
    },
    {
      "x": -12,
      "y": 28,
      "z": 2,
      "name": "Rock_Stone"
    },
    {
      "x": -12,
      "y": 29,
      "z": 2,
      "name": "Rock_Stone"
    },
    {
      "x": -12,
      "y": 30,
      "z": 2,
      "name": "Rock_Stone"
    },
    {
      "x": -12,
      "y": 31,
      "z": 2,
      "name": "Rock_Stone"
    },
    {
      "x": -12,
      "y": 32,
      "z": 2,
      "name": "Soil_Dirt"
    },
    {
      "x": -12,
      "y": 33,
      "z": 2,
      "name": "Soil_Dirt"
    },
    {
      "x": -12,
      "y": 34,
      "z": 2,
      "name": "Soil_Grass"
    },
    {
      "x": -12,
      "y": 35,
      "z": 2,
      "name": "Plant_Grass_Sharp"
    },
    {
      "x": -12,
      "y": 40,
      "z": 2,
      "name": "Wood_Beech_Branch_Long",
      "rotation": 7
    },
    {
      "x": -12,
      "y": 41,
      "z": 2,
      "name": "Plant_Leaves_Beech",
      "rotation": 3
    },
    {
      "x": -12,
      "y": 43,
      "z": 2,
      "name": "Plant_Leaves_Beech",
      "rotation": 3
    },
    {
      "x": -12,
      "y": 44,
      "z": 2,
      "name": "Plant_Leaves_Beech",
      "rotation": 3
    },
    {
      "x": -12,
      "y": 46,
      "z": 2,
      "name": "Plant_Leaves_Oak",
      "rotation": 2
    },
    {
      "x": -12,
      "y": 47,
      "z": 2,
      "name": "Plant_Leaves_Oak",
      "rotation": 2
    },
    {
      "x": -12,
      "y": 48,
      "z": 2,
      "name": "Plant_Leaves_Beech",
      "rotation": 3
    },
    {
      "x": -12,
      "y": 6,
      "z": 3,
      "name": "Rock_Stone"
    },
    {
      "x": -12,
      "y": 7,
      "z": 3,
      "name": "Rock_Stone"
    },
    {
      "x": -12,
      "y": 8,
      "z": 3,
      "name": "Rock_Stone"
    },
    {
      "x": -12,
      "y": 9,
      "z": 3,
      "name": "Rock_Stone"
    },
    {
      "x": -12,
      "y": 10,
      "z": 3,
      "name": "Rock_Stone"
    },
    {
      "x": -12,
      "y": 11,
      "z": 3,
      "name": "Rock_Stone"
    },
    {
      "x": -12,
      "y": 12,
      "z": 3,
      "name": "Rock_Stone"
    },
    {
      "x": -12,
      "y": 13,
      "z": 3,
      "name": "Rock_Stone"
    },
    {
      "x": -12,
      "y": 14,
      "z": 3,
      "name": "Rock_Stone"
    },
    {
      "x": -12,
      "y": 15,
      "z": 3,
      "name": "Rock_Stone"
    },
    {
      "x": -12,
      "y": 16,
      "z": 3,
      "name": "Rock_Stone"
    },
    {
      "x": -12,
      "y": 17,
      "z": 3,
      "name": "Rock_Stone"
    },
    {
      "x": -12,
      "y": 18,
      "z": 3,
      "name": "Rock_Stone"
    },
    {
      "x": -12,
      "y": 19,
      "z": 3,
      "name": "Rock_Stone"
    },
    {
      "x": -12,
      "y": 20,
      "z": 3,
      "name": "Rock_Stone"
    },
    {
      "x": -12,
      "y": 24,
      "z": 3,
      "name": "Rock_Stone"
    },
    {
      "x": -12,
      "y": 25,
      "z": 3,
      "name": "Rock_Stone"
    },
    {
      "x": -12,
      "y": 26,
      "z": 3,
      "name": "Rock_Stone"
    },
    {
      "x": -12,
      "y": 27,
      "z": 3,
      "name": "Rock_Stone"
    },
    {
      "x": -12,
      "y": 28,
      "z": 3,
      "name": "Rock_Stone"
    },
    {
      "x": -12,
      "y": 29,
      "z": 3,
      "name": "Rock_Stone"
    },
    {
      "x": -12,
      "y": 30,
      "z": 3,
      "name": "Rock_Stone"
    },
    {
      "x": -12,
      "y": 31,
      "z": 3,
      "name": "Rock_Stone"
    },
    {
      "x": -12,
      "y": 32,
      "z": 3,
      "name": "Rock_Stone"
    },
    {
      "x": -12,
      "y": 33,
      "z": 3,
      "name": "Soil_Dirt"
    },
    {
      "x": -12,
      "y": 34,
      "z": 3,
      "name": "Soil_Grass"
    },
    {
      "x": -12,
      "y": 35,
      "z": 3,
      "name": "Plant_Grass_Sharp"
    },
    {
      "x": -12,
      "y": 41,
      "z": 3,
      "name": "Plant_Leaves_Beech",
      "rotation": 3
    },
    {
      "x": -12,
      "y": 43,
      "z": 3,
      "name": "Plant_Leaves_Beech",
      "rotation": 3
    },
    {
      "x": -12,
      "y": 44,
      "z": 3,
      "name": "Plant_Leaves_Oak",
      "rotation": 2
    },
    {
      "x": -12,
      "y": 45,
      "z": 3,
      "name": "Plant_Leaves_Beech",
      "rotation": 3
    },
    {
      "x": -12,
      "y": 46,
      "z": 3,
      "name": "Plant_Leaves_Oak",
      "rotation": 2
    },
    {
      "x": -12,
      "y": 47,
      "z": 3,
      "name": "Plant_Leaves_Beech",
      "rotation": 3
    },
    {
      "x": -12,
      "y": 48,
      "z": 3,
      "name": "Plant_Leaves_Beech",
      "rotation": 3
    },
    {
      "x": -12,
      "y": 6,
      "z": 4,
      "name": "Rock_Stone"
    },
    {
      "x": -12,
      "y": 7,
      "z": 4,
      "name": "Rock_Stone"
    },
    {
      "x": -12,
      "y": 8,
      "z": 4,
      "name": "Rock_Stone"
    },
    {
      "x": -12,
      "y": 9,
      "z": 4,
      "name": "Rock_Stone"
    },
    {
      "x": -12,
      "y": 10,
      "z": 4,
      "name": "Rock_Stone"
    },
    {
      "x": -12,
      "y": 11,
      "z": 4,
      "name": "Rock_Stone"
    },
    {
      "x": -12,
      "y": 12,
      "z": 4,
      "name": "Rock_Stone"
    },
    {
      "x": -12,
      "y": 13,
      "z": 4,
      "name": "Rock_Stone"
    },
    {
      "x": -12,
      "y": 14,
      "z": 4,
      "name": "Rock_Stone"
    },
    {
      "x": -12,
      "y": 15,
      "z": 4,
      "name": "Rock_Stone"
    },
    {
      "x": -12,
      "y": 16,
      "z": 4,
      "name": "Rock_Stone"
    },
    {
      "x": -12,
      "y": 30,
      "z": 4,
      "name": "Rock_Stone"
    },
    {
      "x": -12,
      "y": 31,
      "z": 4,
      "name": "Rock_Stone"
    },
    {
      "x": -12,
      "y": 32,
      "z": 4,
      "name": "Rock_Stone"
    },
    {
      "x": -12,
      "y": 33,
      "z": 4,
      "name": "Soil_Grass"
    },
    {
      "x": -12,
      "y": 42,
      "z": 4,
      "name": "Wood_Beech_Branch_Long",
      "rotation": 7
    },
    {
      "x": -12,
      "y": 43,
      "z": 4,
      "name": "Plant_Leaves_Oak",
      "rotation": 2
    },
    {
      "x": -12,
      "y": 44,
      "z": 4,
      "name": "Plant_Leaves_Beech",
      "rotation": 3
    },
    {
      "x": -12,
      "y": 45,
      "z": 4,
      "name": "Plant_Leaves_Beech",
      "rotation": 3
    },
    {
      "x": -12,
      "y": 44,
      "z": 5,
      "name": "Plant_Leaves_Beech",
      "rotation": 3
    },
    {
      "x": -12,
      "y": 41,
      "z": 6,
      "name": "Plant_Leaves_Beech",
      "rotation": 3
    },
    {
      "x": -12,
      "y": 42,
      "z": 6,
      "name": "Plant_Leaves_Beech",
      "rotation": 3
    },
    {
      "x": -11,
      "y": 44,
      "z": -8,
      "name": "Plant_Leaves_Oak",
      "rotation": 2
    },
    {
      "x": -11,
      "y": 40,
      "z": -7,
      "name": "Plant_Leaves_Oak",
      "rotation": 2
    },
    {
      "x": -11,
      "y": 43,
      "z": -7,
      "name": "Plant_Leaves_Oak",
      "rotation": 2
    },
    {
      "x": -11,
      "y": 44,
      "z": -7,
      "name": "Plant_Leaves_Oak",
      "rotation": 2
    },
    {
      "x": -11,
      "y": 45,
      "z": -7,
      "name": "Plant_Leaves_Oak",
      "rotation": 2
    },
    {
      "x": -11,
      "y": 40,
      "z": -6,
      "name": "Plant_Leaves_Oak",
      "rotation": 2
    },
    {
      "x": -11,
      "y": 41,
      "z": -6,
      "name": "Plant_Leaves_Oak",
      "rotation": 2
    },
    {
      "x": -11,
      "y": 43,
      "z": -6,
      "name": "Plant_Leaves_Oak",
      "rotation": 2
    },
    {
      "x": -11,
      "y": 44,
      "z": -6,
      "name": "Plant_Leaves_Oak",
      "rotation": 2
    },
    {
      "x": -11,
      "y": 47,
      "z": -6,
      "name": "Plant_Leaves_Oak",
      "rotation": 2
    },
    {
      "x": -11,
      "y": 48,
      "z": -6,
      "name": "Plant_Leaves_Oak",
      "rotation": 2
    },
    {
      "x": -11,
      "y": 40,
      "z": -5,
      "name": "Plant_Leaves_Oak",
      "rotation": 2
    },
    {
      "x": -11,
      "y": 43,
      "z": -5,
      "name": "Plant_Leaves_Oak",
      "rotation": 2
    },
    {
      "x": -11,
      "y": 44,
      "z": -5,
      "name": "Plant_Leaves_Oak",
      "rotation": 2
    },
    {
      "x": -11,
      "y": 48,
      "z": -5,
      "name": "Plant_Leaves_Oak",
      "rotation": 2
    },
    {
      "x": -11,
      "y": 49,
      "z": -5,
      "name": "Plant_Leaves_Oak",
      "rotation": 2
    },
    {
      "x": -11,
      "y": 31,
      "z": -4,
      "name": "Rock_Stone"
    },
    {
      "x": -11,
      "y": 32,
      "z": -4,
      "name": "Rock_Stone"
    },
    {
      "x": -11,
      "y": 33,
      "z": -4,
      "name": "Soil_Grass"
    },
    {
      "x": -11,
      "y": 34,
      "z": -4,
      "name": "Plant_Grass_Sharp"
    },
    {
      "x": -11,
      "y": 40,
      "z": -4,
      "name": "Plant_Leaves_Oak",
      "rotation": 2
    },
    {
      "x": -11,
      "y": 49,
      "z": -4,
      "name": "Plant_Leaves_Oak",
      "rotation": 2
    },
    {
      "x": -11,
      "y": 28,
      "z": -3,
      "name": "Rock_Stone"
    },
    {
      "x": -11,
      "y": 29,
      "z": -3,
      "name": "Rock_Stone"
    },
    {
      "x": -11,
      "y": 30,
      "z": -3,
      "name": "Rock_Stone"
    },
    {
      "x": -11,
      "y": 31,
      "z": -3,
      "name": "Rock_Stone"
    },
    {
      "x": -11,
      "y": 32,
      "z": -3,
      "name": "Wood_Oak_Trunk",
      "rotation": 2
    },
    {
      "x": -11,
      "y": 33,
      "z": -3,
      "name": "Wood_Oak_Trunk",
      "rotation": 2
    },
    {
      "x": -11,
      "y": 34,
      "z": -3,
      "name": "Wood_Oak_Trunk_Full",
      "rotation": 2
    },
    {
      "x": -11,
      "y": 35,
      "z": -3,
      "name": "Plant_Grass_Sharp"
    },
    {
      "x": -11,
      "y": 44,
      "z": -3,
      "name": "Wood_Oak_Branch_Long",
      "rotation": 7
    },
    {
      "x": -11,
      "y": 49,
      "z": -3,
      "name": "Plant_Leaves_Oak",
      "rotation": 2
    },
    {
      "x": -11,
      "y": 50,
      "z": -3,
      "name": "Plant_Leaves_Oak",
      "rotation": 2
    },
    {
      "x": -11,
      "y": 13,
      "z": -2,
      "name": "Rock_Stone"
    },
    {
      "x": -11,
      "y": 14,
      "z": -2,
      "name": "Rock_Stone"
    },
    {
      "x": -11,
      "y": 15,
      "z": -2,
      "name": "Rock_Stone"
    },
    {
      "x": -11,
      "y": 16,
      "z": -2,
      "name": "Rock_Stone"
    },
    {
      "x": -11,
      "y": 17,
      "z": -2,
      "name": "Rock_Stone"
    },
    {
      "x": -11,
      "y": 18,
      "z": -2,
      "name": "Rock_Stone"
    },
    {
      "x": -11,
      "y": 19,
      "z": -2,
      "name": "Rock_Stone"
    },
    {
      "x": -11,
      "y": 20,
      "z": -2,
      "name": "Rock_Stone"
    },
    {
      "x": -11,
      "y": 21,
      "z": -2,
      "name": "Rock_Stone"
    },
    {
      "x": -11,
      "y": 22,
      "z": -2,
      "name": "Rock_Stone"
    },
    {
      "x": -11,
      "y": 23,
      "z": -2,
      "name": "Rock_Stone"
    },
    {
      "x": -11,
      "y": 24,
      "z": -2,
      "name": "Rock_Stone"
    },
    {
      "x": -11,
      "y": 25,
      "z": -2,
      "name": "Rock_Stone"
    },
    {
      "x": -11,
      "y": 26,
      "z": -2,
      "name": "Rock_Stone"
    },
    {
      "x": -11,
      "y": 27,
      "z": -2,
      "name": "Rock_Stone"
    },
    {
      "x": -11,
      "y": 28,
      "z": -2,
      "name": "Rock_Stone"
    },
    {
      "x": -11,
      "y": 29,
      "z": -2,
      "name": "Rock_Stone"
    },
    {
      "x": -11,
      "y": 30,
      "z": -2,
      "name": "Rock_Stone"
    },
    {
      "x": -11,
      "y": 31,
      "z": -2,
      "name": "Rock_Stone"
    },
    {
      "x": -11,
      "y": 32,
      "z": -2,
      "name": "Wood_Oak_Trunk",
      "rotation": 2
    },
    {
      "x": -11,
      "y": 33,
      "z": -2,
      "name": "Wood_Oak_Trunk",
      "rotation": 2
    },
    {
      "x": -11,
      "y": 34,
      "z": -2,
      "name": "Wood_Oak_Trunk",
      "rotation": 2
    },
    {
      "x": -11,
      "y": 35,
      "z": -2,
      "name": "Wood_Oak_Trunk_Full",
      "rotation": 2
    },
    {
      "x": -11,
      "y": 40,
      "z": -2,
      "name": "Plant_Leaves_Beech",
      "rotation": 3
    },
    {
      "x": -11,
      "y": 41,
      "z": -2,
      "name": "Wood_Oak_Branch_Long",
      "rotation": 7
    },
    {
      "x": -11,
      "y": 49,
      "z": -2,
      "name": "Plant_Leaves_Oak",
      "rotation": 2
    },
    {
      "x": -11,
      "y": 8,
      "z": -1,
      "name": "Rock_Stone"
    },
    {
      "x": -11,
      "y": 9,
      "z": -1,
      "name": "Rock_Stone"
    },
    {
      "x": -11,
      "y": 10,
      "z": -1,
      "name": "Rock_Stone"
    },
    {
      "x": -11,
      "y": 11,
      "z": -1,
      "name": "Rock_Stone"
    },
    {
      "x": -11,
      "y": 12,
      "z": -1,
      "name": "Rock_Stone"
    },
    {
      "x": -11,
      "y": 13,
      "z": -1,
      "name": "Rock_Stone"
    },
    {
      "x": -11,
      "y": 14,
      "z": -1,
      "name": "Rock_Stone"
    },
    {
      "x": -11,
      "y": 15,
      "z": -1,
      "name": "Rock_Stone"
    },
    {
      "x": -11,
      "y": 16,
      "z": -1,
      "name": "Rock_Stone"
    },
    {
      "x": -11,
      "y": 17,
      "z": -1,
      "name": "Rock_Stone"
    },
    {
      "x": -11,
      "y": 18,
      "z": -1,
      "name": "Rock_Stone"
    },
    {
      "x": -11,
      "y": 19,
      "z": -1,
      "name": "Rock_Stone"
    },
    {
      "x": -11,
      "y": 20,
      "z": -1,
      "name": "Rock_Stone"
    },
    {
      "x": -11,
      "y": 21,
      "z": -1,
      "name": "Rock_Stone"
    },
    {
      "x": -11,
      "y": 22,
      "z": -1,
      "name": "Rock_Stone"
    },
    {
      "x": -11,
      "y": 23,
      "z": -1,
      "name": "Rock_Stone"
    },
    {
      "x": -11,
      "y": 24,
      "z": -1,
      "name": "Rock_Stone"
    },
    {
      "x": -11,
      "y": 25,
      "z": -1,
      "name": "Rock_Stone"
    },
    {
      "x": -11,
      "y": 26,
      "z": -1,
      "name": "Rock_Stone"
    },
    {
      "x": -11,
      "y": 27,
      "z": -1,
      "name": "Rock_Stone"
    },
    {
      "x": -11,
      "y": 28,
      "z": -1,
      "name": "Rock_Stone"
    },
    {
      "x": -11,
      "y": 29,
      "z": -1,
      "name": "Rock_Stone"
    },
    {
      "x": -11,
      "y": 30,
      "z": -1,
      "name": "Rock_Stone"
    },
    {
      "x": -11,
      "y": 31,
      "z": -1,
      "name": "Rock_Stone"
    },
    {
      "x": -11,
      "y": 32,
      "z": -1,
      "name": "Soil_Dirt"
    },
    {
      "x": -11,
      "y": 33,
      "z": -1,
      "name": "Soil_Dirt"
    },
    {
      "x": -11,
      "y": 34,
      "z": -1,
      "name": "Soil_Grass"
    },
    {
      "x": -11,
      "y": 40,
      "z": -1,
      "name": "Plant_Leaves_Beech",
      "rotation": 3
    },
    {
      "x": -11,
      "y": 42,
      "z": -1,
      "name": "Plant_Leaves_Beech",
      "rotation": 3
    },
    {
      "x": -11,
      "y": 48,
      "z": -1,
      "name": "Plant_Leaves_Oak",
      "rotation": 2
    },
    {
      "x": -11,
      "y": 49,
      "z": -1,
      "name": "Plant_Leaves_Oak",
      "rotation": 2
    },
    {
      "x": -11,
      "y": 7,
      "z": 0,
      "name": "Rock_Stone"
    },
    {
      "x": -11,
      "y": 8,
      "z": 0,
      "name": "Rock_Stone"
    },
    {
      "x": -11,
      "y": 9,
      "z": 0,
      "name": "Rock_Stone"
    },
    {
      "x": -11,
      "y": 10,
      "z": 0,
      "name": "Rock_Stone"
    },
    {
      "x": -11,
      "y": 11,
      "z": 0,
      "name": "Rock_Stone"
    },
    {
      "x": -11,
      "y": 12,
      "z": 0,
      "name": "Rock_Stone"
    },
    {
      "x": -11,
      "y": 13,
      "z": 0,
      "name": "Rock_Stone"
    },
    {
      "x": -11,
      "y": 14,
      "z": 0,
      "name": "Rock_Stone"
    },
    {
      "x": -11,
      "y": 15,
      "z": 0,
      "name": "Rock_Stone"
    },
    {
      "x": -11,
      "y": 16,
      "z": 0,
      "name": "Rock_Stone"
    },
    {
      "x": -11,
      "y": 17,
      "z": 0,
      "name": "Rock_Stone"
    },
    {
      "x": -11,
      "y": 18,
      "z": 0,
      "name": "Rock_Stone"
    },
    {
      "x": -11,
      "y": 19,
      "z": 0,
      "name": "Rock_Stone"
    },
    {
      "x": -11,
      "y": 20,
      "z": 0,
      "name": "Rock_Stone"
    },
    {
      "x": -11,
      "y": 21,
      "z": 0,
      "name": "Rock_Stone"
    },
    {
      "x": -11,
      "y": 22,
      "z": 0,
      "name": "Rock_Stone"
    },
    {
      "x": -11,
      "y": 23,
      "z": 0,
      "name": "Rock_Stone"
    },
    {
      "x": -11,
      "y": 24,
      "z": 0,
      "name": "Rock_Stone"
    },
    {
      "x": -11,
      "y": 25,
      "z": 0,
      "name": "Rock_Stone"
    },
    {
      "x": -11,
      "y": 26,
      "z": 0,
      "name": "Rock_Stone"
    },
    {
      "x": -11,
      "y": 27,
      "z": 0,
      "name": "Rock_Stone"
    },
    {
      "x": -11,
      "y": 28,
      "z": 0,
      "name": "Rock_Stone"
    },
    {
      "x": -11,
      "y": 29,
      "z": 0,
      "name": "Rock_Stone"
    },
    {
      "x": -11,
      "y": 30,
      "z": 0,
      "name": "Rock_Stone"
    },
    {
      "x": -11,
      "y": 31,
      "z": 0,
      "name": "Rock_Stone"
    },
    {
      "x": -11,
      "y": 32,
      "z": 0,
      "name": "Soil_Dirt"
    },
    {
      "x": -11,
      "y": 33,
      "z": 0,
      "name": "Soil_Dirt"
    },
    {
      "x": -11,
      "y": 34,
      "z": 0,
      "name": "Soil_Grass"
    },
    {
      "x": -11,
      "y": 35,
      "z": 0,
      "name": "Plant_Grass_Sharp"
    },
    {
      "x": -11,
      "y": 39,
      "z": 0,
      "name": "Plant_Leaves_Oak",
      "rotation": 2
    },
    {
      "x": -11,
      "y": 40,
      "z": 0,
      "name": "Plant_Leaves_Beech",
      "rotation": 3
    },
    {
      "x": -11,
      "y": 41,
      "z": 0,
      "name": "Plant_Leaves_Beech",
      "rotation": 3
    },
    {
      "x": -11,
      "y": 42,
      "z": 0,
      "name": "Plant_Leaves_Beech",
      "rotation": 3
    },
    {
      "x": -11,
      "y": 43,
      "z": 0,
      "name": "Plant_Leaves_Beech",
      "rotation": 3
    },
    {
      "x": -11,
      "y": 44,
      "z": 0,
      "name": "Wood_Oak_Branch_Long",
      "rotation": 7
    },
    {
      "x": -11,
      "y": 47,
      "z": 0,
      "name": "Plant_Leaves_Oak",
      "rotation": 2
    },
    {
      "x": -11,
      "y": 48,
      "z": 0,
      "name": "Plant_Leaves_Oak",
      "rotation": 2
    },
    {
      "x": -11,
      "y": 5,
      "z": 1,
      "name": "Rock_Stone"
    },
    {
      "x": -11,
      "y": 6,
      "z": 1,
      "name": "Rock_Stone"
    },
    {
      "x": -11,
      "y": 7,
      "z": 1,
      "name": "Rock_Stone"
    },
    {
      "x": -11,
      "y": 8,
      "z": 1,
      "name": "Rock_Stone"
    },
    {
      "x": -11,
      "y": 9,
      "z": 1,
      "name": "Rock_Stone"
    },
    {
      "x": -11,
      "y": 10,
      "z": 1,
      "name": "Rock_Stone"
    },
    {
      "x": -11,
      "y": 11,
      "z": 1,
      "name": "Rock_Stone"
    },
    {
      "x": -11,
      "y": 12,
      "z": 1,
      "name": "Rock_Stone"
    },
    {
      "x": -11,
      "y": 13,
      "z": 1,
      "name": "Rock_Stone"
    },
    {
      "x": -11,
      "y": 14,
      "z": 1,
      "name": "Rock_Stone"
    },
    {
      "x": -11,
      "y": 15,
      "z": 1,
      "name": "Rock_Stone"
    },
    {
      "x": -11,
      "y": 16,
      "z": 1,
      "name": "Rock_Stone"
    },
    {
      "x": -11,
      "y": 17,
      "z": 1,
      "name": "Rock_Stone"
    },
    {
      "x": -11,
      "y": 18,
      "z": 1,
      "name": "Rock_Stone"
    },
    {
      "x": -11,
      "y": 19,
      "z": 1,
      "name": "Rock_Stone"
    },
    {
      "x": -11,
      "y": 20,
      "z": 1,
      "name": "Rock_Stone"
    },
    {
      "x": -11,
      "y": 21,
      "z": 1,
      "name": "Rock_Stone"
    },
    {
      "x": -11,
      "y": 22,
      "z": 1,
      "name": "Rock_Stone"
    },
    {
      "x": -11,
      "y": 23,
      "z": 1,
      "name": "Rock_Stone"
    },
    {
      "x": -11,
      "y": 24,
      "z": 1,
      "name": "Rock_Stone"
    },
    {
      "x": -11,
      "y": 25,
      "z": 1,
      "name": "Rock_Stone"
    },
    {
      "x": -11,
      "y": 26,
      "z": 1,
      "name": "Rock_Stone"
    },
    {
      "x": -11,
      "y": 27,
      "z": 1,
      "name": "Rock_Stone"
    },
    {
      "x": -11,
      "y": 28,
      "z": 1,
      "name": "Rock_Stone"
    },
    {
      "x": -11,
      "y": 29,
      "z": 1,
      "name": "Rock_Stone"
    },
    {
      "x": -11,
      "y": 30,
      "z": 1,
      "name": "Rock_Stone"
    },
    {
      "x": -11,
      "y": 31,
      "z": 1,
      "name": "Rock_Stone"
    },
    {
      "x": -11,
      "y": 32,
      "z": 1,
      "name": "Soil_Dirt"
    },
    {
      "x": -11,
      "y": 33,
      "z": 1,
      "name": "Soil_Dirt"
    },
    {
      "x": -11,
      "y": 34,
      "z": 1,
      "name": "Soil_Grass"
    },
    {
      "x": -11,
      "y": 35,
      "z": 1,
      "name": "Plant_Grass_Sharp"
    },
    {
      "x": -11,
      "y": 40,
      "z": 1,
      "name": "Plant_Leaves_Beech",
      "rotation": 3
    },
    {
      "x": -11,
      "y": 41,
      "z": 1,
      "name": "Plant_Leaves_Beech",
      "rotation": 3
    },
    {
      "x": -11,
      "y": 43,
      "z": 1,
      "name": "Plant_Leaves_Oak",
      "rotation": 2
    },
    {
      "x": -11,
      "y": 48,
      "z": 1,
      "name": "Plant_Leaves_Oak",
      "rotation": 2
    },
    {
      "x": -11,
      "y": 4,
      "z": 2,
      "name": "Rock_Stone"
    },
    {
      "x": -11,
      "y": 5,
      "z": 2,
      "name": "Rock_Stone"
    },
    {
      "x": -11,
      "y": 6,
      "z": 2,
      "name": "Rock_Stone"
    },
    {
      "x": -11,
      "y": 7,
      "z": 2,
      "name": "Rock_Stone"
    },
    {
      "x": -11,
      "y": 8,
      "z": 2,
      "name": "Rock_Stone"
    },
    {
      "x": -11,
      "y": 9,
      "z": 2,
      "name": "Rock_Stone"
    },
    {
      "x": -11,
      "y": 10,
      "z": 2,
      "name": "Rock_Stone"
    },
    {
      "x": -11,
      "y": 11,
      "z": 2,
      "name": "Rock_Stone"
    },
    {
      "x": -11,
      "y": 12,
      "z": 2,
      "name": "Rock_Stone"
    },
    {
      "x": -11,
      "y": 13,
      "z": 2,
      "name": "Rock_Stone"
    },
    {
      "x": -11,
      "y": 14,
      "z": 2,
      "name": "Rock_Stone"
    },
    {
      "x": -11,
      "y": 15,
      "z": 2,
      "name": "Rock_Stone"
    },
    {
      "x": -11,
      "y": 16,
      "z": 2,
      "name": "Rock_Stone"
    },
    {
      "x": -11,
      "y": 17,
      "z": 2,
      "name": "Rock_Stone"
    },
    {
      "x": -11,
      "y": 18,
      "z": 2,
      "name": "Rock_Stone"
    },
    {
      "x": -11,
      "y": 19,
      "z": 2,
      "name": "Rock_Stone"
    },
    {
      "x": -11,
      "y": 20,
      "z": 2,
      "name": "Rock_Stone"
    },
    {
      "x": -11,
      "y": 21,
      "z": 2,
      "name": "Rock_Stone"
    },
    {
      "x": -11,
      "y": 22,
      "z": 2,
      "name": "Rock_Stone"
    },
    {
      "x": -11,
      "y": 23,
      "z": 2,
      "name": "Rock_Stone"
    },
    {
      "x": -11,
      "y": 24,
      "z": 2,
      "name": "Rock_Stone"
    },
    {
      "x": -11,
      "y": 25,
      "z": 2,
      "name": "Rock_Stone"
    },
    {
      "x": -11,
      "y": 26,
      "z": 2,
      "name": "Rock_Stone"
    },
    {
      "x": -11,
      "y": 27,
      "z": 2,
      "name": "Rock_Stone"
    },
    {
      "x": -11,
      "y": 28,
      "z": 2,
      "name": "Rock_Stone"
    },
    {
      "x": -11,
      "y": 29,
      "z": 2,
      "name": "Rock_Stone"
    },
    {
      "x": -11,
      "y": 30,
      "z": 2,
      "name": "Rock_Stone"
    },
    {
      "x": -11,
      "y": 31,
      "z": 2,
      "name": "Rock_Stone"
    },
    {
      "x": -11,
      "y": 32,
      "z": 2,
      "name": "Soil_Dirt"
    },
    {
      "x": -11,
      "y": 33,
      "z": 2,
      "name": "Soil_Dirt"
    },
    {
      "x": -11,
      "y": 34,
      "z": 2,
      "name": "Soil_Grass"
    },
    {
      "x": -11,
      "y": 35,
      "z": 2,
      "name": "Plant_Grass_Sharp"
    },
    {
      "x": -11,
      "y": 40,
      "z": 2,
      "name": "Plant_Leaves_Beech",
      "rotation": 3
    },
    {
      "x": -11,
      "y": 41,
      "z": 2,
      "name": "Plant_Leaves_Beech",
      "rotation": 3
    },
    {
      "x": -11,
      "y": 43,
      "z": 2,
      "name": "Plant_Leaves_Beech",
      "rotation": 3
    },
    {
      "x": -11,
      "y": 44,
      "z": 2,
      "name": "Plant_Leaves_Oak",
      "rotation": 2
    },
    {
      "x": -11,
      "y": 46,
      "z": 2,
      "name": "Plant_Leaves_Oak",
      "rotation": 2
    },
    {
      "x": -11,
      "y": 3,
      "z": 3,
      "name": "Rock_Stone"
    },
    {
      "x": -11,
      "y": 4,
      "z": 3,
      "name": "Rock_Stone"
    },
    {
      "x": -11,
      "y": 5,
      "z": 3,
      "name": "Rock_Stone"
    },
    {
      "x": -11,
      "y": 6,
      "z": 3,
      "name": "Rock_Stone"
    },
    {
      "x": -11,
      "y": 7,
      "z": 3,
      "name": "Rock_Stone"
    },
    {
      "x": -11,
      "y": 8,
      "z": 3,
      "name": "Rock_Stone"
    },
    {
      "x": -11,
      "y": 9,
      "z": 3,
      "name": "Rock_Stone"
    },
    {
      "x": -11,
      "y": 10,
      "z": 3,
      "name": "Rock_Stone"
    },
    {
      "x": -11,
      "y": 11,
      "z": 3,
      "name": "Rock_Stone"
    },
    {
      "x": -11,
      "y": 12,
      "z": 3,
      "name": "Rock_Stone"
    },
    {
      "x": -11,
      "y": 13,
      "z": 3,
      "name": "Rock_Stone"
    },
    {
      "x": -11,
      "y": 14,
      "z": 3,
      "name": "Rock_Stone"
    },
    {
      "x": -11,
      "y": 15,
      "z": 3,
      "name": "Rock_Stone"
    },
    {
      "x": -11,
      "y": 16,
      "z": 3,
      "name": "Rock_Stone"
    },
    {
      "x": -11,
      "y": 17,
      "z": 3,
      "name": "Rock_Stone"
    },
    {
      "x": -11,
      "y": 18,
      "z": 3,
      "name": "Rock_Stone"
    },
    {
      "x": -11,
      "y": 19,
      "z": 3,
      "name": "Rock_Stone"
    },
    {
      "x": -11,
      "y": 20,
      "z": 3,
      "name": "Rock_Stone"
    },
    {
      "x": -11,
      "y": 21,
      "z": 3,
      "name": "Rock_Stone"
    },
    {
      "x": -11,
      "y": 22,
      "z": 3,
      "name": "Rock_Stone"
    },
    {
      "x": -11,
      "y": 23,
      "z": 3,
      "name": "Rock_Stone"
    },
    {
      "x": -11,
      "y": 24,
      "z": 3,
      "name": "Rock_Stone"
    },
    {
      "x": -11,
      "y": 25,
      "z": 3,
      "name": "Rock_Stone"
    },
    {
      "x": -11,
      "y": 26,
      "z": 3,
      "name": "Rock_Stone"
    },
    {
      "x": -11,
      "y": 27,
      "z": 3,
      "name": "Rock_Stone"
    },
    {
      "x": -11,
      "y": 28,
      "z": 3,
      "name": "Rock_Stone"
    },
    {
      "x": -11,
      "y": 29,
      "z": 3,
      "name": "Rock_Stone"
    },
    {
      "x": -11,
      "y": 30,
      "z": 3,
      "name": "Rock_Stone"
    },
    {
      "x": -11,
      "y": 31,
      "z": 3,
      "name": "Rock_Stone"
    },
    {
      "x": -11,
      "y": 32,
      "z": 3,
      "name": "Soil_Dirt"
    },
    {
      "x": -11,
      "y": 33,
      "z": 3,
      "name": "Soil_Dirt"
    },
    {
      "x": -11,
      "y": 34,
      "z": 3,
      "name": "Soil_Grass"
    },
    {
      "x": -11,
      "y": 40,
      "z": 3,
      "name": "Plant_Leaves_Beech",
      "rotation": 3
    },
    {
      "x": -11,
      "y": 43,
      "z": 3,
      "name": "Plant_Leaves_Oak",
      "rotation": 2
    },
    {
      "x": -11,
      "y": 44,
      "z": 3,
      "name": "Plant_Leaves_Oak",
      "rotation": 2
    },
