{
  "version": 8,
  "blockIdVersion": 8,
  "anchorX": 4,
  "anchorY": 4,
  "anchorZ": -4,
  "blocks": [
    {
      "x": -2,
      "y": 3,
      "z": 2,
      "name": "Rock_Basalt_Brick"
    },
    {
      "x": -2,
      "y": 4,
      "z": 2,
      "name": "Rock_Basalt_Brick"
    },
    {
      "x": -2,
      "y": 5,
      "z": 2,
      "name": "Rock_Basalt_Brick"
    },
    {
      "x": -2,
      "y": 6,
      "z": 2,
      "name": "Rock_Basalt_Brick"
    },
    {
      "x": -2,
      "y": 3,
      "z": 3,
      "name": "Rock_Basalt_Brick"
    },
    {
      "x": -2,
      "y": 4,
      "z": 3,
      "name": "Plant_Seaweed_Grass_Bulbs"
    },
    {
      "x": -2,
      "y": 5,
      "z": 3,
      "name": "Plant_Seaweed_Grass_Bulbs",
      "filler": 1024
    },
    {
      "x": -2,
      "y": 6,
      "z": 3,
      "name": "Rock_Basalt_Brick"
    },
    {
      "x": -2,
      "y": 3,
      "z": 4,
      "name": "Rock_Basalt_Brick"
    },
    {
      "x": -2,
      "y": 4,
      "z": 4,
      "name": "Plant_Reeds_Poison"
    },
    {
      "x": -2,
      "y": 6,
      "z": 4,
      "name": "Rock_Basalt_Brick"
    },
    {
      "x": -2,
      "y": 3,
      "z": 5,
      "name": "Rock_Basalt_Brick"
    },
    {
      "x": -2,
      "y": 4,
      "z": 5,
      "name": "Rock_Basalt_Brick"
    },
    {
      "x": -2,
      "y": 5,
      "z": 5,
      "name": "Rock_Basalt_Brick"
    },
    {
      "x": -2,
      "y": 6,
      "z": 5,
      "name": "Rock_Basalt_Brick"
    },
    {
      "x": -1,
      "y": 3,
      "z": 2,
      "name": "Rock_Basalt_Brick"
    },
    {
      "x": -1,
      "y": 4,
      "z": 2,
      "name": "Rock_Basalt_Brick"
    },
    {
      "x": -1,
      "y": 5,
      "z": 2,
      "name": "Rock_Basalt_Brick"
    },
    {
      "x": -1,
      "y": 6,
      "z": 2,
      "name": "Rock_Basalt_Brick"
    },
    {
      "x": -1,
      "y": 3,
      "z": 3,
      "name": "Rock_Basalt_Brick"
    },
    {
      "x": -1,
      "y": 4,
      "z": 3,
      "name": "Plant_Moss_Rug_Green"
    },
    {
      "x": -1,
      "y": 6,
      "z": 3,
      "name": "Rock_Basalt_Brick"
    },
    {
      "x": -1,
      "y": 3,
      "z": 4,
      "name": "Rock_Basalt_Brick"
    },
    {
      "x": -1,
      "y": 4,
      "z": 4,
      "name": "Plant_Moss_Rug_Green"
    },
    {
      "x": -1,
      "y": 6,
      "z": 4,
      "name": "Rock_Basalt_Brick"
    },
    {
      "x": -1,
      "y": 3,
      "z": 5,
      "name": "Rock_Basalt_Brick"
    },
    {
      "x": -1,
      "y": 4,
      "z": 5,
      "name": "Rock_Basalt_Brick"
    },
    {
      "x": -1,
      "y": 5,
      "z": 5,
      "name": "Rock_Basalt_Brick"
    },
    {
      "x": -1,
      "y": 6,
      "z": 5,
      "name": "Rock_Basalt_Brick"
    },
    {
      "x": -1,
      "y": 3,
      "z": 6,
      "name": "Rock_Basalt_Brick"
    },
    {
      "x": -1,
      "y": 4,
      "z": 6,
      "name": "Rock_Basalt_Brick"
    },
    {
      "x": -1,
      "y": 5,
      "z": 6,
      "name": "Rock_Basalt_Brick"
    },
    {
      "x": -1,
      "y": 6,
      "z": 6,
      "name": "Rock_Basalt_Brick"
    },
    {
      "x": -1,
      "y": 3,
      "z": 7,
      "name": "Rock_Basalt_Brick"
    },
    {
      "x": -1,
      "y": 4,
      "z": 7,
      "name": "Rock_Basalt_Brick"
    },
    {
      "x": -1,
      "y": 5,
      "z": 7,
      "name": "Rock_Basalt_Brick"
    },
    {
      "x": -1,
      "y": 6,
      "z": 7,
      "name": "Rock_Basalt_Brick"
    },
    {
      "x": 0,
      "y": 3,
      "z": 2,
      "name": "Rock_Basalt_Brick"
    },
    {
      "x": 0,
      "y": 4,
      "z": 2,
      "name": "Rock_Basalt_Brick"
    },
    {
      "x": 0,
      "y": 5,
      "z": 2,
      "name": "Rock_Basalt_Brick"
    },
    {
      "x": 0,
      "y": 6,
      "z": 2,
      "name": "Rock_Basalt_Brick"
    },
    {
      "x": 0,
      "y": 3,
      "z": 3,
      "name": "Rock_Basalt_Brick"
    },
    {
      "x": 0,
      "y": 4,
      "z": 3,
      "name": "Plant_Moss_Rug_Green"
    },
    {
      "x": 0,
      "y": 6,
      "z": 3,
      "name": "Rock_Basalt_Brick"
    },
    {
      "x": 0,
      "y": 3,
      "z": 4,
      "name": "Rock_Basalt_Brick"
    },
    {
      "x": 0,
      "y": 4,
      "z": 4,
      "name": "Plant_Moss_Green"
    },
    {
      "x": 0,
      "y": 6,
      "z": 4,
      "name": "Rock_Basalt_Brick"
    },
    {
      "x": 0,
      "y": 3,
      "z": 5,
      "name": "Rock_Basalt_Brick"
    },
    {
      "x": 0,
      "y": 4,
      "z": 5,
      "name": "Furniture_Ancient_Coffin",
      "filler": 992,
      "rotation": 1
    },
    {
      "x": 0,
      "y": 6,
      "z": 5,
      "name": "Rock_Basalt_Brick"
    },
    {
      "x": 0,
      "y": 3,
      "z": 6,
      "name": "Rock_Basalt_Brick"
    },
    {
      "x": 0,
      "y": 4,
      "z": 6,
      "name": "Furniture_Ancient_Coffin",
      "rotation": 1
    },
    {
      "x": 0,
      "y": 6,
      "z": 6,
      "name": "Rock_Basalt_Brick"
    },
    {
      "x": 0,
      "y": 3,
      "z": 7,
      "name": "Rock_Basalt_Brick"
    },
    {
      "x": 0,
      "y": 4,
      "z": 7,
      "name": "Rock_Basalt_Brick"
    },
    {
      "x": 0,
      "y": 5,
      "z": 7,
      "name": "Rock_Basalt_Brick"
    },
    {
      "x": 0,
      "y": 6,
      "z": 7,
      "name": "Rock_Basalt_Brick"
    },
    {
      "x": 1,
      "y": 3,
      "z": 2,
      "name": "Rock_Basalt_Brick"
    },
    {
      "x": 1,
      "y": 4,
      "z": 2,
      "name": "Rock_Basalt_Brick"
    },
    {
      "x": 1,
      "y": 5,
      "z": 2,
      "name": "Rock_Basalt_Brick"
    },
    {
      "x": 1,
      "y": 6,
      "z": 2,
      "name": "Rock_Basalt_Brick"
    },
    {
      "x": 1,
      "y": 3,
      "z": 3,
      "name": "Rock_Basalt_Brick"
    },
    {
      "x": 1,
      "y": 4,
      "z": 3,
      "name": "Plant_Moss_Rug_Green"
    },
    {
      "x": 1,
      "y": 6,
      "z": 3,
      "name": "Rock_Basalt_Brick"
    },
    {
      "x": 1,
      "y": 3,
      "z": 4,
      "name": "Rock_Basalt_Brick"
    },
    {
      "x": 1,
      "y": 4,
      "z": 4,
      "name": "Plant_Seaweed_Grass_Bulbs"
    },
    {
      "x": 1,
      "y": 5,
      "z": 4,
      "name": "Plant_Seaweed_Grass_Bulbs",
      "filler": 1024
    },
    {
      "x": 1,
      "y": 6,
      "z": 4,
      "name": "Rock_Basalt_Brick"
    },
    {
      "x": 1,
      "y": 3,
      "z": 5,
      "name": "Rock_Basalt_Brick"
    },
    {
      "x": 1,
      "y": 4,
      "z": 5,
      "name": "Furniture_Ancient_Coffin",
      "filler": 992,
      "rotation": 1
    },
    {
      "x": 1,
      "y": 6,
      "z": 5,
      "name": "Rock_Basalt_Brick"
    },
    {
      "x": 1,
      "y": 3,
      "z": 6,
      "name": "Rock_Basalt_Brick"
    },
    {
      "x": 1,
      "y": 4,
      "z": 6,
      "name": "Furniture_Ancient_Coffin",
      "rotation": 1
    },
    {
      "x": 1,
      "y": 6,
      "z": 6,
      "name": "Rock_Basalt_Brick"
    },
    {
      "x": 1,
      "y": 3,
      "z": 7,
      "name": "Rock_Basalt_Brick"
    },
    {
      "x": 1,
      "y": 4,
      "z": 7,
      "name": "Rock_Basalt_Brick"
    },
    {
      "x": 1,
      "y": 5,
      "z": 7,
      "name": "Rock_Basalt_Brick"
    },
    {
      "x": 1,
      "y": 6,
      "z": 7,
      "name": "Rock_Basalt_Brick"
    },
    {
      "x": 2,
      "y": 3,
      "z": 2,
      "name": "Rock_Basalt_Brick"
    },
    {
      "x": 2,
      "y": 4,
      "z": 2,
      "name": "Rock_Basalt_Brick"
    },
    {
      "x": 2,
      "y": 5,
      "z": 2,
      "name": "Rock_Basalt_Brick"
    },
    {
      "x": 2,
      "y": 6,
      "z": 2,
      "name": "Rock_Basalt_Brick"
    },
    {
      "x": 2,
      "y": 3,
      "z": 3,
      "name": "Rock_Basalt_Brick"
    },
    {
      "x": 2,
      "y": 6,
      "z": 3,
      "name": "Rock_Basalt_Brick"
    },
    {
      "x": 2,
      "y": 3,
      "z": 4,
      "name": "Rock_Basalt_Brick"
    },
    {
      "x": 2,
      "y": 4,
      "z": 4,
      "name": "Plant_Reeds_Poison"
    },
    {
      "x": 2,
      "y": 6,
      "z": 4,
      "name": "Rock_Basalt_Brick"
    },
    {
      "x": 2,
      "y": 3,
      "z": 5,
      "name": "Rock_Basalt_Brick"
    },
    {
      "x": 2,
      "y": 4,
      "z": 5,
      "name": "Furniture_Ancient_Barrel"
    },
    {
      "x": 2,
      "y": 6,
      "z": 5,
      "name": "Rock_Basalt_Brick"
    },
    {
      "x": 2,
      "y": 3,
      "z": 6,
      "name": "Rock_Basalt_Brick"
    },
    {
      "x": 2,
      "y": 4,
      "z": 6,
      "name": "Furniture_Ancient_Crate",
      "components": {
        "Components": {
          "container": {
            "Custom": false,
            "AllowViewing": true,
            "ItemContainer": {
              "Capacity": 20,
              "Items": {}
            }
          }
        }
      },
      "rotation": 2
    },
    {
      "x": 2,
      "y": 5,
      "z": 6,
      "name": "Furniture_Ancient_Barrel"
    },
    {
      "x": 2,
      "y": 6,
      "z": 6,
      "name": "Rock_Basalt_Brick"
    },
    {
      "x": 2,
      "y": 3,
      "z": 7,
      "name": "Rock_Basalt_Brick"
    },
    {
      "x": 2,
      "y": 4,
      "z": 7,
      "name": "Rock_Basalt_Brick"
    },
    {
      "x": 2,
      "y": 5,
      "z": 7,
      "name": "Rock_Basalt_Brick"
    },
    {
      "x": 2,
      "y": 6,
      "z": 7,
      "name": "Rock_Basalt_Brick"
    },
    {
      "x": 3,
      "y": 3,
      "z": -3,
      "name": "Rock_Basalt_Brick"
    },
    {
      "x": 3,
      "y": 4,
      "z": -3,
      "name": "Rock_Basalt_Brick"
    },
    {
      "x": 3,
      "y": 5,
      "z": -3,
      "name": "Rock_Basalt_Brick"
    },
    {
      "x": 3,
      "y": 6,
      "z": -3,
      "name": "Rock_Basalt_Brick"
    },
    {
      "x": 3,
      "y": 3,
      "z": -2,
      "name": "Rock_Basalt_Brick"
    },
    {
      "x": 3,
      "y": 4,
      "z": -2,
      "name": "Rock_Basalt_Brick"
    },
    {
      "x": 3,
      "y": 5,
      "z": -2,
      "name": "Rock_Basalt_Brick"
    },
    {
      "x": 3,
      "y": 6,
      "z": -2,
      "name": "Rock_Basalt_Brick"
    },
    {
      "x": 3,
      "y": 3,
      "z": -1,
      "name": "Rock_Basalt_Brick"
    },
    {
      "x": 3,
      "y": 4,
      "z": -1,
      "name": "Rock_Basalt_Brick"
    },
    {
      "x": 3,
      "y": 5,
      "z": -1,
      "name": "Rock_Basalt_Brick"
    },
    {
      "x": 3,
      "y": 6,
      "z": -1,
      "name": "Rock_Basalt_Brick"
    },
    {
      "x": 3,
      "y": 3,
      "z": 0,
      "name": "Rock_Basalt_Brick"
    },
    {
      "x": 3,
      "y": 4,
      "z": 0,
      "name": "Rock_Basalt_Brick"
    },
    {
      "x": 3,
      "y": 5,
      "z": 0,
      "name": "Rock_Basalt_Brick"
    },
    {
      "x": 3,
      "y": 6,
      "z": 0,
      "name": "Rock_Basalt_Brick"
    },
    {
      "x": 3,
      "y": 3,
      "z": 1,
      "name": "Rock_Basalt_Brick"
    },
    {
      "x": 3,
      "y": 4,
      "z": 1,
      "name": "Rock_Basalt_Brick"
    },
    {
      "x": 3,
      "y": 5,
      "z": 1,
      "name": "Rock_Basalt_Brick"
    },
    {
      "x": 3,
      "y": 6,
      "z": 1,
      "name": "Rock_Basalt_Brick"
    },
    {
      "x": 3,
      "y": 3,
      "z": 2,
      "name": "Rock_Basalt_Brick"
    },
    {
      "x": 3,
      "y": 4,
      "z": 2,
      "name": "Rock_Basalt_Brick"
    },
    {
      "x": 3,
      "y": 5,
      "z": 2,
      "name": "Rock_Basalt_Brick"
    },
    {
      "x": 3,
      "y": 6,
      "z": 2,
      "name": "Rock_Basalt_Brick"
    },
    {
      "x": 3,
      "y": 3,
      "z": 3,
      "name": "Rock_Basalt_Brick"
    },
    {
      "x": 3,
      "y": 6,
      "z": 3,
      "name": "Rock_Basalt_Brick"
    },
    {
      "x": 3,
      "y": 3,
      "z": 4,
      "name": "Rock_Basalt_Brick"
    },
    {
      "x": 3,
      "y": 6,
      "z": 4,
      "name": "Rock_Basalt_Brick"
    },
    {
      "x": 3,
      "y": 3,
      "z": 5,
      "name": "Rock_Basalt_Brick"
    },
    {
      "x": 3,
      "y": 4,
      "z": 5,
      "name": "Furniture_Ancient_Coffin",
      "filler": 992,
      "rotation": 1
    },
    {
      "x": 3,
      "y": 6,
      "z": 5,
      "name": "Rock_Basalt_Brick"
    },
    {
      "x": 3,
      "y": 3,
      "z": 6,
      "name": "Rock_Basalt_Brick"
    },
    {
      "x": 3,
      "y": 4,
      "z": 6,
      "name": "Furniture_Ancient_Coffin",
      "rotation": 1
    },
    {
      "x": 3,
      "y": 6,
      "z": 6,
      "name": "Rock_Basalt_Brick"
    },
    {
      "x": 3,
      "y": 3,
      "z": 7,
      "name": "Rock_Basalt_Brick"
    },
    {
      "x": 3,
      "y": 4,
      "z": 7,
      "name": "Rock_Basalt_Brick"
    },
    {
      "x": 3,
      "y": 5,
      "z": 7,
      "name": "Rock_Basalt_Brick"
    },
    {
      "x": 3,
      "y": 6,
      "z": 7,
      "name": "Rock_Basalt_Brick"
    },
    {
      "x": 4,
      "y": 3,
      "z": -3,
      "name": "Rock_Basalt_Brick"
    },
    {
      "x": 4,
      "y": 6,
      "z": -3,
      "name": "Rock_Basalt_Brick"
    },
    {
      "x": 4,
      "y": 3,
      "z": -2,
      "name": "Rock_Basalt_Brick"
    },
    {
      "x": 4,
      "y": 4,
      "z": -2,
      "name": "Plant_Moss_Rug_Green"
    },
    {
      "x": 4,
      "y": 6,
      "z": -2,
      "name": "Rock_Basalt_Brick"
    },
    {
      "x": 4,
      "y": 3,
      "z": -1,
      "name": "Rock_Basalt_Brick"
    },
    {
      "x": 4,
      "y": 4,
      "z": -1,
      "name": "Plant_Moss_Rug_Green"
    },
    {
      "x": 4,
      "y": 6,
      "z": -1,
      "name": "Rock_Basalt_Brick"
    },
    {
      "x": 4,
      "y": 3,
      "z": 0,
      "name": "Rock_Basalt_Brick"
    },
    {
      "x": 4,
      "y": 4,
      "z": 0,
      "name": "Plant_Seaweed_Grass_Bulbs"
    },
    {
      "x": 4,
      "y": 5,
      "z": 0,
      "name": "Plant_Seaweed_Grass_Bulbs",
      "filler": 1024
    },
    {
      "x": 4,
      "y": 6,
      "z": 0,
      "name": "Rock_Basalt_Brick"
    },
    {
      "x": 4,
      "y": 3,
      "z": 1,
      "name": "Rock_Basalt_Brick"
    },
    {
      "x": 4,
      "y": 4,
      "z": 1,
      "name": "Plant_Reeds_Poison"
    },
    {
      "x": 4,
      "y": 6,
      "z": 1,
      "name": "Rock_Basalt_Brick"
    },
    {
      "x": 4,
      "y": 3,
      "z": 2,
      "name": "Rock_Basalt_Brick"
    },
    {
      "x": 4,
      "y": 4,
      "z": 2,
      "name": "Plant_Reeds_Poison"
    },
    {
      "x": 4,
      "y": 6,
      "z": 2,
      "name": "Rock_Basalt_Brick"
    },
    {
      "x": 4,
      "y": 3,
      "z": 3,
      "name": "Rock_Basalt_Brick"
    },
    {
      "x": 4,
      "y": 6,
      "z": 3,
      "name": "Rock_Basalt_Brick"
    },
    {
      "x": 4,
      "y": 3,
      "z": 4,
      "name": "Rock_Basalt_Brick"
    },
    {
      "x": 4,
      "y": 4,
      "z": 4,
      "name": "Furniture_Ancient_Barrel"
    },
    {
      "x": 4,
      "y": 6,
      "z": 4,
      "name": "Rock_Basalt_Brick"
    },
    {
      "x": 4,
      "y": 3,
      "z": 5,
      "name": "Rock_Basalt_Brick"
    },
    {
      "x": 4,
      "y": 4,
      "z": 5,
      "name": "Furniture_Ancient_Coffin",
      "filler": 992,
      "rotation": 1
    },
    {
      "x": 4,
      "y": 6,
      "z": 5,
      "name": "Rock_Basalt_Brick"
    },
    {
      "x": 4,
      "y": 3,
      "z": 6,
      "name": "Rock_Basalt_Brick"
    },
    {
      "x": 4,
      "y": 4,
      "z": 6,
      "name": "Furniture_Ancient_Coffin",
      "rotation": 1
    },
    {
      "x": 4,
      "y": 6,
      "z": 6,
      "name": "Rock_Basalt_Brick"
    },
    {
      "x": 4,
      "y": 3,
      "z": 7,
      "name": "Rock_Basalt_Brick"
    },
    {
      "x": 4,
      "y": 4,
      "z": 7,
      "name": "Rock_Basalt_Brick"
    },
    {
      "x": 4,
      "y": 5,
      "z": 7,
      "name": "Rock_Basalt_Brick"
    },
    {
      "x": 4,
      "y": 6,
      "z": 7,
      "name": "Rock_Basalt_Brick"
    },
    {
      "x": 5,
      "y": 3,
      "z": -3,
      "name": "Rock_Basalt_Brick"
    },
    {
      "x": 5,
      "y": 6,
      "z": -3,
      "name": "Rock_Basalt_Brick"
    },
    {
      "x": 5,
      "y": 3,
      "z": -2,
      "name": "Rock_Basalt_Brick"
    },
    {
      "x": 5,
      "y": 4,
      "z": -2,
      "name": "Plant_Moss_Rug_Green"
    },
    {
      "x": 5,
      "y": 6,
      "z": -2,
      "name": "Rock_Basalt_Brick"
    },
    {
      "x": 5,
      "y": 3,
      "z": -1,
      "name": "Rock_Basalt_Brick"
    },
    {
      "x": 5,
      "y": 4,
      "z": -1,
      "name": "Plant_Reeds_Poison"
    },
    {
      "x": 5,
      "y": 6,
      "z": -1,
      "name": "Rock_Basalt_Brick"
    },
    {
      "x": 5,
      "y": 3,
      "z": 0,
      "name": "Rock_Basalt_Brick"
    },
    {
      "x": 5,
      "y": 4,
      "z": 0,
      "name": "Plant_Reeds_Poison"
    },
    {
      "x": 5,
      "y": 6,
      "z": 0,
      "name": "Rock_Basalt_Brick"
    },
    {
      "x": 5,
      "y": 3,
      "z": 1,
      "name": "Rock_Basalt_Brick"
    },
    {
      "x": 5,
      "y": 6,
      "z": 1,
      "name": "Rock_Basalt_Brick"
    },
    {
      "x": 5,
      "y": 3,
      "z": 2,
      "name": "Rock_Basalt_Brick"
    },
    {
      "x": 5,
      "y": 6,
      "z": 2,
      "name": "Rock_Basalt_Brick"
    },
    {
      "x": 5,
      "y": 3,
      "z": 3,
      "name": "Rock_Basalt_Brick"
    },
    {
      "x": 5,
      "y": 6,
      "z": 3,
      "name": "Rock_Basalt_Brick"
    },
    {
      "x": 5,
      "y": 3,
      "z": 4,
      "name": "Rock_Basalt_Brick"
    },
    {
      "x": 5,
      "y": 4,
      "z": 4,
      "name": "Plant_Moss_Rug_Green"
    },
    {
      "x": 5,
      "y": 6,
      "z": 4,
      "name": "Rock_Basalt_Brick"
    },
    {
      "x": 5,
      "y": 3,
      "z": 5,
      "name": "Rock_Basalt_Brick"
    },
    {
      "x": 5,
      "y": 4,
      "z": 5,
      "name": "Plant_Seaweed_Grass_Bulbs"
    },
    {
      "x": 5,
      "y": 5,
      "z": 5,
      "name": "Plant_Seaweed_Grass_Bulbs",
      "filler": 1024
    },
    {
      "x": 5,
      "y": 6,
      "z": 5,
      "name": "Rock_Basalt_Brick"
    },
    {
      "x": 5,
      "y": 3,
      "z": 6,
      "name": "Rock_Basalt_Brick"
    },
    {
      "x": 5,
      "y": 4,
      "z": 6,
      "name": "Plant_Seaweed_Grass_Bulbs"
    },
    {
      "x": 5,
      "y": 5,
      "z": 6,
      "name": "Plant_Seaweed_Grass_Bulbs",
      "filler": 1024
    },
    {
      "x": 5,
      "y": 6,
      "z": 6,
      "name": "Rock_Basalt_Brick"
    },
    {
      "x": 5,
      "y": 3,
      "z": 7,
      "name": "Rock_Basalt_Brick"
    },
    {
      "x": 5,
      "y": 4,
      "z": 7,
      "name": "Rock_Basalt_Brick"
    },
    {
      "x": 5,
      "y": 5,
      "z": 7,
      "name": "Rock_Basalt_Brick"
    },
    {
      "x": 5,
      "y": 6,
      "z": 7,
      "name": "Rock_Basalt_Brick"
    },
    {
      "x": 6,
      "y": 3,
      "z": -3,
      "name": "Rock_Basalt_Brick"
    },
    {
      "x": 6,
      "y": 4,
      "z": -3,
      "name": "Rock_Basalt_Brick"
    },
    {
      "x": 6,
      "y": 5,
      "z": -3,
      "name": "Rock_Basalt_Brick"
    },
    {
      "x": 6,
      "y": 6,
      "z": -3,
      "name": "Rock_Basalt_Brick"
    },
    {
      "x": 6,
      "y": 3,
      "z": -2,
      "name": "Rock_Basalt_Brick"
    },
    {
      "x": 6,
      "y": 4,
      "z": -2,
      "name": "Rock_Basalt_Brick"
    },
    {
      "x": 6,
      "y": 5,
      "z": -2,
      "name": "Rock_Basalt_Brick"
    },
    {
      "x": 6,
      "y": 6,
      "z": -2,
      "name": "Rock_Basalt_Brick"
    },
    {
      "x": 6,
      "y": 3,
      "z": -1,
      "name": "Rock_Basalt_Brick"
    },
    {
      "x": 6,
      "y": 4,
      "z": -1,
      "name": "Rock_Basalt_Brick"
    },
    {
      "x": 6,
      "y": 5,
      "z": -1,
      "name": "Rock_Basalt_Brick"
    },
    {
      "x": 6,
      "y": 6,
      "z": -1,
      "name": "Rock_Basalt_Brick"
    },
    {
      "x": 6,
      "y": 3,
      "z": 0,
      "name": "Rock_Basalt_Brick"
    },
    {
      "x": 6,
      "y": 4,
      "z": 0,
      "name": "Rock_Basalt_Brick"
    },
    {
      "x": 6,
      "y": 5,
      "z": 0,
      "name": "Rock_Basalt_Brick"
    },
    {
      "x": 6,
      "y": 6,
      "z": 0,
      "name": "Rock_Basalt_Brick"
    },
    {
      "x": 6,
      "y": 3,
      "z": 1,
      "name": "Rock_Basalt_Brick"
    },
    {
      "x": 6,
      "y": 4,
      "z": 1,
      "name": "Rock_Basalt_Brick"
    },
    {
      "x": 6,
      "y": 5,
      "z": 1,
      "name": "Rock_Basalt_Brick"
    },
    {
      "x": 6,
      "y": 6,
      "z": 1,
      "name": "Rock_Basalt_Brick"
    },
    {
      "x": 6,
      "y": 3,
      "z": 2,
      "name": "Rock_Basalt_Brick"
    },
    {
      "x": 6,
      "y": 4,
      "z": 2,
      "name": "Rock_Basalt_Brick"
    },
    {
      "x": 6,
      "y": 5,
      "z": 2,
      "name": "Rock_Basalt_Brick"
    },
    {
      "x": 6,
      "y": 6,
      "z": 2,
      "name": "Rock_Basalt_Brick"
    },
    {
      "x": 6,
      "y": 3,
      "z": 3,
      "name": "Rock_Basalt_Brick"
    },
    {
      "x": 6,
      "y": 4,
      "z": 3,
      "name": "Rock_Basalt_Brick"
    },
    {
      "x": 6,
      "y": 5,
      "z": 3,
      "name": "Rock_Basalt_Brick"
    },
    {
      "x": 6,
      "y": 6,
      "z": 3,
      "name": "Rock_Basalt_Brick"
    },
    {
      "x": 6,
      "y": 3,
      "z": 4,
      "name": "Rock_Basalt_Brick"
    },
    {
      "x": 6,
      "y": 4,
      "z": 4,
      "name": "Rock_Basalt_Brick"
    },
    {
      "x": 6,
      "y": 5,
      "z": 4,
      "name": "Rock_Basalt_Brick"
    },
    {
      "x": 6,
      "y": 6,
      "z": 4,
      "name": "Rock_Basalt_Brick"
    },
    {
      "x": 6,
      "y": 3,
      "z": 5,
      "name": "Rock_Basalt_Brick"
    },
    {
      "x": 6,
      "y": 4,
      "z": 5,
      "name": "Rock_Basalt_Brick"
    },
    {
      "x": 6,
      "y": 5,
      "z": 5,
      "name": "Rock_Basalt_Brick"
    },
    {
      "x": 6,
      "y": 6,
      "z": 5,
      "name": "Rock_Basalt_Brick"
    },
    {
      "x": 6,
      "y": 3,
      "z": 6,
      "name": "Rock_Basalt_Brick"
    },
    {
      "x": 6,
      "y": 4,
      "z": 6,
      "name": "Rock_Basalt_Brick"
    },
    {
      "x": 6,
      "y": 5,
      "z": 6,
      "name": "Rock_Basalt_Brick"
    },
    {
      "x": 6,
      "y": 6,
      "z": 6,
      "name": "Rock_Basalt_Brick"
    },
    {
      "x": 6,
      "y": 3,
      "z": 7,
      "name": "Rock_Basalt_Brick"
    },
    {
      "x": 6,
      "y": 4,
      "z": 7,
      "name": "Rock_Basalt_Brick"
    },
    {
      "x": 6,
      "y": 5,
      "z": 7,
      "name": "Rock_Basalt_Brick"
    },
    {
      "x": 6,
      "y": 6,
      "z": 7,
      "name": "Rock_Basalt_Brick"
    }
  ],
  "fluids": [
    {
      "x": -2,
      "y": 4,
      "z": 3,
      "name": "Water",
      "level": 8
    },
    {
      "x": -2,
      "y": 5,
      "z": 3,
      "name": "Water",
      "level": 8
    },
    {
      "x": -2,
      "y": 4,
      "z": 4,
      "name": "Water",
      "level": 8
    },
    {
      "x": -2,
      "y": 5,
      "z": 4,
      "name": "Water_Source",
      "level": 1
    },
    {
      "x": -1,
      "y": 4,
      "z": 3,
      "name": "Water",
      "level": 8
    },
    {
      "x": -1,
      "y": 5,
      "z": 3,
      "name": "Water_Source",
      "level": 1
    },
    {
      "x": -1,
      "y": 4,
      "z": 4,
      "name": "Water",
      "level": 8
    },
    {
      "x": -1,
      "y": 5,
      "z": 4,
      "name": "Water_Source",
      "level": 1
    },
    {
      "x": 0,
      "y": 4,
      "z": 3,
      "name": "Water",
      "level": 8
    },
    {
      "x": 0,
      "y": 5,
      "z": 3,
      "name": "Water_Source",
      "level": 1
    },
    {
      "x": 0,
      "y": 4,
      "z": 4,
      "name": "Water",
      "level": 8
    },
    {
      "x": 0,
      "y": 5,
      "z": 4,
      "name": "Water_Source",
      "level": 1
    },
    {
      "x": 0,
      "y": 4,
      "z": 5,
      "name": "Water",
      "level": 8
    },
    {
      "x": 0,
      "y": 5,
      "z": 5,
      "name": "Water_Source",
      "level": 1
    },
    {
      "x": 0,
      "y": 4,
      "z": 6,
      "name": "Water",
      "level": 8
    },
    {
      "x": 0,
      "y": 5,
      "z": 6,
      "name": "Water_Source",
      "level": 1
    },
    {
      "x": 1,
      "y": 4,
      "z": 3,
      "name": "Water",
      "level": 8
    },
    {
      "x": 1,
      "y": 5,
      "z": 3,
      "name": "Water_Source",
      "level": 1
    },
    {
      "x": 1,
      "y": 4,
      "z": 4,
      "name": "Water",
      "level": 8
    },
    {
      "x": 1,
      "y": 5,
      "z": 4,
      "name": "Water",
      "level": 8
    },
    {
      "x": 1,
      "y": 4,
      "z": 5,
      "name": "Water",
      "level": 8
    },
    {
      "x": 1,
      "y": 5,
      "z": 5,
      "name": "Water_Source",
      "level": 1
    },
    {
      "x": 1,
      "y": 4,
      "z": 6,
      "name": "Water",
      "level": 8
    },
    {
      "x": 1,
      "y": 5,
      "z": 6,
      "name": "Water_Source",
      "level": 1
    },
    {
      "x": 2,
      "y": 4,
      "z": 3,
      "name": "Water_Source",
      "level": 1
    },
    {
      "x": 2,
      "y": 5,
      "z": 3,
      "name": "Water_Source",
      "level": 1
    },
    {
      "x": 2,
      "y": 4,
      "z": 4,
      "name": "Water",
      "level": 8
    },
    {
      "x": 2,
      "y": 5,
      "z": 4,
      "name": "Water_Source",
      "level": 1
    },
    {
      "x": 2,
      "y": 4,
      "z": 5,
      "name": "Water",
      "level": 8
    },
    {
      "x": 2,
      "y": 5,
      "z": 5,
      "name": "Water_Source",
      "level": 1
    },
    {
      "x": 2,
      "y": 4,
      "z": 6,
      "name": "Water",
      "level": 8
    },
    {
      "x": 2,
      "y": 5,
      "z": 6,
      "name": "Water",
      "level": 8
    },
    {
      "x": 3,
      "y": 4,
      "z": 3,
      "name": "Water_Source",
      "level": 1
    },
    {
      "x": 3,
      "y": 5,
      "z": 3,
      "name": "Water_Source",
      "level": 1
    },
    {
      "x": 3,
      "y": 4,
      "z": 4,
      "name": "Water_Source",
      "level": 1
    },
    {
      "x": 3,
      "y": 5,
      "z": 4,
      "name": "Water_Source",
      "level": 1
    },
    {
      "x": 3,
      "y": 4,
      "z": 5,
      "name": "Water",
      "level": 8
    },
    {
      "x": 3,
      "y": 5,
      "z": 5,
      "name": "Water_Source",
      "level": 1
    },
    {
      "x": 3,
      "y": 4,
      "z": 6,
      "name": "Water",
      "level": 8
    },
    {
      "x": 3,
      "y": 5,
      "z": 6,
      "name": "Water_Source",
      "level": 1
    },
    {
      "x": 4,
      "y": 4,
      "z": -4,
      "name": "Water_Source",
      "level": 1
    },
    {
      "x": 4,
      "y": 4,
      "z": -3,
      "name": "Water_Source",
      "level": 1
    },
    {
      "x": 4,
      "y": 5,
      "z": -3,
      "name": "Water_Source",
      "level": 1
    },
    {
      "x": 4,
      "y": 4,
      "z": -2,
      "name": "Water",
      "level": 8
    },
    {
      "x": 4,
      "y": 5,
      "z": -2,
      "name": "Water_Source",
      "level": 1
    },
    {
      "x": 4,
      "y": 4,
      "z": -1,
      "name": "Water",
      "level": 8
    },
    {
      "x": 4,
      "y": 5,
      "z": -1,
      "name": "Water_Source",
      "level": 1
    },
    {
      "x": 4,
      "y": 4,
      "z": 0,
      "name": "Water",
      "level": 8
    },
    {
      "x": 4,
      "y": 5,
      "z": 0,
      "name": "Water",
      "level": 8
    },
    {
      "x": 4,
      "y": 4,
      "z": 1,
      "name": "Water",
      "level": 8
    },
    {
      "x": 4,
      "y": 5,
      "z": 1,
      "name": "Water_Source",
      "level": 1
    },
    {
      "x": 4,
      "y": 4,
      "z": 2,
      "name": "Water",
      "level": 8
    },
    {
      "x": 4,
      "y": 5,
      "z": 2,
      "name": "Water_Source",
      "level": 1
    },
    {
      "x": 4,
      "y": 4,
      "z": 3,
      "name": "Water_Source",
      "level": 1
    },
    {
      "x": 4,
      "y": 5,
      "z": 3,
      "name": "Water_Source",
      "level": 1
    },
    {
      "x": 4,
      "y": 4,
      "z": 4,
      "name": "Water",
      "level": 8
    },
    {
      "x": 4,
      "y": 5,
      "z": 4,
      "name": "Water_Source",
      "level": 1
    },
    {
      "x": 4,
      "y": 4,
      "z": 5,
      "name": "Water",
      "level": 8
    },
    {
      "x": 4,
      "y": 5,
      "z": 5,
      "name": "Water_Source",
      "level": 1
    },
    {
      "x": 4,
      "y": 4,
      "z": 6,
      "name": "Water",
      "level": 8
    },
    {
      "x": 4,
      "y": 5,
      "z": 6,
      "name": "Water_Source",
      "level": 1
    },
    {
      "x": 5,
      "y": 4,
      "z": -3,
      "name": "Water_Source",
      "level": 1
    },
    {
      "x": 5,
      "y": 5,
      "z": -3,
      "name": "Water_Source",
      "level": 1
    },
    {
      "x": 5,
      "y": 4,
      "z": -2,
      "name": "Water",
      "level": 8
    },
    {
      "x": 5,
      "y": 5,
      "z": -2,
      "name": "Water_Source",
      "level": 1
    },
    {
      "x": 5,
      "y": 4,
      "z": -1,
      "name": "Water",
      "level": 8
    },
    {
      "x": 5,
      "y": 5,
      "z": -1,
      "name": "Water_Source",
      "level": 1
    },
    {
      "x": 5,
      "y": 4,
      "z": 0,
      "name": "Water",
      "level": 8
    },
    {
      "x": 5,
      "y": 5,
      "z": 0,
      "name": "Water_Source",
      "level": 1
    },
    {
      "x": 5,
      "y": 4,
      "z": 1,
      "name": "Water_Source",
      "level": 1
    },
    {
      "x": 5,
      "y": 5,
      "z": 1,
      "name": "Water_Source",
      "level": 1
    },
    {
      "x": 5,
      "y": 4,
      "z": 2,
      "name": "Water_Source",
      "level": 1
    },
    {
      "x": 5,
      "y": 5,
      "z": 2,
      "name": "Water_Source",
      "level": 1
    },
    {
      "x": 5,
      "y": 4,
      "z": 3,
      "name": "Water_Source",
      "level": 1
    },
    {
      "x": 5,
      "y": 5,
      "z": 3,
      "name": "Water_Source",
      "level": 1
    },
    {
      "x": 5,
      "y": 4,
      "z": 4,
      "name": "Water",
      "level": 8
    },
    {
      "x": 5,
      "y": 5,
      "z": 4,
      "name": "Water_Source",
      "level": 1
    },
    {
      "x": 5,
      "y": 4,
      "z": 5,
      "name": "Water",
      "level": 8
    },
    {
      "x": 5,
      "y": 5,
      "z": 5,
      "name": "Water",
      "level": 8
    },
    {
      "x": 5,
      "y": 4,
      "z": 6,
      "name": "Water",
      "level": 8
    },
    {
      "x": 5,
      "y": 5,
      "z": 6,
      "name": "Water",
      "level": 8
    }
  ]
}
