{
  "version": 8,
  "blockIdVersion": 8,
  "anchorX": 9,
  "anchorY": 3,
  "anchorZ": 5,
  "blocks": [
    {
      "x": 7,
      "y": 3,
      "z": 3,
      "name": "Plant_Coral_Block_Lime"
    },
    {
      "x": 7,
      "y": 4,
      "z": 3,
      "name": "Plant_Coral_Block_Lime"
    },
    {
      "x": 7,
      "y": 5,
      "z": 3,
      "name": "Plant_Coral_Block_Lime"
    },
    {
      "x": 7,
      "y": 3,
      "z": 4,
      "name": "Plant_Coral_Block_Lime"
    },
    {
      "x": 7,
      "y": 4,
      "z": 4,
      "name": "Plant_Coral_Block_Lime"
    },
    {
      "x": 7,
      "y": 5,
      "z": 4,
      "name": "Plant_Coral_Block_Lime"
    },
    {
      "x": 7,
      "y": 3,
      "z": 5,
      "name": "Plant_Coral_Block_Lime"
    },
    {
      "x": 7,
      "y": 4,
      "z": 5,
      "name": "Plant_Coral_Block_Lime"
    },
    {
      "x": 7,
      "y": 5,
      "z": 5,
      "name": "Plant_Coral_Block_Lime"
    },
    {
      "x": 7,
      "y": 3,
      "z": 6,
      "name": "Plant_Coral_Block_Lime"
    },
    {
      "x": 7,
      "y": 4,
      "z": 6,
      "name": "Plant_Coral_Block_Lime"
    },
    {
      "x": 8,
      "y": 3,
      "z": 2,
      "name": "Plant_Coral_Block_Lime"
    },
    {
      "x": 8,
      "y": 4,
      "z": 2,
      "name": "Plant_Coral_Block_Lime"
    },
    {
      "x": 8,
      "y": 3,
      "z": 3,
      "name": "Plant_Coral_Block_Lime"
    },
    {
      "x": 8,
      "y": 4,
      "z": 3,
      "name": "Plant_Coral_Block_Lime"
    },
    {
      "x": 8,
      "y": 5,
      "z": 3,
      "name": "Plant_Coral_Block_Lime"
    },
    {
      "x": 8,
      "y": 3,
      "z": 4,
      "name": "Plant_Coral_Block_Lime"
    },
    {
      "x": 8,
      "y": 4,
      "z": 4,
      "name": "Rock_Crystal_Green_Block"
    },
    {
      "x": 8,
      "y": 5,
      "z": 4,
      "name": "Plant_Coral_Bush_Green"
    },
    {
      "x": 8,
      "y": 3,
      "z": 5,
      "name": "Plant_Coral_Block_Lime"
    },
    {
      "x": 8,
      "y": 4,
      "z": 5,
      "name": "Rock_Crystal_Green_Block"
    },
    {
      "x": 8,
      "y": 5,
      "z": 5,
      "name": "Rock_Crystal_Green_Medium"
    },
    {
      "x": 8,
      "y": 3,
      "z": 6,
      "name": "Plant_Coral_Block_Lime"
    },
    {
      "x": 8,
      "y": 4,
      "z": 6,
      "name": "Rock_Crystal_Green_Block"
    },
    {
      "x": 8,
      "y": 3,
      "z": 7,
      "name": "Plant_Coral_Block_Lime"
    },
    {
      "x": 8,
      "y": 4,
      "z": 7,
      "name": "Plant_Coral_Block_Lime"
    },
    {
      "x": 8,
      "y": 5,
      "z": 7,
      "name": "Plant_Coral_Block_Lime"
    },
    {
      "x": 9,
      "y": 3,
      "z": 2,
      "name": "Plant_Coral_Block_Lime"
    },
    {
      "x": 9,
      "y": 4,
      "z": 2,
      "name": "Plant_Coral_Block_Lime"
    },
    {
      "x": 9,
      "y": 5,
      "z": 2,
      "name": "Plant_Coral_Block_Lime"
    },
    {
      "x": 9,
      "y": 3,
      "z": 3,
      "name": "Plant_Coral_Block_Lime"
    },
    {
      "x": 9,
      "y": 4,
      "z": 3,
      "name": "Rock_Crystal_Green_Block"
    },
    {
      "x": 9,
      "y": 3,
      "z": 4,
      "name": "Plant_Coral_Block_Lime"
    },
    {
      "x": 9,
      "y": 4,
      "z": 4,
      "name": "Rock_Crystal_Green_Block"
    },
    {
      "x": 9,
      "y": 3,
      "z": 5,
      "name": "Plant_Coral_Block_Lime"
    },
    {
      "x": 9,
      "y": 4,
      "z": 5,
      "name": "Rock_Crystal_Green_Block"
    },
    {
      "x": 9,
      "y": 3,
      "z": 6,
      "name": "Plant_Coral_Block_Lime"
    },
    {
      "x": 9,
      "y": 4,
      "z": 6,
      "name": "Rock_Crystal_Green_Block"
    },
    {
      "x": 9,
      "y": 5,
      "z": 6,
      "name": "Rock_Crystal_Green_Medium"
    },
    {
      "x": 9,
      "y": 3,
      "z": 7,
      "name": "Plant_Coral_Block_Lime"
    },
    {
      "x": 9,
      "y": 4,
      "z": 7,
      "name": "Plant_Coral_Block_Lime"
    },
    {
      "x": 9,
      "y": 5,
      "z": 7,
      "name": "Plant_Coral_Block_Lime"
    },
    {
      "x": 10,
      "y": 3,
      "z": 2,
      "name": "Plant_Coral_Block_Lime"
    },
    {
      "x": 10,
      "y": 4,
      "z": 2,
      "name": "Plant_Coral_Block_Lime"
    },
    {
      "x": 10,
      "y": 5,
      "z": 2,
      "name": "Plant_Coral_Block_Lime"
    },
    {
      "x": 10,
      "y": 3,
      "z": 3,
      "name": "Plant_Coral_Block_Lime"
    },
    {
      "x": 10,
      "y": 4,
      "z": 3,
      "name": "Rock_Crystal_Green_Block"
    },
    {
      "x": 10,
      "y": 5,
      "z": 3,
      "name": "Plant_Coral_Bush_Green"
    },
    {
      "x": 10,
      "y": 3,
      "z": 4,
      "name": "Plant_Coral_Block_Lime"
    },
    {
      "x": 10,
      "y": 4,
      "z": 4,
      "name": "Rock_Crystal_Green_Block"
    },
    {
      "x": 10,
      "y": 5,
      "z": 4,
      "name": "Plant_Coral_Bush_Green"
    },
    {
      "x": 10,
      "y": 3,
      "z": 5,
      "name": "Plant_Coral_Block_Lime"
    },
    {
      "x": 10,
      "y": 4,
      "z": 5,
      "name": "Rock_Crystal_Green_Block"
    },
    {
      "x": 10,
      "y": 3,
      "z": 6,
      "name": "Plant_Coral_Block_Lime"
    },
    {
      "x": 10,
      "y": 4,
      "z": 6,
      "name": "Rock_Crystal_Green_Block"
    },
    {
      "x": 10,
      "y": 3,
      "z": 7,
      "name": "Plant_Coral_Block_Lime"
    },
    {
      "x": 10,
      "y": 4,
      "z": 7,
      "name": "Plant_Coral_Block_Lime"
    },
    {
      "x": 10,
      "y": 5,
      "z": 7,
      "name": "Plant_Coral_Block_Lime"
    },
    {
      "x": 11,
      "y": 3,
      "z": 2,
      "name": "Plant_Coral_Block_Lime"
    },
    {
      "x": 11,
      "y": 4,
      "z": 2,
      "name": "Plant_Coral_Block_Lime"
    },
    {
      "x": 11,
      "y": 3,
      "z": 3,
      "name": "Plant_Coral_Block_Lime"
    },
    {
      "x": 11,
      "y": 4,
      "z": 3,
      "name": "Plant_Coral_Block_Lime"
    },
    {
      "x": 11,
      "y": 5,
      "z": 3,
      "name": "Plant_Coral_Block_Lime"
    },
    {
      "x": 11,
      "y": 6,
      "z": 3,
      "name": "Plant_Coral_Bush_Green"
    },
    {
      "x": 11,
      "y": 3,
      "z": 4,
      "name": "Plant_Coral_Block_Lime"
    },
    {
      "x": 11,
      "y": 4,
      "z": 4,
      "name": "Rock_Crystal_Green_Block"
    },
    {
      "x": 11,
      "y": 5,
      "z": 4,
      "name": "Plant_Coral_Bush_Green"
    },
    {
      "x": 11,
      "y": 3,
      "z": 5,
      "name": "Plant_Coral_Block_Lime"
    },
    {
      "x": 11,
      "y": 4,
      "z": 5,
      "name": "Rock_Crystal_Green_Block"
    },
    {
      "x": 11,
      "y": 3,
      "z": 6,
      "name": "Plant_Coral_Block_Lime"
    },
    {
      "x": 11,
      "y": 4,
      "z": 6,
      "name": "Rock_Crystal_Green_Block"
    },
    {
      "x": 11,
      "y": 5,
      "z": 6,
      "name": "Plant_Coral_Bush_Green"
    },
    {
      "x": 11,
      "y": 3,
      "z": 7,
      "name": "Plant_Coral_Block_Lime"
    },
    {
      "x": 11,
      "y": 4,
      "z": 7,
      "name": "Plant_Coral_Block_Lime"
    },
    {
      "x": 11,
      "y": 5,
      "z": 7,
      "name": "Plant_Coral_Block_Lime"
    },
    {
      "x": 12,
      "y": 3,
      "z": 3,
      "name": "Plant_Coral_Block_Lime"
    },
    {
      "x": 12,
      "y": 3,
      "z": 4,
      "name": "Plant_Coral_Block_Lime"
    },
    {
      "x": 12,
      "y": 4,
      "z": 4,
      "name": "Plant_Coral_Block_Lime"
    },
    {
      "x": 12,
      "y": 5,
      "z": 4,
      "name": "Plant_Coral_Block_Lime"
    },
    {
      "x": 12,
      "y": 3,
      "z": 5,
      "name": "Plant_Coral_Block_Lime"
    },
    {
      "x": 12,
      "y": 4,
      "z": 5,
      "name": "Plant_Coral_Block_Lime"
    },
    {
      "x": 12,
      "y": 5,
      "z": 5,
      "name": "Plant_Coral_Block_Lime"
    },
    {
      "x": 12,
      "y": 3,
      "z": 6,
      "name": "Plant_Coral_Block_Lime"
    },
    {
      "x": 12,
      "y": 4,
      "z": 6,
      "name": "Plant_Coral_Block_Lime"
    },
    {
      "x": 12,
      "y": 5,
      "z": 6,
      "name": "Plant_Coral_Block_Lime"
    }
  ]
}