{
  "version": 8,
  "blockIdVersion": 8,
  "anchorX": 0,
  "anchorY": 47,
  "anchorZ": -1,
  "blocks": [
    {
      "x": -12,
      "y": 40,
      "z": -9,
      "name": "Rock_Crystal_Red_Block",
      "rotation": 5
    },
    {
      "x": -11,
      "y": 40,
      "z": -9,
      "name": "Rock_Crystal_Red_Block",
      "rotation": 5
    },
    {
      "x": -11,
      "y": 41,
      "z": -9,
      "name": "Rock_Crystal_Red_Block",
      "rotation": 5
    },
    {
      "x": -11,
      "y": 41,
      "z": -8,
      "name": "Rock_Crystal_Red_Block",
      "rotation": 5
    },
    {
      "x": -10,
      "y": 40,
      "z": -9,
      "name": "Rock_Crystal_Red_Block",
      "rotation": 5
    },
    {
      "x": -10,
      "y": 41,
      "z": -9,
      "name": "Rock_Crystal_Red_Block",
      "rotation": 5
    },
    {
      "x": -10,
      "y": 40,
      "z": -8,
      "name": "Rock_Crystal_Red_Block",
      "rotation": 5
    },
    {
      "x": -10,
      "y": 41,
      "z": -8,
      "name": "Rock_Crystal_Red_Block",
      "rotation": 5
    },
    {
      "x": -10,
      "y": 42,
      "z": -8,
      "name": "Rock_Crystal_Red_Block",
      "rotation": 5
    },
    {
      "x": -10,
      "y": 41,
      "z": -7,
      "name": "Rock_Crystal_Red_Block",
      "rotation": 5
    },
    {
      "x": -10,
      "y": 42,
      "z": -7,
      "name": "Rock_Crystal_Red_Block",
      "rotation": 5
    },
    {
      "x": -9,
      "y": 41,
      "z": -9,
      "name": "Rock_Crystal_Red_Block",
      "rotation": 5
    },
    {
      "x": -9,
      "y": 42,
      "z": -9,
      "name": "Rock_Crystal_Red_Block",
      "rotation": 5
    },
    {
      "x": -9,
      "y": 41,
      "z": -8,
      "name": "Rock_Crystal_Red_Block",
      "rotation": 5
    },
    {
      "x": -9,
      "y": 42,
      "z": -8,
      "name": "Rock_Crystal_Red_Block",
      "rotation": 5
    },
    {
      "x": -9,
      "y": 43,
      "z": -8,
      "name": "Rock_Crystal_Red_Block",
      "rotation": 5
    },
    {
      "x": -9,
      "y": 41,
      "z": -7,
      "name": "Rock_Crystal_Red_Block",
      "rotation": 5
    },
    {
      "x": -9,
      "y": 42,
      "z": -7,
      "name": "Rock_Crystal_Red_Block",
      "rotation": 5
    },
    {
      "x": -9,
      "y": 43,
      "z": -7,
      "name": "Rock_Crystal_Red_Block",
      "rotation": 5
    },
    {
      "x": -8,
      "y": 41,
      "z": -8,
      "name": "Rock_Crystal_Red_Block",
      "rotation": 5
    },
    {
      "x": -8,
      "y": 42,
      "z": -8,
      "name": "Rock_Crystal_Red_Block",
      "rotation": 5
    },
    {
      "x": -8,
      "y": 43,
      "z": -8,
      "name": "Rock_Crystal_Red_Block",
      "rotation": 5
    },
    {
      "x": -8,
      "y": 44,
      "z": -8,
      "name": "Rock_Crystal_Red_Block",
      "rotation": 5
    },
    {
      "x": -8,
      "y": 41,
      "z": -7,
      "name": "Rock_Crystal_Red_Block",
      "rotation": 5
    },
    {
      "x": -8,
      "y": 42,
      "z": -7,
      "name": "Rock_Crystal_Red_Block",
      "rotation": 5
    },
    {
      "x": -8,
      "y": 43,
      "z": -7,
      "name": "Rock_Crystal_Red_Block",
      "rotation": 5
    },
    {
      "x": -8,
      "y": 44,
      "z": -7,
      "name": "Rock_Crystal_Red_Block",
      "rotation": 5
    },
    {
      "x": -8,
      "y": 42,
      "z": -6,
      "name": "Rock_Crystal_Red_Block",
      "rotation": 5
    },
    {
      "x": -8,
      "y": 43,
      "z": -6,
      "name": "Rock_Crystal_Red_Block",
      "rotation": 5
    },
    {
      "x": -8,
      "y": 44,
      "z": -6,
      "name": "Rock_Crystal_Red_Block",
      "rotation": 5
    },
    {
      "x": -7,
      "y": 43,
      "z": -8,
      "name": "Rock_Crystal_Red_Block",
      "rotation": 5
    },
    {
      "x": -7,
      "y": 44,
      "z": -8,
      "name": "Rock_Crystal_Red_Block",
      "rotation": 5
    },
    {
      "x": -7,
      "y": 42,
      "z": -7,
      "name": "Rock_Crystal_Red_Block",
      "rotation": 5
    },
    {
      "x": -7,
      "y": 43,
      "z": -7,
      "name": "Rock_Crystal_Red_Block",
      "rotation": 5
    },
    {
      "x": -7,
      "y": 44,
      "z": -7,
      "name": "Rock_Crystal_Red_Block",
      "rotation": 5
    },
    {
      "x": -7,
      "y": 45,
      "z": -7,
      "name": "Rock_Crystal_Red_Block",
      "rotation": 5
    },
    {
      "x": -7,
      "y": 42,
      "z": -6,
      "name": "Rock_Crystal_Red_Block",
      "rotation": 5
    },
    {
      "x": -7,
      "y": 43,
      "z": -6,
      "name": "Rock_Crystal_Red_Block",
      "rotation": 5
    },
    {
      "x": -7,
      "y": 44,
      "z": -6,
      "name": "Rock_Crystal_Red_Block",
      "rotation": 5
    },
    {
      "x": -7,
      "y": 45,
      "z": -6,
      "name": "Rock_Crystal_Red_Block",
      "rotation": 5
    },
    {
      "x": -7,
      "y": 42,
      "z": -5,
      "name": "Rock_Basalt"
    },
    {
      "x": -7,
      "y": 43,
      "z": -5,
      "name": "Rock_Crystal_Red_Block",
      "rotation": 5
    },
    {
      "x": -7,
      "y": 44,
      "z": -5,
      "name": "Rock_Crystal_Red_Block",
      "rotation": 5
    },
    {
      "x": -7,
      "y": 40,
      "z": -4,
      "name": "Rock_Basalt"
    },
    {
      "x": -7,
      "y": 41,
      "z": -4,
      "name": "Rock_Basalt"
    },
    {
      "x": -7,
      "y": 42,
      "z": -4,
      "name": "Rock_Basalt"
    },
    {
      "x": -7,
      "y": 46,
      "z": -4,
      "name": "Rock_Basalt"
    },
    {
      "x": -7,
      "y": 38,
      "z": -3,
      "name": "Rock_Basalt"
    },
    {
      "x": -7,
      "y": 39,
      "z": -3,
      "name": "Rock_Basalt"
    },
    {
      "x": -7,
      "y": 40,
      "z": -3,
      "name": "Rock_Basalt"
    },
    {
      "x": -7,
      "y": 41,
      "z": -3,
      "name": "Rock_Basalt"
    },
    {
      "x": -7,
      "y": 42,
      "z": -3,
      "name": "Rock_Basalt"
    },
    {
      "x": -7,
      "y": 45,
      "z": -3,
      "name": "Rock_Basalt"
    },
    {
      "x": -7,
      "y": 46,
      "z": -3,
      "name": "Rock_Basalt"
    },
    {
      "x": -7,
      "y": 47,
      "z": -3,
      "name": "Rock_Basalt"
    },
    {
      "x": -7,
      "y": 38,
      "z": -2,
      "name": "Rock_Basalt"
    },
    {
      "x": -7,
      "y": 39,
      "z": -2,
      "name": "Rock_Basalt"
    },
    {
      "x": -7,
      "y": 40,
      "z": -2,
      "name": "Rock_Basalt"
    },
    {
      "x": -7,
      "y": 41,
      "z": -2,
      "name": "Rock_Basalt"
    },
    {
      "x": -7,
      "y": 42,
      "z": -2,
      "name": "Rock_Basalt"
    },
    {
      "x": -7,
      "y": 43,
      "z": -2,
      "name": "Rock_Basalt"
    },
    {
      "x": -7,
      "y": 45,
      "z": -2,
      "name": "Rock_Basalt"
    },
    {
      "x": -7,
      "y": 46,
      "z": -2,
      "name": "Rock_Basalt"
    },
    {
      "x": -7,
      "y": 47,
      "z": -2,
      "name": "Rock_Basalt"
    },
    {
      "x": -7,
      "y": 48,
      "z": -2,
      "name": "Rock_Basalt"
    },
    {
      "x": -7,
      "y": 39,
      "z": -1,
      "name": "Rock_Basalt"
    },
    {
      "x": -7,
      "y": 40,
      "z": -1,
      "name": "Rock_Basalt"
    },
    {
      "x": -7,
      "y": 41,
      "z": -1,
      "name": "Rock_Basalt"
    },
    {
      "x": -7,
      "y": 42,
      "z": -1,
      "name": "Rock_Basalt"
    },
    {
      "x": -7,
      "y": 43,
      "z": -1,
      "name": "Rock_Basalt"
    },
    {
      "x": -7,
      "y": 47,
      "z": -1,
      "name": "Rock_Basalt"
    },
    {
      "x": -7,
      "y": 48,
      "z": -1,
      "name": "Rock_Basalt"
    },
    {
      "x": -7,
      "y": 40,
      "z": 0,
      "name": "Rock_Basalt"
    },
    {
      "x": -7,
      "y": 41,
      "z": 0,
      "name": "Rock_Basalt"
    },
    {
      "x": -7,
      "y": 42,
      "z": 0,
      "name": "Rock_Basalt"
    },
    {
      "x": -7,
      "y": 43,
      "z": 0,
      "name": "Rock_Basalt"
    },
    {
      "x": -7,
      "y": 44,
      "z": 0,
      "name": "Rock_Basalt"
    },
    {
      "x": -7,
      "y": 45,
      "z": 0,
      "name": "Rock_Basalt"
    },
    {
      "x": -7,
      "y": 42,
      "z": 1,
      "name": "Rock_Basalt"
    },
    {
      "x": -7,
      "y": 43,
      "z": 1,
      "name": "Rock_Basalt"
    },
    {
      "x": -7,
      "y": 44,
      "z": 1,
      "name": "Rock_Basalt"
    },
    {
      "x": -7,
      "y": 45,
      "z": 1,
      "name": "Rock_Basalt"
    },
    {
      "x": -7,
      "y": 46,
      "z": 1,
      "name": "Rock_Basalt"
    },
    {
      "x": -6,
      "y": 42,
      "z": -7,
      "name": "Rock_Basalt"
    },
    {
      "x": -6,
      "y": 43,
      "z": -7,
      "name": "Rock_Crystal_Red_Block",
      "rotation": 5
    },
    {
      "x": -6,
      "y": 44,
      "z": -7,
      "name": "Rock_Crystal_Red_Block",
      "rotation": 5
    },
    {
      "x": -6,
      "y": 45,
      "z": -7,
      "name": "Rock_Crystal_Red_Block",
      "rotation": 5
    },
    {
      "x": -6,
      "y": 41,
      "z": -6,
      "name": "Rock_Basalt"
    },
    {
      "x": -6,
      "y": 42,
      "z": -6,
      "name": "Rock_Basalt"
    },
    {
      "x": -6,
      "y": 43,
      "z": -6,
      "name": "Rock_Crystal_Red_Block",
      "rotation": 5
    },
    {
      "x": -6,
      "y": 44,
      "z": -6,
      "name": "Rock_Crystal_Red_Block",
      "rotation": 5
    },
    {
      "x": -6,
      "y": 45,
      "z": -6,
      "name": "Rock_Crystal_Red_Block",
      "rotation": 5
    },
    {
      "x": -6,
      "y": 46,
      "z": -6,
      "name": "Rock_Crystal_Red_Block"
    },
    {
      "x": -6,
      "y": 36,
      "z": -5,
      "name": "Rock_Basalt"
    },
    {
      "x": -6,
      "y": 37,
      "z": -5,
      "name": "Rock_Basalt"
    },
    {
      "x": -6,
      "y": 38,
      "z": -5,
      "name": "Rock_Basalt"
    },
    {
      "x": -6,
      "y": 39,
      "z": -5,
      "name": "Rock_Basalt"
    },
    {
      "x": -6,
      "y": 40,
      "z": -5,
      "name": "Rock_Basalt"
    },
    {
      "x": -6,
      "y": 41,
      "z": -5,
      "name": "Rock_Basalt"
    },
    {
      "x": -6,
      "y": 42,
      "z": -5,
      "name": "Rock_Basalt"
    },
    {
      "x": -6,
      "y": 43,
      "z": -5,
      "name": "Rock_Basalt"
    },
    {
      "x": -6,
      "y": 44,
      "z": -5,
      "name": "Rock_Crystal_Red_Block",
      "rotation": 5
    },
    {
      "x": -6,
      "y": 45,
      "z": -5,
      "name": "Rock_Crystal_Red_Block",
      "rotation": 5
    },
    {
      "x": -6,
      "y": 46,
      "z": -5,
      "name": "Rock_Basalt"
    },
    {
      "x": -6,
      "y": 47,
      "z": -5,
      "name": "Rock_Basalt"
    },
    {
      "x": -6,
      "y": 48,
      "z": -5,
      "name": "Rock_Basalt"
    },
    {
      "x": -6,
      "y": 34,
      "z": -4,
      "name": "Rock_Basalt"
    },
    {
      "x": -6,
      "y": 35,
      "z": -4,
      "name": "Rock_Basalt"
    },
    {
      "x": -6,
      "y": 36,
      "z": -4,
      "name": "Rock_Basalt"
    },
    {
      "x": -6,
      "y": 37,
      "z": -4,
      "name": "Rock_Basalt"
    },
    {
      "x": -6,
      "y": 38,
      "z": -4,
      "name": "Rock_Basalt"
    },
    {
      "x": -6,
      "y": 39,
      "z": -4,
      "name": "Rock_Basalt"
    },
    {
      "x": -6,
      "y": 40,
      "z": -4,
      "name": "Rock_Basalt"
    },
    {
      "x": -6,
      "y": 41,
      "z": -4,
      "name": "Rock_Basalt"
    },
    {
      "x": -6,
      "y": 42,
      "z": -4,
      "name": "Rock_Basalt"
    },
    {
      "x": -6,
      "y": 43,
      "z": -4,
      "name": "Rock_Crystal_Red_Block",
      "rotation": 5
    },
    {
      "x": -6,
      "y": 44,
      "z": -4,
      "name": "Rock_Crystal_Red_Block",
      "rotation": 5
    },
    {
      "x": -6,
      "y": 45,
      "z": -4,
      "name": "Rock_Crystal_Red_Block",
      "rotation": 5
    },
    {
      "x": -6,
      "y": 46,
      "z": -4,
      "name": "Rock_Basalt"
    },
    {
      "x": -6,
      "y": 47,
      "z": -4,
      "name": "Rock_Basalt"
    },
    {
      "x": -6,
      "y": 48,
      "z": -4,
      "name": "Rock_Basalt"
    },
    {
      "x": -6,
      "y": 49,
      "z": -4,
      "name": "Rock_Basalt"
    },
    {
      "x": -6,
      "y": 33,
      "z": -3,
      "name": "Rock_Basalt"
    },
    {
      "x": -6,
      "y": 34,
      "z": -3,
      "name": "Rock_Basalt"
    },
    {
      "x": -6,
      "y": 35,
      "z": -3,
      "name": "Rock_Basalt"
    },
    {
      "x": -6,
      "y": 36,
      "z": -3,
      "name": "Rock_Basalt"
    },
    {
      "x": -6,
      "y": 37,
      "z": -3,
      "name": "Rock_Basalt"
    },
    {
      "x": -6,
      "y": 38,
      "z": -3,
      "name": "Rock_Basalt"
    },
    {
      "x": -6,
      "y": 39,
      "z": -3,
      "name": "Rock_Basalt"
    },
    {
      "x": -6,
      "y": 40,
      "z": -3,
      "name": "Rock_Basalt"
    },
    {
      "x": -6,
      "y": 41,
      "z": -3,
      "name": "Rock_Basalt"
    },
    {
      "x": -6,
      "y": 42,
      "z": -3,
      "name": "Rock_Basalt"
    },
    {
      "x": -6,
      "y": 43,
      "z": -3,
      "name": "Rock_Crystal_Red_Block",
      "rotation": 5
    },
    {
      "x": -6,
      "y": 44,
      "z": -3,
      "name": "Rock_Crystal_Red_Block",
      "rotation": 5
    },
    {
      "x": -6,
      "y": 45,
      "z": -3,
      "name": "Rock_Basalt"
    },
    {
      "x": -6,
      "y": 46,
      "z": -3,
      "name": "Rock_Basalt"
    },
    {
      "x": -6,
      "y": 47,
      "z": -3,
      "name": "Rock_Basalt"
    },
    {
      "x": -6,
      "y": 48,
      "z": -3,
      "name": "Rock_Basalt"
    },
    {
      "x": -6,
      "y": 49,
      "z": -3,
      "name": "Rock_Basalt"
    },
    {
      "x": -6,
      "y": 33,
      "z": -2,
      "name": "Rock_Basalt"
    },
    {
      "x": -6,
      "y": 34,
      "z": -2,
      "name": "Rock_Basalt"
    },
    {
      "x": -6,
      "y": 35,
      "z": -2,
      "name": "Rock_Basalt"
    },
    {
      "x": -6,
      "y": 36,
      "z": -2,
      "name": "Rock_Basalt"
    },
    {
      "x": -6,
      "y": 37,
      "z": -2,
      "name": "Rock_Basalt"
    },
    {
      "x": -6,
      "y": 38,
      "z": -2,
      "name": "Rock_Basalt"
    },
    {
      "x": -6,
      "y": 39,
      "z": -2,
      "name": "Rock_Basalt"
    },
    {
      "x": -6,
      "y": 40,
      "z": -2,
      "name": "Rock_Basalt"
    },
    {
      "x": -6,
      "y": 41,
      "z": -2,
      "name": "Rock_Basalt"
    },
    {
      "x": -6,
      "y": 42,
      "z": -2,
      "name": "Rock_Basalt"
    },
    {
      "x": -6,
      "y": 43,
      "z": -2,
      "name": "Rock_Basalt"
    },
    {
      "x": -6,
      "y": 44,
      "z": -2,
      "name": "Rock_Crystal_Red_Block",
      "rotation": 5
    },
    {
      "x": -6,
      "y": 45,
      "z": -2,
      "name": "Rock_Basalt"
    },
    {
      "x": -6,
      "y": 46,
      "z": -2,
      "name": "Rock_Basalt"
    },
    {
      "x": -6,
      "y": 47,
      "z": -2,
      "name": "Rock_Basalt"
    },
    {
      "x": -6,
      "y": 48,
      "z": -2,
      "name": "Rock_Basalt"
    },
    {
      "x": -6,
      "y": 49,
      "z": -2,
      "name": "Rock_Basalt"
    },
    {
      "x": -6,
      "y": 50,
      "z": -2,
      "name": "Rock_Basalt"
    },
    {
      "x": -6,
      "y": 34,
      "z": -1,
      "name": "Rock_Basalt"
    },
    {
      "x": -6,
      "y": 35,
      "z": -1,
      "name": "Rock_Basalt"
    },
    {
      "x": -6,
      "y": 36,
      "z": -1,
      "name": "Rock_Basalt"
    },
    {
      "x": -6,
      "y": 37,
      "z": -1,
      "name": "Rock_Basalt"
    },
    {
      "x": -6,
      "y": 38,
      "z": -1,
      "name": "Rock_Basalt"
    },
    {
      "x": -6,
      "y": 39,
      "z": -1,
      "name": "Rock_Basalt"
    },
    {
      "x": -6,
      "y": 40,
      "z": -1,
      "name": "Rock_Basalt"
    },
    {
      "x": -6,
      "y": 41,
      "z": -1,
      "name": "Rock_Basalt"
    },
    {
      "x": -6,
      "y": 42,
      "z": -1,
      "name": "Rock_Basalt"
    },
    {
      "x": -6,
      "y": 43,
      "z": -1,
      "name": "Rock_Basalt"
    },
    {
      "x": -6,
      "y": 44,
      "z": -1,
      "name": "Rock_Crystal_Red_Block",
      "rotation": 5
    },
    {
      "x": -6,
      "y": 45,
      "z": -1,
      "name": "Rock_Crystal_Red_Block",
      "rotation": 5
    },
    {
      "x": -6,
      "y": 46,
      "z": -1,
      "name": "Rock_Crystal_Red_Block",
      "rotation": 5
    },
    {
      "x": -6,
      "y": 47,
      "z": -1,
      "name": "Rock_Basalt"
    },
    {
      "x": -6,
      "y": 48,
      "z": -1,
      "name": "Rock_Basalt"
    },
    {
      "x": -6,
      "y": 49,
      "z": -1,
      "name": "Rock_Basalt"
    },
    {
      "x": -6,
      "y": 50,
      "z": -1,
      "name": "Rock_Basalt"
    },
    {
      "x": -6,
      "y": 35,
      "z": 0,
      "name": "Rock_Basalt"
    },
    {
      "x": -6,
      "y": 36,
      "z": 0,
      "name": "Rock_Basalt"
    },
    {
      "x": -6,
      "y": 37,
      "z": 0,
      "name": "Rock_Basalt"
    },
    {
      "x": -6,
      "y": 38,
      "z": 0,
      "name": "Rock_Basalt"
    },
    {
      "x": -6,
      "y": 39,
      "z": 0,
      "name": "Rock_Basalt"
    },
    {
      "x": -6,
      "y": 40,
      "z": 0,
      "name": "Rock_Basalt"
    },
    {
      "x": -6,
      "y": 41,
      "z": 0,
      "name": "Rock_Basalt"
    },
    {
      "x": -6,
      "y": 42,
      "z": 0,
      "name": "Rock_Basalt"
    },
    {
      "x": -6,
      "y": 43,
      "z": 0,
      "name": "Rock_Basalt"
    },
    {
      "x": -6,
      "y": 44,
      "z": 0,
      "name": "Rock_Basalt"
    },
    {
      "x": -6,
      "y": 45,
      "z": 0,
      "name": "Rock_Basalt"
    },
    {
      "x": -6,
      "y": 46,
      "z": 0,
      "name": "Rock_Crystal_Red_Block",
      "rotation": 5
    },
    {
      "x": -6,
      "y": 47,
      "z": 0,
      "name": "Rock_Basalt"
    },
    {
      "x": -6,
      "y": 48,
      "z": 0,
      "name": "Rock_Basalt"
    },
    {
      "x": -6,
      "y": 49,
      "z": 0,
      "name": "Rock_Basalt"
    },
    {
      "x": -6,
      "y": 50,
      "z": 0,
      "name": "Rock_Basalt"
    },
    {
      "x": -6,
      "y": 37,
      "z": 1,
      "name": "Rock_Basalt"
    },
    {
      "x": -6,
      "y": 38,
      "z": 1,
      "name": "Rock_Basalt"
    },
    {
      "x": -6,
      "y": 39,
      "z": 1,
      "name": "Rock_Basalt"
    },
    {
      "x": -6,
      "y": 40,
      "z": 1,
      "name": "Rock_Basalt"
    },
    {
      "x": -6,
      "y": 41,
      "z": 1,
      "name": "Rock_Basalt"
    },
    {
      "x": -6,
      "y": 42,
      "z": 1,
      "name": "Rock_Basalt"
    },
    {
      "x": -6,
      "y": 43,
      "z": 1,
      "name": "Rock_Basalt"
    },
    {
      "x": -6,
      "y": 44,
      "z": 1,
      "name": "Rock_Basalt"
    },
    {
      "x": -6,
      "y": 45,
      "z": 1,
      "name": "Rock_Basalt"
    },
    {
      "x": -6,
      "y": 46,
      "z": 1,
      "name": "Rock_Basalt"
    },
    {
      "x": -6,
      "y": 47,
      "z": 1,
      "name": "Rock_Basalt"
    },
    {
      "x": -6,
      "y": 48,
      "z": 1,
      "name": "Rock_Basalt"
    },
    {
      "x": -6,
      "y": 49,
      "z": 1,
      "name": "Rock_Basalt"
    },
    {
      "x": -6,
      "y": 50,
      "z": 1,
      "name": "Rock_Basalt"
    },
    {
      "x": -6,
      "y": 39,
      "z": 2,
      "name": "Rock_Basalt"
    },
    {
      "x": -6,
      "y": 40,
      "z": 2,
      "name": "Rock_Basalt"
    },
    {
      "x": -6,
      "y": 41,
      "z": 2,
      "name": "Rock_Basalt"
    },
    {
      "x": -6,
      "y": 42,
      "z": 2,
      "name": "Rock_Basalt"
    },
    {
      "x": -6,
      "y": 43,
      "z": 2,
      "name": "Rock_Basalt"
    },
    {
      "x": -6,
      "y": 44,
      "z": 2,
      "name": "Rock_Basalt"
    },
    {
      "x": -6,
      "y": 45,
      "z": 2,
      "name": "Rock_Basalt"
    },
    {
      "x": -6,
      "y": 46,
      "z": 2,
      "name": "Rock_Basalt"
    },
    {
      "x": -6,
      "y": 47,
      "z": 2,
      "name": "Rock_Basalt"
    },
    {
      "x": -6,
      "y": 48,
      "z": 2,
      "name": "Rock_Basalt"
    },
    {
      "x": -6,
      "y": 49,
      "z": 2,
      "name": "Rock_Basalt"
    },
    {
      "x": -6,
      "y": 50,
      "z": 2,
      "name": "Rock_Basalt"
    },
    {
      "x": -6,
      "y": 41,
      "z": 3,
      "name": "Rock_Basalt"
    },
    {
      "x": -6,
      "y": 42,
      "z": 3,
      "name": "Rock_Basalt"
    },
    {
      "x": -6,
      "y": 43,
      "z": 3,
      "name": "Rock_Basalt"
    },
    {
      "x": -6,
      "y": 44,
      "z": 3,
      "name": "Rock_Basalt"
    },
    {
      "x": -6,
      "y": 45,
      "z": 3,
      "name": "Rock_Basalt"
    },
    {
      "x": -6,
      "y": 46,
      "z": 3,
      "name": "Rock_Basalt"
    },
    {
      "x": -6,
      "y": 47,
      "z": 3,
      "name": "Rock_Basalt"
    },
    {
      "x": -6,
      "y": 48,
      "z": 3,
      "name": "Rock_Basalt"
    },
    {
      "x": -6,
      "y": 49,
      "z": 3,
      "name": "Rock_Basalt"
    },
    {
      "x": -6,
      "y": 46,
      "z": 4,
      "name": "Rock_Basalt"
    },
    {
      "x": -5,
      "y": 41,
      "z": -8,
      "name": "Rock_Basalt"
    },
    {
      "x": -5,
      "y": 42,
      "z": -8,
      "name": "Rock_Basalt"
    },
    {
      "x": -5,
      "y": 39,
      "z": -7,
      "name": "Rock_Basalt"
    },
    {
      "x": -5,
      "y": 40,
      "z": -7,
      "name": "Rock_Basalt"
    },
    {
      "x": -5,
      "y": 41,
      "z": -7,
      "name": "Rock_Basalt"
    },
    {
      "x": -5,
      "y": 42,
      "z": -7,
      "name": "Rock_Basalt"
    },
    {
      "x": -5,
      "y": 43,
      "z": -7,
      "name": "Rock_Crystal_Red_Block",
      "rotation": 4
    },
    {
      "x": -5,
      "y": 44,
      "z": -7,
      "name": "Rock_Crystal_Red_Block",
      "rotation": 5
    },
    {
      "x": -5,
      "y": 45,
      "z": -7,
      "name": "Rock_Crystal_Red_Block",
      "rotation": 5
    },
    {
      "x": -5,
      "y": 46,
      "z": -7,
      "name": "Rock_Crystal_Red_Block"
    },
    {
      "x": -5,
      "y": 38,
      "z": -6,
      "name": "Rock_Basalt"
    },
    {
      "x": -5,
      "y": 39,
      "z": -6,
      "name": "Rock_Basalt"
    },
    {
      "x": -5,
      "y": 40,
      "z": -6,
      "name": "Rock_Basalt"
    },
    {
      "x": -5,
      "y": 41,
      "z": -6,
      "name": "Rock_Basalt"
    },
    {
      "x": -5,
      "y": 42,
      "z": -6,
      "name": "Rock_Basalt"
    },
    {
      "x": -5,
      "y": 43,
      "z": -6,
      "name": "Rock_Basalt"
    },
    {
      "x": -5,
      "y": 44,
      "z": -6,
      "name": "Rock_Crystal_Red_Block",
      "rotation": 5
    },
    {
      "x": -5,
      "y": 45,
      "z": -6,
      "name": "Rock_Crystal_Red_Block",
      "rotation": 5
    },
    {
      "x": -5,
      "y": 46,
      "z": -6,
      "name": "Rock_Crystal_Red_Block"
    },
    {
      "x": -5,
      "y": 47,
      "z": -6,
      "name": "Rock_Basalt"
    },
    {
      "x": -5,
      "y": 48,
      "z": -6,
      "name": "Rock_Basalt"
    },
    {
      "x": -5,
      "y": 32,
      "z": -5,
      "name": "Rock_Basalt"
    },
    {
      "x": -5,
      "y": 33,
      "z": -5,
      "name": "Rock_Basalt"
    },
    {
      "x": -5,
      "y": 34,
      "z": -5,
      "name": "Rock_Basalt"
    },
    {
      "x": -5,
      "y": 35,
      "z": -5,
      "name": "Rock_Basalt"
    },
    {
      "x": -5,
      "y": 36,
      "z": -5,
      "name": "Rock_Basalt"
    },
    {
      "x": -5,
      "y": 37,
      "z": -5,
      "name": "Rock_Basalt"
    },
    {
      "x": -5,
      "y": 38,
      "z": -5,
      "name": "Rock_Basalt"
    },
    {
      "x": -5,
      "y": 39,
      "z": -5,
      "name": "Rock_Basalt"
    },
    {
      "x": -5,
      "y": 40,
      "z": -5,
      "name": "Rock_Basalt"
    },
    {
      "x": -5,
      "y": 41,
      "z": -5,
      "name": "Rock_Basalt"
    },
    {
      "x": -5,
      "y": 42,
      "z": -5,
      "name": "Rock_Basalt"
    },
    {
      "x": -5,
      "y": 43,
      "z": -5,
      "name": "Rock_Basalt"
    },
    {
      "x": -5,
      "y": 44,
      "z": -5,
      "name": "Rock_Basalt"
    },
    {
      "x": -5,
      "y": 45,
      "z": -5,
      "name": "Rock_Basalt"
    },
    {
      "x": -5,
      "y": 46,
      "z": -5,
      "name": "Rock_Basalt"
    },
    {
      "x": -5,
      "y": 47,
      "z": -5,
      "name": "Rock_Basalt"
    },
    {
      "x": -5,
      "y": 48,
      "z": -5,
      "name": "Rock_Basalt"
    },
    {
      "x": -5,
      "y": 49,
      "z": -5,
      "name": "Rock_Basalt"
    },
    {
      "x": -5,
      "y": 50,
      "z": -5,
      "name": "Rock_Basalt"
    },
    {
      "x": -5,
      "y": 30,
      "z": -4,
      "name": "Rock_Basalt"
    },
    {
      "x": -5,
      "y": 31,
      "z": -4,
      "name": "Rock_Basalt"
    },
    {
      "x": -5,
      "y": 32,
      "z": -4,
      "name": "Rock_Basalt"
    },
    {
      "x": -5,
      "y": 33,
      "z": -4,
      "name": "Rock_Basalt"
    },
    {
      "x": -5,
      "y": 34,
      "z": -4,
      "name": "Rock_Basalt"
    },
    {
      "x": -5,
      "y": 35,
      "z": -4,
      "name": "Rock_Basalt"
    },
    {
      "x": -5,
      "y": 36,
      "z": -4,
      "name": "Rock_Basalt"
    },
    {
      "x": -5,
      "y": 37,
      "z": -4,
      "name": "Rock_Basalt"
    },
    {
      "x": -5,
      "y": 38,
      "z": -4,
      "name": "Rock_Basalt"
    },
    {
      "x": -5,
      "y": 39,
      "z": -4,
      "name": "Rock_Basalt"
    },
    {
      "x": -5,
      "y": 40,
      "z": -4,
      "name": "Rock_Basalt"
    },
    {
      "x": -5,
      "y": 41,
      "z": -4,
      "name": "Rock_Basalt"
    },
    {
      "x": -5,
      "y": 42,
      "z": -4,
      "name": "Rock_Basalt"
    },
    {
      "x": -5,
      "y": 43,
      "z": -4,
      "name": "Rock_Basalt"
    },
    {
      "x": -5,
      "y": 44,
      "z": -4,
      "name": "Rock_Basalt"
    },
    {
      "x": -5,
      "y": 45,
      "z": -4,
      "name": "Rock_Basalt"
    },
    {
      "x": -5,
      "y": 46,
      "z": -4,
      "name": "Rock_Basalt"
    },
    {
      "x": -5,
      "y": 47,
      "z": -4,
      "name": "Rock_Basalt"
    },
    {
      "x": -5,
      "y": 48,
      "z": -4,
      "name": "Rock_Basalt"
    },
    {
      "x": -5,
      "y": 49,
      "z": -4,
      "name": "Rock_Basalt"
    },
    {
      "x": -5,
      "y": 50,
      "z": -4,
      "name": "Rock_Basalt"
    },
    {
      "x": -5,
      "y": 27,
      "z": -3,
      "name": "Rock_Basalt"
    },
    {
      "x": -5,
      "y": 30,
      "z": -3,
      "name": "Rock_Basalt"
    },
    {
      "x": -5,
      "y": 31,
      "z": -3,
      "name": "Rock_Basalt"
    },
    {
      "x": -5,
      "y": 32,
      "z": -3,
      "name": "Rock_Basalt"
    },
    {
      "x": -5,
      "y": 33,
      "z": -3,
      "name": "Rock_Basalt"
    },
    {
      "x": -5,
      "y": 34,
      "z": -3,
      "name": "Rock_Basalt"
    },
    {
      "x": -5,
      "y": 35,
      "z": -3,
      "name": "Rock_Basalt"
    },
    {
      "x": -5,
      "y": 36,
      "z": -3,
      "name": "Rock_Basalt"
    },
    {
      "x": -5,
      "y": 37,
      "z": -3,
      "name": "Rock_Basalt"
    },
    {
      "x": -5,
      "y": 38,
      "z": -3,
      "name": "Rock_Basalt"
    },
    {
      "x": -5,
      "y": 39,
      "z": -3,
      "name": "Rock_Basalt"
    },
    {
      "x": -5,
      "y": 40,
      "z": -3,
      "name": "Rock_Basalt"
    },
    {
      "x": -5,
      "y": 41,
      "z": -3,
      "name": "Rock_Basalt"
    },
    {
      "x": -5,
      "y": 42,
      "z": -3,
      "name": "Rock_Basalt"
    },
    {
      "x": -5,
      "y": 43,
      "z": -3,
      "name": "Rock_Basalt"
    },
    {
      "x": -5,
      "y": 44,
      "z": -3,
      "name": "Rock_Basalt"
    },
    {
      "x": -5,
      "y": 45,
      "z": -3,
      "name": "Rock_Basalt"
    },
    {
      "x": -5,
      "y": 46,
      "z": -3,
      "name": "Rock_Basalt"
    },
    {
      "x": -5,
      "y": 47,
      "z": -3,
      "name": "Rock_Basalt"
    },
    {
      "x": -5,
      "y": 48,
      "z": -3,
      "name": "Rock_Basalt"
    },
    {
      "x": -5,
      "y": 49,
      "z": -3,
      "name": "Rock_Basalt"
    },
    {
      "x": -5,
      "y": 50,
      "z": -3,
      "name": "Rock_Basalt"
    },
    {
      "x": -5,
      "y": 51,
      "z": -3,
      "name": "Rock_Basalt"
    },
    {
      "x": -5,
      "y": 25,
      "z": -2,
      "name": "Rock_Basalt"
    },
    {
      "x": -5,
      "y": 26,
      "z": -2,
      "name": "Rock_Basalt"
    },
    {
      "x": -5,
      "y": 27,
      "z": -2,
      "name": "Rock_Basalt"
    },
    {
      "x": -5,
      "y": 28,
      "z": -2,
      "name": "Rock_Basalt"
    },
    {
      "x": -5,
      "y": 30,
      "z": -2,
      "name": "Rock_Basalt"
    },
    {
      "x": -5,
      "y": 31,
      "z": -2,
      "name": "Rock_Basalt"
    },
    {
      "x": -5,
      "y": 32,
      "z": -2,
      "name": "Rock_Basalt"
    },
    {
      "x": -5,
      "y": 33,
      "z": -2,
      "name": "Rock_Basalt"
    },
    {
      "x": -5,
      "y": 34,
      "z": -2,
      "name": "Rock_Basalt"
    },
    {
      "x": -5,
      "y": 35,
      "z": -2,
      "name": "Rock_Basalt"
    },
    {
      "x": -5,
      "y": 36,
      "z": -2,
      "name": "Rock_Basalt"
    },
    {
      "x": -5,
      "y": 37,
      "z": -2,
      "name": "Rock_Basalt"
    },
    {
      "x": -5,
      "y": 38,
      "z": -2,
      "name": "Rock_Basalt"
    },
    {
      "x": -5,
      "y": 39,
      "z": -2,
      "name": "Rock_Basalt"
    },
    {
      "x": -5,
      "y": 40,
      "z": -2,
      "name": "Rock_Basalt"
    },
    {
      "x": -5,
      "y": 41,
      "z": -2,
      "name": "Rock_Basalt"
    },
    {
      "x": -5,
      "y": 42,
      "z": -2,
      "name": "Rock_Basalt"
    },
    {
      "x": -5,
      "y": 43,
      "z": -2,
      "name": "Rock_Basalt"
    },
    {
      "x": -5,
      "y": 44,
      "z": -2,
      "name": "Rock_Basalt"
    },
    {
      "x": -5,
      "y": 45,
      "z": -2,
      "name": "Rock_Basalt"
    },
    {
      "x": -5,
      "y": 46,
      "z": -2,
      "name": "Rock_Basalt"
    },
    {
      "x": -5,
      "y": 47,
      "z": -2,
      "name": "Rock_Basalt"
    },
    {
      "x": -5,
      "y": 48,
      "z": -2,
      "name": "Rock_Basalt"
    },
    {
      "x": -5,
      "y": 49,
      "z": -2,
      "name": "Rock_Basalt"
    },
    {
      "x": -5,
      "y": 50,
      "z": -2,
      "name": "Rock_Basalt"
    },
    {
      "x": -5,
      "y": 51,
      "z": -2,
      "name": "Rock_Basalt"
    },
    {
      "x": -5,
      "y": 24,
      "z": -1,
      "name": "Rock_Basalt"
    },
    {
      "x": -5,
      "y": 25,
      "z": -1,
      "name": "Rock_Basalt"
    },
    {
      "x": -5,
      "y": 26,
      "z": -1,
      "name": "Rock_Basalt"
    },
    {
      "x": -5,
      "y": 27,
      "z": -1,
      "name": "Rock_Basalt"
    },
    {
      "x": -5,
      "y": 28,
      "z": -1,
      "name": "Rock_Basalt"
    },
    {
      "x": -5,
      "y": 30,
      "z": -1,
      "name": "Rock_Basalt"
    },
    {
      "x": -5,
      "y": 31,
      "z": -1,
      "name": "Rock_Basalt"
    },
    {
      "x": -5,
      "y": 32,
      "z": -1,
      "name": "Rock_Basalt"
    },
    {
      "x": -5,
      "y": 33,
      "z": -1,
      "name": "Rock_Basalt"
    },
    {
      "x": -5,
      "y": 34,
      "z": -1,
      "name": "Rock_Basalt"
    },
    {
      "x": -5,
      "y": 35,
      "z": -1,
      "name": "Rock_Basalt"
    },
    {
      "x": -5,
      "y": 36,
      "z": -1,
      "name": "Rock_Basalt"
    },
    {
      "x": -5,
      "y": 37,
      "z": -1,
      "name": "Rock_Basalt"
    },
    {
      "x": -5,
      "y": 38,
      "z": -1,
      "name": "Rock_Basalt"
    },
    {
      "x": -5,
      "y": 39,
      "z": -1,
      "name": "Rock_Basalt"
    },
    {
      "x": -5,
      "y": 40,
      "z": -1,
      "name": "Rock_Basalt"
    },
    {
      "x": -5,
      "y": 41,
      "z": -1,
      "name": "Rock_Basalt"
    },
    {
      "x": -5,
      "y": 42,
      "z": -1,
      "name": "Rock_Basalt"
    },
    {
      "x": -5,
      "y": 43,
      "z": -1,
      "name": "Rock_Basalt"
    },
    {
      "x": -5,
      "y": 44,
      "z": -1,
      "name": "Rock_Basalt"
    },
    {
      "x": -5,
      "y": 45,
      "z": -1,
      "name": "Rock_Basalt"
    },
    {
      "x": -5,
      "y": 46,
      "z": -1,
      "name": "Rock_Basalt"
    },
    {
      "x": -5,
      "y": 47,
      "z": -1,
      "name": "Rock_Basalt"
    },
    {
      "x": -5,
      "y": 48,
      "z": -1,
      "name": "Rock_Basalt"
    },
    {
      "x": -5,
      "y": 49,
      "z": -1,
      "name": "Rock_Basalt"
    },
    {
      "x": -5,
      "y": 50,
      "z": -1,
      "name": "Rock_Basalt"
    },
    {
      "x": -5,
      "y": 51,
      "z": -1,
      "name": "Rock_Basalt"
    },
    {
      "x": -5,
      "y": 25,
      "z": 0,
      "name": "Rock_Basalt"
    },
    {
      "x": -5,
      "y": 26,
      "z": 0,
      "name": "Rock_Basalt"
    },
    {
      "x": -5,
      "y": 27,
      "z": 0,
      "name": "Rock_Basalt"
    },
    {
      "x": -5,
      "y": 28,
      "z": 0,
      "name": "Rock_Basalt"
    },
    {
      "x": -5,
      "y": 31,
      "z": 0,
      "name": "Rock_Basalt"
    },
    {
      "x": -5,
      "y": 32,
      "z": 0,
      "name": "Rock_Basalt"
    },
    {
      "x": -5,
      "y": 33,
      "z": 0,
      "name": "Rock_Basalt"
    },
    {
      "x": -5,
      "y": 34,
      "z": 0,
      "name": "Rock_Basalt"
    },
    {
      "x": -5,
      "y": 35,
      "z": 0,
      "name": "Rock_Basalt"
    },
    {
      "x": -5,
      "y": 36,
      "z": 0,
      "name": "Rock_Basalt"
    },
    {
      "x": -5,
      "y": 37,
      "z": 0,
      "name": "Rock_Basalt"
    },
    {
      "x": -5,
      "y": 38,
      "z": 0,
      "name": "Rock_Basalt"
    },
    {
      "x": -5,
      "y": 39,
      "z": 0,
      "name": "Rock_Basalt"
    },
    {
      "x": -5,
      "y": 40,
      "z": 0,
      "name": "Rock_Basalt"
    },
    {
      "x": -5,
      "y": 41,
      "z": 0,
      "name": "Rock_Basalt"
    },
    {
      "x": -5,
      "y": 42,
      "z": 0,
      "name": "Rock_Basalt"
    },
    {
      "x": -5,
      "y": 43,
      "z": 0,
      "name": "Rock_Basalt"
    },
    {
      "x": -5,
      "y": 44,
      "z": 0,
      "name": "Rock_Basalt"
    },
    {
      "x": -5,
      "y": 45,
      "z": 0,
      "name": "Rock_Basalt"
    },
    {
      "x": -5,
      "y": 46,
      "z": 0,
      "name": "Rock_Basalt"
    },
    {
      "x": -5,
      "y": 47,
      "z": 0,
      "name": "Rock_Basalt"
    },
    {
      "x": -5,
      "y": 48,
      "z": 0,
      "name": "Rock_Basalt"
    },
    {
      "x": -5,
      "y": 49,
      "z": 0,
      "name": "Rock_Basalt"
    },
    {
      "x": -5,
      "y": 50,
      "z": 0,
      "name": "Rock_Basalt"
    },
    {
      "x": -5,
      "y": 51,
      "z": 0,
      "name": "Rock_Basalt"
    },
    {
      "x": -5,
      "y": 32,
      "z": 1,
      "name": "Rock_Basalt"
    },
    {
      "x": -5,
      "y": 33,
      "z": 1,
      "name": "Rock_Basalt"
    },
    {
      "x": -5,
      "y": 34,
      "z": 1,
      "name": "Rock_Basalt"
    },
    {
      "x": -5,
      "y": 35,
      "z": 1,
      "name": "Rock_Basalt"
    },
    {
      "x": -5,
      "y": 36,
      "z": 1,
      "name": "Rock_Basalt"
    },
    {
      "x": -5,
      "y": 37,
      "z": 1,
      "name": "Rock_Basalt"
    },
    {
      "x": -5,
      "y": 38,
      "z": 1,
      "name": "Rock_Basalt"
    },
    {
      "x": -5,
      "y": 39,
      "z": 1,
      "name": "Rock_Basalt"
    },
    {
      "x": -5,
      "y": 40,
      "z": 1,
      "name": "Rock_Basalt"
    },
    {
      "x": -5,
      "y": 41,
      "z": 1,
      "name": "Rock_Basalt"
    },
    {
      "x": -5,
      "y": 42,
      "z": 1,
      "name": "Rock_Basalt"
    },
    {
      "x": -5,
      "y": 43,
      "z": 1,
      "name": "Rock_Basalt"
    },
    {
      "x": -5,
      "y": 44,
      "z": 1,
      "name": "Rock_Basalt"
    },
    {
      "x": -5,
      "y": 45,
      "z": 1,
      "name": "Rock_Basalt"
    },
    {
      "x": -5,
      "y": 46,
      "z": 1,
      "name": "Rock_Basalt"
    },
    {
      "x": -5,
      "y": 47,
      "z": 1,
      "name": "Rock_Basalt"
    },
    {
      "x": -5,
      "y": 48,
      "z": 1,
      "name": "Rock_Basalt"
    },
    {
      "x": -5,
      "y": 49,
      "z": 1,
      "name": "Rock_Basalt"
    },
    {
      "x": -5,
      "y": 50,
      "z": 1,
      "name": "Rock_Basalt"
    },
    {
      "x": -5,
      "y": 51,
      "z": 1,
      "name": "Rock_Basalt"
    },
    {
      "x": -5,
      "y": 34,
      "z": 2,
      "name": "Rock_Basalt"
    },
    {
      "x": -5,
      "y": 35,
      "z": 2,
      "name": "Rock_Basalt"
    },
    {
      "x": -5,
      "y": 36,
      "z": 2,
      "name": "Rock_Basalt"
    },
    {
      "x": -5,
      "y": 37,
      "z": 2,
      "name": "Rock_Basalt"
    },
    {
      "x": -5,
      "y": 38,
      "z": 2,
      "name": "Rock_Basalt"
    },
    {
      "x": -5,
      "y": 39,
      "z": 2,
      "name": "Rock_Basalt"
    },
    {
      "x": -5,
      "y": 40,
      "z": 2,
      "name": "Rock_Basalt"
    },
    {
      "x": -5,
      "y": 41,
      "z": 2,
      "name": "Rock_Basalt"
    },
    {
      "x": -5,
      "y": 42,
      "z": 2,
      "name": "Rock_Basalt"
    },
    {
      "x": -5,
      "y": 43,
      "z": 2,
      "name": "Rock_Basalt"
    },
    {
      "x": -5,
      "y": 44,
      "z": 2,
      "name": "Rock_Basalt"
    },
    {
      "x": -5,
      "y": 45,
      "z": 2,
      "name": "Rock_Basalt"
    },
    {
      "x": -5,
      "y": 46,
      "z": 2,
      "name": "Rock_Basalt"
    },
    {
      "x": -5,
      "y": 47,
      "z": 2,
      "name": "Rock_Basalt"
    },
    {
      "x": -5,
      "y": 48,
      "z": 2,
      "name": "Rock_Basalt"
    },
    {
      "x": -5,
      "y": 49,
      "z": 2,
      "name": "Rock_Basalt"
    },
    {
      "x": -5,
      "y": 50,
      "z": 2,
      "name": "Rock_Basalt"
    },
    {
      "x": -5,
      "y": 51,
      "z": 2,
      "name": "Rock_Basalt"
    },
    {
      "x": -5,
      "y": 37,
      "z": 3,
      "name": "Rock_Basalt"
    },
    {
      "x": -5,
      "y": 38,
      "z": 3,
      "name": "Rock_Basalt"
    },
    {
      "x": -5,
      "y": 39,
      "z": 3,
      "name": "Rock_Basalt"
    },
    {
      "x": -5,
      "y": 40,
      "z": 3,
      "name": "Rock_Basalt"
    },
    {
      "x": -5,
      "y": 41,
      "z": 3,
      "name": "Rock_Basalt"
    },
    {
      "x": -5,
      "y": 42,
      "z": 3,
      "name": "Rock_Basalt"
    },
    {
      "x": -5,
      "y": 43,
      "z": 3,
      "name": "Rock_Basalt"
    },
    {
      "x": -5,
      "y": 44,
      "z": 3,
      "name": "Rock_Basalt"
    },
    {
      "x": -5,
      "y": 45,
      "z": 3,
      "name": "Rock_Basalt"
    },
    {
      "x": -5,
      "y": 46,
      "z": 3,
      "name": "Rock_Basalt"
    },
    {
      "x": -5,
      "y": 47,
      "z": 3,
      "name": "Rock_Basalt"
    },
    {
      "x": -5,
      "y": 48,
      "z": 3,
      "name": "Rock_Basalt"
    },
    {
      "x": -5,
      "y": 49,
      "z": 3,
      "name": "Rock_Basalt"
    },
    {
      "x": -5,
      "y": 50,
      "z": 3,
      "name": "Rock_Basalt"
    },
    {
      "x": -5,
      "y": 40,
      "z": 4,
      "name": "Rock_Basalt"
    },
    {
      "x": -5,
      "y": 41,
      "z": 4,
      "name": "Rock_Basalt"
    },
    {
      "x": -5,
      "y": 42,
      "z": 4,
      "name": "Rock_Basalt"
    },
    {
      "x": -5,
      "y": 43,
      "z": 4,
      "name": "Rock_Basalt"
    },
    {
      "x": -5,
      "y": 44,
      "z": 4,
      "name": "Rock_Basalt"
    },
    {
      "x": -5,
      "y": 45,
      "z": 4,
      "name": "Rock_Basalt"
    },
    {
      "x": -5,
      "y": 46,
      "z": 4,
      "name": "Rock_Basalt"
    },
    {
      "x": -5,
      "y": 47,
      "z": 4,
      "name": "Rock_Basalt"
    },
    {
      "x": -5,
      "y": 48,
      "z": 4,
      "name": "Rock_Basalt"
    },
    {
      "x": -5,
      "y": 49,
      "z": 4,
      "name": "Rock_Basalt"
    },
    {
      "x": -5,
      "y": 44,
      "z": 5,
      "name": "Rock_Basalt"
    },
    {
      "x": -5,
      "y": 46,
      "z": 5,
      "name": "Rock_Basalt"
    },
    {
      "x": -5,
      "y": 47,
      "z": 5,
      "name": "Rock_Basalt"
    },
    {
      "x": -4,
      "y": 40,
      "z": -8,
      "name": "Rock_Basalt"
    },
    {
      "x": -4,
      "y": 41,
      "z": -8,
      "name": "Rock_Basalt"
    },
    {
      "x": -4,
      "y": 42,
      "z": -8,
      "name": "Rock_Basalt"
    },
    {
      "x": -4,
      "y": 44,
      "z": -8,
      "name": "Rock_Basalt"
    },
    {
      "x": -4,
      "y": 45,
      "z": -8,
      "name": "Rock_Basalt"
    },
    {
      "x": -4,
      "y": 48,
      "z": -8,
      "name": "Rock_Basalt"
    },
    {
      "x": -4,
      "y": 49,
      "z": -8,
      "name": "Rock_Basalt"
    },
    {
      "x": -4,
      "y": 35,
      "z": -7,
      "name": "Rock_Basalt"
    },
    {
      "x": -4,
      "y": 36,
      "z": -7,
      "name": "Rock_Basalt"
    },
    {
      "x": -4,
      "y": 40,
      "z": -7,
      "name": "Rock_Basalt"
    },
    {
      "x": -4,
      "y": 41,
      "z": -7,
      "name": "Rock_Basalt"
    },
    {
      "x": -4,
      "y": 42,
      "z": -7,
      "name": "Rock_Basalt"
    },
    {
      "x": -4,
      "y": 43,
      "z": -7,
      "name": "Rock_Crystal_Red_Block",
      "rotation": 4
    },
    {
      "x": -4,
      "y": 44,
      "z": -7,
      "name": "Rock_Basalt"
    },
    {
      "x": -4,
      "y": 45,
      "z": -7,
      "name": "Rock_Crystal_Red_Block",
      "rotation": 5
    },
    {
      "x": -4,
      "y": 46,
      "z": -7,
      "name": "Rock_Crystal_Red_Block"
    },
    {
      "x": -4,
      "y": 47,
      "z": -7,
      "name": "Rock_Crystal_Red_Block"
    },
    {
      "x": -4,
      "y": 48,
      "z": -7,
      "name": "Rock_Basalt"
    },
    {
      "x": -4,
      "y": 49,
      "z": -7,
      "name": "Rock_Basalt"
    },
    {
      "x": -4,
      "y": 50,
      "z": -7,
      "name": "Rock_Basalt"
    },
    {
      "x": -4,
      "y": 31,
      "z": -6,
      "name": "Rock_Basalt"
    },
    {
      "x": -4,
      "y": 32,
      "z": -6,
      "name": "Rock_Basalt"
    },
    {
      "x": -4,
      "y": 33,
      "z": -6,
      "name": "Rock_Basalt"
    },
    {
      "x": -4,
      "y": 34,
      "z": -6,
      "name": "Rock_Basalt"
    },
    {
      "x": -4,
      "y": 35,
      "z": -6,
      "name": "Rock_Basalt"
    },
    {
      "x": -4,
      "y": 36,
      "z": -6,
      "name": "Rock_Basalt"
    },
    {
      "x": -4,
      "y": 37,
      "z": -6,
      "name": "Rock_Crystal_Red_Block"
    },
    {
      "x": -4,
      "y": 38,
      "z": -6,
      "name": "Rock_Crystal_Red_Block"
    },
    {
      "x": -4,
      "y": 39,
      "z": -6,
      "name": "Rock_Crystal_Red_Block"
    },
    {
      "x": -4,
      "y": 40,
      "z": -6,
      "name": "Rock_Basalt"
    },
    {
      "x": -4,
      "y": 41,
      "z": -6,
      "name": "Rock_Basalt"
    },
    {
      "x": -4,
      "y": 42,
      "z": -6,
      "name": "Rock_Basalt"
    },
    {
      "x": -4,
      "y": 43,
      "z": -6,
      "name": "Rock_Basalt"
    },
    {
      "x": -4,
      "y": 44,
      "z": -6,
      "name": "Rock_Basalt"
    },
    {
      "x": -4,
      "y": 45,
      "z": -6,
      "name": "Rock_Basalt"
    },
    {
      "x": -4,
      "y": 46,
      "z": -6,
      "name": "Rock_Crystal_Red_Block"
    },
    {
      "x": -4,
      "y": 47,
      "z": -6,
      "name": "Rock_Basalt"
    },
    {
      "x": -4,
      "y": 48,
      "z": -6,
      "name": "Rock_Basalt"
    },
    {
      "x": -4,
      "y": 49,
      "z": -6,
      "name": "Rock_Basalt"
    },
    {
      "x": -4,
      "y": 50,
      "z": -6,
      "name": "Rock_Basalt"
    },
    {
      "x": -4,
      "y": 51,
      "z": -6,
      "name": "Rock_Basalt"
    },
    {
      "x": -4,
      "y": 28,
      "z": -5,
      "name": "Rock_Basalt"
    },
    {
      "x": -4,
      "y": 29,
      "z": -5,
      "name": "Rock_Basalt"
    },
    {
      "x": -4,
      "y": 30,
      "z": -5,
      "name": "Rock_Basalt"
    },
    {
      "x": -4,
      "y": 31,
      "z": -5,
      "name": "Rock_Basalt"
    },
    {
      "x": -4,
      "y": 32,
      "z": -5,
      "name": "Rock_Basalt"
    },
    {
      "x": -4,
      "y": 33,
      "z": -5,
      "name": "Rock_Basalt"
    },
    {
      "x": -4,
      "y": 34,
      "z": -5,
      "name": "Rock_Basalt"
    },
    {
      "x": -4,
      "y": 35,
      "z": -5,
      "name": "Rock_Basalt"
    },
    {
      "x": -4,
      "y": 36,
      "z": -5,
      "name": "Rock_Basalt"
    },
    {
      "x": -4,
      "y": 37,
      "z": -5,
      "name": "Rock_Basalt"
    },
    {
      "x": -4,
      "y": 38,
      "z": -5,
      "name": "Rock_Basalt"
    },
    {
      "x": -4,
      "y": 39,
      "z": -5,
      "name": "Rock_Basalt"
    },
    {
      "x": -4,
      "y": 40,
      "z": -5,
      "name": "Rock_Basalt"
    },
    {
      "x": -4,
      "y": 41,
      "z": -5,
      "name": "Rock_Basalt"
    },
    {
      "x": -4,
      "y": 42,
      "z": -5,
      "name": "Rock_Basalt"
    },
    {
      "x": -4,
      "y": 43,
      "z": -5,
      "name": "Rock_Basalt"
    },
    {
      "x": -4,
      "y": 44,
      "z": -5,
      "name": "Rock_Basalt"
    },
    {
      "x": -4,
      "y": 45,
      "z": -5,
      "name": "Rock_Basalt"
    },
    {
      "x": -4,
      "y": 46,
      "z": -5,
      "name": "Rock_Basalt"
    },
    {
      "x": -4,
      "y": 47,
      "z": -5,
      "name": "Rock_Basalt"
    },
    {
      "x": -4,
      "y": 48,
      "z": -5,
      "name": "Rock_Basalt"
    },
    {
      "x": -4,
      "y": 49,
      "z": -5,
      "name": "Rock_Basalt"
    },
    {
      "x": -4,
      "y": 50,
      "z": -5,
      "name": "Rock_Basalt"
    },
    {
      "x": -4,
      "y": 51,
      "z": -5,
      "name": "Rock_Basalt"
    },
    {
      "x": -4,
      "y": 26,
      "z": -4,
      "name": "Rock_Basalt"
    },
    {
      "x": -4,
      "y": 27,
      "z": -4,
      "name": "Rock_Basalt"
    },
    {
      "x": -4,
      "y": 28,
      "z": -4,
      "name": "Rock_Basalt"
    },
    {
      "x": -4,
      "y": 29,
      "z": -4,
      "name": "Rock_Basalt"
    },
    {
      "x": -4,
      "y": 30,
      "z": -4,
      "name": "Rock_Basalt"
    },
    {
      "x": -4,
      "y": 31,
      "z": -4,
      "name": "Rock_Basalt"
    },
    {
      "x": -4,
      "y": 32,
      "z": -4,
      "name": "Rock_Basalt"
    },
    {
      "x": -4,
      "y": 33,
      "z": -4,
      "name": "Rock_Basalt"
    },
    {
      "x": -4,
      "y": 34,
      "z": -4,
      "name": "Rock_Basalt"
    },
    {
      "x": -4,
      "y": 35,
      "z": -4,
      "name": "Rock_Basalt"
    },
    {
      "x": -4,
      "y": 36,
      "z": -4,
      "name": "Rock_Basalt"
    },
    {
      "x": -4,
      "y": 37,
      "z": -4,
      "name": "Rock_Basalt"
    },
    {
      "x": -4,
      "y": 38,
      "z": -4,
      "name": "Rock_Basalt"
    },
    {
      "x": -4,
      "y": 39,
      "z": -4,
      "name": "Rock_Basalt"
    },
    {
      "x": -4,
      "y": 40,
      "z": -4,
      "name": "Rock_Basalt"
    },
    {
      "x": -4,
      "y": 41,
      "z": -4,
      "name": "Rock_Basalt"
    },
    {
      "x": -4,
      "y": 42,
      "z": -4,
      "name": "Rock_Basalt"
    },
    {
      "x": -4,
      "y": 43,
      "z": -4,
      "name": "Rock_Basalt"
    },
    {
      "x": -4,
      "y": 44,
      "z": -4,
      "name": "Rock_Basalt"
    },
    {
      "x": -4,
      "y": 45,
      "z": -4,
      "name": "Rock_Basalt"
    },
    {
      "x": -4,
      "y": 46,
      "z": -4,
      "name": "Rock_Basalt"
    },
    {
      "x": -4,
      "y": 47,
      "z": -4,
      "name": "Rock_Basalt"
    },
    {
      "x": -4,
      "y": 48,
      "z": -4,
      "name": "Rock_Basalt"
    },
    {
      "x": -4,
      "y": 49,
      "z": -4,
      "name": "Rock_Basalt"
    },
    {
      "x": -4,
      "y": 50,
      "z": -4,
      "name": "Rock_Basalt"
    },
    {
      "x": -4,
      "y": 51,
      "z": -4,
      "name": "Rock_Basalt"
    },
    {
      "x": -4,
      "y": 22,
      "z": -3,
      "name": "Rock_Basalt"
    },
    {
      "x": -4,
      "y": 23,
      "z": -3,
      "name": "Rock_Basalt"
    },
    {
      "x": -4,
      "y": 24,
      "z": -3,
      "name": "Rock_Basalt"
    },
    {
      "x": -4,
      "y": 25,
      "z": -3,
      "name": "Rock_Basalt"
    },
    {
      "x": -4,
      "y": 26,
      "z": -3,
      "name": "Rock_Basalt"
    },
    {
      "x": -4,
      "y": 27,
      "z": -3,
      "name": "Rock_Basalt"
    },
    {
      "x": -4,
      "y": 28,
      "z": -3,
      "name": "Rock_Crystal_Red_Block",
      "rotation": 5
    },
    {
      "x": -4,
      "y": 29,
      "z": -3,
      "name": "Rock_Crystal_Red_Block",
      "rotation": 5
    },
    {
      "x": -4,
      "y": 30,
      "z": -3,
      "name": "Rock_Basalt"
    },
    {
      "x": -4,
      "y": 31,
      "z": -3,
      "name": "Rock_Basalt"
    },
    {
      "x": -4,
      "y": 32,
      "z": -3,
      "name": "Rock_Basalt"
    },
    {
      "x": -4,
      "y": 33,
      "z": -3,
      "name": "Rock_Basalt"
    },
    {
      "x": -4,
      "y": 34,
      "z": -3,
      "name": "Rock_Basalt"
    },
    {
      "x": -4,
      "y": 35,
      "z": -3,
      "name": "Rock_Basalt"
    },
    {
      "x": -4,
      "y": 36,
      "z": -3,
      "name": "Rock_Basalt"
    },
    {
      "x": -4,
      "y": 37,
      "z": -3,
      "name": "Rock_Basalt"
    },
    {
      "x": -4,
      "y": 38,
      "z": -3,
      "name": "Rock_Basalt"
    },
    {
      "x": -4,
      "y": 39,
      "z": -3,
      "name": "Rock_Basalt"
    },
    {
      "x": -4,
      "y": 40,
      "z": -3,
      "name": "Rock_Basalt"
    },
    {
      "x": -4,
      "y": 41,
      "z": -3,
      "name": "Rock_Basalt"
    },
    {
      "x": -4,
      "y": 42,
      "z": -3,
      "name": "Rock_Basalt"
    },
    {
      "x": -4,
      "y": 43,
      "z": -3,
      "name": "Rock_Basalt"
    },
    {
      "x": -4,
      "y": 44,
      "z": -3,
      "name": "Rock_Basalt"
    },
    {
      "x": -4,
      "y": 45,
      "z": -3,
      "name": "Rock_Basalt"
    },
    {
      "x": -4,
      "y": 46,
      "z": -3,
      "name": "Rock_Basalt"
    },
    {
      "x": -4,
      "y": 47,
      "z": -3,
      "name": "Rock_Basalt"
    },
    {
      "x": -4,
      "y": 48,
      "z": -3,
      "name": "Rock_Basalt"
    },
    {
      "x": -4,
      "y": 49,
      "z": -3,
      "name": "Rock_Basalt"
    },
    {
      "x": -4,
      "y": 50,
      "z": -3,
      "name": "Rock_Basalt"
    },
    {
      "x": -4,
      "y": 51,
      "z": -3,
      "name": "Rock_Basalt"
    },
    {
      "x": -4,
      "y": 52,
      "z": -3,
      "name": "Rock_Basalt"
    },
    {
      "x": -4,
      "y": 20,
      "z": -2,
      "name": "Rock_Basalt"
    },
    {
      "x": -4,
      "y": 21,
      "z": -2,
      "name": "Rock_Basalt"
    },
    {
      "x": -4,
      "y": 22,
      "z": -2,
      "name": "Rock_Basalt"
    },
    {
      "x": -4,
      "y": 23,
      "z": -2,
      "name": "Rock_Basalt"
    },
    {
      "x": -4,
      "y": 24,
      "z": -2,
      "name": "Rock_Basalt"
    },
    {
      "x": -4,
      "y": 25,
      "z": -2,
      "name": "Rock_Basalt"
    },
    {
      "x": -4,
      "y": 26,
      "z": -2,
      "name": "Rock_Basalt"
    },
    {
      "x": -4,
      "y": 27,
      "z": -2,
      "name": "Rock_Basalt"
    },
    {
      "x": -4,
      "y": 28,
      "z": -2,
      "name": "Rock_Basalt"
    },
    {
      "x": -4,
      "y": 29,
      "z": -2,
      "name": "Rock_Crystal_Red_Block",
      "rotation": 5
    },
    {
      "x": -4,
      "y": 30,
      "z": -2,
      "name": "Rock_Basalt"
    },
    {
      "x": -4,
      "y": 31,
      "z": -2,
      "name": "Rock_Basalt"
    },
    {
      "x": -4,
      "y": 32,
      "z": -2,
      "name": "Rock_Basalt"
    },
    {
      "x": -4,
      "y": 33,
      "z": -2,
      "name": "Rock_Basalt"
    },
    {
      "x": -4,
      "y": 34,
      "z": -2,
      "name": "Rock_Basalt"
    },
    {
      "x": -4,
      "y": 35,
      "z": -2,
      "name": "Rock_Basalt"
    },
    {
      "x": -4,
      "y": 36,
      "z": -2,
      "name": "Rock_Basalt"
    },
    {
      "x": -4,
      "y": 37,
      "z": -2,
      "name": "Rock_Basalt"
    },
    {
      "x": -4,
      "y": 38,
      "z": -2,
      "name": "Rock_Basalt"
    },
    {
      "x": -4,
      "y": 39,
      "z": -2,
      "name": "Rock_Basalt"
    },
    {
      "x": -4,
      "y": 40,
      "z": -2,
      "name": "Rock_Basalt"
    },
    {
      "x": -4,
      "y": 41,
      "z": -2,
      "name": "Rock_Basalt"
    },
    {
      "x": -4,
      "y": 42,
      "z": -2,
      "name": "Rock_Basalt"
    },
    {
      "x": -4,
      "y": 43,
      "z": -2,
      "name": "Rock_Basalt"
    },
    {
      "x": -4,
      "y": 44,
      "z": -2,
      "name": "Rock_Basalt"
    },
    {
      "x": -4,
      "y": 45,
      "z": -2,
      "name": "Rock_Basalt"
    },
    {
      "x": -4,
      "y": 46,
      "z": -2,
      "name": "Rock_Basalt"
    },
    {
      "x": -4,
      "y": 47,
      "z": -2,
      "name": "Rock_Basalt"
    },
    {
      "x": -4,
      "y": 48,
      "z": -2,
      "name": "Rock_Basalt"
    },
    {
      "x": -4,
      "y": 49,
      "z": -2,
      "name": "Rock_Basalt"
    },
    {
      "x": -4,
      "y": 50,
      "z": -2,
      "name": "Rock_Basalt"
    },
    {
      "x": -4,
      "y": 51,
      "z": -2,
      "name": "Rock_Basalt"
    },
    {
      "x": -4,
      "y": 52,
      "z": -2,
      "name": "Rock_Basalt"
    },
    {
      "x": -4,
      "y": 18,
      "z": -1,
      "name": "Rock_Basalt"
    },
    {
      "x": -4,
      "y": 19,
      "z": -1,
      "name": "Rock_Basalt"
    },
    {
      "x": -4,
      "y": 20,
      "z": -1,
      "name": "Rock_Basalt"
    },
    {
      "x": -4,
      "y": 21,
      "z": -1,
      "name": "Rock_Basalt"
    },
    {
      "x": -4,
      "y": 22,
      "z": -1,
      "name": "Rock_Basalt"
    },
    {
      "x": -4,
      "y": 23,
      "z": -1,
      "name": "Rock_Basalt"
    },
    {
      "x": -4,
      "y": 24,
      "z": -1,
      "name": "Rock_Basalt"
    },
    {
      "x": -4,
      "y": 25,
      "z": -1,
      "name": "Rock_Basalt"
    },
    {
      "x": -4,
      "y": 26,
      "z": -1,
      "name": "Rock_Basalt"
    },
    {
      "x": -4,
      "y": 27,
      "z": -1,
      "name": "Rock_Basalt"
    },
    {
      "x": -4,
      "y": 28,
      "z": -1,
      "name": "Rock_Basalt"
    },
    {
      "x": -4,
      "y": 29,
      "z": -1,
      "name": "Rock_Crystal_Red_Block",
      "rotation": 5
    },
    {
      "x": -4,
      "y": 30,
      "z": -1,
      "name": "Rock_Crystal_Red_Block"
    },
    {
      "x": -4,
      "y": 31,
      "z": -1,
      "name": "Rock_Basalt"
    },
    {
      "x": -4,
      "y": 32,
      "z": -1,
      "name": "Rock_Basalt"
    },
    {
      "x": -4,
      "y": 33,
      "z": -1,
      "name": "Rock_Basalt"
    },
    {
      "x": -4,
      "y": 34,
      "z": -1,
      "name": "Rock_Basalt"
    },
    {
      "x": -4,
      "y": 35,
      "z": -1,
      "name": "Rock_Basalt"
    },
    {
      "x": -4,
      "y": 36,
      "z": -1,
      "name": "Rock_Basalt"
    },
    {
      "x": -4,
      "y": 37,
      "z": -1,
      "name": "Rock_Basalt"
    },
    {
      "x": -4,
      "y": 38,
      "z": -1,
      "name": "Rock_Basalt"
    },
    {
      "x": -4,
      "y": 39,
      "z": -1,
      "name": "Rock_Basalt"
    },
    {
      "x": -4,
      "y": 40,
      "z": -1,
      "name": "Rock_Basalt"
    },
    {
      "x": -4,
      "y": 41,
      "z": -1,
      "name": "Rock_Basalt"
    },
    {
      "x": -4,
      "y": 42,
      "z": -1,
      "name": "Rock_Basalt"
    },
    {
      "x": -4,
      "y": 43,
      "z": -1,
      "name": "Rock_Basalt"
    },
    {
      "x": -4,
      "y": 44,
      "z": -1,
      "name": "Rock_Basalt"
    },
    {
      "x": -4,
      "y": 45,
      "z": -1,
      "name": "Rock_Basalt"
    },
    {
      "x": -4,
      "y": 46,
      "z": -1,
      "name": "Rock_Basalt"
    },
    {
      "x": -4,
      "y": 47,
      "z": -1,
      "name": "Rock_Basalt"
    },
    {
      "x": -4,
      "y": 48,
      "z": -1,
      "name": "Rock_Basalt"
    },
    {
      "x": -4,
      "y": 49,
      "z": -1,
      "name": "Rock_Basalt"
    },
    {
      "x": -4,
      "y": 50,
      "z": -1,
      "name": "Rock_Basalt"
    },
    {
      "x": -4,
      "y": 51,
      "z": -1,
      "name": "Rock_Basalt"
    },
    {
      "x": -4,
      "y": 52,
      "z": -1,
      "name": "Rock_Basalt"
    },
    {
      "x": -4,
      "y": 19,
      "z": 0,
      "name": "Rock_Basalt"
    },
    {
      "x": -4,
      "y": 20,
      "z": 0,
      "name": "Rock_Basalt"
    },
    {
      "x": -4,
      "y": 21,
      "z": 0,
      "name": "Rock_Basalt"
    },
    {
      "x": -4,
      "y": 22,
      "z": 0,
      "name": "Rock_Basalt"
    },
    {
      "x": -4,
      "y": 23,
      "z": 0,
      "name": "Rock_Basalt"
    },
    {
      "x": -4,
      "y": 24,
      "z": 0,
      "name": "Rock_Basalt"
    },
    {
      "x": -4,
      "y": 25,
      "z": 0,
      "name": "Rock_Basalt"
    },
    {
      "x": -4,
      "y": 26,
      "z": 0,
      "name": "Rock_Basalt"
    },
    {
      "x": -4,
      "y": 27,
      "z": 0,
      "name": "Rock_Basalt"
    },
    {
      "x": -4,
      "y": 28,
      "z": 0,
      "name": "Rock_Basalt"
    },
    {
      "x": -4,
      "y": 29,
      "z": 0,
      "name": "Rock_Crystal_Red_Block"
    },
    {
      "x": -4,
      "y": 30,
      "z": 0,
      "name": "Rock_Crystal_Red_Block"
    },
    {
      "x": -4,
      "y": 31,
      "z": 0,
      "name": "Rock_Crystal_Red_Block"
    },
    {
      "x": -4,
      "y": 32,
      "z": 0,
      "name": "Rock_Basalt"
    },
    {
      "x": -4,
      "y": 33,
      "z": 0,
      "name": "Rock_Basalt"
    },
    {
      "x": -4,
      "y": 34,
      "z": 0,
      "name": "Rock_Basalt"
    },
    {
      "x": -4,
      "y": 35,
      "z": 0,
      "name": "Rock_Basalt"
    },
    {
      "x": -4,
      "y": 36,
      "z": 0,
      "name": "Rock_Basalt"
    },
    {
      "x": -4,
      "y": 37,
      "z": 0,
      "name": "Rock_Basalt"
    },
    {
      "x": -4,
      "y": 38,
      "z": 0,
      "name": "Rock_Basalt"
    },
    {
      "x": -4,
      "y": 39,
      "z": 0,
      "name": "Rock_Basalt"
    },
    {
      "x": -4,
      "y": 40,
      "z": 0,
      "name": "Rock_Basalt"
    },
    {
      "x": -4,
      "y": 41,
      "z": 0,
      "name": "Rock_Basalt"
    },
    {
      "x": -4,
      "y": 42,
      "z": 0,
      "name": "Rock_Basalt"
    },
    {
      "x": -4,
      "y": 43,
      "z": 0,
      "name": "Rock_Basalt"
    },
    {
      "x": -4,
      "y": 44,
      "z": 0,
      "name": "Rock_Basalt"
    },
    {
      "x": -4,
      "y": 45,
      "z": 0,
      "name": "Rock_Basalt"
    },
    {
      "x": -4,
      "y": 46,
      "z": 0,
      "name": "Rock_Basalt"
    },
    {
      "x": -4,
      "y": 47,
      "z": 0,
      "name": "Rock_Basalt"
    },
    {
      "x": -4,
      "y": 48,
      "z": 0,
      "name": "Rock_Basalt"
    },
    {
      "x": -4,
      "y": 49,
      "z": 0,
      "name": "Rock_Basalt"
    },
    {
      "x": -4,
      "y": 50,
      "z": 0,
      "name": "Rock_Basalt"
    },
    {
      "x": -4,
      "y": 51,
      "z": 0,
      "name": "Rock_Basalt"
    },
    {
      "x": -4,
      "y": 52,
      "z": 0,
      "name": "Rock_Basalt"
    },
    {
      "x": -4,
      "y": 22,
      "z": 1,
      "name": "Rock_Basalt"
    },
    {
      "x": -4,
      "y": 23,
      "z": 1,
      "name": "Rock_Basalt"
    },
    {
      "x": -4,
      "y": 24,
      "z": 1,
      "name": "Rock_Basalt"
    },
    {
      "x": -4,
      "y": 25,
      "z": 1,
      "name": "Rock_Basalt"
    },
    {
      "x": -4,
      "y": 26,
      "z": 1,
      "name": "Rock_Basalt"
    },
    {
      "x": -4,
      "y": 27,
      "z": 1,
      "name": "Rock_Basalt"
    },
    {
      "x": -4,
      "y": 29,
      "z": 1,
      "name": "Rock_Crystal_Red_Block"
    },
    {
      "x": -4,
      "y": 30,
      "z": 1,
      "name": "Rock_Crystal_Red_Block"
    },
    {
      "x": -4,
      "y": 31,
      "z": 1,
      "name": "Rock_Basalt"
    },
    {
      "x": -4,
      "y": 32,
      "z": 1,
      "name": "Rock_Basalt"
    },
    {
      "x": -4,
      "y": 33,
      "z": 1,
      "name": "Rock_Basalt"
    },
    {
      "x": -4,
      "y": 34,
      "z": 1,
      "name": "Rock_Basalt"
    },
    {
      "x": -4,
      "y": 35,
      "z": 1,
      "name": "Rock_Basalt"
    },
    {
      "x": -4,
      "y": 36,
      "z": 1,
      "name": "Rock_Basalt"
    },
    {
      "x": -4,
      "y": 37,
      "z": 1,
      "name": "Rock_Basalt"
    },
    {
      "x": -4,
      "y": 38,
      "z": 1,
      "name": "Rock_Basalt"
    },
    {
      "x": -4,
      "y": 39,
      "z": 1,
      "name": "Rock_Basalt"
    },
    {
      "x": -4,
      "y": 40,
      "z": 1,
      "name": "Rock_Basalt"
    },
    {
      "x": -4,
      "y": 41,
      "z": 1,
      "name": "Rock_Basalt"
    },
    {
      "x": -4,
      "y": 42,
      "z": 1,
      "name": "Rock_Basalt"
    },
    {
      "x": -4,
      "y": 43,
      "z": 1,
      "name": "Rock_Basalt"
    },
    {
      "x": -4,
      "y": 44,
      "z": 1,
      "name": "Rock_Basalt"
    },
    {
      "x": -4,
      "y": 45,
      "z": 1,
      "name": "Rock_Basalt"
    },
    {
      "x": -4,
      "y": 46,
      "z": 1,
      "name": "Rock_Basalt"
    },
    {
      "x": -4,
      "y": 47,
      "z": 1,
      "name": "Rock_Basalt"
    },
    {
      "x": -4,
      "y": 48,
      "z": 1,
      "name": "Rock_Basalt"
    },
    {
      "x": -4,
      "y": 49,
      "z": 1,
      "name": "Rock_Basalt"
    },
    {
      "x": -4,
      "y": 50,
      "z": 1,
      "name": "Rock_Basalt"
    },
    {
      "x": -4,
      "y": 51,
      "z": 1,
      "name": "Rock_Basalt"
    },
    {
      "x": -4,
      "y": 52,
      "z": 1,
      "name": "Rock_Basalt"
    },
    {
      "x": -4,
      "y": 22,
      "z": 2,
      "name": "Rock_Basalt"
    },
    {
      "x": -4,
      "y": 23,
      "z": 2,
      "name": "Rock_Basalt"
    },
    {
      "x": -4,
      "y": 24,
      "z": 2,
      "name": "Rock_Basalt"
    },
    {
      "x": -4,
      "y": 25,
      "z": 2,
      "name": "Rock_Basalt"
    },
    {
      "x": -4,
      "y": 26,
      "z": 2,
      "name": "Rock_Basalt"
    },
    {
      "x": -4,
      "y": 30,
      "z": 2,
      "name": "Rock_Basalt"
    },
    {
      "x": -4,
      "y": 31,
      "z": 2,
      "name": "Rock_Basalt"
    },
    {
      "x": -4,
      "y": 32,
      "z": 2,
      "name": "Rock_Basalt"
    },
    {
      "x": -4,
      "y": 33,
      "z": 2,
      "name": "Rock_Basalt"
    },
    {
      "x": -4,
      "y": 34,
      "z": 2,
      "name": "Rock_Basalt"
    },
    {
      "x": -4,
      "y": 35,
      "z": 2,
      "name": "Rock_Basalt"
    },
    {
      "x": -4,
      "y": 36,
      "z": 2,
      "name": "Rock_Basalt"
    },
    {
      "x": -4,
      "y": 37,
      "z": 2,
      "name": "Rock_Basalt"
    },
    {
      "x": -4,
      "y": 38,
      "z": 2,
      "name": "Rock_Basalt"
    },
    {
      "x": -4,
      "y": 39,
      "z": 2,
      "name": "Rock_Basalt"
    },
    {
      "x": -4,
      "y": 40,
      "z": 2,
      "name": "Rock_Basalt"
    },
    {
      "x": -4,
      "y": 41,
      "z": 2,
      "name": "Rock_Basalt"
    },
    {
      "x": -4,
      "y": 42,
      "z": 2,
      "name": "Rock_Basalt"
    },
    {
      "x": -4,
      "y": 43,
      "z": 2,
      "name": "Rock_Basalt"
    },
    {
      "x": -4,
      "y": 44,
      "z": 2,
      "name": "Rock_Basalt"
    },
    {
      "x": -4,
      "y": 45,
      "z": 2,
      "name": "Rock_Basalt"
    },
    {
      "x": -4,
      "y": 46,
      "z": 2,
      "name": "Rock_Basalt"
    },
    {
      "x": -4,
      "y": 47,
      "z": 2,
      "name": "Rock_Basalt"
    },
    {
      "x": -4,
      "y": 48,
      "z": 2,
      "name": "Rock_Basalt"
    },
    {
      "x": -4,
      "y": 49,
      "z": 2,
      "name": "Rock_Basalt"
    },
    {
      "x": -4,
      "y": 50,
      "z": 2,
      "name": "Rock_Basalt"
    },
    {
      "x": -4,
      "y": 51,
      "z": 2,
      "name": "Rock_Basalt"
    },
    {
      "x": -4,
      "y": 52,
      "z": 2,
      "name": "Rock_Basalt"
    },
    {
      "x": -4,
      "y": 33,
      "z": 3,
      "name": "Rock_Basalt"
    },
    {
      "x": -4,
      "y": 34,
      "z": 3,
      "name": "Rock_Basalt"
    },
    {
      "x": -4,
      "y": 35,
      "z": 3,
      "name": "Rock_Basalt"
    },
    {
      "x": -4,
      "y": 36,
      "z": 3,
      "name": "Rock_Basalt"
    },
    {
      "x": -4,
      "y": 37,
      "z": 3,
      "name": "Rock_Basalt"
    },
    {
      "x": -4,
      "y": 38,
      "z": 3,
      "name": "Rock_Basalt"
    },
    {
      "x": -4,
      "y": 39,
      "z": 3,
      "name": "Rock_Basalt"
    },
    {
      "x": -4,
      "y": 40,
      "z": 3,
      "name": "Rock_Basalt"
    },
    {
      "x": -4,
      "y": 41,
      "z": 3,
      "name": "Rock_Basalt"
    },
    {
      "x": -4,
      "y": 42,
      "z": 3,
      "name": "Rock_Basalt"
    },
    {
      "x": -4,
      "y": 43,
      "z": 3,
      "name": "Rock_Basalt"
    },
    {
      "x": -4,
      "y": 44,
      "z": 3,
      "name": "Rock_Basalt"
    },
    {
      "x": -4,
      "y": 45,
      "z": 3,
      "name": "Rock_Basalt"
    },
    {
      "x": -4,
      "y": 46,
      "z": 3,
      "name": "Rock_Basalt"
    },
    {
      "x": -4,
      "y": 47,
      "z": 3,
      "name": "Rock_Basalt"
    },
    {
      "x": -4,
      "y": 48,
      "z": 3,
      "name": "Rock_Basalt"
    },
    {
      "x": -4,
      "y": 49,
      "z": 3,
      "name": "Rock_Basalt"
    },
    {
      "x": -4,
      "y": 50,
      "z": 3,
      "name": "Rock_Basalt"
    },
    {
      "x": -4,
      "y": 51,
      "z": 3,
      "name": "Rock_Basalt"
    },
    {
      "x": -4,
      "y": 37,
      "z": 4,
      "name": "Rock_Basalt"
    },
    {
      "x": -4,
      "y": 38,
      "z": 4,
      "name": "Rock_Basalt"
    },
    {
      "x": -4,
      "y": 39,
      "z": 4,
      "name": "Rock_Basalt"
    },
    {
      "x": -4,
      "y": 40,
      "z": 4,
      "name": "Rock_Basalt"
    },
    {
      "x": -4,
      "y": 41,
      "z": 4,
      "name": "Rock_Basalt"
    },
    {
      "x": -4,
      "y": 42,
      "z": 4,
      "name": "Rock_Basalt"
    },
    {
      "x": -4,
      "y": 43,
      "z": 4,
      "name": "Rock_Basalt"
    },
    {
      "x": -4,
      "y": 44,
      "z": 4,
      "name": "Rock_Basalt"
    },
    {
      "x": -4,
      "y": 45,
      "z": 4,
      "name": "Rock_Basalt"
    },
    {
      "x": -4,
      "y": 46,
      "z": 4,
      "name": "Rock_Basalt"
    },
    {
      "x": -4,
      "y": 47,
      "z": 4,
      "name": "Rock_Basalt"
    },
    {
      "x": -4,
      "y": 48,
      "z": 4,
      "name": "Rock_Basalt"
    },
    {
      "x": -4,
      "y": 49,
      "z": 4,
      "name": "Rock_Basalt"
    },
    {
      "x": -4,
      "y": 50,
      "z": 4,
      "name": "Rock_Basalt"
    },
    {
      "x": -4,
      "y": 41,
      "z": 5,
      "name": "Rock_Basalt"
    },
    {
      "x": -4,
      "y": 42,
      "z": 5,
      "name": "Rock_Basalt"
    },
    {
      "x": -4,
      "y": 43,
      "z": 5,
      "name": "Rock_Basalt"
    },
    {
      "x": -4,
      "y": 44,
      "z": 5,
      "name": "Rock_Basalt"
    },
    {
      "x": -4,
      "y": 45,
      "z": 5,
      "name": "Rock_Basalt"
    },
    {
      "x": -4,
      "y": 46,
      "z": 5,
      "name": "Rock_Basalt"
    },
    {
      "x": -4,
      "y": 47,
      "z": 5,
      "name": "Rock_Basalt"
    },
    {
      "x": -4,
      "y": 48,
      "z": 5,
      "name": "Rock_Basalt"
    },
    {
      "x": -4,
      "y": 49,
      "z": 5,
      "name": "Rock_Basalt"
    },
    {
      "x": -3,
      "y": 37,
      "z": -8,
      "name": "Rock_Basalt"
    },
    {
      "x": -3,
      "y": 38,
      "z": -8,
      "name": "Rock_Basalt"
    },
    {
      "x": -3,
      "y": 44,
      "z": -8,
      "name": "Rock_Basalt"
    },
    {
      "x": -3,
      "y": 45,
      "z": -8,
      "name": "Rock_Basalt"
    },
    {
      "x": -3,
      "y": 46,
      "z": -8,
      "name": "Rock_Basalt"
    },
    {
      "x": -3,
      "y": 47,
      "z": -8,
      "name": "Rock_Basalt"
    },
    {
      "x": -3,
      "y": 48,
      "z": -8,
      "name": "Rock_Basalt"
    },
    {
      "x": -3,
      "y": 49,
      "z": -8,
      "name": "Rock_Basalt"
    },
    {
      "x": -3,
      "y": 50,
      "z": -8,
      "name": "Rock_Basalt"
    },
    {
      "x": -3,
      "y": 51,
      "z": -8,
      "name": "Rock_Basalt"
    },
    {
      "x": -3,
      "y": 32,
      "z": -7,
      "name": "Rock_Basalt"
    },
    {
      "x": -3,
      "y": 33,
      "z": -7,
      "name": "Rock_Basalt"
    },
    {
      "x": -3,
      "y": 34,
      "z": -7,
      "name": "Rock_Basalt"
    },
    {
      "x": -3,
      "y": 35,
      "z": -7,
      "name": "Rock_Basalt"
    },
    {
      "x": -3,
      "y": 36,
      "z": -7,
      "name": "Rock_Basalt"
    },
    {
      "x": -3,
      "y": 37,
      "z": -7,
      "name": "Rock_Basalt"
    },
    {
      "x": -3,
      "y": 38,
      "z": -7,
      "name": "Rock_Basalt"
    },
    {
      "x": -3,
      "y": 39,
      "z": -7,
      "name": "Rock_Crystal_Red_Block",
      "rotation": 4
    },
    {
      "x": -3,
      "y": 40,
      "z": -7,
      "name": "Rock_Crystal_Red_Block",
      "rotation": 4
    },
    {
      "x": -3,
      "y": 41,
      "z": -7,
      "name": "Rock_Crystal_Red_Block",
      "rotation": 4
    },
    {
      "x": -3,
      "y": 42,
      "z": -7,
      "name": "Rock_Crystal_Red_Block",
      "rotation": 4
    },
    {
      "x": -3,
      "y": 43,
      "z": -7,
      "name": "Rock_Crystal_Red_Block",
      "rotation": 4
    },
    {
      "x": -3,
      "y": 44,
      "z": -7,
      "name": "Rock_Basalt"
    },
    {
      "x": -3,
      "y": 45,
      "z": -7,
      "name": "Rock_Basalt"
    },
    {
      "x": -3,
      "y": 46,
      "z": -7,
      "name": "Rock_Crystal_Red_Block"
    },
    {
      "x": -3,
      "y": 47,
      "z": -7,
      "name": "Rock_Basalt"
    },
    {
      "x": -3,
      "y": 48,
      "z": -7,
      "name": "Rock_Basalt"
    },
    {
      "x": -3,
      "y": 49,
      "z": -7,
      "name": "Rock_Basalt"
    },
    {
      "x": -3,
      "y": 50,
      "z": -7,
      "name": "Rock_Basalt"
    },
    {
      "x": -3,
      "y": 51,
      "z": -7,
      "name": "Rock_Basalt"
    },
    {
      "x": -3,
      "y": 29,
      "z": -6,
      "name": "Rock_Basalt"
    },
    {
      "x": -3,
      "y": 30,
      "z": -6,
      "name": "Rock_Basalt"
    },
    {
      "x": -3,
      "y": 31,
      "z": -6,
      "name": "Rock_Basalt"
    },
    {
      "x": -3,
      "y": 32,
      "z": -6,
      "name": "Rock_Basalt"
    },
    {
      "x": -3,
      "y": 33,
      "z": -6,
      "name": "Rock_Basalt"
    },
    {
      "x": -3,
      "y": 34,
      "z": -6,
      "name": "Rock_Basalt"
    },
    {
      "x": -3,
      "y": 35,
      "z": -6,
      "name": "Rock_Basalt"
    },
    {
      "x": -3,
      "y": 36,
      "z": -6,
      "name": "Rock_Basalt"
    },
    {
      "x": -3,
      "y": 37,
      "z": -6,
      "name": "Rock_Basalt"
    },
    {
      "x": -3,
      "y": 38,
      "z": -6,
      "name": "Rock_Basalt"
    },
    {
      "x": -3,
      "y": 39,
      "z": -6,
      "name": "Rock_Basalt"
    },
    {
      "x": -3,
      "y": 40,
      "z": -6,
      "name": "Rock_Basalt"
    },
    {
      "x": -3,
      "y": 41,
      "z": -6,
      "name": "Rock_Basalt"
    },
    {
      "x": -3,
      "y": 42,
      "z": -6,
      "name": "Rock_Basalt"
    },
    {
      "x": -3,
      "y": 43,
      "z": -6,
      "name": "Rock_Basalt"
    },
    {
      "x": -3,
      "y": 44,
      "z": -6,
      "name": "Rock_Basalt"
    },
    {
      "x": -3,
      "y": 45,
      "z": -6,
      "name": "Rock_Basalt"
    },
    {
      "x": -3,
      "y": 46,
      "z": -6,
      "name": "Rock_Basalt"
    },
    {
      "x": -3,
      "y": 47,
      "z": -6,
      "name": "Rock_Basalt"
    },
    {
      "x": -3,
      "y": 48,
      "z": -6,
      "name": "Rock_Basalt"
    },
    {
      "x": -3,
      "y": 49,
      "z": -6,
      "name": "Rock_Basalt"
    },
    {
      "x": -3,
      "y": 50,
      "z": -6,
      "name": "Rock_Basalt"
    },
    {
      "x": -3,
      "y": 51,
      "z": -6,
      "name": "Rock_Basalt"
    },
    {
      "x": -3,
      "y": 52,
      "z": -6,
      "name": "Rock_Basalt"
    },
    {
      "x": -3,
      "y": 25,
      "z": -5,
      "name": "Rock_Basalt"
    },
    {
      "x": -3,
      "y": 26,
      "z": -5,
      "name": "Rock_Basalt"
    },
    {
      "x": -3,
      "y": 27,
      "z": -5,
      "name": "Rock_Basalt"
    },
    {
      "x": -3,
      "y": 28,
      "z": -5,
      "name": "Rock_Basalt"
    },
    {
      "x": -3,
      "y": 29,
      "z": -5,
      "name": "Rock_Basalt"
    },
    {
      "x": -3,
      "y": 30,
      "z": -5,
      "name": "Rock_Basalt"
    },
    {
      "x": -3,
      "y": 31,
      "z": -5,
      "name": "Rock_Basalt"
    },
    {
      "x": -3,
      "y": 32,
      "z": -5,
      "name": "Rock_Basalt"
    },
    {
      "x": -3,
      "y": 33,
      "z": -5,
      "name": "Rock_Basalt"
    },
    {
      "x": -3,
      "y": 34,
      "z": -5,
      "name": "Rock_Basalt"
    },
    {
      "x": -3,
      "y": 35,
      "z": -5,
      "name": "Rock_Basalt"
    },
    {
      "x": -3,
      "y": 36,
      "z": -5,
      "name": "Rock_Basalt"
    },
    {
      "x": -3,
      "y": 37,
      "z": -5,
      "name": "Rock_Basalt"
    },
    {
      "x": -3,
      "y": 38,
      "z": -5,
      "name": "Rock_Basalt"
    },
    {
      "x": -3,
      "y": 39,
      "z": -5,
      "name": "Rock_Basalt"
    },
    {
      "x": -3,
      "y": 40,
      "z": -5,
      "name": "Rock_Basalt"
    },
    {
      "x": -3,
      "y": 41,
      "z": -5,
      "name": "Rock_Basalt"
    },
    {
      "x": -3,
      "y": 42,
      "z": -5,
      "name": "Rock_Basalt"
    },
    {
      "x": -3,
      "y": 43,
      "z": -5,
      "name": "Rock_Basalt"
    },
    {
      "x": -3,
      "y": 44,
      "z": -5,
      "name": "Rock_Basalt"
    },
    {
      "x": -3,
      "y": 45,
      "z": -5,
      "name": "Rock_Basalt"
    },
    {
      "x": -3,
      "y": 46,
      "z": -5,
      "name": "Rock_Basalt"
    },
    {
      "x": -3,
      "y": 47,
      "z": -5,
      "name": "Rock_Basalt"
    },
    {
      "x": -3,
      "y": 48,
      "z": -5,
      "name": "Rock_Basalt"
    },
    {
      "x": -3,
      "y": 49,
      "z": -5,
      "name": "Rock_Basalt"
    },
    {
      "x": -3,
      "y": 50,
      "z": -5,
      "name": "Rock_Basalt"
    },
    {
      "x": -3,
      "y": 51,
      "z": -5,
      "name": "Rock_Basalt"
    },
    {
      "x": -3,
      "y": 52,
      "z": -5,
      "name": "Rock_Basalt"
    },
    {
      "x": -3,
      "y": 53,
      "z": -5,
      "name": "Rock_Basalt"
    },
    {
      "x": -3,
      "y": 22,
      "z": -4,
      "name": "Rock_Basalt"
    },
    {
      "x": -3,
      "y": 23,
      "z": -4,
      "name": "Rock_Basalt"
    },
    {
      "x": -3,
      "y": 24,
      "z": -4,
      "name": "Rock_Basalt"
    },
    {
      "x": -3,
      "y": 25,
      "z": -4,
      "name": "Rock_Basalt"
    },
    {
      "x": -3,
      "y": 26,
      "z": -4,
      "name": "Rock_Basalt"
    },
    {
      "x": -3,
      "y": 27,
      "z": -4,
      "name": "Rock_Basalt"
    },
    {
      "x": -3,
      "y": 28,
      "z": -4,
      "name": "Rock_Basalt"
    },
    {
      "x": -3,
      "y": 29,
      "z": -4,
      "name": "Rock_Basalt"
    },
    {
      "x": -3,
      "y": 30,
      "z": -4,
      "name": "Rock_Basalt"
    },
    {
      "x": -3,
      "y": 31,
      "z": -4,
      "name": "Rock_Basalt"
    },
    {
      "x": -3,
      "y": 32,
      "z": -4,
      "name": "Rock_Basalt"
    },
    {
      "x": -3,
      "y": 33,
      "z": -4,
      "name": "Rock_Basalt"
    },
    {
      "x": -3,
      "y": 34,
      "z": -4,
      "name": "Rock_Basalt"
    },
    {
      "x": -3,
      "y": 35,
      "z": -4,
      "name": "Rock_Basalt"
    },
    {
      "x": -3,
      "y": 36,
      "z": -4,
      "name": "Rock_Basalt"
    },
    {
      "x": -3,
      "y": 37,
      "z": -4,
      "name": "Rock_Basalt"
    },
    {
      "x": -3,
      "y": 38,
      "z": -4,
      "name": "Rock_Basalt"
    },
    {
      "x": -3,
      "y": 39,
      "z": -4,
      "name": "Rock_Basalt"
    },
    {
      "x": -3,
      "y": 40,
      "z": -4,
      "name": "Rock_Basalt"
    },
    {
      "x": -3,
      "y": 41,
      "z": -4,
      "name": "Rock_Basalt"
    },
    {
      "x": -3,
      "y": 42,
      "z": -4,
      "name": "Rock_Basalt"
    },
    {
      "x": -3,
      "y": 43,
      "z": -4,
      "name": "Rock_Basalt"
    },
    {
      "x": -3,
      "y": 44,
      "z": -4,
      "name": "Rock_Basalt"
    },
    {
      "x": -3,
      "y": 45,
      "z": -4,
      "name": "Rock_Basalt"
    },
    {
      "x": -3,
      "y": 46,
      "z": -4,
      "name": "Rock_Basalt"
    },
    {
      "x": -3,
      "y": 47,
      "z": -4,
      "name": "Rock_Basalt"
    },
    {
      "x": -3,
      "y": 48,
      "z": -4,
      "name": "Rock_Basalt"
    },
    {
      "x": -3,
      "y": 49,
      "z": -4,
      "name": "Rock_Basalt"
    },
    {
      "x": -3,
      "y": 50,
      "z": -4,
      "name": "Rock_Basalt"
    },
    {
      "x": -3,
      "y": 51,
      "z": -4,
      "name": "Rock_Basalt"
    },
    {
      "x": -3,
      "y": 52,
      "z": -4,
      "name": "Rock_Basalt"
    },
    {
      "x": -3,
      "y": 18,
      "z": -3,
      "name": "Rock_Basalt"
    },
    {
      "x": -3,
      "y": 19,
      "z": -3,
      "name": "Rock_Basalt"
    },
    {
      "x": -3,
      "y": 20,
      "z": -3,
      "name": "Rock_Basalt"
    },
    {
      "x": -3,
      "y": 21,
      "z": -3,
      "name": "Rock_Basalt"
    },
    {
      "x": -3,
      "y": 22,
      "z": -3,
      "name": "Rock_Basalt"
    },
    {
      "x": -3,
      "y": 23,
      "z": -3,
      "name": "Rock_Basalt"
    },
    {
      "x": -3,
      "y": 24,
      "z": -3,
      "name": "Rock_Basalt"
    },
    {
      "x": -3,
      "y": 25,
      "z": -3,
      "name": "Rock_Basalt"
    },
    {
      "x": -3,
      "y": 26,
      "z": -3,
      "name": "Rock_Basalt"
    },
    {
      "x": -3,
      "y": 27,
      "z": -3,
      "name": "Rock_Basalt"
    },
    {
      "x": -3,
      "y": 28,
      "z": -3,
      "name": "Rock_Basalt"
    },
    {
      "x": -3,
      "y": 29,
      "z": -3,
      "name": "Rock_Basalt"
    },
    {
      "x": -3,
      "y": 30,
      "z": -3,
      "name": "Rock_Basalt"
    },
    {
      "x": -3,
      "y": 31,
      "z": -3,
      "name": "Rock_Basalt"
    },
    {
      "x": -3,
      "y": 32,
      "z": -3,
      "name": "Rock_Basalt"
    },
    {
      "x": -3,
      "y": 33,
      "z": -3,
      "name": "Rock_Basalt"
    },
    {
      "x": -3,
      "y": 34,
      "z": -3,
      "name": "Rock_Basalt"
    },
    {
      "x": -3,
      "y": 35,
      "z": -3,
      "name": "Rock_Basalt"
    },
    {
      "x": -3,
      "y": 36,
      "z": -3,
      "name": "Rock_Basalt"
    },
    {
      "x": -3,
      "y": 37,
      "z": -3,
      "name": "Rock_Basalt"
    },
    {
      "x": -3,
      "y": 38,
      "z": -3,
      "name": "Rock_Basalt"
    },
    {
      "x": -3,
      "y": 39,
      "z": -3,
      "name": "Rock_Basalt"
    },
    {
      "x": -3,
      "y": 40,
      "z": -3,
      "name": "Rock_Basalt"
    },
    {
      "x": -3,
      "y": 41,
      "z": -3,
      "name": "Rock_Basalt"
    },
    {
      "x": -3,
      "y": 42,
      "z": -3,
      "name": "Rock_Basalt"
    },
    {
      "x": -3,
      "y": 43,
      "z": -3,
      "name": "Rock_Basalt"
    },
    {
      "x": -3,
      "y": 44,
      "z": -3,
      "name": "Rock_Basalt"
    },
    {
      "x": -3,
      "y": 45,
      "z": -3,
      "name": "Rock_Basalt"
    },
    {
      "x": -3,
      "y": 46,
      "z": -3,
      "name": "Rock_Basalt"
    },
    {
      "x": -3,
      "y": 47,
      "z": -3,
      "name": "Rock_Basalt"
    },
    {
      "x": -3,
      "y": 48,
      "z": -3,
      "name": "Rock_Basalt"
    },
    {
      "x": -3,
      "y": 49,
      "z": -3,
      "name": "Rock_Basalt"
    },
    {
      "x": -3,
      "y": 50,
      "z": -3,
      "name": "Rock_Basalt"
    },
    {
      "x": -3,
      "y": 51,
      "z": -3,
      "name": "Rock_Basalt"
    },
    {
      "x": -3,
      "y": 52,
      "z": -3,
      "name": "Rock_Basalt"
    },
    {
      "x": -3,
      "y": 53,
      "z": -3,
      "name": "Rock_Basalt"
    },
    {
      "x": -3,
      "y": 15,
      "z": -2,
      "name": "Rock_Basalt"
    },
    {
      "x": -3,
      "y": 16,
      "z": -2,
      "name": "Rock_Basalt"
    },
    {
      "x": -3,
      "y": 17,
      "z": -2,
      "name": "Rock_Basalt"
    },
    {
      "x": -3,
      "y": 18,
      "z": -2,
      "name": "Rock_Basalt"
    },
    {
      "x": -3,
      "y": 19,
      "z": -2,
      "name": "Rock_Basalt"
    },
    {
      "x": -3,
      "y": 20,
      "z": -2,
      "name": "Rock_Basalt"
    },
    {
      "x": -3,
      "y": 21,
      "z": -2,
      "name": "Rock_Basalt"
    },
    {
      "x": -3,
      "y": 22,
      "z": -2,
      "name": "Rock_Basalt"
    },
    {
      "x": -3,
      "y": 23,
      "z": -2,
      "name": "Rock_Basalt"
    },
    {
      "x": -3,
      "y": 24,
      "z": -2,
      "name": "Rock_Basalt"
    },
    {
      "x": -3,
      "y": 25,
      "z": -2,
      "name": "Rock_Basalt"
    },
    {
      "x": -3,
      "y": 26,
      "z": -2,
      "name": "Rock_Basalt"
    },
    {
      "x": -3,
      "y": 27,
      "z": -2,
      "name": "Rock_Basalt"
    },
    {
      "x": -3,
      "y": 28,
      "z": -2,
      "name": "Rock_Basalt"
    },
    {
      "x": -3,
      "y": 29,
      "z": -2,
      "name": "Rock_Basalt"
    },
    {
      "x": -3,
      "y": 30,
      "z": -2,
      "name": "Rock_Basalt"
    },
    {
      "x": -3,
      "y": 31,
      "z": -2,
      "name": "Rock_Basalt"
    },
    {
      "x": -3,
      "y": 32,
      "z": -2,
      "name": "Rock_Basalt"
    },
    {
      "x": -3,
      "y": 33,
      "z": -2,
      "name": "Rock_Basalt"
    },
    {
      "x": -3,
      "y": 34,
      "z": -2,
      "name": "Rock_Basalt"
    },
    {
      "x": -3,
      "y": 35,
      "z": -2,
      "name": "Rock_Basalt"
    },
    {
      "x": -3,
      "y": 36,
      "z": -2,
      "name": "Rock_Basalt"
    },
    {
      "x": -3,
      "y": 37,
      "z": -2,
      "name": "Rock_Basalt"
    },
    {
      "x": -3,
      "y": 38,
      "z": -2,
      "name": "Rock_Basalt"
    },
    {
      "x": -3,
      "y": 39,
      "z": -2,
      "name": "Rock_Basalt"
    },
    {
      "x": -3,
      "y": 40,
      "z": -2,
      "name": "Rock_Basalt"
    },
    {
      "x": -3,
      "y": 41,
      "z": -2,
      "name": "Rock_Basalt"
    },
    {
      "x": -3,
      "y": 42,
      "z": -2,
      "name": "Rock_Basalt"
    },
    {
      "x": -3,
      "y": 43,
      "z": -2,
      "name": "Rock_Basalt"
    },
    {
      "x": -3,
      "y": 44,
      "z": -2,
      "name": "Rock_Basalt"
    },
    {
      "x": -3,
      "y": 45,
      "z": -2,
      "name": "Rock_Basalt"
    },
    {
      "x": -3,
      "y": 46,
      "z": -2,
      "name": "Rock_Basalt"
    },
    {
      "x": -3,
      "y": 47,
      "z": -2,
      "name": "Rock_Basalt"
    },
    {
      "x": -3,
      "y": 48,
      "z": -2,
      "name": "Rock_Basalt"
    },
    {
      "x": -3,
      "y": 49,
      "z": -2,
      "name": "Rock_Basalt"
    },
    {
      "x": -3,
      "y": 50,
      "z": -2,
      "name": "Rock_Basalt"
    },
    {
      "x": -3,
      "y": 51,
      "z": -2,
      "name": "Rock_Basalt"
    },
    {
      "x": -3,
      "y": 52,
      "z": -2,
      "name": "Rock_Basalt"
    },
    {
      "x": -3,
      "y": 53,
      "z": -2,
      "name": "Rock_Basalt"
    },
    {
      "x": -3,
      "y": 12,
      "z": -1,
      "name": "Rock_Basalt"
    },
    {
      "x": -3,
      "y": 13,
      "z": -1,
      "name": "Rock_Basalt"
    },
    {
      "x": -3,
      "y": 14,
      "z": -1,
      "name": "Rock_Basalt"
    },
    {
      "x": -3,
      "y": 15,
      "z": -1,
      "name": "Rock_Basalt"
    },
    {
      "x": -3,
      "y": 16,
      "z": -1,
      "name": "Rock_Basalt"
    },
    {
      "x": -3,
      "y": 17,
      "z": -1,
      "name": "Rock_Basalt"
    },
    {
      "x": -3,
      "y": 18,
      "z": -1,
      "name": "Rock_Basalt"
    },
    {
      "x": -3,
      "y": 19,
      "z": -1,
      "name": "Rock_Basalt"
    },
    {
      "x": -3,
      "y": 20,
      "z": -1,
      "name": "Rock_Basalt"
    },
    {
      "x": -3,
      "y": 21,
      "z": -1,
      "name": "Rock_Basalt"
    },
    {
      "x": -3,
      "y": 22,
      "z": -1,
      "name": "Rock_Basalt"
    },
    {
      "x": -3,
      "y": 23,
      "z": -1,
      "name": "Rock_Basalt"
    },
    {
      "x": -3,
      "y": 24,
      "z": -1,
      "name": "Rock_Basalt"
    },
    {
      "x": -3,
      "y": 25,
      "z": -1,
      "name": "Rock_Basalt"
    },
    {
      "x": -3,
      "y": 26,
      "z": -1,
      "name": "Rock_Basalt"
    },
    {
      "x": -3,
      "y": 27,
      "z": -1,
      "name": "Rock_Basalt"
    },
    {
      "x": -3,
      "y": 28,
      "z": -1,
      "name": "Rock_Basalt"
    },
    {
      "x": -3,
      "y": 29,
      "z": -1,
      "name": "Rock_Basalt"
    },
    {
      "x": -3,
      "y": 30,
      "z": -1,
      "name": "Rock_Basalt"
    },
    {
      "x": -3,
      "y": 31,
      "z": -1,
      "name": "Rock_Basalt"
    },
    {
      "x": -3,
      "y": 32,
      "z": -1,
      "name": "Rock_Basalt"
    },
    {
      "x": -3,
      "y": 33,
      "z": -1,
      "name": "Rock_Basalt"
    },
    {
      "x": -3,
      "y": 34,
      "z": -1,
      "name": "Rock_Basalt"
    },
    {
      "x": -3,
      "y": 35,
      "z": -1,
      "name": "Rock_Basalt"
    },
    {
      "x": -3,
      "y": 36,
      "z": -1,
      "name": "Rock_Basalt"
    },
    {
      "x": -3,
      "y": 37,
      "z": -1,
      "name": "Rock_Basalt"
    },
    {
      "x": -3,
      "y": 38,
      "z": -1,
      "name": "Rock_Basalt"
    },
    {
      "x": -3,
      "y": 39,
      "z": -1,
      "name": "Rock_Basalt"
    },
    {
      "x": -3,
      "y": 40,
      "z": -1,
      "name": "Rock_Basalt"
    },
    {
      "x": -3,
      "y": 41,
      "z": -1,
      "name": "Rock_Basalt"
    },
    {
      "x": -3,
      "y": 42,
      "z": -1,
      "name": "Rock_Basalt"
    },
    {
      "x": -3,
      "y": 43,
      "z": -1,
      "name": "Rock_Basalt"
    },
    {
      "x": -3,
      "y": 44,
      "z": -1,
      "name": "Rock_Basalt"
    },
    {
      "x": -3,
      "y": 45,
      "z": -1,
      "name": "Rock_Basalt"
    },
    {
      "x": -3,
      "y": 46,
      "z": -1,
      "name": "Rock_Basalt"
    },
    {
      "x": -3,
      "y": 47,
      "z": -1,
      "name": "Rock_Basalt"
    },
    {
      "x": -3,
      "y": 48,
      "z": -1,
      "name": "Rock_Basalt"
    },
    {
      "x": -3,
      "y": 49,
      "z": -1,
      "name": "Rock_Basalt"
    },
    {
      "x": -3,
      "y": 50,
      "z": -1,
      "name": "Rock_Basalt"
    },
    {
      "x": -3,
      "y": 51,
      "z": -1,
      "name": "Rock_Basalt"
    },
    {
      "x": -3,
      "y": 52,
      "z": -1,
      "name": "Rock_Basalt"
    },
    {
      "x": -3,
      "y": 53,
      "z": -1,
      "name": "Rock_Basalt"
    },
    {
      "x": -3,
      "y": 13,
      "z": 0,
      "name": "Rock_Basalt"
    },
    {
      "x": -3,
      "y": 14,
      "z": 0,
      "name": "Rock_Basalt"
    },
    {
      "x": -3,
      "y": 15,
      "z": 0,
      "name": "Rock_Basalt"
    },
    {
      "x": -3,
      "y": 16,
      "z": 0,
      "name": "Rock_Basalt"
    },
    {
      "x": -3,
      "y": 17,
      "z": 0,
      "name": "Rock_Basalt"
    },
    {
      "x": -3,
      "y": 18,
      "z": 0,
      "name": "Rock_Basalt"
    },
    {
      "x": -3,
      "y": 19,
      "z": 0,
      "name": "Rock_Basalt"
    },
    {
      "x": -3,
      "y": 20,
      "z": 0,
      "name": "Rock_Basalt"
    },
    {
      "x": -3,
      "y": 21,
      "z": 0,
      "name": "Rock_Basalt"
    },
    {
      "x": -3,
      "y": 22,
      "z": 0,
      "name": "Rock_Basalt"
    },
    {
      "x": -3,
      "y": 23,
      "z": 0,
      "name": "Rock_Basalt"
    },
    {
      "x": -3,
      "y": 24,
      "z": 0,
      "name": "Rock_Basalt"
    },
    {
      "x": -3,
      "y": 25,
      "z": 0,
      "name": "Rock_Basalt"
    },
    {
      "x": -3,
      "y": 26,
      "z": 0,
      "name": "Rock_Basalt"
    },
    {
      "x": -3,
      "y": 27,
      "z": 0,
      "name": "Rock_Basalt"
    },
    {
      "x": -3,
      "y": 28,
      "z": 0,
      "name": "Rock_Basalt"
    },
    {
      "x": -3,
      "y": 29,
      "z": 0,
      "name": "Rock_Crystal_Red_Block"
    },
    {
      "x": -3,
      "y": 30,
      "z": 0,
      "name": "Rock_Crystal_Red_Block"
    },
    {
      "x": -3,
      "y": 31,
      "z": 0,
      "name": "Rock_Basalt"
    },
    {
      "x": -3,
      "y": 32,
      "z": 0,
      "name": "Rock_Basalt"
    },
    {
      "x": -3,
      "y": 33,
      "z": 0,
      "name": "Rock_Basalt"
    },
    {
      "x": -3,
      "y": 34,
      "z": 0,
      "name": "Rock_Basalt"
    },
    {
      "x": -3,
      "y": 35,
      "z": 0,
      "name": "Rock_Basalt"
    },
    {
      "x": -3,
      "y": 36,
      "z": 0,
      "name": "Rock_Basalt"
    },
    {
      "x": -3,
      "y": 37,
      "z": 0,
      "name": "Rock_Basalt"
    },
    {
      "x": -3,
      "y": 38,
      "z": 0,
      "name": "Rock_Basalt"
    },
    {
      "x": -3,
      "y": 39,
      "z": 0,
      "name": "Rock_Basalt"
    },
    {
      "x": -3,
      "y": 40,
      "z": 0,
      "name": "Rock_Basalt"
    },
    {
      "x": -3,
      "y": 41,
      "z": 0,
      "name": "Rock_Basalt"
    },
    {
      "x": -3,
      "y": 42,
      "z": 0,
      "name": "Rock_Basalt"
    },
    {
      "x": -3,
      "y": 43,
      "z": 0,
      "name": "Rock_Basalt"
    },
    {
      "x": -3,
      "y": 44,
      "z": 0,
      "name": "Rock_Basalt"
    },
    {
      "x": -3,
      "y": 45,
      "z": 0,
      "name": "Rock_Basalt"
    },
    {
      "x": -3,
      "y": 46,
      "z": 0,
      "name": "Rock_Basalt"
    },
    {
      "x": -3,
      "y": 47,
      "z": 0,
      "name": "Rock_Basalt"
    },
    {
      "x": -3,
      "y": 48,
      "z": 0,
      "name": "Rock_Basalt"
    },
    {
      "x": -3,
      "y": 49,
      "z": 0,
      "name": "Rock_Basalt"
    },
    {
      "x": -3,
      "y": 50,
      "z": 0,
      "name": "Rock_Basalt"
    },
    {
      "x": -3,
      "y": 51,
      "z": 0,
      "name": "Rock_Basalt"
    },
    {
      "x": -3,
      "y": 52,
      "z": 0,
      "name": "Rock_Basalt"
    },
    {
      "x": -3,
      "y": 53,
      "z": 0,
      "name": "Rock_Basalt"
    },
    {
      "x": -3,
      "y": 16,
      "z": 1,
      "name": "Rock_Basalt"
    },
    {
      "x": -3,
      "y": 17,
      "z": 1,
      "name": "Rock_Basalt"
    },
    {
      "x": -3,
      "y": 18,
      "z": 1,
      "name": "Rock_Basalt"
    },
    {
      "x": -3,
      "y": 19,
      "z": 1,
      "name": "Rock_Basalt"
    },
    {
      "x": -3,
      "y": 20,
      "z": 1,
      "name": "Rock_Basalt"
    },
    {
      "x": -3,
      "y": 21,
      "z": 1,
      "name": "Rock_Basalt"
    },
    {
      "x": -3,
      "y": 22,
      "z": 1,
      "name": "Rock_Basalt"
    },
    {
      "x": -3,
      "y": 23,
      "z": 1,
      "name": "Rock_Basalt"
    },
    {
      "x": -3,
      "y": 24,
      "z": 1,
      "name": "Rock_Basalt"
    },
    {
      "x": -3,
      "y": 25,
      "z": 1,
      "name": "Rock_Basalt"
    },
    {
      "x": -3,
      "y": 26,
      "z": 1,
      "name": "Rock_Basalt"
    },
    {
      "x": -3,
      "y": 27,
      "z": 1,
      "name": "Rock_Basalt"
    },
    {
      "x": -3,
      "y": 28,
      "z": 1,
      "name": "Rock_Crystal_Red_Block"
    },
    {
      "x": -3,
      "y": 29,
      "z": 1,
      "name": "Rock_Crystal_Red_Block"
    },
    {
      "x": -3,
      "y": 30,
      "z": 1,
      "name": "Rock_Crystal_Red_Block"
    },
    {
      "x": -3,
      "y": 31,
      "z": 1,
      "name": "Rock_Basalt"
    },
    {
      "x": -3,
      "y": 32,
      "z": 1,
      "name": "Rock_Basalt"
    },
    {
      "x": -3,
      "y": 33,
      "z": 1,
      "name": "Rock_Basalt"
    },
    {
      "x": -3,
      "y": 34,
      "z": 1,
      "name": "Rock_Basalt"
    },
    {
      "x": -3,
      "y": 35,
      "z": 1,
      "name": "Rock_Basalt"
    },
    {
      "x": -3,
      "y": 36,
      "z": 1,
      "name": "Rock_Basalt"
    },
    {
      "x": -3,
      "y": 37,
      "z": 1,
      "name": "Rock_Basalt"
    },
    {
      "x": -3,
      "y": 38,
      "z": 1,
      "name": "Rock_Basalt"
    },
    {
      "x": -3,
      "y": 39,
      "z": 1,
      "name": "Rock_Basalt"
    },
    {
      "x": -3,
      "y": 40,
      "z": 1,
      "name": "Rock_Basalt"
    },
    {
      "x": -3,
      "y": 41,
      "z": 1,
      "name": "Rock_Basalt"
    },
    {
      "x": -3,
      "y": 42,
      "z": 1,
      "name": "Rock_Basalt"
    },
    {
      "x": -3,
      "y": 43,
      "z": 1,
      "name": "Rock_Basalt"
    },
    {
      "x": -3,
      "y": 44,
      "z": 1,
      "name": "Rock_Basalt"
    },
    {
      "x": -3,
      "y": 45,
      "z": 1,
      "name": "Rock_Basalt"
    },
    {
      "x": -3,
      "y": 46,
      "z": 1,
      "name": "Rock_Basalt"
    },
    {
      "x": -3,
      "y": 47,
      "z": 1,
      "name": "Rock_Basalt"
    },
    {
      "x": -3,
      "y": 48,
      "z": 1,
      "name": "Rock_Basalt"
    },
    {
      "x": -3,
      "y": 49,
      "z": 1,
      "name": "Rock_Basalt"
    },
    {
      "x": -3,
      "y": 50,
      "z": 1,
      "name": "Rock_Basalt"
    },
    {
      "x": -3,
      "y": 51,
      "z": 1,
      "name": "Rock_Basalt"
    },
    {
      "x": -3,
      "y": 52,
      "z": 1,
      "name": "Rock_Basalt"
    },
    {
      "x": -3,
      "y": 53,
      "z": 1,
      "name": "Rock_Basalt"
    },
    {
      "x": -3,
      "y": 20,
      "z": 2,
      "name": "Rock_Basalt"
    },
    {
      "x": -3,
      "y": 21,
      "z": 2,
      "name": "Rock_Basalt"
    },
    {
      "x": -3,
      "y": 22,
      "z": 2,
      "name": "Rock_Basalt"
    },
    {
      "x": -3,
      "y": 23,
      "z": 2,
      "name": "Rock_Basalt"
    },
    {
      "x": -3,
      "y": 24,
      "z": 2,
      "name": "Rock_Basalt"
    },
    {
      "x": -3,
      "y": 25,
      "z": 2,
      "name": "Rock_Basalt"
    },
    {
      "x": -3,
      "y": 26,
      "z": 2,
      "name": "Rock_Basalt"
    },
    {
      "x": -3,
      "y": 28,
      "z": 2,
      "name": "Rock_Crystal_Red_Block"
    },
    {
      "x": -3,
      "y": 29,
      "z": 2,
      "name": "Rock_Crystal_Red_Block"
    },
    {
      "x": -3,
      "y": 30,
      "z": 2,
      "name": "Rock_Crystal_Red_Block"
    },
    {
      "x": -3,
      "y": 31,
      "z": 2,
      "name": "Rock_Basalt"
    },
    {
      "x": -3,
      "y": 32,
      "z": 2,
      "name": "Rock_Basalt"
    },
    {
      "x": -3,
      "y": 33,
      "z": 2,
      "name": "Rock_Basalt"
    },
    {
      "x": -3,
      "y": 34,
      "z": 2,
      "name": "Rock_Basalt"
    },
    {
      "x": -3,
      "y": 35,
      "z": 2,
      "name": "Rock_Basalt"
    },
    {
      "x": -3,
      "y": 36,
      "z": 2,
      "name": "Rock_Basalt"
    },
    {
      "x": -3,
      "y": 37,
      "z": 2,
      "name": "Rock_Basalt"
    },
    {
      "x": -3,
      "y": 38,
      "z": 2,
      "name": "Rock_Basalt"
    },
    {
      "x": -3,
      "y": 39,
      "z": 2,
      "name": "Rock_Basalt"
    },
    {
      "x": -3,
      "y": 40,
      "z": 2,
      "name": "Rock_Basalt"
    },
    {
      "x": -3,
      "y": 41,
      "z": 2,
      "name": "Rock_Basalt"
    },
    {
      "x": -3,
      "y": 42,
      "z": 2,
      "name": "Rock_Basalt"
    },
    {
      "x": -3,
      "y": 43,
      "z": 2,
      "name": "Rock_Basalt"
    },
    {
      "x": -3,
      "y": 44,
      "z": 2,
      "name": "Rock_Basalt"
    },
    {
      "x": -3,
      "y": 45,
      "z": 2,
      "name": "Rock_Basalt"
    },
    {
      "x": -3,
      "y": 46,
      "z": 2,
      "name": "Rock_Basalt"
    },
    {
      "x": -3,
      "y": 47,
      "z": 2,
      "name": "Rock_Basalt"
    },
    {
      "x": -3,
      "y": 48,
      "z": 2,
      "name": "Rock_Basalt"
    },
    {
      "x": -3,
      "y": 49,
      "z": 2,
      "name": "Rock_Basalt"
    },
    {
      "x": -3,
      "y": 50,
      "z": 2,
      "name": "Rock_Basalt"
    },
    {
      "x": -3,
      "y": 51,
      "z": 2,
      "name": "Rock_Basalt"
    },
    {
      "x": -3,
      "y": 52,
      "z": 2,
      "name": "Rock_Basalt"
    },
    {
      "x": -3,
      "y": 21,
      "z": 3,
      "name": "Rock_Basalt"
    },
    {
      "x": -3,
      "y": 22,
      "z": 3,
      "name": "Rock_Basalt"
    },
    {
      "x": -3,
      "y": 23,
      "z": 3,
      "name": "Rock_Basalt"
    },
    {
      "x": -3,
      "y": 24,
      "z": 3,
      "name": "Rock_Basalt"
    },
    {
      "x": -3,
      "y": 25,
      "z": 3,
      "name": "Rock_Basalt"
    },
    {
      "x": -3,
      "y": 29,
      "z": 3,
      "name": "Rock_Basalt"
    },
    {
      "x": -3,
      "y": 30,
      "z": 3,
      "name": "Rock_Basalt"
    },
    {
      "x": -3,
      "y": 31,
      "z": 3,
      "name": "Rock_Basalt"
    },
    {
      "x": -3,
      "y": 32,
      "z": 3,
      "name": "Rock_Basalt"
    },
    {
      "x": -3,
      "y": 33,
      "z": 3,
      "name": "Rock_Basalt"
    },
    {
      "x": -3,
      "y": 34,
      "z": 3,
      "name": "Rock_Basalt"
    },
    {
      "x": -3,
      "y": 35,
      "z": 3,
      "name": "Rock_Basalt"
    },
    {
      "x": -3,
      "y": 36,
      "z": 3,
      "name": "Rock_Basalt"
    },
    {
      "x": -3,
      "y": 37,
      "z": 3,
      "name": "Rock_Basalt"
    },
    {
      "x": -3,
      "y": 38,
      "z": 3,
      "name": "Rock_Basalt"
    },
    {
      "x": -3,
      "y": 39,
      "z": 3,
