{
  "version": 8,
  "blockIdVersion": 8,
  "anchorX": 0,
  "anchorY": 0,
  "anchorZ": 0,
  "blocks": [
    {
      "x": -3,
      "y": 2,
      "z": 0,
      "name": "Plant_Leaves_Fir",
      "rotation": 3
    },
    {
      "x": -2,
      "y": 2,
      "z": 0,
      "name": "Plant_Leaves_Fir",
      "rotation": 3
    },
    {
      "x": -2,
      "y": 3,
      "z": 0,
      "name": "Plant_Leaves_Fir",
      "rotation": 3
    },
    {
      "x": -2,
      "y": 6,
      "z": 0,
      "name": "Plant_Leaves_Fir",
      "rotation": 3
    },
    {
      "x": -2,
      "y": 2,
      "z": 1,
      "name": "Plant_Leaves_Fir",
      "rotation": 3
    },
    {
      "x": -1,
      "y": 2,
      "z": -2,
      "name": "Plant_Leaves_Fir",
      "rotation": 2
    },
    {
      "x": -1,
      "y": 2,
      "z": -1,
      "name": "Plant_Leaves_Fir",
      "rotation": 2
    },
    {
      "x": -1,
      "y": 6,
      "z": -1,
      "name": "Plant_Leaves_Fir",
      "rotation": 3
    },
    {
      "x": -1,
      "y": 2,
      "z": 0,
      "name": "Plant_Leaves_Fir",
      "rotation": 3
    },
    {
      "x": -1,
      "y": 3,
      "z": 0,
      "name": "Plant_Leaves_Fir",
      "rotation": 3
    },
    {
      "x": -1,
      "y": 4,
      "z": 0,
      "name": "Plant_Leaves_Fir",
      "rotation": 3
    },
    {
      "x": -1,
      "y": 6,
      "z": 0,
      "name": "Plant_Leaves_Fir",
      "rotation": 3
    },
    {
      "x": -1,
      "y": 9,
      "z": 0,
      "name": "Plant_Leaves_Fir",
      "rotation": 3
    },
    {
      "x": -1,
      "y": 11,
      "z": 0,
      "name": "Plant_Leaves_Fir",
      "rotation": 3
    },
    {
      "x": -1,
      "y": 3,
      "z": 1,
      "name": "Plant_Leaves_Fir"
    },
    {
      "x": -1,
      "y": 2,
      "z": 2,
      "name": "Plant_Leaves_Fir"
    },
    {
      "x": 0,
      "y": 2,
      "z": -2,
      "name": "Plant_Leaves_Fir",
      "rotation": 2
    },
    {
      "x": 0,
      "y": 6,
      "z": -2,
      "name": "Plant_Leaves_Fir",
      "rotation": 2
    },
    {
      "x": 0,
      "y": 2,
      "z": -1,
      "name": "Plant_Leaves_Fir",
      "rotation": 2
    },
    {
      "x": 0,
      "y": 3,
      "z": -1,
      "name": "Plant_Leaves_Fir",
      "rotation": 2
    },
    {
      "x": 0,
      "y": 6,
      "z": -1,
      "name": "Plant_Leaves_Fir",
      "rotation": 2
    },
    {
      "x": 0,
      "y": 7,
      "z": -1,
      "name": "Plant_Leaves_Fir",
      "rotation": 2
    },
    {
      "x": 0,
      "y": 9,
      "z": -1,
      "name": "Plant_Leaves_Fir",
      "rotation": 2
    },
    {
      "x": 0,
      "y": 0,
      "z": 0,
      "name": "Wood_Fir_Branch_Long"
    },
    {
      "x": 0,
      "y": 1,
      "z": 0,
      "name": "Wood_Fir_Branch_Long"
    },
    {
      "x": 0,
      "y": 2,
      "z": 0,
      "name": "Wood_Fir_Branch_Long"
    },
    {
      "x": 0,
      "y": 3,
      "z": 0,
      "name": "Wood_Fir_Branch_Long"
    },
    {
      "x": 0,
      "y": 4,
      "z": 0,
      "name": "Wood_Fir_Branch_Long"
    },
    {
      "x": 0,
      "y": 5,
      "z": 0,
      "name": "Wood_Fir_Branch_Long"
    },
    {
      "x": 0,
      "y": 6,
      "z": 0,
      "name": "Wood_Fir_Branch_Long"
    },
    {
      "x": 0,
      "y": 7,
      "z": 0,
      "name": "Wood_Fir_Branch_Long"
    },
    {
      "x": 0,
      "y": 8,
      "z": 0,
      "name": "Wood_Fir_Branch_Long"
    },
    {
      "x": 0,
      "y": 9,
      "z": 0,
      "name": "Plant_Leaves_Fir_Tip"
    },
    {
      "x": 0,
      "y": 10,
      "z": 0,
      "name": "Plant_Leaves_Fir_Tip"
    },
    {
      "x": 0,
      "y": 11,
      "z": 0,
      "name": "Plant_Leaves_Fir_Tip"
    },
    {
      "x": 0,
      "y": 12,
      "z": 0,
      "name": "Plant_Leaves_Fir_Tip"
    },
    {
      "x": 0,
      "y": 13,
      "z": 0,
      "name": "Plant_Leaves_Fir_Tip"
    },
    {
      "x": 0,
      "y": 14,
      "z": 0,
      "name": "Plant_Leaves_Fir_Tip"
    },
    {
      "x": 0,
      "y": 3,
      "z": 1,
      "name": "Plant_Leaves_Fir"
    },
    {
      "x": 0,
      "y": 4,
      "z": 1,
      "name": "Plant_Leaves_Fir"
    },
    {
      "x": 0,
      "y": 6,
      "z": 1,
      "name": "Plant_Leaves_Fir"
    },
    {
      "x": 0,
      "y": 7,
      "z": 1,
      "name": "Plant_Leaves_Fir"
    },
    {
      "x": 0,
      "y": 9,
      "z": 1,
      "name": "Plant_Leaves_Fir"
    },
    {
      "x": 0,
      "y": 11,
      "z": 1,
      "name": "Plant_Leaves_Fir"
    },
    {
      "x": 0,
      "y": 2,
      "z": 2,
      "name": "Plant_Leaves_Fir"
    },
    {
      "x": 0,
      "y": 6,
      "z": 2,
      "name": "Plant_Leaves_Fir"
    },
    {
      "x": 0,
      "y": 2,
      "z": 3,
      "name": "Plant_Leaves_Fir"
    },
    {
      "x": 1,
      "y": 2,
      "z": -1,
      "name": "Plant_Leaves_Fir",
      "rotation": 1
    },
    {
      "x": 1,
      "y": 3,
      "z": -1,
      "name": "Plant_Leaves_Fir",
      "rotation": 1
    },
    {
      "x": 1,
      "y": 6,
      "z": -1,
      "name": "Plant_Leaves_Fir",
      "rotation": 2
    },
    {
      "x": 1,
      "y": 2,
      "z": 0,
      "name": "Plant_Leaves_Fir",
      "rotation": 1
    },
    {
      "x": 1,
      "y": 4,
      "z": 0,
      "name": "Plant_Leaves_Fir",
      "rotation": 1
    },
    {
      "x": 1,
      "y": 6,
      "z": 0,
      "name": "Plant_Leaves_Fir",
      "rotation": 1
    },
    {
      "x": 1,
      "y": 9,
      "z": 0,
      "name": "Plant_Leaves_Fir",
      "rotation": 1
    },
    {
      "x": 1,
      "y": 10,
      "z": 0,
      "name": "Plant_Leaves_Fir",
      "rotation": 1
    },
    {
      "x": 1,
      "y": 3,
      "z": 1,
      "name": "Plant_Leaves_Fir",
      "rotation": 1
    },
    {
      "x": 2,
      "y": 2,
      "z": 0,
      "name": "Plant_Leaves_Fir",
      "rotation": 1
    },
    {
      "x": 2,
      "y": 6,
      "z": 0,
      "name": "Plant_Leaves_Fir",
      "rotation": 1
    },
    {
      "x": 2,
      "y": 2,
      "z": 1,
      "name": "Plant_Leaves_Fir",
      "rotation": 1
    },
    {
      "x": 3,
      "y": 2,
      "z": 0,
      "name": "Plant_Leaves_Fir",
      "rotation": 1
    }
  ]
}