{
  "version": 8,
  "blockIdVersion": 8,
  "anchorX": 0,
  "anchorY": 2,
  "anchorZ": 0,
  "blocks": [
    {
      "x": -3,
      "y": 1,
      "z": -1,
      "name": "Rock_Shale_Cobble"
    },
    {
      "x": -3,
      "y": 2,
      "z": -1,
      "name": "Rock_Shale_Cobble"
    },
    {
      "x": -3,
      "y": 3,
      "z": -1,
      "name": "Rock_Shale_Cobble"
    },
    {
      "x": -3,
      "y": 4,
      "z": -1,
      "name": "Wood_Darkwood_Stairs",
      "rotation": 3
    },
    {
      "x": -3,
      "y": 1,
      "z": 0,
      "name": "Soil_Pathway"
    },
    {
      "x": -3,
      "y": 2,
      "z": 0,
      "name": "Rock_Shale_Cobble"
    },
    {
      "x": -3,
      "y": 3,
      "z": 0,
      "name": "Rock_Shale_Cobble"
    },
    {
      "x": -3,
      "y": 2,
      "z": 1,
      "name": "Soil_Pathway"
    },
    {
      "x": -3,
      "y": 3,
      "z": 1,
      "name": "Rock_Shale_Cobble"
    },
    {
      "x": -3,
      "y": 4,
      "z": 1,
      "name": "Wood_Fir_Branch_Long"
    },
    {
      "x": -3,
      "y": 5,
      "z": 1,
      "name": "Cloth_Roof_Blue",
      "rotation": 3
    },
    {
      "x": -2,
      "y": 5,
      "z": -3,
      "name": "Wood_Fir_Branch_Long",
      "rotation": 4
    },
    {
      "x": -2,
      "y": 2,
      "z": -2,
      "name": "Wood_Fir_Trunk"
    },
    {
      "x": -2,
      "y": 3,
      "z": -2,
      "name": "Wood_Fir_Trunk"
    },
    {
      "x": -2,
      "y": 4,
      "z": -2,
      "name": "Wood_Fir_Trunk"
    },
    {
      "x": -2,
      "y": 5,
      "z": -2,
      "name": "Wood_Fir_Trunk"
    },
    {
      "x": -2,
      "y": 1,
      "z": -1,
      "name": "Soil_Pathway"
    },
    {
      "x": -2,
      "y": 2,
      "z": -1,
      "name": "Soil_Grass_Cold"
    },
    {
      "x": -2,
      "y": 3,
      "z": -1,
      "name": "Deco_Bone_Ribs_Feran"
    },
    {
      "x": -2,
      "y": 4,
      "z": -1,
      "name": "Empty"
    },
    {
      "x": -2,
      "y": 5,
      "z": -1,
      "name": "Wood_Fir_Branch_Long",
      "rotation": 4
    },
    {
      "x": -2,
      "y": 0,
      "z": 0,
      "name": "Soil_Pathway"
    },
    {
      "x": -2,
      "y": 1,
      "z": 0,
      "name": "Soil_Pathway"
    },
    {
      "x": -2,
      "y": 2,
      "z": 0,
      "name": "Soil_Pathway"
    },
    {
      "x": -2,
      "y": 3,
      "z": 0,
      "name": "Empty"
    },
    {
      "x": -2,
      "y": 4,
      "z": 0,
      "name": "Empty"
    },
    {
      "x": -2,
      "y": 5,
      "z": 0,
      "name": "Empty"
    },
    {
      "x": -2,
      "y": 0,
      "z": 1,
      "name": "Soil_Pathway"
    },
    {
      "x": -2,
      "y": 1,
      "z": 1,
      "name": "Soil_Pathway"
    },
    {
      "x": -2,
      "y": 2,
      "z": 1,
      "name": "Soil_Grass_Cold"
    },
    {
      "x": -2,
      "y": 3,
      "z": 1,
      "name": "Plant_Grass_Winter"
    },
    {
      "x": -2,
      "y": 4,
      "z": 1,
      "name": "Empty"
    },
    {
      "x": -2,
      "y": 5,
      "z": 1,
      "name": "Wood_Fir_Branch_Long",
      "rotation": 4
    },
    {
      "x": -2,
      "y": 6,
      "z": 1,
      "name": "Cloth_Roof_Blue_Flat"
    },
    {
      "x": -2,
      "y": 2,
      "z": 2,
      "name": "Wood_Fir_Trunk"
    },
    {
      "x": -2,
      "y": 3,
      "z": 2,
      "name": "Wood_Fir_Trunk"
    },
    {
      "x": -2,
      "y": 4,
      "z": 2,
      "name": "Wood_Fir_Trunk"
    },
    {
      "x": -2,
      "y": 5,
      "z": 2,
      "name": "Wood_Fir_Trunk"
    },
    {
      "x": -2,
      "y": 6,
      "z": 2,
      "name": "Cloth_Roof_Blue_Flat"
    },
    {
      "x": -1,
      "y": 2,
      "z": -3,
      "name": "Rock_Shale_Cobble"
    },
    {
      "x": -1,
      "y": 3,
      "z": -3,
      "name": "Rock_Shale_Cobble"
    },
    {
      "x": -1,
      "y": 1,
      "z": -2,
      "name": "Soil_Pathway"
    },
    {
      "x": -1,
      "y": 2,
      "z": -2,
      "name": "Soil_Pathway"
    },
    {
      "x": -1,
      "y": 3,
      "z": -2,
      "name": "Empty"
    },
    {
      "x": -1,
      "y": 4,
      "z": -2,
      "name": "Empty"
    },
    {
      "x": -1,
      "y": 5,
      "z": -2,
      "name": "Empty"
    },
    {
      "x": -1,
      "y": 0,
      "z": -1,
      "name": "Soil_Pathway"
    },
    {
      "x": -1,
      "y": 1,
      "z": -1,
      "name": "Soil_Pathway"
    },
    {
      "x": -1,
      "y": 2,
      "z": -1,
      "name": "Soil_Pathway"
    },
    {
      "x": -1,
      "y": 3,
      "z": -1,
      "name": "Deco_Pot_Clay_Broken"
    },
    {
      "x": -1,
      "y": 4,
      "z": -1,
      "name": "Empty"
    },
    {
      "x": -1,
      "y": 5,
      "z": -1,
      "name": "Empty"
    },
    {
      "x": -1,
      "y": 6,
      "z": -1,
      "name": "Empty"
    },
    {
      "x": -1,
      "y": 0,
      "z": 0,
      "name": "Soil_Pathway"
    },
    {
      "x": -1,
      "y": 1,
      "z": 0,
      "name": "Soil_Pathway"
    },
    {
      "x": -1,
      "y": 2,
      "z": 0,
      "name": "Soil_Pathway"
    },
    {
      "x": -1,
      "y": 3,
      "z": 0,
      "name": "Empty"
    },
    {
      "x": -1,
      "y": 4,
      "z": 0,
      "name": "Empty"
    },
    {
      "x": -1,
      "y": 5,
      "z": 0,
      "name": "Empty"
    },
    {
      "x": -1,
      "y": 6,
      "z": 0,
      "name": "Empty"
    },
    {
      "x": -1,
      "y": 0,
      "z": 1,
      "name": "Soil_Pathway"
    },
    {
      "x": -1,
      "y": 1,
      "z": 1,
      "name": "Soil_Pathway"
    },
    {
      "x": -1,
      "y": 2,
      "z": 1,
      "name": "Soil_Grass_Cold"
    },
    {
      "x": -1,
      "y": 3,
      "z": 1,
      "name": "Empty"
    },
    {
      "x": -1,
      "y": 4,
      "z": 1,
      "name": "Empty"
    },
    {
      "x": -1,
      "y": 5,
      "z": 1,
      "name": "Cloth_Roof_Blue_Flap",
      "rotation": 1
    },
    {
      "x": -1,
      "y": 6,
      "z": 1,
      "name": "Empty"
    },
    {
      "x": -1,
      "y": 0,
      "z": 2,
      "name": "Soil_Pathway"
    },
    {
      "x": -1,
      "y": 1,
      "z": 2,
      "name": "Soil_Pathway"
    },
    {
      "x": -1,
      "y": 2,
      "z": 2,
      "name": "Soil_Grass_Cold"
    },
    {
      "x": -1,
      "y": 3,
      "z": 2,
      "name": "Plant_Grass_Winter_Short"
    },
    {
      "x": -1,
      "y": 4,
      "z": 2,
      "name": "Empty"
    },
    {
      "x": -1,
      "y": 5,
      "z": 2,
      "name": "Empty"
    },
    {
      "x": -1,
      "y": 2,
      "z": 3,
      "name": "Rock_Shale_Cobble"
    },
    {
      "x": 0,
      "y": 2,
      "z": -3,
      "name": "Soil_Pathway"
    },
    {
      "x": 0,
      "y": 1,
      "z": -2,
      "name": "Soil_Pathway"
    },
    {
      "x": 0,
      "y": 2,
      "z": -2,
      "name": "Soil_Pathway"
    },
    {
      "x": 0,
      "y": 3,
      "z": -2,
      "name": "Empty"
    },
    {
      "x": 0,
      "y": 4,
      "z": -2,
      "name": "Empty"
    },
    {
      "x": 0,
      "y": 5,
      "z": -2,
      "name": "Wood_Fir_Branch_Long",
      "rotation": 5
    },
    {
      "x": 0,
      "y": 0,
      "z": -1,
      "name": "Soil_Pathway"
    },
    {
      "x": 0,
      "y": 1,
      "z": -1,
      "name": "Soil_Pathway"
    },
    {
      "x": 0,
      "y": 2,
      "z": -1,
      "name": "Soil_Pathway"
    },
    {
      "x": 0,
      "y": 3,
      "z": -1,
      "name": "Empty"
    },
    {
      "x": 0,
      "y": 4,
      "z": -1,
      "name": "Empty"
    },
    {
      "x": 0,
      "y": 5,
      "z": -1,
      "name": "Empty"
    },
    {
      "x": 0,
      "y": 6,
      "z": -1,
      "name": "Empty"
    },
    {
      "x": 0,
      "y": 0,
      "z": 0,
      "name": "Soil_Pathway"
    },
    {
      "x": 0,
      "y": 1,
      "z": 0,
      "name": "Soil_Pathway"
    },
    {
      "x": 0,
      "y": 2,
      "z": 0,
      "name": "Soil_Pathway"
    },
    {
      "x": 0,
      "y": 3,
      "z": 0,
      "name": "Empty"
    },
    {
      "x": 0,
      "y": 4,
      "z": 0,
      "name": "Empty"
    },
    {
      "x": 0,
      "y": 5,
      "z": 0,
      "name": "Empty"
    },
    {
      "x": 0,
      "y": 6,
      "z": 0,
      "name": "Empty"
    },
    {
      "x": 0,
      "y": 0,
      "z": 1,
      "name": "Soil_Pathway"
    },
    {
      "x": 0,
      "y": 1,
      "z": 1,
      "name": "Soil_Pathway"
    },
    {
      "x": 0,
      "y": 2,
      "z": 1,
      "name": "Soil_Pathway"
    },
    {
      "x": 0,
      "y": 3,
      "z": 1,
      "name": "Empty"
    },
    {
      "x": 0,
      "y": 4,
      "z": 1,
      "name": "Empty"
    },
    {
      "x": 0,
      "y": 5,
      "z": 1,
      "name": "Empty"
    },
    {
      "x": 0,
      "y": 6,
      "z": 1,
      "name": "Empty"
    },
    {
      "x": 0,
      "y": 0,
      "z": 2,
      "name": "Soil_Pathway"
    },
    {
      "x": 0,
      "y": 1,
      "z": 2,
      "name": "Soil_Pathway"
    },
    {
      "x": 0,
      "y": 2,
      "z": 2,
      "name": "Soil_Grass_Cold"
    },
    {
      "x": 0,
      "y": 3,
      "z": 2,
      "name": "Empty"
    },
    {
      "x": 0,
      "y": 4,
      "z": 2,
      "name": "Empty"
    },
    {
      "x": 0,
      "y": 5,
      "z": 2,
      "name": "Empty"
    },
    {
      "x": 0,
      "y": 1,
      "z": 3,
      "name": "Rock_Shale_Cobble"
    },
    {
      "x": 0,
      "y": 2,
      "z": 3,
      "name": "Rock_Shale_Cobble"
    },
    {
      "x": 0,
      "y": 3,
      "z": 3,
      "name": "Rock_Shale_Cobble"
    },
    {
      "x": 1,
      "y": 1,
      "z": -2,
      "name": "Soil_Pathway"
    },
    {
      "x": 1,
      "y": 2,
      "z": -2,
      "name": "Soil_Grass_Cold"
    },
    {
      "x": 1,
      "y": 3,
      "z": -2,
      "name": "Empty"
    },
    {
      "x": 1,
      "y": 4,
      "z": -2,
      "name": "Empty"
    },
    {
      "x": 1,
      "y": 5,
      "z": -2,
      "name": "Wood_Fir_Branch_Long",
      "rotation": 5
    },
    {
      "x": 1,
      "y": 0,
      "z": -1,
      "name": "Soil_Pathway"
    },
    {
      "x": 1,
      "y": 1,
      "z": -1,
      "name": "Soil_Pathway"
    },
    {
      "x": 1,
      "y": 2,
      "z": -1,
      "name": "Soil_Grass_Cold"
    },
    {
      "x": 1,
      "y": 3,
      "z": -1,
      "name": "Plant_Grass_Winter"
    },
    {
      "x": 1,
      "y": 4,
      "z": -1,
      "name": "Empty"
    },
    {
      "x": 1,
      "y": 5,
      "z": -1,
      "name": "Empty"
    },
    {
      "x": 1,
      "y": 6,
      "z": -1,
      "name": "Empty"
    },
    {
      "x": 1,
      "y": 0,
      "z": 0,
      "name": "Soil_Pathway"
    },
    {
      "x": 1,
      "y": 1,
      "z": 0,
      "name": "Soil_Pathway"
    },
    {
      "x": 1,
      "y": 2,
      "z": 0,
      "name": "Soil_Pathway"
    },
    {
      "x": 1,
      "y": 3,
      "z": 0,
      "name": "Empty"
    },
    {
      "x": 1,
      "y": 4,
      "z": 0,
      "name": "Empty"
    },
    {
      "x": 1,
      "y": 5,
      "z": 0,
      "name": "Empty"
    },
    {
      "x": 1,
      "y": 6,
      "z": 0,
      "name": "Empty"
    },
    {
      "x": 1,
      "y": 0,
      "z": 1,
      "name": "Soil_Pathway"
    },
    {
      "x": 1,
      "y": 1,
      "z": 1,
      "name": "Soil_Pathway"
    },
    {
      "x": 1,
      "y": 2,
      "z": 1,
      "name": "Soil_Pathway"
    },
    {
      "x": 1,
      "y": 3,
      "z": 1,
      "name": "Empty"
    },
    {
      "x": 1,
      "y": 4,
      "z": 1,
      "name": "Empty"
    },
    {
      "x": 1,
      "y": 5,
      "z": 1,
      "name": "Empty"
    },
    {
      "x": 1,
      "y": 6,
      "z": 1,
      "name": "Empty"
    },
    {
      "x": 1,
      "y": 1,
      "z": 2,
      "name": "Soil_Pathway"
    },
    {
      "x": 1,
      "y": 2,
      "z": 2,
      "name": "Soil_Pathway"
    },
    {
      "x": 1,
      "y": 3,
      "z": 2,
      "name": "Deco_Bone_Skulls"
    },
    {
      "x": 1,
      "y": 4,
      "z": 2,
      "name": "Empty"
    },
    {
      "x": 1,
      "y": 5,
      "z": 2,
      "name": "Empty"
    },
    {
      "x": 1,
      "y": 2,
      "z": 3,
      "name": "Rock_Shale_Cobble"
    },
    {
      "x": 1,
      "y": 3,
      "z": 3,
      "name": "Rock_Shale_Cobble"
    },
    {
      "x": 1,
      "y": 4,
      "z": 3,
      "name": "Wood_Darkwood_Stairs"
    },
    {
      "x": 2,
      "y": 5,
      "z": -3,
      "name": "Wood_Fir_Branch_Long",
      "rotation": 4
    },
    {
      "x": 2,
      "y": 1,
      "z": -2,
      "name": "Wood_Fir_Trunk"
    },
    {
      "x": 2,
      "y": 2,
      "z": -2,
      "name": "Wood_Fir_Trunk"
    },
    {
      "x": 2,
      "y": 3,
      "z": -2,
      "name": "Wood_Fir_Trunk"
    },
    {
      "x": 2,
      "y": 4,
      "z": -2,
      "name": "Wood_Fir_Trunk"
    },
    {
      "x": 2,
      "y": 5,
      "z": -2,
      "name": "Wood_Fir_Trunk"
    },
    {
      "x": 2,
      "y": 6,
      "z": -2,
      "name": "Cloth_Roof_Blue_Flat"
    },
    {
      "x": 2,
      "y": 1,
      "z": -1,
      "name": "Soil_Pathway"
    },
    {
      "x": 2,
      "y": 2,
      "z": -1,
      "name": "Soil_Grass_Cold"
    },
    {
      "x": 2,
      "y": 3,
      "z": -1,
      "name": "Plant_Grass_Winter_Tall"
    },
    {
      "x": 2,
      "y": 4,
      "z": -1,
      "name": "Plant_Grass_Winter_Tall",
      "filler": 1024
    },
    {
      "x": 2,
      "y": 5,
      "z": -1,
      "name": "Wood_Fir_Branch_Long",
      "rotation": 4
    },
    {
      "x": 2,
      "y": 1,
      "z": 0,
      "name": "Soil_Pathway"
    },
    {
      "x": 2,
      "y": 2,
      "z": 0,
      "name": "Soil_Grass_Cold"
    },
    {
      "x": 2,
      "y": 3,
      "z": 0,
      "name": "Plant_Grass_Winter"
    },
    {
      "x": 2,
      "y": 4,
      "z": 0,
      "name": "Empty"
    },
    {
      "x": 2,
      "y": 5,
      "z": 0,
      "name": "Empty"
    },
    {
      "x": 2,
      "y": 2,
      "z": 1,
      "name": "Soil_Grass_Cold"
    },
    {
      "x": 2,
      "y": 3,
      "z": 1,
      "name": "Plant_Grass_Winter_Short"
    },
    {
      "x": 2,
      "y": 4,
      "z": 1,
      "name": "Empty"
    },
    {
      "x": 2,
      "y": 5,
      "z": 1,
      "name": "Empty"
    },
    {
      "x": 2,
      "y": 3,
      "z": 2,
      "name": "Wood_Fir_Trunk"
    },
    {
      "x": 2,
      "y": 4,
      "z": 2,
      "name": "Wood_Fir_Trunk"
    },
    {
      "x": 2,
      "y": 5,
      "z": 2,
      "name": "Empty"
    },
    {
      "x": 3,
      "y": 5,
      "z": -2,
      "name": "Cloth_Roof_Blue_Flap",
      "rotation": 1
    },
    {
      "x": 3,
      "y": 2,
      "z": -1,
      "name": "Soil_Pathway"
    },
    {
      "x": 3,
      "y": 3,
      "z": -1,
      "name": "Rock_Shale_Cobble"
    },
    {
      "x": 3,
      "y": 4,
      "z": -1,
      "name": "Wood_Darkwood_Stairs",
      "rotation": 1
    },
    {
      "x": 3,
      "y": 2,
      "z": 0,
      "name": "Rock_Shale_Cobble"
    },
    {
      "x": 3,
      "y": 3,
      "z": 0,
      "name": "Rock_Shale_Cobble"
    },
    {
      "x": 3,
      "y": 2,
      "z": 1,
      "name": "Rock_Shale_Cobble"
    },
    {
      "x": 3,
      "y": 3,
      "z": 1,
      "name": "Rock_Shale_Cobble"
    },
    {
      "x": 3,
      "y": 4,
      "z": 1,
      "name": "Wood_Darkwood_Stairs",
      "rotation": 1
    }
  ],
  "entities": [
    {
      "Components": {
        "Nameplate": {
          "Text": "Skeleton_Frost"
        },
        "HiddenFromAdventurePlayer": {},
        "SpawnMarkerComponent": {
          "SpawnMarker": "Skeleton_Frost",
          "RespawnTime": 0.0,
          "SpawnCount": 0,
          "PersistedFlock": {},
          "SpawnPosition": {
            "X": 0.0,
            "Y": 0.0,
            "Z": 0.0
          }
        },
        "Transform": {
          "Position": {
            "X": 1.177781249999498,
            "Y": 3.0,
            "Z": 1.5932042602539696
          },
          "Rotation": {
            "Pitch": 0.0,
            "Yaw": 6.611921787261963,
            "Roll": 0.0
          }
        },
        "Model": {
          "Model": {
            "Id": "NPC_Spawn_Marker",
            "Scale": 1.0
          }
        },
        "UUID": {
          "UUID": {
            "$binary": "BQEH0MWoOY6llBlcgxvW4Q==",
            "$type": "04"
          }
        },
        "HeadRotation": {
          "Rotation": {
            "Pitch": 0.0,
            "Yaw": 3.4703290462493896,
            "Roll": 0.0
          }
        }
      }
    }
  ]
}