{
  "version": 8,
  "blockIdVersion": 8,
  "anchorX": 24,
  "anchorY": 15,
  "anchorZ": 16,
  "blocks": [
    {
      "x": 14,
      "y": 15,
      "z": 9,
      "name": "Rock_Basalt"
    },
    {
      "x": 14,
      "y": 16,
      "z": 9,
      "name": "Rock_Basalt"
    },
    {
      "x": 14,
      "y": 17,
      "z": 9,
      "name": "Rock_Basalt"
    },
    {
      "x": 14,
      "y": 18,
      "z": 9,
      "name": "Rock_Basalt"
    },
    {
      "x": 14,
      "y": 19,
      "z": 9,
      "name": "Soil_Dirt_Burnt"
    },
    {
      "x": 14,
      "y": 18,
      "z": 10,
      "name": "Rock_Basalt"
    },
    {
      "x": 14,
      "y": 19,
      "z": 10,
      "name": "Soil_Dirt_Burnt"
    },
    {
      "x": 14,
      "y": 20,
      "z": 10,
      "name": "Soil_Dirt_Burnt"
    },
    {
      "x": 14,
      "y": 21,
      "z": 10,
      "name": "Soil_Grass_Burnt"
    },
    {
      "x": 14,
      "y": 19,
      "z": 11,
      "name": "Soil_Dirt_Burnt"
    },
    {
      "x": 14,
      "y": 20,
      "z": 11,
      "name": "Soil_Grass_Burnt"
    },
    {
      "x": 15,
      "y": 16,
      "z": 8,
      "name": "Rock_Basalt"
    },
    {
      "x": 15,
      "y": 17,
      "z": 8,
      "name": "Rock_Basalt"
    },
    {
      "x": 15,
      "y": 18,
      "z": 8,
      "name": "Rock_Basalt"
    },
    {
      "x": 15,
      "y": 19,
      "z": 8,
      "name": "Rock_Basalt"
    },
    {
      "x": 15,
      "y": 20,
      "z": 8,
      "name": "Soil_Grass_Burnt"
    },
    {
      "x": 15,
      "y": 14,
      "z": 9,
      "name": "Rock_Basalt"
    },
    {
      "x": 15,
      "y": 15,
      "z": 9,
      "name": "Rock_Basalt"
    },
    {
      "x": 15,
      "y": 16,
      "z": 9,
      "name": "Rock_Basalt"
    },
    {
      "x": 15,
      "y": 17,
      "z": 9,
      "name": "Rock_Basalt"
    },
    {
      "x": 15,
      "y": 18,
      "z": 9,
      "name": "Rock_Basalt"
    },
    {
      "x": 15,
      "y": 19,
      "z": 9,
      "name": "Rock_Basalt"
    },
    {
      "x": 15,
      "y": 20,
      "z": 9,
      "name": "Soil_Dirt_Burnt"
    },
    {
      "x": 15,
      "y": 21,
      "z": 9,
      "name": "Soil_Dirt_Burnt"
    },
    {
      "x": 15,
      "y": 22,
      "z": 9,
      "name": "Soil_Grass_Burnt"
    },
    {
      "x": 15,
      "y": 12,
      "z": 10,
      "name": "Rock_Basalt"
    },
    {
      "x": 15,
      "y": 13,
      "z": 10,
      "name": "Rock_Basalt"
    },
    {
      "x": 15,
      "y": 14,
      "z": 10,
      "name": "Rock_Basalt"
    },
    {
      "x": 15,
      "y": 15,
      "z": 10,
      "name": "Rock_Basalt"
    },
    {
      "x": 15,
      "y": 16,
      "z": 10,
      "name": "Rock_Basalt"
    },
    {
      "x": 15,
      "y": 17,
      "z": 10,
      "name": "Rock_Basalt"
    },
    {
      "x": 15,
      "y": 18,
      "z": 10,
      "name": "Rock_Basalt"
    },
    {
      "x": 15,
      "y": 19,
      "z": 10,
      "name": "Soil_Dirt_Burnt"
    },
    {
      "x": 15,
      "y": 20,
      "z": 10,
      "name": "Soil_Dirt_Burnt"
    },
    {
      "x": 15,
      "y": 21,
      "z": 10,
      "name": "Soil_Dirt_Burnt"
    },
    {
      "x": 15,
      "y": 22,
      "z": 10,
      "name": "Soil_Grass_Burnt"
    },
    {
      "x": 15,
      "y": 13,
      "z": 11,
      "name": "Rock_Basalt"
    },
    {
      "x": 15,
      "y": 14,
      "z": 11,
      "name": "Rock_Basalt"
    },
    {
      "x": 15,
      "y": 15,
      "z": 11,
      "name": "Rock_Basalt"
    },
    {
      "x": 15,
      "y": 16,
      "z": 11,
      "name": "Rock_Basalt"
    },
    {
      "x": 15,
      "y": 17,
      "z": 11,
      "name": "Rock_Basalt"
    },
    {
      "x": 15,
      "y": 18,
      "z": 11,
      "name": "Rock_Basalt"
    },
    {
      "x": 15,
      "y": 19,
      "z": 11,
      "name": "Rock_Basalt"
    },
    {
      "x": 15,
      "y": 20,
      "z": 11,
      "name": "Soil_Dirt_Burnt"
    },
    {
      "x": 15,
      "y": 21,
      "z": 11,
      "name": "Soil_Dirt_Burnt"
    },
    {
      "x": 15,
      "y": 22,
      "z": 11,
      "name": "Soil_Dirt_Burnt"
    },
    {
      "x": 15,
      "y": 23,
      "z": 11,
      "name": "Soil_Grass_Burnt"
    },
    {
      "x": 15,
      "y": 21,
      "z": 12,
      "name": "Soil_Dirt_Burnt"
    },
    {
      "x": 15,
      "y": 22,
      "z": 12,
      "name": "Soil_Dirt_Burnt"
    },
    {
      "x": 15,
      "y": 23,
      "z": 12,
      "name": "Soil_Dirt_Burnt"
    },
    {
      "x": 15,
      "y": 24,
      "z": 12,
      "name": "Soil_Grass_Burnt"
    },
    {
      "x": 15,
      "y": 22,
      "z": 13,
      "name": "Soil_Dirt_Burnt"
    },
    {
      "x": 15,
      "y": 23,
      "z": 13,
      "name": "Soil_Dirt_Burnt"
    },
    {
      "x": 15,
      "y": 24,
      "z": 13,
      "name": "Soil_Grass_Burnt"
    },
    {
      "x": 15,
      "y": 23,
      "z": 14,
      "name": "Soil_Dirt_Burnt"
    },
    {
      "x": 15,
      "y": 24,
      "z": 14,
      "name": "Soil_Grass_Burnt"
    },
    {
      "x": 15,
      "y": 17,
      "z": 25,
      "name": "Rock_Basalt"
    },
    {
      "x": 15,
      "y": 18,
      "z": 25,
      "name": "Rock_Basalt"
    },
    {
      "x": 15,
      "y": 19,
      "z": 25,
      "name": "Rock_Basalt"
    },
    {
      "x": 15,
      "y": 20,
      "z": 25,
      "name": "Rock_Basalt"
    },
    {
      "x": 15,
      "y": 15,
      "z": 26,
      "name": "Rock_Basalt"
    },
    {
      "x": 15,
      "y": 16,
      "z": 26,
      "name": "Rock_Basalt"
    },
    {
      "x": 15,
      "y": 17,
      "z": 26,
      "name": "Rock_Basalt"
    },
    {
      "x": 15,
      "y": 18,
      "z": 26,
      "name": "Rock_Basalt"
    },
    {
      "x": 15,
      "y": 19,
      "z": 26,
      "name": "Rock_Basalt"
    },
    {
      "x": 15,
      "y": 20,
      "z": 26,
      "name": "Soil_Dirt_Burnt"
    },
    {
      "x": 15,
      "y": 16,
      "z": 27,
      "name": "Rock_Basalt"
    },
    {
      "x": 15,
      "y": 17,
      "z": 27,
      "name": "Rock_Basalt"
    },
    {
      "x": 16,
      "y": 17,
      "z": 8,
      "name": "Rock_Basalt"
    },
    {
      "x": 16,
      "y": 18,
      "z": 8,
      "name": "Rock_Basalt"
    },
    {
      "x": 16,
      "y": 19,
      "z": 8,
      "name": "Rock_Basalt"
    },
    {
      "x": 16,
      "y": 20,
      "z": 8,
      "name": "Rock_Basalt"
    },
    {
      "x": 16,
      "y": 21,
      "z": 8,
      "name": "Soil_Grass_Burnt"
    },
    {
      "x": 16,
      "y": 12,
      "z": 9,
      "name": "Rock_Basalt"
    },
    {
      "x": 16,
      "y": 13,
      "z": 9,
      "name": "Rock_Basalt"
    },
    {
      "x": 16,
      "y": 14,
      "z": 9,
      "name": "Rock_Basalt"
    },
    {
      "x": 16,
      "y": 15,
      "z": 9,
      "name": "Rock_Basalt"
    },
    {
      "x": 16,
      "y": 16,
      "z": 9,
      "name": "Rock_Basalt"
    },
    {
      "x": 16,
      "y": 17,
      "z": 9,
      "name": "Rock_Basalt"
    },
    {
      "x": 16,
      "y": 18,
      "z": 9,
      "name": "Rock_Basalt"
    },
    {
      "x": 16,
      "y": 19,
      "z": 9,
      "name": "Rock_Basalt"
    },
    {
      "x": 16,
      "y": 20,
      "z": 9,
      "name": "Rock_Basalt"
    },
    {
      "x": 16,
      "y": 21,
      "z": 9,
      "name": "Soil_Dirt_Burnt"
    },
    {
      "x": 16,
      "y": 22,
      "z": 9,
      "name": "Soil_Dirt_Burnt"
    },
    {
      "x": 16,
      "y": 23,
      "z": 9,
      "name": "Soil_Grass_Burnt"
    },
    {
      "x": 16,
      "y": 24,
      "z": 9,
      "name": "Plant_Grass_Gnarled"
    },
    {
      "x": 16,
      "y": 11,
      "z": 10,
      "name": "Rock_Basalt"
    },
    {
      "x": 16,
      "y": 12,
      "z": 10,
      "name": "Rock_Basalt"
    },
    {
      "x": 16,
      "y": 13,
      "z": 10,
      "name": "Rock_Basalt"
    },
    {
      "x": 16,
      "y": 14,
      "z": 10,
      "name": "Rock_Basalt"
    },
    {
      "x": 16,
      "y": 15,
      "z": 10,
      "name": "Rock_Basalt"
    },
    {
      "x": 16,
      "y": 16,
      "z": 10,
      "name": "Rock_Basalt"
    },
    {
      "x": 16,
      "y": 17,
      "z": 10,
      "name": "Rock_Basalt"
    },
    {
      "x": 16,
      "y": 18,
      "z": 10,
      "name": "Rock_Basalt"
    },
    {
      "x": 16,
      "y": 19,
      "z": 10,
      "name": "Rock_Basalt"
    },
    {
      "x": 16,
      "y": 20,
      "z": 10,
      "name": "Soil_Dirt_Burnt"
    },
    {
      "x": 16,
      "y": 21,
      "z": 10,
      "name": "Soil_Dirt_Burnt"
    },
    {
      "x": 16,
      "y": 22,
      "z": 10,
      "name": "Soil_Dirt_Burnt"
    },
    {
      "x": 16,
      "y": 23,
      "z": 10,
      "name": "Soil_Dirt_Burnt"
    },
    {
      "x": 16,
      "y": 24,
      "z": 10,
      "name": "Soil_Grass_Burnt"
    },
    {
      "x": 16,
      "y": 11,
      "z": 11,
      "name": "Rock_Basalt"
    },
    {
      "x": 16,
      "y": 12,
      "z": 11,
      "name": "Rock_Basalt"
    },
    {
      "x": 16,
      "y": 13,
      "z": 11,
      "name": "Rock_Basalt"
    },
    {
      "x": 16,
      "y": 14,
      "z": 11,
      "name": "Rock_Basalt"
    },
    {
      "x": 16,
      "y": 15,
      "z": 11,
      "name": "Rock_Basalt"
    },
    {
      "x": 16,
      "y": 19,
      "z": 11,
      "name": "Rock_Basalt"
    },
    {
      "x": 16,
      "y": 20,
      "z": 11,
      "name": "Rock_Basalt"
    },
    {
      "x": 16,
      "y": 21,
      "z": 11,
      "name": "Soil_Dirt_Burnt"
    },
    {
      "x": 16,
      "y": 22,
      "z": 11,
      "name": "Soil_Dirt_Burnt"
    },
    {
      "x": 16,
      "y": 23,
      "z": 11,
      "name": "Soil_Dirt_Burnt"
    },
    {
      "x": 16,
      "y": 24,
      "z": 11,
      "name": "Soil_Grass_Burnt"
    },
    {
      "x": 16,
      "y": 25,
      "z": 11,
      "name": "Plant_Grass_Sharp"
    },
    {
      "x": 16,
      "y": 12,
      "z": 12,
      "name": "Rock_Basalt"
    },
    {
      "x": 16,
      "y": 13,
      "z": 12,
      "name": "Rock_Basalt"
    },
    {
      "x": 16,
      "y": 19,
      "z": 12,
      "name": "Rock_Basalt"
    },
    {
      "x": 16,
      "y": 20,
      "z": 12,
      "name": "Rock_Basalt"
    },
    {
      "x": 16,
      "y": 21,
      "z": 12,
      "name": "Rock_Basalt"
    },
    {
      "x": 16,
      "y": 22,
      "z": 12,
      "name": "Soil_Dirt_Burnt"
    },
    {
      "x": 16,
      "y": 23,
      "z": 12,
      "name": "Soil_Dirt_Burnt"
    },
    {
      "x": 16,
      "y": 24,
      "z": 12,
      "name": "Soil_Grass_Burnt"
    },
    {
      "x": 16,
      "y": 20,
      "z": 13,
      "name": "Rock_Basalt"
    },
    {
      "x": 16,
      "y": 21,
      "z": 13,
      "name": "Rock_Basalt"
    },
    {
      "x": 16,
      "y": 22,
      "z": 13,
      "name": "Rock_Basalt"
    },
    {
      "x": 16,
      "y": 23,
      "z": 13,
      "name": "Soil_Dirt_Burnt"
    },
    {
      "x": 16,
      "y": 24,
      "z": 13,
      "name": "Soil_Dirt_Burnt"
    },
    {
      "x": 16,
      "y": 25,
      "z": 13,
      "name": "Soil_Grass_Burnt"
    },
    {
      "x": 16,
      "y": 21,
      "z": 14,
      "name": "Rock_Basalt"
    },
    {
      "x": 16,
      "y": 22,
      "z": 14,
      "name": "Rock_Basalt"
    },
    {
      "x": 16,
      "y": 23,
      "z": 14,
      "name": "Soil_Dirt_Burnt"
    },
    {
      "x": 16,
      "y": 24,
      "z": 14,
      "name": "Soil_Dirt_Burnt"
    },
    {
      "x": 16,
      "y": 25,
      "z": 14,
      "name": "Soil_Grass_Burnt"
    },
    {
      "x": 16,
      "y": 26,
      "z": 14,
      "name": "Plant_Grass_Sharp"
    },
    {
      "x": 16,
      "y": 21,
      "z": 15,
      "name": "Rock_Basalt"
    },
    {
      "x": 16,
      "y": 22,
      "z": 15,
      "name": "Rock_Basalt"
    },
    {
      "x": 16,
      "y": 23,
      "z": 15,
      "name": "Rock_Basalt"
    },
    {
      "x": 16,
      "y": 24,
      "z": 15,
      "name": "Soil_Dirt_Burnt"
    },
    {
      "x": 16,
      "y": 25,
      "z": 15,
      "name": "Soil_Grass_Burnt"
    },
    {
      "x": 16,
      "y": 26,
      "z": 15,
      "name": "Plant_Grass_Sharp"
    },
    {
      "x": 16,
      "y": 24,
      "z": 16,
      "name": "Rock_Basalt"
    },
    {
      "x": 16,
      "y": 25,
      "z": 16,
      "name": "Soil_Grass_Burnt"
    },
    {
      "x": 16,
      "y": 25,
      "z": 17,
      "name": "Soil_Grass_Burnt"
    },
    {
      "x": 16,
      "y": 13,
      "z": 24,
      "name": "Rock_Basalt"
    },
    {
      "x": 16,
      "y": 14,
      "z": 24,
      "name": "Rock_Basalt"
    },
    {
      "x": 16,
      "y": 15,
      "z": 24,
      "name": "Rock_Basalt"
    },
    {
      "x": 16,
      "y": 16,
      "z": 24,
      "name": "Rock_Basalt"
    },
    {
      "x": 16,
      "y": 17,
      "z": 24,
      "name": "Rock_Basalt"
    },
    {
      "x": 16,
      "y": 18,
      "z": 24,
      "name": "Rock_Basalt"
    },
    {
      "x": 16,
      "y": 19,
      "z": 24,
      "name": "Rock_Basalt"
    },
    {
      "x": 16,
      "y": 20,
      "z": 24,
      "name": "Rock_Basalt"
    },
    {
      "x": 16,
      "y": 21,
      "z": 24,
      "name": "Soil_Grass_Burnt"
    },
    {
      "x": 16,
      "y": 14,
      "z": 25,
      "name": "Rock_Basalt"
    },
    {
      "x": 16,
      "y": 15,
      "z": 25,
      "name": "Rock_Basalt"
    },
    {
      "x": 16,
      "y": 16,
      "z": 25,
      "name": "Rock_Basalt"
    },
    {
      "x": 16,
      "y": 17,
      "z": 25,
      "name": "Rock_Basalt"
    },
    {
      "x": 16,
      "y": 18,
      "z": 25,
      "name": "Rock_Basalt"
    },
    {
      "x": 16,
      "y": 19,
      "z": 25,
      "name": "Rock_Basalt"
    },
    {
      "x": 16,
      "y": 20,
      "z": 25,
      "name": "Soil_Dirt_Burnt"
    },
    {
      "x": 16,
      "y": 21,
      "z": 25,
      "name": "Soil_Dirt_Burnt"
    },
    {
      "x": 16,
      "y": 22,
      "z": 25,
      "name": "Soil_Grass_Burnt"
    },
    {
      "x": 16,
      "y": 14,
      "z": 26,
      "name": "Rock_Basalt"
    },
    {
      "x": 16,
      "y": 15,
      "z": 26,
      "name": "Rock_Basalt"
    },
    {
      "x": 16,
      "y": 16,
      "z": 26,
      "name": "Rock_Basalt"
    },
    {
      "x": 16,
      "y": 17,
      "z": 26,
      "name": "Rock_Basalt"
    },
    {
      "x": 16,
      "y": 18,
      "z": 26,
      "name": "Rock_Basalt"
    },
    {
      "x": 16,
      "y": 19,
      "z": 26,
      "name": "Rock_Basalt"
    },
    {
      "x": 16,
      "y": 20,
      "z": 26,
      "name": "Soil_Dirt_Burnt"
    },
    {
      "x": 16,
      "y": 21,
      "z": 26,
      "name": "Soil_Dirt_Burnt"
    },
    {
      "x": 16,
      "y": 22,
      "z": 26,
      "name": "Soil_Grass_Burnt"
    },
    {
      "x": 16,
      "y": 16,
      "z": 27,
      "name": "Rock_Basalt"
    },
    {
      "x": 16,
      "y": 17,
      "z": 27,
      "name": "Rock_Basalt"
    },
    {
      "x": 16,
      "y": 18,
      "z": 27,
      "name": "Rock_Basalt"
    },
    {
      "x": 16,
      "y": 19,
      "z": 27,
      "name": "Rock_Basalt"
    },
    {
      "x": 17,
      "y": 20,
      "z": 8,
      "name": "Rock_Basalt"
    },
    {
      "x": 17,
      "y": 21,
      "z": 8,
      "name": "Rock_Basalt"
    },
    {
      "x": 17,
      "y": 22,
      "z": 8,
      "name": "Soil_Dirt_Burnt"
    },
    {
      "x": 17,
      "y": 23,
      "z": 8,
      "name": "Soil_Grass_Burnt"
    },
    {
      "x": 17,
      "y": 12,
      "z": 9,
      "name": "Rock_Basalt"
    },
    {
      "x": 17,
      "y": 13,
      "z": 9,
      "name": "Rock_Basalt"
    },
    {
      "x": 17,
      "y": 14,
      "z": 9,
      "name": "Rock_Basalt"
    },
    {
      "x": 17,
      "y": 15,
      "z": 9,
      "name": "Rock_Basalt"
    },
    {
      "x": 17,
      "y": 16,
      "z": 9,
      "name": "Rock_Basalt"
    },
    {
      "x": 17,
      "y": 17,
      "z": 9,
      "name": "Rock_Basalt"
    },
    {
      "x": 17,
      "y": 18,
      "z": 9,
      "name": "Rock_Basalt"
    },
    {
      "x": 17,
      "y": 19,
      "z": 9,
      "name": "Rock_Basalt"
    },
    {
      "x": 17,
      "y": 20,
      "z": 9,
      "name": "Rock_Basalt"
    },
    {
      "x": 17,
      "y": 21,
      "z": 9,
      "name": "Soil_Dirt_Burnt"
    },
    {
      "x": 17,
      "y": 22,
      "z": 9,
      "name": "Soil_Dirt_Burnt"
    },
    {
      "x": 17,
      "y": 23,
      "z": 9,
      "name": "Soil_Dirt_Burnt"
    },
    {
      "x": 17,
      "y": 24,
      "z": 9,
      "name": "Soil_Grass_Burnt"
    },
    {
      "x": 17,
      "y": 25,
      "z": 9,
      "name": "Plant_Grass_Sharp"
    },
    {
      "x": 17,
      "y": 12,
      "z": 10,
      "name": "Rock_Basalt"
    },
    {
      "x": 17,
      "y": 13,
      "z": 10,
      "name": "Rock_Basalt"
    },
    {
      "x": 17,
      "y": 14,
      "z": 10,
      "name": "Rock_Basalt"
    },
    {
      "x": 17,
      "y": 15,
      "z": 10,
      "name": "Rock_Basalt"
    },
    {
      "x": 17,
      "y": 16,
      "z": 10,
      "name": "Rock_Basalt"
    },
    {
      "x": 17,
      "y": 18,
      "z": 10,
      "name": "Rock_Basalt"
    },
    {
      "x": 17,
      "y": 19,
      "z": 10,
      "name": "Rock_Basalt"
    },
    {
      "x": 17,
      "y": 20,
      "z": 10,
      "name": "Rock_Basalt"
    },
    {
      "x": 17,
      "y": 21,
      "z": 10,
      "name": "Rock_Basalt"
    },
    {
      "x": 17,
      "y": 22,
      "z": 10,
      "name": "Soil_Dirt_Burnt"
    },
    {
      "x": 17,
      "y": 23,
      "z": 10,
      "name": "Soil_Dirt_Burnt"
    },
    {
      "x": 17,
      "y": 24,
      "z": 10,
      "name": "Soil_Grass_Burnt"
    },
    {
      "x": 17,
      "y": 11,
      "z": 11,
      "name": "Rock_Basalt"
    },
    {
      "x": 17,
      "y": 12,
      "z": 11,
      "name": "Rock_Basalt"
    },
    {
      "x": 17,
      "y": 13,
      "z": 11,
      "name": "Rock_Basalt"
    },
    {
      "x": 17,
      "y": 19,
      "z": 11,
      "name": "Rock_Basalt"
    },
    {
      "x": 17,
      "y": 20,
      "z": 11,
      "name": "Rock_Basalt"
    },
    {
      "x": 17,
      "y": 21,
      "z": 11,
      "name": "Rock_Basalt"
    },
    {
      "x": 17,
      "y": 22,
      "z": 11,
      "name": "Rock_Basalt"
    },
    {
      "x": 17,
      "y": 23,
      "z": 11,
      "name": "Soil_Dirt_Burnt"
    },
    {
      "x": 17,
      "y": 24,
      "z": 11,
      "name": "Soil_Grass_Burnt"
    },
    {
      "x": 17,
      "y": 11,
      "z": 12,
      "name": "Rock_Basalt"
    },
    {
      "x": 17,
      "y": 12,
      "z": 12,
      "name": "Rock_Basalt"
    },
    {
      "x": 17,
      "y": 19,
      "z": 12,
      "name": "Rock_Basalt"
    },
    {
      "x": 17,
      "y": 20,
      "z": 12,
      "name": "Rock_Basalt"
    },
    {
      "x": 17,
      "y": 21,
      "z": 12,
      "name": "Rock_Basalt"
    },
    {
      "x": 17,
      "y": 22,
      "z": 12,
      "name": "Rock_Basalt"
    },
    {
      "x": 17,
      "y": 23,
      "z": 12,
      "name": "Soil_Dirt_Burnt"
    },
    {
      "x": 17,
      "y": 24,
      "z": 12,
      "name": "Soil_Dirt_Burnt"
    },
    {
      "x": 17,
      "y": 25,
      "z": 12,
      "name": "Soil_Grass_Burnt"
    },
    {
      "x": 17,
      "y": 10,
      "z": 13,
      "name": "Rock_Basalt"
    },
    {
      "x": 17,
      "y": 11,
      "z": 13,
      "name": "Rock_Basalt"
    },
    {
      "x": 17,
      "y": 12,
      "z": 13,
      "name": "Rock_Basalt"
    },
    {
      "x": 17,
      "y": 20,
      "z": 13,
      "name": "Rock_Basalt"
    },
    {
      "x": 17,
      "y": 21,
      "z": 13,
      "name": "Rock_Basalt"
    },
    {
      "x": 17,
      "y": 22,
      "z": 13,
      "name": "Rock_Basalt"
    },
    {
      "x": 17,
      "y": 23,
      "z": 13,
      "name": "Soil_Dirt_Burnt"
    },
    {
      "x": 17,
      "y": 24,
      "z": 13,
      "name": "Soil_Dirt_Burnt"
    },
    {
      "x": 17,
      "y": 25,
      "z": 13,
      "name": "Soil_Grass_Burnt"
    },
    {
      "x": 17,
      "y": 26,
      "z": 13,
      "name": "Plant_Grass_Sharp"
    },
    {
      "x": 17,
      "y": 21,
      "z": 14,
      "name": "Rock_Basalt"
    },
    {
      "x": 17,
      "y": 22,
      "z": 14,
      "name": "Rock_Basalt"
    },
    {
      "x": 17,
      "y": 23,
      "z": 14,
      "name": "Rock_Basalt"
    },
    {
      "x": 17,
      "y": 24,
      "z": 14,
      "name": "Soil_Dirt_Burnt"
    },
    {
      "x": 17,
      "y": 25,
      "z": 14,
      "name": "Soil_Grass_Burnt"
    },
    {
      "x": 17,
      "y": 26,
      "z": 14,
      "name": "Plant_Grass_Sharp_Tall"
    },
    {
      "x": 17,
      "y": 27,
      "z": 14,
      "name": "Plant_Grass_Sharp_Tall",
      "filler": 1024
    },
    {
      "x": 17,
      "y": 21,
      "z": 15,
      "name": "Rock_Basalt"
    },
    {
      "x": 17,
      "y": 22,
      "z": 15,
      "name": "Rock_Basalt"
    },
    {
      "x": 17,
      "y": 23,
      "z": 15,
      "name": "Rock_Basalt"
    },
    {
      "x": 17,
      "y": 24,
      "z": 15,
      "name": "Soil_Dirt_Burnt"
    },
    {
      "x": 17,
      "y": 25,
      "z": 15,
      "name": "Soil_Grass_Burnt"
    },
    {
      "x": 17,
      "y": 26,
      "z": 15,
      "name": "Plant_Grass_Sharp_Tall"
    },
    {
      "x": 17,
      "y": 27,
      "z": 15,
      "name": "Plant_Grass_Sharp_Tall",
      "filler": 1024
    },
    {
      "x": 17,
      "y": 23,
      "z": 16,
      "name": "Rock_Basalt"
    },
    {
      "x": 17,
      "y": 24,
      "z": 16,
      "name": "Rock_Basalt"
    },
    {
      "x": 17,
      "y": 25,
      "z": 16,
      "name": "Soil_Grass_Burnt"
    },
    {
      "x": 17,
      "y": 26,
      "z": 16,
      "name": "Plant_Grass_Sharp_Tall"
    },
    {
      "x": 17,
      "y": 27,
      "z": 16,
      "name": "Plant_Grass_Sharp_Tall",
      "filler": 1024
    },
    {
      "x": 17,
      "y": 24,
      "z": 17,
      "name": "Rock_Basalt"
    },
    {
      "x": 17,
      "y": 25,
      "z": 17,
      "name": "Soil_Grass_Burnt"
    },
    {
      "x": 17,
      "y": 24,
      "z": 18,
      "name": "Soil_Dirt_Burnt"
    },
    {
      "x": 17,
      "y": 25,
      "z": 18,
      "name": "Soil_Grass_Burnt"
    },
    {
      "x": 17,
      "y": 25,
      "z": 19,
      "name": "Soil_Grass_Burnt"
    },
    {
      "x": 17,
      "y": 25,
      "z": 20,
      "name": "Soil_Grass_Burnt"
    },
    {
      "x": 17,
      "y": 14,
      "z": 23,
      "name": "Rock_Basalt"
    },
    {
      "x": 17,
      "y": 22,
      "z": 23,
      "name": "Soil_Dirt_Burnt"
    },
    {
      "x": 17,
      "y": 23,
      "z": 23,
      "name": "Soil_Grass_Burnt"
    },
    {
      "x": 17,
      "y": 12,
      "z": 24,
      "name": "Rock_Basalt"
    },
    {
      "x": 17,
      "y": 13,
      "z": 24,
      "name": "Rock_Basalt"
    },
    {
      "x": 17,
      "y": 14,
      "z": 24,
      "name": "Rock_Basalt"
    },
    {
      "x": 17,
      "y": 15,
      "z": 24,
      "name": "Rock_Basalt"
    },
    {
      "x": 17,
      "y": 16,
      "z": 24,
      "name": "Rock_Basalt"
    },
    {
      "x": 17,
      "y": 17,
      "z": 24,
      "name": "Rock_Basalt"
    },
    {
      "x": 17,
      "y": 20,
      "z": 24,
      "name": "Rock_Basalt"
    },
    {
      "x": 17,
      "y": 21,
      "z": 24,
      "name": "Soil_Dirt_Burnt"
    },
    {
      "x": 17,
      "y": 22,
      "z": 24,
      "name": "Soil_Dirt_Burnt"
    },
    {
      "x": 17,
      "y": 23,
      "z": 24,
      "name": "Soil_Dirt_Burnt"
    },
    {
      "x": 17,
      "y": 24,
      "z": 24,
      "name": "Soil_Grass_Burnt"
    },
    {
      "x": 17,
      "y": 25,
      "z": 24,
      "name": "Plant_Grass_Sharp"
    },
    {
      "x": 17,
      "y": 12,
      "z": 25,
      "name": "Rock_Basalt"
    },
    {
      "x": 17,
      "y": 13,
      "z": 25,
      "name": "Rock_Basalt"
    },
    {
      "x": 17,
      "y": 14,
      "z": 25,
      "name": "Rock_Basalt"
    },
    {
      "x": 17,
      "y": 15,
      "z": 25,
      "name": "Rock_Basalt"
    },
    {
      "x": 17,
      "y": 16,
      "z": 25,
      "name": "Rock_Basalt"
    },
    {
      "x": 17,
      "y": 17,
      "z": 25,
      "name": "Rock_Basalt"
    },
    {
      "x": 17,
      "y": 18,
      "z": 25,
      "name": "Rock_Basalt"
    },
    {
      "x": 17,
      "y": 19,
      "z": 25,
      "name": "Rock_Basalt"
    },
    {
      "x": 17,
      "y": 20,
      "z": 25,
      "name": "Rock_Basalt"
    },
    {
      "x": 17,
      "y": 21,
      "z": 25,
      "name": "Soil_Dirt_Burnt"
    },
    {
      "x": 17,
      "y": 22,
      "z": 25,
      "name": "Soil_Dirt_Burnt"
    },
    {
      "x": 17,
      "y": 23,
      "z": 25,
      "name": "Soil_Grass_Burnt"
    },
    {
      "x": 17,
      "y": 24,
      "z": 25,
      "name": "Plant_Grass_Sharp"
    },
    {
      "x": 17,
      "y": 14,
      "z": 26,
      "name": "Rock_Basalt"
    },
    {
      "x": 17,
      "y": 15,
      "z": 26,
      "name": "Rock_Basalt"
    },
    {
      "x": 17,
      "y": 16,
      "z": 26,
      "name": "Rock_Basalt"
    },
    {
      "x": 17,
      "y": 17,
      "z": 26,
      "name": "Rock_Basalt"
    },
    {
      "x": 17,
      "y": 18,
      "z": 26,
      "name": "Rock_Basalt"
    },
    {
      "x": 17,
      "y": 19,
      "z": 26,
      "name": "Rock_Basalt"
    },
    {
      "x": 17,
      "y": 20,
      "z": 26,
      "name": "Soil_Dirt_Burnt"
    },
    {
      "x": 17,
      "y": 21,
      "z": 26,
      "name": "Soil_Dirt_Burnt"
    },
    {
      "x": 17,
      "y": 22,
      "z": 26,
      "name": "Soil_Grass_Burnt"
    },
    {
      "x": 17,
      "y": 23,
      "z": 26,
      "name": "Plant_Grass_Sharp_Tall"
    },
    {
      "x": 17,
      "y": 24,
      "z": 26,
      "name": "Plant_Grass_Sharp_Tall",
      "filler": 1024
    },
    {
      "x": 17,
      "y": 15,
      "z": 27,
      "name": "Rock_Basalt"
    },
    {
      "x": 17,
      "y": 16,
      "z": 27,
      "name": "Rock_Basalt"
    },
    {
      "x": 17,
      "y": 17,
      "z": 27,
      "name": "Rock_Basalt"
    },
    {
      "x": 17,
      "y": 18,
      "z": 27,
      "name": "Rock_Basalt"
    },
    {
      "x": 17,
      "y": 19,
      "z": 27,
      "name": "Rock_Basalt"
    },
    {
      "x": 17,
      "y": 20,
      "z": 27,
      "name": "Rock_Basalt"
    },
    {
      "x": 17,
      "y": 21,
      "z": 27,
      "name": "Soil_Grass_Burnt"
    },
    {
      "x": 18,
      "y": 22,
      "z": 8,
      "name": "Rock_Basalt"
    },
    {
      "x": 18,
      "y": 23,
      "z": 8,
      "name": "Soil_Grass_Burnt"
    },
    {
      "x": 18,
      "y": 24,
      "z": 8,
      "name": "Plant_Grass_Sharp"
    },
    {
      "x": 18,
      "y": 19,
      "z": 9,
      "name": "Rock_Basalt"
    },
    {
      "x": 18,
      "y": 20,
      "z": 9,
      "name": "Rock_Basalt"
    },
    {
      "x": 18,
      "y": 21,
      "z": 9,
      "name": "Rock_Basalt"
    },
    {
      "x": 18,
      "y": 22,
      "z": 9,
      "name": "Soil_Dirt_Burnt"
    },
    {
      "x": 18,
      "y": 23,
      "z": 9,
      "name": "Soil_Dirt_Burnt"
    },
    {
      "x": 18,
      "y": 24,
      "z": 9,
      "name": "Soil_Grass_Burnt"
    },
    {
      "x": 18,
      "y": 25,
      "z": 9,
      "name": "Plant_Grass_Sharp"
    },
    {
      "x": 18,
      "y": 12,
      "z": 10,
      "name": "Rock_Basalt"
    },
    {
      "x": 18,
      "y": 13,
      "z": 10,
      "name": "Rock_Basalt"
    },
    {
      "x": 18,
      "y": 14,
      "z": 10,
      "name": "Rock_Basalt"
    },
    {
      "x": 18,
      "y": 20,
      "z": 10,
      "name": "Rock_Basalt"
    },
    {
      "x": 18,
      "y": 21,
      "z": 10,
      "name": "Rock_Basalt"
    },
    {
      "x": 18,
      "y": 22,
      "z": 10,
      "name": "Rock_Basalt"
    },
    {
      "x": 18,
      "y": 23,
      "z": 10,
      "name": "Soil_Dirt_Burnt"
    },
    {
      "x": 18,
      "y": 24,
      "z": 10,
      "name": "Soil_Dirt_Burnt"
    },
    {
      "x": 18,
      "y": 25,
      "z": 10,
      "name": "Soil_Grass_Burnt"
    },
    {
      "x": 18,
      "y": 11,
      "z": 11,
      "name": "Rock_Basalt"
    },
    {
      "x": 18,
      "y": 12,
      "z": 11,
      "name": "Rock_Basalt"
    },
    {
      "x": 18,
      "y": 13,
      "z": 11,
      "name": "Rock_Basalt"
    },
    {
      "x": 18,
      "y": 20,
      "z": 11,
      "name": "Rock_Basalt"
    },
    {
      "x": 18,
      "y": 21,
      "z": 11,
      "name": "Rock_Basalt"
    },
    {
      "x": 18,
      "y": 22,
      "z": 11,
      "name": "Rock_Basalt"
    },
    {
      "x": 18,
      "y": 23,
      "z": 11,
      "name": "Soil_Dirt_Burnt"
    },
    {
      "x": 18,
      "y": 24,
      "z": 11,
      "name": "Soil_Dirt_Burnt"
    },
    {
      "x": 18,
      "y": 25,
      "z": 11,
      "name": "Soil_Dirt_Burnt"
    },
    {
      "x": 18,
      "y": 26,
      "z": 11,
      "name": "Soil_Grass_Burnt"
    },
    {
      "x": 18,
      "y": 27,
      "z": 11,
      "name": "Plant_Grass_Gnarled"
    },
    {
      "x": 18,
      "y": 10,
      "z": 12,
      "name": "Rock_Basalt"
    },
    {
      "x": 18,
      "y": 11,
      "z": 12,
      "name": "Rock_Basalt"
    },
    {
      "x": 18,
      "y": 20,
      "z": 12,
      "name": "Rock_Basalt"
    },
    {
      "x": 18,
      "y": 21,
      "z": 12,
      "name": "Rock_Basalt"
    },
    {
      "x": 18,
      "y": 22,
      "z": 12,
      "name": "Rock_Basalt"
    },
    {
      "x": 18,
      "y": 23,
      "z": 12,
      "name": "Rock_Basalt"
    },
    {
      "x": 18,
      "y": 24,
      "z": 12,
      "name": "Soil_Dirt_Burnt"
    },
    {
      "x": 18,
      "y": 25,
      "z": 12,
      "name": "Soil_Dirt_Burnt"
    },
    {
      "x": 18,
      "y": 26,
      "z": 12,
      "name": "Soil_Grass_Burnt"
    },
    {
      "x": 18,
      "y": 27,
      "z": 12,
      "name": "Plant_Grass_Gnarled"
    },
    {
      "x": 18,
      "y": 10,
      "z": 13,
      "name": "Rock_Basalt"
    },
    {
      "x": 18,
      "y": 20,
      "z": 13,
      "name": "Rock_Basalt"
    },
    {
      "x": 18,
      "y": 21,
      "z": 13,
      "name": "Rock_Basalt"
    },
    {
      "x": 18,
      "y": 22,
      "z": 13,
      "name": "Rock_Basalt"
    },
    {
      "x": 18,
      "y": 23,
      "z": 13,
      "name": "Rock_Basalt"
    },
    {
      "x": 18,
      "y": 24,
      "z": 13,
      "name": "Soil_Dirt_Burnt"
    },
    {
      "x": 18,
      "y": 25,
      "z": 13,
      "name": "Soil_Dirt_Burnt"
    },
    {
      "x": 18,
      "y": 26,
      "z": 13,
      "name": "Soil_Dirt_Burnt"
    },
    {
      "x": 18,
      "y": 27,
      "z": 13,
      "name": "Soil_Grass_Burnt"
    },
    {
      "x": 18,
      "y": 9,
      "z": 14,
      "name": "Rock_Basalt"
    },
    {
      "x": 18,
      "y": 10,
      "z": 14,
      "name": "Rock_Basalt"
    },
    {
      "x": 18,
      "y": 20,
      "z": 14,
      "name": "Rock_Basalt"
    },
    {
      "x": 18,
      "y": 21,
      "z": 14,
      "name": "Rock_Basalt"
    },
    {
      "x": 18,
      "y": 22,
      "z": 14,
      "name": "Rock_Basalt"
    },
    {
      "x": 18,
      "y": 23,
      "z": 14,
      "name": "Rock_Basalt"
    },
    {
      "x": 18,
      "y": 24,
      "z": 14,
      "name": "Soil_Dirt_Burnt"
    },
    {
      "x": 18,
      "y": 25,
      "z": 14,
      "name": "Soil_Dirt_Burnt"
    },
    {
      "x": 18,
      "y": 26,
      "z": 14,
      "name": "Soil_Dirt_Burnt"
    },
    {
      "x": 18,
      "y": 27,
      "z": 14,
      "name": "Soil_Grass_Burnt"
    },
    {
      "x": 18,
      "y": 22,
      "z": 15,
      "name": "Rock_Basalt"
    },
    {
      "x": 18,
      "y": 23,
      "z": 15,
      "name": "Rock_Basalt"
    },
    {
      "x": 18,
      "y": 24,
      "z": 15,
      "name": "Soil_Dirt_Burnt"
    },
    {
      "x": 18,
      "y": 25,
      "z": 15,
      "name": "Soil_Dirt_Burnt"
    },
    {
      "x": 18,
      "y": 26,
      "z": 15,
      "name": "Soil_Dirt_Burnt"
    },
    {
      "x": 18,
      "y": 27,
      "z": 15,
      "name": "Soil_Grass_Burnt"
    },
    {
      "x": 18,
      "y": 22,
      "z": 16,
      "name": "Rock_Basalt"
    },
    {
      "x": 18,
      "y": 23,
      "z": 16,
      "name": "Rock_Basalt"
    },
    {
      "x": 18,
      "y": 24,
      "z": 16,
      "name": "Soil_Dirt_Burnt"
    },
    {
      "x": 18,
      "y": 25,
      "z": 16,
      "name": "Soil_Dirt_Burnt"
    },
    {
      "x": 18,
      "y": 26,
      "z": 16,
      "name": "Soil_Grass_Burnt"
    },
    {
      "x": 18,
      "y": 24,
      "z": 17,
      "name": "Soil_Dirt_Burnt"
    },
    {
      "x": 18,
      "y": 25,
      "z": 17,
      "name": "Soil_Dirt_Burnt"
    },
    {
      "x": 18,
      "y": 26,
      "z": 17,
      "name": "Soil_Grass_Burnt"
    },
    {
      "x": 18,
      "y": 24,
      "z": 18,
      "name": "Soil_Dirt_Burnt"
    },
    {
      "x": 18,
      "y": 25,
      "z": 18,
      "name": "Soil_Dirt_Burnt"
    },
    {
      "x": 18,
      "y": 26,
      "z": 18,
      "name": "Soil_Grass_Burnt"
    },
    {
      "x": 18,
      "y": 24,
      "z": 19,
      "name": "Soil_Dirt_Burnt"
    },
    {
      "x": 18,
      "y": 25,
      "z": 19,
      "name": "Soil_Grass_Burnt"
    },
    {
      "x": 18,
      "y": 26,
      "z": 19,
      "name": "Plant_Grass_Sharp"
    },
    {
      "x": 18,
      "y": 23,
      "z": 20,
      "name": "Rock_Basalt"
    },
    {
      "x": 18,
      "y": 24,
      "z": 20,
      "name": "Rock_Basalt"
    },
    {
      "x": 18,
      "y": 25,
      "z": 20,
      "name": "Soil_Grass_Burnt"
    },
    {
      "x": 18,
      "y": 26,
      "z": 20,
      "name": "Plant_Grass_Sharp"
    },
    {
      "x": 18,
      "y": 23,
      "z": 21,
      "name": "Rock_Basalt"
    },
    {
      "x": 18,
      "y": 24,
      "z": 21,
      "name": "Soil_Grass_Burnt"
    },
    {
      "x": 18,
      "y": 21,
      "z": 22,
      "name": "Rock_Basalt"
    },
    {
      "x": 18,
      "y": 22,
      "z": 22,
      "name": "Rock_Basalt"
    },
    {
      "x": 18,
      "y": 23,
      "z": 22,
      "name": "Rock_Basalt"
    },
    {
      "x": 18,
      "y": 24,
      "z": 22,
      "name": "Soil_Grass_Burnt"
    },
    {
      "x": 18,
      "y": 25,
      "z": 22,
      "name": "Plant_Grass_Sharp"
    },
    {
      "x": 18,
      "y": 11,
      "z": 23,
      "name": "Rock_Basalt"
    },
    {
      "x": 18,
      "y": 12,
      "z": 23,
      "name": "Rock_Basalt"
    },
    {
      "x": 18,
      "y": 13,
      "z": 23,
      "name": "Rock_Basalt"
    },
    {
      "x": 18,
      "y": 14,
      "z": 23,
      "name": "Rock_Basalt"
    },
    {
      "x": 18,
      "y": 21,
      "z": 23,
      "name": "Rock_Basalt"
    },
    {
      "x": 18,
      "y": 22,
      "z": 23,
      "name": "Rock_Basalt"
    },
    {
      "x": 18,
      "y": 23,
      "z": 23,
      "name": "Soil_Dirt_Burnt"
    },
    {
      "x": 18,
      "y": 24,
      "z": 23,
      "name": "Soil_Grass_Burnt"
    },
    {
      "x": 18,
      "y": 11,
      "z": 24,
      "name": "Rock_Basalt"
    },
    {
      "x": 18,
      "y": 12,
      "z": 24,
      "name": "Rock_Basalt"
    },
    {
      "x": 18,
      "y": 13,
      "z": 24,
      "name": "Rock_Basalt"
    },
    {
      "x": 18,
      "y": 14,
      "z": 24,
      "name": "Rock_Basalt"
    },
    {
      "x": 18,
      "y": 15,
      "z": 24,
      "name": "Rock_Basalt"
    },
    {
      "x": 18,
      "y": 21,
      "z": 24,
      "name": "Rock_Basalt"
    },
    {
      "x": 18,
      "y": 22,
      "z": 24,
      "name": "Soil_Dirt_Burnt"
    },
    {
      "x": 18,
      "y": 23,
      "z": 24,
      "name": "Soil_Dirt_Burnt"
    },
    {
      "x": 18,
      "y": 24,
      "z": 24,
      "name": "Soil_Grass_Burnt"
    },
    {
      "x": 18,
      "y": 25,
      "z": 24,
      "name": "Plant_Grass_Sharp"
    },
    {
      "x": 18,
      "y": 12,
      "z": 25,
      "name": "Rock_Basalt"
    },
    {
      "x": 18,
      "y": 13,
      "z": 25,
      "name": "Rock_Basalt"
    },
    {
      "x": 18,
      "y": 14,
      "z": 25,
      "name": "Rock_Basalt"
    },
    {
      "x": 18,
      "y": 15,
      "z": 25,
      "name": "Rock_Basalt"
    },
    {
      "x": 18,
      "y": 16,
      "z": 25,
      "name": "Rock_Basalt"
    },
    {
      "x": 18,
      "y": 19,
      "z": 25,
      "name": "Rock_Basalt"
    },
    {
      "x": 18,
      "y": 20,
      "z": 25,
      "name": "Rock_Basalt"
    },
    {
      "x": 18,
      "y": 21,
      "z": 25,
      "name": "Soil_Dirt_Burnt"
    },
    {
      "x": 18,
      "y": 22,
      "z": 25,
      "name": "Soil_Dirt_Burnt"
    },
    {
      "x": 18,
      "y": 23,
      "z": 25,
      "name": "Soil_Dirt_Burnt"
    },
    {
      "x": 18,
      "y": 24,
      "z": 25,
      "name": "Soil_Grass_Burnt"
    },
    {
      "x": 18,
      "y": 13,
      "z": 26,
      "name": "Rock_Basalt"
    },
    {
      "x": 18,
      "y": 14,
      "z": 26,
      "name": "Rock_Basalt"
    },
    {
      "x": 18,
      "y": 15,
      "z": 26,
      "name": "Rock_Basalt"
    },
    {
      "x": 18,
      "y": 16,
      "z": 26,
      "name": "Rock_Basalt"
    },
    {
      "x": 18,
      "y": 17,
      "z": 26,
      "name": "Rock_Basalt"
    },
    {
      "x": 18,
      "y": 18,
      "z": 26,
      "name": "Rock_Basalt"
    },
    {
      "x": 18,
      "y": 19,
      "z": 26,
      "name": "Rock_Basalt"
    },
    {
      "x": 18,
      "y": 20,
      "z": 26,
      "name": "Rock_Basalt"
    },
    {
      "x": 18,
      "y": 21,
      "z": 26,
      "name": "Soil_Dirt_Burnt"
    },
    {
      "x": 18,
      "y": 22,
      "z": 26,
      "name": "Soil_Grass_Burnt"
    },
    {
      "x": 18,
      "y": 23,
      "z": 26,
      "name": "Plant_Grass_Sharp_Tall"
    },
    {
      "x": 18,
      "y": 24,
      "z": 26,
      "name": "Plant_Grass_Sharp_Tall",
      "filler": 1024
    },
    {
      "x": 18,
      "y": 17,
      "z": 27,
      "name": "Rock_Basalt"
    },
    {
      "x": 18,
      "y": 18,
      "z": 27,
      "name": "Rock_Basalt"
    },
    {
      "x": 18,
      "y": 19,
      "z": 27,
      "name": "Rock_Basalt"
    },
    {
      "x": 18,
      "y": 20,
      "z": 27,
      "name": "Rock_Basalt"
    },
    {
      "x": 19,
      "y": 22,
      "z": 8,
      "name": "Rock_Basalt"
    },
    {
      "x": 19,
      "y": 23,
      "z": 8,
      "name": "Soil_Grass_Burnt"
    },
    {
      "x": 19,
      "y": 22,
      "z": 9,
      "name": "Rock_Basalt"
    },
    {
      "x": 19,
      "y": 23,
      "z": 9,
      "name": "Rock_Basalt"
    },
    {
      "x": 19,
      "y": 24,
      "z": 9,
      "name": "Soil_Grass_Burnt"
    },
    {
      "x": 19,
      "y": 20,
      "z": 10,
      "name": "Rock_Basalt"
    },
    {
      "x": 19,
      "y": 21,
      "z": 10,
      "name": "Rock_Basalt"
    },
    {
      "x": 19,
      "y": 22,
      "z": 10,
      "name": "Rock_Basalt"
    },
    {
      "x": 19,
      "y": 23,
      "z": 10,
      "name": "Soil_Dirt_Burnt"
    },
    {
      "x": 19,
      "y": 24,
      "z": 10,
      "name": "Soil_Dirt_Burnt"
    },
    {
      "x": 19,
      "y": 25,
      "z": 10,
      "name": "Soil_Grass_Burnt"
    },
    {
      "x": 19,
      "y": 26,
      "z": 10,
      "name": "Plant_Grass_Sharp_Tall"
    },
    {
      "x": 19,
      "y": 27,
      "z": 10,
      "name": "Plant_Grass_Sharp_Tall",
      "filler": 1024
    },
    {
      "x": 19,
      "y": 10,
      "z": 11,
      "name": "Rock_Basalt"
    },
    {
      "x": 19,
      "y": 11,
      "z": 11,
      "name": "Rock_Basalt"
    },
    {
      "x": 19,
      "y": 12,
      "z": 11,
      "name": "Rock_Basalt"
    },
    {
      "x": 19,
      "y": 20,
      "z": 11,
      "name": "Rock_Basalt"
    },
    {
      "x": 19,
      "y": 21,
      "z": 11,
      "name": "Rock_Basalt"
    },
    {
      "x": 19,
      "y": 22,
      "z": 11,
      "name": "Rock_Basalt"
    },
    {
      "x": 19,
      "y": 23,
      "z": 11,
      "name": "Rock_Basalt"
    },
    {
      "x": 19,
      "y": 24,
      "z": 11,
      "name": "Soil_Dirt_Burnt"
    },
    {
      "x": 19,
      "y": 25,
      "z": 11,
      "name": "Soil_Dirt_Burnt"
    },
    {
      "x": 19,
      "y": 26,
      "z": 11,
      "name": "Soil_Grass_Burnt"
    },
    {
      "x": 19,
      "y": 9,
      "z": 12,
      "name": "Rock_Basalt"
    },
    {
      "x": 19,
      "y": 10,
      "z": 12,
      "name": "Rock_Basalt"
    },
    {
      "x": 19,
      "y": 11,
      "z": 12,
      "name": "Rock_Basalt"
    },
    {
      "x": 19,
      "y": 20,
      "z": 12,
      "name": "Rock_Basalt"
    },
    {
      "x": 19,
      "y": 21,
      "z": 12,
      "name": "Rock_Basalt"
    },
    {
      "x": 19,
      "y": 22,
      "z": 12,
      "name": "Rock_Basalt"
    },
    {
      "x": 19,
      "y": 23,
      "z": 12,
      "name": "Rock_Basalt"
    },
    {
      "x": 19,
      "y": 24,
      "z": 12,
      "name": "Rock_Basalt"
    },
    {
      "x": 19,
      "y": 25,
      "z": 12,
      "name": "Soil_Dirt_Burnt"
    },
    {
      "x": 19,
      "y": 26,
      "z": 12,
      "name": "Soil_Dirt_Burnt"
    },
    {
      "x": 19,
      "y": 27,
      "z": 12,
      "name": "Soil_Grass_Burnt"
    },
    {
      "x": 19,
      "y": 9,
      "z": 13,
      "name": "Rock_Basalt"
    },
    {
      "x": 19,
      "y": 10,
      "z": 13,
      "name": "Rock_Basalt"
    },
    {
      "x": 19,
      "y": 20,
      "z": 13,
      "name": "Rock_Basalt"
    },
    {
      "x": 19,
      "y": 21,
      "z": 13,
      "name": "Rock_Basalt"
    },
    {
      "x": 19,
      "y": 22,
      "z": 13,
      "name": "Rock_Basalt"
    },
    {
      "x": 19,
      "y": 23,
      "z": 13,
      "name": "Rock_Basalt"
    },
    {
      "x": 19,
      "y": 24,
      "z": 13,
      "name": "Rock_Basalt"
    },
    {
      "x": 19,
      "y": 25,
      "z": 13,
      "name": "Rock_Basalt"
    },
    {
      "x": 19,
      "y": 26,
      "z": 13,
      "name": "Soil_Dirt_Burnt"
    },
    {
      "x": 19,
      "y": 27,
      "z": 13,
      "name": "Soil_Grass_Burnt"
    },
    {
      "x": 19,
      "y": 28,
      "z": 13,
      "name": "Plant_Grass_Gnarled"
    },
    {
      "x": 19,
      "y": 8,
      "z": 14,
      "name": "Rock_Basalt"
    },
    {
      "x": 19,
      "y": 9,
      "z": 14,
      "name": "Rock_Basalt"
    },
    {
      "x": 19,
      "y": 20,
      "z": 14,
      "name": "Rock_Basalt"
    },
    {
      "x": 19,
      "y": 21,
      "z": 14,
      "name": "Rock_Basalt"
    },
    {
      "x": 19,
      "y": 22,
      "z": 14,
      "name": "Rock_Basalt"
    },
    {
      "x": 19,
      "y": 23,
      "z": 14,
      "name": "Rock_Basalt"
    },
    {
      "x": 19,
      "y": 24,
      "z": 14,
      "name": "Rock_Basalt"
    },
    {
      "x": 19,
      "y": 25,
      "z": 14,
      "name": "Soil_Dirt_Burnt"
    },
    {
      "x": 19,
      "y": 26,
      "z": 14,
      "name": "Soil_Dirt_Burnt"
    },
    {
      "x": 19,
      "y": 27,
      "z": 14,
      "name": "Soil_Grass_Burnt"
    },
    {
      "x": 19,
      "y": 28,
      "z": 14,
      "name": "Plant_Grass_Gnarled"
    },
    {
      "x": 19,
      "y": 22,
      "z": 15,
      "name": "Rock_Basalt"
    },
    {
      "x": 19,
      "y": 23,
      "z": 15,
      "name": "Rock_Basalt"
    },
    {
      "x": 19,
      "y": 24,
      "z": 15,
      "name": "Soil_Dirt_Burnt"
    },
    {
      "x": 19,
      "y": 25,
      "z": 15,
      "name": "Soil_Dirt_Burnt"
    },
    {
      "x": 19,
      "y": 26,
      "z": 15,
      "name": "Soil_Dirt_Burnt"
    },
    {
      "x": 19,
      "y": 27,
      "z": 15,
      "name": "Soil_Grass_Burnt"
    },
    {
      "x": 19,
      "y": 22,
      "z": 16,
      "name": "Rock_Basalt"
    },
    {
      "x": 19,
      "y": 23,
      "z": 16,
      "name": "Rock_Basalt"
    },
    {
      "x": 19,
      "y": 24,
      "z": 16,
      "name": "Rock_Basalt"
    },
    {
      "x": 19,
      "y": 25,
      "z": 16,
      "name": "Soil_Dirt_Burnt"
    },
    {
      "x": 19,
      "y": 26,
      "z": 16,
      "name": "Soil_Dirt_Burnt"
    },
    {
      "x": 19,
      "y": 27,
      "z": 16,
      "name": "Soil_Grass_Burnt"
    },
    {
      "x": 19,
      "y": 28,
      "z": 16,
      "name": "Plant_Grass_Gnarled"
    },
    {
      "x": 19,
      "y": 23,
      "z": 17,
      "name": "Rock_Basalt"
    },
    {
      "x": 19,
      "y": 24,
      "z": 17,
      "name": "Rock_Basalt"
    },
    {
      "x": 19,
      "y": 25,
      "z": 17,
      "name": "Soil_Dirt_Burnt"
    },
    {
      "x": 19,
      "y": 26,
      "z": 17,
      "name": "Soil_Grass_Burnt"
    },
    {
      "x": 19,
      "y": 24,
      "z": 18,
      "name": "Soil_Dirt_Burnt"
    },
    {
      "x": 19,
      "y": 25,
      "z": 18,
      "name": "Soil_Dirt_Burnt"
    },
    {
      "x": 19,
      "y": 26,
      "z": 18,
      "name": "Soil_Grass_Burnt"
    },
    {
      "x": 19,
      "y": 24,
      "z": 19,
      "name": "Rock_Basalt"
    },
    {
      "x": 19,
      "y": 25,
      "z": 19,
      "name": "Soil_Dirt_Burnt"
    },
    {
      "x": 19,
      "y": 26,
      "z": 19,
      "name": "Soil_Grass_Burnt"
    },
    {
      "x": 19,
      "y": 23,
      "z": 20,
      "name": "Rock_Basalt"
    },
    {
      "x": 19,
      "y": 24,
      "z": 20,
      "name": "Rock_Basalt"
    },
    {
      "x": 19,
      "y": 25,
      "z": 20,
      "name": "Soil_Grass_Burnt"
    },
    {
      "x": 19,
      "y": 26,
      "z": 20,
      "name": "Plant_Grass_Sharp"
    },
    {
      "x": 19,
      "y": 23,
      "z": 21,
      "name": "Rock_Basalt"
    },
    {
      "x": 19,
      "y": 24,
      "z": 21,
      "name": "Rock_Basalt"
    },
    {
      "x": 19,
      "y": 25,
      "z": 21,
      "name": "Soil_Grass_Burnt"
    },
    {
      "x": 19,
      "y": 10,
      "z": 22,
      "name": "Rock_Basalt"
    },
    {
      "x": 19,
      "y": 11,
      "z": 22,
      "name": "Rock_Basalt"
    },
    {
      "x": 19,
      "y": 12,
      "z": 22,
      "name": "Rock_Basalt"
    },
    {
      "x": 19,
      "y": 21,
      "z": 22,
      "name": "Rock_Basalt"
    },
    {
      "x": 19,
      "y": 22,
      "z": 22,
      "name": "Rock_Basalt"
    },
    {
      "x": 19,
      "y": 23,
      "z": 22,
      "name": "Rock_Basalt"
    },
    {
      "x": 19,
      "y": 24,
      "z": 22,
      "name": "Soil_Dirt_Burnt"
    },
    {
      "x": 19,
      "y": 25,
      "z": 22,
      "name": "Soil_Grass_Burnt"
    },
    {
      "x": 19,
      "y": 11,
      "z": 23,
      "name": "Rock_Basalt"
    },
    {
      "x": 19,
      "y": 12,
      "z": 23,
      "name": "Rock_Basalt"
    },
    {
      "x": 19,
      "y": 13,
      "z": 23,
      "name": "Rock_Basalt"
    },
    {
      "x": 19,
      "y": 21,
      "z": 23,
      "name": "Rock_Basalt"
    },
    {
      "x": 19,
      "y": 22,
      "z": 23,
      "name": "Rock_Basalt"
    },
    {
      "x": 19,
      "y": 23,
      "z": 23,
      "name": "Rock_Basalt"
    },
    {
      "x": 19,
      "y": 24,
      "z": 23,
      "name": "Soil_Dirt_Burnt"
    },
    {
      "x": 19,
      "y": 25,
      "z": 23,
      "name": "Soil_Grass_Burnt"
    },
    {
      "x": 19,
      "y": 11,
      "z": 24,
      "name": "Rock_Basalt"
    },
    {
      "x": 19,
      "y": 12,
      "z": 24,
      "name": "Rock_Basalt"
    },
    {
      "x": 19,
      "y": 13,
      "z": 24,
      "name": "Rock_Basalt"
    },
    {
      "x": 19,
      "y": 14,
      "z": 24,
      "name": "Rock_Basalt"
    },
    {
      "x": 19,
      "y": 21,
      "z": 24,
      "name": "Rock_Basalt"
    },
    {
      "x": 19,
      "y": 22,
      "z": 24,
      "name": "Rock_Basalt"
    },
    {
      "x": 19,
      "y": 23,
      "z": 24,
      "name": "Soil_Dirt_Burnt"
    },
    {
      "x": 19,
      "y": 24,
      "z": 24,
      "name": "Soil_Dirt_Burnt"
    },
    {
      "x": 19,
      "y": 25,
      "z": 24,
      "name": "Soil_Grass_Burnt"
    },
    {
      "x": 19,
      "y": 11,
      "z": 25,
      "name": "Rock_Basalt"
    },
    {
      "x": 19,
      "y": 12,
      "z": 25,
      "name": "Rock_Basalt"
    },
    {
      "x": 19,
      "y": 13,
      "z": 25,
      "name": "Rock_Basalt"
    },
    {
      "x": 19,
      "y": 14,
      "z": 25,
      "name": "Rock_Basalt"
    },
    {
      "x": 19,
      "y": 15,
      "z": 25,
      "name": "Rock_Basalt"
    },
    {
      "x": 19,
      "y": 20,
      "z": 25,
      "name": "Rock_Basalt"
    },
    {
      "x": 19,
      "y": 21,
      "z": 25,
      "name": "Rock_Basalt"
    },
    {
      "x": 19,
      "y": 22,
      "z": 25,
      "name": "Soil_Dirt_Burnt"
    },
    {
      "x": 19,
      "y": 23,
      "z": 25,
      "name": "Soil_Dirt_Burnt"
    },
    {
      "x": 19,
      "y": 24,
      "z": 25,
      "name": "Soil_Grass_Burnt"
    },
    {
      "x": 19,
      "y": 25,
      "z": 25,
      "name": "Plant_Grass_Sharp"
    },
    {
      "x": 19,
      "y": 12,
      "z": 26,
      "name": "Rock_Basalt"
    },
    {
      "x": 19,
      "y": 13,
      "z": 26,
      "name": "Rock_Basalt"
    },
    {
      "x": 19,
      "y": 21,
      "z": 26,
      "name": "Rock_Basalt"
    },
    {
      "x": 19,
      "y": 22,
      "z": 26,
      "name": "Soil_Grass_Burnt"
    },
    {
      "x": 20,
      "y": 23,
      "z": 8,
      "name": "Rock_Basalt"
    },
    {
      "x": 20,
      "y": 24,
      "z": 8,
      "name": "Soil_Grass_Burnt"
    },
    {
      "x": 20,
      "y": 22,
      "z": 9,
      "name": "Rock_Basalt"
    },
    {
      "x": 20,
      "y": 23,
      "z": 9,
      "name": "Rock_Basalt"
    },
    {
      "x": 20,
      "y": 24,
      "z": 9,
      "name": "Rock_Basalt"
    },
    {
      "x": 20,
      "y": 25,
      "z": 9,
      "name": "Soil_Grass_Burnt"
    },
    {
      "x": 20,
      "y": 26,
      "z": 9,
      "name": "Plant_Grass_Sharp_Tall"
    },
    {
      "x": 20,
      "y": 27,
      "z": 9,
      "name": "Plant_Grass_Sharp_Tall",
      "filler": 1024
    },
    {
      "x": 20,
      "y": 21,
      "z": 10,
      "name": "Rock_Basalt"
    },
    {
      "x": 20,
      "y": 22,
      "z": 10,
      "name": "Rock_Basalt"
    },
    {
      "x": 20,
      "y": 23,
      "z": 10,
      "name": "Rock_Basalt"
    },
    {
      "x": 20,
      "y": 24,
      "z": 10,
      "name": "Soil_Dirt_Burnt"
    },
    {
      "x": 20,
      "y": 25,
      "z": 10,
      "name": "Soil_Grass_Burnt"
    },
    {
      "x": 20,
      "y": 26,
      "z": 10,
      "name": "Plant_Grass_Sharp_Tall"
    },
    {
      "x": 20,
      "y": 27,
      "z": 10,
      "name": "Plant_Grass_Sharp_Tall",
      "filler": 1024
    },
    {
      "x": 20,
      "y": 20,
      "z": 11,
      "name": "Rock_Basalt"
    },
    {
      "x": 20,
      "y": 21,
      "z": 11,
      "name": "Rock_Basalt"
    },
    {
      "x": 20,
      "y": 22,
      "z": 11,
      "name": "Rock_Basalt"
    },
    {
      "x": 20,
      "y": 23,
      "z": 11,
      "name": "Rock_Basalt"
    },
    {
      "x": 20,
      "y": 24,
      "z": 11,
      "name": "Rock_Basalt"
    },
    {
      "x": 20,
      "y": 25,
      "z": 11,
      "name": "Soil_Dirt_Burnt"
    },
    {
      "x": 20,
      "y": 26,
      "z": 11,
      "name": "Soil_Dirt_Burnt"
    },
    {
      "x": 20,
      "y": 27,
      "z": 11,
      "name": "Soil_Grass_Burnt"
    },
    {
      "x": 20,
      "y": 9,
      "z": 12,
      "name": "Rock_Basalt"
    },
    {
      "x": 20,
      "y": 10,
      "z": 12,
      "name": "Rock_Basalt"
    },
    {
      "x": 20,
      "y": 20,
      "z": 12,
      "name": "Rock_Basalt"
    },
    {
      "x": 20,
      "y": 21,
      "z": 12,
      "name": "Rock_Basalt"
    },
    {
      "x": 20,
      "y": 22,
      "z": 12,
      "name": "Rock_Basalt"
    },
    {
      "x": 20,
      "y": 23,
      "z": 12,
      "name": "Rock_Basalt"
    },
    {
      "x": 20,
      "y": 24,
      "z": 12,
      "name": "Rock_Basalt"
    },
    {
      "x": 20,
      "y": 25,
      "z": 12,
      "name": "Rock_Basalt"
    },
    {
      "x": 20,
      "y": 26,
      "z": 12,
      "name": "Soil_Dirt_Burnt"
    },
    {
      "x": 20,
      "y": 27,
      "z": 12,
      "name": "Soil_Grass_Burnt"
    },
    {
      "x": 20,
      "y": 8,
      "z": 13,
      "name": "Rock_Basalt"
    },
    {
      "x": 20,
      "y": 9,
      "z": 13,
      "name": "Rock_Basalt"
    },
    {
      "x": 20,
      "y": 10,
      "z": 13,
      "name": "Rock_Basalt"
    },
    {
      "x": 20,
      "y": 21,
      "z": 13,
      "name": "Rock_Basalt"
    },
    {
      "x": 20,
      "y": 22,
      "z": 13,
      "name": "Rock_Basalt"
    },
    {
      "x": 20,
      "y": 23,
      "z": 13,
      "name": "Rock_Basalt"
    },
    {
      "x": 20,
      "y": 24,
      "z": 13,
      "name": "Rock_Basalt"
    },
    {
      "x": 20,
      "y": 25,
      "z": 13,
      "name": "Rock_Basalt"
    },
    {
      "x": 20,
      "y": 26,
      "z": 13,
      "name": "Rock_Basalt"
    },
    {
      "x": 20,
      "y": 27,
      "z": 13,
      "name": "Soil_Grass_Burnt"
    },
    {
      "x": 20,
      "y": 28,
      "z": 13,
      "name": "Plant_Grass_Gnarled"
    },
    {
      "x": 20,
      "y": 8,
      "z": 14,
      "name": "Rock_Basalt"
    },
    {
      "x": 20,
      "y": 22,
      "z": 14,
      "name": "Rock_Basalt"
    },
    {
      "x": 20,
      "y": 23,
      "z": 14,
      "name": "Rock_Basalt"
    },
    {
      "x": 20,
      "y": 24,
      "z": 14,
      "name": "Rock_Basalt"
    },
    {
      "x": 20,
      "y": 25,
      "z": 14,
      "name": "Rock_Basalt"
    },
    {
      "x": 20,
      "y": 26,
      "z": 14,
      "name": "Soil_Dirt_Burnt"
    },
    {
      "x": 20,
      "y": 27,
      "z": 14,
      "name": "Rock_Basalt"
    },
    {
      "x": 20,
      "y": 28,
      "z": 14,
      "name": "Soil_Grass_Burnt"
    },
    {
      "x": 20,
      "y": 8,
      "z": 15,
      "name": "Rock_Basalt"
    },
    {
      "x": 20,
      "y": 22,
      "z": 15,
      "name": "Rock_Basalt"
    },
    {
      "x": 20,
      "y": 23,
      "z": 15,
      "name": "Rock_Basalt"
    },
    {
      "x": 20,
      "y": 24,
      "z": 15,
      "name": "Rock_Basalt"
    },
    {
      "x": 20,
      "y": 25,
      "z": 15,
      "name": "Soil_Dirt_Burnt"
    },
    {
      "x": 20,
      "y": 26,
      "z": 15,
      "name": "Soil_Dirt_Burnt"
    },
    {
      "x": 20,
      "y": 27,
      "z": 15,
      "name": "Soil_Dirt_Burnt"
    },
    {
      "x": 20,
      "y": 28,
      "z": 15,
      "name": "Soil_Grass_Burnt"
    },
    {
      "x": 20,
      "y": 22,
      "z": 16,
      "name": "Rock_Basalt"
    },
    {
      "x": 20,
      "y": 23,
      "z": 16,
      "name": "Rock_Basalt"
    },
    {
      "x": 20,
      "y": 24,
      "z": 16,
      "name": "Rock_Basalt"
    },
    {
      "x": 20,
      "y": 25,
      "z": 16,
      "name": "Rock_Basalt"
    },
    {
      "x": 20,
      "y": 26,
      "z": 16,
      "name": "Soil_Dirt_Burnt"
    },
    {
      "x": 20,
      "y": 27,
      "z": 16,
      "name": "Rock_Basalt"
    },
    {
      "x": 20,
      "y": 28,
      "z": 16,
      "name": "Soil_Grass_Burnt"
    },
    {
      "x": 20,
      "y": 23,
      "z": 17,
      "name": "Rock_Basalt"
    },
    {
      "x": 20,
      "y": 24,
      "z": 17,
      "name": "Rock_Basalt"
    },
    {
      "x": 20,
      "y": 25,
      "z": 17,
      "name": "Rock_Basalt"
    },
    {
      "x": 20,
      "y": 26,
      "z": 17,
      "name": "Soil_Dirt_Burnt"
    },
    {
      "x": 20,
      "y": 27,
      "z": 17,
      "name": "Soil_Grass_Burnt"
    },
    {
      "x": 20,
      "y": 23,
      "z": 18,
      "name": "Rock_Basalt"
    },
    {
      "x": 20,
      "y": 24,
      "z": 18,
      "name": "Rock_Basalt"
    },
    {
      "x": 20,
      "y": 25,
      "z": 18,
      "name": "Soil_Dirt_Burnt"
    },
    {
      "x": 20,
      "y": 26,
      "z": 18,
      "name": "Soil_Dirt_Burnt"
    },
    {
      "x": 20,
      "y": 27,
      "z": 18,
      "name": "Soil_Grass_Burnt"
    },
    {
      "x": 20,
      "y": 23,
      "z": 19,
      "name": "Rock_Basalt"
    },
    {
      "x": 20,
      "y": 24,
      "z": 19,
      "name": "Rock_Basalt"
    },
    {
      "x": 20,
      "y": 25,
      "z": 19,
      "name": "Rock_Basalt"
    },
    {
      "x": 20,
      "y": 26,
      "z": 19,
      "name": "Soil_Grass_Burnt"
    },
    {
      "x": 20,
      "y": 9,
      "z": 20,
      "name": "Rock_Basalt"
    },
    {
      "x": 20,
      "y": 23,
      "z": 20,
      "name": "Rock_Basalt"
    },
    {
      "x": 20,
      "y": 24,
      "z": 20,
      "name": "Rock_Basalt"
    },
    {
      "x": 20,
      "y": 25,
      "z": 20,
      "name": "Soil_Dirt_Burnt"
    },
    {
      "x": 20,
      "y": 26,
      "z": 20,
      "name": "Soil_Grass_Burnt"
    },
    {
      "x": 20,
      "y": 9,
      "z": 21,
      "name": "Rock_Basalt"
    },
    {
      "x": 20,
      "y": 10,
      "z": 21,
      "name": "Rock_Basalt"
    },
    {
      "x": 20,
      "y": 11,
      "z": 21,
      "name": "Rock_Basalt"
    },
    {
      "x": 20,
      "y": 21,
      "z": 21,
      "name": "Rock_Basalt"
    },
    {
      "x": 20,
      "y": 22,
      "z": 21,
      "name": "Rock_Basalt"
    },
    {
      "x": 20,
      "y": 23,
      "z": 21,
      "name": "Rock_Basalt"
    },
    {
      "x": 20,
      "y": 24,
      "z": 21,
      "name": "Soil_Dirt_Burnt"
    },
    {
      "x": 20,
      "y": 25,
      "z": 21,
      "name": "Soil_Grass_Burnt"
    },
    {
      "x": 20,
      "y": 26,
      "z": 21,
      "name": "Plant_Grass_Sharp_Tall"
    },
    {
      "x": 20,
      "y": 27,
      "z": 21,
      "name": "Plant_Grass_Sharp_Tall",
      "filler": 1024
    },
    {
      "x": 20,
      "y": 9,
      "z": 22,
      "name": "Rock_Basalt"
    },
    {
      "x": 20,
      "y": 10,
      "z": 22,
      "name": "Rock_Basalt"
    },
    {
      "x": 20,
      "y": 11,
      "z": 22,
      "name": "Rock_Basalt"
    },
    {
      "x": 20,
      "y": 12,
      "z": 22,
      "name": "Rock_Basalt"
    },
    {
      "x": 20,
      "y": 21,
      "z": 22,
      "name": "Rock_Basalt"
    },
    {
      "x": 20,
      "y": 22,
      "z": 22,
      "name": "Rock_Basalt"
    },
    {
      "x": 20,
      "y": 23,
      "z": 22,
      "name": "Soil_Dirt_Burnt"
    },
    {
      "x": 20,
      "y": 24,
      "z": 22,
      "name": "Soil_Dirt_Burnt"
    },
    {
      "x": 20,
      "y": 25,
      "z": 22,
      "name": "Soil_Grass_Burnt"
    },
    {
      "x": 20,
      "y": 26,
      "z": 22,
      "name": "Plant_Grass_Sharp_Tall"
    },
    {
      "x": 20,
      "y": 27,
      "z": 22,
      "name": "Plant_Grass_Sharp_Tall",
      "filler": 1024
    },
    {
      "x": 20,
      "y": 9,
      "z": 23,
      "name": "Rock_Basalt"
    },
    {
      "x": 20,
      "y": 10,
      "z": 23,
      "name": "Rock_Basalt"
    },
    {
      "x": 20,
      "y": 11,
      "z": 23,
      "name": "Rock_Basalt"
    },
    {
      "x": 20,
      "y": 12,
      "z": 23,
      "name": "Rock_Basalt"
    },
    {
      "x": 20,
      "y": 13,
      "z": 23,
      "name": "Rock_Basalt"
    },
    {
      "x": 20,
      "y": 21,
      "z": 23,
      "name": "Rock_Basalt"
    },
    {
      "x": 20,
      "y": 22,
      "z": 23,
      "name": "Rock_Basalt"
    },
    {
      "x": 20,
      "y": 23,
      "z": 23,
      "name": "Rock_Basalt"
    },
    {
      "x": 20,
      "y": 24,
      "z": 23,
      "name": "Soil_Dirt_Burnt"
    },
    {
      "x": 20,
      "y": 25,
      "z": 23,
      "name": "Soil_Grass_Burnt"
    },
    {
      "x": 20,
      "y": 26,
      "z": 23,
      "name": "Plant_Grass_Sharp_Tall"
    },
    {
      "x": 20,
      "y": 27,
      "z": 23,
      "name": "Plant_Grass_Sharp_Tall",
      "filler": 1024
    },
    {
      "x": 20,
      "y": 10,
      "z": 24,
      "name": "Rock_Basalt"
    },
    {
      "x": 20,
      "y": 11,
      "z": 24,
      "name": "Rock_Basalt"
    },
    {
      "x": 20,
      "y": 12,
      "z": 24,
      "name": "Rock_Basalt"
    },
    {
      "x": 20,
      "y": 13,
      "z": 24,
      "name": "Rock_Basalt"
    },
    {
      "x": 20,
      "y": 21,
      "z": 24,
      "name": "Rock_Basalt"
    },
    {
      "x": 20,
      "y": 22,
      "z": 24,
      "name": "Rock_Basalt"
    },
    {
      "x": 20,
      "y": 23,
      "z": 24,
      "name": "Soil_Dirt_Burnt"
    },
    {
      "x": 20,
      "y": 24,
      "z": 24,
      "name": "Soil_Dirt_Burnt"
    },
    {
      "x": 20,
      "y": 25,
      "z": 24,
      "name": "Soil_Grass_Burnt"
    },
    {
      "x": 20,
      "y": 26,
      "z": 24,
      "name": "Plant_Grass_Sharp"
    },
    {
      "x": 20,
      "y": 11,
      "z": 25,
      "name": "Rock_Basalt"
    },
    {
      "x": 20,
      "y": 12,
      "z": 25,
      "name": "Rock_Basalt"
    },
    {
      "x": 20,
      "y": 22,
      "z": 25,
      "name": "Rock_Basalt"
    },
    {
      "x": 20,
      "y": 23,
      "z": 25,
      "name": "Soil_Dirt_Burnt"
    },
    {
      "x": 20,
      "y": 24,
      "z": 25,
      "name": "Soil_Grass_Burnt"
    },
    {
      "x": 21,
      "y": 24,
      "z": 8,
      "name": "Rock_Basalt"
    },
    {
      "x": 21,
      "y": 25,
      "z": 8,
      "name": "Soil_Grass_Burnt"
    },
    {
      "x": 21,
      "y": 22,
      "z": 9,
      "name": "Rock_Basalt"
    },
    {
      "x": 21,
      "y": 23,
      "z": 9,
      "name": "Rock_Basalt"
    },
    {
      "x": 21,
      "y": 24,
      "z": 9,
      "name": "Soil_Dirt_Burnt"
    },
    {
      "x": 21,
      "y": 25,
      "z": 9,
      "name": "Soil_Grass_Burnt"
    },
    {
      "x": 21,
      "y": 22,
      "z": 10,
      "name": "Rock_Basalt"
    },
    {
      "x": 21,
      "y": 23,
      "z": 10,
      "name": "Rock_Basalt"
    },
    {
      "x": 21,
      "y": 24,
      "z": 10,
      "name": "Soil_Dirt_Burnt"
    },
    {
      "x": 21,
      "y": 25,
      "z": 10,
      "name": "Soil_Dirt_Burnt"
    },
    {
      "x": 21,
      "y": 26,
      "z": 10,
      "name": "Soil_Grass_Burnt"
    },
    {
      "x": 21,
      "y": 27,
      "z": 10,
      "name": "Plant_Grass_Sharp_Tall"
    },
    {
      "x": 21,
      "y": 28,
      "z": 10,
      "name": "Plant_Grass_Sharp_Tall",
      "filler": 1024
    },
    {
      "x": 21,
      "y": 21,
      "z": 11,
      "name": "Rock_Basalt"
    },
    {
      "x": 21,
      "y": 22,
      "z": 11,
      "name": "Rock_Basalt"
    },
    {
      "x": 21,
      "y": 23,
      "z": 11,
      "name": "Rock_Basalt"
    },
    {
      "x": 21,
      "y": 24,
      "z": 11,
      "name": "Soil_Dirt_Burnt"
    },
    {
      "x": 21,
      "y": 25,
      "z": 11,
      "name": "Soil_Dirt_Burnt"
    },
    {
      "x": 21,
      "y": 26,
      "z": 11,
      "name": "Soil_Dirt_Burnt"
    },
    {
      "x": 21,
      "y": 27,
      "z": 11,
      "name": "Soil_Grass_Burnt"
    },
    {
      "x": 21,
      "y": 21,
      "z": 12,
      "name": "Rock_Basalt"
    },
    {
      "x": 21,
      "y": 22,
      "z": 12,
      "name": "Rock_Basalt"
    },
    {
      "x": 21,
      "y": 23,
      "z": 12,
      "name": "Rock_Basalt"
    },
    {
      "x": 21,
      "y": 24,
      "z": 12,
      "name": "Rock_Basalt"
    },
    {
      "x": 21,
      "y": 25,
      "z": 12,
      "name": "Soil_Dirt_Burnt"
    },
    {
      "x": 21,
      "y": 26,
      "z": 12,
      "name": "Soil_Dirt_Burnt"
    },
    {
      "x": 21,
      "y": 27,
      "z": 12,
      "name": "Soil_Grass_Burnt"
    },
    {
      "x": 21,
      "y": 28,
      "z": 12,
      "name": "Plant_Grass_Sharp"
    },
    {
      "x": 21,
      "y": 8,
      "z": 13,
      "name": "Rock_Basalt"
    },
    {
      "x": 21,
      "y": 9,
      "z": 13,
      "name": "Rock_Basalt"
    },
    {
      "x": 21,
      "y": 21,
      "z": 13,
      "name": "Rock_Basalt"
    },
    {
      "x": 21,
      "y": 22,
      "z": 13,
      "name": "Rock_Basalt"
    },
    {
      "x": 21,
      "y": 23,
      "z": 13,
      "name": "Rock_Basalt"
    },
    {
      "x": 21,
      "y": 24,
      "z": 13,
      "name": "Rock_Basalt"
    },
    {
      "x": 21,
      "y": 25,
      "z": 13,
      "name": "Rock_Basalt"
    },
    {
      "x": 21,
      "y": 26,
      "z": 13,
      "name": "Rock_Basalt"
    },
    {
      "x": 21,
      "y": 27,
      "z": 13,
      "name": "Rock_Basalt"
    },
    {
      "x": 21,
      "y": 28,
      "z": 13,
      "name": "Soil_Grass_Burnt"
    },
    {
      "x": 21,
      "y": 8,
      "z": 14,
      "name": "Rock_Basalt"
    },
    {
      "x": 21,
      "y": 22,
      "z": 14,
      "name": "Rock_Basalt"
    },
    {
      "x": 21,
      "y": 23,
      "z": 14,
      "name": "Rock_Basalt"
    },
    {
      "x": 21,
      "y": 24,
      "z": 14,
      "name": "Rock_Basalt"
    },
    {
      "x": 21,
      "y": 25,
      "z": 14,
      "name": "Rock_Basalt"
    },
    {
      "x": 21,
      "y": 26,
      "z": 14,
      "name": "Rock_Basalt"
    },
    {
      "x": 21,
      "y": 27,
      "z": 14,
      "name": "Rock_Basalt"
    },
    {
      "x": 21,
      "y": 28,
      "z": 14,
      "name": "Soil_Grass_Burnt"
    },
    {
      "x": 21,
      "y": 22,
      "z": 15,
      "name": "Rock_Basalt"
    },
    {
      "x": 21,
      "y": 23,
      "z": 15,
      "name": "Rock_Basalt"
    },
    {
      "x": 21,
      "y": 24,
      "z": 15,
      "name": "Rock_Basalt"
    },
    {
      "x": 21,
      "y": 25,
      "z": 15,
      "name": "Rock_Basalt"
    },
    {
      "x": 21,
      "y": 26,
      "z": 15,
      "name": "Rock_Basalt"
    },
    {
      "x": 21,
      "y": 27,
      "z": 15,
      "name": "Rock_Basalt"
    },
    {
      "x": 21,
      "y": 28,
      "z": 15,
      "name": "Soil_Grass_Burnt"
    },
    {
      "x": 21,
      "y": 22,
      "z": 16,
      "name": "Rock_Basalt"
    },
    {
      "x": 21,
      "y": 23,
      "z": 16,
      "name": "Rock_Basalt"
    },
    {
      "x": 21,
      "y": 24,
      "z": 16,
      "name": "Rock_Basalt"
    },
    {
      "x": 21,
      "y": 25,
      "z": 16,
      "name": "Rock_Basalt"
    },
    {
      "x": 21,
      "y": 26,
      "z": 16,
      "name": "Rock_Basalt"
    },
    {
      "x": 21,
      "y": 27,
      "z": 16,
      "name": "Rock_Basalt"
    },
    {
      "x": 21,
      "y": 28,
      "z": 16,
      "name": "Soil_Grass_Burnt"
    },
    {
      "x": 21,
      "y": 29,
      "z": 16,
      "name": "Plant_Grass_Gnarled"
    },
    {
      "x": 21,
      "y": 22,
      "z": 17,
      "name": "Rock_Basalt"
    },
    {
      "x": 21,
      "y": 23,
      "z": 17,
      "name": "Rock_Basalt"
    },
    {
      "x": 21,
      "y": 24,
      "z": 17,
      "name": "Rock_Basalt"
    },
    {
      "x": 21,
      "y": 25,
      "z": 17,
      "name": "Rock_Basalt"
    },
    {
      "x": 21,
      "y": 26,
      "z": 17,
      "name": "Rock_Basalt"
    },
    {
      "x": 21,
      "y": 27,
      "z": 17,
      "name": "Rock_Basalt"
    },
    {
      "x": 21,
      "y": 28,
      "z": 17,
      "name": "Soil_Grass_Burnt"
    },
    {
      "x": 21,
      "y": 23,
      "z": 18,
      "name": "Rock_Basalt"
    },
    {
      "x": 21,
      "y": 24,
      "z": 18,
      "name": "Rock_Basalt"
    },
    {
      "x": 21,
      "y": 25,
      "z": 18,
      "name": "Rock_Basalt"
    },
    {
      "x": 21,
      "y": 26,
      "z": 18,
      "name": "Rock_Basalt"
    },
    {
      "x": 21,
      "y": 27,
      "z": 18,
      "name": "Soil_Grass_Burnt"
    },
    {
      "x": 21,
      "y": 8,
      "z": 19,
      "name": "Rock_Basalt"
    },
    {
      "x": 21,
      "y": 23,
      "z": 19,
      "name": "Rock_Basalt"
    },
    {
      "x": 21,
      "y": 24,
      "z": 19,
      "name": "Rock_Basalt"
    },
    {
      "x": 21,
      "y": 25,
      "z": 19,
      "name": "Rock_Basalt"
    },
    {
      "x": 21,
      "y": 26,
      "z": 19,
      "name": "Soil_Grass_Burnt"
    },
    {
      "x": 21,
      "y": 7,
      "z": 20,
      "name": "Rock_Basalt"
    },
    {
      "x": 21,
      "y": 8,
      "z": 20,
      "name": "Rock_Basalt"
    },
    {
      "x": 21,
      "y": 9,
      "z": 20,
      "name": "Rock_Basalt"
    },
    {
      "x": 21,
      "y": 10,
      "z": 20,
      "name": "Rock_Basalt"
    },
    {
      "x": 21,
      "y": 23,
      "z": 20,
      "name": "Rock_Basalt"
    },
    {
      "x": 21,
      "y": 24,
      "z": 20,
      "name": "Soil_Dirt_Burnt"
    },
    {
      "x": 21,
      "y": 25,
      "z": 20,
      "name": "Soil_Dirt_Burnt"
    },
    {
      "x": 21,
      "y": 26,
      "z": 20,
      "name": "Soil_Grass_Burnt"
    },
    {
      "x": 21,
      "y": 27,
      "z": 20,
      "name": "Plant_Grass_Sharp_Tall"
    },
    {
      "x": 21,
      "y": 28,
      "z": 20,
      "name": "Plant_Grass_Sharp_Tall",
      "filler": 1024
    },
    {
      "x": 21,
      "y": 8,
      "z": 21,
      "name": "Rock_Basalt"
    },
    {
      "x": 21,
      "y": 9,
      "z": 21,
      "name": "Rock_Basalt"
    },
    {
      "x": 21,
      "y": 10,
      "z": 21,
      "name": "Rock_Basalt"
    },
    {
      "x": 21,
      "y": 11,
      "z": 21,
      "name": "Rock_Basalt"
    },
    {
      "x": 21,
      "y": 22,
      "z": 21,
      "name": "Rock_Basalt"
    },
    {
      "x": 21,
      "y": 23,
      "z": 21,
      "name": "Soil_Dirt_Burnt"
    },
    {
      "x": 21,
      "y": 24,
      "z": 21,
      "name": "Soil_Dirt_Burnt"
    },
    {
      "x": 21,
      "y": 25,
      "z": 21,
      "name": "Soil_Grass_Burnt"
    },
    {
      "x": 21,
      "y": 8,
      "z": 22,
      "name": "Rock_Basalt"
    },
    {
      "x": 21,
      "y": 9,
      "z": 22,
      "name": "Rock_Basalt"
    },
    {
      "x": 21,
      "y": 10,
      "z": 22,
      "name": "Rock_Basalt"
    },
    {
      "x": 21,
      "y": 11,
      "z": 22,
      "name": "Rock_Basalt"
    },
    {
      "x": 21,
      "y": 22,
      "z": 22,
      "name": "Rock_Basalt"
    },
    {
      "x": 21,
      "y": 23,
      "z": 22,
      "name": "Soil_Dirt_Burnt"
    },
    {
      "x": 21,
      "y": 24,
      "z": 22,
      "name": "Soil_Dirt_Burnt"
    },
    {
      "x": 21,
      "y": 25,
      "z": 22,
      "name": "Soil_Grass_Burnt"
    },
    {
      "x": 21,
      "y": 9,
      "z": 23,
      "name": "Rock_Basalt"
    },
    {
      "x": 21,
      "y": 10,
      "z": 23,
      "name": "Rock_Basalt"
    },
    {
      "x": 21,
      "y": 11,
      "z": 23,
      "name": "Rock_Basalt"
    },
    {
      "x": 21,
      "y": 22,
      "z": 23,
      "name": "Rock_Basalt"
    },
    {
      "x": 21,
      "y": 23,
      "z": 23,
      "name": "Soil_Dirt_Burnt"
    },
    {
      "x": 21,
      "y": 24,
      "z": 23,
      "name": "Soil_Dirt_Burnt"
    },
    {
      "x": 21,
      "y": 25,
      "z": 23,
      "name": "Soil_Grass_Burnt"
    },
    {
      "x": 21,
      "y": 26,
      "z": 23,
      "name": "Plant_Grass_Sharp"
    },
    {
      "x": 21,
      "y": 10,
      "z": 24,
      "name": "Rock_Basalt"
    },
    {
      "x": 21,
      "y": 11,
      "z": 24,
      "name": "Rock_Basalt"
    },
    {
      "x": 21,
      "y": 12,
      "z": 24,
      "name": "Rock_Basalt"
    },
    {
      "x": 21,
      "y": 22,
      "z": 24,
      "name": "Rock_Basalt"
    },
    {
      "x": 21,
      "y": 23,
      "z": 24,
      "name": "Soil_Dirt_Burnt"
    },
    {
      "x": 21,
      "y": 24,
      "z": 24,
      "name": "Soil_Dirt_Burnt"
    },
    {
      "x": 21,
      "y": 25,
      "z": 24,
      "name": "Soil_Grass_Burnt"
    },
    {
      "x": 21,
      "y": 23,
      "z": 25,
      "name": "Soil_Grass_Burnt"
    },
    {
      "x": 22,
      "y": 24,
      "z": 8,
      "name": "Rock_Basalt"
    },
    {
      "x": 22,
      "y": 25,
      "z": 8,
      "name": "Soil_Grass_Burnt"
    },
    {
      "x": 22,
      "y": 23,
      "z": 9,
      "name": "Rock_Basalt"
    },
    {
      "x": 22,
      "y": 24,
      "z": 9,
      "name": "Rock_Basalt"
    },
    {
      "x": 22,
      "y": 25,
      "z": 9,
      "name": "Soil_Dirt_Burnt"
    },
    {
      "x": 22,
      "y": 26,
      "z": 9,
      "name": "Soil_Grass_Burnt"
    },
    {
      "x": 22,
      "y": 22,
      "z": 10,
      "name": "Rock_Basalt"
    },
    {
      "x": 22,
      "y": 23,
      "z": 10,
      "name": "Rock_Basalt"
    },
    {
      "x": 22,
      "y": 24,
      "z": 10,
      "name": "Soil_Dirt_Burnt"
    },
    {
      "x": 22,
      "y": 25,
      "z": 10,
      "name": "Soil_Dirt_Burnt"
    },
    {
      "x": 22,
      "y": 26,
      "z": 10,
      "name": "Soil_Grass_Burnt"
    },
    {
      "x": 22,
      "y": 27,
      "z": 10,
      "name": "Plant_Grass_Sharp_Tall"
    },
    {
      "x": 22,
      "y": 28,
      "z": 10,
      "name": "Plant_Grass_Sharp_Tall",
      "filler": 1024
    },
    {
      "x": 22,
      "y": 22,
      "z": 11,
      "name": "Rock_Basalt"
    },
    {
      "x": 22,
      "y": 23,
      "z": 11,
      "name": "Rock_Basalt"
    },
    {
      "x": 22,
      "y": 24,
      "z": 11,
      "name": "Rock_Basalt"
    },
    {
      "x": 22,
      "y": 25,
      "z": 11,
      "name": "Soil_Dirt_Burnt"
    },
    {
      "x": 22,
      "y": 26,
      "z": 11,
      "name": "Soil_Dirt_Burnt"
    },
    {
      "x": 22,
      "y": 27,
      "z": 11,
      "name": "Soil_Grass_Burnt"
    },
    {
      "x": 22,
      "y": 22,
      "z": 12,
      "name": "Rock_Basalt"
    },
    {
      "x": 22,
      "y": 23,
      "z": 12,
      "name": "Rock_Basalt"
    },
    {
      "x": 22,
      "y": 24,
      "z": 12,
      "name": "Rock_Basalt"
    },
    {
      "x": 22,
      "y": 25,
      "z": 12,
      "name": "Rock_Basalt"
    },
    {
      "x": 22,
      "y": 26,
      "z": 12,
      "name": "Soil_Dirt_Burnt"
    },
    {
      "x": 22,
      "y": 27,
      "z": 12,
      "name": "Rock_Basalt"
    },
    {
      "x": 22,
      "y": 28,
      "z": 12,
      "name": "Soil_Grass_Burnt"
    },
    {
      "x": 22,
      "y": 29,
      "z": 12,
      "name": "Plant_Grass_Sharp"
    },
    {
      "x": 22,
      "y": 22,
      "z": 13,
      "name": "Rock_Basalt"
    },
    {
      "x": 22,
      "y": 23,
      "z": 13,
      "name": "Rock_Basalt"
    },
    {
      "x": 22,
      "y": 24,
      "z": 13,
      "name": "Rock_Basalt"
    },
    {
      "x": 22,
      "y": 25,
      "z": 13,
      "name": "Rock_Basalt"
    },
    {
      "x": 22,
      "y": 26,
      "z": 13,
      "name": "Rock_Basalt"
    },
    {
      "x": 22,
      "y": 27,
      "z": 13,
      "name": "Rock_Basalt"
    },
    {
      "x": 22,
      "y": 28,
      "z": 13,
      "name": "Soil_Grass_Burnt"
    },
    {
      "x": 22,
      "y": 29,
      "z": 13,
      "name": "Plant_Grass_Sharp"
    },
    {
      "x": 22,
      "y": 22,
      "z": 14,
      "name": "Rock_Basalt"
    },
    {
      "x": 22,
      "y": 23,
      "z": 14,
      "name": "Rock_Basalt"
    },
    {
      "x": 22,
      "y": 24,
      "z": 14,
      "name": "Rock_Basalt"
    },
    {
      "x": 22,
      "y": 25,
      "z": 14,
      "name": "Rock_Basalt"
    },
    {
      "x": 22,
      "y": 26,
      "z": 14,
      "name": "Rock_Basalt"
    },
    {
      "x": 22,
      "y": 27,
      "z": 14,
      "name": "Rock_Basalt"
    },
    {
      "x": 22,
      "y": 28,
      "z": 14,
      "name": "Soil_Grass_Burnt"
    },
    {
      "x": 22,
      "y": 22,
      "z": 15,
      "name": "Rock_Basalt"
    },
    {
      "x": 22,
      "y": 23,
      "z": 15,
      "name": "Rock_Basalt"
    },
    {
      "x": 22,
      "y": 24,
      "z": 15,
      "name": "Rock_Basalt"
    },
    {
      "x": 22,
      "y": 25,
      "z": 15,
      "name": "Rock_Basalt"
    },
    {
      "x": 22,
      "y": 26,
      "z": 15,
      "name": "Rock_Basalt"
    },
    {
      "x": 22,
      "y": 27,
      "z": 15,
      "name": "Rock_Basalt"
    },
    {
      "x": 22,
      "y": 28,
      "z": 15,
      "name": "Soil_Grass_Burnt"
    },
    {
      "x": 22,
      "y": 29,
      "z": 15,
      "name": "Plant_Grass_Gnarled_Short"
    },
    {
      "x": 22,
      "y": 22,
      "z": 16,
      "name": "Rock_Basalt"
    },
    {
      "x": 22,
      "y": 23,
      "z": 16,
      "name": "Rock_Basalt"
    },
    {
      "x": 22,
      "y": 24,
      "z": 16,
      "name": "Rock_Basalt"
    },
    {
      "x": 22,
      "y": 25,
      "z": 16,
      "name": "Rock_Basalt"
    },
    {
      "x": 22,
      "y": 26,
      "z": 16,
      "name": "Rock_Basalt"
    },
    {
      "x": 22,
      "y": 27,
      "z": 16,
      "name": "Rock_Basalt"
    },
    {
      "x": 22,
      "y": 28,
      "z": 16,
      "name": "Soil_Grass_Burnt"
    },
    {
      "x": 22,
      "y": 29,
      "z": 16,
      "name": "Plant_Grass_Gnarled_Short"
    },
    {
      "x": 22,
      "y": 22,
      "z": 17,
      "name": "Rock_Basalt"
    },
    {
      "x": 22,
      "y": 23,
      "z": 17,
      "name": "Rock_Basalt"
    },
    {
      "x": 22,
      "y": 24,
      "z": 17,
      "name": "Rock_Basalt"
    },
    {
      "x": 22,
      "y": 25,
      "z": 17,
      "name": "Rock_Basalt"
    },
    {
      "x": 22,
      "y": 26,
      "z": 17,
      "name": "Rock_Basalt"
    },
    {
      "x": 22,
      "y": 27,
      "z": 17,
      "name": "Rock_Basalt"
    },
    {
      "x": 22,
      "y": 28,
      "z": 17,
      "name": "Soil_Grass_Burnt"
    },
    {
      "x": 22,
      "y": 23,
      "z": 18,
      "name": "Rock_Basalt"
    },
    {
      "x": 22,
      "y": 24,
      "z": 18,
      "name": "Rock_Basalt"
    },
    {
      "x": 22,
      "y": 25,
      "z": 18,
      "name": "Rock_Basalt"
    },
    {
      "x": 22,
      "y": 26,
      "z": 18,
      "name": "Rock_Basalt"
    },
    {
      "x": 22,
      "y": 27,
      "z": 18,
      "name": "Rock_Basalt"
    },
    {
      "x": 22,
      "y": 28,
      "z": 18,
      "name": "Soil_Grass_Burnt"
    },
    {
      "x": 22,
      "y": 7,
      "z": 19,
      "name": "Rock_Basalt"
    },
    {
      "x": 22,
      "y": 23,
      "z": 19,
      "name": "Rock_Basalt"
    },
    {
      "x": 22,
      "y": 24,
      "z": 19,
      "name": "Rock_Basalt"
    },
    {
      "x": 22,
      "y": 25,
      "z": 19,
      "name": "Rock_Basalt"
    },
    {
      "x": 22,
      "y": 26,
      "z": 19,
      "name": "Soil_Grass_Burnt"
    },
    {
      "x": 22,
      "y": 7,
      "z": 20,
      "name": "Rock_Basalt"
    },
    {
      "x": 22,
      "y": 22,
      "z": 20,
      "name": "Rock_Basalt"
    },
    {
      "x": 22,
      "y": 23,
      "z": 20,
      "name": "Rock_Basalt"
    },
    {
      "x": 22,
      "y": 24,
      "z": 20,
      "name": "Rock_Basalt"
    },
    {
      "x": 22,
      "y": 25,
      "z": 20,
      "name": "Soil_Dirt_Burnt"
    },
    {
      "x": 22,
      "y": 26,
      "z": 20,
      "name": "Soil_Grass_Burnt"
    },
    {
      "x": 22,
      "y": 27,
      "z": 20,
      "name": "Plant_Grass_Sharp_Tall"
    },
    {
      "x": 22,
      "y": 28,
      "z": 20,
      "name": "Plant_Grass_Sharp_Tall",
      "filler": 1024
    },
    {
      "x": 22,
      "y": 7,
      "z": 21,
      "name": "Rock_Basalt"
    },
    {
      "x": 22,
      "y": 8,
      "z": 21,
      "name": "Rock_Basalt"
    },
    {
      "x": 22,
      "y": 9,
      "z": 21,
      "name": "Rock_Basalt"
    },
    {
      "x": 22,
      "y": 22,
      "z": 21,
      "name": "Rock_Basalt"
    },
    {
      "x": 22,
      "y": 23,
      "z": 21,
      "name": "Rock_Basalt"
    },
    {
      "x": 22,
      "y": 24,
      "z": 21,
      "name": "Soil_Dirt_Burnt"
    },
    {
      "x": 22,
      "y": 25,
      "z": 21,
      "name": "Soil_Dirt_Burnt"
    },
    {
      "x": 22,
      "y": 26,
      "z": 21,
      "name": "Soil_Grass_Burnt"
    },
    {
      "x": 22,
      "y": 8,
      "z": 22,
      "name": "Rock_Basalt"
    },
    {
      "x": 22,
      "y": 9,
      "z": 22,
      "name": "Rock_Basalt"
    },
    {
      "x": 22,
      "y": 10,
      "z": 22,
      "name": "Rock_Basalt"
    },
    {
      "x": 22,
      "y": 11,
      "z": 22,
      "name": "Rock_Basalt"
    },
    {
      "x": 22,
      "y": 22,
      "z": 22,
      "name": "Rock_Basalt"
    },
    {
      "x": 22,
      "y": 23,
      "z": 22,
      "name": "Soil_Dirt_Burnt"
    },
    {
      "x": 22,
      "y": 24,
      "z": 22,
      "name": "Soil_Dirt_Burnt"
    },
    {
      "x": 22,
      "y": 25,
      "z": 22,
      "name": "Soil_Grass_Burnt"
    },
    {
      "x": 22,
      "y": 26,
      "z": 22,
      "name": "Plant_Grass_Sharp_Tall"
    },
    {
      "x": 22,
      "y": 27,
      "z": 22,
      "name": "Plant_Grass_Sharp_Tall",
      "filler": 1024
    },
    {
      "x": 22,
      "y": 11,
      "z": 23,
      "name": "Rock_Basalt"
    },
    {
      "x": 22,
      "y": 22,
      "z": 23,
      "name": "Rock_Basalt"
    },
    {
      "x": 22,
      "y": 23,
      "z": 23,
      "name": "Soil_Dirt_Burnt"
    },
    {
      "x": 22,
      "y": 24,
      "z": 23,
      "name": "Soil_Dirt_Burnt"
    },
    {
      "x": 22,
      "y": 25,
      "z": 23,
      "name": "Soil_Grass_Burnt"
    },
    {
      "x": 22,
      "y": 26,
      "z": 23,
      "name": "Plant_Grass_Sharp"
    },
    {
      "x": 22,
      "y": 22,
      "z": 24,
      "name": "Rock_Basalt"
    },
    {
      "x": 22,
      "y": 23,
      "z": 24,
      "name": "Soil_Dirt_Burnt"
    },
    {
      "x": 22,
      "y": 24,
      "z": 24,
      "name": "Soil_Dirt_Burnt"
    },
    {
      "x": 22,
      "y": 25,
      "z": 24,
      "name": "Soil_Grass_Burnt"
    },
    {
      "x": 22,
      "y": 23,
      "z": 25,
      "name": "Soil_Grass_Burnt"
    },
    {
      "x": 23,
      "y": 24,
      "z": 8,
      "name": "Rock_Basalt"
    },
    {
      "x": 23,
      "y": 25,
      "z": 8,
      "name": "Soil_Dirt_Burnt"
    },
    {
      "x": 23,
      "y": 26,
      "z": 8,
      "name": "Soil_Grass_Burnt"
    },
    {
      "x": 23,
      "y": 23,
      "z": 9,
      "name": "Rock_Basalt"
    },
    {
      "x": 23,
      "y": 24,
      "z": 9,
      "name": "Rock_Basalt"
    },
    {
      "x": 23,
      "y": 25,
      "z": 9,
      "name": "Rock_Basalt"
    },
    {
      "x": 23,
      "y": 26,
      "z": 9,
      "name": "Soil_Grass_Burnt"
    },
    {
      "x": 23,
      "y": 27,
      "z": 9,
      "name": "Plant_Grass_Sharp_Tall"
    },
    {
      "x": 23,
      "y": 28,
      "z": 9,
      "name": "Plant_Grass_Sharp_Tall",
      "filler": 1024
    },
    {
      "x": 23,
      "y": 22,
      "z": 10,
      "name": "Rock_Basalt"
    },
    {
      "x": 23,
      "y": 23,
      "z": 10,
      "name": "Rock_Basalt"
    },
    {
      "x": 23,
      "y": 24,
      "z": 10,
      "name": "Rock_Basalt"
    },
    {
      "x": 23,
      "y": 25,
      "z": 10,
      "name": "Soil_Dirt_Burnt"
    },
    {
      "x": 23,
      "y": 26,
      "z": 10,
      "name": "Soil_Dirt_Burnt"
    },
    {
      "x": 23,
      "y": 27,
      "z": 10,
      "name": "Soil_Grass_Burnt"
    },
    {
      "x": 23,
      "y": 22,
      "z": 11,
      "name": "Rock_Basalt"
    },
    {
      "x": 23,
      "y": 23,
      "z": 11,
      "name": "Rock_Basalt"
    },
    {
      "x": 23,
      "y": 24,
      "z": 11,
      "name": "Rock_Basalt"
    },
    {
      "x": 23,
      "y": 25,
      "z": 11,
      "name": "Rock_Basalt"
    },
    {
      "x": 23,
      "y": 26,
      "z": 11,
      "name": "Soil_Dirt_Burnt"
    },
    {
      "x": 23,
      "y": 27,
      "z": 11,
      "name": "Soil_Grass_Burnt"
    },
    {
      "x": 23,
      "y": 22,
      "z": 12,
      "name": "Rock_Basalt"
    },
    {
      "x": 23,
      "y": 23,
      "z": 12,
      "name": "Rock_Basalt"
    },
    {
      "x": 23,
      "y": 24,
      "z": 12,
      "name": "Rock_Basalt"
    },
    {
      "x": 23,
      "y": 25,
      "z": 12,
      "name": "Rock_Basalt"
    },
    {
      "x": 23,
      "y": 26,
      "z": 12,
      "name": "Rock_Basalt"
    },
    {
      "x": 23,
      "y": 27,
      "z": 12,
      "name": "Rock_Basalt"
    },
    {
      "x": 23,
      "y": 28,
      "z": 12,
      "name": "Soil_Grass_Burnt"
    },
    {
      "x": 23,
      "y": 22,
      "z": 13,
      "name": "Rock_Basalt"
    },
    {
      "x": 23,
      "y": 23,
      "z": 13,
      "name": "Rock_Basalt"
    },
    {
      "x": 23,
      "y": 24,
      "z": 13,
      "name": "Rock_Basalt"
    },
    {
      "x": 23,
      "y": 25,
      "z": 13,
      "name": "Rock_Basalt"
    },
    {
      "x": 23,
      "y": 26,
      "z": 13,
      "name": "Rock_Basalt"
    },
    {
      "x": 23,
      "y": 27,
      "z": 13,
      "name": "Rock_Basalt"
    },
    {
      "x": 23,
      "y": 28,
      "z": 13,
      "name": "Soil_Grass_Burnt"
    },
    {
      "x": 23,
      "y": 22,
      "z": 14,
      "name": "Rock_Basalt"
    },
    {
      "x": 23,
      "y": 23,
      "z": 14,
      "name": "Rock_Basalt"
    },
    {
      "x": 23,
      "y": 24,
      "z": 14,
      "name": "Rock_Basalt"
    },
    {
      "x": 23,
      "y": 25,
      "z": 14,
      "name": "Rock_Basalt"
    },
    {
      "x": 23,
      "y": 26,
      "z": 14,
      "name": "Rock_Basalt"
    },
    {
      "x": 23,
      "y": 27,
      "z": 14,
      "name": "Rock_Basalt"
    },
    {
      "x": 23,
      "y": 28,
      "z": 14,
      "name": "Soil_Grass_Burnt"
    },
    {
      "x": 23,
      "y": 29,
      "z": 14,
      "name": "Plant_Grass_Sharp_Tall"
    },
    {
      "x": 23,
      "y": 30,
      "z": 14,
      "name": "Plant_Grass_Sharp_Tall",
      "filler": 1024
    },
    {
      "x": 23,
      "y": 22,
      "z": 15,
      "name": "Rock_Basalt"
    },
    {
      "x": 23,
      "y": 23,
      "z": 15,
      "name": "Rock_Basalt"
    },
    {
      "x": 23,
      "y": 24,
      "z": 15,
      "name": "Rock_Basalt"
    },
    {
      "x": 23,
      "y": 25,
      "z": 15,
      "name": "Rock_Basalt"
    },
    {
      "x": 23,
      "y": 26,
      "z": 15,
      "name": "Rock_Basalt"
    },
    {
      "x": 23,
      "y": 27,
      "z": 15,
      "name": "Rock_Basalt"
    },
    {
      "x": 23,
      "y": 28,
      "z": 15,
      "name": "Soil_Grass_Burnt"
    },
    {
      "x": 23,
      "y": 22,
      "z": 16,
      "name": "Rock_Basalt"
    },
    {
      "x": 23,
      "y": 23,
      "z": 16,
      "name": "Rock_Basalt"
    },
    {
      "x": 23,
      "y": 24,
      "z": 16,
      "name": "Rock_Basalt"
    },
    {
      "x": 23,
      "y": 25,
      "z": 16,
      "name": "Rock_Basalt"
    },
    {
      "x": 23,
      "y": 26,
      "z": 16,
      "name": "Rock_Basalt"
    },
    {
      "x": 23,
      "y": 27,
      "z": 16,
      "name": "Rock_Basalt"
    },
    {
      "x": 23,
      "y": 28,
      "z": 16,
      "name": "Soil_Grass_Burnt"
    },
    {
      "x": 23,
      "y": 29,
      "z": 16,
      "name": "Plant_Grass_Gnarled_Short"
    },
    {
      "x": 23,
      "y": 22,
      "z": 17,
      "name": "Rock_Basalt"
    },
    {
      "x": 23,
      "y": 23,
      "z": 17,
      "name": "Rock_Basalt"
    },
    {
      "x": 23,
      "y": 24,
      "z": 17,
      "name": "Rock_Basalt"
    },
    {
      "x": 23,
      "y": 25,
      "z": 17,
      "name": "Rock_Basalt"
    },
    {
      "x": 23,
      "y": 26,
      "z": 17,
      "name": "Rock_Basalt"
    },
    {
      "x": 23,
      "y": 27,
      "z": 17,
      "name": "Rock_Basalt"
    },
    {
      "x": 23,
      "y": 28,
      "z": 17,
      "name": "Soil_Grass_Burnt"
    },
    {
      "x": 23,
      "y": 23,
      "z": 18,
      "name": "Rock_Basalt"
    },
    {
      "x": 23,
      "y": 24,
      "z": 18,
      "name": "Rock_Basalt"
    },
    {
      "x": 23,
      "y": 25,
      "z": 18,
      "name": "Rock_Basalt"
    },
    {
      "x": 23,
      "y": 26,
      "z": 18,
      "name": "Rock_Basalt"
    },
    {
      "x": 23,
      "y": 27,
      "z": 18,
      "name": "Rock_Basalt"
    },
    {
      "x": 23,
      "y": 28,
      "z": 18,
      "name": "Soil_Grass_Burnt"
    },
    {
      "x": 23,
      "y": 23,
      "z": 19,
      "name": "Rock_Basalt"
    },
    {
      "x": 23,
      "y": 24,
      "z": 19,
      "name": "Rock_Basalt"
    },
    {
      "x": 23,
      "y": 25,
      "z": 19,
      "name": "Rock_Basalt"
    },
    {
      "x": 23,
      "y": 26,
      "z": 19,
      "name": "Rock_Basalt"
    },
    {
      "x": 23,
      "y": 27,
      "z": 19,
      "name": "Soil_Grass_Burnt"
    },
    {
      "x": 23,
      "y": 22,
      "z": 20,
      "name": "Rock_Basalt"
    },
    {
      "x": 23,
      "y": 23,
      "z": 20,
      "name": "Rock_Basalt"
    },
    {
      "x": 23,
      "y": 24,
      "z": 20,
      "name": "Rock_Basalt"
    },
    {
      "x": 23,
      "y": 25,
      "z": 20,
      "name": "Rock_Basalt"
    },
    {
      "x": 23,
      "y": 26,
      "z": 20,
      "name": "Soil_Grass_Burnt"
    },
    {
      "x": 23,
      "y": 22,
      "z": 21,
      "name": "Rock_Basalt"
    },
    {
      "x": 23,
      "y": 23,
      "z": 21,
      "name": "Rock_Basalt"
    },
    {
      "x": 23,
      "y": 24,
      "z": 21,
      "name": "Rock_Basalt"
    },
    {
      "x": 23,
      "y": 25,
      "z": 21,
      "name": "Soil_Dirt_Burnt"
    },
    {
      "x": 23,
      "y": 26,
      "z": 21,
      "name": "Soil_Grass_Burnt"
    },
    {
      "x": 23,
      "y": 22,
      "z": 22,
      "name": "Rock_Basalt"
    },
    {
      "x": 23,
      "y": 23,
      "z": 22,
      "name": "Rock_Basalt"
    },
    {
      "x": 23,
      "y": 24,
      "z": 22,
      "name": "Soil_Dirt_Burnt"
    },
    {
      "x": 23,
      "y": 25,
      "z": 22,
      "name": "Soil_Grass_Burnt"
    },
    {
      "x": 23,
      "y": 22,
      "z": 23,
      "name": "Rock_Basalt"
    },
    {
      "x": 23,
      "y": 23,
      "z": 23,
      "name": "Rock_Basalt"
    },
    {
      "x": 23,
      "y": 24,
      "z": 23,
      "name": "Soil_Dirt_Burnt"
    },
    {
      "x": 23,
      "y": 25,
      "z": 23,
      "name": "Soil_Grass_Burnt"
    },
    {
      "x": 23,
      "y": 26,
      "z": 23,
      "name": "Plant_Grass_Sharp"
    },
    {
      "x": 23,
      "y": 23,
      "z": 24,
      "name": "Soil_Dirt_Burnt"
    },
    {
      "x": 23,
      "y": 24,
      "z": 24,
      "name": "Soil_Grass_Burnt"
    },
    {
      "x": 24,
      "y": 23,
      "z": 8,
      "name": "Rock_Basalt"
    },
    {
      "x": 24,
      "y": 24,
      "z": 8,
      "name": "Soil_Dirt_Burnt"
    },
    {
      "x": 24,
      "y": 25,
      "z": 8,
      "name": "Soil_Dirt_Burnt"
    },
    {
      "x": 24,
      "y": 26,
      "z": 8,
      "name": "Soil_Grass_Burnt"
    },
    {
      "x": 24,
      "y": 23,
      "z": 9,
      "name": "Rock_Basalt"
    },
    {
      "x": 24,
      "y": 24,
      "z": 9,
      "name": "Rock_Basalt"
    },
    {
      "x": 24,
      "y": 25,
      "z": 9,
      "name": "Soil_Dirt_Burnt"
    },
    {
      "x": 24,
      "y": 26,
      "z": 9,
      "name": "Soil_Grass_Burnt"
    },
    {
      "x": 24,
      "y": 22,
      "z": 10,
      "name": "Rock_Basalt"
    },
    {
      "x": 24,
      "y": 23,
      "z": 10,
      "name": "Rock_Basalt"
    },
    {
      "x": 24,
      "y": 24,
      "z": 10,
      "name": "Rock_Basalt"
    },
    {
      "x": 24,
      "y": 25,
      "z": 10,
      "name": "Rock_Basalt"
    },
    {
      "x": 24,
      "y": 26,
      "z": 10,
      "name": "Soil_Dirt_Burnt"
    },
    {
      "x": 24,
      "y": 27,
      "z": 10,
      "name": "Soil_Grass_Burnt"
    },
    {
      "x": 24,
      "y": 22,
      "z": 11,
      "name": "Rock_Basalt"
    },
    {
      "x": 24,
      "y": 23,
      "z": 11,
      "name": "Rock_Basalt"
    },
    {
      "x": 24,
      "y": 24,
      "z": 11,
      "name": "Rock_Basalt"
    },
    {
      "x": 24,
      "y": 25,
      "z": 11,
      "name": "Rock_Basalt"
    },
    {
      "x": 24,
      "y": 26,
      "z": 11,
      "name": "Rock_Basalt"
    },
    {
      "x": 24,
      "y": 27,
      "z": 11,
      "name": "Rock_Basalt"
    },
    {
      "x": 24,
      "y": 28,
      "z": 11,
      "name": "Soil_Grass_Burnt"
    },
    {
      "x": 24,
      "y": 22,
      "z": 12,
      "name": "Rock_Basalt"
    },
    {
      "x": 24,
      "y": 23,
      "z": 12,
      "name": "Rock_Basalt"
    },
    {
      "x": 24,
      "y": 24,
      "z": 12,
      "name": "Rock_Basalt"
    },
    {
      "x": 24,
      "y": 25,
      "z": 12,
      "name": "Rock_Basalt"
    },
    {
      "x": 24,
      "y": 26,
      "z": 12,
      "name": "Rock_Basalt"
    },
    {
      "x": 24,
      "y": 27,
      "z": 12,
      "name": "Rock_Basalt"
    },
    {
      "x": 24,
      "y": 28,
      "z": 12,
      "name": "Soil_Grass_Burnt"
    },
    {
      "x": 24,
      "y": 22,
      "z": 13,
      "name": "Rock_Basalt"
    },
    {
      "x": 24,
      "y": 23,
      "z": 13,
      "name": "Rock_Basalt"
    },
    {
      "x": 24,
      "y": 24,
      "z": 13,
      "name": "Rock_Basalt"
    },
    {
      "x": 24,
      "y": 25,
      "z": 13,
      "name": "Rock_Basalt"
    },
    {
      "x": 24,
      "y": 26,
      "z": 13,
      "name": "Rock_Basalt"
    },
    {
      "x": 24,
      "y": 27,
      "z": 13,
      "name": "Rock_Basalt"
    },
    {
      "x": 24,
      "y": 28,
      "z": 13,
      "name": "Soil_Grass_Burnt"
    },
    {
      "x": 24,
      "y": 29,
      "z": 13,
      "name": "Plant_Grass_Sharp"
    },
    {
      "x": 24,
      "y": 22,
      "z": 14,
      "name": "Rock_Basalt"
    },
    {
      "x": 24,
      "y": 23,
      "z": 14,
      "name": "Rock_Basalt"
    },
    {
      "x": 24,
      "y": 24,
      "z": 14,
      "name": "Rock_Basalt"
    },
    {
      "x": 24,
      "y": 25,
      "z": 14,
      "name": "Rock_Basalt"
    },
    {
      "x": 24,
      "y": 26,
      "z": 14,
      "name": "Rock_Basalt"
    },
    {
      "x": 24,
      "y": 27,
      "z": 14,
      "name": "Rock_Basalt"
    },
    {
      "x": 24,
      "y": 28,
      "z": 14,
      "name": "Soil_Grass_Burnt"
    },
    {
      "x": 24,
      "y": 29,
      "z": 14,
      "name": "Plant_Grass_Sharp"
    },
    {
      "x": 24,
      "y": 9,
      "z": 15,
      "name": "Rock_Basalt"
    },
    {
      "x": 24,
      "y": 22,
      "z": 15,
      "name": "Rock_Basalt"
    },
    {
      "x": 24,
      "y": 23,
      "z": 15,
      "name": "Rock_Basalt"
    },
    {
      "x": 24,
      "y": 24,
      "z": 15,
      "name": "Rock_Basalt"
    },
    {
      "x": 24,
      "y": 25,
      "z": 15,
      "name": "Rock_Basalt"
    },
    {
      "x": 24,
      "y": 26,
      "z": 15,
      "name": "Rock_Basalt"
    },
    {
      "x": 24,
      "y": 27,
      "z": 15,
      "name": "Rock_Basalt"
    },
    {
      "x": 24,
      "y": 28,
      "z": 15,
      "name": "Soil_Grass_Burnt"
    },
    {
      "x": 24,
      "y": 29,
      "z": 15,
      "name": "Plant_Grass_Sharp_Tall"
    },
    {
      "x": 24,
      "y": 30,
      "z": 15,
      "name": "Plant_Grass_Sharp_Tall",
      "filler": 1024
    },
    {
      "x": 24,
      "y": 22,
      "z": 16,
      "name": "Rock_Basalt"
    },
    {
      "x": 24,
      "y": 23,
      "z": 16,
      "name": "Rock_Basalt"
    },
    {
      "x": 24,
      "y": 24,
      "z": 16,
      "name": "Rock_Basalt"
    },
    {
      "x": 24,
      "y": 25,
      "z": 16,
      "name": "Rock_Basalt"
    },
    {
      "x": 24,
      "y": 26,
      "z": 16,
      "name": "Rock_Basalt"
    },
    {
      "x": 24,
      "y": 27,
      "z": 16,
      "name": "Rock_Basalt"
    },
    {
      "x": 24,
      "y": 28,
      "z": 16,
      "name": "Soil_Grass_Burnt"
    },
    {
      "x": 24,
      "y": 23,
      "z": 17,
      "name": "Rock_Basalt"
    },
    {
      "x": 24,
      "y": 24,
      "z": 17,
      "name": "Rock_Basalt"
    },
    {
      "x": 24,
      "y": 25,
      "z": 17,
      "name": "Rock_Basalt"
    },
    {
      "x": 24,
      "y": 26,
      "z": 17,
      "name": "Rock_Basalt"
    },
    {
      "x": 24,
      "y": 27,
      "z": 17,
      "name": "Rock_Basalt"
    },
    {
      "x": 24,
      "y": 28,
      "z": 17,
      "name": "Soil_Grass_Burnt"
    },
    {
      "x": 24,
      "y": 29,
      "z": 17,
      "name": "Plant_Grass_Gnarled"
    },
    {
      "x": 24,
      "y": 23,
      "z": 18,
      "name": "Rock_Basalt"
    },
    {
      "x": 24,
      "y": 24,
      "z": 18,
      "name": "Rock_Basalt"
    },
    {
      "x": 24,
      "y": 25,
      "z": 18,
      "name": "Rock_Basalt"
    },
    {
      "x": 24,
      "y": 26,
      "z": 18,
      "name": "Rock_Basalt"
    },
    {
      "x": 24,
      "y": 27,
      "z": 18,
      "name": "Rock_Basalt"
    },
    {
      "x": 24,
      "y": 28,
      "z": 18,
      "name": "Soil_Grass_Burnt"
    },
    {
      "x": 24,
      "y": 23,
      "z": 19,
      "name": "Rock_Basalt"
    },
    {
      "x": 24,
      "y": 24,
      "z": 19,
      "name": "Rock_Basalt"
    },
    {
      "x": 24,
      "y": 25,
      "z": 19,
      "name": "Rock_Basalt"
    },
    {
      "x": 24,
      "y": 26,
      "z": 19,
      "name": "Rock_Basalt"
    },
    {
      "x": 24,
      "y": 27,
      "z": 19,
      "name": "Soil_Grass_Burnt"
    },
    {
      "x": 24,
      "y": 22,
      "z": 20,
      "name": "Rock_Basalt"
    },
    {
      "x": 24,
      "y": 23,
      "z": 20,
      "name": "Rock_Basalt"
    },
    {
      "x": 24,
      "y": 24,
      "z": 20,
      "name": "Rock_Basalt"
    },
    {
      "x": 24,
      "y": 25,
      "z": 20,
      "name": "Rock_Basalt"
    },
    {
      "x": 24,
      "y": 26,
      "z": 20,
      "name": "Soil_Grass_Burnt"
    },
    {
      "x": 24,
      "y": 27,
      "z": 20,
      "name": "Plant_Grass_Sharp_Tall"
    },
    {
      "x": 24,
      "y": 28,
      "z": 20,
      "name": "Plant_Grass_Sharp_Tall",
      "filler": 1024
    },
    {
      "x": 24,
      "y": 22,
      "z": 21,
      "name": "Rock_Basalt"
    },
    {
      "x": 24,
      "y": 23,
      "z": 21,
      "name": "Rock_Basalt"
    },
    {
      "x": 24,
      "y": 24,
      "z": 21,
      "name": "Rock_Basalt"
    },
    {
      "x": 24,
      "y": 25,
      "z": 21,
      "name": "Rock_Basalt"
    },
    {
      "x": 24,
      "y": 26,
      "z": 21,
      "name": "Soil_Grass_Burnt"
    },
    {
      "x": 24,
      "y": 22,
      "z": 22,
      "name": "Rock_Basalt"
    },
    {
      "x": 24,
      "y": 23,
      "z": 22,
      "name": "Rock_Basalt"
    },
    {
      "x": 24,
      "y": 24,
      "z": 22,
      "name": "Rock_Basalt"
    },
    {
      "x": 24,
      "y": 25,
      "z": 22,
      "name": "Rock_Basalt"
    },
    {
      "x": 24,
      "y": 26,
      "z": 22,
      "name": "Soil_Grass_Burnt"
    },
    {
      "x": 24,
      "y": 27,
      "z": 22,
      "name": "Plant_Grass_Sharp_Tall"
    },
    {
      "x": 24,
      "y": 28,
      "z": 22,
      "name": "Plant_Grass_Sharp_Tall",
      "filler": 1024
    },
    {
      "x": 24,
      "y": 22,
      "z": 23,
      "name": "Rock_Basalt"
    },
    {
      "x": 24,
      "y": 23,
      "z": 23,
      "name": "Rock_Basalt"
    },
    {
      "x": 24,
      "y": 24,
      "z": 23,
      "name": "Rock_Basalt"
    },
    {
      "x": 24,
      "y": 25,
      "z": 23,
      "name": "Soil_Grass_Burnt"
    },
    {
      "x": 24,
      "y": 23,
      "z": 24,
      "name": "Rock_Basalt"
    },
    {
      "x": 24,
      "y": 24,
      "z": 24,
      "name": "Soil_Grass_Burnt"
    },
    {
      "x": 25,
