{
  "version": 8,
  "blockIdVersion": 8,
  "anchorX": 0,
  "anchorY": 0,
  "anchorZ": 0,
  "blocks": [
    {
      "x": -18,
      "y": -6,
      "z": 0,
      "name": "Rock_Stone_Cobble"
    },
    {
      "x": -18,
      "y": -5,
      "z": 0,
      "name": "Rock_Stone_Cobble"
    },
    {
      "x": -18,
      "y": -4,
      "z": 0,
      "name": "Rock_Stone_Cobble"
    },
    {
      "x": -18,
      "y": -3,
      "z": 0,
      "name": "Wood_Softwood_Planks"
    },
    {
      "x": -18,
      "y": -2,
      "z": 0,
      "name": "Wood_Softwood_Stairs",
      "rotation": 3
    },
    {
      "x": -18,
      "y": -6,
      "z": 1,
      "name": "Rock_Stone_Cobble"
    },
    {
      "x": -18,
      "y": -5,
      "z": 1,
      "name": "Rock_Stone_Cobble"
    },
    {
      "x": -18,
      "y": -4,
      "z": 1,
      "name": "Rock_Stone_Cobble"
    },
    {
      "x": -18,
      "y": -3,
      "z": 1,
      "name": "Wood_Softwood_Planks"
    },
    {
      "x": -18,
      "y": -2,
      "z": 1,
      "name": "Wood_Softwood_Stairs",
      "rotation": 3
    },
    {
      "x": -18,
      "y": -5,
      "z": 2,
      "name": "Rock_Stone_Cobble"
    },
    {
      "x": -18,
      "y": -4,
      "z": 2,
      "name": "Rock_Stone_Cobble"
    },
    {
      "x": -18,
      "y": -3,
      "z": 2,
      "name": "Wood_Softwood_Planks"
    },
    {
      "x": -18,
      "y": -2,
      "z": 2,
      "name": "Wood_Softwood_Stairs",
      "rotation": 3
    },
    {
      "x": -17,
      "y": -6,
      "z": 0,
      "name": "Rock_Stone_Cobble"
    },
    {
      "x": -17,
      "y": -5,
      "z": 0,
      "name": "Rock_Stone_Cobble"
    },
    {
      "x": -17,
      "y": -4,
      "z": 0,
      "name": "Rock_Stone_Cobble"
    },
    {
      "x": -17,
      "y": -3,
      "z": 0,
      "name": "Wood_Softwood_Planks"
    },
    {
      "x": -17,
      "y": -2,
      "z": 0,
      "name": "Wood_Softwood_Planks"
    },
    {
      "x": -17,
      "y": -1,
      "z": 0,
      "name": "Wood_Softwood_Stairs",
      "rotation": 3
    },
    {
      "x": -17,
      "y": -6,
      "z": 1,
      "name": "Rock_Stone_Cobble"
    },
    {
      "x": -17,
      "y": -5,
      "z": 1,
      "name": "Rock_Stone_Cobble"
    },
    {
      "x": -17,
      "y": -4,
      "z": 1,
      "name": "Rock_Stone_Cobble"
    },
    {
      "x": -17,
      "y": -3,
      "z": 1,
      "name": "Wood_Softwood_Planks"
    },
    {
      "x": -17,
      "y": -2,
      "z": 1,
      "name": "Wood_Softwood_Planks"
    },
    {
      "x": -17,
      "y": -1,
      "z": 1,
      "name": "Wood_Softwood_Stairs",
      "rotation": 3
    },
    {
      "x": -17,
      "y": -6,
      "z": 2,
      "name": "Rock_Stone_Cobble"
    },
    {
      "x": -17,
      "y": -5,
      "z": 2,
      "name": "Rock_Stone_Cobble"
    },
    {
      "x": -17,
      "y": -4,
      "z": 2,
      "name": "Rock_Stone_Cobble"
    },
    {
      "x": -17,
      "y": -3,
      "z": 2,
      "name": "Wood_Softwood_Planks"
    },
    {
      "x": -17,
      "y": -2,
      "z": 2,
      "name": "Wood_Softwood_Planks"
    },
    {
      "x": -17,
      "y": -1,
      "z": 2,
      "name": "Wood_Softwood_Stairs",
      "rotation": 3
    },
    {
      "x": -16,
      "y": 3,
      "z": -7,
      "name": "Wood_Deadwood_Roof_Hollow",
      "rotation": 3
    },
    {
      "x": -16,
      "y": 3,
      "z": -6,
      "name": "Wood_Deadwood_Roof_Hollow",
      "rotation": 3
    },
    {
      "x": -16,
      "y": 3,
      "z": -5,
      "name": "Wood_Deadwood_Roof_Hollow",
      "rotation": 3
    },
    {
      "x": -16,
      "y": 3,
      "z": -4,
      "name": "Wood_Deadwood_Roof_Hollow",
      "rotation": 3
    },
    {
      "x": -16,
      "y": 3,
      "z": -3,
      "name": "Wood_Deadwood_Roof_Hollow",
      "rotation": 3
    },
    {
      "x": -16,
      "y": 3,
      "z": -2,
      "name": "Wood_Deadwood_Roof_Hollow",
      "rotation": 3
    },
    {
      "x": -16,
      "y": 3,
      "z": -1,
      "name": "Wood_Deadwood_Roof_Hollow",
      "rotation": 3
    },
    {
      "x": -16,
      "y": -5,
      "z": 0,
      "name": "Rock_Stone_Cobble"
    },
    {
      "x": -16,
      "y": -4,
      "z": 0,
      "name": "Rock_Stone_Cobble"
    },
    {
      "x": -16,
      "y": -3,
      "z": 0,
      "name": "Wood_Softwood_Planks"
    },
    {
      "x": -16,
      "y": -2,
      "z": 0,
      "name": "Wood_Softwood_Planks"
    },
    {
      "x": -16,
      "y": -1,
      "z": 0,
      "name": "Wood_Softwood_Planks"
    },
    {
      "x": -16,
      "y": 0,
      "z": 0,
      "name": "Wood_Softwood_Stairs",
      "rotation": 3
    },
    {
      "x": -16,
      "y": 3,
      "z": 0,
      "name": "Wood_Deadwood_Roof_Hollow",
      "rotation": 3
    },
    {
      "x": -16,
      "y": -6,
      "z": 1,
      "name": "Rock_Stone_Cobble"
    },
    {
      "x": -16,
      "y": -5,
      "z": 1,
      "name": "Rock_Stone_Cobble"
    },
    {
      "x": -16,
      "y": -4,
      "z": 1,
      "name": "Rock_Stone_Cobble"
    },
    {
      "x": -16,
      "y": -3,
      "z": 1,
      "name": "Wood_Softwood_Planks"
    },
    {
      "x": -16,
      "y": -2,
      "z": 1,
      "name": "Wood_Softwood_Planks"
    },
    {
      "x": -16,
      "y": -1,
      "z": 1,
      "name": "Wood_Softwood_Planks"
    },
    {
      "x": -16,
      "y": 0,
      "z": 1,
      "name": "Wood_Softwood_Stairs",
      "rotation": 3
    },
    {
      "x": -16,
      "y": 3,
      "z": 1,
      "name": "Wood_Deadwood_Roof_Hollow",
      "rotation": 3
    },
    {
      "x": -16,
      "y": -6,
      "z": 2,
      "name": "Rock_Stone_Cobble"
    },
    {
      "x": -16,
      "y": -5,
      "z": 2,
      "name": "Rock_Stone_Cobble"
    },
    {
      "x": -16,
      "y": -4,
      "z": 2,
      "name": "Rock_Stone_Cobble"
    },
    {
      "x": -16,
      "y": -3,
      "z": 2,
      "name": "Wood_Softwood_Planks"
    },
    {
      "x": -16,
      "y": -2,
      "z": 2,
      "name": "Wood_Softwood_Planks"
    },
    {
      "x": -16,
      "y": -1,
      "z": 2,
      "name": "Wood_Softwood_Planks"
    },
    {
      "x": -16,
      "y": 0,
      "z": 2,
      "name": "Wood_Softwood_Stairs",
      "rotation": 3
    },
    {
      "x": -16,
      "y": 3,
      "z": 2,
      "name": "Wood_Deadwood_Roof_Hollow",
      "rotation": 3
    },
    {
      "x": -16,
      "y": 3,
      "z": 3,
      "name": "Wood_Deadwood_Roof_Hollow",
      "rotation": 3
    },
    {
      "x": -16,
      "y": 3,
      "z": 4,
      "name": "Wood_Deadwood_Roof_Hollow",
      "rotation": 3
    },
    {
      "x": -15,
      "y": -5,
      "z": -7,
      "name": "Wood_Beech_Trunk"
    },
    {
      "x": -15,
      "y": -4,
      "z": -7,
      "name": "Wood_Beech_Trunk"
    },
    {
      "x": -15,
      "y": -3,
      "z": -7,
      "name": "Wood_Beech_Trunk"
    },
    {
      "x": -15,
      "y": -2,
      "z": -7,
      "name": "Wood_Beech_Trunk"
    },
    {
      "x": -15,
      "y": -1,
      "z": -7,
      "name": "Wood_Beech_Trunk"
    },
    {
      "x": -15,
      "y": 0,
      "z": -7,
      "name": "Wood_Beech_Trunk"
    },
    {
      "x": -15,
      "y": 1,
      "z": -7,
      "name": "Wood_Beech_Trunk"
    },
    {
      "x": -15,
      "y": 2,
      "z": -7,
      "name": "Wood_Beech_Trunk"
    },
    {
      "x": -15,
      "y": 3,
      "z": -7,
      "name": "Wood_Beech_Trunk"
    },
    {
      "x": -15,
      "y": 4,
      "z": -7,
      "name": "Wood_Deadwood_Roof",
      "rotation": 3
    },
    {
      "x": -15,
      "y": -1,
      "z": -6,
      "name": "Wood_Softwood_Fence",
      "rotation": 1
    },
    {
      "x": -15,
      "y": 0,
      "z": -6,
      "name": "Wood_Beech_Trunk",
      "support": 1,
      "rotation": 4
    },
    {
      "x": -15,
      "y": 1,
      "z": -6,
      "name": "Wood_Softwood_Decorative"
    },
    {
      "x": -15,
      "y": 2,
      "z": -6,
      "name": "Wood_Softwood_Decorative"
    },
    {
      "x": -15,
      "y": 3,
      "z": -6,
      "name": "Wood_Softwood_Decorative"
    },
    {
      "x": -15,
      "y": 4,
      "z": -6,
      "name": "Wood_Deadwood_Roof",
      "rotation": 3
    },
    {
      "x": -15,
      "y": -1,
      "z": -5,
      "name": "Wood_Softwood_Fence",
      "rotation": 1
    },
    {
      "x": -15,
      "y": 0,
      "z": -5,
      "name": "Wood_Beech_Trunk",
      "support": 2,
      "rotation": 4
    },
    {
      "x": -15,
      "y": 1,
      "z": -5,
      "name": "Wood_Softwood_Planks"
    },
    {
      "x": -15,
      "y": 2,
      "z": -5,
      "name": "Furniture_Crude_Window"
    },
    {
      "x": -15,
      "y": 3,
      "z": -5,
      "name": "Wood_Softwood_Planks"
    },
    {
      "x": -15,
      "y": 4,
      "z": -5,
      "name": "Wood_Deadwood_Roof",
      "rotation": 3
    },
    {
      "x": -15,
      "y": -1,
      "z": -4,
      "name": "Wood_Softwood_Fence",
      "rotation": 1
    },
    {
      "x": -15,
      "y": 0,
      "z": -4,
      "name": "Wood_Beech_Trunk",
      "support": 3,
      "rotation": 4
    },
    {
      "x": -15,
      "y": 1,
      "z": -4,
      "name": "Wood_Softwood_Planks"
    },
    {
      "x": -15,
      "y": 2,
      "z": -4,
      "name": "Furniture_Crude_Window"
    },
    {
      "x": -15,
      "y": 3,
      "z": -4,
      "name": "Wood_Softwood_Planks"
    },
    {
      "x": -15,
      "y": 4,
      "z": -4,
      "name": "Wood_Deadwood_Roof",
      "rotation": 3
    },
    {
      "x": -15,
      "y": -1,
      "z": -3,
      "name": "Wood_Softwood_Fence",
      "rotation": 1
    },
    {
      "x": -15,
      "y": 0,
      "z": -3,
      "name": "Wood_Beech_Trunk",
      "support": 4,
      "rotation": 4
    },
    {
      "x": -15,
      "y": 1,
      "z": -3,
      "name": "Wood_Softwood_Planks"
    },
    {
      "x": -15,
      "y": 2,
      "z": -3,
      "name": "Wood_Softwood_Planks"
    },
    {
      "x": -15,
      "y": 3,
      "z": -3,
      "name": "Wood_Softwood_Planks"
    },
    {
      "x": -15,
      "y": 4,
      "z": -3,
      "name": "Wood_Deadwood_Roof",
      "rotation": 3
    },
    {
      "x": -15,
      "y": -1,
      "z": -2,
      "name": "Wood_Softwood_Fence",
      "rotation": 1
    },
    {
      "x": -15,
      "y": 0,
      "z": -2,
      "name": "Wood_Beech_Trunk",
      "support": 5,
      "rotation": 4
    },
    {
      "x": -15,
      "y": 1,
      "z": -2,
      "name": "Wood_Softwood_Planks"
    },
    {
      "x": -15,
      "y": 2,
      "z": -2,
      "name": "Wood_Softwood_Planks"
    },
    {
      "x": -15,
      "y": 3,
      "z": -2,
      "name": "Wood_Softwood_Planks"
    },
    {
      "x": -15,
      "y": 4,
      "z": -2,
      "name": "Wood_Deadwood_Roof",
      "rotation": 3
    },
    {
      "x": -15,
      "y": -1,
      "z": -1,
      "name": "Wood_Softwood_Fence",
      "rotation": 1
    },
    {
      "x": -15,
      "y": 0,
      "z": -1,
      "name": "Wood_Beech_Trunk",
      "support": 5,
      "rotation": 4
    },
    {
      "x": -15,
      "y": 1,
      "z": -1,
      "name": "Wood_Softwood_Planks"
    },
    {
      "x": -15,
      "y": 2,
      "z": -1,
      "name": "Wood_Softwood_Fence",
      "rotation": 3
    },
    {
      "x": -15,
      "y": 3,
      "z": -1,
      "name": "Wood_Softwood_Planks"
    },
    {
      "x": -15,
      "y": 4,
      "z": -1,
      "name": "Wood_Deadwood_Roof",
      "rotation": 3
    },
    {
      "x": -15,
      "y": -1,
      "z": 0,
      "name": "Wood_Softwood_Fence",
      "rotation": 1
    },
    {
      "x": -15,
      "y": 0,
      "z": 0,
      "name": "Wood_Beech_Trunk",
      "support": 4,
      "rotation": 4
    },
    {
      "x": -15,
      "y": 1,
      "z": 0,
      "name": "Wood_Softwood_Planks"
    },
    {
      "x": -15,
      "y": 2,
      "z": 0,
      "name": "Wood_Softwood_Planks"
    },
    {
      "x": -15,
      "y": 3,
      "z": 0,
      "name": "Wood_Softwood_Planks"
    },
    {
      "x": -15,
      "y": 4,
      "z": 0,
      "name": "Wood_Deadwood_Roof",
      "rotation": 3
    },
    {
      "x": -15,
      "y": -1,
      "z": 1,
      "name": "Wood_Softwood_Fence",
      "rotation": 1
    },
    {
      "x": -15,
      "y": 0,
      "z": 1,
      "name": "Wood_Beech_Trunk",
      "support": 3,
      "rotation": 4
    },
    {
      "x": -15,
      "y": 3,
      "z": 1,
      "name": "Wood_Softwood_Planks"
    },
    {
      "x": -15,
      "y": 4,
      "z": 1,
      "name": "Wood_Deadwood_Roof",
      "rotation": 3
    },
    {
      "x": -15,
      "y": -1,
      "z": 2,
      "name": "Wood_Softwood_Fence",
      "rotation": 1
    },
    {
      "x": -15,
      "y": 0,
      "z": 2,
      "name": "Wood_Beech_Trunk",
      "support": 2,
      "rotation": 4
    },
    {
      "x": -15,
      "y": 1,
      "z": 2,
      "name": "Wood_Softwood_Planks"
    },
    {
      "x": -15,
      "y": 2,
      "z": 2,
      "name": "Wood_Softwood_Planks"
    },
    {
      "x": -15,
      "y": 3,
      "z": 2,
      "name": "Wood_Softwood_Planks"
    },
    {
      "x": -15,
      "y": 4,
      "z": 2,
      "name": "Wood_Deadwood_Roof",
      "rotation": 3
    },
    {
      "x": -15,
      "y": -1,
      "z": 3,
      "name": "Wood_Softwood_Fence",
      "rotation": 1
    },
    {
      "x": -15,
      "y": 0,
      "z": 3,
      "name": "Wood_Beech_Trunk",
      "support": 1,
      "rotation": 4
    },
    {
      "x": -15,
      "y": 1,
      "z": 3,
      "name": "Wood_Softwood_Decorative"
    },
    {
      "x": -15,
      "y": 2,
      "z": 3,
      "name": "Wood_Softwood_Decorative"
    },
    {
      "x": -15,
      "y": 3,
      "z": 3,
      "name": "Wood_Softwood_Decorative"
    },
    {
      "x": -15,
      "y": 4,
      "z": 3,
      "name": "Wood_Deadwood_Roof",
      "rotation": 3
    },
    {
      "x": -15,
      "y": -5,
      "z": 4,
      "name": "Wood_Beech_Trunk"
    },
    {
      "x": -15,
      "y": -4,
      "z": 4,
      "name": "Wood_Beech_Trunk"
    },
    {
      "x": -15,
      "y": -3,
      "z": 4,
      "name": "Wood_Beech_Trunk"
    },
    {
      "x": -15,
      "y": -2,
      "z": 4,
      "name": "Wood_Beech_Trunk"
    },
    {
      "x": -15,
      "y": -1,
      "z": 4,
      "name": "Wood_Beech_Trunk"
    },
    {
      "x": -15,
      "y": 0,
      "z": 4,
      "name": "Wood_Beech_Trunk"
    },
    {
      "x": -15,
      "y": 1,
      "z": 4,
      "name": "Wood_Beech_Trunk"
    },
    {
      "x": -15,
      "y": 2,
      "z": 4,
      "name": "Wood_Beech_Trunk"
    },
    {
      "x": -15,
      "y": 3,
      "z": 4,
      "name": "Wood_Beech_Trunk"
    },
    {
      "x": -15,
      "y": 4,
      "z": 4,
      "name": "Wood_Deadwood_Roof",
      "rotation": 3
    },
    {
      "x": -14,
      "y": -1,
      "z": -7,
      "name": "Wood_Softwood_Fence"
    },
    {
      "x": -14,
      "y": 0,
      "z": -7,
      "name": "Wood_Beech_Trunk",
      "support": 1,
      "rotation": 5
    },
    {
      "x": -14,
      "y": 1,
      "z": -7,
      "name": "Plant_Moss_Rug_Green"
    },
    {
      "x": -14,
      "y": 5,
      "z": -7,
      "name": "Wood_Deadwood_Roof_Flat",
      "rotation": 1
    },
    {
      "x": -14,
      "y": 0,
      "z": -6,
      "name": "Wood_Beech_Trunk",
      "support": 1,
      "rotation": 5
    },
    {
      "x": -14,
      "y": 1,
      "z": -6,
      "name": "Wood_Softwood_Decorative"
    },
    {
      "x": -14,
      "y": 2,
      "z": -6,
      "name": "Wood_Softwood_Fence",
      "rotation": 2
    },
    {
      "x": -14,
      "y": 3,
      "z": -6,
      "name": "Wood_Softwood_Decorative"
    },
    {
      "x": -14,
      "y": 4,
      "z": -6,
      "name": "Wood_Softwood_Decorative"
    },
    {
      "x": -14,
      "y": 5,
      "z": -6,
      "name": "Wood_Deadwood_Roof_Flat",
      "rotation": 1
    },
    {
      "x": -14,
      "y": 0,
      "z": -5,
      "name": "Wood_Softwood_Planks"
    },
    {
      "x": -14,
      "y": 1,
      "z": -5,
      "name": "Furniture_Village_Crate"
    },
    {
      "x": -14,
      "y": 2,
      "z": -5,
      "name": "Empty"
    },
    {
      "x": -14,
      "y": 3,
      "z": -5,
      "name": "Empty"
    },
    {
      "x": -14,
      "y": 4,
      "z": -5,
      "name": "Wood_Softwood_Planks"
    },
    {
      "x": -14,
      "y": 5,
      "z": -5,
      "name": "Wood_Deadwood_Roof_Flat",
      "rotation": 1
    },
    {
      "x": -14,
      "y": 0,
      "z": -4,
      "name": "Wood_Softwood_Planks"
    },
    {
      "x": -14,
      "y": 1,
      "z": -4,
      "name": "Furniture_Village_Crate"
    },
    {
      "x": -14,
      "y": 2,
      "z": -4,
      "name": "Empty"
    },
    {
      "x": -14,
      "y": 3,
      "z": -4,
      "name": "Empty"
    },
    {
      "x": -14,
      "y": 4,
      "z": -4,
      "name": "Wood_Softwood_Planks"
    },
    {
      "x": -14,
      "y": 5,
      "z": -4,
      "name": "Wood_Deadwood_Roof_Flat",
      "rotation": 1
    },
    {
      "x": -14,
      "y": 0,
      "z": -3,
      "name": "Wood_Softwood_Planks"
    },
    {
      "x": -14,
      "y": 1,
      "z": -3,
      "name": "Empty"
    },
    {
      "x": -14,
      "y": 2,
      "z": -3,
      "name": "Empty"
    },
    {
      "x": -14,
      "y": 3,
      "z": -3,
      "name": "Empty"
    },
    {
      "x": -14,
      "y": 4,
      "z": -3,
      "name": "Wood_Softwood_Planks"
    },
    {
      "x": -14,
      "y": 5,
      "z": -3,
      "name": "Wood_Deadwood_Roof_Flat",
      "rotation": 1
    },
    {
      "x": -14,
      "y": 0,
      "z": -2,
      "name": "Wood_Softwood_Planks"
    },
    {
      "x": -14,
      "y": 1,
      "z": -2,
      "name": "Empty"
    },
    {
      "x": -14,
      "y": 2,
      "z": -2,
      "name": "Empty"
    },
    {
      "x": -14,
      "y": 3,
      "z": -2,
      "name": "Empty"
    },
    {
      "x": -14,
      "y": 4,
      "z": -2,
      "name": "Wood_Softwood_Planks"
    },
    {
      "x": -14,
      "y": 5,
      "z": -2,
      "name": "Wood_Deadwood_Roof_Flat",
      "rotation": 1
    },
    {
      "x": -14,
      "y": 0,
      "z": -1,
      "name": "Wood_Softwood_Planks"
    },
    {
      "x": -14,
      "y": 1,
      "z": -1,
      "name": "Empty"
    },
    {
      "x": -14,
      "y": 2,
      "z": -1,
      "name": "Empty"
    },
    {
      "x": -14,
      "y": 3,
      "z": -1,
      "name": "Empty"
    },
    {
      "x": -14,
      "y": 4,
      "z": -1,
      "name": "Wood_Softwood_Planks"
    },
    {
      "x": -14,
      "y": 5,
      "z": -1,
      "name": "Wood_Deadwood_Roof_Flat",
      "rotation": 1
    },
    {
      "x": -14,
      "y": 0,
      "z": 0,
      "name": "Wood_Softwood_Planks"
    },
    {
      "x": -14,
      "y": 1,
      "z": 0,
      "name": "Empty"
    },
    {
      "x": -14,
      "y": 2,
      "z": 0,
      "name": "Empty"
    },
    {
      "x": -14,
      "y": 3,
      "z": 0,
      "name": "Empty"
    },
    {
      "x": -14,
      "y": 4,
      "z": 0,
      "name": "Wood_Softwood_Planks"
    },
    {
      "x": -14,
      "y": 5,
      "z": 0,
      "name": "Wood_Deadwood_Roof_Flat",
      "rotation": 1
    },
    {
      "x": -14,
      "y": 0,
      "z": 1,
      "name": "Wood_Softwood_Planks"
    },
    {
      "x": -14,
      "y": 1,
      "z": 1,
      "name": "Empty"
    },
    {
      "x": -14,
      "y": 2,
      "z": 1,
      "name": "Empty"
    },
    {
      "x": -14,
      "y": 3,
      "z": 1,
      "name": "Empty"
    },
    {
      "x": -14,
      "y": 4,
      "z": 1,
      "name": "Wood_Softwood_Planks"
    },
    {
      "x": -14,
      "y": 5,
      "z": 1,
      "name": "Wood_Deadwood_Roof_Flat",
      "rotation": 1
    },
    {
      "x": -14,
      "y": 0,
      "z": 2,
      "name": "Wood_Softwood_Planks"
    },
    {
      "x": -14,
      "y": 1,
      "z": 2,
      "name": "Empty"
    },
    {
      "x": -14,
      "y": 2,
      "z": 2,
      "name": "Empty"
    },
    {
      "x": -14,
      "y": 3,
      "z": 2,
      "name": "Empty"
    },
    {
      "x": -14,
      "y": 4,
      "z": 2,
      "name": "Wood_Softwood_Planks"
    },
    {
      "x": -14,
      "y": 5,
      "z": 2,
      "name": "Wood_Deadwood_Roof_Flat",
      "rotation": 1
    },
    {
      "x": -14,
      "y": 0,
      "z": 3,
      "name": "Wood_Softwood_Planks"
    },
    {
      "x": -14,
      "y": 1,
      "z": 3,
      "name": "Wood_Softwood_Decorative"
    },
    {
      "x": -14,
      "y": 2,
      "z": 3,
      "name": "Wood_Softwood_Decorative"
    },
    {
      "x": -14,
      "y": 3,
      "z": 3,
      "name": "Wood_Softwood_Decorative"
    },
    {
      "x": -14,
      "y": 4,
      "z": 3,
      "name": "Wood_Softwood_Decorative"
    },
    {
      "x": -14,
      "y": 5,
      "z": 3,
      "name": "Wood_Deadwood_Roof_Flat",
      "rotation": 1
    },
    {
      "x": -14,
      "y": -1,
      "z": 4,
      "name": "Wood_Softwood_Fence",
      "rotation": 2
    },
    {
      "x": -14,
      "y": 0,
      "z": 4,
      "name": "Wood_Beech_Trunk",
      "support": 1,
      "rotation": 5
    },
    {
      "x": -14,
      "y": 5,
      "z": 4,
      "name": "Wood_Deadwood_Roof_Flat",
      "rotation": 1
    },
    {
      "x": -13,
      "y": -1,
      "z": -7,
      "name": "Wood_Softwood_Fence"
    },
    {
      "x": -13,
      "y": 0,
      "z": -7,
      "name": "Wood_Beech_Trunk",
      "support": 2,
      "rotation": 5
    },
    {
      "x": -13,
      "y": 1,
      "z": -7,
      "name": "Plant_Moss_Rug_Green"
    },
    {
      "x": -13,
      "y": 5,
      "z": -7,
      "name": "Wood_Deadwood_Roof",
      "rotation": 3
    },
    {
      "x": -13,
      "y": 0,
      "z": -6,
      "name": "Wood_Beech_Trunk",
      "support": 2,
      "rotation": 5
    },
    {
      "x": -13,
      "y": 1,
      "z": -6,
      "name": "Wood_Softwood_Planks"
    },
    {
      "x": -13,
      "y": 2,
      "z": -6,
      "name": "Wood_Softwood_Planks"
    },
    {
      "x": -13,
      "y": 3,
      "z": -6,
      "name": "Wood_Softwood_Planks"
    },
    {
      "x": -13,
      "y": 4,
      "z": -6,
      "name": "Wood_Softwood_Planks"
    },
    {
      "x": -13,
      "y": 5,
      "z": -6,
      "name": "Wood_Deadwood_Roof",
      "rotation": 3
    },
    {
      "x": -13,
      "y": 0,
      "z": -5,
      "name": "Wood_Softwood_Planks"
    },
    {
      "x": -13,
      "y": 1,
      "z": -5,
      "name": "Furniture_Village_Crate"
    },
    {
      "x": -13,
      "y": 2,
      "z": -5,
      "name": "Empty"
    },
    {
      "x": -13,
      "y": 3,
      "z": -5,
      "name": "Empty"
    },
    {
      "x": -13,
      "y": 4,
      "z": -5,
      "name": "Wood_Softwood_Planks_Half",
      "rotation": 8
    },
    {
      "x": -13,
      "y": 5,
      "z": -5,
      "name": "Wood_Deadwood_Roof",
      "rotation": 3
    },
    {
      "x": -13,
      "y": 0,
      "z": -4,
      "name": "Wood_Softwood_Planks"
    },
    {
      "x": -13,
      "y": 1,
      "z": -4,
      "name": "Empty"
    },
    {
      "x": -13,
      "y": 2,
      "z": -4,
      "name": "Empty"
    },
    {
      "x": -13,
      "y": 3,
      "z": -4,
      "name": "Empty"
    },
    {
      "x": -13,
      "y": 4,
      "z": -4,
      "name": "Wood_Softwood_Planks_Half",
      "rotation": 8
    },
    {
      "x": -13,
      "y": 5,
      "z": -4,
      "name": "Wood_Deadwood_Roof",
      "rotation": 3
    },
    {
      "x": -13,
      "y": 0,
      "z": -3,
      "name": "Wood_Softwood_Planks"
    },
    {
      "x": -13,
      "y": 1,
      "z": -3,
      "name": "Empty"
    },
    {
      "x": -13,
      "y": 2,
      "z": -3,
      "name": "Empty"
    },
    {
      "x": -13,
      "y": 3,
      "z": -3,
      "name": "Empty"
    },
    {
      "x": -13,
      "y": 4,
      "z": -3,
      "name": "Wood_Softwood_Planks_Half",
      "rotation": 8
    },
    {
      "x": -13,
      "y": 5,
      "z": -3,
      "name": "Wood_Deadwood_Roof",
      "rotation": 3
    },
    {
      "x": -13,
      "y": 0,
      "z": -2,
      "name": "Wood_Softwood_Planks"
    },
    {
      "x": -13,
      "y": 1,
      "z": -2,
      "name": "Empty"
    },
    {
      "x": -13,
      "y": 2,
      "z": -2,
      "name": "Empty"
    },
    {
      "x": -13,
      "y": 3,
      "z": -2,
      "name": "Empty"
    },
    {
      "x": -13,
      "y": 4,
      "z": -2,
      "name": "Wood_Softwood_Planks_Half",
      "rotation": 8
    },
    {
      "x": -13,
      "y": 5,
      "z": -2,
      "name": "Wood_Deadwood_Roof",
      "rotation": 3
    },
    {
      "x": -13,
      "y": 0,
      "z": -1,
      "name": "Wood_Softwood_Planks"
    },
    {
      "x": -13,
      "y": 1,
      "z": -1,
      "name": "Empty"
    },
    {
      "x": -13,
      "y": 2,
      "z": -1,
      "name": "Empty"
    },
    {
      "x": -13,
      "y": 3,
      "z": -1,
      "name": "Empty"
    },
    {
      "x": -13,
      "y": 4,
      "z": -1,
      "name": "Wood_Softwood_Planks_Half",
      "rotation": 8
    },
    {
      "x": -13,
      "y": 5,
      "z": -1,
      "name": "Wood_Softwood_Planks_Half"
    },
    {
      "x": -13,
      "y": 0,
      "z": 0,
      "name": "Wood_Softwood_Planks"
    },
    {
      "x": -13,
      "y": 1,
      "z": 0,
      "name": "Empty"
    },
    {
      "x": -13,
      "y": 2,
      "z": 0,
      "name": "Empty"
    },
    {
      "x": -13,
      "y": 3,
      "z": 0,
      "name": "Empty"
    },
    {
      "x": -13,
      "y": 4,
      "z": 0,
      "name": "Wood_Softwood_Planks_Half",
      "rotation": 8
    },
    {
      "x": -13,
      "y": 5,
      "z": 0,
      "name": "Wood_Softwood_Planks_Half"
    },
    {
      "x": -13,
      "y": 0,
      "z": 1,
      "name": "Wood_Softwood_Planks"
    },
    {
      "x": -13,
      "y": 1,
      "z": 1,
      "name": "Empty"
    },
    {
      "x": -13,
      "y": 2,
      "z": 1,
      "name": "Empty"
    },
    {
      "x": -13,
      "y": 3,
      "z": 1,
      "name": "Empty"
    },
    {
      "x": -13,
      "y": 4,
      "z": 1,
      "name": "Wood_Softwood_Planks_Half",
      "rotation": 8
    },
    {
      "x": -13,
      "y": 5,
      "z": 1,
      "name": "Wood_Softwood_Planks_Half"
    },
    {
      "x": -13,
      "y": 0,
      "z": 2,
      "name": "Wood_Softwood_Planks"
    },
    {
      "x": -13,
      "y": 1,
      "z": 2,
      "name": "Empty"
    },
    {
      "x": -13,
      "y": 2,
      "z": 2,
      "name": "Empty"
    },
    {
      "x": -13,
      "y": 3,
      "z": 2,
      "name": "Empty"
    },
    {
      "x": -13,
      "y": 4,
      "z": 2,
      "name": "Wood_Softwood_Planks_Half",
      "rotation": 8
    },
    {
      "x": -13,
      "y": 5,
      "z": 2,
      "name": "Wood_Softwood_Planks_Half"
    },
    {
      "x": -13,
      "y": 0,
      "z": 3,
      "name": "Wood_Softwood_Planks"
    },
    {
      "x": -13,
      "y": 1,
      "z": 3,
      "name": "Wood_Softwood_Planks"
    },
    {
      "x": -13,
      "y": 2,
      "z": 3,
      "name": "Wood_Softwood_Planks"
    },
    {
      "x": -13,
      "y": 3,
      "z": 3,
      "name": "Wood_Softwood_Planks"
    },
    {
      "x": -13,
      "y": 4,
      "z": 3,
      "name": "Wood_Softwood_Planks"
    },
    {
      "x": -13,
      "y": 5,
      "z": 3,
      "name": "Wood_Softwood_Planks_Half"
    },
    {
      "x": -13,
      "y": -1,
      "z": 4,
      "name": "Wood_Softwood_Fence",
      "rotation": 2
    },
    {
      "x": -13,
      "y": 0,
      "z": 4,
      "name": "Wood_Beech_Trunk",
      "support": 2,
      "rotation": 5
    },
    {
      "x": -13,
      "y": 5,
      "z": 4,
      "name": "Wood_Deadwood_Roof",
      "rotation": 3
    },
    {
      "x": -12,
      "y": -1,
      "z": -7,
      "name": "Wood_Softwood_Fence"
    },
    {
      "x": -12,
      "y": 0,
      "z": -7,
      "name": "Wood_Beech_Trunk",
      "support": 1,
      "rotation": 5
    },
    {
      "x": -12,
      "y": 6,
      "z": -7,
      "name": "Wood_Deadwood_Roof_Flat",
      "rotation": 1
    },
    {
      "x": -12,
      "y": 0,
      "z": -6,
      "name": "Wood_Beech_Trunk",
      "support": 1,
      "rotation": 5
    },
    {
      "x": -12,
      "y": 1,
      "z": -6,
      "name": "Wood_Softwood_Decorative"
    },
    {
      "x": -12,
      "y": 2,
      "z": -6,
      "name": "Wood_Softwood_Decorative"
    },
    {
      "x": -12,
      "y": 3,
      "z": -6,
      "name": "Wood_Softwood_Decorative"
    },
    {
      "x": -12,
      "y": 4,
      "z": -6,
      "name": "Wood_Softwood_Decorative"
    },
    {
      "x": -12,
      "y": 5,
      "z": -6,
      "name": "Wood_Softwood_Decorative"
    },
    {
      "x": -12,
      "y": 6,
      "z": -6,
      "name": "Wood_Deadwood_Roof_Flat",
      "rotation": 1
    },
    {
      "x": -12,
      "y": 0,
      "z": -5,
      "name": "Wood_Softwood_Planks"
    },
    {
      "x": -12,
      "y": 1,
      "z": -5,
      "name": "Empty"
    },
    {
      "x": -12,
      "y": 2,
      "z": -5,
      "name": "Empty"
    },
    {
      "x": -12,
      "y": 3,
      "z": -5,
      "name": "Empty"
    },
    {
      "x": -12,
      "y": 4,
      "z": -5,
      "name": "Empty"
    },
    {
      "x": -12,
      "y": 5,
      "z": -5,
      "name": "Wood_Softwood_Planks"
    },
    {
      "x": -12,
      "y": 6,
      "z": -5,
      "name": "Wood_Deadwood_Roof_Flat",
      "rotation": 1
    },
    {
      "x": -12,
      "y": 0,
      "z": -4,
      "name": "Wood_Softwood_Planks"
    },
    {
      "x": -12,
      "y": 1,
      "z": -4,
      "name": "Empty"
    },
    {
      "x": -12,
      "y": 2,
      "z": -4,
      "name": "Empty"
    },
    {
      "x": -12,
      "y": 3,
      "z": -4,
      "name": "Empty"
    },
    {
      "x": -12,
      "y": 4,
      "z": -4,
      "name": "Empty"
    },
    {
      "x": -12,
      "y": 5,
      "z": -4,
      "name": "Wood_Softwood_Planks"
    },
    {
      "x": -12,
      "y": 6,
      "z": -4,
      "name": "Wood_Deadwood_Roof_Flat",
      "rotation": 1
    },
    {
      "x": -12,
      "y": 0,
      "z": -3,
      "name": "Wood_Softwood_Planks"
    },
    {
      "x": -12,
      "y": 1,
      "z": -3,
      "name": "Empty"
    },
    {
      "x": -12,
      "y": 2,
      "z": -3,
      "name": "Empty"
    },
    {
      "x": -12,
      "y": 3,
      "z": -3,
      "name": "Empty"
    },
    {
      "x": -12,
      "y": 4,
      "z": -3,
      "name": "Empty"
    },
    {
      "x": -12,
      "y": 5,
      "z": -3,
      "name": "Wood_Softwood_Planks"
    },
    {
      "x": -12,
      "y": 6,
      "z": -3,
      "name": "Wood_Deadwood_Roof_Flat",
      "rotation": 1
    },
    {
      "x": -12,
      "y": 0,
      "z": -2,
      "name": "Wood_Softwood_Planks"
    },
    {
      "x": -12,
      "y": 1,
      "z": -2,
      "name": "Empty"
    },
    {
      "x": -12,
      "y": 2,
      "z": -2,
      "name": "Empty"
    },
    {
      "x": -12,
      "y": 3,
      "z": -2,
      "name": "Empty"
    },
    {
      "x": -12,
      "y": 4,
      "z": -2,
      "name": "Empty"
    },
    {
      "x": -12,
      "y": 5,
      "z": -2,
      "name": "Wood_Softwood_Planks"
    },
    {
      "x": -12,
      "y": 6,
      "z": -2,
      "name": "Wood_Deadwood_Roof_Flat",
      "rotation": 1
    },
    {
      "x": -12,
      "y": 0,
      "z": -1,
      "name": "Wood_Softwood_Planks"
    },
    {
      "x": -12,
      "y": 1,
      "z": -1,
      "name": "Empty"
    },
    {
      "x": -12,
      "y": 2,
      "z": -1,
      "name": "Empty"
    },
    {
      "x": -12,
      "y": 3,
      "z": -1,
      "name": "Empty"
    },
    {
      "x": -12,
      "y": 4,
      "z": -1,
      "name": "Empty"
    },
    {
      "x": -12,
      "y": 5,
      "z": -1,
      "name": "Wood_Softwood_Planks"
    },
    {
      "x": -12,
      "y": 0,
      "z": 0,
      "name": "Wood_Softwood_Planks"
    },
    {
      "x": -12,
      "y": 1,
      "z": 0,
      "name": "Empty"
    },
    {
      "x": -12,
      "y": 2,
      "z": 0,
      "name": "Empty"
    },
    {
      "x": -12,
      "y": 3,
      "z": 0,
      "name": "Empty"
    },
    {
      "x": -12,
      "y": 4,
      "z": 0,
      "name": "Empty"
    },
    {
      "x": -12,
      "y": 5,
      "z": 0,
      "name": "Empty"
    },
    {
      "x": -12,
      "y": 0,
      "z": 1,
      "name": "Wood_Softwood_Planks"
    },
    {
      "x": -12,
      "y": 1,
      "z": 1,
      "name": "Empty"
    },
    {
      "x": -12,
      "y": 2,
      "z": 1,
      "name": "Empty"
    },
    {
      "x": -12,
      "y": 3,
      "z": 1,
      "name": "Empty"
    },
    {
      "x": -12,
      "y": 4,
      "z": 1,
      "name": "Empty"
    },
    {
      "x": -12,
      "y": 5,
      "z": 1,
      "name": "Empty"
    },
    {
      "x": -12,
      "y": 0,
      "z": 2,
      "name": "Wood_Softwood_Planks"
    },
    {
      "x": -12,
      "y": 1,
      "z": 2,
      "name": "Empty"
    },
    {
      "x": -12,
      "y": 2,
      "z": 2,
      "name": "Empty"
    },
    {
      "x": -12,
      "y": 3,
      "z": 2,
      "name": "Empty"
    },
    {
      "x": -12,
      "y": 4,
      "z": 2,
      "name": "Empty"
    },
    {
      "x": -12,
      "y": 5,
      "z": 2,
      "name": "Empty"
    },
    {
      "x": -12,
      "y": 0,
      "z": 3,
      "name": "Wood_Softwood_Planks"
    },
    {
      "x": -12,
      "y": 1,
      "z": 3,
      "name": "Wood_Softwood_Decorative"
    },
    {
      "x": -12,
      "y": 2,
      "z": 3,
      "name": "Wood_Softwood_Decorative"
    },
    {
      "x": -12,
      "y": 3,
      "z": 3,
      "name": "Wood_Softwood_Decorative"
    },
    {
      "x": -12,
      "y": 4,
      "z": 3,
      "name": "Wood_Softwood_Decorative"
    },
    {
      "x": -12,
      "y": 5,
      "z": 3,
      "name": "Wood_Softwood_Decorative"
    },
    {
      "x": -12,
      "y": -1,
      "z": 4,
      "name": "Wood_Softwood_Fence",
      "rotation": 2
    },
    {
      "x": -12,
      "y": 0,
      "z": 4,
      "name": "Wood_Beech_Trunk",
      "support": 1,
      "rotation": 5
    },
    {
      "x": -12,
      "y": 6,
      "z": 4,
      "name": "Wood_Deadwood_Roof_Flat"
    },
    {
      "x": -12,
      "y": 5,
      "z": 5,
      "name": "Wood_Deadwood_Roof_Hollow",
      "rotation": 3
    },
    {
      "x": -12,
      "y": 5,
      "z": 6,
      "name": "Wood_Deadwood_Roof_Hollow",
      "rotation": 3
    },
    {
      "x": -11,
      "y": -5,
      "z": -7,
      "name": "Wood_Beech_Trunk"
    },
    {
      "x": -11,
      "y": -4,
      "z": -7,
      "name": "Wood_Beech_Trunk"
    },
    {
      "x": -11,
      "y": -3,
      "z": -7,
      "name": "Wood_Beech_Trunk"
    },
    {
      "x": -11,
      "y": -2,
      "z": -7,
      "name": "Wood_Beech_Trunk"
    },
    {
      "x": -11,
      "y": -1,
      "z": -7,
      "name": "Wood_Beech_Trunk"
    },
    {
      "x": -11,
      "y": 0,
      "z": -7,
      "name": "Wood_Beech_Trunk"
    },
    {
      "x": -11,
      "y": 1,
      "z": -7,
      "name": "Wood_Beech_Trunk"
    },
    {
      "x": -11,
      "y": 2,
      "z": -7,
      "name": "Wood_Beech_Trunk"
    },
    {
      "x": -11,
      "y": 3,
      "z": -7,
      "name": "Wood_Beech_Trunk"
    },
    {
      "x": -11,
      "y": 4,
      "z": -7,
      "name": "Wood_Beech_Trunk"
    },
    {
      "x": -11,
      "y": 5,
      "z": -7,
      "name": "Wood_Beech_Trunk"
    },
    {
      "x": -11,
      "y": 6,
      "z": -7,
      "name": "Wood_Deadwood_Roof",
      "rotation": 3
    },
    {
      "x": -11,
      "y": -1,
      "z": -6,
      "name": "Wood_Softwood_Fence",
      "rotation": 3
    },
    {
      "x": -11,
      "y": 0,
      "z": -6,
      "name": "Wood_Beech_Trunk",
      "support": 1,
      "rotation": 4
    },
    {
      "x": -11,
      "y": 1,
      "z": -6,
      "name": "Wood_Softwood_Planks"
    },
    {
      "x": -11,
      "y": 2,
      "z": -6,
      "name": "Wood_Softwood_Planks"
    },
    {
      "x": -11,
      "y": 3,
      "z": -6,
      "name": "Wood_Softwood_Planks"
    },
    {
      "x": -11,
      "y": 4,
      "z": -6,
      "name": "Wood_Softwood_Planks"
    },
    {
      "x": -11,
      "y": 5,
      "z": -6,
      "name": "Wood_Softwood_Planks"
    },
    {
      "x": -11,
      "y": 6,
      "z": -6,
      "name": "Wood_Deadwood_Roof",
      "rotation": 3
    },
    {
      "x": -11,
      "y": -1,
      "z": -5,
      "name": "Wood_Softwood_Fence",
      "rotation": 3
    },
    {
      "x": -11,
      "y": 0,
      "z": -5,
      "name": "Wood_Beech_Trunk",
      "support": 1,
      "rotation": 4
    },
    {
      "x": -11,
      "y": 1,
      "z": -5,
      "name": "Wood_Softwood_Planks"
    },
    {
      "x": -11,
      "y": 2,
      "z": -5,
      "name": "Wood_Softwood_Planks"
    },
    {
      "x": -11,
      "y": 3,
      "z": -5,
      "name": "Wood_Softwood_Planks"
    },
    {
      "x": -11,
      "y": 4,
      "z": -5,
      "name": "Wood_Softwood_Planks"
    },
    {
      "x": -11,
      "y": 5,
      "z": -5,
      "name": "Wood_Softwood_Planks"
    },
    {
      "x": -11,
      "y": 6,
      "z": -5,
      "name": "Wood_Deadwood_Roof",
      "rotation": 3
    },
    {
      "x": -11,
      "y": -5,
      "z": -4,
      "name": "Wood_Beech_Trunk"
    },
    {
      "x": -11,
      "y": -4,
      "z": -4,
      "name": "Wood_Beech_Trunk"
    },
    {
      "x": -11,
      "y": -3,
      "z": -4,
      "name": "Wood_Beech_Trunk"
    },
    {
      "x": -11,
      "y": -2,
      "z": -4,
      "name": "Wood_Beech_Trunk"
    },
    {
      "x": -11,
      "y": -1,
      "z": -4,
      "name": "Wood_Beech_Trunk"
    },
    {
      "x": -11,
      "y": 0,
      "z": -4,
      "name": "Wood_Beech_Trunk"
    },
    {
      "x": -11,
      "y": 1,
      "z": -4,
      "name": "Wood_Beech_Trunk"
    },
    {
      "x": -11,
      "y": 2,
      "z": -4,
      "name": "Wood_Beech_Trunk"
    },
    {
      "x": -11,
      "y": 3,
      "z": -4,
      "name": "Wood_Beech_Trunk"
    },
    {
      "x": -11,
      "y": 4,
      "z": -4,
      "name": "Wood_Beech_Trunk"
    },
    {
      "x": -11,
      "y": 5,
      "z": -4,
      "name": "Wood_Beech_Trunk"
    },
    {
      "x": -11,
      "y": 6,
      "z": -4,
      "name": "Wood_Deadwood_Roof",
      "rotation": 3
    },
    {
      "x": -11,
      "y": 0,
      "z": -3,
      "name": "Wood_Softwood_Planks"
    },
    {
      "x": -11,
      "y": 1,
      "z": -3,
      "name": "Empty"
    },
    {
      "x": -11,
      "y": 2,
      "z": -3,
      "name": "Empty"
    },
    {
      "x": -11,
      "y": 3,
      "z": -3,
      "name": "Empty"
    },
    {
      "x": -11,
      "y": 4,
      "z": -3,
      "name": "Empty"
    },
    {
      "x": -11,
      "y": 5,
      "z": -3,
      "name": "Wood_Softwood_Planks_Half",
      "rotation": 8
    },
    {
      "x": -11,
      "y": 6,
      "z": -3,
      "name": "Wood_Deadwood_Roof",
      "rotation": 3
    },
    {
      "x": -11,
      "y": 0,
      "z": -2,
      "name": "Wood_Softwood_Planks"
    },
    {
      "x": -11,
      "y": 1,
      "z": -2,
      "name": "Empty"
    },
    {
      "x": -11,
      "y": 2,
      "z": -2,
      "name": "Empty"
    },
    {
      "x": -11,
      "y": 3,
      "z": -2,
      "name": "Empty"
    },
    {
      "x": -11,
      "y": 4,
      "z": -2,
      "name": "Empty"
    },
    {
      "x": -11,
      "y": 5,
      "z": -2,
      "name": "Wood_Softwood_Planks_Half",
      "rotation": 8
    },
    {
      "x": -11,
      "y": 6,
      "z": -2,
      "name": "Wood_Deadwood_Roof",
      "rotation": 3
    },
    {
      "x": -11,
      "y": 0,
      "z": -1,
      "name": "Wood_Softwood_Planks"
    },
    {
      "x": -11,
      "y": 1,
      "z": -1,
      "name": "Empty"
    },
    {
      "x": -11,
      "y": 2,
      "z": -1,
      "name": "Empty"
    },
    {
      "x": -11,
      "y": 3,
      "z": -1,
      "name": "Empty"
    },
    {
      "x": -11,
      "y": 4,
      "z": -1,
      "name": "Empty"
    },
    {
      "x": -11,
      "y": 5,
      "z": -1,
      "name": "Wood_Softwood_Planks_Half",
      "rotation": 8
    },
    {
      "x": -11,
      "y": 6,
      "z": -1,
      "name": "Wood_Softwood_Planks_Half"
    },
    {
      "x": -11,
      "y": 0,
      "z": 0,
      "name": "Wood_Softwood_Planks"
    },
    {
      "x": -11,
      "y": 1,
      "z": 0,
      "name": "Empty"
    },
    {
      "x": -11,
      "y": 2,
      "z": 0,
      "name": "Empty"
    },
    {
      "x": -11,
      "y": 3,
      "z": 0,
      "name": "Empty"
    },
    {
      "x": -11,
      "y": 4,
      "z": 0,
      "name": "Empty"
    },
    {
      "x": -11,
      "y": 5,
      "z": 0,
      "name": "Empty"
    },
    {
      "x": -11,
      "y": 0,
      "z": 1,
      "name": "Wood_Softwood_Planks"
    },
    {
      "x": -11,
      "y": 1,
      "z": 1,
      "name": "Empty"
    },
    {
      "x": -11,
      "y": 2,
      "z": 1,
      "name": "Empty"
    },
    {
      "x": -11,
      "y": 3,
      "z": 1,
      "name": "Empty"
    },
    {
      "x": -11,
      "y": 4,
      "z": 1,
      "name": "Empty"
    },
    {
      "x": -11,
      "y": 5,
      "z": 1,
      "name": "Empty"
    },
    {
      "x": -11,
      "y": 0,
      "z": 2,
      "name": "Wood_Softwood_Planks"
    },
    {
      "x": -11,
      "y": 1,
      "z": 2,
      "name": "Empty"
    },
    {
      "x": -11,
      "y": 2,
      "z": 2,
      "name": "Empty"
    },
    {
      "x": -11,
      "y": 3,
      "z": 2,
      "name": "Empty"
    },
    {
      "x": -11,
      "y": 4,
      "z": 2,
      "name": "Empty"
    },
    {
      "x": -11,
      "y": 5,
      "z": 2,
      "name": "Empty"
    },
    {
      "x": -11,
      "y": 0,
      "z": 3,
      "name": "Wood_Softwood_Planks"
    },
    {
      "x": -11,
      "y": 1,
      "z": 3,
      "name": "Empty"
    },
    {
      "x": -11,
      "y": 2,
      "z": 3,
      "name": "Empty"
    },
    {
      "x": -11,
      "y": 3,
      "z": 3,
      "name": "Empty"
    },
    {
      "x": -11,
      "y": 4,
      "z": 3,
      "name": "Empty"
    },
    {
      "x": -11,
      "y": 5,
      "z": 3,
      "name": "Wood_Softwood_Planks_Half",
      "rotation": 8
    },
    {
      "x": -11,
      "y": 6,
      "z": 3,
      "name": "Wood_Softwood_Planks_Half"
    },
    {
      "x": -11,
      "y": -5,
      "z": 4,
      "name": "Wood_Beech_Trunk"
    },
    {
      "x": -11,
      "y": -4,
      "z": 4,
      "name": "Wood_Beech_Trunk"
    },
    {
      "x": -11,
      "y": -3,
      "z": 4,
      "name": "Wood_Beech_Trunk"
    },
    {
      "x": -11,
      "y": -2,
      "z": 4,
      "name": "Wood_Beech_Trunk"
    },
    {
      "x": -11,
      "y": -1,
      "z": 4,
      "name": "Wood_Beech_Trunk"
    },
    {
      "x": -11,
      "y": 0,
      "z": 4,
      "name": "Wood_Beech_Trunk"
    },
    {
      "x": -11,
      "y": 1,
      "z": 4,
      "name": "Wood_Beech_Trunk"
    },
    {
      "x": -11,
      "y": 2,
      "z": 4,
      "name": "Wood_Beech_Trunk"
    },
    {
      "x": -11,
      "y": 3,
      "z": 4,
      "name": "Wood_Beech_Trunk"
    },
    {
      "x": -11,
      "y": 4,
      "z": 4,
      "name": "Wood_Beech_Trunk"
    },
    {
      "x": -11,
      "y": 5,
      "z": 4,
      "name": "Wood_Beech_Trunk"
    },
    {
      "x": -11,
      "y": 6,
      "z": 4,
      "name": "Wood_Deadwood_Roof",
      "rotation": 3
    },
    {
      "x": -11,
      "y": -1,
      "z": 5,
      "name": "Wood_Softwood_Fence",
      "rotation": 1
    },
    {
      "x": -11,
      "y": 0,
      "z": 5,
      "name": "Wood_Beech_Trunk",
      "support": 1,
      "rotation": 4
    },
    {
      "x": -11,
      "y": 1,
      "z": 5,
      "name": "Wood_Softwood_Planks"
    },
    {
      "x": -11,
      "y": 2,
      "z": 5,
      "name": "Wood_Softwood_Planks"
    },
    {
      "x": -11,
      "y": 3,
      "z": 5,
      "name": "Wood_Softwood_Planks"
    },
    {
      "x": -11,
      "y": 4,
      "z": 5,
      "name": "Wood_Softwood_Planks"
    },
    {
      "x": -11,
      "y": 5,
      "z": 5,
      "name": "Wood_Softwood_Planks"
    },
    {
      "x": -11,
      "y": 6,
      "z": 5,
      "name": "Wood_Deadwood_Roof",
      "rotation": 3
    },
    {
      "x": -11,
      "y": -5,
      "z": 6,
      "name": "Wood_Beech_Trunk"
    },
    {
      "x": -11,
      "y": -4,
      "z": 6,
      "name": "Wood_Beech_Trunk"
    },
    {
      "x": -11,
      "y": -3,
      "z": 6,
      "name": "Wood_Beech_Trunk"
    },
    {
      "x": -11,
      "y": -2,
      "z": 6,
      "name": "Wood_Beech_Trunk"
    },
    {
      "x": -11,
      "y": -1,
      "z": 6,
      "name": "Wood_Beech_Trunk"
    },
    {
      "x": -11,
      "y": 0,
      "z": 6,
      "name": "Wood_Beech_Trunk"
    },
    {
      "x": -11,
      "y": 1,
      "z": 6,
      "name": "Wood_Beech_Trunk"
    },
    {
      "x": -11,
      "y": 2,
      "z": 6,
      "name": "Wood_Beech_Trunk"
    },
    {
      "x": -11,
      "y": 3,
      "z": 6,
      "name": "Wood_Beech_Trunk"
    },
    {
      "x": -11,
      "y": 4,
      "z": 6,
      "name": "Wood_Beech_Trunk"
    },
    {
      "x": -11,
      "y": 5,
      "z": 6,
      "name": "Wood_Beech_Trunk"
    },
    {
      "x": -11,
      "y": 6,
      "z": 6,
      "name": "Wood_Deadwood_Roof",
      "rotation": 3
    },
    {
      "x": -10,
      "y": 7,
      "z": -6,
      "name": "Wood_Deadwood_Roof_Flat",
      "rotation": 1
    },
    {
      "x": -10,
      "y": 0,
      "z": -5,
      "name": "Wood_Beech_Trunk",
      "support": 1,
      "rotation": 5
    },
    {
      "x": -10,
      "y": 1,
      "z": -5,
      "name": "Wood_Softwood_Planks"
    },
    {
      "x": -10,
      "y": 2,
      "z": -5,
      "name": "Wood_Softwood_Planks"
    },
    {
      "x": -10,
      "y": 3,
      "z": -5,
      "name": "Wood_Softwood_Planks"
    },
    {
      "x": -10,
      "y": 4,
      "z": -5,
      "name": "Wood_Softwood_Planks"
    },
    {
      "x": -10,
      "y": 5,
      "z": -5,
      "name": "Wood_Softwood_Planks"
    },
    {
      "x": -10,
      "y": 6,
      "z": -5,
      "name": "Wood_Softwood_Planks"
    },
    {
      "x": -10,
      "y": 7,
      "z": -5,
      "name": "Wood_Deadwood_Roof_Flat",
      "rotation": 1
    },
    {
      "x": -10,
      "y": 0,
      "z": -4,
      "name": "Wood_Softwood_Planks"
    },
    {
      "x": -10,
      "y": 1,
      "z": -4,
      "name": "Empty"
    },
    {
      "x": -10,
      "y": 2,
      "z": -4,
      "name": "Empty"
    },
    {
      "x": -10,
      "y": 3,
      "z": -4,
      "name": "Empty"
    },
    {
      "x": -10,
      "y": 4,
      "z": -4,
      "name": "Empty"
    },
    {
      "x": -10,
      "y": 5,
      "z": -4,
      "name": "Empty"
    },
    {
      "x": -10,
      "y": 6,
      "z": -4,
      "name": "Wood_Softwood_Planks"
    },
    {
      "x": -10,
      "y": 7,
      "z": -4,
      "name": "Wood_Deadwood_Roof_Flat",
      "rotation": 1
    },
    {
      "x": -10,
      "y": 0,
      "z": -3,
      "name": "Wood_Softwood_Planks"
    },
    {
      "x": -10,
      "y": 1,
      "z": -3,
      "name": "Empty"
    },
    {
      "x": -10,
      "y": 2,
      "z": -3,
      "name": "Empty"
    },
    {
      "x": -10,
      "y": 3,
      "z": -3,
      "name": "Empty"
    },
    {
      "x": -10,
      "y": 4,
      "z": -3,
      "name": "Empty"
    },
    {
      "x": -10,
      "y": 5,
      "z": -3,
      "name": "Empty"
    },
    {
      "x": -10,
      "y": 6,
      "z": -3,
      "name": "Wood_Softwood_Planks"
    },
    {
      "x": -10,
      "y": 7,
      "z": -3,
      "name": "Wood_Deadwood_Roof_Flat",
      "rotation": 1
    },
    {
      "x": -10,
      "y": 0,
      "z": -2,
      "name": "Wood_Softwood_Planks"
    },
    {
      "x": -10,
      "y": 1,
      "z": -2,
      "name": "Empty"
    },
    {
      "x": -10,
      "y": 2,
      "z": -2,
      "name": "Empty"
    },
    {
      "x": -10,
      "y": 3,
      "z": -2,
      "name": "Empty"
    },
    {
      "x": -10,
      "y": 4,
      "z": -2,
      "name": "Empty"
    },
    {
      "x": -10,
      "y": 5,
      "z": -2,
      "name": "Empty"
    },
    {
      "x": -10,
      "y": 6,
      "z": -2,
      "name": "Wood_Softwood_Planks"
    },
    {
      "x": -10,
      "y": 7,
      "z": -2,
      "name": "Wood_Deadwood_Roof_Flat",
      "rotation": 1
    },
    {
      "x": -10,
      "y": 0,
      "z": -1,
      "name": "Wood_Softwood_Planks"
    },
    {
      "x": -10,
      "y": 1,
      "z": -1,
      "name": "Empty"
    },
    {
      "x": -10,
      "y": 2,
      "z": -1,
      "name": "Empty"
    },
    {
      "x": -10,
      "y": 3,
      "z": -1,
      "name": "Empty"
    },
    {
      "x": -10,
      "y": 4,
      "z": -1,
      "name": "Empty"
    },
    {
      "x": -10,
      "y": 5,
      "z": -1,
      "name": "Empty"
    },
    {
      "x": -10,
      "y": 6,
      "z": -1,
      "name": "Wood_Softwood_Planks"
    },
    {
      "x": -10,
      "y": 0,
      "z": 0,
      "name": "Wood_Softwood_Planks"
    },
    {
      "x": -10,
      "y": 1,
      "z": 0,
      "name": "Empty"
    },
    {
      "x": -10,
      "y": 2,
      "z": 0,
      "name": "Empty"
    },
    {
      "x": -10,
      "y": 3,
      "z": 0,
      "name": "Empty"
    },
    {
      "x": -10,
      "y": 4,
      "z": 0,
      "name": "Empty"
    },
    {
      "x": -10,
      "y": 5,
      "z": 0,
      "name": "Empty"
    },
    {
      "x": -10,
      "y": 0,
      "z": 1,
      "name": "Wood_Softwood_Planks"
    },
    {
      "x": -10,
      "y": 1,
      "z": 1,
      "name": "Empty"
    },
    {
      "x": -10,
      "y": 2,
      "z": 1,
      "name": "Empty"
    },
    {
      "x": -10,
      "y": 3,
      "z": 1,
      "name": "Empty"
    },
    {
      "x": -10,
      "y": 4,
      "z": 1,
      "name": "Empty"
    },
    {
      "x": -10,
      "y": 5,
      "z": 1,
      "name": "Empty"
    },
    {
      "x": -10,
      "y": 0,
      "z": 2,
      "name": "Wood_Softwood_Planks"
    },
    {
      "x": -10,
      "y": 1,
      "z": 2,
      "name": "Empty"
    },
    {
      "x": -10,
      "y": 2,
      "z": 2,
      "name": "Empty"
    },
    {
      "x": -10,
      "y": 3,
      "z": 2,
      "name": "Empty"
    },
    {
      "x": -10,
      "y": 4,
      "z": 2,
      "name": "Empty"
    },
    {
      "x": -10,
      "y": 5,
      "z": 2,
      "name": "Empty"
    },
    {
      "x": -10,
      "y": 0,
      "z": 3,
      "name": "Wood_Softwood_Planks"
    },
    {
      "x": -10,
      "y": 1,
      "z": 3,
      "name": "Rubble_Stone_Mossy"
    },
    {
      "x": -10,
      "y": 2,
      "z": 3,
      "name": "Empty"
    },
    {
      "x": -10,
      "y": 3,
      "z": 3,
      "name": "Empty"
    },
    {
      "x": -10,
      "y": 4,
      "z": 3,
      "name": "Empty"
    },
    {
      "x": -10,
      "y": 5,
      "z": 3,
      "name": "Empty"
    },
    {
      "x": -10,
      "y": 6,
      "z": 3,
      "name": "Wood_Softwood_Planks"
    },
    {
      "x": -10,
      "y": -2,
      "z": 4,
      "name": "Rock_Stone_Cobble"
    },
    {
      "x": -10,
      "y": -1,
      "z": 4,
      "name": "Rock_Stone_Cobble"
    },
    {
      "x": -10,
      "y": 0,
      "z": 4,
      "name": "Rock_Stone_Cobble"
    },
    {
      "x": -10,
      "y": 1,
      "z": 4,
      "name": "Rock_Stone_Cobble"
    },
    {
      "x": -10,
      "y": 2,
      "z": 4,
      "name": "Rock_Stone_Cobble"
    },
    {
      "x": -10,
      "y": 3,
      "z": 4,
      "name": "Empty"
    },
    {
      "x": -10,
      "y": 4,
      "z": 4,
      "name": "Empty"
    },
    {
      "x": -10,
      "y": 5,
      "z": 4,
      "name": "Empty"
    },
    {
      "x": -10,
      "y": 6,
      "z": 4,
      "name": "Wood_Softwood_Planks"
    },
    {
      "x": -10,
      "y": 7,
      "z": 4,
      "name": "Wood_Deadwood_Roof_Flat",
      "rotation": 1
    },
    {
      "x": -10,
      "y": -3,
      "z": 5,
      "name": "Rock_Stone_Cobble"
    },
    {
      "x": -10,
      "y": -2,
      "z": 5,
      "name": "Rock_Stone_Cobble"
    },
    {
      "x": -10,
      "y": -1,
      "z": 5,
      "name": "Rock_Stone_Cobble"
    },
    {
      "x": -10,
      "y": 0,
      "z": 5,
      "name": "Rock_Stone_Cobble"
    },
    {
      "x": -10,
      "y": 1,
      "z": 5,
      "name": "Rock_Stone_Cobble"
    },
    {
      "x": -10,
      "y": 2,
      "z": 5,
      "name": "Rock_Stone_Cobble"
    },
    {
      "x": -10,
      "y": 3,
      "z": 5,
      "name": "Rock_Stone_Cobble"
    },
    {
      "x": -10,
      "y": 4,
      "z": 5,
      "name": "Empty"
    },
    {
      "x": -10,
      "y": 5,
      "z": 5,
      "name": "Empty"
    },
    {
      "x": -10,
      "y": 6,
      "z": 5,
      "name": "Wood_Softwood_Planks"
    },
    {
      "x": -10,
      "y": 7,
      "z": 5,
      "name": "Wood_Deadwood_Roof_Flat",
      "rotation": 1
    },
    {
      "x": -10,
      "y": -3,
      "z": 6,
      "name": "Rock_Stone_Cobble"
    },
    {
      "x": -10,
      "y": -2,
      "z": 6,
      "name": "Rock_Stone_Cobble"
    },
    {
      "x": -10,
      "y": -1,
      "z": 6,
      "name": "Rock_Stone_Cobble"
    },
    {
      "x": -10,
      "y": 0,
      "z": 6,
      "name": "Rock_Stone_Cobble"
    },
    {
      "x": -10,
      "y": 1,
      "z": 6,
      "name": "Rock_Stone_Cobble"
    },
    {
      "x": -10,
      "y": 2,
      "z": 6,
      "name": "Rock_Stone_Cobble"
    },
    {
      "x": -10,
      "y": 3,
      "z": 6,
      "name": "Wood_Softwood_Planks"
    },
    {
      "x": -10,
      "y": 4,
      "z": 6,
      "name": "Wood_Softwood_Planks"
    },
    {
      "x": -10,
      "y": 5,
      "z": 6,
      "name": "Wood_Softwood_Planks"
    },
    {
      "x": -10,
      "y": 6,
      "z": 6,
      "name": "Wood_Softwood_Planks"
    },
    {
      "x": -10,
      "y": 7,
      "z": 6,
      "name": "Wood_Deadwood_Roof_Flat",
      "rotation": 1
    },
    {
      "x": -10,
      "y": -2,
      "z": 7,
      "name": "Rock_Stone_Cobble"
    },
    {
      "x": -10,
      "y": -1,
      "z": 7,
      "name": "Rock_Stone_Cobble"
    },
    {
      "x": -10,
      "y": 0,
      "z": 7,
      "name": "Rock_Stone_Cobble"
    },
    {
      "x": -10,
      "y": 1,
      "z": 7,
      "name": "Rock_Stone_Cobble"
    },
    {
      "x": -10,
      "y": 2,
      "z": 7,
      "name": "Rock_Stone_Cobble"
    },
    {
      "x": -10,
      "y": 3,
      "z": 7,
      "name": "Rock_Stone_Cobble"
    },
    {
      "x": -9,
      "y": 7,
      "z": -6,
      "name": "Wood_Deadwood_Roof_Flat",
      "rotation": 1
    },
    {
      "x": -9,
      "y": 0,
      "z": -5,
      "name": "Wood_Beech_Trunk",
      "support": 2,
      "rotation": 5
    },
    {
      "x": -9,
      "y": 1,
      "z": -5,
      "name": "Wood_Softwood_Planks"
    },
    {
      "x": -9,
      "y": 2,
      "z": -5,
      "name": "Wood_Softwood_Planks"
    },
    {
      "x": -9,
      "y": 3,
      "z": -5,
      "name": "Wood_Softwood_Planks"
    },
    {
      "x": -9,
      "y": 4,
      "z": -5,
      "name": "Wood_Softwood_Planks"
    },
    {
      "x": -9,
      "y": 5,
      "z": -5,
      "name": "Wood_Softwood_Planks"
    },
    {
      "x": -9,
      "y": 6,
      "z": -5,
      "name": "Wood_Softwood_Planks"
    },
    {
      "x": -9,
      "y": 7,
      "z": -5,
      "name": "Wood_Deadwood_Roof_Flat",
      "rotation": 1
    },
    {
      "x": -9,
      "y": 0,
      "z": -4,
      "name": "Wood_Softwood_Planks"
    },
    {
      "x": -9,
      "y": 1,
      "z": -4,
      "name": "Empty"
    },
    {
      "x": -9,
      "y": 2,
      "z": -4,
      "name": "Empty"
    },
    {
      "x": -9,
      "y": 3,
      "z": -4,
      "name": "Empty"
    },
    {
      "x": -9,
      "y": 4,
      "z": -4,
      "name": "Empty"
    },
    {
      "x": -9,
      "y": 5,
      "z": -4,
      "name": "Empty"
    },
    {
      "x": -9,
      "y": 6,
      "z": -4,
      "name": "Wood_Softwood_Planks"
    },
    {
      "x": -9,
      "y": 7,
      "z": -4,
      "name": "Wood_Deadwood_Roof_Flat",
      "rotation": 1
    },
    {
      "x": -9,
      "y": 0,
      "z": -3,
      "name": "Wood_Softwood_Planks"
    },
    {
      "x": -9,
      "y": 1,
      "z": -3,
      "name": "Empty"
    },
    {
      "x": -9,
      "y": 2,
      "z": -3,
      "name": "Empty"
    },
    {
      "x": -9,
      "y": 3,
      "z": -3,
      "name": "Empty"
    },
    {
      "x": -9,
      "y": 4,
      "z": -3,
      "name": "Empty"
    },
    {
      "x": -9,
      "y": 5,
      "z": -3,
      "name": "Empty"
    },
    {
      "x": -9,
      "y": 6,
      "z": -3,
      "name": "Wood_Softwood_Planks"
    },
    {
      "x": -9,
      "y": 7,
      "z": -3,
      "name": "Wood_Deadwood_Roof_Flat",
      "rotation": 1
    },
    {
      "x": -9,
      "y": 0,
      "z": -2,
      "name": "Wood_Softwood_Planks"
    },
    {
      "x": -9,
      "y": 1,
      "z": -2,
      "name": "Empty"
    },
    {
      "x": -9,
      "y": 2,
      "z": -2,
      "name": "Empty"
    },
    {
      "x": -9,
      "y": 3,
      "z": -2,
      "name": "Empty"
    },
    {
      "x": -9,
      "y": 4,
      "z": -2,
      "name": "Empty"
    },
    {
      "x": -9,
      "y": 5,
      "z": -2,
      "name": "Empty"
    },
    {
      "x": -9,
      "y": 6,
      "z": -2,
      "name": "Wood_Softwood_Planks"
    },
    {
      "x": -9,
      "y": 7,
      "z": -2,
      "name": "Wood_Deadwood_Roof_Flat",
      "rotation": 1
    },
    {
      "x": -9,
      "y": 0,
      "z": -1,
      "name": "Wood_Softwood_Planks"
    },
    {
      "x": -9,
      "y": 1,
      "z": -1,
      "name": "Empty"
    },
    {
      "x": -9,
      "y": 2,
      "z": -1,
      "name": "Empty"
    },
    {
      "x": -9,
      "y": 3,
      "z": -1,
      "name": "Empty"
    },
    {
      "x": -9,
      "y": 4,
      "z": -1,
      "name": "Empty"
    },
    {
      "x": -9,
      "y": 5,
      "z": -1,
      "name": "Empty"
    },
    {
      "x": -9,
      "y": 6,
      "z": -1,
      "name": "Wood_Softwood_Planks"
    },
    {
      "x": -9,
      "y": 7,
      "z": -1,
      "name": "Wood_Softwood_Planks_Half"
    },
    {
      "x": -9,
      "y": 0,
      "z": 0,
      "name": "Wood_Softwood_Planks"
    },
    {
      "x": -9,
      "y": 1,
      "z": 0,
      "name": "Empty"
    },
    {
      "x": -9,
      "y": 2,
      "z": 0,
      "name": "Empty"
    },
    {
      "x": -9,
      "y": 3,
      "z": 0,
      "name": "Empty"
    },
    {
      "x": -9,
      "y": 4,
      "z": 0,
      "name": "Empty"
    },
    {
      "x": -9,
      "y": 5,
      "z": 0,
      "name": "Empty"
    },
    {
      "x": -9,
      "y": 6,
      "z": 0,
      "name": "Wood_Softwood_Planks"
    },
    {
      "x": -9,
      "y": 7,
      "z": 0,
      "name": "Wood_Softwood_Planks_Half"
    },
    {
      "x": -9,
      "y": 0,
      "z": 1,
      "name": "Wood_Softwood_Planks"
    },
    {
      "x": -9,
      "y": 1,
      "z": 1,
      "name": "Empty"
    },
    {
      "x": -9,
      "y": 2,
      "z": 1,
      "name": "Empty"
    },
    {
      "x": -9,
      "y": 3,
      "z": 1,
      "name": "Empty"
    },
    {
      "x": -9,
      "y": 4,
      "z": 1,
      "name": "Empty"
    },
    {
      "x": -9,
      "y": 5,
      "z": 1,
      "name": "Empty"
    },
    {
      "x": -9,
      "y": 6,
      "z": 1,
      "name": "Wood_Softwood_Planks"
    },
    {
      "x": -9,
      "y": 7,
      "z": 1,
      "name": "Wood_Softwood_Planks_Half"
    },
    {
      "x": -9,
      "y": 0,
      "z": 2,
      "name": "Wood_Softwood_Planks"
    },
    {
      "x": -9,
      "y": 1,
      "z": 2,
      "name": "Empty"
    },
    {
      "x": -9,
      "y": 2,
      "z": 2,
      "name": "Empty"
    },
    {
      "x": -9,
      "y": 3,
      "z": 2,
      "name": "Empty"
    },
    {
      "x": -9,
      "y": 4,
      "z": 2,
      "name": "Empty"
    },
    {
      "x": -9,
      "y": 5,
      "z": 2,
      "name": "Empty"
    },
    {
      "x": -9,
      "y": 6,
      "z": 2,
      "name": "Wood_Softwood_Planks"
    },
    {
      "x": -9,
      "y": 7,
      "z": 2,
      "name": "Wood_Softwood_Planks_Half"
    },
    {
      "x": -9,
      "y": 0,
      "z": 3,
      "name": "Wood_Softwood_Planks"
    },
    {
      "x": -9,
      "y": 1,
      "z": 3,
      "name": "Empty"
    },
    {
      "x": -9,
      "y": 2,
      "z": 3,
      "name": "Empty"
    },
    {
      "x": -9,
      "y": 3,
      "z": 3,
      "name": "Empty"
    },
    {
      "x": -9,
      "y": 4,
      "z": 3,
      "name": "Empty"
    },
    {
      "x": -9,
      "y": 5,
      "z": 3,
      "name": "Empty"
    },
    {
      "x": -9,
      "y": 6,
      "z": 3,
      "name": "Wood_Softwood_Planks"
    },
    {
      "x": -9,
      "y": 7,
      "z": 3,
      "name": "Wood_Softwood_Planks_Half"
    },
    {
      "x": -9,
      "y": -4,
      "z": 4,
      "name": "Rock_Stone_Cobble"
    },
    {
      "x": -9,
      "y": -3,
      "z": 4,
      "name": "Rock_Stone_Cobble"
    },
    {
      "x": -9,
      "y": -2,
      "z": 4,
      "name": "Rock_Stone_Cobble"
    },
    {
      "x": -9,
      "y": -1,
      "z": 4,
      "name": "Rock_Stone_Cobble"
    },
    {
      "x": -9,
      "y": 0,
      "z": 4,
      "name": "Rock_Stone_Cobble"
    },
    {
      "x": -9,
      "y": 1,
      "z": 4,
      "name": "Empty"
    },
    {
      "x": -9,
      "y": 2,
      "z": 4,
      "name": "Empty"
    },
    {
      "x": -9,
      "y": 3,
      "z": 4,
      "name": "Empty"
    },
    {
      "x": -9,
      "y": 4,
      "z": 4,
      "name": "Empty"
    },
    {
      "x": -9,
      "y": 5,
      "z": 4,
      "name": "Empty"
    },
    {
      "x": -9,
      "y": 6,
      "z": 4,
      "name": "Wood_Softwood_Planks"
    },
    {
      "x": -9,
      "y": 7,
      "z": 4,
      "name": "Wood_Deadwood_Roof_Flat",
      "rotation": 1
    },
    {
      "x": -9,
      "y": -4,
      "z": 5,
      "name": "Rock_Stone_Cobble"
    },
    {
      "x": -9,
      "y": -3,
      "z": 5,
      "name": "Rock_Stone_Cobble"
    },
    {
      "x": -9,
      "y": -2,
      "z": 5,
      "name": "Rock_Stone_Cobble"
    },
    {
      "x": -9,
      "y": -1,
      "z": 5,
      "name": "Rock_Stone_Cobble"
    },
    {
      "x": -9,
      "y": 0,
      "z": 5,
      "name": "Rock_Stone_Cobble"
    },
    {
      "x": -9,
      "y": 1,
      "z": 5,
      "name": "Plant_Moss_Rug_Green"
    },
    {
      "x": -9,
      "y": 2,
      "z": 5,
      "name": "Rock_Stone_Cobble"
    },
    {
      "x": -9,
      "y": 3,
      "z": 5,
      "name": "Rock_Stone_Cobble"
    },
    {
      "x": -9,
      "y": 4,
      "z": 5,
      "name": "Rock_Stone_Cobble"
    },
    {
      "x": -9,
      "y": 5,
      "z": 5,
      "name": "Rock_Stone_Cobble"
    },
    {
      "x": -9,
      "y": 6,
      "z": 5,
      "name": "Rock_Stone_Cobble"
    },
    {
      "x": -9,
      "y": 7,
      "z": 5,
      "name": "Rock_Stone_Cobble"
    },
    {
      "x": -9,
      "y": 8,
      "z": 5,
      "name": "Rock_Stone_Cobble"
    },
    {
      "x": -9,
      "y": 9,
      "z": 5,
      "name": "Rock_Stone_Cobble"
    },
    {
      "x": -9,
      "y": 10,
      "z": 5,
      "name": "Rock_Stone_Cobble"
    },
    {
      "x": -9,
      "y": -4,
      "z": 6,
      "name": "Rock_Stone_Cobble"
    },
    {
      "x": -9,
      "y": -3,
      "z": 6,
      "name": "Rock_Stone_Cobble"
    },
    {
      "x": -9,
      "y": -2,
      "z": 6,
      "name": "Rock_Stone_Cobble"
    },
    {
      "x": -9,
      "y": -1,
      "z": 6,
      "name": "Rock_Stone_Cobble"
    },
    {
      "x": -9,
      "y": 0,
      "z": 6,
      "name": "Rock_Stone_Cobble"
    },
    {
      "x": -9,
      "y": 1,
      "z": 6,
      "name": "Plant_Moss_Rug_Green"
    },
    {
      "x": -9,
      "y": 2,
      "z": 6,
      "name": "Rock_Stone_Cobble"
    },
    {
      "x": -9,
      "y": 3,
      "z": 6,
      "name": "Rock_Stone_Cobble"
    },
    {
      "x": -9,
      "y": 4,
      "z": 6,
      "name": "Rock_Stone_Cobble"
    },
    {
      "x": -9,
      "y": 5,
      "z": 6,
      "name": "Rock_Stone_Cobble"
    },
    {
      "x": -9,
      "y": 6,
      "z": 6,
      "name": "Rock_Stone_Cobble"
    },
    {
      "x": -9,
      "y": 7,
      "z": 6,
      "name": "Rock_Stone_Cobble"
    },
    {
      "x": -9,
      "y": 8,
      "z": 6,
      "name": "Rock_Stone_Cobble"
    },
    {
      "x": -9,
      "y": 9,
      "z": 6,
      "name": "Rock_Stone_Cobble"
    },
    {
      "x": -9,
      "y": 10,
      "z": 6,
      "name": "Rock_Stone_Cobble"
    },
    {
      "x": -9,
      "y": 11,
      "z": 6,
      "name": "Rock_Stone_Cobble"
    },
    {
      "x": -9,
      "y": 12,
      "z": 6,
      "name": "Rock_Stone_Cobble"
    },
    {
      "x": -9,
      "y": 13,
      "z": 6,
      "name": "Rock_Stone_Cobble"
    },
    {
      "x": -9,
      "y": -3,
      "z": 7,
      "name": "Rock_Stone_Cobble"
    },
    {
      "x": -9,
      "y": -2,
      "z": 7,
      "name": "Rock_Stone_Cobble"
    },
    {
      "x": -9,
      "y": -1,
      "z": 7,
      "name": "Rock_Stone_Cobble"
    },
    {
      "x": -9,
      "y": 0,
      "z": 7,
      "name": "Rock_Stone_Cobble"
    },
    {
      "x": -9,
      "y": 1,
      "z": 7,
      "name": "Rock_Stone_Cobble"
    },
    {
      "x": -9,
      "y": 2,
      "z": 7,
      "name": "Rock_Stone_Cobble"
    },
    {
      "x": -9,
      "y": 3,
      "z": 7,
      "name": "Rock_Stone_Cobble"
    },
    {
      "x": -9,
      "y": 4,
      "z": 7,
      "name": "Rock_Stone_Cobble"
    },
    {
      "x": -9,
      "y": 5,
      "z": 7,
      "name": "Rock_Stone_Cobble"
    },
    {
      "x": -9,
      "y": 6,
      "z": 7,
      "name": "Rock_Stone_Cobble"
    },
    {
      "x": -9,
      "y": 7,
      "z": 7,
      "name": "Rock_Stone_Cobble"
    },
    {
      "x": -9,
      "y": 8,
      "z": 7,
      "name": "Rock_Stone_Cobble"
    },
    {
      "x": -9,
      "y": 9,
      "z": 7,
      "name": "Rock_Stone_Cobble"
    },
    {
      "x": -9,
      "y": 10,
      "z": 7,
      "name": "Rock_Stone_Cobble"
    },
    {
      "x": -8,
      "y": 7,
      "z": -6,
      "name": "Wood_Deadwood_Roof_Hollow",
      "rotation": 3
    },
    {
      "x": -8,
      "y": 0,
      "z": -5,
      "name": "Wood_Beech_Trunk",
      "support": 2,
      "rotation": 5
    },
    {
      "x": -8,
      "y": 1,
      "z": -5,
      "name": "Wood_Softwood_Planks"
    },
    {
      "x": -8,
      "y": 2,
      "z": -5,
      "name": "Wood_Softwood_Planks"
    },
    {
      "x": -8,
      "y": 3,
      "z": -5,
      "name": "Wood_Softwood_Planks"
    },
    {
      "x": -8,
      "y": 4,
      "z": -5,
      "name": "Wood_Softwood_Planks"
    },
    {
      "x": -8,
      "y": 5,
      "z": -5,
      "name": "Wood_Softwood_Planks"
    },
    {
      "x": -8,
      "y": 6,
      "z": -5,
      "name": "Wood_Softwood_Planks"
    },
    {
      "x": -8,
      "y": 7,
      "z": -5,
      "name": "Wood_Deadwood_Roof",
      "rotation": 3
    },
    {
      "x": -8,
      "y": 0,
      "z": -4,
      "name": "Wood_Softwood_Planks"
    },
    {
      "x": -8,
      "y": 1,
      "z": -4,
      "name": "Empty"
    },
    {
      "x": -8,
      "y": 2,
      "z": -4,
      "name": "Empty"
    },
    {
      "x": -8,
      "y": 3,
      "z": -4,
      "name": "Empty"
    },
    {
      "x": -8,
      "y": 4,
      "z": -4,
      "name": "Empty"
    },
    {
      "x": -8,
      "y": 5,
      "z": -4,
      "name": "Empty"
    },
    {
      "x": -8,
      "y": 6,
      "z": -4,
      "name": "Wood_Softwood_Planks"
    },
    {
      "x": -8,
      "y": 7,
      "z": -4,
      "name": "Wood_Deadwood_Roof",
      "rotation": 3
    },
    {
      "x": -8,
      "y": 0,
      "z": -3,
      "name": "Wood_Softwood_Planks"
    },
    {
      "x": -8,
      "y": 1,
      "z": -3,
      "name": "Empty"
    },
    {
      "x": -8,
      "y": 2,
      "z": -3,
      "name": "Empty"
    },
    {
      "x": -8,
      "y": 3,
      "z": -3,
      "name": "Empty"
    },
    {
      "x": -8,
      "y": 4,
      "z": -3,
      "name": "Empty"
    },
    {
      "x": -8,
      "y": 5,
      "z": -3,
      "name": "Empty"
    },
    {
      "x": -8,
      "y": 6,
      "z": -3,
      "name": "Wood_Softwood_Planks"
    },
    {
      "x": -8,
      "y": 7,
      "z": -3,
      "name": "Wood_Deadwood_Roof",
      "rotation": 3
    },
    {
      "x": -8,
      "y": 0,
      "z": -2,
      "name": "Wood_Softwood_Planks"
    },
    {
      "x": -8,
      "y": 1,
      "z": -2,
      "name": "Empty"
    },
    {
      "x": -8,
      "y": 2,
      "z": -2,
      "name": "Empty"
    },
    {
      "x": -8,
      "y": 3,
      "z": -2,
      "name": "Empty"
    },
    {
      "x": -8,
      "y": 4,
      "z": -2,
      "name": "Empty"
    },
    {
      "x": -8,
      "y": 5,
      "z": -2,
      "name": "Empty"
    },
    {
      "x": -8,
      "y": 6,
      "z": -2,
      "name": "Wood_Softwood_Planks"
    },
    {
      "x": -8,
      "y": 7,
      "z": -2,
      "name": "Wood_Deadwood_Roof",
      "rotation": 3
    },
    {
      "x": -8,
      "y": 0,
      "z": -1,
      "name": "Wood_Softwood_Planks"
    },
    {
      "x": -8,
      "y": 1,
      "z": -1,
      "name": "Empty"
    },
    {
      "x": -8,
      "y": 2,
      "z": -1,
      "name": "Empty"
    },
    {
      "x": -8,
      "y": 3,
      "z": -1,
      "name": "Empty"
    },
    {
      "x": -8,
      "y": 4,
      "z": -1,
      "name": "Empty"
    },
    {
      "x": -8,
      "y": 5,
      "z": -1,
      "name": "Empty"
    },
    {
      "x": -8,
      "y": 6,
      "z": -1,
      "name": "Wood_Softwood_Planks"
    },
    {
      "x": -8,
      "y": 7,
      "z": -1,
      "name": "Wood_Deadwood_Roof",
      "rotation": 3
    },
    {
      "x": -8,
      "y": 0,
      "z": 0,
      "name": "Wood_Softwood_Planks"
    },
    {
      "x": -8,
      "y": 1,
      "z": 0,
      "name": "Empty"
    },
    {
      "x": -8,
      "y": 2,
      "z": 0,
      "name": "Empty"
    },
    {
      "x": -8,
      "y": 3,
      "z": 0,
      "name": "Empty"
    },
    {
      "x": -8,
      "y": 4,
      "z": 0,
      "name": "Empty"
    },
    {
      "x": -8,
      "y": 5,
      "z": 0,
      "name": "Empty"
    },
    {
      "x": -8,
      "y": 6,
      "z": 0,
      "name": "Wood_Softwood_Planks"
    },
    {
      "x": -8,
      "y": 7,
      "z": 0,
      "name": "Wood_Deadwood_Roof",
      "rotation": 3
    },
    {
      "x": -8,
      "y": 0,
      "z": 1,
      "name": "Wood_Softwood_Planks"
    },
    {
      "x": -8,
      "y": 1,
      "z": 1,
      "name": "Empty"
    },
    {
      "x": -8,
      "y": 2,
      "z": 1,
      "name": "Empty"
    },
    {
      "x": -8,
      "y": 3,
      "z": 1,
      "name": "Empty"
    },
    {
      "x": -8,
      "y": 4,
      "z": 1,
      "name": "Empty"
    },
    {
      "x": -8,
      "y": 5,
      "z": 1,
      "name": "Empty"
    },
    {
      "x": -8,
      "y": 6,
      "z": 1,
      "name": "Wood_Softwood_Planks"
    },
    {
      "x": -8,
      "y": 7,
      "z": 1,
      "name": "Wood_Deadwood_Roof",
      "rotation": 3
    },
    {
      "x": -8,
      "y": 0,
      "z": 2,
      "name": "Wood_Softwood_Planks"
    },
    {
      "x": -8,
      "y": 1,
      "z": 2,
      "name": "Empty"
    },
    {
      "x": -8,
      "y": 2,
      "z": 2,
      "name": "Empty"
    },
    {
      "x": -8,
      "y": 3,
      "z": 2,
      "name": "Empty"
    },
    {
      "x": -8,
      "y": 4,
      "z": 2,
      "name": "Empty"
    },
    {
      "x": -8,
      "y": 5,
      "z": 2,
      "name": "Empty"
    },
    {
      "x": -8,
      "y": 6,
      "z": 2,
      "name": "Wood_Softwood_Planks"
    },
    {
      "x": -8,
      "y": 7,
      "z": 2,
      "name": "Wood_Deadwood_Roof",
      "rotation": 3
    },
    {
      "x": -8,
      "y": 0,
      "z": 3,
      "name": "Wood_Softwood_Planks"
    },
    {
      "x": -8,
      "y": 1,
      "z": 3,
      "name": "Empty"
    },
    {
      "x": -8,
      "y": 2,
      "z": 3,
      "name": "Empty"
    },
    {
      "x": -8,
      "y": 3,
      "z": 3,
      "name": "Empty"
    },
    {
      "x": -8,
      "y": 4,
      "z": 3,
      "name": "Empty"
    },
    {
      "x": -8,
      "y": 5,
      "z": 3,
      "name": "Empty"
    },
    {
      "x": -8,
      "y": 6,
      "z": 3,
      "name": "Wood_Softwood_Planks"
    },
    {
      "x": -8,
      "y": 7,
      "z": 3,
      "name": "Wood_Deadwood_Roof",
      "rotation": 3
    },
    {
      "x": -8,
      "y": -4,
      "z": 4,
      "name": "Rock_Stone_Cobble"
    },
    {
      "x": -8,
      "y": -3,
      "z": 4,
      "name": "Rock_Stone_Cobble"
    },
    {
      "x": -8,
      "y": -2,
      "z": 4,
      "name": "Rock_Stone_Cobble"
    },
    {
      "x": -8,
      "y": -1,
      "z": 4,
      "name": "Rock_Stone_Cobble"
    },
    {
      "x": -8,
      "y": 0,
      "z": 4,
      "name": "Rock_Stone_Cobble"
    },
    {
      "x": -8,
      "y": 1,
      "z": 4,
      "name": "Empty"
    },
    {
      "x": -8,
      "y": 2,
      "z": 4,
      "name": "Empty"
    },
    {
      "x": -8,
      "y": 3,
      "z": 4,
      "name": "Empty"
    },
    {
      "x": -8,
      "y": 4,
      "z": 4,
      "name": "Empty"
    },
    {
      "x": -8,
      "y": 5,
      "z": 4,
      "name": "Empty"
    },
    {
      "x": -8,
      "y": 6,
      "z": 4,
      "name": "Wood_Softwood_Planks"
    },
    {
      "x": -8,
      "y": 7,
      "z": 4,
      "name": "Wood_Deadwood_Roof",
      "rotation": 3
    },
    {
      "x": -8,
      "y": -4,
      "z": 5,
      "name": "Rock_Stone_Cobble"
    },
    {
      "x": -8,
      "y": -3,
      "z": 5,
      "name": "Rock_Stone_Cobble"
    },
    {
      "x": -8,
      "y": -2,
      "z": 5,
      "name": "Rock_Stone_Cobble"
    },
    {
      "x": -8,
      "y": -1,
      "z": 5,
      "name": "Rock_Stone_Cobble"
    },
    {
      "x": -8,
      "y": 0,
      "z": 5,
      "name": "Rock_Stone_Cobble"
    },
    {
      "x": -8,
      "y": 1,
      "z": 5,
      "name": "Plant_Moss_Rug_Green"
    },
    {
      "x": -8,
      "y": 2,
      "z": 5,
      "name": "Empty"
    },
    {
      "x": -8,
      "y": 3,
      "z": 5,
      "name": "Rock_Stone_Cobble"
    },
    {
      "x": -8,
      "y": 4,
      "z": 5,
      "name": "Rock_Stone_Cobble"
    },
    {
      "x": -8,
      "y": 5,
      "z": 5,
      "name": "Rock_Stone_Cobble"
    },
    {
      "x": -8,
      "y": 6,
      "z": 5,
      "name": "Rock_Stone_Cobble"
    },
    {
      "x": -8,
      "y": 7,
      "z": 5,
      "name": "Rock_Stone_Cobble"
    },
    {
      "x": -8,
      "y": 8,
      "z": 5,
      "name": "Rock_Stone_Cobble"
    },
    {
      "x": -8,
      "y": 9,
      "z": 5,
      "name": "Rock_Stone_Cobble"
    },
    {
      "x": -8,
      "y": 10,
      "z": 5,
      "name": "Rock_Stone_Cobble"
    },
    {
      "x": -8,
      "y": 11,
      "z": 5,
      "name": "Rock_Stone_Cobble"
    },
    {
      "x": -8,
      "y": 12,
      "z": 5,
      "name": "Rock_Stone_Cobble"
    },
    {
      "x": -8,
      "y": 13,
      "z": 5,
      "name": "Rock_Stone_Cobble"
    },
    {
      "x": -8,
      "y": -4,
      "z": 6,
      "name": "Rock_Stone_Cobble"
    },
    {
      "x": -8,
      "y": -3,
      "z": 6,
      "name": "Rock_Stone_Cobble"
    },
    {
      "x": -8,
      "y": -2,
      "z": 6,
      "name": "Rock_Stone_Cobble"
    },
    {
      "x": -8,
      "y": -1,
      "z": 6,
      "name": "Rock_Stone_Cobble"
    },
    {
      "x": -8,
      "y": 0,
      "z": 6,
      "name": "Rock_Stone_Cobble"
    },
    {
      "x": -8,
      "y": 1,
      "z": 6,
      "name": "Plant_Moss_Rug_Green"
    },
    {
      "x": -8,
      "y": 2,
      "z": 6,
      "name": "Empty"
    },
    {
      "x": -8,
      "y": -3,
      "z": 7,
      "name": "Rock_Stone_Cobble"
    },
    {
      "x": -8,
      "y": -2,
      "z": 7,
      "name": "Rock_Stone_Cobble"
    },
    {
      "x": -8,
      "y": -1,
      "z": 7,
      "name": "Rock_Stone_Cobble"
    },
    {
      "x": -8,
      "y": 0,
      "z": 7,
      "name": "Rock_Stone_Cobble"
    },
    {
      "x": -8,
      "y": 1,
      "z": 7,
      "name": "Rock_Stone_Cobble"
    },
    {
      "x": -8,
      "y": 2,
      "z": 7,
      "name": "Rock_Stone_Cobble"
    },
    {
      "x": -8,
      "y": 3,
      "z": 7,
      "name": "Rock_Stone_Cobble"
    },
    {
      "x": -8,
      "y": 4,
      "z": 7,
      "name": "Rock_Stone_Cobble"
    },
    {
      "x": -8,
      "y": 5,
      "z": 7,
      "name": "Rock_Stone_Cobble"
    },
    {
      "x": -8,
      "y": 6,
      "z": 7,
      "name": "Rock_Stone_Cobble"
    },
    {
      "x": -8,
      "y": 7,
      "z": 7,
      "name": "Rock_Stone_Cobble"
    },
    {
      "x": -8,
      "y": 8,
      "z": 7,
      "name": "Rock_Stone_Cobble"
    },
    {
      "x": -8,
      "y": 9,
      "z": 7,
      "name": "Rock_Stone_Cobble"
    },
    {
      "x": -8,
      "y": 10,
      "z": 7,
      "name": "Rock_Stone_Cobble"
    },
    {
      "x": -8,
      "y": 11,
      "z": 7,
      "name": "Rock_Stone_Cobble"
    },
    {
      "x": -8,
      "y": 12,
      "z": 7,
      "name": "Rock_Stone_Cobble"
    },
    {
      "x": -8,
      "y": 13,
      "z": 7,
      "name": "Rock_Stone_Cobble"
    },
    {
      "x": -8,
      "y": 14,
      "z": 7,
      "name": "Plant_Fern_Winter"
    },
    {
      "x": -7,
      "y": 8,
      "z": -6,
      "name": "Wood_Deadwood_Roof_Flat",
      "rotation": 1
    },
    {
      "x": -7,
      "y": 0,
      "z": -5,
      "name": "Wood_Beech_Trunk",
      "support": 1,
      "rotation": 5
    },
    {
      "x": -7,
      "y": 1,
      "z": -5,
      "name": "Wood_Softwood_Planks"
    },
    {
      "x": -7,
      "y": 2,
      "z": -5,
      "name": "Wood_Softwood_Planks"
    },
    {
      "x": -7,
      "y": 3,
      "z": -5,
      "name": "Wood_Softwood_Planks"
    },
    {
      "x": -7,
      "y": 4,
      "z": -5,
      "name": "Wood_Softwood_Planks"
    },
    {
      "x": -7,
      "y": 5,
      "z": -5,
      "name": "Wood_Softwood_Planks"
    },
    {
      "x": -7,
      "y": 6,
      "z": -5,
      "name": "Wood_Softwood_Planks"
    },
    {
      "x": -7,
      "y": 7,
      "z": -5,
      "name": "Wood_Softwood_Planks"
    },
    {
      "x": -7,
      "y": 8,
      "z": -5,
      "name": "Wood_Deadwood_Roof_Flat",
      "rotation": 1
    },
    {
      "x": -7,
      "y": 0,
      "z": -4,
      "name": "Wood_Softwood_Planks"
    },
    {
      "x": -7,
      "y": 1,
      "z": -4,
      "name": "Empty"
    },
    {
      "x": -7,
      "y": 2,
      "z": -4,
      "name": "Empty"
    },
    {
      "x": -7,
      "y": 3,
      "z": -4,
      "name": "Empty"
    },
    {
      "x": -7,
      "y": 4,
      "z": -4,
      "name": "Empty"
    },
    {
      "x": -7,
      "y": 5,
      "z": -4,
      "name": "Empty"
    },
    {
      "x": -7,
      "y": 6,
      "z": -4,
      "name": "Wood_Softwood_Planks"
    },
    {
      "x": -7,
      "y": 7,
      "z": -4,
      "name": "Wood_Softwood_Planks"
    },
    {
      "x": -7,
      "y": 8,
      "z": -4,
      "name": "Wood_Deadwood_Roof_Flat",
      "rotation": 1
    },
    {
      "x": -7,
      "y": 0,
      "z": -3,
      "name": "Wood_Softwood_Planks"
    },
    {
      "x": -7,
      "y": 1,
      "z": -3,
      "name": "Empty"
    },
    {
      "x": -7,
      "y": 2,
      "z": -3,
      "name": "Empty"
    },
    {
      "x": -7,
      "y": 3,
      "z": -3,
      "name": "Empty"
    },
    {
      "x": -7,
      "y": 4,
      "z": -3,
      "name": "Empty"
    },
    {
      "x": -7,
      "y": 5,
      "z": -3,
      "name": "Empty"
    },
    {
      "x": -7,
      "y": 6,
      "z": -3,
      "name": "Wood_Softwood_Planks"
    },
    {
      "x": -7,
      "y": 7,
      "z": -3,
      "name": "Wood_Softwood_Planks"
    },
    {
      "x": -7,
      "y": 8,
      "z": -3,
      "name": "Wood_Deadwood_Roof_Flat",
      "rotation": 1
    },
    {
      "x": -7,
      "y": 0,
      "z": -2,
      "name": "Wood_Softwood_Planks"
    },
    {
      "x": -7,
      "y": 1,
      "z": -2,
      "name": "Rail",
      "rotation": 1
    },
    {
      "x": -7,
      "y": 2,
      "z": -2,
      "name": "Empty"
    },
    {
      "x": -7,
      "y": 3,
      "z": -2,
      "name": "Empty"
    },
    {
      "x": -7,
      "y": 4,
      "z": -2,
      "name": "Empty"
    },
    {
      "x": -7,
      "y": 5,
      "z": -2,
      "name": "Empty"
    },
    {
      "x": -7,
      "y": 6,
      "z": -2,
      "name": "Wood_Softwood_Planks"
    },
    {
      "x": -7,
      "y": 7,
      "z": -2,
      "name": "Wood_Softwood_Planks"
    },
    {
      "x": -7,
      "y": 8,
      "z": -2,
      "name": "Wood_Deadwood_Roof_Flat",
      "rotation": 1
    },
    {
      "x": -7,
      "y": 0,
      "z": -1,
      "name": "Wood_Softwood_Planks"
    },
    {
      "x": -7,
      "y": 1,
      "z": -1,
      "name": "Empty"
    },
    {
      "x": -7,
      "y": 2,
      "z": -1,
      "name": "Empty"
    },
    {
      "x": -7,
      "y": 3,
      "z": -1,
      "name": "Empty"
    },
    {
      "x": -7,
      "y": 4,
      "z": -1,
      "name": "Empty"
    },
    {
      "x": -7,
      "y": 5,
      "z": -1,
      "name": "Empty"
    },
    {
      "x": -7,
      "y": 6,
      "z": -1,
      "name": "Wood_Softwood_Planks"
    },
    {
      "x": -7,
      "y": 7,
      "z": -1,
      "name": "Wood_Softwood_Planks"
    },
    {
      "x": -7,
      "y": 8,
      "z": -1,
      "name": "Wood_Deadwood_Roof_Flat",
      "rotation": 1
    },
    {
      "x": -7,
      "y": 0,
      "z": 0,
      "name": "Wood_Softwood_Planks"
    },
    {
      "x": -7,
      "y": 1,
      "z": 0,
      "name": "Empty"
    },
    {
      "x": -7,
      "y": 2,
      "z": 0,
      "name": "Empty"
    },
    {
      "x": -7,
      "y": 3,
      "z": 0,
      "name": "Empty"
    },
    {
      "x": -7,
      "y": 4,
      "z": 0,
      "name": "Empty"
    },
    {
      "x": -7,
      "y": 5,
      "z": 0,
      "name": "Empty"
    },
    {
      "x": -7,
      "y": 6,
      "z": 0,
      "name": "Wood_Softwood_Planks"
    },
    {
      "x": -7,
      "y": 7,
      "z": 0,
      "name": "Wood_Softwood_Planks"
    },
    {
      "x": -7,
      "y": 8,
      "z": 0,
      "name": "Wood_Deadwood_Roof_Flat",
      "rotation": 1
    },
    {
      "x": -7,
      "y": 0,
      "z": 1,
      "name": "Wood_Softwood_Planks"
    },
    {
      "x": -7,
      "y": 1,
      "z": 1,
      "name": "Empty"
    },
    {
      "x": -7,
      "y": 2,
      "z": 1,
      "name": "Empty"
    },
    {
      "x": -7,
      "y": 3,
      "z": 1,
      "name": "Empty"
    },
    {
      "x": -7,
      "y": 4,
      "z": 1,
      "name": "Empty"
    },
    {
      "x": -7,
      "y": 5,
      "z": 1,
      "name": "Empty"
    },
    {
      "x": -7,
      "y": 6,
      "z": 1,
      "name": "Wood_Softwood_Planks"
    },
    {
      "x": -7,
      "y": 7,
      "z": 1,
      "name": "Wood_Softwood_Planks"
    },
    {
      "x": -7,
      "y": 8,
      "z": 1,
      "name": "Wood_Deadwood_Roof_Flat",
      "rotation": 1
    },
    {
      "x": -7,
      "y": 0,
      "z": 2,
      "name": "Wood_Softwood_Planks"
    },
    {
      "x": -7,
      "y": 1,
      "z": 2,
      "name": "Empty"
    },
    {
      "x": -7,
      "y": 2,
      "z": 2,
      "name": "Empty"
    },
    {
      "x": -7,
      "y": 3,
      "z": 2,
      "name": "Empty"
    },
    {
      "x": -7,
      "y": 4,
      "z": 2,
      "name": "Empty"
    },
    {
      "x": -7,
      "y": 5,
      "z": 2,
      "name": "Empty"
    },
    {
      "x": -7,
      "y": 6,
      "z": 2,
      "name": "Wood_Softwood_Planks"
    },
    {
      "x": -7,
      "y": 7,
      "z": 2,
      "name": "Wood_Softwood_Planks"
    },
    {
      "x": -7,
      "y": 8,
      "z": 2,
      "name": "Wood_Deadwood_Roof_Flat",
      "rotation": 1
    },
    {
      "x": -7,
      "y": 0,
      "z": 3,
      "name": "Wood_Softwood_Planks"
    },
    {
      "x": -7,
      "y": 1,
      "z": 3,
      "name": "Empty"
    },
    {
      "x": -7,
      "y": 2,
      "z": 3,
      "name": "Empty"
    },
    {
      "x": -7,
      "y": 3,
      "z": 3,
      "name": "Empty"
    },
    {
      "x": -7,
      "y": 4,
      "z": 3,
      "name": "Empty"
    },
    {
      "x": -7,
      "y": 5,
      "z": 3,
      "name": "Empty"
    },
    {
      "x": -7,
      "y": 6,
      "z": 3,
      "name": "Wood_Softwood_Planks"
    },
    {
      "x": -7,
      "y": 7,
      "z": 3,
      "name": "Wood_Softwood_Planks"
    },
    {
      "x": -7,
      "y": 8,
      "z": 3,
      "name": "Wood_Deadwood_Roof_Flat",
      "rotation": 1
    },
    {
      "x": -7,
      "y": -4,
      "z": 4,
      "name": "Rock_Stone_Cobble"
    },
    {
      "x": -7,
      "y": -3,
      "z": 4,
      "name": "Rock_Stone_Cobble"
    },
    {
      "x": -7,
      "y": -2,
      "z": 4,
      "name": "Rock_Stone_Cobble"
    },
    {
      "x": -7,
      "y": -1,
      "z": 4,
      "name": "Rock_Stone_Cobble"
    },
    {
      "x": -7,
      "y": 0,
      "z": 4,
      "name": "Rock_Stone_Cobble"
    },
    {
      "x": -7,
      "y": 1,
      "z": 4,
      "name": "Rubble_Stone_Mossy_Medium"
    },
    {
      "x": -7,
      "y": 2,
      "z": 4,
      "name": "Empty"
    },
    {
      "x": -7,
      "y": 3,
      "z": 4,
      "name": "Empty"
    },
    {
      "x": -7,
      "y": 4,
      "z": 4,
      "name": "Empty"
    },
    {
      "x": -7,
      "y": 5,
      "z": 4,
      "name": "Empty"
    },
    {
      "x": -7,
      "y": 6,
      "z": 4,
      "name": "Wood_Softwood_Planks"
    },
    {
      "x": -7,
      "y": 7,
      "z": 4,
      "name": "Wood_Softwood_Planks"
    },
    {
      "x": -7,
      "y": 8,
      "z": 4,
      "name": "Wood_Deadwood_Roof_Flat",
      "rotation": 1
    },
    {
      "x": -7,
      "y": -4,
      "z": 5,
      "name": "Rock_Stone_Cobble"
    },
    {
      "x": -7,
      "y": -3,
      "z": 5,
      "name": "Rock_Stone_Cobble"
    },
    {
      "x": -7,
      "y": -2,
      "z": 5,
      "name": "Rock_Stone_Cobble"
    },
    {
      "x": -7,
      "y": -1,
      "z": 5,
      "name": "Rock_Stone_Cobble"
    },
    {
      "x": -7,
      "y": 0,
      "z": 5,
      "name": "Rock_Stone_Cobble"
    },
    {
      "x": -7,
      "y": 1,
      "z": 5,
      "name": "Empty"
    },
    {
      "x": -7,
      "y": 2,
      "z": 5,
      "name": "Rock_Stone_Cobble"
    },
    {
      "x": -7,
      "y": 3,
      "z": 5,
      "name": "Rock_Stone_Cobble"
    },
    {
      "x": -7,
      "y": 4,
      "z": 5,
      "name": "Rock_Stone_Cobble"
    },
    {
      "x": -7,
      "y": 5,
      "z": 5,
      "name": "Rock_Stone_Cobble"
    },
    {
      "x": -7,
      "y": 6,
      "z": 5,
      "name": "Rock_Stone_Cobble"
    },
    {
      "x": -7,
      "y": 7,
      "z": 5,
      "name": "Rock_Stone_Cobble"
    },
    {
      "x": -7,
      "y": 8,
      "z": 5,
      "name": "Rock_Stone_Cobble"
    },
    {
      "x": -7,
      "y": 9,
      "z": 5,
      "name": "Rock_Stone_Cobble"
    },
    {
      "x": -7,
      "y": 10,
      "z": 5,
      "name": "Rock_Stone_Cobble"
    },
    {
      "x": -7,
      "y": 11,
      "z": 5,
      "name": "Plant_Moss_Rug_Green"
    },
    {
      "x": -7,
      "y": -4,
      "z": 6,
      "name": "Rock_Stone_Cobble"
    },
    {
      "x": -7,
      "y": -3,
      "z": 6,
      "name": "Rock_Stone_Cobble"
    },
    {
      "x": -7,
      "y": -2,
      "z": 6,
      "name": "Rock_Stone_Cobble"
    },
    {
      "x": -7,
      "y": -1,
      "z": 6,
      "name": "Rock_Stone_Cobble"
    },
    {
      "x": -7,
      "y": 0,
      "z": 6,
      "name": "Rock_Stone_Cobble"
    },
    {
      "x": -7,
      "y": 1,
      "z": 6,
      "name": "Plant_Moss_Rug_Green"
    },
    {
      "x": -7,
      "y": 2,
      "z": 6,
      "name": "Rock_Stone_Cobble"
    },
    {
      "x": -7,
      "y": 3,
      "z": 6,
      "name": "Rock_Stone_Cobble"
    },
    {
      "x": -7,
      "y": 4,
      "z": 6,
      "name": "Rock_Stone_Cobble"
    },
    {
      "x": -7,
      "y": 5,
      "z": 6,
      "name": "Rock_Stone_Cobble"
    },
    {
      "x": -7,
      "y": 6,
      "z": 6,
      "name": "Rock_Stone_Cobble"
    },
    {
      "x": -7,
      "y": 7,
      "z": 6,
      "name": "Rock_Stone_Cobble"
    },
    {
      "x": -7,
      "y": 8,
      "z": 6,
      "name": "Rock_Stone_Cobble"
    },
    {
      "x": -7,
      "y": 9,
      "z": 6,
      "name": "Rock_Stone_Cobble"
    },
    {
      "x": -7,
      "y": 10,
      "z": 6,
      "name": "Rock_Stone_Cobble"
    },
    {
      "x": -7,
      "y": 11,
      "z": 6,
      "name": "Rock_Stone_Cobble"
    },
    {
      "x": -7,
      "y": 12,
      "z": 6,
      "name": "Rock_Stone_Cobble"
    },
    {
      "x": -7,
      "y": 13,
      "z": 6,
      "name": "Rock_Stone_Cobble"
    },
    {
      "x": -7,
      "y": 14,
      "z": 6,
      "name": "Plant_Moss_Rug_Green"
    },
    {
      "x": -7,
      "y": -3,
      "z": 7,
      "name": "Rock_Stone_Cobble"
    },
    {
      "x": -7,
      "y": -2,
      "z": 7,
      "name": "Rock_Stone_Cobble"
    },
    {
      "x": -7,
      "y": -1,
      "z": 7,
      "name": "Rock_Stone_Cobble"
    },
    {
      "x": -7,
      "y": 0,
      "z": 7,
      "name": "Rock_Stone_Cobble"
    },
    {
      "x": -7,
      "y": 1,
      "z": 7,
      "name": "Rock_Stone_Cobble"
    },
    {
      "x": -7,
      "y": 2,
      "z": 7,
      "name": "Rock_Stone_Cobble"
    },
    {
      "x": -7,
      "y": 3,
      "z": 7,
      "name": "Rock_Stone_Cobble"
    },
    {
      "x": -7,
      "y": 4,
      "z": 7,
      "name": "Rock_Stone_Cobble"
    },
    {
      "x": -7,
      "y": 5,
      "z": 7,
      "name": "Rock_Stone_Cobble"
    },
    {
      "x": -7,
      "y": 6,
      "z": 7,
      "name": "Rock_Stone_Cobble"
    },
    {
      "x": -7,
      "y": 7,
      "z": 7,
      "name": "Rock_Stone_Cobble"
    },
    {
      "x": -7,
      "y": 8,
      "z": 7,
      "name": "Rock_Stone_Cobble"
    },
    {
      "x": -7,
      "y": 9,
      "z": 7,
      "name": "Rock_Stone_Cobble"
    },
    {
      "x": -7,
      "y": 10,
      "z": 7,
      "name": "Rock_Stone_Cobble"
    },
    {
      "x": -6,
      "y": -3,
      "z": -6,
      "name": "Rock_Stone_Cobble"
    },
    {
      "x": -6,
      "y": -2,
      "z": -6,
      "name": "Rock_Stone_Cobble"
    },
    {
      "x": -6,
      "y": -1,
      "z": -6,
      "name": "Rock_Stone_Cobble"
    },
    {
      "x": -6,
      "y": 0,
      "z": -6,
      "name": "Rock_Stone_Cobble"
    },
    {
      "x": -6,
      "y": 8,
      "z": -6,
      "name": "Wood_Deadwood_Roof_Hollow",
      "rotation": 3
    },
    {
      "x": -6,
      "y": -4,
      "z": -5,
      "name": "Rock_Stone_Cobble"
    },
    {
      "x": -6,
      "y": -3,
      "z": -5,
      "name": "Rock_Stone_Cobble"
    },
    {
      "x": -6,
      "y": -2,
      "z": -5,
      "name": "Rock_Stone_Cobble"
    },
    {
      "x": -6,
      "y": -1,
      "z": -5,
      "name": "Rock_Stone_Cobble"
    },
    {
      "x": -6,
      "y": 0,
      "z": -5,
      "name": "Wood_Beech_Trunk",
      "rotation": 5
    },
    {
      "x": -6,
      "y": 1,
      "z": -5,
      "name": "Wood_Softwood_Planks"
    },
    {
      "x": -6,
      "y": 2,
      "z": -5,
      "name": "Wood_Softwood_Planks"
    },
    {
      "x": -6,
      "y": 3,
      "z": -5,
      "name": "Wood_Softwood_Planks"
    },
    {
      "x": -6,
      "y": 4,
      "z": -5,
      "name": "Wood_Softwood_Planks"
    },
    {
      "x": -6,
      "y": 5,
      "z": -5,
      "name": "Wood_Softwood_Planks"
    },
    {
      "x": -6,
      "y": 6,
      "z": -5,
      "name": "Wood_Softwood_Planks"
    },
    {
      "x": -6,
      "y": 7,
      "z": -5,
      "name": "Wood_Softwood_Planks"
    },
    {
      "x": -6,
      "y": 8,
      "z": -5,
      "name": "Wood_Deadwood_Roof",
      "rotation": 3
    },
    {
      "x": -6,
      "y": -4,
      "z": -4,
      "name": "Rock_Stone_Cobble"
    },
    {
      "x": -6,
      "y": -3,
      "z": -4,
      "name": "Rock_Stone_Cobble"
    },
    {
      "x": -6,
      "y": -2,
      "z": -4,
      "name": "Rock_Stone_Cobble"
    },
    {
      "x": -6,
      "y": 0,
      "z": -4,
      "name": "Wood_Softwood_Planks"
    },
    {
      "x": -6,
      "y": 1,
      "z": -4,
      "name": "Empty"
    },
    {
      "x": -6,
      "y": 2,
      "z": -4,
      "name": "Empty"
    },
    {
      "x": -6,
      "y": 3,
      "z": -4,
      "name": "Empty"
    },
    {
      "x": -6,
      "y": 4,
      "z": -4,
      "name": "Empty"
    },
    {
      "x": -6,
      "y": 5,
      "z": -4,
      "name": "Empty"
    },
    {
      "x": -6,
      "y": 6,
      "z": -4,
      "name": "Wood_Softwood_Planks"
    },
    {
      "x": -6,
      "y": 7,
      "z": -4,
      "name": "Wood_Softwood_Planks"
    },
    {
      "x": -6,
      "y": 8,
      "z": -4,
      "name": "Wood_Deadwood_Roof",
      "rotation": 3
    },
    {
      "x": -6,
      "y": -3,
      "z": -3,
      "name": "Rock_Stone_Cobble"
    },
    {
      "x": -6,
      "y": -2,
      "z": -3,
      "name": "Rock_Stone_Cobble"
    },
    {
      "x": -6,
      "y": -1,
      "z": -3,
      "name": "Rock_Stone_Cobble"
    },
    {
      "x": -6,
      "y": 0,
      "z": -3,
      "name": "Wood_Softwood_Planks"
    },
    {
      "x": -6,
      "y": 1,
      "z": -3,
      "name": "Empty"
    },
    {
      "x": -6,
      "y": 2,
      "z": -3,
      "name": "Empty"
    },
    {
      "x": -6,
      "y": 3,
      "z": -3,
      "name": "Empty"
    },
    {
      "x": -6,
      "y": 4,
      "z": -3,
      "name": "Empty"
    },
    {
      "x": -6,
      "y": 5,
      "z": -3,
      "name": "Empty"
    },
    {
      "x": -6,
      "y": 6,
      "z": -3,
      "name": "Wood_Softwood_Planks"
    },
    {
      "x": -6,
      "y": 7,
      "z": -3,
      "name": "Wood_Softwood_Planks"
    },
    {
      "x": -6,
      "y": 8,
      "z": -3,
      "name": "Wood_Deadwood_Roof",
      "rotation": 3
    },
    {
      "x": -6,
      "y": 0,
      "z": -2,
      "name": "Wood_Softwood_Planks"
    },
    {
      "x": -6,
      "y": 1,
      "z": -2,
      "name": "Rail",
      "rotation": 1
    },
    {
      "x": -6,
      "y": 2,
      "z": -2,
      "name": "Empty"
    },
    {
      "x": -6,
      "y": 3,
      "z": -2,
      "name": "Empty"
    },
    {
      "x": -6,
      "y": 4,
      "z": -2,
      "name": "Empty"
    },
    {
      "x": -6,
      "y": 5,
      "z": -2,
      "name": "Empty"
    },
    {
      "x": -6,
      "y": 6,
      "z": -2,
      "name": "Wood_Softwood_Planks"
    },
    {
      "x": -6,
      "y": 7,
      "z": -2,
      "name": "Wood_Softwood_Planks"
    },
    {
      "x": -6,
      "y": 8,
      "z": -2,
      "name": "Wood_Deadwood_Roof",
      "rotation": 3
    },
    {
      "x": -6,
      "y": 0,
      "z": -1,
      "name": "Wood_Softwood_Planks"
    },
    {
      "x": -6,
      "y": 1,
      "z": -1,
      "name": "Empty"
    },
    {
      "x": -6,
      "y": 2,
      "z": -1,
      "name": "Empty"
    },
    {
      "x": -6,
      "y": 3,
      "z": -1,
      "name": "Empty"
    },
    {
      "x": -6,
      "y": 4,
      "z": -1,
      "name": "Empty"
    },
    {
      "x": -6,
      "y": 5,
      "z": -1,
      "name": "Empty"
    },
    {
      "x": -6,
      "y": 6,
      "z": -1,
      "name": "Wood_Softwood_Planks"
    },
    {
      "x": -6,
      "y": 7,
      "z": -1,
      "name": "Wood_Softwood_Planks"
    },
    {
      "x": -6,
      "y": 8,
      "z": -1,
      "name": "Wood_Deadwood_Roof",
      "rotation": 3
    },
    {
      "x": -6,
      "y": 0,
      "z": 0,
      "name": "Wood_Softwood_Planks"
    },
    {
      "x": -6,
      "y": 1,
      "z": 0,
      "name": "Empty"
    },
    {
      "x": -6,
      "y": 2,
      "z": 0,
      "name": "Empty"
    },
    {
      "x": -6,
      "y": 3,
      "z": 0,
      "name": "Empty"
    },
    {
      "x": -6,
      "y": 4,
      "z": 0,
      "name": "Empty"
    },
    {
      "x": -6,
      "y": 5,
      "z": 0,
      "name": "Empty"
    },
    {
      "x": -6,
      "y": 6,
      "z": 0,
      "name": "Wood_Softwood_Planks"
    },
    {
      "x": -6,
      "y": 7,
      "z": 0,
      "name": "Wood_Softwood_Planks"
    },
    {
      "x": -6,
      "y": 8,
      "z": 0,
      "name": "Wood_Deadwood_Roof",
      "rotation": 3
    },
    {
      "x": -6,
      "y": 0,
      "z": 1,
      "name": "Wood_Softwood_Planks"
    },
    {
      "x": -6,
      "y": 1,
      "z": 1,
      "name": "Empty"
    },
    {
      "x": -6,
      "y": 2,
      "z": 1,
      "name": "Empty"
    },
    {
      "x": -6,
      "y": 3,
      "z": 1,
      "name": "Empty"
    },
    {
      "x": -6,
      "y": 4,
      "z": 1,
      "name": "Empty"
    },
    {
      "x": -6,
      "y": 5,
      "z": 1,
      "name": "Empty"
    },
    {
      "x": -6,
      "y": 6,
      "z": 1,
      "name": "Wood_Softwood_Planks"
    },
    {
      "x": -6,
      "y": 7,
      "z": 1,
      "name": "Wood_Softwood_Planks"
    },
    {
      "x": -6,
      "y": 8,
      "z": 1,
      "name": "Wood_Deadwood_Roof",
      "rotation": 3
    },
    {
      "x": -6,
      "y": 0,
      "z": 2,
      "name": "Wood_Softwood_Planks"
    },
    {
      "x": -6,
      "y": 1,
      "z": 2,
      "name": "Empty"
    },
    {
      "x": -6,
      "y": 2,
      "z": 2,
      "name": "Empty"
    },
    {
      "x": -6,
      "y": 3,
      "z": 2,
      "name": "Empty"
    },
    {
      "x": -6,
      "y": 4,
      "z": 2,
      "name": "Wood_Torch_Wall",
      "rotation": 3
    },
    {
      "x": -6,
      "y": 5,
      "z": 2,
      "name": "Empty"
    },
    {
      "x": -6,
      "y": 6,
      "z": 2,
      "name": "Wood_Softwood_Planks"
    },
    {
      "x": -6,
      "y": 7,
      "z": 2,
      "name": "Wood_Softwood_Planks"
    },
    {
      "x": -6,
      "y": 8,
      "z": 2,
      "name": "Wood_Deadwood_Roof",
      "rotation": 3
    },
    {
      "x": -6,
      "y": 0,
      "z": 3,
      "name": "Wood_Softwood_Planks"
    },
    {
      "x": -6,
      "y": 1,
      "z": 3,
      "name": "Empty"
    },
    {
      "x": -6,
      "y": 2,
      "z": 3,
      "name": "Empty"
    },
    {
      "x": -6,
      "y": 3,
      "z": 3,
      "name": "Empty"
    },
    {
      "x": -6,
      "y": 4,
      "z": 3,
      "name": "Empty"
    },
    {
      "x": -6,
      "y": 5,
      "z": 3,
      "name": "Empty"
    },
    {
      "x": -6,
      "y": 6,
      "z": 3,
      "name": "Wood_Softwood_Planks"
    },
    {
      "x": -6,
      "y": 7,
      "z": 3,
      "name": "Wood_Softwood_Planks"
    },
    {
      "x": -6,
      "y": 8,
      "z": 3,
      "name": "Wood_Deadwood_Roof",
      "rotation": 3
    },
    {
      "x": -6,
      "y": -2,
      "z": 4,
      "name": "Rock_Stone_Cobble"
    },
    {
      "x": -6,
      "y": -1,
      "z": 4,
      "name": "Rock_Stone_Cobble"
    },
    {
      "x": -6,
      "y": 0,
      "z": 4,
      "name": "Rock_Stone_Cobble"
    },
    {
      "x": -6,
      "y": 1,
      "z": 4,
      "name": "Rock_Stone_Cobble"
    },
    {
      "x": -6,
      "y": 2,
      "z": 4,
      "name": "Rock_Stone_Cobble"
    },
    {
      "x": -6,
      "y": 3,
      "z": 4,
      "name": "Empty"
    },
    {
      "x": -6,
      "y": 4,
      "z": 4,
