{
  "version": 8,
  "blockIdVersion": 8,
  "anchorX": 0,
  "anchorY": 0,
  "anchorZ": 0,
  "blocks": [
    {
      "x": -8,
      "y": -6,
      "z": -14,
      "name": "Rock_Stone"
    },
    {
      "x": -8,
      "y": -7,
      "z": -13,
      "name": "Rock_Stone"
    },
    {
      "x": -8,
      "y": -6,
      "z": -13,
      "name": "Rock_Stone"
    },
    {
      "x": -8,
      "y": -5,
      "z": -13,
      "name": "Rock_Stone"
    },
    {
      "x": -8,
      "y": -6,
      "z": -12,
      "name": "Rock_Stone"
    },
    {
      "x": -8,
      "y": -5,
      "z": -12,
      "name": "Rock_Stone"
    },
    {
      "x": -8,
      "y": -1,
      "z": -12,
      "name": "Empty"
    },
    {
      "x": -8,
      "y": -6,
      "z": -11,
      "name": "Rock_Stone"
    },
    {
      "x": -8,
      "y": -5,
      "z": -11,
      "name": "Rock_Stone"
    },
    {
      "x": -8,
      "y": -4,
      "z": -11,
      "name": "Rock_Stone"
    },
    {
      "x": -8,
      "y": -5,
      "z": -10,
      "name": "Rock_Stone"
    },
    {
      "x": -8,
      "y": -4,
      "z": -10,
      "name": "Rock_Stone"
    },
    {
      "x": -8,
      "y": -5,
      "z": -9,
      "name": "Rock_Stone"
    },
    {
      "x": -8,
      "y": -4,
      "z": -9,
      "name": "Rock_Stone"
    },
    {
      "x": -8,
      "y": -3,
      "z": -9,
      "name": "Rock_Stone"
    },
    {
      "x": -8,
      "y": -4,
      "z": -8,
      "name": "Rock_Stone"
    },
    {
      "x": -7,
      "y": -7,
      "z": -15,
      "name": "Rock_Stone"
    },
    {
      "x": -7,
      "y": -6,
      "z": -15,
      "name": "Rock_Stone"
    },
    {
      "x": -7,
      "y": -5,
      "z": -15,
      "name": "Rock_Stone"
    },
    {
      "x": -7,
      "y": -7,
      "z": -14,
      "name": "Rock_Stone"
    },
    {
      "x": -7,
      "y": -6,
      "z": -14,
      "name": "Rock_Stone"
    },
    {
      "x": -7,
      "y": -5,
      "z": -14,
      "name": "Rock_Quartzite_Brick"
    },
    {
      "x": -7,
      "y": -4,
      "z": -14,
      "name": "Rock_Quartzite_Brick"
    },
    {
      "x": -7,
      "y": -3,
      "z": -14,
      "name": "Rock_Quartzite_Cobble"
    },
    {
      "x": -7,
      "y": -2,
      "z": -14,
      "name": "Empty"
    },
    {
      "x": -7,
      "y": -1,
      "z": -14,
      "name": "Empty"
    },
    {
      "x": -7,
      "y": -7,
      "z": -13,
      "name": "Rock_Stone"
    },
    {
      "x": -7,
      "y": -6,
      "z": -13,
      "name": "Rock_Stone"
    },
    {
      "x": -7,
      "y": -5,
      "z": -13,
      "name": "Rock_Quartzite_Brick"
    },
    {
      "x": -7,
      "y": -4,
      "z": -13,
      "name": "Rock_Quartzite_Brick"
    },
    {
      "x": -7,
      "y": -3,
      "z": -13,
      "name": "Rock_Quartzite_Cobble"
    },
    {
      "x": -7,
      "y": -2,
      "z": -13,
      "name": "Empty"
    },
    {
      "x": -7,
      "y": -1,
      "z": -13,
      "name": "Empty"
    },
    {
      "x": -7,
      "y": -7,
      "z": -12,
      "name": "Rock_Stone"
    },
    {
      "x": -7,
      "y": -6,
      "z": -12,
      "name": "Rock_Stone"
    },
    {
      "x": -7,
      "y": -5,
      "z": -12,
      "name": "Rock_Stone"
    },
    {
      "x": -7,
      "y": -4,
      "z": -12,
      "name": "Rock_Quartzite_Cobble"
    },
    {
      "x": -7,
      "y": -3,
      "z": -12,
      "name": "Rock_Quartzite_Cobble"
    },
    {
      "x": -7,
      "y": -2,
      "z": -12,
      "name": "Rock_Quartzite_Cobble"
    },
    {
      "x": -7,
      "y": -1,
      "z": -12,
      "name": "Empty"
    },
    {
      "x": -7,
      "y": -7,
      "z": -11,
      "name": "Rock_Stone"
    },
    {
      "x": -7,
      "y": -6,
      "z": -11,
      "name": "Rock_Stone"
    },
    {
      "x": -7,
      "y": -5,
      "z": -11,
      "name": "Rock_Stone"
    },
    {
      "x": -7,
      "y": -4,
      "z": -11,
      "name": "Rock_Quartzite_Cobble"
    },
    {
      "x": -7,
      "y": -3,
      "z": -11,
      "name": "Rock_Quartzite_Brick"
    },
    {
      "x": -7,
      "y": -2,
      "z": -11,
      "name": "Rock_Quartzite_Cobble"
    },
    {
      "x": -7,
      "y": -6,
      "z": -10,
      "name": "Rock_Stone"
    },
    {
      "x": -7,
      "y": -5,
      "z": -10,
      "name": "Rock_Stone"
    },
    {
      "x": -7,
      "y": -4,
      "z": -10,
      "name": "Rock_Stone"
    },
    {
      "x": -7,
      "y": -3,
      "z": -10,
      "name": "Rock_Quartzite_Brick"
    },
    {
      "x": -7,
      "y": -2,
      "z": -10,
      "name": "Rock_Quartzite_Brick"
    },
    {
      "x": -7,
      "y": -5,
      "z": -9,
      "name": "Rock_Stone"
    },
    {
      "x": -7,
      "y": -4,
      "z": -9,
      "name": "Rock_Stone"
    },
    {
      "x": -7,
      "y": -3,
      "z": -9,
      "name": "Rock_Stone"
    },
    {
      "x": -7,
      "y": -5,
      "z": -8,
      "name": "Rock_Stone"
    },
    {
      "x": -7,
      "y": -4,
      "z": -8,
      "name": "Rock_Stone"
    },
    {
      "x": -7,
      "y": -3,
      "z": -8,
      "name": "Rock_Stone"
    },
    {
      "x": -7,
      "y": -5,
      "z": -7,
      "name": "Rock_Stone"
    },
    {
      "x": -7,
      "y": -4,
      "z": -7,
      "name": "Rock_Stone"
    },
    {
      "x": -7,
      "y": -3,
      "z": -7,
      "name": "Rock_Stone"
    },
    {
      "x": -6,
      "y": -7,
      "z": -16,
      "name": "Rock_Stone"
    },
    {
      "x": -6,
      "y": -6,
      "z": -16,
      "name": "Rock_Stone"
    },
    {
      "x": -6,
      "y": -5,
      "z": -16,
      "name": "Rock_Quartzite_Brick"
    },
    {
      "x": -6,
      "y": -4,
      "z": -16,
      "name": "Rock_Quartzite_Brick"
    },
    {
      "x": -6,
      "y": -3,
      "z": -16,
      "name": "Empty"
    },
    {
      "x": -6,
      "y": -2,
      "z": -16,
      "name": "Empty"
    },
    {
      "x": -6,
      "y": -8,
      "z": -15,
      "name": "Rock_Stone"
    },
    {
      "x": -6,
      "y": -7,
      "z": -15,
      "name": "Rock_Stone"
    },
    {
      "x": -6,
      "y": -6,
      "z": -15,
      "name": "Rock_Stone"
    },
    {
      "x": -6,
      "y": -5,
      "z": -15,
      "name": "Rock_Quartzite_Brick"
    },
    {
      "x": -6,
      "y": -4,
      "z": -15,
      "name": "Rock_Quartzite_Cobble"
    },
    {
      "x": -6,
      "y": -3,
      "z": -15,
      "name": "Empty"
    },
    {
      "x": -6,
      "y": -2,
      "z": -15,
      "name": "Empty"
    },
    {
      "x": -6,
      "y": -8,
      "z": -14,
      "name": "Rock_Stone"
    },
    {
      "x": -6,
      "y": -7,
      "z": -14,
      "name": "Rock_Stone"
    },
    {
      "x": -6,
      "y": -6,
      "z": -14,
      "name": "Soil_Gravel"
    },
    {
      "x": -6,
      "y": -5,
      "z": -14,
      "name": "Empty"
    },
    {
      "x": -6,
      "y": -4,
      "z": -14,
      "name": "Empty"
    },
    {
      "x": -6,
      "y": -3,
      "z": -14,
      "name": "Empty"
    },
    {
      "x": -6,
      "y": -2,
      "z": -14,
      "name": "Empty"
    },
    {
      "x": -6,
      "y": -1,
      "z": -14,
      "name": "Empty"
    },
    {
      "x": -6,
      "y": 0,
      "z": -14,
      "name": "Empty"
    },
    {
      "x": -6,
      "y": -8,
      "z": -13,
      "name": "Rock_Stone"
    },
    {
      "x": -6,
      "y": -7,
      "z": -13,
      "name": "Rock_Stone"
    },
    {
      "x": -6,
      "y": -6,
      "z": -13,
      "name": "Soil_Gravel"
    },
    {
      "x": -6,
      "y": -5,
      "z": -13,
      "name": "Empty"
    },
    {
      "x": -6,
      "y": -4,
      "z": -13,
      "name": "Empty"
    },
    {
      "x": -6,
      "y": -3,
      "z": -13,
      "name": "Empty"
    },
    {
      "x": -6,
      "y": -2,
      "z": -13,
      "name": "Empty"
    },
    {
      "x": -6,
      "y": -1,
      "z": -13,
      "name": "Empty"
    },
    {
      "x": -6,
      "y": 0,
      "z": -13,
      "name": "Empty"
    },
    {
      "x": -6,
      "y": -8,
      "z": -12,
      "name": "Rock_Stone"
    },
    {
      "x": -6,
      "y": -7,
      "z": -12,
      "name": "Rock_Stone"
    },
    {
      "x": -6,
      "y": -6,
      "z": -12,
      "name": "Rock_Stone"
    },
    {
      "x": -6,
      "y": -5,
      "z": -12,
      "name": "Rock_Stone"
    },
    {
      "x": -6,
      "y": -4,
      "z": -12,
      "name": "Empty"
    },
    {
      "x": -6,
      "y": -3,
      "z": -12,
      "name": "Empty"
    },
    {
      "x": -6,
      "y": -2,
      "z": -12,
      "name": "Rock_Stone_Stalactite_Large",
      "filler": 31744,
      "rotation": 8
    },
    {
      "x": -6,
      "y": -1,
      "z": -12,
      "name": "Rock_Stone_Stalactite_Large",
      "rotation": 8
    },
    {
      "x": -6,
      "y": -7,
      "z": -11,
      "name": "Rock_Stone"
    },
    {
      "x": -6,
      "y": -6,
      "z": -11,
      "name": "Rock_Stone"
    },
    {
      "x": -6,
      "y": -5,
      "z": -11,
      "name": "Rock_Stone"
    },
    {
      "x": -6,
      "y": -4,
      "z": -11,
      "name": "Empty"
    },
    {
      "x": -6,
      "y": -3,
      "z": -11,
      "name": "Empty"
    },
    {
      "x": -6,
      "y": -2,
      "z": -11,
      "name": "Empty"
    },
    {
      "x": -6,
      "y": -1,
      "z": -11,
      "name": "Rock_Stone_Stalactite_Small",
      "rotation": 8
    },
    {
      "x": -6,
      "y": -6,
      "z": -10,
      "name": "Rock_Stone"
    },
    {
      "x": -6,
      "y": -5,
      "z": -10,
      "name": "Rock_Stone"
    },
    {
      "x": -6,
      "y": -4,
      "z": -10,
      "name": "Rock_Stone_Cobble"
    },
    {
      "x": -6,
      "y": -3,
      "z": -10,
      "name": "Empty"
    },
    {
      "x": -6,
      "y": -2,
      "z": -10,
      "name": "Empty"
    },
    {
      "x": -6,
      "y": -1,
      "z": -10,
      "name": "Empty"
    },
    {
      "x": -6,
      "y": -6,
      "z": -9,
      "name": "Rock_Stone"
    },
    {
      "x": -6,
      "y": -5,
      "z": -9,
      "name": "Rock_Stone"
    },
    {
      "x": -6,
      "y": -4,
      "z": -9,
      "name": "Rock_Stone"
    },
    {
      "x": -6,
      "y": -3,
      "z": -9,
      "name": "Empty"
    },
    {
      "x": -6,
      "y": -2,
      "z": -9,
      "name": "Empty"
    },
    {
      "x": -6,
      "y": -1,
      "z": -9,
      "name": "Empty"
    },
    {
      "x": -6,
      "y": -6,
      "z": -8,
      "name": "Rock_Stone"
    },
    {
      "x": -6,
      "y": -5,
      "z": -8,
      "name": "Rock_Stone"
    },
    {
      "x": -6,
      "y": -4,
      "z": -8,
      "name": "Rock_Stone"
    },
    {
      "x": -6,
      "y": -3,
      "z": -8,
      "name": "Rock_Stone"
    },
    {
      "x": -6,
      "y": -2,
      "z": -8,
      "name": "Empty"
    },
    {
      "x": -6,
      "y": -1,
      "z": -8,
      "name": "Empty"
    },
    {
      "x": -6,
      "y": -5,
      "z": -7,
      "name": "Rock_Stone"
    },
    {
      "x": -6,
      "y": -4,
      "z": -7,
      "name": "Rock_Stone"
    },
    {
      "x": -6,
      "y": -3,
      "z": -7,
      "name": "Rock_Stone"
    },
    {
      "x": -6,
      "y": -4,
      "z": -6,
      "name": "Rock_Stone"
    },
    {
      "x": -5,
      "y": -8,
      "z": -17,
      "name": "Rock_Stone"
    },
    {
      "x": -5,
      "y": -7,
      "z": -17,
      "name": "Rock_Stone"
    },
    {
      "x": -5,
      "y": -6,
      "z": -17,
      "name": "Rock_Stone"
    },
    {
      "x": -5,
      "y": -5,
      "z": -17,
      "name": "Rock_Quartzite_Brick"
    },
    {
      "x": -5,
      "y": -4,
      "z": -17,
      "name": "Rock_Quartzite_Brick"
    },
    {
      "x": -5,
      "y": -8,
      "z": -16,
      "name": "Rock_Stone"
    },
    {
      "x": -5,
      "y": -7,
      "z": -16,
      "name": "Rock_Stone"
    },
    {
      "x": -5,
      "y": -6,
      "z": -16,
      "name": "Rock_Stone"
    },
    {
      "x": -5,
      "y": -5,
      "z": -16,
      "name": "Empty"
    },
    {
      "x": -5,
      "y": -4,
      "z": -16,
      "name": "Empty"
    },
    {
      "x": -5,
      "y": -3,
      "z": -16,
      "name": "Empty"
    },
    {
      "x": -5,
      "y": -2,
      "z": -16,
      "name": "Empty"
    },
    {
      "x": -5,
      "y": -1,
      "z": -16,
      "name": "Empty"
    },
    {
      "x": -5,
      "y": -8,
      "z": -15,
      "name": "Rock_Stone"
    },
    {
      "x": -5,
      "y": -7,
      "z": -15,
      "name": "Rock_Stone"
    },
    {
      "x": -5,
      "y": -6,
      "z": -15,
      "name": "Empty"
    },
    {
      "x": -5,
      "y": -5,
      "z": -15,
      "name": "Empty"
    },
    {
      "x": -5,
      "y": -4,
      "z": -15,
      "name": "Empty"
    },
    {
      "x": -5,
      "y": -3,
      "z": -15,
      "name": "Empty"
    },
    {
      "x": -5,
      "y": -2,
      "z": -15,
      "name": "Empty"
    },
    {
      "x": -5,
      "y": -1,
      "z": -15,
      "name": "Empty"
    },
    {
      "x": -5,
      "y": 0,
      "z": -15,
      "name": "Empty"
    },
    {
      "x": -5,
      "y": -8,
      "z": -14,
      "name": "Rock_Stone"
    },
    {
      "x": -5,
      "y": -7,
      "z": -14,
      "name": "Rock_Stone"
    },
    {
      "x": -5,
      "y": -6,
      "z": -14,
      "name": "Soil_Gravel"
    },
    {
      "x": -5,
      "y": -5,
      "z": -14,
      "name": "Empty"
    },
    {
      "x": -5,
      "y": -4,
      "z": -14,
      "name": "Empty"
    },
    {
      "x": -5,
      "y": -3,
      "z": -14,
      "name": "Empty"
    },
    {
      "x": -5,
      "y": -2,
      "z": -14,
      "name": "Empty"
    },
    {
      "x": -5,
      "y": -1,
      "z": -14,
      "name": "Empty"
    },
    {
      "x": -5,
      "y": 0,
      "z": -14,
      "name": "Empty"
    },
    {
      "x": -5,
      "y": -8,
      "z": -13,
      "name": "Rock_Stone"
    },
    {
      "x": -5,
      "y": -7,
      "z": -13,
      "name": "Rock_Stone"
    },
    {
      "x": -5,
      "y": -6,
      "z": -13,
      "name": "Rock_Stone"
    },
    {
      "x": -5,
      "y": -5,
      "z": -13,
      "name": "Empty"
    },
    {
      "x": -5,
      "y": -4,
      "z": -13,
      "name": "Empty"
    },
    {
      "x": -5,
      "y": -3,
      "z": -13,
      "name": "Empty"
    },
    {
      "x": -5,
      "y": -2,
      "z": -13,
      "name": "Empty"
    },
    {
      "x": -5,
      "y": -1,
      "z": -13,
      "name": "Empty"
    },
    {
      "x": -5,
      "y": 0,
      "z": -13,
      "name": "Empty"
    },
    {
      "x": -5,
      "y": -8,
      "z": -12,
      "name": "Rock_Stone"
    },
    {
      "x": -5,
      "y": -7,
      "z": -12,
      "name": "Rock_Stone"
    },
    {
      "x": -5,
      "y": -6,
      "z": -12,
      "name": "Rock_Stone"
    },
    {
      "x": -5,
      "y": -5,
      "z": -12,
      "name": "Rock_Stone"
    },
    {
      "x": -5,
      "y": -4,
      "z": -12,
      "name": "Empty"
    },
    {
      "x": -5,
      "y": -3,
      "z": -12,
      "name": "Empty"
    },
    {
      "x": -5,
      "y": -2,
      "z": -12,
      "name": "Empty"
    },
    {
      "x": -5,
      "y": -1,
      "z": -12,
      "name": "Empty"
    },
    {
      "x": -5,
      "y": -7,
      "z": -11,
      "name": "Rock_Stone"
    },
    {
      "x": -5,
      "y": -6,
      "z": -11,
      "name": "Rock_Stone"
    },
    {
      "x": -5,
      "y": -5,
      "z": -11,
      "name": "Rock_Stone"
    },
    {
      "x": -5,
      "y": -4,
      "z": -11,
      "name": "Rock_Stone_Cobble"
    },
    {
      "x": -5,
      "y": -3,
      "z": -11,
      "name": "Empty"
    },
    {
      "x": -5,
      "y": -2,
      "z": -11,
      "name": "Empty"
    },
    {
      "x": -5,
      "y": -1,
      "z": -11,
      "name": "Empty"
    },
    {
      "x": -5,
      "y": -7,
      "z": -10,
      "name": "Rock_Stone"
    },
    {
      "x": -5,
      "y": -6,
      "z": -10,
      "name": "Rock_Stone"
    },
    {
      "x": -5,
      "y": -5,
      "z": -10,
      "name": "Rock_Stone"
    },
    {
      "x": -5,
      "y": -4,
      "z": -10,
      "name": "Rock_Stone_Cobble"
    },
    {
      "x": -5,
      "y": -3,
      "z": -10,
      "name": "Empty"
    },
    {
      "x": -5,
      "y": -2,
      "z": -10,
      "name": "Empty"
    },
    {
      "x": -5,
      "y": -1,
      "z": -10,
      "name": "Empty"
    },
    {
      "x": -5,
      "y": 0,
      "z": -10,
      "name": "Empty"
    },
    {
      "x": -5,
      "y": -6,
      "z": -9,
      "name": "Rock_Stone"
    },
    {
      "x": -5,
      "y": -5,
      "z": -9,
      "name": "Rock_Stone"
    },
    {
      "x": -5,
      "y": -4,
      "z": -9,
      "name": "Rock_Stone_Cobble"
    },
    {
      "x": -5,
      "y": -3,
      "z": -9,
      "name": "Empty"
    },
    {
      "x": -5,
      "y": -2,
      "z": -9,
      "name": "Empty"
    },
    {
      "x": -5,
      "y": -1,
      "z": -9,
      "name": "Empty"
    },
    {
      "x": -5,
      "y": 0,
      "z": -9,
      "name": "Empty"
    },
    {
      "x": -5,
      "y": -6,
      "z": -8,
      "name": "Rock_Stone"
    },
    {
      "x": -5,
      "y": -5,
      "z": -8,
      "name": "Rock_Stone"
    },
    {
      "x": -5,
      "y": -4,
      "z": -8,
      "name": "Rock_Stone"
    },
    {
      "x": -5,
      "y": -3,
      "z": -8,
      "name": "Empty"
    },
    {
      "x": -5,
      "y": -2,
      "z": -8,
      "name": "Empty"
    },
    {
      "x": -5,
      "y": -1,
      "z": -8,
      "name": "Empty"
    },
    {
      "x": -5,
      "y": 0,
      "z": -8,
      "name": "Empty"
    },
    {
      "x": -5,
      "y": 1,
      "z": -8,
      "name": "Empty"
    },
    {
      "x": -5,
      "y": -6,
      "z": -7,
      "name": "Rock_Stone"
    },
    {
      "x": -5,
      "y": -5,
      "z": -7,
      "name": "Rock_Stone"
    },
    {
      "x": -5,
      "y": -4,
      "z": -7,
      "name": "Rock_Stone"
    },
    {
      "x": -5,
      "y": -3,
      "z": -7,
      "name": "Rock_Stone"
    },
    {
      "x": -5,
      "y": -2,
      "z": -7,
      "name": "Empty"
    },
    {
      "x": -5,
      "y": -1,
      "z": -7,
      "name": "Empty"
    },
    {
      "x": -5,
      "y": 0,
      "z": -7,
      "name": "Empty"
    },
    {
      "x": -5,
      "y": -5,
      "z": -6,
      "name": "Rock_Stone"
    },
    {
      "x": -5,
      "y": -4,
      "z": -6,
      "name": "Rock_Stone"
    },
    {
      "x": -5,
      "y": -3,
      "z": -6,
      "name": "Rock_Stone"
    },
    {
      "x": -4,
      "y": -7,
      "z": -18,
      "name": "Rock_Stone"
    },
    {
      "x": -4,
      "y": -8,
      "z": -17,
      "name": "Rock_Stone"
    },
    {
      "x": -4,
      "y": -7,
      "z": -17,
      "name": "Rock_Stone"
    },
    {
      "x": -4,
      "y": -6,
      "z": -17,
      "name": "Rock_Quartzite_Brick"
    },
    {
      "x": -4,
      "y": -5,
      "z": -17,
      "name": "Rock_Quartzite_Cobble"
    },
    {
      "x": -4,
      "y": -4,
      "z": -17,
      "name": "Empty"
    },
    {
      "x": -4,
      "y": -3,
      "z": -17,
      "name": "Empty"
    },
    {
      "x": -4,
      "y": -9,
      "z": -16,
      "name": "Rock_Stone"
    },
    {
      "x": -4,
      "y": -8,
      "z": -16,
      "name": "Rock_Stone"
    },
    {
      "x": -4,
      "y": -7,
      "z": -16,
      "name": "Soil_Gravel"
    },
    {
      "x": -4,
      "y": -6,
      "z": -16,
      "name": "Empty"
    },
    {
      "x": -4,
      "y": -5,
      "z": -16,
      "name": "Empty"
    },
    {
      "x": -4,
      "y": -4,
      "z": -16,
      "name": "Empty"
    },
    {
      "x": -4,
      "y": -3,
      "z": -16,
      "name": "Empty"
    },
    {
      "x": -4,
      "y": -2,
      "z": -16,
      "name": "Empty"
    },
    {
      "x": -4,
      "y": -9,
      "z": -15,
      "name": "Rock_Stone"
    },
    {
      "x": -4,
      "y": -8,
      "z": -15,
      "name": "Rock_Stone"
    },
    {
      "x": -4,
      "y": -7,
      "z": -15,
      "name": "Rock_Stone"
    },
    {
      "x": -4,
      "y": -6,
      "z": -15,
      "name": "Empty"
    },
    {
      "x": -4,
      "y": -5,
      "z": -15,
      "name": "Empty"
    },
    {
      "x": -4,
      "y": -4,
      "z": -15,
      "name": "Empty"
    },
    {
      "x": -4,
      "y": -3,
      "z": -15,
      "name": "Empty"
    },
    {
      "x": -4,
      "y": -2,
      "z": -15,
      "name": "Empty"
    },
    {
      "x": -4,
      "y": -1,
      "z": -15,
      "name": "Empty"
    },
    {
      "x": -4,
      "y": 0,
      "z": -15,
      "name": "Empty"
    },
    {
      "x": -4,
      "y": -9,
      "z": -14,
      "name": "Rock_Stone"
    },
    {
      "x": -4,
      "y": -8,
      "z": -14,
      "name": "Rock_Stone"
    },
    {
      "x": -4,
      "y": -7,
      "z": -14,
      "name": "Rock_Stone"
    },
    {
      "x": -4,
      "y": -6,
      "z": -14,
      "name": "Empty"
    },
    {
      "x": -4,
      "y": -5,
      "z": -14,
      "name": "Empty"
    },
    {
      "x": -4,
      "y": -4,
      "z": -14,
      "name": "Empty"
    },
    {
      "x": -4,
      "y": -3,
      "z": -14,
      "name": "Empty"
    },
    {
      "x": -4,
      "y": -2,
      "z": -14,
      "name": "Empty"
    },
    {
      "x": -4,
      "y": -1,
      "z": -14,
      "name": "Empty"
    },
    {
      "x": -4,
      "y": 0,
      "z": -14,
      "name": "Empty"
    },
    {
      "x": -4,
      "y": -8,
      "z": -13,
      "name": "Rock_Stone"
    },
    {
      "x": -4,
      "y": -7,
      "z": -13,
      "name": "Rock_Stone"
    },
    {
      "x": -4,
      "y": -6,
      "z": -13,
      "name": "Empty"
    },
    {
      "x": -4,
      "y": -5,
      "z": -13,
      "name": "Empty"
    },
    {
      "x": -4,
      "y": -4,
      "z": -13,
      "name": "Empty"
    },
    {
      "x": -4,
      "y": -3,
      "z": -13,
      "name": "Empty"
    },
    {
      "x": -4,
      "y": -2,
      "z": -13,
      "name": "Empty"
    },
    {
      "x": -4,
      "y": -1,
      "z": -13,
      "name": "Empty"
    },
    {
      "x": -4,
      "y": 0,
      "z": -13,
      "name": "Empty"
    },
    {
      "x": -4,
      "y": -8,
      "z": -12,
      "name": "Rock_Stone"
    },
    {
      "x": -4,
      "y": -7,
      "z": -12,
      "name": "Rock_Stone"
    },
    {
      "x": -4,
      "y": -6,
      "z": -12,
      "name": "Rock_Stone"
    },
    {
      "x": -4,
      "y": -5,
      "z": -12,
      "name": "Rock_Stone"
    },
    {
      "x": -4,
      "y": -4,
      "z": -12,
      "name": "Empty"
    },
    {
      "x": -4,
      "y": -3,
      "z": -12,
      "name": "Empty"
    },
    {
      "x": -4,
      "y": -2,
      "z": -12,
      "name": "Empty"
    },
    {
      "x": -4,
      "y": -1,
      "z": -12,
      "name": "Empty"
    },
    {
      "x": -4,
      "y": 0,
      "z": -12,
      "name": "Empty"
    },
    {
      "x": -4,
      "y": -8,
      "z": -11,
      "name": "Rock_Stone"
    },
    {
      "x": -4,
      "y": -7,
      "z": -11,
      "name": "Rock_Stone"
    },
    {
      "x": -4,
      "y": -6,
      "z": -11,
      "name": "Rock_Stone"
    },
    {
      "x": -4,
      "y": -5,
      "z": -11,
      "name": "Rock_Stone"
    },
    {
      "x": -4,
      "y": -4,
      "z": -11,
      "name": "Rock_Stone_Cobble"
    },
    {
      "x": -4,
      "y": -3,
      "z": -11,
      "name": "Empty"
    },
    {
      "x": -4,
      "y": -2,
      "z": -11,
      "name": "Empty"
    },
    {
      "x": -4,
      "y": -1,
      "z": -11,
      "name": "Empty"
    },
    {
      "x": -4,
      "y": 0,
      "z": -11,
      "name": "Empty"
    },
    {
      "x": -4,
      "y": 1,
      "z": -11,
      "name": "Empty"
    },
    {
      "x": -4,
      "y": -8,
      "z": -10,
      "name": "Rock_Stone"
    },
    {
      "x": -4,
      "y": -7,
      "z": -10,
      "name": "Rock_Stone"
    },
    {
      "x": -4,
      "y": -6,
      "z": -10,
      "name": "Rock_Stone"
    },
    {
      "x": -4,
      "y": -5,
      "z": -10,
      "name": "Rock_Stone"
    },
    {
      "x": -4,
      "y": -4,
      "z": -10,
      "name": "Rock_Stone_Cobble"
    },
    {
      "x": -4,
      "y": -3,
      "z": -10,
      "name": "Empty"
    },
    {
      "x": -4,
      "y": -2,
      "z": -10,
      "name": "Empty"
    },
    {
      "x": -4,
      "y": -1,
      "z": -10,
      "name": "Empty"
    },
    {
      "x": -4,
      "y": 0,
      "z": -10,
      "name": "Empty"
    },
    {
      "x": -4,
      "y": 1,
      "z": -10,
      "name": "Empty"
    },
    {
      "x": -4,
      "y": 2,
      "z": -10,
      "name": "Empty"
    },
    {
      "x": -4,
      "y": -6,
      "z": -9,
      "name": "Rock_Stone"
    },
    {
      "x": -4,
      "y": -5,
      "z": -9,
      "name": "Rock_Stone"
    },
    {
      "x": -4,
      "y": -4,
      "z": -9,
      "name": "Rock_Stone_Cobble"
    },
    {
      "x": -4,
      "y": -3,
      "z": -9,
      "name": "Empty"
    },
    {
      "x": -4,
      "y": -2,
      "z": -9,
      "name": "Empty"
    },
    {
      "x": -4,
      "y": -1,
      "z": -9,
      "name": "Empty"
    },
    {
      "x": -4,
      "y": 0,
      "z": -9,
      "name": "Empty"
    },
    {
      "x": -4,
      "y": 1,
      "z": -9,
      "name": "Empty"
    },
    {
      "x": -4,
      "y": 2,
      "z": -9,
      "name": "Empty"
    },
    {
      "x": -4,
      "y": -6,
      "z": -8,
      "name": "Rock_Stone"
    },
    {
      "x": -4,
      "y": -5,
      "z": -8,
      "name": "Rock_Stone"
    },
    {
      "x": -4,
      "y": -4,
      "z": -8,
      "name": "Rock_Stone"
    },
    {
      "x": -4,
      "y": -3,
      "z": -8,
      "name": "Rock_Stone_Cobble_Half"
    },
    {
      "x": -4,
      "y": -2,
      "z": -8,
      "name": "Empty"
    },
    {
      "x": -4,
      "y": -1,
      "z": -8,
      "name": "Empty"
    },
    {
      "x": -4,
      "y": 0,
      "z": -8,
      "name": "Empty"
    },
    {
      "x": -4,
      "y": 1,
      "z": -8,
      "name": "Empty"
    },
    {
      "x": -4,
      "y": 2,
      "z": -8,
      "name": "Empty"
    },
    {
      "x": -4,
      "y": -6,
      "z": -7,
      "name": "Rock_Stone"
    },
    {
      "x": -4,
      "y": -5,
      "z": -7,
      "name": "Rock_Stone"
    },
    {
      "x": -4,
      "y": -4,
      "z": -7,
      "name": "Rock_Stone"
    },
    {
      "x": -4,
      "y": -3,
      "z": -7,
      "name": "Soil_Gravel"
    },
    {
      "x": -4,
      "y": -2,
      "z": -7,
      "name": "Empty"
    },
    {
      "x": -4,
      "y": -1,
      "z": -7,
      "name": "Empty"
    },
    {
      "x": -4,
      "y": 0,
      "z": -7,
      "name": "Empty"
    },
    {
      "x": -4,
      "y": 1,
      "z": -7,
      "name": "Empty"
    },
    {
      "x": -4,
      "y": 2,
      "z": -7,
      "name": "Empty"
    },
    {
      "x": -4,
      "y": -5,
      "z": -6,
      "name": "Rock_Stone"
    },
    {
      "x": -4,
      "y": -4,
      "z": -6,
      "name": "Rock_Stone"
    },
    {
      "x": -4,
      "y": -3,
      "z": -6,
      "name": "Rock_Stone"
    },
    {
      "x": -4,
      "y": -2,
      "z": -6,
      "name": "Rock_Stone"
    },
    {
      "x": -4,
      "y": -1,
      "z": -6,
      "name": "Rock_Stone"
    },
    {
      "x": -4,
      "y": 0,
      "z": -6,
      "name": "Empty"
    },
    {
      "x": -4,
      "y": 1,
      "z": -6,
      "name": "Empty"
    },
    {
      "x": -4,
      "y": -4,
      "z": -5,
      "name": "Rock_Stone"
    },
    {
      "x": -4,
      "y": -3,
      "z": -5,
      "name": "Rock_Stone"
    },
    {
      "x": -4,
      "y": -2,
      "z": -5,
      "name": "Rock_Stone"
    },
    {
      "x": -4,
      "y": -1,
      "z": -5,
      "name": "Rock_Stone"
    },
    {
      "x": -4,
      "y": 0,
      "z": -5,
      "name": "Rock_Stone"
    },
    {
      "x": -4,
      "y": -1,
      "z": -4,
      "name": "Rock_Stone"
    },
    {
      "x": -3,
      "y": -9,
      "z": -18,
      "name": "Rock_Stone"
    },
    {
      "x": -3,
      "y": -8,
      "z": -18,
      "name": "Rock_Stone"
    },
    {
      "x": -3,
      "y": -7,
      "z": -18,
      "name": "Rock_Stone"
    },
    {
      "x": -3,
      "y": -6,
      "z": -18,
      "name": "Empty"
    },
    {
      "x": -3,
      "y": -9,
      "z": -17,
      "name": "Rock_Stone"
    },
    {
      "x": -3,
      "y": -8,
      "z": -17,
      "name": "Rock_Stone"
    },
    {
      "x": -3,
      "y": -7,
      "z": -17,
      "name": "Rock_Quartzite_Brick_Pillar_Base"
    },
    {
      "x": -3,
      "y": -6,
      "z": -17,
      "name": "Rock_Quartzite_Brick_Pillar_Middle"
    },
    {
      "x": -3,
      "y": -5,
      "z": -17,
      "name": "Rock_Quartzite_Brick_Pillar_Middle"
    },
    {
      "x": -3,
      "y": -4,
      "z": -17,
      "name": "Rock_Quartzite_Brick_Pillar_Base",
      "rotation": 8
    },
    {
      "x": -3,
      "y": -3,
      "z": -17,
      "name": "Empty"
    },
    {
      "x": -3,
      "y": -9,
      "z": -16,
      "name": "Rock_Stone"
    },
    {
      "x": -3,
      "y": -8,
      "z": -16,
      "name": "Rock_Stone"
    },
    {
      "x": -3,
      "y": -7,
      "z": -16,
      "name": "Soil_Gravel"
    },
    {
      "x": -3,
      "y": -6,
      "z": -16,
      "name": "Empty"
    },
    {
      "x": -3,
      "y": -5,
      "z": -16,
      "name": "Empty"
    },
    {
      "x": -3,
      "y": -4,
      "z": -16,
      "name": "Empty"
    },
    {
      "x": -3,
      "y": -3,
      "z": -16,
      "name": "Empty"
    },
    {
      "x": -3,
      "y": -9,
      "z": -15,
      "name": "Rock_Stone"
    },
    {
      "x": -3,
      "y": -8,
      "z": -15,
      "name": "Rock_Stone"
    },
    {
      "x": -3,
      "y": -7,
      "z": -15,
      "name": "Soil_Gravel"
    },
    {
      "x": -3,
      "y": -6,
      "z": -15,
      "name": "Empty"
    },
    {
      "x": -3,
      "y": -5,
      "z": -15,
      "name": "Empty"
    },
    {
      "x": -3,
      "y": -4,
      "z": -15,
      "name": "Empty"
    },
    {
      "x": -3,
      "y": -3,
      "z": -15,
      "name": "Empty"
    },
    {
      "x": -3,
      "y": -2,
      "z": -15,
      "name": "Empty"
    },
    {
      "x": -3,
      "y": -1,
      "z": -15,
      "name": "Empty"
    },
    {
      "x": -3,
      "y": -9,
      "z": -14,
      "name": "Rock_Stone"
    },
    {
      "x": -3,
      "y": -8,
      "z": -14,
      "name": "Rock_Stone"
    },
    {
      "x": -3,
      "y": -7,
      "z": -14,
      "name": "Rock_Stone"
    },
    {
      "x": -3,
      "y": -6,
      "z": -14,
      "name": "Empty"
    },
    {
      "x": -3,
      "y": -5,
      "z": -14,
      "name": "Empty"
    },
    {
      "x": -3,
      "y": -4,
      "z": -14,
      "name": "Empty"
    },
    {
      "x": -3,
      "y": -3,
      "z": -14,
      "name": "Empty"
    },
    {
      "x": -3,
      "y": -2,
      "z": -14,
      "name": "Empty"
    },
    {
      "x": -3,
      "y": -1,
      "z": -14,
      "name": "Empty"
    },
    {
      "x": -3,
      "y": 0,
      "z": -14,
      "name": "Empty"
    },
    {
      "x": -3,
      "y": -9,
      "z": -13,
      "name": "Rock_Stone"
    },
    {
      "x": -3,
      "y": -8,
      "z": -13,
      "name": "Rock_Stone"
    },
    {
      "x": -3,
      "y": -7,
      "z": -13,
      "name": "Empty"
    },
    {
      "x": -3,
      "y": -6,
      "z": -13,
      "name": "Empty"
    },
    {
      "x": -3,
      "y": -5,
      "z": -13,
      "name": "Empty"
    },
    {
      "x": -3,
      "y": -4,
      "z": -13,
      "name": "Empty"
    },
    {
      "x": -3,
      "y": -3,
      "z": -13,
      "name": "Empty"
    },
    {
      "x": -3,
      "y": -2,
      "z": -13,
      "name": "Empty"
    },
    {
      "x": -3,
      "y": -1,
      "z": -13,
      "name": "Empty"
    },
    {
      "x": -3,
      "y": 0,
      "z": -13,
      "name": "Empty"
    },
    {
      "x": -3,
      "y": -9,
      "z": -12,
      "name": "Rock_Stone"
    },
    {
      "x": -3,
      "y": -8,
      "z": -12,
      "name": "Rock_Stone"
    },
    {
      "x": -3,
      "y": -7,
      "z": -12,
      "name": "Rock_Stone"
    },
    {
      "x": -3,
      "y": -6,
      "z": -12,
      "name": "Empty"
    },
    {
      "x": -3,
      "y": -5,
      "z": -12,
      "name": "Empty"
    },
    {
      "x": -3,
      "y": -4,
      "z": -12,
      "name": "Empty"
    },
    {
      "x": -3,
      "y": -3,
      "z": -12,
      "name": "Empty"
    },
    {
      "x": -3,
      "y": -2,
      "z": -12,
      "name": "Empty"
    },
    {
      "x": -3,
      "y": -1,
      "z": -12,
      "name": "Empty"
    },
    {
      "x": -3,
      "y": 0,
      "z": -12,
      "name": "Empty"
    },
    {
      "x": -3,
      "y": 1,
      "z": -12,
      "name": "Empty"
    },
    {
      "x": -3,
      "y": -8,
      "z": -11,
      "name": "Rock_Stone"
    },
    {
      "x": -3,
      "y": -7,
      "z": -11,
      "name": "Rock_Stone"
    },
    {
      "x": -3,
      "y": -6,
      "z": -11,
      "name": "Rock_Stone"
    },
    {
      "x": -3,
      "y": -5,
      "z": -11,
      "name": "Rock_Stone"
    },
    {
      "x": -3,
      "y": -4,
      "z": -11,
      "name": "Rock_Stone"
    },
    {
      "x": -3,
      "y": -3,
      "z": -11,
      "name": "Rock_Stone"
    },
    {
      "x": -3,
      "y": -2,
      "z": -11,
      "name": "Empty"
    },
    {
      "x": -3,
      "y": -1,
      "z": -11,
      "name": "Empty"
    },
    {
      "x": -3,
      "y": 0,
      "z": -11,
      "name": "Empty"
    },
    {
      "x": -3,
      "y": 1,
      "z": -11,
      "name": "Empty"
    },
    {
      "x": -3,
      "y": 2,
      "z": -11,
      "name": "Empty"
    },
    {
      "x": -3,
      "y": -8,
      "z": -10,
      "name": "Rock_Stone"
    },
    {
      "x": -3,
      "y": -7,
      "z": -10,
      "name": "Rock_Stone"
    },
    {
      "x": -3,
      "y": -6,
      "z": -10,
      "name": "Rock_Stone"
    },
    {
      "x": -3,
      "y": -5,
      "z": -10,
      "name": "Rock_Stone"
    },
    {
      "x": -3,
      "y": -4,
      "z": -10,
      "name": "Rock_Stone"
    },
    {
      "x": -3,
      "y": -3,
      "z": -10,
      "name": "Rock_Stone"
    },
    {
      "x": -3,
      "y": -2,
      "z": -10,
      "name": "Rock_Stone"
    },
    {
      "x": -3,
      "y": -1,
      "z": -10,
      "name": "Empty"
    },
    {
      "x": -3,
      "y": 0,
      "z": -10,
      "name": "Empty"
    },
    {
      "x": -3,
      "y": 1,
      "z": -10,
      "name": "Rock_Stone_Stalactite_Large",
      "filler": 31744,
      "rotation": 8
    },
    {
      "x": -3,
      "y": 2,
      "z": -10,
      "name": "Rock_Stone_Stalactite_Large",
      "rotation": 8
    },
    {
      "x": -3,
      "y": -7,
      "z": -9,
      "name": "Rock_Stone"
    },
    {
      "x": -3,
      "y": -6,
      "z": -9,
      "name": "Rock_Stone"
    },
    {
      "x": -3,
      "y": -5,
      "z": -9,
      "name": "Rock_Stone"
    },
    {
      "x": -3,
      "y": -4,
      "z": -9,
      "name": "Rock_Stone_Cobble"
    },
    {
      "x": -3,
      "y": -3,
      "z": -9,
      "name": "Rock_Stone_Cobble_Half"
    },
    {
      "x": -3,
      "y": -2,
      "z": -9,
      "name": "Empty"
    },
    {
      "x": -3,
      "y": -1,
      "z": -9,
      "name": "Empty"
    },
    {
      "x": -3,
      "y": 0,
      "z": -9,
      "name": "Empty"
    },
    {
      "x": -3,
      "y": 1,
      "z": -9,
      "name": "Empty"
    },
    {
      "x": -3,
      "y": 2,
      "z": -9,
      "name": "Empty"
    },
    {
      "x": -3,
      "y": -6,
      "z": -8,
      "name": "Rock_Stone"
    },
    {
      "x": -3,
      "y": -5,
      "z": -8,
      "name": "Rock_Stone"
    },
    {
      "x": -3,
      "y": -4,
      "z": -8,
      "name": "Rock_Stone"
    },
    {
      "x": -3,
      "y": -3,
      "z": -8,
      "name": "Rock_Stone_Cobble_Half"
    },
    {
      "x": -3,
      "y": -2,
      "z": -8,
      "name": "Empty"
    },
    {
      "x": -3,
      "y": -1,
      "z": -8,
      "name": "Empty"
    },
    {
      "x": -3,
      "y": 0,
      "z": -8,
      "name": "Empty"
    },
    {
      "x": -3,
      "y": 1,
      "z": -8,
      "name": "Empty"
    },
    {
      "x": -3,
      "y": 2,
      "z": -8,
      "name": "Empty"
    },
    {
      "x": -3,
      "y": 3,
      "z": -8,
      "name": "Empty"
    },
    {
      "x": -3,
      "y": -6,
      "z": -7,
      "name": "Rock_Stone"
    },
    {
      "x": -3,
      "y": -5,
      "z": -7,
      "name": "Rock_Stone"
    },
    {
      "x": -3,
      "y": -4,
      "z": -7,
      "name": "Rock_Stone"
    },
    {
      "x": -3,
      "y": -3,
      "z": -7,
      "name": "Soil_Gravel"
    },
    {
      "x": -3,
      "y": -2,
      "z": -7,
      "name": "Empty"
    },
    {
      "x": -3,
      "y": -1,
      "z": -7,
      "name": "Empty"
    },
    {
      "x": -3,
      "y": 0,
      "z": -7,
      "name": "Empty"
    },
    {
      "x": -3,
      "y": 1,
      "z": -7,
      "name": "Empty"
    },
    {
      "x": -3,
      "y": 2,
      "z": -7,
      "name": "Empty"
    },
    {
      "x": -3,
      "y": 3,
      "z": -7,
      "name": "Empty"
    },
    {
      "x": -3,
      "y": -5,
      "z": -6,
      "name": "Rock_Stone"
    },
    {
      "x": -3,
      "y": -4,
      "z": -6,
      "name": "Rock_Stone"
    },
    {
      "x": -3,
      "y": -3,
      "z": -6,
      "name": "Rock_Stone"
    },
    {
      "x": -3,
      "y": -2,
      "z": -6,
      "name": "Empty"
    },
    {
      "x": -3,
      "y": -1,
      "z": -6,
      "name": "Empty"
    },
    {
      "x": -3,
      "y": 0,
      "z": -6,
      "name": "Empty"
    },
    {
      "x": -3,
      "y": 1,
      "z": -6,
      "name": "Empty"
    },
    {
      "x": -3,
      "y": 2,
      "z": -6,
      "name": "Empty"
    },
    {
      "x": -3,
      "y": 3,
      "z": -6,
      "name": "Empty"
    },
    {
      "x": -3,
      "y": -4,
      "z": -5,
      "name": "Rock_Stone"
    },
    {
      "x": -3,
      "y": -3,
      "z": -5,
      "name": "Rock_Stone"
    },
    {
      "x": -3,
      "y": -2,
      "z": -5,
      "name": "Plant_Moss_Block_Blue"
    },
    {
      "x": -3,
      "y": -1,
      "z": -5,
      "name": "Empty"
    },
    {
      "x": -3,
      "y": 0,
      "z": -5,
      "name": "Empty"
    },
    {
      "x": -3,
      "y": 1,
      "z": -5,
      "name": "Plant_Moss_Rug_Blue"
    },
    {
      "x": -3,
      "y": 2,
      "z": -5,
      "name": "Empty"
    },
    {
      "x": -3,
      "y": 3,
      "z": -5,
      "name": "Empty"
    },
    {
      "x": -3,
      "y": -3,
      "z": -4,
      "name": "Rock_Stone"
    },
    {
      "x": -3,
      "y": -2,
      "z": -4,
      "name": "Plant_Moss_Block_Blue"
    },
    {
      "x": -3,
      "y": -1,
      "z": -4,
      "name": "Plant_Moss_Rug_Blue"
    },
    {
      "x": -3,
      "y": 0,
      "z": -4,
      "name": "Empty"
    },
    {
      "x": -3,
      "y": 1,
      "z": -4,
      "name": "Empty"
    },
    {
      "x": -3,
      "y": 2,
      "z": -4,
      "name": "Empty"
    },
    {
      "x": -3,
      "y": -2,
      "z": -3,
      "name": "Rock_Stone"
    },
    {
      "x": -3,
      "y": -1,
      "z": -3,
      "name": "Rock_Stone"
    },
    {
      "x": -3,
      "y": 0,
      "z": -3,
      "name": "Rock_Stone"
    },
    {
      "x": -3,
      "y": -1,
      "z": -2,
      "name": "Rock_Stone"
    },
    {
      "x": -3,
      "y": 0,
      "z": -2,
      "name": "Rock_Stone"
    },
    {
      "x": -3,
      "y": 1,
      "z": -2,
      "name": "Rock_Stone"
    },
    {
      "x": -3,
      "y": -1,
      "z": -1,
      "name": "Rock_Stone"
    },
    {
      "x": -3,
      "y": 0,
      "z": -1,
      "name": "Rock_Stone"
    },
    {
      "x": -3,
      "y": 1,
      "z": -1,
      "name": "Rock_Stone"
    },
    {
      "x": -3,
      "y": 0,
      "z": 0,
      "name": "Rock_Stone"
    },
    {
      "x": -2,
      "y": -8,
      "z": -19,
      "name": "Rock_Stone"
    },
    {
      "x": -2,
      "y": -9,
      "z": -18,
      "name": "Rock_Stone"
    },
    {
      "x": -2,
      "y": -8,
      "z": -18,
      "name": "Rock_Stone"
    },
    {
      "x": -2,
      "y": -7,
      "z": -18,
      "name": "Empty"
    },
    {
      "x": -2,
      "y": -6,
      "z": -18,
      "name": "Empty"
    },
    {
      "x": -2,
      "y": -5,
      "z": -18,
      "name": "Empty"
    },
    {
      "x": -2,
      "y": -10,
      "z": -17,
      "name": "Rock_Stone"
    },
    {
      "x": -2,
      "y": -9,
      "z": -17,
      "name": "Rock_Stone"
    },
    {
      "x": -2,
      "y": -8,
      "z": -17,
      "name": "Rock_Stone"
    },
    {
      "x": -2,
      "y": -7,
      "z": -17,
      "name": "Empty"
    },
    {
      "x": -2,
      "y": -6,
      "z": -17,
      "name": "Empty"
    },
    {
      "x": -2,
      "y": -5,
      "z": -17,
      "name": "Empty"
    },
    {
      "x": -2,
      "y": -4,
      "z": -17,
      "name": "Empty"
    },
    {
      "x": -2,
      "y": -3,
      "z": -17,
      "name": "Empty"
    },
    {
      "x": -2,
      "y": -10,
      "z": -16,
      "name": "Rock_Stone"
    },
    {
      "x": -2,
      "y": -9,
      "z": -16,
      "name": "Rock_Stone"
    },
    {
      "x": -2,
      "y": -8,
      "z": -16,
      "name": "Rock_Stone"
    },
    {
      "x": -2,
      "y": -7,
      "z": -16,
      "name": "Empty"
    },
    {
      "x": -2,
      "y": -6,
      "z": -16,
      "name": "Empty"
    },
    {
      "x": -2,
      "y": -5,
      "z": -16,
      "name": "Empty"
    },
    {
      "x": -2,
      "y": -4,
      "z": -16,
      "name": "Empty"
    },
    {
      "x": -2,
      "y": -3,
      "z": -16,
      "name": "Empty"
    },
    {
      "x": -2,
      "y": -10,
      "z": -15,
      "name": "Rock_Stone"
    },
    {
      "x": -2,
      "y": -9,
      "z": -15,
      "name": "Rock_Stone"
    },
    {
      "x": -2,
      "y": -8,
      "z": -15,
      "name": "Soil_Gravel"
    },
    {
      "x": -2,
      "y": -7,
      "z": -15,
      "name": "Empty"
    },
    {
      "x": -2,
      "y": -6,
      "z": -15,
      "name": "Empty"
    },
    {
      "x": -2,
      "y": -5,
      "z": -15,
      "name": "Empty"
    },
    {
      "x": -2,
      "y": -4,
      "z": -15,
      "name": "Empty"
    },
    {
      "x": -2,
      "y": -3,
      "z": -15,
      "name": "Empty"
    },
    {
      "x": -2,
      "y": -2,
      "z": -15,
      "name": "Empty"
    },
    {
      "x": -2,
      "y": -9,
      "z": -14,
      "name": "Rock_Stone"
    },
    {
      "x": -2,
      "y": -8,
      "z": -14,
      "name": "Rock_Stone"
    },
    {
      "x": -2,
      "y": -7,
      "z": -14,
      "name": "Empty"
    },
    {
      "x": -2,
      "y": -6,
      "z": -14,
      "name": "Empty"
    },
    {
      "x": -2,
      "y": -5,
      "z": -14,
      "name": "Empty"
    },
    {
      "x": -2,
      "y": -4,
      "z": -14,
      "name": "Empty"
    },
    {
      "x": -2,
      "y": -3,
      "z": -14,
      "name": "Empty"
    },
    {
      "x": -2,
      "y": -2,
      "z": -14,
      "name": "Empty"
    },
    {
      "x": -2,
      "y": -9,
      "z": -13,
      "name": "Rock_Stone"
    },
    {
      "x": -2,
      "y": -8,
      "z": -13,
      "name": "Rock_Stone"
    },
    {
      "x": -2,
      "y": -7,
      "z": -13,
      "name": "Empty"
    },
    {
      "x": -2,
      "y": -6,
      "z": -13,
      "name": "Empty"
    },
    {
      "x": -2,
      "y": -5,
      "z": -13,
      "name": "Empty"
    },
    {
      "x": -2,
      "y": -4,
      "z": -13,
      "name": "Empty"
    },
    {
      "x": -2,
      "y": -3,
      "z": -13,
      "name": "Empty"
    },
    {
      "x": -2,
      "y": -2,
      "z": -13,
      "name": "Empty"
    },
    {
      "x": -2,
      "y": -9,
      "z": -12,
      "name": "Rock_Stone"
    },
    {
      "x": -2,
      "y": -8,
      "z": -12,
      "name": "Rock_Stone"
    },
    {
      "x": -2,
      "y": -7,
      "z": -12,
      "name": "Rock_Stone"
    },
    {
      "x": -2,
      "y": -6,
      "z": -12,
      "name": "Empty"
    },
    {
      "x": -2,
      "y": -5,
      "z": -12,
      "name": "Empty"
    },
    {
      "x": -2,
      "y": -4,
      "z": -12,
      "name": "Empty"
    },
    {
      "x": -2,
      "y": -3,
      "z": -12,
      "name": "Empty"
    },
    {
      "x": -2,
      "y": -2,
      "z": -12,
      "name": "Empty"
    },
    {
      "x": -2,
      "y": 1,
      "z": -12,
      "name": "Empty"
    },
    {
      "x": -2,
      "y": 2,
      "z": -12,
      "name": "Empty"
    },
    {
      "x": -2,
      "y": -8,
      "z": -11,
      "name": "Rock_Stone"
    },
    {
      "x": -2,
      "y": -7,
      "z": -11,
      "name": "Rock_Stone"
    },
    {
      "x": -2,
      "y": -6,
      "z": -11,
      "name": "Rock_Stone"
    },
    {
      "x": -2,
      "y": -5,
      "z": -11,
      "name": "Rock_Stone"
    },
    {
      "x": -2,
      "y": -4,
      "z": -11,
      "name": "Rock_Stone"
    },
    {
      "x": -2,
      "y": -3,
      "z": -11,
      "name": "Rock_Stone"
    },
    {
      "x": -2,
      "y": -2,
      "z": -11,
      "name": "Rock_Stone_Stalactite_Small"
    },
    {
      "x": -2,
      "y": -1,
      "z": -11,
      "name": "Empty"
    },
    {
      "x": -2,
      "y": 0,
      "z": -11,
      "name": "Empty"
    },
    {
      "x": -2,
      "y": 1,
      "z": -11,
      "name": "Rock_Stone_Stalactite_Large",
      "filler": 31744,
      "rotation": 8
    },
    {
      "x": -2,
      "y": 2,
      "z": -11,
      "name": "Rock_Stone_Stalactite_Large",
      "rotation": 8
    },
    {
      "x": -2,
      "y": -8,
      "z": -10,
      "name": "Rock_Stone"
    },
    {
      "x": -2,
      "y": -7,
      "z": -10,
      "name": "Rock_Stone"
    },
    {
      "x": -2,
      "y": -6,
      "z": -10,
      "name": "Rock_Stone"
    },
    {
      "x": -2,
      "y": -5,
      "z": -10,
      "name": "Rock_Stone"
    },
    {
      "x": -2,
      "y": -4,
      "z": -10,
      "name": "Rock_Stone"
    },
    {
      "x": -2,
      "y": -3,
      "z": -10,
      "name": "Empty"
    },
    {
      "x": -2,
      "y": -2,
      "z": -10,
      "name": "Empty"
    },
    {
      "x": -2,
      "y": -1,
      "z": -10,
      "name": "Empty"
    },
    {
      "x": -2,
      "y": 0,
      "z": -10,
      "name": "Empty"
    },
    {
      "x": -2,
      "y": 1,
      "z": -10,
      "name": "Empty"
    },
    {
      "x": -2,
      "y": 2,
      "z": -10,
      "name": "Empty"
    },
    {
      "x": -2,
      "y": 3,
      "z": -10,
      "name": "Empty"
    },
    {
      "x": -2,
      "y": -8,
      "z": -9,
      "name": "Rock_Stone"
    },
    {
      "x": -2,
      "y": -7,
      "z": -9,
      "name": "Rock_Stone"
    },
    {
      "x": -2,
      "y": -6,
      "z": -9,
      "name": "Rock_Stone"
    },
    {
      "x": -2,
      "y": -5,
      "z": -9,
      "name": "Rock_Stone"
    },
    {
      "x": -2,
      "y": -4,
      "z": -9,
      "name": "Rock_Stone"
    },
    {
      "x": -2,
      "y": -3,
      "z": -9,
      "name": "Rock_Stone_Cobble_Half"
    },
    {
      "x": -2,
      "y": -2,
      "z": -9,
      "name": "Empty"
    },
    {
      "x": -2,
      "y": -1,
      "z": -9,
      "name": "Empty"
    },
    {
      "x": -2,
      "y": 0,
      "z": -9,
      "name": "Empty"
    },
    {
      "x": -2,
      "y": 1,
      "z": -9,
      "name": "Empty"
    },
    {
      "x": -2,
      "y": 2,
      "z": -9,
      "name": "Empty"
    },
    {
      "x": -2,
      "y": 3,
      "z": -9,
      "name": "Empty"
    },
    {
      "x": -2,
      "y": -6,
      "z": -8,
      "name": "Rock_Stone"
    },
    {
      "x": -2,
      "y": -5,
      "z": -8,
      "name": "Rock_Stone"
    },
    {
      "x": -2,
      "y": -4,
      "z": -8,
      "name": "Rock_Stone"
    },
    {
      "x": -2,
      "y": -3,
      "z": -8,
      "name": "Soil_Gravel"
    },
    {
      "x": -2,
      "y": -2,
      "z": -8,
      "name": "Empty"
    },
    {
      "x": -2,
      "y": -1,
      "z": -8,
      "name": "Empty"
    },
    {
      "x": -2,
      "y": 0,
      "z": -8,
      "name": "Empty"
    },
    {
      "x": -2,
      "y": 1,
      "z": -8,
      "name": "Empty"
    },
    {
      "x": -2,
      "y": 2,
      "z": -8,
      "name": "Empty"
    },
    {
      "x": -2,
      "y": 3,
      "z": -8,
      "name": "Empty"
    },
    {
      "x": -2,
      "y": -5,
      "z": -7,
      "name": "Rock_Stone"
    },
    {
      "x": -2,
      "y": -4,
      "z": -7,
      "name": "Rock_Stone"
    },
    {
      "x": -2,
      "y": -3,
      "z": -7,
      "name": "Soil_Gravel"
    },
    {
      "x": -2,
      "y": -2,
      "z": -7,
      "name": "Empty"
    },
    {
      "x": -2,
      "y": -1,
      "z": -7,
      "name": "Empty"
    },
    {
      "x": -2,
      "y": 0,
      "z": -7,
      "name": "Empty"
    },
    {
      "x": -2,
      "y": 1,
      "z": -7,
      "name": "Empty"
    },
    {
      "x": -2,
      "y": 2,
      "z": -7,
      "name": "Empty"
    },
    {
      "x": -2,
      "y": 3,
      "z": -7,
      "name": "Empty"
    },
    {
      "x": -2,
      "y": -5,
      "z": -6,
      "name": "Rock_Stone"
    },
    {
      "x": -2,
      "y": -4,
      "z": -6,
      "name": "Rock_Stone"
    },
    {
      "x": -2,
      "y": -3,
      "z": -6,
      "name": "Rock_Stone"
    },
    {
      "x": -2,
      "y": -2,
      "z": -6,
      "name": "Rock_Stone"
    },
    {
      "x": -2,
      "y": -1,
      "z": -6,
      "name": "Empty"
    },
    {
      "x": -2,
      "y": 0,
      "z": -6,
      "name": "Empty"
    },
    {
      "x": -2,
      "y": 1,
      "z": -6,
      "name": "Empty"
    },
    {
      "x": -2,
      "y": 2,
      "z": -6,
      "name": "Empty"
    },
    {
      "x": -2,
      "y": 3,
      "z": -6,
      "name": "Empty"
    },
    {
      "x": -2,
      "y": 4,
      "z": -6,
      "name": "Empty"
    },
    {
      "x": -2,
      "y": -4,
      "z": -5,
      "name": "Rock_Stone"
    },
    {
      "x": -2,
      "y": -3,
      "z": -5,
      "name": "Rock_Stone"
    },
    {
      "x": -2,
      "y": -2,
      "z": -5,
      "name": "Rock_Stone"
    },
    {
      "x": -2,
      "y": -1,
      "z": -5,
      "name": "Empty"
    },
    {
      "x": -2,
      "y": 0,
      "z": -5,
      "name": "Empty"
    },
    {
      "x": -2,
      "y": 1,
      "z": -5,
      "name": "Empty"
    },
    {
      "x": -2,
      "y": 2,
      "z": -5,
      "name": "Empty"
    },
    {
      "x": -2,
      "y": 3,
      "z": -5,
      "name": "Empty"
    },
    {
      "x": -2,
      "y": 4,
      "z": -5,
      "name": "Empty"
    },
    {
      "x": -2,
      "y": -4,
      "z": -4,
      "name": "Rock_Stone"
    },
    {
      "x": -2,
      "y": -3,
      "z": -4,
      "name": "Rock_Stone"
    },
    {
      "x": -2,
      "y": -2,
      "z": -4,
      "name": "Rock_Stone"
    },
    {
      "x": -2,
      "y": -1,
      "z": -4,
      "name": "Rock_Quartzite_Brick_Pillar_Base"
    },
    {
      "x": -2,
      "y": 0,
      "z": -4,
      "name": "Rock_Quartzite_Brick_Pillar_Middle"
    },
    {
      "x": -2,
      "y": 1,
      "z": -4,
      "name": "Rock_Quartzite_Brick_Pillar_Middle"
    },
    {
      "x": -2,
      "y": 2,
      "z": -4,
      "name": "Plant_Moss_Rug_Blue"
    },
    {
      "x": -2,
      "y": 3,
      "z": -4,
      "name": "Empty"
    },
    {
      "x": -2,
      "y": 4,
      "z": -4,
      "name": "Empty"
    },
    {
      "x": -2,
      "y": -3,
      "z": -3,
      "name": "Rock_Stone"
    },
    {
      "x": -2,
      "y": -2,
      "z": -3,
      "name": "Rock_Stone"
    },
    {
      "x": -2,
      "y": -1,
      "z": -3,
      "name": "Rock_Stone"
    },
    {
      "x": -2,
      "y": 0,
      "z": -3,
      "name": "Rock_Quartzite_Brick"
    },
    {
      "x": -2,
      "y": 1,
      "z": -3,
      "name": "Plant_Moss_Rug_Blue"
    },
    {
      "x": -2,
      "y": 2,
      "z": -3,
      "name": "Empty"
    },
    {
      "x": -2,
      "y": 3,
      "z": -3,
      "name": "Empty"
    },
    {
      "x": -2,
      "y": -2,
      "z": -2,
      "name": "Rock_Stone"
    },
    {
      "x": -2,
      "y": -1,
      "z": -2,
      "name": "Rock_Stone"
    },
    {
      "x": -2,
      "y": 0,
      "z": -2,
      "name": "Rock_Quartzite_Brick"
    },
    {
      "x": -2,
      "y": 1,
      "z": -2,
      "name": "Rock_Quartzite_Brick"
    },
    {
      "x": -2,
      "y": 2,
      "z": -2,
      "name": "Rock_Quartzite_Brick"
    },
    {
      "x": -2,
      "y": 3,
      "z": -2,
      "name": "Rock_Quartzite_Brick"
    },
    {
      "x": -2,
      "y": -2,
      "z": -1,
      "name": "Rock_Stone"
    },
    {
      "x": -2,
      "y": -1,
      "z": -1,
      "name": "Rock_Stone"
    },
    {
      "x": -2,
      "y": 0,
      "z": -1,
      "name": "Rock_Stone"
    },
    {
      "x": -2,
      "y": 1,
      "z": -1,
      "name": "Rock_Quartzite_Brick"
    },
    {
      "x": -2,
      "y": 2,
      "z": -1,
      "name": "Rock_Quartzite_Brick"
    },
    {
      "x": -2,
      "y": 3,
      "z": -1,
      "name": "Rock_Quartzite_Brick"
    },
    {
      "x": -2,
      "y": -1,
      "z": 0,
      "name": "Rock_Stone"
    },
    {
      "x": -2,
      "y": 0,
      "z": 0,
      "name": "Rock_Stone"
    },
    {
      "x": -2,
      "y": 1,
      "z": 0,
      "name": "Rock_Quartzite_Brick"
    },
    {
      "x": -2,
      "y": 2,
      "z": 0,
      "name": "Rock_Quartzite_Brick"
    },
    {
      "x": -2,
      "y": 3,
      "z": 0,
      "name": "Rock_Quartzite_Brick"
    },
    {
      "x": -1,
      "y": -16,
      "z": -27,
      "name": "Rock_Stone"
    },
    {
      "x": -1,
      "y": -17,
      "z": -26,
      "name": "Rock_Stone"
    },
    {
      "x": -1,
      "y": -16,
      "z": -26,
      "name": "Rock_Stone"
    },
    {
      "x": -1,
      "y": -15,
      "z": -26,
      "name": "Rock_Stone"
    },
    {
      "x": -1,
      "y": -16,
      "z": -25,
      "name": "Rock_Stone"
    },
    {
      "x": -1,
      "y": -15,
      "z": -20,
      "name": "Rock_Stone"
    },
    {
      "x": -1,
      "y": -16,
      "z": -19,
      "name": "Rock_Stone"
    },
    {
      "x": -1,
      "y": -15,
      "z": -19,
      "name": "Rock_Stone"
    },
    {
      "x": -1,
      "y": -14,
      "z": -19,
      "name": "Rock_Stone"
    },
    {
      "x": -1,
      "y": -9,
      "z": -19,
      "name": "Rock_Stone"
    },
    {
      "x": -1,
      "y": -8,
      "z": -19,
      "name": "Rock_Stone"
    },
    {
      "x": -1,
      "y": -7,
      "z": -19,
      "name": "Empty"
    },
    {
      "x": -1,
      "y": -6,
      "z": -19,
      "name": "Empty"
    },
    {
      "x": -1,
      "y": -15,
      "z": -18,
      "name": "Rock_Stone"
    },
    {
      "x": -1,
      "y": -9,
      "z": -18,
      "name": "Rock_Stone"
    },
    {
      "x": -1,
      "y": -8,
      "z": -18,
      "name": "Empty"
    },
    {
      "x": -1,
      "y": -7,
      "z": -18,
      "name": "Empty"
    },
    {
      "x": -1,
      "y": -6,
      "z": -18,
      "name": "Empty"
    },
    {
      "x": -1,
      "y": -5,
      "z": -18,
      "name": "Empty"
    },
    {
      "x": -1,
      "y": -4,
      "z": -18,
      "name": "Empty"
    },
    {
      "x": -1,
      "y": -10,
      "z": -17,
      "name": "Rock_Stone"
    },
    {
      "x": -1,
      "y": -9,
      "z": -17,
      "name": "Rock_Stone"
    },
    {
      "x": -1,
      "y": -8,
      "z": -17,
      "name": "Rock_Stone"
    },
    {
      "x": -1,
      "y": -7,
      "z": -17,
      "name": "Empty"
    },
    {
      "x": -1,
      "y": -6,
      "z": -17,
      "name": "Empty"
    },
    {
      "x": -1,
      "y": -5,
      "z": -17,
      "name": "Empty"
    },
    {
      "x": -1,
      "y": -4,
      "z": -17,
      "name": "Empty"
    },
    {
      "x": -1,
      "y": -10,
      "z": -16,
      "name": "Rock_Stone"
    },
    {
      "x": -1,
      "y": -9,
      "z": -16,
      "name": "Rock_Stone"
    },
    {
      "x": -1,
      "y": -8,
      "z": -16,
      "name": "Rock_Stone"
    },
    {
      "x": -1,
      "y": -7,
      "z": -16,
      "name": "Empty"
    },
    {
      "x": -1,
      "y": -6,
      "z": -16,
      "name": "Empty"
    },
    {
      "x": -1,
      "y": -5,
      "z": -16,
      "name": "Empty"
    },
    {
      "x": -1,
      "y": -4,
      "z": -16,
      "name": "Empty"
    },
    {
      "x": -1,
      "y": -3,
      "z": -16,
      "name": "Empty"
    },
    {
      "x": -1,
      "y": -10,
      "z": -15,
      "name": "Rock_Stone"
    },
    {
      "x": -1,
      "y": -9,
      "z": -15,
      "name": "Rock_Stone"
    },
    {
      "x": -1,
      "y": -8,
      "z": -15,
      "name": "Rock_Stone"
    },
    {
      "x": -1,
      "y": -7,
      "z": -15,
      "name": "Empty"
    },
    {
      "x": -1,
      "y": -6,
      "z": -15,
      "name": "Empty"
    },
    {
      "x": -1,
      "y": -5,
      "z": -15,
      "name": "Empty"
    },
    {
      "x": -1,
      "y": -4,
      "z": -15,
      "name": "Empty"
    },
    {
      "x": -1,
      "y": -3,
      "z": -15,
      "name": "Empty"
    },
    {
      "x": -1,
      "y": -9,
      "z": -14,
      "name": "Rock_Stone"
    },
    {
      "x": -1,
      "y": -8,
      "z": -14,
      "name": "Rock_Stone"
    },
    {
      "x": -1,
      "y": -7,
      "z": -14,
      "name": "Empty"
    },
    {
      "x": -1,
      "y": -6,
      "z": -14,
      "name": "Empty"
    },
    {
      "x": -1,
      "y": -5,
      "z": -14,
      "name": "Empty"
    },
    {
      "x": -1,
      "y": -4,
      "z": -14,
      "name": "Empty"
    },
    {
      "x": -1,
      "y": -3,
      "z": -14,
      "name": "Empty"
    },
    {
      "x": -1,
      "y": -9,
      "z": -13,
      "name": "Rock_Stone"
    },
    {
      "x": -1,
      "y": -8,
      "z": -13,
      "name": "Rock_Stone"
    },
    {
      "x": -1,
      "y": -7,
      "z": -13,
      "name": "Rock_Stone"
    },
    {
      "x": -1,
      "y": -6,
      "z": -13,
      "name": "Empty"
    },
    {
      "x": -1,
      "y": -5,
      "z": -13,
      "name": "Empty"
    },
    {
      "x": -1,
      "y": -4,
      "z": -13,
      "name": "Empty"
    },
    {
      "x": -1,
      "y": -3,
      "z": -13,
      "name": "Empty"
    },
    {
      "x": -1,
      "y": -9,
      "z": -12,
      "name": "Rock_Stone"
    },
    {
      "x": -1,
      "y": -8,
      "z": -12,
      "name": "Rock_Stone"
    },
    {
      "x": -1,
      "y": -7,
      "z": -12,
      "name": "Rock_Stone"
    },
    {
      "x": -1,
      "y": -6,
      "z": -12,
      "name": "Rock_Stone"
    },
    {
      "x": -1,
      "y": -5,
      "z": -12,
      "name": "Rock_Stone"
    },
    {
      "x": -1,
      "y": -4,
      "z": -12,
      "name": "Empty"
    },
    {
      "x": -1,
      "y": -3,
      "z": -12,
      "name": "Empty"
    },
    {
      "x": -1,
      "y": 1,
      "z": -12,
      "name": "Plant_Moss_Rug_Blue"
    },
    {
      "x": -1,
      "y": -8,
      "z": -11,
      "name": "Rock_Stone"
    },
    {
      "x": -1,
      "y": -7,
      "z": -11,
      "name": "Rock_Stone"
    },
    {
      "x": -1,
      "y": -6,
      "z": -11,
      "name": "Rock_Stone"
    },
    {
      "x": -1,
      "y": -5,
      "z": -11,
      "name": "Rock_Stone"
    },
    {
      "x": -1,
      "y": -4,
      "z": -11,
      "name": "Rock_Stone"
    },
    {
      "x": -1,
      "y": -3,
      "z": -11,
      "name": "Plant_Crop_Mushroom_Common_Blue",
      "components": {
        "Components": {
          "FarmingBlock": {}
        }
      }
    },
    {
      "x": -1,
      "y": -2,
      "z": -11,
      "name": "Empty"
    },
    {
      "x": -1,
      "y": 1,
      "z": -11,
      "name": "Plant_Moss_Rug_Blue"
    },
    {
      "x": -1,
      "y": 2,
      "z": -11,
      "name": "Empty"
    },
    {
      "x": -1,
      "y": -8,
      "z": -10,
      "name": "Rock_Stone"
    },
    {
      "x": -1,
      "y": -7,
      "z": -10,
      "name": "Rock_Stone"
    },
    {
      "x": -1,
      "y": -6,
      "z": -10,
      "name": "Rock_Stone"
    },
    {
      "x": -1,
      "y": -5,
      "z": -10,
      "name": "Rock_Stone"
    },
    {
      "x": -1,
      "y": -4,
      "z": -10,
      "name": "Plant_Moss_Block_Blue"
    },
    {
      "x": -1,
      "y": -3,
      "z": -10,
      "name": "Empty"
    },
    {
      "x": -1,
      "y": -2,
      "z": -10,
      "name": "Empty"
    },
    {
      "x": -1,
      "y": -1,
      "z": -10,
      "name": "Empty"
    },
    {
      "x": -1,
      "y": 0,
      "z": -10,
      "name": "Empty"
    },
    {
      "x": -1,
      "y": 1,
      "z": -10,
      "name": "Empty"
    },
    {
      "x": -1,
      "y": 2,
      "z": -10,
      "name": "Empty"
    },
    {
      "x": -1,
      "y": 3,
      "z": -10,
      "name": "Empty"
    },
    {
      "x": -1,
      "y": -7,
      "z": -9,
      "name": "Rock_Stone"
    },
    {
      "x": -1,
      "y": -6,
      "z": -9,
      "name": "Rock_Stone"
    },
    {
      "x": -1,
      "y": -5,
      "z": -9,
      "name": "Rock_Stone"
    },
    {
      "x": -1,
      "y": -4,
      "z": -9,
      "name": "Rock_Stone"
    },
    {
      "x": -1,
      "y": -3,
      "z": -9,
      "name": "Rock_Stone_Cobble_Half"
    },
    {
      "x": -1,
      "y": -2,
      "z": -9,
      "name": "Empty"
    },
    {
      "x": -1,
      "y": -1,
      "z": -9,
      "name": "Empty"
    },
    {
      "x": -1,
      "y": 0,
      "z": -9,
      "name": "Empty"
    },
    {
      "x": -1,
      "y": 1,
      "z": -9,
      "name": "Empty"
    },
    {
      "x": -1,
      "y": 2,
      "z": -9,
      "name": "Empty"
    },
    {
      "x": -1,
      "y": 3,
      "z": -9,
      "name": "Empty"
    },
    {
      "x": -1,
      "y": -5,
      "z": -8,
      "name": "Rock_Stone"
    },
    {
      "x": -1,
      "y": -4,
      "z": -8,
      "name": "Rock_Stone"
    },
    {
      "x": -1,
      "y": -3,
      "z": -8,
      "name": "Rock_Stone"
    },
    {
      "x": -1,
      "y": -2,
      "z": -8,
      "name": "Empty"
    },
    {
      "x": -1,
      "y": -1,
      "z": -8,
      "name": "Empty"
    },
    {
      "x": -1,
      "y": 0,
      "z": -8,
      "name": "Empty"
    },
    {
      "x": -1,
      "y": 1,
      "z": -8,
      "name": "Empty"
    },
    {
      "x": -1,
      "y": 2,
      "z": -8,
      "name": "Empty"
    },
    {
      "x": -1,
      "y": 3,
      "z": -8,
      "name": "Empty"
    },
    {
      "x": -1,
      "y": -5,
      "z": -7,
      "name": "Rock_Stone"
    },
    {
      "x": -1,
      "y": -4,
      "z": -7,
      "name": "Rock_Stone"
    },
    {
      "x": -1,
      "y": -3,
      "z": -7,
      "name": "Soil_Gravel"
    },
    {
      "x": -1,
      "y": -2,
      "z": -7,
      "name": "Empty"
    },
    {
      "x": -1,
      "y": -1,
      "z": -7,
      "name": "Empty"
    },
    {
      "x": -1,
      "y": 0,
      "z": -7,
      "name": "Empty"
    },
    {
      "x": -1,
      "y": 1,
      "z": -7,
      "name": "Empty"
    },
    {
      "x": -1,
      "y": 2,
      "z": -7,
      "name": "Empty"
    },
    {
      "x": -1,
      "y": 3,
      "z": -7,
      "name": "Empty"
    },
    {
      "x": -1,
      "y": 4,
      "z": -7,
      "name": "Empty"
    },
    {
      "x": -1,
      "y": -5,
      "z": -6,
      "name": "Rock_Stone"
    },
    {
      "x": -1,
      "y": -4,
      "z": -6,
      "name": "Rock_Stone"
    },
    {
      "x": -1,
      "y": -3,
      "z": -6,
      "name": "Rock_Stone"
    },
    {
      "x": -1,
      "y": -2,
      "z": -6,
      "name": "Rock_Stone"
    },
    {
      "x": -1,
      "y": -1,
      "z": -6,
      "name": "Empty"
    },
    {
      "x": -1,
      "y": 0,
      "z": -6,
      "name": "Empty"
    },
    {
      "x": -1,
      "y": 1,
      "z": -6,
      "name": "Empty"
    },
    {
      "x": -1,
      "y": 2,
      "z": -6,
      "name": "Empty"
    },
    {
      "x": -1,
      "y": 3,
      "z": -6,
      "name": "Empty"
    },
    {
      "x": -1,
      "y": 4,
      "z": -6,
      "name": "Empty"
    },
    {
      "x": -1,
      "y": -4,
      "z": -5,
      "name": "Rock_Stone"
    },
    {
      "x": -1,
      "y": -3,
      "z": -5,
      "name": "Rock_Stone"
    },
    {
      "x": -1,
      "y": -2,
      "z": -5,
      "name": "Soil_Gravel"
    },
    {
      "x": -1,
      "y": -1,
      "z": -5,
      "name": "Rock_Stone_Cobble_Half"
    },
    {
      "x": -1,
      "y": 0,
      "z": -5,
      "name": "Empty"
    },
    {
      "x": -1,
      "y": 1,
      "z": -5,
      "name": "Empty"
    },
    {
      "x": -1,
      "y": 2,
      "z": -5,
      "name": "Empty"
    },
    {
      "x": -1,
      "y": 3,
      "z": -5,
      "name": "Empty"
    },
    {
      "x": -1,
      "y": 4,
      "z": -5,
      "name": "Empty"
    },
    {
      "x": -1,
      "y": -4,
      "z": -4,
      "name": "Rock_Stone"
    },
    {
      "x": -1,
      "y": -3,
      "z": -4,
      "name": "Rock_Stone"
    },
    {
      "x": -1,
      "y": -2,
      "z": -4,
      "name": "Rock_Stone"
    },
    {
      "x": -1,
      "y": -1,
      "z": -4,
      "name": "Rock_Stone"
    },
    {
      "x": -1,
      "y": 0,
      "z": -4,
      "name": "Empty"
    },
    {
      "x": -1,
      "y": 1,
      "z": -4,
      "name": "Empty"
    },
    {
      "x": -1,
      "y": 2,
      "z": -4,
      "name": "Empty"
    },
    {
      "x": -1,
      "y": 3,
      "z": -4,
      "name": "Empty"
    },
    {
      "x": -1,
      "y": 4,
      "z": -4,
      "name": "Empty"
    },
    {
      "x": -1,
      "y": -3,
      "z": -3,
      "name": "Rock_Stone"
    },
    {
      "x": -1,
      "y": -2,
      "z": -3,
      "name": "Rock_Stone"
    },
    {
      "x": -1,
      "y": -1,
      "z": -3,
      "name": "Plant_Moss_Block_Blue"
    },
    {
      "x": -1,
      "y": 0,
      "z": -3,
      "name": "Empty"
    },
    {
      "x": -1,
      "y": 1,
      "z": -3,
      "name": "Empty"
    },
    {
      "x": -1,
      "y": 2,
      "z": -3,
      "name": "Empty"
    },
    {
      "x": -1,
      "y": 3,
      "z": -3,
      "name": "Empty"
    },
    {
      "x": -1,
      "y": 4,
      "z": -3,
      "name": "Empty"
    },
    {
      "x": -1,
      "y": -3,
      "z": -2,
      "name": "Rock_Stone"
    },
    {
      "x": -1,
      "y": -2,
      "z": -2,
      "name": "Rock_Stone"
    },
    {
      "x": -1,
      "y": -1,
      "z": -2,
      "name": "Plant_Moss_Block_Blue"
    },
    {
      "x": -1,
      "y": 0,
      "z": -2,
      "name": "Empty"
    },
    {
      "x": -1,
      "y": 1,
      "z": -2,
      "name": "Empty"
    },
    {
      "x": -1,
      "y": 2,
      "z": -2,
      "name": "Empty"
    },
    {
      "x": -1,
      "y": 3,
      "z": -2,
      "name": "Empty"
    },
    {
      "x": -1,
      "y": 4,
      "z": -2,
      "name": "Empty"
    },
    {
      "x": -1,
      "y": -2,
      "z": -1,
      "name": "Rock_Stone"
    },
    {
      "x": -1,
      "y": -1,
      "z": -1,
      "name": "Rock_Stone"
    },
    {
      "x": -1,
      "y": 0,
      "z": -1,
      "name": "Rock_Stone"
    },
    {
      "x": -1,
      "y": 1,
      "z": -1,
      "name": "Empty"
    },
    {
      "x": -1,
      "y": 2,
      "z": -1,
      "name": "Empty"
    },
    {
      "x": -1,
      "y": 3,
      "z": -1,
      "name": "Empty"
    },
    {
      "x": -1,
      "y": 4,
      "z": -1,
      "name": "Rock_Quartzite_Brick"
    },
    {
      "x": -1,
      "y": -2,
      "z": 0,
      "name": "Rock_Stone"
    },
    {
      "x": -1,
      "y": -1,
      "z": 0,
      "name": "Rock_Stone"
    },
    {
      "x": -1,
      "y": 0,
      "z": 0,
      "name": "Rock_Stone"
    },
    {
      "x": -1,
      "y": 1,
      "z": 0,
      "name": "Empty"
    },
    {
      "x": -1,
      "y": 2,
      "z": 0,
      "name": "Empty"
    },
    {
      "x": -1,
      "y": 3,
      "z": 0,
      "name": "Empty"
    },
    {
      "x": -1,
      "y": 4,
      "z": 0,
      "name": "Rock_Quartzite_Brick"
    },
    {
      "x": 0,
      "y": -17,
      "z": -28,
      "name": "Rock_Stone"
    },
    {
      "x": 0,
      "y": -16,
      "z": -28,
      "name": "Rock_Stone"
    },
    {
      "x": 0,
      "y": -15,
      "z": -28,
      "name": "Empty"
    },
    {
      "x": 0,
      "y": -14,
      "z": -28,
      "name": "Empty"
    },
    {
      "x": 0,
      "y": -17,
      "z": -27,
      "name": "Rock_Stone"
    },
    {
      "x": 0,
      "y": -16,
      "z": -27,
      "name": "Rock_Stone"
    },
    {
      "x": 0,
      "y": -15,
      "z": -27,
      "name": "Rock_Stone"
    },
    {
      "x": 0,
      "y": -17,
      "z": -26,
      "name": "Rock_Stone"
    },
    {
      "x": 0,
      "y": -16,
      "z": -26,
      "name": "Rock_Stone"
    },
    {
      "x": 0,
      "y": -15,
      "z": -26,
      "name": "Rock_Stone"
    },
    {
      "x": 0,
      "y": -17,
      "z": -25,
      "name": "Rock_Stone"
    },
    {
      "x": 0,
      "y": -16,
      "z": -25,
      "name": "Rock_Stone"
    },
    {
      "x": 0,
      "y": -15,
      "z": -25,
      "name": "Empty"
    },
    {
      "x": 0,
      "y": -17,
      "z": -24,
      "name": "Rock_Stone"
    },
    {
      "x": 0,
      "y": -16,
      "z": -24,
      "name": "Rock_Stone"
    },
    {
      "x": 0,
      "y": -15,
      "z": -24,
      "name": "Rock_Stone_Stalactite_Small"
    },
    {
      "x": 0,
      "y": -14,
      "z": -24,
      "name": "Empty"
    },
    {
      "x": 0,
      "y": -13,
      "z": -24,
      "name": "Empty"
    },
    {
      "x": 0,
      "y": -17,
      "z": -23,
      "name": "Rock_Stone"
    },
    {
      "x": 0,
      "y": -16,
      "z": -23,
      "name": "Soil_Gravel"
    },
    {
      "x": 0,
      "y": -15,
      "z": -23,
      "name": "Empty"
    },
    {
      "x": 0,
      "y": -14,
      "z": -23,
      "name": "Empty"
    },
    {
      "x": 0,
      "y": -17,
      "z": -22,
      "name": "Rock_Stone"
    },
    {
      "x": 0,
      "y": -16,
      "z": -22,
      "name": "Soil_Gravel"
    },
    {
      "x": 0,
      "y": -15,
      "z": -22,
      "name": "Empty"
    },
    {
      "x": 0,
      "y": -17,
      "z": -21,
      "name": "Rock_Stone"
    },
    {
      "x": 0,
      "y": -16,
      "z": -21,
      "name": "Soil_Gravel"
    },
    {
      "x": 0,
      "y": -15,
      "z": -21,
      "name": "Rock_Stone"
    },
    {
      "x": 0,
      "y": -14,
      "z": -21,
      "name": "Rock_Stone"
    },
    {
      "x": 0,
      "y": -16,
      "z": -20,
      "name": "Rock_Stone"
    },
    {
      "x": 0,
      "y": -15,
      "z": -20,
      "name": "Rock_Stone"
    },
    {
      "x": 0,
      "y": -14,
      "z": -20,
      "name": "Rock_Stone"
    },
    {
      "x": 0,
      "y": -13,
      "z": -20,
      "name": "Rock_Stone"
    },
    {
      "x": 0,
      "y": -7,
      "z": -20,
      "name": "Empty"
    },
    {
      "x": 0,
      "y": -16,
      "z": -19,
      "name": "Rock_Stone"
    },
    {
      "x": 0,
      "y": -15,
      "z": -19,
      "name": "Rock_Stone"
    },
    {
      "x": 0,
      "y": -14,
      "z": -19,
      "name": "Rock_Stone"
    },
    {
      "x": 0,
      "y": -13,
      "z": -19,
      "name": "Rock_Stone"
    },
    {
      "x": 0,
      "y": -12,
      "z": -19,
      "name": "Rock_Stone"
    },
    {
      "x": 0,
      "y": -8,
      "z": -19,
      "name": "Empty"
    },
    {
      "x": 0,
      "y": -7,
      "z": -19,
      "name": "Empty"
    },
    {
      "x": 0,
      "y": -6,
      "z": -19,
      "name": "Empty"
    },
    {
      "x": 0,
      "y": -5,
      "z": -19,
      "name": "Empty"
    },
    {
      "x": 0,
      "y": -16,
      "z": -18,
      "name": "Rock_Stone"
    },
    {
      "x": 0,
      "y": -15,
      "z": -18,
      "name": "Rock_Stone"
    },
    {
      "x": 0,
      "y": -14,
      "z": -18,
      "name": "Rock_Stone"
    },
    {
      "x": 0,
      "y": -13,
      "z": -18,
      "name": "Rock_Stone"
    },
    {
      "x": 0,
      "y": -10,
      "z": -18,
      "name": "Rock_Stone"
    },
    {
      "x": 0,
      "y": -9,
      "z": -18,
      "name": "Rock_Stone"
    },
    {
      "x": 0,
      "y": -8,
      "z": -18,
      "name": "Empty"
    },
    {
      "x": 0,
      "y": -7,
      "z": -18,
      "name": "Empty"
    },
    {
      "x": 0,
      "y": -6,
      "z": -18,
      "name": "Empty"
    },
    {
      "x": 0,
      "y": -5,
      "z": -18,
      "name": "Empty"
    },
    {
      "x": 0,
      "y": -16,
      "z": -17,
      "name": "Rock_Stone"
    },
    {
      "x": 0,
      "y": -15,
      "z": -17,
      "name": "Rock_Stone"
    },
    {
      "x": 0,
      "y": -14,
      "z": -17,
      "name": "Rock_Stone"
    },
    {
      "x": 0,
      "y": -11,
      "z": -17,
      "name": "Rock_Stone"
    },
    {
      "x": 0,
      "y": -10,
      "z": -17,
      "name": "Rock_Stone"
    },
    {
      "x": 0,
      "y": -9,
      "z": -17,
      "name": "Rock_Stone"
    },
    {
      "x": 0,
      "y": -8,
      "z": -17,
      "name": "Rock_Stone_Cobble_Half"
    },
    {
      "x": 0,
      "y": -7,
      "z": -17,
      "name": "Empty"
    },
    {
      "x": 0,
      "y": -6,
      "z": -17,
      "name": "Empty"
    },
    {
      "x": 0,
      "y": -5,
      "z": -17,
      "name": "Empty"
    },
    {
      "x": 0,
      "y": -4,
      "z": -17,
      "name": "Empty"
    },
    {
      "x": 0,
      "y": -10,
      "z": -16,
      "name": "Rock_Stone"
    },
    {
      "x": 0,
      "y": -9,
      "z": -16,
      "name": "Rock_Stone"
    },
    {
      "x": 0,
      "y": -8,
      "z": -16,
      "name": "Rock_Stone_Cobble_Half"
    },
    {
      "x": 0,
      "y": -7,
      "z": -16,
      "name": "Empty"
    },
    {
      "x": 0,
      "y": -6,
      "z": -16,
      "name": "Empty"
    },
    {
      "x": 0,
      "y": -5,
      "z": -16,
      "name": "Empty"
    },
    {
      "x": 0,
      "y": -4,
      "z": -16,
      "name": "Empty"
    },
    {
      "x": 0,
      "y": -10,
      "z": -15,
      "name": "Rock_Stone"
    },
    {
      "x": 0,
      "y": -9,
      "z": -15,
      "name": "Rock_Stone"
    },
    {
      "x": 0,
      "y": -8,
      "z": -15,
      "name": "Rock_Stone"
    },
    {
      "x": 0,
      "y": -7,
      "z": -15,
      "name": "Empty"
    },
    {
      "x": 0,
      "y": -6,
      "z": -15,
      "name": "Empty"
    },
    {
      "x": 0,
      "y": -5,
      "z": -15,
      "name": "Empty"
    },
    {
      "x": 0,
      "y": -4,
      "z": -15,
      "name": "Empty"
    },
    {
      "x": 0,
      "y": -3,
      "z": -15,
      "name": "Empty"
    },
    {
      "x": 0,
      "y": -9,
      "z": -14,
      "name": "Rock_Stone"
    },
    {
      "x": 0,
      "y": -8,
      "z": -14,
      "name": "Rock_Stone"
    },
    {
      "x": 0,
      "y": -7,
      "z": -14,
      "name": "Empty"
    },
    {
      "x": 0,
      "y": -6,
      "z": -14,
      "name": "Empty"
    },
    {
      "x": 0,
      "y": -5,
      "z": -14,
      "name": "Empty"
    },
    {
      "x": 0,
      "y": -4,
      "z": -14,
      "name": "Empty"
    },
    {
      "x": 0,
      "y": -3,
      "z": -14,
      "name": "Empty"
    },
    {
      "x": 0,
      "y": -9,
      "z": -13,
      "name": "Rock_Stone"
    },
    {
      "x": 0,
      "y": -8,
      "z": -13,
      "name": "Rock_Stone"
    },
    {
      "x": 0,
      "y": -7,
      "z": -13,
      "name": "Rock_Stone"
    },
    {
      "x": 0,
      "y": -6,
      "z": -13,
      "name": "Rock_Stone"
    },
    {
      "x": 0,
      "y": -5,
      "z": -13,
      "name": "Empty"
    },
    {
      "x": 0,
      "y": -4,
      "z": -13,
      "name": "Empty"
    },
    {
      "x": 0,
      "y": -3,
      "z": -13,
      "name": "Empty"
    },
    {
      "x": 0,
      "y": -9,
      "z": -12,
      "name": "Rock_Stone"
    },
    {
      "x": 0,
      "y": -8,
      "z": -12,
      "name": "Rock_Stone"
    },
    {
      "x": 0,
      "y": -7,
      "z": -12,
      "name": "Rock_Stone"
    },
    {
      "x": 0,
      "y": -6,
      "z": -12,
      "name": "Rock_Stone"
    },
    {
      "x": 0,
      "y": -5,
      "z": -12,
      "name": "Rock_Stone"
    },
    {
      "x": 0,
      "y": -4,
      "z": -12,
      "name": "Rock_Stone"
    },
    {
      "x": 0,
      "y": -3,
      "z": -12,
      "name": "Empty"
    },
    {
      "x": 0,
      "y": -8,
      "z": -11,
      "name": "Rock_Stone"
    },
    {
      "x": 0,
      "y": -7,
      "z": -11,
      "name": "Rock_Stone"
    },
    {
      "x": 0,
      "y": -6,
      "z": -11,
      "name": "Rock_Stone"
    },
    {
      "x": 0,
      "y": -5,
      "z": -11,
      "name": "Rock_Stone"
    },
    {
      "x": 0,
      "y": -4,
      "z": -11,
      "name": "Rock_Stone"
    },
    {
      "x": 0,
      "y": -3,
      "z": -11,
      "name": "Rock_Stone"
    },
    {
      "x": 0,
      "y": 0,
      "z": -11,
      "name": "Plant_Moss_Block_Blue"
    },
    {
      "x": 0,
      "y": 1,
      "z": -11,
      "name": "Plant_Moss_Rug_Blue"
    },
    {
      "x": 0,
      "y": 2,
      "z": -11,
      "name": "Empty"
    },
    {
      "x": 0,
      "y": -8,
      "z": -10,
      "name": "Rock_Stone"
    },
    {
      "x": 0,
      "y": -7,
      "z": -10,
      "name": "Rock_Stone"
    },
    {
      "x": 0,
      "y": -6,
      "z": -10,
      "name": "Rock_Stone"
    },
    {
      "x": 0,
      "y": -5,
      "z": -10,
      "name": "Rock_Stone"
    },
    {
      "x": 0,
      "y": -4,
      "z": -10,
      "name": "Rock_Stone"
    },
    {
      "x": 0,
      "y": -3,
      "z": -10,
      "name": "Plant_Moss_Block_Blue"
    },
    {
      "x": 0,
      "y": -2,
      "z": -10,
      "name": "Plant_Moss_Rug_Blue"
    },
    {
      "x": 0,
      "y": -1,
      "z": -10,
      "name": "Empty"
    },
    {
      "x": 0,
      "y": 0,
      "z": -10,
      "name": "Empty"
    },
    {
      "x": 0,
      "y": 1,
      "z": -10,
      "name": "Empty"
    },
    {
      "x": 0,
      "y": 2,
      "z": -10,
      "name": "Empty"
    },
    {
      "x": 0,
      "y": -6,
      "z": -9,
      "name": "Rock_Stone"
    },
    {
      "x": 0,
      "y": -5,
      "z": -9,
      "name": "Rock_Stone"
    },
    {
      "x": 0,
      "y": -4,
      "z": -9,
      "name": "Rock_Stone"
    },
    {
      "x": 0,
      "y": -3,
      "z": -9,
      "name": "Plant_Moss_Block_Blue"
    },
    {
      "x": 0,
      "y": -2,
      "z": -9,
      "name": "Empty"
    },
    {
      "x": 0,
      "y": -1,
      "z": -9,
      "name": "Empty"
    },
    {
      "x": 0,
      "y": 0,
      "z": -9,
      "name": "Empty"
    },
    {
      "x": 0,
      "y": 1,
      "z": -9,
      "name": "Empty"
    },
    {
      "x": 0,
      "y": 2,
      "z": -9,
      "name": "Empty"
    },
    {
      "x": 0,
      "y": 3,
      "z": -9,
      "name": "Empty"
    },
    {
      "x": 0,
      "y": -5,
      "z": -8,
      "name": "Rock_Stone"
    },
    {
      "x": 0,
      "y": -4,
      "z": -8,
      "name": "Rock_Stone"
    },
    {
      "x": 0,
      "y": -3,
      "z": -8,
      "name": "Rock_Stone"
    },
    {
      "x": 0,
      "y": -2,
      "z": -8,
      "name": "Empty"
    },
    {
      "x": 0,
      "y": -1,
      "z": -8,
      "name": "Empty"
    },
    {
      "x": 0,
      "y": 0,
      "z": -8,
      "name": "Empty"
    },
    {
      "x": 0,
      "y": 1,
      "z": -8,
      "name": "Empty"
    },
    {
      "x": 0,
      "y": 2,
      "z": -8,
      "name": "Empty"
    },
    {
      "x": 0,
      "y": 3,
      "z": -8,
      "name": "Empty"
    },
    {
      "x": 0,
      "y": 4,
      "z": -8,
      "name": "Empty"
    },
    {
      "x": 0,
      "y": -5,
      "z": -7,
      "name": "Rock_Stone"
    },
    {
      "x": 0,
      "y": -4,
      "z": -7,
      "name": "Rock_Stone"
    },
    {
      "x": 0,
      "y": -3,
      "z": -7,
      "name": "Rock_Stone"
    },
    {
      "x": 0,
      "y": -2,
      "z": -7,
      "name": "Rock_Stone"
    },
    {
      "x": 0,
      "y": -1,
      "z": -7,
      "name": "Empty"
    },
    {
      "x": 0,
      "y": 0,
      "z": -7,
      "name": "Empty"
    },
    {
      "x": 0,
      "y": 1,
      "z": -7,
      "name": "Empty"
    },
    {
      "x": 0,
      "y": 2,
      "z": -7,
      "name": "Empty"
    },
    {
      "x": 0,
      "y": 3,
      "z": -7,
      "name": "Empty"
    },
    {
      "x": 0,
      "y": 4,
      "z": -7,
      "name": "Empty"
    },
    {
      "x": 0,
      "y": -4,
      "z": -6,
      "name": "Rock_Stone"
    },
    {
      "x": 0,
      "y": -3,
      "z": -6,
      "name": "Rock_Stone"
    },
    {
      "x": 0,
      "y": -2,
      "z": -6,
      "name": "Soil_Gravel"
    },
    {
      "x": 0,
      "y": -1,
      "z": -6,
      "name": "Rock_Stone_Cobble_Half"
    },
    {
      "x": 0,
      "y": 0,
      "z": -6,
      "name": "Empty"
    },
    {
      "x": 0,
      "y": 1,
      "z": -6,
      "name": "Empty"
    },
    {
      "x": 0,
      "y": 2,
      "z": -6,
      "name": "Empty"
    },
    {
      "x": 0,
      "y": 3,
      "z": -6,
      "name": "Empty"
    },
    {
      "x": 0,
      "y": 4,
      "z": -6,
      "name": "Empty"
    },
    {
      "x": 0,
      "y": 5,
      "z": -6,
      "name": "Empty"
    },
    {
      "x": 0,
      "y": -4,
      "z": -5,
      "name": "Rock_Stone"
    },
    {
      "x": 0,
      "y": -3,
      "z": -5,
      "name": "Rock_Stone"
    },
    {
      "x": 0,
      "y": -2,
      "z": -5,
      "name": "Soil_Gravel"
    },
    {
      "x": 0,
      "y": -1,
      "z": -5,
      "name": "Rock_Stone_Cobble_Half"
    },
    {
      "x": 0,
      "y": 0,
      "z": -5,
      "name": "Empty"
    },
    {
      "x": 0,
      "y": 1,
      "z": -5,
      "name": "Empty"
    },
    {
      "x": 0,
      "y": 2,
      "z": -5,
      "name": "Empty"
    },
    {
      "x": 0,
      "y": 3,
      "z": -5,
      "name": "Empty"
    },
    {
      "x": 0,
      "y": 4,
      "z": -5,
      "name": "Empty"
    },
    {
      "x": 0,
      "y": 5,
      "z": -5,
      "name": "Empty"
    },
    {
      "x": 0,
      "y": -4,
      "z": -4,
      "name": "Rock_Stone"
    },
    {
      "x": 0,
      "y": -3,
      "z": -4,
      "name": "Rock_Stone"
    },
    {
      "x": 0,
      "y": -2,
      "z": -4,
      "name": "Rock_Stone"
    },
    {
      "x": 0,
      "y": -1,
      "z": -4,
      "name": "Rock_Stone"
    },
    {
      "x": 0,
      "y": 0,
      "z": -4,
      "name": "Empty"
    },
    {
      "x": 0,
      "y": 1,
      "z": -4,
      "name": "Empty"
    },
    {
      "x": 0,
      "y": 2,
      "z": -4,
      "name": "Empty"
    },
    {
      "x": 0,
      "y": 3,
      "z": -4,
      "name": "Empty"
    },
    {
      "x": 0,
      "y": 4,
      "z": -4,
      "name": "Empty"
    },
    {
      "x": 0,
      "y": 5,
      "z": -4,
      "name": "Empty"
    },
    {
      "x": 0,
      "y": -3,
      "z": -3,
      "name": "Rock_Stone"
    },
    {
      "x": 0,
      "y": -2,
      "z": -3,
      "name": "Rock_Stone"
    },
    {
      "x": 0,
      "y": -1,
      "z": -3,
      "name": "Rock_Stone"
    },
    {
      "x": 0,
      "y": 0,
      "z": -3,
      "name": "Empty"
    },
    {
      "x": 0,
      "y": 1,
      "z": -3,
      "name": "Empty"
    },
    {
      "x": 0,
      "y": 2,
      "z": -3,
      "name": "Empty"
    },
    {
      "x": 0,
      "y": 3,
      "z": -3,
      "name": "Empty"
    },
    {
      "x": 0,
      "y": 4,
      "z": -3,
      "name": "Empty"
    },
    {
      "x": 0,
      "y": -3,
      "z": -2,
      "name": "Rock_Stone"
    },
    {
      "x": 0,
      "y": -2,
      "z": -2,
      "name": "Rock_Stone"
    },
    {
      "x": 0,
      "y": -1,
      "z": -2,
      "name": "Rock_Stone"
    },
    {
      "x": 0,
      "y": 0,
      "z": -2,
      "name": "Rock_Stone"
    },
    {
      "x": 0,
      "y": 1,
      "z": -2,
      "name": "Empty"
    },
    {
      "x": 0,
      "y": 2,
      "z": -2,
      "name": "Empty"
    },
    {
      "x": 0,
      "y": 3,
      "z": -2,
      "name": "Empty"
    },
    {
      "x": 0,
      "y": 4,
      "z": -2,
      "name": "Empty"
    },
    {
      "x": 0,
      "y": -2,
      "z": -1,
      "name": "Rock_Stone"
    },
    {
      "x": 0,
      "y": -1,
      "z": -1,
      "name": "Rock_Stone"
    },
    {
      "x": 0,
      "y": 0,
      "z": -1,
      "name": "Rock_Stone"
    },
    {
      "x": 0,
      "y": 1,
      "z": -1,
      "name": "Empty"
    },
    {
      "x": 0,
      "y": 2,
      "z": -1,
      "name": "Empty"
    },
    {
      "x": 0,
      "y": 3,
      "z": -1,
      "name": "Empty"
    },
    {
      "x": 0,
      "y": 4,
      "z": -1,
      "name": "Rock_Quartzite_Brick"
    },
    {
      "x": 0,
      "y": -2,
      "z": 0,
      "name": "Rock_Stone"
    },
    {
      "x": 0,
      "y": -1,
      "z": 0,
      "name": "Rock_Stone"
    },
    {
      "x": 0,
      "y": 0,
      "z": 0,
      "name": "Rock_Stone"
    },
    {
      "x": 0,
      "y": 1,
      "z": 0,
      "name": "Empty"
    },
    {
      "x": 0,
      "y": 2,
      "z": 0,
      "name": "Empty"
    },
    {
      "x": 0,
      "y": 3,
      "z": 0,
      "name": "Empty"
    },
    {
      "x": 0,
      "y": 4,
      "z": 0,
      "name": "Rock_Quartzite_Brick"
    },
    {
      "x": 1,
      "y": -17,
      "z": -28,
      "name": "Rock_Stone"
    },
    {
      "x": 1,
      "y": -16,
      "z": -28,
      "name": "Empty"
    },
    {
      "x": 1,
      "y": -15,
      "z": -28,
      "name": "Empty"
    },
    {
      "x": 1,
      "y": -14,
      "z": -28,
      "name": "Empty"
    },
    {
      "x": 1,
      "y": -13,
      "z": -28,
      "name": "Empty"
    },
    {
      "x": 1,
      "y": -18,
      "z": -27,
      "name": "Rock_Stone"
    },
    {
      "x": 1,
      "y": -17,
      "z": -27,
      "name": "Rock_Stone"
    },
    {
      "x": 1,
      "y": -16,
      "z": -27,
      "name": "Empty"
    },
    {
      "x": 1,
      "y": -15,
      "z": -27,
      "name": "Empty"
    },
    {
      "x": 1,
      "y": -14,
      "z": -27,
      "name": "Empty"
    },
    {
      "x": 1,
      "y": -18,
      "z": -26,
      "name": "Rock_Stone"
    },
    {
      "x": 1,
      "y": -17,
      "z": -26,
      "name": "Rock_Stone"
    },
    {
      "x": 1,
      "y": -16,
      "z": -26,
      "name": "Rock_Stone"
    },
    {
      "x": 1,
      "y": -15,
      "z": -26,
      "name": "Empty"
    },
    {
      "x": 1,
      "y": -14,
      "z": -26,
      "name": "Empty"
    },
    {
      "x": 1,
      "y": -13,
      "z": -26,
      "name": "Empty"
    },
    {
      "x": 1,
      "y": -18,
      "z": -25,
      "name": "Rock_Stone"
    },
    {
      "x": 1,
      "y": -17,
      "z": -25,
      "name": "Rock_Stone"
    },
    {
      "x": 1,
      "y": -16,
      "z": -25,
      "name": "Rock_Stone"
    },
    {
      "x": 1,
      "y": -15,
      "z": -25,
      "name": "Empty"
    },
    {
      "x": 1,
      "y": -14,
      "z": -25,
      "name": "Empty"
    },
    {
      "x": 1,
      "y": -13,
      "z": -25,
      "name": "Empty"
    },
    {
      "x": 1,
      "y": -17,
      "z": -24,
      "name": "Rock_Stone"
    },
    {
      "x": 1,
      "y": -16,
      "z": -24,
      "name": "Rock_Stone"
    },
    {
      "x": 1,
      "y": -15,
      "z": -24,
      "name": "Empty"
    },
    {
      "x": 1,
      "y": -14,
      "z": -24,
      "name": "Empty"
    },
    {
      "x": 1,
      "y": -13,
      "z": -24,
      "name": "Empty"
    },
    {
      "x": 1,
      "y": -17,
      "z": -23,
      "name": "Rock_Stone"
    },
    {
      "x": 1,
      "y": -16,
      "z": -23,
      "name": "Soil_Gravel"
    },
    {
      "x": 1,
      "y": -15,
      "z": -23,
      "name": "Empty"
    },
    {
      "x": 1,
      "y": -14,
      "z": -23,
      "name": "Empty"
    },
    {
      "x": 1,
      "y": -13,
      "z": -23,
      "name": "Empty"
    },
    {
      "x": 1,
      "y": -17,
      "z": -22,
      "name": "Rock_Stone"
    },
    {
      "x": 1,
      "y": -16,
      "z": -22,
      "name": "Soil_Gravel"
    },
    {
      "x": 1,
      "y": -15,
      "z": -22,
      "name": "Empty"
    },
    {
      "x": 1,
      "y": -14,
      "z": -22,
      "name": "Empty"
    },
    {
      "x": 1,
      "y": -13,
      "z": -22,
      "name": "Empty"
    },
    {
      "x": 1,
      "y": -17,
      "z": -21,
      "name": "Rock_Stone"
    },
    {
      "x": 1,
      "y": -16,
      "z": -21,
      "name": "Soil_Gravel"
    },
    {
      "x": 1,
      "y": -15,
      "z": -21,
      "name": "Empty"
    },
    {
      "x": 1,
      "y": -14,
      "z": -21,
      "name": "Empty"
    },
    {
      "x": 1,
      "y": -13,
      "z": -21,
      "name": "Empty"
    },
    {
      "x": 1,
      "y": -12,
      "z": -21,
      "name": "Empty"
    },
    {
      "x": 1,
      "y": -17,
      "z": -20,
      "name": "Rock_Stone"
    },
    {
      "x": 1,
      "y": -16,
      "z": -20,
      "name": "Rock_Stone"
    },
    {
      "x": 1,
      "y": -15,
      "z": -20,
      "name": "Empty"
    },
    {
      "x": 1,
      "y": -14,
      "z": -20,
      "name": "Empty"
    },
    {
      "x": 1,
      "y": -13,
      "z": -20,
      "name": "Empty"
    },
    {
      "x": 1,
      "y": -12,
      "z": -20,
      "name": "Rock_Stone"
    },
    {
      "x": 1,
      "y": -8,
      "z": -20,
      "name": "Empty"
    },
    {
      "x": 1,
      "y": -7,
      "z": -20,
      "name": "Empty"
    },
    {
      "x": 1,
      "y": -6,
      "z": -20,
      "name": "Empty"
    },
    {
      "x": 1,
      "y": -17,
      "z": -19,
      "name": "Rock_Stone"
    },
    {
      "x": 1,
      "y": -16,
      "z": -19,
      "name": "Rock_Stone"
    },
    {
      "x": 1,
      "y": -15,
      "z": -19,
      "name": "Rock_Stone"
    },
    {
      "x": 1,
      "y": -14,
      "z": -19,
      "name": "Rock_Stone"
    },
    {
      "x": 1,
      "y": -13,
      "z": -19,
      "name": "Rock_Stone"
    },
    {
      "x": 1,
      "y": -12,
      "z": -19,
      "name": "Rock_Stone"
    },
    {
      "x": 1,
      "y": -11,
      "z": -19,
      "name": "Rock_Stone"
    },
    {
      "x": 1,
      "y": -10,
      "z": -19,
      "name": "Rock_Stone"
    },
    {
      "x": 1,
      "y": -9,
      "z": -19,
      "name": "Rock_Stone"
    },
    {
      "x": 1,
      "y": -8,
      "z": -19,
      "name": "Empty"
    },
    {
      "x": 1,
      "y": -7,
      "z": -19,
      "name": "Empty"
    },
    {
      "x": 1,
      "y": -6,
      "z": -19,
      "name": "Empty"
    },
    {
      "x": 1,
      "y": -5,
      "z": -19,
      "name": "Empty"
    },
    {
      "x": 1,
      "y": -17,
      "z": -18,
      "name": "Rock_Stone"
    },
    {
      "x": 1,
      "y": -16,
      "z": -18,
      "name": "Rock_Stone"
    },
    {
      "x": 1,
      "y": -15,
      "z": -18,
      "name": "Rock_Stone"
    },
    {
      "x": 1,
      "y": -14,
      "z": -18,
      "name": "Rock_Stone"
    },
    {
      "x": 1,
      "y": -13,
      "z": -18,
      "name": "Rock_Stone"
    },
    {
      "x": 1,
      "y": -12,
      "z": -18,
      "name": "Rock_Stone"
    },
    {
      "x": 1,
      "y": -11,
      "z": -18,
      "name": "Rock_Stone"
    },
    {
      "x": 1,
      "y": -10,
      "z": -18,
      "name": "Rock_Stone"
    },
    {
      "x": 1,
      "y": -9,
      "z": -18,
      "name": "Rock_Stone"
    },
    {
      "x": 1,
      "y": -8,
      "z": -18,
      "name": "Empty"
    },
    {
      "x": 1,
      "y": -7,
      "z": -18,
      "name": "Empty"
    },
    {
      "x": 1,
      "y": -6,
      "z": -18,
      "name": "Empty"
    },
    {
      "x": 1,
      "y": -5,
      "z": -18,
      "name": "Empty"
    },
    {
      "x": 1,
      "y": -16,
      "z": -17,
      "name": "Rock_Stone"
    },
    {
      "x": 1,
      "y": -15,
      "z": -17,
      "name": "Rock_Stone"
    },
    {
      "x": 1,
      "y": -14,
      "z": -17,
      "name": "Rock_Stone"
    },
    {
      "x": 1,
      "y": -13,
      "z": -17,
      "name": "Rock_Stone"
    },
    {
      "x": 1,
      "y": -12,
      "z": -17,
      "name": "Rock_Stone"
    },
    {
      "x": 1,
      "y": -11,
      "z": -17,
      "name": "Rock_Stone"
    },
    {
      "x": 1,
      "y": -10,
      "z": -17,
      "name": "Rock_Stone"
    },
    {
      "x": 1,
      "y": -9,
      "z": -17,
      "name": "Rock_Stone"
    },
    {
      "x": 1,
      "y": -8,
      "z": -17,
      "name": "Empty"
    },
    {
      "x": 1,
      "y": -7,
      "z": -17,
      "name": "Empty"
    },
    {
      "x": 1,
      "y": -6,
      "z": -17,
      "name": "Empty"
    },
    {
      "x": 1,
      "y": -5,
      "z": -17,
      "name": "Empty"
    },
    {
      "x": 1,
      "y": -15,
      "z": -16,
      "name": "Rock_Stone"
    },
    {
      "x": 1,
      "y": -11,
      "z": -16,
      "name": "Rock_Stone"
    },
    {
      "x": 1,
      "y": -10,
      "z": -16,
      "name": "Rock_Stone"
    },
    {
      "x": 1,
      "y": -9,
      "z": -16,
      "name": "Soil_Gravel"
    },
    {
      "x": 1,
      "y": -8,
      "z": -16,
      "name": "Rock_Stone_Cobble_Half"
    },
    {
      "x": 1,
      "y": -7,
      "z": -16,
      "name": "Empty"
    },
    {
      "x": 1,
      "y": -6,
      "z": -16,
      "name": "Empty"
    },
    {
      "x": 1,
      "y": -5,
      "z": -16,
      "name": "Empty"
    },
    {
      "x": 1,
      "y": -4,
      "z": -16,
      "name": "Empty"
    },
    {
      "x": 1,
      "y": -11,
      "z": -15,
      "name": "Rock_Stone"
    },
    {
      "x": 1,
      "y": -10,
      "z": -15,
      "name": "Rock_Stone"
    },
    {
      "x": 1,
      "y": -9,
      "z": -15,
      "name": "Rock_Stone"
    },
    {
      "x": 1,
      "y": -8,
      "z": -15,
      "name": "Rock_Stone_Cobble_Half"
    },
    {
      "x": 1,
      "y": -7,
      "z": -15,
      "name": "Empty"
    },
    {
      "x": 1,
      "y": -6,
      "z": -15,
      "name": "Empty"
    },
    {
      "x": 1,
      "y": -5,
      "z": -15,
      "name": "Empty"
    },
    {
      "x": 1,
      "y": -4,
      "z": -15,
      "name": "Empty"
    },
    {
      "x": 1,
      "y": -3,
      "z": -15,
      "name": "Empty"
    },
    {
      "x": 1,
      "y": -9,
      "z": -14,
      "name": "Rock_Stone"
    },
    {
      "x": 1,
      "y": -8,
      "z": -14,
      "name": "Rock_Stone"
    },
    {
      "x": 1,
      "y": -7,
      "z": -14,
      "name": "Empty"
    },
    {
      "x": 1,
      "y": -6,
      "z": -14,
      "name": "Empty"
    },
    {
      "x": 1,
      "y": -5,
      "z": -14,
      "name": "Empty"
    },
    {
      "x": 1,
      "y": -4,
      "z": -14,
      "name": "Empty"
    },
    {
      "x": 1,
      "y": -9,
      "z": -13,
      "name": "Rock_Stone"
    },
    {
      "x": 1,
      "y": -8,
      "z": -13,
      "name": "Rock_Stone"
    },
    {
      "x": 1,
      "y": -7,
      "z": -13,
      "name": "Rock_Stone"
    },
    {
      "x": 1,
      "y": -8,
      "z": -12,
      "name": "Rock_Stone"
    },
    {
      "x": 1,
      "y": -7,
      "z": -12,
      "name": "Rock_Stone"
    },
    {
      "x": 1,
      "y": -6,
      "z": -12,
      "name": "Rock_Stone"
    },
    {
      "x": 1,
      "y": -7,
      "z": -11,
      "name": "Rock_Stone"
    },
    {
      "x": 1,
      "y": -6,
      "z": -11,
      "name": "Rock_Stone"
    },
    {
      "x": 1,
      "y": -5,
      "z": -11,
      "name": "Rock_Stone"
    },
    {
      "x": 1,
      "y": -4,
      "z": -11,
      "name": "Rock_Stone"
    },
    {
      "x": 1,
      "y": -3,
      "z": -11,
      "name": "Rock_Stone"
    },
    {
      "x": 1,
      "y": -2,
      "z": -11,
      "name": "Rock_Stone"
    },
    {
      "x": 1,
      "y": -6,
      "z": -10,
      "name": "Rock_Stone"
    },
    {
      "x": 1,
      "y": -5,
      "z": -10,
      "name": "Rock_Stone"
    },
    {
      "x": 1,
      "y": -4,
      "z": -10,
      "name": "Rock_Stone"
    },
    {
      "x": 1,
      "y": -3,
      "z": -10,
      "name": "Rock_Stone"
    },
    {
      "x": 1,
      "y": -2,
      "z": -10,
      "name": "Rock_Stone"
    },
    {
      "x": 1,
      "y": 0,
      "z": -10,
      "name": "Plant_Moss_Block_Blue"
    },
    {
      "x": 1,
      "y": 1,
      "z": -10,
      "name": "Plant_Moss_Rug_Blue"
    },
    {
      "x": 1,
      "y": 2,
      "z": -10,
      "name": "Empty"
    },
    {
      "x": 1,
      "y": -5,
      "z": -9,
      "name": "Rock_Stone"
    },
    {
      "x": 1,
      "y": -4,
      "z": -9,
      "name": "Rock_Stone"
    },
    {
      "x": 1,
      "y": -3,
      "z": -9,
      "name": "Rock_Stone"
    },
    {
      "x": 1,
      "y": -2,
      "z": -9,
      "name": "Rock_Stone"
    },
    {
      "x": 1,
      "y": -1,
      "z": -9,
      "name": "Plant_Moss_Rug_Blue"
    },
    {
      "x": 1,
      "y": 0,
      "z": -9,
      "name": "Empty"
    },
    {
      "x": 1,
      "y": 1,
      "z": -9,
      "name": "Empty"
    },
    {
      "x": 1,
      "y": 2,
      "z": -9,
      "name": "Empty"
    },
    {
      "x": 1,
      "y": 3,
      "z": -9,
      "name": "Empty"
    },
    {
      "x": 1,
      "y": -5,
      "z": -8,
      "name": "Rock_Stone"
    },
    {
      "x": 1,
      "y": -4,
      "z": -8,
      "name": "Rock_Stone"
    },
    {
      "x": 1,
      "y": -3,
      "z": -8,
      "name": "Plant_Moss_Block_Blue"
    },
    {
      "x": 1,
      "y": -2,
      "z": -8,
      "name": "Empty"
    },
    {
      "x": 1,
      "y": -1,
      "z": -8,
      "name": "Empty"
    },
    {
      "x": 1,
      "y": 0,
      "z": -8,
      "name": "Empty"
    },
    {
      "x": 1,
      "y": 1,
      "z": -8,
      "name": "Empty"
    },
    {
      "x": 1,
      "y": 2,
      "z": -8,
      "name": "Empty"
    },
    {
      "x": 1,
      "y": 3,
      "z": -8,
      "name": "Empty"
    },
    {
      "x": 1,
      "y": 4,
      "z": -8,
      "name": "Empty"
    },
    {
      "x": 1,
      "y": -5,
      "z": -7,
      "name": "Rock_Stone"
    },
    {
      "x": 1,
      "y": -4,
      "z": -7,
      "name": "Rock_Stone"
    },
    {
      "x": 1,
      "y": -3,
      "z": -7,
      "name": "Rock_Stone"
    },
    {
      "x": 1,
      "y": -2,
      "z": -7,
      "name": "Rock_Stone"
    },
    {
      "x": 1,
      "y": -1,
      "z": -7,
      "name": "Empty"
    },
    {
      "x": 1,
      "y": 0,
      "z": -7,
      "name": "Empty"
    },
    {
      "x": 1,
      "y": 1,
      "z": -7,
      "name": "Empty"
    },
    {
      "x": 1,
      "y": 2,
      "z": -7,
      "name": "Empty"
    },
    {
      "x": 1,
      "y": 3,
      "z": -7,
      "name": "Empty"
    },
    {
      "x": 1,
      "y": 4,
      "z": -7,
      "name": "Empty"
    },
    {
      "x": 1,
      "y": -4,
      "z": -6,
      "name": "Rock_Stone"
    },
    {
      "x": 1,
      "y": -3,
      "z": -6,
      "name": "Rock_Stone"
    },
    {
      "x": 1,
      "y": -2,
      "z": -6,
      "name": "Rock_Stone_Cobble"
    },
    {
      "x": 1,
      "y": -1,
      "z": -6,
      "name": "Rock_Stone_Cobble_Half"
    },
    {
      "x": 1,
      "y": 0,
      "z": -6,
      "name": "Empty"
    },
    {
