{
  "version": 8,
  "blockIdVersion": 8,
  "anchorX": -2,
  "anchorY": 7,
  "anchorZ": 1,
  "blocks": [
    {
      "x": -6,
      "y": 7,
      "z": 2,
      "name": "Rock_Quartzite"
    },
    {
      "x": -6,
      "y": 8,
      "z": 2,
      "name": "Rock_Quartzite"
    },
    {
      "x": -6,
      "y": 6,
      "z": 3,
      "name": "Rock_Quartzite"
    },
    {
      "x": -6,
      "y": 7,
      "z": 3,
      "name": "Rock_Quartzite"
    },
    {
      "x": -5,
      "y": 6,
      "z": 1,
      "name": "Rock_Quartzite"
    },
    {
      "x": -5,
      "y": 7,
      "z": 1,
      "name": "Rock_Quartzite"
    },
    {
      "x": -5,
      "y": 9,
      "z": 1,
      "name": "Plant_Moss_Wall_Yellow",
      "rotation": 3
    },
    {
      "x": -5,
      "y": 4,
      "z": 2,
      "name": "Rock_Quartzite"
    },
    {
      "x": -5,
      "y": 5,
      "z": 2,
      "name": "Rock_Quartzite"
    },
    {
      "x": -5,
      "y": 6,
      "z": 2,
      "name": "Rock_Quartzite"
    },
    {
      "x": -5,
      "y": 7,
      "z": 2,
      "name": "Rock_Quartzite"
    },
    {
      "x": -5,
      "y": 8,
      "z": 2,
      "name": "Rock_Quartzite"
    },
    {
      "x": -5,
      "y": 9,
      "z": 2,
      "name": "Plant_Moss_Block_Yellow"
    },
    {
      "x": -5,
      "y": 5,
      "z": 3,
      "name": "Rock_Quartzite"
    },
    {
      "x": -5,
      "y": 6,
      "z": 3,
      "name": "Rock_Quartzite"
    },
    {
      "x": -5,
      "y": 7,
      "z": 3,
      "name": "Rock_Quartzite"
    },
    {
      "x": -5,
      "y": 8,
      "z": 3,
      "name": "Plant_Moss_Block_Yellow"
    },
    {
      "x": -5,
      "y": 9,
      "z": 3,
      "name": "Plant_Moss_Block_Yellow"
    },
    {
      "x": -5,
      "y": 7,
      "z": 4,
      "name": "Rock_Quartzite"
    },
    {
      "x": -5,
      "y": 8,
      "z": 4,
      "name": "Rock_Quartzite"
    },
    {
      "x": -4,
      "y": 8,
      "z": -2,
      "name": "Empty"
    },
    {
      "x": -4,
      "y": 9,
      "z": -2,
      "name": "Empty"
    },
    {
      "x": -4,
      "y": 8,
      "z": -1,
      "name": "Plant_Crop_Health3",
      "rotation": 2
    },
    {
      "x": -4,
      "y": 9,
      "z": -1,
      "name": "Plant_Crop_Health3",
      "filler": 1024,
      "rotation": 2
    },
    {
      "x": -4,
      "y": 7,
      "z": 0,
      "name": "Rock_Quartzite"
    },
    {
      "x": -4,
      "y": 8,
      "z": 0,
      "name": "Rock_Quartzite"
    },
    {
      "x": -4,
      "y": 9,
      "z": 0,
      "name": "Rock_Quartzite"
    },
    {
      "x": -4,
      "y": 5,
      "z": 1,
      "name": "Rock_Quartzite"
    },
    {
      "x": -4,
      "y": 6,
      "z": 1,
      "name": "Rock_Quartzite"
    },
    {
      "x": -4,
      "y": 7,
      "z": 1,
      "name": "Rock_Quartzite"
    },
    {
      "x": -4,
      "y": 8,
      "z": 1,
      "name": "Rock_Quartzite"
    },
    {
      "x": -4,
      "y": 9,
      "z": 1,
      "name": "Plant_Moss_Block_Yellow"
    },
    {
      "x": -4,
      "y": 10,
      "z": 1,
      "name": "Plant_Moss_Short_Yellow"
    },
    {
      "x": -4,
      "y": 3,
      "z": 2,
      "name": "Rock_Quartzite"
    },
    {
      "x": -4,
      "y": 4,
      "z": 2,
      "name": "Rock_Quartzite"
    },
    {
      "x": -4,
      "y": 5,
      "z": 2,
      "name": "Rock_Quartzite"
    },
    {
      "x": -4,
      "y": 6,
      "z": 2,
      "name": "Rock_Quartzite"
    },
    {
      "x": -4,
      "y": 7,
      "z": 2,
      "name": "Rock_Quartzite"
    },
    {
      "x": -4,
      "y": 8,
      "z": 2,
      "name": "Rock_Quartzite"
    },
    {
      "x": -4,
      "y": 9,
      "z": 2,
      "name": "Plant_Moss_Block_Yellow"
    },
    {
      "x": -4,
      "y": 5,
      "z": 3,
      "name": "Rock_Quartzite"
    },
    {
      "x": -4,
      "y": 6,
      "z": 3,
      "name": "Rock_Quartzite"
    },
    {
      "x": -4,
      "y": 7,
      "z": 3,
      "name": "Rock_Quartzite"
    },
    {
      "x": -4,
      "y": 8,
      "z": 3,
      "name": "Rock_Quartzite"
    },
    {
      "x": -4,
      "y": 9,
      "z": 3,
      "name": "Plant_Moss_Block_Yellow"
    },
    {
      "x": -4,
      "y": 10,
      "z": 3,
      "name": "Plant_Moss_Yellow"
    },
    {
      "x": -4,
      "y": 6,
      "z": 4,
      "name": "Rock_Quartzite"
    },
    {
      "x": -4,
      "y": 7,
      "z": 4,
      "name": "Rock_Quartzite"
    },
    {
      "x": -4,
      "y": 8,
      "z": 4,
      "name": "Rock_Quartzite"
    },
    {
      "x": -4,
      "y": 9,
      "z": 4,
      "name": "Plant_Moss_Block_Yellow"
    },
    {
      "x": -4,
      "y": 9,
      "z": 5,
      "name": "Plant_Moss_Wall_Yellow"
    },
    {
      "x": -3,
      "y": 7,
      "z": -1,
      "name": "Rock_Quartzite"
    },
    {
      "x": -3,
      "y": 8,
      "z": -1,
      "name": "Rock_Quartzite"
    },
    {
      "x": -3,
      "y": 6,
      "z": 0,
      "name": "Rock_Quartzite"
    },
    {
      "x": -3,
      "y": 7,
      "z": 0,
      "name": "Rock_Quartzite"
    },
    {
      "x": -3,
      "y": 8,
      "z": 0,
      "name": "Rock_Quartzite"
    },
    {
      "x": -3,
      "y": 9,
      "z": 0,
      "name": "Rock_Quartzite"
    },
    {
      "x": -3,
      "y": 4,
      "z": 1,
      "name": "Rock_Quartzite"
    },
    {
      "x": -3,
      "y": 5,
      "z": 1,
      "name": "Rock_Quartzite"
    },
    {
      "x": -3,
      "y": 6,
      "z": 1,
      "name": "Rock_Quartzite"
    },
    {
      "x": -3,
      "y": 7,
      "z": 1,
      "name": "Rock_Quartzite"
    },
    {
      "x": -3,
      "y": 8,
      "z": 1,
      "name": "Rock_Quartzite"
    },
    {
      "x": -3,
      "y": 9,
      "z": 1,
      "name": "Rock_Quartzite"
    },
    {
      "x": -3,
      "y": 10,
      "z": 1,
      "name": "Plant_Moss_Block_Yellow"
    },
    {
      "x": -3,
      "y": 3,
      "z": 2,
      "name": "Rock_Quartzite"
    },
    {
      "x": -3,
      "y": 4,
      "z": 2,
      "name": "Rock_Quartzite"
    },
    {
      "x": -3,
      "y": 5,
      "z": 2,
      "name": "Rock_Quartzite"
    },
    {
      "x": -3,
      "y": 6,
      "z": 2,
      "name": "Rock_Quartzite"
    },
    {
      "x": -3,
      "y": 7,
      "z": 2,
      "name": "Rock_Quartzite"
    },
    {
      "x": -3,
      "y": 8,
      "z": 2,
      "name": "Rock_Quartzite"
    },
    {
      "x": -3,
      "y": 9,
      "z": 2,
      "name": "Rock_Quartzite"
    },
    {
      "x": -3,
      "y": 10,
      "z": 2,
      "name": "Plant_Moss_Block_Yellow"
    },
    {
      "x": -3,
      "y": 4,
      "z": 3,
      "name": "Rock_Quartzite"
    },
    {
      "x": -3,
      "y": 5,
      "z": 3,
      "name": "Rock_Quartzite"
    },
    {
      "x": -3,
      "y": 6,
      "z": 3,
      "name": "Rock_Quartzite"
    },
    {
      "x": -3,
      "y": 7,
      "z": 3,
      "name": "Rock_Quartzite"
    },
    {
      "x": -3,
      "y": 8,
      "z": 3,
      "name": "Rock_Quartzite"
    },
    {
      "x": -3,
      "y": 9,
      "z": 3,
      "name": "Plant_Moss_Block_Yellow"
    },
    {
      "x": -3,
      "y": 7,
      "z": 4,
      "name": "Rock_Quartzite"
    },
    {
      "x": -3,
      "y": 8,
      "z": 4,
      "name": "Rock_Quartzite"
    },
    {
      "x": -3,
      "y": 9,
      "z": 4,
      "name": "Plant_Moss_Block_Yellow"
    },
    {
      "x": -3,
      "y": 9,
      "z": 5,
      "name": "Plant_Moss_Wall_Yellow"
    },
    {
      "x": -2,
      "y": 6,
      "z": -2,
      "name": "Rock_Quartzite"
    },
    {
      "x": -2,
      "y": 7,
      "z": -2,
      "name": "Rock_Quartzite"
    },
    {
      "x": -2,
      "y": 5,
      "z": -1,
      "name": "Rock_Quartzite"
    },
    {
      "x": -2,
      "y": 6,
      "z": -1,
      "name": "Rock_Quartzite"
    },
    {
      "x": -2,
      "y": 7,
      "z": -1,
      "name": "Rock_Quartzite"
    },
    {
      "x": -2,
      "y": 8,
      "z": -1,
      "name": "Rock_Quartzite"
    },
    {
      "x": -2,
      "y": 9,
      "z": -1,
      "name": "Rock_Quartzite"
    },
    {
      "x": -2,
      "y": 5,
      "z": 0,
      "name": "Rock_Quartzite"
    },
    {
      "x": -2,
      "y": 6,
      "z": 0,
      "name": "Rock_Quartzite"
    },
    {
      "x": -2,
      "y": 7,
      "z": 0,
      "name": "Rock_Quartzite"
    },
    {
      "x": -2,
      "y": 8,
      "z": 0,
      "name": "Rock_Quartzite"
    },
    {
      "x": -2,
      "y": 9,
      "z": 0,
      "name": "Rock_Quartzite"
    },
    {
      "x": -2,
      "y": 10,
      "z": 0,
      "name": "Rubble_Quartzite"
    },
    {
      "x": -2,
      "y": 5,
      "z": 1,
      "name": "Rock_Quartzite"
    },
    {
      "x": -2,
      "y": 6,
      "z": 1,
      "name": "Rock_Quartzite"
    },
    {
      "x": -2,
      "y": 7,
      "z": 1,
      "name": "Rock_Quartzite"
    },
    {
      "x": -2,
      "y": 8,
      "z": 1,
      "name": "Rock_Quartzite"
    },
    {
      "x": -2,
      "y": 9,
      "z": 1,
      "name": "Rock_Quartzite"
    },
    {
      "x": -2,
      "y": 10,
      "z": 1,
      "name": "Rock_Quartzite"
    },
    {
      "x": -2,
      "y": 5,
      "z": 2,
      "name": "Rock_Quartzite"
    },
    {
      "x": -2,
      "y": 6,
      "z": 2,
      "name": "Rock_Quartzite"
    },
    {
      "x": -2,
      "y": 7,
      "z": 2,
      "name": "Rock_Quartzite"
    },
    {
      "x": -2,
      "y": 8,
      "z": 2,
      "name": "Rock_Quartzite"
    },
    {
      "x": -2,
      "y": 9,
      "z": 2,
      "name": "Rock_Quartzite"
    },
    {
      "x": -2,
      "y": 10,
      "z": 2,
      "name": "Plant_Moss_Block_Yellow"
    },
    {
      "x": -2,
      "y": 6,
      "z": 3,
      "name": "Rock_Quartzite"
    },
    {
      "x": -2,
      "y": 7,
      "z": 3,
      "name": "Rock_Quartzite"
    },
    {
      "x": -2,
      "y": 8,
      "z": 3,
      "name": "Rock_Quartzite"
    },
    {
      "x": -2,
      "y": 9,
      "z": 3,
      "name": "Rock_Quartzite"
    },
    {
      "x": -1,
      "y": 6,
      "z": -2,
      "name": "Rock_Quartzite"
    },
    {
      "x": -1,
      "y": 7,
      "z": -2,
      "name": "Rock_Quartzite"
    },
    {
      "x": -1,
      "y": 8,
      "z": -2,
      "name": "Rock_Quartzite"
    },
    {
      "x": -1,
      "y": 4,
      "z": -1,
      "name": "Rock_Quartzite"
    },
    {
      "x": -1,
      "y": 5,
      "z": -1,
      "name": "Rock_Quartzite"
    },
    {
      "x": -1,
      "y": 6,
      "z": -1,
      "name": "Rock_Quartzite"
    },
    {
      "x": -1,
      "y": 7,
      "z": -1,
      "name": "Rock_Quartzite"
    },
    {
      "x": -1,
      "y": 8,
      "z": -1,
      "name": "Rock_Quartzite"
    },
    {
      "x": -1,
      "y": 9,
      "z": -1,
      "name": "Rock_Quartzite"
    },
    {
      "x": -1,
      "y": 4,
      "z": 0,
      "name": "Rock_Quartzite"
    },
    {
      "x": -1,
      "y": 5,
      "z": 0,
      "name": "Rock_Quartzite"
    },
    {
      "x": -1,
      "y": 6,
      "z": 0,
      "name": "Rock_Quartzite"
    },
    {
      "x": -1,
      "y": 7,
      "z": 0,
      "name": "Rock_Quartzite"
    },
    {
      "x": -1,
      "y": 8,
      "z": 0,
      "name": "Rock_Quartzite"
    },
    {
      "x": -1,
      "y": 9,
      "z": 0,
      "name": "Rock_Quartzite"
    },
    {
      "x": -1,
      "y": 10,
      "z": 0,
      "name": "Rock_Quartzite"
    },
    {
      "x": -1,
      "y": 5,
      "z": 1,
      "name": "Rock_Quartzite"
    },
    {
      "x": -1,
      "y": 6,
      "z": 1,
      "name": "Rock_Quartzite"
    },
    {
      "x": -1,
      "y": 7,
      "z": 1,
      "name": "Rock_Quartzite"
    },
    {
      "x": -1,
      "y": 8,
      "z": 1,
      "name": "Rock_Quartzite"
    },
    {
      "x": -1,
      "y": 9,
      "z": 1,
      "name": "Rock_Quartzite"
    },
    {
      "x": -1,
      "y": 10,
      "z": 1,
      "name": "Rock_Quartzite"
    },
    {
      "x": -1,
      "y": 5,
      "z": 2,
      "name": "Rock_Quartzite"
    },
    {
      "x": -1,
      "y": 6,
      "z": 2,
      "name": "Rock_Quartzite"
    },
    {
      "x": -1,
      "y": 7,
      "z": 2,
      "name": "Rock_Quartzite"
    },
    {
      "x": -1,
      "y": 8,
      "z": 2,
      "name": "Rock_Quartzite"
    },
    {
      "x": -1,
      "y": 9,
      "z": 2,
      "name": "Rock_Quartzite"
    },
    {
      "x": -1,
      "y": 7,
      "z": 3,
      "name": "Rock_Quartzite"
    },
    {
      "x": -1,
      "y": 8,
      "z": 3,
      "name": "Rock_Quartzite"
    },
    {
      "x": 0,
      "y": 8,
      "z": -3,
      "name": "Plant_Moss_Wall_Yellow",
      "rotation": 2
    },
    {
      "x": 0,
      "y": 9,
      "z": -3,
      "name": "Plant_Moss_Wall_Yellow",
      "rotation": 2
    },
    {
      "x": 0,
      "y": 5,
      "z": -2,
      "name": "Rock_Quartzite"
    },
    {
      "x": 0,
      "y": 6,
      "z": -2,
      "name": "Rock_Quartzite"
    },
    {
      "x": 0,
      "y": 7,
      "z": -2,
      "name": "Rock_Quartzite"
    },
    {
      "x": 0,
      "y": 8,
      "z": -2,
      "name": "Rock_Quartzite"
    },
    {
      "x": 0,
      "y": 9,
      "z": -2,
      "name": "Plant_Moss_Block_Yellow"
    },
    {
      "x": 0,
      "y": 3,
      "z": -1,
      "name": "Rock_Quartzite"
    },
    {
      "x": 0,
      "y": 4,
      "z": -1,
      "name": "Rock_Quartzite"
    },
    {
      "x": 0,
      "y": 5,
      "z": -1,
      "name": "Rock_Quartzite"
    },
    {
      "x": 0,
      "y": 6,
      "z": -1,
      "name": "Rock_Quartzite"
    },
    {
      "x": 0,
      "y": 7,
      "z": -1,
      "name": "Rock_Quartzite"
    },
    {
      "x": 0,
      "y": 8,
      "z": -1,
      "name": "Rock_Quartzite"
    },
    {
      "x": 0,
      "y": 9,
      "z": -1,
      "name": "Rock_Quartzite"
    },
    {
      "x": 0,
      "y": 10,
      "z": -1,
      "name": "Rock_Quartzite"
    },
    {
      "x": 0,
      "y": 3,
      "z": 0,
      "name": "Rock_Quartzite"
    },
    {
      "x": 0,
      "y": 4,
      "z": 0,
      "name": "Rock_Quartzite"
    },
    {
      "x": 0,
      "y": 5,
      "z": 0,
      "name": "Rock_Quartzite"
    },
    {
      "x": 0,
      "y": 6,
      "z": 0,
      "name": "Rock_Quartzite"
    },
    {
      "x": 0,
      "y": 7,
      "z": 0,
      "name": "Rock_Quartzite"
    },
    {
      "x": 0,
      "y": 8,
      "z": 0,
      "name": "Rock_Quartzite"
    },
    {
      "x": 0,
      "y": 9,
      "z": 0,
      "name": "Rock_Quartzite"
    },
    {
      "x": 0,
      "y": 10,
      "z": 0,
      "name": "Rock_Quartzite"
    },
    {
      "x": 0,
      "y": 4,
      "z": 1,
      "name": "Rock_Quartzite"
    },
    {
      "x": 0,
      "y": 5,
      "z": 1,
      "name": "Rock_Quartzite"
    },
    {
      "x": 0,
      "y": 6,
      "z": 1,
      "name": "Rock_Quartzite"
    },
    {
      "x": 0,
      "y": 7,
      "z": 1,
      "name": "Rock_Quartzite"
    },
    {
      "x": 0,
      "y": 8,
      "z": 1,
      "name": "Rock_Quartzite"
    },
    {
      "x": 0,
      "y": 9,
      "z": 1,
      "name": "Rock_Quartzite"
    },
    {
      "x": 0,
      "y": 10,
      "z": 1,
      "name": "Plant_Moss_Block_Yellow"
    },
    {
      "x": 0,
      "y": 11,
      "z": 1,
      "name": "Plant_Moss_Short_Yellow"
    },
    {
      "x": 0,
      "y": 6,
      "z": 2,
      "name": "Rock_Quartzite"
    },
    {
      "x": 0,
      "y": 7,
      "z": 2,
      "name": "Rock_Quartzite"
    },
    {
      "x": 0,
      "y": 8,
      "z": 2,
      "name": "Rock_Quartzite"
    },
    {
      "x": 0,
      "y": 9,
      "z": 2,
      "name": "Rock_Quartzite"
    },
    {
      "x": 0,
      "y": 8,
      "z": 3,
      "name": "Plant_Moss_Wall_Yellow"
    },
    {
      "x": 1,
      "y": 9,
      "z": -3,
      "name": "Plant_Moss_Wall_Yellow",
      "rotation": 2
    },
    {
      "x": 1,
      "y": 5,
      "z": -2,
      "name": "Rock_Quartzite"
    },
    {
      "x": 1,
      "y": 6,
      "z": -2,
      "name": "Rock_Quartzite"
    },
    {
      "x": 1,
      "y": 7,
      "z": -2,
      "name": "Rock_Quartzite"
    },
    {
      "x": 1,
      "y": 8,
      "z": -2,
      "name": "Rock_Quartzite"
    },
    {
      "x": 1,
      "y": 9,
      "z": -2,
      "name": "Plant_Moss_Block_Yellow"
    },
    {
      "x": 1,
      "y": 3,
      "z": -1,
      "name": "Rock_Quartzite"
    },
    {
      "x": 1,
      "y": 4,
      "z": -1,
      "name": "Rock_Quartzite"
    },
    {
      "x": 1,
      "y": 5,
      "z": -1,
      "name": "Rock_Quartzite"
    },
    {
      "x": 1,
      "y": 6,
      "z": -1,
      "name": "Rock_Quartzite"
    },
    {
      "x": 1,
      "y": 7,
      "z": -1,
      "name": "Rock_Quartzite"
    },
    {
      "x": 1,
      "y": 8,
      "z": -1,
      "name": "Rock_Quartzite"
    },
    {
      "x": 1,
      "y": 9,
      "z": -1,
      "name": "Plant_Moss_Block_Yellow"
    },
    {
      "x": 1,
      "y": 3,
      "z": 0,
      "name": "Rock_Quartzite"
    },
    {
      "x": 1,
      "y": 4,
      "z": 0,
      "name": "Rock_Quartzite"
    },
    {
      "x": 1,
      "y": 5,
      "z": 0,
      "name": "Rock_Quartzite"
    },
    {
      "x": 1,
      "y": 6,
      "z": 0,
      "name": "Rock_Quartzite"
    },
    {
      "x": 1,
      "y": 7,
      "z": 0,
      "name": "Rock_Quartzite"
    },
    {
      "x": 1,
      "y": 8,
      "z": 0,
      "name": "Rock_Quartzite"
    },
    {
      "x": 1,
      "y": 9,
      "z": 0,
      "name": "Rock_Quartzite"
    },
    {
      "x": 1,
      "y": 10,
      "z": 0,
      "name": "Plant_Moss_Block_Yellow"
    },
    {
      "x": 1,
      "y": 11,
      "z": 0,
      "name": "Plant_Moss_Yellow"
    },
    {
      "x": 1,
      "y": 4,
      "z": 1,
      "name": "Rock_Quartzite"
    },
    {
      "x": 1,
      "y": 5,
      "z": 1,
      "name": "Rock_Quartzite"
    },
    {
      "x": 1,
      "y": 6,
      "z": 1,
      "name": "Rock_Quartzite"
    },
    {
      "x": 1,
      "y": 7,
      "z": 1,
      "name": "Rock_Quartzite"
    },
    {
      "x": 1,
      "y": 8,
      "z": 1,
      "name": "Rock_Quartzite"
    },
    {
      "x": 1,
      "y": 9,
      "z": 1,
      "name": "Plant_Moss_Block_Yellow"
    },
    {
      "x": 1,
      "y": 10,
      "z": 1,
      "name": "Plant_Moss_Block_Yellow"
    },
    {
      "x": 1,
      "y": 7,
      "z": 2,
      "name": "Rock_Quartzite"
    },
    {
      "x": 1,
      "y": 8,
      "z": 2,
      "name": "Rock_Quartzite"
    },
    {
      "x": 1,
      "y": 10,
      "z": 2,
      "name": "Plant_Moss_Wall_Yellow"
    },
    {
      "x": 2,
      "y": 7,
      "z": -2,
      "name": "Rock_Quartzite"
    },
    {
      "x": 2,
      "y": 8,
      "z": -2,
      "name": "Rock_Quartzite"
    },
    {
      "x": 2,
      "y": 4,
      "z": -1,
      "name": "Rock_Quartzite"
    },
    {
      "x": 2,
      "y": 5,
      "z": -1,
      "name": "Rock_Quartzite"
    },
    {
      "x": 2,
      "y": 6,
      "z": -1,
      "name": "Rock_Quartzite"
    },
    {
      "x": 2,
      "y": 7,
      "z": -1,
      "name": "Rock_Quartzite"
    },
    {
      "x": 2,
      "y": 8,
      "z": -1,
      "name": "Rock_Quartzite"
    },
    {
      "x": 2,
      "y": 9,
      "z": -1,
      "name": "Rock_Quartzite"
    },
    {
      "x": 2,
      "y": 5,
      "z": 0,
      "name": "Rock_Quartzite"
    },
    {
      "x": 2,
      "y": 6,
      "z": 0,
      "name": "Rock_Quartzite"
    },
    {
      "x": 2,
      "y": 7,
      "z": 0,
      "name": "Rock_Quartzite"
    },
    {
      "x": 2,
      "y": 8,
      "z": 0,
      "name": "Rock_Quartzite"
    },
    {
      "x": 2,
      "y": 9,
      "z": 0,
      "name": "Rock_Quartzite"
    },
    {
      "x": 2,
      "y": 6,
      "z": 1,
      "name": "Rock_Quartzite"
    },
    {
      "x": 2,
      "y": 7,
      "z": 1,
      "name": "Rock_Quartzite"
    },
    {
      "x": 3,
      "y": 6,
      "z": -1,
      "name": "Rock_Quartzite"
    },
    {
      "x": 3,
      "y": 7,
      "z": -1,
      "name": "Rock_Quartzite"
    },
    {
      "x": 3,
      "y": 8,
      "z": -1,
      "name": "Rock_Quartzite"
    },
    {
      "x": 3,
      "y": 5,
      "z": 0,
      "name": "Rock_Quartzite"
    },
    {
      "x": 3,
      "y": 6,
      "z": 0,
      "name": "Rock_Quartzite"
    },
    {
      "x": 3,
      "y": 7,
      "z": 0,
      "name": "Rock_Quartzite"
    },
    {
      "x": 3,
      "y": 8,
      "z": 0,
      "name": "Rock_Quartzite"
    }
  ]
}