{
  "version": 8,
  "blockIdVersion": 8,
  "anchorX": 9,
  "anchorY": 14,
  "anchorZ": 12,
  "blocks": [
    {
      "x": 1,
      "y": 14,
      "z": 10,
      "name": "Rock_Marble"
    },
    {
      "x": 1,
      "y": 15,
      "z": 10,
      "name": "Rock_Marble"
    },
    {
      "x": 1,
      "y": 16,
      "z": 10,
      "name": "Rock_Marble"
    },
    {
      "x": 1,
      "y": 17,
      "z": 10,
      "name": "Rock_Marble"
    },
    {
      "x": 1,
      "y": 14,
      "z": 11,
      "name": "Rock_Marble"
    },
    {
      "x": 1,
      "y": 15,
      "z": 11,
      "name": "Rock_Marble"
    },
    {
      "x": 1,
      "y": 16,
      "z": 11,
      "name": "Rock_Marble"
    },
    {
      "x": 1,
      "y": 17,
      "z": 11,
      "name": "Rock_Marble"
    },
    {
      "x": 1,
      "y": 18,
      "z": 11,
      "name": "Rock_Marble"
    },
    {
      "x": 1,
      "y": 19,
      "z": 11,
      "name": "Soil_Dirt_Cold"
    },
    {
      "x": 1,
      "y": 15,
      "z": 12,
      "name": "Rock_Marble"
    },
    {
      "x": 1,
      "y": 16,
      "z": 12,
      "name": "Rock_Marble"
    },
    {
      "x": 2,
      "y": 15,
      "z": 9,
      "name": "Rock_Marble"
    },
    {
      "x": 2,
      "y": 16,
      "z": 9,
      "name": "Rock_Marble"
    },
    {
      "x": 2,
      "y": 17,
      "z": 9,
      "name": "Rock_Marble"
    },
    {
      "x": 2,
      "y": 18,
      "z": 9,
      "name": "Rock_Marble"
    },
    {
      "x": 2,
      "y": 14,
      "z": 10,
      "name": "Rock_Marble"
    },
    {
      "x": 2,
      "y": 15,
      "z": 10,
      "name": "Rock_Marble"
    },
    {
      "x": 2,
      "y": 16,
      "z": 10,
      "name": "Rock_Marble"
    },
    {
      "x": 2,
      "y": 17,
      "z": 10,
      "name": "Rock_Marble"
    },
    {
      "x": 2,
      "y": 18,
      "z": 10,
      "name": "Soil_Dirt_Cold"
    },
    {
      "x": 2,
      "y": 19,
      "z": 10,
      "name": "Soil_Dirt_Cold"
    },
    {
      "x": 2,
      "y": 20,
      "z": 10,
      "name": "Soil_Grass_Cold"
    },
    {
      "x": 2,
      "y": 14,
      "z": 11,
      "name": "Rock_Marble"
    },
    {
      "x": 2,
      "y": 15,
      "z": 11,
      "name": "Rock_Marble"
    },
    {
      "x": 2,
      "y": 16,
      "z": 11,
      "name": "Rock_Marble"
    },
    {
      "x": 2,
      "y": 17,
      "z": 11,
      "name": "Rock_Marble"
    },
    {
      "x": 2,
      "y": 18,
      "z": 11,
      "name": "Rock_Marble"
    },
    {
      "x": 2,
      "y": 19,
      "z": 11,
      "name": "Soil_Dirt_Cold"
    },
    {
      "x": 2,
      "y": 20,
      "z": 11,
      "name": "Soil_Grass_Cold"
    },
    {
      "x": 2,
      "y": 12,
      "z": 12,
      "name": "Rock_Marble"
    },
    {
      "x": 2,
      "y": 13,
      "z": 12,
      "name": "Rock_Marble"
    },
    {
      "x": 2,
      "y": 14,
      "z": 12,
      "name": "Rock_Marble"
    },
    {
      "x": 2,
      "y": 15,
      "z": 12,
      "name": "Rock_Marble"
    },
    {
      "x": 2,
      "y": 16,
      "z": 12,
      "name": "Rock_Marble"
    },
    {
      "x": 2,
      "y": 17,
      "z": 12,
      "name": "Rock_Marble"
    },
    {
      "x": 2,
      "y": 18,
      "z": 12,
      "name": "Rock_Marble"
    },
    {
      "x": 2,
      "y": 14,
      "z": 13,
      "name": "Rock_Marble"
    },
    {
      "x": 2,
      "y": 15,
      "z": 13,
      "name": "Rock_Marble"
    },
    {
      "x": 2,
      "y": 16,
      "z": 13,
      "name": "Rock_Marble"
    },
    {
      "x": 2,
      "y": 17,
      "z": 13,
      "name": "Rock_Marble"
    },
    {
      "x": 3,
      "y": 14,
      "z": 9,
      "name": "Rock_Marble"
    },
    {
      "x": 3,
      "y": 15,
      "z": 9,
      "name": "Rock_Marble"
    },
    {
      "x": 3,
      "y": 17,
      "z": 9,
      "name": "Rock_Marble"
    },
    {
      "x": 3,
      "y": 18,
      "z": 9,
      "name": "Rock_Marble"
    },
    {
      "x": 3,
      "y": 19,
      "z": 9,
      "name": "Soil_Dirt_Cold"
    },
    {
      "x": 3,
      "y": 14,
      "z": 10,
      "name": "Rock_Marble"
    },
    {
      "x": 3,
      "y": 15,
      "z": 10,
      "name": "Rock_Marble"
    },
    {
      "x": 3,
      "y": 16,
      "z": 10,
      "name": "Rock_Marble"
    },
    {
      "x": 3,
      "y": 17,
      "z": 10,
      "name": "Rock_Marble"
    },
    {
      "x": 3,
      "y": 18,
      "z": 10,
      "name": "Soil_Dirt_Cold"
    },
    {
      "x": 3,
      "y": 19,
      "z": 10,
      "name": "Soil_Dirt_Cold"
    },
    {
      "x": 3,
      "y": 20,
      "z": 10,
      "name": "Soil_Grass_Cold"
    },
    {
      "x": 3,
      "y": 21,
      "z": 10,
      "name": "Plant_Grass_Lush_Tall"
    },
    {
      "x": 3,
      "y": 12,
      "z": 11,
      "name": "Rock_Marble"
    },
    {
      "x": 3,
      "y": 13,
      "z": 11,
      "name": "Rock_Marble"
    },
    {
      "x": 3,
      "y": 14,
      "z": 11,
      "name": "Rock_Marble"
    },
    {
      "x": 3,
      "y": 15,
      "z": 11,
      "name": "Rock_Marble"
    },
    {
      "x": 3,
      "y": 16,
      "z": 11,
      "name": "Rock_Marble"
    },
    {
      "x": 3,
      "y": 17,
      "z": 11,
      "name": "Rock_Marble"
    },
    {
      "x": 3,
      "y": 18,
      "z": 11,
      "name": "Rock_Marble"
    },
    {
      "x": 3,
      "y": 19,
      "z": 11,
      "name": "Soil_Dirt_Cold"
    },
    {
      "x": 3,
      "y": 20,
      "z": 11,
      "name": "Soil_Dirt_Cold"
    },
    {
      "x": 3,
      "y": 21,
      "z": 11,
      "name": "Soil_Grass_Cold"
    },
    {
      "x": 3,
      "y": 11,
      "z": 12,
      "name": "Rock_Marble"
    },
    {
      "x": 3,
      "y": 12,
      "z": 12,
      "name": "Rock_Marble"
    },
    {
      "x": 3,
      "y": 13,
      "z": 12,
      "name": "Rock_Marble"
    },
    {
      "x": 3,
      "y": 14,
      "z": 12,
      "name": "Rock_Marble"
    },
    {
      "x": 3,
      "y": 15,
      "z": 12,
      "name": "Rock_Marble"
    },
    {
      "x": 3,
      "y": 16,
      "z": 12,
      "name": "Rock_Marble"
    },
    {
      "x": 3,
      "y": 17,
      "z": 12,
      "name": "Rock_Marble"
    },
    {
      "x": 3,
      "y": 18,
      "z": 12,
      "name": "Rock_Marble"
    },
    {
      "x": 3,
      "y": 19,
      "z": 12,
      "name": "Soil_Dirt_Cold"
    },
    {
      "x": 3,
      "y": 20,
      "z": 12,
      "name": "Soil_Dirt_Cold"
    },
    {
      "x": 3,
      "y": 21,
      "z": 12,
      "name": "Soil_Grass_Cold"
    },
    {
      "x": 3,
      "y": 22,
      "z": 12,
      "name": "Plant_Grass_Lush_Tall"
    },
    {
      "x": 3,
      "y": 11,
      "z": 13,
      "name": "Rock_Marble"
    },
    {
      "x": 3,
      "y": 12,
      "z": 13,
      "name": "Rock_Marble"
    },
    {
      "x": 3,
      "y": 13,
      "z": 13,
      "name": "Rock_Marble"
    },
    {
      "x": 3,
      "y": 14,
      "z": 13,
      "name": "Rock_Marble"
    },
    {
      "x": 3,
      "y": 15,
      "z": 13,
      "name": "Rock_Marble"
    },
    {
      "x": 3,
      "y": 16,
      "z": 13,
      "name": "Rock_Marble"
    },
    {
      "x": 3,
      "y": 17,
      "z": 13,
      "name": "Rock_Marble"
    },
    {
      "x": 3,
      "y": 18,
      "z": 13,
      "name": "Rock_Marble"
    },
    {
      "x": 3,
      "y": 19,
      "z": 13,
      "name": "Soil_Dirt_Cold"
    },
    {
      "x": 3,
      "y": 20,
      "z": 13,
      "name": "Soil_Dirt_Cold"
    },
    {
      "x": 3,
      "y": 21,
      "z": 13,
      "name": "Soil_Grass_Cold"
    },
    {
      "x": 4,
      "y": 14,
      "z": 9,
      "name": "Rock_Marble"
    },
    {
      "x": 4,
      "y": 13,
      "z": 10,
      "name": "Rock_Marble"
    },
    {
      "x": 4,
      "y": 14,
      "z": 10,
      "name": "Rock_Marble"
    },
    {
      "x": 4,
      "y": 18,
      "z": 10,
      "name": "Rock_Marble"
    },
    {
      "x": 4,
      "y": 19,
      "z": 10,
      "name": "Soil_Dirt_Cold"
    },
    {
      "x": 4,
      "y": 20,
      "z": 10,
      "name": "Soil_Dirt_Cold"
    },
    {
      "x": 4,
      "y": 21,
      "z": 10,
      "name": "Soil_Dirt_Cold"
    },
    {
      "x": 4,
      "y": 22,
      "z": 10,
      "name": "Soil_Grass_Cold"
    },
    {
      "x": 4,
      "y": 12,
      "z": 11,
      "name": "Rock_Marble"
    },
    {
      "x": 4,
      "y": 13,
      "z": 11,
      "name": "Rock_Marble"
    },
    {
      "x": 4,
      "y": 14,
      "z": 11,
      "name": "Rock_Marble"
    },
    {
      "x": 4,
      "y": 15,
      "z": 11,
      "name": "Rock_Marble"
    },
    {
      "x": 4,
      "y": 16,
      "z": 11,
      "name": "Rock_Marble"
    },
    {
      "x": 4,
      "y": 18,
      "z": 11,
      "name": "Rock_Marble"
    },
    {
      "x": 4,
      "y": 19,
      "z": 11,
      "name": "Soil_Dirt_Cold"
    },
    {
      "x": 4,
      "y": 20,
      "z": 11,
      "name": "Soil_Dirt_Cold"
    },
    {
      "x": 4,
      "y": 21,
      "z": 11,
      "name": "Soil_Dirt_Cold"
    },
    {
      "x": 4,
      "y": 22,
      "z": 11,
      "name": "Soil_Grass_Cold"
    },
    {
      "x": 4,
      "y": 10,
      "z": 12,
      "name": "Rock_Marble"
    },
    {
      "x": 4,
      "y": 11,
      "z": 12,
      "name": "Rock_Marble"
    },
    {
      "x": 4,
      "y": 12,
      "z": 12,
      "name": "Rock_Marble"
    },
    {
      "x": 4,
      "y": 13,
      "z": 12,
      "name": "Rock_Marble"
    },
    {
      "x": 4,
      "y": 14,
      "z": 12,
      "name": "Rock_Marble"
    },
    {
      "x": 4,
      "y": 15,
      "z": 12,
      "name": "Rock_Marble"
    },
    {
      "x": 4,
      "y": 16,
      "z": 12,
      "name": "Rock_Marble"
    },
    {
      "x": 4,
      "y": 17,
      "z": 12,
      "name": "Rock_Marble"
    },
    {
      "x": 4,
      "y": 18,
      "z": 12,
      "name": "Rock_Marble"
    },
    {
      "x": 4,
      "y": 19,
      "z": 12,
      "name": "Rock_Marble"
    },
    {
      "x": 4,
      "y": 20,
      "z": 12,
      "name": "Soil_Dirt_Cold"
    },
    {
      "x": 4,
      "y": 21,
      "z": 12,
      "name": "Soil_Dirt_Cold"
    },
    {
      "x": 4,
      "y": 22,
      "z": 12,
      "name": "Soil_Grass_Cold"
    },
    {
      "x": 4,
      "y": 23,
      "z": 12,
      "name": "Plant_Grass_Lush_Tall"
    },
    {
      "x": 4,
      "y": 11,
      "z": 13,
      "name": "Rock_Marble"
    },
    {
      "x": 4,
      "y": 12,
      "z": 13,
      "name": "Rock_Marble"
    },
    {
      "x": 4,
      "y": 13,
      "z": 13,
      "name": "Rock_Marble"
    },
    {
      "x": 4,
      "y": 14,
      "z": 13,
      "name": "Rock_Marble"
    },
    {
      "x": 4,
      "y": 18,
      "z": 13,
      "name": "Rock_Marble"
    },
    {
      "x": 4,
      "y": 19,
      "z": 13,
      "name": "Rock_Marble"
    },
    {
      "x": 4,
      "y": 20,
      "z": 13,
      "name": "Soil_Dirt_Cold"
    },
    {
      "x": 4,
      "y": 21,
      "z": 13,
      "name": "Soil_Grass_Cold"
    },
    {
      "x": 4,
      "y": 22,
      "z": 13,
      "name": "Plant_Grass_Lush_Tall"
    },
    {
      "x": 4,
      "y": 12,
      "z": 14,
      "name": "Rock_Marble"
    },
    {
      "x": 4,
      "y": 13,
      "z": 14,
      "name": "Rock_Marble"
    },
    {
      "x": 4,
      "y": 20,
      "z": 14,
      "name": "Soil_Dirt_Cold"
    },
    {
      "x": 4,
      "y": 21,
      "z": 14,
      "name": "Soil_Grass_Cold"
    },
    {
      "x": 5,
      "y": 12,
      "z": 10,
      "name": "Rock_Marble"
    },
    {
      "x": 5,
      "y": 13,
      "z": 10,
      "name": "Rock_Marble"
    },
    {
      "x": 5,
      "y": 14,
      "z": 10,
      "name": "Rock_Marble"
    },
    {
      "x": 5,
      "y": 21,
      "z": 10,
      "name": "Soil_Dirt_Cold"
    },
    {
      "x": 5,
      "y": 22,
      "z": 10,
      "name": "Soil_Grass_Cold"
    },
    {
      "x": 5,
      "y": 11,
      "z": 11,
      "name": "Rock_Marble"
    },
    {
      "x": 5,
      "y": 12,
      "z": 11,
      "name": "Rock_Marble"
    },
    {
      "x": 5,
      "y": 13,
      "z": 11,
      "name": "Rock_Marble"
    },
    {
      "x": 5,
      "y": 14,
      "z": 11,
      "name": "Rock_Marble"
    },
    {
      "x": 5,
      "y": 19,
      "z": 11,
      "name": "Rock_Marble"
    },
    {
      "x": 5,
      "y": 20,
      "z": 11,
      "name": "Rock_Marble"
    },
    {
      "x": 5,
      "y": 21,
      "z": 11,
      "name": "Soil_Dirt_Cold"
    },
    {
      "x": 5,
      "y": 22,
      "z": 11,
      "name": "Soil_Dirt_Cold"
    },
    {
      "x": 5,
      "y": 23,
      "z": 11,
      "name": "Soil_Grass_Cold"
    },
    {
      "x": 5,
      "y": 24,
      "z": 11,
      "name": "Plant_Grass_Lush_Tall"
    },
    {
      "x": 5,
      "y": 11,
      "z": 12,
      "name": "Rock_Marble"
    },
    {
      "x": 5,
      "y": 12,
      "z": 12,
      "name": "Rock_Marble"
    },
    {
      "x": 5,
      "y": 13,
      "z": 12,
      "name": "Rock_Marble"
    },
    {
      "x": 5,
      "y": 14,
      "z": 12,
      "name": "Rock_Marble"
    },
    {
      "x": 5,
      "y": 19,
      "z": 12,
      "name": "Rock_Marble"
    },
    {
      "x": 5,
      "y": 20,
      "z": 12,
      "name": "Rock_Marble"
    },
    {
      "x": 5,
      "y": 21,
      "z": 12,
      "name": "Soil_Dirt_Cold"
    },
    {
      "x": 5,
      "y": 22,
      "z": 12,
      "name": "Soil_Dirt_Cold"
    },
    {
      "x": 5,
      "y": 23,
      "z": 12,
      "name": "Soil_Grass_Cold"
    },
    {
      "x": 5,
      "y": 11,
      "z": 13,
      "name": "Rock_Marble"
    },
    {
      "x": 5,
      "y": 12,
      "z": 13,
      "name": "Rock_Marble"
    },
    {
      "x": 5,
      "y": 13,
      "z": 13,
      "name": "Rock_Marble"
    },
    {
      "x": 5,
      "y": 21,
      "z": 13,
      "name": "Soil_Dirt_Cold"
    },
    {
      "x": 5,
      "y": 22,
      "z": 13,
      "name": "Soil_Dirt_Cold"
    },
    {
      "x": 5,
      "y": 23,
      "z": 13,
      "name": "Soil_Grass_Cold"
    },
    {
      "x": 5,
      "y": 24,
      "z": 13,
      "name": "Plant_Grass_Lush_Tall"
    },
    {
      "x": 5,
      "y": 12,
      "z": 14,
      "name": "Rock_Marble"
    },
    {
      "x": 5,
      "y": 13,
      "z": 14,
      "name": "Rock_Marble"
    },
    {
      "x": 5,
      "y": 21,
      "z": 14,
      "name": "Soil_Dirt_Cold"
    },
    {
      "x": 5,
      "y": 22,
      "z": 14,
      "name": "Soil_Dirt_Cold"
    },
    {
      "x": 5,
      "y": 23,
      "z": 14,
      "name": "Soil_Grass_Cold"
    },
    {
      "x": 6,
      "y": 22,
      "z": 10,
      "name": "Soil_Dirt_Cold"
    },
    {
      "x": 6,
      "y": 23,
      "z": 10,
      "name": "Soil_Grass_Cold"
    },
    {
      "x": 6,
      "y": 11,
      "z": 11,
      "name": "Rock_Marble"
    },
    {
      "x": 6,
      "y": 12,
      "z": 11,
      "name": "Rock_Marble"
    },
    {
      "x": 6,
      "y": 20,
      "z": 11,
      "name": "Rock_Marble"
    },
    {
      "x": 6,
      "y": 21,
      "z": 11,
      "name": "Rock_Marble"
    },
    {
      "x": 6,
      "y": 22,
      "z": 11,
      "name": "Soil_Dirt_Cold"
    },
    {
      "x": 6,
      "y": 23,
      "z": 11,
      "name": "Soil_Grass_Cold"
    },
    {
      "x": 6,
      "y": 10,
      "z": 12,
      "name": "Rock_Marble"
    },
    {
      "x": 6,
      "y": 11,
      "z": 12,
      "name": "Rock_Marble"
    },
    {
      "x": 6,
      "y": 12,
      "z": 12,
      "name": "Rock_Marble"
    },
    {
      "x": 6,
      "y": 13,
      "z": 12,
      "name": "Rock_Marble"
    },
    {
      "x": 6,
      "y": 20,
      "z": 12,
      "name": "Rock_Marble"
    },
    {
      "x": 6,
      "y": 21,
      "z": 12,
      "name": "Rock_Marble"
    },
    {
      "x": 6,
      "y": 22,
      "z": 12,
      "name": "Soil_Dirt_Cold"
    },
    {
      "x": 6,
      "y": 23,
      "z": 12,
      "name": "Soil_Dirt_Cold"
    },
    {
      "x": 6,
      "y": 24,
      "z": 12,
      "name": "Soil_Grass_Cold"
    },
    {
      "x": 6,
      "y": 10,
      "z": 13,
      "name": "Rock_Marble"
    },
    {
      "x": 6,
      "y": 11,
      "z": 13,
      "name": "Rock_Marble"
    },
    {
      "x": 6,
      "y": 12,
      "z": 13,
      "name": "Rock_Marble"
    },
    {
      "x": 6,
      "y": 21,
      "z": 13,
      "name": "Soil_Dirt_Cold"
    },
    {
      "x": 6,
      "y": 22,
      "z": 13,
      "name": "Soil_Dirt_Cold"
    },
    {
      "x": 6,
      "y": 23,
      "z": 13,
      "name": "Soil_Grass_Cold"
    },
    {
      "x": 6,
      "y": 11,
      "z": 14,
      "name": "Rock_Marble"
    },
    {
      "x": 6,
      "y": 12,
      "z": 14,
      "name": "Rock_Marble"
    },
    {
      "x": 6,
      "y": 22,
      "z": 14,
      "name": "Soil_Dirt_Cold"
    },
    {
      "x": 6,
      "y": 23,
      "z": 14,
      "name": "Soil_Grass_Cold"
    },
    {
      "x": 6,
      "y": 24,
      "z": 14,
      "name": "Plant_Grass_Lush_Tall"
    },
    {
      "x": 7,
      "y": 22,
      "z": 10,
      "name": "Rock_Marble"
    },
    {
      "x": 7,
      "y": 23,
      "z": 10,
      "name": "Soil_Grass_Cold"
    },
    {
      "x": 7,
      "y": 24,
      "z": 10,
      "name": "Plant_Grass_Lush_Tall"
    },
    {
      "x": 7,
      "y": 11,
      "z": 11,
      "name": "Rock_Marble"
    },
    {
      "x": 7,
      "y": 12,
      "z": 11,
      "name": "Rock_Marble"
    },
    {
      "x": 7,
      "y": 21,
      "z": 11,
      "name": "Rock_Marble"
    },
    {
      "x": 7,
      "y": 22,
      "z": 11,
      "name": "Soil_Dirt_Cold"
    },
    {
      "x": 7,
      "y": 23,
      "z": 11,
      "name": "Soil_Dirt_Cold"
    },
    {
      "x": 7,
      "y": 24,
      "z": 11,
      "name": "Soil_Grass_Cold"
    },
    {
      "x": 7,
      "y": 10,
      "z": 12,
      "name": "Rock_Marble"
    },
    {
      "x": 7,
      "y": 11,
      "z": 12,
      "name": "Rock_Marble"
    },
    {
      "x": 7,
      "y": 12,
      "z": 12,
      "name": "Rock_Marble"
    },
    {
      "x": 7,
      "y": 21,
      "z": 12,
      "name": "Rock_Marble"
    },
    {
      "x": 7,
      "y": 22,
      "z": 12,
      "name": "Rock_Marble"
    },
    {
      "x": 7,
      "y": 23,
      "z": 12,
      "name": "Soil_Dirt_Cold"
    },
    {
      "x": 7,
      "y": 24,
      "z": 12,
      "name": "Soil_Dirt_Cold"
    },
    {
      "x": 7,
      "y": 25,
      "z": 12,
      "name": "Soil_Grass_Cold"
    },
    {
      "x": 7,
      "y": 10,
      "z": 13,
      "name": "Rock_Marble"
    },
    {
      "x": 7,
      "y": 11,
      "z": 13,
      "name": "Rock_Marble"
    },
    {
      "x": 7,
      "y": 12,
      "z": 13,
      "name": "Rock_Marble"
    },
    {
      "x": 7,
      "y": 22,
      "z": 13,
      "name": "Soil_Dirt_Cold"
    },
    {
      "x": 7,
      "y": 23,
      "z": 13,
      "name": "Soil_Dirt_Cold"
    },
    {
      "x": 7,
      "y": 24,
      "z": 13,
      "name": "Soil_Dirt_Cold"
    },
    {
      "x": 7,
      "y": 25,
      "z": 13,
      "name": "Soil_Grass_Cold"
    },
    {
      "x": 7,
      "y": 26,
      "z": 13,
      "name": "Plant_Grass_Lush_Tall"
    },
    {
      "x": 7,
      "y": 31,
      "z": 13,
      "name": "Plant_Leaves_Fir",
      "support": 15
    },
    {
      "x": 7,
      "y": 11,
      "z": 14,
      "name": "Rock_Marble"
    },
    {
      "x": 7,
      "y": 12,
      "z": 14,
      "name": "Rock_Marble"
    },
    {
      "x": 7,
      "y": 23,
      "z": 14,
      "name": "Soil_Grass_Cold"
    },
    {
      "x": 7,
      "y": 31,
      "z": 14,
      "name": "Plant_Leaves_Fir",
      "support": 15
    },
    {
      "x": 8,
      "y": 23,
      "z": 10,
      "name": "Soil_Dirt_Cold"
    },
    {
      "x": 8,
      "y": 24,
      "z": 10,
      "name": "Soil_Grass_Cold"
    },
    {
      "x": 8,
      "y": 12,
      "z": 11,
      "name": "Rock_Marble"
    },
    {
      "x": 8,
      "y": 22,
      "z": 11,
      "name": "Soil_Dirt_Cold"
    },
    {
      "x": 8,
      "y": 23,
      "z": 11,
      "name": "Soil_Dirt_Cold"
    },
    {
      "x": 8,
      "y": 24,
      "z": 11,
      "name": "Soil_Grass_Cold"
    },
    {
      "x": 8,
      "y": 25,
      "z": 11,
      "name": "Plant_Grass_Lush_Tall"
    },
    {
      "x": 8,
      "y": 10,
      "z": 12,
      "name": "Rock_Marble"
    },
    {
      "x": 8,
      "y": 11,
      "z": 12,
      "name": "Rock_Marble"
    },
    {
      "x": 8,
      "y": 12,
      "z": 12,
      "name": "Rock_Marble"
    },
    {
      "x": 8,
      "y": 22,
      "z": 12,
      "name": "Rock_Marble"
    },
    {
      "x": 8,
      "y": 23,
      "z": 12,
      "name": "Soil_Dirt_Cold"
    },
    {
      "x": 8,
      "y": 24,
      "z": 12,
      "name": "Soil_Dirt_Cold"
    },
    {
      "x": 8,
      "y": 25,
      "z": 12,
      "name": "Soil_Grass_Cold"
    },
    {
      "x": 8,
      "y": 26,
      "z": 12,
      "name": "Plant_Grass_Lush_Tall"
    },
    {
      "x": 8,
      "y": 31,
      "z": 12,
      "name": "Plant_Leaves_Fir",
      "support": 15
    },
    {
      "x": 8,
      "y": 34,
      "z": 12,
      "name": "Plant_Leaves_Fir",
      "support": 15
    },
    {
      "x": 8,
      "y": 10,
      "z": 13,
      "name": "Rock_Marble"
    },
    {
      "x": 8,
      "y": 11,
      "z": 13,
      "name": "Rock_Marble"
    },
    {
      "x": 8,
      "y": 12,
      "z": 13,
      "name": "Rock_Marble"
    },
    {
      "x": 8,
      "y": 22,
      "z": 13,
      "name": "Soil_Dirt_Cold"
    },
    {
      "x": 8,
      "y": 23,
      "z": 13,
      "name": "Soil_Dirt_Cold"
    },
    {
      "x": 8,
      "y": 24,
      "z": 13,
      "name": "Soil_Dirt_Cold"
    },
    {
      "x": 8,
      "y": 25,
      "z": 13,
      "name": "Soil_Grass_Cold"
    },
    {
      "x": 8,
      "y": 31,
      "z": 13,
      "name": "Plant_Leaves_Fir",
      "support": 15
    },
    {
      "x": 8,
      "y": 34,
      "z": 13,
      "name": "Plant_Leaves_Fir",
      "support": 15
    },
    {
      "x": 8,
      "y": 10,
      "z": 14,
      "name": "Rock_Marble"
    },
    {
      "x": 8,
      "y": 11,
      "z": 14,
      "name": "Rock_Marble"
    },
    {
      "x": 8,
      "y": 24,
      "z": 14,
      "name": "Soil_Grass_Cold"
    },
    {
      "x": 8,
      "y": 31,
      "z": 14,
      "name": "Plant_Leaves_Fir",
      "support": 15
    },
    {
      "x": 9,
      "y": 11,
      "z": 11,
      "name": "Rock_Marble"
    },
    {
      "x": 9,
      "y": 12,
      "z": 11,
      "name": "Rock_Marble"
    },
    {
      "x": 9,
      "y": 22,
      "z": 11,
      "name": "Rock_Marble"
    },
    {
      "x": 9,
      "y": 23,
      "z": 11,
      "name": "Soil_Dirt_Cold"
    },
    {
      "x": 9,
      "y": 24,
      "z": 11,
      "name": "Soil_Grass_Cold"
    },
    {
      "x": 9,
      "y": 10,
      "z": 12,
      "name": "Rock_Marble"
    },
    {
      "x": 9,
      "y": 11,
      "z": 12,
      "name": "Rock_Marble"
    },
    {
      "x": 9,
      "y": 12,
      "z": 12,
      "name": "Rock_Marble"
    },
    {
      "x": 9,
      "y": 22,
      "z": 12,
      "name": "Rock_Marble"
    },
    {
      "x": 9,
      "y": 23,
      "z": 12,
      "name": "Soil_Dirt_Cold"
    },
    {
      "x": 9,
      "y": 24,
      "z": 12,
      "name": "Soil_Dirt_Cold"
    },
    {
      "x": 9,
      "y": 25,
      "z": 12,
      "name": "Soil_Grass_Cold"
    },
    {
      "x": 9,
      "y": 31,
      "z": 12,
      "name": "Plant_Leaves_Fir",
      "support": 15
    },
    {
      "x": 9,
      "y": 34,
      "z": 12,
      "name": "Plant_Leaves_Fir",
      "support": 15
    },
    {
      "x": 9,
      "y": 10,
      "z": 13,
      "name": "Rock_Marble"
    },
    {
      "x": 9,
      "y": 11,
      "z": 13,
      "name": "Rock_Marble"
    },
    {
      "x": 9,
      "y": 12,
      "z": 13,
      "name": "Rock_Marble"
    },
    {
      "x": 9,
      "y": 23,
      "z": 13,
      "name": "Soil_Dirt_Cold"
    },
    {
      "x": 9,
      "y": 24,
      "z": 13,
      "name": "Soil_Dirt_Cold"
    },
    {
      "x": 9,
      "y": 25,
      "z": 13,
      "name": "Soil_Grass_Cold"
    },
    {
      "x": 9,
      "y": 31,
      "z": 13,
      "name": "Plant_Leaves_Fir",
      "support": 15
    },
    {
      "x": 9,
      "y": 32,
      "z": 13,
      "name": "Plant_Leaves_Fir",
      "support": 15
    },
    {
      "x": 9,
      "y": 34,
      "z": 13,
      "name": "Plant_Leaves_Fir",
      "support": 15
    },
    {
      "x": 9,
      "y": 36,
      "z": 13,
      "name": "Plant_Leaves_Fir",
      "support": 15
    },
    {
      "x": 9,
      "y": 40,
      "z": 13,
      "name": "Plant_Leaves_Fir",
      "support": 15
    },
    {
      "x": 9,
      "y": 10,
      "z": 14,
      "name": "Rock_Marble"
    },
    {
      "x": 9,
      "y": 11,
      "z": 14,
      "name": "Rock_Marble"
    },
    {
      "x": 9,
      "y": 23,
      "z": 14,
      "name": "Soil_Dirt_Cold"
    },
    {
      "x": 9,
      "y": 24,
      "z": 14,
      "name": "Soil_Grass_Cold"
    },
    {
      "x": 9,
      "y": 25,
      "z": 14,
      "name": "Plant_Grass_Lush_Tall"
    },
    {
      "x": 9,
      "y": 31,
      "z": 14,
      "name": "Plant_Leaves_Fir",
      "support": 15
    },
    {
      "x": 9,
      "y": 34,
      "z": 14,
      "name": "Plant_Leaves_Fir",
      "support": 15
    },
    {
      "x": 9,
      "y": 38,
      "z": 14,
      "name": "Plant_Leaves_Fir",
      "support": 15
    },
    {
      "x": 9,
      "y": 34,
      "z": 15,
      "name": "Plant_Leaves_Fir",
      "support": 15
    },
    {
      "x": 9,
      "y": 38,
      "z": 15,
      "name": "Plant_Leaves_Fir",
      "support": 15
    },
    {
      "x": 9,
      "y": 34,
      "z": 16,
      "name": "Plant_Leaves_Fir",
      "support": 15
    },
    {
      "x": 10,
      "y": 12,
      "z": 10,
      "name": "Rock_Marble"
    },
    {
      "x": 10,
      "y": 31,
      "z": 10,
      "name": "Plant_Leaves_Fir",
      "support": 15
    },
    {
      "x": 10,
      "y": 11,
      "z": 11,
      "name": "Rock_Marble"
    },
    {
      "x": 10,
      "y": 12,
      "z": 11,
      "name": "Rock_Marble"
    },
    {
      "x": 10,
      "y": 22,
      "z": 11,
      "name": "Soil_Dirt_Cold"
    },
    {
      "x": 10,
      "y": 23,
      "z": 11,
      "name": "Soil_Dirt_Cold"
    },
    {
      "x": 10,
      "y": 24,
      "z": 11,
      "name": "Soil_Dirt_Cold"
    },
    {
      "x": 10,
      "y": 25,
      "z": 11,
      "name": "Soil_Grass_Cold"
    },
    {
      "x": 10,
      "y": 26,
      "z": 11,
      "name": "Plant_Grass_Lush_Tall"
    },
    {
      "x": 10,
      "y": 31,
      "z": 11,
      "name": "Plant_Leaves_Fir",
      "support": 15
    },
    {
      "x": 10,
      "y": 11,
      "z": 12,
      "name": "Rock_Marble"
    },
    {
      "x": 10,
      "y": 12,
      "z": 12,
      "name": "Rock_Marble"
    },
    {
      "x": 10,
      "y": 22,
      "z": 12,
      "name": "Rock_Marble"
    },
    {
      "x": 10,
      "y": 23,
      "z": 12,
      "name": "Soil_Dirt_Cold"
    },
    {
      "x": 10,
      "y": 24,
      "z": 12,
      "name": "Soil_Dirt_Cold"
    },
    {
      "x": 10,
      "y": 25,
      "z": 12,
      "name": "Soil_Grass_Cold"
    },
    {
      "x": 10,
      "y": 31,
      "z": 12,
      "name": "Plant_Leaves_Fir",
      "support": 15
    },
    {
      "x": 10,
      "y": 34,
      "z": 12,
      "name": "Plant_Leaves_Fir",
      "support": 15
    },
    {
      "x": 10,
      "y": 40,
      "z": 12,
      "name": "Plant_Leaves_Fir",
      "support": 15
    },
    {
      "x": 10,
      "y": 10,
      "z": 13,
      "name": "Rock_Marble"
    },
    {
      "x": 10,
      "y": 11,
      "z": 13,
      "name": "Rock_Marble"
    },
    {
      "x": 10,
      "y": 12,
      "z": 13,
      "name": "Rock_Marble"
    },
    {
      "x": 10,
      "y": 23,
      "z": 13,
      "name": "Soil_Dirt_Cold"
    },
    {
      "x": 10,
      "y": 24,
      "z": 13,
      "name": "Soil_Dirt_Cold"
    },
    {
      "x": 10,
      "y": 25,
      "z": 13,
      "name": "Soil_Grass_Cold"
    },
    {
      "x": 10,
      "y": 26,
      "z": 13,
      "name": "Plant_Grass_Lush_Tall"
    },
    {
      "x": 10,
      "y": 31,
      "z": 13,
      "name": "Wood_Fir_Branch_Long",
      "support": 15,
      "rotation": 5
    },
    {
      "x": 10,
      "y": 32,
      "z": 13,
      "name": "Plant_Leaves_Fir",
      "support": 15
    },
    {
      "x": 10,
      "y": 34,
      "z": 13,
      "name": "Plant_Leaves_Fir",
      "support": 15
    },
    {
      "x": 10,
      "y": 36,
      "z": 13,
      "name": "Plant_Leaves_Fir",
      "support": 15
    },
    {
      "x": 10,
      "y": 37,
      "z": 13,
      "name": "Plant_Leaves_Fir",
      "support": 15
    },
    {
      "x": 10,
      "y": 38,
      "z": 13,
      "name": "Plant_Leaves_Fir",
      "support": 15
    },
    {
      "x": 10,
      "y": 40,
      "z": 13,
      "name": "Plant_Leaves_Fir",
      "support": 15
    },
    {
      "x": 10,
      "y": 41,
      "z": 13,
      "name": "Plant_Leaves_Fir",
      "support": 15
    },
    {
      "x": 10,
      "y": 11,
      "z": 14,
      "name": "Rock_Marble"
    },
    {
      "x": 10,
      "y": 12,
      "z": 14,
      "name": "Rock_Marble"
    },
    {
      "x": 10,
      "y": 23,
      "z": 14,
      "name": "Soil_Dirt_Cold"
    },
    {
      "x": 10,
      "y": 24,
      "z": 14,
      "name": "Soil_Grass_Cold"
    },
    {
      "x": 10,
      "y": 31,
      "z": 14,
      "name": "Plant_Leaves_Fir",
      "support": 15
    },
    {
      "x": 10,
      "y": 32,
      "z": 14,
      "name": "Plant_Leaves_Fir",
      "support": 15
    },
    {
      "x": 10,
      "y": 34,
      "z": 14,
      "name": "Plant_Leaves_Fir",
      "support": 15
    },
    {
      "x": 10,
      "y": 36,
      "z": 14,
      "name": "Plant_Leaves_Fir",
      "support": 15
    },
    {
      "x": 10,
      "y": 38,
      "z": 14,
      "name": "Plant_Leaves_Fir",
      "support": 15
    },
    {
      "x": 10,
      "y": 40,
      "z": 14,
      "name": "Plant_Leaves_Fir",
      "support": 15
    },
    {
      "x": 10,
      "y": 30,
      "z": 15,
      "name": "Plant_Leaves_Fir",
      "support": 15
    },
    {
      "x": 10,
      "y": 34,
      "z": 15,
      "name": "Plant_Leaves_Fir",
      "support": 15
    },
    {
      "x": 10,
      "y": 38,
      "z": 15,
      "name": "Plant_Leaves_Fir",
      "support": 15
    },
    {
      "x": 10,
      "y": 30,
      "z": 16,
      "name": "Plant_Leaves_Fir",
      "support": 15
    },
    {
      "x": 11,
      "y": 12,
      "z": 10,
      "name": "Rock_Marble"
    },
    {
      "x": 11,
      "y": 13,
      "z": 10,
      "name": "Rock_Marble"
    },
    {
      "x": 11,
      "y": 14,
      "z": 10,
      "name": "Rock_Marble"
    },
    {
      "x": 11,
      "y": 23,
      "z": 10,
      "name": "Soil_Grass_Cold"
    },
    {
      "x": 11,
      "y": 31,
      "z": 10,
      "name": "Plant_Leaves_Fir",
      "support": 15
    },
    {
      "x": 11,
      "y": 32,
      "z": 10,
      "name": "Plant_Leaves_Fir",
      "support": 15
    },
    {
      "x": 11,
      "y": 11,
      "z": 11,
      "name": "Rock_Marble"
    },
    {
      "x": 11,
      "y": 12,
      "z": 11,
      "name": "Rock_Marble"
    },
    {
      "x": 11,
      "y": 13,
      "z": 11,
      "name": "Rock_Marble"
    },
    {
      "x": 11,
      "y": 14,
      "z": 11,
      "name": "Rock_Marble"
    },
    {
      "x": 11,
      "y": 20,
      "z": 11,
      "name": "Rock_Marble"
    },
    {
      "x": 11,
      "y": 21,
      "z": 11,
      "name": "Rock_Marble"
    },
    {
      "x": 11,
      "y": 22,
      "z": 11,
      "name": "Soil_Dirt_Cold"
    },
    {
      "x": 11,
      "y": 23,
      "z": 11,
      "name": "Soil_Dirt_Cold"
    },
    {
      "x": 11,
      "y": 24,
      "z": 11,
      "name": "Soil_Grass_Cold"
    },
    {
      "x": 11,
      "y": 31,
      "z": 11,
      "name": "Plant_Leaves_Fir",
      "support": 15
    },
    {
      "x": 11,
      "y": 32,
      "z": 11,
      "name": "Plant_Leaves_Fir",
      "support": 15
    },
    {
      "x": 11,
      "y": 35,
      "z": 11,
      "name": "Plant_Leaves_Fir",
      "support": 15
    },
    {
      "x": 11,
      "y": 38,
      "z": 11,
      "name": "Plant_Leaves_Fir",
      "support": 15
    },
    {
      "x": 11,
      "y": 11,
      "z": 12,
      "name": "Rock_Marble"
    },
    {
      "x": 11,
      "y": 12,
      "z": 12,
      "name": "Rock_Marble"
    },
    {
      "x": 11,
      "y": 13,
      "z": 12,
      "name": "Rock_Marble"
    },
    {
      "x": 11,
      "y": 21,
      "z": 12,
      "name": "Rock_Marble"
    },
    {
      "x": 11,
      "y": 22,
      "z": 12,
      "name": "Rock_Marble"
    },
    {
      "x": 11,
      "y": 23,
      "z": 12,
      "name": "Soil_Dirt_Cold"
    },
    {
      "x": 11,
      "y": 24,
      "z": 12,
      "name": "Soil_Dirt_Cold"
    },
    {
      "x": 11,
      "y": 25,
      "z": 12,
      "name": "Soil_Grass_Cold"
    },
    {
      "x": 11,
      "y": 31,
      "z": 12,
      "name": "Plant_Leaves_Fir",
      "support": 15
    },
    {
      "x": 11,
      "y": 34,
      "z": 12,
      "name": "Plant_Leaves_Fir",
      "support": 15
    },
    {
      "x": 11,
      "y": 35,
      "z": 12,
      "name": "Plant_Leaves_Fir",
      "support": 15
    },
    {
      "x": 11,
      "y": 36,
      "z": 12,
      "name": "Plant_Leaves_Fir",
      "support": 15
    },
    {
      "x": 11,
      "y": 38,
      "z": 12,
      "name": "Plant_Leaves_Fir",
      "support": 15
    },
    {
      "x": 11,
      "y": 40,
      "z": 12,
      "name": "Plant_Leaves_Fir",
      "support": 15
    },
    {
      "x": 11,
      "y": 41,
      "z": 12,
      "name": "Plant_Leaves_Fir",
      "support": 15
    },
    {
      "x": 11,
      "y": 11,
      "z": 13,
      "name": "Rock_Marble"
    },
    {
      "x": 11,
      "y": 12,
      "z": 13,
      "name": "Rock_Marble"
    },
    {
      "x": 11,
      "y": 21,
      "z": 13,
      "name": "Wood_Fir_Roots"
    },
    {
      "x": 11,
      "y": 22,
      "z": 13,
      "name": "Wood_Fir_Trunk_Full",
      "support": 15
    },
    {
      "x": 11,
      "y": 23,
      "z": 13,
      "name": "Wood_Fir_Trunk_Full",
      "support": 15
    },
    {
      "x": 11,
      "y": 24,
      "z": 13,
      "name": "Soil_Grass_Cold"
    },
    {
      "x": 11,
      "y": 31,
      "z": 13,
      "name": "Wood_Fir_Branch_Long",
      "support": 15,
      "rotation": 5
    },
    {
      "x": 11,
      "y": 34,
      "z": 13,
      "name": "Plant_Leaves_Fir",
      "support": 15
    },
    {
      "x": 11,
      "y": 36,
      "z": 13,
      "name": "Wood_Fir_Branch_Long",
      "support": 15,
      "rotation": 5
    },
    {
      "x": 11,
      "y": 37,
      "z": 13,
      "name": "Plant_Leaves_Fir",
      "support": 15
    },
    {
      "x": 11,
      "y": 38,
      "z": 13,
      "name": "Plant_Leaves_Fir",
      "support": 15
    },
    {
      "x": 11,
      "y": 40,
      "z": 13,
      "name": "Wood_Fir_Branch_Long",
      "support": 15,
      "rotation": 5
    },
    {
      "x": 11,
      "y": 41,
      "z": 13,
      "name": "Plant_Leaves_Fir",
      "support": 15
    },
    {
      "x": 11,
      "y": 42,
      "z": 13,
      "name": "Plant_Leaves_Fir",
      "support": 15
    },
    {
      "x": 11,
      "y": 43,
      "z": 13,
      "name": "Plant_Leaves_Fir",
      "support": 15
    },
    {
      "x": 11,
      "y": 12,
      "z": 14,
      "name": "Rock_Marble"
    },
    {
      "x": 11,
      "y": 23,
      "z": 14,
      "name": "Soil_Grass_Cold"
    },
    {
      "x": 11,
      "y": 30,
      "z": 14,
      "name": "Plant_Leaves_Fir",
      "support": 15
    },
    {
      "x": 11,
      "y": 33,
      "z": 14,
      "name": "Plant_Leaves_Fir",
      "support": 15
    },
    {
      "x": 11,
      "y": 34,
      "z": 14,
      "name": "Plant_Leaves_Fir",
      "support": 15
    },
    {
      "x": 11,
      "y": 36,
      "z": 14,
      "name": "Plant_Leaves_Fir",
      "support": 15
    },
    {
      "x": 11,
      "y": 37,
      "z": 14,
      "name": "Plant_Leaves_Fir",
      "support": 15
    },
    {
      "x": 11,
      "y": 38,
      "z": 14,
      "name": "Plant_Leaves_Fir",
      "support": 15
    },
    {
      "x": 11,
      "y": 40,
      "z": 14,
      "name": "Plant_Leaves_Fir",
      "support": 15
    },
    {
      "x": 11,
      "y": 41,
      "z": 14,
      "name": "Plant_Leaves_Fir",
      "support": 15
    },
    {
      "x": 11,
      "y": 30,
      "z": 15,
      "name": "Plant_Leaves_Fir",
      "support": 15
    },
    {
      "x": 11,
      "y": 33,
      "z": 15,
      "name": "Plant_Leaves_Fir",
      "support": 15
    },
    {
      "x": 11,
      "y": 35,
      "z": 15,
      "name": "Plant_Leaves_Fir",
      "support": 15
    },
    {
      "x": 11,
      "y": 37,
      "z": 15,
      "name": "Plant_Leaves_Fir",
      "support": 15
    },
    {
      "x": 11,
      "y": 38,
      "z": 15,
      "name": "Plant_Leaves_Fir",
      "support": 15
    },
    {
      "x": 11,
      "y": 40,
      "z": 15,
      "name": "Plant_Leaves_Fir",
      "support": 15
    },
    {
      "x": 11,
      "y": 30,
      "z": 16,
      "name": "Plant_Leaves_Fir",
      "support": 15
    },
    {
      "x": 11,
      "y": 33,
      "z": 16,
      "name": "Plant_Leaves_Fir",
      "support": 15
    },
    {
      "x": 11,
      "y": 30,
      "z": 17,
      "name": "Plant_Leaves_Fir",
      "support": 15
    },
    {
      "x": 11,
      "y": 33,
      "z": 17,
      "name": "Plant_Leaves_Fir",
      "support": 15
    },
    {
      "x": 11,
      "y": 30,
      "z": 18,
      "name": "Plant_Leaves_Fir",
      "support": 15
    },
    {
      "x": 12,
      "y": 13,
      "z": 9,
      "name": "Rock_Marble"
    },
    {
      "x": 12,
      "y": 32,
      "z": 9,
      "name": "Plant_Leaves_Fir",
      "support": 15
    },
    {
      "x": 12,
      "y": 13,
      "z": 10,
      "name": "Rock_Marble"
    },
    {
      "x": 12,
      "y": 14,
      "z": 10,
      "name": "Rock_Marble"
    },
    {
      "x": 12,
      "y": 15,
      "z": 10,
      "name": "Rock_Marble"
    },
    {
      "x": 12,
      "y": 16,
      "z": 10,
      "name": "Rock_Marble"
    },
    {
      "x": 12,
      "y": 19,
      "z": 10,
      "name": "Rock_Marble"
    },
    {
      "x": 12,
      "y": 20,
      "z": 10,
      "name": "Rock_Marble"
    },
    {
      "x": 12,
      "y": 21,
      "z": 10,
      "name": "Soil_Dirt_Cold"
    },
    {
      "x": 12,
      "y": 22,
      "z": 10,
      "name": "Soil_Dirt_Cold"
    },
    {
      "x": 12,
      "y": 23,
      "z": 10,
      "name": "Soil_Grass_Cold"
    },
    {
      "x": 12,
      "y": 24,
      "z": 10,
      "name": "Plant_Grass_Lush_Tall"
    },
    {
      "x": 12,
      "y": 33,
      "z": 10,
      "name": "Plant_Leaves_Fir",
      "support": 15
    },
    {
      "x": 12,
      "y": 35,
      "z": 10,
      "name": "Plant_Leaves_Fir",
      "support": 15
    },
    {
      "x": 12,
      "y": 38,
      "z": 10,
      "name": "Plant_Leaves_Fir",
      "support": 15
    },
    {
      "x": 12,
      "y": 11,
      "z": 11,
      "name": "Rock_Marble"
    },
    {
      "x": 12,
      "y": 12,
      "z": 11,
      "name": "Rock_Marble"
    },
    {
      "x": 12,
      "y": 13,
      "z": 11,
      "name": "Rock_Marble"
    },
    {
      "x": 12,
      "y": 14,
      "z": 11,
      "name": "Rock_Marble"
    },
    {
      "x": 12,
      "y": 15,
      "z": 11,
      "name": "Rock_Marble"
    },
    {
      "x": 12,
      "y": 16,
      "z": 11,
      "name": "Rock_Marble"
    },
    {
      "x": 12,
      "y": 17,
      "z": 11,
      "name": "Rock_Marble"
    },
    {
      "x": 12,
      "y": 19,
      "z": 11,
      "name": "Rock_Marble"
    },
    {
      "x": 12,
      "y": 20,
      "z": 11,
      "name": "Rock_Marble"
    },
    {
      "x": 12,
      "y": 21,
      "z": 11,
      "name": "Rock_Marble"
    },
    {
      "x": 12,
      "y": 22,
      "z": 11,
      "name": "Soil_Dirt_Cold"
    },
    {
      "x": 12,
      "y": 23,
      "z": 11,
      "name": "Soil_Grass_Cold"
    },
    {
      "x": 12,
      "y": 32,
      "z": 11,
      "name": "Wood_Fir_Branch_Long",
      "support": 15,
      "rotation": 4
    },
    {
      "x": 12,
      "y": 33,
      "z": 11,
      "name": "Plant_Leaves_Fir",
      "support": 15
    },
    {
      "x": 12,
      "y": 35,
      "z": 11,
      "name": "Plant_Leaves_Fir",
      "support": 15
    },
    {
      "x": 12,
      "y": 38,
      "z": 11,
      "name": "Plant_Leaves_Fir",
      "support": 15
    },
    {
      "x": 12,
      "y": 40,
      "z": 11,
      "name": "Plant_Leaves_Fir",
      "support": 15
    },
    {
      "x": 12,
      "y": 11,
      "z": 12,
      "name": "Rock_Marble"
    },
    {
      "x": 12,
      "y": 12,
      "z": 12,
      "name": "Rock_Marble"
    },
    {
      "x": 12,
      "y": 13,
      "z": 12,
      "name": "Rock_Marble"
    },
    {
      "x": 12,
      "y": 14,
      "z": 12,
      "name": "Rock_Marble"
    },
    {
      "x": 12,
      "y": 15,
      "z": 12,
      "name": "Rock_Marble"
    },
    {
      "x": 12,
      "y": 21,
      "z": 12,
      "name": "Rock_Marble"
    },
    {
      "x": 12,
      "y": 22,
      "z": 12,
      "name": "Wood_Fir_Roots"
    },
    {
      "x": 12,
      "y": 23,
      "z": 12,
      "name": "Wood_Fir_Trunk_Full",
      "support": 15
    },
    {
      "x": 12,
      "y": 24,
      "z": 12,
      "name": "Wood_Fir_Trunk_Full",
      "support": 15
    },
    {
      "x": 12,
      "y": 31,
      "z": 12,
      "name": "Plant_Leaves_Fir",
      "support": 15
    },
    {
      "x": 12,
      "y": 32,
      "z": 12,
      "name": "Wood_Fir_Branch_Long",
      "support": 15,
      "rotation": 4
    },
    {
      "x": 12,
      "y": 35,
      "z": 12,
      "name": "Wood_Fir_Branch_Long",
      "support": 15,
      "rotation": 4
    },
    {
      "x": 12,
      "y": 37,
      "z": 12,
      "name": "Plant_Leaves_Fir",
      "support": 15
    },
    {
      "x": 12,
      "y": 38,
      "z": 12,
      "name": "Plant_Leaves_Fir",
      "support": 15
    },
    {
      "x": 12,
      "y": 40,
      "z": 12,
      "name": "Plant_Leaves_Fir",
      "support": 15
    },
    {
      "x": 12,
      "y": 41,
      "z": 12,
      "name": "Plant_Leaves_Fir",
      "support": 15
    },
    {
      "x": 12,
      "y": 42,
      "z": 12,
      "name": "Plant_Leaves_Fir",
      "support": 15
    },
    {
      "x": 12,
      "y": 43,
      "z": 12,
      "name": "Plant_Leaves_Fir",
      "support": 15
    },
    {
      "x": 12,
      "y": 11,
      "z": 13,
      "name": "Rock_Marble"
    },
    {
      "x": 12,
      "y": 12,
      "z": 13,
      "name": "Rock_Marble"
    },
    {
      "x": 12,
      "y": 13,
      "z": 13,
      "name": "Rock_Marble"
    },
    {
      "x": 12,
      "y": 20,
      "z": 13,
      "name": "Wood_Fir_Roots"
    },
    {
      "x": 12,
      "y": 21,
      "z": 13,
      "name": "Wood_Fir_Trunk_Full",
      "support": 15
    },
    {
      "x": 12,
      "y": 22,
      "z": 13,
      "name": "Wood_Fir_Trunk",
      "support": 15
    },
    {
      "x": 12,
      "y": 23,
      "z": 13,
      "name": "Wood_Fir_Trunk",
      "support": 15
    },
    {
      "x": 12,
      "y": 24,
      "z": 13,
      "name": "Wood_Fir_Trunk",
      "support": 15
    },
    {
      "x": 12,
      "y": 25,
      "z": 13,
      "name": "Wood_Fir_Trunk_Full",
      "support": 15
    },
    {
      "x": 12,
      "y": 26,
      "z": 13,
      "name": "Wood_Fir_Trunk",
      "support": 15
    },
    {
      "x": 12,
      "y": 27,
      "z": 13,
      "name": "Wood_Fir_Trunk",
      "support": 15
    },
    {
      "x": 12,
      "y": 28,
      "z": 13,
      "name": "Wood_Fir_Trunk",
      "support": 15
    },
    {
      "x": 12,
      "y": 29,
      "z": 13,
      "name": "Wood_Fir_Trunk",
      "support": 15
    },
    {
      "x": 12,
      "y": 30,
      "z": 13,
      "name": "Wood_Fir_Trunk",
      "support": 15
    },
    {
      "x": 12,
      "y": 31,
      "z": 13,
      "name": "Wood_Fir_Trunk",
      "support": 15
    },
    {
      "x": 12,
      "y": 32,
      "z": 13,
      "name": "Wood_Fir_Trunk",
      "support": 15
    },
    {
      "x": 12,
      "y": 33,
      "z": 13,
      "name": "Wood_Fir_Trunk",
      "support": 15
    },
    {
      "x": 12,
      "y": 34,
      "z": 13,
      "name": "Wood_Fir_Trunk",
      "support": 15
    },
    {
      "x": 12,
      "y": 35,
      "z": 13,
      "name": "Wood_Fir_Trunk",
      "support": 15
    },
    {
      "x": 12,
      "y": 36,
      "z": 13,
      "name": "Wood_Fir_Trunk",
      "support": 15
    },
    {
      "x": 12,
      "y": 37,
      "z": 13,
      "name": "Wood_Fir_Trunk",
      "support": 15
    },
    {
      "x": 12,
      "y": 38,
      "z": 13,
      "name": "Wood_Fir_Trunk",
      "support": 15
    },
    {
      "x": 12,
      "y": 39,
      "z": 13,
      "name": "Wood_Fir_Trunk",
      "support": 15
    },
    {
      "x": 12,
      "y": 40,
      "z": 13,
      "name": "Wood_Fir_Trunk",
      "support": 15
    },
    {
      "x": 12,
      "y": 41,
      "z": 13,
      "name": "Wood_Fir_Trunk_Full",
      "support": 15
    },
    {
      "x": 12,
      "y": 42,
      "z": 13,
      "name": "Plant_Leaves_Fir",
      "support": 15
    },
    {
      "x": 12,
      "y": 43,
      "z": 13,
      "name": "Plant_Leaves_Fir",
      "support": 15
    },
    {
      "x": 12,
      "y": 44,
      "z": 13,
      "name": "Plant_Leaves_Fir",
      "support": 15
    },
    {
      "x": 12,
      "y": 45,
      "z": 13,
      "name": "Plant_Leaves_Fir",
      "support": 15
    },
    {
      "x": 12,
      "y": 12,
      "z": 14,
      "name": "Rock_Marble"
    },
    {
      "x": 12,
      "y": 13,
      "z": 14,
      "name": "Rock_Marble"
    },
    {
      "x": 12,
      "y": 22,
      "z": 14,
      "name": "Wood_Fir_Roots"
    },
    {
      "x": 12,
      "y": 23,
      "z": 14,
      "name": "Wood_Fir_Trunk_Full",
      "support": 15
    },
    {
      "x": 12,
      "y": 24,
      "z": 14,
      "name": "Wood_Fir_Trunk_Full",
      "support": 15
    },
    {
      "x": 12,
      "y": 25,
      "z": 14,
      "name": "Wood_Fir_Trunk_Full",
      "support": 15
    },
    {
      "x": 12,
      "y": 30,
      "z": 14,
      "name": "Wood_Fir_Branch_Long",
      "support": 15,
      "rotation": 4
    },
    {
      "x": 12,
      "y": 32,
      "z": 14,
      "name": "Plant_Leaves_Fir",
      "support": 15
    },
    {
      "x": 12,
      "y": 33,
      "z": 14,
      "name": "Wood_Fir_Branch_Long",
      "support": 15,
      "rotation": 4
    },
    {
      "x": 12,
      "y": 35,
      "z": 14,
      "name": "Plant_Leaves_Fir",
      "support": 15
    },
    {
      "x": 12,
      "y": 37,
      "z": 14,
      "name": "Wood_Fir_Branch_Long",
      "support": 15,
      "rotation": 4
    },
    {
      "x": 12,
      "y": 38,
      "z": 14,
      "name": "Plant_Leaves_Fir",
      "support": 15
    },
    {
      "x": 12,
      "y": 40,
      "z": 14,
      "name": "Wood_Fir_Branch_Long",
      "support": 15,
      "rotation": 4
    },
    {
      "x": 12,
      "y": 41,
      "z": 14,
      "name": "Plant_Leaves_Fir",
      "support": 15
    },
    {
      "x": 12,
      "y": 42,
      "z": 14,
      "name": "Plant_Leaves_Fir",
      "support": 15
    },
    {
      "x": 12,
      "y": 30,
      "z": 15,
      "name": "Wood_Fir_Branch_Long",
      "support": 15,
      "rotation": 4
    },
    {
      "x": 12,
      "y": 32,
      "z": 15,
      "name": "Plant_Leaves_Fir",
      "support": 15
    },
    {
      "x": 12,
      "y": 33,
      "z": 15,
      "name": "Wood_Fir_Branch_Long",
      "support": 15,
      "rotation": 4
    },
    {
      "x": 12,
      "y": 35,
      "z": 15,
      "name": "Plant_Leaves_Fir",
      "support": 15
    },
    {
      "x": 12,
      "y": 37,
      "z": 15,
      "name": "Plant_Leaves_Fir",
      "support": 15
    },
    {
      "x": 12,
      "y": 40,
      "z": 15,
      "name": "Plant_Leaves_Fir",
      "support": 15
    },
    {
      "x": 12,
      "y": 41,
      "z": 15,
      "name": "Plant_Leaves_Fir",
      "support": 15
    },
    {
      "x": 12,
      "y": 30,
      "z": 16,
      "name": "Plant_Leaves_Fir",
      "support": 15
    },
    {
      "x": 12,
      "y": 32,
      "z": 16,
      "name": "Plant_Leaves_Fir",
      "support": 15
    },
    {
      "x": 12,
      "y": 33,
      "z": 16,
      "name": "Plant_Leaves_Fir",
      "support": 15
    },
    {
      "x": 12,
      "y": 35,
      "z": 16,
      "name": "Plant_Leaves_Fir",
      "support": 15
    },
    {
      "x": 12,
      "y": 37,
      "z": 16,
      "name": "Plant_Leaves_Fir",
      "support": 15
    },
    {
      "x": 12,
      "y": 40,
      "z": 16,
      "name": "Plant_Leaves_Fir",
      "support": 15
    },
    {
      "x": 12,
      "y": 30,
      "z": 17,
      "name": "Plant_Leaves_Fir",
      "support": 15
    },
    {
      "x": 12,
      "y": 33,
      "z": 17,
      "name": "Plant_Leaves_Fir",
      "support": 15
    },
    {
      "x": 13,
      "y": 13,
      "z": 9,
      "name": "Rock_Marble"
    },
    {
      "x": 13,
      "y": 14,
      "z": 9,
      "name": "Rock_Marble"
    },
    {
      "x": 13,
      "y": 15,
      "z": 9,
      "name": "Rock_Marble"
    },
    {
      "x": 13,
      "y": 20,
      "z": 9,
      "name": "Soil_Dirt_Cold"
    },
    {
      "x": 13,
      "y": 21,
      "z": 9,
      "name": "Soil_Dirt_Cold"
    },
    {
      "x": 13,
      "y": 22,
      "z": 9,
      "name": "Soil_Grass_Cold"
    },
    {
      "x": 13,
      "y": 13,
      "z": 10,
      "name": "Rock_Marble"
    },
    {
      "x": 13,
      "y": 14,
      "z": 10,
      "name": "Rock_Marble"
    },
    {
      "x": 13,
      "y": 15,
      "z": 10,
      "name": "Rock_Marble"
    },
    {
      "x": 13,
      "y": 16,
      "z": 10,
      "name": "Rock_Marble"
    },
    {
      "x": 13,
      "y": 17,
      "z": 10,
      "name": "Rock_Marble"
    },
    {
      "x": 13,
      "y": 18,
      "z": 10,
      "name": "Rock_Marble"
    },
    {
      "x": 13,
      "y": 19,
      "z": 10,
      "name": "Rock_Marble"
    },
    {
      "x": 13,
      "y": 20,
      "z": 10,
      "name": "Rock_Marble"
    },
    {
      "x": 13,
      "y": 21,
      "z": 10,
      "name": "Soil_Dirt_Cold"
    },
    {
      "x": 13,
      "y": 22,
      "z": 10,
      "name": "Soil_Dirt_Cold"
    },
    {
      "x": 13,
      "y": 23,
      "z": 10,
      "name": "Soil_Grass_Cold"
    },
    {
      "x": 13,
      "y": 31,
      "z": 10,
      "name": "Plant_Leaves_Fir",
      "support": 15
    },
    {
      "x": 13,
      "y": 12,
      "z": 11,
      "name": "Rock_Marble"
    },
    {
      "x": 13,
      "y": 13,
      "z": 11,
      "name": "Rock_Marble"
    },
    {
      "x": 13,
      "y": 14,
      "z": 11,
      "name": "Rock_Marble"
    },
    {
      "x": 13,
      "y": 15,
      "z": 11,
      "name": "Rock_Marble"
    },
    {
      "x": 13,
      "y": 16,
      "z": 11,
      "name": "Rock_Marble"
    },
    {
      "x": 13,
      "y": 17,
      "z": 11,
      "name": "Rock_Marble"
    },
    {
      "x": 13,
      "y": 18,
      "z": 11,
      "name": "Rock_Marble"
    },
    {
      "x": 13,
      "y": 19,
      "z": 11,
      "name": "Rock_Marble"
    },
    {
      "x": 13,
      "y": 20,
      "z": 11,
      "name": "Rock_Marble"
    },
    {
      "x": 13,
      "y": 21,
      "z": 11,
      "name": "Rock_Marble"
    },
    {
      "x": 13,
      "y": 22,
      "z": 11,
      "name": "Soil_Dirt_Cold"
    },
    {
      "x": 13,
      "y": 23,
      "z": 11,
      "name": "Soil_Grass_Cold"
    },
    {
      "x": 13,
      "y": 31,
      "z": 11,
      "name": "Plant_Leaves_Fir",
      "support": 15
    },
    {
      "x": 13,
      "y": 32,
      "z": 11,
      "name": "Plant_Leaves_Fir",
      "support": 15
    },
    {
      "x": 13,
      "y": 38,
      "z": 11,
      "name": "Plant_Leaves_Fir",
      "support": 15
    },
    {
      "x": 13,
      "y": 40,
      "z": 11,
      "name": "Plant_Leaves_Fir",
      "support": 15
    },
    {
      "x": 13,
      "y": 11,
      "z": 12,
      "name": "Rock_Marble"
    },
    {
      "x": 13,
      "y": 12,
      "z": 12,
      "name": "Rock_Marble"
    },
    {
      "x": 13,
      "y": 13,
      "z": 12,
      "name": "Rock_Marble"
    },
    {
      "x": 13,
      "y": 14,
      "z": 12,
      "name": "Rock_Marble"
    },
    {
      "x": 13,
      "y": 15,
      "z": 12,
      "name": "Rock_Marble"
    },
    {
      "x": 13,
      "y": 16,
      "z": 12,
      "name": "Rock_Marble"
    },
    {
      "x": 13,
      "y": 17,
      "z": 12,
      "name": "Rock_Marble"
    },
    {
      "x": 13,
      "y": 20,
      "z": 12,
      "name": "Soil_Dirt_Cold"
    },
    {
      "x": 13,
      "y": 21,
      "z": 12,
      "name": "Rock_Marble"
    },
    {
      "x": 13,
      "y": 22,
      "z": 12,
      "name": "Soil_Dirt_Cold"
    },
    {
      "x": 13,
      "y": 23,
      "z": 12,
      "name": "Soil_Grass_Cold"
    },
    {
      "x": 13,
      "y": 31,
      "z": 12,
      "name": "Plant_Leaves_Fir",
      "support": 15
    },
    {
      "x": 13,
      "y": 32,
      "z": 12,
      "name": "Plant_Leaves_Fir",
      "support": 15
    },
    {
      "x": 13,
      "y": 33,
      "z": 12,
      "name": "Plant_Leaves_Fir",
      "support": 15
    },
    {
      "x": 13,
      "y": 34,
      "z": 12,
      "name": "Plant_Leaves_Fir",
      "support": 15
    },
    {
      "x": 13,
      "y": 35,
      "z": 12,
      "name": "Plant_Leaves_Fir",
      "support": 15
    },
    {
      "x": 13,
      "y": 38,
      "z": 12,
      "name": "Plant_Leaves_Fir",
      "support": 15
    },
    {
      "x": 13,
      "y": 40,
      "z": 12,
      "name": "Plant_Leaves_Fir",
      "support": 15
    },
    {
      "x": 13,
      "y": 11,
      "z": 13,
      "name": "Rock_Marble"
    },
    {
      "x": 13,
      "y": 12,
      "z": 13,
      "name": "Rock_Marble"
    },
    {
      "x": 13,
      "y": 13,
      "z": 13,
      "name": "Rock_Marble"
    },
    {
      "x": 13,
      "y": 14,
      "z": 13,
      "name": "Rock_Marble"
    },
    {
      "x": 13,
      "y": 15,
      "z": 13,
      "name": "Rock_Marble"
    },
    {
      "x": 13,
      "y": 16,
      "z": 13,
      "name": "Rock_Marble"
    },
    {
      "x": 13,
      "y": 21,
      "z": 13,
      "name": "Wood_Fir_Roots"
    },
    {
      "x": 13,
      "y": 22,
      "z": 13,
      "name": "Wood_Fir_Trunk_Full",
      "support": 15
    },
    {
      "x": 13,
      "y": 23,
      "z": 13,
      "name": "Wood_Fir_Trunk_Full",
      "support": 15
    },
    {
      "x": 13,
      "y": 31,
      "z": 13,
      "name": "Wood_Fir_Branch_Long",
      "support": 15,
      "rotation": 5
    },
    {
      "x": 13,
      "y": 32,
      "z": 13,
      "name": "Plant_Leaves_Fir",
      "support": 15
    },
    {
      "x": 13,
      "y": 33,
      "z": 13,
      "name": "Plant_Leaves_Fir",
      "support": 15
    },
    {
      "x": 13,
      "y": 34,
      "z": 13,
      "name": "Wood_Fir_Branch_Long",
      "support": 15,
      "rotation": 5
    },
    {
      "x": 13,
      "y": 37,
      "z": 13,
      "name": "Plant_Leaves_Fir",
      "support": 15
    },
    {
      "x": 13,
      "y": 38,
      "z": 13,
      "name": "Wood_Fir_Branch_Long",
      "support": 15,
      "rotation": 5
    },
    {
      "x": 13,
      "y": 40,
      "z": 13,
      "name": "Plant_Leaves_Fir",
      "support": 15
    },
    {
      "x": 13,
      "y": 41,
      "z": 13,
      "name": "Plant_Leaves_Fir",
      "support": 15
    },
    {
      "x": 13,
      "y": 42,
      "z": 13,
      "name": "Plant_Leaves_Fir",
      "support": 15
    },
    {
      "x": 13,
      "y": 13,
      "z": 14,
      "name": "Rock_Marble"
    },
    {
      "x": 13,
      "y": 30,
      "z": 14,
      "name": "Plant_Leaves_Fir",
      "support": 15
    },
    {
      "x": 13,
      "y": 32,
      "z": 14,
      "name": "Plant_Leaves_Fir",
      "support": 15
    },
    {
      "x": 13,
      "y": 33,
      "z": 14,
      "name": "Plant_Leaves_Fir",
      "support": 15
    },
    {
      "x": 13,
      "y": 34,
      "z": 14,
      "name": "Plant_Leaves_Fir",
      "support": 15
    },
    {
      "x": 13,
      "y": 35,
      "z": 14,
      "name": "Plant_Leaves_Fir",
      "support": 15
    },
    {
      "x": 13,
      "y": 37,
      "z": 14,
      "name": "Plant_Leaves_Fir",
      "support": 15
    },
    {
      "x": 13,
      "y": 38,
      "z": 14,
      "name": "Plant_Leaves_Fir",
      "support": 15
    },
    {
      "x": 13,
      "y": 40,
      "z": 14,
      "name": "Plant_Leaves_Fir",
      "support": 15
    },
    {
      "x": 13,
      "y": 30,
      "z": 15,
      "name": "Plant_Leaves_Fir",
      "support": 15
    },
    {
      "x": 13,
      "y": 32,
      "z": 15,
      "name": "Plant_Leaves_Fir",
      "support": 15
    },
    {
      "x": 13,
      "y": 33,
      "z": 15,
      "name": "Plant_Leaves_Fir",
      "support": 15
    },
    {
      "x": 13,
      "y": 35,
      "z": 15,
      "name": "Plant_Leaves_Fir",
      "support": 15
    },
    {
      "x": 13,
      "y": 37,
      "z": 15,
      "name": "Plant_Leaves_Fir",
      "support": 15
    },
    {
      "x": 13,
      "y": 40,
      "z": 15,
      "name": "Plant_Leaves_Fir",
      "support": 15
    },
    {
      "x": 13,
      "y": 30,
      "z": 16,
      "name": "Plant_Leaves_Fir",
      "support": 15
    },
    {
      "x": 13,
      "y": 32,
      "z": 16,
      "name": "Plant_Leaves_Fir",
      "support": 15
    },
    {
      "x": 13,
      "y": 33,
      "z": 16,
      "name": "Plant_Leaves_Fir",
      "support": 15
    },
    {
      "x": 14,
      "y": 14,
      "z": 9,
      "name": "Rock_Marble"
    },
    {
      "x": 14,
      "y": 15,
      "z": 9,
      "name": "Rock_Marble"
    },
    {
      "x": 14,
      "y": 16,
      "z": 9,
      "name": "Rock_Marble"
    },
    {
      "x": 14,
      "y": 17,
      "z": 9,
      "name": "Rock_Marble"
    },
    {
      "x": 14,
      "y": 19,
      "z": 9,
      "name": "Rock_Marble"
    },
    {
      "x": 14,
      "y": 20,
      "z": 9,
      "name": "Rock_Marble"
    },
    {
      "x": 14,
      "y": 21,
      "z": 9,
      "name": "Soil_Grass_Cold"
    },
    {
      "x": 14,
      "y": 22,
      "z": 9,
      "name": "Plant_Grass_Lush_Tall"
    },
    {
      "x": 14,
      "y": 13,
      "z": 10,
      "name": "Rock_Marble"
    },
    {
      "x": 14,
      "y": 14,
      "z": 10,
      "name": "Rock_Marble"
    },
    {
      "x": 14,
      "y": 15,
      "z": 10,
      "name": "Rock_Marble"
    },
    {
      "x": 14,
      "y": 16,
      "z": 10,
      "name": "Rock_Marble"
    },
    {
      "x": 14,
      "y": 17,
      "z": 10,
      "name": "Rock_Marble"
    },
    {
      "x": 14,
      "y": 18,
      "z": 10,
      "name": "Rock_Marble"
    },
    {
      "x": 14,
      "y": 19,
      "z": 10,
      "name": "Rock_Marble"
    },
    {
      "x": 14,
      "y": 20,
      "z": 10,
      "name": "Rock_Marble"
    },
    {
      "x": 14,
      "y": 21,
      "z": 10,
      "name": "Soil_Dirt_Cold"
    },
    {
      "x": 14,
      "y": 22,
      "z": 10,
      "name": "Soil_Dirt_Cold"
    },
    {
      "x": 14,
      "y": 23,
      "z": 10,
      "name": "Soil_Grass_Cold"
    },
    {
      "x": 14,
      "y": 31,
      "z": 10,
      "name": "Plant_Leaves_Fir",
      "support": 15
    },
    {
      "x": 14,
      "y": 12,
      "z": 11,
      "name": "Rock_Marble"
    },
    {
      "x": 14,
      "y": 13,
      "z": 11,
      "name": "Rock_Marble"
    },
    {
      "x": 14,
      "y": 14,
      "z": 11,
      "name": "Rock_Marble"
    },
    {
      "x": 14,
      "y": 15,
      "z": 11,
      "name": "Rock_Marble"
    },
    {
      "x": 14,
      "y": 16,
      "z": 11,
      "name": "Rock_Marble"
    },
    {
      "x": 14,
      "y": 17,
      "z": 11,
      "name": "Rock_Marble"
    },
    {
      "x": 14,
      "y": 18,
      "z": 11,
      "name": "Rock_Marble"
    },
    {
      "x": 14,
      "y": 19,
      "z": 11,
      "name": "Soil_Dirt_Cold"
    },
    {
      "x": 14,
      "y": 20,
      "z": 11,
      "name": "Soil_Dirt_Cold"
    },
    {
      "x": 14,
      "y": 21,
      "z": 11,
      "name": "Soil_Dirt_Cold"
    },
    {
      "x": 14,
      "y": 22,
      "z": 11,
      "name": "Soil_Dirt_Cold"
    },
    {
      "x": 14,
      "y": 23,
      "z": 11,
      "name": "Soil_Grass_Cold"
    },
    {
      "x": 14,
      "y": 24,
      "z": 11,
      "name": "Plant_Grass_Lush_Tall"
    },
    {
      "x": 14,
      "y": 31,
      "z": 11,
      "name": "Plant_Leaves_Fir",
      "support": 15
    },
    {
      "x": 14,
      "y": 34,
      "z": 11,
      "name": "Plant_Leaves_Fir",
      "support": 15
    },
    {
      "x": 14,
      "y": 12,
      "z": 12,
      "name": "Rock_Marble"
    },
    {
      "x": 14,
      "y": 13,
      "z": 12,
      "name": "Rock_Marble"
    },
    {
      "x": 14,
      "y": 14,
      "z": 12,
      "name": "Rock_Marble"
    },
    {
      "x": 14,
      "y": 15,
      "z": 12,
      "name": "Rock_Marble"
    },
    {
      "x": 14,
      "y": 16,
      "z": 12,
      "name": "Rock_Marble"
    },
    {
      "x": 14,
      "y": 17,
      "z": 12,
      "name": "Rock_Marble"
    },
    {
      "x": 14,
      "y": 18,
      "z": 12,
      "name": "Rock_Marble"
    },
    {
      "x": 14,
      "y": 19,
      "z": 12,
      "name": "Soil_Dirt_Cold"
    },
    {
      "x": 14,
      "y": 20,
      "z": 12,
      "name": "Soil_Dirt_Cold"
    },
    {
      "x": 14,
      "y": 21,
      "z": 12,
      "name": "Soil_Dirt_Cold"
    },
    {
      "x": 14,
      "y": 22,
      "z": 12,
      "name": "Soil_Dirt_Cold"
    },
    {
      "x": 14,
      "y": 23,
      "z": 12,
      "name": "Soil_Grass_Cold"
    },
    {
      "x": 14,
      "y": 31,
      "z": 12,
      "name": "Plant_Leaves_Fir",
      "support": 15
    },
    {
      "x": 14,
      "y": 33,
      "z": 12,
      "name": "Plant_Leaves_Fir",
      "support": 15
    },
    {
      "x": 14,
      "y": 34,
      "z": 12,
      "name": "Plant_Leaves_Fir",
      "support": 15
    },
    {
      "x": 14,
      "y": 38,
      "z": 12,
      "name": "Plant_Leaves_Fir",
      "support": 15
    },
    {
      "x": 14,
      "y": 13,
      "z": 13,
      "name": "Rock_Marble"
    },
    {
      "x": 14,
      "y": 14,
      "z": 13,
      "name": "Rock_Marble"
    },
    {
      "x": 14,
      "y": 15,
      "z": 13,
      "name": "Rock_Marble"
    },
    {
      "x": 14,
      "y": 16,
      "z": 13,
      "name": "Rock_Marble"
    },
    {
      "x": 14,
      "y": 17,
      "z": 13,
      "name": "Rock_Marble"
    },
    {
      "x": 14,
      "y": 31,
      "z": 13,
      "name": "Wood_Fir_Branch_Long",
      "support": 15,
      "rotation": 5
    },
    {
      "x": 14,
      "y": 33,
      "z": 13,
      "name": "Plant_Leaves_Fir",
      "support": 15
    },
    {
      "x": 14,
      "y": 34,
      "z": 13,
      "name": "Plant_Leaves_Fir",
      "support": 15
    },
    {
      "x": 14,
      "y": 37,
      "z": 13,
      "name": "Plant_Leaves_Fir",
      "support": 15
    },
    {
      "x": 14,
      "y": 38,
      "z": 13,
      "name": "Plant_Leaves_Fir",
      "support": 15
    },
    {
      "x": 14,
      "y": 31,
      "z": 14,
      "name": "Plant_Leaves_Fir",
      "support": 15
    },
    {
      "x": 14,
      "y": 34,
      "z": 14,
      "name": "Plant_Leaves_Fir",
      "support": 15
    },
    {
      "x": 14,
      "y": 38,
      "z": 14,
      "name": "Plant_Leaves_Fir",
      "support": 15
    },
    {
      "x": 14,
      "y": 31,
      "z": 15,
      "name": "Plant_Leaves_Fir",
      "support": 15
    },
    {
      "x": 14,
      "y": 34,
      "z": 15,
      "name": "Plant_Leaves_Fir",
      "support": 15
    },
    {
      "x": 15,
      "y": 15,
      "z": 10,
      "name": "Rock_Marble"
    },
    {
      "x": 15,
      "y": 16,
      "z": 10,
      "name": "Rock_Marble"
    },
    {
      "x": 15,
      "y": 17,
      "z": 10,
      "name": "Rock_Marble"
    },
    {
      "x": 15,
      "y": 18,
      "z": 10,
      "name": "Rock_Marble"
    },
    {
      "x": 15,
      "y": 19,
      "z": 10,
      "name": "Rock_Marble"
    },
    {
      "x": 15,
      "y": 20,
      "z": 10,
      "name": "Soil_Grass_Cold"
    },
    {
      "x": 15,
      "y": 12,
      "z": 11,
      "name": "Rock_Marble"
    },
    {
      "x": 15,
      "y": 13,
      "z": 11,
      "name": "Rock_Marble"
    },
    {
      "x": 15,
      "y": 14,
      "z": 11,
      "name": "Rock_Marble"
    },
    {
      "x": 15,
      "y": 15,
      "z": 11,
      "name": "Rock_Marble"
    },
    {
      "x": 15,
      "y": 16,
      "z": 11,
      "name": "Rock_Marble"
    },
    {
      "x": 15,
      "y": 17,
      "z": 11,
      "name": "Rock_Marble"
    },
    {
      "x": 15,
      "y": 18,
      "z": 11,
      "name": "Rock_Marble"
    },
    {
      "x": 15,
      "y": 19,
      "z": 11,
      "name": "Soil_Dirt_Cold"
    },
    {
      "x": 15,
      "y": 20,
      "z": 11,
      "name": "Soil_Dirt_Cold"
    },
    {
      "x": 15,
      "y": 21,
      "z": 11,
      "name": "Soil_Dirt_Cold"
    },
    {
      "x": 15,
      "y": 22,
      "z": 11,
      "name": "Soil_Grass_Cold"
    },
    {
      "x": 15,
      "y": 23,
      "z": 11,
      "name": "Plant_Grass_Lush_Tall"
    },
    {
      "x": 15,
      "y": 12,
      "z": 12,
      "name": "Rock_Marble"
    },
    {
      "x": 15,
      "y": 13,
      "z": 12,
      "name": "Rock_Marble"
    },
    {
      "x": 15,
      "y": 14,
      "z": 12,
      "name": "Rock_Marble"
    },
    {
      "x": 15,
      "y": 15,
      "z": 12,
      "name": "Rock_Marble"
    },
    {
      "x": 15,
      "y": 16,
      "z": 12,
      "name": "Rock_Marble"
    },
    {
      "x": 15,
      "y": 17,
      "z": 12,
      "name": "Rock_Marble"
    },
    {
      "x": 15,
      "y": 18,
      "z": 12,
      "name": "Soil_Dirt_Cold"
    },
    {
      "x": 15,
      "y": 19,
      "z": 12,
      "name": "Soil_Dirt_Cold"
    },
    {
      "x": 15,
      "y": 20,
      "z": 12,
      "name": "Soil_Grass_Cold"
    },
    {
      "x": 15,
      "y": 21,
      "z": 12,
      "name": "Plant_Grass_Lush_Tall"
    },
    {
      "x": 15,
      "y": 34,
      "z": 12,
      "name": "Plant_Leaves_Fir",
      "support": 15
    },
    {
      "x": 15,
      "y": 31,
      "z": 13,
      "name": "Plant_Leaves_Fir",
      "support": 15
    },
    {
      "x": 15,
      "y": 33,
      "z": 13,
      "name": "Plant_Leaves_Fir",
      "support": 15
    },
    {
      "x": 15,
      "y": 34,
      "z": 13,
      "name": "Plant_Leaves_Fir",
      "support": 15
    },
    {
      "x": 15,
      "y": 38,
      "z": 13,
      "name": "Plant_Leaves_Fir",
      "support": 15
    },
    {
      "x": 15,
      "y": 31,
      "z": 14,
      "name": "Plant_Leaves_Fir",
      "support": 15
    },
    {
      "x": 15,
      "y": 34,
      "z": 14,
      "name": "Plant_Leaves_Fir",
      "support": 15
    },
    {
      "x": 16,
      "y": 16,
      "z": 10,
      "name": "Rock_Marble"
    },
    {
      "x": 16,
      "y": 17,
      "z": 10,
      "name": "Rock_Marble"
    },
    {
      "x": 16,
      "y": 18,
      "z": 10,
      "name": "Rock_Marble"
    },
    {
      "x": 16,
      "y": 14,
      "z": 11,
      "name": "Rock_Marble"
    },
    {
      "x": 16,
      "y": 15,
      "z": 11,
      "name": "Rock_Marble"
    },
    {
      "x": 16,
      "y": 16,
      "z": 11,
      "name": "Rock_Marble"
    },
    {
      "x": 16,
      "y": 17,
      "z": 11,
      "name": "Rock_Marble"
    },
    {
      "x": 16,
      "y": 18,
      "z": 11,
      "name": "Rock_Marble"
    },
    {
      "x": 16,
      "y": 19,
      "z": 11,
      "name": "Soil_Dirt_Cold"
    },
    {
      "x": 16,
      "y": 20,
      "z": 11,
      "name": "Soil_Dirt_Cold"
    },
    {
      "x": 16,
      "y": 21,
      "z": 11,
      "name": "Soil_Grass_Cold"
    },
    {
      "x": 16,
      "y": 17,
      "z": 12,
      "name": "Rock_Marble"
    },
    {
      "x": 16,
      "y": 18,
      "z": 12,
      "name": "Rock_Marble"
    },
    {
      "x": 16,
      "y": 19,
      "z": 12,
      "name": "Soil_Grass_Cold"
    },
    {
      "x": 16,
      "y": 34,
      "z": 12,
      "name": "Plant_Leaves_Fir",
      "support": 15
    },
    {
      "x": 16,
      "y": 31,
      "z": 13,
      "name": "Plant_Leaves_Fir",
      "support": 15
    },
    {
      "x": 16,
      "y": 34,
      "z": 13,
      "name": "Plant_Leaves_Fir",
      "support": 15
    },
    {
      "x": 16,
      "y": 31,
      "z": 14,
      "name": "Plant_Leaves_Fir",
      "support": 15
    },
    {
      "x": 17,
      "y": 31,
      "z": 13,
      "name": "Plant_Leaves_Fir",
      "support": 15
    }
  ]
}