{
  "version": 8,
  "blockIdVersion": 8,
  "anchorX": -1,
  "anchorY": 18,
  "anchorZ": 21,
  "blocks": [
    {
      "x": -8,
      "y": 18,
      "z": 22,
      "name": "Rock_Sandstone"
    },
    {
      "x": -8,
      "y": 19,
      "z": 22,
      "name": "Rock_Sandstone"
    },
    {
      "x": -8,
      "y": 20,
      "z": 22,
      "name": "Rock_Sandstone"
    },
    {
      "x": -8,
      "y": 21,
      "z": 22,
      "name": "Rock_Sandstone"
    },
    {
      "x": -8,
      "y": 22,
      "z": 22,
      "name": "Rock_Sandstone"
    },
    {
      "x": -8,
      "y": 23,
      "z": 22,
      "name": "Rock_Sandstone"
    },
    {
      "x": -8,
      "y": 24,
      "z": 22,
      "name": "Rock_Sandstone"
    },
    {
      "x": -8,
      "y": 25,
      "z": 22,
      "name": "Rock_Sandstone"
    },
    {
      "x": -8,
      "y": 26,
      "z": 22,
      "name": "Rock_Sandstone"
    },
    {
      "x": -8,
      "y": 27,
      "z": 22,
      "name": "Rock_Sandstone"
    },
    {
      "x": -8,
      "y": 18,
      "z": 23,
      "name": "Rock_Sandstone"
    },
    {
      "x": -8,
      "y": 19,
      "z": 23,
      "name": "Rock_Sandstone"
    },
    {
      "x": -8,
      "y": 20,
      "z": 23,
      "name": "Rock_Sandstone"
    },
    {
      "x": -8,
      "y": 21,
      "z": 23,
      "name": "Rock_Sandstone"
    },
    {
      "x": -8,
      "y": 22,
      "z": 23,
      "name": "Rock_Sandstone"
    },
    {
      "x": -8,
      "y": 23,
      "z": 23,
      "name": "Rock_Sandstone"
    },
    {
      "x": -8,
      "y": 24,
      "z": 23,
      "name": "Rock_Sandstone"
    },
    {
      "x": -8,
      "y": 25,
      "z": 23,
      "name": "Rock_Sandstone"
    },
    {
      "x": -8,
      "y": 26,
      "z": 23,
      "name": "Rock_Sandstone"
    },
    {
      "x": -8,
      "y": 27,
      "z": 23,
      "name": "Rock_Sandstone"
    },
    {
      "x": -8,
      "y": 18,
      "z": 24,
      "name": "Rock_Sandstone"
    },
    {
      "x": -8,
      "y": 19,
      "z": 24,
      "name": "Rock_Sandstone"
    },
    {
      "x": -8,
      "y": 20,
      "z": 24,
      "name": "Rock_Sandstone"
    },
    {
      "x": -8,
      "y": 21,
      "z": 24,
      "name": "Rock_Sandstone"
    },
    {
      "x": -8,
      "y": 22,
      "z": 24,
      "name": "Rock_Sandstone"
    },
    {
      "x": -8,
      "y": 23,
      "z": 24,
      "name": "Rock_Sandstone"
    },
    {
      "x": -8,
      "y": 24,
      "z": 24,
      "name": "Rock_Sandstone"
    },
    {
      "x": -8,
      "y": 25,
      "z": 24,
      "name": "Rock_Sandstone"
    },
    {
      "x": -8,
      "y": 26,
      "z": 24,
      "name": "Rock_Sandstone"
    },
    {
      "x": -8,
      "y": 27,
      "z": 24,
      "name": "Rock_Sandstone"
    },
    {
      "x": -8,
      "y": 28,
      "z": 24,
      "name": "Rock_Sandstone"
    },
    {
      "x": -8,
      "y": 18,
      "z": 25,
      "name": "Rock_Sandstone"
    },
    {
      "x": -8,
      "y": 19,
      "z": 25,
      "name": "Rock_Sandstone"
    },
    {
      "x": -8,
      "y": 20,
      "z": 25,
      "name": "Rock_Sandstone"
    },
    {
      "x": -8,
      "y": 21,
      "z": 25,
      "name": "Rock_Sandstone"
    },
    {
      "x": -8,
      "y": 22,
      "z": 25,
      "name": "Rock_Sandstone"
    },
    {
      "x": -8,
      "y": 23,
      "z": 25,
      "name": "Rock_Sandstone"
    },
    {
      "x": -8,
      "y": 24,
      "z": 25,
      "name": "Rock_Sandstone"
    },
    {
      "x": -8,
      "y": 25,
      "z": 25,
      "name": "Rock_Sandstone"
    },
    {
      "x": -8,
      "y": 26,
      "z": 25,
      "name": "Rock_Sandstone"
    },
    {
      "x": -8,
      "y": 27,
      "z": 25,
      "name": "Rock_Sandstone"
    },
    {
      "x": -8,
      "y": 28,
      "z": 25,
      "name": "Rock_Sandstone"
    },
    {
      "x": -8,
      "y": 17,
      "z": 26,
      "name": "Rock_Sandstone_Brick"
    },
    {
      "x": -8,
      "y": 18,
      "z": 26,
      "name": "Rock_Sandstone_Brick"
    },
    {
      "x": -8,
      "y": 19,
      "z": 26,
      "name": "Rock_Sandstone_Brick"
    },
    {
      "x": -8,
      "y": 20,
      "z": 26,
      "name": "Rock_Sandstone_Brick"
    },
    {
      "x": -8,
      "y": 21,
      "z": 26,
      "name": "Rock_Sandstone_Brick"
    },
    {
      "x": -8,
      "y": 22,
      "z": 26,
      "name": "Rock_Sandstone_Brick"
    },
    {
      "x": -8,
      "y": 23,
      "z": 26,
      "name": "Rock_Sandstone_Brick"
    },
    {
      "x": -8,
      "y": 24,
      "z": 26,
      "name": "Rock_Sandstone"
    },
    {
      "x": -8,
      "y": 25,
      "z": 26,
      "name": "Rock_Sandstone"
    },
    {
      "x": -8,
      "y": 26,
      "z": 26,
      "name": "Rock_Sandstone"
    },
    {
      "x": -8,
      "y": 27,
      "z": 26,
      "name": "Rock_Sandstone"
    },
    {
      "x": -8,
      "y": 28,
      "z": 26,
      "name": "Rock_Sandstone"
    },
    {
      "x": -8,
      "y": 17,
      "z": 27,
      "name": "Rock_Sandstone_Brick"
    },
    {
      "x": -8,
      "y": 18,
      "z": 27,
      "name": "Soil_Sand_White"
    },
    {
      "x": -8,
      "y": 19,
      "z": 27,
      "name": "Empty"
    },
    {
      "x": -8,
      "y": 20,
      "z": 27,
      "name": "Empty"
    },
    {
      "x": -8,
      "y": 21,
      "z": 27,
      "name": "Empty"
    },
    {
      "x": -8,
      "y": 22,
      "z": 27,
      "name": "Empty"
    },
    {
      "x": -8,
      "y": 23,
      "z": 27,
      "name": "Rock_Sandstone_Brick"
    },
    {
      "x": -8,
      "y": 24,
      "z": 27,
      "name": "Rock_Sandstone"
    },
    {
      "x": -8,
      "y": 25,
      "z": 27,
      "name": "Rock_Sandstone"
    },
    {
      "x": -8,
      "y": 26,
      "z": 27,
      "name": "Rock_Sandstone"
    },
    {
      "x": -8,
      "y": 27,
      "z": 27,
      "name": "Rock_Sandstone"
    },
    {
      "x": -8,
      "y": 28,
      "z": 27,
      "name": "Rock_Sandstone"
    },
    {
      "x": -8,
      "y": 17,
      "z": 28,
      "name": "Rock_Sandstone_Brick"
    },
    {
      "x": -8,
      "y": 18,
      "z": 28,
      "name": "Soil_Sand_White"
    },
    {
      "x": -8,
      "y": 19,
      "z": 28,
      "name": "Empty"
    },
    {
      "x": -8,
      "y": 20,
      "z": 28,
      "name": "Empty"
    },
    {
      "x": -8,
      "y": 21,
      "z": 28,
      "name": "Empty"
    },
    {
      "x": -8,
      "y": 22,
      "z": 28,
      "name": "Empty"
    },
    {
      "x": -8,
      "y": 23,
      "z": 28,
      "name": "Rock_Sandstone_Brick"
    },
    {
      "x": -8,
      "y": 24,
      "z": 28,
      "name": "Rock_Sandstone"
    },
    {
      "x": -8,
      "y": 25,
      "z": 28,
      "name": "Rock_Sandstone"
    },
    {
      "x": -8,
      "y": 26,
      "z": 28,
      "name": "Rock_Sandstone"
    },
    {
      "x": -8,
      "y": 27,
      "z": 28,
      "name": "Rock_Sandstone"
    },
    {
      "x": -8,
      "y": 28,
      "z": 28,
      "name": "Rock_Sandstone"
    },
    {
      "x": -8,
      "y": 17,
      "z": 29,
      "name": "Rock_Sandstone_Brick"
    },
    {
      "x": -8,
      "y": 18,
      "z": 29,
      "name": "Soil_Sand_White"
    },
    {
      "x": -8,
      "y": 19,
      "z": 29,
      "name": "Empty"
    },
    {
      "x": -8,
      "y": 20,
      "z": 29,
      "name": "Empty"
    },
    {
      "x": -8,
      "y": 21,
      "z": 29,
      "name": "Empty"
    },
    {
      "x": -8,
      "y": 22,
      "z": 29,
      "name": "Empty"
    },
    {
      "x": -8,
      "y": 23,
      "z": 29,
      "name": "Rock_Sandstone_Brick"
    },
    {
      "x": -8,
      "y": 24,
      "z": 29,
      "name": "Rock_Sandstone"
    },
    {
      "x": -8,
      "y": 25,
      "z": 29,
      "name": "Rock_Sandstone"
    },
    {
      "x": -8,
      "y": 26,
      "z": 29,
      "name": "Rock_Sandstone"
    },
    {
      "x": -8,
      "y": 27,
      "z": 29,
      "name": "Rock_Sandstone"
    },
    {
      "x": -8,
      "y": 28,
      "z": 29,
      "name": "Rock_Sandstone"
    },
    {
      "x": -8,
      "y": 17,
      "z": 30,
      "name": "Rock_Sandstone_Brick"
    },
    {
      "x": -8,
      "y": 18,
      "z": 30,
      "name": "Rock_Sandstone_Brick"
    },
    {
      "x": -8,
      "y": 19,
      "z": 30,
      "name": "Rock_Sandstone_Brick"
    },
    {
      "x": -8,
      "y": 20,
      "z": 30,
      "name": "Rock_Sandstone_Brick"
    },
    {
      "x": -8,
      "y": 21,
      "z": 30,
      "name": "Rock_Sandstone_Brick"
    },
    {
      "x": -8,
      "y": 22,
      "z": 30,
      "name": "Rock_Sandstone_Brick"
    },
    {
      "x": -8,
      "y": 23,
      "z": 30,
      "name": "Rock_Sandstone_Brick"
    },
    {
      "x": -8,
      "y": 24,
      "z": 30,
      "name": "Rock_Sandstone"
    },
    {
      "x": -8,
      "y": 25,
      "z": 30,
      "name": "Rock_Sandstone"
    },
    {
      "x": -8,
      "y": 26,
      "z": 30,
      "name": "Rock_Sandstone"
    },
    {
      "x": -8,
      "y": 27,
      "z": 30,
      "name": "Rock_Sandstone"
    },
    {
      "x": -8,
      "y": 28,
      "z": 30,
      "name": "Rock_Sandstone"
    },
    {
      "x": -8,
      "y": 18,
      "z": 31,
      "name": "Rock_Sandstone"
    },
    {
      "x": -8,
      "y": 19,
      "z": 31,
      "name": "Rock_Sandstone"
    },
    {
      "x": -8,
      "y": 20,
      "z": 31,
      "name": "Rock_Sandstone"
    },
    {
      "x": -8,
      "y": 21,
      "z": 31,
      "name": "Rock_Sandstone"
    },
    {
      "x": -8,
      "y": 22,
      "z": 31,
      "name": "Rock_Sandstone"
    },
    {
      "x": -8,
      "y": 23,
      "z": 31,
      "name": "Rock_Sandstone"
    },
    {
      "x": -8,
      "y": 24,
      "z": 31,
      "name": "Rock_Sandstone"
    },
    {
      "x": -8,
      "y": 25,
      "z": 31,
      "name": "Rock_Sandstone"
    },
    {
      "x": -8,
      "y": 26,
      "z": 31,
      "name": "Rock_Sandstone"
    },
    {
      "x": -8,
      "y": 27,
      "z": 31,
      "name": "Rock_Sandstone"
    },
    {
      "x": -8,
      "y": 28,
      "z": 31,
      "name": "Rock_Sandstone"
    },
    {
      "x": -8,
      "y": 18,
      "z": 32,
      "name": "Rock_Sandstone"
    },
    {
      "x": -8,
      "y": 19,
      "z": 32,
      "name": "Rock_Sandstone"
    },
    {
      "x": -8,
      "y": 20,
      "z": 32,
      "name": "Rock_Sandstone"
    },
    {
      "x": -8,
      "y": 21,
      "z": 32,
      "name": "Rock_Sandstone"
    },
    {
      "x": -8,
      "y": 22,
      "z": 32,
      "name": "Rock_Sandstone"
    },
    {
      "x": -8,
      "y": 23,
      "z": 32,
      "name": "Rock_Sandstone"
    },
    {
      "x": -8,
      "y": 24,
      "z": 32,
      "name": "Rock_Sandstone"
    },
    {
      "x": -8,
      "y": 25,
      "z": 32,
      "name": "Rock_Sandstone"
    },
    {
      "x": -8,
      "y": 26,
      "z": 32,
      "name": "Rock_Sandstone"
    },
    {
      "x": -8,
      "y": 27,
      "z": 32,
      "name": "Rock_Sandstone"
    },
    {
      "x": -8,
      "y": 18,
      "z": 33,
      "name": "Rock_Sandstone"
    },
    {
      "x": -8,
      "y": 19,
      "z": 33,
      "name": "Rock_Sandstone"
    },
    {
      "x": -8,
      "y": 20,
      "z": 33,
      "name": "Rock_Sandstone"
    },
    {
      "x": -8,
      "y": 21,
      "z": 33,
      "name": "Rock_Sandstone"
    },
    {
      "x": -8,
      "y": 22,
      "z": 33,
      "name": "Rock_Sandstone"
    },
    {
      "x": -8,
      "y": 23,
      "z": 33,
      "name": "Rock_Sandstone"
    },
    {
      "x": -8,
      "y": 24,
      "z": 33,
      "name": "Rock_Sandstone"
    },
    {
      "x": -8,
      "y": 25,
      "z": 33,
      "name": "Rock_Sandstone"
    },
    {
      "x": -8,
      "y": 26,
      "z": 33,
      "name": "Rock_Sandstone"
    },
    {
      "x": -8,
      "y": 27,
      "z": 33,
      "name": "Rock_Sandstone"
    },
    {
      "x": -8,
      "y": 20,
      "z": 34,
      "name": "Rock_Sandstone"
    },
    {
      "x": -8,
      "y": 21,
      "z": 34,
      "name": "Rock_Sandstone"
    },
    {
      "x": -8,
      "y": 22,
      "z": 34,
      "name": "Rock_Sandstone"
    },
    {
      "x": -8,
      "y": 23,
      "z": 34,
      "name": "Rock_Sandstone"
    },
    {
      "x": -8,
      "y": 24,
      "z": 34,
      "name": "Rock_Sandstone"
    },
    {
      "x": -8,
      "y": 25,
      "z": 34,
      "name": "Rock_Sandstone"
    },
    {
      "x": -8,
      "y": 26,
      "z": 34,
      "name": "Rock_Sandstone"
    },
    {
      "x": -8,
      "y": 27,
      "z": 34,
      "name": "Rock_Sandstone"
    },
    {
      "x": -7,
      "y": 18,
      "z": 21,
      "name": "Rock_Sandstone"
    },
    {
      "x": -7,
      "y": 19,
      "z": 21,
      "name": "Rock_Sandstone"
    },
    {
      "x": -7,
      "y": 20,
      "z": 21,
      "name": "Rock_Sandstone"
    },
    {
      "x": -7,
      "y": 21,
      "z": 21,
      "name": "Rock_Sandstone"
    },
    {
      "x": -7,
      "y": 22,
      "z": 21,
      "name": "Rock_Sandstone"
    },
    {
      "x": -7,
      "y": 23,
      "z": 21,
      "name": "Rock_Sandstone"
    },
    {
      "x": -7,
      "y": 24,
      "z": 21,
      "name": "Rock_Sandstone"
    },
    {
      "x": -7,
      "y": 25,
      "z": 21,
      "name": "Rock_Sandstone"
    },
    {
      "x": -7,
      "y": 17,
      "z": 22,
      "name": "Rock_Sandstone"
    },
    {
      "x": -7,
      "y": 18,
      "z": 22,
      "name": "Rock_Sandstone"
    },
    {
      "x": -7,
      "y": 19,
      "z": 22,
      "name": "Rock_Sandstone"
    },
    {
      "x": -7,
      "y": 20,
      "z": 22,
      "name": "Rock_Sandstone"
    },
    {
      "x": -7,
      "y": 21,
      "z": 22,
      "name": "Rock_Sandstone"
    },
    {
      "x": -7,
      "y": 22,
      "z": 22,
      "name": "Rock_Sandstone"
    },
    {
      "x": -7,
      "y": 23,
      "z": 22,
      "name": "Rock_Sandstone"
    },
    {
      "x": -7,
      "y": 24,
      "z": 22,
      "name": "Rock_Sandstone"
    },
    {
      "x": -7,
      "y": 25,
      "z": 22,
      "name": "Rock_Sandstone"
    },
    {
      "x": -7,
      "y": 26,
      "z": 22,
      "name": "Rock_Sandstone"
    },
    {
      "x": -7,
      "y": 27,
      "z": 22,
      "name": "Rock_Sandstone"
    },
    {
      "x": -7,
      "y": 28,
      "z": 22,
      "name": "Rock_Sandstone"
    },
    {
      "x": -7,
      "y": 17,
      "z": 23,
      "name": "Rock_Sandstone"
    },
    {
      "x": -7,
      "y": 18,
      "z": 23,
      "name": "Rock_Sandstone"
    },
    {
      "x": -7,
      "y": 19,
      "z": 23,
      "name": "Rock_Sandstone"
    },
    {
      "x": -7,
      "y": 20,
      "z": 23,
      "name": "Rock_Sandstone"
    },
    {
      "x": -7,
      "y": 21,
      "z": 23,
      "name": "Rock_Sandstone"
    },
    {
      "x": -7,
      "y": 22,
      "z": 23,
      "name": "Rock_Sandstone"
    },
    {
      "x": -7,
      "y": 23,
      "z": 23,
      "name": "Rock_Sandstone_Brick_Ornate"
    },
    {
      "x": -7,
      "y": 24,
      "z": 23,
      "name": "Rock_Sandstone_Brick_Half"
    },
    {
      "x": -7,
      "y": 25,
      "z": 23,
      "name": "Rock_Sandstone_Brick_Ornate"
    },
    {
      "x": -7,
      "y": 26,
      "z": 23,
      "name": "Rock_Sandstone"
    },
    {
      "x": -7,
      "y": 27,
      "z": 23,
      "name": "Rock_Sandstone"
    },
    {
      "x": -7,
      "y": 28,
      "z": 23,
      "name": "Rock_Sandstone"
    },
    {
      "x": -7,
      "y": 17,
      "z": 24,
      "name": "Rock_Sandstone"
    },
    {
      "x": -7,
      "y": 18,
      "z": 24,
      "name": "Rock_Sandstone"
    },
    {
      "x": -7,
      "y": 19,
      "z": 24,
      "name": "Rock_Sandstone"
    },
    {
      "x": -7,
      "y": 20,
      "z": 24,
      "name": "Rock_Sandstone"
    },
    {
      "x": -7,
      "y": 21,
      "z": 24,
      "name": "Empty"
    },
    {
      "x": -7,
      "y": 22,
      "z": 24,
      "name": "Empty"
    },
    {
      "x": -7,
      "y": 23,
      "z": 24,
      "name": "Rock_Sandstone_Brick_Ornate"
    },
    {
      "x": -7,
      "y": 24,
      "z": 24,
      "name": "Furniture_Village_Crate"
    },
    {
      "x": -7,
      "y": 25,
      "z": 24,
      "name": "Furniture_Tavern_Barrel"
    },
    {
      "x": -7,
      "y": 26,
      "z": 24,
      "name": "Rock_Sandstone"
    },
    {
      "x": -7,
      "y": 27,
      "z": 24,
      "name": "Rock_Sandstone"
    },
    {
      "x": -7,
      "y": 28,
      "z": 24,
      "name": "Rock_Sandstone"
    },
    {
      "x": -7,
      "y": 17,
      "z": 25,
      "name": "Rock_Sandstone"
    },
    {
      "x": -7,
      "y": 18,
      "z": 25,
      "name": "Soil_Sand_White"
    },
    {
      "x": -7,
      "y": 19,
      "z": 25,
      "name": "Furniture_Tavern_Barrel"
    },
    {
      "x": -7,
      "y": 20,
      "z": 25,
      "name": "Furniture_Tavern_Barrel"
    },
    {
      "x": -7,
      "y": 21,
      "z": 25,
      "name": "Empty"
    },
    {
      "x": -7,
      "y": 22,
      "z": 25,
      "name": "Empty"
    },
    {
      "x": -7,
      "y": 23,
      "z": 25,
      "name": "Rock_Sandstone_Brick_Ornate"
    },
    {
      "x": -7,
      "y": 24,
      "z": 25,
      "name": "Furniture_Village_Crate"
    },
    {
      "x": -7,
      "y": 25,
      "z": 25,
      "name": "Furniture_Tavern_Barrel"
    },
    {
      "x": -7,
      "y": 26,
      "z": 25,
      "name": "Rock_Sandstone"
    },
    {
      "x": -7,
      "y": 27,
      "z": 25,
      "name": "Rock_Sandstone"
    },
    {
      "x": -7,
      "y": 28,
      "z": 25,
      "name": "Rock_Sandstone"
    },
    {
      "x": -7,
      "y": 17,
      "z": 26,
      "name": "Rock_Sandstone"
    },
    {
      "x": -7,
      "y": 18,
      "z": 26,
      "name": "Soil_Sand_White"
    },
    {
      "x": -7,
      "y": 19,
      "z": 26,
      "name": "Container_Bucket"
    },
    {
      "x": -7,
      "y": 20,
      "z": 26,
      "name": "Empty"
    },
    {
      "x": -7,
      "y": 21,
      "z": 26,
      "name": "Wood_Torch_Wall",
      "rotation": 1
    },
    {
      "x": -7,
      "y": 22,
      "z": 26,
      "name": "Empty"
    },
    {
      "x": -7,
      "y": 23,
      "z": 26,
      "name": "Rock_Sandstone_Brick_Ornate"
    },
    {
      "x": -7,
      "y": 24,
      "z": 26,
      "name": "Furniture_Tavern_Barrel"
    },
    {
      "x": -7,
      "y": 25,
      "z": 26,
      "name": "Rock_Sandstone"
    },
    {
      "x": -7,
      "y": 26,
      "z": 26,
      "name": "Rock_Sandstone"
    },
    {
      "x": -7,
      "y": 27,
      "z": 26,
      "name": "Rock_Sandstone"
    },
    {
      "x": -7,
      "y": 28,
      "z": 26,
      "name": "Rock_Sandstone"
    },
    {
      "x": -7,
      "y": 17,
      "z": 27,
      "name": "Rock_Sandstone"
    },
    {
      "x": -7,
      "y": 18,
      "z": 27,
      "name": "Soil_Sand_White"
    },
    {
      "x": -7,
      "y": 19,
      "z": 27,
      "name": "Empty"
    },
    {
      "x": -7,
      "y": 20,
      "z": 27,
      "name": "Empty"
    },
    {
      "x": -7,
      "y": 21,
      "z": 27,
      "name": "Empty"
    },
    {
      "x": -7,
      "y": 22,
      "z": 27,
      "name": "Empty"
    },
    {
      "x": -7,
      "y": 23,
      "z": 27,
      "name": "Rock_Sandstone_Brick_Ornate"
    },
    {
      "x": -7,
      "y": 25,
      "z": 27,
      "name": "Rock_Sandstone"
    },
    {
      "x": -7,
      "y": 26,
      "z": 27,
      "name": "Rock_Sandstone"
    },
    {
      "x": -7,
      "y": 27,
      "z": 27,
      "name": "Rock_Sandstone"
    },
    {
      "x": -7,
      "y": 28,
      "z": 27,
      "name": "Rock_Sandstone"
    },
    {
      "x": -7,
      "y": 17,
      "z": 28,
      "name": "Rock_Sandstone"
    },
    {
      "x": -7,
      "y": 18,
      "z": 28,
      "name": "Soil_Sand_White"
    },
    {
      "x": -7,
      "y": 19,
      "z": 28,
      "name": "Empty"
    },
    {
      "x": -7,
      "y": 20,
      "z": 28,
      "name": "Empty"
    },
    {
      "x": -7,
      "y": 21,
      "z": 28,
      "name": "Empty"
    },
    {
      "x": -7,
      "y": 22,
      "z": 28,
      "name": "Empty"
    },
    {
      "x": -7,
      "y": 23,
      "z": 28,
      "name": "Rock_Sandstone_Brick_Ornate"
    },
    {
      "x": -7,
      "y": 24,
      "z": 28,
      "name": "Rock_Sandstone"
    },
    {
      "x": -7,
      "y": 25,
      "z": 28,
      "name": "Rock_Sandstone"
    },
    {
      "x": -7,
      "y": 26,
      "z": 28,
      "name": "Rock_Sandstone"
    },
    {
      "x": -7,
      "y": 27,
      "z": 28,
      "name": "Rock_Sandstone"
    },
    {
      "x": -7,
      "y": 28,
      "z": 28,
      "name": "Rock_Sandstone"
    },
    {
      "x": -7,
      "y": 17,
      "z": 29,
      "name": "Rock_Sandstone"
    },
    {
      "x": -7,
      "y": 18,
      "z": 29,
      "name": "Soil_Sand_White"
    },
    {
      "x": -7,
      "y": 19,
      "z": 29,
      "name": "Empty"
    },
    {
      "x": -7,
      "y": 20,
      "z": 29,
      "name": "Empty"
    },
    {
      "x": -7,
      "y": 21,
      "z": 29,
      "name": "Empty"
    },
    {
      "x": -7,
      "y": 22,
      "z": 29,
      "name": "Empty"
    },
    {
      "x": -7,
      "y": 23,
      "z": 29,
      "name": "Rock_Sandstone"
    },
    {
      "x": -7,
      "y": 24,
      "z": 29,
      "name": "Rock_Sandstone"
    },
    {
      "x": -7,
      "y": 25,
      "z": 29,
      "name": "Rock_Sandstone"
    },
    {
      "x": -7,
      "y": 26,
      "z": 29,
      "name": "Rock_Sandstone"
    },
    {
      "x": -7,
      "y": 27,
      "z": 29,
      "name": "Rock_Sandstone"
    },
    {
      "x": -7,
      "y": 28,
      "z": 29,
      "name": "Rock_Sandstone"
    },
    {
      "x": -7,
      "y": 17,
      "z": 30,
      "name": "Rock_Sandstone"
    },
    {
      "x": -7,
      "y": 18,
      "z": 30,
      "name": "Soil_Sand_White"
    },
    {
      "x": -7,
      "y": 19,
      "z": 30,
      "name": "Wood_Drywood_Planks"
    },
    {
      "x": -7,
      "y": 20,
      "z": 30,
      "name": "Empty"
    },
    {
      "x": -7,
      "y": 21,
      "z": 30,
      "name": "Rock_Sandstone"
    },
    {
      "x": -7,
      "y": 22,
      "z": 30,
      "name": "Rock_Sandstone"
    },
    {
      "x": -7,
      "y": 23,
      "z": 30,
      "name": "Rock_Sandstone"
    },
    {
      "x": -7,
      "y": 24,
      "z": 30,
      "name": "Rock_Sandstone"
    },
    {
      "x": -7,
      "y": 25,
      "z": 30,
      "name": "Rock_Sandstone"
    },
    {
      "x": -7,
      "y": 26,
      "z": 30,
      "name": "Rock_Sandstone"
    },
    {
      "x": -7,
      "y": 27,
      "z": 30,
      "name": "Rock_Sandstone"
    },
    {
      "x": -7,
      "y": 28,
      "z": 30,
      "name": "Rock_Sandstone"
    },
    {
      "x": -7,
      "y": 17,
      "z": 31,
      "name": "Rock_Sandstone"
    },
    {
      "x": -7,
      "y": 18,
      "z": 31,
      "name": "Rock_Sandstone"
    },
    {
      "x": -7,
      "y": 19,
      "z": 31,
      "name": "Rock_Sandstone"
    },
    {
      "x": -7,
      "y": 20,
      "z": 31,
      "name": "Rock_Sandstone"
    },
    {
      "x": -7,
      "y": 21,
      "z": 31,
      "name": "Rock_Sandstone"
    },
    {
      "x": -7,
      "y": 22,
      "z": 31,
      "name": "Rock_Sandstone"
    },
    {
      "x": -7,
      "y": 23,
      "z": 31,
      "name": "Rock_Sandstone"
    },
    {
      "x": -7,
      "y": 24,
      "z": 31,
      "name": "Rock_Sandstone"
    },
    {
      "x": -7,
      "y": 25,
      "z": 31,
      "name": "Rock_Sandstone"
    },
    {
      "x": -7,
      "y": 26,
      "z": 31,
      "name": "Rock_Sandstone"
    },
    {
      "x": -7,
      "y": 27,
      "z": 31,
      "name": "Rock_Sandstone"
    },
    {
      "x": -7,
      "y": 28,
      "z": 31,
      "name": "Rock_Sandstone"
    },
    {
      "x": -7,
      "y": 17,
      "z": 32,
      "name": "Rock_Sandstone"
    },
    {
      "x": -7,
      "y": 18,
      "z": 32,
      "name": "Rock_Sandstone"
    },
    {
      "x": -7,
      "y": 19,
      "z": 32,
      "name": "Rock_Sandstone"
    },
    {
      "x": -7,
      "y": 20,
      "z": 32,
      "name": "Rock_Sandstone"
    },
    {
      "x": -7,
      "y": 21,
      "z": 32,
      "name": "Rock_Sandstone"
    },
    {
      "x": -7,
      "y": 22,
      "z": 32,
      "name": "Rock_Sandstone"
    },
    {
      "x": -7,
      "y": 23,
      "z": 32,
      "name": "Rock_Sandstone"
    },
    {
      "x": -7,
      "y": 24,
      "z": 32,
      "name": "Rock_Sandstone"
    },
    {
      "x": -7,
      "y": 25,
      "z": 32,
      "name": "Rock_Sandstone"
    },
    {
      "x": -7,
      "y": 26,
      "z": 32,
      "name": "Rock_Sandstone"
    },
    {
      "x": -7,
      "y": 27,
      "z": 32,
      "name": "Rock_Sandstone"
    },
    {
      "x": -7,
      "y": 28,
      "z": 32,
      "name": "Rock_Sandstone"
    },
    {
      "x": -7,
      "y": 17,
      "z": 33,
      "name": "Rock_Sandstone"
    },
    {
      "x": -7,
      "y": 18,
      "z": 33,
      "name": "Rock_Sandstone"
    },
    {
      "x": -7,
      "y": 19,
      "z": 33,
      "name": "Rock_Sandstone"
    },
    {
      "x": -7,
      "y": 20,
      "z": 33,
      "name": "Rock_Sandstone"
    },
    {
      "x": -7,
      "y": 21,
      "z": 33,
      "name": "Rock_Sandstone"
    },
    {
      "x": -7,
      "y": 22,
      "z": 33,
      "name": "Rock_Sandstone"
    },
    {
      "x": -7,
      "y": 23,
      "z": 33,
      "name": "Rock_Sandstone"
    },
    {
      "x": -7,
      "y": 24,
      "z": 33,
      "name": "Rock_Sandstone"
    },
    {
      "x": -7,
      "y": 25,
      "z": 33,
      "name": "Rock_Sandstone"
    },
    {
      "x": -7,
      "y": 26,
      "z": 33,
      "name": "Rock_Sandstone"
    },
    {
      "x": -7,
      "y": 27,
      "z": 33,
      "name": "Rock_Sandstone"
    },
    {
      "x": -7,
      "y": 28,
      "z": 33,
      "name": "Rock_Sandstone"
    },
    {
      "x": -7,
      "y": 17,
      "z": 34,
      "name": "Rock_Sandstone"
    },
    {
      "x": -7,
      "y": 18,
      "z": 34,
      "name": "Rock_Sandstone"
    },
    {
      "x": -7,
      "y": 19,
      "z": 34,
      "name": "Rock_Sandstone"
    },
    {
      "x": -7,
      "y": 20,
      "z": 34,
      "name": "Rock_Sandstone"
    },
    {
      "x": -7,
      "y": 21,
      "z": 34,
      "name": "Rock_Sandstone"
    },
    {
      "x": -7,
      "y": 22,
      "z": 34,
      "name": "Rock_Sandstone"
    },
    {
      "x": -7,
      "y": 23,
      "z": 34,
      "name": "Rock_Sandstone"
    },
    {
      "x": -7,
      "y": 24,
      "z": 34,
      "name": "Rock_Sandstone"
    },
    {
      "x": -7,
      "y": 25,
      "z": 34,
      "name": "Rock_Sandstone"
    },
    {
      "x": -7,
      "y": 26,
      "z": 34,
      "name": "Rock_Sandstone"
    },
    {
      "x": -7,
      "y": 27,
      "z": 34,
      "name": "Rock_Sandstone"
    },
    {
      "x": -7,
      "y": 18,
      "z": 35,
      "name": "Rock_Sandstone"
    },
    {
      "x": -7,
      "y": 19,
      "z": 35,
      "name": "Rock_Sandstone"
    },
    {
      "x": -7,
      "y": 20,
      "z": 35,
      "name": "Rock_Sandstone"
    },
    {
      "x": -7,
      "y": 21,
      "z": 35,
      "name": "Rock_Sandstone"
    },
    {
      "x": -7,
      "y": 22,
      "z": 35,
      "name": "Rock_Sandstone"
    },
    {
      "x": -7,
      "y": 23,
      "z": 35,
      "name": "Rock_Sandstone"
    },
    {
      "x": -7,
      "y": 24,
      "z": 35,
      "name": "Rock_Sandstone"
    },
    {
      "x": -6,
      "y": 18,
      "z": 21,
      "name": "Rock_Sandstone"
    },
    {
      "x": -6,
      "y": 19,
      "z": 21,
      "name": "Rock_Sandstone"
    },
    {
      "x": -6,
      "y": 20,
      "z": 21,
      "name": "Rock_Sandstone"
    },
    {
      "x": -6,
      "y": 21,
      "z": 21,
      "name": "Rock_Sandstone"
    },
    {
      "x": -6,
      "y": 22,
      "z": 21,
      "name": "Rock_Sandstone"
    },
    {
      "x": -6,
      "y": 23,
      "z": 21,
      "name": "Rock_Sandstone"
    },
    {
      "x": -6,
      "y": 24,
      "z": 21,
      "name": "Rock_Sandstone"
    },
    {
      "x": -6,
      "y": 25,
      "z": 21,
      "name": "Rock_Sandstone"
    },
    {
      "x": -6,
      "y": 26,
      "z": 21,
      "name": "Rock_Sandstone"
    },
    {
      "x": -6,
      "y": 27,
      "z": 21,
      "name": "Rock_Sandstone"
    },
    {
      "x": -6,
      "y": 17,
      "z": 22,
      "name": "Rock_Sandstone"
    },
    {
      "x": -6,
      "y": 18,
      "z": 22,
      "name": "Rock_Sandstone"
    },
    {
      "x": -6,
      "y": 19,
      "z": 22,
      "name": "Rock_Sandstone"
    },
    {
      "x": -6,
      "y": 20,
      "z": 22,
      "name": "Rock_Sandstone"
    },
    {
      "x": -6,
      "y": 21,
      "z": 22,
      "name": "Rock_Sandstone"
    },
    {
      "x": -6,
      "y": 22,
      "z": 22,
      "name": "Rock_Sandstone"
    },
    {
      "x": -6,
      "y": 23,
      "z": 22,
      "name": "Rock_Sandstone"
    },
    {
      "x": -6,
      "y": 24,
      "z": 22,
      "name": "Rock_Sandstone"
    },
    {
      "x": -6,
      "y": 25,
      "z": 22,
      "name": "Rock_Sandstone"
    },
    {
      "x": -6,
      "y": 26,
      "z": 22,
      "name": "Rock_Sandstone"
    },
    {
      "x": -6,
      "y": 27,
      "z": 22,
      "name": "Rock_Sandstone"
    },
    {
      "x": -6,
      "y": 28,
      "z": 22,
      "name": "Rock_Sandstone"
    },
    {
      "x": -6,
      "y": 17,
      "z": 23,
      "name": "Rock_Sandstone"
    },
    {
      "x": -6,
      "y": 18,
      "z": 23,
      "name": "Soil_Sand_White"
    },
    {
      "x": -6,
      "y": 19,
      "z": 23,
      "name": "Furniture_Village_Crate"
    },
    {
      "x": -6,
      "y": 20,
      "z": 23,
      "name": "Furniture_Tavern_Barrel"
    },
    {
      "x": -6,
      "y": 21,
      "z": 23,
      "name": "Furniture_Tavern_Barrel"
    },
    {
      "x": -6,
      "y": 22,
      "z": 23,
      "name": "Rock_Sandstone_Brick"
    },
    {
      "x": -6,
      "y": 23,
      "z": 23,
      "name": "Rock_Sandstone_Brick"
    },
    {
      "x": -6,
      "y": 24,
      "z": 23,
      "name": "Rock_Sandstone_Brick"
    },
    {
      "x": -6,
      "y": 25,
      "z": 23,
      "name": "Rock_Sandstone_Brick_Ornate"
    },
    {
      "x": -6,
      "y": 26,
      "z": 23,
      "name": "Rock_Sandstone"
    },
    {
      "x": -6,
      "y": 27,
      "z": 23,
      "name": "Rock_Sandstone"
    },
    {
      "x": -6,
      "y": 28,
      "z": 23,
      "name": "Rock_Sandstone"
    },
    {
      "x": -6,
      "y": 17,
      "z": 24,
      "name": "Rock_Sandstone"
    },
    {
      "x": -6,
      "y": 18,
      "z": 24,
      "name": "Soil_Sand_White"
    },
    {
      "x": -6,
      "y": 19,
      "z": 24,
      "name": "Furniture_Village_Crate"
    },
    {
      "x": -6,
      "y": 20,
      "z": 24,
      "name": "Empty"
    },
    {
      "x": -6,
      "y": 21,
      "z": 24,
      "name": "Empty"
    },
    {
      "x": -6,
      "y": 22,
      "z": 24,
      "name": "Empty"
    },
    {
      "x": -6,
      "y": 23,
      "z": 24,
      "name": "Rock_Sandstone_Brick_Ornate"
    },
    {
      "x": -6,
      "y": 24,
      "z": 24,
      "name": "Furniture_Village_Crate"
    },
    {
      "x": -6,
      "y": 25,
      "z": 24,
      "name": "Furniture_Tavern_Barrel"
    },
    {
      "x": -6,
      "y": 26,
      "z": 24,
      "name": "Rock_Sandstone"
    },
    {
      "x": -6,
      "y": 27,
      "z": 24,
      "name": "Rock_Sandstone"
    },
    {
      "x": -6,
      "y": 28,
      "z": 24,
      "name": "Rock_Sandstone"
    },
    {
      "x": -6,
      "y": 29,
      "z": 24,
      "name": "Rock_Sandstone"
    },
    {
      "x": -6,
      "y": 17,
      "z": 25,
      "name": "Rock_Sandstone"
    },
    {
      "x": -6,
      "y": 18,
      "z": 25,
      "name": "Soil_Sand_White"
    },
    {
      "x": -6,
      "y": 19,
      "z": 25,
      "name": "Empty"
    },
    {
      "x": -6,
      "y": 20,
      "z": 25,
      "name": "Empty"
    },
    {
      "x": -6,
      "y": 21,
      "z": 25,
      "name": "Empty"
    },
    {
      "x": -6,
      "y": 22,
      "z": 25,
      "name": "Empty"
    },
    {
      "x": -6,
      "y": 23,
      "z": 25,
      "name": "Rock_Sandstone_Brick_Ornate"
    },
    {
      "x": -6,
      "y": 24,
      "z": 25,
      "name": "Furniture_Village_Crate"
    },
    {
      "x": -6,
      "y": 25,
      "z": 25,
      "name": "Block_Spawner_Block",
      "components": {
        "Components": {
          "BlockSpawner": {
            "BlockSpawnerId": "Zone2_Encounters_Tier3"
          }
        }
      },
      "rotation": 2
    },
    {
      "x": -6,
      "y": 26,
      "z": 25,
      "name": "Empty"
    },
    {
      "x": -6,
      "y": 27,
      "z": 25,
      "name": "Rock_Sandstone"
    },
    {
      "x": -6,
      "y": 28,
      "z": 25,
      "name": "Rock_Sandstone"
    },
    {
      "x": -6,
      "y": 29,
      "z": 25,
      "name": "Rock_Sandstone"
    },
    {
      "x": -6,
      "y": 17,
      "z": 26,
      "name": "Rock_Sandstone"
    },
    {
      "x": -6,
      "y": 18,
      "z": 26,
      "name": "Soil_Sand_White"
    },
    {
      "x": -6,
      "y": 19,
      "z": 26,
      "name": "Empty"
    },
    {
      "x": -6,
      "y": 20,
      "z": 26,
      "name": "Empty"
    },
    {
      "x": -6,
      "y": 21,
      "z": 26,
      "name": "Empty"
    },
    {
      "x": -6,
      "y": 22,
      "z": 26,
      "name": "Empty"
    },
    {
      "x": -6,
      "y": 23,
      "z": 26,
      "name": "Rock_Sandstone_Brick_Ornate"
    },
    {
      "x": -6,
      "y": 24,
      "z": 26,
      "name": "Furniture_Tavern_Barrel"
    },
    {
      "x": -6,
      "y": 25,
      "z": 26,
      "name": "Wood_Torch_Wall",
      "rotation": 1
    },
    {
      "x": -6,
      "y": 26,
      "z": 26,
      "name": "Empty"
    },
    {
      "x": -6,
      "y": 27,
      "z": 26,
      "name": "Rock_Sandstone"
    },
    {
      "x": -6,
      "y": 28,
      "z": 26,
      "name": "Rock_Sandstone"
    },
    {
      "x": -6,
      "y": 29,
      "z": 26,
      "name": "Rock_Sandstone"
    },
    {
      "x": -6,
      "y": 17,
      "z": 27,
      "name": "Rock_Sandstone"
    },
    {
      "x": -6,
      "y": 18,
      "z": 27,
      "name": "Soil_Sand_White"
    },
    {
      "x": -6,
      "y": 19,
      "z": 27,
      "name": "Empty"
    },
    {
      "x": -6,
      "y": 20,
      "z": 27,
      "name": "Empty"
    },
    {
      "x": -6,
      "y": 21,
      "z": 27,
      "name": "Empty"
    },
    {
      "x": -6,
      "y": 22,
      "z": 27,
      "name": "Empty"
    },
    {
      "x": -6,
      "y": 23,
      "z": 27,
      "name": "Rock_Sandstone_Brick_Ornate"
    },
    {
      "x": -6,
      "y": 25,
      "z": 27,
      "name": "Furniture_Village_Bookcase",
      "rotation": 1
    },
    {
      "x": -6,
      "y": 26,
      "z": 27,
      "name": "Furniture_Village_Bookcase",
      "rotation": 1
    },
    {
      "x": -6,
      "y": 27,
      "z": 27,
      "name": "Rock_Sandstone"
    },
    {
      "x": -6,
      "y": 28,
      "z": 27,
      "name": "Rock_Sandstone"
    },
    {
      "x": -6,
      "y": 29,
      "z": 27,
      "name": "Rock_Sandstone"
    },
    {
      "x": -6,
      "y": 17,
      "z": 28,
      "name": "Rock_Sandstone"
    },
    {
      "x": -6,
      "y": 18,
      "z": 28,
      "name": "Soil_Sand_White"
    },
    {
      "x": -6,
      "y": 19,
      "z": 28,
      "name": "Empty"
    },
    {
      "x": -6,
      "y": 20,
      "z": 28,
      "name": "Empty"
    },
    {
      "x": -6,
      "y": 21,
      "z": 28,
      "name": "Empty"
    },
    {
      "x": -6,
      "y": 22,
      "z": 28,
      "name": "Empty"
    },
    {
      "x": -6,
      "y": 23,
      "z": 28,
      "name": "Rock_Sandstone_Brick_Ornate"
    },
    {
      "x": -6,
      "y": 24,
      "z": 28,
      "name": "Furniture_Temple_Wind_Pot"
    },
    {
      "x": -6,
      "y": 25,
      "z": 28,
      "name": "Furniture_Temple_Wind_Pot",
      "filler": 1024
    },
    {
      "x": -6,
      "y": 26,
      "z": 28,
      "name": "Furniture_Village_Bookcase",
      "rotation": 1
    },
    {
      "x": -6,
      "y": 27,
      "z": 28,
      "name": "Rock_Sandstone"
    },
    {
      "x": -6,
      "y": 28,
      "z": 28,
      "name": "Rock_Sandstone"
    },
    {
      "x": -6,
      "y": 29,
      "z": 28,
      "name": "Rock_Sandstone"
    },
    {
      "x": -6,
      "y": 17,
      "z": 29,
      "name": "Rock_Sandstone"
    },
    {
      "x": -6,
      "y": 18,
      "z": 29,
      "name": "Soil_Sand_White"
    },
    {
      "x": -6,
      "y": 19,
      "z": 29,
      "name": "Furniture_Tavern_Barrel"
    },
    {
      "x": -6,
      "y": 20,
      "z": 29,
      "name": "Empty"
    },
    {
      "x": -6,
      "y": 21,
      "z": 29,
      "name": "Empty"
    },
    {
      "x": -6,
      "y": 22,
      "z": 29,
      "name": "Empty"
    },
    {
      "x": -6,
      "y": 23,
      "z": 29,
      "name": "Rock_Sandstone_Brick_Ornate"
    },
    {
      "x": -6,
      "y": 24,
      "z": 29,
      "name": "Furniture_Village_Pot"
    },
    {
      "x": -6,
      "y": 25,
      "z": 29,
      "name": "Empty"
    },
    {
      "x": -6,
      "y": 26,
      "z": 29,
      "name": "Empty"
    },
    {
      "x": -6,
      "y": 27,
      "z": 29,
      "name": "Rock_Sandstone"
    },
    {
      "x": -6,
      "y": 28,
      "z": 29,
      "name": "Rock_Sandstone"
    },
    {
      "x": -6,
      "y": 29,
      "z": 29,
      "name": "Rock_Sandstone"
    },
    {
      "x": -6,
      "y": 17,
      "z": 30,
      "name": "Rock_Sandstone"
    },
    {
      "x": -6,
      "y": 18,
      "z": 30,
      "name": "Soil_Sand_White"
    },
    {
      "x": -6,
      "y": 19,
      "z": 30,
      "name": "Wood_Dry_Trunk_Full"
    },
    {
      "x": -6,
      "y": 20,
      "z": 30,
      "name": "Wood_Dry_Trunk_Full"
    },
    {
      "x": -6,
      "y": 21,
      "z": 30,
      "name": "Empty"
    },
    {
      "x": -6,
      "y": 22,
      "z": 30,
      "name": "Empty"
    },
    {
      "x": -6,
      "y": 23,
      "z": 30,
      "name": "Rock_Sandstone_Brick_Ornate"
    },
    {
      "x": -6,
      "y": 24,
      "z": 30,
      "name": "Furniture_Village_Pot"
    },
    {
      "x": -6,
      "y": 25,
      "z": 30,
      "name": "Rock_Sandstone"
    },
    {
      "x": -6,
      "y": 26,
      "z": 30,
      "name": "Rock_Sandstone"
    },
    {
      "x": -6,
      "y": 27,
      "z": 30,
      "name": "Rock_Sandstone"
    },
    {
      "x": -6,
      "y": 28,
      "z": 30,
      "name": "Rock_Sandstone"
    },
    {
      "x": -6,
      "y": 29,
      "z": 30,
      "name": "Rock_Sandstone"
    },
    {
      "x": -6,
      "y": 17,
      "z": 31,
      "name": "Rock_Sandstone"
    },
    {
      "x": -6,
      "y": 18,
      "z": 31,
      "name": "Soil_Sand_White"
    },
    {
      "x": -6,
      "y": 19,
      "z": 31,
      "name": "Wood_Drywood_Planks"
    },
    {
      "x": -6,
      "y": 20,
      "z": 31,
      "name": "Furniture_Village_Crate"
    },
    {
      "x": -6,
      "y": 21,
      "z": 31,
      "name": "Furniture_Tavern_Barrel"
    },
    {
      "x": -6,
      "y": 22,
      "z": 31,
      "name": "Rock_Sandstone"
    },
    {
      "x": -6,
      "y": 23,
      "z": 31,
      "name": "Rock_Sandstone"
    },
    {
      "x": -6,
      "y": 24,
      "z": 31,
      "name": "Rock_Sandstone"
    },
    {
      "x": -6,
      "y": 25,
      "z": 31,
      "name": "Rock_Sandstone"
    },
    {
      "x": -6,
      "y": 26,
      "z": 31,
      "name": "Rock_Sandstone"
    },
    {
      "x": -6,
      "y": 27,
      "z": 31,
      "name": "Rock_Sandstone"
    },
    {
      "x": -6,
      "y": 28,
      "z": 31,
      "name": "Rock_Sandstone"
    },
    {
      "x": -6,
      "y": 29,
      "z": 31,
      "name": "Rock_Sandstone"
    },
    {
      "x": -6,
      "y": 17,
      "z": 32,
      "name": "Rock_Sandstone"
    },
    {
      "x": -6,
      "y": 18,
      "z": 32,
      "name": "Soil_Sand_White"
    },
    {
      "x": -6,
      "y": 19,
      "z": 32,
      "name": "Wood_Drywood_Planks"
    },
    {
      "x": -6,
      "y": 20,
      "z": 32,
      "name": "Furniture_Village_Crate"
    },
    {
      "x": -6,
      "y": 21,
      "z": 32,
      "name": "Furniture_Tavern_Barrel"
    },
    {
      "x": -6,
      "y": 22,
      "z": 32,
      "name": "Rock_Sandstone"
    },
    {
      "x": -6,
      "y": 23,
      "z": 32,
      "name": "Rock_Sandstone"
    },
    {
      "x": -6,
      "y": 24,
      "z": 32,
      "name": "Rock_Sandstone"
    },
    {
      "x": -6,
      "y": 25,
      "z": 32,
      "name": "Rock_Sandstone"
    },
    {
      "x": -6,
      "y": 26,
      "z": 32,
      "name": "Rock_Sandstone"
    },
    {
      "x": -6,
      "y": 27,
      "z": 32,
      "name": "Rock_Sandstone"
    },
    {
      "x": -6,
      "y": 28,
      "z": 32,
      "name": "Rock_Sandstone"
    },
    {
      "x": -6,
      "y": 29,
      "z": 32,
      "name": "Rock_Sandstone"
    },
    {
      "x": -6,
      "y": 17,
      "z": 33,
      "name": "Rock_Sandstone"
    },
    {
      "x": -6,
      "y": 18,
      "z": 33,
      "name": "Rock_Sandstone"
    },
    {
      "x": -6,
      "y": 19,
      "z": 33,
      "name": "Rock_Sandstone"
    },
    {
      "x": -6,
      "y": 20,
      "z": 33,
      "name": "Rock_Sandstone"
    },
    {
      "x": -6,
      "y": 21,
      "z": 33,
      "name": "Rock_Sandstone"
    },
    {
      "x": -6,
      "y": 22,
      "z": 33,
      "name": "Rock_Sandstone"
    },
    {
      "x": -6,
      "y": 23,
      "z": 33,
      "name": "Rock_Sandstone"
    },
    {
      "x": -6,
      "y": 24,
      "z": 33,
      "name": "Rock_Sandstone"
    },
    {
      "x": -6,
      "y": 25,
      "z": 33,
      "name": "Rock_Sandstone"
    },
    {
      "x": -6,
      "y": 26,
      "z": 33,
      "name": "Rock_Sandstone"
    },
    {
      "x": -6,
      "y": 27,
      "z": 33,
      "name": "Rock_Sandstone"
    },
    {
      "x": -6,
      "y": 28,
      "z": 33,
      "name": "Rock_Sandstone"
    },
    {
      "x": -6,
      "y": 17,
      "z": 34,
      "name": "Rock_Sandstone"
    },
    {
      "x": -6,
      "y": 18,
      "z": 34,
      "name": "Rock_Sandstone"
    },
    {
      "x": -6,
      "y": 19,
      "z": 34,
      "name": "Rock_Sandstone"
    },
    {
      "x": -6,
      "y": 20,
      "z": 34,
      "name": "Rock_Sandstone"
    },
    {
      "x": -6,
      "y": 21,
      "z": 34,
      "name": "Rock_Sandstone"
    },
    {
      "x": -6,
      "y": 22,
      "z": 34,
      "name": "Rock_Sandstone"
    },
    {
      "x": -6,
      "y": 23,
      "z": 34,
      "name": "Rock_Sandstone"
    },
    {
      "x": -6,
      "y": 24,
      "z": 34,
      "name": "Rock_Sandstone"
    },
    {
      "x": -6,
      "y": 25,
      "z": 34,
      "name": "Rock_Sandstone"
    },
    {
      "x": -6,
      "y": 26,
      "z": 34,
      "name": "Rock_Sandstone"
    },
    {
      "x": -6,
      "y": 27,
      "z": 34,
      "name": "Rock_Sandstone"
    },
    {
      "x": -6,
      "y": 18,
      "z": 35,
      "name": "Rock_Sandstone"
    },
    {
      "x": -6,
      "y": 19,
      "z": 35,
      "name": "Rock_Sandstone"
    },
    {
      "x": -6,
      "y": 20,
      "z": 35,
      "name": "Rock_Sandstone"
    },
    {
      "x": -6,
      "y": 21,
      "z": 35,
      "name": "Rock_Sandstone"
    },
    {
      "x": -6,
      "y": 22,
      "z": 35,
      "name": "Rock_Sandstone"
    },
    {
      "x": -6,
      "y": 23,
      "z": 35,
      "name": "Rock_Sandstone"
    },
    {
      "x": -6,
      "y": 24,
      "z": 35,
      "name": "Rock_Sandstone"
    },
    {
      "x": -6,
      "y": 25,
      "z": 35,
      "name": "Rock_Sandstone"
    },
    {
      "x": -6,
      "y": 26,
      "z": 35,
      "name": "Rock_Sandstone"
    },
    {
      "x": -6,
      "y": 27,
      "z": 35,
      "name": "Rock_Sandstone"
    },
    {
      "x": -5,
      "y": 18,
      "z": 21,
      "name": "Rock_Sandstone"
    },
    {
      "x": -5,
      "y": 19,
      "z": 21,
      "name": "Rock_Sandstone"
    },
    {
      "x": -5,
      "y": 20,
      "z": 21,
      "name": "Rock_Sandstone"
    },
    {
      "x": -5,
      "y": 21,
      "z": 21,
      "name": "Rock_Sandstone"
    },
    {
      "x": -5,
      "y": 22,
      "z": 21,
      "name": "Rock_Sandstone"
    },
    {
      "x": -5,
      "y": 23,
      "z": 21,
      "name": "Rock_Sandstone"
    },
    {
      "x": -5,
      "y": 24,
      "z": 21,
      "name": "Rock_Sandstone"
    },
    {
      "x": -5,
      "y": 25,
      "z": 21,
      "name": "Rock_Sandstone"
    },
    {
      "x": -5,
      "y": 26,
      "z": 21,
      "name": "Rock_Sandstone"
    },
    {
      "x": -5,
      "y": 27,
      "z": 21,
      "name": "Rock_Sandstone"
    },
    {
      "x": -5,
      "y": 17,
      "z": 22,
      "name": "Rock_Sandstone"
    },
    {
      "x": -5,
      "y": 18,
      "z": 22,
      "name": "Rock_Sandstone"
    },
    {
      "x": -5,
      "y": 19,
      "z": 22,
      "name": "Rock_Sandstone"
    },
    {
      "x": -5,
      "y": 20,
      "z": 22,
      "name": "Rock_Sandstone"
    },
    {
      "x": -5,
      "y": 21,
      "z": 22,
      "name": "Rock_Sandstone"
    },
    {
      "x": -5,
      "y": 22,
      "z": 22,
      "name": "Rock_Sandstone"
    },
    {
      "x": -5,
      "y": 23,
      "z": 22,
      "name": "Rock_Sandstone_Brick"
    },
    {
      "x": -5,
      "y": 24,
      "z": 22,
      "name": "Rock_Sandstone_Brick"
    },
    {
      "x": -5,
      "y": 25,
      "z": 22,
      "name": "Rock_Sandstone_Brick_Ornate"
    },
    {
      "x": -5,
      "y": 26,
      "z": 22,
      "name": "Rock_Sandstone"
    },
    {
      "x": -5,
      "y": 27,
      "z": 22,
      "name": "Rock_Sandstone"
    },
    {
      "x": -5,
      "y": 28,
      "z": 22,
      "name": "Rock_Sandstone"
    },
    {
      "x": -5,
      "y": 17,
      "z": 23,
      "name": "Rock_Sandstone"
    },
    {
      "x": -5,
      "y": 18,
      "z": 23,
      "name": "Soil_Sand_White"
    },
    {
      "x": -5,
      "y": 19,
      "z": 23,
      "name": "Furniture_Village_Crate"
    },
    {
      "x": -5,
      "y": 20,
      "z": 23,
      "name": "Furniture_Tavern_Barrel"
    },
    {
      "x": -5,
      "y": 21,
      "z": 23,
      "name": "Empty"
    },
    {
      "x": -5,
      "y": 22,
      "z": 23,
      "name": "Empty"
    },
    {
      "x": -5,
      "y": 23,
      "z": 23,
      "name": "Rock_Sandstone_Brick_Ornate"
    },
    {
      "x": -5,
      "y": 24,
      "z": 23,
      "name": "Rock_Sandstone_Brick"
    },
    {
      "x": -5,
      "y": 25,
      "z": 23,
      "name": "Rock_Sandstone_Brick_Ornate"
    },
    {
      "x": -5,
      "y": 26,
      "z": 23,
      "name": "Rock_Sandstone"
    },
    {
      "x": -5,
      "y": 27,
      "z": 23,
      "name": "Rock_Sandstone"
    },
    {
      "x": -5,
      "y": 28,
      "z": 23,
      "name": "Rock_Sandstone"
    },
    {
      "x": -5,
      "y": 29,
      "z": 23,
      "name": "Rock_Sandstone"
    },
    {
      "x": -5,
      "y": 17,
      "z": 24,
      "name": "Rock_Sandstone"
    },
    {
      "x": -5,
      "y": 18,
      "z": 24,
      "name": "Soil_Sand_White"
    },
    {
      "x": -5,
      "y": 19,
      "z": 24,
      "name": "Furniture_Tavern_Barrel"
    },
    {
      "x": -5,
      "y": 20,
      "z": 24,
      "name": "Empty"
    },
    {
      "x": -5,
      "y": 21,
      "z": 24,
      "name": "Empty"
    },
    {
      "x": -5,
      "y": 22,
      "z": 24,
      "name": "Empty"
    },
    {
      "x": -5,
      "y": 23,
      "z": 24,
      "name": "Rock_Sandstone_Brick_Ornate"
    },
    {
      "x": -5,
      "y": 24,
      "z": 24,
      "name": "Empty"
    },
    {
      "x": -5,
      "y": 25,
      "z": 24,
      "name": "Empty"
    },
    {
      "x": -5,
      "y": 26,
      "z": 24,
      "name": "Empty"
    },
    {
      "x": -5,
      "y": 27,
      "z": 24,
      "name": "Empty"
    },
    {
      "x": -5,
      "y": 28,
      "z": 24,
      "name": "Rock_Sandstone"
    },
    {
      "x": -5,
      "y": 29,
      "z": 24,
      "name": "Rock_Sandstone"
    },
    {
      "x": -5,
      "y": 17,
      "z": 25,
      "name": "Rock_Sandstone"
    },
    {
      "x": -5,
      "y": 18,
      "z": 25,
      "name": "Soil_Sand_White"
    },
    {
      "x": -5,
      "y": 19,
      "z": 25,
      "name": "Empty"
    },
    {
      "x": -5,
      "y": 20,
      "z": 25,
      "name": "Empty"
    },
    {
      "x": -5,
      "y": 21,
      "z": 25,
      "name": "Empty"
    },
    {
      "x": -5,
      "y": 22,
      "z": 25,
      "name": "Empty"
    },
    {
      "x": -5,
      "y": 23,
      "z": 25,
      "name": "Rock_Sandstone_Brick_Ornate"
    },
    {
      "x": -5,
      "y": 24,
      "z": 25,
      "name": "Container_Bucket"
    },
    {
      "x": -5,
      "y": 25,
      "z": 25,
      "name": "Empty"
    },
    {
      "x": -5,
      "y": 26,
      "z": 25,
      "name": "Empty"
    },
    {
      "x": -5,
      "y": 27,
      "z": 25,
      "name": "Empty"
    },
    {
      "x": -5,
      "y": 28,
      "z": 25,
      "name": "Rock_Sandstone"
    },
    {
      "x": -5,
      "y": 29,
      "z": 25,
      "name": "Rock_Sandstone"
    },
    {
      "x": -5,
      "y": 17,
      "z": 26,
      "name": "Rock_Sandstone"
    },
    {
      "x": -5,
      "y": 18,
      "z": 26,
      "name": "Soil_Sand_White"
    },
    {
      "x": -5,
      "y": 19,
      "z": 26,
      "name": "Empty"
    },
    {
      "x": -5,
      "y": 20,
      "z": 26,
      "name": "Empty"
    },
    {
      "x": -5,
      "y": 21,
      "z": 26,
      "name": "Empty"
    },
    {
      "x": -5,
      "y": 22,
      "z": 26,
      "name": "Empty"
    },
    {
      "x": -5,
      "y": 23,
      "z": 26,
      "name": "Rock_Sandstone_Brick_Ornate"
    },
    {
      "x": -5,
      "y": 24,
      "z": 26,
      "name": "Furniture_Ancient_Pot"
    },
    {
      "x": -5,
      "y": 25,
      "z": 26,
      "name": "Empty"
    },
    {
      "x": -5,
      "y": 26,
      "z": 26,
      "name": "Empty"
    },
    {
      "x": -5,
      "y": 27,
      "z": 26,
      "name": "Empty"
    },
    {
      "x": -5,
      "y": 28,
      "z": 26,
      "name": "Rock_Sandstone"
    },
    {
      "x": -5,
      "y": 29,
      "z": 26,
      "name": "Rock_Sandstone"
    },
    {
      "x": -5,
      "y": 17,
      "z": 27,
      "name": "Rock_Sandstone"
    },
    {
      "x": -5,
      "y": 18,
      "z": 27,
      "name": "Soil_Sand_White"
    },
    {
      "x": -5,
      "y": 19,
      "z": 27,
      "name": "Empty"
    },
    {
      "x": -5,
      "y": 20,
      "z": 27,
      "name": "Empty"
    },
    {
      "x": -5,
      "y": 21,
      "z": 27,
      "name": "Empty"
    },
    {
      "x": -5,
      "y": 22,
      "z": 27,
      "name": "Empty"
    },
    {
      "x": -5,
      "y": 23,
      "z": 27,
      "name": "Rock_Sandstone_Brick_Ornate"
    },
    {
      "x": -5,
      "y": 24,
      "z": 27,
      "name": "Deco_Pot_Clay_Broken"
    },
    {
      "x": -5,
      "y": 25,
      "z": 27,
      "name": "Empty"
    },
    {
      "x": -5,
      "y": 26,
      "z": 27,
      "name": "Empty"
    },
    {
      "x": -5,
      "y": 27,
      "z": 27,
      "name": "Empty"
    },
    {
      "x": -5,
      "y": 28,
      "z": 27,
      "name": "Rock_Sandstone"
    },
    {
      "x": -5,
      "y": 29,
      "z": 27,
      "name": "Rock_Sandstone"
    },
    {
      "x": -5,
      "y": 17,
      "z": 28,
      "name": "Rock_Sandstone"
    },
    {
      "x": -5,
      "y": 18,
      "z": 28,
      "name": "Soil_Sand_White"
    },
    {
      "x": -5,
      "y": 19,
      "z": 28,
      "name": "Empty"
    },
    {
      "x": -5,
      "y": 20,
      "z": 28,
      "name": "Empty"
    },
    {
      "x": -5,
      "y": 21,
      "z": 28,
      "name": "Empty"
    },
    {
      "x": -5,
      "y": 22,
      "z": 28,
      "name": "Empty"
    },
    {
      "x": -5,
      "y": 23,
      "z": 28,
      "name": "Rock_Sandstone_Brick_Ornate"
    },
    {
      "x": -5,
      "y": 24,
      "z": 28,
      "name": "Deco_Pot_Clay_Broken"
    },
    {
      "x": -5,
      "y": 25,
      "z": 28,
      "name": "Empty"
    },
    {
      "x": -5,
      "y": 26,
      "z": 28,
      "name": "Empty"
    },
    {
      "x": -5,
      "y": 27,
      "z": 28,
      "name": "Rock_Sandstone"
    },
    {
      "x": -5,
      "y": 28,
      "z": 28,
      "name": "Rock_Sandstone"
    },
    {
      "x": -5,
      "y": 29,
      "z": 28,
      "name": "Rock_Sandstone"
    },
    {
      "x": -5,
      "y": 17,
      "z": 29,
      "name": "Rock_Sandstone"
    },
    {
      "x": -5,
      "y": 18,
      "z": 29,
      "name": "Soil_Sand_White"
    },
    {
      "x": -5,
      "y": 19,
      "z": 29,
      "name": "Empty"
    },
    {
      "x": -5,
      "y": 20,
      "z": 29,
      "name": "Empty"
    },
    {
      "x": -5,
      "y": 21,
      "z": 29,
      "name": "Empty"
    },
    {
      "x": -5,
      "y": 22,
      "z": 29,
      "name": "Empty"
    },
    {
      "x": -5,
      "y": 23,
      "z": 29,
      "name": "Rock_Sandstone_Brick_Ornate"
    },
    {
      "x": -5,
      "y": 24,
      "z": 29,
      "name": "Furniture_Village_Pot"
    },
    {
      "x": -5,
      "y": 25,
      "z": 29,
      "name": "Empty"
    },
    {
      "x": -5,
      "y": 26,
      "z": 29,
      "name": "Empty"
    },
    {
      "x": -5,
      "y": 27,
      "z": 29,
      "name": "Rock_Sandstone"
    },
    {
      "x": -5,
      "y": 28,
      "z": 29,
      "name": "Rock_Sandstone"
    },
    {
      "x": -5,
      "y": 29,
      "z": 29,
      "name": "Rock_Sandstone"
    },
    {
      "x": -5,
      "y": 17,
      "z": 30,
      "name": "Rock_Sandstone"
    },
    {
      "x": -5,
      "y": 18,
      "z": 30,
      "name": "Soil_Sand_White"
    },
    {
      "x": -5,
      "y": 19,
      "z": 30,
      "name": "Wood_Drywood_Planks"
    },
    {
      "x": -5,
      "y": 20,
      "z": 30,
      "name": "Deco_Iron_Bars"
    },
    {
      "x": -5,
      "y": 21,
      "z": 30,
      "name": "Empty"
    },
    {
      "x": -5,
      "y": 22,
      "z": 30,
      "name": "Empty"
    },
    {
      "x": -5,
      "y": 23,
      "z": 30,
      "name": "Rock_Sandstone_Brick_Ornate"
    },
    {
      "x": -5,
      "y": 24,
      "z": 30,
      "name": "Empty"
    },
    {
      "x": -5,
      "y": 25,
      "z": 30,
      "name": "Empty"
    },
    {
      "x": -5,
      "y": 26,
      "z": 30,
      "name": "Empty"
    },
    {
      "x": -5,
      "y": 27,
      "z": 30,
      "name": "Rock_Sandstone"
    },
    {
      "x": -5,
      "y": 28,
      "z": 30,
      "name": "Rock_Sandstone"
    },
    {
      "x": -5,
      "y": 29,
      "z": 30,
      "name": "Rock_Sandstone"
    },
    {
      "x": -5,
      "y": 17,
      "z": 31,
      "name": "Rock_Sandstone"
    },
    {
      "x": -5,
      "y": 18,
      "z": 31,
      "name": "Soil_Sand_White"
    },
    {
      "x": -5,
      "y": 19,
      "z": 31,
      "name": "Wood_Drywood_Planks"
    },
    {
      "x": -5,
      "y": 20,
      "z": 31,
      "name": "Furniture_Village_Crate"
    },
    {
      "x": -5,
      "y": 21,
      "z": 31,
      "name": "Furniture_Tavern_Barrel"
    },
    {
      "x": -5,
      "y": 22,
      "z": 31,
      "name": "Empty"
    },
    {
      "x": -5,
      "y": 23,
      "z": 31,
      "name": "Rock_Sandstone_Brick_Ornate"
    },
    {
      "x": -5,
      "y": 24,
      "z": 31,
      "name": "Furniture_Temple_Wind_Pot"
    },
    {
      "x": -5,
      "y": 25,
      "z": 31,
      "name": "Furniture_Temple_Wind_Pot",
      "filler": 1024
    },
    {
      "x": -5,
      "y": 26,
      "z": 31,
      "name": "Empty"
    },
    {
      "x": -5,
      "y": 27,
      "z": 31,
      "name": "Rock_Sandstone"
    },
    {
      "x": -5,
      "y": 28,
      "z": 31,
      "name": "Rock_Sandstone"
    },
    {
      "x": -5,
      "y": 29,
      "z": 31,
      "name": "Rock_Sandstone"
    },
    {
      "x": -5,
      "y": 17,
      "z": 32,
      "name": "Rock_Sandstone"
    },
    {
      "x": -5,
      "y": 18,
      "z": 32,
      "name": "Soil_Sand_White"
    },
    {
      "x": -5,
      "y": 19,
      "z": 32,
      "name": "Wood_Drywood_Planks"
    },
    {
      "x": -5,
      "y": 20,
      "z": 32,
      "name": "Furniture_Tavern_Barrel"
    },
    {
      "x": -5,
      "y": 21,
      "z": 32,
      "name": "Empty"
    },
    {
      "x": -5,
      "y": 22,
      "z": 32,
      "name": "Empty"
    },
    {
      "x": -5,
      "y": 23,
      "z": 32,
      "name": "Rock_Sandstone_Brick_Ornate"
    },
    {
      "x": -5,
      "y": 24,
      "z": 32,
      "name": "Furniture_Temple_Wind_Pot"
    },
    {
      "x": -5,
      "y": 25,
      "z": 32,
      "name": "Furniture_Temple_Wind_Pot",
      "filler": 1024
    },
    {
      "x": -5,
      "y": 26,
      "z": 32,
      "name": "Empty"
    },
    {
      "x": -5,
      "y": 27,
      "z": 32,
      "name": "Rock_Sandstone"
    },
    {
      "x": -5,
      "y": 28,
      "z": 32,
      "name": "Rock_Sandstone"
    },
    {
      "x": -5,
      "y": 29,
      "z": 32,
      "name": "Rock_Sandstone"
    },
    {
      "x": -5,
      "y": 17,
      "z": 33,
      "name": "Rock_Sandstone"
    },
    {
      "x": -5,
      "y": 18,
      "z": 33,
      "name": "Soil_Sand_White"
    },
    {
      "x": -5,
      "y": 19,
      "z": 33,
      "name": "Wood_Drywood_Planks"
    },
    {
      "x": -5,
      "y": 20,
      "z": 33,
      "name": "Furniture_Tavern_Barrel"
    },
    {
      "x": -5,
      "y": 21,
      "z": 33,
      "name": "Empty"
    },
    {
      "x": -5,
      "y": 22,
      "z": 33,
      "name": "Empty"
    },
    {
      "x": -5,
      "y": 23,
      "z": 33,
      "name": "Rock_Sandstone_Brick_Ornate"
    },
    {
      "x": -5,
      "y": 24,
      "z": 33,
      "name": "Furniture_Village_Bookcase",
      "rotation": 2
    },
    {
      "x": -5,
      "y": 25,
      "z": 33,
      "name": "Furniture_Village_Bookcase",
      "rotation": 2
    },
    {
      "x": -5,
      "y": 26,
      "z": 33,
      "name": "Empty"
    },
    {
      "x": -5,
      "y": 27,
      "z": 33,
      "name": "Rock_Sandstone"
    },
    {
      "x": -5,
      "y": 28,
      "z": 33,
      "name": "Rock_Sandstone"
    },
    {
      "x": -5,
      "y": 29,
      "z": 33,
      "name": "Rock_Sandstone"
    },
    {
      "x": -5,
      "y": 17,
      "z": 34,
      "name": "Rock_Sandstone"
    },
    {
      "x": -5,
      "y": 18,
      "z": 34,
      "name": "Soil_Sand_White"
    },
    {
      "x": -5,
      "y": 19,
      "z": 34,
      "name": "Wood_Drywood_Planks"
    },
    {
      "x": -5,
      "y": 20,
      "z": 34,
      "name": "Furniture_Tavern_Barrel"
    },
    {
      "x": -5,
      "y": 21,
      "z": 34,
      "name": "Rock_Sandstone"
    },
    {
      "x": -5,
      "y": 22,
      "z": 34,
      "name": "Rock_Sandstone"
    },
    {
      "x": -5,
      "y": 23,
      "z": 34,
      "name": "Rock_Sandstone"
    },
    {
      "x": -5,
      "y": 24,
      "z": 34,
      "name": "Rock_Sandstone"
    },
    {
      "x": -5,
      "y": 25,
      "z": 34,
      "name": "Rock_Sandstone"
    },
    {
      "x": -5,
      "y": 26,
      "z": 34,
      "name": "Rock_Sandstone"
    },
    {
      "x": -5,
      "y": 27,
      "z": 34,
      "name": "Rock_Sandstone"
    },
    {
      "x": -5,
      "y": 28,
      "z": 34,
      "name": "Rock_Sandstone"
    },
    {
      "x": -5,
      "y": 18,
      "z": 35,
      "name": "Rock_Sandstone"
    },
    {
      "x": -5,
      "y": 19,
      "z": 35,
      "name": "Rock_Sandstone"
    },
    {
      "x": -5,
      "y": 20,
      "z": 35,
      "name": "Rock_Sandstone"
    },
    {
      "x": -5,
      "y": 21,
      "z": 35,
      "name": "Rock_Sandstone"
    },
    {
      "x": -5,
      "y": 22,
      "z": 35,
      "name": "Rock_Sandstone"
    },
    {
      "x": -5,
      "y": 23,
      "z": 35,
      "name": "Rock_Sandstone"
    },
    {
      "x": -5,
      "y": 24,
      "z": 35,
      "name": "Rock_Sandstone"
    },
    {
      "x": -5,
      "y": 25,
      "z": 35,
      "name": "Rock_Sandstone"
    },
    {
      "x": -5,
      "y": 26,
      "z": 35,
      "name": "Rock_Sandstone"
    },
    {
      "x": -5,
      "y": 27,
      "z": 35,
      "name": "Rock_Sandstone"
    },
    {
      "x": -4,
      "y": 18,
      "z": 21,
      "name": "Rock_Sandstone"
    },
    {
      "x": -4,
      "y": 19,
      "z": 21,
      "name": "Rock_Sandstone"
    },
    {
      "x": -4,
      "y": 20,
      "z": 21,
      "name": "Rock_Sandstone"
    },
    {
      "x": -4,
      "y": 21,
      "z": 21,
      "name": "Rock_Sandstone"
    },
    {
      "x": -4,
      "y": 22,
      "z": 21,
      "name": "Rock_Sandstone"
    },
    {
      "x": -4,
      "y": 23,
      "z": 21,
      "name": "Rock_Sandstone"
    },
    {
      "x": -4,
      "y": 24,
      "z": 21,
      "name": "Rock_Sandstone"
    },
    {
      "x": -4,
      "y": 25,
      "z": 21,
      "name": "Rock_Sandstone"
    },
    {
      "x": -4,
      "y": 26,
      "z": 21,
      "name": "Rock_Sandstone"
    },
    {
      "x": -4,
      "y": 27,
      "z": 21,
      "name": "Rock_Sandstone"
    },
    {
      "x": -4,
      "y": 28,
      "z": 21,
      "name": "Rock_Sandstone"
    },
    {
      "x": -4,
      "y": 17,
      "z": 22,
      "name": "Rock_Sandstone"
    },
    {
      "x": -4,
      "y": 18,
      "z": 22,
      "name": "Rock_Sandstone"
    },
    {
      "x": -4,
      "y": 19,
      "z": 22,
      "name": "Rock_Sandstone"
    },
    {
      "x": -4,
      "y": 20,
      "z": 22,
      "name": "Rock_Sandstone"
    },
    {
      "x": -4,
      "y": 21,
      "z": 22,
      "name": "Empty"
    },
    {
      "x": -4,
      "y": 22,
      "z": 22,
      "name": "Empty"
    },
    {
      "x": -4,
      "y": 23,
      "z": 22,
      "name": "Rock_Sandstone_Brick_Ornate"
    },
    {
      "x": -4,
      "y": 24,
      "z": 22,
      "name": "Empty"
    },
    {
      "x": -4,
      "y": 25,
      "z": 22,
      "name": "Empty"
    },
    {
      "x": -4,
      "y": 26,
      "z": 22,
      "name": "Rock_Sandstone"
    },
    {
      "x": -4,
      "y": 27,
      "z": 22,
      "name": "Rock_Sandstone"
    },
    {
      "x": -4,
      "y": 28,
      "z": 22,
      "name": "Rock_Sandstone"
    },
    {
      "x": -4,
      "y": 17,
      "z": 23,
      "name": "Rock_Sandstone"
    },
    {
      "x": -4,
      "y": 18,
      "z": 23,
      "name": "Soil_Sand_White"
    },
    {
      "x": -4,
      "y": 19,
      "z": 23,
      "name": "Furniture_Tavern_Barrel"
    },
    {
      "x": -4,
      "y": 20,
      "z": 23,
      "name": "Container_Bucket"
    },
    {
      "x": -4,
      "y": 21,
      "z": 23,
      "name": "Empty"
    },
    {
      "x": -4,
      "y": 22,
      "z": 23,
      "name": "Empty"
    },
    {
      "x": -4,
      "y": 23,
      "z": 23,
      "name": "Rock_Sandstone_Brick_Ornate"
    },
    {
      "x": -4,
      "y": 24,
      "z": 23,
      "name": "Furniture_Tavern_Barrel"
    },
    {
      "x": -4,
      "y": 25,
      "z": 23,
      "name": "Empty"
    },
    {
      "x": -4,
      "y": 26,
      "z": 23,
      "name": "Empty"
    },
    {
      "x": -4,
      "y": 27,
      "z": 23,
      "name": "Rock_Sandstone"
    },
    {
      "x": -4,
      "y": 28,
      "z": 23,
      "name": "Rock_Sandstone"
    },
    {
      "x": -4,
      "y": 29,
      "z": 23,
      "name": "Rock_Sandstone"
    },
    {
      "x": -4,
      "y": 17,
      "z": 24,
      "name": "Rock_Sandstone"
    },
    {
      "x": -4,
      "y": 18,
      "z": 24,
      "name": "Soil_Sand_White"
    },
    {
      "x": -4,
      "y": 19,
      "z": 24,
      "name": "Empty"
    },
    {
      "x": -4,
      "y": 20,
      "z": 24,
      "name": "Empty"
    },
    {
      "x": -4,
      "y": 21,
      "z": 24,
      "name": "Empty"
    },
    {
      "x": -4,
      "y": 22,
      "z": 24,
      "name": "Empty"
    },
    {
      "x": -4,
      "y": 23,
      "z": 24,
      "name": "Rock_Sandstone_Brick_Ornate"
    },
    {
      "x": -4,
      "y": 24,
      "z": 24,
      "name": "Furniture_Tavern_Barrel"
    },
    {
      "x": -4,
      "y": 25,
      "z": 24,
      "name": "Empty"
    },
    {
      "x": -4,
      "y": 26,
      "z": 24,
      "name": "Empty"
    },
    {
      "x": -4,
      "y": 27,
      "z": 24,
      "name": "Empty"
    },
    {
      "x": -4,
      "y": 28,
      "z": 24,
      "name": "Rock_Sandstone"
    },
    {
      "x": -4,
      "y": 29,
      "z": 24,
      "name": "Rock_Sandstone"
    },
    {
      "x": -4,
      "y": 17,
      "z": 25,
      "name": "Rock_Sandstone"
    },
    {
      "x": -4,
      "y": 18,
      "z": 25,
      "name": "Soil_Sand_White"
    },
    {
      "x": -4,
      "y": 19,
      "z": 25,
      "name": "Empty"
    },
    {
      "x": -4,
      "y": 20,
      "z": 25,
      "name": "Empty"
    },
    {
      "x": -4,
      "y": 21,
      "z": 25,
      "name": "Empty"
    },
    {
      "x": -4,
      "y": 22,
      "z": 25,
      "name": "Empty"
    },
    {
      "x": -4,
      "y": 23,
      "z": 25,
      "name": "Rock_Sandstone_Brick_Ornate"
    },
    {
      "x": -4,
      "y": 24,
      "z": 25,
      "name": "Empty"
    },
    {
      "x": -4,
      "y": 25,
      "z": 25,
      "name": "Empty"
    },
    {
      "x": -4,
      "y": 26,
      "z": 25,
      "name": "Empty"
    },
    {
      "x": -4,
      "y": 27,
      "z": 25,
      "name": "Empty"
    },
    {
      "x": -4,
      "y": 28,
      "z": 25,
      "name": "Rock_Sandstone"
    },
    {
      "x": -4,
      "y": 29,
      "z": 25,
      "name": "Rock_Sandstone"
    },
    {
      "x": -4,
      "y": 17,
      "z": 26,
      "name": "Rock_Sandstone"
    },
    {
      "x": -4,
      "y": 18,
      "z": 26,
      "name": "Soil_Sand_White"
    },
    {
      "x": -4,
      "y": 19,
      "z": 26,
      "name": "Empty"
    },
    {
      "x": -4,
      "y": 20,
      "z": 26,
      "name": "Empty"
    },
    {
      "x": -4,
      "y": 21,
      "z": 26,
      "name": "Empty"
    },
    {
      "x": -4,
      "y": 22,
      "z": 26,
      "name": "Empty"
    },
    {
      "x": -4,
      "y": 23,
      "z": 26,
      "name": "Rock_Sandstone_Brick_Ornate"
    },
    {
      "x": -4,
      "y": 24,
      "z": 26,
      "name": "Empty"
    },
    {
      "x": -4,
      "y": 25,
      "z": 26,
      "name": "Empty"
    },
    {
      "x": -4,
      "y": 26,
      "z": 26,
      "name": "Empty"
    },
    {
      "x": -4,
      "y": 27,
      "z": 26,
      "name": "Empty"
    },
    {
      "x": -4,
      "y": 28,
      "z": 26,
      "name": "Rock_Sandstone"
    },
    {
      "x": -4,
      "y": 29,
      "z": 26,
      "name": "Rock_Sandstone"
    },
    {
      "x": -4,
      "y": 17,
      "z": 27,
      "name": "Rock_Sandstone"
    },
    {
      "x": -4,
      "y": 18,
      "z": 27,
      "name": "Soil_Sand_White"
    },
    {
      "x": -4,
      "y": 19,
      "z": 27,
      "name": "Empty"
    },
    {
      "x": -4,
      "y": 20,
      "z": 27,
      "name": "Empty"
    },
    {
      "x": -4,
      "y": 21,
      "z": 27,
      "name": "Empty"
    },
    {
      "x": -4,
      "y": 22,
      "z": 27,
      "name": "Empty"
    },
    {
      "x": -4,
      "y": 23,
      "z": 27,
      "name": "Rock_Sandstone_Brick_Ornate"
    },
    {
      "x": -4,
      "y": 24,
      "z": 27,
      "name": "Empty"
    },
    {
      "x": -4,
      "y": 25,
      "z": 27,
      "name": "Empty"
    },
    {
      "x": -4,
      "y": 26,
      "z": 27,
      "name": "Empty"
    },
    {
      "x": -4,
      "y": 27,
      "z": 27,
      "name": "Empty"
    },
    {
      "x": -4,
      "y": 28,
      "z": 27,
      "name": "Rock_Sandstone"
    },
    {
      "x": -4,
      "y": 29,
      "z": 27,
      "name": "Rock_Sandstone"
    },
    {
      "x": -4,
      "y": 17,
      "z": 28,
      "name": "Rock_Sandstone"
    },
    {
      "x": -4,
      "y": 18,
      "z": 28,
      "name": "Soil_Sand_White"
    },
    {
      "x": -4,
      "y": 19,
      "z": 28,
      "name": "Empty"
    },
    {
      "x": -4,
      "y": 20,
      "z": 28,
      "name": "Empty"
    },
    {
      "x": -4,
      "y": 21,
      "z": 28,
      "name": "Empty"
    },
    {
      "x": -4,
      "y": 22,
      "z": 28,
      "name": "Empty"
    },
    {
      "x": -4,
      "y": 23,
      "z": 28,
      "name": "Rock_Sandstone_Brick_Ornate"
    },
    {
      "x": -4,
      "y": 24,
      "z": 28,
      "name": "Empty"
    },
    {
      "x": -4,
      "y": 25,
      "z": 28,
      "name": "Empty"
    },
    {
      "x": -4,
      "y": 26,
      "z": 28,
      "name": "Empty"
    },
    {
      "x": -4,
      "y": 27,
      "z": 28,
      "name": "Empty"
    },
    {
      "x": -4,
      "y": 28,
      "z": 28,
      "name": "Rock_Sandstone"
    },
    {
      "x": -4,
      "y": 29,
      "z": 28,
      "name": "Rock_Sandstone"
    },
    {
      "x": -4,
      "y": 17,
      "z": 29,
      "name": "Rock_Sandstone"
    },
    {
      "x": -4,
      "y": 18,
      "z": 29,
      "name": "Soil_Sand_White"
    },
    {
      "x": -4,
      "y": 19,
      "z": 29,
      "name": "Empty"
    },
    {
      "x": -4,
      "y": 20,
      "z": 29,
      "name": "Empty"
    },
    {
      "x": -4,
      "y": 21,
      "z": 29,
      "name": "Empty"
    },
    {
      "x": -4,
      "y": 22,
      "z": 29,
      "name": "Empty"
    },
    {
      "x": -4,
      "y": 23,
      "z": 29,
      "name": "Rock_Sandstone_Brick_Ornate"
    },
    {
      "x": -4,
      "y": 24,
      "z": 29,
      "name": "Empty"
    },
    {
      "x": -4,
      "y": 25,
      "z": 29,
      "name": "Empty"
    },
    {
      "x": -4,
      "y": 26,
      "z": 29,
      "name": "Empty"
    },
    {
      "x": -4,
      "y": 27,
      "z": 29,
      "name": "Rock_Sandstone"
    },
    {
      "x": -4,
      "y": 28,
      "z": 29,
      "name": "Rock_Sandstone"
    },
    {
      "x": -4,
      "y": 29,
      "z": 29,
      "name": "Rock_Sandstone"
    },
    {
      "x": -4,
      "y": 17,
      "z": 30,
      "name": "Rock_Sandstone"
    },
    {
      "x": -4,
      "y": 18,
      "z": 30,
      "name": "Soil_Sand_White"
    },
    {
      "x": -4,
      "y": 19,
      "z": 30,
      "name": "Wood_Dry_Trunk_Full"
    },
    {
      "x": -4,
      "y": 20,
      "z": 30,
      "name": "Wood_Dry_Trunk_Full"
    },
    {
      "x": -4,
      "y": 21,
      "z": 30,
      "name": "Empty"
    },
    {
      "x": -4,
      "y": 22,
      "z": 30,
      "name": "Empty"
    },
    {
      "x": -4,
      "y": 23,
      "z": 30,
      "name": "Rock_Sandstone_Brick_Ornate"
    },
    {
      "x": -4,
      "y": 24,
      "z": 30,
      "name": "Empty"
    },
    {
      "x": -4,
      "y": 25,
      "z": 30,
      "name": "Empty"
    },
    {
      "x": -4,
      "y": 26,
      "z": 30,
      "name": "Empty"
    },
    {
      "x": -4,
      "y": 27,
      "z": 30,
      "name": "Rock_Sandstone"
    },
    {
      "x": -4,
      "y": 28,
      "z": 30,
      "name": "Rock_Sandstone"
    },
    {
      "x": -4,
      "y": 29,
      "z": 30,
      "name": "Rock_Sandstone"
    },
    {
      "x": -4,
      "y": 17,
      "z": 31,
      "name": "Rock_Sandstone"
    },
    {
      "x": -4,
      "y": 18,
      "z": 31,
      "name": "Soil_Sand_White"
    },
    {
      "x": -4,
      "y": 19,
      "z": 31,
      "name": "Wood_Drywood_Planks"
    },
    {
      "x": -4,
      "y": 20,
      "z": 31,
      "name": "Empty"
    },
    {
      "x": -4,
      "y": 21,
      "z": 31,
      "name": "Empty"
    },
    {
      "x": -4,
      "y": 22,
      "z": 31,
      "name": "Empty"
    },
    {
      "x": -4,
      "y": 23,
      "z": 31,
      "name": "Rock_Sandstone_Brick_Ornate"
    },
    {
      "x": -4,
      "y": 24,
      "z": 31,
      "name": "Empty"
    },
    {
      "x": -4,
      "y": 25,
      "z": 31,
      "name": "Empty"
    },
    {
      "x": -4,
      "y": 26,
      "z": 31,
      "name": "Empty"
    },
    {
      "x": -4,
      "y": 27,
      "z": 31,
      "name": "Rock_Sandstone"
    },
    {
      "x": -4,
      "y": 28,
      "z": 31,
      "name": "Rock_Sandstone"
    },
    {
      "x": -4,
      "y": 29,
      "z": 31,
      "name": "Rock_Sandstone"
    },
    {
      "x": -4,
      "y": 17,
      "z": 32,
      "name": "Rock_Sandstone"
    },
    {
      "x": -4,
      "y": 18,
      "z": 32,
      "name": "Soil_Sand_White"
    },
    {
      "x": -4,
      "y": 19,
      "z": 32,
      "name": "Wood_Drywood_Planks"
    },
    {
      "x": -4,
      "y": 20,
      "z": 32,
      "name": "Empty"
    },
    {
      "x": -4,
      "y": 21,
      "z": 32,
      "name": "Empty"
    },
    {
      "x": -4,
      "y": 22,
      "z": 32,
      "name": "Empty"
    },
    {
      "x": -4,
      "y": 23,
      "z": 32,
      "name": "Rock_Sandstone_Brick_Ornate"
    },
    {
      "x": -4,
      "y": 24,
      "z": 32,
      "name": "Container_Bucket"
    },
    {
      "x": -4,
      "y": 25,
      "z": 32,
      "name": "Empty"
    },
    {
      "x": -4,
      "y": 26,
      "z": 32,
      "name": "Empty"
    },
    {
      "x": -4,
      "y": 27,
      "z": 32,
      "name": "Rock_Sandstone"
    },
    {
      "x": -4,
      "y": 28,
      "z": 32,
      "name": "Rock_Sandstone"
    },
    {
      "x": -4,
      "y": 29,
      "z": 32,
      "name": "Rock_Sandstone"
    },
    {
      "x": -4,
      "y": 17,
      "z": 33,
      "name": "Rock_Sandstone"
    },
    {
      "x": -4,
      "y": 18,
      "z": 33,
      "name": "Soil_Sand_White"
    },
    {
      "x": -4,
      "y": 19,
      "z": 33,
      "name": "Wood_Drywood_Planks"
    },
    {
      "x": -4,
      "y": 20,
      "z": 33,
      "name": "Empty"
    },
    {
      "x": -4,
      "y": 21,
      "z": 33,
      "name": "Empty"
    },
    {
      "x": -4,
      "y": 22,
      "z": 33,
      "name": "Empty"
    },
    {
      "x": -4,
      "y": 23,
      "z": 33,
      "name": "Rock_Sandstone_Brick_Ornate"
    },
    {
      "x": -4,
      "y": 24,
      "z": 33,
      "name": "Furniture_Village_Bookcase",
      "rotation": 2
    },
    {
      "x": -4,
      "y": 25,
      "z": 33,
      "name": "Furniture_Village_Bookcase",
      "rotation": 2
    },
    {
      "x": -4,
      "y": 26,
      "z": 33,
      "name": "Furniture_Village_Bookcase",
      "rotation": 2
    },
    {
      "x": -4,
      "y": 27,
      "z": 33,
      "name": "Rock_Sandstone"
    },
    {
      "x": -4,
      "y": 28,
      "z": 33,
      "name": "Rock_Sandstone"
    },
    {
      "x": -4,
      "y": 29,
      "z": 33,
      "name": "Rock_Sandstone"
    },
    {
      "x": -4,
      "y": 17,
      "z": 34,
      "name": "Rock_Sandstone"
    },
    {
      "x": -4,
      "y": 18,
      "z": 34,
      "name": "Soil_Sand_White"
    },
    {
      "x": -4,
      "y": 19,
      "z": 34,
      "name": "Wood_Drywood_Planks"
    },
    {
      "x": -4,
      "y": 20,
      "z": 34,
      "name": "Furniture_Tavern_Barrel"
    },
    {
      "x": -4,
      "y": 21,
      "z": 34,
      "name": "Empty"
    },
    {
      "x": -4,
      "y": 22,
      "z": 34,
      "name": "Empty"
    },
    {
      "x": -4,
      "y": 23,
      "z": 34,
      "name": "Rock_Sandstone_Brick_Ornate"
    },
    {
      "x": -4,
      "y": 24,
      "z": 34,
      "name": "Rock_Sandstone"
    },
    {
      "x": -4,
      "y": 25,
      "z": 34,
      "name": "Rock_Sandstone"
    },
    {
      "x": -4,
      "y": 26,
      "z": 34,
      "name": "Rock_Sandstone"
    },
    {
      "x": -4,
      "y": 27,
      "z": 34,
      "name": "Rock_Sandstone"
    },
    {
      "x": -4,
      "y": 28,
      "z": 34,
      "name": "Rock_Sandstone"
    },
    {
      "x": -4,
      "y": 18,
      "z": 35,
      "name": "Rock_Sandstone"
    },
    {
      "x": -4,
      "y": 19,
      "z": 35,
      "name": "Rock_Sandstone"
    },
    {
      "x": -4,
      "y": 20,
      "z": 35,
      "name": "Rock_Sandstone"
    },
    {
      "x": -4,
      "y": 21,
      "z": 35,
      "name": "Rock_Sandstone"
    },
    {
      "x": -4,
      "y": 22,
      "z": 35,
      "name": "Rock_Sandstone"
    },
    {
      "x": -4,
      "y": 23,
      "z": 35,
      "name": "Rock_Sandstone"
    },
    {
      "x": -4,
      "y": 24,
      "z": 35,
      "name": "Rock_Sandstone"
    },
    {
      "x": -4,
      "y": 25,
      "z": 35,
      "name": "Rock_Sandstone"
    },
    {
      "x": -4,
      "y": 26,
      "z": 35,
      "name": "Rock_Sandstone"
    },
    {
      "x": -4,
      "y": 27,
      "z": 35,
      "name": "Rock_Sandstone"
    },
    {
      "x": -3,
      "y": 17,
      "z": 21,
      "name": "Rock_Sandstone_Brick"
    },
    {
      "x": -3,
      "y": 18,
      "z": 21,
      "name": "Rock_Sandstone_Brick"
    },
    {
      "x": -3,
      "y": 19,
      "z": 21,
      "name": "Rock_Sandstone_Brick"
    },
    {
      "x": -3,
      "y": 20,
      "z": 21,
      "name": "Rock_Sandstone_Brick"
    },
    {
      "x": -3,
      "y": 21,
      "z": 21,
      "name": "Rock_Sandstone_Brick"
    },
    {
      "x": -3,
      "y": 22,
      "z": 21,
      "name": "Rock_Sandstone_Brick"
    },
    {
      "x": -3,
      "y": 23,
      "z": 21,
      "name": "Rock_Sandstone_Brick"
    },
    {
      "x": -3,
      "y": 24,
      "z": 21,
      "name": "Rock_Sandstone"
    },
    {
      "x": -3,
      "y": 25,
      "z": 21,
      "name": "Rock_Sandstone"
    },
    {
      "x": -3,
      "y": 26,
      "z": 21,
      "name": "Rock_Sandstone"
    },
    {
      "x": -3,
      "y": 27,
      "z": 21,
      "name": "Rock_Sandstone"
    },
    {
      "x": -3,
      "y": 28,
      "z": 21,
      "name": "Rock_Sandstone"
    },
    {
      "x": -3,
      "y": 17,
      "z": 22,
      "name": "Rock_Sandstone"
    },
    {
      "x": -3,
      "y": 18,
      "z": 22,
      "name": "Soil_Sand_White"
    },
    {
      "x": -3,
      "y": 19,
      "z": 22,
      "name": "Rock_Sandstone_Brick_Pillar_Base"
    },
    {
      "x": -3,
      "y": 20,
      "z": 22,
      "name": "Rock_Sandstone_Brick_Pillar_Middle"
    },
    {
      "x": -3,
      "y": 21,
      "z": 22,
      "name": "Rock_Sandstone_Brick_Pillar_Middle"
    },
    {
      "x": -3,
      "y": 22,
      "z": 22,
      "name": "Rock_Sandstone_Brick_Pillar_Base",
      "rotation": 8
    },
    {
      "x": -3,
      "y": 23,
      "z": 22,
      "name": "Rock_Sandstone_Brick_Ornate"
    },
    {
      "x": -3,
      "y": 24,
      "z": 22,
      "name": "Furniture_Village_Crate"
    },
    {
      "x": -3,
      "y": 25,
      "z": 22,
      "name": "Furniture_Tavern_Barrel"
    },
    {
      "x": -3,
      "y": 26,
      "z": 22,
      "name": "Furniture_Tavern_Barrel"
    },
    {
      "x": -3,
      "y": 27,
      "z": 22,
      "name": "Rock_Sandstone"
    },
    {
      "x": -3,
      "y": 28,
      "z": 22,
      "name": "Rock_Sandstone"
    },
    {
      "x": -3,
      "y": 17,
      "z": 23,
      "name": "Rock_Sandstone"
    },
    {
      "x": -3,
      "y": 18,
      "z": 23,
      "name": "Soil_Sand_White"
    },
    {
      "x": -3,
      "y": 19,
      "z": 23,
      "name": "Empty"
    },
    {
      "x": -3,
      "y": 20,
      "z": 23,
      "name": "Empty"
    },
    {
      "x": -3,
      "y": 21,
      "z": 23,
      "name": "Empty"
    },
    {
      "x": -3,
      "y": 22,
      "z": 23,
      "name": "Empty"
    },
    {
      "x": -3,
      "y": 23,
      "z": 23,
      "name": "Rock_Sandstone_Brick_Ornate"
    },
    {
      "x": -3,
      "y": 24,
      "z": 23,
      "name": "Furniture_Village_Crate"
    },
    {
      "x": -3,
      "y": 25,
      "z": 23,
      "name": "Empty"
    },
    {
      "x": -3,
      "y": 26,
      "z": 23,
      "name": "Empty"
    },
    {
      "x": -3,
      "y": 27,
      "z": 23,
      "name": "Rock_Sandstone"
    },
    {
      "x": -3,
      "y": 28,
      "z": 23,
      "name": "Rock_Sandstone"
    },
    {
      "x": -3,
      "y": 29,
      "z": 23,
      "name": "Rock_Sandstone"
    },
    {
      "x": -3,
      "y": 17,
      "z": 24,
      "name": "Rock_Sandstone"
    },
    {
      "x": -3,
      "y": 18,
      "z": 24,
      "name": "Soil_Sand_White"
    },
    {
      "x": -3,
      "y": 19,
      "z": 24,
      "name": "Empty"
    },
    {
      "x": -3,
      "y": 20,
      "z": 24,
      "name": "Empty"
    },
    {
      "x": -3,
      "y": 21,
      "z": 24,
      "name": "Empty"
    },
    {
      "x": -3,
      "y": 22,
      "z": 24,
      "name": "Empty"
    },
    {
      "x": -3,
      "y": 23,
      "z": 24,
      "name": "Rock_Sandstone_Brick_Ornate"
    },
    {
      "x": -3,
      "y": 24,
      "z": 24,
      "name": "Furniture_Tavern_Barrel"
    },
    {
      "x": -3,
      "y": 25,
      "z": 24,
      "name": "Empty"
    },
    {
      "x": -3,
      "y": 26,
      "z": 24,
      "name": "Empty"
    },
    {
      "x": -3,
      "y": 27,
      "z": 24,
      "name": "Empty"
    },
    {
      "x": -3,
      "y": 28,
      "z": 24,
      "name": "Rock_Sandstone"
    },
    {
      "x": -3,
      "y": 29,
      "z": 24,
      "name": "Rock_Sandstone"
    },
    {
      "x": -3,
      "y": 17,
      "z": 25,
      "name": "Rock_Sandstone"
    },
    {
      "x": -3,
      "y": 18,
      "z": 25,
      "name": "Soil_Sand_White"
    },
    {
      "x": -3,
      "y": 19,
      "z": 25,
      "name": "Empty"
    },
    {
      "x": -3,
      "y": 20,
      "z": 25,
      "name": "Empty"
    },
    {
      "x": -3,
      "y": 21,
      "z": 25,
      "name": "Empty"
    },
    {
      "x": -3,
      "y": 22,
      "z": 25,
      "name": "Empty"
    },
    {
      "x": -3,
      "y": 23,
      "z": 25,
      "name": "Rock_Sandstone_Brick_Ornate"
    },
    {
      "x": -3,
      "y": 24,
      "z": 25,
      "name": "Empty"
    },
    {
      "x": -3,
      "y": 25,
      "z": 25,
      "name": "Empty"
    },
    {
      "x": -3,
      "y": 26,
      "z": 25,
      "name": "Empty"
    },
    {
      "x": -3,
      "y": 27,
      "z": 25,
      "name": "Empty"
    },
    {
      "x": -3,
      "y": 28,
      "z": 25,
      "name": "Rock_Sandstone"
    },
    {
      "x": -3,
      "y": 29,
      "z": 25,
      "name": "Rock_Sandstone"
    },
    {
      "x": -3,
      "y": 17,
      "z": 26,
      "name": "Empty"
    },
    {
      "x": -3,
      "y": 18,
      "z": 26,
      "name": "Rock_Sandstone_Brick"
    },
    {
      "x": -3,
      "y": 19,
      "z": 26,
      "name": "Empty"
    },
    {
      "x": -3,
      "y": 20,
      "z": 26,
      "name": "Empty"
    },
    {
      "x": -3,
      "y": 21,
      "z": 26,
      "name": "Empty"
    },
    {
      "x": -3,
      "y": 22,
      "z": 26,
      "name": "Empty"
    },
    {
      "x": -3,
      "y": 23,
      "z": 26,
      "name": "Rock_Sandstone_Brick_Ornate"
    },
    {
      "x": -3,
      "y": 24,
      "z": 26,
      "name": "Empty"
    },
    {
      "x": -3,
      "y": 25,
      "z": 26,
      "name": "Empty"
    },
    {
      "x": -3,
      "y": 26,
      "z": 26,
      "name": "Empty"
    },
    {
      "x": -3,
      "y": 27,
      "z": 26,
      "name": "Empty"
    },
    {
      "x": -3,
      "y": 28,
      "z": 26,
      "name": "Rock_Sandstone"
    },
    {
      "x": -3,
      "y": 29,
      "z": 26,
      "name": "Rock_Sandstone"
    },
    {
      "x": -3,
      "y": 17,
      "z": 27,
      "name": "Empty"
    },
    {
      "x": -3,
      "y": 18,
      "z": 27,
      "name": "Rock_Sandstone_Brick"
    },
    {
      "x": -3,
      "y": 19,
      "z": 27,
      "name": "Empty"
    },
    {
      "x": -3,
      "y": 20,
      "z": 27,
      "name": "Empty"
    },
    {
      "x": -3,
      "y": 21,
      "z": 27,
      "name": "Empty"
    },
    {
      "x": -3,
      "y": 22,
      "z": 27,
      "name": "Empty"
    },
    {
      "x": -3,
      "y": 23,
      "z": 27,
      "name": "Rock_Sandstone_Brick_Ornate"
    },
    {
      "x": -3,
      "y": 24,
      "z": 27,
      "name": "Empty"
    },
    {
      "x": -3,
      "y": 25,
      "z": 27,
      "name": "Empty"
    },
    {
      "x": -3,
      "y": 26,
      "z": 27,
      "name": "Empty"
    },
    {
      "x": -3,
      "y": 27,
      "z": 27,
      "name": "Empty"
    },
    {
      "x": -3,
      "y": 28,
      "z": 27,
      "name": "Rock_Sandstone"
    },
    {
      "x": -3,
      "y": 29,
      "z": 27,
      "name": "Rock_Sandstone"
    },
    {
      "x": -3,
      "y": 17,
      "z": 28,
      "name": "Empty"
    },
    {
      "x": -3,
      "y": 18,
      "z": 28,
      "name": "Rock_Sandstone_Brick"
    },
    {
      "x": -3,
      "y": 19,
      "z": 28,
      "name": "Empty"
    },
    {
      "x": -3,
      "y": 20,
      "z": 28,
      "name": "Empty"
    },
    {
      "x": -3,
      "y": 21,
      "z": 28,
      "name": "Empty"
    },
    {
      "x": -3,
      "y": 22,
      "z": 28,
      "name": "Empty"
    },
    {
      "x": -3,
      "y": 23,
      "z": 28,
      "name": "Rock_Sandstone_Brick_Ornate"
    },
    {
      "x": -3,
      "y": 24,
      "z": 28,
      "name": "Empty"
    },
    {
      "x": -3,
      "y": 25,
      "z": 28,
      "name": "Empty"
    },
    {
      "x": -3,
      "y": 26,
      "z": 28,
      "name": "Empty"
    },
    {
      "x": -3,
      "y": 27,
      "z": 28,
      "name": "Empty"
    },
    {
      "x": -3,
      "y": 28,
      "z": 28,
      "name": "Rock_Sandstone"
    },
    {
      "x": -3,
      "y": 29,
      "z": 28,
      "name": "Rock_Sandstone"
    },
    {
      "x": -3,
      "y": 17,
      "z": 29,
      "name": "Empty"
    },
    {
      "x": -3,
      "y": 18,
      "z": 29,
      "name": "Rock_Sandstone_Brick"
    },
    {
      "x": -3,
      "y": 19,
      "z": 29,
      "name": "Rock_Sandstone_Brick_Half"
    },
    {
      "x": -3,
      "y": 20,
      "z": 29,
      "name": "Empty"
    },
    {
      "x": -3,
      "y": 21,
      "z": 29,
      "name": "Empty"
    },
    {
      "x": -3,
      "y": 22,
      "z": 29,
      "name": "Empty"
    },
    {
      "x": -3,
      "y": 23,
      "z": 29,
      "name": "Rock_Sandstone_Brick_Ornate"
    },
    {
      "x": -3,
      "y": 24,
      "z": 29,
      "name": "Empty"
    },
    {
      "x": -3,
      "y": 25,
      "z": 29,
      "name": "Empty"
    },
    {
      "x": -3,
      "y": 26,
      "z": 29,
      "name": "Empty"
    },
    {
      "x": -3,
      "y": 27,
      "z": 29,
      "name": "Rock_Sandstone"
    },
    {
      "x": -3,
      "y": 28,
      "z": 29,
      "name": "Rock_Sandstone"
    },
    {
      "x": -3,
      "y": 29,
      "z": 29,
      "name": "Rock_Sandstone"
    },
    {
      "x": -3,
      "y": 17,
      "z": 30,
      "name": "Empty"
    },
    {
      "x": -3,
      "y": 18,
      "z": 30,
      "name": "Rock_Sandstone_Brick"
    },
    {
      "x": -3,
      "y": 19,
      "z": 30,
      "name": "Wood_Drywood_Planks"
    },
    {
      "x": -3,
      "y": 20,
      "z": 30,
      "name": "Deco_Iron_Bars"
    },
    {
      "x": -3,
      "y": 21,
      "z": 30,
      "name": "Empty"
    },
    {
      "x": -3,
      "y": 22,
      "z": 30,
      "name": "Empty"
    },
    {
      "x": -3,
      "y": 23,
      "z": 30,
      "name": "Rock_Sandstone_Brick_Ornate"
    },
    {
      "x": -3,
      "y": 24,
      "z": 30,
      "name": "Empty"
    },
    {
      "x": -3,
      "y": 25,
      "z": 30,
      "name": "Empty"
    },
    {
      "x": -3,
      "y": 26,
      "z": 30,
      "name": "Empty"
    },
    {
      "x": -3,
      "y": 27,
      "z": 30,
      "name": "Rock_Sandstone"
    },
    {
      "x": -3,
      "y": 28,
      "z": 30,
      "name": "Rock_Sandstone"
    },
    {
      "x": -3,
      "y": 29,
      "z": 30,
      "name": "Rock_Sandstone"
    },
    {
      "x": -3,
      "y": 17,
      "z": 31,
      "name": "Rock_Sandstone"
    },
    {
      "x": -3,
      "y": 18,
      "z": 31,
      "name": "Soil_Sand_White"
    },
    {
      "x": -3,
      "y": 19,
      "z": 31,
      "name": "Wood_Drywood_Planks"
    },
    {
      "x": -3,
      "y": 20,
      "z": 31,
      "name": "Furniture_Tavern_Barrel"
    },
    {
      "x": -3,
      "y": 21,
      "z": 31,
      "name": "Empty"
    },
    {
      "x": -3,
      "y": 22,
      "z": 31,
      "name": "Empty"
    },
    {
      "x": -3,
      "y": 23,
      "z": 31,
      "name": "Rock_Sandstone_Brick_Ornate"
    },
    {
      "x": -3,
      "y": 24,
      "z": 31,
      "name": "Deco_Pot_Clay_Broken"
    },
    {
      "x": -3,
      "y": 25,
      "z": 31,
      "name": "Empty"
    },
    {
      "x": -3,
      "y": 26,
      "z": 31,
      "name": "Empty"
    },
    {
      "x": -3,
      "y": 27,
      "z": 31,
      "name": "Rock_Sandstone"
    },
    {
      "x": -3,
      "y": 28,
      "z": 31,
      "name": "Rock_Sandstone"
    },
    {
      "x": -3,
      "y": 29,
      "z": 31,
      "name": "Rock_Sandstone"
    },
    {
      "x": -3,
      "y": 17,
      "z": 32,
      "name": "Rock_Sandstone"
    },
    {
      "x": -3,
      "y": 18,
      "z": 32,
      "name": "Soil_Sand_White"
    },
    {
      "x": -3,
      "y": 19,
      "z": 32,
      "name": "Wood_Drywood_Planks"
    },
    {
      "x": -3,
      "y": 20,
      "z": 32,
      "name": "Furniture_Tavern_Barrel"
    },
    {
      "x": -3,
      "y": 21,
      "z": 32,
      "name": "Empty"
    },
    {
      "x": -3,
      "y": 22,
      "z": 32,
      "name": "Empty"
    },
    {
      "x": -3,
      "y": 23,
      "z": 32,
      "name": "Rock_Sandstone_Brick_Ornate"
    },
    {
      "x": -3,
      "y": 24,
      "z": 32,
      "name": "Furniture_Village_Pot"
    },
    {
      "x": -3,
      "y": 25,
      "z": 32,
      "name": "Empty"
    },
    {
      "x": -3,
      "y": 26,
      "z": 32,
      "name": "Empty"
    },
    {
      "x": -3,
      "y": 27,
      "z": 32,
      "name": "Rock_Sandstone"
    },
    {
      "x": -3,
      "y": 28,
      "z": 32,
      "name": "Rock_Sandstone"
    },
    {
      "x": -3,
      "y": 29,
      "z": 32,
      "name": "Rock_Sandstone"
    },
    {
      "x": -3,
      "y": 17,
      "z": 33,
      "name": "Rock_Sandstone"
    },
    {
      "x": -3,
      "y": 18,
      "z": 33,
      "name": "Soil_Sand_White"
    },
    {
      "x": -3,
      "y": 19,
      "z": 33,
      "name": "Wood_Drywood_Planks"
    },
    {
      "x": -3,
      "y": 20,
      "z": 33,
      "name": "Empty"
    },
    {
      "x": -3,
      "y": 21,
      "z": 33,
      "name": "Empty"
    },
    {
      "x": -3,
      "y": 22,
      "z": 33,
      "name": "Empty"
    },
    {
      "x": -3,
      "y": 23,
      "z": 33,
      "name": "Rock_Sandstone_Brick_Ornate"
    },
    {
      "x": -3,
      "y": 24,
      "z": 33,
      "name": "Empty"
    },
    {
      "x": -3,
      "y": 25,
      "z": 33,
      "name": "Empty"
    },
    {
      "x": -3,
      "y": 26,
      "z": 33,
      "name": "Empty"
    },
    {
      "x": -3,
      "y": 27,
      "z": 33,
      "name": "Rock_Sandstone"
    },
    {
      "x": -3,
      "y": 28,
      "z": 33,
      "name": "Rock_Sandstone"
    },
    {
      "x": -3,
      "y": 29,
      "z": 33,
      "name": "Rock_Sandstone"
    },
    {
      "x": -3,
      "y": 17,
      "z": 34,
      "name": "Rock_Sandstone"
    },
    {
      "x": -3,
      "y": 18,
      "z": 34,
      "name": "Soil_Sand_White"
    },
    {
      "x": -3,
      "y": 19,
      "z": 34,
      "name": "Wood_Drywood_Planks"
    },
    {
      "x": -3,
      "y": 20,
      "z": 34,
      "name": "Rock_Sandstone_Brick_Pillar_Base"
    },
    {
      "x": -3,
      "y": 21,
      "z": 34,
      "name": "Rock_Sandstone_Brick_Pillar_Middle"
    },
    {
      "x": -3,
      "y": 22,
      "z": 34,
      "name": "Rock_Sandstone_Brick_Pillar_Base",
      "rotation": 8
    },
    {
      "x": -3,
      "y": 23,
      "z": 34,
      "name": "Rock_Sandstone_Brick_Ornate"
    },
    {
      "x": -3,
      "y": 24,
      "z": 34,
      "name": "Furniture_Village_Bookcase",
      "rotation": 2
    },
    {
      "x": -3,
      "y": 25,
      "z": 34,
      "name": "Furniture_Village_Bookcase",
      "rotation": 2
    },
    {
      "x": -3,
      "y": 26,
      "z": 34,
      "name": "Furniture_Village_Bookcase",
      "rotation": 2
    },
    {
      "x": -3,
      "y": 27,
      "z": 34,
      "name": "Rock_Sandstone"
    },
    {
      "x": -3,
      "y": 28,
      "z": 34,
      "name": "Rock_Sandstone"
    },
    {
      "x": -3,
      "y": 18,
      "z": 35,
      "name": "Rock_Sandstone"
    },
    {
      "x": -3,
      "y": 19,
      "z": 35,
      "name": "Rock_Sandstone"
    },
    {
      "x": -3,
      "y": 20,
      "z": 35,
      "name": "Rock_Sandstone"
    },
    {
      "x": -3,
      "y": 21,
      "z": 35,
      "name": "Rock_Sandstone"
    },
    {
      "x": -3,
      "y": 22,
      "z": 35,
      "name": "Rock_Sandstone"
    },
    {
      "x": -3,
      "y": 23,
      "z": 35,
      "name": "Rock_Sandstone"
    },
    {
      "x": -3,
      "y": 24,
      "z": 35,
      "name": "Rock_Sandstone"
    },
    {
      "x": -3,
      "y": 25,
      "z": 35,
      "name": "Rock_Sandstone"
    },
    {
      "x": -3,
      "y": 26,
      "z": 35,
      "name": "Rock_Sandstone"
    },
    {
      "x": -3,
      "y": 27,
      "z": 35,
      "name": "Rock_Sandstone"
    },
    {
      "x": -3,
      "y": 28,
      "z": 35,
      "name": "Rock_Sandstone"
    },
    {
      "x": -2,
      "y": 17,
      "z": 21,
      "name": "Rock_Sandstone_Brick"
    },
    {
      "x": -2,
      "y": 18,
      "z": 21,
      "name": "Soil_Sand_White"
    },
    {
      "x": -2,
      "y": 19,
      "z": 21,
      "name": "Empty"
    },
    {
      "x": -2,
      "y": 20,
      "z": 21,
      "name": "Empty"
    },
    {
      "x": -2,
      "y": 21,
      "z": 21,
      "name": "Empty"
    },
    {
      "x": -2,
      "y": 22,
      "z": 21,
      "name": "Empty"
    },
    {
      "x": -2,
      "y": 23,
      "z": 21,
      "name": "Rock_Sandstone_Brick"
    },
    {
      "x": -2,
      "y": 24,
      "z": 21,
      "name": "Rock_Sandstone"
    },
    {
      "x": -2,
      "y": 25,
      "z": 21,
      "name": "Rock_Sandstone"
    },
    {
      "x": -2,
      "y": 26,
      "z": 21,
      "name": "Rock_Sandstone"
    },
    {
      "x": -2,
      "y": 27,
      "z": 21,
      "name": "Rock_Sandstone"
    },
    {
      "x": -2,
      "y": 28,
      "z": 21,
      "name": "Rock_Sandstone"
    },
    {
      "x": -2,
      "y": 17,
      "z": 22,
      "name": "Rock_Sandstone"
    },
    {
      "x": -2,
      "y": 18,
      "z": 22,
      "name": "Soil_Sand_White"
    },
    {
      "x": -2,
      "y": 19,
      "z": 22,
      "name": "Empty"
    },
    {
      "x": -2,
      "y": 20,
      "z": 22,
      "name": "Empty"
    },
    {
      "x": -2,
      "y": 21,
      "z": 22,
      "name": "Empty"
    },
    {
      "x": -2,
      "y": 22,
      "z": 22,
      "name": "Empty"
    },
    {
      "x": -2,
      "y": 23,
      "z": 22,
      "name": "Rock_Sandstone_Brick_Ornate"
    },
    {
      "x": -2,
      "y": 24,
      "z": 22,
      "name": "Furniture_Village_Crate"
    },
    {
      "x": -2,
      "y": 25,
      "z": 22,
      "name": "Furniture_Tavern_Barrel"
    },
    {
      "x": -2,
      "y": 26,
      "z": 22,
      "name": "Empty"
    },
    {
      "x": -2,
      "y": 27,
      "z": 22,
      "name": "Rock_Sandstone"
    },
    {
      "x": -2,
      "y": 28,
      "z": 22,
      "name": "Rock_Sandstone"
    },
    {
      "x": -2,
      "y": 17,
      "z": 23,
      "name": "Rock_Sandstone"
    },
    {
      "x": -2,
      "y": 18,
      "z": 23,
      "name": "Soil_Sand_White"
    },
    {
      "x": -2,
      "y": 19,
      "z": 23,
      "name": "Empty"
    },
    {
      "x": -2,
      "y": 20,
      "z": 23,
      "name": "Empty"
    },
    {
      "x": -2,
      "y": 21,
      "z": 23,
      "name": "Empty"
    },
    {
      "x": -2,
      "y": 22,
      "z": 23,
      "name": "Empty"
    },
    {
      "x": -2,
      "y": 23,
      "z": 23,
      "name": "Rock_Sandstone_Brick_Ornate"
    },
    {
      "x": -2,
      "y": 24,
      "z": 23,
      "name": "Furniture_Tavern_Barrel"
    },
    {
      "x": -2,
      "y": 25,
      "z": 23,
      "name": "Empty"
    },
    {
      "x": -2,
      "y": 26,
      "z": 23,
      "name": "Empty"
    },
    {
      "x": -2,
      "y": 27,
      "z": 23,
      "name": "Empty"
    },
    {
      "x": -2,
      "y": 28,
      "z": 23,
      "name": "Rock_Sandstone"
    },
    {
      "x": -2,
      "y": 29,
      "z": 23,
      "name": "Rock_Sandstone"
    },
    {
      "x": -2,
      "y": 17,
      "z": 24,
      "name": "Rock_Sandstone"
    },
    {
      "x": -2,
      "y": 18,
      "z": 24,
      "name": "Soil_Sand_White"
    },
    {
      "x": -2,
      "y": 19,
      "z": 24,
      "name": "Empty"
    },
    {
      "x": -2,
      "y": 20,
      "z": 24,
      "name": "Empty"
    },
    {
      "x": -2,
      "y": 21,
      "z": 24,
      "name": "Empty"
    },
    {
      "x": -2,
      "y": 22,
      "z": 24,
      "name": "Empty"
    },
    {
      "x": -2,
      "y": 23,
      "z": 24,
      "name": "Rock_Sandstone_Brick_Ornate"
    },
    {
      "x": -2,
      "y": 24,
      "z": 24,
      "name": "Empty"
    },
    {
      "x": -2,
      "y": 25,
      "z": 24,
      "name": "Empty"
    },
    {
      "x": -2,
      "y": 26,
      "z": 24,
      "name": "Empty"
    },
    {
      "x": -2,
      "y": 27,
      "z": 24,
      "name": "Empty"
    },
    {
      "x": -2,
      "y": 28,
      "z": 24,
      "name": "Rock_Sandstone"
    },
    {
      "x": -2,
      "y": 29,
      "z": 24,
      "name": "Rock_Sandstone"
    },
    {
      "x": -2,
      "y": 17,
      "z": 25,
      "name": "Rock_Sandstone"
    },
    {
      "x": -2,
      "y": 18,
      "z": 25,
      "name": "Soil_Sand_White"
    },
    {
      "x": -2,
      "y": 19,
      "z": 25,
      "name": "Empty"
    },
    {
      "x": -2,
      "y": 20,
      "z": 25,
      "name": "Empty"
    },
    {
      "x": -2,
      "y": 21,
      "z": 25,
      "name": "Empty"
    },
    {
      "x": -2,
      "y": 22,
      "z": 25,
      "name": "Empty"
    },
    {
      "x": -2,
      "y": 23,
      "z": 25,
      "name": "Rock_Sandstone_Brick_Ornate"
    },
    {
      "x": -2,
      "y": 24,
      "z": 25,
      "name": "Empty"
    },
    {
      "x": -2,
      "y": 25,
      "z": 25,
      "name": "Empty"
    },
    {
      "x": -2,
      "y": 26,
      "z": 25,
      "name": "Empty"
    },
    {
      "x": -2,
      "y": 27,
      "z": 25,
      "name": "Empty"
    },
    {
      "x": -2,
      "y": 28,
      "z": 25,
      "name": "Rock_Sandstone"
    },
    {
      "x": -2,
      "y": 29,
      "z": 25,
      "name": "Rock_Sandstone"
    },
    {
      "x": -2,
      "y": 17,
      "z": 26,
      "name": "Empty"
    },
    {
      "x": -2,
      "y": 18,
      "z": 26,
      "name": "Rock_Sandstone_Brick"
    },
    {
      "x": -2,
      "y": 19,
      "z": 26,
