{
  "version": 8,
  "blockIdVersion": 8,
  "anchorX": -4,
  "anchorY": 12,
  "anchorZ": -2,
  "blocks": [
    {
      "x": -14,
      "y": 13,
      "z": -19,
      "name": "Rock_Sandstone"
    },
    {
      "x": -14,
      "y": 14,
      "z": -19,
      "name": "Soil_Clay"
    },
    {
      "x": -14,
      "y": 15,
      "z": -19,
      "name": "Soil_Clay"
    },
    {
      "x": -14,
      "y": 16,
      "z": -19,
      "name": "Soil_Clay"
    },
    {
      "x": -14,
      "y": 17,
      "z": -19,
      "name": "Rock_Sandstone_Red"
    },
    {
      "x": -14,
      "y": 18,
      "z": -19,
      "name": "Rock_Sandstone_Red"
    },
    {
      "x": -14,
      "y": 19,
      "z": -19,
      "name": "Rock_Sandstone"
    },
    {
      "x": -14,
      "y": 20,
      "z": -19,
      "name": "Rock_Sandstone"
    },
    {
      "x": -14,
      "y": 21,
      "z": -19,
      "name": "Soil_Clay"
    },
    {
      "x": -14,
      "y": 12,
      "z": -18,
      "name": "Rock_Sandstone"
    },
    {
      "x": -14,
      "y": 13,
      "z": -18,
      "name": "Rock_Sandstone"
    },
    {
      "x": -14,
      "y": 14,
      "z": -18,
      "name": "Soil_Clay"
    },
    {
      "x": -14,
      "y": 15,
      "z": -18,
      "name": "Soil_Clay"
    },
    {
      "x": -14,
      "y": 16,
      "z": -18,
      "name": "Soil_Clay"
    },
    {
      "x": -14,
      "y": 17,
      "z": -18,
      "name": "Rock_Sandstone_Red"
    },
    {
      "x": -14,
      "y": 18,
      "z": -18,
      "name": "Rock_Sandstone_Red"
    },
    {
      "x": -14,
      "y": 19,
      "z": -18,
      "name": "Rock_Sandstone"
    },
    {
      "x": -14,
      "y": 20,
      "z": -18,
      "name": "Rock_Sandstone"
    },
    {
      "x": -14,
      "y": 21,
      "z": -18,
      "name": "Soil_Clay"
    },
    {
      "x": -14,
      "y": 13,
      "z": -17,
      "name": "Rock_Sandstone"
    },
    {
      "x": -14,
      "y": 14,
      "z": -17,
      "name": "Soil_Clay"
    },
    {
      "x": -14,
      "y": 15,
      "z": -17,
      "name": "Soil_Clay"
    },
    {
      "x": -14,
      "y": 16,
      "z": -17,
      "name": "Soil_Clay"
    },
    {
      "x": -14,
      "y": 17,
      "z": -17,
      "name": "Rock_Sandstone_Red"
    },
    {
      "x": -14,
      "y": 18,
      "z": -17,
      "name": "Rock_Sandstone_Red"
    },
    {
      "x": -14,
      "y": 19,
      "z": -17,
      "name": "Rock_Sandstone"
    },
    {
      "x": -14,
      "y": 20,
      "z": -17,
      "name": "Rock_Sandstone"
    },
    {
      "x": -13,
      "y": 13,
      "z": -21,
      "name": "Rock_Sandstone"
    },
    {
      "x": -13,
      "y": 14,
      "z": -21,
      "name": "Soil_Clay"
    },
    {
      "x": -13,
      "y": 15,
      "z": -21,
      "name": "Soil_Clay"
    },
    {
      "x": -13,
      "y": 16,
      "z": -21,
      "name": "Soil_Clay"
    },
    {
      "x": -13,
      "y": 17,
      "z": -21,
      "name": "Rock_Sandstone_Red"
    },
    {
      "x": -13,
      "y": 10,
      "z": -20,
      "name": "Rock_Sandstone"
    },
    {
      "x": -13,
      "y": 11,
      "z": -20,
      "name": "Rock_Sandstone"
    },
    {
      "x": -13,
      "y": 12,
      "z": -20,
      "name": "Rock_Sandstone"
    },
    {
      "x": -13,
      "y": 13,
      "z": -20,
      "name": "Rock_Sandstone"
    },
    {
      "x": -13,
      "y": 14,
      "z": -20,
      "name": "Soil_Clay"
    },
    {
      "x": -13,
      "y": 15,
      "z": -20,
      "name": "Soil_Clay"
    },
    {
      "x": -13,
      "y": 16,
      "z": -20,
      "name": "Soil_Clay"
    },
    {
      "x": -13,
      "y": 17,
      "z": -20,
      "name": "Rock_Sandstone_Red"
    },
    {
      "x": -13,
      "y": 18,
      "z": -20,
      "name": "Rock_Sandstone_Red"
    },
    {
      "x": -13,
      "y": 19,
      "z": -20,
      "name": "Rock_Sandstone"
    },
    {
      "x": -13,
      "y": 20,
      "z": -20,
      "name": "Rock_Sandstone"
    },
    {
      "x": -13,
      "y": 21,
      "z": -20,
      "name": "Soil_Clay"
    },
    {
      "x": -13,
      "y": 22,
      "z": -20,
      "name": "Soil_Dirt_Dry"
    },
    {
      "x": -13,
      "y": 23,
      "z": -20,
      "name": "Soil_Dirt_Dry"
    },
    {
      "x": -13,
      "y": 24,
      "z": -20,
      "name": "Soil_Dirt_Dry"
    },
    {
      "x": -13,
      "y": 10,
      "z": -19,
      "name": "Rock_Sandstone"
    },
    {
      "x": -13,
      "y": 11,
      "z": -19,
      "name": "Rock_Sandstone"
    },
    {
      "x": -13,
      "y": 12,
      "z": -19,
      "name": "Rock_Sandstone"
    },
    {
      "x": -13,
      "y": 13,
      "z": -19,
      "name": "Rock_Sandstone"
    },
    {
      "x": -13,
      "y": 14,
      "z": -19,
      "name": "Soil_Clay"
    },
    {
      "x": -13,
      "y": 15,
      "z": -19,
      "name": "Soil_Clay"
    },
    {
      "x": -13,
      "y": 16,
      "z": -19,
      "name": "Soil_Clay"
    },
    {
      "x": -13,
      "y": 17,
      "z": -19,
      "name": "Rock_Sandstone_Red"
    },
    {
      "x": -13,
      "y": 18,
      "z": -19,
      "name": "Rock_Sandstone_Red"
    },
    {
      "x": -13,
      "y": 19,
      "z": -19,
      "name": "Rock_Sandstone"
    },
    {
      "x": -13,
      "y": 20,
      "z": -19,
      "name": "Rock_Sandstone"
    },
    {
      "x": -13,
      "y": 21,
      "z": -19,
      "name": "Soil_Clay"
    },
    {
      "x": -13,
      "y": 22,
      "z": -19,
      "name": "Soil_Dirt_Dry"
    },
    {
      "x": -13,
      "y": 23,
      "z": -19,
      "name": "Soil_Dirt_Dry"
    },
    {
      "x": -13,
      "y": 24,
      "z": -19,
      "name": "Soil_Dirt_Dry"
    },
    {
      "x": -13,
      "y": 25,
      "z": -19,
      "name": "Soil_Dirt_Dry"
    },
    {
      "x": -13,
      "y": 26,
      "z": -19,
      "name": "Rock_Sandstone"
    },
    {
      "x": -13,
      "y": 10,
      "z": -18,
      "name": "Rock_Sandstone"
    },
    {
      "x": -13,
      "y": 11,
      "z": -18,
      "name": "Rock_Sandstone"
    },
    {
      "x": -13,
      "y": 12,
      "z": -18,
      "name": "Rock_Sandstone"
    },
    {
      "x": -13,
      "y": 13,
      "z": -18,
      "name": "Rock_Sandstone"
    },
    {
      "x": -13,
      "y": 14,
      "z": -18,
      "name": "Soil_Clay"
    },
    {
      "x": -13,
      "y": 15,
      "z": -18,
      "name": "Soil_Clay"
    },
    {
      "x": -13,
      "y": 16,
      "z": -18,
      "name": "Soil_Clay"
    },
    {
      "x": -13,
      "y": 17,
      "z": -18,
      "name": "Rock_Sandstone_Red"
    },
    {
      "x": -13,
      "y": 18,
      "z": -18,
      "name": "Rock_Sandstone_Red"
    },
    {
      "x": -13,
      "y": 19,
      "z": -18,
      "name": "Rock_Sandstone"
    },
    {
      "x": -13,
      "y": 20,
      "z": -18,
      "name": "Rock_Sandstone"
    },
    {
      "x": -13,
      "y": 21,
      "z": -18,
      "name": "Soil_Clay"
    },
    {
      "x": -13,
      "y": 22,
      "z": -18,
      "name": "Soil_Dirt_Dry"
    },
    {
      "x": -13,
      "y": 23,
      "z": -18,
      "name": "Soil_Dirt_Dry"
    },
    {
      "x": -13,
      "y": 24,
      "z": -18,
      "name": "Soil_Dirt_Dry"
    },
    {
      "x": -13,
      "y": 25,
      "z": -18,
      "name": "Soil_Dirt_Dry"
    },
    {
      "x": -13,
      "y": 26,
      "z": -18,
      "name": "Rock_Sandstone"
    },
    {
      "x": -13,
      "y": 27,
      "z": -18,
      "name": "Rock_Sandstone"
    },
    {
      "x": -13,
      "y": 28,
      "z": -18,
      "name": "Soil_Clay"
    },
    {
      "x": -13,
      "y": 29,
      "z": -18,
      "name": "Soil_Clay"
    },
    {
      "x": -13,
      "y": 10,
      "z": -17,
      "name": "Rock_Sandstone"
    },
    {
      "x": -13,
      "y": 11,
      "z": -17,
      "name": "Rock_Sandstone"
    },
    {
      "x": -13,
      "y": 12,
      "z": -17,
      "name": "Rock_Sandstone"
    },
    {
      "x": -13,
      "y": 13,
      "z": -17,
      "name": "Rock_Sandstone"
    },
    {
      "x": -13,
      "y": 14,
      "z": -17,
      "name": "Soil_Clay"
    },
    {
      "x": -13,
      "y": 15,
      "z": -17,
      "name": "Soil_Clay"
    },
    {
      "x": -13,
      "y": 16,
      "z": -17,
      "name": "Soil_Clay"
    },
    {
      "x": -13,
      "y": 17,
      "z": -17,
      "name": "Rock_Sandstone_Red"
    },
    {
      "x": -13,
      "y": 18,
      "z": -17,
      "name": "Rock_Sandstone_Red"
    },
    {
      "x": -13,
      "y": 19,
      "z": -17,
      "name": "Rock_Sandstone"
    },
    {
      "x": -13,
      "y": 20,
      "z": -17,
      "name": "Rock_Sandstone"
    },
    {
      "x": -13,
      "y": 21,
      "z": -17,
      "name": "Soil_Clay"
    },
    {
      "x": -13,
      "y": 22,
      "z": -17,
      "name": "Soil_Clay"
    },
    {
      "x": -13,
      "y": 23,
      "z": -17,
      "name": "Soil_Dirt_Dry"
    },
    {
      "x": -13,
      "y": 24,
      "z": -17,
      "name": "Soil_Dirt_Dry"
    },
    {
      "x": -13,
      "y": 25,
      "z": -17,
      "name": "Soil_Dirt_Dry"
    },
    {
      "x": -13,
      "y": 26,
      "z": -17,
      "name": "Rock_Sandstone"
    },
    {
      "x": -13,
      "y": 27,
      "z": -17,
      "name": "Rock_Sandstone"
    },
    {
      "x": -13,
      "y": 28,
      "z": -17,
      "name": "Soil_Clay"
    },
    {
      "x": -13,
      "y": 29,
      "z": -17,
      "name": "Soil_Clay"
    },
    {
      "x": -13,
      "y": 11,
      "z": -16,
      "name": "Rock_Sandstone"
    },
    {
      "x": -13,
      "y": 12,
      "z": -16,
      "name": "Rock_Sandstone"
    },
    {
      "x": -13,
      "y": 13,
      "z": -16,
      "name": "Rock_Sandstone"
    },
    {
      "x": -13,
      "y": 14,
      "z": -16,
      "name": "Soil_Clay"
    },
    {
      "x": -13,
      "y": 15,
      "z": -16,
      "name": "Soil_Clay"
    },
    {
      "x": -13,
      "y": 16,
      "z": -16,
      "name": "Soil_Clay"
    },
    {
      "x": -13,
      "y": 17,
      "z": -16,
      "name": "Rock_Sandstone_Red"
    },
    {
      "x": -13,
      "y": 18,
      "z": -16,
      "name": "Rock_Sandstone_Red"
    },
    {
      "x": -13,
      "y": 19,
      "z": -16,
      "name": "Rock_Sandstone"
    },
    {
      "x": -13,
      "y": 20,
      "z": -16,
      "name": "Rock_Sandstone"
    },
    {
      "x": -13,
      "y": 21,
      "z": -16,
      "name": "Soil_Clay"
    },
    {
      "x": -13,
      "y": 22,
      "z": -16,
      "name": "Soil_Clay"
    },
    {
      "x": -13,
      "y": 23,
      "z": -16,
      "name": "Soil_Dirt_Dry"
    },
    {
      "x": -13,
      "y": 13,
      "z": -15,
      "name": "Rock_Sandstone"
    },
    {
      "x": -13,
      "y": 14,
      "z": -15,
      "name": "Soil_Clay"
    },
    {
      "x": -13,
      "y": 15,
      "z": -15,
      "name": "Soil_Clay"
    },
    {
      "x": -13,
      "y": 16,
      "z": -15,
      "name": "Soil_Clay"
    },
    {
      "x": -13,
      "y": 17,
      "z": -15,
      "name": "Rock_Sandstone_Red"
    },
    {
      "x": -13,
      "y": 18,
      "z": -15,
      "name": "Rock_Sandstone_Red"
    },
    {
      "x": -13,
      "y": 19,
      "z": -15,
      "name": "Rock_Sandstone"
    },
    {
      "x": -13,
      "y": 14,
      "z": 10,
      "name": "Rock_Sandstone"
    },
    {
      "x": -13,
      "y": 15,
      "z": 10,
      "name": "Rock_Sandstone"
    },
    {
      "x": -13,
      "y": 16,
      "z": 10,
      "name": "Soil_Clay"
    },
    {
      "x": -13,
      "y": 17,
      "z": 10,
      "name": "Rock_Sandstone_Red"
    },
    {
      "x": -13,
      "y": 18,
      "z": 10,
      "name": "Rock_Sandstone_Red"
    },
    {
      "x": -13,
      "y": 19,
      "z": 10,
      "name": "Rock_Sandstone_Red"
    },
    {
      "x": -13,
      "y": 20,
      "z": 10,
      "name": "Rock_Sandstone_Red"
    },
    {
      "x": -13,
      "y": 11,
      "z": 11,
      "name": "Rock_Sandstone"
    },
    {
      "x": -13,
      "y": 12,
      "z": 11,
      "name": "Rock_Sandstone"
    },
    {
      "x": -13,
      "y": 13,
      "z": 11,
      "name": "Rock_Sandstone"
    },
    {
      "x": -13,
      "y": 14,
      "z": 11,
      "name": "Rock_Sandstone"
    },
    {
      "x": -13,
      "y": 15,
      "z": 11,
      "name": "Rock_Sandstone"
    },
    {
      "x": -13,
      "y": 16,
      "z": 11,
      "name": "Soil_Clay"
    },
    {
      "x": -13,
      "y": 17,
      "z": 11,
      "name": "Rock_Sandstone_Red"
    },
    {
      "x": -13,
      "y": 18,
      "z": 11,
      "name": "Rock_Sandstone_Red"
    },
    {
      "x": -13,
      "y": 19,
      "z": 11,
      "name": "Rock_Sandstone_Red"
    },
    {
      "x": -13,
      "y": 20,
      "z": 11,
      "name": "Rock_Sandstone_Red"
    },
    {
      "x": -13,
      "y": 21,
      "z": 11,
      "name": "Rock_Sandstone"
    },
    {
      "x": -13,
      "y": 11,
      "z": 12,
      "name": "Rock_Sandstone"
    },
    {
      "x": -13,
      "y": 12,
      "z": 12,
      "name": "Rock_Sandstone"
    },
    {
      "x": -13,
      "y": 13,
      "z": 12,
      "name": "Rock_Sandstone"
    },
    {
      "x": -13,
      "y": 14,
      "z": 12,
      "name": "Rock_Sandstone"
    },
    {
      "x": -13,
      "y": 15,
      "z": 12,
      "name": "Rock_Sandstone"
    },
    {
      "x": -13,
      "y": 16,
      "z": 12,
      "name": "Rock_Sandstone"
    },
    {
      "x": -13,
      "y": 17,
      "z": 12,
      "name": "Rock_Sandstone_Red"
    },
    {
      "x": -13,
      "y": 18,
      "z": 12,
      "name": "Rock_Sandstone_Red"
    },
    {
      "x": -13,
      "y": 19,
      "z": 12,
      "name": "Rock_Sandstone_Red"
    },
    {
      "x": -13,
      "y": 20,
      "z": 12,
      "name": "Rock_Sandstone_Red"
    },
    {
      "x": -13,
      "y": 21,
      "z": 12,
      "name": "Rock_Sandstone"
    },
    {
      "x": -13,
      "y": 14,
      "z": 13,
      "name": "Rock_Sandstone"
    },
    {
      "x": -13,
      "y": 15,
      "z": 13,
      "name": "Rock_Sandstone"
    },
    {
      "x": -13,
      "y": 16,
      "z": 13,
      "name": "Rock_Sandstone"
    },
    {
      "x": -12,
      "y": 10,
      "z": -22,
      "name": "Rock_Sandstone"
    },
    {
      "x": -12,
      "y": 11,
      "z": -22,
      "name": "Rock_Sandstone"
    },
    {
      "x": -12,
      "y": 12,
      "z": -22,
      "name": "Rock_Sandstone"
    },
    {
      "x": -12,
      "y": 13,
      "z": -22,
      "name": "Rock_Sandstone"
    },
    {
      "x": -12,
      "y": 14,
      "z": -22,
      "name": "Soil_Clay"
    },
    {
      "x": -12,
      "y": 15,
      "z": -22,
      "name": "Soil_Clay"
    },
    {
      "x": -12,
      "y": 16,
      "z": -22,
      "name": "Soil_Clay"
    },
    {
      "x": -12,
      "y": 17,
      "z": -22,
      "name": "Rock_Sandstone_Red"
    },
    {
      "x": -12,
      "y": 18,
      "z": -22,
      "name": "Rock_Sandstone_Red"
    },
    {
      "x": -12,
      "y": 19,
      "z": -22,
      "name": "Rock_Sandstone"
    },
    {
      "x": -12,
      "y": 20,
      "z": -22,
      "name": "Soil_Clay"
    },
    {
      "x": -12,
      "y": 21,
      "z": -22,
      "name": "Soil_Clay"
    },
    {
      "x": -12,
      "y": 6,
      "z": -21,
      "name": "Rock_Sandstone"
    },
    {
      "x": -12,
      "y": 7,
      "z": -21,
      "name": "Rock_Sandstone"
    },
    {
      "x": -12,
      "y": 8,
      "z": -21,
      "name": "Rock_Sandstone"
    },
    {
      "x": -12,
      "y": 9,
      "z": -21,
      "name": "Rock_Sandstone"
    },
    {
      "x": -12,
      "y": 10,
      "z": -21,
      "name": "Rock_Sandstone"
    },
    {
      "x": -12,
      "y": 11,
      "z": -21,
      "name": "Rock_Sandstone"
    },
    {
      "x": -12,
      "y": 12,
      "z": -21,
      "name": "Rock_Sandstone"
    },
    {
      "x": -12,
      "y": 13,
      "z": -21,
      "name": "Rock_Sandstone"
    },
    {
      "x": -12,
      "y": 14,
      "z": -21,
      "name": "Soil_Clay"
    },
    {
      "x": -12,
      "y": 15,
      "z": -21,
      "name": "Soil_Clay"
    },
    {
      "x": -12,
      "y": 16,
      "z": -21,
      "name": "Soil_Clay"
    },
    {
      "x": -12,
      "y": 17,
      "z": -21,
      "name": "Rock_Sandstone_Red"
    },
    {
      "x": -12,
      "y": 18,
      "z": -21,
      "name": "Rock_Sandstone_Red"
    },
    {
      "x": -12,
      "y": 19,
      "z": -21,
      "name": "Rock_Sandstone"
    },
    {
      "x": -12,
      "y": 20,
      "z": -21,
      "name": "Soil_Clay"
    },
    {
      "x": -12,
      "y": 21,
      "z": -21,
      "name": "Soil_Clay"
    },
    {
      "x": -12,
      "y": 22,
      "z": -21,
      "name": "Soil_Dirt_Dry"
    },
    {
      "x": -12,
      "y": 23,
      "z": -21,
      "name": "Soil_Dirt_Dry"
    },
    {
      "x": -12,
      "y": 24,
      "z": -21,
      "name": "Soil_Dirt_Dry"
    },
    {
      "x": -12,
      "y": 25,
      "z": -21,
      "name": "Soil_Dirt_Dry"
    },
    {
      "x": -12,
      "y": 26,
      "z": -21,
      "name": "Rock_Sandstone"
    },
    {
      "x": -12,
      "y": 27,
      "z": -21,
      "name": "Soil_Clay"
    },
    {
      "x": -12,
      "y": 28,
      "z": -21,
      "name": "Soil_Clay"
    },
    {
      "x": -12,
      "y": 29,
      "z": -21,
      "name": "Rock_Sandstone_Red"
    },
    {
      "x": -12,
      "y": 6,
      "z": -20,
      "name": "Rock_Sandstone"
    },
    {
      "x": -12,
      "y": 7,
      "z": -20,
      "name": "Rock_Sandstone"
    },
    {
      "x": -12,
      "y": 8,
      "z": -20,
      "name": "Rock_Sandstone"
    },
    {
      "x": -12,
      "y": 9,
      "z": -20,
      "name": "Rock_Sandstone"
    },
    {
      "x": -12,
      "y": 10,
      "z": -20,
      "name": "Rock_Sandstone"
    },
    {
      "x": -12,
      "y": 11,
      "z": -20,
      "name": "Rock_Sandstone"
    },
    {
      "x": -12,
      "y": 12,
      "z": -20,
      "name": "Rock_Sandstone"
    },
    {
      "x": -12,
      "y": 13,
      "z": -20,
      "name": "Rock_Sandstone"
    },
    {
      "x": -12,
      "y": 14,
      "z": -20,
      "name": "Soil_Clay"
    },
    {
      "x": -12,
      "y": 15,
      "z": -20,
      "name": "Soil_Clay"
    },
    {
      "x": -12,
      "y": 16,
      "z": -20,
      "name": "Soil_Clay"
    },
    {
      "x": -12,
      "y": 17,
      "z": -20,
      "name": "Rock_Sandstone_Red"
    },
    {
      "x": -12,
      "y": 18,
      "z": -20,
      "name": "Rock_Sandstone_Red"
    },
    {
      "x": -12,
      "y": 19,
      "z": -20,
      "name": "Rock_Sandstone"
    },
    {
      "x": -12,
      "y": 20,
      "z": -20,
      "name": "Soil_Clay"
    },
    {
      "x": -12,
      "y": 21,
      "z": -20,
      "name": "Soil_Clay"
    },
    {
      "x": -12,
      "y": 22,
      "z": -20,
      "name": "Soil_Dirt_Dry"
    },
    {
      "x": -12,
      "y": 23,
      "z": -20,
      "name": "Soil_Dirt_Dry"
    },
    {
      "x": -12,
      "y": 24,
      "z": -20,
      "name": "Soil_Dirt_Dry"
    },
    {
      "x": -12,
      "y": 25,
      "z": -20,
      "name": "Soil_Dirt_Dry"
    },
    {
      "x": -12,
      "y": 26,
      "z": -20,
      "name": "Rock_Sandstone"
    },
    {
      "x": -12,
      "y": 27,
      "z": -20,
      "name": "Rock_Sandstone"
    },
    {
      "x": -12,
      "y": 28,
      "z": -20,
      "name": "Soil_Clay"
    },
    {
      "x": -12,
      "y": 29,
      "z": -20,
      "name": "Rock_Sandstone_Red"
    },
    {
      "x": -12,
      "y": 30,
      "z": -20,
      "name": "Rock_Sandstone_Red"
    },
    {
      "x": -12,
      "y": 31,
      "z": -20,
      "name": "Rock_Sandstone_Red"
    },
    {
      "x": -12,
      "y": 32,
      "z": -20,
      "name": "Rock_Sandstone_Red"
    },
    {
      "x": -12,
      "y": 33,
      "z": -20,
      "name": "Rock_Sandstone"
    },
    {
      "x": -12,
      "y": 6,
      "z": -19,
      "name": "Rock_Sandstone"
    },
    {
      "x": -12,
      "y": 7,
      "z": -19,
      "name": "Rock_Sandstone"
    },
    {
      "x": -12,
      "y": 8,
      "z": -19,
      "name": "Rock_Sandstone"
    },
    {
      "x": -12,
      "y": 9,
      "z": -19,
      "name": "Rock_Sandstone"
    },
    {
      "x": -12,
      "y": 10,
      "z": -19,
      "name": "Rock_Sandstone"
    },
    {
      "x": -12,
      "y": 11,
      "z": -19,
      "name": "Rock_Sandstone"
    },
    {
      "x": -12,
      "y": 12,
      "z": -19,
      "name": "Rock_Sandstone"
    },
    {
      "x": -12,
      "y": 13,
      "z": -19,
      "name": "Rock_Sandstone"
    },
    {
      "x": -12,
      "y": 14,
      "z": -19,
      "name": "Soil_Clay"
    },
    {
      "x": -12,
      "y": 15,
      "z": -19,
      "name": "Soil_Clay"
    },
    {
      "x": -12,
      "y": 16,
      "z": -19,
      "name": "Soil_Clay"
    },
    {
      "x": -12,
      "y": 17,
      "z": -19,
      "name": "Rock_Sandstone_Red"
    },
    {
      "x": -12,
      "y": 18,
      "z": -19,
      "name": "Rock_Sandstone_Red"
    },
    {
      "x": -12,
      "y": 19,
      "z": -19,
      "name": "Rock_Sandstone"
    },
    {
      "x": -12,
      "y": 20,
      "z": -19,
      "name": "Soil_Clay"
    },
    {
      "x": -12,
      "y": 21,
      "z": -19,
      "name": "Soil_Clay"
    },
    {
      "x": -12,
      "y": 22,
      "z": -19,
      "name": "Soil_Dirt_Dry"
    },
    {
      "x": -12,
      "y": 23,
      "z": -19,
      "name": "Soil_Dirt_Dry"
    },
    {
      "x": -12,
      "y": 24,
      "z": -19,
      "name": "Soil_Dirt_Dry"
    },
    {
      "x": -12,
      "y": 25,
      "z": -19,
      "name": "Soil_Dirt_Dry"
    },
    {
      "x": -12,
      "y": 26,
      "z": -19,
      "name": "Rock_Sandstone"
    },
    {
      "x": -12,
      "y": 27,
      "z": -19,
      "name": "Rock_Sandstone"
    },
    {
      "x": -12,
      "y": 28,
      "z": -19,
      "name": "Soil_Clay"
    },
    {
      "x": -12,
      "y": 29,
      "z": -19,
      "name": "Soil_Clay"
    },
    {
      "x": -12,
      "y": 30,
      "z": -19,
      "name": "Rock_Sandstone_Red"
    },
    {
      "x": -12,
      "y": 31,
      "z": -19,
      "name": "Rock_Sandstone_Red"
    },
    {
      "x": -12,
      "y": 32,
      "z": -19,
      "name": "Rock_Sandstone_Red"
    },
    {
      "x": -12,
      "y": 33,
      "z": -19,
      "name": "Rock_Sandstone"
    },
    {
      "x": -12,
      "y": 34,
      "z": -19,
      "name": "Rock_Sandstone_White"
    },
    {
      "x": -12,
      "y": 35,
      "z": -19,
      "name": "Rock_Sandstone_White"
    },
    {
      "x": -12,
      "y": 36,
      "z": -19,
      "name": "Soil_Sand_Red"
    },
    {
      "x": -12,
      "y": 37,
      "z": -19,
      "name": "Soil_Sand_Red"
    },
    {
      "x": -12,
      "y": 6,
      "z": -18,
      "name": "Rock_Sandstone"
    },
    {
      "x": -12,
      "y": 7,
      "z": -18,
      "name": "Rock_Sandstone"
    },
    {
      "x": -12,
      "y": 8,
      "z": -18,
      "name": "Rock_Sandstone"
    },
    {
      "x": -12,
      "y": 9,
      "z": -18,
      "name": "Rock_Sandstone"
    },
    {
      "x": -12,
      "y": 10,
      "z": -18,
      "name": "Rock_Sandstone"
    },
    {
      "x": -12,
      "y": 11,
      "z": -18,
      "name": "Rock_Sandstone"
    },
    {
      "x": -12,
      "y": 12,
      "z": -18,
      "name": "Rock_Sandstone"
    },
    {
      "x": -12,
      "y": 13,
      "z": -18,
      "name": "Rock_Sandstone"
    },
    {
      "x": -12,
      "y": 14,
      "z": -18,
      "name": "Soil_Clay"
    },
    {
      "x": -12,
      "y": 15,
      "z": -18,
      "name": "Soil_Clay"
    },
    {
      "x": -12,
      "y": 16,
      "z": -18,
      "name": "Soil_Clay"
    },
    {
      "x": -12,
      "y": 17,
      "z": -18,
      "name": "Rock_Sandstone_Red"
    },
    {
      "x": -12,
      "y": 18,
      "z": -18,
      "name": "Rock_Sandstone_Red"
    },
    {
      "x": -12,
      "y": 19,
      "z": -18,
      "name": "Rock_Sandstone"
    },
    {
      "x": -12,
      "y": 20,
      "z": -18,
      "name": "Rock_Sandstone"
    },
    {
      "x": -12,
      "y": 21,
      "z": -18,
      "name": "Soil_Clay"
    },
    {
      "x": -12,
      "y": 22,
      "z": -18,
      "name": "Soil_Dirt_Dry"
    },
    {
      "x": -12,
      "y": 23,
      "z": -18,
      "name": "Soil_Dirt_Dry"
    },
    {
      "x": -12,
      "y": 24,
      "z": -18,
      "name": "Soil_Dirt_Dry"
    },
    {
      "x": -12,
      "y": 25,
      "z": -18,
      "name": "Soil_Dirt_Dry"
    },
    {
      "x": -12,
      "y": 26,
      "z": -18,
      "name": "Rock_Sandstone"
    },
    {
      "x": -12,
      "y": 27,
      "z": -18,
      "name": "Rock_Sandstone"
    },
    {
      "x": -12,
      "y": 28,
      "z": -18,
      "name": "Soil_Clay"
    },
    {
      "x": -12,
      "y": 29,
      "z": -18,
      "name": "Soil_Clay"
    },
    {
      "x": -12,
      "y": 30,
      "z": -18,
      "name": "Rock_Sandstone_Red"
    },
    {
      "x": -12,
      "y": 31,
      "z": -18,
      "name": "Rock_Sandstone_Red"
    },
    {
      "x": -12,
      "y": 32,
      "z": -18,
      "name": "Rock_Sandstone_Red"
    },
    {
      "x": -12,
      "y": 33,
      "z": -18,
      "name": "Rock_Sandstone"
    },
    {
      "x": -12,
      "y": 34,
      "z": -18,
      "name": "Rock_Sandstone_White"
    },
    {
      "x": -12,
      "y": 35,
      "z": -18,
      "name": "Rock_Sandstone_White"
    },
    {
      "x": -12,
      "y": 36,
      "z": -18,
      "name": "Soil_Sand_Red"
    },
    {
      "x": -12,
      "y": 37,
      "z": -18,
      "name": "Soil_Sand_Red"
    },
    {
      "x": -12,
      "y": 6,
      "z": -17,
      "name": "Rock_Sandstone"
    },
    {
      "x": -12,
      "y": 7,
      "z": -17,
      "name": "Rock_Sandstone"
    },
    {
      "x": -12,
      "y": 8,
      "z": -17,
      "name": "Rock_Sandstone"
    },
    {
      "x": -12,
      "y": 9,
      "z": -17,
      "name": "Rock_Sandstone"
    },
    {
      "x": -12,
      "y": 10,
      "z": -17,
      "name": "Rock_Sandstone"
    },
    {
      "x": -12,
      "y": 11,
      "z": -17,
      "name": "Rock_Sandstone"
    },
    {
      "x": -12,
      "y": 12,
      "z": -17,
      "name": "Rock_Sandstone"
    },
    {
      "x": -12,
      "y": 13,
      "z": -17,
      "name": "Rock_Sandstone"
    },
    {
      "x": -12,
      "y": 14,
      "z": -17,
      "name": "Soil_Clay"
    },
    {
      "x": -12,
      "y": 15,
      "z": -17,
      "name": "Soil_Clay"
    },
    {
      "x": -12,
      "y": 16,
      "z": -17,
      "name": "Soil_Clay"
    },
    {
      "x": -12,
      "y": 17,
      "z": -17,
      "name": "Rock_Sandstone_Red"
    },
    {
      "x": -12,
      "y": 18,
      "z": -17,
      "name": "Rock_Sandstone_Red"
    },
    {
      "x": -12,
      "y": 19,
      "z": -17,
      "name": "Rock_Sandstone"
    },
    {
      "x": -12,
      "y": 20,
      "z": -17,
      "name": "Rock_Sandstone"
    },
    {
      "x": -12,
      "y": 21,
      "z": -17,
      "name": "Soil_Clay"
    },
    {
      "x": -12,
      "y": 22,
      "z": -17,
      "name": "Soil_Clay"
    },
    {
      "x": -12,
      "y": 23,
      "z": -17,
      "name": "Soil_Dirt_Dry"
    },
    {
      "x": -12,
      "y": 24,
      "z": -17,
      "name": "Soil_Dirt_Dry"
    },
    {
      "x": -12,
      "y": 25,
      "z": -17,
      "name": "Soil_Dirt_Dry"
    },
    {
      "x": -12,
      "y": 26,
      "z": -17,
      "name": "Rock_Sandstone"
    },
    {
      "x": -12,
      "y": 27,
      "z": -17,
      "name": "Rock_Sandstone"
    },
    {
      "x": -12,
      "y": 28,
      "z": -17,
      "name": "Soil_Clay"
    },
    {
      "x": -12,
      "y": 29,
      "z": -17,
      "name": "Soil_Clay"
    },
    {
      "x": -12,
      "y": 30,
      "z": -17,
      "name": "Rock_Sandstone_Red"
    },
    {
      "x": -12,
      "y": 31,
      "z": -17,
      "name": "Rock_Sandstone_Red"
    },
    {
      "x": -12,
      "y": 32,
      "z": -17,
      "name": "Rock_Sandstone_Red"
    },
    {
      "x": -12,
      "y": 33,
      "z": -17,
      "name": "Rock_Sandstone"
    },
    {
      "x": -12,
      "y": 34,
      "z": -17,
      "name": "Rock_Sandstone_White"
    },
    {
      "x": -12,
      "y": 35,
      "z": -17,
      "name": "Rock_Sandstone_White"
    },
    {
      "x": -12,
      "y": 36,
      "z": -17,
      "name": "Soil_Sand_Red"
    },
    {
      "x": -12,
      "y": 37,
      "z": -17,
      "name": "Soil_Sand_Red"
    },
    {
      "x": -12,
      "y": 7,
      "z": -16,
      "name": "Rock_Sandstone"
    },
    {
      "x": -12,
      "y": 8,
      "z": -16,
      "name": "Rock_Sandstone"
    },
    {
      "x": -12,
      "y": 9,
      "z": -16,
      "name": "Rock_Sandstone"
    },
    {
      "x": -12,
      "y": 10,
      "z": -16,
      "name": "Rock_Sandstone"
    },
    {
      "x": -12,
      "y": 11,
      "z": -16,
      "name": "Rock_Sandstone"
    },
    {
      "x": -12,
      "y": 12,
      "z": -16,
      "name": "Rock_Sandstone"
    },
    {
      "x": -12,
      "y": 13,
      "z": -16,
      "name": "Rock_Sandstone"
    },
    {
      "x": -12,
      "y": 14,
      "z": -16,
      "name": "Soil_Clay"
    },
    {
      "x": -12,
      "y": 15,
      "z": -16,
      "name": "Soil_Clay"
    },
    {
      "x": -12,
      "y": 16,
      "z": -16,
      "name": "Soil_Clay"
    },
    {
      "x": -12,
      "y": 17,
      "z": -16,
      "name": "Rock_Sandstone_Red"
    },
    {
      "x": -12,
      "y": 18,
      "z": -16,
      "name": "Rock_Sandstone_Red"
    },
    {
      "x": -12,
      "y": 19,
      "z": -16,
      "name": "Rock_Sandstone"
    },
    {
      "x": -12,
      "y": 20,
      "z": -16,
      "name": "Rock_Sandstone"
    },
    {
      "x": -12,
      "y": 21,
      "z": -16,
      "name": "Soil_Clay"
    },
    {
      "x": -12,
      "y": 22,
      "z": -16,
      "name": "Soil_Clay"
    },
    {
      "x": -12,
      "y": 23,
      "z": -16,
      "name": "Soil_Dirt_Dry"
    },
    {
      "x": -12,
      "y": 24,
      "z": -16,
      "name": "Soil_Dirt_Dry"
    },
    {
      "x": -12,
      "y": 25,
      "z": -16,
      "name": "Soil_Dirt_Dry"
    },
    {
      "x": -12,
      "y": 26,
      "z": -16,
      "name": "Rock_Sandstone"
    },
    {
      "x": -12,
      "y": 27,
      "z": -16,
      "name": "Rock_Sandstone"
    },
    {
      "x": -12,
      "y": 28,
      "z": -16,
      "name": "Soil_Clay"
    },
    {
      "x": -12,
      "y": 29,
      "z": -16,
      "name": "Soil_Clay"
    },
    {
      "x": -12,
      "y": 30,
      "z": -16,
      "name": "Rock_Sandstone_Red"
    },
    {
      "x": -12,
      "y": 31,
      "z": -16,
      "name": "Rock_Sandstone_Red"
    },
    {
      "x": -12,
      "y": 32,
      "z": -16,
      "name": "Rock_Sandstone_Red"
    },
    {
      "x": -12,
      "y": 33,
      "z": -16,
      "name": "Rock_Sandstone"
    },
    {
      "x": -12,
      "y": 34,
      "z": -16,
      "name": "Rock_Sandstone_White"
    },
    {
      "x": -12,
      "y": 35,
      "z": -16,
      "name": "Soil_Sand_Red"
    },
    {
      "x": -12,
      "y": 36,
      "z": -16,
      "name": "Soil_Sand_Red"
    },
    {
      "x": -12,
      "y": 7,
      "z": -15,
      "name": "Rock_Sandstone"
    },
    {
      "x": -12,
      "y": 8,
      "z": -15,
      "name": "Rock_Sandstone"
    },
    {
      "x": -12,
      "y": 9,
      "z": -15,
      "name": "Rock_Sandstone"
    },
    {
      "x": -12,
      "y": 10,
      "z": -15,
      "name": "Rock_Sandstone"
    },
    {
      "x": -12,
      "y": 11,
      "z": -15,
      "name": "Rock_Sandstone"
    },
    {
      "x": -12,
      "y": 12,
      "z": -15,
      "name": "Rock_Sandstone"
    },
    {
      "x": -12,
      "y": 13,
      "z": -15,
      "name": "Rock_Sandstone"
    },
    {
      "x": -12,
      "y": 14,
      "z": -15,
      "name": "Soil_Clay"
    },
    {
      "x": -12,
      "y": 15,
      "z": -15,
      "name": "Soil_Clay"
    },
    {
      "x": -12,
      "y": 16,
      "z": -15,
      "name": "Soil_Clay"
    },
    {
      "x": -12,
      "y": 17,
      "z": -15,
      "name": "Rock_Sandstone_Red"
    },
    {
      "x": -12,
      "y": 18,
      "z": -15,
      "name": "Rock_Sandstone_Red"
    },
    {
      "x": -12,
      "y": 19,
      "z": -15,
      "name": "Rock_Sandstone"
    },
    {
      "x": -12,
      "y": 20,
      "z": -15,
      "name": "Rock_Sandstone"
    },
    {
      "x": -12,
      "y": 21,
      "z": -15,
      "name": "Soil_Clay"
    },
    {
      "x": -12,
      "y": 22,
      "z": -15,
      "name": "Soil_Clay"
    },
    {
      "x": -12,
      "y": 23,
      "z": -15,
      "name": "Soil_Dirt_Dry"
    },
    {
      "x": -12,
      "y": 24,
      "z": -15,
      "name": "Soil_Dirt_Dry"
    },
    {
      "x": -12,
      "y": 25,
      "z": -15,
      "name": "Soil_Dirt_Dry"
    },
    {
      "x": -12,
      "y": 26,
      "z": -15,
      "name": "Soil_Dirt_Dry"
    },
    {
      "x": -12,
      "y": 27,
      "z": -15,
      "name": "Rock_Sandstone"
    },
    {
      "x": -12,
      "y": 28,
      "z": -15,
      "name": "Rock_Sandstone"
    },
    {
      "x": -12,
      "y": 9,
      "z": -14,
      "name": "Rock_Sandstone"
    },
    {
      "x": -12,
      "y": 10,
      "z": -14,
      "name": "Rock_Sandstone"
    },
    {
      "x": -12,
      "y": 11,
      "z": -14,
      "name": "Rock_Sandstone"
    },
    {
      "x": -12,
      "y": 12,
      "z": -14,
      "name": "Rock_Sandstone"
    },
    {
      "x": -12,
      "y": 13,
      "z": -14,
      "name": "Rock_Sandstone"
    },
    {
      "x": -12,
      "y": 14,
      "z": -14,
      "name": "Soil_Clay"
    },
    {
      "x": -12,
      "y": 15,
      "z": -14,
      "name": "Soil_Clay"
    },
    {
      "x": -12,
      "y": 16,
      "z": -14,
      "name": "Soil_Clay"
    },
    {
      "x": -12,
      "y": 17,
      "z": -14,
      "name": "Rock_Sandstone_Red"
    },
    {
      "x": -12,
      "y": 18,
      "z": -14,
      "name": "Rock_Sandstone_Red"
    },
    {
      "x": -12,
      "y": 19,
      "z": -14,
      "name": "Rock_Sandstone"
    },
    {
      "x": -12,
      "y": 20,
      "z": -14,
      "name": "Rock_Sandstone"
    },
    {
      "x": -12,
      "y": 21,
      "z": -14,
      "name": "Soil_Clay"
    },
    {
      "x": -12,
      "y": 11,
      "z": -13,
      "name": "Rock_Sandstone"
    },
    {
      "x": -12,
      "y": 12,
      "z": -13,
      "name": "Rock_Sandstone"
    },
    {
      "x": -12,
      "y": 13,
      "z": -13,
      "name": "Rock_Sandstone"
    },
    {
      "x": -12,
      "y": 14,
      "z": -13,
      "name": "Soil_Clay"
    },
    {
      "x": -12,
      "y": 15,
      "z": -13,
      "name": "Soil_Clay"
    },
    {
      "x": -12,
      "y": 16,
      "z": -13,
      "name": "Soil_Clay"
    },
    {
      "x": -12,
      "y": 15,
      "z": 7,
      "name": "Rock_Sandstone"
    },
    {
      "x": -12,
      "y": 16,
      "z": 7,
      "name": "Soil_Clay"
    },
    {
      "x": -12,
      "y": 12,
      "z": 8,
      "name": "Rock_Sandstone"
    },
    {
      "x": -12,
      "y": 13,
      "z": 8,
      "name": "Rock_Sandstone"
    },
    {
      "x": -12,
      "y": 14,
      "z": 8,
      "name": "Rock_Sandstone"
    },
    {
      "x": -12,
      "y": 15,
      "z": 8,
      "name": "Rock_Sandstone"
    },
    {
      "x": -12,
      "y": 16,
      "z": 8,
      "name": "Soil_Clay"
    },
    {
      "x": -12,
      "y": 17,
      "z": 8,
      "name": "Rock_Sandstone_Red"
    },
    {
      "x": -12,
      "y": 18,
      "z": 8,
      "name": "Rock_Sandstone_Red"
    },
    {
      "x": -12,
      "y": 19,
      "z": 8,
      "name": "Rock_Sandstone_Red"
    },
    {
      "x": -12,
      "y": 20,
      "z": 8,
      "name": "Rock_Sandstone_Red"
    },
    {
      "x": -12,
      "y": 21,
      "z": 8,
      "name": "Rock_Sandstone"
    },
    {
      "x": -12,
      "y": 22,
      "z": 8,
      "name": "Rock_Sandstone"
    },
    {
      "x": -12,
      "y": 10,
      "z": 9,
      "name": "Rock_Sandstone"
    },
    {
      "x": -12,
      "y": 11,
      "z": 9,
      "name": "Rock_Sandstone"
    },
    {
      "x": -12,
      "y": 12,
      "z": 9,
      "name": "Rock_Sandstone"
    },
    {
      "x": -12,
      "y": 13,
      "z": 9,
      "name": "Rock_Sandstone"
    },
    {
      "x": -12,
      "y": 14,
      "z": 9,
      "name": "Rock_Sandstone"
    },
    {
      "x": -12,
      "y": 15,
      "z": 9,
      "name": "Rock_Sandstone"
    },
    {
      "x": -12,
      "y": 16,
      "z": 9,
      "name": "Soil_Clay"
    },
    {
      "x": -12,
      "y": 17,
      "z": 9,
      "name": "Rock_Sandstone_Red"
    },
    {
      "x": -12,
      "y": 18,
      "z": 9,
      "name": "Rock_Sandstone_Red"
    },
    {
      "x": -12,
      "y": 19,
      "z": 9,
      "name": "Rock_Sandstone_Red"
    },
    {
      "x": -12,
      "y": 20,
      "z": 9,
      "name": "Rock_Sandstone_Red"
    },
    {
      "x": -12,
      "y": 21,
      "z": 9,
      "name": "Rock_Sandstone"
    },
    {
      "x": -12,
      "y": 22,
      "z": 9,
      "name": "Rock_Sandstone"
    },
    {
      "x": -12,
      "y": 23,
      "z": 9,
      "name": "Rock_Sandstone"
    },
    {
      "x": -12,
      "y": 24,
      "z": 9,
      "name": "Soil_Clay"
    },
    {
      "x": -12,
      "y": 9,
      "z": 10,
      "name": "Rock_Sandstone"
    },
    {
      "x": -12,
      "y": 10,
      "z": 10,
      "name": "Rock_Sandstone"
    },
    {
      "x": -12,
      "y": 11,
      "z": 10,
      "name": "Rock_Sandstone"
    },
    {
      "x": -12,
      "y": 12,
      "z": 10,
      "name": "Rock_Sandstone"
    },
    {
      "x": -12,
      "y": 13,
      "z": 10,
      "name": "Rock_Sandstone"
    },
    {
      "x": -12,
      "y": 14,
      "z": 10,
      "name": "Rock_Sandstone"
    },
    {
      "x": -12,
      "y": 15,
      "z": 10,
      "name": "Rock_Sandstone"
    },
    {
      "x": -12,
      "y": 16,
      "z": 10,
      "name": "Soil_Clay"
    },
    {
      "x": -12,
      "y": 17,
      "z": 10,
      "name": "Rock_Sandstone_Red"
    },
    {
      "x": -12,
      "y": 18,
      "z": 10,
      "name": "Rock_Sandstone_Red"
    },
    {
      "x": -12,
      "y": 19,
      "z": 10,
      "name": "Rock_Sandstone_Red"
    },
    {
      "x": -12,
      "y": 20,
      "z": 10,
      "name": "Rock_Sandstone_Red"
    },
    {
      "x": -12,
      "y": 21,
      "z": 10,
      "name": "Rock_Sandstone"
    },
    {
      "x": -12,
      "y": 22,
      "z": 10,
      "name": "Rock_Sandstone"
    },
    {
      "x": -12,
      "y": 23,
      "z": 10,
      "name": "Rock_Sandstone"
    },
    {
      "x": -12,
      "y": 24,
      "z": 10,
      "name": "Soil_Clay"
    },
    {
      "x": -12,
      "y": 9,
      "z": 11,
      "name": "Rock_Sandstone"
    },
    {
      "x": -12,
      "y": 10,
      "z": 11,
      "name": "Rock_Sandstone"
    },
    {
      "x": -12,
      "y": 11,
      "z": 11,
      "name": "Rock_Sandstone"
    },
    {
      "x": -12,
      "y": 12,
      "z": 11,
      "name": "Rock_Sandstone"
    },
    {
      "x": -12,
      "y": 13,
      "z": 11,
      "name": "Rock_Sandstone"
    },
    {
      "x": -12,
      "y": 14,
      "z": 11,
      "name": "Rock_Sandstone"
    },
    {
      "x": -12,
      "y": 15,
      "z": 11,
      "name": "Rock_Sandstone"
    },
    {
      "x": -12,
      "y": 16,
      "z": 11,
      "name": "Soil_Clay"
    },
    {
      "x": -12,
      "y": 17,
      "z": 11,
      "name": "Rock_Sandstone_Red"
    },
    {
      "x": -12,
      "y": 18,
      "z": 11,
      "name": "Rock_Sandstone_Red"
    },
    {
      "x": -12,
      "y": 19,
      "z": 11,
      "name": "Rock_Sandstone_Red"
    },
    {
      "x": -12,
      "y": 20,
      "z": 11,
      "name": "Rock_Sandstone_Red"
    },
    {
      "x": -12,
      "y": 21,
      "z": 11,
      "name": "Rock_Sandstone"
    },
    {
      "x": -12,
      "y": 22,
      "z": 11,
      "name": "Rock_Sandstone"
    },
    {
      "x": -12,
      "y": 23,
      "z": 11,
      "name": "Rock_Sandstone"
    },
    {
      "x": -12,
      "y": 24,
      "z": 11,
      "name": "Soil_Clay"
    },
    {
      "x": -12,
      "y": 9,
      "z": 12,
      "name": "Rock_Sandstone"
    },
    {
      "x": -12,
      "y": 10,
      "z": 12,
      "name": "Rock_Sandstone"
    },
    {
      "x": -12,
      "y": 11,
      "z": 12,
      "name": "Rock_Sandstone"
    },
    {
      "x": -12,
      "y": 12,
      "z": 12,
      "name": "Rock_Sandstone"
    },
    {
      "x": -12,
      "y": 13,
      "z": 12,
      "name": "Rock_Sandstone"
    },
    {
      "x": -12,
      "y": 14,
      "z": 12,
      "name": "Rock_Sandstone"
    },
    {
      "x": -12,
      "y": 15,
      "z": 12,
      "name": "Rock_Sandstone"
    },
    {
      "x": -12,
      "y": 16,
      "z": 12,
      "name": "Rock_Sandstone"
    },
    {
      "x": -12,
      "y": 17,
      "z": 12,
      "name": "Rock_Sandstone_Red"
    },
    {
      "x": -12,
      "y": 18,
      "z": 12,
      "name": "Rock_Sandstone_Red"
    },
    {
      "x": -12,
      "y": 19,
      "z": 12,
      "name": "Rock_Sandstone_Red"
    },
    {
      "x": -12,
      "y": 20,
      "z": 12,
      "name": "Rock_Sandstone_Red"
    },
    {
      "x": -12,
      "y": 21,
      "z": 12,
      "name": "Rock_Sandstone"
    },
    {
      "x": -12,
      "y": 22,
      "z": 12,
      "name": "Rock_Sandstone"
    },
    {
      "x": -12,
      "y": 23,
      "z": 12,
      "name": "Rock_Sandstone"
    },
    {
      "x": -12,
      "y": 24,
      "z": 12,
      "name": "Soil_Clay"
    },
    {
      "x": -12,
      "y": 9,
      "z": 13,
      "name": "Rock_Sandstone"
    },
    {
      "x": -12,
      "y": 10,
      "z": 13,
      "name": "Rock_Sandstone"
    },
    {
      "x": -12,
      "y": 11,
      "z": 13,
      "name": "Rock_Sandstone"
    },
    {
      "x": -12,
      "y": 12,
      "z": 13,
      "name": "Rock_Sandstone"
    },
    {
      "x": -12,
      "y": 13,
      "z": 13,
      "name": "Rock_Sandstone"
    },
    {
      "x": -12,
      "y": 14,
      "z": 13,
      "name": "Rock_Sandstone"
    },
    {
      "x": -12,
      "y": 15,
      "z": 13,
      "name": "Rock_Sandstone"
    },
    {
      "x": -12,
      "y": 16,
      "z": 13,
      "name": "Rock_Sandstone"
    },
    {
      "x": -12,
      "y": 17,
      "z": 13,
      "name": "Rock_Sandstone_Red"
    },
    {
      "x": -12,
      "y": 18,
      "z": 13,
      "name": "Rock_Sandstone_Red"
    },
    {
      "x": -12,
      "y": 19,
      "z": 13,
      "name": "Rock_Sandstone_Red"
    },
    {
      "x": -12,
      "y": 20,
      "z": 13,
      "name": "Rock_Sandstone_Red"
    },
    {
      "x": -12,
      "y": 21,
      "z": 13,
      "name": "Rock_Sandstone"
    },
    {
      "x": -12,
      "y": 22,
      "z": 13,
      "name": "Rock_Sandstone"
    },
    {
      "x": -12,
      "y": 23,
      "z": 13,
      "name": "Rock_Sandstone"
    },
    {
      "x": -12,
      "y": 24,
      "z": 13,
      "name": "Soil_Clay"
    },
    {
      "x": -12,
      "y": 12,
      "z": 14,
      "name": "Rock_Sandstone"
    },
    {
      "x": -12,
      "y": 13,
      "z": 14,
      "name": "Rock_Sandstone"
    },
    {
      "x": -12,
      "y": 14,
      "z": 14,
      "name": "Rock_Sandstone"
    },
    {
      "x": -12,
      "y": 15,
      "z": 14,
      "name": "Rock_Sandstone"
    },
    {
      "x": -12,
      "y": 16,
      "z": 14,
      "name": "Rock_Sandstone"
    },
    {
      "x": -12,
      "y": 17,
      "z": 14,
      "name": "Soil_Clay"
    },
    {
      "x": -12,
      "y": 18,
      "z": 14,
      "name": "Rock_Sandstone_Red"
    },
    {
      "x": -12,
      "y": 19,
      "z": 14,
      "name": "Rock_Sandstone_Red"
    },
    {
      "x": -12,
      "y": 20,
      "z": 14,
      "name": "Rock_Sandstone_Red"
    },
    {
      "x": -12,
      "y": 21,
      "z": 14,
      "name": "Rock_Sandstone"
    },
    {
      "x": -12,
      "y": 22,
      "z": 14,
      "name": "Rock_Sandstone"
    },
    {
      "x": -12,
      "y": 23,
      "z": 14,
      "name": "Rock_Sandstone"
    },
    {
      "x": -12,
      "y": 24,
      "z": 14,
      "name": "Soil_Clay"
    },
    {
      "x": -12,
      "y": 15,
      "z": 15,
      "name": "Rock_Sandstone"
    },
    {
      "x": -12,
      "y": 16,
      "z": 15,
      "name": "Rock_Sandstone"
    },
    {
      "x": -12,
      "y": 17,
      "z": 15,
      "name": "Soil_Clay"
    },
    {
      "x": -12,
      "y": 18,
      "z": 15,
      "name": "Rock_Sandstone_Red"
    },
    {
      "x": -12,
      "y": 19,
      "z": 15,
      "name": "Rock_Sandstone_Red"
    },
    {
      "x": -12,
      "y": 20,
      "z": 15,
      "name": "Rock_Sandstone_Red"
    },
    {
      "x": -11,
      "y": 10,
      "z": -23,
      "name": "Rock_Sandstone"
    },
    {
      "x": -11,
      "y": 11,
      "z": -23,
      "name": "Rock_Sandstone"
    },
    {
      "x": -11,
      "y": 12,
      "z": -23,
      "name": "Rock_Sandstone"
    },
    {
      "x": -11,
      "y": 13,
      "z": -23,
      "name": "Rock_Sandstone"
    },
    {
      "x": -11,
      "y": 14,
      "z": -23,
      "name": "Soil_Clay"
    },
    {
      "x": -11,
      "y": 15,
      "z": -23,
      "name": "Soil_Clay"
    },
    {
      "x": -11,
      "y": 16,
      "z": -23,
      "name": "Soil_Clay"
    },
    {
      "x": -11,
      "y": 17,
      "z": -23,
      "name": "Rock_Sandstone_Red"
    },
    {
      "x": -11,
      "y": 18,
      "z": -23,
      "name": "Rock_Sandstone_Red"
    },
    {
      "x": -11,
      "y": 19,
      "z": -23,
      "name": "Rock_Sandstone"
    },
    {
      "x": -11,
      "y": 6,
      "z": -22,
      "name": "Rock_Sandstone"
    },
    {
      "x": -11,
      "y": 7,
      "z": -22,
      "name": "Rock_Sandstone"
    },
    {
      "x": -11,
      "y": 8,
      "z": -22,
      "name": "Rock_Sandstone"
    },
    {
      "x": -11,
      "y": 9,
      "z": -22,
      "name": "Rock_Sandstone"
    },
    {
      "x": -11,
      "y": 10,
      "z": -22,
      "name": "Rock_Sandstone"
    },
    {
      "x": -11,
      "y": 11,
      "z": -22,
      "name": "Rock_Sandstone"
    },
    {
      "x": -11,
      "y": 12,
      "z": -22,
      "name": "Rock_Sandstone"
    },
    {
      "x": -11,
      "y": 13,
      "z": -22,
      "name": "Rock_Sandstone"
    },
    {
      "x": -11,
      "y": 14,
      "z": -22,
      "name": "Soil_Clay"
    },
    {
      "x": -11,
      "y": 15,
      "z": -22,
      "name": "Soil_Clay"
    },
    {
      "x": -11,
      "y": 16,
      "z": -22,
      "name": "Soil_Clay"
    },
    {
      "x": -11,
      "y": 17,
      "z": -22,
      "name": "Rock_Sandstone_Red"
    },
    {
      "x": -11,
      "y": 18,
      "z": -22,
      "name": "Rock_Sandstone_Red"
    },
    {
      "x": -11,
      "y": 19,
      "z": -22,
      "name": "Rock_Sandstone"
    },
    {
      "x": -11,
      "y": 20,
      "z": -22,
      "name": "Soil_Clay"
    },
    {
      "x": -11,
      "y": 21,
      "z": -22,
      "name": "Soil_Clay"
    },
    {
      "x": -11,
      "y": 22,
      "z": -22,
      "name": "Soil_Dirt_Dry"
    },
    {
      "x": -11,
      "y": 23,
      "z": -22,
      "name": "Soil_Dirt_Dry"
    },
    {
      "x": -11,
      "y": 24,
      "z": -22,
      "name": "Soil_Dirt_Dry"
    },
    {
      "x": -11,
      "y": 5,
      "z": -21,
      "name": "Rock_Sandstone"
    },
    {
      "x": -11,
      "y": 6,
      "z": -21,
      "name": "Rock_Sandstone"
    },
    {
      "x": -11,
      "y": 7,
      "z": -21,
      "name": "Rock_Sandstone"
    },
    {
      "x": -11,
      "y": 8,
      "z": -21,
      "name": "Rock_Sandstone"
    },
    {
      "x": -11,
      "y": 9,
      "z": -21,
      "name": "Rock_Sandstone"
    },
    {
      "x": -11,
      "y": 10,
      "z": -21,
      "name": "Rock_Sandstone"
    },
    {
      "x": -11,
      "y": 11,
      "z": -21,
      "name": "Rock_Sandstone"
    },
    {
      "x": -11,
      "y": 12,
      "z": -21,
      "name": "Rock_Sandstone"
    },
    {
      "x": -11,
      "y": 13,
      "z": -21,
      "name": "Rock_Sandstone"
    },
    {
      "x": -11,
      "y": 14,
      "z": -21,
      "name": "Soil_Clay"
    },
    {
      "x": -11,
      "y": 15,
      "z": -21,
      "name": "Soil_Clay"
    },
    {
      "x": -11,
      "y": 16,
      "z": -21,
      "name": "Soil_Clay"
    },
    {
      "x": -11,
      "y": 17,
      "z": -21,
      "name": "Rock_Sandstone_Red"
    },
    {
      "x": -11,
      "y": 18,
      "z": -21,
      "name": "Rock_Sandstone_Red"
    },
    {
      "x": -11,
      "y": 19,
      "z": -21,
      "name": "Rock_Sandstone"
    },
    {
      "x": -11,
      "y": 20,
      "z": -21,
      "name": "Soil_Clay"
    },
    {
      "x": -11,
      "y": 21,
      "z": -21,
      "name": "Soil_Clay"
    },
    {
      "x": -11,
      "y": 22,
      "z": -21,
      "name": "Soil_Dirt_Dry"
    },
    {
      "x": -11,
      "y": 23,
      "z": -21,
      "name": "Soil_Dirt_Dry"
    },
    {
      "x": -11,
      "y": 24,
      "z": -21,
      "name": "Soil_Dirt_Dry"
    },
    {
      "x": -11,
      "y": 25,
      "z": -21,
      "name": "Rock_Sandstone"
    },
    {
      "x": -11,
      "y": 26,
      "z": -21,
      "name": "Rock_Sandstone"
    },
    {
      "x": -11,
      "y": 27,
      "z": -21,
      "name": "Soil_Clay"
    },
    {
      "x": -11,
      "y": 28,
      "z": -21,
      "name": "Soil_Clay"
    },
    {
      "x": -11,
      "y": 29,
      "z": -21,
      "name": "Rock_Sandstone_Red"
    },
    {
      "x": -11,
      "y": 30,
      "z": -21,
      "name": "Rock_Sandstone_Red"
    },
    {
      "x": -11,
      "y": 5,
      "z": -20,
      "name": "Rock_Sandstone"
    },
    {
      "x": -11,
      "y": 6,
      "z": -20,
      "name": "Rock_Sandstone"
    },
    {
      "x": -11,
      "y": 7,
      "z": -20,
      "name": "Rock_Sandstone"
    },
    {
      "x": -11,
      "y": 8,
      "z": -20,
      "name": "Rock_Sandstone"
    },
    {
      "x": -11,
      "y": 9,
      "z": -20,
      "name": "Rock_Sandstone"
    },
    {
      "x": -11,
      "y": 10,
      "z": -20,
      "name": "Rock_Sandstone"
    },
    {
      "x": -11,
      "y": 11,
      "z": -20,
      "name": "Rock_Sandstone"
    },
    {
      "x": -11,
      "y": 12,
      "z": -20,
      "name": "Rock_Sandstone"
    },
    {
      "x": -11,
      "y": 13,
      "z": -20,
      "name": "Rock_Sandstone"
    },
    {
      "x": -11,
      "y": 14,
      "z": -20,
      "name": "Soil_Clay"
    },
    {
      "x": -11,
      "y": 15,
      "z": -20,
      "name": "Soil_Clay"
    },
    {
      "x": -11,
      "y": 16,
      "z": -20,
      "name": "Soil_Clay"
    },
    {
      "x": -11,
      "y": 17,
      "z": -20,
      "name": "Rock_Sandstone_Red"
    },
    {
      "x": -11,
      "y": 18,
      "z": -20,
      "name": "Rock_Sandstone_Red"
    },
    {
      "x": -11,
      "y": 19,
      "z": -20,
      "name": "Rock_Sandstone"
    },
    {
      "x": -11,
      "y": 20,
      "z": -20,
      "name": "Soil_Clay"
    },
    {
      "x": -11,
      "y": 21,
      "z": -20,
      "name": "Soil_Clay"
    },
    {
      "x": -11,
      "y": 22,
      "z": -20,
      "name": "Soil_Dirt_Dry"
    },
    {
      "x": -11,
      "y": 23,
      "z": -20,
      "name": "Soil_Dirt_Dry"
    },
    {
      "x": -11,
      "y": 24,
      "z": -20,
      "name": "Soil_Dirt_Dry"
    },
    {
      "x": -11,
      "y": 25,
      "z": -20,
      "name": "Soil_Dirt_Dry"
    },
    {
      "x": -11,
      "y": 26,
      "z": -20,
      "name": "Rock_Sandstone"
    },
    {
      "x": -11,
      "y": 27,
      "z": -20,
      "name": "Soil_Clay"
    },
    {
      "x": -11,
      "y": 28,
      "z": -20,
      "name": "Soil_Clay"
    },
    {
      "x": -11,
      "y": 29,
      "z": -20,
      "name": "Rock_Sandstone_Red"
    },
    {
      "x": -11,
      "y": 30,
      "z": -20,
      "name": "Rock_Sandstone_Red"
    },
    {
      "x": -11,
      "y": 31,
      "z": -20,
      "name": "Rock_Sandstone_Red"
    },
    {
      "x": -11,
      "y": 32,
      "z": -20,
      "name": "Rock_Sandstone_Red"
    },
    {
      "x": -11,
      "y": 33,
      "z": -20,
      "name": "Rock_Sandstone"
    },
    {
      "x": -11,
      "y": 34,
      "z": -20,
      "name": "Rock_Sandstone_White"
    },
    {
      "x": -11,
      "y": 35,
      "z": -20,
      "name": "Soil_Sand_Red"
    },
    {
      "x": -11,
      "y": 36,
      "z": -20,
      "name": "Soil_Sand_Red"
    },
    {
      "x": -11,
      "y": 5,
      "z": -19,
      "name": "Rock_Sandstone"
    },
    {
      "x": -11,
      "y": 6,
      "z": -19,
      "name": "Rock_Sandstone"
    },
    {
      "x": -11,
      "y": 7,
      "z": -19,
      "name": "Rock_Sandstone"
    },
    {
      "x": -11,
      "y": 8,
      "z": -19,
      "name": "Rock_Sandstone"
    },
    {
      "x": -11,
      "y": 9,
      "z": -19,
      "name": "Rock_Sandstone"
    },
    {
      "x": -11,
      "y": 10,
      "z": -19,
      "name": "Rock_Sandstone"
    },
    {
      "x": -11,
      "y": 11,
      "z": -19,
      "name": "Rock_Sandstone"
    },
    {
      "x": -11,
      "y": 12,
      "z": -19,
      "name": "Rock_Sandstone"
    },
    {
      "x": -11,
      "y": 13,
      "z": -19,
      "name": "Rock_Sandstone"
    },
    {
      "x": -11,
      "y": 14,
      "z": -19,
      "name": "Soil_Clay"
    },
    {
      "x": -11,
      "y": 15,
      "z": -19,
      "name": "Soil_Clay"
    },
    {
      "x": -11,
      "y": 16,
      "z": -19,
      "name": "Soil_Clay"
    },
    {
      "x": -11,
      "y": 17,
      "z": -19,
      "name": "Rock_Sandstone_Red"
    },
    {
      "x": -11,
      "y": 18,
      "z": -19,
      "name": "Rock_Sandstone_Red"
    },
    {
      "x": -11,
      "y": 19,
      "z": -19,
      "name": "Rock_Sandstone"
    },
    {
      "x": -11,
      "y": 20,
      "z": -19,
      "name": "Soil_Clay"
    },
    {
      "x": -11,
      "y": 21,
      "z": -19,
      "name": "Soil_Clay"
    },
    {
      "x": -11,
      "y": 22,
      "z": -19,
      "name": "Soil_Dirt_Dry"
    },
    {
      "x": -11,
      "y": 23,
      "z": -19,
      "name": "Soil_Dirt_Dry"
    },
    {
      "x": -11,
      "y": 24,
      "z": -19,
      "name": "Soil_Dirt_Dry"
    },
    {
      "x": -11,
      "y": 25,
      "z": -19,
      "name": "Soil_Dirt_Dry"
    },
    {
      "x": -11,
      "y": 26,
      "z": -19,
      "name": "Rock_Sandstone"
    },
    {
      "x": -11,
      "y": 27,
      "z": -19,
      "name": "Soil_Clay"
    },
    {
      "x": -11,
      "y": 28,
      "z": -19,
      "name": "Soil_Clay"
    },
    {
      "x": -11,
      "y": 29,
      "z": -19,
      "name": "Rock_Sandstone_Red"
    },
    {
      "x": -11,
      "y": 30,
      "z": -19,
      "name": "Rock_Sandstone_Red"
    },
    {
      "x": -11,
      "y": 31,
      "z": -19,
      "name": "Rock_Sandstone_Red"
    },
    {
      "x": -11,
      "y": 32,
      "z": -19,
      "name": "Rock_Sandstone_Red"
    },
    {
      "x": -11,
      "y": 33,
      "z": -19,
      "name": "Rock_Sandstone"
    },
    {
      "x": -11,
      "y": 34,
      "z": -19,
      "name": "Rock_Sandstone_White"
    },
    {
      "x": -11,
      "y": 35,
      "z": -19,
      "name": "Rock_Sandstone_White"
    },
    {
      "x": -11,
      "y": 36,
      "z": -19,
      "name": "Soil_Sand_Red"
    },
    {
      "x": -11,
      "y": 37,
      "z": -19,
      "name": "Soil_Sand_Red"
    },
    {
      "x": -11,
      "y": 4,
      "z": -18,
      "name": "Rock_Sandstone"
    },
    {
      "x": -11,
      "y": 5,
      "z": -18,
      "name": "Rock_Sandstone"
    },
    {
      "x": -11,
      "y": 6,
      "z": -18,
      "name": "Rock_Sandstone"
    },
    {
      "x": -11,
      "y": 7,
      "z": -18,
      "name": "Rock_Sandstone"
    },
    {
      "x": -11,
      "y": 8,
      "z": -18,
      "name": "Rock_Sandstone"
    },
    {
      "x": -11,
      "y": 9,
      "z": -18,
      "name": "Rock_Sandstone"
    },
    {
      "x": -11,
      "y": 10,
      "z": -18,
      "name": "Rock_Sandstone"
    },
    {
      "x": -11,
      "y": 11,
      "z": -18,
      "name": "Rock_Sandstone"
    },
    {
      "x": -11,
      "y": 12,
      "z": -18,
      "name": "Rock_Sandstone"
    },
    {
      "x": -11,
      "y": 13,
      "z": -18,
      "name": "Rock_Sandstone"
    },
    {
      "x": -11,
      "y": 14,
      "z": -18,
      "name": "Soil_Clay"
    },
    {
      "x": -11,
      "y": 15,
      "z": -18,
      "name": "Soil_Clay"
    },
    {
      "x": -11,
      "y": 16,
      "z": -18,
      "name": "Soil_Clay"
    },
    {
      "x": -11,
      "y": 17,
      "z": -18,
      "name": "Rock_Sandstone_Red"
    },
    {
      "x": -11,
      "y": 18,
      "z": -18,
      "name": "Rock_Sandstone_Red"
    },
    {
      "x": -11,
      "y": 19,
      "z": -18,
      "name": "Rock_Sandstone"
    },
    {
      "x": -11,
      "y": 20,
      "z": -18,
      "name": "Soil_Clay"
    },
    {
      "x": -11,
      "y": 21,
      "z": -18,
      "name": "Soil_Clay"
    },
    {
      "x": -11,
      "y": 22,
      "z": -18,
      "name": "Soil_Clay"
    },
    {
      "x": -11,
      "y": 23,
      "z": -18,
      "name": "Soil_Dirt_Dry"
    },
    {
      "x": -11,
      "y": 24,
      "z": -18,
      "name": "Soil_Dirt_Dry"
    },
    {
      "x": -11,
      "y": 25,
      "z": -18,
      "name": "Soil_Dirt_Dry"
    },
    {
      "x": -11,
      "y": 26,
      "z": -18,
      "name": "Rock_Sandstone"
    },
    {
      "x": -11,
      "y": 27,
      "z": -18,
      "name": "Rock_Sandstone"
    },
    {
      "x": -11,
      "y": 28,
      "z": -18,
      "name": "Soil_Clay"
    },
    {
      "x": -11,
      "y": 29,
      "z": -18,
      "name": "Rock_Sandstone_Red"
    },
    {
      "x": -11,
      "y": 30,
      "z": -18,
      "name": "Rock_Sandstone_Red"
    },
    {
      "x": -11,
      "y": 31,
      "z": -18,
      "name": "Rock_Sandstone_Red"
    },
    {
      "x": -11,
      "y": 32,
      "z": -18,
      "name": "Rock_Sandstone_Red"
    },
    {
      "x": -11,
      "y": 33,
      "z": -18,
      "name": "Rock_Sandstone"
    },
    {
      "x": -11,
      "y": 34,
      "z": -18,
      "name": "Rock_Sandstone_White"
    },
    {
      "x": -11,
      "y": 35,
      "z": -18,
      "name": "Rock_Sandstone_White"
    },
    {
      "x": -11,
      "y": 36,
      "z": -18,
      "name": "Soil_Sand_Red"
    },
    {
      "x": -11,
      "y": 37,
      "z": -18,
      "name": "Soil_Sand_Red"
    },
    {
      "x": -11,
      "y": 5,
      "z": -17,
      "name": "Rock_Sandstone"
    },
    {
      "x": -11,
      "y": 6,
      "z": -17,
      "name": "Rock_Sandstone"
    },
    {
      "x": -11,
      "y": 7,
      "z": -17,
      "name": "Rock_Sandstone"
    },
    {
      "x": -11,
      "y": 8,
      "z": -17,
      "name": "Rock_Sandstone"
    },
    {
      "x": -11,
      "y": 9,
      "z": -17,
      "name": "Rock_Sandstone"
    },
    {
      "x": -11,
      "y": 10,
      "z": -17,
      "name": "Rock_Sandstone"
    },
    {
      "x": -11,
      "y": 11,
      "z": -17,
      "name": "Rock_Sandstone"
    },
    {
      "x": -11,
      "y": 12,
      "z": -17,
      "name": "Rock_Sandstone"
    },
    {
      "x": -11,
      "y": 13,
      "z": -17,
      "name": "Rock_Sandstone"
    },
    {
      "x": -11,
      "y": 14,
      "z": -17,
      "name": "Soil_Clay"
    },
    {
      "x": -11,
      "y": 15,
      "z": -17,
      "name": "Soil_Clay"
    },
    {
      "x": -11,
      "y": 16,
      "z": -17,
      "name": "Soil_Clay"
    },
    {
      "x": -11,
      "y": 17,
      "z": -17,
      "name": "Rock_Sandstone_Red"
    },
    {
      "x": -11,
      "y": 18,
      "z": -17,
      "name": "Rock_Sandstone_Red"
    },
    {
      "x": -11,
      "y": 19,
      "z": -17,
      "name": "Rock_Sandstone"
    },
    {
      "x": -11,
      "y": 20,
      "z": -17,
      "name": "Soil_Clay"
    },
    {
      "x": -11,
      "y": 21,
      "z": -17,
      "name": "Soil_Clay"
    },
    {
      "x": -11,
      "y": 22,
      "z": -17,
      "name": "Soil_Clay"
    },
    {
      "x": -11,
      "y": 23,
      "z": -17,
      "name": "Soil_Dirt_Dry"
    },
    {
      "x": -11,
      "y": 24,
      "z": -17,
      "name": "Soil_Dirt_Dry"
    },
    {
      "x": -11,
      "y": 25,
      "z": -17,
      "name": "Soil_Dirt_Dry"
    },
    {
      "x": -11,
      "y": 26,
      "z": -17,
      "name": "Rock_Sandstone"
    },
    {
      "x": -11,
      "y": 27,
      "z": -17,
      "name": "Rock_Sandstone"
    },
    {
      "x": -11,
      "y": 28,
      "z": -17,
      "name": "Soil_Clay"
    },
    {
      "x": -11,
      "y": 29,
      "z": -17,
      "name": "Soil_Clay"
    },
    {
      "x": -11,
      "y": 30,
      "z": -17,
      "name": "Rock_Sandstone_Red"
    },
    {
      "x": -11,
      "y": 31,
      "z": -17,
      "name": "Rock_Sandstone_Red"
    },
    {
      "x": -11,
      "y": 32,
      "z": -17,
      "name": "Rock_Sandstone_Red"
    },
    {
      "x": -11,
      "y": 33,
      "z": -17,
      "name": "Rock_Sandstone"
    },
    {
      "x": -11,
      "y": 34,
      "z": -17,
      "name": "Rock_Sandstone_White"
    },
    {
      "x": -11,
      "y": 35,
      "z": -17,
      "name": "Rock_Sandstone_White"
    },
    {
      "x": -11,
      "y": 36,
      "z": -17,
      "name": "Rock_Sandstone_White"
    },
    {
      "x": -11,
      "y": 37,
      "z": -17,
      "name": "Soil_Sand_Red"
    },
    {
      "x": -11,
      "y": 38,
      "z": -17,
      "name": "Soil_Sand_Red"
    },
    {
      "x": -11,
      "y": 5,
      "z": -16,
      "name": "Rock_Sandstone"
    },
    {
      "x": -11,
      "y": 6,
      "z": -16,
      "name": "Rock_Sandstone"
    },
    {
      "x": -11,
      "y": 7,
      "z": -16,
      "name": "Rock_Sandstone"
    },
    {
      "x": -11,
      "y": 8,
      "z": -16,
      "name": "Rock_Sandstone"
    },
    {
      "x": -11,
      "y": 9,
      "z": -16,
      "name": "Rock_Sandstone"
    },
    {
      "x": -11,
      "y": 10,
      "z": -16,
      "name": "Rock_Sandstone"
    },
    {
      "x": -11,
      "y": 11,
      "z": -16,
      "name": "Rock_Sandstone"
    },
    {
      "x": -11,
      "y": 12,
      "z": -16,
      "name": "Rock_Sandstone"
    },
    {
      "x": -11,
      "y": 13,
      "z": -16,
      "name": "Rock_Sandstone"
    },
    {
      "x": -11,
      "y": 14,
      "z": -16,
      "name": "Soil_Clay"
    },
    {
      "x": -11,
      "y": 15,
      "z": -16,
      "name": "Soil_Clay"
    },
    {
      "x": -11,
      "y": 16,
      "z": -16,
      "name": "Soil_Clay"
    },
    {
      "x": -11,
      "y": 17,
      "z": -16,
      "name": "Rock_Sandstone_Red"
    },
    {
      "x": -11,
      "y": 18,
      "z": -16,
      "name": "Rock_Sandstone_Red"
    },
    {
      "x": -11,
      "y": 19,
      "z": -16,
      "name": "Rock_Sandstone"
    },
    {
      "x": -11,
      "y": 20,
      "z": -16,
      "name": "Rock_Sandstone"
    },
    {
      "x": -11,
      "y": 21,
      "z": -16,
      "name": "Soil_Clay"
    },
    {
      "x": -11,
      "y": 22,
      "z": -16,
      "name": "Soil_Clay"
    },
    {
      "x": -11,
      "y": 23,
      "z": -16,
      "name": "Soil_Dirt_Dry"
    },
    {
      "x": -11,
      "y": 24,
      "z": -16,
      "name": "Soil_Dirt_Dry"
    },
    {
      "x": -11,
      "y": 25,
      "z": -16,
      "name": "Soil_Dirt_Dry"
    },
    {
      "x": -11,
      "y": 26,
      "z": -16,
      "name": "Rock_Sandstone"
    },
    {
      "x": -11,
      "y": 27,
      "z": -16,
      "name": "Rock_Sandstone"
    },
    {
      "x": -11,
      "y": 28,
      "z": -16,
      "name": "Soil_Clay"
    },
    {
      "x": -11,
      "y": 29,
      "z": -16,
      "name": "Soil_Clay"
    },
    {
      "x": -11,
      "y": 30,
      "z": -16,
      "name": "Rock_Sandstone_Red"
    },
    {
      "x": -11,
      "y": 31,
      "z": -16,
      "name": "Rock_Sandstone_Red"
    },
    {
      "x": -11,
      "y": 32,
      "z": -16,
      "name": "Rock_Sandstone_Red"
    },
    {
      "x": -11,
      "y": 33,
      "z": -16,
      "name": "Rock_Sandstone"
    },
    {
      "x": -11,
      "y": 34,
      "z": -16,
      "name": "Rock_Sandstone_White"
    },
    {
      "x": -11,
      "y": 35,
      "z": -16,
      "name": "Rock_Sandstone_White"
    },
    {
      "x": -11,
      "y": 36,
      "z": -16,
      "name": "Rock_Sandstone_White"
    },
    {
      "x": -11,
      "y": 37,
      "z": -16,
      "name": "Soil_Sand_Red"
    },
    {
      "x": -11,
      "y": 38,
      "z": -16,
      "name": "Soil_Sand_Red"
    },
    {
      "x": -11,
      "y": 6,
      "z": -15,
      "name": "Rock_Sandstone"
    },
    {
      "x": -11,
      "y": 7,
      "z": -15,
      "name": "Rock_Sandstone"
    },
    {
      "x": -11,
      "y": 8,
      "z": -15,
      "name": "Rock_Sandstone"
    },
    {
      "x": -11,
      "y": 9,
      "z": -15,
      "name": "Rock_Sandstone"
    },
    {
      "x": -11,
      "y": 10,
      "z": -15,
      "name": "Rock_Sandstone"
    },
    {
      "x": -11,
      "y": 11,
      "z": -15,
      "name": "Rock_Sandstone"
    },
    {
      "x": -11,
      "y": 12,
      "z": -15,
      "name": "Rock_Sandstone"
    },
    {
      "x": -11,
      "y": 13,
      "z": -15,
      "name": "Rock_Sandstone"
    },
    {
      "x": -11,
      "y": 14,
      "z": -15,
      "name": "Soil_Clay"
    },
    {
      "x": -11,
      "y": 15,
      "z": -15,
      "name": "Soil_Clay"
    },
    {
      "x": -11,
      "y": 16,
      "z": -15,
      "name": "Soil_Clay"
    },
    {
      "x": -11,
      "y": 17,
      "z": -15,
      "name": "Rock_Sandstone_Red"
    },
    {
      "x": -11,
      "y": 18,
      "z": -15,
      "name": "Rock_Sandstone_Red"
    },
    {
      "x": -11,
      "y": 19,
      "z": -15,
      "name": "Rock_Sandstone"
    },
    {
      "x": -11,
      "y": 20,
      "z": -15,
      "name": "Rock_Sandstone"
    },
    {
      "x": -11,
      "y": 21,
      "z": -15,
      "name": "Soil_Clay"
    },
    {
      "x": -11,
      "y": 22,
      "z": -15,
      "name": "Soil_Clay"
    },
    {
      "x": -11,
      "y": 23,
      "z": -15,
      "name": "Soil_Dirt_Dry"
    },
    {
      "x": -11,
      "y": 24,
      "z": -15,
      "name": "Soil_Dirt_Dry"
    },
    {
      "x": -11,
      "y": 25,
      "z": -15,
      "name": "Soil_Dirt_Dry"
    },
    {
      "x": -11,
      "y": 26,
      "z": -15,
      "name": "Soil_Dirt_Dry"
    },
    {
      "x": -11,
      "y": 27,
      "z": -15,
      "name": "Rock_Sandstone"
    },
    {
      "x": -11,
      "y": 28,
      "z": -15,
      "name": "Rock_Sandstone"
    },
    {
      "x": -11,
      "y": 29,
      "z": -15,
      "name": "Soil_Clay"
    },
    {
      "x": -11,
      "y": 30,
      "z": -15,
      "name": "Rock_Sandstone_Red"
    },
    {
      "x": -11,
      "y": 31,
      "z": -15,
      "name": "Rock_Sandstone_Red"
    },
    {
      "x": -11,
      "y": 32,
      "z": -15,
      "name": "Rock_Sandstone_Red"
    },
    {
      "x": -11,
      "y": 33,
      "z": -15,
      "name": "Rock_Sandstone_Red"
    },
    {
      "x": -11,
      "y": 34,
      "z": -15,
      "name": "Rock_Sandstone"
    },
    {
      "x": -11,
      "y": 35,
      "z": -15,
      "name": "Rock_Sandstone_White"
    },
    {
      "x": -11,
      "y": 36,
      "z": -15,
      "name": "Rock_Sandstone_White"
    },
    {
      "x": -11,
      "y": 37,
      "z": -15,
      "name": "Soil_Sand_Red"
    },
    {
      "x": -11,
      "y": 38,
      "z": -15,
      "name": "Soil_Sand_Red"
    },
    {
      "x": -11,
      "y": 6,
      "z": -14,
      "name": "Rock_Sandstone"
    },
    {
      "x": -11,
      "y": 7,
      "z": -14,
      "name": "Rock_Sandstone"
    },
    {
      "x": -11,
      "y": 8,
      "z": -14,
      "name": "Rock_Sandstone"
    },
    {
      "x": -11,
      "y": 9,
      "z": -14,
      "name": "Rock_Sandstone"
    },
    {
      "x": -11,
      "y": 10,
      "z": -14,
      "name": "Rock_Sandstone"
    },
    {
      "x": -11,
      "y": 11,
      "z": -14,
      "name": "Rock_Sandstone"
    },
    {
      "x": -11,
      "y": 12,
      "z": -14,
      "name": "Rock_Sandstone"
    },
    {
      "x": -11,
      "y": 13,
      "z": -14,
      "name": "Rock_Sandstone"
    },
    {
      "x": -11,
      "y": 14,
      "z": -14,
      "name": "Soil_Clay"
    },
    {
      "x": -11,
      "y": 15,
      "z": -14,
      "name": "Soil_Clay"
    },
    {
      "x": -11,
      "y": 16,
      "z": -14,
      "name": "Soil_Clay"
    },
    {
      "x": -11,
      "y": 17,
      "z": -14,
      "name": "Rock_Sandstone_Red"
    },
    {
      "x": -11,
      "y": 18,
      "z": -14,
      "name": "Rock_Sandstone_Red"
    },
    {
      "x": -11,
      "y": 19,
      "z": -14,
      "name": "Rock_Sandstone"
    },
    {
      "x": -11,
      "y": 20,
      "z": -14,
      "name": "Rock_Sandstone"
    },
    {
      "x": -11,
      "y": 21,
      "z": -14,
      "name": "Soil_Clay"
    },
    {
      "x": -11,
      "y": 22,
      "z": -14,
      "name": "Soil_Clay"
    },
    {
      "x": -11,
      "y": 23,
      "z": -14,
      "name": "Soil_Dirt_Dry"
    },
    {
      "x": -11,
      "y": 24,
      "z": -14,
      "name": "Soil_Dirt_Dry"
    },
    {
      "x": -11,
      "y": 25,
      "z": -14,
      "name": "Soil_Dirt_Dry"
    },
    {
      "x": -11,
      "y": 26,
      "z": -14,
      "name": "Soil_Dirt_Dry"
    },
    {
      "x": -11,
      "y": 27,
      "z": -14,
      "name": "Rock_Sandstone"
    },
    {
      "x": -11,
      "y": 28,
      "z": -14,
      "name": "Rock_Sandstone"
    },
    {
      "x": -11,
      "y": 29,
      "z": -14,
      "name": "Soil_Clay"
    },
    {
      "x": -11,
      "y": 30,
      "z": -14,
      "name": "Rock_Sandstone_Red"
    },
    {
      "x": -11,
      "y": 31,
      "z": -14,
      "name": "Rock_Sandstone_Red"
    },
    {
      "x": -11,
      "y": 32,
      "z": -14,
      "name": "Rock_Sandstone_Red"
    },
    {
      "x": -11,
      "y": 33,
      "z": -14,
      "name": "Rock_Sandstone_Red"
    },
    {
      "x": -11,
      "y": 34,
      "z": -14,
      "name": "Rock_Sandstone"
    },
    {
      "x": -11,
      "y": 35,
      "z": -14,
      "name": "Soil_Sand_Red"
    },
    {
      "x": -11,
      "y": 36,
      "z": -14,
      "name": "Soil_Sand_Red"
    },
    {
      "x": -11,
      "y": 8,
      "z": -13,
      "name": "Rock_Sandstone"
    },
    {
      "x": -11,
      "y": 9,
      "z": -13,
      "name": "Rock_Sandstone"
    },
    {
      "x": -11,
      "y": 10,
      "z": -13,
      "name": "Rock_Sandstone"
    },
    {
      "x": -11,
      "y": 11,
      "z": -13,
      "name": "Rock_Sandstone"
    },
    {
      "x": -11,
      "y": 12,
      "z": -13,
      "name": "Rock_Sandstone"
    },
    {
      "x": -11,
      "y": 13,
      "z": -13,
      "name": "Rock_Sandstone"
    },
    {
      "x": -11,
      "y": 14,
      "z": -13,
      "name": "Soil_Clay"
    },
    {
      "x": -11,
      "y": 15,
      "z": -13,
      "name": "Soil_Clay"
    },
    {
      "x": -11,
      "y": 16,
      "z": -13,
      "name": "Soil_Clay"
    },
    {
      "x": -11,
      "y": 17,
      "z": -13,
      "name": "Rock_Sandstone_Red"
    },
    {
      "x": -11,
      "y": 18,
      "z": -13,
      "name": "Rock_Sandstone_Red"
    },
    {
      "x": -11,
      "y": 19,
      "z": -13,
      "name": "Rock_Sandstone"
    },
    {
      "x": -11,
      "y": 20,
      "z": -13,
      "name": "Rock_Sandstone"
    },
    {
      "x": -11,
      "y": 21,
      "z": -13,
      "name": "Soil_Clay"
    },
    {
      "x": -11,
      "y": 22,
      "z": -13,
      "name": "Soil_Clay"
    },
    {
      "x": -11,
      "y": 23,
      "z": -13,
      "name": "Soil_Dirt_Dry"
    },
    {
      "x": -11,
      "y": 24,
      "z": -13,
      "name": "Soil_Dirt_Dry"
    },
    {
      "x": -11,
      "y": 25,
      "z": -13,
      "name": "Soil_Dirt_Dry"
    },
    {
      "x": -11,
      "y": 26,
      "z": -13,
      "name": "Soil_Dirt_Dry"
    },
    {
      "x": -11,
      "y": 27,
      "z": -13,
      "name": "Rock_Sandstone"
    },
    {
      "x": -11,
      "y": 28,
      "z": -13,
      "name": "Rock_Sandstone"
    },
    {
      "x": -11,
      "y": 29,
      "z": -13,
      "name": "Rock_Sandstone"
    },
    {
      "x": -11,
      "y": 30,
      "z": -13,
      "name": "Soil_Clay"
    },
    {
      "x": -11,
      "y": 31,
      "z": -13,
      "name": "Rock_Sandstone_Red"
    },
    {
      "x": -11,
      "y": 32,
      "z": -13,
      "name": "Rock_Sandstone_Red"
    },
    {
      "x": -11,
      "y": 33,
      "z": -13,
      "name": "Rock_Sandstone_Red"
    },
    {
      "x": -11,
      "y": 34,
      "z": -13,
      "name": "Rock_Sandstone"
    },
    {
      "x": -11,
      "y": 35,
      "z": -13,
      "name": "Soil_Sand_Red"
    },
    {
      "x": -11,
      "y": 36,
      "z": -13,
      "name": "Soil_Sand_Red"
    },
    {
      "x": -11,
      "y": 14,
      "z": 5,
      "name": "Rock_Sandstone"
    },
    {
      "x": -11,
      "y": 15,
      "z": 5,
      "name": "Rock_Sandstone"
    },
    {
      "x": -11,
      "y": 16,
      "z": 5,
      "name": "Soil_Clay"
    },
    {
      "x": -11,
      "y": 17,
      "z": 5,
      "name": "Rock_Sandstone_Red"
    },
    {
      "x": -11,
      "y": 18,
      "z": 5,
      "name": "Rock_Sandstone_Red"
    },
    {
      "x": -11,
      "y": 11,
      "z": 6,
      "name": "Rock_Sandstone"
    },
    {
      "x": -11,
      "y": 12,
      "z": 6,
      "name": "Rock_Sandstone"
    },
    {
      "x": -11,
      "y": 13,
      "z": 6,
      "name": "Rock_Sandstone"
    },
    {
      "x": -11,
      "y": 14,
      "z": 6,
      "name": "Rock_Sandstone"
    },
    {
      "x": -11,
      "y": 15,
      "z": 6,
      "name": "Rock_Sandstone"
    },
    {
      "x": -11,
      "y": 16,
      "z": 6,
      "name": "Soil_Clay"
    },
    {
      "x": -11,
      "y": 17,
      "z": 6,
      "name": "Rock_Sandstone_Red"
    },
    {
      "x": -11,
      "y": 18,
      "z": 6,
      "name": "Rock_Sandstone_Red"
    },
    {
      "x": -11,
      "y": 19,
      "z": 6,
      "name": "Rock_Sandstone_Red"
    },
    {
      "x": -11,
      "y": 20,
      "z": 6,
      "name": "Rock_Sandstone_Red"
    },
    {
      "x": -11,
      "y": 21,
      "z": 6,
      "name": "Rock_Sandstone"
    },
    {
      "x": -11,
      "y": 22,
      "z": 6,
      "name": "Rock_Sandstone"
    },
    {
      "x": -11,
      "y": 9,
      "z": 7,
      "name": "Rock_Sandstone"
    },
    {
      "x": -11,
      "y": 10,
      "z": 7,
      "name": "Rock_Sandstone"
    },
    {
      "x": -11,
      "y": 11,
      "z": 7,
      "name": "Rock_Sandstone"
    },
    {
      "x": -11,
      "y": 12,
      "z": 7,
      "name": "Rock_Sandstone"
    },
    {
      "x": -11,
      "y": 13,
      "z": 7,
      "name": "Rock_Sandstone"
    },
    {
      "x": -11,
      "y": 14,
      "z": 7,
      "name": "Rock_Sandstone"
    },
    {
      "x": -11,
      "y": 15,
      "z": 7,
      "name": "Rock_Sandstone"
    },
    {
      "x": -11,
      "y": 16,
      "z": 7,
      "name": "Soil_Clay"
    },
    {
      "x": -11,
      "y": 17,
      "z": 7,
      "name": "Rock_Sandstone_Red"
    },
    {
      "x": -11,
      "y": 18,
      "z": 7,
      "name": "Rock_Sandstone_Red"
    },
    {
      "x": -11,
      "y": 19,
      "z": 7,
      "name": "Rock_Sandstone_Red"
    },
    {
      "x": -11,
      "y": 20,
      "z": 7,
      "name": "Rock_Sandstone_Red"
    },
    {
      "x": -11,
      "y": 21,
      "z": 7,
      "name": "Rock_Sandstone"
    },
    {
      "x": -11,
      "y": 22,
      "z": 7,
      "name": "Rock_Sandstone"
    },
    {
      "x": -11,
      "y": 23,
      "z": 7,
      "name": "Rock_Sandstone"
    },
    {
      "x": -11,
      "y": 24,
      "z": 7,
      "name": "Soil_Clay"
    },
    {
      "x": -11,
      "y": 25,
      "z": 7,
      "name": "Soil_Clay"
    },
    {
      "x": -11,
      "y": 8,
      "z": 8,
      "name": "Rock_Sandstone"
    },
    {
      "x": -11,
      "y": 9,
      "z": 8,
      "name": "Rock_Sandstone"
    },
    {
      "x": -11,
      "y": 10,
      "z": 8,
      "name": "Rock_Sandstone"
    },
    {
      "x": -11,
      "y": 11,
      "z": 8,
      "name": "Rock_Sandstone"
    },
    {
      "x": -11,
      "y": 12,
      "z": 8,
      "name": "Rock_Sandstone"
    },
    {
      "x": -11,
      "y": 13,
      "z": 8,
      "name": "Rock_Sandstone"
    },
    {
      "x": -11,
      "y": 14,
      "z": 8,
      "name": "Rock_Sandstone"
    },
    {
      "x": -11,
      "y": 15,
      "z": 8,
      "name": "Rock_Sandstone"
    },
    {
      "x": -11,
      "y": 16,
      "z": 8,
      "name": "Soil_Clay"
    },
    {
      "x": -11,
      "y": 17,
      "z": 8,
      "name": "Rock_Sandstone_Red"
    },
    {
      "x": -11,
      "y": 18,
      "z": 8,
      "name": "Rock_Sandstone_Red"
    },
    {
      "x": -11,
      "y": 19,
      "z": 8,
      "name": "Rock_Sandstone_Red"
    },
    {
      "x": -11,
      "y": 20,
      "z": 8,
      "name": "Rock_Sandstone_Red"
    },
    {
      "x": -11,
      "y": 21,
      "z": 8,
      "name": "Rock_Sandstone"
    },
    {
      "x": -11,
      "y": 22,
      "z": 8,
      "name": "Rock_Sandstone"
    },
    {
      "x": -11,
      "y": 23,
      "z": 8,
      "name": "Rock_Sandstone"
    },
    {
      "x": -11,
      "y": 24,
      "z": 8,
      "name": "Soil_Clay"
    },
    {
      "x": -11,
      "y": 25,
      "z": 8,
      "name": "Soil_Clay"
    },
    {
      "x": -11,
      "y": 8,
      "z": 9,
      "name": "Rock_Sandstone"
    },
    {
      "x": -11,
      "y": 9,
      "z": 9,
      "name": "Rock_Sandstone"
    },
    {
      "x": -11,
      "y": 10,
      "z": 9,
      "name": "Rock_Sandstone"
    },
    {
      "x": -11,
      "y": 11,
      "z": 9,
      "name": "Rock_Sandstone"
    },
    {
      "x": -11,
      "y": 12,
      "z": 9,
      "name": "Rock_Sandstone"
    },
    {
      "x": -11,
      "y": 13,
      "z": 9,
      "name": "Rock_Sandstone"
    },
    {
      "x": -11,
      "y": 14,
      "z": 9,
      "name": "Rock_Sandstone"
    },
    {
      "x": -11,
      "y": 15,
      "z": 9,
      "name": "Rock_Sandstone"
    },
    {
      "x": -11,
      "y": 16,
      "z": 9,
      "name": "Soil_Clay"
    },
    {
      "x": -11,
      "y": 17,
      "z": 9,
      "name": "Rock_Sandstone_Red"
    },
    {
      "x": -11,
      "y": 18,
      "z": 9,
      "name": "Rock_Sandstone_Red"
    },
    {
      "x": -11,
      "y": 19,
      "z": 9,
      "name": "Rock_Sandstone_Red"
    },
    {
      "x": -11,
      "y": 20,
      "z": 9,
      "name": "Rock_Sandstone_Red"
    },
    {
      "x": -11,
      "y": 21,
      "z": 9,
      "name": "Rock_Sandstone"
    },
    {
      "x": -11,
      "y": 22,
      "z": 9,
      "name": "Rock_Sandstone"
    },
    {
      "x": -11,
      "y": 23,
      "z": 9,
      "name": "Rock_Sandstone"
    },
    {
      "x": -11,
      "y": 24,
      "z": 9,
      "name": "Soil_Clay"
    },
    {
      "x": -11,
      "y": 25,
      "z": 9,
      "name": "Soil_Clay"
    },
    {
      "x": -11,
      "y": 8,
      "z": 10,
      "name": "Rock_Sandstone"
    },
    {
      "x": -11,
      "y": 9,
      "z": 10,
      "name": "Rock_Sandstone"
    },
    {
      "x": -11,
      "y": 10,
      "z": 10,
      "name": "Rock_Sandstone"
    },
    {
      "x": -11,
      "y": 11,
      "z": 10,
      "name": "Rock_Sandstone"
    },
    {
      "x": -11,
      "y": 12,
      "z": 10,
      "name": "Rock_Sandstone"
    },
    {
      "x": -11,
      "y": 13,
      "z": 10,
      "name": "Rock_Sandstone"
    },
    {
      "x": -11,
      "y": 14,
      "z": 10,
      "name": "Rock_Sandstone"
    },
    {
      "x": -11,
      "y": 15,
      "z": 10,
      "name": "Rock_Sandstone"
    },
    {
      "x": -11,
      "y": 16,
      "z": 10,
      "name": "Soil_Clay"
    },
    {
      "x": -11,
      "y": 17,
      "z": 10,
      "name": "Rock_Sandstone_Red"
    },
    {
      "x": -11,
      "y": 18,
      "z": 10,
      "name": "Rock_Sandstone_Red"
    },
    {
      "x": -11,
      "y": 19,
      "z": 10,
      "name": "Rock_Sandstone_Red"
    },
    {
      "x": -11,
      "y": 20,
      "z": 10,
      "name": "Rock_Sandstone_Red"
    },
    {
      "x": -11,
      "y": 21,
      "z": 10,
      "name": "Rock_Sandstone"
    },
    {
      "x": -11,
      "y": 22,
      "z": 10,
      "name": "Rock_Sandstone"
    },
    {
      "x": -11,
      "y": 23,
      "z": 10,
      "name": "Rock_Sandstone"
    },
    {
      "x": -11,
      "y": 24,
      "z": 10,
      "name": "Soil_Clay"
    },
    {
      "x": -11,
      "y": 25,
      "z": 10,
      "name": "Soil_Clay"
    },
    {
      "x": -11,
      "y": 8,
      "z": 11,
      "name": "Rock_Sandstone"
    },
    {
      "x": -11,
      "y": 9,
      "z": 11,
      "name": "Rock_Sandstone"
    },
    {
      "x": -11,
      "y": 10,
      "z": 11,
      "name": "Rock_Sandstone"
    },
    {
      "x": -11,
      "y": 11,
      "z": 11,
      "name": "Rock_Sandstone"
    },
    {
      "x": -11,
      "y": 12,
      "z": 11,
      "name": "Rock_Sandstone"
    },
    {
      "x": -11,
      "y": 13,
      "z": 11,
      "name": "Rock_Sandstone"
    },
    {
      "x": -11,
      "y": 14,
      "z": 11,
      "name": "Rock_Sandstone"
    },
    {
      "x": -11,
      "y": 15,
      "z": 11,
      "name": "Rock_Sandstone"
    },
    {
      "x": -11,
      "y": 16,
      "z": 11,
      "name": "Soil_Clay"
    },
    {
      "x": -11,
      "y": 17,
      "z": 11,
      "name": "Rock_Sandstone_Red"
    },
    {
      "x": -11,
      "y": 18,
      "z": 11,
      "name": "Rock_Sandstone_Red"
    },
    {
      "x": -11,
      "y": 19,
      "z": 11,
      "name": "Rock_Sandstone_Red"
    },
    {
      "x": -11,
      "y": 20,
      "z": 11,
      "name": "Rock_Sandstone_Red"
    },
    {
      "x": -11,
      "y": 21,
      "z": 11,
      "name": "Rock_Sandstone"
    },
    {
      "x": -11,
      "y": 22,
      "z": 11,
      "name": "Rock_Sandstone"
    },
    {
      "x": -11,
      "y": 23,
      "z": 11,
      "name": "Rock_Sandstone"
    },
    {
      "x": -11,
      "y": 24,
      "z": 11,
      "name": "Soil_Clay"
    },
    {
      "x": -11,
      "y": 25,
      "z": 11,
      "name": "Soil_Clay"
    },
    {
      "x": -11,
      "y": 9,
      "z": 12,
      "name": "Rock_Sandstone"
    },
    {
      "x": -11,
      "y": 10,
      "z": 12,
      "name": "Rock_Sandstone"
    },
    {
      "x": -11,
      "y": 11,
      "z": 12,
      "name": "Rock_Sandstone"
    },
    {
      "x": -11,
      "y": 12,
      "z": 12,
      "name": "Rock_Sandstone"
    },
    {
      "x": -11,
      "y": 13,
      "z": 12,
      "name": "Rock_Sandstone"
    },
    {
      "x": -11,
      "y": 14,
      "z": 12,
      "name": "Rock_Sandstone"
    },
    {
      "x": -11,
      "y": 15,
      "z": 12,
      "name": "Rock_Sandstone"
    },
    {
      "x": -11,
      "y": 16,
      "z": 12,
      "name": "Soil_Clay"
    },
    {
      "x": -11,
      "y": 17,
      "z": 12,
      "name": "Rock_Sandstone_Red"
    },
    {
      "x": -11,
      "y": 18,
      "z": 12,
      "name": "Rock_Sandstone_Red"
    },
    {
      "x": -11,
      "y": 19,
      "z": 12,
      "name": "Rock_Sandstone_Red"
    },
    {
      "x": -11,
      "y": 20,
      "z": 12,
      "name": "Rock_Sandstone_Red"
    },
    {
      "x": -11,
      "y": 21,
      "z": 12,
      "name": "Rock_Sandstone_Red"
    },
    {
      "x": -11,
      "y": 22,
      "z": 12,
      "name": "Rock_Sandstone"
    },
    {
      "x": -11,
      "y": 23,
      "z": 12,
      "name": "Rock_Sandstone"
    },
    {
      "x": -11,
      "y": 24,
      "z": 12,
      "name": "Soil_Clay"
    },
    {
      "x": -11,
      "y": 25,
      "z": 12,
      "name": "Soil_Clay"
    },
    {
      "x": -11,
      "y": 9,
      "z": 13,
      "name": "Rock_Sandstone"
    },
    {
      "x": -11,
      "y": 10,
      "z": 13,
      "name": "Rock_Sandstone"
    },
    {
      "x": -11,
      "y": 11,
      "z": 13,
      "name": "Rock_Sandstone"
    },
    {
      "x": -11,
      "y": 12,
      "z": 13,
      "name": "Rock_Sandstone"
    },
    {
      "x": -11,
      "y": 13,
      "z": 13,
      "name": "Rock_Sandstone"
    },
    {
      "x": -11,
      "y": 14,
      "z": 13,
      "name": "Rock_Sandstone"
    },
    {
      "x": -11,
      "y": 15,
      "z": 13,
      "name": "Rock_Sandstone"
    },
    {
      "x": -11,
      "y": 16,
      "z": 13,
      "name": "Rock_Sandstone"
    },
    {
      "x": -11,
      "y": 17,
      "z": 13,
      "name": "Rock_Sandstone_Red"
    },
    {
      "x": -11,
      "y": 18,
      "z": 13,
      "name": "Rock_Sandstone_Red"
    },
    {
      "x": -11,
      "y": 19,
      "z": 13,
      "name": "Rock_Sandstone_Red"
    },
    {
      "x": -11,
      "y": 20,
      "z": 13,
      "name": "Rock_Sandstone_Red"
    },
    {
      "x": -11,
      "y": 21,
      "z": 13,
      "name": "Rock_Sandstone_Red"
    },
    {
      "x": -11,
      "y": 22,
      "z": 13,
      "name": "Rock_Sandstone"
    },
    {
      "x": -11,
      "y": 23,
      "z": 13,
      "name": "Rock_Sandstone"
    },
    {
      "x": -11,
      "y": 24,
      "z": 13,
      "name": "Soil_Clay"
    },
    {
      "x": -11,
      "y": 9,
      "z": 14,
      "name": "Rock_Sandstone"
    },
    {
      "x": -11,
      "y": 10,
      "z": 14,
      "name": "Rock_Sandstone"
    },
    {
      "x": -11,
      "y": 11,
      "z": 14,
      "name": "Rock_Sandstone"
    },
    {
      "x": -11,
      "y": 12,
      "z": 14,
      "name": "Rock_Sandstone"
    },
    {
      "x": -11,
      "y": 13,
      "z": 14,
      "name": "Rock_Sandstone"
    },
    {
      "x": -11,
      "y": 14,
      "z": 14,
      "name": "Rock_Sandstone"
    },
    {
      "x": -11,
      "y": 15,
      "z": 14,
      "name": "Rock_Sandstone"
    },
    {
      "x": -11,
      "y": 16,
      "z": 14,
      "name": "Rock_Sandstone"
    },
    {
      "x": -11,
      "y": 17,
      "z": 14,
      "name": "Rock_Sandstone_Red"
    },
    {
      "x": -11,
      "y": 18,
      "z": 14,
      "name": "Rock_Sandstone_Red"
    },
    {
      "x": -11,
      "y": 19,
      "z": 14,
      "name": "Soil_Clay"
    },
    {
      "x": -11,
      "y": 20,
      "z": 14,
      "name": "Rock_Sandstone_Red"
    },
    {
      "x": -11,
      "y": 21,
      "z": 14,
      "name": "Rock_Sandstone_Red"
    },
    {
      "x": -11,
      "y": 22,
      "z": 14,
      "name": "Rock_Sandstone"
    },
    {
      "x": -11,
      "y": 23,
      "z": 14,
      "name": "Rock_Sandstone"
    },
    {
      "x": -11,
      "y": 24,
      "z": 14,
      "name": "Soil_Clay"
    },
    {
      "x": -11,
      "y": 10,
      "z": 15,
      "name": "Rock_Sandstone"
    },
    {
      "x": -11,
      "y": 11,
      "z": 15,
      "name": "Rock_Sandstone"
    },
    {
      "x": -11,
      "y": 12,
      "z": 15,
      "name": "Rock_Sandstone"
    },
    {
      "x": -11,
      "y": 13,
      "z": 15,
      "name": "Rock_Sandstone"
    },
    {
      "x": -11,
      "y": 14,
      "z": 15,
      "name": "Rock_Sandstone"
    },
    {
      "x": -11,
      "y": 15,
      "z": 15,
      "name": "Rock_Sandstone"
    },
    {
      "x": -11,
      "y": 16,
      "z": 15,
      "name": "Rock_Sandstone"
    },
    {
      "x": -11,
      "y": 17,
      "z": 15,
      "name": "Soil_Clay"
    },
    {
      "x": -11,
      "y": 18,
      "z": 15,
      "name": "Rock_Sandstone_Red"
    },
    {
      "x": -11,
      "y": 19,
      "z": 15,
      "name": "Soil_Clay"
    },
    {
      "x": -11,
      "y": 20,
      "z": 15,
      "name": "Rock_Sandstone_Red"
    },
    {
      "x": -11,
      "y": 21,
      "z": 15,
      "name": "Rock_Sandstone_Red"
    },
    {
      "x": -11,
      "y": 22,
      "z": 15,
      "name": "Rock_Sandstone"
    },
    {
      "x": -11,
      "y": 23,
      "z": 15,
      "name": "Rock_Sandstone"
    },
    {
      "x": -11,
      "y": 24,
      "z": 15,
      "name": "Rock_Sandstone"
    },
    {
      "x": -11,
      "y": 13,
      "z": 16,
      "name": "Rock_Sandstone"
    },
    {
      "x": -11,
      "y": 14,
      "z": 16,
      "name": "Rock_Sandstone"
    },
    {
      "x": -11,
      "y": 15,
      "z": 16,
      "name": "Rock_Sandstone"
    },
    {
      "x": -11,
      "y": 16,
      "z": 16,
      "name": "Rock_Sandstone"
    },
    {
      "x": -11,
      "y": 17,
      "z": 16,
      "name": "Soil_Clay"
    },
    {
      "x": -11,
      "y": 18,
      "z": 16,
      "name": "Rock_Sandstone_Red"
    },
    {
      "x": -11,
      "y": 19,
      "z": 16,
      "name": "Soil_Clay"
    },
    {
      "x": -11,
      "y": 20,
      "z": 16,
      "name": "Rock_Sandstone_Red"
    },
    {
      "x": -11,
      "y": 21,
      "z": 16,
      "name": "Rock_Sandstone_Red"
    },
    {
      "x": -11,
      "y": 22,
      "z": 16,
      "name": "Rock_Sandstone"
    },
    {
      "x": -10,
      "y": 8,
      "z": -23,
      "name": "Rock_Sandstone"
    },
    {
      "x": -10,
      "y": 9,
      "z": -23,
      "name": "Rock_Sandstone"
    },
    {
      "x": -10,
      "y": 10,
      "z": -23,
      "name": "Rock_Sandstone"
    },
    {
      "x": -10,
      "y": 11,
      "z": -23,
      "name": "Rock_Sandstone"
    },
    {
      "x": -10,
      "y": 12,
      "z": -23,
      "name": "Rock_Sandstone"
    },
    {
      "x": -10,
      "y": 13,
      "z": -23,
      "name": "Rock_Sandstone"
    },
    {
      "x": -10,
      "y": 14,
      "z": -23,
      "name": "Soil_Clay"
    },
    {
      "x": -10,
      "y": 15,
      "z": -23,
      "name": "Soil_Clay"
    },
    {
      "x": -10,
      "y": 16,
      "z": -23,
      "name": "Soil_Clay"
    },
    {
      "x": -10,
      "y": 17,
      "z": -23,
      "name": "Rock_Sandstone_Red"
    },
    {
      "x": -10,
      "y": 18,
      "z": -23,
      "name": "Rock_Sandstone_Red"
    },
    {
      "x": -10,
      "y": 19,
      "z": -23,
      "name": "Rock_Sandstone"
    },
    {
      "x": -10,
      "y": 20,
      "z": -23,
      "name": "Soil_Clay"
    },
    {
      "x": -10,
      "y": 21,
      "z": -23,
      "name": "Soil_Clay"
    },
    {
      "x": -10,
      "y": 22,
      "z": -23,
      "name": "Soil_Dirt_Dry"
    },
    {
      "x": -10,
      "y": 5,
      "z": -22,
      "name": "Rock_Sandstone"
    },
    {
      "x": -10,
      "y": 6,
      "z": -22,
      "name": "Rock_Sandstone"
    },
    {
      "x": -10,
      "y": 7,
      "z": -22,
      "name": "Rock_Sandstone"
    },
    {
      "x": -10,
      "y": 8,
      "z": -22,
      "name": "Rock_Sandstone"
    },
    {
      "x": -10,
      "y": 9,
      "z": -22,
      "name": "Rock_Sandstone"
    },
    {
      "x": -10,
      "y": 10,
      "z": -22,
      "name": "Rock_Sandstone"
    },
    {
      "x": -10,
      "y": 11,
      "z": -22,
      "name": "Rock_Sandstone"
    },
    {
      "x": -10,
      "y": 12,
      "z": -22,
      "name": "Rock_Sandstone"
    },
    {
      "x": -10,
      "y": 13,
      "z": -22,
      "name": "Rock_Sandstone"
    },
    {
      "x": -10,
      "y": 14,
      "z": -22,
      "name": "Soil_Clay"
    },
    {
      "x": -10,
      "y": 15,
      "z": -22,
      "name": "Soil_Clay"
    },
    {
      "x": -10,
      "y": 16,
      "z": -22,
      "name": "Soil_Clay"
    },
    {
      "x": -10,
      "y": 17,
      "z": -22,
      "name": "Rock_Sandstone_Red"
    },
    {
      "x": -10,
      "y": 18,
      "z": -22,
      "name": "Rock_Sandstone_Red"
    },
    {
      "x": -10,
      "y": 19,
      "z": -22,
      "name": "Rock_Sandstone"
    },
    {
      "x": -10,
      "y": 20,
      "z": -22,
      "name": "Soil_Clay"
    },
    {
      "x": -10,
      "y": 21,
      "z": -22,
      "name": "Soil_Clay"
    },
    {
      "x": -10,
      "y": 22,
      "z": -22,
      "name": "Soil_Dirt_Dry"
    },
    {
      "x": -10,
      "y": 23,
      "z": -22,
      "name": "Soil_Dirt_Dry"
    },
    {
      "x": -10,
      "y": 24,
      "z": -22,
      "name": "Soil_Dirt_Dry"
    },
    {
      "x": -10,
      "y": 25,
      "z": -22,
      "name": "Rock_Sandstone"
    },
    {
      "x": -10,
      "y": 26,
      "z": -22,
      "name": "Rock_Sandstone"
    },
    {
      "x": -10,
      "y": 5,
      "z": -21,
      "name": "Rock_Sandstone"
    },
    {
      "x": -10,
      "y": 6,
      "z": -21,
      "name": "Rock_Sandstone"
    },
    {
      "x": -10,
      "y": 7,
      "z": -21,
      "name": "Rock_Sandstone"
    },
    {
      "x": -10,
      "y": 8,
      "z": -21,
      "name": "Rock_Sandstone"
    },
    {
      "x": -10,
      "y": 9,
      "z": -21,
      "name": "Rock_Sandstone"
    },
    {
      "x": -10,
      "y": 10,
      "z": -21,
      "name": "Rock_Sandstone"
    },
    {
      "x": -10,
      "y": 11,
      "z": -21,
      "name": "Rock_Sandstone"
    },
    {
      "x": -10,
      "y": 12,
      "z": -21,
      "name": "Rock_Sandstone"
    },
    {
      "x": -10,
      "y": 13,
      "z": -21,
      "name": "Rock_Sandstone"
    },
    {
      "x": -10,
      "y": 14,
      "z": -21,
      "name": "Soil_Clay"
    },
    {
      "x": -10,
      "y": 15,
      "z": -21,
      "name": "Soil_Clay"
    },
    {
      "x": -10,
      "y": 16,
      "z": -21,
      "name": "Soil_Clay"
    },
    {
      "x": -10,
      "y": 17,
      "z": -21,
      "name": "Rock_Sandstone_Red"
    },
    {
      "x": -10,
      "y": 18,
      "z": -21,
      "name": "Rock_Sandstone_Red"
    },
    {
      "x": -10,
      "y": 19,
      "z": -21,
      "name": "Rock_Sandstone"
    },
    {
      "x": -10,
      "y": 20,
      "z": -21,
      "name": "Soil_Clay"
    },
    {
      "x": -10,
      "y": 21,
      "z": -21,
      "name": "Soil_Clay"
    },
    {
      "x": -10,
      "y": 22,
      "z": -21,
      "name": "Soil_Dirt_Dry"
    },
    {
      "x": -10,
      "y": 23,
      "z": -21,
      "name": "Soil_Dirt_Dry"
    },
    {
      "x": -10,
      "y": 24,
      "z": -21,
      "name": "Soil_Dirt_Dry"
    },
    {
      "x": -10,
      "y": 25,
      "z": -21,
      "name": "Rock_Sandstone"
    },
    {
      "x": -10,
      "y": 26,
      "z": -21,
      "name": "Rock_Sandstone"
    },
    {
      "x": -10,
      "y": 27,
      "z": -21,
      "name": "Soil_Clay"
    },
    {
      "x": -10,
      "y": 28,
      "z": -21,
      "name": "Soil_Clay"
    },
    {
      "x": -10,
      "y": 29,
      "z": -21,
      "name": "Rock_Sandstone_Red"
    },
    {
      "x": -10,
      "y": 30,
      "z": -21,
      "name": "Rock_Sandstone_Red"
    },
    {
      "x": -10,
      "y": 4,
      "z": -20,
      "name": "Rock_Sandstone"
    },
    {
      "x": -10,
      "y": 5,
      "z": -20,
      "name": "Rock_Sandstone"
    },
    {
      "x": -10,
      "y": 6,
      "z": -20,
      "name": "Rock_Sandstone"
    },
    {
      "x": -10,
      "y": 7,
      "z": -20,
      "name": "Rock_Sandstone"
    },
    {
      "x": -10,
      "y": 8,
      "z": -20,
      "name": "Rock_Sandstone"
    },
    {
      "x": -10,
      "y": 9,
      "z": -20,
      "name": "Rock_Sandstone"
    },
    {
      "x": -10,
      "y": 10,
      "z": -20,
      "name": "Rock_Sandstone"
    },
    {
      "x": -10,
      "y": 11,
      "z": -20,
      "name": "Rock_Sandstone"
    },
    {
      "x": -10,
      "y": 12,
      "z": -20,
      "name": "Rock_Sandstone"
    },
    {
      "x": -10,
      "y": 13,
      "z": -20,
      "name": "Rock_Sandstone"
    },
    {
      "x": -10,
      "y": 14,
      "z": -20,
      "name": "Soil_Clay"
    },
    {
      "x": -10,
      "y": 15,
      "z": -20,
      "name": "Soil_Clay"
    },
    {
      "x": -10,
      "y": 16,
      "z": -20,
      "name": "Soil_Clay"
    },
    {
      "x": -10,
      "y": 17,
      "z": -20,
      "name": "Rock_Sandstone_Red"
    },
    {
      "x": -10,
      "y": 18,
      "z": -20,
      "name": "Rock_Sandstone_Red"
    },
    {
      "x": -10,
      "y": 19,
      "z": -20,
      "name": "Rock_Sandstone"
    },
    {
      "x": -10,
      "y": 20,
      "z": -20,
      "name": "Soil_Clay"
    },
    {
      "x": -10,
      "y": 21,
      "z": -20,
      "name": "Soil_Clay"
    },
    {
      "x": -10,
      "y": 22,
      "z": -20,
      "name": "Soil_Clay"
    },
    {
      "x": -10,
      "y": 23,
      "z": -20,
      "name": "Soil_Dirt_Dry"
    },
    {
      "x": -10,
      "y": 24,
      "z": -20,
      "name": "Soil_Dirt_Dry"
    },
    {
      "x": -10,
      "y": 25,
      "z": -20,
      "name": "Rock_Sandstone"
    },
    {
      "x": -10,
      "y": 26,
      "z": -20,
      "name": "Rock_Sandstone"
    },
    {
      "x": -10,
      "y": 27,
      "z": -20,
      "name": "Soil_Clay"
    },
    {
      "x": -10,
      "y": 28,
      "z": -20,
      "name": "Soil_Clay"
    },
    {
      "x": -10,
      "y": 29,
      "z": -20,
      "name": "Rock_Sandstone_Red"
    },
    {
      "x": -10,
      "y": 30,
      "z": -20,
      "name": "Rock_Sandstone_Red"
    },
    {
      "x": -10,
      "y": 31,
      "z": -20,
      "name": "Rock_Sandstone_Red"
    },
    {
      "x": -10,
      "y": 32,
      "z": -20,
      "name": "Rock_Sandstone"
    },
    {
      "x": -10,
      "y": 33,
      "z": -20,
      "name": "Rock_Sandstone"
    },
    {
      "x": -10,
      "y": 34,
      "z": -20,
      "name": "Rock_Sandstone_White"
    },
    {
      "x": -10,
      "y": 35,
      "z": -20,
      "name": "Soil_Sand_Red"
    },
    {
      "x": -10,
      "y": 36,
      "z": -20,
      "name": "Soil_Sand_Red"
    },
    {
      "x": -10,
      "y": 4,
      "z": -19,
      "name": "Rock_Sandstone"
    },
    {
      "x": -10,
      "y": 5,
      "z": -19,
      "name": "Rock_Sandstone"
    },
    {
      "x": -10,
      "y": 6,
      "z": -19,
      "name": "Rock_Sandstone"
    },
    {
      "x": -10,
      "y": 7,
      "z": -19,
      "name": "Rock_Sandstone"
    },
    {
      "x": -10,
      "y": 8,
      "z": -19,
      "name": "Rock_Sandstone"
    },
    {
      "x": -10,
      "y": 9,
      "z": -19,
      "name": "Rock_Sandstone"
    },
    {
      "x": -10,
      "y": 10,
      "z": -19,
      "name": "Rock_Sandstone"
    },
    {
      "x": -10,
      "y": 11,
      "z": -19,
      "name": "Rock_Sandstone"
    },
    {
      "x": -10,
      "y": 12,
      "z": -19,
      "name": "Rock_Sandstone"
    },
    {
      "x": -10,
      "y": 13,
      "z": -19,
      "name": "Rock_Sandstone"
    },
    {
      "x": -10,
      "y": 14,
      "z": -19,
      "name": "Soil_Clay"
    },
    {
      "x": -10,
      "y": 15,
      "z": -19,
      "name": "Soil_Clay"
    },
    {
      "x": -10,
      "y": 16,
      "z": -19,
      "name": "Soil_Clay"
    },
    {
      "x": -10,
      "y": 17,
      "z": -19,
      "name": "Rock_Sandstone_Red"
    },
    {
      "x": -10,
      "y": 18,
      "z": -19,
      "name": "Rock_Sandstone_Red"
    },
    {
      "x": -10,
      "y": 19,
      "z": -19,
      "name": "Rock_Sandstone"
    },
    {
      "x": -10,
      "y": 20,
      "z": -19,
      "name": "Soil_Clay"
    },
    {
      "x": -10,
      "y": 21,
      "z": -19,
      "name": "Soil_Clay"
    },
    {
      "x": -10,
      "y": 22,
