{
  "version": 8,
  "blockIdVersion": 8,
  "anchorX": 0,
  "anchorY": 0,
  "anchorZ": 0,
  "blocks": [
    {
      "x": -5,
      "y": -3,
      "z": -10,
      "name": "Rock_Stone"
    },
    {
      "x": -5,
      "y": -2,
      "z": -10,
      "name": "Rock_Stone"
    },
    {
      "x": -5,
      "y": -1,
      "z": -10,
      "name": "Rock_Stone"
    },
    {
      "x": -5,
      "y": 0,
      "z": -10,
      "name": "Rock_Stone_Cobble"
    },
    {
      "x": -5,
      "y": 1,
      "z": -10,
      "name": "Rock_Quartzite_Brick"
    },
    {
      "x": -5,
      "y": 2,
      "z": -10,
      "name": "Rock_Quartzite_Brick"
    },
    {
      "x": -5,
      "y": 3,
      "z": -10,
      "name": "Rock_Quartzite_Brick"
    },
    {
      "x": -5,
      "y": 4,
      "z": -10,
      "name": "Rock_Quartzite"
    },
    {
      "x": -5,
      "y": 5,
      "z": -10,
      "name": "Rock_Quartzite"
    },
    {
      "x": -5,
      "y": 6,
      "z": -10,
      "name": "Rock_Quartzite"
    },
    {
      "x": -5,
      "y": 7,
      "z": -10,
      "name": "Rock_Quartzite"
    },
    {
      "x": -5,
      "y": 8,
      "z": -10,
      "name": "Rock_Quartzite"
    },
    {
      "x": -5,
      "y": 9,
      "z": -10,
      "name": "Rock_Quartzite"
    },
    {
      "x": -5,
      "y": 10,
      "z": -10,
      "name": "Rock_Quartzite"
    },
    {
      "x": -5,
      "y": -3,
      "z": -9,
      "name": "Rock_Stone"
    },
    {
      "x": -5,
      "y": -2,
      "z": -9,
      "name": "Rock_Stone"
    },
    {
      "x": -5,
      "y": -1,
      "z": -9,
      "name": "Rock_Stone"
    },
    {
      "x": -5,
      "y": 0,
      "z": -9,
      "name": "Rock_Stone_Cobble"
    },
    {
      "x": -5,
      "y": 1,
      "z": -9,
      "name": "Rock_Quartzite_Brick"
    },
    {
      "x": -5,
      "y": 2,
      "z": -9,
      "name": "Rock_Quartzite_Brick"
    },
    {
      "x": -5,
      "y": 3,
      "z": -9,
      "name": "Rock_Quartzite_Brick"
    },
    {
      "x": -5,
      "y": 4,
      "z": -9,
      "name": "Rock_Quartzite"
    },
    {
      "x": -5,
      "y": 5,
      "z": -9,
      "name": "Rock_Quartzite"
    },
    {
      "x": -5,
      "y": 6,
      "z": -9,
      "name": "Rock_Quartzite"
    },
    {
      "x": -5,
      "y": 7,
      "z": -9,
      "name": "Rock_Quartzite"
    },
    {
      "x": -5,
      "y": 8,
      "z": -9,
      "name": "Rock_Quartzite"
    },
    {
      "x": -5,
      "y": 9,
      "z": -9,
      "name": "Rock_Quartzite"
    },
    {
      "x": -5,
      "y": 10,
      "z": -9,
      "name": "Rock_Quartzite"
    },
    {
      "x": -5,
      "y": -3,
      "z": -8,
      "name": "Rock_Stone"
    },
    {
      "x": -5,
      "y": -2,
      "z": -8,
      "name": "Rock_Stone"
    },
    {
      "x": -5,
      "y": -1,
      "z": -8,
      "name": "Rock_Stone"
    },
    {
      "x": -5,
      "y": 0,
      "z": -8,
      "name": "Rock_Stone_Cobble"
    },
    {
      "x": -5,
      "y": 1,
      "z": -8,
      "name": "Rock_Quartzite_Brick"
    },
    {
      "x": -5,
      "y": 2,
      "z": -8,
      "name": "Rock_Quartzite_Brick"
    },
    {
      "x": -5,
      "y": 3,
      "z": -8,
      "name": "Rock_Quartzite_Brick"
    },
    {
      "x": -5,
      "y": 4,
      "z": -8,
      "name": "Rock_Quartzite"
    },
    {
      "x": -5,
      "y": 5,
      "z": -8,
      "name": "Rock_Quartzite"
    },
    {
      "x": -5,
      "y": 6,
      "z": -8,
      "name": "Rock_Quartzite"
    },
    {
      "x": -5,
      "y": 7,
      "z": -8,
      "name": "Rock_Quartzite"
    },
    {
      "x": -5,
      "y": 8,
      "z": -8,
      "name": "Rock_Quartzite"
    },
    {
      "x": -5,
      "y": 9,
      "z": -8,
      "name": "Rock_Quartzite"
    },
    {
      "x": -5,
      "y": 10,
      "z": -8,
      "name": "Rock_Quartzite"
    },
    {
      "x": -5,
      "y": -3,
      "z": -7,
      "name": "Rock_Stone"
    },
    {
      "x": -5,
      "y": -2,
      "z": -7,
      "name": "Rock_Stone"
    },
    {
      "x": -5,
      "y": -1,
      "z": -7,
      "name": "Rock_Stone_Cobble"
    },
    {
      "x": -5,
      "y": 0,
      "z": -7,
      "name": "Rock_Quartzite_Brick"
    },
    {
      "x": -5,
      "y": 1,
      "z": -7,
      "name": "Rock_Quartzite_Brick"
    },
    {
      "x": -5,
      "y": 2,
      "z": -7,
      "name": "Rock_Quartzite_Brick"
    },
    {
      "x": -5,
      "y": 3,
      "z": -7,
      "name": "Rock_Quartzite_Brick"
    },
    {
      "x": -5,
      "y": 4,
      "z": -7,
      "name": "Rock_Quartzite"
    },
    {
      "x": -5,
      "y": 5,
      "z": -7,
      "name": "Rock_Quartzite"
    },
    {
      "x": -5,
      "y": 6,
      "z": -7,
      "name": "Rock_Quartzite_Brick"
    },
    {
      "x": -5,
      "y": 7,
      "z": -7,
      "name": "Rock_Quartzite"
    },
    {
      "x": -5,
      "y": 8,
      "z": -7,
      "name": "Rock_Quartzite"
    },
    {
      "x": -5,
      "y": 9,
      "z": -7,
      "name": "Rock_Quartzite"
    },
    {
      "x": -5,
      "y": 10,
      "z": -7,
      "name": "Rock_Quartzite"
    },
    {
      "x": -5,
      "y": -3,
      "z": -6,
      "name": "Rock_Stone"
    },
    {
      "x": -5,
      "y": -2,
      "z": -6,
      "name": "Rock_Stone"
    },
    {
      "x": -5,
      "y": -1,
      "z": -6,
      "name": "Rock_Stone"
    },
    {
      "x": -5,
      "y": 0,
      "z": -6,
      "name": "Rock_Stone_Cobble"
    },
    {
      "x": -5,
      "y": 1,
      "z": -6,
      "name": "Rock_Quartzite_Brick"
    },
    {
      "x": -5,
      "y": 2,
      "z": -6,
      "name": "Rock_Quartzite_Brick"
    },
    {
      "x": -5,
      "y": 3,
      "z": -6,
      "name": "Rock_Quartzite_Brick"
    },
    {
      "x": -5,
      "y": 4,
      "z": -6,
      "name": "Rock_Quartzite"
    },
    {
      "x": -5,
      "y": 5,
      "z": -6,
      "name": "Rock_Quartzite"
    },
    {
      "x": -5,
      "y": 6,
      "z": -6,
      "name": "Rock_Quartzite"
    },
    {
      "x": -5,
      "y": 7,
      "z": -6,
      "name": "Rock_Quartzite"
    },
    {
      "x": -5,
      "y": 8,
      "z": -6,
      "name": "Rock_Quartzite"
    },
    {
      "x": -5,
      "y": 9,
      "z": -6,
      "name": "Rock_Quartzite"
    },
    {
      "x": -5,
      "y": 10,
      "z": -6,
      "name": "Rock_Quartzite"
    },
    {
      "x": -5,
      "y": -3,
      "z": -5,
      "name": "Rock_Stone"
    },
    {
      "x": -5,
      "y": -2,
      "z": -5,
      "name": "Rock_Stone"
    },
    {
      "x": -5,
      "y": -1,
      "z": -5,
      "name": "Rock_Stone"
    },
    {
      "x": -5,
      "y": 0,
      "z": -5,
      "name": "Rock_Stone_Cobble"
    },
    {
      "x": -5,
      "y": 1,
      "z": -5,
      "name": "Rock_Quartzite_Brick"
    },
    {
      "x": -5,
      "y": 2,
      "z": -5,
      "name": "Rock_Quartzite_Brick"
    },
    {
      "x": -5,
      "y": 3,
      "z": -5,
      "name": "Rock_Quartzite_Brick"
    },
    {
      "x": -5,
      "y": 4,
      "z": -5,
      "name": "Rock_Quartzite"
    },
    {
      "x": -5,
      "y": 5,
      "z": -5,
      "name": "Rock_Quartzite"
    },
    {
      "x": -5,
      "y": 6,
      "z": -5,
      "name": "Rock_Quartzite"
    },
    {
      "x": -5,
      "y": 7,
      "z": -5,
      "name": "Rock_Quartzite"
    },
    {
      "x": -5,
      "y": 8,
      "z": -5,
      "name": "Rock_Quartzite"
    },
    {
      "x": -5,
      "y": 9,
      "z": -5,
      "name": "Rock_Quartzite"
    },
    {
      "x": -5,
      "y": 10,
      "z": -5,
      "name": "Rock_Quartzite"
    },
    {
      "x": -5,
      "y": -3,
      "z": -4,
      "name": "Rock_Stone"
    },
    {
      "x": -5,
      "y": -2,
      "z": -4,
      "name": "Rock_Stone"
    },
    {
      "x": -5,
      "y": -1,
      "z": -4,
      "name": "Rock_Stone"
    },
    {
      "x": -5,
      "y": 0,
      "z": -4,
      "name": "Rock_Stone_Cobble"
    },
    {
      "x": -5,
      "y": 1,
      "z": -4,
      "name": "Rock_Quartzite_Brick"
    },
    {
      "x": -5,
      "y": 2,
      "z": -4,
      "name": "Rock_Quartzite_Brick"
    },
    {
      "x": -5,
      "y": 3,
      "z": -4,
      "name": "Rock_Quartzite_Brick"
    },
    {
      "x": -5,
      "y": 4,
      "z": -4,
      "name": "Rock_Quartzite"
    },
    {
      "x": -5,
      "y": 5,
      "z": -4,
      "name": "Rock_Quartzite"
    },
    {
      "x": -5,
      "y": 6,
      "z": -4,
      "name": "Rock_Quartzite"
    },
    {
      "x": -5,
      "y": 7,
      "z": -4,
      "name": "Rock_Quartzite"
    },
    {
      "x": -5,
      "y": 8,
      "z": -4,
      "name": "Rock_Quartzite"
    },
    {
      "x": -5,
      "y": 9,
      "z": -4,
      "name": "Rock_Quartzite"
    },
    {
      "x": -5,
      "y": 10,
      "z": -4,
      "name": "Rock_Quartzite"
    },
    {
      "x": -5,
      "y": -3,
      "z": -3,
      "name": "Rock_Stone"
    },
    {
      "x": -5,
      "y": -2,
      "z": -3,
      "name": "Rock_Stone"
    },
    {
      "x": -5,
      "y": -1,
      "z": -3,
      "name": "Rock_Stone"
    },
    {
      "x": -5,
      "y": 0,
      "z": -3,
      "name": "Rock_Stone_Cobble"
    },
    {
      "x": -5,
      "y": 1,
      "z": -3,
      "name": "Rock_Quartzite_Brick"
    },
    {
      "x": -5,
      "y": 2,
      "z": -3,
      "name": "Rock_Quartzite_Brick"
    },
    {
      "x": -5,
      "y": 3,
      "z": -3,
      "name": "Rock_Quartzite_Brick"
    },
    {
      "x": -5,
      "y": 4,
      "z": -3,
      "name": "Rock_Quartzite"
    },
    {
      "x": -5,
      "y": 5,
      "z": -3,
      "name": "Rock_Quartzite"
    },
    {
      "x": -5,
      "y": 6,
      "z": -3,
      "name": "Rock_Quartzite"
    },
    {
      "x": -5,
      "y": 7,
      "z": -3,
      "name": "Rock_Quartzite"
    },
    {
      "x": -5,
      "y": 8,
      "z": -3,
      "name": "Rock_Quartzite"
    },
    {
      "x": -5,
      "y": 9,
      "z": -3,
      "name": "Rock_Quartzite"
    },
    {
      "x": -5,
      "y": 10,
      "z": -3,
      "name": "Rock_Quartzite"
    },
    {
      "x": -5,
      "y": -3,
      "z": -2,
      "name": "Rock_Stone"
    },
    {
      "x": -5,
      "y": -2,
      "z": -2,
      "name": "Rock_Stone"
    },
    {
      "x": -5,
      "y": -1,
      "z": -2,
      "name": "Rock_Stone"
    },
    {
      "x": -5,
      "y": 0,
      "z": -2,
      "name": "Rock_Stone_Cobble"
    },
    {
      "x": -5,
      "y": 1,
      "z": -2,
      "name": "Rock_Quartzite_Brick"
    },
    {
      "x": -5,
      "y": 2,
      "z": -2,
      "name": "Rock_Quartzite_Brick"
    },
    {
      "x": -5,
      "y": 3,
      "z": -2,
      "name": "Rock_Quartzite_Brick"
    },
    {
      "x": -5,
      "y": 4,
      "z": -2,
      "name": "Rock_Quartzite"
    },
    {
      "x": -5,
      "y": 5,
      "z": -2,
      "name": "Rock_Quartzite"
    },
    {
      "x": -5,
      "y": 6,
      "z": -2,
      "name": "Rock_Quartzite"
    },
    {
      "x": -5,
      "y": 7,
      "z": -2,
      "name": "Rock_Quartzite"
    },
    {
      "x": -5,
      "y": 8,
      "z": -2,
      "name": "Rock_Quartzite"
    },
    {
      "x": -5,
      "y": 9,
      "z": -2,
      "name": "Rock_Quartzite"
    },
    {
      "x": -5,
      "y": 10,
      "z": -2,
      "name": "Rock_Quartzite"
    },
    {
      "x": -5,
      "y": -3,
      "z": -1,
      "name": "Rock_Stone"
    },
    {
      "x": -5,
      "y": -2,
      "z": -1,
      "name": "Rock_Stone"
    },
    {
      "x": -5,
      "y": -1,
      "z": -1,
      "name": "Rock_Stone"
    },
    {
      "x": -5,
      "y": 0,
      "z": -1,
      "name": "Rock_Stone_Cobble"
    },
    {
      "x": -5,
      "y": 1,
      "z": -1,
      "name": "Rock_Quartzite_Brick"
    },
    {
      "x": -5,
      "y": 2,
      "z": -1,
      "name": "Rock_Quartzite_Brick"
    },
    {
      "x": -5,
      "y": 3,
      "z": -1,
      "name": "Rock_Quartzite_Brick"
    },
    {
      "x": -5,
      "y": 4,
      "z": -1,
      "name": "Rock_Quartzite"
    },
    {
      "x": -5,
      "y": 5,
      "z": -1,
      "name": "Rock_Quartzite"
    },
    {
      "x": -5,
      "y": 6,
      "z": -1,
      "name": "Rock_Quartzite"
    },
    {
      "x": -5,
      "y": 7,
      "z": -1,
      "name": "Rock_Quartzite"
    },
    {
      "x": -5,
      "y": 8,
      "z": -1,
      "name": "Rock_Quartzite"
    },
    {
      "x": -5,
      "y": 9,
      "z": -1,
      "name": "Rock_Quartzite"
    },
    {
      "x": -5,
      "y": 10,
      "z": -1,
      "name": "Rock_Quartzite"
    },
    {
      "x": -5,
      "y": -3,
      "z": 0,
      "name": "Rock_Stone"
    },
    {
      "x": -5,
      "y": -2,
      "z": 0,
      "name": "Rock_Stone"
    },
    {
      "x": -5,
      "y": -1,
      "z": 0,
      "name": "Rock_Stone"
    },
    {
      "x": -5,
      "y": 0,
      "z": 0,
      "name": "Rock_Stone_Cobble"
    },
    {
      "x": -5,
      "y": 1,
      "z": 0,
      "name": "Rock_Quartzite_Brick"
    },
    {
      "x": -5,
      "y": 2,
      "z": 0,
      "name": "Rock_Quartzite_Brick"
    },
    {
      "x": -5,
      "y": 3,
      "z": 0,
      "name": "Rock_Quartzite_Brick"
    },
    {
      "x": -5,
      "y": 4,
      "z": 0,
      "name": "Rock_Quartzite"
    },
    {
      "x": -5,
      "y": 5,
      "z": 0,
      "name": "Rock_Quartzite"
    },
    {
      "x": -5,
      "y": 6,
      "z": 0,
      "name": "Rock_Quartzite"
    },
    {
      "x": -5,
      "y": 7,
      "z": 0,
      "name": "Rock_Quartzite"
    },
    {
      "x": -5,
      "y": 8,
      "z": 0,
      "name": "Rock_Quartzite"
    },
    {
      "x": -5,
      "y": 9,
      "z": 0,
      "name": "Rock_Quartzite"
    },
    {
      "x": -5,
      "y": 10,
      "z": 0,
      "name": "Rock_Quartzite"
    },
    {
      "x": -4,
      "y": -3,
      "z": -10,
      "name": "Rock_Stone"
    },
    {
      "x": -4,
      "y": -2,
      "z": -10,
      "name": "Rock_Stone"
    },
    {
      "x": -4,
      "y": -1,
      "z": -10,
      "name": "Rock_Stone"
    },
    {
      "x": -4,
      "y": 0,
      "z": -10,
      "name": "Rock_Stone_Cobble"
    },
    {
      "x": -4,
      "y": 1,
      "z": -10,
      "name": "Rock_Quartzite_Brick"
    },
    {
      "x": -4,
      "y": 2,
      "z": -10,
      "name": "Rock_Quartzite_Brick"
    },
    {
      "x": -4,
      "y": 3,
      "z": -10,
      "name": "Rock_Quartzite"
    },
    {
      "x": -4,
      "y": 4,
      "z": -10,
      "name": "Empty"
    },
    {
      "x": -4,
      "y": 5,
      "z": -10,
      "name": "Empty"
    },
    {
      "x": -4,
      "y": 6,
      "z": -10,
      "name": "Rock_Quartzite"
    },
    {
      "x": -4,
      "y": 7,
      "z": -10,
      "name": "Rock_Quartzite"
    },
    {
      "x": -4,
      "y": 8,
      "z": -10,
      "name": "Rock_Quartzite"
    },
    {
      "x": -4,
      "y": 9,
      "z": -10,
      "name": "Rock_Quartzite"
    },
    {
      "x": -4,
      "y": 10,
      "z": -10,
      "name": "Rock_Quartzite"
    },
    {
      "x": -4,
      "y": -3,
      "z": -9,
      "name": "Rock_Stone"
    },
    {
      "x": -4,
      "y": -2,
      "z": -9,
      "name": "Rock_Stone"
    },
    {
      "x": -4,
      "y": -1,
      "z": -9,
      "name": "Rock_Stone"
    },
    {
      "x": -4,
      "y": 0,
      "z": -9,
      "name": "Rock_Stone_Cobble"
    },
    {
      "x": -4,
      "y": 1,
      "z": -9,
      "name": "Rock_Quartzite_Brick"
    },
    {
      "x": -4,
      "y": 2,
      "z": -9,
      "name": "Empty"
    },
    {
      "x": -4,
      "y": 3,
      "z": -9,
      "name": "Empty"
    },
    {
      "x": -4,
      "y": 4,
      "z": -9,
      "name": "Empty"
    },
    {
      "x": -4,
      "y": 5,
      "z": -9,
      "name": "Rock_Stone_Brick"
    },
    {
      "x": -4,
      "y": 6,
      "z": -9,
      "name": "Rock_Quartzite"
    },
    {
      "x": -4,
      "y": 7,
      "z": -9,
      "name": "Rock_Quartzite"
    },
    {
      "x": -4,
      "y": 8,
      "z": -9,
      "name": "Rock_Quartzite"
    },
    {
      "x": -4,
      "y": 9,
      "z": -9,
      "name": "Rock_Quartzite"
    },
    {
      "x": -4,
      "y": 10,
      "z": -9,
      "name": "Rock_Quartzite"
    },
    {
      "x": -4,
      "y": -3,
      "z": -8,
      "name": "Rock_Stone"
    },
    {
      "x": -4,
      "y": -2,
      "z": -8,
      "name": "Rock_Stone"
    },
    {
      "x": -4,
      "y": -1,
      "z": -8,
      "name": "Rock_Stone"
    },
    {
      "x": -4,
      "y": 0,
      "z": -8,
      "name": "Rock_Stone_Brick_Smooth_Half",
      "rotation": 4
    },
    {
      "x": -4,
      "y": 1,
      "z": -8,
      "name": "Empty"
    },
    {
      "x": -4,
      "y": 2,
      "z": -8,
      "name": "Empty"
    },
    {
      "x": -4,
      "y": 3,
      "z": -8,
      "name": "Empty"
    },
    {
      "x": -4,
      "y": 4,
      "z": -8,
      "name": "Empty"
    },
    {
      "x": -4,
      "y": 5,
      "z": -8,
      "name": "Rock_Stone_Brick"
    },
    {
      "x": -4,
      "y": 6,
      "z": -8,
      "name": "Furniture_Village_Pot"
    },
    {
      "x": -4,
      "y": 7,
      "z": -8,
      "name": "Empty"
    },
    {
      "x": -4,
      "y": 8,
      "z": -8,
      "name": "Empty"
    },
    {
      "x": -4,
      "y": 9,
      "z": -8,
      "name": "Rock_Quartzite"
    },
    {
      "x": -4,
      "y": 10,
      "z": -8,
      "name": "Rock_Quartzite"
    },
    {
      "x": -4,
      "y": -3,
      "z": -7,
      "name": "Rock_Stone"
    },
    {
      "x": -4,
      "y": -2,
      "z": -7,
      "name": "Empty"
    },
    {
      "x": -4,
      "y": -1,
      "z": -7,
      "name": "Empty"
    },
    {
      "x": -4,
      "y": 0,
      "z": -7,
      "name": "Empty"
    },
    {
      "x": -4,
      "y": 1,
      "z": -7,
      "name": "Empty"
    },
    {
      "x": -4,
      "y": 2,
      "z": -7,
      "name": "Empty"
    },
    {
      "x": -4,
      "y": 3,
      "z": -7,
      "name": "Empty"
    },
    {
      "x": -4,
      "y": 4,
      "z": -7,
      "name": "Empty"
    },
    {
      "x": -4,
      "y": 5,
      "z": -7,
      "name": "Rock_Stone_Brick"
    },
    {
      "x": -4,
      "y": 6,
      "z": -7,
      "name": "Deco_Pot_Clay_Broken"
    },
    {
      "x": -4,
      "y": 7,
      "z": -7,
      "name": "Empty"
    },
    {
      "x": -4,
      "y": 8,
      "z": -7,
      "name": "Rock_Quartzite_Brick_Half",
      "rotation": 6
    },
    {
      "x": -4,
      "y": 9,
      "z": -7,
      "name": "Rock_Quartzite"
    },
    {
      "x": -4,
      "y": 10,
      "z": -7,
      "name": "Rock_Quartzite"
    },
    {
      "x": -4,
      "y": -3,
      "z": -6,
      "name": "Rock_Stone"
    },
    {
      "x": -4,
      "y": -2,
      "z": -6,
      "name": "Rock_Stone_Cobble"
    },
    {
      "x": -4,
      "y": -1,
      "z": -6,
      "name": "Empty"
    },
    {
      "x": -4,
      "y": 0,
      "z": -6,
      "name": "Empty"
    },
    {
      "x": -4,
      "y": 1,
      "z": -6,
      "name": "Empty"
    },
    {
      "x": -4,
      "y": 2,
      "z": -6,
      "name": "Empty"
    },
    {
      "x": -4,
      "y": 3,
      "z": -6,
      "name": "Empty"
    },
    {
      "x": -4,
      "y": 4,
      "z": -6,
      "name": "Empty"
    },
    {
      "x": -4,
      "y": 5,
      "z": -6,
      "name": "Rock_Stone_Brick"
    },
    {
      "x": -4,
      "y": 6,
      "z": -6,
      "name": "Rock_Quartzite_Brick"
    },
    {
      "x": -4,
      "y": 7,
      "z": -6,
      "name": "Rock_Quartzite"
    },
    {
      "x": -4,
      "y": 8,
      "z": -6,
      "name": "Rock_Quartzite"
    },
    {
      "x": -4,
      "y": 9,
      "z": -6,
      "name": "Rock_Quartzite"
    },
    {
      "x": -4,
      "y": 10,
      "z": -6,
      "name": "Rock_Quartzite"
    },
    {
      "x": -4,
      "y": -3,
      "z": -5,
      "name": "Rock_Stone"
    },
    {
      "x": -4,
      "y": -2,
      "z": -5,
      "name": "Rock_Stone_Cobble"
    },
    {
      "x": -4,
      "y": -1,
      "z": -5,
      "name": "Rock_Stone_Cobble"
    },
    {
      "x": -4,
      "y": 0,
      "z": -5,
      "name": "Rock_Stone_Cobble"
    },
    {
      "x": -4,
      "y": 1,
      "z": -5,
      "name": "Rock_Stone_Brick"
    },
    {
      "x": -4,
      "y": 2,
      "z": -5,
      "name": "Furniture_Village_Bookcase",
      "rotation": 1
    },
    {
      "x": -4,
      "y": 3,
      "z": -5,
      "name": "Empty"
    },
    {
      "x": -4,
      "y": 4,
      "z": -5,
      "name": "Rock_Stone_Brick"
    },
    {
      "x": -4,
      "y": 5,
      "z": -5,
      "name": "Rock_Stone_Brick"
    },
    {
      "x": -4,
      "y": 6,
      "z": -5,
      "name": "Plant_Crop_Mushroom_Glowing_Orange"
    },
    {
      "x": -4,
      "y": 7,
      "z": -5,
      "name": "Empty"
    },
    {
      "x": -4,
      "y": 8,
      "z": -5,
      "name": "Rock_Quartzite_Brick_Half",
      "rotation": 4
    },
    {
      "x": -4,
      "y": 9,
      "z": -5,
      "name": "Rock_Quartzite"
    },
    {
      "x": -4,
      "y": 10,
      "z": -5,
      "name": "Rock_Quartzite"
    },
    {
      "x": -4,
      "y": -3,
      "z": -4,
      "name": "Rock_Stone"
    },
    {
      "x": -4,
      "y": -2,
      "z": -4,
      "name": "Rock_Stone"
    },
    {
      "x": -4,
      "y": -1,
      "z": -4,
      "name": "Rock_Stone"
    },
    {
      "x": -4,
      "y": 0,
      "z": -4,
      "name": "Plant_Moss_Block_Blue"
    },
    {
      "x": -4,
      "y": 1,
      "z": -4,
      "name": "Plant_Moss_Block_Blue"
    },
    {
      "x": -4,
      "y": 2,
      "z": -4,
      "name": "Furniture_Village_Bookcase",
      "rotation": 1
    },
    {
      "x": -4,
      "y": 3,
      "z": -4,
      "name": "Furniture_Village_Bookcase",
      "rotation": 1
    },
    {
      "x": -4,
      "y": 4,
      "z": -4,
      "name": "Rock_Stone_Brick"
    },
    {
      "x": -4,
      "y": 5,
      "z": -4,
      "name": "Rock_Stone_Brick"
    },
    {
      "x": -4,
      "y": 6,
      "z": -4,
      "name": "Block_Spawner_Block",
      "components": {
        "Components": {
          "BlockSpawner": {
            "BlockSpawnerId": "Zone1_Encounters_Tier3"
          }
        }
      },
      "rotation": 1
    },
    {
      "x": -4,
      "y": 7,
      "z": -4,
      "name": "Empty"
    },
    {
      "x": -4,
      "y": 8,
      "z": -4,
      "name": "Empty"
    },
    {
      "x": -4,
      "y": 9,
      "z": -4,
      "name": "Rock_Quartzite"
    },
    {
      "x": -4,
      "y": 10,
      "z": -4,
      "name": "Rock_Quartzite"
    },
    {
      "x": -4,
      "y": -3,
      "z": -3,
      "name": "Rock_Stone"
    },
    {
      "x": -4,
      "y": -2,
      "z": -3,
      "name": "Rock_Stone"
    },
    {
      "x": -4,
      "y": -1,
      "z": -3,
      "name": "Rock_Stone"
    },
    {
      "x": -4,
      "y": 0,
      "z": -3,
      "name": "Plant_Moss_Block_Blue"
    },
    {
      "x": -4,
      "y": 1,
      "z": -3,
      "name": "Furniture_Village_Bookcase",
      "rotation": 1
    },
    {
      "x": -4,
      "y": 2,
      "z": -3,
      "name": "Furniture_Village_Bookcase",
      "rotation": 1
    },
    {
      "x": -4,
      "y": 3,
      "z": -3,
      "name": "Furniture_Village_Bookcase",
      "rotation": 1
    },
    {
      "x": -4,
      "y": 4,
      "z": -3,
      "name": "Rock_Stone_Brick"
    },
    {
      "x": -4,
      "y": 5,
      "z": -3,
      "name": "Rock_Stone_Brick"
    },
    {
      "x": -4,
      "y": 6,
      "z": -3,
      "name": "Furniture_Ancient_Barrel"
    },
    {
      "x": -4,
      "y": 7,
      "z": -3,
      "name": "Empty"
    },
    {
      "x": -4,
      "y": 8,
      "z": -3,
      "name": "Rock_Quartzite_Brick_Half",
      "rotation": 6
    },
    {
      "x": -4,
      "y": 9,
      "z": -3,
      "name": "Rock_Quartzite"
    },
    {
      "x": -4,
      "y": 10,
      "z": -3,
      "name": "Rock_Quartzite"
    },
    {
      "x": -4,
      "y": -3,
      "z": -2,
      "name": "Rock_Stone"
    },
    {
      "x": -4,
      "y": -2,
      "z": -2,
      "name": "Rock_Stone"
    },
    {
      "x": -4,
      "y": -1,
      "z": -2,
      "name": "Rock_Stone"
    },
    {
      "x": -4,
      "y": 0,
      "z": -2,
      "name": "Rock_Stone_Cobble"
    },
    {
      "x": -4,
      "y": 1,
      "z": -2,
      "name": "Furniture_Ancient_Barrel"
    },
    {
      "x": -4,
      "y": 2,
      "z": -2,
      "name": "Empty"
    },
    {
      "x": -4,
      "y": 3,
      "z": -2,
      "name": "Empty"
    },
    {
      "x": -4,
      "y": 4,
      "z": -2,
      "name": "Rock_Stone_Brick"
    },
    {
      "x": -4,
      "y": 5,
      "z": -2,
      "name": "Rock_Stone_Brick"
    },
    {
      "x": -4,
      "y": 6,
      "z": -2,
      "name": "Rock_Quartzite_Brick"
    },
    {
      "x": -4,
      "y": 7,
      "z": -2,
      "name": "Rock_Quartzite_Brick"
    },
    {
      "x": -4,
      "y": 8,
      "z": -2,
      "name": "Rock_Quartzite_Brick"
    },
    {
      "x": -4,
      "y": 9,
      "z": -2,
      "name": "Rock_Quartzite"
    },
    {
      "x": -4,
      "y": 10,
      "z": -2,
      "name": "Rock_Quartzite"
    },
    {
      "x": -4,
      "y": -3,
      "z": -1,
      "name": "Rock_Stone"
    },
    {
      "x": -4,
      "y": -2,
      "z": -1,
      "name": "Rock_Stone"
    },
    {
      "x": -4,
      "y": -1,
      "z": -1,
      "name": "Rock_Stone"
    },
    {
      "x": -4,
      "y": 0,
      "z": -1,
      "name": "Rock_Stone_Cobble"
    },
    {
      "x": -4,
      "y": 1,
      "z": -1,
      "name": "Rock_Quartzite_Brick"
    },
    {
      "x": -4,
      "y": 2,
      "z": -1,
      "name": "Rock_Quartzite_Brick"
    },
    {
      "x": -4,
      "y": 3,
      "z": -1,
      "name": "Rock_Quartzite"
    },
    {
      "x": -4,
      "y": 4,
      "z": -1,
      "name": "Rock_Quartzite"
    },
    {
      "x": -4,
      "y": 5,
      "z": -1,
      "name": "Rock_Quartzite"
    },
    {
      "x": -4,
      "y": 6,
      "z": -1,
      "name": "Rock_Quartzite"
    },
    {
      "x": -4,
      "y": 7,
      "z": -1,
      "name": "Rock_Quartzite"
    },
    {
      "x": -4,
      "y": 8,
      "z": -1,
      "name": "Rock_Quartzite"
    },
    {
      "x": -4,
      "y": 9,
      "z": -1,
      "name": "Rock_Quartzite"
    },
    {
      "x": -4,
      "y": 10,
      "z": -1,
      "name": "Rock_Quartzite"
    },
    {
      "x": -4,
      "y": -3,
      "z": 0,
      "name": "Rock_Stone"
    },
    {
      "x": -4,
      "y": -2,
      "z": 0,
      "name": "Rock_Stone"
    },
    {
      "x": -4,
      "y": -1,
      "z": 0,
      "name": "Rock_Stone"
    },
    {
      "x": -4,
      "y": 0,
      "z": 0,
      "name": "Rock_Stone_Brick"
    },
    {
      "x": -4,
      "y": 1,
      "z": 0,
      "name": "Rock_Quartzite_Brick"
    },
    {
      "x": -4,
      "y": 2,
      "z": 0,
      "name": "Rock_Quartzite_Brick"
    },
    {
      "x": -4,
      "y": 3,
      "z": 0,
      "name": "Rock_Quartzite_Brick"
    },
    {
      "x": -4,
      "y": 4,
      "z": 0,
      "name": "Rock_Stone_Brick"
    },
    {
      "x": -4,
      "y": 5,
      "z": 0,
      "name": "Rock_Stone_Brick"
    },
    {
      "x": -4,
      "y": 6,
      "z": 0,
      "name": "Rock_Quartzite"
    },
    {
      "x": -4,
      "y": 7,
      "z": 0,
      "name": "Rock_Quartzite"
    },
    {
      "x": -4,
      "y": 8,
      "z": 0,
      "name": "Rock_Quartzite"
    },
    {
      "x": -4,
      "y": 9,
      "z": 0,
      "name": "Rock_Quartzite"
    },
    {
      "x": -4,
      "y": 10,
      "z": 0,
      "name": "Rock_Quartzite"
    },
    {
      "x": -3,
      "y": -3,
      "z": -10,
      "name": "Rock_Stone"
    },
    {
      "x": -3,
      "y": -2,
      "z": -10,
      "name": "Rock_Stone"
    },
    {
      "x": -3,
      "y": -1,
      "z": -10,
      "name": "Rock_Stone"
    },
    {
      "x": -3,
      "y": 0,
      "z": -10,
      "name": "Rock_Stone_Brick"
    },
    {
      "x": -3,
      "y": 1,
      "z": -10,
      "name": "Plant_Moss_Rug_Blue"
    },
    {
      "x": -3,
      "y": 2,
      "z": -10,
      "name": "Empty"
    },
    {
      "x": -3,
      "y": 3,
      "z": -10,
      "name": "Empty"
    },
    {
      "x": -3,
      "y": 4,
      "z": -10,
      "name": "Empty"
    },
    {
      "x": -3,
      "y": 5,
      "z": -10,
      "name": "Empty"
    },
    {
      "x": -3,
      "y": 6,
      "z": -10,
      "name": "Empty"
    },
    {
      "x": -3,
      "y": 7,
      "z": -10,
      "name": "Rock_Quartzite_Brick_Half",
      "rotation": 5
    },
    {
      "x": -3,
      "y": 8,
      "z": -10,
      "name": "Rock_Quartzite_Brick"
    },
    {
      "x": -3,
      "y": 9,
      "z": -10,
      "name": "Rock_Quartzite_Brick"
    },
    {
      "x": -3,
      "y": 10,
      "z": -10,
      "name": "Rock_Quartzite"
    },
    {
      "x": -3,
      "y": -3,
      "z": -9,
      "name": "Rock_Stone"
    },
    {
      "x": -3,
      "y": -2,
      "z": -9,
      "name": "Rock_Stone"
    },
    {
      "x": -3,
      "y": -1,
      "z": -9,
      "name": "Rock_Stone"
    },
    {
      "x": -3,
      "y": 0,
      "z": -9,
      "name": "Rock_Stone_Brick_Smooth"
    },
    {
      "x": -3,
      "y": 1,
      "z": -9,
      "name": "Plant_Moss_Rug_Blue"
    },
    {
      "x": -3,
      "y": 2,
      "z": -9,
      "name": "Empty"
    },
    {
      "x": -3,
      "y": 3,
      "z": -9,
      "name": "Empty"
    },
    {
      "x": -3,
      "y": 4,
      "z": -9,
      "name": "Empty"
    },
    {
      "x": -3,
      "y": 5,
      "z": -9,
      "name": "Empty"
    },
    {
      "x": -3,
      "y": 6,
      "z": -9,
      "name": "Empty"
    },
    {
      "x": -3,
      "y": 7,
      "z": -9,
      "name": "Rock_Quartzite_Brick_Half",
      "rotation": 5
    },
    {
      "x": -3,
      "y": 8,
      "z": -9,
      "name": "Rock_Quartzite_Brick"
    },
    {
      "x": -3,
      "y": 9,
      "z": -9,
      "name": "Rock_Quartzite_Brick"
    },
    {
      "x": -3,
      "y": 10,
      "z": -9,
      "name": "Rock_Quartzite"
    },
    {
      "x": -3,
      "y": -3,
      "z": -8,
      "name": "Rock_Stone"
    },
    {
      "x": -3,
      "y": -2,
      "z": -8,
      "name": "Empty"
    },
    {
      "x": -3,
      "y": -1,
      "z": -8,
      "name": "Empty"
    },
    {
      "x": -3,
      "y": 0,
      "z": -8,
      "name": "Rock_Stone_Brick_Smooth_Half",
      "rotation": 4
    },
    {
      "x": -3,
      "y": 1,
      "z": -8,
      "name": "Empty"
    },
    {
      "x": -3,
      "y": 2,
      "z": -8,
      "name": "Empty"
    },
    {
      "x": -3,
      "y": 3,
      "z": -8,
      "name": "Deco_Iron_Chain_Small"
    },
    {
      "x": -3,
      "y": 4,
      "z": -8,
      "name": "Deco_Iron_Chain_Small"
    },
    {
      "x": -3,
      "y": 5,
      "z": -8,
      "name": "Rock_Stone_Brick"
    },
    {
      "x": -3,
      "y": 6,
      "z": -8,
      "name": "Empty"
    },
    {
      "x": -3,
      "y": 7,
      "z": -8,
      "name": "Empty"
    },
    {
      "x": -3,
      "y": 8,
      "z": -8,
      "name": "Rock_Quartzite_Brick_Half",
      "rotation": 4
    },
    {
      "x": -3,
      "y": 9,
      "z": -8,
      "name": "Rock_Quartzite_Brick"
    },
    {
      "x": -3,
      "y": 10,
      "z": -8,
      "name": "Rock_Quartzite"
    },
    {
      "x": -3,
      "y": -3,
      "z": -7,
      "name": "Rock_Stone"
    },
    {
      "x": -3,
      "y": -2,
      "z": -7,
      "name": "Empty"
    },
    {
      "x": -3,
      "y": -1,
      "z": -7,
      "name": "Empty"
    },
    {
      "x": -3,
      "y": 0,
      "z": -7,
      "name": "Empty"
    },
    {
      "x": -3,
      "y": 1,
      "z": -7,
      "name": "Empty"
    },
    {
      "x": -3,
      "y": 2,
      "z": -7,
      "name": "Empty"
    },
    {
      "x": -3,
      "y": 3,
      "z": -7,
      "name": "Empty"
    },
    {
      "x": -3,
      "y": 4,
      "z": -7,
      "name": "Empty"
    },
    {
      "x": -3,
      "y": 5,
      "z": -7,
      "name": "Rock_Stone_Brick"
    },
    {
      "x": -3,
      "y": 6,
      "z": -7,
      "name": "Empty"
    },
    {
      "x": -3,
      "y": 7,
      "z": -7,
      "name": "Empty"
    },
    {
      "x": -3,
      "y": 8,
      "z": -7,
      "name": "Rock_Quartzite_Brick_Half",
      "rotation": 6
    },
    {
      "x": -3,
      "y": 9,
      "z": -7,
      "name": "Rock_Quartzite_Brick"
    },
    {
      "x": -3,
      "y": 10,
      "z": -7,
      "name": "Rock_Quartzite"
    },
    {
      "x": -3,
      "y": -3,
      "z": -6,
      "name": "Rock_Stone_Cobble"
    },
    {
      "x": -3,
      "y": -2,
      "z": -6,
      "name": "Empty"
    },
    {
      "x": -3,
      "y": -1,
      "z": -6,
      "name": "Empty"
    },
    {
      "x": -3,
      "y": 0,
      "z": -6,
      "name": "Empty"
    },
    {
      "x": -3,
      "y": 1,
      "z": -6,
      "name": "Empty"
    },
    {
      "x": -3,
      "y": 2,
      "z": -6,
      "name": "Empty"
    },
    {
      "x": -3,
      "y": 3,
      "z": -6,
      "name": "Empty"
    },
    {
      "x": -3,
      "y": 4,
      "z": -6,
      "name": "Empty"
    },
    {
      "x": -3,
      "y": 5,
      "z": -6,
      "name": "Rock_Stone_Brick"
    },
    {
      "x": -3,
      "y": 6,
      "z": -6,
      "name": "Rock_Quartzite_Brick_Half",
      "rotation": 5
    },
    {
      "x": -3,
      "y": 7,
      "z": -6,
      "name": "Rock_Quartzite_Brick"
    },
    {
      "x": -3,
      "y": 8,
      "z": -6,
      "name": "Rock_Quartzite_Brick"
    },
    {
      "x": -3,
      "y": 9,
      "z": -6,
      "name": "Rock_Quartzite_Brick"
    },
    {
      "x": -3,
      "y": 10,
      "z": -6,
      "name": "Rock_Quartzite"
    },
    {
      "x": -3,
      "y": -3,
      "z": -5,
      "name": "Rock_Stone_Cobble"
    },
    {
      "x": -3,
      "y": -2,
      "z": -5,
      "name": "Survival_Trap_Spike_Iron"
    },
    {
      "x": -3,
      "y": -1,
      "z": -5,
      "name": "Empty"
    },
    {
      "x": -3,
      "y": 0,
      "z": -5,
      "name": "Empty"
    },
    {
      "x": -3,
      "y": 1,
      "z": -5,
      "name": "Empty"
    },
    {
      "x": -3,
      "y": 2,
      "z": -5,
      "name": "Empty"
    },
    {
      "x": -3,
      "y": 3,
      "z": -5,
      "name": "Empty"
    },
    {
      "x": -3,
      "y": 4,
      "z": -5,
      "name": "Empty"
    },
    {
      "x": -3,
      "y": 5,
      "z": -5,
      "name": "Rock_Stone_Brick"
    },
    {
      "x": -3,
      "y": 6,
      "z": -5,
      "name": "Empty"
    },
    {
      "x": -3,
      "y": 7,
      "z": -5,
      "name": "Empty"
    },
    {
      "x": -3,
      "y": 8,
      "z": -5,
      "name": "Empty"
    },
    {
      "x": -3,
      "y": 9,
      "z": -5,
      "name": "Rock_Quartzite_Brick"
    },
    {
      "x": -3,
      "y": 10,
      "z": -5,
      "name": "Rock_Quartzite"
    },
    {
      "x": -3,
      "y": -3,
      "z": -4,
      "name": "Rock_Stone_Cobble"
    },
    {
      "x": -3,
      "y": -2,
      "z": -4,
      "name": "Empty"
    },
    {
      "x": -3,
      "y": -1,
      "z": -4,
      "name": "Empty"
    },
    {
      "x": -3,
      "y": 0,
      "z": -4,
      "name": "Empty"
    },
    {
      "x": -3,
      "y": 1,
      "z": -4,
      "name": "Empty"
    },
    {
      "x": -3,
      "y": 2,
      "z": -4,
      "name": "Empty"
    },
    {
      "x": -3,
      "y": 3,
      "z": -4,
      "name": "Empty"
    },
    {
      "x": -3,
      "y": 4,
      "z": -4,
      "name": "Empty"
    },
    {
      "x": -3,
      "y": 5,
      "z": -4,
      "name": "Rock_Stone_Brick"
    },
    {
      "x": -3,
      "y": 6,
      "z": -4,
      "name": "Empty"
    },
    {
      "x": -3,
      "y": 7,
      "z": -4,
      "name": "Empty"
    },
    {
      "x": -3,
      "y": 8,
      "z": -4,
      "name": "Empty"
    },
    {
      "x": -3,
      "y": 9,
      "z": -4,
      "name": "Rock_Quartzite_Brick"
    },
    {
      "x": -3,
      "y": 10,
      "z": -4,
      "name": "Rock_Quartzite"
    },
    {
      "x": -3,
      "y": -3,
      "z": -3,
      "name": "Rock_Stone"
    },
    {
      "x": -3,
      "y": -2,
      "z": -3,
      "name": "Rock_Stone"
    },
    {
      "x": -3,
      "y": -1,
      "z": -3,
      "name": "Empty"
    },
    {
      "x": -3,
      "y": 0,
      "z": -3,
      "name": "Empty"
    },
    {
      "x": -3,
      "y": 1,
      "z": -3,
      "name": "Empty"
    },
    {
      "x": -3,
      "y": 2,
      "z": -3,
      "name": "Empty"
    },
    {
      "x": -3,
      "y": 3,
      "z": -3,
      "name": "Empty"
    },
    {
      "x": -3,
      "y": 4,
      "z": -3,
      "name": "Rock_Stone_Brick"
    },
    {
      "x": -3,
      "y": 5,
      "z": -3,
      "name": "Rock_Stone_Brick"
    },
    {
      "x": -3,
      "y": 6,
      "z": -3,
      "name": "Empty"
    },
    {
      "x": -3,
      "y": 7,
      "z": -3,
      "name": "Empty"
    },
    {
      "x": -3,
      "y": 8,
      "z": -3,
      "name": "Empty"
    },
    {
      "x": -3,
      "y": 9,
      "z": -3,
      "name": "Rock_Quartzite_Brick"
    },
    {
      "x": -3,
      "y": 10,
      "z": -3,
      "name": "Rock_Quartzite"
    },
    {
      "x": -3,
      "y": -3,
      "z": -2,
      "name": "Rock_Stone"
    },
    {
      "x": -3,
      "y": -2,
      "z": -2,
      "name": "Rock_Stone"
    },
    {
      "x": -3,
      "y": -1,
      "z": -2,
      "name": "Rock_Stone"
    },
    {
      "x": -3,
      "y": 0,
      "z": -2,
      "name": "Rock_Stone_Brick_Smooth"
    },
    {
      "x": -3,
      "y": 1,
      "z": -2,
      "name": "Rock_Stone_Brick_Pillar_Base"
    },
    {
      "x": -3,
      "y": 2,
      "z": -2,
      "name": "Rock_Stone_Brick_Pillar_Middle"
    },
    {
      "x": -3,
      "y": 3,
      "z": -2,
      "name": "Rock_Stone_Brick_Pillar_Base",
      "rotation": 8
    },
    {
      "x": -3,
      "y": 4,
      "z": -2,
      "name": "Rock_Stone_Brick"
    },
    {
      "x": -3,
      "y": 5,
      "z": -2,
      "name": "Rock_Stone_Brick"
    },
    {
      "x": -3,
      "y": 6,
      "z": -2,
      "name": "Empty"
    },
    {
      "x": -3,
      "y": 7,
      "z": -2,
      "name": "Empty"
    },
    {
      "x": -3,
      "y": 8,
      "z": -2,
      "name": "Rock_Quartzite_Brick_Half",
      "rotation": 6
    },
    {
      "x": -3,
      "y": 9,
      "z": -2,
      "name": "Rock_Quartzite_Brick"
    },
    {
      "x": -3,
      "y": 10,
      "z": -2,
      "name": "Rock_Quartzite"
    },
    {
      "x": -3,
      "y": -3,
      "z": -1,
      "name": "Rock_Stone"
    },
    {
      "x": -3,
      "y": -2,
      "z": -1,
      "name": "Rock_Stone"
    },
    {
      "x": -3,
      "y": -1,
      "z": -1,
      "name": "Rock_Stone"
    },
    {
      "x": -3,
      "y": 0,
      "z": -1,
      "name": "Rock_Stone_Cobble"
    },
    {
      "x": -3,
      "y": 1,
      "z": -1,
      "name": "Rubble_Quartzite"
    },
    {
      "x": -3,
      "y": 2,
      "z": -1,
      "name": "Empty"
    },
    {
      "x": -3,
      "y": 3,
      "z": -1,
      "name": "Empty"
    },
    {
      "x": -3,
      "y": 4,
      "z": -1,
      "name": "Rock_Stone_Brick"
    },
    {
      "x": -3,
      "y": 5,
      "z": -1,
      "name": "Rock_Stone_Brick"
    },
    {
      "x": -3,
      "y": 6,
      "z": -1,
      "name": "Rock_Quartzite"
    },
    {
      "x": -3,
      "y": 7,
      "z": -1,
      "name": "Rock_Quartzite_Brick_Half",
      "rotation": 5
    },
    {
      "x": -3,
      "y": 8,
      "z": -1,
      "name": "Rock_Quartzite_Brick"
    },
    {
      "x": -3,
      "y": 9,
      "z": -1,
      "name": "Rock_Quartzite_Brick"
    },
    {
      "x": -3,
      "y": 10,
      "z": -1,
      "name": "Rock_Quartzite"
    },
    {
      "x": -3,
      "y": -3,
      "z": 0,
      "name": "Rock_Stone"
    },
    {
      "x": -3,
      "y": -2,
      "z": 0,
      "name": "Rock_Stone"
    },
    {
      "x": -3,
      "y": -1,
      "z": 0,
      "name": "Rock_Stone"
    },
    {
      "x": -3,
      "y": 0,
      "z": 0,
      "name": "Rock_Stone_Cobble"
    },
    {
      "x": -3,
      "y": 1,
      "z": 0,
      "name": "Empty"
    },
    {
      "x": -3,
      "y": 2,
      "z": 0,
      "name": "Empty"
    },
    {
      "x": -3,
      "y": 3,
      "z": 0,
      "name": "Empty"
    },
    {
      "x": -3,
      "y": 4,
      "z": 0,
      "name": "Empty"
    },
    {
      "x": -3,
      "y": 5,
      "z": 0,
      "name": "Rock_Stone_Brick_Half",
      "rotation": 5
    },
    {
      "x": -3,
      "y": 6,
      "z": 0,
      "name": "Empty"
    },
    {
      "x": -3,
      "y": 7,
      "z": 0,
      "name": "Rock_Quartzite_Brick_Half",
      "rotation": 5
    },
    {
      "x": -3,
      "y": 8,
      "z": 0,
      "name": "Rock_Quartzite_Brick"
    },
    {
      "x": -3,
      "y": 9,
      "z": 0,
      "name": "Rock_Quartzite_Brick"
    },
    {
      "x": -3,
      "y": 10,
      "z": 0,
      "name": "Rock_Quartzite"
    },
    {
      "x": -2,
      "y": -3,
      "z": -10,
      "name": "Rock_Stone"
    },
    {
      "x": -2,
      "y": -2,
      "z": -10,
      "name": "Rock_Stone"
    },
    {
      "x": -2,
      "y": -1,
      "z": -10,
      "name": "Rock_Stone"
    },
    {
      "x": -2,
      "y": 0,
      "z": -10,
      "name": "Rock_Stone_Brick"
    },
    {
      "x": -2,
      "y": 1,
      "z": -10,
      "name": "Plant_Moss_Rug_Blue"
    },
    {
      "x": -2,
      "y": 2,
      "z": -10,
      "name": "Empty"
    },
    {
      "x": -2,
      "y": 3,
      "z": -10,
      "name": "Empty"
    },
    {
      "x": -2,
      "y": 4,
      "z": -10,
      "name": "Empty"
    },
    {
      "x": -2,
      "y": 5,
      "z": -10,
      "name": "Empty"
    },
    {
      "x": -2,
      "y": 6,
      "z": -10,
      "name": "Empty"
    },
    {
      "x": -2,
      "y": 7,
      "z": -10,
      "name": "Empty"
    },
    {
      "x": -2,
      "y": 8,
      "z": -10,
      "name": "Empty"
    },
    {
      "x": -2,
      "y": 9,
      "z": -10,
      "name": "Rock_Quartzite_Brick"
    },
    {
      "x": -2,
      "y": 10,
      "z": -10,
      "name": "Rock_Quartzite"
    },
    {
      "x": -2,
      "y": -3,
      "z": -9,
      "name": "Rock_Stone"
    },
    {
      "x": -2,
      "y": -2,
      "z": -9,
      "name": "Rock_Stone"
    },
    {
      "x": -2,
      "y": -1,
      "z": -9,
      "name": "Empty"
    },
    {
      "x": -2,
      "y": 0,
      "z": -9,
      "name": "Rock_Stone_Brick_Smooth"
    },
    {
      "x": -2,
      "y": 1,
      "z": -9,
      "name": "Empty"
    },
    {
      "x": -2,
      "y": 2,
      "z": -9,
      "name": "Empty"
    },
    {
      "x": -2,
      "y": 3,
      "z": -9,
      "name": "Empty"
    },
    {
      "x": -2,
      "y": 4,
      "z": -9,
      "name": "Empty"
    },
    {
      "x": -2,
      "y": 5,
      "z": -9,
      "name": "Empty"
    },
    {
      "x": -2,
      "y": 6,
      "z": -9,
      "name": "Empty"
    },
    {
      "x": -2,
      "y": 7,
      "z": -9,
      "name": "Empty"
    },
    {
      "x": -2,
      "y": 8,
      "z": -9,
      "name": "Empty"
    },
    {
      "x": -2,
      "y": 9,
      "z": -9,
      "name": "Rock_Quartzite_Brick"
    },
    {
      "x": -2,
      "y": 10,
      "z": -9,
      "name": "Rock_Quartzite"
    },
    {
      "x": -2,
      "y": -3,
      "z": -8,
      "name": "Rock_Stone"
    },
    {
      "x": -2,
      "y": -2,
      "z": -8,
      "name": "Empty"
    },
    {
      "x": -2,
      "y": -1,
      "z": -8,
      "name": "Empty"
    },
    {
      "x": -2,
      "y": 0,
      "z": -8,
      "name": "Empty"
    },
    {
      "x": -2,
      "y": 1,
      "z": -8,
      "name": "Empty"
    },
    {
      "x": -2,
      "y": 2,
      "z": -8,
      "name": "Empty"
    },
    {
      "x": -2,
      "y": 3,
      "z": -8,
      "name": "Empty"
    },
    {
      "x": -2,
      "y": 4,
      "z": -8,
      "name": "Empty"
    },
    {
      "x": -2,
      "y": 5,
      "z": -8,
      "name": "Empty"
    },
    {
      "x": -2,
      "y": 6,
      "z": -8,
      "name": "Empty"
    },
    {
      "x": -2,
      "y": 7,
      "z": -8,
      "name": "Empty"
    },
    {
      "x": -2,
      "y": 8,
      "z": -8,
      "name": "Empty"
    },
    {
      "x": -2,
      "y": 9,
      "z": -8,
      "name": "Empty"
    },
    {
      "x": -2,
      "y": 10,
      "z": -8,
      "name": "Rock_Quartzite"
    },
    {
      "x": -2,
      "y": -3,
      "z": -7,
      "name": "Rock_Stone"
    },
    {
      "x": -2,
      "y": -2,
      "z": -7,
      "name": "Rock_Stone_Brick_Pillar_Base"
    },
    {
      "x": -2,
      "y": -1,
      "z": -7,
      "name": "Rock_Stone_Brick_Pillar_Middle"
    },
    {
      "x": -2,
      "y": 0,
      "z": -7,
      "name": "Rock_Stone_Brick_Pillar_Middle"
    },
    {
      "x": -2,
      "y": 1,
      "z": -7,
      "name": "Plant_Moss_Rug_Blue"
    },
    {
      "x": -2,
      "y": 2,
      "z": -7,
      "name": "Empty"
    },
    {
      "x": -2,
      "y": 3,
      "z": -7,
      "name": "Empty"
    },
    {
      "x": -2,
      "y": 4,
      "z": -7,
      "name": "Empty"
    },
    {
      "x": -2,
      "y": 5,
      "z": -7,
      "name": "Empty"
    },
    {
      "x": -2,
      "y": 6,
      "z": -7,
      "name": "Empty"
    },
    {
      "x": -2,
      "y": 7,
      "z": -7,
      "name": "Empty"
    },
    {
      "x": -2,
      "y": 8,
      "z": -7,
      "name": "Empty"
    },
    {
      "x": -2,
      "y": 9,
      "z": -7,
      "name": "Empty"
    },
    {
      "x": -2,
      "y": 10,
      "z": -7,
      "name": "Rock_Quartzite"
    },
    {
      "x": -2,
      "y": -3,
      "z": -6,
      "name": "Rock_Stone"
    },
    {
      "x": -2,
      "y": -2,
      "z": -6,
      "name": "Empty"
    },
    {
      "x": -2,
      "y": -1,
      "z": -6,
      "name": "Empty"
    },
    {
      "x": -2,
      "y": 0,
      "z": -6,
      "name": "Empty"
    },
    {
      "x": -2,
      "y": 1,
      "z": -6,
      "name": "Empty"
    },
    {
      "x": -2,
      "y": 2,
      "z": -6,
      "name": "Empty"
    },
    {
      "x": -2,
      "y": 3,
      "z": -6,
      "name": "Empty"
    },
    {
      "x": -2,
      "y": 4,
      "z": -6,
      "name": "Empty"
    },
    {
      "x": -2,
      "y": 5,
      "z": -6,
      "name": "Empty"
    },
    {
      "x": -2,
      "y": 6,
      "z": -6,
      "name": "Empty"
    },
    {
      "x": -2,
      "y": 7,
      "z": -6,
      "name": "Empty"
    },
    {
      "x": -2,
      "y": 8,
      "z": -6,
      "name": "Empty"
    },
    {
      "x": -2,
      "y": 9,
      "z": -6,
      "name": "Rock_Quartzite_Brick"
    },
    {
      "x": -2,
      "y": 10,
      "z": -6,
      "name": "Rock_Quartzite"
    },
    {
      "x": -2,
      "y": -3,
      "z": -5,
      "name": "Rock_Stone_Cobble"
    },
    {
      "x": -2,
      "y": -2,
      "z": -5,
      "name": "Empty"
    },
    {
      "x": -2,
      "y": -1,
      "z": -5,
      "name": "Empty"
    },
    {
      "x": -2,
      "y": 0,
      "z": -5,
      "name": "Empty"
    },
    {
      "x": -2,
      "y": 1,
      "z": -5,
      "name": "Empty"
    },
    {
      "x": -2,
      "y": 2,
      "z": -5,
      "name": "Empty"
    },
    {
      "x": -2,
      "y": 3,
      "z": -5,
      "name": "Empty"
    },
    {
      "x": -2,
      "y": 4,
      "z": -5,
      "name": "Empty"
    },
    {
      "x": -2,
      "y": 5,
      "z": -5,
      "name": "Rock_Stone_Brick_Half",
      "rotation": 5
    },
    {
      "x": -2,
      "y": 6,
      "z": -5,
      "name": "Empty"
    },
    {
      "x": -2,
      "y": 7,
      "z": -5,
      "name": "Empty"
    },
    {
      "x": -2,
      "y": 8,
      "z": -5,
      "name": "Rock_Quartzite_Brick"
    },
    {
      "x": -2,
      "y": 9,
      "z": -5,
      "name": "Rock_Quartzite_Brick"
    },
    {
      "x": -2,
      "y": 10,
      "z": -5,
      "name": "Rock_Quartzite"
    },
    {
      "x": -2,
      "y": -3,
      "z": -4,
      "name": "Rock_Stone_Cobble"
    },
    {
      "x": -2,
      "y": -2,
      "z": -4,
      "name": "Empty"
    },
    {
      "x": -2,
      "y": -1,
      "z": -4,
      "name": "Empty"
    },
    {
      "x": -2,
      "y": 0,
      "z": -4,
      "name": "Empty"
    },
    {
      "x": -2,
      "y": 1,
      "z": -4,
      "name": "Empty"
    },
    {
      "x": -2,
      "y": 2,
      "z": -4,
      "name": "Empty"
    },
    {
      "x": -2,
      "y": 3,
      "z": -4,
      "name": "Empty"
    },
    {
      "x": -2,
      "y": 4,
      "z": -4,
      "name": "Empty"
    },
    {
      "x": -2,
      "y": 5,
      "z": -4,
      "name": "Rock_Stone_Brick_Half",
      "rotation": 5
    },
    {
      "x": -2,
      "y": 6,
      "z": -4,
      "name": "Empty"
    },
    {
      "x": -2,
      "y": 7,
      "z": -4,
      "name": "Empty"
    },
    {
      "x": -2,
      "y": 8,
      "z": -4,
      "name": "Wood_Beech_Trunk",
      "rotation": 5
    },
    {
      "x": -2,
      "y": 9,
      "z": -4,
      "name": "Rock_Quartzite_Brick"
    },
    {
      "x": -2,
      "y": 10,
      "z": -4,
      "name": "Rock_Quartzite"
    },
    {
      "x": -2,
      "y": -3,
      "z": -3,
      "name": "Rock_Stone"
    },
    {
      "x": -2,
      "y": -2,
      "z": -3,
      "name": "Empty"
    },
    {
      "x": -2,
      "y": -1,
      "z": -3,
      "name": "Empty"
    },
    {
      "x": -2,
      "y": 0,
      "z": -3,
      "name": "Empty"
    },
    {
      "x": -2,
      "y": 1,
      "z": -3,
      "name": "Empty"
    },
    {
      "x": -2,
      "y": 2,
      "z": -3,
      "name": "Empty"
    },
    {
      "x": -2,
      "y": 3,
      "z": -3,
      "name": "Empty"
    },
    {
      "x": -2,
      "y": 4,
      "z": -3,
      "name": "Rock_Stone_Brick"
    },
    {
      "x": -2,
      "y": 5,
      "z": -3,
      "name": "Rock_Stone_Brick"
    },
    {
      "x": -2,
      "y": 6,
      "z": -3,
      "name": "Empty"
    },
    {
      "x": -2,
      "y": 7,
      "z": -3,
      "name": "Empty"
    },
    {
      "x": -2,
      "y": 8,
      "z": -3,
      "name": "Empty"
    },
    {
      "x": -2,
      "y": 9,
      "z": -3,
      "name": "Empty"
    },
    {
      "x": -2,
      "y": 10,
      "z": -3,
      "name": "Rock_Quartzite"
    },
    {
      "x": -2,
      "y": -3,
      "z": -2,
      "name": "Rock_Stone"
    },
    {
      "x": -2,
      "y": -2,
      "z": -2,
      "name": "Rock_Stone"
    },
    {
      "x": -2,
      "y": -1,
      "z": -2,
      "name": "Rock_Stone"
    },
    {
      "x": -2,
      "y": 0,
      "z": -2,
      "name": "Rock_Stone_Brick_Smooth"
    },
    {
      "x": -2,
      "y": 1,
      "z": -2,
      "name": "Empty"
    },
    {
      "x": -2,
      "y": 2,
      "z": -2,
      "name": "Empty"
    },
    {
      "x": -2,
      "y": 3,
      "z": -2,
      "name": "Empty"
    },
    {
      "x": -2,
      "y": 4,
      "z": -2,
      "name": "Rock_Stone_Brick"
    },
    {
      "x": -2,
      "y": 5,
      "z": -2,
      "name": "Rock_Stone_Brick"
    },
    {
      "x": -2,
      "y": 6,
      "z": -2,
      "name": "Empty"
    },
    {
      "x": -2,
      "y": 7,
      "z": -2,
      "name": "Empty"
    },
    {
      "x": -2,
      "y": 8,
      "z": -2,
      "name": "Empty"
    },
    {
      "x": -2,
      "y": 9,
      "z": -2,
      "name": "Empty"
    },
    {
      "x": -2,
      "y": 10,
      "z": -2,
      "name": "Rock_Quartzite"
    },
    {
      "x": -2,
      "y": -3,
      "z": -1,
      "name": "Rock_Stone"
    },
    {
      "x": -2,
      "y": -2,
      "z": -1,
      "name": "Rock_Stone"
    },
    {
      "x": -2,
      "y": -1,
      "z": -1,
      "name": "Rock_Stone"
    },
    {
      "x": -2,
      "y": 0,
      "z": -1,
      "name": "Rock_Stone_Brick"
    },
    {
      "x": -2,
      "y": 1,
      "z": -1,
      "name": "Empty"
    },
    {
      "x": -2,
      "y": 2,
      "z": -1,
      "name": "Empty"
    },
    {
      "x": -2,
      "y": 3,
      "z": -1,
      "name": "Empty"
    },
    {
      "x": -2,
      "y": 4,
      "z": -1,
      "name": "Rock_Stone_Brick_Half",
      "rotation": 4
    },
    {
      "x": -2,
      "y": 5,
      "z": -1,
      "name": "Rock_Stone_Brick_Half",
      "rotation": 4
    },
    {
      "x": -2,
      "y": 6,
      "z": -1,
      "name": "Empty"
    },
    {
      "x": -2,
      "y": 7,
      "z": -1,
      "name": "Empty"
    },
    {
      "x": -2,
      "y": 8,
      "z": -1,
      "name": "Empty"
    },
    {
      "x": -2,
      "y": 9,
      "z": -1,
      "name": "Rock_Quartzite_Brick"
    },
    {
      "x": -2,
      "y": 10,
      "z": -1,
      "name": "Rock_Quartzite"
    },
    {
      "x": -2,
      "y": -3,
      "z": 0,
      "name": "Rock_Stone"
    },
    {
      "x": -2,
      "y": -2,
      "z": 0,
      "name": "Rock_Stone"
    },
    {
      "x": -2,
      "y": -1,
      "z": 0,
      "name": "Rock_Stone"
    },
    {
      "x": -2,
      "y": 0,
      "z": 0,
      "name": "Rock_Stone_Cobble"
    },
    {
      "x": -2,
      "y": 1,
      "z": 0,
      "name": "Empty"
    },
    {
      "x": -2,
      "y": 2,
      "z": 0,
      "name": "Empty"
    },
    {
      "x": -2,
      "y": 3,
      "z": 0,
      "name": "Empty"
    },
    {
      "x": -2,
      "y": 4,
      "z": 0,
      "name": "Empty"
    },
    {
      "x": -2,
      "y": 5,
      "z": 0,
      "name": "Empty"
    },
    {
      "x": -2,
      "y": 6,
      "z": 0,
      "name": "Empty"
    },
    {
      "x": -2,
      "y": 7,
      "z": 0,
      "name": "Empty"
    },
    {
      "x": -2,
      "y": 8,
      "z": 0,
      "name": "Empty"
    },
    {
      "x": -2,
      "y": 9,
      "z": 0,
      "name": "Rock_Quartzite_Brick"
    },
    {
      "x": -2,
      "y": 10,
      "z": 0,
      "name": "Rock_Quartzite"
    },
    {
      "x": -1,
      "y": -3,
      "z": -10,
      "name": "Rock_Stone"
    },
    {
      "x": -1,
      "y": -2,
      "z": -10,
      "name": "Rock_Stone"
    },
    {
      "x": -1,
      "y": -1,
      "z": -10,
      "name": "Rock_Stone"
    },
    {
      "x": -1,
      "y": 0,
      "z": -10,
      "name": "Rock_Stone_Brick"
    },
    {
      "x": -1,
      "y": 1,
      "z": -10,
      "name": "Empty"
    },
    {
      "x": -1,
      "y": 2,
      "z": -10,
      "name": "Empty"
    },
    {
      "x": -1,
      "y": 3,
      "z": -10,
      "name": "Empty"
    },
    {
      "x": -1,
      "y": 4,
      "z": -10,
      "name": "Empty"
    },
    {
      "x": -1,
      "y": 5,
      "z": -10,
      "name": "Empty"
    },
    {
      "x": -1,
      "y": 6,
      "z": -10,
      "name": "Empty"
    },
    {
      "x": -1,
      "y": 7,
      "z": -10,
      "name": "Empty"
    },
    {
      "x": -1,
      "y": 8,
      "z": -10,
      "name": "Empty"
    },
    {
      "x": -1,
      "y": 9,
      "z": -10,
      "name": "Rock_Quartzite_Brick_Half",
      "rotation": 8
    },
    {
      "x": -1,
      "y": 10,
      "z": -10,
      "name": "Rock_Quartzite"
    },
    {
      "x": -1,
      "y": -3,
      "z": -9,
      "name": "Rock_Stone"
    },
    {
      "x": -1,
      "y": -2,
      "z": -9,
      "name": "Empty"
    },
    {
      "x": -1,
      "y": -1,
      "z": -9,
      "name": "Empty"
    },
    {
      "x": -1,
      "y": 0,
      "z": -9,
      "name": "Rock_Stone_Brick_Smooth"
    },
    {
      "x": -1,
      "y": 1,
      "z": -9,
      "name": "Empty"
    },
    {
      "x": -1,
      "y": 2,
      "z": -9,
      "name": "Empty"
    },
    {
      "x": -1,
      "y": 3,
      "z": -9,
      "name": "Empty"
    },
    {
      "x": -1,
      "y": 4,
      "z": -9,
      "name": "Empty"
    },
    {
      "x": -1,
      "y": 5,
      "z": -9,
      "name": "Empty"
    },
    {
      "x": -1,
      "y": 6,
      "z": -9,
      "name": "Empty"
    },
    {
      "x": -1,
      "y": 7,
      "z": -9,
      "name": "Empty"
    },
    {
      "x": -1,
      "y": 8,
      "z": -9,
      "name": "Empty"
    },
    {
      "x": -1,
      "y": 9,
      "z": -9,
      "name": "Rock_Quartzite_Brick_Half",
      "rotation": 8
    },
    {
      "x": -1,
      "y": 10,
      "z": -9,
      "name": "Rock_Quartzite"
    },
    {
      "x": -1,
      "y": -3,
      "z": -8,
      "name": "Rock_Stone"
    },
    {
      "x": -1,
      "y": -2,
      "z": -8,
      "name": "Empty"
    },
    {
      "x": -1,
      "y": -1,
      "z": -8,
      "name": "Empty"
    },
    {
      "x": -1,
      "y": 0,
      "z": -8,
      "name": "Empty"
    },
    {
      "x": -1,
      "y": 1,
      "z": -8,
      "name": "Empty"
    },
    {
      "x": -1,
      "y": 2,
      "z": -8,
      "name": "Empty"
    },
    {
      "x": -1,
      "y": 3,
      "z": -8,
      "name": "Empty"
    },
    {
      "x": -1,
      "y": 4,
      "z": -8,
      "name": "Empty"
    },
    {
      "x": -1,
      "y": 5,
      "z": -8,
      "name": "Empty"
    },
    {
      "x": -1,
      "y": 6,
      "z": -8,
      "name": "Empty"
    },
    {
      "x": -1,
      "y": 7,
      "z": -8,
      "name": "Empty"
    },
    {
      "x": -1,
      "y": 8,
      "z": -8,
      "name": "Empty"
    },
    {
      "x": -1,
      "y": 9,
      "z": -8,
      "name": "Empty"
    },
    {
      "x": -1,
      "y": 10,
      "z": -8,
      "name": "Rock_Quartzite"
    },
    {
      "x": -1,
      "y": -3,
      "z": -7,
      "name": "Rock_Stone"
    },
    {
      "x": -1,
      "y": -2,
      "z": -7,
      "name": "Empty"
    },
    {
      "x": -1,
      "y": -1,
      "z": -7,
      "name": "Empty"
    },
    {
      "x": -1,
      "y": 0,
      "z": -7,
      "name": "Empty"
    },
    {
      "x": -1,
      "y": 1,
      "z": -7,
      "name": "Empty"
    },
    {
      "x": -1,
      "y": 2,
      "z": -7,
      "name": "Empty"
    },
    {
      "x": -1,
      "y": 3,
      "z": -7,
      "name": "Empty"
    },
    {
      "x": -1,
      "y": 4,
      "z": -7,
      "name": "Empty"
    },
    {
      "x": -1,
      "y": 5,
      "z": -7,
      "name": "Empty"
    },
    {
      "x": -1,
      "y": 6,
      "z": -7,
      "name": "Empty"
    },
    {
      "x": -1,
      "y": 7,
      "z": -7,
      "name": "Empty"
    },
    {
      "x": -1,
      "y": 8,
      "z": -7,
      "name": "Empty"
    },
    {
      "x": -1,
      "y": 9,
      "z": -7,
      "name": "Empty"
    },
    {
      "x": -1,
      "y": 10,
      "z": -7,
      "name": "Rock_Quartzite"
    },
    {
      "x": -1,
      "y": -3,
      "z": -6,
      "name": "Rock_Stone"
    },
    {
      "x": -1,
      "y": -2,
      "z": -6,
      "name": "Empty"
    },
    {
      "x": -1,
      "y": -1,
      "z": -6,
      "name": "Empty"
    },
    {
      "x": -1,
      "y": 0,
      "z": -6,
      "name": "Empty"
    },
    {
      "x": -1,
      "y": 1,
      "z": -6,
      "name": "Empty"
    },
    {
      "x": -1,
      "y": 2,
      "z": -6,
      "name": "Empty"
    },
    {
      "x": -1,
      "y": 3,
      "z": -6,
      "name": "Empty"
    },
    {
      "x": -1,
      "y": 4,
      "z": -6,
      "name": "Empty"
    },
    {
      "x": -1,
      "y": 5,
      "z": -6,
      "name": "Empty"
    },
    {
      "x": -1,
      "y": 6,
      "z": -6,
      "name": "Empty"
    },
    {
      "x": -1,
      "y": 7,
      "z": -6,
      "name": "Empty"
    },
    {
      "x": -1,
      "y": 8,
      "z": -6,
      "name": "Empty"
    },
    {
      "x": -1,
      "y": 9,
      "z": -6,
      "name": "Empty"
    },
    {
      "x": -1,
      "y": 10,
      "z": -6,
      "name": "Rock_Quartzite"
    },
    {
      "x": -1,
      "y": -3,
      "z": -5,
      "name": "Rock_Stone"
    },
    {
      "x": -1,
      "y": -2,
      "z": -5,
      "name": "Survival_Trap_Spike_Iron"
    },
    {
      "x": -1,
      "y": -1,
      "z": -5,
      "name": "Empty"
    },
    {
      "x": -1,
      "y": 0,
      "z": -5,
      "name": "Empty"
    },
    {
      "x": -1,
      "y": 1,
      "z": -5,
      "name": "Empty"
    },
    {
      "x": -1,
      "y": 2,
      "z": -5,
      "name": "Empty"
    },
    {
      "x": -1,
      "y": 3,
      "z": -5,
      "name": "Empty"
    },
    {
      "x": -1,
      "y": 4,
      "z": -5,
      "name": "Empty"
    },
    {
      "x": -1,
      "y": 5,
      "z": -5,
      "name": "Empty"
    },
    {
      "x": -1,
      "y": 6,
      "z": -5,
      "name": "Empty"
    },
    {
      "x": -1,
      "y": 7,
      "z": -5,
      "name": "Empty"
    },
    {
      "x": -1,
      "y": 8,
      "z": -5,
      "name": "Empty"
    },
    {
      "x": -1,
      "y": 9,
      "z": -5,
      "name": "Rock_Quartzite_Brick"
    },
    {
      "x": -1,
      "y": 10,
      "z": -5,
      "name": "Rock_Quartzite"
    },
    {
      "x": -1,
      "y": -3,
      "z": -4,
      "name": "Rock_Stone"
    },
    {
      "x": -1,
      "y": -2,
      "z": -4,
      "name": "Empty"
    },
    {
      "x": -1,
      "y": -1,
      "z": -4,
      "name": "Empty"
    },
    {
      "x": -1,
      "y": 0,
      "z": -4,
      "name": "Empty"
    },
    {
      "x": -1,
      "y": 1,
      "z": -4,
      "name": "Empty"
    },
    {
      "x": -1,
      "y": 2,
      "z": -4,
      "name": "Empty"
    },
    {
      "x": -1,
      "y": 3,
      "z": -4,
      "name": "Empty"
    },
    {
      "x": -1,
      "y": 4,
      "z": -4,
      "name": "Empty"
    },
    {
      "x": -1,
      "y": 5,
      "z": -4,
      "name": "Empty"
    },
    {
      "x": -1,
      "y": 6,
      "z": -4,
      "name": "Empty"
    },
    {
      "x": -1,
      "y": 7,
      "z": -4,
      "name": "Empty"
    },
    {
      "x": -1,
      "y": 8,
      "z": -4,
      "name": "Wood_Beech_Trunk",
      "rotation": 5
    },
    {
      "x": -1,
      "y": 9,
      "z": -4,
      "name": "Rock_Quartzite_Brick"
    },
    {
      "x": -1,
      "y": 10,
      "z": -4,
      "name": "Rock_Quartzite"
    },
    {
      "x": -1,
      "y": -3,
      "z": -3,
      "name": "Rock_Stone"
    },
    {
      "x": -1,
      "y": -2,
      "z": -3,
      "name": "Empty"
    },
    {
      "x": -1,
      "y": -1,
      "z": -3,
      "name": "Empty"
    },
    {
      "x": -1,
      "y": 0,
      "z": -3,
      "name": "Empty"
    },
    {
      "x": -1,
      "y": 1,
      "z": -3,
      "name": "Empty"
    },
    {
      "x": -1,
      "y": 2,
      "z": -3,
      "name": "Empty"
    },
    {
      "x": -1,
      "y": 3,
      "z": -3,
      "name": "Empty"
    },
    {
      "x": -1,
      "y": 4,
      "z": -3,
      "name": "Empty"
    },
    {
      "x": -1,
      "y": 5,
      "z": -3,
      "name": "Rock_Stone_Brick_Half",
      "rotation": 6
    },
    {
      "x": -1,
      "y": 6,
      "z": -3,
      "name": "Empty"
    },
    {
      "x": -1,
      "y": 7,
      "z": -3,
      "name": "Empty"
    },
    {
      "x": -1,
      "y": 8,
      "z": -3,
      "name": "Empty"
    },
    {
      "x": -1,
      "y": 9,
      "z": -3,
      "name": "Empty"
    },
    {
      "x": -1,
      "y": 10,
      "z": -3,
      "name": "Rock_Quartzite"
    },
    {
      "x": -1,
      "y": -3,
      "z": -2,
      "name": "Rock_Stone_Cobble"
    },
    {
      "x": -1,
      "y": -2,
      "z": -2,
      "name": "Furniture_Ancient_Barrel"
    },
    {
      "x": -1,
      "y": -1,
      "z": -2,
      "name": "Empty"
    },
    {
      "x": -1,
      "y": 0,
      "z": -2,
      "name": "Rock_Stone_Brick_Smooth"
    },
    {
      "x": -1,
      "y": 1,
      "z": -2,
      "name": "Rock_Stone_Brick_Pillar_Base"
    },
    {
      "x": -1,
      "y": 2,
      "z": -2,
      "name": "Rock_Stone_Brick_Pillar_Middle"
    },
    {
      "x": -1,
      "y": 3,
      "z": -2,
      "name": "Rock_Stone_Brick_Pillar_Base",
      "rotation": 8
    },
    {
      "x": -1,
      "y": 4,
      "z": -2,
      "name": "Rock_Stone_Brick"
    },
    {
      "x": -1,
      "y": 5,
      "z": -2,
      "name": "Rock_Stone_Brick"
    },
    {
      "x": -1,
      "y": 6,
      "z": -2,
      "name": "Empty"
    },
    {
      "x": -1,
      "y": 7,
      "z": -2,
      "name": "Empty"
    },
    {
      "x": -1,
      "y": 8,
      "z": -2,
      "name": "Empty"
    },
    {
      "x": -1,
      "y": 9,
      "z": -2,
      "name": "Wood_Beech_Branch_Corner",
      "rotation": 9
    },
    {
      "x": -1,
      "y": 10,
      "z": -2,
      "name": "Rock_Quartzite"
    },
    {
      "x": -1,
      "y": -3,
      "z": -1,
      "name": "Rock_Stone"
    },
    {
      "x": -1,
      "y": -2,
      "z": -1,
      "name": "Rock_Stone"
    },
    {
      "x": -1,
      "y": -1,
      "z": -1,
      "name": "Rock_Stone"
    },
    {
      "x": -1,
      "y": 0,
      "z": -1,
      "name": "Rock_Stone_Brick"
    },
    {
      "x": -1,
      "y": 1,
      "z": -1,
      "name": "Empty"
    },
    {
      "x": -1,
      "y": 2,
      "z": -1,
      "name": "Empty"
    },
    {
      "x": -1,
      "y": 3,
      "z": -1,
      "name": "Empty"
    },
    {
      "x": -1,
      "y": 4,
      "z": -1,
      "name": "Empty"
    },
    {
      "x": -1,
      "y": 5,
      "z": -1,
      "name": "Rock_Stone_Brick_Half",
      "rotation": 4
    },
    {
      "x": -1,
      "y": 6,
      "z": -1,
      "name": "Empty"
    },
    {
      "x": -1,
      "y": 7,
      "z": -1,
      "name": "Empty"
    },
    {
      "x": -1,
      "y": 8,
      "z": -1,
      "name": "Empty"
    },
    {
      "x": -1,
      "y": 9,
      "z": -1,
      "name": "Rock_Quartzite_Brick_Half",
      "rotation": 8
    },
    {
      "x": -1,
      "y": 10,
      "z": -1,
      "name": "Rock_Quartzite"
    },
    {
      "x": -1,
      "y": -3,
      "z": 0,
      "name": "Rock_Stone"
    },
    {
      "x": -1,
      "y": -2,
      "z": 0,
      "name": "Rock_Stone"
    },
    {
      "x": -1,
      "y": -1,
      "z": 0,
      "name": "Rock_Stone"
    },
    {
      "x": -1,
      "y": 0,
      "z": 0,
      "name": "Rock_Stone_Brick"
    },
    {
      "x": -1,
      "y": 1,
      "z": 0,
      "name": "Empty"
    },
    {
      "x": -1,
      "y": 2,
      "z": 0,
      "name": "Empty"
    },
    {
      "x": -1,
      "y": 3,
      "z": 0,
      "name": "Empty"
    },
    {
      "x": -1,
      "y": 4,
      "z": 0,
      "name": "Empty"
    },
    {
      "x": -1,
      "y": 5,
      "z": 0,
      "name": "Empty"
    },
    {
      "x": -1,
      "y": 6,
      "z": 0,
      "name": "Empty"
    },
    {
      "x": -1,
      "y": 7,
      "z": 0,
      "name": "Empty"
    },
    {
      "x": -1,
      "y": 8,
      "z": 0,
      "name": "Empty"
    },
    {
      "x": -1,
      "y": 9,
      "z": 0,
      "name": "Rock_Quartzite_Brick_Half",
      "rotation": 8
    },
    {
      "x": -1,
      "y": 10,
      "z": 0,
      "name": "Rock_Quartzite"
    },
    {
      "x": 0,
      "y": -3,
      "z": -10,
      "name": "Rock_Stone"
    },
    {
      "x": 0,
      "y": -2,
      "z": -10,
      "name": "Rock_Stone"
    },
    {
      "x": 0,
      "y": -1,
      "z": -10,
      "name": "Rock_Stone"
    },
    {
      "x": 0,
      "y": 0,
      "z": -10,
      "name": "Rock_Stone_Cobble"
    },
    {
      "x": 0,
      "y": 1,
      "z": -10,
      "name": "Empty"
    },
    {
      "x": 0,
      "y": 2,
      "z": -10,
      "name": "Empty"
    },
    {
      "x": 0,
      "y": 3,
      "z": -10,
      "name": "Empty"
    },
    {
      "x": 0,
      "y": 4,
      "z": -10,
      "name": "Empty"
    },
    {
      "x": 0,
      "y": 5,
      "z": -10,
      "name": "Empty"
    },
    {
      "x": 0,
      "y": 6,
      "z": -10,
      "name": "Empty"
    },
    {
      "x": 0,
      "y": 7,
      "z": -10,
      "name": "Empty"
    },
    {
      "x": 0,
      "y": 8,
      "z": -10,
      "name": "Empty"
    },
    {
      "x": 0,
      "y": 9,
      "z": -10,
      "name": "Rock_Quartzite_Brick_Half",
      "rotation": 8
    },
    {
      "x": 0,
      "y": 10,
      "z": -10,
      "name": "Rock_Quartzite"
    },
    {
      "x": 0,
      "y": -3,
      "z": -9,
      "name": "Rock_Stone"
    },
    {
      "x": 0,
      "y": -2,
      "z": -9,
      "name": "Rock_Stone"
    },
    {
      "x": 0,
      "y": -1,
      "z": -9,
      "name": "Empty"
    },
    {
      "x": 0,
      "y": 0,
      "z": -9,
      "name": "Rock_Stone_Brick_Smooth"
    },
    {
      "x": 0,
      "y": 1,
      "z": -9,
      "name": "Empty"
    },
    {
      "x": 0,
      "y": 2,
      "z": -9,
      "name": "Empty"
    },
    {
      "x": 0,
      "y": 3,
      "z": -9,
      "name": "Empty"
    },
    {
      "x": 0,
      "y": 4,
      "z": -9,
      "name": "Empty"
    },
    {
      "x": 0,
      "y": 5,
      "z": -9,
      "name": "Empty"
    },
    {
      "x": 0,
      "y": 6,
      "z": -9,
      "name": "Empty"
    },
    {
      "x": 0,
      "y": 7,
      "z": -9,
      "name": "Empty"
    },
    {
      "x": 0,
      "y": 8,
      "z": -9,
      "name": "Empty"
    },
    {
      "x": 0,
      "y": 9,
      "z": -9,
      "name": "Rock_Quartzite_Brick_Half",
      "rotation": 8
    },
    {
      "x": 0,
      "y": 10,
      "z": -9,
      "name": "Rock_Quartzite"
    },
    {
      "x": 0,
      "y": -3,
      "z": -8,
      "name": "Rock_Stone"
    },
    {
      "x": 0,
      "y": -2,
      "z": -8,
      "name": "Survival_Trap_Spike_Iron"
    },
    {
      "x": 0,
      "y": -1,
      "z": -8,
      "name": "Empty"
    },
    {
      "x": 0,
      "y": 0,
      "z": -8,
      "name": "Empty"
    },
    {
      "x": 0,
      "y": 1,
      "z": -8,
      "name": "Empty"
    },
    {
      "x": 0,
      "y": 2,
      "z": -8,
      "name": "Empty"
    },
    {
      "x": 0,
      "y": 3,
      "z": -8,
      "name": "Empty"
    },
    {
      "x": 0,
      "y": 4,
      "z": -8,
      "name": "Empty"
    },
    {
      "x": 0,
      "y": 5,
      "z": -8,
      "name": "Empty"
    },
    {
      "x": 0,
      "y": 6,
      "z": -8,
      "name": "Empty"
    },
    {
      "x": 0,
      "y": 7,
      "z": -8,
      "name": "Empty"
    },
    {
      "x": 0,
      "y": 8,
      "z": -8,
      "name": "Empty"
    },
    {
      "x": 0,
      "y": 9,
      "z": -8,
      "name": "Empty"
    },
    {
      "x": 0,
      "y": 10,
      "z": -8,
      "name": "Rock_Quartzite"
    },
    {
      "x": 0,
      "y": -3,
      "z": -7,
      "name": "Rock_Stone"
    },
    {
      "x": 0,
      "y": -2,
      "z": -7,
      "name": "Empty"
    },
    {
      "x": 0,
      "y": -1,
      "z": -7,
      "name": "Empty"
    },
    {
      "x": 0,
      "y": 0,
      "z": -7,
      "name": "Empty"
    },
    {
      "x": 0,
      "y": 1,
      "z": -7,
      "name": "Empty"
    },
    {
      "x": 0,
      "y": 2,
      "z": -7,
      "name": "Empty"
    },
    {
      "x": 0,
      "y": 3,
      "z": -7,
      "name": "Empty"
    },
    {
      "x": 0,
      "y": 4,
      "z": -7,
      "name": "Empty"
    },
    {
      "x": 0,
      "y": 5,
      "z": -7,
      "name": "Empty"
    },
    {
      "x": 0,
      "y": 6,
      "z": -7,
      "name": "Empty"
    },
    {
      "x": 0,
      "y": 7,
      "z": -7,
      "name": "Empty"
    },
    {
      "x": 0,
      "y": 8,
      "z": -7,
      "name": "Empty"
    },
    {
      "x": 0,
      "y": 9,
      "z": -7,
      "name": "Empty"
    },
    {
      "x": 0,
      "y": 10,
      "z": -7,
      "name": "Rock_Quartzite"
    },
    {
      "x": 0,
      "y": -3,
      "z": -6,
      "name": "Rock_Stone_Cobble"
    },
    {
      "x": 0,
      "y": -2,
      "z": -6,
      "name": "Empty"
    },
    {
      "x": 0,
      "y": -1,
      "z": -6,
      "name": "Empty"
    },
    {
      "x": 0,
      "y": 0,
      "z": -6,
      "name": "Empty"
    },
    {
      "x": 0,
      "y": 1,
      "z": -6,
      "name": "Empty"
    },
    {
      "x": 0,
      "y": 2,
      "z": -6,
      "name": "Empty"
    },
    {
      "x": 0,
      "y": 3,
      "z": -6,
      "name": "Empty"
    },
    {
      "x": 0,
      "y": 4,
      "z": -6,
      "name": "Empty"
    },
    {
      "x": 0,
      "y": 5,
      "z": -6,
      "name": "Empty"
    },
    {
      "x": 0,
      "y": 6,
      "z": -6,
      "name": "Empty"
    },
    {
      "x": 0,
      "y": 7,
      "z": -6,
      "name": "Empty"
    },
    {
      "x": 0,
      "y": 8,
      "z": -6,
      "name": "Empty"
    },
    {
      "x": 0,
      "y": 9,
      "z": -6,
      "name": "Empty"
    },
    {
      "x": 0,
      "y": 10,
      "z": -6,
      "name": "Rock_Quartzite"
    },
    {
      "x": 0,
      "y": -3,
      "z": -5,
      "name": "Rock_Stone"
    },
    {
      "x": 0,
      "y": -2,
      "z": -5,
      "name": "Empty"
    },
    {
      "x": 0,
      "y": -1,
      "z": -5,
      "name": "Empty"
    },
    {
      "x": 0,
      "y": 0,
      "z": -5,
      "name": "Empty"
    },
    {
      "x": 0,
      "y": 1,
      "z": -5,
      "name": "Empty"
    },
    {
      "x": 0,
      "y": 2,
      "z": -5,
      "name": "Empty"
    },
    {
      "x": 0,
      "y": 3,
      "z": -5,
      "name": "Empty"
    },
    {
      "x": 0,
      "y": 4,
      "z": -5,
      "name": "Empty"
    },
    {
      "x": 0,
      "y": 5,
      "z": -5,
      "name": "Empty"
    },
    {
      "x": 0,
      "y": 6,
      "z": -5,
      "name": "Empty"
    },
    {
      "x": 0,
      "y": 7,
      "z": -5,
      "name": "Empty"
    },
    {
      "x": 0,
      "y": 8,
      "z": -5,
      "name": "Empty"
    },
    {
      "x": 0,
      "y": 9,
      "z": -5,
      "name": "Rock_Quartzite_Brick"
    },
    {
      "x": 0,
      "y": 10,
      "z": -5,
      "name": "Rock_Quartzite"
    },
    {
      "x": 0,
      "y": -3,
      "z": -4,
      "name": "Rock_Stone"
    },
    {
      "x": 0,
      "y": -2,
      "z": -4,
      "name": "Empty"
    },
    {
      "x": 0,
      "y": -1,
      "z": -4,
      "name": "Empty"
    },
    {
      "x": 0,
      "y": 0,
      "z": -4,
      "name": "Empty"
    },
    {
      "x": 0,
      "y": 1,
      "z": -4,
      "name": "Empty"
    },
    {
      "x": 0,
      "y": 2,
      "z": -4,
      "name": "Empty"
    },
    {
      "x": 0,
      "y": 3,
      "z": -4,
      "name": "Empty"
    },
    {
      "x": 0,
      "y": 4,
      "z": -4,
      "name": "Empty"
    },
    {
      "x": 0,
      "y": 5,
      "z": -4,
      "name": "Empty"
    },
    {
      "x": 0,
      "y": 6,
      "z": -4,
      "name": "Empty"
    },
    {
      "x": 0,
      "y": 7,
      "z": -4,
      "name": "Empty"
    },
    {
      "x": 0,
      "y": 8,
      "z": -4,
      "name": "Wood_Beech_Trunk_Full",
      "rotation": 5
    },
    {
      "x": 0,
      "y": 9,
      "z": -4,
      "name": "Rock_Quartzite_Brick"
    },
    {
      "x": 0,
      "y": 10,
      "z": -4,
      "name": "Rock_Quartzite"
    },
    {
      "x": 0,
      "y": -3,
      "z": -3,
      "name": "Rock_Stone_Cobble"
    },
    {
      "x": 0,
      "y": -2,
      "z": -3,
      "name": "Empty"
    },
    {
      "x": 0,
      "y": -1,
      "z": -3,
      "name": "Empty"
    },
    {
      "x": 0,
      "y": 0,
      "z": -3,
      "name": "Rock_Stone_Brick_Smooth_Half",
      "rotation": 6
    },
    {
      "x": 0,
      "y": 1,
      "z": -3,
      "name": "Empty"
    },
    {
      "x": 0,
      "y": 2,
      "z": -3,
      "name": "Empty"
    },
    {
      "x": 0,
      "y": 3,
      "z": -3,
      "name": "Empty"
    },
    {
      "x": 0,
      "y": 4,
      "z": -3,
      "name": "Empty"
    },
    {
      "x": 0,
      "y": 5,
      "z": -3,
      "name": "Empty"
    },
    {
      "x": 0,
      "y": 6,
      "z": -3,
      "name": "Empty"
    },
    {
      "x": 0,
      "y": 7,
      "z": -3,
      "name": "Wood_Beech_Trunk_Full",
      "rotation": 5
    },
    {
      "x": 0,
      "y": 8,
      "z": -3,
      "name": "Wood_Beech_Trunk_Full",
      "rotation": 5
    },
    {
      "x": 0,
      "y": 9,
      "z": -3,
      "name": "Empty"
    },
    {
      "x": 0,
      "y": 10,
      "z": -3,
      "name": "Rock_Quartzite"
    },
    {
      "x": 0,
      "y": -3,
      "z": -2,
      "name": "Rock_Stone_Cobble"
    },
    {
      "x": 0,
      "y": -2,
      "z": -2,
      "name": "Empty"
    },
    {
      "x": 0,
      "y": -1,
      "z": -2,
      "name": "Empty"
    },
    {
      "x": 0,
      "y": 0,
      "z": -2,
      "name": "Rock_Stone_Brick_Smooth"
    },
    {
      "x": 0,
      "y": 1,
      "z": -2,
      "name": "Empty"
    },
    {
      "x": 0,
      "y": 2,
      "z": -2,
      "name": "Empty"
    },
    {
      "x": 0,
      "y": 3,
      "z": -2,
      "name": "Empty"
    },
    {
      "x": 0,
      "y": 4,
      "z": -2,
      "name": "Rock_Stone_Brick"
    },
    {
      "x": 0,
      "y": 5,
      "z": -2,
      "name": "Rock_Stone_Brick"
    },
    {
      "x": 0,
      "y": 6,
      "z": -2,
      "name": "Empty"
    },
    {
      "x": 0,
      "y": 7,
      "z": -2,
      "name": "Empty"
    },
    {
      "x": 0,
      "y": 8,
      "z": -2,
      "name": "Wood_Beech_Branch_Corner"
    },
    {
      "x": 0,
      "y": 9,
      "z": -2,
      "name": "Wood_Beech_Branch_Corner",
      "rotation": 11
    },
    {
      "x": 0,
      "y": 10,
      "z": -2,
      "name": "Rock_Quartzite"
    },
    {
      "x": 0,
      "y": -3,
      "z": -1,
      "name": "Rock_Stone"
    },
    {
      "x": 0,
      "y": -2,
      "z": -1,
      "name": "Block_Spawner_Block",
      "components": {
        "Components": {
          "BlockSpawner": {
            "BlockSpawnerId": "Zone1_Encounters_Tier3"
          }
        }
      },
      "rotation": 2
    },
    {
      "x": 0,
      "y": -1,
      "z": -1,
      "name": "Empty"
    },
    {
      "x": 0,
      "y": 0,
      "z": -1,
      "name": "Rock_Stone_Brick"
    },
    {
      "x": 0,
      "y": 1,
      "z": -1,
      "name": "Empty"
    },
    {
      "x": 0,
      "y": 2,
      "z": -1,
      "name": "Empty"
    },
    {
      "x": 0,
      "y": 3,
      "z": -1,
      "name": "Empty"
    },
    {
      "x": 0,
      "y": 4,
      "z": -1,
      "name": "Empty"
    },
    {
      "x": 0,
      "y": 5,
      "z": -1,
      "name": "Empty"
    },
    {
      "x": 0,
      "y": 6,
      "z": -1,
      "name": "Empty"
    },
    {
      "x": 0,
      "y": 7,
      "z": -1,
      "name": "Empty"
    },
    {
      "x": 0,
      "y": 8,
      "z": -1,
      "name": "Empty"
    },
    {
      "x": 0,
      "y": 9,
      "z": -1,
      "name": "Empty"
    },
    {
      "x": 0,
      "y": 10,
      "z": -1,
      "name": "Rock_Quartzite"
    },
    {
      "x": 0,
      "y": -3,
      "z": 0,
      "name": "Rock_Stone"
    },
    {
      "x": 0,
      "y": -2,
      "z": 0,
      "name": "Rock_Stone"
    },
    {
      "x": 0,
      "y": -1,
      "z": 0,
      "name": "Rock_Stone"
    },
    {
      "x": 0,
      "y": 0,
      "z": 0,
      "name": "Rock_Stone_Brick"
    },
    {
      "x": 0,
      "y": 1,
      "z": 0,
      "name": "Empty"
    },
    {
      "x": 0,
      "y": 2,
      "z": 0,
      "name": "Empty"
    },
    {
      "x": 0,
      "y": 3,
      "z": 0,
      "name": "Empty"
    },
    {
      "x": 0,
      "y": 4,
      "z": 0,
      "name": "Empty"
    },
    {
      "x": 0,
      "y": 5,
      "z": 0,
      "name": "Empty"
    },
    {
      "x": 0,
      "y": 6,
      "z": 0,
      "name": "Empty"
    },
    {
      "x": 0,
      "y": 7,
      "z": 0,
      "name": "Empty"
    },
    {
      "x": 0,
      "y": 8,
      "z": 0,
      "name": "Empty"
    },
    {
      "x": 0,
      "y": 9,
      "z": 0,
      "name": "Rock_Quartzite_Brick_Half",
      "rotation": 8
    },
    {
      "x": 0,
      "y": 10,
      "z": 0,
      "name": "Rock_Quartzite"
    },
    {
      "x": 1,
      "y": -3,
      "z": -10,
      "name": "Rock_Stone"
    },
    {
      "x": 1,
      "y": -2,
      "z": -10,
      "name": "Rock_Stone"
    },
    {
      "x": 1,
      "y": -1,
      "z": -10,
      "name": "Rock_Stone"
    },
    {
      "x": 1,
      "y": 0,
      "z": -10,
      "name": "Rock_Stone_Cobble"
    },
    {
      "x": 1,
      "y": 1,
      "z": -10,
      "name": "Empty"
    },
    {
      "x": 1,
      "y": 2,
      "z": -10,
      "name": "Empty"
    },
    {
      "x": 1,
      "y": 3,
      "z": -10,
      "name": "Empty"
    },
    {
      "x": 1,
      "y": 4,
      "z": -10,
      "name": "Empty"
    },
    {
      "x": 1,
      "y": 5,
      "z": -10,
      "name": "Empty"
    },
    {
      "x": 1,
      "y": 6,
      "z": -10,
      "name": "Empty"
    },
    {
      "x": 1,
      "y": 7,
      "z": -10,
      "name": "Empty"
    },
    {
      "x": 1,
      "y": 8,
      "z": -10,
      "name": "Empty"
    },
    {
      "x": 1,
      "y": 9,
      "z": -10,
      "name": "Rock_Quartzite_Brick_Half",
      "rotation": 8
    },
    {
      "x": 1,
      "y": 10,
      "z": -10,
      "name": "Rock_Quartzite"
    },
    {
      "x": 1,
      "y": -3,
      "z": -9,
      "name": "Rock_Stone"
    },
    {
      "x": 1,
      "y": -2,
      "z": -9,
      "name": "Rock_Stone"
    },
    {
      "x": 1,
      "y": -1,
      "z": -9,
      "name": "Rock_Stone"
    },
    {
      "x": 1,
      "y": 0,
      "z": -9,
      "name": "Rock_Stone_Brick_Smooth"
    },
    {
      "x": 1,
      "y": 1,
      "z": -9,
      "name": "Empty"
    },
    {
      "x": 1,
      "y": 2,
      "z": -9,
      "name": "Empty"
    },
    {
      "x": 1,
      "y": 3,
      "z": -9,
      "name": "Empty"
    },
    {
      "x": 1,
      "y": 4,
      "z": -9,
      "name": "Empty"
    },
    {
      "x": 1,
      "y": 5,
      "z": -9,
      "name": "Rock_Stone_Brick_Half",
      "rotation": 7
    },
    {
      "x": 1,
      "y": 6,
      "z": -9,
      "name": "Empty"
    },
    {
      "x": 1,
      "y": 7,
      "z": -9,
      "name": "Empty"
    },
    {
      "x": 1,
      "y": 8,
      "z": -9,
      "name": "Empty"
    },
    {
      "x": 1,
      "y": 9,
      "z": -9,
      "name": "Rock_Quartzite_Brick_Half",
      "rotation": 8
    },
    {
      "x": 1,
      "y": 10,
      "z": -9,
      "name": "Rock_Quartzite"
    },
    {
      "x": 1,
      "y": -3,
      "z": -8,
      "name": "Rock_Stone_Cobble"
    },
    {
      "x": 1,
      "y": -2,
      "z": -8,
      "name": "Empty"
    },
    {
      "x": 1,
      "y": -1,
      "z": -8,
      "name": "Empty"
    },
    {
      "x": 1,
      "y": 0,
      "z": -8,
      "name": "Empty"
    },
    {
      "x": 1,
      "y": 1,
      "z": -8,
      "name": "Empty"
    },
    {
      "x": 1,
      "y": 2,
      "z": -8,
      "name": "Empty"
    },
    {
      "x": 1,
      "y": 3,
      "z": -8,
      "name": "Empty"
    },
    {
      "x": 1,
      "y": 4,
      "z": -8,
      "name": "Empty"
    },
    {
      "x": 1,
      "y": 5,
      "z": -8,
      "name": "Empty"
    },
    {
      "x": 1,
      "y": 6,
      "z": -8,
      "name": "Empty"
    },
    {
      "x": 1,
      "y": 7,
      "z": -8,
      "name": "Empty"
    },
    {
      "x": 1,
      "y": 8,
      "z": -8,
      "name": "Empty"
    },
    {
      "x": 1,
      "y": 9,
      "z": -8,
      "name": "Empty"
    },
    {
      "x": 1,
      "y": 10,
      "z": -8,
      "name": "Rock_Quartzite"
    },
    {
      "x": 1,
      "y": -3,
      "z": -7,
      "name": "Rock_Stone"
    },
    {
      "x": 1,
      "y": -2,
      "z": -7,
      "name": "Survival_Trap_Spike_Iron"
    },
    {
      "x": 1,
      "y": -1,
      "z": -7,
      "name": "Empty"
    },
    {
      "x": 1,
      "y": 0,
      "z": -7,
      "name": "Empty"
    },
    {
      "x": 1,
      "y": 1,
      "z": -7,
      "name": "Empty"
    },
    {
      "x": 1,
      "y": 2,
      "z": -7,
      "name": "Empty"
    },
    {
      "x": 1,
      "y": 3,
      "z": -7,
      "name": "Empty"
    },
    {
      "x": 1,
      "y": 4,
      "z": -7,
      "name": "Empty"
    },
    {
      "x": 1,
      "y": 5,
      "z": -7,
      "name": "Empty"
    },
    {
      "x": 1,
      "y": 6,
      "z": -7,
      "name": "Empty"
    },
    {
      "x": 1,
      "y": 7,
      "z": -7,
      "name": "Empty"
    },
    {
      "x": 1,
      "y": 8,
      "z": -7,
      "name": "Empty"
    },
    {
      "x": 1,
      "y": 9,
      "z": -7,
      "name": "Empty"
    },
    {
      "x": 1,
      "y": 10,
      "z": -7,
      "name": "Rock_Quartzite"
    },
    {
      "x": 1,
      "y": -3,
      "z": -6,
      "name": "Rock_Stone_Cobble"
    },
    {
      "x": 1,
      "y": -2,
      "z": -6,
      "name": "Empty"
    },
    {
      "x": 1,
      "y": -1,
      "z": -6,
      "name": "Empty"
    },
    {
      "x": 1,
      "y": 0,
      "z": -6,
      "name": "Empty"
    },
    {
      "x": 1,
      "y": 1,
      "z": -6,
      "name": "Empty"
    },
    {
      "x": 1,
      "y": 2,
      "z": -6,
      "name": "Empty"
    },
    {
      "x": 1,
      "y": 3,
      "z": -6,
      "name": "Empty"
    },
    {
      "x": 1,
      "y": 4,
      "z": -6,
      "name": "Empty"
    },
    {
      "x": 1,
      "y": 5,
      "z": -6,
      "name": "Empty"
    },
    {
      "x": 1,
      "y": 6,
      "z": -6,
      "name": "Empty"
    },
    {
      "x": 1,
      "y": 7,
      "z": -6,
      "name": "Empty"
    },
    {
      "x": 1,
      "y": 8,
      "z": -6,
      "name": "Empty"
    },
    {
      "x": 1,
      "y": 9,
      "z": -6,
      "name": "Empty"
    },
    {
      "x": 1,
      "y": 10,
      "z": -6,
      "name": "Rock_Quartzite"
    },
    {
      "x": 1,
      "y": -3,
      "z": -5,
      "name": "Rock_Stone"
    },
    {
      "x": 1,
      "y": -2,
      "z": -5,
      "name": "Rock_Stone_Brick_Pillar_Base"
    },
    {
      "x": 1,
      "y": -1,
      "z": -5,
      "name": "Rock_Stone_Brick_Pillar_Middle"
    },
    {
      "x": 1,
      "y": 0,
      "z": -5,
      "name": "Empty"
    },
    {
      "x": 1,
      "y": 1,
      "z": -5,
      "name": "Empty"
    },
    {
      "x": 1,
      "y": 2,
      "z": -5,
      "name": "Empty"
    },
    {
      "x": 1,
      "y": 3,
      "z": -5,
      "name": "Empty"
    },
    {
      "x": 1,
      "y": 4,
      "z": -5,
      "name": "Empty"
    },
    {
      "x": 1,
      "y": 5,
      "z": -5,
      "name": "Empty"
    },
    {
      "x": 1,
      "y": 6,
      "z": -5,
      "name": "Empty"
    },
    {
      "x": 1,
      "y": 7,
      "z": -5,
      "name": "Empty"
    },
    {
      "x": 1,
      "y": 8,
      "z": -5,
      "name": "Empty"
    },
    {
      "x": 1,
      "y": 9,
      "z": -5,
      "name": "Rock_Quartzite_Brick"
    },
    {
      "x": 1,
      "y": 10,
      "z": -5,
      "name": "Rock_Quartzite"
    },
    {
      "x": 1,
      "y": -3,
      "z": -4,
      "name": "Rock_Stone_Cobble"
    },
    {
      "x": 1,
      "y": -2,
      "z": -4,
      "name": "Empty"
    },
    {
      "x": 1,
      "y": -1,
      "z": -4,
      "name": "Empty"
    },
    {
      "x": 1,
      "y": 0,
      "z": -4,
      "name": "Empty"
    },
    {
      "x": 1,
      "y": 1,
      "z": -4,
      "name": "Empty"
    },
    {
      "x": 1,
      "y": 2,
      "z": -4,
      "name": "Empty"
    },
    {
      "x": 1,
      "y": 3,
      "z": -4,
      "name": "Empty"
    },
    {
      "x": 1,
      "y": 4,
      "z": -4,
      "name": "Empty"
    },
    {
      "x": 1,
      "y": 5,
      "z": -4,
      "name": "Empty"
    },
    {
      "x": 1,
      "y": 6,
      "z": -4,
      "name": "Empty"
    },
    {
      "x": 1,
      "y": 7,
      "z": -4,
      "name": "Empty"
    },
    {
      "x": 1,
      "y": 8,
      "z": -4,
      "name": "Empty"
    },
    {
      "x": 1,
      "y": 9,
      "z": -4,
      "name": "Rock_Quartzite_Brick"
    },
    {
      "x": 1,
      "y": 10,
      "z": -4,
      "name": "Rock_Quartzite"
    },
    {
      "x": 1,
      "y": -3,
      "z": -3,
      "name": "Rock_Stone_Cobble"
    },
    {
      "x": 1,
      "y": -2,
      "z": -3,
      "name": "Empty"
    },
    {
      "x": 1,
      "y": -1,
      "z": -3,
      "name": "Empty"
    },
    {
      "x": 1,
      "y": 0,
      "z": -3,
      "name": "Rock_Stone_Brick_Smooth_Half",
      "rotation": 6
    },
    {
      "x": 1,
      "y": 1,
      "z": -3,
      "name": "Empty"
    },
    {
      "x": 1,
      "y": 2,
      "z": -3,
      "name": "Empty"
    },
    {
      "x": 1,
      "y": 3,
      "z": -3,
      "name": "Empty"
    },
    {
      "x": 1,
      "y": 4,
      "z": -3,
      "name": "Empty"
    },
    {
      "x": 1,
      "y": 5,
      "z": -3,
      "name": "Empty"
    },
    {
      "x": 1,
      "y": 6,
      "z": -3,
      "name": "Wood_Beech_Roots"
    },
    {
      "x": 1,
      "y": 7,
      "z": -3,
      "name": "Wood_Beech_Trunk",
      "rotation": 5
    },
    {
      "x": 1,
      "y": 8,
      "z": -3,
      "name": "Empty"
    },
    {
      "x": 1,
      "y": 9,
      "z": -3,
      "name": "Empty"
    },
    {
      "x": 1,
      "y": 10,
      "z": -3,
      "name": "Rock_Quartzite"
    },
    {
      "x": 1,
      "y": -3,
      "z": -2,
      "name": "Rock_Stone_Cobble"
    },
    {
      "x": 1,
      "y": -2,
      "z": -2,
      "name": "Empty"
    },
    {
      "x": 1,
      "y": -1,
      "z": -2,
      "name": "Empty"
    },
    {
      "x": 1,
      "y": 0,
      "z": -2,
      "name": "Rock_Stone_Brick_Smooth"
    },
    {
      "x": 1,
      "y": 1,
      "z": -2,
      "name": "Empty"
    },
    {
      "x": 1,
      "y": 2,
      "z": -2,
      "name": "Empty"
    },
    {
      "x": 1,
      "y": 3,
      "z": -2,
      "name": "Empty"
    },
    {
      "x": 1,
      "y": 4,
      "z": -2,
      "name": "Rock_Stone_Brick"
    },
    {
      "x": 1,
      "y": 5,
      "z": -2,
      "name": "Rock_Stone_Brick"
    },
    {
      "x": 1,
      "y": 6,
      "z": -2,
      "name": "Empty"
    },
    {
      "x": 1,
      "y": 7,
      "z": -2,
      "name": "Empty"
    },
    {
      "x": 1,
      "y": 8,
      "z": -2,
      "name": "Empty"
    },
    {
      "x": 1,
      "y": 9,
      "z": -2,
      "name": "Empty"
    },
    {
      "x": 1,
      "y": 10,
      "z": -2,
      "name": "Rock_Quartzite"
    },
    {
      "x": 1,
      "y": -3,
      "z": -1,
      "name": "Rock_Stone_Cobble"
    },
    {
      "x": 1,
      "y": -2,
      "z": -1,
      "name": "Empty"
    },
    {
      "x": 1,
      "y": -1,
      "z": -1,
      "name": "Rock_Stone"
    },
    {
      "x": 1,
      "y": 0,
      "z": -1,
      "name": "Rock_Stone_Brick"
    },
    {
      "x": 1,
      "y": 1,
      "z": -1,
      "name": "Empty"
    },
    {
      "x": 1,
      "y": 2,
      "z": -1,
      "name": "Empty"
    },
    {
      "x": 1,
      "y": 3,
      "z": -1,
      "name": "Empty"
    },
    {
      "x": 1,
      "y": 4,
      "z": -1,
      "name": "Empty"
    },
    {
      "x": 1,
      "y": 5,
      "z": -1,
      "name": "Empty"
    },
    {
      "x": 1,
      "y": 6,
      "z": -1,
      "name": "Empty"
    },
    {
      "x": 1,
      "y": 7,
      "z": -1,
      "name": "Empty"
    },
    {
      "x": 1,
      "y": 8,
      "z": -1,
      "name": "Empty"
    },
    {
      "x": 1,
      "y": 9,
      "z": -1,
      "name": "Empty"
    },
    {
      "x": 1,
      "y": 10,
      "z": -1,
      "name": "Rock_Quartzite"
    },
    {
      "x": 1,
      "y": -3,
      "z": 0,
      "name": "Rock_Stone_Cobble"
    },
    {
      "x": 1,
      "y": -2,
      "z": 0,
      "name": "Rock_Stone"
    },
    {
      "x": 1,
      "y": -1,
      "z": 0,
      "name": "Rock_Stone"
    },
    {
      "x": 1,
      "y": 0,
      "z": 0,
      "name": "Rock_Stone_Cobble"
    },
    {
      "x": 1,
      "y": 1,
      "z": 0,
      "name": "Empty"
    },
    {
      "x": 1,
      "y": 2,
      "z": 0,
      "name": "Empty"
    },
    {
      "x": 1,
      "y": 3,
      "z": 0,
      "name": "Empty"
    },
    {
      "x": 1,
      "y": 4,
      "z": 0,
      "name": "Empty"
    },
    {
      "x": 1,
      "y": 5,
      "z": 0,
      "name": "Empty"
    },
    {
      "x": 1,
      "y": 6,
      "z": 0,
      "name": "Empty"
    },
    {
      "x": 1,
      "y": 7,
      "z": 0,
      "name": "Empty"
    },
    {
      "x": 1,
      "y": 8,
      "z": 0,
      "name": "Empty"
    },
    {
      "x": 1,
      "y": 9,
      "z": 0,
      "name": "Empty"
    },
    {
      "x": 1,
      "y": 10,
      "z": 0,
      "name": "Rock_Quartzite"
    },
    {
      "x": 2,
      "y": -3,
      "z": -10,
      "name": "Rock_Stone"
    },
    {
      "x": 2,
      "y": -2,
      "z": -10,
      "name": "Rock_Stone"
    },
    {
      "x": 2,
      "y": -1,
      "z": -10,
      "name": "Rock_Stone"
    },
    {
      "x": 2,
      "y": 0,
      "z": -10,
      "name": "Rock_Stone_Cobble"
    },
    {
      "x": 2,
      "y": 1,
      "z": -10,
      "name": "Empty"
    },
    {
      "x": 2,
      "y": 2,
      "z": -10,
      "name": "Empty"
    },
    {
      "x": 2,
      "y": 3,
      "z": -10,
      "name": "Empty"
    },
    {
      "x": 2,
      "y": 4,
      "z": -10,
      "name": "Empty"
    },
    {
      "x": 2,
      "y": 5,
      "z": -10,
      "name": "Empty"
    },
    {
      "x": 2,
      "y": 6,
      "z": -10,
      "name": "Empty"
    },
    {
      "x": 2,
      "y": 7,
      "z": -10,
      "name": "Empty"
    },
    {
      "x": 2,
      "y": 8,
      "z": -10,
      "name": "Empty"
    },
    {
      "x": 2,
      "y": 9,
      "z": -10,
      "name": "Rock_Quartzite_Brick"
    },
    {
      "x": 2,
      "y": 10,
      "z": -10,
      "name": "Rock_Quartzite"
    },
    {
      "x": 2,
      "y": -3,
      "z": -9,
      "name": "Rock_Stone"
    },
    {
      "x": 2,
      "y": -2,
      "z": -9,
      "name": "Rock_Stone"
    },
    {
      "x": 2,
      "y": -1,
      "z": -9,
      "name": "Rock_Stone"
    },
    {
      "x": 2,
      "y": 0,
      "z": -9,
      "name": "Rock_Stone_Brick_Smooth"
    },
    {
      "x": 2,
      "y": 1,
      "z": -9,
      "name": "Rock_Stone_Brick_Pillar_Base"
    },
    {
      "x": 2,
      "y": 2,
      "z": -9,
      "name": "Rock_Stone_Brick_Pillar_Middle"
    },
    {
      "x": 2,
      "y": 3,
      "z": -9,
      "name": "Rock_Stone_Brick_Pillar_Base",
      "rotation": 8
    },
    {
      "x": 2,
      "y": 4,
      "z": -9,
      "name": "Rock_Stone_Brick"
    },
    {
      "x": 2,
      "y": 5,
      "z": -9,
      "name": "Rock_Stone_Brick"
    },
    {
      "x": 2,
      "y": 6,
      "z": -9,
      "name": "Empty"
    },
    {
      "x": 2,
      "y": 7,
      "z": -9,
      "name": "Empty"
    },
    {
      "x": 2,
      "y": 8,
      "z": -9,
      "name": "Empty"
    },
    {
      "x": 2,
      "y": 9,
      "z": -9,
      "name": "Rock_Quartzite_Brick"
    },
    {
      "x": 2,
      "y": 10,
      "z": -9,
      "name": "Rock_Quartzite"
    },
    {
      "x": 2,
      "y": -3,
      "z": -8,
      "name": "Rock_Stone"
    },
    {
      "x": 2,
      "y": -2,
      "z": -8,
      "name": "Rock_Stone"
    },
    {
      "x": 2,
      "y": -1,
      "z": -8,
      "name": "Empty"
    },
    {
      "x": 2,
      "y": 0,
      "z": -8,
      "name": "Rock_Stone_Brick_Smooth_Half",
      "rotation": 4
    },
    {
      "x": 2,
      "y": 1,
      "z": -8,
      "name": "Empty"
    },
    {
      "x": 2,
      "y": 2,
      "z": -8,
      "name": "Empty"
    },
    {
      "x": 2,
      "y": 3,
      "z": -8,
      "name": "Empty"
    },
    {
      "x": 2,
      "y": 4,
      "z": -8,
      "name": "Empty"
    },
    {
      "x": 2,
      "y": 5,
      "z": -8,
      "name": "Rock_Stone_Brick_Half",
      "rotation": 4
    },
    {
      "x": 2,
      "y": 6,
      "z": -8,
      "name": "Empty"
    },
    {
      "x": 2,
      "y": 7,
      "z": -8,
      "name": "Empty"
    },
    {
      "x": 2,
      "y": 8,
      "z": -8,
      "name": "Empty"
    },
    {
      "x": 2,
      "y": 9,
      "z": -8,
      "name": "Rock_Quartzite_Brick"
    },
    {
      "x": 2,
      "y": 10,
      "z": -8,
      "name": "Rock_Quartzite"
    },
    {
      "x": 2,
      "y": -3,
      "z": -7,
      "name": "Rock_Stone"
    },
    {
      "x": 2,
      "y": -2,
      "z": -7,
      "name": "Survival_Trap_Spike_Iron"
    },
    {
      "x": 2,
      "y": -1,
      "z": -7,
      "name": "Empty"
    },
    {
      "x": 2,
      "y": 0,
      "z": -7,
      "name": "Empty"
    },
    {
      "x": 2,
      "y": 1,
      "z": -7,
      "name": "Empty"
    },
    {
      "x": 2,
      "y": 2,
      "z": -7,
      "name": "Empty"
    },
    {
      "x": 2,
      "y": 3,
      "z": -7,
      "name": "Empty"
    },
    {
      "x": 2,
      "y": 4,
      "z": -7,
      "name": "Empty"
    },
    {
      "x": 2,
      "y": 5,
      "z": -7,
      "name": "Empty"
    },
    {
      "x": 2,
      "y": 6,
      "z": -7,
      "name": "Empty"
    },
    {
      "x": 2,
      "y": 7,
      "z": -7,
      "name": "Empty"
    },
    {
      "x": 2,
      "y": 8,
      "z": -7,
      "name": "Empty"
    },
    {
      "x": 2,
      "y": 9,
      "z": -7,
      "name": "Empty"
    },
    {
      "x": 2,
      "y": 10,
      "z": -7,
      "name": "Rock_Quartzite"
    },
    {
      "x": 2,
      "y": -3,
      "z": -6,
      "name": "Rock_Stone_Cobble"
    },
    {
      "x": 2,
      "y": -2,
      "z": -6,
      "name": "Empty"
    },
    {
      "x": 2,
      "y": -1,
      "z": -6,
      "name": "Empty"
    },
    {
      "x": 2,
      "y": 0,
      "z": -6,
      "name": "Empty"
    },
    {
      "x": 2,
      "y": 1,
      "z": -6,
      "name": "Empty"
    },
    {
      "x": 2,
      "y": 2,
      "z": -6,
      "name": "Empty"
    },
    {
      "x": 2,
      "y": 3,
      "z": -6,
      "name": "Empty"
    },
    {
      "x": 2,
      "y": 4,
      "z": -6,
      "name": "Empty"
    },
    {
      "x": 2,
      "y": 5,
      "z": -6,
      "name": "Empty"
    },
    {
      "x": 2,
      "y": 6,
      "z": -6,
      "name": "Empty"
    },
    {
      "x": 2,
      "y": 7,
      "z": -6,
      "name": "Empty"
    },
    {
      "x": 2,
      "y": 8,
      "z": -6,
      "name": "Empty"
    },
    {
      "x": 2,
      "y": 9,
      "z": -6,
      "name": "Rock_Quartzite_Brick"
    },
    {
      "x": 2,
      "y": 10,
      "z": -6,
      "name": "Rock_Quartzite"
    },
    {
      "x": 2,
      "y": -3,
      "z": -5,
      "name": "Rock_Stone_Cobble"
    },
    {
      "x": 2,
      "y": -2,
      "z": -5,
      "name": "Empty"
    },
    {
      "x": 2,
      "y": -1,
      "z": -5,
      "name": "Empty"
    },
    {
      "x": 2,
      "y": 0,
      "z": -5,
      "name": "Empty"
    },
    {
      "x": 2,
      "y": 1,
      "z": -5,
      "name": "Empty"
    },
    {
      "x": 2,
      "y": 2,
      "z": -5,
      "name": "Empty"
    },
    {
      "x": 2,
      "y": 3,
      "z": -5,
      "name": "Empty"
    },
    {
      "x": 2,
      "y": 4,
      "z": -5,
      "name": "Empty"
    },
    {
      "x": 2,
      "y": 5,
      "z": -5,
      "name": "Empty"
    },
    {
      "x": 2,
      "y": 6,
      "z": -5,
      "name": "Empty"
    },
    {
      "x": 2,
      "y": 7,
      "z": -5,
      "name": "Empty"
    },
    {
      "x": 2,
      "y": 8,
      "z": -5,
      "name": "Empty"
    },
    {
      "x": 2,
      "y": 9,
      "z": -5,
      "name": "Rock_Quartzite_Brick"
    },
    {
      "x": 2,
      "y": 10,
      "z": -5,
      "name": "Rock_Quartzite"
    },
    {
      "x": 2,
      "y": -3,
      "z": -4,
      "name": "Rock_Stone_Cobble"
    },
    {
      "x": 2,
      "y": -2,
      "z": -4,
      "name": "Empty"
    },
    {
      "x": 2,
      "y": -1,
      "z": -4,
