{
  "version": 8,
  "blockIdVersion": 8,
  "anchorX": -1,
  "anchorY": 11,
  "anchorZ": 1,
  "blocks": [
    {
      "x": -3,
      "y": 8,
      "z": 0,
      "name": "Rock_Shale"
    },
    {
      "x": -3,
      "y": 9,
      "z": 0,
      "name": "Rock_Shale"
    },
    {
      "x": -3,
      "y": 10,
      "z": 0,
      "name": "Rock_Shale"
    },
    {
      "x": -3,
      "y": 11,
      "z": 0,
      "name": "Rock_Shale"
    },
    {
      "x": -3,
      "y": 8,
      "z": 1,
      "name": "Rock_Shale"
    },
    {
      "x": -3,
      "y": 9,
      "z": 1,
      "name": "Rock_Shale"
    },
    {
      "x": -3,
      "y": 10,
      "z": 1,
      "name": "Rock_Shale"
    },
    {
      "x": -3,
      "y": 11,
      "z": 1,
      "name": "Rock_Shale"
    },
    {
      "x": -3,
      "y": 12,
      "z": 1,
      "name": "Rock_Shale"
    },
    {
      "x": -3,
      "y": 13,
      "z": 1,
      "name": "Rock_Shale"
    },
    {
      "x": -3,
      "y": 8,
      "z": 2,
      "name": "Rock_Shale"
    },
    {
      "x": -3,
      "y": 9,
      "z": 2,
      "name": "Rock_Shale"
    },
    {
      "x": -3,
      "y": 10,
      "z": 2,
      "name": "Rock_Shale"
    },
    {
      "x": -3,
      "y": 11,
      "z": 2,
      "name": "Rock_Shale"
    },
    {
      "x": -3,
      "y": 12,
      "z": 2,
      "name": "Rock_Shale"
    },
    {
      "x": -3,
      "y": 13,
      "z": 2,
      "name": "Rock_Shale"
    },
    {
      "x": -3,
      "y": 14,
      "z": 2,
      "name": "Rock_Shale"
    },
    {
      "x": -3,
      "y": 10,
      "z": 3,
      "name": "Rock_Shale"
    },
    {
      "x": -3,
      "y": 11,
      "z": 3,
      "name": "Rock_Shale"
    },
    {
      "x": -3,
      "y": 12,
      "z": 3,
      "name": "Rock_Shale"
    },
    {
      "x": -3,
      "y": 13,
      "z": 3,
      "name": "Rock_Shale"
    },
    {
      "x": -3,
      "y": 14,
      "z": 3,
      "name": "Rock_Shale"
    },
    {
      "x": -2,
      "y": 8,
      "z": -1,
      "name": "Rock_Shale"
    },
    {
      "x": -2,
      "y": 9,
      "z": -1,
      "name": "Rock_Shale"
    },
    {
      "x": -2,
      "y": 10,
      "z": -1,
      "name": "Rock_Shale"
    },
    {
      "x": -2,
      "y": 11,
      "z": -1,
      "name": "Rock_Shale"
    },
    {
      "x": -2,
      "y": 7,
      "z": 0,
      "name": "Rock_Shale"
    },
    {
      "x": -2,
      "y": 8,
      "z": 0,
      "name": "Rock_Shale"
    },
    {
      "x": -2,
      "y": 9,
      "z": 0,
      "name": "Rock_Shale"
    },
    {
      "x": -2,
      "y": 10,
      "z": 0,
      "name": "Rock_Shale"
    },
    {
      "x": -2,
      "y": 11,
      "z": 0,
      "name": "Rock_Shale"
    },
    {
      "x": -2,
      "y": 12,
      "z": 0,
      "name": "Rock_Shale"
    },
    {
      "x": -2,
      "y": 13,
      "z": 0,
      "name": "Rock_Shale"
    },
    {
      "x": -2,
      "y": 7,
      "z": 1,
      "name": "Rock_Shale"
    },
    {
      "x": -2,
      "y": 8,
      "z": 1,
      "name": "Rock_Shale"
    },
    {
      "x": -2,
      "y": 9,
      "z": 1,
      "name": "Rock_Shale"
    },
    {
      "x": -2,
      "y": 10,
      "z": 1,
      "name": "Rock_Shale"
    },
    {
      "x": -2,
      "y": 11,
      "z": 1,
      "name": "Rock_Shale"
    },
    {
      "x": -2,
      "y": 12,
      "z": 1,
      "name": "Rock_Shale"
    },
    {
      "x": -2,
      "y": 13,
      "z": 1,
      "name": "Rock_Shale"
    },
    {
      "x": -2,
      "y": 14,
      "z": 1,
      "name": "Rock_Shale"
    },
    {
      "x": -2,
      "y": 8,
      "z": 2,
      "name": "Rock_Shale"
    },
    {
      "x": -2,
      "y": 9,
      "z": 2,
      "name": "Rock_Shale"
    },
    {
      "x": -2,
      "y": 10,
      "z": 2,
      "name": "Rock_Shale"
    },
    {
      "x": -2,
      "y": 11,
      "z": 2,
      "name": "Rock_Shale"
    },
    {
      "x": -2,
      "y": 12,
      "z": 2,
      "name": "Rock_Shale"
    },
    {
      "x": -2,
      "y": 13,
      "z": 2,
      "name": "Rock_Shale"
    },
    {
      "x": -2,
      "y": 14,
      "z": 2,
      "name": "Rock_Shale"
    },
    {
      "x": -2,
      "y": 15,
      "z": 2,
      "name": "Rubble_Shale"
    },
    {
      "x": -2,
      "y": 8,
      "z": 3,
      "name": "Rock_Shale"
    },
    {
      "x": -2,
      "y": 9,
      "z": 3,
      "name": "Rock_Shale"
    },
    {
      "x": -2,
      "y": 10,
      "z": 3,
      "name": "Rock_Shale"
    },
    {
      "x": -2,
      "y": 11,
      "z": 3,
      "name": "Rock_Shale"
    },
    {
      "x": -2,
      "y": 12,
      "z": 3,
      "name": "Rock_Shale"
    },
    {
      "x": -2,
      "y": 13,
      "z": 3,
      "name": "Rock_Shale"
    },
    {
      "x": -2,
      "y": 14,
      "z": 3,
      "name": "Rock_Shale"
    },
    {
      "x": -2,
      "y": 15,
      "z": 3,
      "name": "Rubble_Shale_Medium"
    },
    {
      "x": -2,
      "y": 10,
      "z": 4,
      "name": "Rock_Shale"
    },
    {
      "x": -2,
      "y": 11,
      "z": 4,
      "name": "Rock_Shale"
    },
    {
      "x": -2,
      "y": 12,
      "z": 4,
      "name": "Rock_Shale"
    },
    {
      "x": -2,
      "y": 13,
      "z": 4,
      "name": "Rock_Shale"
    },
    {
      "x": -2,
      "y": 14,
      "z": 4,
      "name": "Rock_Shale"
    },
    {
      "x": -1,
      "y": 9,
      "z": -2,
      "name": "Rock_Shale"
    },
    {
      "x": -1,
      "y": 10,
      "z": -2,
      "name": "Rock_Shale"
    },
    {
      "x": -1,
      "y": 11,
      "z": -2,
      "name": "Rock_Shale"
    },
    {
      "x": -1,
      "y": 7,
      "z": -1,
      "name": "Rock_Shale"
    },
    {
      "x": -1,
      "y": 8,
      "z": -1,
      "name": "Rock_Shale"
    },
    {
      "x": -1,
      "y": 9,
      "z": -1,
      "name": "Rock_Shale"
    },
    {
      "x": -1,
      "y": 10,
      "z": -1,
      "name": "Rock_Shale"
    },
    {
      "x": -1,
      "y": 11,
      "z": -1,
      "name": "Rock_Shale"
    },
    {
      "x": -1,
      "y": 12,
      "z": -1,
      "name": "Rock_Shale"
    },
    {
      "x": -1,
      "y": 7,
      "z": 0,
      "name": "Rock_Shale"
    },
    {
      "x": -1,
      "y": 8,
      "z": 0,
      "name": "Rock_Shale"
    },
    {
      "x": -1,
      "y": 9,
      "z": 0,
      "name": "Rock_Shale"
    },
    {
      "x": -1,
      "y": 10,
      "z": 0,
      "name": "Rock_Shale"
    },
    {
      "x": -1,
      "y": 11,
      "z": 0,
      "name": "Rock_Shale"
    },
    {
      "x": -1,
      "y": 12,
      "z": 0,
      "name": "Rock_Shale"
    },
    {
      "x": -1,
      "y": 13,
      "z": 0,
      "name": "Rock_Shale"
    },
    {
      "x": -1,
      "y": 7,
      "z": 1,
      "name": "Rock_Shale"
    },
    {
      "x": -1,
      "y": 8,
      "z": 1,
      "name": "Rock_Shale"
    },
    {
      "x": -1,
      "y": 9,
      "z": 1,
      "name": "Rock_Shale"
    },
    {
      "x": -1,
      "y": 10,
      "z": 1,
      "name": "Rock_Shale"
    },
    {
      "x": -1,
      "y": 11,
      "z": 1,
      "name": "Rock_Shale"
    },
    {
      "x": -1,
      "y": 12,
      "z": 1,
      "name": "Rock_Shale"
    },
    {
      "x": -1,
      "y": 13,
      "z": 1,
      "name": "Rock_Shale"
    },
    {
      "x": -1,
      "y": 14,
      "z": 1,
      "name": "Rock_Shale"
    },
    {
      "x": -1,
      "y": 8,
      "z": 2,
      "name": "Rock_Shale"
    },
    {
      "x": -1,
      "y": 9,
      "z": 2,
      "name": "Rock_Shale"
    },
    {
      "x": -1,
      "y": 10,
      "z": 2,
      "name": "Rock_Shale"
    },
    {
      "x": -1,
      "y": 11,
      "z": 2,
      "name": "Rock_Shale"
    },
    {
      "x": -1,
      "y": 12,
      "z": 2,
      "name": "Rock_Shale"
    },
    {
      "x": -1,
      "y": 13,
      "z": 2,
      "name": "Rock_Shale"
    },
    {
      "x": -1,
      "y": 14,
      "z": 2,
      "name": "Rock_Shale"
    },
    {
      "x": -1,
      "y": 8,
      "z": 3,
      "name": "Rock_Shale"
    },
    {
      "x": -1,
      "y": 9,
      "z": 3,
      "name": "Rock_Shale"
    },
    {
      "x": -1,
      "y": 10,
      "z": 3,
      "name": "Rock_Shale"
    },
    {
      "x": -1,
      "y": 11,
      "z": 3,
      "name": "Rock_Shale"
    },
    {
      "x": -1,
      "y": 12,
      "z": 3,
      "name": "Rock_Shale"
    },
    {
      "x": -1,
      "y": 13,
      "z": 3,
      "name": "Rock_Shale"
    },
    {
      "x": -1,
      "y": 14,
      "z": 3,
      "name": "Rock_Shale"
    },
    {
      "x": -1,
      "y": 8,
      "z": 4,
      "name": "Rock_Shale"
    },
    {
      "x": -1,
      "y": 9,
      "z": 4,
      "name": "Rock_Shale"
    },
    {
      "x": -1,
      "y": 10,
      "z": 4,
      "name": "Rock_Shale"
    },
    {
      "x": -1,
      "y": 11,
      "z": 4,
      "name": "Rock_Shale"
    },
    {
      "x": -1,
      "y": 12,
      "z": 4,
      "name": "Rock_Shale"
    },
    {
      "x": -1,
      "y": 13,
      "z": 4,
      "name": "Rock_Shale"
    },
    {
      "x": -1,
      "y": 14,
      "z": 4,
      "name": "Rock_Shale"
    },
    {
      "x": 0,
      "y": 8,
      "z": -2,
      "name": "Rock_Shale"
    },
    {
      "x": 0,
      "y": 9,
      "z": -2,
      "name": "Rock_Shale"
    },
    {
      "x": 0,
      "y": 10,
      "z": -2,
      "name": "Rock_Shale"
    },
    {
      "x": 0,
      "y": 11,
      "z": -2,
      "name": "Rock_Shale"
    },
    {
      "x": 0,
      "y": 7,
      "z": -1,
      "name": "Rock_Shale"
    },
    {
      "x": 0,
      "y": 8,
      "z": -1,
      "name": "Rock_Shale"
    },
    {
      "x": 0,
      "y": 9,
      "z": -1,
      "name": "Rock_Shale"
    },
    {
      "x": 0,
      "y": 10,
      "z": -1,
      "name": "Rock_Shale"
    },
    {
      "x": 0,
      "y": 11,
      "z": -1,
      "name": "Rock_Shale"
    },
    {
      "x": 0,
      "y": 12,
      "z": -1,
      "name": "Rock_Shale"
    },
    {
      "x": 0,
      "y": 7,
      "z": 0,
      "name": "Rock_Shale"
    },
    {
      "x": 0,
      "y": 8,
      "z": 0,
      "name": "Rock_Shale"
    },
    {
      "x": 0,
      "y": 9,
      "z": 0,
      "name": "Rock_Shale"
    },
    {
      "x": 0,
      "y": 10,
      "z": 0,
      "name": "Rock_Shale"
    },
    {
      "x": 0,
      "y": 11,
      "z": 0,
      "name": "Rock_Shale"
    },
    {
      "x": 0,
      "y": 12,
      "z": 0,
      "name": "Rock_Shale"
    },
    {
      "x": 0,
      "y": 13,
      "z": 0,
      "name": "Rock_Shale"
    },
    {
      "x": 0,
      "y": 7,
      "z": 1,
      "name": "Rock_Shale"
    },
    {
      "x": 0,
      "y": 8,
      "z": 1,
      "name": "Rock_Shale"
    },
    {
      "x": 0,
      "y": 9,
      "z": 1,
      "name": "Rock_Shale"
    },
    {
      "x": 0,
      "y": 10,
      "z": 1,
      "name": "Rock_Shale"
    },
    {
      "x": 0,
      "y": 11,
      "z": 1,
      "name": "Rock_Shale"
    },
    {
      "x": 0,
      "y": 12,
      "z": 1,
      "name": "Rock_Shale"
    },
    {
      "x": 0,
      "y": 13,
      "z": 1,
      "name": "Rock_Shale"
    },
    {
      "x": 0,
      "y": 14,
      "z": 1,
      "name": "Rock_Shale"
    },
    {
      "x": 0,
      "y": 15,
      "z": 1,
      "name": "Rubble_Shale"
    },
    {
      "x": 0,
      "y": 7,
      "z": 2,
      "name": "Rock_Shale"
    },
    {
      "x": 0,
      "y": 8,
      "z": 2,
      "name": "Rock_Shale"
    },
    {
      "x": 0,
      "y": 9,
      "z": 2,
      "name": "Rock_Shale"
    },
    {
      "x": 0,
      "y": 10,
      "z": 2,
      "name": "Rock_Shale"
    },
    {
      "x": 0,
      "y": 11,
      "z": 2,
      "name": "Rock_Shale"
    },
    {
      "x": 0,
      "y": 12,
      "z": 2,
      "name": "Rock_Shale"
    },
    {
      "x": 0,
      "y": 13,
      "z": 2,
      "name": "Rock_Shale"
    },
    {
      "x": 0,
      "y": 14,
      "z": 2,
      "name": "Rock_Shale"
    },
    {
      "x": 0,
      "y": 8,
      "z": 3,
      "name": "Rock_Shale"
    },
    {
      "x": 0,
      "y": 9,
      "z": 3,
      "name": "Rock_Shale"
    },
    {
      "x": 0,
      "y": 10,
      "z": 3,
      "name": "Rock_Shale"
    },
    {
      "x": 0,
      "y": 11,
      "z": 3,
      "name": "Rock_Shale"
    },
    {
      "x": 0,
      "y": 12,
      "z": 3,
      "name": "Rock_Shale"
    },
    {
      "x": 0,
      "y": 13,
      "z": 3,
      "name": "Rock_Shale"
    },
    {
      "x": 0,
      "y": 14,
      "z": 3,
      "name": "Rock_Shale"
    },
    {
      "x": 0,
      "y": 8,
      "z": 4,
      "name": "Rock_Shale"
    },
    {
      "x": 0,
      "y": 9,
      "z": 4,
      "name": "Rock_Shale"
    },
    {
      "x": 0,
      "y": 10,
      "z": 4,
      "name": "Rock_Shale"
    },
    {
      "x": 0,
      "y": 11,
      "z": 4,
      "name": "Rock_Shale"
    },
    {
      "x": 0,
      "y": 12,
      "z": 4,
      "name": "Rock_Shale"
    },
    {
      "x": 0,
      "y": 13,
      "z": 4,
      "name": "Rock_Shale"
    },
    {
      "x": 1,
      "y": 8,
      "z": -2,
      "name": "Rock_Shale"
    },
    {
      "x": 1,
      "y": 9,
      "z": -2,
      "name": "Rock_Shale"
    },
    {
      "x": 1,
      "y": 10,
      "z": -2,
      "name": "Rock_Shale"
    },
    {
      "x": 1,
      "y": 7,
      "z": -1,
      "name": "Rock_Shale"
    },
    {
      "x": 1,
      "y": 8,
      "z": -1,
      "name": "Rock_Shale"
    },
    {
      "x": 1,
      "y": 9,
      "z": -1,
      "name": "Rock_Shale"
    },
    {
      "x": 1,
      "y": 10,
      "z": -1,
      "name": "Rock_Shale"
    },
    {
      "x": 1,
      "y": 11,
      "z": -1,
      "name": "Rock_Shale"
    },
    {
      "x": 1,
      "y": 12,
      "z": -1,
      "name": "Rock_Shale"
    },
    {
      "x": 1,
      "y": 7,
      "z": 0,
      "name": "Rock_Shale"
    },
    {
      "x": 1,
      "y": 8,
      "z": 0,
      "name": "Rock_Shale"
    },
    {
      "x": 1,
      "y": 9,
      "z": 0,
      "name": "Rock_Shale"
    },
    {
      "x": 1,
      "y": 10,
      "z": 0,
      "name": "Rock_Shale"
    },
    {
      "x": 1,
      "y": 11,
      "z": 0,
      "name": "Rock_Shale"
    },
    {
      "x": 1,
      "y": 12,
      "z": 0,
      "name": "Rock_Shale"
    },
    {
      "x": 1,
      "y": 7,
      "z": 1,
      "name": "Rock_Shale"
    },
    {
      "x": 1,
      "y": 8,
      "z": 1,
      "name": "Rock_Shale"
    },
    {
      "x": 1,
      "y": 9,
      "z": 1,
      "name": "Rock_Shale"
    },
    {
      "x": 1,
      "y": 10,
      "z": 1,
      "name": "Rock_Shale"
    },
    {
      "x": 1,
      "y": 11,
      "z": 1,
      "name": "Rock_Shale"
    },
    {
      "x": 1,
      "y": 12,
      "z": 1,
      "name": "Rock_Shale"
    },
    {
      "x": 1,
      "y": 13,
      "z": 1,
      "name": "Rock_Shale"
    },
    {
      "x": 1,
      "y": 7,
      "z": 2,
      "name": "Rock_Shale"
    },
    {
      "x": 1,
      "y": 8,
      "z": 2,
      "name": "Rock_Shale"
    },
    {
      "x": 1,
      "y": 9,
      "z": 2,
      "name": "Rock_Shale"
    },
    {
      "x": 1,
      "y": 10,
      "z": 2,
      "name": "Rock_Shale"
    },
    {
      "x": 1,
      "y": 11,
      "z": 2,
      "name": "Rock_Shale"
    },
    {
      "x": 1,
      "y": 12,
      "z": 2,
      "name": "Rock_Shale"
    },
    {
      "x": 1,
      "y": 13,
      "z": 2,
      "name": "Rock_Shale"
    },
    {
      "x": 1,
      "y": 8,
      "z": 3,
      "name": "Rock_Shale"
    },
    {
      "x": 1,
      "y": 9,
      "z": 3,
      "name": "Rock_Shale"
    },
    {
      "x": 1,
      "y": 10,
      "z": 3,
      "name": "Rock_Shale"
    },
    {
      "x": 1,
      "y": 11,
      "z": 3,
      "name": "Rock_Shale"
    },
    {
      "x": 1,
      "y": 12,
      "z": 3,
      "name": "Rock_Shale"
    },
    {
      "x": 1,
      "y": 8,
      "z": 4,
      "name": "Rock_Shale"
    },
    {
      "x": 1,
      "y": 9,
      "z": 4,
      "name": "Rock_Shale"
    },
    {
      "x": 1,
      "y": 10,
      "z": 4,
      "name": "Rock_Shale"
    },
    {
      "x": 1,
      "y": 11,
      "z": 4,
      "name": "Rock_Shale"
    },
    {
      "x": 2,
      "y": 8,
      "z": -1,
      "name": "Rock_Shale"
    },
    {
      "x": 2,
      "y": 9,
      "z": -1,
      "name": "Rock_Shale"
    },
    {
      "x": 2,
      "y": 10,
      "z": -1,
      "name": "Rock_Shale"
    },
    {
      "x": 2,
      "y": 11,
      "z": -1,
      "name": "Rock_Shale"
    },
    {
      "x": 2,
      "y": 8,
      "z": 0,
      "name": "Rock_Shale"
    },
    {
      "x": 2,
      "y": 9,
      "z": 0,
      "name": "Rock_Shale"
    },
    {
      "x": 2,
      "y": 10,
      "z": 0,
      "name": "Rock_Shale"
    },
    {
      "x": 2,
      "y": 11,
      "z": 0,
      "name": "Rock_Shale"
    },
    {
      "x": 2,
      "y": 7,
      "z": 1,
      "name": "Rock_Shale"
    },
    {
      "x": 2,
      "y": 8,
      "z": 1,
      "name": "Rock_Shale"
    },
    {
      "x": 2,
      "y": 9,
      "z": 1,
      "name": "Rock_Shale"
    },
    {
      "x": 2,
      "y": 10,
      "z": 1,
      "name": "Rock_Shale"
    },
    {
      "x": 2,
      "y": 11,
      "z": 1,
      "name": "Rock_Shale"
    },
    {
      "x": 2,
      "y": 12,
      "z": 1,
      "name": "Rock_Shale"
    },
    {
      "x": 2,
      "y": 7,
      "z": 2,
      "name": "Rock_Shale"
    },
    {
      "x": 2,
      "y": 8,
      "z": 2,
      "name": "Rock_Shale"
    },
    {
      "x": 2,
      "y": 9,
      "z": 2,
      "name": "Rock_Shale"
    },
    {
      "x": 2,
      "y": 10,
      "z": 2,
      "name": "Rock_Shale"
    },
    {
      "x": 2,
      "y": 11,
      "z": 2,
      "name": "Rock_Shale"
    },
    {
      "x": 2,
      "y": 12,
      "z": 2,
      "name": "Rock_Shale"
    },
    {
      "x": 2,
      "y": 8,
      "z": 3,
      "name": "Rock_Shale"
    },
    {
      "x": 2,
      "y": 9,
      "z": 3,
      "name": "Rock_Shale"
    },
    {
      "x": 2,
      "y": 10,
      "z": 3,
      "name": "Rock_Shale"
    },
    {
      "x": 2,
      "y": 11,
      "z": 3,
      "name": "Rock_Shale"
    },
    {
      "x": 3,
      "y": 8,
      "z": 0,
      "name": "Rock_Shale"
    },
    {
      "x": 3,
      "y": 9,
      "z": 0,
      "name": "Rock_Shale"
    },
    {
      "x": 3,
      "y": 10,
      "z": 0,
      "name": "Rock_Shale"
    },
    {
      "x": 3,
      "y": 8,
      "z": 1,
      "name": "Rock_Shale"
    },
    {
      "x": 3,
      "y": 9,
      "z": 1,
      "name": "Rock_Shale"
    },
    {
      "x": 3,
      "y": 10,
      "z": 1,
      "name": "Rock_Shale"
    },
    {
      "x": 3,
      "y": 11,
      "z": 1,
      "name": "Rock_Shale"
    },
    {
      "x": 3,
      "y": 9,
      "z": 2,
      "name": "Rock_Shale"
    },
    {
      "x": 3,
      "y": 10,
      "z": 2,
      "name": "Rock_Shale"
    },
    {
      "x": 3,
      "y": 11,
      "z": 2,
      "name": "Rock_Shale"
    }
  ]
}