{
  "version": 8,
  "blockIdVersion": 8,
  "anchorX": 2,
  "anchorY": 1,
  "anchorZ": 7,
  "blocks": [
    {
      "x": -4,
      "y": 0,
      "z": -6,
      "name": "Rock_Basalt_Cobble"
    },
    {
      "x": -4,
      "y": 1,
      "z": -6,
      "name": "Rock_Basalt_Cobble"
    },
    {
      "x": -4,
      "y": 2,
      "z": -6,
      "name": "Rock_Basalt_Brick_Smooth"
    },
    {
      "x": -4,
      "y": 3,
      "z": -6,
      "name": "Rock_Basalt_Cobble"
    },
    {
      "x": -4,
      "y": 4,
      "z": -6,
      "name": "Rock_Basalt_Cobble"
    },
    {
      "x": -4,
      "y": 5,
      "z": -6,
      "name": "Rock_Basalt_Cobble"
    },
    {
      "x": -4,
      "y": 6,
      "z": -6,
      "name": "Rock_Basalt_Cobble"
    },
    {
      "x": -4,
      "y": 0,
      "z": -5,
      "name": "Rock_Basalt_Cobble"
    },
    {
      "x": -4,
      "y": 1,
      "z": -5,
      "name": "Rock_Basalt_Cobble"
    },
    {
      "x": -4,
      "y": 2,
      "z": -5,
      "name": "Rock_Basalt_Brick_Smooth"
    },
    {
      "x": -4,
      "y": 3,
      "z": -5,
      "name": "Rock_Basalt_Cobble"
    },
    {
      "x": -4,
      "y": 4,
      "z": -5,
      "name": "Rock_Basalt_Cobble"
    },
    {
      "x": -4,
      "y": 5,
      "z": -5,
      "name": "Rock_Basalt_Cobble"
    },
    {
      "x": -4,
      "y": 6,
      "z": -5,
      "name": "Rock_Basalt_Cobble"
    },
    {
      "x": -4,
      "y": 0,
      "z": -4,
      "name": "Rock_Basalt_Cobble"
    },
    {
      "x": -4,
      "y": 1,
      "z": -4,
      "name": "Rock_Basalt_Cobble"
    },
    {
      "x": -4,
      "y": 2,
      "z": -4,
      "name": "Rock_Basalt_Brick_Smooth"
    },
    {
      "x": -4,
      "y": 3,
      "z": -4,
      "name": "Rock_Basalt_Cobble"
    },
    {
      "x": -4,
      "y": 4,
      "z": -4,
      "name": "Rock_Basalt_Cobble"
    },
    {
      "x": -4,
      "y": 5,
      "z": -4,
      "name": "Rock_Basalt_Cobble"
    },
    {
      "x": -4,
      "y": 6,
      "z": -4,
      "name": "Rock_Basalt_Cobble"
    },
    {
      "x": -4,
      "y": 0,
      "z": -3,
      "name": "Rock_Basalt_Cobble"
    },
    {
      "x": -4,
      "y": 1,
      "z": -3,
      "name": "Rock_Basalt_Cobble"
    },
    {
      "x": -4,
      "y": 2,
      "z": -3,
      "name": "Rock_Basalt_Brick_Smooth"
    },
    {
      "x": -4,
      "y": 3,
      "z": -3,
      "name": "Rock_Basalt_Cobble"
    },
    {
      "x": -4,
      "y": 4,
      "z": -3,
      "name": "Rock_Basalt_Cobble"
    },
    {
      "x": -4,
      "y": 5,
      "z": -3,
      "name": "Rock_Basalt_Cobble"
    },
    {
      "x": -4,
      "y": 6,
      "z": -3,
      "name": "Rock_Basalt_Cobble"
    },
    {
      "x": -4,
      "y": 0,
      "z": -2,
      "name": "Rock_Basalt_Cobble"
    },
    {
      "x": -4,
      "y": 1,
      "z": -2,
      "name": "Rock_Basalt_Cobble"
    },
    {
      "x": -4,
      "y": 2,
      "z": -2,
      "name": "Rock_Basalt_Brick_Smooth"
    },
    {
      "x": -4,
      "y": 3,
      "z": -2,
      "name": "Rock_Basalt_Cobble"
    },
    {
      "x": -4,
      "y": 4,
      "z": -2,
      "name": "Rock_Basalt_Cobble"
    },
    {
      "x": -4,
      "y": 5,
      "z": -2,
      "name": "Rock_Basalt_Cobble"
    },
    {
      "x": -4,
      "y": 6,
      "z": -2,
      "name": "Rock_Basalt_Cobble"
    },
    {
      "x": -4,
      "y": 0,
      "z": -1,
      "name": "Rock_Basalt_Cobble"
    },
    {
      "x": -4,
      "y": 1,
      "z": -1,
      "name": "Rock_Basalt_Cobble"
    },
    {
      "x": -4,
      "y": 2,
      "z": -1,
      "name": "Rock_Marble_Brick_Smooth"
    },
    {
      "x": -4,
      "y": 3,
      "z": -1,
      "name": "Rock_Marble_Brick_Smooth"
    },
    {
      "x": -4,
      "y": 4,
      "z": -1,
      "name": "Rock_Basalt_Cobble"
    },
    {
      "x": -4,
      "y": 5,
      "z": -1,
      "name": "Rock_Basalt_Cobble"
    },
    {
      "x": -4,
      "y": 6,
      "z": -1,
      "name": "Rock_Basalt_Cobble"
    },
    {
      "x": -4,
      "y": 0,
      "z": 0,
      "name": "Rock_Basalt_Cobble"
    },
    {
      "x": -4,
      "y": 1,
      "z": 0,
      "name": "Rock_Marble_Brick_Smooth"
    },
    {
      "x": -4,
      "y": 2,
      "z": 0,
      "name": "Rock_Marble_Brick_Smooth"
    },
    {
      "x": -4,
      "y": 3,
      "z": 0,
      "name": "Rock_Marble_Brick_Smooth"
    },
    {
      "x": -4,
      "y": 4,
      "z": 0,
      "name": "Rock_Marble_Brick_Smooth"
    },
    {
      "x": -4,
      "y": 5,
      "z": 0,
      "name": "Rock_Basalt_Cobble"
    },
    {
      "x": -4,
      "y": 6,
      "z": 0,
      "name": "Rock_Basalt_Cobble"
    },
    {
      "x": -4,
      "y": 0,
      "z": 1,
      "name": "Rock_Basalt_Cobble"
    },
    {
      "x": -4,
      "y": 1,
      "z": 1,
      "name": "Rock_Marble_Brick_Smooth"
    },
    {
      "x": -4,
      "y": 2,
      "z": 1,
      "name": "Rock_Marble_Brick_Smooth"
    },
    {
      "x": -4,
      "y": 3,
      "z": 1,
      "name": "Rock_Marble_Brick_Smooth"
    },
    {
      "x": -4,
      "y": 4,
      "z": 1,
      "name": "Rock_Marble_Brick_Smooth"
    },
    {
      "x": -4,
      "y": 5,
      "z": 1,
      "name": "Rock_Basalt_Cobble"
    },
    {
      "x": -4,
      "y": 6,
      "z": 1,
      "name": "Rock_Basalt_Cobble"
    },
    {
      "x": -4,
      "y": 0,
      "z": 2,
      "name": "Rock_Basalt_Cobble"
    },
    {
      "x": -4,
      "y": 1,
      "z": 2,
      "name": "Rock_Basalt_Cobble"
    },
    {
      "x": -4,
      "y": 2,
      "z": 2,
      "name": "Rock_Marble_Brick_Smooth"
    },
    {
      "x": -4,
      "y": 3,
      "z": 2,
      "name": "Rock_Marble_Brick_Smooth"
    },
    {
      "x": -4,
      "y": 4,
      "z": 2,
      "name": "Rock_Basalt_Cobble"
    },
    {
      "x": -4,
      "y": 5,
      "z": 2,
      "name": "Rock_Basalt_Cobble"
    },
    {
      "x": -4,
      "y": 6,
      "z": 2,
      "name": "Rock_Basalt_Cobble"
    },
    {
      "x": -4,
      "y": 0,
      "z": 3,
      "name": "Rock_Basalt_Cobble"
    },
    {
      "x": -4,
      "y": 1,
      "z": 3,
      "name": "Rock_Basalt_Cobble"
    },
    {
      "x": -4,
      "y": 2,
      "z": 3,
      "name": "Rock_Basalt_Brick_Smooth"
    },
    {
      "x": -4,
      "y": 3,
      "z": 3,
      "name": "Rock_Basalt_Cobble"
    },
    {
      "x": -4,
      "y": 4,
      "z": 3,
      "name": "Rock_Basalt_Cobble"
    },
    {
      "x": -4,
      "y": 5,
      "z": 3,
      "name": "Rock_Basalt_Cobble"
    },
    {
      "x": -4,
      "y": 6,
      "z": 3,
      "name": "Rock_Basalt_Cobble"
    },
    {
      "x": -4,
      "y": 0,
      "z": 4,
      "name": "Rock_Basalt_Cobble"
    },
    {
      "x": -4,
      "y": 1,
      "z": 4,
      "name": "Rock_Basalt_Cobble"
    },
    {
      "x": -4,
      "y": 2,
      "z": 4,
      "name": "Rock_Basalt_Brick_Smooth"
    },
    {
      "x": -4,
      "y": 3,
      "z": 4,
      "name": "Rock_Basalt_Cobble"
    },
    {
      "x": -4,
      "y": 4,
      "z": 4,
      "name": "Rock_Basalt_Cobble"
    },
    {
      "x": -4,
      "y": 5,
      "z": 4,
      "name": "Rock_Basalt_Cobble"
    },
    {
      "x": -4,
      "y": 6,
      "z": 4,
      "name": "Rock_Basalt_Cobble"
    },
    {
      "x": -4,
      "y": 0,
      "z": 5,
      "name": "Rock_Basalt_Cobble"
    },
    {
      "x": -4,
      "y": 1,
      "z": 5,
      "name": "Rock_Basalt_Cobble"
    },
    {
      "x": -4,
      "y": 2,
      "z": 5,
      "name": "Rock_Basalt_Brick_Smooth"
    },
    {
      "x": -4,
      "y": 3,
      "z": 5,
      "name": "Rock_Basalt_Cobble"
    },
    {
      "x": -4,
      "y": 4,
      "z": 5,
      "name": "Rock_Basalt_Cobble"
    },
    {
      "x": -4,
      "y": 5,
      "z": 5,
      "name": "Rock_Basalt_Cobble"
    },
    {
      "x": -4,
      "y": 6,
      "z": 5,
      "name": "Rock_Basalt_Cobble"
    },
    {
      "x": -4,
      "y": 0,
      "z": 6,
      "name": "Rock_Basalt_Cobble"
    },
    {
      "x": -4,
      "y": 1,
      "z": 6,
      "name": "Rock_Basalt_Cobble"
    },
    {
      "x": -4,
      "y": 2,
      "z": 6,
      "name": "Rock_Basalt_Brick_Smooth"
    },
    {
      "x": -4,
      "y": 3,
      "z": 6,
      "name": "Rock_Basalt_Cobble"
    },
    {
      "x": -4,
      "y": 4,
      "z": 6,
      "name": "Rock_Basalt_Cobble"
    },
    {
      "x": -4,
      "y": 5,
      "z": 6,
      "name": "Rock_Basalt_Cobble"
    },
    {
      "x": -4,
      "y": 6,
      "z": 6,
      "name": "Rock_Basalt_Cobble"
    },
    {
      "x": -4,
      "y": 0,
      "z": 7,
      "name": "Rock_Basalt_Cobble"
    },
    {
      "x": -4,
      "y": 1,
      "z": 7,
      "name": "Rock_Basalt_Cobble"
    },
    {
      "x": -4,
      "y": 2,
      "z": 7,
      "name": "Rock_Basalt_Brick_Smooth"
    },
    {
      "x": -4,
      "y": 3,
      "z": 7,
      "name": "Rock_Basalt_Cobble"
    },
    {
      "x": -4,
      "y": 4,
      "z": 7,
      "name": "Rock_Basalt_Cobble"
    },
    {
      "x": -4,
      "y": 5,
      "z": 7,
      "name": "Rock_Basalt_Cobble"
    },
    {
      "x": -4,
      "y": 6,
      "z": 7,
      "name": "Rock_Basalt_Cobble"
    },
    {
      "x": -3,
      "y": 0,
      "z": -6,
      "name": "Rock_Basalt_Cobble"
    },
    {
      "x": -3,
      "y": 1,
      "z": -6,
      "name": "Rock_Basalt_Cobble"
    },
    {
      "x": -3,
      "y": 2,
      "z": -6,
      "name": "Rock_Basalt_Brick_Smooth"
    },
    {
      "x": -3,
      "y": 3,
      "z": -6,
      "name": "Rock_Basalt_Cobble"
    },
    {
      "x": -3,
      "y": 4,
      "z": -6,
      "name": "Rock_Basalt_Cobble"
    },
    {
      "x": -3,
      "y": 5,
      "z": -6,
      "name": "Rock_Basalt_Cobble"
    },
    {
      "x": -3,
      "y": 6,
      "z": -6,
      "name": "Rock_Basalt_Cobble"
    },
    {
      "x": -3,
      "y": 0,
      "z": -5,
      "name": "Rock_Basalt_Cobble"
    },
    {
      "x": -3,
      "y": 1,
      "z": -5,
      "name": "Wood_Darkwood_Planks"
    },
    {
      "x": -3,
      "y": 2,
      "z": -5,
      "name": "Furniture_Village_Bookcase",
      "rotation": 1
    },
    {
      "x": -3,
      "y": 3,
      "z": -5,
      "name": "Furniture_Village_Bookcase",
      "rotation": 1
    },
    {
      "x": -3,
      "y": 4,
      "z": -5,
      "name": "Furniture_Village_Bookcase",
      "rotation": 1
    },
    {
      "x": -3,
      "y": 5,
      "z": -5,
      "name": "Wood_Darkwood_Planks"
    },
    {
      "x": -3,
      "y": 6,
      "z": -5,
      "name": "Wood_Darkwood_Planks"
    },
    {
      "x": -3,
      "y": 0,
      "z": -4,
      "name": "Rock_Basalt_Cobble"
    },
    {
      "x": -3,
      "y": 1,
      "z": -4,
      "name": "Wood_Darkwood_Planks"
    },
    {
      "x": -3,
      "y": 2,
      "z": -4,
      "name": "Furniture_Village_Bookcase",
      "rotation": 1
    },
    {
      "x": -3,
      "y": 3,
      "z": -4,
      "name": "Furniture_Village_Bookcase",
      "rotation": 1
    },
    {
      "x": -3,
      "y": 4,
      "z": -4,
      "name": "Furniture_Village_Bookcase",
      "rotation": 1
    },
    {
      "x": -3,
      "y": 5,
      "z": -4,
      "name": "Wood_Darkwood_Planks_Half",
      "rotation": 5
    },
    {
      "x": -3,
      "y": 6,
      "z": -4,
      "name": "Wood_Darkwood_Planks"
    },
    {
      "x": -3,
      "y": 0,
      "z": -3,
      "name": "Rock_Basalt_Cobble"
    },
    {
      "x": -3,
      "y": 1,
      "z": -3,
      "name": "Wood_Darkwood_Planks"
    },
    {
      "x": -3,
      "y": 2,
      "z": -3,
      "name": "Furniture_Village_Bookcase",
      "rotation": 1
    },
    {
      "x": -3,
      "y": 3,
      "z": -3,
      "name": "Furniture_Village_Bookcase",
      "rotation": 1
    },
    {
      "x": -3,
      "y": 4,
      "z": -3,
      "name": "Furniture_Village_Bookcase",
      "rotation": 1
    },
    {
      "x": -3,
      "y": 5,
      "z": -3,
      "name": "Wood_Darkwood_Planks"
    },
    {
      "x": -3,
      "y": 6,
      "z": -3,
      "name": "Wood_Darkwood_Planks"
    },
    {
      "x": -3,
      "y": 0,
      "z": -2,
      "name": "Rock_Basalt_Cobble"
    },
    {
      "x": -3,
      "y": 1,
      "z": -2,
      "name": "Wood_Darkwood_Planks"
    },
    {
      "x": -3,
      "y": 2,
      "z": -2,
      "name": "Rock_Basalt_Brick_Smooth"
    },
    {
      "x": -3,
      "y": 3,
      "z": -2,
      "name": "Rock_Basalt_Cobble"
    },
    {
      "x": -3,
      "y": 4,
      "z": -2,
      "name": "Rock_Basalt_Cobble"
    },
    {
      "x": -3,
      "y": 5,
      "z": -2,
      "name": "Rock_Basalt_Cobble"
    },
    {
      "x": -3,
      "y": 6,
      "z": -2,
      "name": "Wood_Darkwood_Planks"
    },
    {
      "x": -3,
      "y": 0,
      "z": -1,
      "name": "Rock_Basalt_Cobble"
    },
    {
      "x": -3,
      "y": 1,
      "z": -1,
      "name": "Rock_Marble_Brick_Smooth"
    },
    {
      "x": -3,
      "y": 2,
      "z": -1,
      "name": "Rock_Marble_Cobble_Wall"
    },
    {
      "x": -3,
      "y": 3,
      "z": -1,
      "name": "Empty"
    },
    {
      "x": -3,
      "y": 4,
      "z": -1,
      "name": "Empty"
    },
    {
      "x": -3,
      "y": 5,
      "z": -1,
      "name": "Wood_Darkwood_Planks"
    },
    {
      "x": -3,
      "y": 6,
      "z": -1,
      "name": "Wood_Darkwood_Planks"
    },
    {
      "x": -3,
      "y": 0,
      "z": 0,
      "name": "Rock_Marble_Brick_Smooth"
    },
    {
      "x": -3,
      "y": 1,
      "z": 0,
      "name": "Empty"
    },
    {
      "x": -3,
      "y": 2,
      "z": 0,
      "name": "Empty"
    },
    {
      "x": -3,
      "y": 3,
      "z": 0,
      "name": "Empty"
    },
    {
      "x": -3,
      "y": 4,
      "z": 0,
      "name": "Empty"
    },
    {
      "x": -3,
      "y": 5,
      "z": 0,
      "name": "Wood_Darkwood_Planks_Half",
      "rotation": 5
    },
    {
      "x": -3,
      "y": 6,
      "z": 0,
      "name": "Wood_Darkwood_Planks"
    },
    {
      "x": -3,
      "y": 0,
      "z": 1,
      "name": "Rock_Marble_Brick_Smooth"
    },
    {
      "x": -3,
      "y": 1,
      "z": 1,
      "name": "Empty"
    },
    {
      "x": -3,
      "y": 2,
      "z": 1,
      "name": "Empty"
    },
    {
      "x": -3,
      "y": 3,
      "z": 1,
      "name": "Empty"
    },
    {
      "x": -3,
      "y": 4,
      "z": 1,
      "name": "Empty"
    },
    {
      "x": -3,
      "y": 5,
      "z": 1,
      "name": "Wood_Darkwood_Planks_Half",
      "rotation": 5
    },
    {
      "x": -3,
      "y": 6,
      "z": 1,
      "name": "Wood_Darkwood_Planks"
    },
    {
      "x": -3,
      "y": 0,
      "z": 2,
      "name": "Rock_Basalt_Cobble"
    },
    {
      "x": -3,
      "y": 1,
      "z": 2,
      "name": "Rock_Marble_Brick_Smooth"
    },
    {
      "x": -3,
      "y": 2,
      "z": 2,
      "name": "Empty"
    },
    {
      "x": -3,
      "y": 3,
      "z": 2,
      "name": "Furniture_Lumberjack_Shelf",
      "rotation": 2
    },
    {
      "x": -3,
      "y": 4,
      "z": 2,
      "name": "Empty"
    },
    {
      "x": -3,
      "y": 5,
      "z": 2,
      "name": "Wood_Darkwood_Planks"
    },
    {
      "x": -3,
      "y": 6,
      "z": 2,
      "name": "Wood_Darkwood_Planks"
    },
    {
      "x": -3,
      "y": 0,
      "z": 3,
      "name": "Rock_Basalt_Cobble"
    },
    {
      "x": -3,
      "y": 1,
      "z": 3,
      "name": "Wood_Darkwood_Planks"
    },
    {
      "x": -3,
      "y": 2,
      "z": 3,
      "name": "Rock_Basalt_Brick_Smooth"
    },
    {
      "x": -3,
      "y": 3,
      "z": 3,
      "name": "Rock_Basalt_Cobble"
    },
    {
      "x": -3,
      "y": 4,
      "z": 3,
      "name": "Rock_Basalt_Cobble"
    },
    {
      "x": -3,
      "y": 5,
      "z": 3,
      "name": "Rock_Basalt_Cobble"
    },
    {
      "x": -3,
      "y": 6,
      "z": 3,
      "name": "Wood_Darkwood_Planks"
    },
    {
      "x": -3,
      "y": 0,
      "z": 4,
      "name": "Rock_Basalt_Cobble"
    },
    {
      "x": -3,
      "y": 1,
      "z": 4,
      "name": "Wood_Darkwood_Planks"
    },
    {
      "x": -3,
      "y": 2,
      "z": 4,
      "name": "Furniture_Tavern_Planter"
    },
    {
      "x": -3,
      "y": 3,
      "z": 4,
      "name": "Plant_Bush_Winter_Red"
    },
    {
      "x": -3,
      "y": 4,
      "z": 4,
      "name": "Plant_Bush_Winter_Red"
    },
    {
      "x": -3,
      "y": 5,
      "z": 4,
      "name": "Wood_Darkwood_Planks"
    },
    {
      "x": -3,
      "y": 6,
      "z": 4,
      "name": "Wood_Darkwood_Planks"
    },
    {
      "x": -3,
      "y": 0,
      "z": 5,
      "name": "Rock_Basalt_Cobble"
    },
    {
      "x": -3,
      "y": 1,
      "z": 5,
      "name": "Wood_Darkwood_Planks"
    },
    {
      "x": -3,
      "y": 2,
      "z": 5,
      "name": "Furniture_Village_Counter",
      "rotation": 1
    },
    {
      "x": -3,
      "y": 3,
      "z": 5,
      "name": "Furniture_Village_Counter",
      "rotation": 1
    },
    {
      "x": -3,
      "y": 4,
      "z": 5,
      "name": "Plant_Crop_Mushroom_Common_Blue",
      "components": {
        "Components": {
          "FarmingBlock": {}
        }
      }
    },
    {
      "x": -3,
      "y": 5,
      "z": 5,
      "name": "Wood_Darkwood_Planks_Half",
      "rotation": 5
    },
    {
      "x": -3,
      "y": 6,
      "z": 5,
      "name": "Wood_Darkwood_Planks"
    },
    {
      "x": -3,
      "y": 0,
      "z": 6,
      "name": "Rock_Basalt_Cobble"
    },
    {
      "x": -3,
      "y": 1,
      "z": 6,
      "name": "Wood_Darkwood_Planks"
    },
    {
      "x": -3,
      "y": 2,
      "z": 6,
      "name": "Furniture_Village_Counter",
      "filler": 32,
      "rotation": 1
    },
    {
      "x": -3,
      "y": 3,
      "z": 6,
      "name": "Furniture_Village_Counter",
      "filler": 32,
      "rotation": 1
    },
    {
      "x": -3,
      "y": 4,
      "z": 6,
      "name": "Plant_Crop_Mushroom_Cap_Red",
      "components": {
        "Components": {
          "FarmingBlock": {}
        }
      }
    },
    {
      "x": -3,
      "y": 5,
      "z": 6,
      "name": "Wood_Darkwood_Planks"
    },
    {
      "x": -3,
      "y": 6,
      "z": 6,
      "name": "Wood_Darkwood_Planks"
    },
    {
      "x": -3,
      "y": 0,
      "z": 7,
      "name": "Rock_Basalt_Cobble"
    },
    {
      "x": -3,
      "y": 1,
      "z": 7,
      "name": "Rock_Basalt_Cobble"
    },
    {
      "x": -3,
      "y": 2,
      "z": 7,
      "name": "Rock_Basalt_Brick_Smooth"
    },
    {
      "x": -3,
      "y": 3,
      "z": 7,
      "name": "Rock_Basalt_Cobble"
    },
    {
      "x": -3,
      "y": 4,
      "z": 7,
      "name": "Rock_Basalt_Cobble"
    },
    {
      "x": -3,
      "y": 5,
      "z": 7,
      "name": "Rock_Basalt_Cobble"
    },
    {
      "x": -3,
      "y": 6,
      "z": 7,
      "name": "Rock_Basalt_Cobble"
    },
    {
      "x": -2,
      "y": 0,
      "z": -6,
      "name": "Rock_Basalt_Cobble"
    },
    {
      "x": -2,
      "y": 1,
      "z": -6,
      "name": "Rock_Basalt_Cobble"
    },
    {
      "x": -2,
      "y": 2,
      "z": -6,
      "name": "Rock_Basalt_Brick_Smooth"
    },
    {
      "x": -2,
      "y": 3,
      "z": -6,
      "name": "Rock_Basalt_Cobble"
    },
    {
      "x": -2,
      "y": 4,
      "z": -6,
      "name": "Rock_Basalt_Cobble"
    },
    {
      "x": -2,
      "y": 5,
      "z": -6,
      "name": "Rock_Basalt_Cobble"
    },
    {
      "x": -2,
      "y": 6,
      "z": -6,
      "name": "Rock_Basalt_Cobble"
    },
    {
      "x": -2,
      "y": 0,
      "z": -5,
      "name": "Rock_Basalt_Cobble"
    },
    {
      "x": -2,
      "y": 1,
      "z": -5,
      "name": "Wood_Darkwood_Planks"
    },
    {
      "x": -2,
      "y": 2,
      "z": -5,
      "name": "Furniture_Village_Bookcase"
    },
    {
      "x": -2,
      "y": 3,
      "z": -5,
      "name": "Furniture_Village_Bookcase"
    },
    {
      "x": -2,
      "y": 4,
      "z": -5,
      "name": "Furniture_Village_Bookcase"
    },
    {
      "x": -2,
      "y": 5,
      "z": -5,
      "name": "Wood_Darkwood_Planks_Half",
      "rotation": 4
    },
    {
      "x": -2,
      "y": 6,
      "z": -5,
      "name": "Wood_Darkwood_Planks"
    },
    {
      "x": -2,
      "y": 0,
      "z": -4,
      "name": "Rock_Basalt_Cobble"
    },
    {
      "x": -2,
      "y": 1,
      "z": -4,
      "name": "Wood_Darkwood_Planks"
    },
    {
      "x": -2,
      "y": 2,
      "z": -4,
      "name": "Furniture_Village_Chair"
    },
    {
      "x": -2,
      "y": 3,
      "z": -4,
      "name": "Furniture_Village_Chair",
      "filler": 1024
    },
    {
      "x": -2,
      "y": 4,
      "z": -4,
      "name": "Empty"
    },
    {
      "x": -2,
      "y": 5,
      "z": -4,
      "name": "Empty"
    },
    {
      "x": -2,
      "y": 6,
      "z": -4,
      "name": "Wood_Darkwood_Planks"
    },
    {
      "x": -2,
      "y": 0,
      "z": -3,
      "name": "Rock_Basalt_Cobble"
    },
    {
      "x": -2,
      "y": 1,
      "z": -3,
      "name": "Wood_Darkwood_Planks"
    },
    {
      "x": -2,
      "y": 2,
      "z": -3,
      "name": "Furniture_Village_Counter",
      "rotation": 2
    },
    {
      "x": -2,
      "y": 3,
      "z": -3,
      "name": "Potion_Mana_Large"
    },
    {
      "x": -2,
      "y": 4,
      "z": -3,
      "name": "Empty"
    },
    {
      "x": -2,
      "y": 5,
      "z": -3,
      "name": "Wood_Darkwood_Planks_Half",
      "rotation": 6
    },
    {
      "x": -2,
      "y": 6,
      "z": -3,
      "name": "Wood_Darkwood_Planks"
    },
    {
      "x": -2,
      "y": 0,
      "z": -2,
      "name": "Rock_Basalt_Cobble"
    },
    {
      "x": -2,
      "y": 1,
      "z": -2,
      "name": "Wood_Darkwood_Planks"
    },
    {
      "x": -2,
      "y": 2,
      "z": -2,
      "name": "Rock_Basalt_Brick_Smooth"
    },
    {
      "x": -2,
      "y": 3,
      "z": -2,
      "name": "Rock_Basalt_Cobble"
    },
    {
      "x": -2,
      "y": 4,
      "z": -2,
      "name": "Rock_Basalt_Cobble"
    },
    {
      "x": -2,
      "y": 5,
      "z": -2,
      "name": "Rock_Basalt_Cobble"
    },
    {
      "x": -2,
      "y": 6,
      "z": -2,
      "name": "Wood_Darkwood_Planks"
    },
    {
      "x": -2,
      "y": 0,
      "z": -1,
      "name": "Rock_Basalt_Cobble"
    },
    {
      "x": -2,
      "y": 1,
      "z": -1,
      "name": "Rock_Marble_Brick_Smooth"
    },
    {
      "x": -2,
      "y": 2,
      "z": -1,
      "name": "Rock_Marble_Cobble_Wall"
    },
    {
      "x": -2,
      "y": 3,
      "z": -1,
      "name": "Furniture_Lumberjack_Shelf"
    },
    {
      "x": -2,
      "y": 4,
      "z": -1,
      "name": "Deco_Potion"
    },
    {
      "x": -2,
      "y": 5,
      "z": -1,
      "name": "Wood_Darkwood_Planks_Half",
      "rotation": 4
    },
    {
      "x": -2,
      "y": 6,
      "z": -1,
      "name": "Wood_Darkwood_Planks"
    },
    {
      "x": -2,
      "y": 0,
      "z": 0,
      "name": "Rock_Marble_Brick_Smooth"
    },
    {
      "x": -2,
      "y": 1,
      "z": 0,
      "name": "Empty"
    },
    {
      "x": -2,
      "y": 2,
      "z": 0,
      "name": "Empty"
    },
    {
      "x": -2,
      "y": 3,
      "z": 0,
      "name": "Empty"
    },
    {
      "x": -2,
      "y": 4,
      "z": 0,
      "name": "Empty"
    },
    {
      "x": -2,
      "y": 5,
      "z": 0,
      "name": "Empty"
    },
    {
      "x": -2,
      "y": 6,
      "z": 0,
      "name": "Wood_Darkwood_Planks"
    },
    {
      "x": -2,
      "y": 0,
      "z": 1,
      "name": "Rock_Marble_Brick_Smooth"
    },
    {
      "x": -2,
      "y": 1,
      "z": 1,
      "name": "Empty"
    },
    {
      "x": -2,
      "y": 2,
      "z": 1,
      "name": "Empty"
    },
    {
      "x": -2,
      "y": 3,
      "z": 1,
      "name": "Empty"
    },
    {
      "x": -2,
      "y": 4,
      "z": 1,
      "name": "Empty"
    },
    {
      "x": -2,
      "y": 5,
      "z": 1,
      "name": "Empty"
    },
    {
      "x": -2,
      "y": 6,
      "z": 1,
      "name": "Wood_Darkwood_Planks"
    },
    {
      "x": -2,
      "y": 0,
      "z": 2,
      "name": "Rock_Basalt_Cobble"
    },
    {
      "x": -2,
      "y": 1,
      "z": 2,
      "name": "Rock_Marble_Brick_Smooth"
    },
    {
      "x": -2,
      "y": 2,
      "z": 2,
      "name": "Furniture_Temple_Light_Bench",
      "rotation": 2
    },
    {
      "x": -2,
      "y": 3,
      "z": 2,
      "name": "Furniture_Lumberjack_Shelf",
      "rotation": 2
    },
    {
      "x": -2,
      "y": 4,
      "z": 2,
      "name": "Rock_Crystal_Blue_Small"
    },
    {
      "x": -2,
      "y": 5,
      "z": 2,
      "name": "Wood_Darkwood_Planks_Half",
      "rotation": 6
    },
    {
      "x": -2,
      "y": 6,
      "z": 2,
      "name": "Wood_Darkwood_Planks"
    },
    {
      "x": -2,
      "y": 0,
      "z": 3,
      "name": "Rock_Basalt_Cobble"
    },
    {
      "x": -2,
      "y": 1,
      "z": 3,
      "name": "Wood_Darkwood_Planks"
    },
    {
      "x": -2,
      "y": 2,
      "z": 3,
      "name": "Rock_Basalt_Brick_Smooth"
    },
    {
      "x": -2,
      "y": 3,
      "z": 3,
      "name": "Rock_Basalt_Cobble"
    },
    {
      "x": -2,
      "y": 4,
      "z": 3,
      "name": "Rock_Basalt_Cobble"
    },
    {
      "x": -2,
      "y": 5,
      "z": 3,
      "name": "Rock_Basalt_Cobble"
    },
    {
      "x": -2,
      "y": 6,
      "z": 3,
      "name": "Wood_Darkwood_Planks"
    },
    {
      "x": -2,
      "y": 0,
      "z": 4,
      "name": "Rock_Basalt_Cobble"
    },
    {
      "x": -2,
      "y": 1,
      "z": 4,
      "name": "Wood_Darkwood_Planks"
    },
    {
      "x": -2,
      "y": 2,
      "z": 4,
      "name": "Empty"
    },
    {
      "x": -2,
      "y": 3,
      "z": 4,
      "name": "Empty"
    },
    {
      "x": -2,
      "y": 4,
      "z": 4,
      "name": "Empty"
    },
    {
      "x": -2,
      "y": 5,
      "z": 4,
      "name": "Wood_Darkwood_Planks_Half",
      "rotation": 4
    },
    {
      "x": -2,
      "y": 6,
      "z": 4,
      "name": "Wood_Darkwood_Planks"
    },
    {
      "x": -2,
      "y": 0,
      "z": 5,
      "name": "Rock_Basalt_Cobble"
    },
    {
      "x": -2,
      "y": 1,
      "z": 5,
      "name": "Wood_Darkwood_Planks"
    },
    {
      "x": -2,
      "y": 2,
      "z": 5,
      "name": "Empty"
    },
    {
      "x": -2,
      "y": 3,
      "z": 5,
      "name": "Empty"
    },
    {
      "x": -2,
      "y": 4,
      "z": 5,
      "name": "Empty"
    },
    {
      "x": -2,
      "y": 5,
      "z": 5,
      "name": "Empty"
    },
    {
      "x": -2,
      "y": 6,
      "z": 5,
      "name": "Wood_Darkwood_Planks"
    },
    {
      "x": -2,
      "y": 0,
      "z": 6,
      "name": "Rock_Basalt_Cobble"
    },
    {
      "x": -2,
      "y": 1,
      "z": 6,
      "name": "Wood_Darkwood_Planks"
    },
    {
      "x": -2,
      "y": 2,
      "z": 6,
      "name": "Empty"
    },
    {
      "x": -2,
      "y": 3,
      "z": 6,
      "name": "Empty"
    },
    {
      "x": -2,
      "y": 4,
      "z": 6,
      "name": "Empty"
    },
    {
      "x": -2,
      "y": 5,
      "z": 6,
      "name": "Wood_Darkwood_Planks_Half",
      "rotation": 6
    },
    {
      "x": -2,
      "y": 6,
      "z": 6,
      "name": "Wood_Darkwood_Planks"
    },
    {
      "x": -2,
      "y": 0,
      "z": 7,
      "name": "Rock_Basalt_Cobble"
    },
    {
      "x": -2,
      "y": 1,
      "z": 7,
      "name": "Rock_Basalt_Cobble"
    },
    {
      "x": -2,
      "y": 2,
      "z": 7,
      "name": "Rock_Basalt_Brick_Smooth"
    },
    {
      "x": -2,
      "y": 3,
      "z": 7,
      "name": "Rock_Basalt_Cobble"
    },
    {
      "x": -2,
      "y": 4,
      "z": 7,
      "name": "Rock_Basalt_Cobble"
    },
    {
      "x": -2,
      "y": 5,
      "z": 7,
      "name": "Rock_Basalt_Cobble"
    },
    {
      "x": -2,
      "y": 6,
      "z": 7,
      "name": "Rock_Basalt_Cobble"
    },
    {
      "x": -1,
      "y": 0,
      "z": -6,
      "name": "Rock_Basalt_Cobble"
    },
    {
      "x": -1,
      "y": 1,
      "z": -6,
      "name": "Rock_Basalt_Cobble"
    },
    {
      "x": -1,
      "y": 2,
      "z": -6,
      "name": "Rock_Basalt_Brick_Smooth"
    },
    {
      "x": -1,
      "y": 3,
      "z": -6,
      "name": "Rock_Basalt_Cobble"
    },
    {
      "x": -1,
      "y": 4,
      "z": -6,
      "name": "Rock_Basalt_Cobble"
    },
    {
      "x": -1,
      "y": 5,
      "z": -6,
      "name": "Rock_Basalt_Cobble"
    },
    {
      "x": -1,
      "y": 6,
      "z": -6,
      "name": "Rock_Basalt_Cobble"
    },
    {
      "x": -1,
      "y": 0,
      "z": -5,
      "name": "Rock_Basalt_Cobble"
    },
    {
      "x": -1,
      "y": 1,
      "z": -5,
      "name": "Wood_Darkwood_Planks"
    },
    {
      "x": -1,
      "y": 2,
      "z": -5,
      "name": "Furniture_Village_Bookcase"
    },
    {
      "x": -1,
      "y": 3,
      "z": -5,
      "name": "Furniture_Village_Bookcase"
    },
    {
      "x": -1,
      "y": 4,
      "z": -5,
      "name": "Furniture_Village_Bookcase"
    },
    {
      "x": -1,
      "y": 5,
      "z": -5,
      "name": "Wood_Darkwood_Planks_Half",
      "rotation": 4
    },
    {
      "x": -1,
      "y": 6,
      "z": -5,
      "name": "Wood_Darkwood_Planks"
    },
    {
      "x": -1,
      "y": 0,
      "z": -4,
      "name": "Rock_Basalt_Cobble"
    },
    {
      "x": -1,
      "y": 1,
      "z": -4,
      "name": "Wood_Darkwood_Planks"
    },
    {
      "x": -1,
      "y": 2,
      "z": -4,
      "name": "Empty"
    },
    {
      "x": -1,
      "y": 3,
      "z": -4,
      "name": "Empty"
    },
    {
      "x": -1,
      "y": 4,
      "z": -4,
      "name": "Empty"
    },
    {
      "x": -1,
      "y": 5,
      "z": -4,
      "name": "Empty"
    },
    {
      "x": -1,
      "y": 6,
      "z": -4,
      "name": "Wood_Darkwood_Planks"
    },
    {
      "x": -1,
      "y": 0,
      "z": -3,
      "name": "Rock_Basalt_Cobble"
    },
    {
      "x": -1,
      "y": 1,
      "z": -3,
      "name": "Wood_Darkwood_Planks"
    },
    {
      "x": -1,
      "y": 2,
      "z": -3,
      "name": "Furniture_Village_Counter",
      "filler": 1,
      "rotation": 2
    },
    {
      "x": -1,
      "y": 3,
      "z": -3,
      "name": "Deco_Lantern"
    },
    {
      "x": -1,
      "y": 4,
      "z": -3,
      "name": "Empty"
    },
    {
      "x": -1,
      "y": 5,
      "z": -3,
      "name": "Wood_Darkwood_Planks_Half",
      "rotation": 6
    },
    {
      "x": -1,
      "y": 6,
      "z": -3,
      "name": "Wood_Darkwood_Planks"
    },
    {
      "x": -1,
      "y": 0,
      "z": -2,
      "name": "Rock_Basalt_Cobble"
    },
    {
      "x": -1,
      "y": 1,
      "z": -2,
      "name": "Wood_Darkwood_Planks"
    },
    {
      "x": -1,
      "y": 2,
      "z": -2,
      "name": "Rock_Basalt_Brick_Smooth"
    },
    {
      "x": -1,
      "y": 3,
      "z": -2,
      "name": "Rock_Basalt_Cobble"
    },
    {
      "x": -1,
      "y": 4,
      "z": -2,
      "name": "Rock_Basalt_Cobble"
    },
    {
      "x": -1,
      "y": 5,
      "z": -2,
      "name": "Rock_Basalt_Cobble"
    },
    {
      "x": -1,
      "y": 6,
      "z": -2,
      "name": "Wood_Darkwood_Planks"
    },
    {
      "x": -1,
      "y": 0,
      "z": -1,
      "name": "Rock_Basalt_Cobble"
    },
    {
      "x": -1,
      "y": 1,
      "z": -1,
      "name": "Rock_Marble_Brick_Smooth"
    },
    {
      "x": -1,
      "y": 2,
      "z": -1,
      "name": "Empty"
    },
    {
      "x": -1,
      "y": 3,
      "z": -1,
      "name": "Empty"
    },
    {
      "x": -1,
      "y": 4,
      "z": -1,
      "name": "Empty"
    },
    {
      "x": -1,
      "y": 5,
      "z": -1,
      "name": "Wood_Darkwood_Planks_Half",
      "rotation": 4
    },
    {
      "x": -1,
      "y": 6,
      "z": -1,
      "name": "Wood_Darkwood_Planks"
    },
    {
      "x": -1,
      "y": 0,
      "z": 0,
      "name": "Rock_Marble_Brick_Smooth"
    },
    {
      "x": -1,
      "y": 1,
      "z": 0,
      "name": "Empty"
    },
    {
      "x": -1,
      "y": 2,
      "z": 0,
      "name": "Empty"
    },
    {
      "x": -1,
      "y": 3,
      "z": 0,
      "name": "Empty"
    },
    {
      "x": -1,
      "y": 4,
      "z": 0,
      "name": "Empty"
    },
    {
      "x": -1,
      "y": 5,
      "z": 0,
      "name": "Empty"
    },
    {
      "x": -1,
      "y": 6,
      "z": 0,
      "name": "Wood_Darkwood_Planks"
    },
    {
      "x": -1,
      "y": 0,
      "z": 1,
      "name": "Rock_Marble_Brick_Smooth"
    },
    {
      "x": -1,
      "y": 1,
      "z": 1,
      "name": "Empty"
    },
    {
      "x": -1,
      "y": 2,
      "z": 1,
      "name": "Empty"
    },
    {
      "x": -1,
      "y": 3,
      "z": 1,
      "name": "Empty"
    },
    {
      "x": -1,
      "y": 4,
      "z": 1,
      "name": "Empty"
    },
    {
      "x": -1,
      "y": 5,
      "z": 1,
      "name": "Empty"
    },
    {
      "x": -1,
      "y": 6,
      "z": 1,
      "name": "Wood_Darkwood_Planks"
    },
    {
      "x": -1,
      "y": 0,
      "z": 2,
      "name": "Rock_Basalt_Cobble"
    },
    {
      "x": -1,
      "y": 1,
      "z": 2,
      "name": "Rock_Marble_Brick_Smooth"
    },
    {
      "x": -1,
      "y": 2,
      "z": 2,
      "name": "Furniture_Temple_Light_Bench",
      "filler": 1,
      "rotation": 2
    },
    {
      "x": -1,
      "y": 3,
      "z": 2,
      "name": "Empty"
    },
    {
      "x": -1,
      "y": 4,
      "z": 2,
      "name": "Empty"
    },
    {
      "x": -1,
      "y": 5,
      "z": 2,
      "name": "Wood_Darkwood_Planks"
    },
    {
      "x": -1,
      "y": 6,
      "z": 2,
      "name": "Wood_Darkwood_Planks"
    },
    {
      "x": -1,
      "y": 0,
      "z": 3,
      "name": "Rock_Basalt_Cobble"
    },
    {
      "x": -1,
      "y": 1,
      "z": 3,
      "name": "Wood_Darkwood_Planks"
    },
    {
      "x": -1,
      "y": 2,
      "z": 3,
      "name": "Rock_Basalt_Brick_Smooth"
    },
    {
      "x": -1,
      "y": 3,
      "z": 3,
      "name": "Rock_Basalt_Cobble"
    },
    {
      "x": -1,
      "y": 4,
      "z": 3,
      "name": "Rock_Basalt_Cobble"
    },
    {
      "x": -1,
      "y": 5,
      "z": 3,
      "name": "Rock_Basalt_Cobble"
    },
    {
      "x": -1,
      "y": 6,
      "z": 3,
      "name": "Wood_Darkwood_Planks"
    },
    {
      "x": -1,
      "y": 0,
      "z": 4,
      "name": "Rock_Basalt_Cobble"
    },
    {
      "x": -1,
      "y": 1,
      "z": 4,
      "name": "Wood_Darkwood_Planks"
    },
    {
      "x": -1,
      "y": 2,
      "z": 4,
      "name": "Furniture_Lumberjack_Shelf"
    },
    {
      "x": -1,
      "y": 3,
      "z": 4,
      "name": "Deco_Lantern"
    },
    {
      "x": -1,
      "y": 4,
      "z": 4,
      "name": "Empty"
    },
    {
      "x": -1,
      "y": 5,
      "z": 4,
      "name": "Wood_Darkwood_Planks_Half",
      "rotation": 4
    },
    {
      "x": -1,
      "y": 6,
      "z": 4,
      "name": "Wood_Darkwood_Planks"
    },
    {
      "x": -1,
      "y": 0,
      "z": 5,
      "name": "Rock_Basalt_Cobble"
    },
    {
      "x": -1,
      "y": 1,
      "z": 5,
      "name": "Wood_Darkwood_Planks"
    },
    {
      "x": -1,
      "y": 2,
      "z": 5,
      "name": "Empty"
    },
    {
      "x": -1,
      "y": 3,
      "z": 5,
      "name": "Empty"
    },
    {
      "x": -1,
      "y": 4,
      "z": 5,
      "name": "Empty"
    },
    {
      "x": -1,
      "y": 5,
      "z": 5,
      "name": "Empty"
    },
    {
      "x": -1,
      "y": 6,
      "z": 5,
      "name": "Wood_Darkwood_Planks"
    },
    {
      "x": -1,
      "y": 0,
      "z": 6,
      "name": "Rock_Basalt_Cobble"
    },
    {
      "x": -1,
      "y": 1,
      "z": 6,
      "name": "Wood_Darkwood_Planks"
    },
    {
      "x": -1,
      "y": 2,
      "z": 6,
      "name": "Empty"
    },
    {
      "x": -1,
      "y": 3,
      "z": 6,
      "name": "Empty"
    },
    {
      "x": -1,
      "y": 4,
      "z": 6,
      "name": "Empty"
    },
    {
      "x": -1,
      "y": 5,
      "z": 6,
      "name": "Wood_Darkwood_Planks_Half",
      "rotation": 6
    },
    {
      "x": -1,
      "y": 6,
      "z": 6,
      "name": "Wood_Darkwood_Planks"
    },
    {
      "x": -1,
      "y": 0,
      "z": 7,
      "name": "Rock_Basalt_Cobble"
    },
    {
      "x": -1,
      "y": 1,
      "z": 7,
      "name": "Wood_Darkwood_Planks"
    },
    {
      "x": -1,
      "y": 2,
      "z": 7,
      "name": "Empty"
    },
    {
      "x": -1,
      "y": 3,
      "z": 7,
      "name": "Empty"
    },
    {
      "x": -1,
      "y": 4,
      "z": 7,
      "name": "Empty"
    },
    {
      "x": -1,
      "y": 5,
      "z": 7,
      "name": "Rock_Basalt_Cobble"
    },
    {
      "x": -1,
      "y": 6,
      "z": 7,
      "name": "Rock_Basalt_Cobble"
    },
    {
      "x": 0,
      "y": 0,
      "z": -6,
      "name": "Rock_Basalt_Cobble"
    },
    {
      "x": 0,
      "y": 1,
      "z": -6,
      "name": "Rock_Basalt_Cobble"
    },
    {
      "x": 0,
      "y": 2,
      "z": -6,
      "name": "Rock_Basalt_Brick_Smooth"
    },
    {
      "x": 0,
      "y": 3,
      "z": -6,
      "name": "Rock_Basalt_Cobble"
    },
    {
      "x": 0,
      "y": 4,
      "z": -6,
      "name": "Rock_Basalt_Cobble"
    },
    {
      "x": 0,
      "y": 5,
      "z": -6,
      "name": "Rock_Basalt_Cobble"
    },
    {
      "x": 0,
      "y": 6,
      "z": -6,
      "name": "Rock_Basalt_Cobble"
    },
    {
      "x": 0,
      "y": 0,
      "z": -5,
      "name": "Rock_Basalt_Cobble"
    },
    {
      "x": 0,
      "y": 1,
      "z": -5,
      "name": "Wood_Darkwood_Planks"
    },
    {
      "x": 0,
      "y": 2,
      "z": -5,
      "name": "Furniture_Village_Bookcase"
    },
    {
      "x": 0,
      "y": 3,
      "z": -5,
      "name": "Furniture_Village_Bookcase"
    },
    {
      "x": 0,
      "y": 4,
      "z": -5,
      "name": "Furniture_Village_Bookcase"
    },
    {
      "x": 0,
      "y": 5,
      "z": -5,
      "name": "Wood_Darkwood_Planks_Half",
      "rotation": 4
    },
    {
      "x": 0,
      "y": 6,
      "z": -5,
      "name": "Wood_Darkwood_Planks"
    },
    {
      "x": 0,
      "y": 0,
      "z": -4,
      "name": "Rock_Basalt_Cobble"
    },
    {
      "x": 0,
      "y": 1,
      "z": -4,
      "name": "Wood_Darkwood_Planks"
    },
    {
      "x": 0,
      "y": 2,
      "z": -4,
      "name": "Empty"
    },
    {
      "x": 0,
      "y": 3,
      "z": -4,
      "name": "Empty"
    },
    {
      "x": 0,
      "y": 4,
      "z": -4,
      "name": "Empty"
    },
    {
      "x": 0,
      "y": 5,
      "z": -4,
      "name": "Empty"
    },
    {
      "x": 0,
      "y": 6,
      "z": -4,
      "name": "Wood_Darkwood_Planks"
    },
    {
      "x": 0,
      "y": 0,
      "z": -3,
      "name": "Rock_Basalt_Cobble"
    },
    {
      "x": 0,
      "y": 1,
      "z": -3,
      "name": "Wood_Darkwood_Planks"
    },
    {
      "x": 0,
      "y": 2,
      "z": -3,
      "name": "Empty"
    },
    {
      "x": 0,
      "y": 3,
      "z": -3,
      "name": "Empty"
    },
    {
      "x": 0,
      "y": 4,
      "z": -3,
      "name": "Empty"
    },
    {
      "x": 0,
      "y": 5,
      "z": -3,
      "name": "Empty"
    },
    {
      "x": 0,
      "y": 6,
      "z": -3,
      "name": "Wood_Darkwood_Planks"
    },
    {
      "x": 0,
      "y": 0,
      "z": -2,
      "name": "Rock_Basalt_Cobble"
    },
    {
      "x": 0,
      "y": 1,
      "z": -2,
      "name": "Wood_Darkwood_Planks"
    },
    {
      "x": 0,
      "y": 2,
      "z": -2,
      "name": "Empty"
    },
    {
      "x": 0,
      "y": 3,
      "z": -2,
      "name": "Empty"
    },
    {
      "x": 0,
      "y": 4,
      "z": -2,
      "name": "Empty"
    },
    {
      "x": 0,
      "y": 5,
      "z": -2,
      "name": "Wood_Darkwood_Planks_Half",
      "rotation": 5
    },
    {
      "x": 0,
      "y": 6,
      "z": -2,
      "name": "Wood_Darkwood_Planks"
    },
    {
      "x": 0,
      "y": 0,
      "z": -1,
      "name": "Rock_Basalt_Cobble"
    },
    {
      "x": 0,
      "y": 1,
      "z": -1,
      "name": "Rock_Marble_Brick_Smooth"
    },
    {
      "x": 0,
      "y": 2,
      "z": -1,
      "name": "Empty"
    },
    {
      "x": 0,
      "y": 3,
      "z": -1,
      "name": "Empty"
    },
    {
      "x": 0,
      "y": 4,
      "z": -1,
      "name": "Empty"
    },
    {
      "x": 0,
      "y": 5,
      "z": -1,
      "name": "Empty"
    },
    {
      "x": 0,
      "y": 6,
      "z": -1,
      "name": "Wood_Darkwood_Planks"
    },
    {
      "x": 0,
      "y": 0,
      "z": 0,
      "name": "Rock_Basalt_Cobble"
    },
    {
      "x": 0,
      "y": 1,
      "z": 0,
      "name": "Rock_Marble_Brick_Smooth"
    },
    {
      "x": 0,
      "y": 2,
      "z": 0,
      "name": "Empty"
    },
    {
      "x": 0,
      "y": 3,
      "z": 0,
      "name": "Empty"
    },
    {
      "x": 0,
      "y": 4,
      "z": 0,
      "name": "Empty"
    },
    {
      "x": 0,
      "y": 5,
      "z": 0,
      "name": "Empty"
    },
    {
      "x": 0,
      "y": 6,
      "z": 0,
      "name": "Wood_Darkwood_Planks"
    },
    {
      "x": 0,
      "y": 0,
      "z": 1,
      "name": "Rock_Basalt_Cobble"
    },
    {
      "x": 0,
      "y": 1,
      "z": 1,
      "name": "Rock_Marble_Brick_Smooth"
    },
    {
      "x": 0,
      "y": 2,
      "z": 1,
      "name": "Empty"
    },
    {
      "x": 0,
      "y": 3,
      "z": 1,
      "name": "Empty"
    },
    {
      "x": 0,
      "y": 4,
      "z": 1,
      "name": "Empty"
    },
    {
      "x": 0,
      "y": 5,
      "z": 1,
      "name": "Wood_Darkwood_Planks_Half",
      "rotation": 6
    },
    {
      "x": 0,
      "y": 6,
      "z": 1,
      "name": "Wood_Darkwood_Planks"
    },
    {
      "x": 0,
      "y": 0,
      "z": 2,
      "name": "Rock_Basalt_Cobble"
    },
    {
      "x": 0,
      "y": 1,
      "z": 2,
      "name": "Wood_Darkwood_Planks"
    },
    {
      "x": 0,
      "y": 2,
      "z": 2,
      "name": "Rock_Basalt_Brick_Smooth"
    },
    {
      "x": 0,
      "y": 3,
      "z": 2,
      "name": "Rock_Basalt_Cobble"
    },
    {
      "x": 0,
      "y": 4,
      "z": 2,
      "name": "Rock_Basalt_Cobble"
    },
    {
      "x": 0,
      "y": 5,
      "z": 2,
      "name": "Rock_Basalt_Cobble"
    },
    {
      "x": 0,
      "y": 6,
      "z": 2,
      "name": "Wood_Darkwood_Planks"
    },
    {
      "x": 0,
      "y": 0,
      "z": 3,
      "name": "Rock_Basalt_Cobble"
    },
    {
      "x": 0,
      "y": 1,
      "z": 3,
      "name": "Wood_Darkwood_Planks"
    },
    {
      "x": 0,
      "y": 2,
      "z": 3,
      "name": "Rock_Basalt_Brick_Smooth"
    },
    {
      "x": 0,
      "y": 3,
      "z": 3,
      "name": "Rock_Basalt_Cobble"
    },
    {
      "x": 0,
      "y": 4,
      "z": 3,
      "name": "Rock_Basalt_Cobble"
    },
    {
      "x": 0,
      "y": 5,
      "z": 3,
      "name": "Rock_Basalt_Cobble"
    },
    {
      "x": 0,
      "y": 6,
      "z": 3,
      "name": "Wood_Darkwood_Planks"
    },
    {
      "x": 0,
      "y": 0,
      "z": 4,
      "name": "Rock_Basalt_Cobble"
    },
    {
      "x": 0,
      "y": 1,
      "z": 4,
      "name": "Wood_Darkwood_Planks"
    },
    {
      "x": 0,
      "y": 2,
      "z": 4,
      "name": "Furniture_Lumberjack_Shelf"
    },
    {
      "x": 0,
      "y": 3,
      "z": 4,
      "name": "Empty"
    },
    {
      "x": 0,
      "y": 4,
      "z": 4,
      "name": "Empty"
    },
    {
      "x": 0,
      "y": 5,
      "z": 4,
      "name": "Wood_Darkwood_Planks_Half",
      "rotation": 4
    },
    {
      "x": 0,
      "y": 6,
      "z": 4,
      "name": "Wood_Darkwood_Planks"
    },
    {
      "x": 0,
      "y": 0,
      "z": 5,
      "name": "Rock_Basalt_Cobble"
    },
    {
      "x": 0,
      "y": 1,
      "z": 5,
      "name": "Wood_Darkwood_Planks"
    },
    {
      "x": 0,
      "y": 2,
      "z": 5,
      "name": "Empty"
    },
    {
      "x": 0,
      "y": 3,
      "z": 5,
      "name": "Empty"
    },
    {
      "x": 0,
      "y": 4,
      "z": 5,
      "name": "Empty"
    },
    {
      "x": 0,
      "y": 5,
      "z": 5,
      "name": "Empty"
    },
    {
      "x": 0,
      "y": 6,
      "z": 5,
      "name": "Wood_Darkwood_Planks"
    },
    {
      "x": 0,
      "y": 0,
      "z": 6,
      "name": "Rock_Basalt_Cobble"
    },
    {
      "x": 0,
      "y": 1,
      "z": 6,
      "name": "Wood_Darkwood_Planks"
    },
    {
      "x": 0,
      "y": 2,
      "z": 6,
      "name": "Empty"
    },
    {
      "x": 0,
      "y": 3,
      "z": 6,
      "name": "Empty"
    },
    {
      "x": 0,
      "y": 4,
      "z": 6,
      "name": "Empty"
    },
    {
      "x": 0,
      "y": 5,
      "z": 6,
      "name": "Wood_Darkwood_Planks_Half",
      "rotation": 6
    },
    {
      "x": 0,
      "y": 6,
      "z": 6,
      "name": "Wood_Darkwood_Planks"
    },
    {
      "x": 0,
      "y": 0,
      "z": 7,
      "name": "Rock_Basalt_Cobble"
    },
    {
      "x": 0,
      "y": 1,
      "z": 7,
      "name": "Wood_Darkwood_Planks"
    },
    {
      "x": 0,
      "y": 2,
      "z": 7,
      "name": "Empty"
    },
    {
      "x": 0,
      "y": 3,
      "z": 7,
      "name": "Empty"
    },
    {
      "x": 0,
      "y": 4,
      "z": 7,
      "name": "Empty"
    },
    {
      "x": 0,
      "y": 5,
      "z": 7,
      "name": "Rock_Basalt_Cobble"
    },
    {
      "x": 0,
      "y": 6,
      "z": 7,
      "name": "Rock_Basalt_Cobble"
    },
    {
      "x": 1,
      "y": 0,
      "z": -6,
      "name": "Rock_Basalt_Cobble"
    },
    {
      "x": 1,
      "y": 1,
      "z": -6,
      "name": "Rock_Basalt_Cobble"
    },
    {
      "x": 1,
      "y": 2,
      "z": -6,
      "name": "Rock_Basalt_Brick_Smooth"
    },
    {
      "x": 1,
      "y": 3,
      "z": -6,
      "name": "Rock_Basalt_Cobble"
    },
    {
      "x": 1,
      "y": 4,
      "z": -6,
      "name": "Rock_Basalt_Cobble"
    },
    {
      "x": 1,
      "y": 5,
      "z": -6,
      "name": "Rock_Basalt_Cobble"
    },
    {
      "x": 1,
      "y": 6,
      "z": -6,
      "name": "Rock_Basalt_Cobble"
    },
    {
      "x": 1,
      "y": 0,
      "z": -5,
      "name": "Rock_Basalt_Cobble"
    },
    {
      "x": 1,
      "y": 1,
      "z": -5,
      "name": "Wood_Darkwood_Planks"
    },
    {
      "x": 1,
      "y": 2,
      "z": -5,
      "name": "Empty"
    },
    {
      "x": 1,
      "y": 3,
      "z": -5,
      "name": "Empty"
    },
    {
      "x": 1,
      "y": 4,
      "z": -5,
      "name": "Empty"
    },
    {
      "x": 1,
      "y": 5,
      "z": -5,
      "name": "Wood_Darkwood_Planks_Half",
      "rotation": 4
    },
    {
      "x": 1,
      "y": 6,
      "z": -5,
      "name": "Wood_Darkwood_Planks"
    },
    {
      "x": 1,
      "y": 0,
      "z": -4,
      "name": "Rock_Basalt_Cobble"
    },
    {
      "x": 1,
      "y": 1,
      "z": -4,
      "name": "Wood_Darkwood_Planks"
    },
    {
      "x": 1,
      "y": 2,
      "z": -4,
      "name": "Empty"
    },
    {
      "x": 1,
      "y": 3,
      "z": -4,
      "name": "Empty"
    },
    {
      "x": 1,
      "y": 4,
      "z": -4,
      "name": "Empty"
    },
    {
      "x": 1,
      "y": 5,
      "z": -4,
      "name": "Empty"
    },
    {
      "x": 1,
      "y": 6,
      "z": -4,
      "name": "Wood_Darkwood_Planks"
    },
    {
      "x": 1,
      "y": 0,
      "z": -3,
      "name": "Rock_Basalt_Cobble"
    },
    {
      "x": 1,
      "y": 1,
      "z": -3,
      "name": "Wood_Darkwood_Planks"
    },
    {
      "x": 1,
      "y": 2,
      "z": -3,
      "name": "Empty"
    },
    {
      "x": 1,
      "y": 3,
      "z": -3,
      "name": "Empty"
    },
    {
      "x": 1,
      "y": 4,
      "z": -3,
      "name": "Empty"
    },
    {
      "x": 1,
      "y": 5,
      "z": -3,
      "name": "Empty"
    },
    {
      "x": 1,
      "y": 6,
      "z": -3,
      "name": "Wood_Darkwood_Planks"
    },
    {
      "x": 1,
      "y": 0,
      "z": -2,
      "name": "Rock_Basalt_Cobble"
    },
    {
      "x": 1,
      "y": 1,
      "z": -2,
      "name": "Wood_Darkwood_Planks"
    },
    {
      "x": 1,
      "y": 2,
      "z": -2,
      "name": "Empty"
    },
    {
      "x": 1,
      "y": 3,
      "z": -2,
      "name": "Empty"
    },
    {
      "x": 1,
      "y": 4,
      "z": -2,
      "name": "Empty"
    },
    {
      "x": 1,
      "y": 5,
      "z": -2,
      "name": "Empty"
    },
    {
      "x": 1,
      "y": 6,
      "z": -2,
      "name": "Wood_Darkwood_Planks"
    },
    {
      "x": 1,
      "y": 0,
      "z": -1,
      "name": "Rock_Basalt_Cobble"
    },
    {
      "x": 1,
      "y": 1,
      "z": -1,
      "name": "Wood_Darkwood_Planks"
    },
    {
      "x": 1,
      "y": 2,
      "z": -1,
      "name": "Empty"
    },
    {
      "x": 1,
      "y": 3,
      "z": -1,
      "name": "Empty"
    },
    {
      "x": 1,
      "y": 4,
      "z": -1,
      "name": "Empty"
    },
    {
      "x": 1,
      "y": 5,
      "z": -1,
      "name": "Empty"
    },
    {
      "x": 1,
      "y": 6,
      "z": -1,
      "name": "Wood_Darkwood_Planks"
    },
    {
      "x": 1,
      "y": 0,
      "z": 0,
      "name": "Rock_Basalt_Cobble"
    },
    {
      "x": 1,
      "y": 1,
      "z": 0,
      "name": "Wood_Darkwood_Planks"
    },
    {
      "x": 1,
      "y": 2,
      "z": 0,
      "name": "Empty"
    },
    {
      "x": 1,
      "y": 3,
      "z": 0,
      "name": "Empty"
    },
    {
      "x": 1,
      "y": 4,
      "z": 0,
      "name": "Empty"
    },
    {
      "x": 1,
      "y": 5,
      "z": 0,
      "name": "Empty"
    },
    {
      "x": 1,
      "y": 6,
      "z": 0,
      "name": "Wood_Darkwood_Planks"
    },
    {
      "x": 1,
      "y": 0,
      "z": 1,
      "name": "Rock_Basalt_Cobble"
    },
    {
      "x": 1,
      "y": 1,
      "z": 1,
      "name": "Wood_Darkwood_Planks"
    },
    {
      "x": 1,
      "y": 2,
      "z": 1,
      "name": "Empty"
    },
    {
      "x": 1,
      "y": 3,
      "z": 1,
      "name": "Empty"
    },
    {
      "x": 1,
      "y": 4,
      "z": 1,
      "name": "Empty"
    },
    {
      "x": 1,
      "y": 5,
      "z": 1,
      "name": "Wood_Darkwood_Planks_Half",
      "rotation": 6
    },
    {
      "x": 1,
      "y": 6,
      "z": 1,
      "name": "Wood_Darkwood_Planks"
    },
    {
      "x": 1,
      "y": 0,
      "z": 2,
      "name": "Rock_Basalt_Cobble"
    },
    {
      "x": 1,
      "y": 1,
      "z": 2,
      "name": "Wood_Darkwood_Planks"
    },
    {
      "x": 1,
      "y": 2,
      "z": 2,
      "name": "Rock_Basalt_Brick_Smooth"
    },
    {
      "x": 1,
      "y": 3,
      "z": 2,
      "name": "Rock_Basalt_Cobble"
    },
    {
      "x": 1,
      "y": 4,
      "z": 2,
      "name": "Rock_Basalt_Cobble"
    },
    {
      "x": 1,
      "y": 5,
      "z": 2,
      "name": "Rock_Basalt_Cobble"
    },
    {
      "x": 1,
      "y": 6,
      "z": 2,
      "name": "Wood_Darkwood_Planks"
    },
    {
      "x": 1,
      "y": 0,
      "z": 3,
      "name": "Rock_Basalt_Cobble"
    },
    {
      "x": 1,
      "y": 1,
      "z": 3,
      "name": "Wood_Darkwood_Planks"
    },
    {
      "x": 1,
      "y": 2,
      "z": 3,
      "name": "Empty"
    },
    {
      "x": 1,
      "y": 3,
      "z": 3,
      "name": "Empty"
    },
    {
      "x": 1,
      "y": 4,
      "z": 3,
      "name": "Empty"
    },
    {
      "x": 1,
      "y": 5,
      "z": 3,
      "name": "Wood_Darkwood_Planks"
    },
    {
      "x": 1,
      "y": 6,
      "z": 3,
      "name": "Wood_Darkwood_Planks"
    },
    {
      "x": 1,
      "y": 0,
      "z": 4,
      "name": "Rock_Basalt_Cobble"
    },
    {
      "x": 1,
      "y": 1,
      "z": 4,
      "name": "Wood_Darkwood_Planks"
    },
    {
      "x": 1,
      "y": 2,
      "z": 4,
      "name": "Empty"
    },
    {
      "x": 1,
      "y": 3,
      "z": 4,
      "name": "Empty"
    },
    {
      "x": 1,
      "y": 4,
      "z": 4,
      "name": "Empty"
    },
    {
      "x": 1,
      "y": 5,
      "z": 4,
      "name": "Empty"
    },
    {
      "x": 1,
      "y": 6,
      "z": 4,
      "name": "Wood_Darkwood_Planks"
    },
    {
      "x": 1,
      "y": 0,
      "z": 5,
      "name": "Rock_Basalt_Cobble"
    },
    {
      "x": 1,
      "y": 1,
      "z": 5,
      "name": "Wood_Darkwood_Planks"
    },
    {
      "x": 1,
      "y": 2,
      "z": 5,
      "name": "Empty"
    },
    {
      "x": 1,
      "y": 3,
      "z": 5,
      "name": "Empty"
    },
    {
      "x": 1,
      "y": 4,
      "z": 5,
      "name": "Empty"
    },
    {
      "x": 1,
      "y": 5,
      "z": 5,
      "name": "Empty"
    },
    {
      "x": 1,
      "y": 6,
      "z": 5,
      "name": "Wood_Darkwood_Planks"
    },
    {
      "x": 1,
      "y": 0,
      "z": 6,
      "name": "Rock_Basalt_Cobble"
    },
    {
      "x": 1,
      "y": 1,
      "z": 6,
      "name": "Wood_Darkwood_Planks"
    },
    {
      "x": 1,
      "y": 2,
      "z": 6,
      "name": "Empty"
    },
    {
      "x": 1,
      "y": 3,
      "z": 6,
      "name": "Empty"
    },
    {
      "x": 1,
      "y": 4,
      "z": 6,
      "name": "Empty"
    },
    {
      "x": 1,
      "y": 5,
      "z": 6,
      "name": "Wood_Darkwood_Planks_Half",
      "rotation": 6
    },
    {
      "x": 1,
      "y": 6,
      "z": 6,
      "name": "Wood_Darkwood_Planks"
    },
    {
      "x": 1,
      "y": 0,
      "z": 7,
      "name": "Rock_Basalt_Cobble"
    },
    {
      "x": 1,
      "y": 1,
      "z": 7,
      "name": "Wood_Darkwood_Planks"
    },
    {
      "x": 1,
      "y": 2,
      "z": 7,
      "name": "Empty"
    },
    {
      "x": 1,
      "y": 3,
      "z": 7,
      "name": "Empty"
    },
    {
      "x": 1,
      "y": 4,
      "z": 7,
      "name": "Empty"
    },
    {
      "x": 1,
      "y": 5,
      "z": 7,
      "name": "Rock_Basalt_Cobble"
    },
    {
      "x": 1,
      "y": 6,
      "z": 7,
      "name": "Rock_Basalt_Cobble"
    },
    {
      "x": 2,
      "y": 0,
      "z": -6,
      "name": "Rock_Basalt_Cobble"
    },
    {
      "x": 2,
      "y": 1,
      "z": -6,
      "name": "Rock_Basalt_Cobble"
    },
    {
      "x": 2,
      "y": 2,
      "z": -6,
      "name": "Rock_Basalt_Brick_Smooth"
    },
    {
      "x": 2,
      "y": 3,
      "z": -6,
      "name": "Rock_Basalt_Cobble"
    },
    {
      "x": 2,
      "y": 4,
      "z": -6,
      "name": "Rock_Basalt_Cobble"
    },
    {
      "x": 2,
      "y": 5,
      "z": -6,
      "name": "Rock_Basalt_Cobble"
    },
    {
      "x": 2,
      "y": 6,
      "z": -6,
      "name": "Rock_Basalt_Cobble"
    },
    {
      "x": 2,
      "y": 0,
      "z": -5,
      "name": "Rock_Basalt_Cobble"
    },
    {
      "x": 2,
      "y": 1,
      "z": -5,
      "name": "Wood_Darkwood_Planks"
    },
    {
      "x": 2,
      "y": 2,
      "z": -5,
      "name": "Furniture_Lumberjack_Shelf"
    },
    {
      "x": 2,
      "y": 3,
      "z": -5,
      "name": "Deco_Nest"
    },
    {
      "x": 2,
      "y": 4,
      "z": -5,
      "name": "Empty"
    },
    {
      "x": 2,
      "y": 5,
      "z": -5,
      "name": "Wood_Darkwood_Planks_Half",
      "rotation": 4
    },
    {
      "x": 2,
      "y": 6,
      "z": -5,
      "name": "Wood_Darkwood_Planks"
    },
    {
      "x": 2,
      "y": 0,
      "z": -4,
      "name": "Rock_Basalt_Cobble"
    },
    {
      "x": 2,
      "y": 1,
      "z": -4,
      "name": "Wood_Darkwood_Planks"
    },
    {
      "x": 2,
      "y": 2,
      "z": -4,
      "name": "Empty"
    },
    {
      "x": 2,
      "y": 3,
      "z": -4,
      "name": "Empty"
    },
    {
      "x": 2,
      "y": 4,
      "z": -4,
      "name": "Empty"
    },
    {
      "x": 2,
      "y": 5,
      "z": -4,
      "name": "Empty"
    },
    {
      "x": 2,
      "y": 6,
      "z": -4,
      "name": "Wood_Darkwood_Planks"
    },
    {
      "x": 2,
      "y": 0,
      "z": -3,
      "name": "Rock_Basalt_Cobble"
    },
    {
      "x": 2,
      "y": 1,
      "z": -3,
      "name": "Wood_Darkwood_Planks"
    },
    {
      "x": 2,
      "y": 2,
      "z": -3,
      "name": "Empty"
    },
    {
      "x": 2,
      "y": 3,
      "z": -3,
      "name": "Empty"
    },
    {
      "x": 2,
      "y": 4,
      "z": -3,
      "name": "Empty"
    },
    {
      "x": 2,
      "y": 5,
      "z": -3,
      "name": "Empty"
    },
    {
      "x": 2,
      "y": 6,
      "z": -3,
      "name": "Wood_Darkwood_Planks"
    },
    {
      "x": 2,
      "y": 0,
      "z": -2,
      "name": "Rock_Basalt_Cobble"
    },
    {
      "x": 2,
      "y": 1,
      "z": -2,
      "name": "Wood_Darkwood_Planks"
    },
    {
      "x": 2,
      "y": 2,
      "z": -2,
      "name": "Empty"
    },
    {
      "x": 2,
      "y": 3,
      "z": -2,
      "name": "Empty"
    },
    {
      "x": 2,
      "y": 4,
      "z": -2,
      "name": "Empty"
    },
    {
      "x": 2,
      "y": 5,
      "z": -2,
      "name": "Wood_Darkwood_Planks_Half",
      "rotation": 7
    },
    {
      "x": 2,
      "y": 6,
      "z": -2,
      "name": "Wood_Darkwood_Planks"
    },
    {
      "x": 2,
      "y": 0,
      "z": -1,
      "name": "Rock_Basalt_Cobble"
    },
    {
      "x": 2,
      "y": 1,
      "z": -1,
      "name": "Wood_Darkwood_Planks"
    },
    {
      "x": 2,
      "y": 2,
      "z": -1,
      "name": "Empty"
    },
    {
      "x": 2,
      "y": 3,
      "z": -1,
      "name": "Empty"
    },
    {
      "x": 2,
      "y": 4,
      "z": -1,
      "name": "Empty"
    },
    {
      "x": 2,
      "y": 5,
      "z": -1,
      "name": "Empty"
    },
    {
      "x": 2,
      "y": 6,
      "z": -1,
      "name": "Wood_Darkwood_Planks"
    },
    {
      "x": 2,
      "y": 0,
      "z": 0,
      "name": "Rock_Basalt_Cobble"
    },
    {
      "x": 2,
      "y": 1,
      "z": 0,
      "name": "Wood_Darkwood_Planks"
    },
    {
      "x": 2,
      "y": 2,
      "z": 0,
      "name": "Empty"
    },
    {
      "x": 2,
      "y": 3,
      "z": 0,
      "name": "Empty"
    },
    {
      "x": 2,
      "y": 4,
      "z": 0,
      "name": "Empty"
    },
    {
      "x": 2,
      "y": 5,
      "z": 0,
      "name": "Empty"
    },
    {
      "x": 2,
      "y": 6,
      "z": 0,
      "name": "Wood_Darkwood_Planks"
    },
    {
      "x": 2,
      "y": 0,
      "z": 1,
      "name": "Rock_Basalt_Cobble"
    },
    {
      "x": 2,
      "y": 1,
      "z": 1,
      "name": "Wood_Darkwood_Planks"
    },
    {
      "x": 2,
      "y": 2,
      "z": 1,
      "name": "Empty"
    },
    {
      "x": 2,
      "y": 3,
      "z": 1,
      "name": "Empty"
    },
    {
      "x": 2,
      "y": 4,
      "z": 1,
      "name": "Empty"
    },
    {
      "x": 2,
      "y": 5,
      "z": 1,
      "name": "Empty"
    },
    {
      "x": 2,
      "y": 6,
      "z": 1,
      "name": "Wood_Darkwood_Planks"
    },
    {
      "x": 2,
      "y": 0,
      "z": 2,
      "name": "Rock_Basalt_Cobble"
    },
    {
      "x": 2,
      "y": 1,
      "z": 2,
      "name": "Wood_Darkwood_Planks"
    },
    {
      "x": 2,
      "y": 2,
      "z": 2,
      "name": "Empty"
    },
    {
      "x": 2,
      "y": 3,
      "z": 2,
      "name": "Empty"
    },
    {
      "x": 2,
      "y": 4,
      "z": 2,
      "name": "Empty"
    },
    {
      "x": 2,
      "y": 5,
      "z": 2,
      "name": "Wood_Darkwood_Planks_Half",
      "rotation": 5
    },
    {
      "x": 2,
      "y": 6,
      "z": 2,
      "name": "Wood_Darkwood_Planks"
    },
    {
      "x": 2,
      "y": 0,
      "z": 3,
      "name": "Rock_Basalt_Cobble"
    },
    {
      "x": 2,
      "y": 1,
      "z": 3,
      "name": "Wood_Darkwood_Planks"
    },
    {
      "x": 2,
      "y": 2,
      "z": 3,
      "name": "Empty"
    },
    {
      "x": 2,
      "y": 3,
      "z": 3,
      "name": "Empty"
    },
    {
      "x": 2,
      "y": 4,
      "z": 3,
      "name": "Empty"
    },
    {
      "x": 2,
      "y": 5,
      "z": 3,
      "name": "Empty"
    },
    {
      "x": 2,
      "y": 6,
      "z": 3,
      "name": "Wood_Darkwood_Planks"
    },
    {
      "x": 2,
      "y": 0,
      "z": 4,
      "name": "Rock_Basalt_Cobble"
    },
    {
      "x": 2,
      "y": 1,
      "z": 4,
      "name": "Wood_Darkwood_Planks"
    },
    {
      "x": 2,
      "y": 2,
      "z": 4,
      "name": "Empty"
    },
    {
      "x": 2,
      "y": 3,
      "z": 4,
      "name": "Empty"
    },
    {
      "x": 2,
      "y": 4,
      "z": 4,
      "name": "Empty"
    },
    {
      "x": 2,
      "y": 5,
      "z": 4,
      "name": "Empty"
    },
    {
      "x": 2,
      "y": 6,
      "z": 4,
      "name": "Wood_Darkwood_Planks"
    },
    {
      "x": 2,
      "y": 0,
      "z": 5,
      "name": "Rock_Basalt_Cobble"
    },
    {
      "x": 2,
      "y": 1,
      "z": 5,
      "name": "Wood_Darkwood_Planks"
    },
    {
      "x": 2,
      "y": 2,
      "z": 5,
      "name": "Empty"
    },
    {
      "x": 2,
      "y": 3,
      "z": 5,
      "name": "Empty"
    },
    {
      "x": 2,
      "y": 4,
      "z": 5,
      "name": "Empty"
    },
    {
      "x": 2,
      "y": 5,
      "z": 5,
      "name": "Empty"
    },
    {
      "x": 2,
      "y": 6,
      "z": 5,
      "name": "Wood_Darkwood_Planks"
    },
    {
      "x": 2,
      "y": 0,
      "z": 6,
      "name": "Rock_Basalt_Cobble"
    },
    {
      "x": 2,
      "y": 1,
      "z": 6,
      "name": "Wood_Darkwood_Planks"
    },
    {
      "x": 2,
      "y": 2,
      "z": 6,
      "name": "Empty"
    },
    {
      "x": 2,
      "y": 3,
      "z": 6,
      "name": "Empty"
    },
    {
      "x": 2,
      "y": 4,
      "z": 6,
      "name": "Empty"
    },
    {
      "x": 2,
      "y": 5,
      "z": 6,
      "name": "Wood_Darkwood_Planks_Half",
      "rotation": 6
    },
    {
      "x": 2,
      "y": 6,
      "z": 6,
      "name": "Wood_Darkwood_Planks"
    },
    {
      "x": 2,
      "y": 0,
      "z": 7,
      "name": "Rock_Basalt_Cobble"
    },
    {
      "x": 2,
      "y": 1,
      "z": 7,
      "name": "Wood_Darkwood_Planks"
    },
    {
      "x": 2,
      "y": 2,
      "z": 7,
      "name": "Rock_Basalt_Brick_Smooth"
    },
    {
      "x": 2,
      "y": 3,
      "z": 7,
      "name": "Rock_Basalt_Cobble"
    },
    {
      "x": 2,
      "y": 4,
      "z": 7,
      "name": "Rock_Basalt_Cobble"
    },
    {
      "x": 2,
      "y": 5,
      "z": 7,
      "name": "Rock_Basalt_Cobble"
    },
    {
      "x": 2,
      "y": 6,
      "z": 7,
      "name": "Rock_Basalt_Cobble"
    },
    {
      "x": 3,
      "y": 0,
      "z": -6,
      "name": "Rock_Basalt_Cobble"
    },
    {
      "x": 3,
      "y": 1,
      "z": -6,
      "name": "Rock_Basalt_Cobble"
    },
    {
      "x": 3,
      "y": 2,
      "z": -6,
      "name": "Rock_Basalt_Brick_Smooth"
    },
    {
      "x": 3,
      "y": 3,
      "z": -6,
      "name": "Rock_Basalt_Cobble"
    },
    {
      "x": 3,
      "y": 4,
      "z": -6,
      "name": "Rock_Basalt_Cobble"
    },
    {
      "x": 3,
      "y": 5,
      "z": -6,
      "name": "Rock_Basalt_Cobble"
    },
    {
      "x": 3,
      "y": 6,
      "z": -6,
      "name": "Rock_Basalt_Cobble"
    },
    {
      "x": 3,
      "y": 0,
      "z": -5,
      "name": "Rock_Basalt_Cobble"
    },
    {
      "x": 3,
      "y": 1,
      "z": -5,
      "name": "Wood_Darkwood_Planks"
    },
    {
      "x": 3,
      "y": 2,
      "z": -5,
      "name": "Furniture_Lumberjack_Shelf"
    },
    {
      "x": 3,
      "y": 3,
      "z": -5,
      "name": "Potion_Health_Small"
    },
    {
      "x": 3,
      "y": 4,
      "z": -5,
      "name": "Empty"
    },
    {
      "x": 3,
      "y": 5,
      "z": -5,
      "name": "Wood_Darkwood_Planks_Half",
      "rotation": 4
    },
    {
      "x": 3,
      "y": 6,
      "z": -5,
      "name": "Wood_Darkwood_Planks"
    },
    {
      "x": 3,
      "y": 0,
      "z": -4,
      "name": "Rock_Basalt_Cobble"
    },
    {
      "x": 3,
      "y": 1,
      "z": -4,
      "name": "Wood_Darkwood_Planks"
    },
    {
      "x": 3,
      "y": 2,
      "z": -4,
      "name": "Empty"
    },
    {
      "x": 3,
      "y": 3,
      "z": -4,
      "name": "Empty"
    },
    {
      "x": 3,
      "y": 4,
      "z": -4,
      "name": "Empty"
    },
    {
      "x": 3,
      "y": 5,
      "z": -4,
      "name": "Empty"
    },
    {
      "x": 3,
      "y": 6,
      "z": -4,
      "name": "Wood_Darkwood_Planks"
    },
    {
      "x": 3,
      "y": 0,
      "z": -3,
      "name": "Rock_Basalt_Cobble"
    },
    {
      "x": 3,
      "y": 1,
      "z": -3,
      "name": "Wood_Darkwood_Planks"
    },
    {
      "x": 3,
      "y": 2,
      "z": -3,
      "name": "Empty"
    },
    {
      "x": 3,
      "y": 3,
      "z": -3,
      "name": "Empty"
    },
    {
      "x": 3,
      "y": 4,
      "z": -3,
      "name": "Empty"
    },
    {
      "x": 3,
      "y": 5,
      "z": -3,
      "name": "Wood_Darkwood_Planks_Half",
      "rotation": 6
    },
    {
      "x": 3,
      "y": 6,
      "z": -3,
      "name": "Wood_Darkwood_Planks"
    },
    {
      "x": 3,
      "y": 0,
      "z": -2,
      "name": "Rock_Basalt_Cobble"
    },
    {
      "x": 3,
      "y": 1,
      "z": -2,
      "name": "Wood_Darkwood_Planks"
    },
    {
      "x": 3,
      "y": 2,
      "z": -2,
      "name": "Rock_Basalt_Brick_Smooth"
    },
    {
      "x": 3,
      "y": 3,
      "z": -2,
      "name": "Rock_Basalt_Cobble"
    },
    {
      "x": 3,
      "y": 4,
      "z": -2,
      "name": "Rock_Basalt_Cobble"
    },
    {
      "x": 3,
      "y": 5,
      "z": -2,
      "name": "Rock_Basalt_Cobble"
    },
    {
      "x": 3,
      "y": 6,
      "z": -2,
      "name": "Wood_Darkwood_Planks"
    },
    {
      "x": 3,
      "y": 0,
      "z": -1,
      "name": "Rock_Basalt_Cobble"
    },
    {
      "x": 3,
      "y": 1,
      "z": -1,
      "name": "Wood_Darkwood_Planks"
    },
    {
      "x": 3,
      "y": 2,
      "z": -1,
      "name": "Empty"
    },
    {
      "x": 3,
      "y": 3,
      "z": -1,
      "name": "Empty"
    },
    {
      "x": 3,
      "y": 4,
      "z": -1,
      "name": "Empty"
    },
    {
      "x": 3,
      "y": 5,
      "z": -1,
      "name": "Wood_Darkwood_Planks_Half",
      "rotation": 4
    },
    {
      "x": 3,
      "y": 6,
      "z": -1,
      "name": "Wood_Darkwood_Planks"
    },
    {
      "x": 3,
      "y": 0,
      "z": 0,
      "name": "Rock_Basalt_Cobble"
    },
    {
      "x": 3,
      "y": 1,
      "z": 0,
      "name": "Wood_Darkwood_Planks"
    },
    {
      "x": 3,
      "y": 2,
      "z": 0,
      "name": "Empty"
    },
    {
      "x": 3,
      "y": 3,
      "z": 0,
      "name": "Empty"
    },
    {
      "x": 3,
      "y": 4,
      "z": 0,
      "name": "Empty"
    },
    {
      "x": 3,
      "y": 5,
      "z": 0,
      "name": "Empty"
    },
    {
      "x": 3,
      "y": 6,
      "z": 0,
      "name": "Wood_Darkwood_Planks"
    },
    {
      "x": 3,
      "y": 0,
      "z": 1,
      "name": "Rock_Basalt_Cobble"
    },
    {
      "x": 3,
      "y": 1,
      "z": 1,
      "name": "Wood_Darkwood_Planks"
    },
    {
      "x": 3,
      "y": 2,
      "z": 1,
      "name": "Empty"
    },
    {
      "x": 3,
      "y": 3,
      "z": 1,
      "name": "Empty"
    },
    {
      "x": 3,
      "y": 4,
      "z": 1,
      "name": "Empty"
    },
    {
      "x": 3,
      "y": 5,
      "z": 1,
      "name": "Empty"
    },
    {
      "x": 3,
      "y": 6,
      "z": 1,
      "name": "Wood_Darkwood_Planks"
    },
    {
      "x": 3,
      "y": 0,
      "z": 2,
      "name": "Rock_Basalt_Cobble"
    },
    {
      "x": 3,
      "y": 1,
      "z": 2,
      "name": "Wood_Darkwood_Planks"
    },
    {
      "x": 3,
      "y": 2,
      "z": 2,
      "name": "Empty"
    },
    {
      "x": 3,
      "y": 3,
      "z": 2,
      "name": "Empty"
    },
    {
      "x": 3,
      "y": 4,
      "z": 2,
      "name": "Empty"
    },
    {
      "x": 3,
      "y": 5,
      "z": 2,
      "name": "Empty"
    },
    {
      "x": 3,
      "y": 6,
      "z": 2,
      "name": "Wood_Darkwood_Planks"
    },
    {
      "x": 3,
      "y": 0,
      "z": 3,
      "name": "Rock_Basalt_Cobble"
    },
    {
      "x": 3,
      "y": 1,
      "z": 3,
      "name": "Wood_Darkwood_Planks"
    },
    {
      "x": 3,
      "y": 2,
      "z": 3,
      "name": "Empty"
    },
    {
      "x": 3,
      "y": 3,
      "z": 3,
      "name": "Empty"
    },
    {
      "x": 3,
      "y": 4,
      "z": 3,
      "name": "Empty"
    },
    {
      "x": 3,
      "y": 5,
      "z": 3,
      "name": "Wood_Darkwood_Planks_Half",
      "rotation": 7
    },
    {
      "x": 3,
      "y": 6,
      "z": 3,
      "name": "Wood_Darkwood_Planks"
    },
    {
      "x": 3,
      "y": 0,
      "z": 4,
      "name": "Rock_Basalt_Cobble"
    },
    {
      "x": 3,
      "y": 1,
      "z": 4,
      "name": "Wood_Darkwood_Planks"
    },
    {
      "x": 3,
      "y": 2,
      "z": 4,
      "name": "Empty"
    },
    {
      "x": 3,
      "y": 3,
      "z": 4,
      "name": "Empty"
    },
    {
      "x": 3,
      "y": 4,
      "z": 4,
      "name": "Empty"
    },
    {
      "x": 3,
      "y": 5,
      "z": 4,
      "name": "Empty"
    },
    {
      "x": 3,
      "y": 6,
      "z": 4,
      "name": "Wood_Darkwood_Planks"
    },
    {
      "x": 3,
      "y": 0,
      "z": 5,
      "name": "Rock_Basalt_Cobble"
    },
    {
      "x": 3,
      "y": 1,
      "z": 5,
      "name": "Wood_Darkwood_Planks"
    },
    {
      "x": 3,
      "y": 2,
      "z": 5,
      "name": "Empty"
    },
    {
      "x": 3,
      "y": 3,
      "z": 5,
      "name": "Empty"
    },
    {
      "x": 3,
      "y": 4,
      "z": 5,
      "name": "Empty"
    },
    {
      "x": 3,
      "y": 5,
      "z": 5,
      "name": "Empty"
    },
    {
      "x": 3,
      "y": 6,
      "z": 5,
      "name": "Wood_Darkwood_Planks"
    },
    {
      "x": 3,
      "y": 0,
      "z": 6,
      "name": "Rock_Basalt_Cobble"
    },
    {
      "x": 3,
      "y": 1,
      "z": 6,
      "name": "Wood_Darkwood_Planks"
    },
    {
      "x": 3,
      "y": 2,
      "z": 6,
      "name": "Empty"
    },
    {
      "x": 3,
      "y": 3,
      "z": 6,
      "name": "Empty"
    },
    {
      "x": 3,
      "y": 4,
      "z": 6,
      "name": "Empty"
    },
    {
      "x": 3,
      "y": 5,
      "z": 6,
      "name": "Wood_Darkwood_Planks_Half",
      "rotation": 6
    },
    {
      "x": 3,
      "y": 6,
      "z": 6,
      "name": "Wood_Darkwood_Planks"
    },
    {
      "x": 3,
      "y": 0,
      "z": 7,
      "name": "Rock_Basalt_Cobble"
    },
    {
      "x": 3,
      "y": 1,
      "z": 7,
      "name": "Rock_Basalt_Cobble"
    },
    {
      "x": 3,
      "y": 2,
      "z": 7,
      "name": "Rock_Basalt_Brick_Smooth"
    },
    {
      "x": 3,
      "y": 3,
      "z": 7,
      "name": "Rock_Basalt_Cobble"
    },
    {
      "x": 3,
      "y": 4,
      "z": 7,
      "name": "Rock_Basalt_Cobble"
    },
    {
      "x": 3,
      "y": 5,
      "z": 7,
      "name": "Rock_Basalt_Cobble"
    },
    {
      "x": 3,
      "y": 6,
      "z": 7,
      "name": "Rock_Basalt_Cobble"
    },
    {
      "x": 4,
      "y": 0,
      "z": -6,
      "name": "Rock_Basalt_Cobble"
    },
    {
      "x": 4,
      "y": 1,
      "z": -6,
      "name": "Rock_Basalt_Cobble"
    },
    {
      "x": 4,
      "y": 2,
      "z": -6,
      "name": "Rock_Basalt_Brick_Smooth"
    },
    {
      "x": 4,
      "y": 3,
      "z": -6,
      "name": "Rock_Basalt_Cobble"
    },
    {
      "x": 4,
      "y": 4,
      "z": -6,
      "name": "Rock_Basalt_Cobble"
    },
    {
      "x": 4,
      "y": 5,
      "z": -6,
      "name": "Rock_Basalt_Cobble"
    },
    {
      "x": 4,
      "y": 6,
      "z": -6,
      "name": "Rock_Basalt_Cobble"
    },
    {
      "x": 4,
      "y": 0,
      "z": -5,
      "name": "Rock_Basalt_Cobble"
    },
    {
      "x": 4,
      "y": 1,
      "z": -5,
      "name": "Wood_Darkwood_Planks"
    },
    {
      "x": 4,
      "y": 2,
      "z": -5,
      "name": "Furniture_Lumberjack_Shelf"
    },
    {
      "x": 4,
      "y": 3,
      "z": -5,
      "name": "Empty"
    },
    {
      "x": 4,
      "y": 4,
      "z": -5,
      "name": "Empty"
    },
    {
      "x": 4,
      "y": 5,
      "z": -5,
      "name": "Wood_Darkwood_Planks"
    },
    {
      "x": 4,
      "y": 6,
      "z": -5,
      "name": "Wood_Darkwood_Planks"
    },
    {
      "x": 4,
      "y": 0,
      "z": -4,
      "name": "Rock_Basalt_Cobble"
    },
    {
      "x": 4,
      "y": 1,
      "z": -4,
      "name": "Wood_Darkwood_Planks"
    },
    {
      "x": 4,
      "y": 2,
      "z": -4,
      "name": "Empty"
    },
    {
      "x": 4,
      "y": 3,
      "z": -4,
      "name": "Furniture_Lumberjack_Shelf",
      "rotation": 3
    },
    {
      "x": 4,
      "y": 4,
      "z": -4,
      "name": "Potion_Stamina"
    },
    {
      "x": 4,
      "y": 5,
      "z": -4,
      "name": "Wood_Darkwood_Planks_Half",
      "rotation": 7
    },
    {
      "x": 4,
      "y": 6,
      "z": -4,
      "name": "Wood_Darkwood_Planks"
    },
    {
      "x": 4,
      "y": 0,
      "z": -3,
      "name": "Rock_Basalt_Cobble"
    },
    {
      "x": 4,
      "y": 1,
      "z": -3,
      "name": "Wood_Darkwood_Planks"
    },
    {
      "x": 4,
      "y": 2,
      "z": -3,
      "name": "Block_Spawner_Block",
      "components": {
        "Components": {
          "BlockSpawner": {
            "BlockSpawnerId": "Zone3_Encounters_Tier3"
          }
        }
      },
      "rotation": 3
    },
    {
      "x": 4,
      "y": 3,
      "z": -3,
      "name": "Furniture_Lumberjack_Shelf",
      "rotation": 3
    },
    {
      "x": 4,
      "y": 4,
      "z": -3,
      "name": "Plant_Crop_Mushroom_Flatcap_Green",
      "components": {
        "Components": {
          "FarmingBlock": {}
        }
      }
    },
    {
      "x": 4,
      "y": 5,
      "z": -3,
      "name": "Wood_Darkwood_Planks"
    },
    {
      "x": 4,
      "y": 6,
      "z": -3,
      "name": "Wood_Darkwood_Planks"
    },
    {
      "x": 4,
      "y": 0,
      "z": -2,
      "name": "Rock_Basalt_Cobble"
    },
    {
      "x": 4,
      "y": 1,
      "z": -2,
      "name": "Wood_Darkwood_Planks"
    },
    {
      "x": 4,
      "y": 2,
      "z": -2,
      "name": "Rock_Basalt_Brick_Smooth"
    },
    {
      "x": 4,
      "y": 3,
      "z": -2,
      "name": "Rock_Basalt_Cobble"
    },
    {
      "x": 4,
      "y": 4,
      "z": -2,
      "name": "Rock_Basalt_Cobble"
    },
    {
      "x": 4,
      "y": 5,
      "z": -2,
      "name": "Rock_Basalt_Cobble"
    },
    {
      "x": 4,
      "y": 6,
      "z": -2,
      "name": "Wood_Darkwood_Planks"
    },
    {
      "x": 4,
      "y": 0,
      "z": -1,
      "name": "Rock_Basalt_Cobble"
    },
    {
      "x": 4,
      "y": 1,
      "z": -1,
      "name": "Wood_Darkwood_Planks"
    },
    {
      "x": 4,
      "y": 2,
      "z": -1,
      "name": "Alchemy_Cauldron",
      "rotation": 1
    },
    {
      "x": 4,
      "y": 3,
      "z": -1,
      "name": "Empty"
    },
    {
      "x": 4,
      "y": 4,
      "z": -1,
      "name": "Empty"
    },
    {
      "x": 4,
      "y": 5,
      "z": -1,
      "name": "Wood_Darkwood_Planks"
    },
    {
      "x": 4,
      "y": 6,
      "z": -1,
      "name": "Wood_Darkwood_Planks"
    },
    {
      "x": 4,
      "y": 0,
      "z": 0,
      "name": "Rock_Basalt_Cobble"
    },
    {
      "x": 4,
      "y": 1,
      "z": 0,
      "name": "Wood_Darkwood_Planks"
    },
    {
      "x": 4,
      "y": 2,
      "z": 0,
      "name": "Furniture_Village_Counter",
      "filler": 992,
      "rotation": 3
    },
    {
      "x": 4,
      "y": 3,
      "z": 0,
      "name": "Deco_Lantern"
    },
    {
      "x": 4,
      "y": 4,
      "z": 0,
      "name": "Empty"
    },
    {
      "x": 4,
      "y": 5,
      "z": 0,
      "name": "Wood_Darkwood_Planks_Half",
      "rotation": 7
    },
    {
      "x": 4,
      "y": 6,
      "z": 0,
      "name": "Wood_Darkwood_Planks"
    },
    {
      "x": 4,
      "y": 0,
      "z": 1,
      "name": "Rock_Basalt_Cobble"
    },
    {
      "x": 4,
      "y": 1,
      "z": 1,
      "name": "Wood_Darkwood_Planks"
    },
    {
      "x": 4,
      "y": 2,
      "z": 1,
      "name": "Furniture_Village_Counter",
      "rotation": 3
    },
    {
      "x": 4,
      "y": 3,
      "z": 1,
      "name": "Empty"
    },
    {
      "x": 4,
      "y": 4,
      "z": 1,
      "name": "Empty"
    },
    {
      "x": 4,
      "y": 5,
      "z": 1,
      "name": "Wood_Darkwood_Planks_Half",
      "rotation": 7
    },
    {
      "x": 4,
      "y": 6,
      "z": 1,
      "name": "Wood_Darkwood_Planks"
    },
    {
      "x": 4,
      "y": 0,
      "z": 2,
      "name": "Rock_Basalt_Cobble"
    },
    {
      "x": 4,
      "y": 1,
      "z": 2,
      "name": "Wood_Darkwood_Planks"
    },
    {
      "x": 4,
      "y": 2,
      "z": 2,
      "name": "Empty"
    },
    {
      "x": 4,
      "y": 3,
      "z": 2,
      "name": "Furniture_Lumberjack_Shelf",
      "rotation": 3
    },
    {
      "x": 4,
      "y": 4,
      "z": 2,
      "name": "Deco_Coral_Shell_Swirly"
    },
    {
      "x": 4,
      "y": 5,
      "z": 2,
      "name": "Wood_Darkwood_Planks"
    },
    {
      "x": 4,
      "y": 6,
      "z": 2,
      "name": "Wood_Darkwood_Planks"
    },
    {
      "x": 4,
      "y": 0,
      "z": 3,
      "name": "Rock_Basalt_Cobble"
    },
    {
      "x": 4,
      "y": 1,
      "z": 3,
      "name": "Wood_Darkwood_Planks"
    },
    {
      "x": 4,
      "y": 2,
      "z": 3,
      "name": "Rock_Basalt_Brick_Smooth"
    },
    {
      "x": 4,
      "y": 3,
      "z": 3,
      "name": "Rock_Basalt_Cobble"
    },
    {
      "x": 4,
      "y": 4,
      "z": 3,
      "name": "Rock_Basalt_Cobble"
    },
    {
      "x": 4,
      "y": 5,
      "z": 3,
      "name": "Rock_Basalt_Cobble"
    },
    {
      "x": 4,
      "y": 6,
      "z": 3,
      "name": "Wood_Darkwood_Planks"
    },
    {
      "x": 4,
      "y": 0,
      "z": 4,
      "name": "Rock_Basalt_Cobble"
    },
    {
      "x": 4,
      "y": 1,
      "z": 4,
      "name": "Wood_Darkwood_Planks"
    },
    {
      "x": 4,
      "y": 2,
      "z": 4,
      "name": "Furniture_Tavern_Planter"
    },
    {
      "x": 4,
      "y": 3,
      "z": 4,
      "name": "*Plant_Crop_Carrot_Block_State_Definitions_StageFinal",
      "components": {
        "Components": {
          "FarmingBlock": {}
        }
      }
    },
    {
      "x": 4,
      "y": 4,
      "z": 4,
      "name": "Empty"
    },
    {
      "x": 4,
      "y": 5,
      "z": 4,
      "name": "Wood_Darkwood_Planks"
    },
    {
      "x": 4,
      "y": 6,
      "z": 4,
      "name": "Wood_Darkwood_Planks"
    },
    {
      "x": 4,
      "y": 0,
      "z": 5,
      "name": "Rock_Basalt_Cobble"
    },
    {
      "x": 4,
      "y": 1,
      "z": 5,
      "name": "Wood_Darkwood_Planks"
    },
    {
      "x": 4,
      "y": 2,
      "z": 5,
      "name": "Empty"
    },
    {
      "x": 4,
      "y": 3,
      "z": 5,
      "name": "Furniture_Lumberjack_Shelf",
      "rotation": 3
    },
    {
      "x": 4,
      "y": 4,
      "z": 5,
      "name": "Empty"
    },
    {
      "x": 4,
      "y": 5,
      "z": 5,
      "name": "Wood_Darkwood_Planks_Half",
      "rotation": 7
    },
    {
      "x": 4,
      "y": 6,
      "z": 5,
      "name": "Wood_Darkwood_Planks"
    },
    {
      "x": 4,
      "y": 0,
      "z": 6,
      "name": "Rock_Basalt_Cobble"
    },
    {
      "x": 4,
      "y": 1,
      "z": 6,
      "name": "Wood_Darkwood_Planks"
    },
    {
      "x": 4,
      "y": 2,
      "z": 6,
      "name": "Furniture_Crude_Stool"
    },
    {
      "x": 4,
      "y": 3,
      "z": 6,
      "name": "Furniture_Lumberjack_Shelf",
      "rotation": 3
    },
    {
      "x": 4,
      "y": 4,
      "z": 6,
      "name": "Plant_Fruit_Coconut"
    },
    {
      "x": 4,
      "y": 5,
      "z": 6,
      "name": "Wood_Darkwood_Planks"
    },
    {
      "x": 4,
      "y": 6,
      "z": 6,
      "name": "Wood_Darkwood_Planks"
    },
    {
      "x": 4,
      "y": 0,
      "z": 7,
      "name": "Rock_Basalt_Cobble"
    },
    {
      "x": 4,
      "y": 1,
      "z": 7,
      "name": "Rock_Basalt_Cobble"
    },
    {
      "x": 4,
      "y": 2,
      "z": 7,
      "name": "Rock_Basalt_Brick_Smooth"
    },
    {
      "x": 4,
      "y": 3,
      "z": 7,
      "name": "Rock_Basalt_Cobble"
    },
    {
      "x": 4,
      "y": 4,
      "z": 7,
      "name": "Rock_Basalt_Cobble"
    },
    {
      "x": 4,
      "y": 5,
      "z": 7,
      "name": "Rock_Basalt_Cobble"
    },
    {
      "x": 4,
      "y": 6,
      "z": 7,
      "name": "Rock_Basalt_Cobble"
    },
    {
      "x": 5,
      "y": 0,
      "z": -6,
      "name": "Rock_Basalt_Cobble"
    },
    {
      "x": 5,
      "y": 1,
      "z": -6,
      "name": "Rock_Basalt_Cobble"
    },
    {
      "x": 5,
      "y": 2,
      "z": -6,
      "name": "Rock_Basalt_Brick_Smooth"
    },
    {
      "x": 5,
      "y": 3,
      "z": -6,
      "name": "Rock_Basalt_Cobble"
    },
    {
      "x": 5,
      "y": 4,
      "z": -6,
      "name": "Rock_Basalt_Cobble"
    },
    {
      "x": 5,
      "y": 5,
      "z": -6,
      "name": "Rock_Basalt_Cobble"
    },
    {
      "x": 5,
      "y": 6,
      "z": -6,
      "name": "Rock_Basalt_Cobble"
    },
    {
      "x": 5,
      "y": 0,
      "z": -5,
      "name": "Rock_Basalt_Cobble"
    },
    {
      "x": 5,
      "y": 1,
      "z": -5,
      "name": "Rock_Basalt_Cobble"
    },
    {
      "x": 5,
      "y": 2,
      "z": -5,
      "name": "Rock_Basalt_Brick_Smooth"
    },
    {
      "x": 5,
      "y": 3,
      "z": -5,
      "name": "Rock_Basalt_Cobble"
    },
    {
      "x": 5,
      "y": 4,
      "z": -5,
      "name": "Rock_Basalt_Cobble"
    },
    {
      "x": 5,
      "y": 5,
      "z": -5,
      "name": "Rock_Basalt_Cobble"
    },
    {
      "x": 5,
      "y": 6,
      "z": -5,
      "name": "Rock_Basalt_Cobble"
    },
    {
      "x": 5,
      "y": 0,
      "z": -4,
      "name": "Rock_Basalt_Cobble"
    },
    {
      "x": 5,
      "y": 1,
      "z": -4,
      "name": "Rock_Basalt_Cobble"
    },
    {
      "x": 5,
      "y": 2,
      "z": -4,
      "name": "Rock_Basalt_Brick_Smooth"
    },
    {
      "x": 5,
      "y": 3,
      "z": -4,
      "name": "Rock_Basalt_Cobble"
    },
    {
      "x": 5,
      "y": 4,
      "z": -4,
      "name": "Rock_Basalt_Cobble"
    },
    {
      "x": 5,
      "y": 5,
      "z": -4,
      "name": "Rock_Basalt_Cobble"
    },
    {
      "x": 5,
      "y": 6,
      "z": -4,
      "name": "Rock_Basalt_Cobble"
    },
    {
      "x": 5,
      "y": 0,
      "z": -3,
      "name": "Rock_Basalt_Cobble"
    },
    {
      "x": 5,
      "y": 1,
      "z": -3,
      "name": "Rock_Basalt_Cobble"
    },
    {
      "x": 5,
      "y": 2,
      "z": -3,
      "name": "Rock_Basalt_Brick_Smooth"
    },
    {
      "x": 5,
      "y": 3,
      "z": -3,
      "name": "Rock_Basalt_Cobble"
    },
    {
      "x": 5,
      "y": 4,
      "z": -3,
      "name": "Rock_Basalt_Cobble"
    },
    {
      "x": 5,
      "y": 5,
      "z": -3,
      "name": "Rock_Basalt_Cobble"
    },
    {
      "x": 5,
      "y": 6,
      "z": -3,
      "name": "Rock_Basalt_Cobble"
    },
    {
      "x": 5,
      "y": 0,
      "z": -2,
      "name": "Rock_Basalt_Cobble"
    },
    {
      "x": 5,
      "y": 1,
      "z": -2,
      "name": "Rock_Basalt_Cobble"
    },
    {
      "x": 5,
      "y": 2,
      "z": -2,
      "name": "Rock_Basalt_Brick_Smooth"
    },
    {
      "x": 5,
      "y": 3,
      "z": -2,
      "name": "Rock_Basalt_Cobble"
    },
    {
      "x": 5,
      "y": 4,
      "z": -2,
      "name": "Rock_Basalt_Cobble"
    },
    {
      "x": 5,
      "y": 5,
      "z": -2,
      "name": "Rock_Basalt_Cobble"
    },
    {
      "x": 5,
      "y": 6,
      "z": -2,
      "name": "Rock_Basalt_Cobble"
    },
    {
      "x": 5,
      "y": 0,
      "z": -1,
      "name": "Rock_Basalt_Cobble"
    },
    {
      "x": 5,
      "y": 1,
      "z": -1,
      "name": "Rock_Basalt_Cobble"
    },
    {
      "x": 5,
      "y": 2,
      "z": -1,
      "name": "Rock_Basalt_Brick_Smooth"
    },
    {
      "x": 5,
      "y": 3,
      "z": -1,
      "name": "Rock_Basalt_Cobble"
    },
    {
      "x": 5,
      "y": 4,
      "z": -1,
      "name": "Rock_Basalt_Cobble"
    },
    {
      "x": 5,
      "y": 5,
      "z": -1,
      "name": "Rock_Basalt_Cobble"
    },
    {
      "x": 5,
      "y": 6,
      "z": -1,
      "name": "Rock_Basalt_Cobble"
    },
    {
      "x": 5,
      "y": 0,
      "z": 0,
      "name": "Rock_Basalt_Cobble"
    },
    {
      "x": 5,
      "y": 1,
      "z": 0,
      "name": "Rock_Basalt_Cobble"
    },
    {
      "x": 5,
      "y": 2,
      "z": 0,
      "name": "Rock_Basalt_Brick_Smooth"
    },
    {
      "x": 5,
      "y": 3,
      "z": 0,
      "name": "Rock_Basalt_Cobble"
    },
    {
      "x": 5,
      "y": 4,
      "z": 0,
      "name": "Rock_Basalt_Cobble"
    },
    {
      "x": 5,
      "y": 5,
      "z": 0,
      "name": "Rock_Basalt_Cobble"
    },
    {
      "x": 5,
      "y": 6,
      "z": 0,
      "name": "Rock_Basalt_Cobble"
    },
    {
      "x": 5,
      "y": 0,
      "z": 1,
      "name": "Rock_Basalt_Cobble"
    },
    {
      "x": 5,
      "y": 1,
      "z": 1,
      "name": "Rock_Basalt_Cobble"
    },
    {
      "x": 5,
      "y": 2,
      "z": 1,
      "name": "Rock_Basalt_Brick_Smooth"
    },
    {
      "x": 5,
      "y": 3,
      "z": 1,
      "name": "Rock_Basalt_Cobble"
    },
    {
      "x": 5,
      "y": 4,
      "z": 1,
      "name": "Rock_Basalt_Cobble"
    },
    {
      "x": 5,
      "y": 5,
      "z": 1,
      "name": "Rock_Basalt_Cobble"
    },
    {
      "x": 5,
      "y": 6,
      "z": 1,
      "name": "Rock_Basalt_Cobble"
    },
    {
      "x": 5,
      "y": 0,
      "z": 2,
      "name": "Rock_Basalt_Cobble"
    },
    {
      "x": 5,
      "y": 1,
      "z": 2,
      "name": "Rock_Basalt_Cobble"
    },
    {
      "x": 5,
      "y": 2,
      "z": 2,
      "name": "Rock_Basalt_Brick_Smooth"
    },
    {
      "x": 5,
      "y": 3,
      "z": 2,
      "name": "Rock_Basalt_Cobble"
    },
    {
      "x": 5,
      "y": 4,
      "z": 2,
      "name": "Rock_Basalt_Cobble"
    },
    {
      "x": 5,
      "y": 5,
      "z": 2,
      "name": "Rock_Basalt_Cobble"
    },
    {
      "x": 5,
      "y": 6,
      "z": 2,
      "name": "Rock_Basalt_Cobble"
    },
    {
      "x": 5,
      "y": 0,
      "z": 3,
      "name": "Rock_Basalt_Cobble"
    },
    {
      "x": 5,
      "y": 1,
      "z": 3,
      "name": "Rock_Basalt_Cobble"
    },
    {
      "x": 5,
      "y": 2,
      "z": 3,
      "name": "Rock_Basalt_Brick_Smooth"
    },
    {
      "x": 5,
      "y": 3,
      "z": 3,
      "name": "Rock_Basalt_Cobble"
    },
    {
      "x": 5,
      "y": 4,
      "z": 3,
      "name": "Rock_Basalt_Cobble"
    },
    {
      "x": 5,
      "y": 5,
      "z": 3,
      "name": "Rock_Basalt_Cobble"
    },
    {
      "x": 5,
      "y": 6,
      "z": 3,
      "name": "Rock_Basalt_Cobble"
    },
    {
      "x": 5,
      "y": 0,
      "z": 4,
      "name": "Rock_Basalt_Cobble"
    },
    {
      "x": 5,
      "y": 1,
      "z": 4,
      "name": "Rock_Basalt_Cobble"
    },
    {
      "x": 5,
      "y": 2,
      "z": 4,
      "name": "Rock_Basalt_Brick_Smooth"
    },
    {
      "x": 5,
      "y": 3,
      "z": 4,
      "name": "Rock_Basalt_Cobble"
    },
    {
      "x": 5,
      "y": 4,
      "z": 4,
      "name": "Rock_Basalt_Cobble"
    },
    {
      "x": 5,
      "y": 5,
      "z": 4,
      "name": "Rock_Basalt_Cobble"
    },
    {
      "x": 5,
      "y": 6,
      "z": 4,
      "name": "Rock_Basalt_Cobble"
    },
    {
      "x": 5,
      "y": 0,
      "z": 5,
      "name": "Rock_Basalt_Cobble"
    },
    {
      "x": 5,
      "y": 1,
      "z": 5,
      "name": "Rock_Basalt_Cobble"
    },
    {
      "x": 5,
      "y": 2,
      "z": 5,
      "name": "Rock_Basalt_Brick_Smooth"
    },
    {
      "x": 5,
      "y": 3,
      "z": 5,
      "name": "Rock_Basalt_Cobble"
    },
    {
      "x": 5,
      "y": 4,
      "z": 5,
      "name": "Rock_Basalt_Cobble"
    },
    {
      "x": 5,
      "y": 5,
      "z": 5,
      "name": "Rock_Basalt_Cobble"
    },
    {
      "x": 5,
      "y": 6,
      "z": 5,
      "name": "Rock_Basalt_Cobble"
    },
    {
      "x": 5,
      "y": 0,
      "z": 6,
      "name": "Rock_Basalt_Cobble"
    },
    {
      "x": 5,
      "y": 1,
      "z": 6,
      "name": "Rock_Basalt_Cobble"
    },
    {
      "x": 5,
      "y": 2,
      "z": 6,
      "name": "Rock_Basalt_Brick_Smooth"
    },
    {
      "x": 5,
      "y": 3,
      "z": 6,
      "name": "Rock_Basalt_Cobble"
    },
    {
      "x": 5,
      "y": 4,
      "z": 6,
      "name": "Rock_Basalt_Cobble"
    },
    {
      "x": 5,
      "y": 5,
      "z": 6,
      "name": "Rock_Basalt_Cobble"
    },
    {
      "x": 5,
      "y": 6,
      "z": 6,
      "name": "Rock_Basalt_Cobble"
    },
    {
      "x": 5,
      "y": 0,
      "z": 7,
      "name": "Rock_Basalt_Cobble"
    },
    {
      "x": 5,
      "y": 1,
      "z": 7,
      "name": "Rock_Basalt_Cobble"
    },
    {
      "x": 5,
      "y": 2,
      "z": 7,
      "name": "Rock_Basalt_Brick_Smooth"
    },
    {
      "x": 5,
      "y": 3,
      "z": 7,
      "name": "Rock_Basalt_Cobble"
    },
    {
      "x": 5,
      "y": 4,
      "z": 7,
      "name": "Rock_Basalt_Cobble"
    },
    {
      "x": 5,
      "y": 5,
      "z": 7,
      "name": "Rock_Basalt_Cobble"
    },
    {
      "x": 5,
      "y": 6,
      "z": 7,
      "name": "Rock_Basalt_Cobble"
    }
  ]
}