{
  "version": 8,
  "blockIdVersion": 8,
  "anchorX": -2,
  "anchorY": 4,
  "anchorZ": -1,
  "blocks": [
    {
      "x": -6,
      "y": 9,
      "z": 1,
      "name": "Plant_Leaves_Dry"
    },
    {
      "x": -6,
      "y": 9,
      "z": 2,
      "name": "Plant_Leaves_Dry"
    },
    {
      "x": -6,
      "y": 9,
      "z": 3,
      "name": "Plant_Leaves_Dry"
    },
    {
      "x": -6,
      "y": 9,
      "z": 4,
      "name": "Plant_Leaves_Dry"
    },
    {
      "x": -5,
      "y": 9,
      "z": 0,
      "name": "Plant_Leaves_Dry"
    },
    {
      "x": -5,
      "y": 9,
      "z": 1,
      "name": "Plant_Leaves_Dry"
    },
    {
      "x": -5,
      "y": 9,
      "z": 2,
      "name": "Plant_Leaves_Dry"
    },
    {
      "x": -5,
      "y": 9,
      "z": 3,
      "name": "Plant_Leaves_Dry"
    },
    {
      "x": -5,
      "y": 9,
      "z": 4,
      "name": "Plant_Leaves_Dry"
    },
    {
      "x": -5,
      "y": 9,
      "z": 5,
      "name": "Plant_Leaves_Dry"
    },
    {
      "x": -5,
      "y": 9,
      "z": 6,
      "name": "Plant_Leaves_Dry"
    },
    {
      "x": -4,
      "y": 9,
      "z": -1,
      "name": "Plant_Leaves_Dry"
    },
    {
      "x": -4,
      "y": 9,
      "z": 0,
      "name": "Plant_Leaves_Dry"
    },
    {
      "x": -4,
      "y": 9,
      "z": 1,
      "name": "Plant_Leaves_Dry"
    },
    {
      "x": -4,
      "y": 9,
      "z": 2,
      "name": "Wood_Dry_Branch_Long",
      "rotation": 5
    },
    {
      "x": -4,
      "y": 9,
      "z": 3,
      "name": "Plant_Leaves_Dry"
    },
    {
      "x": -4,
      "y": 10,
      "z": 3,
      "name": "Plant_Leaves_Dry"
    },
    {
      "x": -4,
      "y": 9,
      "z": 4,
      "name": "Plant_Leaves_Dry"
    },
    {
      "x": -4,
      "y": 9,
      "z": 5,
      "name": "Plant_Leaves_Dry"
    },
    {
      "x": -4,
      "y": 9,
      "z": 6,
      "name": "Plant_Leaves_Dry"
    },
    {
      "x": -3,
      "y": 6,
      "z": -3,
      "name": "Plant_Leaves_Dry"
    },
    {
      "x": -3,
      "y": 6,
      "z": -2,
      "name": "Plant_Leaves_Dry"
    },
    {
      "x": -3,
      "y": 4,
      "z": -1,
      "name": "Wood_Dry_Trunk_Full"
    },
    {
      "x": -3,
      "y": 9,
      "z": -1,
      "name": "Plant_Leaves_Dry"
    },
    {
      "x": -3,
      "y": 9,
      "z": 0,
      "name": "Plant_Leaves_Dry"
    },
    {
      "x": -3,
      "y": 10,
      "z": 1,
      "name": "Plant_Leaves_Dry"
    },
    {
      "x": -3,
      "y": 9,
      "z": 2,
      "name": "Wood_Dry_Branch_Long",
      "rotation": 5
    },
    {
      "x": -3,
      "y": 10,
      "z": 2,
      "name": "Plant_Leaves_Dry"
    },
    {
      "x": -3,
      "y": 10,
      "z": 3,
      "name": "Plant_Leaves_Dry"
    },
    {
      "x": -3,
      "y": 9,
      "z": 5,
      "name": "Plant_Leaves_Dry"
    },
    {
      "x": -3,
      "y": 9,
      "z": 6,
      "name": "Plant_Leaves_Dry"
    },
    {
      "x": -3,
      "y": 9,
      "z": 7,
      "name": "Plant_Leaves_Dry"
    },
    {
      "x": -2,
      "y": 6,
      "z": -4,
      "name": "Plant_Leaves_Dry"
    },
    {
      "x": -2,
      "y": 6,
      "z": -3,
      "name": "Plant_Leaves_Dry"
    },
    {
      "x": -2,
      "y": 6,
      "z": -2,
      "name": "Wood_Dry_Branch_Long",
      "rotation": 4
    },
    {
      "x": -2,
      "y": 4,
      "z": -1,
      "name": "Wood_Dry_Trunk"
    },
    {
      "x": -2,
      "y": 5,
      "z": -1,
      "name": "Wood_Dry_Trunk"
    },
    {
      "x": -2,
      "y": 6,
      "z": -1,
      "name": "Wood_Dry_Trunk_Full"
    },
    {
      "x": -2,
      "y": 6,
      "z": 0,
      "name": "Wood_Dry_Trunk_Full"
    },
    {
      "x": -2,
      "y": 7,
      "z": 0,
      "name": "Wood_Dry_Trunk_Full"
    },
    {
      "x": -2,
      "y": 8,
      "z": 0,
      "name": "Wood_Dry_Trunk_Full"
    },
    {
      "x": -2,
      "y": 8,
      "z": 1,
      "name": "Wood_Dry_Trunk_Full"
    },
    {
      "x": -2,
      "y": 9,
      "z": 1,
      "name": "Wood_Dry_Trunk_Full"
    },
    {
      "x": -2,
      "y": 10,
      "z": 1,
      "name": "Plant_Leaves_Dry"
    },
    {
      "x": -2,
      "y": 9,
      "z": 2,
      "name": "Wood_Dry_Trunk_Full"
    },
    {
      "x": -2,
      "y": 10,
      "z": 2,
      "name": "Plant_Leaves_Dry"
    },
    {
      "x": -2,
      "y": 9,
      "z": 3,
      "name": "Wood_Dry_Branch_Long",
      "rotation": 4
    },
    {
      "x": -2,
      "y": 10,
      "z": 3,
      "name": "Plant_Leaves_Dry"
    },
    {
      "x": -2,
      "y": 9,
      "z": 4,
      "name": "Wood_Dry_Branch_Long",
      "rotation": 4
    },
    {
      "x": -2,
      "y": 10,
      "z": 4,
      "name": "Plant_Leaves_Dry"
    },
    {
      "x": -2,
      "y": 9,
      "z": 5,
      "name": "Plant_Leaves_Dry"
    },
    {
      "x": -2,
      "y": 9,
      "z": 6,
      "name": "Plant_Leaves_Dry"
    },
    {
      "x": -2,
      "y": 9,
      "z": 7,
      "name": "Plant_Leaves_Dry"
    },
    {
      "x": -1,
      "y": 6,
      "z": -4,
      "name": "Plant_Leaves_Dry"
    },
    {
      "x": -1,
      "y": 6,
      "z": -3,
      "name": "Plant_Leaves_Dry"
    },
    {
      "x": -1,
      "y": 6,
      "z": -2,
      "name": "Plant_Leaves_Dry"
    },
    {
      "x": -1,
      "y": 6,
      "z": -1,
      "name": "Plant_Leaves_Dry"
    },
    {
      "x": -1,
      "y": 9,
      "z": 2,
      "name": "Wood_Dry_Branch_Long",
      "rotation": 5
    },
    {
      "x": -1,
      "y": 10,
      "z": 2,
      "name": "Plant_Leaves_Dry"
    },
    {
      "x": -1,
      "y": 10,
      "z": 3,
      "name": "Plant_Leaves_Dry"
    },
    {
      "x": -1,
      "y": 10,
      "z": 4,
      "name": "Plant_Leaves_Dry"
    },
    {
      "x": -1,
      "y": 9,
      "z": 5,
      "name": "Plant_Leaves_Dry"
    },
    {
      "x": -1,
      "y": 10,
      "z": 5,
      "name": "Plant_Leaves_Dry"
    },
    {
      "x": -1,
      "y": 9,
      "z": 6,
      "name": "Plant_Leaves_Dry"
    },
    {
      "x": -1,
      "y": 9,
      "z": 7,
      "name": "Plant_Leaves_Dry"
    },
    {
      "x": 0,
      "y": 6,
      "z": -3,
      "name": "Plant_Leaves_Dry"
    },
    {
      "x": 0,
      "y": 6,
      "z": -2,
      "name": "Plant_Leaves_Dry"
    },
    {
      "x": 0,
      "y": 9,
      "z": -1,
      "name": "Plant_Leaves_Dry"
    },
    {
      "x": 0,
      "y": 10,
      "z": 1,
      "name": "Plant_Leaves_Dry"
    },
    {
      "x": 0,
      "y": 9,
      "z": 2,
      "name": "Wood_Dry_Branch_Long",
      "rotation": 5
    },
    {
      "x": 0,
      "y": 10,
      "z": 2,
      "name": "Plant_Leaves_Dry"
    },
    {
      "x": 0,
      "y": 10,
      "z": 3,
      "name": "Plant_Leaves_Dry"
    },
    {
      "x": 0,
      "y": 10,
      "z": 4,
      "name": "Plant_Leaves_Dry"
    },
    {
      "x": 0,
      "y": 9,
      "z": 5,
      "name": "Plant_Leaves_Dry"
    },
    {
      "x": 0,
      "y": 9,
      "z": 6,
      "name": "Plant_Leaves_Dry"
    },
    {
      "x": 1,
      "y": 9,
      "z": -1,
      "name": "Plant_Leaves_Dry"
    },
    {
      "x": 1,
      "y": 9,
      "z": 0,
      "name": "Plant_Leaves_Dry"
    },
    {
      "x": 1,
      "y": 9,
      "z": 1,
      "name": "Plant_Leaves_Dry"
    },
    {
      "x": 1,
      "y": 9,
      "z": 2,
      "name": "Plant_Leaves_Dry"
    },
    {
      "x": 1,
      "y": 9,
      "z": 3,
      "name": "Plant_Leaves_Dry"
    },
    {
      "x": 1,
      "y": 9,
      "z": 4,
      "name": "Plant_Leaves_Dry"
    },
    {
      "x": 1,
      "y": 9,
      "z": 5,
      "name": "Plant_Leaves_Dry"
    },
    {
      "x": 1,
      "y": 9,
      "z": 6,
      "name": "Plant_Leaves_Dry"
    },
    {
      "x": 2,
      "y": 9,
      "z": 0,
      "name": "Plant_Leaves_Dry"
    },
    {
      "x": 2,
      "y": 9,
      "z": 1,
      "name": "Plant_Leaves_Dry"
    },
    {
      "x": 2,
      "y": 9,
      "z": 2,
      "name": "Plant_Leaves_Dry"
    },
    {
      "x": 2,
      "y": 9,
      "z": 3,
      "name": "Plant_Leaves_Dry"
    },
    {
      "x": 2,
      "y": 9,
      "z": 4,
      "name": "Plant_Leaves_Dry"
    },
    {
      "x": 2,
      "y": 9,
      "z": 5,
      "name": "Plant_Leaves_Dry"
    },
    {
      "x": 3,
      "y": 9,
      "z": 2,
      "name": "Plant_Leaves_Dry"
    },
    {
      "x": 3,
      "y": 9,
      "z": 3,
      "name": "Plant_Leaves_Dry"
    }
  ]
}