{
  "version": 8,
  "blockIdVersion": 8,
  "anchorX": 4,
  "anchorY": 8,
  "anchorZ": 5,
  "blocks": [
    {
      "x": 3,
      "y": 8,
      "z": 4,
      "name": "Plant_Coral_Block_Blue"
    },
    {
      "x": 3,
      "y": 9,
      "z": 4,
      "name": "Plant_Coral_Block_Purple"
    },
    {
      "x": 3,
      "y": 10,
      "z": 4,
      "name": "Plant_Coral_Block_Purple"
    },
    {
      "x": 3,
      "y": 11,
      "z": 4,
      "name": "Rock_Crystal_Purple_Large"
    },
    {
      "x": 3,
      "y": 6,
      "z": 5,
      "name": "Plant_Coral_Block_Blue"
    },
    {
      "x": 3,
      "y": 7,
      "z": 5,
      "name": "Plant_Coral_Block_Blue"
    },
    {
      "x": 3,
      "y": 8,
      "z": 5,
      "name": "Plant_Coral_Block_Blue"
    },
    {
      "x": 3,
      "y": 9,
      "z": 5,
      "name": "Plant_Coral_Block_Blue"
    },
    {
      "x": 3,
      "y": 10,
      "z": 5,
      "name": "Plant_Coral_Block_Purple"
    },
    {
      "x": 3,
      "y": 11,
      "z": 5,
      "name": "Plant_Coral_Block_Purple"
    },
    {
      "x": 3,
      "y": 12,
      "z": 5,
      "name": "Plant_Coral_Block_Purple"
    },
    {
      "x": 3,
      "y": 13,
      "z": 5,
      "name": "Plant_Coral_Block_Purple"
    },
    {
      "x": 3,
      "y": 14,
      "z": 5,
      "name": "Plant_Coral_Block_Purple"
    },
    {
      "x": 3,
      "y": 15,
      "z": 5,
      "name": "Rock_Crystal_Purple_Medium"
    },
    {
      "x": 3,
      "y": 8,
      "z": 6,
      "name": "Plant_Coral_Block_Blue"
    },
    {
      "x": 3,
      "y": 9,
      "z": 6,
      "name": "Plant_Coral_Block_Blue"
    },
    {
      "x": 3,
      "y": 10,
      "z": 6,
      "name": "Plant_Coral_Block_Blue"
    },
    {
      "x": 3,
      "y": 11,
      "z": 6,
      "name": "Plant_Coral_Block_Blue"
    },
    {
      "x": 3,
      "y": 12,
      "z": 6,
      "name": "Plant_Coral_Block_Purple"
    },
    {
      "x": 3,
      "y": 13,
      "z": 6,
      "name": "Rock_Crystal_Purple_Medium"
    },
    {
      "x": 4,
      "y": 7,
      "z": 4,
      "name": "Plant_Coral_Block_Blue"
    },
    {
      "x": 4,
      "y": 8,
      "z": 4,
      "name": "Plant_Coral_Block_Blue"
    },
    {
      "x": 4,
      "y": 9,
      "z": 4,
      "name": "Plant_Coral_Block_Blue"
    },
    {
      "x": 4,
      "y": 10,
      "z": 4,
      "name": "Plant_Coral_Block_Purple"
    },
    {
      "x": 4,
      "y": 11,
      "z": 4,
      "name": "Plant_Coral_Block_Purple"
    },
    {
      "x": 4,
      "y": 12,
      "z": 4,
      "name": "Plant_Coral_Block_Purple"
    },
    {
      "x": 4,
      "y": 13,
      "z": 4,
      "name": "Rock_Crystal_Purple_Medium"
    },
    {
      "x": 4,
      "y": 5,
      "z": 5,
      "name": "Plant_Coral_Block_Blue"
    },
    {
      "x": 4,
      "y": 6,
      "z": 5,
      "name": "Plant_Coral_Block_Blue"
    },
    {
      "x": 4,
      "y": 7,
      "z": 5,
      "name": "Plant_Coral_Block_Blue"
    },
    {
      "x": 4,
      "y": 8,
      "z": 5,
      "name": "Plant_Coral_Block_Blue"
    },
    {
      "x": 4,
      "y": 9,
      "z": 5,
      "name": "Plant_Coral_Block_Blue"
    },
    {
      "x": 4,
      "y": 10,
      "z": 5,
      "name": "Plant_Coral_Block_Blue"
    },
    {
      "x": 4,
      "y": 11,
      "z": 5,
      "name": "Plant_Coral_Block_Blue"
    },
    {
      "x": 4,
      "y": 12,
      "z": 5,
      "name": "Plant_Coral_Block_Purple"
    },
    {
      "x": 4,
      "y": 13,
      "z": 5,
      "name": "Plant_Coral_Block_Purple"
    },
    {
      "x": 4,
      "y": 14,
      "z": 5,
      "name": "Plant_Coral_Block_Purple"
    },
    {
      "x": 4,
      "y": 15,
      "z": 5,
      "name": "Plant_Coral_Block_Purple"
    },
    {
      "x": 4,
      "y": 16,
      "z": 5,
      "name": "Plant_Coral_Block_Purple"
    },
    {
      "x": 4,
      "y": 17,
      "z": 5,
      "name": "Plant_Coral_Block_Purple"
    },
    {
      "x": 4,
      "y": 18,
      "z": 5,
      "name": "Plant_Coral_Block_Purple"
    },
    {
      "x": 4,
      "y": 19,
      "z": 5,
      "name": "Rock_Crystal_Purple_Medium"
    },
    {
      "x": 4,
      "y": 4,
      "z": 6,
      "name": "Plant_Coral_Block_Blue"
    },
    {
      "x": 4,
      "y": 5,
      "z": 6,
      "name": "Plant_Coral_Block_Blue"
    },
    {
      "x": 4,
      "y": 6,
      "z": 6,
      "name": "Plant_Coral_Block_Blue"
    },
    {
      "x": 4,
      "y": 7,
      "z": 6,
      "name": "Plant_Coral_Block_Blue"
    },
    {
      "x": 4,
      "y": 8,
      "z": 6,
      "name": "Plant_Coral_Block_Blue"
    },
    {
      "x": 4,
      "y": 9,
      "z": 6,
      "name": "Plant_Coral_Block_Blue"
    },
    {
      "x": 4,
      "y": 10,
      "z": 6,
      "name": "Plant_Coral_Block_Blue"
    },
    {
      "x": 4,
      "y": 11,
      "z": 6,
      "name": "Plant_Coral_Block_Blue"
    },
    {
      "x": 4,
      "y": 12,
      "z": 6,
      "name": "Plant_Coral_Block_Blue"
    },
    {
      "x": 4,
      "y": 13,
      "z": 6,
      "name": "Plant_Coral_Block_Blue"
    },
    {
      "x": 4,
      "y": 14,
      "z": 6,
      "name": "Plant_Coral_Block_Purple"
    },
    {
      "x": 4,
      "y": 15,
      "z": 6,
      "name": "Plant_Coral_Block_Purple"
    },
    {
      "x": 4,
      "y": 16,
      "z": 6,
      "name": "Plant_Coral_Block_Purple"
    },
    {
      "x": 4,
      "y": 17,
      "z": 6,
      "name": "Rock_Crystal_Purple_Small"
    },
    {
      "x": 4,
      "y": 8,
      "z": 7,
      "name": "Plant_Coral_Block_Blue"
    },
    {
      "x": 4,
      "y": 9,
      "z": 7,
      "name": "Plant_Coral_Block_Purple"
    },
    {
      "x": 4,
      "y": 10,
      "z": 7,
      "name": "Rock_Crystal_Purple_Small"
    },
    {
      "x": 5,
      "y": 8,
      "z": 4,
      "name": "Plant_Coral_Block_Blue"
    },
    {
      "x": 5,
      "y": 9,
      "z": 4,
      "name": "Plant_Coral_Block_Blue"
    },
    {
      "x": 5,
      "y": 10,
      "z": 4,
      "name": "Rock_Crystal_Purple_Medium"
    },
    {
      "x": 5,
      "y": 6,
      "z": 5,
      "name": "Plant_Coral_Block_Blue"
    },
    {
      "x": 5,
      "y": 7,
      "z": 5,
      "name": "Plant_Coral_Block_Blue"
    },
    {
      "x": 5,
      "y": 8,
      "z": 5,
      "name": "Plant_Coral_Block_Blue"
    },
    {
      "x": 5,
      "y": 9,
      "z": 5,
      "name": "Plant_Coral_Block_Blue"
    },
    {
      "x": 5,
      "y": 10,
      "z": 5,
      "name": "Plant_Coral_Block_Blue"
    },
    {
      "x": 5,
      "y": 11,
      "z": 5,
      "name": "Plant_Coral_Block_Purple"
    },
    {
      "x": 5,
      "y": 12,
      "z": 5,
      "name": "Plant_Coral_Block_Purple"
    },
    {
      "x": 5,
      "y": 13,
      "z": 5,
      "name": "Plant_Coral_Block_Purple"
    },
    {
      "x": 5,
      "y": 14,
      "z": 5,
      "name": "Plant_Coral_Block_Purple"
    },
    {
      "x": 5,
      "y": 15,
      "z": 5,
      "name": "Rock_Crystal_Purple_Small"
    },
    {
      "x": 5,
      "y": 7,
      "z": 6,
      "name": "Plant_Coral_Block_Blue"
    },
    {
      "x": 5,
      "y": 8,
      "z": 6,
      "name": "Plant_Coral_Block_Blue"
    },
    {
      "x": 5,
      "y": 9,
      "z": 6,
      "name": "Plant_Coral_Block_Blue"
    },
    {
      "x": 5,
      "y": 10,
      "z": 6,
      "name": "Plant_Coral_Block_Blue"
    },
    {
      "x": 5,
      "y": 11,
      "z": 6,
      "name": "Plant_Coral_Block_Purple"
    },
    {
      "x": 5,
      "y": 12,
      "z": 6,
      "name": "Plant_Coral_Block_Purple"
    },
    {
      "x": 5,
      "y": 13,
      "z": 6,
      "name": "Plant_Coral_Block_Purple"
    },
    {
      "x": 5,
      "y": 14,
      "z": 6,
      "name": "Rock_Crystal_Purple_Medium"
    },
    {
      "x": 5,
      "y": 8,
      "z": 7,
      "name": "Plant_Coral_Block_Blue"
    },
    {
      "x": 5,
      "y": 9,
      "z": 7,
      "name": "Plant_Coral_Block_Blue"
    },
    {
      "x": 5,
      "y": 10,
      "z": 7,
      "name": "Plant_Coral_Block_Purple"
    },
    {
      "x": 5,
      "y": 11,
      "z": 7,
      "name": "Rock_Crystal_Purple_Large"
    }
  ]
}