{
  "version": 8,
  "blockIdVersion": 8,
  "anchorX": 0,
  "anchorY": 0,
  "anchorZ": 0,
  "blocks": [
    {
      "x": -19,
      "y": 9,
      "z": 7,
      "name": "Rock_Chalk"
    },
    {
      "x": -19,
      "y": 10,
      "z": 7,
      "name": "Rock_Chalk"
    },
    {
      "x": -19,
      "y": 11,
      "z": 7,
      "name": "Rock_Chalk"
    },
    {
      "x": -19,
      "y": 12,
      "z": 7,
      "name": "Rock_Chalk"
    },
    {
      "x": -18,
      "y": 10,
      "z": 4,
      "name": "Rock_Chalk"
    },
    {
      "x": -18,
      "y": 11,
      "z": 4,
      "name": "Rock_Chalk"
    },
    {
      "x": -18,
      "y": 12,
      "z": 4,
      "name": "Rock_Chalk"
    },
    {
      "x": -18,
      "y": 10,
      "z": 5,
      "name": "Rock_Chalk"
    },
    {
      "x": -18,
      "y": 11,
      "z": 5,
      "name": "Rock_Chalk"
    },
    {
      "x": -18,
      "y": 12,
      "z": 5,
      "name": "Rock_Chalk"
    },
    {
      "x": -18,
      "y": 13,
      "z": 5,
      "name": "Rock_Chalk"
    },
    {
      "x": -18,
      "y": 10,
      "z": 6,
      "name": "Rock_Chalk"
    },
    {
      "x": -18,
      "y": 11,
      "z": 6,
      "name": "Rock_Chalk"
    },
    {
      "x": -18,
      "y": 12,
      "z": 6,
      "name": "Rock_Chalk"
    },
    {
      "x": -18,
      "y": 13,
      "z": 6,
      "name": "Rock_Chalk"
    },
    {
      "x": -18,
      "y": 11,
      "z": 7,
      "name": "Rock_Chalk"
    },
    {
      "x": -18,
      "y": 12,
      "z": 7,
      "name": "Rock_Chalk"
    },
    {
      "x": -18,
      "y": 13,
      "z": 7,
      "name": "Rock_Chalk"
    },
    {
      "x": -18,
      "y": 14,
      "z": 7,
      "name": "Rock_Calcite"
    },
    {
      "x": -18,
      "y": 12,
      "z": 11,
      "name": "Rock_Chalk"
    },
    {
      "x": -17,
      "y": 10,
      "z": 2,
      "name": "Rock_Chalk"
    },
    {
      "x": -17,
      "y": 11,
      "z": 2,
      "name": "Rock_Chalk"
    },
    {
      "x": -17,
      "y": 12,
      "z": 2,
      "name": "Rock_Chalk"
    },
    {
      "x": -17,
      "y": 11,
      "z": 3,
      "name": "Rock_Chalk"
    },
    {
      "x": -17,
      "y": 12,
      "z": 3,
      "name": "Rock_Chalk"
    },
    {
      "x": -17,
      "y": 13,
      "z": 3,
      "name": "Rock_Chalk"
    },
    {
      "x": -17,
      "y": 11,
      "z": 4,
      "name": "Rock_Chalk"
    },
    {
      "x": -17,
      "y": 12,
      "z": 4,
      "name": "Rock_Chalk"
    },
    {
      "x": -17,
      "y": 13,
      "z": 4,
      "name": "Rock_Chalk"
    },
    {
      "x": -17,
      "y": 14,
      "z": 4,
      "name": "Rock_Calcite"
    },
    {
      "x": -17,
      "y": 12,
      "z": 5,
      "name": "Rock_Chalk"
    },
    {
      "x": -17,
      "y": 13,
      "z": 5,
      "name": "Rock_Chalk"
    },
    {
      "x": -17,
      "y": 14,
      "z": 5,
      "name": "Rock_Calcite"
    },
    {
      "x": -17,
      "y": 15,
      "z": 5,
      "name": "Rock_Calcite"
    },
    {
      "x": -17,
      "y": 12,
      "z": 6,
      "name": "Rock_Chalk"
    },
    {
      "x": -17,
      "y": 13,
      "z": 6,
      "name": "Rock_Chalk"
    },
    {
      "x": -17,
      "y": 14,
      "z": 6,
      "name": "Rock_Calcite"
    },
    {
      "x": -17,
      "y": 15,
      "z": 6,
      "name": "Rock_Calcite"
    },
    {
      "x": -17,
      "y": 12,
      "z": 7,
      "name": "Rock_Chalk"
    },
    {
      "x": -17,
      "y": 13,
      "z": 7,
      "name": "Rock_Chalk"
    },
    {
      "x": -17,
      "y": 14,
      "z": 7,
      "name": "Rock_Calcite"
    },
    {
      "x": -17,
      "y": 15,
      "z": 7,
      "name": "Rock_Calcite"
    },
    {
      "x": -17,
      "y": 11,
      "z": 11,
      "name": "Rock_Chalk"
    },
    {
      "x": -17,
      "y": 12,
      "z": 11,
      "name": "Rock_Chalk"
    },
    {
      "x": -17,
      "y": 13,
      "z": 11,
      "name": "Rock_Chalk"
    },
    {
      "x": -17,
      "y": 10,
      "z": 12,
      "name": "Rock_Chalk"
    },
    {
      "x": -17,
      "y": 11,
      "z": 12,
      "name": "Rock_Chalk"
    },
    {
      "x": -17,
      "y": 12,
      "z": 12,
      "name": "Rock_Chalk"
    },
    {
      "x": -17,
      "y": 13,
      "z": 12,
      "name": "Rock_Chalk"
    },
    {
      "x": -17,
      "y": 9,
      "z": 13,
      "name": "Rock_Chalk"
    },
    {
      "x": -17,
      "y": 10,
      "z": 13,
      "name": "Rock_Chalk"
    },
    {
      "x": -17,
      "y": 11,
      "z": 13,
      "name": "Rock_Chalk"
    },
    {
      "x": -17,
      "y": 12,
      "z": 13,
      "name": "Rock_Chalk"
    },
    {
      "x": -16,
      "y": 11,
      "z": -12,
      "name": "Rock_Chalk"
    },
    {
      "x": -16,
      "y": 12,
      "z": -12,
      "name": "Rock_Chalk"
    },
    {
      "x": -16,
      "y": 12,
      "z": -7,
      "name": "Rock_Chalk"
    },
    {
      "x": -16,
      "y": 13,
      "z": -7,
      "name": "Rock_Chalk"
    },
    {
      "x": -16,
      "y": 10,
      "z": -6,
      "name": "Rock_Chalk"
    },
    {
      "x": -16,
      "y": 11,
      "z": -6,
      "name": "Rock_Chalk"
    },
    {
      "x": -16,
      "y": 12,
      "z": -6,
      "name": "Rock_Chalk"
    },
    {
      "x": -16,
      "y": 13,
      "z": -6,
      "name": "Rock_Chalk"
    },
    {
      "x": -16,
      "y": 10,
      "z": -5,
      "name": "Rock_Chalk"
    },
    {
      "x": -16,
      "y": 11,
      "z": -5,
      "name": "Rock_Chalk"
    },
    {
      "x": -16,
      "y": 12,
      "z": -5,
      "name": "Rock_Chalk"
    },
    {
      "x": -16,
      "y": 13,
      "z": -5,
      "name": "Rock_Chalk"
    },
    {
      "x": -16,
      "y": 10,
      "z": -4,
      "name": "Rock_Chalk"
    },
    {
      "x": -16,
      "y": 11,
      "z": -4,
      "name": "Rock_Chalk"
    },
    {
      "x": -16,
      "y": 12,
      "z": -4,
      "name": "Rock_Chalk"
    },
    {
      "x": -16,
      "y": 10,
      "z": -3,
      "name": "Rock_Chalk"
    },
    {
      "x": -16,
      "y": 11,
      "z": -3,
      "name": "Rock_Chalk"
    },
    {
      "x": -16,
      "y": 12,
      "z": -3,
      "name": "Rock_Chalk"
    },
    {
      "x": -16,
      "y": 9,
      "z": -2,
      "name": "Rock_Chalk"
    },
    {
      "x": -16,
      "y": 10,
      "z": -2,
      "name": "Rock_Chalk"
    },
    {
      "x": -16,
      "y": 11,
      "z": -2,
      "name": "Rock_Chalk"
    },
    {
      "x": -16,
      "y": 12,
      "z": -2,
      "name": "Rock_Chalk"
    },
    {
      "x": -16,
      "y": 9,
      "z": -1,
      "name": "Rock_Chalk"
    },
    {
      "x": -16,
      "y": 10,
      "z": -1,
      "name": "Rock_Chalk"
    },
    {
      "x": -16,
      "y": 11,
      "z": -1,
      "name": "Rock_Chalk"
    },
    {
      "x": -16,
      "y": 12,
      "z": -1,
      "name": "Rock_Chalk"
    },
    {
      "x": -16,
      "y": 10,
      "z": 0,
      "name": "Rock_Chalk"
    },
    {
      "x": -16,
      "y": 11,
      "z": 0,
      "name": "Rock_Chalk"
    },
    {
      "x": -16,
      "y": 12,
      "z": 0,
      "name": "Rock_Chalk"
    },
    {
      "x": -16,
      "y": 13,
      "z": 0,
      "name": "Rock_Chalk"
    },
    {
      "x": -16,
      "y": 10,
      "z": 1,
      "name": "Rock_Chalk"
    },
    {
      "x": -16,
      "y": 11,
      "z": 1,
      "name": "Rock_Chalk"
    },
    {
      "x": -16,
      "y": 12,
      "z": 1,
      "name": "Rock_Chalk"
    },
    {
      "x": -16,
      "y": 13,
      "z": 1,
      "name": "Rock_Chalk"
    },
    {
      "x": -16,
      "y": 11,
      "z": 2,
      "name": "Rock_Chalk"
    },
    {
      "x": -16,
      "y": 12,
      "z": 2,
      "name": "Rock_Chalk"
    },
    {
      "x": -16,
      "y": 13,
      "z": 2,
      "name": "Rock_Chalk"
    },
    {
      "x": -16,
      "y": 14,
      "z": 2,
      "name": "Rock_Chalk"
    },
    {
      "x": -16,
      "y": 12,
      "z": 3,
      "name": "Rock_Chalk"
    },
    {
      "x": -16,
      "y": 13,
      "z": 3,
      "name": "Rock_Chalk"
    },
    {
      "x": -16,
      "y": 14,
      "z": 3,
      "name": "Rock_Calcite"
    },
    {
      "x": -16,
      "y": 15,
      "z": 3,
      "name": "Rock_Calcite"
    },
    {
      "x": -16,
      "y": 13,
      "z": 4,
      "name": "Rock_Chalk"
    },
    {
      "x": -16,
      "y": 14,
      "z": 4,
      "name": "Rock_Calcite"
    },
    {
      "x": -16,
      "y": 15,
      "z": 4,
      "name": "Rock_Calcite"
    },
    {
      "x": -16,
      "y": 16,
      "z": 4,
      "name": "Rock_Calcite"
    },
    {
      "x": -16,
      "y": 13,
      "z": 5,
      "name": "Rock_Chalk"
    },
    {
      "x": -16,
      "y": 14,
      "z": 5,
      "name": "Rock_Calcite"
    },
    {
      "x": -16,
      "y": 15,
      "z": 5,
      "name": "Rock_Calcite"
    },
    {
      "x": -16,
      "y": 16,
      "z": 5,
      "name": "Rock_Calcite"
    },
    {
      "x": -16,
      "y": 13,
      "z": 6,
      "name": "Rock_Chalk"
    },
    {
      "x": -16,
      "y": 14,
      "z": 6,
      "name": "Rock_Calcite"
    },
    {
      "x": -16,
      "y": 15,
      "z": 6,
      "name": "Rock_Calcite"
    },
    {
      "x": -16,
      "y": 16,
      "z": 6,
      "name": "Rock_Marble"
    },
    {
      "x": -16,
      "y": 13,
      "z": 7,
      "name": "Rock_Chalk"
    },
    {
      "x": -16,
      "y": 14,
      "z": 7,
      "name": "Rock_Calcite"
    },
    {
      "x": -16,
      "y": 15,
      "z": 7,
      "name": "Rock_Calcite"
    },
    {
      "x": -16,
      "y": 16,
      "z": 7,
      "name": "Rock_Marble"
    },
    {
      "x": -16,
      "y": 12,
      "z": 11,
      "name": "Rock_Chalk"
    },
    {
      "x": -16,
      "y": 13,
      "z": 11,
      "name": "Rock_Chalk"
    },
    {
      "x": -16,
      "y": 14,
      "z": 11,
      "name": "Rock_Calcite"
    },
    {
      "x": -16,
      "y": 15,
      "z": 11,
      "name": "Rock_Calcite"
    },
    {
      "x": -16,
      "y": 11,
      "z": 12,
      "name": "Rock_Chalk"
    },
    {
      "x": -16,
      "y": 12,
      "z": 12,
      "name": "Rock_Chalk"
    },
    {
      "x": -16,
      "y": 13,
      "z": 12,
      "name": "Rock_Chalk"
    },
    {
      "x": -16,
      "y": 14,
      "z": 12,
      "name": "Rock_Calcite"
    },
    {
      "x": -16,
      "y": 10,
      "z": 13,
      "name": "Rock_Chalk"
    },
    {
      "x": -16,
      "y": 11,
      "z": 13,
      "name": "Rock_Chalk"
    },
    {
      "x": -16,
      "y": 12,
      "z": 13,
      "name": "Rock_Chalk"
    },
    {
      "x": -16,
      "y": 13,
      "z": 13,
      "name": "Rock_Chalk"
    },
    {
      "x": -15,
      "y": 10,
      "z": -13,
      "name": "Rock_Chalk"
    },
    {
      "x": -15,
      "y": 11,
      "z": -13,
      "name": "Rock_Chalk"
    },
    {
      "x": -15,
      "y": 12,
      "z": -13,
      "name": "Rock_Chalk"
    },
    {
      "x": -15,
      "y": 10,
      "z": -12,
      "name": "Rock_Chalk"
    },
    {
      "x": -15,
      "y": 11,
      "z": -12,
      "name": "Rock_Chalk"
    },
    {
      "x": -15,
      "y": 12,
      "z": -12,
      "name": "Rock_Chalk"
    },
    {
      "x": -15,
      "y": 13,
      "z": -12,
      "name": "Rock_Chalk"
    },
    {
      "x": -15,
      "y": 13,
      "z": -11,
      "name": "Rock_Chalk"
    },
    {
      "x": -15,
      "y": 14,
      "z": -11,
      "name": "Rock_Chalk"
    },
    {
      "x": -15,
      "y": 13,
      "z": -6,
      "name": "Rock_Chalk"
    },
    {
      "x": -15,
      "y": 14,
      "z": -6,
      "name": "Rock_Chalk"
    },
    {
      "x": -15,
      "y": 11,
      "z": -5,
      "name": "Rock_Chalk"
    },
    {
      "x": -15,
      "y": 12,
      "z": -5,
      "name": "Rock_Chalk"
    },
    {
      "x": -15,
      "y": 13,
      "z": -5,
      "name": "Rock_Chalk"
    },
    {
      "x": -15,
      "y": 14,
      "z": -5,
      "name": "Rock_Chalk"
    },
    {
      "x": -15,
      "y": 11,
      "z": -4,
      "name": "Rock_Chalk"
    },
    {
      "x": -15,
      "y": 12,
      "z": -4,
      "name": "Rock_Chalk"
    },
    {
      "x": -15,
      "y": 13,
      "z": -4,
      "name": "Rock_Chalk"
    },
    {
      "x": -15,
      "y": 14,
      "z": -4,
      "name": "Rock_Chalk"
    },
    {
      "x": -15,
      "y": 11,
      "z": -3,
      "name": "Rock_Chalk"
    },
    {
      "x": -15,
      "y": 12,
      "z": -3,
      "name": "Rock_Chalk"
    },
    {
      "x": -15,
      "y": 13,
      "z": -3,
      "name": "Rock_Chalk"
    },
    {
      "x": -15,
      "y": 11,
      "z": -2,
      "name": "Rock_Chalk"
    },
    {
      "x": -15,
      "y": 12,
      "z": -2,
      "name": "Rock_Chalk"
    },
    {
      "x": -15,
      "y": 13,
      "z": -2,
      "name": "Rock_Chalk"
    },
    {
      "x": -15,
      "y": 11,
      "z": -1,
      "name": "Rock_Chalk"
    },
    {
      "x": -15,
      "y": 12,
      "z": -1,
      "name": "Rock_Chalk"
    },
    {
      "x": -15,
      "y": 13,
      "z": -1,
      "name": "Rock_Chalk"
    },
    {
      "x": -15,
      "y": 11,
      "z": 0,
      "name": "Rock_Chalk"
    },
    {
      "x": -15,
      "y": 12,
      "z": 0,
      "name": "Rock_Chalk"
    },
    {
      "x": -15,
      "y": 13,
      "z": 0,
      "name": "Rock_Chalk"
    },
    {
      "x": -15,
      "y": 14,
      "z": 0,
      "name": "Rock_Chalk"
    },
    {
      "x": -15,
      "y": 12,
      "z": 1,
      "name": "Rock_Chalk"
    },
    {
      "x": -15,
      "y": 13,
      "z": 1,
      "name": "Rock_Chalk"
    },
    {
      "x": -15,
      "y": 14,
      "z": 1,
      "name": "Rock_Chalk"
    },
    {
      "x": -15,
      "y": 15,
      "z": 1,
      "name": "Rock_Calcite"
    },
    {
      "x": -15,
      "y": 13,
      "z": 2,
      "name": "Rock_Chalk"
    },
    {
      "x": -15,
      "y": 14,
      "z": 2,
      "name": "Rock_Chalk"
    },
    {
      "x": -15,
      "y": 15,
      "z": 2,
      "name": "Rock_Calcite"
    },
    {
      "x": -15,
      "y": 16,
      "z": 2,
      "name": "Rock_Calcite"
    },
    {
      "x": -15,
      "y": 14,
      "z": 3,
      "name": "Rock_Calcite"
    },
    {
      "x": -15,
      "y": 15,
      "z": 3,
      "name": "Rock_Calcite"
    },
    {
      "x": -15,
      "y": 16,
      "z": 3,
      "name": "Rock_Calcite"
    },
    {
      "x": -15,
      "y": 17,
      "z": 3,
      "name": "Rock_Marble"
    },
    {
      "x": -15,
      "y": 14,
      "z": 4,
      "name": "Rock_Calcite"
    },
    {
      "x": -15,
      "y": 15,
      "z": 4,
      "name": "Rock_Calcite"
    },
    {
      "x": -15,
      "y": 16,
      "z": 4,
      "name": "Rock_Calcite"
    },
    {
      "x": -15,
      "y": 17,
      "z": 4,
      "name": "Rock_Marble"
    },
    {
      "x": -15,
      "y": 15,
      "z": 5,
      "name": "Rock_Calcite"
    },
    {
      "x": -15,
      "y": 16,
      "z": 5,
      "name": "Rock_Calcite"
    },
    {
      "x": -15,
      "y": 17,
      "z": 5,
      "name": "Rock_Marble"
    },
    {
      "x": -15,
      "y": 18,
      "z": 5,
      "name": "Rock_Marble"
    },
    {
      "x": -15,
      "y": 15,
      "z": 6,
      "name": "Rock_Calcite"
    },
    {
      "x": -15,
      "y": 16,
      "z": 6,
      "name": "Rock_Marble"
    },
    {
      "x": -15,
      "y": 17,
      "z": 6,
      "name": "Rock_Marble"
    },
    {
      "x": -15,
      "y": 18,
      "z": 6,
      "name": "Rock_Marble"
    },
    {
      "x": -15,
      "y": 13,
      "z": 10,
      "name": "Rock_Chalk"
    },
    {
      "x": -15,
      "y": 14,
      "z": 10,
      "name": "Rock_Calcite"
    },
    {
      "x": -15,
      "y": 15,
      "z": 10,
      "name": "Rock_Calcite"
    },
    {
      "x": -15,
      "y": 16,
      "z": 10,
      "name": "Rock_Marble"
    },
    {
      "x": -15,
      "y": 13,
      "z": 11,
      "name": "Rock_Chalk"
    },
    {
      "x": -15,
      "y": 14,
      "z": 11,
      "name": "Rock_Calcite"
    },
    {
      "x": -15,
      "y": 15,
      "z": 11,
      "name": "Rock_Marble"
    },
    {
      "x": -15,
      "y": 12,
      "z": 12,
      "name": "Rock_Chalk"
    },
    {
      "x": -15,
      "y": 13,
      "z": 12,
      "name": "Rock_Chalk"
    },
    {
      "x": -15,
      "y": 14,
      "z": 12,
      "name": "Rock_Calcite"
    },
    {
      "x": -15,
      "y": 11,
      "z": 13,
      "name": "Rock_Chalk"
    },
    {
      "x": -15,
      "y": 12,
      "z": 13,
      "name": "Rock_Chalk"
    },
    {
      "x": -15,
      "y": 13,
      "z": 13,
      "name": "Rock_Chalk"
    },
    {
      "x": -15,
      "y": 9,
      "z": 14,
      "name": "Rock_Chalk"
    },
    {
      "x": -15,
      "y": 10,
      "z": 14,
      "name": "Rock_Chalk"
    },
    {
      "x": -15,
      "y": 11,
      "z": 14,
      "name": "Rock_Chalk"
    },
    {
      "x": -15,
      "y": 12,
      "z": 14,
      "name": "Rock_Chalk"
    },
    {
      "x": -14,
      "y": 10,
      "z": -14,
      "name": "Rock_Chalk"
    },
    {
      "x": -14,
      "y": 11,
      "z": -14,
      "name": "Rock_Chalk"
    },
    {
      "x": -14,
      "y": 12,
      "z": -14,
      "name": "Rock_Chalk"
    },
    {
      "x": -14,
      "y": 10,
      "z": -13,
      "name": "Rock_Chalk"
    },
    {
      "x": -14,
      "y": 11,
      "z": -13,
      "name": "Rock_Chalk"
    },
    {
      "x": -14,
      "y": 12,
      "z": -13,
      "name": "Rock_Chalk"
    },
    {
      "x": -14,
      "y": 13,
      "z": -13,
      "name": "Rock_Chalk"
    },
    {
      "x": -14,
      "y": 11,
      "z": -12,
      "name": "Rock_Chalk"
    },
    {
      "x": -14,
      "y": 12,
      "z": -12,
      "name": "Rock_Chalk"
    },
    {
      "x": -14,
      "y": 13,
      "z": -12,
      "name": "Rock_Chalk"
    },
    {
      "x": -14,
      "y": 14,
      "z": -12,
      "name": "Rock_Chalk"
    },
    {
      "x": -14,
      "y": 11,
      "z": -11,
      "name": "Rock_Chalk"
    },
    {
      "x": -14,
      "y": 12,
      "z": -11,
      "name": "Rock_Chalk"
    },
    {
      "x": -14,
      "y": 13,
      "z": -11,
      "name": "Rock_Chalk"
    },
    {
      "x": -14,
      "y": 14,
      "z": -11,
      "name": "Rock_Chalk"
    },
    {
      "x": -14,
      "y": 14,
      "z": -10,
      "name": "Rock_Chalk"
    },
    {
      "x": -14,
      "y": 15,
      "z": -10,
      "name": "Rock_Chalk"
    },
    {
      "x": -14,
      "y": 12,
      "z": -5,
      "name": "Rock_Chalk"
    },
    {
      "x": -14,
      "y": 13,
      "z": -5,
      "name": "Rock_Chalk"
    },
    {
      "x": -14,
      "y": 14,
      "z": -5,
      "name": "Rock_Chalk"
    },
    {
      "x": -14,
      "y": 15,
      "z": -5,
      "name": "Rock_Chalk"
    },
    {
      "x": -14,
      "y": 12,
      "z": -4,
      "name": "Rock_Chalk"
    },
    {
      "x": -14,
      "y": 13,
      "z": -4,
      "name": "Rock_Chalk"
    },
    {
      "x": -14,
      "y": 14,
      "z": -4,
      "name": "Rock_Chalk"
    },
    {
      "x": -14,
      "y": 15,
      "z": -4,
      "name": "Rock_Chalk"
    },
    {
      "x": -14,
      "y": 12,
      "z": -3,
      "name": "Rock_Chalk"
    },
    {
      "x": -14,
      "y": 13,
      "z": -3,
      "name": "Rock_Chalk"
    },
    {
      "x": -14,
      "y": 14,
      "z": -3,
      "name": "Rock_Chalk"
    },
    {
      "x": -14,
      "y": 15,
      "z": -3,
      "name": "Rock_Chalk"
    },
    {
      "x": -14,
      "y": 12,
      "z": -2,
      "name": "Rock_Chalk"
    },
    {
      "x": -14,
      "y": 13,
      "z": -2,
      "name": "Rock_Chalk"
    },
    {
      "x": -14,
      "y": 14,
      "z": -2,
      "name": "Rock_Chalk"
    },
    {
      "x": -14,
      "y": 15,
      "z": -2,
      "name": "Rock_Chalk"
    },
    {
      "x": -14,
      "y": 12,
      "z": -1,
      "name": "Rock_Chalk"
    },
    {
      "x": -14,
      "y": 13,
      "z": -1,
      "name": "Rock_Chalk"
    },
    {
      "x": -14,
      "y": 14,
      "z": -1,
      "name": "Rock_Chalk"
    },
    {
      "x": -14,
      "y": 15,
      "z": -1,
      "name": "Rock_Chalk"
    },
    {
      "x": -14,
      "y": 13,
      "z": 0,
      "name": "Rock_Chalk"
    },
    {
      "x": -14,
      "y": 14,
      "z": 0,
      "name": "Rock_Chalk"
    },
    {
      "x": -14,
      "y": 15,
      "z": 0,
      "name": "Rock_Calcite"
    },
    {
      "x": -14,
      "y": 13,
      "z": 1,
      "name": "Rock_Chalk"
    },
    {
      "x": -14,
      "y": 14,
      "z": 1,
      "name": "Rock_Chalk"
    },
    {
      "x": -14,
      "y": 15,
      "z": 1,
      "name": "Rock_Calcite"
    },
    {
      "x": -14,
      "y": 16,
      "z": 1,
      "name": "Rock_Calcite"
    },
    {
      "x": -14,
      "y": 14,
      "z": 2,
      "name": "Rock_Chalk"
    },
    {
      "x": -14,
      "y": 15,
      "z": 2,
      "name": "Rock_Calcite"
    },
    {
      "x": -14,
      "y": 16,
      "z": 2,
      "name": "Rock_Calcite"
    },
    {
      "x": -14,
      "y": 17,
      "z": 2,
      "name": "Rock_Calcite"
    },
    {
      "x": -14,
      "y": 15,
      "z": 3,
      "name": "Rock_Calcite"
    },
    {
      "x": -14,
      "y": 16,
      "z": 3,
      "name": "Rock_Calcite"
    },
    {
      "x": -14,
      "y": 17,
      "z": 3,
      "name": "Rock_Calcite"
    },
    {
      "x": -14,
      "y": 18,
      "z": 3,
      "name": "Rock_Marble"
    },
    {
      "x": -14,
      "y": 16,
      "z": 4,
      "name": "Rock_Calcite"
    },
    {
      "x": -14,
      "y": 17,
      "z": 4,
      "name": "Rock_Marble"
    },
    {
      "x": -14,
      "y": 18,
      "z": 4,
      "name": "Rock_Marble"
    },
    {
      "x": -14,
      "y": 19,
      "z": 4,
      "name": "Rock_Marble"
    },
    {
      "x": -14,
      "y": 16,
      "z": 5,
      "name": "Rock_Calcite"
    },
    {
      "x": -14,
      "y": 17,
      "z": 5,
      "name": "Rock_Marble"
    },
    {
      "x": -14,
      "y": 18,
      "z": 5,
      "name": "Rock_Marble"
    },
    {
      "x": -14,
      "y": 19,
      "z": 5,
      "name": "Rock_Marble"
    },
    {
      "x": -14,
      "y": 15,
      "z": 9,
      "name": "Rock_Calcite"
    },
    {
      "x": -14,
      "y": 16,
      "z": 9,
      "name": "Rock_Marble"
    },
    {
      "x": -14,
      "y": 17,
      "z": 9,
      "name": "Rock_Marble"
    },
    {
      "x": -14,
      "y": 18,
      "z": 9,
      "name": "Rock_Marble"
    },
    {
      "x": -14,
      "y": 14,
      "z": 10,
      "name": "Rock_Calcite"
    },
    {
      "x": -14,
      "y": 15,
      "z": 10,
      "name": "Rock_Calcite"
    },
    {
      "x": -14,
      "y": 16,
      "z": 10,
      "name": "Rock_Marble"
    },
    {
      "x": -14,
      "y": 17,
      "z": 10,
      "name": "Rock_Marble"
    },
    {
      "x": -14,
      "y": 13,
      "z": 11,
      "name": "Rock_Chalk"
    },
    {
      "x": -14,
      "y": 14,
      "z": 11,
      "name": "Rock_Calcite"
    },
    {
      "x": -14,
      "y": 15,
      "z": 11,
      "name": "Rock_Marble"
    },
    {
      "x": -14,
      "y": 16,
      "z": 11,
      "name": "Rock_Marble"
    },
    {
      "x": -14,
      "y": 12,
      "z": 12,
      "name": "Rock_Chalk"
    },
    {
      "x": -14,
      "y": 13,
      "z": 12,
      "name": "Rock_Chalk"
    },
    {
      "x": -14,
      "y": 14,
      "z": 12,
      "name": "Rock_Calcite"
    },
    {
      "x": -14,
      "y": 15,
      "z": 12,
      "name": "Rock_Marble"
    },
    {
      "x": -14,
      "y": 11,
      "z": 13,
      "name": "Rock_Chalk"
    },
    {
      "x": -14,
      "y": 12,
      "z": 13,
      "name": "Rock_Chalk"
    },
    {
      "x": -14,
      "y": 13,
      "z": 13,
      "name": "Rock_Chalk"
    },
    {
      "x": -14,
      "y": 14,
      "z": 13,
      "name": "Rock_Calcite"
    },
    {
      "x": -14,
      "y": 10,
      "z": 14,
      "name": "Rock_Chalk"
    },
    {
      "x": -14,
      "y": 11,
      "z": 14,
      "name": "Rock_Chalk"
    },
    {
      "x": -14,
      "y": 12,
      "z": 14,
      "name": "Rock_Chalk"
    },
    {
      "x": -13,
      "y": 10,
      "z": -15,
      "name": "Rock_Chalk"
    },
    {
      "x": -13,
      "y": 11,
      "z": -15,
      "name": "Rock_Chalk"
    },
    {
      "x": -13,
      "y": 12,
      "z": -15,
      "name": "Rock_Chalk"
    },
    {
      "x": -13,
      "y": 10,
      "z": -14,
      "name": "Rock_Chalk"
    },
    {
      "x": -13,
      "y": 11,
      "z": -14,
      "name": "Rock_Chalk"
    },
    {
      "x": -13,
      "y": 12,
      "z": -14,
      "name": "Rock_Chalk"
    },
    {
      "x": -13,
      "y": 13,
      "z": -14,
      "name": "Rock_Chalk"
    },
    {
      "x": -13,
      "y": 11,
      "z": -13,
      "name": "Rock_Chalk"
    },
    {
      "x": -13,
      "y": 12,
      "z": -13,
      "name": "Rock_Chalk"
    },
    {
      "x": -13,
      "y": 13,
      "z": -13,
      "name": "Rock_Chalk"
    },
    {
      "x": -13,
      "y": 14,
      "z": -13,
      "name": "Rock_Chalk"
    },
    {
      "x": -13,
      "y": 11,
      "z": -12,
      "name": "Rock_Chalk"
    },
    {
      "x": -13,
      "y": 12,
      "z": -12,
      "name": "Rock_Chalk"
    },
    {
      "x": -13,
      "y": 13,
      "z": -12,
      "name": "Rock_Chalk"
    },
    {
      "x": -13,
      "y": 14,
      "z": -12,
      "name": "Rock_Chalk"
    },
    {
      "x": -13,
      "y": 12,
      "z": -11,
      "name": "Rock_Chalk"
    },
    {
      "x": -13,
      "y": 13,
      "z": -11,
      "name": "Rock_Chalk"
    },
    {
      "x": -13,
      "y": 14,
      "z": -11,
      "name": "Rock_Chalk"
    },
    {
      "x": -13,
      "y": 15,
      "z": -11,
      "name": "Rock_Chalk"
    },
    {
      "x": -13,
      "y": 12,
      "z": -10,
      "name": "Rock_Chalk"
    },
    {
      "x": -13,
      "y": 13,
      "z": -10,
      "name": "Rock_Chalk"
    },
    {
      "x": -13,
      "y": 14,
      "z": -10,
      "name": "Rock_Chalk"
    },
    {
      "x": -13,
      "y": 15,
      "z": -10,
      "name": "Rock_Chalk"
    },
    {
      "x": -13,
      "y": 15,
      "z": -9,
      "name": "Rock_Chalk"
    },
    {
      "x": -13,
      "y": 16,
      "z": -9,
      "name": "Rock_Chalk"
    },
    {
      "x": -13,
      "y": 13,
      "z": -4,
      "name": "Rock_Chalk"
    },
    {
      "x": -13,
      "y": 14,
      "z": -4,
      "name": "Rock_Chalk"
    },
    {
      "x": -13,
      "y": 15,
      "z": -4,
      "name": "Rock_Chalk"
    },
    {
      "x": -13,
      "y": 16,
      "z": -4,
      "name": "Rock_Chalk"
    },
    {
      "x": -13,
      "y": 13,
      "z": -3,
      "name": "Rock_Chalk"
    },
    {
      "x": -13,
      "y": 14,
      "z": -3,
      "name": "Rock_Chalk"
    },
    {
      "x": -13,
      "y": 15,
      "z": -3,
      "name": "Rock_Chalk"
    },
    {
      "x": -13,
      "y": 16,
      "z": -3,
      "name": "Rock_Chalk"
    },
    {
      "x": -13,
      "y": 13,
      "z": -2,
      "name": "Rock_Chalk"
    },
    {
      "x": -13,
      "y": 14,
      "z": -2,
      "name": "Rock_Chalk"
    },
    {
      "x": -13,
      "y": 15,
      "z": -2,
      "name": "Rock_Chalk"
    },
    {
      "x": -13,
      "y": 16,
      "z": -2,
      "name": "Rock_Chalk"
    },
    {
      "x": -13,
      "y": 13,
      "z": -1,
      "name": "Rock_Chalk"
    },
    {
      "x": -13,
      "y": 14,
      "z": -1,
      "name": "Rock_Chalk"
    },
    {
      "x": -13,
      "y": 15,
      "z": -1,
      "name": "Rock_Calcite"
    },
    {
      "x": -13,
      "y": 16,
      "z": -1,
      "name": "Rock_Calcite"
    },
    {
      "x": -13,
      "y": 14,
      "z": 0,
      "name": "Rock_Chalk"
    },
    {
      "x": -13,
      "y": 15,
      "z": 0,
      "name": "Rock_Calcite"
    },
    {
      "x": -13,
      "y": 16,
      "z": 0,
      "name": "Rock_Calcite"
    },
    {
      "x": -13,
      "y": 17,
      "z": 0,
      "name": "Rock_Calcite"
    },
    {
      "x": -13,
      "y": 15,
      "z": 1,
      "name": "Rock_Calcite"
    },
    {
      "x": -13,
      "y": 16,
      "z": 1,
      "name": "Rock_Calcite"
    },
    {
      "x": -13,
      "y": 17,
      "z": 1,
      "name": "Rock_Calcite"
    },
    {
      "x": -13,
      "y": 18,
      "z": 1,
      "name": "Rock_Marble"
    },
    {
      "x": -13,
      "y": 16,
      "z": 2,
      "name": "Rock_Calcite"
    },
    {
      "x": -13,
      "y": 17,
      "z": 2,
      "name": "Rock_Calcite"
    },
    {
      "x": -13,
      "y": 18,
      "z": 2,
      "name": "Rock_Marble"
    },
    {
      "x": -13,
      "y": 19,
      "z": 2,
      "name": "Rock_Marble"
    },
    {
      "x": -13,
      "y": 16,
      "z": 3,
      "name": "Rock_Calcite"
    },
    {
      "x": -13,
      "y": 17,
      "z": 3,
      "name": "Rock_Calcite"
    },
    {
      "x": -13,
      "y": 18,
      "z": 3,
      "name": "Rock_Marble"
    },
    {
      "x": -13,
      "y": 19,
      "z": 3,
      "name": "Rock_Marble"
    },
    {
      "x": -13,
      "y": 17,
      "z": 4,
      "name": "Rock_Marble"
    },
    {
      "x": -13,
      "y": 18,
      "z": 4,
      "name": "Rock_Marble"
    },
    {
      "x": -13,
      "y": 19,
      "z": 4,
      "name": "Rock_Marble"
    },
    {
      "x": -13,
      "y": 20,
      "z": 4,
      "name": "Rock_Marble"
    },
    {
      "x": -13,
      "y": 19,
      "z": 5,
      "name": "Rock_Marble"
    },
    {
      "x": -13,
      "y": 20,
      "z": 5,
      "name": "Rock_Marble"
    },
    {
      "x": -13,
      "y": 18,
      "z": 8,
      "name": "Rock_Marble"
    },
    {
      "x": -13,
      "y": 19,
      "z": 8,
      "name": "Rock_Marble"
    },
    {
      "x": -13,
      "y": 15,
      "z": 9,
      "name": "Rock_Calcite"
    },
    {
      "x": -13,
      "y": 16,
      "z": 9,
      "name": "Rock_Marble"
    },
    {
      "x": -13,
      "y": 17,
      "z": 9,
      "name": "Rock_Marble"
    },
    {
      "x": -13,
      "y": 18,
      "z": 9,
      "name": "Rock_Marble"
    },
    {
      "x": -13,
      "y": 15,
      "z": 10,
      "name": "Rock_Calcite"
    },
    {
      "x": -13,
      "y": 16,
      "z": 10,
      "name": "Rock_Marble"
    },
    {
      "x": -13,
      "y": 17,
      "z": 10,
      "name": "Rock_Marble"
    },
    {
      "x": -13,
      "y": 18,
      "z": 10,
      "name": "Rock_Marble"
    },
    {
      "x": -13,
      "y": 14,
      "z": 11,
      "name": "Rock_Calcite"
    },
    {
      "x": -13,
      "y": 15,
      "z": 11,
      "name": "Rock_Marble"
    },
    {
      "x": -13,
      "y": 16,
      "z": 11,
      "name": "Rock_Marble"
    },
    {
      "x": -13,
      "y": 17,
      "z": 11,
      "name": "Rock_Marble"
    },
    {
      "x": -13,
      "y": 13,
      "z": 12,
      "name": "Rock_Chalk"
    },
    {
      "x": -13,
      "y": 14,
      "z": 12,
      "name": "Rock_Calcite"
    },
    {
      "x": -13,
      "y": 15,
      "z": 12,
      "name": "Rock_Marble"
    },
    {
      "x": -13,
      "y": 16,
      "z": 12,
      "name": "Rock_Marble"
    },
    {
      "x": -13,
      "y": 12,
      "z": 13,
      "name": "Rock_Chalk"
    },
    {
      "x": -13,
      "y": 13,
      "z": 13,
      "name": "Rock_Chalk"
    },
    {
      "x": -13,
      "y": 14,
      "z": 13,
      "name": "Rock_Calcite"
    },
    {
      "x": -13,
      "y": 15,
      "z": 13,
      "name": "Rock_Marble"
    },
    {
      "x": -13,
      "y": 10,
      "z": 14,
      "name": "Rock_Chalk"
    },
    {
      "x": -13,
      "y": 11,
      "z": 14,
      "name": "Rock_Chalk"
    },
    {
      "x": -13,
      "y": 12,
      "z": 14,
      "name": "Rock_Chalk"
    },
    {
      "x": -13,
      "y": 13,
      "z": 14,
      "name": "Rock_Chalk"
    },
    {
      "x": -12,
      "y": 10,
      "z": -16,
      "name": "Rock_Chalk"
    },
    {
      "x": -12,
      "y": 11,
      "z": -16,
      "name": "Rock_Chalk"
    },
    {
      "x": -12,
      "y": 12,
      "z": -16,
      "name": "Rock_Chalk"
    },
    {
      "x": -12,
      "y": 10,
      "z": -15,
      "name": "Rock_Chalk"
    },
    {
      "x": -12,
      "y": 11,
      "z": -15,
      "name": "Rock_Chalk"
    },
    {
      "x": -12,
      "y": 12,
      "z": -15,
      "name": "Rock_Chalk"
    },
    {
      "x": -12,
      "y": 13,
      "z": -15,
      "name": "Rock_Chalk"
    },
    {
      "x": -12,
      "y": 11,
      "z": -14,
      "name": "Rock_Chalk"
    },
    {
      "x": -12,
      "y": 12,
      "z": -14,
      "name": "Rock_Chalk"
    },
    {
      "x": -12,
      "y": 13,
      "z": -14,
      "name": "Rock_Chalk"
    },
    {
      "x": -12,
      "y": 14,
      "z": -14,
      "name": "Rock_Chalk"
    },
    {
      "x": -12,
      "y": 11,
      "z": -13,
      "name": "Rock_Chalk"
    },
    {
      "x": -12,
      "y": 12,
      "z": -13,
      "name": "Rock_Chalk"
    },
    {
      "x": -12,
      "y": 13,
      "z": -13,
      "name": "Rock_Chalk"
    },
    {
      "x": -12,
      "y": 14,
      "z": -13,
      "name": "Rock_Chalk"
    },
    {
      "x": -12,
      "y": 12,
      "z": -12,
      "name": "Rock_Chalk"
    },
    {
      "x": -12,
      "y": 13,
      "z": -12,
      "name": "Rock_Chalk"
    },
    {
      "x": -12,
      "y": 14,
      "z": -12,
      "name": "Rock_Chalk"
    },
    {
      "x": -12,
      "y": 15,
      "z": -12,
      "name": "Rock_Chalk"
    },
    {
      "x": -12,
      "y": 12,
      "z": -11,
      "name": "Rock_Chalk"
    },
    {
      "x": -12,
      "y": 13,
      "z": -11,
      "name": "Rock_Chalk"
    },
    {
      "x": -12,
      "y": 14,
      "z": -11,
      "name": "Rock_Chalk"
    },
    {
      "x": -12,
      "y": 15,
      "z": -11,
      "name": "Rock_Chalk"
    },
    {
      "x": -12,
      "y": 13,
      "z": -10,
      "name": "Rock_Chalk"
    },
    {
      "x": -12,
      "y": 14,
      "z": -10,
      "name": "Rock_Chalk"
    },
    {
      "x": -12,
      "y": 15,
      "z": -10,
      "name": "Rock_Chalk"
    },
    {
      "x": -12,
      "y": 16,
      "z": -10,
      "name": "Rock_Chalk"
    },
    {
      "x": -12,
      "y": 13,
      "z": -9,
      "name": "Rock_Chalk"
    },
    {
      "x": -12,
      "y": 14,
      "z": -9,
      "name": "Rock_Chalk"
    },
    {
      "x": -12,
      "y": 15,
      "z": -9,
      "name": "Rock_Chalk"
    },
    {
      "x": -12,
      "y": 16,
      "z": -9,
      "name": "Rock_Chalk"
    },
    {
      "x": -12,
      "y": 16,
      "z": -8,
      "name": "Rock_Chalk"
    },
    {
      "x": -12,
      "y": 17,
      "z": -8,
      "name": "Rock_Chalk"
    },
    {
      "x": -12,
      "y": 16,
      "z": -4,
      "name": "Rock_Chalk"
    },
    {
      "x": -12,
      "y": 17,
      "z": -4,
      "name": "Rock_Calcite"
    },
    {
      "x": -12,
      "y": 14,
      "z": -3,
      "name": "Rock_Chalk"
    },
    {
      "x": -12,
      "y": 15,
      "z": -3,
      "name": "Rock_Chalk"
    },
    {
      "x": -12,
      "y": 16,
      "z": -3,
      "name": "Rock_Chalk"
    },
    {
      "x": -12,
      "y": 17,
      "z": -3,
      "name": "Rock_Calcite"
    },
    {
      "x": -12,
      "y": 14,
      "z": -2,
      "name": "Rock_Chalk"
    },
    {
      "x": -12,
      "y": 15,
      "z": -2,
      "name": "Rock_Chalk"
    },
    {
      "x": -12,
      "y": 16,
      "z": -2,
      "name": "Rock_Calcite"
    },
    {
      "x": -12,
      "y": 17,
      "z": -2,
      "name": "Rock_Calcite"
    },
    {
      "x": -12,
      "y": 15,
      "z": -1,
      "name": "Rock_Calcite"
    },
    {
      "x": -12,
      "y": 16,
      "z": -1,
      "name": "Rock_Calcite"
    },
    {
      "x": -12,
      "y": 17,
      "z": -1,
      "name": "Rock_Marble"
    },
    {
      "x": -12,
      "y": 18,
      "z": -1,
      "name": "Rock_Marble"
    },
    {
      "x": -12,
      "y": 15,
      "z": 0,
      "name": "Rock_Calcite"
    },
    {
      "x": -12,
      "y": 16,
      "z": 0,
      "name": "Rock_Calcite"
    },
    {
      "x": -12,
      "y": 17,
      "z": 0,
      "name": "Rock_Marble"
    },
    {
      "x": -12,
      "y": 18,
      "z": 0,
      "name": "Rock_Marble"
    },
    {
      "x": -12,
      "y": 16,
      "z": 1,
      "name": "Rock_Calcite"
    },
    {
      "x": -12,
      "y": 17,
      "z": 1,
      "name": "Rock_Marble"
    },
    {
      "x": -12,
      "y": 18,
      "z": 1,
      "name": "Rock_Marble"
    },
    {
      "x": -12,
      "y": 19,
      "z": 1,
      "name": "Rock_Marble"
    },
    {
      "x": -12,
      "y": 17,
      "z": 2,
      "name": "Rock_Calcite"
    },
    {
      "x": -12,
      "y": 18,
      "z": 2,
      "name": "Rock_Marble"
    },
    {
      "x": -12,
      "y": 19,
      "z": 2,
      "name": "Rock_Marble"
    },
    {
      "x": -12,
      "y": 20,
      "z": 2,
      "name": "Rock_Marble"
    },
    {
      "x": -12,
      "y": 17,
      "z": 3,
      "name": "Rock_Calcite"
    },
    {
      "x": -12,
      "y": 18,
      "z": 3,
      "name": "Rock_Marble"
    },
    {
      "x": -12,
      "y": 19,
      "z": 3,
      "name": "Rock_Marble"
    },
    {
      "x": -12,
      "y": 20,
      "z": 3,
      "name": "Rock_Marble"
    },
    {
      "x": -12,
      "y": 19,
      "z": 4,
      "name": "Rock_Marble"
    },
    {
      "x": -12,
      "y": 20,
      "z": 4,
      "name": "Rock_Marble"
    },
    {
      "x": -12,
      "y": 21,
      "z": 4,
      "name": "Rock_Marble"
    },
    {
      "x": -12,
      "y": 19,
      "z": 7,
      "name": "Rock_Marble"
    },
    {
      "x": -12,
      "y": 20,
      "z": 7,
      "name": "Rock_Marble"
    },
    {
      "x": -12,
      "y": 17,
      "z": 8,
      "name": "Rock_Marble"
    },
    {
      "x": -12,
      "y": 18,
      "z": 8,
      "name": "Rock_Marble"
    },
    {
      "x": -12,
      "y": 19,
      "z": 8,
      "name": "Rock_Marble"
    },
    {
      "x": -12,
      "y": 20,
      "z": 8,
      "name": "Rock_Marble"
    },
    {
      "x": -12,
      "y": 16,
      "z": 9,
      "name": "Rock_Marble"
    },
    {
      "x": -12,
      "y": 17,
      "z": 9,
      "name": "Rock_Marble"
    },
    {
      "x": -12,
      "y": 18,
      "z": 9,
      "name": "Rock_Marble"
    },
    {
      "x": -12,
      "y": 19,
      "z": 9,
      "name": "Rock_Marble"
    },
    {
      "x": -12,
      "y": 15,
      "z": 10,
      "name": "Rock_Marble"
    },
    {
      "x": -12,
      "y": 16,
      "z": 10,
      "name": "Rock_Marble"
    },
    {
      "x": -12,
      "y": 17,
      "z": 10,
      "name": "Rock_Marble"
    },
    {
      "x": -12,
      "y": 18,
      "z": 10,
      "name": "Rock_Marble"
    },
    {
      "x": -12,
      "y": 15,
      "z": 11,
      "name": "Rock_Marble"
    },
    {
      "x": -12,
      "y": 16,
      "z": 11,
      "name": "Rock_Marble"
    },
    {
      "x": -12,
      "y": 17,
      "z": 11,
      "name": "Rock_Marble"
    },
    {
      "x": -12,
      "y": 18,
      "z": 11,
      "name": "Rock_Marble"
    },
    {
      "x": -12,
      "y": 14,
      "z": 12,
      "name": "Rock_Calcite"
    },
    {
      "x": -12,
      "y": 15,
      "z": 12,
      "name": "Rock_Marble"
    },
    {
      "x": -12,
      "y": 16,
      "z": 12,
      "name": "Rock_Marble"
    },
    {
      "x": -12,
      "y": 17,
      "z": 12,
      "name": "Rock_Marble"
    },
    {
      "x": -12,
      "y": 13,
      "z": 13,
      "name": "Rock_Chalk"
    },
    {
      "x": -12,
      "y": 14,
      "z": 13,
      "name": "Rock_Calcite"
    },
    {
      "x": -12,
      "y": 15,
      "z": 13,
      "name": "Rock_Marble"
    },
    {
      "x": -12,
      "y": 11,
      "z": 14,
      "name": "Rock_Chalk"
    },
    {
      "x": -12,
      "y": 12,
      "z": 14,
      "name": "Rock_Chalk"
    },
    {
      "x": -12,
      "y": 13,
      "z": 14,
      "name": "Rock_Chalk"
    },
    {
      "x": -12,
      "y": 14,
      "z": 14,
      "name": "Rock_Calcite"
    },
    {
      "x": -12,
      "y": 9,
      "z": 15,
      "name": "Rock_Chalk"
    },
    {
      "x": -12,
      "y": 10,
      "z": 15,
      "name": "Rock_Chalk"
    },
    {
      "x": -12,
      "y": 11,
      "z": 15,
      "name": "Rock_Chalk"
    },
    {
      "x": -12,
      "y": 12,
      "z": 15,
      "name": "Rock_Chalk"
    },
    {
      "x": -11,
      "y": 10,
      "z": -17,
      "name": "Rock_Chalk"
    },
    {
      "x": -11,
      "y": 11,
      "z": -17,
      "name": "Rock_Chalk"
    },
    {
      "x": -11,
      "y": 12,
      "z": -17,
      "name": "Rock_Chalk"
    },
    {
      "x": -11,
      "y": 10,
      "z": -16,
      "name": "Rock_Chalk"
    },
    {
      "x": -11,
      "y": 11,
      "z": -16,
      "name": "Rock_Chalk"
    },
    {
      "x": -11,
      "y": 12,
      "z": -16,
      "name": "Rock_Chalk"
    },
    {
      "x": -11,
      "y": 13,
      "z": -16,
      "name": "Rock_Chalk"
    },
    {
      "x": -11,
      "y": 11,
      "z": -15,
      "name": "Rock_Chalk"
    },
    {
      "x": -11,
      "y": 12,
      "z": -15,
      "name": "Rock_Chalk"
    },
    {
      "x": -11,
      "y": 13,
      "z": -15,
      "name": "Rock_Chalk"
    },
    {
      "x": -11,
      "y": 14,
      "z": -15,
      "name": "Rock_Chalk"
    },
    {
      "x": -11,
      "y": 11,
      "z": -14,
      "name": "Rock_Chalk"
    },
    {
      "x": -11,
      "y": 12,
      "z": -14,
      "name": "Rock_Chalk"
    },
    {
      "x": -11,
      "y": 13,
      "z": -14,
      "name": "Rock_Chalk"
    },
    {
      "x": -11,
      "y": 14,
      "z": -14,
      "name": "Rock_Chalk"
    },
    {
      "x": -11,
      "y": 12,
      "z": -13,
      "name": "Rock_Chalk"
    },
    {
      "x": -11,
      "y": 13,
      "z": -13,
      "name": "Rock_Chalk"
    },
    {
      "x": -11,
      "y": 14,
      "z": -13,
      "name": "Rock_Chalk"
    },
    {
      "x": -11,
      "y": 12,
      "z": -12,
      "name": "Rock_Chalk"
    },
    {
      "x": -11,
      "y": 13,
      "z": -12,
      "name": "Rock_Chalk"
    },
    {
      "x": -11,
      "y": 14,
      "z": -12,
      "name": "Rock_Chalk"
    },
    {
      "x": -11,
      "y": 15,
      "z": -12,
      "name": "Rock_Chalk"
    },
    {
      "x": -11,
      "y": 12,
      "z": -11,
      "name": "Rock_Chalk"
    },
    {
      "x": -11,
      "y": 13,
      "z": -11,
      "name": "Rock_Chalk"
    },
    {
      "x": -11,
      "y": 14,
      "z": -11,
      "name": "Rock_Chalk"
    },
    {
      "x": -11,
      "y": 15,
      "z": -11,
      "name": "Rock_Chalk"
    },
    {
      "x": -11,
      "y": 13,
      "z": -10,
      "name": "Rock_Chalk"
    },
    {
      "x": -11,
      "y": 14,
      "z": -10,
      "name": "Rock_Chalk"
    },
    {
      "x": -11,
      "y": 15,
      "z": -10,
      "name": "Rock_Chalk"
    },
    {
      "x": -11,
      "y": 16,
      "z": -10,
      "name": "Rock_Chalk"
    },
    {
      "x": -11,
      "y": 13,
      "z": -9,
      "name": "Rock_Chalk"
    },
    {
      "x": -11,
      "y": 14,
      "z": -9,
      "name": "Rock_Chalk"
    },
    {
      "x": -11,
      "y": 15,
      "z": -9,
      "name": "Rock_Chalk"
    },
    {
      "x": -11,
      "y": 16,
      "z": -9,
      "name": "Rock_Chalk"
    },
    {
      "x": -11,
      "y": 16,
      "z": -8,
      "name": "Rock_Chalk"
    },
    {
      "x": -11,
      "y": 17,
      "z": -8,
      "name": "Rock_Chalk"
    },
    {
      "x": -11,
      "y": 18,
      "z": -2,
      "name": "Rock_Marble"
    },
    {
      "x": -11,
      "y": 19,
      "z": -2,
      "name": "Rock_Marble"
    },
    {
      "x": -11,
      "y": 18,
      "z": -1,
      "name": "Rock_Marble"
    },
    {
      "x": -11,
      "y": 19,
      "z": -1,
      "name": "Rock_Marble"
    },
    {
      "x": -11,
      "y": 18,
      "z": 0,
      "name": "Rock_Marble"
    },
    {
      "x": -11,
      "y": 19,
      "z": 0,
      "name": "Rock_Marble"
    },
    {
      "x": -11,
      "y": 19,
      "z": 1,
      "name": "Rock_Marble"
    },
    {
      "x": -11,
      "y": 20,
      "z": 1,
      "name": "Rock_Marble"
    },
    {
      "x": -11,
      "y": 17,
      "z": 2,
      "name": "Rock_Marble"
    },
    {
      "x": -11,
      "y": 18,
      "z": 2,
      "name": "Rock_Marble"
    },
    {
      "x": -11,
      "y": 19,
      "z": 2,
      "name": "Rock_Marble"
    },
    {
      "x": -11,
      "y": 20,
      "z": 2,
      "name": "Rock_Marble"
    },
    {
      "x": -11,
      "y": 20,
      "z": 3,
      "name": "Rock_Marble"
    },
    {
      "x": -11,
      "y": 21,
      "z": 3,
      "name": "Rock_Marble"
    },
    {
      "x": -11,
      "y": 20,
      "z": 6,
      "name": "Rock_Marble"
    },
    {
      "x": -11,
      "y": 21,
      "z": 6,
      "name": "Rock_Marble"
    },
    {
      "x": -11,
      "y": 18,
      "z": 7,
      "name": "Rock_Marble"
    },
    {
      "x": -11,
      "y": 19,
      "z": 7,
      "name": "Rock_Marble"
    },
    {
      "x": -11,
      "y": 20,
      "z": 7,
      "name": "Rock_Marble"
    },
    {
      "x": -11,
      "y": 21,
      "z": 7,
      "name": "Rock_Marble"
    },
    {
      "x": -11,
      "y": 17,
      "z": 8,
      "name": "Rock_Marble"
    },
    {
      "x": -11,
      "y": 18,
      "z": 8,
      "name": "Rock_Marble"
    },
    {
      "x": -11,
      "y": 19,
      "z": 8,
      "name": "Rock_Marble"
    },
    {
      "x": -11,
      "y": 20,
      "z": 8,
      "name": "Rock_Marble"
    },
    {
      "x": -11,
      "y": 17,
      "z": 9,
      "name": "Rock_Marble"
    },
    {
      "x": -11,
      "y": 18,
      "z": 9,
      "name": "Rock_Marble"
    },
    {
      "x": -11,
      "y": 19,
      "z": 9,
      "name": "Rock_Marble"
    },
    {
      "x": -11,
      "y": 20,
      "z": 9,
      "name": "Rock_Marble"
    },
    {
      "x": -11,
      "y": 16,
      "z": 10,
      "name": "Rock_Marble"
    },
    {
      "x": -11,
      "y": 17,
      "z": 10,
      "name": "Rock_Marble"
    },
    {
      "x": -11,
      "y": 18,
      "z": 10,
      "name": "Rock_Marble"
    },
    {
      "x": -11,
      "y": 19,
      "z": 10,
      "name": "Rock_Marble"
    },
    {
      "x": -11,
      "y": 15,
      "z": 11,
      "name": "Rock_Marble"
    },
    {
      "x": -11,
      "y": 16,
      "z": 11,
      "name": "Rock_Marble"
    },
    {
      "x": -11,
      "y": 17,
      "z": 11,
      "name": "Rock_Marble"
    },
    {
      "x": -11,
      "y": 18,
      "z": 11,
      "name": "Rock_Marble"
    },
    {
      "x": -11,
      "y": 14,
      "z": 12,
      "name": "Rock_Calcite"
    },
    {
      "x": -11,
      "y": 15,
      "z": 12,
      "name": "Rock_Marble"
    },
    {
      "x": -11,
      "y": 16,
      "z": 12,
      "name": "Rock_Marble"
    },
    {
      "x": -11,
      "y": 17,
      "z": 12,
      "name": "Rock_Marble"
    },
    {
      "x": -11,
      "y": 13,
      "z": 13,
      "name": "Rock_Chalk"
    },
    {
      "x": -11,
      "y": 14,
      "z": 13,
      "name": "Rock_Calcite"
    },
    {
      "x": -11,
      "y": 15,
      "z": 13,
      "name": "Rock_Marble"
    },
    {
      "x": -11,
      "y": 16,
      "z": 13,
      "name": "Rock_Marble"
    },
    {
      "x": -11,
      "y": 12,
      "z": 14,
      "name": "Rock_Chalk"
    },
    {
      "x": -11,
      "y": 13,
      "z": 14,
      "name": "Rock_Chalk"
    },
    {
      "x": -11,
      "y": 14,
      "z": 14,
      "name": "Rock_Calcite"
    },
    {
      "x": -11,
      "y": 15,
      "z": 14,
      "name": "Rock_Marble"
    },
    {
      "x": -11,
      "y": 10,
      "z": 15,
      "name": "Rock_Chalk"
    },
    {
      "x": -11,
      "y": 11,
      "z": 15,
      "name": "Rock_Chalk"
    },
    {
      "x": -11,
      "y": 12,
      "z": 15,
      "name": "Rock_Chalk"
    },
    {
      "x": -11,
      "y": 13,
      "z": 15,
      "name": "Rock_Chalk"
    },
    {
      "x": -10,
      "y": 9,
      "z": -18,
      "name": "Rock_Chalk"
    },
    {
      "x": -10,
      "y": 10,
      "z": -18,
      "name": "Rock_Chalk"
    },
    {
      "x": -10,
      "y": 11,
      "z": -18,
      "name": "Rock_Chalk"
    },
    {
      "x": -10,
      "y": 12,
      "z": -18,
      "name": "Rock_Chalk"
    },
    {
      "x": -10,
      "y": 10,
      "z": -17,
      "name": "Rock_Chalk"
    },
    {
      "x": -10,
      "y": 11,
      "z": -17,
      "name": "Rock_Chalk"
    },
    {
      "x": -10,
      "y": 12,
      "z": -17,
      "name": "Rock_Chalk"
    },
    {
      "x": -10,
      "y": 13,
      "z": -17,
      "name": "Rock_Chalk"
    },
    {
      "x": -10,
      "y": 11,
      "z": -16,
      "name": "Rock_Chalk"
    },
    {
      "x": -10,
      "y": 12,
      "z": -16,
      "name": "Rock_Chalk"
    },
    {
      "x": -10,
      "y": 13,
      "z": -16,
      "name": "Rock_Chalk"
    },
    {
      "x": -10,
      "y": 14,
      "z": -16,
      "name": "Rock_Chalk"
    },
    {
      "x": -10,
      "y": 11,
      "z": -15,
      "name": "Rock_Chalk"
    },
    {
      "x": -10,
      "y": 12,
      "z": -15,
      "name": "Rock_Chalk"
    },
    {
      "x": -10,
      "y": 13,
      "z": -15,
      "name": "Rock_Chalk"
    },
    {
      "x": -10,
      "y": 14,
      "z": -15,
      "name": "Rock_Chalk"
    },
    {
      "x": -10,
      "y": 12,
      "z": -14,
      "name": "Rock_Chalk"
    },
    {
      "x": -10,
      "y": 13,
      "z": -14,
      "name": "Rock_Chalk"
    },
    {
      "x": -10,
      "y": 14,
      "z": -14,
      "name": "Rock_Chalk"
    },
    {
      "x": -10,
      "y": 12,
      "z": -13,
      "name": "Rock_Chalk"
    },
    {
      "x": -10,
      "y": 13,
      "z": -13,
      "name": "Rock_Chalk"
    },
    {
      "x": -10,
      "y": 14,
      "z": -13,
      "name": "Rock_Chalk"
    },
    {
      "x": -10,
      "y": 15,
      "z": -13,
      "name": "Rock_Chalk"
    },
    {
      "x": -10,
      "y": 12,
      "z": -12,
      "name": "Rock_Chalk"
    },
    {
      "x": -10,
      "y": 13,
      "z": -12,
      "name": "Rock_Chalk"
    },
    {
      "x": -10,
      "y": 14,
      "z": -12,
      "name": "Rock_Chalk"
    },
    {
      "x": -10,
      "y": 15,
      "z": -12,
      "name": "Rock_Chalk"
    },
    {
      "x": -10,
      "y": 12,
      "z": -11,
      "name": "Rock_Chalk"
    },
    {
      "x": -10,
      "y": 13,
      "z": -11,
      "name": "Rock_Chalk"
    },
    {
      "x": -10,
      "y": 14,
      "z": -11,
      "name": "Rock_Chalk"
    },
    {
      "x": -10,
      "y": 15,
      "z": -11,
      "name": "Rock_Chalk"
    },
    {
      "x": -10,
      "y": 13,
      "z": -10,
      "name": "Rock_Chalk"
    },
    {
      "x": -10,
      "y": 14,
      "z": -10,
      "name": "Rock_Chalk"
    },
    {
      "x": -10,
      "y": 15,
      "z": -10,
      "name": "Rock_Chalk"
    },
    {
      "x": -10,
      "y": 16,
      "z": -10,
      "name": "Rock_Chalk"
    },
    {
      "x": -10,
      "y": 14,
      "z": -9,
      "name": "Rock_Chalk"
    },
    {
      "x": -10,
      "y": 15,
      "z": -9,
      "name": "Rock_Chalk"
    },
    {
      "x": -10,
      "y": 16,
      "z": -9,
      "name": "Rock_Chalk"
    },
    {
      "x": -10,
      "y": 17,
      "z": -9,
      "name": "Rock_Chalk"
    },
    {
      "x": -10,
      "y": 16,
      "z": -8,
      "name": "Rock_Chalk"
    },
    {
      "x": -10,
      "y": 17,
      "z": -8,
      "name": "Rock_Chalk"
    },
    {
      "x": -10,
      "y": 22,
      "z": 3,
      "name": "Rock_Marble"
    },
    {
      "x": -10,
      "y": 21,
      "z": 6,
      "name": "Rock_Marble"
    },
    {
      "x": -10,
      "y": 22,
      "z": 6,
      "name": "Rock_Marble"
    },
    {
      "x": -10,
      "y": 18,
      "z": 7,
      "name": "Rock_Marble"
    },
    {
      "x": -10,
      "y": 19,
      "z": 7,
      "name": "Rock_Marble"
    },
    {
      "x": -10,
      "y": 20,
      "z": 7,
      "name": "Rock_Marble"
    },
    {
      "x": -10,
      "y": 21,
      "z": 7,
      "name": "Rock_Marble"
    },
    {
      "x": -10,
      "y": 18,
      "z": 8,
      "name": "Rock_Marble"
    },
    {
      "x": -10,
      "y": 19,
      "z": 8,
      "name": "Rock_Marble"
    },
    {
      "x": -10,
      "y": 20,
      "z": 8,
      "name": "Rock_Marble"
    },
    {
      "x": -10,
      "y": 21,
      "z": 8,
      "name": "Rock_Marble"
    },
    {
      "x": -10,
      "y": 17,
      "z": 9,
      "name": "Rock_Marble"
    },
    {
      "x": -10,
      "y": 18,
      "z": 9,
      "name": "Rock_Marble"
    },
    {
      "x": -10,
      "y": 19,
      "z": 9,
      "name": "Rock_Marble"
    },
    {
      "x": -10,
      "y": 20,
      "z": 9,
      "name": "Rock_Marble"
    },
    {
      "x": -10,
      "y": 17,
      "z": 10,
      "name": "Rock_Marble"
    },
    {
      "x": -10,
      "y": 18,
      "z": 10,
      "name": "Rock_Marble"
    },
    {
      "x": -10,
      "y": 19,
      "z": 10,
      "name": "Rock_Marble"
    },
    {
      "x": -10,
      "y": 20,
      "z": 10,
      "name": "Rock_Marble"
    },
    {
      "x": -10,
      "y": 16,
      "z": 11,
      "name": "Rock_Marble"
    },
    {
      "x": -10,
      "y": 17,
      "z": 11,
      "name": "Rock_Marble"
    },
    {
      "x": -10,
      "y": 18,
      "z": 11,
      "name": "Rock_Marble"
    },
    {
      "x": -10,
      "y": 19,
      "z": 11,
      "name": "Rock_Marble"
    },
    {
      "x": -10,
      "y": 15,
      "z": 12,
      "name": "Rock_Marble"
    },
    {
      "x": -10,
      "y": 16,
      "z": 12,
      "name": "Rock_Marble"
    },
    {
      "x": -10,
      "y": 17,
      "z": 12,
      "name": "Rock_Marble"
    },
    {
      "x": -10,
      "y": 18,
      "z": 12,
      "name": "Rock_Marble"
    },
    {
      "x": -10,
      "y": 14,
      "z": 13,
      "name": "Rock_Calcite"
    },
    {
      "x": -10,
      "y": 15,
      "z": 13,
      "name": "Rock_Marble"
    },
    {
      "x": -10,
      "y": 16,
      "z": 13,
      "name": "Rock_Marble"
    },
    {
      "x": -10,
      "y": 17,
      "z": 13,
      "name": "Rock_Marble"
    },
    {
      "x": -10,
      "y": 13,
      "z": 14,
      "name": "Rock_Chalk"
    },
    {
      "x": -10,
      "y": 14,
      "z": 14,
      "name": "Rock_Calcite"
    },
    {
      "x": -10,
      "y": 15,
      "z": 14,
      "name": "Rock_Marble"
    },
    {
      "x": -10,
      "y": 11,
      "z": 15,
      "name": "Rock_Chalk"
    },
    {
      "x": -10,
      "y": 12,
      "z": 15,
      "name": "Rock_Chalk"
    },
    {
      "x": -10,
      "y": 13,
      "z": 15,
      "name": "Rock_Chalk"
    },
    {
      "x": -10,
      "y": 14,
      "z": 15,
      "name": "Rock_Calcite"
    },
    {
      "x": -10,
      "y": 9,
      "z": 16,
      "name": "Rock_Chalk"
    },
    {
      "x": -10,
      "y": 10,
      "z": 16,
      "name": "Rock_Chalk"
    },
    {
      "x": -10,
      "y": 11,
      "z": 16,
      "name": "Rock_Chalk"
    },
    {
      "x": -10,
      "y": 12,
      "z": 16,
      "name": "Rock_Chalk"
    },
    {
      "x": -9,
      "y": 9,
      "z": -18,
      "name": "Rock_Chalk"
    },
    {
      "x": -9,
      "y": 10,
      "z": -18,
      "name": "Rock_Chalk"
    },
    {
      "x": -9,
      "y": 11,
      "z": -18,
      "name": "Rock_Chalk"
    },
    {
      "x": -9,
      "y": 12,
      "z": -18,
      "name": "Rock_Chalk"
    },
    {
      "x": -9,
      "y": 10,
      "z": -17,
      "name": "Rock_Chalk"
    },
    {
      "x": -9,
      "y": 11,
      "z": -17,
      "name": "Rock_Chalk"
    },
    {
      "x": -9,
      "y": 12,
      "z": -17,
      "name": "Rock_Chalk"
    },
    {
      "x": -9,
      "y": 13,
      "z": -17,
      "name": "Rock_Chalk"
    },
    {
      "x": -9,
      "y": 11,
      "z": -16,
      "name": "Rock_Chalk"
    },
    {
      "x": -9,
      "y": 12,
      "z": -16,
      "name": "Rock_Chalk"
    },
    {
      "x": -9,
      "y": 13,
      "z": -16,
      "name": "Rock_Chalk"
    },
    {
      "x": -9,
      "y": 14,
      "z": -16,
      "name": "Rock_Chalk"
    },
    {
      "x": -9,
      "y": 11,
      "z": -15,
      "name": "Rock_Chalk"
    },
    {
      "x": -9,
      "y": 12,
      "z": -15,
      "name": "Rock_Chalk"
    },
    {
      "x": -9,
      "y": 13,
      "z": -15,
      "name": "Rock_Chalk"
    },
    {
      "x": -9,
      "y": 14,
      "z": -15,
      "name": "Rock_Chalk"
    },
    {
      "x": -9,
      "y": 12,
      "z": -14,
      "name": "Rock_Chalk"
    },
    {
      "x": -9,
      "y": 13,
      "z": -14,
      "name": "Rock_Chalk"
    },
    {
      "x": -9,
      "y": 14,
      "z": -14,
      "name": "Rock_Chalk"
    },
    {
      "x": -9,
      "y": 15,
      "z": -14,
      "name": "Rock_Chalk"
    },
    {
      "x": -9,
      "y": 12,
      "z": -13,
      "name": "Rock_Chalk"
    },
    {
      "x": -9,
      "y": 13,
      "z": -13,
      "name": "Rock_Chalk"
    },
    {
      "x": -9,
      "y": 14,
      "z": -13,
      "name": "Rock_Chalk"
    },
    {
      "x": -9,
      "y": 15,
      "z": -13,
      "name": "Rock_Chalk"
    },
    {
      "x": -9,
      "y": 12,
      "z": -12,
      "name": "Rock_Chalk"
    },
    {
      "x": -9,
      "y": 13,
      "z": -12,
      "name": "Rock_Chalk"
    },
    {
      "x": -9,
      "y": 14,
      "z": -12,
      "name": "Rock_Chalk"
    },
    {
      "x": -9,
      "y": 15,
      "z": -12,
      "name": "Rock_Chalk"
    },
    {
      "x": -9,
      "y": 12,
      "z": -11,
      "name": "Rock_Chalk"
    },
    {
      "x": -9,
      "y": 13,
      "z": -11,
      "name": "Rock_Chalk"
    },
    {
      "x": -9,
      "y": 14,
      "z": -11,
      "name": "Rock_Chalk"
    },
    {
      "x": -9,
      "y": 15,
      "z": -11,
      "name": "Rock_Chalk"
    },
    {
      "x": -9,
      "y": 13,
      "z": -10,
      "name": "Rock_Chalk"
    },
    {
      "x": -9,
      "y": 14,
      "z": -10,
      "name": "Rock_Chalk"
    },
    {
      "x": -9,
      "y": 15,
      "z": -10,
      "name": "Rock_Chalk"
    },
    {
      "x": -9,
      "y": 16,
      "z": -10,
      "name": "Rock_Chalk"
    },
    {
      "x": -9,
      "y": 14,
      "z": -9,
      "name": "Rock_Chalk"
    },
    {
      "x": -9,
      "y": 15,
      "z": -9,
      "name": "Rock_Chalk"
    },
    {
      "x": -9,
      "y": 16,
      "z": -9,
      "name": "Rock_Chalk"
    },
    {
      "x": -9,
      "y": 17,
      "z": -9,
      "name": "Rock_Calcite"
    },
    {
      "x": -9,
      "y": 17,
      "z": -8,
      "name": "Rock_Calcite"
    },
    {
      "x": -9,
      "y": 18,
      "z": -8,
      "name": "Rock_Calcite"
    },
    {
      "x": -9,
      "y": 23,
      "z": 5,
      "name": "Rock_Marble"
    },
    {
      "x": -9,
      "y": 19,
      "z": 6,
      "name": "Rock_Marble"
    },
    {
      "x": -9,
      "y": 20,
      "z": 6,
      "name": "Rock_Marble"
    },
    {
      "x": -9,
      "y": 21,
      "z": 6,
      "name": "Rock_Marble"
    },
    {
      "x": -9,
      "y": 22,
      "z": 6,
      "name": "Rock_Marble"
    },
    {
      "x": -9,
      "y": 19,
      "z": 7,
      "name": "Rock_Marble"
    },
    {
      "x": -9,
      "y": 20,
      "z": 7,
      "name": "Rock_Marble"
    },
    {
      "x": -9,
      "y": 21,
      "z": 7,
      "name": "Rock_Marble"
    },
    {
      "x": -9,
      "y": 22,
      "z": 7,
      "name": "Rock_Marble"
    },
    {
      "x": -9,
      "y": 18,
      "z": 8,
      "name": "Rock_Marble"
    },
    {
      "x": -9,
      "y": 19,
      "z": 8,
      "name": "Rock_Marble"
    },
    {
      "x": -9,
      "y": 20,
      "z": 8,
      "name": "Rock_Marble"
    },
    {
      "x": -9,
      "y": 21,
      "z": 8,
      "name": "Rock_Marble"
    },
    {
      "x": -9,
      "y": 18,
      "z": 9,
      "name": "Rock_Marble"
    },
    {
      "x": -9,
      "y": 19,
      "z": 9,
      "name": "Rock_Marble"
    },
    {
      "x": -9,
      "y": 20,
      "z": 9,
      "name": "Rock_Marble"
    },
    {
      "x": -9,
      "y": 21,
      "z": 9,
      "name": "Rock_Marble"
    },
    {
      "x": -9,
      "y": 17,
      "z": 10,
      "name": "Rock_Marble"
    },
    {
      "x": -9,
      "y": 18,
      "z": 10,
      "name": "Rock_Marble"
    },
    {
      "x": -9,
      "y": 19,
      "z": 10,
      "name": "Rock_Marble"
    },
    {
      "x": -9,
      "y": 20,
      "z": 10,
      "name": "Rock_Marble"
    },
    {
      "x": -9,
      "y": 16,
      "z": 11,
      "name": "Rock_Marble"
    },
    {
      "x": -9,
      "y": 17,
      "z": 11,
      "name": "Rock_Marble"
    },
    {
      "x": -9,
      "y": 18,
      "z": 11,
      "name": "Rock_Marble"
    },
    {
      "x": -9,
      "y": 19,
      "z": 11,
      "name": "Rock_Marble"
    },
    {
      "x": -9,
      "y": 15,
      "z": 12,
      "name": "Rock_Marble"
    },
    {
      "x": -9,
      "y": 16,
      "z": 12,
      "name": "Rock_Marble"
    },
    {
      "x": -9,
      "y": 17,
      "z": 12,
      "name": "Rock_Marble"
    },
    {
      "x": -9,
      "y": 18,
      "z": 12,
      "name": "Rock_Marble"
    },
    {
      "x": -9,
      "y": 14,
      "z": 13,
      "name": "Rock_Calcite"
    },
    {
      "x": -9,
      "y": 15,
      "z": 13,
      "name": "Rock_Marble"
    },
    {
      "x": -9,
      "y": 16,
      "z": 13,
      "name": "Rock_Marble"
    },
    {
      "x": -9,
      "y": 17,
      "z": 13,
      "name": "Rock_Marble"
    },
    {
      "x": -9,
      "y": 13,
      "z": 14,
      "name": "Rock_Chalk"
    },
    {
      "x": -9,
      "y": 14,
      "z": 14,
      "name": "Rock_Calcite"
    },
    {
      "x": -9,
      "y": 15,
      "z": 14,
      "name": "Rock_Marble"
    },
    {
      "x": -9,
      "y": 16,
      "z": 14,
      "name": "Rock_Marble"
    },
    {
      "x": -9,
      "y": 12,
      "z": 15,
      "name": "Rock_Chalk"
    },
    {
      "x": -9,
      "y": 13,
      "z": 15,
      "name": "Rock_Chalk"
    },
    {
      "x": -9,
      "y": 14,
      "z": 15,
      "name": "Rock_Calcite"
    },
    {
      "x": -9,
      "y": 10,
      "z": 16,
      "name": "Rock_Chalk"
    },
    {
      "x": -9,
      "y": 11,
      "z": 16,
      "name": "Rock_Chalk"
    },
    {
      "x": -9,
      "y": 12,
      "z": 16,
      "name": "Rock_Chalk"
    },
    {
      "x": -9,
      "y": 13,
      "z": 16,
      "name": "Rock_Chalk"
    },
    {
      "x": -8,
      "y": 9,
      "z": -18,
      "name": "Rock_Chalk"
    },
    {
      "x": -8,
      "y": 10,
      "z": -18,
      "name": "Rock_Chalk"
    },
    {
      "x": -8,
      "y": 11,
      "z": -18,
      "name": "Rock_Chalk"
    },
    {
      "x": -8,
      "y": 12,
      "z": -18,
      "name": "Rock_Chalk"
    },
    {
      "x": -8,
      "y": 10,
      "z": -17,
      "name": "Rock_Chalk"
    },
    {
      "x": -8,
      "y": 11,
      "z": -17,
      "name": "Rock_Chalk"
    },
    {
      "x": -8,
      "y": 12,
      "z": -17,
      "name": "Rock_Chalk"
    },
    {
      "x": -8,
      "y": 13,
      "z": -17,
      "name": "Rock_Chalk"
    },
    {
      "x": -8,
      "y": 11,
      "z": -16,
      "name": "Rock_Chalk"
    },
    {
      "x": -8,
      "y": 12,
      "z": -16,
      "name": "Rock_Chalk"
    },
    {
      "x": -8,
      "y": 13,
      "z": -16,
      "name": "Rock_Chalk"
    },
    {
      "x": -8,
      "y": 14,
      "z": -16,
      "name": "Rock_Chalk"
    },
    {
      "x": -8,
      "y": 12,
      "z": -15,
      "name": "Rock_Chalk"
    },
    {
      "x": -8,
      "y": 13,
      "z": -15,
      "name": "Rock_Chalk"
    },
    {
      "x": -8,
      "y": 14,
      "z": -15,
      "name": "Rock_Chalk"
    },
    {
      "x": -8,
      "y": 12,
      "z": -14,
      "name": "Rock_Chalk"
    },
    {
      "x": -8,
      "y": 13,
      "z": -14,
      "name": "Rock_Chalk"
    },
    {
      "x": -8,
      "y": 14,
      "z": -14,
      "name": "Rock_Chalk"
    },
    {
      "x": -8,
      "y": 15,
      "z": -14,
      "name": "Rock_Chalk"
    },
    {
      "x": -8,
      "y": 12,
      "z": -13,
      "name": "Rock_Chalk"
    },
    {
      "x": -8,
      "y": 13,
      "z": -13,
      "name": "Rock_Chalk"
    },
    {
      "x": -8,
      "y": 14,
      "z": -13,
      "name": "Rock_Chalk"
    },
    {
      "x": -8,
      "y": 15,
      "z": -13,
      "name": "Rock_Chalk"
    },
    {
      "x": -8,
      "y": 12,
      "z": -12,
      "name": "Rock_Chalk"
    },
    {
      "x": -8,
      "y": 13,
      "z": -12,
      "name": "Rock_Chalk"
    },
    {
      "x": -8,
      "y": 14,
      "z": -12,
      "name": "Rock_Chalk"
    },
    {
      "x": -8,
      "y": 15,
      "z": -12,
      "name": "Rock_Chalk"
    },
    {
      "x": -8,
      "y": 13,
      "z": -11,
      "name": "Rock_Chalk"
    },
    {
      "x": -8,
      "y": 14,
      "z": -11,
      "name": "Rock_Chalk"
    },
    {
      "x": -8,
      "y": 15,
      "z": -11,
      "name": "Rock_Chalk"
    },
    {
      "x": -8,
      "y": 13,
      "z": -10,
      "name": "Rock_Chalk"
    },
    {
      "x": -8,
      "y": 14,
      "z": -10,
      "name": "Rock_Chalk"
    },
    {
      "x": -8,
      "y": 15,
      "z": -10,
      "name": "Rock_Chalk"
    },
    {
      "x": -8,
      "y": 16,
      "z": -10,
      "name": "Rock_Chalk"
    },
    {
      "x": -8,
      "y": 14,
      "z": -9,
      "name": "Rock_Chalk"
    },
    {
      "x": -8,
      "y": 15,
      "z": -9,
      "name": "Rock_Chalk"
    },
    {
      "x": -8,
      "y": 16,
      "z": -9,
      "name": "Rock_Chalk"
    },
    {
      "x": -8,
      "y": 17,
      "z": -9,
      "name": "Rock_Calcite"
    },
    {
      "x": -8,
      "y": 20,
      "z": 6,
      "name": "Rock_Marble"
    },
    {
      "x": -8,
      "y": 21,
      "z": 6,
      "name": "Rock_Marble"
    },
    {
      "x": -8,
      "y": 22,
      "z": 6,
      "name": "Rock_Marble"
    },
    {
      "x": -8,
      "y": 23,
      "z": 6,
      "name": "Rock_Marble"
    },
    {
      "x": -8,
      "y": 19,
      "z": 7,
      "name": "Rock_Marble"
    },
    {
      "x": -8,
      "y": 20,
      "z": 7,
      "name": "Rock_Marble"
    },
    {
      "x": -8,
      "y": 21,
      "z": 7,
      "name": "Rock_Marble"
    },
    {
      "x": -8,
      "y": 22,
      "z": 7,
      "name": "Rock_Marble"
    },
    {
      "x": -8,
      "y": 23,
      "z": 7,
      "name": "Rock_Marble"
    },
    {
      "x": -8,
      "y": 19,
      "z": 8,
      "name": "Rock_Marble"
    },
    {
      "x": -8,
      "y": 20,
      "z": 8,
      "name": "Rock_Marble"
    },
    {
      "x": -8,
      "y": 21,
      "z": 8,
      "name": "Rock_Marble"
    },
    {
      "x": -8,
      "y": 22,
      "z": 8,
      "name": "Rock_Marble"
    },
    {
      "x": -8,
      "y": 18,
      "z": 9,
      "name": "Rock_Marble"
    },
    {
      "x": -8,
      "y": 19,
      "z": 9,
      "name": "Rock_Marble"
    },
    {
      "x": -8,
      "y": 20,
      "z": 9,
      "name": "Rock_Marble"
    },
    {
      "x": -8,
      "y": 21,
      "z": 9,
      "name": "Rock_Marble"
    },
    {
      "x": -8,
      "y": 17,
      "z": 10,
      "name": "Rock_Marble"
    },
    {
      "x": -8,
      "y": 18,
      "z": 10,
      "name": "Rock_Marble"
    },
    {
      "x": -8,
      "y": 19,
      "z": 10,
      "name": "Rock_Marble"
    },
    {
      "x": -8,
      "y": 20,
      "z": 10,
      "name": "Rock_Marble"
    },
    {
      "x": -8,
      "y": 16,
      "z": 11,
      "name": "Rock_Marble"
    },
    {
      "x": -8,
      "y": 17,
      "z": 11,
      "name": "Rock_Marble"
    },
    {
      "x": -8,
      "y": 18,
      "z": 11,
      "name": "Rock_Marble"
    },
    {
      "x": -8,
      "y": 19,
      "z": 11,
      "name": "Rock_Marble"
    },
    {
      "x": -8,
      "y": 20,
      "z": 11,
      "name": "Rock_Marble"
    },
    {
      "x": -8,
      "y": 16,
      "z": 12,
      "name": "Rock_Marble"
    },
    {
      "x": -8,
      "y": 17,
      "z": 12,
      "name": "Rock_Marble"
    },
    {
      "x": -8,
      "y": 18,
      "z": 12,
      "name": "Rock_Marble"
    },
    {
      "x": -8,
      "y": 19,
      "z": 12,
      "name": "Rock_Marble"
    },
    {
      "x": -8,
      "y": 15,
      "z": 13,
      "name": "Rock_Marble"
    },
    {
      "x": -8,
      "y": 16,
      "z": 13,
      "name": "Rock_Marble"
    },
    {
      "x": -8,
      "y": 17,
      "z": 13,
      "name": "Rock_Marble"
    },
    {
      "x": -8,
      "y": 18,
      "z": 13,
      "name": "Rock_Marble"
    },
    {
      "x": -8,
      "y": 13,
      "z": 14,
      "name": "Rock_Chalk"
    },
    {
      "x": -8,
      "y": 14,
      "z": 14,
      "name": "Rock_Marble"
    },
    {
      "x": -8,
      "y": 15,
      "z": 14,
      "name": "Rock_Marble"
    },
    {
      "x": -8,
      "y": 16,
      "z": 14,
      "name": "Rock_Marble"
    },
    {
      "x": -8,
      "y": 12,
      "z": 15,
      "name": "Rock_Chalk"
    },
    {
      "x": -8,
      "y": 13,
      "z": 15,
      "name": "Rock_Chalk"
    },
    {
      "x": -8,
      "y": 14,
      "z": 15,
      "name": "Rock_Marble"
    },
    {
      "x": -8,
      "y": 15,
      "z": 15,
      "name": "Rock_Marble"
    },
    {
      "x": -8,
      "y": 11,
      "z": 16,
      "name": "Rock_Chalk"
    },
    {
      "x": -8,
      "y": 12,
      "z": 16,
      "name": "Rock_Chalk"
    },
    {
      "x": -8,
      "y": 13,
      "z": 16,
      "name": "Rock_Chalk"
    },
    {
      "x": -7,
      "y": 9,
      "z": -18,
      "name": "Rock_Chalk"
    },
    {
      "x": -7,
      "y": 10,
      "z": -18,
      "name": "Rock_Chalk"
    },
    {
      "x": -7,
      "y": 11,
      "z": -18,
      "name": "Rock_Chalk"
    },
    {
      "x": -7,
      "y": 12,
      "z": -18,
      "name": "Rock_Chalk"
    },
    {
      "x": -7,
      "y": 10,
      "z": -17,
      "name": "Rock_Chalk"
    },
    {
      "x": -7,
      "y": 11,
      "z": -17,
      "name": "Rock_Chalk"
    },
    {
      "x": -7,
      "y": 12,
      "z": -17,
      "name": "Rock_Chalk"
    },
    {
      "x": -7,
      "y": 13,
      "z": -17,
      "name": "Rock_Chalk"
    },
    {
      "x": -7,
      "y": 11,
      "z": -16,
      "name": "Rock_Chalk"
    },
    {
      "x": -7,
      "y": 12,
      "z": -16,
      "name": "Rock_Chalk"
    },
    {
      "x": -7,
      "y": 13,
      "z": -16,
      "name": "Rock_Chalk"
    },
    {
      "x": -7,
      "y": 14,
      "z": -16,
      "name": "Rock_Chalk"
    },
    {
      "x": -7,
      "y": 11,
      "z": -15,
      "name": "Rock_Chalk"
    },
    {
      "x": -7,
      "y": 12,
      "z": -15,
      "name": "Rock_Chalk"
    },
    {
      "x": -7,
      "y": 13,
      "z": -15,
      "name": "Rock_Chalk"
    },
    {
      "x": -7,
      "y": 14,
      "z": -15,
      "name": "Rock_Chalk"
    },
    {
      "x": -7,
      "y": 12,
      "z": -14,
      "name": "Rock_Chalk"
    },
    {
      "x": -7,
      "y": 13,
      "z": -14,
      "name": "Rock_Chalk"
    },
    {
      "x": -7,
      "y": 14,
      "z": -14,
      "name": "Rock_Chalk"
    },
    {
      "x": -7,
      "y": 15,
      "z": -14,
      "name": "Rock_Chalk"
    },
    {
      "x": -7,
      "y": 12,
      "z": -13,
      "name": "Rock_Chalk"
    },
    {
      "x": -7,
      "y": 13,
      "z": -13,
      "name": "Rock_Chalk"
    },
    {
      "x": -7,
      "y": 14,
      "z": -13,
      "name": "Rock_Chalk"
    },
    {
      "x": -7,
      "y": 15,
      "z": -13,
      "name": "Rock_Chalk"
    },
    {
      "x": -7,
      "y": 12,
      "z": -12,
      "name": "Rock_Chalk"
    },
    {
      "x": -7,
      "y": 13,
      "z": -12,
      "name": "Rock_Chalk"
    },
    {
      "x": -7,
      "y": 14,
      "z": -12,
      "name": "Rock_Chalk"
    },
    {
      "x": -7,
      "y": 15,
      "z": -12,
      "name": "Rock_Chalk"
    },
    {
      "x": -7,
      "y": 13,
      "z": -11,
      "name": "Rock_Chalk"
    },
    {
      "x": -7,
      "y": 14,
      "z": -11,
      "name": "Rock_Chalk"
    },
    {
      "x": -7,
      "y": 15,
      "z": -11,
      "name": "Rock_Chalk"
    },
    {
      "x": -7,
      "y": 16,
      "z": -11,
      "name": "Rock_Chalk"
    },
    {
      "x": -7,
      "y": 13,
      "z": -10,
      "name": "Rock_Chalk"
    },
    {
      "x": -7,
      "y": 14,
      "z": -10,
      "name": "Rock_Chalk"
    },
    {
      "x": -7,
      "y": 15,
      "z": -10,
      "name": "Rock_Chalk"
    },
    {
      "x": -7,
      "y": 16,
      "z": -10,
      "name": "Rock_Chalk"
    },
    {
      "x": -7,
      "y": 14,
      "z": -9,
      "name": "Rock_Chalk"
    },
    {
      "x": -7,
      "y": 15,
      "z": -9,
      "name": "Rock_Chalk"
    },
    {
      "x": -7,
      "y": 16,
      "z": -9,
      "name": "Rock_Chalk"
    },
    {
      "x": -7,
      "y": 17,
      "z": -9,
      "name": "Rock_Calcite"
    },
    {
      "x": -7,
      "y": 22,
      "z": 5,
      "name": "Rock_Marble"
    },
    {
      "x": -7,
      "y": 23,
      "z": 5,
      "name": "Rock_Marble"
    },
    {
      "x": -7,
      "y": 24,
      "z": 5,
      "name": "Rock_Marble"
    },
    {
      "x": -7,
      "y": 20,
      "z": 6,
      "name": "Rock_Marble"
    },
    {
      "x": -7,
      "y": 21,
      "z": 6,
      "name": "Rock_Marble"
    },
    {
      "x": -7,
      "y": 22,
      "z": 6,
      "name": "Rock_Marble"
    },
    {
      "x": -7,
      "y": 23,
      "z": 6,
      "name": "Rock_Marble"
    },
    {
      "x": -7,
      "y": 24,
      "z": 6,
      "name": "Rock_Marble"
    },
    {
      "x": -7,
      "y": 20,
      "z": 7,
      "name": "Rock_Marble"
    },
    {
      "x": -7,
      "y": 21,
      "z": 7,
      "name": "Rock_Marble"
    },
    {
      "x": -7,
      "y": 22,
      "z": 7,
      "name": "Rock_Marble"
    },
    {
      "x": -7,
      "y": 23,
      "z": 7,
      "name": "Rock_Marble"
    },
    {
      "x": -7,
      "y": 19,
      "z": 8,
      "name": "Rock_Marble"
    },
    {
      "x": -7,
      "y": 20,
      "z": 8,
      "name": "Rock_Marble"
    },
    {
      "x": -7,
      "y": 21,
      "z": 8,
      "name": "Rock_Marble"
    },
    {
      "x": -7,
      "y": 22,
      "z": 8,
      "name": "Rock_Marble"
    },
    {
      "x": -7,
      "y": 18,
      "z": 9,
      "name": "Rock_Marble"
    },
    {
      "x": -7,
      "y": 19,
      "z": 9,
      "name": "Rock_Marble"
    },
    {
      "x": -7,
      "y": 20,
      "z": 9,
      "name": "Rock_Marble"
    },
    {
      "x": -7,
      "y": 21,
      "z": 9,
      "name": "Rock_Marble"
    },
    {
      "x": -7,
      "y": 22,
      "z": 9,
      "name": "Rock_Marble"
    },
    {
      "x": -7,
      "y": 18,
      "z": 10,
      "name": "Rock_Marble"
    },
    {
      "x": -7,
      "y": 19,
      "z": 10,
      "name": "Rock_Marble"
    },
    {
      "x": -7,
      "y": 20,
      "z": 10,
      "name": "Rock_Marble"
    },
    {
      "x": -7,
      "y": 21,
      "z": 10,
      "name": "Rock_Marble"
    },
    {
      "x": -7,
      "y": 17,
      "z": 11,
      "name": "Rock_Marble"
    },
    {
      "x": -7,
      "y": 18,
      "z": 11,
      "name": "Rock_Marble"
    },
    {
      "x": -7,
      "y": 19,
      "z": 11,
      "name": "Rock_Marble"
    },
    {
      "x": -7,
      "y": 20,
      "z": 11,
      "name": "Rock_Marble"
    },
    {
      "x": -7,
      "y": 16,
      "z": 12,
      "name": "Rock_Marble"
    },
    {
      "x": -7,
      "y": 17,
      "z": 12,
      "name": "Rock_Marble"
    },
    {
      "x": -7,
      "y": 18,
      "z": 12,
      "name": "Rock_Marble"
    },
    {
      "x": -7,
      "y": 19,
      "z": 12,
      "name": "Rock_Marble"
    },
    {
      "x": -7,
      "y": 15,
      "z": 13,
      "name": "Rock_Marble"
    },
    {
      "x": -7,
      "y": 16,
      "z": 13,
      "name": "Rock_Marble"
    },
    {
      "x": -7,
      "y": 17,
      "z": 13,
      "name": "Rock_Marble"
    },
    {
      "x": -7,
      "y": 18,
      "z": 13,
      "name": "Rock_Marble"
    },
    {
      "x": -7,
      "y": 14,
      "z": 14,
      "name": "Rock_Marble"
    },
    {
      "x": -7,
      "y": 15,
      "z": 14,
      "name": "Rock_Marble"
    },
    {
      "x": -7,
      "y": 16,
      "z": 14,
      "name": "Rock_Marble"
    },
    {
      "x": -7,
      "y": 17,
      "z": 14,
      "name": "Rock_Marble"
    },
    {
      "x": -7,
      "y": 12,
      "z": 15,
      "name": "Rock_Chalk"
    },
    {
      "x": -7,
      "y": 13,
      "z": 15,
      "name": "Rock_Chalk"
    },
    {
      "x": -7,
      "y": 14,
      "z": 15,
      "name": "Rock_Marble"
    },
    {
      "x": -7,
      "y": 15,
      "z": 15,
      "name": "Rock_Marble"
    },
    {
      "x": -7,
      "y": 11,
      "z": 16,
      "name": "Rock_Chalk"
    },
    {
      "x": -7,
      "y": 12,
      "z": 16,
      "name": "Rock_Chalk"
    },
    {
      "x": -7,
      "y": 13,
      "z": 16,
      "name": "Rock_Chalk"
    },
    {
      "x": -7,
      "y": 14,
      "z": 16,
      "name": "Rock_Marble"
    },
    {
      "x": -7,
      "y": 9,
      "z": 17,
      "name": "Rock_Chalk"
    },
    {
      "x": -7,
      "y": 10,
      "z": 17,
      "name": "Rock_Chalk"
    },
    {
      "x": -7,
      "y": 11,
      "z": 17,
      "name": "Rock_Chalk"
    },
    {
      "x": -7,
      "y": 12,
      "z": 17,
      "name": "Rock_Chalk"
    },
    {
      "x": -6,
      "y": 9,
      "z": -18,
      "name": "Rock_Chalk"
    },
    {
      "x": -6,
      "y": 10,
      "z": -18,
      "name": "Rock_Chalk"
    },
    {
      "x": -6,
      "y": 11,
      "z": -18,
      "name": "Rock_Chalk"
    },
    {
      "x": -6,
      "y": 12,
      "z": -18,
      "name": "Rock_Chalk"
    },
    {
      "x": -6,
      "y": 10,
      "z": -17,
      "name": "Rock_Chalk"
    },
    {
      "x": -6,
      "y": 11,
      "z": -17,
      "name": "Rock_Chalk"
    },
    {
      "x": -6,
      "y": 12,
      "z": -17,
      "name": "Rock_Chalk"
    },
    {
      "x": -6,
      "y": 13,
      "z": -17,
      "name": "Rock_Chalk"
    },
    {
      "x": -6,
      "y": 11,
      "z": -16,
      "name": "Rock_Chalk"
    },
    {
      "x": -6,
      "y": 12,
      "z": -16,
      "name": "Rock_Chalk"
    },
    {
      "x": -6,
      "y": 13,
      "z": -16,
      "name": "Rock_Chalk"
    },
    {
      "x": -6,
      "y": 14,
      "z": -16,
      "name": "Rock_Chalk"
    },
    {
      "x": -6,
      "y": 11,
      "z": -15,
      "name": "Rock_Chalk"
    },
    {
      "x": -6,
      "y": 12,
      "z": -15,
      "name": "Rock_Chalk"
    },
    {
      "x": -6,
      "y": 13,
      "z": -15,
      "name": "Rock_Chalk"
    },
    {
      "x": -6,
      "y": 14,
      "z": -15,
      "name": "Rock_Chalk"
    },
    {
      "x": -6,
      "y": 12,
      "z": -14,
      "name": "Rock_Chalk"
    },
    {
      "x": -6,
      "y": 13,
      "z": -14,
      "name": "Rock_Chalk"
    },
    {
      "x": -6,
      "y": 14,
      "z": -14,
      "name": "Rock_Chalk"
    },
    {
      "x": -6,
      "y": 12,
      "z": -13,
      "name": "Rock_Chalk"
    },
    {
      "x": -6,
      "y": 13,
      "z": -13,
      "name": "Rock_Chalk"
    },
    {
      "x": -6,
      "y": 14,
      "z": -13,
      "name": "Rock_Chalk"
    },
    {
      "x": -6,
      "y": 15,
      "z": -13,
      "name": "Rock_Chalk"
    },
    {
      "x": -6,
      "y": 12,
      "z": -12,
      "name": "Rock_Chalk"
    },
    {
      "x": -6,
      "y": 13,
      "z": -12,
      "name": "Rock_Chalk"
    },
    {
      "x": -6,
      "y": 14,
      "z": -12,
      "name": "Rock_Chalk"
    },
    {
      "x": -6,
      "y": 15,
      "z": -12,
      "name": "Rock_Chalk"
    },
    {
      "x": -6,
      "y": 13,
      "z": -11,
      "name": "Rock_Chalk"
    },
    {
      "x": -6,
      "y": 14,
      "z": -11,
      "name": "Rock_Chalk"
    },
    {
      "x": -6,
      "y": 15,
      "z": -11,
      "name": "Rock_Chalk"
    },
    {
      "x": -6,
      "y": 16,
      "z": -11,
      "name": "Rock_Chalk"
    },
    {
      "x": -6,
      "y": 14,
      "z": -10,
      "name": "Rock_Chalk"
    },
    {
      "x": -6,
      "y": 15,
      "z": -10,
      "name": "Rock_Chalk"
    },
    {
      "x": -6,
      "y": 16,
      "z": -10,
      "name": "Rock_Chalk"
    },
    {
      "x": -6,
      "y": 17,
      "z": -10,
      "name": "Rock_Calcite"
    },
    {
      "x": -6,
      "y": 14,
      "z": -9,
      "name": "Rock_Chalk"
    },
    {
      "x": -6,
      "y": 15,
      "z": -9,
      "name": "Rock_Chalk"
    },
    {
      "x": -6,
      "y": 16,
      "z": -9,
      "name": "Rock_Chalk"
    },
    {
      "x": -6,
      "y": 17,
      "z": -9,
      "name": "Rock_Calcite"
    },
    {
      "x": -6,
      "y": 22,
      "z": -4,
      "name": "Rock_Marble"
    },
    {
      "x": -6,
      "y": 23,
      "z": 5,
      "name": "Rock_Marble"
    },
    {
      "x": -6,
      "y": 24,
      "z": 5,
      "name": "Rock_Marble"
    },
    {
      "x": -6,
      "y": 21,
      "z": 6,
      "name": "Rock_Marble"
    },
    {
      "x": -6,
      "y": 22,
      "z": 6,
      "name": "Rock_Marble"
    },
    {
      "x": -6,
      "y": 23,
      "z": 6,
      "name": "Rock_Marble"
    },
    {
      "x": -6,
      "y": 24,
      "z": 6,
      "name": "Rock_Marble"
    },
    {
      "x": -6,
      "y": 20,
      "z": 7,
      "name": "Rock_Marble"
    },
    {
      "x": -6,
      "y": 21,
      "z": 7,
      "name": "Rock_Marble"
    },
    {
      "x": -6,
      "y": 22,
      "z": 7,
      "name": "Rock_Marble"
    },
    {
      "x": -6,
      "y": 23,
      "z": 7,
      "name": "Rock_Marble"
    },
    {
      "x": -6,
      "y": 19,
      "z": 8,
      "name": "Rock_Marble"
    },
    {
      "x": -6,
      "y": 20,
      "z": 8,
      "name": "Rock_Marble"
    },
    {
      "x": -6,
      "y": 21,
      "z": 8,
      "name": "Rock_Marble"
    },
    {
      "x": -6,
      "y": 22,
      "z": 8,
      "name": "Rock_Marble"
    },
    {
      "x": -6,
      "y": 23,
      "z": 8,
      "name": "Rock_Marble"
    },
    {
      "x": -6,
      "y": 19,
      "z": 9,
      "name": "Rock_Marble"
    },
    {
      "x": -6,
      "y": 20,
      "z": 9,
      "name": "Rock_Marble"
    },
    {
      "x": -6,
      "y": 21,
      "z": 9,
      "name": "Rock_Marble"
    },
    {
      "x": -6,
      "y": 22,
      "z": 9,
      "name": "Rock_Marble"
    },
    {
      "x": -6,
      "y": 18,
      "z": 10,
      "name": "Rock_Marble"
    },
    {
      "x": -6,
      "y": 19,
      "z": 10,
      "name": "Rock_Marble"
    },
    {
      "x": -6,
      "y": 20,
      "z": 10,
      "name": "Rock_Marble"
    },
    {
      "x": -6,
      "y": 21,
      "z": 10,
      "name": "Rock_Marble"
    },
    {
      "x": -6,
      "y": 17,
      "z": 11,
      "name": "Rock_Marble"
    },
    {
      "x": -6,
      "y": 18,
      "z": 11,
      "name": "Rock_Marble"
    },
    {
      "x": -6,
      "y": 19,
      "z": 11,
      "name": "Rock_Marble"
    },
    {
      "x": -6,
      "y": 20,
      "z": 11,
      "name": "Rock_Marble"
    },
    {
      "x": -6,
      "y": 16,
      "z": 12,
      "name": "Rock_Marble"
    },
    {
      "x": -6,
      "y": 17,
      "z": 12,
      "name": "Rock_Marble"
    },
    {
      "x": -6,
      "y": 18,
      "z": 12,
      "name": "Rock_Marble"
    },
    {
      "x": -6,
      "y": 19,
      "z": 12,
      "name": "Rock_Marble"
    },
    {
      "x": -6,
      "y": 15,
      "z": 13,
      "name": "Rock_Marble"
    },
    {
      "x": -6,
      "y": 16,
      "z": 13,
      "name": "Rock_Marble"
    },
    {
      "x": -6,
      "y": 17,
      "z": 13,
      "name": "Rock_Marble"
    },
    {
      "x": -6,
      "y": 18,
      "z": 13,
      "name": "Rock_Marble"
    },
    {
      "x": -6,
      "y": 14,
      "z": 14,
      "name": "Rock_Marble"
    },
    {
      "x": -6,
      "y": 15,
      "z": 14,
      "name": "Rock_Marble"
    },
    {
      "x": -6,
      "y": 16,
      "z": 14,
      "name": "Rock_Marble"
    },
    {
      "x": -6,
      "y": 17,
      "z": 14,
      "name": "Rock_Marble"
    },
    {
      "x": -6,
      "y": 13,
      "z": 15,
      "name": "Rock_Chalk"
    },
    {
      "x": -6,
      "y": 14,
      "z": 15,
      "name": "Rock_Marble"
    },
    {
      "x": -6,
      "y": 15,
      "z": 15,
      "name": "Rock_Marble"
    },
    {
      "x": -6,
      "y": 11,
      "z": 16,
      "name": "Rock_Chalk"
    },
    {
      "x": -6,
      "y": 12,
      "z": 16,
      "name": "Rock_Chalk"
    },
    {
      "x": -6,
      "y": 13,
      "z": 16,
      "name": "Rock_Chalk"
    },
    {
      "x": -6,
      "y": 14,
      "z": 16,
      "name": "Rock_Marble"
    },
    {
      "x": -6,
      "y": 9,
      "z": 17,
      "name": "Rock_Chalk"
    },
    {
      "x": -6,
      "y": 10,
      "z": 17,
      "name": "Rock_Chalk"
    },
    {
      "x": -6,
      "y": 11,
      "z": 17,
      "name": "Rock_Chalk"
    },
    {
      "x": -6,
      "y": 12,
      "z": 17,
      "name": "Rock_Chalk"
    },
    {
      "x": -5,
      "y": 10,
      "z": -17,
      "name": "Rock_Chalk"
    },
    {
      "x": -5,
      "y": 11,
      "z": -17,
      "name": "Rock_Chalk"
    },
    {
      "x": -5,
      "y": 12,
      "z": -17,
      "name": "Rock_Chalk"
    },
    {
      "x": -5,
      "y": 13,
      "z": -17,
      "name": "Rock_Chalk"
    },
    {
      "x": -5,
      "y": 11,
      "z": -16,
      "name": "Rock_Chalk"
    },
    {
      "x": -5,
      "y": 12,
      "z": -16,
      "name": "Rock_Chalk"
    },
    {
      "x": -5,
      "y": 13,
      "z": -16,
      "name": "Rock_Chalk"
    },
    {
      "x": -5,
      "y": 11,
      "z": -15,
      "name": "Rock_Chalk"
    },
    {
      "x": -5,
      "y": 12,
      "z": -15,
      "name": "Rock_Chalk"
    },
    {
      "x": -5,
      "y": 13,
      "z": -15,
      "name": "Rock_Chalk"
    },
    {
      "x": -5,
      "y": 14,
      "z": -15,
      "name": "Rock_Chalk"
    },
    {
      "x": -5,
      "y": 11,
      "z": -14,
      "name": "Rock_Chalk"
    },
    {
      "x": -5,
      "y": 12,
      "z": -14,
      "name": "Rock_Chalk"
    },
    {
      "x": -5,
      "y": 13,
      "z": -14,
      "name": "Rock_Chalk"
    },
    {
      "x": -5,
      "y": 14,
      "z": -14,
      "name": "Rock_Chalk"
    },
    {
      "x": -5,
      "y": 12,
      "z": -13,
      "name": "Rock_Chalk"
    },
    {
      "x": -5,
      "y": 13,
      "z": -13,
      "name": "Rock_Chalk"
    },
    {
      "x": -5,
      "y": 14,
      "z": -13,
      "name": "Rock_Chalk"
    },
    {
      "x": -5,
      "y": 15,
      "z": -13,
      "name": "Rock_Chalk"
    },
    {
      "x": -5,
      "y": 12,
      "z": -12,
      "name": "Rock_Chalk"
    },
    {
      "x": -5,
      "y": 13,
      "z": -12,
      "name": "Rock_Chalk"
    },
    {
      "x": -5,
      "y": 14,
      "z": -12,
      "name": "Rock_Chalk"
    },
    {
      "x": -5,
      "y": 15,
      "z": -12,
      "name": "Rock_Chalk"
    },
    {
      "x": -5,
      "y": 13,
      "z": -11,
      "name": "Rock_Chalk"
    },
    {
      "x": -5,
      "y": 14,
      "z": -11,
      "name": "Rock_Chalk"
    },
    {
      "x": -5,
      "y": 15,
      "z": -11,
      "name": "Rock_Chalk"
    },
    {
      "x": -5,
      "y": 16,
      "z": -11,
      "name": "Rock_Chalk"
    },
    {
      "x": -5,
      "y": 14,
      "z": -10,
      "name": "Rock_Chalk"
    },
    {
      "x": -5,
      "y": 15,
      "z": -10,
      "name": "Rock_Chalk"
    },
    {
      "x": -5,
      "y": 16,
      "z": -10,
      "name": "Rock_Chalk"
    },
    {
      "x": -5,
      "y": 17,
      "z": -10,
      "name": "Rock_Calcite"
    },
    {
      "x": -5,
      "y": 20,
      "z": -7,
      "name": "Rock_Marble"
    },
    {
      "x": -5,
      "y": 17,
      "z": -6,
      "name": "Rock_Calcite"
    },
    {
      "x": -5,
      "y": 18,
      "z": -6,
      "name": "Rock_Calcite"
    },
    {
      "x": -5,
      "y": 19,
      "z": -6,
      "name": "Rock_Marble"
    },
    {
      "x": -5,
      "y": 20,
      "z": -6,
      "name": "Rock_Marble"
    },
    {
      "x": -5,
      "y": 18,
      "z": -5,
      "name": "Rock_Calcite"
    },
    {
      "x": -5,
      "y": 19,
      "z": -5,
      "name": "Rock_Marble"
    },
    {
      "x": -5,
      "y": 20,
      "z": -5,
      "name": "Rock_Marble"
    },
    {
      "x": -5,
      "y": 21,
      "z": -5,
      "name": "Rock_Marble"
    },
    {
      "x": -5,
      "y": 19,
      "z": -4,
      "name": "Rock_Marble"
    },
    {
      "x": -5,
      "y": 20,
      "z": -4,
      "name": "Rock_Marble"
    },
    {
      "x": -5,
      "y": 21,
      "z": -4,
      "name": "Rock_Marble"
    },
    {
      "x": -5,
      "y": 22,
      "z": -4,
      "name": "Rock_Marble"
    },
    {
      "x": -5,
      "y": 22,
      "z": -3,
      "name": "Rock_Marble"
    },
    {
      "x": -5,
      "y": 23,
      "z": -3,
      "name": "Rock_Marble"
    },
    {
      "x": -5,
      "y": 22,
      "z": -2,
      "name": "Rock_Marble"
    },
    {
      "x": -5,
      "y": 23,
      "z": -2,
      "name": "Rock_Marble"
    },
    {
      "x": -5,
      "y": 23,
      "z": -1,
      "name": "Rock_Marble"
    },
    {
      "x": -5,
      "y": 24,
      "z": -1,
      "name": "Rock_Marble"
    },
    {
      "x": -5,
      "y": 25,
      "z": 4,
      "name": "Rock_Marble"
    },
    {
      "x": -5,
      "y": 23,
      "z": 5,
      "name": "Rock_Marble"
    },
    {
      "x": -5,
      "y": 24,
      "z": 5,
      "name": "Rock_Marble"
    },
    {
      "x": -5,
      "y": 25,
      "z": 5,
      "name": "Rock_Calcite"
    },
    {
      "x": -5,
      "y": 21,
      "z": 6,
      "name": "Rock_Marble"
    },
    {
      "x": -5,
      "y": 22,
      "z": 6,
      "name": "Rock_Marble"
    },
    {
      "x": -5,
      "y": 23,
      "z": 6,
      "name": "Rock_Marble"
    },
    {
      "x": -5,
      "y": 24,
      "z": 6,
      "name": "Rock_Marble"
    },
    {
      "x": -5,
      "y": 20,
      "z": 7,
      "name": "Rock_Marble"
    },
    {
      "x": -5,
      "y": 21,
      "z": 7,
      "name": "Rock_Marble"
    },
    {
      "x": -5,
      "y": 22,
      "z": 7,
      "name": "Rock_Marble"
    },
    {
      "x": -5,
      "y": 23,
      "z": 7,
      "name": "Rock_Marble"
    },
    {
      "x": -5,
      "y": 24,
      "z": 7,
      "name": "Rock_Calcite"
    },
    {
      "x": -5,
      "y": 20,
      "z": 8,
      "name": "Rock_Marble"
    },
    {
      "x": -5,
      "y": 21,
      "z": 8,
      "name": "Rock_Marble"
    },
    {
      "x": -5,
      "y": 22,
      "z": 8,
      "name": "Rock_Marble"
    },
    {
      "x": -5,
      "y": 23,
      "z": 8,
      "name": "Rock_Marble"
    },
    {
      "x": -5,
      "y": 19,
      "z": 9,
      "name": "Rock_Marble"
    },
    {
      "x": -5,
      "y": 20,
      "z": 9,
      "name": "Rock_Marble"
    },
    {
      "x": -5,
      "y": 21,
      "z": 9,
      "name": "Rock_Marble"
    },
    {
      "x": -5,
      "y": 22,
      "z": 9,
      "name": "Rock_Marble"
    },
    {
      "x": -5,
      "y": 18,
      "z": 10,
      "name": "Rock_Marble"
    },
    {
      "x": -5,
      "y": 19,
      "z": 10,
      "name": "Rock_Marble"
    },
    {
      "x": -5,
      "y": 20,
      "z": 10,
      "name": "Rock_Marble"
    },
    {
      "x": -5,
      "y": 21,
      "z": 10,
      "name": "Rock_Marble"
    },
    {
      "x": -5,
      "y": 17,
      "z": 11,
      "name": "Rock_Marble"
    },
    {
      "x": -5,
      "y": 18,
      "z": 11,
      "name": "Rock_Marble"
    },
    {
      "x": -5,
      "y": 19,
      "z": 11,
      "name": "Rock_Marble"
    },
    {
      "x": -5,
      "y": 20,
      "z": 11,
      "name": "Rock_Marble"
    },
    {
      "x": -5,
      "y": 16,
      "z": 12,
      "name": "Rock_Marble"
    },
    {
      "x": -5,
      "y": 17,
      "z": 12,
      "name": "Rock_Marble"
    },
    {
      "x": -5,
      "y": 18,
      "z": 12,
      "name": "Rock_Marble"
    },
    {
      "x": -5,
      "y": 19,
      "z": 12,
      "name": "Rock_Marble"
    },
    {
      "x": -5,
      "y": 15,
      "z": 13,
      "name": "Rock_Marble"
    },
    {
      "x": -5,
      "y": 16,
      "z": 13,
      "name": "Rock_Marble"
    },
    {
      "x": -5,
      "y": 17,
      "z": 13,
      "name": "Rock_Marble"
    },
    {
      "x": -5,
      "y": 18,
      "z": 13,
      "name": "Rock_Marble"
    },
    {
      "x": -5,
      "y": 14,
      "z": 14,
      "name": "Rock_Marble"
    },
    {
      "x": -5,
      "y": 15,
      "z": 14,
      "name": "Rock_Marble"
    },
    {
      "x": -5,
      "y": 16,
      "z": 14,
      "name": "Rock_Marble"
    },
    {
      "x": -5,
      "y": 17,
      "z": 14,
      "name": "Rock_Marble"
    },
    {
      "x": -5,
      "y": 13,
      "z": 15,
      "name": "Rock_Chalk"
    },
    {
      "x": -5,
      "y": 14,
      "z": 15,
      "name": "Rock_Marble"
    },
    {
      "x": -5,
      "y": 15,
      "z": 15,
      "name": "Rock_Marble"
    },
    {
      "x": -5,
      "y": 16,
      "z": 15,
      "name": "Rock_Marble"
    },
    {
      "x": -5,
      "y": 11,
      "z": 16,
      "name": "Rock_Chalk"
    },
    {
      "x": -5,
      "y": 12,
      "z": 16,
      "name": "Rock_Chalk"
    },
    {
      "x": -5,
      "y": 13,
      "z": 16,
      "name": "Rock_Chalk"
    },
    {
      "x": -5,
      "y": 14,
      "z": 16,
      "name": "Rock_Marble"
    },
    {
      "x": -5,
      "y": 10,
      "z": 17,
      "name": "Rock_Chalk"
    },
    {
      "x": -5,
      "y": 11,
      "z": 17,
      "name": "Rock_Chalk"
    },
    {
      "x": -5,
      "y": 12,
      "z": 17,
      "name": "Rock_Chalk"
    },
    {
      "x": -4,
      "y": 9,
      "z": -17,
      "name": "Rock_Chalk"
    },
    {
      "x": -4,
      "y": 10,
      "z": -17,
      "name": "Rock_Chalk"
    },
    {
      "x": -4,
      "y": 11,
      "z": -17,
      "name": "Rock_Chalk"
    },
    {
      "x": -4,
      "y": 12,
      "z": -17,
      "name": "Rock_Chalk"
    },
    {
      "x": -4,
      "y": 10,
      "z": -16,
      "name": "Rock_Chalk"
    },
    {
      "x": -4,
      "y": 11,
      "z": -16,
      "name": "Rock_Chalk"
    },
    {
      "x": -4,
      "y": 12,
      "z": -16,
      "name": "Rock_Chalk"
    },
    {
      "x": -4,
      "y": 13,
      "z": -16,
      "name": "Rock_Chalk"
    },
    {
      "x": -4,
      "y": 11,
      "z": -15,
      "name": "Rock_Chalk"
    },
    {
      "x": -4,
      "y": 12,
      "z": -15,
      "name": "Rock_Chalk"
    },
    {
      "x": -4,
      "y": 13,
      "z": -15,
      "name": "Rock_Chalk"
    },
    {
      "x": -4,
      "y": 11,
      "z": -14,
      "name": "Rock_Chalk"
    },
    {
      "x": -4,
      "y": 12,
      "z": -14,
      "name": "Rock_Chalk"
    },
    {
      "x": -4,
      "y": 13,
      "z": -14,
      "name": "Rock_Chalk"
    },
    {
      "x": -4,
      "y": 14,
      "z": -14,
      "name": "Rock_Chalk"
    },
    {
      "x": -4,
      "y": 12,
      "z": -13,
      "name": "Rock_Chalk"
    },
    {
      "x": -4,
      "y": 13,
      "z": -13,
      "name": "Rock_Chalk"
    },
    {
      "x": -4,
      "y": 14,
      "z": -13,
      "name": "Rock_Chalk"
    },
    {
      "x": -4,
      "y": 12,
      "z": -12,
      "name": "Rock_Chalk"
    },
    {
      "x": -4,
      "y": 13,
      "z": -12,
      "name": "Rock_Chalk"
    },
    {
      "x": -4,
      "y": 14,
      "z": -12,
      "name": "Rock_Chalk"
    },
    {
      "x": -4,
      "y": 15,
      "z": -12,
      "name": "Rock_Chalk"
    },
    {
      "x": -4,
      "y": 13,
      "z": -11,
      "name": "Rock_Chalk"
    },
    {
      "x": -4,
      "y": 14,
      "z": -11,
      "name": "Rock_Chalk"
    },
    {
      "x": -4,
      "y": 15,
      "z": -11,
      "name": "Rock_Chalk"
    },
    {
      "x": -4,
      "y": 16,
      "z": -11,
      "name": "Rock_Chalk"
    },
    {
      "x": -4,
      "y": 17,
      "z": -7,
      "name": "Rock_Calcite"
    },
    {
      "x": -4,
      "y": 18,
      "z": -7,
      "name": "Rock_Calcite"
    },
    {
      "x": -4,
      "y": 19,
      "z": -7,
      "name": "Rock_Marble"
    },
    {
      "x": -4,
      "y": 20,
      "z": -7,
      "name": "Rock_Marble"
    },
    {
      "x": -4,
      "y": 18,
      "z": -6,
      "name": "Rock_Calcite"
    },
    {
      "x": -4,
      "y": 19,
      "z": -6,
      "name": "Rock_Marble"
    },
    {
      "x": -4,
      "y": 20,
      "z": -6,
      "name": "Rock_Marble"
    },
    {
      "x": -4,
      "y": 21,
      "z": -6,
      "name": "Rock_Marble"
    },
    {
      "x": -4,
      "y": 18,
      "z": -5,
      "name": "Rock_Calcite"
    },
    {
      "x": -4,
      "y": 19,
      "z": -5,
      "name": "Rock_Marble"
    },
    {
      "x": -4,
      "y": 20,
      "z": -5,
      "name": "Rock_Marble"
    },
    {
      "x": -4,
      "y": 21,
      "z": -5,
      "name": "Rock_Marble"
    },
    {
      "x": -4,
      "y": 22,
      "z": -5,
      "name": "Rock_Marble"
    },
    {
      "x": -4,
      "y": 19,
      "z": -4,
      "name": "Rock_Marble"
    },
    {
      "x": -4,
      "y": 20,
      "z": -4,
      "name": "Rock_Marble"
    },
    {
      "x": -4,
      "y": 21,
      "z": -4,
      "name": "Rock_Marble"
    },
    {
      "x": -4,
      "y": 22,
      "z": -4,
      "name": "Rock_Marble"
    },
    {
      "x": -4,
      "y": 20,
      "z": -3,
      "name": "Rock_Marble"
    },
    {
      "x": -4,
      "y": 21,
      "z": -3,
      "name": "Rock_Marble"
    },
    {
      "x": -4,
      "y": 22,
      "z": -3,
      "name": "Rock_Marble"
    },
    {
      "x": -4,
      "y": 23,
      "z": -3,
      "name": "Rock_Marble"
    },
    {
      "x": -4,
      "y": 20,
      "z": -2,
      "name": "Rock_Marble"
    },
    {
      "x": -4,
      "y": 21,
      "z": -2,
      "name": "Rock_Marble"
    },
    {
      "x": -4,
      "y": 22,
      "z": -2,
      "name": "Rock_Marble"
    },
    {
      "x": -4,
      "y": 23,
      "z": -2,
      "name": "Rock_Marble"
    },
    {
      "x": -4,
      "y": 24,
      "z": -2,
      "name": "Rock_Marble"
    },
    {
      "x": -4,
      "y": 21,
      "z": -1,
      "name": "Rock_Marble"
    },
    {
      "x": -4,
      "y": 22,
      "z": -1,
      "name": "Rock_Marble"
    },
    {
      "x": -4,
      "y": 23,
      "z": -1,
      "name": "Rock_Marble"
    },
    {
      "x": -4,
      "y": 24,
      "z": -1,
      "name": "Rock_Marble"
    },
    {
      "x": -4,
      "y": 23,
      "z": 0,
      "name": "Rock_Marble"
    },
    {
      "x": -4,
      "y": 24,
      "z": 0,
      "name": "Rock_Marble"
    },
    {
      "x": -4,
      "y": 25,
      "z": 0,
      "name": "Rock_Marble"
    },
    {
      "x": -4,
      "y": 23,
      "z": 5,
      "name": "Rock_Marble"
    },
    {
      "x": -4,
      "y": 24,
      "z": 5,
      "name": "Rock_Marble"
    },
    {
      "x": -4,
      "y": 25,
      "z": 5,
      "name": "Rock_Calcite"
    },
    {
      "x": -4,
      "y": 21,
      "z": 6,
      "name": "Rock_Marble"
    },
    {
      "x": -4,
      "y": 22,
      "z": 6,
      "name": "Rock_Marble"
    },
    {
      "x": -4,
      "y": 23,
      "z": 6,
      "name": "Rock_Marble"
    },
    {
      "x": -4,
      "y": 24,
      "z": 6,
      "name": "Rock_Marble"
    },
    {
      "x": -4,
      "y": 21,
      "z": 7,
      "name": "Rock_Marble"
    },
    {
      "x": -4,
      "y": 22,
      "z": 7,
      "name": "Rock_Marble"
    },
    {
