{
  "version": 8,
  "blockIdVersion": 8,
  "anchorX": 14,
  "anchorY": 16,
  "anchorZ": -2,
  "blocks": [
    {
      "x": 5,
      "y": 20,
      "z": -1,
      "name": "Rock_Shale"
    },
    {
      "x": 5,
      "y": 21,
      "z": -1,
      "name": "Rock_Shale"
    },
    {
      "x": 5,
      "y": 22,
      "z": -1,
      "name": "Rock_Shale"
    },
    {
      "x": 5,
      "y": 18,
      "z": 0,
      "name": "Rock_Shale"
    },
    {
      "x": 5,
      "y": 19,
      "z": 0,
      "name": "Rock_Shale"
    },
    {
      "x": 5,
      "y": 20,
      "z": 0,
      "name": "Rock_Shale"
    },
    {
      "x": 5,
      "y": 21,
      "z": 0,
      "name": "Rock_Shale"
    },
    {
      "x": 5,
      "y": 22,
      "z": 0,
      "name": "Rock_Shale"
    },
    {
      "x": 5,
      "y": 23,
      "z": 0,
      "name": "Rock_Shale"
    },
    {
      "x": 5,
      "y": 24,
      "z": 0,
      "name": "Rock_Shale"
    },
    {
      "x": 5,
      "y": 25,
      "z": 0,
      "name": "Soil_Dirt_Cold"
    },
    {
      "x": 5,
      "y": 20,
      "z": 1,
      "name": "Rock_Shale"
    },
    {
      "x": 5,
      "y": 21,
      "z": 1,
      "name": "Rock_Shale"
    },
    {
      "x": 5,
      "y": 22,
      "z": 1,
      "name": "Rock_Shale"
    },
    {
      "x": 5,
      "y": 23,
      "z": 1,
      "name": "Rock_Shale"
    },
    {
      "x": 5,
      "y": 24,
      "z": 1,
      "name": "Rock_Shale"
    },
    {
      "x": 6,
      "y": 20,
      "z": -2,
      "name": "Rock_Shale"
    },
    {
      "x": 6,
      "y": 21,
      "z": -2,
      "name": "Rock_Shale"
    },
    {
      "x": 6,
      "y": 22,
      "z": -2,
      "name": "Rock_Shale"
    },
    {
      "x": 6,
      "y": 23,
      "z": -2,
      "name": "Rock_Shale"
    },
    {
      "x": 6,
      "y": 24,
      "z": -2,
      "name": "Rock_Shale"
    },
    {
      "x": 6,
      "y": 25,
      "z": -2,
      "name": "Rock_Shale"
    },
    {
      "x": 6,
      "y": 17,
      "z": -1,
      "name": "Rock_Shale"
    },
    {
      "x": 6,
      "y": 18,
      "z": -1,
      "name": "Rock_Shale"
    },
    {
      "x": 6,
      "y": 19,
      "z": -1,
      "name": "Rock_Shale"
    },
    {
      "x": 6,
      "y": 20,
      "z": -1,
      "name": "Rock_Shale"
    },
    {
      "x": 6,
      "y": 21,
      "z": -1,
      "name": "Rock_Shale"
    },
    {
      "x": 6,
      "y": 22,
      "z": -1,
      "name": "Rock_Shale"
    },
    {
      "x": 6,
      "y": 23,
      "z": -1,
      "name": "Rock_Shale"
    },
    {
      "x": 6,
      "y": 24,
      "z": -1,
      "name": "Rock_Shale"
    },
    {
      "x": 6,
      "y": 25,
      "z": -1,
      "name": "Soil_Dirt_Cold"
    },
    {
      "x": 6,
      "y": 26,
      "z": -1,
      "name": "Soil_Grass_Cold"
    },
    {
      "x": 6,
      "y": 17,
      "z": 0,
      "name": "Rock_Shale"
    },
    {
      "x": 6,
      "y": 18,
      "z": 0,
      "name": "Rock_Shale"
    },
    {
      "x": 6,
      "y": 19,
      "z": 0,
      "name": "Rock_Shale"
    },
    {
      "x": 6,
      "y": 20,
      "z": 0,
      "name": "Rock_Shale"
    },
    {
      "x": 6,
      "y": 21,
      "z": 0,
      "name": "Rock_Shale"
    },
    {
      "x": 6,
      "y": 22,
      "z": 0,
      "name": "Rock_Shale"
    },
    {
      "x": 6,
      "y": 23,
      "z": 0,
      "name": "Rock_Shale"
    },
    {
      "x": 6,
      "y": 24,
      "z": 0,
      "name": "Rock_Shale"
    },
    {
      "x": 6,
      "y": 25,
      "z": 0,
      "name": "Soil_Dirt_Cold"
    },
    {
      "x": 6,
      "y": 26,
      "z": 0,
      "name": "Soil_Dirt_Cold"
    },
    {
      "x": 6,
      "y": 27,
      "z": 0,
      "name": "Soil_Dirt_Cold"
    },
    {
      "x": 6,
      "y": 28,
      "z": 0,
      "name": "Soil_Grass_Cold"
    },
    {
      "x": 6,
      "y": 18,
      "z": 1,
      "name": "Rock_Shale"
    },
    {
      "x": 6,
      "y": 19,
      "z": 1,
      "name": "Rock_Shale"
    },
    {
      "x": 6,
      "y": 20,
      "z": 1,
      "name": "Rock_Shale"
    },
    {
      "x": 6,
      "y": 21,
      "z": 1,
      "name": "Rock_Shale"
    },
    {
      "x": 6,
      "y": 22,
      "z": 1,
      "name": "Rock_Shale"
    },
    {
      "x": 6,
      "y": 23,
      "z": 1,
      "name": "Rock_Shale"
    },
    {
      "x": 6,
      "y": 24,
      "z": 1,
      "name": "Soil_Dirt_Cold"
    },
    {
      "x": 6,
      "y": 25,
      "z": 1,
      "name": "Soil_Dirt_Cold"
    },
    {
      "x": 6,
      "y": 26,
      "z": 1,
      "name": "Soil_Dirt_Cold"
    },
    {
      "x": 6,
      "y": 27,
      "z": 1,
      "name": "Soil_Dirt_Cold"
    },
    {
      "x": 6,
      "y": 28,
      "z": 1,
      "name": "Soil_Grass_Cold"
    },
    {
      "x": 6,
      "y": 21,
      "z": 2,
      "name": "Rock_Shale"
    },
    {
      "x": 6,
      "y": 22,
      "z": 2,
      "name": "Rock_Shale"
    },
    {
      "x": 6,
      "y": 23,
      "z": 2,
      "name": "Rock_Shale"
    },
    {
      "x": 7,
      "y": 18,
      "z": -2,
      "name": "Rock_Shale"
    },
    {
      "x": 7,
      "y": 20,
      "z": -2,
      "name": "Rock_Shale"
    },
    {
      "x": 7,
      "y": 21,
      "z": -2,
      "name": "Rock_Shale"
    },
    {
      "x": 7,
      "y": 22,
      "z": -2,
      "name": "Rock_Shale"
    },
    {
      "x": 7,
      "y": 23,
      "z": -2,
      "name": "Rock_Shale"
    },
    {
      "x": 7,
      "y": 24,
      "z": -2,
      "name": "Rock_Shale"
    },
    {
      "x": 7,
      "y": 25,
      "z": -2,
      "name": "Rock_Shale"
    },
    {
      "x": 7,
      "y": 26,
      "z": -2,
      "name": "Soil_Grass_Cold"
    },
    {
      "x": 7,
      "y": 16,
      "z": -1,
      "name": "Rock_Shale"
    },
    {
      "x": 7,
      "y": 17,
      "z": -1,
      "name": "Rock_Shale"
    },
    {
      "x": 7,
      "y": 18,
      "z": -1,
      "name": "Rock_Shale"
    },
    {
      "x": 7,
      "y": 19,
      "z": -1,
      "name": "Rock_Shale"
    },
    {
      "x": 7,
      "y": 20,
      "z": -1,
      "name": "Rock_Shale"
    },
    {
      "x": 7,
      "y": 21,
      "z": -1,
      "name": "Rock_Shale"
    },
    {
      "x": 7,
      "y": 22,
      "z": -1,
      "name": "Rock_Shale"
    },
    {
      "x": 7,
      "y": 23,
      "z": -1,
      "name": "Rock_Shale"
    },
    {
      "x": 7,
      "y": 24,
      "z": -1,
      "name": "Rock_Shale"
    },
    {
      "x": 7,
      "y": 25,
      "z": -1,
      "name": "Soil_Dirt_Cold"
    },
    {
      "x": 7,
      "y": 26,
      "z": -1,
      "name": "Soil_Dirt_Cold"
    },
    {
      "x": 7,
      "y": 27,
      "z": -1,
      "name": "Soil_Dirt_Cold"
    },
    {
      "x": 7,
      "y": 28,
      "z": -1,
      "name": "Soil_Grass_Cold"
    },
    {
      "x": 7,
      "y": 15,
      "z": 0,
      "name": "Rock_Shale"
    },
    {
      "x": 7,
      "y": 16,
      "z": 0,
      "name": "Rock_Shale"
    },
    {
      "x": 7,
      "y": 17,
      "z": 0,
      "name": "Rock_Shale"
    },
    {
      "x": 7,
      "y": 18,
      "z": 0,
      "name": "Rock_Shale"
    },
    {
      "x": 7,
      "y": 19,
      "z": 0,
      "name": "Rock_Shale"
    },
    {
      "x": 7,
      "y": 20,
      "z": 0,
      "name": "Rock_Shale"
    },
    {
      "x": 7,
      "y": 21,
      "z": 0,
      "name": "Rock_Shale"
    },
    {
      "x": 7,
      "y": 22,
      "z": 0,
      "name": "Rock_Shale"
    },
    {
      "x": 7,
      "y": 23,
      "z": 0,
      "name": "Rock_Shale"
    },
    {
      "x": 7,
      "y": 24,
      "z": 0,
      "name": "Rock_Shale"
    },
    {
      "x": 7,
      "y": 25,
      "z": 0,
      "name": "Soil_Dirt_Cold"
    },
    {
      "x": 7,
      "y": 26,
      "z": 0,
      "name": "Soil_Dirt_Cold"
    },
    {
      "x": 7,
      "y": 27,
      "z": 0,
      "name": "Soil_Dirt_Cold"
    },
    {
      "x": 7,
      "y": 28,
      "z": 0,
      "name": "Soil_Dirt_Cold"
    },
    {
      "x": 7,
      "y": 29,
      "z": 0,
      "name": "Soil_Grass_Cold"
    },
    {
      "x": 7,
      "y": 30,
      "z": 0,
      "name": "Plant_Fern_Forest"
    },
    {
      "x": 7,
      "y": 15,
      "z": 1,
      "name": "Rock_Shale"
    },
    {
      "x": 7,
      "y": 16,
      "z": 1,
      "name": "Rock_Shale"
    },
    {
      "x": 7,
      "y": 17,
      "z": 1,
      "name": "Rock_Shale"
    },
    {
      "x": 7,
      "y": 18,
      "z": 1,
      "name": "Rock_Shale"
    },
    {
      "x": 7,
      "y": 19,
      "z": 1,
      "name": "Rock_Shale"
    },
    {
      "x": 7,
      "y": 20,
      "z": 1,
      "name": "Rock_Shale"
    },
    {
      "x": 7,
      "y": 21,
      "z": 1,
      "name": "Rock_Shale"
    },
    {
      "x": 7,
      "y": 22,
      "z": 1,
      "name": "Rock_Shale"
    },
    {
      "x": 7,
      "y": 23,
      "z": 1,
      "name": "Rock_Shale"
    },
    {
      "x": 7,
      "y": 24,
      "z": 1,
      "name": "Rock_Shale"
    },
    {
      "x": 7,
      "y": 25,
      "z": 1,
      "name": "Soil_Dirt_Cold"
    },
    {
      "x": 7,
      "y": 26,
      "z": 1,
      "name": "Soil_Dirt_Cold"
    },
    {
      "x": 7,
      "y": 27,
      "z": 1,
      "name": "Soil_Dirt_Cold"
    },
    {
      "x": 7,
      "y": 28,
      "z": 1,
      "name": "Soil_Dirt_Cold"
    },
    {
      "x": 7,
      "y": 29,
      "z": 1,
      "name": "Soil_Grass_Cold"
    },
    {
      "x": 7,
      "y": 30,
      "z": 1,
      "name": "Plant_Grass_Winter"
    },
    {
      "x": 7,
      "y": 17,
      "z": 2,
      "name": "Rock_Shale"
    },
    {
      "x": 7,
      "y": 18,
      "z": 2,
      "name": "Rock_Shale"
    },
    {
      "x": 7,
      "y": 19,
      "z": 2,
      "name": "Rock_Shale"
    },
    {
      "x": 7,
      "y": 20,
      "z": 2,
      "name": "Rock_Shale"
    },
    {
      "x": 7,
      "y": 21,
      "z": 2,
      "name": "Rock_Shale"
    },
    {
      "x": 7,
      "y": 22,
      "z": 2,
      "name": "Rock_Shale"
    },
    {
      "x": 7,
      "y": 23,
      "z": 2,
      "name": "Rock_Shale"
    },
    {
      "x": 7,
      "y": 24,
      "z": 2,
      "name": "Rock_Shale"
    },
    {
      "x": 7,
      "y": 25,
      "z": 2,
      "name": "Soil_Dirt_Cold"
    },
    {
      "x": 7,
      "y": 26,
      "z": 2,
      "name": "Soil_Grass_Cold"
    },
    {
      "x": 8,
      "y": 16,
      "z": -2,
      "name": "Rock_Shale"
    },
    {
      "x": 8,
      "y": 17,
      "z": -2,
      "name": "Rock_Shale"
    },
    {
      "x": 8,
      "y": 18,
      "z": -2,
      "name": "Rock_Shale"
    },
    {
      "x": 8,
      "y": 20,
      "z": -2,
      "name": "Rock_Shale"
    },
    {
      "x": 8,
      "y": 23,
      "z": -2,
      "name": "Rock_Shale"
    },
    {
      "x": 8,
      "y": 24,
      "z": -2,
      "name": "Rock_Shale"
    },
    {
      "x": 8,
      "y": 25,
      "z": -2,
      "name": "Rock_Shale"
    },
    {
      "x": 8,
      "y": 26,
      "z": -2,
      "name": "Soil_Grass_Cold"
    },
    {
      "x": 8,
      "y": 14,
      "z": -1,
      "name": "Rock_Shale"
    },
    {
      "x": 8,
      "y": 15,
      "z": -1,
      "name": "Rock_Shale"
    },
    {
      "x": 8,
      "y": 16,
      "z": -1,
      "name": "Rock_Shale"
    },
    {
      "x": 8,
      "y": 17,
      "z": -1,
      "name": "Rock_Shale"
    },
    {
      "x": 8,
      "y": 18,
      "z": -1,
      "name": "Rock_Shale"
    },
    {
      "x": 8,
      "y": 19,
      "z": -1,
      "name": "Rock_Shale"
    },
    {
      "x": 8,
      "y": 20,
      "z": -1,
      "name": "Rock_Shale"
    },
    {
      "x": 8,
      "y": 21,
      "z": -1,
      "name": "Rock_Shale"
    },
    {
      "x": 8,
      "y": 22,
      "z": -1,
      "name": "Rock_Shale"
    },
    {
      "x": 8,
      "y": 23,
      "z": -1,
      "name": "Rock_Shale"
    },
    {
      "x": 8,
      "y": 24,
      "z": -1,
      "name": "Rock_Shale"
    },
    {
      "x": 8,
      "y": 25,
      "z": -1,
      "name": "Rock_Shale"
    },
    {
      "x": 8,
      "y": 26,
      "z": -1,
      "name": "Soil_Dirt_Cold"
    },
    {
      "x": 8,
      "y": 27,
      "z": -1,
      "name": "Soil_Dirt_Cold"
    },
    {
      "x": 8,
      "y": 28,
      "z": -1,
      "name": "Soil_Dirt_Cold"
    },
    {
      "x": 8,
      "y": 29,
      "z": -1,
      "name": "Soil_Grass_Cold"
    },
    {
      "x": 8,
      "y": 14,
      "z": 0,
      "name": "Rock_Shale"
    },
    {
      "x": 8,
      "y": 15,
      "z": 0,
      "name": "Rock_Shale"
    },
    {
      "x": 8,
      "y": 16,
      "z": 0,
      "name": "Rock_Shale"
    },
    {
      "x": 8,
      "y": 17,
      "z": 0,
      "name": "Rock_Shale"
    },
    {
      "x": 8,
      "y": 18,
      "z": 0,
      "name": "Rock_Shale"
    },
    {
      "x": 8,
      "y": 19,
      "z": 0,
      "name": "Rock_Shale"
    },
    {
      "x": 8,
      "y": 20,
      "z": 0,
      "name": "Rock_Shale"
    },
    {
      "x": 8,
      "y": 21,
      "z": 0,
      "name": "Rock_Shale"
    },
    {
      "x": 8,
      "y": 22,
      "z": 0,
      "name": "Rock_Shale"
    },
    {
      "x": 8,
      "y": 23,
      "z": 0,
      "name": "Rock_Shale"
    },
    {
      "x": 8,
      "y": 24,
      "z": 0,
      "name": "Rock_Shale"
    },
    {
      "x": 8,
      "y": 25,
      "z": 0,
      "name": "Soil_Dirt_Cold"
    },
    {
      "x": 8,
      "y": 26,
      "z": 0,
      "name": "Soil_Dirt_Cold"
    },
    {
      "x": 8,
      "y": 27,
      "z": 0,
      "name": "Soil_Dirt_Cold"
    },
    {
      "x": 8,
      "y": 28,
      "z": 0,
      "name": "Soil_Dirt_Cold"
    },
    {
      "x": 8,
      "y": 29,
      "z": 0,
      "name": "Soil_Dirt_Cold"
    },
    {
      "x": 8,
      "y": 30,
      "z": 0,
      "name": "Soil_Grass_Cold"
    },
    {
      "x": 8,
      "y": 13,
      "z": 1,
      "name": "Rock_Shale"
    },
    {
      "x": 8,
      "y": 14,
      "z": 1,
      "name": "Rock_Shale"
    },
    {
      "x": 8,
      "y": 15,
      "z": 1,
      "name": "Rock_Shale"
    },
    {
      "x": 8,
      "y": 16,
      "z": 1,
      "name": "Rock_Shale"
    },
    {
      "x": 8,
      "y": 17,
      "z": 1,
      "name": "Rock_Shale"
    },
    {
      "x": 8,
      "y": 18,
      "z": 1,
      "name": "Rock_Shale"
    },
    {
      "x": 8,
      "y": 19,
      "z": 1,
      "name": "Rock_Shale"
    },
    {
      "x": 8,
      "y": 20,
      "z": 1,
      "name": "Rock_Shale"
    },
    {
      "x": 8,
      "y": 21,
      "z": 1,
      "name": "Rock_Shale"
    },
    {
      "x": 8,
      "y": 22,
      "z": 1,
      "name": "Rock_Shale"
    },
    {
      "x": 8,
      "y": 23,
      "z": 1,
      "name": "Rock_Shale"
    },
    {
      "x": 8,
      "y": 24,
      "z": 1,
      "name": "Rock_Shale"
    },
    {
      "x": 8,
      "y": 25,
      "z": 1,
      "name": "Soil_Dirt_Cold"
    },
    {
      "x": 8,
      "y": 26,
      "z": 1,
      "name": "Soil_Dirt_Cold"
    },
    {
      "x": 8,
      "y": 27,
      "z": 1,
      "name": "Soil_Dirt_Cold"
    },
    {
      "x": 8,
      "y": 28,
      "z": 1,
      "name": "Soil_Dirt_Cold"
    },
    {
      "x": 8,
      "y": 29,
      "z": 1,
      "name": "Soil_Dirt_Cold"
    },
    {
      "x": 8,
      "y": 30,
      "z": 1,
      "name": "Soil_Grass_Cold"
    },
    {
      "x": 8,
      "y": 14,
      "z": 2,
      "name": "Rock_Shale"
    },
    {
      "x": 8,
      "y": 15,
      "z": 2,
      "name": "Rock_Shale"
    },
    {
      "x": 8,
      "y": 16,
      "z": 2,
      "name": "Rock_Shale"
    },
    {
      "x": 8,
      "y": 17,
      "z": 2,
      "name": "Rock_Shale"
    },
    {
      "x": 8,
      "y": 18,
      "z": 2,
      "name": "Rock_Shale"
    },
    {
      "x": 8,
      "y": 24,
      "z": 2,
      "name": "Rock_Shale"
    },
    {
      "x": 8,
      "y": 25,
      "z": 2,
      "name": "Soil_Dirt_Cold"
    },
    {
      "x": 8,
      "y": 26,
      "z": 2,
      "name": "Soil_Dirt_Cold"
    },
    {
      "x": 8,
      "y": 27,
      "z": 2,
      "name": "Soil_Grass_Cold"
    },
    {
      "x": 8,
      "y": 28,
      "z": 2,
      "name": "Plant_Grass_Winter"
    },
    {
      "x": 9,
      "y": 15,
      "z": -11,
      "name": "Rock_Shale"
    },
    {
      "x": 9,
      "y": 16,
      "z": -11,
      "name": "Rock_Shale"
    },
    {
      "x": 9,
      "y": 17,
      "z": -11,
      "name": "Rock_Shale"
    },
    {
      "x": 9,
      "y": 18,
      "z": -11,
      "name": "Rock_Shale"
    },
    {
      "x": 9,
      "y": 19,
      "z": -11,
      "name": "Rock_Shale"
    },
    {
      "x": 9,
      "y": 20,
      "z": -11,
      "name": "Rock_Shale"
    },
    {
      "x": 9,
      "y": 13,
      "z": -10,
      "name": "Rock_Shale"
    },
    {
      "x": 9,
      "y": 14,
      "z": -10,
      "name": "Rock_Shale"
    },
    {
      "x": 9,
      "y": 15,
      "z": -10,
      "name": "Rock_Shale"
    },
    {
      "x": 9,
      "y": 16,
      "z": -10,
      "name": "Rock_Shale"
    },
    {
      "x": 9,
      "y": 17,
      "z": -10,
      "name": "Rock_Shale"
    },
    {
      "x": 9,
      "y": 18,
      "z": -10,
      "name": "Rock_Shale"
    },
    {
      "x": 9,
      "y": 19,
      "z": -10,
      "name": "Rock_Shale"
    },
    {
      "x": 9,
      "y": 14,
      "z": -9,
      "name": "Rock_Shale"
    },
    {
      "x": 9,
      "y": 15,
      "z": -9,
      "name": "Rock_Shale"
    },
    {
      "x": 9,
      "y": 17,
      "z": -2,
      "name": "Rock_Shale"
    },
    {
      "x": 9,
      "y": 18,
      "z": -2,
      "name": "Rock_Shale"
    },
    {
      "x": 9,
      "y": 14,
      "z": -1,
      "name": "Rock_Shale"
    },
    {
      "x": 9,
      "y": 15,
      "z": -1,
      "name": "Rock_Shale"
    },
    {
      "x": 9,
      "y": 16,
      "z": -1,
      "name": "Rock_Shale"
    },
    {
      "x": 9,
      "y": 17,
      "z": -1,
      "name": "Rock_Shale"
    },
    {
      "x": 9,
      "y": 18,
      "z": -1,
      "name": "Rock_Shale"
    },
    {
      "x": 9,
      "y": 19,
      "z": -1,
      "name": "Rock_Shale"
    },
    {
      "x": 9,
      "y": 20,
      "z": -1,
      "name": "Rock_Shale"
    },
    {
      "x": 9,
      "y": 25,
      "z": -1,
      "name": "Rock_Shale"
    },
    {
      "x": 9,
      "y": 26,
      "z": -1,
      "name": "Rock_Shale"
    },
    {
      "x": 9,
      "y": 27,
      "z": -1,
      "name": "Soil_Dirt_Cold"
    },
    {
      "x": 9,
      "y": 28,
      "z": -1,
      "name": "Soil_Dirt_Cold"
    },
    {
      "x": 9,
      "y": 29,
      "z": -1,
      "name": "Soil_Dirt_Cold"
    },
    {
      "x": 9,
      "y": 30,
      "z": -1,
      "name": "Soil_Grass_Cold"
    },
    {
      "x": 9,
      "y": 12,
      "z": 0,
      "name": "Rock_Shale"
    },
    {
      "x": 9,
      "y": 13,
      "z": 0,
      "name": "Rock_Shale"
    },
    {
      "x": 9,
      "y": 14,
      "z": 0,
      "name": "Rock_Shale"
    },
    {
      "x": 9,
      "y": 15,
      "z": 0,
      "name": "Rock_Shale"
    },
    {
      "x": 9,
      "y": 16,
      "z": 0,
      "name": "Rock_Shale"
    },
    {
      "x": 9,
      "y": 17,
      "z": 0,
      "name": "Rock_Shale"
    },
    {
      "x": 9,
      "y": 18,
      "z": 0,
      "name": "Rock_Shale"
    },
    {
      "x": 9,
      "y": 19,
      "z": 0,
      "name": "Rock_Shale"
    },
    {
      "x": 9,
      "y": 20,
      "z": 0,
      "name": "Rock_Shale"
    },
    {
      "x": 9,
      "y": 21,
      "z": 0,
      "name": "Rock_Shale"
    },
    {
      "x": 9,
      "y": 22,
      "z": 0,
      "name": "Rock_Shale"
    },
    {
      "x": 9,
      "y": 23,
      "z": 0,
      "name": "Rock_Shale"
    },
    {
      "x": 9,
      "y": 24,
      "z": 0,
      "name": "Rock_Shale"
    },
    {
      "x": 9,
      "y": 25,
      "z": 0,
      "name": "Rock_Shale"
    },
    {
      "x": 9,
      "y": 26,
      "z": 0,
      "name": "Soil_Dirt_Cold"
    },
    {
      "x": 9,
      "y": 27,
      "z": 0,
      "name": "Soil_Dirt_Cold"
    },
    {
      "x": 9,
      "y": 28,
      "z": 0,
      "name": "Soil_Dirt_Cold"
    },
    {
      "x": 9,
      "y": 29,
      "z": 0,
      "name": "Soil_Dirt_Cold"
    },
    {
      "x": 9,
      "y": 30,
      "z": 0,
      "name": "Soil_Dirt_Cold"
    },
    {
      "x": 9,
      "y": 31,
      "z": 0,
      "name": "Soil_Grass_Cold"
    },
    {
      "x": 9,
      "y": 12,
      "z": 1,
      "name": "Rock_Shale"
    },
    {
      "x": 9,
      "y": 13,
      "z": 1,
      "name": "Rock_Shale"
    },
    {
      "x": 9,
      "y": 14,
      "z": 1,
      "name": "Rock_Shale"
    },
    {
      "x": 9,
      "y": 16,
      "z": 1,
      "name": "Rock_Shale"
    },
    {
      "x": 9,
      "y": 17,
      "z": 1,
      "name": "Rock_Shale"
    },
    {
      "x": 9,
      "y": 18,
      "z": 1,
      "name": "Rock_Shale"
    },
    {
      "x": 9,
      "y": 19,
      "z": 1,
      "name": "Rock_Shale"
    },
    {
      "x": 9,
      "y": 23,
      "z": 1,
      "name": "Rock_Shale"
    },
    {
      "x": 9,
      "y": 24,
      "z": 1,
      "name": "Rock_Shale"
    },
    {
      "x": 9,
      "y": 25,
      "z": 1,
      "name": "Rock_Shale"
    },
    {
      "x": 9,
      "y": 26,
      "z": 1,
      "name": "Soil_Dirt_Cold"
    },
    {
      "x": 9,
      "y": 27,
      "z": 1,
      "name": "Soil_Dirt_Cold"
    },
    {
      "x": 9,
      "y": 28,
      "z": 1,
      "name": "Soil_Dirt_Cold"
    },
    {
      "x": 9,
      "y": 29,
      "z": 1,
      "name": "Soil_Dirt_Cold"
    },
    {
      "x": 9,
      "y": 30,
      "z": 1,
      "name": "Soil_Grass_Cold"
    },
    {
      "x": 9,
      "y": 12,
      "z": 2,
      "name": "Rock_Shale"
    },
    {
      "x": 9,
      "y": 13,
      "z": 2,
      "name": "Rock_Shale"
    },
    {
      "x": 9,
      "y": 14,
      "z": 2,
      "name": "Rock_Shale"
    },
    {
      "x": 9,
      "y": 25,
      "z": 2,
      "name": "Rock_Shale"
    },
    {
      "x": 9,
      "y": 26,
      "z": 2,
      "name": "Soil_Grass_Cold"
    },
    {
      "x": 10,
      "y": 18,
      "z": -13,
      "name": "Rock_Shale"
    },
    {
      "x": 10,
      "y": 19,
      "z": -13,
      "name": "Rock_Shale"
    },
    {
      "x": 10,
      "y": 16,
      "z": -12,
      "name": "Rock_Shale"
    },
    {
      "x": 10,
      "y": 17,
      "z": -12,
      "name": "Rock_Shale"
    },
    {
      "x": 10,
      "y": 18,
      "z": -12,
      "name": "Rock_Shale"
    },
    {
      "x": 10,
      "y": 19,
      "z": -12,
      "name": "Rock_Shale"
    },
    {
      "x": 10,
      "y": 20,
      "z": -12,
      "name": "Rock_Shale"
    },
    {
      "x": 10,
      "y": 14,
      "z": -11,
      "name": "Rock_Shale"
    },
    {
      "x": 10,
      "y": 15,
      "z": -11,
      "name": "Rock_Shale"
    },
    {
      "x": 10,
      "y": 16,
      "z": -11,
      "name": "Rock_Shale"
    },
    {
      "x": 10,
      "y": 17,
      "z": -11,
      "name": "Rock_Shale"
    },
    {
      "x": 10,
      "y": 18,
      "z": -11,
      "name": "Rock_Shale"
    },
    {
      "x": 10,
      "y": 19,
      "z": -11,
      "name": "Rock_Shale"
    },
    {
      "x": 10,
      "y": 20,
      "z": -11,
      "name": "Rock_Shale"
    },
    {
      "x": 10,
      "y": 21,
      "z": -11,
      "name": "Rock_Shale"
    },
    {
      "x": 10,
      "y": 12,
      "z": -10,
      "name": "Rock_Shale"
    },
    {
      "x": 10,
      "y": 13,
      "z": -10,
      "name": "Rock_Shale"
    },
    {
      "x": 10,
      "y": 14,
      "z": -10,
      "name": "Rock_Shale"
    },
    {
      "x": 10,
      "y": 15,
      "z": -10,
      "name": "Rock_Shale"
    },
    {
      "x": 10,
      "y": 16,
      "z": -10,
      "name": "Rock_Shale"
    },
    {
      "x": 10,
      "y": 17,
      "z": -10,
      "name": "Rock_Shale"
    },
    {
      "x": 10,
      "y": 18,
      "z": -10,
      "name": "Rock_Shale"
    },
    {
      "x": 10,
      "y": 19,
      "z": -10,
      "name": "Rock_Shale"
    },
    {
      "x": 10,
      "y": 20,
      "z": -10,
      "name": "Rock_Shale"
    },
    {
      "x": 10,
      "y": 21,
      "z": -10,
      "name": "Rock_Shale"
    },
    {
      "x": 10,
      "y": 12,
      "z": -9,
      "name": "Rock_Shale"
    },
    {
      "x": 10,
      "y": 13,
      "z": -9,
      "name": "Rock_Shale"
    },
    {
      "x": 10,
      "y": 14,
      "z": -9,
      "name": "Rock_Shale"
    },
    {
      "x": 10,
      "y": 15,
      "z": -9,
      "name": "Rock_Shale"
    },
    {
      "x": 10,
      "y": 16,
      "z": -9,
      "name": "Rock_Shale"
    },
    {
      "x": 10,
      "y": 17,
      "z": -9,
      "name": "Rock_Shale"
    },
    {
      "x": 10,
      "y": 18,
      "z": -9,
      "name": "Rock_Shale"
    },
    {
      "x": 10,
      "y": 19,
      "z": -9,
      "name": "Rock_Shale"
    },
    {
      "x": 10,
      "y": 12,
      "z": -8,
      "name": "Rock_Shale"
    },
    {
      "x": 10,
      "y": 13,
      "z": -8,
      "name": "Rock_Shale"
    },
    {
      "x": 10,
      "y": 14,
      "z": -8,
      "name": "Rock_Shale"
    },
    {
      "x": 10,
      "y": 15,
      "z": -8,
      "name": "Rock_Shale"
    },
    {
      "x": 10,
      "y": 16,
      "z": -8,
      "name": "Rock_Shale"
    },
    {
      "x": 10,
      "y": 13,
      "z": -7,
      "name": "Rock_Shale"
    },
    {
      "x": 10,
      "y": 14,
      "z": -7,
      "name": "Rock_Shale"
    },
    {
      "x": 10,
      "y": 13,
      "z": -1,
      "name": "Rock_Shale"
    },
    {
      "x": 10,
      "y": 14,
      "z": -1,
      "name": "Rock_Shale"
    },
    {
      "x": 10,
      "y": 26,
      "z": -1,
      "name": "Rock_Shale"
    },
    {
      "x": 10,
      "y": 27,
      "z": -1,
      "name": "Rock_Shale"
    },
    {
      "x": 10,
      "y": 28,
      "z": -1,
      "name": "Soil_Dirt_Cold"
    },
    {
      "x": 10,
      "y": 29,
      "z": -1,
      "name": "Soil_Dirt_Cold"
    },
    {
      "x": 10,
      "y": 30,
      "z": -1,
      "name": "Soil_Dirt_Cold"
    },
    {
      "x": 10,
      "y": 31,
      "z": -1,
      "name": "Soil_Grass_Cold"
    },
    {
      "x": 10,
      "y": 12,
      "z": 0,
      "name": "Rock_Shale"
    },
    {
      "x": 10,
      "y": 13,
      "z": 0,
      "name": "Rock_Shale"
    },
    {
      "x": 10,
      "y": 14,
      "z": 0,
      "name": "Rock_Shale"
    },
    {
      "x": 10,
      "y": 15,
      "z": 0,
      "name": "Rock_Shale"
    },
    {
      "x": 10,
      "y": 25,
      "z": 0,
      "name": "Rock_Shale"
    },
    {
      "x": 10,
      "y": 26,
      "z": 0,
      "name": "Rock_Shale"
    },
    {
      "x": 10,
      "y": 27,
      "z": 0,
      "name": "Rock_Shale"
    },
    {
      "x": 10,
      "y": 28,
      "z": 0,
      "name": "Soil_Dirt_Cold"
    },
    {
      "x": 10,
      "y": 29,
      "z": 0,
      "name": "Soil_Dirt_Cold"
    },
    {
      "x": 10,
      "y": 30,
      "z": 0,
      "name": "Soil_Dirt_Cold"
    },
    {
      "x": 10,
      "y": 31,
      "z": 0,
      "name": "Soil_Grass_Cold"
    },
    {
      "x": 10,
      "y": 32,
      "z": 0,
      "name": "Plant_Grass_Winter_Tall"
    },
    {
      "x": 10,
      "y": 33,
      "z": 0,
      "name": "Plant_Grass_Winter_Tall",
      "filler": 1024
    },
    {
      "x": 10,
      "y": 11,
      "z": 1,
      "name": "Rock_Shale"
    },
    {
      "x": 10,
      "y": 12,
      "z": 1,
      "name": "Rock_Shale"
    },
    {
      "x": 10,
      "y": 13,
      "z": 1,
      "name": "Rock_Shale"
    },
    {
      "x": 10,
      "y": 26,
      "z": 1,
      "name": "Rock_Shale"
    },
    {
      "x": 10,
      "y": 27,
      "z": 1,
      "name": "Soil_Dirt_Cold"
    },
    {
      "x": 10,
      "y": 28,
      "z": 1,
      "name": "Soil_Dirt_Cold"
    },
    {
      "x": 10,
      "y": 29,
      "z": 1,
      "name": "Soil_Dirt_Cold"
    },
    {
      "x": 10,
      "y": 30,
      "z": 1,
      "name": "Soil_Dirt_Cold"
    },
    {
      "x": 10,
      "y": 31,
      "z": 1,
      "name": "Soil_Grass_Cold"
    },
    {
      "x": 10,
      "y": 11,
      "z": 2,
      "name": "Rock_Shale"
    },
    {
      "x": 10,
      "y": 12,
      "z": 2,
      "name": "Rock_Shale"
    },
    {
      "x": 10,
      "y": 27,
      "z": 2,
      "name": "Rock_Shale"
    },
    {
      "x": 10,
      "y": 28,
      "z": 2,
      "name": "Soil_Dirt_Cold"
    },
    {
      "x": 10,
      "y": 29,
      "z": 2,
      "name": "Soil_Dirt_Cold"
    },
    {
      "x": 10,
      "y": 30,
      "z": 2,
      "name": "Soil_Dirt_Cold"
    },
    {
      "x": 10,
      "y": 31,
      "z": 2,
      "name": "Soil_Grass_Cold"
    },
    {
      "x": 10,
      "y": 32,
      "z": 2,
      "name": "Plant_Fern_Forest"
    },
    {
      "x": 10,
      "y": 11,
      "z": 3,
      "name": "Rock_Shale"
    },
    {
      "x": 11,
      "y": 15,
      "z": -12,
      "name": "Rock_Shale"
    },
    {
      "x": 11,
      "y": 16,
      "z": -12,
      "name": "Rock_Shale"
    },
    {
      "x": 11,
      "y": 17,
      "z": -12,
      "name": "Rock_Shale"
    },
    {
      "x": 11,
      "y": 18,
      "z": -12,
      "name": "Rock_Shale"
    },
    {
      "x": 11,
      "y": 19,
      "z": -12,
      "name": "Rock_Shale"
    },
    {
      "x": 11,
      "y": 20,
      "z": -12,
      "name": "Rock_Shale"
    },
    {
      "x": 11,
      "y": 21,
      "z": -12,
      "name": "Rock_Shale"
    },
    {
      "x": 11,
      "y": 13,
      "z": -11,
      "name": "Rock_Shale"
    },
    {
      "x": 11,
      "y": 14,
      "z": -11,
      "name": "Rock_Shale"
    },
    {
      "x": 11,
      "y": 15,
      "z": -11,
      "name": "Rock_Shale"
    },
    {
      "x": 11,
      "y": 16,
      "z": -11,
      "name": "Rock_Shale"
    },
    {
      "x": 11,
      "y": 17,
      "z": -11,
      "name": "Rock_Shale"
    },
    {
      "x": 11,
      "y": 18,
      "z": -11,
      "name": "Rock_Shale"
    },
    {
      "x": 11,
      "y": 19,
      "z": -11,
      "name": "Rock_Shale"
    },
    {
      "x": 11,
      "y": 20,
      "z": -11,
      "name": "Rock_Shale"
    },
    {
      "x": 11,
      "y": 21,
      "z": -11,
      "name": "Rock_Shale"
    },
    {
      "x": 11,
      "y": 22,
      "z": -11,
      "name": "Rock_Shale"
    },
    {
      "x": 11,
      "y": 12,
      "z": -10,
      "name": "Rock_Shale"
    },
    {
      "x": 11,
      "y": 13,
      "z": -10,
      "name": "Rock_Shale"
    },
    {
      "x": 11,
      "y": 14,
      "z": -10,
      "name": "Rock_Shale"
    },
    {
      "x": 11,
      "y": 15,
      "z": -10,
      "name": "Rock_Shale"
    },
    {
      "x": 11,
      "y": 16,
      "z": -10,
      "name": "Rock_Shale"
    },
    {
      "x": 11,
      "y": 17,
      "z": -10,
      "name": "Rock_Shale"
    },
    {
      "x": 11,
      "y": 18,
      "z": -10,
      "name": "Rock_Shale"
    },
    {
      "x": 11,
      "y": 19,
      "z": -10,
      "name": "Rock_Shale"
    },
    {
      "x": 11,
      "y": 20,
      "z": -10,
      "name": "Rock_Shale"
    },
    {
      "x": 11,
      "y": 21,
      "z": -10,
      "name": "Rock_Shale"
    },
    {
      "x": 11,
      "y": 22,
      "z": -10,
      "name": "Rock_Shale"
    },
    {
      "x": 11,
      "y": 11,
      "z": -9,
      "name": "Rock_Shale"
    },
    {
      "x": 11,
      "y": 12,
      "z": -9,
      "name": "Rock_Shale"
    },
    {
      "x": 11,
      "y": 13,
      "z": -9,
      "name": "Rock_Shale"
    },
    {
      "x": 11,
      "y": 14,
      "z": -9,
      "name": "Rock_Shale"
    },
    {
      "x": 11,
      "y": 15,
      "z": -9,
      "name": "Rock_Shale"
    },
    {
      "x": 11,
      "y": 16,
      "z": -9,
      "name": "Rock_Shale"
    },
    {
      "x": 11,
      "y": 17,
      "z": -9,
      "name": "Rock_Shale"
    },
    {
      "x": 11,
      "y": 18,
      "z": -9,
      "name": "Rock_Shale"
    },
    {
      "x": 11,
      "y": 19,
      "z": -9,
      "name": "Rock_Shale"
    },
    {
      "x": 11,
      "y": 20,
      "z": -9,
      "name": "Rock_Shale"
    },
    {
      "x": 11,
      "y": 21,
      "z": -9,
      "name": "Rock_Shale"
    },
    {
      "x": 11,
      "y": 11,
      "z": -8,
      "name": "Rock_Shale"
    },
    {
      "x": 11,
      "y": 12,
      "z": -8,
      "name": "Rock_Shale"
    },
    {
      "x": 11,
      "y": 13,
      "z": -8,
      "name": "Rock_Shale"
    },
    {
      "x": 11,
      "y": 14,
      "z": -8,
      "name": "Rock_Shale"
    },
    {
      "x": 11,
      "y": 15,
      "z": -8,
      "name": "Rock_Shale"
    },
    {
      "x": 11,
      "y": 16,
      "z": -8,
      "name": "Rock_Shale"
    },
    {
      "x": 11,
      "y": 17,
      "z": -8,
      "name": "Rock_Shale"
    },
    {
      "x": 11,
      "y": 11,
      "z": -7,
      "name": "Rock_Shale"
    },
    {
      "x": 11,
      "y": 12,
      "z": -7,
      "name": "Rock_Shale"
    },
    {
      "x": 11,
      "y": 13,
      "z": -7,
      "name": "Rock_Shale"
    },
    {
      "x": 11,
      "y": 14,
      "z": -7,
      "name": "Rock_Shale"
    },
    {
      "x": 11,
      "y": 15,
      "z": -7,
      "name": "Rock_Shale"
    },
    {
      "x": 11,
      "y": 11,
      "z": -6,
      "name": "Rock_Shale"
    },
    {
      "x": 11,
      "y": 12,
      "z": -6,
      "name": "Rock_Shale"
    },
    {
      "x": 11,
      "y": 13,
      "z": -6,
      "name": "Rock_Shale"
    },
    {
      "x": 11,
      "y": 14,
      "z": -6,
      "name": "Rock_Shale"
    },
    {
      "x": 11,
      "y": 28,
      "z": -2,
      "name": "Soil_Dirt_Cold"
    },
    {
      "x": 11,
      "y": 29,
      "z": -2,
      "name": "Soil_Dirt_Cold"
    },
    {
      "x": 11,
      "y": 30,
      "z": -2,
      "name": "Soil_Dirt_Cold"
    },
    {
      "x": 11,
      "y": 31,
      "z": -2,
      "name": "Soil_Grass_Cold"
    },
    {
      "x": 11,
      "y": 27,
      "z": -1,
      "name": "Rock_Shale"
    },
    {
      "x": 11,
      "y": 28,
      "z": -1,
      "name": "Soil_Dirt_Cold"
    },
    {
      "x": 11,
      "y": 29,
      "z": -1,
      "name": "Soil_Dirt_Cold"
    },
    {
      "x": 11,
      "y": 30,
      "z": -1,
      "name": "Soil_Dirt_Cold"
    },
    {
      "x": 11,
      "y": 31,
      "z": -1,
      "name": "Soil_Grass_Cold"
    },
    {
      "x": 11,
      "y": 32,
      "z": -1,
      "name": "Plant_Grass_Winter"
    },
    {
      "x": 11,
      "y": 12,
      "z": 0,
      "name": "Rock_Shale"
    },
    {
      "x": 11,
      "y": 27,
      "z": 0,
      "name": "Rock_Shale"
    },
    {
      "x": 11,
      "y": 28,
      "z": 0,
      "name": "Soil_Dirt_Cold"
    },
    {
      "x": 11,
      "y": 29,
      "z": 0,
      "name": "Soil_Dirt_Cold"
    },
    {
      "x": 11,
      "y": 30,
      "z": 0,
      "name": "Soil_Dirt_Cold"
    },
    {
      "x": 11,
      "y": 31,
      "z": 0,
      "name": "Soil_Grass_Cold"
    },
    {
      "x": 11,
      "y": 11,
      "z": 1,
      "name": "Rock_Shale"
    },
    {
      "x": 11,
      "y": 12,
      "z": 1,
      "name": "Rock_Shale"
    },
    {
      "x": 11,
      "y": 28,
      "z": 1,
      "name": "Soil_Dirt_Cold"
    },
    {
      "x": 11,
      "y": 29,
      "z": 1,
      "name": "Soil_Dirt_Cold"
    },
    {
      "x": 11,
      "y": 30,
      "z": 1,
      "name": "Soil_Dirt_Cold"
    },
    {
      "x": 11,
      "y": 31,
      "z": 1,
      "name": "Soil_Dirt_Cold"
    },
    {
      "x": 11,
      "y": 32,
      "z": 1,
      "name": "Soil_Dirt_Poisoned"
    },
    {
      "x": 11,
      "y": 11,
      "z": 2,
      "name": "Rock_Shale"
    },
    {
      "x": 11,
      "y": 28,
      "z": 2,
      "name": "Soil_Dirt_Cold"
    },
    {
      "x": 11,
      "y": 29,
      "z": 2,
      "name": "Soil_Dirt_Cold"
    },
    {
      "x": 11,
      "y": 30,
      "z": 2,
      "name": "Soil_Dirt_Poisoned"
    },
    {
      "x": 11,
      "y": 31,
      "z": 2,
      "name": "Soil_Dirt_Poisoned"
    },
    {
      "x": 11,
      "y": 11,
      "z": 3,
      "name": "Rock_Shale"
    },
    {
      "x": 12,
      "y": 17,
      "z": -12,
      "name": "Rock_Shale"
    },
    {
      "x": 12,
      "y": 18,
      "z": -12,
      "name": "Rock_Shale"
    },
    {
      "x": 12,
      "y": 14,
      "z": -11,
      "name": "Rock_Shale"
    },
    {
      "x": 12,
      "y": 15,
      "z": -11,
      "name": "Rock_Shale"
    },
    {
      "x": 12,
      "y": 16,
      "z": -11,
      "name": "Rock_Shale"
    },
    {
      "x": 12,
      "y": 17,
      "z": -11,
      "name": "Rock_Shale"
    },
    {
      "x": 12,
      "y": 18,
      "z": -11,
      "name": "Rock_Shale"
    },
    {
      "x": 12,
      "y": 19,
      "z": -11,
      "name": "Rock_Shale"
    },
    {
      "x": 12,
      "y": 21,
      "z": -11,
      "name": "Rock_Shale"
    },
    {
      "x": 12,
      "y": 22,
      "z": -11,
      "name": "Rock_Shale"
    },
    {
      "x": 12,
      "y": 12,
      "z": -10,
      "name": "Rock_Shale"
    },
    {
      "x": 12,
      "y": 13,
      "z": -10,
      "name": "Rock_Shale"
    },
    {
      "x": 12,
      "y": 14,
      "z": -10,
      "name": "Rock_Shale"
    },
    {
      "x": 12,
      "y": 15,
      "z": -10,
      "name": "Rock_Shale"
    },
    {
      "x": 12,
      "y": 16,
      "z": -10,
      "name": "Rock_Shale"
    },
    {
      "x": 12,
      "y": 17,
      "z": -10,
      "name": "Rock_Shale"
    },
    {
      "x": 12,
      "y": 18,
      "z": -10,
      "name": "Rock_Shale"
    },
    {
      "x": 12,
      "y": 19,
      "z": -10,
      "name": "Rock_Shale"
    },
    {
      "x": 12,
      "y": 20,
      "z": -10,
      "name": "Rock_Shale"
    },
    {
      "x": 12,
      "y": 21,
      "z": -10,
      "name": "Rock_Shale"
    },
    {
      "x": 12,
      "y": 22,
      "z": -10,
      "name": "Rock_Shale"
    },
    {
      "x": 12,
      "y": 23,
      "z": -10,
      "name": "Rock_Shale"
    },
    {
      "x": 12,
      "y": 11,
      "z": -9,
      "name": "Rock_Shale"
    },
    {
      "x": 12,
      "y": 12,
      "z": -9,
      "name": "Rock_Shale"
    },
    {
      "x": 12,
      "y": 13,
      "z": -9,
      "name": "Rock_Shale"
    },
    {
      "x": 12,
      "y": 14,
      "z": -9,
      "name": "Rock_Shale"
    },
    {
      "x": 12,
      "y": 15,
      "z": -9,
      "name": "Rock_Shale"
    },
    {
      "x": 12,
      "y": 16,
      "z": -9,
      "name": "Rock_Shale"
    },
    {
      "x": 12,
      "y": 17,
      "z": -9,
      "name": "Rock_Shale"
    },
    {
      "x": 12,
      "y": 18,
      "z": -9,
      "name": "Rock_Shale"
    },
    {
      "x": 12,
      "y": 19,
      "z": -9,
      "name": "Rock_Shale"
    },
    {
      "x": 12,
      "y": 20,
      "z": -9,
      "name": "Rock_Shale"
    },
    {
      "x": 12,
      "y": 21,
      "z": -9,
      "name": "Rock_Shale"
    },
    {
      "x": 12,
      "y": 22,
      "z": -9,
      "name": "Rock_Shale"
    },
    {
      "x": 12,
      "y": 11,
      "z": -8,
      "name": "Rock_Shale"
    },
    {
      "x": 12,
      "y": 12,
      "z": -8,
      "name": "Rock_Shale"
    },
    {
      "x": 12,
      "y": 13,
      "z": -8,
      "name": "Rock_Shale"
    },
    {
      "x": 12,
      "y": 14,
      "z": -8,
      "name": "Rock_Shale"
    },
    {
      "x": 12,
      "y": 15,
      "z": -8,
      "name": "Rock_Shale"
    },
    {
      "x": 12,
      "y": 16,
      "z": -8,
      "name": "Rock_Shale"
    },
    {
      "x": 12,
      "y": 17,
      "z": -8,
      "name": "Rock_Shale"
    },
    {
      "x": 12,
      "y": 11,
      "z": -7,
      "name": "Rock_Shale"
    },
    {
      "x": 12,
      "y": 12,
      "z": -7,
      "name": "Rock_Shale"
    },
    {
      "x": 12,
      "y": 13,
      "z": -7,
      "name": "Rock_Shale"
    },
    {
      "x": 12,
      "y": 14,
      "z": -7,
      "name": "Rock_Shale"
    },
    {
      "x": 12,
      "y": 15,
      "z": -7,
      "name": "Rock_Shale"
    },
    {
      "x": 12,
      "y": 11,
      "z": -6,
      "name": "Rock_Shale"
    },
    {
      "x": 12,
      "y": 12,
      "z": -6,
      "name": "Rock_Shale"
    },
    {
      "x": 12,
      "y": 13,
      "z": -6,
      "name": "Rock_Shale"
    },
    {
      "x": 12,
      "y": 11,
      "z": -5,
      "name": "Rock_Shale"
    },
    {
      "x": 12,
      "y": 12,
      "z": -5,
      "name": "Rock_Shale"
    },
    {
      "x": 12,
      "y": 29,
      "z": -3,
      "name": "Soil_Dirt_Cold"
    },
    {
      "x": 12,
      "y": 30,
      "z": -3,
      "name": "Soil_Grass_Cold"
    },
    {
      "x": 12,
      "y": 28,
      "z": -2,
      "name": "Rock_Shale"
    },
    {
      "x": 12,
      "y": 29,
      "z": -2,
      "name": "Soil_Dirt_Cold"
    },
    {
      "x": 12,
      "y": 30,
      "z": -2,
      "name": "Soil_Dirt_Cold"
    },
    {
      "x": 12,
      "y": 31,
      "z": -2,
      "name": "Soil_Dirt_Cold"
    },
    {
      "x": 12,
      "y": 32,
      "z": -2,
      "name": "Soil_Grass_Cold"
    },
    {
      "x": 12,
      "y": 27,
      "z": -1,
      "name": "Rock_Shale"
    },
    {
      "x": 12,
      "y": 28,
      "z": -1,
      "name": "Rock_Shale"
    },
    {
      "x": 12,
      "y": 29,
      "z": -1,
      "name": "Soil_Dirt_Cold"
    },
    {
      "x": 12,
      "y": 30,
      "z": -1,
      "name": "Soil_Dirt_Cold"
    },
    {
      "x": 12,
      "y": 31,
      "z": -1,
      "name": "Soil_Dirt_Cold"
    },
    {
      "x": 12,
      "y": 32,
      "z": -1,
      "name": "Soil_Grass_Cold"
    },
    {
      "x": 12,
      "y": 28,
      "z": 0,
      "name": "Soil_Dirt_Cold"
    },
    {
      "x": 12,
      "y": 29,
      "z": 0,
      "name": "Soil_Dirt_Cold"
    },
    {
      "x": 12,
      "y": 30,
      "z": 0,
      "name": "Soil_Dirt_Cold"
    },
    {
      "x": 12,
      "y": 31,
      "z": 0,
      "name": "Soil_Dirt_Cold"
    },
    {
      "x": 12,
      "y": 32,
      "z": 0,
      "name": "Soil_Dirt_Poisoned"
    },
    {
      "x": 12,
      "y": 28,
      "z": 1,
      "name": "Soil_Dirt_Cold"
    },
    {
      "x": 12,
      "y": 29,
      "z": 1,
      "name": "Soil_Dirt_Cold"
    },
    {
      "x": 12,
      "y": 30,
      "z": 1,
      "name": "Soil_Dirt_Poisoned"
    },
    {
      "x": 12,
      "y": 31,
      "z": 1,
      "name": "Soil_Dirt_Poisoned"
    },
    {
      "x": 12,
      "y": 32,
      "z": 1,
      "name": "Soil_Dirt_Poisoned"
    },
    {
      "x": 12,
      "y": 10,
      "z": 2,
      "name": "Rock_Shale"
    },
    {
      "x": 12,
      "y": 11,
      "z": 2,
      "name": "Rock_Shale"
    },
    {
      "x": 12,
      "y": 29,
      "z": 2,
      "name": "Soil_Dirt_Poisoned"
    },
    {
      "x": 12,
      "y": 30,
      "z": 2,
      "name": "Soil_Dirt_Poisoned"
    },
    {
      "x": 12,
      "y": 31,
      "z": 2,
      "name": "Soil_Dirt_Poisoned"
    },
    {
      "x": 12,
      "y": 32,
      "z": 2,
      "name": "Soil_Dirt_Poisoned"
    },
    {
      "x": 12,
      "y": 33,
      "z": 2,
      "name": "*Plant_Crop_Berry_Winter_Block_State_Definitions_StageFinal",
      "components": {
        "Components": {
          "FarmingBlock": {}
        }
      }
    },
    {
      "x": 12,
      "y": 10,
      "z": 3,
      "name": "Rock_Shale"
    },
    {
      "x": 12,
      "y": 30,
      "z": 3,
      "name": "Soil_Dirt_Poisoned"
    },
    {
      "x": 12,
      "y": 10,
      "z": 4,
      "name": "Rock_Shale"
    },
    {
      "x": 13,
      "y": 17,
      "z": -11,
      "name": "Rock_Shale"
    },
    {
      "x": 13,
      "y": 18,
      "z": -11,
      "name": "Rock_Shale"
    },
    {
      "x": 13,
      "y": 13,
      "z": -10,
      "name": "Rock_Shale"
    },
    {
      "x": 13,
      "y": 14,
      "z": -10,
      "name": "Rock_Shale"
    },
    {
      "x": 13,
      "y": 15,
      "z": -10,
      "name": "Rock_Shale"
    },
    {
      "x": 13,
      "y": 16,
      "z": -10,
      "name": "Rock_Shale"
    },
    {
      "x": 13,
      "y": 17,
      "z": -10,
      "name": "Rock_Shale"
    },
    {
      "x": 13,
      "y": 18,
      "z": -10,
      "name": "Rock_Shale"
    },
    {
      "x": 13,
      "y": 19,
      "z": -10,
      "name": "Rock_Shale"
    },
    {
      "x": 13,
      "y": 22,
      "z": -10,
      "name": "Rock_Shale"
    },
    {
      "x": 13,
      "y": 23,
      "z": -10,
      "name": "Rock_Shale"
    },
    {
      "x": 13,
      "y": 13,
      "z": -9,
      "name": "Rock_Shale"
    },
    {
      "x": 13,
      "y": 14,
      "z": -9,
      "name": "Rock_Shale"
    },
    {
      "x": 13,
      "y": 15,
      "z": -9,
      "name": "Rock_Shale"
    },
    {
      "x": 13,
      "y": 16,
      "z": -9,
      "name": "Rock_Shale"
    },
    {
      "x": 13,
      "y": 21,
      "z": -9,
      "name": "Rock_Shale"
    },
    {
      "x": 13,
      "y": 22,
      "z": -9,
      "name": "Rock_Shale"
    },
    {
      "x": 13,
      "y": 23,
      "z": -9,
      "name": "Rock_Shale"
    },
    {
      "x": 13,
      "y": 24,
      "z": -9,
      "name": "Rock_Shale"
    },
    {
      "x": 13,
      "y": 11,
      "z": -8,
      "name": "Rock_Shale"
    },
    {
      "x": 13,
      "y": 12,
      "z": -8,
      "name": "Rock_Shale"
    },
    {
      "x": 13,
      "y": 13,
      "z": -8,
      "name": "Rock_Shale"
    },
    {
      "x": 13,
      "y": 14,
      "z": -8,
      "name": "Rock_Shale"
    },
    {
      "x": 13,
      "y": 15,
      "z": -8,
      "name": "Rock_Shale"
    },
    {
      "x": 13,
      "y": 16,
      "z": -8,
      "name": "Rock_Shale"
    },
    {
      "x": 13,
      "y": 24,
      "z": -8,
      "name": "Rock_Shale"
    },
    {
      "x": 13,
      "y": 10,
      "z": -7,
      "name": "Rock_Shale"
    },
    {
      "x": 13,
      "y": 11,
      "z": -7,
      "name": "Rock_Shale"
    },
    {
      "x": 13,
      "y": 12,
      "z": -7,
      "name": "Rock_Shale"
    },
    {
      "x": 13,
      "y": 13,
      "z": -7,
      "name": "Rock_Shale"
    },
    {
      "x": 13,
      "y": 14,
      "z": -7,
      "name": "Rock_Shale"
    },
    {
      "x": 13,
      "y": 10,
      "z": -6,
      "name": "Rock_Shale"
    },
    {
      "x": 13,
      "y": 11,
      "z": -6,
      "name": "Rock_Shale"
    },
    {
      "x": 13,
      "y": 12,
      "z": -6,
      "name": "Rock_Shale"
    },
    {
      "x": 13,
      "y": 13,
      "z": -6,
      "name": "Rock_Shale"
    },
    {
      "x": 13,
      "y": 11,
      "z": -5,
      "name": "Rock_Shale"
    },
    {
      "x": 13,
      "y": 12,
      "z": -5,
      "name": "Rock_Shale"
    },
    {
      "x": 13,
      "y": 13,
      "z": -5,
      "name": "Rock_Shale"
    },
    {
      "x": 13,
      "y": 11,
      "z": -4,
      "name": "Rock_Shale"
    },
    {
      "x": 13,
      "y": 12,
      "z": -4,
      "name": "Rock_Shale"
    },
    {
      "x": 13,
      "y": 13,
      "z": -4,
      "name": "Rock_Shale"
    },
    {
      "x": 13,
      "y": 29,
      "z": -3,
      "name": "Soil_Dirt_Cold"
    },
    {
      "x": 13,
      "y": 30,
      "z": -3,
      "name": "Soil_Dirt_Cold"
    },
    {
      "x": 13,
      "y": 31,
      "z": -3,
      "name": "Soil_Grass_Cold"
    },
    {
      "x": 13,
      "y": 27,
      "z": -2,
      "name": "Rock_Shale"
    },
    {
      "x": 13,
      "y": 28,
      "z": -2,
      "name": "Rock_Shale"
    },
    {
      "x": 13,
      "y": 29,
      "z": -2,
      "name": "Soil_Dirt_Cold"
    },
    {
      "x": 13,
      "y": 30,
      "z": -2,
      "name": "Soil_Dirt_Cold"
    },
    {
      "x": 13,
      "y": 31,
      "z": -2,
      "name": "Soil_Dirt_Cold"
    },
    {
      "x": 13,
      "y": 32,
      "z": -2,
      "name": "Soil_Grass_Cold"
    },
    {
      "x": 13,
      "y": 33,
      "z": -2,
      "name": "Plant_Fern_Winter"
    },
    {
      "x": 13,
      "y": 27,
      "z": -1,
      "name": "Rock_Shale"
    },
    {
      "x": 13,
      "y": 28,
      "z": -1,
      "name": "Rock_Shale"
    },
    {
      "x": 13,
      "y": 29,
      "z": -1,
      "name": "Soil_Dirt_Cold"
    },
    {
      "x": 13,
      "y": 30,
      "z": -1,
      "name": "Soil_Dirt_Cold"
    },
    {
      "x": 13,
      "y": 31,
      "z": -1,
      "name": "Soil_Dirt_Cold"
    },
    {
      "x": 13,
      "y": 32,
      "z": -1,
      "name": "Soil_Dirt_Cold"
    },
    {
      "x": 13,
      "y": 33,
      "z": -1,
      "name": "Soil_Grass_Cold"
    },
    {
      "x": 13,
      "y": 34,
      "z": -1,
      "name": "Plant_Fern_Forest"
    },
    {
      "x": 13,
      "y": 28,
      "z": 0,
      "name": "Rock_Shale"
    },
    {
      "x": 13,
      "y": 29,
      "z": 0,
      "name": "Soil_Dirt_Cold"
    },
    {
      "x": 13,
      "y": 30,
      "z": 0,
      "name": "Soil_Dirt_Cold"
    },
    {
      "x": 13,
      "y": 31,
      "z": 0,
      "name": "Soil_Dirt_Cold"
    },
    {
      "x": 13,
      "y": 32,
      "z": 0,
      "name": "Soil_Dirt_Cold"
    },
    {
      "x": 13,
      "y": 33,
      "z": 0,
      "name": "Soil_Dirt_Poisoned"
    },
    {
      "x": 13,
      "y": 34,
      "z": 0,
      "name": "*Plant_Crop_Berry_Winter_Block_State_Definitions_StageFinal",
      "components": {
        "Components": {
          "FarmingBlock": {}
        }
      }
    },
    {
      "x": 13,
      "y": 28,
      "z": 1,
      "name": "Rock_Shale"
    },
    {
      "x": 13,
      "y": 29,
      "z": 1,
      "name": "Soil_Dirt_Cold"
    },
    {
      "x": 13,
      "y": 30,
      "z": 1,
      "name": "Soil_Dirt_Poisoned"
    },
    {
      "x": 13,
      "y": 31,
      "z": 1,
      "name": "Soil_Dirt_Poisoned"
    },
    {
      "x": 13,
      "y": 32,
      "z": 1,
      "name": "Soil_Dirt_Poisoned"
    },
    {
      "x": 13,
      "y": 33,
      "z": 1,
      "name": "Soil_Dirt_Poisoned"
    },
    {
      "x": 13,
      "y": 34,
      "z": 1,
      "name": "*Plant_Crop_Berry_Winter_Block_State_Definitions_StageFinal",
      "components": {
        "Components": {
          "FarmingBlock": {}
        }
      }
    },
    {
      "x": 13,
      "y": 29,
      "z": 2,
      "name": "Soil_Dirt_Poisoned"
    },
    {
      "x": 13,
      "y": 30,
      "z": 2,
      "name": "Soil_Dirt_Poisoned"
    },
    {
      "x": 13,
      "y": 31,
      "z": 2,
      "name": "Soil_Dirt_Poisoned"
    },
    {
      "x": 13,
      "y": 32,
      "z": 2,
      "name": "Soil_Dirt_Poisoned"
    },
    {
      "x": 13,
      "y": 10,
      "z": 3,
      "name": "Rock_Shale"
    },
    {
      "x": 13,
      "y": 29,
      "z": 3,
      "name": "Rock_Shale"
    },
    {
      "x": 13,
      "y": 30,
      "z": 3,
      "name": "Soil_Dirt_Poisoned"
    },
    {
      "x": 13,
      "y": 31,
      "z": 3,
      "name": "Soil_Dirt_Poisoned"
    },
    {
      "x": 13,
      "y": 10,
      "z": 4,
      "name": "Rock_Shale"
    },
    {
      "x": 14,
      "y": 14,
      "z": -9,
      "name": "Rock_Shale"
    },
    {
      "x": 14,
      "y": 15,
      "z": -9,
      "name": "Rock_Shale"
    },
    {
      "x": 14,
      "y": 12,
      "z": -8,
      "name": "Rock_Shale"
    },
    {
      "x": 14,
      "y": 13,
      "z": -8,
      "name": "Rock_Shale"
    },
    {
      "x": 14,
      "y": 14,
      "z": -8,
      "name": "Rock_Shale"
    },
    {
      "x": 14,
      "y": 23,
      "z": -8,
      "name": "Rock_Shale"
    },
    {
      "x": 14,
      "y": 24,
      "z": -8,
      "name": "Rock_Shale"
    },
    {
      "x": 14,
      "y": 25,
      "z": -8,
      "name": "Rock_Shale"
    },
    {
      "x": 14,
      "y": 10,
      "z": -7,
      "name": "Rock_Shale"
    },
    {
      "x": 14,
      "y": 11,
      "z": -7,
      "name": "Rock_Shale"
    },
    {
      "x": 14,
      "y": 12,
      "z": -7,
      "name": "Rock_Shale"
    },
    {
      "x": 14,
      "y": 13,
      "z": -7,
      "name": "Rock_Shale"
    },
    {
      "x": 14,
      "y": 25,
      "z": -7,
      "name": "Rock_Shale"
    },
    {
      "x": 14,
      "y": 26,
      "z": -7,
      "name": "Rock_Shale"
    },
    {
      "x": 14,
      "y": 10,
      "z": -6,
      "name": "Rock_Shale"
    },
    {
      "x": 14,
      "y": 11,
      "z": -6,
      "name": "Rock_Shale"
    },
    {
      "x": 14,
      "y": 12,
      "z": -6,
      "name": "Rock_Shale"
    },
    {
      "x": 14,
      "y": 13,
      "z": -6,
      "name": "Rock_Shale"
    },
    {
      "x": 14,
      "y": 10,
      "z": -5,
      "name": "Rock_Shale"
    },
    {
      "x": 14,
      "y": 11,
      "z": -5,
      "name": "Rock_Shale"
    },
    {
      "x": 14,
      "y": 12,
      "z": -5,
      "name": "Rock_Shale"
    },
    {
      "x": 14,
      "y": 13,
      "z": -5,
      "name": "Rock_Shale"
    },
    {
      "x": 14,
      "y": 10,
      "z": -4,
      "name": "Rock_Shale"
    },
    {
      "x": 14,
      "y": 11,
      "z": -4,
      "name": "Rock_Shale"
    },
    {
      "x": 14,
      "y": 12,
      "z": -4,
      "name": "Rock_Shale"
    },
    {
      "x": 14,
      "y": 13,
      "z": -4,
      "name": "Rock_Shale"
    },
    {
      "x": 14,
      "y": 30,
      "z": -4,
      "name": "Soil_Dirt_Cold"
    },
    {
      "x": 14,
      "y": 31,
      "z": -4,
      "name": "Soil_Grass_Cold"
    },
    {
      "x": 14,
      "y": 32,
      "z": -4,
      "name": "Plant_Grass_Winter"
    },
    {
      "x": 14,
      "y": 11,
      "z": -3,
      "name": "Rock_Shale"
    },
    {
      "x": 14,
      "y": 12,
      "z": -3,
      "name": "Rock_Shale"
    },
    {
      "x": 14,
      "y": 28,
      "z": -3,
      "name": "Rock_Shale"
    },
    {
      "x": 14,
      "y": 29,
      "z": -3,
      "name": "Soil_Dirt_Cold"
    },
    {
      "x": 14,
      "y": 30,
      "z": -3,
      "name": "Soil_Dirt_Cold"
    },
    {
      "x": 14,
      "y": 31,
      "z": -3,
      "name": "Soil_Grass_Cold"
    },
    {
      "x": 14,
      "y": 32,
      "z": -3,
      "name": "Plant_Grass_Winter"
    },
    {
      "x": 14,
      "y": 27,
      "z": -2,
      "name": "Rock_Shale"
    },
    {
      "x": 14,
      "y": 28,
      "z": -2,
      "name": "Rock_Shale"
    },
    {
      "x": 14,
      "y": 29,
      "z": -2,
      "name": "Soil_Dirt_Cold"
    },
    {
      "x": 14,
      "y": 30,
      "z": -2,
      "name": "Soil_Dirt_Cold"
    },
    {
      "x": 14,
      "y": 31,
      "z": -2,
      "name": "Soil_Dirt_Cold"
    },
    {
      "x": 14,
      "y": 32,
      "z": -2,
      "name": "Soil_Grass_Cold"
    },
    {
      "x": 14,
      "y": 33,
      "z": -2,
      "name": "Plant_Fern_Forest"
    },
    {
      "x": 14,
      "y": 27,
      "z": -1,
      "name": "Rock_Shale"
    },
    {
      "x": 14,
      "y": 28,
      "z": -1,
      "name": "Rock_Shale"
    },
    {
      "x": 14,
      "y": 29,
      "z": -1,
      "name": "Soil_Dirt_Cold"
    },
    {
      "x": 14,
      "y": 30,
      "z": -1,
      "name": "Soil_Dirt_Cold"
    },
    {
      "x": 14,
      "y": 31,
      "z": -1,
      "name": "Soil_Dirt_Cold"
    },
    {
      "x": 14,
      "y": 32,
      "z": -1,
      "name": "Soil_Dirt_Cold"
    },
    {
      "x": 14,
      "y": 33,
      "z": -1,
      "name": "Soil_Grass_Cold"
    },
    {
      "x": 14,
      "y": 34,
      "z": -1,
      "name": "Plant_Grass_Winter_Tall"
    },
    {
      "x": 14,
      "y": 35,
      "z": -1,
      "name": "Plant_Grass_Winter_Tall",
      "filler": 1024
    },
    {
      "x": 14,
      "y": 27,
      "z": 0,
      "name": "Rock_Shale"
    },
    {
      "x": 14,
      "y": 28,
      "z": 0,
      "name": "Rock_Shale"
    },
    {
      "x": 14,
      "y": 29,
      "z": 0,
      "name": "Soil_Dirt_Cold"
    },
    {
      "x": 14,
      "y": 30,
      "z": 0,
      "name": "Soil_Dirt_Cold"
    },
    {
      "x": 14,
      "y": 31,
      "z": 0,
      "name": "Soil_Dirt_Cold"
    },
    {
      "x": 14,
      "y": 32,
      "z": 0,
      "name": "Soil_Dirt_Cold"
    },
    {
      "x": 14,
      "y": 33,
      "z": 0,
      "name": "Soil_Dirt_Poisoned"
    },
    {
      "x": 14,
      "y": 34,
      "z": 0,
      "name": "*Plant_Crop_Berry_Winter_Block_State_Definitions_StageFinal",
      "components": {
        "Components": {
          "FarmingBlock": {}
        }
      }
    },
    {
      "x": 14,
      "y": 28,
      "z": 1,
      "name": "Rock_Shale"
    },
    {
      "x": 14,
      "y": 29,
      "z": 1,
      "name": "Soil_Dirt_Cold"
    },
    {
      "x": 14,
      "y": 30,
      "z": 1,
      "name": "Soil_Dirt_Poisoned"
    },
    {
      "x": 14,
      "y": 31,
      "z": 1,
      "name": "Soil_Dirt_Poisoned"
    },
    {
      "x": 14,
      "y": 32,
      "z": 1,
      "name": "Soil_Roots_Poisoned"
    },
    {
      "x": 14,
      "y": 33,
      "z": 1,
      "name": "Soil_Roots_Poisoned"
    },
    {
      "x": 14,
      "y": 29,
      "z": 2,
      "name": "Rock_Shale"
    },
    {
      "x": 14,
      "y": 30,
      "z": 2,
      "name": "Soil_Dirt_Poisoned"
    },
    {
      "x": 14,
      "y": 31,
      "z": 2,
      "name": "Soil_Dirt_Poisoned"
    },
    {
      "x": 14,
      "y": 32,
      "z": 2,
      "name": "Soil_Roots_Poisoned"
    },
    {
      "x": 14,
      "y": 33,
      "z": 2,
      "name": "Soil_Roots_Poisoned"
    },
    {
      "x": 14,
      "y": 29,
      "z": 3,
      "name": "Rock_Shale"
    },
    {
      "x": 14,
      "y": 30,
      "z": 3,
      "name": "Soil_Dirt_Poisoned"
    },
    {
      "x": 14,
      "y": 31,
      "z": 3,
      "name": "Soil_Roots_Poisoned"
    },
    {
      "x": 14,
      "y": 32,
      "z": 3,
      "name": "Soil_Roots_Poisoned"
    },
    {
      "x": 15,
      "y": 13,
      "z": -7,
      "name": "Rock_Shale"
    },
    {
      "x": 15,
      "y": 11,
      "z": -6,
      "name": "Rock_Shale"
    },
    {
      "x": 15,
      "y": 12,
      "z": -6,
      "name": "Rock_Shale"
    },
    {
      "x": 15,
      "y": 13,
      "z": -6,
      "name": "Rock_Shale"
    },
    {
      "x": 15,
      "y": 10,
      "z": -5,
      "name": "Rock_Shale"
    },
    {
      "x": 15,
      "y": 11,
      "z": -5,
      "name": "Rock_Shale"
    },
    {
      "x": 15,
      "y": 12,
      "z": -5,
      "name": "Rock_Shale"
    },
    {
      "x": 15,
      "y": 13,
      "z": -5,
      "name": "Rock_Shale"
    },
    {
      "x": 15,
      "y": 10,
      "z": -4,
      "name": "Rock_Shale"
    },
    {
      "x": 15,
      "y": 11,
      "z": -4,
      "name": "Rock_Shale"
    },
    {
      "x": 15,
      "y": 12,
      "z": -4,
      "name": "Rock_Shale"
    },
    {
      "x": 15,
      "y": 13,
      "z": -4,
      "name": "Rock_Shale"
    },
    {
      "x": 15,
      "y": 29,
      "z": -4,
      "name": "Soil_Dirt_Cold"
    },
    {
      "x": 15,
      "y": 30,
      "z": -4,
      "name": "Soil_Dirt_Cold"
    },
    {
      "x": 15,
      "y": 31,
      "z": -4,
      "name": "Soil_Grass_Cold"
    },
    {
      "x": 15,
      "y": 32,
      "z": -4,
      "name": "Plant_Fern_Winter"
    },
    {
      "x": 15,
      "y": 11,
      "z": -3,
      "name": "Rock_Shale"
    },
    {
      "x": 15,
      "y": 12,
      "z": -3,
      "name": "Rock_Shale"
    },
    {
      "x": 15,
      "y": 13,
      "z": -3,
      "name": "Rock_Shale"
    },
    {
      "x": 15,
      "y": 27,
      "z": -3,
      "name": "Rock_Shale"
    },
    {
      "x": 15,
      "y": 28,
      "z": -3,
      "name": "Rock_Shale"
    },
    {
      "x": 15,
      "y": 29,
      "z": -3,
      "name": "Soil_Dirt_Cold"
    },
    {
      "x": 15,
      "y": 30,
      "z": -3,
      "name": "Soil_Dirt_Cold"
    },
    {
      "x": 15,
      "y": 31,
      "z": -3,
      "name": "Soil_Grass_Cold"
    },
    {
      "x": 15,
      "y": 32,
      "z": -3,
      "name": "Plant_Grass_Winter"
    },
    {
      "x": 15,
      "y": 27,
      "z": -2,
      "name": "Rock_Shale"
    },
    {
      "x": 15,
      "y": 28,
      "z": -2,
      "name": "Soil_Dirt_Cold"
    },
    {
      "x": 15,
      "y": 29,
      "z": -2,
      "name": "Soil_Dirt_Cold"
    },
    {
      "x": 15,
      "y": 30,
      "z": -2,
      "name": "Soil_Dirt_Cold"
    },
    {
      "x": 15,
      "y": 31,
      "z": -2,
      "name": "Soil_Dirt_Cold"
    },
    {
      "x": 15,
      "y": 32,
      "z": -2,
      "name": "Soil_Grass_Cold"
    },
    {
      "x": 15,
      "y": 27,
      "z": -1,
      "name": "Rock_Shale"
    },
    {
      "x": 15,
      "y": 28,
      "z": -1,
      "name": "Rock_Shale"
    },
    {
      "x": 15,
      "y": 29,
      "z": -1,
      "name": "Soil_Dirt_Cold"
    },
    {
      "x": 15,
      "y": 30,
      "z": -1,
      "name": "Soil_Dirt_Cold"
    },
    {
      "x": 15,
      "y": 31,
      "z": -1,
      "name": "Soil_Dirt_Cold"
    },
    {
      "x": 15,
      "y": 32,
      "z": -1,
      "name": "Soil_Dirt_Cold"
    },
    {
      "x": 15,
      "y": 33,
      "z": -1,
      "name": "Soil_Grass_Cold"
    },
    {
      "x": 15,
      "y": 34,
      "z": -1,
      "name": "Plant_Grass_Winter_Tall"
    },
    {
      "x": 15,
      "y": 35,
      "z": -1,
      "name": "Plant_Grass_Winter_Tall",
      "filler": 1024
    },
    {
      "x": 15,
      "y": 27,
      "z": 0,
      "name": "Rock_Shale"
    },
    {
      "x": 15,
      "y": 28,
      "z": 0,
      "name": "Rock_Shale"
    },
    {
      "x": 15,
      "y": 29,
      "z": 0,
      "name": "Soil_Dirt_Cold"
    },
    {
      "x": 15,
      "y": 30,
      "z": 0,
      "name": "Soil_Dirt_Cold"
    },
    {
      "x": 15,
      "y": 31,
      "z": 0,
      "name": "Soil_Dirt_Cold"
    },
    {
      "x": 15,
      "y": 32,
      "z": 0,
      "name": "Soil_Dirt_Cold"
    },
    {
      "x": 15,
      "y": 33,
      "z": 0,
      "name": "Soil_Roots_Poisoned"
    },
    {
      "x": 15,
      "y": 29,
      "z": 1,
      "name": "Rock_Shale"
    },
    {
      "x": 15,
      "y": 30,
      "z": 1,
      "name": "Soil_Dirt_Cold"
    },
    {
      "x": 15,
      "y": 31,
      "z": 1,
      "name": "Soil_Dirt_Cold"
    },
    {
      "x": 15,
      "y": 32,
      "z": 1,
      "name": "Soil_Roots_Poisoned"
    },
    {
      "x": 15,
      "y": 33,
      "z": 1,
      "name": "Soil_Roots_Poisoned"
    },
    {
      "x": 15,
      "y": 29,
      "z": 2,
      "name": "Rock_Shale"
    },
    {
      "x": 15,
      "y": 30,
      "z": 2,
      "name": "Soil_Roots_Poisoned"
    },
    {
      "x": 15,
      "y": 31,
      "z": 2,
      "name": "Soil_Roots_Poisoned"
    },
    {
      "x": 15,
      "y": 32,
      "z": 2,
      "name": "Soil_Roots_Poisoned"
    },
    {
      "x": 15,
      "y": 33,
      "z": 2,
      "name": "Soil_Roots_Poisoned"
    },
    {
      "x": 15,
      "y": 29,
      "z": 3,
      "name": "Soil_Roots_Poisoned"
    },
    {
      "x": 15,
      "y": 30,
      "z": 3,
      "name": "Soil_Roots_Poisoned"
    },
    {
      "x": 15,
      "y": 31,
      "z": 3,
      "name": "Soil_Roots_Poisoned"
    },
    {
      "x": 15,
      "y": 32,
      "z": 3,
      "name": "Soil_Roots_Poisoned"
    },
    {
      "x": 15,
      "y": 33,
      "z": 3,
      "name": "Plant_Crop_Mushroom_Glowing_Purple"
    },
    {
      "x": 15,
      "y": 29,
      "z": 4,
      "name": "Soil_Roots_Poisoned"
    },
    {
      "x": 15,
      "y": 30,
      "z": 4,
      "name": "Soil_Roots_Poisoned"
    },
    {
      "x": 16,
      "y": 12,
      "z": -6,
      "name": "Rock_Shale"
    },
    {
      "x": 16,
      "y": 13,
      "z": -6,
      "name": "Rock_Shale"
    },
    {
      "x": 16,
      "y": 11,
      "z": -5,
      "name": "Rock_Shale"
    },
    {
      "x": 16,
      "y": 12,
      "z": -5,
      "name": "Rock_Shale"
    },
    {
      "x": 16,
      "y": 13,
      "z": -5,
      "name": "Rock_Shale"
    },
    {
      "x": 16,
      "y": 11,
      "z": -4,
      "name": "Rock_Shale"
    },
    {
      "x": 16,
      "y": 12,
      "z": -4,
      "name": "Rock_Shale"
    },
    {
      "x": 16,
      "y": 13,
      "z": -4,
      "name": "Rock_Shale"
    },
    {
      "x": 16,
      "y": 14,
      "z": -4,
      "name": "Rock_Shale"
    },
    {
      "x": 16,
      "y": 28,
      "z": -4,
      "name": "Rock_Shale"
    },
    {
      "x": 16,
      "y": 29,
      "z": -4,
      "name": "Soil_Dirt_Cold"
    },
    {
      "x": 16,
      "y": 30,
      "z": -4,
      "name": "Soil_Dirt_Cold"
    },
    {
      "x": 16,
      "y": 11,
      "z": -3,
      "name": "Rock_Shale"
    },
    {
      "x": 16,
      "y": 12,
      "z": -3,
      "name": "Rock_Shale"
    },
    {
      "x": 16,
      "y": 13,
      "z": -3,
      "name": "Rock_Shale"
    },
    {
      "x": 16,
      "y": 14,
      "z": -3,
      "name": "Rock_Shale"
    },
    {
      "x": 16,
      "y": 27,
      "z": -3,
      "name": "Rock_Shale"
    },
    {
      "x": 16,
      "y": 28,
      "z": -3,
      "name": "Rock_Shale"
    },
    {
      "x": 16,
      "y": 29,
      "z": -3,
      "name": "Soil_Dirt_Cold"
    },
    {
      "x": 16,
      "y": 30,
      "z": -3,
      "name": "Soil_Dirt_Cold"
    },
    {
      "x": 16,
      "y": 31,
      "z": -3,
      "name": "Soil_Grass_Cold"
    },
    {
      "x": 16,
      "y": 32,
      "z": -3,
      "name": "Plant_Grass_Winter_Tall"
    },
    {
      "x": 16,
      "y": 33,
      "z": -3,
      "name": "Plant_Grass_Winter_Tall",
      "filler": 1024
    },
    {
      "x": 16,
      "y": 27,
      "z": -2,
      "name": "Rock_Shale"
    },
    {
      "x": 16,
      "y": 28,
      "z": -2,
      "name": "Rock_Shale"
    },
    {
      "x": 16,
      "y": 29,
      "z": -2,
      "name": "Soil_Dirt_Cold"
    },
    {
      "x": 16,
      "y": 30,
      "z": -2,
      "name": "Soil_Dirt_Cold"
    },
    {
      "x": 16,
      "y": 31,
      "z": -2,
      "name": "Soil_Dirt_Cold"
    },
    {
      "x": 16,
      "y": 32,
      "z": -2,
      "name": "Soil_Grass_Cold"
    },
    {
      "x": 16,
      "y": 33,
      "z": -2,
      "name": "Plant_Grass_Winter"
    },
    {
      "x": 16,
      "y": 27,
      "z": -1,
      "name": "Rock_Shale"
    },
    {
      "x": 16,
      "y": 28,
      "z": -1,
      "name": "Rock_Shale"
    },
    {
      "x": 16,
      "y": 29,
      "z": -1,
      "name": "Soil_Dirt_Cold"
    },
    {
      "x": 16,
      "y": 30,
      "z": -1,
      "name": "Soil_Dirt_Cold"
    },
    {
      "x": 16,
      "y": 31,
      "z": -1,
      "name": "Soil_Dirt_Cold"
    },
    {
      "x": 16,
      "y": 32,
      "z": -1,
      "name": "Soil_Grass_Cold"
    },
    {
      "x": 16,
      "y": 27,
      "z": 0,
      "name": "Rock_Shale"
    },
    {
      "x": 16,
      "y": 28,
      "z": 0,
      "name": "Rock_Shale"
    },
    {
      "x": 16,
      "y": 29,
      "z": 0,
      "name": "Rock_Shale"
    },
    {
      "x": 16,
      "y": 30,
      "z": 0,
      "name": "Soil_Dirt_Cold"
    },
    {
      "x": 16,
      "y": 31,
      "z": 0,
      "name": "Soil_Dirt_Cold"
    },
    {
      "x": 16,
      "y": 32,
      "z": 0,
      "name": "Soil_Dirt_Cold"
    },
    {
      "x": 16,
      "y": 33,
      "z": 0,
      "name": "Soil_Grass_Cold"
    },
    {
      "x": 16,
      "y": 28,
      "z": 1,
      "name": "Rock_Shale"
    },
    {
      "x": 16,
      "y": 29,
      "z": 1,
      "name": "Rock_Shale"
    },
    {
      "x": 16,
      "y": 30,
      "z": 1,
      "name": "Soil_Dirt_Cold"
    },
    {
      "x": 16,
      "y": 31,
      "z": 1,
      "name": "Soil_Roots_Poisoned"
    },
    {
      "x": 16,
      "y": 32,
      "z": 1,
      "name": "Soil_Roots_Poisoned"
    },
    {
      "x": 16,
      "y": 33,
      "z": 1,
      "name": "Plant_Crop_Mushroom_Glowing_Purple"
    },
    {
      "x": 16,
      "y": 29,
      "z": 2,
      "name": "Soil_Roots_Poisoned"
    },
    {
      "x": 16,
      "y": 30,
      "z": 2,
      "name": "Soil_Roots_Poisoned"
    },
    {
      "x": 16,
      "y": 31,
      "z": 2,
      "name": "Soil_Roots_Poisoned"
    },
    {
      "x": 16,
      "y": 32,
      "z": 2,
      "name": "Soil_Roots_Poisoned"
    },
    {
      "x": 16,
      "y": 33,
      "z": 2,
      "name": "Plant_Flower_Bushy_Poisoned"
    },
    {
      "x": 16,
      "y": 10,
      "z": 3,
      "name": "Rock_Shale"
    },
    {
      "x": 16,
      "y": 29,
      "z": 3,
      "name": "Soil_Roots_Poisoned"
    },
    {
      "x": 16,
      "y": 30,
      "z": 3,
      "name": "Soil_Roots_Poisoned"
    },
    {
      "x": 16,
      "y": 31,
      "z": 3,
      "name": "Soil_Roots_Poisoned"
    },
    {
      "x": 16,
      "y": 32,
      "z": 3,
      "name": "Soil_Roots_Poisoned"
    },
    {
      "x": 16,
      "y": 11,
      "z": 4,
      "name": "Rock_Shale"
    },
    {
      "x": 16,
      "y": 28,
      "z": 4,
      "name": "Soil_Roots_Poisoned"
    },
    {
      "x": 16,
      "y": 29,
      "z": 4,
      "name": "Soil_Roots_Poisoned"
    },
    {
      "x": 17,
      "y": 12,
      "z": -5,
      "name": "Rock_Shale"
    },
    {
      "x": 17,
      "y": 11,
      "z": -4,
      "name": "Rock_Shale"
    },
    {
      "x": 17,
      "y": 12,
      "z": -4,
      "name": "Rock_Shale"
    },
    {
      "x": 17,
      "y": 13,
      "z": -4,
      "name": "Rock_Shale"
    },
    {
      "x": 17,
      "y": 28,
      "z": -4,
      "name": "Rock_Shale"
    },
    {
      "x": 17,
      "y": 29,
      "z": -4,
      "name": "Rock_Shale"
    },
    {
      "x": 17,
      "y": 30,
      "z": -4,
      "name": "Soil_Dirt_Cold"
    },
    {
      "x": 17,
      "y": 31,
      "z": -4,
      "name": "Soil_Grass_Cold"
    },
    {
      "x": 17,
      "y": 11,
      "z": -3,
      "name": "Rock_Shale"
    },
    {
      "x": 17,
      "y": 12,
      "z": -3,
      "name": "Rock_Shale"
    },
    {
      "x": 17,
      "y": 13,
      "z": -3,
      "name": "Rock_Shale"
    },
    {
      "x": 17,
      "y": 14,
      "z": -3,
      "name": "Rock_Shale"
    },
    {
      "x": 17,
      "y": 15,
      "z": -3,
      "name": "Rock_Shale"
    },
    {
      "x": 17,
      "y": 27,
      "z": -3,
      "name": "Rock_Shale"
    },
    {
      "x": 17,
      "y": 28,
      "z": -3,
      "name": "Rock_Shale"
    },
    {
      "x": 17,
      "y": 29,
      "z": -3,
      "name": "Soil_Dirt_Cold"
    },
    {
      "x": 17,
      "y": 30,
      "z": -3,
      "name": "Soil_Dirt_Cold"
    },
    {
      "x": 17,
      "y": 31,
      "z": -3,
      "name": "Soil_Grass_Cold"
    },
    {
      "x": 17,
      "y": 12,
      "z": -2,
      "name": "Rock_Shale"
    },
    {
      "x": 17,
      "y": 13,
      "z": -2,
      "name": "Rock_Shale"
    },
    {
      "x": 17,
      "y": 14,
      "z": -2,
      "name": "Rock_Shale"
    },
    {
      "x": 17,
      "y": 15,
      "z": -2,
      "name": "Rock_Shale"
    },
    {
      "x": 17,
      "y": 27,
      "z": -2,
      "name": "Rock_Shale"
    },
    {
      "x": 17,
      "y": 28,
      "z": -2,
      "name": "Rock_Shale"
    },
    {
      "x": 17,
      "y": 29,
      "z": -2,
      "name": "Soil_Dirt_Cold"
    },
    {
      "x": 17,
      "y": 30,
      "z": -2,
      "name": "Soil_Dirt_Cold"
    },
    {
      "x": 17,
      "y": 31,
      "z": -2,
      "name": "Soil_Roots_Poisoned"
    },
    {
      "x": 17,
      "y": 32,
      "z": -2,
      "name": "Soil_Roots_Poisoned"
    },
    {
      "x": 17,
      "y": 15,
      "z": -1,
      "name": "Rock_Shale"
    },
    {
      "x": 17,
      "y": 26,
      "z": -1,
      "name": "Rock_Shale"
    },
    {
      "x": 17,
      "y": 27,
      "z": -1,
      "name": "Rock_Shale"
    },
    {
      "x": 17,
      "y": 28,
      "z": -1,
      "name": "Rock_Shale"
    },
    {
      "x": 17,
      "y": 29,
      "z": -1,
      "name": "Soil_Dirt_Cold"
    },
    {
      "x": 17,
      "y": 30,
      "z": -1,
      "name": "Soil_Roots_Poisoned"
    },
    {
      "x": 17,
      "y": 31,
      "z": -1,
      "name": "Soil_Roots_Poisoned"
    },
    {
      "x": 17,
      "y": 32,
      "z": -1,
      "name": "Soil_Roots_Poisoned"
    },
    {
      "x": 17,
      "y": 33,
      "z": -1,
      "name": "Plant_Crop_Mushroom_Glowing_Purple"
    },
    {
      "x": 17,
      "y": 28,
      "z": 0,
      "name": "Rock_Shale"
    },
    {
      "x": 17,
      "y": 29,
      "z": 0,
      "name": "Soil_Dirt_Cold"
    },
    {
      "x": 17,
      "y": 30,
      "z": 0,
      "name": "Soil_Roots_Poisoned"
    },
    {
      "x": 17,
      "y": 31,
      "z": 0,
      "name": "Soil_Roots_Poisoned"
    },
    {
      "x": 17,
      "y": 32,
      "z": 0,
      "name": "Soil_Roots_Poisoned"
    },
    {
      "x": 17,
      "y": 33,
      "z": 0,
      "name": "Plant_Flower_Bushy_Poisoned"
    },
    {
      "x": 17,
      "y": 27,
      "z": 1,
      "name": "Rock_Shale"
    },
    {
      "x": 17,
      "y": 28,
      "z": 1,
      "name": "Rock_Shale"
    },
    {
      "x": 17,
      "y": 29,
      "z": 1,
      "name": "Soil_Dirt_Cold"
    },
    {
      "x": 17,
      "y": 30,
      "z": 1,
      "name": "Soil_Dirt_Cold"
    },
    {
      "x": 17,
      "y": 31,
      "z": 1,
      "name": "Soil_Roots_Poisoned"
    },
    {
      "x": 17,
      "y": 32,
      "z": 1,
      "name": "Soil_Roots_Poisoned"
    },
    {
      "x": 17,
      "y": 33,
      "z": 1,
      "name": "Plant_Crop_Mushroom_Glowing_Purple"
    },
    {
      "x": 17,
      "y": 27,
      "z": 2,
      "name": "Rock_Shale"
    },
    {
      "x": 17,
      "y": 28,
      "z": 2,
      "name": "Soil_Dirt_Cold"
    },
    {
      "x": 17,
      "y": 29,
      "z": 2,
      "name": "Soil_Dirt_Cold"
    },
    {
      "x": 17,
      "y": 30,
      "z": 2,
      "name": "Soil_Roots_Poisoned"
    },
    {
      "x": 17,
      "y": 31,
      "z": 2,
      "name": "Soil_Roots_Poisoned"
    },
    {
      "x": 17,
      "y": 32,
      "z": 2,
      "name": "Soil_Roots_Poisoned"
    },
    {
      "x": 17,
      "y": 33,
      "z": 2,
      "name": "Plant_Flower_Bushy_Poisoned"
    },
    {
      "x": 17,
      "y": 27,
      "z": 3,
      "name": "Rock_Shale"
    },
    {
      "x": 17,
      "y": 28,
      "z": 3,
      "name": "Soil_Roots_Poisoned"
    },
    {
      "x": 17,
      "y": 29,
      "z": 3,
      "name": "Soil_Roots_Poisoned"
    },
    {
      "x": 17,
      "y": 30,
      "z": 3,
      "name": "Soil_Roots_Poisoned"
    },
    {
      "x": 17,
      "y": 31,
      "z": 3,
      "name": "Soil_Roots_Poisoned"
    },
    {
      "x": 17,
      "y": 32,
      "z": 3,
      "name": "Soil_Roots_Poisoned"
    },
    {
      "x": 17,
      "y": 11,
      "z": 4,
      "name": "Rock_Shale"
    },
    {
      "x": 17,
      "y": 12,
      "z": 4,
      "name": "Rock_Shale"
    },
    {
      "x": 17,
      "y": 13,
      "z": 4,
      "name": "Rock_Shale"
    },
    {
      "x": 17,
      "y": 28,
      "z": 4,
      "name": "Soil_Roots_Poisoned"
    },
    {
      "x": 17,
      "y": 29,
      "z": 4,
      "name": "Soil_Roots_Poisoned"
    },
    {
      "x": 17,
      "y": 30,
      "z": 4,
      "name": "Soil_Roots_Poisoned"
    },
    {
      "x": 17,
      "y": 12,
      "z": 5,
      "name": "Rock_Shale"
    },
    {
      "x": 17,
      "y": 13,
      "z": 5,
      "name": "Rock_Shale"
    },
    {
      "x": 17,
      "y": 28,
      "z": 5,
      "name": "Soil_Roots_Poisoned"
    },
    {
      "x": 17,
      "y": 29,
      "z": 5,
      "name": "Soil_Roots_Poisoned"
    },
    {
      "x": 17,
      "y": 14,
      "z": 6,
      "name": "Rock_Shale"
    },
    {
      "x": 17,
      "y": 15,
      "z": 7,
      "name": "Rock_Shale"
    },
    {
      "x": 18,
      "y": 28,
      "z": -4,
      "name": "Rock_Shale"
    },
    {
      "x": 18,
      "y": 29,
      "z": -4,
      "name": "Rock_Shale"
    },
    {
      "x": 18,
      "y": 30,
      "z": -4,
      "name": "Soil_Dirt_Cold"
    },
    {
      "x": 18,
      "y": 31,
      "z": -4,
      "name": "Soil_Grass_Cold"
    },
    {
      "x": 18,
      "y": 13,
      "z": -3,
      "name": "Rock_Shale"
    },
    {
      "x": 18,
      "y": 14,
      "z": -3,
      "name": "Rock_Shale"
    },
    {
      "x": 18,
      "y": 27,
      "z": -3,
      "name": "Rock_Shale"
    },
    {
      "x": 18,
      "y": 28,
      "z": -3,
      "name": "Rock_Shale"
    },
    {
      "x": 18,
      "y": 29,
      "z": -3,
      "name": "Soil_Dirt_Cold"
    },
    {
      "x": 18,
      "y": 30,
      "z": -3,
      "name": "Soil_Roots_Poisoned"
    },
    {
      "x": 18,
      "y": 31,
      "z": -3,
      "name": "Soil_Roots_Poisoned"
    },
    {
      "x": 18,
      "y": 12,
      "z": -2,
      "name": "Rock_Shale"
    },
    {
      "x": 18,
      "y": 13,
      "z": -2,
      "name": "Rock_Shale"
    },
    {
      "x": 18,
      "y": 14,
      "z": -2,
      "name": "Rock_Shale"
    },
    {
      "x": 18,
      "y": 15,
      "z": -2,
      "name": "Rock_Shale"
    },
    {
      "x": 18,
      "y": 26,
      "z": -2,
      "name": "Rock_Shale"
    },
    {
      "x": 18,
      "y": 27,
      "z": -2,
      "name": "Rock_Shale"
    },
    {
      "x": 18,
      "y": 28,
      "z": -2,
      "name": "Soil_Dirt_Cold"
    },
    {
      "x": 18,
      "y": 29,
      "z": -2,
      "name": "Soil_Dirt_Cold"
    },
    {
      "x": 18,
      "y": 30,
      "z": -2,
      "name": "Soil_Roots_Poisoned"
    },
    {
      "x": 18,
      "y": 31,
      "z": -2,
      "name": "Soil_Roots_Poisoned"
    },
    {
      "x": 18,
      "y": 32,
      "z": -2,
      "name": "Soil_Roots_Poisoned"
    },
    {
      "x": 18,
      "y": 14,
      "z": -1,
      "name": "Rock_Shale"
    },
    {
      "x": 18,
      "y": 15,
      "z": -1,
      "name": "Rock_Shale"
    },
    {
      "x": 18,
      "y": 16,
      "z": -1,
      "name": "Rock_Shale"
    },
    {
      "x": 18,
      "y": 26,
      "z": -1,
      "name": "Rock_Shale"
    },
    {
      "x": 18,
      "y": 27,
      "z": -1,
      "name": "Rock_Shale"
    },
    {
      "x": 18,
      "y": 28,
      "z": -1,
      "name": "Soil_Dirt_Cold"
    },
    {
      "x": 18,
      "y": 29,
      "z": -1,
      "name": "Soil_Roots_Poisoned"
    },
    {
      "x": 18,
      "y": 30,
      "z": -1,
      "name": "Soil_Roots_Poisoned"
    },
    {
      "x": 18,
      "y": 31,
      "z": -1,
      "name": "Soil_Roots_Poisoned"
    },
    {
      "x": 18,
      "y": 32,
      "z": -1,
      "name": "Soil_Roots_Poisoned"
    },
    {
      "x": 18,
      "y": 33,
      "z": -1,
      "name": "Plant_Crop_Mushroom_Glowing_Purple"
    },
    {
      "x": 18,
      "y": 27,
      "z": 0,
      "name": "Rock_Shale"
    },
    {
      "x": 18,
      "y": 28,
      "z": 0,
      "name": "Soil_Dirt_Cold"
    },
    {
      "x": 18,
      "y": 29,
      "z": 0,
      "name": "Soil_Dirt_Cold"
    },
    {
      "x": 18,
      "y": 30,
      "z": 0,
      "name": "Soil_Roots_Poisoned"
    },
    {
      "x": 18,
      "y": 31,
      "z": 0,
      "name": "Soil_Roots_Poisoned"
    },
    {
      "x": 18,
      "y": 32,
      "z": 0,
      "name": "Soil_Roots_Poisoned"
    },
    {
      "x": 18,
      "y": 33,
      "z": 0,
      "name": "Plant_Crop_Mushroom_Glowing_Purple"
    },
    {
      "x": 18,
      "y": 27,
      "z": 1,
      "name": "Rock_Shale"
    },
    {
      "x": 18,
      "y": 28,
      "z": 1,
      "name": "Soil_Dirt_Cold"
    },
    {
      "x": 18,
      "y": 29,
      "z": 1,
      "name": "Soil_Dirt_Cold"
    },
    {
      "x": 18,
      "y": 30,
      "z": 1,
      "name": "Soil_Roots_Poisoned"
    },
    {
      "x": 18,
      "y": 31,
      "z": 1,
      "name": "Soil_Roots_Poisoned"
    },
    {
      "x": 18,
      "y": 32,
      "z": 1,
      "name": "Soil_Roots_Poisoned"
    },
    {
      "x": 18,
      "y": 27,
      "z": 2,
      "name": "Rock_Shale"
    },
    {
      "x": 18,
      "y": 28,
      "z": 2,
      "name": "Soil_Dirt_Cold"
    },
    {
      "x": 18,
      "y": 29,
      "z": 2,
      "name": "Soil_Dirt_Cold"
    },
    {
      "x": 18,
      "y": 30,
      "z": 2,
      "name": "Soil_Roots_Poisoned"
    },
    {
      "x": 18,
      "y": 31,
      "z": 2,
      "name": "Soil_Roots_Poisoned"
    },
    {
      "x": 18,
      "y": 32,
      "z": 2,
      "name": "Soil_Roots_Poisoned"
    },
    {
      "x": 18,
      "y": 27,
      "z": 3,
      "name": "Rock_Shale"
    },
    {
      "x": 18,
      "y": 28,
      "z": 3,
      "name": "Soil_Dirt_Cold"
    },
    {
      "x": 18,
      "y": 29,
      "z": 3,
      "name": "Soil_Dirt_Cold"
    },
    {
      "x": 18,
      "y": 30,
      "z": 3,
      "name": "Soil_Roots_Poisoned"
    },
    {
      "x": 18,
      "y": 31,
      "z": 3,
      "name": "Soil_Roots_Poisoned"
    },
    {
      "x": 18,
      "y": 32,
      "z": 3,
      "name": "Soil_Roots_Poisoned"
    },
    {
      "x": 18,
      "y": 13,
      "z": 4,
      "name": "Rock_Shale"
    },
    {
      "x": 18,
      "y": 27,
      "z": 4,
      "name": "Soil_Dirt_Cold"
    },
    {
      "x": 18,
      "y": 28,
      "z": 4,
      "name": "Soil_Dirt_Cold"
    },
    {
      "x": 18,
      "y": 29,
      "z": 4,
      "name": "Soil_Roots_Poisoned"
    },
    {
      "x": 18,
      "y": 30,
      "z": 4,
      "name": "Soil_Roots_Poisoned"
    },
    {
      "x": 18,
      "y": 31,
      "z": 4,
      "name": "Soil_Roots_Poisoned"
    },
    {
      "x": 18,
      "y": 12,
      "z": 5,
      "name": "Rock_Shale"
    },
    {
      "x": 18,
      "y": 13,
      "z": 5,
      "name": "Rock_Shale"
    },
    {
      "x": 18,
      "y": 14,
      "z": 5,
      "name": "Rock_Shale"
    },
    {
      "x": 18,
      "y": 27,
      "z": 5,
      "name": "Soil_Dirt_Cold"
    },
    {
      "x": 18,
      "y": 28,
      "z": 5,
      "name": "Soil_Dirt_Cold"
    },
    {
      "x": 18,
      "y": 29,
      "z": 5,
      "name": "Soil_Dirt_Cold"
    },
    {
      "x": 18,
      "y": 30,
      "z": 5,
      "name": "Soil_Roots_Poisoned"
    },
    {
      "x": 18,
      "y": 13,
      "z": 6,
      "name": "Rock_Shale"
    },
    {
      "x": 18,
      "y": 14,
      "z": 6,
      "name": "Rock_Shale"
    },
    {
      "x": 18,
      "y": 15,
      "z": 6,
      "name": "Rock_Shale"
    },
    {
      "x": 18,
      "y": 16,
      "z": 6,
      "name": "Rock_Shale"
    },
    {
      "x": 18,
      "y": 17,
      "z": 6,
      "name": "Rock_Shale"
    },
    {
      "x": 18,
      "y": 27,
      "z": 6,
      "name": "Soil_Dirt_Cold"
    },
    {
      "x": 18,
      "y": 28,
      "z": 6,
      "name": "Soil_Dirt_Cold"
    },
    {
      "x": 18,
      "y": 29,
      "z": 6,
      "name": "Soil_Grass_Cold"
    },
    {
      "x": 18,
      "y": 14,
      "z": 7,
      "name": "Rock_Shale"
    },
    {
      "x": 18,
      "y": 15,
      "z": 7,
      "name": "Rock_Shale"
    },
    {
      "x": 18,
      "y": 17,
      "z": 7,
      "name": "Rock_Shale"
    },
    {
      "x": 18,
      "y": 18,
      "z": 7,
      "name": "Rock_Shale"
    },
    {
      "x": 18,
      "y": 19,
      "z": 7,
      "name": "Rock_Shale"
    },
    {
      "x": 18,
      "y": 20,
      "z": 7,
      "name": "Rock_Shale"
    },
    {
      "x": 18,
      "y": 17,
      "z": 8,
      "name": "Rock_Shale"
    },
    {
      "x": 18,
      "y": 18,
      "z": 8,
      "name": "Rock_Shale"
    },
    {
      "x": 18,
      "y": 19,
      "z": 8,
      "name": "Rock_Shale"
    },
    {
      "x": 19,
      "y": 29,
      "z": -4,
      "name": "Soil_Roots_Poisoned"
    },
    {
      "x": 19,
      "y": 30,
      "z": -4,
      "name": "Soil_Roots_Poisoned"
    },
    {
      "x": 19,
      "y": 14,
      "z": -3,
      "name": "Rock_Shale"
    },
    {
      "x": 19,
      "y": 26,
      "z": -3,
      "name": "Soil_Dirt_Cold"
    },
    {
      "x": 19,
      "y": 27,
      "z": -3,
      "name": "Soil_Dirt_Cold"
    },
    {
      "x": 19,
      "y": 28,
      "z": -3,
      "name": "Soil_Dirt_Cold"
    },
    {
      "x": 19,
      "y": 29,
      "z": -3,
      "name": "Soil_Roots_Poisoned"
    },
    {
      "x": 19,
      "y": 30,
      "z": -3,
      "name": "Soil_Roots_Poisoned"
    },
    {
      "x": 19,
      "y": 31,
      "z": -3,
      "name": "Soil_Roots_Poisoned"
    },
    {
      "x": 19,
      "y": 13,
      "z": -2,
      "name": "Rock_Shale"
    },
    {
      "x": 19,
      "y": 14,
      "z": -2,
      "name": "Rock_Shale"
    },
    {
      "x": 19,
      "y": 15,
      "z": -2,
      "name": "Rock_Shale"
    },
    {
      "x": 19,
      "y": 16,
      "z": -2,
      "name": "Rock_Shale"
    },
    {
      "x": 19,
      "y": 25,
      "z": -2,
      "name": "Rock_Shale"
    },
    {
      "x": 19,
      "y": 26,
      "z": -2,
      "name": "Soil_Dirt_Cold"
    },
    {
      "x": 19,
      "y": 27,
      "z": -2,
      "name": "Soil_Dirt_Cold"
    },
    {
      "x": 19,
      "y": 28,
      "z": -2,
      "name": "Soil_Dirt_Cold"
    },
    {
      "x": 19,
      "y": 29,
      "z": -2,
      "name": "Soil_Roots_Poisoned"
    },
    {
      "x": 19,
      "y": 30,
      "z": -2,
      "name": "Soil_Roots_Poisoned"
    },
    {
      "x": 19,
      "y": 31,
      "z": -2,
      "name": "Soil_Roots_Poisoned"
    },
    {
      "x": 19,
      "y": 14,
      "z": -1,
      "name": "Rock_Shale"
    },
    {
      "x": 19,
      "y": 15,
      "z": -1,
      "name": "Rock_Shale"
    },
    {
      "x": 19,
      "y": 16,
      "z": -1,
      "name": "Rock_Shale"
    },
    {
      "x": 19,
      "y": 17,
      "z": -1,
      "name": "Rock_Shale"
    },
    {
      "x": 19,
      "y": 25,
      "z": -1,
      "name": "Rock_Shale"
    },
    {
      "x": 19,
      "y": 26,
      "z": -1,
      "name": "Rock_Shale"
    },
    {
      "x": 19,
      "y": 27,
      "z": -1,
      "name": "Rock_Shale"
    },
    {
      "x": 19,
      "y": 28,
      "z": -1,
      "name": "Soil_Dirt_Cold"
    },
    {
      "x": 19,
      "y": 29,
      "z": -1,
      "name": "Soil_Dirt_Cold"
    },
    {
      "x": 19,
      "y": 30,
      "z": -1,
      "name": "Soil_Roots_Poisoned"
    },
    {
      "x": 19,
      "y": 31,
      "z": -1,
      "name": "Soil_Roots_Poisoned"
    },
    {
      "x": 19,
      "y": 32,
      "z": -1,
      "name": "Plant_Flower_Bushy_Poisoned"
    },
    {
      "x": 19,
      "y": 15,
      "z": 0,
      "name": "Rock_Shale"
    },
    {
      "x": 19,
      "y": 16,
      "z": 0,
      "name": "Rock_Shale"
    },
    {
      "x": 19,
      "y": 17,
      "z": 0,
      "name": "Rock_Shale"
    },
    {
      "x": 19,
      "y": 26,
      "z": 0,
      "name": "Rock_Shale"
    },
    {
      "x": 19,
      "y": 27,
      "z": 0,
      "name": "Rock_Shale"
    },
    {
      "x": 19,
      "y": 28,
      "z": 0,
      "name": "Soil_Dirt_Cold"
    },
    {
      "x": 19,
      "y": 29,
      "z": 0,
      "name": "Soil_Dirt_Cold"
    },
    {
      "x": 19,
      "y": 30,
      "z": 0,
      "name": "Soil_Roots_Poisoned"
    },
    {
      "x": 19,
      "y": 31,
      "z": 0,
      "name": "Soil_Roots_Poisoned"
    },
    {
      "x": 19,
      "y": 32,
      "z": 0,
      "name": "Soil_Roots_Poisoned"
    },
    {
      "x": 19,
      "y": 33,
      "z": 0,
      "name": "Plant_Flower_Bushy_Poisoned"
    },
    {
      "x": 19,
      "y": 26,
      "z": 1,
      "name": "Rock_Shale"
    },
    {
      "x": 19,
      "y": 27,
      "z": 1,
      "name": "Rock_Shale"
    },
    {
      "x": 19,
      "y": 28,
      "z": 1,
      "name": "Soil_Dirt_Cold"
    },
    {
      "x": 19,
      "y": 29,
      "z": 1,
      "name": "Soil_Dirt_Cold"
    },
    {
      "x": 19,
      "y": 30,
      "z": 1,
      "name": "Soil_Roots_Poisoned"
    },
    {
      "x": 19,
      "y": 31,
      "z": 1,
      "name": "Soil_Roots_Poisoned"
    },
    {
      "x": 19,
      "y": 32,
      "z": 1,
      "name": "Soil_Roots_Poisoned"
    },
    {
      "x": 19,
      "y": 26,
      "z": 2,
      "name": "Rock_Shale"
    },
    {
      "x": 19,
      "y": 27,
      "z": 2,
      "name": "Rock_Shale"
    },
    {
      "x": 19,
      "y": 28,
      "z": 2,
      "name": "Soil_Dirt_Cold"
    },
    {
      "x": 19,
      "y": 29,
      "z": 2,
      "name": "Soil_Roots_Poisoned"
    },
    {
      "x": 19,
      "y": 30,
      "z": 2,
      "name": "Soil_Roots_Poisoned"
    },
    {
      "x": 19,
      "y": 31,
      "z": 2,
      "name": "Soil_Roots_Poisoned"
    },
    {
      "x": 19,
      "y": 32,
      "z": 2,
      "name": "Soil_Roots_Poisoned"
    },
    {
      "x": 19,
      "y": 27,
      "z": 3,
      "name": "Soil_Dirt_Cold"
    },
    {
      "x": 19,
      "y": 28,
      "z": 3,
      "name": "Soil_Dirt_Cold"
    },
    {
      "x": 19,
      "y": 29,
      "z": 3,
      "name": "Soil_Dirt_Cold"
    },
    {
      "x": 19,
      "y": 30,
      "z": 3,
      "name": "Soil_Roots_Poisoned"
    },
    {
      "x": 19,
      "y": 31,
      "z": 3,
      "name": "Soil_Roots_Poisoned"
    },
    {
      "x": 19,
      "y": 26,
      "z": 4,
      "name": "Soil_Dirt_Cold"
    },
    {
      "x": 19,
      "y": 27,
      "z": 4,
      "name": "Soil_Dirt_Cold"
    },
    {
      "x": 19,
      "y": 28,
      "z": 4,
      "name": "Soil_Dirt_Cold"
    },
    {
      "x": 19,
      "y": 29,
      "z": 4,
      "name": "Soil_Dirt_Cold"
    },
    {
      "x": 19,
      "y": 30,
      "z": 4,
      "name": "Soil_Roots_Poisoned"
    },
    {
      "x": 19,
      "y": 31,
      "z": 4,
      "name": "Soil_Roots_Poisoned"
    },
    {
      "x": 19,
      "y": 13,
      "z": 5,
      "name": "Rock_Shale"
    },
    {
      "x": 19,
      "y": 14,
      "z": 5,
      "name": "Rock_Shale"
    },
    {
      "x": 19,
      "y": 15,
      "z": 5,
      "name": "Rock_Shale"
    },
    {
      "x": 19,
      "y": 16,
      "z": 5,
      "name": "Rock_Shale"
    },
    {
      "x": 19,
      "y": 26,
      "z": 5,
      "name": "Soil_Dirt_Cold"
    },
    {
      "x": 19,
      "y": 27,
      "z": 5,
      "name": "Soil_Dirt_Cold"
    },
    {
      "x": 19,
      "y": 28,
      "z": 5,
      "name": "Soil_Dirt_Cold"
    },
    {
      "x": 19,
      "y": 29,
      "z": 5,
      "name": "Soil_Dirt_Cold"
    },
    {
      "x": 19,
      "y": 30,
      "z": 5,
      "name": "Soil_Roots_Poisoned"
    },
    {
      "x": 19,
      "y": 13,
      "z": 6,
      "name": "Rock_Shale"
    },
    {
      "x": 19,
      "y": 14,
      "z": 6,
      "name": "Rock_Shale"
    },
    {
      "x": 19,
      "y": 15,
      "z": 6,
      "name": "Rock_Shale"
    },
    {
      "x": 19,
      "y": 16,
      "z": 6,
      "name": "Rock_Shale"
    },
    {
      "x": 19,
      "y": 17,
      "z": 6,
      "name": "Rock_Shale"
    },
    {
      "x": 19,
      "y": 18,
      "z": 6,
      "name": "Rock_Shale"
    },
    {
      "x": 19,
      "y": 19,
      "z": 6,
      "name": "Rock_Shale"
    },
    {
      "x": 19,
      "y": 25,
      "z": 6,
      "name": "Rock_Shale"
    },
    {
      "x": 19,
      "y": 26,
      "z": 6,
      "name": "Soil_Dirt_Cold"
    },
    {
      "x": 19,
      "y": 27,
      "z": 6,
      "name": "Soil_Dirt_Cold"
    },
    {
      "x": 19,
      "y": 28,
      "z": 6,
      "name": "Soil_Dirt_Cold"
    },
    {
      "x": 19,
      "y": 29,
      "z": 6,
      "name": "Soil_Dirt_Cold"
    },
    {
      "x": 19,
      "y": 30,
      "z": 6,
      "name": "Soil_Grass_Cold"
    },
    {
      "x": 19,
      "y": 31,
      "z": 6,
      "name": "Plant_Grass_Winter"
    },
    {
      "x": 19,
      "y": 14,
      "z": 7,
      "name": "Rock_Shale"
    },
    {
      "x": 19,
      "y": 15,
      "z": 7,
      "name": "Rock_Shale"
    },
    {
      "x": 19,
      "y": 16,
      "z": 7,
      "name": "Rock_Shale"
    },
    {
      "x": 19,
      "y": 17,
      "z": 7,
      "name": "Rock_Shale"
    },
    {
      "x": 19,
      "y": 18,
      "z": 7,
      "name": "Rock_Shale"
    },
    {
      "x": 19,
      "y": 19,
      "z": 7,
      "name": "Rock_Shale"
    },
    {
      "x": 19,
      "y": 20,
      "z": 7,
      "name": "Rock_Shale"
    },
    {
      "x": 19,
      "y": 21,
      "z": 7,
      "name": "Rock_Shale"
    },
    {
      "x": 19,
      "y": 22,
      "z": 7,
      "name": "Rock_Shale"
    },
    {
      "x": 19,
      "y": 23,
      "z": 7,
      "name": "Rock_Shale"
    },
    {
      "x": 19,
      "y": 24,
      "z": 7,
      "name": "Rock_Shale"
    },
    {
      "x": 19,
      "y": 25,
      "z": 7,
      "name": "Rock_Shale"
    },
    {
      "x": 19,
      "y": 26,
      "z": 7,
      "name": "Soil_Dirt_Cold"
    },
    {
      "x": 19,
      "y": 27,
      "z": 7,
      "name": "Soil_Dirt_Cold"
    },
    {
      "x": 19,
      "y": 28,
      "z": 7,
      "name": "Soil_Grass_Cold"
    },
    {
      "x": 19,
      "y": 14,
      "z": 8,
      "name": "Rock_Shale"
    },
    {
      "x": 19,
      "y": 15,
      "z": 8,
      "name": "Rock_Shale"
    },
    {
      "x": 19,
      "y": 16,
      "z": 8,
      "name": "Rock_Shale"
    },
    {
      "x": 19,
      "y": 17,
      "z": 8,
      "name": "Rock_Shale"
    },
    {
      "x": 19,
      "y": 18,
      "z": 8,
      "name": "Rock_Shale"
    },
    {
      "x": 19,
      "y": 19,
      "z": 8,
      "name": "Rock_Shale"
    },
    {
      "x": 19,
      "y": 20,
      "z": 8,
      "name": "Rock_Shale"
    },
    {
      "x": 19,
      "y": 21,
      "z": 8,
      "name": "Rock_Shale"
    },
    {
      "x": 19,
      "y": 22,
      "z": 8,
      "name": "Rock_Shale"
    },
    {
      "x": 19,
      "y": 23,
      "z": 8,
      "name": "Rock_Shale"
    },
    {
      "x": 19,
      "y": 24,
      "z": 8,
      "name": "Rock_Shale"
    },
    {
      "x": 19,
      "y": 25,
      "z": 8,
      "name": "Soil_Dirt_Cold"
    },
    {
      "x": 19,
      "y": 26,
      "z": 8,
      "name": "Soil_Grass_Cold"
    },
    {
      "x": 19,
      "y": 20,
      "z": 9,
      "name": "Rock_Shale"
    },
    {
      "x": 19,
      "y": 21,
      "z": 9,
      "name": "Rock_Shale"
    },
    {
      "x": 19,
      "y": 22,
      "z": 9,
      "name": "Rock_Shale"
    },
    {
      "x": 20,
      "y": 27,
      "z": -4,
      "name": "Soil_Dirt_Cold"
    },
    {
      "x": 20,
      "y": 28,
      "z": -4,
      "name": "Soil_Dirt_Cold"
    },
    {
      "x": 20,
      "y": 29,
      "z": -4,
      "name": "Soil_Roots_Poisoned"
    },
    {
      "x": 20,
      "y": 30,
      "z": -4,
      "name": "Soil_Roots_Poisoned"
    },
    {
      "x": 20,
      "y": 24,
      "z": -3,
      "name": "Soil_Dirt_Cold"
    },
    {
      "x": 20,
      "y": 25,
      "z": -3,
      "name": "Soil_Dirt_Cold"
    },
    {
      "x": 20,
      "y": 26,
      "z": -3,
      "name": "Soil_Dirt_Cold"
    },
    {
      "x": 20,
      "y": 27,
      "z": -3,
      "name": "Soil_Dirt_Cold"
    },
    {
      "x": 20,
      "y": 28,
      "z": -3,
      "name": "Soil_Roots_Poisoned"
    },
    {
      "x": 20,
      "y": 29,
      "z": -3,
      "name": "Soil_Roots_Poisoned"
    },
    {
      "x": 20,
      "y": 30,
      "z": -3,
      "name": "Soil_Roots_Poisoned"
    },
    {
      "x": 20,
      "y": 14,
      "z": -2,
      "name": "Rock_Shale"
    },
    {
      "x": 20,
      "y": 15,
      "z": -2,
      "name": "Rock_Shale"
    },
    {
      "x": 20,
      "y": 16,
      "z": -2,
      "name": "Rock_Shale"
    },
    {
      "x": 20,
      "y": 17,
      "z": -2,
      "name": "Rock_Shale"
    },
    {
      "x": 20,
      "y": 18,
      "z": -2,
      "name": "Rock_Shale"
    },
    {
      "x": 20,
      "y": 24,
      "z": -2,
      "name": "Rock_Shale"
    },
    {
      "x": 20,
      "y": 25,
      "z": -2,
      "name": "Soil_Dirt_Cold"
    },
    {
      "x": 20,
      "y": 26,
      "z": -2,
      "name": "Soil_Dirt_Cold"
    },
    {
      "x": 20,
      "y": 27,
      "z": -2,
      "name": "Soil_Dirt_Cold"
    },
    {
      "x": 20,
      "y": 28,
      "z": -2,
      "name": "Soil_Dirt_Cold"
    },
    {
      "x": 20,
      "y": 29,
      "z": -2,
      "name": "Soil_Roots_Poisoned"
    },
    {
      "x": 20,
      "y": 30,
      "z": -2,
      "name": "Soil_Roots_Poisoned"
    },
    {
      "x": 20,
      "y": 31,
      "z": -2,
      "name": "Soil_Roots_Poisoned"
    },
    {
      "x": 20,
      "y": 14,
      "z": -1,
      "name": "Rock_Shale"
    },
    {
      "x": 20,
      "y": 15,
      "z": -1,
      "name": "Rock_Shale"
    },
    {
      "x": 20,
      "y": 16,
      "z": -1,
      "name": "Rock_Shale"
    },
    {
      "x": 20,
      "y": 17,
      "z": -1,
      "name": "Rock_Shale"
    },
    {
      "x": 20,
      "y": 18,
      "z": -1,
      "name": "Rock_Shale"
    },
    {
      "x": 20,
      "y": 19,
      "z": -1,
      "name": "Rock_Shale"
    },
    {
      "x": 20,
      "y": 24,
      "z": -1,
      "name": "Rock_Shale"
    },
    {
      "x": 20,
      "y": 25,
      "z": -1,
      "name": "Rock_Shale"
    },
    {
      "x": 20,
      "y": 26,
      "z": -1,
      "name": "Soil_Dirt_Cold"
    },
    {
      "x": 20,
      "y": 27,
      "z": -1,
      "name": "Soil_Dirt_Cold"
    },
    {
      "x": 20,
      "y": 28,
      "z": -1,
      "name": "Soil_Dirt_Cold"
    },
    {
      "x": 20,
      "y": 29,
      "z": -1,
      "name": "Soil_Dirt_Cold"
    },
    {
      "x": 20,
      "y": 30,
      "z": -1,
      "name": "Soil_Roots_Poisoned"
    },
    {
      "x": 20,
      "y": 31,
      "z": -1,
      "name": "Soil_Roots_Poisoned"
    },
    {
      "x": 20,
      "y": 32,
      "z": -1,
      "name": "Plant_Crop_Mushroom_Glowing_Purple"
    },
    {
      "x": 20,
      "y": 16,
      "z": 0,
      "name": "Rock_Shale"
    },
    {
      "x": 20,
      "y": 17,
      "z": 0,
      "name": "Rock_Shale"
    },
    {
      "x": 20,
      "y": 18,
      "z": 0,
      "name": "Rock_Shale"
    },
    {
      "x": 20,
      "y": 25,
      "z": 0,
      "name": "Rock_Shale"
    },
    {
      "x": 20,
      "y": 26,
      "z": 0,
      "name": "Rock_Shale"
    },
    {
      "x": 20,
      "y": 27,
      "z": 0,
      "name": "Rock_Shale"
    },
    {
      "x": 20,
      "y": 28,
      "z": 0,
      "name": "Soil_Dirt_Cold"
    },
    {
      "x": 20,
      "y": 29,
      "z": 0,
      "name": "Soil_Roots_Poisoned"
    },
    {
      "x": 20,
      "y": 30,
      "z": 0,
      "name": "Soil_Roots_Poisoned"
    },
    {
      "x": 20,
      "y": 31,
      "z": 0,
      "name": "Soil_Roots_Poisoned"
    },
    {
      "x": 20,
      "y": 26,
      "z": 1,
      "name": "Rock_Shale"
    },
    {
      "x": 20,
      "y": 27,
      "z": 1,
      "name": "Rock_Shale"
    },
    {
      "x": 20,
      "y": 28,
      "z": 1,
      "name": "Soil_Dirt_Cold"
    },
    {
      "x": 20,
      "y": 29,
      "z": 1,
      "name": "Soil_Dirt_Cold"
    },
    {
      "x": 20,
      "y": 30,
      "z": 1,
      "name": "Soil_Roots_Poisoned"
    },
    {
      "x": 20,
      "y": 31,
      "z": 1,
      "name": "Soil_Roots_Poisoned"
    },
    {
      "x": 20,
      "y": 27,
      "z": 2,
      "name": "Rock_Shale"
    },
    {
      "x": 20,
      "y": 28,
      "z": 2,
      "name": "Soil_Dirt_Cold"
    },
    {
      "x": 20,
      "y": 29,
      "z": 2,
      "name": "Soil_Dirt_Cold"
    },
    {
      "x": 20,
      "y": 30,
      "z": 2,
      "name": "Soil_Roots_Poisoned"
    },
    {
      "x": 20,
      "y": 27,
      "z": 3,
      "name": "Soil_Dirt_Cold"
    },
    {
      "x": 20,
      "y": 28,
      "z": 3,
      "name": "Soil_Dirt_Cold"
    },
    {
      "x": 20,
      "y": 29,
      "z": 3,
      "name": "Soil_Dirt_Cold"
    },
    {
      "x": 20,
      "y": 30,
      "z": 3,
      "name": "Soil_Roots_Poisoned"
    },
    {
      "x": 20,
      "y": 27,
      "z": 4,
      "name": "Soil_Dirt_Cold"
    },
    {
      "x": 20,
      "y": 28,
      "z": 4,
      "name": "Soil_Dirt_Cold"
    },
    {
      "x": 20,
      "y": 29,
      "z": 4,
