{
  "version": 8,
  "blockIdVersion": 8,
  "anchorX": 13,
  "anchorY": 19,
  "anchorZ": -1,
  "blocks": [
    {
      "x": 1,
      "y": 39,
      "z": 1,
      "name": "Plant_Leaves_Dead"
    },
    {
      "x": 2,
      "y": 40,
      "z": 0,
      "name": "Plant_Leaves_Dead"
    },
    {
      "x": 2,
      "y": 39,
      "z": 1,
      "name": "Plant_Leaves_Dead"
    },
    {
      "x": 2,
      "y": 40,
      "z": 1,
      "name": "Plant_Leaves_Dead"
    },
    {
      "x": 2,
      "y": 46,
      "z": 1,
      "name": "Plant_Leaves_Dead"
    },
    {
      "x": 3,
      "y": 43,
      "z": -2,
      "name": "Plant_Leaves_Dead"
    },
    {
      "x": 3,
      "y": 40,
      "z": 0,
      "name": "Plant_Leaves_Dead"
    },
    {
      "x": 3,
      "y": 40,
      "z": 1,
      "name": "Wood_Fir_Branch_Long",
      "rotation": 5
    },
    {
      "x": 3,
      "y": 41,
      "z": 1,
      "name": "Plant_Leaves_Dead"
    },
    {
      "x": 3,
      "y": 46,
      "z": 1,
      "name": "Plant_Leaves_Dead"
    },
    {
      "x": 3,
      "y": 47,
      "z": 1,
      "name": "Plant_Leaves_Dead"
    },
    {
      "x": 3,
      "y": 51,
      "z": 1,
      "name": "Plant_Leaves_Dead"
    },
    {
      "x": 3,
      "y": 40,
      "z": 2,
      "name": "Plant_Leaves_Dead"
    },
    {
      "x": 4,
      "y": 43,
      "z": -2,
      "name": "Plant_Leaves_Dead"
    },
    {
      "x": 4,
      "y": 23,
      "z": -1,
      "name": "Rock_Shale"
    },
    {
      "x": 4,
      "y": 24,
      "z": -1,
      "name": "Rock_Shale"
    },
    {
      "x": 4,
      "y": 25,
      "z": -1,
      "name": "Rock_Shale"
    },
    {
      "x": 4,
      "y": 26,
      "z": -1,
      "name": "Rock_Shale"
    },
    {
      "x": 4,
      "y": 29,
      "z": -1,
      "name": "Wood_Fir_Roots"
    },
    {
      "x": 4,
      "y": 30,
      "z": -1,
      "name": "Wood_Fir_Trunk_Full"
    },
    {
      "x": 4,
      "y": 31,
      "z": -1,
      "name": "Wood_Fir_Trunk_Full"
    },
    {
      "x": 4,
      "y": 41,
      "z": -1,
      "name": "Plant_Leaves_Dead"
    },
    {
      "x": 4,
      "y": 43,
      "z": -1,
      "name": "Plant_Leaves_Dead"
    },
    {
      "x": 4,
      "y": 44,
      "z": -1,
      "name": "Plant_Leaves_Dead"
    },
    {
      "x": 4,
      "y": 24,
      "z": 0,
      "name": "Rock_Shale"
    },
    {
      "x": 4,
      "y": 25,
      "z": 0,
      "name": "Rock_Shale"
    },
    {
      "x": 4,
      "y": 26,
      "z": 0,
      "name": "Rock_Shale"
    },
    {
      "x": 4,
      "y": 27,
      "z": 0,
      "name": "Rock_Shale"
    },
    {
      "x": 4,
      "y": 41,
      "z": 0,
      "name": "Plant_Leaves_Dead"
    },
    {
      "x": 4,
      "y": 44,
      "z": 0,
      "name": "Plant_Leaves_Dead"
    },
    {
      "x": 4,
      "y": 47,
      "z": 0,
      "name": "Plant_Leaves_Dead"
    },
    {
      "x": 4,
      "y": 48,
      "z": 0,
      "name": "Plant_Leaves_Dead"
    },
    {
      "x": 4,
      "y": 28,
      "z": 1,
      "name": "Wood_Fir_Roots"
    },
    {
      "x": 4,
      "y": 29,
      "z": 1,
      "name": "Wood_Fir_Trunk_Full"
    },
    {
      "x": 4,
      "y": 30,
      "z": 1,
      "name": "Wood_Fir_Trunk"
    },
    {
      "x": 4,
      "y": 31,
      "z": 1,
      "name": "Wood_Fir_Trunk"
    },
    {
      "x": 4,
      "y": 32,
      "z": 1,
      "name": "Wood_Fir_Trunk_Full"
    },
    {
      "x": 4,
      "y": 40,
      "z": 1,
      "name": "Wood_Fir_Branch_Long",
      "rotation": 5
    },
    {
      "x": 4,
      "y": 41,
      "z": 1,
      "name": "Plant_Leaves_Dead"
    },
    {
      "x": 4,
      "y": 42,
      "z": 1,
      "name": "Plant_Leaves_Dead"
    },
    {
      "x": 4,
      "y": 44,
      "z": 1,
      "name": "Plant_Leaves_Dead"
    },
    {
      "x": 4,
      "y": 47,
      "z": 1,
      "name": "Wood_Fir_Branch_Long",
      "rotation": 5
    },
    {
      "x": 4,
      "y": 48,
      "z": 1,
      "name": "Plant_Leaves_Dead"
    },
    {
      "x": 4,
      "y": 51,
      "z": 1,
      "name": "Plant_Leaves_Dead"
    },
    {
      "x": 4,
      "y": 52,
      "z": 1,
      "name": "Plant_Leaves_Dead"
    },
    {
      "x": 4,
      "y": 53,
      "z": 1,
      "name": "Plant_Leaves_Dead"
    },
    {
      "x": 4,
      "y": 41,
      "z": 2,
      "name": "Plant_Leaves_Dead"
    },
    {
      "x": 4,
      "y": 44,
      "z": 2,
      "name": "Plant_Leaves_Dead"
    },
    {
      "x": 4,
      "y": 47,
      "z": 2,
      "name": "Plant_Leaves_Dead"
    },
    {
      "x": 4,
      "y": 43,
      "z": 3,
      "name": "Plant_Leaves_Dead"
    },
    {
      "x": 4,
      "y": 43,
      "z": 4,
      "name": "Plant_Leaves_Dead"
    },
    {
      "x": 5,
      "y": 22,
      "z": -2,
      "name": "Rock_Shale"
    },
    {
      "x": 5,
      "y": 23,
      "z": -2,
      "name": "Rock_Shale"
    },
    {
      "x": 5,
      "y": 24,
      "z": -2,
      "name": "Rock_Shale"
    },
    {
      "x": 5,
      "y": 25,
      "z": -2,
      "name": "Rock_Shale"
    },
    {
      "x": 5,
      "y": 26,
      "z": -2,
      "name": "Rock_Shale"
    },
    {
      "x": 5,
      "y": 27,
      "z": -2,
      "name": "Rock_Shale"
    },
    {
      "x": 5,
      "y": 41,
      "z": -2,
      "name": "Plant_Leaves_Dead"
    },
    {
      "x": 5,
      "y": 42,
      "z": -2,
      "name": "Plant_Leaves_Dead"
    },
    {
      "x": 5,
      "y": 20,
      "z": -1,
      "name": "Rock_Shale"
    },
    {
      "x": 5,
      "y": 21,
      "z": -1,
      "name": "Rock_Shale"
    },
    {
      "x": 5,
      "y": 22,
      "z": -1,
      "name": "Rock_Shale"
    },
    {
      "x": 5,
      "y": 23,
      "z": -1,
      "name": "Rock_Shale"
    },
    {
      "x": 5,
      "y": 24,
      "z": -1,
      "name": "Rock_Shale"
    },
    {
      "x": 5,
      "y": 25,
      "z": -1,
      "name": "Rock_Shale"
    },
    {
      "x": 5,
      "y": 26,
      "z": -1,
      "name": "Rock_Shale"
    },
    {
      "x": 5,
      "y": 27,
      "z": -1,
      "name": "Rock_Shale"
    },
    {
      "x": 5,
      "y": 28,
      "z": -1,
      "name": "Rock_Shale"
    },
    {
      "x": 5,
      "y": 29,
      "z": -1,
      "name": "Rock_Shale"
    },
    {
      "x": 5,
      "y": 31,
      "z": -1,
      "name": "Wood_Fir_Trunk_Full"
    },
    {
      "x": 5,
      "y": 41,
      "z": -1,
      "name": "Plant_Leaves_Dead"
    },
    {
      "x": 5,
      "y": 42,
      "z": -1,
      "name": "Plant_Leaves_Dead"
    },
    {
      "x": 5,
      "y": 44,
      "z": -1,
      "name": "Plant_Leaves_Dead"
    },
    {
      "x": 5,
      "y": 51,
      "z": -1,
      "name": "Plant_Leaves_Dead"
    },
    {
      "x": 5,
      "y": 19,
      "z": 0,
      "name": "Rock_Shale"
    },
    {
      "x": 5,
      "y": 20,
      "z": 0,
      "name": "Rock_Shale"
    },
    {
      "x": 5,
      "y": 21,
      "z": 0,
      "name": "Rock_Shale"
    },
    {
      "x": 5,
      "y": 22,
      "z": 0,
      "name": "Rock_Shale"
    },
    {
      "x": 5,
      "y": 23,
      "z": 0,
      "name": "Rock_Shale"
    },
    {
      "x": 5,
      "y": 24,
      "z": 0,
      "name": "Rock_Shale"
    },
    {
      "x": 5,
      "y": 25,
      "z": 0,
      "name": "Rock_Shale"
    },
    {
      "x": 5,
      "y": 26,
      "z": 0,
      "name": "Rock_Shale"
    },
    {
      "x": 5,
      "y": 27,
      "z": 0,
      "name": "Rock_Shale"
    },
    {
      "x": 5,
      "y": 28,
      "z": 0,
      "name": "Rock_Shale"
    },
    {
      "x": 5,
      "y": 29,
      "z": 0,
      "name": "Rock_Shale"
    },
    {
      "x": 5,
      "y": 30,
      "z": 0,
      "name": "Soil_Dirt_Cold"
    },
    {
      "x": 5,
      "y": 31,
      "z": 0,
      "name": "Soil_Dirt_Cold"
    },
    {
      "x": 5,
      "y": 32,
      "z": 0,
      "name": "Soil_Grass_Cold"
    },
    {
      "x": 5,
      "y": 33,
      "z": 0,
      "name": "Wood_Fir_Trunk_Full"
    },
    {
      "x": 5,
      "y": 34,
      "z": 0,
      "name": "Wood_Fir_Trunk"
    },
    {
      "x": 5,
      "y": 35,
      "z": 0,
      "name": "Wood_Fir_Trunk"
    },
    {
      "x": 5,
      "y": 36,
      "z": 0,
      "name": "Wood_Fir_Trunk"
    },
    {
      "x": 5,
      "y": 37,
      "z": 0,
      "name": "Wood_Fir_Trunk"
    },
    {
      "x": 5,
      "y": 38,
      "z": 0,
      "name": "Wood_Fir_Trunk"
    },
    {
      "x": 5,
      "y": 39,
      "z": 0,
      "name": "Wood_Fir_Trunk_Full"
    },
    {
      "x": 5,
      "y": 44,
      "z": 0,
      "name": "Plant_Leaves_Dead"
    },
    {
      "x": 5,
      "y": 45,
      "z": 0,
      "name": "Plant_Leaves_Dead"
    },
    {
      "x": 5,
      "y": 48,
      "z": 0,
      "name": "Plant_Leaves_Dead"
    },
    {
      "x": 5,
      "y": 52,
      "z": 0,
      "name": "Plant_Leaves_Dead"
    },
    {
      "x": 5,
      "y": 21,
      "z": 1,
      "name": "Rock_Shale"
    },
    {
      "x": 5,
      "y": 22,
      "z": 1,
      "name": "Rock_Shale"
    },
    {
      "x": 5,
      "y": 23,
      "z": 1,
      "name": "Rock_Shale"
    },
    {
      "x": 5,
      "y": 24,
      "z": 1,
      "name": "Rock_Shale"
    },
    {
      "x": 5,
      "y": 25,
      "z": 1,
      "name": "Rock_Shale"
    },
    {
      "x": 5,
      "y": 26,
      "z": 1,
      "name": "Rock_Shale"
    },
    {
      "x": 5,
      "y": 27,
      "z": 1,
      "name": "Rock_Shale"
    },
    {
      "x": 5,
      "y": 28,
      "z": 1,
      "name": "Rock_Shale"
    },
    {
      "x": 5,
      "y": 29,
      "z": 1,
      "name": "Rock_Shale"
    },
    {
      "x": 5,
      "y": 30,
      "z": 1,
      "name": "Soil_Dirt_Cold"
    },
    {
      "x": 5,
      "y": 31,
      "z": 1,
      "name": "Soil_Grass_Cold"
    },
    {
      "x": 5,
      "y": 32,
      "z": 1,
      "name": "Wood_Fir_Trunk_Full"
    },
    {
      "x": 5,
      "y": 33,
      "z": 1,
      "name": "Wood_Fir_Trunk"
    },
    {
      "x": 5,
      "y": 34,
      "z": 1,
      "name": "Wood_Fir_Trunk"
    },
    {
      "x": 5,
      "y": 35,
      "z": 1,
      "name": "Wood_Fir_Trunk"
    },
    {
      "x": 5,
      "y": 36,
      "z": 1,
      "name": "Wood_Fir_Trunk"
    },
    {
      "x": 5,
      "y": 37,
      "z": 1,
      "name": "Wood_Fir_Trunk"
    },
    {
      "x": 5,
      "y": 38,
      "z": 1,
      "name": "Wood_Fir_Trunk"
    },
    {
      "x": 5,
      "y": 39,
      "z": 1,
      "name": "Wood_Fir_Trunk"
    },
    {
      "x": 5,
      "y": 40,
      "z": 1,
      "name": "Wood_Fir_Trunk"
    },
    {
      "x": 5,
      "y": 41,
      "z": 1,
      "name": "Wood_Fir_Trunk"
    },
    {
      "x": 5,
      "y": 42,
      "z": 1,
      "name": "Wood_Fir_Trunk_Full"
    },
    {
      "x": 5,
      "y": 44,
      "z": 1,
      "name": "Wood_Fir_Branch_Long",
      "rotation": 5
    },
    {
      "x": 5,
      "y": 45,
      "z": 1,
      "name": "Plant_Leaves_Dead"
    },
    {
      "x": 5,
      "y": 46,
      "z": 1,
      "name": "Plant_Leaves_Dead"
    },
    {
      "x": 5,
      "y": 47,
      "z": 1,
      "name": "Wood_Fir_Branch_Long",
      "rotation": 5
    },
    {
      "x": 5,
      "y": 48,
      "z": 1,
      "name": "Plant_Leaves_Dead"
    },
    {
      "x": 5,
      "y": 49,
      "z": 1,
      "name": "Plant_Leaves_Dead"
    },
    {
      "x": 5,
      "y": 52,
      "z": 1,
      "name": "Wood_Fir_Branch_Long",
      "rotation": 5
    },
    {
      "x": 5,
      "y": 53,
      "z": 1,
      "name": "Plant_Leaves_Dead"
    },
    {
      "x": 5,
      "y": 54,
      "z": 1,
      "name": "Plant_Leaves_Dead"
    },
    {
      "x": 5,
      "y": 55,
      "z": 1,
      "name": "Plant_Leaves_Dead"
    },
    {
      "x": 5,
      "y": 26,
      "z": 2,
      "name": "Rock_Shale"
    },
    {
      "x": 5,
      "y": 27,
      "z": 2,
      "name": "Rock_Shale"
    },
    {
      "x": 5,
      "y": 28,
      "z": 2,
      "name": "Rock_Shale"
    },
    {
      "x": 5,
      "y": 29,
      "z": 2,
      "name": "Rock_Shale"
    },
    {
      "x": 5,
      "y": 30,
      "z": 2,
      "name": "Rock_Shale"
    },
    {
      "x": 5,
      "y": 41,
      "z": 2,
      "name": "Plant_Leaves_Dead"
    },
    {
      "x": 5,
      "y": 44,
      "z": 2,
      "name": "Plant_Leaves_Dead"
    },
    {
      "x": 5,
      "y": 45,
      "z": 2,
      "name": "Plant_Leaves_Dead"
    },
    {
      "x": 5,
      "y": 48,
      "z": 2,
      "name": "Plant_Leaves_Dead"
    },
    {
      "x": 5,
      "y": 49,
      "z": 2,
      "name": "Plant_Leaves_Dead"
    },
    {
      "x": 5,
      "y": 52,
      "z": 2,
      "name": "Plant_Leaves_Dead"
    },
    {
      "x": 5,
      "y": 40,
      "z": 3,
      "name": "Plant_Leaves_Dead"
    },
    {
      "x": 5,
      "y": 44,
      "z": 3,
      "name": "Plant_Leaves_Dead"
    },
    {
      "x": 5,
      "y": 40,
      "z": 4,
      "name": "Plant_Leaves_Dead"
    },
    {
      "x": 6,
      "y": 40,
      "z": -5,
      "name": "Plant_Leaves_Dead"
    },
    {
      "x": 6,
      "y": 40,
      "z": -4,
      "name": "Plant_Leaves_Dead"
    },
    {
      "x": 6,
      "y": 41,
      "z": -4,
      "name": "Plant_Leaves_Dead"
    },
    {
      "x": 6,
      "y": 21,
      "z": -3,
      "name": "Rock_Shale"
    },
    {
      "x": 6,
      "y": 22,
      "z": -3,
      "name": "Rock_Shale"
    },
    {
      "x": 6,
      "y": 23,
      "z": -3,
      "name": "Rock_Shale"
    },
    {
      "x": 6,
      "y": 24,
      "z": -3,
      "name": "Rock_Shale"
    },
    {
      "x": 6,
      "y": 25,
      "z": -3,
      "name": "Rock_Shale"
    },
    {
      "x": 6,
      "y": 26,
      "z": -3,
      "name": "Rock_Shale"
    },
    {
      "x": 6,
      "y": 27,
      "z": -3,
      "name": "Rock_Shale"
    },
    {
      "x": 6,
      "y": 28,
      "z": -3,
      "name": "Rock_Shale"
    },
    {
      "x": 6,
      "y": 41,
      "z": -3,
      "name": "Plant_Leaves_Dead"
    },
    {
      "x": 6,
      "y": 42,
      "z": -3,
      "name": "Plant_Leaves_Dead"
    },
    {
      "x": 6,
      "y": 18,
      "z": -2,
      "name": "Rock_Shale"
    },
    {
      "x": 6,
      "y": 19,
      "z": -2,
      "name": "Rock_Shale"
    },
    {
      "x": 6,
      "y": 20,
      "z": -2,
      "name": "Rock_Shale"
    },
    {
      "x": 6,
      "y": 21,
      "z": -2,
      "name": "Rock_Shale"
    },
    {
      "x": 6,
      "y": 22,
      "z": -2,
      "name": "Rock_Shale"
    },
    {
      "x": 6,
      "y": 23,
      "z": -2,
      "name": "Rock_Shale"
    },
    {
      "x": 6,
      "y": 24,
      "z": -2,
      "name": "Rock_Shale"
    },
    {
      "x": 6,
      "y": 25,
      "z": -2,
      "name": "Rock_Shale"
    },
    {
      "x": 6,
      "y": 26,
      "z": -2,
      "name": "Rock_Shale"
    },
    {
      "x": 6,
      "y": 27,
      "z": -2,
      "name": "Rock_Shale"
    },
    {
      "x": 6,
      "y": 28,
      "z": -2,
      "name": "Rock_Shale"
    },
    {
      "x": 6,
      "y": 29,
      "z": -2,
      "name": "Rock_Shale"
    },
    {
      "x": 6,
      "y": 30,
      "z": -2,
      "name": "Soil_Dirt_Cold"
    },
    {
      "x": 6,
      "y": 41,
      "z": -2,
      "name": "Wood_Fir_Branch_Long",
      "rotation": 4
    },
    {
      "x": 6,
      "y": 42,
      "z": -2,
      "name": "Plant_Leaves_Dead"
    },
    {
      "x": 6,
      "y": 47,
      "z": -2,
      "name": "Plant_Leaves_Dead"
    },
    {
      "x": 6,
      "y": 50,
      "z": -2,
      "name": "Plant_Leaves_Dead"
    },
    {
      "x": 6,
      "y": 51,
      "z": -2,
      "name": "Plant_Leaves_Dead"
    },
    {
      "x": 6,
      "y": 16,
      "z": -1,
      "name": "Rock_Shale"
    },
    {
      "x": 6,
      "y": 17,
      "z": -1,
      "name": "Rock_Shale"
    },
    {
      "x": 6,
      "y": 18,
      "z": -1,
      "name": "Rock_Shale"
    },
    {
      "x": 6,
      "y": 19,
      "z": -1,
      "name": "Rock_Shale"
    },
    {
      "x": 6,
      "y": 20,
      "z": -1,
      "name": "Rock_Shale"
    },
    {
      "x": 6,
      "y": 21,
      "z": -1,
      "name": "Rock_Shale"
    },
    {
      "x": 6,
      "y": 22,
      "z": -1,
      "name": "Rock_Shale"
    },
    {
      "x": 6,
      "y": 23,
      "z": -1,
      "name": "Rock_Shale"
    },
    {
      "x": 6,
      "y": 24,
      "z": -1,
      "name": "Rock_Shale"
    },
    {
      "x": 6,
      "y": 25,
      "z": -1,
      "name": "Rock_Shale"
    },
    {
      "x": 6,
      "y": 26,
      "z": -1,
      "name": "Rock_Shale"
    },
    {
      "x": 6,
      "y": 27,
      "z": -1,
      "name": "Wood_Fir_Roots"
    },
    {
      "x": 6,
      "y": 28,
      "z": -1,
      "name": "Wood_Fir_Trunk_Full"
    },
    {
      "x": 6,
      "y": 29,
      "z": -1,
      "name": "Wood_Fir_Trunk"
    },
    {
      "x": 6,
      "y": 30,
      "z": -1,
      "name": "Wood_Fir_Trunk"
    },
    {
      "x": 6,
      "y": 31,
      "z": -1,
      "name": "Wood_Fir_Trunk"
    },
    {
      "x": 6,
      "y": 32,
      "z": -1,
      "name": "Wood_Fir_Trunk"
    },
    {
      "x": 6,
      "y": 33,
      "z": -1,
      "name": "Wood_Fir_Trunk"
    },
    {
      "x": 6,
      "y": 34,
      "z": -1,
      "name": "Wood_Fir_Trunk_Full"
    },
    {
      "x": 6,
      "y": 41,
      "z": -1,
      "name": "Wood_Fir_Branch_Long",
      "rotation": 4
    },
    {
      "x": 6,
      "y": 42,
      "z": -1,
      "name": "Plant_Leaves_Dead"
    },
    {
      "x": 6,
      "y": 43,
      "z": -1,
      "name": "Plant_Leaves_Dead"
    },
    {
      "x": 6,
      "y": 47,
      "z": -1,
      "name": "Plant_Leaves_Dead"
    },
    {
      "x": 6,
      "y": 48,
      "z": -1,
      "name": "Plant_Leaves_Dead"
    },
    {
      "x": 6,
      "y": 51,
      "z": -1,
      "name": "Plant_Leaves_Dead"
    },
    {
      "x": 6,
      "y": 52,
      "z": -1,
      "name": "Plant_Leaves_Dead"
    },
    {
      "x": 6,
      "y": 17,
      "z": 0,
      "name": "Rock_Shale"
    },
    {
      "x": 6,
      "y": 18,
      "z": 0,
      "name": "Rock_Shale"
    },
    {
      "x": 6,
      "y": 19,
      "z": 0,
      "name": "Rock_Shale"
    },
    {
      "x": 6,
      "y": 20,
      "z": 0,
      "name": "Rock_Shale"
    },
    {
      "x": 6,
      "y": 21,
      "z": 0,
      "name": "Rock_Shale"
    },
    {
      "x": 6,
      "y": 22,
      "z": 0,
      "name": "Rock_Shale"
    },
    {
      "x": 6,
      "y": 23,
      "z": 0,
      "name": "Rock_Shale"
    },
    {
      "x": 6,
      "y": 24,
      "z": 0,
      "name": "Rock_Shale"
    },
    {
      "x": 6,
      "y": 25,
      "z": 0,
      "name": "Rock_Shale"
    },
    {
      "x": 6,
      "y": 26,
      "z": 0,
      "name": "Rock_Shale"
    },
    {
      "x": 6,
      "y": 27,
      "z": 0,
      "name": "Rock_Shale"
    },
    {
      "x": 6,
      "y": 28,
      "z": 0,
      "name": "Rock_Shale"
    },
    {
      "x": 6,
      "y": 29,
      "z": 0,
      "name": "Rock_Shale"
    },
    {
      "x": 6,
      "y": 30,
      "z": 0,
      "name": "Soil_Dirt_Cold"
    },
    {
      "x": 6,
      "y": 31,
      "z": 0,
      "name": "Soil_Dirt_Cold"
    },
    {
      "x": 6,
      "y": 32,
      "z": 0,
      "name": "Wood_Fir_Trunk_Full"
    },
    {
      "x": 6,
      "y": 33,
      "z": 0,
      "name": "Wood_Fir_Trunk"
    },
    {
      "x": 6,
      "y": 34,
      "z": 0,
      "name": "Wood_Fir_Trunk"
    },
    {
      "x": 6,
      "y": 35,
      "z": 0,
      "name": "Wood_Fir_Trunk"
    },
    {
      "x": 6,
      "y": 36,
      "z": 0,
      "name": "Wood_Fir_Trunk"
    },
    {
      "x": 6,
      "y": 37,
      "z": 0,
      "name": "Wood_Fir_Trunk"
    },
    {
      "x": 6,
      "y": 38,
      "z": 0,
      "name": "Wood_Fir_Trunk"
    },
    {
      "x": 6,
      "y": 39,
      "z": 0,
      "name": "Wood_Fir_Trunk"
    },
    {
      "x": 6,
      "y": 40,
      "z": 0,
      "name": "Wood_Fir_Trunk"
    },
    {
      "x": 6,
      "y": 41,
      "z": 0,
      "name": "Wood_Fir_Trunk"
    },
    {
      "x": 6,
      "y": 42,
      "z": 0,
      "name": "Wood_Fir_Trunk"
    },
    {
      "x": 6,
      "y": 43,
      "z": 0,
      "name": "Wood_Fir_Trunk"
    },
    {
      "x": 6,
      "y": 44,
      "z": 0,
      "name": "Wood_Fir_Trunk"
    },
    {
      "x": 6,
      "y": 45,
      "z": 0,
      "name": "Wood_Fir_Trunk_Full"
    },
    {
      "x": 6,
      "y": 46,
      "z": 0,
      "name": "Plant_Leaves_Dead"
    },
    {
      "x": 6,
      "y": 48,
      "z": 0,
      "name": "Wood_Fir_Branch_Long",
      "rotation": 4
    },
    {
      "x": 6,
      "y": 49,
      "z": 0,
      "name": "Plant_Leaves_Dead"
    },
    {
      "x": 6,
      "y": 52,
      "z": 0,
      "name": "Wood_Fir_Branch_Long",
      "rotation": 4
    },
    {
      "x": 6,
      "y": 53,
      "z": 0,
      "name": "Plant_Leaves_Dead"
    },
    {
      "x": 6,
      "y": 54,
      "z": 0,
      "name": "Plant_Leaves_Dead"
    },
    {
      "x": 6,
      "y": 17,
      "z": 1,
      "name": "Rock_Shale"
    },
    {
      "x": 6,
      "y": 18,
      "z": 1,
      "name": "Rock_Shale"
    },
    {
      "x": 6,
      "y": 19,
      "z": 1,
      "name": "Rock_Shale"
    },
    {
      "x": 6,
      "y": 20,
      "z": 1,
      "name": "Rock_Shale"
    },
    {
      "x": 6,
      "y": 21,
      "z": 1,
      "name": "Rock_Shale"
    },
    {
      "x": 6,
      "y": 22,
      "z": 1,
      "name": "Rock_Shale"
    },
    {
      "x": 6,
      "y": 23,
      "z": 1,
      "name": "Rock_Shale"
    },
    {
      "x": 6,
      "y": 24,
      "z": 1,
      "name": "Rock_Shale"
    },
    {
      "x": 6,
      "y": 25,
      "z": 1,
      "name": "Rock_Shale"
    },
    {
      "x": 6,
      "y": 26,
      "z": 1,
      "name": "Rock_Shale"
    },
    {
      "x": 6,
      "y": 27,
      "z": 1,
      "name": "Rock_Shale"
    },
    {
      "x": 6,
      "y": 28,
      "z": 1,
      "name": "Rock_Shale"
    },
    {
      "x": 6,
      "y": 29,
      "z": 1,
      "name": "Rock_Shale"
    },
    {
      "x": 6,
      "y": 30,
      "z": 1,
      "name": "Soil_Dirt_Cold"
    },
    {
      "x": 6,
      "y": 31,
      "z": 1,
      "name": "Soil_Dirt_Cold"
    },
    {
      "x": 6,
      "y": 32,
      "z": 1,
      "name": "Wood_Fir_Trunk_Full"
    },
    {
      "x": 6,
      "y": 33,
      "z": 1,
      "name": "Wood_Fir_Trunk"
    },
    {
      "x": 6,
      "y": 34,
      "z": 1,
      "name": "Wood_Fir_Trunk"
    },
    {
      "x": 6,
      "y": 35,
      "z": 1,
      "name": "Wood_Fir_Trunk"
    },
    {
      "x": 6,
      "y": 36,
      "z": 1,
      "name": "Wood_Fir_Trunk"
    },
    {
      "x": 6,
      "y": 37,
      "z": 1,
      "name": "Wood_Fir_Trunk"
    },
    {
      "x": 6,
      "y": 38,
      "z": 1,
      "name": "Wood_Fir_Trunk"
    },
    {
      "x": 6,
      "y": 39,
      "z": 1,
      "name": "Wood_Fir_Trunk"
    },
    {
      "x": 6,
      "y": 40,
      "z": 1,
      "name": "Wood_Fir_Trunk"
    },
    {
      "x": 6,
      "y": 41,
      "z": 1,
      "name": "Wood_Fir_Trunk"
    },
    {
      "x": 6,
      "y": 42,
      "z": 1,
      "name": "Wood_Fir_Trunk"
    },
    {
      "x": 6,
      "y": 43,
      "z": 1,
      "name": "Wood_Fir_Trunk"
    },
    {
      "x": 6,
      "y": 44,
      "z": 1,
      "name": "Wood_Fir_Trunk"
    },
    {
      "x": 6,
      "y": 45,
      "z": 1,
      "name": "Wood_Fir_Trunk"
    },
    {
      "x": 6,
      "y": 46,
      "z": 1,
      "name": "Wood_Fir_Trunk"
    },
    {
      "x": 6,
      "y": 47,
      "z": 1,
      "name": "Wood_Fir_Trunk"
    },
    {
      "x": 6,
      "y": 48,
      "z": 1,
      "name": "Wood_Fir_Trunk"
    },
    {
      "x": 6,
      "y": 49,
      "z": 1,
      "name": "Wood_Fir_Trunk"
    },
    {
      "x": 6,
      "y": 50,
      "z": 1,
      "name": "Wood_Fir_Trunk"
    },
    {
      "x": 6,
      "y": 51,
      "z": 1,
      "name": "Wood_Fir_Trunk"
    },
    {
      "x": 6,
      "y": 52,
      "z": 1,
      "name": "Wood_Fir_Trunk"
    },
    {
      "x": 6,
      "y": 53,
      "z": 1,
      "name": "Wood_Fir_Trunk"
    },
    {
      "x": 6,
      "y": 54,
      "z": 1,
      "name": "Wood_Fir_Trunk_Full"
    },
    {
      "x": 6,
      "y": 55,
      "z": 1,
      "name": "Plant_Leaves_Dead"
    },
    {
      "x": 6,
      "y": 56,
      "z": 1,
      "name": "Plant_Leaves_Dead"
    },
    {
      "x": 6,
      "y": 57,
      "z": 1,
      "name": "Plant_Leaves_Dead"
    },
    {
      "x": 6,
      "y": 24,
      "z": 2,
      "name": "Rock_Shale"
    },
    {
      "x": 6,
      "y": 25,
      "z": 2,
      "name": "Rock_Shale"
    },
    {
      "x": 6,
      "y": 26,
      "z": 2,
      "name": "Wood_Fir_Roots"
    },
    {
      "x": 6,
      "y": 27,
      "z": 2,
      "name": "Wood_Fir_Trunk_Full"
    },
    {
      "x": 6,
      "y": 28,
      "z": 2,
      "name": "Wood_Fir_Trunk"
    },
    {
      "x": 6,
      "y": 29,
      "z": 2,
      "name": "Wood_Fir_Trunk"
    },
    {
      "x": 6,
      "y": 30,
      "z": 2,
      "name": "Wood_Fir_Trunk"
    },
    {
      "x": 6,
      "y": 31,
      "z": 2,
      "name": "Wood_Fir_Trunk"
    },
    {
      "x": 6,
      "y": 32,
      "z": 2,
      "name": "Wood_Fir_Trunk"
    },
    {
      "x": 6,
      "y": 33,
      "z": 2,
      "name": "Wood_Fir_Trunk"
    },
    {
      "x": 6,
      "y": 34,
      "z": 2,
      "name": "Wood_Fir_Trunk"
    },
    {
      "x": 6,
      "y": 35,
      "z": 2,
      "name": "Wood_Fir_Trunk_Full"
    },
    {
      "x": 6,
      "y": 40,
      "z": 2,
      "name": "Wood_Fir_Branch_Long",
      "rotation": 4
    },
    {
      "x": 6,
      "y": 41,
      "z": 2,
      "name": "Plant_Leaves_Dead"
    },
    {
      "x": 6,
      "y": 44,
      "z": 2,
      "name": "Wood_Fir_Branch_Long",
      "rotation": 4
    },
    {
      "x": 6,
      "y": 45,
      "z": 2,
      "name": "Plant_Leaves_Dead"
    },
    {
      "x": 6,
      "y": 46,
      "z": 2,
      "name": "Plant_Leaves_Dead"
    },
    {
      "x": 6,
      "y": 49,
      "z": 2,
      "name": "Wood_Fir_Branch_Long",
      "rotation": 4
    },
    {
      "x": 6,
      "y": 50,
      "z": 2,
      "name": "Plant_Leaves_Dead"
    },
    {
      "x": 6,
      "y": 51,
      "z": 2,
      "name": "Wood_Fir_Branch_Long",
      "rotation": 4
    },
    {
      "x": 6,
      "y": 52,
      "z": 2,
      "name": "Plant_Leaves_Dead"
    },
    {
      "x": 6,
      "y": 53,
      "z": 2,
      "name": "Plant_Leaves_Dead"
    },
    {
      "x": 6,
      "y": 54,
      "z": 2,
      "name": "Plant_Leaves_Dead"
    },
    {
      "x": 6,
      "y": 28,
      "z": 3,
      "name": "Rock_Shale"
    },
    {
      "x": 6,
      "y": 29,
      "z": 3,
      "name": "Rock_Shale"
    },
    {
      "x": 6,
      "y": 30,
      "z": 3,
      "name": "Rock_Shale"
    },
    {
      "x": 6,
      "y": 31,
      "z": 3,
      "name": "Rock_Shale"
    },
    {
      "x": 6,
      "y": 32,
      "z": 3,
      "name": "Rock_Shale"
    },
    {
      "x": 6,
      "y": 33,
      "z": 3,
      "name": "Soil_Grass_Cold"
    },
    {
      "x": 6,
      "y": 40,
      "z": 3,
      "name": "Wood_Fir_Branch_Long",
      "rotation": 4
    },
    {
      "x": 6,
      "y": 41,
      "z": 3,
      "name": "Plant_Leaves_Dead"
    },
    {
      "x": 6,
      "y": 44,
      "z": 3,
      "name": "Plant_Leaves_Dead"
    },
    {
      "x": 6,
      "y": 48,
      "z": 3,
      "name": "Plant_Leaves_Dead"
    },
    {
      "x": 6,
      "y": 49,
      "z": 3,
      "name": "Plant_Leaves_Dead"
    },
    {
      "x": 6,
      "y": 52,
      "z": 3,
      "name": "Plant_Leaves_Dead"
    },
    {
      "x": 6,
      "y": 28,
      "z": 4,
      "name": "Rock_Shale"
    },
    {
      "x": 6,
      "y": 29,
      "z": 4,
      "name": "Rock_Shale"
    },
    {
      "x": 6,
      "y": 30,
      "z": 4,
      "name": "Rock_Shale"
    },
    {
      "x": 6,
      "y": 31,
      "z": 4,
      "name": "Rock_Shale"
    },
    {
      "x": 6,
      "y": 32,
      "z": 4,
      "name": "Soil_Grass_Cold"
    },
    {
      "x": 6,
      "y": 39,
      "z": 4,
      "name": "Plant_Leaves_Dead"
    },
    {
      "x": 6,
      "y": 40,
      "z": 4,
      "name": "Plant_Leaves_Dead"
    },
    {
      "x": 6,
      "y": 47,
      "z": 4,
      "name": "Plant_Leaves_Dead"
    },
    {
      "x": 6,
      "y": 48,
      "z": 4,
      "name": "Plant_Leaves_Dead"
    },
    {
      "x": 6,
      "y": 31,
      "z": 5,
      "name": "Rock_Shale"
    },
    {
      "x": 6,
      "y": 32,
      "z": 5,
      "name": "Soil_Grass_Cold"
    },
    {
      "x": 6,
      "y": 33,
      "z": 5,
      "name": "Plant_Grass_Winter"
    },
    {
      "x": 6,
      "y": 39,
      "z": 5,
      "name": "Plant_Leaves_Dead"
    },
    {
      "x": 6,
      "y": 47,
      "z": 5,
      "name": "Plant_Leaves_Dead"
    },
    {
      "x": 7,
      "y": 27,
      "z": -4,
      "name": "Rock_Shale"
    },
    {
      "x": 7,
      "y": 28,
      "z": -4,
      "name": "Rock_Shale"
    },
    {
      "x": 7,
      "y": 20,
      "z": -3,
      "name": "Rock_Shale"
    },
    {
      "x": 7,
      "y": 21,
      "z": -3,
      "name": "Rock_Shale"
    },
    {
      "x": 7,
      "y": 22,
      "z": -3,
      "name": "Rock_Shale"
    },
    {
      "x": 7,
      "y": 23,
      "z": -3,
      "name": "Rock_Shale"
    },
    {
      "x": 7,
      "y": 24,
      "z": -3,
      "name": "Rock_Shale"
    },
    {
      "x": 7,
      "y": 25,
      "z": -3,
      "name": "Rock_Shale"
    },
    {
      "x": 7,
      "y": 26,
      "z": -3,
      "name": "Rock_Shale"
    },
    {
      "x": 7,
      "y": 27,
      "z": -3,
      "name": "Rock_Shale"
    },
    {
      "x": 7,
      "y": 28,
      "z": -3,
      "name": "Rock_Shale"
    },
    {
      "x": 7,
      "y": 29,
      "z": -3,
      "name": "Rock_Shale"
    },
    {
      "x": 7,
      "y": 30,
      "z": -3,
      "name": "Soil_Dirt_Cold"
    },
    {
      "x": 7,
      "y": 15,
      "z": -2,
      "name": "Rock_Shale"
    },
    {
      "x": 7,
      "y": 16,
      "z": -2,
      "name": "Rock_Shale"
    },
    {
      "x": 7,
      "y": 17,
      "z": -2,
      "name": "Rock_Shale"
    },
    {
      "x": 7,
      "y": 18,
      "z": -2,
      "name": "Rock_Shale"
    },
    {
      "x": 7,
      "y": 19,
      "z": -2,
      "name": "Rock_Shale"
    },
    {
      "x": 7,
      "y": 20,
      "z": -2,
      "name": "Rock_Shale"
    },
    {
      "x": 7,
      "y": 21,
      "z": -2,
      "name": "Rock_Shale"
    },
    {
      "x": 7,
      "y": 22,
      "z": -2,
      "name": "Rock_Shale"
    },
    {
      "x": 7,
      "y": 23,
      "z": -2,
      "name": "Rock_Shale"
    },
    {
      "x": 7,
      "y": 24,
      "z": -2,
      "name": "Rock_Shale"
    },
    {
      "x": 7,
      "y": 25,
      "z": -2,
      "name": "Rock_Shale"
    },
    {
      "x": 7,
      "y": 26,
      "z": -2,
      "name": "Rock_Shale"
    },
    {
      "x": 7,
      "y": 27,
      "z": -2,
      "name": "Rock_Shale"
    },
    {
      "x": 7,
      "y": 28,
      "z": -2,
      "name": "Rock_Shale"
    },
    {
      "x": 7,
      "y": 29,
      "z": -2,
      "name": "Rock_Shale"
    },
    {
      "x": 7,
      "y": 30,
      "z": -2,
      "name": "Soil_Dirt_Cold"
    },
    {
      "x": 7,
      "y": 31,
      "z": -2,
      "name": "Soil_Dirt_Cold"
    },
    {
      "x": 7,
      "y": 32,
      "z": -2,
      "name": "Soil_Grass_Cold"
    },
    {
      "x": 7,
      "y": 41,
      "z": -2,
      "name": "Plant_Leaves_Dead"
    },
    {
      "x": 7,
      "y": 15,
      "z": -1,
      "name": "Rock_Shale"
    },
    {
      "x": 7,
      "y": 16,
      "z": -1,
      "name": "Rock_Shale"
    },
    {
      "x": 7,
      "y": 17,
      "z": -1,
      "name": "Rock_Shale"
    },
    {
      "x": 7,
      "y": 18,
      "z": -1,
      "name": "Rock_Shale"
    },
    {
      "x": 7,
      "y": 19,
      "z": -1,
      "name": "Rock_Shale"
    },
    {
      "x": 7,
      "y": 20,
      "z": -1,
      "name": "Rock_Shale"
    },
    {
      "x": 7,
      "y": 21,
      "z": -1,
      "name": "Rock_Shale"
    },
    {
      "x": 7,
      "y": 22,
      "z": -1,
      "name": "Rock_Shale"
    },
    {
      "x": 7,
      "y": 23,
      "z": -1,
      "name": "Rock_Shale"
    },
    {
      "x": 7,
      "y": 24,
      "z": -1,
      "name": "Rock_Shale"
    },
    {
      "x": 7,
      "y": 25,
      "z": -1,
      "name": "Rock_Shale"
    },
    {
      "x": 7,
      "y": 26,
      "z": -1,
      "name": "Rock_Shale"
    },
    {
      "x": 7,
      "y": 27,
      "z": -1,
      "name": "Rock_Shale"
    },
    {
      "x": 7,
      "y": 28,
      "z": -1,
      "name": "Rock_Shale"
    },
    {
      "x": 7,
      "y": 29,
      "z": -1,
      "name": "Rock_Shale"
    },
    {
      "x": 7,
      "y": 30,
      "z": -1,
      "name": "Soil_Dirt_Cold"
    },
    {
      "x": 7,
      "y": 31,
      "z": -1,
      "name": "Soil_Dirt_Cold"
    },
    {
      "x": 7,
      "y": 32,
      "z": -1,
      "name": "Soil_Dirt_Cold"
    },
    {
      "x": 7,
      "y": 33,
      "z": -1,
      "name": "Soil_Dirt_Cold"
    },
    {
      "x": 7,
      "y": 34,
      "z": -1,
      "name": "Soil_Dirt_Cold"
    },
    {
      "x": 7,
      "y": 35,
      "z": -1,
      "name": "Soil_Grass_Cold"
    },
    {
      "x": 7,
      "y": 41,
      "z": -1,
      "name": "Plant_Leaves_Dead"
    },
    {
      "x": 7,
      "y": 42,
      "z": -1,
      "name": "Plant_Leaves_Dead"
    },
    {
      "x": 7,
      "y": 45,
      "z": -1,
      "name": "Plant_Leaves_Dead"
    },
    {
      "x": 7,
      "y": 48,
      "z": -1,
      "name": "Plant_Leaves_Dead"
    },
    {
      "x": 7,
      "y": 15,
      "z": 0,
      "name": "Rock_Shale"
    },
    {
      "x": 7,
      "y": 16,
      "z": 0,
      "name": "Rock_Shale"
    },
    {
      "x": 7,
      "y": 17,
      "z": 0,
      "name": "Rock_Shale"
    },
    {
      "x": 7,
      "y": 18,
      "z": 0,
      "name": "Rock_Shale"
    },
    {
      "x": 7,
      "y": 19,
      "z": 0,
      "name": "Rock_Shale"
    },
    {
      "x": 7,
      "y": 20,
      "z": 0,
      "name": "Rock_Shale"
    },
    {
      "x": 7,
      "y": 21,
      "z": 0,
      "name": "Rock_Shale"
    },
    {
      "x": 7,
      "y": 22,
      "z": 0,
      "name": "Rock_Shale"
    },
    {
      "x": 7,
      "y": 23,
      "z": 0,
      "name": "Rock_Shale"
    },
    {
      "x": 7,
      "y": 24,
      "z": 0,
      "name": "Rock_Shale"
    },
    {
      "x": 7,
      "y": 25,
      "z": 0,
      "name": "Rock_Shale"
    },
    {
      "x": 7,
      "y": 26,
      "z": 0,
      "name": "Rock_Shale"
    },
    {
      "x": 7,
      "y": 27,
      "z": 0,
      "name": "Rock_Shale"
    },
    {
      "x": 7,
      "y": 28,
      "z": 0,
      "name": "Rock_Shale"
    },
    {
      "x": 7,
      "y": 29,
      "z": 0,
      "name": "Rock_Shale"
    },
    {
      "x": 7,
      "y": 30,
      "z": 0,
      "name": "Soil_Dirt_Cold"
    },
    {
      "x": 7,
      "y": 31,
      "z": 0,
      "name": "Wood_Fir_Trunk_Full"
    },
    {
      "x": 7,
      "y": 32,
      "z": 0,
      "name": "Wood_Fir_Trunk"
    },
    {
      "x": 7,
      "y": 33,
      "z": 0,
      "name": "Wood_Fir_Trunk"
    },
    {
      "x": 7,
      "y": 34,
      "z": 0,
      "name": "Wood_Fir_Trunk"
    },
    {
      "x": 7,
      "y": 35,
      "z": 0,
      "name": "Wood_Fir_Trunk_Full"
    },
    {
      "x": 7,
      "y": 36,
      "z": 0,
      "name": "Plant_Grass_Winter"
    },
    {
      "x": 7,
      "y": 41,
      "z": 0,
      "name": "Plant_Leaves_Dead"
    },
    {
      "x": 7,
      "y": 42,
      "z": 0,
      "name": "Plant_Leaves_Dead"
    },
    {
      "x": 7,
      "y": 45,
      "z": 0,
      "name": "Plant_Leaves_Dead"
    },
    {
      "x": 7,
      "y": 46,
      "z": 0,
      "name": "Plant_Leaves_Dead"
    },
    {
      "x": 7,
      "y": 48,
      "z": 0,
      "name": "Plant_Leaves_Dead"
    },
    {
      "x": 7,
      "y": 49,
      "z": 0,
      "name": "Plant_Leaves_Dead"
    },
    {
      "x": 7,
      "y": 52,
      "z": 0,
      "name": "Plant_Leaves_Dead"
    },
    {
      "x": 7,
      "y": 16,
      "z": 1,
      "name": "Rock_Shale"
    },
    {
      "x": 7,
      "y": 17,
      "z": 1,
      "name": "Rock_Shale"
    },
    {
      "x": 7,
      "y": 19,
      "z": 1,
      "name": "Rock_Shale"
    },
    {
      "x": 7,
      "y": 20,
      "z": 1,
      "name": "Rock_Shale"
    },
    {
      "x": 7,
      "y": 21,
      "z": 1,
      "name": "Rock_Shale"
    },
    {
      "x": 7,
      "y": 22,
      "z": 1,
      "name": "Rock_Shale"
    },
    {
      "x": 7,
      "y": 23,
      "z": 1,
      "name": "Rock_Shale"
    },
    {
      "x": 7,
      "y": 24,
      "z": 1,
      "name": "Rock_Shale"
    },
    {
      "x": 7,
      "y": 25,
      "z": 1,
      "name": "Rock_Shale"
    },
    {
      "x": 7,
      "y": 26,
      "z": 1,
      "name": "Rock_Shale"
    },
    {
      "x": 7,
      "y": 27,
      "z": 1,
      "name": "Rock_Shale"
    },
    {
      "x": 7,
      "y": 28,
      "z": 1,
      "name": "Rock_Shale"
    },
    {
      "x": 7,
      "y": 29,
      "z": 1,
      "name": "Rock_Shale"
    },
    {
      "x": 7,
      "y": 30,
      "z": 1,
      "name": "Soil_Dirt_Cold"
    },
    {
      "x": 7,
      "y": 31,
      "z": 1,
      "name": "Soil_Dirt_Cold"
    },
    {
      "x": 7,
      "y": 32,
      "z": 1,
      "name": "Soil_Dirt_Cold"
    },
    {
      "x": 7,
      "y": 33,
      "z": 1,
      "name": "Wood_Fir_Trunk_Full"
    },
    {
      "x": 7,
      "y": 34,
      "z": 1,
      "name": "Wood_Fir_Trunk"
    },
    {
      "x": 7,
      "y": 35,
      "z": 1,
      "name": "Wood_Fir_Trunk"
    },
    {
      "x": 7,
      "y": 36,
      "z": 1,
      "name": "Wood_Fir_Trunk"
    },
    {
      "x": 7,
      "y": 37,
      "z": 1,
      "name": "Wood_Fir_Trunk_Full"
    },
    {
      "x": 7,
      "y": 41,
      "z": 1,
      "name": "Wood_Fir_Branch_Long",
      "rotation": 5
    },
    {
      "x": 7,
      "y": 42,
      "z": 1,
      "name": "Plant_Leaves_Dead"
    },
    {
      "x": 7,
      "y": 43,
      "z": 1,
      "name": "Plant_Leaves_Dead"
    },
    {
      "x": 7,
      "y": 45,
      "z": 1,
      "name": "Wood_Fir_Branch_Long",
      "rotation": 5
    },
    {
      "x": 7,
      "y": 46,
      "z": 1,
      "name": "Plant_Leaves_Dead"
    },
    {
      "x": 7,
      "y": 48,
      "z": 1,
      "name": "Wood_Fir_Branch_Long",
      "rotation": 5
    },
    {
      "x": 7,
      "y": 49,
      "z": 1,
      "name": "Plant_Leaves_Dead"
    },
    {
      "x": 7,
      "y": 52,
      "z": 1,
      "name": "Wood_Fir_Branch_Long",
      "rotation": 5
    },
    {
      "x": 7,
      "y": 53,
      "z": 1,
      "name": "Plant_Leaves_Dead"
    },
    {
      "x": 7,
      "y": 54,
      "z": 1,
      "name": "Plant_Leaves_Dead"
    },
    {
      "x": 7,
      "y": 22,
      "z": 2,
      "name": "Rock_Shale"
    },
    {
      "x": 7,
      "y": 23,
      "z": 2,
      "name": "Rock_Shale"
    },
    {
      "x": 7,
      "y": 24,
      "z": 2,
      "name": "Rock_Shale"
    },
    {
      "x": 7,
      "y": 25,
      "z": 2,
      "name": "Rock_Shale"
    },
    {
      "x": 7,
      "y": 26,
      "z": 2,
      "name": "Rock_Shale"
    },
    {
      "x": 7,
      "y": 27,
      "z": 2,
      "name": "Rock_Shale"
    },
    {
      "x": 7,
      "y": 28,
      "z": 2,
      "name": "Rock_Shale"
    },
    {
      "x": 7,
      "y": 29,
      "z": 2,
      "name": "Wood_Fir_Roots"
    },
    {
      "x": 7,
      "y": 30,
      "z": 2,
      "name": "Wood_Fir_Trunk_Full"
    },
    {
      "x": 7,
      "y": 31,
      "z": 2,
      "name": "Soil_Dirt_Cold"
    },
    {
      "x": 7,
      "y": 32,
      "z": 2,
      "name": "Soil_Dirt_Cold"
    },
    {
      "x": 7,
      "y": 33,
      "z": 2,
      "name": "Soil_Dirt_Cold"
    },
    {
      "x": 7,
      "y": 34,
      "z": 2,
      "name": "Soil_Dirt_Cold"
    },
    {
      "x": 7,
      "y": 35,
      "z": 2,
      "name": "Soil_Grass_Cold"
    },
    {
      "x": 7,
      "y": 41,
      "z": 2,
      "name": "Plant_Leaves_Dead"
    },
    {
      "x": 7,
      "y": 44,
      "z": 2,
      "name": "Plant_Leaves_Dead"
    },
    {
      "x": 7,
      "y": 45,
      "z": 2,
      "name": "Plant_Leaves_Dead"
    },
    {
      "x": 7,
      "y": 49,
      "z": 2,
      "name": "Plant_Leaves_Dead"
    },
    {
      "x": 7,
      "y": 52,
      "z": 2,
      "name": "Plant_Leaves_Dead"
    },
    {
      "x": 7,
      "y": 53,
      "z": 2,
      "name": "Plant_Leaves_Dead"
    },
    {
      "x": 7,
      "y": 25,
      "z": 3,
      "name": "Rock_Shale"
    },
    {
      "x": 7,
      "y": 26,
      "z": 3,
      "name": "Rock_Shale"
    },
    {
      "x": 7,
      "y": 27,
      "z": 3,
      "name": "Rock_Shale"
    },
    {
      "x": 7,
      "y": 28,
      "z": 3,
      "name": "Rock_Shale"
    },
    {
      "x": 7,
      "y": 29,
      "z": 3,
      "name": "Rock_Shale"
    },
    {
      "x": 7,
      "y": 30,
      "z": 3,
      "name": "Rock_Shale"
    },
    {
      "x": 7,
      "y": 31,
      "z": 3,
      "name": "Rock_Shale"
    },
    {
      "x": 7,
      "y": 32,
      "z": 3,
      "name": "Rock_Shale"
    },
    {
      "x": 7,
      "y": 33,
      "z": 3,
      "name": "Soil_Dirt_Cold"
    },
    {
      "x": 7,
      "y": 34,
      "z": 3,
      "name": "Soil_Dirt_Cold"
    },
    {
      "x": 7,
      "y": 35,
      "z": 3,
      "name": "Soil_Grass_Cold"
    },
    {
      "x": 7,
      "y": 40,
      "z": 3,
      "name": "Plant_Leaves_Dead"
    },
    {
      "x": 7,
      "y": 43,
      "z": 3,
      "name": "Plant_Leaves_Dead"
    },
    {
      "x": 7,
      "y": 44,
      "z": 3,
      "name": "Plant_Leaves_Dead"
    },
    {
      "x": 7,
      "y": 48,
      "z": 3,
      "name": "Plant_Leaves_Dead"
    },
    {
      "x": 7,
      "y": 51,
      "z": 3,
      "name": "Plant_Leaves_Dead"
    },
    {
      "x": 7,
      "y": 27,
      "z": 4,
      "name": "Rock_Shale"
    },
    {
      "x": 7,
      "y": 28,
      "z": 4,
      "name": "Rock_Shale"
    },
    {
      "x": 7,
      "y": 29,
      "z": 4,
      "name": "Rock_Shale"
    },
    {
      "x": 7,
      "y": 30,
      "z": 4,
      "name": "Rock_Shale"
    },
    {
      "x": 7,
      "y": 31,
      "z": 4,
      "name": "Rock_Shale"
    },
    {
      "x": 7,
      "y": 32,
      "z": 4,
      "name": "Rock_Shale"
    },
    {
      "x": 7,
      "y": 33,
      "z": 4,
      "name": "Soil_Dirt_Cold"
    },
    {
      "x": 7,
      "y": 34,
      "z": 4,
      "name": "Soil_Grass_Cold"
    },
    {
      "x": 7,
      "y": 39,
      "z": 4,
      "name": "Plant_Leaves_Dead"
    },
    {
      "x": 7,
      "y": 31,
      "z": 5,
      "name": "Rock_Shale"
    },
    {
      "x": 7,
      "y": 32,
      "z": 5,
      "name": "Rock_Shale"
    },
    {
      "x": 7,
      "y": 33,
      "z": 5,
      "name": "Soil_Dirt_Cold"
    },
    {
      "x": 7,
      "y": 34,
      "z": 5,
      "name": "Soil_Grass_Cold"
    },
    {
      "x": 8,
      "y": 27,
      "z": -4,
      "name": "Rock_Shale"
    },
    {
      "x": 8,
      "y": 28,
      "z": -4,
      "name": "Rock_Shale"
    },
    {
      "x": 8,
      "y": 29,
      "z": -4,
      "name": "Rock_Shale"
    },
    {
      "x": 8,
      "y": 30,
      "z": -4,
      "name": "Rock_Shale"
    },
    {
      "x": 8,
      "y": 31,
      "z": -4,
      "name": "Rock_Shale"
    },
    {
      "x": 8,
      "y": 25,
      "z": -3,
      "name": "Rock_Shale"
    },
    {
      "x": 8,
      "y": 26,
      "z": -3,
      "name": "Rock_Shale"
    },
    {
      "x": 8,
      "y": 27,
      "z": -3,
      "name": "Rock_Shale"
    },
    {
      "x": 8,
      "y": 28,
      "z": -3,
      "name": "Rock_Shale"
    },
    {
      "x": 8,
      "y": 29,
      "z": -3,
      "name": "Rock_Shale"
    },
    {
      "x": 8,
      "y": 30,
      "z": -3,
      "name": "Rock_Shale"
    },
    {
      "x": 8,
      "y": 31,
      "z": -3,
      "name": "Soil_Dirt_Cold"
    },
    {
      "x": 8,
      "y": 32,
      "z": -3,
      "name": "Soil_Dirt_Cold"
    },
    {
      "x": 8,
      "y": 33,
      "z": -3,
      "name": "Soil_Grass_Cold"
    },
    {
      "x": 8,
      "y": 34,
      "z": -3,
      "name": "Plant_Grass_Winter"
    },
    {
      "x": 8,
      "y": 14,
      "z": -2,
      "name": "Rock_Shale"
    },
    {
      "x": 8,
      "y": 15,
      "z": -2,
      "name": "Rock_Shale"
    },
    {
      "x": 8,
      "y": 16,
      "z": -2,
      "name": "Rock_Shale"
    },
    {
      "x": 8,
      "y": 17,
      "z": -2,
      "name": "Rock_Shale"
    },
    {
      "x": 8,
      "y": 18,
      "z": -2,
      "name": "Rock_Shale"
    },
    {
      "x": 8,
      "y": 19,
      "z": -2,
      "name": "Rock_Shale"
    },
    {
      "x": 8,
      "y": 20,
      "z": -2,
      "name": "Rock_Shale"
    },
    {
      "x": 8,
      "y": 21,
      "z": -2,
      "name": "Rock_Shale"
    },
    {
      "x": 8,
      "y": 22,
      "z": -2,
      "name": "Rock_Shale"
    },
    {
      "x": 8,
      "y": 23,
      "z": -2,
      "name": "Rock_Shale"
    },
    {
      "x": 8,
      "y": 24,
      "z": -2,
      "name": "Rock_Shale"
    },
    {
      "x": 8,
      "y": 25,
      "z": -2,
      "name": "Rock_Shale"
    },
    {
      "x": 8,
      "y": 26,
      "z": -2,
      "name": "Rock_Shale"
    },
    {
      "x": 8,
      "y": 27,
      "z": -2,
      "name": "Rock_Shale"
    },
    {
      "x": 8,
      "y": 28,
      "z": -2,
      "name": "Rock_Shale"
    },
    {
      "x": 8,
      "y": 29,
      "z": -2,
      "name": "Rock_Shale"
    },
    {
      "x": 8,
      "y": 30,
      "z": -2,
      "name": "Soil_Dirt_Cold"
    },
    {
      "x": 8,
      "y": 31,
      "z": -2,
      "name": "Soil_Dirt_Cold"
    },
    {
      "x": 8,
      "y": 32,
      "z": -2,
      "name": "Soil_Dirt_Cold"
    },
    {
      "x": 8,
      "y": 33,
      "z": -2,
      "name": "Soil_Dirt_Cold"
    },
    {
      "x": 8,
      "y": 34,
      "z": -2,
      "name": "Soil_Grass_Cold"
    },
    {
      "x": 8,
      "y": 44,
      "z": -2,
      "name": "Plant_Leaves_Dead"
    },
    {
      "x": 8,
      "y": 14,
      "z": -1,
      "name": "Rock_Shale"
    },
    {
      "x": 8,
      "y": 15,
      "z": -1,
      "name": "Rock_Shale"
    },
    {
      "x": 8,
      "y": 16,
      "z": -1,
      "name": "Rock_Shale"
    },
    {
      "x": 8,
      "y": 17,
      "z": -1,
      "name": "Rock_Shale"
    },
    {
      "x": 8,
      "y": 18,
      "z": -1,
      "name": "Rock_Shale"
    },
    {
      "x": 8,
      "y": 19,
      "z": -1,
      "name": "Rock_Shale"
    },
    {
      "x": 8,
      "y": 20,
      "z": -1,
      "name": "Rock_Shale"
    },
    {
      "x": 8,
      "y": 21,
      "z": -1,
      "name": "Rock_Shale"
    },
    {
      "x": 8,
      "y": 22,
      "z": -1,
      "name": "Rock_Shale"
    },
    {
      "x": 8,
      "y": 23,
      "z": -1,
      "name": "Rock_Shale"
    },
    {
      "x": 8,
      "y": 24,
      "z": -1,
      "name": "Rock_Shale"
    },
    {
      "x": 8,
      "y": 25,
      "z": -1,
      "name": "Rock_Shale"
    },
    {
      "x": 8,
      "y": 26,
      "z": -1,
      "name": "Rock_Shale"
    },
    {
      "x": 8,
      "y": 27,
      "z": -1,
      "name": "Rock_Shale"
    },
    {
      "x": 8,
      "y": 28,
      "z": -1,
      "name": "Rock_Shale"
    },
    {
      "x": 8,
      "y": 29,
      "z": -1,
      "name": "Rock_Shale"
    },
    {
      "x": 8,
      "y": 30,
      "z": -1,
      "name": "Soil_Dirt_Cold"
    },
    {
      "x": 8,
      "y": 31,
      "z": -1,
      "name": "Soil_Dirt_Cold"
    },
    {
      "x": 8,
      "y": 32,
      "z": -1,
      "name": "Soil_Dirt_Cold"
    },
    {
      "x": 8,
      "y": 33,
      "z": -1,
      "name": "Soil_Dirt_Cold"
    },
    {
      "x": 8,
      "y": 34,
      "z": -1,
      "name": "Soil_Dirt_Cold"
    },
    {
      "x": 8,
      "y": 35,
      "z": -1,
      "name": "Soil_Grass_Cold"
    },
    {
      "x": 8,
      "y": 44,
      "z": -1,
      "name": "Plant_Leaves_Dead"
    },
    {
      "x": 8,
      "y": 45,
      "z": -1,
      "name": "Plant_Leaves_Dead"
    },
    {
      "x": 8,
      "y": 14,
      "z": 0,
      "name": "Rock_Shale"
    },
    {
      "x": 8,
      "y": 15,
      "z": 0,
      "name": "Rock_Shale"
    },
    {
      "x": 8,
      "y": 16,
      "z": 0,
      "name": "Rock_Shale"
    },
    {
      "x": 8,
      "y": 19,
      "z": 0,
      "name": "Rock_Shale"
    },
    {
      "x": 8,
      "y": 20,
      "z": 0,
      "name": "Rock_Shale"
    },
    {
      "x": 8,
      "y": 21,
      "z": 0,
      "name": "Rock_Shale"
    },
    {
      "x": 8,
      "y": 22,
      "z": 0,
      "name": "Rock_Shale"
    },
    {
      "x": 8,
      "y": 23,
      "z": 0,
      "name": "Rock_Shale"
    },
    {
      "x": 8,
      "y": 24,
      "z": 0,
      "name": "Rock_Shale"
    },
    {
      "x": 8,
      "y": 25,
      "z": 0,
      "name": "Rock_Shale"
    },
    {
      "x": 8,
      "y": 26,
      "z": 0,
      "name": "Rock_Shale"
    },
    {
      "x": 8,
      "y": 27,
      "z": 0,
      "name": "Rock_Shale"
    },
    {
      "x": 8,
      "y": 28,
      "z": 0,
      "name": "Wood_Fir_Roots"
    },
    {
      "x": 8,
      "y": 29,
      "z": 0,
      "name": "Wood_Fir_Trunk_Full"
    },
    {
      "x": 8,
      "y": 30,
      "z": 0,
      "name": "Wood_Fir_Trunk"
    },
    {
      "x": 8,
      "y": 31,
      "z": 0,
      "name": "Wood_Fir_Trunk_Full"
    },
    {
      "x": 8,
      "y": 32,
      "z": 0,
      "name": "Soil_Dirt_Cold"
    },
    {
      "x": 8,
      "y": 33,
      "z": 0,
      "name": "Soil_Dirt_Cold"
    },
    {
      "x": 8,
      "y": 34,
      "z": 0,
      "name": "Soil_Dirt_Cold"
    },
    {
      "x": 8,
      "y": 35,
      "z": 0,
      "name": "Soil_Grass_Cold"
    },
    {
      "x": 8,
      "y": 36,
      "z": 0,
      "name": "Plant_Grass_Winter_Tall"
    },
    {
      "x": 8,
      "y": 37,
      "z": 0,
      "name": "Plant_Grass_Winter_Tall",
      "filler": 1024
    },
    {
      "x": 8,
      "y": 41,
      "z": 0,
      "name": "Plant_Leaves_Dead"
    },
    {
      "x": 8,
      "y": 45,
      "z": 0,
      "name": "Plant_Leaves_Dead"
    },
    {
      "x": 8,
      "y": 51,
      "z": 0,
      "name": "Plant_Leaves_Dead"
    },
    {
      "x": 8,
      "y": 15,
      "z": 1,
      "name": "Rock_Shale"
    },
    {
      "x": 8,
      "y": 20,
      "z": 1,
      "name": "Rock_Shale"
    },
    {
      "x": 8,
      "y": 21,
      "z": 1,
      "name": "Rock_Shale"
    },
    {
      "x": 8,
      "y": 22,
      "z": 1,
      "name": "Rock_Shale"
    },
    {
      "x": 8,
      "y": 23,
      "z": 1,
      "name": "Rock_Shale"
    },
    {
      "x": 8,
      "y": 24,
      "z": 1,
      "name": "Rock_Shale"
    },
    {
      "x": 8,
      "y": 25,
      "z": 1,
      "name": "Rock_Shale"
    },
    {
      "x": 8,
      "y": 26,
      "z": 1,
      "name": "Rock_Shale"
    },
    {
      "x": 8,
      "y": 27,
      "z": 1,
      "name": "Rock_Shale"
    },
    {
      "x": 8,
      "y": 28,
      "z": 1,
      "name": "Rock_Shale"
    },
    {
      "x": 8,
      "y": 29,
      "z": 1,
      "name": "Rock_Shale"
    },
    {
      "x": 8,
      "y": 30,
      "z": 1,
      "name": "Rock_Shale"
    },
    {
      "x": 8,
      "y": 31,
      "z": 1,
      "name": "Soil_Dirt_Cold"
    },
    {
      "x": 8,
      "y": 32,
      "z": 1,
      "name": "Soil_Dirt_Cold"
    },
    {
      "x": 8,
      "y": 33,
      "z": 1,
      "name": "Soil_Dirt_Cold"
    },
    {
      "x": 8,
      "y": 34,
      "z": 1,
      "name": "Soil_Dirt_Cold"
    },
    {
      "x": 8,
      "y": 35,
      "z": 1,
      "name": "Soil_Grass_Cold"
    },
    {
      "x": 8,
      "y": 36,
      "z": 1,
      "name": "Plant_Grass_Winter_Tall"
    },
    {
      "x": 8,
      "y": 37,
      "z": 1,
      "name": "Plant_Grass_Winter_Tall",
      "filler": 1024
    },
    {
      "x": 8,
      "y": 41,
      "z": 1,
      "name": "Wood_Fir_Branch_Long",
      "rotation": 5
    },
    {
      "x": 8,
      "y": 42,
      "z": 1,
      "name": "Plant_Leaves_Dead"
    },
    {
      "x": 8,
      "y": 45,
      "z": 1,
      "name": "Plant_Leaves_Dead"
    },
    {
      "x": 8,
      "y": 48,
      "z": 1,
      "name": "Plant_Leaves_Dead"
    },
    {
      "x": 8,
      "y": 52,
      "z": 1,
      "name": "Plant_Leaves_Dead"
    },
    {
      "x": 8,
      "y": 23,
      "z": 2,
      "name": "Rock_Shale"
    },
    {
      "x": 8,
      "y": 24,
      "z": 2,
      "name": "Rock_Shale"
    },
    {
      "x": 8,
      "y": 25,
      "z": 2,
      "name": "Rock_Shale"
    },
    {
      "x": 8,
      "y": 26,
      "z": 2,
      "name": "Rock_Shale"
    },
    {
      "x": 8,
      "y": 27,
      "z": 2,
      "name": "Rock_Shale"
    },
    {
      "x": 8,
      "y": 28,
      "z": 2,
      "name": "Rock_Shale"
    },
    {
      "x": 8,
      "y": 29,
      "z": 2,
      "name": "Rock_Shale"
    },
    {
      "x": 8,
      "y": 30,
      "z": 2,
      "name": "Rock_Shale"
    },
    {
      "x": 8,
      "y": 31,
      "z": 2,
      "name": "Rock_Shale"
    },
    {
      "x": 8,
      "y": 32,
      "z": 2,
      "name": "Soil_Dirt_Cold"
    },
    {
      "x": 8,
      "y": 33,
      "z": 2,
      "name": "Soil_Dirt_Cold"
    },
    {
      "x": 8,
      "y": 34,
      "z": 2,
      "name": "Soil_Dirt_Cold"
    },
    {
      "x": 8,
      "y": 35,
      "z": 2,
      "name": "Soil_Grass_Cold"
    },
    {
      "x": 8,
      "y": 41,
      "z": 2,
      "name": "Plant_Leaves_Dead"
    },
    {
      "x": 8,
      "y": 47,
      "z": 2,
      "name": "Plant_Leaves_Dead"
    },
    {
      "x": 8,
      "y": 48,
      "z": 2,
      "name": "Plant_Leaves_Dead"
    },
    {
      "x": 8,
      "y": 26,
      "z": 3,
      "name": "Rock_Shale"
    },
    {
      "x": 8,
      "y": 27,
      "z": 3,
      "name": "Rock_Shale"
    },
    {
      "x": 8,
      "y": 28,
      "z": 3,
      "name": "Rock_Shale"
    },
    {
      "x": 8,
      "y": 29,
      "z": 3,
      "name": "Rock_Shale"
    },
    {
      "x": 8,
      "y": 30,
      "z": 3,
      "name": "Rock_Shale"
    },
    {
      "x": 8,
      "y": 31,
      "z": 3,
      "name": "Rock_Shale"
    },
    {
      "x": 8,
      "y": 32,
      "z": 3,
      "name": "Soil_Dirt_Cold"
    },
    {
      "x": 8,
      "y": 33,
      "z": 3,
      "name": "Soil_Dirt_Cold"
    },
    {
      "x": 8,
      "y": 34,
      "z": 3,
      "name": "Soil_Dirt_Cold"
    },
    {
      "x": 8,
      "y": 35,
      "z": 3,
      "name": "Soil_Dirt_Poisoned"
    },
    {
      "x": 8,
      "y": 36,
      "z": 3,
      "name": "*Plant_Crop_Berry_Winter_Block_State_Definitions_StageFinal",
      "components": {
        "Components": {
          "FarmingBlock": {}
        }
      }
    },
    {
      "x": 8,
      "y": 43,
      "z": 3,
      "name": "Plant_Leaves_Dead"
    },
    {
      "x": 8,
      "y": 29,
      "z": 4,
      "name": "Rock_Shale"
    },
    {
      "x": 8,
      "y": 30,
      "z": 4,
      "name": "Rock_Shale"
    },
    {
      "x": 8,
      "y": 31,
      "z": 4,
      "name": "Rock_Shale"
    },
    {
      "x": 8,
      "y": 32,
      "z": 4,
      "name": "Soil_Dirt_Cold"
    },
    {
      "x": 8,
      "y": 33,
      "z": 4,
      "name": "Soil_Dirt_Cold"
    },
    {
      "x": 8,
      "y": 34,
      "z": 4,
      "name": "Soil_Dirt_Cold"
    },
    {
      "x": 8,
      "y": 35,
      "z": 4,
      "name": "Soil_Dirt_Poisoned"
    },
    {
      "x": 8,
      "y": 42,
      "z": 4,
      "name": "Plant_Leaves_Dead"
    },
    {
      "x": 8,
      "y": 30,
      "z": 5,
      "name": "Rock_Shale"
    },
    {
      "x": 8,
      "y": 31,
      "z": 5,
      "name": "Rock_Shale"
    },
    {
      "x": 8,
      "y": 32,
      "z": 5,
      "name": "Soil_Dirt_Cold"
    },
    {
      "x": 8,
      "y": 33,
      "z": 5,
      "name": "Soil_Dirt_Poisoned"
    },
    {
      "x": 8,
      "y": 34,
      "z": 5,
      "name": "Soil_Dirt_Poisoned"
    },
    {
      "x": 8,
      "y": 35,
      "z": 5,
      "name": "Soil_Dirt_Poisoned"
    },
    {
      "x": 8,
      "y": 32,
      "z": 6,
      "name": "Rock_Shale"
    },
    {
      "x": 8,
      "y": 33,
      "z": 6,
      "name": "Soil_Dirt_Poisoned"
    },
    {
      "x": 8,
      "y": 34,
      "z": 6,
      "name": "Soil_Dirt_Poisoned"
    },
    {
      "x": 8,
      "y": 35,
      "z": 6,
      "name": "Soil_Dirt_Poisoned"
    },
    {
      "x": 9,
      "y": 29,
      "z": -4,
      "name": "Rock_Shale"
    },
    {
      "x": 9,
      "y": 30,
      "z": -4,
      "name": "Rock_Shale"
    },
    {
      "x": 9,
      "y": 31,
      "z": -4,
      "name": "Rock_Shale"
    },
    {
      "x": 9,
      "y": 32,
      "z": -4,
      "name": "Rock_Shale"
    },
    {
      "x": 9,
      "y": 33,
      "z": -4,
      "name": "Soil_Dirt_Cold"
    },
    {
      "x": 9,
      "y": 34,
      "z": -4,
      "name": "Soil_Dirt_Cold"
    },
    {
      "x": 9,
      "y": 35,
      "z": -4,
      "name": "Soil_Grass_Cold"
    },
    {
      "x": 9,
      "y": 26,
      "z": -3,
      "name": "Rock_Shale"
    },
    {
      "x": 9,
      "y": 27,
      "z": -3,
      "name": "Rock_Shale"
    },
    {
      "x": 9,
      "y": 28,
      "z": -3,
      "name": "Rock_Shale"
    },
    {
      "x": 9,
      "y": 29,
      "z": -3,
      "name": "Rock_Shale"
    },
    {
      "x": 9,
      "y": 30,
      "z": -3,
      "name": "Rock_Shale"
    },
    {
      "x": 9,
      "y": 31,
      "z": -3,
      "name": "Rock_Shale"
    },
    {
      "x": 9,
      "y": 32,
      "z": -3,
      "name": "Soil_Dirt_Cold"
    },
    {
      "x": 9,
      "y": 33,
      "z": -3,
      "name": "Soil_Dirt_Cold"
    },
    {
      "x": 9,
      "y": 34,
      "z": -3,
      "name": "Soil_Dirt_Cold"
    },
    {
      "x": 9,
      "y": 35,
      "z": -3,
      "name": "Soil_Dirt_Cold"
    },
    {
      "x": 9,
      "y": 36,
      "z": -3,
      "name": "Soil_Grass_Cold"
    },
    {
      "x": 9,
      "y": 14,
      "z": -2,
      "name": "Rock_Shale"
    },
    {
      "x": 9,
      "y": 15,
      "z": -2,
      "name": "Rock_Shale"
    },
    {
      "x": 9,
      "y": 19,
      "z": -2,
      "name": "Rock_Shale"
    },
    {
      "x": 9,
      "y": 20,
      "z": -2,
      "name": "Rock_Shale"
    },
    {
      "x": 9,
      "y": 23,
      "z": -2,
      "name": "Rock_Shale"
    },
    {
      "x": 9,
      "y": 24,
      "z": -2,
      "name": "Rock_Shale"
    },
    {
      "x": 9,
      "y": 25,
      "z": -2,
      "name": "Rock_Shale"
    },
    {
      "x": 9,
      "y": 26,
      "z": -2,
      "name": "Rock_Shale"
    },
    {
      "x": 9,
      "y": 27,
      "z": -2,
      "name": "Rock_Shale"
    },
    {
      "x": 9,
      "y": 28,
      "z": -2,
      "name": "Rock_Shale"
    },
    {
      "x": 9,
      "y": 29,
      "z": -2,
      "name": "Rock_Shale"
    },
    {
      "x": 9,
      "y": 30,
      "z": -2,
      "name": "Rock_Shale"
    },
    {
      "x": 9,
      "y": 31,
      "z": -2,
      "name": "Soil_Dirt_Cold"
    },
    {
      "x": 9,
      "y": 32,
      "z": -2,
      "name": "Soil_Dirt_Cold"
    },
    {
      "x": 9,
      "y": 33,
      "z": -2,
      "name": "Soil_Dirt_Cold"
    },
    {
      "x": 9,
      "y": 34,
      "z": -2,
      "name": "Soil_Dirt_Cold"
    },
    {
      "x": 9,
      "y": 35,
      "z": -2,
      "name": "Soil_Dirt_Cold"
    },
    {
      "x": 9,
      "y": 36,
      "z": -2,
      "name": "Soil_Grass_Cold"
    },
    {
      "x": 9,
      "y": 13,
      "z": -1,
      "name": "Rock_Shale"
    },
    {
      "x": 9,
      "y": 14,
      "z": -1,
      "name": "Rock_Shale"
    },
    {
      "x": 9,
      "y": 15,
      "z": -1,
      "name": "Rock_Shale"
    },
    {
      "x": 9,
      "y": 16,
      "z": -1,
      "name": "Rock_Shale"
    },
    {
      "x": 9,
      "y": 17,
      "z": -1,
      "name": "Rock_Shale"
    },
    {
      "x": 9,
      "y": 19,
      "z": -1,
      "name": "Rock_Shale"
    },
    {
      "x": 9,
      "y": 20,
      "z": -1,
      "name": "Rock_Shale"
    },
    {
      "x": 9,
      "y": 21,
      "z": -1,
      "name": "Rock_Shale"
    },
    {
      "x": 9,
      "y": 22,
      "z": -1,
      "name": "Rock_Shale"
    },
    {
      "x": 9,
      "y": 23,
      "z": -1,
      "name": "Rock_Shale"
    },
    {
      "x": 9,
      "y": 24,
      "z": -1,
      "name": "Rock_Shale"
    },
    {
      "x": 9,
      "y": 25,
      "z": -1,
      "name": "Rock_Shale"
    },
    {
      "x": 9,
      "y": 26,
      "z": -1,
      "name": "Rock_Shale"
    },
    {
      "x": 9,
      "y": 27,
      "z": -1,
      "name": "Rock_Shale"
    },
    {
      "x": 9,
      "y": 28,
      "z": -1,
      "name": "Rock_Shale"
    },
    {
      "x": 9,
      "y": 29,
      "z": -1,
      "name": "Rock_Shale"
    },
    {
      "x": 9,
      "y": 30,
      "z": -1,
      "name": "Rock_Shale"
    },
    {
      "x": 9,
      "y": 31,
      "z": -1,
      "name": "Soil_Dirt_Cold"
    },
    {
      "x": 9,
      "y": 32,
      "z": -1,
      "name": "Soil_Dirt_Cold"
    },
    {
      "x": 9,
      "y": 33,
      "z": -1,
      "name": "Soil_Dirt_Cold"
    },
    {
      "x": 9,
      "y": 34,
      "z": -1,
      "name": "Soil_Dirt_Cold"
    },
    {
      "x": 9,
      "y": 35,
      "z": -1,
      "name": "Soil_Grass_Cold"
    },
    {
      "x": 9,
      "y": 13,
      "z": 0,
      "name": "Rock_Shale"
    },
    {
      "x": 9,
      "y": 14,
      "z": 0,
      "name": "Rock_Shale"
    },
    {
      "x": 9,
      "y": 20,
      "z": 0,
      "name": "Rock_Shale"
    },
    {
      "x": 9,
      "y": 21,
      "z": 0,
      "name": "Rock_Shale"
    },
    {
      "x": 9,
      "y": 22,
      "z": 0,
      "name": "Rock_Shale"
    },
    {
      "x": 9,
      "y": 23,
      "z": 0,
      "name": "Rock_Shale"
    },
    {
      "x": 9,
      "y": 24,
      "z": 0,
      "name": "Rock_Shale"
    },
    {
      "x": 9,
      "y": 25,
      "z": 0,
      "name": "Rock_Shale"
    },
    {
      "x": 9,
      "y": 26,
      "z": 0,
      "name": "Rock_Shale"
    },
    {
      "x": 9,
      "y": 27,
      "z": 0,
      "name": "Rock_Shale"
    },
    {
      "x": 9,
      "y": 28,
      "z": 0,
      "name": "Rock_Shale"
    },
    {
      "x": 9,
      "y": 29,
      "z": 0,
      "name": "Rock_Shale"
    },
    {
      "x": 9,
      "y": 30,
      "z": 0,
      "name": "Rock_Shale"
    },
    {
      "x": 9,
      "y": 31,
      "z": 0,
      "name": "Soil_Dirt_Cold"
    },
    {
      "x": 9,
      "y": 32,
      "z": 0,
      "name": "Soil_Dirt_Cold"
    },
    {
      "x": 9,
      "y": 33,
      "z": 0,
      "name": "Soil_Dirt_Cold"
    },
    {
      "x": 9,
      "y": 34,
      "z": 0,
      "name": "Soil_Dirt_Cold"
    },
    {
      "x": 9,
      "y": 35,
      "z": 0,
      "name": "Soil_Grass_Cold"
    },
    {
      "x": 9,
      "y": 36,
      "z": 0,
      "name": "Plant_Grass_Winter_Tall"
    },
    {
      "x": 9,
      "y": 37,
      "z": 0,
      "name": "Plant_Grass_Winter_Tall",
      "filler": 1024
    },
    {
      "x": 9,
      "y": 40,
      "z": 0,
      "name": "Plant_Leaves_Dead"
    },
    {
      "x": 9,
      "y": 14,
      "z": 1,
      "name": "Rock_Shale"
    },
    {
      "x": 9,
      "y": 24,
      "z": 1,
      "name": "Rock_Shale"
    },
    {
      "x": 9,
      "y": 25,
      "z": 1,
      "name": "Rock_Shale"
    },
    {
      "x": 9,
      "y": 26,
      "z": 1,
      "name": "Rock_Shale"
    },
    {
      "x": 9,
      "y": 27,
      "z": 1,
      "name": "Rock_Shale"
    },
    {
      "x": 9,
      "y": 28,
      "z": 1,
      "name": "Rock_Shale"
    },
    {
      "x": 9,
      "y": 29,
      "z": 1,
      "name": "Rock_Shale"
    },
    {
      "x": 9,
      "y": 30,
      "z": 1,
      "name": "Rock_Shale"
    },
    {
      "x": 9,
      "y": 31,
      "z": 1,
      "name": "Rock_Shale"
    },
    {
      "x": 9,
      "y": 32,
      "z": 1,
      "name": "Soil_Dirt_Cold"
    },
    {
      "x": 9,
      "y": 33,
      "z": 1,
      "name": "Soil_Dirt_Cold"
    },
    {
      "x": 9,
      "y": 34,
      "z": 1,
      "name": "Soil_Dirt_Cold"
    },
    {
      "x": 9,
      "y": 35,
      "z": 1,
      "name": "Soil_Grass_Cold"
    },
    {
      "x": 9,
      "y": 40,
      "z": 1,
      "name": "Plant_Leaves_Dead"
    },
    {
      "x": 9,
      "y": 41,
      "z": 1,
      "name": "Plant_Leaves_Dead"
    },
    {
      "x": 9,
      "y": 28,
      "z": 2,
      "name": "Rock_Shale"
    },
    {
      "x": 9,
      "y": 29,
      "z": 2,
      "name": "Rock_Shale"
    },
    {
      "x": 9,
      "y": 30,
      "z": 2,
      "name": "Rock_Shale"
    },
    {
      "x": 9,
      "y": 31,
      "z": 2,
      "name": "Rock_Shale"
    },
    {
      "x": 9,
      "y": 32,
      "z": 2,
      "name": "Soil_Dirt_Cold"
    },
    {
      "x": 9,
      "y": 33,
      "z": 2,
      "name": "Soil_Dirt_Cold"
    },
    {
      "x": 9,
      "y": 34,
      "z": 2,
      "name": "Soil_Dirt_Cold"
    },
    {
      "x": 9,
      "y": 35,
      "z": 2,
      "name": "Soil_Dirt_Poisoned"
    },
    {
      "x": 9,
      "y": 40,
      "z": 2,
      "name": "Plant_Leaves_Dead"
    },
    {
      "x": 9,
      "y": 47,
      "z": 2,
      "name": "Plant_Leaves_Dead"
    },
    {
      "x": 9,
      "y": 29,
      "z": 3,
      "name": "Rock_Shale"
    },
    {
      "x": 9,
      "y": 30,
      "z": 3,
      "name": "Rock_Shale"
    },
    {
      "x": 9,
      "y": 31,
      "z": 3,
      "name": "Rock_Shale"
    },
    {
      "x": 9,
      "y": 32,
      "z": 3,
      "name": "Soil_Dirt_Cold"
    },
    {
      "x": 9,
      "y": 33,
      "z": 3,
      "name": "Soil_Dirt_Cold"
    },
    {
      "x": 9,
      "y": 34,
      "z": 3,
      "name": "Soil_Dirt_Cold"
    },
    {
      "x": 9,
      "y": 35,
      "z": 3,
      "name": "Soil_Dirt_Poisoned"
    },
    {
      "x": 9,
      "y": 30,
      "z": 4,
      "name": "Rock_Shale"
    },
    {
      "x": 9,
      "y": 31,
      "z": 4,
      "name": "Rock_Shale"
    },
    {
      "x": 9,
      "y": 32,
      "z": 4,
      "name": "Soil_Dirt_Cold"
    },
    {
      "x": 9,
      "y": 33,
      "z": 4,
      "name": "Soil_Dirt_Poisoned"
    },
    {
      "x": 9,
      "y": 34,
      "z": 4,
      "name": "Soil_Dirt_Poisoned"
    },
    {
      "x": 9,
      "y": 35,
      "z": 4,
      "name": "Soil_Dirt_Poisoned"
    },
    {
      "x": 9,
      "y": 36,
      "z": 4,
      "name": "*Plant_Crop_Berry_Winter_Block_State_Definitions_StageFinal",
      "components": {
        "Components": {
          "FarmingBlock": {}
        }
      }
    },
    {
      "x": 9,
      "y": 31,
      "z": 5,
      "name": "Rock_Shale"
    },
    {
      "x": 9,
      "y": 32,
      "z": 5,
      "name": "Soil_Dirt_Poisoned"
    },
    {
      "x": 9,
      "y": 33,
      "z": 5,
      "name": "Soil_Dirt_Poisoned"
    },
    {
      "x": 9,
      "y": 34,
      "z": 5,
      "name": "Soil_Dirt_Poisoned"
    },
    {
      "x": 9,
      "y": 35,
      "z": 5,
      "name": "Soil_Dirt_Poisoned"
    },
    {
      "x": 9,
      "y": 49,
      "z": 5,
      "name": "Plant_Leaves_Cedar"
    },
    {
      "x": 9,
      "y": 31,
      "z": 6,
      "name": "Rock_Shale"
    },
    {
      "x": 9,
      "y": 32,
      "z": 6,
      "name": "Soil_Dirt_Poisoned"
    },
    {
      "x": 9,
      "y": 33,
      "z": 6,
      "name": "Soil_Dirt_Poisoned"
    },
    {
      "x": 9,
      "y": 34,
      "z": 6,
      "name": "Soil_Dirt_Poisoned"
    },
    {
      "x": 9,
      "y": 35,
      "z": 6,
      "name": "Soil_Dirt_Poisoned"
    },
    {
      "x": 9,
      "y": 32,
      "z": 7,
      "name": "Soil_Dirt_Poisoned"
    },
    {
      "x": 9,
      "y": 33,
      "z": 7,
      "name": "Soil_Dirt_Poisoned"
    },
    {
      "x": 9,
      "y": 34,
      "z": 7,
      "name": "Soil_Dirt_Poisoned"
    },
    {
      "x": 10,
      "y": 33,
      "z": -5,
      "name": "Rock_Shale"
    },
    {
      "x": 10,
      "y": 34,
      "z": -5,
      "name": "Soil_Dirt_Cold"
    },
    {
      "x": 10,
      "y": 35,
      "z": -5,
      "name": "Soil_Dirt_Cold"
    },
    {
      "x": 10,
      "y": 36,
      "z": -5,
      "name": "Soil_Grass_Cold"
    },
    {
      "x": 10,
      "y": 31,
      "z": -4,
      "name": "Rock_Shale"
    },
    {
      "x": 10,
      "y": 32,
      "z": -4,
      "name": "Rock_Shale"
    },
    {
      "x": 10,
      "y": 33,
      "z": -4,
      "name": "Soil_Dirt_Cold"
    },
    {
      "x": 10,
      "y": 34,
      "z": -4,
      "name": "Soil_Dirt_Cold"
    },
    {
      "x": 10,
      "y": 35,
      "z": -4,
      "name": "Soil_Dirt_Cold"
    },
    {
      "x": 10,
      "y": 36,
      "z": -4,
      "name": "Soil_Grass_Cold"
    },
    {
      "x": 10,
      "y": 30,
      "z": -3,
      "name": "Rock_Shale"
    },
    {
      "x": 10,
      "y": 31,
      "z": -3,
      "name": "Rock_Shale"
    },
    {
      "x": 10,
      "y": 32,
      "z": -3,
      "name": "Rock_Shale"
    },
    {
      "x": 10,
      "y": 33,
      "z": -3,
      "name": "Soil_Dirt_Cold"
    },
    {
      "x": 10,
      "y": 34,
      "z": -3,
      "name": "Soil_Dirt_Cold"
    },
    {
      "x": 10,
      "y": 35,
      "z": -3,
      "name": "Soil_Dirt_Cold"
    },
    {
      "x": 10,
      "y": 36,
      "z": -3,
      "name": "Soil_Grass_Cold"
    },
    {
      "x": 10,
      "y": 28,
      "z": -2,
      "name": "Rock_Shale"
    },
    {
      "x": 10,
      "y": 29,
      "z": -2,
      "name": "Rock_Shale"
    },
    {
      "x": 10,
      "y": 30,
      "z": -2,
      "name": "Rock_Shale"
    },
    {
      "x": 10,
      "y": 31,
      "z": -2,
      "name": "Rock_Shale"
    },
    {
      "x": 10,
      "y": 32,
      "z": -2,
      "name": "Rock_Shale"
    },
    {
      "x": 10,
      "y": 33,
      "z": -2,
      "name": "Soil_Dirt_Cold"
    },
    {
      "x": 10,
      "y": 34,
      "z": -2,
      "name": "Soil_Dirt_Cold"
    },
    {
      "x": 10,
      "y": 35,
      "z": -2,
      "name": "Soil_Dirt_Cold"
    },
    {
      "x": 10,
      "y": 36,
      "z": -2,
      "name": "Soil_Grass_Cold"
    },
    {
      "x": 10,
      "y": 13,
      "z": -1,
      "name": "Rock_Shale"
    },
    {
      "x": 10,
      "y": 28,
      "z": -1,
      "name": "Rock_Shale"
    },
    {
      "x": 10,
      "y": 29,
      "z": -1,
      "name": "Rock_Shale"
    },
    {
      "x": 10,
      "y": 30,
      "z": -1,
      "name": "Rock_Shale"
    },
    {
      "x": 10,
      "y": 31,
      "z": -1,
      "name": "Rock_Shale"
    },
    {
      "x": 10,
      "y": 32,
      "z": -1,
      "name": "Rock_Shale"
    },
    {
      "x": 10,
      "y": 33,
      "z": -1,
      "name": "Soil_Dirt_Cold"
    },
    {
      "x": 10,
      "y": 34,
      "z": -1,
      "name": "Soil_Dirt_Cold"
    },
    {
      "x": 10,
      "y": 35,
      "z": -1,
      "name": "Soil_Dirt_Cold"
    },
    {
      "x": 10,
      "y": 36,
      "z": -1,
      "name": "Soil_Grass_Cold"
    },
    {
      "x": 10,
      "y": 13,
      "z": 0,
      "name": "Rock_Shale"
    },
    {
      "x": 10,
      "y": 14,
      "z": 0,
      "name": "Rock_Shale"
    },
    {
      "x": 10,
      "y": 28,
      "z": 0,
      "name": "Rock_Shale"
    },
    {
      "x": 10,
      "y": 29,
      "z": 0,
      "name": "Rock_Shale"
    },
    {
      "x": 10,
      "y": 30,
      "z": 0,
      "name": "Rock_Shale"
    },
    {
      "x": 10,
      "y": 31,
      "z": 0,
      "name": "Rock_Shale"
    },
    {
      "x": 10,
      "y": 32,
      "z": 0,
      "name": "Rock_Shale"
    },
    {
      "x": 10,
      "y": 33,
      "z": 0,
      "name": "Soil_Dirt_Cold"
    },
    {
      "x": 10,
      "y": 34,
      "z": 0,
      "name": "Soil_Dirt_Cold"
    },
    {
      "x": 10,
      "y": 35,
      "z": 0,
      "name": "Soil_Grass_Cold"
    },
    {
      "x": 10,
      "y": 28,
      "z": 1,
      "name": "Rock_Shale"
    },
    {
      "x": 10,
      "y": 29,
      "z": 1,
      "name": "Rock_Shale"
    },
    {
      "x": 10,
      "y": 30,
      "z": 1,
      "name": "Rock_Shale"
    },
    {
      "x": 10,
      "y": 31,
      "z": 1,
      "name": "Rock_Shale"
    },
    {
      "x": 10,
      "y": 32,
      "z": 1,
      "name": "Rock_Shale"
    },
    {
      "x": 10,
      "y": 33,
      "z": 1,
      "name": "Soil_Dirt_Poisoned"
    },
    {
      "x": 10,
      "y": 34,
      "z": 1,
      "name": "Soil_Dirt_Poisoned"
    },
    {
      "x": 10,
      "y": 35,
      "z": 1,
      "name": "Soil_Dirt_Poisoned"
    },
    {
      "x": 10,
      "y": 39,
      "z": 1,
      "name": "Plant_Leaves_Dead"
    },
    {
      "x": 10,
      "y": 40,
      "z": 1,
      "name": "Plant_Leaves_Dead"
    },
    {
      "x": 10,
      "y": 29,
      "z": 2,
      "name": "Rock_Shale"
    },
    {
      "x": 10,
      "y": 30,
      "z": 2,
      "name": "Rock_Shale"
    },
    {
      "x": 10,
      "y": 31,
      "z": 2,
      "name": "Rock_Shale"
    },
    {
      "x": 10,
      "y": 32,
      "z": 2,
      "name": "Soil_Dirt_Cold"
    },
    {
      "x": 10,
      "y": 33,
      "z": 2,
      "name": "Soil_Dirt_Poisoned"
    },
    {
      "x": 10,
      "y": 34,
      "z": 2,
      "name": "Soil_Dirt_Poisoned"
    },
    {
      "x": 10,
      "y": 35,
      "z": 2,
      "name": "Soil_Dirt_Poisoned"
    },
    {
      "x": 10,
      "y": 36,
      "z": 2,
      "name": "*Plant_Crop_Berry_Winter_Block_State_Definitions_StageFinal",
      "components": {
        "Components": {
          "FarmingBlock": {}
        }
      }
    },
    {
      "x": 10,
      "y": 30,
      "z": 3,
      "name": "Rock_Shale"
    },
    {
      "x": 10,
      "y": 31,
      "z": 3,
      "name": "Rock_Shale"
    },
    {
      "x": 10,
      "y": 32,
      "z": 3,
      "name": "Soil_Dirt_Cold"
    },
    {
      "x": 10,
      "y": 33,
      "z": 3,
      "name": "Soil_Dirt_Poisoned"
    },
    {
      "x": 10,
      "y": 34,
      "z": 3,
      "name": "Soil_Dirt_Poisoned"
    },
    {
      "x": 10,
      "y": 35,
      "z": 3,
      "name": "Soil_Dirt_Poisoned"
    },
    {
      "x": 10,
      "y": 36,
      "z": 3,
      "name": "*Plant_Crop_Berry_Winter_Block_State_Definitions_StageFinal",
      "components": {
        "Components": {
          "FarmingBlock": {}
        }
      }
    },
    {
      "x": 10,
      "y": 30,
      "z": 4,
      "name": "Rock_Shale"
    },
    {
      "x": 10,
      "y": 31,
      "z": 4,
      "name": "Soil_Dirt_Cold"
    },
    {
      "x": 10,
      "y": 32,
      "z": 4,
      "name": "Soil_Dirt_Cold"
    },
    {
      "x": 10,
      "y": 33,
      "z": 4,
      "name": "Soil_Dirt_Poisoned"
    },
    {
      "x": 10,
      "y": 34,
      "z": 4,
      "name": "Soil_Dirt_Poisoned"
    },
    {
      "x": 10,
      "y": 35,
      "z": 4,
      "name": "Soil_Dirt_Poisoned"
    },
    {
      "x": 10,
      "y": 36,
      "z": 4,
      "name": "*Plant_Crop_Berry_Winter_Block_State_Definitions_StageFinal",
      "components": {
        "Components": {
          "FarmingBlock": {}
        }
      }
    },
    {
      "x": 10,
      "y": 31,
      "z": 5,
      "name": "Rock_Shale"
    },
    {
      "x": 10,
      "y": 32,
      "z": 5,
      "name": "Soil_Dirt_Poisoned"
    },
    {
      "x": 10,
      "y": 33,
      "z": 5,
      "name": "Soil_Dirt_Poisoned"
    },
    {
      "x": 10,
      "y": 34,
      "z": 5,
      "name": "Soil_Dirt_Poisoned"
    },
    {
      "x": 10,
      "y": 35,
      "z": 5,
      "name": "Soil_Dirt_Poisoned"
    },
    {
      "x": 10,
      "y": 49,
      "z": 5,
      "name": "Plant_Leaves_Cedar"
    },
    {
      "x": 10,
      "y": 50,
      "z": 5,
      "name": "Plant_Leaves_Cedar"
    },
    {
      "x": 10,
      "y": 31,
      "z": 6,
      "name": "Soil_Dirt_Poisoned"
    },
    {
      "x": 10,
      "y": 32,
      "z": 6,
      "name": "Soil_Dirt_Poisoned"
    },
    {
      "x": 10,
      "y": 33,
      "z": 6,
      "name": "Soil_Dirt_Poisoned"
    },
    {
      "x": 10,
      "y": 34,
      "z": 6,
      "name": "Soil_Dirt_Poisoned"
    },
    {
      "x": 10,
      "y": 31,
      "z": 7,
      "name": "Soil_Dirt_Poisoned"
    },
    {
      "x": 10,
      "y": 32,
      "z": 7,
      "name": "Soil_Dirt_Poisoned"
    },
    {
      "x": 10,
      "y": 33,
      "z": 7,
      "name": "Soil_Dirt_Poisoned"
    },
    {
      "x": 10,
      "y": 34,
      "z": 7,
      "name": "Soil_Roots_Poisoned"
    },
    {
      "x": 10,
      "y": 33,
      "z": 8,
      "name": "Soil_Dirt_Poisoned"
    },
    {
      "x": 10,
      "y": 34,
      "z": 8,
      "name": "Soil_Dirt_Poisoned"
    },
    {
      "x": 11,
      "y": 34,
      "z": -6,
      "name": "Soil_Dirt_Cold"
    },
    {
      "x": 11,
      "y": 35,
      "z": -6,
      "name": "Soil_Grass_Cold"
    },
    {
      "x": 11,
      "y": 32,
      "z": -5,
      "name": "Rock_Shale"
    },
    {
      "x": 11,
      "y": 33,
      "z": -5,
      "name": "Soil_Dirt_Cold"
    },
    {
      "x": 11,
      "y": 34,
      "z": -5,
      "name": "Soil_Dirt_Cold"
    },
    {
      "x": 11,
      "y": 35,
      "z": -5,
      "name": "Soil_Dirt_Cold"
    },
    {
      "x": 11,
      "y": 36,
      "z": -5,
      "name": "Soil_Grass_Cold"
    },
    {
      "x": 11,
      "y": 31,
      "z": -4,
      "name": "Rock_Shale"
    },
    {
      "x": 11,
      "y": 32,
      "z": -4,
      "name": "Rock_Shale"
    },
    {
      "x": 11,
      "y": 33,
      "z": -4,
      "name": "Soil_Dirt_Cold"
    },
    {
      "x": 11,
      "y": 34,
      "z": -4,
      "name": "Soil_Dirt_Cold"
    },
    {
      "x": 11,
      "y": 35,
      "z": -4,
      "name": "Soil_Dirt_Cold"
    },
    {
      "x": 11,
      "y": 36,
      "z": -4,
      "name": "Soil_Grass_Cold"
    },
    {
      "x": 11,
      "y": 30,
      "z": -3,
      "name": "Rock_Shale"
    },
    {
      "x": 11,
      "y": 31,
      "z": -3,
      "name": "Rock_Shale"
    },
    {
      "x": 11,
      "y": 32,
      "z": -3,
      "name": "Rock_Shale"
    },
    {
      "x": 11,
      "y": 33,
      "z": -3,
      "name": "Soil_Dirt_Cold"
    },
    {
      "x": 11,
      "y": 34,
      "z": -3,
      "name": "Soil_Dirt_Cold"
    },
    {
      "x": 11,
      "y": 35,
      "z": -3,
      "name": "Soil_Dirt_Cold"
    },
    {
      "x": 11,
      "y": 36,
      "z": -3,
      "name": "Soil_Grass_Cold"
    },
    {
      "x": 11,
      "y": 37,
      "z": -3,
      "name": "Plant_Fern_Winter"
    },
    {
      "x": 11,
      "y": 29,
      "z": -2,
      "name": "Rock_Shale"
    },
    {
      "x": 11,
      "y": 30,
      "z": -2,
      "name": "Rock_Shale"
    },
    {
      "x": 11,
      "y": 31,
      "z": -2,
      "name": "Rock_Shale"
    },
    {
      "x": 11,
      "y": 32,
      "z": -2,
      "name": "Rock_Shale"
    },
    {
      "x": 11,
      "y": 33,
      "z": -2,
      "name": "Soil_Dirt_Cold"
    },
    {
      "x": 11,
      "y": 34,
      "z": -2,
      "name": "Soil_Dirt_Cold"
    },
    {
      "x": 11,
      "y": 35,
      "z": -2,
      "name": "Soil_Dirt_Cold"
    },
    {
      "x": 11,
      "y": 36,
      "z": -2,
      "name": "Soil_Grass_Cold"
    },
    {
      "x": 11,
      "y": 12,
      "z": -1,
      "name": "Rock_Shale"
    },
    {
      "x": 11,
      "y": 28,
      "z": -1,
      "name": "Rock_Shale"
    },
    {
      "x": 11,
      "y": 29,
      "z": -1,
      "name": "Rock_Shale"
    },
    {
      "x": 11,
      "y": 30,
      "z": -1,
      "name": "Rock_Shale"
    },
    {
      "x": 11,
      "y": 31,
      "z": -1,
      "name": "Rock_Shale"
    },
    {
      "x": 11,
      "y": 32,
      "z": -1,
      "name": "Rock_Shale"
    },
    {
      "x": 11,
      "y": 33,
      "z": -1,
      "name": "Soil_Dirt_Cold"
    },
    {
      "x": 11,
      "y": 34,
      "z": -1,
      "name": "Soil_Dirt_Cold"
    },
    {
      "x": 11,
      "y": 35,
      "z": -1,
      "name": "Soil_Dirt_Cold"
    },
    {
      "x": 11,
      "y": 36,
      "z": -1,
      "name": "Soil_Grass_Cold"
    },
    {
      "x": 11,
      "y": 37,
      "z": -1,
      "name": "Plant_Grass_Winter"
    },
    {
      "x": 11,
      "y": 28,
      "z": 0,
      "name": "Rock_Shale"
    },
    {
      "x": 11,
      "y": 29,
      "z": 0,
      "name": "Rock_Shale"
    },
    {
      "x": 11,
      "y": 30,
      "z": 0,
      "name": "Rock_Shale"
    },
    {
      "x": 11,
      "y": 31,
      "z": 0,
      "name": "Rock_Shale"
    },
    {
      "x": 11,
      "y": 32,
      "z": 0,
      "name": "Rock_Shale"
    },
    {
      "x": 11,
      "y": 33,
      "z": 0,
      "name": "Rock_Shale"
    },
    {
      "x": 11,
      "y": 34,
      "z": 0,
      "name": "Soil_Dirt_Poisoned"
    },
    {
      "x": 11,
      "y": 35,
      "z": 0,
      "name": "Soil_Grass_Cold"
    },
    {
      "x": 11,
      "y": 28,
      "z": 1,
      "name": "Rock_Shale"
    },
    {
      "x": 11,
      "y": 29,
      "z": 1,
      "name": "Rock_Shale"
    },
    {
      "x": 11,
      "y": 30,
      "z": 1,
      "name": "Rock_Shale"
    },
    {
      "x": 11,
      "y": 31,
      "z": 1,
      "name": "Rock_Shale"
    },
    {
      "x": 11,
      "y": 32,
      "z": 1,
      "name": "Rock_Shale"
    },
    {
      "x": 11,
      "y": 33,
      "z": 1,
      "name": "Soil_Dirt_Poisoned"
    },
    {
      "x": 11,
      "y": 34,
      "z": 1,
      "name": "Soil_Dirt_Poisoned"
    },
    {
      "x": 11,
      "y": 35,
      "z": 1,
      "name": "Soil_Dirt_Poisoned"
    },
    {
      "x": 11,
      "y": 39,
      "z": 1,
      "name": "Plant_Leaves_Dead"
    },
    {
      "x": 11,
      "y": 30,
      "z": 2,
      "name": "Rock_Shale"
    },
    {
      "x": 11,
      "y": 31,
      "z": 2,
      "name": "Rock_Shale"
    },
    {
      "x": 11,
      "y": 32,
      "z": 2,
      "name": "Soil_Dirt_Poisoned"
    },
    {
      "x": 11,
      "y": 33,
      "z": 2,
      "name": "Soil_Dirt_Poisoned"
    },
    {
      "x": 11,
      "y": 34,
      "z": 2,
      "name": "Soil_Dirt_Poisoned"
    },
    {
      "x": 11,
      "y": 35,
      "z": 2,
      "name": "Soil_Dirt_Poisoned"
    },
    {
      "x": 11,
      "y": 50,
      "z": 2,
      "name": "Plant_Leaves_Cedar"
    },
    {
      "x": 11,
      "y": 31,
      "z": 3,
      "name": "Rock_Shale"
    },
    {
      "x": 11,
      "y": 32,
      "z": 3,
      "name": "Soil_Dirt_Poisoned"
    },
    {
      "x": 11,
      "y": 33,
      "z": 3,
      "name": "Soil_Dirt_Poisoned"
    },
    {
      "x": 11,
      "y": 34,
      "z": 3,
      "name": "Soil_Dirt_Poisoned"
    },
    {
      "x": 11,
      "y": 35,
      "z": 3,
      "name": "Soil_Dirt_Poisoned"
    },
    {
      "x": 11,
      "y": 32,
      "z": 4,
      "name": "Soil_Dirt_Cold"
    },
    {
      "x": 11,
      "y": 33,
      "z": 4,
      "name": "Soil_Dirt_Poisoned"
    },
    {
      "x": 11,
      "y": 34,
      "z": 4,
      "name": "Soil_Dirt_Poisoned"
    },
    {
      "x": 11,
      "y": 35,
      "z": 4,
      "name": "*Plant_Crop_Berry_Winter_Block_State_Definitions_StageFinal",
      "components": {
        "Components": {
          "FarmingBlock": {}
        }
      }
    },
    {
      "x": 11,
      "y": 50,
      "z": 4,
      "name": "Plant_Leaves_Cedar"
    },
    {
      "x": 11,
      "y": 53,
      "z": 4,
      "name": "Plant_Leaves_Cedar"
    },
    {
      "x": 11,
      "y": 31,
      "z": 5,
      "name": "Soil_Dirt_Cold"
    },
    {
      "x": 11,
      "y": 32,
      "z": 5,
      "name": "Soil_Dirt_Poisoned"
    },
    {
      "x": 11,
      "y": 33,
      "z": 5,
      "name": "Soil_Dirt_Poisoned"
    },
    {
      "x": 11,
      "y": 34,
      "z": 5,
      "name": "Soil_Dirt_Poisoned"
    },
    {
      "x": 11,
      "y": 50,
      "z": 5,
      "name": "Plant_Leaves_Cedar"
    },
    {
      "x": 11,
      "y": 31,
      "z": 6,
      "name": "Soil_Dirt_Poisoned"
    },
    {
      "x": 11,
      "y": 32,
      "z": 6,
      "name": "Soil_Dirt_Poisoned"
    },
    {
      "x": 11,
      "y": 33,
      "z": 6,
      "name": "Soil_Roots_Poisoned"
    },
    {
      "x": 11,
      "y": 34,
      "z": 6,
      "name": "Soil_Roots_Poisoned"
    },
    {
      "x": 11,
      "y": 50,
      "z": 6,
      "name": "Plant_Leaves_Cedar"
    },
    {
      "x": 11,
      "y": 31,
      "z": 7,
      "name": "Soil_Dirt_Poisoned"
    },
    {
      "x": 11,
      "y": 32,
      "z": 7,
      "name": "Soil_Dirt_Poisoned"
    },
    {
      "x": 11,
      "y": 33,
      "z": 7,
      "name": "Soil_Roots_Poisoned"
    },
    {
      "x": 11,
      "y": 34,
      "z": 7,
      "name": "Soil_Roots_Poisoned"
    },
    {
      "x": 11,
      "y": 31,
      "z": 8,
      "name": "Soil_Dirt_Poisoned"
    },
    {
      "x": 11,
      "y": 32,
      "z": 8,
      "name": "Soil_Dirt_Poisoned"
    },
    {
      "x": 11,
      "y": 33,
      "z": 8,
      "name": "Soil_Roots_Poisoned"
    },
    {
      "x": 11,
      "y": 34,
      "z": 8,
      "name": "Soil_Roots_Poisoned"
    },
    {
      "x": 11,
      "y": 31,
      "z": 9,
      "name": "Soil_Dirt_Poisoned"
    },
    {
      "x": 11,
      "y": 32,
      "z": 9,
      "name": "Soil_Dirt_Poisoned"
    },
    {
      "x": 11,
      "y": 33,
      "z": 9,
      "name": "Soil_Dirt_Poisoned"
    },
    {
      "x": 11,
      "y": 34,
      "z": 9,
      "name": "Soil_Roots_Poisoned"
    },
    {
      "x": 12,
      "y": 33,
      "z": -6,
      "name": "Soil_Dirt_Cold"
    },
    {
      "x": 12,
      "y": 34,
      "z": -6,
      "name": "Soil_Dirt_Cold"
    },
    {
      "x": 12,
      "y": 35,
      "z": -6,
      "name": "Soil_Dirt_Cold"
    },
    {
      "x": 12,
      "y": 36,
      "z": -6,
      "name": "Soil_Grass_Cold"
    },
    {
      "x": 12,
      "y": 32,
      "z": -5,
      "name": "Rock_Shale"
    },
    {
      "x": 12,
      "y": 33,
      "z": -5,
      "name": "Soil_Dirt_Cold"
    },
    {
      "x": 12,
      "y": 34,
      "z": -5,
      "name": "Soil_Dirt_Cold"
    },
    {
      "x": 12,
      "y": 35,
      "z": -5,
      "name": "Soil_Dirt_Cold"
    },
    {
      "x": 12,
      "y": 36,
      "z": -5,
      "name": "Soil_Grass_Cold"
    },
    {
      "x": 12,
      "y": 37,
      "z": -5,
      "name": "Plant_Grass_Winter_Tall"
    },
    {
      "x": 12,
      "y": 38,
      "z": -5,
      "name": "Plant_Grass_Winter_Tall",
      "filler": 1024
    },
    {
      "x": 12,
      "y": 31,
      "z": -4,
      "name": "Rock_Shale"
    },
    {
      "x": 12,
      "y": 32,
      "z": -4,
      "name": "Rock_Shale"
    },
    {
      "x": 12,
      "y": 33,
      "z": -4,
      "name": "Soil_Dirt_Cold"
    },
    {
      "x": 12,
      "y": 34,
      "z": -4,
      "name": "Soil_Dirt_Cold"
    },
    {
      "x": 12,
      "y": 35,
      "z": -4,
      "name": "Soil_Dirt_Cold"
    },
    {
      "x": 12,
      "y": 36,
      "z": -4,
      "name": "Soil_Grass_Cold"
    },
    {
      "x": 12,
      "y": 30,
      "z": -3,
      "name": "Rock_Shale"
    },
    {
      "x": 12,
      "y": 31,
      "z": -3,
      "name": "Rock_Shale"
    },
    {
      "x": 12,
      "y": 32,
      "z": -3,
      "name": "Rock_Shale"
    },
    {
      "x": 12,
      "y": 33,
      "z": -3,
      "name": "Soil_Dirt_Cold"
    },
    {
      "x": 12,
      "y": 34,
      "z": -3,
      "name": "Soil_Dirt_Cold"
    },
    {
      "x": 12,
      "y": 35,
      "z": -3,
      "name": "Soil_Dirt_Cold"
    },
    {
      "x": 12,
      "y": 36,
      "z": -3,
      "name": "Soil_Grass_Cold"
    },
    {
      "x": 12,
      "y": 37,
      "z": -3,
      "name": "Plant_Fern_Forest"
    },
    {
      "x": 12,
      "y": 30,
      "z": -2,
      "name": "Rock_Shale"
    },
    {
      "x": 12,
      "y": 31,
      "z": -2,
      "name": "Rock_Shale"
    },
    {
      "x": 12,
      "y": 32,
      "z": -2,
      "name": "Rock_Shale"
    },
    {
      "x": 12,
      "y": 33,
      "z": -2,
      "name": "Soil_Dirt_Cold"
    },
    {
      "x": 12,
      "y": 34,
      "z": -2,
      "name": "Soil_Dirt_Cold"
    },
    {
      "x": 12,
      "y": 35,
      "z": -2,
      "name": "Soil_Dirt_Cold"
    },
    {
      "x": 12,
      "y": 36,
      "z": -2,
      "name": "Soil_Grass_Cold"
    },
    {
      "x": 12,
      "y": 37,
      "z": -2,
      "name": "Plant_Fern_Forest"
    },
    {
      "x": 12,
      "y": 30,
      "z": -1,
      "name": "Rock_Shale"
    },
    {
      "x": 12,
      "y": 31,
      "z": -1,
      "name": "Rock_Shale"
    },
    {
      "x": 12,
      "y": 32,
      "z": -1,
      "name": "Rock_Shale"
    },
    {
      "x": 12,
      "y": 33,
      "z": -1,
      "name": "Rock_Shale"
    },
    {
      "x": 12,
      "y": 34,
      "z": -1,
      "name": "Soil_Dirt_Cold"
    },
    {
      "x": 12,
      "y": 35,
      "z": -1,
      "name": "Soil_Dirt_Cold"
    },
    {
      "x": 12,
      "y": 36,
      "z": -1,
      "name": "Soil_Grass_Cold"
    },
    {
      "x": 12,
      "y": 30,
      "z": 0,
      "name": "Rock_Shale"
    },
    {
      "x": 12,
      "y": 31,
      "z": 0,
      "name": "Rock_Shale"
    },
    {
      "x": 12,
      "y": 32,
      "z": 0,
      "name": "Rock_Shale"
    },
    {
      "x": 12,
      "y": 33,
      "z": 0,
      "name": "Rock_Shale"
    },
    {
      "x": 12,
      "y": 34,
      "z": 0,
      "name": "Rock_Shale"
    },
    {
      "x": 12,
      "y": 35,
      "z": 0,
      "name": "Soil_Dirt_Poisoned"
    },
    {
      "x": 12,
      "y": 36,
      "z": 0,
      "name": "Soil_Grass_Cold"
    },
    {
      "x": 12,
      "y": 30,
      "z": 1,
      "name": "Rock_Shale"
    },
    {
      "x": 12,
      "y": 31,
      "z": 1,
      "name": "Rock_Shale"
    },
    {
      "x": 12,
      "y": 32,
      "z": 1,
      "name": "Rock_Shale"
    },
    {
      "x": 12,
      "y": 33,
      "z": 1,
      "name": "Rock_Shale"
    },
    {
      "x": 12,
      "y": 34,
      "z": 1,
      "name": "Soil_Dirt_Poisoned"
    },
    {
      "x": 12,
      "y": 35,
      "z": 1,
      "name": "Soil_Dirt_Poisoned"
    },
    {
      "x": 12,
      "y": 49,
      "z": 1,
      "name": "Plant_Leaves_Cedar"
    },
    {
      "x": 12,
      "y": 10,
      "z": 2,
      "name": "Rock_Shale"
    },
    {
      "x": 12,
      "y": 31,
      "z": 2,
      "name": "Rock_Shale"
    },
    {
      "x": 12,
      "y": 32,
      "z": 2,
      "name": "Rock_Shale"
    },
    {
      "x": 12,
      "y": 33,
      "z": 2,
      "name": "Soil_Dirt_Poisoned"
    },
    {
      "x": 12,
      "y": 34,
      "z": 2,
      "name": "Soil_Dirt_Poisoned"
    },
    {
      "x": 12,
      "y": 35,
      "z": 2,
      "name": "Soil_Dirt_Poisoned"
    },
    {
      "x": 12,
      "y": 49,
      "z": 2,
      "name": "Plant_Leaves_Cedar"
    },
    {
      "x": 12,
      "y": 50,
      "z": 2,
      "name": "Plant_Leaves_Cedar"
    },
    {
      "x": 12,
      "y": 51,
      "z": 2,
      "name": "Plant_Leaves_Cedar"
    },
    {
      "x": 12,
      "y": 31,
      "z": 3,
      "name": "Rock_Shale"
    },
    {
      "x": 12,
      "y": 32,
      "z": 3,
      "name": "Soil_Dirt_Poisoned"
    },
    {
      "x": 12,
      "y": 33,
      "z": 3,
      "name": "Soil_Dirt_Poisoned"
    },
    {
      "x": 12,
      "y": 50,
      "z": 3,
      "name": "Plant_Leaves_Cedar"
    },
    {
      "x": 12,
      "y": 53,
      "z": 3,
      "name": "Plant_Leaves_Cedar"
    },
    {
      "x": 12,
      "y": 55,
      "z": 3,
      "name": "Plant_Leaves_Cedar"
    },
    {
      "x": 12,
      "y": 57,
      "z": 3,
      "name": "Plant_Leaves_Cedar"
    },
    {
      "x": 12,
      "y": 31,
      "z": 4,
      "name": "Wood_Cedar_Roots"
    },
    {
      "x": 12,
      "y": 32,
      "z": 4,
      "name": "Wood_Cedar_Trunk"
    },
    {
      "x": 12,
      "y": 33,
      "z": 4,
      "name": "Wood_Cedar_Trunk_Full"
    },
    {
      "x": 12,
      "y": 40,
      "z": 4,
      "name": "Wood_Cedar_Branch_Short",
      "rotation": 3
    },
    {
      "x": 12,
      "y": 46,
      "z": 4,
      "name": "Wood_Cedar_Branch_Long",
      "rotation": 5
    },
    {
      "x": 12,
      "y": 50,
      "z": 4,
      "name": "Plant_Leaves_Cedar"
    },
    {
      "x": 12,
      "y": 51,
      "z": 4,
      "name": "Plant_Leaves_Cedar"
    },
    {
      "x": 12,
      "y": 53,
      "z": 4,
      "name": "Plant_Leaves_Cedar"
    },
    {
      "x": 12,
      "y": 55,
      "z": 4,
      "name": "Plant_Leaves_Cedar"
    },
    {
      "x": 12,
      "y": 57,
      "z": 4,
      "name": "Plant_Leaves_Cedar"
    },
    {
      "x": 12,
      "y": 58,
      "z": 4,
      "name": "Plant_Leaves_Cedar"
    },
    {
      "x": 12,
      "y": 50,
      "z": 5,
      "name": "Plant_Leaves_Cedar"
    },
    {
      "x": 12,
      "y": 51,
      "z": 5,
      "name": "Plant_Leaves_Cedar"
    },
    {
      "x": 12,
      "y": 53,
      "z": 5,
      "name": "Plant_Leaves_Cedar"
    },
    {
      "x": 12,
      "y": 54,
      "z": 5,
      "name": "Plant_Leaves_Cedar"
    },
    {
      "x": 12,
      "y": 32,
      "z": 6,
      "name": "Soil_Dirt_Cold"
    },
    {
      "x": 12,
      "y": 33,
      "z": 6,
      "name": "Soil_Roots_Poisoned"
    },
    {
      "x": 12,
      "y": 34,
      "z": 6,
      "name": "Soil_Roots_Poisoned"
    },
    {
      "x": 12,
      "y": 50,
      "z": 6,
      "name": "Plant_Leaves_Cedar"
    },
    {
      "x": 12,
      "y": 51,
      "z": 6,
      "name": "Plant_Leaves_Cedar"
    },
    {
      "x": 12,
      "y": 53,
      "z": 6,
      "name": "Plant_Leaves_Cedar"
    },
    {
      "x": 12,
      "y": 31,
      "z": 7,
      "name": "Soil_Dirt_Cold"
    },
    {
      "x": 12,
      "y": 32,
      "z": 7,
      "name": "Soil_Roots_Poisoned"
    },
    {
      "x": 12,
      "y": 33,
      "z": 7,
      "name": "Soil_Roots_Poisoned"
    },
    {
      "x": 12,
      "y": 34,
      "z": 7,
      "name": "Soil_Roots_Poisoned"
    },
    {
      "x": 12,
      "y": 50,
      "z": 7,
      "name": "Plant_Leaves_Cedar"
    },
    {
      "x": 12,
      "y": 30,
      "z": 8,
      "name": "Rock_Shale"
    },
    {
      "x": 12,
      "y": 31,
      "z": 8,
      "name": "Soil_Dirt_Poisoned"
    },
    {
      "x": 12,
      "y": 32,
      "z": 8,
      "name": "Soil_Dirt_Poisoned"
    },
    {
      "x": 12,
      "y": 33,
      "z": 8,
      "name": "Soil_Roots_Poisoned"
    },
    {
      "x": 12,
      "y": 34,
      "z": 8,
      "name": "Soil_Roots_Poisoned"
    },
    {
      "x": 12,
      "y": 35,
      "z": 8,
      "name": "Plant_Crop_Mushroom_Glowing_Purple"
    },
    {
      "x": 12,
      "y": 31,
      "z": 9,
      "name": "Soil_Dirt_Cold"
    },
    {
      "x": 12,
      "y": 32,
      "z": 9,
      "name": "Soil_Dirt_Poisoned"
    },
    {
      "x": 12,
      "y": 33,
      "z": 9,
      "name": "Soil_Roots_Poisoned"
    },
    {
      "x": 12,
      "y": 34,
      "z": 9,
      "name": "Soil_Roots_Poisoned"
    },
    {
      "x": 12,
      "y": 35,
      "z": 9,
      "name": "Plant_Flower_Bushy_Poisoned"
    },
    {
      "x": 13,
      "y": 32,
      "z": -6,
      "name": "Rock_Shale"
    },
    {
      "x": 13,
      "y": 33,
      "z": -6,
      "name": "Soil_Dirt_Cold"
    },
    {
      "x": 13,
      "y": 34,
      "z": -6,
      "name": "Soil_Dirt_Cold"
    },
    {
      "x": 13,
      "y": 35,
      "z": -6,
      "name": "Soil_Dirt_Cold"
    },
    {
      "x": 13,
      "y": 36,
      "z": -6,
      "name": "Soil_Grass_Cold"
    },
    {
      "x": 13,
      "y": 13,
      "z": -5,
      "name": "Rock_Shale"
    },
    {
      "x": 13,
      "y": 32,
      "z": -5,
      "name": "Rock_Shale"
    },
    {
      "x": 13,
      "y": 33,
      "z": -5,
      "name": "Soil_Dirt_Cold"
    },
    {
      "x": 13,
      "y": 34,
      "z": -5,
      "name": "Soil_Dirt_Cold"
    },
    {
      "x": 13,
      "y": 35,
      "z": -5,
      "name": "Soil_Dirt_Cold"
    },
    {
      "x": 13,
      "y": 36,
      "z": -5,
      "name": "Soil_Grass_Cold"
    },
    {
      "x": 13,
      "y": 37,
      "z": -5,
      "name": "Plant_Grass_Winter_Tall"
    },
    {
      "x": 13,
      "y": 38,
      "z": -5,
      "name": "Plant_Grass_Winter_Tall",
      "filler": 1024
    },
    {
      "x": 13,
      "y": 13,
      "z": -4,
      "name": "Rock_Shale"
    },
    {
      "x": 13,
      "y": 32,
      "z": -4,
      "name": "Soil_Dirt_Cold"
    },
    {
      "x": 13,
      "y": 33,
      "z": -4,
      "name": "Soil_Dirt_Cold"
    },
    {
      "x": 13,
      "y": 34,
      "z": -4,
      "name": "Soil_Dirt_Cold"
    },
    {
      "x": 13,
      "y": 35,
      "z": -4,
      "name": "Soil_Dirt_Cold"
    },
    {
      "x": 13,
      "y": 36,
      "z": -4,
      "name": "Soil_Grass_Cold"
    },
    {
      "x": 13,
      "y": 37,
      "z": -4,
      "name": "Plant_Grass_Winter"
    },
    {
      "x": 13,
      "y": 30,
      "z": -3,
      "name": "Rock_Shale"
    },
    {
      "x": 13,
      "y": 31,
      "z": -3,
      "name": "Rock_Shale"
    },
    {
      "x": 13,
      "y": 32,
      "z": -3,
      "name": "Rock_Shale"
    },
    {
      "x": 13,
      "y": 33,
      "z": -3,
      "name": "Soil_Dirt_Cold"
    },
    {
      "x": 13,
      "y": 34,
      "z": -3,
      "name": "Soil_Dirt_Cold"
    },
    {
      "x": 13,
      "y": 35,
      "z": -3,
      "name": "Soil_Dirt_Cold"
    },
    {
      "x": 13,
      "y": 36,
      "z": -3,
      "name": "Soil_Grass_Cold"
    },
    {
      "x": 13,
      "y": 31,
      "z": -2,
      "name": "Rock_Shale"
    },
    {
      "x": 13,
      "y": 32,
      "z": -2,
      "name": "Rock_Shale"
    },
    {
      "x": 13,
      "y": 33,
      "z": -2,
      "name": "Soil_Dirt_Cold"
    },
    {
      "x": 13,
      "y": 34,
      "z": -2,
      "name": "Soil_Dirt_Cold"
    },
    {
      "x": 13,
      "y": 35,
      "z": -2,
      "name": "Soil_Dirt_Cold"
    },
    {
      "x": 13,
      "y": 36,
      "z": -2,
      "name": "Soil_Grass_Cold"
    },
    {
      "x": 13,
      "y": 30,
      "z": -1,
      "name": "Rock_Shale"
    },
    {
      "x": 13,
      "y": 31,
      "z": -1,
      "name": "Rock_Shale"
    },
    {
      "x": 13,
      "y": 32,
      "z": -1,
      "name": "Rock_Shale"
    },
    {
      "x": 13,
      "y": 33,
      "z": -1,
      "name": "Rock_Shale"
    },
    {
      "x": 13,
      "y": 34,
      "z": -1,
      "name": "Soil_Dirt_Cold"
    },
    {
      "x": 13,
      "y": 35,
      "z": -1,
      "name": "Soil_Dirt_Cold"
    },
    {
      "x": 13,
      "y": 36,
      "z": -1,
      "name": "Soil_Grass_Cold"
    },
    {
      "x": 13,
      "y": 30,
      "z": 0,
      "name": "Rock_Shale"
    },
    {
      "x": 13,
      "y": 31,
      "z": 0,
      "name": "Rock_Shale"
    },
    {
      "x": 13,
      "y": 32,
      "z": 0,
      "name": "Rock_Shale"
    },
    {
      "x": 13,
      "y": 33,
      "z": 0,
      "name": "Rock_Shale"
    },
    {
      "x": 13,
      "y": 34,
      "z": 0,
      "name": "Soil_Dirt_Poisoned"
    },
    {
      "x": 13,
      "y": 35,
      "z": 0,
      "name": "Soil_Dirt_Poisoned"
    },
    {
      "x": 13,
      "y": 36,
      "z": 0,
      "name": "Soil_Grass_Cold"
    },
    {
      "x": 13,
      "y": 30,
      "z": 1,
      "name": "Rock_Shale"
    },
    {
      "x": 13,
