{
  "version": 8,
  "blockIdVersion": 8,
  "anchorX": 0,
  "anchorY": 0,
  "anchorZ": 0,
  "blocks": [
    {
      "x": -12,
      "y": 7,
      "z": -1,
      "name": "Rock_Chalk"
    },
    {
      "x": -12,
      "y": 7,
      "z": 0,
      "name": "Rock_Chalk"
    },
    {
      "x": -12,
      "y": 7,
      "z": 1,
      "name": "Rock_Chalk"
    },
    {
      "x": -11,
      "y": 8,
      "z": -2,
      "name": "Rock_Chalk"
    },
    {
      "x": -11,
      "y": 8,
      "z": -1,
      "name": "Rock_Chalk"
    },
    {
      "x": -11,
      "y": 8,
      "z": 0,
      "name": "Rock_Chalk"
    },
    {
      "x": -11,
      "y": 8,
      "z": 1,
      "name": "Rock_Chalk"
    },
    {
      "x": -11,
      "y": 7,
      "z": 3,
      "name": "Rock_Chalk"
    },
    {
      "x": -10,
      "y": 7,
      "z": -6,
      "name": "Rock_Chalk"
    },
    {
      "x": -10,
      "y": 9,
      "z": -2,
      "name": "Rock_Chalk"
    },
    {
      "x": -10,
      "y": 9,
      "z": -1,
      "name": "Rock_Chalk"
    },
    {
      "x": -10,
      "y": 9,
      "z": 0,
      "name": "Rock_Chalk"
    },
    {
      "x": -10,
      "y": 9,
      "z": 1,
      "name": "Rock_Chalk"
    },
    {
      "x": -10,
      "y": 8,
      "z": 2,
      "name": "Rock_Chalk"
    },
    {
      "x": -10,
      "y": 9,
      "z": 2,
      "name": "Rock_Chalk"
    },
    {
      "x": -10,
      "y": 8,
      "z": 3,
      "name": "Rock_Chalk"
    },
    {
      "x": -10,
      "y": 7,
      "z": 4,
      "name": "Rock_Chalk"
    },
    {
      "x": -10,
      "y": 7,
      "z": 5,
      "name": "Rock_Chalk"
    },
    {
      "x": -9,
      "y": 8,
      "z": -6,
      "name": "Rock_Chalk"
    },
    {
      "x": -9,
      "y": 9,
      "z": -2,
      "name": "Rock_Chalk"
    },
    {
      "x": -9,
      "y": 10,
      "z": -2,
      "name": "Rock_Chalk"
    },
    {
      "x": -9,
      "y": 10,
      "z": -1,
      "name": "Rock_Chalk"
    },
    {
      "x": -9,
      "y": 10,
      "z": 0,
      "name": "Rock_Chalk"
    },
    {
      "x": -9,
      "y": 9,
      "z": 1,
      "name": "Rock_Chalk"
    },
    {
      "x": -9,
      "y": 10,
      "z": 1,
      "name": "Rock_Chalk"
    },
    {
      "x": -9,
      "y": 9,
      "z": 2,
      "name": "Rock_Chalk"
    },
    {
      "x": -9,
      "y": 10,
      "z": 2,
      "name": "Rock_Chalk"
    },
    {
      "x": -9,
      "y": 9,
      "z": 3,
      "name": "Rock_Chalk"
    },
    {
      "x": -9,
      "y": 8,
      "z": 4,
      "name": "Rock_Chalk"
    },
    {
      "x": -9,
      "y": 8,
      "z": 5,
      "name": "Rock_Chalk"
    },
    {
      "x": -9,
      "y": 7,
      "z": 6,
      "name": "Rock_Chalk"
    },
    {
      "x": -8,
      "y": 8,
      "z": -6,
      "name": "Rock_Chalk"
    },
    {
      "x": -8,
      "y": 10,
      "z": -2,
      "name": "Rock_Chalk"
    },
    {
      "x": -8,
      "y": 11,
      "z": -2,
      "name": "Rock_Chalk"
    },
    {
      "x": -8,
      "y": 10,
      "z": -1,
      "name": "Rock_Chalk"
    },
    {
      "x": -8,
      "y": 11,
      "z": -1,
      "name": "Rock_Chalk"
    },
    {
      "x": -8,
      "y": 10,
      "z": 0,
      "name": "Rock_Chalk"
    },
    {
      "x": -8,
      "y": 11,
      "z": 0,
      "name": "Rock_Chalk"
    },
    {
      "x": -8,
      "y": 10,
      "z": 1,
      "name": "Rock_Chalk"
    },
    {
      "x": -8,
      "y": 11,
      "z": 1,
      "name": "Rock_Chalk"
    },
    {
      "x": -8,
      "y": 10,
      "z": 2,
      "name": "Rock_Chalk"
    },
    {
      "x": -8,
      "y": 9,
      "z": 3,
      "name": "Rock_Chalk"
    },
    {
      "x": -8,
      "y": 10,
      "z": 3,
      "name": "Rock_Chalk"
    },
    {
      "x": -8,
      "y": 9,
      "z": 4,
      "name": "Rock_Chalk"
    },
    {
      "x": -8,
      "y": 8,
      "z": 5,
      "name": "Rock_Chalk"
    },
    {
      "x": -8,
      "y": 8,
      "z": 6,
      "name": "Rock_Chalk"
    },
    {
      "x": -8,
      "y": 7,
      "z": 7,
      "name": "Rock_Chalk"
    },
    {
      "x": -7,
      "y": 8,
      "z": -6,
      "name": "Rock_Chalk"
    },
    {
      "x": -7,
      "y": 10,
      "z": -2,
      "name": "Rock_Chalk"
    },
    {
      "x": -7,
      "y": 11,
      "z": -2,
      "name": "Rock_Chalk"
    },
    {
      "x": -7,
      "y": 10,
      "z": -1,
      "name": "Rock_Chalk"
    },
    {
      "x": -7,
      "y": 11,
      "z": -1,
      "name": "Rock_Chalk"
    },
    {
      "x": -7,
      "y": 10,
      "z": 0,
      "name": "Rock_Chalk"
    },
    {
      "x": -7,
      "y": 11,
      "z": 0,
      "name": "Rock_Chalk"
    },
    {
      "x": -7,
      "y": 10,
      "z": 1,
      "name": "Rock_Chalk"
    },
    {
      "x": -7,
      "y": 11,
      "z": 1,
      "name": "Rock_Chalk"
    },
    {
      "x": -7,
      "y": 10,
      "z": 2,
      "name": "Rock_Chalk"
    },
    {
      "x": -7,
      "y": 11,
      "z": 2,
      "name": "Rock_Chalk"
    },
    {
      "x": -7,
      "y": 10,
      "z": 3,
      "name": "Rock_Chalk"
    },
    {
      "x": -7,
      "y": 9,
      "z": 4,
      "name": "Rock_Chalk"
    },
    {
      "x": -7,
      "y": 10,
      "z": 4,
      "name": "Rock_Chalk"
    },
    {
      "x": -7,
      "y": 9,
      "z": 5,
      "name": "Rock_Chalk"
    },
    {
      "x": -7,
      "y": 8,
      "z": 6,
      "name": "Rock_Chalk"
    },
    {
      "x": -6,
      "y": 7,
      "z": -7,
      "name": "Rock_Chalk"
    },
    {
      "x": -6,
      "y": 8,
      "z": -6,
      "name": "Rock_Chalk"
    },
    {
      "x": -6,
      "y": 10,
      "z": -3,
      "name": "Rock_Chalk"
    },
    {
      "x": -6,
      "y": 11,
      "z": -3,
      "name": "Rock_Chalk"
    },
    {
      "x": -6,
      "y": 11,
      "z": -2,
      "name": "Rock_Chalk"
    },
    {
      "x": -6,
      "y": 11,
      "z": -1,
      "name": "Rock_Chalk"
    },
    {
      "x": -6,
      "y": 12,
      "z": -1,
      "name": "Rock_Marble"
    },
    {
      "x": -6,
      "y": 11,
      "z": 0,
      "name": "Rock_Chalk"
    },
    {
      "x": -6,
      "y": 12,
      "z": 0,
      "name": "Rock_Marble"
    },
    {
      "x": -6,
      "y": 11,
      "z": 1,
      "name": "Rock_Chalk"
    },
    {
      "x": -6,
      "y": 10,
      "z": 2,
      "name": "Rock_Chalk"
    },
    {
      "x": -6,
      "y": 11,
      "z": 2,
      "name": "Rock_Chalk"
    },
    {
      "x": -6,
      "y": 10,
      "z": 3,
      "name": "Rock_Chalk"
    },
    {
      "x": -6,
      "y": 11,
      "z": 3,
      "name": "Rock_Chalk"
    },
    {
      "x": -6,
      "y": 10,
      "z": 4,
      "name": "Rock_Chalk"
    },
    {
      "x": -6,
      "y": 9,
      "z": 5,
      "name": "Rock_Chalk"
    },
    {
      "x": -6,
      "y": 10,
      "z": 5,
      "name": "Rock_Chalk"
    },
    {
      "x": -6,
      "y": 9,
      "z": 6,
      "name": "Rock_Chalk"
    },
    {
      "x": -6,
      "y": 8,
      "z": 7,
      "name": "Rock_Chalk"
    },
    {
      "x": -6,
      "y": 7,
      "z": 8,
      "name": "Rock_Chalk"
    },
    {
      "x": -5,
      "y": 7,
      "z": -7,
      "name": "Rock_Chalk"
    },
    {
      "x": -5,
      "y": 11,
      "z": -3,
      "name": "Rock_Chalk"
    },
    {
      "x": -5,
      "y": 11,
      "z": -2,
      "name": "Rock_Chalk"
    },
    {
      "x": -5,
      "y": 12,
      "z": -2,
      "name": "Rock_Marble"
    },
    {
      "x": -5,
      "y": 11,
      "z": -1,
      "name": "Rock_Chalk"
    },
    {
      "x": -5,
      "y": 12,
      "z": -1,
      "name": "Rock_Marble"
    },
    {
      "x": -5,
      "y": 11,
      "z": 0,
      "name": "Rock_Chalk"
    },
    {
      "x": -5,
      "y": 12,
      "z": 0,
      "name": "Rock_Marble"
    },
    {
      "x": -5,
      "y": 11,
      "z": 1,
      "name": "Rock_Chalk"
    },
    {
      "x": -5,
      "y": 12,
      "z": 1,
      "name": "Rock_Marble"
    },
    {
      "x": -5,
      "y": 11,
      "z": 2,
      "name": "Rock_Chalk"
    },
    {
      "x": -5,
      "y": 10,
      "z": 3,
      "name": "Rock_Chalk"
    },
    {
      "x": -5,
      "y": 11,
      "z": 3,
      "name": "Rock_Chalk"
    },
    {
      "x": -5,
      "y": 10,
      "z": 4,
      "name": "Rock_Chalk"
    },
    {
      "x": -5,
      "y": 11,
      "z": 4,
      "name": "Rock_Chalk"
    },
    {
      "x": -5,
      "y": 10,
      "z": 5,
      "name": "Rock_Chalk"
    },
    {
      "x": -5,
      "y": 9,
      "z": 6,
      "name": "Rock_Chalk"
    },
    {
      "x": -5,
      "y": 9,
      "z": 7,
      "name": "Rock_Chalk"
    },
    {
      "x": -5,
      "y": 8,
      "z": 8,
      "name": "Rock_Chalk"
    },
    {
      "x": -5,
      "y": 7,
      "z": 9,
      "name": "Rock_Chalk"
    },
    {
      "x": -4,
      "y": 7,
      "z": -8,
      "name": "Rock_Chalk"
    },
    {
      "x": -4,
      "y": 8,
      "z": -7,
      "name": "Rock_Chalk"
    },
    {
      "x": -4,
      "y": 10,
      "z": -4,
      "name": "Rock_Chalk"
    },
    {
      "x": -4,
      "y": 11,
      "z": -4,
      "name": "Rock_Chalk"
    },
    {
      "x": -4,
      "y": 11,
      "z": -3,
      "name": "Rock_Chalk"
    },
    {
      "x": -4,
      "y": 12,
      "z": -3,
      "name": "Rock_Chalk"
    },
    {
      "x": -4,
      "y": 11,
      "z": -2,
      "name": "Rock_Chalk"
    },
    {
      "x": -4,
      "y": 12,
      "z": -2,
      "name": "Rock_Marble"
    },
    {
      "x": -4,
      "y": 11,
      "z": -1,
      "name": "Rock_Chalk"
    },
    {
      "x": -4,
      "y": 12,
      "z": -1,
      "name": "Rock_Marble"
    },
    {
      "x": -4,
      "y": 11,
      "z": 0,
      "name": "Rock_Chalk"
    },
    {
      "x": -4,
      "y": 12,
      "z": 0,
      "name": "Rock_Marble"
    },
    {
      "x": -4,
      "y": 11,
      "z": 1,
      "name": "Rock_Chalk"
    },
    {
      "x": -4,
      "y": 12,
      "z": 1,
      "name": "Rock_Marble"
    },
    {
      "x": -4,
      "y": 11,
      "z": 2,
      "name": "Rock_Chalk"
    },
    {
      "x": -4,
      "y": 12,
      "z": 2,
      "name": "Rock_Marble"
    },
    {
      "x": -4,
      "y": 11,
      "z": 3,
      "name": "Rock_Chalk"
    },
    {
      "x": -4,
      "y": 10,
      "z": 4,
      "name": "Rock_Chalk"
    },
    {
      "x": -4,
      "y": 11,
      "z": 4,
      "name": "Rock_Chalk"
    },
    {
      "x": -4,
      "y": 10,
      "z": 5,
      "name": "Rock_Chalk"
    },
    {
      "x": -4,
      "y": 11,
      "z": 5,
      "name": "Rock_Chalk"
    },
    {
      "x": -4,
      "y": 10,
      "z": 6,
      "name": "Rock_Chalk"
    },
    {
      "x": -4,
      "y": 9,
      "z": 7,
      "name": "Rock_Chalk"
    },
    {
      "x": -4,
      "y": 8,
      "z": 8,
      "name": "Rock_Chalk"
    },
    {
      "x": -4,
      "y": 7,
      "z": 9,
      "name": "Rock_Chalk"
    },
    {
      "x": -3,
      "y": 8,
      "z": -8,
      "name": "Rock_Chalk"
    },
    {
      "x": -3,
      "y": 9,
      "z": -7,
      "name": "Rock_Chalk"
    },
    {
      "x": -3,
      "y": 11,
      "z": -4,
      "name": "Rock_Chalk"
    },
    {
      "x": -3,
      "y": 12,
      "z": -4,
      "name": "Rock_Chalk"
    },
    {
      "x": -3,
      "y": 11,
      "z": -3,
      "name": "Rock_Chalk"
    },
    {
      "x": -3,
      "y": 12,
      "z": -3,
      "name": "Rock_Chalk"
    },
    {
      "x": -3,
      "y": 11,
      "z": -2,
      "name": "Rock_Chalk"
    },
    {
      "x": -3,
      "y": 12,
      "z": -2,
      "name": "Rock_Marble"
    },
    {
      "x": -3,
      "y": 12,
      "z": -1,
      "name": "Rock_Marble"
    },
    {
      "x": -3,
      "y": 13,
      "z": -1,
      "name": "Rock_Marble"
    },
    {
      "x": -3,
      "y": 12,
      "z": 0,
      "name": "Rock_Marble"
    },
    {
      "x": -3,
      "y": 13,
      "z": 0,
      "name": "Rock_Marble"
    },
    {
      "x": -3,
      "y": 11,
      "z": 1,
      "name": "Rock_Chalk"
    },
    {
      "x": -3,
      "y": 12,
      "z": 1,
      "name": "Rock_Marble"
    },
    {
      "x": -3,
      "y": 11,
      "z": 2,
      "name": "Rock_Chalk"
    },
    {
      "x": -3,
      "y": 12,
      "z": 2,
      "name": "Rock_Chalk"
    },
    {
      "x": -3,
      "y": 11,
      "z": 3,
      "name": "Rock_Chalk"
    },
    {
      "x": -3,
      "y": 12,
      "z": 3,
      "name": "Rock_Chalk"
    },
    {
      "x": -3,
      "y": 11,
      "z": 4,
      "name": "Rock_Chalk"
    },
    {
      "x": -3,
      "y": 12,
      "z": 4,
      "name": "Rock_Chalk"
    },
    {
      "x": -3,
      "y": 10,
      "z": 5,
      "name": "Rock_Chalk"
    },
    {
      "x": -3,
      "y": 11,
      "z": 5,
      "name": "Rock_Chalk"
    },
    {
      "x": -3,
      "y": 10,
      "z": 6,
      "name": "Rock_Chalk"
    },
    {
      "x": -3,
      "y": 9,
      "z": 7,
      "name": "Rock_Chalk"
    },
    {
      "x": -3,
      "y": 10,
      "z": 7,
      "name": "Rock_Chalk"
    },
    {
      "x": -3,
      "y": 8,
      "z": 8,
      "name": "Rock_Chalk"
    },
    {
      "x": -3,
      "y": 9,
      "z": 8,
      "name": "Rock_Chalk"
    },
    {
      "x": -3,
      "y": 8,
      "z": 9,
      "name": "Rock_Chalk"
    },
    {
      "x": -3,
      "y": 7,
      "z": 10,
      "name": "Rock_Chalk"
    },
    {
      "x": -2,
      "y": 11,
      "z": -4,
      "name": "Rock_Chalk"
    },
    {
      "x": -2,
      "y": 12,
      "z": -4,
      "name": "Rock_Chalk"
    },
    {
      "x": -2,
      "y": 11,
      "z": -3,
      "name": "Rock_Chalk"
    },
    {
      "x": -2,
      "y": 12,
      "z": -3,
      "name": "Rock_Chalk"
    },
    {
      "x": -2,
      "y": 11,
      "z": -2,
      "name": "Rock_Chalk"
    },
    {
      "x": -2,
      "y": 12,
      "z": -2,
      "name": "Rock_Chalk"
    },
    {
      "x": -2,
      "y": 13,
      "z": -2,
      "name": "Rock_Marble"
    },
    {
      "x": -2,
      "y": 12,
      "z": -1,
      "name": "Rock_Marble"
    },
    {
      "x": -2,
      "y": 13,
      "z": -1,
      "name": "Rock_Marble"
    },
    {
      "x": -2,
      "y": 12,
      "z": 0,
      "name": "Rock_Marble"
    },
    {
      "x": -2,
      "y": 13,
      "z": 0,
      "name": "Rock_Marble"
    },
    {
      "x": -2,
      "y": 12,
      "z": 1,
      "name": "Rock_Marble"
    },
    {
      "x": -2,
      "y": 13,
      "z": 1,
      "name": "Rock_Marble"
    },
    {
      "x": -2,
      "y": 12,
      "z": 2,
      "name": "Rock_Chalk"
    },
    {
      "x": -2,
      "y": 13,
      "z": 2,
      "name": "Rock_Marble"
    },
    {
      "x": -2,
      "y": 11,
      "z": 3,
      "name": "Rock_Chalk"
    },
    {
      "x": -2,
      "y": 12,
      "z": 3,
      "name": "Rock_Chalk"
    },
    {
      "x": -2,
      "y": 11,
      "z": 4,
      "name": "Rock_Chalk"
    },
    {
      "x": -2,
      "y": 12,
      "z": 4,
      "name": "Rock_Chalk"
    },
    {
      "x": -2,
      "y": 11,
      "z": 5,
      "name": "Rock_Chalk"
    },
    {
      "x": -2,
      "y": 10,
      "z": 6,
      "name": "Rock_Chalk"
    },
    {
      "x": -2,
      "y": 11,
      "z": 6,
      "name": "Rock_Chalk"
    },
    {
      "x": -2,
      "y": 9,
      "z": 7,
      "name": "Rock_Chalk"
    },
    {
      "x": -2,
      "y": 10,
      "z": 7,
      "name": "Rock_Chalk"
    },
    {
      "x": -2,
      "y": 9,
      "z": 8,
      "name": "Rock_Chalk"
    },
    {
      "x": -2,
      "y": 8,
      "z": 9,
      "name": "Rock_Chalk"
    },
    {
      "x": -2,
      "y": 7,
      "z": 10,
      "name": "Rock_Chalk"
    },
    {
      "x": -1,
      "y": 12,
      "z": -2,
      "name": "Rock_Chalk"
    },
    {
      "x": -1,
      "y": 13,
      "z": -2,
      "name": "Rock_Marble"
    },
    {
      "x": -1,
      "y": 12,
      "z": -1,
      "name": "Rock_Marble"
    },
    {
      "x": -1,
      "y": 13,
      "z": -1,
      "name": "Rock_Marble"
    },
    {
      "x": -1,
      "y": 12,
      "z": 0,
      "name": "Rock_Marble"
    },
    {
      "x": -1,
      "y": 13,
      "z": 0,
      "name": "Rock_Marble"
    },
    {
      "x": -1,
      "y": 12,
      "z": 1,
      "name": "Rock_Marble"
    },
    {
      "x": -1,
      "y": 13,
      "z": 1,
      "name": "Rock_Marble"
    },
    {
      "x": -1,
      "y": 12,
      "z": 2,
      "name": "Rock_Chalk"
    },
    {
      "x": -1,
      "y": 13,
      "z": 2,
      "name": "Rock_Marble"
    },
    {
      "x": -1,
      "y": 12,
      "z": 3,
      "name": "Rock_Chalk"
    },
    {
      "x": -1,
      "y": 13,
      "z": 3,
      "name": "Rock_Marble"
    },
    {
      "x": -1,
      "y": 11,
      "z": 4,
      "name": "Rock_Chalk"
    },
    {
      "x": -1,
      "y": 12,
      "z": 4,
      "name": "Rock_Chalk"
    },
    {
      "x": -1,
      "y": 11,
      "z": 5,
      "name": "Rock_Chalk"
    },
    {
      "x": -1,
      "y": 12,
      "z": 5,
      "name": "Rock_Chalk"
    },
    {
      "x": -1,
      "y": 10,
      "z": 6,
      "name": "Rock_Chalk"
    },
    {
      "x": -1,
      "y": 11,
      "z": 6,
      "name": "Rock_Chalk"
    },
    {
      "x": -1,
      "y": 9,
      "z": 7,
      "name": "Rock_Chalk"
    },
    {
      "x": -1,
      "y": 10,
      "z": 7,
      "name": "Rock_Chalk"
    },
    {
      "x": -1,
      "y": 8,
      "z": 8,
      "name": "Rock_Chalk"
    },
    {
      "x": -1,
      "y": 9,
      "z": 8,
      "name": "Rock_Chalk"
    },
    {
      "x": -1,
      "y": 8,
      "z": 9,
      "name": "Rock_Chalk"
    },
    {
      "x": 0,
      "y": 12,
      "z": 0,
      "name": "Rock_Marble"
    },
    {
      "x": 0,
      "y": 13,
      "z": 0,
      "name": "Rock_Marble"
    },
    {
      "x": 0,
      "y": 12,
      "z": 1,
      "name": "Rock_Marble"
    },
    {
      "x": 0,
      "y": 13,
      "z": 1,
      "name": "Rock_Marble"
    },
    {
      "x": 0,
      "y": 12,
      "z": 2,
      "name": "Rock_Marble"
    },
    {
      "x": 0,
      "y": 13,
      "z": 2,
      "name": "Rock_Marble"
    },
    {
      "x": 0,
      "y": 12,
      "z": 3,
      "name": "Rock_Chalk"
    },
    {
      "x": 0,
      "y": 13,
      "z": 3,
      "name": "Rock_Marble"
    },
    {
      "x": 0,
      "y": 12,
      "z": 4,
      "name": "Rock_Chalk"
    },
    {
      "x": 0,
      "y": 13,
      "z": 4,
      "name": "Rock_Marble"
    },
    {
      "x": 0,
      "y": 11,
      "z": 5,
      "name": "Rock_Chalk"
    },
    {
      "x": 0,
      "y": 12,
      "z": 5,
      "name": "Rock_Chalk"
    },
    {
      "x": 0,
      "y": 10,
      "z": 6,
      "name": "Rock_Chalk"
    },
    {
      "x": 0,
      "y": 11,
      "z": 6,
      "name": "Rock_Chalk"
    },
    {
      "x": 0,
      "y": 9,
      "z": 7,
      "name": "Rock_Chalk"
    },
    {
      "x": 0,
      "y": 10,
      "z": 7,
      "name": "Rock_Chalk"
    },
    {
      "x": 0,
      "y": 8,
      "z": 8,
      "name": "Rock_Chalk"
    },
    {
      "x": 0,
      "y": 7,
      "z": 9,
      "name": "Rock_Chalk"
    },
    {
      "x": 1,
      "y": 12,
      "z": 1,
      "name": "Rock_Marble"
    },
    {
      "x": 1,
      "y": 13,
      "z": 1,
      "name": "Rock_Marble"
    },
    {
      "x": 1,
      "y": 12,
      "z": 2,
      "name": "Rock_Marble"
    },
    {
      "x": 1,
      "y": 13,
      "z": 2,
      "name": "Rock_Marble"
    },
    {
      "x": 1,
      "y": 12,
      "z": 3,
      "name": "Rock_Chalk"
    },
    {
      "x": 1,
      "y": 13,
      "z": 3,
      "name": "Rock_Marble"
    },
    {
      "x": 1,
      "y": 12,
      "z": 4,
      "name": "Rock_Chalk"
    },
    {
      "x": 1,
      "y": 13,
      "z": 4,
      "name": "Rock_Marble"
    },
    {
      "x": 2,
      "y": 10,
      "z": -6,
      "name": "Rock_Chalk"
    },
    {
      "x": 2,
      "y": 10,
      "z": -5,
      "name": "Rock_Chalk"
    },
    {
      "x": 2,
      "y": 11,
      "z": -5,
      "name": "Rock_Chalk"
    },
    {
      "x": 2,
      "y": 11,
      "z": -4,
      "name": "Rock_Chalk"
    },
    {
      "x": 2,
      "y": 11,
      "z": -3,
      "name": "Rock_Chalk"
    },
    {
      "x": 2,
      "y": 12,
      "z": -3,
      "name": "Rock_Chalk"
    },
    {
      "x": 2,
      "y": 11,
      "z": -2,
      "name": "Rock_Chalk"
    },
    {
      "x": 2,
      "y": 12,
      "z": -2,
      "name": "Rock_Chalk"
    },
    {
      "x": 3,
      "y": 9,
      "z": -7,
      "name": "Rock_Chalk"
    },
    {
      "x": 3,
      "y": 10,
      "z": -6,
      "name": "Rock_Chalk"
    },
    {
      "x": 3,
      "y": 10,
      "z": -5,
      "name": "Rock_Chalk"
    },
    {
      "x": 3,
      "y": 11,
      "z": -5,
      "name": "Rock_Chalk"
    },
    {
      "x": 3,
      "y": 10,
      "z": -4,
      "name": "Rock_Chalk"
    },
    {
      "x": 3,
      "y": 11,
      "z": -4,
      "name": "Rock_Chalk"
    },
    {
      "x": 3,
      "y": 11,
      "z": -3,
      "name": "Rock_Chalk"
    },
    {
      "x": 3,
      "y": 12,
      "z": -3,
      "name": "Rock_Chalk"
    },
    {
      "x": 3,
      "y": 11,
      "z": -2,
      "name": "Rock_Chalk"
    },
    {
      "x": 3,
      "y": 12,
      "z": -2,
      "name": "Rock_Chalk"
    },
    {
      "x": 3,
      "y": 11,
      "z": -1,
      "name": "Rock_Chalk"
    },
    {
      "x": 3,
      "y": 12,
      "z": -1,
      "name": "Rock_Chalk"
    },
    {
      "x": 4,
      "y": 8,
      "z": -8,
      "name": "Rock_Chalk"
    },
    {
      "x": 4,
      "y": 9,
      "z": -7,
      "name": "Rock_Chalk"
    },
    {
      "x": 4,
      "y": 9,
      "z": -6,
      "name": "Rock_Chalk"
    },
    {
      "x": 4,
      "y": 10,
      "z": -6,
      "name": "Rock_Chalk"
    },
    {
      "x": 4,
      "y": 10,
      "z": -5,
      "name": "Rock_Chalk"
    },
    {
      "x": 4,
      "y": 10,
      "z": -4,
      "name": "Rock_Chalk"
    },
    {
      "x": 4,
      "y": 11,
      "z": -4,
      "name": "Rock_Chalk"
    },
    {
      "x": 4,
      "y": 11,
      "z": -3,
      "name": "Rock_Chalk"
    },
    {
      "x": 4,
      "y": 11,
      "z": -2,
      "name": "Rock_Chalk"
    },
    {
      "x": 4,
      "y": 12,
      "z": -2,
      "name": "Rock_Chalk"
    },
    {
      "x": 4,
      "y": 11,
      "z": -1,
      "name": "Rock_Chalk"
    },
    {
      "x": 4,
      "y": 12,
      "z": -1,
      "name": "Rock_Chalk"
    },
    {
      "x": 4,
      "y": 11,
      "z": 0,
      "name": "Rock_Chalk"
    },
    {
      "x": 4,
      "y": 12,
      "z": 0,
      "name": "Rock_Chalk"
    },
    {
      "x": 5,
      "y": 7,
      "z": -8,
      "name": "Rock_Chalk"
    },
    {
      "x": 5,
      "y": 8,
      "z": -7,
      "name": "Rock_Chalk"
    },
    {
      "x": 5,
      "y": 9,
      "z": -6,
      "name": "Rock_Chalk"
    },
    {
      "x": 5,
      "y": 10,
      "z": -5,
      "name": "Rock_Chalk"
    },
    {
      "x": 5,
      "y": 10,
      "z": -4,
      "name": "Rock_Chalk"
    },
    {
      "x": 5,
      "y": 11,
      "z": -4,
      "name": "Rock_Chalk"
    },
    {
      "x": 5,
      "y": 10,
      "z": -3,
      "name": "Rock_Chalk"
    },
    {
      "x": 5,
      "y": 11,
      "z": -3,
      "name": "Rock_Chalk"
    },
    {
      "x": 5,
      "y": 11,
      "z": -2,
      "name": "Rock_Chalk"
    },
    {
      "x": 5,
      "y": 11,
      "z": -1,
      "name": "Rock_Chalk"
    },
    {
      "x": 5,
      "y": 12,
      "z": -1,
      "name": "Rock_Chalk"
    },
    {
      "x": 5,
      "y": 11,
      "z": 0,
      "name": "Rock_Chalk"
    },
    {
      "x": 5,
      "y": 12,
      "z": 0,
      "name": "Rock_Chalk"
    },
    {
      "x": 5,
      "y": 11,
      "z": 1,
      "name": "Rock_Chalk"
    },
    {
      "x": 5,
      "y": 12,
      "z": 1,
      "name": "Rock_Chalk"
    },
    {
      "x": 5,
      "y": 11,
      "z": 2,
      "name": "Rock_Chalk"
    },
    {
      "x": 5,
      "y": 12,
      "z": 2,
      "name": "Rock_Chalk"
    },
    {
      "x": 5,
      "y": 11,
      "z": 3,
      "name": "Rock_Chalk"
    },
    {
      "x": 5,
      "y": 12,
      "z": 3,
      "name": "Rock_Chalk"
    },
    {
      "x": 5,
      "y": 11,
      "z": 4,
      "name": "Rock_Chalk"
    },
    {
      "x": 5,
      "y": 12,
      "z": 4,
      "name": "Rock_Chalk"
    },
    {
      "x": 6,
      "y": 8,
      "z": -7,
      "name": "Rock_Chalk"
    },
    {
      "x": 6,
      "y": 9,
      "z": -6,
      "name": "Rock_Chalk"
    },
    {
      "x": 6,
      "y": 9,
      "z": -5,
      "name": "Rock_Chalk"
    },
    {
      "x": 6,
      "y": 10,
      "z": -5,
      "name": "Rock_Chalk"
    },
    {
      "x": 6,
      "y": 10,
      "z": -4,
      "name": "Rock_Chalk"
    },
    {
      "x": 6,
      "y": 10,
      "z": -3,
      "name": "Rock_Chalk"
    },
    {
      "x": 6,
      "y": 11,
      "z": -3,
      "name": "Rock_Chalk"
    },
    {
      "x": 6,
      "y": 10,
      "z": -2,
      "name": "Rock_Chalk"
    },
    {
      "x": 6,
      "y": 11,
      "z": -2,
      "name": "Rock_Chalk"
    },
    {
      "x": 6,
      "y": 10,
      "z": -1,
      "name": "Rock_Chalk"
    },
    {
      "x": 6,
      "y": 11,
      "z": -1,
      "name": "Rock_Chalk"
    },
    {
      "x": 6,
      "y": 10,
      "z": 0,
      "name": "Rock_Chalk"
    },
    {
      "x": 6,
      "y": 11,
      "z": 0,
      "name": "Rock_Chalk"
    },
    {
      "x": 6,
      "y": 10,
      "z": 1,
      "name": "Rock_Chalk"
    },
    {
      "x": 6,
      "y": 11,
      "z": 1,
      "name": "Rock_Chalk"
    },
    {
      "x": 6,
      "y": 10,
      "z": 2,
      "name": "Rock_Chalk"
    },
    {
      "x": 6,
      "y": 11,
      "z": 2,
      "name": "Rock_Chalk"
    },
    {
      "x": 6,
      "y": 10,
      "z": 3,
      "name": "Rock_Chalk"
    },
    {
      "x": 6,
      "y": 11,
      "z": 3,
      "name": "Rock_Chalk"
    },
    {
      "x": 6,
      "y": 10,
      "z": 4,
      "name": "Rock_Chalk"
    },
    {
      "x": 6,
      "y": 11,
      "z": 4,
      "name": "Rock_Chalk"
    },
    {
      "x": 6,
      "y": 10,
      "z": 5,
      "name": "Rock_Chalk"
    },
    {
      "x": 6,
      "y": 9,
      "z": 6,
      "name": "Rock_Chalk"
    },
    {
      "x": 6,
      "y": 10,
      "z": 6,
      "name": "Rock_Chalk"
    },
    {
      "x": 6,
      "y": 8,
      "z": 7,
      "name": "Rock_Chalk"
    },
    {
      "x": 6,
      "y": 9,
      "z": 7,
      "name": "Rock_Chalk"
    },
    {
      "x": 7,
      "y": 7,
      "z": -7,
      "name": "Rock_Chalk"
    },
    {
      "x": 7,
      "y": 8,
      "z": -6,
      "name": "Rock_Chalk"
    },
    {
      "x": 7,
      "y": 9,
      "z": -5,
      "name": "Rock_Chalk"
    },
    {
      "x": 7,
      "y": 9,
      "z": -4,
      "name": "Rock_Chalk"
    },
    {
      "x": 7,
      "y": 10,
      "z": -4,
      "name": "Rock_Chalk"
    },
    {
      "x": 7,
      "y": 10,
      "z": -3,
      "name": "Rock_Chalk"
    },
    {
      "x": 7,
      "y": 10,
      "z": -2,
      "name": "Rock_Chalk"
    },
    {
      "x": 7,
      "y": 10,
      "z": -1,
      "name": "Rock_Chalk"
    },
    {
      "x": 7,
      "y": 10,
      "z": 0,
      "name": "Rock_Chalk"
    },
    {
      "x": 7,
      "y": 10,
      "z": 1,
      "name": "Rock_Chalk"
    },
    {
      "x": 7,
      "y": 10,
      "z": 2,
      "name": "Rock_Chalk"
    },
    {
      "x": 7,
      "y": 10,
      "z": 3,
      "name": "Rock_Chalk"
    },
    {
      "x": 7,
      "y": 10,
      "z": 4,
      "name": "Rock_Chalk"
    },
    {
      "x": 7,
      "y": 9,
      "z": 5,
      "name": "Rock_Chalk"
    },
    {
      "x": 7,
      "y": 10,
      "z": 5,
      "name": "Rock_Chalk"
    },
    {
      "x": 7,
      "y": 9,
      "z": 6,
      "name": "Rock_Chalk"
    },
    {
      "x": 7,
      "y": 8,
      "z": 7,
      "name": "Rock_Chalk"
    },
    {
      "x": 7,
      "y": 7,
      "z": 8,
      "name": "Rock_Chalk"
    },
    {
      "x": 8,
      "y": 7,
      "z": -6,
      "name": "Rock_Chalk"
    },
    {
      "x": 8,
      "y": 8,
      "z": -5,
      "name": "Rock_Chalk"
    },
    {
      "x": 8,
      "y": 9,
      "z": -4,
      "name": "Rock_Chalk"
    },
    {
      "x": 8,
      "y": 9,
      "z": -3,
      "name": "Rock_Chalk"
    },
    {
      "x": 8,
      "y": 9,
      "z": -2,
      "name": "Rock_Chalk"
    },
    {
      "x": 8,
      "y": 9,
      "z": -1,
      "name": "Rock_Chalk"
    },
    {
      "x": 8,
      "y": 10,
      "z": -1,
      "name": "Rock_Chalk"
    },
    {
      "x": 8,
      "y": 9,
      "z": 0,
      "name": "Rock_Chalk"
    },
    {
      "x": 8,
      "y": 9,
      "z": 1,
      "name": "Rock_Chalk"
    },
    {
      "x": 8,
      "y": 9,
      "z": 2,
      "name": "Rock_Chalk"
    },
    {
      "x": 8,
      "y": 9,
      "z": 3,
      "name": "Rock_Chalk"
    },
    {
      "x": 8,
      "y": 9,
      "z": 4,
      "name": "Rock_Chalk"
    },
    {
      "x": 8,
      "y": 9,
      "z": 5,
      "name": "Rock_Chalk"
    },
    {
      "x": 8,
      "y": 9,
      "z": 6,
      "name": "Rock_Chalk"
    },
    {
      "x": 8,
      "y": 8,
      "z": 7,
      "name": "Rock_Chalk"
    },
    {
      "x": 8,
      "y": 7,
      "z": 8,
      "name": "Rock_Chalk"
    },
    {
      "x": 9,
      "y": 7,
      "z": -5,
      "name": "Rock_Chalk"
    },
    {
      "x": 9,
      "y": 8,
      "z": -4,
      "name": "Rock_Chalk"
    },
    {
      "x": 9,
      "y": 8,
      "z": -3,
      "name": "Rock_Chalk"
    },
    {
      "x": 9,
      "y": 8,
      "z": -2,
      "name": "Rock_Chalk"
    },
    {
      "x": 9,
      "y": 8,
      "z": -1,
      "name": "Rock_Chalk"
    },
    {
      "x": 9,
      "y": 8,
      "z": 0,
      "name": "Rock_Chalk"
    },
    {
      "x": 9,
      "y": 8,
      "z": 1,
      "name": "Rock_Chalk"
    },
    {
      "x": 9,
      "y": 8,
      "z": 2,
      "name": "Rock_Chalk"
    },
    {
      "x": 9,
      "y": 8,
      "z": 3,
      "name": "Rock_Chalk"
    },
    {
      "x": 9,
      "y": 9,
      "z": 3,
      "name": "Rock_Chalk"
    },
    {
      "x": 9,
      "y": 9,
      "z": 4,
      "name": "Rock_Chalk"
    },
    {
      "x": 9,
      "y": 9,
      "z": 5,
      "name": "Rock_Chalk"
    },
    {
      "x": 9,
      "y": 8,
      "z": 6,
      "name": "Rock_Chalk"
    },
    {
      "x": 9,
      "y": 8,
      "z": 7,
      "name": "Rock_Chalk"
    },
    {
      "x": 10,
      "y": 7,
      "z": -4,
      "name": "Rock_Chalk"
    },
    {
      "x": 10,
      "y": 7,
      "z": -3,
      "name": "Rock_Chalk"
    },
    {
      "x": 10,
      "y": 7,
      "z": -2,
      "name": "Rock_Chalk"
    },
    {
      "x": 10,
      "y": 7,
      "z": -1,
      "name": "Rock_Chalk"
    },
    {
      "x": 10,
      "y": 7,
      "z": 0,
      "name": "Rock_Chalk"
    },
    {
      "x": 10,
      "y": 7,
      "z": 1,
      "name": "Rock_Chalk"
    },
    {
      "x": 10,
      "y": 7,
      "z": 2,
      "name": "Rock_Chalk"
    },
    {
      "x": 10,
      "y": 8,
      "z": 3,
      "name": "Rock_Chalk"
    },
    {
      "x": 10,
      "y": 8,
      "z": 4,
      "name": "Rock_Chalk"
    },
    {
      "x": 10,
      "y": 8,
      "z": 5,
      "name": "Rock_Chalk"
    },
    {
      "x": 10,
      "y": 8,
      "z": 6,
      "name": "Rock_Chalk"
    },
    {
      "x": 10,
      "y": 7,
      "z": 7,
      "name": "Rock_Chalk"
    },
    {
      "x": 11,
      "y": 7,
      "z": 3,
      "name": "Rock_Chalk"
    },
    {
      "x": 11,
      "y": 7,
      "z": 4,
      "name": "Rock_Chalk"
    },
    {
      "x": 11,
      "y": 7,
      "z": 5,
      "name": "Rock_Chalk"
    },
    {
      "x": 11,
      "y": 7,
      "z": 6,
      "name": "Rock_Chalk"
    },
    {
      "x": 12,
      "y": 6,
      "z": 5,
      "name": "Rock_Marble"
    }
  ]
}