{
  "version": 8,
  "blockIdVersion": 8,
  "anchorX": -1,
  "anchorY": 0,
  "anchorZ": -2,
  "blocks": [
    {
      "x": -11,
      "y": 17,
      "z": 1,
      "name": "Plant_Leaves_Dry"
    },
    {
      "x": -10,
      "y": 17,
      "z": -1,
      "name": "Plant_Leaves_Dry"
    },
    {
      "x": -10,
      "y": 17,
      "z": 0,
      "name": "Plant_Leaves_Dry"
    },
    {
      "x": -10,
      "y": 17,
      "z": 1,
      "name": "Plant_Leaves_Dry"
    },
    {
      "x": -10,
      "y": 17,
      "z": 2,
      "name": "Plant_Leaves_Dry"
    },
    {
      "x": -10,
      "y": 17,
      "z": 3,
      "name": "Plant_Leaves_Dry"
    },
    {
      "x": -9,
      "y": 17,
      "z": -3,
      "name": "Plant_Leaves_Dry"
    },
    {
      "x": -9,
      "y": 17,
      "z": -2,
      "name": "Plant_Leaves_Dry"
    },
    {
      "x": -9,
      "y": 17,
      "z": -1,
      "name": "Plant_Leaves_Dry"
    },
    {
      "x": -9,
      "y": 17,
      "z": 0,
      "name": "Plant_Leaves_Dry"
    },
    {
      "x": -9,
      "y": 18,
      "z": 0,
      "name": "Plant_Leaves_Dry"
    },
    {
      "x": -9,
      "y": 17,
      "z": 1,
      "name": "Plant_Leaves_Dry"
    },
    {
      "x": -9,
      "y": 17,
      "z": 2,
      "name": "Plant_Leaves_Dry"
    },
    {
      "x": -9,
      "y": 17,
      "z": 3,
      "name": "Plant_Leaves_Dry"
    },
    {
      "x": -9,
      "y": 17,
      "z": 4,
      "name": "Plant_Leaves_Dry"
    },
    {
      "x": -9,
      "y": 17,
      "z": 5,
      "name": "Plant_Leaves_Dry"
    },
    {
      "x": -8,
      "y": 17,
      "z": -4,
      "name": "Plant_Leaves_Dry"
    },
    {
      "x": -8,
      "y": 17,
      "z": -3,
      "name": "Plant_Leaves_Dry"
    },
    {
      "x": -8,
      "y": 17,
      "z": -2,
      "name": "Plant_Leaves_Dry"
    },
    {
      "x": -8,
      "y": 17,
      "z": -1,
      "name": "Plant_Leaves_Dry"
    },
    {
      "x": -8,
      "y": 18,
      "z": 0,
      "name": "Plant_Leaves_Dry"
    },
    {
      "x": -8,
      "y": 17,
      "z": 1,
      "name": "Wood_Dry_Branch_Long",
      "rotation": 5
    },
    {
      "x": -8,
      "y": 18,
      "z": 1,
      "name": "Plant_Leaves_Dry"
    },
    {
      "x": -8,
      "y": 17,
      "z": 2,
      "name": "Plant_Leaves_Dry"
    },
    {
      "x": -8,
      "y": 17,
      "z": 3,
      "name": "Plant_Leaves_Dry"
    },
    {
      "x": -8,
      "y": 17,
      "z": 4,
      "name": "Plant_Leaves_Dry"
    },
    {
      "x": -8,
      "y": 17,
      "z": 5,
      "name": "Plant_Leaves_Dry"
    },
    {
      "x": -7,
      "y": 17,
      "z": -4,
      "name": "Plant_Leaves_Dry"
    },
    {
      "x": -7,
      "y": 17,
      "z": -3,
      "name": "Plant_Leaves_Dry"
    },
    {
      "x": -7,
      "y": 17,
      "z": -2,
      "name": "Plant_Leaves_Dry"
    },
    {
      "x": -7,
      "y": 18,
      "z": -1,
      "name": "Plant_Leaves_Dry"
    },
    {
      "x": -7,
      "y": 18,
      "z": 0,
      "name": "Plant_Leaves_Dry"
    },
    {
      "x": -7,
      "y": 17,
      "z": 1,
      "name": "Wood_Dry_Branch_Long",
      "rotation": 5
    },
    {
      "x": -7,
      "y": 18,
      "z": 1,
      "name": "Plant_Leaves_Dry"
    },
    {
      "x": -7,
      "y": 18,
      "z": 2,
      "name": "Plant_Leaves_Dry"
    },
    {
      "x": -7,
      "y": 18,
      "z": 3,
      "name": "Plant_Leaves_Dry"
    },
    {
      "x": -7,
      "y": 17,
      "z": 4,
      "name": "Plant_Leaves_Dry"
    },
    {
      "x": -7,
      "y": 17,
      "z": 5,
      "name": "Plant_Leaves_Dry"
    },
    {
      "x": -7,
      "y": 17,
      "z": 6,
      "name": "Plant_Leaves_Dry"
    },
    {
      "x": -6,
      "y": 17,
      "z": -4,
      "name": "Plant_Leaves_Dry"
    },
    {
      "x": -6,
      "y": 17,
      "z": -3,
      "name": "Plant_Leaves_Dry"
    },
    {
      "x": -6,
      "y": 17,
      "z": -2,
      "name": "Plant_Leaves_Dry"
    },
    {
      "x": -6,
      "y": 18,
      "z": -2,
      "name": "Plant_Leaves_Dry"
    },
    {
      "x": -6,
      "y": 17,
      "z": -1,
      "name": "Wood_Dry_Branch_Long",
      "rotation": 4
    },
    {
      "x": -6,
      "y": 18,
      "z": -1,
      "name": "Plant_Leaves_Dry"
    },
    {
      "x": -6,
      "y": 17,
      "z": 0,
      "name": "Wood_Dry_Branch_Long",
      "rotation": 4
    },
    {
      "x": -6,
      "y": 18,
      "z": 0,
      "name": "Plant_Leaves_Dry"
    },
    {
      "x": -6,
      "y": 17,
      "z": 1,
      "name": "Wood_Dry_Trunk_Full"
    },
    {
      "x": -6,
      "y": 17,
      "z": 2,
      "name": "Wood_Dry_Branch_Long",
      "rotation": 4
    },
    {
      "x": -6,
      "y": 17,
      "z": 3,
      "name": "Wood_Dry_Branch_Long",
      "rotation": 4
    },
    {
      "x": -6,
      "y": 18,
      "z": 3,
      "name": "Plant_Leaves_Dry"
    },
    {
      "x": -6,
      "y": 17,
      "z": 4,
      "name": "Plant_Leaves_Dry"
    },
    {
      "x": -6,
      "y": 17,
      "z": 5,
      "name": "Plant_Leaves_Dry"
    },
    {
      "x": -5,
      "y": 15,
      "z": -5,
      "name": "Plant_Leaves_Dry"
    },
    {
      "x": -5,
      "y": 15,
      "z": -4,
      "name": "Plant_Leaves_Dry"
    },
    {
      "x": -5,
      "y": 17,
      "z": -4,
      "name": "Plant_Leaves_Dry"
    },
    {
      "x": -5,
      "y": 15,
      "z": -3,
      "name": "Plant_Leaves_Dry"
    },
    {
      "x": -5,
      "y": 17,
      "z": -3,
      "name": "Plant_Leaves_Dry"
    },
    {
      "x": -5,
      "y": 17,
      "z": -2,
      "name": "Plant_Leaves_Dry"
    },
    {
      "x": -5,
      "y": 14,
      "z": 0,
      "name": "Wood_Dry_Trunk_Full"
    },
    {
      "x": -5,
      "y": 15,
      "z": 0,
      "name": "Wood_Dry_Trunk"
    },
    {
      "x": -5,
      "y": 16,
      "z": 0,
      "name": "Wood_Dry_Trunk_Full"
    },
    {
      "x": -5,
      "y": 18,
      "z": 0,
      "name": "Plant_Leaves_Dry"
    },
    {
      "x": -5,
      "y": 16,
      "z": 1,
      "name": "Wood_Dry_Trunk_Full"
    },
    {
      "x": -5,
      "y": 17,
      "z": 1,
      "name": "Wood_Dry_Trunk_Full"
    },
    {
      "x": -5,
      "y": 18,
      "z": 1,
      "name": "Plant_Leaves_Dry"
    },
    {
      "x": -5,
      "y": 18,
      "z": 2,
      "name": "Plant_Leaves_Dry"
    },
    {
      "x": -5,
      "y": 17,
      "z": 3,
      "name": "Plant_Leaves_Dry"
    },
    {
      "x": -5,
      "y": 17,
      "z": 5,
      "name": "Plant_Leaves_Dry"
    },
    {
      "x": -5,
      "y": 17,
      "z": 6,
      "name": "Plant_Leaves_Dry"
    },
    {
      "x": -4,
      "y": 15,
      "z": -5,
      "name": "Plant_Leaves_Dry"
    },
    {
      "x": -4,
      "y": 15,
      "z": -4,
      "name": "Plant_Leaves_Dry"
    },
    {
      "x": -4,
      "y": 17,
      "z": -3,
      "name": "Plant_Leaves_Dry"
    },
    {
      "x": -4,
      "y": 16,
      "z": -2,
      "name": "Plant_Leaves_Dry"
    },
    {
      "x": -4,
      "y": 17,
      "z": -2,
      "name": "Plant_Leaves_Dry"
    },
    {
      "x": -4,
      "y": 16,
      "z": -1,
      "name": "Plant_Leaves_Dry"
    },
    {
      "x": -4,
      "y": 9,
      "z": 0,
      "name": "Wood_Dry_Trunk_Full"
    },
    {
      "x": -4,
      "y": 10,
      "z": 0,
      "name": "Wood_Dry_Trunk"
    },
    {
      "x": -4,
      "y": 11,
      "z": 0,
      "name": "Wood_Dry_Trunk"
    },
    {
      "x": -4,
      "y": 12,
      "z": 0,
      "name": "Wood_Dry_Trunk"
    },
    {
      "x": -4,
      "y": 13,
      "z": 0,
      "name": "Wood_Dry_Trunk"
    },
    {
      "x": -4,
      "y": 14,
      "z": 0,
      "name": "Wood_Dry_Trunk_Full"
    },
    {
      "x": -4,
      "y": 18,
      "z": 1,
      "name": "Plant_Leaves_Dry"
    },
    {
      "x": -4,
      "y": 15,
      "z": 2,
      "name": "Plant_Leaves_Dry"
    },
    {
      "x": -4,
      "y": 18,
      "z": 2,
      "name": "Plant_Leaves_Dry"
    },
    {
      "x": -4,
      "y": 15,
      "z": 3,
      "name": "Plant_Leaves_Dry"
    },
    {
      "x": -4,
      "y": 17,
      "z": 4,
      "name": "Plant_Leaves_Dry"
    },
    {
      "x": -4,
      "y": 17,
      "z": 5,
      "name": "Plant_Leaves_Dry"
    },
    {
      "x": -3,
      "y": 15,
      "z": -6,
      "name": "Plant_Leaves_Dry"
    },
    {
      "x": -3,
      "y": 15,
      "z": -5,
      "name": "Plant_Leaves_Dry"
    },
    {
      "x": -3,
      "y": 15,
      "z": -3,
      "name": "Plant_Leaves_Dry"
    },
    {
      "x": -3,
      "y": 16,
      "z": -2,
      "name": "Plant_Leaves_Dry"
    },
    {
      "x": -3,
      "y": 6,
      "z": -1,
      "name": "Wood_Dry_Trunk_Full"
    },
    {
      "x": -3,
      "y": 7,
      "z": -1,
      "name": "Wood_Dry_Trunk"
    },
    {
      "x": -3,
      "y": 8,
      "z": -1,
      "name": "Wood_Dry_Trunk"
    },
    {
      "x": -3,
      "y": 9,
      "z": -1,
      "name": "Wood_Dry_Trunk_Full"
    },
    {
      "x": -3,
      "y": 15,
      "z": -1,
      "name": "Wood_Dry_Trunk_Full"
    },
    {
      "x": -3,
      "y": 16,
      "z": -1,
      "name": "Plant_Leaves_Dry"
    },
    {
      "x": -3,
      "y": 9,
      "z": 0,
      "name": "Wood_Dry_Trunk_Full"
    },
    {
      "x": -3,
      "y": 10,
      "z": 0,
      "name": "Wood_Dry_Trunk_Full"
    },
    {
      "x": -3,
      "y": 13,
      "z": 0,
      "name": "Wood_Dry_Trunk_Full"
    },
    {
      "x": -3,
      "y": 14,
      "z": 0,
      "name": "Wood_Dry_Trunk"
    },
    {
      "x": -3,
      "y": 15,
      "z": 0,
      "name": "Wood_Dry_Trunk_Full"
    },
    {
      "x": -3,
      "y": 16,
      "z": 0,
      "name": "Plant_Leaves_Dry"
    },
    {
      "x": -3,
      "y": 15,
      "z": 2,
      "name": "Plant_Leaves_Dry"
    },
    {
      "x": -3,
      "y": 15,
      "z": 3,
      "name": "Plant_Leaves_Dry"
    },
    {
      "x": -3,
      "y": 17,
      "z": 3,
      "name": "Plant_Leaves_Dry"
    },
    {
      "x": -3,
      "y": 15,
      "z": 4,
      "name": "Plant_Leaves_Dry"
    },
    {
      "x": -3,
      "y": 17,
      "z": 4,
      "name": "Plant_Leaves_Dry"
    },
    {
      "x": -3,
      "y": 17,
      "z": 5,
      "name": "Plant_Leaves_Dry"
    },
    {
      "x": -2,
      "y": 15,
      "z": -5,
      "name": "Plant_Leaves_Dry"
    },
    {
      "x": -2,
      "y": 15,
      "z": -4,
      "name": "Plant_Leaves_Dry"
    },
    {
      "x": -2,
      "y": 15,
      "z": -3,
      "name": "Wood_Dry_Branch_Long",
      "rotation": 4
    },
    {
      "x": -2,
      "y": 16,
      "z": -3,
      "name": "Plant_Leaves_Dry"
    },
    {
      "x": -2,
      "y": 0,
      "z": -2,
      "name": "Wood_Dry_Trunk"
    },
    {
      "x": -2,
      "y": 1,
      "z": -2,
      "name": "Wood_Dry_Trunk"
    },
    {
      "x": -2,
      "y": 2,
      "z": -2,
      "name": "Wood_Dry_Trunk"
    },
    {
      "x": -2,
      "y": 3,
      "z": -2,
      "name": "Wood_Dry_Trunk"
    },
    {
      "x": -2,
      "y": 4,
      "z": -2,
      "name": "Wood_Dry_Trunk"
    },
    {
      "x": -2,
      "y": 5,
      "z": -2,
      "name": "Wood_Dry_Trunk"
    },
    {
      "x": -2,
      "y": 6,
      "z": -2,
      "name": "Wood_Dry_Trunk_Full"
    },
    {
      "x": -2,
      "y": 15,
      "z": -2,
      "name": "Wood_Dry_Branch_Long",
      "rotation": 4
    },
    {
      "x": -2,
      "y": 6,
      "z": -1,
      "name": "Wood_Dry_Trunk_Full"
    },
    {
      "x": -2,
      "y": 15,
      "z": -1,
      "name": "Wood_Dry_Trunk_Full"
    },
    {
      "x": -2,
      "y": 15,
      "z": 0,
      "name": "Wood_Dry_Branch_Long",
      "rotation": 4
    },
    {
      "x": -2,
      "y": 16,
      "z": 0,
      "name": "Plant_Leaves_Dry"
    },
    {
      "x": -2,
      "y": 8,
      "z": 1,
      "name": "Plant_Leaves_Dry"
    },
    {
      "x": -2,
      "y": 15,
      "z": 1,
      "name": "Wood_Dry_Branch_Long",
      "rotation": 4
    },
    {
      "x": -2,
      "y": 16,
      "z": 1,
      "name": "Plant_Leaves_Dry"
    },
    {
      "x": -2,
      "y": 8,
      "z": 2,
      "name": "Plant_Leaves_Dry"
    },
    {
      "x": -2,
      "y": 15,
      "z": 2,
      "name": "Plant_Leaves_Dry"
    },
    {
      "x": -2,
      "y": 16,
      "z": 2,
      "name": "Plant_Leaves_Dry"
    },
    {
      "x": -2,
      "y": 8,
      "z": 3,
      "name": "Plant_Leaves_Dry"
    },
    {
      "x": -2,
      "y": 15,
      "z": 3,
      "name": "Plant_Leaves_Dry"
    },
    {
      "x": -2,
      "y": 8,
      "z": 4,
      "name": "Plant_Leaves_Dry"
    },
    {
      "x": -2,
      "y": 15,
      "z": 4,
      "name": "Plant_Leaves_Dry"
    },
    {
      "x": -1,
      "y": 15,
      "z": -6,
      "name": "Plant_Leaves_Dry"
    },
    {
      "x": -1,
      "y": 15,
      "z": -5,
      "name": "Plant_Leaves_Dry"
    },
    {
      "x": -1,
      "y": 15,
      "z": -4,
      "name": "Plant_Leaves_Dry"
    },
    {
      "x": -1,
      "y": 0,
      "z": -3,
      "name": "Wood_Dry_Trunk"
    },
    {
      "x": -1,
      "y": 1,
      "z": -3,
      "name": "Wood_Dry_Trunk_Full"
    },
    {
      "x": -1,
      "y": 16,
      "z": -3,
      "name": "Plant_Leaves_Dry"
    },
    {
      "x": -1,
      "y": 0,
      "z": -2,
      "name": "Wood_Dry_Trunk"
    },
    {
      "x": -1,
      "y": 1,
      "z": -2,
      "name": "Wood_Dry_Trunk"
    },
    {
      "x": -1,
      "y": 2,
      "z": -2,
      "name": "Wood_Dry_Trunk"
    },
    {
      "x": -1,
      "y": 3,
      "z": -2,
      "name": "Wood_Dry_Trunk"
    },
    {
      "x": -1,
      "y": 4,
      "z": -2,
      "name": "Wood_Dry_Trunk_Full"
    },
    {
      "x": -1,
      "y": 16,
      "z": -2,
      "name": "Plant_Leaves_Dry"
    },
    {
      "x": -1,
      "y": 15,
      "z": -1,
      "name": "Wood_Dry_Branch_Long",
      "rotation": 5
    },
    {
      "x": -1,
      "y": 16,
      "z": -1,
      "name": "Plant_Leaves_Dry"
    },
    {
      "x": -1,
      "y": 8,
      "z": 0,
      "name": "Plant_Leaves_Dry"
    },
    {
      "x": -1,
      "y": 16,
      "z": 0,
      "name": "Plant_Leaves_Dry"
    },
    {
      "x": -1,
      "y": 8,
      "z": 1,
      "name": "Plant_Leaves_Dry"
    },
    {
      "x": -1,
      "y": 16,
      "z": 1,
      "name": "Plant_Leaves_Dry"
    },
    {
      "x": -1,
      "y": 8,
      "z": 2,
      "name": "Plant_Leaves_Dry"
    },
    {
      "x": -1,
      "y": 15,
      "z": 2,
      "name": "Plant_Leaves_Dry"
    },
    {
      "x": -1,
      "y": 8,
      "z": 3,
      "name": "Plant_Leaves_Dry"
    },
    {
      "x": -1,
      "y": 15,
      "z": 3,
      "name": "Plant_Leaves_Dry"
    },
    {
      "x": -1,
      "y": 8,
      "z": 4,
      "name": "Plant_Leaves_Dry"
    },
    {
      "x": -1,
      "y": 15,
      "z": 4,
      "name": "Plant_Leaves_Dry"
    },
    {
      "x": -1,
      "y": 8,
      "z": 5,
      "name": "Plant_Leaves_Dry"
    },
    {
      "x": -1,
      "y": 8,
      "z": 6,
      "name": "Plant_Leaves_Dry"
    },
    {
      "x": 0,
      "y": 15,
      "z": -5,
      "name": "Plant_Leaves_Dry"
    },
    {
      "x": 0,
      "y": 15,
      "z": -4,
      "name": "Plant_Leaves_Dry"
    },
    {
      "x": 0,
      "y": 15,
      "z": -3,
      "name": "Plant_Leaves_Dry"
    },
    {
      "x": 0,
      "y": 4,
      "z": -2,
      "name": "Wood_Dry_Trunk_Full"
    },
    {
      "x": 0,
      "y": 5,
      "z": -2,
      "name": "Wood_Dry_Trunk_Full"
    },
    {
      "x": 0,
      "y": 15,
      "z": -2,
      "name": "Plant_Leaves_Dry"
    },
    {
      "x": 0,
      "y": 8,
      "z": -1,
      "name": "Plant_Leaves_Dry"
    },
    {
      "x": 0,
      "y": 15,
      "z": -1,
      "name": "Wood_Dry_Branch_Long",
      "rotation": 5
    },
    {
      "x": 0,
      "y": 16,
      "z": -1,
      "name": "Plant_Leaves_Dry"
    },
    {
      "x": 0,
      "y": 8,
      "z": 0,
      "name": "Plant_Leaves_Dry"
    },
    {
      "x": 0,
      "y": 16,
      "z": 0,
      "name": "Plant_Leaves_Dry"
    },
    {
      "x": 0,
      "y": 8,
      "z": 1,
      "name": "Plant_Leaves_Dry"
    },
    {
      "x": 0,
      "y": 15,
      "z": 1,
      "name": "Plant_Leaves_Dry"
    },
    {
      "x": 0,
      "y": 8,
      "z": 2,
      "name": "Wood_Dry_Branch_Long",
      "rotation": 5
    },
    {
      "x": 0,
      "y": 15,
      "z": 2,
      "name": "Plant_Leaves_Dry"
    },
    {
      "x": 0,
      "y": 8,
      "z": 3,
      "name": "Plant_Leaves_Dry"
    },
    {
      "x": 0,
      "y": 9,
      "z": 3,
      "name": "Plant_Leaves_Dry"
    },
    {
      "x": 0,
      "y": 15,
      "z": 3,
      "name": "Plant_Leaves_Dry"
    },
    {
      "x": 0,
      "y": 8,
      "z": 4,
      "name": "Plant_Leaves_Dry"
    },
    {
      "x": 0,
      "y": 15,
      "z": 4,
      "name": "Plant_Leaves_Dry"
    },
    {
      "x": 0,
      "y": 8,
      "z": 5,
      "name": "Plant_Leaves_Dry"
    },
    {
      "x": 0,
      "y": 8,
      "z": 6,
      "name": "Plant_Leaves_Dry"
    },
    {
      "x": 1,
      "y": 15,
      "z": -5,
      "name": "Plant_Leaves_Dry"
    },
    {
      "x": 1,
      "y": 15,
      "z": -4,
      "name": "Plant_Leaves_Dry"
    },
    {
      "x": 1,
      "y": 15,
      "z": -3,
      "name": "Plant_Leaves_Dry"
    },
    {
      "x": 1,
      "y": 5,
      "z": -2,
      "name": "Wood_Dry_Trunk_Full"
    },
    {
      "x": 1,
      "y": 15,
      "z": -2,
      "name": "Plant_Leaves_Dry"
    },
    {
      "x": 1,
      "y": 5,
      "z": -1,
      "name": "Wood_Dry_Trunk_Full"
    },
    {
      "x": 1,
      "y": 6,
      "z": -1,
      "name": "Wood_Dry_Trunk_Full"
    },
    {
      "x": 1,
      "y": 15,
      "z": -1,
      "name": "Plant_Leaves_Dry"
    },
    {
      "x": 1,
      "y": 6,
      "z": 0,
      "name": "Wood_Dry_Trunk_Full"
    },
    {
      "x": 1,
      "y": 15,
      "z": 0,
      "name": "Plant_Leaves_Dry"
    },
    {
      "x": 1,
      "y": 16,
      "z": 0,
      "name": "Plant_Leaves_Dry"
    },
    {
      "x": 1,
      "y": 9,
      "z": 1,
      "name": "Plant_Leaves_Dry"
    },
    {
      "x": 1,
      "y": 15,
      "z": 1,
      "name": "Plant_Leaves_Dry"
    },
    {
      "x": 1,
      "y": 8,
      "z": 2,
      "name": "Wood_Dry_Branch_Long",
      "rotation": 5
    },
    {
      "x": 1,
      "y": 9,
      "z": 2,
      "name": "Plant_Leaves_Dry"
    },
    {
      "x": 1,
      "y": 15,
      "z": 2,
      "name": "Plant_Leaves_Dry"
    },
    {
      "x": 1,
      "y": 9,
      "z": 3,
      "name": "Plant_Leaves_Dry"
    },
    {
      "x": 1,
      "y": 15,
      "z": 3,
      "name": "Plant_Leaves_Dry"
    },
    {
      "x": 1,
      "y": 8,
      "z": 5,
      "name": "Plant_Leaves_Dry"
    },
    {
      "x": 1,
      "y": 8,
      "z": 6,
      "name": "Plant_Leaves_Dry"
    },
    {
      "x": 1,
      "y": 8,
      "z": 7,
      "name": "Plant_Leaves_Dry"
    },
    {
      "x": 2,
      "y": 15,
      "z": -3,
      "name": "Plant_Leaves_Dry"
    },
    {
      "x": 2,
      "y": 15,
      "z": -2,
      "name": "Plant_Leaves_Dry"
    },
    {
      "x": 2,
      "y": 15,
      "z": -1,
      "name": "Plant_Leaves_Dry"
    },
    {
      "x": 2,
      "y": 6,
      "z": 0,
      "name": "Wood_Dry_Trunk_Full"
    },
    {
      "x": 2,
      "y": 7,
      "z": 0,
      "name": "Wood_Dry_Trunk_Full"
    },
    {
      "x": 2,
      "y": 15,
      "z": 0,
      "name": "Plant_Leaves_Dry"
    },
    {
      "x": 2,
      "y": 7,
      "z": 1,
      "name": "Wood_Dry_Trunk_Full"
    },
    {
      "x": 2,
      "y": 9,
      "z": 1,
      "name": "Plant_Leaves_Dry"
    },
    {
      "x": 2,
      "y": 15,
      "z": 1,
      "name": "Plant_Leaves_Dry"
    },
    {
      "x": 2,
      "y": 7,
      "z": 2,
      "name": "Wood_Dry_Trunk_Full"
    },
    {
      "x": 2,
      "y": 8,
      "z": 2,
      "name": "Wood_Dry_Trunk_Full"
    },
    {
      "x": 2,
      "y": 9,
      "z": 2,
      "name": "Plant_Leaves_Dry"
    },
    {
      "x": 2,
      "y": 8,
      "z": 3,
      "name": "Wood_Dry_Branch_Long",
      "rotation": 4
    },
    {
      "x": 2,
      "y": 9,
      "z": 3,
      "name": "Plant_Leaves_Dry"
    },
    {
      "x": 2,
      "y": 8,
      "z": 4,
      "name": "Wood_Dry_Branch_Long",
      "rotation": 4
    },
    {
      "x": 2,
      "y": 9,
      "z": 4,
      "name": "Plant_Leaves_Dry"
    },
    {
      "x": 2,
      "y": 8,
      "z": 5,
      "name": "Plant_Leaves_Dry"
    },
    {
      "x": 2,
      "y": 8,
      "z": 6,
      "name": "Plant_Leaves_Dry"
    },
    {
      "x": 2,
      "y": 8,
      "z": 7,
      "name": "Plant_Leaves_Dry"
    },
    {
      "x": 3,
      "y": 15,
      "z": -1,
      "name": "Plant_Leaves_Dry"
    },
    {
      "x": 3,
      "y": 8,
      "z": 2,
      "name": "Wood_Dry_Branch_Long",
      "rotation": 5
    },
    {
      "x": 3,
      "y": 9,
      "z": 2,
      "name": "Plant_Leaves_Dry"
    },
    {
      "x": 3,
      "y": 9,
      "z": 3,
      "name": "Plant_Leaves_Dry"
    },
    {
      "x": 3,
      "y": 9,
      "z": 4,
      "name": "Plant_Leaves_Dry"
    },
    {
      "x": 3,
      "y": 8,
      "z": 5,
      "name": "Plant_Leaves_Dry"
    },
    {
      "x": 3,
      "y": 9,
      "z": 5,
      "name": "Plant_Leaves_Dry"
    },
    {
      "x": 3,
      "y": 8,
      "z": 6,
      "name": "Plant_Leaves_Dry"
    },
    {
      "x": 3,
      "y": 8,
      "z": 7,
      "name": "Plant_Leaves_Dry"
    },
    {
      "x": 4,
      "y": 8,
      "z": -1,
      "name": "Plant_Leaves_Dry"
    },
    {
      "x": 4,
      "y": 9,
      "z": 1,
      "name": "Plant_Leaves_Dry"
    },
    {
      "x": 4,
      "y": 8,
      "z": 2,
      "name": "Wood_Dry_Branch_Long",
      "rotation": 5
    },
    {
      "x": 4,
      "y": 9,
      "z": 2,
      "name": "Plant_Leaves_Dry"
    },
    {
      "x": 4,
      "y": 9,
      "z": 3,
      "name": "Plant_Leaves_Dry"
    },
    {
      "x": 4,
      "y": 9,
      "z": 4,
      "name": "Plant_Leaves_Dry"
    },
    {
      "x": 4,
      "y": 8,
      "z": 5,
      "name": "Plant_Leaves_Dry"
    },
    {
      "x": 4,
      "y": 8,
      "z": 6,
      "name": "Plant_Leaves_Dry"
    },
    {
      "x": 5,
      "y": 8,
      "z": -1,
      "name": "Plant_Leaves_Dry"
    },
    {
      "x": 5,
      "y": 8,
      "z": 0,
      "name": "Plant_Leaves_Dry"
    },
    {
      "x": 5,
      "y": 8,
      "z": 1,
      "name": "Plant_Leaves_Dry"
    },
    {
      "x": 5,
      "y": 8,
      "z": 2,
      "name": "Plant_Leaves_Dry"
    },
    {
      "x": 5,
      "y": 8,
      "z": 3,
      "name": "Plant_Leaves_Dry"
    },
    {
      "x": 5,
      "y": 8,
      "z": 4,
      "name": "Plant_Leaves_Dry"
    },
    {
      "x": 5,
      "y": 8,
      "z": 5,
      "name": "Plant_Leaves_Dry"
    },
    {
      "x": 5,
      "y": 8,
      "z": 6,
      "name": "Plant_Leaves_Dry"
    },
    {
      "x": 6,
      "y": 8,
      "z": 0,
      "name": "Plant_Leaves_Dry"
    },
    {
      "x": 6,
      "y": 8,
      "z": 1,
      "name": "Plant_Leaves_Dry"
    },
    {
      "x": 6,
      "y": 8,
      "z": 2,
      "name": "Plant_Leaves_Dry"
    },
    {
      "x": 6,
      "y": 8,
      "z": 3,
      "name": "Plant_Leaves_Dry"
    },
    {
      "x": 6,
      "y": 8,
      "z": 4,
      "name": "Plant_Leaves_Dry"
    },
    {
      "x": 6,
      "y": 8,
      "z": 5,
      "name": "Plant_Leaves_Dry"
    },
    {
      "x": 7,
      "y": 8,
      "z": 2,
      "name": "Plant_Leaves_Dry"
    },
    {
      "x": 7,
      "y": 8,
      "z": 3,
      "name": "Plant_Leaves_Dry"
    }
  ]
}