{
  "version": 8,
  "blockIdVersion": 8,
  "anchorX": 0,
  "anchorY": -51,
  "anchorZ": 0,
  "blocks": [
    {
      "x": -7,
      "y": -1,
      "z": -1,
      "name": "Rock_Stone"
    },
    {
      "x": -7,
      "y": 0,
      "z": -1,
      "name": "Rock_Stone"
    },
    {
      "x": -7,
      "y": 1,
      "z": -1,
      "name": "Rock_Stone"
    },
    {
      "x": -7,
      "y": 0,
      "z": 0,
      "name": "Rock_Stone"
    },
    {
      "x": -7,
      "y": 1,
      "z": 0,
      "name": "Rock_Stone"
    },
    {
      "x": -6,
      "y": -2,
      "z": -2,
      "name": "Rock_Basalt"
    },
    {
      "x": -6,
      "y": -1,
      "z": -2,
      "name": "Rock_Stone"
    },
    {
      "x": -6,
      "y": 0,
      "z": -2,
      "name": "Rock_Stone"
    },
    {
      "x": -6,
      "y": 1,
      "z": -2,
      "name": "Rock_Stone"
    },
    {
      "x": -6,
      "y": 2,
      "z": -2,
      "name": "Rock_Stone"
    },
    {
      "x": -6,
      "y": -2,
      "z": -1,
      "name": "Rock_Basalt"
    },
    {
      "x": -6,
      "y": -1,
      "z": -1,
      "name": "Rock_Stone"
    },
    {
      "x": -6,
      "y": 0,
      "z": -1,
      "name": "Rock_Stone"
    },
    {
      "x": -6,
      "y": 1,
      "z": -1,
      "name": "Rock_Stone"
    },
    {
      "x": -6,
      "y": 2,
      "z": -1,
      "name": "Rock_Stone"
    },
    {
      "x": -6,
      "y": -2,
      "z": 0,
      "name": "Rock_Basalt"
    },
    {
      "x": -6,
      "y": -1,
      "z": 0,
      "name": "Rock_Stone"
    },
    {
      "x": -6,
      "y": 0,
      "z": 0,
      "name": "Rock_Stone"
    },
    {
      "x": -6,
      "y": 1,
      "z": 0,
      "name": "Rock_Stone"
    },
    {
      "x": -6,
      "y": 2,
      "z": 0,
      "name": "Rock_Stone"
    },
    {
      "x": -6,
      "y": -1,
      "z": 1,
      "name": "Rock_Stone"
    },
    {
      "x": -6,
      "y": 0,
      "z": 1,
      "name": "Rock_Stone"
    },
    {
      "x": -6,
      "y": 1,
      "z": 1,
      "name": "Rock_Stone"
    },
    {
      "x": -6,
      "y": -1,
      "z": 2,
      "name": "Rock_Stone"
    },
    {
      "x": -6,
      "y": 0,
      "z": 2,
      "name": "Rock_Stone"
    },
    {
      "x": -5,
      "y": -1,
      "z": -4,
      "name": "Rock_Stone"
    },
    {
      "x": -5,
      "y": -3,
      "z": -3,
      "name": "Rock_Basalt"
    },
    {
      "x": -5,
      "y": -2,
      "z": -3,
      "name": "Rock_Basalt"
    },
    {
      "x": -5,
      "y": -1,
      "z": -3,
      "name": "Rock_Stone"
    },
    {
      "x": -5,
      "y": 0,
      "z": -3,
      "name": "Rock_Stone"
    },
    {
      "x": -5,
      "y": 1,
      "z": -3,
      "name": "Rock_Stone"
    },
    {
      "x": -5,
      "y": 2,
      "z": -3,
      "name": "Rock_Stone"
    },
    {
      "x": -5,
      "y": -3,
      "z": -2,
      "name": "Rock_Basalt"
    },
    {
      "x": -5,
      "y": -2,
      "z": -2,
      "name": "Rock_Basalt"
    },
    {
      "x": -5,
      "y": -1,
      "z": -2,
      "name": "Rock_Stone"
    },
    {
      "x": -5,
      "y": 0,
      "z": -2,
      "name": "Rock_Stone"
    },
    {
      "x": -5,
      "y": 1,
      "z": -2,
      "name": "Rock_Stone"
    },
    {
      "x": -5,
      "y": 2,
      "z": -2,
      "name": "Rock_Stone"
    },
    {
      "x": -5,
      "y": -3,
      "z": -1,
      "name": "Rock_Basalt"
    },
    {
      "x": -5,
      "y": -2,
      "z": -1,
      "name": "Rock_Basalt"
    },
    {
      "x": -5,
      "y": -1,
      "z": -1,
      "name": "Rock_Stone"
    },
    {
      "x": -5,
      "y": 0,
      "z": -1,
      "name": "Rock_Stone"
    },
    {
      "x": -5,
      "y": 1,
      "z": -1,
      "name": "Rock_Stone"
    },
    {
      "x": -5,
      "y": 2,
      "z": -1,
      "name": "Rock_Stone"
    },
    {
      "x": -5,
      "y": -3,
      "z": 0,
      "name": "Rock_Basalt"
    },
    {
      "x": -5,
      "y": -2,
      "z": 0,
      "name": "Rock_Basalt"
    },
    {
      "x": -5,
      "y": -1,
      "z": 0,
      "name": "Rock_Stone"
    },
    {
      "x": -5,
      "y": 0,
      "z": 0,
      "name": "Rock_Stone"
    },
    {
      "x": -5,
      "y": 1,
      "z": 0,
      "name": "Rock_Stone"
    },
    {
      "x": -5,
      "y": 2,
      "z": 0,
      "name": "Rock_Stone"
    },
    {
      "x": -5,
      "y": -3,
      "z": 1,
      "name": "Rock_Basalt"
    },
    {
      "x": -5,
      "y": -2,
      "z": 1,
      "name": "Rock_Basalt"
    },
    {
      "x": -5,
      "y": -1,
      "z": 1,
      "name": "Rock_Stone"
    },
    {
      "x": -5,
      "y": 0,
      "z": 1,
      "name": "Rock_Stone"
    },
    {
      "x": -5,
      "y": 1,
      "z": 1,
      "name": "Rock_Stone"
    },
    {
      "x": -5,
      "y": 2,
      "z": 1,
      "name": "Rock_Stone"
    },
    {
      "x": -5,
      "y": -3,
      "z": 2,
      "name": "Rock_Basalt"
    },
    {
      "x": -5,
      "y": -2,
      "z": 2,
      "name": "Rock_Basalt"
    },
    {
      "x": -5,
      "y": -1,
      "z": 2,
      "name": "Rock_Stone"
    },
    {
      "x": -5,
      "y": 0,
      "z": 2,
      "name": "Rock_Stone"
    },
    {
      "x": -5,
      "y": 1,
      "z": 2,
      "name": "Rock_Stone"
    },
    {
      "x": -5,
      "y": 2,
      "z": 2,
      "name": "Rock_Stone"
    },
    {
      "x": -5,
      "y": -2,
      "z": 3,
      "name": "Rock_Stone"
    },
    {
      "x": -5,
      "y": -1,
      "z": 3,
      "name": "Rock_Stone"
    },
    {
      "x": -5,
      "y": 0,
      "z": 3,
      "name": "Rock_Stone"
    },
    {
      "x": -5,
      "y": 1,
      "z": 3,
      "name": "Rock_Stone"
    },
    {
      "x": -5,
      "y": -1,
      "z": 4,
      "name": "Rock_Stone"
    },
    {
      "x": -4,
      "y": -1,
      "z": -5,
      "name": "Rock_Stone"
    },
    {
      "x": -4,
      "y": 0,
      "z": -5,
      "name": "Rock_Stone"
    },
    {
      "x": -4,
      "y": -3,
      "z": -4,
      "name": "Rock_Basalt"
    },
    {
      "x": -4,
      "y": -2,
      "z": -4,
      "name": "Rock_Basalt"
    },
    {
      "x": -4,
      "y": -1,
      "z": -4,
      "name": "Rock_Stone"
    },
    {
      "x": -4,
      "y": 0,
      "z": -4,
      "name": "Rock_Stone"
    },
    {
      "x": -4,
      "y": 1,
      "z": -4,
      "name": "Rock_Stone"
    },
    {
      "x": -4,
      "y": 2,
      "z": -4,
      "name": "Rock_Stone"
    },
    {
      "x": -4,
      "y": -3,
      "z": -3,
      "name": "Rock_Basalt"
    },
    {
      "x": -4,
      "y": -2,
      "z": -3,
      "name": "Rock_Basalt"
    },
    {
      "x": -4,
      "y": -1,
      "z": -3,
      "name": "Rock_Stone"
    },
    {
      "x": -4,
      "y": 0,
      "z": -3,
      "name": "Rock_Stone"
    },
    {
      "x": -4,
      "y": 1,
      "z": -3,
      "name": "Rock_Stone"
    },
    {
      "x": -4,
      "y": 2,
      "z": -3,
      "name": "Rock_Stone"
    },
    {
      "x": -4,
      "y": -3,
      "z": -2,
      "name": "Rock_Basalt"
    },
    {
      "x": -4,
      "y": -2,
      "z": -2,
      "name": "Rock_Basalt"
    },
    {
      "x": -4,
      "y": -1,
      "z": -2,
      "name": "Rock_Stone"
    },
    {
      "x": -4,
      "y": 0,
      "z": -2,
      "name": "Rock_Stone"
    },
    {
      "x": -4,
      "y": 1,
      "z": -2,
      "name": "Rock_Stone"
    },
    {
      "x": -4,
      "y": 2,
      "z": -2,
      "name": "Rock_Stone"
    },
    {
      "x": -4,
      "y": -3,
      "z": -1,
      "name": "Rock_Basalt"
    },
    {
      "x": -4,
      "y": -2,
      "z": -1,
      "name": "Rock_Basalt"
    },
    {
      "x": -4,
      "y": -1,
      "z": -1,
      "name": "Rock_Basalt"
    },
    {
      "x": -4,
      "y": 0,
      "z": -1,
      "name": "Rock_Stone"
    },
    {
      "x": -4,
      "y": 1,
      "z": -1,
      "name": "Rock_Stone"
    },
    {
      "x": -4,
      "y": 2,
      "z": -1,
      "name": "Rock_Stone"
    },
    {
      "x": -4,
      "y": 3,
      "z": -1,
      "name": "Rock_Stone"
    },
    {
      "x": -4,
      "y": -3,
      "z": 0,
      "name": "Rock_Basalt"
    },
    {
      "x": -4,
      "y": -2,
      "z": 0,
      "name": "Rock_Basalt"
    },
    {
      "x": -4,
      "y": -1,
      "z": 0,
      "name": "Rock_Basalt"
    },
    {
      "x": -4,
      "y": 0,
      "z": 0,
      "name": "Rock_Stone"
    },
    {
      "x": -4,
      "y": 1,
      "z": 0,
      "name": "Rock_Stone"
    },
    {
      "x": -4,
      "y": 2,
      "z": 0,
      "name": "Rock_Stone"
    },
    {
      "x": -4,
      "y": 3,
      "z": 0,
      "name": "Rock_Stone"
    },
    {
      "x": -4,
      "y": -2,
      "z": 1,
      "name": "Rock_Basalt"
    },
    {
      "x": -4,
      "y": -1,
      "z": 1,
      "name": "Rock_Stone"
    },
    {
      "x": -4,
      "y": 0,
      "z": 1,
      "name": "Rock_Stone"
    },
    {
      "x": -4,
      "y": 1,
      "z": 1,
      "name": "Rock_Stone"
    },
    {
      "x": -4,
      "y": 2,
      "z": 1,
      "name": "Rock_Stone"
    },
    {
      "x": -4,
      "y": -2,
      "z": 2,
      "name": "Rock_Basalt"
    },
    {
      "x": -4,
      "y": -1,
      "z": 2,
      "name": "Rock_Stone"
    },
    {
      "x": -4,
      "y": 0,
      "z": 2,
      "name": "Rock_Stone"
    },
    {
      "x": -4,
      "y": 1,
      "z": 2,
      "name": "Rock_Stone"
    },
    {
      "x": -4,
      "y": 2,
      "z": 2,
      "name": "Rock_Stone"
    },
    {
      "x": -4,
      "y": -2,
      "z": 3,
      "name": "Rock_Stone"
    },
    {
      "x": -4,
      "y": -1,
      "z": 3,
      "name": "Rock_Stone"
    },
    {
      "x": -4,
      "y": 0,
      "z": 3,
      "name": "Rock_Stone"
    },
    {
      "x": -4,
      "y": 1,
      "z": 3,
      "name": "Rock_Stone"
    },
    {
      "x": -4,
      "y": -1,
      "z": 4,
      "name": "Rock_Stone"
    },
    {
      "x": -4,
      "y": 0,
      "z": 4,
      "name": "Rock_Stone"
    },
    {
      "x": -4,
      "y": 1,
      "z": 4,
      "name": "Rock_Stone"
    },
    {
      "x": -3,
      "y": -1,
      "z": -6,
      "name": "Rock_Stone"
    },
    {
      "x": -3,
      "y": 0,
      "z": -6,
      "name": "Rock_Stone"
    },
    {
      "x": -3,
      "y": -2,
      "z": -5,
      "name": "Rock_Basalt"
    },
    {
      "x": -3,
      "y": -1,
      "z": -5,
      "name": "Rock_Stone"
    },
    {
      "x": -3,
      "y": 0,
      "z": -5,
      "name": "Rock_Stone"
    },
    {
      "x": -3,
      "y": 1,
      "z": -5,
      "name": "Rock_Stone"
    },
    {
      "x": -3,
      "y": 2,
      "z": -5,
      "name": "Rock_Stone"
    },
    {
      "x": -3,
      "y": -4,
      "z": -4,
      "name": "Rock_Basalt"
    },
    {
      "x": -3,
      "y": -3,
      "z": -4,
      "name": "Rock_Basalt"
    },
    {
      "x": -3,
      "y": -2,
      "z": -4,
      "name": "Rock_Basalt"
    },
    {
      "x": -3,
      "y": -1,
      "z": -4,
      "name": "Rock_Basalt"
    },
    {
      "x": -3,
      "y": 0,
      "z": -4,
      "name": "Rock_Stone"
    },
    {
      "x": -3,
      "y": 1,
      "z": -4,
      "name": "Rock_Stone"
    },
    {
      "x": -3,
      "y": 2,
      "z": -4,
      "name": "Rock_Stone"
    },
    {
      "x": -3,
      "y": 3,
      "z": -4,
      "name": "Rock_Stone"
    },
    {
      "x": -3,
      "y": -3,
      "z": -3,
      "name": "Rock_Basalt"
    },
    {
      "x": -3,
      "y": -2,
      "z": -3,
      "name": "Rock_Basalt"
    },
    {
      "x": -3,
      "y": -1,
      "z": -3,
      "name": "Rock_Basalt"
    },
    {
      "x": -3,
      "y": 0,
      "z": -3,
      "name": "Rock_Stone"
    },
    {
      "x": -3,
      "y": 1,
      "z": -3,
      "name": "Rock_Stone"
    },
    {
      "x": -3,
      "y": 2,
      "z": -3,
      "name": "Rock_Stone"
    },
    {
      "x": -3,
      "y": 3,
      "z": -3,
      "name": "Rock_Stone"
    },
    {
      "x": -3,
      "y": -3,
      "z": -2,
      "name": "Rock_Basalt"
    },
    {
      "x": -3,
      "y": -2,
      "z": -2,
      "name": "Rock_Basalt"
    },
    {
      "x": -3,
      "y": -1,
      "z": -2,
      "name": "Rock_Basalt"
    },
    {
      "x": -3,
      "y": 0,
      "z": -2,
      "name": "Rock_Stone"
    },
    {
      "x": -3,
      "y": 1,
      "z": -2,
      "name": "Rock_Stone"
    },
    {
      "x": -3,
      "y": 2,
      "z": -2,
      "name": "Rock_Stone"
    },
    {
      "x": -3,
      "y": 3,
      "z": -2,
      "name": "Rock_Stone"
    },
    {
      "x": -3,
      "y": -3,
      "z": -1,
      "name": "Rock_Basalt"
    },
    {
      "x": -3,
      "y": -2,
      "z": -1,
      "name": "Rock_Basalt"
    },
    {
      "x": -3,
      "y": -1,
      "z": -1,
      "name": "Rock_Basalt"
    },
    {
      "x": -3,
      "y": 0,
      "z": -1,
      "name": "Rock_Stone"
    },
    {
      "x": -3,
      "y": 1,
      "z": -1,
      "name": "Rock_Stone"
    },
    {
      "x": -3,
      "y": 2,
      "z": -1,
      "name": "Rock_Stone"
    },
    {
      "x": -3,
      "y": 3,
      "z": -1,
      "name": "Rock_Stone"
    },
    {
      "x": -3,
      "y": -3,
      "z": 0,
      "name": "Rock_Basalt"
    },
    {
      "x": -3,
      "y": -2,
      "z": 0,
      "name": "Rock_Basalt"
    },
    {
      "x": -3,
      "y": -1,
      "z": 0,
      "name": "Rock_Basalt"
    },
    {
      "x": -3,
      "y": 0,
      "z": 0,
      "name": "Rock_Stone"
    },
    {
      "x": -3,
      "y": 1,
      "z": 0,
      "name": "Rock_Stone"
    },
    {
      "x": -3,
      "y": 2,
      "z": 0,
      "name": "Rock_Stone"
    },
    {
      "x": -3,
      "y": 3,
      "z": 0,
      "name": "Rock_Stone"
    },
    {
      "x": -3,
      "y": -3,
      "z": 1,
      "name": "Rock_Basalt"
    },
    {
      "x": -3,
      "y": -2,
      "z": 1,
      "name": "Rock_Basalt"
    },
    {
      "x": -3,
      "y": -1,
      "z": 1,
      "name": "Rock_Stone"
    },
    {
      "x": -3,
      "y": 0,
      "z": 1,
      "name": "Rock_Stone"
    },
    {
      "x": -3,
      "y": 1,
      "z": 1,
      "name": "Rock_Stone"
    },
    {
      "x": -3,
      "y": 2,
      "z": 1,
      "name": "Rock_Stone"
    },
    {
      "x": -3,
      "y": -3,
      "z": 2,
      "name": "Rock_Basalt"
    },
    {
      "x": -3,
      "y": -2,
      "z": 2,
      "name": "Rock_Basalt"
    },
    {
      "x": -3,
      "y": -1,
      "z": 2,
      "name": "Rock_Stone"
    },
    {
      "x": -3,
      "y": 0,
      "z": 2,
      "name": "Rock_Stone"
    },
    {
      "x": -3,
      "y": 1,
      "z": 2,
      "name": "Rock_Stone"
    },
    {
      "x": -3,
      "y": 2,
      "z": 2,
      "name": "Rock_Stone"
    },
    {
      "x": -3,
      "y": -2,
      "z": 3,
      "name": "Rock_Basalt"
    },
    {
      "x": -3,
      "y": -1,
      "z": 3,
      "name": "Rock_Stone"
    },
    {
      "x": -3,
      "y": 0,
      "z": 3,
      "name": "Rock_Stone"
    },
    {
      "x": -3,
      "y": 1,
      "z": 3,
      "name": "Rock_Stone"
    },
    {
      "x": -3,
      "y": 2,
      "z": 3,
      "name": "Rock_Stone"
    },
    {
      "x": -3,
      "y": -2,
      "z": 4,
      "name": "Rock_Stone"
    },
    {
      "x": -3,
      "y": -1,
      "z": 4,
      "name": "Rock_Stone"
    },
    {
      "x": -3,
      "y": 0,
      "z": 4,
      "name": "Rock_Stone"
    },
    {
      "x": -3,
      "y": 1,
      "z": 4,
      "name": "Rock_Stone"
    },
    {
      "x": -3,
      "y": -1,
      "z": 5,
      "name": "Rock_Stone"
    },
    {
      "x": -3,
      "y": 0,
      "z": 5,
      "name": "Rock_Stone"
    },
    {
      "x": -3,
      "y": 1,
      "z": 5,
      "name": "Rock_Stone"
    },
    {
      "x": -2,
      "y": -1,
      "z": -6,
      "name": "Rock_Stone"
    },
    {
      "x": -2,
      "y": 0,
      "z": -6,
      "name": "Rock_Stone"
    },
    {
      "x": -2,
      "y": 1,
      "z": -6,
      "name": "Rock_Stone"
    },
    {
      "x": -2,
      "y": -3,
      "z": -5,
      "name": "Rock_Basalt"
    },
    {
      "x": -2,
      "y": -2,
      "z": -5,
      "name": "Rock_Basalt"
    },
    {
      "x": -2,
      "y": -1,
      "z": -5,
      "name": "Rock_Basalt"
    },
    {
      "x": -2,
      "y": 0,
      "z": -5,
      "name": "Rock_Stone"
    },
    {
      "x": -2,
      "y": 1,
      "z": -5,
      "name": "Rock_Stone"
    },
    {
      "x": -2,
      "y": 2,
      "z": -5,
      "name": "Rock_Stone"
    },
    {
      "x": -2,
      "y": 3,
      "z": -5,
      "name": "Rock_Stone"
    },
    {
      "x": -2,
      "y": -3,
      "z": -4,
      "name": "Rock_Basalt"
    },
    {
      "x": -2,
      "y": -2,
      "z": -4,
      "name": "Rock_Basalt"
    },
    {
      "x": -2,
      "y": -1,
      "z": -4,
      "name": "Rock_Basalt"
    },
    {
      "x": -2,
      "y": 0,
      "z": -4,
      "name": "Rock_Basalt"
    },
    {
      "x": -2,
      "y": 1,
      "z": -4,
      "name": "Rock_Stone"
    },
    {
      "x": -2,
      "y": 2,
      "z": -4,
      "name": "Rock_Stone"
    },
    {
      "x": -2,
      "y": 3,
      "z": -4,
      "name": "Rock_Stone"
    },
    {
      "x": -2,
      "y": 4,
      "z": -4,
      "name": "Rock_Stone"
    },
    {
      "x": -2,
      "y": -3,
      "z": -3,
      "name": "Rock_Basalt"
    },
    {
      "x": -2,
      "y": -2,
      "z": -3,
      "name": "Rock_Basalt"
    },
    {
      "x": -2,
      "y": -1,
      "z": -3,
      "name": "Rock_Basalt"
    },
    {
      "x": -2,
      "y": 0,
      "z": -3,
      "name": "Rock_Stone"
    },
    {
      "x": -2,
      "y": 1,
      "z": -3,
      "name": "Rock_Stone"
    },
    {
      "x": -2,
      "y": 2,
      "z": -3,
      "name": "Rock_Stone"
    },
    {
      "x": -2,
      "y": 3,
      "z": -3,
      "name": "Rock_Stone"
    },
    {
      "x": -2,
      "y": -4,
      "z": -2,
      "name": "Rock_Basalt"
    },
    {
      "x": -2,
      "y": -3,
      "z": -2,
      "name": "Rock_Basalt"
    },
    {
      "x": -2,
      "y": -2,
      "z": -2,
      "name": "Rock_Basalt"
    },
    {
      "x": -2,
      "y": -1,
      "z": -2,
      "name": "Rock_Basalt"
    },
    {
      "x": -2,
      "y": 0,
      "z": -2,
      "name": "Rock_Stone"
    },
    {
      "x": -2,
      "y": 1,
      "z": -2,
      "name": "Rock_Stone"
    },
    {
      "x": -2,
      "y": 2,
      "z": -2,
      "name": "Rock_Stone"
    },
    {
      "x": -2,
      "y": 3,
      "z": -2,
      "name": "Rock_Stone"
    },
    {
      "x": -2,
      "y": -4,
      "z": -1,
      "name": "Rock_Basalt"
    },
    {
      "x": -2,
      "y": -3,
      "z": -1,
      "name": "Rock_Basalt"
    },
    {
      "x": -2,
      "y": -2,
      "z": -1,
      "name": "Rock_Basalt"
    },
    {
      "x": -2,
      "y": -1,
      "z": -1,
      "name": "Rock_Basalt"
    },
    {
      "x": -2,
      "y": 0,
      "z": -1,
      "name": "Rock_Stone"
    },
    {
      "x": -2,
      "y": 1,
      "z": -1,
      "name": "Rock_Stone"
    },
    {
      "x": -2,
      "y": 2,
      "z": -1,
      "name": "Rock_Stone"
    },
    {
      "x": -2,
      "y": 3,
      "z": -1,
      "name": "Rock_Stone"
    },
    {
      "x": -2,
      "y": -3,
      "z": 0,
      "name": "Rock_Basalt"
    },
    {
      "x": -2,
      "y": -2,
      "z": 0,
      "name": "Rock_Basalt"
    },
    {
      "x": -2,
      "y": -1,
      "z": 0,
      "name": "Rock_Stone"
    },
    {
      "x": -2,
      "y": 0,
      "z": 0,
      "name": "Rock_Stone"
    },
    {
      "x": -2,
      "y": 1,
      "z": 0,
      "name": "Rock_Stone"
    },
    {
      "x": -2,
      "y": 2,
      "z": 0,
      "name": "Rock_Stone"
    },
    {
      "x": -2,
      "y": -3,
      "z": 1,
      "name": "Rock_Basalt"
    },
    {
      "x": -2,
      "y": -2,
      "z": 1,
      "name": "Rock_Basalt"
    },
    {
      "x": -2,
      "y": -1,
      "z": 1,
      "name": "Rock_Stone"
    },
    {
      "x": -2,
      "y": 0,
      "z": 1,
      "name": "Rock_Stone"
    },
    {
      "x": -2,
      "y": 1,
      "z": 1,
      "name": "Rock_Stone"
    },
    {
      "x": -2,
      "y": 2,
      "z": 1,
      "name": "Rock_Stone"
    },
    {
      "x": -2,
      "y": -4,
      "z": 2,
      "name": "Rock_Basalt"
    },
    {
      "x": -2,
      "y": -3,
      "z": 2,
      "name": "Rock_Basalt"
    },
    {
      "x": -2,
      "y": -2,
      "z": 2,
      "name": "Rock_Basalt"
    },
    {
      "x": -2,
      "y": -1,
      "z": 2,
      "name": "Rock_Stone"
    },
    {
      "x": -2,
      "y": 0,
      "z": 2,
      "name": "Rock_Stone"
    },
    {
      "x": -2,
      "y": 1,
      "z": 2,
      "name": "Rock_Stone"
    },
    {
      "x": -2,
      "y": 2,
      "z": 2,
      "name": "Rock_Stone"
    },
    {
      "x": -2,
      "y": -3,
      "z": 3,
      "name": "Rock_Basalt"
    },
    {
      "x": -2,
      "y": -2,
      "z": 3,
      "name": "Rock_Basalt"
    },
    {
      "x": -2,
      "y": -1,
      "z": 3,
      "name": "Rock_Stone"
    },
    {
      "x": -2,
      "y": 0,
      "z": 3,
      "name": "Rock_Stone"
    },
    {
      "x": -2,
      "y": 1,
      "z": 3,
      "name": "Rock_Stone"
    },
    {
      "x": -2,
      "y": 2,
      "z": 3,
      "name": "Rock_Stone"
    },
    {
      "x": -2,
      "y": -1,
      "z": 4,
      "name": "Rock_Stone"
    },
    {
      "x": -2,
      "y": 0,
      "z": 4,
      "name": "Rock_Stone"
    },
    {
      "x": -2,
      "y": 1,
      "z": 4,
      "name": "Rock_Stone"
    },
    {
      "x": -2,
      "y": 0,
      "z": 5,
      "name": "Rock_Stone"
    },
    {
      "x": -2,
      "y": 1,
      "z": 5,
      "name": "Rock_Stone"
    },
    {
      "x": -1,
      "y": -2,
      "z": -6,
      "name": "Rock_Basalt"
    },
    {
      "x": -1,
      "y": -1,
      "z": -6,
      "name": "Rock_Stone"
    },
    {
      "x": -1,
      "y": 0,
      "z": -6,
      "name": "Rock_Stone"
    },
    {
      "x": -1,
      "y": 1,
      "z": -6,
      "name": "Rock_Stone"
    },
    {
      "x": -1,
      "y": 2,
      "z": -6,
      "name": "Rock_Stone"
    },
    {
      "x": -1,
      "y": -3,
      "z": -5,
      "name": "Rock_Basalt"
    },
    {
      "x": -1,
      "y": -2,
      "z": -5,
      "name": "Rock_Basalt"
    },
    {
      "x": -1,
      "y": -1,
      "z": -5,
      "name": "Rock_Basalt"
    },
    {
      "x": -1,
      "y": 0,
      "z": -5,
      "name": "Rock_Stone"
    },
    {
      "x": -1,
      "y": 1,
      "z": -5,
      "name": "Rock_Stone"
    },
    {
      "x": -1,
      "y": 2,
      "z": -5,
      "name": "Rock_Stone"
    },
    {
      "x": -1,
      "y": 3,
      "z": -5,
      "name": "Rock_Stone"
    },
    {
      "x": -1,
      "y": -4,
      "z": -4,
      "name": "Rock_Basalt"
    },
    {
      "x": -1,
      "y": -3,
      "z": -4,
      "name": "Rock_Basalt"
    },
    {
      "x": -1,
      "y": -2,
      "z": -4,
      "name": "Rock_Basalt"
    },
    {
      "x": -1,
      "y": -1,
      "z": -4,
      "name": "Rock_Basalt"
    },
    {
      "x": -1,
      "y": 0,
      "z": -4,
      "name": "Rock_Basalt"
    },
    {
      "x": -1,
      "y": 1,
      "z": -4,
      "name": "Rock_Stone"
    },
    {
      "x": -1,
      "y": 2,
      "z": -4,
      "name": "Rock_Stone"
    },
    {
      "x": -1,
      "y": 3,
      "z": -4,
      "name": "Rock_Stone"
    },
    {
      "x": -1,
      "y": 4,
      "z": -4,
      "name": "Rock_Stone"
    },
    {
      "x": -1,
      "y": -4,
      "z": -2,
      "name": "Rock_Basalt"
    },
    {
      "x": -1,
      "y": -3,
      "z": -2,
      "name": "Rock_Basalt"
    },
    {
      "x": -1,
      "y": -2,
      "z": -2,
      "name": "Rock_Basalt"
    },
    {
      "x": -1,
      "y": -1,
      "z": -2,
      "name": "Rock_Basalt"
    },
    {
      "x": -1,
      "y": 0,
      "z": -2,
      "name": "Rock_Stone"
    },
    {
      "x": -1,
      "y": 1,
      "z": -2,
      "name": "Rock_Stone"
    },
    {
      "x": -1,
      "y": 2,
      "z": -2,
      "name": "Rock_Stone"
    },
    {
      "x": -1,
      "y": 3,
      "z": -2,
      "name": "Rock_Stone"
    },
    {
      "x": -1,
      "y": -5,
      "z": -1,
      "name": "Rock_Basalt"
    },
    {
      "x": -1,
      "y": -4,
      "z": -1,
      "name": "Rock_Basalt"
    },
    {
      "x": -1,
      "y": -3,
      "z": -1,
      "name": "Rock_Basalt"
    },
    {
      "x": -1,
      "y": -2,
      "z": -1,
      "name": "Rock_Basalt"
    },
    {
      "x": -1,
      "y": -1,
      "z": -1,
      "name": "Rock_Basalt"
    },
    {
      "x": -1,
      "y": 0,
      "z": -1,
      "name": "Rock_Stone"
    },
    {
      "x": -1,
      "y": 1,
      "z": -1,
      "name": "Rock_Stone"
    },
    {
      "x": -1,
      "y": 2,
      "z": -1,
      "name": "Rock_Stone"
    },
    {
      "x": -1,
      "y": 3,
      "z": -1,
      "name": "Rock_Stone"
    },
    {
      "x": -1,
      "y": -4,
      "z": 0,
      "name": "Rock_Basalt"
    },
    {
      "x": -1,
      "y": -3,
      "z": 0,
      "name": "Rock_Basalt"
    },
    {
      "x": -1,
      "y": -2,
      "z": 0,
      "name": "Rock_Basalt"
    },
    {
      "x": -1,
      "y": -1,
      "z": 0,
      "name": "Rock_Basalt"
    },
    {
      "x": -1,
      "y": 0,
      "z": 0,
      "name": "Rock_Stone"
    },
    {
      "x": -1,
      "y": 1,
      "z": 0,
      "name": "Rock_Stone"
    },
    {
      "x": -1,
      "y": 2,
      "z": 0,
      "name": "Rock_Stone"
    },
    {
      "x": -1,
      "y": 3,
      "z": 0,
      "name": "Rock_Stone"
    },
    {
      "x": -1,
      "y": -4,
      "z": 1,
      "name": "Rock_Basalt"
    },
    {
      "x": -1,
      "y": -3,
      "z": 1,
      "name": "Rock_Basalt"
    },
    {
      "x": -1,
      "y": -2,
      "z": 1,
      "name": "Rock_Basalt"
    },
    {
      "x": -1,
      "y": -1,
      "z": 1,
      "name": "Rock_Basalt"
    },
    {
      "x": -1,
      "y": 0,
      "z": 1,
      "name": "Rock_Stone"
    },
    {
      "x": -1,
      "y": 1,
      "z": 1,
      "name": "Rock_Stone"
    },
    {
      "x": -1,
      "y": 2,
      "z": 1,
      "name": "Rock_Stone"
    },
    {
      "x": -1,
      "y": 3,
      "z": 1,
      "name": "Rock_Stone"
    },
    {
      "x": -1,
      "y": -4,
      "z": 2,
      "name": "Rock_Basalt"
    },
    {
      "x": -1,
      "y": -3,
      "z": 2,
      "name": "Rock_Basalt"
    },
    {
      "x": -1,
      "y": -2,
      "z": 2,
      "name": "Rock_Basalt"
    },
    {
      "x": -1,
      "y": -1,
      "z": 2,
      "name": "Rock_Stone"
    },
    {
      "x": -1,
      "y": 0,
      "z": 2,
      "name": "Rock_Stone"
    },
    {
      "x": -1,
      "y": 1,
      "z": 2,
      "name": "Rock_Stone"
    },
    {
      "x": -1,
      "y": 2,
      "z": 2,
      "name": "Rock_Stone"
    },
    {
      "x": -1,
      "y": -2,
      "z": 4,
      "name": "Rock_Stone"
    },
    {
      "x": -1,
      "y": -1,
      "z": 4,
      "name": "Rock_Stone"
    },
    {
      "x": -1,
      "y": 0,
      "z": 4,
      "name": "Rock_Stone"
    },
    {
      "x": -1,
      "y": 1,
      "z": 4,
      "name": "Rock_Stone"
    },
    {
      "x": -1,
      "y": -2,
      "z": 5,
      "name": "Rock_Stone"
    },
    {
      "x": -1,
      "y": -1,
      "z": 5,
      "name": "Rock_Stone"
    },
    {
      "x": -1,
      "y": 0,
      "z": 5,
      "name": "Rock_Stone"
    },
    {
      "x": -1,
      "y": 1,
      "z": 5,
      "name": "Rock_Stone"
    },
    {
      "x": -1,
      "y": -1,
      "z": 6,
      "name": "Rock_Stone"
    },
    {
      "x": -1,
      "y": 0,
      "z": 6,
      "name": "Rock_Stone"
    },
    {
      "x": 0,
      "y": -5,
      "z": 0,
      "name": "Rock_Basalt"
    },
    {
      "x": 0,
      "y": -4,
      "z": 0,
      "name": "Rock_Basalt"
    },
    {
      "x": 0,
      "y": -3,
      "z": 0,
      "name": "Rock_Basalt"
    },
    {
      "x": 0,
      "y": -2,
      "z": 0,
      "name": "Rock_Basalt"
    },
    {
      "x": 0,
      "y": -1,
      "z": 0,
      "name": "Rock_Basalt"
    },
    {
      "x": 0,
      "y": 0,
      "z": 0,
      "name": "Rock_Stone"
    },
    {
      "x": 0,
      "y": 1,
      "z": 0,
      "name": "Rock_Stone"
    },
    {
      "x": 0,
      "y": 2,
      "z": 0,
      "name": "Rock_Stone"
    },
    {
      "x": 0,
      "y": 3,
      "z": 0,
      "name": "Rock_Stone"
    },
    {
      "x": 0,
      "y": -4,
      "z": 1,
      "name": "Rock_Basalt"
    },
    {
      "x": 0,
      "y": -3,
      "z": 1,
      "name": "Rock_Basalt"
    },
    {
      "x": 0,
      "y": -2,
      "z": 1,
      "name": "Rock_Basalt"
    },
    {
      "x": 0,
      "y": -1,
      "z": 1,
      "name": "Rock_Basalt"
    },
    {
      "x": 0,
      "y": 0,
      "z": 1,
      "name": "Rock_Stone"
    },
    {
      "x": 0,
      "y": 1,
      "z": 1,
      "name": "Rock_Stone"
    },
    {
      "x": 0,
      "y": 2,
      "z": 1,
      "name": "Rock_Stone"
    },
    {
      "x": 0,
      "y": 3,
      "z": 1,
      "name": "Rock_Stone"
    },
    {
      "x": 0,
      "y": -4,
      "z": 2,
      "name": "Rock_Basalt"
    },
    {
      "x": 0,
      "y": -3,
      "z": 2,
      "name": "Rock_Basalt"
    },
    {
      "x": 0,
      "y": -2,
      "z": 2,
      "name": "Rock_Basalt"
    },
    {
      "x": 0,
      "y": -1,
      "z": 2,
      "name": "Rock_Basalt"
    },
    {
      "x": 0,
      "y": 0,
      "z": 2,
      "name": "Rock_Stone"
    },
    {
      "x": 0,
      "y": 1,
      "z": 2,
      "name": "Rock_Stone"
    },
    {
      "x": 0,
      "y": 2,
      "z": 2,
      "name": "Rock_Stone"
    },
    {
      "x": 0,
      "y": 3,
      "z": 2,
      "name": "Rock_Stone"
    },
    {
      "x": 0,
      "y": -3,
      "z": 4,
      "name": "Rock_Basalt"
    },
    {
      "x": 0,
      "y": -2,
      "z": 4,
      "name": "Rock_Stone"
    },
    {
      "x": 0,
      "y": -1,
      "z": 4,
      "name": "Rock_Stone"
    },
    {
      "x": 0,
      "y": 0,
      "z": 4,
      "name": "Rock_Stone"
    },
    {
      "x": 0,
      "y": 1,
      "z": 4,
      "name": "Rock_Stone"
    },
    {
      "x": 0,
      "y": -3,
      "z": 5,
      "name": "Rock_Basalt"
    },
    {
      "x": 0,
      "y": -2,
      "z": 5,
      "name": "Rock_Stone"
    },
    {
      "x": 0,
      "y": -1,
      "z": 5,
      "name": "Rock_Stone"
    },
    {
      "x": 0,
      "y": 0,
      "z": 5,
      "name": "Rock_Stone"
    },
    {
      "x": 0,
      "y": 1,
      "z": 5,
      "name": "Rock_Stone"
    },
    {
      "x": 0,
      "y": -1,
      "z": 6,
      "name": "Rock_Stone"
    },
    {
      "x": 0,
      "y": 0,
      "z": 6,
      "name": "Rock_Stone"
    },
    {
      "x": 0,
      "y": 1,
      "z": 6,
      "name": "Rock_Stone"
    },
    {
      "x": 1,
      "y": -3,
      "z": -5,
      "name": "Rock_Basalt"
    },
    {
      "x": 1,
      "y": -2,
      "z": -5,
      "name": "Rock_Basalt"
    },
    {
      "x": 1,
      "y": -1,
      "z": -5,
      "name": "Rock_Basalt"
    },
    {
      "x": 1,
      "y": 0,
      "z": -5,
      "name": "Rock_Stone"
    },
    {
      "x": 1,
      "y": 1,
      "z": -5,
      "name": "Rock_Stone"
    },
    {
      "x": 1,
      "y": 2,
      "z": -5,
      "name": "Rock_Stone"
    },
    {
      "x": 1,
      "y": 3,
      "z": -5,
      "name": "Rock_Stone"
    },
    {
      "x": 1,
      "y": -5,
      "z": -4,
      "name": "Rock_Basalt"
    },
    {
      "x": 1,
      "y": -4,
      "z": -4,
      "name": "Rock_Basalt"
    },
    {
      "x": 1,
      "y": -3,
      "z": -4,
      "name": "Rock_Basalt"
    },
    {
      "x": 1,
      "y": -2,
      "z": -4,
      "name": "Rock_Basalt"
    },
    {
      "x": 1,
      "y": -1,
      "z": -4,
      "name": "Rock_Basalt"
    },
    {
      "x": 1,
      "y": 0,
      "z": -4,
      "name": "Rock_Basalt"
    },
    {
      "x": 1,
      "y": 1,
      "z": -4,
      "name": "Rock_Stone"
    },
    {
      "x": 1,
      "y": 2,
      "z": -4,
      "name": "Rock_Stone"
    },
    {
      "x": 1,
      "y": 3,
      "z": -4,
      "name": "Rock_Stone"
    },
    {
      "x": 1,
      "y": 4,
      "z": -4,
      "name": "Rock_Stone"
    },
    {
      "x": 1,
      "y": -5,
      "z": -3,
      "name": "Rock_Basalt"
    },
    {
      "x": 1,
      "y": -4,
      "z": -3,
      "name": "Rock_Basalt"
    },
    {
      "x": 1,
      "y": -3,
      "z": -3,
      "name": "Rock_Basalt"
    },
    {
      "x": 1,
      "y": -2,
      "z": -3,
      "name": "Rock_Basalt"
    },
    {
      "x": 1,
      "y": -1,
      "z": -3,
      "name": "Rock_Basalt"
    },
    {
      "x": 1,
      "y": 0,
      "z": -3,
      "name": "Rock_Basalt"
    },
    {
      "x": 1,
      "y": 1,
      "z": -3,
      "name": "Rock_Stone"
    },
    {
      "x": 1,
      "y": 2,
      "z": -3,
      "name": "Rock_Stone"
    },
    {
      "x": 1,
      "y": 3,
      "z": -3,
      "name": "Rock_Stone"
    },
    {
      "x": 1,
      "y": 4,
      "z": -3,
      "name": "Rock_Stone"
    },
    {
      "x": 1,
      "y": -5,
      "z": -2,
      "name": "Rock_Basalt"
    },
    {
      "x": 1,
      "y": -4,
      "z": -2,
      "name": "Rock_Basalt"
    },
    {
      "x": 1,
      "y": -3,
      "z": -2,
      "name": "Rock_Basalt"
    },
    {
      "x": 1,
      "y": -2,
      "z": -2,
      "name": "Rock_Basalt"
    },
    {
      "x": 1,
      "y": -1,
      "z": -2,
      "name": "Rock_Basalt"
    },
    {
      "x": 1,
      "y": 0,
      "z": -2,
      "name": "Rock_Stone"
    },
    {
      "x": 1,
      "y": 1,
      "z": -2,
      "name": "Rock_Stone"
    },
    {
      "x": 1,
      "y": 2,
      "z": -2,
      "name": "Rock_Stone"
    },
    {
      "x": 1,
      "y": 3,
      "z": -2,
      "name": "Rock_Stone"
    },
    {
      "x": 1,
      "y": -5,
      "z": -1,
      "name": "Rock_Basalt"
    },
    {
      "x": 1,
      "y": -4,
      "z": -1,
      "name": "Rock_Basalt"
    },
    {
      "x": 1,
      "y": -3,
      "z": -1,
      "name": "Rock_Basalt"
    },
    {
      "x": 1,
      "y": -2,
      "z": -1,
      "name": "Rock_Basalt"
    },
    {
      "x": 1,
      "y": -1,
      "z": -1,
      "name": "Rock_Basalt"
    },
    {
      "x": 1,
      "y": 0,
      "z": -1,
      "name": "Rock_Stone"
    },
    {
      "x": 1,
      "y": 1,
      "z": -1,
      "name": "Rock_Stone"
    },
    {
      "x": 1,
      "y": 2,
      "z": -1,
      "name": "Rock_Stone"
    },
    {
      "x": 1,
      "y": 3,
      "z": -1,
      "name": "Rock_Stone"
    },
    {
      "x": 1,
      "y": -5,
      "z": 0,
      "name": "Rock_Basalt"
    },
    {
      "x": 1,
      "y": -4,
      "z": 0,
      "name": "Rock_Basalt"
    },
    {
      "x": 1,
      "y": -3,
      "z": 0,
      "name": "Rock_Basalt"
    },
    {
      "x": 1,
      "y": -2,
      "z": 0,
      "name": "Rock_Basalt"
    },
    {
      "x": 1,
      "y": -1,
      "z": 0,
      "name": "Rock_Basalt"
    },
    {
      "x": 1,
      "y": 0,
      "z": 0,
      "name": "Rock_Stone"
    },
    {
      "x": 1,
      "y": 1,
      "z": 0,
      "name": "Rock_Stone"
    },
    {
      "x": 1,
      "y": 2,
      "z": 0,
      "name": "Rock_Stone"
    },
    {
      "x": 1,
      "y": 3,
      "z": 0,
      "name": "Rock_Stone"
    },
    {
      "x": 2,
      "y": -3,
      "z": -6,
      "name": "Rock_Basalt"
    },
    {
      "x": 2,
      "y": -2,
      "z": -6,
      "name": "Rock_Stone"
    },
    {
      "x": 2,
      "y": -1,
      "z": -6,
      "name": "Rock_Stone"
    },
    {
      "x": 2,
      "y": 0,
      "z": -6,
      "name": "Rock_Stone"
    },
    {
      "x": 2,
      "y": 1,
      "z": -6,
      "name": "Rock_Stone"
    },
    {
      "x": 2,
      "y": -4,
      "z": -5,
      "name": "Rock_Basalt"
    },
    {
      "x": 2,
      "y": -3,
      "z": -5,
      "name": "Rock_Basalt"
    },
    {
      "x": 2,
      "y": -2,
      "z": -5,
      "name": "Rock_Basalt"
    },
    {
      "x": 2,
      "y": -1,
      "z": -5,
      "name": "Rock_Stone"
    },
    {
      "x": 2,
      "y": 0,
      "z": -5,
      "name": "Rock_Stone"
    },
    {
      "x": 2,
      "y": 1,
      "z": -5,
      "name": "Rock_Stone"
    },
    {
      "x": 2,
      "y": 2,
      "z": -5,
      "name": "Rock_Stone"
    },
    {
      "x": 2,
      "y": -4,
      "z": -4,
      "name": "Rock_Basalt"
    },
    {
      "x": 2,
      "y": -3,
      "z": -4,
      "name": "Rock_Basalt"
    },
    {
      "x": 2,
      "y": -2,
      "z": -4,
      "name": "Rock_Basalt"
    },
    {
      "x": 2,
      "y": -1,
      "z": -4,
      "name": "Rock_Basalt"
    },
    {
      "x": 2,
      "y": 0,
      "z": -4,
      "name": "Rock_Stone"
    },
    {
      "x": 2,
      "y": 1,
      "z": -4,
      "name": "Rock_Stone"
    },
    {
      "x": 2,
      "y": 2,
      "z": -4,
      "name": "Rock_Stone"
    },
    {
      "x": 2,
      "y": 3,
      "z": -4,
      "name": "Rock_Stone"
    },
    {
      "x": 2,
      "y": -5,
      "z": -3,
      "name": "Rock_Basalt"
    },
    {
      "x": 2,
      "y": -4,
      "z": -3,
      "name": "Rock_Basalt"
    },
    {
      "x": 2,
      "y": -3,
      "z": -3,
      "name": "Rock_Basalt"
    },
    {
      "x": 2,
      "y": -2,
      "z": -3,
      "name": "Rock_Basalt"
    },
    {
      "x": 2,
      "y": -1,
      "z": -3,
      "name": "Rock_Basalt"
    },
    {
      "x": 2,
      "y": 0,
      "z": -3,
      "name": "Rock_Basalt"
    },
    {
      "x": 2,
      "y": 1,
      "z": -3,
      "name": "Rock_Stone"
    },
    {
      "x": 2,
      "y": 2,
      "z": -3,
      "name": "Rock_Stone"
    },
    {
      "x": 2,
      "y": 3,
      "z": -3,
      "name": "Rock_Stone"
    },
    {
      "x": 2,
      "y": 4,
      "z": -3,
      "name": "Rock_Stone"
    },
    {
      "x": 2,
      "y": -5,
      "z": -2,
      "name": "Rock_Basalt"
    },
    {
      "x": 2,
      "y": -4,
      "z": -2,
      "name": "Rock_Basalt"
    },
    {
      "x": 2,
      "y": -3,
      "z": -2,
      "name": "Rock_Basalt"
    },
    {
      "x": 2,
      "y": -2,
      "z": -2,
      "name": "Rock_Basalt"
    },
    {
      "x": 2,
      "y": -1,
      "z": -2,
      "name": "Rock_Basalt"
    },
    {
      "x": 2,
      "y": 0,
      "z": -2,
      "name": "Rock_Basalt"
    },
    {
      "x": 2,
      "y": 1,
      "z": -2,
      "name": "Rock_Stone"
    },
    {
      "x": 2,
      "y": 2,
      "z": -2,
      "name": "Rock_Stone"
    },
    {
      "x": 2,
      "y": 3,
      "z": -2,
      "name": "Rock_Stone"
    },
    {
      "x": 2,
      "y": 4,
      "z": -2,
      "name": "Rock_Stone"
    },
    {
      "x": 2,
      "y": -5,
      "z": -1,
      "name": "Rock_Basalt"
    },
    {
      "x": 2,
      "y": -4,
      "z": -1,
      "name": "Rock_Basalt"
    },
    {
      "x": 2,
      "y": -3,
      "z": -1,
      "name": "Rock_Basalt"
    },
    {
      "x": 2,
      "y": -2,
      "z": -1,
      "name": "Rock_Basalt"
    },
    {
      "x": 2,
      "y": -1,
      "z": -1,
      "name": "Rock_Basalt"
    },
    {
      "x": 2,
      "y": 0,
      "z": -1,
      "name": "Rock_Stone"
    },
    {
      "x": 2,
      "y": 1,
      "z": -1,
      "name": "Rock_Stone"
    },
    {
      "x": 2,
      "y": 2,
      "z": -1,
      "name": "Rock_Stone"
    },
    {
      "x": 2,
      "y": 3,
      "z": -1,
      "name": "Rock_Stone"
    },
    {
      "x": 2,
      "y": -5,
      "z": 0,
      "name": "Rock_Basalt"
    },
    {
      "x": 2,
      "y": -4,
      "z": 0,
      "name": "Rock_Basalt"
    },
    {
      "x": 2,
      "y": -3,
      "z": 0,
      "name": "Rock_Basalt"
    },
    {
      "x": 2,
      "y": -2,
      "z": 0,
      "name": "Rock_Basalt"
    },
    {
      "x": 2,
      "y": -1,
      "z": 0,
      "name": "Rock_Basalt"
    },
    {
      "x": 2,
      "y": 0,
      "z": 0,
      "name": "Rock_Stone"
    },
    {
      "x": 2,
      "y": 1,
      "z": 0,
      "name": "Rock_Stone"
    },
    {
      "x": 2,
      "y": 2,
      "z": 0,
      "name": "Rock_Stone"
    },
    {
      "x": 2,
      "y": 3,
      "z": 0,
      "name": "Rock_Stone"
    },
    {
      "x": 2,
      "y": -5,
      "z": 2,
      "name": "Rock_Basalt"
    },
    {
      "x": 2,
      "y": -4,
      "z": 2,
      "name": "Rock_Basalt"
    },
    {
      "x": 2,
      "y": -3,
      "z": 2,
      "name": "Rock_Basalt"
    },
    {
      "x": 2,
      "y": -2,
      "z": 2,
      "name": "Rock_Basalt"
    },
    {
      "x": 2,
      "y": -1,
      "z": 2,
      "name": "Rock_Basalt"
    },
    {
      "x": 2,
      "y": 0,
      "z": 2,
      "name": "Rock_Stone"
    },
    {
      "x": 2,
      "y": 1,
      "z": 2,
      "name": "Rock_Stone"
    },
    {
      "x": 2,
      "y": 2,
      "z": 2,
      "name": "Rock_Stone"
    },
    {
      "x": 2,
      "y": 3,
      "z": 2,
      "name": "Rock_Stone"
    },
    {
      "x": 2,
      "y": -4,
      "z": 3,
      "name": "Rock_Basalt"
    },
    {
      "x": 2,
      "y": -3,
      "z": 3,
      "name": "Rock_Basalt"
    },
    {
      "x": 2,
      "y": -2,
      "z": 3,
      "name": "Rock_Basalt"
    },
    {
      "x": 2,
      "y": -1,
      "z": 3,
      "name": "Rock_Basalt"
    },
    {
      "x": 2,
      "y": 0,
      "z": 3,
      "name": "Rock_Stone"
    },
    {
      "x": 2,
      "y": 1,
      "z": 3,
      "name": "Rock_Stone"
    },
    {
      "x": 2,
      "y": 2,
      "z": 3,
      "name": "Rock_Stone"
    },
    {
      "x": 2,
      "y": 3,
      "z": 3,
      "name": "Rock_Stone"
    },
    {
      "x": 2,
      "y": -3,
      "z": 4,
      "name": "Rock_Basalt"
    },
    {
      "x": 2,
      "y": -2,
      "z": 4,
      "name": "Rock_Basalt"
    },
    {
      "x": 2,
      "y": -1,
      "z": 4,
      "name": "Rock_Stone"
    },
    {
      "x": 2,
      "y": 0,
      "z": 4,
      "name": "Rock_Stone"
    },
    {
      "x": 2,
      "y": 1,
      "z": 4,
      "name": "Rock_Stone"
    },
    {
      "x": 2,
      "y": 2,
      "z": 4,
      "name": "Rock_Stone"
    },
    {
      "x": 3,
      "y": -2,
      "z": -6,
      "name": "Rock_Stone"
    },
    {
      "x": 3,
      "y": -1,
      "z": -6,
      "name": "Rock_Stone"
    },
    {
      "x": 3,
      "y": 0,
      "z": -6,
      "name": "Rock_Stone"
    },
    {
      "x": 3,
      "y": -4,
      "z": -5,
      "name": "Rock_Basalt"
    },
    {
      "x": 3,
      "y": -3,
      "z": -5,
      "name": "Rock_Basalt"
    },
    {
      "x": 3,
      "y": -2,
      "z": -5,
      "name": "Rock_Basalt"
    },
    {
      "x": 3,
      "y": -1,
      "z": -5,
      "name": "Rock_Stone"
    },
    {
      "x": 3,
      "y": 0,
      "z": -5,
      "name": "Rock_Stone"
    },
    {
      "x": 3,
      "y": 1,
      "z": -5,
      "name": "Rock_Stone"
    },
    {
      "x": 3,
      "y": 2,
      "z": -5,
      "name": "Rock_Stone"
    },
    {
      "x": 3,
      "y": -4,
      "z": -4,
      "name": "Rock_Basalt"
    },
    {
      "x": 3,
      "y": -3,
      "z": -4,
      "name": "Rock_Basalt"
    },
    {
      "x": 3,
      "y": -2,
      "z": -4,
      "name": "Rock_Basalt"
    },
    {
      "x": 3,
      "y": -1,
      "z": -4,
      "name": "Rock_Basalt"
    },
    {
      "x": 3,
      "y": 0,
      "z": -4,
      "name": "Rock_Stone"
    },
    {
      "x": 3,
      "y": 1,
      "z": -4,
      "name": "Rock_Stone"
    },
    {
      "x": 3,
      "y": 2,
      "z": -4,
      "name": "Rock_Stone"
    },
    {
      "x": 3,
      "y": 3,
      "z": -4,
      "name": "Rock_Stone"
    },
    {
      "x": 3,
      "y": -5,
      "z": -3,
      "name": "Rock_Basalt"
    },
    {
      "x": 3,
      "y": -4,
      "z": -3,
      "name": "Rock_Basalt"
    },
    {
      "x": 3,
      "y": -3,
      "z": -3,
      "name": "Rock_Basalt"
    },
    {
      "x": 3,
      "y": -2,
      "z": -3,
      "name": "Rock_Basalt"
    },
    {
      "x": 3,
      "y": -1,
      "z": -3,
      "name": "Rock_Basalt"
    },
    {
      "x": 3,
      "y": 0,
      "z": -3,
      "name": "Rock_Basalt"
    },
    {
      "x": 3,
      "y": 1,
      "z": -3,
      "name": "Rock_Stone"
    },
    {
      "x": 3,
      "y": 2,
      "z": -3,
      "name": "Rock_Stone"
    },
    {
      "x": 3,
      "y": 3,
      "z": -3,
      "name": "Rock_Stone"
    },
    {
      "x": 3,
      "y": 4,
      "z": -3,
      "name": "Rock_Stone"
    },
    {
      "x": 3,
      "y": -5,
      "z": -2,
      "name": "Rock_Basalt"
    },
    {
      "x": 3,
      "y": -4,
      "z": -2,
      "name": "Rock_Basalt"
    },
    {
      "x": 3,
      "y": -3,
      "z": -2,
      "name": "Rock_Basalt"
    },
    {
      "x": 3,
      "y": -2,
      "z": -2,
      "name": "Rock_Basalt"
    },
    {
      "x": 3,
      "y": -1,
      "z": -2,
      "name": "Rock_Basalt"
    },
    {
      "x": 3,
      "y": 0,
      "z": -2,
      "name": "Rock_Basalt"
    },
    {
      "x": 3,
      "y": 1,
      "z": -2,
      "name": "Rock_Stone"
    },
    {
      "x": 3,
      "y": 2,
      "z": -2,
      "name": "Rock_Stone"
    },
    {
      "x": 3,
      "y": 3,
      "z": -2,
      "name": "Rock_Stone"
    },
    {
      "x": 3,
      "y": 4,
      "z": -2,
      "name": "Rock_Stone"
    },
    {
      "x": 3,
      "y": -6,
      "z": -1,
      "name": "Rock_Basalt"
    },
    {
      "x": 3,
      "y": -5,
      "z": -1,
      "name": "Rock_Basalt"
    },
    {
      "x": 3,
      "y": -4,
      "z": -1,
      "name": "Rock_Basalt"
    },
    {
      "x": 3,
      "y": -3,
      "z": -1,
      "name": "Rock_Basalt"
    },
    {
      "x": 3,
      "y": -2,
      "z": -1,
      "name": "Rock_Basalt"
    },
    {
      "x": 3,
      "y": -1,
      "z": -1,
      "name": "Rock_Basalt"
    },
    {
      "x": 3,
      "y": 0,
      "z": -1,
      "name": "Rock_Basalt"
    },
    {
      "x": 3,
      "y": 1,
      "z": -1,
      "name": "Rock_Stone"
    },
    {
      "x": 3,
      "y": 2,
      "z": -1,
      "name": "Rock_Stone"
    },
    {
      "x": 3,
      "y": 3,
      "z": -1,
      "name": "Rock_Stone"
    },
    {
      "x": 3,
      "y": 4,
      "z": -1,
      "name": "Rock_Stone"
    },
    {
      "x": 3,
      "y": -5,
      "z": 1,
      "name": "Rock_Basalt"
    },
    {
      "x": 3,
      "y": -4,
      "z": 1,
      "name": "Rock_Basalt"
    },
    {
      "x": 3,
      "y": -3,
      "z": 1,
      "name": "Rock_Basalt"
    },
    {
      "x": 3,
      "y": -2,
      "z": 1,
      "name": "Rock_Basalt"
    },
    {
      "x": 3,
      "y": -1,
      "z": 1,
      "name": "Rock_Basalt"
    },
    {
      "x": 3,
      "y": 0,
      "z": 1,
      "name": "Rock_Basalt"
    },
    {
      "x": 3,
      "y": 1,
      "z": 1,
      "name": "Rock_Stone"
    },
    {
      "x": 3,
      "y": 2,
      "z": 1,
      "name": "Rock_Stone"
    },
    {
      "x": 3,
      "y": 3,
      "z": 1,
      "name": "Rock_Stone"
    },
    {
      "x": 3,
      "y": 4,
      "z": 1,
      "name": "Rock_Stone"
    },
    {
      "x": 3,
      "y": -5,
      "z": 2,
      "name": "Rock_Basalt"
    },
    {
      "x": 3,
      "y": -4,
      "z": 2,
      "name": "Rock_Basalt"
    },
    {
      "x": 3,
      "y": -3,
      "z": 2,
      "name": "Rock_Basalt"
    },
    {
      "x": 3,
      "y": -2,
      "z": 2,
      "name": "Rock_Basalt"
    },
    {
      "x": 3,
      "y": -1,
      "z": 2,
      "name": "Rock_Basalt"
    },
    {
      "x": 3,
      "y": 0,
      "z": 2,
      "name": "Rock_Stone"
    },
    {
      "x": 3,
      "y": 1,
      "z": 2,
      "name": "Rock_Stone"
    },
    {
      "x": 3,
      "y": 2,
      "z": 2,
      "name": "Rock_Stone"
    },
    {
      "x": 3,
      "y": 3,
      "z": 2,
      "name": "Rock_Stone"
    },
    {
      "x": 3,
      "y": -5,
      "z": 3,
      "name": "Rock_Basalt"
    },
    {
      "x": 3,
      "y": -4,
      "z": 3,
      "name": "Rock_Basalt"
    },
    {
      "x": 3,
      "y": -3,
      "z": 3,
      "name": "Rock_Basalt"
    },
    {
      "x": 3,
      "y": -2,
      "z": 3,
      "name": "Rock_Basalt"
    },
    {
      "x": 3,
      "y": -1,
      "z": 3,
      "name": "Rock_Basalt"
    },
    {
      "x": 3,
      "y": 0,
      "z": 3,
      "name": "Rock_Stone"
    },
    {
      "x": 3,
      "y": 1,
      "z": 3,
      "name": "Rock_Stone"
    },
    {
      "x": 3,
      "y": 2,
      "z": 3,
      "name": "Rock_Stone"
    },
    {
      "x": 3,
      "y": 3,
      "z": 3,
      "name": "Rock_Stone"
    },
    {
      "x": 3,
      "y": -4,
      "z": 4,
      "name": "Rock_Basalt"
    },
    {
      "x": 3,
      "y": -3,
      "z": 4,
      "name": "Rock_Basalt"
    },
    {
      "x": 3,
      "y": -2,
      "z": 4,
      "name": "Rock_Basalt"
    },
    {
      "x": 3,
      "y": -1,
      "z": 4,
      "name": "Rock_Basalt"
    },
    {
      "x": 3,
      "y": 0,
      "z": 4,
      "name": "Rock_Stone"
    },
    {
      "x": 3,
      "y": 1,
      "z": 4,
      "name": "Rock_Stone"
    },
    {
      "x": 3,
      "y": 2,
      "z": 4,
      "name": "Rock_Stone"
    },
    {
      "x": 3,
      "y": 3,
      "z": 4,
      "name": "Rock_Stone"
    },
    {
      "x": 3,
      "y": -3,
      "z": 5,
      "name": "Rock_Basalt"
    },
    {
      "x": 3,
      "y": -2,
      "z": 5,
      "name": "Rock_Basalt"
    },
    {
      "x": 3,
      "y": -1,
      "z": 5,
      "name": "Rock_Basalt"
    },
    {
      "x": 3,
      "y": 0,
      "z": 5,
      "name": "Rock_Stone"
    },
    {
      "x": 3,
      "y": 1,
      "z": 5,
      "name": "Rock_Stone"
    },
    {
      "x": 3,
      "y": 2,
      "z": 5,
      "name": "Rock_Stone"
    },
    {
      "x": 3,
      "y": 3,
      "z": 5,
      "name": "Rock_Stone"
    },
    {
      "x": 4,
      "y": -3,
      "z": -5,
      "name": "Rock_Basalt"
    },
    {
      "x": 4,
      "y": -2,
      "z": -5,
      "name": "Rock_Stone"
    },
    {
      "x": 4,
      "y": -1,
      "z": -5,
      "name": "Rock_Stone"
    },
    {
      "x": 4,
      "y": 0,
      "z": -5,
      "name": "Rock_Stone"
    },
    {
      "x": 4,
      "y": 1,
      "z": -5,
      "name": "Rock_Stone"
    },
    {
      "x": 4,
      "y": -5,
      "z": -4,
      "name": "Rock_Basalt"
    },
    {
      "x": 4,
      "y": -4,
      "z": -4,
      "name": "Rock_Basalt"
    },
    {
      "x": 4,
      "y": -3,
      "z": -4,
      "name": "Rock_Basalt"
    },
    {
      "x": 4,
      "y": -2,
      "z": -4,
      "name": "Rock_Basalt"
    },
    {
      "x": 4,
      "y": -1,
      "z": -4,
      "name": "Rock_Basalt"
    },
    {
      "x": 4,
      "y": 0,
      "z": -4,
      "name": "Rock_Stone"
    },
    {
      "x": 4,
      "y": 1,
      "z": -4,
      "name": "Rock_Stone"
    },
    {
      "x": 4,
      "y": 2,
      "z": -4,
      "name": "Rock_Stone"
    },
    {
      "x": 4,
      "y": 3,
      "z": -4,
      "name": "Rock_Stone"
    },
    {
      "x": 4,
      "y": -5,
      "z": -3,
      "name": "Rock_Basalt"
    },
    {
      "x": 4,
      "y": -4,
      "z": -3,
      "name": "Rock_Basalt"
    },
    {
      "x": 4,
      "y": -3,
      "z": -3,
      "name": "Rock_Basalt"
    },
    {
      "x": 4,
      "y": -2,
      "z": -3,
      "name": "Rock_Basalt"
    },
    {
      "x": 4,
      "y": -1,
      "z": -3,
      "name": "Rock_Basalt"
    },
    {
      "x": 4,
      "y": 0,
      "z": -3,
      "name": "Rock_Stone"
    },
    {
      "x": 4,
      "y": 1,
      "z": -3,
      "name": "Rock_Stone"
    },
    {
      "x": 4,
      "y": 2,
      "z": -3,
      "name": "Rock_Stone"
    },
    {
      "x": 4,
      "y": 3,
      "z": -3,
      "name": "Rock_Stone"
    },
    {
      "x": 4,
      "y": -5,
      "z": -2,
      "name": "Rock_Basalt"
    },
    {
      "x": 4,
      "y": -4,
      "z": -2,
      "name": "Rock_Basalt"
    },
    {
      "x": 4,
      "y": -3,
      "z": -2,
      "name": "Rock_Basalt"
    },
    {
      "x": 4,
      "y": -2,
      "z": -2,
      "name": "Rock_Basalt"
    },
    {
      "x": 4,
      "y": -1,
      "z": -2,
      "name": "Rock_Basalt"
    },
    {
      "x": 4,
      "y": 0,
      "z": -2,
      "name": "Rock_Basalt"
    },
    {
      "x": 4,
      "y": 1,
      "z": -2,
      "name": "Rock_Stone"
    },
    {
      "x": 4,
      "y": 2,
      "z": -2,
      "name": "Rock_Stone"
    },
    {
      "x": 4,
      "y": 3,
      "z": -2,
      "name": "Rock_Stone"
    },
    {
      "x": 4,
      "y": 4,
      "z": -2,
      "name": "Rock_Stone"
    },
    {
      "x": 4,
      "y": -5,
      "z": -1,
      "name": "Rock_Basalt"
    },
    {
      "x": 4,
      "y": -4,
      "z": -1,
      "name": "Rock_Basalt"
    },
    {
      "x": 4,
      "y": -3,
      "z": -1,
      "name": "Rock_Basalt"
    },
    {
      "x": 4,
      "y": -2,
      "z": -1,
      "name": "Rock_Basalt"
    },
    {
      "x": 4,
      "y": -1,
      "z": -1,
      "name": "Rock_Basalt"
    },
    {
      "x": 4,
      "y": 0,
      "z": -1,
      "name": "Rock_Basalt"
    },
    {
      "x": 4,
      "y": 1,
      "z": -1,
      "name": "Rock_Stone"
    },
    {
      "x": 4,
      "y": 2,
      "z": -1,
      "name": "Rock_Stone"
    },
    {
      "x": 4,
      "y": 3,
      "z": -1,
      "name": "Rock_Stone"
    },
    {
      "x": 4,
      "y": 4,
      "z": -1,
      "name": "Rock_Stone"
    },
    {
      "x": 4,
      "y": -6,
      "z": 0,
      "name": "Rock_Basalt"
    },
    {
      "x": 4,
      "y": -5,
      "z": 0,
      "name": "Rock_Basalt"
    },
    {
      "x": 4,
      "y": -4,
      "z": 0,
      "name": "Rock_Basalt"
    },
    {
      "x": 4,
      "y": -3,
      "z": 0,
      "name": "Rock_Basalt"
    },
    {
      "x": 4,
      "y": -2,
      "z": 0,
      "name": "Rock_Basalt"
    },
    {
      "x": 4,
      "y": -1,
      "z": 0,
      "name": "Rock_Basalt"
    },
    {
      "x": 4,
      "y": 0,
      "z": 0,
      "name": "Rock_Basalt"
    },
    {
      "x": 4,
      "y": 1,
      "z": 0,
      "name": "Rock_Basalt"
    },
    {
      "x": 4,
      "y": 2,
      "z": 0,
      "name": "Rock_Stone"
    },
    {
      "x": 4,
      "y": 3,
      "z": 0,
      "name": "Rock_Stone"
    },
    {
      "x": 4,
      "y": 4,
      "z": 0,
      "name": "Rock_Stone"
    },
    {
      "x": 4,
      "y": 5,
      "z": 0,
      "name": "Rock_Stone"
    },
    {
      "x": 4,
      "y": -6,
      "z": 1,
      "name": "Rock_Basalt"
    },
    {
      "x": 4,
      "y": -5,
      "z": 1,
      "name": "Rock_Basalt"
    },
    {
      "x": 4,
      "y": -4,
      "z": 1,
      "name": "Rock_Basalt"
    },
    {
      "x": 4,
      "y": -3,
      "z": 1,
      "name": "Rock_Basalt"
    },
    {
      "x": 4,
      "y": -2,
      "z": 1,
      "name": "Rock_Basalt"
    },
    {
      "x": 4,
      "y": -1,
      "z": 1,
      "name": "Rock_Basalt"
    },
    {
      "x": 4,
      "y": 0,
      "z": 1,
      "name": "Rock_Basalt"
    },
    {
      "x": 4,
      "y": 1,
      "z": 1,
      "name": "Rock_Stone"
    },
    {
      "x": 4,
      "y": 2,
      "z": 1,
      "name": "Rock_Stone"
    },
    {
      "x": 4,
      "y": 3,
      "z": 1,
      "name": "Rock_Stone"
    },
    {
      "x": 4,
      "y": 4,
      "z": 1,
      "name": "Rock_Stone"
    },
    {
      "x": 4,
      "y": -6,
      "z": 2,
      "name": "Rock_Basalt"
    },
    {
      "x": 4,
      "y": -5,
      "z": 2,
      "name": "Rock_Basalt"
    },
    {
      "x": 4,
      "y": -4,
      "z": 2,
      "name": "Rock_Basalt"
    },
    {
      "x": 4,
      "y": -3,
      "z": 2,
      "name": "Rock_Basalt"
    },
    {
      "x": 4,
      "y": -2,
      "z": 2,
      "name": "Rock_Basalt"
    },
    {
      "x": 4,
      "y": -1,
      "z": 2,
      "name": "Rock_Basalt"
    },
    {
      "x": 4,
      "y": 0,
      "z": 2,
      "name": "Rock_Basalt"
    },
    {
      "x": 4,
      "y": 1,
      "z": 2,
      "name": "Rock_Stone"
    },
    {
      "x": 4,
      "y": 2,
      "z": 2,
      "name": "Rock_Stone"
    },
    {
      "x": 4,
      "y": 3,
      "z": 2,
      "name": "Rock_Stone"
    },
    {
      "x": 4,
      "y": 4,
      "z": 2,
      "name": "Rock_Stone"
    },
    {
      "x": 4,
      "y": -5,
      "z": 3,
      "name": "Rock_Basalt"
    },
    {
      "x": 4,
      "y": -4,
      "z": 3,
      "name": "Rock_Basalt"
    },
    {
      "x": 4,
      "y": -3,
      "z": 3,
      "name": "Rock_Basalt"
    },
    {
      "x": 4,
      "y": -2,
      "z": 3,
      "name": "Rock_Basalt"
    },
    {
      "x": 4,
      "y": -1,
      "z": 3,
      "name": "Rock_Basalt"
    },
    {
      "x": 4,
      "y": 0,
      "z": 3,
      "name": "Rock_Stone"
    },
    {
      "x": 4,
      "y": 1,
      "z": 3,
      "name": "Rock_Stone"
    },
    {
      "x": 4,
      "y": 2,
      "z": 3,
      "name": "Rock_Stone"
    },
    {
      "x": 4,
      "y": 3,
      "z": 3,
      "name": "Rock_Stone"
    },
    {
      "x": 4,
      "y": -5,
      "z": 4,
      "name": "Rock_Basalt"
    },
    {
      "x": 4,
      "y": -4,
      "z": 4,
      "name": "Rock_Basalt"
    },
    {
      "x": 4,
      "y": -3,
      "z": 4,
      "name": "Rock_Basalt"
    },
    {
      "x": 4,
      "y": -2,
      "z": 4,
      "name": "Rock_Basalt"
    },
    {
      "x": 4,
      "y": -1,
      "z": 4,
      "name": "Rock_Basalt"
    },
    {
      "x": 4,
      "y": 0,
      "z": 4,
      "name": "Rock_Basalt"
    },
    {
      "x": 4,
      "y": 1,
      "z": 4,
      "name": "Rock_Stone"
    },
    {
      "x": 4,
      "y": 2,
      "z": 4,
      "name": "Rock_Stone"
    },
    {
      "x": 4,
      "y": 3,
      "z": 4,
      "name": "Rock_Stone"
    },
    {
      "x": 4,
      "y": 4,
      "z": 4,
      "name": "Rock_Stone"
    },
    {
      "x": 4,
      "y": -3,
      "z": 5,
      "name": "Rock_Basalt"
    },
    {
      "x": 4,
      "y": -2,
      "z": 5,
      "name": "Rock_Basalt"
    },
    {
      "x": 4,
      "y": -1,
      "z": 5,
      "name": "Rock_Basalt"
    },
    {
      "x": 4,
      "y": 0,
      "z": 5,
      "name": "Rock_Stone"
    },
    {
      "x": 4,
      "y": 1,
      "z": 5,
      "name": "Rock_Stone"
    },
    {
      "x": 4,
      "y": 2,
      "z": 5,
      "name": "Rock_Stone"
    },
    {
      "x": 4,
      "y": 3,
      "z": 5,
      "name": "Rock_Stone"
    },
    {
      "x": 5,
      "y": -1,
      "z": -5,
      "name": "Rock_Stone"
    },
    {
      "x": 5,
      "y": -4,
      "z": -4,
      "name": "Rock_Basalt"
    },
    {
      "x": 5,
      "y": -3,
      "z": -4,
      "name": "Rock_Basalt"
    },
    {
      "x": 5,
      "y": -2,
      "z": -4,
      "name": "Rock_Basalt"
    },
    {
      "x": 5,
      "y": -1,
      "z": -4,
      "name": "Rock_Stone"
    },
    {
      "x": 5,
      "y": 0,
      "z": -4,
      "name": "Rock_Stone"
    },
    {
      "x": 5,
      "y": 1,
      "z": -4,
      "name": "Rock_Stone"
    },
    {
      "x": 5,
      "y": 2,
      "z": -4,
      "name": "Rock_Stone"
    },
    {
      "x": 5,
      "y": -5,
      "z": -3,
      "name": "Rock_Basalt"
    },
    {
      "x": 5,
      "y": -4,
      "z": -3,
      "name": "Rock_Basalt"
    },
    {
      "x": 5,
      "y": -3,
      "z": -3,
      "name": "Rock_Basalt"
    },
    {
      "x": 5,
      "y": -2,
      "z": -3,
      "name": "Rock_Basalt"
    },
    {
      "x": 5,
      "y": -1,
      "z": -3,
      "name": "Rock_Basalt"
    },
    {
      "x": 5,
      "y": 0,
      "z": -3,
      "name": "Rock_Stone"
    },
    {
      "x": 5,
      "y": 1,
      "z": -3,
      "name": "Rock_Stone"
    },
    {
      "x": 5,
      "y": 2,
      "z": -3,
      "name": "Rock_Stone"
    },
    {
      "x": 5,
      "y": 3,
      "z": -3,
      "name": "Rock_Stone"
    },
    {
      "x": 5,
      "y": -5,
      "z": -2,
      "name": "Rock_Basalt"
    },
    {
      "x": 5,
      "y": -4,
      "z": -2,
      "name": "Rock_Basalt"
    },
    {
      "x": 5,
      "y": -3,
      "z": -2,
      "name": "Rock_Basalt"
    },
    {
      "x": 5,
      "y": -2,
      "z": -2,
      "name": "Rock_Basalt"
    },
    {
      "x": 5,
      "y": -1,
      "z": -2,
      "name": "Rock_Basalt"
    },
    {
      "x": 5,
      "y": 0,
      "z": -2,
      "name": "Rock_Basalt"
    },
    {
      "x": 5,
      "y": 1,
      "z": -2,
      "name": "Rock_Stone"
    },
    {
      "x": 5,
      "y": 2,
      "z": -2,
      "name": "Rock_Stone"
    },
    {
      "x": 5,
      "y": 3,
      "z": -2,
      "name": "Rock_Stone"
    },
    {
      "x": 5,
      "y": 4,
      "z": -2,
      "name": "Rock_Stone"
    },
    {
      "x": 5,
      "y": -5,
      "z": -1,
      "name": "Rock_Basalt"
    },
    {
      "x": 5,
      "y": -4,
      "z": -1,
      "name": "Rock_Basalt"
    },
    {
      "x": 5,
      "y": -3,
      "z": -1,
      "name": "Rock_Basalt"
    },
    {
      "x": 5,
      "y": -2,
      "z": -1,
      "name": "Rock_Basalt"
    },
    {
      "x": 5,
      "y": -1,
      "z": -1,
      "name": "Rock_Basalt"
    },
    {
      "x": 5,
      "y": 0,
      "z": -1,
      "name": "Rock_Basalt"
    },
    {
      "x": 5,
      "y": 1,
      "z": -1,
      "name": "Rock_Stone"
    },
    {
      "x": 5,
      "y": 2,
      "z": -1,
      "name": "Rock_Stone"
    },
    {
      "x": 5,
      "y": 3,
      "z": -1,
      "name": "Rock_Stone"
    },
    {
      "x": 5,
      "y": 4,
      "z": -1,
      "name": "Rock_Stone"
    },
    {
      "x": 5,
      "y": -6,
      "z": 0,
      "name": "Rock_Basalt"
    },
    {
      "x": 5,
      "y": -5,
      "z": 0,
      "name": "Rock_Basalt"
    },
    {
      "x": 5,
      "y": -4,
      "z": 0,
      "name": "Rock_Basalt"
    },
    {
      "x": 5,
      "y": -3,
      "z": 0,
      "name": "Rock_Basalt"
    },
    {
      "x": 5,
      "y": -2,
      "z": 0,
      "name": "Rock_Basalt"
    },
    {
      "x": 5,
      "y": -1,
      "z": 0,
      "name": "Rock_Basalt"
    },
    {
      "x": 5,
      "y": 0,
      "z": 0,
      "name": "Rock_Basalt"
    },
    {
      "x": 5,
      "y": 1,
      "z": 0,
      "name": "Rock_Basalt"
    },
    {
      "x": 5,
      "y": 2,
      "z": 0,
      "name": "Rock_Stone"
    },
    {
      "x": 5,
      "y": 3,
      "z": 0,
      "name": "Rock_Stone"
    },
    {
      "x": 5,
      "y": 4,
      "z": 0,
      "name": "Rock_Stone"
    },
    {
      "x": 5,
      "y": 5,
      "z": 0,
      "name": "Rock_Stone"
    },
    {
      "x": 5,
      "y": -5,
      "z": 1,
      "name": "Rock_Basalt"
    },
    {
      "x": 5,
      "y": -4,
      "z": 1,
      "name": "Rock_Basalt"
    },
    {
      "x": 5,
      "y": -3,
      "z": 1,
      "name": "Rock_Basalt"
    },
    {
      "x": 5,
      "y": -2,
      "z": 1,
      "name": "Rock_Basalt"
    },
    {
      "x": 5,
      "y": -1,
      "z": 1,
      "name": "Rock_Basalt"
    },
    {
      "x": 5,
      "y": 0,
      "z": 1,
      "name": "Rock_Basalt"
    },
    {
      "x": 5,
      "y": 1,
      "z": 1,
      "name": "Rock_Basalt"
    },
    {
      "x": 5,
      "y": 2,
      "z": 1,
      "name": "Rock_Stone"
    },
    {
      "x": 5,
      "y": 3,
      "z": 1,
      "name": "Rock_Stone"
    },
    {
      "x": 5,
      "y": 4,
      "z": 1,
      "name": "Rock_Stone"
    },
    {
      "x": 5,
      "y": 5,
      "z": 1,
      "name": "Rock_Stone"
    },
    {
      "x": 5,
      "y": -5,
      "z": 2,
      "name": "Rock_Basalt"
    },
    {
      "x": 5,
      "y": -4,
      "z": 2,
      "name": "Rock_Basalt"
    },
    {
      "x": 5,
      "y": -3,
      "z": 2,
      "name": "Rock_Basalt"
    },
    {
      "x": 5,
      "y": -2,
      "z": 2,
      "name": "Rock_Basalt"
    },
    {
      "x": 5,
      "y": -1,
      "z": 2,
      "name": "Rock_Basalt"
    },
    {
      "x": 5,
      "y": 0,
      "z": 2,
      "name": "Rock_Basalt"
    },
    {
      "x": 5,
      "y": 1,
      "z": 2,
      "name": "Rock_Basalt"
    },
    {
      "x": 5,
      "y": 2,
      "z": 2,
      "name": "Rock_Stone"
    },
    {
      "x": 5,
      "y": 3,
      "z": 2,
      "name": "Rock_Stone"
    },
    {
      "x": 5,
      "y": 4,
      "z": 2,
      "name": "Rock_Stone"
    },
    {
      "x": 5,
      "y": 5,
      "z": 2,
      "name": "Rock_Stone"
    },
    {
      "x": 5,
      "y": -5,
      "z": 3,
      "name": "Rock_Basalt"
    },
    {
      "x": 5,
      "y": -4,
      "z": 3,
      "name": "Rock_Basalt"
    },
    {
      "x": 5,
      "y": -3,
      "z": 3,
      "name": "Rock_Basalt"
    },
    {
      "x": 5,
      "y": -2,
      "z": 3,
      "name": "Rock_Basalt"
    },
    {
      "x": 5,
      "y": -1,
      "z": 3,
      "name": "Rock_Basalt"
    },
    {
      "x": 5,
      "y": 0,
      "z": 3,
      "name": "Rock_Basalt"
    },
    {
      "x": 5,
      "y": 1,
      "z": 3,
      "name": "Rock_Stone"
    },
    {
      "x": 5,
      "y": 2,
      "z": 3,
      "name": "Rock_Stone"
    },
    {
      "x": 5,
      "y": 3,
      "z": 3,
      "name": "Rock_Stone"
    },
    {
      "x": 5,
      "y": 4,
      "z": 3,
      "name": "Rock_Stone"
    },
    {
      "x": 5,
      "y": -4,
      "z": 4,
      "name": "Rock_Basalt"
    },
    {
      "x": 5,
      "y": -3,
      "z": 4,
      "name": "Rock_Basalt"
    },
    {
      "x": 5,
      "y": -2,
      "z": 4,
      "name": "Rock_Basalt"
    },
    {
      "x": 5,
      "y": -1,
      "z": 4,
      "name": "Rock_Basalt"
    },
    {
      "x": 5,
      "y": 0,
      "z": 4,
      "name": "Rock_Stone"
    },
    {
      "x": 5,
      "y": 1,
      "z": 4,
      "name": "Rock_Stone"
    },
    {
      "x": 5,
      "y": 2,
      "z": 4,
      "name": "Rock_Stone"
    },
    {
      "x": 5,
      "y": 3,
      "z": 4,
      "name": "Rock_Stone"
    },
    {
      "x": 5,
      "y": -1,
      "z": 5,
      "name": "Rock_Stone"
    },
    {
      "x": 5,
      "y": 0,
      "z": 5,
      "name": "Rock_Stone"
    },
    {
      "x": 5,
      "y": 1,
      "z": 5,
      "name": "Rock_Stone"
    },
    {
      "x": 5,
      "y": 2,
      "z": 5,
      "name": "Rock_Stone"
    },
    {
      "x": 6,
      "y": -1,
      "z": -4,
      "name": "Rock_Stone"
    },
    {
      "x": 6,
      "y": 0,
      "z": -4,
      "name": "Rock_Stone"
    },
    {
      "x": 6,
      "y": 1,
      "z": -4,
      "name": "Rock_Stone"
    },
    {
      "x": 6,
      "y": 2,
      "z": -4,
      "name": "Rock_Stone"
    },
    {
      "x": 6,
      "y": -3,
      "z": -3,
      "name": "Rock_Basalt"
    },
    {
      "x": 6,
      "y": -2,
      "z": -3,
      "name": "Rock_Basalt"
    },
    {
      "x": 6,
      "y": -1,
      "z": -3,
      "name": "Rock_Basalt"
    },
    {
      "x": 6,
      "y": 0,
      "z": -3,
      "name": "Rock_Stone"
    },
    {
      "x": 6,
      "y": 1,
      "z": -3,
      "name": "Rock_Stone"
    },
    {
      "x": 6,
      "y": 2,
      "z": -3,
      "name": "Rock_Stone"
    },
    {
      "x": 6,
      "y": 3,
      "z": -3,
      "name": "Rock_Stone"
    },
    {
      "x": 6,
      "y": -4,
      "z": -2,
      "name": "Rock_Basalt"
    },
    {
      "x": 6,
      "y": -3,
      "z": -2,
      "name": "Rock_Basalt"
    },
    {
      "x": 6,
      "y": -2,
      "z": -2,
      "name": "Rock_Basalt"
    },
    {
      "x": 6,
      "y": -1,
      "z": -2,
      "name": "Rock_Basalt"
    },
    {
      "x": 6,
      "y": 0,
      "z": -2,
      "name": "Rock_Stone"
    },
    {
      "x": 6,
      "y": 1,
      "z": -2,
      "name": "Rock_Stone"
    },
    {
      "x": 6,
      "y": 2,
      "z": -2,
      "name": "Rock_Stone"
    },
    {
      "x": 6,
      "y": 3,
      "z": -2,
      "name": "Rock_Stone"
    },
    {
      "x": 6,
      "y": -4,
      "z": -1,
      "name": "Rock_Basalt"
    },
    {
      "x": 6,
      "y": -3,
      "z": -1,
      "name": "Rock_Basalt"
    },
    {
      "x": 6,
      "y": -2,
      "z": -1,
      "name": "Rock_Basalt"
    },
    {
      "x": 6,
      "y": -1,
      "z": -1,
      "name": "Rock_Basalt"
    },
    {
      "x": 6,
      "y": 0,
      "z": -1,
      "name": "Rock_Basalt"
    },
    {
      "x": 6,
      "y": 1,
      "z": -1,
      "name": "Rock_Stone"
    },
    {
      "x": 6,
      "y": 2,
      "z": -1,
      "name": "Rock_Stone"
    },
    {
      "x": 6,
      "y": 3,
      "z": -1,
      "name": "Rock_Stone"
    },
    {
      "x": 6,
      "y": 4,
      "z": -1,
      "name": "Rock_Stone"
    },
    {
      "x": 6,
      "y": -5,
      "z": 0,
      "name": "Rock_Basalt"
    },
    {
      "x": 6,
      "y": -4,
      "z": 0,
      "name": "Rock_Basalt"
    },
    {
      "x": 6,
      "y": -3,
      "z": 0,
      "name": "Rock_Basalt"
    },
    {
      "x": 6,
      "y": -2,
      "z": 0,
      "name": "Rock_Basalt"
    },
    {
      "x": 6,
      "y": -1,
      "z": 0,
      "name": "Rock_Basalt"
    },
    {
      "x": 6,
      "y": 0,
      "z": 0,
      "name": "Rock_Basalt"
    },
    {
      "x": 6,
      "y": 1,
      "z": 0,
      "name": "Rock_Basalt"
    },
    {
      "x": 6,
      "y": 2,
      "z": 0,
      "name": "Rock_Stone"
    },
    {
      "x": 6,
      "y": 3,
      "z": 0,
      "name": "Rock_Stone"
    },
    {
      "x": 6,
      "y": 4,
      "z": 0,
      "name": "Rock_Stone"
    },
    {
      "x": 6,
      "y": 5,
      "z": 0,
      "name": "Rock_Stone"
    },
    {
      "x": 6,
      "y": -4,
      "z": 1,
      "name": "Rock_Basalt"
    },
    {
      "x": 6,
      "y": -3,
      "z": 1,
      "name": "Rock_Basalt"
    },
    {
      "x": 6,
      "y": -2,
      "z": 1,
      "name": "Rock_Basalt"
    },
    {
      "x": 6,
      "y": -1,
      "z": 1,
      "name": "Rock_Basalt"
    },
    {
      "x": 6,
      "y": 0,
      "z": 1,
      "name": "Rock_Basalt"
    },
    {
      "x": 6,
      "y": 1,
      "z": 1,
      "name": "Rock_Stone"
    },
    {
      "x": 6,
      "y": 2,
      "z": 1,
      "name": "Rock_Stone"
    },
    {
      "x": 6,
      "y": 3,
      "z": 1,
      "name": "Rock_Stone"
    },
    {
      "x": 6,
      "y": 4,
      "z": 1,
      "name": "Rock_Stone"
    },
    {
      "x": 6,
      "y": -4,
      "z": 2,
      "name": "Rock_Basalt"
    },
    {
      "x": 6,
      "y": -3,
      "z": 2,
      "name": "Rock_Basalt"
    },
    {
      "x": 6,
      "y": -2,
      "z": 2,
      "name": "Rock_Basalt"
    },
    {
      "x": 6,
      "y": -1,
      "z": 2,
      "name": "Rock_Basalt"
    },
    {
      "x": 6,
      "y": 0,
      "z": 2,
      "name": "Rock_Basalt"
    },
    {
      "x": 6,
      "y": 1,
      "z": 2,
      "name": "Rock_Stone"
    },
    {
      "x": 6,
      "y": 2,
      "z": 2,
      "name": "Rock_Stone"
    },
    {
      "x": 6,
      "y": 3,
      "z": 2,
      "name": "Rock_Stone"
    },
    {
      "x": 6,
      "y": 4,
      "z": 2,
      "name": "Rock_Stone"
    },
    {
      "x": 6,
      "y": -3,
      "z": 3,
      "name": "Rock_Basalt"
    },
    {
      "x": 6,
      "y": -2,
      "z": 3,
      "name": "Rock_Basalt"
    },
    {
      "x": 6,
      "y": -1,
      "z": 3,
      "name": "Rock_Basalt"
    },
    {
      "x": 6,
      "y": 0,
      "z": 3,
      "name": "Rock_Basalt"
    },
    {
      "x": 6,
      "y": 1,
      "z": 3,
      "name": "Rock_Stone"
    },
    {
      "x": 6,
      "y": 2,
      "z": 3,
      "name": "Rock_Stone"
    },
    {
      "x": 6,
      "y": 3,
      "z": 3,
      "name": "Rock_Stone"
    },
    {
      "x": 6,
      "y": 4,
      "z": 3,
      "name": "Rock_Stone"
    },
    {
      "x": 6,
      "y": -1,
      "z": 4,
      "name": "Rock_Basalt"
    },
    {
      "x": 6,
      "y": 0,
      "z": 4,
      "name": "Rock_Stone"
    },
    {
      "x": 6,
      "y": 1,
      "z": 4,
      "name": "Rock_Stone"
    },
    {
      "x": 6,
      "y": 2,
      "z": 4,
      "name": "Rock_Stone"
    },
    {
      "x": 6,
      "y": 3,
      "z": 4,
      "name": "Rock_Stone"
    },
    {
      "x": 6,
      "y": 0,
      "z": 5,
      "name": "Rock_Stone"
    },
    {
      "x": 6,
      "y": 1,
      "z": 5,
      "name": "Rock_Stone"
    },
    {
      "x": 6,
      "y": 2,
      "z": 5,
      "name": "Rock_Stone"
    },
    {
      "x": 7,
      "y": -2,
      "z": -3,
      "name": "Rock_Stone"
    },
    {
      "x": 7,
      "y": -1,
      "z": -3,
      "name": "Rock_Stone"
    },
    {
      "x": 7,
      "y": 0,
      "z": -3,
      "name": "Rock_Stone"
    },
    {
      "x": 7,
      "y": 1,
      "z": -3,
      "name": "Rock_Stone"
    },
    {
      "x": 7,
      "y": -2,
      "z": -2,
      "name": "Rock_Basalt"
    },
    {
      "x": 7,
      "y": -1,
      "z": -2,
      "name": "Rock_Stone"
    },
    {
      "x": 7,
      "y": 0,
      "z": -2,
      "name": "Rock_Stone"
    },
    {
      "x": 7,
      "y": 1,
      "z": -2,
      "name": "Rock_Stone"
    },
    {
      "x": 7,
      "y": 2,
      "z": -2,
      "name": "Rock_Stone"
    },
    {
      "x": 7,
      "y": -3,
      "z": -1,
      "name": "Rock_Basalt"
    },
    {
      "x": 7,
      "y": -2,
      "z": -1,
      "name": "Rock_Basalt"
    },
    {
      "x": 7,
      "y": -1,
      "z": -1,
      "name": "Rock_Stone"
    },
    {
      "x": 7,
      "y": 0,
      "z": -1,
      "name": "Rock_Stone"
    },
    {
      "x": 7,
      "y": 1,
      "z": -1,
      "name": "Rock_Stone"
    },
    {
      "x": 7,
      "y": 2,
      "z": -1,
      "name": "Rock_Stone"
    },
    {
      "x": 7,
      "y": -3,
      "z": 0,
      "name": "Rock_Basalt"
    },
    {
      "x": 7,
      "y": -2,
      "z": 0,
      "name": "Rock_Basalt"
    },
    {
      "x": 7,
      "y": -1,
      "z": 0,
      "name": "Rock_Basalt"
    },
    {
      "x": 7,
      "y": 0,
      "z": 0,
      "name": "Rock_Basalt"
    },
    {
      "x": 7,
      "y": 1,
      "z": 0,
      "name": "Rock_Stone"
    },
    {
      "x": 7,
      "y": 2,
      "z": 0,
      "name": "Rock_Stone"
    },
    {
      "x": 7,
      "y": 3,
      "z": 0,
      "name": "Rock_Stone"
    },
    {
      "x": 7,
      "y": 4,
      "z": 0,
      "name": "Rock_Stone"
    },
    {
      "x": 7,
      "y": -3,
      "z": 1,
      "name": "Rock_Basalt"
    },
    {
      "x": 7,
      "y": -2,
      "z": 1,
      "name": "Rock_Basalt"
    },
    {
      "x": 7,
      "y": -1,
      "z": 1,
      "name": "Rock_Basalt"
    },
    {
      "x": 7,
      "y": 0,
      "z": 1,
      "name": "Rock_Basalt"
    },
    {
      "x": 7,
      "y": 1,
      "z": 1,
      "name": "Rock_Stone"
    },
    {
      "x": 7,
      "y": 2,
      "z": 1,
      "name": "Rock_Stone"
    },
    {
      "x": 7,
      "y": 3,
      "z": 1,
      "name": "Rock_Stone"
    },
    {
      "x": 7,
      "y": 4,
      "z": 1,
      "name": "Rock_Stone"
    },
    {
      "x": 7,
      "y": -2,
      "z": 2,
      "name": "Rock_Basalt"
    },
    {
      "x": 7,
      "y": -1,
      "z": 2,
      "name": "Rock_Basalt"
    },
    {
      "x": 7,
      "y": 0,
      "z": 2,
      "name": "Rock_Stone"
    },
    {
      "x": 7,
      "y": 1,
      "z": 2,
      "name": "Rock_Stone"
    },
    {
      "x": 7,
      "y": 2,
      "z": 2,
      "name": "Rock_Stone"
    },
    {
      "x": 7,
      "y": 3,
      "z": 2,
      "name": "Rock_Stone"
    },
    {
      "x": 7,
      "y": -2,
      "z": 3,
      "name": "Rock_Basalt"
    },
    {
      "x": 7,
      "y": -1,
      "z": 3,
      "name": "Rock_Basalt"
    },
    {
      "x": 7,
      "y": 0,
      "z": 3,
      "name": "Rock_Stone"
    },
    {
      "x": 7,
      "y": 1,
      "z": 3,
      "name": "Rock_Stone"
    },
    {
      "x": 7,
      "y": 2,
      "z": 3,
      "name": "Rock_Stone"
    },
    {
      "x": 7,
      "y": 3,
      "z": 3,
      "name": "Rock_Stone"
    },
    {
      "x": 7,
      "y": 0,
      "z": 4,
      "name": "Rock_Stone"
    },
    {
      "x": 7,
      "y": 1,
      "z": 4,
      "name": "Rock_Stone"
    },
    {
      "x": 7,
      "y": 2,
      "z": 4,
      "name": "Rock_Stone"
    },
    {
      "x": 8,
      "y": -2,
      "z": -2,
      "name": "Rock_Stone"
    },
    {
      "x": 8,
      "y": -1,
      "z": -2,
      "name": "Rock_Stone"
    },
    {
      "x": 8,
      "y": 0,
      "z": -2,
      "name": "Rock_Stone"
    },
    {
      "x": 8,
      "y": -3,
      "z": -1,
      "name": "Rock_Basalt"
    },
    {
      "x": 8,
      "y": -2,
      "z": -1,
      "name": "Rock_Stone"
    },
    {
      "x": 8,
      "y": -1,
      "z": -1,
      "name": "Rock_Stone"
    },
    {
      "x": 8,
      "y": 0,
      "z": -1,
      "name": "Rock_Stone"
    },
    {
      "x": 8,
      "y": 1,
      "z": -1,
      "name": "Rock_Stone"
    },
    {
      "x": 8,
      "y": -3,
      "z": 0,
      "name": "Rock_Basalt"
    },
    {
      "x": 8,
      "y": -2,
      "z": 0,
      "name": "Rock_Basalt"
    },
    {
      "x": 8,
      "y": -1,
      "z": 0,
      "name": "Rock_Basalt"
    },
    {
      "x": 8,
      "y": 0,
      "z": 0,
      "name": "Rock_Stone"
    },
    {
      "x": 8,
      "y": 1,
      "z": 0,
      "name": "Rock_Stone"
    },
    {
      "x": 8,
      "y": 2,
      "z": 0,
      "name": "Rock_Stone"
    },
    {
      "x": 8,
      "y": 3,
      "z": 0,
      "name": "Rock_Stone"
    },
    {
      "x": 8,
      "y": -3,
      "z": 1,
      "name": "Rock_Basalt"
    },
    {
      "x": 8,
      "y": -2,
      "z": 1,
      "name": "Rock_Basalt"
    },
    {
      "x": 8,
      "y": -1,
      "z": 1,
      "name": "Rock_Stone"
    },
    {
      "x": 8,
      "y": 0,
      "z": 1,
      "name": "Rock_Stone"
    },
    {
      "x": 8,
      "y": 1,
      "z": 1,
      "name": "Rock_Stone"
    },
    {
      "x": 8,
      "y": 2,
      "z": 1,
      "name": "Rock_Stone"
    },
    {
      "x": 8,
      "y": -2,
      "z": 2,
      "name": "Rock_Basalt"
    },
    {
      "x": 8,
      "y": -1,
      "z": 2,
      "name": "Rock_Stone"
    },
    {
      "x": 8,
      "y": 0,
      "z": 2,
      "name": "Rock_Stone"
    },
    {
      "x": 8,
      "y": 1,
      "z": 2,
      "name": "Rock_Stone"
    },
    {
      "x": 8,
      "y": 2,
      "z": 2,
      "name": "Rock_Stone"
    },
    {
      "x": 8,
      "y": 0,
      "z": 3,
      "name": "Rock_Stone"
    },
    {
      "x": 8,
      "y": 1,
      "z": 3,
      "name": "Rock_Stone"
    }
  ]
}