{
  "version": 8,
  "blockIdVersion": 8,
  "anchorX": 0,
  "anchorY": 0,
  "anchorZ": 0,
  "blocks": [
    {
      "x": -6,
      "y": -7,
      "z": -12,
      "name": "Rock_Stone"
    },
    {
      "x": -6,
      "y": -6,
      "z": -12,
      "name": "Rock_Stone"
    },
    {
      "x": -6,
      "y": -5,
      "z": -12,
      "name": "Rock_Stone"
    },
    {
      "x": -6,
      "y": -4,
      "z": -12,
      "name": "Rock_Stone"
    },
    {
      "x": -6,
      "y": -3,
      "z": -12,
      "name": "Rock_Stone"
    },
    {
      "x": -6,
      "y": -2,
      "z": -12,
      "name": "Rock_Stone"
    },
    {
      "x": -6,
      "y": -1,
      "z": -12,
      "name": "Rock_Stone"
    },
    {
      "x": -6,
      "y": 0,
      "z": -12,
      "name": "Rock_Stone"
    },
    {
      "x": -6,
      "y": 1,
      "z": -12,
      "name": "Rock_Stone"
    },
    {
      "x": -6,
      "y": 2,
      "z": -12,
      "name": "Rock_Stone"
    },
    {
      "x": -6,
      "y": 3,
      "z": -12,
      "name": "Rock_Stone"
    },
    {
      "x": -6,
      "y": 4,
      "z": -12,
      "name": "Rock_Stone"
    },
    {
      "x": -6,
      "y": 5,
      "z": -12,
      "name": "Rock_Stone"
    },
    {
      "x": -6,
      "y": 6,
      "z": -12,
      "name": "Rock_Stone"
    },
    {
      "x": -6,
      "y": 7,
      "z": -12,
      "name": "Rock_Stone"
    },
    {
      "x": -6,
      "y": 8,
      "z": -12,
      "name": "Rock_Stone"
    },
    {
      "x": -6,
      "y": 9,
      "z": -12,
      "name": "Rock_Stone"
    },
    {
      "x": -6,
      "y": 10,
      "z": -12,
      "name": "Rock_Stone"
    },
    {
      "x": -6,
      "y": -7,
      "z": -11,
      "name": "Rock_Stone"
    },
    {
      "x": -6,
      "y": -6,
      "z": -11,
      "name": "Rock_Stone"
    },
    {
      "x": -6,
      "y": -5,
      "z": -11,
      "name": "Rock_Stone"
    },
    {
      "x": -6,
      "y": -4,
      "z": -11,
      "name": "Rock_Stone"
    },
    {
      "x": -6,
      "y": -3,
      "z": -11,
      "name": "Rock_Stone"
    },
    {
      "x": -6,
      "y": -2,
      "z": -11,
      "name": "Rock_Stone"
    },
    {
      "x": -6,
      "y": -1,
      "z": -11,
      "name": "Rock_Stone"
    },
    {
      "x": -6,
      "y": 0,
      "z": -11,
      "name": "Rock_Stone"
    },
    {
      "x": -6,
      "y": 1,
      "z": -11,
      "name": "Rock_Stone"
    },
    {
      "x": -6,
      "y": 2,
      "z": -11,
      "name": "Rock_Stone"
    },
    {
      "x": -6,
      "y": 3,
      "z": -11,
      "name": "Rock_Stone"
    },
    {
      "x": -6,
      "y": 4,
      "z": -11,
      "name": "Rock_Stone"
    },
    {
      "x": -6,
      "y": 5,
      "z": -11,
      "name": "Rock_Stone"
    },
    {
      "x": -6,
      "y": 6,
      "z": -11,
      "name": "Rock_Stone"
    },
    {
      "x": -6,
      "y": 7,
      "z": -11,
      "name": "Rock_Stone"
    },
    {
      "x": -6,
      "y": 8,
      "z": -11,
      "name": "Rock_Stone"
    },
    {
      "x": -6,
      "y": 9,
      "z": -11,
      "name": "Rock_Stone"
    },
    {
      "x": -6,
      "y": 10,
      "z": -11,
      "name": "Rock_Stone"
    },
    {
      "x": -6,
      "y": -7,
      "z": -10,
      "name": "Rock_Stone"
    },
    {
      "x": -6,
      "y": -6,
      "z": -10,
      "name": "Rock_Stone"
    },
    {
      "x": -6,
      "y": -5,
      "z": -10,
      "name": "Rock_Stone"
    },
    {
      "x": -6,
      "y": -4,
      "z": -10,
      "name": "Rock_Stone"
    },
    {
      "x": -6,
      "y": -3,
      "z": -10,
      "name": "Rock_Stone"
    },
    {
      "x": -6,
      "y": -2,
      "z": -10,
      "name": "Rock_Stone"
    },
    {
      "x": -6,
      "y": -1,
      "z": -10,
      "name": "Rock_Stone"
    },
    {
      "x": -6,
      "y": 0,
      "z": -10,
      "name": "Rock_Stone"
    },
    {
      "x": -6,
      "y": 1,
      "z": -10,
      "name": "Rock_Stone"
    },
    {
      "x": -6,
      "y": 2,
      "z": -10,
      "name": "Rock_Stone"
    },
    {
      "x": -6,
      "y": 3,
      "z": -10,
      "name": "Rock_Stone"
    },
    {
      "x": -6,
      "y": 4,
      "z": -10,
      "name": "Rock_Stone"
    },
    {
      "x": -6,
      "y": 5,
      "z": -10,
      "name": "Rock_Stone"
    },
    {
      "x": -6,
      "y": 6,
      "z": -10,
      "name": "Rock_Stone"
    },
    {
      "x": -6,
      "y": 7,
      "z": -10,
      "name": "Rock_Stone"
    },
    {
      "x": -6,
      "y": 8,
      "z": -10,
      "name": "Rock_Stone"
    },
    {
      "x": -6,
      "y": 9,
      "z": -10,
      "name": "Rock_Stone"
    },
    {
      "x": -6,
      "y": 10,
      "z": -10,
      "name": "Rock_Stone"
    },
    {
      "x": -6,
      "y": -7,
      "z": -9,
      "name": "Rock_Stone"
    },
    {
      "x": -6,
      "y": -6,
      "z": -9,
      "name": "Rock_Stone"
    },
    {
      "x": -6,
      "y": -5,
      "z": -9,
      "name": "Rock_Stone"
    },
    {
      "x": -6,
      "y": -4,
      "z": -9,
      "name": "Rock_Stone"
    },
    {
      "x": -6,
      "y": -3,
      "z": -9,
      "name": "Rock_Stone"
    },
    {
      "x": -6,
      "y": -2,
      "z": -9,
      "name": "Rock_Stone"
    },
    {
      "x": -6,
      "y": -1,
      "z": -9,
      "name": "Rock_Stone"
    },
    {
      "x": -6,
      "y": 0,
      "z": -9,
      "name": "Rock_Stone"
    },
    {
      "x": -6,
      "y": 1,
      "z": -9,
      "name": "Rock_Stone"
    },
    {
      "x": -6,
      "y": 2,
      "z": -9,
      "name": "Rock_Stone"
    },
    {
      "x": -6,
      "y": 3,
      "z": -9,
      "name": "Rock_Stone"
    },
    {
      "x": -6,
      "y": 4,
      "z": -9,
      "name": "Rock_Stone"
    },
    {
      "x": -6,
      "y": 5,
      "z": -9,
      "name": "Rock_Stone"
    },
    {
      "x": -6,
      "y": 6,
      "z": -9,
      "name": "Rock_Stone"
    },
    {
      "x": -6,
      "y": 7,
      "z": -9,
      "name": "Rock_Stone"
    },
    {
      "x": -6,
      "y": 8,
      "z": -9,
      "name": "Rock_Stone"
    },
    {
      "x": -6,
      "y": 9,
      "z": -9,
      "name": "Rock_Stone"
    },
    {
      "x": -6,
      "y": 10,
      "z": -9,
      "name": "Rock_Stone"
    },
    {
      "x": -6,
      "y": -7,
      "z": -8,
      "name": "Rock_Stone"
    },
    {
      "x": -6,
      "y": -6,
      "z": -8,
      "name": "Rock_Stone"
    },
    {
      "x": -6,
      "y": -5,
      "z": -8,
      "name": "Rock_Stone"
    },
    {
      "x": -6,
      "y": -4,
      "z": -8,
      "name": "Rock_Stone"
    },
    {
      "x": -6,
      "y": -3,
      "z": -8,
      "name": "Rock_Stone"
    },
    {
      "x": -6,
      "y": -2,
      "z": -8,
      "name": "Rock_Stone"
    },
    {
      "x": -6,
      "y": -1,
      "z": -8,
      "name": "Rock_Stone"
    },
    {
      "x": -6,
      "y": 0,
      "z": -8,
      "name": "Rock_Stone"
    },
    {
      "x": -6,
      "y": 1,
      "z": -8,
      "name": "Rock_Stone"
    },
    {
      "x": -6,
      "y": 2,
      "z": -8,
      "name": "Rock_Stone"
    },
    {
      "x": -6,
      "y": 3,
      "z": -8,
      "name": "Rock_Stone"
    },
    {
      "x": -6,
      "y": 4,
      "z": -8,
      "name": "Rock_Stone"
    },
    {
      "x": -6,
      "y": 5,
      "z": -8,
      "name": "Rock_Stone"
    },
    {
      "x": -6,
      "y": 6,
      "z": -8,
      "name": "Rock_Stone"
    },
    {
      "x": -6,
      "y": 7,
      "z": -8,
      "name": "Rock_Stone"
    },
    {
      "x": -6,
      "y": 8,
      "z": -8,
      "name": "Rock_Stone"
    },
    {
      "x": -6,
      "y": 9,
      "z": -8,
      "name": "Rock_Stone"
    },
    {
      "x": -6,
      "y": 10,
      "z": -8,
      "name": "Rock_Stone"
    },
    {
      "x": -6,
      "y": -7,
      "z": -7,
      "name": "Rock_Stone"
    },
    {
      "x": -6,
      "y": -6,
      "z": -7,
      "name": "Rock_Stone"
    },
    {
      "x": -6,
      "y": -5,
      "z": -7,
      "name": "Rock_Stone"
    },
    {
      "x": -6,
      "y": -4,
      "z": -7,
      "name": "Rock_Stone"
    },
    {
      "x": -6,
      "y": -3,
      "z": -7,
      "name": "Rock_Stone"
    },
    {
      "x": -6,
      "y": -2,
      "z": -7,
      "name": "Rock_Stone"
    },
    {
      "x": -6,
      "y": -1,
      "z": -7,
      "name": "Rock_Stone"
    },
    {
      "x": -6,
      "y": 0,
      "z": -7,
      "name": "Rock_Stone"
    },
    {
      "x": -6,
      "y": 1,
      "z": -7,
      "name": "Rock_Stone"
    },
    {
      "x": -6,
      "y": 2,
      "z": -7,
      "name": "Rock_Stone"
    },
    {
      "x": -6,
      "y": 3,
      "z": -7,
      "name": "Rock_Stone"
    },
    {
      "x": -6,
      "y": 4,
      "z": -7,
      "name": "Rock_Stone"
    },
    {
      "x": -6,
      "y": 5,
      "z": -7,
      "name": "Rock_Stone"
    },
    {
      "x": -6,
      "y": 6,
      "z": -7,
      "name": "Rock_Stone"
    },
    {
      "x": -6,
      "y": 7,
      "z": -7,
      "name": "Rock_Stone"
    },
    {
      "x": -6,
      "y": 8,
      "z": -7,
      "name": "Rock_Stone"
    },
    {
      "x": -6,
      "y": 9,
      "z": -7,
      "name": "Rock_Stone"
    },
    {
      "x": -6,
      "y": 10,
      "z": -7,
      "name": "Rock_Stone"
    },
    {
      "x": -6,
      "y": -7,
      "z": -6,
      "name": "Rock_Stone"
    },
    {
      "x": -6,
      "y": -6,
      "z": -6,
      "name": "Rock_Stone"
    },
    {
      "x": -6,
      "y": -5,
      "z": -6,
      "name": "Rock_Stone"
    },
    {
      "x": -6,
      "y": -4,
      "z": -6,
      "name": "Rock_Stone"
    },
    {
      "x": -6,
      "y": -3,
      "z": -6,
      "name": "Rock_Stone"
    },
    {
      "x": -6,
      "y": -2,
      "z": -6,
      "name": "Rock_Stone"
    },
    {
      "x": -6,
      "y": -1,
      "z": -6,
      "name": "Rock_Stone"
    },
    {
      "x": -6,
      "y": 0,
      "z": -6,
      "name": "Rock_Stone_Brick"
    },
    {
      "x": -6,
      "y": 1,
      "z": -6,
      "name": "Rock_Stone_Brick"
    },
    {
      "x": -6,
      "y": 2,
      "z": -6,
      "name": "Rock_Stone_Brick"
    },
    {
      "x": -6,
      "y": 3,
      "z": -6,
      "name": "Rock_Stone"
    },
    {
      "x": -6,
      "y": 4,
      "z": -6,
      "name": "Rock_Stone"
    },
    {
      "x": -6,
      "y": 5,
      "z": -6,
      "name": "Rock_Stone"
    },
    {
      "x": -6,
      "y": 6,
      "z": -6,
      "name": "Rock_Stone"
    },
    {
      "x": -6,
      "y": 7,
      "z": -6,
      "name": "Rock_Stone"
    },
    {
      "x": -6,
      "y": 8,
      "z": -6,
      "name": "Rock_Stone"
    },
    {
      "x": -6,
      "y": 9,
      "z": -6,
      "name": "Rock_Stone"
    },
    {
      "x": -6,
      "y": 10,
      "z": -6,
      "name": "Rock_Stone"
    },
    {
      "x": -6,
      "y": -7,
      "z": -5,
      "name": "Rock_Stone"
    },
    {
      "x": -6,
      "y": -6,
      "z": -5,
      "name": "Rock_Stone"
    },
    {
      "x": -6,
      "y": -5,
      "z": -5,
      "name": "Rock_Stone"
    },
    {
      "x": -6,
      "y": -4,
      "z": -5,
      "name": "Rock_Stone"
    },
    {
      "x": -6,
      "y": -3,
      "z": -5,
      "name": "Rock_Stone"
    },
    {
      "x": -6,
      "y": -2,
      "z": -5,
      "name": "Rock_Stone"
    },
    {
      "x": -6,
      "y": -1,
      "z": -5,
      "name": "Rock_Stone"
    },
    {
      "x": -6,
      "y": 0,
      "z": -5,
      "name": "Rock_Stone"
    },
    {
      "x": -6,
      "y": 1,
      "z": -5,
      "name": "Rock_Stone"
    },
    {
      "x": -6,
      "y": 2,
      "z": -5,
      "name": "Rock_Stone"
    },
    {
      "x": -6,
      "y": 3,
      "z": -5,
      "name": "Rock_Stone"
    },
    {
      "x": -6,
      "y": 4,
      "z": -5,
      "name": "Rock_Stone"
    },
    {
      "x": -6,
      "y": 5,
      "z": -5,
      "name": "Rock_Stone"
    },
    {
      "x": -6,
      "y": 6,
      "z": -5,
      "name": "Rock_Stone"
    },
    {
      "x": -6,
      "y": 7,
      "z": -5,
      "name": "Rock_Stone"
    },
    {
      "x": -6,
      "y": 8,
      "z": -5,
      "name": "Rock_Stone"
    },
    {
      "x": -6,
      "y": 9,
      "z": -5,
      "name": "Rock_Stone"
    },
    {
      "x": -6,
      "y": 10,
      "z": -5,
      "name": "Rock_Stone"
    },
    {
      "x": -6,
      "y": -7,
      "z": -4,
      "name": "Rock_Stone"
    },
    {
      "x": -6,
      "y": -6,
      "z": -4,
      "name": "Rock_Stone"
    },
    {
      "x": -6,
      "y": -5,
      "z": -4,
      "name": "Rock_Stone"
    },
    {
      "x": -6,
      "y": -4,
      "z": -4,
      "name": "Rock_Stone"
    },
    {
      "x": -6,
      "y": -3,
      "z": -4,
      "name": "Rock_Stone"
    },
    {
      "x": -6,
      "y": -2,
      "z": -4,
      "name": "Rock_Stone"
    },
    {
      "x": -6,
      "y": -1,
      "z": -4,
      "name": "Rock_Stone"
    },
    {
      "x": -6,
      "y": 0,
      "z": -4,
      "name": "Rock_Stone"
    },
    {
      "x": -6,
      "y": 1,
      "z": -4,
      "name": "Rock_Stone"
    },
    {
      "x": -6,
      "y": 2,
      "z": -4,
      "name": "Rock_Stone"
    },
    {
      "x": -6,
      "y": 3,
      "z": -4,
      "name": "Rock_Stone"
    },
    {
      "x": -6,
      "y": 4,
      "z": -4,
      "name": "Rock_Stone"
    },
    {
      "x": -6,
      "y": 5,
      "z": -4,
      "name": "Rock_Stone"
    },
    {
      "x": -6,
      "y": 6,
      "z": -4,
      "name": "Rock_Stone"
    },
    {
      "x": -6,
      "y": 7,
      "z": -4,
      "name": "Rock_Stone"
    },
    {
      "x": -6,
      "y": 8,
      "z": -4,
      "name": "Rock_Stone"
    },
    {
      "x": -6,
      "y": 9,
      "z": -4,
      "name": "Rock_Stone"
    },
    {
      "x": -6,
      "y": 10,
      "z": -4,
      "name": "Rock_Stone"
    },
    {
      "x": -6,
      "y": -7,
      "z": -3,
      "name": "Rock_Stone"
    },
    {
      "x": -6,
      "y": -6,
      "z": -3,
      "name": "Rock_Stone"
    },
    {
      "x": -6,
      "y": -5,
      "z": -3,
      "name": "Rock_Stone"
    },
    {
      "x": -6,
      "y": -4,
      "z": -3,
      "name": "Rock_Stone"
    },
    {
      "x": -6,
      "y": -3,
      "z": -3,
      "name": "Rock_Stone"
    },
    {
      "x": -6,
      "y": -2,
      "z": -3,
      "name": "Rock_Stone"
    },
    {
      "x": -6,
      "y": -1,
      "z": -3,
      "name": "Rock_Stone"
    },
    {
      "x": -6,
      "y": 0,
      "z": -3,
      "name": "Rock_Stone"
    },
    {
      "x": -6,
      "y": 1,
      "z": -3,
      "name": "Rock_Stone"
    },
    {
      "x": -6,
      "y": 2,
      "z": -3,
      "name": "Rock_Stone"
    },
    {
      "x": -6,
      "y": 3,
      "z": -3,
      "name": "Rock_Stone"
    },
    {
      "x": -6,
      "y": 4,
      "z": -3,
      "name": "Rock_Stone"
    },
    {
      "x": -6,
      "y": 5,
      "z": -3,
      "name": "Rock_Stone"
    },
    {
      "x": -6,
      "y": 6,
      "z": -3,
      "name": "Rock_Stone"
    },
    {
      "x": -6,
      "y": 7,
      "z": -3,
      "name": "Rock_Stone"
    },
    {
      "x": -6,
      "y": 8,
      "z": -3,
      "name": "Rock_Stone"
    },
    {
      "x": -6,
      "y": 9,
      "z": -3,
      "name": "Rock_Stone"
    },
    {
      "x": -6,
      "y": 10,
      "z": -3,
      "name": "Rock_Stone"
    },
    {
      "x": -6,
      "y": -7,
      "z": -2,
      "name": "Rock_Stone"
    },
    {
      "x": -6,
      "y": -6,
      "z": -2,
      "name": "Rock_Stone"
    },
    {
      "x": -6,
      "y": -5,
      "z": -2,
      "name": "Rock_Stone"
    },
    {
      "x": -6,
      "y": -4,
      "z": -2,
      "name": "Rock_Stone"
    },
    {
      "x": -6,
      "y": -3,
      "z": -2,
      "name": "Rock_Stone"
    },
    {
      "x": -6,
      "y": -2,
      "z": -2,
      "name": "Rock_Stone"
    },
    {
      "x": -6,
      "y": -1,
      "z": -2,
      "name": "Rock_Stone"
    },
    {
      "x": -6,
      "y": 0,
      "z": -2,
      "name": "Rock_Stone"
    },
    {
      "x": -6,
      "y": 1,
      "z": -2,
      "name": "Rock_Stone"
    },
    {
      "x": -6,
      "y": 2,
      "z": -2,
      "name": "Rock_Stone"
    },
    {
      "x": -6,
      "y": 3,
      "z": -2,
      "name": "Rock_Stone"
    },
    {
      "x": -6,
      "y": 4,
      "z": -2,
      "name": "Rock_Stone"
    },
    {
      "x": -6,
      "y": 5,
      "z": -2,
      "name": "Rock_Stone"
    },
    {
      "x": -6,
      "y": 6,
      "z": -2,
      "name": "Rock_Stone"
    },
    {
      "x": -6,
      "y": 7,
      "z": -2,
      "name": "Rock_Stone"
    },
    {
      "x": -6,
      "y": 8,
      "z": -2,
      "name": "Rock_Stone"
    },
    {
      "x": -6,
      "y": 9,
      "z": -2,
      "name": "Rock_Stone"
    },
    {
      "x": -6,
      "y": 10,
      "z": -2,
      "name": "Rock_Stone"
    },
    {
      "x": -6,
      "y": -7,
      "z": -1,
      "name": "Rock_Stone"
    },
    {
      "x": -6,
      "y": -6,
      "z": -1,
      "name": "Rock_Stone"
    },
    {
      "x": -6,
      "y": -5,
      "z": -1,
      "name": "Rock_Stone"
    },
    {
      "x": -6,
      "y": -4,
      "z": -1,
      "name": "Rock_Stone"
    },
    {
      "x": -6,
      "y": -3,
      "z": -1,
      "name": "Rock_Stone"
    },
    {
      "x": -6,
      "y": -2,
      "z": -1,
      "name": "Rock_Stone"
    },
    {
      "x": -6,
      "y": -1,
      "z": -1,
      "name": "Rock_Stone"
    },
    {
      "x": -6,
      "y": 0,
      "z": -1,
      "name": "Rock_Stone"
    },
    {
      "x": -6,
      "y": 1,
      "z": -1,
      "name": "Rock_Stone"
    },
    {
      "x": -6,
      "y": 2,
      "z": -1,
      "name": "Rock_Stone"
    },
    {
      "x": -6,
      "y": 3,
      "z": -1,
      "name": "Rock_Stone"
    },
    {
      "x": -6,
      "y": 4,
      "z": -1,
      "name": "Rock_Stone"
    },
    {
      "x": -6,
      "y": 5,
      "z": -1,
      "name": "Rock_Stone"
    },
    {
      "x": -6,
      "y": 6,
      "z": -1,
      "name": "Rock_Stone"
    },
    {
      "x": -6,
      "y": 7,
      "z": -1,
      "name": "Rock_Stone"
    },
    {
      "x": -6,
      "y": 8,
      "z": -1,
      "name": "Rock_Stone"
    },
    {
      "x": -6,
      "y": 9,
      "z": -1,
      "name": "Rock_Stone"
    },
    {
      "x": -6,
      "y": 10,
      "z": -1,
      "name": "Rock_Stone"
    },
    {
      "x": -6,
      "y": -7,
      "z": 0,
      "name": "Rock_Stone"
    },
    {
      "x": -6,
      "y": -6,
      "z": 0,
      "name": "Rock_Stone"
    },
    {
      "x": -6,
      "y": -5,
      "z": 0,
      "name": "Rock_Stone"
    },
    {
      "x": -6,
      "y": -4,
      "z": 0,
      "name": "Rock_Stone"
    },
    {
      "x": -6,
      "y": -3,
      "z": 0,
      "name": "Rock_Stone"
    },
    {
      "x": -6,
      "y": -2,
      "z": 0,
      "name": "Rock_Stone"
    },
    {
      "x": -6,
      "y": -1,
      "z": 0,
      "name": "Rock_Stone"
    },
    {
      "x": -6,
      "y": 0,
      "z": 0,
      "name": "Rock_Stone"
    },
    {
      "x": -6,
      "y": 1,
      "z": 0,
      "name": "Rock_Stone"
    },
    {
      "x": -6,
      "y": 2,
      "z": 0,
      "name": "Rock_Stone"
    },
    {
      "x": -6,
      "y": 3,
      "z": 0,
      "name": "Rock_Stone"
    },
    {
      "x": -6,
      "y": 4,
      "z": 0,
      "name": "Rock_Stone"
    },
    {
      "x": -6,
      "y": 5,
      "z": 0,
      "name": "Rock_Stone"
    },
    {
      "x": -6,
      "y": 6,
      "z": 0,
      "name": "Rock_Stone"
    },
    {
      "x": -6,
      "y": 7,
      "z": 0,
      "name": "Rock_Stone"
    },
    {
      "x": -6,
      "y": 8,
      "z": 0,
      "name": "Rock_Stone"
    },
    {
      "x": -6,
      "y": 9,
      "z": 0,
      "name": "Rock_Stone"
    },
    {
      "x": -6,
      "y": 10,
      "z": 0,
      "name": "Rock_Stone"
    },
    {
      "x": -5,
      "y": -7,
      "z": -12,
      "name": "Rock_Stone"
    },
    {
      "x": -5,
      "y": -6,
      "z": -12,
      "name": "Rock_Stone"
    },
    {
      "x": -5,
      "y": -5,
      "z": -12,
      "name": "Rock_Stone"
    },
    {
      "x": -5,
      "y": -4,
      "z": -12,
      "name": "Rock_Stone"
    },
    {
      "x": -5,
      "y": -3,
      "z": -12,
      "name": "Rock_Stone"
    },
    {
      "x": -5,
      "y": -2,
      "z": -12,
      "name": "Rock_Stone"
    },
    {
      "x": -5,
      "y": -1,
      "z": -12,
      "name": "Rock_Stone"
    },
    {
      "x": -5,
      "y": 0,
      "z": -12,
      "name": "Rock_Stone"
    },
    {
      "x": -5,
      "y": 1,
      "z": -12,
      "name": "Rock_Stone"
    },
    {
      "x": -5,
      "y": 2,
      "z": -12,
      "name": "Rock_Stone"
    },
    {
      "x": -5,
      "y": 3,
      "z": -12,
      "name": "Rock_Stone"
    },
    {
      "x": -5,
      "y": 4,
      "z": -12,
      "name": "Rock_Stone"
    },
    {
      "x": -5,
      "y": 5,
      "z": -12,
      "name": "Rock_Stone"
    },
    {
      "x": -5,
      "y": 6,
      "z": -12,
      "name": "Rock_Stone"
    },
    {
      "x": -5,
      "y": 7,
      "z": -12,
      "name": "Rock_Stone"
    },
    {
      "x": -5,
      "y": 8,
      "z": -12,
      "name": "Rock_Stone"
    },
    {
      "x": -5,
      "y": 9,
      "z": -12,
      "name": "Rock_Stone"
    },
    {
      "x": -5,
      "y": 10,
      "z": -12,
      "name": "Rock_Stone"
    },
    {
      "x": -5,
      "y": -7,
      "z": -11,
      "name": "Rock_Stone"
    },
    {
      "x": -5,
      "y": -6,
      "z": -11,
      "name": "Rock_Stone"
    },
    {
      "x": -5,
      "y": -5,
      "z": -11,
      "name": "Rock_Stone"
    },
    {
      "x": -5,
      "y": -4,
      "z": -11,
      "name": "Rock_Stone"
    },
    {
      "x": -5,
      "y": -3,
      "z": -11,
      "name": "Rock_Stone"
    },
    {
      "x": -5,
      "y": -2,
      "z": -11,
      "name": "Rock_Stone"
    },
    {
      "x": -5,
      "y": -1,
      "z": -11,
      "name": "Rock_Stone"
    },
    {
      "x": -5,
      "y": 0,
      "z": -11,
      "name": "Rock_Stone"
    },
    {
      "x": -5,
      "y": 1,
      "z": -11,
      "name": "Rock_Stone"
    },
    {
      "x": -5,
      "y": 2,
      "z": -11,
      "name": "Rock_Stone"
    },
    {
      "x": -5,
      "y": 3,
      "z": -11,
      "name": "Rock_Stone"
    },
    {
      "x": -5,
      "y": 4,
      "z": -11,
      "name": "Rock_Stone"
    },
    {
      "x": -5,
      "y": 5,
      "z": -11,
      "name": "Rock_Stone"
    },
    {
      "x": -5,
      "y": 6,
      "z": -11,
      "name": "Rock_Stone"
    },
    {
      "x": -5,
      "y": 7,
      "z": -11,
      "name": "Rock_Stone"
    },
    {
      "x": -5,
      "y": 8,
      "z": -11,
      "name": "Rock_Stone"
    },
    {
      "x": -5,
      "y": 9,
      "z": -11,
      "name": "Rock_Stone"
    },
    {
      "x": -5,
      "y": 10,
      "z": -11,
      "name": "Rock_Stone"
    },
    {
      "x": -5,
      "y": -7,
      "z": -10,
      "name": "Rock_Stone"
    },
    {
      "x": -5,
      "y": -6,
      "z": -10,
      "name": "Rock_Stone"
    },
    {
      "x": -5,
      "y": -5,
      "z": -10,
      "name": "Rock_Stone"
    },
    {
      "x": -5,
      "y": -4,
      "z": -10,
      "name": "Rock_Stone"
    },
    {
      "x": -5,
      "y": -3,
      "z": -10,
      "name": "Rock_Stone"
    },
    {
      "x": -5,
      "y": -2,
      "z": -10,
      "name": "Rock_Stone"
    },
    {
      "x": -5,
      "y": -1,
      "z": -10,
      "name": "Rock_Stone"
    },
    {
      "x": -5,
      "y": 0,
      "z": -10,
      "name": "Rock_Stone"
    },
    {
      "x": -5,
      "y": 1,
      "z": -10,
      "name": "Rock_Stone"
    },
    {
      "x": -5,
      "y": 2,
      "z": -10,
      "name": "Rock_Stone"
    },
    {
      "x": -5,
      "y": 3,
      "z": -10,
      "name": "Rock_Stone"
    },
    {
      "x": -5,
      "y": 4,
      "z": -10,
      "name": "Rock_Stone"
    },
    {
      "x": -5,
      "y": 5,
      "z": -10,
      "name": "Rock_Stone"
    },
    {
      "x": -5,
      "y": 6,
      "z": -10,
      "name": "Rock_Stone"
    },
    {
      "x": -5,
      "y": 7,
      "z": -10,
      "name": "Rock_Stone"
    },
    {
      "x": -5,
      "y": 8,
      "z": -10,
      "name": "Rock_Stone"
    },
    {
      "x": -5,
      "y": 9,
      "z": -10,
      "name": "Rock_Stone"
    },
    {
      "x": -5,
      "y": 10,
      "z": -10,
      "name": "Rock_Stone"
    },
    {
      "x": -5,
      "y": -7,
      "z": -9,
      "name": "Rock_Stone"
    },
    {
      "x": -5,
      "y": -6,
      "z": -9,
      "name": "Rock_Stone"
    },
    {
      "x": -5,
      "y": -5,
      "z": -9,
      "name": "Rock_Stone"
    },
    {
      "x": -5,
      "y": -4,
      "z": -9,
      "name": "Rock_Stone"
    },
    {
      "x": -5,
      "y": -3,
      "z": -9,
      "name": "Rock_Stone"
    },
    {
      "x": -5,
      "y": -2,
      "z": -9,
      "name": "Rock_Stone"
    },
    {
      "x": -5,
      "y": -1,
      "z": -9,
      "name": "Rock_Stone"
    },
    {
      "x": -5,
      "y": 0,
      "z": -9,
      "name": "Empty"
    },
    {
      "x": -5,
      "y": 1,
      "z": -9,
      "name": "Empty"
    },
    {
      "x": -5,
      "y": 2,
      "z": -9,
      "name": "Empty"
    },
    {
      "x": -5,
      "y": 3,
      "z": -9,
      "name": "Empty"
    },
    {
      "x": -5,
      "y": 4,
      "z": -9,
      "name": "Rock_Stone"
    },
    {
      "x": -5,
      "y": 5,
      "z": -9,
      "name": "Rock_Stone"
    },
    {
      "x": -5,
      "y": 6,
      "z": -9,
      "name": "Rock_Stone"
    },
    {
      "x": -5,
      "y": 7,
      "z": -9,
      "name": "Rock_Stone"
    },
    {
      "x": -5,
      "y": 8,
      "z": -9,
      "name": "Rock_Stone"
    },
    {
      "x": -5,
      "y": 9,
      "z": -9,
      "name": "Rock_Stone"
    },
    {
      "x": -5,
      "y": 10,
      "z": -9,
      "name": "Rock_Stone"
    },
    {
      "x": -5,
      "y": -7,
      "z": -8,
      "name": "Rock_Stone"
    },
    {
      "x": -5,
      "y": -6,
      "z": -8,
      "name": "Rock_Stone"
    },
    {
      "x": -5,
      "y": -5,
      "z": -8,
      "name": "Rock_Stone"
    },
    {
      "x": -5,
      "y": -4,
      "z": -8,
      "name": "Rock_Stone"
    },
    {
      "x": -5,
      "y": -3,
      "z": -8,
      "name": "Rock_Stone"
    },
    {
      "x": -5,
      "y": -2,
      "z": -8,
      "name": "Rock_Stone"
    },
    {
      "x": -5,
      "y": -1,
      "z": -8,
      "name": "Rock_Stone"
    },
    {
      "x": -5,
      "y": 0,
      "z": -8,
      "name": "Rock_Stone_Brick_Pillar_Middle"
    },
    {
      "x": -5,
      "y": 1,
      "z": -8,
      "name": "Rock_Stone_Brick_Smooth"
    },
    {
      "x": -5,
      "y": 2,
      "z": -8,
      "name": "Rock_Stone_Brick_Pillar_Middle"
    },
    {
      "x": -5,
      "y": 3,
      "z": -8,
      "name": "Rock_Stone_Brick_Smooth"
    },
    {
      "x": -5,
      "y": 4,
      "z": -8,
      "name": "Rock_Stone"
    },
    {
      "x": -5,
      "y": 5,
      "z": -8,
      "name": "Rock_Stone"
    },
    {
      "x": -5,
      "y": 6,
      "z": -8,
      "name": "Rock_Stone"
    },
    {
      "x": -5,
      "y": 7,
      "z": -8,
      "name": "Rock_Stone"
    },
    {
      "x": -5,
      "y": 8,
      "z": -8,
      "name": "Rock_Stone"
    },
    {
      "x": -5,
      "y": 9,
      "z": -8,
      "name": "Rock_Stone"
    },
    {
      "x": -5,
      "y": 10,
      "z": -8,
      "name": "Rock_Stone"
    },
    {
      "x": -5,
      "y": -7,
      "z": -7,
      "name": "Rock_Stone"
    },
    {
      "x": -5,
      "y": -6,
      "z": -7,
      "name": "Rock_Stone"
    },
    {
      "x": -5,
      "y": -5,
      "z": -7,
      "name": "Rock_Stone"
    },
    {
      "x": -5,
      "y": -4,
      "z": -7,
      "name": "Rock_Stone"
    },
    {
      "x": -5,
      "y": -3,
      "z": -7,
      "name": "Rock_Stone"
    },
    {
      "x": -5,
      "y": -2,
      "z": -7,
      "name": "Rock_Stone"
    },
    {
      "x": -5,
      "y": -1,
      "z": -7,
      "name": "Rock_Stone"
    },
    {
      "x": -5,
      "y": 0,
      "z": -7,
      "name": "Furniture_Temple_Dark_Wardrobe",
      "rotation": 1
    },
    {
      "x": -5,
      "y": 1,
      "z": -7,
      "name": "Furniture_Temple_Dark_Wardrobe",
      "filler": 1024,
      "rotation": 1
    },
    {
      "x": -5,
      "y": 2,
      "z": -7,
      "name": "Empty"
    },
    {
      "x": -5,
      "y": 3,
      "z": -7,
      "name": "Rock_Stone_Brick_Smooth_Half",
      "rotation": 8
    },
    {
      "x": -5,
      "y": 4,
      "z": -7,
      "name": "Rock_Stone"
    },
    {
      "x": -5,
      "y": 5,
      "z": -7,
      "name": "Rock_Stone"
    },
    {
      "x": -5,
      "y": 6,
      "z": -7,
      "name": "Rock_Stone"
    },
    {
      "x": -5,
      "y": 7,
      "z": -7,
      "name": "Rock_Stone"
    },
    {
      "x": -5,
      "y": 8,
      "z": -7,
      "name": "Rock_Stone"
    },
    {
      "x": -5,
      "y": 9,
      "z": -7,
      "name": "Rock_Stone"
    },
    {
      "x": -5,
      "y": 10,
      "z": -7,
      "name": "Rock_Stone"
    },
    {
      "x": -5,
      "y": -7,
      "z": -6,
      "name": "Rock_Stone"
    },
    {
      "x": -5,
      "y": -6,
      "z": -6,
      "name": "Rock_Stone"
    },
    {
      "x": -5,
      "y": -5,
      "z": -6,
      "name": "Rock_Stone"
    },
    {
      "x": -5,
      "y": -4,
      "z": -6,
      "name": "Rock_Stone"
    },
    {
      "x": -5,
      "y": -3,
      "z": -6,
      "name": "Rock_Stone"
    },
    {
      "x": -5,
      "y": -2,
      "z": -6,
      "name": "Rock_Stone"
    },
    {
      "x": -5,
      "y": -1,
      "z": -6,
      "name": "Rock_Stone"
    },
    {
      "x": -5,
      "y": 0,
      "z": -6,
      "name": "Furniture_Temple_Dark_Wardrobe",
      "filler": 32,
      "rotation": 1
    },
    {
      "x": -5,
      "y": 1,
      "z": -6,
      "name": "Furniture_Temple_Dark_Wardrobe",
      "filler": 1056,
      "rotation": 1
    },
    {
      "x": -5,
      "y": 2,
      "z": -6,
      "name": "Empty"
    },
    {
      "x": -5,
      "y": 3,
      "z": -6,
      "name": "Rock_Stone_Brick_Smooth_Half",
      "rotation": 8
    },
    {
      "x": -5,
      "y": 4,
      "z": -6,
      "name": "Rock_Stone"
    },
    {
      "x": -5,
      "y": 5,
      "z": -6,
      "name": "Rock_Stone"
    },
    {
      "x": -5,
      "y": 6,
      "z": -6,
      "name": "Rock_Stone"
    },
    {
      "x": -5,
      "y": 7,
      "z": -6,
      "name": "Rock_Stone"
    },
    {
      "x": -5,
      "y": 8,
      "z": -6,
      "name": "Rock_Stone"
    },
    {
      "x": -5,
      "y": 9,
      "z": -6,
      "name": "Rock_Stone"
    },
    {
      "x": -5,
      "y": 10,
      "z": -6,
      "name": "Rock_Stone"
    },
    {
      "x": -5,
      "y": -7,
      "z": -5,
      "name": "Rock_Stone"
    },
    {
      "x": -5,
      "y": -6,
      "z": -5,
      "name": "Rock_Stone"
    },
    {
      "x": -5,
      "y": -5,
      "z": -5,
      "name": "Rock_Stone"
    },
    {
      "x": -5,
      "y": -4,
      "z": -5,
      "name": "Rock_Stone"
    },
    {
      "x": -5,
      "y": -3,
      "z": -5,
      "name": "Rock_Stone"
    },
    {
      "x": -5,
      "y": -2,
      "z": -5,
      "name": "Rock_Stone"
    },
    {
      "x": -5,
      "y": -1,
      "z": -5,
      "name": "Rock_Stone"
    },
    {
      "x": -5,
      "y": 0,
      "z": -5,
      "name": "Rock_Stone_Brick_Pillar_Middle"
    },
    {
      "x": -5,
      "y": 1,
      "z": -5,
      "name": "Rock_Stone_Brick_Smooth"
    },
    {
      "x": -5,
      "y": 2,
      "z": -5,
      "name": "Rock_Stone_Brick_Pillar_Middle"
    },
    {
      "x": -5,
      "y": 3,
      "z": -5,
      "name": "Rock_Stone_Brick_Smooth"
    },
    {
      "x": -5,
      "y": 4,
      "z": -5,
      "name": "Empty"
    },
    {
      "x": -5,
      "y": 5,
      "z": -5,
      "name": "Empty"
    },
    {
      "x": -5,
      "y": 6,
      "z": -5,
      "name": "Rock_Stone"
    },
    {
      "x": -5,
      "y": 7,
      "z": -5,
      "name": "Rock_Stone"
    },
    {
      "x": -5,
      "y": 8,
      "z": -5,
      "name": "Rock_Stone"
    },
    {
      "x": -5,
      "y": 9,
      "z": -5,
      "name": "Rock_Stone"
    },
    {
      "x": -5,
      "y": 10,
      "z": -5,
      "name": "Rock_Stone"
    },
    {
      "x": -5,
      "y": -7,
      "z": -4,
      "name": "Rock_Stone"
    },
    {
      "x": -5,
      "y": -6,
      "z": -4,
      "name": "Rock_Stone"
    },
    {
      "x": -5,
      "y": -5,
      "z": -4,
      "name": "Rock_Stone"
    },
    {
      "x": -5,
      "y": -4,
      "z": -4,
      "name": "Rock_Stone"
    },
    {
      "x": -5,
      "y": -3,
      "z": -4,
      "name": "Rock_Stone"
    },
    {
      "x": -5,
      "y": -2,
      "z": -4,
      "name": "Rock_Stone"
    },
    {
      "x": -5,
      "y": -1,
      "z": -4,
      "name": "Rock_Stone"
    },
    {
      "x": -5,
      "y": 0,
      "z": -4,
      "name": "Empty"
    },
    {
      "x": -5,
      "y": 1,
      "z": -4,
      "name": "Empty"
    },
    {
      "x": -5,
      "y": 2,
      "z": -4,
      "name": "Empty"
    },
    {
      "x": -5,
      "y": 3,
      "z": -4,
      "name": "Rock_Stone"
    },
    {
      "x": -5,
      "y": 4,
      "z": -4,
      "name": "Rock_Stone"
    },
    {
      "x": -5,
      "y": 5,
      "z": -4,
      "name": "Rock_Stone"
    },
    {
      "x": -5,
      "y": 6,
      "z": -4,
      "name": "Rock_Stone"
    },
    {
      "x": -5,
      "y": 7,
      "z": -4,
      "name": "Rock_Stone"
    },
    {
      "x": -5,
      "y": 8,
      "z": -4,
      "name": "Rock_Stone"
    },
    {
      "x": -5,
      "y": 9,
      "z": -4,
      "name": "Rock_Stone"
    },
    {
      "x": -5,
      "y": 10,
      "z": -4,
      "name": "Rock_Stone"
    },
    {
      "x": -5,
      "y": -7,
      "z": -3,
      "name": "Rock_Stone"
    },
    {
      "x": -5,
      "y": -6,
      "z": -3,
      "name": "Rock_Stone"
    },
    {
      "x": -5,
      "y": -5,
      "z": -3,
      "name": "Rock_Stone"
    },
    {
      "x": -5,
      "y": -4,
      "z": -3,
      "name": "Rock_Stone"
    },
    {
      "x": -5,
      "y": -3,
      "z": -3,
      "name": "Rock_Stone"
    },
    {
      "x": -5,
      "y": -2,
      "z": -3,
      "name": "Rock_Stone"
    },
    {
      "x": -5,
      "y": -1,
      "z": -3,
      "name": "Rock_Stone"
    },
    {
      "x": -5,
      "y": 0,
      "z": -3,
      "name": "Rock_Stone"
    },
    {
      "x": -5,
      "y": 1,
      "z": -3,
      "name": "Rock_Stone"
    },
    {
      "x": -5,
      "y": 2,
      "z": -3,
      "name": "Rock_Stone"
    },
    {
      "x": -5,
      "y": 3,
      "z": -3,
      "name": "Rock_Stone"
    },
    {
      "x": -5,
      "y": 4,
      "z": -3,
      "name": "Rock_Stone"
    },
    {
      "x": -5,
      "y": 5,
      "z": -3,
      "name": "Rock_Stone"
    },
    {
      "x": -5,
      "y": 6,
      "z": -3,
      "name": "Rock_Stone"
    },
    {
      "x": -5,
      "y": 7,
      "z": -3,
      "name": "Rock_Stone"
    },
    {
      "x": -5,
      "y": 8,
      "z": -3,
      "name": "Rock_Stone"
    },
    {
      "x": -5,
      "y": 9,
      "z": -3,
      "name": "Rock_Stone"
    },
    {
      "x": -5,
      "y": 10,
      "z": -3,
      "name": "Rock_Stone"
    },
    {
      "x": -5,
      "y": -7,
      "z": -2,
      "name": "Rock_Stone"
    },
    {
      "x": -5,
      "y": -6,
      "z": -2,
      "name": "Rock_Stone"
    },
    {
      "x": -5,
      "y": -5,
      "z": -2,
      "name": "Rock_Stone"
    },
    {
      "x": -5,
      "y": -4,
      "z": -2,
      "name": "Rock_Stone"
    },
    {
      "x": -5,
      "y": -3,
      "z": -2,
      "name": "Rock_Stone"
    },
    {
      "x": -5,
      "y": -2,
      "z": -2,
      "name": "Rock_Stone"
    },
    {
      "x": -5,
      "y": -1,
      "z": -2,
      "name": "Rock_Stone"
    },
    {
      "x": -5,
      "y": 0,
      "z": -2,
      "name": "Rock_Stone"
    },
    {
      "x": -5,
      "y": 1,
      "z": -2,
      "name": "Rock_Stone"
    },
    {
      "x": -5,
      "y": 2,
      "z": -2,
      "name": "Rock_Stone"
    },
    {
      "x": -5,
      "y": 3,
      "z": -2,
      "name": "Rock_Stone"
    },
    {
      "x": -5,
      "y": 4,
      "z": -2,
      "name": "Rock_Stone"
    },
    {
      "x": -5,
      "y": 5,
      "z": -2,
      "name": "Rock_Stone"
    },
    {
      "x": -5,
      "y": 6,
      "z": -2,
      "name": "Rock_Stone"
    },
    {
      "x": -5,
      "y": 7,
      "z": -2,
      "name": "Rock_Stone"
    },
    {
      "x": -5,
      "y": 8,
      "z": -2,
      "name": "Rock_Stone"
    },
    {
      "x": -5,
      "y": 9,
      "z": -2,
      "name": "Rock_Stone"
    },
    {
      "x": -5,
      "y": 10,
      "z": -2,
      "name": "Rock_Stone"
    },
    {
      "x": -5,
      "y": -7,
      "z": -1,
      "name": "Rock_Stone"
    },
    {
      "x": -5,
      "y": -6,
      "z": -1,
      "name": "Rock_Stone"
    },
    {
      "x": -5,
      "y": -5,
      "z": -1,
      "name": "Rock_Stone"
    },
    {
      "x": -5,
      "y": -4,
      "z": -1,
      "name": "Rock_Stone"
    },
    {
      "x": -5,
      "y": -3,
      "z": -1,
      "name": "Rock_Stone"
    },
    {
      "x": -5,
      "y": -2,
      "z": -1,
      "name": "Rock_Stone"
    },
    {
      "x": -5,
      "y": -1,
      "z": -1,
      "name": "Rock_Stone"
    },
    {
      "x": -5,
      "y": 0,
      "z": -1,
      "name": "Rock_Stone"
    },
    {
      "x": -5,
      "y": 1,
      "z": -1,
      "name": "Rock_Stone"
    },
    {
      "x": -5,
      "y": 2,
      "z": -1,
      "name": "Rock_Stone"
    },
    {
      "x": -5,
      "y": 3,
      "z": -1,
      "name": "Rock_Stone"
    },
    {
      "x": -5,
      "y": 4,
      "z": -1,
      "name": "Rock_Stone"
    },
    {
      "x": -5,
      "y": 5,
      "z": -1,
      "name": "Rock_Stone"
    },
    {
      "x": -5,
      "y": 6,
      "z": -1,
      "name": "Rock_Stone"
    },
    {
      "x": -5,
      "y": 7,
      "z": -1,
      "name": "Rock_Stone"
    },
    {
      "x": -5,
      "y": 8,
      "z": -1,
      "name": "Rock_Stone"
    },
    {
      "x": -5,
      "y": 9,
      "z": -1,
      "name": "Rock_Stone"
    },
    {
      "x": -5,
      "y": 10,
      "z": -1,
      "name": "Rock_Stone"
    },
    {
      "x": -5,
      "y": -7,
      "z": 0,
      "name": "Rock_Stone"
    },
    {
      "x": -5,
      "y": -6,
      "z": 0,
      "name": "Rock_Stone"
    },
    {
      "x": -5,
      "y": -5,
      "z": 0,
      "name": "Rock_Stone"
    },
    {
      "x": -5,
      "y": -4,
      "z": 0,
      "name": "Rock_Stone"
    },
    {
      "x": -5,
      "y": -3,
      "z": 0,
      "name": "Rock_Stone"
    },
    {
      "x": -5,
      "y": -2,
      "z": 0,
      "name": "Rock_Stone"
    },
    {
      "x": -5,
      "y": -1,
      "z": 0,
      "name": "Rock_Stone"
    },
    {
      "x": -5,
      "y": 0,
      "z": 0,
      "name": "Rock_Stone"
    },
    {
      "x": -5,
      "y": 1,
      "z": 0,
      "name": "Rock_Stone"
    },
    {
      "x": -5,
      "y": 2,
      "z": 0,
      "name": "Rock_Stone"
    },
    {
      "x": -5,
      "y": 3,
      "z": 0,
      "name": "Rock_Stone"
    },
    {
      "x": -5,
      "y": 4,
      "z": 0,
      "name": "Rock_Stone"
    },
    {
      "x": -5,
      "y": 5,
      "z": 0,
      "name": "Rock_Stone"
    },
    {
      "x": -5,
      "y": 6,
      "z": 0,
      "name": "Rock_Stone"
    },
    {
      "x": -5,
      "y": 7,
      "z": 0,
      "name": "Rock_Stone"
    },
    {
      "x": -5,
      "y": 8,
      "z": 0,
      "name": "Rock_Stone"
    },
    {
      "x": -5,
      "y": 9,
      "z": 0,
      "name": "Rock_Stone"
    },
    {
      "x": -5,
      "y": 10,
      "z": 0,
      "name": "Rock_Stone"
    },
    {
      "x": -4,
      "y": -7,
      "z": -12,
      "name": "Rock_Stone"
    },
    {
      "x": -4,
      "y": -6,
      "z": -12,
      "name": "Rock_Stone"
    },
    {
      "x": -4,
      "y": -5,
      "z": -12,
      "name": "Rock_Stone"
    },
    {
      "x": -4,
      "y": -4,
      "z": -12,
      "name": "Rock_Stone"
    },
    {
      "x": -4,
      "y": -3,
      "z": -12,
      "name": "Rock_Stone"
    },
    {
      "x": -4,
      "y": -2,
      "z": -12,
      "name": "Rock_Stone"
    },
    {
      "x": -4,
      "y": -1,
      "z": -12,
      "name": "Rock_Stone"
    },
    {
      "x": -4,
      "y": 0,
      "z": -12,
      "name": "Rock_Stone"
    },
    {
      "x": -4,
      "y": 1,
      "z": -12,
      "name": "Rock_Stone"
    },
    {
      "x": -4,
      "y": 2,
      "z": -12,
      "name": "Rock_Stone"
    },
    {
      "x": -4,
      "y": 3,
      "z": -12,
      "name": "Rock_Stone"
    },
    {
      "x": -4,
      "y": 4,
      "z": -12,
      "name": "Rock_Stone"
    },
    {
      "x": -4,
      "y": 5,
      "z": -12,
      "name": "Rock_Stone"
    },
    {
      "x": -4,
      "y": 6,
      "z": -12,
      "name": "Rock_Stone"
    },
    {
      "x": -4,
      "y": 7,
      "z": -12,
      "name": "Rock_Stone"
    },
    {
      "x": -4,
      "y": 8,
      "z": -12,
      "name": "Rock_Stone"
    },
    {
      "x": -4,
      "y": 9,
      "z": -12,
      "name": "Rock_Stone"
    },
    {
      "x": -4,
      "y": 10,
      "z": -12,
      "name": "Rock_Stone"
    },
    {
      "x": -4,
      "y": -7,
      "z": -11,
      "name": "Rock_Stone"
    },
    {
      "x": -4,
      "y": -6,
      "z": -11,
      "name": "Rock_Stone"
    },
    {
      "x": -4,
      "y": -5,
      "z": -11,
      "name": "Rock_Stone"
    },
    {
      "x": -4,
      "y": -4,
      "z": -11,
      "name": "Rock_Stone"
    },
    {
      "x": -4,
      "y": -3,
      "z": -11,
      "name": "Rock_Stone"
    },
    {
      "x": -4,
      "y": -2,
      "z": -11,
      "name": "Rock_Stone"
    },
    {
      "x": -4,
      "y": -1,
      "z": -11,
      "name": "Rock_Stone"
    },
    {
      "x": -4,
      "y": 0,
      "z": -11,
      "name": "Rock_Stone"
    },
    {
      "x": -4,
      "y": 1,
      "z": -11,
      "name": "Rock_Stone"
    },
    {
      "x": -4,
      "y": 2,
      "z": -11,
      "name": "Rock_Stone"
    },
    {
      "x": -4,
      "y": 3,
      "z": -11,
      "name": "Rock_Stone"
    },
    {
      "x": -4,
      "y": 4,
      "z": -11,
      "name": "Rock_Stone"
    },
    {
      "x": -4,
      "y": 5,
      "z": -11,
      "name": "Rock_Stone"
    },
    {
      "x": -4,
      "y": 6,
      "z": -11,
      "name": "Rock_Stone"
    },
    {
      "x": -4,
      "y": 7,
      "z": -11,
      "name": "Rock_Stone"
    },
    {
      "x": -4,
      "y": 8,
      "z": -11,
      "name": "Rock_Stone"
    },
    {
      "x": -4,
      "y": 9,
      "z": -11,
      "name": "Rock_Stone"
    },
    {
      "x": -4,
      "y": 10,
      "z": -11,
      "name": "Rock_Stone"
    },
    {
      "x": -4,
      "y": -7,
      "z": -10,
      "name": "Rock_Stone"
    },
    {
      "x": -4,
      "y": -6,
      "z": -10,
      "name": "Rock_Stone"
    },
    {
      "x": -4,
      "y": -5,
      "z": -10,
      "name": "Rock_Stone"
    },
    {
      "x": -4,
      "y": -4,
      "z": -10,
      "name": "Rock_Stone"
    },
    {
      "x": -4,
      "y": -3,
      "z": -10,
      "name": "Rock_Stone"
    },
    {
      "x": -4,
      "y": -2,
      "z": -10,
      "name": "Rock_Stone"
    },
    {
      "x": -4,
      "y": -1,
      "z": -10,
      "name": "Rock_Stone"
    },
    {
      "x": -4,
      "y": 0,
      "z": -10,
      "name": "Deco_Bone_Skulls_Wall"
    },
    {
      "x": -4,
      "y": 1,
      "z": -10,
      "name": "Deco_Bone_Skulls_Wall"
    },
    {
      "x": -4,
      "y": 2,
      "z": -10,
      "name": "Deco_Bone_Skulls_Wall"
    },
    {
      "x": -4,
      "y": 3,
      "z": -10,
      "name": "Rock_Stone"
    },
    {
      "x": -4,
      "y": 4,
      "z": -10,
      "name": "Rock_Stone"
    },
    {
      "x": -4,
      "y": 5,
      "z": -10,
      "name": "Rock_Stone"
    },
    {
      "x": -4,
      "y": 6,
      "z": -10,
      "name": "Rock_Stone"
    },
    {
      "x": -4,
      "y": 7,
      "z": -10,
      "name": "Rock_Stone"
    },
    {
      "x": -4,
      "y": 8,
      "z": -10,
      "name": "Rock_Stone"
    },
    {
      "x": -4,
      "y": 9,
      "z": -10,
      "name": "Rock_Stone"
    },
    {
      "x": -4,
      "y": 10,
      "z": -10,
      "name": "Rock_Stone"
    },
    {
      "x": -4,
      "y": -7,
      "z": -9,
      "name": "Rock_Stone"
    },
    {
      "x": -4,
      "y": -6,
      "z": -9,
      "name": "Rock_Stone"
    },
    {
      "x": -4,
      "y": -5,
      "z": -9,
      "name": "Rock_Stone"
    },
    {
      "x": -4,
      "y": -4,
      "z": -9,
      "name": "Rock_Stone"
    },
    {
      "x": -4,
      "y": -3,
      "z": -9,
      "name": "Rock_Stone"
    },
    {
      "x": -4,
      "y": -2,
      "z": -9,
      "name": "Rock_Stone"
    },
    {
      "x": -4,
      "y": -1,
      "z": -9,
      "name": "Soil_Ash"
    },
    {
      "x": -4,
      "y": 0,
      "z": -9,
      "name": "Furniture_Village_Tombstone"
    },
    {
      "x": -4,
      "y": 1,
      "z": -9,
      "name": "Furniture_Village_Tombstone",
      "filler": 1024
    },
    {
      "x": -4,
      "y": 2,
      "z": -9,
      "name": "Empty"
    },
    {
      "x": -4,
      "y": 3,
      "z": -9,
      "name": "Empty"
    },
    {
      "x": -4,
      "y": 4,
      "z": -9,
      "name": "Rock_Stone"
    },
    {
      "x": -4,
      "y": 5,
      "z": -9,
      "name": "Rock_Stone"
    },
    {
      "x": -4,
      "y": 6,
      "z": -9,
      "name": "Rock_Stone"
    },
    {
      "x": -4,
      "y": 7,
      "z": -9,
      "name": "Rock_Stone"
    },
    {
      "x": -4,
      "y": 8,
      "z": -9,
      "name": "Rock_Stone"
    },
    {
      "x": -4,
      "y": 9,
      "z": -9,
      "name": "Rock_Stone"
    },
    {
      "x": -4,
      "y": 10,
      "z": -9,
      "name": "Rock_Stone"
    },
    {
      "x": -4,
      "y": -7,
      "z": -8,
      "name": "Rock_Stone"
    },
    {
      "x": -4,
      "y": -6,
      "z": -8,
      "name": "Rock_Stone"
    },
    {
      "x": -4,
      "y": -5,
      "z": -8,
      "name": "Rock_Stone"
    },
    {
      "x": -4,
      "y": -4,
      "z": -8,
      "name": "Rock_Stone"
    },
    {
      "x": -4,
      "y": -3,
      "z": -8,
      "name": "Rock_Stone"
    },
    {
      "x": -4,
      "y": -2,
      "z": -8,
      "name": "Rock_Stone"
    },
    {
      "x": -4,
      "y": -1,
      "z": -8,
      "name": "Soil_Ash"
    },
    {
      "x": -4,
      "y": 0,
      "z": -8,
      "name": "Furniture_Temple_Dark_Pot"
    },
    {
      "x": -4,
      "y": 1,
      "z": -8,
      "name": "Empty"
    },
    {
      "x": -4,
      "y": 2,
      "z": -8,
      "name": "Empty"
    },
    {
      "x": -4,
      "y": 3,
      "z": -8,
      "name": "Empty"
    },
    {
      "x": -4,
      "y": 4,
      "z": -8,
      "name": "Rock_Stone"
    },
    {
      "x": -4,
      "y": 5,
      "z": -8,
      "name": "Rock_Stone"
    },
    {
      "x": -4,
      "y": 6,
      "z": -8,
      "name": "Rock_Stone"
    },
    {
      "x": -4,
      "y": 7,
      "z": -8,
      "name": "Rock_Stone"
    },
    {
      "x": -4,
      "y": 8,
      "z": -8,
      "name": "Rock_Stone"
    },
    {
      "x": -4,
      "y": 9,
      "z": -8,
      "name": "Rock_Stone"
    },
    {
      "x": -4,
      "y": 10,
      "z": -8,
      "name": "Rock_Stone"
    },
    {
      "x": -4,
      "y": -7,
      "z": -7,
      "name": "Rock_Stone"
    },
    {
      "x": -4,
      "y": -6,
      "z": -7,
      "name": "Rock_Stone"
    },
    {
      "x": -4,
      "y": -5,
      "z": -7,
      "name": "Rock_Stone"
    },
    {
      "x": -4,
      "y": -4,
      "z": -7,
      "name": "Rock_Stone"
    },
    {
      "x": -4,
      "y": -3,
      "z": -7,
      "name": "Rock_Stone"
    },
    {
      "x": -4,
      "y": -2,
      "z": -7,
      "name": "Rock_Stone"
    },
    {
      "x": -4,
      "y": -1,
      "z": -7,
      "name": "Soil_Ash"
    },
    {
      "x": -4,
      "y": 0,
      "z": -7,
      "name": "Empty"
    },
    {
      "x": -4,
      "y": 1,
      "z": -7,
      "name": "Empty"
    },
    {
      "x": -4,
      "y": 2,
      "z": -7,
      "name": "Empty"
    },
    {
      "x": -4,
      "y": 3,
      "z": -7,
      "name": "Empty"
    },
    {
      "x": -4,
      "y": 4,
      "z": -7,
      "name": "Empty"
    },
    {
      "x": -4,
      "y": 5,
      "z": -7,
      "name": "Rock_Stone"
    },
    {
      "x": -4,
      "y": 6,
      "z": -7,
      "name": "Rock_Stone"
    },
    {
      "x": -4,
      "y": 7,
      "z": -7,
      "name": "Rock_Stone"
    },
    {
      "x": -4,
      "y": 8,
      "z": -7,
      "name": "Rock_Stone"
    },
    {
      "x": -4,
      "y": 9,
      "z": -7,
      "name": "Rock_Stone"
    },
    {
      "x": -4,
      "y": 10,
      "z": -7,
      "name": "Rock_Stone"
    },
    {
      "x": -4,
      "y": -7,
      "z": -6,
      "name": "Rock_Stone"
    },
    {
      "x": -4,
      "y": -6,
      "z": -6,
      "name": "Rock_Stone"
    },
    {
      "x": -4,
      "y": -5,
      "z": -6,
      "name": "Rock_Stone"
    },
    {
      "x": -4,
      "y": -4,
      "z": -6,
      "name": "Rock_Stone"
    },
    {
      "x": -4,
      "y": -3,
      "z": -6,
      "name": "Rock_Stone"
    },
    {
      "x": -4,
      "y": -2,
      "z": -6,
      "name": "Rock_Stone"
    },
    {
      "x": -4,
      "y": -1,
      "z": -6,
      "name": "Soil_Ash"
    },
    {
      "x": -4,
      "y": 0,
      "z": -6,
      "name": "Deco_Bone_Skulls"
    },
    {
      "x": -4,
      "y": 1,
      "z": -6,
      "name": "Empty"
    },
    {
      "x": -4,
      "y": 2,
      "z": -6,
      "name": "Empty"
    },
    {
      "x": -4,
      "y": 3,
      "z": -6,
      "name": "Empty"
    },
    {
      "x": -4,
      "y": 4,
      "z": -6,
      "name": "Empty"
    },
    {
      "x": -4,
      "y": 5,
      "z": -6,
      "name": "Empty"
    },
    {
      "x": -4,
      "y": 6,
      "z": -6,
      "name": "Rock_Stone"
    },
    {
      "x": -4,
      "y": 7,
      "z": -6,
      "name": "Rock_Stone"
    },
    {
      "x": -4,
      "y": 8,
      "z": -6,
      "name": "Rock_Stone"
    },
    {
      "x": -4,
      "y": 9,
      "z": -6,
      "name": "Rock_Stone"
    },
    {
      "x": -4,
      "y": 10,
      "z": -6,
      "name": "Rock_Stone"
    },
    {
      "x": -4,
      "y": -7,
      "z": -5,
      "name": "Rock_Stone"
    },
    {
      "x": -4,
      "y": -6,
      "z": -5,
      "name": "Rock_Stone"
    },
    {
      "x": -4,
      "y": -5,
      "z": -5,
      "name": "Rock_Stone"
    },
    {
      "x": -4,
      "y": -4,
      "z": -5,
      "name": "Rock_Stone"
    },
    {
      "x": -4,
      "y": -3,
      "z": -5,
      "name": "Rock_Stone"
    },
    {
      "x": -4,
      "y": -2,
      "z": -5,
      "name": "Rock_Stone"
    },
    {
      "x": -4,
      "y": -1,
      "z": -5,
      "name": "Rock_Stone"
    },
    {
      "x": -4,
      "y": 0,
      "z": -5,
      "name": "Deco_Bone_Skulls"
    },
    {
      "x": -4,
      "y": 1,
      "z": -5,
      "name": "Empty"
    },
    {
      "x": -4,
      "y": 2,
      "z": -5,
      "name": "Empty"
    },
    {
      "x": -4,
      "y": 3,
      "z": -5,
      "name": "Empty"
    },
    {
      "x": -4,
      "y": 4,
      "z": -5,
      "name": "Empty"
    },
    {
      "x": -4,
      "y": 5,
      "z": -5,
      "name": "Empty"
    },
    {
      "x": -4,
      "y": 6,
      "z": -5,
      "name": "Empty"
    },
    {
      "x": -4,
      "y": 7,
      "z": -5,
      "name": "Rock_Stone"
    },
    {
      "x": -4,
      "y": 8,
      "z": -5,
      "name": "Rock_Stone"
    },
    {
      "x": -4,
      "y": 9,
      "z": -5,
      "name": "Rock_Stone"
    },
    {
      "x": -4,
      "y": 10,
      "z": -5,
      "name": "Rock_Stone"
    },
    {
      "x": -4,
      "y": -7,
      "z": -4,
      "name": "Rock_Stone"
    },
    {
      "x": -4,
      "y": -6,
      "z": -4,
      "name": "Rock_Stone"
    },
    {
      "x": -4,
      "y": -5,
      "z": -4,
      "name": "Rock_Stone"
    },
    {
      "x": -4,
      "y": -4,
      "z": -4,
      "name": "Rock_Stone"
    },
    {
      "x": -4,
      "y": -3,
      "z": -4,
      "name": "Rock_Stone"
    },
    {
      "x": -4,
      "y": -2,
      "z": -4,
      "name": "Rock_Stone"
    },
    {
      "x": -4,
      "y": -1,
      "z": -4,
      "name": "Rock_Stone"
    },
    {
      "x": -4,
      "y": 0,
      "z": -4,
      "name": "Empty"
    },
    {
      "x": -4,
      "y": 1,
      "z": -4,
      "name": "Empty"
    },
    {
      "x": -4,
      "y": 2,
      "z": -4,
      "name": "Empty"
    },
    {
      "x": -4,
      "y": 3,
      "z": -4,
      "name": "Empty"
    },
    {
      "x": -4,
      "y": 4,
      "z": -4,
      "name": "Empty"
    },
    {
      "x": -4,
      "y": 5,
      "z": -4,
      "name": "Empty"
    },
    {
      "x": -4,
      "y": 6,
      "z": -4,
      "name": "Empty"
    },
    {
      "x": -4,
      "y": 7,
      "z": -4,
      "name": "Rock_Stone"
    },
    {
      "x": -4,
      "y": 8,
      "z": -4,
      "name": "Rock_Stone"
    },
    {
      "x": -4,
      "y": 9,
      "z": -4,
      "name": "Rock_Stone"
    },
    {
      "x": -4,
      "y": 10,
      "z": -4,
      "name": "Rock_Stone"
    },
    {
      "x": -4,
      "y": -7,
      "z": -3,
      "name": "Rock_Stone"
    },
    {
      "x": -4,
      "y": -6,
      "z": -3,
      "name": "Rock_Stone"
    },
    {
      "x": -4,
      "y": -5,
      "z": -3,
      "name": "Rock_Stone"
    },
    {
      "x": -4,
      "y": -4,
      "z": -3,
      "name": "Rock_Stone"
    },
    {
      "x": -4,
      "y": -3,
      "z": -3,
      "name": "Rock_Stone"
    },
    {
      "x": -4,
      "y": -2,
      "z": -3,
      "name": "Rock_Stone"
    },
    {
      "x": -4,
      "y": -1,
      "z": -3,
      "name": "Rock_Stone"
    },
    {
      "x": -4,
      "y": 0,
      "z": -3,
      "name": "Deco_Bone_Skulls"
    },
    {
      "x": -4,
      "y": 1,
      "z": -3,
      "name": "Empty"
    },
    {
      "x": -4,
      "y": 2,
      "z": -3,
      "name": "Empty"
    },
    {
      "x": -4,
      "y": 3,
      "z": -3,
      "name": "Empty"
    },
    {
      "x": -4,
      "y": 4,
      "z": -3,
      "name": "Rock_Stone"
    },
    {
      "x": -4,
      "y": 5,
      "z": -3,
      "name": "Rock_Stone"
    },
    {
      "x": -4,
      "y": 6,
      "z": -3,
      "name": "Rock_Stone"
    },
    {
      "x": -4,
      "y": 7,
      "z": -3,
      "name": "Rock_Stone"
    },
    {
      "x": -4,
      "y": 8,
      "z": -3,
      "name": "Rock_Stone"
    },
    {
      "x": -4,
      "y": 9,
      "z": -3,
      "name": "Rock_Stone"
    },
    {
      "x": -4,
      "y": 10,
      "z": -3,
      "name": "Rock_Stone"
    },
    {
      "x": -4,
      "y": -7,
      "z": -2,
      "name": "Rock_Stone"
    },
    {
      "x": -4,
      "y": -6,
      "z": -2,
      "name": "Rock_Stone"
    },
    {
      "x": -4,
      "y": -5,
      "z": -2,
      "name": "Rock_Stone"
    },
    {
      "x": -4,
      "y": -4,
      "z": -2,
      "name": "Rock_Stone"
    },
    {
      "x": -4,
      "y": -3,
      "z": -2,
      "name": "Rock_Stone"
    },
    {
      "x": -4,
      "y": -2,
      "z": -2,
      "name": "Rock_Stone"
    },
    {
      "x": -4,
      "y": -1,
      "z": -2,
      "name": "Rock_Stone"
    },
    {
      "x": -4,
      "y": 0,
      "z": -2,
      "name": "Empty"
    },
    {
      "x": -4,
      "y": 1,
      "z": -2,
      "name": "Empty"
    },
    {
      "x": -4,
      "y": 2,
      "z": -2,
      "name": "Rock_Stone"
    },
    {
      "x": -4,
      "y": 3,
      "z": -2,
      "name": "Rock_Stone"
    },
    {
      "x": -4,
      "y": 4,
      "z": -2,
      "name": "Rock_Stone"
    },
    {
      "x": -4,
      "y": 5,
      "z": -2,
      "name": "Rock_Stone"
    },
    {
      "x": -4,
      "y": 6,
      "z": -2,
      "name": "Rock_Stone"
    },
    {
      "x": -4,
      "y": 7,
      "z": -2,
      "name": "Rock_Stone"
    },
    {
      "x": -4,
      "y": 8,
      "z": -2,
      "name": "Rock_Stone"
    },
    {
      "x": -4,
      "y": 9,
      "z": -2,
      "name": "Rock_Stone"
    },
    {
      "x": -4,
      "y": 10,
      "z": -2,
      "name": "Rock_Stone"
    },
    {
      "x": -4,
      "y": -7,
      "z": -1,
      "name": "Rock_Stone"
    },
    {
      "x": -4,
      "y": -6,
      "z": -1,
      "name": "Rock_Stone"
    },
    {
      "x": -4,
      "y": -5,
      "z": -1,
      "name": "Rock_Stone"
    },
    {
      "x": -4,
      "y": -4,
      "z": -1,
      "name": "Rock_Stone"
    },
    {
      "x": -4,
      "y": -3,
      "z": -1,
      "name": "Rock_Stone"
    },
    {
      "x": -4,
      "y": -2,
      "z": -1,
      "name": "Rock_Stone"
    },
    {
      "x": -4,
      "y": -1,
      "z": -1,
      "name": "Rock_Stone"
    },
    {
      "x": -4,
      "y": 0,
      "z": -1,
      "name": "Rock_Stone"
    },
    {
      "x": -4,
      "y": 1,
      "z": -1,
      "name": "Rock_Stone"
    },
    {
      "x": -4,
      "y": 2,
      "z": -1,
      "name": "Rock_Stone"
    },
    {
      "x": -4,
      "y": 3,
      "z": -1,
      "name": "Rock_Stone"
    },
    {
      "x": -4,
      "y": 4,
      "z": -1,
      "name": "Rock_Stone"
    },
    {
      "x": -4,
      "y": 5,
      "z": -1,
      "name": "Rock_Stone"
    },
    {
      "x": -4,
      "y": 6,
      "z": -1,
      "name": "Rock_Stone"
    },
    {
      "x": -4,
      "y": 7,
      "z": -1,
      "name": "Rock_Stone"
    },
    {
      "x": -4,
      "y": 8,
      "z": -1,
      "name": "Rock_Stone"
    },
    {
      "x": -4,
      "y": 9,
      "z": -1,
      "name": "Rock_Stone"
    },
    {
      "x": -4,
      "y": 10,
      "z": -1,
      "name": "Rock_Stone"
    },
    {
      "x": -4,
      "y": -7,
      "z": 0,
      "name": "Rock_Stone"
    },
    {
      "x": -4,
      "y": -6,
      "z": 0,
      "name": "Rock_Stone"
    },
    {
      "x": -4,
      "y": -5,
      "z": 0,
      "name": "Rock_Stone"
    },
    {
      "x": -4,
      "y": -4,
      "z": 0,
      "name": "Rock_Stone"
    },
    {
      "x": -4,
      "y": -3,
      "z": 0,
      "name": "Rock_Stone"
    },
    {
      "x": -4,
      "y": -2,
      "z": 0,
      "name": "Rock_Stone"
    },
    {
      "x": -4,
      "y": -1,
      "z": 0,
      "name": "Rock_Stone"
    },
    {
      "x": -4,
      "y": 0,
      "z": 0,
      "name": "Rock_Stone"
    },
    {
      "x": -4,
      "y": 1,
      "z": 0,
      "name": "Rock_Stone"
    },
    {
      "x": -4,
      "y": 2,
      "z": 0,
      "name": "Rock_Stone"
    },
    {
      "x": -4,
      "y": 3,
      "z": 0,
      "name": "Rock_Stone"
    },
    {
      "x": -4,
      "y": 4,
      "z": 0,
      "name": "Rock_Stone"
    },
    {
      "x": -4,
      "y": 5,
      "z": 0,
      "name": "Rock_Stone"
    },
    {
      "x": -4,
      "y": 6,
      "z": 0,
      "name": "Rock_Stone"
    },
    {
      "x": -4,
      "y": 7,
      "z": 0,
      "name": "Rock_Stone"
    },
    {
      "x": -4,
      "y": 8,
      "z": 0,
      "name": "Rock_Stone"
    },
    {
      "x": -4,
      "y": 9,
      "z": 0,
      "name": "Rock_Stone"
    },
    {
      "x": -4,
      "y": 10,
      "z": 0,
      "name": "Rock_Stone"
    },
    {
      "x": -3,
      "y": -7,
      "z": -12,
      "name": "Rock_Stone"
    },
    {
      "x": -3,
      "y": -6,
      "z": -12,
      "name": "Rock_Stone"
    },
    {
      "x": -3,
      "y": -5,
      "z": -12,
      "name": "Rock_Stone"
    },
    {
      "x": -3,
      "y": -4,
      "z": -12,
      "name": "Rock_Stone"
    },
    {
      "x": -3,
      "y": -3,
      "z": -12,
      "name": "Rock_Stone"
    },
    {
      "x": -3,
      "y": -2,
      "z": -12,
      "name": "Rock_Stone"
    },
    {
      "x": -3,
      "y": -1,
      "z": -12,
      "name": "Rock_Stone"
    },
    {
      "x": -3,
      "y": 0,
      "z": -12,
      "name": "Rock_Stone"
    },
    {
      "x": -3,
      "y": 1,
      "z": -12,
      "name": "Rock_Stone"
    },
    {
      "x": -3,
      "y": 2,
      "z": -12,
      "name": "Rock_Stone"
    },
    {
      "x": -3,
      "y": 3,
      "z": -12,
      "name": "Rock_Stone"
    },
    {
      "x": -3,
      "y": 4,
      "z": -12,
      "name": "Rock_Stone"
    },
    {
      "x": -3,
      "y": 5,
      "z": -12,
      "name": "Rock_Stone"
    },
    {
      "x": -3,
      "y": 6,
      "z": -12,
      "name": "Rock_Stone"
    },
    {
      "x": -3,
      "y": 7,
      "z": -12,
      "name": "Rock_Stone"
    },
    {
      "x": -3,
      "y": 8,
      "z": -12,
      "name": "Rock_Stone"
    },
    {
      "x": -3,
      "y": 9,
      "z": -12,
      "name": "Rock_Stone"
    },
    {
      "x": -3,
      "y": 10,
      "z": -12,
      "name": "Rock_Stone"
    },
    {
      "x": -3,
      "y": -7,
      "z": -11,
      "name": "Rock_Stone"
    },
    {
      "x": -3,
      "y": -6,
      "z": -11,
      "name": "Rock_Stone"
    },
    {
      "x": -3,
      "y": -5,
      "z": -11,
      "name": "Rock_Stone"
    },
    {
      "x": -3,
      "y": -4,
      "z": -11,
      "name": "Rock_Stone"
    },
    {
      "x": -3,
      "y": -3,
      "z": -11,
      "name": "Rock_Stone"
    },
    {
      "x": -3,
      "y": -2,
      "z": -11,
      "name": "Rock_Stone"
    },
    {
      "x": -3,
      "y": -1,
      "z": -11,
      "name": "Rock_Stone"
    },
    {
      "x": -3,
      "y": 0,
      "z": -11,
      "name": "Rock_Stone"
    },
    {
      "x": -3,
      "y": 1,
      "z": -11,
      "name": "Rock_Stone"
    },
    {
      "x": -3,
      "y": 2,
      "z": -11,
      "name": "Rock_Stone"
    },
    {
      "x": -3,
      "y": 3,
      "z": -11,
      "name": "Rock_Stone"
    },
    {
      "x": -3,
      "y": 4,
      "z": -11,
      "name": "Rock_Stone"
    },
    {
      "x": -3,
      "y": 5,
      "z": -11,
      "name": "Rock_Stone"
    },
    {
      "x": -3,
      "y": 6,
      "z": -11,
      "name": "Rock_Stone"
    },
    {
      "x": -3,
      "y": 7,
      "z": -11,
      "name": "Rock_Stone"
    },
    {
      "x": -3,
      "y": 8,
      "z": -11,
      "name": "Rock_Stone"
    },
    {
      "x": -3,
      "y": 9,
      "z": -11,
      "name": "Rock_Stone"
    },
    {
      "x": -3,
      "y": 10,
      "z": -11,
      "name": "Rock_Stone"
    },
    {
      "x": -3,
      "y": -7,
      "z": -10,
      "name": "Rock_Stone"
    },
    {
      "x": -3,
      "y": -6,
      "z": -10,
      "name": "Rock_Stone"
    },
    {
      "x": -3,
      "y": -5,
      "z": -10,
      "name": "Rock_Stone"
    },
    {
      "x": -3,
      "y": -4,
      "z": -10,
      "name": "Rock_Stone"
    },
    {
      "x": -3,
      "y": -3,
      "z": -10,
      "name": "Rock_Stone"
    },
    {
      "x": -3,
      "y": -2,
      "z": -10,
      "name": "Rock_Stone"
    },
    {
      "x": -3,
      "y": -1,
      "z": -10,
      "name": "Soil_Ash"
    },
    {
      "x": -3,
      "y": 0,
      "z": -10,
      "name": "Deco_Bone_Skulls_Wall"
    },
    {
      "x": -3,
      "y": 1,
      "z": -10,
      "name": "Deco_Bone_Skulls_Wall"
    },
    {
      "x": -3,
      "y": 2,
      "z": -10,
      "name": "Deco_Bone_Skulls_Wall"
    },
    {
      "x": -3,
      "y": 3,
      "z": -10,
      "name": "Empty"
    },
    {
      "x": -3,
      "y": 4,
      "z": -10,
      "name": "Empty"
    },
    {
      "x": -3,
      "y": 5,
      "z": -10,
      "name": "Rock_Stone"
    },
    {
      "x": -3,
      "y": 6,
      "z": -10,
      "name": "Rock_Stone"
    },
    {
      "x": -3,
      "y": 7,
      "z": -10,
      "name": "Rock_Stone"
    },
    {
      "x": -3,
      "y": 8,
      "z": -10,
      "name": "Rock_Stone"
    },
    {
      "x": -3,
      "y": 9,
      "z": -10,
      "name": "Rock_Stone"
    },
    {
      "x": -3,
      "y": 10,
      "z": -10,
      "name": "Rock_Stone"
    },
    {
      "x": -3,
      "y": -7,
      "z": -9,
      "name": "Rock_Stone"
    },
    {
      "x": -3,
      "y": -6,
      "z": -9,
      "name": "Rock_Stone"
    },
    {
      "x": -3,
      "y": -5,
      "z": -9,
      "name": "Rock_Stone"
    },
    {
      "x": -3,
      "y": -4,
      "z": -9,
      "name": "Rock_Stone"
    },
    {
      "x": -3,
      "y": -3,
      "z": -9,
      "name": "Rock_Stone"
    },
    {
      "x": -3,
      "y": -2,
      "z": -9,
      "name": "Rock_Stone"
    },
    {
      "x": -3,
      "y": -1,
      "z": -9,
      "name": "Soil_Ash"
    },
    {
      "x": -3,
      "y": 0,
      "z": -9,
      "name": "Empty"
    },
    {
      "x": -3,
      "y": 1,
      "z": -9,
      "name": "Empty"
    },
    {
      "x": -3,
      "y": 2,
      "z": -9,
      "name": "Empty"
    },
    {
      "x": -3,
      "y": 3,
      "z": -9,
      "name": "Empty"
    },
    {
      "x": -3,
      "y": 4,
      "z": -9,
      "name": "Rock_Stone"
    },
    {
      "x": -3,
      "y": 5,
      "z": -9,
      "name": "Rock_Stone"
    },
    {
      "x": -3,
      "y": 6,
      "z": -9,
      "name": "Rock_Stone"
    },
    {
      "x": -3,
      "y": 7,
      "z": -9,
      "name": "Rock_Stone"
    },
    {
      "x": -3,
      "y": 8,
      "z": -9,
      "name": "Rock_Stone"
    },
    {
      "x": -3,
      "y": 9,
      "z": -9,
      "name": "Rock_Stone"
    },
    {
      "x": -3,
      "y": 10,
      "z": -9,
      "name": "Rock_Stone"
    },
    {
      "x": -3,
      "y": -7,
      "z": -8,
      "name": "Rock_Stone"
    },
    {
      "x": -3,
      "y": -6,
      "z": -8,
      "name": "Rock_Stone"
    },
    {
      "x": -3,
      "y": -5,
      "z": -8,
      "name": "Rock_Stone"
    },
    {
      "x": -3,
      "y": -4,
      "z": -8,
      "name": "Rock_Stone"
    },
    {
      "x": -3,
      "y": -3,
      "z": -8,
      "name": "Rock_Stone_Cobble"
    },
    {
      "x": -3,
      "y": -2,
      "z": -8,
      "name": "Rock_Stone"
    },
    {
      "x": -3,
      "y": -1,
      "z": -8,
      "name": "Soil_Ash"
    },
    {
      "x": -3,
      "y": 0,
      "z": -8,
      "name": "Deco_Bone_Skulls"
    },
    {
      "x": -3,
      "y": 1,
      "z": -8,
      "name": "Empty"
    },
    {
      "x": -3,
      "y": 2,
      "z": -8,
      "name": "Empty"
    },
    {
      "x": -3,
      "y": 3,
      "z": -8,
      "name": "Empty"
    },
    {
      "x": -3,
      "y": 4,
      "z": -8,
      "name": "Empty"
    },
    {
      "x": -3,
      "y": 5,
      "z": -8,
      "name": "Empty"
    },
    {
      "x": -3,
      "y": 6,
      "z": -8,
      "name": "Rock_Stone"
    },
    {
      "x": -3,
      "y": 7,
      "z": -8,
      "name": "Rock_Stone"
    },
    {
      "x": -3,
      "y": 8,
      "z": -8,
      "name": "Rock_Stone"
    },
    {
      "x": -3,
      "y": 9,
      "z": -8,
      "name": "Rock_Stone"
    },
    {
      "x": -3,
      "y": 10,
      "z": -8,
      "name": "Rock_Stone"
    },
    {
      "x": -3,
      "y": -7,
      "z": -7,
      "name": "Rock_Stone"
    },
    {
      "x": -3,
      "y": -6,
      "z": -7,
      "name": "Rock_Stone"
    },
    {
      "x": -3,
      "y": -5,
      "z": -7,
      "name": "Rock_Stone"
    },
    {
      "x": -3,
      "y": -4,
      "z": -7,
      "name": "Rock_Stone"
    },
    {
      "x": -3,
      "y": -3,
      "z": -7,
      "name": "Rock_Stone"
    },
    {
      "x": -3,
      "y": -2,
      "z": -7,
      "name": "Rock_Stone"
    },
    {
      "x": -3,
      "y": -1,
      "z": -7,
      "name": "Soil_Ash"
    },
    {
      "x": -3,
      "y": 0,
      "z": -7,
      "name": "Empty"
    },
    {
      "x": -3,
      "y": 1,
      "z": -7,
      "name": "Empty"
    },
    {
      "x": -3,
      "y": 2,
      "z": -7,
      "name": "Empty"
    },
    {
      "x": -3,
      "y": 3,
      "z": -7,
      "name": "Empty"
    },
    {
      "x": -3,
      "y": 4,
      "z": -7,
      "name": "Empty"
    },
    {
      "x": -3,
      "y": 5,
      "z": -7,
      "name": "Empty"
    },
    {
      "x": -3,
      "y": 6,
      "z": -7,
      "name": "Empty"
    },
    {
      "x": -3,
      "y": 7,
      "z": -7,
      "name": "Empty"
    },
    {
      "x": -3,
      "y": 8,
      "z": -7,
      "name": "Rock_Stone"
    },
    {
      "x": -3,
      "y": 9,
      "z": -7,
      "name": "Rock_Stone"
    },
    {
      "x": -3,
      "y": 10,
      "z": -7,
      "name": "Rock_Stone"
    },
    {
      "x": -3,
      "y": -7,
      "z": -6,
      "name": "Rock_Stone"
    },
    {
      "x": -3,
      "y": -6,
      "z": -6,
      "name": "Rock_Stone"
    },
    {
      "x": -3,
      "y": -5,
      "z": -6,
      "name": "Rock_Stone"
    },
    {
      "x": -3,
      "y": -4,
      "z": -6,
      "name": "Rock_Stone"
    },
    {
      "x": -3,
      "y": -3,
      "z": -6,
      "name": "Rock_Stone"
    },
    {
      "x": -3,
      "y": -2,
      "z": -6,
      "name": "Rock_Stone"
    },
    {
      "x": -3,
      "y": -1,
      "z": -6,
      "name": "Soil_Ash"
    },
    {
      "x": -3,
      "y": 0,
      "z": -6,
      "name": "Deco_Bone_Skulls"
    },
    {
      "x": -3,
      "y": 1,
      "z": -6,
      "name": "Empty"
    },
    {
      "x": -3,
      "y": 2,
      "z": -6,
      "name": "Empty"
    },
    {
      "x": -3,
      "y": 3,
      "z": -6,
      "name": "Empty"
    },
    {
      "x": -3,
      "y": 4,
      "z": -6,
      "name": "Empty"
    },
    {
      "x": -3,
      "y": 5,
      "z": -6,
      "name": "Empty"
    },
    {
      "x": -3,
      "y": 6,
      "z": -6,
      "name": "Empty"
    },
    {
      "x": -3,
      "y": 7,
      "z": -6,
      "name": "Empty"
    },
    {
      "x": -3,
      "y": 8,
      "z": -6,
      "name": "Rock_Stone"
    },
    {
      "x": -3,
      "y": 9,
      "z": -6,
      "name": "Rock_Stone"
    },
    {
      "x": -3,
      "y": 10,
      "z": -6,
      "name": "Rock_Stone"
    },
    {
      "x": -3,
      "y": -7,
      "z": -5,
      "name": "Rock_Stone"
    },
    {
      "x": -3,
      "y": -6,
      "z": -5,
      "name": "Rock_Stone"
    },
    {
      "x": -3,
      "y": -5,
      "z": -5,
      "name": "Rock_Stone"
    },
    {
      "x": -3,
      "y": -4,
      "z": -5,
      "name": "Rock_Stone"
    },
    {
      "x": -3,
      "y": -3,
      "z": -5,
      "name": "Rock_Stone"
    },
    {
      "x": -3,
      "y": -2,
      "z": -5,
      "name": "Rock_Stone"
    },
    {
      "x": -3,
      "y": -1,
      "z": -5,
      "name": "Soil_Ash"
    },
    {
      "x": -3,
      "y": 0,
      "z": -5,
      "name": "Empty"
    },
    {
      "x": -3,
      "y": 1,
      "z": -5,
      "name": "Empty"
    },
    {
      "x": -3,
      "y": 2,
      "z": -5,
      "name": "Empty"
    },
    {
      "x": -3,
      "y": 3,
      "z": -5,
      "name": "Empty"
    },
    {
      "x": -3,
      "y": 4,
      "z": -5,
      "name": "Empty"
    },
    {
      "x": -3,
      "y": 5,
      "z": -5,
      "name": "Empty"
    },
    {
      "x": -3,
      "y": 6,
      "z": -5,
      "name": "Empty"
    },
    {
      "x": -3,
      "y": 7,
      "z": -5,
      "name": "Empty"
    },
    {
      "x": -3,
      "y": 8,
      "z": -5,
      "name": "Empty"
    },
    {
      "x": -3,
      "y": 9,
      "z": -5,
      "name": "Rock_Stone"
    },
    {
      "x": -3,
      "y": 10,
      "z": -5,
      "name": "Rock_Stone"
    },
    {
      "x": -3,
      "y": -7,
      "z": -4,
      "name": "Rock_Stone"
    },
    {
      "x": -3,
      "y": -6,
      "z": -4,
      "name": "Rock_Stone"
    },
    {
      "x": -3,
      "y": -5,
      "z": -4,
      "name": "Rock_Stone"
    },
    {
      "x": -3,
      "y": -4,
      "z": -4,
      "name": "Rock_Stone"
    },
    {
      "x": -3,
      "y": -3,
      "z": -4,
      "name": "Rock_Stone"
    },
    {
      "x": -3,
      "y": -2,
      "z": -4,
      "name": "Rock_Stone"
    },
    {
      "x": -3,
      "y": -1,
      "z": -4,
      "name": "Soil_Ash"
    },
    {
      "x": -3,
      "y": 0,
      "z": -4,
      "name": "Deco_Bone_Skulls"
    },
    {
      "x": -3,
      "y": 1,
      "z": -4,
      "name": "Empty"
    },
    {
      "x": -3,
      "y": 2,
      "z": -4,
      "name": "Empty"
    },
    {
      "x": -3,
      "y": 3,
      "z": -4,
      "name": "Empty"
    },
    {
      "x": -3,
      "y": 4,
      "z": -4,
      "name": "Empty"
    },
    {
      "x": -3,
      "y": 5,
      "z": -4,
      "name": "Empty"
    },
    {
      "x": -3,
      "y": 6,
      "z": -4,
      "name": "Empty"
    },
    {
      "x": -3,
      "y": 7,
      "z": -4,
      "name": "Empty"
    },
    {
      "x": -3,
      "y": 8,
      "z": -4,
      "name": "Rock_Stone"
    },
    {
      "x": -3,
      "y": 9,
      "z": -4,
      "name": "Rock_Stone"
    },
    {
      "x": -3,
      "y": 10,
      "z": -4,
      "name": "Rock_Stone"
    },
    {
      "x": -3,
      "y": -7,
      "z": -3,
      "name": "Rock_Stone"
    },
    {
      "x": -3,
      "y": -6,
      "z": -3,
      "name": "Rock_Stone"
    },
    {
      "x": -3,
      "y": -5,
      "z": -3,
      "name": "Rock_Stone"
    },
    {
      "x": -3,
      "y": -4,
      "z": -3,
      "name": "Rock_Stone"
    },
    {
      "x": -3,
      "y": -3,
      "z": -3,
      "name": "Rock_Stone"
    },
    {
      "x": -3,
      "y": -2,
      "z": -3,
      "name": "Rock_Stone"
    },
    {
      "x": -3,
      "y": -1,
      "z": -3,
      "name": "Rock_Stone"
    },
    {
      "x": -3,
      "y": 0,
      "z": -3,
      "name": "Deco_Bone_Skulls"
    },
    {
      "x": -3,
      "y": 1,
      "z": -3,
      "name": "Empty"
    },
    {
      "x": -3,
      "y": 2,
      "z": -3,
      "name": "Empty"
    },
    {
      "x": -3,
      "y": 3,
      "z": -3,
      "name": "Empty"
    },
    {
      "x": -3,
      "y": 4,
      "z": -3,
      "name": "Empty"
    },
    {
      "x": -3,
      "y": 5,
      "z": -3,
      "name": "Empty"
    },
    {
      "x": -3,
      "y": 6,
      "z": -3,
      "name": "Empty"
    },
    {
      "x": -3,
      "y": 7,
      "z": -3,
      "name": "Rock_Stone"
    },
    {
      "x": -3,
      "y": 8,
      "z": -3,
      "name": "Rock_Stone"
    },
    {
      "x": -3,
      "y": 9,
      "z": -3,
      "name": "Rock_Stone"
    },
    {
      "x": -3,
      "y": 10,
      "z": -3,
      "name": "Rock_Stone"
    },
    {
      "x": -3,
      "y": -7,
      "z": -2,
      "name": "Rock_Stone"
    },
    {
      "x": -3,
      "y": -6,
      "z": -2,
      "name": "Rock_Stone"
    },
    {
      "x": -3,
      "y": -5,
      "z": -2,
      "name": "Rock_Stone"
    },
    {
      "x": -3,
      "y": -4,
      "z": -2,
      "name": "Rock_Stone"
    },
    {
      "x": -3,
      "y": -3,
      "z": -2,
      "name": "Rock_Stone"
    },
    {
      "x": -3,
      "y": -2,
      "z": -2,
      "name": "Rock_Stone"
    },
    {
      "x": -3,
      "y": -1,
      "z": -2,
      "name": "Rock_Stone"
    },
    {
      "x": -3,
      "y": 0,
      "z": -2,
      "name": "Empty"
    },
    {
      "x": -3,
      "y": 1,
      "z": -2,
      "name": "Empty"
    },
    {
      "x": -3,
      "y": 2,
      "z": -2,
      "name": "Empty"
    },
    {
      "x": -3,
      "y": 3,
      "z": -2,
      "name": "Empty"
    },
    {
      "x": -3,
      "y": 4,
      "z": -2,
      "name": "Empty"
    },
    {
      "x": -3,
      "y": 5,
      "z": -2,
      "name": "Rock_Stone"
    },
    {
      "x": -3,
      "y": 6,
      "z": -2,
      "name": "Rock_Stone"
    },
    {
      "x": -3,
      "y": 7,
      "z": -2,
      "name": "Rock_Stone"
    },
    {
      "x": -3,
      "y": 8,
      "z": -2,
      "name": "Rock_Stone"
    },
    {
      "x": -3,
      "y": 9,
      "z": -2,
      "name": "Rock_Stone"
    },
    {
      "x": -3,
      "y": 10,
      "z": -2,
      "name": "Rock_Stone"
    },
    {
      "x": -3,
      "y": -7,
      "z": -1,
      "name": "Rock_Stone"
    },
    {
      "x": -3,
      "y": -6,
      "z": -1,
      "name": "Rock_Stone"
    },
    {
      "x": -3,
      "y": -5,
      "z": -1,
      "name": "Rock_Stone"
    },
    {
      "x": -3,
      "y": -4,
      "z": -1,
      "name": "Rock_Stone"
    },
    {
      "x": -3,
      "y": -3,
      "z": -1,
      "name": "Rock_Stone"
    },
    {
      "x": -3,
      "y": -2,
      "z": -1,
      "name": "Rock_Stone"
    },
    {
      "x": -3,
      "y": -1,
      "z": -1,
      "name": "Rock_Stone"
    },
    {
      "x": -3,
      "y": 0,
      "z": -1,
      "name": "Rock_Stone"
    },
    {
      "x": -3,
      "y": 1,
      "z": -1,
      "name": "Rock_Stone"
    },
    {
      "x": -3,
      "y": 2,
      "z": -1,
      "name": "Rock_Stone"
    },
    {
      "x": -3,
      "y": 3,
      "z": -1,
      "name": "Rock_Stone"
    },
    {
      "x": -3,
      "y": 4,
      "z": -1,
      "name": "Rock_Stone"
    },
    {
      "x": -3,
      "y": 5,
      "z": -1,
      "name": "Rock_Stone"
    },
    {
      "x": -3,
      "y": 6,
      "z": -1,
      "name": "Rock_Stone"
    },
    {
      "x": -3,
      "y": 7,
      "z": -1,
      "name": "Rock_Stone"
    },
    {
      "x": -3,
      "y": 8,
      "z": -1,
      "name": "Rock_Stone"
    },
    {
      "x": -3,
      "y": 9,
      "z": -1,
      "name": "Rock_Stone"
    },
    {
      "x": -3,
      "y": 10,
      "z": -1,
      "name": "Rock_Stone"
    },
    {
      "x": -3,
      "y": -7,
      "z": 0,
      "name": "Rock_Stone"
    },
    {
      "x": -3,
      "y": -6,
      "z": 0,
      "name": "Rock_Stone"
    },
    {
      "x": -3,
      "y": -5,
      "z": 0,
      "name": "Rock_Stone"
    },
    {
      "x": -3,
      "y": -4,
      "z": 0,
      "name": "Rock_Stone"
    },
    {
      "x": -3,
      "y": -3,
      "z": 0,
      "name": "Rock_Stone"
    },
    {
      "x": -3,
      "y": -2,
      "z": 0,
      "name": "Rock_Stone"
    },
    {
      "x": -3,
      "y": -1,
      "z": 0,
      "name": "Rock_Stone"
    },
    {
      "x": -3,
      "y": 0,
      "z": 0,
      "name": "Rock_Stone"
    },
    {
      "x": -3,
      "y": 1,
      "z": 0,
      "name": "Rock_Stone"
    },
    {
      "x": -3,
      "y": 2,
      "z": 0,
      "name": "Rock_Stone"
    },
    {
      "x": -3,
      "y": 3,
      "z": 0,
      "name": "Rock_Stone"
    },
    {
      "x": -3,
      "y": 4,
      "z": 0,
      "name": "Rock_Stone"
    },
    {
      "x": -3,
      "y": 5,
      "z": 0,
      "name": "Rock_Stone"
    },
    {
      "x": -3,
      "y": 6,
      "z": 0,
      "name": "Rock_Stone"
    },
    {
      "x": -3,
      "y": 7,
      "z": 0,
      "name": "Rock_Stone"
    },
    {
      "x": -3,
      "y": 8,
      "z": 0,
      "name": "Rock_Stone"
    },
    {
      "x": -3,
      "y": 9,
      "z": 0,
      "name": "Rock_Stone"
    },
    {
      "x": -3,
      "y": 10,
      "z": 0,
      "name": "Rock_Stone"
    },
    {
      "x": -2,
      "y": -7,
      "z": -12,
      "name": "Rock_Stone"
    },
    {
      "x": -2,
      "y": -6,
      "z": -12,
      "name": "Rock_Stone"
    },
    {
      "x": -2,
      "y": -5,
      "z": -12,
      "name": "Rock_Stone"
    },
    {
      "x": -2,
      "y": -4,
      "z": -12,
      "name": "Rock_Stone"
    },
    {
      "x": -2,
      "y": -3,
      "z": -12,
      "name": "Rock_Stone"
    },
    {
      "x": -2,
      "y": -2,
      "z": -12,
      "name": "Rock_Stone"
    },
    {
      "x": -2,
      "y": -1,
      "z": -12,
      "name": "Rock_Stone"
    },
    {
      "x": -2,
      "y": 0,
      "z": -12,
      "name": "Rock_Stone"
    },
    {
      "x": -2,
      "y": 1,
      "z": -12,
      "name": "Rock_Stone"
    },
    {
      "x": -2,
      "y": 2,
      "z": -12,
      "name": "Rock_Stone"
    },
    {
      "x": -2,
      "y": 3,
      "z": -12,
      "name": "Rock_Stone"
    },
    {
      "x": -2,
      "y": 4,
      "z": -12,
      "name": "Rock_Stone"
    },
    {
      "x": -2,
      "y": 5,
      "z": -12,
      "name": "Rock_Stone"
    },
    {
      "x": -2,
      "y": 6,
      "z": -12,
      "name": "Rock_Stone"
    },
    {
      "x": -2,
      "y": 7,
      "z": -12,
      "name": "Rock_Stone"
    },
    {
      "x": -2,
      "y": 8,
      "z": -12,
      "name": "Rock_Stone"
    },
    {
      "x": -2,
      "y": 9,
      "z": -12,
      "name": "Rock_Stone"
    },
    {
      "x": -2,
      "y": 10,
      "z": -12,
      "name": "Rock_Stone"
    },
    {
      "x": -2,
      "y": -7,
      "z": -11,
      "name": "Rock_Stone"
    },
    {
      "x": -2,
      "y": -6,
      "z": -11,
      "name": "Rock_Stone"
    },
    {
      "x": -2,
      "y": -5,
      "z": -11,
      "name": "Rock_Stone"
    },
    {
      "x": -2,
      "y": -4,
      "z": -11,
      "name": "Rock_Stone"
    },
    {
      "x": -2,
      "y": -3,
      "z": -11,
      "name": "Rock_Stone"
    },
    {
      "x": -2,
      "y": -2,
      "z": -11,
      "name": "Rock_Stone"
    },
    {
      "x": -2,
      "y": -1,
      "z": -11,
      "name": "Rock_Stone_Cobble"
    },
    {
      "x": -2,
      "y": 0,
      "z": -11,
      "name": "Rock_Stone_Cobble"
    },
    {
      "x": -2,
      "y": 1,
      "z": -11,
      "name": "Rock_Stone"
    },
    {
      "x": -2,
      "y": 2,
      "z": -11,
      "name": "Rock_Stone"
    },
    {
      "x": -2,
      "y": 3,
      "z": -11,
      "name": "Rock_Stone"
    },
    {
      "x": -2,
      "y": 4,
      "z": -11,
      "name": "Rock_Stone"
    },
    {
      "x": -2,
      "y": 5,
      "z": -11,
      "name": "Rock_Stone"
    },
    {
      "x": -2,
      "y": 6,
      "z": -11,
      "name": "Rock_Stone"
    },
    {
      "x": -2,
      "y": 7,
      "z": -11,
      "name": "Rock_Stone"
    },
    {
      "x": -2,
      "y": 8,
      "z": -11,
      "name": "Rock_Stone"
    },
    {
      "x": -2,
      "y": 9,
      "z": -11,
      "name": "Rock_Stone"
    },
    {
      "x": -2,
      "y": 10,
      "z": -11,
      "name": "Rock_Stone"
    },
    {
      "x": -2,
      "y": -7,
      "z": -10,
      "name": "Rock_Stone"
    },
    {
      "x": -2,
      "y": -6,
      "z": -10,
      "name": "Rock_Stone"
    },
    {
      "x": -2,
      "y": -5,
      "z": -10,
      "name": "Rock_Stone"
    },
    {
      "x": -2,
      "y": -4,
      "z": -10,
      "name": "Rock_Stone"
    },
    {
      "x": -2,
      "y": -3,
      "z": -10,
      "name": "Rock_Stone"
    },
    {
      "x": -2,
      "y": -2,
      "z": -10,
      "name": "Rock_Stone"
    },
    {
      "x": -2,
      "y": -1,
      "z": -10,
      "name": "Soil_Ash"
    },
    {
      "x": -2,
      "y": 0,
      "z": -10,
      "name": "Rock_Stone_Brick_Pillar_Middle"
    },
    {
      "x": -2,
      "y": 1,
      "z": -10,
      "name": "Rock_Stone_Brick_Smooth"
    },
    {
      "x": -2,
      "y": 2,
      "z": -10,
      "name": "Rock_Stone_Brick_Pillar_Middle"
    },
    {
      "x": -2,
      "y": 3,
      "z": -10,
      "name": "Rock_Stone_Brick_Pillar_Base",
      "rotation": 8
    },
    {
      "x": -2,
      "y": 4,
      "z": -10,
      "name": "Rock_Stone_Brick_Smooth"
    },
    {
      "x": -2,
      "y": 5,
      "z": -10,
      "name": "Rock_Stone"
    },
    {
      "x": -2,
      "y": 6,
      "z": -10,
      "name": "Rock_Stone"
    },
    {
      "x": -2,
      "y": 7,
      "z": -10,
      "name": "Rock_Stone"
    },
    {
      "x": -2,
      "y": 8,
      "z": -10,
      "name": "Rock_Stone"
    },
    {
      "x": -2,
      "y": 9,
      "z": -10,
      "name": "Rock_Stone"
    },
    {
      "x": -2,
      "y": 10,
      "z": -10,
      "name": "Rock_Stone"
    },
    {
      "x": -2,
      "y": -7,
      "z": -9,
      "name": "Rock_Stone"
    },
    {
      "x": -2,
      "y": -6,
      "z": -9,
      "name": "Rock_Stone"
    },
    {
      "x": -2,
      "y": -5,
      "z": -9,
      "name": "Rock_Stone"
    },
    {
      "x": -2,
      "y": -4,
      "z": -9,
      "name": "Rock_Stone"
    },
    {
      "x": -2,
      "y": -3,
      "z": -9,
      "name": "Rock_Stone_Cobble"
    },
    {
      "x": -2,
      "y": -2,
      "z": -9,
      "name": "Rock_Stone"
    },
    {
      "x": -2,
      "y": -1,
      "z": -9,
      "name": "Soil_Ash"
    },
    {
      "x": -2,
      "y": 0,
      "z": -9,
      "name": "Block_Spawner_Block",
      "components": {
        "Components": {
          "BlockSpawner": {
            "BlockSpawnerId": "Zone1_Encounters_Tier3"
          }
        }
      }
    },
    {
      "x": -2,
      "y": 1,
      "z": -9,
      "name": "Empty"
    },
    {
      "x": -2,
      "y": 2,
      "z": -9,
      "name": "Empty"
    },
    {
      "x": -2,
      "y": 3,
      "z": -9,
      "name": "Empty"
    },
    {
      "x": -2,
      "y": 4,
      "z": -9,
      "name": "Empty"
    },
    {
      "x": -2,
      "y": 5,
      "z": -9,
      "name": "Rock_Stone"
    },
    {
      "x": -2,
      "y": 6,
      "z": -9,
      "name": "Rock_Stone"
    },
    {
      "x": -2,
      "y": 7,
      "z": -9,
      "name": "Rock_Stone"
    },
    {
      "x": -2,
      "y": 8,
      "z": -9,
      "name": "Rock_Stone"
    },
    {
      "x": -2,
      "y": 9,
      "z": -9,
      "name": "Rock_Stone"
    },
    {
      "x": -2,
      "y": 10,
      "z": -9,
      "name": "Rock_Stone"
    },
    {
      "x": -2,
      "y": -7,
      "z": -8,
      "name": "Rock_Stone"
    },
    {
      "x": -2,
      "y": -6,
      "z": -8,
      "name": "Rock_Stone"
    },
    {
      "x": -2,
      "y": -5,
      "z": -8,
      "name": "Rock_Stone"
    },
    {
      "x": -2,
      "y": -4,
      "z": -8,
      "name": "Rock_Stone"
    },
    {
      "x": -2,
      "y": -3,
      "z": -8,
      "name": "Rock_Stone_Cobble"
    },
    {
      "x": -2,
      "y": -2,
      "z": -8,
      "name": "Rock_Stone"
    },
    {
      "x": -2,
      "y": -1,
      "z": -8,
      "name": "Soil_Ash"
    },
    {
      "x": -2,
      "y": 0,
      "z": -8,
      "name": "Empty"
    },
    {
      "x": -2,
      "y": 1,
      "z": -8,
      "name": "Empty"
    },
    {
      "x": -2,
      "y": 2,
      "z": -8,
      "name": "Empty"
    },
    {
      "x": -2,
      "y": 3,
      "z": -8,
      "name": "Empty"
    },
    {
      "x": -2,
      "y": 4,
      "z": -8,
      "name": "Empty"
    },
    {
      "x": -2,
      "y": 5,
      "z": -8,
      "name": "Empty"
    },
    {
      "x": -2,
      "y": 6,
      "z": -8,
      "name": "Empty"
    },
    {
      "x": -2,
      "y": 7,
      "z": -8,
      "name": "Rock_Stone"
    },
    {
      "x": -2,
      "y": 8,
      "z": -8,
      "name": "Rock_Stone"
    },
    {
      "x": -2,
      "y": 9,
      "z": -8,
      "name": "Rock_Stone"
    },
    {
      "x": -2,
      "y": 10,
      "z": -8,
      "name": "Rock_Stone"
    },
    {
      "x": -2,
      "y": -7,
      "z": -7,
      "name": "Rock_Stone"
    },
    {
      "x": -2,
      "y": -6,
      "z": -7,
      "name": "Rock_Stone"
    },
    {
      "x": -2,
      "y": -5,
      "z": -7,
      "name": "Rock_Stone"
    },
    {
      "x": -2,
      "y": -4,
      "z": -7,
      "name": "Rock_Stone"
    },
    {
      "x": -2,
      "y": -3,
      "z": -7,
      "name": "Rock_Stone_Cobble"
    },
    {
      "x": -2,
      "y": -2,
      "z": -7,
      "name": "Rock_Stone"
    },
    {
      "x": -2,
      "y": -1,
      "z": -7,
      "name": "Soil_Ash"
    },
    {
      "x": -2,
      "y": 0,
      "z": -7,
      "name": "Deco_Bone_Skulls"
    },
    {
      "x": -2,
      "y": 1,
      "z": -7,
      "name": "Empty"
    },
    {
      "x": -2,
      "y": 2,
      "z": -7,
      "name": "Empty"
    },
    {
      "x": -2,
      "y": 3,
      "z": -7,
      "name": "Empty"
    },
    {
      "x": -2,
      "y": 4,
      "z": -7,
      "name": "Empty"
    },
    {
      "x": -2,
      "y": 5,
      "z": -7,
      "name": "Empty"
    },
    {
      "x": -2,
      "y": 6,
      "z": -7,
      "name": "Empty"
    },
    {
      "x": -2,
      "y": 7,
      "z": -7,
      "name": "Empty"
    },
    {
      "x": -2,
      "y": 8,
      "z": -7,
      "name": "Rock_Stone"
    },
    {
      "x": -2,
      "y": 9,
      "z": -7,
      "name": "Rock_Stone"
    },
    {
      "x": -2,
      "y": 10,
      "z": -7,
      "name": "Rock_Stone"
    },
    {
      "x": -2,
      "y": -7,
      "z": -6,
      "name": "Rock_Stone"
    },
    {
      "x": -2,
      "y": -6,
      "z": -6,
      "name": "Rock_Stone"
    },
    {
      "x": -2,
      "y": -5,
      "z": -6,
      "name": "Rock_Stone"
    },
    {
      "x": -2,
      "y": -4,
      "z": -6,
      "name": "Rock_Stone"
    },
    {
      "x": -2,
      "y": -3,
      "z": -6,
      "name": "Rock_Stone"
    },
    {
      "x": -2,
      "y": -2,
      "z": -6,
      "name": "Rock_Stone"
    },
    {
      "x": -2,
      "y": -1,
      "z": -6,
      "name": "Soil_Ash"
    },
    {
      "x": -2,
      "y": 0,
      "z": -6,
      "name": "Deco_Bone_Skulls"
    },
    {
      "x": -2,
      "y": 1,
      "z": -6,
      "name": "Empty"
    },
    {
      "x": -2,
      "y": 2,
      "z": -6,
      "name": "Empty"
    },
    {
      "x": -2,
      "y": 3,
      "z": -6,
      "name": "Empty"
    },
    {
      "x": -2,
      "y": 4,
      "z": -6,
      "name": "Empty"
    },
    {
      "x": -2,
      "y": 5,
      "z": -6,
      "name": "Empty"
    },
    {
      "x": -2,
      "y": 6,
      "z": -6,
      "name": "Empty"
    },
    {
      "x": -2,
      "y": 7,
      "z": -6,
      "name": "Rock_Stone_Stalactite_Large",
      "filler": 31744,
      "rotation": 8
    },
    {
      "x": -2,
      "y": 8,
      "z": -6,
      "name": "Rock_Stone_Stalactite_Large",
      "rotation": 8
    },
    {
      "x": -2,
      "y": 9,
      "z": -6,
      "name": "Rock_Stone"
    },
    {
      "x": -2,
      "y": 10,
      "z": -6,
      "name": "Rock_Stone"
    },
    {
      "x": -2,
      "y": -7,
      "z": -5,
      "name": "Rock_Stone"
    },
    {
      "x": -2,
      "y": -6,
      "z": -5,
      "name": "Rock_Stone"
    },
    {
      "x": -2,
      "y": -5,
      "z": -5,
      "name": "Rock_Stone"
    },
    {
      "x": -2,
      "y": -4,
      "z": -5,
      "name": "Rock_Stone"
    },
    {
      "x": -2,
      "y": -3,
      "z": -5,
      "name": "Rock_Stone"
    },
    {
      "x": -2,
      "y": -2,
      "z": -5,
      "name": "Rock_Stone"
    },
    {
      "x": -2,
      "y": -1,
      "z": -5,
      "name": "Soil_Ash"
    },
    {
      "x": -2,
      "y": 0,
      "z": -5,
      "name": "Empty"
    },
    {
      "x": -2,
      "y": 1,
      "z": -5,
      "name": "Empty"
    },
    {
      "x": -2,
      "y": 2,
      "z": -5,
      "name": "Empty"
    },
    {
      "x": -2,
      "y": 3,
      "z": -5,
      "name": "Empty"
    },
    {
      "x": -2,
      "y": 4,
      "z": -5,
      "name": "Empty"
    },
    {
      "x": -2,
      "y": 5,
      "z": -5,
      "name": "Empty"
    },
    {
      "x": -2,
      "y": 6,
      "z": -5,
      "name": "Empty"
    },
    {
      "x": -2,
      "y": 7,
      "z": -5,
      "name": "Empty"
    },
    {
      "x": -2,
      "y": 8,
      "z": -5,
      "name": "Empty"
    },
    {
      "x": -2,
      "y": 9,
      "z": -5,
      "name": "Rock_Stone"
    },
    {
      "x": -2,
      "y": 10,
      "z": -5,
      "name": "Rock_Stone"
    },
    {
      "x": -2,
      "y": -7,
      "z": -4,
      "name": "Rock_Stone"
    },
    {
      "x": -2,
      "y": -6,
      "z": -4,
      "name": "Rock_Stone"
    },
    {
      "x": -2,
      "y": -5,
      "z": -4,
      "name": "Rock_Stone"
    },
    {
      "x": -2,
      "y": -4,
      "z": -4,
      "name": "Rock_Stone"
    },
    {
      "x": -2,
      "y": -3,
      "z": -4,
      "name": "Rock_Stone"
    },
    {
      "x": -2,
      "y": -2,
      "z": -4,
      "name": "Rock_Stone"
    },
    {
      "x": -2,
      "y": -1,
      "z": -4,
      "name": "Soil_Ash"
    },
    {
      "x": -2,
      "y": 0,
      "z": -4,
      "name": "Deco_Bone_Skulls"
    },
    {
      "x": -2,
      "y": 1,
      "z": -4,
      "name": "Empty"
    },
    {
      "x": -2,
      "y": 2,
      "z": -4,
      "name": "Empty"
    },
    {
      "x": -2,
      "y": 3,
      "z": -4,
      "name": "Empty"
    },
    {
      "x": -2,
      "y": 4,
      "z": -4,
      "name": "Empty"
    },
    {
      "x": -2,
      "y": 5,
      "z": -4,
      "name": "Empty"
    },
    {
      "x": -2,
      "y": 6,
      "z": -4,
      "name": "Empty"
    },
    {
      "x": -2,
      "y": 7,
      "z": -4,
      "name": "Empty"
    },
    {
      "x": -2,
      "y": 8,
      "z": -4,
      "name": "Empty"
    },
    {
      "x": -2,
      "y": 9,
      "z": -4,
      "name": "Rock_Stone"
    },
    {
      "x": -2,
      "y": 10,
      "z": -4,
      "name": "Rock_Stone"
    },
    {
      "x": -2,
      "y": -7,
      "z": -3,
      "name": "Rock_Stone"
    },
    {
      "x": -2,
      "y": -6,
      "z": -3,
      "name": "Rock_Stone"
    },
    {
      "x": -2,
      "y": -5,
      "z": -3,
      "name": "Rock_Stone"
    },
    {
      "x": -2,
      "y": -4,
      "z": -3,
      "name": "Rock_Stone"
    },
    {
      "x": -2,
      "y": -3,
      "z": -3,
      "name": "Rock_Stone"
    },
    {
      "x": -2,
      "y": -2,
      "z": -3,
      "name": "Rock_Stone"
    },
    {
      "x": -2,
      "y": -1,
      "z": -3,
      "name": "Soil_Ash"
    },
    {
      "x": -2,
      "y": 0,
      "z": -3,
      "name": "Deco_Bone_Skulls"
    },
    {
      "x": -2,
      "y": 1,
      "z": -3,
      "name": "Empty"
    },
    {
      "x": -2,
      "y": 2,
      "z": -3,
      "name": "Empty"
    },
    {
      "x": -2,
      "y": 3,
      "z": -3,
      "name": "Empty"
    },
    {
      "x": -2,
      "y": 4,
      "z": -3,
      "name": "Empty"
    },
    {
      "x": -2,
      "y": 5,
      "z": -3,
      "name": "Empty"
    },
    {
      "x": -2,
      "y": 6,
      "z": -3,
      "name": "Empty"
    },
    {
      "x": -2,
      "y": 7,
      "z": -3,
      "name": "Empty"
    },
    {
      "x": -2,
      "y": 8,
      "z": -3,
      "name": "Rock_Stone"
    },
    {
      "x": -2,
      "y": 9,
      "z": -3,
      "name": "Rock_Stone"
    },
    {
      "x": -2,
      "y": 10,
      "z": -3,
      "name": "Rock_Stone"
    },
    {
      "x": -2,
      "y": -7,
      "z": -2,
      "name": "Rock_Stone"
    },
    {
      "x": -2,
      "y": -6,
      "z": -2,
      "name": "Rock_Stone"
    },
    {
      "x": -2,
      "y": -5,
      "z": -2,
      "name": "Rock_Stone"
    },
    {
      "x": -2,
      "y": -4,
      "z": -2,
      "name": "Rock_Stone"
    },
    {
      "x": -2,
      "y": -3,
      "z": -2,
      "name": "Rock_Stone"
    },
    {
      "x": -2,
      "y": -2,
      "z": -2,
      "name": "Rock_Stone"
    },
    {
      "x": -2,
      "y": -1,
      "z": -2,
      "name": "Rock_Stone"
    },
    {
      "x": -2,
      "y": 0,
      "z": -2,
      "name": "Rubble_Stone_Medium"
    },
    {
      "x": -2,
      "y": 1,
      "z": -2,
      "name": "Empty"
    },
    {
      "x": -2,
      "y": 2,
      "z": -2,
      "name": "Empty"
    },
    {
      "x": -2,
      "y": 3,
      "z": -2,
      "name": "Empty"
    },
    {
      "x": -2,
      "y": 4,
      "z": -2,
      "name": "Empty"
    },
    {
      "x": -2,
      "y": 5,
      "z": -2,
      "name": "Empty"
    },
    {
      "x": -2,
      "y": 6,
      "z": -2,
      "name": "Empty"
    },
    {
      "x": -2,
      "y": 7,
      "z": -2,
      "name": "Rock_Stone"
    },
    {
      "x": -2,
      "y": 8,
      "z": -2,
      "name": "Rock_Stone"
    },
    {
      "x": -2,
      "y": 9,
      "z": -2,
      "name": "Rock_Stone"
    },
    {
      "x": -2,
      "y": 10,
      "z": -2,
      "name": "Rock_Stone"
    },
    {
      "x": -2,
      "y": -7,
      "z": -1,
      "name": "Rock_Stone"
    },
    {
      "x": -2,
      "y": -6,
      "z": -1,
      "name": "Rock_Stone"
    },
    {
      "x": -2,
      "y": -5,
      "z": -1,
      "name": "Rock_Stone"
    },
    {
      "x": -2,
      "y": -4,
      "z": -1,
      "name": "Rock_Stone"
    },
    {
      "x": -2,
      "y": -3,
      "z": -1,
      "name": "Rock_Stone"
    },
    {
      "x": -2,
      "y": -2,
      "z": -1,
      "name": "Rock_Stone"
    },
    {
      "x": -2,
      "y": -1,
      "z": -1,
      "name": "Rock_Stone"
    },
    {
      "x": -2,
      "y": 0,
      "z": -1,
      "name": "Rock_Stone_Cobble"
    },
    {
      "x": -2,
      "y": 1,
      "z": -1,
      "name": "Rubble_Stone"
    },
    {
      "x": -2,
      "y": 2,
      "z": -1,
      "name": "Empty"
    },
    {
      "x": -2,
      "y": 3,
      "z": -1,
      "name": "Empty"
    },
    {
      "x": -2,
      "y": 4,
      "z": -1,
      "name": "Rock_Stone"
    },
    {
      "x": -2,
      "y": 5,
      "z": -1,
      "name": "Rock_Stone"
    },
    {
      "x": -2,
      "y": 6,
      "z": -1,
      "name": "Rock_Stone"
    },
    {
      "x": -2,
      "y": 7,
      "z": -1,
      "name": "Rock_Stone"
    },
    {
      "x": -2,
      "y": 8,
      "z": -1,
      "name": "Rock_Stone"
    },
    {
      "x": -2,
      "y": 9,
      "z": -1,
      "name": "Rock_Stone"
    },
    {
      "x": -2,
      "y": 10,
      "z": -1,
      "name": "Rock_Stone"
    },
    {
      "x": -2,
      "y": -7,
      "z": 0,
      "name": "Rock_Stone"
    },
    {
      "x": -2,
      "y": -6,
      "z": 0,
      "name": "Rock_Stone"
    },
    {
      "x": -2,
      "y": -5,
      "z": 0,
      "name": "Rock_Stone"
    },
    {
      "x": -2,
      "y": -4,
      "z": 0,
      "name": "Rock_Stone"
    },
    {
      "x": -2,
      "y": -3,
      "z": 0,
      "name": "Rock_Stone"
    },
    {
      "x": -2,
      "y": -2,
      "z": 0,
      "name": "Rock_Stone"
    },
    {
      "x": -2,
      "y": -1,
      "z": 0,
      "name": "Rock_Stone"
    },
    {
      "x": -2,
      "y": 0,
      "z": 0,
      "name": "Rock_Stone"
    },
    {
      "x": -2,
      "y": 1,
      "z": 0,
      "name": "Rock_Stone"
    },
    {
      "x": -2,
      "y": 2,
      "z": 0,
      "name": "Rock_Stone"
    },
    {
      "x": -2,
      "y": 3,
      "z": 0,
      "name": "Rock_Stone"
    },
    {
      "x": -2,
      "y": 4,
      "z": 0,
      "name": "Rock_Stone"
    },
    {
      "x": -2,
      "y": 5,
      "z": 0,
      "name": "Rock_Stone"
    },
    {
      "x": -2,
      "y": 6,
      "z": 0,
      "name": "Rock_Stone"
    },
    {
      "x": -2,
      "y": 7,
      "z": 0,
      "name": "Rock_Stone"
    },
    {
      "x": -2,
      "y": 8,
      "z": 0,
      "name": "Rock_Stone"
    },
    {
      "x": -2,
      "y": 9,
      "z": 0,
      "name": "Rock_Stone"
    },
    {
      "x": -2,
      "y": 10,
      "z": 0,
      "name": "Rock_Stone"
    },
    {
      "x": -1,
      "y": -7,
      "z": -12,
      "name": "Rock_Stone"
    },
    {
      "x": -1,
      "y": -6,
      "z": -12,
      "name": "Rock_Stone"
    },
    {
      "x": -1,
      "y": -5,
      "z": -12,
      "name": "Rock_Stone"
    },
    {
      "x": -1,
      "y": -4,
      "z": -12,
      "name": "Rock_Stone"
    },
    {
      "x": -1,
      "y": -3,
      "z": -12,
      "name": "Rock_Stone"
    },
    {
      "x": -1,
      "y": -2,
      "z": -12,
      "name": "Rock_Stone"
    },
    {
      "x": -1,
      "y": -1,
      "z": -12,
      "name": "Rock_Stone"
    },
    {
      "x": -1,
