{
  "version": 8,
  "blockIdVersion": 8,
  "anchorX": 9,
  "anchorY": 20,
  "anchorZ": 9,
  "blocks": [
    {
      "x": 0,
      "y": 17,
      "z": 5,
      "name": "Rock_Slate"
    },
    {
      "x": 0,
      "y": 18,
      "z": 5,
      "name": "Rock_Slate"
    },
    {
      "x": 0,
      "y": 19,
      "z": 5,
      "name": "Rock_Slate"
    },
    {
      "x": 0,
      "y": 20,
      "z": 5,
      "name": "Rock_Slate"
    },
    {
      "x": 0,
      "y": 16,
      "z": 6,
      "name": "Rock_Slate"
    },
    {
      "x": 0,
      "y": 17,
      "z": 6,
      "name": "Rock_Slate"
    },
    {
      "x": 0,
      "y": 18,
      "z": 6,
      "name": "Rock_Slate"
    },
    {
      "x": 0,
      "y": 19,
      "z": 6,
      "name": "Rock_Slate"
    },
    {
      "x": 0,
      "y": 20,
      "z": 6,
      "name": "Rock_Shale_Brick"
    },
    {
      "x": 0,
      "y": 21,
      "z": 6,
      "name": "Rock_Shale_Brick"
    },
    {
      "x": 0,
      "y": 14,
      "z": 7,
      "name": "Rock_Slate"
    },
    {
      "x": 0,
      "y": 15,
      "z": 7,
      "name": "Rock_Slate"
    },
    {
      "x": 0,
      "y": 16,
      "z": 7,
      "name": "Rock_Slate"
    },
    {
      "x": 0,
      "y": 17,
      "z": 7,
      "name": "Rock_Slate"
    },
    {
      "x": 0,
      "y": 18,
      "z": 7,
      "name": "Rock_Slate"
    },
    {
      "x": 0,
      "y": 19,
      "z": 7,
      "name": "Rock_Slate"
    },
    {
      "x": 0,
      "y": 20,
      "z": 7,
      "name": "Rock_Shale_Brick"
    },
    {
      "x": 0,
      "y": 21,
      "z": 7,
      "name": "Rock_Shale_Brick"
    },
    {
      "x": 0,
      "y": 13,
      "z": 8,
      "name": "Rock_Slate"
    },
    {
      "x": 0,
      "y": 14,
      "z": 8,
      "name": "Rock_Slate"
    },
    {
      "x": 0,
      "y": 15,
      "z": 8,
      "name": "Rock_Slate"
    },
    {
      "x": 0,
      "y": 16,
      "z": 8,
      "name": "Rock_Slate"
    },
    {
      "x": 0,
      "y": 17,
      "z": 8,
      "name": "Rock_Slate"
    },
    {
      "x": 0,
      "y": 18,
      "z": 8,
      "name": "Rock_Slate"
    },
    {
      "x": 0,
      "y": 19,
      "z": 8,
      "name": "Rock_Slate"
    },
    {
      "x": 0,
      "y": 20,
      "z": 8,
      "name": "Rock_Shale_Cobble"
    },
    {
      "x": 0,
      "y": 13,
      "z": 9,
      "name": "Rock_Slate"
    },
    {
      "x": 0,
      "y": 14,
      "z": 9,
      "name": "Rock_Slate"
    },
    {
      "x": 0,
      "y": 15,
      "z": 9,
      "name": "Rock_Slate"
    },
    {
      "x": 0,
      "y": 16,
      "z": 9,
      "name": "Rock_Slate"
    },
    {
      "x": 0,
      "y": 17,
      "z": 9,
      "name": "Rock_Slate"
    },
    {
      "x": 0,
      "y": 18,
      "z": 9,
      "name": "Rock_Slate"
    },
    {
      "x": 0,
      "y": 19,
      "z": 9,
      "name": "Rock_Slate"
    },
    {
      "x": 0,
      "y": 20,
      "z": 9,
      "name": "Rock_Shale_Cobble"
    },
    {
      "x": 0,
      "y": 13,
      "z": 10,
      "name": "Rock_Slate"
    },
    {
      "x": 0,
      "y": 14,
      "z": 10,
      "name": "Rock_Slate"
    },
    {
      "x": 0,
      "y": 15,
      "z": 10,
      "name": "Rock_Slate"
    },
    {
      "x": 0,
      "y": 16,
      "z": 10,
      "name": "Rock_Slate"
    },
    {
      "x": 0,
      "y": 17,
      "z": 10,
      "name": "Rock_Slate"
    },
    {
      "x": 0,
      "y": 18,
      "z": 10,
      "name": "Rock_Slate"
    },
    {
      "x": 0,
      "y": 19,
      "z": 10,
      "name": "Rock_Slate"
    },
    {
      "x": 0,
      "y": 20,
      "z": 10,
      "name": "Soil_Ash"
    },
    {
      "x": 0,
      "y": 15,
      "z": 11,
      "name": "Rock_Slate"
    },
    {
      "x": 0,
      "y": 16,
      "z": 11,
      "name": "Rock_Slate"
    },
    {
      "x": 0,
      "y": 17,
      "z": 11,
      "name": "Rock_Slate"
    },
    {
      "x": 0,
      "y": 18,
      "z": 11,
      "name": "Rock_Slate"
    },
    {
      "x": 0,
      "y": 19,
      "z": 11,
      "name": "Rock_Slate"
    },
    {
      "x": 0,
      "y": 20,
      "z": 11,
      "name": "Rock_Shale_Brick"
    },
    {
      "x": 0,
      "y": 21,
      "z": 11,
      "name": "Rock_Shale_Brick"
    },
    {
      "x": 0,
      "y": 16,
      "z": 12,
      "name": "Rock_Slate"
    },
    {
      "x": 0,
      "y": 17,
      "z": 12,
      "name": "Rock_Slate"
    },
    {
      "x": 0,
      "y": 18,
      "z": 12,
      "name": "Rock_Slate"
    },
    {
      "x": 0,
      "y": 19,
      "z": 12,
      "name": "Rock_Slate"
    },
    {
      "x": 0,
      "y": 20,
      "z": 12,
      "name": "Rock_Shale_Brick"
    },
    {
      "x": 0,
      "y": 21,
      "z": 12,
      "name": "Rock_Shale_Brick"
    },
    {
      "x": 0,
      "y": 17,
      "z": 13,
      "name": "Rock_Slate"
    },
    {
      "x": 0,
      "y": 18,
      "z": 13,
      "name": "Rock_Slate"
    },
    {
      "x": 0,
      "y": 19,
      "z": 13,
      "name": "Rock_Slate"
    },
    {
      "x": 0,
      "y": 20,
      "z": 13,
      "name": "Rock_Slate"
    },
    {
      "x": 1,
      "y": 18,
      "z": 3,
      "name": "Rock_Slate"
    },
    {
      "x": 1,
      "y": 19,
      "z": 3,
      "name": "Rock_Slate"
    },
    {
      "x": 1,
      "y": 20,
      "z": 3,
      "name": "Rock_Slate"
    },
    {
      "x": 1,
      "y": 16,
      "z": 4,
      "name": "Rock_Slate"
    },
    {
      "x": 1,
      "y": 17,
      "z": 4,
      "name": "Rock_Slate"
    },
    {
      "x": 1,
      "y": 18,
      "z": 4,
      "name": "Rock_Slate"
    },
    {
      "x": 1,
      "y": 19,
      "z": 4,
      "name": "Rock_Slate"
    },
    {
      "x": 1,
      "y": 20,
      "z": 4,
      "name": "Rock_Slate"
    },
    {
      "x": 1,
      "y": 15,
      "z": 5,
      "name": "Rock_Slate"
    },
    {
      "x": 1,
      "y": 16,
      "z": 5,
      "name": "Rock_Slate"
    },
    {
      "x": 1,
      "y": 17,
      "z": 5,
      "name": "Rock_Slate"
    },
    {
      "x": 1,
      "y": 18,
      "z": 5,
      "name": "Rock_Slate"
    },
    {
      "x": 1,
      "y": 19,
      "z": 5,
      "name": "Rock_Slate"
    },
    {
      "x": 1,
      "y": 20,
      "z": 5,
      "name": "Rock_Slate"
    },
    {
      "x": 1,
      "y": 13,
      "z": 6,
      "name": "Rock_Slate"
    },
    {
      "x": 1,
      "y": 14,
      "z": 6,
      "name": "Rock_Slate"
    },
    {
      "x": 1,
      "y": 15,
      "z": 6,
      "name": "Rock_Slate"
    },
    {
      "x": 1,
      "y": 16,
      "z": 6,
      "name": "Rock_Slate"
    },
    {
      "x": 1,
      "y": 17,
      "z": 6,
      "name": "Rock_Slate"
    },
    {
      "x": 1,
      "y": 18,
      "z": 6,
      "name": "Rock_Slate"
    },
    {
      "x": 1,
      "y": 19,
      "z": 6,
      "name": "Rock_Slate"
    },
    {
      "x": 1,
      "y": 20,
      "z": 6,
      "name": "Rock_Slate"
    },
    {
      "x": 1,
      "y": 12,
      "z": 7,
      "name": "Rock_Slate"
    },
    {
      "x": 1,
      "y": 13,
      "z": 7,
      "name": "Rock_Slate"
    },
    {
      "x": 1,
      "y": 14,
      "z": 7,
      "name": "Rock_Slate"
    },
    {
      "x": 1,
      "y": 15,
      "z": 7,
      "name": "Rock_Slate"
    },
    {
      "x": 1,
      "y": 16,
      "z": 7,
      "name": "Rock_Slate"
    },
    {
      "x": 1,
      "y": 17,
      "z": 7,
      "name": "Rock_Slate"
    },
    {
      "x": 1,
      "y": 18,
      "z": 7,
      "name": "Rock_Slate"
    },
    {
      "x": 1,
      "y": 19,
      "z": 7,
      "name": "Rock_Slate"
    },
    {
      "x": 1,
      "y": 20,
      "z": 7,
      "name": "Rock_Slate"
    },
    {
      "x": 1,
      "y": 10,
      "z": 8,
      "name": "Rock_Slate"
    },
    {
      "x": 1,
      "y": 11,
      "z": 8,
      "name": "Rock_Slate"
    },
    {
      "x": 1,
      "y": 12,
      "z": 8,
      "name": "Rock_Slate"
    },
    {
      "x": 1,
      "y": 13,
      "z": 8,
      "name": "Rock_Slate"
    },
    {
      "x": 1,
      "y": 14,
      "z": 8,
      "name": "Rock_Slate"
    },
    {
      "x": 1,
      "y": 15,
      "z": 8,
      "name": "Rock_Slate"
    },
    {
      "x": 1,
      "y": 16,
      "z": 8,
      "name": "Rock_Slate"
    },
    {
      "x": 1,
      "y": 17,
      "z": 8,
      "name": "Rock_Slate"
    },
    {
      "x": 1,
      "y": 18,
      "z": 8,
      "name": "Rock_Slate"
    },
    {
      "x": 1,
      "y": 19,
      "z": 8,
      "name": "Rock_Slate"
    },
    {
      "x": 1,
      "y": 20,
      "z": 8,
      "name": "Rock_Shale_Cobble"
    },
    {
      "x": 1,
      "y": 9,
      "z": 9,
      "name": "Rock_Slate"
    },
    {
      "x": 1,
      "y": 10,
      "z": 9,
      "name": "Rock_Slate"
    },
    {
      "x": 1,
      "y": 11,
      "z": 9,
      "name": "Rock_Slate"
    },
    {
      "x": 1,
      "y": 12,
      "z": 9,
      "name": "Rock_Slate"
    },
    {
      "x": 1,
      "y": 13,
      "z": 9,
      "name": "Rock_Slate"
    },
    {
      "x": 1,
      "y": 14,
      "z": 9,
      "name": "Rock_Slate"
    },
    {
      "x": 1,
      "y": 15,
      "z": 9,
      "name": "Rock_Slate"
    },
    {
      "x": 1,
      "y": 16,
      "z": 9,
      "name": "Rock_Slate"
    },
    {
      "x": 1,
      "y": 17,
      "z": 9,
      "name": "Rock_Slate"
    },
    {
      "x": 1,
      "y": 18,
      "z": 9,
      "name": "Rock_Slate"
    },
    {
      "x": 1,
      "y": 19,
      "z": 9,
      "name": "Rock_Slate"
    },
    {
      "x": 1,
      "y": 20,
      "z": 9,
      "name": "Rock_Shale_Cobble"
    },
    {
      "x": 1,
      "y": 11,
      "z": 10,
      "name": "Rock_Slate"
    },
    {
      "x": 1,
      "y": 12,
      "z": 10,
      "name": "Rock_Slate"
    },
    {
      "x": 1,
      "y": 13,
      "z": 10,
      "name": "Rock_Slate"
    },
    {
      "x": 1,
      "y": 14,
      "z": 10,
      "name": "Rock_Slate"
    },
    {
      "x": 1,
      "y": 15,
      "z": 10,
      "name": "Rock_Slate"
    },
    {
      "x": 1,
      "y": 16,
      "z": 10,
      "name": "Rock_Slate"
    },
    {
      "x": 1,
      "y": 17,
      "z": 10,
      "name": "Rock_Slate"
    },
    {
      "x": 1,
      "y": 18,
      "z": 10,
      "name": "Rock_Slate"
    },
    {
      "x": 1,
      "y": 19,
      "z": 10,
      "name": "Rock_Slate"
    },
    {
      "x": 1,
      "y": 20,
      "z": 10,
      "name": "Rock_Shale_Cobble"
    },
    {
      "x": 1,
      "y": 11,
      "z": 11,
      "name": "Rock_Slate"
    },
    {
      "x": 1,
      "y": 12,
      "z": 11,
      "name": "Rock_Slate"
    },
    {
      "x": 1,
      "y": 13,
      "z": 11,
      "name": "Rock_Slate"
    },
    {
      "x": 1,
      "y": 14,
      "z": 11,
      "name": "Rock_Slate"
    },
    {
      "x": 1,
      "y": 15,
      "z": 11,
      "name": "Rock_Slate"
    },
    {
      "x": 1,
      "y": 16,
      "z": 11,
      "name": "Rock_Slate"
    },
    {
      "x": 1,
      "y": 17,
      "z": 11,
      "name": "Rock_Slate"
    },
    {
      "x": 1,
      "y": 18,
      "z": 11,
      "name": "Rock_Slate"
    },
    {
      "x": 1,
      "y": 19,
      "z": 11,
      "name": "Rock_Slate"
    },
    {
      "x": 1,
      "y": 20,
      "z": 11,
      "name": "Soil_Ash"
    },
    {
      "x": 1,
      "y": 13,
      "z": 12,
      "name": "Rock_Slate"
    },
    {
      "x": 1,
      "y": 14,
      "z": 12,
      "name": "Rock_Slate"
    },
    {
      "x": 1,
      "y": 15,
      "z": 12,
      "name": "Rock_Slate"
    },
    {
      "x": 1,
      "y": 16,
      "z": 12,
      "name": "Rock_Slate"
    },
    {
      "x": 1,
      "y": 17,
      "z": 12,
      "name": "Rock_Slate"
    },
    {
      "x": 1,
      "y": 18,
      "z": 12,
      "name": "Rock_Slate"
    },
    {
      "x": 1,
      "y": 19,
      "z": 12,
      "name": "Rock_Slate"
    },
    {
      "x": 1,
      "y": 20,
      "z": 12,
      "name": "Rock_Slate"
    },
    {
      "x": 1,
      "y": 15,
      "z": 13,
      "name": "Rock_Slate"
    },
    {
      "x": 1,
      "y": 16,
      "z": 13,
      "name": "Rock_Slate"
    },
    {
      "x": 1,
      "y": 17,
      "z": 13,
      "name": "Rock_Slate"
    },
    {
      "x": 1,
      "y": 18,
      "z": 13,
      "name": "Rock_Slate"
    },
    {
      "x": 1,
      "y": 19,
      "z": 13,
      "name": "Rock_Slate"
    },
    {
      "x": 1,
      "y": 20,
      "z": 13,
      "name": "Rock_Slate"
    },
    {
      "x": 1,
      "y": 17,
      "z": 14,
      "name": "Rock_Slate"
    },
    {
      "x": 1,
      "y": 18,
      "z": 14,
      "name": "Rock_Slate"
    },
    {
      "x": 1,
      "y": 19,
      "z": 14,
      "name": "Rock_Slate"
    },
    {
      "x": 1,
      "y": 20,
      "z": 14,
      "name": "Rock_Slate"
    },
    {
      "x": 1,
      "y": 19,
      "z": 15,
      "name": "Rock_Slate"
    },
    {
      "x": 1,
      "y": 20,
      "z": 15,
      "name": "Rock_Slate"
    },
    {
      "x": 2,
      "y": 16,
      "z": 2,
      "name": "Rock_Slate"
    },
    {
      "x": 2,
      "y": 17,
      "z": 2,
      "name": "Rock_Slate"
    },
    {
      "x": 2,
      "y": 18,
      "z": 2,
      "name": "Rock_Slate"
    },
    {
      "x": 2,
      "y": 19,
      "z": 2,
      "name": "Soil_Ash"
    },
    {
      "x": 2,
      "y": 20,
      "z": 2,
      "name": "Soil_Ash"
    },
    {
      "x": 2,
      "y": 16,
      "z": 3,
      "name": "Rock_Slate"
    },
    {
      "x": 2,
      "y": 17,
      "z": 3,
      "name": "Rock_Slate"
    },
    {
      "x": 2,
      "y": 18,
      "z": 3,
      "name": "Rock_Slate"
    },
    {
      "x": 2,
      "y": 19,
      "z": 3,
      "name": "Rock_Slate"
    },
    {
      "x": 2,
      "y": 20,
      "z": 3,
      "name": "Soil_Ash"
    },
    {
      "x": 2,
      "y": 15,
      "z": 4,
      "name": "Rock_Slate"
    },
    {
      "x": 2,
      "y": 16,
      "z": 4,
      "name": "Rock_Slate"
    },
    {
      "x": 2,
      "y": 17,
      "z": 4,
      "name": "Rock_Slate"
    },
    {
      "x": 2,
      "y": 18,
      "z": 4,
      "name": "Rock_Slate"
    },
    {
      "x": 2,
      "y": 19,
      "z": 4,
      "name": "Rock_Slate"
    },
    {
      "x": 2,
      "y": 20,
      "z": 4,
      "name": "Soil_Ash"
    },
    {
      "x": 2,
      "y": 13,
      "z": 5,
      "name": "Rock_Slate"
    },
    {
      "x": 2,
      "y": 14,
      "z": 5,
      "name": "Rock_Slate"
    },
    {
      "x": 2,
      "y": 15,
      "z": 5,
      "name": "Rock_Slate"
    },
    {
      "x": 2,
      "y": 16,
      "z": 5,
      "name": "Rock_Slate"
    },
    {
      "x": 2,
      "y": 17,
      "z": 5,
      "name": "Rock_Slate"
    },
    {
      "x": 2,
      "y": 18,
      "z": 5,
      "name": "Rock_Slate"
    },
    {
      "x": 2,
      "y": 19,
      "z": 5,
      "name": "Rock_Slate"
    },
    {
      "x": 2,
      "y": 20,
      "z": 5,
      "name": "Soil_Ash"
    },
    {
      "x": 2,
      "y": 11,
      "z": 6,
      "name": "Rock_Slate"
    },
    {
      "x": 2,
      "y": 12,
      "z": 6,
      "name": "Rock_Slate"
    },
    {
      "x": 2,
      "y": 13,
      "z": 6,
      "name": "Rock_Slate"
    },
    {
      "x": 2,
      "y": 14,
      "z": 6,
      "name": "Rock_Slate"
    },
    {
      "x": 2,
      "y": 15,
      "z": 6,
      "name": "Rock_Slate"
    },
    {
      "x": 2,
      "y": 16,
      "z": 6,
      "name": "Rock_Slate"
    },
    {
      "x": 2,
      "y": 17,
      "z": 6,
      "name": "Rock_Slate"
    },
    {
      "x": 2,
      "y": 18,
      "z": 6,
      "name": "Rock_Slate"
    },
    {
      "x": 2,
      "y": 19,
      "z": 6,
      "name": "Rock_Slate"
    },
    {
      "x": 2,
      "y": 20,
      "z": 6,
      "name": "Soil_Ash"
    },
    {
      "x": 2,
      "y": 9,
      "z": 7,
      "name": "Rock_Slate"
    },
    {
      "x": 2,
      "y": 10,
      "z": 7,
      "name": "Rock_Slate"
    },
    {
      "x": 2,
      "y": 11,
      "z": 7,
      "name": "Rock_Slate"
    },
    {
      "x": 2,
      "y": 12,
      "z": 7,
      "name": "Rock_Slate"
    },
    {
      "x": 2,
      "y": 13,
      "z": 7,
      "name": "Rock_Slate"
    },
    {
      "x": 2,
      "y": 14,
      "z": 7,
      "name": "Rock_Slate"
    },
    {
      "x": 2,
      "y": 15,
      "z": 7,
      "name": "Rock_Slate"
    },
    {
      "x": 2,
      "y": 16,
      "z": 7,
      "name": "Rock_Slate"
    },
    {
      "x": 2,
      "y": 17,
      "z": 7,
      "name": "Rock_Slate"
    },
    {
      "x": 2,
      "y": 18,
      "z": 7,
      "name": "Rock_Slate"
    },
    {
      "x": 2,
      "y": 19,
      "z": 7,
      "name": "Rock_Slate"
    },
    {
      "x": 2,
      "y": 20,
      "z": 7,
      "name": "Rock_Shale_Brick"
    },
    {
      "x": 2,
      "y": 21,
      "z": 7,
      "name": "Rock_Shale_Brick"
    },
    {
      "x": 2,
      "y": 22,
      "z": 7,
      "name": "Rock_Shale_Brick"
    },
    {
      "x": 2,
      "y": 8,
      "z": 8,
      "name": "Rock_Slate"
    },
    {
      "x": 2,
      "y": 9,
      "z": 8,
      "name": "Rock_Slate"
    },
    {
      "x": 2,
      "y": 10,
      "z": 8,
      "name": "Rock_Slate"
    },
    {
      "x": 2,
      "y": 11,
      "z": 8,
      "name": "Rock_Slate"
    },
    {
      "x": 2,
      "y": 12,
      "z": 8,
      "name": "Rock_Slate"
    },
    {
      "x": 2,
      "y": 13,
      "z": 8,
      "name": "Rock_Slate"
    },
    {
      "x": 2,
      "y": 14,
      "z": 8,
      "name": "Rock_Slate"
    },
    {
      "x": 2,
      "y": 15,
      "z": 8,
      "name": "Rock_Slate"
    },
    {
      "x": 2,
      "y": 16,
      "z": 8,
      "name": "Rock_Slate"
    },
    {
      "x": 2,
      "y": 17,
      "z": 8,
      "name": "Rock_Slate"
    },
    {
      "x": 2,
      "y": 18,
      "z": 8,
      "name": "Rock_Slate"
    },
    {
      "x": 2,
      "y": 19,
      "z": 8,
      "name": "Rock_Slate"
    },
    {
      "x": 2,
      "y": 20,
      "z": 8,
      "name": "Soil_Ash"
    },
    {
      "x": 2,
      "y": 8,
      "z": 9,
      "name": "Rock_Slate"
    },
    {
      "x": 2,
      "y": 9,
      "z": 9,
      "name": "Rock_Slate"
    },
    {
      "x": 2,
      "y": 10,
      "z": 9,
      "name": "Rock_Slate"
    },
    {
      "x": 2,
      "y": 11,
      "z": 9,
      "name": "Rock_Slate"
    },
    {
      "x": 2,
      "y": 12,
      "z": 9,
      "name": "Rock_Slate"
    },
    {
      "x": 2,
      "y": 13,
      "z": 9,
      "name": "Rock_Slate"
    },
    {
      "x": 2,
      "y": 14,
      "z": 9,
      "name": "Rock_Slate"
    },
    {
      "x": 2,
      "y": 15,
      "z": 9,
      "name": "Rock_Slate"
    },
    {
      "x": 2,
      "y": 16,
      "z": 9,
      "name": "Rock_Slate"
    },
    {
      "x": 2,
      "y": 17,
      "z": 9,
      "name": "Rock_Slate"
    },
    {
      "x": 2,
      "y": 18,
      "z": 9,
      "name": "Rock_Slate"
    },
    {
      "x": 2,
      "y": 19,
      "z": 9,
      "name": "Rock_Slate"
    },
    {
      "x": 2,
      "y": 20,
      "z": 9,
      "name": "Rock_Shale_Cobble"
    },
    {
      "x": 2,
      "y": 9,
      "z": 10,
      "name": "Rock_Slate"
    },
    {
      "x": 2,
      "y": 10,
      "z": 10,
      "name": "Rock_Slate"
    },
    {
      "x": 2,
      "y": 11,
      "z": 10,
      "name": "Rock_Slate"
    },
    {
      "x": 2,
      "y": 12,
      "z": 10,
      "name": "Rock_Slate"
    },
    {
      "x": 2,
      "y": 13,
      "z": 10,
      "name": "Rock_Slate"
    },
    {
      "x": 2,
      "y": 14,
      "z": 10,
      "name": "Rock_Slate"
    },
    {
      "x": 2,
      "y": 15,
      "z": 10,
      "name": "Rock_Slate"
    },
    {
      "x": 2,
      "y": 16,
      "z": 10,
      "name": "Rock_Slate"
    },
    {
      "x": 2,
      "y": 17,
      "z": 10,
      "name": "Rock_Slate"
    },
    {
      "x": 2,
      "y": 18,
      "z": 10,
      "name": "Rock_Slate"
    },
    {
      "x": 2,
      "y": 19,
      "z": 10,
      "name": "Rock_Slate"
    },
    {
      "x": 2,
      "y": 20,
      "z": 10,
      "name": "Rock_Shale_Cobble"
    },
    {
      "x": 2,
      "y": 10,
      "z": 11,
      "name": "Rock_Slate"
    },
    {
      "x": 2,
      "y": 11,
      "z": 11,
      "name": "Rock_Slate"
    },
    {
      "x": 2,
      "y": 12,
      "z": 11,
      "name": "Rock_Slate"
    },
    {
      "x": 2,
      "y": 13,
      "z": 11,
      "name": "Rock_Slate"
    },
    {
      "x": 2,
      "y": 14,
      "z": 11,
      "name": "Rock_Slate"
    },
    {
      "x": 2,
      "y": 15,
      "z": 11,
      "name": "Rock_Slate"
    },
    {
      "x": 2,
      "y": 16,
      "z": 11,
      "name": "Rock_Slate"
    },
    {
      "x": 2,
      "y": 17,
      "z": 11,
      "name": "Rock_Slate"
    },
    {
      "x": 2,
      "y": 18,
      "z": 11,
      "name": "Rock_Slate"
    },
    {
      "x": 2,
      "y": 19,
      "z": 11,
      "name": "Rock_Slate"
    },
    {
      "x": 2,
      "y": 20,
      "z": 11,
      "name": "Rock_Shale_Brick"
    },
    {
      "x": 2,
      "y": 21,
      "z": 11,
      "name": "Rock_Shale_Brick"
    },
    {
      "x": 2,
      "y": 22,
      "z": 11,
      "name": "Rock_Shale_Brick"
    },
    {
      "x": 2,
      "y": 11,
      "z": 12,
      "name": "Rock_Slate"
    },
    {
      "x": 2,
      "y": 12,
      "z": 12,
      "name": "Rock_Slate"
    },
    {
      "x": 2,
      "y": 13,
      "z": 12,
      "name": "Rock_Slate"
    },
    {
      "x": 2,
      "y": 14,
      "z": 12,
      "name": "Rock_Slate"
    },
    {
      "x": 2,
      "y": 15,
      "z": 12,
      "name": "Rock_Slate"
    },
    {
      "x": 2,
      "y": 16,
      "z": 12,
      "name": "Rock_Slate"
    },
    {
      "x": 2,
      "y": 17,
      "z": 12,
      "name": "Rock_Slate"
    },
    {
      "x": 2,
      "y": 18,
      "z": 12,
      "name": "Rock_Slate"
    },
    {
      "x": 2,
      "y": 19,
      "z": 12,
      "name": "Rock_Slate"
    },
    {
      "x": 2,
      "y": 20,
      "z": 12,
      "name": "Rock_Slate"
    },
    {
      "x": 2,
      "y": 12,
      "z": 13,
      "name": "Rock_Slate"
    },
    {
      "x": 2,
      "y": 13,
      "z": 13,
      "name": "Rock_Slate"
    },
    {
      "x": 2,
      "y": 14,
      "z": 13,
      "name": "Rock_Slate"
    },
    {
      "x": 2,
      "y": 15,
      "z": 13,
      "name": "Rock_Slate"
    },
    {
      "x": 2,
      "y": 16,
      "z": 13,
      "name": "Rock_Slate"
    },
    {
      "x": 2,
      "y": 17,
      "z": 13,
      "name": "Rock_Slate"
    },
    {
      "x": 2,
      "y": 18,
      "z": 13,
      "name": "Rock_Slate"
    },
    {
      "x": 2,
      "y": 19,
      "z": 13,
      "name": "Rock_Slate"
    },
    {
      "x": 2,
      "y": 20,
      "z": 13,
      "name": "Rock_Slate"
    },
    {
      "x": 2,
      "y": 21,
      "z": 13,
      "name": "Rock_Shale_Cobble"
    },
    {
      "x": 2,
      "y": 22,
      "z": 13,
      "name": "Rock_Shale_Cobble"
    },
    {
      "x": 2,
      "y": 23,
      "z": 13,
      "name": "Rock_Shale_Cobble"
    },
    {
      "x": 2,
      "y": 24,
      "z": 13,
      "name": "Rock_Shale_Cobble"
    },
    {
      "x": 2,
      "y": 25,
      "z": 13,
      "name": "Rock_Shale_Cobble"
    },
    {
      "x": 2,
      "y": 26,
      "z": 13,
      "name": "Rock_Shale_Brick"
    },
    {
      "x": 2,
      "y": 14,
      "z": 14,
      "name": "Rock_Slate"
    },
    {
      "x": 2,
      "y": 15,
      "z": 14,
      "name": "Rock_Slate"
    },
    {
      "x": 2,
      "y": 16,
      "z": 14,
      "name": "Rock_Slate"
    },
    {
      "x": 2,
      "y": 17,
      "z": 14,
      "name": "Rock_Slate"
    },
    {
      "x": 2,
      "y": 18,
      "z": 14,
      "name": "Rock_Slate"
    },
    {
      "x": 2,
      "y": 19,
      "z": 14,
      "name": "Rock_Slate"
    },
    {
      "x": 2,
      "y": 20,
      "z": 14,
      "name": "Rock_Slate"
    },
    {
      "x": 2,
      "y": 21,
      "z": 14,
      "name": "Rock_Shale_Cobble"
    },
    {
      "x": 2,
      "y": 22,
      "z": 14,
      "name": "Rock_Shale_Cobble"
    },
    {
      "x": 2,
      "y": 23,
      "z": 14,
      "name": "Rock_Shale_Cobble"
    },
    {
      "x": 2,
      "y": 24,
      "z": 14,
      "name": "Rock_Shale_Cobble"
    },
    {
      "x": 2,
      "y": 25,
      "z": 14,
      "name": "Rock_Shale_Cobble"
    },
    {
      "x": 2,
      "y": 26,
      "z": 14,
      "name": "Rock_Shale_Brick"
    },
    {
      "x": 2,
      "y": 16,
      "z": 15,
      "name": "Rock_Slate"
    },
    {
      "x": 2,
      "y": 17,
      "z": 15,
      "name": "Rock_Slate"
    },
    {
      "x": 2,
      "y": 18,
      "z": 15,
      "name": "Rock_Slate"
    },
    {
      "x": 2,
      "y": 19,
      "z": 15,
      "name": "Rock_Slate"
    },
    {
      "x": 2,
      "y": 20,
      "z": 15,
      "name": "Rock_Slate"
    },
    {
      "x": 2,
      "y": 21,
      "z": 15,
      "name": "Rock_Shale_Cobble"
    },
    {
      "x": 2,
      "y": 22,
      "z": 15,
      "name": "Rock_Shale_Cobble"
    },
    {
      "x": 2,
      "y": 23,
      "z": 15,
      "name": "Rock_Shale_Cobble"
    },
    {
      "x": 2,
      "y": 24,
      "z": 15,
      "name": "Rock_Shale_Cobble"
    },
    {
      "x": 2,
      "y": 25,
      "z": 15,
      "name": "Rock_Shale_Cobble"
    },
    {
      "x": 2,
      "y": 26,
      "z": 15,
      "name": "Rock_Shale_Brick"
    },
    {
      "x": 2,
      "y": 19,
      "z": 16,
      "name": "Rock_Slate"
    },
    {
      "x": 2,
      "y": 20,
      "z": 16,
      "name": "Rock_Slate"
    },
    {
      "x": 3,
      "y": 18,
      "z": 1,
      "name": "Rock_Slate"
    },
    {
      "x": 3,
      "y": 19,
      "z": 1,
      "name": "Soil_Ash"
    },
    {
      "x": 3,
      "y": 20,
      "z": 1,
      "name": "Soil_Ash"
    },
    {
      "x": 3,
      "y": 16,
      "z": 2,
      "name": "Rock_Slate"
    },
    {
      "x": 3,
      "y": 17,
      "z": 2,
      "name": "Rock_Slate"
    },
    {
      "x": 3,
      "y": 18,
      "z": 2,
      "name": "Rock_Slate"
    },
    {
      "x": 3,
      "y": 19,
      "z": 2,
      "name": "Soil_Ash"
    },
    {
      "x": 3,
      "y": 20,
      "z": 2,
      "name": "Soil_Ash"
    },
    {
      "x": 3,
      "y": 15,
      "z": 3,
      "name": "Rock_Slate"
    },
    {
      "x": 3,
      "y": 16,
      "z": 3,
      "name": "Rock_Slate"
    },
    {
      "x": 3,
      "y": 17,
      "z": 3,
      "name": "Rock_Slate"
    },
    {
      "x": 3,
      "y": 18,
      "z": 3,
      "name": "Rock_Slate"
    },
    {
      "x": 3,
      "y": 19,
      "z": 3,
      "name": "Rock_Slate"
    },
    {
      "x": 3,
      "y": 20,
      "z": 3,
      "name": "Soil_Ash"
    },
    {
      "x": 3,
      "y": 13,
      "z": 4,
      "name": "Rock_Slate"
    },
    {
      "x": 3,
      "y": 14,
      "z": 4,
      "name": "Rock_Slate"
    },
    {
      "x": 3,
      "y": 15,
      "z": 4,
      "name": "Rock_Slate"
    },
    {
      "x": 3,
      "y": 16,
      "z": 4,
      "name": "Rock_Slate"
    },
    {
      "x": 3,
      "y": 17,
      "z": 4,
      "name": "Rock_Slate"
    },
    {
      "x": 3,
      "y": 18,
      "z": 4,
      "name": "Rock_Slate"
    },
    {
      "x": 3,
      "y": 19,
      "z": 4,
      "name": "Rock_Slate"
    },
    {
      "x": 3,
      "y": 20,
      "z": 4,
      "name": "Rock_Slate"
    },
    {
      "x": 3,
      "y": 11,
      "z": 5,
      "name": "Rock_Slate"
    },
    {
      "x": 3,
      "y": 12,
      "z": 5,
      "name": "Rock_Slate"
    },
    {
      "x": 3,
      "y": 13,
      "z": 5,
      "name": "Rock_Slate"
    },
    {
      "x": 3,
      "y": 14,
      "z": 5,
      "name": "Rock_Slate"
    },
    {
      "x": 3,
      "y": 15,
      "z": 5,
      "name": "Rock_Slate"
    },
    {
      "x": 3,
      "y": 16,
      "z": 5,
      "name": "Rock_Slate"
    },
    {
      "x": 3,
      "y": 17,
      "z": 5,
      "name": "Rock_Slate"
    },
    {
      "x": 3,
      "y": 18,
      "z": 5,
      "name": "Rock_Slate"
    },
    {
      "x": 3,
      "y": 19,
      "z": 5,
      "name": "Rock_Slate"
    },
    {
      "x": 3,
      "y": 20,
      "z": 5,
      "name": "Rock_Slate"
    },
    {
      "x": 3,
      "y": 11,
      "z": 6,
      "name": "Rock_Slate"
    },
    {
      "x": 3,
      "y": 12,
      "z": 6,
      "name": "Rock_Slate"
    },
    {
      "x": 3,
      "y": 13,
      "z": 6,
      "name": "Rock_Slate"
    },
    {
      "x": 3,
      "y": 14,
      "z": 6,
      "name": "Rock_Slate"
    },
    {
      "x": 3,
      "y": 15,
      "z": 6,
      "name": "Rock_Slate"
    },
    {
      "x": 3,
      "y": 16,
      "z": 6,
      "name": "Rock_Slate"
    },
    {
      "x": 3,
      "y": 17,
      "z": 6,
      "name": "Rock_Slate"
    },
    {
      "x": 3,
      "y": 18,
      "z": 6,
      "name": "Rock_Slate"
    },
    {
      "x": 3,
      "y": 19,
      "z": 6,
      "name": "Rock_Slate"
    },
    {
      "x": 3,
      "y": 20,
      "z": 6,
      "name": "Soil_Ash"
    },
    {
      "x": 3,
      "y": 9,
      "z": 7,
      "name": "Rock_Slate"
    },
    {
      "x": 3,
      "y": 10,
      "z": 7,
      "name": "Rock_Slate"
    },
    {
      "x": 3,
      "y": 11,
      "z": 7,
      "name": "Rock_Slate"
    },
    {
      "x": 3,
      "y": 12,
      "z": 7,
      "name": "Rock_Slate"
    },
    {
      "x": 3,
      "y": 13,
      "z": 7,
      "name": "Rock_Slate"
    },
    {
      "x": 3,
      "y": 14,
      "z": 7,
      "name": "Rock_Slate"
    },
    {
      "x": 3,
      "y": 15,
      "z": 7,
      "name": "Rock_Slate"
    },
    {
      "x": 3,
      "y": 16,
      "z": 7,
      "name": "Rock_Slate"
    },
    {
      "x": 3,
      "y": 17,
      "z": 7,
      "name": "Rock_Slate"
    },
    {
      "x": 3,
      "y": 18,
      "z": 7,
      "name": "Rock_Slate"
    },
    {
      "x": 3,
      "y": 19,
      "z": 7,
      "name": "Rock_Slate"
    },
    {
      "x": 3,
      "y": 20,
      "z": 7,
      "name": "Soil_Ash"
    },
    {
      "x": 3,
      "y": 7,
      "z": 8,
      "name": "Rock_Slate"
    },
    {
      "x": 3,
      "y": 8,
      "z": 8,
      "name": "Rock_Slate"
    },
    {
      "x": 3,
      "y": 9,
      "z": 8,
      "name": "Rock_Slate"
    },
    {
      "x": 3,
      "y": 10,
      "z": 8,
      "name": "Rock_Slate"
    },
    {
      "x": 3,
      "y": 11,
      "z": 8,
      "name": "Rock_Slate"
    },
    {
      "x": 3,
      "y": 12,
      "z": 8,
      "name": "Rock_Slate"
    },
    {
      "x": 3,
      "y": 13,
      "z": 8,
      "name": "Rock_Slate"
    },
    {
      "x": 3,
      "y": 14,
      "z": 8,
      "name": "Rock_Slate"
    },
    {
      "x": 3,
      "y": 15,
      "z": 8,
      "name": "Rock_Slate"
    },
    {
      "x": 3,
      "y": 16,
      "z": 8,
      "name": "Rock_Slate"
    },
    {
      "x": 3,
      "y": 17,
      "z": 8,
      "name": "Rock_Slate"
    },
    {
      "x": 3,
      "y": 18,
      "z": 8,
      "name": "Rock_Slate"
    },
    {
      "x": 3,
      "y": 19,
      "z": 8,
      "name": "Rock_Slate"
    },
    {
      "x": 3,
      "y": 20,
      "z": 8,
      "name": "Rock_Shale_Cobble"
    },
    {
      "x": 3,
      "y": 6,
      "z": 9,
      "name": "Rock_Slate"
    },
    {
      "x": 3,
      "y": 7,
      "z": 9,
      "name": "Rock_Slate"
    },
    {
      "x": 3,
      "y": 8,
      "z": 9,
      "name": "Rock_Slate"
    },
    {
      "x": 3,
      "y": 9,
      "z": 9,
      "name": "Rock_Slate"
    },
    {
      "x": 3,
      "y": 10,
      "z": 9,
      "name": "Rock_Slate"
    },
    {
      "x": 3,
      "y": 11,
      "z": 9,
      "name": "Rock_Slate"
    },
    {
      "x": 3,
      "y": 12,
      "z": 9,
      "name": "Rock_Slate"
    },
    {
      "x": 3,
      "y": 13,
      "z": 9,
      "name": "Rock_Slate"
    },
    {
      "x": 3,
      "y": 14,
      "z": 9,
      "name": "Rock_Slate"
    },
    {
      "x": 3,
      "y": 15,
      "z": 9,
      "name": "Rock_Slate"
    },
    {
      "x": 3,
      "y": 16,
      "z": 9,
      "name": "Rock_Slate"
    },
    {
      "x": 3,
      "y": 17,
      "z": 9,
      "name": "Rock_Slate"
    },
    {
      "x": 3,
      "y": 18,
      "z": 9,
      "name": "Rock_Slate"
    },
    {
      "x": 3,
      "y": 19,
      "z": 9,
      "name": "Rock_Slate"
    },
    {
      "x": 3,
      "y": 20,
      "z": 9,
      "name": "Rock_Shale_Cobble"
    },
    {
      "x": 3,
      "y": 7,
      "z": 10,
      "name": "Rock_Slate"
    },
    {
      "x": 3,
      "y": 8,
      "z": 10,
      "name": "Rock_Slate"
    },
    {
      "x": 3,
      "y": 9,
      "z": 10,
      "name": "Rock_Slate"
    },
    {
      "x": 3,
      "y": 10,
      "z": 10,
      "name": "Rock_Slate"
    },
    {
      "x": 3,
      "y": 11,
      "z": 10,
      "name": "Rock_Slate"
    },
    {
      "x": 3,
      "y": 12,
      "z": 10,
      "name": "Rock_Slate"
    },
    {
      "x": 3,
      "y": 13,
      "z": 10,
      "name": "Rock_Slate"
    },
    {
      "x": 3,
      "y": 14,
      "z": 10,
      "name": "Rock_Slate"
    },
    {
      "x": 3,
      "y": 15,
      "z": 10,
      "name": "Rock_Slate"
    },
    {
      "x": 3,
      "y": 16,
      "z": 10,
      "name": "Rock_Slate"
    },
    {
      "x": 3,
      "y": 17,
      "z": 10,
      "name": "Rock_Slate"
    },
    {
      "x": 3,
      "y": 18,
      "z": 10,
      "name": "Rock_Slate"
    },
    {
      "x": 3,
      "y": 19,
      "z": 10,
      "name": "Rock_Slate"
    },
    {
      "x": 3,
      "y": 20,
      "z": 10,
      "name": "Rock_Shale_Cobble"
    },
    {
      "x": 3,
      "y": 8,
      "z": 11,
      "name": "Rock_Slate"
    },
    {
      "x": 3,
      "y": 9,
      "z": 11,
      "name": "Rock_Slate"
    },
    {
      "x": 3,
      "y": 10,
      "z": 11,
      "name": "Rock_Slate"
    },
    {
      "x": 3,
      "y": 11,
      "z": 11,
      "name": "Rock_Slate"
    },
    {
      "x": 3,
      "y": 12,
      "z": 11,
      "name": "Rock_Slate"
    },
    {
      "x": 3,
      "y": 13,
      "z": 11,
      "name": "Rock_Slate"
    },
    {
      "x": 3,
      "y": 14,
      "z": 11,
      "name": "Rock_Slate"
    },
    {
      "x": 3,
      "y": 15,
      "z": 11,
      "name": "Rock_Slate"
    },
    {
      "x": 3,
      "y": 16,
      "z": 11,
      "name": "Rock_Slate"
    },
    {
      "x": 3,
      "y": 17,
      "z": 11,
      "name": "Rock_Slate"
    },
    {
      "x": 3,
      "y": 18,
      "z": 11,
      "name": "Rock_Slate"
    },
    {
      "x": 3,
      "y": 19,
      "z": 11,
      "name": "Rock_Slate"
    },
    {
      "x": 3,
      "y": 20,
      "z": 11,
      "name": "Soil_Ash"
    },
    {
      "x": 3,
      "y": 10,
      "z": 12,
      "name": "Rock_Slate"
    },
    {
      "x": 3,
      "y": 11,
      "z": 12,
      "name": "Rock_Slate"
    },
    {
      "x": 3,
      "y": 12,
      "z": 12,
      "name": "Rock_Slate"
    },
    {
      "x": 3,
      "y": 13,
      "z": 12,
      "name": "Rock_Slate"
    },
    {
      "x": 3,
      "y": 14,
      "z": 12,
      "name": "Rock_Slate"
    },
    {
      "x": 3,
      "y": 15,
      "z": 12,
      "name": "Rock_Slate"
    },
    {
      "x": 3,
      "y": 16,
      "z": 12,
      "name": "Rock_Slate"
    },
    {
      "x": 3,
      "y": 17,
      "z": 12,
      "name": "Rock_Slate"
    },
    {
      "x": 3,
      "y": 18,
      "z": 12,
      "name": "Rock_Slate"
    },
    {
      "x": 3,
      "y": 19,
      "z": 12,
      "name": "Rock_Slate"
    },
    {
      "x": 3,
      "y": 20,
      "z": 12,
      "name": "Soil_Ash"
    },
    {
      "x": 3,
      "y": 21,
      "z": 12,
      "name": "Rock_Shale_Cobble"
    },
    {
      "x": 3,
      "y": 22,
      "z": 12,
      "name": "Rock_Shale_Cobble"
    },
    {
      "x": 3,
      "y": 23,
      "z": 12,
      "name": "Rock_Shale_Cobble"
    },
    {
      "x": 3,
      "y": 24,
      "z": 12,
      "name": "Rock_Shale_Cobble"
    },
    {
      "x": 3,
      "y": 25,
      "z": 12,
      "name": "Rock_Shale_Cobble"
    },
    {
      "x": 3,
      "y": 26,
      "z": 12,
      "name": "Rock_Shale_Brick"
    },
    {
      "x": 3,
      "y": 11,
      "z": 13,
      "name": "Rock_Slate"
    },
    {
      "x": 3,
      "y": 12,
      "z": 13,
      "name": "Rock_Slate"
    },
    {
      "x": 3,
      "y": 13,
      "z": 13,
      "name": "Rock_Slate"
    },
    {
      "x": 3,
      "y": 14,
      "z": 13,
      "name": "Rock_Slate"
    },
    {
      "x": 3,
      "y": 15,
      "z": 13,
      "name": "Rock_Slate"
    },
    {
      "x": 3,
      "y": 16,
      "z": 13,
      "name": "Rock_Slate"
    },
    {
      "x": 3,
      "y": 17,
      "z": 13,
      "name": "Rock_Slate"
    },
    {
      "x": 3,
      "y": 18,
      "z": 13,
      "name": "Rock_Slate"
    },
    {
      "x": 3,
      "y": 19,
      "z": 13,
      "name": "Rock_Slate"
    },
    {
      "x": 3,
      "y": 20,
      "z": 13,
      "name": "Rock_Slate"
    },
    {
      "x": 3,
      "y": 21,
      "z": 13,
      "name": "Rock_Crystal_Green_Large"
    },
    {
      "x": 3,
      "y": 26,
      "z": 13,
      "name": "Rock_Shale_Cobble"
    },
    {
      "x": 3,
      "y": 27,
      "z": 13,
      "name": "Rock_Shale_Cobble"
    },
    {
      "x": 3,
      "y": 28,
      "z": 13,
      "name": "Rock_Shale_Cobble"
    },
    {
      "x": 3,
      "y": 29,
      "z": 13,
      "name": "Rock_Shale_Cobble"
    },
    {
      "x": 3,
      "y": 30,
      "z": 13,
      "name": "Rock_Shale_Cobble"
    },
    {
      "x": 3,
      "y": 31,
      "z": 13,
      "name": "Rock_Shale_Cobble"
    },
    {
      "x": 3,
      "y": 32,
      "z": 13,
      "name": "Rock_Shale_Cobble"
    },
    {
      "x": 3,
      "y": 33,
      "z": 13,
      "name": "Rock_Shale_Cobble"
    },
    {
      "x": 3,
      "y": 34,
      "z": 13,
      "name": "Rock_Shale_Cobble"
    },
    {
      "x": 3,
      "y": 35,
      "z": 13,
      "name": "Rock_Shale_Cobble"
    },
    {
      "x": 3,
      "y": 36,
      "z": 13,
      "name": "Rock_Shale_Cobble"
    },
    {
      "x": 3,
      "y": 38,
      "z": 13,
      "name": "Rock_Shale_Cobble"
    },
    {
      "x": 3,
      "y": 12,
      "z": 14,
      "name": "Rock_Slate"
    },
    {
      "x": 3,
      "y": 13,
      "z": 14,
      "name": "Rock_Slate"
    },
    {
      "x": 3,
      "y": 14,
      "z": 14,
      "name": "Rock_Slate"
    },
    {
      "x": 3,
      "y": 15,
      "z": 14,
      "name": "Rock_Slate"
    },
    {
      "x": 3,
      "y": 16,
      "z": 14,
      "name": "Rock_Slate"
    },
    {
      "x": 3,
      "y": 17,
      "z": 14,
      "name": "Rock_Slate"
    },
    {
      "x": 3,
      "y": 18,
      "z": 14,
      "name": "Rock_Slate"
    },
    {
      "x": 3,
      "y": 19,
      "z": 14,
      "name": "Rock_Slate"
    },
    {
      "x": 3,
      "y": 20,
      "z": 14,
      "name": "Rock_Slate"
    },
    {
      "x": 3,
      "y": 21,
      "z": 14,
      "name": "Rock_Crystal_Green_Large"
    },
    {
      "x": 3,
      "y": 26,
      "z": 14,
      "name": "Rock_Shale_Cobble"
    },
    {
      "x": 3,
      "y": 27,
      "z": 14,
      "name": "Rock_Shale_Cobble"
    },
    {
      "x": 3,
      "y": 28,
      "z": 14,
      "name": "Rock_Shale_Cobble"
    },
    {
      "x": 3,
      "y": 29,
      "z": 14,
      "name": "Rock_Shale_Cobble"
    },
    {
      "x": 3,
      "y": 30,
      "z": 14,
      "name": "Rock_Shale_Cobble"
    },
    {
      "x": 3,
      "y": 31,
      "z": 14,
      "name": "Rock_Shale_Cobble"
    },
    {
      "x": 3,
      "y": 32,
      "z": 14,
      "name": "Rock_Shale_Cobble"
    },
    {
      "x": 3,
      "y": 33,
      "z": 14,
      "name": "Rock_Shale_Cobble"
    },
    {
      "x": 3,
      "y": 34,
      "z": 14,
      "name": "Rock_Shale_Cobble"
    },
    {
      "x": 3,
      "y": 35,
      "z": 14,
      "name": "Rock_Shale_Cobble"
    },
    {
      "x": 3,
      "y": 36,
      "z": 14,
      "name": "Rock_Shale_Cobble"
    },
    {
      "x": 3,
      "y": 37,
      "z": 14,
      "name": "Rock_Shale_Cobble"
    },
    {
      "x": 3,
      "y": 38,
      "z": 14,
      "name": "Rock_Shale_Cobble"
    },
    {
      "x": 3,
      "y": 14,
      "z": 15,
      "name": "Rock_Slate"
    },
    {
      "x": 3,
      "y": 15,
      "z": 15,
      "name": "Rock_Slate"
    },
    {
      "x": 3,
      "y": 16,
      "z": 15,
      "name": "Rock_Slate"
    },
    {
      "x": 3,
      "y": 17,
      "z": 15,
      "name": "Rock_Slate"
    },
    {
      "x": 3,
      "y": 18,
      "z": 15,
      "name": "Rock_Slate"
    },
    {
      "x": 3,
      "y": 19,
      "z": 15,
      "name": "Rock_Slate"
    },
    {
      "x": 3,
      "y": 20,
      "z": 15,
      "name": "Rock_Slate"
    },
    {
      "x": 3,
      "y": 21,
      "z": 15,
      "name": "Rock_Crystal_Green_Large"
    },
    {
      "x": 3,
      "y": 22,
      "z": 15,
      "name": "Rock_Crystal_Green_Large"
    },
    {
      "x": 3,
      "y": 26,
      "z": 15,
      "name": "Rock_Shale_Cobble"
    },
    {
      "x": 3,
      "y": 27,
      "z": 15,
      "name": "Rock_Shale_Cobble"
    },
    {
      "x": 3,
      "y": 28,
      "z": 15,
      "name": "Rock_Shale_Cobble"
    },
    {
      "x": 3,
      "y": 29,
      "z": 15,
      "name": "Rock_Shale_Cobble"
    },
    {
      "x": 3,
      "y": 30,
      "z": 15,
      "name": "Rock_Shale_Cobble"
    },
    {
      "x": 3,
      "y": 31,
      "z": 15,
      "name": "Rock_Shale_Cobble"
    },
    {
      "x": 3,
      "y": 32,
      "z": 15,
      "name": "Rock_Shale_Cobble"
    },
    {
      "x": 3,
      "y": 33,
      "z": 15,
      "name": "Rock_Shale_Cobble"
    },
    {
      "x": 3,
      "y": 34,
      "z": 15,
      "name": "Rock_Shale_Cobble"
    },
    {
      "x": 3,
      "y": 35,
      "z": 15,
      "name": "Rock_Shale_Cobble"
    },
    {
      "x": 3,
      "y": 36,
      "z": 15,
      "name": "Rock_Shale_Cobble"
    },
    {
      "x": 3,
      "y": 38,
      "z": 15,
      "name": "Rock_Shale_Cobble"
    },
    {
      "x": 3,
      "y": 16,
      "z": 16,
      "name": "Rock_Slate"
    },
    {
      "x": 3,
      "y": 17,
      "z": 16,
      "name": "Rock_Slate"
    },
    {
      "x": 3,
      "y": 18,
      "z": 16,
      "name": "Rock_Slate"
    },
    {
      "x": 3,
      "y": 19,
      "z": 16,
      "name": "Rock_Slate"
    },
    {
      "x": 3,
      "y": 20,
      "z": 16,
      "name": "Rock_Slate"
    },
    {
      "x": 3,
      "y": 21,
      "z": 16,
      "name": "Rock_Shale_Cobble"
    },
    {
      "x": 3,
      "y": 22,
      "z": 16,
      "name": "Rock_Shale_Cobble"
    },
    {
      "x": 3,
      "y": 23,
      "z": 16,
      "name": "Rock_Shale_Cobble"
    },
    {
      "x": 3,
      "y": 24,
      "z": 16,
      "name": "Rock_Shale_Cobble"
    },
    {
      "x": 3,
      "y": 25,
      "z": 16,
      "name": "Rock_Shale_Cobble"
    },
    {
      "x": 3,
      "y": 26,
      "z": 16,
      "name": "Rock_Shale_Brick"
    },
    {
      "x": 3,
      "y": 19,
      "z": 17,
      "name": "Rock_Slate"
    },
    {
      "x": 3,
      "y": 20,
      "z": 17,
      "name": "Rock_Slate"
    },
    {
      "x": 4,
      "y": 16,
      "z": 1,
      "name": "Rock_Slate"
    },
    {
      "x": 4,
      "y": 17,
      "z": 1,
      "name": "Rock_Slate"
    },
    {
      "x": 4,
      "y": 18,
      "z": 1,
      "name": "Rock_Slate"
    },
    {
      "x": 4,
      "y": 19,
      "z": 1,
      "name": "Rock_Slate"
    },
    {
      "x": 4,
      "y": 20,
      "z": 1,
      "name": "Soil_Ash"
    },
    {
      "x": 4,
      "y": 15,
      "z": 2,
      "name": "Rock_Slate"
    },
    {
      "x": 4,
      "y": 16,
      "z": 2,
      "name": "Rock_Slate"
    },
    {
      "x": 4,
      "y": 17,
      "z": 2,
      "name": "Rock_Slate"
    },
    {
      "x": 4,
      "y": 18,
      "z": 2,
      "name": "Rock_Slate"
    },
    {
      "x": 4,
      "y": 19,
      "z": 2,
      "name": "Rock_Slate"
    },
    {
      "x": 4,
      "y": 20,
      "z": 2,
      "name": "Soil_Ash"
    },
    {
      "x": 4,
      "y": 13,
      "z": 3,
      "name": "Rock_Slate"
    },
    {
      "x": 4,
      "y": 14,
      "z": 3,
      "name": "Rock_Slate"
    },
    {
      "x": 4,
      "y": 15,
      "z": 3,
      "name": "Rock_Slate"
    },
    {
      "x": 4,
      "y": 16,
      "z": 3,
      "name": "Rock_Slate"
    },
    {
      "x": 4,
      "y": 17,
      "z": 3,
      "name": "Rock_Slate"
    },
    {
      "x": 4,
      "y": 18,
      "z": 3,
      "name": "Rock_Slate"
    },
    {
      "x": 4,
      "y": 19,
      "z": 3,
      "name": "Rock_Slate"
    },
    {
      "x": 4,
      "y": 20,
      "z": 3,
      "name": "Soil_Ash"
    },
    {
      "x": 4,
      "y": 12,
      "z": 4,
      "name": "Rock_Slate"
    },
    {
      "x": 4,
      "y": 13,
      "z": 4,
      "name": "Rock_Slate"
    },
    {
      "x": 4,
      "y": 14,
      "z": 4,
      "name": "Rock_Slate"
    },
    {
      "x": 4,
      "y": 15,
      "z": 4,
      "name": "Rock_Slate"
    },
    {
      "x": 4,
      "y": 16,
      "z": 4,
      "name": "Rock_Slate"
    },
    {
      "x": 4,
      "y": 17,
      "z": 4,
      "name": "Rock_Slate"
    },
    {
      "x": 4,
      "y": 18,
      "z": 4,
      "name": "Rock_Slate"
    },
    {
      "x": 4,
      "y": 19,
      "z": 4,
      "name": "Rock_Slate"
    },
    {
      "x": 4,
      "y": 20,
      "z": 4,
      "name": "Rock_Slate"
    },
    {
      "x": 4,
      "y": 21,
      "z": 4,
      "name": "Rock_Shale_Brick"
    },
    {
      "x": 4,
      "y": 12,
      "z": 5,
      "name": "Rock_Slate"
    },
    {
      "x": 4,
      "y": 13,
      "z": 5,
      "name": "Rock_Slate"
    },
    {
      "x": 4,
      "y": 14,
      "z": 5,
      "name": "Rock_Slate"
    },
    {
      "x": 4,
      "y": 15,
      "z": 5,
      "name": "Rock_Slate"
    },
    {
      "x": 4,
      "y": 16,
      "z": 5,
      "name": "Rock_Slate"
    },
    {
      "x": 4,
      "y": 17,
      "z": 5,
      "name": "Rock_Slate"
    },
    {
      "x": 4,
      "y": 18,
      "z": 5,
      "name": "Rock_Slate"
    },
    {
      "x": 4,
      "y": 19,
      "z": 5,
      "name": "Rock_Slate"
    },
    {
      "x": 4,
      "y": 20,
      "z": 5,
      "name": "Rock_Slate"
    },
    {
      "x": 4,
      "y": 21,
      "z": 5,
      "name": "Rock_Aqua_Brick"
    },
    {
      "x": 4,
      "y": 22,
      "z": 5,
      "name": "Rock_Shale_Brick"
    },
    {
      "x": 4,
      "y": 10,
      "z": 6,
      "name": "Rock_Slate"
    },
    {
      "x": 4,
      "y": 11,
      "z": 6,
      "name": "Rock_Slate"
    },
    {
      "x": 4,
      "y": 12,
      "z": 6,
      "name": "Rock_Slate"
    },
    {
      "x": 4,
      "y": 13,
      "z": 6,
      "name": "Rock_Slate"
    },
    {
      "x": 4,
      "y": 14,
      "z": 6,
      "name": "Rock_Slate"
    },
    {
      "x": 4,
      "y": 15,
      "z": 6,
      "name": "Rock_Slate"
    },
    {
      "x": 4,
      "y": 16,
      "z": 6,
      "name": "Rock_Slate"
    },
    {
      "x": 4,
      "y": 17,
      "z": 6,
      "name": "Rock_Slate"
    },
    {
      "x": 4,
      "y": 18,
      "z": 6,
      "name": "Rock_Slate"
    },
    {
      "x": 4,
      "y": 19,
      "z": 6,
      "name": "Rock_Slate"
    },
    {
      "x": 4,
      "y": 20,
      "z": 6,
      "name": "Rock_Slate"
    },
    {
      "x": 4,
      "y": 21,
      "z": 6,
      "name": "Rock_Aqua_Brick"
    },
    {
      "x": 4,
      "y": 22,
      "z": 6,
      "name": "Rock_Aqua_Brick"
    },
    {
      "x": 4,
      "y": 23,
      "z": 6,
      "name": "Rock_Shale_Brick"
    },
    {
      "x": 4,
      "y": 8,
      "z": 7,
      "name": "Rock_Slate"
    },
    {
      "x": 4,
      "y": 9,
      "z": 7,
      "name": "Rock_Slate"
    },
    {
      "x": 4,
      "y": 10,
      "z": 7,
      "name": "Rock_Slate"
    },
    {
      "x": 4,
      "y": 11,
      "z": 7,
      "name": "Rock_Slate"
    },
    {
      "x": 4,
      "y": 12,
      "z": 7,
      "name": "Rock_Slate"
    },
    {
      "x": 4,
      "y": 13,
      "z": 7,
      "name": "Rock_Slate"
    },
    {
      "x": 4,
      "y": 14,
      "z": 7,
      "name": "Rock_Slate"
    },
    {
      "x": 4,
      "y": 15,
      "z": 7,
      "name": "Rock_Slate"
    },
    {
      "x": 4,
      "y": 16,
      "z": 7,
      "name": "Rock_Slate"
    },
    {
      "x": 4,
      "y": 17,
      "z": 7,
      "name": "Rock_Slate"
    },
    {
      "x": 4,
      "y": 18,
      "z": 7,
      "name": "Rock_Slate"
    },
    {
      "x": 4,
      "y": 19,
      "z": 7,
      "name": "Rock_Slate"
    },
    {
      "x": 4,
      "y": 20,
      "z": 7,
      "name": "Rock_Shale_Brick"
    },
    {
      "x": 4,
      "y": 21,
      "z": 7,
      "name": "Rock_Shale_Brick"
    },
    {
      "x": 4,
      "y": 22,
      "z": 7,
      "name": "Rock_Shale_Brick"
    },
    {
      "x": 4,
      "y": 23,
      "z": 7,
      "name": "Rock_Shale_Brick"
    },
    {
      "x": 4,
      "y": 24,
      "z": 7,
      "name": "Rock_Shale_Brick"
    },
    {
      "x": 4,
      "y": 6,
      "z": 8,
      "name": "Rock_Slate"
    },
    {
      "x": 4,
      "y": 7,
      "z": 8,
      "name": "Rock_Slate"
    },
    {
      "x": 4,
      "y": 8,
      "z": 8,
      "name": "Rock_Slate"
    },
    {
      "x": 4,
      "y": 9,
      "z": 8,
      "name": "Rock_Slate"
    },
    {
      "x": 4,
      "y": 10,
      "z": 8,
      "name": "Rock_Slate"
    },
    {
      "x": 4,
      "y": 11,
      "z": 8,
      "name": "Rock_Slate"
    },
    {
      "x": 4,
      "y": 12,
      "z": 8,
      "name": "Rock_Slate"
    },
    {
      "x": 4,
      "y": 13,
      "z": 8,
      "name": "Rock_Slate"
    },
    {
      "x": 4,
      "y": 14,
      "z": 8,
      "name": "Rock_Slate"
    },
    {
      "x": 4,
      "y": 15,
      "z": 8,
      "name": "Rock_Slate"
    },
    {
      "x": 4,
      "y": 16,
      "z": 8,
      "name": "Rock_Slate"
    },
    {
      "x": 4,
      "y": 17,
      "z": 8,
      "name": "Rock_Slate"
    },
    {
      "x": 4,
      "y": 18,
      "z": 8,
      "name": "Rock_Slate"
    },
    {
      "x": 4,
      "y": 19,
      "z": 8,
      "name": "Rock_Slate"
    },
    {
      "x": 4,
      "y": 20,
      "z": 8,
      "name": "Rock_Shale_Cobble"
    },
    {
      "x": 4,
      "y": 5,
      "z": 9,
      "name": "Rock_Slate"
    },
    {
      "x": 4,
      "y": 6,
      "z": 9,
      "name": "Rock_Slate"
    },
    {
      "x": 4,
      "y": 7,
      "z": 9,
      "name": "Rock_Slate"
    },
    {
      "x": 4,
      "y": 8,
      "z": 9,
      "name": "Rock_Slate"
    },
    {
      "x": 4,
      "y": 9,
      "z": 9,
      "name": "Rock_Slate"
    },
    {
      "x": 4,
      "y": 10,
      "z": 9,
      "name": "Rock_Slate"
    },
    {
      "x": 4,
      "y": 11,
      "z": 9,
      "name": "Rock_Slate"
    },
    {
      "x": 4,
      "y": 12,
      "z": 9,
      "name": "Rock_Slate"
    },
    {
      "x": 4,
      "y": 13,
      "z": 9,
      "name": "Rock_Slate"
    },
    {
      "x": 4,
      "y": 14,
      "z": 9,
      "name": "Rock_Slate"
    },
    {
      "x": 4,
      "y": 15,
      "z": 9,
      "name": "Rock_Slate"
    },
    {
      "x": 4,
      "y": 16,
      "z": 9,
      "name": "Rock_Slate"
    },
    {
      "x": 4,
      "y": 17,
      "z": 9,
      "name": "Rock_Slate"
    },
    {
      "x": 4,
      "y": 18,
      "z": 9,
      "name": "Rock_Slate"
    },
    {
      "x": 4,
      "y": 19,
      "z": 9,
      "name": "Rock_Slate"
    },
    {
      "x": 4,
      "y": 20,
      "z": 9,
      "name": "Soil_Ash"
    },
    {
      "x": 4,
      "y": 6,
      "z": 10,
      "name": "Rock_Slate"
    },
    {
      "x": 4,
      "y": 7,
      "z": 10,
      "name": "Rock_Slate"
    },
    {
      "x": 4,
      "y": 8,
      "z": 10,
      "name": "Rock_Slate"
    },
    {
      "x": 4,
      "y": 9,
      "z": 10,
      "name": "Rock_Slate"
    },
    {
      "x": 4,
      "y": 10,
      "z": 10,
      "name": "Rock_Slate"
    },
    {
      "x": 4,
      "y": 11,
      "z": 10,
      "name": "Rock_Slate"
    },
    {
      "x": 4,
      "y": 12,
      "z": 10,
      "name": "Rock_Slate"
    },
    {
      "x": 4,
      "y": 13,
      "z": 10,
      "name": "Rock_Slate"
    },
    {
      "x": 4,
      "y": 14,
      "z": 10,
      "name": "Rock_Slate"
    },
    {
      "x": 4,
      "y": 15,
      "z": 10,
      "name": "Rock_Slate"
    },
    {
      "x": 4,
      "y": 16,
      "z": 10,
      "name": "Rock_Slate"
    },
    {
      "x": 4,
      "y": 17,
      "z": 10,
      "name": "Rock_Slate"
    },
    {
      "x": 4,
      "y": 18,
      "z": 10,
      "name": "Rock_Slate"
    },
    {
      "x": 4,
      "y": 19,
      "z": 10,
      "name": "Rock_Slate"
    },
    {
      "x": 4,
      "y": 20,
      "z": 10,
      "name": "Soil_Ash"
    },
    {
      "x": 4,
      "y": 7,
      "z": 11,
      "name": "Rock_Slate"
    },
    {
      "x": 4,
      "y": 8,
      "z": 11,
      "name": "Rock_Slate"
    },
    {
      "x": 4,
      "y": 9,
      "z": 11,
      "name": "Rock_Slate"
    },
    {
      "x": 4,
      "y": 10,
      "z": 11,
      "name": "Rock_Slate"
    },
    {
      "x": 4,
      "y": 11,
      "z": 11,
      "name": "Rock_Slate"
    },
    {
      "x": 4,
      "y": 12,
      "z": 11,
      "name": "Rock_Slate"
    },
    {
      "x": 4,
      "y": 13,
      "z": 11,
      "name": "Rock_Slate"
    },
    {
      "x": 4,
      "y": 14,
      "z": 11,
      "name": "Rock_Slate"
    },
    {
      "x": 4,
      "y": 15,
      "z": 11,
      "name": "Rock_Slate"
    },
    {
      "x": 4,
      "y": 16,
      "z": 11,
      "name": "Rock_Slate"
    },
    {
      "x": 4,
      "y": 17,
      "z": 11,
      "name": "Rock_Slate"
    },
    {
      "x": 4,
      "y": 18,
      "z": 11,
      "name": "Rock_Slate"
    },
    {
      "x": 4,
      "y": 19,
      "z": 11,
      "name": "Rock_Slate"
    },
    {
      "x": 4,
      "y": 20,
      "z": 11,
      "name": "Rock_Shale_Brick"
    },
    {
      "x": 4,
      "y": 8,
      "z": 12,
      "name": "Rock_Slate"
    },
    {
      "x": 4,
      "y": 9,
      "z": 12,
      "name": "Rock_Slate"
    },
    {
      "x": 4,
      "y": 10,
      "z": 12,
      "name": "Rock_Slate"
    },
    {
      "x": 4,
      "y": 11,
      "z": 12,
      "name": "Rock_Slate"
    },
    {
      "x": 4,
      "y": 12,
      "z": 12,
      "name": "Rock_Slate"
    },
    {
      "x": 4,
      "y": 13,
      "z": 12,
      "name": "Rock_Slate"
    },
    {
      "x": 4,
      "y": 14,
      "z": 12,
      "name": "Rock_Slate"
    },
    {
      "x": 4,
      "y": 15,
      "z": 12,
      "name": "Rock_Slate"
    },
    {
      "x": 4,
      "y": 16,
      "z": 12,
      "name": "Rock_Slate"
    },
    {
      "x": 4,
      "y": 17,
      "z": 12,
      "name": "Rock_Slate"
    },
    {
      "x": 4,
      "y": 18,
      "z": 12,
      "name": "Rock_Slate"
    },
    {
      "x": 4,
      "y": 19,
      "z": 12,
      "name": "Rock_Slate"
    },
    {
      "x": 4,
      "y": 20,
      "z": 12,
      "name": "Soil_Ash"
    },
    {
      "x": 4,
      "y": 21,
      "z": 12,
      "name": "Rock_Shale_Cobble"
    },
    {
      "x": 4,
      "y": 23,
      "z": 12,
      "name": "Rock_Shale_Brick"
    },
    {
      "x": 4,
      "y": 24,
      "z": 12,
      "name": "Rock_Shale_Cobble"
    },
    {
      "x": 4,
      "y": 25,
      "z": 12,
      "name": "Rock_Shale_Cobble"
    },
    {
      "x": 4,
      "y": 26,
      "z": 12,
      "name": "Rock_Shale_Brick"
    },
    {
      "x": 4,
      "y": 10,
      "z": 13,
      "name": "Rock_Slate"
    },
    {
      "x": 4,
      "y": 11,
      "z": 13,
      "name": "Rock_Slate"
    },
    {
      "x": 4,
      "y": 12,
      "z": 13,
      "name": "Rock_Slate"
    },
    {
      "x": 4,
      "y": 13,
      "z": 13,
      "name": "Rock_Slate"
    },
    {
      "x": 4,
      "y": 14,
      "z": 13,
      "name": "Rock_Slate"
    },
    {
      "x": 4,
      "y": 15,
      "z": 13,
      "name": "Rock_Slate"
    },
    {
      "x": 4,
      "y": 16,
      "z": 13,
      "name": "Rock_Slate"
    },
    {
      "x": 4,
      "y": 17,
      "z": 13,
      "name": "Rock_Slate"
    },
    {
      "x": 4,
      "y": 18,
      "z": 13,
      "name": "Rock_Slate"
    },
    {
      "x": 4,
      "y": 19,
      "z": 13,
      "name": "Rock_Slate"
    },
    {
      "x": 4,
      "y": 20,
      "z": 13,
      "name": "Rock_Slate"
    },
    {
      "x": 4,
      "y": 21,
      "z": 13,
      "name": "Rock_Crystal_Green_Large"
    },
    {
      "x": 4,
      "y": 26,
      "z": 13,
      "name": "Rock_Shale_Cobble"
    },
    {
      "x": 4,
      "y": 27,
      "z": 13,
      "name": "Rock_Shale_Cobble"
    },
    {
      "x": 4,
      "y": 28,
      "z": 13,
      "name": "Rock_Shale_Cobble"
    },
    {
      "x": 4,
      "y": 29,
      "z": 13,
      "name": "Rock_Shale_Cobble"
    },
    {
      "x": 4,
      "y": 30,
      "z": 13,
      "name": "Rock_Shale_Cobble"
    },
    {
      "x": 4,
      "y": 31,
      "z": 13,
      "name": "Rock_Shale_Cobble"
    },
    {
      "x": 4,
      "y": 32,
      "z": 13,
      "name": "Rock_Shale_Cobble"
    },
    {
      "x": 4,
      "y": 33,
      "z": 13,
      "name": "Rock_Shale_Cobble"
    },
    {
      "x": 4,
      "y": 34,
      "z": 13,
      "name": "Rock_Shale_Cobble"
    },
    {
      "x": 4,
      "y": 35,
      "z": 13,
      "name": "Rock_Shale_Cobble"
    },
    {
      "x": 4,
      "y": 36,
      "z": 13,
      "name": "Rock_Shale_Cobble"
    },
    {
      "x": 4,
      "y": 37,
      "z": 13,
      "name": "Rock_Shale_Cobble"
    },
    {
      "x": 4,
      "y": 38,
      "z": 13,
      "name": "Rock_Shale_Cobble"
    },
    {
      "x": 4,
      "y": 11,
      "z": 14,
      "name": "Rock_Slate"
    },
    {
      "x": 4,
      "y": 12,
      "z": 14,
      "name": "Rock_Slate"
    },
    {
      "x": 4,
      "y": 13,
      "z": 14,
      "name": "Rock_Slate"
    },
    {
      "x": 4,
      "y": 14,
      "z": 14,
      "name": "Rock_Slate"
    },
    {
      "x": 4,
      "y": 15,
      "z": 14,
      "name": "Rock_Slate"
    },
    {
      "x": 4,
      "y": 16,
      "z": 14,
      "name": "Rock_Slate"
    },
    {
      "x": 4,
      "y": 17,
      "z": 14,
      "name": "Rock_Slate"
    },
    {
      "x": 4,
      "y": 18,
      "z": 14,
      "name": "Rock_Slate"
    },
    {
      "x": 4,
      "y": 19,
      "z": 14,
      "name": "Rock_Slate"
    },
    {
      "x": 4,
      "y": 20,
      "z": 14,
      "name": "Rock_Slate"
    },
    {
      "x": 4,
      "y": 21,
      "z": 14,
      "name": "Rock_Crystal_Green_Large"
    },
    {
      "x": 4,
      "y": 12,
      "z": 15,
      "name": "Rock_Slate"
    },
    {
      "x": 4,
      "y": 13,
      "z": 15,
      "name": "Rock_Slate"
    },
    {
      "x": 4,
      "y": 14,
      "z": 15,
      "name": "Rock_Slate"
    },
    {
      "x": 4,
      "y": 15,
      "z": 15,
      "name": "Rock_Slate"
    },
    {
      "x": 4,
      "y": 16,
      "z": 15,
      "name": "Rock_Slate"
    },
    {
      "x": 4,
      "y": 17,
      "z": 15,
      "name": "Rock_Slate"
    },
    {
      "x": 4,
      "y": 18,
      "z": 15,
      "name": "Rock_Slate"
    },
    {
      "x": 4,
      "y": 19,
      "z": 15,
      "name": "Rock_Slate"
    },
    {
      "x": 4,
      "y": 20,
      "z": 15,
      "name": "Rock_Slate"
    },
    {
      "x": 4,
      "y": 21,
      "z": 15,
      "name": "Rock_Crystal_Green_Large"
    },
    {
      "x": 4,
      "y": 26,
      "z": 15,
      "name": "Rock_Shale_Cobble"
    },
    {
      "x": 4,
      "y": 27,
      "z": 15,
      "name": "Rock_Shale_Cobble"
    },
    {
      "x": 4,
      "y": 28,
      "z": 15,
      "name": "Rock_Shale_Cobble"
    },
    {
      "x": 4,
      "y": 29,
      "z": 15,
      "name": "Rock_Shale_Cobble"
    },
    {
      "x": 4,
      "y": 30,
      "z": 15,
      "name": "Rock_Shale_Cobble"
    },
    {
      "x": 4,
      "y": 31,
      "z": 15,
      "name": "Rock_Shale_Cobble"
    },
    {
      "x": 4,
      "y": 32,
      "z": 15,
      "name": "Rock_Shale_Cobble"
    },
    {
      "x": 4,
      "y": 33,
      "z": 15,
      "name": "Rock_Shale_Cobble"
    },
    {
      "x": 4,
      "y": 34,
      "z": 15,
      "name": "Rock_Shale_Cobble"
    },
    {
      "x": 4,
      "y": 35,
      "z": 15,
      "name": "Rock_Shale_Cobble"
    },
    {
      "x": 4,
      "y": 36,
      "z": 15,
      "name": "Rock_Shale_Cobble"
    },
    {
      "x": 4,
      "y": 37,
      "z": 15,
      "name": "Rock_Shale_Cobble"
    },
    {
      "x": 4,
      "y": 38,
      "z": 15,
      "name": "Rock_Shale_Cobble"
    },
    {
      "x": 4,
      "y": 14,
      "z": 16,
      "name": "Rock_Slate"
    },
    {
      "x": 4,
      "y": 15,
      "z": 16,
      "name": "Rock_Slate"
    },
    {
      "x": 4,
      "y": 16,
      "z": 16,
      "name": "Rock_Slate"
    },
    {
      "x": 4,
      "y": 17,
      "z": 16,
      "name": "Rock_Slate"
    },
    {
      "x": 4,
      "y": 18,
      "z": 16,
      "name": "Rock_Slate"
    },
    {
      "x": 4,
      "y": 19,
      "z": 16,
      "name": "Rock_Slate"
    },
    {
      "x": 4,
      "y": 20,
      "z": 16,
      "name": "Rock_Slate"
    },
    {
      "x": 4,
      "y": 21,
      "z": 16,
      "name": "Rock_Shale_Cobble"
    },
    {
      "x": 4,
      "y": 22,
      "z": 16,
      "name": "Rock_Shale_Cobble"
    },
    {
      "x": 4,
      "y": 23,
      "z": 16,
      "name": "Rock_Shale_Cobble"
    },
    {
      "x": 4,
      "y": 24,
      "z": 16,
      "name": "Rock_Shale_Cobble"
    },
    {
      "x": 4,
      "y": 25,
      "z": 16,
      "name": "Rock_Shale_Cobble"
    },
    {
      "x": 4,
      "y": 26,
      "z": 16,
      "name": "Rock_Shale_Brick"
    },
    {
      "x": 4,
      "y": 16,
      "z": 17,
      "name": "Rock_Slate"
    },
    {
      "x": 4,
      "y": 17,
      "z": 17,
      "name": "Rock_Slate"
    },
    {
      "x": 4,
      "y": 18,
      "z": 17,
      "name": "Rock_Slate"
    },
    {
      "x": 4,
      "y": 19,
      "z": 17,
      "name": "Rock_Slate"
    },
    {
      "x": 4,
      "y": 20,
      "z": 17,
      "name": "Rock_Slate"
    },
    {
      "x": 5,
      "y": 18,
      "z": 0,
      "name": "Rock_Slate"
    },
    {
      "x": 5,
      "y": 19,
      "z": 0,
      "name": "Rock_Slate"
    },
    {
      "x": 5,
      "y": 20,
      "z": 0,
      "name": "Rock_Slate"
    },
    {
      "x": 5,
      "y": 15,
      "z": 1,
      "name": "Rock_Slate"
    },
    {
      "x": 5,
      "y": 16,
      "z": 1,
      "name": "Rock_Slate"
    },
    {
      "x": 5,
      "y": 17,
      "z": 1,
      "name": "Rock_Slate"
    },
    {
      "x": 5,
      "y": 18,
      "z": 1,
      "name": "Rock_Slate"
    },
    {
      "x": 5,
      "y": 19,
      "z": 1,
      "name": "Rock_Slate"
    },
    {
      "x": 5,
      "y": 20,
      "z": 1,
      "name": "Rock_Slate"
    },
    {
      "x": 5,
      "y": 14,
      "z": 2,
      "name": "Rock_Slate"
    },
    {
      "x": 5,
      "y": 15,
      "z": 2,
      "name": "Rock_Slate"
    },
    {
      "x": 5,
      "y": 16,
      "z": 2,
      "name": "Rock_Slate"
    },
    {
      "x": 5,
      "y": 17,
      "z": 2,
      "name": "Rock_Slate"
    },
    {
      "x": 5,
      "y": 18,
      "z": 2,
      "name": "Rock_Slate"
    },
    {
      "x": 5,
      "y": 19,
      "z": 2,
      "name": "Rock_Slate"
    },
    {
      "x": 5,
      "y": 20,
      "z": 2,
      "name": "Soil_Ash"
    },
    {
      "x": 5,
      "y": 12,
      "z": 3,
      "name": "Rock_Slate"
    },
    {
      "x": 5,
      "y": 13,
      "z": 3,
      "name": "Rock_Slate"
    },
    {
      "x": 5,
      "y": 14,
      "z": 3,
      "name": "Rock_Slate"
    },
    {
      "x": 5,
      "y": 15,
      "z": 3,
      "name": "Rock_Slate"
    },
    {
      "x": 5,
      "y": 16,
      "z": 3,
      "name": "Rock_Slate"
    },
    {
      "x": 5,
      "y": 17,
      "z": 3,
      "name": "Rock_Slate"
    },
    {
      "x": 5,
      "y": 18,
      "z": 3,
      "name": "Rock_Slate"
    },
    {
      "x": 5,
      "y": 19,
      "z": 3,
      "name": "Rock_Slate"
    },
    {
      "x": 5,
      "y": 20,
      "z": 3,
      "name": "Rock_Slate"
    },
    {
      "x": 5,
      "y": 11,
      "z": 4,
      "name": "Rock_Slate"
    },
    {
      "x": 5,
      "y": 12,
      "z": 4,
      "name": "Rock_Slate"
    },
    {
      "x": 5,
      "y": 13,
      "z": 4,
      "name": "Rock_Slate"
    },
    {
      "x": 5,
      "y": 14,
      "z": 4,
      "name": "Rock_Slate"
    },
    {
      "x": 5,
      "y": 15,
      "z": 4,
      "name": "Rock_Slate"
    },
    {
      "x": 5,
      "y": 16,
      "z": 4,
      "name": "Rock_Slate"
    },
    {
      "x": 5,
      "y": 17,
      "z": 4,
      "name": "Rock_Slate"
    },
    {
      "x": 5,
      "y": 18,
      "z": 4,
      "name": "Rock_Slate"
    },
    {
      "x": 5,
      "y": 19,
      "z": 4,
      "name": "Rock_Slate"
    },
    {
      "x": 5,
      "y": 20,
      "z": 4,
      "name": "Rock_Slate"
    },
    {
      "x": 5,
      "y": 21,
      "z": 4,
      "name": "Rock_Aqua_Brick"
    },
    {
      "x": 5,
      "y": 22,
      "z": 4,
      "name": "Rock_Shale_Brick"
    },
    {
      "x": 5,
      "y": 10,
      "z": 5,
      "name": "Rock_Slate"
    },
    {
      "x": 5,
      "y": 11,
      "z": 5,
      "name": "Rock_Slate"
    },
    {
      "x": 5,
      "y": 12,
      "z": 5,
      "name": "Rock_Slate"
    },
    {
      "x": 5,
      "y": 13,
      "z": 5,
      "name": "Rock_Slate"
    },
    {
      "x": 5,
      "y": 14,
      "z": 5,
      "name": "Rock_Slate"
    },
    {
      "x": 5,
      "y": 15,
      "z": 5,
      "name": "Rock_Slate"
    },
    {
      "x": 5,
      "y": 16,
      "z": 5,
      "name": "Rock_Slate"
    },
    {
      "x": 5,
      "y": 17,
      "z": 5,
      "name": "Rock_Slate"
    },
    {
      "x": 5,
      "y": 18,
      "z": 5,
      "name": "Rock_Slate"
    },
    {
      "x": 5,
      "y": 19,
      "z": 5,
      "name": "Rock_Slate"
    },
    {
      "x": 5,
      "y": 20,
      "z": 5,
      "name": "Rock_Slate"
    },
    {
      "x": 5,
      "y": 9,
      "z": 6,
      "name": "Rock_Slate"
    },
    {
      "x": 5,
      "y": 10,
      "z": 6,
      "name": "Rock_Slate"
    },
    {
      "x": 5,
      "y": 11,
      "z": 6,
      "name": "Rock_Slate"
    },
    {
      "x": 5,
      "y": 12,
      "z": 6,
      "name": "Rock_Slate"
    },
    {
      "x": 5,
      "y": 13,
      "z": 6,
      "name": "Rock_Slate"
    },
    {
      "x": 5,
      "y": 14,
      "z": 6,
      "name": "Rock_Slate"
    },
    {
      "x": 5,
      "y": 15,
      "z": 6,
      "name": "Rock_Slate"
    },
    {
      "x": 5,
      "y": 16,
      "z": 6,
      "name": "Rock_Slate"
    },
    {
      "x": 5,
      "y": 17,
      "z": 6,
      "name": "Rock_Slate"
    },
    {
      "x": 5,
      "y": 18,
      "z": 6,
      "name": "Rock_Slate"
    },
    {
      "x": 5,
      "y": 19,
      "z": 6,
      "name": "Rock_Slate"
    },
    {
      "x": 5,
      "y": 20,
      "z": 6,
      "name": "Rock_Slate"
    },
    {
      "x": 5,
      "y": 6,
      "z": 7,
      "name": "Rock_Slate"
    },
    {
      "x": 5,
      "y": 7,
      "z": 7,
      "name": "Rock_Slate"
    },
    {
      "x": 5,
      "y": 8,
      "z": 7,
      "name": "Rock_Slate"
    },
    {
      "x": 5,
      "y": 9,
      "z": 7,
      "name": "Rock_Slate"
    },
    {
      "x": 5,
      "y": 10,
      "z": 7,
      "name": "Rock_Slate"
    },
    {
      "x": 5,
      "y": 11,
      "z": 7,
      "name": "Rock_Slate"
    },
    {
      "x": 5,
      "y": 12,
      "z": 7,
      "name": "Rock_Slate"
    },
    {
      "x": 5,
      "y": 13,
      "z": 7,
      "name": "Rock_Slate"
    },
    {
      "x": 5,
      "y": 14,
      "z": 7,
      "name": "Rock_Slate"
    },
    {
      "x": 5,
      "y": 15,
      "z": 7,
      "name": "Rock_Slate"
    },
    {
      "x": 5,
      "y": 16,
      "z": 7,
      "name": "Rock_Slate"
    },
    {
      "x": 5,
      "y": 17,
      "z": 7,
      "name": "Rock_Slate"
    },
    {
      "x": 5,
      "y": 18,
      "z": 7,
      "name": "Rock_Slate"
    },
    {
      "x": 5,
      "y": 19,
      "z": 7,
      "name": "Rock_Slate"
    },
    {
      "x": 5,
      "y": 20,
      "z": 7,
      "name": "Rock_Slate"
    },
    {
      "x": 5,
      "y": 5,
      "z": 8,
      "name": "Rock_Slate"
    },
    {
      "x": 5,
      "y": 6,
      "z": 8,
      "name": "Rock_Slate"
    },
    {
      "x": 5,
      "y": 7,
      "z": 8,
      "name": "Rock_Slate"
    },
    {
      "x": 5,
      "y": 8,
      "z": 8,
      "name": "Rock_Slate"
    },
    {
      "x": 5,
      "y": 9,
      "z": 8,
      "name": "Rock_Slate"
    },
    {
      "x": 5,
      "y": 10,
      "z": 8,
      "name": "Rock_Slate"
    },
    {
      "x": 5,
      "y": 11,
      "z": 8,
      "name": "Rock_Slate"
    },
    {
      "x": 5,
      "y": 12,
      "z": 8,
      "name": "Rock_Slate"
    },
    {
      "x": 5,
      "y": 13,
      "z": 8,
      "name": "Rock_Slate"
    },
    {
      "x": 5,
      "y": 14,
      "z": 8,
      "name": "Rock_Slate"
    },
    {
      "x": 5,
      "y": 15,
      "z": 8,
      "name": "Rock_Slate"
    },
    {
      "x": 5,
      "y": 16,
      "z": 8,
      "name": "Rock_Slate"
    },
    {
      "x": 5,
      "y": 17,
      "z": 8,
      "name": "Rock_Slate"
    },
    {
      "x": 5,
      "y": 18,
      "z": 8,
      "name": "Rock_Slate"
    },
    {
      "x": 5,
      "y": 19,
      "z": 8,
      "name": "Rock_Slate"
    },
    {
      "x": 5,
      "y": 20,
      "z": 8,
      "name": "Soil_Ash"
    },
    {
      "x": 5,
      "y": 4,
      "z": 9,
      "name": "Rock_Slate"
    },
    {
      "x": 5,
      "y": 5,
      "z": 9,
      "name": "Rock_Slate"
    },
    {
      "x": 5,
      "y": 6,
      "z": 9,
      "name": "Rock_Slate"
    },
    {
      "x": 5,
      "y": 7,
      "z": 9,
      "name": "Rock_Slate"
    },
    {
      "x": 5,
      "y": 8,
      "z": 9,
      "name": "Rock_Slate"
    },
    {
      "x": 5,
      "y": 9,
      "z": 9,
      "name": "Rock_Slate"
    },
    {
      "x": 5,
      "y": 10,
      "z": 9,
      "name": "Rock_Slate"
    },
    {
      "x": 5,
      "y": 11,
      "z": 9,
      "name": "Rock_Slate"
    },
    {
      "x": 5,
      "y": 12,
      "z": 9,
      "name": "Rock_Slate"
    },
    {
      "x": 5,
      "y": 13,
      "z": 9,
      "name": "Rock_Slate"
    },
    {
      "x": 5,
      "y": 14,
      "z": 9,
      "name": "Rock_Slate"
    },
    {
      "x": 5,
      "y": 15,
      "z": 9,
      "name": "Rock_Slate"
    },
    {
      "x": 5,
      "y": 16,
      "z": 9,
      "name": "Rock_Slate"
    },
    {
      "x": 5,
      "y": 17,
      "z": 9,
      "name": "Rock_Slate"
    },
    {
      "x": 5,
      "y": 18,
      "z": 9,
      "name": "Rock_Slate"
    },
    {
      "x": 5,
      "y": 19,
      "z": 9,
      "name": "Rock_Slate"
    },
    {
      "x": 5,
      "y": 20,
      "z": 9,
      "name": "Soil_Ash"
    },
    {
      "x": 5,
      "y": 5,
      "z": 10,
      "name": "Rock_Slate"
    },
    {
      "x": 5,
      "y": 6,
      "z": 10,
      "name": "Rock_Slate"
    },
    {
      "x": 5,
      "y": 7,
      "z": 10,
      "name": "Rock_Slate"
    },
    {
      "x": 5,
      "y": 8,
      "z": 10,
      "name": "Rock_Slate"
    },
    {
      "x": 5,
      "y": 9,
      "z": 10,
      "name": "Rock_Slate"
    },
    {
      "x": 5,
      "y": 10,
      "z": 10,
      "name": "Rock_Slate"
    },
    {
      "x": 5,
      "y": 11,
      "z": 10,
      "name": "Rock_Slate"
    },
    {
      "x": 5,
      "y": 12,
      "z": 10,
      "name": "Rock_Slate"
    },
    {
      "x": 5,
      "y": 13,
      "z": 10,
      "name": "Rock_Slate"
    },
    {
      "x": 5,
      "y": 14,
      "z": 10,
      "name": "Rock_Slate"
    },
    {
      "x": 5,
      "y": 15,
      "z": 10,
      "name": "Rock_Slate"
    },
    {
      "x": 5,
      "y": 16,
      "z": 10,
      "name": "Rock_Slate"
    },
    {
      "x": 5,
      "y": 17,
      "z": 10,
      "name": "Rock_Slate"
    },
    {
      "x": 5,
      "y": 18,
      "z": 10,
      "name": "Rock_Slate"
    },
    {
      "x": 5,
      "y": 19,
      "z": 10,
      "name": "Rock_Slate"
    },
    {
      "x": 5,
      "y": 20,
      "z": 10,
      "name": "Soil_Ash"
    },
    {
      "x": 5,
      "y": 6,
      "z": 11,
      "name": "Rock_Slate"
    },
    {
      "x": 5,
      "y": 7,
      "z": 11,
      "name": "Rock_Slate"
    },
    {
      "x": 5,
      "y": 8,
      "z": 11,
      "name": "Rock_Slate"
    },
    {
      "x": 5,
      "y": 9,
      "z": 11,
      "name": "Rock_Slate"
    },
    {
      "x": 5,
      "y": 10,
      "z": 11,
      "name": "Rock_Slate"
    },
    {
      "x": 5,
      "y": 11,
      "z": 11,
      "name": "Rock_Slate"
    },
    {
      "x": 5,
      "y": 12,
      "z": 11,
      "name": "Rock_Slate"
    },
    {
      "x": 5,
      "y": 13,
      "z": 11,
      "name": "Rock_Slate"
    },
    {
      "x": 5,
      "y": 14,
      "z": 11,
      "name": "Rock_Slate"
    },
    {
      "x": 5,
      "y": 15,
      "z": 11,
      "name": "Rock_Slate"
    },
    {
      "x": 5,
      "y": 16,
      "z": 11,
      "name": "Rock_Slate"
    },
    {
      "x": 5,
      "y": 17,
      "z": 11,
      "name": "Rock_Slate"
    },
    {
      "x": 5,
      "y": 18,
      "z": 11,
      "name": "Rock_Slate"
    },
    {
      "x": 5,
      "y": 19,
      "z": 11,
      "name": "Rock_Slate"
    },
    {
      "x": 5,
      "y": 20,
      "z": 11,
      "name": "Rock_Slate"
    },
    {
      "x": 5,
      "y": 6,
      "z": 12,
      "name": "Rock_Slate"
    },
    {
      "x": 5,
      "y": 8,
      "z": 12,
      "name": "Rock_Slate"
    },
    {
      "x": 5,
      "y": 9,
      "z": 12,
      "name": "Rock_Slate"
    },
    {
      "x": 5,
      "y": 10,
      "z": 12,
      "name": "Rock_Slate"
    },
    {
      "x": 5,
      "y": 11,
      "z": 12,
      "name": "Rock_Slate"
    },
    {
      "x": 5,
      "y": 12,
      "z": 12,
      "name": "Rock_Slate"
    },
    {
      "x": 5,
      "y": 13,
      "z": 12,
      "name": "Rock_Slate"
    },
    {
      "x": 5,
      "y": 14,
      "z": 12,
      "name": "Rock_Slate"
    },
    {
      "x": 5,
      "y": 15,
      "z": 12,
      "name": "Rock_Slate"
    },
    {
      "x": 5,
      "y": 16,
      "z": 12,
      "name": "Rock_Slate"
    },
    {
      "x": 5,
      "y": 17,
      "z": 12,
      "name": "Rock_Slate"
    },
    {
      "x": 5,
      "y": 18,
      "z": 12,
      "name": "Rock_Slate"
    },
    {
      "x": 5,
      "y": 19,
      "z": 12,
      "name": "Rock_Slate"
    },
    {
      "x": 5,
      "y": 20,
      "z": 12,
      "name": "Rock_Slate"
    },
    {
      "x": 5,
      "y": 21,
      "z": 12,
      "name": "Rock_Shale_Cobble"
    },
    {
      "x": 5,
      "y": 22,
      "z": 12,
      "name": "Rock_Shale_Cobble"
    },
    {
      "x": 5,
      "y": 23,
      "z": 12,
      "name": "Rock_Shale_Cobble"
    },
    {
      "x": 5,
      "y": 24,
      "z": 12,
      "name": "Rock_Shale_Cobble"
    },
    {
      "x": 5,
      "y": 25,
      "z": 12,
      "name": "Rock_Shale_Cobble"
    },
    {
      "x": 5,
      "y": 26,
      "z": 12,
      "name": "Rock_Shale_Brick"
    },
    {
      "x": 5,
      "y": 8,
      "z": 13,
      "name": "Rock_Slate"
    },
    {
      "x": 5,
      "y": 9,
      "z": 13,
      "name": "Rock_Slate"
    },
    {
      "x": 5,
      "y": 10,
      "z": 13,
      "name": "Rock_Slate"
    },
    {
      "x": 5,
      "y": 11,
      "z": 13,
      "name": "Rock_Slate"
    },
    {
      "x": 5,
      "y": 12,
      "z": 13,
      "name": "Rock_Slate"
    },
    {
      "x": 5,
      "y": 13,
      "z": 13,
      "name": "Rock_Slate"
    },
    {
      "x": 5,
      "y": 14,
      "z": 13,
      "name": "Rock_Slate"
    },
    {
      "x": 5,
      "y": 15,
      "z": 13,
      "name": "Rock_Slate"
    },
    {
      "x": 5,
      "y": 16,
      "z": 13,
      "name": "Rock_Slate"
    },
    {
      "x": 5,
      "y": 17,
      "z": 13,
      "name": "Rock_Slate"
    },
    {
      "x": 5,
      "y": 18,
      "z": 13,
      "name": "Rock_Slate"
    },
    {
      "x": 5,
      "y": 19,
      "z": 13,
      "name": "Rock_Slate"
    },
    {
      "x": 5,
      "y": 20,
      "z": 13,
      "name": "Rock_Slate"
    },
    {
      "x": 5,
      "y": 21,
      "z": 13,
      "name": "Rock_Crystal_Green_Large"
    },
    {
      "x": 5,
      "y": 26,
      "z": 13,
      "name": "Rock_Shale_Cobble"
    },
    {
      "x": 5,
      "y": 27,
      "z": 13,
      "name": "Rock_Shale_Cobble"
    },
    {
      "x": 5,
      "y": 28,
      "z": 13,
      "name": "Rock_Shale_Cobble"
    },
    {
      "x": 5,
      "y": 29,
      "z": 13,
      "name": "Rock_Shale_Cobble"
    },
    {
      "x": 5,
      "y": 30,
      "z": 13,
      "name": "Rock_Shale_Cobble"
    },
    {
      "x": 5,
      "y": 31,
      "z": 13,
      "name": "Rock_Shale_Cobble"
    },
    {
      "x": 5,
      "y": 32,
      "z": 13,
      "name": "Rock_Shale_Cobble"
    },
    {
      "x": 5,
      "y": 33,
      "z": 13,
      "name": "Rock_Shale_Cobble"
    },
    {
      "x": 5,
      "y": 34,
      "z": 13,
      "name": "Rock_Shale_Cobble"
    },
    {
      "x": 5,
      "y": 35,
      "z": 13,
      "name": "Rock_Shale_Cobble"
    },
    {
      "x": 5,
      "y": 36,
      "z": 13,
      "name": "Rock_Shale_Cobble"
    },
    {
      "x": 5,
      "y": 38,
      "z": 13,
      "name": "Rock_Shale_Cobble"
    },
    {
      "x": 5,
      "y": 10,
      "z": 14,
      "name": "Rock_Slate"
    },
    {
      "x": 5,
      "y": 11,
      "z": 14,
      "name": "Rock_Slate"
    },
    {
      "x": 5,
      "y": 12,
      "z": 14,
      "name": "Rock_Slate"
    },
    {
      "x": 5,
      "y": 13,
      "z": 14,
      "name": "Rock_Slate"
    },
    {
      "x": 5,
      "y": 14,
      "z": 14,
      "name": "Rock_Slate"
    },
    {
      "x": 5,
      "y": 15,
      "z": 14,
      "name": "Rock_Slate"
    },
    {
      "x": 5,
      "y": 16,
      "z": 14,
      "name": "Rock_Slate"
    },
    {
      "x": 5,
      "y": 17,
      "z": 14,
      "name": "Rock_Slate"
    },
    {
      "x": 5,
      "y": 18,
      "z": 14,
      "name": "Rock_Slate"
    },
    {
      "x": 5,
      "y": 19,
      "z": 14,
      "name": "Rock_Slate"
    },
    {
      "x": 5,
      "y": 20,
      "z": 14,
      "name": "Rock_Slate"
    },
    {
      "x": 5,
      "y": 21,
      "z": 14,
      "name": "Rock_Crystal_Green_Large"
    },
    {
      "x": 5,
      "y": 22,
      "z": 14,
      "name": "Rock_Crystal_Green_Large"
    },
    {
      "x": 5,
      "y": 26,
      "z": 14,
      "name": "Rock_Shale_Cobble"
    },
    {
      "x": 5,
      "y": 28,
      "z": 14,
      "name": "Rock_Shale_Cobble"
    },
    {
      "x": 5,
      "y": 29,
      "z": 14,
      "name": "Rock_Shale_Cobble"
    },
    {
      "x": 5,
      "y": 30,
      "z": 14,
      "name": "Rock_Shale_Cobble"
    },
    {
      "x": 5,
      "y": 31,
      "z": 14,
      "name": "Rock_Shale_Cobble"
    },
    {
      "x": 5,
      "y": 32,
      "z": 14,
      "name": "Rock_Shale_Cobble"
    },
    {
      "x": 5,
      "y": 33,
      "z": 14,
      "name": "Rock_Shale_Cobble"
    },
    {
      "x": 5,
      "y": 34,
      "z": 14,
      "name": "Rock_Shale_Cobble"
    },
    {
      "x": 5,
      "y": 35,
      "z": 14,
      "name": "Rock_Shale_Cobble"
    },
    {
      "x": 5,
      "y": 36,
      "z": 14,
      "name": "Rock_Shale_Cobble"
    },
    {
      "x": 5,
      "y": 37,
      "z": 14,
      "name": "Rock_Shale_Cobble"
    },
    {
      "x": 5,
      "y": 38,
      "z": 14,
      "name": "Rock_Shale_Cobble"
    },
    {
      "x": 5,
      "y": 11,
      "z": 15,
      "name": "Rock_Slate"
    },
    {
      "x": 5,
      "y": 12,
      "z": 15,
      "name": "Rock_Slate"
    },
    {
      "x": 5,
      "y": 13,
      "z": 15,
      "name": "Rock_Slate"
    },
    {
      "x": 5,
      "y": 14,
      "z": 15,
      "name": "Rock_Slate"
    },
    {
      "x": 5,
      "y": 15,
      "z": 15,
      "name": "Rock_Slate"
    },
    {
      "x": 5,
      "y": 16,
      "z": 15,
      "name": "Rock_Slate"
    },
    {
      "x": 5,
      "y": 17,
      "z": 15,
      "name": "Rock_Slate"
    },
    {
      "x": 5,
      "y": 18,
      "z": 15,
      "name": "Rock_Slate"
    },
    {
      "x": 5,
      "y": 19,
      "z": 15,
      "name": "Rock_Slate"
    },
    {
      "x": 5,
      "y": 20,
      "z": 15,
      "name": "Rock_Slate"
    },
    {
      "x": 5,
      "y": 21,
      "z": 15,
      "name": "Rock_Crystal_Green_Large"
    },
    {
      "x": 5,
      "y": 22,
      "z": 15,
      "name": "Rock_Crystal_Green_Large"
    },
    {
      "x": 5,
      "y": 26,
      "z": 15,
      "name": "Rock_Shale_Cobble"
    },
    {
      "x": 5,
      "y": 27,
      "z": 15,
      "name": "Rock_Shale_Cobble"
    },
    {
      "x": 5,
      "y": 28,
      "z": 15,
      "name": "Rock_Shale_Cobble"
    },
    {
      "x": 5,
      "y": 29,
      "z": 15,
      "name": "Rock_Shale_Cobble"
    },
    {
      "x": 5,
      "y": 30,
      "z": 15,
      "name": "Rock_Shale_Cobble"
    },
    {
      "x": 5,
      "y": 31,
      "z": 15,
      "name": "Rock_Shale_Cobble"
    },
    {
      "x": 5,
      "y": 32,
      "z": 15,
      "name": "Rock_Shale_Cobble"
    },
    {
      "x": 5,
      "y": 33,
      "z": 15,
      "name": "Rock_Shale_Cobble"
    },
    {
      "x": 5,
      "y": 34,
      "z": 15,
      "name": "Rock_Shale_Cobble"
    },
    {
      "x": 5,
      "y": 35,
      "z": 15,
      "name": "Rock_Shale_Cobble"
    },
    {
      "x": 5,
      "y": 36,
      "z": 15,
      "name": "Rock_Shale_Cobble"
    },
    {
      "x": 5,
      "y": 38,
      "z": 15,
      "name": "Rock_Shale_Cobble"
    },
    {
      "x": 5,
      "y": 12,
      "z": 16,
      "name": "Rock_Slate"
    },
    {
      "x": 5,
      "y": 13,
      "z": 16,
      "name": "Rock_Slate"
    },
    {
      "x": 5,
      "y": 14,
      "z": 16,
      "name": "Rock_Slate"
    },
    {
      "x": 5,
      "y": 15,
      "z": 16,
      "name": "Rock_Slate"
    },
    {
      "x": 5,
      "y": 16,
      "z": 16,
      "name": "Rock_Slate"
    },
    {
      "x": 5,
      "y": 17,
      "z": 16,
      "name": "Rock_Slate"
    },
    {
      "x": 5,
      "y": 18,
      "z": 16,
      "name": "Rock_Slate"
    },
    {
      "x": 5,
      "y": 19,
      "z": 16,
      "name": "Rock_Slate"
    },
    {
      "x": 5,
      "y": 20,
      "z": 16,
      "name": "Rock_Slate"
    },
    {
      "x": 5,
      "y": 21,
      "z": 16,
      "name": "Rock_Shale_Cobble"
    },
    {
      "x": 5,
      "y": 22,
      "z": 16,
      "name": "Rock_Shale_Cobble"
    },
    {
      "x": 5,
      "y": 23,
      "z": 16,
      "name": "Rock_Shale_Cobble"
    },
    {
      "x": 5,
      "y": 24,
      "z": 16,
      "name": "Rock_Shale_Cobble"
    },
    {
      "x": 5,
      "y": 25,
      "z": 16,
      "name": "Rock_Shale_Cobble"
    },
    {
      "x": 5,
      "y": 26,
      "z": 16,
      "name": "Rock_Shale_Brick"
    },
    {
      "x": 5,
      "y": 13,
      "z": 17,
      "name": "Rock_Slate"
    },
    {
      "x": 5,
      "y": 14,
      "z": 17,
      "name": "Rock_Slate"
    },
    {
      "x": 5,
      "y": 15,
      "z": 17,
      "name": "Rock_Slate"
    },
    {
      "x": 5,
      "y": 16,
      "z": 17,
      "name": "Rock_Slate"
    },
    {
      "x": 5,
      "y": 17,
      "z": 17,
      "name": "Rock_Slate"
    },
    {
      "x": 5,
      "y": 18,
      "z": 17,
      "name": "Rock_Slate"
    },
    {
      "x": 5,
      "y": 19,
      "z": 17,
      "name": "Rock_Slate"
    },
    {
      "x": 5,
      "y": 20,
      "z": 17,
      "name": "Rock_Slate"
    },
    {
      "x": 5,
      "y": 18,
      "z": 18,
      "name": "Rock_Slate"
    },
    {
      "x": 5,
      "y": 19,
      "z": 18,
      "name": "Rock_Slate"
    },
    {
      "x": 5,
      "y": 20,
      "z": 18,
      "name": "Rock_Slate"
    },
    {
      "x": 6,
      "y": 16,
      "z": 0,
      "name": "Rock_Slate"
    },
    {
      "x": 6,
      "y": 17,
      "z": 0,
      "name": "Rock_Slate"
    },
    {
      "x": 6,
      "y": 18,
      "z": 0,
      "name": "Rock_Slate"
    },
    {
      "x": 6,
      "y": 19,
      "z": 0,
      "name": "Rock_Slate"
    },
    {
      "x": 6,
      "y": 20,
      "z": 0,
      "name": "Rock_Shale_Brick"
    },
    {
      "x": 6,
      "y": 21,
      "z": 0,
      "name": "Rock_Shale_Brick"
    },
    {
      "x": 6,
      "y": 14,
      "z": 1,
      "name": "Rock_Slate"
    },
    {
      "x": 6,
      "y": 15,
      "z": 1,
      "name": "Rock_Slate"
    },
    {
      "x": 6,
      "y": 16,
      "z": 1,
      "name": "Rock_Slate"
    },
    {
      "x": 6,
      "y": 17,
      "z": 1,
      "name": "Rock_Slate"
    },
    {
      "x": 6,
      "y": 18,
      "z": 1,
      "name": "Rock_Slate"
    },
    {
      "x": 6,
      "y": 19,
      "z": 1,
      "name": "Rock_Slate"
    },
    {
      "x": 6,
      "y": 20,
      "z": 1,
      "name": "Soil_Ash"
    },
    {
      "x": 6,
      "y": 13,
      "z": 2,
      "name": "Rock_Slate"
    },
    {
      "x": 6,
      "y": 14,
      "z": 2,
      "name": "Rock_Slate"
    },
    {
      "x": 6,
      "y": 15,
      "z": 2,
      "name": "Rock_Slate"
    },
    {
      "x": 6,
      "y": 16,
      "z": 2,
      "name": "Rock_Slate"
    },
    {
      "x": 6,
      "y": 17,
      "z": 2,
      "name": "Rock_Slate"
    },
    {
      "x": 6,
      "y": 18,
      "z": 2,
      "name": "Rock_Slate"
    },
    {
      "x": 6,
      "y": 19,
      "z": 2,
      "name": "Rock_Slate"
    },
    {
      "x": 6,
      "y": 20,
      "z": 2,
      "name": "Soil_Ash"
    },
    {
      "x": 6,
      "y": 11,
      "z": 3,
      "name": "Rock_Slate"
    },
    {
      "x": 6,
      "y": 12,
      "z": 3,
      "name": "Rock_Slate"
    },
    {
      "x": 6,
      "y": 13,
      "z": 3,
      "name": "Rock_Slate"
    },
    {
      "x": 6,
      "y": 14,
      "z": 3,
      "name": "Rock_Slate"
    },
    {
      "x": 6,
      "y": 15,
      "z": 3,
      "name": "Rock_Slate"
    },
    {
      "x": 6,
      "y": 16,
      "z": 3,
      "name": "Rock_Slate"
    },
    {
      "x": 6,
      "y": 17,
      "z": 3,
      "name": "Rock_Slate"
    },
    {
      "x": 6,
      "y": 18,
      "z": 3,
      "name": "Rock_Slate"
    },
    {
      "x": 6,
      "y": 19,
      "z": 3,
      "name": "Rock_Slate"
    },
    {
      "x": 6,
      "y": 20,
      "z": 3,
      "name": "Rock_Slate"
    },
    {
      "x": 6,
      "y": 10,
      "z": 4,
      "name": "Rock_Slate"
    },
    {
      "x": 6,
      "y": 11,
      "z": 4,
      "name": "Rock_Slate"
    },
    {
      "x": 6,
      "y": 12,
      "z": 4,
      "name": "Rock_Slate"
    },
    {
      "x": 6,
      "y": 13,
      "z": 4,
      "name": "Rock_Slate"
    },
    {
      "x": 6,
      "y": 14,
      "z": 4,
      "name": "Rock_Slate"
    },
    {
      "x": 6,
      "y": 15,
      "z": 4,
      "name": "Rock_Slate"
    },
    {
      "x": 6,
      "y": 16,
      "z": 4,
      "name": "Rock_Slate"
    },
    {
      "x": 6,
      "y": 17,
      "z": 4,
      "name": "Rock_Slate"
    },
    {
      "x": 6,
      "y": 18,
      "z": 4,
      "name": "Rock_Slate"
    },
    {
      "x": 6,
      "y": 19,
      "z": 4,
      "name": "Rock_Slate"
    },
    {
      "x": 6,
      "y": 20,
      "z": 4,
      "name": "Rock_Slate"
    },
    {
      "x": 6,
      "y": 21,
      "z": 4,
      "name": "Rock_Aqua_Brick"
    },
    {
      "x": 6,
      "y": 22,
      "z": 4,
      "name": "Rock_Aqua_Brick"
    },
    {
      "x": 6,
      "y": 23,
      "z": 4,
      "name": "Rock_Shale_Brick"
    },
    {
      "x": 6,
      "y": 8,
      "z": 5,
      "name": "Rock_Slate"
    },
    {
      "x": 6,
      "y": 9,
      "z": 5,
      "name": "Rock_Slate"
    },
    {
      "x": 6,
      "y": 10,
      "z": 5,
      "name": "Rock_Slate"
    },
    {
      "x": 6,
      "y": 11,
      "z": 5,
      "name": "Rock_Slate"
    },
    {
      "x": 6,
      "y": 12,
      "z": 5,
      "name": "Rock_Slate"
    },
    {
      "x": 6,
      "y": 13,
      "z": 5,
      "name": "Rock_Slate"
    },
    {
      "x": 6,
      "y": 14,
      "z": 5,
      "name": "Rock_Slate"
    },
    {
      "x": 6,
      "y": 15,
      "z": 5,
      "name": "Rock_Slate"
    },
    {
      "x": 6,
      "y": 16,
      "z": 5,
      "name": "Rock_Slate"
    },
    {
      "x": 6,
      "y": 17,
      "z": 5,
      "name": "Rock_Slate"
    },
    {
      "x": 6,
      "y": 18,
      "z": 5,
      "name": "Rock_Slate"
    },
    {
      "x": 6,
      "y": 19,
      "z": 5,
      "name": "Rock_Slate"
    },
    {
      "x": 6,
      "y": 20,
      "z": 5,
      "name": "Rock_Slate"
    },
    {
      "x": 6,
      "y": 8,
      "z": 6,
      "name": "Rock_Slate"
    },
    {
      "x": 6,
      "y": 9,
      "z": 6,
      "name": "Rock_Slate"
    },
    {
      "x": 6,
      "y": 10,
      "z": 6,
      "name": "Rock_Slate"
    },
    {
      "x": 6,
      "y": 11,
      "z": 6,
      "name": "Rock_Slate"
    },
    {
      "x": 6,
      "y": 12,
      "z": 6,
      "name": "Rock_Slate"
    },
    {
      "x": 6,
      "y": 13,
      "z": 6,
      "name": "Rock_Slate"
    },
    {
      "x": 6,
      "y": 14,
      "z": 6,
      "name": "Rock_Slate"
    },
    {
      "x": 6,
      "y": 15,
      "z": 6,
      "name": "Rock_Slate"
    },
    {
      "x": 6,
      "y": 16,
      "z": 6,
      "name": "Rock_Slate"
    },
    {
      "x": 6,
      "y": 17,
      "z": 6,
      "name": "Rock_Slate"
    },
    {
      "x": 6,
      "y": 18,
      "z": 6,
      "name": "Rock_Slate"
    },
    {
      "x": 6,
      "y": 19,
      "z": 6,
      "name": "Rock_Slate"
    },
    {
      "x": 6,
      "y": 20,
      "z": 6,
      "name": "Soil_Ash"
    },
    {
      "x": 6,
      "y": 6,
      "z": 7,
      "name": "Rock_Slate"
    },
    {
      "x": 6,
      "y": 7,
      "z": 7,
      "name": "Rock_Slate"
    },
    {
      "x": 6,
      "y": 8,
      "z": 7,
      "name": "Rock_Slate"
    },
    {
      "x": 6,
      "y": 9,
      "z": 7,
      "name": "Rock_Slate"
    },
    {
      "x": 6,
      "y": 10,
      "z": 7,
      "name": "Rock_Slate"
    },
    {
      "x": 6,
      "y": 11,
      "z": 7,
      "name": "Rock_Slate"
    },
    {
      "x": 6,
      "y": 12,
      "z": 7,
      "name": "Rock_Slate"
    },
    {
      "x": 6,
      "y": 13,
      "z": 7,
      "name": "Rock_Slate"
    },
    {
      "x": 6,
      "y": 14,
      "z": 7,
      "name": "Rock_Slate"
    },
    {
      "x": 6,
      "y": 15,
      "z": 7,
      "name": "Rock_Slate"
    },
    {
      "x": 6,
      "y": 16,
      "z": 7,
      "name": "Rock_Slate"
    },
    {
      "x": 6,
      "y": 17,
      "z": 7,
      "name": "Rock_Slate"
    },
    {
      "x": 6,
      "y": 18,
      "z": 7,
      "name": "Rock_Slate"
    },
    {
      "x": 6,
      "y": 19,
      "z": 7,
      "name": "Rock_Slate"
    },
    {
      "x": 6,
      "y": 20,
      "z": 7,
      "name": "Soil_Ash"
    },
    {
      "x": 6,
      "y": 5,
      "z": 8,
      "name": "Rock_Slate"
    },
    {
      "x": 6,
      "y": 6,
      "z": 8,
      "name": "Rock_Slate"
    },
    {
      "x": 6,
      "y": 7,
      "z": 8,
      "name": "Rock_Slate"
    },
    {
      "x": 6,
      "y": 8,
      "z": 8,
      "name": "Rock_Slate"
    },
    {
      "x": 6,
      "y": 9,
      "z": 8,
      "name": "Rock_Slate"
    },
    {
      "x": 6,
      "y": 10,
      "z": 8,
      "name": "Rock_Slate"
    },
    {
      "x": 6,
      "y": 11,
      "z": 8,
      "name": "Rock_Slate"
    },
    {
      "x": 6,
      "y": 12,
      "z": 8,
      "name": "Rock_Slate"
    },
    {
      "x": 6,
      "y": 13,
      "z": 8,
      "name": "Rock_Slate"
    },
    {
      "x": 6,
      "y": 14,
      "z": 8,
      "name": "Rock_Slate"
    },
    {
      "x": 6,
      "y": 15,
      "z": 8,
      "name": "Rock_Slate"
    },
    {
      "x": 6,
      "y": 16,
      "z": 8,
      "name": "Rock_Slate"
    },
    {
      "x": 6,
      "y": 17,
      "z": 8,
      "name": "Rock_Slate"
    },
    {
      "x": 6,
      "y": 18,
      "z": 8,
      "name": "Rock_Slate"
    },
    {
      "x": 6,
      "y": 19,
      "z": 8,
      "name": "Rock_Slate"
    },
    {
      "x": 6,
      "y": 20,
      "z": 8,
      "name": "Soil_Ash"
    },
    {
      "x": 6,
      "y": 4,
      "z": 9,
      "name": "Rock_Slate"
    },
    {
      "x": 6,
      "y": 5,
      "z": 9,
      "name": "Rock_Slate"
    },
    {
      "x": 6,
      "y": 6,
      "z": 9,
      "name": "Rock_Slate"
    },
    {
      "x": 6,
      "y": 7,
      "z": 9,
      "name": "Rock_Slate"
    },
    {
      "x": 6,
      "y": 8,
      "z": 9,
      "name": "Rock_Slate"
    },
    {
      "x": 6,
      "y": 9,
      "z": 9,
      "name": "Rock_Slate"
    },
    {
      "x": 6,
      "y": 10,
      "z": 9,
      "name": "Rock_Slate"
    },
    {
      "x": 6,
      "y": 11,
      "z": 9,
      "name": "Rock_Slate"
    },
    {
      "x": 6,
      "y": 12,
      "z": 9,
      "name": "Rock_Slate"
    },
    {
      "x": 6,
      "y": 13,
      "z": 9,
      "name": "Rock_Slate"
    },
    {
      "x": 6,
      "y": 14,
      "z": 9,
      "name": "Rock_Slate"
    },
    {
      "x": 6,
      "y": 15,
      "z": 9,
      "name": "Rock_Slate"
    },
    {
      "x": 6,
      "y": 16,
      "z": 9,
      "name": "Rock_Slate"
    },
    {
      "x": 6,
      "y": 17,
      "z": 9,
      "name": "Rock_Slate"
    },
    {
      "x": 6,
      "y": 18,
      "z": 9,
      "name": "Rock_Slate"
    },
    {
      "x": 6,
      "y": 19,
      "z": 9,
      "name": "Rock_Slate"
    },
    {
      "x": 6,
      "y": 20,
      "z": 9,
      "name": "Soil_Ash"
    },
    {
      "x": 6,
      "y": 4,
      "z": 10,
      "name": "Rock_Slate"
    },
    {
      "x": 6,
      "y": 5,
      "z": 10,
      "name": "Rock_Slate"
    },
    {
      "x": 6,
      "y": 6,
      "z": 10,
      "name": "Rock_Slate"
    },
    {
      "x": 6,
      "y": 7,
      "z": 10,
      "name": "Rock_Slate"
    },
    {
      "x": 6,
      "y": 8,
      "z": 10,
      "name": "Rock_Slate"
    },
    {
      "x": 6,
      "y": 9,
      "z": 10,
      "name": "Rock_Slate"
    },
    {
      "x": 6,
      "y": 10,
      "z": 10,
      "name": "Rock_Slate"
    },
    {
      "x": 6,
      "y": 11,
      "z": 10,
      "name": "Rock_Slate"
    },
    {
      "x": 6,
      "y": 12,
      "z": 10,
      "name": "Rock_Slate"
    },
    {
      "x": 6,
      "y": 13,
      "z": 10,
      "name": "Rock_Slate"
    },
    {
      "x": 6,
      "y": 14,
      "z": 10,
      "name": "Rock_Slate"
    },
    {
      "x": 6,
      "y": 15,
      "z": 10,
      "name": "Rock_Slate"
    },
    {
      "x": 6,
      "y": 16,
      "z": 10,
      "name": "Rock_Slate"
    },
    {
      "x": 6,
      "y": 17,
      "z": 10,
      "name": "Rock_Slate"
    },
    {
      "x": 6,
      "y": 18,
      "z": 10,
      "name": "Rock_Slate"
    },
    {
      "x": 6,
      "y": 19,
      "z": 10,
      "name": "Rock_Slate"
    },
    {
      "x": 6,
      "y": 20,
      "z": 10,
      "name": "Soil_Ash"
    },
    {
      "x": 6,
      "y": 5,
      "z": 11,
      "name": "Rock_Slate"
    },
    {
      "x": 6,
      "y": 6,
      "z": 11,
      "name": "Rock_Slate"
    },
    {
      "x": 6,
      "y": 7,
      "z": 11,
      "name": "Rock_Slate"
    },
    {
      "x": 6,
      "y": 8,
      "z": 11,
      "name": "Rock_Slate"
    },
    {
      "x": 6,
      "y": 9,
      "z": 11,
      "name": "Rock_Slate"
    },
    {
      "x": 6,
      "y": 10,
      "z": 11,
      "name": "Rock_Slate"
    },
    {
      "x": 6,
      "y": 11,
      "z": 11,
      "name": "Rock_Slate"
    },
    {
      "x": 6,
      "y": 12,
      "z": 11,
      "name": "Rock_Slate"
    },
    {
      "x": 6,
      "y": 13,
      "z": 11,
      "name": "Rock_Slate"
    },
    {
      "x": 6,
      "y": 14,
      "z": 11,
      "name": "Rock_Slate"
    },
    {
      "x": 6,
      "y": 15,
      "z": 11,
      "name": "Rock_Slate"
    },
    {
      "x": 6,
      "y": 16,
      "z": 11,
      "name": "Rock_Slate"
    },
    {
      "x": 6,
      "y": 17,
      "z": 11,
      "name": "Rock_Slate"
    },
    {
      "x": 6,
      "y": 18,
      "z": 11,
      "name": "Rock_Slate"
    },
    {
      "x": 6,
      "y": 19,
      "z": 11,
      "name": "Rock_Slate"
    },
    {
      "x": 6,
      "y": 20,
      "z": 11,
      "name": "Rock_Slate"
    },
    {
      "x": 6,
      "y": 6,
      "z": 12,
      "name": "Rock_Slate"
    },
    {
      "x": 6,
      "y": 7,
      "z": 12,
      "name": "Rock_Slate"
    },
    {
      "x": 6,
      "y": 8,
      "z": 12,
      "name": "Rock_Slate"
    },
    {
      "x": 6,
      "y": 9,
      "z": 12,
      "name": "Rock_Slate"
    },
    {
      "x": 6,
      "y": 10,
      "z": 12,
      "name": "Rock_Slate"
    },
    {
      "x": 6,
      "y": 11,
      "z": 12,
      "name": "Rock_Slate"
    },
    {
      "x": 6,
      "y": 12,
      "z": 12,
      "name": "Rock_Slate"
    },
    {
      "x": 6,
      "y": 13,
      "z": 12,
      "name": "Rock_Slate"
    },
    {
      "x": 6,
      "y": 14,
      "z": 12,
      "name": "Rock_Slate"
    },
    {
      "x": 6,
      "y": 15,
      "z": 12,
      "name": "Rock_Slate"
    },
    {
      "x": 6,
      "y": 16,
      "z": 12,
      "name": "Rock_Slate"
    },
    {
      "x": 6,
      "y": 17,
      "z": 12,
      "name": "Rock_Slate"
    },
    {
      "x": 6,
      "y": 18,
      "z": 12,
      "name": "Rock_Slate"
    },
    {
      "x": 6,
      "y": 19,
      "z": 12,
      "name": "Rock_Slate"
    },
    {
      "x": 6,
      "y": 20,
      "z": 12,
      "name": "Soil_Ash"
    },
    {
      "x": 6,
      "y": 7,
      "z": 13,
      "name": "Rock_Slate"
    },
    {
      "x": 6,
      "y": 8,
      "z": 13,
      "name": "Rock_Slate"
    },
    {
      "x": 6,
      "y": 9,
      "z": 13,
      "name": "Rock_Slate"
    },
    {
      "x": 6,
      "y": 10,
      "z": 13,
      "name": "Rock_Slate"
    },
    {
      "x": 6,
      "y": 11,
      "z": 13,
      "name": "Rock_Slate"
    },
    {
      "x": 6,
      "y": 12,
      "z": 13,
      "name": "Rock_Slate"
    },
    {
      "x": 6,
      "y": 13,
      "z": 13,
      "name": "Rock_Slate"
    },
    {
      "x": 6,
      "y": 14,
      "z": 13,
      "name": "Rock_Slate"
    },
    {
      "x": 6,
      "y": 15,
      "z": 13,
      "name": "Rock_Slate"
    },
    {
      "x": 6,
      "y": 16,
      "z": 13,
      "name": "Rock_Slate"
    },
    {
      "x": 6,
      "y": 17,
      "z": 13,
      "name": "Rock_Slate"
    },
    {
      "x": 6,
      "y": 18,
      "z": 13,
      "name": "Rock_Slate"
    },
    {
      "x": 6,
      "y": 19,
      "z": 13,
      "name": "Rock_Slate"
    },
    {
      "x": 6,
      "y": 20,
      "z": 13,
      "name": "Rock_Slate"
    },
    {
      "x": 6,
      "y": 21,
      "z": 13,
      "name": "Rock_Shale_Cobble"
    },
    {
      "x": 6,
      "y": 22,
      "z": 13,
      "name": "Rock_Shale_Cobble"
    },
    {
      "x": 6,
      "y": 23,
      "z": 13,
      "name": "Rock_Shale_Cobble"
    },
    {
