{
  "version": 8,
  "blockIdVersion": 8,
  "anchorX": 0,
  "anchorY": 8,
  "anchorZ": 2,
  "blocks": [
    {
      "x": -11,
      "y": 0,
      "z": 2,
      "name": "Plant_Coral_Block_Purple"
    },
    {
      "x": -11,
      "y": 1,
      "z": 2,
      "name": "Plant_Coral_Block_Purple"
    },
    {
      "x": -11,
      "y": 2,
      "z": 2,
      "name": "Plant_Coral_Block_Purple"
    },
    {
      "x": -11,
      "y": 3,
      "z": 2,
      "name": "Plant_Coral_Block_Purple"
    },
    {
      "x": -11,
      "y": 4,
      "z": 2,
      "name": "Plant_Coral_Block_Purple"
    },
    {
      "x": -11,
      "y": 5,
      "z": 2,
      "name": "Plant_Coral_Block_Purple"
    },
    {
      "x": -11,
      "y": 6,
      "z": 2,
      "name": "Plant_Coral_Block_Purple"
    },
    {
      "x": -11,
      "y": 7,
      "z": 2,
      "name": "Plant_Coral_Block_Purple"
    },
    {
      "x": -11,
      "y": 0,
      "z": 3,
      "name": "Plant_Coral_Block_Purple"
    },
    {
      "x": -11,
      "y": 1,
      "z": 3,
      "name": "Plant_Coral_Block_Purple"
    },
    {
      "x": -11,
      "y": 2,
      "z": 3,
      "name": "Plant_Coral_Block_Purple"
    },
    {
      "x": -11,
      "y": 3,
      "z": 3,
      "name": "Plant_Coral_Block_Purple"
    },
    {
      "x": -11,
      "y": 4,
      "z": 3,
      "name": "Plant_Coral_Block_Purple"
    },
    {
      "x": -11,
      "y": 5,
      "z": 3,
      "name": "Plant_Coral_Block_Purple"
    },
    {
      "x": -11,
      "y": 6,
      "z": 3,
      "name": "Plant_Coral_Block_Purple"
    },
    {
      "x": -11,
      "y": 7,
      "z": 3,
      "name": "Plant_Coral_Block_Purple"
    },
    {
      "x": -11,
      "y": 8,
      "z": 3,
      "name": "Plant_Coral_Block_Purple"
    },
    {
      "x": -11,
      "y": 9,
      "z": 3,
      "name": "Plant_Coral_Block_Purple"
    },
    {
      "x": -11,
      "y": 0,
      "z": 4,
      "name": "Plant_Coral_Block_Purple"
    },
    {
      "x": -11,
      "y": 1,
      "z": 4,
      "name": "Plant_Coral_Block_Purple"
    },
    {
      "x": -11,
      "y": 2,
      "z": 4,
      "name": "Plant_Coral_Block_Purple"
    },
    {
      "x": -11,
      "y": 3,
      "z": 4,
      "name": "Plant_Coral_Block_Purple"
    },
    {
      "x": -11,
      "y": 4,
      "z": 4,
      "name": "Plant_Coral_Block_Purple"
    },
    {
      "x": -11,
      "y": 5,
      "z": 4,
      "name": "Plant_Coral_Block_Purple"
    },
    {
      "x": -11,
      "y": 6,
      "z": 4,
      "name": "Plant_Coral_Block_Purple"
    },
    {
      "x": -11,
      "y": 7,
      "z": 4,
      "name": "Plant_Coral_Block_Purple"
    },
    {
      "x": -11,
      "y": 8,
      "z": 4,
      "name": "Plant_Coral_Block_Purple"
    },
    {
      "x": -11,
      "y": 9,
      "z": 4,
      "name": "Plant_Coral_Block_Purple"
    },
    {
      "x": -11,
      "y": 6,
      "z": 5,
      "name": "Plant_Coral_Block_Purple"
    },
    {
      "x": -11,
      "y": 7,
      "z": 5,
      "name": "Plant_Coral_Block_Purple"
    },
    {
      "x": -11,
      "y": 8,
      "z": 5,
      "name": "Plant_Coral_Block_Purple"
    },
    {
      "x": -11,
      "y": 9,
      "z": 5,
      "name": "Plant_Coral_Block_Purple"
    },
    {
      "x": -10,
      "y": 0,
      "z": 1,
      "name": "Plant_Coral_Block_Purple"
    },
    {
      "x": -10,
      "y": 1,
      "z": 1,
      "name": "Plant_Coral_Block_Purple"
    },
    {
      "x": -10,
      "y": 2,
      "z": 1,
      "name": "Plant_Coral_Block_Purple"
    },
    {
      "x": -10,
      "y": 3,
      "z": 1,
      "name": "Plant_Coral_Block_Purple"
    },
    {
      "x": -10,
      "y": 4,
      "z": 1,
      "name": "Plant_Coral_Block_Purple"
    },
    {
      "x": -10,
      "y": 5,
      "z": 1,
      "name": "Plant_Coral_Block_Purple"
    },
    {
      "x": -10,
      "y": 6,
      "z": 1,
      "name": "Plant_Coral_Block_Purple"
    },
    {
      "x": -10,
      "y": 7,
      "z": 1,
      "name": "Plant_Coral_Block_Purple"
    },
    {
      "x": -10,
      "y": 0,
      "z": 2,
      "name": "Rock_Slate"
    },
    {
      "x": -10,
      "y": 1,
      "z": 2,
      "name": "Rock_Slate"
    },
    {
      "x": -10,
      "y": 2,
      "z": 2,
      "name": "Rock_Slate"
    },
    {
      "x": -10,
      "y": 3,
      "z": 2,
      "name": "Rock_Slate"
    },
    {
      "x": -10,
      "y": 4,
      "z": 2,
      "name": "Rock_Slate"
    },
    {
      "x": -10,
      "y": 5,
      "z": 2,
      "name": "Rock_Slate"
    },
    {
      "x": -10,
      "y": 6,
      "z": 2,
      "name": "Rock_Slate"
    },
    {
      "x": -10,
      "y": 7,
      "z": 2,
      "name": "Rock_Slate"
    },
    {
      "x": -10,
      "y": 8,
      "z": 2,
      "name": "Plant_Coral_Block_Purple"
    },
    {
      "x": -10,
      "y": 9,
      "z": 2,
      "name": "Plant_Coral_Block_Purple"
    },
    {
      "x": -10,
      "y": 0,
      "z": 3,
      "name": "Rock_Slate"
    },
    {
      "x": -10,
      "y": 1,
      "z": 3,
      "name": "Rock_Slate"
    },
    {
      "x": -10,
      "y": 2,
      "z": 3,
      "name": "Rock_Slate"
    },
    {
      "x": -10,
      "y": 3,
      "z": 3,
      "name": "Rock_Slate"
    },
    {
      "x": -10,
      "y": 4,
      "z": 3,
      "name": "Rock_Slate"
    },
    {
      "x": -10,
      "y": 5,
      "z": 3,
      "name": "Rock_Slate"
    },
    {
      "x": -10,
      "y": 6,
      "z": 3,
      "name": "Rock_Slate"
    },
    {
      "x": -10,
      "y": 7,
      "z": 3,
      "name": "Rock_Slate"
    },
    {
      "x": -10,
      "y": 8,
      "z": 3,
      "name": "Rock_Slate"
    },
    {
      "x": -10,
      "y": 0,
      "z": 4,
      "name": "Rock_Slate"
    },
    {
      "x": -10,
      "y": 1,
      "z": 4,
      "name": "Rock_Slate"
    },
    {
      "x": -10,
      "y": 2,
      "z": 4,
      "name": "Rock_Slate"
    },
    {
      "x": -10,
      "y": 3,
      "z": 4,
      "name": "Rock_Slate"
    },
    {
      "x": -10,
      "y": 4,
      "z": 4,
      "name": "Rock_Slate"
    },
    {
      "x": -10,
      "y": 5,
      "z": 4,
      "name": "Rock_Slate"
    },
    {
      "x": -10,
      "y": 6,
      "z": 4,
      "name": "Rock_Slate"
    },
    {
      "x": -10,
      "y": 7,
      "z": 4,
      "name": "Rock_Slate"
    },
    {
      "x": -10,
      "y": 8,
      "z": 4,
      "name": "Rock_Slate"
    },
    {
      "x": -10,
      "y": 0,
      "z": 5,
      "name": "Plant_Coral_Block_Purple"
    },
    {
      "x": -10,
      "y": 1,
      "z": 5,
      "name": "Plant_Coral_Block_Purple"
    },
    {
      "x": -10,
      "y": 2,
      "z": 5,
      "name": "Plant_Coral_Block_Purple"
    },
    {
      "x": -10,
      "y": 3,
      "z": 5,
      "name": "Plant_Coral_Block_Purple"
    },
    {
      "x": -10,
      "y": 4,
      "z": 5,
      "name": "Plant_Coral_Block_Purple"
    },
    {
      "x": -10,
      "y": 5,
      "z": 5,
      "name": "Plant_Coral_Block_Purple"
    },
    {
      "x": -10,
      "y": 6,
      "z": 5,
      "name": "Plant_Coral_Block_Purple"
    },
    {
      "x": -10,
      "y": 7,
      "z": 5,
      "name": "Plant_Coral_Block_Purple"
    },
    {
      "x": -10,
      "y": 8,
      "z": 5,
      "name": "Rock_Slate"
    },
    {
      "x": -10,
      "y": 9,
      "z": 5,
      "name": "Rock_Slate"
    },
    {
      "x": -10,
      "y": 7,
      "z": 6,
      "name": "Plant_Coral_Block_Purple"
    },
    {
      "x": -10,
      "y": 8,
      "z": 6,
      "name": "Plant_Coral_Block_Purple"
    },
    {
      "x": -10,
      "y": 9,
      "z": 6,
      "name": "Plant_Coral_Block_Purple"
    },
    {
      "x": -10,
      "y": 10,
      "z": 6,
      "name": "Plant_Coral_Block_Purple"
    },
    {
      "x": -9,
      "y": 0,
      "z": -3,
      "name": "Plant_Coral_Block_Purple"
    },
    {
      "x": -9,
      "y": 1,
      "z": -3,
      "name": "Plant_Coral_Block_Purple"
    },
    {
      "x": -9,
      "y": 2,
      "z": -3,
      "name": "Plant_Coral_Block_Purple"
    },
    {
      "x": -9,
      "y": 3,
      "z": -3,
      "name": "Plant_Coral_Block_Purple"
    },
    {
      "x": -9,
      "y": 4,
      "z": -3,
      "name": "Plant_Coral_Block_Purple"
    },
    {
      "x": -9,
      "y": 5,
      "z": -3,
      "name": "Plant_Coral_Block_Purple"
    },
    {
      "x": -9,
      "y": 6,
      "z": -3,
      "name": "Plant_Coral_Block_Purple"
    },
    {
      "x": -9,
      "y": 7,
      "z": -3,
      "name": "Plant_Coral_Block_Purple"
    },
    {
      "x": -9,
      "y": 0,
      "z": -2,
      "name": "Plant_Coral_Block_Purple"
    },
    {
      "x": -9,
      "y": 1,
      "z": -2,
      "name": "Plant_Coral_Block_Purple"
    },
    {
      "x": -9,
      "y": 2,
      "z": -2,
      "name": "Plant_Coral_Block_Purple"
    },
    {
      "x": -9,
      "y": 3,
      "z": -2,
      "name": "Plant_Coral_Block_Purple"
    },
    {
      "x": -9,
      "y": 4,
      "z": -2,
      "name": "Plant_Coral_Block_Purple"
    },
    {
      "x": -9,
      "y": 5,
      "z": -2,
      "name": "Plant_Coral_Block_Purple"
    },
    {
      "x": -9,
      "y": 6,
      "z": -2,
      "name": "Plant_Coral_Block_Purple"
    },
    {
      "x": -9,
      "y": 7,
      "z": -2,
      "name": "Plant_Coral_Block_Purple"
    },
    {
      "x": -9,
      "y": 8,
      "z": -2,
      "name": "Plant_Coral_Block_Purple"
    },
    {
      "x": -9,
      "y": 0,
      "z": -1,
      "name": "Plant_Coral_Block_Purple"
    },
    {
      "x": -9,
      "y": 1,
      "z": -1,
      "name": "Plant_Coral_Block_Purple"
    },
    {
      "x": -9,
      "y": 2,
      "z": -1,
      "name": "Plant_Coral_Block_Purple"
    },
    {
      "x": -9,
      "y": 3,
      "z": -1,
      "name": "Plant_Coral_Block_Purple"
    },
    {
      "x": -9,
      "y": 4,
      "z": -1,
      "name": "Plant_Coral_Block_Purple"
    },
    {
      "x": -9,
      "y": 5,
      "z": -1,
      "name": "Plant_Coral_Block_Purple"
    },
    {
      "x": -9,
      "y": 6,
      "z": -1,
      "name": "Plant_Coral_Block_Purple"
    },
    {
      "x": -9,
      "y": 7,
      "z": -1,
      "name": "Plant_Coral_Block_Purple"
    },
    {
      "x": -9,
      "y": 8,
      "z": -1,
      "name": "Plant_Coral_Block_Purple"
    },
    {
      "x": -9,
      "y": 0,
      "z": 1,
      "name": "Plant_Coral_Block_Purple"
    },
    {
      "x": -9,
      "y": 1,
      "z": 1,
      "name": "Plant_Coral_Block_Purple"
    },
    {
      "x": -9,
      "y": 2,
      "z": 1,
      "name": "Plant_Coral_Block_Purple"
    },
    {
      "x": -9,
      "y": 3,
      "z": 1,
      "name": "Plant_Coral_Block_Purple"
    },
    {
      "x": -9,
      "y": 4,
      "z": 1,
      "name": "Plant_Coral_Block_Purple"
    },
    {
      "x": -9,
      "y": 5,
      "z": 1,
      "name": "Plant_Coral_Block_Purple"
    },
    {
      "x": -9,
      "y": 6,
      "z": 1,
      "name": "Plant_Coral_Block_Purple"
    },
    {
      "x": -9,
      "y": 7,
      "z": 1,
      "name": "Plant_Coral_Block_Purple"
    },
    {
      "x": -9,
      "y": 0,
      "z": 2,
      "name": "Rock_Slate"
    },
    {
      "x": -9,
      "y": 1,
      "z": 2,
      "name": "Rock_Slate"
    },
    {
      "x": -9,
      "y": 2,
      "z": 2,
      "name": "Rock_Slate"
    },
    {
      "x": -9,
      "y": 3,
      "z": 2,
      "name": "Rock_Slate"
    },
    {
      "x": -9,
      "y": 4,
      "z": 2,
      "name": "Rock_Slate"
    },
    {
      "x": -9,
      "y": 5,
      "z": 2,
      "name": "Rock_Slate"
    },
    {
      "x": -9,
      "y": 6,
      "z": 2,
      "name": "Rock_Slate"
    },
    {
      "x": -9,
      "y": 7,
      "z": 2,
      "name": "Rock_Slate"
    },
    {
      "x": -9,
      "y": 8,
      "z": 2,
      "name": "Plant_Coral_Block_Purple"
    },
    {
      "x": -9,
      "y": 9,
      "z": 2,
      "name": "Plant_Coral_Block_Purple"
    },
    {
      "x": -9,
      "y": 0,
      "z": 3,
      "name": "Rock_Slate"
    },
    {
      "x": -9,
      "y": 1,
      "z": 3,
      "name": "Rock_Slate"
    },
    {
      "x": -9,
      "y": 2,
      "z": 3,
      "name": "Rock_Slate"
    },
    {
      "x": -9,
      "y": 3,
      "z": 3,
      "name": "Rock_Slate"
    },
    {
      "x": -9,
      "y": 4,
      "z": 3,
      "name": "Rock_Slate"
    },
    {
      "x": -9,
      "y": 5,
      "z": 3,
      "name": "Rock_Slate"
    },
    {
      "x": -9,
      "y": 6,
      "z": 3,
      "name": "Rock_Slate"
    },
    {
      "x": -9,
      "y": 7,
      "z": 3,
      "name": "Rock_Slate"
    },
    {
      "x": -9,
      "y": 8,
      "z": 3,
      "name": "Rock_Slate"
    },
    {
      "x": -9,
      "y": 0,
      "z": 4,
      "name": "Rock_Slate"
    },
    {
      "x": -9,
      "y": 1,
      "z": 4,
      "name": "Rock_Slate"
    },
    {
      "x": -9,
      "y": 2,
      "z": 4,
      "name": "Rock_Slate"
    },
    {
      "x": -9,
      "y": 3,
      "z": 4,
      "name": "Rock_Slate"
    },
    {
      "x": -9,
      "y": 4,
      "z": 4,
      "name": "Rock_Slate"
    },
    {
      "x": -9,
      "y": 5,
      "z": 4,
      "name": "Rock_Slate"
    },
    {
      "x": -9,
      "y": 6,
      "z": 4,
      "name": "Rock_Slate"
    },
    {
      "x": -9,
      "y": 7,
      "z": 4,
      "name": "Rock_Slate"
    },
    {
      "x": -9,
      "y": 8,
      "z": 4,
      "name": "Rock_Slate"
    },
    {
      "x": -9,
      "y": 9,
      "z": 4,
      "name": "Rock_Slate"
    },
    {
      "x": -9,
      "y": 0,
      "z": 5,
      "name": "Plant_Coral_Block_Purple"
    },
    {
      "x": -9,
      "y": 1,
      "z": 5,
      "name": "Plant_Coral_Block_Purple"
    },
    {
      "x": -9,
      "y": 2,
      "z": 5,
      "name": "Plant_Coral_Block_Purple"
    },
    {
      "x": -9,
      "y": 3,
      "z": 5,
      "name": "Plant_Coral_Block_Purple"
    },
    {
      "x": -9,
      "y": 4,
      "z": 5,
      "name": "Plant_Coral_Block_Purple"
    },
    {
      "x": -9,
      "y": 5,
      "z": 5,
      "name": "Plant_Coral_Block_Purple"
    },
    {
      "x": -9,
      "y": 6,
      "z": 5,
      "name": "Plant_Coral_Block_Purple"
    },
    {
      "x": -9,
      "y": 7,
      "z": 5,
      "name": "Plant_Coral_Block_Purple"
    },
    {
      "x": -9,
      "y": 8,
      "z": 5,
      "name": "Rock_Slate"
    },
    {
      "x": -9,
      "y": 9,
      "z": 5,
      "name": "Rock_Slate"
    },
    {
      "x": -9,
      "y": 6,
      "z": 6,
      "name": "Plant_Coral_Block_Purple"
    },
    {
      "x": -9,
      "y": 7,
      "z": 6,
      "name": "Plant_Coral_Block_Purple"
    },
    {
      "x": -9,
      "y": 8,
      "z": 6,
      "name": "Plant_Coral_Block_Purple"
    },
    {
      "x": -9,
      "y": 9,
      "z": 6,
      "name": "Plant_Coral_Block_Purple"
    },
    {
      "x": -9,
      "y": 10,
      "z": 6,
      "name": "Plant_Coral_Block_Purple"
    },
    {
      "x": -8,
      "y": 0,
      "z": -4,
      "name": "Plant_Coral_Block_Purple"
    },
    {
      "x": -8,
      "y": 1,
      "z": -4,
      "name": "Plant_Coral_Block_Purple"
    },
    {
      "x": -8,
      "y": 2,
      "z": -4,
      "name": "Plant_Coral_Block_Purple"
    },
    {
      "x": -8,
      "y": 3,
      "z": -4,
      "name": "Plant_Coral_Block_Purple"
    },
    {
      "x": -8,
      "y": 4,
      "z": -4,
      "name": "Plant_Coral_Block_Purple"
    },
    {
      "x": -8,
      "y": 5,
      "z": -4,
      "name": "Plant_Coral_Block_Purple"
    },
    {
      "x": -8,
      "y": 6,
      "z": -4,
      "name": "Plant_Coral_Block_Purple"
    },
    {
      "x": -8,
      "y": 7,
      "z": -4,
      "name": "Plant_Coral_Block_Purple"
    },
    {
      "x": -8,
      "y": 8,
      "z": -4,
      "name": "Plant_Coral_Block_Purple"
    },
    {
      "x": -8,
      "y": 0,
      "z": -3,
      "name": "Rock_Slate"
    },
    {
      "x": -8,
      "y": 1,
      "z": -3,
      "name": "Rock_Slate"
    },
    {
      "x": -8,
      "y": 2,
      "z": -3,
      "name": "Rock_Slate"
    },
    {
      "x": -8,
      "y": 3,
      "z": -3,
      "name": "Rock_Slate"
    },
    {
      "x": -8,
      "y": 4,
      "z": -3,
      "name": "Rock_Slate"
    },
    {
      "x": -8,
      "y": 5,
      "z": -3,
      "name": "Rock_Slate"
    },
    {
      "x": -8,
      "y": 6,
      "z": -3,
      "name": "Rock_Slate"
    },
    {
      "x": -8,
      "y": 7,
      "z": -3,
      "name": "Rock_Slate"
    },
    {
      "x": -8,
      "y": 8,
      "z": -3,
      "name": "Plant_Coral_Block_Purple"
    },
    {
      "x": -8,
      "y": 9,
      "z": -3,
      "name": "Plant_Coral_Block_Purple"
    },
    {
      "x": -8,
      "y": 10,
      "z": -3,
      "name": "Plant_Coral_Block_Purple"
    },
    {
      "x": -8,
      "y": 0,
      "z": -2,
      "name": "Rock_Slate"
    },
    {
      "x": -8,
      "y": 1,
      "z": -2,
      "name": "Rock_Slate"
    },
    {
      "x": -8,
      "y": 2,
      "z": -2,
      "name": "Rock_Slate"
    },
    {
      "x": -8,
      "y": 3,
      "z": -2,
      "name": "Rock_Slate"
    },
    {
      "x": -8,
      "y": 4,
      "z": -2,
      "name": "Rock_Slate"
    },
    {
      "x": -8,
      "y": 5,
      "z": -2,
      "name": "Rock_Slate"
    },
    {
      "x": -8,
      "y": 6,
      "z": -2,
      "name": "Rock_Slate"
    },
    {
      "x": -8,
      "y": 7,
      "z": -2,
      "name": "Rock_Slate"
    },
    {
      "x": -8,
      "y": 8,
      "z": -2,
      "name": "Rock_Slate"
    },
    {
      "x": -8,
      "y": 9,
      "z": -2,
      "name": "Plant_Coral_Block_Purple"
    },
    {
      "x": -8,
      "y": 10,
      "z": -2,
      "name": "Plant_Coral_Block_Purple"
    },
    {
      "x": -8,
      "y": 11,
      "z": -2,
      "name": "Plant_Coral_Block_Purple"
    },
    {
      "x": -8,
      "y": 0,
      "z": -1,
      "name": "Rock_Slate"
    },
    {
      "x": -8,
      "y": 1,
      "z": -1,
      "name": "Rock_Slate"
    },
    {
      "x": -8,
      "y": 2,
      "z": -1,
      "name": "Rock_Slate"
    },
    {
      "x": -8,
      "y": 3,
      "z": -1,
      "name": "Rock_Slate"
    },
    {
      "x": -8,
      "y": 4,
      "z": -1,
      "name": "Rock_Slate"
    },
    {
      "x": -8,
      "y": 5,
      "z": -1,
      "name": "Rock_Slate"
    },
    {
      "x": -8,
      "y": 6,
      "z": -1,
      "name": "Rock_Slate"
    },
    {
      "x": -8,
      "y": 7,
      "z": -1,
      "name": "Rock_Slate"
    },
    {
      "x": -8,
      "y": 8,
      "z": -1,
      "name": "Rock_Slate"
    },
    {
      "x": -8,
      "y": 9,
      "z": -1,
      "name": "Plant_Coral_Block_Purple"
    },
    {
      "x": -8,
      "y": 10,
      "z": -1,
      "name": "Plant_Coral_Block_Purple"
    },
    {
      "x": -8,
      "y": 11,
      "z": -1,
      "name": "Plant_Coral_Block_Purple"
    },
    {
      "x": -8,
      "y": 0,
      "z": 0,
      "name": "Plant_Coral_Block_Purple"
    },
    {
      "x": -8,
      "y": 1,
      "z": 0,
      "name": "Plant_Coral_Block_Purple"
    },
    {
      "x": -8,
      "y": 2,
      "z": 0,
      "name": "Plant_Coral_Block_Purple"
    },
    {
      "x": -8,
      "y": 3,
      "z": 0,
      "name": "Plant_Coral_Block_Purple"
    },
    {
      "x": -8,
      "y": 4,
      "z": 0,
      "name": "Plant_Coral_Block_Purple"
    },
    {
      "x": -8,
      "y": 5,
      "z": 0,
      "name": "Plant_Coral_Block_Purple"
    },
    {
      "x": -8,
      "y": 6,
      "z": 0,
      "name": "Plant_Coral_Block_Purple"
    },
    {
      "x": -8,
      "y": 7,
      "z": 0,
      "name": "Plant_Coral_Block_Purple"
    },
    {
      "x": -8,
      "y": 8,
      "z": 0,
      "name": "Plant_Coral_Block_Purple"
    },
    {
      "x": -8,
      "y": 0,
      "z": 1,
      "name": "Plant_Coral_Block_Purple"
    },
    {
      "x": -8,
      "y": 1,
      "z": 1,
      "name": "Plant_Coral_Block_Purple"
    },
    {
      "x": -8,
      "y": 2,
      "z": 1,
      "name": "Plant_Coral_Block_Purple"
    },
    {
      "x": -8,
      "y": 3,
      "z": 1,
      "name": "Plant_Coral_Block_Purple"
    },
    {
      "x": -8,
      "y": 4,
      "z": 1,
      "name": "Plant_Coral_Block_Purple"
    },
    {
      "x": -8,
      "y": 5,
      "z": 1,
      "name": "Plant_Coral_Block_Purple"
    },
    {
      "x": -8,
      "y": 6,
      "z": 1,
      "name": "Plant_Coral_Block_Purple"
    },
    {
      "x": -8,
      "y": 7,
      "z": 1,
      "name": "Plant_Coral_Block_Purple"
    },
    {
      "x": -8,
      "y": 0,
      "z": 2,
      "name": "Rock_Slate"
    },
    {
      "x": -8,
      "y": 1,
      "z": 2,
      "name": "Rock_Slate"
    },
    {
      "x": -8,
      "y": 2,
      "z": 2,
      "name": "Rock_Slate"
    },
    {
      "x": -8,
      "y": 3,
      "z": 2,
      "name": "Rock_Slate"
    },
    {
      "x": -8,
      "y": 4,
      "z": 2,
      "name": "Rock_Slate"
    },
    {
      "x": -8,
      "y": 5,
      "z": 2,
      "name": "Rock_Slate"
    },
    {
      "x": -8,
      "y": 6,
      "z": 2,
      "name": "Rock_Slate"
    },
    {
      "x": -8,
      "y": 7,
      "z": 2,
      "name": "Rock_Slate"
    },
    {
      "x": -8,
      "y": 8,
      "z": 2,
      "name": "Plant_Coral_Block_Purple"
    },
    {
      "x": -8,
      "y": 9,
      "z": 2,
      "name": "Plant_Coral_Block_Purple"
    },
    {
      "x": -8,
      "y": 0,
      "z": 3,
      "name": "Rock_Slate"
    },
    {
      "x": -8,
      "y": 1,
      "z": 3,
      "name": "Rock_Slate"
    },
    {
      "x": -8,
      "y": 2,
      "z": 3,
      "name": "Rock_Slate"
    },
    {
      "x": -8,
      "y": 3,
      "z": 3,
      "name": "Rock_Slate"
    },
    {
      "x": -8,
      "y": 4,
      "z": 3,
      "name": "Rock_Slate"
    },
    {
      "x": -8,
      "y": 5,
      "z": 3,
      "name": "Rock_Slate"
    },
    {
      "x": -8,
      "y": 6,
      "z": 3,
      "name": "Rock_Slate"
    },
    {
      "x": -8,
      "y": 7,
      "z": 3,
      "name": "Rock_Slate"
    },
    {
      "x": -8,
      "y": 8,
      "z": 3,
      "name": "Rock_Slate"
    },
    {
      "x": -8,
      "y": 9,
      "z": 3,
      "name": "Rock_Slate"
    },
    {
      "x": -8,
      "y": 0,
      "z": 4,
      "name": "Rock_Slate"
    },
    {
      "x": -8,
      "y": 1,
      "z": 4,
      "name": "Rock_Slate"
    },
    {
      "x": -8,
      "y": 2,
      "z": 4,
      "name": "Rock_Slate"
    },
    {
      "x": -8,
      "y": 3,
      "z": 4,
      "name": "Rock_Slate"
    },
    {
      "x": -8,
      "y": 4,
      "z": 4,
      "name": "Rock_Slate"
    },
    {
      "x": -8,
      "y": 5,
      "z": 4,
      "name": "Rock_Slate"
    },
    {
      "x": -8,
      "y": 6,
      "z": 4,
      "name": "Rock_Slate"
    },
    {
      "x": -8,
      "y": 7,
      "z": 4,
      "name": "Rock_Slate"
    },
    {
      "x": -8,
      "y": 8,
      "z": 4,
      "name": "Rock_Slate"
    },
    {
      "x": -8,
      "y": 9,
      "z": 4,
      "name": "Rock_Slate"
    },
    {
      "x": -8,
      "y": 0,
      "z": 5,
      "name": "Plant_Coral_Block_Purple"
    },
    {
      "x": -8,
      "y": 1,
      "z": 5,
      "name": "Plant_Coral_Block_Purple"
    },
    {
      "x": -8,
      "y": 2,
      "z": 5,
      "name": "Plant_Coral_Block_Purple"
    },
    {
      "x": -8,
      "y": 3,
      "z": 5,
      "name": "Plant_Coral_Block_Purple"
    },
    {
      "x": -8,
      "y": 4,
      "z": 5,
      "name": "Plant_Coral_Block_Purple"
    },
    {
      "x": -8,
      "y": 5,
      "z": 5,
      "name": "Plant_Coral_Block_Purple"
    },
    {
      "x": -8,
      "y": 6,
      "z": 5,
      "name": "Plant_Coral_Block_Purple"
    },
    {
      "x": -8,
      "y": 7,
      "z": 5,
      "name": "Plant_Coral_Block_Purple"
    },
    {
      "x": -8,
      "y": 8,
      "z": 5,
      "name": "Rock_Slate"
    },
    {
      "x": -8,
      "y": 9,
      "z": 5,
      "name": "Rock_Slate"
    },
    {
      "x": -8,
      "y": 0,
      "z": 6,
      "name": "Plant_Coral_Block_Purple"
    },
    {
      "x": -8,
      "y": 1,
      "z": 6,
      "name": "Plant_Coral_Block_Purple"
    },
    {
      "x": -8,
      "y": 2,
      "z": 6,
      "name": "Plant_Coral_Block_Purple"
    },
    {
      "x": -8,
      "y": 3,
      "z": 6,
      "name": "Plant_Coral_Block_Purple"
    },
    {
      "x": -8,
      "y": 4,
      "z": 6,
      "name": "Plant_Coral_Block_Purple"
    },
    {
      "x": -8,
      "y": 5,
      "z": 6,
      "name": "Plant_Coral_Block_Purple"
    },
    {
      "x": -8,
      "y": 6,
      "z": 6,
      "name": "Plant_Coral_Block_Purple"
    },
    {
      "x": -8,
      "y": 7,
      "z": 6,
      "name": "Plant_Coral_Block_Purple"
    },
    {
      "x": -8,
      "y": 8,
      "z": 6,
      "name": "Plant_Coral_Block_Purple"
    },
    {
      "x": -8,
      "y": 9,
      "z": 6,
      "name": "Plant_Coral_Block_Purple"
    },
    {
      "x": -8,
      "y": 10,
      "z": 6,
      "name": "Plant_Coral_Block_Purple"
    },
    {
      "x": -8,
      "y": 0,
      "z": 7,
      "name": "Plant_Coral_Block_Purple"
    },
    {
      "x": -8,
      "y": 1,
      "z": 7,
      "name": "Plant_Coral_Block_Purple"
    },
    {
      "x": -8,
      "y": 2,
      "z": 7,
      "name": "Plant_Coral_Block_Purple"
    },
    {
      "x": -8,
      "y": 3,
      "z": 7,
      "name": "Plant_Coral_Block_Purple"
    },
    {
      "x": -8,
      "y": 4,
      "z": 7,
      "name": "Plant_Coral_Block_Purple"
    },
    {
      "x": -8,
      "y": 5,
      "z": 7,
      "name": "Plant_Coral_Block_Purple"
    },
    {
      "x": -8,
      "y": 6,
      "z": 7,
      "name": "Plant_Coral_Block_Purple"
    },
    {
      "x": -8,
      "y": 7,
      "z": 7,
      "name": "Plant_Coral_Block_Purple"
    },
    {
      "x": -8,
      "y": 8,
      "z": 7,
      "name": "Plant_Coral_Block_Purple"
    },
    {
      "x": -8,
      "y": 9,
      "z": 7,
      "name": "Plant_Coral_Block_Purple"
    },
    {
      "x": -8,
      "y": 10,
      "z": 7,
      "name": "Plant_Coral_Block_Purple"
    },
    {
      "x": -8,
      "y": 0,
      "z": 8,
      "name": "Plant_Coral_Block_Purple"
    },
    {
      "x": -8,
      "y": 1,
      "z": 8,
      "name": "Plant_Coral_Block_Purple"
    },
    {
      "x": -8,
      "y": 2,
      "z": 8,
      "name": "Plant_Coral_Block_Purple"
    },
    {
      "x": -8,
      "y": 3,
      "z": 8,
      "name": "Plant_Coral_Block_Purple"
    },
    {
      "x": -8,
      "y": 4,
      "z": 8,
      "name": "Plant_Coral_Block_Purple"
    },
    {
      "x": -8,
      "y": 5,
      "z": 8,
      "name": "Plant_Coral_Block_Purple"
    },
    {
      "x": -8,
      "y": 6,
      "z": 8,
      "name": "Plant_Coral_Block_Purple"
    },
    {
      "x": -8,
      "y": 7,
      "z": 8,
      "name": "Plant_Coral_Block_Purple"
    },
    {
      "x": -8,
      "y": 8,
      "z": 8,
      "name": "Plant_Coral_Block_Purple"
    },
    {
      "x": -8,
      "y": 9,
      "z": 8,
      "name": "Plant_Coral_Block_Purple"
    },
    {
      "x": -8,
      "y": 10,
      "z": 8,
      "name": "Plant_Coral_Block_Purple"
    },
    {
      "x": -8,
      "y": 6,
      "z": 9,
      "name": "Plant_Coral_Block_Purple"
    },
    {
      "x": -8,
      "y": 7,
      "z": 9,
      "name": "Plant_Coral_Block_Purple"
    },
    {
      "x": -8,
      "y": 8,
      "z": 9,
      "name": "Plant_Coral_Block_Purple"
    },
    {
      "x": -8,
      "y": 9,
      "z": 9,
      "name": "Plant_Coral_Block_Purple"
    },
    {
      "x": -7,
      "y": 0,
      "z": -4,
      "name": "Plant_Coral_Block_Purple"
    },
    {
      "x": -7,
      "y": 1,
      "z": -4,
      "name": "Plant_Coral_Block_Purple"
    },
    {
      "x": -7,
      "y": 2,
      "z": -4,
      "name": "Plant_Coral_Block_Purple"
    },
    {
      "x": -7,
      "y": 3,
      "z": -4,
      "name": "Plant_Coral_Block_Purple"
    },
    {
      "x": -7,
      "y": 4,
      "z": -4,
      "name": "Plant_Coral_Block_Purple"
    },
    {
      "x": -7,
      "y": 5,
      "z": -4,
      "name": "Plant_Coral_Block_Purple"
    },
    {
      "x": -7,
      "y": 6,
      "z": -4,
      "name": "Plant_Coral_Block_Purple"
    },
    {
      "x": -7,
      "y": 7,
      "z": -4,
      "name": "Plant_Coral_Block_Purple"
    },
    {
      "x": -7,
      "y": 8,
      "z": -4,
      "name": "Plant_Coral_Block_Purple"
    },
    {
      "x": -7,
      "y": 9,
      "z": -4,
      "name": "Plant_Coral_Block_Purple"
    },
    {
      "x": -7,
      "y": 10,
      "z": -4,
      "name": "Plant_Coral_Block_Purple"
    },
    {
      "x": -7,
      "y": 0,
      "z": -3,
      "name": "Rock_Slate"
    },
    {
      "x": -7,
      "y": 1,
      "z": -3,
      "name": "Rock_Slate"
    },
    {
      "x": -7,
      "y": 2,
      "z": -3,
      "name": "Rock_Slate"
    },
    {
      "x": -7,
      "y": 3,
      "z": -3,
      "name": "Rock_Slate"
    },
    {
      "x": -7,
      "y": 4,
      "z": -3,
      "name": "Rock_Slate"
    },
    {
      "x": -7,
      "y": 5,
      "z": -3,
      "name": "Rock_Slate"
    },
    {
      "x": -7,
      "y": 6,
      "z": -3,
      "name": "Rock_Slate"
    },
    {
      "x": -7,
      "y": 7,
      "z": -3,
      "name": "Rock_Slate"
    },
    {
      "x": -7,
      "y": 8,
      "z": -3,
      "name": "Rock_Slate"
    },
    {
      "x": -7,
      "y": 9,
      "z": -3,
      "name": "Rock_Slate"
    },
    {
      "x": -7,
      "y": 0,
      "z": -2,
      "name": "Rock_Slate"
    },
    {
      "x": -7,
      "y": 1,
      "z": -2,
      "name": "Rock_Slate"
    },
    {
      "x": -7,
      "y": 2,
      "z": -2,
      "name": "Rock_Slate"
    },
    {
      "x": -7,
      "y": 3,
      "z": -2,
      "name": "Rock_Slate"
    },
    {
      "x": -7,
      "y": 4,
      "z": -2,
      "name": "Rock_Slate"
    },
    {
      "x": -7,
      "y": 5,
      "z": -2,
      "name": "Rock_Slate"
    },
    {
      "x": -7,
      "y": 6,
      "z": -2,
      "name": "Rock_Slate"
    },
    {
      "x": -7,
      "y": 7,
      "z": -2,
      "name": "Rock_Slate"
    },
    {
      "x": -7,
      "y": 8,
      "z": -2,
      "name": "Rock_Slate"
    },
    {
      "x": -7,
      "y": 9,
      "z": -2,
      "name": "Rock_Slate"
    },
    {
      "x": -7,
      "y": 0,
      "z": -1,
      "name": "Rock_Slate"
    },
    {
      "x": -7,
      "y": 1,
      "z": -1,
      "name": "Rock_Slate"
    },
    {
      "x": -7,
      "y": 2,
      "z": -1,
      "name": "Rock_Slate"
    },
    {
      "x": -7,
      "y": 3,
      "z": -1,
      "name": "Rock_Slate"
    },
    {
      "x": -7,
      "y": 4,
      "z": -1,
      "name": "Rock_Slate"
    },
    {
      "x": -7,
      "y": 5,
      "z": -1,
      "name": "Rock_Slate"
    },
    {
      "x": -7,
      "y": 6,
      "z": -1,
      "name": "Rock_Slate"
    },
    {
      "x": -7,
      "y": 7,
      "z": -1,
      "name": "Rock_Slate"
    },
    {
      "x": -7,
      "y": 8,
      "z": -1,
      "name": "Rock_Slate"
    },
    {
      "x": -7,
      "y": 9,
      "z": -1,
      "name": "Rock_Slate"
    },
    {
      "x": -7,
      "y": 10,
      "z": -1,
      "name": "Rock_Slate"
    },
    {
      "x": -7,
      "y": 0,
      "z": 0,
      "name": "Plant_Coral_Block_Purple"
    },
    {
      "x": -7,
      "y": 1,
      "z": 0,
      "name": "Plant_Coral_Block_Purple"
    },
    {
      "x": -7,
      "y": 2,
      "z": 0,
      "name": "Plant_Coral_Block_Purple"
    },
    {
      "x": -7,
      "y": 3,
      "z": 0,
      "name": "Plant_Coral_Block_Purple"
    },
    {
      "x": -7,
      "y": 4,
      "z": 0,
      "name": "Plant_Coral_Block_Purple"
    },
    {
      "x": -7,
      "y": 5,
      "z": 0,
      "name": "Plant_Coral_Block_Purple"
    },
    {
      "x": -7,
      "y": 6,
      "z": 0,
      "name": "Plant_Coral_Block_Purple"
    },
    {
      "x": -7,
      "y": 7,
      "z": 0,
      "name": "Plant_Coral_Block_Purple"
    },
    {
      "x": -7,
      "y": 8,
      "z": 0,
      "name": "Plant_Coral_Block_Purple"
    },
    {
      "x": -7,
      "y": 9,
      "z": 0,
      "name": "Plant_Coral_Block_Purple"
    },
    {
      "x": -7,
      "y": 10,
      "z": 0,
      "name": "Plant_Coral_Block_Purple"
    },
    {
      "x": -7,
      "y": 11,
      "z": 0,
      "name": "Plant_Coral_Block_Purple"
    },
    {
      "x": -7,
      "y": 0,
      "z": 2,
      "name": "Plant_Coral_Block_Purple"
    },
    {
      "x": -7,
      "y": 1,
      "z": 2,
      "name": "Plant_Coral_Block_Purple"
    },
    {
      "x": -7,
      "y": 2,
      "z": 2,
      "name": "Plant_Coral_Block_Purple"
    },
    {
      "x": -7,
      "y": 3,
      "z": 2,
      "name": "Plant_Coral_Block_Purple"
    },
    {
      "x": -7,
      "y": 4,
      "z": 2,
      "name": "Plant_Coral_Block_Purple"
    },
    {
      "x": -7,
      "y": 5,
      "z": 2,
      "name": "Plant_Coral_Block_Purple"
    },
    {
      "x": -7,
      "y": 6,
      "z": 2,
      "name": "Plant_Coral_Block_Purple"
    },
    {
      "x": -7,
      "y": 7,
      "z": 2,
      "name": "Plant_Coral_Block_Purple"
    },
    {
      "x": -7,
      "y": 0,
      "z": 3,
      "name": "Plant_Coral_Block_Purple"
    },
    {
      "x": -7,
      "y": 1,
      "z": 3,
      "name": "Plant_Coral_Block_Purple"
    },
    {
      "x": -7,
      "y": 2,
      "z": 3,
      "name": "Plant_Coral_Block_Purple"
    },
    {
      "x": -7,
      "y": 3,
      "z": 3,
      "name": "Plant_Coral_Block_Purple"
    },
    {
      "x": -7,
      "y": 4,
      "z": 3,
      "name": "Plant_Coral_Block_Purple"
    },
    {
      "x": -7,
      "y": 5,
      "z": 3,
      "name": "Plant_Coral_Block_Purple"
    },
    {
      "x": -7,
      "y": 6,
      "z": 3,
      "name": "Plant_Coral_Block_Purple"
    },
    {
      "x": -7,
      "y": 7,
      "z": 3,
      "name": "Plant_Coral_Block_Purple"
    },
    {
      "x": -7,
      "y": 8,
      "z": 3,
      "name": "Plant_Coral_Block_Purple"
    },
    {
      "x": -7,
      "y": 9,
      "z": 3,
      "name": "Plant_Coral_Block_Purple"
    },
    {
      "x": -7,
      "y": 10,
      "z": 3,
      "name": "Plant_Coral_Block_Purple"
    },
    {
      "x": -7,
      "y": 0,
      "z": 4,
      "name": "Plant_Coral_Block_Purple"
    },
    {
      "x": -7,
      "y": 1,
      "z": 4,
      "name": "Plant_Coral_Block_Purple"
    },
    {
      "x": -7,
      "y": 2,
      "z": 4,
      "name": "Plant_Coral_Block_Purple"
    },
    {
      "x": -7,
      "y": 3,
      "z": 4,
      "name": "Plant_Coral_Block_Purple"
    },
    {
      "x": -7,
      "y": 4,
      "z": 4,
      "name": "Plant_Coral_Block_Purple"
    },
    {
      "x": -7,
      "y": 5,
      "z": 4,
      "name": "Plant_Coral_Block_Purple"
    },
    {
      "x": -7,
      "y": 6,
      "z": 4,
      "name": "Plant_Coral_Block_Purple"
    },
    {
      "x": -7,
      "y": 7,
      "z": 4,
      "name": "Plant_Coral_Block_Purple"
    },
    {
      "x": -7,
      "y": 8,
      "z": 4,
      "name": "Plant_Coral_Block_Purple"
    },
    {
      "x": -7,
      "y": 9,
      "z": 4,
      "name": "Plant_Coral_Block_Purple"
    },
    {
      "x": -7,
      "y": 10,
      "z": 4,
      "name": "Plant_Coral_Block_Purple"
    },
    {
      "x": -7,
      "y": 0,
      "z": 5,
      "name": "Plant_Coral_Block_Purple"
    },
    {
      "x": -7,
      "y": 1,
      "z": 5,
      "name": "Plant_Coral_Block_Purple"
    },
    {
      "x": -7,
      "y": 2,
      "z": 5,
      "name": "Plant_Coral_Block_Purple"
    },
    {
      "x": -7,
      "y": 3,
      "z": 5,
      "name": "Plant_Coral_Block_Purple"
    },
    {
      "x": -7,
      "y": 4,
      "z": 5,
      "name": "Plant_Coral_Block_Purple"
    },
    {
      "x": -7,
      "y": 5,
      "z": 5,
      "name": "Plant_Coral_Block_Purple"
    },
    {
      "x": -7,
      "y": 6,
      "z": 5,
      "name": "Plant_Coral_Block_Purple"
    },
    {
      "x": -7,
      "y": 7,
      "z": 5,
      "name": "Plant_Coral_Block_Purple"
    },
    {
      "x": -7,
      "y": 8,
      "z": 5,
      "name": "Plant_Coral_Block_Purple"
    },
    {
      "x": -7,
      "y": 9,
      "z": 5,
      "name": "Plant_Coral_Block_Purple"
    },
    {
      "x": -7,
      "y": 10,
      "z": 5,
      "name": "Plant_Coral_Block_Purple"
    },
    {
      "x": -7,
      "y": 0,
      "z": 6,
      "name": "Rock_Slate"
    },
    {
      "x": -7,
      "y": 1,
      "z": 6,
      "name": "Rock_Slate"
    },
    {
      "x": -7,
      "y": 2,
      "z": 6,
      "name": "Rock_Slate"
    },
    {
      "x": -7,
      "y": 3,
      "z": 6,
      "name": "Rock_Slate"
    },
    {
      "x": -7,
      "y": 4,
      "z": 6,
      "name": "Rock_Slate"
    },
    {
      "x": -7,
      "y": 5,
      "z": 6,
      "name": "Rock_Slate"
    },
    {
      "x": -7,
      "y": 6,
      "z": 6,
      "name": "Rock_Slate"
    },
    {
      "x": -7,
      "y": 7,
      "z": 6,
      "name": "Rock_Slate"
    },
    {
      "x": -7,
      "y": 8,
      "z": 6,
      "name": "Plant_Coral_Block_Purple"
    },
    {
      "x": -7,
      "y": 9,
      "z": 6,
      "name": "Plant_Coral_Block_Purple"
    },
    {
      "x": -7,
      "y": 10,
      "z": 6,
      "name": "Plant_Coral_Block_Purple"
    },
    {
      "x": -7,
      "y": 0,
      "z": 7,
      "name": "Rock_Slate"
    },
    {
      "x": -7,
      "y": 1,
      "z": 7,
      "name": "Rock_Slate"
    },
    {
      "x": -7,
      "y": 2,
      "z": 7,
      "name": "Rock_Slate"
    },
    {
      "x": -7,
      "y": 3,
      "z": 7,
      "name": "Rock_Slate"
    },
    {
      "x": -7,
      "y": 4,
      "z": 7,
      "name": "Rock_Slate"
    },
    {
      "x": -7,
      "y": 5,
      "z": 7,
      "name": "Rock_Slate"
    },
    {
      "x": -7,
      "y": 6,
      "z": 7,
      "name": "Rock_Slate"
    },
    {
      "x": -7,
      "y": 7,
      "z": 7,
      "name": "Rock_Slate"
    },
    {
      "x": -7,
      "y": 8,
      "z": 7,
      "name": "Rock_Slate"
    },
    {
      "x": -7,
      "y": 9,
      "z": 7,
      "name": "Rock_Slate"
    },
    {
      "x": -7,
      "y": 0,
      "z": 8,
      "name": "Rock_Slate"
    },
    {
      "x": -7,
      "y": 1,
      "z": 8,
      "name": "Rock_Slate"
    },
    {
      "x": -7,
      "y": 2,
      "z": 8,
      "name": "Rock_Slate"
    },
    {
      "x": -7,
      "y": 3,
      "z": 8,
      "name": "Rock_Slate"
    },
    {
      "x": -7,
      "y": 4,
      "z": 8,
      "name": "Rock_Slate"
    },
    {
      "x": -7,
      "y": 5,
      "z": 8,
      "name": "Rock_Slate"
    },
    {
      "x": -7,
      "y": 6,
      "z": 8,
      "name": "Rock_Slate"
    },
    {
      "x": -7,
      "y": 7,
      "z": 8,
      "name": "Rock_Slate"
    },
    {
      "x": -7,
      "y": 8,
      "z": 8,
      "name": "Rock_Slate"
    },
    {
      "x": -7,
      "y": 9,
      "z": 8,
      "name": "Rock_Slate"
    },
    {
      "x": -7,
      "y": 0,
      "z": 9,
      "name": "Plant_Coral_Block_Purple"
    },
    {
      "x": -7,
      "y": 1,
      "z": 9,
      "name": "Plant_Coral_Block_Purple"
    },
    {
      "x": -7,
      "y": 2,
      "z": 9,
      "name": "Plant_Coral_Block_Purple"
    },
    {
      "x": -7,
      "y": 3,
      "z": 9,
      "name": "Plant_Coral_Block_Purple"
    },
    {
      "x": -7,
      "y": 4,
      "z": 9,
      "name": "Plant_Coral_Block_Purple"
    },
    {
      "x": -7,
      "y": 5,
      "z": 9,
      "name": "Plant_Coral_Block_Purple"
    },
    {
      "x": -7,
      "y": 6,
      "z": 9,
      "name": "Plant_Coral_Block_Purple"
    },
    {
      "x": -7,
      "y": 7,
      "z": 9,
      "name": "Plant_Coral_Block_Purple"
    },
    {
      "x": -7,
      "y": 8,
      "z": 9,
      "name": "Rock_Slate"
    },
    {
      "x": -7,
      "y": 0,
      "z": 10,
      "name": "Plant_Coral_Block_Purple"
    },
    {
      "x": -7,
      "y": 1,
      "z": 10,
      "name": "Plant_Coral_Block_Purple"
    },
    {
      "x": -7,
      "y": 2,
      "z": 10,
      "name": "Plant_Coral_Block_Purple"
    },
    {
      "x": -7,
      "y": 3,
      "z": 10,
      "name": "Plant_Coral_Block_Purple"
    },
    {
      "x": -7,
      "y": 4,
      "z": 10,
      "name": "Plant_Coral_Block_Purple"
    },
    {
      "x": -7,
      "y": 5,
      "z": 10,
      "name": "Plant_Coral_Block_Purple"
    },
    {
      "x": -7,
      "y": 6,
      "z": 10,
      "name": "Plant_Coral_Block_Purple"
    },
    {
      "x": -7,
      "y": 7,
      "z": 10,
      "name": "Plant_Coral_Block_Purple"
    },
    {
      "x": -7,
      "y": 8,
      "z": 10,
      "name": "Plant_Coral_Block_Purple"
    },
    {
      "x": -7,
      "y": 9,
      "z": 10,
      "name": "Plant_Coral_Block_Purple"
    },
    {
      "x": -6,
      "y": 0,
      "z": -4,
      "name": "Plant_Coral_Block_Purple"
    },
    {
      "x": -6,
      "y": 1,
      "z": -4,
      "name": "Plant_Coral_Block_Purple"
    },
    {
      "x": -6,
      "y": 2,
      "z": -4,
      "name": "Plant_Coral_Block_Purple"
    },
    {
      "x": -6,
      "y": 3,
      "z": -4,
      "name": "Plant_Coral_Block_Purple"
    },
    {
      "x": -6,
      "y": 4,
      "z": -4,
      "name": "Plant_Coral_Block_Purple"
    },
    {
      "x": -6,
      "y": 5,
      "z": -4,
      "name": "Plant_Coral_Block_Purple"
    },
    {
      "x": -6,
      "y": 6,
      "z": -4,
      "name": "Plant_Coral_Block_Purple"
    },
    {
      "x": -6,
      "y": 7,
      "z": -4,
      "name": "Plant_Coral_Block_Purple"
    },
    {
      "x": -6,
      "y": 8,
      "z": -4,
      "name": "Plant_Coral_Block_Purple"
    },
    {
      "x": -6,
      "y": 9,
      "z": -4,
      "name": "Plant_Coral_Block_Purple"
    },
    {
      "x": -6,
      "y": 10,
      "z": -4,
      "name": "Plant_Coral_Block_Purple"
    },
    {
      "x": -6,
      "y": 0,
      "z": -3,
      "name": "Rock_Slate"
    },
    {
      "x": -6,
      "y": 1,
      "z": -3,
      "name": "Rock_Slate"
    },
    {
      "x": -6,
      "y": 2,
      "z": -3,
      "name": "Rock_Slate"
    },
    {
      "x": -6,
      "y": 3,
      "z": -3,
      "name": "Rock_Slate"
    },
    {
      "x": -6,
      "y": 4,
      "z": -3,
      "name": "Rock_Slate"
    },
    {
      "x": -6,
      "y": 5,
      "z": -3,
      "name": "Rock_Slate"
    },
    {
      "x": -6,
      "y": 6,
      "z": -3,
      "name": "Rock_Slate"
    },
    {
      "x": -6,
      "y": 7,
      "z": -3,
      "name": "Rock_Slate"
    },
    {
      "x": -6,
      "y": 8,
      "z": -3,
      "name": "Rock_Slate"
    },
    {
      "x": -6,
      "y": 9,
      "z": -3,
      "name": "Rock_Slate"
    },
    {
      "x": -6,
      "y": 10,
      "z": -3,
      "name": "Rock_Slate"
    },
    {
      "x": -6,
      "y": 0,
      "z": -2,
      "name": "Rock_Slate"
    },
    {
      "x": -6,
      "y": 1,
      "z": -2,
      "name": "Rock_Slate"
    },
    {
      "x": -6,
      "y": 2,
      "z": -2,
      "name": "Rock_Slate"
    },
    {
      "x": -6,
      "y": 3,
      "z": -2,
      "name": "Rock_Slate"
    },
    {
      "x": -6,
      "y": 4,
      "z": -2,
      "name": "Rock_Slate"
    },
    {
      "x": -6,
      "y": 5,
      "z": -2,
      "name": "Rock_Slate"
    },
    {
      "x": -6,
      "y": 6,
      "z": -2,
      "name": "Rock_Slate"
    },
    {
      "x": -6,
      "y": 7,
      "z": -2,
      "name": "Rock_Slate"
    },
    {
      "x": -6,
      "y": 8,
      "z": -2,
      "name": "Rock_Slate"
    },
    {
      "x": -6,
      "y": 9,
      "z": -2,
      "name": "Rock_Slate"
    },
    {
      "x": -6,
      "y": 10,
      "z": -2,
      "name": "Rock_Slate"
    },
    {
      "x": -6,
      "y": 0,
      "z": -1,
      "name": "Rock_Slate"
    },
    {
      "x": -6,
      "y": 1,
      "z": -1,
      "name": "Rock_Slate"
    },
    {
      "x": -6,
      "y": 2,
      "z": -1,
      "name": "Rock_Slate"
    },
    {
      "x": -6,
      "y": 3,
      "z": -1,
      "name": "Rock_Slate"
    },
    {
      "x": -6,
      "y": 4,
      "z": -1,
      "name": "Rock_Slate"
    },
    {
      "x": -6,
      "y": 5,
      "z": -1,
      "name": "Rock_Slate"
    },
    {
      "x": -6,
      "y": 6,
      "z": -1,
      "name": "Rock_Slate"
    },
    {
      "x": -6,
      "y": 7,
      "z": -1,
      "name": "Rock_Slate"
    },
    {
      "x": -6,
      "y": 8,
      "z": -1,
      "name": "Rock_Slate"
    },
    {
      "x": -6,
      "y": 9,
      "z": -1,
      "name": "Rock_Slate"
    },
    {
      "x": -6,
      "y": 10,
      "z": -1,
      "name": "Rock_Slate"
    },
    {
      "x": -6,
      "y": 0,
      "z": 0,
      "name": "Plant_Coral_Block_Purple"
    },
    {
      "x": -6,
      "y": 1,
      "z": 0,
      "name": "Plant_Coral_Block_Purple"
    },
    {
      "x": -6,
      "y": 2,
      "z": 0,
      "name": "Plant_Coral_Block_Purple"
    },
    {
      "x": -6,
      "y": 3,
      "z": 0,
      "name": "Plant_Coral_Block_Purple"
    },
    {
      "x": -6,
      "y": 4,
      "z": 0,
      "name": "Plant_Coral_Block_Purple"
    },
    {
      "x": -6,
      "y": 5,
      "z": 0,
      "name": "Plant_Coral_Block_Purple"
    },
    {
      "x": -6,
      "y": 6,
      "z": 0,
      "name": "Plant_Coral_Block_Purple"
    },
    {
      "x": -6,
      "y": 7,
      "z": 0,
      "name": "Plant_Coral_Block_Purple"
    },
    {
      "x": -6,
      "y": 8,
      "z": 0,
      "name": "Plant_Coral_Block_Purple"
    },
    {
      "x": -6,
      "y": 9,
      "z": 0,
      "name": "Plant_Coral_Block_Purple"
    },
    {
      "x": -6,
      "y": 10,
      "z": 0,
      "name": "Plant_Coral_Block_Purple"
    },
    {
      "x": -6,
      "y": 11,
      "z": 0,
      "name": "Plant_Coral_Block_Purple"
    },
    {
      "x": -6,
      "y": 8,
      "z": 1,
      "name": "Plant_Coral_Block_Purple"
    },
    {
      "x": -6,
      "y": 9,
      "z": 1,
      "name": "Plant_Coral_Block_Purple"
    },
    {
      "x": -6,
      "y": 10,
      "z": 1,
      "name": "Plant_Coral_Block_Purple"
    },
    {
      "x": -6,
      "y": 0,
      "z": 2,
      "name": "Plant_Coral_Block_Purple"
    },
    {
      "x": -6,
      "y": 1,
      "z": 2,
      "name": "Plant_Coral_Block_Purple"
    },
    {
      "x": -6,
      "y": 2,
      "z": 2,
      "name": "Plant_Coral_Block_Purple"
    },
    {
      "x": -6,
      "y": 3,
      "z": 2,
      "name": "Plant_Coral_Block_Purple"
    },
    {
      "x": -6,
      "y": 4,
      "z": 2,
      "name": "Plant_Coral_Block_Purple"
    },
    {
      "x": -6,
      "y": 5,
      "z": 2,
      "name": "Plant_Coral_Block_Purple"
    },
    {
      "x": -6,
      "y": 6,
      "z": 2,
      "name": "Plant_Coral_Block_Purple"
    },
    {
      "x": -6,
      "y": 7,
      "z": 2,
      "name": "Plant_Coral_Block_Purple"
    },
    {
      "x": -6,
      "y": 8,
      "z": 2,
      "name": "Plant_Coral_Block_Purple"
    },
    {
      "x": -6,
      "y": 9,
      "z": 2,
      "name": "Plant_Coral_Block_Purple"
    },
    {
      "x": -6,
      "y": 10,
      "z": 2,
      "name": "Plant_Coral_Block_Purple"
    },
    {
      "x": -6,
      "y": 11,
      "z": 2,
      "name": "Plant_Coral_Block_Purple"
    },
    {
      "x": -6,
      "y": 12,
      "z": 2,
      "name": "Plant_Coral_Block_Purple"
    },
    {
      "x": -6,
      "y": 13,
      "z": 2,
      "name": "Plant_Coral_Block_Purple"
    },
    {
      "x": -6,
      "y": 0,
      "z": 3,
      "name": "Plant_Coral_Block_Purple"
    },
    {
      "x": -6,
      "y": 1,
      "z": 3,
      "name": "Plant_Coral_Block_Purple"
    },
    {
      "x": -6,
      "y": 2,
      "z": 3,
      "name": "Plant_Coral_Block_Purple"
    },
    {
      "x": -6,
      "y": 3,
      "z": 3,
      "name": "Plant_Coral_Block_Purple"
    },
    {
      "x": -6,
      "y": 4,
      "z": 3,
      "name": "Plant_Coral_Block_Purple"
    },
    {
      "x": -6,
      "y": 5,
      "z": 3,
      "name": "Plant_Coral_Block_Purple"
    },
    {
      "x": -6,
      "y": 6,
      "z": 3,
      "name": "Plant_Coral_Block_Purple"
    },
    {
      "x": -6,
      "y": 7,
      "z": 3,
      "name": "Plant_Coral_Block_Purple"
    },
    {
      "x": -6,
      "y": 8,
      "z": 3,
      "name": "Plant_Coral_Block_Purple"
    },
    {
      "x": -6,
      "y": 9,
      "z": 3,
      "name": "Plant_Coral_Block_Purple"
    },
    {
      "x": -6,
      "y": 10,
      "z": 3,
      "name": "Plant_Coral_Block_Purple"
    },
    {
      "x": -6,
      "y": 11,
      "z": 3,
      "name": "Plant_Coral_Block_Purple"
    },
    {
      "x": -6,
      "y": 12,
      "z": 3,
      "name": "Plant_Coral_Block_Purple"
    },
    {
      "x": -6,
      "y": 13,
      "z": 3,
      "name": "Plant_Coral_Block_Purple"
    },
    {
      "x": -6,
      "y": 0,
      "z": 4,
      "name": "Plant_Coral_Block_Purple"
    },
    {
      "x": -6,
      "y": 1,
      "z": 4,
      "name": "Plant_Coral_Block_Purple"
    },
    {
      "x": -6,
      "y": 2,
      "z": 4,
      "name": "Plant_Coral_Block_Purple"
    },
    {
      "x": -6,
      "y": 3,
      "z": 4,
      "name": "Plant_Coral_Block_Purple"
    },
    {
      "x": -6,
      "y": 4,
      "z": 4,
      "name": "Plant_Coral_Block_Purple"
    },
    {
      "x": -6,
      "y": 5,
      "z": 4,
      "name": "Plant_Coral_Block_Purple"
    },
    {
      "x": -6,
      "y": 6,
      "z": 4,
      "name": "Plant_Coral_Block_Purple"
    },
    {
      "x": -6,
      "y": 7,
      "z": 4,
      "name": "Plant_Coral_Block_Purple"
    },
    {
      "x": -6,
      "y": 11,
      "z": 4,
      "name": "Plant_Coral_Block_Purple"
    },
    {
      "x": -6,
      "y": 12,
      "z": 4,
      "name": "Plant_Coral_Block_Purple"
    },
    {
      "x": -6,
      "y": 0,
      "z": 5,
      "name": "Plant_Coral_Block_Purple"
    },
    {
      "x": -6,
      "y": 1,
      "z": 5,
      "name": "Plant_Coral_Block_Purple"
    },
    {
      "x": -6,
      "y": 2,
      "z": 5,
      "name": "Plant_Coral_Block_Purple"
    },
    {
      "x": -6,
      "y": 3,
      "z": 5,
      "name": "Plant_Coral_Block_Purple"
    },
    {
      "x": -6,
      "y": 4,
      "z": 5,
      "name": "Plant_Coral_Block_Purple"
    },
    {
      "x": -6,
      "y": 5,
      "z": 5,
      "name": "Plant_Coral_Block_Purple"
    },
    {
      "x": -6,
      "y": 6,
      "z": 5,
      "name": "Plant_Coral_Block_Purple"
    },
    {
      "x": -6,
      "y": 7,
      "z": 5,
      "name": "Plant_Coral_Block_Purple"
    },
    {
      "x": -6,
      "y": 0,
      "z": 6,
      "name": "Rock_Slate"
    },
    {
      "x": -6,
      "y": 1,
      "z": 6,
      "name": "Rock_Slate"
    },
    {
      "x": -6,
      "y": 2,
      "z": 6,
      "name": "Rock_Slate"
    },
    {
      "x": -6,
      "y": 3,
      "z": 6,
      "name": "Rock_Slate"
    },
    {
      "x": -6,
      "y": 4,
      "z": 6,
      "name": "Rock_Slate"
    },
    {
      "x": -6,
      "y": 5,
      "z": 6,
      "name": "Rock_Slate"
    },
    {
      "x": -6,
      "y": 6,
      "z": 6,
      "name": "Rock_Slate"
    },
    {
      "x": -6,
      "y": 7,
      "z": 6,
      "name": "Rock_Slate"
    },
    {
      "x": -6,
      "y": 8,
      "z": 6,
      "name": "Plant_Coral_Block_Purple"
    },
    {
      "x": -6,
      "y": 9,
      "z": 6,
      "name": "Plant_Coral_Block_Purple"
    },
    {
      "x": -6,
      "y": 10,
      "z": 6,
      "name": "Plant_Coral_Block_Purple"
    },
    {
      "x": -6,
      "y": 11,
      "z": 6,
      "name": "Plant_Coral_Block_Purple"
    },
    {
      "x": -6,
      "y": 0,
      "z": 7,
      "name": "Rock_Slate"
    },
    {
      "x": -6,
      "y": 1,
      "z": 7,
      "name": "Rock_Slate"
    },
    {
      "x": -6,
      "y": 2,
      "z": 7,
      "name": "Rock_Slate"
    },
    {
      "x": -6,
      "y": 3,
      "z": 7,
      "name": "Rock_Slate"
    },
    {
      "x": -6,
      "y": 4,
      "z": 7,
      "name": "Rock_Slate"
    },
    {
      "x": -6,
      "y": 5,
      "z": 7,
      "name": "Rock_Slate"
    },
    {
      "x": -6,
      "y": 6,
      "z": 7,
      "name": "Rock_Slate"
    },
    {
      "x": -6,
      "y": 7,
      "z": 7,
      "name": "Rock_Slate"
    },
    {
      "x": -6,
      "y": 8,
      "z": 7,
      "name": "Rock_Slate"
    },
    {
      "x": -6,
      "y": 9,
      "z": 7,
      "name": "Rock_Slate"
    },
    {
      "x": -6,
      "y": 10,
      "z": 7,
      "name": "Rock_Slate"
    },
    {
      "x": -6,
      "y": 0,
      "z": 8,
      "name": "Rock_Slate"
    },
    {
      "x": -6,
      "y": 1,
      "z": 8,
      "name": "Rock_Slate"
    },
    {
      "x": -6,
      "y": 2,
      "z": 8,
      "name": "Rock_Slate"
    },
    {
      "x": -6,
      "y": 3,
      "z": 8,
      "name": "Rock_Slate"
    },
    {
      "x": -6,
      "y": 4,
      "z": 8,
      "name": "Rock_Slate"
    },
    {
      "x": -6,
      "y": 5,
      "z": 8,
      "name": "Rock_Slate"
    },
    {
      "x": -6,
      "y": 6,
      "z": 8,
      "name": "Rock_Slate"
    },
    {
      "x": -6,
      "y": 7,
      "z": 8,
      "name": "Rock_Slate"
    },
    {
      "x": -6,
      "y": 8,
      "z": 8,
      "name": "Rock_Slate"
    },
    {
      "x": -6,
      "y": 9,
      "z": 8,
      "name": "Rock_Slate"
    },
    {
      "x": -6,
      "y": 0,
      "z": 9,
      "name": "Plant_Coral_Block_Purple"
    },
    {
      "x": -6,
      "y": 1,
      "z": 9,
      "name": "Plant_Coral_Block_Purple"
    },
    {
      "x": -6,
      "y": 2,
      "z": 9,
      "name": "Plant_Coral_Block_Purple"
    },
    {
      "x": -6,
      "y": 3,
      "z": 9,
      "name": "Plant_Coral_Block_Purple"
    },
    {
      "x": -6,
      "y": 4,
      "z": 9,
      "name": "Plant_Coral_Block_Purple"
    },
    {
      "x": -6,
      "y": 5,
      "z": 9,
      "name": "Plant_Coral_Block_Purple"
    },
    {
      "x": -6,
      "y": 6,
      "z": 9,
      "name": "Plant_Coral_Block_Purple"
    },
    {
      "x": -6,
      "y": 7,
      "z": 9,
      "name": "Plant_Coral_Block_Purple"
    },
    {
      "x": -6,
      "y": 8,
      "z": 9,
      "name": "Rock_Slate"
    },
    {
      "x": -6,
      "y": 9,
      "z": 9,
      "name": "Rock_Slate"
    },
    {
      "x": -6,
      "y": 0,
      "z": 10,
      "name": "Plant_Coral_Block_Purple"
    },
    {
      "x": -6,
      "y": 1,
      "z": 10,
      "name": "Plant_Coral_Block_Purple"
    },
    {
      "x": -6,
      "y": 2,
      "z": 10,
      "name": "Plant_Coral_Block_Purple"
    },
    {
      "x": -6,
      "y": 3,
      "z": 10,
      "name": "Plant_Coral_Block_Purple"
    },
    {
      "x": -6,
      "y": 4,
      "z": 10,
      "name": "Plant_Coral_Block_Purple"
    },
    {
      "x": -6,
      "y": 5,
      "z": 10,
      "name": "Plant_Coral_Block_Purple"
    },
    {
      "x": -6,
      "y": 6,
      "z": 10,
      "name": "Plant_Coral_Block_Purple"
    },
    {
      "x": -6,
      "y": 7,
      "z": 10,
      "name": "Plant_Coral_Block_Purple"
    },
    {
      "x": -6,
      "y": 8,
      "z": 10,
      "name": "Plant_Coral_Block_Purple"
    },
    {
      "x": -6,
      "y": 9,
      "z": 10,
      "name": "Plant_Coral_Block_Purple"
    },
    {
      "x": -6,
      "y": 10,
      "z": 10,
      "name": "Plant_Coral_Block_Purple"
    },
    {
      "x": -5,
      "y": 0,
      "z": -7,
      "name": "Plant_Coral_Block_Purple"
    },
    {
      "x": -5,
      "y": 1,
      "z": -7,
      "name": "Plant_Coral_Block_Purple"
    },
    {
      "x": -5,
      "y": 2,
      "z": -7,
      "name": "Plant_Coral_Block_Purple"
    },
    {
      "x": -5,
      "y": 3,
      "z": -7,
      "name": "Plant_Coral_Block_Purple"
    },
    {
      "x": -5,
      "y": 4,
      "z": -7,
      "name": "Plant_Coral_Block_Purple"
    },
    {
      "x": -5,
      "y": 5,
      "z": -7,
      "name": "Plant_Coral_Block_Purple"
    },
    {
      "x": -5,
      "y": 6,
      "z": -7,
      "name": "Plant_Coral_Block_Purple"
    },
    {
      "x": -5,
      "y": 7,
      "z": -7,
      "name": "Plant_Coral_Block_Purple"
    },
    {
      "x": -5,
      "y": 0,
      "z": -6,
      "name": "Plant_Coral_Block_Purple"
    },
    {
      "x": -5,
      "y": 1,
      "z": -6,
      "name": "Plant_Coral_Block_Purple"
    },
    {
      "x": -5,
      "y": 2,
      "z": -6,
      "name": "Plant_Coral_Block_Purple"
    },
    {
      "x": -5,
      "y": 3,
      "z": -6,
      "name": "Plant_Coral_Block_Purple"
    },
    {
      "x": -5,
      "y": 4,
      "z": -6,
      "name": "Plant_Coral_Block_Purple"
    },
    {
      "x": -5,
      "y": 5,
      "z": -6,
      "name": "Plant_Coral_Block_Purple"
    },
    {
      "x": -5,
      "y": 6,
      "z": -6,
      "name": "Plant_Coral_Block_Purple"
    },
    {
      "x": -5,
      "y": 7,
      "z": -6,
      "name": "Plant_Coral_Block_Purple"
    },
    {
      "x": -5,
      "y": 8,
      "z": -6,
      "name": "Plant_Coral_Block_Purple"
    },
    {
      "x": -5,
      "y": 9,
      "z": -6,
      "name": "Plant_Coral_Block_Purple"
    },
    {
      "x": -5,
      "y": 0,
      "z": -5,
      "name": "Plant_Coral_Block_Purple"
    },
    {
      "x": -5,
      "y": 1,
      "z": -5,
      "name": "Plant_Coral_Block_Purple"
    },
    {
      "x": -5,
      "y": 2,
      "z": -5,
      "name": "Plant_Coral_Block_Purple"
    },
    {
      "x": -5,
      "y": 3,
      "z": -5,
      "name": "Plant_Coral_Block_Purple"
    },
    {
      "x": -5,
      "y": 4,
      "z": -5,
      "name": "Plant_Coral_Block_Purple"
    },
    {
      "x": -5,
      "y": 5,
      "z": -5,
      "name": "Plant_Coral_Block_Purple"
    },
    {
      "x": -5,
      "y": 6,
      "z": -5,
      "name": "Plant_Coral_Block_Purple"
    },
    {
      "x": -5,
      "y": 7,
      "z": -5,
      "name": "Plant_Coral_Block_Purple"
    },
    {
      "x": -5,
      "y": 8,
      "z": -5,
      "name": "Plant_Coral_Block_Purple"
    },
    {
      "x": -5,
      "y": 9,
      "z": -5,
      "name": "Plant_Coral_Block_Purple"
    },
    {
      "x": -5,
      "y": 8,
      "z": -4,
      "name": "Plant_Coral_Block_Purple"
    },
    {
      "x": -5,
      "y": 9,
      "z": -4,
      "name": "Plant_Coral_Block_Purple"
    },
    {
      "x": -5,
      "y": 10,
      "z": -4,
      "name": "Plant_Coral_Block_Purple"
    },
    {
      "x": -5,
      "y": 11,
      "z": -4,
      "name": "Plant_Coral_Block_Purple"
    },
    {
      "x": -5,
      "y": 0,
      "z": -3,
      "name": "Plant_Coral_Block_Purple"
    },
    {
      "x": -5,
      "y": 1,
      "z": -3,
      "name": "Plant_Coral_Block_Purple"
    },
    {
      "x": -5,
      "y": 2,
      "z": -3,
      "name": "Plant_Coral_Block_Purple"
    },
    {
      "x": -5,
      "y": 3,
      "z": -3,
      "name": "Plant_Coral_Block_Purple"
    },
    {
      "x": -5,
      "y": 4,
      "z": -3,
      "name": "Plant_Coral_Block_Purple"
    },
    {
      "x": -5,
      "y": 5,
      "z": -3,
      "name": "Plant_Coral_Block_Purple"
    },
    {
      "x": -5,
      "y": 6,
      "z": -3,
      "name": "Plant_Coral_Block_Purple"
    },
    {
      "x": -5,
      "y": 7,
      "z": -3,
      "name": "Plant_Coral_Block_Purple"
    },
    {
      "x": -5,
      "y": 8,
      "z": -3,
      "name": "Plant_Coral_Block_Purple"
    },
    {
      "x": -5,
      "y": 9,
      "z": -3,
      "name": "Rock_Slate"
    },
    {
      "x": -5,
      "y": 10,
      "z": -3,
      "name": "Rock_Slate"
    },
    {
      "x": -5,
      "y": 11,
      "z": -3,
      "name": "Rock_Slate"
    },
    {
      "x": -5,
      "y": 0,
      "z": -2,
      "name": "Plant_Coral_Block_Purple"
    },
    {
      "x": -5,
      "y": 1,
      "z": -2,
      "name": "Plant_Coral_Block_Purple"
    },
    {
      "x": -5,
      "y": 2,
      "z": -2,
      "name": "Plant_Coral_Block_Purple"
    },
    {
      "x": -5,
      "y": 3,
      "z": -2,
      "name": "Plant_Coral_Block_Purple"
    },
    {
      "x": -5,
      "y": 4,
      "z": -2,
      "name": "Plant_Coral_Block_Purple"
    },
    {
      "x": -5,
      "y": 5,
      "z": -2,
      "name": "Plant_Coral_Block_Purple"
    },
    {
      "x": -5,
      "y": 6,
      "z": -2,
      "name": "Plant_Coral_Block_Purple"
    },
    {
      "x": -5,
      "y": 7,
      "z": -2,
      "name": "Plant_Coral_Block_Purple"
    },
    {
      "x": -5,
      "y": 8,
      "z": -2,
      "name": "Plant_Coral_Block_Purple"
    },
    {
      "x": -5,
      "y": 9,
      "z": -2,
      "name": "Rock_Slate"
    },
    {
      "x": -5,
      "y": 10,
      "z": -2,
      "name": "Rock_Slate"
    },
    {
      "x": -5,
      "y": 11,
      "z": -2,
      "name": "Rock_Slate"
    },
    {
      "x": -5,
      "y": 0,
      "z": -1,
      "name": "Plant_Coral_Block_Purple"
    },
    {
      "x": -5,
      "y": 1,
      "z": -1,
      "name": "Plant_Coral_Block_Purple"
    },
    {
      "x": -5,
      "y": 2,
      "z": -1,
      "name": "Plant_Coral_Block_Purple"
    },
    {
      "x": -5,
      "y": 3,
      "z": -1,
      "name": "Plant_Coral_Block_Purple"
    },
    {
      "x": -5,
      "y": 4,
      "z": -1,
      "name": "Plant_Coral_Block_Purple"
    },
    {
      "x": -5,
      "y": 5,
      "z": -1,
      "name": "Plant_Coral_Block_Purple"
    },
    {
      "x": -5,
      "y": 6,
      "z": -1,
      "name": "Plant_Coral_Block_Purple"
    },
    {
      "x": -5,
      "y": 7,
      "z": -1,
      "name": "Plant_Coral_Block_Purple"
    },
    {
      "x": -5,
      "y": 8,
      "z": -1,
      "name": "Plant_Coral_Block_Purple"
    },
    {
      "x": -5,
      "y": 9,
      "z": -1,
      "name": "Rock_Slate"
    },
    {
      "x": -5,
      "y": 10,
      "z": -1,
      "name": "Rock_Slate"
    },
    {
      "x": -5,
      "y": 11,
      "z": -1,
      "name": "Rock_Slate"
    },
    {
      "x": -5,
      "y": 8,
      "z": 0,
      "name": "Plant_Coral_Block_Purple"
    },
    {
      "x": -5,
      "y": 9,
      "z": 0,
      "name": "Plant_Coral_Block_Purple"
    },
    {
      "x": -5,
      "y": 10,
      "z": 0,
      "name": "Plant_Coral_Block_Purple"
    },
    {
      "x": -5,
      "y": 11,
      "z": 0,
      "name": "Plant_Coral_Block_Purple"
    },
    {
      "x": -5,
      "y": 12,
      "z": 0,
      "name": "Plant_Coral_Block_Purple"
    },
    {
      "x": -5,
      "y": 0,
      "z": 1,
      "name": "Plant_Coral_Block_Purple"
    },
    {
      "x": -5,
      "y": 1,
      "z": 1,
      "name": "Plant_Coral_Block_Purple"
    },
    {
      "x": -5,
      "y": 2,
      "z": 1,
      "name": "Plant_Coral_Block_Purple"
    },
    {
      "x": -5,
      "y": 3,
      "z": 1,
      "name": "Plant_Coral_Block_Purple"
    },
    {
      "x": -5,
      "y": 4,
      "z": 1,
      "name": "Plant_Coral_Block_Purple"
    },
    {
      "x": -5,
      "y": 5,
      "z": 1,
      "name": "Plant_Coral_Block_Purple"
    },
    {
      "x": -5,
      "y": 6,
      "z": 1,
      "name": "Plant_Coral_Block_Purple"
    },
    {
      "x": -5,
      "y": 7,
      "z": 1,
      "name": "Plant_Coral_Block_Purple"
    },
    {
      "x": -5,
      "y": 8,
      "z": 1,
      "name": "Rock_Slate"
    },
    {
      "x": -5,
      "y": 9,
      "z": 1,
      "name": "Rock_Slate"
    },
    {
      "x": -5,
      "y": 10,
      "z": 1,
      "name": "Rock_Slate"
    },
    {
      "x": -5,
      "y": 11,
      "z": 1,
      "name": "Plant_Coral_Block_Purple"
    },
    {
      "x": -5,
      "y": 12,
      "z": 1,
      "name": "Plant_Coral_Block_Purple"
    },
    {
      "x": -5,
      "y": 13,
      "z": 1,
      "name": "Plant_Coral_Block_Purple"
    },
    {
      "x": -5,
      "y": 0,
      "z": 2,
      "name": "Rock_Slate"
    },
    {
      "x": -5,
      "y": 1,
      "z": 2,
      "name": "Rock_Slate"
    },
    {
      "x": -5,
      "y": 2,
      "z": 2,
      "name": "Rock_Slate"
    },
    {
      "x": -5,
      "y": 3,
      "z": 2,
      "name": "Rock_Slate"
    },
    {
      "x": -5,
      "y": 4,
      "z": 2,
      "name": "Rock_Slate"
    },
    {
      "x": -5,
      "y": 5,
      "z": 2,
      "name": "Rock_Slate"
    },
    {
      "x": -5,
      "y": 6,
      "z": 2,
      "name": "Rock_Slate"
    },
    {
      "x": -5,
      "y": 7,
      "z": 2,
      "name": "Rock_Slate"
    },
    {
      "x": -5,
      "y": 8,
      "z": 2,
      "name": "Rock_Slate"
    },
    {
      "x": -5,
      "y": 9,
      "z": 2,
      "name": "Rock_Slate"
    },
    {
      "x": -5,
      "y": 10,
      "z": 2,
      "name": "Rock_Slate"
    },
    {
      "x": -5,
      "y": 11,
      "z": 2,
      "name": "Rock_Slate"
    },
    {
      "x": -5,
      "y": 12,
      "z": 2,
      "name": "Rock_Slate"
    },
    {
      "x": -5,
      "y": 13,
      "z": 2,
      "name": "Rock_Slate"
    },
    {
      "x": -5,
      "y": 14,
      "z": 2,
      "name": "Plant_Coral_Block_Purple"
    },
    {
      "x": -5,
      "y": 15,
      "z": 2,
      "name": "Plant_Coral_Block_Purple"
    },
    {
      "x": -5,
      "y": 0,
      "z": 3,
      "name": "Rock_Slate"
    },
    {
      "x": -5,
      "y": 1,
      "z": 3,
      "name": "Rock_Slate"
    },
    {
      "x": -5,
      "y": 2,
      "z": 3,
      "name": "Rock_Slate"
    },
    {
      "x": -5,
      "y": 3,
      "z": 3,
      "name": "Rock_Slate"
    },
    {
      "x": -5,
      "y": 4,
      "z": 3,
      "name": "Rock_Slate"
    },
    {
      "x": -5,
      "y": 5,
      "z": 3,
      "name": "Rock_Slate"
    },
    {
      "x": -5,
      "y": 6,
      "z": 3,
      "name": "Rock_Slate"
    },
    {
      "x": -5,
      "y": 7,
      "z": 3,
      "name": "Rock_Slate"
    },
    {
      "x": -5,
      "y": 8,
      "z": 3,
      "name": "Rock_Slate"
    },
    {
      "x": -5,
      "y": 9,
      "z": 3,
      "name": "Rock_Slate"
    },
    {
      "x": -5,
      "y": 10,
      "z": 3,
      "name": "Rock_Slate"
    },
    {
      "x": -5,
      "y": 11,
      "z": 3,
      "name": "Rock_Slate"
    },
    {
      "x": -5,
      "y": 12,
      "z": 3,
      "name": "Rock_Slate"
    },
    {
      "x": -5,
      "y": 13,
      "z": 3,
      "name": "Rock_Slate"
    },
    {
      "x": -5,
      "y": 14,
      "z": 3,
      "name": "Plant_Coral_Block_Purple"
    },
    {
      "x": -5,
      "y": 0,
      "z": 4,
      "name": "Rock_Slate"
    },
    {
      "x": -5,
      "y": 1,
      "z": 4,
      "name": "Rock_Slate"
    },
    {
      "x": -5,
      "y": 2,
      "z": 4,
      "name": "Rock_Slate"
    },
    {
      "x": -5,
      "y": 3,
      "z": 4,
      "name": "Rock_Slate"
    },
    {
      "x": -5,
      "y": 4,
      "z": 4,
      "name": "Rock_Slate"
    },
    {
      "x": -5,
      "y": 5,
      "z": 4,
      "name": "Rock_Slate"
    },
    {
      "x": -5,
      "y": 6,
      "z": 4,
      "name": "Rock_Slate"
    },
    {
      "x": -5,
      "y": 7,
      "z": 4,
      "name": "Rock_Slate"
    },
    {
      "x": -5,
      "y": 8,
      "z": 4,
      "name": "Plant_Coral_Block_Purple"
    },
    {
      "x": -5,
      "y": 9,
      "z": 4,
      "name": "Plant_Coral_Block_Purple"
    },
    {
      "x": -5,
      "y": 10,
      "z": 4,
      "name": "Plant_Coral_Block_Purple"
    },
    {
      "x": -5,
      "y": 11,
      "z": 4,
      "name": "Rock_Slate"
    },
    {
      "x": -5,
      "y": 12,
      "z": 4,
      "name": "Rock_Slate"
    },
    {
      "x": -5,
      "y": 13,
      "z": 4,
      "name": "Plant_Coral_Block_Purple"
    },
    {
      "x": -5,
      "y": 14,
      "z": 4,
      "name": "Plant_Coral_Block_Purple"
    },
    {
      "x": -5,
      "y": 0,
      "z": 5,
      "name": "Plant_Coral_Block_Purple"
    },
    {
      "x": -5,
      "y": 1,
      "z": 5,
      "name": "Plant_Coral_Block_Purple"
    },
    {
      "x": -5,
      "y": 2,
      "z": 5,
      "name": "Plant_Coral_Block_Purple"
    },
    {
      "x": -5,
      "y": 3,
      "z": 5,
      "name": "Plant_Coral_Block_Purple"
    },
    {
      "x": -5,
      "y": 4,
      "z": 5,
      "name": "Plant_Coral_Block_Purple"
    },
    {
      "x": -5,
      "y": 5,
      "z": 5,
      "name": "Plant_Coral_Block_Purple"
    },
    {
      "x": -5,
      "y": 6,
      "z": 5,
      "name": "Plant_Coral_Block_Purple"
    },
    {
      "x": -5,
      "y": 7,
      "z": 5,
      "name": "Plant_Coral_Block_Purple"
    },
    {
      "x": -5,
      "y": 11,
      "z": 5,
      "name": "Plant_Coral_Block_Purple"
    },
    {
      "x": -5,
      "y": 12,
      "z": 5,
      "name": "Plant_Coral_Block_Purple"
    },
    {
      "x": -5,
      "y": 13,
      "z": 5,
      "name": "Plant_Coral_Block_Purple"
    },
    {
      "x": -5,
      "y": 0,
      "z": 6,
      "name": "Rock_Slate"
    },
    {
      "x": -5,
      "y": 1,
      "z": 6,
      "name": "Rock_Slate"
    },
    {
      "x": -5,
      "y": 2,
      "z": 6,
      "name": "Rock_Slate"
    },
    {
      "x": -5,
      "y": 3,
      "z": 6,
      "name": "Rock_Slate"
    },
    {
      "x": -5,
      "y": 4,
      "z": 6,
      "name": "Rock_Slate"
    },
    {
      "x": -5,
      "y": 5,
      "z": 6,
      "name": "Rock_Slate"
    },
    {
      "x": -5,
      "y": 6,
      "z": 6,
      "name": "Rock_Slate"
    },
    {
      "x": -5,
      "y": 7,
      "z": 6,
      "name": "Rock_Slate"
    },
    {
      "x": -5,
      "y": 8,
      "z": 6,
      "name": "Plant_Coral_Block_Purple"
    },
    {
      "x": -5,
      "y": 9,
      "z": 6,
      "name": "Plant_Coral_Block_Purple"
    },
    {
      "x": -5,
      "y": 10,
      "z": 6,
      "name": "Plant_Coral_Block_Purple"
    },
    {
      "x": -5,
      "y": 11,
      "z": 6,
      "name": "Plant_Coral_Block_Purple"
    },
    {
      "x": -5,
      "y": 0,
      "z": 7,
      "name": "Rock_Slate"
    },
    {
      "x": -5,
      "y": 1,
      "z": 7,
      "name": "Rock_Slate"
    },
    {
      "x": -5,
      "y": 2,
      "z": 7,
      "name": "Rock_Slate"
    },
    {
      "x": -5,
      "y": 3,
      "z": 7,
      "name": "Rock_Slate"
    },
    {
      "x": -5,
      "y": 4,
      "z": 7,
      "name": "Rock_Slate"
    },
    {
      "x": -5,
      "y": 5,
      "z": 7,
      "name": "Rock_Slate"
    },
    {
      "x": -5,
      "y": 6,
      "z": 7,
      "name": "Rock_Slate"
    },
    {
      "x": -5,
      "y": 7,
      "z": 7,
      "name": "Rock_Slate"
    },
    {
      "x": -5,
      "y": 8,
      "z": 7,
      "name": "Rock_Slate"
    },
    {
      "x": -5,
      "y": 9,
      "z": 7,
      "name": "Rock_Slate"
    },
    {
      "x": -5,
      "y": 10,
      "z": 7,
      "name": "Rock_Slate"
    },
    {
      "x": -5,
      "y": 0,
      "z": 8,
      "name": "Rock_Slate"
    },
    {
      "x": -5,
      "y": 1,
      "z": 8,
      "name": "Rock_Slate"
    },
    {
      "x": -5,
      "y": 2,
      "z": 8,
      "name": "Rock_Slate"
    },
    {
      "x": -5,
      "y": 3,
      "z": 8,
      "name": "Rock_Slate"
    },
    {
      "x": -5,
      "y": 4,
      "z": 8,
      "name": "Rock_Slate"
    },
    {
      "x": -5,
      "y": 5,
      "z": 8,
      "name": "Rock_Slate"
    },
    {
      "x": -5,
      "y": 6,
      "z": 8,
      "name": "Rock_Slate"
    },
    {
      "x": -5,
      "y": 7,
      "z": 8,
      "name": "Rock_Slate"
    },
    {
      "x": -5,
      "y": 8,
      "z": 8,
      "name": "Rock_Slate"
    },
    {
      "x": -5,
      "y": 9,
      "z": 8,
      "name": "Rock_Slate"
    },
    {
      "x": -5,
      "y": 10,
      "z": 8,
      "name": "Rock_Slate"
    },
    {
      "x": -5,
      "y": 0,
      "z": 9,
      "name": "Plant_Coral_Block_Purple"
    },
    {
      "x": -5,
      "y": 1,
      "z": 9,
      "name": "Plant_Coral_Block_Purple"
    },
    {
      "x": -5,
      "y": 2,
      "z": 9,
      "name": "Plant_Coral_Block_Purple"
    },
    {
      "x": -5,
      "y": 3,
      "z": 9,
      "name": "Plant_Coral_Block_Purple"
    },
    {
      "x": -5,
      "y": 4,
      "z": 9,
      "name": "Plant_Coral_Block_Purple"
    },
    {
      "x": -5,
      "y": 5,
      "z": 9,
      "name": "Plant_Coral_Block_Purple"
    },
    {
      "x": -5,
      "y": 6,
      "z": 9,
      "name": "Plant_Coral_Block_Purple"
    },
    {
      "x": -5,
      "y": 7,
      "z": 9,
      "name": "Plant_Coral_Block_Purple"
    },
    {
      "x": -5,
      "y": 8,
      "z": 9,
      "name": "Rock_Slate"
    },
    {
      "x": -5,
      "y": 9,
      "z": 9,
      "name": "Rock_Slate"
    },
    {
      "x": -5,
      "y": 8,
      "z": 10,
      "name": "Plant_Coral_Block_Purple"
    },
    {
      "x": -5,
      "y": 9,
      "z": 10,
      "name": "Plant_Coral_Block_Purple"
    },
    {
      "x": -5,
      "y": 10,
      "z": 10,
      "name": "Plant_Coral_Block_Purple"
    },
    {
      "x": -4,
      "y": 0,
      "z": -8,
      "name": "Plant_Coral_Block_Purple"
    },
    {
      "x": -4,
      "y": 1,
      "z": -8,
      "name": "Plant_Coral_Block_Purple"
    },
    {
      "x": -4,
      "y": 2,
      "z": -8,
      "name": "Plant_Coral_Block_Purple"
    },
    {
      "x": -4,
      "y": 3,
      "z": -8,
      "name": "Plant_Coral_Block_Purple"
    },
    {
      "x": -4,
      "y": 4,
      "z": -8,
      "name": "Plant_Coral_Block_Purple"
    },
    {
      "x": -4,
      "y": 5,
      "z": -8,
      "name": "Plant_Coral_Block_Purple"
    },
    {
      "x": -4,
      "y": 6,
      "z": -8,
      "name": "Plant_Coral_Block_Purple"
    },
    {
      "x": -4,
      "y": 7,
      "z": -8,
      "name": "Plant_Coral_Block_Purple"
    },
    {
      "x": -4,
      "y": 0,
      "z": -7,
      "name": "Rock_Slate"
    },
    {
      "x": -4,
      "y": 1,
      "z": -7,
      "name": "Rock_Slate"
    },
    {
      "x": -4,
      "y": 2,
      "z": -7,
      "name": "Rock_Slate"
    },
    {
      "x": -4,
      "y": 3,
      "z": -7,
      "name": "Rock_Slate"
    },
    {
      "x": -4,
      "y": 4,
      "z": -7,
      "name": "Rock_Slate"
    },
    {
      "x": -4,
      "y": 5,
      "z": -7,
      "name": "Rock_Slate"
    },
    {
      "x": -4,
      "y": 6,
      "z": -7,
      "name": "Rock_Slate"
    },
    {
      "x": -4,
      "y": 7,
      "z": -7,
      "name": "Rock_Slate"
    },
    {
      "x": -4,
      "y": 8,
      "z": -7,
      "name": "Plant_Coral_Block_Purple"
    },
    {
      "x": -4,
      "y": 9,
      "z": -7,
      "name": "Plant_Coral_Block_Purple"
    },
    {
      "x": -4,
      "y": 0,
      "z": -6,
      "name": "Rock_Slate"
    },
    {
      "x": -4,
      "y": 1,
      "z": -6,
      "name": "Rock_Slate"
    },
    {
      "x": -4,
      "y": 2,
      "z": -6,
      "name": "Rock_Slate"
    },
    {
      "x": -4,
      "y": 3,
      "z": -6,
      "name": "Rock_Slate"
    },
    {
      "x": -4,
      "y": 4,
      "z": -6,
      "name": "Rock_Slate"
    },
    {
      "x": -4,
      "y": 5,
      "z": -6,
      "name": "Rock_Slate"
    },
    {
      "x": -4,
      "y": 6,
      "z": -6,
      "name": "Rock_Slate"
    },
    {
      "x": -4,
      "y": 7,
      "z": -6,
      "name": "Rock_Slate"
    },
    {
      "x": -4,
      "y": 8,
      "z": -6,
      "name": "Rock_Slate"
    },
    {
      "x": -4,
      "y": 0,
      "z": -5,
      "name": "Rock_Slate"
    },
    {
      "x": -4,
      "y": 1,
      "z": -5,
      "name": "Rock_Slate"
    },
    {
      "x": -4,
      "y": 2,
      "z": -5,
      "name": "Rock_Slate"
    },
    {
      "x": -4,
      "y": 3,
      "z": -5,
      "name": "Rock_Slate"
    },
    {
      "x": -4,
      "y": 4,
      "z": -5,
      "name": "Rock_Slate"
    },
    {
      "x": -4,
      "y": 5,
      "z": -5,
      "name": "Rock_Slate"
    },
    {
      "x": -4,
      "y": 6,
      "z": -5,
      "name": "Rock_Slate"
    },
    {
      "x": -4,
      "y": 7,
      "z": -5,
      "name": "Rock_Slate"
    },
    {
      "x": -4,
      "y": 8,
      "z": -5,
      "name": "Rock_Slate"
    },
    {
      "x": -4,
      "y": 0,
      "z": -4,
      "name": "Plant_Coral_Block_Purple"
    },
    {
      "x": -4,
      "y": 1,
      "z": -4,
      "name": "Plant_Coral_Block_Purple"
    },
    {
      "x": -4,
      "y": 2,
      "z": -4,
      "name": "Plant_Coral_Block_Purple"
    },
    {
      "x": -4,
      "y": 3,
      "z": -4,
      "name": "Plant_Coral_Block_Purple"
    },
    {
      "x": -4,
      "y": 4,
      "z": -4,
      "name": "Plant_Coral_Block_Purple"
    },
    {
      "x": -4,
      "y": 5,
      "z": -4,
      "name": "Plant_Coral_Block_Purple"
    },
    {
      "x": -4,
      "y": 6,
      "z": -4,
      "name": "Plant_Coral_Block_Purple"
    },
    {
      "x": -4,
      "y": 7,
      "z": -4,
      "name": "Plant_Coral_Block_Purple"
    },
    {
      "x": -4,
      "y": 8,
      "z": -4,
      "name": "Rock_Slate"
    },
    {
      "x": -4,
      "y": 9,
      "z": -4,
      "name": "Rock_Slate"
    },
    {
      "x": -4,
      "y": 8,
      "z": -3,
      "name": "Plant_Coral_Block_Purple"
    },
    {
      "x": -4,
      "y": 9,
      "z": -3,
      "name": "Plant_Coral_Block_Purple"
    },
    {
      "x": -4,
      "y": 10,
      "z": -3,
      "name": "Plant_Coral_Block_Purple"
    },
    {
      "x": -4,
      "y": 11,
      "z": -3,
      "name": "Plant_Coral_Block_Purple"
    },
    {
      "x": -4,
      "y": 12,
      "z": -3,
      "name": "Plant_Coral_Block_Purple"
    },
    {
      "x": -4,
      "y": 9,
      "z": -2,
      "name": "Plant_Coral_Block_Purple"
    },
    {
      "x": -4,
      "y": 10,
      "z": -2,
      "name": "Plant_Coral_Block_Purple"
    },
    {
      "x": -4,
      "y": 11,
      "z": -2,
      "name": "Plant_Coral_Block_Purple"
    },
    {
      "x": -4,
      "y": 12,
      "z": -2,
      "name": "Plant_Coral_Block_Purple"
    },
    {
      "x": -4,
      "y": 9,
      "z": -1,
      "name": "Plant_Coral_Block_Purple"
    },
    {
      "x": -4,
      "y": 10,
      "z": -1,
      "name": "Plant_Coral_Block_Purple"
    },
    {
      "x": -4,
      "y": 11,
      "z": -1,
      "name": "Plant_Coral_Block_Purple"
    },
    {
      "x": -4,
      "y": 12,
      "z": -1,
      "name": "Plant_Coral_Block_Purple"
    },
    {
      "x": -4,
      "y": 8,
      "z": 0,
      "name": "Plant_Coral_Block_Purple"
    },
    {
      "x": -4,
      "y": 9,
      "z": 0,
      "name": "Plant_Coral_Block_Purple"
    },
    {
      "x": -4,
      "y": 10,
      "z": 0,
      "name": "Plant_Coral_Block_Purple"
    },
    {
      "x": -4,
      "y": 0,
      "z": 1,
      "name": "Plant_Coral_Block_Purple"
    },
    {
      "x": -4,
      "y": 1,
      "z": 1,
      "name": "Plant_Coral_Block_Purple"
    },
    {
      "x": -4,
      "y": 2,
      "z": 1,
      "name": "Plant_Coral_Block_Purple"
    },
    {
      "x": -4,
      "y": 3,
      "z": 1,
      "name": "Plant_Coral_Block_Purple"
    },
    {
      "x": -4,
      "y": 4,
      "z": 1,
      "name": "Plant_Coral_Block_Purple"
    },
    {
      "x": -4,
      "y": 5,
      "z": 1,
      "name": "Plant_Coral_Block_Purple"
    },
    {
      "x": -4,
      "y": 6,
      "z": 1,
      "name": "Plant_Coral_Block_Purple"
    },
    {
      "x": -4,
      "y": 7,
      "z": 1,
      "name": "Plant_Coral_Block_Purple"
    },
    {
      "x": -4,
      "y": 8,
      "z": 1,
      "name": "Rock_Slate"
    },
    {
      "x": -4,
      "y": 9,
      "z": 1,
      "name": "Rock_Slate"
    },
    {
      "x": -4,
      "y": 10,
      "z": 1,
      "name": "Rock_Slate"
    },
    {
      "x": -4,
      "y": 11,
      "z": 1,
      "name": "Plant_Coral_Block_Purple"
    },
    {
      "x": -4,
      "y": 12,
      "z": 1,
      "name": "Plant_Coral_Block_Purple"
    },
    {
      "x": -4,
      "y": 13,
      "z": 1,
      "name": "Plant_Coral_Block_Purple"
    },
    {
      "x": -4,
      "y": 14,
      "z": 1,
      "name": "Plant_Coral_Block_Purple"
    },
    {
      "x": -4,
      "y": 15,
      "z": 1,
      "name": "Plant_Coral_Block_Purple"
    },
    {
      "x": -4,
      "y": 0,
      "z": 2,
      "name": "Rock_Slate"
    },
    {
      "x": -4,
      "y": 1,
      "z": 2,
      "name": "Rock_Slate"
    },
    {
      "x": -4,
      "y": 2,
      "z": 2,
      "name": "Rock_Slate"
    },
    {
      "x": -4,
      "y": 3,
      "z": 2,
      "name": "Rock_Slate"
    },
    {
      "x": -4,
      "y": 4,
      "z": 2,
      "name": "Rock_Slate"
    },
    {
      "x": -4,
      "y": 5,
      "z": 2,
      "name": "Rock_Slate"
    },
    {
      "x": -4,
      "y": 6,
      "z": 2,
      "name": "Rock_Slate"
    },
    {
      "x": -4,
      "y": 7,
      "z": 2,
      "name": "Rock_Slate"
    },
    {
      "x": -4,
      "y": 8,
      "z": 2,
      "name": "Rock_Slate"
    },
    {
      "x": -4,
      "y": 9,
      "z": 2,
      "name": "Rock_Slate"
    },
    {
      "x": -4,
      "y": 10,
      "z": 2,
      "name": "Rock_Slate"
    },
    {
      "x": -4,
      "y": 11,
      "z": 2,
      "name": "Rock_Slate"
    },
    {
      "x": -4,
      "y": 12,
      "z": 2,
      "name": "Rock_Slate"
    },
    {
      "x": -4,
      "y": 13,
      "z": 2,
      "name": "Rock_Slate"
    },
    {
      "x": -4,
      "y": 14,
      "z": 2,
      "name": "Rock_Slate"
    },
    {
      "x": -4,
      "y": 0,
      "z": 3,
      "name": "Rock_Slate"
    },
    {
      "x": -4,
      "y": 1,
      "z": 3,
      "name": "Rock_Slate"
    },
    {
      "x": -4,
      "y": 2,
      "z": 3,
      "name": "Rock_Slate"
    },
    {
      "x": -4,
      "y": 3,
      "z": 3,
      "name": "Rock_Slate"
    },
    {
      "x": -4,
      "y": 4,
      "z": 3,
      "name": "Rock_Slate"
    },
    {
      "x": -4,
      "y": 5,
      "z": 3,
      "name": "Rock_Slate"
    },
    {
      "x": -4,
      "y": 6,
      "z": 3,
      "name": "Rock_Slate"
    },
    {
      "x": -4,
      "y": 7,
      "z": 3,
      "name": "Rock_Slate"
    },
    {
      "x": -4,
      "y": 8,
      "z": 3,
      "name": "Rock_Slate"
    },
    {
      "x": -4,
      "y": 9,
      "z": 3,
      "name": "Rock_Slate"
    },
    {
      "x": -4,
      "y": 10,
      "z": 3,
      "name": "Rock_Slate"
    },
    {
      "x": -4,
      "y": 11,
      "z": 3,
      "name": "Rock_Slate"
    },
    {
      "x": -4,
      "y": 12,
      "z": 3,
      "name": "Rock_Slate"
    },
    {
      "x": -4,
      "y": 13,
      "z": 3,
      "name": "Rock_Slate"
    },
    {
      "x": -4,
      "y": 0,
      "z": 4,
      "name": "Rock_Slate"
    },
    {
      "x": -4,
      "y": 1,
      "z": 4,
      "name": "Rock_Slate"
    },
    {
      "x": -4,
      "y": 2,
      "z": 4,
      "name": "Rock_Slate"
    },
    {
      "x": -4,
      "y": 3,
      "z": 4,
      "name": "Rock_Slate"
    },
    {
      "x": -4,
      "y": 4,
      "z": 4,
      "name": "Rock_Slate"
    },
    {
      "x": -4,
      "y": 5,
      "z": 4,
      "name": "Rock_Slate"
    },
    {
      "x": -4,
      "y": 6,
      "z": 4,
      "name": "Rock_Slate"
    },
    {
      "x": -4,
      "y": 7,
      "z": 4,
      "name": "Rock_Slate"
    },
    {
      "x": -4,
      "y": 8,
      "z": 4,
      "name": "Plant_Coral_Block_Purple"
    },
    {
      "x": -4,
      "y": 9,
      "z": 4,
      "name": "Plant_Coral_Block_Purple"
    },
    {
      "x": -4,
      "y": 10,
      "z": 4,
      "name": "Plant_Coral_Block_Purple"
    },
    {
      "x": -4,
      "y": 11,
      "z": 4,
      "name": "Rock_Slate"
    },
    {
      "x": -4,
      "y": 12,
      "z": 4,
      "name": "Rock_Slate"
    },
    {
      "x": -4,
      "y": 13,
      "z": 4,
      "name": "Rock_Slate"
    },
    {
      "x": -4,
      "y": 0,
      "z": 5,
      "name": "Plant_Coral_Block_Purple"
    },
    {
      "x": -4,
      "y": 1,
      "z": 5,
      "name": "Plant_Coral_Block_Purple"
    },
    {
      "x": -4,
      "y": 2,
      "z": 5,
      "name": "Plant_Coral_Block_Purple"
    },
    {
      "x": -4,
      "y": 3,
      "z": 5,
      "name": "Plant_Coral_Block_Purple"
    },
    {
      "x": -4,
      "y": 4,
      "z": 5,
      "name": "Plant_Coral_Block_Purple"
    },
    {
      "x": -4,
      "y": 5,
      "z": 5,
      "name": "Plant_Coral_Block_Purple"
    },
    {
      "x": -4,
      "y": 6,
      "z": 5,
      "name": "Plant_Coral_Block_Purple"
    },
    {
      "x": -4,
      "y": 7,
      "z": 5,
      "name": "Plant_Coral_Block_Purple"
    },
    {
      "x": -4,
      "y": 11,
      "z": 5,
      "name": "Plant_Coral_Block_Purple"
    },
    {
      "x": -4,
      "y": 12,
      "z": 5,
      "name": "Plant_Coral_Block_Purple"
    },
    {
      "x": -4,
      "y": 13,
      "z": 5,
      "name": "Plant_Coral_Block_Purple"
    },
    {
      "x": -4,
      "y": 14,
      "z": 5,
      "name": "Plant_Coral_Block_Purple"
    },
    {
      "x": -4,
      "y": 0,
      "z": 6,
      "name": "Plant_Coral_Block_Purple"
    },
    {
      "x": -4,
      "y": 1,
      "z": 6,
      "name": "Plant_Coral_Block_Purple"
    },
    {
      "x": -4,
      "y": 2,
      "z": 6,
      "name": "Plant_Coral_Block_Purple"
    },
    {
      "x": -4,
      "y": 3,
      "z": 6,
      "name": "Plant_Coral_Block_Purple"
    },
    {
      "x": -4,
      "y": 4,
      "z": 6,
      "name": "Plant_Coral_Block_Purple"
    },
    {
      "x": -4,
      "y": 5,
      "z": 6,
      "name": "Plant_Coral_Block_Purple"
    },
    {
      "x": -4,
      "y": 6,
      "z": 6,
      "name": "Plant_Coral_Block_Purple"
    },
    {
      "x": -4,
      "y": 7,
      "z": 6,
      "name": "Plant_Coral_Block_Purple"
    },
    {
      "x": -4,
      "y": 0,
      "z": 7,
      "name": "Plant_Coral_Block_Purple"
    },
    {
      "x": -4,
      "y": 1,
      "z": 7,
      "name": "Plant_Coral_Block_Purple"
    },
    {
      "x": -4,
      "y": 2,
      "z": 7,
      "name": "Plant_Coral_Block_Purple"
    },
    {
      "x": -4,
      "y": 3,
      "z": 7,
      "name": "Plant_Coral_Block_Purple"
    },
    {
      "x": -4,
      "y": 4,
      "z": 7,
      "name": "Plant_Coral_Block_Purple"
    },
    {
      "x": -4,
      "y": 5,
      "z": 7,
      "name": "Plant_Coral_Block_Purple"
    },
    {
      "x": -4,
      "y": 6,
      "z": 7,
      "name": "Plant_Coral_Block_Purple"
    },
    {
      "x": -4,
      "y": 7,
      "z": 7,
      "name": "Plant_Coral_Block_Purple"
    },
    {
      "x": -4,
      "y": 8,
      "z": 7,
      "name": "Plant_Coral_Block_Purple"
    },
    {
      "x": -4,
      "y": 9,
      "z": 7,
      "name": "Plant_Coral_Block_Purple"
    },
    {
      "x": -4,
      "y": 10,
      "z": 7,
      "name": "Plant_Coral_Block_Purple"
    },
    {
      "x": -4,
      "y": 11,
      "z": 7,
      "name": "Plant_Coral_Block_Purple"
    },
    {
      "x": -4,
      "y": 0,
      "z": 8,
      "name": "Plant_Coral_Block_Purple"
    },
    {
      "x": -4,
      "y": 1,
      "z": 8,
      "name": "Plant_Coral_Block_Purple"
    },
    {
      "x": -4,
      "y": 2,
      "z": 8,
      "name": "Plant_Coral_Block_Purple"
    },
    {
      "x": -4,
      "y": 3,
      "z": 8,
      "name": "Plant_Coral_Block_Purple"
    },
    {
      "x": -4,
      "y": 4,
      "z": 8,
      "name": "Plant_Coral_Block_Purple"
    },
    {
      "x": -4,
      "y": 5,
      "z": 8,
      "name": "Plant_Coral_Block_Purple"
    },
    {
      "x": -4,
      "y": 6,
      "z": 8,
      "name": "Plant_Coral_Block_Purple"
    },
    {
      "x": -4,
      "y": 7,
      "z": 8,
      "name": "Plant_Coral_Block_Purple"
    },
    {
      "x": -4,
      "y": 8,
      "z": 8,
      "name": "Plant_Coral_Block_Purple"
    },
    {
      "x": -4,
      "y": 9,
      "z": 8,
      "name": "Plant_Coral_Block_Purple"
    },
    {
      "x": -4,
      "y": 10,
      "z": 8,
      "name": "Plant_Coral_Block_Purple"
    },
    {
      "x": -4,
      "y": 11,
      "z": 8,
      "name": "Plant_Coral_Block_Purple"
    },
    {
      "x": -4,
      "y": 7,
      "z": 9,
      "name": "Plant_Coral_Block_Purple"
    },
    {
      "x": -4,
      "y": 8,
      "z": 9,
      "name": "Plant_Coral_Block_Purple"
    },
    {
      "x": -4,
      "y": 9,
      "z": 9,
      "name": "Plant_Coral_Block_Purple"
    },
    {
      "x": -4,
      "y": 10,
      "z": 9,
      "name": "Plant_Coral_Block_Purple"
    },
    {
      "x": -3,
      "y": 0,
      "z": -8,
      "name": "Plant_Coral_Block_Purple"
    },
    {
      "x": -3,
      "y": 1,
      "z": -8,
      "name": "Plant_Coral_Block_Purple"
    },
    {
      "x": -3,
      "y": 2,
      "z": -8,
      "name": "Plant_Coral_Block_Purple"
    },
    {
      "x": -3,
      "y": 3,
      "z": -8,
      "name": "Plant_Coral_Block_Purple"
    },
    {
      "x": -3,
      "y": 4,
      "z": -8,
      "name": "Plant_Coral_Block_Purple"
    },
    {
      "x": -3,
      "y": 5,
      "z": -8,
      "name": "Plant_Coral_Block_Purple"
    },
    {
      "x": -3,
      "y": 6,
      "z": -8,
      "name": "Plant_Coral_Block_Purple"
    },
    {
      "x": -3,
      "y": 7,
      "z": -8,
      "name": "Plant_Coral_Block_Purple"
    },
    {
      "x": -3,
      "y": 8,
      "z": -8,
      "name": "Plant_Coral_Block_Purple"
    },
    {
      "x": -3,
      "y": 0,
      "z": -7,
      "name": "Rock_Slate"
    },
    {
      "x": -3,
      "y": 1,
      "z": -7,
      "name": "Rock_Slate"
    },
    {
      "x": -3,
      "y": 2,
      "z": -7,
      "name": "Rock_Slate"
    },
    {
      "x": -3,
      "y": 3,
      "z": -7,
      "name": "Rock_Slate"
    },
    {
      "x": -3,
      "y": 4,
      "z": -7,
      "name": "Rock_Slate"
    },
    {
      "x": -3,
      "y": 5,
      "z": -7,
      "name": "Rock_Slate"
    },
    {
      "x": -3,
      "y": 6,
      "z": -7,
      "name": "Rock_Slate"
    },
    {
      "x": -3,
      "y": 7,
      "z": -7,
      "name": "Rock_Slate"
    },
    {
      "x": -3,
      "y": 8,
      "z": -7,
      "name": "Plant_Coral_Block_Purple"
    },
    {
      "x": -3,
      "y": 9,
      "z": -7,
      "name": "Plant_Coral_Block_Purple"
    },
    {
      "x": -3,
      "y": 0,
      "z": -6,
      "name": "Rock_Slate"
    },
    {
      "x": -3,
      "y": 1,
      "z": -6,
      "name": "Rock_Slate"
    },
    {
      "x": -3,
      "y": 2,
      "z": -6,
      "name": "Rock_Slate"
    },
    {
      "x": -3,
      "y": 3,
      "z": -6,
      "name": "Rock_Slate"
    },
    {
      "x": -3,
      "y": 4,
      "z": -6,
      "name": "Rock_Slate"
    },
    {
      "x": -3,
      "y": 5,
      "z": -6,
      "name": "Rock_Slate"
    },
    {
      "x": -3,
      "y": 6,
      "z": -6,
      "name": "Rock_Slate"
    },
    {
      "x": -3,
      "y": 7,
      "z": -6,
      "name": "Rock_Slate"
    },
    {
      "x": -3,
      "y": 8,
      "z": -6,
      "name": "Rock_Slate"
    },
    {
      "x": -3,
      "y": 0,
      "z": -5,
      "name": "Rock_Slate"
    },
    {
      "x": -3,
      "y": 1,
      "z": -5,
      "name": "Rock_Slate"
    },
    {
      "x": -3,
      "y": 2,
      "z": -5,
      "name": "Rock_Slate"
    },
    {
      "x": -3,
      "y": 3,
      "z": -5,
      "name": "Rock_Slate"
    },
    {
      "x": -3,
      "y": 4,
      "z": -5,
      "name": "Rock_Slate"
    },
    {
      "x": -3,
      "y": 5,
      "z": -5,
      "name": "Rock_Slate"
    },
    {
      "x": -3,
      "y": 6,
      "z": -5,
      "name": "Rock_Slate"
    },
    {
      "x": -3,
      "y": 7,
      "z": -5,
      "name": "Rock_Slate"
    },
    {
      "x": -3,
      "y": 8,
      "z": -5,
      "name": "Rock_Slate"
    },
    {
      "x": -3,
      "y": 0,
      "z": -4,
      "name": "Plant_Coral_Block_Purple"
    },
    {
      "x": -3,
      "y": 1,
      "z": -4,
      "name": "Plant_Coral_Block_Purple"
    },
    {
      "x": -3,
      "y": 2,
      "z": -4,
      "name": "Plant_Coral_Block_Purple"
    },
    {
      "x": -3,
      "y": 3,
      "z": -4,
      "name": "Plant_Coral_Block_Purple"
    },
    {
      "x": -3,
      "y": 4,
      "z": -4,
      "name": "Plant_Coral_Block_Purple"
    },
    {
      "x": -3,
      "y": 5,
      "z": -4,
      "name": "Plant_Coral_Block_Purple"
    },
    {
      "x": -3,
      "y": 6,
      "z": -4,
      "name": "Plant_Coral_Block_Purple"
    },
    {
      "x": -3,
      "y": 7,
      "z": -4,
      "name": "Plant_Coral_Block_Purple"
    },
    {
      "x": -3,
      "y": 8,
      "z": -4,
      "name": "Rock_Slate"
    },
    {
      "x": -3,
      "y": 9,
      "z": -4,
      "name": "Rock_Slate"
    },
    {
      "x": -3,
      "y": 8,
      "z": -3,
      "name": "Plant_Coral_Block_Purple"
    },
    {
      "x": -3,
      "y": 9,
      "z": -3,
      "name": "Plant_Coral_Block_Purple"
    },
    {
      "x": -3,
      "y": 10,
      "z": -3,
      "name": "Plant_Coral_Block_Purple"
    },
    {
      "x": -3,
      "y": 8,
      "z": 0,
      "name": "Plant_Coral_Block_Purple"
    },
    {
      "x": -3,
      "y": 9,
      "z": 0,
      "name": "Plant_Coral_Block_Purple"
    },
    {
      "x": -3,
      "y": 10,
      "z": 0,
      "name": "Plant_Coral_Block_Purple"
    },
    {
      "x": -3,
      "y": 0,
      "z": 1,
      "name": "Plant_Coral_Block_Purple"
    },
    {
      "x": -3,
      "y": 1,
      "z": 1,
      "name": "Plant_Coral_Block_Purple"
    },
    {
      "x": -3,
      "y": 2,
      "z": 1,
      "name": "Plant_Coral_Block_Purple"
    },
    {
      "x": -3,
      "y": 3,
      "z": 1,
      "name": "Plant_Coral_Block_Purple"
    },
    {
      "x": -3,
      "y": 4,
      "z": 1,
      "name": "Plant_Coral_Block_Purple"
    },
    {
      "x": -3,
      "y": 5,
      "z": 1,
      "name": "Plant_Coral_Block_Purple"
    },
    {
      "x": -3,
      "y": 6,
      "z": 1,
      "name": "Plant_Coral_Block_Purple"
    },
    {
      "x": -3,
      "y": 7,
      "z": 1,
      "name": "Plant_Coral_Block_Purple"
    },
    {
      "x": -3,
      "y": 8,
      "z": 1,
      "name": "Rock_Slate"
    },
    {
      "x": -3,
      "y": 9,
      "z": 1,
      "name": "Rock_Slate"
    },
    {
      "x": -3,
      "y": 10,
      "z": 1,
      "name": "Rock_Slate"
    },
    {
      "x": -3,
      "y": 11,
      "z": 1,
      "name": "Plant_Coral_Block_Purple"
    },
    {
      "x": -3,
      "y": 12,
      "z": 1,
      "name": "Plant_Coral_Block_Purple"
    },
    {
      "x": -3,
      "y": 13,
      "z": 1,
      "name": "Plant_Coral_Block_Purple"
    },
    {
      "x": -3,
      "y": 14,
      "z": 1,
      "name": "Plant_Coral_Block_Purple"
    },
    {
      "x": -3,
      "y": 15,
      "z": 1,
      "name": "Plant_Coral_Block_Purple"
    },
    {
      "x": -3,
      "y": 16,
      "z": 1,
      "name": "Plant_Coral_Block_Purple"
    },
    {
      "x": -3,
      "y": 0,
      "z": 2,
      "name": "Rock_Slate"
    },
    {
      "x": -3,
      "y": 1,
      "z": 2,
      "name": "Rock_Slate"
    },
    {
      "x": -3,
      "y": 2,
      "z": 2,
      "name": "Rock_Slate"
    },
    {
      "x": -3,
      "y": 3,
      "z": 2,
      "name": "Rock_Slate"
    },
    {
      "x": -3,
      "y": 4,
      "z": 2,
      "name": "Rock_Slate"
    },
    {
      "x": -3,
      "y": 5,
      "z": 2,
      "name": "Rock_Slate"
    },
    {
      "x": -3,
      "y": 6,
      "z": 2,
      "name": "Rock_Slate"
    },
    {
      "x": -3,
      "y": 7,
      "z": 2,
      "name": "Rock_Slate"
    },
    {
      "x": -3,
      "y": 8,
      "z": 2,
      "name": "Rock_Slate"
    },
    {
      "x": -3,
      "y": 9,
      "z": 2,
      "name": "Rock_Slate"
    },
    {
      "x": -3,
      "y": 10,
      "z": 2,
      "name": "Rock_Slate"
    },
    {
      "x": -3,
      "y": 11,
      "z": 2,
      "name": "Rock_Slate"
    },
    {
      "x": -3,
      "y": 12,
      "z": 2,
      "name": "Rock_Slate"
    },
    {
      "x": -3,
      "y": 13,
      "z": 2,
      "name": "Rock_Slate"
    },
    {
      "x": -3,
      "y": 14,
      "z": 2,
      "name": "Rock_Slate"
    },
    {
      "x": -3,
      "y": 0,
      "z": 3,
      "name": "Rock_Slate"
    },
    {
      "x": -3,
      "y": 1,
      "z": 3,
      "name": "Rock_Slate"
    },
    {
      "x": -3,
      "y": 2,
      "z": 3,
      "name": "Rock_Slate"
    },
    {
      "x": -3,
      "y": 3,
      "z": 3,
      "name": "Rock_Slate"
    },
    {
      "x": -3,
      "y": 4,
      "z": 3,
      "name": "Rock_Slate"
    },
    {
      "x": -3,
      "y": 5,
      "z": 3,
      "name": "Rock_Slate"
    },
    {
      "x": -3,
      "y": 6,
      "z": 3,
      "name": "Rock_Slate"
    },
    {
      "x": -3,
      "y": 7,
      "z": 3,
      "name": "Rock_Slate"
    },
    {
      "x": -3,
      "y": 8,
      "z": 3,
      "name": "Rock_Slate"
    },
    {
      "x": -3,
      "y": 9,
      "z": 3,
      "name": "Rock_Slate"
    },
    {
      "x": -3,
      "y": 10,
      "z": 3,
      "name": "Rock_Slate"
    },
    {
      "x": -3,
      "y": 11,
      "z": 3,
      "name": "Rock_Slate"
    },
    {
      "x": -3,
      "y": 12,
      "z": 3,
      "name": "Rock_Slate"
    },
    {
      "x": -3,
      "y": 13,
      "z": 3,
      "name": "Rock_Slate"
    },
    {
      "x": -3,
      "y": 14,
      "z": 3,
      "name": "Rock_Slate"
    },
    {
      "x": -3,
      "y": 0,
      "z": 4,
      "name": "Rock_Slate"
    },
    {
      "x": -3,
      "y": 1,
      "z": 4,
      "name": "Rock_Slate"
    },
    {
      "x": -3,
      "y": 2,
      "z": 4,
      "name": "Rock_Slate"
    },
    {
      "x": -3,
      "y": 3,
      "z": 4,
      "name": "Rock_Slate"
    },
    {
      "x": -3,
      "y": 4,
      "z": 4,
      "name": "Rock_Slate"
    },
    {
      "x": -3,
      "y": 5,
      "z": 4,
      "name": "Rock_Slate"
    },
    {
      "x": -3,
      "y": 6,
      "z": 4,
      "name": "Rock_Slate"
    },
    {
      "x": -3,
      "y": 7,
      "z": 4,
      "name": "Rock_Slate"
    },
    {
      "x": -3,
      "y": 8,
      "z": 4,
      "name": "Plant_Coral_Block_Purple"
    },
    {
      "x": -3,
      "y": 9,
      "z": 4,
      "name": "Plant_Coral_Block_Purple"
    },
    {
      "x": -3,
      "y": 10,
      "z": 4,
      "name": "Plant_Coral_Block_Purple"
    },
    {
      "x": -3,
      "y": 11,
      "z": 4,
      "name": "Rock_Slate"
    },
    {
      "x": -3,
      "y": 12,
      "z": 4,
      "name": "Rock_Slate"
    },
    {
      "x": -3,
      "y": 13,
      "z": 4,
      "name": "Rock_Slate"
    },
    {
      "x": -3,
      "y": 0,
      "z": 5,
      "name": "Plant_Coral_Block_Purple"
    },
    {
      "x": -3,
      "y": 1,
      "z": 5,
      "name": "Plant_Coral_Block_Purple"
    },
    {
      "x": -3,
      "y": 2,
      "z": 5,
      "name": "Plant_Coral_Block_Purple"
    },
    {
      "x": -3,
      "y": 3,
      "z": 5,
      "name": "Plant_Coral_Block_Purple"
    },
    {
      "x": -3,
      "y": 4,
      "z": 5,
      "name": "Plant_Coral_Block_Purple"
    },
    {
      "x": -3,
      "y": 5,
      "z": 5,
      "name": "Plant_Coral_Block_Purple"
    },
    {
      "x": -3,
      "y": 6,
      "z": 5,
      "name": "Plant_Coral_Block_Purple"
    },
    {
      "x": -3,
      "y": 7,
      "z": 5,
      "name": "Plant_Coral_Block_Purple"
    },
    {
      "x": -3,
      "y": 11,
      "z": 5,
      "name": "Plant_Coral_Block_Purple"
    },
    {
      "x": -3,
      "y": 12,
      "z": 5,
      "name": "Plant_Coral_Block_Purple"
    },
    {
      "x": -3,
      "y": 13,
      "z": 5,
      "name": "Plant_Coral_Block_Purple"
    },
    {
      "x": -3,
      "y": 14,
      "z": 5,
      "name": "Plant_Coral_Block_Purple"
    },
    {
      "x": -3,
      "y": 15,
      "z": 5,
      "name": "Plant_Coral_Block_Purple"
    },
    {
      "x": -3,
      "y": 0,
      "z": 7,
      "name": "Plant_Coral_Block_Purple"
    },
    {
      "x": -3,
      "y": 1,
      "z": 7,
