{
  "version": 8,
  "blockIdVersion": 8,
  "anchorX": 6,
  "anchorY": 0,
  "anchorZ": 6,
  "blocks": [
    {
      "x": 1,
      "y": 10,
      "z": 6,
      "name": "Plant_Leaves_Aspen"
    },
    {
      "x": 2,
      "y": 9,
      "z": 4,
      "name": "Plant_Leaves_Aspen"
    },
    {
      "x": 2,
      "y": 9,
      "z": 5,
      "name": "Plant_Leaves_Aspen"
    },
    {
      "x": 2,
      "y": 10,
      "z": 5,
      "name": "Plant_Leaves_Aspen"
    },
    {
      "x": 2,
      "y": 11,
      "z": 5,
      "name": "Plant_Leaves_Aspen"
    },
    {
      "x": 2,
      "y": 12,
      "z": 5,
      "name": "Plant_Leaves_Aspen"
    },
    {
      "x": 2,
      "y": 8,
      "z": 6,
      "name": "Plant_Leaves_Aspen"
    },
    {
      "x": 2,
      "y": 9,
      "z": 6,
      "name": "Plant_Leaves_Aspen"
    },
    {
      "x": 2,
      "y": 10,
      "z": 6,
      "name": "Plant_Leaves_Aspen"
    },
    {
      "x": 2,
      "y": 11,
      "z": 6,
      "name": "Plant_Leaves_Aspen"
    },
    {
      "x": 2,
      "y": 12,
      "z": 6,
      "name": "Plant_Leaves_Aspen"
    },
    {
      "x": 2,
      "y": 13,
      "z": 6,
      "name": "Plant_Leaves_Aspen"
    },
    {
      "x": 2,
      "y": 8,
      "z": 7,
      "name": "Plant_Leaves_Aspen"
    },
    {
      "x": 2,
      "y": 9,
      "z": 7,
      "name": "Plant_Leaves_Aspen"
    },
    {
      "x": 2,
      "y": 8,
      "z": 8,
      "name": "Plant_Leaves_Aspen"
    },
    {
      "x": 3,
      "y": 9,
      "z": 3,
      "name": "Plant_Leaves_Aspen"
    },
    {
      "x": 3,
      "y": 10,
      "z": 3,
      "name": "Plant_Leaves_Aspen"
    },
    {
      "x": 3,
      "y": 11,
      "z": 3,
      "name": "Plant_Leaves_Aspen"
    },
    {
      "x": 3,
      "y": 12,
      "z": 4,
      "name": "Plant_Leaves_Aspen"
    },
    {
      "x": 3,
      "y": 12,
      "z": 5,
      "name": "Plant_Leaves_Aspen"
    },
    {
      "x": 3,
      "y": 13,
      "z": 5,
      "name": "Plant_Leaves_Aspen"
    },
    {
      "x": 3,
      "y": 14,
      "z": 5,
      "name": "Plant_Leaves_Aspen"
    },
    {
      "x": 3,
      "y": 15,
      "z": 5,
      "name": "Plant_Leaves_Aspen"
    },
    {
      "x": 3,
      "y": 7,
      "z": 6,
      "name": "Plant_Leaves_Aspen"
    },
    {
      "x": 3,
      "y": 8,
      "z": 6,
      "name": "Plant_Leaves_Aspen"
    },
    {
      "x": 3,
      "y": 9,
      "z": 6,
      "name": "Wood_Aspen_Branch_Corner",
      "rotation": 3
    },
    {
      "x": 3,
      "y": 10,
      "z": 6,
      "name": "Wood_Aspen_Branch_Long"
    },
    {
      "x": 3,
      "y": 11,
      "z": 6,
      "name": "Wood_Aspen_Branch_Long"
    },
    {
      "x": 3,
      "y": 13,
      "z": 6,
      "name": "Plant_Leaves_Aspen"
    },
    {
      "x": 3,
      "y": 14,
      "z": 6,
      "name": "Plant_Leaves_Aspen"
    },
    {
      "x": 3,
      "y": 15,
      "z": 6,
      "name": "Plant_Leaves_Aspen"
    },
    {
      "x": 3,
      "y": 11,
      "z": 7,
      "name": "Plant_Leaves_Aspen"
    },
    {
      "x": 3,
      "y": 12,
      "z": 7,
      "name": "Plant_Leaves_Aspen"
    },
    {
      "x": 3,
      "y": 13,
      "z": 7,
      "name": "Plant_Leaves_Aspen"
    },
    {
      "x": 3,
      "y": 7,
      "z": 8,
      "name": "Plant_Leaves_Aspen"
    },
    {
      "x": 3,
      "y": 8,
      "z": 8,
      "name": "Plant_Leaves_Aspen"
    },
    {
      "x": 3,
      "y": 9,
      "z": 8,
      "name": "Plant_Leaves_Aspen"
    },
    {
      "x": 3,
      "y": 10,
      "z": 8,
      "name": "Plant_Leaves_Aspen"
    },
    {
      "x": 3,
      "y": 11,
      "z": 8,
      "name": "Plant_Leaves_Aspen"
    },
    {
      "x": 3,
      "y": 8,
      "z": 9,
      "name": "Plant_Leaves_Aspen"
    },
    {
      "x": 3,
      "y": 9,
      "z": 9,
      "name": "Plant_Leaves_Aspen"
    },
    {
      "x": 3,
      "y": 9,
      "z": 10,
      "name": "Plant_Leaves_Aspen"
    },
    {
      "x": 4,
      "y": 9,
      "z": 2,
      "name": "Plant_Leaves_Aspen"
    },
    {
      "x": 4,
      "y": 10,
      "z": 2,
      "name": "Plant_Leaves_Aspen"
    },
    {
      "x": 4,
      "y": 8,
      "z": 3,
      "name": "Plant_Leaves_Aspen"
    },
    {
      "x": 4,
      "y": 9,
      "z": 3,
      "name": "Plant_Leaves_Aspen"
    },
    {
      "x": 4,
      "y": 12,
      "z": 3,
      "name": "Plant_Leaves_Aspen"
    },
    {
      "x": 4,
      "y": 13,
      "z": 4,
      "name": "Plant_Leaves_Aspen"
    },
    {
      "x": 4,
      "y": 9,
      "z": 5,
      "name": "Wood_Aspen_Branch_Corner",
      "rotation": 2
    },
    {
      "x": 4,
      "y": 10,
      "z": 5,
      "name": "Wood_Aspen_Branch_Long"
    },
    {
      "x": 4,
      "y": 11,
      "z": 5,
      "name": "Wood_Aspen_Branch_Long"
    },
    {
      "x": 4,
      "y": 12,
      "z": 5,
      "name": "Plant_Leaves_Aspen"
    },
    {
      "x": 4,
      "y": 13,
      "z": 5,
      "name": "Plant_Leaves_Aspen"
    },
    {
      "x": 4,
      "y": 14,
      "z": 5,
      "name": "Plant_Leaves_Aspen"
    },
    {
      "x": 4,
      "y": 15,
      "z": 5,
      "name": "Plant_Leaves_Aspen"
    },
    {
      "x": 4,
      "y": 9,
      "z": 6,
      "name": "Wood_Aspen_Trunk_Full"
    },
    {
      "x": 4,
      "y": 10,
      "z": 6,
      "name": "Wood_Aspen_Branch_Long"
    },
    {
      "x": 4,
      "y": 11,
      "z": 6,
      "name": "Wood_Aspen_Branch_Long"
    },
    {
      "x": 4,
      "y": 12,
      "z": 6,
      "name": "Wood_Aspen_Branch_Long"
    },
    {
      "x": 4,
      "y": 13,
      "z": 6,
      "name": "Wood_Aspen_Branch_Long"
    },
    {
      "x": 4,
      "y": 14,
      "z": 6,
      "name": "Plant_Leaves_Aspen"
    },
    {
      "x": 4,
      "y": 15,
      "z": 6,
      "name": "Plant_Leaves_Aspen"
    },
    {
      "x": 4,
      "y": 16,
      "z": 6,
      "name": "Plant_Leaves_Aspen"
    },
    {
      "x": 4,
      "y": 17,
      "z": 6,
      "name": "Plant_Leaves_Aspen"
    },
    {
      "x": 4,
      "y": 14,
      "z": 7,
      "name": "Plant_Leaves_Aspen"
    },
    {
      "x": 4,
      "y": 15,
      "z": 7,
      "name": "Plant_Leaves_Aspen"
    },
    {
      "x": 4,
      "y": 16,
      "z": 7,
      "name": "Plant_Leaves_Aspen"
    },
    {
      "x": 4,
      "y": 9,
      "z": 9,
      "name": "Plant_Leaves_Aspen"
    },
    {
      "x": 4,
      "y": 10,
      "z": 9,
      "name": "Plant_Leaves_Aspen"
    },
    {
      "x": 4,
      "y": 11,
      "z": 9,
      "name": "Plant_Leaves_Aspen"
    },
    {
      "x": 4,
      "y": 12,
      "z": 9,
      "name": "Plant_Leaves_Aspen"
    },
    {
      "x": 5,
      "y": 9,
      "z": 1,
      "name": "Plant_Leaves_Aspen"
    },
    {
      "x": 5,
      "y": 9,
      "z": 2,
      "name": "Plant_Leaves_Aspen"
    },
    {
      "x": 5,
      "y": 11,
      "z": 2,
      "name": "Plant_Leaves_Aspen"
    },
    {
      "x": 5,
      "y": 11,
      "z": 3,
      "name": "Plant_Leaves_Aspen"
    },
    {
      "x": 5,
      "y": 12,
      "z": 3,
      "name": "Plant_Leaves_Aspen"
    },
    {
      "x": 5,
      "y": 13,
      "z": 3,
      "name": "Plant_Leaves_Aspen"
    },
    {
      "x": 5,
      "y": 14,
      "z": 3,
      "name": "Plant_Leaves_Aspen"
    },
    {
      "x": 5,
      "y": 15,
      "z": 4,
      "name": "Plant_Leaves_Aspen"
    },
    {
      "x": 5,
      "y": 16,
      "z": 4,
      "name": "Plant_Leaves_Aspen"
    },
    {
      "x": 5,
      "y": 12,
      "z": 5,
      "name": "Wood_Aspen_Branch_Corner",
      "rotation": 3
    },
    {
      "x": 5,
      "y": 13,
      "z": 5,
      "name": "Wood_Aspen_Branch_Long"
    },
    {
      "x": 5,
      "y": 14,
      "z": 5,
      "name": "Wood_Aspen_Branch_Long"
    },
    {
      "x": 5,
      "y": 17,
      "z": 5,
      "name": "Plant_Leaves_Aspen"
    },
    {
      "x": 5,
      "y": 3,
      "z": 6,
      "name": "Wood_Aspen_Branch_Short",
      "rotation": 3
    },
    {
      "x": 5,
      "y": 9,
      "z": 6,
      "name": "Wood_Aspen_Trunk_Full"
    },
    {
      "x": 5,
      "y": 16,
      "z": 6,
      "name": "Plant_Leaves_Aspen"
    },
    {
      "x": 5,
      "y": 17,
      "z": 6,
      "name": "Plant_Leaves_Aspen"
    },
    {
      "x": 5,
      "y": 18,
      "z": 6,
      "name": "Plant_Leaves_Aspen"
    },
    {
      "x": 5,
      "y": 16,
      "z": 7,
      "name": "Plant_Leaves_Aspen"
    },
    {
      "x": 5,
      "y": 17,
      "z": 7,
      "name": "Plant_Leaves_Aspen"
    },
    {
      "x": 5,
      "y": 18,
      "z": 7,
      "name": "Plant_Leaves_Aspen"
    },
    {
      "x": 5,
      "y": 8,
      "z": 8,
      "name": "Wood_Aspen_Branch_Corner",
      "rotation": 3
    },
    {
      "x": 5,
      "y": 9,
      "z": 8,
      "name": "Wood_Aspen_Branch_Long"
    },
    {
      "x": 5,
      "y": 10,
      "z": 8,
      "name": "Plant_Leaves_Aspen"
    },
    {
      "x": 5,
      "y": 13,
      "z": 8,
      "name": "Plant_Leaves_Aspen"
    },
    {
      "x": 5,
      "y": 14,
      "z": 8,
      "name": "Plant_Leaves_Aspen"
    },
    {
      "x": 5,
      "y": 15,
      "z": 8,
      "name": "Plant_Leaves_Aspen"
    },
    {
      "x": 5,
      "y": 16,
      "z": 8,
      "name": "Plant_Leaves_Aspen"
    },
    {
      "x": 5,
      "y": 9,
      "z": 9,
      "name": "Plant_Leaves_Aspen"
    },
    {
      "x": 5,
      "y": 12,
      "z": 9,
      "name": "Plant_Leaves_Aspen"
    },
    {
      "x": 5,
      "y": 13,
      "z": 9,
      "name": "Plant_Leaves_Aspen"
    },
    {
      "x": 5,
      "y": 14,
      "z": 9,
      "name": "Plant_Leaves_Aspen"
    },
    {
      "x": 5,
      "y": 8,
      "z": 10,
      "name": "Plant_Leaves_Aspen"
    },
    {
      "x": 5,
      "y": 9,
      "z": 10,
      "name": "Plant_Leaves_Aspen"
    },
    {
      "x": 5,
      "y": 10,
      "z": 10,
      "name": "Plant_Leaves_Aspen"
    },
    {
      "x": 6,
      "y": 12,
      "z": 1,
      "name": "Plant_Leaves_Aspen"
    },
    {
      "x": 6,
      "y": 8,
      "z": 2,
      "name": "Plant_Leaves_Aspen"
    },
    {
      "x": 6,
      "y": 9,
      "z": 2,
      "name": "Plant_Leaves_Aspen"
    },
    {
      "x": 6,
      "y": 10,
      "z": 2,
      "name": "Plant_Leaves_Aspen"
    },
    {
      "x": 6,
      "y": 11,
      "z": 2,
      "name": "Plant_Leaves_Aspen"
    },
    {
      "x": 6,
      "y": 12,
      "z": 2,
      "name": "Plant_Leaves_Aspen"
    },
    {
      "x": 6,
      "y": 13,
      "z": 2,
      "name": "Plant_Leaves_Aspen"
    },
    {
      "x": 6,
      "y": 15,
      "z": 2,
      "name": "Plant_Leaves_Aspen"
    },
    {
      "x": 6,
      "y": 7,
      "z": 3,
      "name": "Plant_Leaves_Aspen"
    },
    {
      "x": 6,
      "y": 8,
      "z": 3,
      "name": "Plant_Leaves_Aspen"
    },
    {
      "x": 6,
      "y": 9,
      "z": 3,
      "name": "Plant_Leaves_Aspen"
    },
    {
      "x": 6,
      "y": 10,
      "z": 3,
      "name": "Plant_Leaves_Aspen"
    },
    {
      "x": 6,
      "y": 11,
      "z": 3,
      "name": "Plant_Leaves_Aspen"
    },
    {
      "x": 6,
      "y": 12,
      "z": 3,
      "name": "Plant_Leaves_Aspen"
    },
    {
      "x": 6,
      "y": 13,
      "z": 3,
      "name": "Plant_Leaves_Aspen"
    },
    {
      "x": 6,
      "y": 14,
      "z": 3,
      "name": "Plant_Leaves_Aspen"
    },
    {
      "x": 6,
      "y": 15,
      "z": 3,
      "name": "Plant_Leaves_Aspen"
    },
    {
      "x": 6,
      "y": 16,
      "z": 3,
      "name": "Plant_Leaves_Aspen"
    },
    {
      "x": 6,
      "y": 10,
      "z": 4,
      "name": "Wood_Aspen_Branch_Long",
      "rotation": 4
    },
    {
      "x": 6,
      "y": 13,
      "z": 4,
      "name": "Wood_Aspen_Branch_Corner",
      "rotation": 2
    },
    {
      "x": 6,
      "y": 14,
      "z": 4,
      "name": "Wood_Aspen_Branch_Long"
    },
    {
      "x": 6,
      "y": 15,
      "z": 4,
      "name": "Plant_Leaves_Aspen"
    },
    {
      "x": 6,
      "y": 16,
      "z": 4,
      "name": "Plant_Leaves_Aspen"
    },
    {
      "x": 6,
      "y": 17,
      "z": 4,
      "name": "Plant_Leaves_Aspen"
    },
    {
      "x": 6,
      "y": 18,
      "z": 4,
      "name": "Plant_Leaves_Aspen"
    },
    {
      "x": 6,
      "y": 10,
      "z": 5,
      "name": "Wood_Aspen_Trunk_Full"
    },
    {
      "x": 6,
      "y": 11,
      "z": 5,
      "name": "Wood_Aspen_Trunk"
    },
    {
      "x": 6,
      "y": 12,
      "z": 5,
      "name": "Wood_Aspen_Trunk"
    },
    {
      "x": 6,
      "y": 13,
      "z": 5,
      "name": "Wood_Aspen_Trunk_Full"
    },
    {
      "x": 6,
      "y": 14,
      "z": 5,
      "name": "Wood_Aspen_Branch_Long"
    },
    {
      "x": 6,
      "y": 15,
      "z": 5,
      "name": "Wood_Aspen_Branch_Long"
    },
    {
      "x": 6,
      "y": 16,
      "z": 5,
      "name": "Wood_Aspen_Branch_Long"
    },
    {
      "x": 6,
      "y": 17,
      "z": 5,
      "name": "Plant_Leaves_Aspen"
    },
    {
      "x": 6,
      "y": 18,
      "z": 5,
      "name": "Plant_Leaves_Aspen"
    },
    {
      "x": 6,
      "y": 19,
      "z": 5,
      "name": "Plant_Leaves_Aspen"
    },
    {
      "x": 6,
      "y": 0,
      "z": 6,
      "name": "Wood_Aspen_Trunk"
    },
    {
      "x": 6,
      "y": 1,
      "z": 6,
      "name": "Wood_Aspen_Trunk"
    },
    {
      "x": 6,
      "y": 2,
      "z": 6,
      "name": "Wood_Aspen_Trunk"
    },
    {
      "x": 6,
      "y": 3,
      "z": 6,
      "name": "Wood_Aspen_Trunk"
    },
    {
      "x": 6,
      "y": 4,
      "z": 6,
      "name": "Wood_Aspen_Trunk"
    },
    {
      "x": 6,
      "y": 5,
      "z": 6,
      "name": "Wood_Aspen_Trunk"
    },
    {
      "x": 6,
      "y": 6,
      "z": 6,
      "name": "Wood_Aspen_Trunk"
    },
    {
      "x": 6,
      "y": 7,
      "z": 6,
      "name": "Wood_Aspen_Trunk"
    },
    {
      "x": 6,
      "y": 8,
      "z": 6,
      "name": "Wood_Aspen_Trunk"
    },
    {
      "x": 6,
      "y": 9,
      "z": 6,
      "name": "Wood_Aspen_Trunk"
    },
    {
      "x": 6,
      "y": 10,
      "z": 6,
      "name": "Wood_Aspen_Trunk_Full"
    },
    {
      "x": 6,
      "y": 17,
      "z": 6,
      "name": "Plant_Leaves_Aspen"
    },
    {
      "x": 6,
      "y": 18,
      "z": 6,
      "name": "Plant_Leaves_Aspen"
    },
    {
      "x": 6,
      "y": 19,
      "z": 6,
      "name": "Plant_Leaves_Aspen"
    },
    {
      "x": 6,
      "y": 6,
      "z": 7,
      "name": "Wood_Aspen_Branch_Short"
    },
    {
      "x": 6,
      "y": 8,
      "z": 7,
      "name": "Wood_Aspen_Trunk_Full"
    },
    {
      "x": 6,
      "y": 9,
      "z": 7,
      "name": "Deco_Nest"
    },
    {
      "x": 6,
      "y": 16,
      "z": 7,
      "name": "Plant_Leaves_Aspen"
    },
    {
      "x": 6,
      "y": 17,
      "z": 7,
      "name": "Plant_Leaves_Aspen"
    },
    {
      "x": 6,
      "y": 18,
      "z": 7,
      "name": "Plant_Leaves_Aspen"
    },
    {
      "x": 6,
      "y": 19,
      "z": 7,
      "name": "Plant_Leaves_Aspen"
    },
    {
      "x": 6,
      "y": 8,
      "z": 8,
      "name": "Wood_Aspen_Trunk_Full"
    },
    {
      "x": 6,
      "y": 9,
      "z": 8,
      "name": "Wood_Aspen_Branch_Long"
    },
    {
      "x": 6,
      "y": 10,
      "z": 8,
      "name": "Wood_Aspen_Branch_Long"
    },
    {
      "x": 6,
      "y": 11,
      "z": 8,
      "name": "Wood_Aspen_Branch_Long"
    },
    {
      "x": 6,
      "y": 12,
      "z": 8,
      "name": "Wood_Aspen_Branch_Long"
    },
    {
      "x": 6,
      "y": 13,
      "z": 8,
      "name": "Plant_Leaves_Aspen"
    },
    {
      "x": 6,
      "y": 14,
      "z": 8,
      "name": "Plant_Leaves_Aspen"
    },
    {
      "x": 6,
      "y": 15,
      "z": 8,
      "name": "Plant_Leaves_Aspen"
    },
    {
      "x": 6,
      "y": 16,
      "z": 8,
      "name": "Plant_Leaves_Aspen"
    },
    {
      "x": 6,
      "y": 17,
      "z": 8,
      "name": "Plant_Leaves_Aspen"
    },
    {
      "x": 6,
      "y": 18,
      "z": 8,
      "name": "Plant_Leaves_Aspen"
    },
    {
      "x": 6,
      "y": 6,
      "z": 9,
      "name": "Plant_Leaves_Aspen"
    },
    {
      "x": 6,
      "y": 7,
      "z": 9,
      "name": "Plant_Leaves_Aspen"
    },
    {
      "x": 6,
      "y": 8,
      "z": 9,
      "name": "Wood_Aspen_Branch_Corner"
    },
    {
      "x": 6,
      "y": 9,
      "z": 9,
      "name": "Wood_Aspen_Branch_Long"
    },
    {
      "x": 6,
      "y": 10,
      "z": 9,
      "name": "Plant_Leaves_Aspen"
    },
    {
      "x": 6,
      "y": 11,
      "z": 9,
      "name": "Plant_Leaves_Aspen"
    },
    {
      "x": 6,
      "y": 12,
      "z": 9,
      "name": "Plant_Leaves_Aspen"
    },
    {
      "x": 6,
      "y": 13,
      "z": 9,
      "name": "Plant_Leaves_Aspen"
    },
    {
      "x": 6,
      "y": 14,
      "z": 9,
      "name": "Plant_Leaves_Aspen"
    },
    {
      "x": 6,
      "y": 16,
      "z": 9,
      "name": "Plant_Leaves_Aspen"
    },
    {
      "x": 6,
      "y": 7,
      "z": 10,
      "name": "Plant_Leaves_Aspen"
    },
    {
      "x": 6,
      "y": 8,
      "z": 10,
      "name": "Plant_Leaves_Aspen"
    },
    {
      "x": 6,
      "y": 9,
      "z": 10,
      "name": "Plant_Leaves_Aspen"
    },
    {
      "x": 6,
      "y": 10,
      "z": 10,
      "name": "Plant_Leaves_Aspen"
    },
    {
      "x": 6,
      "y": 11,
      "z": 10,
      "name": "Plant_Leaves_Aspen"
    },
    {
      "x": 6,
      "y": 13,
      "z": 10,
      "name": "Plant_Leaves_Aspen"
    },
    {
      "x": 7,
      "y": 9,
      "z": 2,
      "name": "Plant_Leaves_Aspen"
    },
    {
      "x": 7,
      "y": 10,
      "z": 2,
      "name": "Plant_Leaves_Aspen"
    },
    {
      "x": 7,
      "y": 8,
      "z": 3,
      "name": "Plant_Leaves_Aspen"
    },
    {
      "x": 7,
      "y": 10,
      "z": 3,
      "name": "Plant_Leaves_Aspen"
    },
    {
      "x": 7,
      "y": 11,
      "z": 3,
      "name": "Plant_Leaves_Aspen"
    },
    {
      "x": 7,
      "y": 12,
      "z": 3,
      "name": "Plant_Leaves_Aspen"
    },
    {
      "x": 7,
      "y": 15,
      "z": 4,
      "name": "Plant_Leaves_Aspen"
    },
    {
      "x": 7,
      "y": 16,
      "z": 4,
      "name": "Plant_Leaves_Aspen"
    },
    {
      "x": 7,
      "y": 12,
      "z": 5,
      "name": "Wood_Aspen_Branch_Corner",
      "rotation": 1
    },
    {
      "x": 7,
      "y": 13,
      "z": 5,
      "name": "Wood_Aspen_Branch_Long"
    },
    {
      "x": 7,
      "y": 14,
      "z": 5,
      "name": "Wood_Aspen_Branch_Long"
    },
    {
      "x": 7,
      "y": 15,
      "z": 5,
      "name": "Wood_Aspen_Branch_Long"
    },
    {
      "x": 7,
      "y": 17,
      "z": 5,
      "name": "Plant_Leaves_Aspen"
    },
    {
      "x": 7,
      "y": 18,
      "z": 5,
      "name": "Plant_Leaves_Aspen"
    },
    {
      "x": 7,
      "y": 9,
      "z": 6,
      "name": "Wood_Aspen_Trunk_Full"
    },
    {
      "x": 7,
      "y": 16,
      "z": 6,
      "name": "Plant_Leaves_Aspen"
    },
    {
      "x": 7,
      "y": 17,
      "z": 6,
      "name": "Plant_Leaves_Aspen"
    },
    {
      "x": 7,
      "y": 18,
      "z": 6,
      "name": "Plant_Leaves_Aspen"
    },
    {
      "x": 7,
      "y": 19,
      "z": 6,
      "name": "Plant_Leaves_Aspen"
    },
    {
      "x": 7,
      "y": 9,
      "z": 7,
      "name": "Wood_Aspen_Branch_Corner"
    },
    {
      "x": 7,
      "y": 10,
      "z": 7,
      "name": "Wood_Aspen_Branch_Long"
    },
    {
      "x": 7,
      "y": 11,
      "z": 7,
      "name": "Wood_Aspen_Branch_Long"
    },
    {
      "x": 7,
      "y": 12,
      "z": 7,
      "name": "Wood_Aspen_Branch_Long"
    },
    {
      "x": 7,
      "y": 13,
      "z": 7,
      "name": "Plant_Leaves_Aspen"
    },
    {
      "x": 7,
      "y": 14,
      "z": 7,
      "name": "Plant_Leaves_Aspen"
    },
    {
      "x": 7,
      "y": 16,
      "z": 7,
      "name": "Plant_Leaves_Aspen"
    },
    {
      "x": 7,
      "y": 17,
      "z": 7,
      "name": "Plant_Leaves_Aspen"
    },
    {
      "x": 7,
      "y": 18,
      "z": 7,
      "name": "Plant_Leaves_Aspen"
    },
    {
      "x": 7,
      "y": 12,
      "z": 8,
      "name": "Plant_Leaves_Aspen"
    },
    {
      "x": 7,
      "y": 13,
      "z": 8,
      "name": "Plant_Leaves_Aspen"
    },
    {
      "x": 7,
      "y": 14,
      "z": 8,
      "name": "Plant_Leaves_Aspen"
    },
    {
      "x": 7,
      "y": 16,
      "z": 8,
      "name": "Plant_Leaves_Aspen"
    },
    {
      "x": 7,
      "y": 8,
      "z": 9,
      "name": "Plant_Leaves_Aspen"
    },
    {
      "x": 7,
      "y": 9,
      "z": 9,
      "name": "Plant_Leaves_Aspen"
    },
    {
      "x": 7,
      "y": 10,
      "z": 9,
      "name": "Plant_Leaves_Aspen"
    },
    {
      "x": 7,
      "y": 11,
      "z": 9,
      "name": "Plant_Leaves_Aspen"
    },
    {
      "x": 7,
      "y": 12,
      "z": 9,
      "name": "Plant_Leaves_Aspen"
    },
    {
      "x": 7,
      "y": 8,
      "z": 10,
      "name": "Plant_Leaves_Aspen"
    },
    {
      "x": 7,
      "y": 9,
      "z": 10,
      "name": "Plant_Leaves_Aspen"
    },
    {
      "x": 8,
      "y": 11,
      "z": 3,
      "name": "Plant_Leaves_Aspen"
    },
    {
      "x": 8,
      "y": 9,
      "z": 4,
      "name": "Plant_Leaves_Aspen"
    },
    {
      "x": 8,
      "y": 13,
      "z": 4,
      "name": "Plant_Leaves_Aspen"
    },
    {
      "x": 8,
      "y": 14,
      "z": 4,
      "name": "Plant_Leaves_Aspen"
    },
    {
      "x": 8,
      "y": 16,
      "z": 4,
      "name": "Plant_Leaves_Aspen"
    },
    {
      "x": 8,
      "y": 9,
      "z": 5,
      "name": "Plant_Leaves_Aspen"
    },
    {
      "x": 8,
      "y": 10,
      "z": 5,
      "name": "Wood_Aspen_Branch_Corner",
      "rotation": 2
    },
    {
      "x": 8,
      "y": 11,
      "z": 5,
      "name": "Wood_Aspen_Branch_Long"
    },
    {
      "x": 8,
      "y": 12,
      "z": 5,
      "name": "Wood_Aspen_Branch_Long"
    },
    {
      "x": 8,
      "y": 13,
      "z": 5,
      "name": "Plant_Leaves_Aspen"
    },
    {
      "x": 8,
      "y": 14,
      "z": 5,
      "name": "Plant_Leaves_Aspen"
    },
    {
      "x": 8,
      "y": 15,
      "z": 5,
      "name": "Plant_Leaves_Aspen"
    },
    {
      "x": 8,
      "y": 6,
      "z": 6,
      "name": "Plant_Leaves_Aspen"
    },
    {
      "x": 8,
      "y": 7,
      "z": 6,
      "name": "Plant_Leaves_Aspen"
    },
    {
      "x": 8,
      "y": 8,
      "z": 6,
      "name": "Plant_Leaves_Aspen"
    },
    {
      "x": 8,
      "y": 9,
      "z": 6,
      "name": "Wood_Aspen_Trunk_Full"
    },
    {
      "x": 8,
      "y": 10,
      "z": 6,
      "name": "Wood_Aspen_Trunk_Full"
    },
    {
      "x": 8,
      "y": 11,
      "z": 6,
      "name": "Wood_Aspen_Branch_Long"
    },
    {
      "x": 8,
      "y": 12,
      "z": 6,
      "name": "Wood_Aspen_Branch_Long"
    },
    {
      "x": 8,
      "y": 13,
      "z": 6,
      "name": "Wood_Aspen_Branch_Long"
    },
    {
      "x": 8,
      "y": 14,
      "z": 6,
      "name": "Plant_Leaves_Aspen"
    },
    {
      "x": 8,
      "y": 15,
      "z": 6,
      "name": "Plant_Leaves_Aspen"
    },
    {
      "x": 8,
      "y": 16,
      "z": 6,
      "name": "Plant_Leaves_Aspen"
    },
    {
      "x": 8,
      "y": 17,
      "z": 6,
      "name": "Plant_Leaves_Aspen"
    },
    {
      "x": 8,
      "y": 11,
      "z": 7,
      "name": "Plant_Leaves_Aspen"
    },
    {
      "x": 8,
      "y": 12,
      "z": 7,
      "name": "Plant_Leaves_Aspen"
    },
    {
      "x": 8,
      "y": 16,
      "z": 7,
      "name": "Plant_Leaves_Aspen"
    },
    {
      "x": 8,
      "y": 7,
      "z": 8,
      "name": "Plant_Leaves_Aspen"
    },
    {
      "x": 8,
      "y": 8,
      "z": 8,
      "name": "Plant_Leaves_Aspen"
    },
    {
      "x": 8,
      "y": 9,
      "z": 8,
      "name": "Plant_Leaves_Aspen"
    },
    {
      "x": 8,
      "y": 8,
      "z": 9,
      "name": "Plant_Leaves_Aspen"
    },
    {
      "x": 8,
      "y": 9,
      "z": 9,
      "name": "Plant_Leaves_Aspen"
    },
    {
      "x": 9,
      "y": 10,
      "z": 4,
      "name": "Plant_Leaves_Aspen"
    },
    {
      "x": 9,
      "y": 11,
      "z": 4,
      "name": "Plant_Leaves_Aspen"
    },
    {
      "x": 9,
      "y": 12,
      "z": 4,
      "name": "Plant_Leaves_Aspen"
    },
    {
      "x": 9,
      "y": 8,
      "z": 5,
      "name": "Plant_Leaves_Aspen"
    },
    {
      "x": 9,
      "y": 9,
      "z": 5,
      "name": "Plant_Leaves_Aspen"
    },
    {
      "x": 9,
      "y": 10,
      "z": 5,
      "name": "Plant_Leaves_Aspen"
    },
    {
      "x": 9,
      "y": 11,
      "z": 5,
      "name": "Plant_Leaves_Aspen"
    },
    {
      "x": 9,
      "y": 12,
      "z": 5,
      "name": "Plant_Leaves_Aspen"
    },
    {
      "x": 9,
      "y": 13,
      "z": 5,
      "name": "Plant_Leaves_Aspen"
    },
    {
      "x": 9,
      "y": 14,
      "z": 5,
      "name": "Plant_Leaves_Aspen"
    },
    {
      "x": 9,
      "y": 8,
      "z": 6,
      "name": "Plant_Leaves_Aspen"
    },
    {
      "x": 9,
      "y": 9,
      "z": 6,
      "name": "Plant_Leaves_Aspen"
    },
    {
      "x": 9,
      "y": 10,
      "z": 6,
      "name": "Plant_Leaves_Aspen"
    },
    {
      "x": 9,
      "y": 11,
      "z": 6,
      "name": "Plant_Leaves_Aspen"
    },
    {
      "x": 9,
      "y": 12,
      "z": 6,
      "name": "Plant_Leaves_Aspen"
    },
    {
      "x": 9,
      "y": 13,
      "z": 6,
      "name": "Plant_Leaves_Aspen"
    },
    {
      "x": 9,
      "y": 14,
      "z": 6,
      "name": "Plant_Leaves_Aspen"
    },
    {
      "x": 9,
      "y": 7,
      "z": 7,
      "name": "Plant_Leaves_Aspen"
    },
    {
      "x": 9,
      "y": 8,
      "z": 7,
      "name": "Plant_Leaves_Aspen"
    },
    {
      "x": 9,
      "y": 9,
      "z": 7,
      "name": "Plant_Leaves_Aspen"
    },
    {
      "x": 9,
      "y": 11,
      "z": 7,
      "name": "Plant_Leaves_Aspen"
    },
    {
      "x": 9,
      "y": 8,
      "z": 8,
      "name": "Plant_Leaves_Aspen"
    },
    {
      "x": 9,
      "y": 9,
      "z": 8,
      "name": "Plant_Leaves_Aspen"
    },
    {
      "x": 10,
      "y": 12,
      "z": 6,
      "name": "Plant_Leaves_Aspen"
    },
    {
      "x": 10,
      "y": 9,
      "z": 7,
      "name": "Plant_Leaves_Aspen"
    }
  ]
}