{
  "version": 8,
  "blockIdVersion": 8,
  "anchorX": 2,
  "anchorY": 11,
  "anchorZ": 2,
  "blocks": [
    {
      "x": -6,
      "y": 11,
      "z": 4,
      "name": "Rock_Stone"
    },
    {
      "x": -6,
      "y": 12,
      "z": 4,
      "name": "Rock_Stone"
    },
    {
      "x": -6,
      "y": 13,
      "z": 4,
      "name": "Rock_Stone"
    },
    {
      "x": -6,
      "y": 14,
      "z": 4,
      "name": "Rock_Stone"
    },
    {
      "x": -6,
      "y": 15,
      "z": 4,
      "name": "Rock_Stone"
    },
    {
      "x": -6,
      "y": 12,
      "z": 5,
      "name": "Rock_Stone"
    },
    {
      "x": -6,
      "y": 13,
      "z": 5,
      "name": "Rock_Stone"
    },
    {
      "x": -6,
      "y": 14,
      "z": 5,
      "name": "Rock_Stone"
    },
    {
      "x": -5,
      "y": 13,
      "z": 2,
      "name": "Rock_Stone"
    },
    {
      "x": -5,
      "y": 14,
      "z": 2,
      "name": "Rock_Stone"
    },
    {
      "x": -5,
      "y": 15,
      "z": 2,
      "name": "Rock_Stone"
    },
    {
      "x": -5,
      "y": 16,
      "z": 2,
      "name": "Rock_Stone"
    },
    {
      "x": -5,
      "y": 12,
      "z": 3,
      "name": "Rock_Stone"
    },
    {
      "x": -5,
      "y": 13,
      "z": 3,
      "name": "Rock_Stone"
    },
    {
      "x": -5,
      "y": 14,
      "z": 3,
      "name": "Rock_Stone"
    },
    {
      "x": -5,
      "y": 15,
      "z": 3,
      "name": "Rock_Stone"
    },
    {
      "x": -5,
      "y": 16,
      "z": 3,
      "name": "Rock_Stone"
    },
    {
      "x": -5,
      "y": 17,
      "z": 3,
      "name": "Rock_Stone"
    },
    {
      "x": -5,
      "y": 18,
      "z": 3,
      "name": "Soil_Dirt"
    },
    {
      "x": -5,
      "y": 19,
      "z": 3,
      "name": "Soil_Grass_Deep"
    },
    {
      "x": -5,
      "y": 20,
      "z": 3,
      "name": "Plant_Flower_Common_Violet"
    },
    {
      "x": -5,
      "y": 10,
      "z": 4,
      "name": "Rock_Stone"
    },
    {
      "x": -5,
      "y": 11,
      "z": 4,
      "name": "Rock_Stone"
    },
    {
      "x": -5,
      "y": 12,
      "z": 4,
      "name": "Rock_Stone"
    },
    {
      "x": -5,
      "y": 13,
      "z": 4,
      "name": "Rock_Stone"
    },
    {
      "x": -5,
      "y": 14,
      "z": 4,
      "name": "Rock_Stone"
    },
    {
      "x": -5,
      "y": 15,
      "z": 4,
      "name": "Soil_Dirt"
    },
    {
      "x": -5,
      "y": 16,
      "z": 4,
      "name": "Rock_Stone"
    },
    {
      "x": -5,
      "y": 17,
      "z": 4,
      "name": "Rock_Stone"
    },
    {
      "x": -5,
      "y": 18,
      "z": 4,
      "name": "Soil_Dirt"
    },
    {
      "x": -5,
      "y": 19,
      "z": 4,
      "name": "Soil_Grass_Deep"
    },
    {
      "x": -5,
      "y": 9,
      "z": 5,
      "name": "Rock_Stone"
    },
    {
      "x": -5,
      "y": 10,
      "z": 5,
      "name": "Rock_Stone"
    },
    {
      "x": -5,
      "y": 11,
      "z": 5,
      "name": "Rock_Stone"
    },
    {
      "x": -5,
      "y": 12,
      "z": 5,
      "name": "Rock_Stone"
    },
    {
      "x": -5,
      "y": 13,
      "z": 5,
      "name": "Rock_Stone"
    },
    {
      "x": -5,
      "y": 14,
      "z": 5,
      "name": "Rock_Stone"
    },
    {
      "x": -5,
      "y": 15,
      "z": 5,
      "name": "Rock_Stone"
    },
    {
      "x": -5,
      "y": 16,
      "z": 5,
      "name": "Rock_Stone"
    },
    {
      "x": -5,
      "y": 17,
      "z": 5,
      "name": "Rock_Stone"
    },
    {
      "x": -5,
      "y": 18,
      "z": 5,
      "name": "Soil_Grass_Deep"
    },
    {
      "x": -5,
      "y": 11,
      "z": 6,
      "name": "Rock_Stone"
    },
    {
      "x": -5,
      "y": 12,
      "z": 6,
      "name": "Rock_Stone"
    },
    {
      "x": -5,
      "y": 13,
      "z": 6,
      "name": "Rock_Stone"
    },
    {
      "x": -5,
      "y": 14,
      "z": 6,
      "name": "Rock_Stone"
    },
    {
      "x": -5,
      "y": 15,
      "z": 6,
      "name": "Rock_Stone"
    },
    {
      "x": -4,
      "y": 12,
      "z": 2,
      "name": "Rock_Stone"
    },
    {
      "x": -4,
      "y": 13,
      "z": 2,
      "name": "Rock_Stone"
    },
    {
      "x": -4,
      "y": 14,
      "z": 2,
      "name": "Rock_Stone"
    },
    {
      "x": -4,
      "y": 15,
      "z": 2,
      "name": "Rock_Stone"
    },
    {
      "x": -4,
      "y": 16,
      "z": 2,
      "name": "Rock_Stone"
    },
    {
      "x": -4,
      "y": 17,
      "z": 2,
      "name": "Rock_Stone"
    },
    {
      "x": -4,
      "y": 18,
      "z": 2,
      "name": "Rock_Stone"
    },
    {
      "x": -4,
      "y": 10,
      "z": 3,
      "name": "Rock_Stone"
    },
    {
      "x": -4,
      "y": 11,
      "z": 3,
      "name": "Rock_Stone"
    },
    {
      "x": -4,
      "y": 12,
      "z": 3,
      "name": "Rock_Stone"
    },
    {
      "x": -4,
      "y": 13,
      "z": 3,
      "name": "Rock_Stone"
    },
    {
      "x": -4,
      "y": 14,
      "z": 3,
      "name": "Rock_Stone"
    },
    {
      "x": -4,
      "y": 15,
      "z": 3,
      "name": "Rock_Stone"
    },
    {
      "x": -4,
      "y": 16,
      "z": 3,
      "name": "Soil_Dirt"
    },
    {
      "x": -4,
      "y": 17,
      "z": 3,
      "name": "Rock_Stone"
    },
    {
      "x": -4,
      "y": 18,
      "z": 3,
      "name": "Soil_Dirt"
    },
    {
      "x": -4,
      "y": 19,
      "z": 3,
      "name": "Soil_Grass_Deep"
    },
    {
      "x": -4,
      "y": 8,
      "z": 4,
      "name": "Rock_Stone"
    },
    {
      "x": -4,
      "y": 9,
      "z": 4,
      "name": "Rock_Stone"
    },
    {
      "x": -4,
      "y": 10,
      "z": 4,
      "name": "Rock_Stone"
    },
    {
      "x": -4,
      "y": 11,
      "z": 4,
      "name": "Rock_Stone"
    },
    {
      "x": -4,
      "y": 12,
      "z": 4,
      "name": "Rock_Stone"
    },
    {
      "x": -4,
      "y": 13,
      "z": 4,
      "name": "Rock_Stone"
    },
    {
      "x": -4,
      "y": 14,
      "z": 4,
      "name": "Rock_Stone"
    },
    {
      "x": -4,
      "y": 15,
      "z": 4,
      "name": "Rock_Stone"
    },
    {
      "x": -4,
      "y": 16,
      "z": 4,
      "name": "Soil_Dirt"
    },
    {
      "x": -4,
      "y": 17,
      "z": 4,
      "name": "Rock_Stone"
    },
    {
      "x": -4,
      "y": 18,
      "z": 4,
      "name": "Soil_Dirt"
    },
    {
      "x": -4,
      "y": 19,
      "z": 4,
      "name": "Soil_Dirt"
    },
    {
      "x": -4,
      "y": 20,
      "z": 4,
      "name": "Soil_Grass_Deep"
    },
    {
      "x": -4,
      "y": 8,
      "z": 5,
      "name": "Rock_Stone"
    },
    {
      "x": -4,
      "y": 9,
      "z": 5,
      "name": "Rock_Stone"
    },
    {
      "x": -4,
      "y": 10,
      "z": 5,
      "name": "Rock_Stone"
    },
    {
      "x": -4,
      "y": 11,
      "z": 5,
      "name": "Rock_Stone"
    },
    {
      "x": -4,
      "y": 12,
      "z": 5,
      "name": "Rock_Stone"
    },
    {
      "x": -4,
      "y": 13,
      "z": 5,
      "name": "Rock_Stone"
    },
    {
      "x": -4,
      "y": 14,
      "z": 5,
      "name": "Rock_Stone"
    },
    {
      "x": -4,
      "y": 15,
      "z": 5,
      "name": "Rock_Stone"
    },
    {
      "x": -4,
      "y": 16,
      "z": 5,
      "name": "Soil_Dirt"
    },
    {
      "x": -4,
      "y": 17,
      "z": 5,
      "name": "Rock_Stone"
    },
    {
      "x": -4,
      "y": 18,
      "z": 5,
      "name": "Soil_Dirt"
    },
    {
      "x": -4,
      "y": 19,
      "z": 5,
      "name": "Soil_Dirt"
    },
    {
      "x": -4,
      "y": 20,
      "z": 5,
      "name": "Soil_Grass_Deep"
    },
    {
      "x": -4,
      "y": 8,
      "z": 6,
      "name": "Rock_Stone"
    },
    {
      "x": -4,
      "y": 9,
      "z": 6,
      "name": "Rock_Stone"
    },
    {
      "x": -4,
      "y": 10,
      "z": 6,
      "name": "Rock_Stone"
    },
    {
      "x": -4,
      "y": 11,
      "z": 6,
      "name": "Rock_Stone"
    },
    {
      "x": -4,
      "y": 12,
      "z": 6,
      "name": "Rock_Stone"
    },
    {
      "x": -4,
      "y": 13,
      "z": 6,
      "name": "Rock_Stone"
    },
    {
      "x": -4,
      "y": 14,
      "z": 6,
      "name": "Rock_Stone"
    },
    {
      "x": -4,
      "y": 15,
      "z": 6,
      "name": "Rock_Stone"
    },
    {
      "x": -4,
      "y": 16,
      "z": 6,
      "name": "Rock_Stone"
    },
    {
      "x": -4,
      "y": 17,
      "z": 6,
      "name": "Rock_Stone"
    },
    {
      "x": -4,
      "y": 18,
      "z": 6,
      "name": "Soil_Dirt"
    },
    {
      "x": -4,
      "y": 19,
      "z": 6,
      "name": "Soil_Grass_Deep"
    },
    {
      "x": -3,
      "y": 14,
      "z": 2,
      "name": "Rock_Stone"
    },
    {
      "x": -3,
      "y": 15,
      "z": 2,
      "name": "Rock_Stone"
    },
    {
      "x": -3,
      "y": 16,
      "z": 2,
      "name": "Rock_Stone"
    },
    {
      "x": -3,
      "y": 17,
      "z": 2,
      "name": "Rock_Stone"
    },
    {
      "x": -3,
      "y": 18,
      "z": 2,
      "name": "Rock_Stone"
    },
    {
      "x": -3,
      "y": 19,
      "z": 2,
      "name": "Soil_Dirt"
    },
    {
      "x": -3,
      "y": 20,
      "z": 2,
      "name": "Soil_Dirt"
    },
    {
      "x": -3,
      "y": 21,
      "z": 2,
      "name": "Soil_Grass_Deep"
    },
    {
      "x": -3,
      "y": 9,
      "z": 3,
      "name": "Rock_Stone"
    },
    {
      "x": -3,
      "y": 10,
      "z": 3,
      "name": "Rock_Stone"
    },
    {
      "x": -3,
      "y": 11,
      "z": 3,
      "name": "Rock_Stone"
    },
    {
      "x": -3,
      "y": 12,
      "z": 3,
      "name": "Rock_Stone"
    },
    {
      "x": -3,
      "y": 13,
      "z": 3,
      "name": "Rock_Stone"
    },
    {
      "x": -3,
      "y": 14,
      "z": 3,
      "name": "Rock_Stone"
    },
    {
      "x": -3,
      "y": 15,
      "z": 3,
      "name": "Rock_Stone"
    },
    {
      "x": -3,
      "y": 16,
      "z": 3,
      "name": "Soil_Dirt"
    },
    {
      "x": -3,
      "y": 17,
      "z": 3,
      "name": "Soil_Dirt"
    },
    {
      "x": -3,
      "y": 18,
      "z": 3,
      "name": "Soil_Dirt"
    },
    {
      "x": -3,
      "y": 19,
      "z": 3,
      "name": "Soil_Dirt"
    },
    {
      "x": -3,
      "y": 20,
      "z": 3,
      "name": "Soil_Dirt"
    },
    {
      "x": -3,
      "y": 21,
      "z": 3,
      "name": "Soil_Grass_Deep"
    },
    {
      "x": -3,
      "y": 7,
      "z": 4,
      "name": "Rock_Stone"
    },
    {
      "x": -3,
      "y": 8,
      "z": 4,
      "name": "Rock_Stone"
    },
    {
      "x": -3,
      "y": 9,
      "z": 4,
      "name": "Rock_Stone"
    },
    {
      "x": -3,
      "y": 10,
      "z": 4,
      "name": "Rock_Stone"
    },
    {
      "x": -3,
      "y": 11,
      "z": 4,
      "name": "Rock_Stone"
    },
    {
      "x": -3,
      "y": 12,
      "z": 4,
      "name": "Rock_Stone"
    },
    {
      "x": -3,
      "y": 13,
      "z": 4,
      "name": "Rock_Stone"
    },
    {
      "x": -3,
      "y": 14,
      "z": 4,
      "name": "Rock_Stone"
    },
    {
      "x": -3,
      "y": 15,
      "z": 4,
      "name": "Rock_Stone"
    },
    {
      "x": -3,
      "y": 16,
      "z": 4,
      "name": "Soil_Dirt"
    },
    {
      "x": -3,
      "y": 17,
      "z": 4,
      "name": "Soil_Dirt"
    },
    {
      "x": -3,
      "y": 18,
      "z": 4,
      "name": "Soil_Dirt"
    },
    {
      "x": -3,
      "y": 19,
      "z": 4,
      "name": "Soil_Dirt"
    },
    {
      "x": -3,
      "y": 20,
      "z": 4,
      "name": "Soil_Dirt"
    },
    {
      "x": -3,
      "y": 21,
      "z": 4,
      "name": "Soil_Grass_Deep"
    },
    {
      "x": -3,
      "y": 7,
      "z": 5,
      "name": "Rock_Stone"
    },
    {
      "x": -3,
      "y": 8,
      "z": 5,
      "name": "Rock_Stone"
    },
    {
      "x": -3,
      "y": 9,
      "z": 5,
      "name": "Rock_Stone"
    },
    {
      "x": -3,
      "y": 10,
      "z": 5,
      "name": "Rock_Stone"
    },
    {
      "x": -3,
      "y": 11,
      "z": 5,
      "name": "Rock_Stone"
    },
    {
      "x": -3,
      "y": 12,
      "z": 5,
      "name": "Rock_Stone"
    },
    {
      "x": -3,
      "y": 13,
      "z": 5,
      "name": "Rock_Stone"
    },
    {
      "x": -3,
      "y": 14,
      "z": 5,
      "name": "Rock_Stone"
    },
    {
      "x": -3,
      "y": 15,
      "z": 5,
      "name": "Rock_Stone"
    },
    {
      "x": -3,
      "y": 16,
      "z": 5,
      "name": "Soil_Dirt"
    },
    {
      "x": -3,
      "y": 17,
      "z": 5,
      "name": "Soil_Dirt"
    },
    {
      "x": -3,
      "y": 18,
      "z": 5,
      "name": "Soil_Dirt"
    },
    {
      "x": -3,
      "y": 19,
      "z": 5,
      "name": "Soil_Dirt"
    },
    {
      "x": -3,
      "y": 20,
      "z": 5,
      "name": "Soil_Grass_Deep"
    },
    {
      "x": -3,
      "y": 7,
      "z": 6,
      "name": "Rock_Stone"
    },
    {
      "x": -3,
      "y": 8,
      "z": 6,
      "name": "Rock_Stone"
    },
    {
      "x": -3,
      "y": 9,
      "z": 6,
      "name": "Rock_Stone"
    },
    {
      "x": -3,
      "y": 10,
      "z": 6,
      "name": "Rock_Stone"
    },
    {
      "x": -3,
      "y": 11,
      "z": 6,
      "name": "Rock_Stone"
    },
    {
      "x": -3,
      "y": 12,
      "z": 6,
      "name": "Rock_Stone"
    },
    {
      "x": -3,
      "y": 13,
      "z": 6,
      "name": "Rock_Stone"
    },
    {
      "x": -3,
      "y": 14,
      "z": 6,
      "name": "Rock_Stone"
    },
    {
      "x": -3,
      "y": 15,
      "z": 6,
      "name": "Rock_Stone"
    },
    {
      "x": -3,
      "y": 16,
      "z": 6,
      "name": "Rock_Stone"
    },
    {
      "x": -3,
      "y": 17,
      "z": 6,
      "name": "Soil_Dirt"
    },
    {
      "x": -3,
      "y": 18,
      "z": 6,
      "name": "Soil_Dirt"
    },
    {
      "x": -3,
      "y": 19,
      "z": 6,
      "name": "Soil_Dirt"
    },
    {
      "x": -3,
      "y": 20,
      "z": 6,
      "name": "Soil_Grass_Deep"
    },
    {
      "x": -3,
      "y": 9,
      "z": 7,
      "name": "Rock_Stone"
    },
    {
      "x": -3,
      "y": 10,
      "z": 7,
      "name": "Rock_Stone"
    },
    {
      "x": -3,
      "y": 11,
      "z": 7,
      "name": "Rock_Stone"
    },
    {
      "x": -3,
      "y": 17,
      "z": 7,
      "name": "Rock_Stone"
    },
    {
      "x": -3,
      "y": 18,
      "z": 7,
      "name": "Soil_Grass_Deep"
    },
    {
      "x": -2,
      "y": 18,
      "z": 1,
      "name": "Rock_Stone"
    },
    {
      "x": -2,
      "y": 19,
      "z": 1,
      "name": "Rock_Stone"
    },
    {
      "x": -2,
      "y": 20,
      "z": 1,
      "name": "Rock_Stone_Mossy"
    },
    {
      "x": -2,
      "y": 21,
      "z": 1,
      "name": "Rock_Stone"
    },
    {
      "x": -2,
      "y": 22,
      "z": 1,
      "name": "Rock_Stone"
    },
    {
      "x": -2,
      "y": 17,
      "z": 2,
      "name": "Rock_Stone"
    },
    {
      "x": -2,
      "y": 18,
      "z": 2,
      "name": "Rock_Stone"
    },
    {
      "x": -2,
      "y": 19,
      "z": 2,
      "name": "Rock_Stone"
    },
    {
      "x": -2,
      "y": 20,
      "z": 2,
      "name": "Soil_Dirt"
    },
    {
      "x": -2,
      "y": 21,
      "z": 2,
      "name": "Soil_Dirt"
    },
    {
      "x": -2,
      "y": 22,
      "z": 2,
      "name": "Soil_Grass_Deep"
    },
    {
      "x": -2,
      "y": 10,
      "z": 3,
      "name": "Rock_Stone"
    },
    {
      "x": -2,
      "y": 11,
      "z": 3,
      "name": "Rock_Stone"
    },
    {
      "x": -2,
      "y": 15,
      "z": 3,
      "name": "Rock_Stone"
    },
    {
      "x": -2,
      "y": 16,
      "z": 3,
      "name": "Rock_Stone"
    },
    {
      "x": -2,
      "y": 17,
      "z": 3,
      "name": "Rock_Stone"
    },
    {
      "x": -2,
      "y": 18,
      "z": 3,
      "name": "Rock_Stone"
    },
    {
      "x": -2,
      "y": 19,
      "z": 3,
      "name": "Soil_Dirt"
    },
    {
      "x": -2,
      "y": 20,
      "z": 3,
      "name": "Soil_Dirt"
    },
    {
      "x": -2,
      "y": 21,
      "z": 3,
      "name": "Soil_Dirt"
    },
    {
      "x": -2,
      "y": 22,
      "z": 3,
      "name": "Soil_Grass_Deep"
    },
    {
      "x": -2,
      "y": 6,
      "z": 4,
      "name": "Rock_Stone"
    },
    {
      "x": -2,
      "y": 7,
      "z": 4,
      "name": "Rock_Stone"
    },
    {
      "x": -2,
      "y": 8,
      "z": 4,
      "name": "Rock_Stone"
    },
    {
      "x": -2,
      "y": 9,
      "z": 4,
      "name": "Rock_Stone"
    },
    {
      "x": -2,
      "y": 10,
      "z": 4,
      "name": "Rock_Stone"
    },
    {
      "x": -2,
      "y": 11,
      "z": 4,
      "name": "Rock_Stone"
    },
    {
      "x": -2,
      "y": 12,
      "z": 4,
      "name": "Rock_Stone"
    },
    {
      "x": -2,
      "y": 13,
      "z": 4,
      "name": "Rock_Stone"
    },
    {
      "x": -2,
      "y": 14,
      "z": 4,
      "name": "Rock_Stone"
    },
    {
      "x": -2,
      "y": 15,
      "z": 4,
      "name": "Rock_Stone"
    },
    {
      "x": -2,
      "y": 16,
      "z": 4,
      "name": "Rock_Stone"
    },
    {
      "x": -2,
      "y": 17,
      "z": 4,
      "name": "Rock_Stone"
    },
    {
      "x": -2,
      "y": 18,
      "z": 4,
      "name": "Rock_Stone"
    },
    {
      "x": -2,
      "y": 19,
      "z": 4,
      "name": "Soil_Dirt"
    },
    {
      "x": -2,
      "y": 20,
      "z": 4,
      "name": "Soil_Dirt"
    },
    {
      "x": -2,
      "y": 21,
      "z": 4,
      "name": "Soil_Dirt"
    },
    {
      "x": -2,
      "y": 22,
      "z": 4,
      "name": "Soil_Grass_Deep"
    },
    {
      "x": -2,
      "y": 6,
      "z": 5,
      "name": "Rock_Stone"
    },
    {
      "x": -2,
      "y": 7,
      "z": 5,
      "name": "Rock_Stone"
    },
    {
      "x": -2,
      "y": 8,
      "z": 5,
      "name": "Rock_Stone"
    },
    {
      "x": -2,
      "y": 9,
      "z": 5,
      "name": "Rock_Stone"
    },
    {
      "x": -2,
      "y": 10,
      "z": 5,
      "name": "Rock_Stone"
    },
    {
      "x": -2,
      "y": 11,
      "z": 5,
      "name": "Rock_Stone"
    },
    {
      "x": -2,
      "y": 12,
      "z": 5,
      "name": "Rock_Stone"
    },
    {
      "x": -2,
      "y": 13,
      "z": 5,
      "name": "Rock_Stone"
    },
    {
      "x": -2,
      "y": 14,
      "z": 5,
      "name": "Rock_Stone"
    },
    {
      "x": -2,
      "y": 15,
      "z": 5,
      "name": "Rock_Stone"
    },
    {
      "x": -2,
      "y": 16,
      "z": 5,
      "name": "Rock_Stone"
    },
    {
      "x": -2,
      "y": 17,
      "z": 5,
      "name": "Rock_Stone"
    },
    {
      "x": -2,
      "y": 18,
      "z": 5,
      "name": "Soil_Dirt"
    },
    {
      "x": -2,
      "y": 19,
      "z": 5,
      "name": "Soil_Dirt"
    },
    {
      "x": -2,
      "y": 20,
      "z": 5,
      "name": "Soil_Dirt"
    },
    {
      "x": -2,
      "y": 21,
      "z": 5,
      "name": "Soil_Dirt"
    },
    {
      "x": -2,
      "y": 22,
      "z": 5,
      "name": "Soil_Grass_Deep"
    },
    {
      "x": -2,
      "y": 23,
      "z": 5,
      "name": "Plant_Fern_Winter"
    },
    {
      "x": -2,
      "y": 6,
      "z": 6,
      "name": "Rock_Stone"
    },
    {
      "x": -2,
      "y": 7,
      "z": 6,
      "name": "Rock_Stone"
    },
    {
      "x": -2,
      "y": 8,
      "z": 6,
      "name": "Rock_Stone"
    },
    {
      "x": -2,
      "y": 9,
      "z": 6,
      "name": "Rock_Stone"
    },
    {
      "x": -2,
      "y": 10,
      "z": 6,
      "name": "Rock_Stone"
    },
    {
      "x": -2,
      "y": 11,
      "z": 6,
      "name": "Rock_Stone"
    },
    {
      "x": -2,
      "y": 12,
      "z": 6,
      "name": "Rock_Stone"
    },
    {
      "x": -2,
      "y": 15,
      "z": 6,
      "name": "Rock_Stone"
    },
    {
      "x": -2,
      "y": 16,
      "z": 6,
      "name": "Rock_Stone"
    },
    {
      "x": -2,
      "y": 17,
      "z": 6,
      "name": "Rock_Stone"
    },
    {
      "x": -2,
      "y": 18,
      "z": 6,
      "name": "Rock_Stone"
    },
    {
      "x": -2,
      "y": 19,
      "z": 6,
      "name": "Soil_Dirt"
    },
    {
      "x": -2,
      "y": 20,
      "z": 6,
      "name": "Soil_Dirt"
    },
    {
      "x": -2,
      "y": 21,
      "z": 6,
      "name": "Soil_Grass_Deep"
    },
    {
      "x": -2,
      "y": 6,
      "z": 7,
      "name": "Rock_Stone"
    },
    {
      "x": -2,
      "y": 7,
      "z": 7,
      "name": "Rock_Stone"
    },
    {
      "x": -2,
      "y": 8,
      "z": 7,
      "name": "Rock_Stone"
    },
    {
      "x": -2,
      "y": 9,
      "z": 7,
      "name": "Rock_Stone"
    },
    {
      "x": -2,
      "y": 16,
      "z": 7,
      "name": "Rock_Stone"
    },
    {
      "x": -2,
      "y": 17,
      "z": 7,
      "name": "Rock_Stone"
    },
    {
      "x": -2,
      "y": 18,
      "z": 7,
      "name": "Soil_Dirt"
    },
    {
      "x": -2,
      "y": 19,
      "z": 7,
      "name": "Soil_Dirt"
    },
    {
      "x": -2,
      "y": 20,
      "z": 7,
      "name": "Soil_Grass_Deep"
    },
    {
      "x": -2,
      "y": 18,
      "z": 8,
      "name": "Rock_Stone"
    },
    {
      "x": -2,
      "y": 19,
      "z": 8,
      "name": "Soil_Grass_Deep"
    },
    {
      "x": -1,
      "y": 22,
      "z": 0,
      "name": "Rock_Stone_Mossy"
    },
    {
      "x": -1,
      "y": 23,
      "z": 0,
      "name": "Rock_Stone_Mossy"
    },
    {
      "x": -1,
      "y": 24,
      "z": 0,
      "name": "Rock_Stone_Mossy"
    },
    {
      "x": -1,
      "y": 17,
      "z": 1,
      "name": "Rock_Stone"
    },
    {
      "x": -1,
      "y": 18,
      "z": 1,
      "name": "Rock_Stone_Mossy"
    },
    {
      "x": -1,
      "y": 19,
      "z": 1,
      "name": "Rock_Stone_Mossy"
    },
    {
      "x": -1,
      "y": 20,
      "z": 1,
      "name": "Rock_Stone_Mossy"
    },
    {
      "x": -1,
      "y": 21,
      "z": 1,
      "name": "Rock_Stone_Mossy"
    },
    {
      "x": -1,
      "y": 22,
      "z": 1,
      "name": "Rock_Stone_Mossy"
    },
    {
      "x": -1,
      "y": 23,
      "z": 1,
      "name": "Rock_Stone"
    },
    {
      "x": -1,
      "y": 24,
      "z": 1,
      "name": "Rock_Stone_Mossy"
    },
    {
      "x": -1,
      "y": 25,
      "z": 1,
      "name": "Rubble_Stone_Mossy"
    },
    {
      "x": -1,
      "y": 17,
      "z": 2,
      "name": "Rock_Stone"
    },
    {
      "x": -1,
      "y": 18,
      "z": 2,
      "name": "Rock_Stone"
    },
    {
      "x": -1,
      "y": 19,
      "z": 2,
      "name": "Rock_Stone"
    },
    {
      "x": -1,
      "y": 20,
      "z": 2,
      "name": "Rock_Stone_Mossy"
    },
    {
      "x": -1,
      "y": 21,
      "z": 2,
      "name": "Rock_Stone"
    },
    {
      "x": -1,
      "y": 22,
      "z": 2,
      "name": "Rock_Stone_Mossy"
    },
    {
      "x": -1,
      "y": 23,
      "z": 2,
      "name": "Rock_Stone_Mossy"
    },
    {
      "x": -1,
      "y": 24,
      "z": 2,
      "name": "Rock_Stone_Mossy"
    },
    {
      "x": -1,
      "y": 16,
      "z": 3,
      "name": "Rock_Stone"
    },
    {
      "x": -1,
      "y": 17,
      "z": 3,
      "name": "Rock_Stone"
    },
    {
      "x": -1,
      "y": 18,
      "z": 3,
      "name": "Rock_Stone"
    },
    {
      "x": -1,
      "y": 19,
      "z": 3,
      "name": "Rock_Stone"
    },
    {
      "x": -1,
      "y": 20,
      "z": 3,
      "name": "Soil_Dirt"
    },
    {
      "x": -1,
      "y": 21,
      "z": 3,
      "name": "Soil_Dirt"
    },
    {
      "x": -1,
      "y": 22,
      "z": 3,
      "name": "Soil_Grass_Deep"
    },
    {
      "x": -1,
      "y": 6,
      "z": 4,
      "name": "Rock_Stone"
    },
    {
      "x": -1,
      "y": 7,
      "z": 4,
      "name": "Rock_Stone"
    },
    {
      "x": -1,
      "y": 8,
      "z": 4,
      "name": "Rock_Stone"
    },
    {
      "x": -1,
      "y": 9,
      "z": 4,
      "name": "Rock_Stone"
    },
    {
      "x": -1,
      "y": 16,
      "z": 4,
      "name": "Rock_Stone"
    },
    {
      "x": -1,
      "y": 17,
      "z": 4,
      "name": "Rock_Stone"
    },
    {
      "x": -1,
      "y": 18,
      "z": 4,
      "name": "Rock_Stone"
    },
    {
      "x": -1,
      "y": 19,
      "z": 4,
      "name": "Rock_Stone"
    },
    {
      "x": -1,
      "y": 20,
      "z": 4,
      "name": "Soil_Dirt"
    },
    {
      "x": -1,
      "y": 21,
      "z": 4,
      "name": "Soil_Dirt"
    },
    {
      "x": -1,
      "y": 22,
      "z": 4,
      "name": "Soil_Grass_Deep"
    },
    {
      "x": -1,
      "y": 5,
      "z": 5,
      "name": "Rock_Stone"
    },
    {
      "x": -1,
      "y": 6,
      "z": 5,
      "name": "Rock_Stone"
    },
    {
      "x": -1,
      "y": 7,
      "z": 5,
      "name": "Rock_Stone"
    },
    {
      "x": -1,
      "y": 8,
      "z": 5,
      "name": "Rock_Stone"
    },
    {
      "x": -1,
      "y": 9,
      "z": 5,
      "name": "Rock_Stone"
    },
    {
      "x": -1,
      "y": 10,
      "z": 5,
      "name": "Rock_Stone"
    },
    {
      "x": -1,
      "y": 11,
      "z": 5,
      "name": "Rock_Stone"
    },
    {
      "x": -1,
      "y": 16,
      "z": 5,
      "name": "Rock_Stone"
    },
    {
      "x": -1,
      "y": 17,
      "z": 5,
      "name": "Rock_Stone"
    },
    {
      "x": -1,
      "y": 18,
      "z": 5,
      "name": "Rock_Stone"
    },
    {
      "x": -1,
      "y": 19,
      "z": 5,
      "name": "Soil_Dirt"
    },
    {
      "x": -1,
      "y": 20,
      "z": 5,
      "name": "Soil_Dirt"
    },
    {
      "x": -1,
      "y": 21,
      "z": 5,
      "name": "Soil_Dirt"
    },
    {
      "x": -1,
      "y": 22,
      "z": 5,
      "name": "Soil_Grass_Deep"
    },
    {
      "x": -1,
      "y": 5,
      "z": 6,
      "name": "Rock_Stone"
    },
    {
      "x": -1,
      "y": 6,
      "z": 6,
      "name": "Rock_Stone"
    },
    {
      "x": -1,
      "y": 7,
      "z": 6,
      "name": "Rock_Stone"
    },
    {
      "x": -1,
      "y": 8,
      "z": 6,
      "name": "Rock_Stone"
    },
    {
      "x": -1,
      "y": 9,
      "z": 6,
      "name": "Rock_Stone"
    },
    {
      "x": -1,
      "y": 10,
      "z": 6,
      "name": "Rock_Stone"
    },
    {
      "x": -1,
      "y": 16,
      "z": 6,
      "name": "Rock_Stone"
    },
    {
      "x": -1,
      "y": 17,
      "z": 6,
      "name": "Rock_Stone"
    },
    {
      "x": -1,
      "y": 18,
      "z": 6,
      "name": "Rock_Stone"
    },
    {
      "x": -1,
      "y": 19,
      "z": 6,
      "name": "Soil_Dirt"
    },
    {
      "x": -1,
      "y": 20,
      "z": 6,
      "name": "Soil_Dirt"
    },
    {
      "x": -1,
      "y": 21,
      "z": 6,
      "name": "Soil_Dirt"
    },
    {
      "x": -1,
      "y": 22,
      "z": 6,
      "name": "Soil_Grass_Deep"
    },
    {
      "x": -1,
      "y": 5,
      "z": 7,
      "name": "Rock_Stone"
    },
    {
      "x": -1,
      "y": 6,
      "z": 7,
      "name": "Rock_Stone"
    },
    {
      "x": -1,
      "y": 7,
      "z": 7,
      "name": "Rock_Stone"
    },
    {
      "x": -1,
      "y": 8,
      "z": 7,
      "name": "Rock_Stone"
    },
    {
      "x": -1,
      "y": 16,
      "z": 7,
      "name": "Rock_Stone"
    },
    {
      "x": -1,
      "y": 17,
      "z": 7,
      "name": "Rock_Stone"
    },
    {
      "x": -1,
      "y": 18,
      "z": 7,
      "name": "Rock_Stone"
    },
    {
      "x": -1,
      "y": 19,
      "z": 7,
      "name": "Soil_Dirt"
    },
    {
      "x": -1,
      "y": 20,
      "z": 7,
      "name": "Soil_Dirt"
    },
    {
      "x": -1,
      "y": 21,
      "z": 7,
      "name": "Soil_Dirt"
    },
    {
      "x": -1,
      "y": 22,
      "z": 7,
      "name": "Soil_Grass_Deep"
    },
    {
      "x": -1,
      "y": 7,
      "z": 8,
      "name": "Rock_Stone"
    },
    {
      "x": -1,
      "y": 18,
      "z": 8,
      "name": "Rock_Stone"
    },
    {
      "x": -1,
      "y": 19,
      "z": 8,
      "name": "Soil_Dirt"
    },
    {
      "x": -1,
      "y": 20,
      "z": 8,
      "name": "Soil_Grass_Deep"
    },
    {
      "x": 0,
      "y": 19,
      "z": 0,
      "name": "Rock_Stone"
    },
    {
      "x": 0,
      "y": 20,
      "z": 0,
      "name": "Rock_Stone"
    },
    {
      "x": 0,
      "y": 21,
      "z": 0,
      "name": "Rock_Stone"
    },
    {
      "x": 0,
      "y": 22,
      "z": 0,
      "name": "Rock_Stone"
    },
    {
      "x": 0,
      "y": 23,
      "z": 0,
      "name": "Rock_Stone"
    },
    {
      "x": 0,
      "y": 24,
      "z": 0,
      "name": "Rock_Stone_Mossy"
    },
    {
      "x": 0,
      "y": 18,
      "z": 1,
      "name": "Rock_Stone"
    },
    {
      "x": 0,
      "y": 19,
      "z": 1,
      "name": "Rock_Stone"
    },
    {
      "x": 0,
      "y": 20,
      "z": 1,
      "name": "Rock_Stone_Mossy"
    },
    {
      "x": 0,
      "y": 21,
      "z": 1,
      "name": "Rock_Stone"
    },
    {
      "x": 0,
      "y": 22,
      "z": 1,
      "name": "Rock_Stone_Mossy"
    },
    {
      "x": 0,
      "y": 23,
      "z": 1,
      "name": "Rock_Stone_Mossy"
    },
    {
      "x": 0,
      "y": 24,
      "z": 1,
      "name": "Rock_Stone_Mossy"
    },
    {
      "x": 0,
      "y": 25,
      "z": 1,
      "name": "Rock_Stone_Mossy"
    },
    {
      "x": 0,
      "y": 17,
      "z": 2,
      "name": "Rock_Stone"
    },
    {
      "x": 0,
      "y": 18,
      "z": 2,
      "name": "Rock_Stone"
    },
    {
      "x": 0,
      "y": 19,
      "z": 2,
      "name": "Rock_Stone"
    },
    {
      "x": 0,
      "y": 20,
      "z": 2,
      "name": "Rock_Stone"
    },
    {
      "x": 0,
      "y": 21,
      "z": 2,
      "name": "Rock_Stone"
    },
    {
      "x": 0,
      "y": 22,
      "z": 2,
      "name": "Rock_Stone"
    },
    {
      "x": 0,
      "y": 23,
      "z": 2,
      "name": "Rock_Stone"
    },
    {
      "x": 0,
      "y": 24,
      "z": 2,
      "name": "Rock_Stone_Mossy"
    },
    {
      "x": 0,
      "y": 17,
      "z": 3,
      "name": "Rock_Stone"
    },
    {
      "x": 0,
      "y": 18,
      "z": 3,
      "name": "Rock_Stone"
    },
    {
      "x": 0,
      "y": 19,
      "z": 3,
      "name": "Rock_Stone"
    },
    {
      "x": 0,
      "y": 20,
      "z": 3,
      "name": "Soil_Dirt"
    },
    {
      "x": 0,
      "y": 21,
      "z": 3,
      "name": "Soil_Dirt"
    },
    {
      "x": 0,
      "y": 22,
      "z": 3,
      "name": "Rock_Stone"
    },
    {
      "x": 0,
      "y": 23,
      "z": 3,
      "name": "Soil_Grass_Deep"
    },
    {
      "x": 0,
      "y": 6,
      "z": 4,
      "name": "Rock_Stone"
    },
    {
      "x": 0,
      "y": 7,
      "z": 4,
      "name": "Rock_Stone"
    },
    {
      "x": 0,
      "y": 16,
      "z": 4,
      "name": "Rock_Stone"
    },
    {
      "x": 0,
      "y": 17,
      "z": 4,
      "name": "Rock_Stone"
    },
    {
      "x": 0,
      "y": 18,
      "z": 4,
      "name": "Rock_Stone"
    },
    {
      "x": 0,
      "y": 19,
      "z": 4,
      "name": "Rock_Stone"
    },
    {
      "x": 0,
      "y": 20,
      "z": 4,
      "name": "Rock_Stone"
    },
    {
      "x": 0,
      "y": 21,
      "z": 4,
      "name": "Soil_Dirt"
    },
    {
      "x": 0,
      "y": 22,
      "z": 4,
      "name": "Soil_Dirt"
    },
    {
      "x": 0,
      "y": 23,
      "z": 4,
      "name": "Soil_Grass_Deep"
    },
    {
      "x": 0,
      "y": 5,
      "z": 5,
      "name": "Rock_Stone"
    },
    {
      "x": 0,
      "y": 6,
      "z": 5,
      "name": "Rock_Stone"
    },
    {
      "x": 0,
      "y": 7,
      "z": 5,
      "name": "Rock_Stone"
    },
    {
      "x": 0,
      "y": 8,
      "z": 5,
      "name": "Rock_Stone"
    },
    {
      "x": 0,
      "y": 16,
      "z": 5,
      "name": "Rock_Stone"
    },
    {
      "x": 0,
      "y": 17,
      "z": 5,
      "name": "Rock_Stone"
    },
    {
      "x": 0,
      "y": 18,
      "z": 5,
      "name": "Rock_Stone"
    },
    {
      "x": 0,
      "y": 19,
      "z": 5,
      "name": "Rock_Stone"
    },
    {
      "x": 0,
      "y": 20,
      "z": 5,
      "name": "Soil_Dirt"
    },
    {
      "x": 0,
      "y": 21,
      "z": 5,
      "name": "Soil_Dirt"
    },
    {
      "x": 0,
      "y": 22,
      "z": 5,
      "name": "Soil_Grass_Deep"
    },
    {
      "x": 0,
      "y": 4,
      "z": 6,
      "name": "Rock_Stone"
    },
    {
      "x": 0,
      "y": 5,
      "z": 6,
      "name": "Rock_Stone"
    },
    {
      "x": 0,
      "y": 6,
      "z": 6,
      "name": "Rock_Stone"
    },
    {
      "x": 0,
      "y": 7,
      "z": 6,
      "name": "Rock_Stone"
    },
    {
      "x": 0,
      "y": 8,
      "z": 6,
      "name": "Rock_Stone"
    },
    {
      "x": 0,
      "y": 16,
      "z": 6,
      "name": "Rock_Stone"
    },
    {
      "x": 0,
      "y": 17,
      "z": 6,
      "name": "Rock_Stone"
    },
    {
      "x": 0,
      "y": 18,
      "z": 6,
      "name": "Rock_Stone"
    },
    {
      "x": 0,
      "y": 19,
      "z": 6,
      "name": "Soil_Dirt"
    },
    {
      "x": 0,
      "y": 20,
      "z": 6,
      "name": "Soil_Dirt"
    },
    {
      "x": 0,
      "y": 21,
      "z": 6,
      "name": "Soil_Dirt"
    },
    {
      "x": 0,
      "y": 22,
      "z": 6,
      "name": "Soil_Grass_Deep"
    },
    {
      "x": 0,
      "y": 5,
      "z": 7,
      "name": "Rock_Stone"
    },
    {
      "x": 0,
      "y": 6,
      "z": 7,
      "name": "Rock_Stone"
    },
    {
      "x": 0,
      "y": 7,
      "z": 7,
      "name": "Rock_Stone"
    },
    {
      "x": 0,
      "y": 17,
      "z": 7,
      "name": "Rock_Stone"
    },
    {
      "x": 0,
      "y": 18,
      "z": 7,
      "name": "Rock_Stone"
    },
    {
      "x": 0,
      "y": 19,
      "z": 7,
      "name": "Soil_Dirt"
    },
    {
      "x": 0,
      "y": 20,
      "z": 7,
      "name": "Soil_Dirt"
    },
    {
      "x": 0,
      "y": 21,
      "z": 7,
      "name": "Soil_Dirt"
    },
    {
      "x": 0,
      "y": 22,
      "z": 7,
      "name": "Soil_Grass_Deep"
    },
    {
      "x": 0,
      "y": 5,
      "z": 8,
      "name": "Rock_Stone"
    },
    {
      "x": 0,
      "y": 6,
      "z": 8,
      "name": "Rock_Stone"
    },
    {
      "x": 0,
      "y": 7,
      "z": 8,
      "name": "Rock_Stone"
    },
    {
      "x": 0,
      "y": 19,
      "z": 8,
      "name": "Soil_Dirt"
    },
    {
      "x": 0,
      "y": 20,
      "z": 8,
      "name": "Soil_Grass_Deep"
    },
    {
      "x": 1,
      "y": 18,
      "z": 0,
      "name": "Rock_Stone"
    },
    {
      "x": 1,
      "y": 19,
      "z": 0,
      "name": "Rock_Stone"
    },
    {
      "x": 1,
      "y": 20,
      "z": 0,
      "name": "Rock_Stone"
    },
    {
      "x": 1,
      "y": 21,
      "z": 0,
      "name": "Rock_Stone"
    },
    {
      "x": 1,
      "y": 22,
      "z": 0,
      "name": "Rock_Stone"
    },
    {
      "x": 1,
      "y": 23,
      "z": 0,
      "name": "Rock_Stone"
    },
    {
      "x": 1,
      "y": 24,
      "z": 0,
      "name": "Rock_Stone"
    },
    {
      "x": 1,
      "y": 25,
      "z": 0,
      "name": "Rock_Stone"
    },
    {
      "x": 1,
      "y": 26,
      "z": 0,
      "name": "Rock_Stone"
    },
    {
      "x": 1,
      "y": 18,
      "z": 1,
      "name": "Rock_Stone"
    },
    {
      "x": 1,
      "y": 19,
      "z": 1,
      "name": "Rock_Stone"
    },
    {
      "x": 1,
      "y": 20,
      "z": 1,
      "name": "Rock_Stone"
    },
    {
      "x": 1,
      "y": 21,
      "z": 1,
      "name": "Rock_Stone"
    },
    {
      "x": 1,
      "y": 22,
      "z": 1,
      "name": "Rock_Stone"
    },
    {
      "x": 1,
      "y": 23,
      "z": 1,
      "name": "Rock_Stone"
    },
    {
      "x": 1,
      "y": 24,
      "z": 1,
      "name": "Rock_Stone"
    },
    {
      "x": 1,
      "y": 25,
      "z": 1,
      "name": "Rock_Stone"
    },
    {
      "x": 1,
      "y": 26,
      "z": 1,
      "name": "Rock_Stone"
    },
    {
      "x": 1,
      "y": 17,
      "z": 2,
      "name": "Rock_Stone"
    },
    {
      "x": 1,
      "y": 18,
      "z": 2,
      "name": "Rock_Stone"
    },
    {
      "x": 1,
      "y": 19,
      "z": 2,
      "name": "Rock_Stone"
    },
    {
      "x": 1,
      "y": 20,
      "z": 2,
      "name": "Rock_Stone"
    },
    {
      "x": 1,
      "y": 21,
      "z": 2,
      "name": "Rock_Stone"
    },
    {
      "x": 1,
      "y": 22,
      "z": 2,
      "name": "Rock_Stone"
    },
    {
      "x": 1,
      "y": 23,
      "z": 2,
      "name": "Rock_Stone"
    },
    {
      "x": 1,
      "y": 24,
      "z": 2,
      "name": "Rock_Stone"
    },
    {
      "x": 1,
      "y": 25,
      "z": 2,
      "name": "Rock_Stone"
    },
    {
      "x": 1,
      "y": 26,
      "z": 2,
      "name": "Rock_Stone"
    },
    {
      "x": 1,
      "y": 17,
      "z": 3,
      "name": "Rock_Stone"
    },
    {
      "x": 1,
      "y": 18,
      "z": 3,
      "name": "Rock_Stone"
    },
    {
      "x": 1,
      "y": 19,
      "z": 3,
      "name": "Rock_Stone"
    },
    {
      "x": 1,
      "y": 20,
      "z": 3,
      "name": "Soil_Dirt"
    },
    {
      "x": 1,
      "y": 21,
      "z": 3,
      "name": "Rock_Stone"
    },
    {
      "x": 1,
      "y": 22,
      "z": 3,
      "name": "Rock_Stone"
    },
    {
      "x": 1,
      "y": 23,
      "z": 3,
      "name": "Rock_Stone"
    },
    {
      "x": 1,
      "y": 24,
      "z": 3,
      "name": "Rock_Stone"
    },
    {
      "x": 1,
      "y": 17,
      "z": 4,
      "name": "Rock_Stone"
    },
    {
      "x": 1,
      "y": 18,
      "z": 4,
      "name": "Rock_Stone"
    },
    {
      "x": 1,
      "y": 19,
      "z": 4,
      "name": "Rock_Stone"
    },
    {
      "x": 1,
      "y": 20,
      "z": 4,
      "name": "Rock_Stone"
    },
    {
      "x": 1,
      "y": 21,
      "z": 4,
      "name": "Rock_Stone"
    },
    {
      "x": 1,
      "y": 22,
      "z": 4,
      "name": "Soil_Dirt"
    },
    {
      "x": 1,
      "y": 23,
      "z": 4,
      "name": "Soil_Grass_Deep"
    },
    {
      "x": 1,
      "y": 5,
      "z": 5,
      "name": "Rock_Stone"
    },
    {
      "x": 1,
      "y": 6,
      "z": 5,
      "name": "Rock_Stone"
    },
    {
      "x": 1,
      "y": 7,
      "z": 5,
      "name": "Rock_Stone"
    },
    {
      "x": 1,
      "y": 16,
      "z": 5,
      "name": "Rock_Stone"
    },
    {
      "x": 1,
      "y": 17,
      "z": 5,
      "name": "Rock_Stone"
    },
    {
      "x": 1,
      "y": 18,
      "z": 5,
      "name": "Rock_Stone"
    },
    {
      "x": 1,
      "y": 19,
      "z": 5,
      "name": "Rock_Stone"
    },
    {
      "x": 1,
      "y": 20,
      "z": 5,
      "name": "Rock_Stone"
    },
    {
      "x": 1,
      "y": 21,
      "z": 5,
      "name": "Soil_Dirt"
    },
    {
      "x": 1,
      "y": 22,
      "z": 5,
      "name": "Soil_Dirt"
    },
    {
      "x": 1,
      "y": 23,
      "z": 5,
      "name": "Soil_Grass_Deep"
    },
    {
      "x": 1,
      "y": 4,
      "z": 6,
      "name": "Rock_Stone"
    },
    {
      "x": 1,
      "y": 5,
      "z": 6,
      "name": "Rock_Stone"
    },
    {
      "x": 1,
      "y": 6,
      "z": 6,
      "name": "Rock_Stone"
    },
    {
      "x": 1,
      "y": 7,
      "z": 6,
      "name": "Rock_Stone"
    },
    {
      "x": 1,
      "y": 17,
      "z": 6,
      "name": "Rock_Stone"
    },
    {
      "x": 1,
      "y": 18,
      "z": 6,
      "name": "Rock_Stone"
    },
    {
      "x": 1,
      "y": 19,
      "z": 6,
      "name": "Rock_Stone"
    },
    {
      "x": 1,
      "y": 20,
      "z": 6,
      "name": "Rock_Stone"
    },
    {
      "x": 1,
      "y": 21,
      "z": 6,
      "name": "Soil_Dirt"
    },
    {
      "x": 1,
      "y": 22,
      "z": 6,
      "name": "Soil_Dirt"
    },
    {
      "x": 1,
      "y": 23,
      "z": 6,
      "name": "Soil_Leaves"
    },
    {
      "x": 1,
      "y": 24,
      "z": 6,
      "name": "Plant_Grass_Lush"
    },
    {
      "x": 1,
      "y": 4,
      "z": 7,
      "name": "Rock_Stone"
    },
    {
      "x": 1,
      "y": 5,
      "z": 7,
      "name": "Rock_Stone"
    },
    {
      "x": 1,
      "y": 6,
      "z": 7,
      "name": "Rock_Stone"
    },
    {
      "x": 1,
      "y": 7,
      "z": 7,
      "name": "Rock_Stone"
    },
    {
      "x": 1,
      "y": 18,
      "z": 7,
      "name": "Rock_Stone"
    },
    {
      "x": 1,
      "y": 19,
      "z": 7,
      "name": "Rock_Stone"
    },
    {
      "x": 1,
      "y": 20,
      "z": 7,
      "name": "Soil_Dirt"
    },
    {
      "x": 1,
      "y": 21,
      "z": 7,
      "name": "Soil_Dirt"
    },
    {
      "x": 1,
      "y": 22,
      "z": 7,
      "name": "Soil_Grass_Deep"
    },
    {
      "x": 1,
      "y": 4,
      "z": 8,
      "name": "Rock_Stone"
    },
    {
      "x": 1,
      "y": 5,
      "z": 8,
      "name": "Rock_Stone"
    },
    {
      "x": 1,
      "y": 19,
      "z": 8,
      "name": "Rock_Stone"
    },
    {
      "x": 1,
      "y": 20,
      "z": 8,
      "name": "Soil_Dirt"
    },
    {
      "x": 1,
      "y": 21,
      "z": 8,
      "name": "Soil_Grass_Deep"
    },
    {
      "x": 2,
      "y": 21,
      "z": -1,
      "name": "Rock_Stone"
    },
    {
      "x": 2,
      "y": 22,
      "z": -1,
      "name": "Rock_Stone"
    },
    {
      "x": 2,
      "y": 23,
      "z": -1,
      "name": "Rock_Stone"
    },
    {
      "x": 2,
      "y": 24,
      "z": -1,
      "name": "Rock_Stone"
    },
    {
      "x": 2,
      "y": 18,
      "z": 0,
      "name": "Rock_Stone"
    },
    {
      "x": 2,
      "y": 19,
      "z": 0,
      "name": "Rock_Stone"
    },
    {
      "x": 2,
      "y": 20,
      "z": 0,
      "name": "Rock_Stone"
    },
    {
      "x": 2,
      "y": 21,
      "z": 0,
      "name": "Rock_Stone_Mossy"
    },
    {
      "x": 2,
      "y": 22,
      "z": 0,
      "name": "Rock_Stone_Mossy"
    },
    {
      "x": 2,
      "y": 23,
      "z": 0,
      "name": "Rock_Stone"
    },
    {
      "x": 2,
      "y": 24,
      "z": 0,
      "name": "Soil_Gravel"
    },
    {
      "x": 2,
      "y": 25,
      "z": 0,
      "name": "Rock_Stone"
    },
    {
      "x": 2,
      "y": 26,
      "z": 0,
      "name": "Soil_Gravel"
    },
    {
      "x": 2,
      "y": 18,
      "z": 1,
      "name": "Rock_Stone"
    },
    {
      "x": 2,
      "y": 19,
      "z": 1,
      "name": "Rock_Stone"
    },
    {
      "x": 2,
      "y": 20,
      "z": 1,
      "name": "Rock_Stone_Mossy"
    },
    {
      "x": 2,
      "y": 21,
      "z": 1,
      "name": "Rock_Stone"
    },
    {
      "x": 2,
      "y": 22,
      "z": 1,
      "name": "Rock_Stone"
    },
    {
      "x": 2,
      "y": 23,
      "z": 1,
      "name": "Rock_Stone"
    },
    {
      "x": 2,
      "y": 24,
      "z": 1,
      "name": "Rock_Stone"
    },
    {
      "x": 2,
      "y": 25,
      "z": 1,
      "name": "Soil_Gravel"
    },
    {
      "x": 2,
      "y": 26,
      "z": 1,
      "name": "Soil_Gravel"
    },
    {
      "x": 2,
      "y": 18,
      "z": 2,
      "name": "Rock_Stone"
    },
    {
      "x": 2,
      "y": 19,
      "z": 2,
      "name": "Rock_Stone"
    },
    {
      "x": 2,
      "y": 20,
      "z": 2,
      "name": "Rock_Stone"
    },
    {
      "x": 2,
      "y": 21,
      "z": 2,
      "name": "Rock_Stone"
    },
    {
      "x": 2,
      "y": 22,
      "z": 2,
      "name": "Rock_Stone"
    },
    {
      "x": 2,
      "y": 23,
      "z": 2,
      "name": "Soil_Gravel"
    },
    {
      "x": 2,
      "y": 24,
      "z": 2,
      "name": "Soil_Gravel"
    },
    {
      "x": 2,
      "y": 25,
      "z": 2,
      "name": "Soil_Gravel"
    },
    {
      "x": 2,
      "y": 26,
      "z": 2,
      "name": "Rock_Stone"
    },
    {
      "x": 2,
      "y": 17,
      "z": 3,
      "name": "Rock_Stone"
    },
    {
      "x": 2,
      "y": 18,
      "z": 3,
      "name": "Rock_Stone"
    },
    {
      "x": 2,
      "y": 19,
      "z": 3,
      "name": "Rock_Stone"
    },
    {
      "x": 2,
      "y": 20,
      "z": 3,
      "name": "Rock_Stone"
    },
    {
      "x": 2,
      "y": 21,
      "z": 3,
      "name": "Rock_Stone"
    },
    {
      "x": 2,
      "y": 22,
      "z": 3,
      "name": "Rock_Stone"
    },
    {
      "x": 2,
      "y": 23,
      "z": 3,
      "name": "Rock_Stone"
    },
    {
      "x": 2,
      "y": 24,
      "z": 3,
      "name": "Rock_Stone"
    },
    {
      "x": 2,
      "y": 17,
      "z": 4,
      "name": "Rock_Stone"
    },
    {
      "x": 2,
      "y": 18,
      "z": 4,
      "name": "Rock_Stone"
    },
    {
      "x": 2,
      "y": 19,
      "z": 4,
      "name": "Rock_Stone"
    },
    {
      "x": 2,
      "y": 20,
      "z": 4,
      "name": "Rock_Stone"
    },
    {
      "x": 2,
      "y": 21,
      "z": 4,
      "name": "Rock_Stone"
    },
    {
      "x": 2,
      "y": 22,
      "z": 4,
      "name": "Soil_Dirt"
    },
    {
      "x": 2,
      "y": 23,
      "z": 4,
      "name": "Rock_Stone"
    },
    {
      "x": 2,
      "y": 17,
      "z": 5,
      "name": "Rock_Stone"
    },
    {
      "x": 2,
      "y": 18,
      "z": 5,
      "name": "Rock_Stone"
    },
    {
      "x": 2,
      "y": 19,
      "z": 5,
      "name": "Rock_Stone"
    },
    {
      "x": 2,
      "y": 20,
      "z": 5,
      "name": "Rock_Stone"
    },
    {
      "x": 2,
      "y": 21,
      "z": 5,
      "name": "Soil_Dirt"
    },
    {
      "x": 2,
      "y": 22,
      "z": 5,
      "name": "Soil_Dirt"
    },
    {
      "x": 2,
      "y": 23,
      "z": 5,
      "name": "Soil_Leaves"
    },
    {
      "x": 2,
      "y": 4,
      "z": 6,
      "name": "Rock_Stone"
    },
    {
      "x": 2,
      "y": 5,
      "z": 6,
      "name": "Rock_Stone"
    },
    {
      "x": 2,
      "y": 6,
      "z": 6,
      "name": "Rock_Stone"
    },
    {
      "x": 2,
      "y": 17,
      "z": 6,
      "name": "Rock_Stone"
    },
    {
      "x": 2,
      "y": 18,
      "z": 6,
      "name": "Rock_Stone"
    },
    {
      "x": 2,
      "y": 19,
      "z": 6,
      "name": "Rock_Stone"
    },
    {
      "x": 2,
      "y": 20,
      "z": 6,
      "name": "Rock_Stone"
    },
    {
      "x": 2,
      "y": 21,
      "z": 6,
      "name": "Soil_Dirt"
    },
    {
      "x": 2,
      "y": 22,
      "z": 6,
      "name": "Soil_Dirt"
    },
    {
      "x": 2,
      "y": 23,
      "z": 6,
      "name": "Soil_Leaves"
    },
    {
      "x": 2,
      "y": 24,
      "z": 6,
      "name": "Plant_Crop_Mushroom_Cap_Red",
      "components": {
        "Components": {
          "FarmingBlock": {}
        }
      }
    },
    {
      "x": 2,
      "y": 5,
      "z": 7,
      "name": "Rock_Stone"
    },
    {
      "x": 2,
      "y": 18,
      "z": 7,
      "name": "Rock_Stone"
    },
    {
      "x": 2,
      "y": 19,
      "z": 7,
      "name": "Rock_Stone"
    },
    {
      "x": 2,
      "y": 20,
      "z": 7,
      "name": "Soil_Dirt"
    },
    {
      "x": 2,
      "y": 21,
      "z": 7,
      "name": "Soil_Dirt"
    },
    {
      "x": 2,
      "y": 22,
      "z": 7,
      "name": "Soil_Leaves"
    },
    {
      "x": 2,
      "y": 5,
      "z": 8,
      "name": "Rock_Stone"
    },
    {
      "x": 2,
      "y": 18,
      "z": 8,
      "name": "Rock_Stone"
    },
    {
      "x": 2,
      "y": 19,
      "z": 8,
      "name": "Rock_Stone"
    },
    {
      "x": 2,
      "y": 20,
      "z": 8,
      "name": "Soil_Dirt"
    },
    {
      "x": 2,
      "y": 21,
      "z": 8,
      "name": "Soil_Dirt"
    },
    {
      "x": 2,
      "y": 22,
      "z": 8,
      "name": "Soil_Grass_Deep"
    },
    {
      "x": 2,
      "y": 20,
      "z": 9,
      "name": "Soil_Dirt"
    },
    {
      "x": 2,
      "y": 21,
      "z": 9,
      "name": "Soil_Grass_Deep"
    },
    {
      "x": 3,
      "y": 20,
      "z": -1,
      "name": "Rock_Stone_Mossy"
    },
    {
      "x": 3,
      "y": 21,
      "z": -1,
      "name": "Rock_Stone_Mossy"
    },
    {
      "x": 3,
      "y": 22,
      "z": -1,
      "name": "Rock_Stone_Mossy"
    },
    {
      "x": 3,
      "y": 23,
      "z": -1,
      "name": "Rock_Stone"
    },
    {
      "x": 3,
      "y": 24,
      "z": -1,
      "name": "Soil_Gravel"
    },
    {
      "x": 3,
      "y": 18,
      "z": 0,
      "name": "Rock_Stone"
    },
    {
      "x": 3,
      "y": 19,
      "z": 0,
      "name": "Rock_Stone"
    },
    {
      "x": 3,
      "y": 20,
      "z": 0,
      "name": "Rock_Stone_Mossy"
    },
    {
      "x": 3,
      "y": 21,
      "z": 0,
      "name": "Rock_Stone"
    },
    {
      "x": 3,
      "y": 22,
      "z": 0,
      "name": "Soil_Gravel"
    },
    {
      "x": 3,
      "y": 23,
      "z": 0,
      "name": "Soil_Gravel"
    },
    {
      "x": 3,
      "y": 24,
      "z": 0,
      "name": "Soil_Gravel"
    },
    {
      "x": 3,
      "y": 25,
      "z": 0,
      "name": "Soil_Gravel"
    },
    {
      "x": 3,
      "y": 26,
      "z": 0,
      "name": "Soil_Gravel"
    },
    {
      "x": 3,
      "y": 18,
      "z": 1,
      "name": "Rock_Stone"
    },
    {
      "x": 3,
      "y": 19,
      "z": 1,
      "name": "Rock_Stone"
    },
    {
      "x": 3,
      "y": 20,
      "z": 1,
      "name": "Rock_Stone"
    },
    {
      "x": 3,
      "y": 21,
      "z": 1,
      "name": "Rock_Stone"
    },
    {
      "x": 3,
      "y": 22,
      "z": 1,
      "name": "Rock_Stone"
    },
    {
      "x": 3,
      "y": 23,
      "z": 1,
      "name": "Rock_Stone"
    },
    {
      "x": 3,
      "y": 24,
      "z": 1,
      "name": "Soil_Gravel"
    },
    {
      "x": 3,
      "y": 25,
      "z": 1,
      "name": "Rock_Stone"
    },
    {
      "x": 3,
      "y": 26,
      "z": 1,
      "name": "Soil_Gravel"
    },
    {
      "x": 3,
      "y": 27,
      "z": 1,
      "name": "Rubble_Stone"
    },
    {
      "x": 3,
      "y": 18,
      "z": 2,
      "name": "Rock_Stone"
    },
    {
      "x": 3,
      "y": 19,
      "z": 2,
      "name": "Rock_Stone"
    },
    {
      "x": 3,
      "y": 20,
      "z": 2,
      "name": "Soil_Dirt"
    },
    {
      "x": 3,
      "y": 21,
      "z": 2,
      "name": "Rock_Stone"
    },
    {
      "x": 3,
      "y": 22,
      "z": 2,
      "name": "Rock_Stone"
    },
    {
      "x": 3,
      "y": 23,
      "z": 2,
      "name": "Rock_Stone"
    },
    {
      "x": 3,
      "y": 24,
      "z": 2,
      "name": "Rock_Stone"
    },
    {
      "x": 3,
      "y": 25,
      "z": 2,
      "name": "Soil_Gravel"
    },
    {
      "x": 3,
      "y": 17,
      "z": 3,
      "name": "Rock_Stone"
    },
    {
      "x": 3,
      "y": 18,
      "z": 3,
      "name": "Rock_Stone"
    },
    {
      "x": 3,
      "y": 19,
      "z": 3,
      "name": "Rock_Stone"
    },
    {
      "x": 3,
      "y": 20,
      "z": 3,
      "name": "Rock_Stone"
    },
    {
      "x": 3,
      "y": 21,
      "z": 3,
      "name": "Rock_Stone"
    },
    {
      "x": 3,
      "y": 22,
      "z": 3,
      "name": "Rock_Stone"
    },
    {
      "x": 3,
      "y": 23,
      "z": 3,
      "name": "Rock_Stone"
    },
    {
      "x": 3,
      "y": 24,
      "z": 3,
      "name": "Rubble_Stone"
    },
    {
      "x": 3,
      "y": 17,
      "z": 4,
      "name": "Rock_Stone"
    },
    {
      "x": 3,
      "y": 18,
      "z": 4,
      "name": "Rock_Stone"
    },
    {
      "x": 3,
      "y": 19,
      "z": 4,
      "name": "Rock_Stone"
    },
    {
      "x": 3,
      "y": 20,
      "z": 4,
      "name": "Rock_Stone"
    },
    {
      "x": 3,
      "y": 21,
      "z": 4,
      "name": "Rock_Stone"
    },
    {
      "x": 3,
      "y": 22,
      "z": 4,
      "name": "Soil_Dirt"
    },
    {
      "x": 3,
      "y": 23,
      "z": 4,
      "name": "Soil_Leaves"
    },
    {
      "x": 3,
      "y": 24,
      "z": 4,
      "name": "Plant_Grass_Lush_Short"
    },
    {
      "x": 3,
      "y": 17,
      "z": 5,
      "name": "Rock_Stone"
    },
    {
      "x": 3,
      "y": 18,
      "z": 5,
      "name": "Rock_Stone"
    },
    {
      "x": 3,
      "y": 19,
      "z": 5,
      "name": "Rock_Stone"
    },
    {
      "x": 3,
      "y": 20,
      "z": 5,
      "name": "Rock_Stone"
    },
    {
      "x": 3,
      "y": 21,
      "z": 5,
      "name": "Rock_Stone"
    },
    {
      "x": 3,
      "y": 22,
      "z": 5,
      "name": "Soil_Dirt"
    },
    {
      "x": 3,
      "y": 23,
      "z": 5,
      "name": "Soil_Leaves"
    },
    {
      "x": 3,
      "y": 17,
      "z": 6,
      "name": "Rock_Stone"
    },
    {
      "x": 3,
      "y": 18,
      "z": 6,
      "name": "Rock_Stone"
    },
    {
      "x": 3,
      "y": 19,
      "z": 6,
      "name": "Rock_Stone"
    },
    {
      "x": 3,
      "y": 20,
      "z": 6,
      "name": "Rock_Stone"
    },
    {
      "x": 3,
      "y": 21,
      "z": 6,
      "name": "Soil_Dirt"
    },
    {
      "x": 3,
      "y": 22,
      "z": 6,
      "name": "Soil_Dirt"
    },
    {
      "x": 3,
      "y": 23,
      "z": 6,
      "name": "Soil_Leaves"
    },
    {
      "x": 3,
      "y": 17,
      "z": 7,
      "name": "Rock_Stone"
    },
    {
      "x": 3,
      "y": 18,
      "z": 7,
      "name": "Rock_Stone"
    },
    {
      "x": 3,
      "y": 19,
      "z": 7,
      "name": "Rock_Stone"
    },
    {
      "x": 3,
      "y": 20,
      "z": 7,
      "name": "Soil_Dirt"
    },
    {
      "x": 3,
      "y": 21,
      "z": 7,
      "name": "Soil_Dirt"
    },
    {
      "x": 3,
      "y": 22,
      "z": 7,
      "name": "Soil_Grass_Deep"
    },
    {
      "x": 3,
      "y": 18,
      "z": 8,
      "name": "Rock_Stone"
    },
    {
      "x": 3,
      "y": 19,
      "z": 8,
      "name": "Rock_Stone"
    },
    {
      "x": 3,
      "y": 20,
      "z": 8,
      "name": "Soil_Dirt"
    },
    {
      "x": 3,
      "y": 21,
      "z": 8,
      "name": "Soil_Dirt"
    },
    {
      "x": 3,
      "y": 22,
      "z": 8,
      "name": "Soil_Grass_Deep"
    },
    {
      "x": 3,
      "y": 20,
      "z": 9,
      "name": "Soil_Dirt"
    },
    {
      "x": 3,
      "y": 21,
      "z": 9,
      "name": "Soil_Grass_Deep"
    },
    {
      "x": 4,
      "y": 22,
      "z": -1,
      "name": "Rock_Stone"
    },
    {
      "x": 4,
      "y": 23,
      "z": -1,
      "name": "Rock_Stone"
    },
    {
      "x": 4,
      "y": 19,
      "z": 0,
      "name": "Rock_Stone"
    },
    {
      "x": 4,
      "y": 20,
      "z": 0,
      "name": "Rock_Stone"
    },
    {
      "x": 4,
      "y": 21,
      "z": 0,
      "name": "Rock_Stone"
    },
    {
      "x": 4,
      "y": 22,
      "z": 0,
      "name": "Rock_Stone"
    },
    {
      "x": 4,
      "y": 23,
      "z": 0,
      "name": "Rock_Stone"
    },
    {
      "x": 4,
      "y": 18,
      "z": 1,
      "name": "Rock_Stone"
    },
    {
      "x": 4,
      "y": 19,
      "z": 1,
      "name": "Rock_Stone"
    },
    {
      "x": 4,
      "y": 20,
      "z": 1,
      "name": "Rock_Stone"
    },
    {
      "x": 4,
      "y": 21,
      "z": 1,
      "name": "Rock_Stone"
    },
    {
      "x": 4,
      "y": 22,
      "z": 1,
      "name": "Soil_Gravel"
    },
    {
      "x": 4,
      "y": 23,
      "z": 1,
      "name": "Soil_Gravel"
    },
    {
      "x": 4,
      "y": 24,
      "z": 1,
      "name": "Soil_Gravel"
    },
    {
      "x": 4,
      "y": 25,
      "z": 1,
      "name": "Soil_Gravel"
    },
    {
      "x": 4,
      "y": 18,
      "z": 2,
      "name": "Rock_Stone"
    },
    {
      "x": 4,
      "y": 19,
      "z": 2,
      "name": "Rock_Stone"
    },
    {
      "x": 4,
      "y": 20,
      "z": 2,
      "name": "Soil_Dirt"
    },
    {
      "x": 4,
      "y": 21,
      "z": 2,
      "name": "Soil_Dirt"
    },
    {
      "x": 4,
      "y": 22,
      "z": 2,
      "name": "Soil_Dirt"
    },
    {
      "x": 4,
      "y": 23,
      "z": 2,
      "name": "Rock_Stone"
    },
    {
      "x": 4,
      "y": 24,
      "z": 2,
      "name": "Soil_Gravel"
    },
    {
      "x": 4,
      "y": 25,
      "z": 2,
      "name": "Soil_Gravel"
    },
    {
      "x": 4,
      "y": 17,
      "z": 3,
      "name": "Rock_Stone"
    },
    {
      "x": 4,
      "y": 18,
      "z": 3,
      "name": "Rock_Stone"
    },
    {
      "x": 4,
      "y": 19,
      "z": 3,
      "name": "Rock_Stone"
    },
    {
      "x": 4,
      "y": 20,
      "z": 3,
      "name": "Rock_Stone"
    },
    {
      "x": 4,
      "y": 21,
      "z": 3,
      "name": "Soil_Dirt"
    },
    {
      "x": 4,
      "y": 22,
      "z": 3,
      "name": "Soil_Dirt"
    },
    {
      "x": 4,
      "y": 23,
      "z": 3,
      "name": "Soil_Grass_Deep"
    },
    {
      "x": 4,
      "y": 17,
      "z": 4,
      "name": "Rock_Stone"
    },
    {
      "x": 4,
      "y": 18,
      "z": 4,
      "name": "Rock_Stone"
    },
    {
      "x": 4,
      "y": 19,
      "z": 4,
      "name": "Rock_Stone"
    },
    {
      "x": 4,
      "y": 20,
      "z": 4,
      "name": "Rock_Stone"
    },
    {
      "x": 4,
      "y": 21,
      "z": 4,
      "name": "Rock_Stone"
    },
    {
      "x": 4,
      "y": 22,
      "z": 4,
      "name": "Soil_Dirt"
    },
    {
      "x": 4,
      "y": 23,
      "z": 4,
      "name": "Soil_Grass_Deep"
    },
    {
      "x": 4,
      "y": 17,
      "z": 5,
      "name": "Rock_Stone"
    },
    {
      "x": 4,
      "y": 18,
      "z": 5,
      "name": "Rock_Stone"
    },
    {
      "x": 4,
      "y": 19,
      "z": 5,
      "name": "Rock_Stone"
    },
    {
      "x": 4,
      "y": 20,
      "z": 5,
      "name": "Rock_Stone"
    },
    {
      "x": 4,
      "y": 21,
      "z": 5,
      "name": "Rock_Stone"
    },
    {
      "x": 4,
      "y": 22,
      "z": 5,
      "name": "Soil_Dirt"
    },
    {
      "x": 4,
      "y": 23,
      "z": 5,
      "name": "Soil_Leaves"
    },
    {
      "x": 4,
      "y": 17,
      "z": 6,
      "name": "Rock_Stone"
    },
    {
      "x": 4,
      "y": 18,
      "z": 6,
      "name": "Rock_Stone"
    },
    {
      "x": 4,
      "y": 19,
      "z": 6,
      "name": "Rock_Stone"
    },
    {
      "x": 4,
      "y": 20,
      "z": 6,
      "name": "Rock_Stone"
    },
    {
      "x": 4,
      "y": 21,
      "z": 6,
      "name": "Soil_Dirt"
    },
    {
      "x": 4,
      "y": 22,
      "z": 6,
      "name": "Soil_Dirt"
    },
    {
      "x": 4,
      "y": 23,
      "z": 6,
      "name": "Soil_Grass_Deep"
    },
    {
      "x": 4,
      "y": 17,
      "z": 7,
      "name": "Rock_Stone"
    },
    {
      "x": 4,
      "y": 18,
      "z": 7,
      "name": "Rock_Stone"
    },
    {
      "x": 4,
      "y": 19,
      "z": 7,
      "name": "Rock_Stone"
    },
    {
      "x": 4,
      "y": 20,
      "z": 7,
      "name": "Soil_Dirt"
    },
    {
      "x": 4,
      "y": 21,
      "z": 7,
      "name": "Soil_Dirt"
    },
    {
      "x": 4,
      "y": 22,
      "z": 7,
      "name": "Soil_Grass_Deep"
    },
    {
      "x": 4,
      "y": 17,
      "z": 8,
      "name": "Rock_Stone"
    },
    {
      "x": 4,
      "y": 18,
      "z": 8,
      "name": "Rock_Stone"
    },
    {
      "x": 4,
      "y": 19,
      "z": 8,
      "name": "Rock_Stone"
    },
    {
      "x": 4,
      "y": 20,
      "z": 8,
      "name": "Soil_Dirt"
    },
    {
      "x": 4,
      "y": 21,
      "z": 8,
      "name": "Soil_Dirt"
    },
    {
      "x": 4,
      "y": 22,
      "z": 8,
      "name": "Soil_Grass_Deep"
    },
    {
      "x": 4,
      "y": 19,
      "z": 9,
      "name": "Rock_Stone"
    },
    {
      "x": 4,
      "y": 20,
      "z": 9,
      "name": "Soil_Dirt"
    },
    {
      "x": 4,
      "y": 21,
      "z": 9,
      "name": "Soil_Grass_Deep"
    },
    {
      "x": 5,
      "y": 19,
      "z": 0,
      "name": "Soil_Dirt"
    },
    {
      "x": 5,
      "y": 20,
      "z": 0,
      "name": "Soil_Grass_Deep"
    },
    {
      "x": 5,
      "y": 21,
      "z": 0,
      "name": "Rock_Stone"
    },
    {
      "x": 5,
      "y": 18,
      "z": 1,
      "name": "Rock_Stone"
    },
    {
      "x": 5,
      "y": 19,
      "z": 1,
      "name": "Soil_Dirt"
    },
    {
      "x": 5,
      "y": 20,
      "z": 1,
      "name": "Soil_Dirt"
    },
    {
      "x": 5,
      "y": 21,
      "z": 1,
      "name": "Soil_Dirt"
    },
    {
      "x": 5,
      "y": 22,
      "z": 1,
      "name": "Soil_Grass_Deep"
    },
    {
      "x": 5,
      "y": 18,
      "z": 2,
      "name": "Rock_Stone"
    },
    {
      "x": 5,
      "y": 19,
      "z": 2,
      "name": "Soil_Dirt"
    },
    {
      "x": 5,
      "y": 20,
      "z": 2,
      "name": "Soil_Dirt"
    },
    {
      "x": 5,
      "y": 21,
      "z": 2,
      "name": "Soil_Dirt"
    },
    {
      "x": 5,
      "y": 22,
      "z": 2,
      "name": "Soil_Grass_Deep"
    },
    {
      "x": 5,
      "y": 23,
      "z": 2,
      "name": "Plant_Flower_Common_Violet"
    },
    {
      "x": 5,
      "y": 17,
      "z": 3,
      "name": "Rock_Stone"
    },
    {
      "x": 5,
      "y": 18,
      "z": 3,
      "name": "Rock_Stone"
    },
    {
      "x": 5,
      "y": 19,
      "z": 3,
      "name": "Rock_Stone"
    },
    {
      "x": 5,
      "y": 20,
      "z": 3,
      "name": "Soil_Dirt"
    },
    {
      "x": 5,
      "y": 21,
      "z": 3,
      "name": "Soil_Dirt"
    },
    {
      "x": 5,
      "y": 22,
      "z": 3,
      "name": "Soil_Dirt"
    },
    {
      "x": 5,
      "y": 23,
      "z": 3,
      "name": "Soil_Grass_Deep"
    },
    {
      "x": 5,
      "y": 17,
      "z": 4,
      "name": "Rock_Stone"
    },
    {
      "x": 5,
      "y": 18,
      "z": 4,
      "name": "Rock_Stone"
    },
    {
      "x": 5,
      "y": 19,
      "z": 4,
      "name": "Rock_Stone"
    },
    {
      "x": 5,
      "y": 20,
      "z": 4,
      "name": "Rock_Stone"
    },
    {
      "x": 5,
      "y": 21,
      "z": 4,
      "name": "Rock_Stone"
    },
    {
      "x": 5,
      "y": 22,
      "z": 4,
      "name": "Soil_Dirt"
    },
    {
      "x": 5,
      "y": 23,
      "z": 4,
      "name": "Soil_Grass_Deep"
    },
    {
      "x": 5,
      "y": 17,
      "z": 5,
      "name": "Rock_Stone"
    },
    {
      "x": 5,
      "y": 18,
      "z": 5,
      "name": "Rock_Stone"
    },
    {
      "x": 5,
      "y": 19,
      "z": 5,
      "name": "Rock_Stone"
    },
    {
      "x": 5,
      "y": 20,
      "z": 5,
      "name": "Rock_Stone"
    },
    {
      "x": 5,
      "y": 21,
      "z": 5,
      "name": "Soil_Dirt"
    },
    {
      "x": 5,
      "y": 22,
      "z": 5,
      "name": "Soil_Dirt"
    },
    {
      "x": 5,
      "y": 23,
      "z": 5,
      "name": "Soil_Grass_Deep"
    },
    {
      "x": 5,
      "y": 17,
      "z": 6,
      "name": "Rock_Stone"
    },
    {
      "x": 5,
      "y": 18,
      "z": 6,
      "name": "Rock_Stone"
    },
    {
      "x": 5,
      "y": 19,
      "z": 6,
      "name": "Rock_Stone"
    },
    {
      "x": 5,
      "y": 20,
      "z": 6,
      "name": "Rock_Stone"
    },
    {
      "x": 5,
      "y": 21,
      "z": 6,
      "name": "Soil_Dirt"
    },
    {
      "x": 5,
      "y": 22,
      "z": 6,
      "name": "Soil_Grass_Deep"
    },
    {
      "x": 5,
      "y": 17,
      "z": 7,
      "name": "Rock_Stone"
    },
    {
      "x": 5,
      "y": 18,
      "z": 7,
      "name": "Rock_Stone"
    },
    {
      "x": 5,
      "y": 19,
      "z": 7,
      "name": "Rock_Stone"
    },
    {
      "x": 5,
      "y": 20,
      "z": 7,
      "name": "Rock_Stone"
    },
    {
      "x": 5,
      "y": 21,
      "z": 7,
      "name": "Soil_Dirt"
    },
    {
      "x": 5,
      "y": 22,
      "z": 7,
      "name": "Soil_Grass_Deep"
    },
    {
      "x": 5,
      "y": 17,
      "z": 8,
      "name": "Rock_Stone"
    },
    {
      "x": 5,
      "y": 18,
      "z": 8,
      "name": "Rock_Stone"
    },
    {
      "x": 5,
      "y": 19,
      "z": 8,
      "name": "Rock_Stone"
    },
    {
      "x": 5,
      "y": 20,
      "z": 8,
      "name": "Soil_Dirt"
    },
    {
      "x": 5,
      "y": 21,
      "z": 8,
      "name": "Soil_Grass_Deep"
    },
    {
      "x": 5,
      "y": 19,
      "z": 9,
      "name": "Rock_Stone"
    },
    {
      "x": 5,
      "y": 20,
      "z": 9,
      "name": "Soil_Grass_Deep"
    },
    {
      "x": 6,
      "y": 19,
      "z": 0,
      "name": "Soil_Dirt"
    },
    {
      "x": 6,
      "y": 20,
      "z": 0,
      "name": "Soil_Grass_Deep"
    },
    {
      "x": 6,
      "y": 5,
      "z": 1,
      "name": "Rock_Stone"
    },
    {
      "x": 6,
      "y": 6,
      "z": 1,
      "name": "Rock_Stone"
    },
    {
      "x": 6,
      "y": 18,
      "z": 1,
      "name": "Rock_Stone"
    },
    {
      "x": 6,
      "y": 19,
      "z": 1,
      "name": "Soil_Dirt"
    },
    {
      "x": 6,
      "y": 20,
      "z": 1,
      "name": "Soil_Dirt"
    },
    {
      "x": 6,
      "y": 21,
      "z": 1,
      "name": "Soil_Grass_Deep"
    },
    {
      "x": 6,
      "y": 5,
      "z": 2,
      "name": "Rock_Stone"
    },
    {
      "x": 6,
      "y": 6,
      "z": 2,
      "name": "Rock_Stone"
    },
    {
      "x": 6,
      "y": 7,
      "z": 2,
      "name": "Rock_Stone"
    },
    {
      "x": 6,
      "y": 17,
      "z": 2,
      "name": "Rock_Stone"
    },
    {
      "x": 6,
      "y": 18,
      "z": 2,
      "name": "Rock_Stone"
    },
    {
      "x": 6,
      "y": 19,
      "z": 2,
      "name": "Soil_Dirt"
    },
    {
      "x": 6,
      "y": 20,
      "z": 2,
      "name": "Soil_Dirt"
    },
    {
      "x": 6,
      "y": 21,
      "z": 2,
      "name": "Soil_Dirt"
    },
    {
      "x": 6,
      "y": 22,
      "z": 2,
      "name": "Soil_Grass_Deep"
    },
    {
      "x": 6,
      "y": 17,
      "z": 3,
      "name": "Rock_Stone"
    },
    {
      "x": 6,
      "y": 18,
      "z": 3,
      "name": "Rock_Stone"
    },
    {
      "x": 6,
      "y": 19,
      "z": 3,
      "name": "Soil_Dirt"
    },
    {
      "x": 6,
      "y": 20,
      "z": 3,
      "name": "Soil_Dirt"
    },
    {
      "x": 6,
      "y": 21,
      "z": 3,
      "name": "Soil_Dirt"
    },
    {
      "x": 6,
      "y": 22,
      "z": 3,
      "name": "Soil_Grass_Deep"
    },
    {
      "x": 6,
      "y": 23,
      "z": 3,
      "name": "Rubble_Stone_Mossy"
    },
    {
      "x": 6,
      "y": 16,
      "z": 4,
      "name": "Rock_Stone"
    },
    {
      "x": 6,
      "y": 17,
      "z": 4,
      "name": "Rock_Stone"
    },
    {
      "x": 6,
      "y": 18,
      "z": 4,
      "name": "Rock_Stone"
    },
    {
      "x": 6,
      "y": 19,
      "z": 4,
      "name": "Rock_Stone"
    },
    {
      "x": 6,
      "y": 20,
      "z": 4,
      "name": "Rock_Stone"
    },
    {
      "x": 6,
      "y": 21,
      "z": 4,
      "name": "Soil_Dirt"
    },
    {
      "x": 6,
      "y": 22,
      "z": 4,
      "name": "Soil_Dirt"
    },
    {
      "x": 6,
      "y": 23,
      "z": 4,
      "name": "Soil_Grass_Deep"
    },
    {
      "x": 6,
      "y": 16,
      "z": 5,
      "name": "Rock_Stone"
    },
    {
      "x": 6,
      "y": 17,
      "z": 5,
      "name": "Rock_Stone"
    },
    {
      "x": 6,
      "y": 18,
      "z": 5,
      "name": "Rock_Stone"
    },
    {
      "x": 6,
      "y": 19,
      "z": 5,
      "name": "Rock_Stone"
    },
    {
      "x": 6,
      "y": 20,
      "z": 5,
      "name": "Rock_Stone"
    },
    {
      "x": 6,
      "y": 21,
      "z": 5,
      "name": "Soil_Dirt"
    },
    {
      "x": 6,
      "y": 22,
      "z": 5,
      "name": "Soil_Grass_Deep"
    },
    {
      "x": 6,
      "y": 17,
      "z": 6,
      "name": "Rock_Stone"
    },
    {
      "x": 6,
      "y": 18,
      "z": 6,
      "name": "Rock_Stone"
    },
    {
      "x": 6,
      "y": 19,
      "z": 6,
      "name": "Rock_Stone"
    },
    {
      "x": 6,
      "y": 20,
      "z": 6,
      "name": "Soil_Dirt"
    },
    {
      "x": 6,
      "y": 21,
      "z": 6,
      "name": "Soil_Dirt"
    },
    {
      "x": 6,
      "y": 22,
      "z": 6,
      "name": "Soil_Grass_Deep"
    },
    {
      "x": 6,
      "y": 17,
      "z": 7,
      "name": "Rock_Stone"
    },
    {
      "x": 6,
      "y": 18,
      "z": 7,
      "name": "Rock_Stone"
    },
    {
      "x": 6,
      "y": 19,
      "z": 7,
      "name": "Rock_Stone"
    },
    {
      "x": 6,
      "y": 20,
      "z": 7,
      "name": "Soil_Dirt"
    },
    {
      "x": 6,
      "y": 21,
      "z": 7,
      "name": "Soil_Dirt"
    },
    {
      "x": 6,
      "y": 22,
      "z": 7,
      "name": "Soil_Grass_Deep"
    },
    {
      "x": 6,
      "y": 17,
      "z": 8,
      "name": "Rock_Stone"
    },
    {
      "x": 6,
      "y": 18,
      "z": 8,
      "name": "Rock_Stone"
    },
    {
      "x": 6,
      "y": 19,
      "z": 8,
      "name": "Rock_Stone"
    },
    {
      "x": 6,
      "y": 20,
      "z": 8,
      "name": "Soil_Dirt"
    },
    {
      "x": 6,
      "y": 21,
      "z": 8,
      "name": "Soil_Grass_Deep"
    },
    {
      "x": 7,
      "y": 6,
      "z": 0,
      "name": "Rock_Stone"
    },
    {
      "x": 7,
      "y": 7,
      "z": 0,
      "name": "Rock_Stone"
    },
    {
      "x": 7,
      "y": 19,
      "z": 0,
      "name": "Soil_Grass_Deep"
    },
    {
      "x": 7,
      "y": 6,
      "z": 1,
      "name": "Rock_Stone"
    },
    {
      "x": 7,
      "y": 7,
      "z": 1,
      "name": "Rock_Stone"
    },
    {
      "x": 7,
      "y": 17,
      "z": 1,
      "name": "Rock_Stone"
    },
    {
      "x": 7,
      "y": 18,
      "z": 1,
      "name": "Soil_Dirt"
    },
    {
      "x": 7,
      "y": 19,
      "z": 1,
      "name": "Soil_Dirt"
    },
    {
      "x": 7,
      "y": 20,
      "z": 1,
      "name": "Soil_Dirt"
    },
    {
      "x": 7,
      "y": 21,
      "z": 1,
      "name": "Soil_Grass_Deep"
    },
    {
      "x": 7,
      "y": 5,
      "z": 2,
      "name": "Rock_Stone"
    },
    {
      "x": 7,
      "y": 6,
      "z": 2,
      "name": "Rock_Stone"
    },
    {
      "x": 7,
      "y": 7,
      "z": 2,
      "name": "Rock_Stone"
    },
    {
      "x": 7,
      "y": 8,
      "z": 2,
      "name": "Rock_Stone"
    },
    {
      "x": 7,
      "y": 9,
      "z": 2,
      "name": "Rock_Stone"
    },
    {
      "x": 7,
      "y": 17,
      "z": 2,
      "name": "Rock_Stone"
    },
    {
      "x": 7,
      "y": 18,
      "z": 2,
      "name": "Rock_Stone"
    },
    {
      "x": 7,
      "y": 19,
      "z": 2,
      "name": "Soil_Dirt"
    },
    {
      "x": 7,
      "y": 20,
      "z": 2,
      "name": "Soil_Dirt"
    },
    {
      "x": 7,
      "y": 21,
      "z": 2,
      "name": "Soil_Dirt"
    },
    {
      "x": 7,
      "y": 22,
      "z": 2,
      "name": "Soil_Grass_Deep"
    },
    {
      "x": 7,
      "y": 6,
      "z": 3,
      "name": "Rock_Stone"
    },
    {
      "x": 7,
      "y": 7,
      "z": 3,
      "name": "Rock_Stone"
    },
    {
      "x": 7,
      "y": 8,
      "z": 3,
      "name": "Rock_Stone"
    },
    {
      "x": 7,
      "y": 17,
      "z": 3,
      "name": "Rock_Stone"
    },
    {
      "x": 7,
      "y": 18,
      "z": 3,
      "name": "Rock_Stone"
    },
    {
      "x": 7,
      "y": 19,
      "z": 3,
      "name": "Soil_Dirt"
    },
    {
      "x": 7,
      "y": 20,
      "z": 3,
      "name": "Soil_Dirt"
    },
    {
      "x": 7,
      "y": 21,
      "z": 3,
      "name": "Soil_Dirt"
    },
    {
      "x": 7,
      "y": 22,
      "z": 3,
      "name": "Soil_Grass_Deep"
    },
    {
      "x": 7,
      "y": 16,
      "z": 4,
      "name": "Rock_Stone"
    },
    {
      "x": 7,
      "y": 17,
      "z": 4,
      "name": "Rock_Stone"
    },
    {
      "x": 7,
      "y": 18,
      "z": 4,
      "name": "Rock_Stone"
    },
    {
      "x": 7,
      "y": 19,
      "z": 4,
      "name": "Rock_Stone"
    },
    {
      "x": 7,
      "y": 20,
      "z": 4,
      "name": "Soil_Dirt"
    },
    {
      "x": 7,
      "y": 21,
      "z": 4,
      "name": "Soil_Dirt"
    },
    {
      "x": 7,
      "y": 22,
      "z": 4,
      "name": "Soil_Grass_Deep"
    },
    {
      "x": 7,
      "y": 16,
      "z": 5,
      "name": "Rock_Stone"
    },
    {
      "x": 7,
      "y": 17,
      "z": 5,
      "name": "Rock_Stone"
    },
    {
      "x": 7,
      "y": 18,
      "z": 5,
      "name": "Rock_Stone"
    },
    {
      "x": 7,
      "y": 19,
      "z": 5,
      "name": "Rock_Stone"
    },
    {
      "x": 7,
      "y": 20,
      "z": 5,
      "name": "Soil_Dirt"
    },
    {
      "x": 7,
      "y": 21,
      "z": 5,
      "name": "Soil_Dirt"
    },
    {
      "x": 7,
      "y": 22,
      "z": 5,
      "name": "Soil_Grass_Deep"
    },
    {
      "x": 7,
      "y": 17,
      "z": 6,
      "name": "Rock_Stone"
    },
    {
      "x": 7,
      "y": 18,
      "z": 6,
      "name": "Rock_Stone"
    },
    {
      "x": 7,
      "y": 19,
      "z": 6,
      "name": "Soil_Dirt"
    },
    {
      "x": 7,
      "y": 20,
      "z": 6,
      "name": "Soil_Dirt"
    },
    {
      "x": 7,
      "y": 21,
      "z": 6,
      "name": "Soil_Dirt"
    },
    {
      "x": 7,
      "y": 22,
      "z": 6,
      "name": "Soil_Leaves"
    },
    {
      "x": 7,
      "y": 17,
      "z": 7,
      "name": "Rock_Stone"
    },
    {
      "x": 7,
      "y": 18,
      "z": 7,
      "name": "Rock_Stone"
    },
    {
      "x": 7,
      "y": 19,
      "z": 7,
      "name": "Soil_Dirt"
    },
    {
      "x": 7,
      "y": 20,
      "z": 7,
      "name": "Soil_Dirt"
    },
    {
      "x": 7,
      "y": 21,
      "z": 7,
      "name": "Soil_Dirt"
    },
    {
      "x": 7,
      "y": 22,
      "z": 7,
      "name": "Soil_Leaves"
    },
    {
      "x": 7,
      "y": 23,
      "z": 7,
      "name": "Plant_Grass_Lush_Short"
    },
    {
      "x": 7,
      "y": 18,
      "z": 8,
      "name": "Rock_Stone"
    },
    {
      "x": 7,
      "y": 19,
      "z": 8,
      "name": "Soil_Dirt"
    },
    {
      "x": 7,
      "y": 20,
      "z": 8,
      "name": "Soil_Grass_Deep"
    },
    {
      "x": 8,
      "y": 7,
      "z": 0,
      "name": "Rock_Stone"
    },
    {
      "x": 8,
      "y": 8,
      "z": 0,
      "name": "Rock_Stone"
    },
    {
      "x": 8,
      "y": 18,
      "z": 0,
      "name": "Rock_Stone"
    },
    {
      "x": 8,
      "y": 19,
      "z": 0,
      "name": "Soil_Grass_Deep"
    },
    {
      "x": 8,
      "y": 6,
      "z": 1,
      "name": "Rock_Stone"
    },
    {
      "x": 8,
      "y": 7,
      "z": 1,
      "name": "Rock_Stone"
    },
    {
      "x": 8,
      "y": 8,
      "z": 1,
      "name": "Rock_Stone"
    },
    {
      "x": 8,
      "y": 9,
      "z": 1,
      "name": "Rock_Stone"
    },
    {
      "x": 8,
      "y": 17,
      "z": 1,
      "name": "Rock_Stone"
    },
    {
      "x": 8,
      "y": 18,
      "z": 1,
      "name": "Soil_Dirt"
    },
    {
      "x": 8,
      "y": 19,
      "z": 1,
      "name": "Soil_Dirt"
    },
    {
      "x": 8,
      "y": 20,
      "z": 1,
      "name": "Soil_Dirt"
    },
    {
      "x": 8,
      "y": 21,
      "z": 1,
      "name": "Soil_Grass_Deep"
    },
    {
      "x": 8,
      "y": 5,
      "z": 2,
      "name": "Rock_Stone"
    },
    {
      "x": 8,
      "y": 6,
      "z": 2,
      "name": "Rock_Stone"
    },
    {
      "x": 8,
      "y": 7,
      "z": 2,
      "name": "Rock_Stone"
    },
    {
      "x": 8,
      "y": 8,
      "z": 2,
      "name": "Rock_Stone"
    },
    {
      "x": 8,
      "y": 9,
      "z": 2,
      "name": "Rock_Stone"
    },
    {
      "x": 8,
      "y": 10,
      "z": 2,
      "name": "Rock_Stone"
    },
    {
      "x": 8,
      "y": 11,
      "z": 2,
      "name": "Rock_Stone"
    },
    {
      "x": 8,
      "y": 12,
      "z": 2,
      "name": "Rock_Stone"
    },
    {
      "x": 8,
      "y": 15,
      "z": 2,
      "name": "Rock_Stone"
    },
    {
      "x": 8,
      "y": 16,
      "z": 2,
      "name": "Rock_Stone"
    },
    {
      "x": 8,
      "y": 17,
      "z": 2,
      "name": "Rock_Stone"
    },
    {
      "x": 8,
      "y": 18,
      "z": 2,
      "name": "Rock_Stone"
    },
    {
      "x": 8,
      "y": 19,
      "z": 2,
      "name": "Soil_Dirt"
    },
    {
      "x": 8,
      "y": 20,
      "z": 2,
      "name": "Soil_Dirt"
    },
    {
      "x": 8,
      "y": 21,
      "z": 2,
      "name": "Soil_Grass_Deep"
    },
    {
      "x": 8,
      "y": 7,
      "z": 3,
      "name": "Rock_Stone"
    },
    {
      "x": 8,
      "y": 8,
      "z": 3,
      "name": "Rock_Stone"
    },
    {
      "x": 8,
      "y": 9,
      "z": 3,
      "name": "Rock_Stone"
    },
    {
      "x": 8,
      "y": 10,
      "z": 3,
      "name": "Rock_Stone"
    },
    {
      "x": 8,
      "y": 11,
      "z": 3,
      "name": "Rock_Stone"
    },
    {
      "x": 8,
      "y": 12,
      "z": 3,
      "name": "Rock_Stone"
    },
    {
      "x": 8,
      "y": 13,
      "z": 3,
      "name": "Rock_Stone"
    },
    {
      "x": 8,
      "y": 14,
      "z": 3,
      "name": "Rock_Stone"
    },
    {
      "x": 8,
      "y": 15,
      "z": 3,
      "name": "Rock_Stone"
    },
    {
      "x": 8,
      "y": 16,
      "z": 3,
      "name": "Rock_Stone"
    },
    {
      "x": 8,
      "y": 17,
      "z": 3,
      "name": "Rock_Stone"
    },
    {
      "x": 8,
      "y": 18,
      "z": 3,
      "name": "Rock_Stone"
    },
    {
      "x": 8,
      "y": 19,
      "z": 3,
      "name": "Soil_Dirt"
    },
    {
      "x": 8,
      "y": 20,
      "z": 3,
      "name": "Soil_Dirt"
    },
    {
      "x": 8,
      "y": 21,
      "z": 3,
      "name": "Soil_Dirt"
    },
    {
      "x": 8,
      "y": 22,
      "z": 3,
      "name": "Soil_Grass_Deep"
    },
    {
      "x": 8,
      "y": 9,
      "z": 4,
      "name": "Rock_Stone"
    },
    {
      "x": 8,
      "y": 13,
      "z": 4,
      "name": "Rock_Stone"
    },
    {
      "x": 8,
      "y": 14,
      "z": 4,
      "name": "Rock_Stone"
    },
    {
      "x": 8,
      "y": 15,
      "z": 4,
      "name": "Rock_Stone"
    },
    {
      "x": 8,
      "y": 16,
      "z": 4,
      "name": "Rock_Stone"
    },
    {
      "x": 8,
      "y": 17,
      "z": 4,
      "name": "Rock_Stone"
    },
    {
      "x": 8,
      "y": 18,
      "z": 4,
      "name": "Rock_Stone"
    },
    {
      "x": 8,
      "y": 19,
      "z": 4,
      "name": "Rock_Stone"
    },
    {
      "x": 8,
      "y": 20,
      "z": 4,
      "name": "Soil_Dirt"
    },
    {
      "x": 8,
      "y": 21,
      "z": 4,
      "name": "Soil_Dirt"
    },
    {
      "x": 8,
      "y": 22,
      "z": 4,
      "name": "Soil_Grass_Deep"
    },
    {
      "x": 8,
      "y": 16,
      "z": 5,
      "name": "Rock_Stone"
    },
    {
      "x": 8,
      "y": 17,
      "z": 5,
      "name": "Rock_Stone"
    },
    {
      "x": 8,
      "y": 18,
      "z": 5,
      "name": "Rock_Stone"
    },
    {
      "x": 8,
      "y": 19,
      "z": 5,
      "name": "Soil_Dirt"
    },
    {
      "x": 8,
      "y": 20,
      "z": 5,
      "name": "Soil_Dirt"
    },
    {
      "x": 8,
      "y": 21,
      "z": 5,
      "name": "Soil_Leaves"
    },
    {
      "x": 8,
      "y": 22,
      "z": 5,
      "name": "Plant_Crop_Mushroom_Cap_Red",
      "components": {
        "Components": {
          "FarmingBlock": {}
        }
      }
    },
    {
      "x": 8,
      "y": 16,
      "z": 6,
      "name": "Rock_Stone"
    },
    {
      "x": 8,
      "y": 17,
      "z": 6,
      "name": "Rock_Stone"
    },
    {
      "x": 8,
      "y": 18,
      "z": 6,
      "name": "Rock_Stone"
    },
    {
      "x": 8,
      "y": 19,
      "z": 6,
      "name": "Soil_Dirt"
    },
    {
      "x": 8,
      "y": 20,
      "z": 6,
      "name": "Soil_Dirt"
    },
    {
      "x": 8,
      "y": 21,
      "z": 6,
      "name": "Soil_Leaves"
    },
    {
      "x": 8,
      "y": 17,
      "z": 7,
      "name": "Rock_Stone"
    },
    {
      "x": 8,
      "y": 18,
      "z": 7,
      "name": "Rock_Stone"
    },
    {
      "x": 8,
      "y": 19,
      "z": 7,
      "name": "Soil_Dirt"
    },
    {
      "x": 8,
      "y": 20,
      "z": 7,
      "name": "Soil_Dirt"
    },
    {
      "x": 8,
      "y": 21,
      "z": 7,
      "name": "Soil_Leaves"
    },
    {
      "x": 9,
      "y": 8,
      "z": 0,
      "name": "Rock_Stone"
    },
    {
      "x": 9,
      "y": 18,
      "z": 0,
      "name": "Soil_Grass_Deep"
    },
    {
      "x": 9,
      "y": 7,
      "z": 1,
      "name": "Rock_Stone"
    },
    {
      "x": 9,
      "y": 8,
      "z": 1,
      "name": "Rock_Stone"
    },
    {
      "x": 9,
      "y": 9,
      "z": 1,
      "name": "Rock_Stone"
    },
    {
      "x": 9,
      "y": 10,
      "z": 1,
      "name": "Rock_Stone"
    },
    {
      "x": 9,
      "y": 11,
      "z": 1,
      "name": "Rock_Stone"
    },
    {
      "x": 9,
      "y": 12,
      "z": 1,
      "name": "Rock_Stone"
    },
    {
      "x": 9,
      "y": 13,
      "z": 1,
      "name": "Rock_Stone"
    },
    {
      "x": 9,
      "y": 16,
      "z": 1,
      "name": "Rock_Stone"
    },
    {
      "x": 9,
      "y": 17,
      "z": 1,
      "name": "Rock_Stone"
    },
    {
      "x": 9,
      "y": 18,
      "z": 1,
      "name": "Soil_Dirt"
    },
    {
      "x": 9,
      "y": 19,
      "z": 1,
      "name": "Soil_Dirt"
    },
    {
      "x": 9,
      "y": 20,
      "z": 1,
      "name": "Soil_Grass_Deep"
    },
    {
      "x": 9,
      "y": 6,
      "z": 2,
      "name": "Rock_Stone"
    },
    {
      "x": 9,
      "y": 7,
      "z": 2,
      "name": "Rock_Stone"
    },
    {
      "x": 9,
      "y": 8,
      "z": 2,
      "name": "Rock_Stone"
    },
    {
      "x": 9,
      "y": 9,
      "z": 2,
      "name": "Rock_Stone"
    },
    {
      "x": 9,
      "y": 10,
      "z": 2,
      "name": "Rock_Stone"
    },
    {
      "x": 9,
      "y": 11,
      "z": 2,
      "name": "Rock_Stone"
    },
    {
      "x": 9,
      "y": 12,
      "z": 2,
      "name": "Rock_Stone"
    },
    {
      "x": 9,
      "y": 13,
      "z": 2,
      "name": "Rock_Stone"
    },
    {
      "x": 9,
      "y": 14,
      "z": 2,
      "name": "Rock_Stone"
    },
    {
      "x": 9,
      "y": 15,
      "z": 2,
      "name": "Rock_Stone"
    },
    {
      "x": 9,
      "y": 16,
      "z": 2,
      "name": "Rock_Stone"
    },
    {
      "x": 9,
      "y": 17,
      "z": 2,
      "name": "Soil_Dirt"
    },
    {
      "x": 9,
      "y": 18,
      "z": 2,
      "name": "Soil_Dirt"
    },
    {
      "x": 9,
      "y": 19,
      "z": 2,
      "name": "Soil_Dirt"
    },
    {
      "x": 9,
      "y": 20,
      "z": 2,
      "name": "Soil_Dirt"
    },
    {
      "x": 9,
      "y": 21,
      "z": 2,
      "name": "Soil_Grass_Deep"
    },
    {
      "x": 9,
      "y": 7,
      "z": 3,
      "name": "Rock_Stone"
    },
    {
      "x": 9,
      "y": 8,
      "z": 3,
      "name": "Rock_Stone"
    },
    {
      "x": 9,
      "y": 9,
      "z": 3,
      "name": "Rock_Stone"
    },
    {
      "x": 9,
      "y": 10,
      "z": 3,
      "name": "Rock_Stone"
    },
    {
      "x": 9,
      "y": 11,
      "z": 3,
      "name": "Rock_Stone"
    },
    {
      "x": 9,
      "y": 12,
      "z": 3,
      "name": "Rock_Stone"
    },
    {
      "x": 9,
      "y": 13,
      "z": 3,
      "name": "Rock_Stone"
    },
    {
      "x": 9,
      "y": 14,
      "z": 3,
      "name": "Rock_Stone"
    },
    {
      "x": 9,
      "y": 15,
      "z": 3,
      "name": "Rock_Stone"
    },
    {
      "x": 9,
      "y": 16,
      "z": 3,
      "name": "Rock_Stone"
    },
    {
      "x": 9,
      "y": 17,
      "z": 3,
      "name": "Soil_Dirt"
    },
    {
      "x": 9,
      "y": 18,
      "z": 3,
      "name": "Soil_Dirt"
    },
    {
      "x": 9,
      "y": 19,
      "z": 3,
      "name": "Soil_Dirt"
    },
    {
      "x": 9,
      "y": 20,
      "z": 3,
      "name": "Soil_Dirt"
    },
    {
      "x": 9,
      "y": 21,
      "z": 3,
      "name": "Soil_Grass_Deep"
    },
    {
      "x": 9,
      "y": 8,
      "z": 4,
      "name": "Rock_Stone"
    },
    {
      "x": 9,
      "y": 9,
      "z": 4,
      "name": "Rock_Stone"
    },
    {
      "x": 9,
      "y": 10,
      "z": 4,
      "name": "Rock_Stone"
    },
    {
      "x": 9,
      "y": 11,
      "z": 4,
      "name": "Rock_Stone"
    },
    {
      "x": 9,
      "y": 12,
      "z": 4,
      "name": "Rock_Stone"
    },
    {
      "x": 9,
      "y": 13,
      "z": 4,
      "name": "Rock_Stone"
    },
    {
      "x": 9,
      "y": 14,
      "z": 4,
      "name": "Rock_Stone"
    },
    {
      "x": 9,
      "y": 15,
      "z": 4,
      "name": "Rock_Stone"
    },
    {
      "x": 9,
      "y": 16,
      "z": 4,
      "name": "Rock_Stone"
    },
    {
      "x": 9,
      "y": 17,
      "z": 4,
      "name": "Soil_Dirt"
    },
    {
      "x": 9,
      "y": 18,
      "z": 4,
      "name": "Rock_Stone"
    },
    {
      "x": 9,
      "y": 19,
      "z": 4,
      "name": "Soil_Dirt"
    },
    {
      "x": 9,
      "y": 20,
      "z": 4,
      "name": "Soil_Dirt"
    },
    {
      "x": 9,
      "y": 21,
      "z": 4,
      "name": "Soil_Grass_Deep"
    },
    {
      "x": 9,
      "y": 12,
      "z": 5,
      "name": "Rock_Stone"
    },
    {
      "x": 9,
      "y": 13,
      "z": 5,
      "name": "Rock_Stone"
    },
    {
      "x": 9,
      "y": 15,
      "z": 5,
      "name": "Rock_Stone"
    },
    {
      "x": 9,
      "y": 16,
      "z": 5,
      "name": "Rock_Stone"
    },
    {
      "x": 9,
      "y": 17,
      "z": 5,
      "name": "Rock_Stone"
    },
    {
      "x": 9,
      "y": 18,
      "z": 5,
      "name": "Soil_Dirt"
    },
    {
      "x": 9,
      "y": 19,
      "z": 5,
      "name": "Soil_Dirt"
    },
    {
      "x": 9,
      "y": 20,
      "z": 5,
      "name": "Soil_Dirt"
    },
    {
      "x": 9,
      "y": 21,
      "z": 5,
      "name": "Soil_Grass_Deep"
    },
    {
      "x": 9,
      "y": 16,
      "z": 6,
      "name": "Rock_Stone"
    },
    {
      "x": 9,
      "y": 17,
      "z": 6,
      "name": "Rock_Stone"
    },
    {
      "x": 9,
      "y": 18,
      "z": 6,
      "name": "Rock_Stone"
    },
    {
      "x": 9,
      "y": 19,
      "z": 6,
      "name": "Soil_Dirt"
    },
    {
      "x": 9,
      "y": 20,
      "z": 6,
      "name": "Soil_Dirt"
    },
    {
      "x": 9,
      "y": 21,
      "z": 6,
      "name": "Soil_Leaves"
    },
    {
      "x": 9,
      "y": 22,
      "z": 6,
      "name": "Plant_Grass_Lush_Short"
    },
    {
      "x": 9,
      "y": 16,
      "z": 7,
      "name": "Rock_Stone"
    },
    {
      "x": 9,
      "y": 17,
      "z": 7,
      "name": "Rock_Stone"
    },
    {
      "x": 9,
      "y": 18,
      "z": 7,
      "name": "Soil_Dirt"
    },
    {
      "x": 9,
      "y": 19,
      "z": 7,
      "name": "Soil_Dirt"
    },
    {
      "x": 9,
      "y": 20,
      "z": 7,
      "name": "Soil_Leaves"
    },
    {
      "x": 9,
      "y": 21,
      "z": 7,
      "name": "Plant_Grass_Lush"
    },
    {
      "x": 10,
      "y": 17,
      "z": 0,
      "name": "Rock_Stone"
    },
    {
      "x": 10,
      "y": 18,
      "z": 0,
      "name": "Soil_Grass_Deep"
    },
    {
      "x": 10,
      "y": 9,
      "z": 1,
      "name": "Rock_Stone"
    },
    {
      "x": 10,
      "y": 10,
      "z": 1,
      "name": "Rock_Stone"
    },
    {
      "x": 10,
      "y": 11,
      "z": 1,
      "name": "Rock_Stone"
    },
    {
      "x": 10,
      "y": 12,
      "z": 1,
      "name": "Rock_Stone"
    },
    {
      "x": 10,
      "y": 13,
      "z": 1,
      "name": "Rock_Stone"
    },
    {
      "x": 10,
      "y": 14,
      "z": 1,
      "name": "Rock_Stone"
    },
    {
      "x": 10,
      "y": 15,
      "z": 1,
      "name": "Rock_Stone"
    },
    {
      "x": 10,
      "y": 16,
      "z": 1,
      "name": "Rock_Stone"
    },
    {
      "x": 10,
      "y": 17,
      "z": 1,
      "name": "Soil_Dirt"
    },
    {
      "x": 10,
      "y": 18,
      "z": 1,
      "name": "Soil_Dirt"
    },
    {
      "x": 10,
      "y": 19,
      "z": 1,
      "name": "Soil_Dirt"
    },
    {
      "x": 10,
      "y": 20,
      "z": 1,
      "name": "Soil_Grass_Deep"
    },
    {
      "x": 10,
      "y": 8,
      "z": 2,
      "name": "Rock_Stone"
    },
    {
      "x": 10,
      "y": 9,
      "z": 2,
      "name": "Rock_Stone"
    },
    {
      "x": 10,
      "y": 10,
      "z": 2,
      "name": "Rock_Stone"
    },
    {
      "x": 10,
      "y": 11,
      "z": 2,
      "name": "Rock_Stone"
    },
    {
      "x": 10,
      "y": 12,
      "z": 2,
      "name": "Rock_Stone"
    },
    {
      "x": 10,
      "y": 13,
      "z": 2,
      "name": "Rock_Stone"
    },
    {
      "x": 10,
      "y": 14,
      "z": 2,
      "name": "Rock_Stone"
    },
    {
      "x": 10,
      "y": 15,
      "z": 2,
      "name": "Rock_Stone"
    },
    {
      "x": 10,
      "y": 16,
      "z": 2,
      "name": "Rock_Stone"
    },
    {
      "x": 10,
      "y": 17,
      "z": 2,
      "name": "Soil_Dirt"
    },
    {
      "x": 10,
      "y": 18,
      "z": 2,
      "name": "Soil_Dirt"
    },
    {
      "x": 10,
      "y": 19,
      "z": 2,
      "name": "Soil_Dirt"
    },
    {
      "x": 10,
      "y": 20,
      "z": 2,
      "name": "Soil_Grass_Deep"
    },
    {
      "x": 10,
      "y": 7,
      "z": 3,
      "name": "Rock_Stone"
    },
    {
      "x": 10,
      "y": 8,
      "z": 3,
      "name": "Rock_Stone"
    },
    {
      "x": 10,
      "y": 9,
      "z": 3,
      "name": "Rock_Stone"
    },
    {
      "x": 10,
      "y": 10,
      "z": 3,
      "name": "Rock_Stone"
    },
    {
      "x": 10,
      "y": 11,
      "z": 3,
      "name": "Rock_Stone"
    },
    {
      "x": 10,
      "y": 12,
      "z": 3,
      "name": "Rock_Stone"
    },
    {
      "x": 10,
      "y": 13,
      "z": 3,
      "name": "Rock_Stone"
    },
    {
      "x": 10,
      "y": 14,
      "z": 3,
      "name": "Rock_Stone"
    },
    {
      "x": 10,
      "y": 15,
      "z": 3,
      "name": "Rock_Stone"
    },
    {
      "x": 10,
      "y": 16,
      "z": 3,
      "name": "Rock_Stone"
    },
    {
      "x": 10,
      "y": 17,
      "z": 3,
      "name": "Soil_Dirt"
    },
    {
      "x": 10,
      "y": 18,
      "z": 3,
      "name": "Soil_Dirt"
    },
    {
      "x": 10,
      "y": 19,
      "z": 3,
      "name": "Soil_Dirt"
    },
    {
      "x": 10,
      "y": 20,
      "z": 3,
      "name": "Soil_Dirt"
    },
    {
      "x": 10,
      "y": 21,
      "z": 3,
      "name": "Soil_Grass_Deep"
    },
    {
      "x": 10,
      "y": 22,
      "z": 3,
      "name": "Plant_Fern_Winter"
    },
    {
      "x": 10,
      "y": 9,
      "z": 4,
      "name": "Rock_Stone"
    },
    {
      "x": 10,
      "y": 10,
      "z": 4,
      "name": "Rock_Stone"
    },
    {
      "x": 10,
      "y": 11,
      "z": 4,
      "name": "Rock_Stone"
    },
    {
      "x": 10,
      "y": 12,
      "z": 4,
      "name": "Rock_Stone"
    },
    {
      "x": 10,
      "y": 13,
      "z": 4,
      "name": "Rock_Stone"
    },
    {
      "x": 10,
      "y": 14,
      "z": 4,
      "name": "Rock_Stone"
    },
    {
      "x": 10,
      "y": 15,
      "z": 4,
      "name": "Rock_Stone"
    },
    {
      "x": 10,
      "y": 16,
      "z": 4,
      "name": "Rock_Stone"
    },
    {
      "x": 10,
      "y": 17,
      "z": 4,
      "name": "Soil_Dirt"
    },
    {
      "x": 10,
      "y": 18,
      "z": 4,
      "name": "Soil_Dirt"
    },
    {
      "x": 10,
      "y": 19,
      "z": 4,
      "name": "Soil_Dirt"
    },
    {
      "x": 10,
      "y": 20,
      "z": 4,
      "name": "Soil_Dirt"
    },
    {
      "x": 10,
      "y": 21,
      "z": 4,
      "name": "Soil_Grass_Deep"
    },
    {
      "x": 10,
      "y": 11,
      "z": 5,
      "name": "Rock_Stone"
    },
    {
      "x": 10,
      "y": 12,
      "z": 5,
      "name": "Rock_Stone"
    },
    {
      "x": 10,
      "y": 13,
      "z": 5,
      "name": "Rock_Stone"
    },
    {
      "x": 10,
      "y": 14,
      "z": 5,
      "name": "Rock_Stone"
    },
    {
      "x": 10,
      "y": 15,
      "z": 5,
      "name": "Rock_Stone"
    },
    {
      "x": 10,
      "y": 16,
      "z": 5,
      "name": "Rock_Stone"
    },
    {
      "x": 10,
      "y": 17,
      "z": 5,
      "name": "Soil_Dirt"
    },
    {
      "x": 10,
      "y": 18,
      "z": 5,
      "name": "Soil_Dirt"
    },
    {
      "x": 10,
      "y": 19,
      "z": 5,
      "name": "Soil_Dirt"
    },
    {
      "x": 10,
      "y": 20,
      "z": 5,
      "name": "Soil_Grass_Deep"
    },
    {
      "x": 10,
      "y": 15,
      "z": 6,
      "name": "Rock_Stone"
    },
    {
      "x": 10,
      "y": 16,
      "z": 6,
      "name": "Rock_Stone"
    },
    {
      "x": 10,
      "y": 17,
      "z": 6,
      "name": "Soil_Dirt"
    },
    {
      "x": 10,
      "y": 18,
      "z": 6,
      "name": "Soil_Dirt"
    },
    {
      "x": 10,
      "y": 19,
      "z": 6,
      "name": "Soil_Dirt"
    },
    {
      "x": 10,
      "y": 20,
      "z": 6,
      "name": "Soil_Grass_Deep"
    },
    {
      "x": 10,
      "y": 16,
      "z": 7,
      "name": "Rock_Stone"
    },
    {
      "x": 10,
      "y": 17,
      "z": 7,
      "name": "Rock_Stone"
    },
    {
      "x": 11,
      "y": 11,
      "z": 1,
      "name": "Rock_Stone"
    },
    {
      "x": 11,
      "y": 12,
      "z": 1,
      "name": "Rock_Stone"
    },
    {
      "x": 11,
      "y": 13,
      "z": 1,
      "name": "Rock_Stone"
    },
    {
      "x": 11,
      "y": 14,
      "z": 1,
      "name": "Rock_Stone"
    },
    {
      "x": 11,
      "y": 15,
      "z": 1,
      "name": "Rock_Stone"
    },
    {
      "x": 11,
      "y": 16,
      "z": 1,
      "name": "Rock_Stone"
    },
    {
      "x": 11,
      "y": 17,
      "z": 1,
      "name": "Soil_Dirt"
    },
    {
      "x": 11,
      "y": 18,
      "z": 1,
      "name": "Soil_Dirt"
    },
    {
      "x": 11,
      "y": 19,
      "z": 1,
      "name": "Soil_Grass_Deep"
    },
    {
      "x": 11,
      "y": 10,
      "z": 2,
      "name": "Rock_Stone"
    },
    {
      "x": 11,
      "y": 11,
      "z": 2,
      "name": "Rock_Stone"
    },
    {
      "x": 11,
      "y": 12,
      "z": 2,
      "name": "Rock_Stone"
    },
    {
      "x": 11,
      "y": 13,
      "z": 2,
      "name": "Rock_Stone"
    },
    {
      "x": 11,
      "y": 14,
      "z": 2,
      "name": "Rock_Stone"
    },
    {
      "x": 11,
      "y": 15,
      "z": 2,
      "name": "Rock_Stone"
    },
    {
      "x": 11,
      "y": 16,
      "z": 2,
      "name": "Rock_Stone"
    },
    {
      "x": 11,
      "y": 17,
      "z": 2,
      "name": "Soil_Dirt"
    },
    {
      "x": 11,
      "y": 18,
      "z": 2,
      "name": "Soil_Dirt"
    },
    {
      "x": 11,
      "y": 19,
      "z": 2,
      "name": "Soil_Dirt"
    },
    {
      "x": 11,
      "y": 20,
      "z": 2,
      "name": "Soil_Grass_Deep"
    },
    {
      "x": 11,
      "y": 11,
      "z": 3,
      "name": "Rock_Stone"
    },
    {
      "x": 11,
      "y": 12,
      "z": 3,
      "name": "Rock_Stone"
    },
    {
      "x": 11,
      "y": 13,
      "z": 3,
      "name": "Rock_Stone"
    },
    {
      "x": 11,
      "y": 14,
      "z": 3,
      "name": "Rock_Stone"
    },
    {
      "x": 11,
      "y": 15,
      "z": 3,
      "name": "Rock_Stone"
    },
    {
      "x": 11,
      "y": 16,
      "z": 3,
      "name": "Soil_Dirt"
    },
    {
      "x": 11,
      "y": 17,
      "z": 3,
      "name": "Soil_Dirt"
    },
    {
      "x": 11,
      "y": 18,
      "z": 3,
      "name": "Soil_Dirt"
    },
    {
      "x": 11,
      "y": 19,
      "z": 3,
      "name": "Soil_Dirt"
    },
    {
      "x": 11,
      "y": 20,
      "z": 3,
      "name": "Soil_Grass_Deep"
    },
    {
      "x": 11,
      "y": 11,
      "z": 4,
      "name": "Rock_Stone"
    },
    {
      "x": 11,
      "y": 12,
      "z": 4,
      "name": "Rock_Stone"
    },
    {
      "x": 11,
      "y": 13,
      "z": 4,
      "name": "Rock_Stone"
    },
    {
      "x": 11,
      "y": 14,
      "z": 4,
      "name": "Rock_Stone"
    },
    {
      "x": 11,
      "y": 15,
      "z": 4,
      "name": "Rock_Stone"
    },
    {
      "x": 11,
      "y": 16,
      "z": 4,
      "name": "Rock_Stone"
    },
    {
      "x": 11,
      "y": 17,
      "z": 4,
      "name": "Soil_Dirt"
    },
    {
      "x": 11,
      "y": 18,
      "z": 4,
      "name": "Soil_Dirt"
    },
    {
      "x": 11,
      "y": 19,
      "z": 4,
      "name": "Soil_Dirt"
    },
    {
      "x": 11,
      "y": 20,
      "z": 4,
      "name": "Soil_Grass_Deep"
    },
    {
      "x": 11,
      "y": 13,
      "z": 5,
      "name": "Rock_Stone"
    },
    {
      "x": 11,
      "y": 14,
      "z": 5,
      "name": "Rock_Stone"
    },
    {
      "x": 11,
      "y": 15,
      "z": 5,
      "name": "Rock_Stone"
    },
    {
      "x": 11,
      "y": 16,
      "z": 5,
      "name": "Rock_Stone"
    },
    {
      "x": 11,
      "y": 17,
      "z": 5,
      "name": "Soil_Dirt"
    },
    {
      "x": 11,
      "y": 18,
      "z": 5,
      "name": "Soil_Dirt"
    },
    {
      "x": 11,
      "y": 19,
      "z": 5,
      "name": "Soil_Dirt"
    },
    {
      "x": 11,
      "y": 20,
      "z": 5,
      "name": "Soil_Grass_Deep"
    },
    {
      "x": 11,
      "y": 14,
      "z": 6,
      "name": "Rock_Stone"
    },
    {
      "x": 11,
      "y": 15,
      "z": 6,
      "name": "Rock_Stone"
    },
    {
      "x": 11,
      "y": 16,
      "z": 6,
      "name": "Rock_Stone"
    },
    {
      "x": 11,
      "y": 17,
      "z": 6,
      "name": "Rock_Stone"
    },
    {
      "x": 11,
      "y": 18,
      "z": 6,
      "name": "Soil_Grass_Deep"
    },
    {
      "x": 12,
      "y": 13,
      "z": 1,
      "name": "Rock_Stone"
    },
    {
      "x": 12,
      "y": 14,
      "z": 1,
      "name": "Rock_Stone"
    },
    {
      "x": 12,
      "y": 15,
      "z": 1,
      "name": "Rock_Stone"
    },
    {
      "x": 12,
      "y": 12,
      "z": 2,
      "name": "Rock_Stone"
    },
    {
      "x": 12,
      "y": 13,
      "z": 2,
      "name": "Rock_Stone"
    },
    {
      "x": 12,
      "y": 14,
      "z": 2,
      "name": "Rock_Stone"
    },
    {
      "x": 12,
      "y": 15,
      "z": 2,
      "name": "Rock_Stone"
    },
    {
      "x": 12,
      "y": 16,
      "z": 2,
      "name": "Rock_Stone"
    },
    {
      "x": 12,
      "y": 17,
      "z": 2,
      "name": "Soil_Grass"
    },
    {
      "x": 12,
      "y": 12,
      "z": 3,
      "name": "Rock_Stone"
    },
    {
      "x": 12,
      "y": 13,
      "z": 3,
      "name": "Rock_Stone"
    },
    {
      "x": 12,
      "y": 14,
      "z": 3,
      "name": "Rock_Stone"
    },
    {
      "x": 12,
      "y": 15,
      "z": 3,
      "name": "Rock_Stone"
    },
    {
      "x": 12,
      "y": 16,
      "z": 3,
      "name": "Rock_Stone"
    },
    {
      "x": 12,
      "y": 17,
      "z": 3,
      "name": "Soil_Dirt"
    },
    {
      "x": 12,
      "y": 18,
      "z": 3,
      "name": "Soil_Grass_Deep"
    },
    {
      "x": 12,
      "y": 13,
      "z": 4,
      "name": "Rock_Stone"
    },
    {
      "x": 12,
      "y": 14,
      "z": 4,
      "name": "Rock_Stone"
    },
    {
      "x": 12,
      "y": 15,
      "z": 4,
      "name": "Rock_Stone"
    },
    {
      "x": 12,
      "y": 16,
      "z": 4,
      "name": "Rock_Stone"
    },
    {
      "x": 12,
      "y": 17,
      "z": 4,
      "name": "Soil_Dirt"
    },
    {
      "x": 12,
      "y": 18,
      "z": 4,
      "name": "Soil_Grass_Deep"
    },
    {
      "x": 12,
      "y": 15,
      "z": 5,
      "name": "Rock_Stone"
    },
    {
      "x": 12,
      "y": 16,
      "z": 5,
      "name": "Rock_Stone"
    },
    {
      "x": 12,
      "y": 17,
      "z": 5,
      "name": "Soil_Dirt"
    },
    {
      "x": 12,
      "y": 18,
      "z": 5,
      "name": "Soil_Grass_Deep"
    },
    {
      "x": 12,
      "y": 19,
      "z": 5,
      "name": "Plant_Flower_Common_Violet"
    },
    {
      "x": 12,
      "y": 17,
      "z": 6,
      "name": "Rock_Stone"
    },
    {
      "x": 13,
      "y": 14,
      "z": 3,
      "name": "Rock_Stone"
    },
    {
      "x": 13,
      "y": 15,
      "z": 3,
      "name": "Rock_Stone"
    },
    {
      "x": 13,
      "y": 16,
      "z": 3,
      "name": "Rock_Stone"
    },
    {
      "x": 13,
      "y": 14,
      "z": 4,
      "name": "Rock_Stone"
    },
    {
      "x": 13,
