{
  "version": 8,
  "blockIdVersion": 8,
  "anchorX": 9,
  "anchorY": 6,
  "anchorZ": 9,
  "blocks": [
    {
      "x": 2,
      "y": 7,
      "z": 7,
      "name": "Rock_Calcite"
    },
    {
      "x": 2,
      "y": 8,
      "z": 7,
      "name": "Rock_Calcite"
    },
    {
      "x": 2,
      "y": 9,
      "z": 7,
      "name": "Rock_Calcite"
    },
    {
      "x": 2,
      "y": 10,
      "z": 7,
      "name": "Rock_Calcite"
    },
    {
      "x": 2,
      "y": 11,
      "z": 7,
      "name": "Rock_Calcite"
    },
    {
      "x": 2,
      "y": 4,
      "z": 8,
      "name": "Rock_Calcite"
    },
    {
      "x": 2,
      "y": 5,
      "z": 8,
      "name": "Rock_Calcite"
    },
    {
      "x": 2,
      "y": 6,
      "z": 8,
      "name": "Rock_Calcite"
    },
    {
      "x": 2,
      "y": 7,
      "z": 8,
      "name": "Rock_Calcite"
    },
    {
      "x": 2,
      "y": 8,
      "z": 8,
      "name": "Rock_Calcite"
    },
    {
      "x": 2,
      "y": 9,
      "z": 8,
      "name": "Rock_Calcite"
    },
    {
      "x": 2,
      "y": 10,
      "z": 8,
      "name": "Rock_Calcite"
    },
    {
      "x": 2,
      "y": 11,
      "z": 8,
      "name": "Rock_Calcite"
    },
    {
      "x": 2,
      "y": 5,
      "z": 9,
      "name": "Rock_Calcite"
    },
    {
      "x": 2,
      "y": 6,
      "z": 9,
      "name": "Rock_Calcite"
    },
    {
      "x": 2,
      "y": 7,
      "z": 9,
      "name": "Rock_Calcite"
    },
    {
      "x": 2,
      "y": 8,
      "z": 9,
      "name": "Rock_Calcite"
    },
    {
      "x": 2,
      "y": 9,
      "z": 9,
      "name": "Rock_Calcite"
    },
    {
      "x": 2,
      "y": 10,
      "z": 9,
      "name": "Rock_Calcite"
    },
    {
      "x": 2,
      "y": 11,
      "z": 9,
      "name": "Rock_Calcite"
    },
    {
      "x": 3,
      "y": 3,
      "z": 6,
      "name": "Rock_Calcite"
    },
    {
      "x": 3,
      "y": 4,
      "z": 6,
      "name": "Rock_Calcite"
    },
    {
      "x": 3,
      "y": 5,
      "z": 6,
      "name": "Rock_Calcite"
    },
    {
      "x": 3,
      "y": 6,
      "z": 6,
      "name": "Rock_Calcite"
    },
    {
      "x": 3,
      "y": 7,
      "z": 6,
      "name": "Rock_Calcite"
    },
    {
      "x": 3,
      "y": 8,
      "z": 6,
      "name": "Rock_Calcite"
    },
    {
      "x": 3,
      "y": 9,
      "z": 6,
      "name": "Rock_Calcite"
    },
    {
      "x": 3,
      "y": 10,
      "z": 6,
      "name": "Rock_Calcite"
    },
    {
      "x": 3,
      "y": 11,
      "z": 6,
      "name": "Rock_Calcite"
    },
    {
      "x": 3,
      "y": 2,
      "z": 7,
      "name": "Rock_Calcite"
    },
    {
      "x": 3,
      "y": 3,
      "z": 7,
      "name": "Rock_Calcite"
    },
    {
      "x": 3,
      "y": 4,
      "z": 7,
      "name": "Rock_Calcite"
    },
    {
      "x": 3,
      "y": 5,
      "z": 7,
      "name": "Rock_Calcite"
    },
    {
      "x": 3,
      "y": 6,
      "z": 7,
      "name": "Rock_Calcite"
    },
    {
      "x": 3,
      "y": 7,
      "z": 7,
      "name": "Rock_Calcite"
    },
    {
      "x": 3,
      "y": 8,
      "z": 7,
      "name": "Rock_Calcite"
    },
    {
      "x": 3,
      "y": 9,
      "z": 7,
      "name": "Rock_Calcite"
    },
    {
      "x": 3,
      "y": 10,
      "z": 7,
      "name": "Rock_Calcite"
    },
    {
      "x": 3,
      "y": 11,
      "z": 7,
      "name": "Rock_Calcite"
    },
    {
      "x": 3,
      "y": 1,
      "z": 8,
      "name": "Rock_Calcite"
    },
    {
      "x": 3,
      "y": 2,
      "z": 8,
      "name": "Rock_Calcite"
    },
    {
      "x": 3,
      "y": 3,
      "z": 8,
      "name": "Rock_Calcite"
    },
    {
      "x": 3,
      "y": 4,
      "z": 8,
      "name": "Rock_Calcite"
    },
    {
      "x": 3,
      "y": 5,
      "z": 8,
      "name": "Rock_Calcite"
    },
    {
      "x": 3,
      "y": 6,
      "z": 8,
      "name": "Rock_Calcite"
    },
    {
      "x": 3,
      "y": 7,
      "z": 8,
      "name": "Rock_Calcite"
    },
    {
      "x": 3,
      "y": 8,
      "z": 8,
      "name": "Rock_Calcite"
    },
    {
      "x": 3,
      "y": 9,
      "z": 8,
      "name": "Rock_Calcite"
    },
    {
      "x": 3,
      "y": 10,
      "z": 8,
      "name": "Rock_Calcite"
    },
    {
      "x": 3,
      "y": 11,
      "z": 8,
      "name": "Rock_Calcite"
    },
    {
      "x": 3,
      "y": 1,
      "z": 9,
      "name": "Rock_Calcite"
    },
    {
      "x": 3,
      "y": 2,
      "z": 9,
      "name": "Rock_Calcite"
    },
    {
      "x": 3,
      "y": 3,
      "z": 9,
      "name": "Rock_Calcite"
    },
    {
      "x": 3,
      "y": 4,
      "z": 9,
      "name": "Rock_Calcite"
    },
    {
      "x": 3,
      "y": 5,
      "z": 9,
      "name": "Rock_Calcite"
    },
    {
      "x": 3,
      "y": 6,
      "z": 9,
      "name": "Rock_Calcite"
    },
    {
      "x": 3,
      "y": 7,
      "z": 9,
      "name": "Rock_Calcite"
    },
    {
      "x": 3,
      "y": 8,
      "z": 9,
      "name": "Rock_Calcite"
    },
    {
      "x": 3,
      "y": 9,
      "z": 9,
      "name": "Rock_Calcite"
    },
    {
      "x": 3,
      "y": 10,
      "z": 9,
      "name": "Rock_Calcite"
    },
    {
      "x": 3,
      "y": 11,
      "z": 9,
      "name": "Rock_Calcite"
    },
    {
      "x": 3,
      "y": 1,
      "z": 10,
      "name": "Rock_Calcite"
    },
    {
      "x": 3,
      "y": 2,
      "z": 10,
      "name": "Rock_Calcite"
    },
    {
      "x": 3,
      "y": 3,
      "z": 10,
      "name": "Rock_Calcite"
    },
    {
      "x": 3,
      "y": 4,
      "z": 10,
      "name": "Rock_Calcite"
    },
    {
      "x": 3,
      "y": 5,
      "z": 10,
      "name": "Rock_Calcite"
    },
    {
      "x": 3,
      "y": 6,
      "z": 10,
      "name": "Rock_Calcite"
    },
    {
      "x": 3,
      "y": 7,
      "z": 10,
      "name": "Rock_Calcite"
    },
    {
      "x": 3,
      "y": 8,
      "z": 10,
      "name": "Rock_Calcite"
    },
    {
      "x": 3,
      "y": 9,
      "z": 10,
      "name": "Rock_Calcite"
    },
    {
      "x": 3,
      "y": 10,
      "z": 10,
      "name": "Rock_Calcite"
    },
    {
      "x": 3,
      "y": 11,
      "z": 10,
      "name": "Rock_Calcite"
    },
    {
      "x": 3,
      "y": 3,
      "z": 11,
      "name": "Rock_Calcite"
    },
    {
      "x": 3,
      "y": 4,
      "z": 11,
      "name": "Rock_Calcite"
    },
    {
      "x": 3,
      "y": 5,
      "z": 11,
      "name": "Rock_Calcite"
    },
    {
      "x": 3,
      "y": 6,
      "z": 11,
      "name": "Rock_Calcite"
    },
    {
      "x": 3,
      "y": 7,
      "z": 11,
      "name": "Rock_Calcite"
    },
    {
      "x": 3,
      "y": 8,
      "z": 11,
      "name": "Rock_Calcite"
    },
    {
      "x": 3,
      "y": 9,
      "z": 11,
      "name": "Rock_Calcite"
    },
    {
      "x": 3,
      "y": 10,
      "z": 11,
      "name": "Rock_Calcite"
    },
    {
      "x": 3,
      "y": 11,
      "z": 11,
      "name": "Rock_Calcite"
    },
    {
      "x": 3,
      "y": 12,
      "z": 11,
      "name": "Rock_Calcite"
    },
    {
      "x": 3,
      "y": 8,
      "z": 12,
      "name": "Rock_Calcite"
    },
    {
      "x": 3,
      "y": 9,
      "z": 12,
      "name": "Rock_Calcite"
    },
    {
      "x": 3,
      "y": 10,
      "z": 12,
      "name": "Rock_Calcite"
    },
    {
      "x": 3,
      "y": 11,
      "z": 12,
      "name": "Rock_Calcite"
    },
    {
      "x": 3,
      "y": 12,
      "z": 12,
      "name": "Rock_Calcite"
    },
    {
      "x": 4,
      "y": 3,
      "z": 5,
      "name": "Rock_Calcite"
    },
    {
      "x": 4,
      "y": 4,
      "z": 5,
      "name": "Rock_Calcite"
    },
    {
      "x": 4,
      "y": 5,
      "z": 5,
      "name": "Rock_Calcite"
    },
    {
      "x": 4,
      "y": 6,
      "z": 5,
      "name": "Rock_Calcite"
    },
    {
      "x": 4,
      "y": 7,
      "z": 5,
      "name": "Rock_Calcite"
    },
    {
      "x": 4,
      "y": 8,
      "z": 5,
      "name": "Rock_Calcite"
    },
    {
      "x": 4,
      "y": 9,
      "z": 5,
      "name": "Rock_Calcite"
    },
    {
      "x": 4,
      "y": 10,
      "z": 5,
      "name": "Rock_Calcite"
    },
    {
      "x": 4,
      "y": 11,
      "z": 5,
      "name": "Rock_Calcite"
    },
    {
      "x": 4,
      "y": 1,
      "z": 6,
      "name": "Rock_Calcite"
    },
    {
      "x": 4,
      "y": 2,
      "z": 6,
      "name": "Rock_Calcite"
    },
    {
      "x": 4,
      "y": 3,
      "z": 6,
      "name": "Rock_Calcite"
    },
    {
      "x": 4,
      "y": 4,
      "z": 6,
      "name": "Rock_Calcite"
    },
    {
      "x": 4,
      "y": 5,
      "z": 6,
      "name": "Rock_Calcite"
    },
    {
      "x": 4,
      "y": 6,
      "z": 6,
      "name": "Rock_Calcite"
    },
    {
      "x": 4,
      "y": 7,
      "z": 6,
      "name": "Rock_Calcite"
    },
    {
      "x": 4,
      "y": 8,
      "z": 6,
      "name": "Rock_Calcite"
    },
    {
      "x": 4,
      "y": 9,
      "z": 6,
      "name": "Rock_Calcite"
    },
    {
      "x": 4,
      "y": 10,
      "z": 6,
      "name": "Rock_Calcite"
    },
    {
      "x": 4,
      "y": 11,
      "z": 6,
      "name": "Rock_Calcite"
    },
    {
      "x": 4,
      "y": 1,
      "z": 7,
      "name": "Rock_Calcite"
    },
    {
      "x": 4,
      "y": 2,
      "z": 7,
      "name": "Rock_Calcite"
    },
    {
      "x": 4,
      "y": 3,
      "z": 7,
      "name": "Rock_Calcite"
    },
    {
      "x": 4,
      "y": 4,
      "z": 7,
      "name": "Rock_Calcite"
    },
    {
      "x": 4,
      "y": 5,
      "z": 7,
      "name": "Rock_Calcite"
    },
    {
      "x": 4,
      "y": 6,
      "z": 7,
      "name": "Rock_Calcite"
    },
    {
      "x": 4,
      "y": 7,
      "z": 7,
      "name": "Rock_Calcite"
    },
    {
      "x": 4,
      "y": 8,
      "z": 7,
      "name": "Rock_Calcite"
    },
    {
      "x": 4,
      "y": 9,
      "z": 7,
      "name": "Rock_Calcite"
    },
    {
      "x": 4,
      "y": 10,
      "z": 7,
      "name": "Rock_Calcite"
    },
    {
      "x": 4,
      "y": 11,
      "z": 7,
      "name": "Rock_Calcite"
    },
    {
      "x": 4,
      "y": 1,
      "z": 8,
      "name": "Rock_Calcite"
    },
    {
      "x": 4,
      "y": 2,
      "z": 8,
      "name": "Rock_Calcite"
    },
    {
      "x": 4,
      "y": 3,
      "z": 8,
      "name": "Rock_Calcite"
    },
    {
      "x": 4,
      "y": 4,
      "z": 8,
      "name": "Rock_Calcite"
    },
    {
      "x": 4,
      "y": 5,
      "z": 8,
      "name": "Rock_Calcite"
    },
    {
      "x": 4,
      "y": 6,
      "z": 8,
      "name": "Rock_Calcite"
    },
    {
      "x": 4,
      "y": 7,
      "z": 8,
      "name": "Rock_Calcite"
    },
    {
      "x": 4,
      "y": 8,
      "z": 8,
      "name": "Rock_Calcite"
    },
    {
      "x": 4,
      "y": 9,
      "z": 8,
      "name": "Rock_Calcite"
    },
    {
      "x": 4,
      "y": 10,
      "z": 8,
      "name": "Rock_Calcite"
    },
    {
      "x": 4,
      "y": 11,
      "z": 8,
      "name": "Rock_Calcite"
    },
    {
      "x": 4,
      "y": 1,
      "z": 9,
      "name": "Rock_Calcite"
    },
    {
      "x": 4,
      "y": 2,
      "z": 9,
      "name": "Rock_Calcite"
    },
    {
      "x": 4,
      "y": 3,
      "z": 9,
      "name": "Rock_Calcite"
    },
    {
      "x": 4,
      "y": 4,
      "z": 9,
      "name": "Rock_Calcite"
    },
    {
      "x": 4,
      "y": 5,
      "z": 9,
      "name": "Rock_Calcite"
    },
    {
      "x": 4,
      "y": 6,
      "z": 9,
      "name": "Rock_Calcite"
    },
    {
      "x": 4,
      "y": 7,
      "z": 9,
      "name": "Rock_Calcite"
    },
    {
      "x": 4,
      "y": 8,
      "z": 9,
      "name": "Rock_Calcite"
    },
    {
      "x": 4,
      "y": 9,
      "z": 9,
      "name": "Rock_Calcite"
    },
    {
      "x": 4,
      "y": 10,
      "z": 9,
      "name": "Rock_Calcite"
    },
    {
      "x": 4,
      "y": 11,
      "z": 9,
      "name": "Rock_Calcite"
    },
    {
      "x": 4,
      "y": 1,
      "z": 10,
      "name": "Rock_Calcite"
    },
    {
      "x": 4,
      "y": 2,
      "z": 10,
      "name": "Rock_Calcite"
    },
    {
      "x": 4,
      "y": 3,
      "z": 10,
      "name": "Rock_Calcite"
    },
    {
      "x": 4,
      "y": 4,
      "z": 10,
      "name": "Rock_Calcite"
    },
    {
      "x": 4,
      "y": 5,
      "z": 10,
      "name": "Rock_Calcite"
    },
    {
      "x": 4,
      "y": 6,
      "z": 10,
      "name": "Rock_Calcite"
    },
    {
      "x": 4,
      "y": 7,
      "z": 10,
      "name": "Rock_Calcite"
    },
    {
      "x": 4,
      "y": 8,
      "z": 10,
      "name": "Rock_Calcite"
    },
    {
      "x": 4,
      "y": 9,
      "z": 10,
      "name": "Rock_Calcite"
    },
    {
      "x": 4,
      "y": 10,
      "z": 10,
      "name": "Rock_Calcite"
    },
    {
      "x": 4,
      "y": 11,
      "z": 10,
      "name": "Rock_Calcite"
    },
    {
      "x": 4,
      "y": 1,
      "z": 11,
      "name": "Rock_Calcite"
    },
    {
      "x": 4,
      "y": 2,
      "z": 11,
      "name": "Rock_Calcite"
    },
    {
      "x": 4,
      "y": 3,
      "z": 11,
      "name": "Rock_Calcite"
    },
    {
      "x": 4,
      "y": 4,
      "z": 11,
      "name": "Rock_Calcite"
    },
    {
      "x": 4,
      "y": 5,
      "z": 11,
      "name": "Rock_Calcite"
    },
    {
      "x": 4,
      "y": 6,
      "z": 11,
      "name": "Rock_Calcite"
    },
    {
      "x": 4,
      "y": 7,
      "z": 11,
      "name": "Rock_Calcite"
    },
    {
      "x": 4,
      "y": 8,
      "z": 11,
      "name": "Rock_Calcite"
    },
    {
      "x": 4,
      "y": 9,
      "z": 11,
      "name": "Rock_Calcite"
    },
    {
      "x": 4,
      "y": 10,
      "z": 11,
      "name": "Rock_Calcite"
    },
    {
      "x": 4,
      "y": 11,
      "z": 11,
      "name": "Rock_Calcite"
    },
    {
      "x": 4,
      "y": 12,
      "z": 11,
      "name": "Rock_Calcite"
    },
    {
      "x": 4,
      "y": 3,
      "z": 12,
      "name": "Rock_Calcite"
    },
    {
      "x": 4,
      "y": 4,
      "z": 12,
      "name": "Rock_Calcite"
    },
    {
      "x": 4,
      "y": 5,
      "z": 12,
      "name": "Rock_Calcite"
    },
    {
      "x": 4,
      "y": 6,
      "z": 12,
      "name": "Rock_Calcite"
    },
    {
      "x": 4,
      "y": 7,
      "z": 12,
      "name": "Rock_Calcite"
    },
    {
      "x": 4,
      "y": 8,
      "z": 12,
      "name": "Rock_Calcite"
    },
    {
      "x": 4,
      "y": 9,
      "z": 12,
      "name": "Rock_Calcite"
    },
    {
      "x": 4,
      "y": 10,
      "z": 12,
      "name": "Rock_Calcite"
    },
    {
      "x": 4,
      "y": 11,
      "z": 12,
      "name": "Rock_Calcite"
    },
    {
      "x": 4,
      "y": 12,
      "z": 12,
      "name": "Rock_Calcite"
    },
    {
      "x": 5,
      "y": 1,
      "z": 5,
      "name": "Rock_Calcite"
    },
    {
      "x": 5,
      "y": 2,
      "z": 5,
      "name": "Rock_Calcite"
    },
    {
      "x": 5,
      "y": 3,
      "z": 5,
      "name": "Rock_Calcite"
    },
    {
      "x": 5,
      "y": 4,
      "z": 5,
      "name": "Rock_Calcite"
    },
    {
      "x": 5,
      "y": 5,
      "z": 5,
      "name": "Rock_Calcite"
    },
    {
      "x": 5,
      "y": 6,
      "z": 5,
      "name": "Rock_Calcite"
    },
    {
      "x": 5,
      "y": 7,
      "z": 5,
      "name": "Rock_Calcite"
    },
    {
      "x": 5,
      "y": 8,
      "z": 5,
      "name": "Rock_Calcite"
    },
    {
      "x": 5,
      "y": 9,
      "z": 5,
      "name": "Rock_Calcite"
    },
    {
      "x": 5,
      "y": 10,
      "z": 5,
      "name": "Rock_Calcite"
    },
    {
      "x": 5,
      "y": 11,
      "z": 5,
      "name": "Rock_Calcite"
    },
    {
      "x": 5,
      "y": 1,
      "z": 6,
      "name": "Rock_Calcite"
    },
    {
      "x": 5,
      "y": 2,
      "z": 6,
      "name": "Rock_Calcite"
    },
    {
      "x": 5,
      "y": 3,
      "z": 6,
      "name": "Rock_Calcite"
    },
    {
      "x": 5,
      "y": 4,
      "z": 6,
      "name": "Rock_Calcite"
    },
    {
      "x": 5,
      "y": 5,
      "z": 6,
      "name": "Rock_Calcite"
    },
    {
      "x": 5,
      "y": 6,
      "z": 6,
      "name": "Rock_Calcite"
    },
    {
      "x": 5,
      "y": 7,
      "z": 6,
      "name": "Rock_Calcite"
    },
    {
      "x": 5,
      "y": 8,
      "z": 6,
      "name": "Rock_Calcite"
    },
    {
      "x": 5,
      "y": 9,
      "z": 6,
      "name": "Rock_Calcite"
    },
    {
      "x": 5,
      "y": 10,
      "z": 6,
      "name": "Rock_Calcite"
    },
    {
      "x": 5,
      "y": 11,
      "z": 6,
      "name": "Rock_Calcite"
    },
    {
      "x": 5,
      "y": 1,
      "z": 7,
      "name": "Rock_Calcite"
    },
    {
      "x": 5,
      "y": 2,
      "z": 7,
      "name": "Rock_Calcite"
    },
    {
      "x": 5,
      "y": 3,
      "z": 7,
      "name": "Rock_Calcite"
    },
    {
      "x": 5,
      "y": 4,
      "z": 7,
      "name": "Rock_Calcite"
    },
    {
      "x": 5,
      "y": 5,
      "z": 7,
      "name": "Rock_Calcite"
    },
    {
      "x": 5,
      "y": 6,
      "z": 7,
      "name": "Rock_Calcite"
    },
    {
      "x": 5,
      "y": 7,
      "z": 7,
      "name": "Rock_Calcite"
    },
    {
      "x": 5,
      "y": 8,
      "z": 7,
      "name": "Rock_Calcite"
    },
    {
      "x": 5,
      "y": 9,
      "z": 7,
      "name": "Rock_Calcite"
    },
    {
      "x": 5,
      "y": 10,
      "z": 7,
      "name": "Rock_Calcite"
    },
    {
      "x": 5,
      "y": 11,
      "z": 7,
      "name": "Rock_Calcite"
    },
    {
      "x": 5,
      "y": 1,
      "z": 8,
      "name": "Rock_Calcite"
    },
    {
      "x": 5,
      "y": 2,
      "z": 8,
      "name": "Rock_Calcite"
    },
    {
      "x": 5,
      "y": 3,
      "z": 8,
      "name": "Rock_Calcite"
    },
    {
      "x": 5,
      "y": 4,
      "z": 8,
      "name": "Rock_Calcite"
    },
    {
      "x": 5,
      "y": 5,
      "z": 8,
      "name": "Rock_Calcite"
    },
    {
      "x": 5,
      "y": 6,
      "z": 8,
      "name": "Rock_Calcite"
    },
    {
      "x": 5,
      "y": 7,
      "z": 8,
      "name": "Rock_Calcite"
    },
    {
      "x": 5,
      "y": 8,
      "z": 8,
      "name": "Rock_Calcite"
    },
    {
      "x": 5,
      "y": 9,
      "z": 8,
      "name": "Rock_Calcite"
    },
    {
      "x": 5,
      "y": 10,
      "z": 8,
      "name": "Rock_Calcite"
    },
    {
      "x": 5,
      "y": 11,
      "z": 8,
      "name": "Rock_Calcite"
    },
    {
      "x": 5,
      "y": 1,
      "z": 9,
      "name": "Rock_Calcite"
    },
    {
      "x": 5,
      "y": 2,
      "z": 9,
      "name": "Rock_Calcite"
    },
    {
      "x": 5,
      "y": 3,
      "z": 9,
      "name": "Rock_Calcite"
    },
    {
      "x": 5,
      "y": 4,
      "z": 9,
      "name": "Rock_Calcite"
    },
    {
      "x": 5,
      "y": 5,
      "z": 9,
      "name": "Rock_Calcite"
    },
    {
      "x": 5,
      "y": 6,
      "z": 9,
      "name": "Rock_Calcite"
    },
    {
      "x": 5,
      "y": 7,
      "z": 9,
      "name": "Rock_Calcite"
    },
    {
      "x": 5,
      "y": 8,
      "z": 9,
      "name": "Rock_Calcite"
    },
    {
      "x": 5,
      "y": 9,
      "z": 9,
      "name": "Rock_Calcite"
    },
    {
      "x": 5,
      "y": 10,
      "z": 9,
      "name": "Rock_Calcite"
    },
    {
      "x": 5,
      "y": 11,
      "z": 9,
      "name": "Rock_Calcite"
    },
    {
      "x": 5,
      "y": 1,
      "z": 10,
      "name": "Rock_Calcite"
    },
    {
      "x": 5,
      "y": 2,
      "z": 10,
      "name": "Rock_Calcite"
    },
    {
      "x": 5,
      "y": 3,
      "z": 10,
      "name": "Rock_Calcite"
    },
    {
      "x": 5,
      "y": 4,
      "z": 10,
      "name": "Rock_Calcite"
    },
    {
      "x": 5,
      "y": 5,
      "z": 10,
      "name": "Rock_Calcite"
    },
    {
      "x": 5,
      "y": 6,
      "z": 10,
      "name": "Rock_Calcite"
    },
    {
      "x": 5,
      "y": 7,
      "z": 10,
      "name": "Rock_Calcite"
    },
    {
      "x": 5,
      "y": 8,
      "z": 10,
      "name": "Rock_Calcite"
    },
    {
      "x": 5,
      "y": 9,
      "z": 10,
      "name": "Rock_Calcite"
    },
    {
      "x": 5,
      "y": 10,
      "z": 10,
      "name": "Rock_Calcite"
    },
    {
      "x": 5,
      "y": 11,
      "z": 10,
      "name": "Rock_Calcite"
    },
    {
      "x": 5,
      "y": 12,
      "z": 10,
      "name": "Rock_Calcite"
    },
    {
      "x": 5,
      "y": 1,
      "z": 11,
      "name": "Rock_Calcite"
    },
    {
      "x": 5,
      "y": 2,
      "z": 11,
      "name": "Rock_Calcite"
    },
    {
      "x": 5,
      "y": 3,
      "z": 11,
      "name": "Rock_Calcite"
    },
    {
      "x": 5,
      "y": 4,
      "z": 11,
      "name": "Rock_Calcite"
    },
    {
      "x": 5,
      "y": 5,
      "z": 11,
      "name": "Rock_Calcite"
    },
    {
      "x": 5,
      "y": 6,
      "z": 11,
      "name": "Rock_Calcite"
    },
    {
      "x": 5,
      "y": 7,
      "z": 11,
      "name": "Rock_Calcite"
    },
    {
      "x": 5,
      "y": 8,
      "z": 11,
      "name": "Rock_Calcite"
    },
    {
      "x": 5,
      "y": 9,
      "z": 11,
      "name": "Rock_Calcite"
    },
    {
      "x": 5,
      "y": 10,
      "z": 11,
      "name": "Rock_Calcite"
    },
    {
      "x": 5,
      "y": 11,
      "z": 11,
      "name": "Rock_Calcite"
    },
    {
      "x": 5,
      "y": 12,
      "z": 11,
      "name": "Rock_Calcite"
    },
    {
      "x": 5,
      "y": 2,
      "z": 12,
      "name": "Rock_Calcite"
    },
    {
      "x": 5,
      "y": 3,
      "z": 12,
      "name": "Rock_Calcite"
    },
    {
      "x": 5,
      "y": 4,
      "z": 12,
      "name": "Rock_Calcite"
    },
    {
      "x": 5,
      "y": 5,
      "z": 12,
      "name": "Rock_Calcite"
    },
    {
      "x": 5,
      "y": 6,
      "z": 12,
      "name": "Rock_Calcite"
    },
    {
      "x": 5,
      "y": 7,
      "z": 12,
      "name": "Rock_Calcite"
    },
    {
      "x": 5,
      "y": 8,
      "z": 12,
      "name": "Rock_Calcite"
    },
    {
      "x": 5,
      "y": 9,
      "z": 12,
      "name": "Rock_Calcite"
    },
    {
      "x": 5,
      "y": 10,
      "z": 12,
      "name": "Rock_Calcite"
    },
    {
      "x": 5,
      "y": 11,
      "z": 12,
      "name": "Rock_Calcite"
    },
    {
      "x": 5,
      "y": 12,
      "z": 12,
      "name": "Rock_Calcite"
    },
    {
      "x": 6,
      "y": 3,
      "z": 4,
      "name": "Rock_Calcite"
    },
    {
      "x": 6,
      "y": 4,
      "z": 4,
      "name": "Rock_Calcite"
    },
    {
      "x": 6,
      "y": 5,
      "z": 4,
      "name": "Rock_Calcite"
    },
    {
      "x": 6,
      "y": 6,
      "z": 4,
      "name": "Rock_Calcite"
    },
    {
      "x": 6,
      "y": 7,
      "z": 4,
      "name": "Rock_Calcite"
    },
    {
      "x": 6,
      "y": 8,
      "z": 4,
      "name": "Rock_Calcite"
    },
    {
      "x": 6,
      "y": 9,
      "z": 4,
      "name": "Rock_Calcite"
    },
    {
      "x": 6,
      "y": 10,
      "z": 4,
      "name": "Rock_Calcite"
    },
    {
      "x": 6,
      "y": 11,
      "z": 4,
      "name": "Rock_Calcite"
    },
    {
      "x": 6,
      "y": 1,
      "z": 5,
      "name": "Rock_Calcite"
    },
    {
      "x": 6,
      "y": 2,
      "z": 5,
      "name": "Rock_Calcite"
    },
    {
      "x": 6,
      "y": 3,
      "z": 5,
      "name": "Rock_Calcite"
    },
    {
      "x": 6,
      "y": 4,
      "z": 5,
      "name": "Rock_Calcite"
    },
    {
      "x": 6,
      "y": 5,
      "z": 5,
      "name": "Rock_Calcite"
    },
    {
      "x": 6,
      "y": 6,
      "z": 5,
      "name": "Rock_Calcite"
    },
    {
      "x": 6,
      "y": 7,
      "z": 5,
      "name": "Rock_Calcite"
    },
    {
      "x": 6,
      "y": 8,
      "z": 5,
      "name": "Rock_Calcite"
    },
    {
      "x": 6,
      "y": 9,
      "z": 5,
      "name": "Rock_Calcite"
    },
    {
      "x": 6,
      "y": 10,
      "z": 5,
      "name": "Rock_Calcite"
    },
    {
      "x": 6,
      "y": 11,
      "z": 5,
      "name": "Rock_Calcite"
    },
    {
      "x": 6,
      "y": 1,
      "z": 6,
      "name": "Rock_Calcite"
    },
    {
      "x": 6,
      "y": 2,
      "z": 6,
      "name": "Rock_Calcite"
    },
    {
      "x": 6,
      "y": 3,
      "z": 6,
      "name": "Rock_Calcite"
    },
    {
      "x": 6,
      "y": 4,
      "z": 6,
      "name": "Rock_Calcite"
    },
    {
      "x": 6,
      "y": 5,
      "z": 6,
      "name": "Rock_Calcite"
    },
    {
      "x": 6,
      "y": 6,
      "z": 6,
      "name": "Rock_Calcite"
    },
    {
      "x": 6,
      "y": 7,
      "z": 6,
      "name": "Rock_Calcite"
    },
    {
      "x": 6,
      "y": 8,
      "z": 6,
      "name": "Rock_Calcite"
    },
    {
      "x": 6,
      "y": 9,
      "z": 6,
      "name": "Rock_Calcite"
    },
    {
      "x": 6,
      "y": 10,
      "z": 6,
      "name": "Rock_Calcite"
    },
    {
      "x": 6,
      "y": 11,
      "z": 6,
      "name": "Rock_Calcite"
    },
    {
      "x": 6,
      "y": 1,
      "z": 7,
      "name": "Rock_Calcite"
    },
    {
      "x": 6,
      "y": 2,
      "z": 7,
      "name": "Rock_Calcite"
    },
    {
      "x": 6,
      "y": 3,
      "z": 7,
      "name": "Rock_Calcite"
    },
    {
      "x": 6,
      "y": 4,
      "z": 7,
      "name": "Rock_Calcite"
    },
    {
      "x": 6,
      "y": 5,
      "z": 7,
      "name": "Rock_Calcite"
    },
    {
      "x": 6,
      "y": 6,
      "z": 7,
      "name": "Rock_Calcite"
    },
    {
      "x": 6,
      "y": 7,
      "z": 7,
      "name": "Rock_Calcite"
    },
    {
      "x": 6,
      "y": 8,
      "z": 7,
      "name": "Rock_Calcite"
    },
    {
      "x": 6,
      "y": 9,
      "z": 7,
      "name": "Rock_Calcite"
    },
    {
      "x": 6,
      "y": 10,
      "z": 7,
      "name": "Rock_Calcite"
    },
    {
      "x": 6,
      "y": 11,
      "z": 7,
      "name": "Rock_Calcite"
    },
    {
      "x": 6,
      "y": 1,
      "z": 8,
      "name": "Rock_Calcite"
    },
    {
      "x": 6,
      "y": 2,
      "z": 8,
      "name": "Rock_Calcite"
    },
    {
      "x": 6,
      "y": 3,
      "z": 8,
      "name": "Rock_Calcite"
    },
    {
      "x": 6,
      "y": 4,
      "z": 8,
      "name": "Rock_Calcite"
    },
    {
      "x": 6,
      "y": 5,
      "z": 8,
      "name": "Rock_Calcite"
    },
    {
      "x": 6,
      "y": 6,
      "z": 8,
      "name": "Rock_Calcite"
    },
    {
      "x": 6,
      "y": 7,
      "z": 8,
      "name": "Rock_Calcite"
    },
    {
      "x": 6,
      "y": 8,
      "z": 8,
      "name": "Rock_Calcite"
    },
    {
      "x": 6,
      "y": 9,
      "z": 8,
      "name": "Rock_Calcite"
    },
    {
      "x": 6,
      "y": 10,
      "z": 8,
      "name": "Rock_Calcite"
    },
    {
      "x": 6,
      "y": 11,
      "z": 8,
      "name": "Rock_Calcite"
    },
    {
      "x": 6,
      "y": 1,
      "z": 9,
      "name": "Rock_Calcite"
    },
    {
      "x": 6,
      "y": 2,
      "z": 9,
      "name": "Rock_Calcite"
    },
    {
      "x": 6,
      "y": 3,
      "z": 9,
      "name": "Rock_Calcite"
    },
    {
      "x": 6,
      "y": 4,
      "z": 9,
      "name": "Rock_Calcite"
    },
    {
      "x": 6,
      "y": 5,
      "z": 9,
      "name": "Rock_Calcite"
    },
    {
      "x": 6,
      "y": 6,
      "z": 9,
      "name": "Rock_Calcite"
    },
    {
      "x": 6,
      "y": 7,
      "z": 9,
      "name": "Rock_Calcite"
    },
    {
      "x": 6,
      "y": 8,
      "z": 9,
      "name": "Rock_Calcite"
    },
    {
      "x": 6,
      "y": 9,
      "z": 9,
      "name": "Rock_Calcite"
    },
    {
      "x": 6,
      "y": 10,
      "z": 9,
      "name": "Rock_Calcite"
    },
    {
      "x": 6,
      "y": 11,
      "z": 9,
      "name": "Rock_Calcite"
    },
    {
      "x": 6,
      "y": 1,
      "z": 10,
      "name": "Rock_Calcite"
    },
    {
      "x": 6,
      "y": 2,
      "z": 10,
      "name": "Rock_Calcite"
    },
    {
      "x": 6,
      "y": 3,
      "z": 10,
      "name": "Rock_Calcite"
    },
    {
      "x": 6,
      "y": 4,
      "z": 10,
      "name": "Rock_Calcite"
    },
    {
      "x": 6,
      "y": 5,
      "z": 10,
      "name": "Rock_Calcite"
    },
    {
      "x": 6,
      "y": 6,
      "z": 10,
      "name": "Rock_Calcite"
    },
    {
      "x": 6,
      "y": 7,
      "z": 10,
      "name": "Rock_Calcite"
    },
    {
      "x": 6,
      "y": 8,
      "z": 10,
      "name": "Rock_Calcite"
    },
    {
      "x": 6,
      "y": 9,
      "z": 10,
      "name": "Rock_Calcite"
    },
    {
      "x": 6,
      "y": 10,
      "z": 10,
      "name": "Rock_Calcite"
    },
    {
      "x": 6,
      "y": 11,
      "z": 10,
      "name": "Rock_Calcite"
    },
    {
      "x": 6,
      "y": 12,
      "z": 10,
      "name": "Rock_Calcite"
    },
    {
      "x": 6,
      "y": 1,
      "z": 11,
      "name": "Rock_Calcite"
    },
    {
      "x": 6,
      "y": 2,
      "z": 11,
      "name": "Rock_Calcite"
    },
    {
      "x": 6,
      "y": 3,
      "z": 11,
      "name": "Rock_Calcite"
    },
    {
      "x": 6,
      "y": 4,
      "z": 11,
      "name": "Rock_Calcite"
    },
    {
      "x": 6,
      "y": 5,
      "z": 11,
      "name": "Rock_Calcite"
    },
    {
      "x": 6,
      "y": 6,
      "z": 11,
      "name": "Rock_Calcite"
    },
    {
      "x": 6,
      "y": 7,
      "z": 11,
      "name": "Rock_Calcite"
    },
    {
      "x": 6,
      "y": 8,
      "z": 11,
      "name": "Rock_Calcite"
    },
    {
      "x": 6,
      "y": 9,
      "z": 11,
      "name": "Rock_Calcite"
    },
    {
      "x": 6,
      "y": 10,
      "z": 11,
      "name": "Rock_Calcite"
    },
    {
      "x": 6,
      "y": 11,
      "z": 11,
      "name": "Rock_Calcite"
    },
    {
      "x": 6,
      "y": 12,
      "z": 11,
      "name": "Rock_Calcite"
    },
    {
      "x": 6,
      "y": 1,
      "z": 12,
      "name": "Rock_Calcite"
    },
    {
      "x": 6,
      "y": 2,
      "z": 12,
      "name": "Rock_Calcite"
    },
    {
      "x": 6,
      "y": 3,
      "z": 12,
      "name": "Rock_Calcite"
    },
    {
      "x": 6,
      "y": 4,
      "z": 12,
      "name": "Rock_Calcite"
    },
    {
      "x": 6,
      "y": 5,
      "z": 12,
      "name": "Rock_Calcite"
    },
    {
      "x": 6,
      "y": 6,
      "z": 12,
      "name": "Rock_Calcite"
    },
    {
      "x": 6,
      "y": 7,
      "z": 12,
      "name": "Rock_Calcite"
    },
    {
      "x": 6,
      "y": 8,
      "z": 12,
      "name": "Rock_Calcite"
    },
    {
      "x": 6,
      "y": 9,
      "z": 12,
      "name": "Rock_Calcite"
    },
    {
      "x": 6,
      "y": 10,
      "z": 12,
      "name": "Rock_Calcite"
    },
    {
      "x": 6,
      "y": 11,
      "z": 12,
      "name": "Rock_Calcite"
    },
    {
      "x": 6,
      "y": 12,
      "z": 12,
      "name": "Rock_Calcite"
    },
    {
      "x": 6,
      "y": 3,
      "z": 13,
      "name": "Rock_Calcite"
    },
    {
      "x": 6,
      "y": 4,
      "z": 13,
      "name": "Rock_Calcite"
    },
    {
      "x": 6,
      "y": 5,
      "z": 13,
      "name": "Rock_Calcite"
    },
    {
      "x": 6,
      "y": 6,
      "z": 13,
      "name": "Rock_Calcite"
    },
    {
      "x": 6,
      "y": 7,
      "z": 13,
      "name": "Rock_Calcite"
    },
    {
      "x": 6,
      "y": 8,
      "z": 13,
      "name": "Rock_Calcite"
    },
    {
      "x": 6,
      "y": 9,
      "z": 13,
      "name": "Rock_Calcite"
    },
    {
      "x": 6,
      "y": 10,
      "z": 13,
      "name": "Rock_Calcite"
    },
    {
      "x": 6,
      "y": 11,
      "z": 13,
      "name": "Rock_Calcite"
    },
    {
      "x": 6,
      "y": 12,
      "z": 13,
      "name": "Rock_Calcite"
    },
    {
      "x": 6,
      "y": 13,
      "z": 13,
      "name": "Rock_Calcite"
    },
    {
      "x": 7,
      "y": 6,
      "z": 3,
      "name": "Rock_Calcite"
    },
    {
      "x": 7,
      "y": 7,
      "z": 3,
      "name": "Rock_Calcite"
    },
    {
      "x": 7,
      "y": 8,
      "z": 3,
      "name": "Rock_Calcite"
    },
    {
      "x": 7,
      "y": 9,
      "z": 3,
      "name": "Rock_Calcite"
    },
    {
      "x": 7,
      "y": 10,
      "z": 3,
      "name": "Rock_Calcite"
    },
    {
      "x": 7,
      "y": 11,
      "z": 3,
      "name": "Rock_Calcite"
    },
    {
      "x": 7,
      "y": 2,
      "z": 4,
      "name": "Rock_Calcite"
    },
    {
      "x": 7,
      "y": 3,
      "z": 4,
      "name": "Rock_Calcite"
    },
    {
      "x": 7,
      "y": 4,
      "z": 4,
      "name": "Rock_Calcite"
    },
    {
      "x": 7,
      "y": 5,
      "z": 4,
      "name": "Rock_Calcite"
    },
    {
      "x": 7,
      "y": 6,
      "z": 4,
      "name": "Rock_Calcite"
    },
    {
      "x": 7,
      "y": 7,
      "z": 4,
      "name": "Rock_Calcite"
    },
    {
      "x": 7,
      "y": 8,
      "z": 4,
      "name": "Rock_Calcite"
    },
    {
      "x": 7,
      "y": 9,
      "z": 4,
      "name": "Rock_Calcite"
    },
    {
      "x": 7,
      "y": 10,
      "z": 4,
      "name": "Rock_Calcite"
    },
    {
      "x": 7,
      "y": 11,
      "z": 4,
      "name": "Rock_Calcite"
    },
    {
      "x": 7,
      "y": 1,
      "z": 5,
      "name": "Rock_Calcite"
    },
    {
      "x": 7,
      "y": 2,
      "z": 5,
      "name": "Rock_Calcite"
    },
    {
      "x": 7,
      "y": 3,
      "z": 5,
      "name": "Rock_Calcite"
    },
    {
      "x": 7,
      "y": 4,
      "z": 5,
      "name": "Rock_Calcite"
    },
    {
      "x": 7,
      "y": 5,
      "z": 5,
      "name": "Rock_Calcite"
    },
    {
      "x": 7,
      "y": 6,
      "z": 5,
      "name": "Rock_Calcite"
    },
    {
      "x": 7,
      "y": 7,
      "z": 5,
      "name": "Rock_Calcite"
    },
    {
      "x": 7,
      "y": 8,
      "z": 5,
      "name": "Rock_Calcite"
    },
    {
      "x": 7,
      "y": 9,
      "z": 5,
      "name": "Rock_Calcite"
    },
    {
      "x": 7,
      "y": 10,
      "z": 5,
      "name": "Rock_Calcite"
    },
    {
      "x": 7,
      "y": 11,
      "z": 5,
      "name": "Rock_Calcite"
    },
    {
      "x": 7,
      "y": 1,
      "z": 6,
      "name": "Rock_Calcite"
    },
    {
      "x": 7,
      "y": 2,
      "z": 6,
      "name": "Rock_Calcite"
    },
    {
      "x": 7,
      "y": 3,
      "z": 6,
      "name": "Rock_Calcite"
    },
    {
      "x": 7,
      "y": 4,
      "z": 6,
      "name": "Rock_Calcite"
    },
    {
      "x": 7,
      "y": 5,
      "z": 6,
      "name": "Rock_Calcite"
    },
    {
      "x": 7,
      "y": 6,
      "z": 6,
      "name": "Rock_Calcite"
    },
    {
      "x": 7,
      "y": 7,
      "z": 6,
      "name": "Rock_Calcite"
    },
    {
      "x": 7,
      "y": 8,
      "z": 6,
      "name": "Rock_Calcite"
    },
    {
      "x": 7,
      "y": 9,
      "z": 6,
      "name": "Rock_Calcite"
    },
    {
      "x": 7,
      "y": 10,
      "z": 6,
      "name": "Rock_Calcite"
    },
    {
      "x": 7,
      "y": 11,
      "z": 6,
      "name": "Rock_Calcite"
    },
    {
      "x": 7,
      "y": 1,
      "z": 7,
      "name": "Rock_Calcite"
    },
    {
      "x": 7,
      "y": 2,
      "z": 7,
      "name": "Rock_Calcite"
    },
    {
      "x": 7,
      "y": 3,
      "z": 7,
      "name": "Rock_Calcite"
    },
    {
      "x": 7,
      "y": 4,
      "z": 7,
      "name": "Rock_Calcite"
    },
    {
      "x": 7,
      "y": 5,
      "z": 7,
      "name": "Rock_Calcite"
    },
    {
      "x": 7,
      "y": 6,
      "z": 7,
      "name": "Rock_Calcite"
    },
    {
      "x": 7,
      "y": 7,
      "z": 7,
      "name": "Rock_Calcite"
    },
    {
      "x": 7,
      "y": 8,
      "z": 7,
      "name": "Rock_Calcite"
    },
    {
      "x": 7,
      "y": 9,
      "z": 7,
      "name": "Rock_Calcite"
    },
    {
      "x": 7,
      "y": 10,
      "z": 7,
      "name": "Rock_Calcite"
    },
    {
      "x": 7,
      "y": 11,
      "z": 7,
      "name": "Rock_Calcite"
    },
    {
      "x": 7,
      "y": 1,
      "z": 8,
      "name": "Rock_Calcite"
    },
    {
      "x": 7,
      "y": 2,
      "z": 8,
      "name": "Rock_Calcite"
    },
    {
      "x": 7,
      "y": 3,
      "z": 8,
      "name": "Rock_Calcite"
    },
    {
      "x": 7,
      "y": 4,
      "z": 8,
      "name": "Rock_Calcite"
    },
    {
      "x": 7,
      "y": 5,
      "z": 8,
      "name": "Rock_Calcite"
    },
    {
      "x": 7,
      "y": 6,
      "z": 8,
      "name": "Rock_Calcite"
    },
    {
      "x": 7,
      "y": 7,
      "z": 8,
      "name": "Rock_Calcite"
    },
    {
      "x": 7,
      "y": 8,
      "z": 8,
      "name": "Rock_Calcite"
    },
    {
      "x": 7,
      "y": 9,
      "z": 8,
      "name": "Rock_Calcite"
    },
    {
      "x": 7,
      "y": 10,
      "z": 8,
      "name": "Rock_Calcite"
    },
    {
      "x": 7,
      "y": 11,
      "z": 8,
      "name": "Rock_Calcite"
    },
    {
      "x": 7,
      "y": 1,
      "z": 9,
      "name": "Rock_Calcite"
    },
    {
      "x": 7,
      "y": 2,
      "z": 9,
      "name": "Rock_Calcite"
    },
    {
      "x": 7,
      "y": 3,
      "z": 9,
      "name": "Rock_Calcite"
    },
    {
      "x": 7,
      "y": 4,
      "z": 9,
      "name": "Rock_Calcite"
    },
    {
      "x": 7,
      "y": 5,
      "z": 9,
      "name": "Rock_Calcite"
    },
    {
      "x": 7,
      "y": 6,
      "z": 9,
      "name": "Rock_Calcite"
    },
    {
      "x": 7,
      "y": 7,
      "z": 9,
      "name": "Rock_Calcite"
    },
    {
      "x": 7,
      "y": 8,
      "z": 9,
      "name": "Rock_Calcite"
    },
    {
      "x": 7,
      "y": 9,
      "z": 9,
      "name": "Rock_Calcite"
    },
    {
      "x": 7,
      "y": 10,
      "z": 9,
      "name": "Rock_Calcite"
    },
    {
      "x": 7,
      "y": 11,
      "z": 9,
      "name": "Rock_Calcite"
    },
    {
      "x": 7,
      "y": 12,
      "z": 9,
      "name": "Rock_Calcite"
    },
    {
      "x": 7,
      "y": 1,
      "z": 10,
      "name": "Rock_Calcite"
    },
    {
      "x": 7,
      "y": 2,
      "z": 10,
      "name": "Rock_Calcite"
    },
    {
      "x": 7,
      "y": 3,
      "z": 10,
      "name": "Rock_Calcite"
    },
    {
      "x": 7,
      "y": 4,
      "z": 10,
      "name": "Rock_Calcite"
    },
    {
      "x": 7,
      "y": 5,
      "z": 10,
      "name": "Rock_Calcite"
    },
    {
      "x": 7,
      "y": 6,
      "z": 10,
      "name": "Rock_Calcite"
    },
    {
      "x": 7,
      "y": 7,
      "z": 10,
      "name": "Rock_Calcite"
    },
    {
      "x": 7,
      "y": 8,
      "z": 10,
      "name": "Rock_Calcite"
    },
    {
      "x": 7,
      "y": 9,
      "z": 10,
      "name": "Rock_Calcite"
    },
    {
      "x": 7,
      "y": 10,
      "z": 10,
      "name": "Rock_Calcite"
    },
    {
      "x": 7,
      "y": 11,
      "z": 10,
      "name": "Rock_Calcite"
    },
    {
      "x": 7,
      "y": 12,
      "z": 10,
      "name": "Rock_Calcite"
    },
    {
      "x": 7,
      "y": 1,
      "z": 11,
      "name": "Rock_Calcite"
    },
    {
      "x": 7,
      "y": 2,
      "z": 11,
      "name": "Rock_Calcite"
    },
    {
      "x": 7,
      "y": 3,
      "z": 11,
      "name": "Rock_Calcite"
    },
    {
      "x": 7,
      "y": 4,
      "z": 11,
      "name": "Rock_Calcite"
    },
    {
      "x": 7,
      "y": 5,
      "z": 11,
      "name": "Rock_Calcite"
    },
    {
      "x": 7,
      "y": 6,
      "z": 11,
      "name": "Rock_Calcite"
    },
    {
      "x": 7,
      "y": 7,
      "z": 11,
      "name": "Rock_Calcite"
    },
    {
      "x": 7,
      "y": 8,
      "z": 11,
      "name": "Rock_Calcite"
    },
    {
      "x": 7,
      "y": 9,
      "z": 11,
      "name": "Rock_Calcite"
    },
    {
      "x": 7,
      "y": 10,
      "z": 11,
      "name": "Rock_Calcite"
    },
    {
      "x": 7,
      "y": 11,
      "z": 11,
      "name": "Rock_Calcite"
    },
    {
      "x": 7,
      "y": 12,
      "z": 11,
      "name": "Rock_Calcite"
    },
    {
      "x": 7,
      "y": 1,
      "z": 12,
      "name": "Rock_Calcite"
    },
    {
      "x": 7,
      "y": 2,
      "z": 12,
      "name": "Rock_Calcite"
    },
    {
      "x": 7,
      "y": 3,
      "z": 12,
      "name": "Rock_Calcite"
    },
    {
      "x": 7,
      "y": 4,
      "z": 12,
      "name": "Rock_Calcite"
    },
    {
      "x": 7,
      "y": 5,
      "z": 12,
      "name": "Rock_Calcite"
    },
    {
      "x": 7,
      "y": 6,
      "z": 12,
      "name": "Rock_Calcite"
    },
    {
      "x": 7,
      "y": 7,
      "z": 12,
      "name": "Rock_Calcite"
    },
    {
      "x": 7,
      "y": 8,
      "z": 12,
      "name": "Rock_Calcite"
    },
    {
      "x": 7,
      "y": 9,
      "z": 12,
      "name": "Rock_Calcite"
    },
    {
      "x": 7,
      "y": 10,
      "z": 12,
      "name": "Rock_Calcite"
    },
    {
      "x": 7,
      "y": 11,
      "z": 12,
      "name": "Rock_Calcite"
    },
    {
      "x": 7,
      "y": 12,
      "z": 12,
      "name": "Rock_Calcite"
    },
    {
      "x": 7,
      "y": 13,
      "z": 12,
      "name": "Rock_Calcite"
    },
    {
      "x": 7,
      "y": 3,
      "z": 13,
      "name": "Rock_Calcite"
    },
    {
      "x": 7,
      "y": 4,
      "z": 13,
      "name": "Rock_Calcite"
    },
    {
      "x": 7,
      "y": 5,
      "z": 13,
      "name": "Rock_Calcite"
    },
    {
      "x": 7,
      "y": 6,
      "z": 13,
      "name": "Rock_Calcite"
    },
    {
      "x": 7,
      "y": 7,
      "z": 13,
      "name": "Rock_Calcite"
    },
    {
      "x": 7,
      "y": 8,
      "z": 13,
      "name": "Rock_Calcite"
    },
    {
      "x": 7,
      "y": 9,
      "z": 13,
      "name": "Rock_Calcite"
    },
    {
      "x": 7,
      "y": 10,
      "z": 13,
      "name": "Rock_Calcite"
    },
    {
      "x": 7,
      "y": 11,
      "z": 13,
      "name": "Rock_Calcite"
    },
    {
      "x": 7,
      "y": 12,
      "z": 13,
      "name": "Rock_Calcite"
    },
    {
      "x": 7,
      "y": 13,
      "z": 13,
      "name": "Rock_Calcite"
    },
    {
      "x": 8,
      "y": 5,
      "z": 3,
      "name": "Rock_Calcite"
    },
    {
      "x": 8,
      "y": 6,
      "z": 3,
      "name": "Rock_Calcite"
    },
    {
      "x": 8,
      "y": 7,
      "z": 3,
      "name": "Rock_Calcite"
    },
    {
      "x": 8,
      "y": 8,
      "z": 3,
      "name": "Rock_Calcite"
    },
    {
      "x": 8,
      "y": 9,
      "z": 3,
      "name": "Rock_Calcite"
    },
    {
      "x": 8,
      "y": 10,
      "z": 3,
      "name": "Rock_Calcite"
    },
    {
      "x": 8,
      "y": 11,
      "z": 3,
      "name": "Rock_Calcite"
    },
    {
      "x": 8,
      "y": 2,
      "z": 4,
      "name": "Rock_Calcite"
    },
    {
      "x": 8,
      "y": 3,
      "z": 4,
      "name": "Rock_Calcite"
    },
    {
      "x": 8,
      "y": 4,
      "z": 4,
      "name": "Rock_Calcite"
    },
    {
      "x": 8,
      "y": 5,
      "z": 4,
      "name": "Rock_Calcite"
    },
    {
      "x": 8,
      "y": 6,
      "z": 4,
      "name": "Rock_Calcite"
    },
    {
      "x": 8,
      "y": 7,
      "z": 4,
      "name": "Rock_Calcite"
    },
    {
      "x": 8,
      "y": 8,
      "z": 4,
      "name": "Rock_Calcite"
    },
    {
      "x": 8,
      "y": 9,
      "z": 4,
      "name": "Rock_Calcite"
    },
    {
      "x": 8,
      "y": 10,
      "z": 4,
      "name": "Rock_Calcite"
    },
    {
      "x": 8,
      "y": 11,
      "z": 4,
      "name": "Rock_Calcite"
    },
    {
      "x": 8,
      "y": 1,
      "z": 5,
      "name": "Rock_Calcite"
    },
    {
      "x": 8,
      "y": 2,
      "z": 5,
      "name": "Rock_Calcite"
    },
    {
      "x": 8,
      "y": 3,
      "z": 5,
      "name": "Rock_Calcite"
    },
    {
      "x": 8,
      "y": 4,
      "z": 5,
      "name": "Rock_Calcite"
    },
    {
      "x": 8,
      "y": 5,
      "z": 5,
      "name": "Rock_Calcite"
    },
    {
      "x": 8,
      "y": 6,
      "z": 5,
      "name": "Rock_Calcite"
    },
    {
      "x": 8,
      "y": 7,
      "z": 5,
      "name": "Rock_Calcite"
    },
    {
      "x": 8,
      "y": 8,
      "z": 5,
      "name": "Rock_Calcite"
    },
    {
      "x": 8,
      "y": 9,
      "z": 5,
      "name": "Rock_Calcite"
    },
    {
      "x": 8,
      "y": 10,
      "z": 5,
      "name": "Rock_Calcite"
    },
    {
      "x": 8,
      "y": 11,
      "z": 5,
      "name": "Rock_Calcite"
    },
    {
      "x": 8,
      "y": 1,
      "z": 6,
      "name": "Rock_Calcite"
    },
    {
      "x": 8,
      "y": 2,
      "z": 6,
      "name": "Rock_Calcite"
    },
    {
      "x": 8,
      "y": 3,
      "z": 6,
      "name": "Rock_Calcite"
    },
    {
      "x": 8,
      "y": 4,
      "z": 6,
      "name": "Rock_Calcite"
    },
    {
      "x": 8,
      "y": 5,
      "z": 6,
      "name": "Rock_Calcite"
    },
    {
      "x": 8,
      "y": 6,
      "z": 6,
      "name": "Rock_Calcite"
    },
    {
      "x": 8,
      "y": 7,
      "z": 6,
      "name": "Rock_Calcite"
    },
    {
      "x": 8,
      "y": 8,
      "z": 6,
      "name": "Rock_Calcite"
    },
    {
      "x": 8,
      "y": 9,
      "z": 6,
      "name": "Rock_Calcite"
    },
    {
      "x": 8,
      "y": 10,
      "z": 6,
      "name": "Rock_Calcite"
    },
    {
      "x": 8,
      "y": 11,
      "z": 6,
      "name": "Rock_Calcite"
    },
    {
      "x": 8,
      "y": 1,
      "z": 7,
      "name": "Rock_Calcite"
    },
    {
      "x": 8,
      "y": 2,
      "z": 7,
      "name": "Rock_Calcite"
    },
    {
      "x": 8,
      "y": 3,
      "z": 7,
      "name": "Rock_Calcite"
    },
    {
      "x": 8,
      "y": 4,
      "z": 7,
      "name": "Rock_Calcite"
    },
    {
      "x": 8,
      "y": 5,
      "z": 7,
      "name": "Rock_Calcite"
    },
    {
      "x": 8,
      "y": 6,
      "z": 7,
      "name": "Rock_Calcite"
    },
    {
      "x": 8,
      "y": 7,
      "z": 7,
      "name": "Rock_Calcite"
    },
    {
      "x": 8,
      "y": 8,
      "z": 7,
      "name": "Rock_Calcite"
    },
    {
      "x": 8,
      "y": 9,
      "z": 7,
      "name": "Rock_Calcite"
    },
    {
      "x": 8,
      "y": 10,
      "z": 7,
      "name": "Rock_Calcite"
    },
    {
      "x": 8,
      "y": 11,
      "z": 7,
      "name": "Rock_Calcite"
    },
    {
      "x": 8,
      "y": 1,
      "z": 8,
      "name": "Rock_Calcite"
    },
    {
      "x": 8,
      "y": 2,
      "z": 8,
      "name": "Rock_Calcite"
    },
    {
      "x": 8,
      "y": 3,
      "z": 8,
      "name": "Rock_Calcite"
    },
    {
      "x": 8,
      "y": 4,
      "z": 8,
      "name": "Rock_Calcite"
    },
    {
      "x": 8,
      "y": 5,
      "z": 8,
      "name": "Rock_Calcite"
    },
    {
      "x": 8,
      "y": 6,
      "z": 8,
      "name": "Rock_Calcite"
    },
    {
      "x": 8,
      "y": 7,
      "z": 8,
      "name": "Rock_Calcite"
    },
    {
      "x": 8,
      "y": 8,
      "z": 8,
      "name": "Rock_Calcite"
    },
    {
      "x": 8,
      "y": 9,
      "z": 8,
      "name": "Rock_Calcite"
    },
    {
      "x": 8,
      "y": 10,
      "z": 8,
      "name": "Rock_Calcite"
    },
    {
      "x": 8,
      "y": 11,
      "z": 8,
      "name": "Rock_Calcite"
    },
    {
      "x": 8,
      "y": 12,
      "z": 8,
      "name": "Rock_Calcite"
    },
    {
      "x": 8,
      "y": 1,
      "z": 9,
      "name": "Rock_Calcite"
    },
    {
      "x": 8,
      "y": 2,
      "z": 9,
      "name": "Rock_Calcite"
    },
    {
      "x": 8,
      "y": 3,
      "z": 9,
      "name": "Rock_Calcite"
    },
    {
      "x": 8,
      "y": 4,
      "z": 9,
      "name": "Rock_Calcite"
    },
    {
      "x": 8,
      "y": 5,
      "z": 9,
      "name": "Rock_Calcite"
    },
    {
      "x": 8,
      "y": 6,
      "z": 9,
      "name": "Rock_Calcite"
    },
    {
      "x": 8,
      "y": 7,
      "z": 9,
      "name": "Rock_Calcite"
    },
    {
      "x": 8,
      "y": 8,
      "z": 9,
      "name": "Rock_Calcite"
    },
    {
      "x": 8,
      "y": 9,
      "z": 9,
      "name": "Rock_Calcite"
    },
    {
      "x": 8,
      "y": 10,
      "z": 9,
      "name": "Rock_Calcite"
    },
    {
      "x": 8,
      "y": 11,
      "z": 9,
      "name": "Rock_Calcite"
    },
    {
      "x": 8,
      "y": 12,
      "z": 9,
      "name": "Rock_Calcite"
    },
    {
      "x": 8,
      "y": 1,
      "z": 10,
      "name": "Rock_Calcite"
    },
    {
      "x": 8,
      "y": 2,
      "z": 10,
      "name": "Rock_Calcite"
    },
    {
      "x": 8,
      "y": 3,
      "z": 10,
      "name": "Rock_Calcite"
    },
    {
      "x": 8,
      "y": 4,
      "z": 10,
      "name": "Rock_Calcite"
    },
    {
      "x": 8,
      "y": 5,
      "z": 10,
      "name": "Rock_Calcite"
    },
    {
      "x": 8,
      "y": 6,
      "z": 10,
      "name": "Rock_Calcite"
    },
    {
      "x": 8,
      "y": 7,
      "z": 10,
      "name": "Rock_Calcite"
    },
    {
      "x": 8,
      "y": 8,
      "z": 10,
      "name": "Rock_Calcite"
    },
    {
      "x": 8,
      "y": 9,
      "z": 10,
      "name": "Rock_Calcite"
    },
    {
      "x": 8,
      "y": 10,
      "z": 10,
      "name": "Rock_Calcite"
    },
    {
      "x": 8,
      "y": 11,
      "z": 10,
      "name": "Rock_Calcite"
    },
    {
      "x": 8,
      "y": 12,
      "z": 10,
      "name": "Rock_Calcite"
    },
    {
      "x": 8,
      "y": 1,
      "z": 11,
      "name": "Rock_Calcite"
    },
    {
      "x": 8,
      "y": 2,
      "z": 11,
      "name": "Rock_Calcite"
    },
    {
      "x": 8,
      "y": 3,
      "z": 11,
      "name": "Rock_Calcite"
    },
    {
      "x": 8,
      "y": 4,
      "z": 11,
      "name": "Rock_Calcite"
    },
    {
      "x": 8,
      "y": 5,
      "z": 11,
      "name": "Rock_Calcite"
    },
    {
      "x": 8,
      "y": 6,
      "z": 11,
      "name": "Rock_Calcite"
    },
    {
      "x": 8,
      "y": 7,
      "z": 11,
      "name": "Rock_Calcite"
    },
    {
      "x": 8,
      "y": 8,
      "z": 11,
      "name": "Rock_Calcite"
    },
    {
      "x": 8,
      "y": 9,
      "z": 11,
      "name": "Rock_Calcite"
    },
    {
      "x": 8,
      "y": 10,
      "z": 11,
      "name": "Rock_Calcite"
    },
    {
      "x": 8,
      "y": 11,
      "z": 11,
      "name": "Rock_Calcite"
    },
    {
      "x": 8,
      "y": 12,
      "z": 11,
      "name": "Rock_Calcite"
    },
    {
      "x": 8,
      "y": 1,
      "z": 12,
      "name": "Rock_Calcite"
    },
    {
      "x": 8,
      "y": 2,
      "z": 12,
      "name": "Rock_Calcite"
    },
    {
      "x": 8,
      "y": 3,
      "z": 12,
      "name": "Rock_Calcite"
    },
    {
      "x": 8,
      "y": 4,
      "z": 12,
      "name": "Rock_Calcite"
    },
    {
      "x": 8,
      "y": 5,
      "z": 12,
      "name": "Rock_Calcite"
    },
    {
      "x": 8,
      "y": 6,
      "z": 12,
      "name": "Rock_Calcite"
    },
    {
      "x": 8,
      "y": 7,
      "z": 12,
      "name": "Rock_Calcite"
    },
    {
      "x": 8,
      "y": 8,
      "z": 12,
      "name": "Rock_Calcite"
    },
    {
      "x": 8,
      "y": 9,
      "z": 12,
      "name": "Rock_Calcite"
    },
    {
      "x": 8,
      "y": 10,
      "z": 12,
      "name": "Rock_Calcite"
    },
    {
      "x": 8,
      "y": 11,
      "z": 12,
      "name": "Rock_Calcite"
    },
    {
      "x": 8,
      "y": 12,
      "z": 12,
      "name": "Rock_Calcite"
    },
    {
      "x": 8,
      "y": 13,
      "z": 12,
      "name": "Rock_Calcite"
    },
    {
      "x": 8,
      "y": 2,
      "z": 13,
      "name": "Rock_Calcite"
    },
    {
      "x": 8,
      "y": 3,
      "z": 13,
      "name": "Rock_Calcite"
    },
    {
      "x": 8,
      "y": 4,
      "z": 13,
      "name": "Rock_Calcite"
    },
    {
      "x": 8,
      "y": 5,
      "z": 13,
      "name": "Rock_Calcite"
    },
    {
      "x": 8,
      "y": 6,
      "z": 13,
      "name": "Rock_Calcite"
    },
    {
      "x": 8,
      "y": 7,
      "z": 13,
      "name": "Rock_Calcite"
    },
    {
      "x": 8,
      "y": 8,
      "z": 13,
      "name": "Rock_Calcite"
    },
    {
      "x": 8,
      "y": 9,
      "z": 13,
      "name": "Rock_Calcite"
    },
    {
      "x": 8,
      "y": 10,
      "z": 13,
      "name": "Rock_Calcite"
    },
    {
      "x": 8,
      "y": 11,
      "z": 13,
      "name": "Rock_Calcite"
    },
    {
      "x": 8,
      "y": 12,
      "z": 13,
      "name": "Rock_Calcite"
    },
    {
      "x": 8,
      "y": 13,
      "z": 13,
      "name": "Rock_Calcite"
    },
    {
      "x": 9,
      "y": 3,
      "z": 4,
      "name": "Rock_Calcite"
    },
    {
      "x": 9,
      "y": 4,
      "z": 4,
      "name": "Rock_Calcite"
    },
    {
      "x": 9,
      "y": 5,
      "z": 4,
      "name": "Rock_Calcite"
    },
    {
      "x": 9,
      "y": 6,
      "z": 4,
      "name": "Rock_Calcite"
    },
    {
      "x": 9,
      "y": 7,
      "z": 4,
      "name": "Rock_Calcite"
    },
    {
      "x": 9,
      "y": 8,
      "z": 4,
      "name": "Rock_Calcite"
    },
    {
      "x": 9,
      "y": 9,
      "z": 4,
      "name": "Rock_Calcite"
    },
    {
      "x": 9,
      "y": 10,
      "z": 4,
      "name": "Rock_Calcite"
    },
    {
      "x": 9,
      "y": 11,
      "z": 4,
      "name": "Rock_Calcite"
    },
    {
      "x": 9,
      "y": 1,
      "z": 5,
      "name": "Rock_Calcite"
    },
    {
      "x": 9,
      "y": 2,
      "z": 5,
      "name": "Rock_Calcite"
    },
    {
      "x": 9,
      "y": 3,
      "z": 5,
      "name": "Rock_Calcite"
    },
    {
      "x": 9,
      "y": 4,
      "z": 5,
      "name": "Rock_Calcite"
    },
    {
      "x": 9,
      "y": 5,
      "z": 5,
      "name": "Rock_Calcite"
    },
    {
      "x": 9,
      "y": 6,
      "z": 5,
      "name": "Rock_Calcite"
    },
    {
      "x": 9,
      "y": 7,
      "z": 5,
      "name": "Rock_Calcite"
    },
    {
      "x": 9,
      "y": 8,
      "z": 5,
      "name": "Rock_Calcite"
    },
    {
      "x": 9,
      "y": 9,
      "z": 5,
      "name": "Rock_Calcite"
    },
    {
      "x": 9,
      "y": 10,
      "z": 5,
      "name": "Rock_Calcite"
    },
    {
      "x": 9,
      "y": 11,
      "z": 5,
      "name": "Rock_Calcite"
    },
    {
      "x": 9,
      "y": 1,
      "z": 6,
      "name": "Rock_Calcite"
    },
    {
      "x": 9,
      "y": 2,
      "z": 6,
      "name": "Rock_Calcite"
    },
    {
      "x": 9,
      "y": 3,
      "z": 6,
      "name": "Rock_Calcite"
    },
    {
      "x": 9,
      "y": 4,
      "z": 6,
      "name": "Rock_Calcite"
    },
    {
      "x": 9,
      "y": 5,
      "z": 6,
      "name": "Rock_Calcite"
    },
    {
      "x": 9,
      "y": 6,
      "z": 6,
      "name": "Rock_Calcite"
    },
    {
      "x": 9,
      "y": 7,
      "z": 6,
      "name": "Rock_Calcite"
    },
    {
      "x": 9,
      "y": 8,
      "z": 6,
      "name": "Rock_Calcite"
    },
    {
      "x": 9,
      "y": 9,
      "z": 6,
      "name": "Rock_Calcite"
    },
    {
      "x": 9,
      "y": 10,
      "z": 6,
      "name": "Rock_Calcite"
    },
    {
      "x": 9,
      "y": 11,
      "z": 6,
      "name": "Rock_Calcite"
    },
    {
      "x": 9,
      "y": 1,
      "z": 7,
      "name": "Rock_Calcite"
    },
    {
      "x": 9,
      "y": 2,
      "z": 7,
      "name": "Rock_Calcite"
    },
    {
      "x": 9,
      "y": 3,
      "z": 7,
      "name": "Rock_Calcite"
    },
    {
      "x": 9,
      "y": 4,
      "z": 7,
      "name": "Rock_Calcite"
    },
    {
      "x": 9,
      "y": 5,
      "z": 7,
      "name": "Rock_Calcite"
    },
    {
      "x": 9,
      "y": 6,
      "z": 7,
      "name": "Rock_Calcite"
    },
    {
      "x": 9,
      "y": 7,
      "z": 7,
      "name": "Rock_Calcite"
    },
    {
      "x": 9,
      "y": 8,
      "z": 7,
      "name": "Rock_Calcite"
    },
    {
      "x": 9,
      "y": 9,
      "z": 7,
      "name": "Rock_Calcite"
    },
    {
      "x": 9,
      "y": 10,
      "z": 7,
      "name": "Rock_Calcite"
    },
    {
      "x": 9,
      "y": 11,
      "z": 7,
      "name": "Rock_Calcite"
    },
    {
      "x": 9,
      "y": 12,
      "z": 7,
      "name": "Rock_Calcite"
    },
    {
      "x": 9,
      "y": 1,
      "z": 8,
      "name": "Rock_Calcite"
    },
    {
      "x": 9,
      "y": 2,
      "z": 8,
      "name": "Rock_Calcite"
    },
    {
      "x": 9,
      "y": 3,
      "z": 8,
      "name": "Rock_Calcite"
    },
    {
      "x": 9,
      "y": 4,
      "z": 8,
      "name": "Rock_Calcite"
    },
    {
      "x": 9,
      "y": 5,
      "z": 8,
      "name": "Rock_Calcite"
    },
    {
      "x": 9,
      "y": 6,
      "z": 8,
      "name": "Rock_Calcite"
    },
    {
      "x": 9,
      "y": 7,
      "z": 8,
      "name": "Rock_Calcite"
    },
    {
      "x": 9,
      "y": 8,
      "z": 8,
      "name": "Rock_Calcite"
    },
    {
      "x": 9,
      "y": 9,
      "z": 8,
      "name": "Rock_Calcite"
    },
    {
      "x": 9,
      "y": 10,
      "z": 8,
      "name": "Rock_Calcite"
    },
    {
      "x": 9,
      "y": 11,
      "z": 8,
      "name": "Rock_Calcite"
    },
    {
      "x": 9,
      "y": 12,
      "z": 8,
      "name": "Rock_Calcite"
    },
    {
      "x": 9,
      "y": 1,
      "z": 9,
      "name": "Rock_Calcite"
    },
    {
      "x": 9,
      "y": 2,
      "z": 9,
      "name": "Rock_Calcite"
    },
    {
      "x": 9,
      "y": 3,
      "z": 9,
      "name": "Rock_Calcite"
    },
    {
      "x": 9,
      "y": 4,
      "z": 9,
      "name": "Rock_Calcite"
    },
    {
      "x": 9,
      "y": 5,
      "z": 9,
      "name": "Rock_Calcite"
    },
    {
      "x": 9,
      "y": 6,
      "z": 9,
      "name": "Rock_Calcite"
    },
    {
      "x": 9,
      "y": 7,
      "z": 9,
      "name": "Rock_Calcite"
    },
    {
      "x": 9,
      "y": 8,
      "z": 9,
      "name": "Rock_Calcite"
    },
    {
      "x": 9,
      "y": 9,
      "z": 9,
      "name": "Rock_Calcite"
    },
    {
      "x": 9,
      "y": 10,
      "z": 9,
      "name": "Rock_Calcite"
    },
    {
      "x": 9,
      "y": 11,
      "z": 9,
      "name": "Rock_Calcite"
    },
    {
      "x": 9,
      "y": 12,
      "z": 9,
      "name": "Rock_Calcite"
    },
    {
      "x": 9,
      "y": 1,
      "z": 10,
      "name": "Rock_Calcite"
    },
    {
      "x": 9,
      "y": 2,
      "z": 10,
      "name": "Rock_Calcite"
    },
    {
      "x": 9,
      "y": 3,
      "z": 10,
      "name": "Rock_Calcite"
    },
    {
      "x": 9,
      "y": 4,
      "z": 10,
      "name": "Rock_Calcite"
    },
    {
      "x": 9,
      "y": 5,
      "z": 10,
      "name": "Rock_Calcite"
    },
    {
      "x": 9,
      "y": 6,
      "z": 10,
      "name": "Rock_Calcite"
    },
    {
      "x": 9,
      "y": 7,
      "z": 10,
      "name": "Rock_Calcite"
    },
    {
      "x": 9,
      "y": 8,
      "z": 10,
      "name": "Rock_Calcite"
    },
    {
      "x": 9,
      "y": 9,
      "z": 10,
      "name": "Rock_Calcite"
    },
    {
      "x": 9,
      "y": 10,
      "z": 10,
      "name": "Rock_Calcite"
    },
    {
      "x": 9,
      "y": 11,
      "z": 10,
      "name": "Rock_Calcite"
    },
    {
      "x": 9,
      "y": 12,
      "z": 10,
      "name": "Rock_Calcite"
    },
    {
      "x": 9,
      "y": 1,
      "z": 11,
      "name": "Rock_Calcite"
    },
    {
      "x": 9,
      "y": 2,
      "z": 11,
      "name": "Rock_Calcite"
    },
    {
      "x": 9,
      "y": 3,
      "z": 11,
      "name": "Rock_Calcite"
    },
    {
      "x": 9,
      "y": 4,
      "z": 11,
      "name": "Rock_Calcite"
    },
    {
      "x": 9,
      "y": 5,
      "z": 11,
      "name": "Rock_Calcite"
    },
    {
      "x": 9,
      "y": 6,
      "z": 11,
      "name": "Rock_Calcite"
    },
    {
      "x": 9,
      "y": 7,
      "z": 11,
      "name": "Rock_Calcite"
    },
    {
      "x": 9,
      "y": 8,
      "z": 11,
      "name": "Rock_Calcite"
    },
    {
      "x": 9,
      "y": 9,
      "z": 11,
      "name": "Rock_Calcite"
    },
    {
      "x": 9,
      "y": 10,
      "z": 11,
      "name": "Rock_Calcite"
    },
    {
      "x": 9,
      "y": 11,
      "z": 11,
      "name": "Rock_Calcite"
    },
    {
      "x": 9,
      "y": 12,
      "z": 11,
      "name": "Rock_Calcite"
    },
    {
      "x": 9,
      "y": 13,
      "z": 11,
      "name": "Rock_Calcite"
    },
    {
      "x": 9,
      "y": 1,
      "z": 12,
      "name": "Rock_Calcite"
    },
    {
      "x": 9,
      "y": 2,
      "z": 12,
      "name": "Rock_Calcite"
    },
    {
      "x": 9,
      "y": 3,
      "z": 12,
      "name": "Rock_Calcite"
    },
    {
      "x": 9,
      "y": 4,
      "z": 12,
      "name": "Rock_Calcite"
    },
    {
      "x": 9,
      "y": 5,
      "z": 12,
      "name": "Rock_Calcite"
    },
    {
      "x": 9,
      "y": 6,
      "z": 12,
      "name": "Rock_Calcite"
    },
    {
      "x": 9,
      "y": 7,
      "z": 12,
      "name": "Rock_Calcite"
    },
    {
      "x": 9,
      "y": 8,
      "z": 12,
      "name": "Rock_Calcite"
    },
    {
      "x": 9,
      "y": 9,
      "z": 12,
      "name": "Rock_Calcite"
    },
    {
      "x": 9,
      "y": 10,
      "z": 12,
      "name": "Rock_Calcite"
    },
    {
      "x": 9,
      "y": 11,
      "z": 12,
      "name": "Rock_Calcite"
    },
    {
      "x": 9,
      "y": 12,
      "z": 12,
      "name": "Rock_Calcite"
    },
    {
      "x": 9,
      "y": 13,
      "z": 12,
      "name": "Rock_Calcite"
    },
    {
      "x": 9,
      "y": 2,
      "z": 13,
      "name": "Rock_Calcite"
    },
    {
      "x": 9,
      "y": 3,
      "z": 13,
      "name": "Rock_Calcite"
    },
    {
      "x": 9,
      "y": 4,
      "z": 13,
      "name": "Rock_Calcite"
    },
    {
      "x": 9,
      "y": 5,
      "z": 13,
      "name": "Rock_Calcite"
    },
    {
      "x": 9,
      "y": 6,
      "z": 13,
      "name": "Rock_Calcite"
    },
    {
      "x": 9,
      "y": 7,
      "z": 13,
      "name": "Rock_Calcite"
    },
    {
      "x": 9,
      "y": 8,
      "z": 13,
      "name": "Rock_Calcite"
    },
    {
      "x": 9,
      "y": 9,
      "z": 13,
      "name": "Rock_Calcite"
    },
    {
      "x": 9,
      "y": 10,
      "z": 13,
      "name": "Rock_Calcite"
    },
    {
      "x": 9,
      "y": 11,
      "z": 13,
      "name": "Rock_Calcite"
    },
    {
      "x": 9,
      "y": 12,
      "z": 13,
      "name": "Rock_Calcite"
    },
    {
      "x": 9,
      "y": 13,
      "z": 13,
      "name": "Rock_Calcite"
    },
    {
      "x": 10,
      "y": 3,
      "z": 4,
      "name": "Rock_Calcite"
    },
    {
      "x": 10,
      "y": 4,
      "z": 4,
      "name": "Rock_Calcite"
    },
    {
      "x": 10,
      "y": 5,
      "z": 4,
      "name": "Rock_Calcite"
    },
    {
      "x": 10,
      "y": 6,
      "z": 4,
      "name": "Rock_Calcite"
    },
    {
      "x": 10,
      "y": 7,
      "z": 4,
      "name": "Rock_Calcite"
    },
    {
      "x": 10,
      "y": 8,
      "z": 4,
      "name": "Rock_Calcite"
    },
    {
      "x": 10,
      "y": 9,
      "z": 4,
      "name": "Rock_Calcite"
    },
    {
      "x": 10,
      "y": 10,
      "z": 4,
      "name": "Rock_Calcite"
    },
    {
      "x": 10,
      "y": 11,
      "z": 4,
      "name": "Rock_Calcite"
    },
    {
      "x": 10,
      "y": 1,
      "z": 5,
      "name": "Rock_Calcite"
    },
    {
      "x": 10,
      "y": 2,
      "z": 5,
      "name": "Rock_Calcite"
    },
    {
      "x": 10,
      "y": 3,
      "z": 5,
      "name": "Rock_Calcite"
    },
    {
      "x": 10,
      "y": 4,
      "z": 5,
      "name": "Rock_Calcite"
    },
    {
      "x": 10,
      "y": 5,
      "z": 5,
      "name": "Rock_Calcite"
    },
    {
      "x": 10,
      "y": 6,
      "z": 5,
      "name": "Rock_Calcite"
    },
    {
      "x": 10,
      "y": 7,
      "z": 5,
      "name": "Rock_Calcite"
    },
    {
      "x": 10,
      "y": 8,
      "z": 5,
      "name": "Rock_Calcite"
    },
    {
      "x": 10,
      "y": 9,
      "z": 5,
      "name": "Rock_Calcite"
    },
    {
      "x": 10,
      "y": 10,
      "z": 5,
      "name": "Rock_Calcite"
    },
    {
      "x": 10,
      "y": 11,
      "z": 5,
      "name": "Rock_Calcite"
    },
    {
      "x": 10,
      "y": 12,
      "z": 5,
      "name": "Rock_Calcite"
    },
    {
      "x": 10,
      "y": 1,
      "z": 6,
      "name": "Rock_Calcite"
    },
    {
      "x": 10,
      "y": 2,
      "z": 6,
      "name": "Rock_Calcite"
    },
    {
      "x": 10,
      "y": 3,
      "z": 6,
      "name": "Rock_Calcite"
    },
    {
      "x": 10,
      "y": 4,
      "z": 6,
      "name": "Rock_Calcite"
    },
    {
      "x": 10,
      "y": 5,
      "z": 6,
      "name": "Rock_Calcite"
    },
    {
      "x": 10,
      "y": 6,
      "z": 6,
      "name": "Rock_Calcite"
    },
    {
      "x": 10,
      "y": 7,
      "z": 6,
      "name": "Rock_Calcite"
    },
    {
      "x": 10,
      "y": 8,
      "z": 6,
      "name": "Rock_Calcite"
    },
    {
      "x": 10,
      "y": 9,
      "z": 6,
      "name": "Rock_Calcite"
    },
    {
      "x": 10,
      "y": 10,
      "z": 6,
      "name": "Rock_Calcite"
    },
    {
      "x": 10,
      "y": 11,
      "z": 6,
      "name": "Rock_Calcite"
    },
    {
      "x": 10,
      "y": 12,
      "z": 6,
      "name": "Rock_Calcite"
    },
    {
      "x": 10,
      "y": 1,
      "z": 7,
      "name": "Rock_Calcite"
    },
    {
      "x": 10,
      "y": 2,
      "z": 7,
      "name": "Rock_Calcite"
    },
    {
      "x": 10,
      "y": 3,
      "z": 7,
      "name": "Rock_Calcite"
    },
    {
      "x": 10,
      "y": 4,
      "z": 7,
      "name": "Rock_Calcite"
    },
    {
      "x": 10,
      "y": 5,
      "z": 7,
      "name": "Rock_Calcite"
    },
    {
      "x": 10,
      "y": 6,
      "z": 7,
      "name": "Rock_Calcite"
    },
    {
      "x": 10,
      "y": 7,
      "z": 7,
      "name": "Rock_Calcite"
    },
    {
      "x": 10,
      "y": 8,
      "z": 7,
      "name": "Rock_Calcite"
    },
    {
      "x": 10,
      "y": 9,
      "z": 7,
      "name": "Rock_Calcite"
    },
    {
      "x": 10,
      "y": 10,
      "z": 7,
      "name": "Rock_Calcite"
    },
    {
      "x": 10,
      "y": 11,
      "z": 7,
      "name": "Rock_Calcite"
    },
    {
      "x": 10,
      "y": 12,
      "z": 7,
      "name": "Rock_Calcite"
    },
    {
      "x": 10,
      "y": 1,
      "z": 8,
      "name": "Rock_Calcite"
    },
    {
      "x": 10,
      "y": 2,
      "z": 8,
      "name": "Rock_Calcite"
    },
    {
      "x": 10,
      "y": 3,
      "z": 8,
      "name": "Rock_Calcite"
    },
    {
      "x": 10,
      "y": 4,
      "z": 8,
      "name": "Rock_Calcite"
    },
    {
      "x": 10,
      "y": 5,
      "z": 8,
      "name": "Rock_Calcite"
    },
    {
      "x": 10,
      "y": 6,
      "z": 8,
      "name": "Rock_Calcite"
    },
    {
      "x": 10,
      "y": 7,
      "z": 8,
      "name": "Rock_Calcite"
    },
    {
      "x": 10,
      "y": 8,
      "z": 8,
      "name": "Rock_Calcite"
    },
    {
      "x": 10,
      "y": 9,
      "z": 8,
      "name": "Rock_Calcite"
    },
    {
      "x": 10,
      "y": 10,
      "z": 8,
      "name": "Rock_Calcite"
    },
    {
      "x": 10,
      "y": 11,
      "z": 8,
      "name": "Rock_Calcite"
    },
    {
      "x": 10,
      "y": 12,
      "z": 8,
      "name": "Rock_Calcite"
    },
    {
      "x": 10,
      "y": 1,
      "z": 9,
      "name": "Rock_Calcite"
    },
    {
      "x": 10,
      "y": 2,
      "z": 9,
      "name": "Rock_Calcite"
    },
    {
      "x": 10,
      "y": 3,
      "z": 9,
      "name": "Rock_Calcite"
    },
    {
      "x": 10,
      "y": 4,
      "z": 9,
      "name": "Rock_Calcite"
    },
    {
      "x": 10,
      "y": 5,
      "z": 9,
      "name": "Rock_Calcite"
    },
    {
      "x": 10,
      "y": 6,
      "z": 9,
      "name": "Rock_Calcite"
    },
    {
      "x": 10,
      "y": 7,
      "z": 9,
      "name": "Rock_Calcite"
    },
    {
      "x": 10,
      "y": 8,
      "z": 9,
      "name": "Rock_Calcite"
    },
    {
      "x": 10,
      "y": 9,
      "z": 9,
      "name": "Rock_Calcite"
    },
    {
      "x": 10,
      "y": 10,
      "z": 9,
      "name": "Rock_Calcite"
    },
    {
      "x": 10,
      "y": 11,
      "z": 9,
      "name": "Rock_Calcite"
    },
    {
      "x": 10,
      "y": 12,
      "z": 9,
      "name": "Rock_Calcite"
    },
    {
      "x": 10,
      "y": 1,
      "z": 10,
      "name": "Rock_Calcite"
    },
    {
      "x": 10,
      "y": 2,
      "z": 10,
      "name": "Rock_Calcite"
    },
    {
      "x": 10,
      "y": 3,
      "z": 10,
      "name": "Rock_Calcite"
    },
    {
      "x": 10,
      "y": 4,
      "z": 10,
      "name": "Rock_Calcite"
    },
    {
      "x": 10,
      "y": 5,
      "z": 10,
      "name": "Rock_Calcite"
    },
    {
      "x": 10,
      "y": 6,
      "z": 10,
      "name": "Rock_Calcite"
    },
    {
      "x": 10,
      "y": 7,
      "z": 10,
      "name": "Rock_Calcite"
    },
    {
      "x": 10,
      "y": 8,
      "z": 10,
      "name": "Rock_Calcite"
    },
    {
      "x": 10,
      "y": 9,
      "z": 10,
      "name": "Rock_Calcite"
    },
    {
      "x": 10,
      "y": 10,
      "z": 10,
      "name": "Rock_Calcite"
    },
    {
      "x": 10,
      "y": 11,
      "z": 10,
      "name": "Rock_Calcite"
    },
    {
      "x": 10,
      "y": 12,
      "z": 10,
      "name": "Rock_Calcite"
    },
    {
      "x": 10,
      "y": 13,
      "z": 10,
      "name": "Rock_Calcite"
    },
    {
      "x": 10,
      "y": 1,
      "z": 11,
      "name": "Rock_Calcite"
    },
    {
      "x": 10,
      "y": 2,
      "z": 11,
      "name": "Rock_Calcite"
    },
    {
      "x": 10,
      "y": 3,
      "z": 11,
      "name": "Rock_Calcite"
    },
    {
      "x": 10,
      "y": 4,
      "z": 11,
      "name": "Rock_Calcite"
    },
    {
      "x": 10,
      "y": 5,
      "z": 11,
      "name": "Rock_Calcite"
    },
    {
      "x": 10,
      "y": 6,
      "z": 11,
      "name": "Rock_Calcite"
    },
    {
      "x": 10,
      "y": 7,
      "z": 11,
      "name": "Rock_Calcite"
    },
    {
      "x": 10,
      "y": 8,
      "z": 11,
      "name": "Rock_Calcite"
    },
    {
      "x": 10,
      "y": 9,
      "z": 11,
      "name": "Rock_Calcite"
    },
    {
      "x": 10,
      "y": 10,
      "z": 11,
      "name": "Rock_Calcite"
    },
    {
      "x": 10,
      "y": 11,
      "z": 11,
      "name": "Rock_Calcite"
    },
    {
      "x": 10,
      "y": 12,
      "z": 11,
      "name": "Rock_Calcite"
    },
    {
      "x": 10,
      "y": 13,
      "z": 11,
      "name": "Rock_Calcite"
    },
    {
      "x": 10,
      "y": 1,
      "z": 12,
      "name": "Rock_Calcite"
    },
    {
      "x": 10,
      "y": 2,
      "z": 12,
      "name": "Rock_Calcite"
    },
    {
      "x": 10,
      "y": 3,
      "z": 12,
      "name": "Rock_Calcite"
    },
    {
      "x": 10,
      "y": 4,
      "z": 12,
      "name": "Rock_Calcite"
    },
    {
      "x": 10,
      "y": 5,
      "z": 12,
      "name": "Rock_Calcite"
    },
    {
      "x": 10,
      "y": 6,
      "z": 12,
      "name": "Rock_Calcite"
    },
    {
      "x": 10,
      "y": 7,
      "z": 12,
      "name": "Rock_Calcite"
    },
    {
      "x": 10,
      "y": 8,
      "z": 12,
      "name": "Rock_Calcite"
    },
    {
      "x": 10,
      "y": 9,
      "z": 12,
      "name": "Rock_Calcite"
    },
    {
      "x": 10,
      "y": 10,
      "z": 12,
      "name": "Rock_Calcite"
    },
    {
      "x": 10,
      "y": 11,
      "z": 12,
      "name": "Rock_Calcite"
    },
    {
      "x": 10,
      "y": 12,
      "z": 12,
      "name": "Rock_Calcite"
    },
    {
      "x": 10,
      "y": 13,
      "z": 12,
      "name": "Rock_Calcite"
    },
    {
      "x": 10,
      "y": 1,
      "z": 13,
      "name": "Rock_Calcite"
    },
    {
      "x": 10,
      "y": 2,
      "z": 13,
      "name": "Rock_Calcite"
    },
    {
      "x": 10,
      "y": 3,
      "z": 13,
      "name": "Rock_Calcite"
    },
    {
      "x": 10,
      "y": 4,
      "z": 13,
      "name": "Rock_Calcite"
    },
    {
      "x": 10,
      "y": 5,
      "z": 13,
      "name": "Rock_Calcite"
    },
    {
      "x": 10,
      "y": 6,
      "z": 13,
      "name": "Rock_Calcite"
    },
    {
      "x": 10,
      "y": 7,
      "z": 13,
      "name": "Rock_Calcite"
    },
    {
      "x": 10,
      "y": 8,
      "z": 13,
      "name": "Rock_Calcite"
    },
    {
      "x": 10,
      "y": 9,
      "z": 13,
      "name": "Rock_Calcite"
    },
    {
      "x": 10,
      "y": 10,
      "z": 13,
      "name": "Rock_Calcite"
    },
    {
      "x": 10,
      "y": 11,
      "z": 13,
      "name": "Rock_Calcite"
    },
    {
      "x": 10,
      "y": 12,
      "z": 13,
      "name": "Rock_Calcite"
    },
    {
      "x": 10,
      "y": 13,
      "z": 13,
      "name": "Rock_Calcite"
    },
    {
      "x": 10,
      "y": 6,
      "z": 14,
      "name": "Rock_Calcite"
    },
    {
      "x": 10,
      "y": 7,
      "z": 14,
      "name": "Rock_Calcite"
    },
    {
      "x": 10,
      "y": 8,
      "z": 14,
      "name": "Rock_Calcite"
    },
    {
      "x": 10,
      "y": 9,
      "z": 14,
      "name": "Rock_Calcite"
    },
    {
      "x": 10,
      "y": 10,
      "z": 14,
      "name": "Rock_Calcite"
    },
    {
      "x": 10,
      "y": 11,
      "z": 14,
      "name": "Rock_Calcite"
    },
    {
      "x": 10,
      "y": 12,
      "z": 14,
      "name": "Rock_Calcite"
    },
    {
      "x": 10,
      "y": 13,
      "z": 14,
      "name": "Rock_Calcite"
    },
    {
      "x": 11,
      "y": 6,
      "z": 4,
      "name": "Rock_Calcite"
    },
    {
      "x": 11,
      "y": 7,
      "z": 4,
      "name": "Rock_Calcite"
    },
    {
      "x": 11,
      "y": 8,
      "z": 4,
      "name": "Rock_Calcite"
    },
    {
      "x": 11,
      "y": 9,
      "z": 4,
      "name": "Rock_Calcite"
    },
    {
      "x": 11,
      "y": 10,
      "z": 4,
      "name": "Rock_Calcite"
    },
    {
      "x": 11,
      "y": 11,
      "z": 4,
      "name": "Rock_Calcite"
    },
    {
      "x": 11,
      "y": 12,
      "z": 4,
      "name": "Rock_Calcite"
    },
    {
      "x": 11,
      "y": 2,
      "z": 5,
      "name": "Rock_Calcite"
    },
    {
      "x": 11,
      "y": 3,
      "z": 5,
      "name": "Rock_Calcite"
    },
    {
      "x": 11,
      "y": 4,
      "z": 5,
      "name": "Rock_Calcite"
    },
    {
      "x": 11,
      "y": 5,
      "z": 5,
      "name": "Rock_Calcite"
    },
    {
      "x": 11,
      "y": 6,
      "z": 5,
      "name": "Rock_Calcite"
    },
    {
      "x": 11,
      "y": 7,
      "z": 5,
      "name": "Rock_Calcite"
    },
    {
      "x": 11,
      "y": 8,
      "z": 5,
      "name": "Rock_Calcite"
    },
    {
      "x": 11,
      "y": 9,
      "z": 5,
      "name": "Rock_Calcite"
    },
    {
      "x": 11,
      "y": 10,
      "z": 5,
      "name": "Rock_Calcite"
    },
    {
      "x": 11,
      "y": 11,
      "z": 5,
      "name": "Rock_Calcite"
    },
    {
      "x": 11,
      "y": 12,
      "z": 5,
      "name": "Rock_Calcite"
    },
    {
      "x": 11,
      "y": 1,
      "z": 6,
      "name": "Rock_Calcite"
    },
    {
      "x": 11,
      "y": 2,
      "z": 6,
      "name": "Rock_Calcite"
    },
    {
      "x": 11,
      "y": 3,
      "z": 6,
      "name": "Rock_Calcite"
    },
    {
      "x": 11,
      "y": 4,
      "z": 6,
      "name": "Rock_Calcite"
    },
    {
      "x": 11,
      "y": 5,
      "z": 6,
      "name": "Rock_Calcite"
    },
    {
      "x": 11,
      "y": 6,
      "z": 6,
      "name": "Rock_Calcite"
    },
    {
      "x": 11,
      "y": 7,
      "z": 6,
      "name": "Rock_Calcite"
    },
    {
      "x": 11,
      "y": 8,
      "z": 6,
      "name": "Rock_Calcite"
    },
    {
      "x": 11,
      "y": 9,
      "z": 6,
      "name": "Rock_Calcite"
    },
    {
      "x": 11,
      "y": 10,
      "z": 6,
      "name": "Rock_Calcite"
    },
    {
      "x": 11,
      "y": 11,
      "z": 6,
      "name": "Rock_Calcite"
    },
    {
      "x": 11,
      "y": 12,
      "z": 6,
      "name": "Rock_Calcite"
    },
    {
      "x": 11,
      "y": 1,
      "z": 7,
      "name": "Rock_Calcite"
    },
    {
      "x": 11,
      "y": 2,
      "z": 7,
      "name": "Rock_Calcite"
    },
    {
      "x": 11,
      "y": 3,
      "z": 7,
      "name": "Rock_Calcite"
    },
    {
      "x": 11,
      "y": 4,
      "z": 7,
      "name": "Rock_Calcite"
    },
    {
      "x": 11,
      "y": 5,
      "z": 7,
      "name": "Rock_Calcite"
    },
    {
      "x": 11,
      "y": 6,
      "z": 7,
      "name": "Rock_Calcite"
    },
    {
      "x": 11,
      "y": 7,
      "z": 7,
      "name": "Rock_Calcite"
    },
    {
      "x": 11,
      "y": 8,
      "z": 7,
      "name": "Rock_Calcite"
    },
    {
      "x": 11,
      "y": 9,
      "z": 7,
      "name": "Rock_Calcite"
    },
    {
      "x": 11,
      "y": 10,
      "z": 7,
      "name": "Rock_Calcite"
    },
    {
      "x": 11,
      "y": 11,
      "z": 7,
      "name": "Rock_Calcite"
    },
    {
      "x": 11,
      "y": 12,
      "z": 7,
      "name": "Rock_Calcite"
    },
    {
      "x": 11,
      "y": 1,
      "z": 8,
      "name": "Rock_Calcite"
    },
    {
      "x": 11,
      "y": 2,
      "z": 8,
      "name": "Rock_Calcite"
    },
    {
      "x": 11,
      "y": 3,
      "z": 8,
      "name": "Rock_Calcite"
    },
    {
      "x": 11,
      "y": 4,
      "z": 8,
      "name": "Rock_Calcite"
    },
    {
      "x": 11,
      "y": 5,
      "z": 8,
      "name": "Rock_Calcite"
    },
    {
      "x": 11,
      "y": 6,
      "z": 8,
      "name": "Rock_Calcite"
    },
    {
      "x": 11,
      "y": 7,
      "z": 8,
      "name": "Rock_Calcite"
    },
    {
      "x": 11,
      "y": 8,
      "z": 8,
      "name": "Rock_Calcite"
    },
    {
      "x": 11,
      "y": 9,
      "z": 8,
      "name": "Rock_Calcite"
    },
    {
      "x": 11,
      "y": 10,
      "z": 8,
      "name": "Rock_Calcite"
    },
    {
      "x": 11,
      "y": 11,
      "z": 8,
      "name": "Rock_Calcite"
    },
    {
      "x": 11,
      "y": 12,
      "z": 8,
      "name": "Rock_Calcite"
    },
    {
      "x": 11,
      "y": 1,
      "z": 9,
      "name": "Rock_Calcite"
    },
    {
      "x": 11,
      "y": 2,
      "z": 9,
      "name": "Rock_Calcite"
    },
    {
      "x": 11,
      "y": 3,
      "z": 9,
      "name": "Rock_Calcite"
    },
    {
      "x": 11,
      "y": 4,
      "z": 9,
      "name": "Rock_Calcite"
    },
    {
      "x": 11,
      "y": 5,
      "z": 9,
      "name": "Rock_Calcite"
    },
    {
      "x": 11,
      "y": 6,
      "z": 9,
      "name": "Rock_Calcite"
    },
    {
      "x": 11,
      "y": 7,
      "z": 9,
      "name": "Rock_Calcite"
    },
    {
      "x": 11,
      "y": 8,
      "z": 9,
      "name": "Rock_Calcite"
    },
    {
      "x": 11,
      "y": 9,
      "z": 9,
      "name": "Rock_Calcite"
    },
    {
      "x": 11,
      "y": 10,
      "z": 9,
      "name": "Rock_Calcite"
    },
    {
      "x": 11,
      "y": 11,
      "z": 9,
      "name": "Rock_Calcite"
    },
    {
      "x": 11,
      "y": 12,
      "z": 9,
      "name": "Rock_Calcite"
    },
    {
      "x": 11,
      "y": 13,
      "z": 9,
      "name": "Rock_Calcite"
    },
    {
      "x": 11,
      "y": 1,
      "z": 10,
      "name": "Rock_Calcite"
    },
    {
      "x": 11,
      "y": 2,
      "z": 10,
      "name": "Rock_Calcite"
    },
    {
      "x": 11,
      "y": 3,
      "z": 10,
      "name": "Rock_Calcite"
    },
    {
      "x": 11,
      "y": 4,
      "z": 10,
      "name": "Rock_Calcite"
    },
    {
      "x": 11,
      "y": 5,
      "z": 10,
      "name": "Rock_Calcite"
    },
    {
      "x": 11,
      "y": 6,
      "z": 10,
      "name": "Rock_Calcite"
    },
    {
      "x": 11,
      "y": 7,
      "z": 10,
      "name": "Rock_Calcite"
    },
    {
      "x": 11,
      "y": 8,
      "z": 10,
      "name": "Rock_Calcite"
    },
    {
      "x": 11,
      "y": 9,
      "z": 10,
      "name": "Rock_Calcite"
    },
    {
      "x": 11,
      "y": 10,
      "z": 10,
      "name": "Rock_Calcite"
    },
    {
      "x": 11,
      "y": 11,
      "z": 10,
      "name": "Rock_Calcite"
    },
    {
      "x": 11,
      "y": 12,
      "z": 10,
      "name": "Rock_Calcite"
    },
    {
      "x": 11,
      "y": 13,
      "z": 10,
      "name": "Rock_Calcite"
    },
    {
      "x": 11,
      "y": 1,
      "z": 11,
      "name": "Rock_Calcite"
    },
    {
      "x": 11,
      "y": 2,
      "z": 11,
      "name": "Rock_Calcite"
    },
    {
      "x": 11,
      "y": 3,
      "z": 11,
      "name": "Rock_Calcite"
    },
    {
      "x": 11,
      "y": 4,
      "z": 11,
      "name": "Rock_Calcite"
    },
    {
      "x": 11,
      "y": 5,
      "z": 11,
      "name": "Rock_Calcite"
    },
    {
      "x": 11,
      "y": 6,
      "z": 11,
      "name": "Rock_Calcite"
    },
    {
      "x": 11,
      "y": 7,
      "z": 11,
      "name": "Rock_Calcite"
    },
    {
      "x": 11,
      "y": 8,
      "z": 11,
      "name": "Rock_Calcite"
    },
    {
      "x": 11,
      "y": 9,
      "z": 11,
      "name": "Rock_Calcite"
    },
    {
      "x": 11,
      "y": 10,
      "z": 11,
      "name": "Rock_Calcite"
    },
    {
      "x": 11,
      "y": 11,
      "z": 11,
      "name": "Rock_Calcite"
    },
    {
      "x": 11,
      "y": 12,
      "z": 11,
      "name": "Rock_Calcite"
    },
    {
      "x": 11,
      "y": 13,
      "z": 11,
      "name": "Rock_Calcite"
    },
    {
      "x": 11,
      "y": 1,
      "z": 12,
      "name": "Rock_Calcite"
    },
    {
      "x": 11,
      "y": 2,
      "z": 12,
      "name": "Rock_Calcite"
    },
    {
      "x": 11,
      "y": 3,
      "z": 12,
      "name": "Rock_Calcite"
    },
    {
      "x": 11,
      "y": 4,
      "z": 12,
      "name": "Rock_Calcite"
    },
    {
      "x": 11,
      "y": 5,
      "z": 12,
      "name": "Rock_Calcite"
    },
    {
      "x": 11,
      "y": 6,
      "z": 12,
      "name": "Rock_Calcite"
    },
    {
      "x": 11,
      "y": 7,
      "z": 12,
      "name": "Rock_Calcite"
    },
    {
      "x": 11,
      "y": 8,
      "z": 12,
      "name": "Rock_Calcite"
    },
    {
      "x": 11,
      "y": 9,
      "z": 12,
      "name": "Rock_Calcite"
    },
    {
      "x": 11,
      "y": 10,
      "z": 12,
      "name": "Rock_Calcite"
    },
    {
      "x": 11,
      "y": 11,
      "z": 12,
      "name": "Rock_Calcite"
    },
    {
      "x": 11,
      "y": 12,
      "z": 12,
      "name": "Rock_Calcite"
    },
    {
      "x": 11,
      "y": 13,
      "z": 12,
      "name": "Rock_Calcite"
    },
    {
      "x": 11,
      "y": 4,
      "z": 13,
      "name": "Rock_Calcite"
    },
    {
      "x": 11,
      "y": 5,
      "z": 13,
      "name": "Rock_Calcite"
    },
    {
      "x": 11,
      "y": 6,
      "z": 13,
      "name": "Rock_Calcite"
    },
    {
      "x": 11,
      "y": 7,
      "z": 13,
      "name": "Rock_Calcite"
    },
    {
      "x": 11,
      "y": 8,
      "z": 13,
      "name": "Rock_Calcite"
    },
    {
      "x": 11,
      "y": 9,
      "z": 13,
      "name": "Rock_Calcite"
    },
    {
      "x": 11,
      "y": 10,
      "z": 13,
      "name": "Rock_Calcite"
    },
    {
      "x": 11,
      "y": 11,
      "z": 13,
      "name": "Rock_Calcite"
    },
    {
      "x": 11,
      "y": 12,
      "z": 13,
      "name": "Rock_Calcite"
    },
    {
      "x": 11,
      "y": 13,
      "z": 13,
      "name": "Rock_Calcite"
    },
    {
      "x": 11,
      "y": 9,
      "z": 14,
      "name": "Rock_Calcite"
    },
    {
      "x": 11,
      "y": 10,
      "z": 14,
      "name": "Rock_Calcite"
    },
    {
      "x": 11,
      "y": 11,
      "z": 14,
      "name": "Rock_Calcite"
    },
    {
      "x": 11,
      "y": 12,
      "z": 14,
      "name": "Rock_Calcite"
    },
    {
      "x": 11,
      "y": 13,
      "z": 14,
      "name": "Rock_Calcite"
    },
    {
      "x": 12,
      "y": 4,
      "z": 5,
      "name": "Rock_Calcite"
    },
    {
      "x": 12,
      "y": 5,
      "z": 5,
      "name": "Rock_Calcite"
    },
    {
      "x": 12,
      "y": 6,
      "z": 5,
      "name": "Rock_Calcite"
    },
    {
      "x": 12,
      "y": 7,
      "z": 5,
      "name": "Rock_Calcite"
    },
    {
      "x": 12,
      "y": 8,
      "z": 5,
      "name": "Rock_Calcite"
    },
    {
      "x": 12,
      "y": 9,
      "z": 5,
      "name": "Rock_Calcite"
    },
    {
      "x": 12,
      "y": 10,
      "z": 5,
      "name": "Rock_Calcite"
    },
    {
      "x": 12,
      "y": 11,
      "z": 5,
      "name": "Rock_Calcite"
    },
    {
      "x": 12,
      "y": 12,
      "z": 5,
      "name": "Rock_Calcite"
    },
    {
      "x": 12,
      "y": 3,
      "z": 6,
      "name": "Rock_Calcite"
    },
    {
      "x": 12,
      "y": 4,
      "z": 6,
      "name": "Rock_Calcite"
    },
    {
      "x": 12,
      "y": 5,
      "z": 6,
      "name": "Rock_Calcite"
    },
    {
      "x": 12,
      "y": 6,
      "z": 6,
      "name": "Rock_Calcite"
    },
    {
      "x": 12,
      "y": 7,
      "z": 6,
      "name": "Rock_Calcite"
    },
    {
      "x": 12,
      "y": 8,
      "z": 6,
      "name": "Rock_Calcite"
    },
    {
      "x": 12,
      "y": 9,
      "z": 6,
      "name": "Rock_Calcite"
    },
    {
      "x": 12,
      "y": 10,
      "z": 6,
      "name": "Rock_Calcite"
    },
    {
      "x": 12,
      "y": 11,
      "z": 6,
      "name": "Rock_Calcite"
    },
    {
      "x": 12,
      "y": 12,
      "z": 6,
      "name": "Rock_Calcite"
    },
    {
      "x": 12,
      "y": 1,
      "z": 7,
      "name": "Rock_Calcite"
    },
    {
      "x": 12,
      "y": 2,
      "z": 7,
      "name": "Rock_Calcite"
    },
    {
      "x": 12,
      "y": 3,
      "z": 7,
      "name": "Rock_Calcite"
    },
    {
      "x": 12,
      "y": 4,
      "z": 7,
      "name": "Rock_Calcite"
    },
    {
      "x": 12,
      "y": 5,
      "z": 7,
      "name": "Rock_Calcite"
    },
    {
      "x": 12,
      "y": 6,
      "z": 7,
      "name": "Rock_Calcite"
    },
    {
      "x": 12,
      "y": 7,
      "z": 7,
      "name": "Rock_Calcite"
    },
    {
      "x": 12,
      "y": 8,
      "z": 7,
      "name": "Rock_Calcite"
    },
    {
      "x": 12,
      "y": 9,
      "z": 7,
      "name": "Rock_Calcite"
    },
    {
      "x": 12,
      "y": 10,
      "z": 7,
      "name": "Rock_Calcite"
    },
    {
      "x": 12,
      "y": 11,
      "z": 7,
      "name": "Rock_Calcite"
    },
    {
      "x": 12,
      "y": 12,
      "z": 7,
      "name": "Rock_Calcite"
    },
    {
      "x": 12,
      "y": 1,
      "z": 8,
      "name": "Rock_Calcite"
    },
    {
      "x": 12,
      "y": 2,
      "z": 8,
      "name": "Rock_Calcite"
    },
    {
      "x": 12,
      "y": 3,
      "z": 8,
      "name": "Rock_Calcite"
    },
    {
      "x": 12,
      "y": 4,
      "z": 8,
      "name": "Rock_Calcite"
    },
    {
      "x": 12,
      "y": 5,
      "z": 8,
      "name": "Rock_Calcite"
    },
    {
      "x": 12,
      "y": 6,
      "z": 8,
      "name": "Rock_Calcite"
    },
    {
      "x": 12,
      "y": 7,
      "z": 8,
      "name": "Rock_Calcite"
    },
    {
      "x": 12,
      "y": 8,
      "z": 8,
      "name": "Rock_Calcite"
    },
    {
      "x": 12,
      "y": 9,
      "z": 8,
      "name": "Rock_Calcite"
    },
    {
      "x": 12,
      "y": 10,
      "z": 8,
      "name": "Rock_Calcite"
    },
    {
      "x": 12,
      "y": 11,
      "z": 8,
      "name": "Rock_Calcite"
    },
    {
      "x": 12,
      "y": 12,
      "z": 8,
      "name": "Rock_Calcite"
    },
    {
      "x": 12,
      "y": 1,
      "z": 9,
      "name": "Rock_Calcite"
    },
    {
      "x": 12,
      "y": 2,
      "z": 9,
      "name": "Rock_Calcite"
    },
    {
      "x": 12,
      "y": 3,
      "z": 9,
      "name": "Rock_Calcite"
    },
    {
      "x": 12,
      "y": 4,
      "z": 9,
      "name": "Rock_Calcite"
    },
    {
      "x": 12,
      "y": 5,
      "z": 9,
      "name": "Rock_Calcite"
    },
    {
      "x": 12,
      "y": 6,
      "z": 9,
      "name": "Rock_Calcite"
    },
    {
      "x": 12,
      "y": 7,
      "z": 9,
      "name": "Rock_Calcite"
    },
    {
      "x": 12,
      "y": 8,
      "z": 9,
      "name": "Rock_Calcite"
    },
    {
      "x": 12,
      "y": 9,
      "z": 9,
      "name": "Rock_Calcite"
    },
    {
      "x": 12,
      "y": 10,
      "z": 9,
      "name": "Rock_Calcite"
    },
    {
      "x": 12,
      "y": 11,
      "z": 9,
      "name": "Rock_Calcite"
    },
    {
      "x": 12,
      "y": 12,
      "z": 9,
      "name": "Rock_Calcite"
    },
    {
      "x": 12,
      "y": 13,
      "z": 9,
      "name": "Rock_Calcite"
    },
    {
      "x": 12,
      "y": 1,
      "z": 10,
      "name": "Rock_Calcite"
    },
    {
      "x": 12,
      "y": 2,
      "z": 10,
      "name": "Rock_Calcite"
    },
    {
      "x": 12,
      "y": 3,
      "z": 10,
      "name": "Rock_Calcite"
    },
    {
      "x": 12,
      "y": 4,
      "z": 10,
      "name": "Rock_Calcite"
    },
    {
      "x": 12,
      "y": 5,
      "z": 10,
      "name": "Rock_Calcite"
    },
    {
      "x": 12,
      "y": 6,
      "z": 10,
      "name": "Rock_Calcite"
    },
    {
      "x": 12,
      "y": 7,
      "z": 10,
      "name": "Rock_Calcite"
    },
    {
      "x": 12,
      "y": 8,
      "z": 10,
      "name": "Rock_Calcite"
    },
    {
      "x": 12,
      "y": 9,
      "z": 10,
      "name": "Rock_Calcite"
    },
    {
      "x": 12,
      "y": 10,
      "z": 10,
      "name": "Rock_Calcite"
    },
    {
      "x": 12,
      "y": 11,
      "z": 10,
      "name": "Rock_Calcite"
    },
    {
      "x": 12,
      "y": 12,
      "z": 10,
      "name": "Rock_Calcite"
    },
    {
      "x": 12,
      "y": 13,
      "z": 10,
      "name": "Rock_Calcite"
    },
    {
      "x": 12,
      "y": 2,
      "z": 11,
      "name": "Rock_Calcite"
    },
    {
      "x": 12,
      "y": 3,
      "z": 11,
      "name": "Rock_Calcite"
    },
    {
      "x": 12,
      "y": 4,
      "z": 11,
      "name": "Rock_Calcite"
    },
    {
      "x": 12,
      "y": 5,
      "z": 11,
      "name": "Rock_Calcite"
    },
    {
      "x": 12,
      "y": 6,
      "z": 11,
      "name": "Rock_Calcite"
    },
    {
      "x": 12,
      "y": 7,
      "z": 11,
      "name": "Rock_Calcite"
    },
    {
      "x": 12,
      "y": 8,
      "z": 11,
      "name": "Rock_Calcite"
    },
    {
      "x": 12,
      "y": 9,
      "z": 11,
      "name": "Rock_Calcite"
    },
    {
      "x": 12,
      "y": 10,
      "z": 11,
      "name": "Rock_Calcite"
    },
    {
      "x": 12,
      "y": 11,
      "z": 11,
      "name": "Rock_Calcite"
    },
    {
      "x": 12,
      "y": 12,
      "z": 11,
      "name": "Rock_Calcite"
    },
    {
      "x": 12,
      "y": 13,
      "z": 11,
      "name": "Rock_Calcite"
    },
    {
      "x": 12,
      "y": 3,
      "z": 12,
      "name": "Rock_Calcite"
    },
    {
      "x": 12,
      "y": 4,
      "z": 12,
      "name": "Rock_Calcite"
    },
    {
      "x": 12,
      "y": 5,
      "z": 12,
      "name": "Rock_Calcite"
    },
    {
      "x": 12,
      "y": 6,
      "z": 12,
      "name": "Rock_Calcite"
    },
    {
      "x": 12,
      "y": 7,
      "z": 12,
      "name": "Rock_Calcite"
    },
    {
      "x": 12,
      "y": 8,
      "z": 12,
      "name": "Rock_Calcite"
    },
    {
      "x": 12,
      "y": 9,
      "z": 12,
      "name": "Rock_Calcite"
    },
    {
      "x": 12,
      "y": 10,
      "z": 12,
      "name": "Rock_Calcite"
    },
    {
      "x": 12,
      "y": 11,
      "z": 12,
      "name": "Rock_Calcite"
    },
    {
      "x": 12,
      "y": 12,
      "z": 12,
      "name": "Rock_Calcite"
    },
    {
      "x": 12,
      "y": 13,
      "z": 12,
      "name": "Rock_Calcite"
    },
    {
      "x": 12,
      "y": 7,
      "z": 13,
      "name": "Rock_Calcite"
    },
    {
      "x": 12,
      "y": 8,
      "z": 13,
      "name": "Rock_Calcite"
    },
    {
      "x": 12,
      "y": 9,
      "z": 13,
      "name": "Rock_Calcite"
    },
    {
      "x": 12,
      "y": 10,
      "z": 13,
      "name": "Rock_Calcite"
    },
    {
      "x": 12,
      "y": 11,
      "z": 13,
      "name": "Rock_Calcite"
    },
    {
      "x": 12,
      "y": 12,
      "z": 13,
      "name": "Rock_Calcite"
    },
    {
      "x": 12,
      "y": 13,
      "z": 13,
      "name": "Rock_Calcite"
    },
    {
      "x": 12,
      "y": 8,
      "z": 14,
      "name": "Rock_Calcite"
    },
    {
      "x": 12,
      "y": 9,
      "z": 14,
      "name": "Rock_Calcite"
    },
    {
      "x": 12,
      "y": 10,
      "z": 14,
      "name": "Rock_Calcite"
    },
    {
      "x": 12,
      "y": 11,
      "z": 14,
      "name": "Rock_Calcite"
    },
    {
      "x": 12,
      "y": 12,
      "z": 14,
      "name": "Rock_Calcite"
    },
    {
      "x": 12,
      "y": 13,
      "z": 14,
      "name": "Rock_Calcite"
    },
    {
      "x": 13,
      "y": 6,
      "z": 5,
      "name": "Rock_Calcite"
    },
    {
      "x": 13,
      "y": 7,
      "z": 5,
      "name": "Rock_Calcite"
    },
    {
      "x": 13,
      "y": 8,
      "z": 5,
      "name": "Rock_Calcite"
    },
    {
      "x": 13,
      "y": 9,
      "z": 5,
      "name": "Rock_Calcite"
    },
    {
      "x": 13,
      "y": 10,
      "z": 5,
      "name": "Rock_Calcite"
    },
    {
      "x": 13,
      "y": 11,
      "z": 5,
      "name": "Rock_Calcite"
    },
    {
      "x": 13,
      "y": 12,
      "z": 5,
      "name": "Rock_Calcite"
    },
    {
      "x": 13,
      "y": 6,
      "z": 6,
      "name": "Rock_Calcite"
    },
    {
      "x": 13,
      "y": 7,
      "z": 6,
      "name": "Rock_Calcite"
    },
    {
      "x": 13,
      "y": 8,
      "z": 6,
      "name": "Rock_Calcite"
    },
    {
      "x": 13,
      "y": 9,
      "z": 6,
      "name": "Rock_Calcite"
    },
    {
      "x": 13,
      "y": 10,
      "z": 6,
      "name": "Rock_Calcite"
    },
    {
      "x": 13,
      "y": 11,
      "z": 6,
      "name": "Rock_Calcite"
    },
    {
      "x": 13,
      "y": 12,
      "z": 6,
      "name": "Rock_Calcite"
    },
    {
      "x": 13,
      "y": 5,
      "z": 7,
      "name": "Rock_Calcite"
    },
    {
      "x": 13,
      "y": 6,
      "z": 7,
      "name": "Rock_Calcite"
    },
    {
      "x": 13,
      "y": 7,
      "z": 7,
      "name": "Rock_Calcite"
    },
    {
      "x": 13,
      "y": 8,
      "z": 7,
      "name": "Rock_Calcite"
    },
    {
      "x": 13,
      "y": 9,
      "z": 7,
      "name": "Rock_Calcite"
    },
    {
      "x": 13,
      "y": 10,
      "z": 7,
      "name": "Rock_Calcite"
    },
    {
      "x": 13,
      "y": 11,
      "z": 7,
      "name": "Rock_Calcite"
    },
    {
      "x": 13,
      "y": 12,
      "z": 7,
      "name": "Rock_Calcite"
    },
    {
      "x": 13,
      "y": 4,
      "z": 8,
      "name": "Rock_Calcite"
    },
    {
      "x": 13,
      "y": 5,
      "z": 8,
      "name": "Rock_Calcite"
    },
    {
      "x": 13,
      "y": 6,
      "z": 8,
      "name": "Rock_Calcite"
    },
    {
      "x": 13,
      "y": 7,
      "z": 8,
      "name": "Rock_Calcite"
    },
    {
      "x": 13,
      "y": 8,
      "z": 8,
      "name": "Rock_Calcite"
    },
    {
      "x": 13,
      "y": 9,
      "z": 8,
      "name": "Rock_Calcite"
    },
    {
      "x": 13,
      "y": 10,
      "z": 8,
      "name": "Rock_Calcite"
    },
    {
      "x": 13,
      "y": 11,
      "z": 8,
      "name": "Rock_Calcite"
    },
    {
      "x": 13,
      "y": 12,
      "z": 8,
      "name": "Rock_Calcite"
    },
    {
      "x": 13,
      "y": 13,
      "z": 8,
      "name": "Rock_Calcite"
    },
    {
      "x": 13,
      "y": 4,
      "z": 9,
      "name": "Rock_Calcite"
    },
    {
      "x": 13,
      "y": 5,
      "z": 9,
      "name": "Rock_Calcite"
    },
    {
      "x": 13,
      "y": 6,
      "z": 9,
      "name": "Rock_Calcite"
    },
    {
      "x": 13,
      "y": 7,
      "z": 9,
      "name": "Rock_Calcite"
    },
    {
      "x": 13,
      "y": 8,
      "z": 9,
      "name": "Rock_Calcite"
    },
    {
      "x": 13,
      "y": 9,
      "z": 9,
      "name": "Rock_Calcite"
    },
    {
      "x": 13,
      "y": 10,
      "z": 9,
      "name": "Rock_Calcite"
    },
    {
      "x": 13,
      "y": 11,
      "z": 9,
      "name": "Rock_Calcite"
    },
    {
      "x": 13,
      "y": 12,
      "z": 9,
      "name": "Rock_Calcite"
    },
    {
      "x": 13,
      "y": 13,
      "z": 9,
      "name": "Rock_Calcite"
    },
    {
      "x": 13,
      "y": 5,
      "z": 10,
      "name": "Rock_Calcite"
    },
    {
      "x": 13,
      "y": 6,
      "z": 10,
      "name": "Rock_Calcite"
    },
    {
      "x": 13,
      "y": 7,
      "z": 10,
      "name": "Rock_Calcite"
    },
    {
      "x": 13,
      "y": 8,
      "z": 10,
      "name": "Rock_Calcite"
    },
    {
      "x": 13,
      "y": 9,
      "z": 10,
      "name": "Rock_Calcite"
    },
    {
      "x": 13,
      "y": 10,
      "z": 10,
      "name": "Rock_Calcite"
    },
    {
      "x": 13,
      "y": 11,
      "z": 10,
      "name": "Rock_Calcite"
    },
    {
      "x": 13,
      "y": 12,
      "z": 10,
      "name": "Rock_Calcite"
    },
    {
      "x": 13,
      "y": 13,
      "z": 10,
      "name": "Rock_Calcite"
    },
    {
      "x": 13,
      "y": 6,
      "z": 11,
      "name": "Rock_Calcite"
    },
    {
      "x": 13,
      "y": 7,
      "z": 11,
      "name": "Rock_Calcite"
    },
    {
      "x": 13,
      "y": 8,
      "z": 11,
      "name": "Rock_Calcite"
    },
    {
      "x": 13,
      "y": 9,
      "z": 11,
      "name": "Rock_Calcite"
    },
    {
      "x": 13,
      "y": 10,
      "z": 11,
      "name": "Rock_Calcite"
    },
    {
      "x": 13,
      "y": 11,
      "z": 11,
      "name": "Rock_Calcite"
    },
    {
      "x": 13,
      "y": 12,
      "z": 11,
      "name": "Rock_Calcite"
    },
    {
      "x": 13,
      "y": 13,
      "z": 11,
      "name": "Rock_Calcite"
    }
  ]
}