{
  "version": 8,
  "blockIdVersion": 10,
  "anchorX": 21,
  "anchorY": 4,
  "anchorZ": 19,
  "blocks": [
    {
      "x": 10,
      "y": 15,
      "z": 23,
      "name": "Plant_Leaves_Crystal"
    },
    {
      "x": 10,
      "y": 15,
      "z": 24,
      "name": "Plant_Leaves_Crystal"
    },
    {
      "x": 11,
      "y": 15,
      "z": 21,
      "name": "Plant_Leaves_Crystal"
    },
    {
      "x": 11,
      "y": 15,
      "z": 22,
      "name": "Plant_Leaves_Crystal"
    },
    {
      "x": 11,
      "y": 15,
      "z": 23,
      "name": "Plant_Leaves_Crystal"
    },
    {
      "x": 11,
      "y": 15,
      "z": 24,
      "name": "Plant_Leaves_Crystal"
    },
    {
      "x": 11,
      "y": 15,
      "z": 25,
      "name": "Plant_Leaves_Crystal"
    },
    {
      "x": 12,
      "y": 15,
      "z": 21,
      "name": "Plant_Leaves_Crystal"
    },
    {
      "x": 12,
      "y": 15,
      "z": 22,
      "name": "Plant_Leaves_Crystal"
    },
    {
      "x": 12,
      "y": 16,
      "z": 22,
      "name": "Plant_Leaves_Crystal"
    },
    {
      "x": 12,
      "y": 15,
      "z": 23,
      "name": "Plant_Leaves_Crystal"
    },
    {
      "x": 12,
      "y": 16,
      "z": 23,
      "name": "Plant_Leaves_Crystal"
    },
    {
      "x": 12,
      "y": 15,
      "z": 24,
      "name": "Plant_Leaves_Crystal"
    },
    {
      "x": 12,
      "y": 15,
      "z": 25,
      "name": "Plant_Leaves_Crystal"
    },
    {
      "x": 12,
      "y": 16,
      "z": 25,
      "name": "Plant_Leaves_Crystal"
    },
    {
      "x": 13,
      "y": 15,
      "z": 20,
      "name": "Plant_Leaves_Crystal"
    },
    {
      "x": 13,
      "y": 15,
      "z": 21,
      "name": "Plant_Leaves_Crystal"
    },
    {
      "x": 13,
      "y": 16,
      "z": 21,
      "name": "Plant_Leaves_Crystal"
    },
    {
      "x": 13,
      "y": 15,
      "z": 22,
      "name": "Plant_Leaves_Crystal"
    },
    {
      "x": 13,
      "y": 16,
      "z": 22,
      "name": "Plant_Leaves_Crystal"
    },
    {
      "x": 13,
      "y": 15,
      "z": 23,
      "name": "Plant_Leaves_Crystal"
    },
    {
      "x": 13,
      "y": 16,
      "z": 23,
      "name": "Plant_Leaves_Crystal"
    },
    {
      "x": 13,
      "y": 15,
      "z": 24,
      "name": "Plant_Leaves_Crystal"
    },
    {
      "x": 13,
      "y": 16,
      "z": 24,
      "name": "Plant_Leaves_Crystal"
    },
    {
      "x": 13,
      "y": 15,
      "z": 25,
      "name": "Plant_Leaves_Crystal"
    },
    {
      "x": 13,
      "y": 16,
      "z": 25,
      "name": "Plant_Leaves_Crystal"
    },
    {
      "x": 13,
      "y": 15,
      "z": 26,
      "name": "Plant_Leaves_Crystal"
    },
    {
      "x": 14,
      "y": 18,
      "z": 11,
      "name": "Plant_Leaves_Crystal"
    },
    {
      "x": 14,
      "y": 18,
      "z": 12,
      "name": "Plant_Leaves_Crystal"
    },
    {
      "x": 14,
      "y": 18,
      "z": 13,
      "name": "Plant_Leaves_Crystal"
    },
    {
      "x": 14,
      "y": 15,
      "z": 17,
      "name": "Plant_Leaves_Crystal"
    },
    {
      "x": 14,
      "y": 15,
      "z": 18,
      "name": "Plant_Leaves_Crystal"
    },
    {
      "x": 14,
      "y": 19,
      "z": 18,
      "name": "Plant_Leaves_Crystal"
    },
    {
      "x": 14,
      "y": 15,
      "z": 19,
      "name": "Plant_Leaves_Crystal"
    },
    {
      "x": 14,
      "y": 19,
      "z": 19,
      "name": "Plant_Leaves_Crystal"
    },
    {
      "x": 14,
      "y": 15,
      "z": 20,
      "name": "Plant_Leaves_Crystal"
    },
    {
      "x": 14,
      "y": 16,
      "z": 20,
      "name": "Plant_Leaves_Crystal"
    },
    {
      "x": 14,
      "y": 16,
      "z": 21,
      "name": "Plant_Leaves_Crystal"
    },
    {
      "x": 14,
      "y": 16,
      "z": 22,
      "name": "Plant_Leaves_Crystal"
    },
    {
      "x": 14,
      "y": 15,
      "z": 23,
      "name": "Wood_Crystal_Branch_Long",
      "rotation": 5
    },
    {
      "x": 14,
      "y": 15,
      "z": 24,
      "name": "Plant_Leaves_Crystal"
    },
    {
      "x": 14,
      "y": 16,
      "z": 24,
      "name": "Plant_Leaves_Crystal"
    },
    {
      "x": 14,
      "y": 15,
      "z": 25,
      "name": "Plant_Leaves_Crystal"
    },
    {
      "x": 14,
      "y": 16,
      "z": 25,
      "name": "Plant_Leaves_Crystal"
    },
    {
      "x": 15,
      "y": 18,
      "z": 10,
      "name": "Plant_Leaves_Crystal"
    },
    {
      "x": 15,
      "y": 18,
      "z": 11,
      "name": "Plant_Leaves_Crystal"
    },
    {
      "x": 15,
      "y": 18,
      "z": 12,
      "name": "Plant_Leaves_Crystal"
    },
    {
      "x": 15,
      "y": 18,
      "z": 13,
      "name": "Plant_Leaves_Crystal"
    },
    {
      "x": 15,
      "y": 15,
      "z": 17,
      "name": "Plant_Leaves_Crystal"
    },
    {
      "x": 15,
      "y": 19,
      "z": 17,
      "name": "Plant_Leaves_Crystal"
    },
    {
      "x": 15,
      "y": 15,
      "z": 18,
      "name": "Plant_Leaves_Crystal"
    },
    {
      "x": 15,
      "y": 19,
      "z": 18,
      "name": "Plant_Leaves_Crystal"
    },
    {
      "x": 15,
      "y": 15,
      "z": 19,
      "name": "Plant_Leaves_Crystal"
    },
    {
      "x": 15,
      "y": 16,
      "z": 19,
      "name": "Plant_Leaves_Crystal"
    },
    {
      "x": 15,
      "y": 19,
      "z": 19,
      "name": "Plant_Leaves_Crystal"
    },
    {
      "x": 15,
      "y": 15,
      "z": 20,
      "name": "Plant_Leaves_Crystal"
    },
    {
      "x": 15,
      "y": 16,
      "z": 20,
      "name": "Plant_Leaves_Crystal"
    },
    {
      "x": 15,
      "y": 19,
      "z": 20,
      "name": "Plant_Leaves_Crystal"
    },
    {
      "x": 15,
      "y": 16,
      "z": 21,
      "name": "Plant_Leaves_Crystal"
    },
    {
      "x": 15,
      "y": 19,
      "z": 21,
      "name": "Plant_Leaves_Crystal"
    },
    {
      "x": 15,
      "y": 15,
      "z": 22,
      "name": "Wood_Crystal_Branch_Long",
      "rotation": 4
    },
    {
      "x": 15,
      "y": 16,
      "z": 22,
      "name": "Plant_Leaves_Crystal"
    },
    {
      "x": 15,
      "y": 15,
      "z": 23,
      "name": "Wood_Crystal_Trunk_Full"
    },
    {
      "x": 15,
      "y": 15,
      "z": 24,
      "name": "Plant_Leaves_Crystal"
    },
    {
      "x": 15,
      "y": 16,
      "z": 24,
      "name": "Plant_Leaves_Crystal"
    },
    {
      "x": 15,
      "y": 15,
      "z": 26,
      "name": "Plant_Leaves_Crystal"
    },
    {
      "x": 16,
      "y": 18,
      "z": 9,
      "name": "Plant_Leaves_Crystal"
    },
    {
      "x": 16,
      "y": 18,
      "z": 10,
      "name": "Plant_Leaves_Crystal"
    },
    {
      "x": 16,
      "y": 18,
      "z": 12,
      "name": "Plant_Leaves_Crystal"
    },
    {
      "x": 16,
      "y": 19,
      "z": 12,
      "name": "Plant_Leaves_Crystal"
    },
    {
      "x": 16,
      "y": 18,
      "z": 13,
      "name": "Wood_Crystal_Branch_Long",
      "rotation": 5
    },
    {
      "x": 16,
      "y": 19,
      "z": 13,
      "name": "Plant_Leaves_Crystal"
    },
    {
      "x": 16,
      "y": 18,
      "z": 14,
      "name": "Plant_Leaves_Crystal"
    },
    {
      "x": 16,
      "y": 18,
      "z": 15,
      "name": "Plant_Leaves_Crystal"
    },
    {
      "x": 16,
      "y": 19,
      "z": 16,
      "name": "Plant_Leaves_Crystal"
    },
    {
      "x": 16,
      "y": 15,
      "z": 17,
      "name": "Plant_Leaves_Crystal"
    },
    {
      "x": 16,
      "y": 19,
      "z": 17,
      "name": "Plant_Leaves_Crystal"
    },
    {
      "x": 16,
      "y": 15,
      "z": 18,
      "name": "Plant_Leaves_Crystal"
    },
    {
      "x": 16,
      "y": 19,
      "z": 18,
      "name": "Plant_Leaves_Crystal"
    },
    {
      "x": 16,
      "y": 15,
      "z": 19,
      "name": "Plant_Leaves_Crystal"
    },
    {
      "x": 16,
      "y": 16,
      "z": 19,
      "name": "Plant_Leaves_Crystal"
    },
    {
      "x": 16,
      "y": 19,
      "z": 19,
      "name": "Plant_Leaves_Crystal"
    },
    {
      "x": 16,
      "y": 20,
      "z": 19,
      "name": "Plant_Leaves_Crystal"
    },
    {
      "x": 16,
      "y": 15,
      "z": 20,
      "name": "Wood_Crystal_Branch_Long",
      "rotation": 5
    },
    {
      "x": 16,
      "y": 16,
      "z": 20,
      "name": "Plant_Leaves_Crystal"
    },
    {
      "x": 16,
      "y": 19,
      "z": 20,
      "name": "Plant_Leaves_Crystal"
    },
    {
      "x": 16,
      "y": 19,
      "z": 21,
      "name": "Plant_Leaves_Crystal"
    },
    {
      "x": 16,
      "y": 16,
      "z": 22,
      "name": "Plant_Leaves_Crystal"
    },
    {
      "x": 16,
      "y": 19,
      "z": 22,
      "name": "Plant_Leaves_Crystal"
    },
    {
      "x": 16,
      "y": 15,
      "z": 23,
      "name": "Wood_Crystal_Trunk_Full"
    },
    {
      "x": 16,
      "y": 16,
      "z": 23,
      "name": "Plant_Leaves_Crystal"
    },
    {
      "x": 16,
      "y": 15,
      "z": 24,
      "name": "Wood_Crystal_Branch_Long",
      "rotation": 4
    },
    {
      "x": 16,
      "y": 16,
      "z": 24,
      "name": "Plant_Leaves_Crystal"
    },
    {
      "x": 16,
      "y": 15,
      "z": 25,
      "name": "Wood_Crystal_Branch_Long",
      "rotation": 4
    },
    {
      "x": 16,
      "y": 16,
      "z": 25,
      "name": "Plant_Leaves_Crystal"
    },
    {
      "x": 16,
      "y": 16,
      "z": 26,
      "name": "Plant_Leaves_Crystal"
    },
    {
      "x": 16,
      "y": 15,
      "z": 27,
      "name": "Plant_Leaves_Crystal"
    },
    {
      "x": 16,
      "y": 15,
      "z": 28,
      "name": "Plant_Leaves_Crystal"
    },
    {
      "x": 17,
      "y": 18,
      "z": 9,
      "name": "Plant_Leaves_Crystal"
    },
    {
      "x": 17,
      "y": 18,
      "z": 10,
      "name": "Plant_Leaves_Crystal"
    },
    {
      "x": 17,
      "y": 19,
      "z": 10,
      "name": "Plant_Leaves_Crystal"
    },
    {
      "x": 17,
      "y": 18,
      "z": 11,
      "name": "Plant_Leaves_Crystal"
    },
    {
      "x": 17,
      "y": 19,
      "z": 11,
      "name": "Plant_Leaves_Crystal"
    },
    {
      "x": 17,
      "y": 18,
      "z": 12,
      "name": "Plant_Leaves_Crystal"
    },
    {
      "x": 17,
      "y": 19,
      "z": 12,
      "name": "Plant_Leaves_Crystal"
    },
    {
      "x": 17,
      "y": 18,
      "z": 13,
      "name": "Wood_Crystal_Branch_Long",
      "rotation": 5
    },
    {
      "x": 17,
      "y": 19,
      "z": 13,
      "name": "Plant_Leaves_Crystal"
    },
    {
      "x": 17,
      "y": 18,
      "z": 14,
      "name": "Plant_Leaves_Crystal"
    },
    {
      "x": 17,
      "y": 19,
      "z": 14,
      "name": "Plant_Leaves_Crystal"
    },
    {
      "x": 17,
      "y": 18,
      "z": 15,
      "name": "Plant_Leaves_Crystal"
    },
    {
      "x": 17,
      "y": 19,
      "z": 15,
      "name": "Plant_Leaves_Crystal"
    },
    {
      "x": 17,
      "y": 19,
      "z": 16,
      "name": "Plant_Leaves_Crystal"
    },
    {
      "x": 17,
      "y": 19,
      "z": 17,
      "name": "Plant_Leaves_Crystal"
    },
    {
      "x": 17,
      "y": 20,
      "z": 17,
      "name": "Plant_Leaves_Crystal"
    },
    {
      "x": 17,
      "y": 19,
      "z": 18,
      "name": "Plant_Leaves_Crystal"
    },
    {
      "x": 17,
      "y": 20,
      "z": 18,
      "name": "Plant_Leaves_Crystal"
    },
    {
      "x": 17,
      "y": 15,
      "z": 19,
      "name": "Plant_Leaves_Crystal"
    },
    {
      "x": 17,
      "y": 16,
      "z": 19,
      "name": "Plant_Leaves_Crystal"
    },
    {
      "x": 17,
      "y": 19,
      "z": 19,
      "name": "Plant_Leaves_Crystal"
    },
    {
      "x": 17,
      "y": 20,
      "z": 19,
      "name": "Plant_Leaves_Crystal"
    },
    {
      "x": 17,
      "y": 15,
      "z": 20,
      "name": "Wood_Crystal_Trunk_Full"
    },
    {
      "x": 17,
      "y": 16,
      "z": 20,
      "name": "Plant_Leaves_Crystal"
    },
    {
      "x": 17,
      "y": 19,
      "z": 20,
      "name": "Plant_Leaves_Crystal"
    },
    {
      "x": 17,
      "y": 20,
      "z": 20,
      "name": "Plant_Leaves_Crystal"
    },
    {
      "x": 17,
      "y": 14,
      "z": 23,
      "name": "Wood_Crystal_Trunk_Full"
    },
    {
      "x": 17,
      "y": 15,
      "z": 23,
      "name": "Wood_Crystal_Trunk_Full"
    },
    {
      "x": 17,
      "y": 16,
      "z": 24,
      "name": "Plant_Leaves_Crystal"
    },
    {
      "x": 17,
      "y": 16,
      "z": 25,
      "name": "Plant_Leaves_Crystal"
    },
    {
      "x": 17,
      "y": 15,
      "z": 26,
      "name": "Plant_Leaves_Crystal"
    },
    {
      "x": 17,
      "y": 16,
      "z": 26,
      "name": "Plant_Leaves_Crystal"
    },
    {
      "x": 17,
      "y": 15,
      "z": 27,
      "name": "Plant_Leaves_Crystal"
    },
    {
      "x": 17,
      "y": 16,
      "z": 27,
      "name": "Plant_Leaves_Crystal"
    },
    {
      "x": 17,
      "y": 15,
      "z": 28,
      "name": "Plant_Leaves_Crystal"
    },
    {
      "x": 17,
      "y": 15,
      "z": 29,
      "name": "Plant_Leaves_Crystal"
    },
    {
      "x": 18,
      "y": 18,
      "z": 6,
      "name": "Plant_Leaves_Crystal"
    },
    {
      "x": 18,
      "y": 18,
      "z": 8,
      "name": "Plant_Leaves_Crystal"
    },
    {
      "x": 18,
      "y": 18,
      "z": 9,
      "name": "Plant_Leaves_Crystal"
    },
    {
      "x": 18,
      "y": 19,
      "z": 9,
      "name": "Plant_Leaves_Crystal"
    },
    {
      "x": 18,
      "y": 18,
      "z": 10,
      "name": "Plant_Leaves_Crystal"
    },
    {
      "x": 18,
      "y": 19,
      "z": 10,
      "name": "Plant_Leaves_Crystal"
    },
    {
      "x": 18,
      "y": 18,
      "z": 11,
      "name": "Plant_Leaves_Crystal"
    },
    {
      "x": 18,
      "y": 19,
      "z": 11,
      "name": "Plant_Leaves_Crystal"
    },
    {
      "x": 18,
      "y": 18,
      "z": 12,
      "name": "Plant_Leaves_Crystal"
    },
    {
      "x": 18,
      "y": 19,
      "z": 12,
      "name": "Plant_Leaves_Crystal"
    },
    {
      "x": 18,
      "y": 18,
      "z": 13,
      "name": "Wood_Crystal_Trunk_Full"
    },
    {
      "x": 18,
      "y": 19,
      "z": 13,
      "name": "Plant_Leaves_Crystal"
    },
    {
      "x": 18,
      "y": 19,
      "z": 14,
      "name": "Plant_Leaves_Crystal"
    },
    {
      "x": 18,
      "y": 19,
      "z": 15,
      "name": "Plant_Leaves_Crystal"
    },
    {
      "x": 18,
      "y": 19,
      "z": 16,
      "name": "Plant_Leaves_Crystal"
    },
    {
      "x": 18,
      "y": 19,
      "z": 17,
      "name": "Wood_Crystal_Branch_Long",
      "rotation": 5
    },
    {
      "x": 18,
      "y": 20,
      "z": 17,
      "name": "Plant_Leaves_Crystal"
    },
    {
      "x": 18,
      "y": 3,
      "z": 18,
      "name": "Rock_Shale"
    },
    {
      "x": 18,
      "y": 4,
      "z": 18,
      "name": "Rock_Shale"
    },
    {
      "x": 18,
      "y": 5,
      "z": 18,
      "name": "Rock_Shale"
    },
    {
      "x": 18,
      "y": 15,
      "z": 18,
      "name": "Plant_Leaves_Crystal"
    },
    {
      "x": 18,
      "y": 19,
      "z": 18,
      "name": "Plant_Leaves_Crystal"
    },
    {
      "x": 18,
      "y": 20,
      "z": 18,
      "name": "Plant_Leaves_Crystal"
    },
    {
      "x": 18,
      "y": 1,
      "z": 19,
      "name": "Wood_Crystal_Roots"
    },
    {
      "x": 18,
      "y": 2,
      "z": 19,
      "name": "Wood_Crystal_Trunk_Full"
    },
    {
      "x": 18,
      "y": 3,
      "z": 19,
      "name": "Wood_Crystal_Trunk"
    },
    {
      "x": 18,
      "y": 4,
      "z": 19,
      "name": "Wood_Crystal_Trunk"
    },
    {
      "x": 18,
      "y": 5,
      "z": 19,
      "name": "Wood_Crystal_Trunk"
    },
    {
      "x": 18,
      "y": 6,
      "z": 19,
      "name": "Wood_Crystal_Trunk_Full"
    },
    {
      "x": 18,
      "y": 15,
      "z": 19,
      "name": "Wood_Crystal_Branch_Long",
      "rotation": 4
    },
    {
      "x": 18,
      "y": 16,
      "z": 19,
      "name": "Plant_Leaves_Crystal"
    },
    {
      "x": 18,
      "y": 19,
      "z": 19,
      "name": "Wood_Crystal_Branch_Long",
      "rotation": 5
    },
    {
      "x": 18,
      "y": 20,
      "z": 19,
      "name": "Plant_Leaves_Crystal"
    },
    {
      "x": 18,
      "y": 21,
      "z": 19,
      "name": "Plant_Leaves_Crystal"
    },
    {
      "x": 18,
      "y": 3,
      "z": 20,
      "name": "Rock_Shale"
    },
    {
      "x": 18,
      "y": 4,
      "z": 20,
      "name": "Rock_Shale"
    },
    {
      "x": 18,
      "y": 5,
      "z": 20,
      "name": "Rock_Shale"
    },
    {
      "x": 18,
      "y": 6,
      "z": 20,
      "name": "Rock_Shale"
    },
    {
      "x": 18,
      "y": 7,
      "z": 20,
      "name": "*Plant_Crop_Berry_Winter_Block_State_Definitions_StageFinal"
    },
    {
      "x": 18,
      "y": 15,
      "z": 20,
      "name": "Wood_Crystal_Trunk_Full"
    },
    {
      "x": 18,
      "y": 16,
      "z": 20,
      "name": "Plant_Leaves_Crystal"
    },
    {
      "x": 18,
      "y": 19,
      "z": 20,
      "name": "Plant_Leaves_Crystal"
    },
    {
      "x": 18,
      "y": 20,
      "z": 20,
      "name": "Plant_Leaves_Crystal"
    },
    {
      "x": 18,
      "y": 4,
      "z": 21,
      "name": "Rock_Shale"
    },
    {
      "x": 18,
      "y": 5,
      "z": 21,
      "name": "Rock_Shale"
    },
    {
      "x": 18,
      "y": 6,
      "z": 21,
      "name": "Rock_Shale"
    },
    {
      "x": 18,
      "y": 19,
      "z": 21,
      "name": "Plant_Leaves_Crystal"
    },
    {
      "x": 18,
      "y": 5,
      "z": 22,
      "name": "Rock_Shale"
    },
    {
      "x": 18,
      "y": 6,
      "z": 22,
      "name": "*Plant_Crop_Berry_Winter_Block_State_Definitions_StageFinal"
    },
    {
      "x": 18,
      "y": 19,
      "z": 22,
      "name": "Plant_Leaves_Crystal"
    },
    {
      "x": 18,
      "y": 14,
      "z": 23,
      "name": "Wood_Crystal_Trunk_Full"
    },
    {
      "x": 18,
      "y": 19,
      "z": 23,
      "name": "Plant_Leaves_Crystal"
    },
    {
      "x": 18,
      "y": 16,
      "z": 24,
      "name": "Plant_Leaves_Crystal"
    },
    {
      "x": 18,
      "y": 19,
      "z": 24,
      "name": "Plant_Leaves_Crystal"
    },
    {
      "x": 18,
      "y": 15,
      "z": 26,
      "name": "Plant_Leaves_Crystal"
    },
    {
      "x": 18,
      "y": 16,
      "z": 26,
      "name": "Plant_Leaves_Crystal"
    },
    {
      "x": 18,
      "y": 19,
      "z": 26,
      "name": "Plant_Leaves_Crystal"
    },
    {
      "x": 18,
      "y": 15,
      "z": 27,
      "name": "Plant_Leaves_Crystal"
    },
    {
      "x": 18,
      "y": 16,
      "z": 27,
      "name": "Plant_Leaves_Crystal"
    },
    {
      "x": 18,
      "y": 15,
      "z": 29,
      "name": "Plant_Leaves_Crystal"
    },
    {
      "x": 18,
      "y": 15,
      "z": 30,
      "name": "Plant_Leaves_Crystal"
    },
    {
      "x": 19,
      "y": 18,
      "z": 4,
      "name": "Plant_Leaves_Crystal"
    },
    {
      "x": 19,
      "y": 18,
      "z": 5,
      "name": "Plant_Leaves_Crystal"
    },
    {
      "x": 19,
      "y": 19,
      "z": 5,
      "name": "Plant_Leaves_Crystal"
    },
    {
      "x": 19,
      "y": 18,
      "z": 6,
      "name": "Plant_Leaves_Crystal"
    },
    {
      "x": 19,
      "y": 19,
      "z": 6,
      "name": "Plant_Leaves_Crystal"
    },
    {
      "x": 19,
      "y": 18,
      "z": 7,
      "name": "Plant_Leaves_Crystal"
    },
    {
      "x": 19,
      "y": 19,
      "z": 7,
      "name": "Plant_Leaves_Crystal"
    },
    {
      "x": 19,
      "y": 18,
      "z": 9,
      "name": "Wood_Crystal_Branch_Long",
      "rotation": 5
    },
    {
      "x": 19,
      "y": 19,
      "z": 9,
      "name": "Plant_Leaves_Crystal"
    },
    {
      "x": 19,
      "y": 19,
      "z": 10,
      "name": "Plant_Leaves_Crystal"
    },
    {
      "x": 19,
      "y": 18,
      "z": 11,
      "name": "Wood_Crystal_Branch_Long",
      "rotation": 4
    },
    {
      "x": 19,
      "y": 18,
      "z": 12,
      "name": "Wood_Crystal_Trunk_Full"
    },
    {
      "x": 19,
      "y": 19,
      "z": 12,
      "name": "Plant_Leaves_Crystal"
    },
    {
      "x": 19,
      "y": 18,
      "z": 13,
      "name": "Wood_Crystal_Trunk_Full"
    },
    {
      "x": 19,
      "y": 19,
      "z": 13,
      "name": "Plant_Leaves_Crystal"
    },
    {
      "x": 19,
      "y": 18,
      "z": 14,
      "name": "Plant_Leaves_Crystal"
    },
    {
      "x": 19,
      "y": 19,
      "z": 16,
      "name": "Plant_Leaves_Crystal"
    },
    {
      "x": 19,
      "y": 3,
      "z": 17,
      "name": "Rock_Shale"
    },
    {
      "x": 19,
      "y": 4,
      "z": 17,
      "name": "Rock_Shale"
    },
    {
      "x": 19,
      "y": 5,
      "z": 17,
      "name": "Wood_Crystal_Trunk"
    },
    {
      "x": 19,
      "y": 6,
      "z": 17,
      "name": "Wood_Crystal_Trunk_Full"
    },
    {
      "x": 19,
      "y": 15,
      "z": 17,
      "name": "Plant_Leaves_Crystal"
    },
    {
      "x": 19,
      "y": 18,
      "z": 17,
      "name": "Wood_Crystal_Trunk_Full"
    },
    {
      "x": 19,
      "y": 19,
      "z": 17,
      "name": "Wood_Crystal_Trunk_Full"
    },
    {
      "x": 19,
      "y": 20,
      "z": 17,
      "name": "Plant_Leaves_Crystal"
    },
    {
      "x": 19,
      "y": 3,
      "z": 18,
      "name": "Rock_Shale"
    },
    {
      "x": 19,
      "y": 4,
      "z": 18,
      "name": "Rock_Shale"
    },
    {
      "x": 19,
      "y": 5,
      "z": 18,
      "name": "Rock_Shale"
    },
    {
      "x": 19,
      "y": 6,
      "z": 18,
      "name": "Wood_Crystal_Trunk_Full"
    },
    {
      "x": 19,
      "y": 15,
      "z": 18,
      "name": "Plant_Leaves_Crystal"
    },
    {
      "x": 19,
      "y": 16,
      "z": 18,
      "name": "Plant_Leaves_Crystal"
    },
    {
      "x": 19,
      "y": 19,
      "z": 18,
      "name": "Wood_Crystal_Trunk_Full"
    },
    {
      "x": 19,
      "y": 21,
      "z": 18,
      "name": "Plant_Leaves_Crystal"
    },
    {
      "x": 19,
      "y": 2,
      "z": 19,
      "name": "Rock_Shale"
    },
    {
      "x": 19,
      "y": 3,
      "z": 19,
      "name": "Rock_Shale"
    },
    {
      "x": 19,
      "y": 4,
      "z": 19,
      "name": "Rock_Shale"
    },
    {
      "x": 19,
      "y": 5,
      "z": 19,
      "name": "Rock_Shale"
    },
    {
      "x": 19,
      "y": 6,
      "z": 19,
      "name": "Rock_Shale"
    },
    {
      "x": 19,
      "y": 7,
      "z": 19,
      "name": "Wood_Crystal_Trunk_Full"
    },
    {
      "x": 19,
      "y": 15,
      "z": 19,
      "name": "Plant_Leaves_Crystal"
    },
    {
      "x": 19,
      "y": 16,
      "z": 19,
      "name": "Plant_Leaves_Crystal"
    },
    {
      "x": 19,
      "y": 19,
      "z": 19,
      "name": "Wood_Crystal_Trunk_Full"
    },
    {
      "x": 19,
      "y": 20,
      "z": 19,
      "name": "Rock_Crystal_Pink_Medium"
    },
    {
      "x": 19,
      "y": 21,
      "z": 19,
      "name": "Plant_Leaves_Crystal"
    },
    {
      "x": 19,
      "y": 2,
      "z": 20,
      "name": "Rock_Shale"
    },
    {
      "x": 19,
      "y": 3,
      "z": 20,
      "name": "Rock_Shale"
    },
    {
      "x": 19,
      "y": 4,
      "z": 20,
      "name": "Rock_Shale"
    },
    {
      "x": 19,
      "y": 5,
      "z": 20,
      "name": "Rock_Shale"
    },
    {
      "x": 19,
      "y": 6,
      "z": 20,
      "name": "Rock_Shale"
    },
    {
      "x": 19,
      "y": 7,
      "z": 20,
      "name": "Rock_Crystal_Pink_Medium"
    },
    {
      "x": 19,
      "y": 15,
      "z": 20,
      "name": "Wood_Crystal_Trunk_Full"
    },
    {
      "x": 19,
      "y": 20,
      "z": 20,
      "name": "Plant_Leaves_Crystal"
    },
    {
      "x": 19,
      "y": 21,
      "z": 20,
      "name": "Plant_Leaves_Crystal"
    },
    {
      "x": 19,
      "y": 3,
      "z": 21,
      "name": "Rock_Shale"
    },
    {
      "x": 19,
      "y": 4,
      "z": 21,
      "name": "Rock_Shale"
    },
    {
      "x": 19,
      "y": 5,
      "z": 21,
      "name": "Rock_Shale"
    },
    {
      "x": 19,
      "y": 6,
      "z": 21,
      "name": "Rock_Shale"
    },
    {
      "x": 19,
      "y": 15,
      "z": 21,
      "name": "Wood_Crystal_Trunk_Full"
    },
    {
      "x": 19,
      "y": 20,
      "z": 21,
      "name": "Plant_Leaves_Crystal"
    },
    {
      "x": 19,
      "y": 21,
      "z": 21,
      "name": "Plant_Leaves_Crystal"
    },
    {
      "x": 19,
      "y": 4,
      "z": 22,
      "name": "Rock_Shale"
    },
    {
      "x": 19,
      "y": 5,
      "z": 22,
      "name": "Rock_Shale"
    },
    {
      "x": 19,
      "y": 6,
      "z": 22,
      "name": "Wood_Crystal_Trunk_Full"
    },
    {
      "x": 19,
      "y": 14,
      "z": 22,
      "name": "Wood_Crystal_Trunk_Full"
    },
    {
      "x": 19,
      "y": 15,
      "z": 22,
      "name": "Wood_Crystal_Trunk_Full"
    },
    {
      "x": 19,
      "y": 19,
      "z": 22,
      "name": "Wood_Crystal_Branch_Long",
      "rotation": 5
    },
    {
      "x": 19,
      "y": 20,
      "z": 22,
      "name": "Plant_Leaves_Crystal"
    },
    {
      "x": 19,
      "y": 4,
      "z": 23,
      "name": "Rock_Shale"
    },
    {
      "x": 19,
      "y": 5,
      "z": 23,
      "name": "Rock_Shale"
    },
    {
      "x": 19,
      "y": 6,
      "z": 23,
      "name": "Rock_Shale"
    },
    {
      "x": 19,
      "y": 14,
      "z": 23,
      "name": "Wood_Crystal_Trunk_Full"
    },
    {
      "x": 19,
      "y": 19,
      "z": 23,
      "name": "Plant_Leaves_Crystal"
    },
    {
      "x": 19,
      "y": 20,
      "z": 23,
      "name": "Plant_Leaves_Crystal"
    },
    {
      "x": 19,
      "y": 19,
      "z": 24,
      "name": "Plant_Leaves_Crystal"
    },
    {
      "x": 19,
      "y": 15,
      "z": 25,
      "name": "Wood_Crystal_Trunk_Full"
    },
    {
      "x": 19,
      "y": 16,
      "z": 25,
      "name": "Plant_Leaves_Crystal"
    },
    {
      "x": 19,
      "y": 19,
      "z": 25,
      "name": "Plant_Leaves_Crystal"
    },
    {
      "x": 19,
      "y": 20,
      "z": 25,
      "name": "Plant_Leaves_Crystal"
    },
    {
      "x": 19,
      "y": 15,
      "z": 26,
      "name": "Plant_Leaves_Crystal"
    },
    {
      "x": 19,
      "y": 16,
      "z": 26,
      "name": "Plant_Leaves_Crystal"
    },
    {
      "x": 19,
      "y": 19,
      "z": 26,
      "name": "Plant_Leaves_Crystal"
    },
    {
      "x": 19,
      "y": 15,
      "z": 27,
      "name": "Plant_Leaves_Crystal"
    },
    {
      "x": 19,
      "y": 16,
      "z": 27,
      "name": "Plant_Leaves_Crystal"
    },
    {
      "x": 19,
      "y": 19,
      "z": 27,
      "name": "Plant_Leaves_Crystal"
    },
    {
      "x": 19,
      "y": 15,
      "z": 28,
      "name": "Plant_Leaves_Crystal"
    },
    {
      "x": 19,
      "y": 16,
      "z": 28,
      "name": "Plant_Leaves_Crystal"
    },
    {
      "x": 19,
      "y": 15,
      "z": 29,
      "name": "Plant_Leaves_Crystal"
    },
    {
      "x": 19,
      "y": 15,
      "z": 30,
      "name": "Plant_Leaves_Crystal"
    },
    {
      "x": 20,
      "y": 18,
      "z": 3,
      "name": "Plant_Leaves_Crystal"
    },
    {
      "x": 20,
      "y": 18,
      "z": 4,
      "name": "Plant_Leaves_Crystal"
    },
    {
      "x": 20,
      "y": 18,
      "z": 5,
      "name": "Plant_Leaves_Crystal"
    },
    {
      "x": 20,
      "y": 18,
      "z": 6,
      "name": "Plant_Leaves_Crystal"
    },
    {
      "x": 20,
      "y": 19,
      "z": 6,
      "name": "Plant_Leaves_Crystal"
    },
    {
      "x": 20,
      "y": 18,
      "z": 7,
      "name": "Plant_Leaves_Crystal"
    },
    {
      "x": 20,
      "y": 19,
      "z": 7,
      "name": "Plant_Leaves_Crystal"
    },
    {
      "x": 20,
      "y": 18,
      "z": 8,
      "name": "Plant_Leaves_Crystal"
    },
    {
      "x": 20,
      "y": 19,
      "z": 8,
      "name": "Plant_Leaves_Crystal"
    },
    {
      "x": 20,
      "y": 18,
      "z": 9,
      "name": "Wood_Crystal_Branch_Long",
      "rotation": 5
    },
    {
      "x": 20,
      "y": 19,
      "z": 9,
      "name": "Plant_Leaves_Crystal"
    },
    {
      "x": 20,
      "y": 19,
      "z": 10,
      "name": "Plant_Leaves_Crystal"
    },
    {
      "x": 20,
      "y": 19,
      "z": 11,
      "name": "Plant_Leaves_Crystal"
    },
    {
      "x": 20,
      "y": 17,
      "z": 13,
      "name": "Wood_Crystal_Trunk_Full"
    },
    {
      "x": 20,
      "y": 18,
      "z": 13,
      "name": "Wood_Crystal_Trunk_Full"
    },
    {
      "x": 20,
      "y": 4,
      "z": 16,
      "name": "Rock_Shale"
    },
    {
      "x": 20,
      "y": 5,
      "z": 16,
      "name": "*Plant_Crop_Berry_Winter_Block_State_Definitions_StageFinal"
    },
    {
      "x": 20,
      "y": 3,
      "z": 17,
      "name": "Rock_Shale"
    },
    {
      "x": 20,
      "y": 4,
      "z": 17,
      "name": "Rock_Shale"
    },
    {
      "x": 20,
      "y": 5,
      "z": 17,
      "name": "Rock_Shale"
    },
    {
      "x": 20,
      "y": 6,
      "z": 17,
      "name": "Wood_Crystal_Trunk_Full"
    },
    {
      "x": 20,
      "y": 15,
      "z": 17,
      "name": "Plant_Leaves_Crystal"
    },
    {
      "x": 20,
      "y": 17,
      "z": 17,
      "name": "Wood_Crystal_Trunk_Full"
    },
    {
      "x": 20,
      "y": 18,
      "z": 17,
      "name": "Wood_Crystal_Trunk_Full"
    },
    {
      "x": 20,
      "y": 2,
      "z": 18,
      "name": "Rock_Shale"
    },
    {
      "x": 20,
      "y": 3,
      "z": 18,
      "name": "Rock_Shale"
    },
    {
      "x": 20,
      "y": 4,
      "z": 18,
      "name": "Rock_Shale"
    },
    {
      "x": 20,
      "y": 5,
      "z": 18,
      "name": "Rock_Shale"
    },
    {
      "x": 20,
      "y": 6,
      "z": 18,
      "name": "Rock_Shale"
    },
    {
      "x": 20,
      "y": 7,
      "z": 18,
      "name": "Wood_Crystal_Trunk_Full"
    },
    {
      "x": 20,
      "y": 15,
      "z": 18,
      "name": "Plant_Leaves_Crystal"
    },
    {
      "x": 20,
      "y": 16,
      "z": 18,
      "name": "Plant_Leaves_Crystal"
    },
    {
      "x": 20,
      "y": 21,
      "z": 18,
      "name": "Plant_Leaves_Crystal"
    },
    {
      "x": 20,
      "y": 2,
      "z": 19,
      "name": "Rock_Shale"
    },
    {
      "x": 20,
      "y": 3,
      "z": 19,
      "name": "Rock_Shale"
    },
    {
      "x": 20,
      "y": 4,
      "z": 19,
      "name": "Rock_Shale"
    },
    {
      "x": 20,
      "y": 5,
      "z": 19,
      "name": "Rock_Shale"
    },
    {
      "x": 20,
      "y": 6,
      "z": 19,
      "name": "Rock_Shale"
    },
    {
      "x": 20,
      "y": 7,
      "z": 19,
      "name": "Rock_Shale"
    },
    {
      "x": 20,
      "y": 8,
      "z": 19,
      "name": "Wood_Crystal_Trunk_Full"
    },
    {
      "x": 20,
      "y": 15,
      "z": 19,
      "name": "Plant_Leaves_Crystal"
    },
    {
      "x": 20,
      "y": 16,
      "z": 19,
      "name": "Plant_Leaves_Crystal"
    },
    {
      "x": 20,
      "y": 21,
      "z": 19,
      "name": "Plant_Leaves_Crystal"
    },
    {
      "x": 20,
      "y": 2,
      "z": 20,
      "name": "Rock_Shale"
    },
    {
      "x": 20,
      "y": 3,
      "z": 20,
      "name": "Rock_Shale"
    },
    {
      "x": 20,
      "y": 4,
      "z": 20,
      "name": "Rock_Shale"
    },
    {
      "x": 20,
      "y": 5,
      "z": 20,
      "name": "Rock_Shale"
    },
    {
      "x": 20,
      "y": 6,
      "z": 20,
      "name": "Rock_Shale"
    },
    {
      "x": 20,
      "y": 7,
      "z": 20,
      "name": "Rock_Shale"
    },
    {
      "x": 20,
      "y": 8,
      "z": 20,
      "name": "Wood_Crystal_Trunk_Full"
    },
    {
      "x": 20,
      "y": 15,
      "z": 20,
      "name": "Plant_Leaves_Crystal"
    },
    {
      "x": 20,
      "y": 16,
      "z": 20,
      "name": "Plant_Leaves_Crystal"
    },
    {
      "x": 20,
      "y": 3,
      "z": 21,
      "name": "Rock_Shale"
    },
    {
      "x": 20,
      "y": 4,
      "z": 21,
      "name": "Rock_Shale"
    },
    {
      "x": 20,
      "y": 5,
      "z": 21,
      "name": "Rock_Shale"
    },
    {
      "x": 20,
      "y": 6,
      "z": 21,
      "name": "Rock_Shale"
    },
    {
      "x": 20,
      "y": 7,
      "z": 21,
      "name": "Wood_Crystal_Trunk"
    },
    {
      "x": 20,
      "y": 8,
      "z": 21,
      "name": "Wood_Crystal_Trunk_Full"
    },
    {
      "x": 20,
      "y": 16,
      "z": 21,
      "name": "Plant_Leaves_Crystal"
    },
    {
      "x": 20,
      "y": 3,
      "z": 22,
      "name": "Rock_Shale"
    },
    {
      "x": 20,
      "y": 4,
      "z": 22,
      "name": "Rock_Shale"
    },
    {
      "x": 20,
      "y": 5,
      "z": 22,
      "name": "Rock_Shale"
    },
    {
      "x": 20,
      "y": 6,
      "z": 22,
      "name": "Rock_Shale"
    },
    {
      "x": 20,
      "y": 7,
      "z": 22,
      "name": "Wood_Crystal_Trunk_Full"
    },
    {
      "x": 20,
      "y": 19,
      "z": 22,
      "name": "Wood_Crystal_Branch_Long",
      "rotation": 5
    },
    {
      "x": 20,
      "y": 4,
      "z": 23,
      "name": "Rock_Shale"
    },
    {
      "x": 20,
      "y": 5,
      "z": 23,
      "name": "Rock_Shale"
    },
    {
      "x": 20,
      "y": 6,
      "z": 23,
      "name": "Rock_Shale"
    },
    {
      "x": 20,
      "y": 7,
      "z": 23,
      "name": "*Plant_Crop_Berry_Winter_Block_State_Definitions_StageFinal"
    },
    {
      "x": 20,
      "y": 14,
      "z": 23,
      "name": "Wood_Crystal_Trunk_Full"
    },
    {
      "x": 20,
      "y": 19,
      "z": 23,
      "name": "Plant_Leaves_Crystal"
    },
    {
      "x": 20,
      "y": 14,
      "z": 24,
      "name": "Wood_Crystal_Trunk_Full"
    },
    {
      "x": 20,
      "y": 15,
      "z": 24,
      "name": "Wood_Crystal_Trunk_Full"
    },
    {
      "x": 20,
      "y": 19,
      "z": 24,
      "name": "Plant_Leaves_Crystal"
    },
    {
      "x": 20,
      "y": 20,
      "z": 24,
      "name": "Plant_Leaves_Crystal"
    },
    {
      "x": 20,
      "y": 15,
      "z": 25,
      "name": "Wood_Crystal_Trunk_Full"
    },
    {
      "x": 20,
      "y": 16,
      "z": 25,
      "name": "Plant_Leaves_Crystal"
    },
    {
      "x": 20,
      "y": 15,
      "z": 26,
      "name": "Wood_Crystal_Trunk_Full"
    },
    {
      "x": 20,
      "y": 16,
      "z": 26,
      "name": "Plant_Leaves_Crystal"
    },
    {
      "x": 20,
      "y": 19,
      "z": 26,
      "name": "Plant_Leaves_Crystal"
    },
    {
      "x": 20,
      "y": 15,
      "z": 27,
      "name": "Plant_Leaves_Crystal"
    },
    {
      "x": 20,
      "y": 16,
      "z": 27,
      "name": "Plant_Leaves_Crystal"
    },
    {
      "x": 20,
      "y": 19,
      "z": 27,
      "name": "Plant_Leaves_Crystal"
    },
    {
      "x": 20,
      "y": 15,
      "z": 28,
      "name": "Plant_Leaves_Crystal"
    },
    {
      "x": 20,
      "y": 16,
      "z": 28,
      "name": "Plant_Leaves_Crystal"
    },
    {
      "x": 20,
      "y": 15,
      "z": 29,
      "name": "Plant_Leaves_Crystal"
    },
    {
      "x": 20,
      "y": 15,
      "z": 30,
      "name": "Plant_Leaves_Crystal"
    },
    {
      "x": 21,
      "y": 18,
      "z": 3,
      "name": "Plant_Leaves_Crystal"
    },
    {
      "x": 21,
      "y": 18,
      "z": 4,
      "name": "Plant_Leaves_Crystal"
    },
    {
      "x": 21,
      "y": 18,
      "z": 5,
      "name": "Plant_Leaves_Crystal"
    },
    {
      "x": 21,
      "y": 19,
      "z": 5,
      "name": "Plant_Leaves_Crystal"
    },
    {
      "x": 21,
      "y": 18,
      "z": 6,
      "name": "Plant_Leaves_Crystal"
    },
    {
      "x": 21,
      "y": 19,
      "z": 6,
      "name": "Plant_Leaves_Crystal"
    },
    {
      "x": 21,
      "y": 18,
      "z": 7,
      "name": "Wood_Crystal_Branch_Long",
      "rotation": 4
    },
    {
      "x": 21,
      "y": 18,
      "z": 8,
      "name": "Wood_Crystal_Trunk_Full"
    },
    {
      "x": 21,
      "y": 18,
      "z": 9,
      "name": "Wood_Crystal_Trunk_Full"
    },
    {
      "x": 21,
      "y": 19,
      "z": 9,
      "name": "Plant_Leaves_Crystal"
    },
    {
      "x": 21,
      "y": 17,
      "z": 10,
      "name": "Wood_Crystal_Trunk_Full"
    },
    {
      "x": 21,
      "y": 18,
      "z": 10,
      "name": "Wood_Crystal_Trunk_Full"
    },
    {
      "x": 21,
      "y": 17,
      "z": 11,
      "name": "Wood_Crystal_Trunk_Full"
    },
    {
      "x": 21,
      "y": 17,
      "z": 12,
      "name": "Wood_Crystal_Trunk_Full"
    },
    {
      "x": 21,
      "y": 17,
      "z": 13,
      "name": "Wood_Crystal_Trunk_Full"
    },
    {
      "x": 21,
      "y": 17,
      "z": 14,
      "name": "Wood_Crystal_Trunk_Full"
    },
    {
      "x": 21,
      "y": 16,
      "z": 15,
      "name": "Wood_Crystal_Trunk_Full"
    },
    {
      "x": 21,
      "y": 17,
      "z": 15,
      "name": "Wood_Crystal_Trunk_Full"
    },
    {
      "x": 21,
      "y": 4,
      "z": 16,
      "name": "Rock_Shale"
    },
    {
      "x": 21,
      "y": 5,
      "z": 16,
      "name": "Rock_Shale"
    },
    {
      "x": 21,
      "y": 16,
      "z": 16,
      "name": "Wood_Crystal_Trunk_Full"
    },
    {
      "x": 21,
      "y": 3,
      "z": 17,
      "name": "Rock_Shale"
    },
    {
      "x": 21,
      "y": 4,
      "z": 17,
      "name": "Rock_Shale"
    },
    {
      "x": 21,
      "y": 5,
      "z": 17,
      "name": "Rock_Shale"
    },
    {
      "x": 21,
      "y": 6,
      "z": 17,
      "name": "Rock_Shale"
    },
    {
      "x": 21,
      "y": 7,
      "z": 17,
      "name": "*Plant_Crop_Berry_Winter_Block_State_Definitions_StageFinal"
    },
    {
      "x": 21,
      "y": 16,
      "z": 17,
      "name": "Wood_Crystal_Trunk_Full"
    },
    {
      "x": 21,
      "y": 17,
      "z": 17,
      "name": "Wood_Crystal_Trunk_Full"
    },
    {
      "x": 21,
      "y": 2,
      "z": 18,
      "name": "Rock_Shale"
    },
    {
      "x": 21,
      "y": 3,
      "z": 18,
      "name": "Rock_Shale"
    },
    {
      "x": 21,
      "y": 4,
      "z": 18,
      "name": "Rock_Shale"
    },
    {
      "x": 21,
      "y": 5,
      "z": 18,
      "name": "Rock_Shale"
    },
    {
      "x": 21,
      "y": 6,
      "z": 18,
      "name": "Rock_Shale"
    },
    {
      "x": 21,
      "y": 7,
      "z": 18,
      "name": "Rock_Shale"
    },
    {
      "x": 21,
      "y": 8,
      "z": 18,
      "name": "Rubble_Shale_Medium"
    },
    {
      "x": 21,
      "y": 16,
      "z": 18,
      "name": "Wood_Crystal_Trunk_Full"
    },
    {
      "x": 21,
      "y": 17,
      "z": 18,
      "name": "Wood_Crystal_Trunk_Full"
    },
    {
      "x": 21,
      "y": 21,
      "z": 18,
      "name": "Plant_Leaves_Crystal"
    },
    {
      "x": 21,
      "y": 2,
      "z": 19,
      "name": "Rock_Shale"
    },
    {
      "x": 21,
      "y": 3,
      "z": 19,
      "name": "Rock_Shale"
    },
    {
      "x": 21,
      "y": 4,
      "z": 19,
      "name": "Rock_Shale"
    },
    {
      "x": 21,
      "y": 5,
      "z": 19,
      "name": "Rock_Shale"
    },
    {
      "x": 21,
      "y": 6,
      "z": 19,
      "name": "Rock_Shale"
    },
    {
      "x": 21,
      "y": 7,
      "z": 19,
      "name": "Wood_Crystal_Trunk"
    },
    {
      "x": 21,
      "y": 8,
      "z": 19,
      "name": "Wood_Crystal_Trunk_Full"
    },
    {
      "x": 21,
      "y": 15,
      "z": 19,
      "name": "Wood_Crystal_Trunk_Full"
    },
    {
      "x": 21,
      "y": 16,
      "z": 19,
      "name": "Wood_Crystal_Trunk_Full"
    },
    {
      "x": 21,
      "y": 17,
      "z": 19,
      "name": "Wood_Crystal_Trunk_Full"
    },
    {
      "x": 21,
      "y": 3,
      "z": 20,
      "name": "Rock_Shale"
    },
    {
      "x": 21,
      "y": 4,
      "z": 20,
      "name": "Rock_Shale"
    },
    {
      "x": 21,
      "y": 5,
      "z": 20,
      "name": "Rock_Shale"
    },
    {
      "x": 21,
      "y": 6,
      "z": 20,
      "name": "Rock_Shale"
    },
    {
      "x": 21,
      "y": 7,
      "z": 20,
      "name": "Rock_Shale"
    },
    {
      "x": 21,
      "y": 8,
      "z": 20,
      "name": "Wood_Crystal_Trunk_Full"
    },
    {
      "x": 21,
      "y": 15,
      "z": 20,
      "name": "Plant_Leaves_Crystal"
    },
    {
      "x": 21,
      "y": 16,
      "z": 20,
      "name": "Plant_Leaves_Crystal"
    },
    {
      "x": 21,
      "y": 19,
      "z": 20,
      "name": "Wood_Crystal_Trunk_Full"
    },
    {
      "x": 21,
      "y": 3,
      "z": 21,
      "name": "Rock_Shale"
    },
    {
      "x": 21,
      "y": 4,
      "z": 21,
      "name": "Rock_Shale"
    },
    {
      "x": 21,
      "y": 5,
      "z": 21,
      "name": "Rock_Shale"
    },
    {
      "x": 21,
      "y": 6,
      "z": 21,
      "name": "Rock_Shale"
    },
    {
      "x": 21,
      "y": 7,
      "z": 21,
      "name": "Rock_Shale"
    },
    {
      "x": 21,
      "y": 8,
      "z": 21,
      "name": "Wood_Crystal_Trunk"
    },
    {
      "x": 21,
      "y": 9,
      "z": 21,
      "name": "Wood_Crystal_Trunk_Full"
    },
    {
      "x": 21,
      "y": 17,
      "z": 21,
      "name": "Wood_Crystal_Trunk_Full"
    },
    {
      "x": 21,
      "y": 18,
      "z": 21,
      "name": "Wood_Crystal_Trunk_Full"
    },
    {
      "x": 21,
      "y": 19,
      "z": 21,
      "name": "Wood_Crystal_Trunk_Full"
    },
    {
      "x": 21,
      "y": 20,
      "z": 21,
      "name": "Plant_Leaves_Crystal"
    },
    {
      "x": 21,
      "y": 3,
      "z": 22,
      "name": "Rock_Shale"
    },
    {
      "x": 21,
      "y": 4,
      "z": 22,
      "name": "Rock_Shale"
    },
    {
      "x": 21,
      "y": 5,
      "z": 22,
      "name": "Rock_Shale"
    },
    {
      "x": 21,
      "y": 6,
      "z": 22,
      "name": "Rock_Shale"
    },
    {
      "x": 21,
      "y": 7,
      "z": 22,
      "name": "Rock_Shale"
    },
    {
      "x": 21,
      "y": 8,
      "z": 22,
      "name": "Wood_Crystal_Trunk"
    },
    {
      "x": 21,
      "y": 9,
      "z": 22,
      "name": "Wood_Crystal_Trunk_Full"
    },
    {
      "x": 21,
      "y": 19,
      "z": 22,
      "name": "Wood_Crystal_Trunk_Full"
    },
    {
      "x": 21,
      "y": 20,
      "z": 22,
      "name": "Plant_Leaves_Crystal"
    },
    {
      "x": 21,
      "y": 4,
      "z": 23,
      "name": "Rock_Shale"
    },
    {
      "x": 21,
      "y": 5,
      "z": 23,
      "name": "Rock_Shale"
    },
    {
      "x": 21,
      "y": 6,
      "z": 23,
      "name": "Rock_Shale"
    },
    {
      "x": 21,
      "y": 7,
      "z": 23,
      "name": "Rock_Shale"
    },
    {
      "x": 21,
      "y": 8,
      "z": 23,
      "name": "*Plant_Crop_Berry_Winter_Block_State_Definitions_StageFinal"
    },
    {
      "x": 21,
      "y": 14,
      "z": 23,
      "name": "Wood_Crystal_Trunk_Full"
    },
    {
      "x": 21,
      "y": 19,
      "z": 23,
      "name": "Wood_Crystal_Trunk_Full"
    },
    {
      "x": 21,
      "y": 20,
      "z": 23,
      "name": "Rock_Crystal_Pink_Medium"
    },
    {
      "x": 21,
      "y": 19,
      "z": 24,
      "name": "Wood_Crystal_Branch_Long",
      "rotation": 4
    },
    {
      "x": 21,
      "y": 15,
      "z": 25,
      "name": "Plant_Leaves_Crystal"
    },
    {
      "x": 21,
      "y": 19,
      "z": 25,
      "name": "Plant_Leaves_Crystal"
    },
    {
      "x": 21,
      "y": 20,
      "z": 25,
      "name": "Plant_Leaves_Crystal"
    },
    {
      "x": 21,
      "y": 16,
      "z": 26,
      "name": "Plant_Leaves_Crystal"
    },
    {
      "x": 21,
      "y": 19,
      "z": 26,
      "name": "Plant_Leaves_Crystal"
    },
    {
      "x": 21,
      "y": 15,
      "z": 27,
      "name": "Plant_Leaves_Crystal"
    },
    {
      "x": 21,
      "y": 16,
      "z": 27,
      "name": "Plant_Leaves_Crystal"
    },
    {
      "x": 21,
      "y": 19,
      "z": 27,
      "name": "Plant_Leaves_Crystal"
    },
    {
      "x": 21,
      "y": 15,
      "z": 28,
      "name": "Plant_Leaves_Crystal"
    },
    {
      "x": 22,
      "y": 18,
      "z": 4,
      "name": "Plant_Leaves_Crystal"
    },
    {
      "x": 22,
      "y": 18,
      "z": 5,
      "name": "Plant_Leaves_Crystal"
    },
    {
      "x": 22,
      "y": 19,
      "z": 5,
      "name": "Plant_Leaves_Crystal"
    },
    {
      "x": 22,
      "y": 18,
      "z": 6,
      "name": "Plant_Leaves_Crystal"
    },
    {
      "x": 22,
      "y": 19,
      "z": 6,
      "name": "Plant_Leaves_Crystal"
    },
    {
      "x": 22,
      "y": 19,
      "z": 7,
      "name": "Plant_Leaves_Crystal"
    },
    {
      "x": 22,
      "y": 18,
      "z": 8,
      "name": "Wood_Crystal_Branch_Long",
      "rotation": 5
    },
    {
      "x": 22,
      "y": 19,
      "z": 8,
      "name": "Plant_Leaves_Crystal"
    },
    {
      "x": 22,
      "y": 19,
      "z": 9,
      "name": "Plant_Leaves_Crystal"
    },
    {
      "x": 22,
      "y": 17,
      "z": 12,
      "name": "Wood_Crystal_Trunk_Full"
    },
    {
      "x": 22,
      "y": 18,
      "z": 12,
      "name": "Wood_Crystal_Trunk_Full"
    },
    {
      "x": 22,
      "y": 4,
      "z": 16,
      "name": "Rock_Shale"
    },
    {
      "x": 22,
      "y": 5,
      "z": 16,
      "name": "Rock_Shale"
    },
    {
      "x": 22,
      "y": 4,
      "z": 17,
      "name": "Rock_Shale"
    },
    {
      "x": 22,
      "y": 5,
      "z": 17,
      "name": "Rock_Shale"
    },
    {
      "x": 22,
      "y": 6,
      "z": 17,
      "name": "Rock_Shale"
    },
    {
      "x": 22,
      "y": 7,
      "z": 17,
      "name": "*Plant_Crop_Berry_Winter_Block_State_Definitions_StageFinal"
    },
    {
      "x": 22,
      "y": 17,
      "z": 17,
      "name": "Wood_Crystal_Trunk_Full"
    },
    {
      "x": 22,
      "y": 21,
      "z": 17,
      "name": "Plant_Leaves_Crystal"
    },
    {
      "x": 22,
      "y": 3,
      "z": 18,
      "name": "Rock_Shale"
    },
    {
      "x": 22,
      "y": 4,
      "z": 18,
      "name": "Rock_Shale"
    },
    {
      "x": 22,
      "y": 5,
      "z": 18,
      "name": "Rock_Shale"
    },
    {
      "x": 22,
      "y": 6,
      "z": 18,
      "name": "Rock_Shale"
    },
    {
      "x": 22,
      "y": 7,
      "z": 18,
      "name": "Rock_Shale"
    },
    {
      "x": 22,
      "y": 16,
      "z": 18,
      "name": "Wood_Crystal_Trunk_Full"
    },
    {
      "x": 22,
      "y": 17,
      "z": 18,
      "name": "Wood_Crystal_Trunk_Full"
    },
    {
      "x": 22,
      "y": 21,
      "z": 18,
      "name": "Plant_Leaves_Crystal"
    },
    {
      "x": 22,
      "y": 3,
      "z": 19,
      "name": "Rock_Shale"
    },
    {
      "x": 22,
      "y": 4,
      "z": 19,
      "name": "Rock_Shale"
    },
    {
      "x": 22,
      "y": 5,
      "z": 19,
      "name": "Rock_Shale"
    },
    {
      "x": 22,
      "y": 6,
      "z": 19,
      "name": "Rock_Shale"
    },
    {
      "x": 22,
      "y": 7,
      "z": 19,
      "name": "Wood_Crystal_Trunk_Full"
    },
    {
      "x": 22,
      "y": 15,
      "z": 19,
      "name": "Wood_Crystal_Trunk_Full"
    },
    {
      "x": 22,
      "y": 16,
      "z": 19,
      "name": "Wood_Crystal_Trunk_Full"
    },
    {
      "x": 22,
      "y": 17,
      "z": 19,
      "name": "Wood_Crystal_Trunk_Full"
    },
    {
      "x": 22,
      "y": 21,
      "z": 19,
      "name": "Plant_Leaves_Crystal"
    },
    {
      "x": 22,
      "y": 3,
      "z": 20,
      "name": "Rock_Shale"
    },
    {
      "x": 22,
      "y": 4,
      "z": 20,
      "name": "Rock_Shale"
    },
    {
      "x": 22,
      "y": 5,
      "z": 20,
      "name": "Rock_Shale"
    },
    {
      "x": 22,
      "y": 6,
      "z": 20,
      "name": "Rock_Shale"
    },
    {
      "x": 22,
      "y": 7,
      "z": 20,
      "name": "Rock_Shale"
    },
    {
      "x": 22,
      "y": 8,
      "z": 20,
      "name": "Wood_Crystal_Trunk_Full"
    },
    {
      "x": 22,
      "y": 15,
      "z": 20,
      "name": "Wood_Crystal_Trunk_Full"
    },
    {
      "x": 22,
      "y": 16,
      "z": 20,
      "name": "Wood_Crystal_Trunk_Full"
    },
    {
      "x": 22,
      "y": 17,
      "z": 20,
      "name": "Wood_Crystal_Trunk_Full"
    },
    {
      "x": 22,
      "y": 19,
      "z": 20,
      "name": "Wood_Crystal_Trunk_Full"
    },
    {
      "x": 22,
      "y": 3,
      "z": 21,
      "name": "Rock_Shale"
    },
    {
      "x": 22,
      "y": 4,
      "z": 21,
      "name": "Rock_Shale"
    },
    {
      "x": 22,
      "y": 5,
      "z": 21,
      "name": "Rock_Shale"
    },
    {
      "x": 22,
      "y": 6,
      "z": 21,
      "name": "Rock_Shale"
    },
    {
      "x": 22,
      "y": 7,
      "z": 21,
      "name": "Rock_Shale"
    },
    {
      "x": 22,
      "y": 8,
      "z": 21,
      "name": "Wood_Crystal_Trunk"
    },
    {
      "x": 22,
      "y": 9,
      "z": 21,
      "name": "Wood_Crystal_Trunk_Full"
    },
    {
      "x": 22,
      "y": 15,
      "z": 21,
      "name": "Wood_Crystal_Trunk_Full"
    },
    {
      "x": 22,
      "y": 16,
      "z": 21,
      "name": "Wood_Crystal_Trunk_Full"
    },
    {
      "x": 22,
      "y": 17,
      "z": 21,
      "name": "Wood_Crystal_Trunk_Full"
    },
    {
      "x": 22,
      "y": 4,
      "z": 22,
      "name": "Rock_Shale"
    },
    {
      "x": 22,
      "y": 5,
      "z": 22,
      "name": "Rock_Shale"
    },
    {
      "x": 22,
      "y": 6,
      "z": 22,
      "name": "Rock_Shale"
    },
    {
      "x": 22,
      "y": 7,
      "z": 22,
      "name": "Rock_Shale"
    },
    {
      "x": 22,
      "y": 8,
      "z": 22,
      "name": "Wood_Crystal_Trunk"
    },
    {
      "x": 22,
      "y": 9,
      "z": 22,
      "name": "Wood_Crystal_Trunk"
    },
    {
      "x": 22,
      "y": 10,
      "z": 22,
      "name": "Wood_Crystal_Trunk_Full"
    },
    {
      "x": 22,
      "y": 14,
      "z": 22,
      "name": "Wood_Crystal_Trunk_Full"
    },
    {
      "x": 22,
      "y": 15,
      "z": 22,
      "name": "Wood_Crystal_Trunk_Full"
    },
    {
      "x": 22,
      "y": 5,
      "z": 23,
      "name": "Rock_Shale"
    },
    {
      "x": 22,
      "y": 6,
      "z": 23,
      "name": "Rock_Shale"
    },
    {
      "x": 22,
      "y": 7,
      "z": 23,
      "name": "Rock_Shale"
    },
    {
      "x": 22,
      "y": 8,
      "z": 23,
      "name": "Rubble_Shale_Medium"
    },
    {
      "x": 22,
      "y": 9,
      "z": 23,
      "name": "Wood_Crystal_Trunk_Full"
    },
    {
      "x": 22,
      "y": 10,
      "z": 23,
      "name": "Wood_Crystal_Trunk"
    },
    {
      "x": 22,
      "y": 11,
      "z": 23,
      "name": "Wood_Crystal_Trunk_Full"
    },
    {
      "x": 22,
      "y": 13,
      "z": 23,
      "name": "Wood_Crystal_Trunk_Full"
    },
    {
      "x": 22,
      "y": 14,
      "z": 23,
      "name": "Wood_Crystal_Trunk_Full"
    },
    {
      "x": 22,
      "y": 19,
      "z": 23,
      "name": "Wood_Crystal_Branch_Long",
      "rotation": 5
    },
    {
      "x": 22,
      "y": 20,
      "z": 23,
      "name": "Plant_Leaves_Crystal"
    },
    {
      "x": 22,
      "y": 11,
      "z": 24,
      "name": "Wood_Crystal_Trunk_Full"
    },
    {
      "x": 22,
      "y": 19,
      "z": 24,
      "name": "Plant_Leaves_Crystal"
    },
    {
      "x": 22,
      "y": 19,
      "z": 25,
      "name": "Plant_Leaves_Crystal"
    },
    {
      "x": 22,
      "y": 20,
      "z": 25,
      "name": "Plant_Leaves_Crystal"
    },
    {
      "x": 22,
      "y": 20,
      "z": 26,
      "name": "Plant_Leaves_Crystal"
    },
    {
      "x": 22,
      "y": 15,
      "z": 27,
      "name": "Plant_Leaves_Crystal"
    },
    {
      "x": 22,
      "y": 19,
      "z": 27,
      "name": "Plant_Leaves_Crystal"
    },
    {
      "x": 22,
      "y": 15,
      "z": 28,
      "name": "Plant_Leaves_Crystal"
    },
    {
      "x": 23,
      "y": 18,
      "z": 4,
      "name": "Plant_Leaves_Crystal"
    },
    {
      "x": 23,
      "y": 18,
      "z": 5,
      "name": "Plant_Leaves_Crystal"
    },
    {
      "x": 23,
      "y": 18,
      "z": 6,
      "name": "Plant_Leaves_Crystal"
    },
    {
      "x": 23,
      "y": 19,
      "z": 6,
      "name": "Plant_Leaves_Crystal"
    },
    {
      "x": 23,
      "y": 19,
      "z": 7,
      "name": "Plant_Leaves_Crystal"
    },
    {
      "x": 23,
      "y": 18,
      "z": 8,
      "name": "Plant_Leaves_Crystal"
    },
    {
      "x": 23,
      "y": 19,
      "z": 8,
      "name": "Plant_Leaves_Crystal"
    },
    {
      "x": 23,
      "y": 18,
      "z": 12,
      "name": "Wood_Crystal_Trunk_Full"
    },
    {
      "x": 23,
      "y": 19,
      "z": 13,
      "name": "Plant_Leaves_Crystal"
    },
    {
      "x": 23,
      "y": 4,
      "z": 17,
      "name": "Rock_Shale"
    },
    {
      "x": 23,
      "y": 5,
      "z": 17,
      "name": "Rock_Shale"
    },
    {
      "x": 23,
      "y": 6,
      "z": 17,
      "name": "Rock_Shale"
    },
    {
      "x": 23,
      "y": 4,
      "z": 18,
      "name": "Rock_Shale"
    },
    {
      "x": 23,
      "y": 5,
      "z": 18,
      "name": "Rock_Shale"
    },
    {
      "x": 23,
      "y": 6,
      "z": 18,
      "name": "Rock_Shale"
    },
    {
      "x": 23,
      "y": 7,
      "z": 18,
      "name": "*Plant_Crop_Berry_Winter_Block_State_Definitions_StageFinal"
    },
    {
      "x": 23,
      "y": 3,
      "z": 19,
      "name": "Rock_Shale"
    },
    {
      "x": 23,
      "y": 4,
      "z": 19,
      "name": "Rock_Shale"
    },
    {
      "x": 23,
      "y": 5,
      "z": 19,
      "name": "Rock_Shale"
    },
    {
      "x": 23,
      "y": 6,
      "z": 19,
      "name": "Rock_Shale"
    },
    {
      "x": 23,
      "y": 7,
      "z": 19,
      "name": "Wood_Crystal_Trunk_Full"
    },
    {
      "x": 23,
      "y": 16,
      "z": 19,
      "name": "Wood_Crystal_Trunk_Full"
    },
    {
      "x": 23,
      "y": 19,
      "z": 19,
      "name": "Plant_Leaves_Crystal"
    },
    {
      "x": 23,
      "y": 21,
      "z": 19,
      "name": "Plant_Leaves_Crystal"
    },
    {
      "x": 23,
      "y": 3,
      "z": 20,
      "name": "Rock_Shale"
    },
    {
      "x": 23,
      "y": 4,
      "z": 20,
      "name": "Rock_Shale"
    },
    {
      "x": 23,
      "y": 5,
      "z": 20,
      "name": "Rock_Shale"
    },
    {
      "x": 23,
      "y": 6,
      "z": 20,
      "name": "Rock_Shale"
    },
    {
      "x": 23,
      "y": 7,
      "z": 20,
      "name": "Rock_Shale"
    },
    {
      "x": 23,
      "y": 8,
      "z": 20,
      "name": "Rock_Shale"
    },
    {
      "x": 23,
      "y": 9,
      "z": 20,
      "name": "*Plant_Crop_Berry_Winter_Block_State_Definitions_StageFinal"
    },
    {
      "x": 23,
      "y": 16,
      "z": 20,
      "name": "Wood_Crystal_Trunk_Full"
    },
    {
      "x": 23,
      "y": 17,
      "z": 20,
      "name": "Wood_Crystal_Trunk_Full"
    },
    {
      "x": 23,
      "y": 19,
      "z": 20,
      "name": "Wood_Crystal_Trunk_Full"
    },
    {
      "x": 23,
      "y": 20,
      "z": 20,
      "name": "Rock_Crystal_Pink_Medium",
      "rotation": 8
    },
    {
      "x": 23,
      "y": 21,
      "z": 20,
      "name": "Plant_Leaves_Crystal"
    },
    {
      "x": 23,
      "y": 4,
      "z": 21,
      "name": "Rock_Shale"
    },
    {
      "x": 23,
      "y": 5,
      "z": 21,
      "name": "Rock_Shale"
    },
    {
      "x": 23,
      "y": 6,
      "z": 21,
      "name": "Rock_Shale"
    },
    {
      "x": 23,
      "y": 7,
      "z": 21,
      "name": "Rock_Shale"
    },
    {
      "x": 23,
      "y": 8,
      "z": 21,
      "name": "Wood_Crystal_Trunk"
    },
    {
      "x": 23,
      "y": 9,
      "z": 21,
      "name": "Wood_Crystal_Trunk_Full"
    },
    {
      "x": 23,
      "y": 15,
      "z": 21,
      "name": "Wood_Crystal_Trunk_Full"
    },
    {
      "x": 23,
      "y": 16,
      "z": 21,
      "name": "Wood_Crystal_Trunk_Full"
    },
    {
      "x": 23,
      "y": 19,
      "z": 21,
      "name": "Wood_Crystal_Branch_Long",
      "rotation": 4
    },
    {
      "x": 23,
      "y": 20,
      "z": 21,
      "name": "Plant_Leaves_Crystal"
    },
    {
      "x": 23,
      "y": 21,
      "z": 21,
      "name": "Plant_Leaves_Crystal"
    },
    {
      "x": 23,
      "y": 4,
      "z": 22,
      "name": "Rock_Shale"
    },
    {
      "x": 23,
      "y": 5,
      "z": 22,
      "name": "Rock_Shale"
    },
    {
      "x": 23,
      "y": 6,
      "z": 22,
      "name": "Rock_Shale"
    },
    {
      "x": 23,
      "y": 7,
      "z": 22,
      "name": "Rock_Shale"
    },
    {
      "x": 23,
      "y": 8,
      "z": 22,
      "name": "Wood_Crystal_Trunk"
    },
    {
      "x": 23,
      "y": 9,
      "z": 22,
      "name": "Wood_Crystal_Trunk"
    },
    {
      "x": 23,
      "y": 10,
      "z": 22,
      "name": "Wood_Crystal_Trunk_Full"
    },
    {
      "x": 23,
      "y": 15,
      "z": 22,
      "name": "Wood_Crystal_Trunk_Full"
    },
    {
      "x": 23,
      "y": 16,
      "z": 22,
      "name": "Wood_Crystal_Trunk_Full"
    },
    {
      "x": 23,
      "y": 19,
      "z": 22,
      "name": "Plant_Leaves_Crystal"
    },
    {
      "x": 23,
      "y": 3,
      "z": 23,
      "name": "Wood_Crystal_Roots"
    },
    {
      "x": 23,
      "y": 4,
      "z": 23,
      "name": "Wood_Crystal_Trunk_Full"
    },
    {
      "x": 23,
      "y": 5,
      "z": 23,
      "name": "Wood_Crystal_Trunk"
    },
    {
      "x": 23,
      "y": 6,
      "z": 23,
      "name": "Wood_Crystal_Trunk"
    },
    {
      "x": 23,
      "y": 7,
      "z": 23,
      "name": "Wood_Crystal_Trunk"
    },
    {
      "x": 23,
      "y": 8,
      "z": 23,
      "name": "Wood_Crystal_Trunk"
    },
    {
      "x": 23,
      "y": 9,
      "z": 23,
      "name": "Wood_Crystal_Trunk"
    },
    {
      "x": 23,
      "y": 10,
      "z": 23,
      "name": "Wood_Crystal_Trunk"
    },
    {
      "x": 23,
      "y": 11,
      "z": 23,
      "name": "Wood_Crystal_Trunk_Full"
    },
    {
      "x": 23,
      "y": 13,
      "z": 23,
      "name": "Wood_Crystal_Trunk_Full"
    },
    {
      "x": 23,
      "y": 14,
      "z": 23,
      "name": "Wood_Crystal_Trunk_Full"
    },
    {
      "x": 23,
      "y": 15,
      "z": 23,
      "name": "Wood_Crystal_Trunk_Full"
    },
    {
      "x": 23,
      "y": 19,
      "z": 23,
      "name": "Plant_Leaves_Crystal"
    },
    {
      "x": 23,
      "y": 20,
      "z": 23,
      "name": "Plant_Leaves_Crystal"
    },
    {
      "x": 23,
      "y": 9,
      "z": 24,
      "name": "Wood_Crystal_Trunk_Full"
    },
    {
      "x": 23,
      "y": 10,
      "z": 24,
      "name": "Wood_Crystal_Trunk"
    },
    {
      "x": 23,
      "y": 11,
      "z": 24,
      "name": "Wood_Crystal_Trunk"
    },
    {
      "x": 23,
      "y": 12,
      "z": 24,
      "name": "Wood_Crystal_Trunk_Full"
    },
    {
      "x": 23,
      "y": 13,
      "z": 24,
      "name": "Wood_Crystal_Trunk_Full"
    },
    {
      "x": 23,
      "y": 14,
      "z": 24,
      "name": "Wood_Crystal_Trunk_Full"
    },
    {
      "x": 23,
      "y": 15,
      "z": 24,
      "name": "Wood_Crystal_Trunk_Full"
    },
    {
      "x": 23,
      "y": 19,
      "z": 24,
      "name": "Plant_Leaves_Crystal"
    },
    {
      "x": 23,
      "y": 11,
      "z": 25,
      "name": "Wood_Crystal_Trunk_Full"
    },
    {
      "x": 23,
      "y": 12,
      "z": 25,
      "name": "Wood_Crystal_Trunk"
    },
    {
      "x": 23,
      "y": 13,
      "z": 25,
      "name": "Wood_Crystal_Trunk_Full"
    },
    {
      "x": 23,
      "y": 19,
      "z": 25,
      "name": "Plant_Leaves_Crystal"
    },
    {
      "x": 23,
      "y": 19,
      "z": 26,
      "name": "Plant_Leaves_Crystal"
    },
    {
      "x": 24,
      "y": 18,
      "z": 6,
      "name": "Plant_Leaves_Crystal"
    },
    {
      "x": 24,
      "y": 18,
      "z": 7,
      "name": "Plant_Leaves_Crystal"
    },
    {
      "x": 24,
      "y": 19,
      "z": 7,
      "name": "Plant_Leaves_Crystal"
    },
    {
      "x": 24,
      "y": 18,
      "z": 8,
      "name": "Plant_Leaves_Crystal"
    },
    {
      "x": 24,
      "y": 19,
      "z": 8,
      "name": "Plant_Leaves_Crystal"
    },
    {
      "x": 24,
      "y": 18,
      "z": 9,
      "name": "Wood_Crystal_Branch_Long",
      "rotation": 4
    },
    {
      "x": 24,
      "y": 19,
      "z": 9,
      "name": "Plant_Leaves_Crystal"
    },
    {
      "x": 24,
      "y": 18,
      "z": 10,
      "name": "Wood_Crystal_Trunk_Full"
    },
    {
      "x": 24,
      "y": 19,
      "z": 10,
      "name": "Plant_Leaves_Crystal"
    },
    {
      "x": 24,
      "y": 18,
      "z": 11,
      "name": "Wood_Crystal_Trunk_Full"
    },
    {
      "x": 24,
      "y": 19,
      "z": 11,
      "name": "Plant_Leaves_Crystal"
    },
    {
      "x": 24,
      "y": 18,
      "z": 12,
      "name": "Wood_Crystal_Trunk_Full"
    },
    {
      "x": 24,
      "y": 18,
      "z": 13,
      "name": "Plant_Leaves_Crystal"
    },
    {
      "x": 24,
      "y": 19,
      "z": 13,
      "name": "Plant_Leaves_Crystal"
    },
    {
      "x": 24,
      "y": 18,
      "z": 14,
      "name": "Plant_Leaves_Crystal"
    },
    {
      "x": 24,
      "y": 19,
      "z": 14,
      "name": "Plant_Leaves_Crystal"
    },
    {
      "x": 24,
      "y": 18,
      "z": 15,
      "name": "Plant_Leaves_Crystal"
    },
    {
      "x": 24,
      "y": 16,
      "z": 16,
      "name": "Plant_Leaves_Crystal"
    },
    {
      "x": 24,
      "y": 16,
      "z": 17,
      "name": "Plant_Leaves_Crystal"
    },
    {
      "x": 24,
      "y": 19,
      "z": 17,
      "name": "Plant_Leaves_Crystal"
    },
    {
      "x": 24,
      "y": 20,
      "z": 17,
      "name": "Plant_Leaves_Crystal"
    },
    {
      "x": 24,
      "y": 5,
      "z": 18,
      "name": "Rock_Shale"
    },
    {
      "x": 24,
      "y": 19,
      "z": 18,
      "name": "Plant_Leaves_Crystal"
    },
    {
      "x": 24,
      "y": 4,
      "z": 19,
      "name": "Rock_Shale"
    },
    {
      "x": 24,
      "y": 5,
      "z": 19,
      "name": "Rock_Shale"
    },
    {
      "x": 24,
      "y": 6,
      "z": 19,
      "name": "Rock_Shale"
    },
    {
      "x": 24,
      "y": 7,
      "z": 19,
      "name": "Rock_Crystal_Pink_Medium"
    },
    {
      "x": 24,
      "y": 19,
      "z": 19,
      "name": "Plant_Leaves_Crystal"
    },
    {
      "x": 24,
      "y": 20,
      "z": 19,
      "name": "Plant_Leaves_Crystal"
    },
    {
      "x": 24,
      "y": 4,
      "z": 20,
      "name": "Rock_Shale"
    },
    {
      "x": 24,
      "y": 5,
      "z": 20,
      "name": "Rock_Shale"
    },
    {
      "x": 24,
      "y": 6,
      "z": 20,
      "name": "Rock_Shale"
    },
    {
      "x": 24,
      "y": 7,
      "z": 20,
      "name": "Rock_Shale"
    },
    {
      "x": 24,
      "y": 19,
      "z": 20,
      "name": "Wood_Crystal_Branch_Long",
      "rotation": 5
    },
    {
      "x": 24,
      "y": 20,
      "z": 20,
      "name": "Plant_Leaves_Crystal"
    },
    {
      "x": 24,
      "y": 21,
      "z": 20,
      "name": "Plant_Leaves_Crystal"
    },
    {
      "x": 24,
      "y": 4,
      "z": 21,
      "name": "Rock_Shale"
    },
    {
      "x": 24,
      "y": 5,
      "z": 21,
      "name": "Rock_Shale"
    },
    {
      "x": 24,
      "y": 6,
      "z": 21,
      "name": "Rock_Shale"
    },
    {
      "x": 24,
      "y": 7,
      "z": 21,
      "name": "Wood_Crystal_Trunk_Full"
    },
    {
      "x": 24,
      "y": 19,
      "z": 21,
      "name": "Plant_Leaves_Crystal"
    },
    {
      "x": 24,
      "y": 20,
      "z": 21,
      "name": "Plant_Leaves_Crystal"
    },
    {
      "x": 24,
      "y": 21,
      "z": 21,
      "name": "Plant_Leaves_Crystal"
    },
    {
      "x": 24,
      "y": 5,
      "z": 22,
      "name": "Rock_Shale"
    },
    {
      "x": 24,
      "y": 6,
      "z": 22,
      "name": "Rock_Shale"
    },
    {
      "x": 24,
      "y": 7,
      "z": 22,
      "name": "Wood_Crystal_Trunk"
    },
    {
      "x": 24,
      "y": 8,
      "z": 22,
      "name": "Wood_Crystal_Trunk"
    },
    {
      "x": 24,
      "y": 9,
      "z": 22,
      "name": "Wood_Crystal_Trunk_Full"
    },
    {
      "x": 24,
      "y": 15,
      "z": 22,
      "name": "Wood_Crystal_Trunk_Full"
    },
    {
      "x": 24,
      "y": 19,
      "z": 22,
      "name": "Plant_Leaves_Crystal"
    },
    {
      "x": 24,
      "y": 8,
      "z": 23,
      "name": "Wood_Crystal_Trunk_Full"
    },
    {
      "x": 24,
      "y": 9,
      "z": 23,
      "name": "Wood_Crystal_Trunk"
    },
    {
      "x": 24,
      "y": 10,
      "z": 23,
      "name": "Wood_Crystal_Trunk_Full"
    },
    {
      "x": 24,
      "y": 15,
      "z": 23,
      "name": "Wood_Crystal_Trunk_Full"
    },
    {
      "x": 24,
      "y": 16,
      "z": 23,
      "name": "Wood_Crystal_Trunk_Full"
    },
    {
      "x": 24,
      "y": 19,
      "z": 23,
      "name": "Plant_Leaves_Crystal"
    },
    {
      "x": 24,
      "y": 10,
      "z": 24,
      "name": "Wood_Crystal_Trunk_Full"
    },
    {
      "x": 24,
      "y": 11,
      "z": 24,
      "name": "Wood_Crystal_Trunk"
    },
    {
      "x": 24,
      "y": 12,
      "z": 24,
      "name": "Wood_Crystal_Trunk_Full"
    },
    {
      "x": 24,
      "y": 14,
      "z": 24,
      "name": "Wood_Crystal_Trunk_Full"
    },
    {
      "x": 24,
      "y": 15,
      "z": 24,
      "name": "Wood_Crystal_Trunk"
    },
    {
      "x": 24,
      "y": 16,
      "z": 24,
      "name": "Wood_Crystal_Trunk_Full"
    },
    {
      "x": 24,
      "y": 19,
      "z": 24,
      "name": "Plant_Leaves_Crystal"
    },
    {
      "x": 24,
      "y": 12,
      "z": 25,
      "name": "Wood_Crystal_Trunk_Full"
    },
    {
      "x": 24,
      "y": 13,
      "z": 25,
      "name": "Wood_Crystal_Trunk"
    },
    {
      "x": 24,
      "y": 14,
      "z": 25,
      "name": "Wood_Crystal_Trunk"
    },
    {
      "x": 24,
      "y": 15,
      "z": 25,
      "name": "Wood_Crystal_Trunk_Full"
    },
    {
      "x": 24,
      "y": 12,
      "z": 26,
      "name": "Wood_Crystal_Trunk_Full"
    },
    {
      "x": 24,
      "y": 13,
      "z": 26,
      "name": "Wood_Crystal_Trunk"
    },
    {
      "x": 24,
      "y": 14,
      "z": 26,
      "name": "Wood_Crystal_Trunk_Full"
    },
    {
      "x": 24,
      "y": 16,
      "z": 26,
      "name": "Plant_Leaves_Crystal"
    },
    {
      "x": 25,
      "y": 18,
      "z": 7,
      "name": "Plant_Leaves_Crystal"
    },
    {
      "x": 25,
      "y": 18,
      "z": 8,
      "name": "Plant_Leaves_Crystal"
    },
    {
      "x": 25,
      "y": 19,
      "z": 8,
      "name": "Plant_Leaves_Crystal"
    },
    {
      "x": 25,
      "y": 18,
      "z": 9,
      "name": "Plant_Leaves_Crystal"
    },
    {
      "x": 25,
      "y": 19,
      "z": 9,
      "name": "Plant_Leaves_Crystal"
    },
    {
      "x": 25,
      "y": 18,
      "z": 10,
      "name": "Plant_Leaves_Crystal"
    },
    {
      "x": 25,
      "y": 19,
      "z": 10,
      "name": "Plant_Leaves_Crystal"
    },
    {
      "x": 25,
      "y": 18,
      "z": 11,
      "name": "Wood_Crystal_Branch_Long",
      "rotation": 5
    },
    {
      "x": 25,
      "y": 19,
      "z": 11,
      "name": "Plant_Leaves_Crystal"
    },
    {
      "x": 25,
      "y": 18,
      "z": 12,
      "name": "Plant_Leaves_Crystal"
    },
    {
      "x": 25,
      "y": 19,
      "z": 12,
      "name": "Plant_Leaves_Crystal"
    },
    {
      "x": 25,
      "y": 18,
      "z": 13,
      "name": "Plant_Leaves_Crystal"
    },
    {
      "x": 25,
      "y": 19,
      "z": 13,
      "name": "Plant_Leaves_Crystal"
    },
    {
      "x": 25,
      "y": 16,
      "z": 14,
      "name": "Plant_Leaves_Crystal"
    },
    {
      "x": 25,
      "y": 18,
      "z": 14,
      "name": "Plant_Leaves_Crystal"
    },
    {
      "x": 25,
      "y": 16,
      "z": 15,
      "name": "Plant_Leaves_Crystal"
    },
    {
      "x": 25,
      "y": 18,
      "z": 15,
      "name": "Plant_Leaves_Crystal"
    },
    {
      "x": 25,
      "y": 16,
      "z": 16,
      "name": "Plant_Leaves_Crystal"
    },
    {
      "x": 25,
      "y": 16,
      "z": 17,
      "name": "Plant_Leaves_Crystal"
    },
    {
      "x": 25,
      "y": 17,
      "z": 17,
      "name": "Plant_Leaves_Crystal"
    },
    {
      "x": 25,
      "y": 19,
      "z": 17,
      "name": "Plant_Leaves_Crystal"
    },
    {
      "x": 25,
      "y": 16,
      "z": 18,
      "name": "Plant_Leaves_Crystal"
    },
    {
      "x": 25,
      "y": 19,
      "z": 18,
      "name": "Plant_Leaves_Crystal"
    },
    {
      "x": 25,
      "y": 20,
      "z": 18,
      "name": "Plant_Leaves_Crystal"
    },
    {
      "x": 25,
      "y": 16,
      "z": 19,
      "name": "Plant_Leaves_Crystal"
    },
    {
      "x": 25,
      "y": 17,
      "z": 19,
      "name": "Plant_Leaves_Crystal"
    },
    {
      "x": 25,
      "y": 19,
      "z": 19,
      "name": "Plant_Leaves_Crystal"
    },
    {
      "x": 25,
      "y": 20,
      "z": 19,
      "name": "Plant_Leaves_Crystal"
    },
    {
      "x": 25,
      "y": 2,
      "z": 20,
      "name": "Wood_Crystal_Roots"
    },
    {
      "x": 25,
      "y": 3,
      "z": 20,
      "name": "Wood_Crystal_Trunk_Full"
    },
    {
      "x": 25,
      "y": 4,
      "z": 20,
      "name": "Wood_Crystal_Trunk"
    },
    {
      "x": 25,
      "y": 5,
      "z": 20,
      "name": "Wood_Crystal_Trunk_Full"
    },
    {
      "x": 25,
      "y": 19,
      "z": 20,
      "name": "Plant_Leaves_Crystal"
    },
    {
      "x": 25,
      "y": 5,
      "z": 21,
      "name": "Wood_Crystal_Trunk_Full"
    },
    {
      "x": 25,
      "y": 6,
      "z": 21,
      "name": "Wood_Crystal_Trunk_Full"
    },
    {
      "x": 25,
      "y": 19,
      "z": 21,
      "name": "Plant_Leaves_Crystal"
    },
    {
      "x": 25,
      "y": 20,
      "z": 21,
      "name": "Plant_Leaves_Crystal"
    },
    {
      "x": 25,
      "y": 15,
      "z": 22,
      "name": "Wood_Crystal_Trunk_Full"
    },
    {
      "x": 25,
      "y": 20,
      "z": 22,
      "name": "Plant_Leaves_Crystal"
    },
    {
      "x": 25,
      "y": 14,
      "z": 24,
      "name": "Wood_Crystal_Trunk_Full"
    },
    {
      "x": 25,
      "y": 14,
      "z": 25,
      "name": "Wood_Crystal_Trunk_Full"
    },
    {
      "x": 25,
      "y": 15,
      "z": 25,
      "name": "Wood_Crystal_Trunk_Full"
    },
    {
      "x": 25,
      "y": 16,
      "z": 25,
      "name": "Plant_Leaves_Crystal"
    },
    {
      "x": 25,
      "y": 13,
      "z": 26,
      "name": "Wood_Crystal_Trunk_Full"
    },
    {
      "x": 25,
      "y": 14,
      "z": 26,
      "name": "Wood_Crystal_Trunk"
    },
    {
      "x": 25,
      "y": 15,
      "z": 26,
      "name": "Wood_Crystal_Trunk_Full"
    },
    {
      "x": 25,
      "y": 16,
      "z": 26,
      "name": "Plant_Leaves_Crystal"
    },
    {
      "x": 25,
      "y": 13,
      "z": 27,
      "name": "Wood_Crystal_Trunk_Full"
    },
    {
      "x": 25,
      "y": 14,
      "z": 27,
      "name": "Wood_Crystal_Trunk_Full"
    },
    {
      "x": 25,
      "y": 16,
      "z": 28,
      "name": "Plant_Leaves_Crystal"
    },
    {
      "x": 26,
      "y": 18,
      "z": 7,
      "name": "Plant_Leaves_Crystal"
    },
    {
      "x": 26,
      "y": 18,
      "z": 8,
      "name": "Plant_Leaves_Crystal"
    },
    {
      "x": 26,
      "y": 18,
      "z": 9,
      "name": "Plant_Leaves_Crystal"
    },
    {
      "x": 26,
      "y": 18,
      "z": 11,
      "name": "Plant_Leaves_Crystal"
    },
    {
      "x": 26,
      "y": 18,
      "z": 12,
      "name": "Plant_Leaves_Crystal"
    },
    {
      "x": 26,
      "y": 19,
      "z": 12,
      "name": "Plant_Leaves_Crystal"
    },
    {
      "x": 26,
      "y": 18,
      "z": 13,
      "name": "Plant_Leaves_Crystal"
    },
    {
      "x": 26,
      "y": 19,
      "z": 13,
      "name": "Plant_Leaves_Crystal"
    },
    {
      "x": 26,
      "y": 16,
      "z": 14,
      "name": "Plant_Leaves_Crystal"
    },
    {
      "x": 26,
      "y": 18,
      "z": 14,
      "name": "Plant_Leaves_Crystal"
    },
    {
      "x": 26,
      "y": 16,
      "z": 15,
      "name": "Plant_Leaves_Crystal"
    },
    {
      "x": 26,
      "y": 16,
      "z": 16,
      "name": "Plant_Leaves_Crystal"
    },
    {
      "x": 26,
      "y": 17,
      "z": 17,
      "name": "Plant_Leaves_Crystal"
    },
    {
      "x": 26,
      "y": 16,
      "z": 18,
      "name": "Plant_Leaves_Crystal"
    },
    {
      "x": 26,
      "y": 17,
      "z": 18,
      "name": "Plant_Leaves_Crystal"
    },
    {
      "x": 26,
      "y": 19,
      "z": 18,
      "name": "Plant_Leaves_Crystal"
    },
    {
      "x": 26,
      "y": 16,
      "z": 19,
      "name": "Wood_Crystal_Branch_Long",
      "rotation": 5
    },
    {
      "x": 26,
      "y": 19,
      "z": 19,
      "name": "Plant_Leaves_Crystal"
    },
    {
      "x": 26,
      "y": 20,
      "z": 19,
      "name": "Plant_Leaves_Crystal"
    },
    {
      "x": 26,
      "y": 17,
      "z": 20,
      "name": "Plant_Leaves_Crystal"
    },
    {
      "x": 26,
      "y": 19,
      "z": 20,
      "name": "Plant_Leaves_Crystal"
    },
    {
      "x": 26,
      "y": 20,
      "z": 20,
      "name": "Plant_Leaves_Crystal"
    },
    {
      "x": 26,
      "y": 18,
      "z": 21,
      "name": "Plant_Leaves_Crystal"
    },
    {
      "x": 26,
      "y": 19,
      "z": 21,
      "name": "Plant_Leaves_Crystal"
    },
    {
      "x": 26,
      "y": 20,
      "z": 21,
      "name": "Plant_Leaves_Crystal"
    },
    {
      "x": 26,
      "y": 15,
      "z": 22,
      "name": "Wood_Crystal_Trunk_Full"
    },
    {
      "x": 26,
      "y": 19,
      "z": 22,
      "name": "Plant_Leaves_Crystal"
    },
    {
      "x": 26,
      "y": 17,
      "z": 23,
      "name": "Plant_Leaves_Crystal"
    },
    {
      "x": 26,
      "y": 19,
      "z": 23,
      "name": "Plant_Leaves_Crystal"
    },
    {
      "x": 26,
      "y": 16,
      "z": 24,
      "name": "Plant_Leaves_Crystal"
    },
    {
      "x": 26,
      "y": 17,
      "z": 24,
      "name": "Plant_Leaves_Crystal"
    },
    {
      "x": 26,
      "y": 19,
      "z": 24,
      "name": "Plant_Leaves_Crystal"
    },
    {
      "x": 26,
      "y": 16,
      "z": 25,
      "name": "Plant_Leaves_Crystal"
    },
    {
      "x": 26,
      "y": 17,
      "z": 25,
      "name": "Plant_Leaves_Crystal"
    },
    {
      "x": 26,
      "y": 16,
      "z": 26,
      "name": "Plant_Leaves_Crystal"
    },
    {
      "x": 26,
      "y": 17,
      "z": 26,
      "name": "Plant_Leaves_Crystal"
    },
    {
      "x": 26,
      "y": 16,
      "z": 27,
      "name": "Plant_Leaves_Crystal"
    },
    {
      "x": 26,
      "y": 16,
      "z": 28,
      "name": "Plant_Leaves_Crystal"
    },
    {
      "x": 27,
      "y": 18,
      "z": 7,
      "name": "Plant_Leaves_Crystal"
    },
    {
      "x": 27,
      "y": 18,
      "z": 8,
      "name": "Plant_Leaves_Crystal"
    },
    {
      "x": 27,
      "y": 18,
      "z": 9,
      "name": "Plant_Leaves_Crystal"
    },
    {
      "x": 27,
      "y": 18,
      "z": 12,
      "name": "Plant_Leaves_Crystal"
    },
    {
      "x": 27,
      "y": 18,
      "z": 13,
      "name": "Plant_Leaves_Crystal"
    },
    {
      "x": 27,
      "y": 16,
      "z": 14,
      "name": "Plant_Leaves_Crystal"
    },
    {
      "x": 27,
      "y": 16,
      "z": 15,
      "name": "Plant_Leaves_Crystal"
    },
    {
      "x": 27,
      "y": 16,
      "z": 16,
      "name": "Plant_Leaves_Crystal"
    },
    {
      "x": 27,
      "y": 17,
      "z": 16,
      "name": "Plant_Leaves_Crystal"
    },
    {
      "x": 27,
      "y": 16,
      "z": 17,
      "name": "Wood_Crystal_Branch_Long",
      "rotation": 4
    },
    {
      "x": 27,
      "y": 17,
      "z": 17,
      "name": "Plant_Leaves_Crystal"
    },
    {
      "x": 27,
      "y": 16,
      "z": 18,
      "name": "Wood_Crystal_Trunk_Full"
    },
    {
      "x": 27,
      "y": 17,
      "z": 18,
      "name": "Plant_Leaves_Crystal"
    },
    {
      "x": 27,
      "y": 19,
      "z": 18,
      "name": "Plant_Leaves_Crystal"
    },
    {
      "x": 27,
      "y": 16,
      "z": 19,
      "name": "Wood_Crystal_Trunk_Full"
    },
    {
      "x": 27,
      "y": 17,
      "z": 19,
      "name": "Plant_Leaves_Crystal"
    },
    {
      "x": 27,
      "y": 18,
      "z": 19,
      "name": "Plant_Leaves_Crystal"
    },
    {
      "x": 27,
      "y": 19,
      "z": 19,
      "name": "Plant_Leaves_Crystal"
    },
    {
      "x": 27,
      "y": 16,
      "z": 20,
      "name": "Wood_Crystal_Trunk_Full"
    },
    {
      "x": 27,
      "y": 18,
      "z": 20,
      "name": "Plant_Leaves_Crystal"
    },
    {
      "x": 27,
      "y": 19,
      "z": 20,
      "name": "Plant_Leaves_Crystal"
    },
    {
      "x": 27,
      "y": 15,
      "z": 21,
      "name": "Wood_Crystal_Trunk_Full"
    },
    {
      "x": 27,
      "y": 16,
      "z": 21,
      "name": "Wood_Crystal_Trunk_Full"
    },
    {
      "x": 27,
      "y": 18,
      "z": 21,
      "name": "Plant_Leaves_Crystal"
    },
    {
      "x": 27,
      "y": 19,
      "z": 21,
      "name": "Plant_Leaves_Crystal"
    },
    {
      "x": 27,
      "y": 15,
      "z": 22,
      "name": "Wood_Crystal_Trunk_Full"
    },
    {
      "x": 27,
      "y": 19,
      "z": 22,
      "name": "Plant_Leaves_Crystal"
    },
    {
      "x": 27,
      "y": 18,
      "z": 23,
      "name": "Plant_Leaves_Crystal"
    },
    {
      "x": 27,
      "y": 16,
      "z": 24,
      "name": "Plant_Leaves_Crystal"
    },
    {
      "x": 27,
      "y": 17,
      "z": 24,
      "name": "Plant_Leaves_Crystal"
    },
    {
      "x": 27,
      "y": 18,
      "z": 24,
      "name": "Plant_Leaves_Crystal"
    },
    {
      "x": 27,
      "y": 16,
      "z": 25,
      "name": "Wood_Crystal_Branch_Long",
      "rotation": 5
    },
    {
      "x": 27,
      "y": 17,
      "z": 25,
      "name": "Plant_Leaves_Crystal"
    },
    {
      "x": 27,
      "y": 16,
      "z": 26,
      "name": "Plant_Leaves_Crystal"
    },
    {
      "x": 27,
      "y": 16,
      "z": 27,
      "name": "Plant_Leaves_Crystal"
    },
    {
      "x": 27,
      "y": 16,
      "z": 28,
      "name": "Plant_Leaves_Crystal"
    },
    {
      "x": 28,
      "y": 16,
      "z": 14,
      "name": "Plant_Leaves_Crystal"
    },
    {
      "x": 28,
      "y": 16,
      "z": 15,
      "name": "Plant_Leaves_Crystal"
    },
    {
      "x": 28,
      "y": 16,
      "z": 16,
      "name": "Plant_Leaves_Crystal"
    },
    {
      "x": 28,
      "y": 16,
      "z": 17,
      "name": "Plant_Leaves_Crystal"
    },
    {
      "x": 28,
      "y": 17,
      "z": 17,
      "name": "Plant_Leaves_Crystal"
    },
    {
      "x": 28,
      "y": 16,
      "z": 18,
      "name": "Plant_Leaves_Crystal"
    },
    {
      "x": 28,
      "y": 17,
      "z": 18,
      "name": "Plant_Leaves_Crystal"
    },
    {
      "x": 28,
      "y": 16,
      "z": 19,
      "name": "Plant_Leaves_Crystal"
    },
    {
      "x": 28,
      "y": 17,
      "z": 19,
      "name": "Plant_Leaves_Crystal"
    },
    {
      "x": 28,
      "y": 18,
      "z": 19,
      "name": "Plant_Leaves_Crystal"
    },
    {
      "x": 28,
      "y": 16,
      "z": 20,
      "name": "Wood_Crystal_Trunk_Full"
    },
    {
      "x": 28,
      "y": 17,
      "z": 20,
      "name": "Rock_Crystal_Pink_Medium"
    },
    {
      "x": 28,
      "y": 18,
      "z": 20,
      "name": "Plant_Leaves_Crystal"
    },
    {
      "x": 28,
      "y": 19,
      "z": 20,
      "name": "Plant_Leaves_Crystal"
    },
    {
      "x": 28,
      "y": 18,
      "z": 21,
      "name": "Plant_Leaves_Crystal"
    },
    {
      "x": 28,
      "y": 19,
      "z": 21,
      "name": "Plant_Leaves_Crystal"
    },
    {
      "x": 28,
      "y": 15,
      "z": 22,
      "name": "Wood_Crystal_Trunk_Full"
    },
    {
      "x": 28,
      "y": 17,
      "z": 22,
      "name": "Plant_Leaves_Crystal"
    },
    {
      "x": 28,
      "y": 15,
      "z": 23,
      "name": "Wood_Crystal_Trunk_Full"
    },
    {
      "x": 28,
      "y": 16,
      "z": 23,
      "name": "Wood_Crystal_Trunk_Full"
    },
    {
      "x": 28,
      "y": 17,
      "z": 23,
      "name": "Plant_Leaves_Crystal"
    },
    {
      "x": 28,
      "y": 18,
      "z": 23,
      "name": "Plant_Leaves_Crystal"
    },
    {
      "x": 28,
      "y": 16,
      "z": 24,
      "name": "Wood_Crystal_Trunk_Full"
    },
    {
      "x": 28,
      "y": 17,
      "z": 24,
      "name": "Plant_Leaves_Crystal"
    },
    {
      "x": 28,
      "y": 18,
      "z": 24,
      "name": "Plant_Leaves_Crystal"
    },
    {
      "x": 28,
      "y": 16,
      "z": 25,
      "name": "Wood_Crystal_Trunk_Full"
    },
    {
      "x": 28,
      "y": 17,
      "z": 25,
      "name": "Rock_Crystal_Pink_Medium"
    },
    {
      "x": 28,
      "y": 18,
      "z": 25,
      "name": "Plant_Leaves_Crystal"
    },
    {
      "x": 28,
      "y": 16,
      "z": 26,
      "name": "Wood_Crystal_Branch_Long",
      "rotation": 4
    },
    {
      "x": 28,
      "y": 17,
      "z": 26,
      "name": "Plant_Leaves_Crystal"
    },
    {
      "x": 28,
      "y": 16,
      "z": 27,
      "name": "Plant_Leaves_Crystal"
    },
    {
      "x": 28,
      "y": 16,
      "z": 28,
      "name": "Plant_Leaves_Crystal"
    },
    {
      "x": 28,
      "y": 16,
      "z": 29,
      "name": "Plant_Leaves_Crystal"
    },
    {
      "x": 29,
      "y": 16,
      "z": 15,
      "name": "Plant_Leaves_Crystal"
    },
    {
      "x": 29,
      "y": 16,
      "z": 17,
      "name": "Plant_Leaves_Crystal"
    },
    {
      "x": 29,
      "y": 17,
      "z": 17,
      "name": "Plant_Leaves_Crystal"
    },
    {
      "x": 29,
      "y": 16,
      "z": 18,
      "name": "Plant_Leaves_Crystal"
    },
    {
      "x": 29,
      "y": 17,
      "z": 18,
      "name": "Plant_Leaves_Crystal"
    },
    {
      "x": 29,
      "y": 17,
      "z": 19,
      "name": "Plant_Leaves_Crystal"
    },
    {
      "x": 29,
      "y": 16,
      "z": 20,
      "name": "Wood_Crystal_Branch_Long",
      "rotation": 5
    },
    {
      "x": 29,
      "y": 17,
      "z": 20,
      "name": "Plant_Leaves_Crystal"
    },
    {
      "x": 29,
      "y": 16,
      "z": 21,
      "name": "Plant_Leaves_Crystal"
    },
    {
      "x": 29,
      "y": 18,
      "z": 21,
      "name": "Plant_Leaves_Crystal"
    },
    {
      "x": 29,
      "y": 15,
      "z": 22,
      "name": "Wood_Crystal_Trunk_Full"
    },
    {
      "x": 29,
      "y": 16,
      "z": 22,
      "name": "Wood_Crystal_Trunk_Full"
    },
    {
      "x": 29,
      "y": 18,
      "z": 22,
      "name": "Plant_Leaves_Crystal"
    },
    {
      "x": 29,
      "y": 16,
      "z": 23,
      "name": "Plant_Leaves_Crystal"
    },
    {
      "x": 29,
      "y": 17,
      "z": 23,
      "name": "Plant_Leaves_Crystal"
    },
    {
      "x": 29,
      "y": 18,
      "z": 23,
      "name": "Plant_Leaves_Crystal"
    },
    {
      "x": 29,
      "y": 17,
      "z": 24,
      "name": "Plant_Leaves_Crystal"
    },
    {
      "x": 29,
      "y": 18,
      "z": 24,
      "name": "Plant_Leaves_Crystal"
    },
    {
      "x": 29,
      "y": 16,
      "z": 25,
      "name": "Wood_Crystal_Branch_Long",
      "rotation": 5
    },
    {
      "x": 29,
      "y": 17,
      "z": 25,
      "name": "Plant_Leaves_Crystal"
    },
    {
      "x": 29,
      "y": 16,
      "z": 26,
      "name": "Plant_Leaves_Crystal"
    },
    {
      "x": 29,
      "y": 17,
      "z": 26,
      "name": "Plant_Leaves_Crystal"
    },
    {
      "x": 29,
      "y": 16,
      "z": 27,
      "name": "Plant_Leaves_Crystal"
    },
    {
      "x": 29,
      "y": 16,
      "z": 28,
      "name": "Plant_Leaves_Crystal"
    },
    {
      "x": 30,
      "y": 16,
      "z": 17,
      "name": "Plant_Leaves_Crystal"
    },
    {
      "x": 30,
      "y": 16,
      "z": 18,
      "name": "Plant_Leaves_Crystal"
    },
    {
      "x": 30,
      "y": 16,
      "z": 19,
      "name": "Plant_Leaves_Crystal"
    },
    {
      "x": 30,
      "y": 17,
      "z": 19,
      "name": "Plant_Leaves_Crystal"
    },
    {
      "x": 30,
      "y": 16,
      "z": 20,
      "name": "Plant_Leaves_Crystal"
    },
    {
      "x": 30,
      "y": 17,
      "z": 20,
      "name": "Plant_Leaves_Crystal"
    },
    {
      "x": 30,
      "y": 18,
      "z": 20,
      "name": "Plant_Leaves_Crystal"
    },
    {
      "x": 30,
      "y": 16,
      "z": 21,
      "name": "Wood_Crystal_Branch_Long",
      "rotation": 4
    },
    {
      "x": 30,
      "y": 17,
      "z": 21,
      "name": "Plant_Leaves_Crystal"
    },
    {
      "x": 30,
      "y": 18,
      "z": 21,
      "name": "Plant_Leaves_Crystal"
    },
    {
      "x": 30,
      "y": 16,
      "z": 22,
      "name": "Wood_Crystal_Trunk_Full"
    },
    {
      "x": 30,
      "y": 18,
      "z": 22,
      "name": "Plant_Leaves_Crystal"
    },
    {
      "x": 30,
      "y": 16,
      "z": 23,
      "name": "Plant_Leaves_Crystal"
    },
    {
      "x": 30,
      "y": 17,
      "z": 23,
      "name": "Plant_Leaves_Crystal"
    },
    {
      "x": 30,
      "y": 18,
      "z": 23,
      "name": "Plant_Leaves_Crystal"
    },
    {
      "x": 30,
      "y": 16,
      "z": 24,
      "name": "Plant_Leaves_Crystal"
    },
    {
      "x": 30,
      "y": 17,
      "z": 24,
      "name": "Plant_Leaves_Crystal"
    },
    {
      "x": 30,
      "y": 16,
      "z": 25,
      "name": "Plant_Leaves_Crystal"
    },
    {
      "x": 30,
      "y": 17,
      "z": 25,
      "name": "Plant_Leaves_Crystal"
    },
    {
      "x": 30,
      "y": 16,
      "z": 26,
      "name": "Plant_Leaves_Crystal"
    },
    {
      "x": 30,
      "y": 16,
      "z": 27,
      "name": "Plant_Leaves_Crystal"
    },
    {
      "x": 30,
      "y": 16,
      "z": 28,
      "name": "Plant_Leaves_Crystal"
    },
    {
      "x": 31,
      "y": 16,
      "z": 18,
      "name": "Plant_Leaves_Crystal"
    },
    {
      "x": 31,
      "y": 16,
      "z": 19,
      "name": "Plant_Leaves_Crystal"
    },
    {
      "x": 31,
      "y": 17,
      "z": 19,
      "name": "Plant_Leaves_Crystal"
    },
    {
      "x": 31,
      "y": 16,
      "z": 20,
      "name": "Plant_Leaves_Crystal"
    },
    {
      "x": 31,
      "y": 17,
      "z": 20,
      "name": "Plant_Leaves_Crystal"
    },
    {
      "x": 31,
      "y": 16,
      "z": 21,
      "name": "Plant_Leaves_Crystal"
    },
    {
      "x": 31,
      "y": 17,
      "z": 21,
      "name": "Plant_Leaves_Crystal"
    },
    {
      "x": 31,
      "y": 16,
      "z": 22,
      "name": "Wood_Crystal_Branch_Long",
      "rotation": 5
    },
    {
      "x": 31,
      "y": 17,
      "z": 22,
      "name": "Plant_Leaves_Crystal"
    },
    {
      "x": 31,
      "y": 16,
      "z": 23,
      "name": "Plant_Leaves_Crystal"
    },
    {
      "x": 31,
      "y": 17,
      "z": 23,
      "name": "Plant_Leaves_Crystal"
    },
    {
      "x": 32,
      "y": 16,
      "z": 18,
      "name": "Plant_Leaves_Crystal"
    },
    {
      "x": 32,
      "y": 16,
      "z": 19,
      "name": "Plant_Leaves_Crystal"
    },
    {
      "x": 32,
      "y": 16,
      "z": 20,
      "name": "Plant_Leaves_Crystal"
    },
    {
      "x": 32,
      "y": 17,
      "z": 20,
      "name": "Plant_Leaves_Crystal"
    },
    {
      "x": 32,
      "y": 16,
      "z": 21,
      "name": "Plant_Leaves_Crystal"
    },
    {
      "x": 32,
      "y": 17,
      "z": 21,
      "name": "Plant_Leaves_Crystal"
    },
    {
      "x": 32,
      "y": 16,
      "z": 22,
      "name": "Wood_Crystal_Branch_Long",
      "rotation": 5
    },
    {
      "x": 32,
      "y": 16,
      "z": 23,
      "name": "Plant_Leaves_Crystal"
    },
    {
      "x": 32,
      "y": 17,
      "z": 23,
      "name": "Plant_Leaves_Crystal"
    },
    {
      "x": 32,
      "y": 16,
      "z": 24,
      "name": "Plant_Leaves_Crystal"
    },
    {
      "x": 32,
      "y": 16,
      "z": 25,
      "name": "Plant_Leaves_Crystal"
    },
    {
      "x": 33,
      "y": 16,
      "z": 20,
      "name": "Plant_Leaves_Crystal"
    },
    {
      "x": 33,
      "y": 17,
      "z": 20,
      "name": "Plant_Leaves_Crystal"
    },
    {
      "x": 33,
      "y": 16,
      "z": 21,
      "name": "Plant_Leaves_Crystal"
    },
    {
      "x": 33,
      "y": 17,
      "z": 21,
      "name": "Plant_Leaves_Crystal"
    },
    {
      "x": 33,
      "y": 16,
      "z": 22,
      "name": "Plant_Leaves_Crystal"
    },
    {
      "x": 33,
      "y": 16,
      "z": 23,
      "name": "Plant_Leaves_Crystal"
    },
    {
      "x": 33,
      "y": 17,
      "z": 23,
      "name": "Plant_Leaves_Crystal"
    },
    {
      "x": 33,
      "y": 16,
      "z": 24,
      "name": "Plant_Leaves_Crystal"
    },
    {
      "x": 34,
      "y": 16,
      "z": 20,
      "name": "Plant_Leaves_Crystal"
    },
    {
      "x": 34,
      "y": 16,
      "z": 21,
      "name": "Plant_Leaves_Crystal"
    },
    {
      "x": 34,
      "y": 16,
      "z": 22,
      "name": "Plant_Leaves_Crystal"
    },
    {
      "x": 34,
      "y": 16,
      "z": 23,
      "name": "Plant_Leaves_Crystal"
    },
    {
      "x": 35,
      "y": 16,
      "z": 21,
      "name": "Plant_Leaves_Crystal"
    },
    {
      "x": 35,
      "y": 16,
      "z": 23,
      "name": "Plant_Leaves_Crystal"
    }
  ]
}