{
  "version": 8,
  "blockIdVersion": 8,
  "anchorX": 1,
  "anchorY": 7,
  "anchorZ": -2,
  "blocks": [
    {
      "x": -4,
      "y": 9,
      "z": -3,
      "name": "Rock_Slate"
    },
    {
      "x": -4,
      "y": 10,
      "z": -3,
      "name": "Rock_Slate"
    },
    {
      "x": -4,
      "y": 11,
      "z": -3,
      "name": "Rock_Slate"
    },
    {
      "x": -4,
      "y": 7,
      "z": -2,
      "name": "Rock_Slate"
    },
    {
      "x": -4,
      "y": 8,
      "z": -2,
      "name": "Rock_Slate"
    },
    {
      "x": -4,
      "y": 9,
      "z": -2,
      "name": "Rock_Slate"
    },
    {
      "x": -4,
      "y": 10,
      "z": -2,
      "name": "Rock_Slate"
    },
    {
      "x": -4,
      "y": 11,
      "z": -2,
      "name": "Rock_Slate"
    },
    {
      "x": -4,
      "y": 12,
      "z": -2,
      "name": "Rock_Slate"
    },
    {
      "x": -4,
      "y": 5,
      "z": -1,
      "name": "Rock_Slate"
    },
    {
      "x": -4,
      "y": 6,
      "z": -1,
      "name": "Rock_Slate"
    },
    {
      "x": -4,
      "y": 7,
      "z": -1,
      "name": "Rock_Slate"
    },
    {
      "x": -4,
      "y": 8,
      "z": -1,
      "name": "Rock_Slate"
    },
    {
      "x": -4,
      "y": 9,
      "z": -1,
      "name": "Rock_Slate"
    },
    {
      "x": -4,
      "y": 10,
      "z": -1,
      "name": "Rock_Slate"
    },
    {
      "x": -4,
      "y": 11,
      "z": -1,
      "name": "Rock_Slate"
    },
    {
      "x": -4,
      "y": 12,
      "z": -1,
      "name": "Rock_Slate"
    },
    {
      "x": -4,
      "y": 6,
      "z": 0,
      "name": "Rock_Slate"
    },
    {
      "x": -4,
      "y": 7,
      "z": 0,
      "name": "Rock_Slate"
    },
    {
      "x": -4,
      "y": 8,
      "z": 0,
      "name": "Rock_Slate"
    },
    {
      "x": -4,
      "y": 9,
      "z": 0,
      "name": "Rock_Slate"
    },
    {
      "x": -4,
      "y": 10,
      "z": 0,
      "name": "Rock_Slate"
    },
    {
      "x": -4,
      "y": 11,
      "z": 0,
      "name": "Rock_Slate"
    },
    {
      "x": -4,
      "y": 12,
      "z": 0,
      "name": "Rock_Slate"
    },
    {
      "x": -3,
      "y": 7,
      "z": -4,
      "name": "Rock_Slate"
    },
    {
      "x": -3,
      "y": 8,
      "z": -4,
      "name": "Rock_Slate"
    },
    {
      "x": -3,
      "y": 9,
      "z": -4,
      "name": "Rock_Slate"
    },
    {
      "x": -3,
      "y": 3,
      "z": -3,
      "name": "Rock_Slate"
    },
    {
      "x": -3,
      "y": 4,
      "z": -3,
      "name": "Rock_Slate"
    },
    {
      "x": -3,
      "y": 5,
      "z": -3,
      "name": "Rock_Slate"
    },
    {
      "x": -3,
      "y": 6,
      "z": -3,
      "name": "Rock_Slate"
    },
    {
      "x": -3,
      "y": 7,
      "z": -3,
      "name": "Rock_Slate"
    },
    {
      "x": -3,
      "y": 8,
      "z": -3,
      "name": "Rock_Slate"
    },
    {
      "x": -3,
      "y": 9,
      "z": -3,
      "name": "Rock_Slate"
    },
    {
      "x": -3,
      "y": 10,
      "z": -3,
      "name": "Rock_Slate"
    },
    {
      "x": -3,
      "y": 11,
      "z": -3,
      "name": "Rock_Slate"
    },
    {
      "x": -3,
      "y": 12,
      "z": -3,
      "name": "Rock_Slate"
    },
    {
      "x": -3,
      "y": 3,
      "z": -2,
      "name": "Rock_Slate"
    },
    {
      "x": -3,
      "y": 4,
      "z": -2,
      "name": "Rock_Slate"
    },
    {
      "x": -3,
      "y": 5,
      "z": -2,
      "name": "Rock_Slate"
    },
    {
      "x": -3,
      "y": 6,
      "z": -2,
      "name": "Rock_Slate"
    },
    {
      "x": -3,
      "y": 7,
      "z": -2,
      "name": "Rock_Slate"
    },
    {
      "x": -3,
      "y": 8,
      "z": -2,
      "name": "Rock_Slate"
    },
    {
      "x": -3,
      "y": 9,
      "z": -2,
      "name": "Rock_Slate"
    },
    {
      "x": -3,
      "y": 10,
      "z": -2,
      "name": "Rock_Slate"
    },
    {
      "x": -3,
      "y": 11,
      "z": -2,
      "name": "Rock_Slate"
    },
    {
      "x": -3,
      "y": 12,
      "z": -2,
      "name": "Rock_Slate"
    },
    {
      "x": -3,
      "y": 3,
      "z": -1,
      "name": "Rock_Slate"
    },
    {
      "x": -3,
      "y": 4,
      "z": -1,
      "name": "Rock_Slate"
    },
    {
      "x": -3,
      "y": 5,
      "z": -1,
      "name": "Rock_Slate"
    },
    {
      "x": -3,
      "y": 6,
      "z": -1,
      "name": "Rock_Slate"
    },
    {
      "x": -3,
      "y": 7,
      "z": -1,
      "name": "Rock_Slate"
    },
    {
      "x": -3,
      "y": 8,
      "z": -1,
      "name": "Rock_Slate"
    },
    {
      "x": -3,
      "y": 9,
      "z": -1,
      "name": "Rock_Slate"
    },
    {
      "x": -3,
      "y": 10,
      "z": -1,
      "name": "Rock_Slate"
    },
    {
      "x": -3,
      "y": 11,
      "z": -1,
      "name": "Rock_Slate"
    },
    {
      "x": -3,
      "y": 12,
      "z": -1,
      "name": "Rock_Slate"
    },
    {
      "x": -3,
      "y": 3,
      "z": 0,
      "name": "Rock_Slate"
    },
    {
      "x": -3,
      "y": 4,
      "z": 0,
      "name": "Rock_Slate"
    },
    {
      "x": -3,
      "y": 5,
      "z": 0,
      "name": "Rock_Slate"
    },
    {
      "x": -3,
      "y": 6,
      "z": 0,
      "name": "Rock_Slate"
    },
    {
      "x": -3,
      "y": 7,
      "z": 0,
      "name": "Rock_Slate"
    },
    {
      "x": -3,
      "y": 8,
      "z": 0,
      "name": "Rock_Slate"
    },
    {
      "x": -3,
      "y": 9,
      "z": 0,
      "name": "Rock_Slate"
    },
    {
      "x": -3,
      "y": 10,
      "z": 0,
      "name": "Rock_Slate"
    },
    {
      "x": -3,
      "y": 11,
      "z": 0,
      "name": "Rock_Slate"
    },
    {
      "x": -3,
      "y": 12,
      "z": 0,
      "name": "Rock_Slate"
    },
    {
      "x": -3,
      "y": 3,
      "z": 1,
      "name": "Rock_Slate"
    },
    {
      "x": -3,
      "y": 4,
      "z": 1,
      "name": "Rock_Slate"
    },
    {
      "x": -3,
      "y": 5,
      "z": 1,
      "name": "Rock_Slate"
    },
    {
      "x": -3,
      "y": 6,
      "z": 1,
      "name": "Rock_Slate"
    },
    {
      "x": -3,
      "y": 7,
      "z": 1,
      "name": "Rock_Slate"
    },
    {
      "x": -3,
      "y": 8,
      "z": 1,
      "name": "Rock_Slate"
    },
    {
      "x": -3,
      "y": 9,
      "z": 1,
      "name": "Rock_Slate"
    },
    {
      "x": -3,
      "y": 10,
      "z": 1,
      "name": "Rock_Slate"
    },
    {
      "x": -3,
      "y": 11,
      "z": 1,
      "name": "Rock_Slate"
    },
    {
      "x": -3,
      "y": 12,
      "z": 1,
      "name": "Rock_Slate"
    },
    {
      "x": -3,
      "y": 6,
      "z": 2,
      "name": "Rock_Slate"
    },
    {
      "x": -3,
      "y": 7,
      "z": 2,
      "name": "Rock_Slate"
    },
    {
      "x": -3,
      "y": 8,
      "z": 2,
      "name": "Rock_Slate"
    },
    {
      "x": -3,
      "y": 9,
      "z": 2,
      "name": "Rock_Slate"
    },
    {
      "x": -3,
      "y": 10,
      "z": 2,
      "name": "Rock_Slate"
    },
    {
      "x": -3,
      "y": 11,
      "z": 2,
      "name": "Rock_Slate"
    },
    {
      "x": -3,
      "y": 7,
      "z": 3,
      "name": "Rock_Slate"
    },
    {
      "x": -3,
      "y": 8,
      "z": 3,
      "name": "Rock_Slate"
    },
    {
      "x": -3,
      "y": 9,
      "z": 3,
      "name": "Rock_Slate"
    },
    {
      "x": -2,
      "y": 5,
      "z": -5,
      "name": "Rock_Slate"
    },
    {
      "x": -2,
      "y": 6,
      "z": -5,
      "name": "Rock_Slate"
    },
    {
      "x": -2,
      "y": 7,
      "z": -5,
      "name": "Rock_Slate"
    },
    {
      "x": -2,
      "y": 8,
      "z": -5,
      "name": "Rock_Slate"
    },
    {
      "x": -2,
      "y": 3,
      "z": -4,
      "name": "Rock_Slate"
    },
    {
      "x": -2,
      "y": 4,
      "z": -4,
      "name": "Rock_Slate"
    },
    {
      "x": -2,
      "y": 5,
      "z": -4,
      "name": "Rock_Slate"
    },
    {
      "x": -2,
      "y": 6,
      "z": -4,
      "name": "Rock_Slate"
    },
    {
      "x": -2,
      "y": 7,
      "z": -4,
      "name": "Rock_Slate"
    },
    {
      "x": -2,
      "y": 8,
      "z": -4,
      "name": "Rock_Slate"
    },
    {
      "x": -2,
      "y": 9,
      "z": -4,
      "name": "Rock_Slate"
    },
    {
      "x": -2,
      "y": 10,
      "z": -4,
      "name": "Rock_Slate"
    },
    {
      "x": -2,
      "y": 11,
      "z": -4,
      "name": "Rock_Slate"
    },
    {
      "x": -2,
      "y": 12,
      "z": -4,
      "name": "Rock_Slate"
    },
    {
      "x": -2,
      "y": 1,
      "z": -3,
      "name": "Rock_Slate"
    },
    {
      "x": -2,
      "y": 2,
      "z": -3,
      "name": "Rock_Slate"
    },
    {
      "x": -2,
      "y": 3,
      "z": -3,
      "name": "Rock_Slate"
    },
    {
      "x": -2,
      "y": 4,
      "z": -3,
      "name": "Rock_Slate"
    },
    {
      "x": -2,
      "y": 5,
      "z": -3,
      "name": "Rock_Slate"
    },
    {
      "x": -2,
      "y": 6,
      "z": -3,
      "name": "Rock_Slate"
    },
    {
      "x": -2,
      "y": 7,
      "z": -3,
      "name": "Rock_Slate"
    },
    {
      "x": -2,
      "y": 8,
      "z": -3,
      "name": "Rock_Slate"
    },
    {
      "x": -2,
      "y": 9,
      "z": -3,
      "name": "Rock_Slate"
    },
    {
      "x": -2,
      "y": 10,
      "z": -3,
      "name": "Rock_Slate"
    },
    {
      "x": -2,
      "y": 11,
      "z": -3,
      "name": "Rock_Slate"
    },
    {
      "x": -2,
      "y": 12,
      "z": -3,
      "name": "Rock_Slate"
    },
    {
      "x": -2,
      "y": 1,
      "z": -2,
      "name": "Rock_Slate"
    },
    {
      "x": -2,
      "y": 2,
      "z": -2,
      "name": "Rock_Slate"
    },
    {
      "x": -2,
      "y": 3,
      "z": -2,
      "name": "Rock_Slate"
    },
    {
      "x": -2,
      "y": 4,
      "z": -2,
      "name": "Rock_Slate"
    },
    {
      "x": -2,
      "y": 5,
      "z": -2,
      "name": "Rock_Slate"
    },
    {
      "x": -2,
      "y": 6,
      "z": -2,
      "name": "Rock_Slate"
    },
    {
      "x": -2,
      "y": 7,
      "z": -2,
      "name": "Rock_Slate"
    },
    {
      "x": -2,
      "y": 8,
      "z": -2,
      "name": "Rock_Slate"
    },
    {
      "x": -2,
      "y": 9,
      "z": -2,
      "name": "Rock_Slate"
    },
    {
      "x": -2,
      "y": 10,
      "z": -2,
      "name": "Rock_Slate"
    },
    {
      "x": -2,
      "y": 11,
      "z": -2,
      "name": "Rock_Slate"
    },
    {
      "x": -2,
      "y": 12,
      "z": -2,
      "name": "Rock_Slate"
    },
    {
      "x": -2,
      "y": 1,
      "z": -1,
      "name": "Rock_Slate"
    },
    {
      "x": -2,
      "y": 2,
      "z": -1,
      "name": "Rock_Slate"
    },
    {
      "x": -2,
      "y": 3,
      "z": -1,
      "name": "Rock_Slate"
    },
    {
      "x": -2,
      "y": 4,
      "z": -1,
      "name": "Rock_Slate"
    },
    {
      "x": -2,
      "y": 5,
      "z": -1,
      "name": "Rock_Slate"
    },
    {
      "x": -2,
      "y": 6,
      "z": -1,
      "name": "Rock_Slate"
    },
    {
      "x": -2,
      "y": 7,
      "z": -1,
      "name": "Rock_Slate"
    },
    {
      "x": -2,
      "y": 8,
      "z": -1,
      "name": "Rock_Slate"
    },
    {
      "x": -2,
      "y": 9,
      "z": -1,
      "name": "Rock_Slate"
    },
    {
      "x": -2,
      "y": 10,
      "z": -1,
      "name": "Rock_Slate"
    },
    {
      "x": -2,
      "y": 11,
      "z": -1,
      "name": "Rock_Slate"
    },
    {
      "x": -2,
      "y": 12,
      "z": -1,
      "name": "Rock_Slate"
    },
    {
      "x": -2,
      "y": 13,
      "z": -1,
      "name": "Rubble_Slate"
    },
    {
      "x": -2,
      "y": 1,
      "z": 0,
      "name": "Rock_Slate"
    },
    {
      "x": -2,
      "y": 2,
      "z": 0,
      "name": "Rock_Slate"
    },
    {
      "x": -2,
      "y": 3,
      "z": 0,
      "name": "Rock_Slate"
    },
    {
      "x": -2,
      "y": 4,
      "z": 0,
      "name": "Rock_Slate"
    },
    {
      "x": -2,
      "y": 5,
      "z": 0,
      "name": "Rock_Slate"
    },
    {
      "x": -2,
      "y": 6,
      "z": 0,
      "name": "Rock_Slate"
    },
    {
      "x": -2,
      "y": 7,
      "z": 0,
      "name": "Rock_Slate"
    },
    {
      "x": -2,
      "y": 8,
      "z": 0,
      "name": "Rock_Slate"
    },
    {
      "x": -2,
      "y": 9,
      "z": 0,
      "name": "Rock_Slate"
    },
    {
      "x": -2,
      "y": 10,
      "z": 0,
      "name": "Rock_Slate"
    },
    {
      "x": -2,
      "y": 11,
      "z": 0,
      "name": "Rock_Slate"
    },
    {
      "x": -2,
      "y": 12,
      "z": 0,
      "name": "Rock_Slate"
    },
    {
      "x": -2,
      "y": 2,
      "z": 1,
      "name": "Rock_Slate"
    },
    {
      "x": -2,
      "y": 3,
      "z": 1,
      "name": "Rock_Slate"
    },
    {
      "x": -2,
      "y": 4,
      "z": 1,
      "name": "Rock_Slate"
    },
    {
      "x": -2,
      "y": 5,
      "z": 1,
      "name": "Rock_Slate"
    },
    {
      "x": -2,
      "y": 6,
      "z": 1,
      "name": "Rock_Slate"
    },
    {
      "x": -2,
      "y": 7,
      "z": 1,
      "name": "Rock_Slate"
    },
    {
      "x": -2,
      "y": 8,
      "z": 1,
      "name": "Rock_Slate"
    },
    {
      "x": -2,
      "y": 9,
      "z": 1,
      "name": "Rock_Slate"
    },
    {
      "x": -2,
      "y": 10,
      "z": 1,
      "name": "Rock_Slate"
    },
    {
      "x": -2,
      "y": 11,
      "z": 1,
      "name": "Rock_Slate"
    },
    {
      "x": -2,
      "y": 12,
      "z": 1,
      "name": "Rock_Slate"
    },
    {
      "x": -2,
      "y": 3,
      "z": 2,
      "name": "Rock_Slate"
    },
    {
      "x": -2,
      "y": 4,
      "z": 2,
      "name": "Rock_Slate"
    },
    {
      "x": -2,
      "y": 5,
      "z": 2,
      "name": "Rock_Slate"
    },
    {
      "x": -2,
      "y": 6,
      "z": 2,
      "name": "Rock_Slate"
    },
    {
      "x": -2,
      "y": 7,
      "z": 2,
      "name": "Rock_Slate"
    },
    {
      "x": -2,
      "y": 8,
      "z": 2,
      "name": "Rock_Slate"
    },
    {
      "x": -2,
      "y": 9,
      "z": 2,
      "name": "Rock_Slate"
    },
    {
      "x": -2,
      "y": 10,
      "z": 2,
      "name": "Rock_Slate"
    },
    {
      "x": -2,
      "y": 11,
      "z": 2,
      "name": "Rock_Slate"
    },
    {
      "x": -2,
      "y": 12,
      "z": 2,
      "name": "Rock_Slate"
    },
    {
      "x": -2,
      "y": 5,
      "z": 3,
      "name": "Rock_Slate"
    },
    {
      "x": -2,
      "y": 6,
      "z": 3,
      "name": "Rock_Slate"
    },
    {
      "x": -2,
      "y": 7,
      "z": 3,
      "name": "Rock_Slate"
    },
    {
      "x": -2,
      "y": 8,
      "z": 3,
      "name": "Rock_Slate"
    },
    {
      "x": -2,
      "y": 9,
      "z": 3,
      "name": "Rock_Slate"
    },
    {
      "x": -2,
      "y": 10,
      "z": 3,
      "name": "Rock_Slate"
    },
    {
      "x": -2,
      "y": 11,
      "z": 3,
      "name": "Rock_Slate"
    },
    {
      "x": -2,
      "y": 12,
      "z": 3,
      "name": "Plant_Bush_Dead_Tall"
    },
    {
      "x": -1,
      "y": 3,
      "z": -6,
      "name": "Rock_Slate"
    },
    {
      "x": -1,
      "y": 4,
      "z": -6,
      "name": "Rock_Slate"
    },
    {
      "x": -1,
      "y": 5,
      "z": -6,
      "name": "Rock_Slate"
    },
    {
      "x": -1,
      "y": 6,
      "z": -6,
      "name": "Rock_Slate"
    },
    {
      "x": -1,
      "y": 7,
      "z": -6,
      "name": "Rock_Slate"
    },
    {
      "x": -1,
      "y": 8,
      "z": -6,
      "name": "Rock_Slate"
    },
    {
      "x": -1,
      "y": 2,
      "z": -5,
      "name": "Rock_Slate"
    },
    {
      "x": -1,
      "y": 3,
      "z": -5,
      "name": "Rock_Slate"
    },
    {
      "x": -1,
      "y": 4,
      "z": -5,
      "name": "Rock_Slate"
    },
    {
      "x": -1,
      "y": 5,
      "z": -5,
      "name": "Rock_Slate"
    },
    {
      "x": -1,
      "y": 6,
      "z": -5,
      "name": "Rock_Slate"
    },
    {
      "x": -1,
      "y": 7,
      "z": -5,
      "name": "Rock_Slate"
    },
    {
      "x": -1,
      "y": 8,
      "z": -5,
      "name": "Rock_Slate"
    },
    {
      "x": -1,
      "y": 9,
      "z": -5,
      "name": "Rock_Slate"
    },
    {
      "x": -1,
      "y": 10,
      "z": -5,
      "name": "Rock_Slate"
    },
    {
      "x": -1,
      "y": 11,
      "z": -5,
      "name": "Rock_Slate"
    },
    {
      "x": -1,
      "y": 1,
      "z": -4,
      "name": "Rock_Slate"
    },
    {
      "x": -1,
      "y": 2,
      "z": -4,
      "name": "Rock_Slate"
    },
    {
      "x": -1,
      "y": 3,
      "z": -4,
      "name": "Rock_Slate"
    },
    {
      "x": -1,
      "y": 4,
      "z": -4,
      "name": "Rock_Slate"
    },
    {
      "x": -1,
      "y": 5,
      "z": -4,
      "name": "Rock_Slate"
    },
    {
      "x": -1,
      "y": 6,
      "z": -4,
      "name": "Rock_Slate"
    },
    {
      "x": -1,
      "y": 7,
      "z": -4,
      "name": "Rock_Slate"
    },
    {
      "x": -1,
      "y": 8,
      "z": -4,
      "name": "Rock_Slate"
    },
    {
      "x": -1,
      "y": 9,
      "z": -4,
      "name": "Rock_Slate"
    },
    {
      "x": -1,
      "y": 10,
      "z": -4,
      "name": "Rock_Slate"
    },
    {
      "x": -1,
      "y": 11,
      "z": -4,
      "name": "Rock_Slate"
    },
    {
      "x": -1,
      "y": 1,
      "z": -3,
      "name": "Rock_Slate"
    },
    {
      "x": -1,
      "y": 2,
      "z": -3,
      "name": "Rock_Slate"
    },
    {
      "x": -1,
      "y": 3,
      "z": -3,
      "name": "Rock_Slate"
    },
    {
      "x": -1,
      "y": 4,
      "z": -3,
      "name": "Rock_Slate"
    },
    {
      "x": -1,
      "y": 5,
      "z": -3,
      "name": "Rock_Slate"
    },
    {
      "x": -1,
      "y": 6,
      "z": -3,
      "name": "Rock_Slate"
    },
    {
      "x": -1,
      "y": 7,
      "z": -3,
      "name": "Rock_Slate"
    },
    {
      "x": -1,
      "y": 8,
      "z": -3,
      "name": "Rock_Slate"
    },
    {
      "x": -1,
      "y": 9,
      "z": -3,
      "name": "Rock_Slate"
    },
    {
      "x": -1,
      "y": 10,
      "z": -3,
      "name": "Rock_Slate"
    },
    {
      "x": -1,
      "y": 11,
      "z": -3,
      "name": "Rock_Slate"
    },
    {
      "x": -1,
      "y": 12,
      "z": -3,
      "name": "Rock_Slate"
    },
    {
      "x": -1,
      "y": 1,
      "z": -2,
      "name": "Rock_Slate"
    },
    {
      "x": -1,
      "y": 2,
      "z": -2,
      "name": "Rock_Slate"
    },
    {
      "x": -1,
      "y": 3,
      "z": -2,
      "name": "Rock_Slate"
    },
    {
      "x": -1,
      "y": 4,
      "z": -2,
      "name": "Rock_Slate"
    },
    {
      "x": -1,
      "y": 5,
      "z": -2,
      "name": "Rock_Slate"
    },
    {
      "x": -1,
      "y": 6,
      "z": -2,
      "name": "Rock_Slate"
    },
    {
      "x": -1,
      "y": 7,
      "z": -2,
      "name": "Rock_Slate"
    },
    {
      "x": -1,
      "y": 8,
      "z": -2,
      "name": "Rock_Slate"
    },
    {
      "x": -1,
      "y": 9,
      "z": -2,
      "name": "Rock_Slate"
    },
    {
      "x": -1,
      "y": 10,
      "z": -2,
      "name": "Rock_Slate"
    },
    {
      "x": -1,
      "y": 11,
      "z": -2,
      "name": "Rock_Slate"
    },
    {
      "x": -1,
      "y": 12,
      "z": -2,
      "name": "Rock_Slate"
    },
    {
      "x": -1,
      "y": 1,
      "z": -1,
      "name": "Rock_Slate"
    },
    {
      "x": -1,
      "y": 2,
      "z": -1,
      "name": "Rock_Slate"
    },
    {
      "x": -1,
      "y": 3,
      "z": -1,
      "name": "Rock_Slate"
    },
    {
      "x": -1,
      "y": 4,
      "z": -1,
      "name": "Rock_Slate"
    },
    {
      "x": -1,
      "y": 5,
      "z": -1,
      "name": "Rock_Slate"
    },
    {
      "x": -1,
      "y": 6,
      "z": -1,
      "name": "Rock_Slate"
    },
    {
      "x": -1,
      "y": 7,
      "z": -1,
      "name": "Rock_Slate"
    },
    {
      "x": -1,
      "y": 8,
      "z": -1,
      "name": "Rock_Slate"
    },
    {
      "x": -1,
      "y": 9,
      "z": -1,
      "name": "Rock_Slate"
    },
    {
      "x": -1,
      "y": 10,
      "z": -1,
      "name": "Rock_Slate"
    },
    {
      "x": -1,
      "y": 11,
      "z": -1,
      "name": "Rock_Slate"
    },
    {
      "x": -1,
      "y": 12,
      "z": -1,
      "name": "Rock_Slate"
    },
    {
      "x": -1,
      "y": 1,
      "z": 0,
      "name": "Rock_Slate"
    },
    {
      "x": -1,
      "y": 2,
      "z": 0,
      "name": "Rock_Slate"
    },
    {
      "x": -1,
      "y": 3,
      "z": 0,
      "name": "Rock_Slate"
    },
    {
      "x": -1,
      "y": 4,
      "z": 0,
      "name": "Rock_Slate"
    },
    {
      "x": -1,
      "y": 5,
      "z": 0,
      "name": "Rock_Slate"
    },
    {
      "x": -1,
      "y": 6,
      "z": 0,
      "name": "Rock_Slate"
    },
    {
      "x": -1,
      "y": 7,
      "z": 0,
      "name": "Rock_Slate"
    },
    {
      "x": -1,
      "y": 8,
      "z": 0,
      "name": "Rock_Slate"
    },
    {
      "x": -1,
      "y": 9,
      "z": 0,
      "name": "Rock_Slate"
    },
    {
      "x": -1,
      "y": 10,
      "z": 0,
      "name": "Rock_Slate"
    },
    {
      "x": -1,
      "y": 11,
      "z": 0,
      "name": "Rock_Slate"
    },
    {
      "x": -1,
      "y": 12,
      "z": 0,
      "name": "Rock_Slate"
    },
    {
      "x": -1,
      "y": 1,
      "z": 1,
      "name": "Rock_Slate"
    },
    {
      "x": -1,
      "y": 2,
      "z": 1,
      "name": "Rock_Slate"
    },
    {
      "x": -1,
      "y": 3,
      "z": 1,
      "name": "Rock_Slate"
    },
    {
      "x": -1,
      "y": 4,
      "z": 1,
      "name": "Rock_Slate"
    },
    {
      "x": -1,
      "y": 5,
      "z": 1,
      "name": "Rock_Slate"
    },
    {
      "x": -1,
      "y": 6,
      "z": 1,
      "name": "Rock_Slate"
    },
    {
      "x": -1,
      "y": 7,
      "z": 1,
      "name": "Rock_Slate"
    },
    {
      "x": -1,
      "y": 8,
      "z": 1,
      "name": "Rock_Slate"
    },
    {
      "x": -1,
      "y": 9,
      "z": 1,
      "name": "Rock_Slate"
    },
    {
      "x": -1,
      "y": 10,
      "z": 1,
      "name": "Rock_Slate"
    },
    {
      "x": -1,
      "y": 11,
      "z": 1,
      "name": "Rock_Slate"
    },
    {
      "x": -1,
      "y": 12,
      "z": 1,
      "name": "Rock_Slate"
    },
    {
      "x": -1,
      "y": 3,
      "z": 2,
      "name": "Rock_Slate"
    },
    {
      "x": -1,
      "y": 4,
      "z": 2,
      "name": "Rock_Slate"
    },
    {
      "x": -1,
      "y": 5,
      "z": 2,
      "name": "Rock_Slate"
    },
    {
      "x": -1,
      "y": 6,
      "z": 2,
      "name": "Rock_Slate"
    },
    {
      "x": -1,
      "y": 7,
      "z": 2,
      "name": "Rock_Slate"
    },
    {
      "x": -1,
      "y": 8,
      "z": 2,
      "name": "Rock_Slate"
    },
    {
      "x": -1,
      "y": 9,
      "z": 2,
      "name": "Rock_Slate"
    },
    {
      "x": -1,
      "y": 10,
      "z": 2,
      "name": "Rock_Slate"
    },
    {
      "x": -1,
      "y": 11,
      "z": 2,
      "name": "Rock_Slate"
    },
    {
      "x": -1,
      "y": 12,
      "z": 2,
      "name": "Rock_Slate"
    },
    {
      "x": -1,
      "y": 4,
      "z": 3,
      "name": "Rock_Slate"
    },
    {
      "x": -1,
      "y": 5,
      "z": 3,
      "name": "Rock_Slate"
    },
    {
      "x": -1,
      "y": 6,
      "z": 3,
      "name": "Rock_Slate"
    },
    {
      "x": -1,
      "y": 7,
      "z": 3,
      "name": "Rock_Slate"
    },
    {
      "x": -1,
      "y": 8,
      "z": 3,
      "name": "Rock_Slate"
    },
    {
      "x": -1,
      "y": 9,
      "z": 3,
      "name": "Rock_Slate"
    },
    {
      "x": -1,
      "y": 10,
      "z": 3,
      "name": "Rock_Slate"
    },
    {
      "x": -1,
      "y": 11,
      "z": 3,
      "name": "Rock_Slate"
    },
    {
      "x": -1,
      "y": 12,
      "z": 3,
      "name": "Rock_Slate"
    },
    {
      "x": -1,
      "y": 5,
      "z": 4,
      "name": "Rock_Slate"
    },
    {
      "x": -1,
      "y": 6,
      "z": 4,
      "name": "Rock_Slate"
    },
    {
      "x": -1,
      "y": 7,
      "z": 4,
      "name": "Rock_Slate"
    },
    {
      "x": -1,
      "y": 8,
      "z": 4,
      "name": "Rock_Slate"
    },
    {
      "x": -1,
      "y": 9,
      "z": 4,
      "name": "Rock_Slate"
    },
    {
      "x": -1,
      "y": 10,
      "z": 4,
      "name": "Rock_Slate"
    },
    {
      "x": -1,
      "y": 11,
      "z": 4,
      "name": "Plant_Bush_Dead_Tall"
    },
    {
      "x": 0,
      "y": 3,
      "z": -7,
      "name": "Rock_Slate"
    },
    {
      "x": 0,
      "y": 4,
      "z": -7,
      "name": "Rock_Slate"
    },
    {
      "x": 0,
      "y": 5,
      "z": -7,
      "name": "Rock_Slate"
    },
    {
      "x": 0,
      "y": 6,
      "z": -7,
      "name": "Rock_Slate"
    },
    {
      "x": 0,
      "y": 7,
      "z": -7,
      "name": "Rock_Slate"
    },
    {
      "x": 0,
      "y": 8,
      "z": -7,
      "name": "Rock_Slate"
    },
    {
      "x": 0,
      "y": 9,
      "z": -7,
      "name": "Rock_Slate"
    },
    {
      "x": 0,
      "y": 10,
      "z": -7,
      "name": "Rock_Slate"
    },
    {
      "x": 0,
      "y": 1,
      "z": -6,
      "name": "Rock_Slate"
    },
    {
      "x": 0,
      "y": 2,
      "z": -6,
      "name": "Rock_Slate"
    },
    {
      "x": 0,
      "y": 3,
      "z": -6,
      "name": "Rock_Slate"
    },
    {
      "x": 0,
      "y": 4,
      "z": -6,
      "name": "Rock_Slate"
    },
    {
      "x": 0,
      "y": 5,
      "z": -6,
      "name": "Rock_Slate"
    },
    {
      "x": 0,
      "y": 6,
      "z": -6,
      "name": "Rock_Slate"
    },
    {
      "x": 0,
      "y": 7,
      "z": -6,
      "name": "Rock_Slate"
    },
    {
      "x": 0,
      "y": 8,
      "z": -6,
      "name": "Rock_Slate"
    },
    {
      "x": 0,
      "y": 9,
      "z": -6,
      "name": "Rock_Slate"
    },
    {
      "x": 0,
      "y": 10,
      "z": -6,
      "name": "Rock_Slate"
    },
    {
      "x": 0,
      "y": 1,
      "z": -5,
      "name": "Rock_Slate"
    },
    {
      "x": 0,
      "y": 2,
      "z": -5,
      "name": "Rock_Slate"
    },
    {
      "x": 0,
      "y": 3,
      "z": -5,
      "name": "Rock_Slate"
    },
    {
      "x": 0,
      "y": 4,
      "z": -5,
      "name": "Rock_Slate"
    },
    {
      "x": 0,
      "y": 5,
      "z": -5,
      "name": "Rock_Slate"
    },
    {
      "x": 0,
      "y": 6,
      "z": -5,
      "name": "Rock_Slate"
    },
    {
      "x": 0,
      "y": 7,
      "z": -5,
      "name": "Rock_Slate"
    },
    {
      "x": 0,
      "y": 8,
      "z": -5,
      "name": "Rock_Slate"
    },
    {
      "x": 0,
      "y": 9,
      "z": -5,
      "name": "Rock_Slate"
    },
    {
      "x": 0,
      "y": 10,
      "z": -5,
      "name": "Rock_Slate"
    },
    {
      "x": 0,
      "y": 11,
      "z": -5,
      "name": "Rock_Slate"
    },
    {
      "x": 0,
      "y": 1,
      "z": -4,
      "name": "Rock_Slate"
    },
    {
      "x": 0,
      "y": 2,
      "z": -4,
      "name": "Rock_Slate"
    },
    {
      "x": 0,
      "y": 3,
      "z": -4,
      "name": "Rock_Slate"
    },
    {
      "x": 0,
      "y": 4,
      "z": -4,
      "name": "Rock_Slate"
    },
    {
      "x": 0,
      "y": 5,
      "z": -4,
      "name": "Rock_Slate"
    },
    {
      "x": 0,
      "y": 6,
      "z": -4,
      "name": "Rock_Slate"
    },
    {
      "x": 0,
      "y": 7,
      "z": -4,
      "name": "Rock_Slate"
    },
    {
      "x": 0,
      "y": 8,
      "z": -4,
      "name": "Rock_Slate"
    },
    {
      "x": 0,
      "y": 9,
      "z": -4,
      "name": "Rock_Slate"
    },
    {
      "x": 0,
      "y": 10,
      "z": -4,
      "name": "Rock_Slate"
    },
    {
      "x": 0,
      "y": 11,
      "z": -4,
      "name": "Rock_Slate"
    },
    {
      "x": 0,
      "y": 1,
      "z": -3,
      "name": "Rock_Slate"
    },
    {
      "x": 0,
      "y": 2,
      "z": -3,
      "name": "Rock_Slate"
    },
    {
      "x": 0,
      "y": 3,
      "z": -3,
      "name": "Rock_Slate"
    },
    {
      "x": 0,
      "y": 4,
      "z": -3,
      "name": "Rock_Slate"
    },
    {
      "x": 0,
      "y": 5,
      "z": -3,
      "name": "Rock_Slate"
    },
    {
      "x": 0,
      "y": 6,
      "z": -3,
      "name": "Rock_Slate"
    },
    {
      "x": 0,
      "y": 7,
      "z": -3,
      "name": "Rock_Slate"
    },
    {
      "x": 0,
      "y": 8,
      "z": -3,
      "name": "Rock_Slate"
    },
    {
      "x": 0,
      "y": 9,
      "z": -3,
      "name": "Rock_Slate"
    },
    {
      "x": 0,
      "y": 10,
      "z": -3,
      "name": "Rock_Slate"
    },
    {
      "x": 0,
      "y": 11,
      "z": -3,
      "name": "Rock_Slate"
    },
    {
      "x": 0,
      "y": 1,
      "z": -2,
      "name": "Rock_Slate"
    },
    {
      "x": 0,
      "y": 2,
      "z": -2,
      "name": "Rock_Slate"
    },
    {
      "x": 0,
      "y": 3,
      "z": -2,
      "name": "Rock_Slate"
    },
    {
      "x": 0,
      "y": 4,
      "z": -2,
      "name": "Rock_Slate"
    },
    {
      "x": 0,
      "y": 5,
      "z": -2,
      "name": "Rock_Slate"
    },
    {
      "x": 0,
      "y": 6,
      "z": -2,
      "name": "Rock_Slate"
    },
    {
      "x": 0,
      "y": 7,
      "z": -2,
      "name": "Rock_Slate"
    },
    {
      "x": 0,
      "y": 8,
      "z": -2,
      "name": "Rock_Slate"
    },
    {
      "x": 0,
      "y": 9,
      "z": -2,
      "name": "Rock_Slate"
    },
    {
      "x": 0,
      "y": 10,
      "z": -2,
      "name": "Rock_Slate"
    },
    {
      "x": 0,
      "y": 11,
      "z": -2,
      "name": "Rock_Slate"
    },
    {
      "x": 0,
      "y": 1,
      "z": -1,
      "name": "Rock_Slate"
    },
    {
      "x": 0,
      "y": 2,
      "z": -1,
      "name": "Rock_Slate"
    },
    {
      "x": 0,
      "y": 3,
      "z": -1,
      "name": "Rock_Slate"
    },
    {
      "x": 0,
      "y": 4,
      "z": -1,
      "name": "Rock_Slate"
    },
    {
      "x": 0,
      "y": 5,
      "z": -1,
      "name": "Rock_Slate"
    },
    {
      "x": 0,
      "y": 6,
      "z": -1,
      "name": "Rock_Slate"
    },
    {
      "x": 0,
      "y": 7,
      "z": -1,
      "name": "Rock_Slate"
    },
    {
      "x": 0,
      "y": 8,
      "z": -1,
      "name": "Rock_Slate"
    },
    {
      "x": 0,
      "y": 9,
      "z": -1,
      "name": "Rock_Slate"
    },
    {
      "x": 0,
      "y": 10,
      "z": -1,
      "name": "Rock_Slate"
    },
    {
      "x": 0,
      "y": 11,
      "z": -1,
      "name": "Rock_Slate"
    },
    {
      "x": 0,
      "y": 12,
      "z": -1,
      "name": "Rock_Slate"
    },
    {
      "x": 0,
      "y": 1,
      "z": 0,
      "name": "Rock_Slate"
    },
    {
      "x": 0,
      "y": 2,
      "z": 0,
      "name": "Rock_Slate"
    },
    {
      "x": 0,
      "y": 3,
      "z": 0,
      "name": "Rock_Slate"
    },
    {
      "x": 0,
      "y": 4,
      "z": 0,
      "name": "Rock_Slate"
    },
    {
      "x": 0,
      "y": 5,
      "z": 0,
      "name": "Rock_Slate"
    },
    {
      "x": 0,
      "y": 6,
      "z": 0,
      "name": "Rock_Slate"
    },
    {
      "x": 0,
      "y": 7,
      "z": 0,
      "name": "Rock_Slate"
    },
    {
      "x": 0,
      "y": 8,
      "z": 0,
      "name": "Rock_Slate"
    },
    {
      "x": 0,
      "y": 9,
      "z": 0,
      "name": "Rock_Slate"
    },
    {
      "x": 0,
      "y": 10,
      "z": 0,
      "name": "Rock_Slate"
    },
    {
      "x": 0,
      "y": 11,
      "z": 0,
      "name": "Rock_Slate"
    },
    {
      "x": 0,
      "y": 12,
      "z": 0,
      "name": "Rock_Slate"
    },
    {
      "x": 0,
      "y": 1,
      "z": 1,
      "name": "Rock_Slate"
    },
    {
      "x": 0,
      "y": 2,
      "z": 1,
      "name": "Rock_Slate"
    },
    {
      "x": 0,
      "y": 3,
      "z": 1,
      "name": "Rock_Slate"
    },
    {
      "x": 0,
      "y": 4,
      "z": 1,
      "name": "Rock_Slate"
    },
    {
      "x": 0,
      "y": 5,
      "z": 1,
      "name": "Rock_Slate"
    },
    {
      "x": 0,
      "y": 6,
      "z": 1,
      "name": "Rock_Slate"
    },
    {
      "x": 0,
      "y": 7,
      "z": 1,
      "name": "Rock_Slate"
    },
    {
      "x": 0,
      "y": 8,
      "z": 1,
      "name": "Rock_Slate"
    },
    {
      "x": 0,
      "y": 9,
      "z": 1,
      "name": "Rock_Slate"
    },
    {
      "x": 0,
      "y": 10,
      "z": 1,
      "name": "Rock_Slate"
    },
    {
      "x": 0,
      "y": 11,
      "z": 1,
      "name": "Rock_Slate"
    },
    {
      "x": 0,
      "y": 12,
      "z": 1,
      "name": "Rock_Slate"
    },
    {
      "x": 0,
      "y": 2,
      "z": 2,
      "name": "Rock_Slate"
    },
    {
      "x": 0,
      "y": 3,
      "z": 2,
      "name": "Rock_Slate"
    },
    {
      "x": 0,
      "y": 4,
      "z": 2,
      "name": "Rock_Slate"
    },
    {
      "x": 0,
      "y": 5,
      "z": 2,
      "name": "Rock_Slate"
    },
    {
      "x": 0,
      "y": 6,
      "z": 2,
      "name": "Rock_Slate"
    },
    {
      "x": 0,
      "y": 7,
      "z": 2,
      "name": "Rock_Slate"
    },
    {
      "x": 0,
      "y": 8,
      "z": 2,
      "name": "Rock_Slate"
    },
    {
      "x": 0,
      "y": 9,
      "z": 2,
      "name": "Rock_Slate"
    },
    {
      "x": 0,
      "y": 10,
      "z": 2,
      "name": "Rock_Slate"
    },
    {
      "x": 0,
      "y": 11,
      "z": 2,
      "name": "Rock_Slate"
    },
    {
      "x": 0,
      "y": 12,
      "z": 2,
      "name": "Rock_Slate"
    },
    {
      "x": 0,
      "y": 3,
      "z": 3,
      "name": "Rock_Slate"
    },
    {
      "x": 0,
      "y": 4,
      "z": 3,
      "name": "Rock_Slate"
    },
    {
      "x": 0,
      "y": 5,
      "z": 3,
      "name": "Rock_Slate"
    },
    {
      "x": 0,
      "y": 6,
      "z": 3,
      "name": "Rock_Slate"
    },
    {
      "x": 0,
      "y": 7,
      "z": 3,
      "name": "Rock_Slate"
    },
    {
      "x": 0,
      "y": 8,
      "z": 3,
      "name": "Rock_Slate"
    },
    {
      "x": 0,
      "y": 9,
      "z": 3,
      "name": "Rock_Slate"
    },
    {
      "x": 0,
      "y": 10,
      "z": 3,
      "name": "Rock_Slate"
    },
    {
      "x": 0,
      "y": 11,
      "z": 3,
      "name": "Rock_Slate"
    },
    {
      "x": 0,
      "y": 12,
      "z": 3,
      "name": "Rock_Slate"
    },
    {
      "x": 0,
      "y": 5,
      "z": 4,
      "name": "Rock_Slate"
    },
    {
      "x": 0,
      "y": 6,
      "z": 4,
      "name": "Rock_Slate"
    },
    {
      "x": 0,
      "y": 7,
      "z": 4,
      "name": "Rock_Slate"
    },
    {
      "x": 0,
      "y": 8,
      "z": 4,
      "name": "Rock_Slate"
    },
    {
      "x": 0,
      "y": 9,
      "z": 4,
      "name": "Rock_Slate"
    },
    {
      "x": 0,
      "y": 10,
      "z": 4,
      "name": "Rock_Slate"
    },
    {
      "x": 0,
      "y": 11,
      "z": 4,
      "name": "Rock_Slate"
    },
    {
      "x": 0,
      "y": 12,
      "z": 4,
      "name": "Rock_Slate"
    },
    {
      "x": 1,
      "y": 7,
      "z": -8,
      "name": "Soil_Dirt_Burnt"
    },
    {
      "x": 1,
      "y": 8,
      "z": -8,
      "name": "Soil_Dirt_Burnt"
    },
    {
      "x": 1,
      "y": 9,
      "z": -8,
      "name": "Soil_Grass_Burnt"
    },
    {
      "x": 1,
      "y": 10,
      "z": -8,
      "name": "Plant_Grass_Gnarled_Tall"
    },
    {
      "x": 1,
      "y": 11,
      "z": -8,
      "name": "Plant_Grass_Gnarled_Tall",
      "filler": 1024
    },
    {
      "x": 1,
      "y": 2,
      "z": -7,
      "name": "Rock_Slate"
    },
    {
      "x": 1,
      "y": 3,
      "z": -7,
      "name": "Rock_Slate"
    },
    {
      "x": 1,
      "y": 4,
      "z": -7,
      "name": "Rock_Slate"
    },
    {
      "x": 1,
      "y": 5,
      "z": -7,
      "name": "Rock_Slate"
    },
    {
      "x": 1,
      "y": 6,
      "z": -7,
      "name": "Rock_Slate"
    },
    {
      "x": 1,
      "y": 7,
      "z": -7,
      "name": "Rock_Slate"
    },
    {
      "x": 1,
      "y": 8,
      "z": -7,
      "name": "Rock_Slate"
    },
    {
      "x": 1,
      "y": 9,
      "z": -7,
      "name": "Rock_Slate"
    },
    {
      "x": 1,
      "y": 10,
      "z": -7,
      "name": "Rock_Slate"
    },
    {
      "x": 1,
      "y": 1,
      "z": -6,
      "name": "Rock_Slate"
    },
    {
      "x": 1,
      "y": 2,
      "z": -6,
      "name": "Rock_Slate"
    },
    {
      "x": 1,
      "y": 3,
      "z": -6,
      "name": "Rock_Slate"
    },
    {
      "x": 1,
      "y": 4,
      "z": -6,
      "name": "Rock_Slate"
    },
    {
      "x": 1,
      "y": 5,
      "z": -6,
      "name": "Rock_Slate"
    },
    {
      "x": 1,
      "y": 6,
      "z": -6,
      "name": "Rock_Slate"
    },
    {
      "x": 1,
      "y": 7,
      "z": -6,
      "name": "Rock_Slate"
    },
    {
      "x": 1,
      "y": 8,
      "z": -6,
      "name": "Rock_Slate"
    },
    {
      "x": 1,
      "y": 9,
      "z": -6,
      "name": "Rock_Slate"
    },
    {
      "x": 1,
      "y": 10,
      "z": -6,
      "name": "Rock_Slate"
    },
    {
      "x": 1,
      "y": 11,
      "z": -6,
      "name": "Rock_Slate"
    },
    {
      "x": 1,
      "y": 1,
      "z": -5,
      "name": "Rock_Slate"
    },
    {
      "x": 1,
      "y": 2,
      "z": -5,
      "name": "Rock_Slate"
    },
    {
      "x": 1,
      "y": 3,
      "z": -5,
      "name": "Rock_Slate"
    },
    {
      "x": 1,
      "y": 4,
      "z": -5,
      "name": "Rock_Slate"
    },
    {
      "x": 1,
      "y": 5,
      "z": -5,
      "name": "Rock_Slate"
    },
    {
      "x": 1,
      "y": 6,
      "z": -5,
      "name": "Rock_Slate"
    },
    {
      "x": 1,
      "y": 7,
      "z": -5,
      "name": "Rock_Slate"
    },
    {
      "x": 1,
      "y": 8,
      "z": -5,
      "name": "Rock_Slate"
    },
    {
      "x": 1,
      "y": 9,
      "z": -5,
      "name": "Rock_Slate"
    },
    {
      "x": 1,
      "y": 10,
      "z": -5,
      "name": "Rock_Slate"
    },
    {
      "x": 1,
      "y": 11,
      "z": -5,
      "name": "Rock_Slate"
    },
    {
      "x": 1,
      "y": 1,
      "z": -4,
      "name": "Rock_Slate"
    },
    {
      "x": 1,
      "y": 2,
      "z": -4,
      "name": "Rock_Slate"
    },
    {
      "x": 1,
      "y": 3,
      "z": -4,
      "name": "Rock_Slate"
    },
    {
      "x": 1,
      "y": 4,
      "z": -4,
      "name": "Rock_Slate"
    },
    {
      "x": 1,
      "y": 5,
      "z": -4,
      "name": "Rock_Slate"
    },
    {
      "x": 1,
      "y": 6,
      "z": -4,
      "name": "Rock_Slate"
    },
    {
      "x": 1,
      "y": 7,
      "z": -4,
      "name": "Rock_Slate"
    },
    {
      "x": 1,
      "y": 8,
      "z": -4,
      "name": "Rock_Slate"
    },
    {
      "x": 1,
      "y": 9,
      "z": -4,
      "name": "Rock_Slate"
    },
    {
      "x": 1,
      "y": 10,
      "z": -4,
      "name": "Rock_Slate"
    },
    {
      "x": 1,
      "y": 11,
      "z": -4,
      "name": "Rock_Slate"
    },
    {
      "x": 1,
      "y": 1,
      "z": -3,
      "name": "Rock_Slate"
    },
    {
      "x": 1,
      "y": 2,
      "z": -3,
      "name": "Rock_Slate"
    },
    {
      "x": 1,
      "y": 3,
      "z": -3,
      "name": "Rock_Slate"
    },
    {
      "x": 1,
      "y": 4,
      "z": -3,
      "name": "Rock_Slate"
    },
    {
      "x": 1,
      "y": 5,
      "z": -3,
      "name": "Rock_Slate"
    },
    {
      "x": 1,
      "y": 6,
      "z": -3,
      "name": "Rock_Slate"
    },
    {
      "x": 1,
      "y": 7,
      "z": -3,
      "name": "Rock_Slate"
    },
    {
      "x": 1,
      "y": 8,
      "z": -3,
      "name": "Rock_Slate"
    },
    {
      "x": 1,
      "y": 9,
      "z": -3,
      "name": "Rock_Slate"
    },
    {
      "x": 1,
      "y": 10,
      "z": -3,
      "name": "Rock_Slate"
    },
    {
      "x": 1,
      "y": 11,
      "z": -3,
      "name": "Rock_Slate"
    },
    {
      "x": 1,
      "y": 1,
      "z": -2,
      "name": "Rock_Slate"
    },
    {
      "x": 1,
      "y": 2,
      "z": -2,
      "name": "Rock_Slate"
    },
    {
      "x": 1,
      "y": 3,
      "z": -2,
      "name": "Rock_Slate"
    },
    {
      "x": 1,
      "y": 4,
      "z": -2,
      "name": "Rock_Slate"
    },
    {
      "x": 1,
      "y": 5,
      "z": -2,
      "name": "Rock_Slate"
    },
    {
      "x": 1,
      "y": 6,
      "z": -2,
      "name": "Rock_Gem_Topaz"
    },
    {
      "x": 1,
      "y": 7,
      "z": -2,
      "name": "Rock_Slate"
    },
    {
      "x": 1,
      "y": 8,
      "z": -2,
      "name": "Rock_Slate"
    },
    {
      "x": 1,
      "y": 9,
      "z": -2,
      "name": "Rock_Slate"
    },
    {
      "x": 1,
      "y": 10,
      "z": -2,
      "name": "Rock_Slate"
    },
    {
      "x": 1,
      "y": 11,
      "z": -2,
      "name": "Rock_Slate"
    },
    {
      "x": 1,
      "y": 12,
      "z": -2,
      "name": "Rubble_Slate"
    },
    {
      "x": 1,
      "y": 1,
      "z": -1,
      "name": "Rock_Slate"
    },
    {
      "x": 1,
      "y": 2,
      "z": -1,
      "name": "Rock_Slate"
    },
    {
      "x": 1,
      "y": 3,
      "z": -1,
      "name": "Rock_Slate"
    },
    {
      "x": 1,
      "y": 4,
      "z": -1,
      "name": "Rock_Slate"
    },
    {
      "x": 1,
      "y": 5,
      "z": -1,
      "name": "Rock_Slate"
    },
    {
      "x": 1,
      "y": 6,
      "z": -1,
      "name": "Rock_Slate"
    },
    {
      "x": 1,
      "y": 7,
      "z": -1,
      "name": "Rock_Slate"
    },
    {
      "x": 1,
      "y": 8,
      "z": -1,
      "name": "Rock_Slate"
    },
    {
      "x": 1,
      "y": 9,
      "z": -1,
      "name": "Rock_Slate"
    },
    {
      "x": 1,
      "y": 10,
      "z": -1,
      "name": "Rock_Slate"
    },
    {
      "x": 1,
      "y": 11,
      "z": -1,
      "name": "Rock_Slate"
    },
    {
      "x": 1,
      "y": 1,
      "z": 0,
      "name": "Rock_Slate"
    },
    {
      "x": 1,
      "y": 2,
      "z": 0,
      "name": "Rock_Slate"
    },
    {
      "x": 1,
      "y": 3,
      "z": 0,
      "name": "Rock_Slate"
    },
    {
      "x": 1,
      "y": 4,
      "z": 0,
      "name": "Rock_Slate"
    },
    {
      "x": 1,
      "y": 5,
      "z": 0,
      "name": "Rock_Slate"
    },
    {
      "x": 1,
      "y": 6,
      "z": 0,
      "name": "Rock_Slate"
    },
    {
      "x": 1,
      "y": 7,
      "z": 0,
      "name": "Rock_Slate"
    },
    {
      "x": 1,
      "y": 8,
      "z": 0,
      "name": "Rock_Slate"
    },
    {
      "x": 1,
      "y": 9,
      "z": 0,
      "name": "Rock_Slate"
    },
    {
      "x": 1,
      "y": 10,
      "z": 0,
      "name": "Rock_Slate"
    },
    {
      "x": 1,
      "y": 11,
      "z": 0,
      "name": "Rock_Slate"
    },
    {
      "x": 1,
      "y": 1,
      "z": 1,
      "name": "Rock_Slate"
    },
    {
      "x": 1,
      "y": 2,
      "z": 1,
      "name": "Rock_Slate"
    },
    {
      "x": 1,
      "y": 3,
      "z": 1,
      "name": "Rock_Slate"
    },
    {
      "x": 1,
      "y": 4,
      "z": 1,
      "name": "Rock_Slate"
    },
    {
      "x": 1,
      "y": 5,
      "z": 1,
      "name": "Rock_Slate"
    },
    {
      "x": 1,
      "y": 6,
      "z": 1,
      "name": "Rock_Slate"
    },
    {
      "x": 1,
      "y": 7,
      "z": 1,
      "name": "Rock_Slate"
    },
    {
      "x": 1,
      "y": 8,
      "z": 1,
      "name": "Rock_Slate"
    },
    {
      "x": 1,
      "y": 9,
      "z": 1,
      "name": "Rock_Slate"
    },
    {
      "x": 1,
      "y": 10,
      "z": 1,
      "name": "Rock_Slate"
    },
    {
      "x": 1,
      "y": 11,
      "z": 1,
      "name": "Rock_Slate"
    },
    {
      "x": 1,
      "y": 12,
      "z": 1,
      "name": "Rock_Slate"
    },
    {
      "x": 1,
      "y": 1,
      "z": 2,
      "name": "Rock_Slate"
    },
    {
      "x": 1,
      "y": 2,
      "z": 2,
      "name": "Rock_Slate"
    },
    {
      "x": 1,
      "y": 3,
      "z": 2,
      "name": "Rock_Slate"
    },
    {
      "x": 1,
      "y": 4,
      "z": 2,
      "name": "Rock_Slate"
    },
    {
      "x": 1,
      "y": 5,
      "z": 2,
      "name": "Rock_Slate"
    },
    {
      "x": 1,
      "y": 6,
      "z": 2,
      "name": "Rock_Slate"
    },
    {
      "x": 1,
      "y": 7,
      "z": 2,
      "name": "Rock_Slate"
    },
    {
      "x": 1,
      "y": 8,
      "z": 2,
      "name": "Rock_Slate"
    },
    {
      "x": 1,
      "y": 9,
      "z": 2,
      "name": "Rock_Slate"
    },
    {
      "x": 1,
      "y": 10,
      "z": 2,
      "name": "Rock_Slate"
    },
    {
      "x": 1,
      "y": 11,
      "z": 2,
      "name": "Rock_Slate"
    },
    {
      "x": 1,
      "y": 12,
      "z": 2,
      "name": "Rock_Slate"
    },
    {
      "x": 1,
      "y": 3,
      "z": 3,
      "name": "Rock_Slate"
    },
    {
      "x": 1,
      "y": 4,
      "z": 3,
      "name": "Rock_Slate"
    },
    {
      "x": 1,
      "y": 5,
      "z": 3,
      "name": "Rock_Slate"
    },
    {
      "x": 1,
      "y": 6,
      "z": 3,
      "name": "Rock_Slate"
    },
    {
      "x": 1,
      "y": 7,
      "z": 3,
      "name": "Rock_Slate"
    },
    {
      "x": 1,
      "y": 8,
      "z": 3,
      "name": "Rock_Slate"
    },
    {
      "x": 1,
      "y": 9,
      "z": 3,
      "name": "Rock_Slate"
    },
    {
      "x": 1,
      "y": 10,
      "z": 3,
      "name": "Rock_Slate"
    },
    {
      "x": 1,
      "y": 11,
      "z": 3,
      "name": "Rock_Slate"
    },
    {
      "x": 1,
      "y": 12,
      "z": 3,
      "name": "Rock_Slate"
    },
    {
      "x": 1,
      "y": 6,
      "z": 4,
      "name": "Rock_Slate"
    },
    {
      "x": 1,
      "y": 7,
      "z": 4,
      "name": "Rock_Slate"
    },
    {
      "x": 1,
      "y": 8,
      "z": 4,
      "name": "Rock_Slate"
    },
    {
      "x": 1,
      "y": 9,
      "z": 4,
      "name": "Rock_Slate"
    },
    {
      "x": 1,
      "y": 10,
      "z": 4,
      "name": "Rock_Slate"
    },
    {
      "x": 1,
      "y": 11,
      "z": 4,
      "name": "Rock_Slate"
    },
    {
      "x": 1,
      "y": 12,
      "z": 4,
      "name": "Rock_Slate"
    },
    {
      "x": 1,
      "y": 13,
      "z": 4,
      "name": "Rubble_Slate"
    },
    {
      "x": 1,
      "y": 8,
      "z": 5,
      "name": "Rock_Slate"
    },
    {
      "x": 1,
      "y": 9,
      "z": 5,
      "name": "Rock_Slate"
    },
    {
      "x": 1,
      "y": 10,
      "z": 5,
      "name": "Rock_Slate"
    },
    {
      "x": 2,
      "y": 8,
      "z": -8,
      "name": "Soil_Dirt_Burnt"
    },
    {
      "x": 2,
      "y": 9,
      "z": -8,
      "name": "Soil_Grass_Burnt"
    },
    {
      "x": 2,
      "y": 1,
      "z": -7,
      "name": "Rock_Slate"
    },
    {
      "x": 2,
      "y": 2,
      "z": -7,
      "name": "Rock_Slate"
    },
    {
      "x": 2,
      "y": 3,
      "z": -7,
      "name": "Rock_Slate"
    },
    {
      "x": 2,
      "y": 4,
      "z": -7,
      "name": "Rock_Slate"
    },
    {
      "x": 2,
      "y": 5,
      "z": -7,
      "name": "Rock_Slate"
    },
    {
      "x": 2,
      "y": 6,
      "z": -7,
      "name": "Rock_Slate"
    },
    {
      "x": 2,
      "y": 7,
      "z": -7,
      "name": "Rock_Slate"
    },
    {
      "x": 2,
      "y": 8,
      "z": -7,
      "name": "Rock_Slate"
    },
    {
      "x": 2,
      "y": 9,
      "z": -7,
      "name": "Rock_Slate"
    },
    {
      "x": 2,
      "y": 10,
      "z": -7,
      "name": "Rock_Slate"
    },
    {
      "x": 2,
      "y": 1,
      "z": -6,
      "name": "Rock_Slate"
    },
    {
      "x": 2,
      "y": 2,
      "z": -6,
      "name": "Rock_Slate"
    },
    {
      "x": 2,
      "y": 3,
      "z": -6,
      "name": "Rock_Slate"
    },
    {
      "x": 2,
      "y": 4,
      "z": -6,
      "name": "Rock_Slate"
    },
    {
      "x": 2,
      "y": 5,
      "z": -6,
      "name": "Rock_Slate"
    },
    {
      "x": 2,
      "y": 6,
      "z": -6,
      "name": "Rock_Slate"
    },
    {
      "x": 2,
      "y": 7,
      "z": -6,
      "name": "Rock_Slate"
    },
    {
      "x": 2,
      "y": 8,
      "z": -6,
      "name": "Rock_Slate"
    },
    {
      "x": 2,
      "y": 9,
      "z": -6,
      "name": "Rock_Slate"
    },
    {
      "x": 2,
      "y": 10,
      "z": -6,
      "name": "Rock_Slate"
    },
    {
      "x": 2,
      "y": 11,
      "z": -6,
      "name": "Rock_Slate"
    },
    {
      "x": 2,
      "y": 1,
      "z": -5,
      "name": "Rock_Slate"
    },
    {
      "x": 2,
      "y": 2,
      "z": -5,
      "name": "Rock_Slate"
    },
    {
      "x": 2,
      "y": 3,
      "z": -5,
      "name": "Rock_Slate"
    },
    {
      "x": 2,
      "y": 4,
      "z": -5,
      "name": "Rock_Slate"
    },
    {
      "x": 2,
      "y": 5,
      "z": -5,
      "name": "Rock_Slate"
    },
    {
      "x": 2,
      "y": 6,
      "z": -5,
      "name": "Rock_Slate"
    },
    {
      "x": 2,
      "y": 7,
      "z": -5,
      "name": "Rock_Slate"
    },
    {
      "x": 2,
      "y": 8,
      "z": -5,
      "name": "Rock_Slate"
    },
    {
      "x": 2,
      "y": 9,
      "z": -5,
      "name": "Rock_Slate"
    },
    {
      "x": 2,
      "y": 10,
      "z": -5,
      "name": "Rock_Slate"
    },
    {
      "x": 2,
      "y": 11,
      "z": -5,
      "name": "Rock_Slate"
    },
    {
      "x": 2,
      "y": 12,
      "z": -5,
      "name": "Rubble_Slate"
    },
    {
      "x": 2,
      "y": 1,
      "z": -4,
      "name": "Rock_Slate"
    },
    {
      "x": 2,
      "y": 2,
      "z": -4,
      "name": "Rock_Slate"
    },
    {
      "x": 2,
      "y": 3,
      "z": -4,
      "name": "Rock_Slate"
    },
    {
      "x": 2,
      "y": 4,
      "z": -4,
      "name": "Rock_Slate"
    },
    {
      "x": 2,
      "y": 5,
      "z": -4,
      "name": "Rock_Slate"
    },
    {
      "x": 2,
      "y": 6,
      "z": -4,
      "name": "Rock_Slate"
    },
    {
      "x": 2,
      "y": 7,
      "z": -4,
      "name": "Rock_Slate"
    },
    {
      "x": 2,
      "y": 8,
      "z": -4,
      "name": "Rock_Slate"
    },
    {
      "x": 2,
      "y": 9,
      "z": -4,
      "name": "Rock_Slate"
    },
    {
      "x": 2,
      "y": 10,
      "z": -4,
      "name": "Rock_Slate"
    },
    {
      "x": 2,
      "y": 11,
      "z": -4,
      "name": "Rock_Slate"
    },
    {
      "x": 2,
      "y": 1,
      "z": -3,
      "name": "Rock_Slate"
    },
    {
      "x": 2,
      "y": 2,
      "z": -3,
      "name": "Rock_Slate"
    },
    {
      "x": 2,
      "y": 3,
      "z": -3,
      "name": "Rock_Slate"
    },
    {
      "x": 2,
      "y": 4,
      "z": -3,
      "name": "Rock_Slate"
    },
    {
      "x": 2,
      "y": 5,
      "z": -3,
      "name": "Rock_Slate"
    },
    {
      "x": 2,
      "y": 6,
      "z": -3,
      "name": "Rock_Slate"
    },
    {
      "x": 2,
      "y": 7,
      "z": -3,
      "name": "Rock_Slate"
    },
    {
      "x": 2,
      "y": 8,
      "z": -3,
      "name": "Rock_Slate"
    },
    {
      "x": 2,
      "y": 9,
      "z": -3,
      "name": "Rock_Slate"
    },
    {
      "x": 2,
      "y": 10,
      "z": -3,
      "name": "Rock_Slate"
    },
    {
      "x": 2,
      "y": 11,
      "z": -3,
      "name": "Rock_Slate"
    },
    {
      "x": 2,
      "y": 1,
      "z": -2,
      "name": "Rock_Slate"
    },
    {
      "x": 2,
      "y": 2,
      "z": -2,
      "name": "Rock_Slate"
    },
    {
      "x": 2,
      "y": 3,
      "z": -2,
      "name": "Rock_Slate"
    },
    {
      "x": 2,
      "y": 4,
      "z": -2,
      "name": "Rock_Slate"
    },
    {
      "x": 2,
      "y": 5,
      "z": -2,
      "name": "Rock_Slate"
    },
    {
      "x": 2,
      "y": 6,
      "z": -2,
      "name": "Rock_Slate"
    },
    {
      "x": 2,
      "y": 7,
      "z": -2,
      "name": "Rock_Slate"
    },
    {
      "x": 2,
      "y": 8,
      "z": -2,
      "name": "Rock_Slate"
    },
    {
      "x": 2,
      "y": 9,
      "z": -2,
      "name": "Rock_Slate"
    },
    {
      "x": 2,
      "y": 10,
      "z": -2,
      "name": "Rock_Slate"
    },
    {
      "x": 2,
      "y": 11,
      "z": -2,
      "name": "Rock_Slate"
    },
    {
      "x": 2,
      "y": 1,
      "z": -1,
      "name": "Rock_Slate"
    },
    {
      "x": 2,
      "y": 2,
      "z": -1,
      "name": "Rock_Slate"
    },
    {
      "x": 2,
      "y": 3,
      "z": -1,
      "name": "Rock_Slate"
    },
    {
      "x": 2,
      "y": 4,
      "z": -1,
      "name": "Rock_Slate"
    },
    {
      "x": 2,
      "y": 5,
      "z": -1,
      "name": "Rock_Slate"
    },
    {
      "x": 2,
      "y": 6,
      "z": -1,
      "name": "Rock_Slate"
    },
    {
      "x": 2,
      "y": 7,
      "z": -1,
      "name": "Rock_Slate"
    },
    {
      "x": 2,
      "y": 8,
      "z": -1,
      "name": "Rock_Slate"
    },
    {
      "x": 2,
      "y": 9,
      "z": -1,
      "name": "Rock_Slate"
    },
    {
      "x": 2,
      "y": 10,
      "z": -1,
      "name": "Rock_Slate"
    },
    {
      "x": 2,
      "y": 11,
      "z": -1,
      "name": "Rock_Slate"
    },
    {
      "x": 2,
      "y": 1,
      "z": 0,
      "name": "Rock_Slate"
    },
    {
      "x": 2,
      "y": 2,
      "z": 0,
      "name": "Rock_Slate"
    },
    {
      "x": 2,
      "y": 3,
      "z": 0,
      "name": "Rock_Slate"
    },
    {
      "x": 2,
      "y": 4,
      "z": 0,
      "name": "Rock_Slate"
    },
    {
      "x": 2,
      "y": 5,
      "z": 0,
      "name": "Rock_Slate"
    },
    {
      "x": 2,
      "y": 6,
      "z": 0,
      "name": "Rock_Slate"
    },
    {
      "x": 2,
      "y": 7,
      "z": 0,
      "name": "Rock_Slate"
    },
    {
      "x": 2,
      "y": 8,
      "z": 0,
      "name": "Rock_Slate"
    },
    {
      "x": 2,
      "y": 9,
      "z": 0,
      "name": "Rock_Slate"
    },
    {
      "x": 2,
      "y": 10,
      "z": 0,
      "name": "Rock_Slate"
    },
    {
      "x": 2,
      "y": 11,
      "z": 0,
      "name": "Rock_Slate"
    },
    {
      "x": 2,
      "y": 1,
      "z": 1,
      "name": "Rock_Slate"
    },
    {
      "x": 2,
      "y": 2,
      "z": 1,
      "name": "Rock_Slate"
    },
    {
      "x": 2,
      "y": 3,
      "z": 1,
      "name": "Rock_Slate"
    },
    {
      "x": 2,
      "y": 4,
      "z": 1,
      "name": "Rock_Slate"
    },
    {
      "x": 2,
      "y": 5,
      "z": 1,
      "name": "Rock_Slate"
    },
    {
      "x": 2,
      "y": 6,
      "z": 1,
      "name": "Rock_Slate"
    },
    {
      "x": 2,
      "y": 7,
      "z": 1,
      "name": "Rock_Slate"
    },
    {
      "x": 2,
      "y": 8,
      "z": 1,
      "name": "Rock_Slate"
    },
    {
      "x": 2,
      "y": 9,
      "z": 1,
      "name": "Rock_Slate"
    },
    {
      "x": 2,
      "y": 10,
      "z": 1,
      "name": "Rock_Slate"
    },
    {
      "x": 2,
      "y": 11,
      "z": 1,
      "name": "Rock_Slate"
    },
    {
      "x": 2,
      "y": 2,
      "z": 2,
      "name": "Rock_Slate"
    },
    {
      "x": 2,
      "y": 3,
      "z": 2,
      "name": "Rock_Slate"
    },
    {
      "x": 2,
      "y": 4,
      "z": 2,
      "name": "Rock_Slate"
    },
    {
      "x": 2,
      "y": 5,
      "z": 2,
      "name": "Rock_Slate"
    },
    {
      "x": 2,
      "y": 6,
      "z": 2,
      "name": "Rock_Slate"
    },
    {
      "x": 2,
      "y": 7,
      "z": 2,
      "name": "Rock_Slate"
    },
    {
      "x": 2,
      "y": 8,
      "z": 2,
      "name": "Rock_Slate"
    },
    {
      "x": 2,
      "y": 9,
      "z": 2,
      "name": "Rock_Slate"
    },
    {
      "x": 2,
      "y": 10,
      "z": 2,
      "name": "Rock_Slate"
    },
    {
      "x": 2,
      "y": 11,
      "z": 2,
      "name": "Rock_Slate"
    },
    {
      "x": 2,
      "y": 4,
      "z": 3,
      "name": "Rock_Slate"
    },
    {
      "x": 2,
      "y": 5,
      "z": 3,
      "name": "Rock_Slate"
    },
    {
      "x": 2,
      "y": 6,
      "z": 3,
      "name": "Rock_Slate"
    },
    {
      "x": 2,
      "y": 7,
      "z": 3,
      "name": "Rock_Slate"
    },
    {
      "x": 2,
      "y": 8,
      "z": 3,
      "name": "Rock_Slate"
    },
    {
      "x": 2,
      "y": 9,
      "z": 3,
      "name": "Rock_Slate"
    },
    {
      "x": 2,
      "y": 10,
      "z": 3,
      "name": "Rock_Slate"
    },
    {
      "x": 2,
      "y": 11,
      "z": 3,
      "name": "Rock_Slate"
    },
    {
      "x": 2,
      "y": 12,
      "z": 3,
      "name": "Rock_Slate"
    },
    {
      "x": 2,
      "y": 7,
      "z": 4,
      "name": "Rock_Slate"
    },
    {
      "x": 2,
      "y": 8,
      "z": 4,
      "name": "Rock_Slate"
    },
    {
      "x": 2,
      "y": 9,
      "z": 4,
      "name": "Rock_Slate"
    },
    {
      "x": 2,
      "y": 10,
      "z": 4,
      "name": "Rock_Slate"
    },
    {
      "x": 2,
      "y": 11,
      "z": 4,
      "name": "Rock_Slate"
    },
    {
      "x": 3,
      "y": 1,
      "z": -7,
      "name": "Rock_Slate"
    },
    {
      "x": 3,
      "y": 2,
      "z": -7,
      "name": "Rock_Slate"
    },
    {
      "x": 3,
      "y": 3,
      "z": -7,
      "name": "Rock_Slate"
    },
    {
      "x": 3,
      "y": 4,
      "z": -7,
      "name": "Rock_Slate"
    },
    {
      "x": 3,
      "y": 5,
      "z": -7,
      "name": "Rock_Slate"
    },
    {
      "x": 3,
      "y": 6,
      "z": -7,
      "name": "Rock_Slate"
    },
    {
      "x": 3,
      "y": 7,
      "z": -7,
      "name": "Rock_Slate"
    },
    {
      "x": 3,
      "y": 8,
      "z": -7,
      "name": "Rock_Slate"
    },
    {
      "x": 3,
      "y": 9,
      "z": -7,
      "name": "Rock_Slate"
    },
    {
      "x": 3,
      "y": 10,
      "z": -7,
      "name": "Rock_Slate"
    },
    {
      "x": 3,
      "y": 1,
      "z": -6,
      "name": "Rock_Slate"
    },
    {
      "x": 3,
      "y": 2,
      "z": -6,
      "name": "Rock_Slate"
    },
    {
      "x": 3,
      "y": 3,
      "z": -6,
      "name": "Rock_Slate"
    },
    {
      "x": 3,
      "y": 4,
      "z": -6,
      "name": "Rock_Slate"
    },
    {
      "x": 3,
      "y": 5,
      "z": -6,
      "name": "Rock_Slate"
    },
    {
      "x": 3,
      "y": 6,
      "z": -6,
      "name": "Rock_Slate"
    },
    {
      "x": 3,
      "y": 7,
      "z": -6,
      "name": "Rock_Slate"
    },
    {
      "x": 3,
      "y": 8,
      "z": -6,
      "name": "Rock_Slate"
    },
    {
      "x": 3,
      "y": 9,
      "z": -6,
      "name": "Rock_Slate"
    },
    {
      "x": 3,
      "y": 10,
      "z": -6,
      "name": "Rock_Slate"
    },
    {
      "x": 3,
      "y": 11,
      "z": -6,
      "name": "Rock_Slate"
    },
    {
      "x": 3,
      "y": 1,
      "z": -5,
      "name": "Rock_Slate"
    },
    {
      "x": 3,
      "y": 2,
      "z": -5,
      "name": "Rock_Slate"
    },
    {
      "x": 3,
      "y": 3,
      "z": -5,
      "name": "Rock_Slate"
    },
    {
      "x": 3,
      "y": 4,
      "z": -5,
      "name": "Rock_Slate"
    },
    {
      "x": 3,
      "y": 5,
      "z": -5,
      "name": "Rock_Slate"
    },
    {
      "x": 3,
      "y": 6,
      "z": -5,
      "name": "Rock_Slate"
    },
    {
      "x": 3,
      "y": 7,
      "z": -5,
      "name": "Rock_Slate"
    },
    {
      "x": 3,
      "y": 8,
      "z": -5,
      "name": "Rock_Slate"
    },
    {
      "x": 3,
      "y": 9,
      "z": -5,
      "name": "Rock_Slate"
    },
    {
      "x": 3,
      "y": 10,
      "z": -5,
      "name": "Rock_Slate"
    },
    {
      "x": 3,
      "y": 11,
      "z": -5,
      "name": "Rock_Slate"
    },
    {
      "x": 3,
      "y": 1,
      "z": -4,
      "name": "Rock_Slate"
    },
    {
      "x": 3,
      "y": 2,
      "z": -4,
      "name": "Rock_Slate"
    },
    {
      "x": 3,
      "y": 3,
      "z": -4,
      "name": "Rock_Slate"
    },
    {
      "x": 3,
      "y": 4,
      "z": -4,
      "name": "Rock_Slate"
    },
    {
      "x": 3,
      "y": 5,
      "z": -4,
      "name": "Rock_Slate"
    },
    {
      "x": 3,
      "y": 6,
      "z": -4,
      "name": "Rock_Slate"
    },
    {
      "x": 3,
      "y": 7,
      "z": -4,
      "name": "Rock_Slate"
    },
    {
      "x": 3,
      "y": 8,
      "z": -4,
      "name": "Rock_Slate"
    },
    {
      "x": 3,
      "y": 9,
      "z": -4,
      "name": "Rock_Slate"
    },
    {
      "x": 3,
      "y": 10,
      "z": -4,
      "name": "Rock_Slate"
    },
    {
      "x": 3,
      "y": 11,
      "z": -4,
      "name": "Rock_Slate"
    },
    {
      "x": 3,
      "y": 1,
      "z": -3,
      "name": "Rock_Slate"
    },
    {
      "x": 3,
      "y": 2,
      "z": -3,
      "name": "Rock_Slate"
    },
    {
      "x": 3,
      "y": 3,
      "z": -3,
      "name": "Rock_Slate"
    },
    {
      "x": 3,
      "y": 4,
      "z": -3,
      "name": "Rock_Slate"
    },
    {
      "x": 3,
      "y": 5,
      "z": -3,
      "name": "Rock_Slate"
    },
    {
      "x": 3,
      "y": 6,
      "z": -3,
      "name": "Rock_Slate"
    },
    {
      "x": 3,
      "y": 7,
      "z": -3,
      "name": "Rock_Slate"
    },
    {
      "x": 3,
      "y": 8,
      "z": -3,
      "name": "Rock_Slate"
    },
    {
      "x": 3,
      "y": 9,
      "z": -3,
      "name": "Rock_Slate"
    },
    {
      "x": 3,
      "y": 10,
      "z": -3,
      "name": "Rock_Slate"
    },
    {
      "x": 3,
      "y": 11,
      "z": -3,
      "name": "Rock_Slate"
    },
    {
      "x": 3,
      "y": 1,
      "z": -2,
      "name": "Rock_Slate"
    },
    {
      "x": 3,
      "y": 2,
      "z": -2,
      "name": "Rock_Slate"
    },
    {
      "x": 3,
      "y": 3,
      "z": -2,
      "name": "Rock_Slate"
    },
    {
      "x": 3,
      "y": 4,
      "z": -2,
      "name": "Rock_Slate"
    },
    {
      "x": 3,
      "y": 5,
      "z": -2,
      "name": "Rock_Slate"
    },
    {
      "x": 3,
      "y": 6,
      "z": -2,
      "name": "Rock_Slate"
    },
    {
      "x": 3,
      "y": 7,
      "z": -2,
      "name": "Rock_Slate"
    },
    {
      "x": 3,
      "y": 8,
      "z": -2,
      "name": "Rock_Slate"
    },
    {
      "x": 3,
      "y": 9,
      "z": -2,
      "name": "Rock_Slate"
    },
    {
      "x": 3,
      "y": 10,
      "z": -2,
      "name": "Rock_Slate"
    },
    {
      "x": 3,
      "y": 11,
      "z": -2,
      "name": "Rock_Slate"
    },
    {
      "x": 3,
      "y": 1,
      "z": -1,
      "name": "Rock_Slate"
    },
    {
      "x": 3,
      "y": 2,
      "z": -1,
      "name": "Rock_Slate"
    },
    {
      "x": 3,
      "y": 3,
      "z": -1,
      "name": "Rock_Slate"
    },
    {
      "x": 3,
      "y": 4,
      "z": -1,
      "name": "Rock_Slate"
    },
    {
      "x": 3,
      "y": 5,
      "z": -1,
      "name": "Rock_Slate"
    },
    {
      "x": 3,
      "y": 6,
      "z": -1,
      "name": "Rock_Slate"
    },
    {
      "x": 3,
      "y": 7,
      "z": -1,
      "name": "Rock_Slate"
    },
    {
      "x": 3,
      "y": 8,
      "z": -1,
      "name": "Rock_Slate"
    },
    {
      "x": 3,
      "y": 9,
      "z": -1,
      "name": "Rock_Slate"
    },
    {
      "x": 3,
      "y": 10,
      "z": -1,
      "name": "Rock_Slate"
    },
    {
      "x": 3,
      "y": 11,
      "z": -1,
      "name": "Rock_Slate"
    },
    {
      "x": 3,
      "y": 1,
      "z": 0,
      "name": "Rock_Slate"
    },
    {
      "x": 3,
      "y": 2,
      "z": 0,
      "name": "Rock_Slate"
    },
    {
      "x": 3,
      "y": 3,
      "z": 0,
      "name": "Rock_Slate"
    },
    {
      "x": 3,
      "y": 4,
      "z": 0,
      "name": "Rock_Slate"
    },
    {
      "x": 3,
      "y": 5,
      "z": 0,
      "name": "Rock_Slate"
    },
    {
      "x": 3,
      "y": 6,
      "z": 0,
      "name": "Rock_Slate"
    },
    {
      "x": 3,
      "y": 7,
      "z": 0,
      "name": "Rock_Slate"
    },
    {
      "x": 3,
      "y": 8,
      "z": 0,
      "name": "Rock_Slate"
    },
    {
      "x": 3,
      "y": 9,
      "z": 0,
      "name": "Rock_Slate"
    },
    {
      "x": 3,
      "y": 10,
      "z": 0,
      "name": "Rock_Slate"
    },
    {
      "x": 3,
      "y": 11,
      "z": 0,
      "name": "Rock_Slate"
    },
    {
      "x": 3,
      "y": 1,
      "z": 1,
      "name": "Rock_Slate"
    },
    {
      "x": 3,
      "y": 2,
      "z": 1,
      "name": "Rock_Slate"
    },
    {
      "x": 3,
      "y": 3,
      "z": 1,
      "name": "Rock_Slate"
    },
    {
      "x": 3,
      "y": 4,
      "z": 1,
      "name": "Rock_Slate"
    },
    {
      "x": 3,
      "y": 5,
      "z": 1,
      "name": "Rock_Slate"
    },
    {
      "x": 3,
      "y": 6,
      "z": 1,
      "name": "Rock_Slate"
    },
    {
      "x": 3,
      "y": 7,
      "z": 1,
      "name": "Rock_Slate"
    },
    {
      "x": 3,
      "y": 8,
      "z": 1,
      "name": "Rock_Slate"
    },
    {
      "x": 3,
      "y": 9,
      "z": 1,
      "name": "Rock_Slate"
    },
    {
      "x": 3,
      "y": 10,
      "z": 1,
      "name": "Rock_Slate"
    },
    {
      "x": 3,
      "y": 11,
      "z": 1,
      "name": "Rock_Slate"
    },
    {
      "x": 3,
      "y": 3,
      "z": 2,
      "name": "Rock_Slate"
    },
    {
      "x": 3,
      "y": 4,
      "z": 2,
      "name": "Rock_Slate"
    },
    {
      "x": 3,
      "y": 5,
      "z": 2,
      "name": "Rock_Slate"
    },
    {
      "x": 3,
      "y": 6,
      "z": 2,
      "name": "Rock_Slate"
    },
    {
      "x": 3,
      "y": 7,
      "z": 2,
      "name": "Rock_Slate"
    },
    {
      "x": 3,
      "y": 8,
      "z": 2,
      "name": "Rock_Slate"
    },
    {
      "x": 3,
      "y": 9,
      "z": 2,
      "name": "Rock_Slate"
    },
    {
      "x": 3,
      "y": 10,
      "z": 2,
      "name": "Rock_Slate"
    },
    {
      "x": 3,
      "y": 11,
      "z": 2,
      "name": "Rock_Slate"
    },
    {
      "x": 4,
      "y": 3,
      "z": -7,
      "name": "Rock_Slate"
    },
    {
      "x": 4,
      "y": 4,
      "z": -7,
      "name": "Rock_Slate"
    },
    {
      "x": 4,
      "y": 5,
      "z": -7,
      "name": "Rock_Slate"
    },
    {
      "x": 4,
      "y": 6,
      "z": -7,
      "name": "Rock_Slate"
    },
    {
      "x": 4,
      "y": 7,
      "z": -7,
      "name": "Rock_Slate"
    },
    {
      "x": 4,
      "y": 8,
      "z": -7,
      "name": "Rock_Slate"
    },
    {
      "x": 4,
      "y": 9,
      "z": -7,
      "name": "Soil_Dirt_Burnt"
    },
    {
      "x": 4,
      "y": 10,
      "z": -7,
      "name": "Soil_Grass_Burnt"
    },
    {
      "x": 4,
      "y": 1,
      "z": -6,
      "name": "Rock_Slate"
    },
    {
      "x": 4,
      "y": 2,
      "z": -6,
      "name": "Rock_Slate"
    },
    {
      "x": 4,
      "y": 3,
      "z": -6,
      "name": "Rock_Slate"
    },
    {
      "x": 4,
      "y": 4,
      "z": -6,
      "name": "Rock_Slate"
    },
    {
      "x": 4,
      "y": 5,
      "z": -6,
      "name": "Rock_Slate"
    },
    {
      "x": 4,
      "y": 6,
      "z": -6,
      "name": "Rock_Slate"
    },
    {
      "x": 4,
      "y": 7,
      "z": -6,
      "name": "Rock_Slate"
    },
    {
      "x": 4,
      "y": 8,
      "z": -6,
      "name": "Rock_Slate"
    },
    {
      "x": 4,
      "y": 9,
      "z": -6,
      "name": "Rock_Slate"
    },
    {
      "x": 4,
      "y": 10,
      "z": -6,
      "name": "Soil_Grass_Burnt"
    },
    {
      "x": 4,
      "y": 1,
      "z": -5,
      "name": "Rock_Slate"
    },
    {
      "x": 4,
      "y": 2,
      "z": -5,
      "name": "Rock_Slate"
    },
    {
      "x": 4,
      "y": 3,
      "z": -5,
      "name": "Rock_Slate"
    },
    {
      "x": 4,
      "y": 4,
      "z": -5,
      "name": "Rock_Slate"
    },
    {
      "x": 4,
      "y": 5,
      "z": -5,
      "name": "Rock_Slate"
    },
    {
      "x": 4,
      "y": 6,
      "z": -5,
      "name": "Rock_Slate"
    },
    {
      "x": 4,
      "y": 7,
      "z": -5,
      "name": "Rock_Slate"
    },
    {
      "x": 4,
      "y": 8,
      "z": -5,
      "name": "Rock_Slate"
    },
    {
      "x": 4,
      "y": 9,
      "z": -5,
      "name": "Rock_Slate"
    },
    {
      "x": 4,
      "y": 10,
      "z": -5,
      "name": "Rock_Slate"
    },
    {
      "x": 4,
      "y": 11,
      "z": -5,
      "name": "Rock_Slate"
    },
    {
      "x": 4,
      "y": 1,
      "z": -4,
      "name": "Rock_Slate"
    },
    {
      "x": 4,
      "y": 2,
      "z": -4,
      "name": "Rock_Slate"
    },
    {
      "x": 4,
      "y": 3,
      "z": -4,
      "name": "Rock_Slate"
    },
    {
      "x": 4,
      "y": 4,
      "z": -4,
      "name": "Rock_Slate"
    },
    {
      "x": 4,
      "y": 5,
      "z": -4,
      "name": "Rock_Slate"
    },
    {
      "x": 4,
      "y": 6,
      "z": -4,
      "name": "Rock_Slate"
    },
    {
      "x": 4,
      "y": 7,
      "z": -4,
      "name": "Rock_Slate"
    },
    {
      "x": 4,
      "y": 8,
      "z": -4,
      "name": "Rock_Slate"
    },
    {
      "x": 4,
      "y": 9,
      "z": -4,
      "name": "Rock_Slate"
    },
    {
      "x": 4,
      "y": 10,
      "z": -4,
      "name": "Rock_Slate"
    },
    {
      "x": 4,
      "y": 11,
      "z": -4,
      "name": "Rock_Slate"
    },
    {
      "x": 4,
      "y": 1,
      "z": -3,
      "name": "Rock_Slate"
    },
    {
      "x": 4,
      "y": 2,
      "z": -3,
      "name": "Rock_Slate"
    },
    {
      "x": 4,
      "y": 3,
      "z": -3,
      "name": "Rock_Slate"
    },
    {
      "x": 4,
      "y": 4,
      "z": -3,
      "name": "Rock_Slate"
    },
    {
      "x": 4,
      "y": 5,
      "z": -3,
      "name": "Rock_Slate"
    },
    {
      "x": 4,
      "y": 6,
      "z": -3,
      "name": "Rock_Slate"
    },
    {
      "x": 4,
      "y": 7,
      "z": -3,
      "name": "Rock_Slate"
    },
    {
      "x": 4,
      "y": 8,
      "z": -3,
      "name": "Rock_Slate"
    },
    {
      "x": 4,
      "y": 9,
      "z": -3,
      "name": "Rock_Slate"
    },
    {
      "x": 4,
      "y": 10,
      "z": -3,
      "name": "Rock_Slate"
    },
    {
      "x": 4,
      "y": 11,
      "z": -3,
      "name": "Rock_Slate"
    },
    {
      "x": 4,
      "y": 1,
      "z": -2,
      "name": "Rock_Slate"
    },
    {
      "x": 4,
      "y": 2,
      "z": -2,
      "name": "Rock_Slate"
    },
    {
      "x": 4,
      "y": 3,
      "z": -2,
      "name": "Rock_Slate"
    },
    {
      "x": 4,
      "y": 4,
      "z": -2,
      "name": "Rock_Slate"
    },
    {
      "x": 4,
      "y": 5,
      "z": -2,
      "name": "Rock_Slate"
    },
    {
      "x": 4,
      "y": 6,
      "z": -2,
      "name": "Rock_Slate"
    },
    {
      "x": 4,
      "y": 7,
      "z": -2,
      "name": "Rock_Slate"
    },
    {
      "x": 4,
      "y": 8,
      "z": -2,
      "name": "Rock_Slate"
    },
    {
      "x": 4,
      "y": 9,
      "z": -2,
      "name": "Rock_Slate"
    },
    {
      "x": 4,
      "y": 10,
      "z": -2,
      "name": "Rock_Slate"
    },
    {
      "x": 4,
      "y": 11,
      "z": -2,
      "name": "Rock_Slate"
    },
    {
      "x": 4,
      "y": 1,
      "z": -1,
      "name": "Rock_Slate"
    },
    {
      "x": 4,
      "y": 2,
      "z": -1,
      "name": "Rock_Slate"
    },
    {
      "x": 4,
      "y": 3,
      "z": -1,
      "name": "Rock_Slate"
    },
    {
      "x": 4,
      "y": 4,
      "z": -1,
      "name": "Rock_Slate"
    },
    {
      "x": 4,
      "y": 5,
      "z": -1,
      "name": "Rock_Slate"
    },
    {
      "x": 4,
      "y": 6,
      "z": -1,
      "name": "Rock_Slate"
    },
    {
      "x": 4,
      "y": 7,
      "z": -1,
      "name": "Rock_Slate"
    },
    {
      "x": 4,
      "y": 8,
      "z": -1,
      "name": "Rock_Slate"
    },
    {
      "x": 4,
      "y": 9,
      "z": -1,
      "name": "Rock_Slate"
    },
    {
      "x": 4,
      "y": 10,
      "z": -1,
      "name": "Rock_Slate"
    },
    {
      "x": 4,
      "y": 11,
      "z": -1,
      "name": "Rock_Slate"
    },
    {
      "x": 4,
      "y": 1,
      "z": 0,
      "name": "Rock_Slate"
    },
    {
      "x": 4,
      "y": 2,
      "z": 0,
      "name": "Rock_Slate"
    },
    {
      "x": 4,
      "y": 3,
      "z": 0,
      "name": "Rock_Slate"
    },
    {
      "x": 4,
      "y": 4,
      "z": 0,
      "name": "Rock_Slate"
    },
    {
      "x": 4,
      "y": 5,
      "z": 0,
      "name": "Rock_Slate"
    },
    {
      "x": 4,
      "y": 6,
      "z": 0,
      "name": "Rock_Slate"
    },
    {
      "x": 4,
      "y": 7,
      "z": 0,
      "name": "Rock_Slate"
    },
    {
      "x": 4,
      "y": 8,
      "z": 0,
      "name": "Rock_Slate"
    },
    {
      "x": 4,
      "y": 9,
      "z": 0,
      "name": "Rock_Slate"
    },
    {
      "x": 4,
      "y": 10,
      "z": 0,
      "name": "Rock_Slate"
    },
    {
      "x": 4,
      "y": 11,
      "z": 0,
      "name": "Rock_Slate"
    },
    {
      "x": 4,
      "y": 3,
      "z": 1,
      "name": "Rock_Slate"
    },
    {
      "x": 4,
      "y": 4,
      "z": 1,
      "name": "Rock_Slate"
    },
    {
      "x": 4,
      "y": 5,
      "z": 1,
      "name": "Rock_Slate"
    },
    {
      "x": 4,
      "y": 6,
      "z": 1,
      "name": "Rock_Slate"
    },
    {
      "x": 4,
      "y": 7,
      "z": 1,
      "name": "Rock_Slate"
    },
    {
      "x": 4,
      "y": 8,
      "z": 1,
      "name": "Rock_Slate"
    },
    {
      "x": 4,
      "y": 9,
      "z": 1,
      "name": "Rock_Slate"
    },
    {
      "x": 4,
      "y": 10,
      "z": 1,
      "name": "Rock_Slate"
    },
    {
      "x": 4,
      "y": 6,
      "z": 2,
      "name": "Rock_Slate"
    },
    {
      "x": 4,
      "y": 7,
      "z": 2,
      "name": "Rock_Slate"
    },
    {
      "x": 4,
      "y": 8,
      "z": 2,
      "name": "Rock_Slate"
    },
    {
      "x": 4,
      "y": 9,
      "z": 2,
      "name": "Soil_Dirt_Burnt"
    },
    {
      "x": 4,
      "y": 10,
      "z": 2,
      "name": "Soil_Grass_Burnt"
    },
    {
      "x": 4,
      "y": 11,
      "z": 2,
      "name": "Plant_Grass_Gnarled"
    },
    {
      "x": 5,
      "y": 6,
      "z": -7,
      "name": "Rock_Slate"
    },
    {
      "x": 5,
      "y": 7,
      "z": -7,
      "name": "Rock_Slate"
    },
    {
      "x": 5,
      "y": 8,
      "z": -7,
      "name": "Soil_Dirt_Burnt"
    },
    {
      "x": 5,
      "y": 9,
      "z": -7,
      "name": "Soil_Grass_Burnt"
    },
    {
      "x": 5,
      "y": 10,
      "z": -7,
      "name": "Plant_Grass_Gnarled_Tall"
    },
    {
      "x": 5,
      "y": 11,
      "z": -7,
      "name": "Plant_Grass_Gnarled_Tall",
      "filler": 1024
    },
    {
      "x": 5,
      "y": 3,
      "z": -6,
      "name": "Rock_Slate"
    },
    {
      "x": 5,
      "y": 4,
      "z": -6,
      "name": "Rock_Slate"
    },
    {
      "x": 5,
      "y": 5,
      "z": -6,
      "name": "Rock_Slate"
    },
    {
      "x": 5,
      "y": 6,
      "z": -6,
      "name": "Rock_Slate"
    },
    {
      "x": 5,
      "y": 7,
      "z": -6,
      "name": "Rock_Slate"
    },
    {
      "x": 5,
      "y": 8,
      "z": -6,
      "name": "Soil_Dirt_Burnt"
    },
    {
      "x": 5,
      "y": 9,
      "z": -6,
      "name": "Soil_Dirt_Burnt"
    },
    {
      "x": 5,
      "y": 10,
      "z": -6,
      "name": "Soil_Grass_Burnt"
    },
    {
      "x": 5,
      "y": 3,
      "z": -5,
      "name": "Rock_Slate"
    },
    {
      "x": 5,
      "y": 4,
      "z": -5,
      "name": "Rock_Slate"
    },
    {
      "x": 5,
      "y": 5,
      "z": -5,
      "name": "Rock_Slate"
    },
    {
      "x": 5,
      "y": 6,
      "z": -5,
      "name": "Rock_Slate"
    },
    {
      "x": 5,
      "y": 7,
      "z": -5,
      "name": "Rock_Slate"
    },
    {
      "x": 5,
      "y": 8,
      "z": -5,
      "name": "Rock_Slate"
    },
    {
      "x": 5,
      "y": 9,
      "z": -5,
      "name": "Rock_Slate"
    },
    {
      "x": 5,
      "y": 10,
      "z": -5,
      "name": "Soil_Grass_Burnt"
    },
    {
      "x": 5,
      "y": 11,
      "z": -5,
      "name": "Plant_Grass_Gnarled_Tall"
    },
    {
      "x": 5,
      "y": 12,
      "z": -5,
      "name": "Plant_Grass_Gnarled_Tall",
      "filler": 1024
    },
    {
      "x": 5,
      "y": 1,
      "z": -4,
      "name": "Rock_Slate"
    },
    {
      "x": 5,
      "y": 2,
      "z": -4,
      "name": "Rock_Slate"
    },
    {
      "x": 5,
      "y": 3,
      "z": -4,
      "name": "Rock_Slate"
    },
    {
      "x": 5,
      "y": 4,
      "z": -4,
      "name": "Rock_Slate"
    },
    {
      "x": 5,
      "y": 5,
      "z": -4,
      "name": "Rock_Slate"
    },
    {
      "x": 5,
      "y": 6,
      "z": -4,
      "name": "Rock_Slate"
    },
    {
      "x": 5,
      "y": 7,
      "z": -4,
      "name": "Rock_Slate"
    },
    {
      "x": 5,
      "y": 8,
      "z": -4,
      "name": "Rock_Slate"
    },
    {
      "x": 5,
      "y": 9,
      "z": -4,
      "name": "Rock_Slate"
    },
    {
      "x": 5,
      "y": 10,
      "z": -4,
      "name": "Rock_Slate"
    },
    {
      "x": 5,
      "y": 1,
      "z": -3,
      "name": "Rock_Slate"
    },
    {
      "x": 5,
      "y": 2,
      "z": -3,
      "name": "Rock_Slate"
    },
    {
      "x": 5,
      "y": 3,
      "z": -3,
      "name": "Rock_Slate"
    },
    {
      "x": 5,
      "y": 4,
      "z": -3,
      "name": "Rock_Slate"
    },
    {
      "x": 5,
      "y": 5,
      "z": -3,
      "name": "Rock_Slate"
    },
    {
      "x": 5,
      "y": 6,
      "z": -3,
      "name": "Rock_Slate"
    },
    {
      "x": 5,
      "y": 7,
      "z": -3,
      "name": "Rock_Slate"
    },
    {
      "x": 5,
      "y": 8,
      "z": -3,
      "name": "Rock_Slate"
    },
    {
      "x": 5,
      "y": 9,
      "z": -3,
      "name": "Rock_Slate"
    },
    {
      "x": 5,
      "y": 10,
      "z": -3,
      "name": "Rock_Slate"
    },
    {
      "x": 5,
      "y": 11,
      "z": -3,
      "name": "Rock_Slate"
    },
    {
      "x": 5,
      "y": 1,
      "z": -2,
      "name": "Rock_Slate"
    },
    {
      "x": 5,
      "y": 2,
      "z": -2,
      "name": "Rock_Slate"
    },
    {
      "x": 5,
      "y": 3,
      "z": -2,
      "name": "Rock_Slate"
    },
    {
      "x": 5,
      "y": 4,
      "z": -2,
      "name": "Rock_Slate"
    },
    {
      "x": 5,
      "y": 5,
      "z": -2,
      "name": "Rock_Slate"
    },
    {
      "x": 5,
      "y": 6,
      "z": -2,
      "name": "Rock_Slate"
    },
    {
      "x": 5,
      "y": 7,
      "z": -2,
      "name": "Rock_Slate"
    },
    {
      "x": 5,
      "y": 8,
      "z": -2,
      "name": "Rock_Slate"
    },
    {
      "x": 5,
      "y": 9,
      "z": -2,
      "name": "Rock_Slate"
    },
    {
      "x": 5,
      "y": 10,
      "z": -2,
      "name": "Rock_Slate"
    },
    {
      "x": 5,
      "y": 11,
      "z": -2,
      "name": "Rock_Slate"
    },
    {
      "x": 5,
      "y": 2,
      "z": -1,
      "name": "Rock_Slate"
    },
    {
      "x": 5,
      "y": 3,
      "z": -1,
      "name": "Rock_Slate"
    },
    {
      "x": 5,
      "y": 4,
      "z": -1,
      "name": "Rock_Slate"
    },
    {
      "x": 5,
      "y": 5,
      "z": -1,
      "name": "Rock_Slate"
    },
    {
      "x": 5,
      "y": 6,
      "z": -1,
      "name": "Rock_Slate"
    },
    {
      "x": 5,
      "y": 7,
      "z": -1,
      "name": "Rock_Slate"
    },
    {
      "x": 5,
      "y": 8,
      "z": -1,
      "name": "Rock_Slate"
    },
    {
      "x": 5,
      "y": 9,
      "z": -1,
      "name": "Rock_Slate"
    },
    {
      "x": 5,
      "y": 10,
      "z": -1,
      "name": "Rock_Slate"
    },
    {
      "x": 5,
      "y": 11,
      "z": -1,
      "name": "Rock_Slate"
    },
    {
      "x": 5,
      "y": 3,
      "z": 0,
      "name": "Rock_Slate"
    },
    {
      "x": 5,
      "y": 4,
      "z": 0,
      "name": "Rock_Slate"
    },
    {
      "x": 5,
      "y": 5,
      "z": 0,
      "name": "Rock_Slate"
    },
    {
      "x": 5,
      "y": 6,
      "z": 0,
      "name": "Rock_Slate"
    },
    {
      "x": 5,
      "y": 7,
      "z": 0,
      "name": "Rock_Slate"
    },
    {
      "x": 5,
      "y": 8,
      "z": 0,
      "name": "Rock_Slate"
    },
    {
      "x": 5,
      "y": 9,
      "z": 0,
      "name": "Rock_Slate"
    },
    {
      "x": 5,
      "y": 10,
      "z": 0,
      "name": "Rock_Slate"
    },
    {
      "x": 5,
      "y": 11,
      "z": 0,
      "name": "Rock_Slate"
    },
    {
      "x": 5,
      "y": 5,
      "z": 1,
      "name": "Rock_Slate"
    },
    {
      "x": 5,
      "y": 6,
      "z": 1,
      "name": "Rock_Slate"
    },
    {
      "x": 5,
      "y": 7,
      "z": 1,
      "name": "Rock_Slate"
    },
    {
      "x": 5,
      "y": 8,
      "z": 1,
      "name": "Soil_Dirt_Burnt"
    },
    {
      "x": 5,
      "y": 9,
      "z": 1,
      "name": "Soil_Grass_Burnt"
    },
    {
      "x": 5,
      "y": 10,
      "z": 1,
      "name": "Plant_Grass_Gnarled_Tall"
    },
    {
      "x": 5,
      "y": 11,
      "z": 1,
      "name": "Plant_Grass_Gnarled_Tall",
      "filler": 1024
    },
    {
      "x": 6,
      "y": 7,
      "z": -5,
      "name": "Soil_Dirt_Burnt"
    },
    {
      "x": 6,
      "y": 8,
      "z": -5,
      "name": "Soil_Dirt_Burnt"
    },
    {
      "x": 6,
      "y": 9,
      "z": -5,
      "name": "Soil_Grass_Burnt"
    },
    {
      "x": 6,
      "y": 10,
      "z": -5,
      "name": "Plant_Grass_Gnarled"
    },
    {
      "x": 6,
      "y": 4,
      "z": -4,
      "name": "Rock_Slate"
    },
    {
      "x": 6,
      "y": 5,
      "z": -4,
      "name": "Rock_Slate"
    },
    {
      "x": 6,
      "y": 6,
      "z": -4,
      "name": "Rock_Slate"
    },
    {
      "x": 6,
      "y": 7,
      "z": -4,
      "name": "Rock_Slate"
    },
    {
      "x": 6,
      "y": 8,
      "z": -4,
      "name": "Rock_Slate"
    },
    {
      "x": 6,
      "y": 9,
      "z": -4,
      "name": "Rock_Slate"
    },
    {
      "x": 6,
      "y": 10,
      "z": -4,
      "name": "Rock_Slate"
    },
    {
      "x": 6,
      "y": 3,
      "z": -3,
      "name": "Rock_Slate"
    },
    {
      "x": 6,
      "y": 4,
      "z": -3,
      "name": "Rock_Slate"
    },
    {
      "x": 6,
      "y": 5,
      "z": -3,
      "name": "Rock_Slate"
    },
    {
      "x": 6,
      "y": 6,
      "z": -3,
      "name": "Rock_Slate"
    },
    {
      "x": 6,
      "y": 7,
      "z": -3,
      "name": "Rock_Slate"
    },
    {
      "x": 6,
      "y": 8,
      "z": -3,
      "name": "Rock_Slate"
    },
    {
      "x": 6,
      "y": 9,
      "z": -3,
      "name": "Rock_Slate"
    },
    {
      "x": 6,
      "y": 10,
      "z": -3,
      "name": "Rock_Slate"
    },
    {
      "x": 6,
      "y": 11,
      "z": -3,
      "name": "Rubble_Slate"
    },
    {
      "x": 6,
      "y": 3,
      "z": -2,
      "name": "Rock_Slate"
    },
    {
      "x": 6,
      "y": 4,
      "z": -2,
      "name": "Rock_Slate"
    },
    {
      "x": 6,
      "y": 5,
      "z": -2,
      "name": "Rock_Slate"
    },
    {
      "x": 6,
      "y": 6,
      "z": -2,
      "name": "Rock_Slate"
    },
    {
      "x": 6,
      "y": 7,
      "z": -2,
      "name": "Rock_Slate"
    },
    {
      "x": 6,
      "y": 8,
      "z": -2,
      "name": "Rock_Slate"
    },
    {
      "x": 6,
      "y": 9,
      "z": -2,
      "name": "Rock_Slate"
    },
    {
      "x": 6,
      "y": 10,
      "z": -2,
      "name": "Rock_Slate"
    },
    {
      "x": 6,
      "y": 5,
      "z": -1,
      "name": "Rock_Slate"
    },
    {
      "x": 6,
      "y": 6,
      "z": -1,
      "name": "Rock_Slate"
    },
    {
      "x": 6,
      "y": 7,
      "z": -1,
      "name": "Rock_Slate"
    },
    {
      "x": 6,
      "y": 8,
      "z": -1,
      "name": "Rock_Slate"
    },
    {
      "x": 6,
      "y": 9,
      "z": -1,
      "name": "Plant_Bush_Dead_Tall"
    }
  ]
}