{
  "version": 8,
  "blockIdVersion": 8,
  "anchorX": 0,
  "anchorY": 0,
  "anchorZ": 0,
  "blocks": [
    {
      "x": -21,
      "y": 9,
      "z": 0,
      "name": "Rock_Stone"
    },
    {
      "x": -21,
      "y": 10,
      "z": 0,
      "name": "Rock_Stone"
    },
    {
      "x": -21,
      "y": 11,
      "z": 0,
      "name": "Rock_Chalk"
    },
    {
      "x": -21,
      "y": 12,
      "z": 0,
      "name": "Rock_Chalk"
    },
    {
      "x": -21,
      "y": 10,
      "z": 1,
      "name": "Rock_Stone"
    },
    {
      "x": -21,
      "y": 11,
      "z": 1,
      "name": "Rock_Stone"
    },
    {
      "x": -21,
      "y": 12,
      "z": 1,
      "name": "Rock_Stone"
    },
    {
      "x": -21,
      "y": 12,
      "z": 2,
      "name": "Rock_Stone"
    },
    {
      "x": -21,
      "y": 13,
      "z": 2,
      "name": "Rock_Stone"
    },
    {
      "x": -20,
      "y": 9,
      "z": -2,
      "name": "Rock_Stone"
    },
    {
      "x": -20,
      "y": 10,
      "z": -2,
      "name": "Rock_Stone"
    },
    {
      "x": -20,
      "y": 11,
      "z": -2,
      "name": "Rock_Chalk"
    },
    {
      "x": -20,
      "y": 12,
      "z": -2,
      "name": "Rock_Chalk"
    },
    {
      "x": -20,
      "y": 9,
      "z": -1,
      "name": "Rock_Stone"
    },
    {
      "x": -20,
      "y": 10,
      "z": -1,
      "name": "Rock_Stone"
    },
    {
      "x": -20,
      "y": 11,
      "z": -1,
      "name": "Rock_Stone"
    },
    {
      "x": -20,
      "y": 12,
      "z": -1,
      "name": "Rock_Chalk"
    },
    {
      "x": -20,
      "y": 13,
      "z": -1,
      "name": "Rock_Chalk"
    },
    {
      "x": -20,
      "y": 11,
      "z": 0,
      "name": "Rock_Stone"
    },
    {
      "x": -20,
      "y": 12,
      "z": 0,
      "name": "Rock_Stone"
    },
    {
      "x": -20,
      "y": 13,
      "z": 0,
      "name": "Rock_Stone"
    },
    {
      "x": -20,
      "y": 14,
      "z": 0,
      "name": "Rock_Calcite"
    },
    {
      "x": -20,
      "y": 13,
      "z": 1,
      "name": "Rock_Stone"
    },
    {
      "x": -20,
      "y": 14,
      "z": 1,
      "name": "Rock_Calcite"
    },
    {
      "x": -19,
      "y": 9,
      "z": -4,
      "name": "Rock_Stone"
    },
    {
      "x": -19,
      "y": 10,
      "z": -4,
      "name": "Rock_Stone"
    },
    {
      "x": -19,
      "y": 11,
      "z": -4,
      "name": "Rock_Stone"
    },
    {
      "x": -19,
      "y": 12,
      "z": -4,
      "name": "Rock_Chalk"
    },
    {
      "x": -19,
      "y": 10,
      "z": -3,
      "name": "Rock_Stone"
    },
    {
      "x": -19,
      "y": 11,
      "z": -3,
      "name": "Rock_Stone"
    },
    {
      "x": -19,
      "y": 12,
      "z": -3,
      "name": "Rock_Chalk"
    },
    {
      "x": -19,
      "y": 13,
      "z": -3,
      "name": "Rock_Chalk"
    },
    {
      "x": -19,
      "y": 11,
      "z": -2,
      "name": "Rock_Stone"
    },
    {
      "x": -19,
      "y": 12,
      "z": -2,
      "name": "Rock_Stone"
    },
    {
      "x": -19,
      "y": 13,
      "z": -2,
      "name": "Rock_Chalk"
    },
    {
      "x": -19,
      "y": 14,
      "z": -2,
      "name": "Rock_Calcite"
    },
    {
      "x": -19,
      "y": 12,
      "z": -1,
      "name": "Rock_Stone"
    },
    {
      "x": -19,
      "y": 13,
      "z": -1,
      "name": "Rock_Chalk"
    },
    {
      "x": -19,
      "y": 14,
      "z": -1,
      "name": "Rock_Calcite"
    },
    {
      "x": -19,
      "y": 15,
      "z": -1,
      "name": "Rock_Marble"
    },
    {
      "x": -19,
      "y": 14,
      "z": 0,
      "name": "Rock_Stone"
    },
    {
      "x": -19,
      "y": 15,
      "z": 0,
      "name": "Rock_Marble"
    },
    {
      "x": -19,
      "y": 17,
      "z": 6,
      "name": "Rock_Stone"
    },
    {
      "x": -19,
      "y": 18,
      "z": 6,
      "name": "Rock_Marble"
    },
    {
      "x": -19,
      "y": 17,
      "z": 7,
      "name": "Rock_Stone"
    },
    {
      "x": -19,
      "y": 18,
      "z": 7,
      "name": "Rock_Marble"
    },
    {
      "x": -19,
      "y": 16,
      "z": 8,
      "name": "Rock_Stone"
    },
    {
      "x": -19,
      "y": 17,
      "z": 8,
      "name": "Rock_Stone"
    },
    {
      "x": -19,
      "y": 15,
      "z": 9,
      "name": "Rock_Stone"
    },
    {
      "x": -19,
      "y": 16,
      "z": 9,
      "name": "Rock_Stone"
    },
    {
      "x": -18,
      "y": 10,
      "z": -5,
      "name": "Rock_Stone"
    },
    {
      "x": -18,
      "y": 11,
      "z": -5,
      "name": "Rock_Stone"
    },
    {
      "x": -18,
      "y": 12,
      "z": -5,
      "name": "Rock_Stone"
    },
    {
      "x": -18,
      "y": 18,
      "z": 5,
      "name": "Rock_Stone"
    },
    {
      "x": -18,
      "y": 19,
      "z": 5,
      "name": "Rock_Marble"
    },
    {
      "x": -18,
      "y": 16,
      "z": 6,
      "name": "Rock_Stone"
    },
    {
      "x": -18,
      "y": 17,
      "z": 6,
      "name": "Rock_Stone"
    },
    {
      "x": -18,
      "y": 18,
      "z": 6,
      "name": "Rock_Marble"
    },
    {
      "x": -18,
      "y": 19,
      "z": 6,
      "name": "Rock_Marble"
    },
    {
      "x": -18,
      "y": 16,
      "z": 7,
      "name": "Rock_Stone"
    },
    {
      "x": -18,
      "y": 17,
      "z": 7,
      "name": "Rock_Marble"
    },
    {
      "x": -18,
      "y": 18,
      "z": 7,
      "name": "Rock_Marble"
    },
    {
      "x": -18,
      "y": 19,
      "z": 7,
      "name": "Rock_Marble"
    },
    {
      "x": -18,
      "y": 15,
      "z": 8,
      "name": "Rock_Stone"
    },
    {
      "x": -18,
      "y": 16,
      "z": 8,
      "name": "Rock_Marble"
    },
    {
      "x": -18,
      "y": 17,
      "z": 8,
      "name": "Rock_Marble"
    },
    {
      "x": -18,
      "y": 18,
      "z": 8,
      "name": "Rock_Marble"
    },
    {
      "x": -18,
      "y": 14,
      "z": 9,
      "name": "Rock_Stone"
    },
    {
      "x": -18,
      "y": 15,
      "z": 9,
      "name": "Rock_Marble"
    },
    {
      "x": -18,
      "y": 16,
      "z": 9,
      "name": "Rock_Marble"
    },
    {
      "x": -18,
      "y": 17,
      "z": 9,
      "name": "Rock_Marble"
    },
    {
      "x": -18,
      "y": 13,
      "z": 10,
      "name": "Rock_Stone"
    },
    {
      "x": -18,
      "y": 14,
      "z": 10,
      "name": "Rock_Marble"
    },
    {
      "x": -18,
      "y": 15,
      "z": 10,
      "name": "Rock_Stone"
    },
    {
      "x": -18,
      "y": 16,
      "z": 10,
      "name": "Rock_Marble"
    },
    {
      "x": -18,
      "y": 14,
      "z": 11,
      "name": "Rock_Stone"
    },
    {
      "x": -18,
      "y": 15,
      "z": 11,
      "name": "Rock_Stone"
    },
    {
      "x": -17,
      "y": 9,
      "z": -11,
      "name": "Rock_Stone"
    },
    {
      "x": -17,
      "y": 10,
      "z": -11,
      "name": "Rock_Stone"
    },
    {
      "x": -17,
      "y": 11,
      "z": -11,
      "name": "Rock_Stone"
    },
    {
      "x": -17,
      "y": 12,
      "z": -11,
      "name": "Rock_Stone"
    },
    {
      "x": -17,
      "y": 10,
      "z": -10,
      "name": "Rock_Stone"
    },
    {
      "x": -17,
      "y": 11,
      "z": -10,
      "name": "Rock_Stone"
    },
    {
      "x": -17,
      "y": 12,
      "z": -10,
      "name": "Rock_Stone"
    },
    {
      "x": -17,
      "y": 10,
      "z": -9,
      "name": "Rock_Stone"
    },
    {
      "x": -17,
      "y": 11,
      "z": -9,
      "name": "Rock_Stone"
    },
    {
      "x": -17,
      "y": 12,
      "z": -9,
      "name": "Rock_Stone"
    },
    {
      "x": -17,
      "y": 10,
      "z": -8,
      "name": "Rock_Stone"
    },
    {
      "x": -17,
      "y": 11,
      "z": -8,
      "name": "Rock_Stone"
    },
    {
      "x": -17,
      "y": 12,
      "z": -8,
      "name": "Rock_Stone"
    },
    {
      "x": -17,
      "y": 13,
      "z": -8,
      "name": "Rock_Stone"
    },
    {
      "x": -17,
      "y": 10,
      "z": -7,
      "name": "Rock_Stone"
    },
    {
      "x": -17,
      "y": 11,
      "z": -7,
      "name": "Rock_Stone"
    },
    {
      "x": -17,
      "y": 12,
      "z": -7,
      "name": "Rock_Stone"
    },
    {
      "x": -17,
      "y": 13,
      "z": -7,
      "name": "Plant_Moss_Block_Green"
    },
    {
      "x": -17,
      "y": 14,
      "z": -7,
      "name": "Plant_Moss_Rug_Green"
    },
    {
      "x": -17,
      "y": 13,
      "z": -6,
      "name": "Rock_Stone"
    },
    {
      "x": -17,
      "y": 14,
      "z": -6,
      "name": "Plant_Moss_Rug_Green"
    },
    {
      "x": -17,
      "y": 19,
      "z": 4,
      "name": "Rock_Stone"
    },
    {
      "x": -17,
      "y": 20,
      "z": 4,
      "name": "Rock_Marble"
    },
    {
      "x": -17,
      "y": 21,
      "z": 4,
      "name": "Plant_Moss_Rug_Green"
    },
    {
      "x": -17,
      "y": 17,
      "z": 5,
      "name": "Rock_Stone"
    },
    {
      "x": -17,
      "y": 18,
      "z": 5,
      "name": "Rock_Stone"
    },
    {
      "x": -17,
      "y": 19,
      "z": 5,
      "name": "Rock_Marble"
    },
    {
      "x": -17,
      "y": 20,
      "z": 5,
      "name": "Rock_Marble"
    },
    {
      "x": -17,
      "y": 21,
      "z": 5,
      "name": "Plant_Moss_Rug_Green"
    },
    {
      "x": -17,
      "y": 17,
      "z": 6,
      "name": "Rock_Stone"
    },
    {
      "x": -17,
      "y": 18,
      "z": 6,
      "name": "Rock_Marble"
    },
    {
      "x": -17,
      "y": 19,
      "z": 6,
      "name": "Rock_Marble"
    },
    {
      "x": -17,
      "y": 20,
      "z": 6,
      "name": "Rock_Marble"
    },
    {
      "x": -17,
      "y": 17,
      "z": 7,
      "name": "Rock_Stone"
    },
    {
      "x": -17,
      "y": 18,
      "z": 7,
      "name": "Rock_Marble"
    },
    {
      "x": -17,
      "y": 19,
      "z": 7,
      "name": "Rock_Marble"
    },
    {
      "x": -17,
      "y": 20,
      "z": 7,
      "name": "Rock_Marble"
    },
    {
      "x": -17,
      "y": 16,
      "z": 8,
      "name": "Rock_Stone"
    },
    {
      "x": -17,
      "y": 17,
      "z": 8,
      "name": "Rock_Marble"
    },
    {
      "x": -17,
      "y": 18,
      "z": 8,
      "name": "Rock_Marble"
    },
    {
      "x": -17,
      "y": 19,
      "z": 8,
      "name": "Rock_Marble"
    },
    {
      "x": -17,
      "y": 15,
      "z": 9,
      "name": "Rock_Stone"
    },
    {
      "x": -17,
      "y": 16,
      "z": 9,
      "name": "Rock_Marble"
    },
    {
      "x": -17,
      "y": 17,
      "z": 9,
      "name": "Rock_Marble"
    },
    {
      "x": -17,
      "y": 18,
      "z": 9,
      "name": "Rock_Marble"
    },
    {
      "x": -17,
      "y": 14,
      "z": 10,
      "name": "Rock_Stone"
    },
    {
      "x": -17,
      "y": 15,
      "z": 10,
      "name": "Rock_Marble"
    },
    {
      "x": -17,
      "y": 16,
      "z": 10,
      "name": "Rock_Marble"
    },
    {
      "x": -17,
      "y": 17,
      "z": 10,
      "name": "Rock_Marble"
    },
    {
      "x": -17,
      "y": 13,
      "z": 11,
      "name": "Rock_Stone"
    },
    {
      "x": -17,
      "y": 14,
      "z": 11,
      "name": "Rock_Stone"
    },
    {
      "x": -17,
      "y": 15,
      "z": 11,
      "name": "Rock_Marble"
    },
    {
      "x": -17,
      "y": 16,
      "z": 11,
      "name": "Rock_Marble"
    },
    {
      "x": -17,
      "y": 15,
      "z": 12,
      "name": "Rock_Stone"
    },
    {
      "x": -16,
      "y": 10,
      "z": -14,
      "name": "Rock_Stone"
    },
    {
      "x": -16,
      "y": 11,
      "z": -14,
      "name": "Rock_Stone"
    },
    {
      "x": -16,
      "y": 12,
      "z": -14,
      "name": "Rock_Marble"
    },
    {
      "x": -16,
      "y": 13,
      "z": -14,
      "name": "Rock_Marble"
    },
    {
      "x": -16,
      "y": 10,
      "z": -13,
      "name": "Rock_Stone"
    },
    {
      "x": -16,
      "y": 11,
      "z": -13,
      "name": "Rock_Stone"
    },
    {
      "x": -16,
      "y": 12,
      "z": -13,
      "name": "Rock_Stone"
    },
    {
      "x": -16,
      "y": 13,
      "z": -13,
      "name": "Rock_Marble"
    },
    {
      "x": -16,
      "y": 11,
      "z": -12,
      "name": "Rock_Stone"
    },
    {
      "x": -16,
      "y": 12,
      "z": -12,
      "name": "Rock_Stone"
    },
    {
      "x": -16,
      "y": 13,
      "z": -12,
      "name": "Rock_Marble"
    },
    {
      "x": -16,
      "y": 14,
      "z": -12,
      "name": "Rock_Marble"
    },
    {
      "x": -16,
      "y": 12,
      "z": -11,
      "name": "Rock_Stone"
    },
    {
      "x": -16,
      "y": 13,
      "z": -11,
      "name": "Rock_Marble"
    },
    {
      "x": -16,
      "y": 14,
      "z": -11,
      "name": "Rock_Marble"
    },
    {
      "x": -16,
      "y": 12,
      "z": -10,
      "name": "Rock_Stone"
    },
    {
      "x": -16,
      "y": 13,
      "z": -10,
      "name": "Rock_Marble"
    },
    {
      "x": -16,
      "y": 14,
      "z": -10,
      "name": "Rock_Marble"
    },
    {
      "x": -16,
      "y": 12,
      "z": -9,
      "name": "Rock_Stone"
    },
    {
      "x": -16,
      "y": 13,
      "z": -9,
      "name": "Rock_Marble"
    },
    {
      "x": -16,
      "y": 14,
      "z": -9,
      "name": "Rock_Marble"
    },
    {
      "x": -16,
      "y": 15,
      "z": -9,
      "name": "Rock_Marble"
    },
    {
      "x": -16,
      "y": 12,
      "z": -8,
      "name": "Rock_Stone"
    },
    {
      "x": -16,
      "y": 13,
      "z": -8,
      "name": "Plant_Moss_Block_Green"
    },
    {
      "x": -16,
      "y": 14,
      "z": -8,
      "name": "Plant_Moss_Block_Green"
    },
    {
      "x": -16,
      "y": 15,
      "z": -8,
      "name": "Plant_Moss_Block_Green"
    },
    {
      "x": -16,
      "y": 14,
      "z": -7,
      "name": "Plant_Moss_Block_Green"
    },
    {
      "x": -16,
      "y": 15,
      "z": -7,
      "name": "Plant_Moss_Block_Green"
    },
    {
      "x": -16,
      "y": 20,
      "z": 3,
      "name": "Plant_Moss_Block_Green"
    },
    {
      "x": -16,
      "y": 21,
      "z": 3,
      "name": "Plant_Moss_Block_Green"
    },
    {
      "x": -16,
      "y": 22,
      "z": 3,
      "name": "Plant_Moss_Rug_Green"
    },
    {
      "x": -16,
      "y": 18,
      "z": 4,
      "name": "Rock_Stone"
    },
    {
      "x": -16,
      "y": 19,
      "z": 4,
      "name": "Plant_Moss_Block_Green"
    },
    {
      "x": -16,
      "y": 20,
      "z": 4,
      "name": "Plant_Moss_Block_Green"
    },
    {
      "x": -16,
      "y": 21,
      "z": 4,
      "name": "Plant_Moss_Block_Green"
    },
    {
      "x": -16,
      "y": 22,
      "z": 4,
      "name": "Plant_Moss_Rug_Green"
    },
    {
      "x": -16,
      "y": 18,
      "z": 5,
      "name": "Rock_Stone"
    },
    {
      "x": -16,
      "y": 19,
      "z": 5,
      "name": "Rock_Marble"
    },
    {
      "x": -16,
      "y": 20,
      "z": 5,
      "name": "Rock_Marble"
    },
    {
      "x": -16,
      "y": 21,
      "z": 5,
      "name": "Rock_Marble"
    },
    {
      "x": -16,
      "y": 22,
      "z": 5,
      "name": "Plant_Moss_Rug_Green"
    },
    {
      "x": -16,
      "y": 18,
      "z": 6,
      "name": "Rock_Stone"
    },
    {
      "x": -16,
      "y": 19,
      "z": 6,
      "name": "Rock_Marble"
    },
    {
      "x": -16,
      "y": 20,
      "z": 6,
      "name": "Rock_Marble"
    },
    {
      "x": -16,
      "y": 21,
      "z": 6,
      "name": "Rock_Marble"
    },
    {
      "x": -16,
      "y": 22,
      "z": 6,
      "name": "Plant_Moss_Rug_Green"
    },
    {
      "x": -16,
      "y": 18,
      "z": 7,
      "name": "Rock_Stone"
    },
    {
      "x": -16,
      "y": 19,
      "z": 7,
      "name": "Rock_Marble"
    },
    {
      "x": -16,
      "y": 20,
      "z": 7,
      "name": "Rock_Marble"
    },
    {
      "x": -16,
      "y": 21,
      "z": 7,
      "name": "Rock_Marble"
    },
    {
      "x": -16,
      "y": 17,
      "z": 8,
      "name": "Rock_Stone"
    },
    {
      "x": -16,
      "y": 18,
      "z": 8,
      "name": "Rock_Marble"
    },
    {
      "x": -16,
      "y": 19,
      "z": 8,
      "name": "Rock_Marble"
    },
    {
      "x": -16,
      "y": 20,
      "z": 8,
      "name": "Rock_Marble"
    },
    {
      "x": -16,
      "y": 16,
      "z": 9,
      "name": "Rock_Stone"
    },
    {
      "x": -16,
      "y": 17,
      "z": 9,
      "name": "Rock_Marble"
    },
    {
      "x": -16,
      "y": 18,
      "z": 9,
      "name": "Rock_Marble"
    },
    {
      "x": -16,
      "y": 19,
      "z": 9,
      "name": "Rock_Marble"
    },
    {
      "x": -16,
      "y": 15,
      "z": 10,
      "name": "Rock_Stone"
    },
    {
      "x": -16,
      "y": 16,
      "z": 10,
      "name": "Rock_Marble"
    },
    {
      "x": -16,
      "y": 17,
      "z": 10,
      "name": "Rock_Marble"
    },
    {
      "x": -16,
      "y": 18,
      "z": 10,
      "name": "Rock_Marble"
    },
    {
      "x": -16,
      "y": 14,
      "z": 11,
      "name": "Rock_Stone"
    },
    {
      "x": -16,
      "y": 15,
      "z": 11,
      "name": "Rock_Marble"
    },
    {
      "x": -16,
      "y": 16,
      "z": 11,
      "name": "Rock_Marble"
    },
    {
      "x": -16,
      "y": 17,
      "z": 11,
      "name": "Rock_Marble"
    },
    {
      "x": -16,
      "y": 14,
      "z": 12,
      "name": "Rock_Stone"
    },
    {
      "x": -16,
      "y": 15,
      "z": 12,
      "name": "Rock_Marble"
    },
    {
      "x": -16,
      "y": 16,
      "z": 12,
      "name": "Rock_Marble"
    },
    {
      "x": -16,
      "y": 15,
      "z": 13,
      "name": "Rock_Stone"
    },
    {
      "x": -16,
      "y": 16,
      "z": 13,
      "name": "Rock_Marble"
    },
    {
      "x": -15,
      "y": 9,
      "z": -18,
      "name": "Rock_Stone"
    },
    {
      "x": -15,
      "y": 10,
      "z": -18,
      "name": "Rock_Stone"
    },
    {
      "x": -15,
      "y": 11,
      "z": -18,
      "name": "Rock_Stone"
    },
    {
      "x": -15,
      "y": 12,
      "z": -18,
      "name": "Rock_Marble"
    },
    {
      "x": -15,
      "y": 10,
      "z": -17,
      "name": "Rock_Stone"
    },
    {
      "x": -15,
      "y": 11,
      "z": -17,
      "name": "Rock_Stone"
    },
    {
      "x": -15,
      "y": 12,
      "z": -17,
      "name": "Rock_Marble"
    },
    {
      "x": -15,
      "y": 13,
      "z": -17,
      "name": "Rock_Marble"
    },
    {
      "x": -15,
      "y": 10,
      "z": -16,
      "name": "Rock_Stone"
    },
    {
      "x": -15,
      "y": 11,
      "z": -16,
      "name": "Rock_Stone"
    },
    {
      "x": -15,
      "y": 12,
      "z": -16,
      "name": "Rock_Stone"
    },
    {
      "x": -15,
      "y": 13,
      "z": -16,
      "name": "Rock_Marble"
    },
    {
      "x": -15,
      "y": 11,
      "z": -15,
      "name": "Rock_Stone"
    },
    {
      "x": -15,
      "y": 12,
      "z": -15,
      "name": "Rock_Stone"
    },
    {
      "x": -15,
      "y": 13,
      "z": -15,
      "name": "Rock_Marble"
    },
    {
      "x": -15,
      "y": 14,
      "z": -15,
      "name": "Rock_Marble"
    },
    {
      "x": -15,
      "y": 12,
      "z": -14,
      "name": "Rock_Stone"
    },
    {
      "x": -15,
      "y": 13,
      "z": -14,
      "name": "Rock_Stone"
    },
    {
      "x": -15,
      "y": 14,
      "z": -14,
      "name": "Rock_Marble"
    },
    {
      "x": -15,
      "y": 15,
      "z": -14,
      "name": "Rock_Marble"
    },
    {
      "x": -15,
      "y": 13,
      "z": -13,
      "name": "Rock_Stone"
    },
    {
      "x": -15,
      "y": 14,
      "z": -13,
      "name": "Rock_Marble"
    },
    {
      "x": -15,
      "y": 15,
      "z": -13,
      "name": "Rock_Marble"
    },
    {
      "x": -15,
      "y": 16,
      "z": -13,
      "name": "Rock_Marble"
    },
    {
      "x": -15,
      "y": 13,
      "z": -12,
      "name": "Rock_Stone"
    },
    {
      "x": -15,
      "y": 14,
      "z": -12,
      "name": "Rock_Stone"
    },
    {
      "x": -15,
      "y": 15,
      "z": -12,
      "name": "Rock_Marble"
    },
    {
      "x": -15,
      "y": 16,
      "z": -12,
      "name": "Rock_Marble"
    },
    {
      "x": -15,
      "y": 13,
      "z": -11,
      "name": "Rock_Stone"
    },
    {
      "x": -15,
      "y": 14,
      "z": -11,
      "name": "Rock_Stone"
    },
    {
      "x": -15,
      "y": 15,
      "z": -11,
      "name": "Rock_Marble"
    },
    {
      "x": -15,
      "y": 16,
      "z": -11,
      "name": "Rock_Marble"
    },
    {
      "x": -15,
      "y": 13,
      "z": -10,
      "name": "Rock_Stone"
    },
    {
      "x": -15,
      "y": 14,
      "z": -10,
      "name": "Rock_Stone"
    },
    {
      "x": -15,
      "y": 15,
      "z": -10,
      "name": "Rock_Marble"
    },
    {
      "x": -15,
      "y": 16,
      "z": -10,
      "name": "Rock_Marble"
    },
    {
      "x": -15,
      "y": 13,
      "z": -9,
      "name": "Rock_Stone"
    },
    {
      "x": -15,
      "y": 14,
      "z": -9,
      "name": "Plant_Moss_Block_Green"
    },
    {
      "x": -15,
      "y": 15,
      "z": -9,
      "name": "Plant_Moss_Block_Green"
    },
    {
      "x": -15,
      "y": 16,
      "z": -9,
      "name": "Plant_Moss_Block_Green"
    },
    {
      "x": -15,
      "y": 17,
      "z": -9,
      "name": "Plant_Moss_Block_Green"
    },
    {
      "x": -15,
      "y": 18,
      "z": -9,
      "name": "Plant_Moss_Rug_Green"
    },
    {
      "x": -15,
      "y": 15,
      "z": -8,
      "name": "Plant_Moss_Block_Green"
    },
    {
      "x": -15,
      "y": 16,
      "z": -8,
      "name": "Plant_Moss_Block_Green"
    },
    {
      "x": -15,
      "y": 17,
      "z": -4,
      "name": "Rock_Stone"
    },
    {
      "x": -15,
      "y": 18,
      "z": -4,
      "name": "Rock_Marble"
    },
    {
      "x": -15,
      "y": 18,
      "z": 3,
      "name": "Plant_Moss_Block_Green"
    },
    {
      "x": -15,
      "y": 19,
      "z": 3,
      "name": "Plant_Moss_Block_Green"
    },
    {
      "x": -15,
      "y": 20,
      "z": 3,
      "name": "Plant_Moss_Block_Green"
    },
    {
      "x": -15,
      "y": 21,
      "z": 3,
      "name": "Plant_Moss_Block_Green"
    },
    {
      "x": -15,
      "y": 22,
      "z": 3,
      "name": "Plant_Moss_Rug_Green"
    },
    {
      "x": -15,
      "y": 19,
      "z": 4,
      "name": "Plant_Moss_Block_Green"
    },
    {
      "x": -15,
      "y": 20,
      "z": 4,
      "name": "Plant_Moss_Block_Green"
    },
    {
      "x": -15,
      "y": 21,
      "z": 4,
      "name": "Plant_Moss_Block_Green"
    },
    {
      "x": -15,
      "y": 22,
      "z": 4,
      "name": "Plant_Moss_Block_Green"
    },
    {
      "x": -15,
      "y": 19,
      "z": 5,
      "name": "Rock_Stone"
    },
    {
      "x": -15,
      "y": 20,
      "z": 5,
      "name": "Rock_Marble"
    },
    {
      "x": -15,
      "y": 21,
      "z": 5,
      "name": "Rock_Marble"
    },
    {
      "x": -15,
      "y": 22,
      "z": 5,
      "name": "Rock_Marble"
    },
    {
      "x": -15,
      "y": 19,
      "z": 6,
      "name": "Rock_Stone"
    },
    {
      "x": -15,
      "y": 20,
      "z": 6,
      "name": "Rock_Marble"
    },
    {
      "x": -15,
      "y": 21,
      "z": 6,
      "name": "Rock_Marble"
    },
    {
      "x": -15,
      "y": 22,
      "z": 6,
      "name": "Rock_Marble"
    },
    {
      "x": -15,
      "y": 18,
      "z": 7,
      "name": "Rock_Stone"
    },
    {
      "x": -15,
      "y": 19,
      "z": 7,
      "name": "Rock_Marble"
    },
    {
      "x": -15,
      "y": 20,
      "z": 7,
      "name": "Rock_Marble"
    },
    {
      "x": -15,
      "y": 21,
      "z": 7,
      "name": "Rock_Marble"
    },
    {
      "x": -15,
      "y": 22,
      "z": 7,
      "name": "Rock_Marble"
    },
    {
      "x": -15,
      "y": 18,
      "z": 8,
      "name": "Rock_Stone"
    },
    {
      "x": -15,
      "y": 19,
      "z": 8,
      "name": "Rock_Marble"
    },
    {
      "x": -15,
      "y": 20,
      "z": 8,
      "name": "Rock_Marble"
    },
    {
      "x": -15,
      "y": 21,
      "z": 8,
      "name": "Rock_Marble"
    },
    {
      "x": -15,
      "y": 17,
      "z": 9,
      "name": "Rock_Stone"
    },
    {
      "x": -15,
      "y": 18,
      "z": 9,
      "name": "Rock_Marble"
    },
    {
      "x": -15,
      "y": 19,
      "z": 9,
      "name": "Rock_Marble"
    },
    {
      "x": -15,
      "y": 20,
      "z": 9,
      "name": "Rock_Marble"
    },
    {
      "x": -15,
      "y": 16,
      "z": 10,
      "name": "Rock_Stone"
    },
    {
      "x": -15,
      "y": 17,
      "z": 10,
      "name": "Rock_Marble"
    },
    {
      "x": -15,
      "y": 18,
      "z": 10,
      "name": "Rock_Marble"
    },
    {
      "x": -15,
      "y": 19,
      "z": 10,
      "name": "Rock_Marble"
    },
    {
      "x": -15,
      "y": 15,
      "z": 11,
      "name": "Rock_Stone"
    },
    {
      "x": -15,
      "y": 16,
      "z": 11,
      "name": "Rock_Marble"
    },
    {
      "x": -15,
      "y": 17,
      "z": 11,
      "name": "Rock_Marble"
    },
    {
      "x": -15,
      "y": 18,
      "z": 11,
      "name": "Rock_Marble"
    },
    {
      "x": -15,
      "y": 14,
      "z": 12,
      "name": "Rock_Stone"
    },
    {
      "x": -15,
      "y": 15,
      "z": 12,
      "name": "Rock_Marble"
    },
    {
      "x": -15,
      "y": 16,
      "z": 12,
      "name": "Rock_Marble"
    },
    {
      "x": -15,
      "y": 17,
      "z": 12,
      "name": "Rock_Marble"
    },
    {
      "x": -15,
      "y": 13,
      "z": 13,
      "name": "Rock_Stone"
    },
    {
      "x": -15,
      "y": 14,
      "z": 13,
      "name": "Rock_Stone"
    },
    {
      "x": -15,
      "y": 15,
      "z": 13,
      "name": "Rock_Marble"
    },
    {
      "x": -15,
      "y": 16,
      "z": 13,
      "name": "Rock_Marble"
    },
    {
      "x": -15,
      "y": 14,
      "z": 14,
      "name": "Rock_Stone"
    },
    {
      "x": -15,
      "y": 15,
      "z": 14,
      "name": "Rock_Stone"
    },
    {
      "x": -14,
      "y": 10,
      "z": -19,
      "name": "Rock_Stone"
    },
    {
      "x": -14,
      "y": 11,
      "z": -19,
      "name": "Rock_Stone"
    },
    {
      "x": -14,
      "y": 12,
      "z": -19,
      "name": "Rock_Stone"
    },
    {
      "x": -14,
      "y": 13,
      "z": -19,
      "name": "Rock_Marble"
    },
    {
      "x": -14,
      "y": 11,
      "z": -18,
      "name": "Rock_Stone"
    },
    {
      "x": -14,
      "y": 12,
      "z": -18,
      "name": "Rock_Stone"
    },
    {
      "x": -14,
      "y": 13,
      "z": -18,
      "name": "Rock_Marble"
    },
    {
      "x": -14,
      "y": 14,
      "z": -18,
      "name": "Rock_Marble"
    },
    {
      "x": -14,
      "y": 12,
      "z": -17,
      "name": "Rock_Stone"
    },
    {
      "x": -14,
      "y": 13,
      "z": -17,
      "name": "Rock_Stone"
    },
    {
      "x": -14,
      "y": 14,
      "z": -17,
      "name": "Rock_Marble"
    },
    {
      "x": -14,
      "y": 15,
      "z": -17,
      "name": "Rock_Marble"
    },
    {
      "x": -14,
      "y": 13,
      "z": -16,
      "name": "Rock_Stone"
    },
    {
      "x": -14,
      "y": 14,
      "z": -16,
      "name": "Rock_Marble"
    },
    {
      "x": -14,
      "y": 15,
      "z": -16,
      "name": "Rock_Marble"
    },
    {
      "x": -14,
      "y": 16,
      "z": -16,
      "name": "Rock_Marble"
    },
    {
      "x": -14,
      "y": 13,
      "z": -15,
      "name": "Rock_Stone"
    },
    {
      "x": -14,
      "y": 14,
      "z": -15,
      "name": "Rock_Stone"
    },
    {
      "x": -14,
      "y": 15,
      "z": -15,
      "name": "Rock_Marble"
    },
    {
      "x": -14,
      "y": 16,
      "z": -15,
      "name": "Rock_Marble"
    },
    {
      "x": -14,
      "y": 14,
      "z": -14,
      "name": "Rock_Stone"
    },
    {
      "x": -14,
      "y": 15,
      "z": -14,
      "name": "Rock_Marble"
    },
    {
      "x": -14,
      "y": 16,
      "z": -14,
      "name": "Rock_Marble"
    },
    {
      "x": -14,
      "y": 17,
      "z": -14,
      "name": "Rock_Marble"
    },
    {
      "x": -14,
      "y": 14,
      "z": -13,
      "name": "Rock_Stone"
    },
    {
      "x": -14,
      "y": 15,
      "z": -13,
      "name": "Rock_Marble"
    },
    {
      "x": -14,
      "y": 16,
      "z": -13,
      "name": "Rock_Marble"
    },
    {
      "x": -14,
      "y": 17,
      "z": -13,
      "name": "Rock_Marble"
    },
    {
      "x": -14,
      "y": 15,
      "z": -12,
      "name": "Rock_Stone"
    },
    {
      "x": -14,
      "y": 16,
      "z": -12,
      "name": "Rock_Marble"
    },
    {
      "x": -14,
      "y": 17,
      "z": -12,
      "name": "Rock_Marble"
    },
    {
      "x": -14,
      "y": 18,
      "z": -12,
      "name": "Rock_Marble"
    },
    {
      "x": -14,
      "y": 15,
      "z": -11,
      "name": "Rock_Stone"
    },
    {
      "x": -14,
      "y": 16,
      "z": -11,
      "name": "Rock_Marble"
    },
    {
      "x": -14,
      "y": 17,
      "z": -11,
      "name": "Rock_Marble"
    },
    {
      "x": -14,
      "y": 18,
      "z": -11,
      "name": "Rock_Marble"
    },
    {
      "x": -14,
      "y": 15,
      "z": -10,
      "name": "Rock_Stone"
    },
    {
      "x": -14,
      "y": 16,
      "z": -10,
      "name": "Plant_Moss_Block_Green"
    },
    {
      "x": -14,
      "y": 17,
      "z": -10,
      "name": "Plant_Moss_Block_Green"
    },
    {
      "x": -14,
      "y": 18,
      "z": -10,
      "name": "Plant_Moss_Block_Green"
    },
    {
      "x": -14,
      "y": 19,
      "z": -10,
      "name": "Plant_Moss_Rug_Green"
    },
    {
      "x": -14,
      "y": 17,
      "z": -9,
      "name": "Plant_Moss_Block_Green"
    },
    {
      "x": -14,
      "y": 18,
      "z": -9,
      "name": "Plant_Moss_Block_Green"
    },
    {
      "x": -14,
      "y": 19,
      "z": -9,
      "name": "Plant_Moss_Rug_Green"
    },
    {
      "x": -14,
      "y": 17,
      "z": -8,
      "name": "Plant_Moss_Wall_Green"
    },
    {
      "x": -14,
      "y": 18,
      "z": -8,
      "name": "Plant_Moss_Wall_Green"
    },
    {
      "x": -14,
      "y": 15,
      "z": -5,
      "name": "Rock_Stone"
    },
    {
      "x": -14,
      "y": 16,
      "z": -5,
      "name": "Rock_Stone"
    },
    {
      "x": -14,
      "y": 17,
      "z": -5,
      "name": "Rock_Marble"
    },
    {
      "x": -14,
      "y": 18,
      "z": -5,
      "name": "Rock_Marble"
    },
    {
      "x": -14,
      "y": 16,
      "z": -4,
      "name": "Rock_Stone"
    },
    {
      "x": -14,
      "y": 17,
      "z": -4,
      "name": "Rock_Marble"
    },
    {
      "x": -14,
      "y": 18,
      "z": -4,
      "name": "Rock_Marble"
    },
    {
      "x": -14,
      "y": 19,
      "z": -4,
      "name": "Rock_Marble"
    },
    {
      "x": -14,
      "y": 16,
      "z": -3,
      "name": "Rock_Stone"
    },
    {
      "x": -14,
      "y": 17,
      "z": -3,
      "name": "Rock_Marble"
    },
    {
      "x": -14,
      "y": 18,
      "z": -3,
      "name": "Plant_Moss_Block_Green"
    },
    {
      "x": -14,
      "y": 19,
      "z": -3,
      "name": "Plant_Moss_Block_Green"
    },
    {
      "x": -14,
      "y": 17,
      "z": -2,
      "name": "Plant_Moss_Block_Green"
    },
    {
      "x": -14,
      "y": 18,
      "z": -2,
      "name": "Plant_Moss_Block_Green"
    },
    {
      "x": -14,
      "y": 19,
      "z": -2,
      "name": "Plant_Moss_Block_Green"
    },
    {
      "x": -14,
      "y": 20,
      "z": -2,
      "name": "Plant_Moss_Block_Green"
    },
    {
      "x": -14,
      "y": 21,
      "z": -2,
      "name": "Plant_Moss_Rug_Green"
    },
    {
      "x": -14,
      "y": 19,
      "z": 3,
      "name": "Plant_Moss_Block_Green"
    },
    {
      "x": -14,
      "y": 20,
      "z": 3,
      "name": "Plant_Moss_Block_Green"
    },
    {
      "x": -14,
      "y": 21,
      "z": 3,
      "name": "Plant_Moss_Block_Green"
    },
    {
      "x": -14,
      "y": 22,
      "z": 3,
      "name": "Plant_Moss_Block_Green"
    },
    {
      "x": -14,
      "y": 19,
      "z": 4,
      "name": "Plant_Moss_Block_Green"
    },
    {
      "x": -14,
      "y": 20,
      "z": 4,
      "name": "Plant_Moss_Block_Green"
    },
    {
      "x": -14,
      "y": 21,
      "z": 4,
      "name": "Plant_Moss_Block_Green"
    },
    {
      "x": -14,
      "y": 22,
      "z": 4,
      "name": "Plant_Moss_Block_Green"
    },
    {
      "x": -14,
      "y": 19,
      "z": 5,
      "name": "Rock_Stone"
    },
    {
      "x": -14,
      "y": 20,
      "z": 5,
      "name": "Plant_Moss_Block_Green"
    },
    {
      "x": -14,
      "y": 21,
      "z": 5,
      "name": "Plant_Moss_Block_Green"
    },
    {
      "x": -14,
      "y": 22,
      "z": 5,
      "name": "Plant_Moss_Block_Green"
    },
    {
      "x": -14,
      "y": 23,
      "z": 5,
      "name": "Plant_Moss_Block_Green"
    },
    {
      "x": -14,
      "y": 19,
      "z": 6,
      "name": "Rock_Stone"
    },
    {
      "x": -14,
      "y": 20,
      "z": 6,
      "name": "Rock_Marble"
    },
    {
      "x": -14,
      "y": 21,
      "z": 6,
      "name": "Rock_Marble"
    },
    {
      "x": -14,
      "y": 22,
      "z": 6,
      "name": "Rock_Marble"
    },
    {
      "x": -14,
      "y": 19,
      "z": 7,
      "name": "Rock_Stone"
    },
    {
      "x": -14,
      "y": 20,
      "z": 7,
      "name": "Rock_Marble"
    },
    {
      "x": -14,
      "y": 21,
      "z": 7,
      "name": "Rock_Marble"
    },
    {
      "x": -14,
      "y": 22,
      "z": 7,
      "name": "Rock_Marble"
    },
    {
      "x": -14,
      "y": 18,
      "z": 8,
      "name": "Rock_Stone"
    },
    {
      "x": -14,
      "y": 19,
      "z": 8,
      "name": "Rock_Marble"
    },
    {
      "x": -14,
      "y": 20,
      "z": 8,
      "name": "Rock_Marble"
    },
    {
      "x": -14,
      "y": 21,
      "z": 8,
      "name": "Rock_Marble"
    },
    {
      "x": -14,
      "y": 17,
      "z": 9,
      "name": "Rock_Stone"
    },
    {
      "x": -14,
      "y": 18,
      "z": 9,
      "name": "Rock_Marble"
    },
    {
      "x": -14,
      "y": 19,
      "z": 9,
      "name": "Rock_Marble"
    },
    {
      "x": -14,
      "y": 20,
      "z": 9,
      "name": "Rock_Marble"
    },
    {
      "x": -14,
      "y": 16,
      "z": 10,
      "name": "Rock_Stone"
    },
    {
      "x": -14,
      "y": 17,
      "z": 10,
      "name": "Rock_Marble"
    },
    {
      "x": -14,
      "y": 18,
      "z": 10,
      "name": "Rock_Marble"
    },
    {
      "x": -14,
      "y": 19,
      "z": 10,
      "name": "Rock_Marble"
    },
    {
      "x": -14,
      "y": 20,
      "z": 10,
      "name": "Rock_Marble"
    },
    {
      "x": -14,
      "y": 16,
      "z": 11,
      "name": "Rock_Stone"
    },
    {
      "x": -14,
      "y": 17,
      "z": 11,
      "name": "Rock_Marble"
    },
    {
      "x": -14,
      "y": 18,
      "z": 11,
      "name": "Rock_Marble"
    },
    {
      "x": -14,
      "y": 19,
      "z": 11,
      "name": "Rock_Marble"
    },
    {
      "x": -14,
      "y": 15,
      "z": 12,
      "name": "Rock_Stone"
    },
    {
      "x": -14,
      "y": 16,
      "z": 12,
      "name": "Rock_Marble"
    },
    {
      "x": -14,
      "y": 17,
      "z": 12,
      "name": "Rock_Marble"
    },
    {
      "x": -14,
      "y": 18,
      "z": 12,
      "name": "Rock_Marble"
    },
    {
      "x": -14,
      "y": 14,
      "z": 13,
      "name": "Rock_Stone"
    },
    {
      "x": -14,
      "y": 15,
      "z": 13,
      "name": "Rock_Marble"
    },
    {
      "x": -14,
      "y": 16,
      "z": 13,
      "name": "Rock_Marble"
    },
    {
      "x": -14,
      "y": 17,
      "z": 13,
      "name": "Rock_Marble"
    },
    {
      "x": -14,
      "y": 14,
      "z": 14,
      "name": "Rock_Stone"
    },
    {
      "x": -14,
      "y": 15,
      "z": 14,
      "name": "Rock_Marble"
    },
    {
      "x": -14,
      "y": 13,
      "z": 15,
      "name": "Rock_Stone"
    },
    {
      "x": -14,
      "y": 14,
      "z": 15,
      "name": "Rock_Stone"
    },
    {
      "x": -13,
      "y": 12,
      "z": -20,
      "name": "Rock_Stone"
    },
    {
      "x": -13,
      "y": 13,
      "z": -20,
      "name": "Rock_Marble"
    },
    {
      "x": -13,
      "y": 12,
      "z": -19,
      "name": "Rock_Stone"
    },
    {
      "x": -13,
      "y": 13,
      "z": -19,
      "name": "Rock_Stone"
    },
    {
      "x": -13,
      "y": 14,
      "z": -19,
      "name": "Rock_Marble"
    },
    {
      "x": -13,
      "y": 13,
      "z": -18,
      "name": "Rock_Stone"
    },
    {
      "x": -13,
      "y": 14,
      "z": -18,
      "name": "Rock_Stone"
    },
    {
      "x": -13,
      "y": 15,
      "z": -18,
      "name": "Rock_Marble"
    },
    {
      "x": -13,
      "y": 16,
      "z": -18,
      "name": "Rock_Marble"
    },
    {
      "x": -13,
      "y": 14,
      "z": -17,
      "name": "Rock_Stone"
    },
    {
      "x": -13,
      "y": 15,
      "z": -17,
      "name": "Plant_Moss_Block_Green"
    },
    {
      "x": -13,
      "y": 16,
      "z": -17,
      "name": "Plant_Moss_Block_Green"
    },
    {
      "x": -13,
      "y": 14,
      "z": -16,
      "name": "Rock_Stone"
    },
    {
      "x": -13,
      "y": 15,
      "z": -16,
      "name": "Rock_Stone"
    },
    {
      "x": -13,
      "y": 16,
      "z": -16,
      "name": "Rock_Stone"
    },
    {
      "x": -13,
      "y": 17,
      "z": -16,
      "name": "Rock_Marble"
    },
    {
      "x": -13,
      "y": 15,
      "z": -15,
      "name": "Rock_Stone"
    },
    {
      "x": -13,
      "y": 16,
      "z": -15,
      "name": "Plant_Moss_Block_Green"
    },
    {
      "x": -13,
      "y": 17,
      "z": -15,
      "name": "Plant_Moss_Block_Green"
    },
    {
      "x": -13,
      "y": 18,
      "z": -15,
      "name": "Plant_Moss_Block_Green"
    },
    {
      "x": -13,
      "y": 15,
      "z": -14,
      "name": "Rock_Stone"
    },
    {
      "x": -13,
      "y": 16,
      "z": -14,
      "name": "Rock_Marble"
    },
    {
      "x": -13,
      "y": 17,
      "z": -14,
      "name": "Rock_Marble"
    },
    {
      "x": -13,
      "y": 18,
      "z": -14,
      "name": "Rock_Marble"
    },
    {
      "x": -13,
      "y": 15,
      "z": -13,
      "name": "Rock_Stone"
    },
    {
      "x": -13,
      "y": 16,
      "z": -13,
      "name": "Rock_Marble"
    },
    {
      "x": -13,
      "y": 17,
      "z": -13,
      "name": "Rock_Marble"
    },
    {
      "x": -13,
      "y": 18,
      "z": -13,
      "name": "Rock_Marble"
    },
    {
      "x": -13,
      "y": 16,
      "z": -12,
      "name": "Rock_Stone"
    },
    {
      "x": -13,
      "y": 17,
      "z": -12,
      "name": "Plant_Moss_Block_Green"
    },
    {
      "x": -13,
      "y": 18,
      "z": -12,
      "name": "Plant_Moss_Block_Green"
    },
    {
      "x": -13,
      "y": 19,
      "z": -12,
      "name": "Plant_Moss_Block_Green"
    },
    {
      "x": -13,
      "y": 16,
      "z": -11,
      "name": "Rock_Stone"
    },
    {
      "x": -13,
      "y": 17,
      "z": -11,
      "name": "Rock_Stone"
    },
    {
      "x": -13,
      "y": 18,
      "z": -11,
      "name": "Plant_Moss_Block_Green"
    },
    {
      "x": -13,
      "y": 19,
      "z": -11,
      "name": "Plant_Moss_Block_Green"
    },
    {
      "x": -13,
      "y": 20,
      "z": -11,
      "name": "Plant_Moss_Rug_Green"
    },
    {
      "x": -13,
      "y": 18,
      "z": -10,
      "name": "Plant_Moss_Wall_Green"
    },
    {
      "x": -13,
      "y": 19,
      "z": -10,
      "name": "Plant_Moss_Wall_Green"
    },
    {
      "x": -13,
      "y": 18,
      "z": -9,
      "name": "Plant_Moss_Wall_Green",
      "rotation": 1
    },
    {
      "x": -13,
      "y": 16,
      "z": -6,
      "name": "Rock_Stone"
    },
    {
      "x": -13,
      "y": 17,
      "z": -6,
      "name": "Rock_Marble"
    },
    {
      "x": -13,
      "y": 18,
      "z": -6,
      "name": "Rock_Marble"
    },
    {
      "x": -13,
      "y": 19,
      "z": -6,
      "name": "Rock_Marble"
    },
    {
      "x": -13,
      "y": 17,
      "z": -5,
      "name": "Rock_Stone"
    },
    {
      "x": -13,
      "y": 18,
      "z": -5,
      "name": "Rock_Marble"
    },
    {
      "x": -13,
      "y": 19,
      "z": -5,
      "name": "Rock_Marble"
    },
    {
      "x": -13,
      "y": 20,
      "z": -5,
      "name": "Rock_Marble"
    },
    {
      "x": -13,
      "y": 17,
      "z": -4,
      "name": "Rock_Stone"
    },
    {
      "x": -13,
      "y": 18,
      "z": -4,
      "name": "Rock_Marble"
    },
    {
      "x": -13,
      "y": 19,
      "z": -4,
      "name": "Rock_Marble"
    },
    {
      "x": -13,
      "y": 20,
      "z": -4,
      "name": "Rock_Marble"
    },
    {
      "x": -13,
      "y": 17,
      "z": -3,
      "name": "Rock_Stone"
    },
    {
      "x": -13,
      "y": 18,
      "z": -3,
      "name": "Rock_Marble"
    },
    {
      "x": -13,
      "y": 19,
      "z": -3,
      "name": "Rock_Marble"
    },
    {
      "x": -13,
      "y": 20,
      "z": -3,
      "name": "Rock_Marble"
    },
    {
      "x": -13,
      "y": 18,
      "z": -2,
      "name": "Plant_Moss_Block_Green"
    },
    {
      "x": -13,
      "y": 19,
      "z": -2,
      "name": "Plant_Moss_Block_Green"
    },
    {
      "x": -13,
      "y": 20,
      "z": -2,
      "name": "Plant_Moss_Block_Green"
    },
    {
      "x": -13,
      "y": 21,
      "z": -2,
      "name": "Plant_Moss_Block_Green"
    },
    {
      "x": -13,
      "y": 22,
      "z": -2,
      "name": "Plant_Moss_Rug_Green"
    },
    {
      "x": -13,
      "y": 20,
      "z": -1,
      "name": "Plant_Moss_Block_Green"
    },
    {
      "x": -13,
      "y": 21,
      "z": -1,
      "name": "Plant_Moss_Block_Green"
    },
    {
      "x": -13,
      "y": 22,
      "z": -1,
      "name": "Plant_Moss_Rug_Green"
    },
    {
      "x": -13,
      "y": 19,
      "z": 3,
      "name": "Plant_Moss_Block_Green"
    },
    {
      "x": -13,
      "y": 20,
      "z": 3,
      "name": "Plant_Moss_Block_Green"
    },
    {
      "x": -13,
      "y": 21,
      "z": 3,
      "name": "Plant_Moss_Block_Green"
    },
    {
      "x": -13,
      "y": 22,
      "z": 3,
      "name": "Plant_Moss_Block_Green"
    },
    {
      "x": -13,
      "y": 20,
      "z": 4,
      "name": "Plant_Moss_Block_Green"
    },
    {
      "x": -13,
      "y": 21,
      "z": 4,
      "name": "Plant_Moss_Block_Green"
    },
    {
      "x": -13,
      "y": 22,
      "z": 4,
      "name": "Plant_Moss_Block_Green"
    },
    {
      "x": -13,
      "y": 23,
      "z": 4,
      "name": "Plant_Moss_Block_Green"
    },
    {
      "x": -13,
      "y": 20,
      "z": 5,
      "name": "Rock_Stone"
    },
    {
      "x": -13,
      "y": 21,
      "z": 5,
      "name": "Rock_Marble"
    },
    {
      "x": -13,
      "y": 22,
      "z": 5,
      "name": "Rock_Marble"
    },
    {
      "x": -13,
      "y": 23,
      "z": 5,
      "name": "Rock_Calcite"
    },
    {
      "x": -13,
      "y": 20,
      "z": 6,
      "name": "Rock_Stone"
    },
    {
      "x": -13,
      "y": 21,
      "z": 6,
      "name": "Rock_Marble"
    },
    {
      "x": -13,
      "y": 22,
      "z": 6,
      "name": "Rock_Marble"
    },
    {
      "x": -13,
      "y": 23,
      "z": 6,
      "name": "Rock_Calcite"
    },
    {
      "x": -13,
      "y": 19,
      "z": 7,
      "name": "Rock_Stone"
    },
    {
      "x": -13,
      "y": 20,
      "z": 7,
      "name": "Rock_Marble"
    },
    {
      "x": -13,
      "y": 21,
      "z": 7,
      "name": "Rock_Marble"
    },
    {
      "x": -13,
      "y": 22,
      "z": 7,
      "name": "Rock_Marble"
    },
    {
      "x": -13,
      "y": 18,
      "z": 8,
      "name": "Rock_Stone"
    },
    {
      "x": -13,
      "y": 19,
      "z": 8,
      "name": "Rock_Marble"
    },
    {
      "x": -13,
      "y": 20,
      "z": 8,
      "name": "Rock_Marble"
    },
    {
      "x": -13,
      "y": 21,
      "z": 8,
      "name": "Rock_Marble"
    },
    {
      "x": -13,
      "y": 22,
      "z": 8,
      "name": "Rock_Marble"
    },
    {
      "x": -13,
      "y": 18,
      "z": 9,
      "name": "Rock_Stone"
    },
    {
      "x": -13,
      "y": 19,
      "z": 9,
      "name": "Rock_Marble"
    },
    {
      "x": -13,
      "y": 20,
      "z": 9,
      "name": "Rock_Marble"
    },
    {
      "x": -13,
      "y": 21,
      "z": 9,
      "name": "Rock_Marble"
    },
    {
      "x": -13,
      "y": 17,
      "z": 10,
      "name": "Rock_Stone"
    },
    {
      "x": -13,
      "y": 18,
      "z": 10,
      "name": "Rock_Marble"
    },
    {
      "x": -13,
      "y": 19,
      "z": 10,
      "name": "Rock_Marble"
    },
    {
      "x": -13,
      "y": 20,
      "z": 10,
      "name": "Rock_Marble"
    },
    {
      "x": -13,
      "y": 16,
      "z": 11,
      "name": "Rock_Stone"
    },
    {
      "x": -13,
      "y": 17,
      "z": 11,
      "name": "Rock_Marble"
    },
    {
      "x": -13,
      "y": 18,
      "z": 11,
      "name": "Rock_Marble"
    },
    {
      "x": -13,
      "y": 19,
      "z": 11,
      "name": "Rock_Marble"
    },
    {
      "x": -13,
      "y": 15,
      "z": 12,
      "name": "Rock_Stone"
    },
    {
      "x": -13,
      "y": 16,
      "z": 12,
      "name": "Rock_Marble"
    },
    {
      "x": -13,
      "y": 17,
      "z": 12,
      "name": "Rock_Marble"
    },
    {
      "x": -13,
      "y": 18,
      "z": 12,
      "name": "Rock_Marble"
    },
    {
      "x": -13,
      "y": 14,
      "z": 13,
      "name": "Rock_Stone"
    },
    {
      "x": -13,
      "y": 15,
      "z": 13,
      "name": "Rock_Marble"
    },
    {
      "x": -13,
      "y": 16,
      "z": 13,
      "name": "Rock_Marble"
    },
    {
      "x": -13,
      "y": 14,
      "z": 14,
      "name": "Rock_Stone"
    },
    {
      "x": -13,
      "y": 15,
      "z": 14,
      "name": "Rock_Marble"
    },
    {
      "x": -13,
      "y": 13,
      "z": 15,
      "name": "Rock_Stone"
    },
    {
      "x": -13,
      "y": 14,
      "z": 15,
      "name": "Rock_Stone"
    },
    {
      "x": -12,
      "y": 16,
      "z": -17,
      "name": "Plant_Moss_Block_Green"
    },
    {
      "x": -12,
      "y": 17,
      "z": -17,
      "name": "Plant_Moss_Block_Green"
    },
    {
      "x": -12,
      "y": 17,
      "z": -16,
      "name": "Plant_Moss_Block_Green"
    },
    {
      "x": -12,
      "y": 18,
      "z": -16,
      "name": "Plant_Moss_Block_Green"
    },
    {
      "x": -12,
      "y": 15,
      "z": -15,
      "name": "Plant_Moss_Block_Green"
    },
    {
      "x": -12,
      "y": 16,
      "z": -15,
      "name": "Plant_Moss_Block_Green"
    },
    {
      "x": -12,
      "y": 17,
      "z": -15,
      "name": "Plant_Moss_Block_Green"
    },
    {
      "x": -12,
      "y": 18,
      "z": -15,
      "name": "Plant_Moss_Block_Green"
    },
    {
      "x": -12,
      "y": 16,
      "z": -14,
      "name": "Plant_Moss_Block_Green"
    },
    {
      "x": -12,
      "y": 17,
      "z": -14,
      "name": "Plant_Moss_Block_Green"
    },
    {
      "x": -12,
      "y": 18,
      "z": -14,
      "name": "Plant_Moss_Block_Green"
    },
    {
      "x": -12,
      "y": 19,
      "z": -14,
      "name": "Plant_Moss_Block_Green"
    },
    {
      "x": -12,
      "y": 20,
      "z": -14,
      "name": "Plant_Moss_Rug_Green"
    },
    {
      "x": -12,
      "y": 16,
      "z": -13,
      "name": "Rock_Stone"
    },
    {
      "x": -12,
      "y": 17,
      "z": -13,
      "name": "Plant_Moss_Block_Green"
    },
    {
      "x": -12,
      "y": 18,
      "z": -13,
      "name": "Plant_Moss_Block_Green"
    },
    {
      "x": -12,
      "y": 19,
      "z": -13,
      "name": "Plant_Moss_Block_Green"
    },
    {
      "x": -12,
      "y": 16,
      "z": -12,
      "name": "Plant_Moss_Block_Green"
    },
    {
      "x": -12,
      "y": 17,
      "z": -12,
      "name": "Plant_Moss_Block_Green"
    },
    {
      "x": -12,
      "y": 18,
      "z": -12,
      "name": "Plant_Moss_Block_Green"
    },
    {
      "x": -12,
      "y": 19,
      "z": -12,
      "name": "Plant_Moss_Block_Green"
    },
    {
      "x": -12,
      "y": 17,
      "z": -7,
      "name": "Rock_Stone"
    },
    {
      "x": -12,
      "y": 18,
      "z": -7,
      "name": "Rock_Marble"
    },
    {
      "x": -12,
      "y": 19,
      "z": -7,
      "name": "Rock_Marble"
    },
    {
      "x": -12,
      "y": 20,
      "z": -7,
      "name": "Rock_Marble"
    },
    {
      "x": -12,
      "y": 17,
      "z": -6,
      "name": "Rock_Stone"
    },
    {
      "x": -12,
      "y": 18,
      "z": -6,
      "name": "Rock_Marble"
    },
    {
      "x": -12,
      "y": 19,
      "z": -6,
      "name": "Rock_Marble"
    },
    {
      "x": -12,
      "y": 20,
      "z": -6,
      "name": "Rock_Marble"
    },
    {
      "x": -12,
      "y": 18,
      "z": -5,
      "name": "Rock_Stone"
    },
    {
      "x": -12,
      "y": 19,
      "z": -5,
      "name": "Rock_Marble"
    },
    {
      "x": -12,
      "y": 20,
      "z": -5,
      "name": "Rock_Marble"
    },
    {
      "x": -12,
      "y": 21,
      "z": -5,
      "name": "Rock_Marble"
    },
    {
      "x": -12,
      "y": 18,
      "z": -4,
      "name": "Rock_Stone"
    },
    {
      "x": -12,
      "y": 19,
      "z": -4,
      "name": "Rock_Marble"
    },
    {
      "x": -12,
      "y": 20,
      "z": -4,
      "name": "Rock_Marble"
    },
    {
      "x": -12,
      "y": 21,
      "z": -4,
      "name": "Rock_Marble"
    },
    {
      "x": -12,
      "y": 18,
      "z": -3,
      "name": "Rock_Stone"
    },
    {
      "x": -12,
      "y": 19,
      "z": -3,
      "name": "Rock_Marble"
    },
    {
      "x": -12,
      "y": 20,
      "z": -3,
      "name": "Rock_Marble"
    },
    {
      "x": -12,
      "y": 21,
      "z": -3,
      "name": "Rock_Marble"
    },
    {
      "x": -12,
      "y": 18,
      "z": -2,
      "name": "Rock_Stone"
    },
    {
      "x": -12,
      "y": 19,
      "z": -2,
      "name": "Rock_Marble"
    },
    {
      "x": -12,
      "y": 20,
      "z": -2,
      "name": "Rock_Marble"
    },
    {
      "x": -12,
      "y": 21,
      "z": -2,
      "name": "Rock_Marble"
    },
    {
      "x": -12,
      "y": 22,
      "z": -2,
      "name": "Rock_Marble"
    },
    {
      "x": -12,
      "y": 19,
      "z": -1,
      "name": "Plant_Moss_Block_Green"
    },
    {
      "x": -12,
      "y": 20,
      "z": -1,
      "name": "Plant_Moss_Block_Green"
    },
    {
      "x": -12,
      "y": 21,
      "z": -1,
      "name": "Plant_Moss_Block_Green"
    },
    {
      "x": -12,
      "y": 22,
      "z": -1,
      "name": "Plant_Moss_Block_Green"
    },
    {
      "x": -12,
      "y": 21,
      "z": 2,
      "name": "Plant_Moss_Block_Green"
    },
    {
      "x": -12,
      "y": 22,
      "z": 2,
      "name": "Plant_Moss_Block_Green"
    },
    {
      "x": -12,
      "y": 23,
      "z": 2,
      "name": "Plant_Moss_Block_Green"
    },
    {
      "x": -12,
      "y": 20,
      "z": 3,
      "name": "Plant_Moss_Block_Green"
    },
    {
      "x": -12,
      "y": 21,
      "z": 3,
      "name": "Plant_Moss_Block_Green"
    },
    {
      "x": -12,
      "y": 22,
      "z": 3,
      "name": "Plant_Moss_Block_Green"
    },
    {
      "x": -12,
      "y": 23,
      "z": 3,
      "name": "Plant_Moss_Block_Green"
    },
    {
      "x": -12,
      "y": 20,
      "z": 4,
      "name": "Rock_Stone"
    },
    {
      "x": -12,
      "y": 21,
      "z": 4,
      "name": "Plant_Moss_Block_Green"
    },
    {
      "x": -12,
      "y": 22,
      "z": 4,
      "name": "Plant_Moss_Block_Green"
    },
    {
      "x": -12,
      "y": 23,
      "z": 4,
      "name": "Plant_Moss_Block_Green"
    },
    {
      "x": -12,
      "y": 20,
      "z": 5,
      "name": "Rock_Stone"
    },
    {
      "x": -12,
      "y": 21,
      "z": 5,
      "name": "Rock_Marble"
    },
    {
      "x": -12,
      "y": 22,
      "z": 5,
      "name": "Rock_Marble"
    },
    {
      "x": -12,
      "y": 23,
      "z": 5,
      "name": "Rock_Calcite"
    },
    {
      "x": -12,
      "y": 20,
      "z": 6,
      "name": "Rock_Stone"
    },
    {
      "x": -12,
      "y": 21,
      "z": 6,
      "name": "Rock_Marble"
    },
    {
      "x": -12,
      "y": 22,
      "z": 6,
      "name": "Rock_Marble"
    },
    {
      "x": -12,
      "y": 23,
      "z": 6,
      "name": "Rock_Calcite"
    },
    {
      "x": -12,
      "y": 19,
      "z": 7,
      "name": "Rock_Stone"
    },
    {
      "x": -12,
      "y": 20,
      "z": 7,
      "name": "Rock_Marble"
    },
    {
      "x": -12,
      "y": 21,
      "z": 7,
      "name": "Rock_Marble"
    },
    {
      "x": -12,
      "y": 22,
      "z": 7,
      "name": "Rock_Marble"
    },
    {
      "x": -12,
      "y": 18,
      "z": 8,
      "name": "Rock_Stone"
    },
    {
      "x": -12,
      "y": 19,
      "z": 8,
      "name": "Rock_Marble"
    },
    {
      "x": -12,
      "y": 20,
      "z": 8,
      "name": "Rock_Marble"
    },
    {
      "x": -12,
      "y": 21,
      "z": 8,
      "name": "Rock_Marble"
    },
    {
      "x": -12,
      "y": 22,
      "z": 8,
      "name": "Rock_Marble"
    },
    {
      "x": -12,
      "y": 18,
      "z": 9,
      "name": "Rock_Stone"
    },
    {
      "x": -12,
      "y": 19,
      "z": 9,
      "name": "Rock_Marble"
    },
    {
      "x": -12,
      "y": 20,
      "z": 9,
      "name": "Rock_Marble"
    },
    {
      "x": -12,
      "y": 21,
      "z": 9,
      "name": "Rock_Marble"
    },
    {
      "x": -12,
      "y": 17,
      "z": 10,
      "name": "Rock_Stone"
    },
    {
      "x": -12,
      "y": 18,
      "z": 10,
      "name": "Rock_Marble"
    },
    {
      "x": -12,
      "y": 19,
      "z": 10,
      "name": "Rock_Marble"
    },
    {
      "x": -12,
      "y": 20,
      "z": 10,
      "name": "Rock_Marble"
    },
    {
      "x": -12,
      "y": 16,
      "z": 11,
      "name": "Rock_Stone"
    },
    {
      "x": -12,
      "y": 17,
      "z": 11,
      "name": "Rock_Marble"
    },
    {
      "x": -12,
      "y": 18,
      "z": 11,
      "name": "Rock_Marble"
    },
    {
      "x": -12,
      "y": 19,
      "z": 11,
      "name": "Rock_Marble"
    },
    {
      "x": -12,
      "y": 14,
      "z": 12,
      "name": "Rock_Stone"
    },
    {
      "x": -12,
      "y": 15,
      "z": 12,
      "name": "Rock_Stone"
    },
    {
      "x": -12,
      "y": 16,
      "z": 12,
      "name": "Rock_Marble"
    },
    {
      "x": -12,
      "y": 17,
      "z": 12,
      "name": "Rock_Marble"
    },
    {
      "x": -12,
      "y": 13,
      "z": 13,
      "name": "Rock_Stone"
    },
    {
      "x": -12,
      "y": 14,
      "z": 13,
      "name": "Rock_Marble"
    },
    {
      "x": -12,
      "y": 15,
      "z": 13,
      "name": "Rock_Marble"
    },
    {
      "x": -12,
      "y": 16,
      "z": 13,
      "name": "Rock_Marble"
    },
    {
      "x": -12,
      "y": 12,
      "z": 14,
      "name": "Rock_Stone"
    },
    {
      "x": -12,
      "y": 13,
      "z": 14,
      "name": "Rock_Marble"
    },
    {
      "x": -12,
      "y": 14,
      "z": 14,
      "name": "Rock_Marble"
    },
    {
      "x": -12,
      "y": 15,
      "z": 14,
      "name": "Rock_Marble"
    },
    {
      "x": -12,
      "y": 13,
      "z": 15,
      "name": "Rock_Stone"
    },
    {
      "x": -11,
      "y": 19,
      "z": -15,
      "name": "Plant_Moss_Wall_Green",
      "rotation": 2
    },
    {
      "x": -11,
      "y": 17,
      "z": -14,
      "name": "Plant_Moss_Cave_Green",
      "rotation": 8
    },
    {
      "x": -11,
      "y": 18,
      "z": -14,
      "name": "Plant_Moss_Block_Green"
    },
    {
      "x": -11,
      "y": 19,
      "z": -14,
      "name": "Plant_Moss_Block_Green"
    },
    {
      "x": -11,
      "y": 20,
      "z": -14,
      "name": "Plant_Moss_Rug_Green"
    },
    {
      "x": -11,
      "y": 16,
      "z": -13,
      "name": "Rock_Stone"
    },
    {
      "x": -11,
      "y": 17,
      "z": -13,
      "name": "Plant_Moss_Block_Green"
    },
    {
      "x": -11,
      "y": 18,
      "z": -13,
      "name": "Plant_Moss_Block_Green"
    },
    {
      "x": -11,
      "y": 19,
      "z": -13,
      "name": "Plant_Moss_Block_Green"
    },
    {
      "x": -11,
      "y": 20,
      "z": -13,
      "name": "Plant_Moss_Block_Green"
    },
    {
      "x": -11,
      "y": 20,
      "z": -12,
      "name": "Plant_Moss_Wall_Green"
    },
    {
      "x": -11,
      "y": 21,
      "z": -9,
      "name": "Rock_Marble"
    },
    {
      "x": -11,
      "y": 18,
      "z": -8,
      "name": "Rock_Stone"
    },
    {
      "x": -11,
      "y": 19,
      "z": -8,
      "name": "Rock_Marble"
    },
    {
      "x": -11,
      "y": 20,
      "z": -8,
      "name": "Rock_Marble"
    },
    {
      "x": -11,
      "y": 21,
      "z": -8,
      "name": "Rock_Marble"
    },
    {
      "x": -11,
      "y": 18,
      "z": -7,
      "name": "Rock_Stone"
    },
    {
      "x": -11,
      "y": 19,
      "z": -7,
      "name": "Rock_Marble"
    },
    {
      "x": -11,
      "y": 20,
      "z": -7,
      "name": "Rock_Marble"
    },
    {
      "x": -11,
      "y": 21,
      "z": -7,
      "name": "Rock_Marble"
    },
    {
      "x": -11,
      "y": 18,
      "z": -6,
      "name": "Rock_Stone"
    },
    {
      "x": -11,
      "y": 19,
      "z": -6,
      "name": "Rock_Marble"
    },
    {
      "x": -11,
      "y": 20,
      "z": -6,
      "name": "Rock_Marble"
    },
    {
      "x": -11,
      "y": 21,
      "z": -6,
      "name": "Rock_Marble"
    },
    {
      "x": -11,
      "y": 18,
      "z": -5,
      "name": "Rock_Stone"
    },
    {
      "x": -11,
      "y": 19,
      "z": -5,
      "name": "Rock_Marble"
    },
    {
      "x": -11,
      "y": 20,
      "z": -5,
      "name": "Rock_Marble"
    },
    {
      "x": -11,
      "y": 21,
      "z": -5,
      "name": "Rock_Marble"
    },
    {
      "x": -11,
      "y": 22,
      "z": -5,
      "name": "Rock_Marble"
    },
    {
      "x": -11,
      "y": 19,
      "z": -4,
      "name": "Rock_Stone"
    },
    {
      "x": -11,
      "y": 20,
      "z": -4,
      "name": "Rock_Marble"
    },
    {
      "x": -11,
      "y": 21,
      "z": -4,
      "name": "Rock_Marble"
    },
    {
      "x": -11,
      "y": 22,
      "z": -4,
      "name": "Rock_Marble"
    },
    {
      "x": -11,
      "y": 19,
      "z": -3,
      "name": "Rock_Stone"
    },
    {
      "x": -11,
      "y": 20,
      "z": -3,
      "name": "Rock_Marble"
    },
    {
      "x": -11,
      "y": 21,
      "z": -3,
      "name": "Rock_Marble"
    },
    {
      "x": -11,
      "y": 22,
      "z": -3,
      "name": "Rock_Marble"
    },
    {
      "x": -11,
      "y": 19,
      "z": -2,
      "name": "Rock_Stone"
    },
    {
      "x": -11,
      "y": 20,
      "z": -2,
      "name": "Rock_Marble"
    },
    {
      "x": -11,
      "y": 21,
      "z": -2,
      "name": "Plant_Moss_Block_Green"
    },
    {
      "x": -11,
      "y": 22,
      "z": -2,
      "name": "Plant_Moss_Block_Green"
    },
    {
      "x": -11,
      "y": 19,
      "z": -1,
      "name": "Rock_Stone"
    },
    {
      "x": -11,
      "y": 20,
      "z": -1,
      "name": "Plant_Moss_Block_Green"
    },
    {
      "x": -11,
      "y": 21,
      "z": -1,
      "name": "Plant_Moss_Block_Green"
    },
    {
      "x": -11,
      "y": 22,
      "z": -1,
      "name": "Plant_Moss_Block_Green"
    },
    {
      "x": -11,
      "y": 23,
      "z": -1,
      "name": "Plant_Moss_Block_Green"
    },
    {
      "x": -11,
      "y": 24,
      "z": -1,
      "name": "Plant_Moss_Rug_Green"
    },
    {
      "x": -11,
      "y": 23,
      "z": 0,
      "name": "Plant_Moss_Block_Green"
    },
    {
      "x": -11,
      "y": 24,
      "z": 0,
      "name": "Plant_Moss_Rug_Green"
    },
    {
      "x": -11,
      "y": 22,
      "z": 2,
      "name": "Plant_Moss_Block_Green"
    },
    {
      "x": -11,
      "y": 23,
      "z": 2,
      "name": "Plant_Moss_Block_Green"
    },
    {
      "x": -11,
      "y": 20,
      "z": 3,
      "name": "Rock_Stone"
    },
    {
      "x": -11,
      "y": 21,
      "z": 3,
      "name": "Plant_Moss_Block_Green"
    },
    {
      "x": -11,
      "y": 22,
      "z": 3,
      "name": "Plant_Moss_Block_Green"
    },
    {
      "x": -11,
      "y": 23,
      "z": 3,
      "name": "Plant_Moss_Block_Green"
    },
    {
      "x": -11,
      "y": 20,
      "z": 4,
      "name": "Rock_Stone"
    },
    {
      "x": -11,
      "y": 21,
      "z": 4,
      "name": "Rock_Marble"
    },
    {
      "x": -11,
      "y": 22,
      "z": 4,
      "name": "Rock_Marble"
    },
    {
      "x": -11,
      "y": 23,
      "z": 4,
      "name": "Rock_Calcite"
    },
    {
      "x": -11,
      "y": 24,
      "z": 4,
      "name": "Rock_Calcite"
    },
    {
      "x": -11,
      "y": 20,
      "z": 5,
      "name": "Rock_Stone"
    },
    {
      "x": -11,
      "y": 21,
      "z": 5,
      "name": "Rock_Marble"
    },
    {
      "x": -11,
      "y": 22,
      "z": 5,
      "name": "Rock_Marble"
    },
    {
      "x": -11,
      "y": 23,
      "z": 5,
      "name": "Rock_Calcite"
    },
    {
      "x": -11,
      "y": 20,
      "z": 6,
      "name": "Rock_Stone"
    },
    {
      "x": -11,
      "y": 21,
      "z": 6,
      "name": "Rock_Marble"
    },
    {
      "x": -11,
      "y": 22,
      "z": 6,
      "name": "Rock_Marble"
    },
    {
      "x": -11,
      "y": 23,
      "z": 6,
      "name": "Rock_Calcite"
    },
    {
      "x": -11,
      "y": 19,
      "z": 7,
      "name": "Rock_Stone"
    },
    {
      "x": -11,
      "y": 20,
      "z": 7,
      "name": "Rock_Marble"
    },
    {
      "x": -11,
      "y": 21,
      "z": 7,
      "name": "Rock_Marble"
    },
    {
      "x": -11,
      "y": 22,
      "z": 7,
      "name": "Rock_Marble"
    },
    {
      "x": -11,
      "y": 18,
      "z": 8,
      "name": "Rock_Stone"
    },
    {
      "x": -11,
      "y": 19,
      "z": 8,
      "name": "Rock_Marble"
    },
    {
      "x": -11,
      "y": 20,
      "z": 8,
      "name": "Rock_Marble"
    },
    {
      "x": -11,
      "y": 21,
      "z": 8,
      "name": "Rock_Marble"
    },
    {
      "x": -11,
      "y": 17,
      "z": 9,
      "name": "Rock_Stone"
    },
    {
      "x": -11,
      "y": 18,
      "z": 9,
      "name": "Rock_Marble"
    },
    {
      "x": -11,
      "y": 19,
      "z": 9,
      "name": "Rock_Marble"
    },
    {
      "x": -11,
      "y": 20,
      "z": 9,
      "name": "Rock_Marble"
    },
    {
      "x": -11,
      "y": 21,
      "z": 9,
      "name": "Rock_Marble"
    },
    {
      "x": -11,
      "y": 16,
      "z": 10,
      "name": "Rock_Stone"
    },
    {
      "x": -11,
      "y": 17,
      "z": 10,
      "name": "Rock_Marble"
    },
    {
      "x": -11,
      "y": 18,
      "z": 10,
      "name": "Rock_Marble"
    },
    {
      "x": -11,
      "y": 19,
      "z": 10,
      "name": "Rock_Marble"
    },
    {
      "x": -11,
      "y": 20,
      "z": 10,
      "name": "Rock_Marble"
    },
    {
      "x": -11,
      "y": 15,
      "z": 11,
      "name": "Rock_Stone"
    },
    {
      "x": -11,
      "y": 16,
      "z": 11,
      "name": "Rock_Marble"
    },
    {
      "x": -11,
      "y": 17,
      "z": 11,
      "name": "Rock_Marble"
    },
    {
      "x": -11,
      "y": 18,
      "z": 11,
      "name": "Rock_Marble"
    },
    {
      "x": -11,
      "y": 14,
      "z": 12,
      "name": "Rock_Stone"
    },
    {
      "x": -11,
      "y": 15,
      "z": 12,
      "name": "Rock_Marble"
    },
    {
      "x": -11,
      "y": 16,
      "z": 12,
      "name": "Rock_Marble"
    },
    {
      "x": -11,
      "y": 17,
      "z": 12,
      "name": "Rock_Marble"
    },
    {
      "x": -11,
      "y": 13,
      "z": 13,
      "name": "Rock_Stone"
    },
    {
      "x": -11,
      "y": 14,
      "z": 13,
      "name": "Rock_Marble"
    },
    {
      "x": -11,
      "y": 15,
      "z": 13,
      "name": "Rock_Marble"
    },
    {
      "x": -11,
      "y": 16,
      "z": 13,
      "name": "Rock_Marble"
    },
    {
      "x": -11,
      "y": 12,
      "z": 14,
      "name": "Rock_Stone"
    },
    {
      "x": -11,
      "y": 13,
      "z": 14,
      "name": "Rock_Marble"
    },
    {
      "x": -11,
      "y": 14,
      "z": 14,
      "name": "Rock_Marble"
    },
    {
      "x": -11,
      "y": 12,
      "z": 15,
      "name": "Rock_Stone"
    },
    {
      "x": -11,
      "y": 13,
      "z": 15,
      "name": "Rock_Stone"
    },
    {
      "x": -10,
      "y": 19,
      "z": -14,
      "name": "Plant_Moss_Wall_Green",
      "rotation": 1
    },
    {
      "x": -10,
      "y": 19,
      "z": -13,
      "name": "Plant_Moss_Wall_Green",
      "rotation": 1
    },
    {
      "x": -10,
      "y": 20,
      "z": -13,
      "name": "Plant_Moss_Wall_Green",
      "rotation": 1
    },
    {
      "x": -10,
      "y": 18,
      "z": -9,
      "name": "Rock_Stone"
    },
    {
      "x": -10,
      "y": 19,
      "z": -9,
      "name": "Rock_Marble"
    },
    {
      "x": -10,
      "y": 20,
      "z": -9,
      "name": "Rock_Marble"
    },
    {
      "x": -10,
      "y": 21,
      "z": -9,
      "name": "Rock_Calcite"
    },
    {
      "x": -10,
      "y": 18,
      "z": -8,
      "name": "Rock_Stone"
    },
    {
      "x": -10,
      "y": 19,
      "z": -8,
      "name": "Rock_Marble"
    },
    {
      "x": -10,
      "y": 20,
      "z": -8,
      "name": "Rock_Marble"
    },
    {
      "x": -10,
      "y": 21,
      "z": -8,
      "name": "Rock_Calcite"
    },
    {
      "x": -10,
      "y": 18,
      "z": -7,
      "name": "Rock_Stone"
    },
    {
      "x": -10,
      "y": 19,
      "z": -7,
      "name": "Rock_Marble"
    },
    {
      "x": -10,
      "y": 20,
      "z": -7,
      "name": "Rock_Marble"
    },
    {
      "x": -10,
      "y": 21,
      "z": -7,
      "name": "Rock_Marble"
    },
    {
      "x": -10,
      "y": 22,
      "z": -7,
      "name": "Rock_Calcite"
    },
    {
      "x": -10,
      "y": 23,
      "z": -7,
      "name": "Plant_Moss_Rug_Green"
    },
    {
      "x": -10,
      "y": 19,
      "z": -6,
      "name": "Rock_Stone"
    },
    {
      "x": -10,
      "y": 20,
      "z": -6,
      "name": "Rock_Marble"
    },
    {
      "x": -10,
      "y": 21,
      "z": -6,
      "name": "Rock_Marble"
    },
    {
      "x": -10,
      "y": 22,
      "z": -6,
      "name": "Rock_Marble"
    },
    {
      "x": -10,
      "y": 19,
      "z": -5,
      "name": "Rock_Stone"
    },
    {
      "x": -10,
      "y": 20,
      "z": -5,
      "name": "Rock_Marble"
    },
    {
      "x": -10,
      "y": 21,
      "z": -5,
      "name": "Rock_Marble"
    },
    {
      "x": -10,
      "y": 22,
      "z": -5,
      "name": "Rock_Marble"
    },
    {
      "x": -10,
      "y": 19,
      "z": -4,
      "name": "Rock_Stone"
    },
    {
      "x": -10,
      "y": 20,
      "z": -4,
      "name": "Rock_Marble"
    },
    {
      "x": -10,
      "y": 21,
      "z": -4,
      "name": "Rock_Marble"
    },
    {
      "x": -10,
      "y": 22,
      "z": -4,
      "name": "Rock_Marble"
    },
    {
      "x": -10,
      "y": 23,
      "z": -4,
      "name": "Rock_Calcite"
    },
    {
      "x": -10,
      "y": 20,
      "z": -3,
      "name": "Rock_Stone"
    },
    {
      "x": -10,
      "y": 21,
      "z": -3,
      "name": "Rock_Marble"
    },
    {
      "x": -10,
      "y": 22,
      "z": -3,
      "name": "Rock_Marble"
    },
    {
      "x": -10,
      "y": 23,
      "z": -3,
      "name": "Rock_Calcite"
    },
    {
      "x": -10,
      "y": 20,
      "z": -2,
      "name": "Rock_Stone"
    },
    {
      "x": -10,
      "y": 21,
      "z": -2,
      "name": "Rock_Marble"
    },
    {
      "x": -10,
      "y": 22,
      "z": -2,
      "name": "Rock_Marble"
    },
    {
      "x": -10,
      "y": 23,
      "z": -2,
      "name": "Rock_Calcite"
    },
    {
      "x": -10,
      "y": 20,
      "z": -1,
      "name": "Rock_Stone"
    },
    {
      "x": -10,
      "y": 21,
      "z": -1,
      "name": "Plant_Moss_Block_Green"
    },
    {
      "x": -10,
      "y": 22,
      "z": -1,
      "name": "Plant_Moss_Block_Green"
    },
    {
      "x": -10,
      "y": 23,
      "z": -1,
      "name": "Plant_Moss_Block_Green"
    },
    {
      "x": -10,
      "y": 24,
      "z": -1,
      "name": "Plant_Moss_Rug_Green"
    },
    {
      "x": -10,
      "y": 22,
      "z": 2,
      "name": "Plant_Moss_Block_Green"
    },
    {
      "x": -10,
      "y": 23,
      "z": 2,
      "name": "Plant_Moss_Block_Green"
    },
    {
      "x": -10,
      "y": 24,
      "z": 2,
      "name": "Plant_Moss_Block_Green"
    },
    {
      "x": -10,
      "y": 20,
      "z": 3,
      "name": "Rock_Stone"
    },
    {
      "x": -10,
      "y": 21,
      "z": 3,
      "name": "Rock_Stone"
    },
    {
      "x": -10,
      "y": 22,
      "z": 3,
      "name": "Plant_Moss_Block_Green"
    },
    {
      "x": -10,
      "y": 23,
      "z": 3,
      "name": "Plant_Moss_Block_Green"
    },
    {
      "x": -10,
      "y": 24,
      "z": 3,
      "name": "Plant_Moss_Block_Green"
    },
    {
      "x": -10,
      "y": 25,
      "z": 3,
      "name": "Plant_Moss_Rug_Green"
    },
    {
      "x": -10,
      "y": 20,
      "z": 4,
      "name": "Rock_Stone"
    },
    {
      "x": -10,
      "y": 21,
      "z": 4,
      "name": "Rock_Marble"
    },
    {
      "x": -10,
      "y": 22,
      "z": 4,
      "name": "Rock_Marble"
    },
    {
      "x": -10,
      "y": 23,
      "z": 4,
      "name": "Rock_Calcite"
    },
    {
      "x": -10,
      "y": 24,
      "z": 4,
      "name": "Rock_Calcite"
    },
    {
      "x": -10,
      "y": 20,
      "z": 5,
      "name": "Rock_Stone"
    },
    {
      "x": -10,
      "y": 21,
      "z": 5,
      "name": "Rock_Marble"
    },
    {
      "x": -10,
      "y": 22,
      "z": 5,
      "name": "Rock_Marble"
    },
    {
      "x": -10,
      "y": 23,
      "z": 5,
      "name": "Rock_Calcite"
    },
    {
      "x": -10,
      "y": 20,
      "z": 6,
      "name": "Rock_Stone"
    },
    {
      "x": -10,
      "y": 21,
      "z": 6,
      "name": "Rock_Marble"
    },
    {
      "x": -10,
      "y": 22,
      "z": 6,
      "name": "Rock_Marble"
    },
    {
      "x": -10,
      "y": 23,
      "z": 6,
      "name": "Rock_Calcite"
    },
    {
      "x": -10,
      "y": 19,
      "z": 7,
      "name": "Rock_Stone"
    },
    {
      "x": -10,
      "y": 20,
      "z": 7,
      "name": "Rock_Marble"
    },
    {
      "x": -10,
      "y": 21,
      "z": 7,
      "name": "Rock_Marble"
    },
    {
      "x": -10,
      "y": 22,
      "z": 7,
      "name": "Rock_Marble"
    },
    {
      "x": -10,
      "y": 18,
      "z": 8,
      "name": "Rock_Stone"
    },
    {
      "x": -10,
      "y": 19,
      "z": 8,
      "name": "Rock_Marble"
    },
    {
      "x": -10,
      "y": 20,
      "z": 8,
      "name": "Rock_Marble"
    },
    {
      "x": -10,
      "y": 21,
      "z": 8,
      "name": "Rock_Marble"
    },
    {
      "x": -10,
      "y": 17,
      "z": 9,
      "name": "Rock_Stone"
    },
    {
      "x": -10,
      "y": 18,
      "z": 9,
      "name": "Rock_Marble"
    },
    {
      "x": -10,
      "y": 19,
      "z": 9,
      "name": "Rock_Marble"
    },
    {
      "x": -10,
      "y": 20,
      "z": 9,
      "name": "Rock_Marble"
    },
    {
      "x": -10,
      "y": 16,
      "z": 10,
      "name": "Rock_Stone"
    },
    {
      "x": -10,
      "y": 17,
      "z": 10,
      "name": "Rock_Marble"
    },
    {
      "x": -10,
      "y": 18,
      "z": 10,
      "name": "Rock_Marble"
    },
    {
      "x": -10,
      "y": 19,
      "z": 10,
      "name": "Rock_Marble"
    },
    {
      "x": -10,
      "y": 15,
      "z": 11,
      "name": "Rock_Stone"
    },
    {
      "x": -10,
      "y": 16,
      "z": 11,
      "name": "Rock_Marble"
    },
    {
      "x": -10,
      "y": 17,
      "z": 11,
      "name": "Rock_Marble"
    },
    {
      "x": -10,
      "y": 18,
      "z": 11,
      "name": "Rock_Marble"
    },
    {
      "x": -10,
      "y": 14,
      "z": 12,
      "name": "Rock_Stone"
    },
    {
      "x": -10,
      "y": 15,
      "z": 12,
      "name": "Rock_Marble"
    },
    {
      "x": -10,
      "y": 16,
      "z": 12,
      "name": "Rock_Marble"
    },
    {
      "x": -10,
      "y": 17,
      "z": 12,
      "name": "Rock_Marble"
    },
    {
      "x": -10,
      "y": 13,
      "z": 13,
      "name": "Rock_Stone"
    },
    {
      "x": -10,
      "y": 14,
      "z": 13,
      "name": "Rock_Marble"
    },
    {
      "x": -10,
      "y": 15,
      "z": 13,
      "name": "Rock_Marble"
    },
    {
      "x": -10,
      "y": 16,
      "z": 13,
      "name": "Rock_Marble"
    },
    {
      "x": -10,
      "y": 12,
      "z": 14,
      "name": "Rock_Stone"
    },
    {
      "x": -10,
      "y": 13,
      "z": 14,
      "name": "Rock_Marble"
    },
    {
      "x": -10,
      "y": 14,
      "z": 14,
      "name": "Rock_Marble"
    },
    {
      "x": -10,
      "y": 13,
      "z": 15,
      "name": "Rock_Stone"
    },
    {
      "x": -9,
      "y": 18,
      "z": -9,
      "name": "Rock_Stone"
    },
    {
      "x": -9,
      "y": 19,
      "z": -9,
      "name": "Rock_Marble"
    },
    {
      "x": -9,
      "y": 20,
      "z": -9,
      "name": "Plant_Moss_Block_Green"
    },
    {
      "x": -9,
      "y": 21,
      "z": -9,
      "name": "Plant_Moss_Block_Green"
    },
    {
      "x": -9,
      "y": 22,
      "z": -9,
      "name": "Plant_Moss_Block_Green"
    },
    {
      "x": -9,
      "y": 19,
      "z": -8,
      "name": "Rock_Stone"
    },
    {
      "x": -9,
      "y": 20,
      "z": -8,
      "name": "Rock_Calcite"
    },
    {
      "x": -9,
      "y": 21,
      "z": -8,
      "name": "Rock_Calcite"
    },
    {
      "x": -9,
      "y": 22,
      "z": -8,
      "name": "Rock_Calcite"
    },
    {
      "x": -9,
      "y": 23,
      "z": -8,
      "name": "Plant_Moss_Rug_Green"
    },
    {
      "x": -9,
      "y": 19,
      "z": -7,
      "name": "Rock_Stone"
    },
    {
      "x": -9,
      "y": 20,
      "z": -7,
      "name": "Rock_Marble"
    },
    {
      "x": -9,
      "y": 21,
      "z": -7,
      "name": "Rock_Calcite"
    },
    {
      "x": -9,
      "y": 22,
      "z": -7,
      "name": "Rock_Calcite"
    },
    {
      "x": -9,
      "y": 19,
      "z": -6,
      "name": "Rock_Stone"
    },
    {
      "x": -9,
      "y": 20,
      "z": -6,
      "name": "Rock_Marble"
    },
    {
      "x": -9,
      "y": 21,
      "z": -6,
      "name": "Rock_Marble"
    },
    {
      "x": -9,
      "y": 22,
      "z": -6,
      "name": "Rock_Marble"
    },
    {
      "x": -9,
      "y": 23,
      "z": -6,
      "name": "Rock_Calcite"
    },
    {
      "x": -9,
      "y": 20,
      "z": -5,
      "name": "Rock_Stone"
    },
    {
      "x": -9,
      "y": 21,
      "z": -5,
      "name": "Rock_Marble"
    },
    {
      "x": -9,
      "y": 22,
      "z": -5,
      "name": "Rock_Marble"
    },
    {
      "x": -9,
      "y": 23,
      "z": -5,
      "name": "Rock_Calcite"
    },
    {
      "x": -9,
      "y": 20,
      "z": -4,
      "name": "Rock_Stone"
    },
    {
      "x": -9,
      "y": 21,
      "z": -4,
      "name": "Rock_Marble"
    },
    {
      "x": -9,
      "y": 22,
      "z": -4,
      "name": "Rock_Marble"
    },
    {
      "x": -9,
      "y": 23,
      "z": -4,
      "name": "Rock_Calcite"
    },
    {
      "x": -9,
      "y": 20,
      "z": -3,
      "name": "Rock_Stone"
    },
    {
      "x": -9,
      "y": 21,
      "z": -3,
      "name": "Rock_Marble"
    },
    {
      "x": -9,
      "y": 22,
      "z": -3,
      "name": "Rock_Marble"
    },
    {
      "x": -9,
      "y": 23,
      "z": -3,
      "name": "Rock_Calcite"
    },
    {
      "x": -9,
      "y": 24,
      "z": -3,
      "name": "Rock_Calcite"
    },
    {
      "x": -9,
      "y": 20,
      "z": -2,
      "name": "Rock_Stone"
    },
    {
      "x": -9,
      "y": 21,
      "z": -2,
      "name": "Rock_Marble"
    },
    {
      "x": -9,
      "y": 22,
      "z": -2,
      "name": "Rock_Marble"
    },
    {
      "x": -9,
      "y": 23,
      "z": -2,
      "name": "Rock_Calcite"
    },
    {
      "x": -9,
      "y": 24,
      "z": -2,
      "name": "Rock_Calcite"
    },
    {
      "x": -9,
      "y": 20,
      "z": -1,
      "name": "Rock_Stone"
    },
    {
      "x": -9,
      "y": 21,
      "z": -1,
      "name": "Rock_Stone"
    },
    {
      "x": -9,
      "y": 22,
      "z": -1,
      "name": "Rock_Marble"
    },
    {
      "x": -9,
      "y": 23,
      "z": -1,
      "name": "Rock_Calcite"
    },
    {
      "x": -9,
      "y": 24,
      "z": -1,
      "name": "Rock_Calcite"
    },
    {
      "x": -9,
      "y": 21,
      "z": 2,
      "name": "Plant_Moss_Block_Green"
    },
    {
      "x": -9,
      "y": 22,
      "z": 2,
      "name": "Plant_Moss_Block_Green"
    },
    {
      "x": -9,
      "y": 23,
      "z": 2,
      "name": "Plant_Moss_Block_Green"
    },
    {
      "x": -9,
      "y": 24,
      "z": 2,
      "name": "Plant_Moss_Block_Green"
    },
    {
      "x": -9,
      "y": 25,
      "z": 2,
      "name": "Plant_Moss_Rug_Green"
    },
    {
      "x": -9,
      "y": 21,
      "z": 3,
      "name": "Rock_Stone"
    },
    {
      "x": -9,
      "y": 22,
      "z": 3,
      "name": "Plant_Moss_Block_Green"
    },
    {
      "x": -9,
      "y": 23,
      "z": 3,
      "name": "Plant_Moss_Block_Green"
    },
    {
      "x": -9,
      "y": 24,
      "z": 3,
      "name": "Plant_Moss_Block_Green"
    },
    {
      "x": -9,
      "y": 21,
      "z": 4,
      "name": "Rock_Stone"
    },
    {
      "x": -9,
      "y": 22,
      "z": 4,
      "name": "Rock_Marble"
    },
    {
      "x": -9,
      "y": 23,
      "z": 4,
      "name": "Rock_Calcite"
    },
    {
      "x": -9,
      "y": 24,
      "z": 4,
      "name": "Rock_Calcite"
    },
    {
      "x": -9,
      "y": 20,
      "z": 5,
      "name": "Rock_Stone"
    },
    {
      "x": -9,
      "y": 21,
      "z": 5,
      "name": "Rock_Marble"
    },
    {
      "x": -9,
      "y": 22,
      "z": 5,
      "name": "Rock_Marble"
    },
    {
      "x": -9,
      "y": 23,
      "z": 5,
      "name": "Rock_Calcite"
    },
    {
      "x": -9,
      "y": 24,
      "z": 5,
      "name": "Rock_Calcite"
    },
    {
      "x": -9,
      "y": 20,
      "z": 6,
      "name": "Rock_Stone"
    },
    {
      "x": -9,
      "y": 21,
      "z": 6,
      "name": "Rock_Marble"
    },
    {
      "x": -9,
      "y": 22,
      "z": 6,
      "name": "Rock_Marble"
    },
    {
      "x": -9,
      "y": 23,
      "z": 6,
      "name": "Rock_Calcite"
    },
    {
      "x": -9,
      "y": 19,
      "z": 7,
      "name": "Rock_Stone"
    },
    {
      "x": -9,
      "y": 20,
      "z": 7,
      "name": "Rock_Marble"
    },
    {
      "x": -9,
      "y": 21,
      "z": 7,
      "name": "Rock_Marble"
    },
    {
      "x": -9,
      "y": 22,
      "z": 7,
      "name": "Rock_Marble"
    },
    {
      "x": -9,
      "y": 18,
      "z": 8,
      "name": "Rock_Stone"
    },
    {
      "x": -9,
      "y": 19,
      "z": 8,
      "name": "Rock_Marble"
    },
    {
      "x": -9,
      "y": 20,
      "z": 8,
      "name": "Rock_Marble"
    },
    {
      "x": -9,
      "y": 21,
      "z": 8,
      "name": "Rock_Marble"
    },
    {
      "x": -9,
      "y": 17,
      "z": 9,
      "name": "Rock_Stone"
    },
    {
      "x": -9,
      "y": 18,
      "z": 9,
      "name": "Rock_Marble"
    },
    {
      "x": -9,
      "y": 19,
      "z": 9,
      "name": "Rock_Marble"
    },
    {
      "x": -9,
      "y": 20,
      "z": 9,
      "name": "Rock_Marble"
    },
    {
      "x": -9,
      "y": 16,
      "z": 10,
      "name": "Rock_Stone"
    },
    {
      "x": -9,
      "y": 17,
      "z": 10,
      "name": "Rock_Marble"
    },
    {
      "x": -9,
      "y": 18,
      "z": 10,
      "name": "Rock_Marble"
    },
    {
      "x": -9,
      "y": 19,
      "z": 10,
      "name": "Rock_Marble"
    },
    {
      "x": -9,
      "y": 15,
      "z": 11,
      "name": "Rock_Stone"
    },
    {
      "x": -9,
      "y": 16,
      "z": 11,
      "name": "Rock_Marble"
    },
    {
      "x": -9,
      "y": 17,
      "z": 11,
      "name": "Rock_Marble"
    },
    {
      "x": -9,
      "y": 18,
      "z": 11,
      "name": "Rock_Marble"
    },
    {
      "x": -9,
      "y": 14,
      "z": 12,
      "name": "Rock_Stone"
    },
    {
      "x": -9,
      "y": 15,
      "z": 12,
      "name": "Rock_Marble"
    },
    {
      "x": -9,
      "y": 16,
      "z": 12,
      "name": "Rock_Marble"
    },
    {
      "x": -9,
      "y": 17,
      "z": 12,
      "name": "Rock_Marble"
    },
    {
      "x": -9,
      "y": 13,
      "z": 13,
      "name": "Rock_Stone"
    },
    {
      "x": -9,
      "y": 14,
      "z": 13,
      "name": "Rock_Marble"
    },
    {
      "x": -9,
      "y": 15,
      "z": 13,
      "name": "Rock_Marble"
    },
    {
      "x": -9,
      "y": 16,
      "z": 13,
      "name": "Rock_Marble"
    },
    {
      "x": -9,
      "y": 12,
      "z": 14,
      "name": "Rock_Stone"
    },
    {
      "x": -9,
      "y": 13,
      "z": 14,
      "name": "Rock_Marble"
    },
    {
      "x": -9,
      "y": 14,
      "z": 14,
      "name": "Rock_Marble"
    },
    {
      "x": -9,
      "y": 15,
      "z": 14,
      "name": "Rock_Marble"
    },
    {
      "x": -9,
      "y": 13,
      "z": 15,
      "name": "Rock_Stone"
    },
    {
      "x": -9,
      "y": 14,
      "z": 15,
      "name": "Rock_Stone"
    },
    {
      "x": -8,
      "y": 19,
      "z": -9,
      "name": "Plant_Moss_Block_Green"
    },
    {
      "x": -8,
      "y": 20,
      "z": -9,
      "name": "Plant_Moss_Block_Green"
    },
    {
      "x": -8,
      "y": 21,
      "z": -9,
      "name": "Plant_Moss_Block_Green"
    },
    {
      "x": -8,
      "y": 22,
      "z": -9,
      "name": "Plant_Moss_Block_Green"
    },
    {
      "x": -8,
      "y": 23,
      "z": -9,
      "name": "Plant_Moss_Rug_Green"
    },
    {
      "x": -8,
      "y": 19,
      "z": -8,
      "name": "Rock_Stone"
    },
    {
      "x": -8,
      "y": 20,
      "z": -8,
      "name": "Plant_Moss_Block_Green"
    },
    {
      "x": -8,
      "y": 21,
      "z": -8,
      "name": "Plant_Moss_Block_Green"
    },
    {
      "x": -8,
      "y": 22,
      "z": -8,
      "name": "Plant_Moss_Block_Green"
    },
    {
      "x": -8,
      "y": 23,
      "z": -8,
      "name": "Plant_Moss_Rug_Green"
    },
    {
      "x": -8,
      "y": 19,
      "z": -7,
      "name": "Rock_Stone"
    },
    {
      "x": -8,
      "y": 20,
      "z": -7,
      "name": "Rock_Marble"
    },
    {
      "x": -8,
      "y": 21,
      "z": -7,
      "name": "Rock_Calcite"
    },
    {
      "x": -8,
      "y": 22,
      "z": -7,
      "name": "Rock_Calcite"
    },
    {
      "x": -8,
      "y": 23,
      "z": -7,
      "name": "Rock_Calcite"
    },
    {
      "x": -8,
      "y": 20,
      "z": -6,
      "name": "Rock_Stone"
    },
    {
      "x": -8,
      "y": 21,
      "z": -6,
      "name": "Rock_Marble"
    },
    {
      "x": -8,
      "y": 22,
      "z": -6,
      "name": "Rock_Calcite"
    },
    {
      "x": -8,
      "y": 23,
      "z": -6,
      "name": "Rock_Calcite"
    },
    {
      "x": -8,
      "y": 20,
      "z": -5,
      "name": "Rock_Stone"
    },
    {
      "x": -8,
      "y": 21,
      "z": -5,
      "name": "Rock_Marble"
    },
    {
      "x": -8,
      "y": 22,
      "z": -5,
      "name": "Rock_Calcite"
    },
    {
      "x": -8,
      "y": 23,
      "z": -5,
      "name": "Rock_Calcite"
    },
    {
      "x": -8,
      "y": 24,
      "z": -5,
      "name": "Rock_Calcite"
    },
    {
      "x": -8,
      "y": 25,
      "z": -5,
      "name": "Plant_Moss_Rug_Green"
    },
    {
      "x": -8,
      "y": 21,
      "z": -4,
      "name": "Rock_Stone"
    },
    {
      "x": -8,
      "y": 22,
      "z": -4,
      "name": "Rock_Marble"
    },
    {
      "x": -8,
      "y": 23,
      "z": -4,
      "name": "Rock_Calcite"
    },
    {
      "x": -8,
      "y": 24,
      "z": -4,
      "name": "Rock_Calcite"
    },
    {
      "x": -8,
      "y": 21,
      "z": -3,
      "name": "Rock_Stone"
    },
    {
      "x": -8,
      "y": 22,
      "z": -3,
      "name": "Rock_Marble"
    },
    {
      "x": -8,
      "y": 23,
      "z": -3,
      "name": "Rock_Calcite"
    },
    {
      "x": -8,
      "y": 24,
      "z": -3,
      "name": "Rock_Calcite"
    },
    {
      "x": -8,
      "y": 21,
      "z": -2,
      "name": "Rock_Stone"
    },
    {
      "x": -8,
      "y": 22,
      "z": -2,
      "name": "Rock_Stone"
    },
    {
      "x": -8,
      "y": 23,
      "z": -2,
      "name": "Rock_Calcite"
    },
    {
      "x": -8,
      "y": 24,
      "z": -2,
      "name": "Rock_Calcite"
    },
    {
      "x": -8,
      "y": 25,
      "z": 0,
      "name": "Plant_Moss_Wall_Green",
      "rotation": 3
    },
    {
      "x": -8,
      "y": 21,
      "z": 1,
      "name": "Plant_Moss_Block_Green"
    },
    {
      "x": -8,
      "y": 22,
      "z": 1,
      "name": "Plant_Moss_Block_Green"
    },
    {
      "x": -8,
      "y": 23,
      "z": 1,
      "name": "Plant_Moss_Block_Green"
    },
    {
      "x": -8,
      "y": 24,
      "z": 1,
      "name": "Plant_Moss_Block_Green"
    },
    {
      "x": -8,
      "y": 25,
      "z": 1,
      "name": "Plant_Moss_Rug_Green"
    },
    {
      "x": -8,
      "y": 21,
      "z": 2,
      "name": "Rock_Stone"
    },
    {
      "x": -8,
      "y": 22,
      "z": 2,
      "name": "Plant_Moss_Block_Green"
    },
    {
      "x": -8,
      "y": 23,
      "z": 2,
      "name": "Plant_Moss_Block_Green"
    },
    {
      "x": -8,
      "y": 24,
      "z": 2,
      "name": "Plant_Moss_Block_Green"
    },
    {
      "x": -8,
      "y": 25,
      "z": 2,
      "name": "Plant_Moss_Rug_Green"
    },
    {
      "x": -8,
      "y": 21,
      "z": 3,
      "name": "Rock_Stone"
    },
    {
      "x": -8,
      "y": 22,
      "z": 3,
      "name": "Rock_Marble"
    },
    {
      "x": -8,
      "y": 23,
      "z": 3,
      "name": "Rock_Calcite"
    },
    {
      "x": -8,
      "y": 24,
      "z": 3,
      "name": "Rock_Calcite"
    },
    {
      "x": -8,
      "y": 21,
      "z": 4,
      "name": "Rock_Stone"
    },
    {
      "x": -8,
      "y": 22,
      "z": 4,
      "name": "Rock_Marble"
    },
    {
      "x": -8,
      "y": 23,
      "z": 4,
      "name": "Rock_Calcite"
    },
    {
      "x": -8,
      "y": 24,
      "z": 4,
      "name": "Rock_Calcite"
    },
    {
      "x": -8,
      "y": 20,
      "z": 5,
      "name": "Rock_Stone"
    },
    {
      "x": -8,
      "y": 21,
      "z": 5,
      "name": "Rock_Marble"
    },
    {
      "x": -8,
      "y": 22,
      "z": 5,
      "name": "Rock_Marble"
    },
    {
      "x": -8,
      "y": 23,
      "z": 5,
      "name": "Rock_Calcite"
    },
    {
      "x": -8,
      "y": 24,
      "z": 5,
      "name": "Rock_Calcite"
    },
    {
      "x": -8,
      "y": 20,
      "z": 6,
      "name": "Rock_Stone"
    },
    {
      "x": -8,
      "y": 21,
      "z": 6,
      "name": "Rock_Marble"
    },
    {
      "x": -8,
      "y": 22,
      "z": 6,
      "name": "Rock_Marble"
    },
    {
      "x": -8,
      "y": 23,
      "z": 6,
      "name": "Rock_Calcite"
    },
    {
      "x": -8,
      "y": 19,
      "z": 7,
      "name": "Rock_Stone"
    },
    {
      "x": -8,
      "y": 20,
      "z": 7,
      "name": "Rock_Marble"
    },
    {
      "x": -8,
      "y": 21,
      "z": 7,
      "name": "Rock_Marble"
    },
    {
      "x": -8,
      "y": 22,
      "z": 7,
      "name": "Rock_Marble"
    },
    {
      "x": -8,
      "y": 18,
      "z": 8,
      "name": "Rock_Stone"
    },
    {
      "x": -8,
      "y": 19,
      "z": 8,
      "name": "Rock_Marble"
    },
    {
      "x": -8,
      "y": 20,
      "z": 8,
      "name": "Rock_Marble"
    },
    {
      "x": -8,
      "y": 21,
      "z": 8,
      "name": "Rock_Marble"
    },
    {
      "x": -8,
      "y": 17,
      "z": 9,
      "name": "Rock_Stone"
    },
    {
      "x": -8,
      "y": 18,
      "z": 9,
      "name": "Rock_Marble"
    },
    {
      "x": -8,
      "y": 19,
      "z": 9,
      "name": "Rock_Marble"
    },
    {
      "x": -8,
      "y": 20,
      "z": 9,
      "name": "Rock_Marble"
    },
    {
      "x": -8,
      "y": 21,
      "z": 9,
      "name": "Rock_Marble"
    },
    {
      "x": -8,
      "y": 17,
      "z": 10,
      "name": "Rock_Stone"
    },
    {
      "x": -8,
      "y": 18,
      "z": 10,
      "name": "Rock_Marble"
    },
    {
      "x": -8,
      "y": 19,
      "z": 10,
      "name": "Rock_Marble"
    },
    {
      "x": -8,
      "y": 20,
      "z": 10,
      "name": "Rock_Marble"
    },
    {
      "x": -8,
      "y": 16,
      "z": 11,
      "name": "Rock_Stone"
    },
    {
      "x": -8,
      "y": 17,
      "z": 11,
      "name": "Rock_Marble"
    },
    {
      "x": -8,
      "y": 18,
      "z": 11,
      "name": "Rock_Marble"
    },
    {
      "x": -8,
      "y": 19,
      "z": 11,
      "name": "Rock_Marble"
    },
    {
      "x": -8,
      "y": 15,
      "z": 12,
      "name": "Rock_Stone"
    },
    {
      "x": -8,
      "y": 16,
      "z": 12,
      "name": "Rock_Marble"
    },
    {
      "x": -8,
      "y": 17,
      "z": 12,
      "name": "Rock_Marble"
    },
    {
      "x": -8,
      "y": 18,
      "z": 12,
      "name": "Rock_Marble"
    },
    {
      "x": -8,
      "y": 14,
      "z": 13,
      "name": "Rock_Stone"
    },
    {
      "x": -8,
      "y": 15,
      "z": 13,
      "name": "Rock_Marble"
    },
    {
      "x": -8,
      "y": 16,
      "z": 13,
      "name": "Rock_Marble"
    },
    {
      "x": -8,
      "y": 12,
      "z": 14,
      "name": "Rock_Stone"
    },
    {
      "x": -8,
      "y": 13,
      "z": 14,
      "name": "Rock_Stone"
    },
    {
      "x": -8,
      "y": 14,
      "z": 14,
      "name": "Plant_Moss_Block_Green"
    },
    {
      "x": -8,
      "y": 15,
      "z": 14,
      "name": "Plant_Moss_Block_Green"
    },
    {
      "x": -8,
      "y": 13,
      "z": 15,
      "name": "Rock_Stone"
    },
    {
      "x": -8,
      "y": 14,
      "z": 15,
      "name": "Rock_Stone"
    },
    {
      "x": -7,
      "y": 22,
      "z": -9,
      "name": "Plant_Moss_Wall_Green",
      "rotation": 2
    },
    {
      "x": -7,
      "y": 23,
      "z": -9,
      "name": "Plant_Moss_Wall_Green",
      "rotation": 2
    },
    {
      "x": -7,
      "y": 19,
      "z": -8,
      "name": "Rock_Stone"
    },
    {
      "x": -7,
      "y": 20,
      "z": -8,
      "name": "Rock_Stone"
    },
    {
      "x": -7,
      "y": 21,
      "z": -8,
      "name": "Plant_Moss_Block_Green"
    },
    {
      "x": -7,
      "y": 22,
      "z": -8,
      "name": "Plant_Moss_Block_Green"
    },
    {
      "x": -7,
      "y": 23,
      "z": -8,
      "name": "Plant_Moss_Block_Green"
    },
    {
      "x": -7,
      "y": 20,
      "z": -7,
      "name": "Rock_Stone"
    },
    {
      "x": -7,
      "y": 21,
      "z": -7,
      "name": "Plant_Moss_Block_Green"
    },
    {
      "x": -7,
      "y": 22,
      "z": -7,
      "name": "Plant_Moss_Block_Green"
    },
    {
      "x": -7,
      "y": 23,
      "z": -7,
      "name": "Plant_Moss_Block_Green"
    },
    {
      "x": -7,
      "y": 20,
      "z": -6,
      "name": "Rock_Stone"
    },
    {
      "x": -7,
      "y": 21,
      "z": -6,
      "name": "Rock_Marble"
    },
    {
      "x": -7,
      "y": 22,
      "z": -6,
      "name": "Rock_Calcite"
    },
    {
      "x": -7,
      "y": 23,
      "z": -6,
      "name": "Rock_Calcite"
    },
    {
      "x": -7,
      "y": 24,
      "z": -6,
      "name": "Rock_Calcite"
    },
    {
      "x": -7,
      "y": 25,
      "z": -6,
      "name": "Plant_Moss_Rug_Green"
    },
    {
      "x": -7,
      "y": 21,
      "z": -5,
      "name": "Rock_Stone"
    },
    {
      "x": -7,
      "y": 22,
      "z": -5,
      "name": "Rock_Calcite"
    },
    {
      "x": -7,
      "y": 23,
      "z": -5,
      "name": "Rock_Calcite"
    },
    {
      "x": -7,
      "y": 24,
      "z": -5,
      "name": "Rock_Calcite"
    },
    {
      "x": -7,
      "y": 21,
      "z": -4,
      "name": "Rock_Stone"
    },
    {
      "x": -7,
      "y": 22,
      "z": -4,
      "name": "Rock_Calcite"
    },
    {
      "x": -7,
      "y": 23,
      "z": -4,
      "name": "Rock_Calcite"
    },
    {
      "x": -7,
      "y": 24,
      "z": -4,
      "name": "Rock_Calcite"
    },
    {
      "x": -7,
      "y": 21,
      "z": -3,
      "name": "Rock_Stone"
    },
    {
      "x": -7,
      "y": 22,
      "z": -3,
      "name": "Rock_Stone"
    },
    {
      "x": -7,
      "y": 23,
      "z": -3,
      "name": "Rock_Calcite"
    },
    {
      "x": -7,
      "y": 24,
      "z": -3,
      "name": "Rock_Calcite"
    },
    {
      "x": -7,
      "y": 25,
      "z": -3,
      "name": "Rock_Calcite"
    },
    {
      "x": -7,
      "y": 26,
      "z": -3,
      "name": "Plant_Moss_Rug_Green"
    },
    {
      "x": -7,
      "y": 23,
      "z": -2,
      "name": "Rock_Stone"
    },
    {
      "x": -7,
      "y": 24,
      "z": -2,
      "name": "Rock_Calcite"
    },
    {
      "x": -7,
      "y": 25,
      "z": -2,
      "name": "Rock_Calcite"
    },
    {
      "x": -7,
      "y": 26,
      "z": -2,
      "name": "Plant_Moss_Rug_Green"
    },
    {
      "x": -7,
      "y": 25,
      "z": -1,
      "name": "Plant_Moss_Wall_Green",
      "rotation": 2
    },
    {
      "x": -7,
      "y": 25,
      "z": 0,
      "name": "Plant_Moss_Block_Green"
    },
    {
      "x": -7,
      "y": 26,
      "z": 0,
      "name": "Plant_Moss_Rug_Green"
    },
    {
      "x": -7,
      "y": 21,
      "z": 1,
      "name": "Rock_Stone"
    },
    {
      "x": -7,
      "y": 22,
      "z": 1,
      "name": "Plant_Moss_Block_Green"
    },
    {
      "x": -7,
      "y": 23,
      "z": 1,
      "name": "Plant_Moss_Block_Green"
    },
    {
      "x": -7,
      "y": 24,
      "z": 1,
      "name": "Plant_Moss_Block_Green"
    },
    {
      "x": -7,
      "y": 25,
      "z": 1,
      "name": "Plant_Moss_Block_Green"
    },
    {
      "x": -7,
      "y": 26,
      "z": 1,
      "name": "Plant_Moss_Rug_Green"
    },
    {
      "x": -7,
      "y": 21,
      "z": 2,
      "name": "Rock_Stone"
    },
    {
      "x": -7,
      "y": 22,
      "z": 2,
      "name": "Rock_Marble"
    },
    {
      "x": -7,
      "y": 23,
      "z": 2,
      "name": "Rock_Calcite"
    },
    {
      "x": -7,
      "y": 24,
      "z": 2,
      "name": "Rock_Calcite"
    },
    {
      "x": -7,
      "y": 25,
      "z": 2,
      "name": "Rock_Calcite"
    },
    {
      "x": -7,
      "y": 21,
      "z": 3,
      "name": "Rock_Stone"
    },
    {
      "x": -7,
      "y": 22,
      "z": 3,
      "name": "Rock_Marble"
    },
    {
      "x": -7,
      "y": 23,
      "z": 3,
      "name": "Rock_Calcite"
    },
    {
      "x": -7,
      "y": 24,
      "z": 3,
      "name": "Rock_Calcite"
    },
    {
      "x": -7,
      "y": 25,
      "z": 3,
      "name": "Rock_Calcite"
    },
    {
      "x": -7,
      "y": 21,
      "z": 4,
      "name": "Rock_Stone"
    },
    {
      "x": -7,
      "y": 22,
      "z": 4,
      "name": "Rock_Marble"
    },
    {
      "x": -7,
      "y": 23,
      "z": 4,
      "name": "Rock_Calcite"
    },
    {
      "x": -7,
      "y": 24,
      "z": 4,
      "name": "Rock_Calcite"
    },
    {
      "x": -7,
      "y": 20,
      "z": 5,
      "name": "Rock_Stone"
    },
    {
      "x": -7,
      "y": 21,
      "z": 5,
      "name": "Rock_Marble"
    },
    {
      "x": -7,
      "y": 22,
      "z": 5,
      "name": "Rock_Marble"
    },
    {
      "x": -7,
      "y": 23,
      "z": 5,
      "name": "Rock_Calcite"
    },
    {
      "x": -7,
      "y": 24,
      "z": 5,
      "name": "Rock_Calcite"
    },
    {
      "x": -7,
      "y": 20,
      "z": 6,
      "name": "Rock_Stone"
    },
    {
      "x": -7,
      "y": 21,
      "z": 6,
      "name": "Rock_Marble"
    },
    {
      "x": -7,
      "y": 22,
      "z": 6,
      "name": "Rock_Marble"
    },
    {
      "x": -7,
      "y": 23,
      "z": 6,
      "name": "Rock_Calcite"
    },
    {
      "x": -7,
      "y": 19,
      "z": 7,
      "name": "Rock_Stone"
    },
    {
      "x": -7,
      "y": 20,
      "z": 7,
      "name": "Rock_Marble"
    },
    {
      "x": -7,
      "y": 21,
      "z": 7,
      "name": "Rock_Marble"
    },
    {
      "x": -7,
      "y": 22,
      "z": 7,
      "name": "Rock_Marble"
    },
    {
      "x": -7,
      "y": 18,
      "z": 8,
      "name": "Rock_Stone"
    },
    {
      "x": -7,
      "y": 19,
      "z": 8,
      "name": "Rock_Marble"
    },
    {
      "x": -7,
      "y": 20,
      "z": 8,
      "name": "Rock_Marble"
    },
    {
      "x": -7,
      "y": 21,
      "z": 8,
      "name": "Rock_Marble"
    },
    {
      "x": -7,
      "y": 22,
      "z": 8,
      "name": "Rock_Marble"
    },
    {
      "x": -7,
      "y": 18,
      "z": 9,
      "name": "Rock_Stone"
    },
    {
      "x": -7,
      "y": 19,
      "z": 9,
      "name": "Rock_Marble"
    },
    {
      "x": -7,
      "y": 20,
      "z": 9,
      "name": "Rock_Marble"
    },
    {
      "x": -7,
      "y": 21,
      "z": 9,
      "name": "Rock_Marble"
    },
    {
      "x": -7,
      "y": 17,
      "z": 10,
      "name": "Rock_Stone"
    },
    {
      "x": -7,
      "y": 18,
      "z": 10,
      "name": "Rock_Marble"
    },
    {
      "x": -7,
      "y": 19,
      "z": 10,
      "name": "Rock_Marble"
    },
    {
      "x": -7,
      "y": 20,
      "z": 10,
      "name": "Rock_Marble"
    },
    {
      "x": -7,
      "y": 16,
      "z": 11,
      "name": "Rock_Stone"
    },
    {
      "x": -7,
      "y": 17,
      "z": 11,
      "name": "Rock_Marble"
    },
    {
      "x": -7,
      "y": 18,
      "z": 11,
      "name": "Rock_Marble"
    },
    {
      "x": -7,
      "y": 19,
      "z": 11,
      "name": "Rock_Marble"
    },
    {
      "x": -7,
      "y": 15,
      "z": 12,
      "name": "Rock_Stone"
    },
    {
      "x": -7,
      "y": 16,
      "z": 12,
      "name": "Rock_Marble"
    },
    {
      "x": -7,
      "y": 17,
      "z": 12,
      "name": "Rock_Marble"
    },
    {
      "x": -7,
      "y": 18,
      "z": 12,
      "name": "Rock_Marble"
    },
    {
      "x": -7,
      "y": 14,
      "z": 13,
      "name": "Plant_Moss_Block_Green"
    },
    {
      "x": -7,
      "y": 15,
      "z": 13,
      "name": "Plant_Moss_Block_Green"
    },
    {
      "x": -7,
      "y": 16,
      "z": 13,
      "name": "Plant_Moss_Block_Green"
    },
    {
      "x": -7,
      "y": 17,
      "z": 13,
      "name": "Plant_Moss_Block_Green"
    },
    {
      "x": -7,
      "y": 15,
      "z": 14,
      "name": "Plant_Moss_Block_Green"
    },
    {
      "x": -7,
      "y": 16,
      "z": 14,
      "name": "Plant_Moss_Block_Green"
    },
    {
      "x": -6,
      "y": 23,
      "z": -9,
      "name": "Plant_Moss_Wall_Green",
      "rotation": 2
    },
    {
      "x": -6,
      "y": 22,
      "z": -8,
      "name": "Plant_Moss_Cave_Green",
      "rotation": 8
    },
    {
      "x": -6,
      "y": 23,
      "z": -8,
      "name": "Plant_Moss_Block_Green"
    },
    {
      "x": -6,
      "y": 24,
      "z": -8,
      "name": "Plant_Moss_Rug_Green"
    },
    {
      "x": -6,
      "y": 20,
      "z": -7,
      "name": "Plant_Moss_Block_Green"
    },
    {
      "x": -6,
      "y": 21,
      "z": -7,
      "name": "Plant_Moss_Block_Green"
    },
    {
      "x": -6,
      "y": 22,
      "z": -7,
      "name": "Plant_Moss_Block_Green"
    },
