{
  "version": 8,
  "blockIdVersion": 8,
  "anchorX": 0,
  "anchorY": 5,
  "anchorZ": -1,
  "blocks": [
    {
      "x": -8,
      "y": 3,
      "z": -5,
      "name": "Rock_Sandstone_Red"
    },
    {
      "x": -8,
      "y": 4,
      "z": -5,
      "name": "Soil_Hive"
    },
    {
      "x": -8,
      "y": 5,
      "z": -5,
      "name": "Soil_Hive"
    },
    {
      "x": -8,
      "y": 3,
      "z": -4,
      "name": "Rock_Sandstone_Red"
    },
    {
      "x": -8,
      "y": 4,
      "z": -4,
      "name": "Rock_Sandstone_Red"
    },
    {
      "x": -8,
      "y": 5,
      "z": -4,
      "name": "Soil_Hive"
    },
    {
      "x": -8,
      "y": 6,
      "z": -4,
      "name": "Soil_Hive"
    },
    {
      "x": -8,
      "y": 7,
      "z": -4,
      "name": "Soil_Hive"
    },
    {
      "x": -8,
      "y": 3,
      "z": -3,
      "name": "Rock_Sandstone_Red"
    },
    {
      "x": -8,
      "y": 4,
      "z": -3,
      "name": "Rock_Sandstone_Red"
    },
    {
      "x": -8,
      "y": 5,
      "z": -3,
      "name": "Rock_Sandstone_Red"
    },
    {
      "x": -8,
      "y": 6,
      "z": -3,
      "name": "Soil_Clay"
    },
    {
      "x": -8,
      "y": 7,
      "z": -3,
      "name": "Soil_Hive"
    },
    {
      "x": -8,
      "y": 3,
      "z": -2,
      "name": "Rock_Sandstone_Red"
    },
    {
      "x": -8,
      "y": 4,
      "z": -2,
      "name": "Rock_Sandstone_Red"
    },
    {
      "x": -8,
      "y": 5,
      "z": -2,
      "name": "Rock_Sandstone_Red"
    },
    {
      "x": -8,
      "y": 6,
      "z": -2,
      "name": "Soil_Clay"
    },
    {
      "x": -8,
      "y": 7,
      "z": -2,
      "name": "Soil_Hive"
    },
    {
      "x": -8,
      "y": 8,
      "z": -2,
      "name": "Soil_Hive"
    },
    {
      "x": -8,
      "y": 3,
      "z": -1,
      "name": "Rock_Sandstone_Red"
    },
    {
      "x": -8,
      "y": 4,
      "z": -1,
      "name": "Rock_Sandstone_Red"
    },
    {
      "x": -8,
      "y": 5,
      "z": -1,
      "name": "Rock_Sandstone_Red"
    },
    {
      "x": -8,
      "y": 6,
      "z": -1,
      "name": "Soil_Clay"
    },
    {
      "x": -8,
      "y": 7,
      "z": -1,
      "name": "Rock_Sandstone_Red"
    },
    {
      "x": -8,
      "y": 8,
      "z": -1,
      "name": "Rock_Sandstone_Red"
    },
    {
      "x": -8,
      "y": 3,
      "z": 0,
      "name": "Rock_Sandstone_Red"
    },
    {
      "x": -8,
      "y": 4,
      "z": 0,
      "name": "Rock_Sandstone_Red"
    },
    {
      "x": -8,
      "y": 5,
      "z": 0,
      "name": "Soil_Hive"
    },
    {
      "x": -8,
      "y": 6,
      "z": 0,
      "name": "Soil_Hive"
    },
    {
      "x": -8,
      "y": 7,
      "z": 0,
      "name": "Rock_Sandstone_Red"
    },
    {
      "x": -8,
      "y": 8,
      "z": 0,
      "name": "Rock_Sandstone_Red"
    },
    {
      "x": -8,
      "y": 3,
      "z": 1,
      "name": "Rock_Sandstone_Red"
    },
    {
      "x": -8,
      "y": 4,
      "z": 1,
      "name": "Rock_Sandstone_Red"
    },
    {
      "x": -8,
      "y": 5,
      "z": 1,
      "name": "Rock_Sandstone_Red"
    },
    {
      "x": -8,
      "y": 6,
      "z": 1,
      "name": "Soil_Hive"
    },
    {
      "x": -8,
      "y": 7,
      "z": 1,
      "name": "Soil_Hive"
    },
    {
      "x": -8,
      "y": 8,
      "z": 1,
      "name": "Soil_Hive"
    },
    {
      "x": -8,
      "y": 3,
      "z": 3,
      "name": "Rock_Sandstone_Red"
    },
    {
      "x": -8,
      "y": 4,
      "z": 3,
      "name": "Rock_Sandstone_Red"
    },
    {
      "x": -8,
      "y": 5,
      "z": 3,
      "name": "Rock_Sandstone_Red"
    },
    {
      "x": -8,
      "y": 6,
      "z": 3,
      "name": "Rock_Sandstone_Red"
    },
    {
      "x": -8,
      "y": 7,
      "z": 3,
      "name": "Soil_Clay"
    },
    {
      "x": -8,
      "y": 8,
      "z": 3,
      "name": "Soil_Hive"
    },
    {
      "x": -8,
      "y": 3,
      "z": 4,
      "name": "Rock_Sandstone_Red"
    },
    {
      "x": -8,
      "y": 4,
      "z": 4,
      "name": "Rock_Sandstone_Red"
    },
    {
      "x": -8,
      "y": 5,
      "z": 4,
      "name": "Rock_Sandstone_Red"
    },
    {
      "x": -8,
      "y": 6,
      "z": 4,
      "name": "Rock_Sandstone_Red"
    },
    {
      "x": -8,
      "y": 7,
      "z": 4,
      "name": "Soil_Clay"
    },
    {
      "x": -8,
      "y": 8,
      "z": 4,
      "name": "Rock_Sandstone_Red"
    },
    {
      "x": -8,
      "y": 3,
      "z": 5,
      "name": "Rock_Sandstone_Red"
    },
    {
      "x": -8,
      "y": 4,
      "z": 5,
      "name": "Rock_Sandstone_Red"
    },
    {
      "x": -8,
      "y": 5,
      "z": 5,
      "name": "Rock_Sandstone_Red"
    },
    {
      "x": -8,
      "y": 6,
      "z": 5,
      "name": "Rock_Sandstone_Red"
    },
    {
      "x": -8,
      "y": 7,
      "z": 5,
      "name": "Soil_Clay"
    },
    {
      "x": -8,
      "y": 8,
      "z": 5,
      "name": "Rock_Sandstone_Red"
    },
    {
      "x": -8,
      "y": 9,
      "z": 5,
      "name": "Soil_Mud_Dry"
    },
    {
      "x": -8,
      "y": 4,
      "z": 6,
      "name": "Rock_Sandstone_Red"
    },
    {
      "x": -8,
      "y": 5,
      "z": 6,
      "name": "Rock_Sandstone_Red"
    },
    {
      "x": -8,
      "y": 6,
      "z": 6,
      "name": "Rock_Sandstone_Red"
    },
    {
      "x": -8,
      "y": 7,
      "z": 6,
      "name": "Soil_Clay"
    },
    {
      "x": -8,
      "y": 8,
      "z": 6,
      "name": "Rock_Sandstone_Red"
    },
    {
      "x": -8,
      "y": 9,
      "z": 6,
      "name": "Soil_Mud_Dry"
    },
    {
      "x": -7,
      "y": 3,
      "z": -7,
      "name": "Soil_Hive"
    },
    {
      "x": -7,
      "y": 4,
      "z": -7,
      "name": "Soil_Hive"
    },
    {
      "x": -7,
      "y": 5,
      "z": -7,
      "name": "Soil_Hive"
    },
    {
      "x": -7,
      "y": 3,
      "z": -6,
      "name": "Rock_Sandstone_Red"
    },
    {
      "x": -7,
      "y": 4,
      "z": -6,
      "name": "Soil_Hive"
    },
    {
      "x": -7,
      "y": 5,
      "z": -6,
      "name": "Soil_Hive"
    },
    {
      "x": -7,
      "y": 3,
      "z": -5,
      "name": "Rock_Sandstone_Red"
    },
    {
      "x": -7,
      "y": 4,
      "z": -5,
      "name": "Rock_Sandstone_Red"
    },
    {
      "x": -7,
      "y": 5,
      "z": -5,
      "name": "Rock_Sandstone_Red"
    },
    {
      "x": -7,
      "y": 6,
      "z": -5,
      "name": "Soil_Clay"
    },
    {
      "x": -7,
      "y": 7,
      "z": -5,
      "name": "Soil_Hive"
    },
    {
      "x": -7,
      "y": 3,
      "z": -4,
      "name": "Rock_Sandstone_Red"
    },
    {
      "x": -7,
      "y": 4,
      "z": -4,
      "name": "Rock_Sandstone_Red"
    },
    {
      "x": -7,
      "y": 5,
      "z": -4,
      "name": "Rock_Sandstone_Red"
    },
    {
      "x": -7,
      "y": 6,
      "z": -4,
      "name": "Soil_Clay"
    },
    {
      "x": -7,
      "y": 7,
      "z": -4,
      "name": "Soil_Hive"
    },
    {
      "x": -7,
      "y": 3,
      "z": -3,
      "name": "Rock_Sandstone_Red"
    },
    {
      "x": -7,
      "y": 4,
      "z": -3,
      "name": "Rock_Sandstone_Red"
    },
    {
      "x": -7,
      "y": 5,
      "z": -3,
      "name": "Rock_Sandstone_Red"
    },
    {
      "x": -7,
      "y": 3,
      "z": -2,
      "name": "Rock_Sandstone_Red"
    },
    {
      "x": -7,
      "y": 4,
      "z": -2,
      "name": "Rock_Sandstone_Red"
    },
    {
      "x": -7,
      "y": 5,
      "z": -2,
      "name": "Rock_Sandstone_Red"
    },
    {
      "x": -7,
      "y": 3,
      "z": -1,
      "name": "Rock_Sandstone_Red"
    },
    {
      "x": -7,
      "y": 4,
      "z": -1,
      "name": "Rock_Sandstone_Red"
    },
    {
      "x": -7,
      "y": 5,
      "z": -1,
      "name": "Rock_Sandstone_Red"
    },
    {
      "x": -7,
      "y": 3,
      "z": 0,
      "name": "Rock_Sandstone_Red"
    },
    {
      "x": -7,
      "y": 4,
      "z": 0,
      "name": "Rock_Sandstone_Red"
    },
    {
      "x": -7,
      "y": 5,
      "z": 0,
      "name": "Rock_Sandstone_Red"
    },
    {
      "x": -7,
      "y": 3,
      "z": 1,
      "name": "Rock_Sandstone_Red"
    },
    {
      "x": -7,
      "y": 4,
      "z": 1,
      "name": "Rock_Sandstone_Red"
    },
    {
      "x": -7,
      "y": 5,
      "z": 1,
      "name": "Rock_Sandstone_Red"
    },
    {
      "x": -7,
      "y": 6,
      "z": 1,
      "name": "Soil_Hive"
    },
    {
      "x": -7,
      "y": 7,
      "z": 1,
      "name": "Soil_Hive"
    },
    {
      "x": -7,
      "y": 8,
      "z": 1,
      "name": "Soil_Hive"
    },
    {
      "x": -7,
      "y": 3,
      "z": 2,
      "name": "Rock_Sandstone_Red"
    },
    {
      "x": -7,
      "y": 4,
      "z": 2,
      "name": "Rock_Sandstone_Red"
    },
    {
      "x": -7,
      "y": 5,
      "z": 2,
      "name": "Rock_Sandstone_Red"
    },
    {
      "x": -7,
      "y": 6,
      "z": 2,
      "name": "Soil_Clay"
    },
    {
      "x": -7,
      "y": 7,
      "z": 2,
      "name": "Soil_Hive"
    },
    {
      "x": -7,
      "y": 8,
      "z": 2,
      "name": "Soil_Hive"
    },
    {
      "x": -7,
      "y": 3,
      "z": 3,
      "name": "Rock_Sandstone_Red"
    },
    {
      "x": -7,
      "y": 4,
      "z": 3,
      "name": "Rock_Sandstone_Red"
    },
    {
      "x": -7,
      "y": 5,
      "z": 3,
      "name": "Rock_Sandstone_Red"
    },
    {
      "x": -7,
      "y": 6,
      "z": 3,
      "name": "Rock_Sandstone_Red"
    },
    {
      "x": -7,
      "y": 7,
      "z": 3,
      "name": "Soil_Clay"
    },
    {
      "x": -7,
      "y": 8,
      "z": 3,
      "name": "Soil_Hive"
    },
    {
      "x": -7,
      "y": 3,
      "z": 4,
      "name": "Rock_Sandstone_Red"
    },
    {
      "x": -7,
      "y": 4,
      "z": 4,
      "name": "Rock_Sandstone_Red"
    },
    {
      "x": -7,
      "y": 3,
      "z": 5,
      "name": "Rock_Sandstone_Red"
    },
    {
      "x": -7,
      "y": 4,
      "z": 5,
      "name": "Rock_Sandstone_Red"
    },
    {
      "x": -7,
      "y": 3,
      "z": 6,
      "name": "Rock_Sandstone_Red"
    },
    {
      "x": -7,
      "y": 4,
      "z": 6,
      "name": "Rock_Sandstone_Red"
    },
    {
      "x": -7,
      "y": 7,
      "z": 6,
      "name": "Rock_Sandstone_Red"
    },
    {
      "x": -7,
      "y": 8,
      "z": 6,
      "name": "Rock_Sandstone_Red"
    },
    {
      "x": -7,
      "y": 9,
      "z": 6,
      "name": "Soil_Mud_Dry"
    },
    {
      "x": -7,
      "y": 10,
      "z": 6,
      "name": "Plant_Flower_Common_Poisoned"
    },
    {
      "x": -7,
      "y": 3,
      "z": 7,
      "name": "Rock_Sandstone_Red"
    },
    {
      "x": -7,
      "y": 4,
      "z": 7,
      "name": "Rock_Sandstone_Red"
    },
    {
      "x": -7,
      "y": 5,
      "z": 7,
      "name": "Rock_Sandstone_Red"
    },
    {
      "x": -7,
      "y": 6,
      "z": 7,
      "name": "Rock_Sandstone_Red"
    },
    {
      "x": -7,
      "y": 7,
      "z": 7,
      "name": "Soil_Clay"
    },
    {
      "x": -7,
      "y": 8,
      "z": 7,
      "name": "Rock_Sandstone_Red"
    },
    {
      "x": -7,
      "y": 9,
      "z": 7,
      "name": "Soil_Mud_Dry"
    },
    {
      "x": -6,
      "y": 3,
      "z": -7,
      "name": "Rock_Sandstone_Red"
    },
    {
      "x": -6,
      "y": 4,
      "z": -7,
      "name": "Rock_Sandstone_Red"
    },
    {
      "x": -6,
      "y": 5,
      "z": -7,
      "name": "Soil_Hive"
    },
    {
      "x": -6,
      "y": 6,
      "z": -7,
      "name": "Soil_Hive"
    },
    {
      "x": -6,
      "y": 7,
      "z": -7,
      "name": "Soil_Hive"
    },
    {
      "x": -6,
      "y": 8,
      "z": -7,
      "name": "Soil_Hive"
    },
    {
      "x": -6,
      "y": 3,
      "z": -6,
      "name": "Rock_Sandstone_Red"
    },
    {
      "x": -6,
      "y": 4,
      "z": -6,
      "name": "Rock_Sandstone_Red"
    },
    {
      "x": -6,
      "y": 5,
      "z": -6,
      "name": "Rock_Sandstone_Red"
    },
    {
      "x": -6,
      "y": 6,
      "z": -6,
      "name": "Soil_Clay"
    },
    {
      "x": -6,
      "y": 7,
      "z": -6,
      "name": "Soil_Hive"
    },
    {
      "x": -6,
      "y": 3,
      "z": -5,
      "name": "Rock_Sandstone_Red"
    },
    {
      "x": -6,
      "y": 4,
      "z": -5,
      "name": "Rock_Sandstone_Red"
    },
    {
      "x": -6,
      "y": 5,
      "z": -5,
      "name": "Rock_Sandstone_Red"
    },
    {
      "x": -6,
      "y": 3,
      "z": -4,
      "name": "Rock_Sandstone_Red"
    },
    {
      "x": -6,
      "y": 4,
      "z": -4,
      "name": "Rock_Sandstone_Red"
    },
    {
      "x": -6,
      "y": 5,
      "z": -4,
      "name": "Rock_Sandstone_Red"
    },
    {
      "x": -6,
      "y": 3,
      "z": -3,
      "name": "Rock_Sandstone_Red"
    },
    {
      "x": -6,
      "y": 4,
      "z": -3,
      "name": "Rock_Sandstone_Red"
    },
    {
      "x": -6,
      "y": 5,
      "z": -3,
      "name": "Rock_Sandstone_Red"
    },
    {
      "x": -6,
      "y": 3,
      "z": -2,
      "name": "Rock_Sandstone_Red"
    },
    {
      "x": -6,
      "y": 4,
      "z": -2,
      "name": "Rock_Sandstone_Red"
    },
    {
      "x": -6,
      "y": 5,
      "z": -2,
      "name": "Rock_Sandstone_Red"
    },
    {
      "x": -6,
      "y": 3,
      "z": -1,
      "name": "Rock_Sandstone_Red"
    },
    {
      "x": -6,
      "y": 4,
      "z": -1,
      "name": "Rock_Sandstone_Red"
    },
    {
      "x": -6,
      "y": 5,
      "z": -1,
      "name": "Rock_Sandstone_Red"
    },
    {
      "x": -6,
      "y": 3,
      "z": 0,
      "name": "Rock_Sandstone_Red"
    },
    {
      "x": -6,
      "y": 4,
      "z": 0,
      "name": "Rock_Sandstone_Red"
    },
    {
      "x": -6,
      "y": 5,
      "z": 0,
      "name": "Rock_Sandstone_Red"
    },
    {
      "x": -6,
      "y": 3,
      "z": 1,
      "name": "Rock_Sandstone_Red"
    },
    {
      "x": -6,
      "y": 4,
      "z": 1,
      "name": "Rock_Sandstone_Red"
    },
    {
      "x": -6,
      "y": 5,
      "z": 1,
      "name": "Rock_Sandstone_Red"
    },
    {
      "x": -6,
      "y": 6,
      "z": 1,
      "name": "Rock_Sandstone_Red"
    },
    {
      "x": -6,
      "y": 7,
      "z": 1,
      "name": "Soil_Clay"
    },
    {
      "x": -6,
      "y": 8,
      "z": 1,
      "name": "Soil_Hive"
    },
    {
      "x": -6,
      "y": 3,
      "z": 2,
      "name": "Rock_Sandstone_Red"
    },
    {
      "x": -6,
      "y": 4,
      "z": 2,
      "name": "Rock_Sandstone_Red"
    },
    {
      "x": -6,
      "y": 5,
      "z": 2,
      "name": "Rock_Sandstone_Red"
    },
    {
      "x": -6,
      "y": 3,
      "z": 3,
      "name": "Rock_Sandstone_Red"
    },
    {
      "x": -6,
      "y": 4,
      "z": 3,
      "name": "Rock_Sandstone_Red"
    },
    {
      "x": -6,
      "y": 5,
      "z": 3,
      "name": "Rock_Sandstone_Red"
    },
    {
      "x": -6,
      "y": 3,
      "z": 4,
      "name": "Rock_Sandstone_Red"
    },
    {
      "x": -6,
      "y": 4,
      "z": 4,
      "name": "Rock_Sandstone_Red"
    },
    {
      "x": -6,
      "y": 5,
      "z": 4,
      "name": "Rock_Sandstone_Red"
    },
    {
      "x": -6,
      "y": 3,
      "z": 5,
      "name": "Rock_Sandstone_Red"
    },
    {
      "x": -6,
      "y": 4,
      "z": 5,
      "name": "Rock_Sandstone_Red"
    },
    {
      "x": -6,
      "y": 3,
      "z": 6,
      "name": "Rock_Sandstone_Red"
    },
    {
      "x": -6,
      "y": 4,
      "z": 6,
      "name": "Rock_Sandstone_Red"
    },
    {
      "x": -6,
      "y": 3,
      "z": 7,
      "name": "Rock_Sandstone_Red"
    },
    {
      "x": -6,
      "y": 4,
      "z": 7,
      "name": "Rock_Sandstone_Red"
    },
    {
      "x": -6,
      "y": 5,
      "z": 7,
      "name": "Rock_Sandstone_Red"
    },
    {
      "x": -6,
      "y": 6,
      "z": 7,
      "name": "Rock_Sandstone_Red"
    },
    {
      "x": -6,
      "y": 7,
      "z": 7,
      "name": "Soil_Clay"
    },
    {
      "x": -6,
      "y": 8,
      "z": 7,
      "name": "Rock_Sandstone_Red"
    },
    {
      "x": -6,
      "y": 9,
      "z": 7,
      "name": "Soil_Mud_Dry"
    },
    {
      "x": -6,
      "y": 4,
      "z": 8,
      "name": "Rock_Sandstone_Red"
    },
    {
      "x": -6,
      "y": 5,
      "z": 8,
      "name": "Rock_Sandstone_Red"
    },
    {
      "x": -6,
      "y": 6,
      "z": 8,
      "name": "Rock_Sandstone_Red"
    },
    {
      "x": -6,
      "y": 7,
      "z": 8,
      "name": "Soil_Clay"
    },
    {
      "x": -6,
      "y": 8,
      "z": 8,
      "name": "Rock_Sandstone_Red"
    },
    {
      "x": -6,
      "y": 9,
      "z": 8,
      "name": "Soil_Mud_Dry"
    },
    {
      "x": -5,
      "y": 3,
      "z": -8,
      "name": "Rock_Sandstone_Red"
    },
    {
      "x": -5,
      "y": 4,
      "z": -8,
      "name": "Rock_Sandstone_Red"
    },
    {
      "x": -5,
      "y": 5,
      "z": -8,
      "name": "Rock_Sandstone_Red"
    },
    {
      "x": -5,
      "y": 6,
      "z": -8,
      "name": "Soil_Clay"
    },
    {
      "x": -5,
      "y": 7,
      "z": -8,
      "name": "Rock_Sandstone_Red"
    },
    {
      "x": -5,
      "y": 3,
      "z": -7,
      "name": "Rock_Sandstone_Red"
    },
    {
      "x": -5,
      "y": 4,
      "z": -7,
      "name": "Rock_Sandstone_Red"
    },
    {
      "x": -5,
      "y": 5,
      "z": -7,
      "name": "Rock_Sandstone_Red"
    },
    {
      "x": -5,
      "y": 6,
      "z": -7,
      "name": "Soil_Clay"
    },
    {
      "x": -5,
      "y": 7,
      "z": -7,
      "name": "Rock_Sandstone_Red"
    },
    {
      "x": -5,
      "y": 8,
      "z": -7,
      "name": "Soil_Hive"
    },
    {
      "x": -5,
      "y": 3,
      "z": -6,
      "name": "Rock_Sandstone_Red"
    },
    {
      "x": -5,
      "y": 4,
      "z": -6,
      "name": "Rock_Sandstone_Red"
    },
    {
      "x": -5,
      "y": 5,
      "z": -6,
      "name": "Rock_Sandstone_Red"
    },
    {
      "x": -5,
      "y": 6,
      "z": -6,
      "name": "Soil_Clay"
    },
    {
      "x": -5,
      "y": 7,
      "z": -6,
      "name": "Soil_Hive"
    },
    {
      "x": -5,
      "y": 3,
      "z": -5,
      "name": "Rock_Sandstone_Red"
    },
    {
      "x": -5,
      "y": 4,
      "z": -5,
      "name": "Rock_Sandstone_Red"
    },
    {
      "x": -5,
      "y": 5,
      "z": -5,
      "name": "Rock_Sandstone_Red"
    },
    {
      "x": -5,
      "y": 3,
      "z": -4,
      "name": "Rock_Sandstone_Red"
    },
    {
      "x": -5,
      "y": 4,
      "z": -4,
      "name": "Rock_Sandstone_Red"
    },
    {
      "x": -5,
      "y": 5,
      "z": -4,
      "name": "Rock_Sandstone_Red"
    },
    {
      "x": -5,
      "y": 3,
      "z": -3,
      "name": "Rock_Sandstone_Red"
    },
    {
      "x": -5,
      "y": 4,
      "z": -3,
      "name": "Rock_Sandstone_Red"
    },
    {
      "x": -5,
      "y": 5,
      "z": -3,
      "name": "Rock_Sandstone_Red"
    },
    {
      "x": -5,
      "y": 3,
      "z": -2,
      "name": "Rock_Sandstone_Red"
    },
    {
      "x": -5,
      "y": 4,
      "z": -2,
      "name": "Rock_Sandstone_Red"
    },
    {
      "x": -5,
      "y": 5,
      "z": -2,
      "name": "Rock_Sandstone_Red"
    },
    {
      "x": -5,
      "y": 3,
      "z": -1,
      "name": "Rock_Sandstone_Red"
    },
    {
      "x": -5,
      "y": 4,
      "z": -1,
      "name": "Rock_Sandstone_Red"
    },
    {
      "x": -5,
      "y": 5,
      "z": -1,
      "name": "Rock_Sandstone_Red"
    },
    {
      "x": -5,
      "y": 3,
      "z": 0,
      "name": "Rock_Sandstone_Red"
    },
    {
      "x": -5,
      "y": 4,
      "z": 0,
      "name": "Rock_Sandstone_Red"
    },
    {
      "x": -5,
      "y": 5,
      "z": 0,
      "name": "Rock_Sandstone_Red"
    },
    {
      "x": -5,
      "y": 3,
      "z": 1,
      "name": "Rock_Sandstone_Red"
    },
    {
      "x": -5,
      "y": 4,
      "z": 1,
      "name": "Rock_Sandstone_Red"
    },
    {
      "x": -5,
      "y": 5,
      "z": 1,
      "name": "Rock_Sandstone_Red"
    },
    {
      "x": -5,
      "y": 6,
      "z": 1,
      "name": "Rock_Sandstone_Red"
    },
    {
      "x": -5,
      "y": 7,
      "z": 1,
      "name": "Soil_Clay"
    },
    {
      "x": -5,
      "y": 8,
      "z": 1,
      "name": "Soil_Hive"
    },
    {
      "x": -5,
      "y": 3,
      "z": 2,
      "name": "Rock_Sandstone_Red"
    },
    {
      "x": -5,
      "y": 4,
      "z": 2,
      "name": "Rock_Sandstone_Red"
    },
    {
      "x": -5,
      "y": 5,
      "z": 2,
      "name": "Rock_Sandstone_Red"
    },
    {
      "x": -5,
      "y": 3,
      "z": 3,
      "name": "Rock_Sandstone_Red"
    },
    {
      "x": -5,
      "y": 4,
      "z": 3,
      "name": "Rock_Sandstone_Red"
    },
    {
      "x": -5,
      "y": 5,
      "z": 3,
      "name": "Rock_Sandstone_Red"
    },
    {
      "x": -5,
      "y": 3,
      "z": 4,
      "name": "Rock_Sandstone_Red"
    },
    {
      "x": -5,
      "y": 4,
      "z": 4,
      "name": "Rock_Sandstone_Red"
    },
    {
      "x": -5,
      "y": 5,
      "z": 4,
      "name": "Rock_Sandstone_Red"
    },
    {
      "x": -5,
      "y": 3,
      "z": 5,
      "name": "Rock_Sandstone_Red"
    },
    {
      "x": -5,
      "y": 4,
      "z": 5,
      "name": "Rock_Sandstone_Red"
    },
    {
      "x": -5,
      "y": 5,
      "z": 5,
      "name": "Rock_Sandstone_Red"
    },
    {
      "x": -5,
      "y": 3,
      "z": 6,
      "name": "Rock_Sandstone_Red"
    },
    {
      "x": -5,
      "y": 4,
      "z": 6,
      "name": "Rock_Sandstone_Red"
    },
    {
      "x": -5,
      "y": 5,
      "z": 6,
      "name": "Rock_Sandstone_Red"
    },
    {
      "x": -5,
      "y": 6,
      "z": 6,
      "name": "Rock_Sandstone_Red"
    },
    {
      "x": -5,
      "y": 3,
      "z": 7,
      "name": "Rock_Sandstone_Red"
    },
    {
      "x": -5,
      "y": 4,
      "z": 7,
      "name": "Rock_Sandstone_Red"
    },
    {
      "x": -5,
      "y": 5,
      "z": 7,
      "name": "Rock_Sandstone_Red"
    },
    {
      "x": -5,
      "y": 6,
      "z": 7,
      "name": "Rock_Sandstone_Red"
    },
    {
      "x": -5,
      "y": 3,
      "z": 8,
      "name": "Rock_Sandstone_Red"
    },
    {
      "x": -5,
      "y": 4,
      "z": 8,
      "name": "Rock_Sandstone_Red"
    },
    {
      "x": -5,
      "y": 5,
      "z": 8,
      "name": "Rock_Sandstone_Red"
    },
    {
      "x": -5,
      "y": 6,
      "z": 8,
      "name": "Rock_Sandstone_Red"
    },
    {
      "x": -5,
      "y": 7,
      "z": 8,
      "name": "Soil_Clay"
    },
    {
      "x": -5,
      "y": 8,
      "z": 8,
      "name": "Soil_Clay"
    },
    {
      "x": -5,
      "y": 9,
      "z": 8,
      "name": "Soil_Mud_Dry"
    },
    {
      "x": -5,
      "y": 10,
      "z": 8,
      "name": "Plant_Flower_Common_Poisoned"
    },
    {
      "x": -4,
      "y": 3,
      "z": -8,
      "name": "Rock_Sandstone_Red"
    },
    {
      "x": -4,
      "y": 4,
      "z": -8,
      "name": "Rock_Sandstone_Red"
    },
    {
      "x": -4,
      "y": 5,
      "z": -8,
      "name": "Rock_Sandstone_Red"
    },
    {
      "x": -4,
      "y": 6,
      "z": -8,
      "name": "Soil_Clay"
    },
    {
      "x": -4,
      "y": 7,
      "z": -8,
      "name": "Rock_Sandstone_Red"
    },
    {
      "x": -4,
      "y": 8,
      "z": -8,
      "name": "Soil_Hive"
    },
    {
      "x": -4,
      "y": 3,
      "z": -7,
      "name": "Rock_Sandstone_Red"
    },
    {
      "x": -4,
      "y": 4,
      "z": -7,
      "name": "Rock_Sandstone_Red"
    },
    {
      "x": -4,
      "y": 5,
      "z": -7,
      "name": "Rock_Sandstone_Red"
    },
    {
      "x": -4,
      "y": 6,
      "z": -7,
      "name": "Soil_Clay"
    },
    {
      "x": -4,
      "y": 7,
      "z": -7,
      "name": "Rock_Sandstone_Red"
    },
    {
      "x": -4,
      "y": 8,
      "z": -7,
      "name": "Soil_Hive"
    },
    {
      "x": -4,
      "y": 3,
      "z": -6,
      "name": "Rock_Sandstone_Red"
    },
    {
      "x": -4,
      "y": 4,
      "z": -6,
      "name": "Rock_Sandstone_Red"
    },
    {
      "x": -4,
      "y": 5,
      "z": -6,
      "name": "Rock_Sandstone_Red"
    },
    {
      "x": -4,
      "y": 3,
      "z": -5,
      "name": "Rock_Sandstone_Red"
    },
    {
      "x": -4,
      "y": 4,
      "z": -5,
      "name": "Rock_Sandstone_Red"
    },
    {
      "x": -4,
      "y": 5,
      "z": -5,
      "name": "Rock_Sandstone_Red"
    },
    {
      "x": -4,
      "y": 3,
      "z": -4,
      "name": "Rock_Sandstone_Red"
    },
    {
      "x": -4,
      "y": 4,
      "z": -4,
      "name": "Rock_Sandstone_Red"
    },
    {
      "x": -4,
      "y": 5,
      "z": -4,
      "name": "Rock_Sandstone_Red"
    },
    {
      "x": -4,
      "y": 3,
      "z": -3,
      "name": "Rock_Sandstone_Red"
    },
    {
      "x": -4,
      "y": 4,
      "z": -3,
      "name": "Rock_Sandstone_Red"
    },
    {
      "x": -4,
      "y": 5,
      "z": -3,
      "name": "Rock_Sandstone_Red"
    },
    {
      "x": -4,
      "y": 3,
      "z": -2,
      "name": "Rock_Sandstone_Red"
    },
    {
      "x": -4,
      "y": 4,
      "z": -2,
      "name": "Rock_Sandstone_Red"
    },
    {
      "x": -4,
      "y": 5,
      "z": -2,
      "name": "Rock_Sandstone_Red"
    },
    {
      "x": -4,
      "y": 3,
      "z": -1,
      "name": "Rock_Sandstone_Red"
    },
    {
      "x": -4,
      "y": 4,
      "z": -1,
      "name": "Rock_Sandstone_Red"
    },
    {
      "x": -4,
      "y": 5,
      "z": -1,
      "name": "Rock_Sandstone_Red"
    },
    {
      "x": -4,
      "y": 3,
      "z": 0,
      "name": "Rock_Sandstone_Red"
    },
    {
      "x": -4,
      "y": 4,
      "z": 0,
      "name": "Rock_Sandstone_Red"
    },
    {
      "x": -4,
      "y": 5,
      "z": 0,
      "name": "Rock_Sandstone_Red"
    },
    {
      "x": -4,
      "y": 3,
      "z": 1,
      "name": "Rock_Sandstone_Red"
    },
    {
      "x": -4,
      "y": 4,
      "z": 1,
      "name": "Rock_Sandstone_Red"
    },
    {
      "x": -4,
      "y": 5,
      "z": 1,
      "name": "Rock_Sandstone_Red"
    },
    {
      "x": -4,
      "y": 6,
      "z": 1,
      "name": "Rock_Sandstone_Red"
    },
    {
      "x": -4,
      "y": 7,
      "z": 1,
      "name": "Soil_Clay"
    },
    {
      "x": -4,
      "y": 8,
      "z": 1,
      "name": "Soil_Hive"
    },
    {
      "x": -4,
      "y": 3,
      "z": 2,
      "name": "Rock_Sandstone_Red"
    },
    {
      "x": -4,
      "y": 4,
      "z": 2,
      "name": "Rock_Sandstone_Red"
    },
    {
      "x": -4,
      "y": 5,
      "z": 2,
      "name": "Rock_Sandstone_Red"
    },
    {
      "x": -4,
      "y": 8,
      "z": 2,
      "name": "Soil_Hive"
    },
    {
      "x": -4,
      "y": 3,
      "z": 3,
      "name": "Rock_Sandstone_Red"
    },
    {
      "x": -4,
      "y": 4,
      "z": 3,
      "name": "Rock_Sandstone_Red"
    },
    {
      "x": -4,
      "y": 5,
      "z": 3,
      "name": "Rock_Sandstone_Red"
    },
    {
      "x": -4,
      "y": 3,
      "z": 4,
      "name": "Rock_Sandstone_Red"
    },
    {
      "x": -4,
      "y": 4,
      "z": 4,
      "name": "Rock_Sandstone_Red"
    },
    {
      "x": -4,
      "y": 5,
      "z": 4,
      "name": "Rock_Sandstone_Red"
    },
    {
      "x": -4,
      "y": 3,
      "z": 5,
      "name": "Rock_Sandstone_Red"
    },
    {
      "x": -4,
      "y": 4,
      "z": 5,
      "name": "Rock_Sandstone_Red"
    },
    {
      "x": -4,
      "y": 5,
      "z": 5,
      "name": "Rock_Sandstone_Red"
    },
    {
      "x": -4,
      "y": 3,
      "z": 6,
      "name": "Rock_Sandstone_Red"
    },
    {
      "x": -4,
      "y": 4,
      "z": 6,
      "name": "Rock_Sandstone_Red"
    },
    {
      "x": -4,
      "y": 5,
      "z": 6,
      "name": "Rock_Sandstone_Red"
    },
    {
      "x": -4,
      "y": 6,
      "z": 6,
      "name": "Rock_Sandstone_Red"
    },
    {
      "x": -4,
      "y": 3,
      "z": 7,
      "name": "Rock_Sandstone_Red"
    },
    {
      "x": -4,
      "y": 4,
      "z": 7,
      "name": "Rock_Sandstone_Red"
    },
    {
      "x": -4,
      "y": 5,
      "z": 7,
      "name": "Rock_Sandstone_Red"
    },
    {
      "x": -4,
      "y": 6,
      "z": 7,
      "name": "Rock_Sandstone_Red"
    },
    {
      "x": -4,
      "y": 3,
      "z": 8,
      "name": "Rock_Sandstone_Red"
    },
    {
      "x": -4,
      "y": 4,
      "z": 8,
      "name": "Rock_Sandstone_Red"
    },
    {
      "x": -4,
      "y": 5,
      "z": 8,
      "name": "Rock_Sandstone_Red"
    },
    {
      "x": -4,
      "y": 6,
      "z": 8,
      "name": "Rock_Sandstone_Red"
    },
    {
      "x": -4,
      "y": 7,
      "z": 8,
      "name": "Rock_Sandstone_Red"
    },
    {
      "x": -4,
      "y": 8,
      "z": 8,
      "name": "Soil_Clay"
    },
    {
      "x": -4,
      "y": 9,
      "z": 8,
      "name": "Soil_Mud_Dry"
    },
    {
      "x": -3,
      "y": 3,
      "z": -9,
      "name": "Rock_Sandstone_Red"
    },
    {
      "x": -3,
      "y": 4,
      "z": -9,
      "name": "Rock_Sandstone_Red"
    },
    {
      "x": -3,
      "y": 5,
      "z": -9,
      "name": "Rock_Sandstone_Red"
    },
    {
      "x": -3,
      "y": 6,
      "z": -9,
      "name": "Soil_Clay"
    },
    {
      "x": -3,
      "y": 7,
      "z": -9,
      "name": "Soil_Mud_Dry"
    },
    {
      "x": -3,
      "y": 3,
      "z": -8,
      "name": "Rock_Sandstone_Red"
    },
    {
      "x": -3,
      "y": 4,
      "z": -8,
      "name": "Rock_Sandstone_Red"
    },
    {
      "x": -3,
      "y": 5,
      "z": -8,
      "name": "Rock_Sandstone_Red"
    },
    {
      "x": -3,
      "y": 6,
      "z": -8,
      "name": "Soil_Clay"
    },
    {
      "x": -3,
      "y": 7,
      "z": -8,
      "name": "Soil_Mud_Dry"
    },
    {
      "x": -3,
      "y": 8,
      "z": -8,
      "name": "Soil_Mud_Dry"
    },
    {
      "x": -3,
      "y": 3,
      "z": -7,
      "name": "Rock_Sandstone_Red"
    },
    {
      "x": -3,
      "y": 4,
      "z": -7,
      "name": "Rock_Sandstone_Red"
    },
    {
      "x": -3,
      "y": 5,
      "z": -7,
      "name": "Rock_Sandstone_Red"
    },
    {
      "x": -3,
      "y": 3,
      "z": -6,
      "name": "Rock_Sandstone_Red"
    },
    {
      "x": -3,
      "y": 4,
      "z": -6,
      "name": "Rock_Sandstone_Red"
    },
    {
      "x": -3,
      "y": 5,
      "z": -6,
      "name": "Rock_Sandstone_Red"
    },
    {
      "x": -3,
      "y": 3,
      "z": -5,
      "name": "Rock_Sandstone_Red"
    },
    {
      "x": -3,
      "y": 4,
      "z": -5,
      "name": "Rock_Sandstone_Red"
    },
    {
      "x": -3,
      "y": 5,
      "z": -5,
      "name": "Rock_Sandstone_Red"
    },
    {
      "x": -3,
      "y": 3,
      "z": -4,
      "name": "Rock_Sandstone_Red"
    },
    {
      "x": -3,
      "y": 4,
      "z": -4,
      "name": "Rock_Sandstone_Red"
    },
    {
      "x": -3,
      "y": 5,
      "z": -4,
      "name": "Rock_Sandstone_Red"
    },
    {
      "x": -3,
      "y": 3,
      "z": -3,
      "name": "Rock_Sandstone_Red"
    },
    {
      "x": -3,
      "y": 4,
      "z": -3,
      "name": "Rock_Sandstone_Red"
    },
    {
      "x": -3,
      "y": 5,
      "z": -3,
      "name": "Rock_Sandstone_Red"
    },
    {
      "x": -3,
      "y": 3,
      "z": -2,
      "name": "Rock_Sandstone_Red"
    },
    {
      "x": -3,
      "y": 4,
      "z": -2,
      "name": "Rock_Sandstone_Red"
    },
    {
      "x": -3,
      "y": 5,
      "z": -2,
      "name": "Rock_Sandstone_Red"
    },
    {
      "x": -3,
      "y": 3,
      "z": -1,
      "name": "Rock_Sandstone_Red"
    },
    {
      "x": -3,
      "y": 4,
      "z": -1,
      "name": "Rock_Sandstone_Red"
    },
    {
      "x": -3,
      "y": 5,
      "z": -1,
      "name": "Rock_Sandstone_Red"
    },
    {
      "x": -3,
      "y": 3,
      "z": 0,
      "name": "Rock_Sandstone_Red"
    },
    {
      "x": -3,
      "y": 4,
      "z": 0,
      "name": "Rock_Sandstone_Red"
    },
    {
      "x": -3,
      "y": 5,
      "z": 0,
      "name": "Rock_Sandstone_Red"
    },
    {
      "x": -3,
      "y": 3,
      "z": 1,
      "name": "Rock_Sandstone_Red"
    },
    {
      "x": -3,
      "y": 4,
      "z": 1,
      "name": "Rock_Sandstone_Red"
    },
    {
      "x": -3,
      "y": 5,
      "z": 1,
      "name": "Rock_Sandstone_Red"
    },
    {
      "x": -3,
      "y": 3,
      "z": 2,
      "name": "Rock_Sandstone_Red"
    },
    {
      "x": -3,
      "y": 4,
      "z": 2,
      "name": "Rock_Sandstone_Red"
    },
    {
      "x": -3,
      "y": 5,
      "z": 2,
      "name": "Rock_Sandstone_Red"
    },
    {
      "x": -3,
      "y": 6,
      "z": 2,
      "name": "Rock_Sandstone_Red"
    },
    {
      "x": -3,
      "y": 7,
      "z": 2,
      "name": "Soil_Clay"
    },
    {
      "x": -3,
      "y": 8,
      "z": 2,
      "name": "Soil_Hive"
    },
    {
      "x": -3,
      "y": 3,
      "z": 3,
      "name": "Rock_Sandstone_Red"
    },
    {
      "x": -3,
      "y": 4,
      "z": 3,
      "name": "Rock_Sandstone_Red"
    },
    {
      "x": -3,
      "y": 5,
      "z": 3,
      "name": "Rock_Sandstone_Red"
    },
    {
      "x": -3,
      "y": 8,
      "z": 3,
      "name": "Soil_Hive"
    },
    {
      "x": -3,
      "y": 3,
      "z": 4,
      "name": "Rock_Sandstone_Red"
    },
    {
      "x": -3,
      "y": 4,
      "z": 4,
      "name": "Rock_Sandstone_Red"
    },
    {
      "x": -3,
      "y": 5,
      "z": 4,
      "name": "Rock_Sandstone_Red"
    },
    {
      "x": -3,
      "y": 3,
      "z": 5,
      "name": "Rock_Sandstone_Red"
    },
    {
      "x": -3,
      "y": 4,
      "z": 5,
      "name": "Rock_Sandstone_Red"
    },
    {
      "x": -3,
      "y": 5,
      "z": 5,
      "name": "Rock_Sandstone_Red"
    },
    {
      "x": -3,
      "y": 3,
      "z": 6,
      "name": "Rock_Sandstone_Red"
    },
    {
      "x": -3,
      "y": 4,
      "z": 6,
      "name": "Rock_Sandstone_Red"
    },
    {
      "x": -3,
      "y": 5,
      "z": 6,
      "name": "Rock_Sandstone_Red"
    },
    {
      "x": -3,
      "y": 6,
      "z": 6,
      "name": "Rock_Sandstone_Red"
    },
    {
      "x": -3,
      "y": 7,
      "z": 6,
      "name": "Rock_Sandstone_Red"
    },
    {
      "x": -3,
      "y": 3,
      "z": 7,
      "name": "Rock_Sandstone_Red"
    },
    {
      "x": -3,
      "y": 4,
      "z": 7,
      "name": "Rock_Sandstone_Red"
    },
    {
      "x": -3,
      "y": 5,
      "z": 7,
      "name": "Rock_Sandstone_Red"
    },
    {
      "x": -3,
      "y": 6,
      "z": 7,
      "name": "Rock_Sandstone_Red"
    },
    {
      "x": -3,
      "y": 7,
      "z": 7,
      "name": "Rock_Sandstone_Red"
    },
    {
      "x": -3,
      "y": 8,
      "z": 7,
      "name": "Rock_Sandstone_Red"
    },
    {
      "x": -3,
      "y": 9,
      "z": 7,
      "name": "Soil_Mud_Dry"
    },
    {
      "x": -3,
      "y": 3,
      "z": 8,
      "name": "Rock_Sandstone_Red"
    },
    {
      "x": -3,
      "y": 4,
      "z": 8,
      "name": "Rock_Sandstone_Red"
    },
    {
      "x": -3,
      "y": 5,
      "z": 8,
      "name": "Rock_Sandstone_Red"
    },
    {
      "x": -3,
      "y": 6,
      "z": 8,
      "name": "Rock_Sandstone_Red"
    },
    {
      "x": -3,
      "y": 7,
      "z": 8,
      "name": "Rock_Sandstone_Red"
    },
    {
      "x": -3,
      "y": 8,
      "z": 8,
      "name": "Soil_Clay"
    },
    {
      "x": -3,
      "y": 9,
      "z": 8,
      "name": "Soil_Mud_Dry"
    },
    {
      "x": -2,
      "y": 3,
      "z": -9,
      "name": "Rock_Sandstone_Red"
    },
    {
      "x": -2,
      "y": 4,
      "z": -9,
      "name": "Rock_Sandstone_Red"
    },
    {
      "x": -2,
      "y": 5,
      "z": -9,
      "name": "Rock_Sandstone_Red"
    },
    {
      "x": -2,
      "y": 6,
      "z": -9,
      "name": "Soil_Clay"
    },
    {
      "x": -2,
      "y": 7,
      "z": -9,
      "name": "Soil_Mud_Dry"
    },
    {
      "x": -2,
      "y": 8,
      "z": -9,
      "name": "Soil_Mud_Dry"
    },
    {
      "x": -2,
      "y": 3,
      "z": -8,
      "name": "Rock_Sandstone_Red"
    },
    {
      "x": -2,
      "y": 4,
      "z": -8,
      "name": "Rock_Sandstone_Red"
    },
    {
      "x": -2,
      "y": 5,
      "z": -8,
      "name": "Rock_Sandstone_Red"
    },
    {
      "x": -2,
      "y": 6,
      "z": -8,
      "name": "Soil_Clay"
    },
    {
      "x": -2,
      "y": 7,
      "z": -8,
      "name": "Soil_Mud_Dry"
    },
    {
      "x": -2,
      "y": 8,
      "z": -8,
      "name": "Soil_Mud_Dry"
    },
    {
      "x": -2,
      "y": 3,
      "z": -7,
      "name": "Rock_Sandstone_Red"
    },
    {
      "x": -2,
      "y": 4,
      "z": -7,
      "name": "Rock_Sandstone_Red"
    },
    {
      "x": -2,
      "y": 5,
      "z": -7,
      "name": "Rock_Sandstone_Red"
    },
    {
      "x": -2,
      "y": 3,
      "z": -6,
      "name": "Rock_Sandstone_Red"
    },
    {
      "x": -2,
      "y": 4,
      "z": -6,
      "name": "Rock_Sandstone_Red"
    },
    {
      "x": -2,
      "y": 5,
      "z": -6,
      "name": "Rock_Sandstone_Red"
    },
    {
      "x": -2,
      "y": 3,
      "z": -5,
      "name": "Rock_Sandstone_Red"
    },
    {
      "x": -2,
      "y": 4,
      "z": -5,
      "name": "Rock_Sandstone_Red"
    },
    {
      "x": -2,
      "y": 5,
      "z": -5,
      "name": "Rock_Sandstone_Red"
    },
    {
      "x": -2,
      "y": 3,
      "z": -4,
      "name": "Rock_Sandstone_Red"
    },
    {
      "x": -2,
      "y": 4,
      "z": -4,
      "name": "Rock_Sandstone_Red"
    },
    {
      "x": -2,
      "y": 5,
      "z": -4,
      "name": "Rock_Sandstone_Red"
    },
    {
      "x": -2,
      "y": 3,
      "z": -3,
      "name": "Rock_Sandstone_Red"
    },
    {
      "x": -2,
      "y": 4,
      "z": -3,
      "name": "Rock_Sandstone_Red"
    },
    {
      "x": -2,
      "y": 5,
      "z": -3,
      "name": "Rock_Sandstone_Red"
    },
    {
      "x": -2,
      "y": 3,
      "z": -2,
      "name": "Rock_Sandstone_Red"
    },
    {
      "x": -2,
      "y": 4,
      "z": -2,
      "name": "Rock_Sandstone_Red"
    },
    {
      "x": -2,
      "y": 5,
      "z": -2,
      "name": "Rock_Sandstone_Red"
    },
    {
      "x": -2,
      "y": 3,
      "z": -1,
      "name": "Rock_Sandstone_Red"
    },
    {
      "x": -2,
      "y": 4,
      "z": -1,
      "name": "Rock_Sandstone_Red"
    },
    {
      "x": -2,
      "y": 5,
      "z": -1,
      "name": "Rock_Sandstone_Red"
    },
    {
      "x": -2,
      "y": 3,
      "z": 0,
      "name": "Rock_Sandstone_Red"
    },
    {
      "x": -2,
      "y": 4,
      "z": 0,
      "name": "Rock_Sandstone_Red"
    },
    {
      "x": -2,
      "y": 5,
      "z": 0,
      "name": "Rock_Sandstone_Red"
    },
    {
      "x": -2,
      "y": 3,
      "z": 1,
      "name": "Rock_Sandstone_Red"
    },
    {
      "x": -2,
      "y": 4,
      "z": 1,
      "name": "Rock_Sandstone_Red"
    },
    {
      "x": -2,
      "y": 5,
      "z": 1,
      "name": "Rock_Sandstone_Red"
    },
    {
      "x": -2,
      "y": 3,
      "z": 2,
      "name": "Rock_Sandstone_Red"
    },
    {
      "x": -2,
      "y": 4,
      "z": 2,
      "name": "Rock_Sandstone_Red"
    },
    {
      "x": -2,
      "y": 5,
      "z": 2,
      "name": "Rock_Sandstone_Red"
    },
    {
      "x": -2,
      "y": 3,
      "z": 3,
      "name": "Rock_Sandstone_Red"
    },
    {
      "x": -2,
      "y": 4,
      "z": 3,
      "name": "Rock_Sandstone_Red"
    },
    {
      "x": -2,
      "y": 5,
      "z": 3,
      "name": "Rock_Sandstone_Red"
    },
    {
      "x": -2,
      "y": 6,
      "z": 3,
      "name": "Rock_Sandstone_Red"
    },
    {
      "x": -2,
      "y": 7,
      "z": 3,
      "name": "Soil_Clay"
    },
    {
      "x": -2,
      "y": 8,
      "z": 3,
      "name": "Soil_Hive"
    },
    {
      "x": -2,
      "y": 3,
      "z": 4,
      "name": "Rock_Sandstone_Red"
    },
    {
      "x": -2,
      "y": 4,
      "z": 4,
      "name": "Rock_Sandstone_Red"
    },
    {
      "x": -2,
      "y": 5,
      "z": 4,
      "name": "Rock_Sandstone_Red"
    },
    {
      "x": -2,
      "y": 6,
      "z": 4,
      "name": "Rock_Sandstone_Red"
    },
    {
      "x": -2,
      "y": 7,
      "z": 4,
      "name": "Soil_Clay"
    },
    {
      "x": -2,
      "y": 8,
      "z": 4,
      "name": "Rock_Sandstone_Red"
    },
    {
      "x": -2,
      "y": 9,
      "z": 4,
      "name": "Rock_Sandstone_Red"
    },
    {
      "x": -2,
      "y": 3,
      "z": 5,
      "name": "Rock_Sandstone_Red"
    },
    {
      "x": -2,
      "y": 4,
      "z": 5,
      "name": "Rock_Sandstone_Red"
    },
    {
      "x": -2,
      "y": 5,
      "z": 5,
      "name": "Rock_Sandstone_Red"
    },
    {
      "x": -2,
      "y": 6,
      "z": 5,
      "name": "Rock_Sandstone_Red"
    },
    {
      "x": -2,
      "y": 7,
      "z": 5,
      "name": "Soil_Clay"
    },
    {
      "x": -2,
      "y": 8,
      "z": 5,
      "name": "Soil_Clay"
    },
    {
      "x": -2,
      "y": 9,
      "z": 5,
      "name": "Rock_Sandstone_Red"
    },
    {
      "x": -2,
      "y": 3,
      "z": 6,
      "name": "Rock_Sandstone_Red"
    },
    {
      "x": -2,
      "y": 4,
      "z": 6,
      "name": "Rock_Sandstone_Red"
    },
    {
      "x": -2,
      "y": 5,
      "z": 6,
      "name": "Rock_Sandstone_Red"
    },
    {
      "x": -2,
      "y": 6,
      "z": 6,
      "name": "Rock_Sandstone_Red"
    },
    {
      "x": -2,
      "y": 7,
      "z": 6,
      "name": "Soil_Clay"
    },
    {
      "x": -2,
      "y": 8,
      "z": 6,
      "name": "Soil_Clay"
    },
    {
      "x": -2,
      "y": 9,
      "z": 6,
      "name": "Soil_Mud_Dry"
    },
    {
      "x": -2,
      "y": 3,
      "z": 7,
      "name": "Rock_Sandstone_Red"
    },
    {
      "x": -2,
      "y": 4,
      "z": 7,
      "name": "Rock_Sandstone_Red"
    },
    {
      "x": -2,
      "y": 5,
      "z": 7,
      "name": "Rock_Sandstone_Red"
    },
    {
      "x": -2,
      "y": 6,
      "z": 7,
      "name": "Rock_Sandstone_Red"
    },
    {
      "x": -2,
      "y": 7,
      "z": 7,
      "name": "Soil_Clay"
    },
    {
      "x": -2,
      "y": 8,
      "z": 7,
      "name": "Soil_Clay"
    },
    {
      "x": -2,
      "y": 9,
      "z": 7,
      "name": "Soil_Mud_Dry"
    },
    {
      "x": -2,
      "y": 3,
      "z": 8,
      "name": "Soil_Hive"
    },
    {
      "x": -2,
      "y": 4,
      "z": 8,
      "name": "Soil_Hive"
    },
    {
      "x": -1,
      "y": 3,
      "z": -9,
      "name": "Rock_Sandstone_Red"
    },
    {
      "x": -1,
      "y": 4,
      "z": -9,
      "name": "Rock_Sandstone_Red"
    },
    {
      "x": -1,
      "y": 5,
      "z": -9,
      "name": "Rock_Sandstone_Red"
    },
    {
      "x": -1,
      "y": 6,
      "z": -9,
      "name": "Soil_Clay"
    },
    {
      "x": -1,
      "y": 7,
      "z": -9,
      "name": "Rock_Sandstone_Red"
    },
    {
      "x": -1,
      "y": 8,
      "z": -9,
      "name": "Soil_Mud_Dry"
    },
    {
      "x": -1,
      "y": 3,
      "z": -8,
      "name": "Rock_Sandstone_Red"
    },
    {
      "x": -1,
      "y": 4,
      "z": -8,
      "name": "Rock_Sandstone_Red"
    },
    {
      "x": -1,
      "y": 5,
      "z": -8,
      "name": "Rock_Sandstone_Red"
    },
    {
      "x": -1,
      "y": 6,
      "z": -8,
      "name": "Soil_Clay"
    },
    {
      "x": -1,
      "y": 7,
      "z": -8,
      "name": "Rock_Sandstone_Red"
    },
    {
      "x": -1,
      "y": 8,
      "z": -8,
      "name": "Soil_Hive"
    },
    {
      "x": -1,
      "y": 3,
      "z": -7,
      "name": "Rock_Sandstone_Red"
    },
    {
      "x": -1,
      "y": 4,
      "z": -7,
      "name": "Rock_Sandstone_Red"
    },
    {
      "x": -1,
      "y": 5,
      "z": -7,
      "name": "Rock_Sandstone_Red"
    },
    {
      "x": -1,
      "y": 3,
      "z": -6,
      "name": "Rock_Sandstone_Red"
    },
    {
      "x": -1,
      "y": 4,
      "z": -6,
      "name": "Rock_Sandstone_Red"
    },
    {
      "x": -1,
      "y": 5,
      "z": -6,
      "name": "Rock_Sandstone_Red"
    },
    {
      "x": -1,
      "y": 3,
      "z": -5,
      "name": "Rock_Sandstone_Red"
    },
    {
      "x": -1,
      "y": 4,
      "z": -5,
      "name": "Rock_Sandstone_Red"
    },
    {
      "x": -1,
      "y": 5,
      "z": -5,
      "name": "Rock_Sandstone_Red"
    },
    {
      "x": -1,
      "y": 3,
      "z": -4,
      "name": "Rock_Sandstone_Red"
    },
    {
      "x": -1,
      "y": 4,
      "z": -4,
      "name": "Rock_Sandstone_Red"
    },
    {
      "x": -1,
      "y": 5,
      "z": -4,
      "name": "Rock_Sandstone_Red"
    },
    {
      "x": -1,
      "y": 3,
      "z": -3,
      "name": "Rock_Sandstone_Red"
    },
    {
      "x": -1,
      "y": 4,
      "z": -3,
      "name": "Rock_Sandstone_Red"
    },
    {
      "x": -1,
      "y": 5,
      "z": -3,
      "name": "Rock_Sandstone_Red"
    },
    {
      "x": -1,
      "y": 3,
      "z": -2,
      "name": "Rock_Sandstone_Red"
    },
    {
      "x": -1,
      "y": 4,
      "z": -2,
      "name": "Rock_Sandstone_Red"
    },
    {
      "x": -1,
      "y": 5,
      "z": -2,
      "name": "Rock_Sandstone_Red"
    },
    {
      "x": -1,
      "y": 3,
      "z": -1,
      "name": "Rock_Sandstone_Red"
    },
    {
      "x": -1,
      "y": 4,
      "z": -1,
      "name": "Rock_Sandstone_Red"
    },
    {
      "x": -1,
      "y": 5,
      "z": -1,
      "name": "Rock_Sandstone_Red"
    },
    {
      "x": -1,
      "y": 3,
      "z": 0,
      "name": "Rock_Sandstone_Red"
    },
    {
      "x": -1,
      "y": 4,
      "z": 0,
      "name": "Rock_Sandstone_Red"
    },
    {
      "x": -1,
      "y": 5,
      "z": 0,
      "name": "Rock_Sandstone_Red"
    },
    {
      "x": -1,
      "y": 3,
      "z": 1,
      "name": "Rock_Sandstone_Red"
    },
    {
      "x": -1,
      "y": 4,
      "z": 1,
      "name": "Rock_Sandstone_Red"
    },
    {
      "x": -1,
      "y": 5,
      "z": 1,
      "name": "Rock_Sandstone_Red"
    },
    {
      "x": -1,
      "y": 3,
      "z": 2,
      "name": "Rock_Sandstone_Red"
    },
    {
      "x": -1,
      "y": 4,
      "z": 2,
      "name": "Rock_Sandstone_Red"
    },
    {
      "x": -1,
      "y": 5,
      "z": 2,
      "name": "Rock_Sandstone_Red"
    },
    {
      "x": -1,
      "y": 3,
      "z": 3,
      "name": "Rock_Sandstone_Red"
    },
    {
      "x": -1,
      "y": 4,
      "z": 3,
      "name": "Rock_Sandstone_Red"
    },
    {
      "x": -1,
      "y": 5,
      "z": 3,
      "name": "Rock_Sandstone_Red"
    },
    {
      "x": -1,
      "y": 3,
      "z": 4,
      "name": "Rock_Sandstone_Red"
    },
    {
      "x": -1,
      "y": 4,
      "z": 4,
      "name": "Rock_Sandstone_Red"
    },
    {
      "x": -1,
      "y": 5,
      "z": 4,
      "name": "Rock_Sandstone_Red"
    },
    {
      "x": -1,
      "y": 3,
      "z": 5,
      "name": "Rock_Sandstone_Red"
    },
    {
      "x": -1,
      "y": 4,
      "z": 5,
      "name": "Rock_Sandstone_Red"
    },
    {
      "x": -1,
      "y": 5,
      "z": 5,
      "name": "Rock_Sandstone_Red"
    },
    {
      "x": -1,
      "y": 6,
      "z": 5,
      "name": "Soil_Mud"
    },
    {
      "x": -1,
      "y": 3,
      "z": 6,
      "name": "Rock_Sandstone_Red"
    },
    {
      "x": -1,
      "y": 4,
      "z": 6,
      "name": "Rock_Sandstone_Red"
    },
    {
      "x": -1,
      "y": 5,
      "z": 6,
      "name": "Rock_Sandstone_Red"
    },
    {
      "x": -1,
      "y": 6,
      "z": 6,
      "name": "Soil_Mud"
    },
    {
      "x": -1,
      "y": 3,
      "z": 7,
      "name": "Rock_Sandstone_Red"
    },
    {
      "x": -1,
      "y": 4,
      "z": 7,
      "name": "Rock_Sandstone_Red"
    },
    {
      "x": -1,
      "y": 5,
      "z": 7,
      "name": "Rock_Sandstone_Red"
    },
    {
      "x": -1,
      "y": 6,
      "z": 7,
      "name": "Rock_Sandstone_Red"
    },
    {
      "x": -1,
      "y": 7,
      "z": 7,
      "name": "Soil_Clay"
    },
    {
      "x": -1,
      "y": 8,
      "z": 7,
      "name": "Soil_Mud_Dry"
    },
    {
      "x": -1,
      "y": 9,
      "z": 7,
      "name": "Plant_Flower_Common_Poisoned"
    },
    {
      "x": -1,
      "y": 4,
      "z": 8,
      "name": "Soil_Hive"
    },
    {
      "x": 0,
      "y": 3,
      "z": -9,
      "name": "Rock_Sandstone_Red"
    },
    {
      "x": 0,
      "y": 4,
      "z": -9,
      "name": "Rock_Sandstone_Red"
    },
    {
      "x": 0,
      "y": 5,
      "z": -9,
      "name": "Rock_Sandstone_Red"
    },
    {
      "x": 0,
      "y": 6,
      "z": -9,
      "name": "Soil_Clay"
    },
    {
      "x": 0,
      "y": 7,
      "z": -9,
      "name": "Rock_Sandstone_Red"
    },
    {
      "x": 0,
      "y": 8,
      "z": -9,
      "name": "Soil_Hive"
    },
    {
      "x": 0,
      "y": 3,
      "z": -8,
      "name": "Rock_Sandstone_Red"
    },
    {
      "x": 0,
      "y": 4,
      "z": -8,
      "name": "Rock_Sandstone_Red"
    },
    {
      "x": 0,
      "y": 5,
      "z": -8,
      "name": "Rock_Sandstone_Red"
    },
    {
      "x": 0,
      "y": 6,
      "z": -8,
      "name": "Soil_Clay"
    },
    {
      "x": 0,
      "y": 7,
      "z": -8,
      "name": "Rock_Sandstone_Red"
    },
    {
      "x": 0,
      "y": 8,
      "z": -8,
      "name": "Soil_Hive"
    },
    {
      "x": 0,
      "y": 3,
      "z": -7,
      "name": "Rock_Sandstone_Red"
    },
    {
      "x": 0,
      "y": 4,
      "z": -7,
      "name": "Rock_Sandstone_Red"
    },
    {
      "x": 0,
      "y": 5,
      "z": -7,
      "name": "Rock_Sandstone_Red"
    },
    {
      "x": 0,
      "y": 6,
      "z": -7,
      "name": "Soil_Mud"
    },
    {
      "x": 0,
      "y": 3,
      "z": -6,
      "name": "Rock_Sandstone_Red"
    },
    {
      "x": 0,
      "y": 4,
      "z": -6,
      "name": "Rock_Sandstone_Red"
    },
    {
      "x": 0,
      "y": 5,
      "z": -6,
      "name": "Rock_Sandstone_Red"
    },
    {
      "x": 0,
      "y": 3,
      "z": -5,
      "name": "Rock_Sandstone_Red"
    },
    {
      "x": 0,
      "y": 4,
      "z": -5,
      "name": "Rock_Sandstone_Red"
    },
    {
      "x": 0,
      "y": 5,
      "z": -5,
      "name": "Rock_Sandstone_Red"
    },
    {
      "x": 0,
      "y": 3,
      "z": -4,
      "name": "Rock_Sandstone_Red"
    },
    {
      "x": 0,
      "y": 4,
      "z": -4,
      "name": "Rock_Sandstone_Red"
    },
    {
      "x": 0,
      "y": 5,
      "z": -4,
      "name": "Rock_Sandstone_Red"
    },
    {
      "x": 0,
      "y": 3,
      "z": -3,
      "name": "Rock_Sandstone_Red"
    },
    {
      "x": 0,
      "y": 4,
      "z": -3,
      "name": "Rock_Sandstone_Red"
    },
    {
      "x": 0,
      "y": 5,
      "z": -3,
      "name": "Rock_Sandstone_Red"
    },
    {
      "x": 0,
      "y": 3,
      "z": -2,
      "name": "Rock_Sandstone_Red"
    },
    {
      "x": 0,
      "y": 4,
      "z": -2,
      "name": "Rock_Sandstone_Red"
    },
    {
      "x": 0,
      "y": 5,
      "z": -2,
      "name": "Rock_Sandstone_Red"
    },
    {
      "x": 0,
      "y": 3,
      "z": -1,
      "name": "Rock_Sandstone_Red"
    },
    {
      "x": 0,
      "y": 4,
      "z": -1,
      "name": "Rock_Sandstone_Red"
    },
    {
      "x": 0,
      "y": 5,
      "z": -1,
      "name": "Rock_Sandstone_Red"
    },
    {
      "x": 0,
      "y": 3,
      "z": 0,
      "name": "Rock_Sandstone_Red"
    },
    {
      "x": 0,
      "y": 4,
      "z": 0,
      "name": "Rock_Sandstone_Red"
    },
    {
      "x": 0,
      "y": 5,
      "z": 0,
      "name": "Rock_Sandstone_Red"
    },
    {
      "x": 0,
      "y": 3,
      "z": 1,
      "name": "Rock_Sandstone_Red"
    },
    {
      "x": 0,
      "y": 4,
      "z": 1,
      "name": "Rock_Sandstone_Red"
    },
    {
      "x": 0,
      "y": 5,
      "z": 1,
      "name": "Rock_Sandstone_Red"
    },
    {
      "x": 0,
      "y": 3,
      "z": 2,
      "name": "Rock_Sandstone_Red"
    },
    {
      "x": 0,
      "y": 4,
      "z": 2,
      "name": "Rock_Sandstone_Red"
    },
    {
      "x": 0,
      "y": 5,
      "z": 2,
      "name": "Rock_Sandstone_Red"
    },
    {
      "x": 0,
      "y": 3,
      "z": 3,
      "name": "Rock_Sandstone_Red"
    },
    {
      "x": 0,
      "y": 4,
      "z": 3,
      "name": "Rock_Sandstone_Red"
    },
    {
      "x": 0,
      "y": 5,
      "z": 3,
      "name": "Rock_Sandstone_Red"
    },
    {
      "x": 0,
      "y": 3,
      "z": 4,
      "name": "Rock_Sandstone_Red"
    },
    {
      "x": 0,
      "y": 4,
      "z": 4,
      "name": "Rock_Sandstone_Red"
    },
    {
      "x": 0,
      "y": 5,
      "z": 4,
      "name": "Rock_Sandstone_Red"
    },
    {
      "x": 0,
      "y": 3,
      "z": 5,
      "name": "Rock_Sandstone_Red"
    },
    {
      "x": 0,
      "y": 4,
      "z": 5,
      "name": "Rock_Sandstone_Red"
    },
    {
      "x": 0,
      "y": 5,
      "z": 5,
      "name": "Rock_Sandstone_Red"
    },
    {
      "x": 0,
      "y": 3,
      "z": 6,
      "name": "Rock_Sandstone_Red"
    },
    {
      "x": 0,
      "y": 4,
      "z": 6,
      "name": "Rock_Sandstone_Red"
    },
    {
      "x": 0,
      "y": 5,
      "z": 6,
      "name": "Rock_Sandstone_Red"
    },
    {
      "x": 0,
      "y": 6,
      "z": 6,
      "name": "Soil_Mud"
    },
    {
      "x": 0,
      "y": 3,
      "z": 7,
      "name": "Rock_Sandstone_Red"
    },
    {
      "x": 0,
      "y": 4,
      "z": 7,
      "name": "Rock_Sandstone_Red"
    },
    {
      "x": 0,
      "y": 5,
      "z": 7,
      "name": "Rock_Sandstone_Red"
    },
    {
      "x": 0,
      "y": 6,
      "z": 7,
      "name": "Rock_Sandstone_Red"
    },
    {
      "x": 0,
      "y": 7,
      "z": 7,
      "name": "Soil_Clay"
    },
    {
      "x": 0,
      "y": 8,
      "z": 7,
      "name": "Soil_Hive"
    },
    {
      "x": 0,
      "y": 4,
      "z": 8,
      "name": "Soil_Hive"
    },
    {
      "x": 0,
      "y": 5,
      "z": 8,
      "name": "Soil_Hive"
    },
    {
      "x": 1,
      "y": 3,
      "z": -9,
      "name": "Rock_Sandstone_Red"
    },
    {
      "x": 1,
      "y": 4,
      "z": -9,
      "name": "Rock_Sandstone_Red"
    },
    {
      "x": 1,
      "y": 5,
      "z": -9,
      "name": "Rock_Sandstone_Red"
    },
    {
      "x": 1,
      "y": 6,
      "z": -9,
      "name": "Soil_Clay"
    },
    {
      "x": 1,
      "y": 7,
      "z": -9,
      "name": "Soil_Clay"
    },
    {
      "x": 1,
      "y": 8,
      "z": -9,
      "name": "Soil_Hive"
    },
    {
      "x": 1,
      "y": 3,
      "z": -8,
      "name": "Rock_Sandstone_Red"
    },
    {
      "x": 1,
      "y": 4,
      "z": -8,
      "name": "Rock_Sandstone_Red"
    },
    {
      "x": 1,
      "y": 5,
      "z": -8,
      "name": "Rock_Sandstone_Red"
    },
    {
      "x": 1,
      "y": 6,
      "z": -8,
      "name": "Soil_Clay"
    },
    {
      "x": 1,
      "y": 7,
      "z": -8,
      "name": "Rock_Sandstone_Red"
    },
    {
      "x": 1,
      "y": 8,
      "z": -8,
      "name": "Soil_Hive"
    },
    {
      "x": 1,
      "y": 3,
      "z": -7,
      "name": "Rock_Sandstone_Red"
    },
    {
      "x": 1,
      "y": 4,
      "z": -7,
      "name": "Rock_Sandstone_Red"
    },
    {
      "x": 1,
      "y": 5,
      "z": -7,
      "name": "Rock_Sandstone_Red"
    },
    {
      "x": 1,
      "y": 6,
      "z": -7,
      "name": "Soil_Mud"
    },
    {
      "x": 1,
      "y": 3,
      "z": -6,
      "name": "Rock_Sandstone_Red"
    },
    {
      "x": 1,
      "y": 4,
      "z": -6,
      "name": "Rock_Sandstone_Red"
    },
    {
      "x": 1,
      "y": 5,
      "z": -6,
      "name": "Rock_Sandstone_Red"
    },
    {
      "x": 1,
      "y": 3,
      "z": -5,
      "name": "Rock_Sandstone_Red"
    },
    {
      "x": 1,
      "y": 4,
      "z": -5,
      "name": "Rock_Sandstone_Red"
    },
    {
      "x": 1,
      "y": 5,
      "z": -5,
      "name": "Rock_Sandstone_Red"
    },
    {
      "x": 1,
      "y": 3,
      "z": -4,
      "name": "Rock_Sandstone_Red"
    },
    {
      "x": 1,
      "y": 4,
      "z": -4,
      "name": "Rock_Sandstone_Red"
    },
    {
      "x": 1,
      "y": 5,
      "z": -4,
      "name": "Rock_Sandstone_Red"
    },
    {
      "x": 1,
      "y": 3,
      "z": -3,
      "name": "Rock_Sandstone_Red"
    },
    {
      "x": 1,
      "y": 4,
      "z": -3,
      "name": "Rock_Sandstone_Red"
    },
    {
      "x": 1,
      "y": 5,
      "z": -3,
      "name": "Rock_Sandstone_Red"
    },
    {
      "x": 1,
      "y": 3,
      "z": -2,
      "name": "Rock_Sandstone_Red"
    },
    {
      "x": 1,
      "y": 4,
      "z": -2,
      "name": "Rock_Sandstone_Red"
    },
    {
      "x": 1,
      "y": 5,
      "z": -2,
      "name": "Rock_Sandstone_Red"
    },
    {
      "x": 1,
      "y": 3,
      "z": -1,
      "name": "Rock_Sandstone_Red"
    },
    {
      "x": 1,
      "y": 4,
      "z": -1,
      "name": "Rock_Sandstone_Red"
    },
    {
      "x": 1,
      "y": 5,
      "z": -1,
      "name": "Rock_Sandstone_Red"
    },
    {
      "x": 1,
      "y": 3,
      "z": 0,
      "name": "Rock_Sandstone_Red"
    },
    {
      "x": 1,
      "y": 4,
      "z": 0,
      "name": "Rock_Sandstone_Red"
    },
    {
      "x": 1,
      "y": 5,
      "z": 0,
      "name": "Rock_Sandstone_Red"
    },
    {
      "x": 1,
      "y": 3,
      "z": 1,
      "name": "Rock_Sandstone_Red"
    },
    {
      "x": 1,
      "y": 4,
      "z": 1,
      "name": "Rock_Sandstone_Red"
    },
    {
      "x": 1,
      "y": 5,
      "z": 1,
      "name": "Rock_Sandstone_Red"
    },
    {
      "x": 1,
      "y": 3,
      "z": 2,
      "name": "Rock_Sandstone_Red"
    },
    {
      "x": 1,
      "y": 4,
      "z": 2,
      "name": "Rock_Sandstone_Red"
    },
    {
      "x": 1,
      "y": 5,
      "z": 2,
      "name": "Rock_Sandstone_Red"
    },
    {
      "x": 1,
      "y": 3,
      "z": 3,
      "name": "Rock_Sandstone_Red"
    },
    {
      "x": 1,
      "y": 4,
      "z": 3,
      "name": "Rock_Sandstone_Red"
    },
    {
      "x": 1,
      "y": 5,
      "z": 3,
      "name": "Rock_Sandstone_Red"
    },
    {
      "x": 1,
      "y": 3,
      "z": 4,
      "name": "Rock_Sandstone_Red"
    },
    {
      "x": 1,
      "y": 4,
      "z": 4,
      "name": "Rock_Sandstone_Red"
    },
    {
      "x": 1,
      "y": 5,
      "z": 4,
      "name": "Rock_Sandstone_Red"
    },
    {
      "x": 1,
      "y": 3,
      "z": 5,
      "name": "Rock_Sandstone_Red"
    },
    {
      "x": 1,
      "y": 4,
      "z": 5,
      "name": "Rock_Sandstone_Red"
    },
    {
      "x": 1,
      "y": 5,
      "z": 5,
      "name": "Rock_Sandstone_Red"
    },
    {
      "x": 1,
      "y": 6,
      "z": 5,
      "name": "Soil_Mud"
    },
    {
      "x": 1,
      "y": 3,
      "z": 6,
      "name": "Rock_Sandstone_Red"
    },
    {
      "x": 1,
      "y": 4,
      "z": 6,
      "name": "Rock_Sandstone_Red"
    },
    {
      "x": 1,
      "y": 5,
      "z": 6,
      "name": "Rock_Sandstone_Red"
    },
    {
      "x": 1,
      "y": 6,
      "z": 6,
      "name": "Soil_Mud"
    },
    {
      "x": 1,
      "y": 3,
      "z": 7,
      "name": "Rock_Sandstone_Red"
    },
    {
      "x": 1,
      "y": 4,
      "z": 7,
      "name": "Rock_Sandstone_Red"
    },
    {
      "x": 1,
      "y": 5,
      "z": 7,
      "name": "Rock_Sandstone_Red"
    },
    {
      "x": 1,
      "y": 6,
      "z": 7,
      "name": "Rock_Sandstone_Red"
    },
    {
      "x": 1,
      "y": 7,
      "z": 7,
      "name": "Soil_Clay"
    },
    {
      "x": 1,
      "y": 8,
      "z": 7,
      "name": "Soil_Hive"
    },
    {
      "x": 1,
      "y": 4,
      "z": 8,
      "name": "Soil_Hive"
    },
    {
      "x": 1,
      "y": 5,
      "z": 8,
      "name": "Soil_Hive"
    },
    {
      "x": 2,
      "y": 3,
      "z": -9,
      "name": "Rock_Sandstone_Red"
    },
    {
      "x": 2,
      "y": 4,
      "z": -9,
      "name": "Rock_Sandstone_Red"
    },
    {
      "x": 2,
      "y": 5,
      "z": -9,
      "name": "Rock_Sandstone_Red"
    },
    {
      "x": 2,
      "y": 6,
      "z": -9,
      "name": "Soil_Clay"
    },
    {
      "x": 2,
      "y": 7,
      "z": -9,
      "name": "Soil_Clay"
    },
    {
      "x": 2,
      "y": 3,
      "z": -8,
      "name": "Rock_Sandstone_Red"
    },
    {
      "x": 2,
      "y": 4,
      "z": -8,
      "name": "Rock_Sandstone_Red"
    },
    {
      "x": 2,
      "y": 5,
      "z": -8,
      "name": "Rock_Sandstone_Red"
    },
    {
      "x": 2,
      "y": 6,
      "z": -8,
      "name": "Soil_Clay"
    },
    {
      "x": 2,
      "y": 7,
      "z": -8,
      "name": "Soil_Clay"
    },
    {
      "x": 2,
      "y": 8,
      "z": -8,
      "name": "Soil_Hive"
    },
    {
      "x": 2,
      "y": 3,
      "z": -7,
      "name": "Rock_Sandstone_Red"
    },
    {
      "x": 2,
      "y": 4,
      "z": -7,
      "name": "Rock_Sandstone_Red"
    },
    {
      "x": 2,
      "y": 5,
      "z": -7,
      "name": "Rock_Sandstone_Red"
    },
    {
      "x": 2,
      "y": 6,
      "z": -7,
      "name": "Soil_Mud"
    },
    {
      "x": 2,
      "y": 3,
      "z": -6,
      "name": "Rock_Sandstone_Red"
    },
    {
      "x": 2,
      "y": 4,
      "z": -6,
      "name": "Rock_Sandstone_Red"
    },
    {
      "x": 2,
      "y": 5,
      "z": -6,
      "name": "Rock_Sandstone_Red"
    },
    {
      "x": 2,
      "y": 6,
      "z": -6,
      "name": "Soil_Mud"
    },
    {
      "x": 2,
      "y": 3,
      "z": -5,
      "name": "Rock_Sandstone_Red"
    },
    {
      "x": 2,
      "y": 4,
      "z": -5,
      "name": "Rock_Sandstone_Red"
    },
    {
      "x": 2,
      "y": 5,
      "z": -5,
      "name": "Rock_Sandstone_Red"
    },
    {
      "x": 2,
      "y": 3,
      "z": -4,
      "name": "Rock_Sandstone_Red"
    },
    {
      "x": 2,
      "y": 4,
      "z": -4,
      "name": "Rock_Sandstone_Red"
    },
    {
      "x": 2,
      "y": 5,
      "z": -4,
      "name": "Rock_Sandstone_Red"
    },
    {
      "x": 2,
      "y": 3,
      "z": -3,
      "name": "Rock_Sandstone_Red"
    },
    {
      "x": 2,
      "y": 4,
      "z": -3,
      "name": "Rock_Sandstone_Red"
    },
    {
      "x": 2,
      "y": 5,
      "z": -3,
      "name": "Rock_Sandstone_Red"
    },
    {
      "x": 2,
      "y": 3,
      "z": -2,
      "name": "Rock_Sandstone_Red"
    },
    {
      "x": 2,
      "y": 4,
      "z": -2,
      "name": "Rock_Sandstone_Red"
    },
    {
      "x": 2,
      "y": 5,
      "z": -2,
      "name": "Rock_Sandstone_Red"
    },
    {
      "x": 2,
      "y": 3,
      "z": -1,
      "name": "Rock_Sandstone_Red"
    },
    {
      "x": 2,
      "y": 4,
      "z": -1,
      "name": "Rock_Sandstone_Red"
    },
    {
      "x": 2,
      "y": 5,
      "z": -1,
      "name": "Rock_Sandstone_Red"
    },
    {
      "x": 2,
      "y": 3,
      "z": 0,
      "name": "Rock_Sandstone_Red"
    },
    {
      "x": 2,
      "y": 4,
      "z": 0,
      "name": "Rock_Sandstone_Red"
    },
    {
      "x": 2,
      "y": 5,
      "z": 0,
      "name": "Rock_Sandstone_Red"
    },
    {
      "x": 2,
      "y": 3,
      "z": 1,
      "name": "Rock_Sandstone_Red"
    },
    {
      "x": 2,
      "y": 4,
      "z": 1,
      "name": "Rock_Sandstone_Red"
    },
    {
      "x": 2,
      "y": 5,
      "z": 1,
      "name": "Rock_Sandstone_Red"
    },
    {
      "x": 2,
      "y": 3,
      "z": 2,
      "name": "Rock_Sandstone_Red"
    },
    {
      "x": 2,
      "y": 4,
      "z": 2,
      "name": "Rock_Sandstone_Red"
    },
    {
      "x": 2,
      "y": 5,
      "z": 2,
      "name": "Rock_Sandstone_Red"
    },
    {
      "x": 2,
      "y": 3,
      "z": 3,
      "name": "Rock_Sandstone_Red"
    },
    {
      "x": 2,
      "y": 4,
      "z": 3,
      "name": "Rock_Sandstone_Red"
    },
    {
      "x": 2,
      "y": 5,
      "z": 3,
      "name": "Rock_Sandstone_Red"
    },
    {
      "x": 2,
      "y": 3,
      "z": 4,
      "name": "Rock_Sandstone_Red"
    },
    {
      "x": 2,
      "y": 4,
      "z": 4,
      "name": "Rock_Sandstone_Red"
    },
    {
      "x": 2,
      "y": 5,
      "z": 4,
      "name": "Rock_Sandstone_Red"
    },
    {
      "x": 2,
      "y": 3,
      "z": 5,
      "name": "Rock_Sandstone_Red"
    },
    {
      "x": 2,
      "y": 4,
      "z": 5,
      "name": "Rock_Sandstone_Red"
    },
    {
      "x": 2,
      "y": 5,
      "z": 5,
      "name": "Rock_Sandstone_Red"
    },
    {
      "x": 2,
      "y": 6,
      "z": 5,
      "name": "Soil_Mud"
    },
    {
      "x": 2,
      "y": 7,
      "z": 5,
      "name": "Soil_Mud"
    },
    {
      "x": 2,
      "y": 3,
      "z": 6,
      "name": "Rock_Sandstone_Red"
    },
    {
      "x": 2,
      "y": 4,
      "z": 6,
      "name": "Rock_Sandstone_Red"
    },
    {
      "x": 2,
      "y": 5,
      "z": 6,
      "name": "Rock_Sandstone_Red"
    },
    {
      "x": 2,
      "y": 6,
      "z": 6,
      "name": "Rock_Sandstone_Red"
    },
    {
      "x": 2,
      "y": 7,
      "z": 6,
      "name": "Soil_Clay"
    },
    {
      "x": 2,
      "y": 8,
      "z": 6,
      "name": "Soil_Hive"
    },
    {
      "x": 2,
      "y": 3,
      "z": 7,
      "name": "Rock_Sandstone_Red"
    },
    {
      "x": 2,
      "y": 4,
      "z": 7,
      "name": "Rock_Sandstone_Red"
    },
    {
      "x": 2,
      "y": 5,
      "z": 7,
      "name": "Rock_Sandstone_Red"
    },
    {
      "x": 2,
      "y": 6,
      "z": 7,
      "name": "Rock_Sandstone_Red"
    },
    {
      "x": 2,
      "y": 7,
      "z": 7,
      "name": "Soil_Clay"
    },
    {
      "x": 2,
      "y": 8,
      "z": 7,
      "name": "Soil_Hive"
    },
    {
      "x": 2,
      "y": 5,
      "z": 8,
      "name": "Soil_Hive"
    },
    {
      "x": 2,
      "y": 6,
      "z": 8,
      "name": "Soil_Hive"
    },
    {
      "x": 3,
      "y": 3,
      "z": -9,
      "name": "Rock_Sandstone_Red"
    },
    {
      "x": 3,
      "y": 4,
      "z": -9,
      "name": "Rock_Sandstone_Red"
    },
    {
      "x": 3,
      "y": 5,
      "z": -9,
      "name": "Rock_Sandstone_Red"
    },
    {
      "x": 3,
      "y": 3,
      "z": -8,
      "name": "Rock_Sandstone_Red"
    },
    {
      "x": 3,
      "y": 4,
      "z": -8,
      "name": "Rock_Sandstone_Red"
    },
    {
      "x": 3,
      "y": 5,
      "z": -8,
      "name": "Rock_Sandstone_Red"
    },
    {
      "x": 3,
      "y": 6,
      "z": -8,
      "name": "Rock_Sandstone_Red"
    },
    {
      "x": 3,
      "y": 7,
      "z": -8,
      "name": "Soil_Clay"
    },
    {
      "x": 3,
      "y": 8,
      "z": -8,
      "name": "Soil_Mud_Dry"
    },
    {
      "x": 3,
      "y": 9,
      "z": -8,
      "name": "Plant_Flower_Common_Poisoned"
    },
    {
      "x": 3,
      "y": 3,
      "z": -7,
      "name": "Rock_Sandstone_Red"
    },
    {
      "x": 3,
      "y": 4,
      "z": -7,
      "name": "Rock_Sandstone_Red"
    },
    {
      "x": 3,
      "y": 5,
      "z": -7,
      "name": "Rock_Sandstone_Red"
    },
    {
      "x": 3,
      "y": 6,
      "z": -7,
      "name": "Soil_Mud"
    },
    {
      "x": 3,
      "y": 7,
      "z": -7,
      "name": "Soil_Mud"
    },
    {
      "x": 3,
      "y": 3,
      "z": -6,
      "name": "Rock_Sandstone_Red"
    },
    {
      "x": 3,
      "y": 4,
      "z": -6,
      "name": "Rock_Sandstone_Red"
    },
    {
      "x": 3,
      "y": 5,
      "z": -6,
      "name": "Rock_Sandstone_Red"
    },
    {
      "x": 3,
      "y": 6,
      "z": -6,
      "name": "Soil_Mud"
    },
    {
      "x": 3,
      "y": 3,
      "z": -5,
      "name": "Rock_Sandstone_Red"
    },
    {
      "x": 3,
      "y": 4,
      "z": -5,
      "name": "Rock_Sandstone_Red"
    },
    {
      "x": 3,
      "y": 5,
      "z": -5,
      "name": "Rock_Sandstone_Red"
    },
    {
      "x": 3,
      "y": 6,
      "z": -5,
      "name": "Soil_Mud"
    },
    {
      "x": 3,
      "y": 3,
      "z": -4,
      "name": "Rock_Sandstone_Red"
    },
    {
      "x": 3,
      "y": 4,
      "z": -4,
      "name": "Rock_Sandstone_Red"
    },
    {
      "x": 3,
      "y": 5,
      "z": -4,
      "name": "Rock_Sandstone_Red"
    },
    {
      "x": 3,
      "y": 3,
      "z": -3,
      "name": "Rock_Sandstone_Red"
    },
    {
      "x": 3,
      "y": 4,
      "z": -3,
      "name": "Rock_Sandstone_Red"
    },
    {
      "x": 3,
      "y": 5,
      "z": -3,
      "name": "Rock_Sandstone_Red"
    },
    {
      "x": 3,
      "y": 3,
      "z": -2,
      "name": "Rock_Sandstone_Red"
    },
    {
      "x": 3,
      "y": 4,
      "z": -2,
      "name": "Rock_Sandstone_Red"
    },
    {
      "x": 3,
      "y": 5,
      "z": -2,
      "name": "Rock_Sandstone_Red"
    },
    {
      "x": 3,
      "y": 3,
      "z": -1,
      "name": "Rock_Sandstone_Red"
    },
    {
      "x": 3,
      "y": 4,
      "z": -1,
      "name": "Rock_Sandstone_Red"
    },
    {
      "x": 3,
      "y": 5,
      "z": -1,
      "name": "Rock_Sandstone_Red"
    },
    {
      "x": 3,
      "y": 3,
      "z": 0,
      "name": "Rock_Sandstone_Red"
    },
    {
      "x": 3,
      "y": 4,
      "z": 0,
      "name": "Rock_Sandstone_Red"
    },
    {
      "x": 3,
      "y": 5,
      "z": 0,
      "name": "Rock_Sandstone_Red"
    },
    {
      "x": 3,
      "y": 3,
      "z": 1,
      "name": "Rock_Sandstone_Red"
    },
    {
      "x": 3,
      "y": 4,
      "z": 1,
      "name": "Rock_Sandstone_Red"
    },
    {
      "x": 3,
      "y": 5,
      "z": 1,
      "name": "Rock_Sandstone_Red"
    },
    {
      "x": 3,
      "y": 3,
      "z": 2,
      "name": "Rock_Sandstone_Red"
    },
    {
      "x": 3,
      "y": 4,
      "z": 2,
      "name": "Rock_Sandstone_Red"
    },
    {
      "x": 3,
      "y": 5,
      "z": 2,
      "name": "Rock_Sandstone_Red"
    },
    {
      "x": 3,
      "y": 3,
      "z": 3,
      "name": "Rock_Sandstone_Red"
    },
    {
      "x": 3,
      "y": 4,
      "z": 3,
      "name": "Rock_Sandstone_Red"
    },
    {
      "x": 3,
      "y": 5,
      "z": 3,
      "name": "Rock_Sandstone_Red"
    },
    {
      "x": 3,
      "y": 3,
      "z": 4,
      "name": "Rock_Sandstone_Red"
    },
    {
      "x": 3,
      "y": 4,
      "z": 4,
      "name": "Rock_Sandstone_Red"
    },
    {
      "x": 3,
      "y": 5,
      "z": 4,
      "name": "Rock_Sandstone_Red"
    },
    {
      "x": 3,
      "y": 3,
      "z": 5,
      "name": "Rock_Sandstone_Red"
    },
    {
      "x": 3,
      "y": 4,
      "z": 5,
      "name": "Rock_Sandstone_Red"
    },
    {
      "x": 3,
      "y": 5,
      "z": 5,
      "name": "Rock_Sandstone_Red"
    },
    {
      "x": 3,
      "y": 6,
      "z": 5,
      "name": "Soil_Clay"
    },
    {
      "x": 3,
      "y": 7,
      "z": 5,
      "name": "Soil_Mud"
    },
    {
      "x": 3,
      "y": 3,
      "z": 6,
      "name": "Rock_Sandstone_Red"
    },
    {
      "x": 3,
      "y": 4,
      "z": 6,
      "name": "Rock_Sandstone_Red"
    },
    {
      "x": 3,
      "y": 5,
      "z": 6,
      "name": "Rock_Sandstone_Red"
    },
    {
      "x": 3,
      "y": 6,
      "z": 6,
      "name": "Rock_Sandstone_Red"
    },
    {
      "x": 3,
      "y": 7,
      "z": 6,
      "name": "Soil_Clay"
    },
    {
      "x": 3,
      "y": 8,
      "z": 6,
      "name": "Soil_Hive"
    },
    {
      "x": 3,
      "y": 4,
      "z": 7,
      "name": "Rock_Sandstone_Red"
    },
    {
      "x": 3,
      "y": 5,
      "z": 7,
      "name": "Soil_Hive"
    },
    {
      "x": 3,
      "y": 6,
      "z": 7,
      "name": "Soil_Hive"
    },
    {
      "x": 3,
      "y": 7,
      "z": 7,
      "name": "Soil_Hive"
    },
    {
      "x": 3,
      "y": 8,
      "z": 7,
      "name": "Soil_Hive"
    },
    {
      "x": 3,
      "y": 5,
      "z": 8,
      "name": "Soil_Hive"
    },
    {
      "x": 3,
      "y": 6,
      "z": 8,
      "name": "Soil_Hive"
    },
    {
      "x": 4,
      "y": 3,
      "z": -8,
      "name": "Rock_Sandstone_Red"
    },
    {
      "x": 4,
      "y": 4,
      "z": -8,
      "name": "Rock_Sandstone_Red"
    },
    {
      "x": 4,
      "y": 5,
      "z": -8,
      "name": "Rock_Sandstone_Red"
    },
    {
      "x": 4,
      "y": 6,
      "z": -8,
      "name": "Rock_Sandstone_Red"
    },
    {
      "x": 4,
      "y": 7,
      "z": -8,
      "name": "Soil_Clay"
    },
    {
      "x": 4,
      "y": 8,
      "z": -8,
      "name": "Soil_Mud_Dry"
    },
    {
      "x": 4,
      "y": 3,
      "z": -7,
      "name": "Rock_Sandstone_Red"
    },
    {
      "x": 4,
      "y": 4,
      "z": -7,
      "name": "Rock_Sandstone_Red"
    },
    {
      "x": 4,
      "y": 5,
      "z": -7,
      "name": "Rock_Sandstone_Red"
    },
    {
      "x": 4,
      "y": 6,
      "z": -7,
      "name": "Soil_Clay"
    },
    {
      "x": 4,
      "y": 7,
      "z": -7,
      "name": "Soil_Clay"
    },
    {
      "x": 4,
      "y": 8,
      "z": -7,
      "name": "Soil_Mud_Dry"
    },
    {
      "x": 4,
      "y": 9,
      "z": -7,
      "name": "Plant_Flower_Common_Poisoned"
    },
    {
      "x": 4,
      "y": 3,
      "z": -6,
      "name": "Rock_Sandstone_Red"
    },
    {
      "x": 4,
      "y": 4,
      "z": -6,
      "name": "Rock_Sandstone_Red"
    },
    {
      "x": 4,
      "y": 5,
      "z": -6,
      "name": "Rock_Sandstone_Red"
    },
    {
      "x": 4,
      "y": 6,
      "z": -6,
      "name": "Soil_Mud"
    },
    {
      "x": 4,
      "y": 3,
      "z": -5,
      "name": "Rock_Sandstone_Red"
    },
    {
      "x": 4,
      "y": 4,
      "z": -5,
      "name": "Rock_Sandstone_Red"
    },
    {
      "x": 4,
      "y": 5,
      "z": -5,
      "name": "Rock_Sandstone_Red"
    },
    {
      "x": 4,
      "y": 6,
      "z": -5,
      "name": "Soil_Mud"
    },
    {
      "x": 4,
      "y": 3,
      "z": -4,
      "name": "Rock_Sandstone_Red"
    },
    {
      "x": 4,
      "y": 4,
      "z": -4,
      "name": "Rock_Sandstone_Red"
    },
    {
      "x": 4,
      "y": 5,
      "z": -4,
      "name": "Rock_Sandstone_Red"
    },
    {
      "x": 4,
      "y": 3,
      "z": -3,
      "name": "Rock_Sandstone_Red"
    },
    {
      "x": 4,
      "y": 4,
      "z": -3,
      "name": "Rock_Sandstone_Red"
    },
    {
      "x": 4,
      "y": 5,
      "z": -3,
      "name": "Rock_Sandstone_Red"
    },
    {
      "x": 4,
      "y": 3,
      "z": -2,
      "name": "Rock_Sandstone_Red"
    },
    {
      "x": 4,
      "y": 4,
      "z": -2,
      "name": "Rock_Sandstone_Red"
    },
    {
      "x": 4,
      "y": 5,
      "z": -2,
      "name": "Rock_Sandstone_Red"
    },
    {
      "x": 4,
      "y": 3,
      "z": -1,
      "name": "Rock_Sandstone_Red"
    },
    {
      "x": 4,
      "y": 4,
      "z": -1,
      "name": "Rock_Sandstone_Red"
    },
    {
      "x": 4,
      "y": 5,
      "z": -1,
      "name": "Rock_Sandstone_Red"
    },
    {
      "x": 4,
      "y": 3,
      "z": 0,
      "name": "Rock_Sandstone_Red"
    },
    {
      "x": 4,
      "y": 4,
      "z": 0,
      "name": "Rock_Sandstone_Red"
    },
    {
      "x": 4,
      "y": 5,
      "z": 0,
      "name": "Rock_Sandstone_Red"
    },
    {
      "x": 4,
      "y": 3,
      "z": 1,
      "name": "Rock_Sandstone_Red"
    },
    {
      "x": 4,
      "y": 4,
      "z": 1,
      "name": "Rock_Sandstone_Red"
    },
    {
      "x": 4,
      "y": 5,
      "z": 1,
      "name": "Rock_Sandstone_Red"
    },
    {
      "x": 4,
      "y": 3,
      "z": 2,
      "name": "Rock_Sandstone_Red"
    },
    {
      "x": 4,
      "y": 4,
      "z": 2,
      "name": "Rock_Sandstone_Red"
    },
    {
      "x": 4,
      "y": 5,
      "z": 2,
      "name": "Rock_Sandstone_Red"
    },
    {
      "x": 4,
      "y": 3,
      "z": 3,
      "name": "Rock_Sandstone_Red"
    },
    {
      "x": 4,
      "y": 4,
      "z": 3,
      "name": "Rock_Sandstone_Red"
    },
    {
      "x": 4,
      "y": 5,
      "z": 3,
      "name": "Rock_Sandstone_Red"
    },
    {
      "x": 4,
      "y": 3,
      "z": 4,
      "name": "Rock_Sandstone_Red"
    },
    {
      "x": 4,
      "y": 4,
      "z": 4,
      "name": "Rock_Sandstone_Red"
    },
    {
      "x": 4,
      "y": 5,
      "z": 4,
      "name": "Rock_Sandstone_Red"
    },
    {
      "x": 4,
      "y": 6,
      "z": 4,
      "name": "Soil_Mud"
    },
    {
      "x": 4,
      "y": 3,
      "z": 5,
      "name": "Rock_Sandstone_Red"
    },
    {
      "x": 4,
      "y": 4,
      "z": 5,
      "name": "Rock_Sandstone_Red"
    },
    {
      "x": 4,
      "y": 5,
      "z": 5,
      "name": "Rock_Sandstone_Red"
    },
    {
      "x": 4,
      "y": 6,
      "z": 5,
      "name": "Rock_Sandstone_Red"
    },
    {
      "x": 4,
      "y": 7,
      "z": 5,
      "name": "Rock_Sandstone_Red"
    },
    {
      "x": 4,
      "y": 8,
      "z": 5,
      "name": "Soil_Mud_Dry"
    },
    {
      "x": 4,
      "y": 3,
      "z": 6,
      "name": "Rock_Sandstone_Red"
    },
    {
      "x": 4,
      "y": 4,
      "z": 6,
      "name": "Rock_Sandstone_Red"
    },
    {
      "x": 4,
      "y": 5,
      "z": 6,
      "name": "Rock_Sandstone_Red"
    },
    {
      "x": 4,
      "y": 6,
      "z": 6,
      "name": "Soil_Clay"
    },
    {
      "x": 4,
      "y": 7,
      "z": 6,
      "name": "Soil_Clay"
    },
    {
      "x": 4,
      "y": 8,
      "z": 6,
      "name": "Soil_Mud_Dry"
    },
    {
      "x": 5,
      "y": 3,
      "z": -8,
      "name": "Rock_Sandstone_Red"
    },
    {
      "x": 5,
      "y": 4,
      "z": -8,
      "name": "Rock_Sandstone_Red"
    },
    {
      "x": 5,
      "y": 5,
      "z": -8,
      "name": "Rock_Sandstone_Red"
    },
    {
      "x": 5,
      "y": 6,
      "z": -8,
      "name": "Rock_Sandstone_Red"
    },
    {
      "x": 5,
      "y": 7,
      "z": -8,
      "name": "Soil_Clay"
    },
    {
      "x": 5,
      "y": 3,
      "z": -7,
      "name": "Rock_Sandstone_Red"
    },
    {
      "x": 5,
      "y": 4,
      "z": -7,
      "name": "Rock_Sandstone_Red"
    },
    {
      "x": 5,
      "y": 5,
      "z": -7,
      "name": "Rock_Sandstone_Red"
    },
    {
      "x": 5,
      "y": 6,
      "z": -7,
      "name": "Rock_Sandstone_Red"
    },
    {
      "x": 5,
      "y": 7,
      "z": -7,
      "name": "Soil_Clay"
    },
    {
      "x": 5,
      "y": 8,
      "z": -7,
      "name": "Soil_Mud_Dry"
    },
    {
      "x": 5,
      "y": 3,
      "z": -6,
      "name": "Rock_Sandstone_Red"
    },
    {
      "x": 5,
      "y": 4,
      "z": -6,
      "name": "Rock_Sandstone_Red"
    },
    {
      "x": 5,
      "y": 5,
      "z": -6,
      "name": "Rock_Sandstone_Red"
    },
    {
      "x": 5,
      "y": 6,
      "z": -6,
      "name": "Rock_Sandstone_Red"
    },
    {
      "x": 5,
      "y": 7,
      "z": -6,
      "name": "Soil_Mud"
    },
    {
      "x": 5,
      "y": 3,
      "z": -5,
      "name": "Rock_Sandstone_Red"
    },
    {
      "x": 5,
      "y": 4,
      "z": -5,
      "name": "Rock_Sandstone_Red"
    },
    {
      "x": 5,
      "y": 5,
      "z": -5,
      "name": "Rock_Sandstone_Red"
    },
    {
      "x": 5,
      "y": 6,
      "z": -5,
      "name": "Rock_Sandstone_Red"
    },
    {
      "x": 5,
      "y": 7,
      "z": -5,
      "name": "Soil_Mud"
    },
    {
      "x": 5,
      "y": 3,
      "z": -4,
      "name": "Rock_Sandstone_Red"
    },
    {
      "x": 5,
      "y": 4,
      "z": -4,
      "name": "Rock_Sandstone_Red"
    },
    {
      "x": 5,
      "y": 5,
      "z": -4,
      "name": "Rock_Sandstone_Red"
    },
    {
      "x": 5,
      "y": 6,
      "z": -4,
      "name": "Soil_Hive"
    },
    {
      "x": 5,
      "y": 7,
      "z": -4,
      "name": "Soil_Mud"
    },
    {
      "x": 5,
      "y": 3,
      "z": -3,
      "name": "Rock_Sandstone_Red"
    },
    {
      "x": 5,
      "y": 4,
      "z": -3,
      "name": "Rock_Sandstone_Red"
    },
    {
      "x": 5,
      "y": 5,
      "z": -3,
      "name": "Rock_Sandstone_Red"
    },
    {
      "x": 5,
      "y": 6,
      "z": -3,
      "name": "Soil_Mud"
    },
    {
      "x": 5,
      "y": 3,
      "z": -2,
      "name": "Rock_Sandstone_Red"
    },
    {
      "x": 5,
      "y": 4,
      "z": -2,
      "name": "Rock_Sandstone_Red"
    },
    {
      "x": 5,
      "y": 5,
      "z": -2,
      "name": "Rock_Sandstone_Red"
    },
    {
      "x": 5,
      "y": 6,
      "z": -2,
      "name": "Soil_Mud"
    },
    {
      "x": 5,
      "y": 3,
      "z": -1,
      "name": "Rock_Sandstone_Red"
    },
    {
      "x": 5,
      "y": 4,
      "z": -1,
      "name": "Rock_Sandstone_Red"
    },
    {
      "x": 5,
      "y": 5,
      "z": -1,
      "name": "Rock_Sandstone_Red"
    },
    {
      "x": 5,
      "y": 3,
      "z": 0,
      "name": "Rock_Sandstone_Red"
    },
    {
      "x": 5,
      "y": 4,
      "z": 0,
      "name": "Rock_Sandstone_Red"
    },
    {
      "x": 5,
      "y": 5,
      "z": 0,
      "name": "Rock_Sandstone_Red"
    },
    {
      "x": 5,
      "y": 3,
      "z": 1,
      "name": "Rock_Sandstone_Red"
    },
    {
      "x": 5,
      "y": 4,
      "z": 1,
      "name": "Rock_Sandstone_Red"
    },
    {
      "x": 5,
      "y": 5,
      "z": 1,
      "name": "Rock_Sandstone_Red"
    },
    {
      "x": 5,
      "y": 3,
      "z": 2,
      "name": "Rock_Sandstone_Red"
    },
    {
      "x": 5,
      "y": 4,
      "z": 2,
      "name": "Rock_Sandstone_Red"
    },
    {
      "x": 5,
      "y": 5,
      "z": 2,
      "name": "Rock_Sandstone_Red"
    },
    {
      "x": 5,
      "y": 3,
      "z": 3,
      "name": "Rock_Sandstone_Red"
    },
    {
      "x": 5,
      "y": 4,
      "z": 3,
      "name": "Rock_Sandstone_Red"
    },
    {
      "x": 5,
      "y": 5,
      "z": 3,
      "name": "Rock_Sandstone_Red"
    },
    {
      "x": 5,
      "y": 6,
      "z": 3,
      "name": "Soil_Mud"
    },
    {
      "x": 5,
      "y": 3,
      "z": 4,
      "name": "Rock_Sandstone_Red"
    },
    {
      "x": 5,
      "y": 4,
      "z": 4,
      "name": "Rock_Sandstone_Red"
    },
    {
      "x": 5,
      "y": 5,
      "z": 4,
      "name": "Rock_Sandstone_Red"
    },
    {
      "x": 5,
      "y": 6,
      "z": 4,
      "name": "Soil_Mud"
    },
    {
      "x": 5,
      "y": 3,
      "z": 5,
      "name": "Rock_Sandstone_Red"
    },
    {
      "x": 5,
      "y": 4,
      "z": 5,
      "name": "Rock_Sandstone_Red"
    },
    {
      "x": 5,
      "y": 5,
      "z": 5,
      "name": "Rock_Sandstone_Red"
    },
    {
      "x": 5,
      "y": 6,
      "z": 5,
      "name": "Soil_Clay"
    },
    {
      "x": 5,
      "y": 7,
      "z": 5,
      "name": "Rock_Sandstone_Red"
    },
    {
      "x": 5,
      "y": 3,
      "z": 6,
      "name": "Rock_Sandstone_Red"
    },
    {
      "x": 5,
      "y": 4,
      "z": 6,
      "name": "Rock_Sandstone_Red"
    },
    {
      "x": 5,
      "y": 5,
      "z": 6,
      "name": "Rock_Sandstone_Red"
    },
    {
      "x": 5,
      "y": 6,
      "z": 6,
      "name": "Soil_Clay"
    },
    {
      "x": 6,
      "y": 3,
      "z": -8,
      "name": "Rock_Sandstone_Red"
    },
    {
      "x": 6,
      "y": 4,
      "z": -8,
      "name": "Rock_Sandstone_Red"
    },
    {
      "x": 6,
      "y": 5,
      "z": -8,
      "name": "Rock_Sandstone_Red"
    },
    {
      "x": 6,
      "y": 3,
      "z": -7,
      "name": "Rock_Sandstone_Red"
    },
    {
      "x": 6,
      "y": 4,
      "z": -7,
      "name": "Rock_Sandstone_Red"
    },
    {
      "x": 6,
      "y": 5,
      "z": -7,
      "name": "Rock_Sandstone_Red"
    },
    {
      "x": 6,
      "y": 6,
      "z": -7,
      "name": "Rock_Sandstone_Red"
    },
    {
      "x": 6,
      "y": 7,
      "z": -7,
      "name": "Soil_Clay"
    },
    {
      "x": 6,
      "y": 8,
      "z": -7,
      "name": "Soil_Mud_Dry"
    },
    {
      "x": 6,
      "y": 3,
      "z": -6,
      "name": "Rock_Sandstone_Red"
    },
    {
      "x": 6,
      "y": 4,
      "z": -6,
      "name": "Rock_Sandstone_Red"
    },
    {
      "x": 6,
      "y": 5,
      "z": -6,
      "name": "Rock_Sandstone_Red"
    },
    {
      "x": 6,
      "y": 6,
      "z": -6,
      "name": "Rock_Sandstone_Red"
    },
    {
      "x": 6,
      "y": 7,
      "z": -6,
      "name": "Soil_Clay"
    },
    {
      "x": 6,
      "y": 8,
      "z": -6,
      "name": "Soil_Mud_Dry"
    },
    {
      "x": 6,
      "y": 9,
      "z": -6,
      "name": "Plant_Flower_Common_Poisoned"
    },
    {
      "x": 6,
      "y": 3,
      "z": -5,
      "name": "Rock_Sandstone_Red"
    },
    {
      "x": 6,
      "y": 4,
      "z": -5,
      "name": "Rock_Sandstone_Red"
    },
    {
      "x": 6,
      "y": 5,
      "z": -5,
      "name": "Rock_Sandstone_Red"
    },
    {
      "x": 6,
      "y": 6,
      "z": -5,
      "name": "Rock_Sandstone_Red"
    },
    {
      "x": 6,
      "y": 7,
      "z": -5,
      "name": "Soil_Clay"
    },
    {
      "x": 6,
      "y": 8,
      "z": -5,
      "name": "Soil_Hive"
    },
    {
      "x": 6,
      "y": 3,
      "z": -4,
      "name": "Rock_Sandstone_Red"
    },
    {
      "x": 6,
      "y": 4,
      "z": -4,
      "name": "Rock_Sandstone_Red"
    },
    {
      "x": 6,
      "y": 5,
      "z": -4,
      "name": "Rock_Sandstone_Red"
    },
    {
      "x": 6,
      "y": 6,
      "z": -4,
      "name": "Rock_Sandstone_Red"
    },
    {
      "x": 6,
      "y": 7,
      "z": -4,
      "name": "Soil_Mud"
    },
    {
      "x": 6,
      "y": 3,
      "z": -3,
      "name": "Rock_Sandstone_Red"
    },
    {
      "x": 6,
      "y": 4,
      "z": -3,
      "name": "Rock_Sandstone_Red"
    },
    {
      "x": 6,
      "y": 5,
      "z": -3,
      "name": "Rock_Sandstone_Red"
    },
    {
      "x": 6,
      "y": 6,
      "z": -3,
      "name": "Soil_Mud"
    },
    {
      "x": 6,
      "y": 3,
      "z": -2,
      "name": "Rock_Sandstone_Red"
    },
    {
      "x": 6,
      "y": 4,
      "z": -2,
      "name": "Rock_Sandstone_Red"
    },
    {
      "x": 6,
      "y": 5,
      "z": -2,
      "name": "Rock_Sandstone_Red"
    },
    {
      "x": 6,
      "y": 6,
      "z": -2,
      "name": "Soil_Mud"
    },
    {
      "x": 6,
      "y": 3,
      "z": -1,
      "name": "Rock_Sandstone_Red"
    },
    {
      "x": 6,
      "y": 4,
      "z": -1,
      "name": "Rock_Sandstone_Red"
    },
    {
      "x": 6,
      "y": 5,
      "z": -1,
      "name": "Rock_Sandstone_Red"
    },
    {
      "x": 6,
      "y": 3,
      "z": 0,
      "name": "Rock_Sandstone_Red"
    },
    {
      "x": 6,
      "y": 4,
      "z": 0,
      "name": "Rock_Sandstone_Red"
    },
    {
      "x": 6,
      "y": 5,
      "z": 0,
      "name": "Rock_Sandstone_Red"
    },
    {
      "x": 6,
      "y": 3,
      "z": 1,
      "name": "Rock_Sandstone_Red"
    },
    {
      "x": 6,
      "y": 4,
      "z": 1,
      "name": "Rock_Sandstone_Red"
    },
    {
      "x": 6,
      "y": 5,
      "z": 1,
      "name": "Rock_Sandstone_Red"
    },
    {
      "x": 6,
      "y": 3,
      "z": 2,
      "name": "Rock_Sandstone_Red"
    },
    {
      "x": 6,
      "y": 4,
      "z": 2,
      "name": "Rock_Sandstone_Red"
    },
    {
      "x": 6,
      "y": 5,
      "z": 2,
      "name": "Rock_Sandstone_Red"
    },
    {
      "x": 6,
      "y": 6,
      "z": 2,
      "name": "Soil_Mud"
    },
    {
      "x": 6,
      "y": 3,
      "z": 3,
      "name": "Rock_Sandstone_Red"
    },
    {
      "x": 6,
      "y": 4,
      "z": 3,
      "name": "Rock_Sandstone_Red"
    },
    {
      "x": 6,
      "y": 5,
      "z": 3,
      "name": "Rock_Sandstone_Red"
    },
    {
      "x": 6,
      "y": 6,
      "z": 3,
      "name": "Soil_Mud"
    },
    {
      "x": 6,
      "y": 3,
      "z": 4,
      "name": "Rock_Sandstone_Red"
    },
    {
      "x": 6,
      "y": 4,
      "z": 4,
      "name": "Rock_Sandstone_Red"
    },
    {
      "x": 6,
      "y": 5,
      "z": 4,
      "name": "Rock_Sandstone_Red"
    },
    {
      "x": 6,
      "y": 6,
      "z": 4,
      "name": "Soil_Clay"
    },
    {
      "x": 6,
      "y": 7,
      "z": 4,
      "name": "Soil_Mud_Dry"
    },
    {
      "x": 6,
      "y": 8,
      "z": 4,
      "name": "Plant_Flower_Common_Poisoned"
    },
    {
      "x": 6,
      "y": 3,
      "z": 5,
      "name": "Rock_Sandstone_Red"
    },
    {
      "x": 6,
      "y": 4,
      "z": 5,
      "name": "Rock_Sandstone_Red"
    },
    {
      "x": 6,
      "y": 5,
      "z": 5,
      "name": "Rock_Sandstone_Red"
    },
    {
      "x": 6,
      "y": 6,
      "z": 5,
      "name": "Soil_Clay"
    },
    {
      "x": 6,
      "y": 7,
      "z": 5,
      "name": "Rock_Sandstone_Red"
    },
    {
      "x": 7,
      "y": 3,
      "z": -7,
      "name": "Soil_Hive"
    },
    {
      "x": 7,
      "y": 4,
      "z": -7,
      "name": "Soil_Hive"
    },
    {
      "x": 7,
      "y": 3,
      "z": -6,
      "name": "Rock_Sandstone_Red"
    },
    {
      "x": 7,
      "y": 4,
      "z": -6,
      "name": "Rock_Sandstone_Red"
    },
    {
      "x": 7,
      "y": 5,
      "z": -6,
      "name": "Rock_Sandstone_Red"
    },
    {
      "x": 7,
      "y": 6,
      "z": -6,
      "name": "Rock_Sandstone_Red"
    },
    {
      "x": 7,
      "y": 7,
      "z": -6,
      "name": "Soil_Clay"
    },
    {
      "x": 7,
      "y": 8,
      "z": -6,
      "name": "Soil_Hive"
    },
    {
      "x": 7,
      "y": 3,
      "z": -5,
      "name": "Rock_Sandstone_Red"
    },
    {
      "x": 7,
      "y": 4,
      "z": -5,
      "name": "Rock_Sandstone_Red"
    },
    {
      "x": 7,
      "y": 5,
      "z": -5,
      "name": "Rock_Sandstone_Red"
    },
    {
      "x": 7,
      "y": 6,
      "z": -5,
      "name": "Rock_Sandstone_Red"
    },
    {
      "x": 7,
      "y": 7,
      "z": -5,
      "name": "Soil_Clay"
    },
    {
      "x": 7,
      "y": 8,
      "z": -5,
      "name": "Soil_Hive"
    },
    {
      "x": 7,
      "y": 3,
      "z": -4,
      "name": "Rock_Sandstone_Red"
    },
    {
      "x": 7,
      "y": 4,
      "z": -4,
      "name": "Rock_Sandstone_Red"
    },
    {
      "x": 7,
      "y": 5,
      "z": -4,
      "name": "Rock_Sandstone_Red"
    },
    {
      "x": 7,
      "y": 6,
      "z": -4,
      "name": "Rock_Sandstone_Red"
    },
    {
      "x": 7,
      "y": 7,
      "z": -4,
      "name": "Soil_Clay"
    },
    {
      "x": 7,
      "y": 8,
      "z": -4,
      "name": "Soil_Hive"
    },
    {
      "x": 7,
      "y": 3,
      "z": -3,
      "name": "Rock_Sandstone_Red"
    },
    {
      "x": 7,
      "y": 4,
      "z": -3,
      "name": "Rock_Sandstone_Red"
    },
    {
      "x": 7,
      "y": 5,
      "z": -3,
      "name": "Rock_Sandstone_Red"
    },
    {
      "x": 7,
      "y": 6,
      "z": -3,
      "name": "Rock_Sandstone_Red"
    },
    {
      "x": 7,
      "y": 7,
      "z": -3,
      "name": "Soil_Clay"
    },
    {
      "x": 7,
      "y": 8,
      "z": -3,
      "name": "Soil_Hive"
    },
    {
      "x": 7,
      "y": 3,
      "z": -2,
      "name": "Rock_Sandstone_Red"
    },
    {
      "x": 7,
      "y": 4,
      "z": -2,
      "name": "Rock_Sandstone_Red"
    },
    {
      "x": 7,
      "y": 5,
      "z": -2,
      "name": "Rock_Sandstone_Red"
    },
    {
      "x": 7,
      "y": 6,
      "z": -2,
      "name": "Soil_Mud"
    },
    {
      "x": 7,
      "y": 3,
      "z": -1,
      "name": "Rock_Sandstone_Red"
    },
    {
      "x": 7,
      "y": 4,
      "z": -1,
      "name": "Rock_Sandstone_Red"
    },
    {
      "x": 7,
      "y": 5,
      "z": -1,
      "name": "Rock_Sandstone_Red"
    },
    {
      "x": 7,
      "y": 6,
      "z": -1,
      "name": "Soil_Mud"
    },
    {
      "x": 7,
      "y": 3,
      "z": 0,
      "name": "Rock_Sandstone_Red"
    },
    {
      "x": 7,
      "y": 4,
      "z": 0,
      "name": "Rock_Sandstone_Red"
    },
    {
      "x": 7,
      "y": 5,
      "z": 0,
      "name": "Rock_Sandstone_Red"
    },
    {
      "x": 7,
      "y": 6,
      "z": 0,
      "name": "Soil_Mud"
    },
    {
      "x": 7,
      "y": 3,
      "z": 1,
      "name": "Rock_Sandstone_Red"
    },
    {
      "x": 7,
      "y": 4,
      "z": 1,
      "name": "Rock_Sandstone_Red"
    },
    {
      "x": 7,
      "y": 5,
      "z": 1,
      "name": "Rock_Sandstone_Red"
    },
    {
      "x": 7,
      "y": 6,
      "z": 1,
      "name": "Soil_Clay"
    },
    {
      "x": 7,
      "y": 7,
      "z": 1,
      "name": "Soil_Mud"
    },
    {
      "x": 7,
      "y": 3,
      "z": 2,
      "name": "Rock_Sandstone_Red"
    },
    {
      "x": 7,
      "y": 4,
      "z": 2,
      "name": "Rock_Sandstone_Red"
    },
    {
      "x": 7,
      "y": 5,
      "z": 2,
      "name": "Rock_Sandstone_Red"
    },
    {
      "x": 7,
      "y": 6,
      "z": 2,
      "name": "Rock_Sandstone_Red"
    },
    {
      "x": 7,
      "y": 7,
      "z": 2,
      "name": "Soil_Mud_Dry"
    },
    {
      "x": 7,
      "y": 8,
      "z": 2,
      "name": "Plant_Flower_Common_Poisoned"
    },
    {
      "x": 7,
      "y": 3,
      "z": 3,
      "name": "Rock_Sandstone_Red"
    },
    {
      "x": 7,
      "y": 4,
      "z": 3,
      "name": "Rock_Sandstone_Red"
    },
    {
      "x": 7,
      "y": 5,
      "z": 3,
      "name": "Rock_Sandstone_Red"
    },
    {
      "x": 7,
      "y": 6,
      "z": 3,
      "name": "Soil_Clay"
    },
    {
      "x": 7,
      "y": 7,
      "z": 3,
      "name": "Soil_Mud_Dry"
    },
    {
      "x": 7,
      "y": 3,
      "z": 4,
      "name": "Rock_Sandstone_Red"
    },
    {
      "x": 7,
      "y": 4,
      "z": 4,
      "name": "Rock_Sandstone_Red"
    },
    {
      "x": 7,
      "y": 5,
      "z": 4,
      "name": "Rock_Sandstone_Red"
    },
    {
      "x": 7,
      "y": 6,
      "z": 4,
      "name": "Soil_Clay"
    },
    {
      "x": 7,
      "y": 7,
      "z": 4,
      "name": "Soil_Mud_Dry"
    },
    {
      "x": 7,
      "y": 3,
      "z": 5,
      "name": "Rock_Sandstone_Red"
    },
    {
      "x": 7,
      "y": 4,
      "z": 5,
      "name": "Rock_Sandstone_Red"
    },
    {
      "x": 7,
      "y": 5,
      "z": 5,
      "name": "Rock_Sandstone_Red"
    },
    {
      "x": 8,
      "y": 3,
      "z": -7,
      "name": "Soil_Hive"
    },
    {
      "x": 8,
      "y": 3,
      "z": -6,
      "name": "Soil_Hive"
    },
    {
      "x": 8,
      "y": 4,
      "z": -6,
      "name": "Soil_Hive"
    },
    {
      "x": 8,
      "y": 5,
      "z": -6,
      "name": "Soil_Hive"
    },
    {
      "x": 8,
      "y": 6,
      "z": -6,
      "name": "Soil_Hive"
    },
    {
      "x": 8,
      "y": 3,
      "z": -5,
      "name": "Soil_Hive"
    },
    {
      "x": 8,
      "y": 4,
      "z": -5,
      "name": "Soil_Hive"
    },
    {
      "x": 8,
      "y": 5,
      "z": -5,
      "name": "Soil_Hive"
    },
    {
      "x": 8,
      "y": 6,
      "z": -5,
      "name": "Soil_Hive"
    },
    {
      "x": 8,
      "y": 7,
      "z": -5,
      "name": "Soil_Hive"
    },
    {
      "x": 8,
      "y": 3,
      "z": -4,
      "name": "Rock_Sandstone_Red"
    },
    {
      "x": 8,
      "y": 4,
      "z": -4,
      "name": "Rock_Sandstone_Red"
    },
    {
      "x": 8,
      "y": 5,
      "z": -4,
      "name": "Rock_Sandstone_Red"
    },
    {
      "x": 8,
      "y": 6,
      "z": -4,
      "name": "Rock_Sandstone_Red"
    },
    {
      "x": 8,
      "y": 7,
      "z": -4,
      "name": "Soil_Hive"
    },
    {
      "x": 8,
      "y": 3,
      "z": -3,
      "name": "Rock_Sandstone_Red"
    },
    {
      "x": 8,
      "y": 4,
      "z": -3,
      "name": "Rock_Sandstone_Red"
    },
    {
      "x": 8,
      "y": 5,
      "z": -3,
      "name": "Rock_Sandstone_Red"
    },
    {
      "x": 8,
      "y": 6,
      "z": -3,
      "name": "Rock_Sandstone_Red"
    },
    {
      "x": 8,
      "y": 7,
      "z": -3,
      "name": "Soil_Clay"
    },
    {
      "x": 8,
      "y": 8,
      "z": -3,
      "name": "Soil_Hive"
    },
    {
      "x": 8,
      "y": 3,
      "z": -2,
      "name": "Rock_Sandstone_Red"
    },
    {
      "x": 8,
      "y": 4,
      "z": -2,
      "name": "Rock_Sandstone_Red"
    },
    {
      "x": 8,
      "y": 5,
      "z": -2,
      "name": "Rock_Sandstone_Red"
    },
    {
      "x": 8,
      "y": 6,
      "z": -2,
      "name": "Rock_Sandstone_Red"
    },
    {
      "x": 8,
      "y": 7,
      "z": -2,
      "name": "Soil_Clay"
    },
    {
      "x": 8,
      "y": 8,
      "z": -2,
      "name": "Soil_Hive"
    },
    {
      "x": 8,
      "y": 3,
      "z": -1,
      "name": "Rock_Sandstone_Red"
    },
    {
      "x": 8,
      "y": 4,
      "z": -1,
      "name": "Rock_Sandstone_Red"
    },
    {
      "x": 8,
      "y": 5,
      "z": -1,
      "name": "Rock_Sandstone_Red"
    },
    {
      "x": 8,
      "y": 6,
      "z": -1,
      "name": "Soil_Clay"
    },
    {
      "x": 8,
      "y": 7,
      "z": -1,
      "name": "Soil_Clay"
    },
    {
      "x": 8,
      "y": 8,
      "z": -1,
      "name": "Soil_Mud_Dry"
    },
    {
      "x": 8,
      "y": 3,
      "z": 0,
      "name": "Rock_Sandstone_Red"
    },
    {
      "x": 8,
      "y": 4,
      "z": 0,
      "name": "Rock_Sandstone_Red"
    },
    {
      "x": 8,
      "y": 5,
      "z": 0,
      "name": "Rock_Sandstone_Red"
    },
    {
      "x": 8,
      "y": 6,
      "z": 0,
      "name": "Soil_Clay"
    },
    {
      "x": 8,
      "y": 7,
      "z": 0,
      "name": "Soil_Clay"
    },
    {
      "x": 8,
      "y": 8,
      "z": 0,
      "name": "Soil_Mud_Dry"
    },
    {
      "x": 8,
      "y": 3,
      "z": 1,
      "name": "Rock_Sandstone_Red"
    },
    {
      "x": 8,
      "y": 4,
      "z": 1,
      "name": "Rock_Sandstone_Red"
    },
    {
      "x": 8,
      "y": 5,
      "z": 1,
      "name": "Rock_Sandstone_Red"
    },
    {
      "x": 8,
      "y": 6,
      "z": 1,
      "name": "Soil_Clay"
    },
    {
      "x": 8,
      "y": 7,
      "z": 1,
      "name": "Rock_Sandstone_Red"
    },
    {
      "x": 8,
      "y": 8,
      "z": 1,
      "name": "Soil_Mud_Dry"
    },
    {
      "x": 8,
      "y": 3,
      "z": 2,
      "name": "Rock_Sandstone_Red"
    },
    {
      "x": 8,
      "y": 4,
      "z": 2,
      "name": "Rock_Sandstone_Red"
    },
    {
      "x": 8,
      "y": 5,
      "z": 2,
      "name": "Rock_Sandstone_Red"
    },
    {
      "x": 8,
      "y": 6,
      "z": 2,
      "name": "Soil_Clay"
    },
    {
      "x": 8,
      "y": 7,
      "z": 2,
      "name": "Soil_Mud_Dry"
    },
    {
      "x": 8,
      "y": 3,
      "z": 3,
      "name": "Rock_Sandstone_Red"
    },
    {
      "x": 8,
      "y": 4,
      "z": 3,
      "name": "Rock_Sandstone_Red"
    },
    {
      "x": 8,
      "y": 5,
      "z": 3,
      "name": "Rock_Sandstone_Red"
    },
    {
      "x": 8,
      "y": 6,
      "z": 3,
      "name": "Soil_Clay"
    },
    {
      "x": 8,
      "y": 7,
      "z": 3,
      "name": "Soil_Mud_Dry"
    },
    {
      "x": 8,
      "y": 8,
      "z": 3,
      "name": "Plant_Flower_Common_Poisoned"
    },
    {
      "x": 9,
      "y": 3,
      "z": -5,
      "name": "Soil_Hive"
    },
    {
      "x": 9,
      "y": 4,
      "z": -5,
      "name": "Soil_Hive"
    },
    {
      "x": 9,
      "y": 5,
      "z": -5,
      "name": "Soil_Hive"
    },
    {
      "x": 9,
      "y": 6,
      "z": -5,
      "name": "Soil_Hive"
    },
    {
      "x": 9,
      "y": 3,
      "z": -4,
      "name": "Soil_Hive"
    },
    {
      "x": 9,
      "y": 4,
      "z": -4,
      "name": "Soil_Hive"
    },
    {
      "x": 9,
      "y": 5,
      "z": -4,
      "name": "Soil_Hive"
    },
    {
      "x": 9,
      "y": 6,
      "z": -4,
      "name": "Soil_Hive"
    },
    {
      "x": 9,
      "y": 6,
      "z": -3,
      "name": "Soil_Hive"
    },
    {
      "x": 9,
      "y": 7,
      "z": -3,
      "name": "Soil_Hive"
    },
    {
      "x": 9,
      "y": 3,
      "z": -1,
      "name": "Rock_Sandstone_Red"
    },
    {
      "x": 9,
      "y": 3,
      "z": 0,
      "name": "Rock_Sandstone_Red"
    },
    {
      "x": 9,
      "y": 4,
      "z": 0,
      "name": "Rock_Sandstone_Red"
    },
    {
      "x": 9,
      "y": 5,
      "z": 0,
      "name": "Rock_Sandstone_Red"
    },
    {
      "x": 9,
      "y": 3,
      "z": 1,
      "name": "Rock_Sandstone_Red"
    },
    {
      "x": 9,
      "y": 4,
      "z": 1,
      "name": "Rock_Sandstone_Red"
    },
    {
