{
  "version": 8,
  "blockIdVersion": 9,
  "anchorX": 0,
  "anchorY": 10,
  "anchorZ": 15,
  "blocks": [
    {
      "x": -22,
      "y": 10,
      "z": -5,
      "name": "Rock_Stone"
    },
    {
      "x": -22,
      "y": 11,
      "z": -5,
      "name": "Rock_Stone"
    },
    {
      "x": -22,
      "y": 12,
      "z": -5,
      "name": "Rock_Stone"
    },
    {
      "x": -22,
      "y": 13,
      "z": -5,
      "name": "Rock_Stone"
    },
    {
      "x": -22,
      "y": 10,
      "z": -4,
      "name": "Rock_Stone"
    },
    {
      "x": -22,
      "y": 11,
      "z": -4,
      "name": "Rock_Stone"
    },
    {
      "x": -22,
      "y": 12,
      "z": -4,
      "name": "Rock_Stone"
    },
    {
      "x": -22,
      "y": 13,
      "z": -4,
      "name": "Rock_Stone"
    },
    {
      "x": -22,
      "y": 14,
      "z": -4,
      "name": "Rock_Stone"
    },
    {
      "x": -22,
      "y": 10,
      "z": -3,
      "name": "Rock_Stone"
    },
    {
      "x": -22,
      "y": 11,
      "z": -3,
      "name": "Rock_Stone"
    },
    {
      "x": -22,
      "y": 12,
      "z": -3,
      "name": "Rock_Stone"
    },
    {
      "x": -22,
      "y": 13,
      "z": -3,
      "name": "Rock_Stone"
    },
    {
      "x": -22,
      "y": 14,
      "z": -3,
      "name": "Rock_Stone"
    },
    {
      "x": -22,
      "y": 15,
      "z": -3,
      "name": "Rock_Stone"
    },
    {
      "x": -22,
      "y": 10,
      "z": -2,
      "name": "Rock_Stone"
    },
    {
      "x": -22,
      "y": 11,
      "z": -2,
      "name": "Rock_Stone"
    },
    {
      "x": -22,
      "y": 12,
      "z": -2,
      "name": "Rock_Stone"
    },
    {
      "x": -22,
      "y": 13,
      "z": -2,
      "name": "Rock_Stone"
    },
    {
      "x": -22,
      "y": 14,
      "z": -2,
      "name": "Rock_Stone"
    },
    {
      "x": -22,
      "y": 15,
      "z": -2,
      "name": "Rock_Stone"
    },
    {
      "x": -22,
      "y": 11,
      "z": -1,
      "name": "Rock_Stone"
    },
    {
      "x": -22,
      "y": 12,
      "z": -1,
      "name": "Rock_Stone"
    },
    {
      "x": -22,
      "y": 13,
      "z": -1,
      "name": "Rock_Stone"
    },
    {
      "x": -22,
      "y": 14,
      "z": -1,
      "name": "Rock_Stone"
    },
    {
      "x": -22,
      "y": 15,
      "z": -1,
      "name": "Rock_Stone"
    },
    {
      "x": -22,
      "y": 11,
      "z": 0,
      "name": "Rock_Stone"
    },
    {
      "x": -22,
      "y": 12,
      "z": 0,
      "name": "Rock_Stone"
    },
    {
      "x": -22,
      "y": 13,
      "z": 0,
      "name": "Rock_Stone"
    },
    {
      "x": -22,
      "y": 14,
      "z": 0,
      "name": "Rock_Stone"
    },
    {
      "x": -22,
      "y": 15,
      "z": 0,
      "name": "Rock_Stone"
    },
    {
      "x": -22,
      "y": 11,
      "z": 1,
      "name": "Rock_Stone"
    },
    {
      "x": -22,
      "y": 12,
      "z": 1,
      "name": "Rock_Stone"
    },
    {
      "x": -22,
      "y": 13,
      "z": 1,
      "name": "Rock_Stone"
    },
    {
      "x": -22,
      "y": 14,
      "z": 1,
      "name": "Rock_Stone"
    },
    {
      "x": -21,
      "y": 9,
      "z": -6,
      "name": "Rock_Stone"
    },
    {
      "x": -21,
      "y": 10,
      "z": -6,
      "name": "Rock_Stone"
    },
    {
      "x": -21,
      "y": 11,
      "z": -6,
      "name": "Rock_Stone"
    },
    {
      "x": -21,
      "y": 12,
      "z": -6,
      "name": "Rock_Stone"
    },
    {
      "x": -21,
      "y": 13,
      "z": -6,
      "name": "Rock_Stone"
    },
    {
      "x": -21,
      "y": 14,
      "z": -6,
      "name": "Rock_Stone"
    },
    {
      "x": -21,
      "y": 9,
      "z": -5,
      "name": "Rock_Stone"
    },
    {
      "x": -21,
      "y": 10,
      "z": -5,
      "name": "Rock_Stone"
    },
    {
      "x": -21,
      "y": 11,
      "z": -5,
      "name": "Rock_Stone"
    },
    {
      "x": -21,
      "y": 12,
      "z": -5,
      "name": "Rock_Stone"
    },
    {
      "x": -21,
      "y": 13,
      "z": -5,
      "name": "Rock_Stone"
    },
    {
      "x": -21,
      "y": 14,
      "z": -5,
      "name": "Rock_Stone"
    },
    {
      "x": -21,
      "y": 15,
      "z": -5,
      "name": "Rock_Stone"
    },
    {
      "x": -21,
      "y": 16,
      "z": -5,
      "name": "Rock_Stone"
    },
    {
      "x": -21,
      "y": 9,
      "z": -4,
      "name": "Rock_Stone"
    },
    {
      "x": -21,
      "y": 10,
      "z": -4,
      "name": "Rock_Stone"
    },
    {
      "x": -21,
      "y": 11,
      "z": -4,
      "name": "Rock_Stone"
    },
    {
      "x": -21,
      "y": 12,
      "z": -4,
      "name": "Rock_Stone"
    },
    {
      "x": -21,
      "y": 13,
      "z": -4,
      "name": "Rock_Stone"
    },
    {
      "x": -21,
      "y": 14,
      "z": -4,
      "name": "Rock_Stone"
    },
    {
      "x": -21,
      "y": 15,
      "z": -4,
      "name": "Rock_Stone"
    },
    {
      "x": -21,
      "y": 16,
      "z": -4,
      "name": "Rock_Stone"
    },
    {
      "x": -21,
      "y": 9,
      "z": -3,
      "name": "Rock_Stone"
    },
    {
      "x": -21,
      "y": 10,
      "z": -3,
      "name": "Rock_Stone"
    },
    {
      "x": -21,
      "y": 11,
      "z": -3,
      "name": "Rock_Stone"
    },
    {
      "x": -21,
      "y": 12,
      "z": -3,
      "name": "Rock_Stone"
    },
    {
      "x": -21,
      "y": 13,
      "z": -3,
      "name": "Rock_Stone"
    },
    {
      "x": -21,
      "y": 14,
      "z": -3,
      "name": "Rock_Stone"
    },
    {
      "x": -21,
      "y": 15,
      "z": -3,
      "name": "Rock_Stone"
    },
    {
      "x": -21,
      "y": 16,
      "z": -3,
      "name": "Rock_Stone"
    },
    {
      "x": -21,
      "y": 17,
      "z": -3,
      "name": "Rock_Stone"
    },
    {
      "x": -21,
      "y": 9,
      "z": -2,
      "name": "Rock_Stone"
    },
    {
      "x": -21,
      "y": 10,
      "z": -2,
      "name": "Rock_Stone"
    },
    {
      "x": -21,
      "y": 11,
      "z": -2,
      "name": "Rock_Stone"
    },
    {
      "x": -21,
      "y": 12,
      "z": -2,
      "name": "Rock_Stone"
    },
    {
      "x": -21,
      "y": 13,
      "z": -2,
      "name": "Rock_Stone"
    },
    {
      "x": -21,
      "y": 14,
      "z": -2,
      "name": "Rock_Stone"
    },
    {
      "x": -21,
      "y": 15,
      "z": -2,
      "name": "Rock_Stone"
    },
    {
      "x": -21,
      "y": 16,
      "z": -2,
      "name": "Rock_Stone"
    },
    {
      "x": -21,
      "y": 17,
      "z": -2,
      "name": "Rock_Stone"
    },
    {
      "x": -21,
      "y": 9,
      "z": -1,
      "name": "Rock_Stone"
    },
    {
      "x": -21,
      "y": 10,
      "z": -1,
      "name": "Rock_Stone"
    },
    {
      "x": -21,
      "y": 11,
      "z": -1,
      "name": "Rock_Stone"
    },
    {
      "x": -21,
      "y": 12,
      "z": -1,
      "name": "Rock_Stone"
    },
    {
      "x": -21,
      "y": 13,
      "z": -1,
      "name": "Rock_Stone"
    },
    {
      "x": -21,
      "y": 14,
      "z": -1,
      "name": "Rock_Stone"
    },
    {
      "x": -21,
      "y": 15,
      "z": -1,
      "name": "Rock_Stone"
    },
    {
      "x": -21,
      "y": 16,
      "z": -1,
      "name": "Rock_Stone"
    },
    {
      "x": -21,
      "y": 17,
      "z": -1,
      "name": "Rock_Stone"
    },
    {
      "x": -21,
      "y": 9,
      "z": 0,
      "name": "Rock_Stone"
    },
    {
      "x": -21,
      "y": 10,
      "z": 0,
      "name": "Rock_Stone"
    },
    {
      "x": -21,
      "y": 11,
      "z": 0,
      "name": "Rock_Stone"
    },
    {
      "x": -21,
      "y": 12,
      "z": 0,
      "name": "Rock_Stone"
    },
    {
      "x": -21,
      "y": 13,
      "z": 0,
      "name": "Rock_Stone"
    },
    {
      "x": -21,
      "y": 14,
      "z": 0,
      "name": "Rock_Stone"
    },
    {
      "x": -21,
      "y": 15,
      "z": 0,
      "name": "Rock_Stone"
    },
    {
      "x": -21,
      "y": 16,
      "z": 0,
      "name": "Rock_Stone"
    },
    {
      "x": -21,
      "y": 17,
      "z": 0,
      "name": "Rock_Stone"
    },
    {
      "x": -21,
      "y": 10,
      "z": 1,
      "name": "Rock_Stone"
    },
    {
      "x": -21,
      "y": 11,
      "z": 1,
      "name": "Rock_Stone"
    },
    {
      "x": -21,
      "y": 12,
      "z": 1,
      "name": "Rock_Stone"
    },
    {
      "x": -21,
      "y": 13,
      "z": 1,
      "name": "Rock_Stone"
    },
    {
      "x": -21,
      "y": 14,
      "z": 1,
      "name": "Rock_Stone"
    },
    {
      "x": -21,
      "y": 15,
      "z": 1,
      "name": "Rock_Stone"
    },
    {
      "x": -21,
      "y": 16,
      "z": 1,
      "name": "Rock_Stone"
    },
    {
      "x": -21,
      "y": 17,
      "z": 1,
      "name": "Rock_Stone"
    },
    {
      "x": -21,
      "y": 11,
      "z": 2,
      "name": "Rock_Stone"
    },
    {
      "x": -21,
      "y": 12,
      "z": 2,
      "name": "Rock_Stone"
    },
    {
      "x": -21,
      "y": 13,
      "z": 2,
      "name": "Rock_Stone"
    },
    {
      "x": -21,
      "y": 14,
      "z": 2,
      "name": "Rock_Stone"
    },
    {
      "x": -21,
      "y": 15,
      "z": 2,
      "name": "Soil_Dirt"
    },
    {
      "x": -21,
      "y": 16,
      "z": 2,
      "name": "Soil_Grass"
    },
    {
      "x": -21,
      "y": 11,
      "z": 3,
      "name": "Rock_Stone"
    },
    {
      "x": -21,
      "y": 12,
      "z": 3,
      "name": "Rock_Stone"
    },
    {
      "x": -21,
      "y": 13,
      "z": 3,
      "name": "Soil_Dirt"
    },
    {
      "x": -21,
      "y": 14,
      "z": 3,
      "name": "Soil_Grass"
    },
    {
      "x": -21,
      "y": 12,
      "z": 9,
      "name": "Rock_Stone"
    },
    {
      "x": -21,
      "y": 13,
      "z": 9,
      "name": "Soil_Dirt"
    },
    {
      "x": -21,
      "y": 14,
      "z": 9,
      "name": "Soil_Grass"
    },
    {
      "x": -21,
      "y": 10,
      "z": 10,
      "name": "Rock_Stone"
    },
    {
      "x": -21,
      "y": 11,
      "z": 10,
      "name": "Rock_Stone"
    },
    {
      "x": -21,
      "y": 12,
      "z": 10,
      "name": "Rock_Stone"
    },
    {
      "x": -21,
      "y": 13,
      "z": 10,
      "name": "Soil_Dirt"
    },
    {
      "x": -21,
      "y": 14,
      "z": 10,
      "name": "Soil_Dirt"
    },
    {
      "x": -21,
      "y": 15,
      "z": 10,
      "name": "Soil_Grass"
    },
    {
      "x": -21,
      "y": 8,
      "z": 11,
      "name": "Rock_Stone"
    },
    {
      "x": -21,
      "y": 9,
      "z": 11,
      "name": "Rock_Stone"
    },
    {
      "x": -21,
      "y": 10,
      "z": 11,
      "name": "Rock_Stone"
    },
    {
      "x": -21,
      "y": 11,
      "z": 11,
      "name": "Rock_Stone"
    },
    {
      "x": -21,
      "y": 12,
      "z": 11,
      "name": "Rock_Stone"
    },
    {
      "x": -21,
      "y": 13,
      "z": 11,
      "name": "Rock_Stone"
    },
    {
      "x": -21,
      "y": 14,
      "z": 11,
      "name": "Soil_Dirt"
    },
    {
      "x": -21,
      "y": 15,
      "z": 11,
      "name": "Soil_Grass"
    },
    {
      "x": -21,
      "y": 7,
      "z": 12,
      "name": "Rock_Stone"
    },
    {
      "x": -21,
      "y": 8,
      "z": 12,
      "name": "Rock_Stone"
    },
    {
      "x": -21,
      "y": 9,
      "z": 12,
      "name": "Rock_Stone"
    },
    {
      "x": -21,
      "y": 10,
      "z": 12,
      "name": "Rock_Stone"
    },
    {
      "x": -21,
      "y": 11,
      "z": 12,
      "name": "Rock_Stone"
    },
    {
      "x": -21,
      "y": 12,
      "z": 12,
      "name": "Rock_Stone"
    },
    {
      "x": -21,
      "y": 13,
      "z": 12,
      "name": "Rock_Stone"
    },
    {
      "x": -21,
      "y": 14,
      "z": 12,
      "name": "Soil_Dirt"
    },
    {
      "x": -21,
      "y": 15,
      "z": 12,
      "name": "Soil_Grass"
    },
    {
      "x": -21,
      "y": 7,
      "z": 13,
      "name": "Rock_Stone"
    },
    {
      "x": -21,
      "y": 8,
      "z": 13,
      "name": "Rock_Stone"
    },
    {
      "x": -21,
      "y": 9,
      "z": 13,
      "name": "Rock_Stone"
    },
    {
      "x": -21,
      "y": 10,
      "z": 13,
      "name": "Rock_Stone"
    },
    {
      "x": -21,
      "y": 11,
      "z": 13,
      "name": "Rock_Stone"
    },
    {
      "x": -21,
      "y": 12,
      "z": 13,
      "name": "Rock_Stone"
    },
    {
      "x": -21,
      "y": 13,
      "z": 13,
      "name": "Rock_Stone"
    },
    {
      "x": -21,
      "y": 14,
      "z": 13,
      "name": "Rock_Stone"
    },
    {
      "x": -21,
      "y": 8,
      "z": 14,
      "name": "Rock_Stone"
    },
    {
      "x": -21,
      "y": 9,
      "z": 14,
      "name": "Rock_Stone"
    },
    {
      "x": -21,
      "y": 10,
      "z": 14,
      "name": "Rock_Stone"
    },
    {
      "x": -21,
      "y": 11,
      "z": 14,
      "name": "Rock_Stone"
    },
    {
      "x": -21,
      "y": 12,
      "z": 14,
      "name": "Rock_Stone"
    },
    {
      "x": -21,
      "y": 13,
      "z": 14,
      "name": "Rock_Stone"
    },
    {
      "x": -20,
      "y": 24,
      "z": -13,
      "name": "Plant_Leaves_Beech",
      "support": 2
    },
    {
      "x": -20,
      "y": 23,
      "z": -12,
      "name": "Plant_Leaves_Beech",
      "support": 2
    },
    {
      "x": -20,
      "y": 24,
      "z": -12,
      "name": "Plant_Leaves_Beech",
      "support": 1
    },
    {
      "x": -20,
      "y": 25,
      "z": -12,
      "name": "Plant_Leaves_Beech",
      "support": 2
    },
    {
      "x": -20,
      "y": 22,
      "z": -11,
      "name": "Plant_Leaves_Beech",
      "support": 2
    },
    {
      "x": -20,
      "y": 23,
      "z": -11,
      "name": "Plant_Leaves_Beech",
      "support": 1
    },
    {
      "x": -20,
      "y": 24,
      "z": -11,
      "name": "Plant_Leaves_Beech"
    },
    {
      "x": -20,
      "y": 24,
      "z": -10,
      "name": "Plant_Leaves_Beech",
      "support": 1
    },
    {
      "x": -20,
      "y": 25,
      "z": -10,
      "name": "Plant_Leaves_Beech",
      "support": 2
    },
    {
      "x": -20,
      "y": 9,
      "z": -7,
      "name": "Rock_Stone"
    },
    {
      "x": -20,
      "y": 10,
      "z": -7,
      "name": "Rock_Stone"
    },
    {
      "x": -20,
      "y": 11,
      "z": -7,
      "name": "Rock_Stone"
    },
    {
      "x": -20,
      "y": 12,
      "z": -7,
      "name": "Rock_Stone"
    },
    {
      "x": -20,
      "y": 13,
      "z": -7,
      "name": "Rock_Stone"
    },
    {
      "x": -20,
      "y": 14,
      "z": -7,
      "name": "Rock_Stone"
    },
    {
      "x": -20,
      "y": 15,
      "z": -7,
      "name": "Soil_Grass"
    },
    {
      "x": -20,
      "y": 16,
      "z": -7,
      "name": "Plant_Grass_Sharp"
    },
    {
      "x": -20,
      "y": 9,
      "z": -6,
      "name": "Rock_Stone"
    },
    {
      "x": -20,
      "y": 10,
      "z": -6,
      "name": "Rock_Stone"
    },
    {
      "x": -20,
      "y": 11,
      "z": -6,
      "name": "Rock_Stone"
    },
    {
      "x": -20,
      "y": 12,
      "z": -6,
      "name": "Rock_Stone"
    },
    {
      "x": -20,
      "y": 13,
      "z": -6,
      "name": "Rock_Stone"
    },
    {
      "x": -20,
      "y": 14,
      "z": -6,
      "name": "Rock_Stone"
    },
    {
      "x": -20,
      "y": 15,
      "z": -6,
      "name": "Rock_Stone"
    },
    {
      "x": -20,
      "y": 16,
      "z": -6,
      "name": "Rock_Stone"
    },
    {
      "x": -20,
      "y": 17,
      "z": -6,
      "name": "Rock_Stone"
    },
    {
      "x": -20,
      "y": 9,
      "z": -5,
      "name": "Rock_Stone"
    },
    {
      "x": -20,
      "y": 10,
      "z": -5,
      "name": "Rock_Stone"
    },
    {
      "x": -20,
      "y": 11,
      "z": -5,
      "name": "Rock_Stone"
    },
    {
      "x": -20,
      "y": 12,
      "z": -5,
      "name": "Rock_Stone"
    },
    {
      "x": -20,
      "y": 13,
      "z": -5,
      "name": "Rock_Stone"
    },
    {
      "x": -20,
      "y": 14,
      "z": -5,
      "name": "Rock_Stone"
    },
    {
      "x": -20,
      "y": 15,
      "z": -5,
      "name": "Rock_Stone"
    },
    {
      "x": -20,
      "y": 16,
      "z": -5,
      "name": "Rock_Stone"
    },
    {
      "x": -20,
      "y": 17,
      "z": -5,
      "name": "Rock_Stone"
    },
    {
      "x": -20,
      "y": 9,
      "z": -4,
      "name": "Rock_Stone"
    },
    {
      "x": -20,
      "y": 10,
      "z": -4,
      "name": "Rock_Stone"
    },
    {
      "x": -20,
      "y": 11,
      "z": -4,
      "name": "Rock_Stone"
    },
    {
      "x": -20,
      "y": 12,
      "z": -4,
      "name": "Rock_Stone"
    },
    {
      "x": -20,
      "y": 13,
      "z": -4,
      "name": "Rock_Stone"
    },
    {
      "x": -20,
      "y": 14,
      "z": -4,
      "name": "Rock_Stone"
    },
    {
      "x": -20,
      "y": 15,
      "z": -4,
      "name": "Rock_Stone"
    },
    {
      "x": -20,
      "y": 16,
      "z": -4,
      "name": "Rock_Stone"
    },
    {
      "x": -20,
      "y": 17,
      "z": -4,
      "name": "Rock_Stone"
    },
    {
      "x": -20,
      "y": 18,
      "z": -4,
      "name": "Rock_Stone"
    },
    {
      "x": -20,
      "y": 9,
      "z": -3,
      "name": "Rock_Stone"
    },
    {
      "x": -20,
      "y": 10,
      "z": -3,
      "name": "Rock_Stone"
    },
    {
      "x": -20,
      "y": 11,
      "z": -3,
      "name": "Rock_Stone"
    },
    {
      "x": -20,
      "y": 12,
      "z": -3,
      "name": "Rock_Stone"
    },
    {
      "x": -20,
      "y": 13,
      "z": -3,
      "name": "Rock_Stone"
    },
    {
      "x": -20,
      "y": 14,
      "z": -3,
      "name": "Rock_Stone"
    },
    {
      "x": -20,
      "y": 15,
      "z": -3,
      "name": "Rock_Stone"
    },
    {
      "x": -20,
      "y": 16,
      "z": -3,
      "name": "Rock_Stone"
    },
    {
      "x": -20,
      "y": 17,
      "z": -3,
      "name": "Rock_Stone"
    },
    {
      "x": -20,
      "y": 18,
      "z": -3,
      "name": "Rock_Stone"
    },
    {
      "x": -20,
      "y": 19,
      "z": -3,
      "name": "Rock_Stone"
    },
    {
      "x": -20,
      "y": 9,
      "z": -2,
      "name": "Rock_Stone"
    },
    {
      "x": -20,
      "y": 10,
      "z": -2,
      "name": "Rock_Stone"
    },
    {
      "x": -20,
      "y": 11,
      "z": -2,
      "name": "Rock_Stone"
    },
    {
      "x": -20,
      "y": 12,
      "z": -2,
      "name": "Rock_Stone"
    },
    {
      "x": -20,
      "y": 13,
      "z": -2,
      "name": "Rock_Stone"
    },
    {
      "x": -20,
      "y": 14,
      "z": -2,
      "name": "Rock_Stone"
    },
    {
      "x": -20,
      "y": 15,
      "z": -2,
      "name": "Rock_Stone"
    },
    {
      "x": -20,
      "y": 16,
      "z": -2,
      "name": "Rock_Stone"
    },
    {
      "x": -20,
      "y": 17,
      "z": -2,
      "name": "Rock_Stone"
    },
    {
      "x": -20,
      "y": 18,
      "z": -2,
      "name": "Rock_Stone"
    },
    {
      "x": -20,
      "y": 19,
      "z": -2,
      "name": "Rock_Stone"
    },
    {
      "x": -20,
      "y": 20,
      "z": -2,
      "name": "Rock_Stone"
    },
    {
      "x": -20,
      "y": 9,
      "z": -1,
      "name": "Rock_Stone"
    },
    {
      "x": -20,
      "y": 10,
      "z": -1,
      "name": "Rock_Stone"
    },
    {
      "x": -20,
      "y": 11,
      "z": -1,
      "name": "Rock_Stone"
    },
    {
      "x": -20,
      "y": 12,
      "z": -1,
      "name": "Rock_Stone"
    },
    {
      "x": -20,
      "y": 13,
      "z": -1,
      "name": "Rock_Stone"
    },
    {
      "x": -20,
      "y": 14,
      "z": -1,
      "name": "Rock_Stone"
    },
    {
      "x": -20,
      "y": 15,
      "z": -1,
      "name": "Rock_Stone"
    },
    {
      "x": -20,
      "y": 16,
      "z": -1,
      "name": "Rock_Stone"
    },
    {
      "x": -20,
      "y": 17,
      "z": -1,
      "name": "Rock_Stone"
    },
    {
      "x": -20,
      "y": 18,
      "z": -1,
      "name": "Rock_Stone"
    },
    {
      "x": -20,
      "y": 19,
      "z": -1,
      "name": "Rock_Stone"
    },
    {
      "x": -20,
      "y": 20,
      "z": -1,
      "name": "Rock_Stone"
    },
    {
      "x": -20,
      "y": 9,
      "z": 0,
      "name": "Rock_Stone"
    },
    {
      "x": -20,
      "y": 10,
      "z": 0,
      "name": "Rock_Stone"
    },
    {
      "x": -20,
      "y": 11,
      "z": 0,
      "name": "Rock_Stone"
    },
    {
      "x": -20,
      "y": 12,
      "z": 0,
      "name": "Rock_Stone"
    },
    {
      "x": -20,
      "y": 13,
      "z": 0,
      "name": "Rock_Stone"
    },
    {
      "x": -20,
      "y": 14,
      "z": 0,
      "name": "Rock_Stone"
    },
    {
      "x": -20,
      "y": 15,
      "z": 0,
      "name": "Rock_Stone"
    },
    {
      "x": -20,
      "y": 16,
      "z": 0,
      "name": "Rock_Stone"
    },
    {
      "x": -20,
      "y": 17,
      "z": 0,
      "name": "Rock_Stone"
    },
    {
      "x": -20,
      "y": 18,
      "z": 0,
      "name": "Rock_Stone"
    },
    {
      "x": -20,
      "y": 19,
      "z": 0,
      "name": "Rock_Stone"
    },
    {
      "x": -20,
      "y": 9,
      "z": 1,
      "name": "Rock_Stone"
    },
    {
      "x": -20,
      "y": 10,
      "z": 1,
      "name": "Rock_Stone"
    },
    {
      "x": -20,
      "y": 11,
      "z": 1,
      "name": "Rock_Stone"
    },
    {
      "x": -20,
      "y": 12,
      "z": 1,
      "name": "Rock_Stone"
    },
    {
      "x": -20,
      "y": 13,
      "z": 1,
      "name": "Rock_Stone"
    },
    {
      "x": -20,
      "y": 14,
      "z": 1,
      "name": "Rock_Stone"
    },
    {
      "x": -20,
      "y": 15,
      "z": 1,
      "name": "Rock_Stone"
    },
    {
      "x": -20,
      "y": 16,
      "z": 1,
      "name": "Rock_Stone"
    },
    {
      "x": -20,
      "y": 17,
      "z": 1,
      "name": "Rock_Stone"
    },
    {
      "x": -20,
      "y": 18,
      "z": 1,
      "name": "Soil_Grass"
    },
    {
      "x": -20,
      "y": 19,
      "z": 1,
      "name": "Plant_Flower_Bushy_Green"
    },
    {
      "x": -20,
      "y": 9,
      "z": 2,
      "name": "Rock_Stone"
    },
    {
      "x": -20,
      "y": 10,
      "z": 2,
      "name": "Rock_Stone"
    },
    {
      "x": -20,
      "y": 11,
      "z": 2,
      "name": "Rock_Stone"
    },
    {
      "x": -20,
      "y": 12,
      "z": 2,
      "name": "Rock_Stone"
    },
    {
      "x": -20,
      "y": 13,
      "z": 2,
      "name": "Rock_Stone"
    },
    {
      "x": -20,
      "y": 14,
      "z": 2,
      "name": "Rock_Stone"
    },
    {
      "x": -20,
      "y": 15,
      "z": 2,
      "name": "Rock_Stone"
    },
    {
      "x": -20,
      "y": 16,
      "z": 2,
      "name": "Rock_Stone"
    },
    {
      "x": -20,
      "y": 17,
      "z": 2,
      "name": "Soil_Grass"
    },
    {
      "x": -20,
      "y": 18,
      "z": 2,
      "name": "Plant_Grass_Sharp"
    },
    {
      "x": -20,
      "y": 10,
      "z": 3,
      "name": "Rock_Stone"
    },
    {
      "x": -20,
      "y": 11,
      "z": 3,
      "name": "Rock_Stone"
    },
    {
      "x": -20,
      "y": 12,
      "z": 3,
      "name": "Rock_Stone"
    },
    {
      "x": -20,
      "y": 13,
      "z": 3,
      "name": "Rock_Stone"
    },
    {
      "x": -20,
      "y": 14,
      "z": 3,
      "name": "Rock_Stone"
    },
    {
      "x": -20,
      "y": 15,
      "z": 3,
      "name": "Soil_Dirt"
    },
    {
      "x": -20,
      "y": 16,
      "z": 3,
      "name": "Soil_Grass"
    },
    {
      "x": -20,
      "y": 10,
      "z": 4,
      "name": "Rock_Stone"
    },
    {
      "x": -20,
      "y": 11,
      "z": 4,
      "name": "Rock_Stone"
    },
    {
      "x": -20,
      "y": 12,
      "z": 4,
      "name": "Soil_Dirt"
    },
    {
      "x": -20,
      "y": 13,
      "z": 4,
      "name": "Soil_Dirt"
    },
    {
      "x": -20,
      "y": 14,
      "z": 4,
      "name": "Soil_Dirt"
    },
    {
      "x": -20,
      "y": 15,
      "z": 4,
      "name": "Soil_Dirt"
    },
    {
      "x": -20,
      "y": 16,
      "z": 4,
      "name": "Soil_Grass"
    },
    {
      "x": -20,
      "y": 10,
      "z": 5,
      "name": "Rock_Stone"
    },
    {
      "x": -20,
      "y": 11,
      "z": 5,
      "name": "Rock_Stone"
    },
    {
      "x": -20,
      "y": 12,
      "z": 5,
      "name": "Soil_Dirt"
    },
    {
      "x": -20,
      "y": 13,
      "z": 5,
      "name": "Soil_Dirt"
    },
    {
      "x": -20,
      "y": 14,
      "z": 5,
      "name": "Soil_Dirt"
    },
    {
      "x": -20,
      "y": 15,
      "z": 5,
      "name": "Soil_Grass"
    },
    {
      "x": -20,
      "y": 11,
      "z": 6,
      "name": "Rock_Stone"
    },
    {
      "x": -20,
      "y": 12,
      "z": 6,
      "name": "Rock_Stone"
    },
    {
      "x": -20,
      "y": 13,
      "z": 6,
      "name": "Soil_Dirt"
    },
    {
      "x": -20,
      "y": 14,
      "z": 6,
      "name": "Soil_Dirt"
    },
    {
      "x": -20,
      "y": 15,
      "z": 6,
      "name": "Soil_Grass"
    },
    {
      "x": -20,
      "y": 11,
      "z": 7,
      "name": "Rock_Stone"
    },
    {
      "x": -20,
      "y": 12,
      "z": 7,
      "name": "Rock_Stone"
    },
    {
      "x": -20,
      "y": 13,
      "z": 7,
      "name": "Soil_Dirt"
    },
    {
      "x": -20,
      "y": 14,
      "z": 7,
      "name": "Soil_Dirt"
    },
    {
      "x": -20,
      "y": 15,
      "z": 7,
      "name": "Soil_Grass"
    },
    {
      "x": -20,
      "y": 16,
      "z": 7,
      "name": "Plant_Grass_Sharp"
    },
    {
      "x": -20,
      "y": 10,
      "z": 8,
      "name": "Rock_Stone"
    },
    {
      "x": -20,
      "y": 11,
      "z": 8,
      "name": "Rock_Stone"
    },
    {
      "x": -20,
      "y": 12,
      "z": 8,
      "name": "Rock_Stone"
    },
    {
      "x": -20,
      "y": 13,
      "z": 8,
      "name": "Rock_Stone"
    },
    {
      "x": -20,
      "y": 14,
      "z": 8,
      "name": "Soil_Dirt"
    },
    {
      "x": -20,
      "y": 15,
      "z": 8,
      "name": "Soil_Dirt"
    },
    {
      "x": -20,
      "y": 16,
      "z": 8,
      "name": "Soil_Grass"
    },
    {
      "x": -20,
      "y": 17,
      "z": 8,
      "name": "Plant_Flower_Common_Yellow"
    },
    {
      "x": -20,
      "y": 10,
      "z": 9,
      "name": "Rock_Stone"
    },
    {
      "x": -20,
      "y": 11,
      "z": 9,
      "name": "Rock_Stone"
    },
    {
      "x": -20,
      "y": 12,
      "z": 9,
      "name": "Rock_Stone"
    },
    {
      "x": -20,
      "y": 13,
      "z": 9,
      "name": "Rock_Stone"
    },
    {
      "x": -20,
      "y": 14,
      "z": 9,
      "name": "Rock_Stone"
    },
    {
      "x": -20,
      "y": 15,
      "z": 9,
      "name": "Soil_Dirt"
    },
    {
      "x": -20,
      "y": 16,
      "z": 9,
      "name": "Soil_Dirt"
    },
    {
      "x": -20,
      "y": 17,
      "z": 9,
      "name": "Soil_Grass"
    },
    {
      "x": -20,
      "y": 18,
      "z": 9,
      "name": "Plant_Grass_Sharp"
    },
    {
      "x": -20,
      "y": 8,
      "z": 10,
      "name": "Rock_Stone"
    },
    {
      "x": -20,
      "y": 9,
      "z": 10,
      "name": "Rock_Stone"
    },
    {
      "x": -20,
      "y": 10,
      "z": 10,
      "name": "Rock_Stone"
    },
    {
      "x": -20,
      "y": 11,
      "z": 10,
      "name": "Rock_Stone"
    },
    {
      "x": -20,
      "y": 12,
      "z": 10,
      "name": "Rock_Stone"
    },
    {
      "x": -20,
      "y": 13,
      "z": 10,
      "name": "Rock_Stone"
    },
    {
      "x": -20,
      "y": 14,
      "z": 10,
      "name": "Rock_Stone"
    },
    {
      "x": -20,
      "y": 15,
      "z": 10,
      "name": "Rock_Stone"
    },
    {
      "x": -20,
      "y": 16,
      "z": 10,
      "name": "Soil_Dirt"
    },
    {
      "x": -20,
      "y": 17,
      "z": 10,
      "name": "Soil_Grass"
    },
    {
      "x": -20,
      "y": 7,
      "z": 11,
      "name": "Rock_Stone"
    },
    {
      "x": -20,
      "y": 8,
      "z": 11,
      "name": "Rock_Stone"
    },
    {
      "x": -20,
      "y": 9,
      "z": 11,
      "name": "Rock_Stone"
    },
    {
      "x": -20,
      "y": 10,
      "z": 11,
      "name": "Rock_Stone"
    },
    {
      "x": -20,
      "y": 11,
      "z": 11,
      "name": "Rock_Stone"
    },
    {
      "x": -20,
      "y": 12,
      "z": 11,
      "name": "Rock_Stone"
    },
    {
      "x": -20,
      "y": 13,
      "z": 11,
      "name": "Rock_Stone"
    },
    {
      "x": -20,
      "y": 14,
      "z": 11,
      "name": "Rock_Stone"
    },
    {
      "x": -20,
      "y": 15,
      "z": 11,
      "name": "Rock_Stone"
    },
    {
      "x": -20,
      "y": 16,
      "z": 11,
      "name": "Soil_Dirt"
    },
    {
      "x": -20,
      "y": 17,
      "z": 11,
      "name": "Soil_Grass"
    },
    {
      "x": -20,
      "y": 6,
      "z": 12,
      "name": "Rock_Stone"
    },
    {
      "x": -20,
      "y": 7,
      "z": 12,
      "name": "Rock_Stone"
    },
    {
      "x": -20,
      "y": 8,
      "z": 12,
      "name": "Rock_Stone"
    },
    {
      "x": -20,
      "y": 9,
      "z": 12,
      "name": "Rock_Stone"
    },
    {
      "x": -20,
      "y": 10,
      "z": 12,
      "name": "Rock_Stone"
    },
    {
      "x": -20,
      "y": 11,
      "z": 12,
      "name": "Rock_Stone"
    },
    {
      "x": -20,
      "y": 12,
      "z": 12,
      "name": "Rock_Stone"
    },
    {
      "x": -20,
      "y": 13,
      "z": 12,
      "name": "Rock_Stone"
    },
    {
      "x": -20,
      "y": 14,
      "z": 12,
      "name": "Rock_Stone"
    },
    {
      "x": -20,
      "y": 15,
      "z": 12,
      "name": "Rock_Stone"
    },
    {
      "x": -20,
      "y": 16,
      "z": 12,
      "name": "Soil_Dirt"
    },
    {
      "x": -20,
      "y": 17,
      "z": 12,
      "name": "Rock_Stone"
    },
    {
      "x": -20,
      "y": 6,
      "z": 13,
      "name": "Rock_Stone"
    },
    {
      "x": -20,
      "y": 7,
      "z": 13,
      "name": "Rock_Stone"
    },
    {
      "x": -20,
      "y": 8,
      "z": 13,
      "name": "Rock_Stone"
    },
    {
      "x": -20,
      "y": 9,
      "z": 13,
      "name": "Rock_Stone"
    },
    {
      "x": -20,
      "y": 10,
      "z": 13,
      "name": "Rock_Stone"
    },
    {
      "x": -20,
      "y": 11,
      "z": 13,
      "name": "Rock_Stone"
    },
    {
      "x": -20,
      "y": 12,
      "z": 13,
      "name": "Rock_Stone"
    },
    {
      "x": -20,
      "y": 13,
      "z": 13,
      "name": "Rock_Stone"
    },
    {
      "x": -20,
      "y": 14,
      "z": 13,
      "name": "Rock_Stone"
    },
    {
      "x": -20,
      "y": 15,
      "z": 13,
      "name": "Rock_Stone"
    },
    {
      "x": -20,
      "y": 16,
      "z": 13,
      "name": "Rock_Stone"
    },
    {
      "x": -20,
      "y": 17,
      "z": 13,
      "name": "Rock_Stone"
    },
    {
      "x": -20,
      "y": 18,
      "z": 13,
      "name": "Rock_Stone"
    },
    {
      "x": -20,
      "y": 6,
      "z": 14,
      "name": "Rock_Stone"
    },
    {
      "x": -20,
      "y": 7,
      "z": 14,
      "name": "Rock_Stone"
    },
    {
      "x": -20,
      "y": 8,
      "z": 14,
      "name": "Rock_Stone"
    },
    {
      "x": -20,
      "y": 9,
      "z": 14,
      "name": "Rock_Stone"
    },
    {
      "x": -20,
      "y": 10,
      "z": 14,
      "name": "Rock_Stone"
    },
    {
      "x": -20,
      "y": 11,
      "z": 14,
      "name": "Rock_Stone"
    },
    {
      "x": -20,
      "y": 12,
      "z": 14,
      "name": "Rock_Stone"
    },
    {
      "x": -20,
      "y": 13,
      "z": 14,
      "name": "Rock_Stone"
    },
    {
      "x": -20,
      "y": 14,
      "z": 14,
      "name": "Rock_Stone"
    },
    {
      "x": -20,
      "y": 15,
      "z": 14,
      "name": "Rock_Stone"
    },
    {
      "x": -20,
      "y": 16,
      "z": 14,
      "name": "Rock_Stone"
    },
    {
      "x": -20,
      "y": 17,
      "z": 14,
      "name": "Rock_Stone"
    },
    {
      "x": -20,
      "y": 18,
      "z": 14,
      "name": "Rock_Stone"
    },
    {
      "x": -20,
      "y": 7,
      "z": 15,
      "name": "Rock_Stone"
    },
    {
      "x": -20,
      "y": 8,
      "z": 15,
      "name": "Rock_Stone"
    },
    {
      "x": -20,
      "y": 9,
      "z": 15,
      "name": "Rock_Stone"
    },
    {
      "x": -20,
      "y": 10,
      "z": 15,
      "name": "Rock_Stone"
    },
    {
      "x": -20,
      "y": 11,
      "z": 15,
      "name": "Rock_Stone"
    },
    {
      "x": -20,
      "y": 12,
      "z": 15,
      "name": "Rock_Stone"
    },
    {
      "x": -20,
      "y": 13,
      "z": 15,
      "name": "Rock_Stone"
    },
    {
      "x": -20,
      "y": 14,
      "z": 15,
      "name": "Rock_Stone"
    },
    {
      "x": -20,
      "y": 15,
      "z": 15,
      "name": "Rock_Stone"
    },
    {
      "x": -20,
      "y": 8,
      "z": 16,
      "name": "Rock_Stone"
    },
    {
      "x": -20,
      "y": 9,
      "z": 16,
      "name": "Rock_Stone"
    },
    {
      "x": -20,
      "y": 10,
      "z": 16,
      "name": "Rock_Stone"
    },
    {
      "x": -20,
      "y": 11,
      "z": 16,
      "name": "Rock_Stone"
    },
    {
      "x": -20,
      "y": 12,
      "z": 16,
      "name": "Rock_Stone"
    },
    {
      "x": -20,
      "y": 13,
      "z": 16,
      "name": "Rock_Stone"
    },
    {
      "x": -19,
      "y": 24,
      "z": -13,
      "name": "Plant_Leaves_Beech",
      "support": 1
    },
    {
      "x": -19,
      "y": 25,
      "z": -13,
      "name": "Plant_Leaves_Beech",
      "support": 2
    },
    {
      "x": -19,
      "y": 24,
      "z": -12,
      "name": "Plant_Leaves_Beech"
    },
    {
      "x": -19,
      "y": 25,
      "z": -12,
      "name": "Plant_Leaves_Beech",
      "support": 1
    },
    {
      "x": -19,
      "y": 20,
      "z": -11,
      "name": "Plant_Leaves_Beech",
      "support": 1
    },
    {
      "x": -19,
      "y": 24,
      "z": -11,
      "name": "Wood_Beech_Branch_Long",
      "support": 1,
      "rotation": 5
    },
    {
      "x": -19,
      "y": 25,
      "z": -11,
      "name": "Plant_Leaves_Beech"
    },
    {
      "x": -19,
      "y": 26,
      "z": -11,
      "name": "Plant_Leaves_Beech",
      "support": 1
    },
    {
      "x": -19,
      "y": 22,
      "z": -10,
      "name": "Plant_Leaves_Beech",
      "support": 2
    },
    {
      "x": -19,
      "y": 23,
      "z": -10,
      "name": "Plant_Leaves_Beech",
      "support": 1
    },
    {
      "x": -19,
      "y": 24,
      "z": -10,
      "name": "Plant_Leaves_Beech"
    },
    {
      "x": -19,
      "y": 25,
      "z": -10,
      "name": "Plant_Leaves_Beech",
      "support": 1
    },
    {
      "x": -19,
      "y": 26,
      "z": -10,
      "name": "Plant_Leaves_Beech",
      "support": 2
    },
    {
      "x": -19,
      "y": 23,
      "z": -9,
      "name": "Plant_Leaves_Beech",
      "support": 2
    },
    {
      "x": -19,
      "y": 24,
      "z": -9,
      "name": "Plant_Leaves_Beech",
      "support": 1
    },
    {
      "x": -19,
      "y": 11,
      "z": -8,
      "name": "Rock_Stone"
    },
    {
      "x": -19,
      "y": 12,
      "z": -8,
      "name": "Rock_Stone"
    },
    {
      "x": -19,
      "y": 13,
      "z": -8,
      "name": "Rock_Stone"
    },
    {
      "x": -19,
      "y": 14,
      "z": -8,
      "name": "Soil_Dirt"
    },
    {
      "x": -19,
      "y": 15,
      "z": -8,
      "name": "Soil_Grass"
    },
    {
      "x": -19,
      "y": 16,
      "z": -8,
      "name": "Plant_Grass_Sharp"
    },
    {
      "x": -19,
      "y": 24,
      "z": -8,
      "name": "Plant_Leaves_Beech",
      "support": 2
    },
    {
      "x": -19,
      "y": 9,
      "z": -7,
      "name": "Rock_Stone"
    },
    {
      "x": -19,
      "y": 10,
      "z": -7,
      "name": "Rock_Stone"
    },
    {
      "x": -19,
      "y": 11,
      "z": -7,
      "name": "Rock_Stone"
    },
    {
      "x": -19,
      "y": 12,
      "z": -7,
      "name": "Rock_Stone"
    },
    {
      "x": -19,
      "y": 13,
      "z": -7,
      "name": "Rock_Stone"
    },
    {
      "x": -19,
      "y": 14,
      "z": -7,
      "name": "Rock_Stone"
    },
    {
      "x": -19,
      "y": 15,
      "z": -7,
      "name": "Rock_Stone"
    },
    {
      "x": -19,
      "y": 16,
      "z": -7,
      "name": "Soil_Dirt"
    },
    {
      "x": -19,
      "y": 17,
      "z": -7,
      "name": "Soil_Grass"
    },
    {
      "x": -19,
      "y": 18,
      "z": -7,
      "name": "Plant_Grass_Sharp"
    },
    {
      "x": -19,
      "y": 9,
      "z": -6,
      "name": "Rock_Stone"
    },
    {
      "x": -19,
      "y": 10,
      "z": -6,
      "name": "Rock_Stone"
    },
    {
      "x": -19,
      "y": 11,
      "z": -6,
      "name": "Rock_Stone"
    },
    {
      "x": -19,
      "y": 12,
      "z": -6,
      "name": "Rock_Stone"
    },
    {
      "x": -19,
      "y": 13,
      "z": -6,
      "name": "Rock_Stone"
    },
    {
      "x": -19,
      "y": 14,
      "z": -6,
      "name": "Rock_Stone"
    },
    {
      "x": -19,
      "y": 15,
      "z": -6,
      "name": "Rock_Stone"
    },
    {
      "x": -19,
      "y": 16,
      "z": -6,
      "name": "Rock_Stone"
    },
    {
      "x": -19,
      "y": 17,
      "z": -6,
      "name": "Rock_Stone"
    },
    {
      "x": -19,
      "y": 18,
      "z": -6,
      "name": "Rock_Stone"
    },
    {
      "x": -19,
      "y": 9,
      "z": -5,
      "name": "Rock_Stone"
    },
    {
      "x": -19,
      "y": 10,
      "z": -5,
      "name": "Rock_Stone"
    },
    {
      "x": -19,
      "y": 11,
      "z": -5,
      "name": "Rock_Stone"
    },
    {
      "x": -19,
      "y": 12,
      "z": -5,
      "name": "Rock_Stone"
    },
    {
      "x": -19,
      "y": 13,
      "z": -5,
      "name": "Rock_Stone"
    },
    {
      "x": -19,
      "y": 14,
      "z": -5,
      "name": "Rock_Stone"
    },
    {
      "x": -19,
      "y": 15,
      "z": -5,
      "name": "Rock_Stone"
    },
    {
      "x": -19,
      "y": 16,
      "z": -5,
      "name": "Rock_Stone"
    },
    {
      "x": -19,
      "y": 17,
      "z": -5,
      "name": "Rock_Stone"
    },
    {
      "x": -19,
      "y": 18,
      "z": -5,
      "name": "Rock_Stone"
    },
    {
      "x": -19,
      "y": 19,
      "z": -5,
      "name": "Rock_Stone"
    },
    {
      "x": -19,
      "y": 20,
      "z": -5,
      "name": "Rock_Stone"
    },
    {
      "x": -19,
      "y": 8,
      "z": -4,
      "name": "Rock_Stone"
    },
    {
      "x": -19,
      "y": 9,
      "z": -4,
      "name": "Rock_Stone"
    },
    {
      "x": -19,
      "y": 10,
      "z": -4,
      "name": "Rock_Stone"
    },
    {
      "x": -19,
      "y": 11,
      "z": -4,
      "name": "Rock_Stone"
    },
    {
      "x": -19,
      "y": 12,
      "z": -4,
      "name": "Rock_Stone"
    },
    {
      "x": -19,
      "y": 13,
      "z": -4,
      "name": "Rock_Stone"
    },
    {
      "x": -19,
      "y": 14,
      "z": -4,
      "name": "Rock_Stone"
    },
    {
      "x": -19,
      "y": 15,
      "z": -4,
      "name": "Rock_Stone"
    },
    {
      "x": -19,
      "y": 16,
      "z": -4,
      "name": "Rock_Stone"
    },
    {
      "x": -19,
      "y": 17,
      "z": -4,
      "name": "Rock_Stone"
    },
    {
      "x": -19,
      "y": 18,
      "z": -4,
      "name": "Rock_Stone"
    },
    {
      "x": -19,
      "y": 19,
      "z": -4,
      "name": "Rock_Stone"
    },
    {
      "x": -19,
      "y": 20,
      "z": -4,
      "name": "Rock_Stone"
    },
    {
      "x": -19,
      "y": 8,
      "z": -3,
      "name": "Rock_Stone"
    },
    {
      "x": -19,
      "y": 9,
      "z": -3,
      "name": "Rock_Stone"
    },
    {
      "x": -19,
      "y": 10,
      "z": -3,
      "name": "Rock_Stone"
    },
    {
      "x": -19,
      "y": 11,
      "z": -3,
      "name": "Rock_Stone"
    },
    {
      "x": -19,
      "y": 12,
      "z": -3,
      "name": "Rock_Stone"
    },
    {
      "x": -19,
      "y": 13,
      "z": -3,
      "name": "Rock_Stone"
    },
    {
      "x": -19,
      "y": 14,
      "z": -3,
      "name": "Rock_Stone"
    },
    {
      "x": -19,
      "y": 15,
      "z": -3,
      "name": "Rock_Stone"
    },
    {
      "x": -19,
      "y": 16,
      "z": -3,
      "name": "Rock_Stone"
    },
    {
      "x": -19,
      "y": 17,
      "z": -3,
      "name": "Rock_Stone"
    },
    {
      "x": -19,
      "y": 18,
      "z": -3,
      "name": "Rock_Stone"
    },
    {
      "x": -19,
      "y": 19,
      "z": -3,
      "name": "Rock_Stone"
    },
    {
      "x": -19,
      "y": 20,
      "z": -3,
      "name": "Rock_Stone"
    },
    {
      "x": -19,
      "y": 21,
      "z": -3,
      "name": "Rock_Stone"
    },
    {
      "x": -19,
      "y": 8,
      "z": -2,
      "name": "Rock_Stone"
    },
    {
      "x": -19,
      "y": 9,
      "z": -2,
      "name": "Rock_Stone"
    },
    {
      "x": -19,
      "y": 10,
      "z": -2,
      "name": "Rock_Stone"
    },
    {
      "x": -19,
      "y": 11,
      "z": -2,
      "name": "Rock_Stone"
    },
    {
      "x": -19,
      "y": 12,
      "z": -2,
      "name": "Rock_Stone"
    },
    {
      "x": -19,
      "y": 13,
      "z": -2,
      "name": "Rock_Stone"
    },
    {
      "x": -19,
      "y": 14,
      "z": -2,
      "name": "Rock_Stone"
    },
    {
      "x": -19,
      "y": 15,
      "z": -2,
      "name": "Rock_Stone"
    },
    {
      "x": -19,
      "y": 16,
      "z": -2,
      "name": "Rock_Stone"
    },
    {
      "x": -19,
      "y": 17,
      "z": -2,
      "name": "Rock_Stone"
    },
    {
      "x": -19,
      "y": 18,
      "z": -2,
      "name": "Rock_Stone"
    },
    {
      "x": -19,
      "y": 19,
      "z": -2,
      "name": "Rock_Stone"
    },
    {
      "x": -19,
      "y": 20,
      "z": -2,
      "name": "Rock_Stone"
    },
    {
      "x": -19,
      "y": 21,
      "z": -2,
      "name": "Rock_Stone"
    },
    {
      "x": -19,
      "y": 22,
      "z": -2,
      "name": "Rock_Stone"
    },
    {
      "x": -19,
      "y": 8,
      "z": -1,
      "name": "Rock_Stone"
    },
    {
      "x": -19,
      "y": 9,
      "z": -1,
      "name": "Rock_Stone"
    },
    {
      "x": -19,
      "y": 10,
      "z": -1,
      "name": "Rock_Stone"
    },
    {
      "x": -19,
      "y": 11,
      "z": -1,
      "name": "Rock_Stone"
    },
    {
      "x": -19,
      "y": 12,
      "z": -1,
      "name": "Rock_Stone"
    },
    {
      "x": -19,
      "y": 13,
      "z": -1,
      "name": "Rock_Stone"
    },
    {
      "x": -19,
      "y": 14,
      "z": -1,
      "name": "Rock_Stone"
    },
    {
      "x": -19,
      "y": 15,
      "z": -1,
      "name": "Rock_Stone"
    },
    {
      "x": -19,
      "y": 16,
      "z": -1,
      "name": "Rock_Stone"
    },
    {
      "x": -19,
      "y": 17,
      "z": -1,
      "name": "Rock_Stone"
    },
    {
      "x": -19,
      "y": 18,
      "z": -1,
      "name": "Rock_Stone"
    },
    {
      "x": -19,
      "y": 19,
      "z": -1,
      "name": "Rock_Stone"
    },
    {
      "x": -19,
      "y": 20,
      "z": -1,
      "name": "Rock_Stone"
    },
    {
      "x": -19,
      "y": 21,
      "z": -1,
      "name": "Rock_Stone"
    },
    {
      "x": -19,
      "y": 22,
      "z": -1,
      "name": "Rock_Stone"
    },
    {
      "x": -19,
      "y": 8,
      "z": 0,
      "name": "Rock_Stone"
    },
    {
      "x": -19,
      "y": 9,
      "z": 0,
      "name": "Rock_Stone"
    },
    {
      "x": -19,
      "y": 10,
      "z": 0,
      "name": "Rock_Stone"
    },
    {
      "x": -19,
      "y": 11,
      "z": 0,
      "name": "Rock_Stone"
    },
    {
      "x": -19,
      "y": 12,
      "z": 0,
      "name": "Rock_Stone"
    },
    {
      "x": -19,
      "y": 13,
      "z": 0,
      "name": "Rock_Stone"
    },
    {
      "x": -19,
      "y": 14,
      "z": 0,
      "name": "Rock_Stone"
    },
    {
      "x": -19,
      "y": 15,
      "z": 0,
      "name": "Rock_Stone"
    },
    {
      "x": -19,
      "y": 16,
      "z": 0,
      "name": "Rock_Stone"
    },
    {
      "x": -19,
      "y": 17,
      "z": 0,
      "name": "Rock_Stone"
    },
    {
      "x": -19,
      "y": 18,
      "z": 0,
      "name": "Rock_Stone"
    },
    {
      "x": -19,
      "y": 19,
      "z": 0,
      "name": "Rock_Stone"
    },
    {
      "x": -19,
      "y": 20,
      "z": 0,
      "name": "Rock_Stone"
    },
    {
      "x": -19,
      "y": 8,
      "z": 1,
      "name": "Rock_Stone"
    },
    {
      "x": -19,
      "y": 9,
      "z": 1,
      "name": "Rock_Stone"
    },
    {
      "x": -19,
      "y": 10,
      "z": 1,
      "name": "Rock_Stone"
    },
    {
      "x": -19,
      "y": 11,
      "z": 1,
      "name": "Rock_Stone"
    },
    {
      "x": -19,
      "y": 12,
      "z": 1,
      "name": "Rock_Stone"
    },
    {
      "x": -19,
      "y": 13,
      "z": 1,
      "name": "Rock_Stone"
    },
    {
      "x": -19,
      "y": 14,
      "z": 1,
      "name": "Rock_Stone"
    },
    {
      "x": -19,
      "y": 15,
      "z": 1,
      "name": "Rock_Stone"
    },
    {
      "x": -19,
      "y": 16,
      "z": 1,
      "name": "Rock_Stone"
    },
    {
      "x": -19,
      "y": 17,
      "z": 1,
      "name": "Rock_Stone"
    },
    {
      "x": -19,
      "y": 18,
      "z": 1,
      "name": "Rock_Stone"
    },
    {
      "x": -19,
      "y": 19,
      "z": 1,
      "name": "Rock_Stone"
    },
    {
      "x": -19,
      "y": 8,
      "z": 2,
      "name": "Rock_Stone"
    },
    {
      "x": -19,
      "y": 9,
      "z": 2,
      "name": "Rock_Stone"
    },
    {
      "x": -19,
      "y": 10,
      "z": 2,
      "name": "Rock_Stone"
    },
    {
      "x": -19,
      "y": 11,
      "z": 2,
      "name": "Rock_Stone"
    },
    {
      "x": -19,
      "y": 12,
      "z": 2,
      "name": "Rock_Stone"
    },
    {
      "x": -19,
      "y": 13,
      "z": 2,
      "name": "Rock_Stone"
    },
    {
      "x": -19,
      "y": 14,
      "z": 2,
      "name": "Rock_Stone"
    },
    {
      "x": -19,
      "y": 15,
      "z": 2,
      "name": "Rock_Stone"
    },
    {
      "x": -19,
      "y": 16,
      "z": 2,
      "name": "Rock_Stone"
    },
    {
      "x": -19,
      "y": 17,
      "z": 2,
      "name": "Rock_Stone"
    },
    {
      "x": -19,
      "y": 18,
      "z": 2,
      "name": "Soil_Grass"
    },
    {
      "x": -19,
      "y": 8,
      "z": 3,
      "name": "Rock_Stone"
    },
    {
      "x": -19,
      "y": 9,
      "z": 3,
      "name": "Rock_Stone"
    },
    {
      "x": -19,
      "y": 10,
      "z": 3,
      "name": "Rock_Stone"
    },
    {
      "x": -19,
      "y": 11,
      "z": 3,
      "name": "Rock_Stone"
    },
    {
      "x": -19,
      "y": 12,
      "z": 3,
      "name": "Rock_Stone"
    },
    {
      "x": -19,
      "y": 13,
      "z": 3,
      "name": "Rock_Stone"
    },
    {
      "x": -19,
      "y": 14,
      "z": 3,
      "name": "Rock_Stone"
    },
    {
      "x": -19,
      "y": 15,
      "z": 3,
      "name": "Rock_Stone"
    },
    {
      "x": -19,
      "y": 16,
      "z": 3,
      "name": "Rock_Stone"
    },
    {
      "x": -19,
      "y": 17,
      "z": 3,
      "name": "Soil_Dirt"
    },
    {
      "x": -19,
      "y": 18,
      "z": 3,
      "name": "Soil_Grass"
    },
    {
      "x": -19,
      "y": 19,
      "z": 3,
      "name": "Plant_Grass_Sharp"
    },
    {
      "x": -19,
      "y": 9,
      "z": 4,
      "name": "Rock_Stone"
    },
    {
      "x": -19,
      "y": 10,
      "z": 4,
      "name": "Rock_Stone"
    },
    {
      "x": -19,
      "y": 11,
      "z": 4,
      "name": "Rock_Stone"
    },
    {
      "x": -19,
      "y": 12,
      "z": 4,
      "name": "Rock_Stone"
    },
    {
      "x": -19,
      "y": 13,
      "z": 4,
      "name": "Rock_Stone"
    },
    {
      "x": -19,
      "y": 14,
      "z": 4,
      "name": "Rock_Stone"
    },
    {
      "x": -19,
      "y": 15,
      "z": 4,
      "name": "Rock_Stone"
    },
    {
      "x": -19,
      "y": 16,
      "z": 4,
      "name": "Rock_Stone"
    },
    {
      "x": -19,
      "y": 17,
      "z": 4,
      "name": "Soil_Dirt"
    },
    {
      "x": -19,
      "y": 18,
      "z": 4,
      "name": "Soil_Grass"
    },
    {
      "x": -19,
      "y": 9,
      "z": 5,
      "name": "Rock_Stone"
    },
    {
      "x": -19,
      "y": 10,
      "z": 5,
      "name": "Rock_Stone"
    },
    {
      "x": -19,
      "y": 11,
      "z": 5,
      "name": "Rock_Stone"
    },
    {
      "x": -19,
      "y": 12,
      "z": 5,
      "name": "Rock_Stone"
    },
    {
      "x": -19,
      "y": 13,
      "z": 5,
      "name": "Rock_Stone"
    },
    {
      "x": -19,
      "y": 14,
      "z": 5,
      "name": "Rock_Stone"
    },
    {
      "x": -19,
      "y": 15,
      "z": 5,
      "name": "Rock_Stone"
    },
    {
      "x": -19,
      "y": 16,
      "z": 5,
      "name": "Soil_Dirt"
    },
    {
      "x": -19,
      "y": 17,
      "z": 5,
      "name": "Soil_Grass"
    },
    {
      "x": -19,
      "y": 9,
      "z": 6,
      "name": "Rock_Stone"
    },
    {
      "x": -19,
      "y": 10,
      "z": 6,
      "name": "Rock_Stone"
    },
    {
      "x": -19,
      "y": 11,
      "z": 6,
      "name": "Rock_Stone"
    },
    {
      "x": -19,
      "y": 12,
      "z": 6,
      "name": "Rock_Stone"
    },
    {
      "x": -19,
      "y": 13,
      "z": 6,
      "name": "Rock_Stone"
    },
    {
      "x": -19,
      "y": 14,
      "z": 6,
      "name": "Rock_Stone"
    },
    {
      "x": -19,
      "y": 15,
      "z": 6,
      "name": "Rock_Stone"
    },
    {
      "x": -19,
      "y": 16,
      "z": 6,
      "name": "Soil_Dirt"
    },
    {
      "x": -19,
      "y": 17,
      "z": 6,
      "name": "Soil_Grass"
    },
    {
      "x": -19,
      "y": 9,
      "z": 7,
      "name": "Rock_Stone"
    },
    {
      "x": -19,
      "y": 10,
      "z": 7,
      "name": "Rock_Stone"
    },
    {
      "x": -19,
      "y": 11,
      "z": 7,
      "name": "Rock_Stone"
    },
    {
      "x": -19,
      "y": 12,
      "z": 7,
      "name": "Rock_Stone"
    },
    {
      "x": -19,
      "y": 13,
      "z": 7,
      "name": "Rock_Stone"
    },
    {
      "x": -19,
      "y": 14,
      "z": 7,
      "name": "Rock_Stone"
    },
    {
      "x": -19,
      "y": 15,
      "z": 7,
      "name": "Rock_Stone"
    },
    {
      "x": -19,
      "y": 16,
      "z": 7,
      "name": "Soil_Dirt"
    },
    {
      "x": -19,
      "y": 17,
      "z": 7,
      "name": "Soil_Grass"
    },
    {
      "x": -19,
      "y": 18,
      "z": 7,
      "name": "Plant_Flower_Bushy_Green"
    },
    {
      "x": -19,
      "y": 9,
      "z": 8,
      "name": "Rock_Stone"
    },
    {
      "x": -19,
      "y": 10,
      "z": 8,
      "name": "Rock_Stone"
    },
    {
      "x": -19,
      "y": 11,
      "z": 8,
      "name": "Rock_Stone"
    },
    {
      "x": -19,
      "y": 12,
      "z": 8,
      "name": "Rock_Stone"
    },
    {
      "x": -19,
      "y": 13,
      "z": 8,
      "name": "Rock_Stone"
    },
    {
      "x": -19,
      "y": 14,
      "z": 8,
      "name": "Rock_Stone"
    },
    {
      "x": -19,
      "y": 15,
      "z": 8,
      "name": "Rock_Stone"
    },
    {
      "x": -19,
      "y": 16,
      "z": 8,
      "name": "Rock_Stone"
    },
    {
      "x": -19,
      "y": 17,
      "z": 8,
      "name": "Soil_Dirt"
    },
    {
      "x": -19,
      "y": 18,
      "z": 8,
      "name": "Soil_Grass"
    },
    {
      "x": -19,
      "y": 19,
      "z": 8,
      "name": "Plant_Flower_Bushy_Green"
    },
    {
      "x": -19,
      "y": 8,
      "z": 9,
      "name": "Rock_Stone"
    },
    {
      "x": -19,
      "y": 9,
      "z": 9,
      "name": "Rock_Stone"
    },
    {
      "x": -19,
      "y": 10,
      "z": 9,
      "name": "Rock_Stone"
    },
    {
      "x": -19,
      "y": 11,
      "z": 9,
      "name": "Rock_Stone"
    },
    {
      "x": -19,
      "y": 12,
      "z": 9,
      "name": "Rock_Stone"
    },
    {
      "x": -19,
      "y": 13,
      "z": 9,
      "name": "Rock_Stone"
    },
    {
      "x": -19,
      "y": 14,
      "z": 9,
      "name": "Rock_Stone"
    },
    {
      "x": -19,
      "y": 15,
      "z": 9,
      "name": "Rock_Stone"
    },
    {
      "x": -19,
      "y": 16,
      "z": 9,
      "name": "Rock_Stone"
    },
    {
      "x": -19,
      "y": 17,
      "z": 9,
      "name": "Rock_Stone"
    },
    {
      "x": -19,
      "y": 18,
      "z": 9,
      "name": "Soil_Grass"
    },
    {
      "x": -19,
      "y": 7,
      "z": 10,
      "name": "Rock_Stone"
    },
    {
      "x": -19,
      "y": 8,
      "z": 10,
      "name": "Rock_Stone"
    },
    {
      "x": -19,
      "y": 9,
      "z": 10,
      "name": "Rock_Stone"
    },
    {
      "x": -19,
      "y": 10,
      "z": 10,
      "name": "Rock_Stone"
    },
    {
      "x": -19,
      "y": 11,
      "z": 10,
      "name": "Rock_Stone"
    },
    {
      "x": -19,
      "y": 12,
      "z": 10,
      "name": "Rock_Stone"
    },
    {
      "x": -19,
      "y": 13,
      "z": 10,
      "name": "Rock_Stone"
    },
    {
      "x": -19,
      "y": 14,
      "z": 10,
      "name": "Rock_Stone"
    },
    {
      "x": -19,
      "y": 15,
      "z": 10,
      "name": "Rock_Stone"
    },
    {
      "x": -19,
      "y": 16,
      "z": 10,
      "name": "Rock_Stone"
    },
    {
      "x": -19,
      "y": 17,
      "z": 10,
      "name": "Rock_Stone"
    },
    {
      "x": -19,
      "y": 18,
      "z": 10,
      "name": "Soil_Grass"
    },
    {
      "x": -19,
      "y": 19,
      "z": 10,
      "name": "Plant_Grass_Sharp"
    },
    {
      "x": -19,
      "y": 6,
      "z": 11,
      "name": "Rock_Stone"
    },
    {
      "x": -19,
      "y": 7,
      "z": 11,
      "name": "Rock_Stone"
    },
    {
      "x": -19,
      "y": 8,
      "z": 11,
      "name": "Rock_Stone"
    },
    {
      "x": -19,
      "y": 9,
      "z": 11,
      "name": "Rock_Stone"
    },
    {
      "x": -19,
      "y": 10,
      "z": 11,
      "name": "Rock_Stone"
    },
    {
      "x": -19,
      "y": 11,
      "z": 11,
      "name": "Rock_Stone"
    },
    {
      "x": -19,
      "y": 12,
      "z": 11,
      "name": "Rock_Stone"
    },
    {
      "x": -19,
      "y": 13,
      "z": 11,
      "name": "Rock_Stone"
    },
    {
      "x": -19,
      "y": 14,
      "z": 11,
      "name": "Rock_Stone"
    },
    {
      "x": -19,
      "y": 15,
      "z": 11,
      "name": "Rock_Stone"
    },
    {
      "x": -19,
      "y": 16,
      "z": 11,
      "name": "Rock_Stone"
    },
    {
      "x": -19,
      "y": 17,
      "z": 11,
      "name": "Rock_Stone"
    },
    {
      "x": -19,
      "y": 18,
      "z": 11,
      "name": "Soil_Dirt"
    },
    {
      "x": -19,
      "y": 19,
      "z": 11,
      "name": "Rock_Stone"
    },
    {
      "x": -19,
      "y": 5,
      "z": 12,
      "name": "Rock_Stone"
    },
    {
      "x": -19,
      "y": 6,
      "z": 12,
      "name": "Rock_Stone"
    },
    {
      "x": -19,
      "y": 7,
      "z": 12,
      "name": "Rock_Stone"
    },
    {
      "x": -19,
      "y": 8,
      "z": 12,
      "name": "Rock_Stone"
    },
    {
      "x": -19,
      "y": 9,
      "z": 12,
      "name": "Rock_Stone"
    },
    {
      "x": -19,
      "y": 10,
      "z": 12,
      "name": "Rock_Stone"
    },
    {
      "x": -19,
      "y": 11,
      "z": 12,
      "name": "Rock_Stone"
    },
    {
      "x": -19,
      "y": 12,
      "z": 12,
      "name": "Rock_Stone"
    },
    {
      "x": -19,
      "y": 13,
      "z": 12,
      "name": "Rock_Stone"
    },
    {
      "x": -19,
      "y": 14,
      "z": 12,
      "name": "Rock_Stone"
    },
    {
      "x": -19,
      "y": 15,
      "z": 12,
      "name": "Rock_Stone"
    },
    {
      "x": -19,
      "y": 16,
      "z": 12,
      "name": "Rock_Stone"
    },
    {
      "x": -19,
      "y": 17,
      "z": 12,
      "name": "Rock_Stone"
    },
    {
      "x": -19,
      "y": 18,
      "z": 12,
      "name": "Rock_Stone"
    },
    {
      "x": -19,
      "y": 19,
      "z": 12,
      "name": "Rock_Stone"
    },
    {
      "x": -19,
      "y": 20,
      "z": 12,
      "name": "Rock_Stone"
    },
    {
      "x": -19,
      "y": 5,
      "z": 13,
      "name": "Rock_Stone"
    },
    {
      "x": -19,
      "y": 6,
      "z": 13,
      "name": "Rock_Stone"
    },
    {
      "x": -19,
      "y": 7,
      "z": 13,
      "name": "Rock_Stone"
    },
    {
      "x": -19,
      "y": 8,
      "z": 13,
      "name": "Rock_Stone"
    },
    {
      "x": -19,
      "y": 9,
      "z": 13,
      "name": "Rock_Stone"
    },
    {
      "x": -19,
      "y": 10,
      "z": 13,
      "name": "Rock_Stone"
    },
    {
      "x": -19,
      "y": 11,
      "z": 13,
      "name": "Rock_Stone"
    },
    {
      "x": -19,
      "y": 12,
      "z": 13,
      "name": "Rock_Stone"
    },
    {
      "x": -19,
      "y": 13,
      "z": 13,
      "name": "Rock_Stone"
    },
    {
      "x": -19,
      "y": 14,
      "z": 13,
      "name": "Rock_Stone"
    },
    {
      "x": -19,
      "y": 15,
      "z": 13,
      "name": "Rock_Stone"
    },
    {
      "x": -19,
      "y": 16,
      "z": 13,
      "name": "Rock_Stone"
    },
    {
      "x": -19,
      "y": 17,
      "z": 13,
      "name": "Rock_Stone"
    },
    {
      "x": -19,
      "y": 18,
      "z": 13,
      "name": "Rock_Stone"
    },
    {
      "x": -19,
      "y": 19,
      "z": 13,
      "name": "Rock_Stone"
    },
    {
      "x": -19,
      "y": 20,
      "z": 13,
      "name": "Rock_Stone"
    },
    {
      "x": -19,
      "y": 6,
      "z": 14,
      "name": "Rock_Stone"
    },
    {
      "x": -19,
      "y": 7,
      "z": 14,
      "name": "Rock_Stone"
    },
    {
      "x": -19,
      "y": 8,
      "z": 14,
      "name": "Rock_Stone"
    },
    {
      "x": -19,
      "y": 9,
      "z": 14,
      "name": "Rock_Stone"
    },
    {
      "x": -19,
      "y": 10,
      "z": 14,
      "name": "Rock_Stone"
    },
    {
      "x": -19,
      "y": 11,
      "z": 14,
      "name": "Rock_Stone"
    },
    {
      "x": -19,
      "y": 12,
      "z": 14,
      "name": "Rock_Stone"
    },
    {
      "x": -19,
      "y": 13,
      "z": 14,
      "name": "Rock_Stone"
    },
    {
      "x": -19,
      "y": 14,
      "z": 14,
      "name": "Rock_Stone"
    },
    {
      "x": -19,
      "y": 15,
      "z": 14,
      "name": "Rock_Stone"
    },
    {
      "x": -19,
      "y": 16,
      "z": 14,
      "name": "Rock_Stone"
    },
    {
      "x": -19,
      "y": 17,
      "z": 14,
      "name": "Rock_Stone"
    },
    {
      "x": -19,
      "y": 18,
      "z": 14,
      "name": "Rock_Stone"
    },
    {
      "x": -19,
      "y": 19,
      "z": 14,
      "name": "Rock_Stone"
    },
    {
      "x": -19,
      "y": 20,
      "z": 14,
      "name": "Rock_Stone"
    },
    {
      "x": -19,
      "y": 6,
      "z": 15,
      "name": "Rock_Stone"
    },
    {
      "x": -19,
      "y": 7,
      "z": 15,
      "name": "Rock_Stone"
    },
    {
      "x": -19,
      "y": 8,
      "z": 15,
      "name": "Rock_Stone"
    },
    {
      "x": -19,
      "y": 9,
      "z": 15,
      "name": "Rock_Stone"
    },
    {
      "x": -19,
      "y": 10,
      "z": 15,
      "name": "Rock_Stone"
    },
    {
      "x": -19,
      "y": 11,
      "z": 15,
      "name": "Rock_Stone"
    },
    {
      "x": -19,
      "y": 12,
      "z": 15,
      "name": "Rock_Stone"
    },
    {
      "x": -19,
      "y": 13,
      "z": 15,
      "name": "Rock_Stone"
    },
    {
      "x": -19,
      "y": 14,
      "z": 15,
      "name": "Rock_Stone"
    },
    {
      "x": -19,
      "y": 15,
      "z": 15,
      "name": "Rock_Stone"
    },
    {
      "x": -19,
      "y": 16,
      "z": 15,
      "name": "Rock_Stone"
    },
    {
      "x": -19,
      "y": 17,
      "z": 15,
      "name": "Rock_Stone"
    },
    {
      "x": -19,
      "y": 7,
      "z": 16,
      "name": "Rock_Stone"
    },
    {
      "x": -19,
      "y": 8,
      "z": 16,
      "name": "Rock_Stone"
    },
    {
      "x": -19,
      "y": 9,
      "z": 16,
      "name": "Rock_Stone"
    },
    {
      "x": -19,
      "y": 10,
      "z": 16,
      "name": "Rock_Stone"
    },
    {
      "x": -19,
      "y": 11,
      "z": 16,
      "name": "Rock_Stone"
    },
    {
      "x": -19,
      "y": 12,
      "z": 16,
      "name": "Rock_Stone"
    },
    {
      "x": -19,
      "y": 13,
      "z": 16,
      "name": "Rock_Stone"
    },
    {
      "x": -19,
      "y": 14,
      "z": 16,
      "name": "Rock_Stone"
    },
    {
      "x": -19,
      "y": 8,
      "z": 17,
      "name": "Rock_Stone"
    },
    {
      "x": -19,
      "y": 9,
      "z": 17,
      "name": "Rock_Stone"
    },
    {
      "x": -19,
      "y": 10,
      "z": 17,
      "name": "Rock_Stone"
    },
    {
      "x": -19,
      "y": 11,
      "z": 17,
      "name": "Rock_Stone"
    },
    {
      "x": -18,
      "y": 24,
      "z": -14,
      "name": "Plant_Leaves_Beech",
      "support": 1
    },
    {
      "x": -18,
      "y": 25,
      "z": -13,
      "name": "Plant_Leaves_Beech",
      "support": 1
    },
    {
      "x": -18,
      "y": 20,
      "z": -12,
      "name": "Plant_Leaves_Beech",
      "support": 1
    },
    {
      "x": -18,
      "y": 27,
      "z": -12,
      "name": "Plant_Leaves_Beech",
      "support": 1
    },
    {
      "x": -18,
      "y": 28,
      "z": -12,
      "name": "Plant_Leaves_Beech",
      "support": 2
    },
    {
      "x": -18,
      "y": 20,
      "z": -11,
      "name": "Plant_Leaves_Beech"
    },
    {
      "x": -18,
      "y": 21,
      "z": -11,
      "name": "Plant_Leaves_Beech",
      "support": 1
    },
    {
      "x": -18,
      "y": 24,
      "z": -11,
      "name": "Wood_Beech_Branch_Long",
      "rotation": 5
    },
    {
      "x": -18,
      "y": 27,
      "z": -11,
      "name": "Plant_Leaves_Beech"
    },
    {
      "x": -18,
      "y": 28,
      "z": -11,
      "name": "Plant_Leaves_Beech",
      "support": 1
    },
    {
      "x": -18,
      "y": 29,
      "z": -11,
      "name": "Plant_Leaves_Beech",
      "support": 1
    },
    {
      "x": -18,
      "y": 30,
      "z": -11,
      "name": "Plant_Leaves_Beech",
      "support": 2
    },
    {
      "x": -18,
      "y": 20,
      "z": -10,
      "name": "Plant_Leaves_Beech",
      "support": 1
    },
    {
      "x": -18,
      "y": 27,
      "z": -10,
      "name": "Plant_Leaves_Beech",
      "support": 1
    },
    {
      "x": -18,
      "y": 29,
      "z": -10,
      "name": "Plant_Leaves_Beech",
      "support": 2
    },
    {
      "x": -18,
      "y": 11,
      "z": -9,
      "name": "Rock_Stone"
    },
    {
      "x": -18,
      "y": 12,
      "z": -9,
      "name": "Rock_Stone"
    },
    {
      "x": -18,
      "y": 13,
      "z": -9,
      "name": "Soil_Dirt"
    },
    {
      "x": -18,
      "y": 14,
      "z": -9,
      "name": "Soil_Grass"
    },
    {
      "x": -18,
      "y": 9,
      "z": -8,
      "name": "Rock_Stone"
    },
    {
      "x": -18,
      "y": 10,
      "z": -8,
      "name": "Rock_Stone"
    },
    {
      "x": -18,
      "y": 11,
      "z": -8,
      "name": "Rock_Stone"
    },
    {
      "x": -18,
      "y": 12,
      "z": -8,
      "name": "Rock_Stone"
    },
    {
      "x": -18,
      "y": 13,
      "z": -8,
      "name": "Rock_Stone"
    },
    {
      "x": -18,
      "y": 14,
      "z": -8,
      "name": "Rock_Stone"
    },
    {
      "x": -18,
      "y": 15,
      "z": -8,
      "name": "Soil_Dirt"
    },
    {
      "x": -18,
      "y": 16,
      "z": -8,
      "name": "Soil_Grass"
    },
    {
      "x": -18,
      "y": 23,
      "z": -8,
      "name": "Plant_Leaves_Beech",
      "support": 2
    },
    {
      "x": -18,
      "y": 24,
      "z": -8,
      "name": "Plant_Leaves_Beech",
      "support": 1
    },
    {
      "x": -18,
      "y": 25,
      "z": -8,
      "name": "Plant_Leaves_Beech",
      "support": 2
    },
    {
      "x": -18,
      "y": 9,
      "z": -7,
      "name": "Rock_Stone"
    },
    {
      "x": -18,
      "y": 10,
      "z": -7,
      "name": "Rock_Stone"
    },
    {
      "x": -18,
      "y": 11,
      "z": -7,
      "name": "Rock_Stone"
    },
    {
      "x": -18,
      "y": 12,
      "z": -7,
      "name": "Rock_Stone"
    },
    {
      "x": -18,
      "y": 13,
      "z": -7,
      "name": "Rock_Stone"
    },
    {
      "x": -18,
      "y": 14,
      "z": -7,
      "name": "Rock_Stone"
    },
    {
      "x": -18,
      "y": 15,
      "z": -7,
      "name": "Rock_Stone"
    },
    {
      "x": -18,
      "y": 16,
      "z": -7,
      "name": "Rock_Stone"
    },
    {
      "x": -18,
      "y": 17,
      "z": -7,
      "name": "Soil_Dirt"
    },
    {
      "x": -18,
      "y": 18,
      "z": -7,
      "name": "Soil_Grass"
    },
    {
      "x": -18,
      "y": 23,
      "z": -7,
      "name": "Plant_Leaves_Beech",
      "support": 3
    },
    {
      "x": -18,
      "y": 24,
      "z": -7,
      "name": "Plant_Leaves_Beech",
      "support": 2
    },
    {
      "x": -18,
      "y": 9,
      "z": -6,
      "name": "Rock_Stone"
    },
    {
      "x": -18,
      "y": 10,
      "z": -6,
      "name": "Rock_Stone"
    },
    {
      "x": -18,
      "y": 11,
      "z": -6,
      "name": "Rock_Stone"
    },
    {
      "x": -18,
      "y": 12,
      "z": -6,
      "name": "Rock_Stone"
    },
    {
      "x": -18,
      "y": 13,
      "z": -6,
      "name": "Rock_Stone"
    },
    {
      "x": -18,
      "y": 14,
      "z": -6,
      "name": "Rock_Stone"
    },
    {
      "x": -18,
      "y": 15,
      "z": -6,
      "name": "Rock_Stone"
    },
    {
      "x": -18,
      "y": 16,
      "z": -6,
      "name": "Rock_Stone"
    },
    {
      "x": -18,
      "y": 17,
      "z": -6,
      "name": "Rock_Stone"
    },
    {
      "x": -18,
      "y": 18,
      "z": -6,
      "name": "Rock_Stone"
    },
    {
      "x": -18,
      "y": 19,
      "z": -6,
      "name": "Rock_Stone"
    },
    {
      "x": -18,
      "y": 8,
      "z": -5,
      "name": "Rock_Stone"
    },
    {
      "x": -18,
      "y": 9,
      "z": -5,
      "name": "Rock_Stone"
    },
    {
      "x": -18,
      "y": 10,
      "z": -5,
      "name": "Rock_Stone"
    },
    {
      "x": -18,
      "y": 11,
      "z": -5,
      "name": "Rock_Stone"
    },
    {
      "x": -18,
      "y": 12,
      "z": -5,
      "name": "Rock_Stone"
    },
    {
      "x": -18,
      "y": 13,
      "z": -5,
      "name": "Rock_Stone"
    },
    {
      "x": -18,
      "y": 14,
      "z": -5,
      "name": "Rock_Stone"
    },
    {
      "x": -18,
      "y": 15,
      "z": -5,
      "name": "Rock_Stone"
    },
    {
      "x": -18,
      "y": 16,
      "z": -5,
      "name": "Rock_Stone"
    },
    {
      "x": -18,
      "y": 17,
      "z": -5,
      "name": "Rock_Stone"
    },
    {
      "x": -18,
      "y": 18,
      "z": -5,
      "name": "Rock_Stone"
    },
    {
      "x": -18,
      "y": 19,
      "z": -5,
      "name": "Rock_Stone"
    },
    {
      "x": -18,
      "y": 20,
      "z": -5,
      "name": "Rock_Stone"
    },
    {
      "x": -18,
      "y": 21,
      "z": -5,
      "name": "Rock_Stone"
    },
    {
      "x": -18,
      "y": 8,
      "z": -4,
      "name": "Rock_Stone"
    },
    {
      "x": -18,
      "y": 9,
      "z": -4,
      "name": "Rock_Stone"
    },
    {
      "x": -18,
      "y": 10,
      "z": -4,
      "name": "Rock_Stone"
    },
    {
      "x": -18,
      "y": 11,
      "z": -4,
      "name": "Rock_Stone"
    },
    {
      "x": -18,
      "y": 12,
      "z": -4,
      "name": "Rock_Stone"
    },
    {
      "x": -18,
      "y": 13,
      "z": -4,
      "name": "Rock_Stone"
    },
    {
      "x": -18,
      "y": 14,
      "z": -4,
      "name": "Rock_Stone"
    },
    {
      "x": -18,
      "y": 15,
      "z": -4,
      "name": "Rock_Stone"
    },
    {
      "x": -18,
      "y": 16,
      "z": -4,
      "name": "Rock_Stone"
    },
    {
      "x": -18,
      "y": 17,
      "z": -4,
      "name": "Rock_Stone"
    },
    {
      "x": -18,
      "y": 18,
      "z": -4,
      "name": "Rock_Stone"
    },
    {
      "x": -18,
      "y": 19,
      "z": -4,
      "name": "Rock_Stone"
    },
    {
      "x": -18,
      "y": 20,
      "z": -4,
      "name": "Rock_Stone"
    },
    {
      "x": -18,
      "y": 21,
      "z": -4,
      "name": "Rock_Stone"
    },
    {
      "x": -18,
      "y": 22,
      "z": -4,
      "name": "Rock_Stone"
    },
    {
      "x": -18,
      "y": 8,
      "z": -3,
      "name": "Rock_Stone"
    },
    {
      "x": -18,
      "y": 9,
      "z": -3,
      "name": "Rock_Stone"
    },
    {
      "x": -18,
      "y": 10,
      "z": -3,
      "name": "Rock_Stone"
    },
    {
      "x": -18,
      "y": 11,
      "z": -3,
      "name": "Rock_Stone"
    },
    {
      "x": -18,
      "y": 12,
      "z": -3,
      "name": "Rock_Stone"
    },
    {
      "x": -18,
      "y": 13,
      "z": -3,
      "name": "Rock_Stone"
    },
    {
      "x": -18,
      "y": 14,
      "z": -3,
      "name": "Rock_Stone"
    },
    {
      "x": -18,
      "y": 15,
      "z": -3,
      "name": "Rock_Stone"
    },
    {
      "x": -18,
      "y": 16,
      "z": -3,
      "name": "Rock_Stone"
    },
    {
      "x": -18,
      "y": 17,
      "z": -3,
      "name": "Rock_Stone"
    },
    {
      "x": -18,
      "y": 18,
      "z": -3,
      "name": "Rock_Stone"
    },
    {
      "x": -18,
      "y": 19,
      "z": -3,
      "name": "Rock_Stone"
    },
    {
      "x": -18,
      "y": 20,
      "z": -3,
      "name": "Rock_Stone"
    },
    {
      "x": -18,
      "y": 21,
      "z": -3,
      "name": "Rock_Stone"
    },
    {
      "x": -18,
      "y": 22,
      "z": -3,
      "name": "Rock_Stone"
    },
    {
      "x": -18,
      "y": 23,
      "z": -3,
      "name": "Rock_Stone"
    },
    {
      "x": -18,
      "y": 7,
      "z": -2,
      "name": "Rock_Stone"
    },
    {
      "x": -18,
      "y": 8,
      "z": -2,
      "name": "Rock_Stone"
    },
    {
      "x": -18,
      "y": 9,
      "z": -2,
      "name": "Rock_Stone"
    },
    {
      "x": -18,
      "y": 10,
      "z": -2,
      "name": "Rock_Stone"
    },
    {
      "x": -18,
      "y": 11,
      "z": -2,
      "name": "Rock_Stone"
    },
    {
      "x": -18,
      "y": 12,
      "z": -2,
      "name": "Rock_Stone"
    },
    {
      "x": -18,
      "y": 13,
      "z": -2,
      "name": "Rock_Stone"
    },
    {
      "x": -18,
      "y": 14,
      "z": -2,
      "name": "Rock_Stone"
    },
    {
      "x": -18,
      "y": 15,
      "z": -2,
      "name": "Rock_Stone"
    },
    {
      "x": -18,
      "y": 16,
      "z": -2,
      "name": "Rock_Stone"
    },
    {
      "x": -18,
      "y": 17,
      "z": -2,
      "name": "Rock_Stone"
    },
    {
      "x": -18,
      "y": 18,
      "z": -2,
      "name": "Rock_Stone"
    },
    {
      "x": -18,
      "y": 19,
      "z": -2,
      "name": "Rock_Stone"
    },
    {
      "x": -18,
      "y": 20,
      "z": -2,
      "name": "Rock_Stone"
    },
    {
      "x": -18,
      "y": 21,
      "z": -2,
      "name": "Rock_Stone"
    },
    {
      "x": -18,
      "y": 22,
      "z": -2,
      "name": "Rock_Stone"
    },
    {
      "x": -18,
      "y": 23,
      "z": -2,
      "name": "Rock_Stone"
    },
    {
      "x": -18,
      "y": 24,
      "z": -2,
      "name": "Rock_Stone"
    },
    {
      "x": -18,
      "y": 7,
      "z": -1,
      "name": "Rock_Stone"
    },
    {
      "x": -18,
      "y": 8,
      "z": -1,
      "name": "Rock_Stone"
    },
    {
      "x": -18,
      "y": 9,
      "z": -1,
      "name": "Rock_Stone"
    },
    {
      "x": -18,
      "y": 10,
      "z": -1,
      "name": "Rock_Stone"
    },
    {
      "x": -18,
      "y": 11,
      "z": -1,
      "name": "Rock_Stone"
    },
    {
      "x": -18,
      "y": 12,
      "z": -1,
      "name": "Rock_Stone"
    },
    {
      "x": -18,
      "y": 13,
      "z": -1,
      "name": "Rock_Stone"
    },
    {
      "x": -18,
      "y": 14,
      "z": -1,
      "name": "Rock_Stone"
    },
    {
      "x": -18,
      "y": 15,
      "z": -1,
      "name": "Rock_Stone"
    },
    {
      "x": -18,
      "y": 16,
      "z": -1,
      "name": "Rock_Stone"
    },
    {
      "x": -18,
      "y": 17,
      "z": -1,
      "name": "Rock_Stone"
    },
    {
      "x": -18,
      "y": 18,
      "z": -1,
      "name": "Rock_Stone"
    },
    {
      "x": -18,
      "y": 19,
      "z": -1,
      "name": "Rock_Stone"
    },
    {
      "x": -18,
      "y": 20,
      "z": -1,
      "name": "Rock_Stone"
    },
    {
      "x": -18,
      "y": 21,
      "z": -1,
      "name": "Rock_Stone"
    },
    {
      "x": -18,
      "y": 22,
      "z": -1,
      "name": "Rock_Stone"
    },
    {
      "x": -18,
      "y": 23,
      "z": -1,
      "name": "Rock_Stone"
    },
    {
      "x": -18,
      "y": 24,
      "z": -1,
      "name": "Rock_Stone"
    },
    {
      "x": -18,
      "y": 7,
      "z": 0,
      "name": "Rock_Stone"
    },
    {
      "x": -18,
      "y": 8,
      "z": 0,
      "name": "Rock_Stone"
    },
    {
      "x": -18,
      "y": 9,
      "z": 0,
      "name": "Rock_Stone"
    },
    {
      "x": -18,
      "y": 10,
      "z": 0,
      "name": "Rock_Stone"
    },
    {
      "x": -18,
      "y": 11,
      "z": 0,
      "name": "Rock_Stone"
    },
    {
      "x": -18,
      "y": 12,
      "z": 0,
      "name": "Rock_Stone"
    },
    {
      "x": -18,
      "y": 13,
      "z": 0,
      "name": "Rock_Stone"
    },
    {
      "x": -18,
      "y": 14,
      "z": 0,
      "name": "Rock_Stone"
    },
    {
      "x": -18,
      "y": 15,
      "z": 0,
      "name": "Rock_Stone"
    },
    {
      "x": -18,
      "y": 16,
      "z": 0,
      "name": "Rock_Stone"
    },
    {
      "x": -18,
      "y": 17,
      "z": 0,
      "name": "Rock_Stone"
    },
    {
      "x": -18,
      "y": 18,
      "z": 0,
      "name": "Rock_Stone"
    },
    {
      "x": -18,
      "y": 19,
      "z": 0,
      "name": "Rock_Stone"
    },
    {
      "x": -18,
      "y": 20,
      "z": 0,
      "name": "Rock_Stone"
    },
    {
      "x": -18,
      "y": 21,
      "z": 0,
      "name": "Rock_Stone"
    },
    {
      "x": -18,
      "y": 22,
      "z": 0,
      "name": "Rock_Stone"
    },
    {
      "x": -18,
      "y": 7,
      "z": 1,
      "name": "Rock_Stone"
    },
    {
      "x": -18,
      "y": 8,
      "z": 1,
      "name": "Rock_Stone"
    },
    {
      "x": -18,
      "y": 9,
      "z": 1,
      "name": "Rock_Stone"
    },
    {
      "x": -18,
      "y": 10,
      "z": 1,
      "name": "Rock_Stone"
    },
    {
      "x": -18,
      "y": 11,
      "z": 1,
      "name": "Rock_Stone"
    },
    {
      "x": -18,
      "y": 12,
      "z": 1,
      "name": "Rock_Stone"
    },
    {
      "x": -18,
      "y": 13,
      "z": 1,
      "name": "Rock_Stone"
    },
    {
      "x": -18,
      "y": 14,
      "z": 1,
      "name": "Rock_Stone"
    },
    {
      "x": -18,
      "y": 15,
      "z": 1,
      "name": "Rock_Stone"
    },
    {
      "x": -18,
      "y": 16,
      "z": 1,
      "name": "Rock_Stone"
    },
    {
      "x": -18,
      "y": 17,
      "z": 1,
      "name": "Rock_Stone"
    },
    {
      "x": -18,
      "y": 18,
      "z": 1,
      "name": "Rock_Stone"
    },
    {
      "x": -18,
      "y": 19,
      "z": 1,
      "name": "Rock_Stone"
    },
    {
      "x": -18,
      "y": 20,
      "z": 1,
      "name": "Rock_Stone"
    },
    {
      "x": -18,
      "y": 7,
      "z": 2,
      "name": "Rock_Stone"
    },
    {
      "x": -18,
      "y": 8,
      "z": 2,
      "name": "Rock_Stone"
    },
    {
      "x": -18,
      "y": 9,
      "z": 2,
      "name": "Rock_Stone"
    },
    {
      "x": -18,
      "y": 10,
      "z": 2,
      "name": "Rock_Stone"
    },
    {
      "x": -18,
      "y": 11,
      "z": 2,
      "name": "Rock_Stone"
    },
    {
      "x": -18,
      "y": 12,
      "z": 2,
      "name": "Rock_Stone"
    },
    {
      "x": -18,
      "y": 13,
      "z": 2,
      "name": "Rock_Stone"
    },
    {
      "x": -18,
      "y": 14,
      "z": 2,
      "name": "Rock_Stone"
    },
    {
      "x": -18,
      "y": 15,
      "z": 2,
      "name": "Rock_Stone"
    },
    {
      "x": -18,
      "y": 16,
      "z": 2,
      "name": "Rock_Stone"
    },
    {
      "x": -18,
      "y": 17,
      "z": 2,
      "name": "Rock_Stone"
    },
    {
      "x": -18,
      "y": 18,
      "z": 2,
      "name": "Rock_Stone"
    },
    {
      "x": -18,
      "y": 19,
      "z": 2,
      "name": "Soil_Grass"
    },
    {
      "x": -18,
      "y": 20,
      "z": 2,
      "name": "Plant_Grass_Sharp"
    },
    {
      "x": -18,
      "y": 7,
      "z": 3,
      "name": "Rock_Stone"
    },
    {
      "x": -18,
      "y": 8,
      "z": 3,
      "name": "Rock_Stone"
    },
    {
      "x": -18,
      "y": 9,
      "z": 3,
      "name": "Rock_Stone"
    },
    {
      "x": -18,
      "y": 10,
      "z": 3,
      "name": "Rock_Stone"
    },
    {
      "x": -18,
      "y": 11,
      "z": 3,
      "name": "Rock_Stone"
    },
    {
      "x": -18,
      "y": 12,
      "z": 3,
      "name": "Rock_Stone"
    },
    {
      "x": -18,
      "y": 13,
      "z": 3,
      "name": "Rock_Stone"
    },
    {
      "x": -18,
      "y": 14,
      "z": 3,
      "name": "Rock_Stone"
    },
    {
      "x": -18,
      "y": 15,
      "z": 3,
      "name": "Rock_Stone"
    },
    {
      "x": -18,
      "y": 16,
      "z": 3,
      "name": "Rock_Stone"
    },
    {
      "x": -18,
      "y": 17,
      "z": 3,
      "name": "Rock_Stone"
    },
    {
      "x": -18,
      "y": 18,
      "z": 3,
      "name": "Rock_Stone"
    },
    {
      "x": -18,
      "y": 19,
      "z": 3,
      "name": "Soil_Grass"
    },
    {
      "x": -18,
      "y": 27,
      "z": 3,
      "name": "Deco_Rope"
    },
    {
      "x": -18,
      "y": 28,
      "z": 3,
      "name": "Deco_Rope"
    },
    {
      "x": -18,
      "y": 29,
      "z": 3,
      "name": "Deco_Rope"
    },
    {
      "x": -18,
      "y": 30,
      "z": 3,
      "name": "Wood_Oak_Trunk",
      "support": 15,
      "rotation": 5
    },
    {
      "x": -18,
      "y": 8,
      "z": 4,
      "name": "Rock_Stone"
    },
    {
      "x": -18,
      "y": 9,
      "z": 4,
      "name": "Rock_Stone"
    },
    {
      "x": -18,
      "y": 10,
      "z": 4,
      "name": "Rock_Stone"
    },
    {
      "x": -18,
      "y": 11,
      "z": 4,
      "name": "Rock_Stone"
    },
    {
      "x": -18,
      "y": 12,
      "z": 4,
      "name": "Rock_Stone"
    },
    {
      "x": -18,
      "y": 13,
      "z": 4,
      "name": "Rock_Stone"
    },
    {
      "x": -18,
      "y": 14,
      "z": 4,
      "name": "Rock_Stone"
    },
    {
      "x": -18,
      "y": 15,
      "z": 4,
      "name": "Rock_Stone"
    },
    {
      "x": -18,
      "y": 16,
      "z": 4,
      "name": "Rock_Stone"
    },
    {
      "x": -18,
      "y": 17,
      "z": 4,
      "name": "Rock_Stone"
    },
    {
      "x": -18,
      "y": 18,
      "z": 4,
      "name": "Soil_Grass"
    },
    {
      "x": -18,
      "y": 8,
      "z": 5,
      "name": "Rock_Stone"
    },
    {
      "x": -18,
      "y": 9,
      "z": 5,
      "name": "Rock_Stone"
    },
    {
      "x": -18,
      "y": 10,
      "z": 5,
      "name": "Rock_Stone"
    },
    {
      "x": -18,
      "y": 11,
      "z": 5,
      "name": "Rock_Stone"
    },
    {
      "x": -18,
      "y": 12,
      "z": 5,
      "name": "Rock_Stone"
    },
    {
      "x": -18,
      "y": 13,
      "z": 5,
      "name": "Rock_Stone"
    },
    {
      "x": -18,
      "y": 14,
      "z": 5,
      "name": "Rock_Stone"
    },
    {
      "x": -18,
      "y": 15,
      "z": 5,
      "name": "Rock_Stone"
    },
    {
      "x": -18,
      "y": 16,
      "z": 5,
      "name": "Rock_Stone"
    },
    {
      "x": -18,
      "y": 17,
      "z": 5,
      "name": "Rock_Stone"
    },
    {
      "x": -18,
      "y": 18,
      "z": 5,
      "name": "Soil_Grass"
    },
    {
      "x": -18,
      "y": 19,
      "z": 5,
      "name": "Plant_Flower_Common_Yellow"
    },
    {
      "x": -18,
      "y": 30,
      "z": 5,
      "name": "Furniture_Crude_Platform",
      "rotation": 1
    },
    {
      "x": -18,
      "y": 8,
      "z": 6,
      "name": "Rock_Stone"
    },
    {
      "x": -18,
      "y": 9,
      "z": 6,
      "name": "Rock_Stone"
    },
    {
      "x": -18,
      "y": 10,
      "z": 6,
      "name": "Rock_Stone"
    },
    {
      "x": -18,
      "y": 11,
      "z": 6,
      "name": "Rock_Stone"
    },
    {
      "x": -18,
      "y": 12,
      "z": 6,
      "name": "Rock_Stone"
    },
    {
      "x": -18,
      "y": 13,
      "z": 6,
      "name": "Rock_Stone"
    },
    {
      "x": -18,
      "y": 14,
      "z": 6,
      "name": "Rock_Stone"
    },
    {
      "x": -18,
      "y": 15,
      "z": 6,
      "name": "Rock_Stone"
    },
    {
      "x": -18,
      "y": 16,
      "z": 6,
      "name": "Rock_Stone"
    },
    {
      "x": -18,
      "y": 17,
      "z": 6,
      "name": "Rock_Stone"
    },
    {
      "x": -18,
      "y": 18,
      "z": 6,
      "name": "Soil_Grass"
    },
    {
      "x": -18,
      "y": 30,
      "z": 6,
      "name": "Furniture_Crude_Platform",
      "rotation": 1
    },
    {
      "x": -18,
      "y": 8,
      "z": 7,
      "name": "Rock_Stone"
    },
    {
      "x": -18,
      "y": 9,
      "z": 7,
      "name": "Rock_Stone"
    },
    {
      "x": -18,
      "y": 10,
      "z": 7,
      "name": "Rock_Stone"
    },
    {
      "x": -18,
      "y": 11,
      "z": 7,
      "name": "Rock_Stone"
    },
    {
      "x": -18,
      "y": 12,
      "z": 7,
      "name": "Rock_Stone"
    },
    {
      "x": -18,
      "y": 13,
      "z": 7,
      "name": "Rock_Stone"
    },
    {
      "x": -18,
      "y": 14,
      "z": 7,
      "name": "Rock_Stone"
    },
    {
      "x": -18,
      "y": 15,
      "z": 7,
      "name": "Rock_Stone"
    },
    {
      "x": -18,
      "y": 16,
      "z": 7,
      "name": "Rock_Stone"
    },
    {
      "x": -18,
      "y": 17,
      "z": 7,
      "name": "Soil_Clay_Black"
    },
    {
      "x": -18,
      "y": 18,
      "z": 7,
      "name": "Soil_Dirt"
    },
    {
      "x": -18,
      "y": 19,
      "z": 7,
      "name": "Soil_Grass"
    },
    {
      "x": -18,
      "y": 30,
      "z": 7,
      "name": "Furniture_Crude_Platform",
      "rotation": 1
    },
    {
      "x": -18,
      "y": 8,
      "z": 8,
      "name": "Rock_Stone"
    },
    {
      "x": -18,
      "y": 9,
      "z": 8,
      "name": "Rock_Stone"
    },
    {
      "x": -18,
      "y": 10,
      "z": 8,
      "name": "Rock_Stone"
    },
    {
      "x": -18,
      "y": 11,
      "z": 8,
      "name": "Rock_Stone"
    },
    {
      "x": -18,
      "y": 12,
      "z": 8,
      "name": "Rock_Stone"
    },
    {
      "x": -18,
      "y": 13,
      "z": 8,
      "name": "Rock_Stone"
    },
    {
      "x": -18,
      "y": 14,
      "z": 8,
      "name": "Rock_Stone"
    },
    {
      "x": -18,
      "y": 15,
      "z": 8,
      "name": "Rock_Stone"
    },
    {
      "x": -18,
      "y": 16,
      "z": 8,
      "name": "Rock_Stone"
    },
    {
      "x": -18,
      "y": 17,
      "z": 8,
      "name": "Rock_Stone"
    },
    {
      "x": -18,
      "y": 18,
      "z": 8,
      "name": "Rock_Stone"
    },
    {
      "x": -18,
      "y": 19,
      "z": 8,
      "name": "Soil_Grass"
    },
    {
      "x": -18,
      "y": 20,
      "z": 8,
      "name": "Plant_Grass_Sharp"
    },
    {
      "x": -18,
      "y": 28,
      "z": 8,
      "name": "Deco_Rope"
    },
    {
      "x": -18,
      "y": 29,
      "z": 8,
      "name": "Deco_Rope"
    },
    {
      "x": -18,
      "y": 30,
      "z": 8,
      "name": "Wood_Oak_Trunk",
      "support": 15,
      "rotation": 5
    },
    {
      "x": -18,
      "y": 7,
      "z": 9,
      "name": "Rock_Stone"
    },
    {
      "x": -18,
      "y": 8,
      "z": 9,
      "name": "Rock_Stone"
    },
    {
      "x": -18,
      "y": 9,
      "z": 9,
      "name": "Rock_Stone"
    },
    {
      "x": -18,
      "y": 10,
      "z": 9,
      "name": "Rock_Stone"
    },
    {
      "x": -18,
      "y": 11,
      "z": 9,
      "name": "Rock_Stone"
    },
    {
      "x": -18,
      "y": 12,
      "z": 9,
      "name": "Rock_Stone"
    },
    {
      "x": -18,
      "y": 13,
      "z": 9,
      "name": "Rock_Stone"
    },
    {
      "x": -18,
      "y": 14,
      "z": 9,
      "name": "Rock_Stone"
    },
    {
      "x": -18,
      "y": 15,
      "z": 9,
      "name": "Rock_Stone"
    },
    {
      "x": -18,
      "y": 16,
      "z": 9,
      "name": "Rock_Stone"
    },
    {
      "x": -18,
      "y": 17,
      "z": 9,
      "name": "Rock_Stone"
    },
    {
      "x": -18,
      "y": 18,
      "z": 9,
      "name": "Rock_Stone"
    },
    {
      "x": -18,
      "y": 19,
      "z": 9,
      "name": "Soil_Grass"
    },
    {
      "x": -18,
      "y": 6,
      "z": 10,
      "name": "Rock_Stone"
    },
    {
      "x": -18,
      "y": 7,
      "z": 10,
      "name": "Rock_Stone"
    },
    {
      "x": -18,
      "y": 8,
      "z": 10,
      "name": "Rock_Stone"
    },
    {
      "x": -18,
      "y": 9,
      "z": 10,
      "name": "Rock_Stone"
    },
    {
      "x": -18,
      "y": 10,
      "z": 10,
      "name": "Rock_Stone"
    },
    {
      "x": -18,
      "y": 11,
      "z": 10,
      "name": "Rock_Stone"
    },
    {
      "x": -18,
      "y": 12,
      "z": 10,
      "name": "Rock_Stone"
    },
    {
      "x": -18,
      "y": 13,
      "z": 10,
      "name": "Rock_Stone"
    },
    {
      "x": -18,
      "y": 14,
      "z": 10,
      "name": "Rock_Stone"
    },
    {
      "x": -18,
      "y": 15,
      "z": 10,
      "name": "Rock_Stone"
    },
    {
      "x": -18,
      "y": 16,
      "z": 10,
      "name": "Rock_Stone"
    },
    {
      "x": -18,
      "y": 17,
      "z": 10,
      "name": "Rock_Stone"
    },
    {
      "x": -18,
      "y": 18,
      "z": 10,
      "name": "Rock_Stone"
    },
    {
      "x": -18,
      "y": 19,
      "z": 10,
      "name": "Soil_Grass"
    },
    {
      "x": -18,
      "y": 6,
      "z": 11,
      "name": "Rock_Stone"
    },
    {
      "x": -18,
      "y": 7,
      "z": 11,
      "name": "Rock_Stone"
    },
    {
      "x": -18,
      "y": 8,
      "z": 11,
      "name": "Rock_Stone"
    },
    {
      "x": -18,
      "y": 9,
      "z": 11,
      "name": "Rock_Stone"
    },
    {
      "x": -18,
      "y": 10,
      "z": 11,
      "name": "Rock_Stone"
    },
    {
      "x": -18,
      "y": 11,
      "z": 11,
      "name": "Rock_Stone"
    },
    {
      "x": -18,
      "y": 12,
      "z": 11,
      "name": "Rock_Stone"
    },
    {
      "x": -18,
      "y": 13,
      "z": 11,
      "name": "Rock_Stone"
    },
    {
      "x": -18,
      "y": 14,
      "z": 11,
      "name": "Rock_Stone"
    },
    {
      "x": -18,
      "y": 15,
      "z": 11,
      "name": "Rock_Stone"
    },
    {
      "x": -18,
      "y": 16,
      "z": 11,
      "name": "Rock_Stone"
    },
    {
      "x": -18,
      "y": 17,
      "z": 11,
      "name": "Rock_Stone"
    },
    {
      "x": -18,
      "y": 18,
      "z": 11,
      "name": "Rock_Stone"
    },
    {
      "x": -18,
      "y": 19,
      "z": 11,
      "name": "Rock_Stone"
    },
    {
      "x": -18,
      "y": 20,
      "z": 11,
      "name": "Soil_Dirt"
    },
    {
      "x": -18,
      "y": 21,
      "z": 11,
      "name": "Soil_Grass"
    },
    {
      "x": -18,
      "y": 5,
      "z": 12,
      "name": "Rock_Stone"
    },
    {
      "x": -18,
      "y": 6,
      "z": 12,
      "name": "Rock_Stone"
    },
    {
      "x": -18,
      "y": 7,
      "z": 12,
      "name": "Rock_Stone"
    },
    {
      "x": -18,
      "y": 8,
      "z": 12,
      "name": "Rock_Stone"
    },
    {
      "x": -18,
      "y": 9,
      "z": 12,
      "name": "Rock_Stone"
    },
    {
      "x": -18,
      "y": 10,
      "z": 12,
      "name": "Rock_Stone"
    },
    {
      "x": -18,
      "y": 11,
      "z": 12,
      "name": "Rock_Stone"
    },
    {
      "x": -18,
      "y": 12,
      "z": 12,
      "name": "Rock_Stone"
    },
    {
      "x": -18,
      "y": 13,
      "z": 12,
      "name": "Rock_Stone"
    },
    {
      "x": -18,
      "y": 14,
      "z": 12,
      "name": "Rock_Stone"
    },
    {
      "x": -18,
      "y": 15,
      "z": 12,
      "name": "Rock_Stone"
    },
    {
      "x": -18,
      "y": 16,
      "z": 12,
      "name": "Rock_Stone"
    },
    {
      "x": -18,
      "y": 17,
      "z": 12,
      "name": "Rock_Stone"
    },
    {
      "x": -18,
      "y": 18,
      "z": 12,
      "name": "Rock_Stone"
    },
    {
      "x": -18,
      "y": 19,
      "z": 12,
      "name": "Rock_Stone"
    },
    {
      "x": -18,
      "y": 20,
      "z": 12,
      "name": "Rock_Stone"
    },
    {
      "x": -18,
      "y": 21,
      "z": 12,
      "name": "Rock_Stone"
    },
    {
      "x": -18,
      "y": 22,
      "z": 12,
      "name": "Soil_Dirt"
    },
    {
      "x": -18,
      "y": 23,
      "z": 12,
      "name": "Soil_Grass"
    },
    {
      "x": -18,
      "y": 24,
      "z": 12,
      "name": "Plant_Flower_Bushy_Green"
    },
    {
      "x": -18,
      "y": 5,
      "z": 13,
      "name": "Rock_Stone"
    },
    {
      "x": -18,
      "y": 6,
      "z": 13,
      "name": "Rock_Stone"
    },
    {
      "x": -18,
      "y": 7,
      "z": 13,
      "name": "Rock_Stone"
    },
    {
      "x": -18,
      "y": 8,
      "z": 13,
      "name": "Rock_Stone"
    },
    {
      "x": -18,
      "y": 9,
      "z": 13,
      "name": "Rock_Stone"
    },
    {
      "x": -18,
      "y": 10,
      "z": 13,
      "name": "Rock_Stone"
    },
    {
      "x": -18,
      "y": 11,
      "z": 13,
      "name": "Rock_Stone"
    },
    {
      "x": -18,
      "y": 12,
      "z": 13,
      "name": "Rock_Stone"
    },
    {
      "x": -18,
      "y": 13,
      "z": 13,
      "name": "Rock_Stone"
    },
    {
      "x": -18,
      "y": 14,
      "z": 13,
      "name": "Rock_Stone"
    },
    {
      "x": -18,
      "y": 15,
      "z": 13,
      "name": "Rock_Stone"
    },
    {
      "x": -18,
      "y": 16,
      "z": 13,
      "name": "Rock_Stone"
    },
    {
      "x": -18,
      "y": 17,
      "z": 13,
      "name": "Rock_Stone"
    },
    {
      "x": -18,
      "y": 18,
      "z": 13,
      "name": "Rock_Stone"
    },
    {
      "x": -18,
      "y": 19,
      "z": 13,
      "name": "Rock_Stone"
    },
    {
      "x": -18,
      "y": 20,
      "z": 13,
      "name": "Rock_Stone"
    },
    {
      "x": -18,
      "y": 21,
      "z": 13,
      "name": "Rock_Stone"
    },
    {
      "x": -18,
      "y": 22,
      "z": 13,
      "name": "Rock_Stone"
    },
    {
      "x": -18,
      "y": 23,
      "z": 13,
      "name": "Rock_Stone"
    },
    {
      "x": -18,
      "y": 5,
      "z": 14,
      "name": "Rock_Stone"
    },
    {
      "x": -18,
      "y": 6,
      "z": 14,
      "name": "Rock_Stone"
    },
    {
      "x": -18,
      "y": 7,
      "z": 14,
      "name": "Rock_Stone"
    },
    {
      "x": -18,
      "y": 8,
      "z": 14,
      "name": "Rock_Stone"
    },
    {
      "x": -18,
      "y": 9,
      "z": 14,
      "name": "Rock_Stone"
    },
    {
      "x": -18,
      "y": 10,
      "z": 14,
      "name": "Rock_Stone"
    },
    {
      "x": -18,
      "y": 11,
      "z": 14,
      "name": "Rock_Stone"
    },
    {
      "x": -18,
      "y": 12,
      "z": 14,
      "name": "Rock_Stone"
    },
    {
      "x": -18,
      "y": 13,
      "z": 14,
      "name": "Rock_Stone"
    },
    {
      "x": -18,
      "y": 14,
      "z": 14,
      "name": "Rock_Stone"
    },
    {
      "x": -18,
      "y": 15,
      "z": 14,
      "name": "Rock_Stone"
    },
    {
      "x": -18,
      "y": 16,
      "z": 14,
      "name": "Rock_Stone"
    },
    {
      "x": -18,
      "y": 17,
      "z": 14,
      "name": "Rock_Stone"
    },
    {
      "x": -18,
      "y": 18,
      "z": 14,
      "name": "Rock_Stone"
    },
    {
      "x": -18,
      "y": 19,
      "z": 14,
      "name": "Rock_Stone"
    },
    {
      "x": -18,
      "y": 20,
      "z": 14,
      "name": "Rock_Stone"
    },
    {
      "x": -18,
      "y": 21,
      "z": 14,
      "name": "Rock_Stone"
    },
    {
      "x": -18,
      "y": 22,
      "z": 14,
      "name": "Rock_Stone"
    },
    {
      "x": -18,
      "y": 6,
      "z": 15,
      "name": "Rock_Stone"
    },
    {
      "x": -18,
      "y": 7,
      "z": 15,
      "name": "Rock_Stone"
    },
    {
      "x": -18,
      "y": 8,
      "z": 15,
      "name": "Rock_Stone"
    },
    {
      "x": -18,
      "y": 9,
      "z": 15,
      "name": "Rock_Stone"
    },
    {
      "x": -18,
      "y": 10,
      "z": 15,
      "name": "Rock_Stone"
    },
    {
      "x": -18,
      "y": 11,
      "z": 15,
      "name": "Rock_Stone"
    },
    {
      "x": -18,
      "y": 12,
      "z": 15,
      "name": "Rock_Stone"
    },
    {
      "x": -18,
      "y": 13,
      "z": 15,
      "name": "Rock_Stone"
    },
    {
      "x": -18,
      "y": 14,
      "z": 15,
      "name": "Rock_Stone"
    },
    {
      "x": -18,
      "y": 15,
      "z": 15,
      "name": "Rock_Stone"
    },
    {
      "x": -18,
      "y": 16,
      "z": 15,
      "name": "Rock_Stone"
    },
    {
      "x": -18,
      "y": 17,
      "z": 15,
      "name": "Rock_Stone"
    },
    {
      "x": -18,
      "y": 18,
      "z": 15,
      "name": "Rock_Stone"
    },
    {
      "x": -18,
      "y": 19,
      "z": 15,
      "name": "Rock_Stone"
    },
    {
      "x": -18,
      "y": 6,
      "z": 16,
      "name": "Rock_Stone"
    },
    {
      "x": -18,
      "y": 7,
      "z": 16,
      "name": "Rock_Stone"
    },
    {
      "x": -18,
      "y": 8,
      "z": 16,
      "name": "Rock_Stone"
    },
    {
      "x": -18,
      "y": 9,
      "z": 16,
      "name": "Rock_Stone"
    },
    {
      "x": -18,
      "y": 10,
      "z": 16,
      "name": "Rock_Stone"
    },
    {
      "x": -18,
      "y": 11,
      "z": 16,
      "name": "Rock_Stone"
    },
    {
      "x": -18,
      "y": 12,
      "z": 16,
      "name": "Rock_Stone"
    },
    {
      "x": -18,
      "y": 13,
      "z": 16,
      "name": "Rock_Stone"
    },
    {
      "x": -18,
      "y": 14,
      "z": 16,
      "name": "Rock_Stone"
    },
    {
      "x": -18,
      "y": 15,
      "z": 16,
      "name": "Rock_Stone"
    },
    {
      "x": -18,
      "y": 16,
      "z": 16,
      "name": "Rock_Stone"
    },
    {
      "x": -18,
      "y": 7,
      "z": 17,
      "name": "Rock_Stone"
    },
    {
      "x": -18,
      "y": 8,
      "z": 17,
      "name": "Rock_Stone"
    },
    {
      "x": -18,
      "y": 9,
      "z": 17,
      "name": "Rock_Stone"
    },
    {
      "x": -18,
      "y": 10,
      "z": 17,
      "name": "Rock_Stone"
    },
    {
      "x": -18,
      "y": 11,
      "z": 17,
      "name": "Rock_Stone"
    },
    {
      "x": -18,
      "y": 12,
      "z": 17,
      "name": "Rock_Stone"
    },
    {
      "x": -18,
      "y": 13,
      "z": 17,
      "name": "Rock_Stone"
    },
    {
      "x": -17,
      "y": 23,
      "z": -15,
      "name": "Plant_Leaves_Beech",
      "support": 1
    },
    {
      "x": -17,
      "y": 24,
      "z": -15,
      "name": "Plant_Leaves_Beech",
      "support": 1
    },
    {
      "x": -17,
      "y": 24,
      "z": -14,
      "name": "Plant_Leaves_Beech"
    },
    {
      "x": -17,
      "y": 24,
      "z": -13,
      "name": "Wood_Beech_Branch_Long",
      "support": 1,
      "rotation": 4
    },
    {
      "x": -17,
      "y": 25,
      "z": -13,
      "name": "Plant_Leaves_Beech"
    },
    {
      "x": -17,
      "y": 27,
      "z": -13,
      "name": "Plant_Leaves_Beech",
      "support": 1
    },
    {
      "x": -17,
      "y": 28,
      "z": -13,
      "name": "Plant_Leaves_Beech",
      "support": 2
    },
    {
      "x": -17,
      "y": 29,
      "z": -13,
      "name": "Plant_Leaves_Beech",
      "support": 1
    },
    {
      "x": -17,
      "y": 21,
      "z": -12,
      "name": "Plant_Leaves_Beech",
      "support": 1
    },
    {
      "x": -17,
      "y": 24,
      "z": -12,
      "name": "Wood_Beech_Branch_Long",
      "rotation": 4
    },
    {
      "x": -17,
      "y": 27,
      "z": -12,
      "name": "Plant_Leaves_Beech"
    },
    {
      "x": -17,
      "y": 29,
      "z": -12,
      "name": "Plant_Leaves_Beech",
      "support": 1
    },
    {
      "x": -17,
      "y": 20,
      "z": -11,
      "name": "Wood_Beech_Branch_Long",
      "support": 1,
      "rotation": 5
    },
    {
      "x": -17,
      "y": 21,
      "z": -11,
      "name": "Plant_Leaves_Beech"
    },
    {
      "x": -17,
      "y": 23,
      "z": -11,
      "name": "Wood_Beech_Trunk_Full"
    },
    {
      "x": -17,
      "y": 24,
      "z": -11,
      "name": "Wood_Beech_Trunk_Full"
    },
    {
      "x": -17,
      "y": 25,
      "z": -11,
      "name": "Wood_Beech_Branch_Long"
    },
    {
      "x": -17,
      "y": 26,
      "z": -11,
      "name": "Wood_Beech_Branch_Long",
      "support": 1
    },
    {
      "x": -17,
      "y": 27,
      "z": -11,
      "name": "Wood_Beech_Branch_Long",
      "support": 2
    },
    {
      "x": -17,
      "y": 28,
      "z": -11,
      "name": "Plant_Leaves_Beech"
    },
    {
      "x": -17,
      "y": 29,
      "z": -11,
      "name": "Plant_Leaves_Beech"
    },
    {
      "x": -17,
      "y": 30,
      "z": -11,
      "name": "Plant_Leaves_Beech",
      "support": 1
    },
    {
      "x": -17,
      "y": 31,
      "z": -11,
      "name": "Plant_Leaves_Beech",
      "support": 1
    },
    {
      "x": -17,
      "y": 11,
      "z": -10,
      "name": "Rock_Stone"
    },
    {
      "x": -17,
      "y": 12,
      "z": -10,
      "name": "Rock_Stone"
    },
    {
      "x": -17,
      "y": 13,
      "z": -10,
      "name": "Soil_Dirt"
    },
    {
      "x": -17,
      "y": 14,
      "z": -10,
      "name": "Soil_Dirt"
    },
    {
      "x": -17,
      "y": 15,
      "z": -10,
      "name": "Soil_Grass"
    },
    {
      "x": -17,
      "y": 20,
      "z": -10,
      "name": "Plant_Leaves_Beech"
    },
    {
      "x": -17,
      "y": 24,
      "z": -10,
      "name": "Wood_Beech_Branch_Long",
      "rotation": 4
    },
    {
      "x": -17,
      "y": 28,
      "z": -10,
      "name": "Plant_Leaves_Beech",
      "support": 1
    },
    {
      "x": -17,
      "y": 30,
      "z": -10,
      "name": "Plant_Leaves_Beech",
      "support": 2
    },
    {
      "x": -17,
      "y": 9,
      "z": -9,
      "name": "Rock_Stone"
    },
    {
      "x": -17,
      "y": 10,
      "z": -9,
      "name": "Rock_Stone"
    },
    {
      "x": -17,
      "y": 11,
      "z": -9,
      "name": "Rock_Stone"
    },
    {
      "x": -17,
      "y": 12,
      "z": -9,
      "name": "Rock_Stone"
    },
    {
      "x": -17,
      "y": 13,
      "z": -9,
      "name": "Rock_Stone"
    },
    {
      "x": -17,
      "y": 14,
      "z": -9,
      "name": "Rock_Stone"
    },
    {
      "x": -17,
      "y": 15,
      "z": -9,
      "name": "Soil_Dirt"
    },
    {
      "x": -17,
      "y": 16,
      "z": -9,
      "name": "Soil_Grass"
    },
    {
      "x": -17,
      "y": 24,
      "z": -9,
      "name": "Wood_Beech_Branch_Long",
      "support": 1,
      "rotation": 4
    },
    {
      "x": -17,
      "y": 27,
      "z": -9,
      "name": "Plant_Leaves_Beech",
      "support": 2
    },
    {
      "x": -17,
      "y": 28,
      "z": -9,
      "name": "Plant_Leaves_Beech",
      "support": 2
    },
    {
      "x": -17,
      "y": 9,
      "z": -8,
      "name": "Rock_Stone"
    },
    {
      "x": -17,
      "y": 10,
      "z": -8,
      "name": "Rock_Stone"
    },
    {
      "x": -17,
      "y": 11,
      "z": -8,
      "name": "Rock_Stone"
    },
    {
      "x": -17,
      "y": 12,
      "z": -8,
      "name": "Rock_Stone"
    },
    {
      "x": -17,
