{
  "version": 8,
  "blockIdVersion": 8,
  "anchorX": 0,
  "anchorY": 0,
  "anchorZ": 0,
  "blocks": [
    {
      "x": -21,
      "y": 1,
      "z": -12,
      "name": "Rock_Marble"
    },
    {
      "x": -21,
      "y": 2,
      "z": -12,
      "name": "Rock_Marble"
    },
    {
      "x": -21,
      "y": 1,
      "z": -11,
      "name": "Rock_Chalk"
    },
    {
      "x": -21,
      "y": 2,
      "z": -11,
      "name": "Rock_Chalk"
    },
    {
      "x": -20,
      "y": -1,
      "z": -13,
      "name": "Rock_Marble"
    },
    {
      "x": -20,
      "y": 0,
      "z": -13,
      "name": "Rock_Marble"
    },
    {
      "x": -20,
      "y": -2,
      "z": -12,
      "name": "Rock_Marble"
    },
    {
      "x": -20,
      "y": -1,
      "z": -12,
      "name": "Rock_Marble"
    },
    {
      "x": -20,
      "y": 0,
      "z": -12,
      "name": "Rock_Marble"
    },
    {
      "x": -20,
      "y": -2,
      "z": -11,
      "name": "Rock_Marble"
    },
    {
      "x": -20,
      "y": -1,
      "z": -11,
      "name": "Rock_Marble"
    },
    {
      "x": -20,
      "y": -2,
      "z": -10,
      "name": "Rock_Chalk"
    },
    {
      "x": -20,
      "y": -1,
      "z": -10,
      "name": "Rock_Chalk"
    },
    {
      "x": -20,
      "y": -2,
      "z": -9,
      "name": "Rock_Chalk"
    },
    {
      "x": -19,
      "y": -1,
      "z": -14,
      "name": "Rock_Marble"
    },
    {
      "x": -19,
      "y": -3,
      "z": -13,
      "name": "Rock_Marble"
    },
    {
      "x": -19,
      "y": -2,
      "z": -13,
      "name": "Rock_Marble"
    },
    {
      "x": -19,
      "y": -1,
      "z": -13,
      "name": "Rock_Marble"
    },
    {
      "x": -19,
      "y": -4,
      "z": -12,
      "name": "Rock_Marble"
    },
    {
      "x": -19,
      "y": -3,
      "z": -12,
      "name": "Rock_Marble"
    },
    {
      "x": -19,
      "y": -2,
      "z": -12,
      "name": "Rock_Marble"
    },
    {
      "x": -19,
      "y": -4,
      "z": -11,
      "name": "Rock_Marble"
    },
    {
      "x": -19,
      "y": -3,
      "z": -11,
      "name": "Rock_Marble"
    },
    {
      "x": -19,
      "y": -2,
      "z": -11,
      "name": "Rock_Marble"
    },
    {
      "x": -19,
      "y": -4,
      "z": -10,
      "name": "Rock_Marble"
    },
    {
      "x": -19,
      "y": -3,
      "z": -10,
      "name": "Rock_Marble"
    },
    {
      "x": -18,
      "y": -4,
      "z": -14,
      "name": "Rock_Marble"
    },
    {
      "x": -18,
      "y": -3,
      "z": -14,
      "name": "Rock_Marble"
    },
    {
      "x": -18,
      "y": -6,
      "z": -13,
      "name": "Rock_Marble"
    },
    {
      "x": -18,
      "y": -5,
      "z": -13,
      "name": "Rock_Marble"
    },
    {
      "x": -18,
      "y": -4,
      "z": -13,
      "name": "Rock_Marble"
    },
    {
      "x": -18,
      "y": -3,
      "z": -13,
      "name": "Rock_Marble"
    },
    {
      "x": -18,
      "y": -7,
      "z": -12,
      "name": "Rock_Marble"
    },
    {
      "x": -18,
      "y": -6,
      "z": -12,
      "name": "Rock_Marble"
    },
    {
      "x": -18,
      "y": -5,
      "z": -12,
      "name": "Rock_Marble"
    },
    {
      "x": -18,
      "y": -4,
      "z": -12,
      "name": "Rock_Marble"
    },
    {
      "x": -18,
      "y": -7,
      "z": -11,
      "name": "Rock_Marble"
    },
    {
      "x": -18,
      "y": -6,
      "z": -11,
      "name": "Rock_Marble"
    },
    {
      "x": -18,
      "y": -5,
      "z": -11,
      "name": "Rock_Marble"
    },
    {
      "x": -18,
      "y": -4,
      "z": -11,
      "name": "Rock_Marble"
    },
    {
      "x": -18,
      "y": -6,
      "z": -10,
      "name": "Rock_Calcite"
    },
    {
      "x": -18,
      "y": -5,
      "z": -10,
      "name": "Rock_Calcite"
    },
    {
      "x": -17,
      "y": 2,
      "z": -16,
      "name": "Rock_Marble"
    },
    {
      "x": -17,
      "y": 3,
      "z": -16,
      "name": "Rock_Marble"
    },
    {
      "x": -17,
      "y": 4,
      "z": -16,
      "name": "Plant_Moss_Block_Green"
    },
    {
      "x": -17,
      "y": -4,
      "z": -15,
      "name": "Rock_Marble"
    },
    {
      "x": -17,
      "y": 2,
      "z": -15,
      "name": "Rock_Marble"
    },
    {
      "x": -17,
      "y": 3,
      "z": -15,
      "name": "Plant_Moss_Block_Green"
    },
    {
      "x": -17,
      "y": 4,
      "z": -15,
      "name": "Plant_Moss_Block_Green"
    },
    {
      "x": -17,
      "y": -6,
      "z": -14,
      "name": "Rock_Marble"
    },
    {
      "x": -17,
      "y": -5,
      "z": -14,
      "name": "Rock_Marble"
    },
    {
      "x": -17,
      "y": -4,
      "z": -14,
      "name": "Rock_Marble"
    },
    {
      "x": -17,
      "y": 7,
      "z": -14,
      "name": "Plant_Moss_Wall_Green",
      "rotation": 3
    },
    {
      "x": -17,
      "y": -6,
      "z": -13,
      "name": "Rock_Marble"
    },
    {
      "x": -17,
      "y": 4,
      "z": -13,
      "name": "Plant_Moss_Wall_Green",
      "rotation": 3
    },
    {
      "x": -17,
      "y": 5,
      "z": -13,
      "name": "Plant_Moss_Wall_Green",
      "rotation": 3
    },
    {
      "x": -17,
      "y": 6,
      "z": -13,
      "name": "Plant_Moss_Wall_Green",
      "rotation": 3
    },
    {
      "x": -17,
      "y": 6,
      "z": -12,
      "name": "Plant_Moss_Wall_Green",
      "rotation": 3
    },
    {
      "x": -16,
      "y": 0,
      "z": -17,
      "name": "Rock_Marble"
    },
    {
      "x": -16,
      "y": 1,
      "z": -17,
      "name": "Rock_Marble"
    },
    {
      "x": -16,
      "y": 2,
      "z": -17,
      "name": "Rock_Marble"
    },
    {
      "x": -16,
      "y": 3,
      "z": -17,
      "name": "Rock_Marble"
    },
    {
      "x": -16,
      "y": 0,
      "z": -16,
      "name": "Rock_Marble"
    },
    {
      "x": -16,
      "y": 1,
      "z": -16,
      "name": "Rock_Marble"
    },
    {
      "x": -16,
      "y": 2,
      "z": -16,
      "name": "Rock_Marble"
    },
    {
      "x": -16,
      "y": 3,
      "z": -16,
      "name": "Rock_Marble"
    },
    {
      "x": -16,
      "y": 4,
      "z": -16,
      "name": "Rock_Marble"
    },
    {
      "x": -16,
      "y": 5,
      "z": -16,
      "name": "Rock_Marble"
    },
    {
      "x": -16,
      "y": 1,
      "z": -15,
      "name": "Rock_Marble"
    },
    {
      "x": -16,
      "y": 2,
      "z": -15,
      "name": "Rock_Marble"
    },
    {
      "x": -16,
      "y": 3,
      "z": -15,
      "name": "Rock_Marble"
    },
    {
      "x": -16,
      "y": 4,
      "z": -15,
      "name": "Rock_Marble"
    },
    {
      "x": -16,
      "y": 5,
      "z": -15,
      "name": "Plant_Moss_Block_Green"
    },
    {
      "x": -16,
      "y": 6,
      "z": -15,
      "name": "Plant_Moss_Block_Green"
    },
    {
      "x": -16,
      "y": 1,
      "z": -14,
      "name": "Rock_Marble"
    },
    {
      "x": -16,
      "y": 2,
      "z": -14,
      "name": "Rock_Marble"
    },
    {
      "x": -16,
      "y": 3,
      "z": -14,
      "name": "Rock_Marble"
    },
    {
      "x": -16,
      "y": 4,
      "z": -14,
      "name": "Plant_Moss_Block_Green"
    },
    {
      "x": -16,
      "y": 5,
      "z": -14,
      "name": "Plant_Moss_Block_Green"
    },
    {
      "x": -16,
      "y": 6,
      "z": -14,
      "name": "Plant_Moss_Block_Green"
    },
    {
      "x": -16,
      "y": 7,
      "z": -14,
      "name": "Plant_Moss_Block_Green"
    },
    {
      "x": -16,
      "y": 8,
      "z": -14,
      "name": "Plant_Moss_Rug_Green"
    },
    {
      "x": -16,
      "y": 4,
      "z": -13,
      "name": "Plant_Moss_Block_Green"
    },
    {
      "x": -16,
      "y": 5,
      "z": -13,
      "name": "Plant_Moss_Block_Green"
    },
    {
      "x": -16,
      "y": 6,
      "z": -13,
      "name": "Plant_Moss_Block_Green"
    },
    {
      "x": -16,
      "y": 4,
      "z": -12,
      "name": "Plant_Moss_Wall_Green"
    },
    {
      "x": -16,
      "y": 6,
      "z": -12,
      "name": "Plant_Moss_Block_Green"
    },
    {
      "x": -16,
      "y": 6,
      "z": -11,
      "name": "Plant_Moss_Wall_Green"
    },
    {
      "x": -15,
      "y": -1,
      "z": -18,
      "name": "Rock_Marble"
    },
    {
      "x": -15,
      "y": 0,
      "z": -18,
      "name": "Rock_Marble"
    },
    {
      "x": -15,
      "y": 1,
      "z": -18,
      "name": "Rock_Marble"
    },
    {
      "x": -15,
      "y": 2,
      "z": -18,
      "name": "Rock_Marble"
    },
    {
      "x": -15,
      "y": 3,
      "z": -18,
      "name": "Rock_Marble"
    },
    {
      "x": -15,
      "y": -1,
      "z": -17,
      "name": "Rock_Marble"
    },
    {
      "x": -15,
      "y": 0,
      "z": -17,
      "name": "Rock_Marble"
    },
    {
      "x": -15,
      "y": 1,
      "z": -17,
      "name": "Rock_Marble"
    },
    {
      "x": -15,
      "y": 2,
      "z": -17,
      "name": "Rock_Marble"
    },
    {
      "x": -15,
      "y": 3,
      "z": -17,
      "name": "Rock_Marble"
    },
    {
      "x": -15,
      "y": 4,
      "z": -17,
      "name": "Rock_Marble"
    },
    {
      "x": -15,
      "y": 5,
      "z": -17,
      "name": "Rock_Marble"
    },
    {
      "x": -15,
      "y": 0,
      "z": -16,
      "name": "Rock_Stone"
    },
    {
      "x": -15,
      "y": 1,
      "z": -16,
      "name": "Rock_Marble"
    },
    {
      "x": -15,
      "y": 2,
      "z": -16,
      "name": "Rock_Marble"
    },
    {
      "x": -15,
      "y": 3,
      "z": -16,
      "name": "Rock_Marble"
    },
    {
      "x": -15,
      "y": 4,
      "z": -16,
      "name": "Rock_Marble"
    },
    {
      "x": -15,
      "y": 5,
      "z": -16,
      "name": "Rock_Marble"
    },
    {
      "x": -15,
      "y": 6,
      "z": -16,
      "name": "Rock_Marble"
    },
    {
      "x": -15,
      "y": -9,
      "z": -15,
      "name": "Plant_Moss_Wall_Green",
      "rotation": 3
    },
    {
      "x": -15,
      "y": 0,
      "z": -15,
      "name": "Rock_Stone"
    },
    {
      "x": -15,
      "y": 1,
      "z": -15,
      "name": "Rock_Stone"
    },
    {
      "x": -15,
      "y": 2,
      "z": -15,
      "name": "Rock_Stone"
    },
    {
      "x": -15,
      "y": 3,
      "z": -15,
      "name": "Rock_Stone"
    },
    {
      "x": -15,
      "y": 4,
      "z": -15,
      "name": "Rock_Marble"
    },
    {
      "x": -15,
      "y": 5,
      "z": -15,
      "name": "Plant_Moss_Block_Green"
    },
    {
      "x": -15,
      "y": 6,
      "z": -15,
      "name": "Plant_Moss_Block_Green"
    },
    {
      "x": -15,
      "y": 7,
      "z": -15,
      "name": "Plant_Moss_Block_Green"
    },
    {
      "x": -15,
      "y": -10,
      "z": -14,
      "name": "Plant_Moss_Wall_Green",
      "rotation": 3
    },
    {
      "x": -15,
      "y": -9,
      "z": -14,
      "name": "Plant_Moss_Wall_Green",
      "rotation": 3
    },
    {
      "x": -15,
      "y": 4,
      "z": -14,
      "name": "Rock_Stone"
    },
    {
      "x": -15,
      "y": 5,
      "z": -14,
      "name": "Rock_Stone"
    },
    {
      "x": -15,
      "y": 6,
      "z": -14,
      "name": "Plant_Moss_Block_Green"
    },
    {
      "x": -15,
      "y": 7,
      "z": -14,
      "name": "Plant_Moss_Block_Green"
    },
    {
      "x": -15,
      "y": -10,
      "z": -13,
      "name": "Plant_Moss_Block_Green"
    },
    {
      "x": -15,
      "y": 6,
      "z": -13,
      "name": "Rock_Stone"
    },
    {
      "x": -15,
      "y": 7,
      "z": -13,
      "name": "Plant_Moss_Block_Green"
    },
    {
      "x": -15,
      "y": 8,
      "z": -13,
      "name": "Plant_Moss_Rug_Green"
    },
    {
      "x": -15,
      "y": -10,
      "z": -12,
      "name": "Plant_Moss_Block_Green"
    },
    {
      "x": -15,
      "y": 6,
      "z": -12,
      "name": "Plant_Moss_Cave_Green",
      "rotation": 8
    },
    {
      "x": -15,
      "y": 7,
      "z": -12,
      "name": "Plant_Moss_Block_Green"
    },
    {
      "x": -15,
      "y": 8,
      "z": -12,
      "name": "Plant_Moss_Rug_Green"
    },
    {
      "x": -15,
      "y": 7,
      "z": -11,
      "name": "Plant_Moss_Wall_Green"
    },
    {
      "x": -14,
      "y": -3,
      "z": -20,
      "name": "Plant_Moss_Wall_Green",
      "rotation": 3
    },
    {
      "x": -14,
      "y": -1,
      "z": -20,
      "name": "Rock_Marble"
    },
    {
      "x": -14,
      "y": -3,
      "z": -19,
      "name": "Plant_Moss_Wall_Green",
      "rotation": 3
    },
    {
      "x": -14,
      "y": -2,
      "z": -19,
      "name": "Rock_Marble"
    },
    {
      "x": -14,
      "y": -1,
      "z": -19,
      "name": "Rock_Marble"
    },
    {
      "x": -14,
      "y": 0,
      "z": -19,
      "name": "Rock_Marble"
    },
    {
      "x": -14,
      "y": 1,
      "z": -19,
      "name": "Rock_Marble"
    },
    {
      "x": -14,
      "y": 2,
      "z": -19,
      "name": "Rock_Marble"
    },
    {
      "x": -14,
      "y": 3,
      "z": -19,
      "name": "Rock_Marble"
    },
    {
      "x": -14,
      "y": -2,
      "z": -18,
      "name": "Rock_Marble"
    },
    {
      "x": -14,
      "y": -1,
      "z": -18,
      "name": "Rock_Marble"
    },
    {
      "x": -14,
      "y": 0,
      "z": -18,
      "name": "Rock_Marble"
    },
    {
      "x": -14,
      "y": 1,
      "z": -18,
      "name": "Rock_Marble"
    },
    {
      "x": -14,
      "y": 2,
      "z": -18,
      "name": "Rock_Marble"
    },
    {
      "x": -14,
      "y": 3,
      "z": -18,
      "name": "Rock_Marble"
    },
    {
      "x": -14,
      "y": 4,
      "z": -18,
      "name": "Plant_Moss_Block_Green"
    },
    {
      "x": -14,
      "y": -2,
      "z": -17,
      "name": "Rock_Marble"
    },
    {
      "x": -14,
      "y": -1,
      "z": -17,
      "name": "Rock_Marble"
    },
    {
      "x": -14,
      "y": 0,
      "z": -17,
      "name": "Rock_Marble"
    },
    {
      "x": -14,
      "y": 1,
      "z": -17,
      "name": "Rock_Marble"
    },
    {
      "x": -14,
      "y": 2,
      "z": -17,
      "name": "Rock_Marble"
    },
    {
      "x": -14,
      "y": 3,
      "z": -17,
      "name": "Rock_Marble"
    },
    {
      "x": -14,
      "y": 4,
      "z": -17,
      "name": "Rock_Marble"
    },
    {
      "x": -14,
      "y": 5,
      "z": -17,
      "name": "Rock_Marble"
    },
    {
      "x": -14,
      "y": -2,
      "z": -16,
      "name": "Rock_Marble"
    },
    {
      "x": -14,
      "y": -1,
      "z": -16,
      "name": "Rock_Marble"
    },
    {
      "x": -14,
      "y": 0,
      "z": -16,
      "name": "Rock_Stone"
    },
    {
      "x": -14,
      "y": 1,
      "z": -16,
      "name": "Rock_Stone"
    },
    {
      "x": -14,
      "y": 2,
      "z": -16,
      "name": "Rock_Stone"
    },
    {
      "x": -14,
      "y": 3,
      "z": -16,
      "name": "Rock_Marble"
    },
    {
      "x": -14,
      "y": 4,
      "z": -16,
      "name": "Rock_Marble"
    },
    {
      "x": -14,
      "y": 5,
      "z": -16,
      "name": "Rock_Marble"
    },
    {
      "x": -14,
      "y": 6,
      "z": -16,
      "name": "Plant_Moss_Block_Green"
    },
    {
      "x": -14,
      "y": -9,
      "z": -15,
      "name": "Plant_Moss_Block_Green"
    },
    {
      "x": -14,
      "y": -8,
      "z": -15,
      "name": "Plant_Moss_Rug_Green"
    },
    {
      "x": -14,
      "y": 3,
      "z": -15,
      "name": "Rock_Stone"
    },
    {
      "x": -14,
      "y": 4,
      "z": -15,
      "name": "Rock_Stone"
    },
    {
      "x": -14,
      "y": 5,
      "z": -15,
      "name": "Rock_Marble"
    },
    {
      "x": -14,
      "y": 6,
      "z": -15,
      "name": "Plant_Moss_Block_Green"
    },
    {
      "x": -14,
      "y": 7,
      "z": -15,
      "name": "Plant_Moss_Block_Green"
    },
    {
      "x": -14,
      "y": -11,
      "z": -14,
      "name": "Plant_Moss_Cave_Green",
      "rotation": 8
    },
    {
      "x": -14,
      "y": -10,
      "z": -14,
      "name": "Plant_Moss_Block_Green"
    },
    {
      "x": -14,
      "y": -9,
      "z": -14,
      "name": "Plant_Moss_Block_Green"
    },
    {
      "x": -14,
      "y": -8,
      "z": -14,
      "name": "Plant_Moss_Rug_Green"
    },
    {
      "x": -14,
      "y": 5,
      "z": -14,
      "name": "Rock_Stone"
    },
    {
      "x": -14,
      "y": 6,
      "z": -14,
      "name": "Plant_Moss_Block_Green"
    },
    {
      "x": -14,
      "y": 7,
      "z": -14,
      "name": "Plant_Moss_Block_Green"
    },
    {
      "x": -14,
      "y": 8,
      "z": -14,
      "name": "Plant_Moss_Block_Green"
    },
    {
      "x": -14,
      "y": -10,
      "z": -13,
      "name": "Plant_Moss_Block_Green"
    },
    {
      "x": -14,
      "y": -9,
      "z": -13,
      "name": "Plant_Moss_Wall_Green"
    },
    {
      "x": -14,
      "y": 6,
      "z": -13,
      "name": "Rock_Stone"
    },
    {
      "x": -14,
      "y": 7,
      "z": -13,
      "name": "Plant_Moss_Block_Green"
    },
    {
      "x": -14,
      "y": 8,
      "z": -13,
      "name": "Plant_Moss_Block_Green"
    },
    {
      "x": -14,
      "y": 9,
      "z": -13,
      "name": "Plant_Moss_Rug_Green"
    },
    {
      "x": -14,
      "y": -11,
      "z": -12,
      "name": "Plant_Moss_Block_Green"
    },
    {
      "x": -14,
      "y": -10,
      "z": -12,
      "name": "Plant_Moss_Block_Green"
    },
    {
      "x": -14,
      "y": 7,
      "z": -12,
      "name": "Plant_Moss_Block_Green"
    },
    {
      "x": -14,
      "y": 8,
      "z": -12,
      "name": "Plant_Moss_Rug_Green"
    },
    {
      "x": -14,
      "y": -11,
      "z": -11,
      "name": "Plant_Moss_Block_Green"
    },
    {
      "x": -14,
      "y": -10,
      "z": -11,
      "name": "Plant_Moss_Block_Green"
    },
    {
      "x": -14,
      "y": -12,
      "z": -10,
      "name": "Plant_Moss_Cave_Green",
      "rotation": 8
    },
    {
      "x": -14,
      "y": -11,
      "z": -10,
      "name": "Plant_Moss_Block_Green"
    },
    {
      "x": -14,
      "y": -10,
      "z": -10,
      "name": "Plant_Moss_Rug_Green"
    },
    {
      "x": -14,
      "y": -11,
      "z": -9,
      "name": "Plant_Moss_Wall_Green"
    },
    {
      "x": -13,
      "y": -2,
      "z": -21,
      "name": "Plant_Moss_Block_Green"
    },
    {
      "x": -13,
      "y": -1,
      "z": -21,
      "name": "Rock_Calcite"
    },
    {
      "x": -13,
      "y": 0,
      "z": -21,
      "name": "Rock_Calcite"
    },
    {
      "x": -13,
      "y": -3,
      "z": -20,
      "name": "Plant_Moss_Block_Green"
    },
    {
      "x": -13,
      "y": -2,
      "z": -20,
      "name": "Plant_Moss_Block_Green"
    },
    {
      "x": -13,
      "y": -1,
      "z": -20,
      "name": "Rock_Marble"
    },
    {
      "x": -13,
      "y": 0,
      "z": -20,
      "name": "Rock_Marble"
    },
    {
      "x": -13,
      "y": 1,
      "z": -20,
      "name": "Rock_Marble"
    },
    {
      "x": -13,
      "y": 2,
      "z": -20,
      "name": "Rock_Marble"
    },
    {
      "x": -13,
      "y": -3,
      "z": -19,
      "name": "Plant_Moss_Block_Green"
    },
    {
      "x": -13,
      "y": -2,
      "z": -19,
      "name": "Plant_Moss_Block_Green"
    },
    {
      "x": -13,
      "y": -1,
      "z": -19,
      "name": "Rock_Marble"
    },
    {
      "x": -13,
      "y": 0,
      "z": -19,
      "name": "Rock_Marble"
    },
    {
      "x": -13,
      "y": 1,
      "z": -19,
      "name": "Rock_Marble"
    },
    {
      "x": -13,
      "y": 2,
      "z": -19,
      "name": "Rock_Marble"
    },
    {
      "x": -13,
      "y": 3,
      "z": -19,
      "name": "Rock_Marble"
    },
    {
      "x": -13,
      "y": 4,
      "z": -19,
      "name": "Plant_Moss_Block_Green"
    },
    {
      "x": -13,
      "y": -3,
      "z": -18,
      "name": "Plant_Moss_Wall_Green"
    },
    {
      "x": -13,
      "y": -2,
      "z": -18,
      "name": "Rock_Stone"
    },
    {
      "x": -13,
      "y": -1,
      "z": -18,
      "name": "Rock_Marble"
    },
    {
      "x": -13,
      "y": 0,
      "z": -18,
      "name": "Rock_Marble"
    },
    {
      "x": -13,
      "y": 1,
      "z": -18,
      "name": "Rock_Marble"
    },
    {
      "x": -13,
      "y": 2,
      "z": -18,
      "name": "Rock_Marble"
    },
    {
      "x": -13,
      "y": 3,
      "z": -18,
      "name": "Rock_Marble"
    },
    {
      "x": -13,
      "y": 4,
      "z": -18,
      "name": "Rock_Marble"
    },
    {
      "x": -13,
      "y": 5,
      "z": -18,
      "name": "Plant_Moss_Block_Green"
    },
    {
      "x": -13,
      "y": -8,
      "z": -17,
      "name": "Plant_Moss_Block_Green"
    },
    {
      "x": -13,
      "y": -2,
      "z": -17,
      "name": "Rock_Stone"
    },
    {
      "x": -13,
      "y": -1,
      "z": -17,
      "name": "Rock_Stone"
    },
    {
      "x": -13,
      "y": 0,
      "z": -17,
      "name": "Rock_Stone"
    },
    {
      "x": -13,
      "y": 1,
      "z": -17,
      "name": "Rock_Stone"
    },
    {
      "x": -13,
      "y": 2,
      "z": -17,
      "name": "Rock_Stone"
    },
    {
      "x": -13,
      "y": 3,
      "z": -17,
      "name": "Rock_Marble"
    },
    {
      "x": -13,
      "y": 4,
      "z": -17,
      "name": "Rock_Marble"
    },
    {
      "x": -13,
      "y": 5,
      "z": -17,
      "name": "Rock_Marble"
    },
    {
      "x": -13,
      "y": 6,
      "z": -17,
      "name": "Plant_Moss_Block_Green"
    },
    {
      "x": -13,
      "y": -9,
      "z": -16,
      "name": "Plant_Moss_Block_Green"
    },
    {
      "x": -13,
      "y": -8,
      "z": -16,
      "name": "Plant_Moss_Block_Green"
    },
    {
      "x": -13,
      "y": 3,
      "z": -16,
      "name": "Rock_Stone"
    },
    {
      "x": -13,
      "y": 4,
      "z": -16,
      "name": "Rock_Stone"
    },
    {
      "x": -13,
      "y": 5,
      "z": -16,
      "name": "Rock_Marble"
    },
    {
      "x": -13,
      "y": 6,
      "z": -16,
      "name": "Plant_Moss_Block_Green"
    },
    {
      "x": -13,
      "y": 7,
      "z": -16,
      "name": "Plant_Moss_Block_Green"
    },
    {
      "x": -13,
      "y": -10,
      "z": -15,
      "name": "Rock_Marble"
    },
    {
      "x": -13,
      "y": -9,
      "z": -15,
      "name": "Plant_Moss_Block_Green"
    },
    {
      "x": -13,
      "y": -8,
      "z": -15,
      "name": "Plant_Moss_Rug_Green"
    },
    {
      "x": -13,
      "y": 5,
      "z": -15,
      "name": "Rock_Stone"
    },
    {
      "x": -13,
      "y": 6,
      "z": -15,
      "name": "Plant_Moss_Block_Green"
    },
    {
      "x": -13,
      "y": 7,
      "z": -15,
      "name": "Plant_Moss_Block_Green"
    },
    {
      "x": -13,
      "y": -10,
      "z": -14,
      "name": "Rock_Marble"
    },
    {
      "x": -13,
      "y": -9,
      "z": -14,
      "name": "Soil_Grass_Wet"
    },
    {
      "x": -13,
      "y": -8,
      "z": -14,
      "name": "Plant_Grass_Wet"
    },
    {
      "x": -13,
      "y": 6,
      "z": -14,
      "name": "Rock_Stone"
    },
    {
      "x": -13,
      "y": 7,
      "z": -14,
      "name": "Plant_Moss_Block_Green"
    },
    {
      "x": -13,
      "y": 8,
      "z": -14,
      "name": "Plant_Moss_Block_Green"
    },
    {
      "x": -13,
      "y": -11,
      "z": -13,
      "name": "Rock_Marble"
    },
    {
      "x": -13,
      "y": -10,
      "z": -13,
      "name": "Plant_Moss_Block_Green"
    },
    {
      "x": -13,
      "y": -9,
      "z": -13,
      "name": "Rock_Stone"
    },
    {
      "x": -13,
      "y": 7,
      "z": -13,
      "name": "Plant_Moss_Block_Green"
    },
    {
      "x": -13,
      "y": -11,
      "z": -12,
      "name": "Plant_Moss_Block_Green"
    },
    {
      "x": -13,
      "y": -10,
      "z": -12,
      "name": "Rock_Stone"
    },
    {
      "x": -13,
      "y": -11,
      "z": -11,
      "name": "Plant_Moss_Block_Green"
    },
    {
      "x": -13,
      "y": -10,
      "z": -11,
      "name": "Plant_Moss_Rug_Green"
    },
    {
      "x": -13,
      "y": -11,
      "z": -10,
      "name": "Plant_Moss_Block_Green"
    },
    {
      "x": -13,
      "y": -10,
      "z": -10,
      "name": "Plant_Moss_Rug_Green"
    },
    {
      "x": -13,
      "y": -11,
      "z": -9,
      "name": "Plant_Moss_Wall_Green"
    },
    {
      "x": -12,
      "y": -2,
      "z": -22,
      "name": "Rock_Calcite"
    },
    {
      "x": -12,
      "y": -1,
      "z": -22,
      "name": "Rock_Calcite"
    },
    {
      "x": -12,
      "y": 0,
      "z": -22,
      "name": "Rock_Calcite"
    },
    {
      "x": -12,
      "y": -3,
      "z": -21,
      "name": "Plant_Moss_Block_Green"
    },
    {
      "x": -12,
      "y": -2,
      "z": -21,
      "name": "Plant_Moss_Block_Green"
    },
    {
      "x": -12,
      "y": -1,
      "z": -21,
      "name": "Rock_Marble"
    },
    {
      "x": -12,
      "y": 0,
      "z": -21,
      "name": "Rock_Calcite"
    },
    {
      "x": -12,
      "y": 1,
      "z": -21,
      "name": "Rock_Marble"
    },
    {
      "x": -12,
      "y": 2,
      "z": -21,
      "name": "Rock_Marble"
    },
    {
      "x": -12,
      "y": -3,
      "z": -20,
      "name": "Plant_Moss_Block_Green"
    },
    {
      "x": -12,
      "y": -2,
      "z": -20,
      "name": "Plant_Moss_Block_Green"
    },
    {
      "x": -12,
      "y": -1,
      "z": -20,
      "name": "Rock_Marble"
    },
    {
      "x": -12,
      "y": 0,
      "z": -20,
      "name": "Rock_Marble"
    },
    {
      "x": -12,
      "y": 1,
      "z": -20,
      "name": "Rock_Marble"
    },
    {
      "x": -12,
      "y": 2,
      "z": -20,
      "name": "Rock_Marble"
    },
    {
      "x": -12,
      "y": 3,
      "z": -20,
      "name": "Rock_Marble"
    },
    {
      "x": -12,
      "y": -8,
      "z": -19,
      "name": "Plant_Moss_Wall_Green",
      "rotation": 3
    },
    {
      "x": -12,
      "y": -2,
      "z": -19,
      "name": "Rock_Stone"
    },
    {
      "x": -12,
      "y": -1,
      "z": -19,
      "name": "Rock_Marble"
    },
    {
      "x": -12,
      "y": 0,
      "z": -19,
      "name": "Rock_Marble"
    },
    {
      "x": -12,
      "y": 1,
      "z": -19,
      "name": "Rock_Marble"
    },
    {
      "x": -12,
      "y": 2,
      "z": -19,
      "name": "Rock_Marble"
    },
    {
      "x": -12,
      "y": 3,
      "z": -19,
      "name": "Rock_Marble"
    },
    {
      "x": -12,
      "y": 4,
      "z": -19,
      "name": "Rock_Marble"
    },
    {
      "x": -12,
      "y": -8,
      "z": -18,
      "name": "Plant_Moss_Block_Green"
    },
    {
      "x": -12,
      "y": -2,
      "z": -18,
      "name": "Rock_Stone"
    },
    {
      "x": -12,
      "y": -1,
      "z": -18,
      "name": "Rock_Stone"
    },
    {
      "x": -12,
      "y": 0,
      "z": -18,
      "name": "Rock_Stone"
    },
    {
      "x": -12,
      "y": 1,
      "z": -18,
      "name": "Rock_Stone"
    },
    {
      "x": -12,
      "y": 2,
      "z": -18,
      "name": "Rock_Stone"
    },
    {
      "x": -12,
      "y": 3,
      "z": -18,
      "name": "Rock_Marble"
    },
    {
      "x": -12,
      "y": 4,
      "z": -18,
      "name": "Rock_Marble"
    },
    {
      "x": -12,
      "y": 5,
      "z": -18,
      "name": "Rock_Marble"
    },
    {
      "x": -12,
      "y": -9,
      "z": -17,
      "name": "Rock_Marble"
    },
    {
      "x": -12,
      "y": -8,
      "z": -17,
      "name": "Plant_Moss_Block_Green"
    },
    {
      "x": -12,
      "y": -7,
      "z": -17,
      "name": "Plant_Moss_Rug_Green"
    },
    {
      "x": -12,
      "y": 3,
      "z": -17,
      "name": "Rock_Stone"
    },
    {
      "x": -12,
      "y": 4,
      "z": -17,
      "name": "Rock_Marble"
    },
    {
      "x": -12,
      "y": 5,
      "z": -17,
      "name": "Rock_Marble"
    },
    {
      "x": -12,
      "y": 6,
      "z": -17,
      "name": "Plant_Moss_Block_Green"
    },
    {
      "x": -12,
      "y": -9,
      "z": -16,
      "name": "Soil_Grass_Wet"
    },
    {
      "x": -12,
      "y": -8,
      "z": -16,
      "name": "Plant_Bush"
    },
    {
      "x": -12,
      "y": 4,
      "z": -16,
      "name": "Rock_Stone"
    },
    {
      "x": -12,
      "y": 5,
      "z": -16,
      "name": "Rock_Marble"
    },
    {
      "x": -12,
      "y": 6,
      "z": -16,
      "name": "Plant_Moss_Block_Green"
    },
    {
      "x": -12,
      "y": 7,
      "z": -16,
      "name": "Plant_Moss_Block_Green"
    },
    {
      "x": -12,
      "y": -10,
      "z": -15,
      "name": "Rock_Marble"
    },
    {
      "x": -12,
      "y": -9,
      "z": -15,
      "name": "Soil_Grass_Wet"
    },
    {
      "x": -12,
      "y": -8,
      "z": -15,
      "name": "Plant_Grass_Wet"
    },
    {
      "x": -12,
      "y": 5,
      "z": -15,
      "name": "Rock_Stone"
    },
    {
      "x": -12,
      "y": 6,
      "z": -15,
      "name": "Plant_Moss_Block_Green"
    },
    {
      "x": -12,
      "y": 7,
      "z": -15,
      "name": "Plant_Moss_Block_Green"
    },
    {
      "x": -12,
      "y": 8,
      "z": -15,
      "name": "Plant_Moss_Block_Green"
    },
    {
      "x": -12,
      "y": -11,
      "z": -14,
      "name": "Rock_Marble"
    },
    {
      "x": -12,
      "y": -10,
      "z": -14,
      "name": "Rock_Marble"
    },
    {
      "x": -12,
      "y": -9,
      "z": -14,
      "name": "Soil_Grass_Full"
    },
    {
      "x": -12,
      "y": -8,
      "z": -14,
      "name": "Plant_Grass_Wet"
    },
    {
      "x": -12,
      "y": 6,
      "z": -14,
      "name": "Rock_Stone"
    },
    {
      "x": -12,
      "y": 7,
      "z": -14,
      "name": "Plant_Moss_Block_Green"
    },
    {
      "x": -12,
      "y": 8,
      "z": -14,
      "name": "Plant_Moss_Block_Green"
    },
    {
      "x": -12,
      "y": -12,
      "z": -13,
      "name": "Rock_Marble"
    },
    {
      "x": -12,
      "y": -11,
      "z": -13,
      "name": "Rock_Marble"
    },
    {
      "x": -12,
      "y": -10,
      "z": -13,
      "name": "Soil_Grass_Wet"
    },
    {
      "x": -12,
      "y": 7,
      "z": -13,
      "name": "Plant_Moss_Block_Green"
    },
    {
      "x": -12,
      "y": -12,
      "z": -12,
      "name": "Plant_Moss_Block_Green"
    },
    {
      "x": -12,
      "y": -11,
      "z": -12,
      "name": "Soil_Grass_Wet"
    },
    {
      "x": -12,
      "y": -10,
      "z": -12,
      "name": "Plant_Grass_Lush_Short"
    },
    {
      "x": -12,
      "y": -12,
      "z": -11,
      "name": "Plant_Moss_Block_Green"
    },
    {
      "x": -12,
      "y": -11,
      "z": -11,
      "name": "Soil_Grass_Wet"
    },
    {
      "x": -12,
      "y": -10,
      "z": -11,
      "name": "Plant_Grass_Wet"
    },
    {
      "x": -12,
      "y": -12,
      "z": -10,
      "name": "Plant_Moss_Block_Green"
    },
    {
      "x": -11,
      "y": -2,
      "z": -23,
      "name": "Rock_Calcite"
    },
    {
      "x": -11,
      "y": -1,
      "z": -23,
      "name": "Rock_Calcite"
    },
    {
      "x": -11,
      "y": -3,
      "z": -22,
      "name": "Plant_Moss_Block_Green"
    },
    {
      "x": -11,
      "y": -2,
      "z": -22,
      "name": "Rock_Calcite"
    },
    {
      "x": -11,
      "y": -1,
      "z": -22,
      "name": "Rock_Calcite"
    },
    {
      "x": -11,
      "y": 0,
      "z": -22,
      "name": "Rock_Calcite"
    },
    {
      "x": -11,
      "y": 1,
      "z": -22,
      "name": "Rock_Calcite"
    },
    {
      "x": -11,
      "y": -3,
      "z": -21,
      "name": "Plant_Moss_Block_Green"
    },
    {
      "x": -11,
      "y": -2,
      "z": -21,
      "name": "Plant_Moss_Block_Green"
    },
    {
      "x": -11,
      "y": -1,
      "z": -21,
      "name": "Rock_Marble"
    },
    {
      "x": -11,
      "y": 0,
      "z": -21,
      "name": "Rock_Marble"
    },
    {
      "x": -11,
      "y": 1,
      "z": -21,
      "name": "Rock_Marble"
    },
    {
      "x": -11,
      "y": 2,
      "z": -21,
      "name": "Rock_Marble"
    },
    {
      "x": -11,
      "y": 3,
      "z": -21,
      "name": "Rock_Marble"
    },
    {
      "x": -11,
      "y": -8,
      "z": -20,
      "name": "Plant_Moss_Wall_Green",
      "rotation": 2
    },
    {
      "x": -11,
      "y": -3,
      "z": -20,
      "name": "Rock_Stone"
    },
    {
      "x": -11,
      "y": -2,
      "z": -20,
      "name": "Plant_Moss_Block_Green"
    },
    {
      "x": -11,
      "y": -1,
      "z": -20,
      "name": "Rock_Marble"
    },
    {
      "x": -11,
      "y": 0,
      "z": -20,
      "name": "Rock_Marble"
    },
    {
      "x": -11,
      "y": 1,
      "z": -20,
      "name": "Rock_Marble"
    },
    {
      "x": -11,
      "y": 2,
      "z": -20,
      "name": "Rock_Marble"
    },
    {
      "x": -11,
      "y": 3,
      "z": -20,
      "name": "Rock_Marble"
    },
    {
      "x": -11,
      "y": 4,
      "z": -20,
      "name": "Rock_Marble"
    },
    {
      "x": -11,
      "y": -9,
      "z": -19,
      "name": "Plant_Moss_Cave_Green",
      "rotation": 8
    },
    {
      "x": -11,
      "y": -8,
      "z": -19,
      "name": "Plant_Moss_Block_Green"
    },
    {
      "x": -11,
      "y": -7,
      "z": -19,
      "name": "Plant_Moss_Rug_Green"
    },
    {
      "x": -11,
      "y": -3,
      "z": -19,
      "name": "Rock_Stone"
    },
    {
      "x": -11,
      "y": -2,
      "z": -19,
      "name": "Rock_Stone"
    },
    {
      "x": -11,
      "y": -1,
      "z": -19,
      "name": "Rock_Stone"
    },
    {
      "x": -11,
      "y": 0,
      "z": -19,
      "name": "Rock_Stone"
    },
    {
      "x": -11,
      "y": 1,
      "z": -19,
      "name": "Rock_Stone"
    },
    {
      "x": -11,
      "y": 2,
      "z": -19,
      "name": "Rock_Marble"
    },
    {
      "x": -11,
      "y": 3,
      "z": -19,
      "name": "Rock_Marble"
    },
    {
      "x": -11,
      "y": 4,
      "z": -19,
      "name": "Rock_Marble"
    },
    {
      "x": -11,
      "y": 5,
      "z": -19,
      "name": "Rock_Marble"
    },
    {
      "x": -11,
      "y": -9,
      "z": -18,
      "name": "Rock_Marble"
    },
    {
      "x": -11,
      "y": -8,
      "z": -18,
      "name": "Plant_Moss_Block_Green"
    },
    {
      "x": -11,
      "y": -7,
      "z": -18,
      "name": "Plant_Moss_Rug_Green"
    },
    {
      "x": -11,
      "y": 2,
      "z": -18,
      "name": "Rock_Stone"
    },
    {
      "x": -11,
      "y": 3,
      "z": -18,
      "name": "Rock_Stone"
    },
    {
      "x": -11,
      "y": 4,
      "z": -18,
      "name": "Rock_Marble"
    },
    {
      "x": -11,
      "y": 5,
      "z": -18,
      "name": "Rock_Marble"
    },
    {
      "x": -11,
      "y": 6,
      "z": -18,
      "name": "Rock_Marble"
    },
    {
      "x": -11,
      "y": -9,
      "z": -17,
      "name": "Rock_Marble"
    },
    {
      "x": -11,
      "y": -8,
      "z": -17,
      "name": "Soil_Grass_Full"
    },
    {
      "x": -11,
      "y": -7,
      "z": -17,
      "name": "Plant_Bush"
    },
    {
      "x": -11,
      "y": 4,
      "z": -17,
      "name": "Rock_Stone"
    },
    {
      "x": -11,
      "y": 5,
      "z": -17,
      "name": "Rock_Marble"
    },
    {
      "x": -11,
      "y": 6,
      "z": -17,
      "name": "Rock_Marble"
    },
    {
      "x": -11,
      "y": 7,
      "z": -17,
      "name": "Plant_Moss_Block_Green"
    },
    {
      "x": -11,
      "y": -10,
      "z": -16,
      "name": "Rock_Marble"
    },
    {
      "x": -11,
      "y": -9,
      "z": -16,
      "name": "Soil_Grass_Wet"
    },
    {
      "x": -11,
      "y": -8,
      "z": -16,
      "name": "Plant_Bush"
    },
    {
      "x": -11,
      "y": 5,
      "z": -16,
      "name": "Rock_Stone"
    },
    {
      "x": -11,
      "y": 6,
      "z": -16,
      "name": "Rock_Marble"
    },
    {
      "x": -11,
      "y": 7,
      "z": -16,
      "name": "Plant_Moss_Block_Green"
    },
    {
      "x": -11,
      "y": 8,
      "z": -16,
      "name": "Plant_Moss_Block_Green"
    },
    {
      "x": -11,
      "y": -11,
      "z": -15,
      "name": "Rock_Marble"
    },
    {
      "x": -11,
      "y": -10,
      "z": -15,
      "name": "Rock_Marble"
    },
    {
      "x": -11,
      "y": -9,
      "z": -15,
      "name": "Soil_Grass_Full"
    },
    {
      "x": -11,
      "y": -8,
      "z": -15,
      "name": "Plant_Bush"
    },
    {
      "x": -11,
      "y": 6,
      "z": -15,
      "name": "Rock_Stone"
    },
    {
      "x": -11,
      "y": 7,
      "z": -15,
      "name": "Plant_Moss_Block_Green"
    },
    {
      "x": -11,
      "y": 8,
      "z": -15,
      "name": "Plant_Moss_Block_Green"
    },
    {
      "x": -11,
      "y": -12,
      "z": -14,
      "name": "Rock_Marble"
    },
    {
      "x": -11,
      "y": -11,
      "z": -14,
      "name": "Rock_Marble"
    },
    {
      "x": -11,
      "y": -10,
      "z": -14,
      "name": "Soil_Grass_Wet"
    },
    {
      "x": -11,
      "y": 7,
      "z": -14,
      "name": "Rock_Stone"
    },
    {
      "x": -11,
      "y": -12,
      "z": -13,
      "name": "Rock_Marble"
    },
    {
      "x": -11,
      "y": -11,
      "z": -13,
      "name": "Rock_Marble"
    },
    {
      "x": -11,
      "y": -10,
      "z": -13,
      "name": "Soil_Grass_Wet"
    },
    {
      "x": -11,
      "y": -13,
      "z": -12,
      "name": "Rock_Marble"
    },
    {
      "x": -11,
      "y": -12,
      "z": -12,
      "name": "Plant_Moss_Block_Green"
    },
    {
      "x": -11,
      "y": -11,
      "z": -12,
      "name": "Soil_Grass_Full"
    },
    {
      "x": -11,
      "y": -10,
      "z": -12,
      "name": "Plant_Grass_Lush_Short"
    },
    {
      "x": -11,
      "y": -13,
      "z": -11,
      "name": "Plant_Moss_Block_Green"
    },
    {
      "x": -11,
      "y": -12,
      "z": -11,
      "name": "Soil_Grass_Wet"
    },
    {
      "x": -11,
      "y": -11,
      "z": -11,
      "name": "Plant_Grass_Wet"
    },
    {
      "x": -11,
      "y": -13,
      "z": -10,
      "name": "Plant_Moss_Block_Green"
    },
    {
      "x": -10,
      "y": -3,
      "z": -23,
      "name": "Plant_Moss_Block_Green"
    },
    {
      "x": -10,
      "y": -2,
      "z": -23,
      "name": "Rock_Calcite"
    },
    {
      "x": -10,
      "y": -1,
      "z": -23,
      "name": "Rock_Calcite"
    },
    {
      "x": -10,
      "y": 0,
      "z": -23,
      "name": "Rock_Calcite"
    },
    {
      "x": -10,
      "y": 1,
      "z": -23,
      "name": "Rock_Calcite"
    },
    {
      "x": -10,
      "y": -4,
      "z": -22,
      "name": "Plant_Moss_Block_Green"
    },
    {
      "x": -10,
      "y": -3,
      "z": -22,
      "name": "Plant_Moss_Block_Green"
    },
    {
      "x": -10,
      "y": -2,
      "z": -22,
      "name": "Rock_Marble"
    },
    {
      "x": -10,
      "y": -1,
      "z": -22,
      "name": "Rock_Marble"
    },
    {
      "x": -10,
      "y": 0,
      "z": -22,
      "name": "Rock_Calcite"
    },
    {
      "x": -10,
      "y": 1,
      "z": -22,
      "name": "Rock_Calcite"
    },
    {
      "x": -10,
      "y": 2,
      "z": -22,
      "name": "Rock_Calcite"
    },
    {
      "x": -10,
      "y": -4,
      "z": -21,
      "name": "Plant_Moss_Block_Green"
    },
    {
      "x": -10,
      "y": -3,
      "z": -21,
      "name": "Plant_Moss_Block_Green"
    },
    {
      "x": -10,
      "y": -2,
      "z": -21,
      "name": "Rock_Marble"
    },
    {
      "x": -10,
      "y": -1,
      "z": -21,
      "name": "Rock_Marble"
    },
    {
      "x": -10,
      "y": 0,
      "z": -21,
      "name": "Rock_Marble"
    },
    {
      "x": -10,
      "y": 1,
      "z": -21,
      "name": "Rock_Marble"
    },
    {
      "x": -10,
      "y": 2,
      "z": -21,
      "name": "Rock_Marble"
    },
    {
      "x": -10,
      "y": 3,
      "z": -21,
      "name": "Rock_Marble"
    },
    {
      "x": -10,
      "y": -8,
      "z": -20,
      "name": "Plant_Moss_Wall_Green",
      "rotation": 2
    },
    {
      "x": -10,
      "y": -3,
      "z": -20,
      "name": "Rock_Stone"
    },
    {
      "x": -10,
      "y": -2,
      "z": -20,
      "name": "Rock_Stone"
    },
    {
      "x": -10,
      "y": -1,
      "z": -20,
      "name": "Rock_Stone"
    },
    {
      "x": -10,
      "y": 0,
      "z": -20,
      "name": "Rock_Stone"
    },
    {
      "x": -10,
      "y": 1,
      "z": -20,
      "name": "Rock_Stone"
    },
    {
      "x": -10,
      "y": 2,
      "z": -20,
      "name": "Rock_Marble"
    },
    {
      "x": -10,
      "y": 3,
      "z": -20,
      "name": "Rock_Marble"
    },
    {
      "x": -10,
      "y": 4,
      "z": -20,
      "name": "Rock_Marble"
    },
    {
      "x": -10,
      "y": -8,
      "z": -19,
      "name": "Plant_Moss_Block_Green"
    },
    {
      "x": -10,
      "y": -7,
      "z": -19,
      "name": "Plant_Moss_Rug_Green"
    },
    {
      "x": -10,
      "y": 2,
      "z": -19,
      "name": "Rock_Stone"
    },
    {
      "x": -10,
      "y": 3,
      "z": -19,
      "name": "Rock_Marble"
    },
    {
      "x": -10,
      "y": 4,
      "z": -19,
      "name": "Rock_Marble"
    },
    {
      "x": -10,
      "y": 5,
      "z": -19,
      "name": "Rock_Marble"
    },
    {
      "x": -10,
      "y": 6,
      "z": -19,
      "name": "Rock_Marble"
    },
    {
      "x": -10,
      "y": -9,
      "z": -18,
      "name": "Plant_Moss_Block_Green"
    },
    {
      "x": -10,
      "y": -8,
      "z": -18,
      "name": "Soil_Grass_Full"
    },
    {
      "x": -10,
      "y": -7,
      "z": -18,
      "name": "Plant_Grass_Wet_Short"
    },
    {
      "x": -10,
      "y": 3,
      "z": -18,
      "name": "Rock_Stone"
    },
    {
      "x": -10,
      "y": 4,
      "z": -18,
      "name": "Rock_Marble"
    },
    {
      "x": -10,
      "y": 5,
      "z": -18,
      "name": "Rock_Marble"
    },
    {
      "x": -10,
      "y": 6,
      "z": -18,
      "name": "Rock_Marble"
    },
    {
      "x": -10,
      "y": 7,
      "z": -18,
      "name": "Plant_Moss_Block_Green"
    },
    {
      "x": -10,
      "y": -10,
      "z": -17,
      "name": "Rock_Marble"
    },
    {
      "x": -10,
      "y": -9,
      "z": -17,
      "name": "Soil_Grass_Wet"
    },
    {
      "x": -10,
      "y": 4,
      "z": -17,
      "name": "Rock_Stone"
    },
    {
      "x": -10,
      "y": 5,
      "z": -17,
      "name": "Rock_Marble"
    },
    {
      "x": -10,
      "y": 6,
      "z": -17,
      "name": "Plant_Moss_Block_Green"
    },
    {
      "x": -10,
      "y": 7,
      "z": -17,
      "name": "Plant_Moss_Block_Green"
    },
    {
      "x": -10,
      "y": 8,
      "z": -17,
      "name": "Plant_Moss_Block_Green"
    },
    {
      "x": -10,
      "y": -11,
      "z": -16,
      "name": "Rock_Marble"
    },
    {
      "x": -10,
      "y": -10,
      "z": -16,
      "name": "Rock_Marble"
    },
    {
      "x": -10,
      "y": -9,
      "z": -16,
      "name": "Soil_Grass_Wet"
    },
    {
      "x": -10,
      "y": -8,
      "z": -16,
      "name": "Plant_Bush"
    },
    {
      "x": -10,
      "y": 5,
      "z": -16,
      "name": "Rock_Stone"
    },
    {
      "x": -10,
      "y": 6,
      "z": -16,
      "name": "Rock_Stone"
    },
    {
      "x": -10,
      "y": 7,
      "z": -16,
      "name": "Plant_Moss_Block_Green"
    },
    {
      "x": -10,
      "y": 8,
      "z": -16,
      "name": "Plant_Moss_Block_Green"
    },
    {
      "x": -10,
      "y": 9,
      "z": -16,
      "name": "Plant_Moss_Rug_Green"
    },
    {
      "x": -10,
      "y": -12,
      "z": -15,
      "name": "Rock_Marble"
    },
    {
      "x": -10,
      "y": -11,
      "z": -15,
      "name": "Rock_Marble"
    },
    {
      "x": -10,
      "y": -10,
      "z": -15,
      "name": "Rock_Marble"
    },
    {
      "x": -10,
      "y": -9,
      "z": -15,
      "name": "Soil_Grass_Full"
    },
    {
      "x": -10,
      "y": 7,
      "z": -15,
      "name": "Rock_Stone"
    },
    {
      "x": -10,
      "y": -13,
      "z": -14,
      "name": "Rock_Marble"
    },
    {
      "x": -10,
      "y": -12,
      "z": -14,
      "name": "Rock_Marble"
    },
    {
      "x": -10,
      "y": -11,
      "z": -14,
      "name": "Rock_Marble"
    },
    {
      "x": -10,
      "y": -10,
      "z": -14,
      "name": "Soil_Grass_Full"
    },
    {
      "x": -10,
      "y": -9,
      "z": -14,
      "name": "Plant_Grass_Lush_Short"
    },
    {
      "x": -10,
      "y": -13,
      "z": -13,
      "name": "Rock_Marble"
    },
    {
      "x": -10,
      "y": -12,
      "z": -13,
      "name": "Rock_Marble"
    },
    {
      "x": -10,
      "y": -11,
      "z": -13,
      "name": "Soil_Grass_Full"
    },
    {
      "x": -10,
      "y": -10,
      "z": -13,
      "name": "Plant_Grass_Wet"
    },
    {
      "x": -10,
      "y": -14,
      "z": -12,
      "name": "Rock_Marble"
    },
    {
      "x": -10,
      "y": -13,
      "z": -12,
      "name": "Rock_Marble"
    },
    {
      "x": -10,
      "y": -12,
      "z": -12,
      "name": "Soil_Grass_Full"
    },
    {
      "x": -10,
      "y": -11,
      "z": -12,
      "name": "Plant_Grass_Wet"
    },
    {
      "x": -10,
      "y": -14,
      "z": -11,
      "name": "Rock_Calcite"
    },
    {
      "x": -10,
      "y": -13,
      "z": -11,
      "name": "Soil_Grass_Wet"
    },
    {
      "x": -10,
      "y": -12,
      "z": -11,
      "name": "Plant_Grass_Wet"
    },
    {
      "x": -10,
      "y": -14,
      "z": -10,
      "name": "Rock_Calcite"
    },
    {
      "x": -9,
      "y": -3,
      "z": -24,
      "name": "Rock_Calcite"
    },
    {
      "x": -9,
      "y": -2,
      "z": -24,
      "name": "Rock_Calcite"
    },
    {
      "x": -9,
      "y": -1,
      "z": -24,
      "name": "Rock_Calcite"
    },
    {
      "x": -9,
      "y": 0,
      "z": -24,
      "name": "Rock_Calcite"
    },
    {
      "x": -9,
      "y": -4,
      "z": -23,
      "name": "Plant_Moss_Block_Green"
    },
    {
      "x": -9,
      "y": -3,
      "z": -23,
      "name": "Plant_Moss_Block_Green"
    },
    {
      "x": -9,
      "y": -2,
      "z": -23,
      "name": "Rock_Calcite"
    },
    {
      "x": -9,
      "y": -1,
      "z": -23,
      "name": "Rock_Calcite"
    },
    {
      "x": -9,
      "y": 0,
      "z": -23,
      "name": "Rock_Calcite"
    },
    {
      "x": -9,
      "y": 1,
      "z": -23,
      "name": "Rock_Calcite"
    },
    {
      "x": -9,
      "y": 2,
      "z": -23,
      "name": "Rock_Calcite"
    },
    {
      "x": -9,
      "y": -4,
      "z": -22,
      "name": "Plant_Moss_Block_Green"
    },
    {
      "x": -9,
      "y": -3,
      "z": -22,
      "name": "Plant_Moss_Block_Green"
    },
    {
      "x": -9,
      "y": -2,
      "z": -22,
      "name": "Rock_Marble"
    },
    {
      "x": -9,
      "y": -1,
      "z": -22,
      "name": "Rock_Marble"
    },
    {
      "x": -9,
      "y": 0,
      "z": -22,
      "name": "Rock_Calcite"
    },
    {
      "x": -9,
      "y": 1,
      "z": -22,
      "name": "Rock_Calcite"
    },
    {
      "x": -9,
      "y": 2,
      "z": -22,
      "name": "Rock_Calcite"
    },
    {
      "x": -9,
      "y": 3,
      "z": -22,
      "name": "Rock_Calcite"
    },
    {
      "x": -9,
      "y": -4,
      "z": -21,
      "name": "Plant_Moss_Block_Green"
    },
    {
      "x": -9,
      "y": -3,
      "z": -21,
      "name": "Plant_Moss_Block_Green"
    },
    {
      "x": -9,
      "y": -2,
      "z": -21,
      "name": "Rock_Stone"
    },
    {
      "x": -9,
      "y": -1,
      "z": -21,
      "name": "Rock_Stone"
    },
    {
      "x": -9,
      "y": 0,
      "z": -21,
      "name": "Rock_Stone"
    },
    {
      "x": -9,
      "y": 1,
      "z": -21,
      "name": "Rock_Marble"
    },
    {
      "x": -9,
      "y": 2,
      "z": -21,
      "name": "Rock_Marble"
    },
    {
      "x": -9,
      "y": 3,
      "z": -21,
      "name": "Rock_Marble"
    },
    {
      "x": -9,
      "y": 4,
      "z": -21,
      "name": "Plant_Moss_Block_Green"
    },
    {
      "x": -9,
      "y": -8,
      "z": -20,
      "name": "Plant_Moss_Block_Green"
    },
    {
      "x": -9,
      "y": -4,
      "z": -20,
      "name": "Plant_Moss_Block_Green"
    },
    {
      "x": -9,
      "y": -3,
      "z": -20,
      "name": "Rock_Stone"
    },
    {
      "x": -9,
      "y": 1,
      "z": -20,
      "name": "Rock_Stone"
    },
    {
      "x": -9,
      "y": 2,
      "z": -20,
      "name": "Rock_Stone"
    },
    {
      "x": -9,
      "y": 3,
      "z": -20,
      "name": "Rock_Marble"
    },
    {
      "x": -9,
      "y": 4,
      "z": -20,
      "name": "Rock_Marble"
    },
    {
      "x": -9,
      "y": 5,
      "z": -20,
      "name": "Rock_Marble"
    },
    {
      "x": -9,
      "y": -9,
      "z": -19,
      "name": "Plant_Moss_Block_Green"
    },
    {
      "x": -9,
      "y": -8,
      "z": -19,
      "name": "Soil_Grass_Full"
    },
    {
      "x": -9,
      "y": -7,
      "z": -19,
      "name": "Plant_Grass_Wet_Short"
    },
    {
      "x": -9,
      "y": 3,
      "z": -19,
      "name": "Rock_Stone"
    },
    {
      "x": -9,
      "y": 4,
      "z": -19,
      "name": "Rock_Marble"
    },
    {
      "x": -9,
      "y": 5,
      "z": -19,
      "name": "Rock_Marble"
    },
    {
      "x": -9,
      "y": 6,
      "z": -19,
      "name": "Rock_Marble"
    },
    {
      "x": -9,
      "y": -10,
      "z": -18,
      "name": "Plant_Moss_Block_Green"
    },
    {
      "x": -9,
      "y": -9,
      "z": -18,
      "name": "Soil_Grass_Wet"
    },
    {
      "x": -9,
      "y": 4,
      "z": -18,
      "name": "Rock_Stone"
    },
    {
      "x": -9,
      "y": 5,
      "z": -18,
      "name": "Rock_Marble"
    },
    {
      "x": -9,
      "y": 6,
      "z": -18,
      "name": "Rock_Marble"
    },
    {
      "x": -9,
      "y": 7,
      "z": -18,
      "name": "Plant_Moss_Block_Green"
    },
    {
      "x": -9,
      "y": 8,
      "z": -18,
      "name": "Plant_Moss_Block_Green"
    },
    {
      "x": -9,
      "y": -11,
      "z": -17,
      "name": "Rock_Marble"
    },
    {
      "x": -9,
      "y": -10,
      "z": -17,
      "name": "Rock_Marble"
    },
    {
      "x": -9,
      "y": -9,
      "z": -17,
      "name": "Soil_Grass_Wet"
    },
    {
      "x": -9,
      "y": 5,
      "z": -17,
      "name": "Rock_Stone"
    },
    {
      "x": -9,
      "y": 6,
      "z": -17,
      "name": "Plant_Moss_Block_Green"
    },
    {
      "x": -9,
      "y": 7,
      "z": -17,
      "name": "Plant_Moss_Block_Green"
    },
    {
      "x": -9,
      "y": 8,
      "z": -17,
      "name": "Plant_Moss_Block_Green"
    },
    {
      "x": -9,
      "y": 9,
      "z": -17,
      "name": "Plant_Moss_Rug_Green"
    },
    {
      "x": -9,
      "y": -12,
      "z": -16,
      "name": "Rock_Marble"
    },
    {
      "x": -9,
      "y": -11,
      "z": -16,
      "name": "Rock_Marble"
    },
    {
      "x": -9,
      "y": -10,
      "z": -16,
      "name": "Rock_Marble"
    },
    {
      "x": -9,
      "y": -9,
      "z": -16,
      "name": "Soil_Grass_Full"
    },
    {
      "x": -9,
      "y": -8,
      "z": -16,
      "name": "Plant_Grass_Lush_Short"
    },
    {
      "x": -9,
      "y": 6,
      "z": -16,
      "name": "Rock_Stone"
    },
    {
      "x": -9,
      "y": 7,
      "z": -16,
      "name": "Plant_Moss_Block_Green"
    },
    {
      "x": -9,
      "y": -13,
      "z": -15,
      "name": "Rock_Marble"
    },
    {
      "x": -9,
      "y": -12,
      "z": -15,
      "name": "Rock_Marble"
    },
    {
      "x": -9,
      "y": -11,
      "z": -15,
      "name": "Rock_Marble"
    },
    {
      "x": -9,
      "y": -10,
      "z": -15,
      "name": "Soil_Grass_Full"
    },
    {
      "x": -9,
      "y": 7,
      "z": -15,
      "name": "Rock_Stone"
    },
    {
      "x": -9,
      "y": -14,
      "z": -14,
      "name": "Rock_Marble"
    },
    {
      "x": -9,
      "y": -13,
      "z": -14,
      "name": "Rock_Marble"
    },
    {
      "x": -9,
      "y": -12,
      "z": -14,
      "name": "Rock_Marble"
    },
    {
      "x": -9,
      "y": -11,
      "z": -14,
      "name": "Soil_Grass_Full"
    },
    {
      "x": -9,
      "y": -10,
      "z": -14,
      "name": "Plant_Grass_Wet"
    },
    {
      "x": -9,
      "y": 11,
      "z": -14,
      "name": "Rock_Marble"
    },
    {
      "x": -9,
      "y": -15,
      "z": -13,
      "name": "Plant_Moss_Block_Green"
    },
    {
      "x": -9,
      "y": -14,
      "z": -13,
      "name": "Rock_Marble"
    },
    {
      "x": -9,
      "y": -13,
      "z": -13,
      "name": "Rock_Marble"
    },
    {
      "x": -9,
      "y": -12,
      "z": -13,
      "name": "Soil_Grass_Full"
    },
    {
      "x": -9,
      "y": -11,
      "z": -13,
      "name": "Plant_Grass_Wet"
    },
    {
      "x": -9,
      "y": 11,
      "z": -13,
      "name": "Rock_Marble"
    },
    {
      "x": -9,
      "y": -15,
      "z": -12,
      "name": "Plant_Moss_Block_Green"
    },
    {
      "x": -9,
      "y": -14,
      "z": -12,
      "name": "Plant_Moss_Block_Green"
    },
    {
      "x": -9,
      "y": -13,
      "z": -12,
      "name": "Soil_Grass_Full"
    },
    {
      "x": -9,
      "y": -12,
      "z": -12,
      "name": "Plant_Grass_Wet"
    },
    {
      "x": -9,
      "y": 12,
      "z": -12,
      "name": "Rock_Marble"
    },
    {
      "x": -9,
      "y": -15,
      "z": -11,
      "name": "Plant_Moss_Block_Green"
    },
    {
      "x": -9,
      "y": -14,
      "z": -11,
      "name": "Soil_Grass_Wet"
    },
    {
      "x": -9,
      "y": -13,
      "z": -11,
      "name": "Plant_Grass_Wet_Short"
    },
    {
      "x": -9,
      "y": 12,
      "z": -11,
      "name": "Rock_Chalk"
    },
    {
      "x": -9,
      "y": -15,
      "z": -10,
      "name": "Plant_Moss_Block_Green"
    },
    {
      "x": -9,
      "y": 12,
      "z": -10,
      "name": "Rock_Chalk"
    },
    {
      "x": -9,
      "y": 12,
      "z": -9,
      "name": "Rock_Chalk"
    },
    {
      "x": -8,
      "y": -1,
      "z": -25,
      "name": "Rock_Marble"
    },
    {
      "x": -8,
      "y": -3,
      "z": -24,
      "name": "Rock_Calcite"
    },
    {
      "x": -8,
      "y": -2,
      "z": -24,
      "name": "Rock_Calcite"
    },
    {
      "x": -8,
      "y": -1,
      "z": -24,
      "name": "Rock_Calcite"
    },
    {
      "x": -8,
      "y": 0,
      "z": -24,
      "name": "Rock_Calcite"
    },
    {
      "x": -8,
      "y": 1,
      "z": -24,
      "name": "Rock_Calcite"
    },
    {
      "x": -8,
      "y": -4,
      "z": -23,
      "name": "Plant_Moss_Block_Green"
    },
    {
      "x": -8,
      "y": -3,
      "z": -23,
      "name": "Rock_Calcite"
    },
    {
      "x": -8,
      "y": -2,
      "z": -23,
      "name": "Rock_Calcite"
    },
    {
      "x": -8,
      "y": -1,
      "z": -23,
      "name": "Rock_Calcite"
    },
    {
      "x": -8,
      "y": 0,
      "z": -23,
      "name": "Rock_Calcite"
    },
    {
      "x": -8,
      "y": 1,
      "z": -23,
      "name": "Rock_Calcite"
    },
    {
      "x": -8,
      "y": 2,
      "z": -23,
      "name": "Rock_Calcite"
    },
    {
      "x": -8,
      "y": -4,
      "z": -22,
      "name": "Plant_Moss_Block_Green"
    },
    {
      "x": -8,
      "y": -3,
      "z": -22,
      "name": "Plant_Moss_Block_Green"
    },
    {
      "x": -8,
      "y": -2,
      "z": -22,
      "name": "Rock_Marble"
    },
    {
      "x": -8,
      "y": -1,
      "z": -22,
      "name": "Rock_Calcite"
    },
    {
      "x": -8,
      "y": 0,
      "z": -22,
      "name": "Rock_Calcite"
    },
    {
      "x": -8,
      "y": 1,
      "z": -22,
      "name": "Rock_Calcite"
    },
    {
      "x": -8,
      "y": 2,
      "z": -22,
      "name": "Rock_Calcite"
    },
    {
      "x": -8,
      "y": 3,
      "z": -22,
      "name": "Plant_Moss_Block_Green"
    },
    {
      "x": -8,
      "y": 4,
      "z": -22,
      "name": "Plant_Moss_Block_Green"
    },
    {
      "x": -8,
      "y": -8,
      "z": -21,
      "name": "Plant_Moss_Wall_Green",
      "rotation": 2
    },
    {
      "x": -8,
      "y": -4,
      "z": -21,
      "name": "Plant_Moss_Block_Green"
    },
    {
      "x": -8,
      "y": -3,
      "z": -21,
      "name": "Rock_Stone"
    },
    {
      "x": -8,
      "y": -2,
      "z": -21,
      "name": "Rock_Stone"
    },
    {
      "x": -8,
      "y": -1,
      "z": -21,
      "name": "Rock_Stone"
    },
    {
      "x": -8,
      "y": 0,
      "z": -21,
      "name": "Rock_Stone"
    },
    {
      "x": -8,
      "y": 1,
      "z": -21,
      "name": "Rock_Stone"
    },
    {
      "x": -8,
      "y": 2,
      "z": -21,
      "name": "Rock_Marble"
    },
    {
      "x": -8,
      "y": 3,
      "z": -21,
      "name": "Rock_Marble"
    },
    {
      "x": -8,
      "y": 4,
      "z": -21,
      "name": "Rock_Marble"
    },
    {
      "x": -8,
      "y": 5,
      "z": -21,
      "name": "Plant_Moss_Block_Green"
    },
    {
      "x": -8,
      "y": -8,
      "z": -20,
      "name": "Plant_Moss_Block_Green"
    },
    {
      "x": -8,
      "y": -7,
      "z": -20,
      "name": "Plant_Moss_Rug_Green"
    },
    {
      "x": -8,
      "y": -4,
      "z": -20,
      "name": "Plant_Moss_Block_Green"
    },
    {
      "x": -8,
      "y": 2,
      "z": -20,
      "name": "Rock_Stone"
    },
    {
      "x": -8,
      "y": 3,
      "z": -20,
      "name": "Rock_Marble"
    },
    {
      "x": -8,
      "y": 4,
      "z": -20,
      "name": "Rock_Marble"
    },
    {
      "x": -8,
      "y": 5,
      "z": -20,
      "name": "Rock_Marble"
    },
    {
      "x": -8,
      "y": 6,
      "z": -20,
      "name": "Rock_Marble"
    },
    {
      "x": -8,
      "y": -10,
      "z": -19,
      "name": "Plant_Moss_Block_Green"
    },
    {
      "x": -8,
      "y": -9,
      "z": -19,
      "name": "Plant_Moss_Block_Green"
    },
    {
      "x": -8,
      "y": -8,
      "z": -19,
      "name": "Soil_Grass_Full"
    },
    {
      "x": -8,
      "y": 3,
      "z": -19,
      "name": "Rock_Stone"
    },
    {
      "x": -8,
      "y": 4,
      "z": -19,
      "name": "Rock_Marble"
    },
    {
      "x": -8,
      "y": 5,
      "z": -19,
      "name": "Rock_Marble"
    },
    {
      "x": -8,
      "y": 6,
      "z": -19,
      "name": "Rock_Marble"
    },
    {
      "x": -8,
      "y": 7,
      "z": -19,
      "name": "Plant_Moss_Block_Green"
    },
    {
      "x": -8,
      "y": -11,
      "z": -18,
      "name": "Rock_Marble"
    },
    {
      "x": -8,
      "y": -10,
      "z": -18,
      "name": "Plant_Moss_Block_Green"
    },
    {
      "x": -8,
      "y": -9,
      "z": -18,
      "name": "Soil_Grass_Wet"
    },
    {
      "x": -8,
      "y": -8,
      "z": -18,
      "name": "Plant_Bush"
    },
    {
      "x": -8,
      "y": 4,
      "z": -18,
      "name": "Rock_Stone"
    },
    {
      "x": -8,
      "y": 5,
      "z": -18,
      "name": "Rock_Marble"
    },
    {
      "x": -8,
      "y": 6,
      "z": -18,
      "name": "Rock_Marble"
    },
    {
      "x": -8,
      "y": 7,
      "z": -18,
      "name": "Plant_Moss_Block_Green"
    },
    {
      "x": -8,
      "y": 8,
      "z": -18,
      "name": "Plant_Moss_Block_Green"
    },
    {
      "x": -8,
      "y": 9,
      "z": -18,
      "name": "Plant_Moss_Rug_Green"
    },
    {
      "x": -8,
      "y": -12,
      "z": -17,
      "name": "Rock_Marble"
    },
    {
      "x": -8,
      "y": -11,
      "z": -17,
      "name": "Rock_Marble"
    },
    {
      "x": -8,
      "y": -10,
      "z": -17,
      "name": "Rock_Marble"
    },
    {
      "x": -8,
      "y": -9,
      "z": -17,
      "name": "Soil_Grass_Wet"
    },
    {
      "x": -8,
      "y": -8,
      "z": -17,
      "name": "Plant_Grass_Lush_Short"
    },
    {
      "x": -8,
      "y": 5,
      "z": -17,
      "name": "Rock_Stone"
    },
    {
      "x": -8,
      "y": 6,
      "z": -17,
      "name": "Rock_Stone"
    },
    {
      "x": -8,
      "y": 7,
      "z": -17,
      "name": "Plant_Moss_Block_Green"
    },
    {
      "x": -8,
      "y": 8,
      "z": -17,
      "name": "Plant_Moss_Block_Green"
    },
    {
      "x": -8,
      "y": 9,
      "z": -17,
      "name": "Plant_Moss_Rug_Green"
    },
    {
      "x": -8,
      "y": -13,
      "z": -16,
      "name": "Rock_Marble"
    },
    {
      "x": -8,
      "y": -12,
      "z": -16,
      "name": "Rock_Marble"
    },
    {
      "x": -8,
      "y": -11,
      "z": -16,
      "name": "Rock_Marble"
    },
    {
      "x": -8,
      "y": -10,
      "z": -16,
      "name": "Soil_Clay_Red"
    },
    {
      "x": -8,
      "y": -9,
      "z": -16,
      "name": "Soil_Grass_Wet"
    },
    {
      "x": -8,
      "y": -8,
      "z": -16,
      "name": "Plant_Grass_Wet_Short"
    },
    {
      "x": -8,
      "y": 7,
      "z": -16,
      "name": "Rock_Stone"
    },
    {
      "x": -8,
      "y": -14,
      "z": -15,
      "name": "Rock_Marble"
    },
    {
      "x": -8,
      "y": -13,
      "z": -15,
      "name": "Rock_Marble"
    },
    {
      "x": -8,
      "y": -12,
      "z": -15,
      "name": "Rock_Marble"
    },
    {
      "x": -8,
      "y": -11,
      "z": -15,
      "name": "Soil_Grass_Wet"
    },
    {
      "x": -8,
      "y": -10,
      "z": -15,
      "name": "Plant_Grass_Wet"
    },
    {
      "x": -8,
      "y": 11,
      "z": -15,
      "name": "Rock_Marble"
    },
    {
      "x": -8,
      "y": -15,
      "z": -14,
      "name": "Rock_Marble"
    },
    {
      "x": -8,
      "y": -14,
      "z": -14,
      "name": "Rock_Marble"
    },
    {
      "x": -8,
      "y": -13,
      "z": -14,
      "name": "Rock_Marble"
    },
    {
      "x": -8,
      "y": -12,
      "z": -14,
      "name": "Soil_Grass_Full"
    },
    {
      "x": -8,
      "y": -11,
      "z": -14,
      "name": "Plant_Grass_Wet"
    },
    {
      "x": -8,
      "y": 11,
      "z": -14,
      "name": "Rock_Marble"
    },
    {
      "x": -8,
      "y": -16,
      "z": -13,
      "name": "Rock_Marble"
    },
    {
      "x": -8,
      "y": -15,
      "z": -13,
      "name": "Plant_Moss_Block_Green"
    },
    {
      "x": -8,
      "y": -14,
      "z": -13,
      "name": "Rock_Marble"
    },
    {
      "x": -8,
      "y": -13,
      "z": -13,
      "name": "Soil_Grass_Full"
    },
    {
      "x": -8,
      "y": -12,
      "z": -13,
      "name": "Plant_Grass_Wet"
    },
    {
      "x": -8,
      "y": 11,
      "z": -13,
      "name": "Rock_Stone"
    },
    {
      "x": -8,
      "y": 12,
      "z": -13,
      "name": "Rock_Marble"
    },
    {
      "x": -8,
      "y": -17,
      "z": -12,
      "name": "Plant_Moss_Block_Green"
    },
    {
      "x": -8,
      "y": -16,
      "z": -12,
      "name": "Plant_Moss_Block_Green"
    },
    {
      "x": -8,
      "y": -15,
      "z": -12,
      "name": "Plant_Moss_Block_Green"
    },
    {
      "x": -8,
      "y": -14,
      "z": -12,
      "name": "Soil_Grass_Wet"
    },
    {
      "x": -8,
      "y": -13,
      "z": -12,
      "name": "Plant_Grass_Wet"
    },
    {
      "x": -8,
      "y": 11,
      "z": -12,
      "name": "Rock_Stone"
    },
    {
      "x": -8,
      "y": 12,
      "z": -12,
      "name": "Rock_Marble"
    },
    {
      "x": -8,
      "y": -17,
      "z": -11,
      "name": "Plant_Moss_Block_Green"
    },
    {
      "x": -8,
      "y": -16,
      "z": -11,
      "name": "Plant_Moss_Block_Green"
    },
    {
      "x": -8,
      "y": -15,
      "z": -11,
      "name": "Rock_Stone"
    },
    {
      "x": -8,
      "y": 12,
      "z": -11,
      "name": "Rock_Stone"
    },
    {
      "x": -8,
      "y": -17,
      "z": -10,
      "name": "Plant_Moss_Block_Green"
    },
    {
      "x": -8,
      "y": -16,
      "z": -10,
      "name": "Plant_Moss_Block_Green"
    },
    {
      "x": -8,
      "y": 12,
      "z": -10,
      "name": "Rock_Chalk"
    },
    {
      "x": -8,
      "y": -17,
      "z": -9,
      "name": "Plant_Moss_Block_Green"
    },
    {
      "x": -8,
      "y": -16,
      "z": -9,
      "name": "Plant_Moss_Rug_Green"
    },
    {
      "x": -7,
      "y": -2,
      "z": -25,
      "name": "Rock_Marble"
    },
    {
      "x": -7,
      "y": -1,
      "z": -25,
      "name": "Rock_Marble"
    },
    {
      "x": -7,
      "y": 0,
      "z": -25,
      "name": "Rock_Marble"
    },
    {
      "x": -7,
      "y": -4,
      "z": -24,
      "name": "Plant_Moss_Block_Green"
    },
    {
      "x": -7,
      "y": -3,
      "z": -24,
      "name": "Rock_Calcite"
    },
    {
      "x": -7,
      "y": -2,
      "z": -24,
      "name": "Rock_Calcite"
    },
    {
      "x": -7,
      "y": -1,
      "z": -24,
      "name": "Rock_Calcite"
    },
    {
      "x": -7,
      "y": 0,
      "z": -24,
      "name": "Rock_Calcite"
    },
    {
      "x": -7,
      "y": 1,
      "z": -24,
      "name": "Rock_Calcite"
    },
    {
      "x": -7,
      "y": 2,
      "z": -24,
      "name": "Rock_Calcite"
    },
    {
      "x": -7,
      "y": -4,
      "z": -23,
      "name": "Plant_Moss_Block_Green"
    },
    {
      "x": -7,
      "y": -3,
      "z": -23,
      "name": "Rock_Calcite"
    },
    {
      "x": -7,
      "y": -2,
      "z": -23,
      "name": "Rock_Calcite"
    },
    {
      "x": -7,
      "y": -1,
      "z": -23,
      "name": "Rock_Calcite"
    },
    {
      "x": -7,
      "y": 0,
      "z": -23,
      "name": "Rock_Calcite"
    },
    {
      "x": -7,
      "y": 1,
      "z": -23,
      "name": "Rock_Calcite"
    },
    {
      "x": -7,
      "y": 2,
      "z": -23,
      "name": "Rock_Calcite"
    },
    {
      "x": -7,
      "y": 3,
      "z": -23,
      "name": "Rock_Calcite"
    },
    {
      "x": -7,
      "y": -4,
      "z": -22,
      "name": "Plant_Moss_Block_Green"
    },
    {
      "x": -7,
      "y": -3,
      "z": -22,
      "name": "Plant_Moss_Block_Green"
    },
    {
      "x": -7,
      "y": -2,
      "z": -22,
      "name": "Rock_Calcite"
    },
    {
      "x": -7,
      "y": -1,
      "z": -22,
      "name": "Rock_Calcite"
    },
    {
      "x": -7,
      "y": 0,
      "z": -22,
      "name": "Rock_Calcite"
    },
    {
      "x": -7,
      "y": 1,
      "z": -22,
      "name": "Rock_Calcite"
    },
    {
      "x": -7,
      "y": 2,
      "z": -22,
      "name": "Rock_Calcite"
    },
    {
      "x": -7,
      "y": 3,
      "z": -22,
      "name": "Rock_Calcite"
    },
    {
      "x": -7,
      "y": 4,
      "z": -22,
      "name": "Rock_Calcite"
    },
    {
      "x": -7,
      "y": -8,
      "z": -21,
      "name": "Plant_Moss_Wall_Green",
      "rotation": 2
    },
    {
      "x": -7,
      "y": -4,
      "z": -21,
      "name": "Plant_Moss_Block_Green"
    },
    {
      "x": -7,
      "y": -3,
      "z": -21,
      "name": "Rock_Stone"
    },
    {
      "x": -7,
      "y": -2,
      "z": -21,
      "name": "Rock_Stone"
    },
    {
      "x": -7,
      "y": -1,
      "z": -21,
      "name": "Rock_Stone"
    },
    {
      "x": -7,
      "y": 0,
      "z": -21,
      "name": "Rock_Stone"
    },
    {
      "x": -7,
      "y": 1,
      "z": -21,
      "name": "Rock_Stone"
    },
    {
      "x": -7,
      "y": 2,
      "z": -21,
      "name": "Rock_Marble"
    },
    {
      "x": -7,
      "y": 3,
      "z": -21,
      "name": "Rock_Marble"
    },
    {
      "x": -7,
      "y": 4,
      "z": -21,
      "name": "Rock_Marble"
    },
    {
      "x": -7,
      "y": 5,
      "z": -21,
      "name": "Plant_Moss_Block_Green"
    },
    {
      "x": -7,
      "y": -9,
      "z": -20,
      "name": "Plant_Moss_Block_Green"
    },
    {
      "x": -7,
      "y": -8,
      "z": -20,
      "name": "Plant_Moss_Block_Green"
    },
    {
      "x": -7,
      "y": -7,
      "z": -20,
      "name": "Plant_Moss_Rug_Green"
    },
    {
      "x": -7,
      "y": -4,
      "z": -20,
      "name": "Plant_Moss_Block_Green"
    },
    {
      "x": -7,
      "y": 2,
      "z": -20,
      "name": "Rock_Stone"
    },
    {
      "x": -7,
      "y": 3,
      "z": -20,
      "name": "Rock_Stone"
    },
    {
      "x": -7,
      "y": 4,
      "z": -20,
      "name": "Rock_Marble"
    },
    {
      "x": -7,
      "y": 5,
      "z": -20,
      "name": "Rock_Marble"
    },
    {
      "x": -7,
      "y": 6,
      "z": -20,
      "name": "Plant_Moss_Block_Green"
    },
    {
      "x": -7,
      "y": -10,
      "z": -19,
      "name": "Plant_Moss_Block_Green"
    },
    {
      "x": -7,
      "y": -9,
      "z": -19,
      "name": "Plant_Moss_Block_Green"
    },
    {
      "x": -7,
      "y": -8,
      "z": -19,
      "name": "Soil_Grass_Wet"
    },
    {
      "x": -7,
      "y": -7,
      "z": -19,
      "name": "Plant_Bush"
    },
    {
      "x": -7,
      "y": 4,
      "z": -19,
      "name": "Rock_Stone"
    },
    {
      "x": -7,
      "y": 5,
      "z": -19,
      "name": "Rock_Marble"
    },
    {
      "x": -7,
      "y": 6,
      "z": -19,
      "name": "Plant_Moss_Block_Green"
    },
    {
      "x": -7,
      "y": 7,
      "z": -19,
      "name": "Plant_Moss_Block_Green"
    },
    {
      "x": -7,
      "y": -11,
      "z": -18,
      "name": "Rock_Marble"
    },
    {
      "x": -7,
      "y": -10,
      "z": -18,
      "name": "Plant_Moss_Block_Green"
    },
    {
      "x": -7,
      "y": -9,
      "z": -18,
      "name": "Plant_Moss_Block_Green"
    },
    {
      "x": -7,
      "y": -8,
      "z": -18,
      "name": "Soil_Grass_Wet"
    },
    {
      "x": -7,
      "y": -7,
      "z": -18,
      "name": "Plant_Bush"
    },
    {
      "x": -7,
      "y": 5,
      "z": -18,
      "name": "Rock_Stone"
    },
    {
      "x": -7,
      "y": 6,
      "z": -18,
      "name": "Plant_Moss_Block_Green"
    },
    {
      "x": -7,
      "y": 7,
      "z": -18,
      "name": "Plant_Moss_Block_Green"
    },
    {
      "x": -7,
      "y": -12,
      "z": -17,
      "name": "Rock_Marble"
    },
    {
      "x": -7,
      "y": -11,
      "z": -17,
      "name": "Rock_Marble"
    },
    {
      "x": -7,
      "y": -10,
      "z": -17,
      "name": "Rock_Marble"
    },
    {
      "x": -7,
      "y": -9,
      "z": -17,
      "name": "Soil_Clay_Red"
    },
    {
      "x": -7,
      "y": -8,
      "z": -17,
      "name": "Soil_Grass_Wet"
    },
    {
      "x": -7,
      "y": -7,
      "z": -17,
      "name": "Plant_Bush"
    },
    {
      "x": -7,
      "y": 6,
      "z": -17,
      "name": "Rock_Stone"
    },
    {
      "x": -7,
      "y": 7,
      "z": -17,
      "name": "Rock_Stone"
    },
    {
      "x": -7,
      "y": -13,
      "z": -16,
      "name": "Rock_Marble"
    },
    {
      "x": -7,
      "y": -12,
      "z": -16,
      "name": "Rock_Marble"
    },
    {
      "x": -7,
      "y": -11,
      "z": -16,
      "name": "Rock_Marble"
    },
    {
      "x": -7,
      "y": -10,
      "z": -16,
      "name": "Soil_Grass_Full"
    },
    {
      "x": -7,
      "y": 7,
      "z": -16,
      "name": "Rock_Stone"
    },
    {
      "x": -7,
      "y": 11,
      "z": -16,
      "name": "Rock_Marble"
    },
    {
      "x": -7,
      "y": -14,
      "z": -15,
      "name": "Rock_Marble"
    },
    {
      "x": -7,
      "y": -13,
      "z": -15,
      "name": "Rock_Marble"
    },
    {
      "x": -7,
      "y": -12,
      "z": -15,
      "name": "Rock_Marble"
    },
    {
      "x": -7,
      "y": -11,
      "z": -15,
      "name": "Soil_Grass_Wet"
    },
    {
      "x": -7,
      "y": 11,
      "z": -15,
      "name": "Rock_Marble"
    },
    {
      "x": -7,
      "y": -16,
      "z": -14,
      "name": "Rock_Marble"
    },
    {
      "x": -7,
      "y": -15,
      "z": -14,
      "name": "Rock_Marble"
    },
    {
      "x": -7,
      "y": -14,
      "z": -14,
      "name": "Rock_Marble"
    },
    {
      "x": -7,
      "y": -13,
      "z": -14,
      "name": "Rock_Marble"
    },
    {
      "x": -7,
      "y": -12,
      "z": -14,
      "name": "Soil_Grass_Wet"
    },
    {
      "x": -7,
      "y": -11,
      "z": -14,
      "name": "Plant_Grass_Wet"
    },
    {
      "x": -7,
      "y": 11,
      "z": -14,
      "name": "Rock_Stone"
    },
    {
      "x": -7,
      "y": 12,
      "z": -14,
      "name": "Rock_Marble"
    },
    {
      "x": -7,
      "y": -17,
      "z": -13,
      "name": "Rock_Marble"
    },
    {
      "x": -7,
      "y": -16,
      "z": -13,
      "name": "Rock_Marble"
    },
    {
      "x": -7,
      "y": -15,
      "z": -13,
      "name": "Plant_Moss_Block_Green"
    },
    {
      "x": -7,
      "y": -14,
      "z": -13,
      "name": "Rock_Marble"
    },
    {
      "x": -7,
      "y": -13,
      "z": -13,
      "name": "Soil_Grass_Full"
    },
    {
      "x": -7,
      "y": 11,
      "z": -13,
      "name": "Rock_Stone"
    },
    {
      "x": -7,
      "y": 12,
      "z": -13,
      "name": "Rock_Marble"
    },
    {
      "x": -7,
      "y": -18,
      "z": -12,
      "name": "Rock_Calcite"
    },
    {
      "x": -7,
      "y": -17,
      "z": -12,
      "name": "Plant_Moss_Block_Green"
    },
    {
      "x": -7,
      "y": -16,
      "z": -12,
      "name": "Plant_Moss_Block_Green"
    },
    {
      "x": -7,
      "y": -15,
      "z": -12,
      "name": "Rock_Stone"
    },
    {
      "x": -7,
      "y": -14,
      "z": -12,
      "name": "Soil_Grass_Wet"
    },
    {
      "x": -7,
      "y": -13,
      "z": -12,
      "name": "Plant_Grass_Lush_Short"
    },
    {
      "x": -7,
      "y": 12,
      "z": -12,
      "name": "Rock_Stone"
    },
    {
      "x": -7,
      "y": 13,
      "z": -12,
      "name": "Rock_Marble"
    },
    {
      "x": -7,
      "y": -18,
      "z": -11,
      "name": "Plant_Moss_Block_Green"
    },
    {
      "x": -7,
      "y": -17,
      "z": -11,
      "name": "Plant_Moss_Block_Green"
    },
    {
      "x": -7,
      "y": -16,
      "z": -11,
      "name": "Rock_Stone"
    },
    {
      "x": -7,
      "y": 12,
      "z": -11,
      "name": "Rock_Stone"
    },
    {
      "x": -7,
      "y": 13,
      "z": -11,
      "name": "Rock_Chalk"
    },
    {
      "x": -7,
      "y": -18,
      "z": -10,
      "name": "Plant_Moss_Block_Green"
    },
    {
      "x": -7,
      "y": -17,
      "z": -10,
      "name": "Plant_Moss_Block_Green"
    },
    {
      "x": -7,
      "y": 13,
      "z": -10,
      "name": "Rock_Stone"
    },
    {
      "x": -7,
      "y": -18,
      "z": -9,
      "name": "Plant_Moss_Block_Green"
    },
    {
      "x": -6,
      "y": -3,
      "z": -25,
      "name": "Plant_Moss_Block_Green"
    },
    {
      "x": -6,
      "y": -2,
      "z": -25,
      "name": "Rock_Marble"
    },
    {
      "x": -6,
      "y": -1,
      "z": -25,
      "name": "Rock_Marble"
    },
    {
      "x": -6,
      "y": 0,
      "z": -25,
      "name": "Rock_Marble"
    },
    {
      "x": -6,
      "y": 1,
      "z": -25,
      "name": "Rock_Marble"
    },
    {
      "x": -6,
      "y": -4,
      "z": -24,
      "name": "Plant_Moss_Block_Green"
    },
    {
      "x": -6,
      "y": -3,
      "z": -24,
      "name": "Plant_Moss_Block_Green"
    },
    {
      "x": -6,
      "y": -2,
      "z": -24,
      "name": "Rock_Calcite"
    },
    {
      "x": -6,
      "y": -1,
      "z": -24,
      "name": "Rock_Calcite"
    },
    {
      "x": -6,
      "y": 0,
      "z": -24,
      "name": "Rock_Calcite"
    },
    {
      "x": -6,
      "y": 1,
      "z": -24,
      "name": "Rock_Calcite"
    },
    {
      "x": -6,
      "y": 2,
      "z": -24,
      "name": "Rock_Calcite"
    },
    {
      "x": -6,
      "y": -4,
      "z": -23,
      "name": "Plant_Moss_Block_Green"
    },
    {
      "x": -6,
      "y": -3,
      "z": -23,
      "name": "Plant_Moss_Block_Green"
    },
    {
      "x": -6,
      "y": -2,
      "z": -23,
      "name": "Rock_Calcite"
    },
    {
      "x": -6,
      "y": -1,
      "z": -23,
      "name": "Rock_Calcite"
    },
    {
      "x": -6,
      "y": 0,
      "z": -23,
      "name": "Rock_Calcite"
    },
    {
      "x": -6,
      "y": 1,
      "z": -23,
      "name": "Rock_Calcite"
    },
    {
      "x": -6,
      "y": 2,
      "z": -23,
      "name": "Rock_Calcite"
    },
    {
      "x": -6,
      "y": 3,
      "z": -23,
      "name": "Rock_Calcite"
    },
    {
      "x": -6,
      "y": 4,
      "z": -23,
      "name": "Plant_Moss_Block_Green"
    },
    {
      "x": -6,
      "y": -8,
      "z": -22,
      "name": "Plant_Moss_Wall_Green",
      "rotation": 2
    },
    {
      "x": -6,
      "y": -3,
      "z": -22,
      "name": "Rock_Stone"
    },
    {
      "x": -6,
      "y": -2,
      "z": -22,
      "name": "Rock_Stone"
    },
    {
      "x": -6,
      "y": -1,
      "z": -22,
      "name": "Rock_Stone"
    },
    {
      "x": -6,
      "y": 0,
      "z": -22,
      "name": "Rock_Stone"
    },
    {
      "x": -6,
      "y": 1,
      "z": -22,
      "name": "Rock_Calcite"
    },
    {
      "x": -6,
      "y": 2,
      "z": -22,
      "name": "Rock_Calcite"
    },
    {
      "x": -6,
      "y": 3,
      "z": -22,
      "name": "Rock_Calcite"
    },
    {
      "x": -6,
      "y": 4,
      "z": -22,
      "name": "Rock_Calcite"
    },
    {
      "x": -6,
      "y": 5,
      "z": -22,
      "name": "Plant_Moss_Block_Green"
    },
    {
      "x": -6,
      "y": -9,
      "z": -21,
      "name": "Plant_Moss_Cave_Green",
      "rotation": 8
    },
    {
      "x": -6,
      "y": -8,
      "z": -21,
      "name": "Plant_Moss_Block_Green"
    },
    {
      "x": -6,
      "y": -7,
      "z": -21,
      "name": "Plant_Moss_Rug_Green"
    },
    {
      "x": -6,
      "y": -3,
      "z": -21,
      "name": "Rock_Stone"
    },
    {
      "x": -6,
      "y": 1,
      "z": -21,
      "name": "Rock_Stone"
    },
    {
      "x": -6,
      "y": 2,
      "z": -21,
      "name": "Rock_Stone"
    },
    {
      "x": -6,
      "y": 3,
      "z": -21,
      "name": "Rock_Marble"
    },
    {
      "x": -6,
      "y": 4,
      "z": -21,
      "name": "Rock_Marble"
    },
    {
      "x": -6,
      "y": 5,
      "z": -21,
      "name": "Rock_Marble"
    },
    {
      "x": -6,
      "y": 6,
      "z": -21,
      "name": "Plant_Moss_Block_Green"
    },
    {
      "x": -6,
      "y": -9,
      "z": -20,
      "name": "Plant_Moss_Block_Green"
    },
    {
      "x": -6,
      "y": -8,
      "z": -20,
      "name": "Plant_Moss_Block_Green"
    },
    {
      "x": -6,
      "y": -7,
      "z": -20,
      "name": "Plant_Moss_Rug_Green"
    },
    {
      "x": -6,
      "y": 3,
      "z": -20,
      "name": "Rock_Stone"
    },
    {
      "x": -6,
      "y": 4,
      "z": -20,
      "name": "Rock_Marble"
    },
    {
      "x": -6,
      "y": 5,
      "z": -20,
      "name": "Rock_Marble"
    },
    {
      "x": -6,
      "y": 6,
      "z": -20,
      "name": "Plant_Moss_Block_Green"
    },
    {
      "x": -6,
      "y": 7,
      "z": -20,
      "name": "Plant_Moss_Block_Green"
    },
    {
      "x": -6,
      "y": -10,
      "z": -19,
      "name": "Rock_Marble"
    },
    {
      "x": -6,
      "y": -9,
      "z": -19,
      "name": "Plant_Moss_Block_Green"
    },
    {
      "x": -6,
      "y": -8,
      "z": -19,
      "name": "Soil_Grass_Wet"
    },
    {
      "x": -6,
      "y": -7,
      "z": -19,
      "name": "Plant_Moss_Rug_Green"
    },
    {
      "x": -6,
      "y": 4,
      "z": -19,
      "name": "Rock_Stone"
    },
    {
      "x": -6,
      "y": 5,
      "z": -19,
      "name": "Rock_Marble"
    },
    {
      "x": -6,
      "y": 6,
      "z": -19,
      "name": "Plant_Moss_Block_Green"
    },
    {
      "x": -6,
      "y": 7,
      "z": -19,
      "name": "Plant_Moss_Block_Green"
    },
    {
      "x": -6,
      "y": -11,
      "z": -18,
      "name": "Rock_Marble"
    },
    {
      "x": -6,
      "y": -10,
      "z": -18,
      "name": "Rock_Marble"
    },
    {
      "x": -6,
      "y": -9,
      "z": -18,
      "name": "Plant_Moss_Block_Green"
    },
    {
      "x": -6,
      "y": -8,
      "z": -18,
      "name": "Soil_Grass_Wet"
    },
    {
      "x": -6,
      "y": -7,
      "z": -18,
      "name": "Plant_Bush"
    },
    {
      "x": -6,
      "y": 5,
      "z": -18,
      "name": "Rock_Stone"
    },
    {
      "x": -6,
      "y": 6,
      "z": -18,
      "name": "Rock_Stone"
    },
    {
      "x": -6,
      "y": -12,
      "z": -17,
      "name": "Rock_Marble"
    },
    {
      "x": -6,
      "y": -11,
      "z": -17,
      "name": "Rock_Marble"
    },
    {
      "x": -6,
      "y": -10,
      "z": -17,
      "name": "Rock_Marble"
    },
    {
      "x": -6,
      "y": -9,
      "z": -17,
      "name": "Soil_Clay_Red"
    },
    {
      "x": -6,
      "y": -8,
      "z": -17,
      "name": "Soil_Grass_Wet"
    },
    {
      "x": -6,
      "y": -7,
      "z": -17,
      "name": "Plant_Bush"
    },
    {
      "x": -6,
      "y": 10,
      "z": -17,
      "name": "Rock_Marble"
    },
    {
      "x": -6,
      "y": -14,
      "z": -16,
      "name": "Rock_Marble"
    },
    {
      "x": -6,
      "y": -13,
      "z": -16,
      "name": "Rock_Marble"
    },
    {
      "x": -6,
      "y": -12,
      "z": -16,
      "name": "Rock_Marble"
    },
    {
      "x": -6,
      "y": -11,
      "z": -16,
      "name": "Rock_Marble"
    },
    {
      "x": -6,
      "y": -10,
      "z": -16,
      "name": "Soil_Grass_Full"
    },
    {
      "x": -6,
      "y": -9,
      "z": -16,
      "name": "Plant_Grass_Lush_Short"
    },
    {
      "x": -6,
      "y": 10,
      "z": -16,
      "name": "Rock_Stone"
    },
    {
      "x": -6,
      "y": 11,
      "z": -16,
      "name": "Rock_Marble"
    },
    {
      "x": -6,
      "y": -15,
      "z": -15,
      "name": "Rock_Marble"
    },
    {
      "x": -6,
      "y": -14,
      "z": -15,
      "name": "Rock_Marble"
    },
    {
      "x": -6,
      "y": -13,
      "z": -15,
      "name": "Rock_Marble"
    },
    {
      "x": -6,
      "y": -12,
      "z": -15,
      "name": "Rock_Marble"
    },
    {
      "x": -6,
      "y": -11,
      "z": -15,
      "name": "Soil_Grass_Wet"
    },
    {
      "x": -6,
      "y": -10,
      "z": -15,
      "name": "Plant_Grass_Lush_Short"
    },
    {
      "x": -6,
      "y": 10,
      "z": -15,
      "name": "Rock_Stone"
    },
    {
      "x": -6,
      "y": 11,
      "z": -15,
      "name": "Rock_Marble"
    },
    {
      "x": -6,
      "y": 12,
      "z": -15,
      "name": "Rock_Marble"
    },
    {
      "x": -6,
      "y": -16,
      "z": -14,
      "name": "Rock_Marble"
    },
    {
      "x": -6,
      "y": -15,
      "z": -14,
      "name": "Rock_Marble"
    },
    {
      "x": -6,
      "y": -14,
      "z": -14,
      "name": "Rock_Marble"
    },
    {
      "x": -6,
      "y": -13,
      "z": -14,
      "name": "Soil_Clay_Red"
    },
    {
      "x": -6,
      "y": -12,
      "z": -14,
      "name": "Soil_Grass_Wet"
    },
    {
      "x": -6,
      "y": 10,
      "z": -14,
      "name": "Rock_Stone"
    },
    {
      "x": -6,
      "y": 11,
      "z": -14,
      "name": "Rock_Marble"
    },
    {
      "x": -6,
      "y": 12,
      "z": -14,
      "name": "Rock_Marble"
    },
    {
      "x": -6,
      "y": -17,
      "z": -13,
      "name": "Rock_Calcite"
    },
    {
      "x": -6,
      "y": -16,
      "z": -13,
      "name": "Rock_Calcite"
    },
    {
      "x": -6,
      "y": -15,
      "z": -13,
      "name": "Rock_Calcite"
    },
    {
      "x": -6,
      "y": -14,
      "z": -13,
      "name": "Soil_Grass_Full"
    },
    {
      "x": -6,
      "y": -13,
      "z": -13,
      "name": "Plant_Grass_Lush_Short"
    },
    {
      "x": -6,
      "y": 11,
      "z": -13,
      "name": "Rock_Stone"
    },
    {
      "x": -6,
      "y": 12,
      "z": -13,
      "name": "Rock_Marble"
    },
    {
      "x": -6,
      "y": 13,
      "z": -13,
      "name": "Rock_Marble"
    },
    {
      "x": -6,
      "y": -18,
      "z": -12,
      "name": "Rock_Calcite"
    },
    {
      "x": -6,
      "y": -17,
      "z": -12,
      "name": "Plant_Moss_Block_Green"
    },
    {
      "x": -6,
      "y": -16,
      "z": -12,
      "name": "Rock_Calcite"
    },
    {
      "x": -6,
      "y": -15,
      "z": -12,
      "name": "Soil_Grass_Wet"
    },
    {
      "x": -6,
      "y": -14,
      "z": -12,
      "name": "Plant_Grass_Wet_Short"
    },
    {
      "x": -6,
      "y": 12,
      "z": -12,
      "name": "Rock_Stone"
    },
    {
      "x": -6,
      "y": 13,
      "z": -12,
      "name": "Rock_Marble"
    },
    {
      "x": -6,
      "y": -18,
      "z": -11,
      "name": "Plant_Moss_Block_Green"
    },
    {
      "x": -6,
      "y": -17,
      "z": -11,
      "name": "Plant_Moss_Block_Green"
    },
    {
      "x": -6,
      "y": -16,
      "z": -11,
      "name": "Rock_Stone"
    },
    {
      "x": -6,
      "y": -15,
      "z": -11,
      "name": "Plant_Moss_Rug_Green"
    },
    {
      "x": -6,
      "y": 13,
      "z": -11,
      "name": "Rock_Stone"
    },
    {
      "x": -6,
      "y": -18,
      "z": -10,
      "name": "Plant_Moss_Block_Green"
    },
    {
      "x": -6,
      "y": -17,
      "z": -10,
      "name": "Plant_Moss_Block_Green"
    },
    {
      "x": -6,
      "y": -18,
      "z": -9,
      "name": "Plant_Moss_Block_Green"
    },
    {
      "x": -5,
      "y": -3,
      "z": -25,
      "name": "Plant_Moss_Block_Green"
    },
    {
      "x": -5,
      "y": -2,
      "z": -25,
      "name": "Rock_Marble"
    },
    {
      "x": -5,
      "y": -1,
      "z": -25,
      "name": "Rock_Marble"
    },
    {
      "x": -5,
      "y": 0,
      "z": -25,
      "name": "Rock_Marble"
    },
    {
      "x": -5,
      "y": 1,
      "z": -25,
      "name": "Rock_Marble"
    },
    {
      "x": -5,
      "y": -4,
      "z": -24,
      "name": "Plant_Moss_Block_Green"
    },
    {
      "x": -5,
      "y": -3,
      "z": -24,
      "name": "Plant_Moss_Block_Green"
    },
    {
      "x": -5,
      "y": -2,
      "z": -24,
      "name": "Rock_Calcite"
    },
    {
      "x": -5,
      "y": -1,
      "z": -24,
      "name": "Rock_Calcite"
    },
    {
      "x": -5,
      "y": 0,
      "z": -24,
      "name": "Rock_Calcite"
    },
    {
      "x": -5,
      "y": 1,
      "z": -24,
      "name": "Rock_Calcite"
    },
    {
      "x": -5,
      "y": 2,
      "z": -24,
      "name": "Rock_Calcite"
    },
    {
      "x": -5,
      "y": 3,
      "z": -24,
      "name": "Rock_Calcite"
    },
    {
      "x": -5,
      "y": -4,
      "z": -23,
      "name": "Plant_Moss_Block_Green"
    },
    {
      "x": -5,
      "y": -3,
      "z": -23,
      "name": "Plant_Moss_Block_Green"
    },
    {
      "x": -5,
      "y": -2,
      "z": -23,
      "name": "Rock_Calcite"
    },
    {
      "x": -5,
      "y": -1,
      "z": -23,
      "name": "Rock_Calcite"
    },
    {
      "x": -5,
      "y": 0,
      "z": -23,
      "name": "Rock_Calcite"
    },
    {
      "x": -5,
      "y": 1,
      "z": -23,
      "name": "Rock_Calcite"
    },
    {
      "x": -5,
      "y": 2,
      "z": -23,
      "name": "Rock_Calcite"
    },
    {
      "x": -5,
      "y": 3,
      "z": -23,
      "name": "Rock_Calcite"
    },
    {
      "x": -5,
      "y": 4,
      "z": -23,
      "name": "Rock_Calcite"
    },
    {
      "x": -5,
      "y": -3,
      "z": -22,
      "name": "Rock_Stone"
    },
    {
      "x": -5,
      "y": -2,
      "z": -22,
      "name": "Rock_Stone"
    },
    {
      "x": -5,
      "y": -1,
      "z": -22,
      "name": "Rock_Stone"
    },
    {
      "x": -5,
      "y": 0,
      "z": -22,
      "name": "Rock_Stone"
    },
    {
      "x": -5,
      "y": 1,
      "z": -22,
      "name": "Rock_Calcite"
    },
    {
      "x": -5,
      "y": 2,
      "z": -22,
      "name": "Rock_Calcite"
    },
    {
      "x": -5,
      "y": 3,
      "z": -22,
      "name": "Rock_Calcite"
    },
    {
      "x": -5,
      "y": 4,
      "z": -22,
      "name": "Rock_Calcite"
    },
    {
      "x": -5,
      "y": 5,
      "z": -22,
      "name": "Rock_Calcite"
    },
    {
      "x": -5,
      "y": -8,
      "z": -21,
      "name": "Plant_Moss_Block_Green"
    },
    {
      "x": -5,
      "y": -3,
      "z": -21,
      "name": "Rock_Stone"
    },
    {
      "x": -5,
      "y": 1,
      "z": -21,
      "name": "Rock_Stone"
    },
    {
      "x": -5,
      "y": 2,
      "z": -21,
      "name": "Rock_Stone"
    },
    {
      "x": -5,
      "y": 3,
      "z": -21,
      "name": "Rock_Marble"
    },
    {
      "x": -5,
      "y": 4,
      "z": -21,
      "name": "Rock_Marble"
    },
    {
      "x": -5,
      "y": 5,
      "z": -21,
      "name": "Rock_Marble"
    },
    {
      "x": -5,
      "y": 6,
      "z": -21,
      "name": "Plant_Moss_Block_Green"
    },
    {
      "x": -5,
      "y": -9,
      "z": -20,
      "name": "Plant_Moss_Block_Green"
    },
    {
      "x": -5,
      "y": -8,
      "z": -20,
      "name": "Plant_Moss_Block_Green"
    },
    {
      "x": -5,
      "y": -7,
      "z": -20,
      "name": "Plant_Moss_Rug_Green"
    },
    {
      "x": -5,
      "y": 3,
      "z": -20,
      "name": "Rock_Stone"
    },
    {
      "x": -5,
      "y": 4,
      "z": -20,
      "name": "Rock_Stone"
    },
    {
      "x": -5,
      "y": 5,
      "z": -20,
      "name": "Rock_Marble"
    },
    {
      "x": -5,
      "y": 6,
      "z": -20,
      "name": "Plant_Moss_Block_Green"
    },
    {
      "x": -5,
      "y": 7,
      "z": -20,
      "name": "Plant_Moss_Block_Green"
    },
    {
      "x": -5,
      "y": -10,
      "z": -19,
      "name": "Rock_Marble"
    },
    {
      "x": -5,
      "y": -9,
      "z": -19,
      "name": "Rock_Marble"
    },
    {
      "x": -5,
      "y": -8,
      "z": -19,
      "name": "Soil_Grass_Full"
    },
    {
      "x": -5,
      "y": -7,
      "z": -19,
      "name": "Plant_Moss_Rug_Green"
    },
    {
      "x": -5,
      "y": 5,
      "z": -19,
      "name": "Rock_Stone"
    },
    {
      "x": -5,
      "y": 6,
      "z": -19,
      "name": "Plant_Moss_Block_Green"
    },
    {
      "x": -5,
      "y": 7,
      "z": -19,
      "name": "Plant_Moss_Block_Green"
    },
    {
      "x": -5,
      "y": 8,
      "z": -19,
      "name": "Plant_Moss_Rug_Green"
    },
    {
      "x": -5,
      "y": -11,
      "z": -18,
      "name": "Rock_Marble"
    },
    {
      "x": -5,
      "y": -10,
      "z": -18,
      "name": "Rock_Marble"
    },
    {
      "x": -5,
      "y": -9,
      "z": -18,
      "name": "Rock_Marble"
    },
    {
      "x": -5,
      "y": -8,
      "z": -18,
      "name": "Soil_Grass_Full"
    },
    {
      "x": -5,
      "y": -7,
      "z": -18,
      "name": "Plant_Bush"
    },
    {
      "x": -5,
      "y": 6,
      "z": -18,
      "name": "Rock_Stone"
    },
    {
      "x": -5,
      "y": 10,
      "z": -18,
      "name": "Rock_Marble"
    },
    {
      "x": -5,
      "y": -12,
      "z": -17,
      "name": "Rock_Marble"
    },
    {
      "x": -5,
      "y": -11,
      "z": -17,
      "name": "Rock_Marble"
    },
    {
      "x": -5,
      "y": -10,
      "z": -17,
      "name": "Rock_Marble"
    },
    {
      "x": -5,
      "y": -9,
      "z": -17,
      "name": "Soil_Grass_Full"
    },
    {
      "x": -5,
      "y": -8,
      "z": -17,
      "name": "Plant_Bush"
    },
    {
      "x": -5,
      "y": 10,
      "z": -17,
      "name": "Rock_Stone"
    },
    {
      "x": -5,
      "y": 11,
      "z": -17,
      "name": "Rock_Marble"
    },
    {
      "x": -5,
      "y": -14,
      "z": -16,
      "name": "Rock_Marble"
    },
    {
      "x": -5,
      "y": -13,
      "z": -16,
      "name": "Rock_Marble"
    },
    {
      "x": -5,
      "y": -12,
      "z": -16,
      "name": "Rock_Marble"
    },
    {
      "x": -5,
      "y": -11,
      "z": -16,
      "name": "Rock_Marble"
    },
    {
      "x": -5,
      "y": -10,
      "z": -16,
      "name": "Soil_Grass_Full"
    },
    {
      "x": -5,
      "y": -9,
      "z": -16,
      "name": "Plant_Bush"
    },
    {
      "x": -5,
      "y": 10,
      "z": -16,
      "name": "Rock_Stone"
    },
    {
      "x": -5,
      "y": 11,
      "z": -16,
      "name": "Rock_Marble"
    },
    {
      "x": -5,
      "y": -15,
      "z": -15,
      "name": "Rock_Marble"
    },
    {
      "x": -5,
      "y": -14,
      "z": -15,
      "name": "Rock_Marble"
    },
    {
      "x": -5,
      "y": -13,
      "z": -15,
      "name": "Rock_Marble"
    },
    {
      "x": -5,
      "y": -12,
      "z": -15,
      "name": "Rock_Marble"
    },
    {
      "x": -5,
      "y": -11,
      "z": -15,
      "name": "Soil_Grass_Full"
    },
    {
      "x": -5,
      "y": -10,
      "z": -15,
      "name": "Plant_Grass_Lush_Short"
    },
    {
      "x": -5,
      "y": 10,
      "z": -15,
      "name": "Rock_Stone"
    },
    {
      "x": -5,
      "y": 11,
      "z": -15,
      "name": "Rock_Marble"
    },
    {
      "x": -5,
      "y": 12,
      "z": -15,
      "name": "Rock_Marble"
    },
    {
      "x": -5,
      "y": -16,
      "z": -14,
      "name": "Rock_Marble"
    },
    {
      "x": -5,
      "y": -15,
      "z": -14,
      "name": "Rock_Marble"
    },
    {
      "x": -5,
      "y": -14,
      "z": -14,
      "name": "Rock_Marble"
    },
    {
      "x": -5,
      "y": -13,
      "z": -14,
      "name": "Soil_Clay_Red"
    },
    {
      "x": -5,
      "y": -12,
      "z": -14,
      "name": "Soil_Grass_Wet"
    },
    {
      "x": -5,
      "y": -11,
      "z": -14,
      "name": "Plant_Grass_Lush_Short"
    },
    {
      "x": -5,
      "y": 11,
      "z": -14,
      "name": "Rock_Stone"
    },
    {
      "x": -5,
      "y": 12,
      "z": -14,
      "name": "Rock_Marble"
    },
    {
      "x": -5,
      "y": 13,
      "z": -14,
      "name": "Rock_Marble"
    },
    {
      "x": -5,
      "y": -17,
      "z": -13,
      "name": "Rock_Marble"
    },
    {
      "x": -5,
      "y": -16,
      "z": -13,
      "name": "Rock_Marble"
    },
    {
      "x": -5,
      "y": -15,
      "z": -13,
      "name": "Rock_Marble"
    },
    {
      "x": -5,
      "y": -14,
      "z": -13,
      "name": "Soil_Grass_Full"
    },
    {
      "x": -5,
      "y": 12,
      "z": -13,
      "name": "Rock_Stone"
    },
    {
      "x": -5,
      "y": 13,
      "z": -13,
      "name": "Rock_Marble"
    },
    {
      "x": -5,
      "y": 14,
      "z": -13,
      "name": "Rock_Marble"
    },
    {
      "x": -5,
      "y": -18,
      "z": -12,
      "name": "Rock_Calcite"
    },
    {
      "x": -5,
      "y": -17,
      "z": -12,
      "name": "Plant_Moss_Block_Green"
    },
    {
      "x": -5,
      "y": -16,
      "z": -12,
      "name": "Rock_Calcite"
    },
    {
      "x": -5,
      "y": -15,
      "z": -12,
      "name": "Soil_Grass_Wet"
    },
    {
      "x": -5,
      "y": 13,
      "z": -12,
      "name": "Rock_Stone"
    },
    {
      "x": -5,
      "y": 14,
      "z": -12,
      "name": "Rock_Marble"
    },
    {
      "x": -5,
      "y": -18,
      "z": -11,
      "name": "Plant_Moss_Block_Green"
    },
    {
      "x": -5,
      "y": -17,
      "z": -11,
      "name": "Plant_Moss_Block_Green"
    },
    {
      "x": -5,
      "y": -16,
      "z": -11,
      "name": "Rock_Stone"
    },
    {
      "x": -5,
      "y": -15,
      "z": -11,
      "name": "Plant_Moss_Rug_Green"
    },
    {
      "x": -5,
      "y": 13,
      "z": -11,
      "name": "Rock_Stone"
    },
    {
      "x": -5,
      "y": 14,
      "z": -11,
      "name": "Rock_Chalk"
    },
    {
      "x": -5,
      "y": -18,
      "z": -10,
      "name": "Plant_Moss_Block_Green"
    },
    {
      "x": -5,
      "y": -17,
      "z": -10,
      "name": "Plant_Moss_Block_Green"
    },
    {
      "x": -5,
      "y": -16,
      "z": -10,
      "name": "Plant_Moss_Wall_Green"
    },
    {
      "x": -5,
      "y": 14,
      "z": -10,
      "name": "Rock_Stone"
    },
    {
      "x": -5,
      "y": -18,
      "z": -9,
      "name": "Plant_Moss_Block_Green"
    },
    {
      "x": -4,
      "y": -4,
      "z": -26,
      "name": "Plant_Moss_Wall_Green",
      "rotation": 2
    },
    {
      "x": -4,
      "y": -3,
      "z": -26,
      "name": "Plant_Moss_Wall_Green",
      "rotation": 2
    },
    {
      "x": -4,
      "y": -5,
      "z": -25,
      "name": "Plant_Moss_Cave_Green",
      "rotation": 8
    },
    {
      "x": -4,
      "y": -4,
      "z": -25,
      "name": "Plant_Moss_Block_Green"
    },
    {
      "x": -4,
      "y": -3,
      "z": -25,
      "name": "Plant_Moss_Block_Green"
    },
    {
      "x": -4,
      "y": -2,
      "z": -25,
      "name": "Plant_Moss_Block_Green"
    },
    {
      "x": -4,
      "y": -1,
      "z": -25,
      "name": "Rock_Marble"
    },
    {
      "x": -4,
      "y": 0,
      "z": -25,
      "name": "Rock_Marble"
    },
    {
      "x": -4,
      "y": 1,
      "z": -25,
      "name": "Rock_Marble"
    },
    {
      "x": -4,
      "y": 2,
      "z": -25,
      "name": "Rock_Marble"
    },
    {
      "x": -4,
      "y": -3,
      "z": -24,
      "name": "Rock_Stone"
    },
    {
      "x": -4,
      "y": -2,
      "z": -24,
      "name": "Plant_Moss_Block_Green"
    },
    {
      "x": -4,
      "y": -1,
      "z": -24,
      "name": "Rock_Calcite"
    },
    {
      "x": -4,
      "y": 0,
      "z": -24,
      "name": "Rock_Calcite"
    },
    {
      "x": -4,
      "y": 1,
      "z": -24,
      "name": "Rock_Marble"
    },
    {
      "x": -4,
      "y": 2,
      "z": -24,
      "name": "Rock_Marble"
    },
    {
      "x": -4,
      "y": 3,
      "z": -24,
      "name": "Rock_Marble"
    },
    {
      "x": -4,
      "y": -3,
      "z": -23,
      "name": "Rock_Stone"
    },
    {
      "x": -4,
      "y": -2,
      "z": -23,
      "name": "Rock_Calcite"
    },
    {
      "x": -4,
      "y": -1,
      "z": -23,
      "name": "Rock_Calcite"
    },
    {
      "x": -4,
      "y": 0,
      "z": -23,
      "name": "Rock_Calcite"
    },
    {
      "x": -4,
      "y": 1,
      "z": -23,
      "name": "Rock_Calcite"
    },
    {
      "x": -4,
      "y": 2,
      "z": -23,
      "name": "Rock_Calcite"
    },
    {
      "x": -4,
      "y": 3,
      "z": -23,
      "name": "Rock_Calcite"
    },
    {
      "x": -4,
      "y": 4,
      "z": -23,
      "name": "Rock_Calcite"
    },
    {
      "x": -4,
      "y": 5,
      "z": -23,
      "name": "Rock_Calcite"
    },
    {
      "x": -4,
      "y": -3,
      "z": -22,
      "name": "Rock_Stone"
    },
    {
      "x": -4,
      "y": -2,
      "z": -22,
      "name": "Rock_Stone"
    },
    {
      "x": -4,
      "y": -1,
      "z": -22,
      "name": "Rock_Stone"
    },
    {
      "x": -4,
      "y": 0,
      "z": -22,
      "name": "Rock_Stone"
    },
    {
      "x": -4,
      "y": 1,
      "z": -22,
      "name": "Rock_Stone"
    },
    {
      "x": -4,
      "y": 2,
      "z": -22,
      "name": "Rock_Calcite"
    },
    {
      "x": -4,
      "y": 3,
      "z": -22,
      "name": "Rock_Calcite"
    },
    {
      "x": -4,
      "y": 4,
      "z": -22,
      "name": "Rock_Calcite"
    },
    {
      "x": -4,
      "y": 5,
      "z": -22,
      "name": "Rock_Calcite"
    },
    {
      "x": -4,
      "y": 6,
      "z": -22,
      "name": "Plant_Moss_Block_Green"
    },
    {
      "x": -4,
      "y": -8,
      "z": -21,
      "name": "Plant_Moss_Block_Green"
    },
    {
      "x": -4,
      "y": 2,
      "z": -21,
      "name": "Rock_Stone"
    },
    {
      "x": -4,
      "y": 3,
      "z": -21,
      "name": "Rock_Stone"
    },
    {
      "x": -4,
      "y": 4,
      "z": -21,
      "name": "Rock_Calcite"
    },
    {
      "x": -4,
      "y": 5,
      "z": -21,
      "name": "Plant_Moss_Block_Green"
    },
    {
      "x": -4,
      "y": 6,
      "z": -21,
      "name": "Plant_Moss_Block_Green"
    },
    {
      "x": -4,
      "y": -9,
      "z": -20,
      "name": "Plant_Moss_Block_Green"
    },
    {
      "x": -4,
      "y": -8,
      "z": -20,
      "name": "Plant_Moss_Block_Green"
    },
    {
      "x": -4,
      "y": 4,
      "z": -20,
      "name": "Rock_Stone"
    },
    {
      "x": -4,
      "y": 5,
      "z": -20,
      "name": "Plant_Moss_Block_Green"
    },
    {
      "x": -4,
      "y": 6,
      "z": -20,
      "name": "Rock_Stone"
    },
    {
      "x": -4,
      "y": -10,
      "z": -19,
