{
  "version": 8,
  "blockIdVersion": 8,
  "anchorX": 4,
  "anchorY": 8,
  "anchorZ": 3,
  "blocks": [
    {
      "x": 2,
      "y": 8,
      "z": 2,
      "name": "Rock_Shale"
    },
    {
      "x": 2,
      "y": 8,
      "z": 3,
      "name": "Rock_Shale"
    },
    {
      "x": 2,
      "y": 9,
      "z": 3,
      "name": "Rock_Shale"
    },
    {
      "x": 3,
      "y": 7,
      "z": 1,
      "name": "Rock_Shale"
    },
    {
      "x": 3,
      "y": 8,
      "z": 1,
      "name": "Rock_Shale"
    },
    {
      "x": 3,
      "y": 9,
      "z": 1,
      "name": "Rock_Shale"
    },
    {
      "x": 3,
      "y": 10,
      "z": 1,
      "name": "Rubble_Shale_Medium"
    },
    {
      "x": 3,
      "y": 6,
      "z": 2,
      "name": "Rock_Shale"
    },
    {
      "x": 3,
      "y": 7,
      "z": 2,
      "name": "Rock_Shale"
    },
    {
      "x": 3,
      "y": 8,
      "z": 2,
      "name": "Rock_Shale"
    },
    {
      "x": 3,
      "y": 9,
      "z": 2,
      "name": "Rock_Shale"
    },
    {
      "x": 3,
      "y": 10,
      "z": 2,
      "name": "Rock_Shale"
    },
    {
      "x": 3,
      "y": 7,
      "z": 3,
      "name": "Rock_Shale"
    },
    {
      "x": 3,
      "y": 8,
      "z": 3,
      "name": "Rock_Shale"
    },
    {
      "x": 3,
      "y": 9,
      "z": 3,
      "name": "Rock_Shale"
    },
    {
      "x": 3,
      "y": 10,
      "z": 3,
      "name": "Rock_Shale"
    },
    {
      "x": 3,
      "y": 9,
      "z": 4,
      "name": "Rock_Shale"
    },
    {
      "x": 3,
      "y": 10,
      "z": 4,
      "name": "Rock_Shale"
    },
    {
      "x": 4,
      "y": 6,
      "z": 1,
      "name": "Rock_Shale"
    },
    {
      "x": 4,
      "y": 7,
      "z": 1,
      "name": "Rock_Shale"
    },
    {
      "x": 4,
      "y": 8,
      "z": 1,
      "name": "Rock_Shale"
    },
    {
      "x": 4,
      "y": 9,
      "z": 1,
      "name": "Rock_Shale"
    },
    {
      "x": 4,
      "y": 10,
      "z": 1,
      "name": "Rock_Shale"
    },
    {
      "x": 4,
      "y": 5,
      "z": 2,
      "name": "Rock_Shale"
    },
    {
      "x": 4,
      "y": 6,
      "z": 2,
      "name": "Rock_Shale"
    },
    {
      "x": 4,
      "y": 7,
      "z": 2,
      "name": "Rock_Shale"
    },
    {
      "x": 4,
      "y": 8,
      "z": 2,
      "name": "Rock_Shale"
    },
    {
      "x": 4,
      "y": 9,
      "z": 2,
      "name": "Rock_Shale"
    },
    {
      "x": 4,
      "y": 10,
      "z": 2,
      "name": "Rock_Shale"
    },
    {
      "x": 4,
      "y": 11,
      "z": 2,
      "name": "Rubble_Shale_Medium"
    },
    {
      "x": 4,
      "y": 5,
      "z": 3,
      "name": "Rock_Shale"
    },
    {
      "x": 4,
      "y": 6,
      "z": 3,
      "name": "Rock_Shale"
    },
    {
      "x": 4,
      "y": 7,
      "z": 3,
      "name": "Rock_Shale"
    },
    {
      "x": 4,
      "y": 8,
      "z": 3,
      "name": "Rock_Shale"
    },
    {
      "x": 4,
      "y": 9,
      "z": 3,
      "name": "Rock_Shale"
    },
    {
      "x": 4,
      "y": 10,
      "z": 3,
      "name": "Rock_Shale"
    },
    {
      "x": 4,
      "y": 11,
      "z": 3,
      "name": "Rock_Shale"
    },
    {
      "x": 4,
      "y": 6,
      "z": 4,
      "name": "Rock_Shale"
    },
    {
      "x": 4,
      "y": 7,
      "z": 4,
      "name": "Rock_Shale"
    },
    {
      "x": 4,
      "y": 8,
      "z": 4,
      "name": "Rock_Shale"
    },
    {
      "x": 4,
      "y": 9,
      "z": 4,
      "name": "Rock_Shale"
    },
    {
      "x": 4,
      "y": 10,
      "z": 4,
      "name": "Rock_Shale"
    },
    {
      "x": 4,
      "y": 11,
      "z": 4,
      "name": "Rock_Shale"
    },
    {
      "x": 4,
      "y": 7,
      "z": 5,
      "name": "Rock_Shale"
    },
    {
      "x": 4,
      "y": 8,
      "z": 5,
      "name": "Rock_Shale"
    },
    {
      "x": 4,
      "y": 9,
      "z": 5,
      "name": "Rock_Shale"
    },
    {
      "x": 4,
      "y": 10,
      "z": 5,
      "name": "Rock_Shale"
    },
    {
      "x": 4,
      "y": 11,
      "z": 5,
      "name": "Rubble_Shale_Medium"
    },
    {
      "x": 5,
      "y": 6,
      "z": 1,
      "name": "Rock_Shale"
    },
    {
      "x": 5,
      "y": 7,
      "z": 1,
      "name": "Rock_Shale"
    },
    {
      "x": 5,
      "y": 8,
      "z": 1,
      "name": "Rock_Shale"
    },
    {
      "x": 5,
      "y": 9,
      "z": 1,
      "name": "Rock_Shale"
    },
    {
      "x": 5,
      "y": 10,
      "z": 1,
      "name": "Rock_Shale"
    },
    {
      "x": 5,
      "y": 5,
      "z": 2,
      "name": "Rock_Shale"
    },
    {
      "x": 5,
      "y": 6,
      "z": 2,
      "name": "Rock_Shale"
    },
    {
      "x": 5,
      "y": 7,
      "z": 2,
      "name": "Rock_Shale"
    },
    {
      "x": 5,
      "y": 8,
      "z": 2,
      "name": "Rock_Shale"
    },
    {
      "x": 5,
      "y": 9,
      "z": 2,
      "name": "Rock_Shale"
    },
    {
      "x": 5,
      "y": 10,
      "z": 2,
      "name": "Rock_Shale"
    },
    {
      "x": 5,
      "y": 11,
      "z": 2,
      "name": "Rock_Shale"
    },
    {
      "x": 5,
      "y": 6,
      "z": 3,
      "name": "Rock_Shale"
    },
    {
      "x": 5,
      "y": 7,
      "z": 3,
      "name": "Rock_Shale"
    },
    {
      "x": 5,
      "y": 8,
      "z": 3,
      "name": "Rock_Shale"
    },
    {
      "x": 5,
      "y": 9,
      "z": 3,
      "name": "Rock_Shale"
    },
    {
      "x": 5,
      "y": 10,
      "z": 3,
      "name": "Rock_Shale"
    },
    {
      "x": 5,
      "y": 11,
      "z": 3,
      "name": "Rock_Shale"
    },
    {
      "x": 5,
      "y": 6,
      "z": 4,
      "name": "Rock_Shale"
    },
    {
      "x": 5,
      "y": 7,
      "z": 4,
      "name": "Rock_Shale"
    },
    {
      "x": 5,
      "y": 8,
      "z": 4,
      "name": "Rock_Shale"
    },
    {
      "x": 5,
      "y": 9,
      "z": 4,
      "name": "Rock_Shale"
    },
    {
      "x": 5,
      "y": 10,
      "z": 4,
      "name": "Rock_Shale"
    },
    {
      "x": 5,
      "y": 11,
      "z": 4,
      "name": "Rock_Shale"
    },
    {
      "x": 5,
      "y": 7,
      "z": 5,
      "name": "Rock_Shale"
    },
    {
      "x": 5,
      "y": 8,
      "z": 5,
      "name": "Rock_Shale"
    },
    {
      "x": 5,
      "y": 9,
      "z": 5,
      "name": "Rock_Shale"
    },
    {
      "x": 5,
      "y": 10,
      "z": 5,
      "name": "Rock_Shale"
    },
    {
      "x": 6,
      "y": 7,
      "z": 1,
      "name": "Rock_Shale"
    },
    {
      "x": 6,
      "y": 8,
      "z": 1,
      "name": "Rock_Shale"
    },
    {
      "x": 6,
      "y": 6,
      "z": 2,
      "name": "Rock_Shale"
    },
    {
      "x": 6,
      "y": 7,
      "z": 2,
      "name": "Rock_Shale"
    },
    {
      "x": 6,
      "y": 8,
      "z": 2,
      "name": "Rock_Shale"
    },
    {
      "x": 6,
      "y": 9,
      "z": 2,
      "name": "Rock_Shale"
    },
    {
      "x": 6,
      "y": 10,
      "z": 2,
      "name": "Rock_Shale"
    },
    {
      "x": 6,
      "y": 6,
      "z": 3,
      "name": "Rock_Shale"
    },
    {
      "x": 6,
      "y": 7,
      "z": 3,
      "name": "Rock_Shale"
    },
    {
      "x": 6,
      "y": 8,
      "z": 3,
      "name": "Rock_Shale"
    },
    {
      "x": 6,
      "y": 9,
      "z": 3,
      "name": "Rock_Shale"
    },
    {
      "x": 6,
      "y": 10,
      "z": 3,
      "name": "Rock_Shale"
    },
    {
      "x": 6,
      "y": 11,
      "z": 3,
      "name": "Rubble_Shale_Medium"
    },
    {
      "x": 6,
      "y": 7,
      "z": 4,
      "name": "Rock_Shale"
    },
    {
      "x": 6,
      "y": 8,
      "z": 4,
      "name": "Rock_Shale"
    },
    {
      "x": 6,
      "y": 9,
      "z": 4,
      "name": "Rock_Shale"
    },
    {
      "x": 6,
      "y": 10,
      "z": 4,
      "name": "Rock_Shale"
    },
    {
      "x": 6,
      "y": 8,
      "z": 5,
      "name": "Rock_Shale"
    },
    {
      "x": 6,
      "y": 9,
      "z": 5,
      "name": "Rock_Shale"
    }
  ]
}