{
  "version": 8,
  "blockIdVersion": 8,
  "anchorX": -3,
  "anchorY": 2,
  "anchorZ": 9,
  "blocks": [
    {
      "x": -8,
      "y": 4,
      "z": 4,
      "name": "Rock_Shale"
    },
    {
      "x": -8,
      "y": 5,
      "z": 4,
      "name": "Rock_Shale"
    },
    {
      "x": -8,
      "y": 6,
      "z": 4,
      "name": "Rock_Shale"
    },
    {
      "x": -8,
      "y": 3,
      "z": 5,
      "name": "Rock_Shale"
    },
    {
      "x": -8,
      "y": 4,
      "z": 5,
      "name": "Rock_Shale"
    },
    {
      "x": -8,
      "y": 5,
      "z": 5,
      "name": "Rock_Shale"
    },
    {
      "x": -8,
      "y": 6,
      "z": 5,
      "name": "Rock_Shale"
    },
    {
      "x": -8,
      "y": 1,
      "z": 6,
      "name": "Rock_Shale"
    },
    {
      "x": -8,
      "y": 2,
      "z": 6,
      "name": "Rock_Shale"
    },
    {
      "x": -8,
      "y": 3,
      "z": 6,
      "name": "Rock_Shale"
    },
    {
      "x": -8,
      "y": 4,
      "z": 6,
      "name": "Rock_Shale"
    },
    {
      "x": -8,
      "y": 5,
      "z": 6,
      "name": "Rock_Shale"
    },
    {
      "x": -8,
      "y": 6,
      "z": 6,
      "name": "Rock_Shale"
    },
    {
      "x": -8,
      "y": 1,
      "z": 7,
      "name": "Rock_Shale"
    },
    {
      "x": -8,
      "y": 2,
      "z": 7,
      "name": "Rock_Shale"
    },
    {
      "x": -8,
      "y": 3,
      "z": 7,
      "name": "Rock_Shale"
    },
    {
      "x": -8,
      "y": 4,
      "z": 7,
      "name": "Rock_Shale"
    },
    {
      "x": -8,
      "y": 5,
      "z": 7,
      "name": "Rock_Shale"
    },
    {
      "x": -8,
      "y": 6,
      "z": 7,
      "name": "Rock_Shale"
    },
    {
      "x": -8,
      "y": 2,
      "z": 8,
      "name": "Rock_Shale"
    },
    {
      "x": -8,
      "y": 3,
      "z": 8,
      "name": "Rock_Shale"
    },
    {
      "x": -8,
      "y": 4,
      "z": 8,
      "name": "Rock_Shale"
    },
    {
      "x": -8,
      "y": 5,
      "z": 8,
      "name": "Rock_Shale"
    },
    {
      "x": -8,
      "y": 6,
      "z": 8,
      "name": "Rock_Shale"
    },
    {
      "x": -8,
      "y": 7,
      "z": 8,
      "name": "Rock_Basalt"
    },
    {
      "x": -8,
      "y": 2,
      "z": 9,
      "name": "Rock_Shale_Brick_Smooth"
    },
    {
      "x": -8,
      "y": 3,
      "z": 9,
      "name": "Rock_Shale_Brick_Pillar_Base"
    },
    {
      "x": -8,
      "y": 4,
      "z": 9,
      "name": "Rock_Shale_Brick_Pillar_Middle"
    },
    {
      "x": -8,
      "y": 5,
      "z": 9,
      "name": "Rock_Shale_Brick_Pillar_Base",
      "rotation": 8
    },
    {
      "x": -8,
      "y": 6,
      "z": 9,
      "name": "Rock_Shale_Brick"
    },
    {
      "x": -8,
      "y": 7,
      "z": 9,
      "name": "Rock_Basalt"
    },
    {
      "x": -7,
      "y": 1,
      "z": 2,
      "name": "Rock_Shale"
    },
    {
      "x": -7,
      "y": 2,
      "z": 2,
      "name": "Rock_Shale"
    },
    {
      "x": -7,
      "y": 3,
      "z": 2,
      "name": "Rock_Shale"
    },
    {
      "x": -7,
      "y": 4,
      "z": 2,
      "name": "Rock_Shale"
    },
    {
      "x": -7,
      "y": 5,
      "z": 2,
      "name": "Rock_Shale"
    },
    {
      "x": -7,
      "y": 6,
      "z": 2,
      "name": "Rock_Shale"
    },
    {
      "x": -7,
      "y": 1,
      "z": 3,
      "name": "Rock_Shale"
    },
    {
      "x": -7,
      "y": 2,
      "z": 3,
      "name": "Rock_Shale"
    },
    {
      "x": -7,
      "y": 3,
      "z": 3,
      "name": "Rock_Shale"
    },
    {
      "x": -7,
      "y": 4,
      "z": 3,
      "name": "Rock_Shale"
    },
    {
      "x": -7,
      "y": 5,
      "z": 3,
      "name": "Rock_Shale"
    },
    {
      "x": -7,
      "y": 6,
      "z": 3,
      "name": "Rock_Shale"
    },
    {
      "x": -7,
      "y": 1,
      "z": 4,
      "name": "Rock_Shale"
    },
    {
      "x": -7,
      "y": 2,
      "z": 4,
      "name": "Rock_Shale"
    },
    {
      "x": -7,
      "y": 3,
      "z": 4,
      "name": "Rock_Shale"
    },
    {
      "x": -7,
      "y": 4,
      "z": 4,
      "name": "Rock_Basalt"
    },
    {
      "x": -7,
      "y": 5,
      "z": 4,
      "name": "Rock_Basalt"
    },
    {
      "x": -7,
      "y": 6,
      "z": 4,
      "name": "Rock_Basalt"
    },
    {
      "x": -7,
      "y": 1,
      "z": 5,
      "name": "Rock_Shale"
    },
    {
      "x": -7,
      "y": 2,
      "z": 5,
      "name": "Rock_Shale"
    },
    {
      "x": -7,
      "y": 3,
      "z": 5,
      "name": "Rock_Shale"
    },
    {
      "x": -7,
      "y": 4,
      "z": 5,
      "name": "Rock_Basalt"
    },
    {
      "x": -7,
      "y": 5,
      "z": 5,
      "name": "Rock_Basalt"
    },
    {
      "x": -7,
      "y": 6,
      "z": 5,
      "name": "Rock_Basalt"
    },
    {
      "x": -7,
      "y": 1,
      "z": 6,
      "name": "Rock_Shale"
    },
    {
      "x": -7,
      "y": 2,
      "z": 6,
      "name": "Rock_Shale"
    },
    {
      "x": -7,
      "y": 3,
      "z": 6,
      "name": "Rock_Shale"
    },
    {
      "x": -7,
      "y": 4,
      "z": 6,
      "name": "Rock_Shale"
    },
    {
      "x": -7,
      "y": 5,
      "z": 6,
      "name": "Rock_Basalt"
    },
    {
      "x": -7,
      "y": 6,
      "z": 6,
      "name": "Rock_Basalt"
    },
    {
      "x": -7,
      "y": 1,
      "z": 7,
      "name": "Rock_Shale"
    },
    {
      "x": -7,
      "y": 2,
      "z": 7,
      "name": "Rock_Shale"
    },
    {
      "x": -7,
      "y": 3,
      "z": 7,
      "name": "Rock_Shale"
    },
    {
      "x": -7,
      "y": 4,
      "z": 7,
      "name": "Rock_Shale"
    },
    {
      "x": -7,
      "y": 5,
      "z": 7,
      "name": "Empty"
    },
    {
      "x": -7,
      "y": 6,
      "z": 7,
      "name": "Rock_Basalt"
    },
    {
      "x": -7,
      "y": 2,
      "z": 8,
      "name": "Rock_Basalt"
    },
    {
      "x": -7,
      "y": 3,
      "z": 8,
      "name": "Furniture_Ancient_Barrel"
    },
    {
      "x": -7,
      "y": 4,
      "z": 8,
      "name": "Empty"
    },
    {
      "x": -7,
      "y": 5,
      "z": 8,
      "name": "Empty"
    },
    {
      "x": -7,
      "y": 6,
      "z": 8,
      "name": "Rock_Basalt"
    },
    {
      "x": -7,
      "y": 7,
      "z": 8,
      "name": "Rock_Basalt"
    },
    {
      "x": -7,
      "y": 2,
      "z": 9,
      "name": "Rock_Basalt"
    },
    {
      "x": -7,
      "y": 3,
      "z": 9,
      "name": "Empty"
    },
    {
      "x": -7,
      "y": 4,
      "z": 9,
      "name": "Empty"
    },
    {
      "x": -7,
      "y": 5,
      "z": 9,
      "name": "Empty"
    },
    {
      "x": -7,
      "y": 6,
      "z": 9,
      "name": "Rock_Shale_Brick_Stairs",
      "rotation": 11
    },
    {
      "x": -7,
      "y": 7,
      "z": 9,
      "name": "Rock_Basalt"
    },
    {
      "x": -6,
      "y": 1,
      "z": 1,
      "name": "Rock_Shale"
    },
    {
      "x": -6,
      "y": 2,
      "z": 1,
      "name": "Rock_Shale"
    },
    {
      "x": -6,
      "y": 3,
      "z": 1,
      "name": "Rock_Shale"
    },
    {
      "x": -6,
      "y": 4,
      "z": 1,
      "name": "Rock_Shale"
    },
    {
      "x": -6,
      "y": 5,
      "z": 1,
      "name": "Rock_Shale"
    },
    {
      "x": -6,
      "y": 6,
      "z": 1,
      "name": "Rock_Basalt"
    },
    {
      "x": -6,
      "y": 1,
      "z": 2,
      "name": "Rock_Shale"
    },
    {
      "x": -6,
      "y": 2,
      "z": 2,
      "name": "Rock_Shale"
    },
    {
      "x": -6,
      "y": 3,
      "z": 2,
      "name": "Rock_Shale"
    },
    {
      "x": -6,
      "y": 4,
      "z": 2,
      "name": "Empty"
    },
    {
      "x": -6,
      "y": 5,
      "z": 2,
      "name": "Empty"
    },
    {
      "x": -6,
      "y": 6,
      "z": 2,
      "name": "Rock_Basalt"
    },
    {
      "x": -6,
      "y": 1,
      "z": 3,
      "name": "Rock_Basalt"
    },
    {
      "x": -6,
      "y": 2,
      "z": 3,
      "name": "Empty"
    },
    {
      "x": -6,
      "y": 3,
      "z": 3,
      "name": "Empty"
    },
    {
      "x": -6,
      "y": 4,
      "z": 3,
      "name": "Empty"
    },
    {
      "x": -6,
      "y": 5,
      "z": 3,
      "name": "Empty"
    },
    {
      "x": -6,
      "y": 6,
      "z": 3,
      "name": "Rock_Basalt"
    },
    {
      "x": -6,
      "y": 1,
      "z": 4,
      "name": "Rock_Shale"
    },
    {
      "x": -6,
      "y": 2,
      "z": 4,
      "name": "Wood_Redwood_Trunk",
      "support": 15
    },
    {
      "x": -6,
      "y": 3,
      "z": 4,
      "name": "Wood_Redwood_Trunk",
      "support": 15
    },
    {
      "x": -6,
      "y": 4,
      "z": 4,
      "name": "Wood_Redwood_Trunk",
      "support": 15
    },
    {
      "x": -6,
      "y": 5,
      "z": 4,
      "name": "Wood_Redwood_Trunk",
      "support": 15
    },
    {
      "x": -6,
      "y": 6,
      "z": 4,
      "name": "Rock_Basalt"
    },
    {
      "x": -6,
      "y": 1,
      "z": 5,
      "name": "Rock_Shale"
    },
    {
      "x": -6,
      "y": 2,
      "z": 5,
      "name": "Rock_Shale_Cobble_Half"
    },
    {
      "x": -6,
      "y": 3,
      "z": 5,
      "name": "Empty"
    },
    {
      "x": -6,
      "y": 4,
      "z": 5,
      "name": "Empty"
    },
    {
      "x": -6,
      "y": 5,
      "z": 5,
      "name": "Empty"
    },
    {
      "x": -6,
      "y": 6,
      "z": 5,
      "name": "Rock_Basalt"
    },
    {
      "x": -6,
      "y": 1,
      "z": 6,
      "name": "Rock_Shale"
    },
    {
      "x": -6,
      "y": 2,
      "z": 6,
      "name": "Rock_Shale_Cobble_Half"
    },
    {
      "x": -6,
      "y": 3,
      "z": 6,
      "name": "Empty"
    },
    {
      "x": -6,
      "y": 4,
      "z": 6,
      "name": "Empty"
    },
    {
      "x": -6,
      "y": 5,
      "z": 6,
      "name": "Empty"
    },
    {
      "x": -6,
      "y": 6,
      "z": 6,
      "name": "Rock_Basalt"
    },
    {
      "x": -6,
      "y": 1,
      "z": 7,
      "name": "Rock_Shale"
    },
    {
      "x": -6,
      "y": 2,
      "z": 7,
      "name": "Rock_Shale_Cobble"
    },
    {
      "x": -6,
      "y": 3,
      "z": 7,
      "name": "Empty"
    },
    {
      "x": -6,
      "y": 4,
      "z": 7,
      "name": "Empty"
    },
    {
      "x": -6,
      "y": 5,
      "z": 7,
      "name": "Empty"
    },
    {
      "x": -6,
      "y": 6,
      "z": 7,
      "name": "Rock_Basalt"
    },
    {
      "x": -6,
      "y": 2,
      "z": 8,
      "name": "Rock_Basalt"
    },
    {
      "x": -6,
      "y": 3,
      "z": 8,
      "name": "Furniture_Ancient_Barrel"
    },
    {
      "x": -6,
      "y": 4,
      "z": 8,
      "name": "Empty"
    },
    {
      "x": -6,
      "y": 5,
      "z": 8,
      "name": "Wood_Gnarled_Roots"
    },
    {
      "x": -6,
      "y": 6,
      "z": 8,
      "name": "Rock_Basalt"
    },
    {
      "x": -6,
      "y": 7,
      "z": 8,
      "name": "Rock_Basalt"
    },
    {
      "x": -6,
      "y": 2,
      "z": 9,
      "name": "Rock_Basalt"
    },
    {
      "x": -6,
      "y": 3,
      "z": 9,
      "name": "Empty"
    },
    {
      "x": -6,
      "y": 4,
      "z": 9,
      "name": "Empty"
    },
    {
      "x": -6,
      "y": 5,
      "z": 9,
      "name": "Empty"
    },
    {
      "x": -6,
      "y": 6,
      "z": 9,
      "name": "Empty"
    },
    {
      "x": -6,
      "y": 7,
      "z": 9,
      "name": "Rock_Basalt"
    },
    {
      "x": -5,
      "y": 1,
      "z": 0,
      "name": "Rock_Shale"
    },
    {
      "x": -5,
      "y": 2,
      "z": 0,
      "name": "Rock_Shale"
    },
    {
      "x": -5,
      "y": 3,
      "z": 0,
      "name": "Rock_Shale"
    },
    {
      "x": -5,
      "y": 4,
      "z": 0,
      "name": "Rock_Shale"
    },
    {
      "x": -5,
      "y": 5,
      "z": 0,
      "name": "Rock_Shale"
    },
    {
      "x": -5,
      "y": 6,
      "z": 0,
      "name": "Rock_Basalt"
    },
    {
      "x": -5,
      "y": 1,
      "z": 1,
      "name": "Rock_Shale"
    },
    {
      "x": -5,
      "y": 2,
      "z": 1,
      "name": "Rock_Shale"
    },
    {
      "x": -5,
      "y": 3,
      "z": 1,
      "name": "Rock_Shale"
    },
    {
      "x": -5,
      "y": 4,
      "z": 1,
      "name": "Rock_Shale"
    },
    {
      "x": -5,
      "y": 5,
      "z": 1,
      "name": "Empty"
    },
    {
      "x": -5,
      "y": 6,
      "z": 1,
      "name": "Rock_Basalt"
    },
    {
      "x": -5,
      "y": 1,
      "z": 2,
      "name": "Rock_Shale"
    },
    {
      "x": -5,
      "y": 2,
      "z": 2,
      "name": "Rock_Shale"
    },
    {
      "x": -5,
      "y": 3,
      "z": 2,
      "name": "Rock_Shale_Stalactites_Small"
    },
    {
      "x": -5,
      "y": 4,
      "z": 2,
      "name": "Empty"
    },
    {
      "x": -5,
      "y": 5,
      "z": 2,
      "name": "Empty"
    },
    {
      "x": -5,
      "y": 6,
      "z": 2,
      "name": "Rock_Basalt"
    },
    {
      "x": -5,
      "y": 1,
      "z": 3,
      "name": "Rock_Basalt"
    },
    {
      "x": -5,
      "y": 2,
      "z": 3,
      "name": "Rubble_Basalt_Medium"
    },
    {
      "x": -5,
      "y": 3,
      "z": 3,
      "name": "Empty"
    },
    {
      "x": -5,
      "y": 4,
      "z": 3,
      "name": "Empty"
    },
    {
      "x": -5,
      "y": 5,
      "z": 3,
      "name": "Plant_Bush_Dead_Hanging"
    },
    {
      "x": -5,
      "y": 6,
      "z": 3,
      "name": "Rock_Basalt"
    },
    {
      "x": -5,
      "y": 1,
      "z": 4,
      "name": "Rock_Basalt"
    },
    {
      "x": -5,
      "y": 2,
      "z": 4,
      "name": "Empty"
    },
    {
      "x": -5,
      "y": 3,
      "z": 4,
      "name": "Empty"
    },
    {
      "x": -5,
      "y": 4,
      "z": 4,
      "name": "Empty"
    },
    {
      "x": -5,
      "y": 5,
      "z": 4,
      "name": "Empty"
    },
    {
      "x": -5,
      "y": 6,
      "z": 4,
      "name": "Rock_Basalt"
    },
    {
      "x": -5,
      "y": 1,
      "z": 5,
      "name": "Rock_Shale"
    },
    {
      "x": -5,
      "y": 2,
      "z": 5,
      "name": "Rock_Shale_Cobble_Half"
    },
    {
      "x": -5,
      "y": 3,
      "z": 5,
      "name": "Empty"
    },
    {
      "x": -5,
      "y": 4,
      "z": 5,
      "name": "Empty"
    },
    {
      "x": -5,
      "y": 5,
      "z": 5,
      "name": "Empty"
    },
    {
      "x": -5,
      "y": 6,
      "z": 5,
      "name": "Rock_Basalt"
    },
    {
      "x": -5,
      "y": 1,
      "z": 6,
      "name": "Rock_Shale"
    },
    {
      "x": -5,
      "y": 2,
      "z": 6,
      "name": "Rock_Shale_Cobble_Half"
    },
    {
      "x": -5,
      "y": 3,
      "z": 6,
      "name": "Empty"
    },
    {
      "x": -5,
      "y": 4,
      "z": 6,
      "name": "Empty"
    },
    {
      "x": -5,
      "y": 5,
      "z": 6,
      "name": "Empty"
    },
    {
      "x": -5,
      "y": 6,
      "z": 6,
      "name": "Rock_Basalt"
    },
    {
      "x": -5,
      "y": 1,
      "z": 7,
      "name": "Rock_Shale"
    },
    {
      "x": -5,
      "y": 2,
      "z": 7,
      "name": "Rock_Shale_Cobble"
    },
    {
      "x": -5,
      "y": 3,
      "z": 7,
      "name": "Deco_Bone_Skulls"
    },
    {
      "x": -5,
      "y": 4,
      "z": 7,
      "name": "Empty"
    },
    {
      "x": -5,
      "y": 5,
      "z": 7,
      "name": "Empty"
    },
    {
      "x": -5,
      "y": 6,
      "z": 7,
      "name": "Rock_Basalt"
    },
    {
      "x": -5,
      "y": 2,
      "z": 8,
      "name": "Rock_Shale_Cobble"
    },
    {
      "x": -5,
      "y": 3,
      "z": 8,
      "name": "Empty"
    },
    {
      "x": -5,
      "y": 4,
      "z": 8,
      "name": "Empty"
    },
    {
      "x": -5,
      "y": 5,
      "z": 8,
      "name": "Empty"
    },
    {
      "x": -5,
      "y": 6,
      "z": 8,
      "name": "Rock_Basalt"
    },
    {
      "x": -5,
      "y": 7,
      "z": 8,
      "name": "Rock_Basalt"
    },
    {
      "x": -5,
      "y": 2,
      "z": 9,
      "name": "Rock_Basalt"
    },
    {
      "x": -5,
      "y": 3,
      "z": 9,
      "name": "Empty"
    },
    {
      "x": -5,
      "y": 4,
      "z": 9,
      "name": "Empty"
    },
    {
      "x": -5,
      "y": 5,
      "z": 9,
      "name": "Empty"
    },
    {
      "x": -5,
      "y": 6,
      "z": 9,
      "name": "Empty"
    },
    {
      "x": -5,
      "y": 7,
      "z": 9,
      "name": "Rock_Basalt"
    },
    {
      "x": -4,
      "y": 0,
      "z": -2,
      "name": "Rock_Shale"
    },
    {
      "x": -4,
      "y": 1,
      "z": -2,
      "name": "Rock_Basalt_Brick"
    },
    {
      "x": -4,
      "y": 2,
      "z": -2,
      "name": "Rock_Basalt_Brick"
    },
    {
      "x": -4,
      "y": 3,
      "z": -2,
      "name": "Rock_Basalt_Brick"
    },
    {
      "x": -4,
      "y": 4,
      "z": -2,
      "name": "Rock_Basalt_Brick"
    },
    {
      "x": -4,
      "y": 5,
      "z": -2,
      "name": "Rock_Basalt"
    },
    {
      "x": -4,
      "y": 0,
      "z": -1,
      "name": "Rock_Shale"
    },
    {
      "x": -4,
      "y": 1,
      "z": -1,
      "name": "Rock_Basalt_Brick"
    },
    {
      "x": -4,
      "y": 2,
      "z": -1,
      "name": "Rock_Basalt_Brick"
    },
    {
      "x": -4,
      "y": 3,
      "z": -1,
      "name": "Rock_Basalt_Brick"
    },
    {
      "x": -4,
      "y": 4,
      "z": -1,
      "name": "Rock_Basalt_Brick"
    },
    {
      "x": -4,
      "y": 5,
      "z": -1,
      "name": "Rock_Basalt"
    },
    {
      "x": -4,
      "y": 1,
      "z": 0,
      "name": "Rock_Shale"
    },
    {
      "x": -4,
      "y": 2,
      "z": 0,
      "name": "Rock_Shale"
    },
    {
      "x": -4,
      "y": 3,
      "z": 0,
      "name": "Rock_Shale"
    },
    {
      "x": -4,
      "y": 4,
      "z": 0,
      "name": "Rock_Basalt"
    },
    {
      "x": -4,
      "y": 5,
      "z": 0,
      "name": "Rock_Basalt"
    },
    {
      "x": -4,
      "y": 6,
      "z": 0,
      "name": "Rock_Basalt"
    },
    {
      "x": -4,
      "y": 1,
      "z": 1,
      "name": "Soil_Dirt_Cold"
    },
    {
      "x": -4,
      "y": 2,
      "z": 1,
      "name": "Empty"
    },
    {
      "x": -4,
      "y": 3,
      "z": 1,
      "name": "Empty"
    },
    {
      "x": -4,
      "y": 4,
      "z": 1,
      "name": "Empty"
    },
    {
      "x": -4,
      "y": 5,
      "z": 1,
      "name": "Empty"
    },
    {
      "x": -4,
      "y": 6,
      "z": 1,
      "name": "Rock_Basalt"
    },
    {
      "x": -4,
      "y": 1,
      "z": 2,
      "name": "Soil_Dirt_Cold"
    },
    {
      "x": -4,
      "y": 2,
      "z": 2,
      "name": "*Plant_Crop_Berry_Winter_Block_State_Definitions_StageFinal",
      "components": {
        "Components": {
          "FarmingBlock": {}
        }
      }
    },
    {
      "x": -4,
      "y": 3,
      "z": 2,
      "name": "Empty"
    },
    {
      "x": -4,
      "y": 4,
      "z": 2,
      "name": "Empty"
    },
    {
      "x": -4,
      "y": 5,
      "z": 2,
      "name": "Empty"
    },
    {
      "x": -4,
      "y": 6,
      "z": 2,
      "name": "Rock_Basalt"
    },
    {
      "x": -4,
      "y": 1,
      "z": 3,
      "name": "Soil_Dirt_Cold"
    },
    {
      "x": -4,
      "y": 2,
      "z": 3,
      "name": "Rock_Shale_Brick_Beam"
    },
    {
      "x": -4,
      "y": 3,
      "z": 3,
      "name": "Furniture_Human_Ruins_Torch"
    },
    {
      "x": -4,
      "y": 4,
      "z": 3,
      "name": "Empty"
    },
    {
      "x": -4,
      "y": 5,
      "z": 3,
      "name": "Empty"
    },
    {
      "x": -4,
      "y": 6,
      "z": 3,
      "name": "Rock_Basalt"
    },
    {
      "x": -4,
      "y": 1,
      "z": 4,
      "name": "Rock_Basalt"
    },
    {
      "x": -4,
      "y": 2,
      "z": 4,
      "name": "Empty"
    },
    {
      "x": -4,
      "y": 3,
      "z": 4,
      "name": "Empty"
    },
    {
      "x": -4,
      "y": 4,
      "z": 4,
      "name": "Empty"
    },
    {
      "x": -4,
      "y": 5,
      "z": 4,
      "name": "Wood_Gnarled_Roots"
    },
    {
      "x": -4,
      "y": 6,
      "z": 4,
      "name": "Rock_Basalt"
    },
    {
      "x": -4,
      "y": 1,
      "z": 5,
      "name": "Rock_Shale_Cobble"
    },
    {
      "x": -4,
      "y": 2,
      "z": 5,
      "name": "Empty"
    },
    {
      "x": -4,
      "y": 3,
      "z": 5,
      "name": "Empty"
    },
    {
      "x": -4,
      "y": 4,
      "z": 5,
      "name": "Empty"
    },
    {
      "x": -4,
      "y": 5,
      "z": 5,
      "name": "Empty"
    },
    {
      "x": -4,
      "y": 6,
      "z": 5,
      "name": "Rock_Basalt"
    },
    {
      "x": -4,
      "y": 1,
      "z": 6,
      "name": "Rock_Shale"
    },
    {
      "x": -4,
      "y": 2,
      "z": 6,
      "name": "Rock_Shale_Brick_Half"
    },
    {
      "x": -4,
      "y": 3,
      "z": 6,
      "name": "Empty"
    },
    {
      "x": -4,
      "y": 4,
      "z": 6,
      "name": "Empty"
    },
    {
      "x": -4,
      "y": 5,
      "z": 6,
      "name": "Empty"
    },
    {
      "x": -4,
      "y": 6,
      "z": 6,
      "name": "Rock_Basalt"
    },
    {
      "x": -4,
      "y": 1,
      "z": 7,
      "name": "Rock_Shale"
    },
    {
      "x": -4,
      "y": 2,
      "z": 7,
      "name": "Rock_Shale_Brick_Half"
    },
    {
      "x": -4,
      "y": 3,
      "z": 7,
      "name": "Empty"
    },
    {
      "x": -4,
      "y": 4,
      "z": 7,
      "name": "Empty"
    },
    {
      "x": -4,
      "y": 5,
      "z": 7,
      "name": "Empty"
    },
    {
      "x": -4,
      "y": 6,
      "z": 7,
      "name": "Rock_Basalt"
    },
    {
      "x": -4,
      "y": 2,
      "z": 8,
      "name": "Rock_Shale_Brick"
    },
    {
      "x": -4,
      "y": 3,
      "z": 8,
      "name": "Empty"
    },
    {
      "x": -4,
      "y": 4,
      "z": 8,
      "name": "Empty"
    },
    {
      "x": -4,
      "y": 5,
      "z": 8,
      "name": "Empty"
    },
    {
      "x": -4,
      "y": 6,
      "z": 8,
      "name": "Empty"
    },
    {
      "x": -4,
      "y": 7,
      "z": 8,
      "name": "Rock_Basalt"
    },
    {
      "x": -4,
      "y": 2,
      "z": 9,
      "name": "Rock_Shale_Brick"
    },
    {
      "x": -4,
      "y": 3,
      "z": 9,
      "name": "Empty"
    },
    {
      "x": -4,
      "y": 4,
      "z": 9,
      "name": "Empty"
    },
    {
      "x": -4,
      "y": 5,
      "z": 9,
      "name": "Empty"
    },
    {
      "x": -4,
      "y": 6,
      "z": 9,
      "name": "Empty"
    },
    {
      "x": -4,
      "y": 7,
      "z": 9,
      "name": "Rock_Basalt"
    },
    {
      "x": -3,
      "y": 0,
      "z": -6,
      "name": "Rock_Shale"
    },
    {
      "x": -3,
      "y": 1,
      "z": -6,
      "name": "Rock_Shale"
    },
    {
      "x": -3,
      "y": 2,
      "z": -6,
      "name": "Rock_Shale"
    },
    {
      "x": -3,
      "y": 3,
      "z": -6,
      "name": "Rock_Shale"
    },
    {
      "x": -3,
      "y": 4,
      "z": -6,
      "name": "Rock_Shale"
    },
    {
      "x": -3,
      "y": 5,
      "z": -6,
      "name": "Rock_Basalt"
    },
    {
      "x": -3,
      "y": 0,
      "z": -5,
      "name": "Rock_Shale"
    },
    {
      "x": -3,
      "y": 1,
      "z": -5,
      "name": "Rock_Shale"
    },
    {
      "x": -3,
      "y": 2,
      "z": -5,
      "name": "Rock_Shale"
    },
    {
      "x": -3,
      "y": 3,
      "z": -5,
      "name": "Rock_Shale"
    },
    {
      "x": -3,
      "y": 4,
      "z": -5,
      "name": "Rock_Shale"
    },
    {
      "x": -3,
      "y": 5,
      "z": -5,
      "name": "Rock_Basalt"
    },
    {
      "x": -3,
      "y": 0,
      "z": -4,
      "name": "Rock_Shale"
    },
    {
      "x": -3,
      "y": 1,
      "z": -4,
      "name": "Rock_Shale"
    },
    {
      "x": -3,
      "y": 2,
      "z": -4,
      "name": "Rock_Shale"
    },
    {
      "x": -3,
      "y": 3,
      "z": -4,
      "name": "Rock_Shale"
    },
    {
      "x": -3,
      "y": 4,
      "z": -4,
      "name": "Rock_Shale"
    },
    {
      "x": -3,
      "y": 5,
      "z": -4,
      "name": "Rock_Basalt"
    },
    {
      "x": -3,
      "y": 0,
      "z": -3,
      "name": "Rock_Shale"
    },
    {
      "x": -3,
      "y": 1,
      "z": -3,
      "name": "Rock_Shale"
    },
    {
      "x": -3,
      "y": 2,
      "z": -3,
      "name": "Rock_Shale"
    },
    {
      "x": -3,
      "y": 3,
      "z": -3,
      "name": "Rock_Shale"
    },
    {
      "x": -3,
      "y": 4,
      "z": -3,
      "name": "Rock_Shale"
    },
    {
      "x": -3,
      "y": 5,
      "z": -3,
      "name": "Rock_Basalt"
    },
    {
      "x": -3,
      "y": 0,
      "z": -2,
      "name": "Rock_Shale"
    },
    {
      "x": -3,
      "y": 1,
      "z": -2,
      "name": "Rock_Basalt_Brick"
    },
    {
      "x": -3,
      "y": 2,
      "z": -2,
      "name": "Rock_Basalt_Brick"
    },
    {
      "x": -3,
      "y": 3,
      "z": -2,
      "name": "Rock_Basalt_Brick"
    },
    {
      "x": -3,
      "y": 4,
      "z": -2,
      "name": "Rock_Basalt_Brick"
    },
    {
      "x": -3,
      "y": 5,
      "z": -2,
      "name": "Rock_Basalt"
    },
    {
      "x": -3,
      "y": 0,
      "z": -1,
      "name": "Rock_Shale"
    },
    {
      "x": -3,
      "y": 1,
      "z": -1,
      "name": "Rock_Basalt_Brick"
    },
    {
      "x": -3,
      "y": 2,
      "z": -1,
      "name": "Rock_Basalt_Brick"
    },
    {
      "x": -3,
      "y": 3,
      "z": -1,
      "name": "Rock_Basalt_Brick"
    },
    {
      "x": -3,
      "y": 4,
      "z": -1,
      "name": "Rock_Basalt_Brick"
    },
    {
      "x": -3,
      "y": 5,
      "z": -1,
      "name": "Rock_Basalt"
    },
    {
      "x": -3,
      "y": 1,
      "z": 0,
      "name": "Rock_Shale"
    },
    {
      "x": -3,
      "y": 2,
      "z": 0,
      "name": "Wood_Redwood_Branch_Long",
      "support": 15
    },
    {
      "x": -3,
      "y": 3,
      "z": 0,
      "name": "Wood_Redwood_Branch_Long",
      "support": 15
    },
    {
      "x": -3,
      "y": 4,
      "z": 0,
      "name": "Wood_Redwood_Branch_Long",
      "support": 15
    },
    {
      "x": -3,
      "y": 5,
      "z": 0,
      "name": "Rock_Basalt"
    },
    {
      "x": -3,
      "y": 6,
      "z": 0,
      "name": "Rock_Basalt"
    },
    {
      "x": -3,
      "y": 1,
      "z": 1,
      "name": "Soil_Dirt_Cold"
    },
    {
      "x": -3,
      "y": 2,
      "z": 1,
      "name": "Plant_Bush_Dead_Twisted"
    },
    {
      "x": -3,
      "y": 3,
      "z": 1,
      "name": "Empty"
    },
    {
      "x": -3,
      "y": 4,
      "z": 1,
      "name": "Empty"
    },
    {
      "x": -3,
      "y": 5,
      "z": 1,
      "name": "Empty"
    },
    {
      "x": -3,
      "y": 6,
      "z": 1,
      "name": "Rock_Basalt"
    },
    {
      "x": -3,
      "y": 1,
      "z": 2,
      "name": "Rock_Shale_Cobble"
    },
    {
      "x": -3,
      "y": 2,
      "z": 2,
      "name": "Deco_Bone_Skulls"
    },
    {
      "x": -3,
      "y": 3,
      "z": 2,
      "name": "Empty"
    },
    {
      "x": -3,
      "y": 4,
      "z": 2,
      "name": "Empty"
    },
    {
      "x": -3,
      "y": 5,
      "z": 2,
      "name": "Empty"
    },
    {
      "x": -3,
      "y": 6,
      "z": 2,
      "name": "Rock_Basalt"
    },
    {
      "x": -3,
      "y": 1,
      "z": 3,
      "name": "Rock_Shale_Cobble"
    },
    {
      "x": -3,
      "y": 2,
      "z": 3,
      "name": "Empty"
    },
    {
      "x": -3,
      "y": 3,
      "z": 3,
      "name": "Empty"
    },
    {
      "x": -3,
      "y": 4,
      "z": 3,
      "name": "Empty"
    },
    {
      "x": -3,
      "y": 5,
      "z": 3,
      "name": "Empty"
    },
    {
      "x": -3,
      "y": 6,
      "z": 3,
      "name": "Rock_Basalt"
    },
    {
      "x": -3,
      "y": 1,
      "z": 4,
      "name": "Rock_Shale_Brick"
    },
    {
      "x": -3,
      "y": 2,
      "z": 4,
      "name": "Empty"
    },
    {
      "x": -3,
      "y": 3,
      "z": 4,
      "name": "Empty"
    },
    {
      "x": -3,
      "y": 4,
      "z": 4,
      "name": "Empty"
    },
    {
      "x": -3,
      "y": 5,
      "z": 4,
      "name": "Empty"
    },
    {
      "x": -3,
      "y": 6,
      "z": 4,
      "name": "Rock_Basalt"
    },
    {
      "x": -3,
      "y": 1,
      "z": 5,
      "name": "Rock_Shale_Brick"
    },
    {
      "x": -3,
      "y": 2,
      "z": 5,
      "name": "Empty"
    },
    {
      "x": -3,
      "y": 3,
      "z": 5,
      "name": "Empty"
    },
    {
      "x": -3,
      "y": 4,
      "z": 5,
      "name": "Empty"
    },
    {
      "x": -3,
      "y": 5,
      "z": 5,
      "name": "Empty"
    },
    {
      "x": -3,
      "y": 6,
      "z": 5,
      "name": "Rock_Basalt"
    },
    {
      "x": -3,
      "y": 1,
      "z": 6,
      "name": "Rock_Shale"
    },
    {
      "x": -3,
      "y": 2,
      "z": 6,
      "name": "Rock_Shale_Brick_Half"
    },
    {
      "x": -3,
      "y": 3,
      "z": 6,
      "name": "Empty"
    },
    {
      "x": -3,
      "y": 4,
      "z": 6,
      "name": "Empty"
    },
    {
      "x": -3,
      "y": 5,
      "z": 6,
      "name": "Empty"
    },
    {
      "x": -3,
      "y": 6,
      "z": 6,
      "name": "Rock_Basalt"
    },
    {
      "x": -3,
      "y": 1,
      "z": 7,
      "name": "Rock_Shale"
    },
    {
      "x": -3,
      "y": 2,
      "z": 7,
      "name": "Rock_Shale_Brick_Half"
    },
    {
      "x": -3,
      "y": 3,
      "z": 7,
      "name": "Empty"
    },
    {
      "x": -3,
      "y": 4,
      "z": 7,
      "name": "Empty"
    },
    {
      "x": -3,
      "y": 5,
      "z": 7,
      "name": "Empty"
    },
    {
      "x": -3,
      "y": 6,
      "z": 7,
      "name": "Rock_Basalt"
    },
    {
      "x": -3,
      "y": 2,
      "z": 8,
      "name": "Rock_Shale_Brick"
    },
    {
      "x": -3,
      "y": 3,
      "z": 8,
      "name": "Empty"
    },
    {
      "x": -3,
      "y": 4,
      "z": 8,
      "name": "Empty"
    },
    {
      "x": -3,
      "y": 5,
      "z": 8,
      "name": "Empty"
    },
    {
      "x": -3,
      "y": 6,
      "z": 8,
      "name": "Empty"
    },
    {
      "x": -3,
      "y": 7,
      "z": 8,
      "name": "Rock_Basalt"
    },
    {
      "x": -3,
      "y": 2,
      "z": 9,
      "name": "Rock_Shale_Brick"
    },
    {
      "x": -3,
      "y": 3,
      "z": 9,
      "name": "Empty"
    },
    {
      "x": -3,
      "y": 4,
      "z": 9,
      "name": "Empty"
    },
    {
      "x": -3,
      "y": 5,
      "z": 9,
      "name": "Empty"
    },
    {
      "x": -3,
      "y": 6,
      "z": 9,
      "name": "Empty"
    },
    {
      "x": -3,
      "y": 7,
      "z": 9,
      "name": "Rock_Basalt"
    },
    {
      "x": -2,
      "y": 0,
      "z": -8,
      "name": "Rock_Shale"
    },
    {
      "x": -2,
      "y": 1,
      "z": -8,
      "name": "Rock_Shale"
    },
    {
      "x": -2,
      "y": 2,
      "z": -8,
      "name": "Rock_Shale"
    },
    {
      "x": -2,
      "y": 3,
      "z": -8,
      "name": "Rock_Shale"
    },
    {
      "x": -2,
      "y": 4,
      "z": -8,
      "name": "Rock_Shale"
    },
    {
      "x": -2,
      "y": 5,
      "z": -8,
      "name": "Rock_Basalt"
    },
    {
      "x": -2,
      "y": 0,
      "z": -7,
      "name": "Rock_Shale"
    },
    {
      "x": -2,
      "y": 1,
      "z": -7,
      "name": "Rock_Shale"
    },
    {
      "x": -2,
      "y": 2,
      "z": -7,
      "name": "Rock_Shale"
    },
    {
      "x": -2,
      "y": 3,
      "z": -7,
      "name": "Rock_Shale"
    },
    {
      "x": -2,
      "y": 4,
      "z": -7,
      "name": "Rock_Shale"
    },
    {
      "x": -2,
      "y": 5,
      "z": -7,
      "name": "Rock_Basalt"
    },
    {
      "x": -2,
      "y": 0,
      "z": -6,
      "name": "Rock_Shale"
    },
    {
      "x": -2,
      "y": 1,
      "z": -6,
      "name": "Rock_Shale"
    },
    {
      "x": -2,
      "y": 2,
      "z": -6,
      "name": "Rock_Shale"
    },
    {
      "x": -2,
      "y": 3,
      "z": -6,
      "name": "Rock_Shale"
    },
    {
      "x": -2,
      "y": 4,
      "z": -6,
      "name": "Rock_Shale"
    },
    {
      "x": -2,
      "y": 5,
      "z": -6,
      "name": "Rock_Basalt"
    },
    {
      "x": -2,
      "y": 0,
      "z": -5,
      "name": "Rock_Basalt"
    },
    {
      "x": -2,
      "y": 1,
      "z": -5,
      "name": "Rock_Basalt"
    },
    {
      "x": -2,
      "y": 2,
      "z": -5,
      "name": "Rock_Basalt"
    },
    {
      "x": -2,
      "y": 3,
      "z": -5,
      "name": "Rock_Shale_Stalactites_Large",
      "filler": 31744,
      "rotation": 8
    },
    {
      "x": -2,
      "y": 4,
      "z": -5,
      "name": "Rock_Shale_Stalactites_Large",
      "rotation": 8
    },
    {
      "x": -2,
      "y": 5,
      "z": -5,
      "name": "Rock_Basalt"
    },
    {
      "x": -2,
      "y": 0,
      "z": -4,
      "name": "Rock_Shale_Brick"
    },
    {
      "x": -2,
      "y": 1,
      "z": -4,
      "name": "Furniture_Ancient_Barrel"
    },
    {
      "x": -2,
      "y": 2,
      "z": -4,
      "name": "Empty"
    },
    {
      "x": -2,
      "y": 3,
      "z": -4,
      "name": "Empty"
    },
    {
      "x": -2,
      "y": 4,
      "z": -4,
      "name": "Empty"
    },
    {
      "x": -2,
      "y": 5,
      "z": -4,
      "name": "Rock_Basalt"
    },
    {
      "x": -2,
      "y": 0,
      "z": -3,
      "name": "Rock_Shale_Brick"
    },
    {
      "x": -2,
      "y": 1,
      "z": -3,
      "name": "Furniture_Ancient_Barrel"
    },
    {
      "x": -2,
      "y": 2,
      "z": -3,
      "name": "Empty"
    },
    {
      "x": -2,
      "y": 3,
      "z": -3,
      "name": "Empty"
    },
    {
      "x": -2,
      "y": 4,
      "z": -3,
      "name": "Empty"
    },
    {
      "x": -2,
      "y": 5,
      "z": -3,
      "name": "Rock_Basalt"
    },
    {
      "x": -2,
      "y": 0,
      "z": -2,
      "name": "Rock_Shale"
    },
    {
      "x": -2,
      "y": 1,
      "z": -2,
      "name": "Rock_Shale_Brick_Half"
    },
    {
      "x": -2,
      "y": 2,
      "z": -2,
      "name": "Empty"
    },
    {
      "x": -2,
      "y": 3,
      "z": -2,
      "name": "Rock_Basalt_Brick_Half",
      "rotation": 5
    },
    {
      "x": -2,
      "y": 4,
      "z": -2,
      "name": "Rock_Basalt_Brick"
    },
    {
      "x": -2,
      "y": 5,
      "z": -2,
      "name": "Rock_Basalt"
    },
    {
      "x": -2,
      "y": 0,
      "z": -1,
      "name": "Rock_Shale"
    },
    {
      "x": -2,
      "y": 1,
      "z": -1,
      "name": "Rock_Shale_Brick_Half"
    },
    {
      "x": -2,
      "y": 2,
      "z": -1,
      "name": "Empty"
    },
    {
      "x": -2,
      "y": 3,
      "z": -1,
      "name": "Rock_Basalt_Brick_Half",
      "rotation": 5
    },
    {
      "x": -2,
      "y": 4,
      "z": -1,
      "name": "Rock_Basalt_Brick"
    },
    {
      "x": -2,
      "y": 5,
      "z": -1,
      "name": "Rock_Basalt"
    },
    {
      "x": -2,
      "y": 1,
      "z": 0,
      "name": "Rock_Shale_Brick"
    },
    {
      "x": -2,
      "y": 2,
      "z": 0,
      "name": "Empty"
    },
    {
      "x": -2,
      "y": 3,
      "z": 0,
      "name": "Empty"
    },
    {
      "x": -2,
      "y": 4,
      "z": 0,
      "name": "Empty"
    },
    {
      "x": -2,
      "y": 5,
      "z": 0,
      "name": "Empty"
    },
    {
      "x": -2,
      "y": 6,
      "z": 0,
      "name": "Rock_Basalt"
    },
    {
      "x": -2,
      "y": 1,
      "z": 1,
      "name": "Rock_Shale_Brick"
    },
    {
      "x": -2,
      "y": 2,
      "z": 1,
      "name": "Deco_Bone_Pile"
    },
    {
      "x": -2,
      "y": 3,
      "z": 1,
      "name": "Empty"
    },
    {
      "x": -2,
      "y": 4,
      "z": 1,
      "name": "Empty"
    },
    {
      "x": -2,
      "y": 5,
      "z": 1,
      "name": "Empty"
    },
    {
      "x": -2,
      "y": 6,
      "z": 1,
      "name": "Rock_Basalt"
    },
    {
      "x": -2,
      "y": 1,
      "z": 2,
      "name": "Rock_Shale_Cobble"
    },
    {
      "x": -2,
      "y": 2,
      "z": 2,
      "name": "Empty"
    },
    {
      "x": -2,
      "y": 3,
      "z": 2,
      "name": "Empty"
    },
    {
      "x": -2,
      "y": 4,
      "z": 2,
      "name": "Empty"
    },
    {
      "x": -2,
      "y": 5,
      "z": 2,
      "name": "Empty"
    },
    {
      "x": -2,
      "y": 6,
      "z": 2,
      "name": "Rock_Basalt"
    },
    {
      "x": -2,
      "y": 1,
      "z": 3,
      "name": "Rock_Shale"
    },
    {
      "x": -2,
      "y": 2,
      "z": 3,
      "name": "Empty"
    },
    {
      "x": -2,
      "y": 3,
      "z": 3,
      "name": "Empty"
    },
    {
      "x": -2,
      "y": 4,
      "z": 3,
      "name": "Empty"
    },
    {
      "x": -2,
      "y": 5,
      "z": 3,
      "name": "Empty"
    },
    {
      "x": -2,
      "y": 6,
      "z": 3,
      "name": "Rock_Basalt"
    },
    {
      "x": -2,
      "y": 1,
      "z": 4,
      "name": "Rock_Shale"
    },
    {
      "x": -2,
      "y": 2,
      "z": 4,
      "name": "Empty"
    },
    {
      "x": -2,
      "y": 3,
      "z": 4,
      "name": "Empty"
    },
    {
      "x": -2,
      "y": 4,
      "z": 4,
      "name": "Empty"
    },
    {
      "x": -2,
      "y": 5,
      "z": 4,
      "name": "Empty"
    },
    {
      "x": -2,
      "y": 6,
      "z": 4,
      "name": "Rock_Basalt"
    },
    {
      "x": -2,
      "y": 1,
      "z": 5,
      "name": "Rock_Shale_Brick"
    },
    {
      "x": -2,
      "y": 2,
      "z": 5,
      "name": "Empty"
    },
    {
      "x": -2,
      "y": 3,
      "z": 5,
      "name": "Empty"
    },
    {
      "x": -2,
      "y": 4,
      "z": 5,
      "name": "Empty"
    },
    {
      "x": -2,
      "y": 5,
      "z": 5,
      "name": "Empty"
    },
    {
      "x": -2,
      "y": 6,
      "z": 5,
      "name": "Rock_Basalt"
    },
    {
      "x": -2,
      "y": 1,
      "z": 6,
      "name": "Rock_Shale_Brick"
    },
    {
      "x": -2,
      "y": 2,
      "z": 6,
      "name": "Empty"
    },
    {
      "x": -2,
      "y": 3,
      "z": 6,
      "name": "Empty"
    },
    {
      "x": -2,
      "y": 4,
      "z": 6,
      "name": "Empty"
    },
    {
      "x": -2,
      "y": 5,
      "z": 6,
      "name": "Empty"
    },
    {
      "x": -2,
      "y": 6,
      "z": 6,
      "name": "Rock_Basalt"
    },
    {
      "x": -2,
      "y": 1,
      "z": 7,
      "name": "Rock_Shale"
    },
    {
      "x": -2,
      "y": 2,
      "z": 7,
      "name": "Rock_Shale_Cobble_Half"
    },
    {
      "x": -2,
      "y": 3,
      "z": 7,
      "name": "Empty"
    },
    {
      "x": -2,
      "y": 4,
      "z": 7,
      "name": "Empty"
    },
    {
      "x": -2,
      "y": 5,
      "z": 7,
      "name": "Empty"
    },
    {
      "x": -2,
      "y": 6,
      "z": 7,
      "name": "Rock_Basalt"
    },
    {
      "x": -2,
      "y": 2,
      "z": 8,
      "name": "Rock_Shale_Cobble"
    },
    {
      "x": -2,
      "y": 3,
      "z": 8,
      "name": "Empty"
    },
    {
      "x": -2,
      "y": 4,
      "z": 8,
      "name": "Empty"
    },
    {
      "x": -2,
      "y": 5,
      "z": 8,
      "name": "Empty"
    },
    {
      "x": -2,
      "y": 6,
      "z": 8,
      "name": "Empty"
    },
    {
      "x": -2,
      "y": 7,
      "z": 8,
      "name": "Rock_Basalt"
    },
    {
      "x": -2,
      "y": 2,
      "z": 9,
      "name": "Rock_Shale_Cobble"
    },
    {
      "x": -2,
      "y": 3,
      "z": 9,
      "name": "Empty"
    },
    {
      "x": -2,
      "y": 4,
      "z": 9,
      "name": "Empty"
    },
    {
      "x": -2,
      "y": 5,
      "z": 9,
      "name": "Empty"
    },
    {
      "x": -2,
      "y": 6,
      "z": 9,
      "name": "Empty"
    },
    {
      "x": -2,
      "y": 7,
      "z": 9,
      "name": "Rock_Basalt"
    },
    {
      "x": -1,
      "y": 0,
      "z": -9,
      "name": "Rock_Shale"
    },
    {
      "x": -1,
      "y": 1,
      "z": -9,
      "name": "Rock_Shale"
    },
    {
      "x": -1,
      "y": 2,
      "z": -9,
      "name": "Rock_Shale"
    },
    {
      "x": -1,
      "y": 3,
      "z": -9,
      "name": "Rock_Shale"
    },
    {
      "x": -1,
      "y": 4,
      "z": -9,
      "name": "Rock_Shale"
    },
    {
      "x": -1,
      "y": 5,
      "z": -9,
      "name": "Rock_Basalt"
    },
    {
      "x": -1,
      "y": 0,
      "z": -8,
      "name": "Rock_Shale"
    },
    {
      "x": -1,
      "y": 1,
      "z": -8,
      "name": "Rock_Shale"
    },
    {
      "x": -1,
      "y": 2,
      "z": -8,
      "name": "Rock_Shale"
    },
    {
      "x": -1,
      "y": 3,
      "z": -8,
      "name": "Rock_Shale"
    },
    {
      "x": -1,
      "y": 4,
      "z": -8,
      "name": "Rock_Shale"
    },
    {
      "x": -1,
      "y": 5,
      "z": -8,
      "name": "Rock_Basalt"
    },
    {
      "x": -1,
      "y": 0,
      "z": -7,
      "name": "Rock_Basalt"
    },
    {
      "x": -1,
      "y": 1,
      "z": -7,
      "name": "Rock_Basalt"
    },
    {
      "x": -1,
      "y": 2,
      "z": -7,
      "name": "Rubble_Basalt_Medium"
    },
    {
      "x": -1,
      "y": 3,
      "z": -7,
      "name": "Rock_Shale"
    },
    {
      "x": -1,
      "y": 4,
      "z": -7,
      "name": "Rock_Shale"
    },
    {
      "x": -1,
      "y": 5,
      "z": -7,
      "name": "Rock_Basalt"
    },
    {
      "x": -1,
      "y": 0,
      "z": -6,
      "name": "Rock_Basalt"
    },
    {
      "x": -1,
      "y": 1,
      "z": -6,
      "name": "Rock_Basalt"
    },
    {
      "x": -1,
      "y": 2,
      "z": -6,
      "name": "Empty"
    },
    {
      "x": -1,
      "y": 3,
      "z": -6,
      "name": "Empty"
    },
    {
      "x": -1,
      "y": 4,
      "z": -6,
      "name": "Plant_Bush_Dead_Hanging"
    },
    {
      "x": -1,
      "y": 5,
      "z": -6,
      "name": "Rock_Basalt"
    },
    {
      "x": -1,
      "y": 0,
      "z": -5,
      "name": "Rock_Basalt"
    },
    {
      "x": -1,
      "y": 1,
      "z": -5,
      "name": "Empty"
    },
    {
      "x": -1,
      "y": 2,
      "z": -5,
      "name": "Empty"
    },
    {
      "x": -1,
      "y": 3,
      "z": -5,
      "name": "Empty"
    },
    {
      "x": -1,
      "y": 4,
      "z": -5,
      "name": "Empty"
    },
    {
      "x": -1,
      "y": 5,
      "z": -5,
      "name": "Rock_Basalt"
    },
    {
      "x": -1,
      "y": 0,
      "z": -4,
      "name": "Rock_Shale_Brick"
    },
    {
      "x": -1,
      "y": 1,
      "z": -4,
      "name": "Furniture_Ancient_Bench",
      "rotation": 1
    },
    {
      "x": -1,
      "y": 2,
      "z": -4,
      "name": "Empty"
    },
    {
      "x": -1,
      "y": 3,
      "z": -4,
      "name": "Empty"
    },
    {
      "x": -1,
      "y": 4,
      "z": -4,
      "name": "Empty"
    },
    {
      "x": -1,
      "y": 5,
      "z": -4,
      "name": "Rock_Basalt"
    },
    {
      "x": -1,
      "y": 0,
      "z": -3,
      "name": "Rock_Shale_Brick"
    },
    {
      "x": -1,
      "y": 1,
      "z": -3,
      "name": "Furniture_Ancient_Bench",
      "filler": 32,
      "rotation": 1
    },
    {
      "x": -1,
      "y": 2,
      "z": -3,
      "name": "Empty"
    },
    {
      "x": -1,
      "y": 3,
      "z": -3,
      "name": "Empty"
    },
    {
      "x": -1,
      "y": 4,
      "z": -3,
      "name": "Empty"
    },
    {
      "x": -1,
      "y": 5,
      "z": -3,
      "name": "Rock_Basalt"
    },
    {
      "x": -1,
      "y": 0,
      "z": -2,
      "name": "Rock_Shale"
    },
    {
      "x": -1,
      "y": 1,
      "z": -2,
      "name": "Rock_Shale_Brick_Half"
    },
    {
      "x": -1,
      "y": 2,
      "z": -2,
      "name": "Empty"
    },
    {
      "x": -1,
      "y": 3,
      "z": -2,
      "name": "Empty"
    },
    {
      "x": -1,
      "y": 4,
      "z": -2,
      "name": "Empty"
    },
    {
      "x": -1,
      "y": 5,
      "z": -2,
      "name": "Rock_Basalt"
    },
    {
      "x": -1,
      "y": 0,
      "z": -1,
      "name": "Rock_Shale"
    },
    {
      "x": -1,
      "y": 1,
      "z": -1,
      "name": "Rock_Shale_Brick_Half"
    },
    {
      "x": -1,
      "y": 2,
      "z": -1,
      "name": "Empty"
    },
    {
      "x": -1,
      "y": 3,
      "z": -1,
      "name": "Empty"
    },
    {
      "x": -1,
      "y": 4,
      "z": -1,
      "name": "Empty"
    },
    {
      "x": -1,
      "y": 5,
      "z": -1,
      "name": "Rock_Basalt"
    },
    {
      "x": -1,
      "y": 1,
      "z": 0,
      "name": "Rock_Shale_Brick"
    },
    {
      "x": -1,
      "y": 2,
      "z": 0,
      "name": "Empty"
    },
    {
      "x": -1,
      "y": 3,
      "z": 0,
      "name": "Empty"
    },
    {
      "x": -1,
      "y": 4,
      "z": 0,
      "name": "Empty"
    },
    {
      "x": -1,
      "y": 5,
      "z": 0,
      "name": "Empty"
    },
    {
      "x": -1,
      "y": 6,
      "z": 0,
      "name": "Rock_Basalt"
    },
    {
      "x": -1,
      "y": 1,
      "z": 1,
      "name": "Rock_Shale"
    },
    {
      "x": -1,
      "y": 2,
      "z": 1,
      "name": "Empty"
    },
    {
      "x": -1,
      "y": 3,
      "z": 1,
      "name": "Empty"
    },
    {
      "x": -1,
      "y": 4,
      "z": 1,
      "name": "Empty"
    },
    {
      "x": -1,
      "y": 5,
      "z": 1,
      "name": "Empty"
    },
    {
      "x": -1,
      "y": 6,
      "z": 1,
      "name": "Rock_Basalt"
    },
    {
      "x": -1,
      "y": 1,
      "z": 2,
      "name": "Rock_Shale"
    },
    {
      "x": -1,
      "y": 2,
      "z": 2,
      "name": "Empty"
    },
    {
      "x": -1,
      "y": 3,
      "z": 2,
      "name": "Empty"
    },
    {
      "x": -1,
      "y": 4,
      "z": 2,
      "name": "Empty"
    },
    {
      "x": -1,
      "y": 5,
      "z": 2,
      "name": "Empty"
    },
    {
      "x": -1,
      "y": 6,
      "z": 2,
      "name": "Rock_Basalt"
    },
    {
      "x": -1,
      "y": 1,
      "z": 3,
      "name": "Rock_Shale"
    },
    {
      "x": -1,
      "y": 2,
      "z": 3,
      "name": "Empty"
    },
    {
      "x": -1,
      "y": 3,
      "z": 3,
      "name": "Empty"
    },
    {
      "x": -1,
      "y": 4,
      "z": 3,
      "name": "Empty"
    },
    {
      "x": -1,
      "y": 5,
      "z": 3,
      "name": "Empty"
    },
    {
      "x": -1,
      "y": 6,
      "z": 3,
      "name": "Rock_Basalt"
    },
    {
      "x": -1,
      "y": 1,
      "z": 4,
      "name": "Rock_Shale"
    },
    {
      "x": -1,
      "y": 2,
      "z": 4,
      "name": "Empty"
    },
    {
      "x": -1,
      "y": 3,
      "z": 4,
      "name": "Empty"
    },
    {
      "x": -1,
      "y": 4,
      "z": 4,
      "name": "Empty"
    },
    {
      "x": -1,
      "y": 5,
      "z": 4,
      "name": "Empty"
    },
    {
      "x": -1,
      "y": 6,
      "z": 4,
      "name": "Rock_Basalt"
    },
    {
      "x": -1,
      "y": 1,
      "z": 5,
      "name": "Rock_Shale"
    },
    {
      "x": -1,
      "y": 2,
      "z": 5,
      "name": "Empty"
    },
    {
      "x": -1,
      "y": 3,
      "z": 5,
      "name": "Empty"
    },
    {
      "x": -1,
      "y": 4,
      "z": 5,
      "name": "Empty"
    },
    {
      "x": -1,
      "y": 5,
      "z": 5,
      "name": "Empty"
    },
    {
      "x": -1,
      "y": 6,
      "z": 5,
      "name": "Rock_Basalt"
    },
    {
      "x": -1,
      "y": 1,
      "z": 6,
      "name": "Rock_Shale_Brick"
    },
    {
      "x": -1,
      "y": 2,
      "z": 6,
      "name": "Empty"
    },
    {
      "x": -1,
      "y": 3,
      "z": 6,
      "name": "Empty"
    },
    {
      "x": -1,
      "y": 4,
      "z": 6,
      "name": "Empty"
    },
    {
      "x": -1,
      "y": 5,
      "z": 6,
      "name": "Empty"
    },
    {
      "x": -1,
      "y": 6,
      "z": 6,
      "name": "Rock_Basalt"
    },
    {
      "x": -1,
      "y": 1,
      "z": 7,
      "name": "Rock_Shale"
    },
    {
      "x": -1,
      "y": 2,
      "z": 7,
      "name": "Rock_Shale_Cobble_Half"
    },
    {
      "x": -1,
      "y": 3,
      "z": 7,
      "name": "Empty"
    },
    {
      "x": -1,
      "y": 4,
      "z": 7,
      "name": "Empty"
    },
    {
      "x": -1,
      "y": 5,
      "z": 7,
      "name": "Empty"
    },
    {
      "x": -1,
      "y": 6,
      "z": 7,
      "name": "Rock_Basalt"
    },
    {
      "x": -1,
      "y": 2,
      "z": 8,
      "name": "Rock_Shale_Cobble"
    },
    {
      "x": -1,
      "y": 3,
      "z": 8,
      "name": "Empty"
    },
    {
      "x": -1,
      "y": 4,
      "z": 8,
      "name": "Empty"
    },
    {
      "x": -1,
      "y": 5,
      "z": 8,
      "name": "Empty"
    },
    {
      "x": -1,
      "y": 6,
      "z": 8,
      "name": "Empty"
    },
    {
      "x": -1,
      "y": 7,
      "z": 8,
      "name": "Rock_Shale"
    },
    {
      "x": -1,
      "y": 2,
      "z": 9,
      "name": "Soil_Dirt_Cold"
    },
    {
      "x": -1,
      "y": 3,
      "z": 9,
      "name": "Empty"
    },
    {
      "x": -1,
      "y": 4,
      "z": 9,
      "name": "Empty"
    },
    {
      "x": -1,
      "y": 5,
      "z": 9,
      "name": "Empty"
    },
    {
      "x": -1,
      "y": 6,
      "z": 9,
      "name": "Empty"
    },
    {
      "x": -1,
      "y": 7,
      "z": 9,
      "name": "Rock_Basalt"
    },
    {
      "x": 0,
      "y": 0,
      "z": -9,
      "name": "Rock_Shale_Brick_Smooth"
    },
    {
      "x": 0,
      "y": 1,
      "z": -9,
      "name": "Rock_Shale_Brick_Pillar_Base"
    },
    {
      "x": 0,
      "y": 2,
      "z": -9,
      "name": "Rock_Shale_Brick_Pillar_Middle"
    },
    {
      "x": 0,
      "y": 3,
      "z": -9,
      "name": "Rock_Shale_Brick_Pillar_Base",
      "rotation": 8
    },
    {
      "x": 0,
      "y": 4,
      "z": -9,
      "name": "Rock_Shale_Brick"
    },
    {
      "x": 0,
      "y": 5,
      "z": -9,
      "name": "Rock_Basalt"
    },
    {
      "x": 0,
      "y": 0,
      "z": -8,
      "name": "Soil_Dirt_Cold"
    },
    {
      "x": 0,
      "y": 1,
      "z": -8,
      "name": "Empty"
    },
    {
      "x": 0,
      "y": 2,
      "z": -8,
      "name": "Empty"
    },
    {
      "x": 0,
      "y": 3,
      "z": -8,
      "name": "Empty"
    },
    {
      "x": 0,
      "y": 4,
      "z": -8,
      "name": "Wood_Gnarled_Roots"
    },
    {
      "x": 0,
      "y": 5,
      "z": -8,
      "name": "Rock_Basalt"
    },
    {
      "x": 0,
      "y": 0,
      "z": -7,
      "name": "Soil_Dirt_Cold"
    },
    {
      "x": 0,
      "y": 1,
      "z": -7,
      "name": "Empty"
    },
    {
      "x": 0,
      "y": 2,
      "z": -7,
      "name": "Empty"
    },
    {
      "x": 0,
      "y": 3,
      "z": -7,
      "name": "Empty"
    },
    {
      "x": 0,
      "y": 4,
      "z": -7,
      "name": "Empty"
    },
    {
      "x": 0,
      "y": 5,
      "z": -7,
      "name": "Rock_Basalt"
    },
    {
      "x": 0,
      "y": 0,
      "z": -6,
      "name": "Rock_Basalt"
    },
    {
      "x": 0,
      "y": 1,
      "z": -6,
      "name": "Rubble_Basalt"
    },
    {
      "x": 0,
      "y": 2,
      "z": -6,
      "name": "Empty"
    },
    {
      "x": 0,
      "y": 3,
      "z": -6,
      "name": "Empty"
    },
    {
      "x": 0,
      "y": 4,
      "z": -6,
      "name": "Empty"
    },
    {
      "x": 0,
      "y": 5,
      "z": -6,
      "name": "Rock_Basalt"
    },
    {
      "x": 0,
      "y": 0,
      "z": -5,
      "name": "Rock_Basalt"
    },
    {
      "x": 0,
      "y": 1,
      "z": -5,
      "name": "Empty"
    },
    {
      "x": 0,
      "y": 2,
      "z": -5,
      "name": "Empty"
    },
    {
      "x": 0,
      "y": 3,
      "z": -5,
      "name": "Empty"
    },
    {
      "x": 0,
      "y": 4,
      "z": -5,
      "name": "Empty"
    },
    {
      "x": 0,
      "y": 5,
      "z": -5,
      "name": "Rock_Basalt"
    },
    {
      "x": 0,
      "y": 0,
      "z": -4,
      "name": "Rock_Shale_Cobble"
    },
    {
      "x": 0,
      "y": 1,
      "z": -4,
      "name": "Empty"
    },
    {
      "x": 0,
      "y": 2,
      "z": -4,
      "name": "Empty"
    },
    {
      "x": 0,
      "y": 3,
      "z": -4,
      "name": "Empty"
    },
    {
      "x": 0,
      "y": 4,
      "z": -4,
      "name": "Empty"
    },
    {
      "x": 0,
      "y": 5,
      "z": -4,
      "name": "Rock_Basalt"
    },
    {
      "x": 0,
      "y": 0,
      "z": -3,
      "name": "Rock_Shale_Cobble"
    },
    {
      "x": 0,
      "y": 1,
      "z": -3,
      "name": "Empty"
    },
    {
      "x": 0,
      "y": 2,
      "z": -3,
      "name": "Empty"
    },
    {
      "x": 0,
      "y": 3,
      "z": -3,
      "name": "Empty"
    },
    {
      "x": 0,
      "y": 4,
      "z": -3,
      "name": "Empty"
    },
    {
      "x": 0,
      "y": 5,
      "z": -3,
      "name": "Rock_Basalt"
    },
    {
      "x": 0,
      "y": 0,
      "z": -2,
      "name": "Rock_Shale_Cobble"
    },
    {
      "x": 0,
      "y": 1,
      "z": -2,
      "name": "Empty"
    },
    {
      "x": 0,
      "y": 2,
      "z": -2,
      "name": "Empty"
    },
    {
      "x": 0,
      "y": 3,
      "z": -2,
      "name": "Empty"
    },
    {
      "x": 0,
      "y": 4,
      "z": -2,
      "name": "Empty"
    },
    {
      "x": 0,
      "y": 5,
      "z": -2,
      "name": "Rock_Basalt"
    },
    {
      "x": 0,
      "y": 0,
      "z": -1,
      "name": "Rock_Shale"
    },
    {
      "x": 0,
      "y": 1,
      "z": -1,
      "name": "Rock_Shale_Cobble_Half"
    },
    {
      "x": 0,
      "y": 2,
      "z": -1,
      "name": "Empty"
    },
    {
      "x": 0,
      "y": 3,
      "z": -1,
      "name": "Empty"
    },
    {
      "x": 0,
      "y": 4,
      "z": -1,
      "name": "Empty"
    },
    {
      "x": 0,
      "y": 5,
      "z": -1,
      "name": "Rock_Basalt"
    },
    {
      "x": 0,
      "y": 1,
      "z": 0,
      "name": "Rock_Shale_Brick"
    },
    {
      "x": 0,
      "y": 2,
      "z": 0,
      "name": "Empty"
    },
    {
      "x": 0,
      "y": 3,
      "z": 0,
      "name": "Empty"
    },
    {
      "x": 0,
      "y": 4,
      "z": 0,
      "name": "Empty"
    },
    {
      "x": 0,
      "y": 5,
      "z": 0,
      "name": "Empty"
    },
    {
      "x": 0,
      "y": 6,
      "z": 0,
      "name": "Rock_Basalt"
    },
    {
      "x": 0,
      "y": 1,
      "z": 1,
      "name": "Rock_Shale"
    },
    {
      "x": 0,
      "y": 2,
      "z": 1,
      "name": "Empty"
    },
    {
      "x": 0,
      "y": 3,
      "z": 1,
      "name": "Empty"
    },
    {
      "x": 0,
      "y": 4,
      "z": 1,
      "name": "Empty"
    },
    {
      "x": 0,
      "y": 5,
      "z": 1,
      "name": "Empty"
    },
    {
      "x": 0,
      "y": 6,
      "z": 1,
      "name": "Rock_Basalt"
    },
    {
      "x": 0,
      "y": 1,
      "z": 2,
      "name": "Rock_Shale_Cobble"
    },
    {
      "x": 0,
      "y": 2,
      "z": 2,
      "name": "Empty"
    },
    {
      "x": 0,
      "y": 3,
      "z": 2,
      "name": "Empty"
    },
    {
      "x": 0,
      "y": 4,
      "z": 2,
      "name": "Empty"
    },
    {
      "x": 0,
      "y": 5,
      "z": 2,
      "name": "Empty"
    },
    {
      "x": 0,
      "y": 6,
      "z": 2,
      "name": "Rock_Basalt"
    },
    {
      "x": 0,
      "y": 1,
      "z": 3,
      "name": "Soil_Dirt_Cold"
    },
    {
      "x": 0,
      "y": 2,
      "z": 3,
      "name": "Empty"
    },
    {
      "x": 0,
      "y": 3,
      "z": 3,
      "name": "Empty"
    },
    {
      "x": 0,
      "y": 4,
      "z": 3,
      "name": "Empty"
    },
    {
      "x": 0,
      "y": 5,
      "z": 3,
      "name": "Empty"
    },
    {
      "x": 0,
      "y": 6,
      "z": 3,
      "name": "Rock_Basalt"
    },
    {
      "x": 0,
      "y": 1,
      "z": 4,
      "name": "Soil_Dirt_Cold"
    },
    {
      "x": 0,
      "y": 2,
      "z": 4,
      "name": "Empty"
    },
    {
      "x": 0,
      "y": 3,
      "z": 4,
      "name": "Empty"
    },
    {
      "x": 0,
      "y": 4,
      "z": 4,
      "name": "Empty"
    },
    {
      "x": 0,
      "y": 5,
      "z": 4,
      "name": "Empty"
    },
    {
      "x": 0,
      "y": 6,
      "z": 4,
      "name": "Rock_Basalt"
    },
    {
      "x": 0,
      "y": 1,
      "z": 5,
      "name": "Soil_Dirt_Cold"
    },
    {
      "x": 0,
      "y": 2,
      "z": 5,
      "name": "Empty"
    },
    {
      "x": 0,
      "y": 3,
      "z": 5,
      "name": "Empty"
    },
    {
      "x": 0,
      "y": 4,
      "z": 5,
      "name": "Empty"
    },
    {
      "x": 0,
      "y": 5,
      "z": 5,
      "name": "Empty"
    },
    {
      "x": 0,
      "y": 6,
      "z": 5,
      "name": "Rock_Basalt"
    },
    {
      "x": 0,
      "y": 1,
      "z": 6,
      "name": "Soil_Dirt_Cold"
    },
    {
      "x": 0,
      "y": 2,
      "z": 6,
      "name": "Empty"
    },
    {
      "x": 0,
      "y": 3,
      "z": 6,
      "name": "Empty"
    },
    {
      "x": 0,
      "y": 4,
      "z": 6,
      "name": "Empty"
    },
    {
      "x": 0,
      "y": 5,
      "z": 6,
      "name": "Empty"
    },
    {
      "x": 0,
      "y": 6,
      "z": 6,
      "name": "Rock_Basalt"
    },
    {
      "x": 0,
      "y": 1,
      "z": 7,
      "name": "Rock_Shale"
    },
    {
      "x": 0,
      "y": 2,
      "z": 7,
      "name": "Rock_Shale_Cobble_Half"
    },
    {
      "x": 0,
      "y": 3,
      "z": 7,
      "name": "Empty"
    },
    {
      "x": 0,
      "y": 4,
      "z": 7,
      "name": "Rock_Shale_Stalactites_Large",
      "filler": 31744,
      "rotation": 8
    },
    {
      "x": 0,
      "y": 5,
      "z": 7,
      "name": "Rock_Shale_Stalactites_Large",
      "rotation": 8
    },
    {
      "x": 0,
      "y": 6,
      "z": 7,
      "name": "Rock_Shale"
    },
    {
      "x": 0,
      "y": 2,
      "z": 8,
      "name": "Soil_Dirt_Cold"
    },
    {
      "x": 0,
      "y": 3,
      "z": 8,
      "name": "Empty"
    },
    {
      "x": 0,
      "y": 4,
      "z": 8,
      "name": "Empty"
    },
    {
      "x": 0,
      "y": 5,
      "z": 8,
      "name": "Empty"
    },
    {
      "x": 0,
      "y": 6,
      "z": 8,
      "name": "Rock_Shale_Stalactites_Small",
      "rotation": 8
    },
    {
      "x": 0,
      "y": 7,
      "z": 8,
      "name": "Rock_Shale"
    },
    {
      "x": 0,
      "y": 2,
      "z": 9,
      "name": "Soil_Dirt_Cold"
    },
    {
      "x": 0,
      "y": 3,
      "z": 9,
      "name": "*Plant_Crop_Berry_Winter_Block_State_Definitions_StageFinal",
      "components": {
        "Components": {
          "FarmingBlock": {}
        }
      }
    },
    {
      "x": 0,
      "y": 4,
      "z": 9,
      "name": "Empty"
    },
    {
      "x": 0,
      "y": 5,
      "z": 9,
      "name": "Empty"
    },
    {
      "x": 0,
      "y": 6,
      "z": 9,
      "name": "Rock_Shale_Brick_Stairs",
      "rotation": 9
    },
    {
      "x": 0,
      "y": 7,
      "z": 9,
      "name": "Rock_Basalt"
    },
    {
      "x": 1,
      "y": 0,
      "z": -9,
      "name": "Rock_Shale_Brick"
    },
    {
      "x": 1,
      "y": 1,
      "z": -9,
      "name": "Empty"
    },
    {
      "x": 1,
      "y": 2,
      "z": -9,
      "name": "Empty"
    },
    {
      "x": 1,
      "y": 3,
      "z": -9,
      "name": "Empty"
    },
    {
      "x": 1,
      "y": 4,
      "z": -9,
      "name": "Rock_Shale_Brick_Stairs",
      "rotation": 11
    },
    {
      "x": 1,
      "y": 5,
      "z": -9,
      "name": "Rock_Basalt"
    },
    {
      "x": 1,
      "y": 0,
      "z": -8,
      "name": "Rock_Shale_Brick"
    },
    {
      "x": 1,
      "y": 1,
      "z": -8,
      "name": "Plant_Crop_Mushroom_Glowing_Red"
    },
    {
      "x": 1,
      "y": 2,
      "z": -8,
      "name": "Empty"
    },
    {
      "x": 1,
      "y": 3,
      "z": -8,
      "name": "Empty"
    },
    {
      "x": 1,
      "y": 4,
      "z": -8,
      "name": "Empty"
    },
    {
      "x": 1,
      "y": 5,
      "z": -8,
      "name": "Rock_Basalt"
    },
    {
      "x": 1,
      "y": 0,
      "z": -7,
      "name": "Soil_Dirt_Cold"
    },
    {
      "x": 1,
      "y": 1,
      "z": -7,
      "name": "Plant_Bush_Dead_Twisted"
    },
    {
      "x": 1,
      "y": 2,
      "z": -7,
      "name": "Empty"
    },
    {
      "x": 1,
      "y": 3,
      "z": -7,
      "name": "Empty"
    },
    {
      "x": 1,
      "y": 4,
      "z": -7,
      "name": "Plant_Bush_Dead_Hanging"
    },
    {
      "x": 1,
      "y": 5,
      "z": -7,
      "name": "Rock_Basalt"
    },
    {
      "x": 1,
      "y": 0,
      "z": -6,
      "name": "Rock_Shale"
    },
    {
      "x": 1,
      "y": 1,
      "z": -6,
      "name": "Empty"
    },
    {
      "x": 1,
      "y": 2,
      "z": -6,
      "name": "Empty"
    },
    {
      "x": 1,
      "y": 3,
      "z": -6,
      "name": "Empty"
    },
    {
      "x": 1,
      "y": 4,
      "z": -6,
      "name": "Empty"
    },
    {
      "x": 1,
      "y": 5,
      "z": -6,
      "name": "Rock_Basalt"
    },
    {
      "x": 1,
      "y": 0,
      "z": -5,
      "name": "Rock_Shale"
    },
    {
      "x": 1,
      "y": 1,
      "z": -5,
      "name": "Empty"
    },
    {
      "x": 1,
      "y": 2,
      "z": -5,
      "name": "Empty"
    },
    {
      "x": 1,
      "y": 3,
      "z": -5,
      "name": "Empty"
    },
    {
      "x": 1,
      "y": 4,
      "z": -5,
      "name": "Empty"
    },
    {
      "x": 1,
      "y": 5,
      "z": -5,
      "name": "Rock_Basalt"
    },
    {
      "x": 1,
      "y": 0,
      "z": -4,
      "name": "Rock_Shale"
    },
    {
      "x": 1,
      "y": 1,
      "z": -4,
      "name": "Empty"
    },
    {
      "x": 1,
      "y": 2,
      "z": -4,
      "name": "Empty"
    },
    {
      "x": 1,
      "y": 3,
      "z": -4,
      "name": "Empty"
    },
    {
      "x": 1,
      "y": 4,
      "z": -4,
      "name": "Empty"
    },
    {
      "x": 1,
      "y": 5,
      "z": -4,
      "name": "Rock_Basalt"
    },
    {
      "x": 1,
      "y": 0,
      "z": -3,
      "name": "Rock_Shale"
    },
    {
      "x": 1,
      "y": 1,
      "z": -3,
      "name": "Empty"
    },
    {
      "x": 1,
      "y": 2,
      "z": -3,
      "name": "Empty"
    },
    {
      "x": 1,
      "y": 3,
      "z": -3,
      "name": "Empty"
    },
    {
      "x": 1,
      "y": 4,
      "z": -3,
      "name": "Empty"
    },
    {
      "x": 1,
      "y": 5,
      "z": -3,
      "name": "Rock_Basalt"
    },
    {
      "x": 1,
      "y": 0,
      "z": -2,
      "name": "Rock_Shale_Brick"
    },
    {
      "x": 1,
      "y": 1,
      "z": -2,
      "name": "Empty"
    },
    {
      "x": 1,
      "y": 2,
      "z": -2,
      "name": "Empty"
    },
    {
      "x": 1,
      "y": 3,
      "z": -2,
      "name": "Empty"
    },
    {
      "x": 1,
      "y": 4,
      "z": -2,
      "name": "Empty"
    },
    {
      "x": 1,
      "y": 5,
      "z": -2,
      "name": "Rock_Basalt"
    },
    {
      "x": 1,
      "y": 0,
      "z": -1,
      "name": "Rock_Shale"
    },
    {
      "x": 1,
      "y": 1,
      "z": -1,
      "name": "Rock_Shale_Cobble_Half"
    },
    {
      "x": 1,
      "y": 2,
      "z": -1,
      "name": "Empty"
    },
    {
      "x": 1,
      "y": 3,
      "z": -1,
      "name": "Empty"
    },
    {
      "x": 1,
      "y": 4,
      "z": -1,
      "name": "Empty"
    },
    {
      "x": 1,
      "y": 5,
      "z": -1,
      "name": "Rock_Basalt"
    },
    {
      "x": 1,
      "y": 1,
      "z": 0,
      "name": "Rock_Shale_Cobble"
    },
    {
      "x": 1,
      "y": 2,
      "z": 0,
      "name": "Empty"
    },
    {
      "x": 1,
      "y": 3,
      "z": 0,
      "name": "Empty"
    },
    {
      "x": 1,
      "y": 4,
      "z": 0,
      "name": "Empty"
    },
    {
      "x": 1,
      "y": 5,
      "z": 0,
      "name": "Rock_Basalt_Brick_Half",
      "rotation": 8
    },
    {
      "x": 1,
      "y": 6,
      "z": 0,
      "name": "Rock_Basalt"
    },
    {
      "x": 1,
      "y": 1,
      "z": 1,
      "name": "Rock_Shale_Cobble"
    },
    {
      "x": 1,
      "y": 2,
      "z": 1,
      "name": "Empty"
    },
    {
      "x": 1,
      "y": 3,
      "z": 1,
      "name": "Empty"
    },
    {
      "x": 1,
      "y": 4,
      "z": 1,
      "name": "Empty"
    },
    {
      "x": 1,
      "y": 5,
      "z": 1,
      "name": "Rock_Basalt_Brick_Half",
      "rotation": 8
    },
    {
      "x": 1,
      "y": 6,
      "z": 1,
      "name": "Rock_Basalt"
    },
    {
      "x": 1,
      "y": 1,
      "z": 2,
      "name": "Rock_Shale_Cobble"
    },
    {
      "x": 1,
      "y": 2,
      "z": 2,
      "name": "Furniture_Ancient_Crate",
      "rotation": 3
    },
    {
      "x": 1,
      "y": 3,
      "z": 2,
      "name": "Empty"
    },
    {
      "x": 1,
      "y": 4,
      "z": 2,
      "name": "Empty"
    },
    {
      "x": 1,
      "y": 5,
      "z": 2,
      "name": "Empty"
    },
    {
      "x": 1,
      "y": 6,
      "z": 2,
      "name": "Rock_Basalt"
    },
    {
      "x": 1,
      "y": 1,
      "z": 3,
      "name": "Soil_Dirt_Cold"
    },
    {
      "x": 1,
      "y": 2,
      "z": 3,
      "name": "Plant_Crop_Mushroom_Glowing_Blue"
    },
    {
      "x": 1,
      "y": 3,
      "z": 3,
      "name": "Empty"
    },
    {
      "x": 1,
      "y": 4,
      "z": 3,
      "name": "Empty"
    },
    {
      "x": 1,
      "y": 5,
      "z": 3,
      "name": "Empty"
    },
    {
      "x": 1,
      "y": 6,
      "z": 3,
      "name": "Rock_Basalt"
    },
    {
      "x": 1,
      "y": 1,
      "z": 4,
      "name": "Soil_Dirt_Cold"
    },
    {
      "x": 1,
      "y": 2,
      "z": 4,
      "name": "Empty"
    },
    {
      "x": 1,
      "y": 3,
      "z": 4,
      "name": "Empty"
    },
    {
      "x": 1,
      "y": 4,
      "z": 4,
      "name": "Empty"
    },
    {
      "x": 1,
      "y": 5,
      "z": 4,
      "name": "Empty"
    },
    {
      "x": 1,
      "y": 6,
      "z": 4,
      "name": "Rock_Basalt"
    },
    {
      "x": 1,
      "y": 1,
      "z": 5,
      "name": "Soil_Dirt_Cold"
    },
    {
      "x": 1,
      "y": 2,
      "z": 5,
      "name": "Empty"
    },
    {
      "x": 1,
      "y": 3,
      "z": 5,
      "name": "Empty"
    },
    {
      "x": 1,
      "y": 4,
      "z": 5,
      "name": "Empty"
    },
    {
      "x": 1,
      "y": 5,
      "z": 5,
      "name": "Plant_Bush_Dead_Hanging"
    },
    {
      "x": 1,
      "y": 6,
      "z": 5,
      "name": "Rock_Basalt"
    },
    {
      "x": 1,
      "y": 1,
      "z": 6,
      "name": "Soil_Dirt_Cold"
    },
    {
      "x": 1,
      "y": 2,
      "z": 6,
      "name": "Plant_Bush_Dead_Twisted"
    },
    {
      "x": 1,
      "y": 3,
      "z": 6,
      "name": "Empty"
    },
    {
      "x": 1,
      "y": 4,
      "z": 6,
      "name": "Empty"
    },
    {
      "x": 1,
      "y": 5,
      "z": 6,
      "name": "Empty"
    },
    {
      "x": 1,
      "y": 6,
      "z": 6,
      "name": "Rock_Basalt"
    },
    {
      "x": 1,
      "y": 1,
      "z": 7,
      "name": "Rock_Shale"
    },
    {
      "x": 1,
      "y": 2,
      "z": 7,
      "name": "Rock_Shale"
    },
    {
      "x": 1,
      "y": 3,
      "z": 7,
      "name": "Rock_Shale"
    },
    {
      "x": 1,
      "y": 4,
      "z": 7,
      "name": "Rock_Shale"
    },
    {
      "x": 1,
      "y": 5,
      "z": 7,
      "name": "Rock_Shale"
    },
    {
      "x": 1,
      "y": 6,
      "z": 7,
      "name": "Rock_Basalt"
    },
    {
      "x": 1,
      "y": 2,
      "z": 8,
      "name": "Rock_Shale"
    },
    {
      "x": 1,
      "y": 3,
      "z": 8,
      "name": "Rock_Shale"
    },
    {
      "x": 1,
      "y": 4,
      "z": 8,
      "name": "Rock_Shale"
    },
    {
      "x": 1,
      "y": 5,
      "z": 8,
      "name": "Rock_Shale"
    },
    {
      "x": 1,
      "y": 6,
      "z": 8,
      "name": "Rock_Shale"
    },
    {
      "x": 1,
      "y": 7,
      "z": 8,
      "name": "Rock_Basalt"
    },
    {
      "x": 1,
      "y": 2,
      "z": 9,
      "name": "Rock_Shale_Brick_Smooth"
    },
    {
      "x": 1,
      "y": 3,
      "z": 9,
      "name": "Rock_Shale_Brick_Pillar_Base"
    },
    {
      "x": 1,
      "y": 4,
      "z": 9,
      "name": "Rock_Shale_Brick_Pillar_Middle"
    },
    {
      "x": 1,
      "y": 5,
      "z": 9,
      "name": "Rock_Shale_Brick_Pillar_Base",
      "rotation": 8
    },
    {
      "x": 1,
      "y": 6,
      "z": 9,
      "name": "Rock_Shale_Brick"
    },
    {
      "x": 1,
      "y": 7,
      "z": 9,
      "name": "Rock_Basalt"
    },
    {
      "x": 2,
      "y": 0,
      "z": -9,
      "name": "Rock_Shale_Brick"
    },
    {
      "x": 2,
      "y": 1,
      "z": -9,
      "name": "Empty"
    },
    {
      "x": 2,
      "y": 2,
      "z": -9,
      "name": "Empty"
    },
    {
      "x": 2,
      "y": 3,
      "z": -9,
      "name": "Empty"
    },
    {
      "x": 2,
      "y": 4,
      "z": -9,
      "name": "Empty"
    },
    {
      "x": 2,
      "y": 5,
      "z": -9,
      "name": "Rock_Basalt"
    },
    {
      "x": 2,
      "y": 0,
      "z": -8,
      "name": "Soil_Dirt_Cold"
    },
    {
      "x": 2,
      "y": 1,
      "z": -8,
      "name": "*Plant_Crop_Berry_Winter_Block_State_Definitions_StageFinal",
      "components": {
        "Components": {
          "FarmingBlock": {}
        }
      }
    },
    {
      "x": 2,
      "y": 2,
      "z": -8,
      "name": "Empty"
    },
    {
      "x": 2,
      "y": 3,
      "z": -8,
      "name": "Empty"
    },
    {
      "x": 2,
      "y": 4,
      "z": -8,
      "name": "Empty"
    },
    {
      "x": 2,
      "y": 5,
      "z": -8,
      "name": "Rock_Basalt"
    },
    {
      "x": 2,
      "y": 0,
      "z": -7,
      "name": "Rock_Shale"
    },
    {
      "x": 2,
      "y": 1,
      "z": -7,
      "name": "Empty"
    },
    {
      "x": 2,
      "y": 2,
      "z": -7,
      "name": "Empty"
    },
    {
      "x": 2,
      "y": 3,
      "z": -7,
      "name": "Empty"
    },
    {
      "x": 2,
      "y": 4,
      "z": -7,
      "name": "Empty"
    },
    {
      "x": 2,
      "y": 5,
      "z": -7,
      "name": "Rock_Basalt"
    },
    {
      "x": 2,
      "y": 0,
      "z": -6,
      "name": "Rock_Shale"
    },
    {
      "x": 2,
      "y": 1,
      "z": -6,
      "name": "Empty"
    },
    {
      "x": 2,
      "y": 2,
      "z": -6,
      "name": "Empty"
    },
    {
      "x": 2,
      "y": 3,
      "z": -6,
      "name": "Empty"
    },
    {
      "x": 2,
      "y": 4,
      "z": -6,
      "name": "Empty"
    },
    {
      "x": 2,
      "y": 5,
      "z": -6,
      "name": "Rock_Basalt"
    },
    {
      "x": 2,
      "y": 0,
      "z": -5,
      "name": "Rock_Shale"
    },
    {
      "x": 2,
      "y": 1,
      "z": -5,
      "name": "Empty"
    },
    {
      "x": 2,
      "y": 2,
      "z": -5,
      "name": "Empty"
    },
    {
      "x": 2,
      "y": 3,
      "z": -5,
      "name": "Empty"
    },
    {
      "x": 2,
      "y": 4,
      "z": -5,
      "name": "Empty"
    },
    {
      "x": 2,
      "y": 5,
      "z": -5,
      "name": "Rock_Basalt"
    },
    {
      "x": 2,
      "y": 0,
      "z": -4,
      "name": "Rock_Shale"
    },
    {
      "x": 2,
      "y": 1,
      "z": -4,
      "name": "Empty"
    },
    {
      "x": 2,
      "y": 2,
      "z": -4,
      "name": "Empty"
    },
    {
      "x": 2,
      "y": 3,
      "z": -4,
      "name": "Empty"
    },
    {
      "x": 2,
      "y": 4,
      "z": -4,
      "name": "Empty"
    },
    {
      "x": 2,
      "y": 5,
      "z": -4,
      "name": "Rock_Basalt"
    },
    {
      "x": 2,
      "y": 0,
      "z": -3,
      "name": "Rock_Shale_Brick"
    },
    {
      "x": 2,
      "y": 1,
      "z": -3,
      "name": "Empty"
    },
    {
      "x": 2,
      "y": 2,
      "z": -3,
      "name": "Empty"
    },
    {
      "x": 2,
      "y": 3,
      "z": -3,
      "name": "Empty"
    },
    {
      "x": 2,
      "y": 4,
      "z": -3,
      "name": "Empty"
    },
    {
      "x": 2,
      "y": 5,
      "z": -3,
      "name": "Rock_Basalt"
    },
    {
      "x": 2,
      "y": 0,
      "z": -2,
      "name": "Rock_Shale_Brick"
    },
    {
      "x": 2,
      "y": 1,
      "z": -2,
      "name": "Empty"
    },
    {
      "x": 2,
      "y": 2,
      "z": -2,
      "name": "Empty"
    },
    {
      "x": 2,
      "y": 3,
      "z": -2,
      "name": "Empty"
    },
    {
      "x": 2,
      "y": 4,
      "z": -2,
      "name": "Plant_Bush_Dead_Hanging"
    },
    {
      "x": 2,
      "y": 5,
      "z": -2,
      "name": "Rock_Basalt"
    },
    {
      "x": 2,
      "y": 0,
      "z": -1,
      "name": "Rock_Shale"
    },
    {
      "x": 2,
      "y": 1,
      "z": -1,
      "name": "Rock_Shale_Brick_Half"
    },
    {
      "x": 2,
      "y": 2,
      "z": -1,
      "name": "Empty"
    },
    {
      "x": 2,
      "y": 3,
      "z": -1,
      "name": "Empty"
    },
    {
      "x": 2,
      "y": 4,
      "z": -1,
      "name": "Wood_Gnarled_Roots"
    },
    {
      "x": 2,
      "y": 5,
      "z": -1,
      "name": "Rock_Basalt"
    },
    {
      "x": 2,
      "y": 1,
      "z": 0,
      "name": "Rock_Shale_Brick"
    },
    {
      "x": 2,
      "y": 2,
      "z": 0,
      "name": "Empty"
    },
    {
      "x": 2,
      "y": 3,
      "z": 0,
      "name": "Empty"
    },
    {
      "x": 2,
      "y": 4,
      "z": 0,
      "name": "Rock_Basalt_Brick_Half",
      "rotation": 7
    },
    {
      "x": 2,
      "y": 5,
      "z": 0,
      "name": "Rock_Basalt_Brick"
    },
    {
      "x": 2,
      "y": 6,
      "z": 0,
      "name": "Rock_Basalt"
    },
    {
      "x": 2,
      "y": 1,
      "z": 1,
      "name": "Rock_Shale_Brick"
    },
    {
      "x": 2,
      "y": 2,
      "z": 1,
      "name": "Furniture_Ancient_Barrel"
    },
    {
      "x": 2,
      "y": 3,
      "z": 1,
      "name": "Empty"
    },
    {
      "x": 2,
      "y": 4,
      "z": 1,
      "name": "Rock_Basalt_Brick_Half",
      "rotation": 7
    },
    {
      "x": 2,
      "y": 5,
      "z": 1,
      "name": "Rock_Basalt_Brick"
    },
    {
      "x": 2,
      "y": 6,
      "z": 1,
      "name": "Rock_Basalt"
    },
    {
      "x": 2,
      "y": 1,
      "z": 2,
      "name": "Rock_Basalt"
    },
    {
      "x": 2,
      "y": 2,
      "z": 2,
      "name": "Furniture_Ancient_Barrel"
    },
    {
      "x": 2,
      "y": 3,
      "z": 2,
      "name": "Empty"
    },
    {
      "x": 2,
      "y": 4,
      "z": 2,
      "name": "Empty"
    },
    {
      "x": 2,
      "y": 5,
      "z": 2,
      "name": "Plant_Bush_Dead_Hanging"
    },
    {
      "x": 2,
      "y": 6,
      "z": 2,
      "name": "Rock_Basalt"
    },
    {
      "x": 2,
      "y": 1,
      "z": 3,
      "name": "Rock_Basalt"
    },
    {
      "x": 2,
      "y": 2,
      "z": 3,
      "name": "Rubble_Basalt"
    },
    {
      "x": 2,
      "y": 3,
      "z": 3,
      "name": "Empty"
    },
    {
      "x": 2,
      "y": 4,
      "z": 3,
      "name": "Empty"
    },
    {
      "x": 2,
      "y": 5,
      "z": 3,
      "name": "Empty"
    },
    {
      "x": 2,
      "y": 6,
      "z": 3,
      "name": "Rock_Basalt"
    },
    {
      "x": 2,
      "y": 1,
      "z": 4,
      "name": "Rock_Basalt"
    },
    {
      "x": 2,
      "y": 2,
      "z": 4,
      "name": "Empty"
    },
    {
      "x": 2,
      "y": 3,
      "z": 4,
      "name": "Empty"
    },
    {
      "x": 2,
      "y": 4,
      "z": 4,
      "name": "Plant_Bush_Dead_Hanging"
    },
    {
      "x": 2,
      "y": 5,
      "z": 4,
      "name": "Rock_Shale_Brick"
    },
    {
      "x": 2,
      "y": 6,
      "z": 4,
      "name": "Rock_Basalt"
    },
    {
      "x": 2,
      "y": 1,
      "z": 5,
      "name": "Soil_Dirt_Cold"
    },
    {
      "x": 2,
      "y": 2,
      "z": 5,
      "name": "*Plant_Crop_Berry_Winter_Block_State_Definitions_StageFinal",
      "components": {
        "Components": {
          "FarmingBlock": {}
        }
      }
    },
    {
      "x": 2,
      "y": 3,
      "z": 5,
      "name": "Empty"
    },
    {
      "x": 2,
      "y": 4,
      "z": 5,
      "name": "Rock_Shale_Brick_Stairs",
      "rotation": 8
    },
    {
      "x": 2,
      "y": 5,
      "z": 5,
      "name": "Rock_Shale_Brick"
    },
    {
      "x": 2,
      "y": 6,
      "z": 5,
      "name": "Rock_Basalt"
    },
    {
      "x": 2,
      "y": 1,
      "z": 6,
      "name": "Rock_Shale"
    },
    {
      "x": 2,
      "y": 2,
      "z": 6,
      "name": "Rock_Shale_Brick_Pillar_Base"
    },
    {
      "x": 2,
      "y": 3,
      "z": 6,
      "name": "Rock_Shale_Brick_Pillar_Middle"
    },
    {
      "x": 2,
      "y": 4,
      "z": 6,
      "name": "Rock_Shale"
    },
    {
      "x": 2,
      "y": 5,
      "z": 6,
      "name": "Rock_Shale"
    },
    {
      "x": 2,
      "y": 6,
      "z": 6,
      "name": "Rock_Shale"
    },
    {
      "x": 2,
      "y": 1,
      "z": 7,
      "name": "Rock_Shale"
    },
    {
      "x": 2,
      "y": 2,
      "z": 7,
      "name": "Rock_Shale"
    },
    {
      "x": 2,
      "y": 3,
      "z": 7,
      "name": "Rock_Shale"
    },
    {
      "x": 2,
      "y": 4,
      "z": 7,
      "name": "Rock_Shale"
    },
    {
      "x": 3,
      "y": 0,
      "z": -9,
      "name": "Rock_Shale"
    },
    {
      "x": 3,
      "y": 1,
      "z": -9,
      "name": "Empty"
    },
    {
      "x": 3,
      "y": 2,
      "z": -9,
      "name": "Empty"
    },
    {
      "x": 3,
      "y": 3,
      "z": -9,
      "name": "Empty"
    },
    {
      "x": 3,
      "y": 4,
      "z": -9,
      "name": "Empty"
    },
    {
      "x": 3,
      "y": 5,
      "z": -9,
      "name": "Rock_Basalt"
    },
    {
      "x": 3,
      "y": 0,
      "z": -8,
      "name": "Rock_Shale"
    },
    {
      "x": 3,
      "y": 1,
      "z": -8,
      "name": "Empty"
    },
    {
      "x": 3,
      "y": 2,
      "z": -8,
      "name": "Empty"
    },
    {
      "x": 3,
      "y": 3,
      "z": -8,
      "name": "Empty"
    },
    {
      "x": 3,
      "y": 4,
      "z": -8,
      "name": "Empty"
    },
    {
      "x": 3,
      "y": 5,
      "z": -8,
      "name": "Rock_Basalt"
    },
    {
      "x": 3,
      "y": 0,
      "z": -7,
      "name": "Rock_Shale"
    },
    {
      "x": 3,
      "y": 1,
      "z": -7,
      "name": "Empty"
    },
    {
      "x": 3,
      "y": 2,
      "z": -7,
      "name": "Empty"
    },
    {
      "x": 3,
      "y": 3,
      "z": -7,
      "name": "Empty"
    },
    {
      "x": 3,
      "y": 4,
      "z": -7,
      "name": "Empty"
    },
    {
      "x": 3,
      "y": 5,
      "z": -7,
      "name": "Rock_Basalt"
    },
    {
      "x": 3,
      "y": 0,
      "z": -6,
      "name": "Rock_Shale"
    },
    {
      "x": 3,
      "y": 1,
      "z": -6,
      "name": "Empty"
    },
    {
      "x": 3,
      "y": 2,
      "z": -6,
      "name": "Empty"
    },
    {
      "x": 3,
      "y": 3,
      "z": -6,
      "name": "Empty"
    },
    {
      "x": 3,
      "y": 4,
      "z": -6,
      "name": "Empty"
    },
    {
      "x": 3,
      "y": 5,
      "z": -6,
      "name": "Rock_Basalt"
    },
    {
      "x": 3,
      "y": 0,
      "z": -5,
      "name": "Rock_Shale"
    },
    {
      "x": 3,
      "y": 1,
      "z": -5,
      "name": "Empty"
    },
    {
      "x": 3,
      "y": 2,
      "z": -5,
      "name": "Empty"
    },
    {
      "x": 3,
      "y": 3,
      "z": -5,
      "name": "Empty"
    },
    {
      "x": 3,
      "y": 4,
      "z": -5,
      "name": "Empty"
    },
    {
      "x": 3,
      "y": 5,
      "z": -5,
      "name": "Rock_Basalt"
    },
    {
      "x": 3,
      "y": 0,
      "z": -4,
      "name": "Rock_Shale_Brick"
    },
    {
      "x": 3,
      "y": 1,
      "z": -4,
      "name": "Empty"
    },
    {
      "x": 3,
      "y": 2,
      "z": -4,
      "name": "Empty"
    },
    {
      "x": 3,
      "y": 3,
      "z": -4,
      "name": "Empty"
    },
    {
      "x": 3,
      "y": 4,
      "z": -4,
      "name": "Empty"
    },
    {
      "x": 3,
      "y": 5,
      "z": -4,
      "name": "Rock_Basalt"
    },
    {
      "x": 3,
      "y": 0,
      "z": -3,
      "name": "Soil_Dirt_Cold"
    },
    {
      "x": 3,
      "y": 1,
      "z": -3,
      "name": "Empty"
    },
    {
      "x": 3,
      "y": 2,
      "z": -3,
      "name": "Empty"
    },
    {
      "x": 3,
      "y": 3,
      "z": -3,
      "name": "Empty"
    },
    {
      "x": 3,
      "y": 4,
      "z": -3,
      "name": "Empty"
    },
    {
      "x": 3,
      "y": 5,
      "z": -3,
      "name": "Rock_Basalt"
    },
    {
      "x": 3,
      "y": 0,
      "z": -2,
      "name": "Soil_Dirt_Cold"
    },
    {
      "x": 3,
      "y": 1,
      "z": -2,
      "name": "Empty"
    },
    {
      "x": 3,
      "y": 2,
      "z": -2,
      "name": "Empty"
    },
    {
      "x": 3,
      "y": 3,
      "z": -2,
      "name": "Empty"
    },
    {
      "x": 3,
      "y": 4,
      "z": -2,
      "name": "Empty"
    },
    {
      "x": 3,
      "y": 5,
      "z": -2,
      "name": "Rock_Basalt"
    },
    {
      "x": 3,
      "y": 0,
      "z": -1,
      "name": "Rock_Shale"
    },
    {
      "x": 3,
      "y": 1,
      "z": -1,
      "name": "Rock_Shale"
    },
    {
      "x": 3,
      "y": 2,
      "z": -1,
      "name": "Rock_Shale"
    },
    {
      "x": 3,
      "y": 3,
      "z": -1,
      "name": "Empty"
    },
    {
      "x": 3,
      "y": 4,
      "z": -1,
      "name": "Empty"
    },
    {
      "x": 3,
      "y": 5,
      "z": -1,
      "name": "Rock_Basalt"
    },
    {
      "x": 3,
      "y": 1,
      "z": 0,
      "name": "Rock_Shale"
    },
    {
      "x": 3,
      "y": 2,
      "z": 0,
      "name": "Rock_Basalt_Brick"
    },
    {
      "x": 3,
      "y": 3,
      "z": 0,
      "name": "Rock_Basalt_Brick"
    },
    {
      "x": 3,
      "y": 4,
      "z": 0,
      "name": "Rock_Basalt_Brick"
    },
    {
      "x": 3,
      "y": 5,
      "z": 0,
      "name": "Rock_Basalt_Brick"
    },
    {
      "x": 3,
      "y": 6,
      "z": 0,
      "name": "Rock_Basalt"
    },
    {
      "x": 3,
      "y": 1,
      "z": 1,
      "name": "Rock_Shale"
    },
    {
      "x": 3,
      "y": 2,
      "z": 1,
      "name": "Rock_Basalt_Brick"
    },
    {
      "x": 3,
      "y": 3,
      "z": 1,
      "name": "Rock_Basalt_Brick"
    },
    {
      "x": 3,
      "y": 4,
      "z": 1,
      "name": "Rock_Basalt_Brick"
    },
    {
      "x": 3,
      "y": 5,
      "z": 1,
      "name": "Rock_Basalt_Brick"
    },
    {
      "x": 3,
      "y": 6,
      "z": 1,
      "name": "Rock_Basalt"
    },
    {
      "x": 3,
      "y": 1,
      "z": 2,
      "name": "Rock_Shale"
    },
    {
      "x": 3,
      "y": 2,
      "z": 2,
      "name": "Rock_Shale_Brick_Pillar_Base"
    },
    {
      "x": 3,
      "y": 3,
      "z": 2,
      "name": "Rock_Shale_Brick_Pillar_Middle"
    },
    {
      "x": 3,
      "y": 4,
      "z": 2,
      "name": "Rock_Shale_Brick"
    },
    {
      "x": 3,
      "y": 5,
      "z": 2,
      "name": "Rock_Shale_Brick"
    },
    {
      "x": 3,
      "y": 6,
      "z": 2,
      "name": "Rock_Basalt"
    },
    {
      "x": 3,
      "y": 1,
      "z": 3,
      "name": "Rock_Shale"
    },
    {
      "x": 3,
      "y": 2,
      "z": 3,
      "name": "Rock_Shale_Brick"
    },
    {
      "x": 3,
      "y": 3,
      "z": 3,
      "name": "Furniture_Temple_Dark_Coffin",
      "filler": 992,
      "rotation": 1
    },
    {
      "x": 3,
      "y": 4,
      "z": 3,
      "name": "Rock_Shale_Brick_Stairs",
      "rotation": 10
    },
    {
      "x": 3,
      "y": 5,
      "z": 3,
      "name": "Rock_Shale_Brick"
    },
    {
      "x": 3,
      "y": 6,
      "z": 3,
      "name": "Rock_Basalt"
    },
    {
      "x": 3,
      "y": 1,
      "z": 4,
      "name": "Rock_Shale"
    },
    {
      "x": 3,
      "y": 2,
      "z": 4,
      "name": "Rock_Shale_Brick"
    },
    {
      "x": 3,
      "y": 3,
      "z": 4,
      "name": "Furniture_Temple_Dark_Coffin",
      "rotation": 1
    },
    {
      "x": 3,
      "y": 4,
      "z": 4,
      "name": "Empty"
    },
    {
      "x": 3,
      "y": 1,
      "z": 5,
      "name": "Rock_Shale_Brick"
    },
    {
      "x": 3,
      "y": 2,
      "z": 5,
      "name": "Rock_Shale_Brick"
    },
    {
      "x": 3,
      "y": 3,
      "z": 5,
      "name": "Empty"
    },
    {
      "x": 3,
      "y": 4,
      "z": 5,
      "name": "Empty"
    },
    {
      "x": 3,
      "y": 1,
      "z": 6,
      "name": "Rock_Shale"
    },
    {
      "x": 3,
      "y": 2,
      "z": 6,
      "name": "Rock_Shale"
    },
    {
      "x": 3,
      "y": 3,
      "z": 6,
      "name": "Rock_Shale"
    },
    {
      "x": 4,
      "y": 0,
      "z": -9,
      "name": "Rock_Shale"
    },
    {
      "x": 4,
      "y": 1,
      "z": -9,
      "name": "Empty"
    },
    {
      "x": 4,
      "y": 2,
      "z": -9,
      "name": "Empty"
    },
    {
      "x": 4,
      "y": 3,
      "z": -9,
      "name": "Empty"
    },
    {
      "x": 4,
      "y": 4,
      "z": -9,
      "name": "Empty"
    },
    {
      "x": 4,
      "y": 5,
      "z": -9,
      "name": "Rock_Basalt"
    },
    {
      "x": 4,
      "y": 0,
      "z": -8,
      "name": "Rock_Shale"
    },
    {
      "x": 4,
      "y": 1,
      "z": -8,
      "name": "Empty"
    },
    {
      "x": 4,
      "y": 2,
      "z": -8,
      "name": "Empty"
    },
    {
      "x": 4,
      "y": 3,
      "z": -8,
      "name": "Empty"
    },
    {
      "x": 4,
      "y": 4,
      "z": -8,
      "name": "Empty"
    },
    {
      "x": 4,
      "y": 5,
      "z": -8,
      "name": "Rock_Basalt"
    },
    {
      "x": 4,
      "y": 0,
      "z": -7,
      "name": "Rock_Shale"
    },
    {
      "x": 4,
      "y": 1,
      "z": -7,
      "name": "Empty"
    },
    {
      "x": 4,
      "y": 2,
      "z": -7,
      "name": "Empty"
    },
    {
      "x": 4,
      "y": 3,
      "z": -7,
      "name": "Empty"
    },
    {
      "x": 4,
      "y": 4,
      "z": -7,
      "name": "Empty"
    },
    {
      "x": 4,
      "y": 5,
      "z": -7,
      "name": "Rock_Basalt"
    },
    {
      "x": 4,
      "y": 0,
      "z": -6,
      "name": "Rock_Shale_Brick"
    },
    {
      "x": 4,
      "y": 1,
      "z": -6,
      "name": "Empty"
    },
    {
      "x": 4,
      "y": 2,
      "z": -6,
      "name": "Empty"
    },
    {
      "x": 4,
      "y": 3,
      "z": -6,
      "name": "Empty"
    },
    {
      "x": 4,
      "y": 4,
      "z": -6,
      "name": "Empty"
    },
    {
      "x": 4,
      "y": 5,
      "z": -6,
      "name": "Rock_Basalt"
    },
    {
      "x": 4,
      "y": 0,
      "z": -5,
      "name": "Rock_Shale_Brick"
    },
    {
      "x": 4,
      "y": 1,
      "z": -5,
      "name": "Empty"
    },
    {
      "x": 4,
      "y": 2,
      "z": -5,
      "name": "Empty"
    },
    {
      "x": 4,
      "y": 3,
      "z": -5,
      "name": "Empty"
    },
    {
      "x": 4,
      "y": 4,
      "z": -5,
      "name": "Empty"
    },
    {
      "x": 4,
      "y": 5,
      "z": -5,
      "name": "Rock_Basalt"
    },
    {
      "x": 4,
      "y": 0,
      "z": -4,
      "name": "Soil_Dirt_Cold"
    },
    {
      "x": 4,
      "y": 1,
      "z": -4,
      "name": "Empty"
    },
    {
      "x": 4,
      "y": 2,
      "z": -4,
      "name": "Empty"
    },
    {
      "x": 4,
      "y": 3,
      "z": -4,
      "name": "Empty"
    },
    {
      "x": 4,
      "y": 4,
      "z": -4,
      "name": "Empty"
    },
    {
      "x": 4,
      "y": 5,
      "z": -4,
      "name": "Rock_Basalt"
    },
    {
      "x": 4,
      "y": 0,
      "z": -3,
      "name": "Soil_Dirt_Cold"
    },
    {
      "x": 4,
      "y": 1,
      "z": -3,
      "name": "Empty"
    },
    {
      "x": 4,
      "y": 2,
      "z": -3,
      "name": "Empty"
    },
    {
      "x": 4,
      "y": 3,
      "z": -3,
      "name": "Empty"
    },
    {
      "x": 4,
      "y": 4,
      "z": -3,
      "name": "Rock_Basalt"
    },
    {
      "x": 4,
      "y": 5,
      "z": -3,
      "name": "Rock_Basalt"
    },
    {
      "x": 4,
      "y": 0,
      "z": -2,
      "name": "Rock_Shale"
    },
    {
      "x": 4,
      "y": 1,
      "z": -2,
      "name": "Rock_Shale"
    },
    {
      "x": 4,
      "y": 2,
      "z": -2,
      "name": "Rock_Shale"
    },
    {
      "x": 4,
      "y": 3,
      "z": -2,
      "name": "Rock_Shale"
    },
    {
      "x": 4,
      "y": 4,
      "z": -2,
      "name": "Rock_Basalt"
    },
    {
      "x": 4,
      "y": 5,
      "z": -2,
      "name": "Rock_Basalt"
    },
    {
      "x": 4,
      "y": 0,
      "z": -1,
      "name": "Rock_Shale"
    },
    {
      "x": 4,
      "y": 1,
      "z": -1,
      "name": "Rock_Shale"
    },
    {
      "x": 4,
      "y": 2,
      "z": -1,
      "name": "Rock_Shale"
    },
    {
      "x": 4,
      "y": 3,
      "z": -1,
      "name": "Rock_Shale"
    },
    {
      "x": 4,
      "y": 4,
      "z": -1,
      "name": "Rock_Shale"
    },
    {
      "x": 4,
      "y": 5,
      "z": -1,
      "name": "Rock_Basalt"
    },
    {
      "x": 4,
      "y": 1,
      "z": 0,
      "name": "Rock_Shale"
    },
    {
      "x": 4,
      "y": 2,
      "z": 0,
      "name": "Rock_Basalt_Brick"
    },
    {
      "x": 4,
      "y": 3,
      "z": 0,
      "name": "Rock_Basalt_Brick"
    },
    {
      "x": 4,
      "y": 4,
      "z": 0,
      "name": "Rock_Basalt_Brick"
    },
    {
      "x": 4,
      "y": 5,
      "z": 0,
      "name": "Rock_Basalt_Brick"
    },
    {
      "x": 4,
      "y": 6,
      "z": 0,
      "name": "Rock_Basalt"
    },
    {
      "x": 4,
      "y": 1,
      "z": 1,
      "name": "Rock_Shale"
    },
    {
      "x": 4,
      "y": 2,
      "z": 1,
      "name": "Rock_Basalt_Brick"
    },
    {
      "x": 4,
      "y": 3,
      "z": 1,
      "name": "Rock_Basalt_Brick"
    },
    {
      "x": 4,
      "y": 4,
      "z": 1,
      "name": "Rock_Basalt_Brick"
    },
    {
      "x": 4,
      "y": 5,
      "z": 1,
      "name": "Rock_Basalt_Brick"
    },
    {
      "x": 4,
      "y": 6,
      "z": 1,
      "name": "Rock_Basalt_Brick"
    },
    {
      "x": 4,
      "y": 1,
      "z": 2,
      "name": "Rock_Shale"
    },
    {
      "x": 4,
      "y": 2,
      "z": 2,
      "name": "Rock_Shale_Brick"
    },
    {
      "x": 4,
      "y": 1,
      "z": 3,
      "name": "Rock_Shale"
    },
    {
      "x": 4,
      "y": 2,
      "z": 3,
      "name": "Rock_Shale_Brick"
    },
    {
      "x": 4,
      "y": 1,
      "z": 4,
      "name": "Rock_Shale_Brick"
    },
    {
      "x": 4,
      "y": 2,
      "z": 4,
      "name": "Rock_Shale_Brick"
    },
    {
      "x": 5,
      "y": 0,
      "z": -9,
      "name": "Rock_Shale"
    },
    {
      "x": 5,
      "y": 1,
      "z": -9,
      "name": "Empty"
    },
    {
      "x": 5,
      "y": 2,
      "z": -9,
      "name": "Empty"
    },
    {
      "x": 5,
      "y": 3,
      "z": -9,
      "name": "Empty"
    },
    {
      "x": 5,
      "y": 4,
      "z": -9,
      "name": "Empty"
    },
    {
      "x": 5,
      "y": 5,
      "z": -9,
      "name": "Rock_Basalt"
    },
    {
      "x": 5,
      "y": 0,
      "z": -8,
      "name": "Rock_Shale"
    },
    {
      "x": 5,
      "y": 1,
      "z": -8,
      "name": "Empty"
    },
    {
      "x": 5,
      "y": 2,
      "z": -8,
      "name": "Empty"
    },
    {
      "x": 5,
      "y": 3,
      "z": -8,
      "name": "Empty"
    },
    {
      "x": 5,
      "y": 4,
      "z": -8,
      "name": "Empty"
    },
    {
      "x": 5,
      "y": 5,
      "z": -8,
      "name": "Rock_Basalt"
    },
    {
      "x": 5,
      "y": 0,
      "z": -7,
      "name": "Rock_Basalt"
    },
    {
      "x": 5,
      "y": 1,
      "z": -7,
      "name": "Rubble_Basalt"
    },
    {
      "x": 5,
      "y": 2,
      "z": -7,
      "name": "Empty"
    },
    {
      "x": 5,
      "y": 3,
      "z": -7,
      "name": "Empty"
    },
    {
      "x": 5,
      "y": 4,
      "z": -7,
      "name": "Empty"
    },
    {
      "x": 5,
      "y": 5,
      "z": -7,
      "name": "Rock_Basalt"
    },
    {
      "x": 5,
      "y": 0,
      "z": -6,
      "name": "Rock_Basalt"
    },
    {
      "x": 5,
      "y": 1,
      "z": -6,
      "name": "Deco_Bone_Pile"
    },
    {
      "x": 5,
      "y": 2,
      "z": -6,
      "name": "Empty"
    },
    {
      "x": 5,
      "y": 3,
      "z": -6,
      "name": "Empty"
    },
    {
      "x": 5,
      "y": 4,
      "z": -6,
      "name": "Empty"
    },
    {
      "x": 5,
      "y": 5,
      "z": -6,
      "name": "Rock_Basalt"
    },
    {
      "x": 5,
      "y": 0,
      "z": -5,
      "name": "Rock_Shale"
    },
    {
      "x": 5,
      "y": 1,
      "z": -5,
      "name": "Empty"
    },
    {
      "x": 5,
      "y": 2,
      "z": -5,
      "name": "Empty"
    },
    {
      "x": 5,
      "y": 3,
      "z": -5,
      "name": "Empty"
    },
    {
      "x": 5,
      "y": 4,
      "z": -5,
      "name": "Empty"
    },
    {
      "x": 5,
      "y": 5,
      "z": -5,
      "name": "Rock_Basalt"
    },
    {
      "x": 5,
      "y": 0,
      "z": -4,
      "name": "Rock_Shale"
    },
    {
      "x": 5,
      "y": 1,
      "z": -4,
      "name": "Plant_Crop_Mushroom_Glowing_Blue"
    },
    {
      "x": 5,
      "y": 2,
      "z": -4,
      "name": "Empty"
    },
    {
      "x": 5,
      "y": 3,
      "z": -4,
      "name": "Empty"
    },
    {
      "x": 5,
      "y": 4,
      "z": -4,
      "name": "Empty"
    },
    {
      "x": 5,
      "y": 5,
      "z": -4,
      "name": "Rock_Basalt"
    },
    {
      "x": 5,
      "y": 0,
      "z": -3,
      "name": "Rock_Shale"
    },
    {
      "x": 5,
      "y": 1,
      "z": -3,
      "name": "Rock_Shale"
    },
    {
      "x": 5,
      "y": 2,
      "z": -3,
      "name": "Rock_Shale"
    },
    {
      "x": 5,
      "y": 3,
      "z": -3,
      "name": "Empty"
    },
    {
      "x": 5,
      "y": 4,
      "z": -3,
      "name": "Rock_Basalt"
    },
    {
      "x": 5,
      "y": 5,
      "z": -3,
      "name": "Rock_Basalt"
    },
    {
      "x": 5,
      "y": 0,
      "z": -2,
      "name": "Rock_Shale"
    },
    {
      "x": 5,
      "y": 1,
      "z": -2,
      "name": "Rock_Shale"
    },
    {
      "x": 5,
      "y": 2,
      "z": -2,
      "name": "Rock_Shale"
    },
    {
      "x": 5,
      "y": 3,
      "z": -2,
      "name": "Rock_Shale"
    },
    {
      "x": 5,
      "y": 4,
      "z": -2,
      "name": "Rock_Shale"
    },
    {
      "x": 5,
      "y": 5,
      "z": -2,
      "name": "Rock_Basalt"
    },
    {
      "x": 6,
      "y": 0,
      "z": -9,
      "name": "Rock_Basalt"
    },
    {
      "x": 6,
      "y": 1,
      "z": -9,
      "name": "Empty"
    },
    {
      "x": 6,
      "y": 2,
      "z": -9,
      "name": "Empty"
    },
    {
      "x": 6,
      "y": 3,
      "z": -9,
      "name": "Empty"
    },
    {
      "x": 6,
      "y": 4,
      "z": -9,
      "name": "Empty"
    },
    {
      "x": 6,
      "y": 5,
      "z": -9,
      "name": "Rock_Basalt"
    },
    {
      "x": 6,
      "y": 0,
      "z": -8,
      "name": "Rock_Basalt"
    },
    {
      "x": 6,
      "y": 1,
      "z": -8,
      "name": "Empty"
    },
    {
      "x": 6,
      "y": 2,
      "z": -8,
      "name": "Empty"
    },
    {
      "x": 6,
      "y": 3,
      "z": -8,
      "name": "Empty"
    },
    {
      "x": 6,
      "y": 4,
      "z": -8,
      "name": "Plant_Bush_Dead_Hanging"
    },
    {
      "x": 6,
      "y": 5,
      "z": -8,
      "name": "Rock_Basalt"
    },
    {
      "x": 6,
      "y": 0,
      "z": -7,
      "name": "Rock_Basalt"
    },
    {
      "x": 6,
      "y": 1,
      "z": -7,
      "name": "Deco_Bone_Skulls"
    },
    {
      "x": 6,
      "y": 2,
      "z": -7,
      "name": "Empty"
    },
    {
      "x": 6,
      "y": 3,
      "z": -7,
      "name": "Empty"
    },
    {
      "x": 6,
      "y": 4,
      "z": -7,
      "name": "Empty"
    },
    {
      "x": 6,
      "y": 5,
      "z": -7,
      "name": "Rock_Basalt"
    },
    {
      "x": 6,
      "y": 0,
      "z": -6,
      "name": "Soil_Dirt_Cold"
    },
    {
      "x": 6,
      "y": 1,
      "z": -6,
      "name": "Plant_Bush_Dead_Twisted"
    },
    {
      "x": 6,
      "y": 2,
      "z": -6,
      "name": "Empty"
    },
    {
      "x": 6,
      "y": 3,
      "z": -6,
      "name": "Empty"
    },
    {
      "x": 6,
      "y": 4,
      "z": -6,
      "name": "Empty"
    },
    {
      "x": 6,
      "y": 5,
      "z": -6,
      "name": "Rock_Basalt"
    },
    {
      "x": 6,
      "y": 0,
      "z": -5,
      "name": "Soil_Dirt_Cold"
    },
    {
      "x": 6,
      "y": 1,
      "z": -5,
      "name": "Empty"
    },
    {
      "x": 6,
      "y": 2,
      "z": -5,
      "name": "Empty"
    },
    {
      "x": 6,
      "y": 3,
      "z": -5,
      "name": "Empty"
    },
    {
      "x": 6,
      "y": 4,
      "z": -5,
      "name": "Empty"
    },
    {
      "x": 6,
      "y": 5,
      "z": -5,
      "name": "Rock_Basalt"
    },
    {
      "x": 6,
      "y": 0,
      "z": -4,
      "name": "Rock_Shale"
    },
    {
      "x": 6,
      "y": 1,
      "z": -4,
      "name": "Empty"
    },
    {
      "x": 6,
      "y": 2,
      "z": -4,
      "name": "Empty"
    },
    {
      "x": 6,
      "y": 3,
      "z": -4,
      "name": "Empty"
    },
    {
      "x": 6,
      "y": 4,
      "z": -4,
      "name": "Empty"
    },
    {
      "x": 6,
      "y": 5,
      "z": -4,
      "name": "Rock_Basalt"
    },
    {
      "x": 6,
      "y": 0,
      "z": -3,
      "name": "Rock_Shale"
    },
    {
      "x": 6,
      "y": 1,
      "z": -3,
      "name": "Rock_Shale"
    },
    {
      "x": 6,
      "y": 2,
      "z": -3,
      "name": "Rock_Shale"
    },
    {
      "x": 6,
      "y": 3,
      "z": -3,
      "name": "Rock_Shale"
    },
    {
      "x": 6,
      "y": 4,
      "z": -3,
      "name": "Rock_Shale"
    },
    {
      "x": 6,
      "y": 5,
      "z": -3,
      "name": "Rock_Basalt"
    },
    {
      "x": 7,
      "y": 0,
      "z": -9,
      "name": "Soil_Dirt_Cold"
    },
    {
      "x": 7,
      "y": 1,
      "z": -9,
      "name": "Empty"
    },
    {
      "x": 7,
      "y": 2,
      "z": -9,
      "name": "Empty"
    },
    {
      "x": 7,
      "y": 3,
      "z": -9,
      "name": "Empty"
    },
    {
      "x": 7,
      "y": 4,
      "z": -9,
      "name": "Rock_Basalt"
    },
    {
      "x": 7,
      "y": 5,
      "z": -9,
      "name": "Rock_Basalt"
    },
    {
      "x": 7,
      "y": 0,
      "z": -8,
      "name": "Soil_Dirt_Cold"
    },
    {
      "x": 7,
      "y": 1,
      "z": -8,
      "name": "Empty"
    },
    {
      "x": 7,
      "y": 2,
      "z": -8,
      "name": "Empty"
    },
    {
      "x": 7,
      "y": 3,
      "z": -8,
      "name": "Empty"
    },
    {
      "x": 7,
      "y": 4,
      "z": -8,
      "name": "Rock_Basalt"
    },
    {
      "x": 7,
      "y": 5,
      "z": -8,
      "name": "Rock_Basalt"
    },
    {
      "x": 7,
      "y": 0,
      "z": -7,
      "name": "Soil_Dirt_Cold"
    },
    {
      "x": 7,
      "y": 1,
      "z": -7,
      "name": "Empty"
    },
    {
      "x": 7,
      "y": 2,
      "z": -7,
      "name": "Empty"
    },
    {
      "x": 7,
      "y": 3,
      "z": -7,
      "name": "Empty"
    },
    {
      "x": 7,
      "y": 4,
      "z": -7,
      "name": "Rock_Basalt"
    },
    {
      "x": 7,
      "y": 5,
      "z": -7,
      "name": "Rock_Basalt"
    },
    {
      "x": 7,
      "y": 0,
      "z": -6,
      "name": "Soil_Dirt_Cold"
    },
    {
      "x": 7,
      "y": 1,
      "z": -6,
      "name": "Empty"
    },
    {
      "x": 7,
      "y": 2,
      "z": -6,
      "name": "Rock_Shale_Stalactites_Small",
      "rotation": 8
    },
    {
      "x": 7,
      "y": 3,
      "z": -6,
      "name": "Rock_Shale"
    },
    {
      "x": 7,
      "y": 4,
      "z": -6,
      "name": "Rock_Shale"
    },
    {
      "x": 7,
      "y": 5,
      "z": -6,
      "name": "Rock_Basalt"
    },
    {
      "x": 7,
      "y": 0,
      "z": -5,
      "name": "Rock_Shale"
    },
    {
      "x": 7,
      "y": 1,
      "z": -5,
      "name": "Rock_Shale"
    },
    {
      "x": 7,
      "y": 2,
      "z": -5,
      "name": "Rock_Shale"
    },
    {
      "x": 7,
      "y": 3,
      "z": -5,
      "name": "Rock_Shale"
    },
