{
  "version": 8,
  "blockIdVersion": 8,
  "anchorX": 0,
  "anchorY": 0,
  "anchorZ": 0,
  "blocks": [
    {
      "x": -11,
      "y": -7,
      "z": -11,
      "name": "Rock_Stone"
    },
    {
      "x": -11,
      "y": -6,
      "z": -11,
      "name": "Rock_Stone"
    },
    {
      "x": -11,
      "y": -5,
      "z": -11,
      "name": "Rock_Stone"
    },
    {
      "x": -11,
      "y": -8,
      "z": -10,
      "name": "Rock_Stone"
    },
    {
      "x": -11,
      "y": -7,
      "z": -10,
      "name": "Rock_Stone"
    },
    {
      "x": -11,
      "y": -6,
      "z": -10,
      "name": "Rock_Stone"
    },
    {
      "x": -11,
      "y": -5,
      "z": -10,
      "name": "Rock_Stone"
    },
    {
      "x": -11,
      "y": -8,
      "z": -9,
      "name": "Rock_Stone"
    },
    {
      "x": -11,
      "y": -7,
      "z": -9,
      "name": "Rock_Stone"
    },
    {
      "x": -11,
      "y": -6,
      "z": -9,
      "name": "Rock_Stone"
    },
    {
      "x": -11,
      "y": -5,
      "z": -9,
      "name": "Rock_Stone"
    },
    {
      "x": -11,
      "y": -10,
      "z": -8,
      "name": "Rock_Stone"
    },
    {
      "x": -11,
      "y": -9,
      "z": -8,
      "name": "Rock_Stone"
    },
    {
      "x": -11,
      "y": -8,
      "z": -8,
      "name": "Rock_Stone"
    },
    {
      "x": -11,
      "y": -7,
      "z": -8,
      "name": "Rock_Stone"
    },
    {
      "x": -11,
      "y": -6,
      "z": -8,
      "name": "Rock_Stone"
    },
    {
      "x": -11,
      "y": -5,
      "z": -8,
      "name": "Rock_Stone"
    },
    {
      "x": -11,
      "y": -10,
      "z": -7,
      "name": "Rock_Stone"
    },
    {
      "x": -11,
      "y": -9,
      "z": -7,
      "name": "Rock_Stone"
    },
    {
      "x": -11,
      "y": -8,
      "z": -7,
      "name": "Rock_Stone"
    },
    {
      "x": -11,
      "y": -7,
      "z": -7,
      "name": "Rock_Stone"
    },
    {
      "x": -11,
      "y": -6,
      "z": -7,
      "name": "Rock_Stone"
    },
    {
      "x": -11,
      "y": -5,
      "z": -7,
      "name": "Rock_Stone"
    },
    {
      "x": -11,
      "y": -10,
      "z": -6,
      "name": "Rock_Stone"
    },
    {
      "x": -11,
      "y": -9,
      "z": -6,
      "name": "Rock_Stone"
    },
    {
      "x": -11,
      "y": -8,
      "z": -6,
      "name": "Rock_Stone"
    },
    {
      "x": -11,
      "y": -7,
      "z": -6,
      "name": "Rock_Stone"
    },
    {
      "x": -11,
      "y": -6,
      "z": -6,
      "name": "Rock_Stone"
    },
    {
      "x": -11,
      "y": -5,
      "z": -6,
      "name": "Rock_Stone"
    },
    {
      "x": -11,
      "y": -10,
      "z": -5,
      "name": "Rock_Stone"
    },
    {
      "x": -11,
      "y": -9,
      "z": -5,
      "name": "Rock_Stone"
    },
    {
      "x": -11,
      "y": -8,
      "z": -5,
      "name": "Rock_Stone"
    },
    {
      "x": -11,
      "y": -7,
      "z": -5,
      "name": "Rock_Stone"
    },
    {
      "x": -11,
      "y": -6,
      "z": -5,
      "name": "Rock_Stone"
    },
    {
      "x": -11,
      "y": -5,
      "z": -5,
      "name": "Rock_Stone"
    },
    {
      "x": -11,
      "y": -4,
      "z": -5,
      "name": "Rock_Stone"
    },
    {
      "x": -11,
      "y": -3,
      "z": -5,
      "name": "Rock_Stone"
    },
    {
      "x": -11,
      "y": -10,
      "z": -4,
      "name": "Rock_Stone"
    },
    {
      "x": -11,
      "y": -9,
      "z": -4,
      "name": "Rock_Stone"
    },
    {
      "x": -11,
      "y": -8,
      "z": -4,
      "name": "Rock_Stone"
    },
    {
      "x": -11,
      "y": -7,
      "z": -4,
      "name": "Rock_Stone"
    },
    {
      "x": -11,
      "y": -6,
      "z": -4,
      "name": "Rock_Stone"
    },
    {
      "x": -11,
      "y": -5,
      "z": -4,
      "name": "Rock_Stone"
    },
    {
      "x": -11,
      "y": -4,
      "z": -4,
      "name": "Rock_Stone"
    },
    {
      "x": -11,
      "y": -10,
      "z": -3,
      "name": "Rock_Stone"
    },
    {
      "x": -11,
      "y": -9,
      "z": -3,
      "name": "Rock_Stone"
    },
    {
      "x": -11,
      "y": -8,
      "z": -3,
      "name": "Rock_Stone"
    },
    {
      "x": -11,
      "y": -7,
      "z": -3,
      "name": "Rock_Stone"
    },
    {
      "x": -11,
      "y": -6,
      "z": -3,
      "name": "Rock_Stone"
    },
    {
      "x": -11,
      "y": -5,
      "z": -3,
      "name": "Rock_Stone"
    },
    {
      "x": -11,
      "y": -4,
      "z": -3,
      "name": "Rock_Stone"
    },
    {
      "x": -11,
      "y": -3,
      "z": -3,
      "name": "Rock_Stone"
    },
    {
      "x": -11,
      "y": -2,
      "z": -3,
      "name": "Rock_Stone"
    },
    {
      "x": -11,
      "y": -10,
      "z": -2,
      "name": "Rock_Stone"
    },
    {
      "x": -11,
      "y": -9,
      "z": -2,
      "name": "Rock_Stone"
    },
    {
      "x": -11,
      "y": -8,
      "z": -2,
      "name": "Rock_Stone"
    },
    {
      "x": -11,
      "y": -7,
      "z": -2,
      "name": "Rock_Stone"
    },
    {
      "x": -11,
      "y": -6,
      "z": -2,
      "name": "Rock_Stone"
    },
    {
      "x": -11,
      "y": -5,
      "z": -2,
      "name": "Rock_Stone"
    },
    {
      "x": -11,
      "y": -4,
      "z": -2,
      "name": "Rock_Stone"
    },
    {
      "x": -11,
      "y": -3,
      "z": -2,
      "name": "Rock_Stone"
    },
    {
      "x": -11,
      "y": -2,
      "z": -2,
      "name": "Rock_Stone"
    },
    {
      "x": -11,
      "y": -10,
      "z": -1,
      "name": "Rock_Stone"
    },
    {
      "x": -11,
      "y": -9,
      "z": -1,
      "name": "Rock_Stone"
    },
    {
      "x": -11,
      "y": -8,
      "z": -1,
      "name": "Rock_Stone"
    },
    {
      "x": -11,
      "y": -7,
      "z": -1,
      "name": "Rock_Stone"
    },
    {
      "x": -11,
      "y": -6,
      "z": -1,
      "name": "Rock_Stone"
    },
    {
      "x": -11,
      "y": -5,
      "z": -1,
      "name": "Rock_Stone"
    },
    {
      "x": -11,
      "y": -4,
      "z": -1,
      "name": "Rock_Stone"
    },
    {
      "x": -11,
      "y": -3,
      "z": -1,
      "name": "Rock_Stone"
    },
    {
      "x": -11,
      "y": -2,
      "z": -1,
      "name": "Rock_Stone"
    },
    {
      "x": -11,
      "y": -10,
      "z": 0,
      "name": "Rock_Stone"
    },
    {
      "x": -11,
      "y": -9,
      "z": 0,
      "name": "Rock_Stone"
    },
    {
      "x": -11,
      "y": -8,
      "z": 0,
      "name": "Rock_Stone"
    },
    {
      "x": -11,
      "y": -7,
      "z": 0,
      "name": "Rock_Stone"
    },
    {
      "x": -11,
      "y": -6,
      "z": 0,
      "name": "Rock_Stone"
    },
    {
      "x": -11,
      "y": -5,
      "z": 0,
      "name": "Rock_Stone"
    },
    {
      "x": -11,
      "y": -4,
      "z": 0,
      "name": "Rock_Stone"
    },
    {
      "x": -11,
      "y": -3,
      "z": 0,
      "name": "Rock_Stone"
    },
    {
      "x": -11,
      "y": -2,
      "z": 0,
      "name": "Rock_Stone"
    },
    {
      "x": -11,
      "y": -10,
      "z": 1,
      "name": "Rock_Stone"
    },
    {
      "x": -11,
      "y": -9,
      "z": 1,
      "name": "Rock_Stone"
    },
    {
      "x": -11,
      "y": -8,
      "z": 1,
      "name": "Rock_Stone"
    },
    {
      "x": -11,
      "y": -7,
      "z": 1,
      "name": "Rock_Stone"
    },
    {
      "x": -11,
      "y": -6,
      "z": 1,
      "name": "Rock_Stone"
    },
    {
      "x": -11,
      "y": -5,
      "z": 1,
      "name": "Rock_Stone"
    },
    {
      "x": -11,
      "y": -4,
      "z": 1,
      "name": "Rock_Stone"
    },
    {
      "x": -11,
      "y": -3,
      "z": 1,
      "name": "Rock_Stone"
    },
    {
      "x": -11,
      "y": -10,
      "z": 2,
      "name": "Rock_Stone"
    },
    {
      "x": -11,
      "y": -9,
      "z": 2,
      "name": "Rock_Stone"
    },
    {
      "x": -11,
      "y": -8,
      "z": 2,
      "name": "Rock_Stone"
    },
    {
      "x": -11,
      "y": -7,
      "z": 2,
      "name": "Rock_Stone"
    },
    {
      "x": -11,
      "y": -6,
      "z": 2,
      "name": "Rock_Stone"
    },
    {
      "x": -11,
      "y": -5,
      "z": 2,
      "name": "Rock_Stone"
    },
    {
      "x": -11,
      "y": -4,
      "z": 2,
      "name": "Rock_Stone"
    },
    {
      "x": -11,
      "y": -3,
      "z": 2,
      "name": "Rock_Stone"
    },
    {
      "x": -11,
      "y": -2,
      "z": 2,
      "name": "Rock_Stone"
    },
    {
      "x": -11,
      "y": -1,
      "z": 2,
      "name": "Rock_Stone"
    },
    {
      "x": -11,
      "y": 0,
      "z": 2,
      "name": "Rock_Stone"
    },
    {
      "x": -11,
      "y": -8,
      "z": 3,
      "name": "Rock_Stone"
    },
    {
      "x": -11,
      "y": -7,
      "z": 3,
      "name": "Rock_Stone"
    },
    {
      "x": -11,
      "y": -6,
      "z": 3,
      "name": "Rock_Stone"
    },
    {
      "x": -11,
      "y": -5,
      "z": 3,
      "name": "Rock_Stone"
    },
    {
      "x": -11,
      "y": -4,
      "z": 3,
      "name": "Rock_Stone"
    },
    {
      "x": -11,
      "y": -3,
      "z": 3,
      "name": "Rock_Stone"
    },
    {
      "x": -11,
      "y": -2,
      "z": 3,
      "name": "Rock_Stone"
    },
    {
      "x": -11,
      "y": -1,
      "z": 3,
      "name": "Rock_Stone"
    },
    {
      "x": -11,
      "y": 0,
      "z": 3,
      "name": "Rock_Stone"
    },
    {
      "x": -11,
      "y": -6,
      "z": 4,
      "name": "Rock_Stone"
    },
    {
      "x": -11,
      "y": -5,
      "z": 4,
      "name": "Rock_Stone"
    },
    {
      "x": -11,
      "y": -4,
      "z": 4,
      "name": "Rock_Stone"
    },
    {
      "x": -11,
      "y": -3,
      "z": 4,
      "name": "Rock_Stone"
    },
    {
      "x": -11,
      "y": -2,
      "z": 4,
      "name": "Rock_Stone"
    },
    {
      "x": -11,
      "y": -6,
      "z": 5,
      "name": "Rock_Stone"
    },
    {
      "x": -11,
      "y": -5,
      "z": 5,
      "name": "Rock_Stone"
    },
    {
      "x": -11,
      "y": -4,
      "z": 5,
      "name": "Rock_Stone"
    },
    {
      "x": -10,
      "y": -8,
      "z": -11,
      "name": "Rock_Stone"
    },
    {
      "x": -10,
      "y": -7,
      "z": -11,
      "name": "Rock_Stone"
    },
    {
      "x": -10,
      "y": -6,
      "z": -11,
      "name": "Rock_Stone"
    },
    {
      "x": -10,
      "y": -5,
      "z": -11,
      "name": "Rock_Stone"
    },
    {
      "x": -10,
      "y": -4,
      "z": -11,
      "name": "Rock_Stone"
    },
    {
      "x": -10,
      "y": -9,
      "z": -10,
      "name": "Rock_Stone"
    },
    {
      "x": -10,
      "y": -8,
      "z": -10,
      "name": "Soil_Pathway"
    },
    {
      "x": -10,
      "y": -7,
      "z": -10,
      "name": "Furniture_Crude_Platform",
      "rotation": 1
    },
    {
      "x": -10,
      "y": -6,
      "z": -10,
      "name": "Furniture_Village_Crate"
    },
    {
      "x": -10,
      "y": -5,
      "z": -10,
      "name": "Furniture_Crude_Platform",
      "rotation": 1
    },
    {
      "x": -10,
      "y": -4,
      "z": -10,
      "name": "Wood_Softwood_Planks_Half",
      "rotation": 8
    },
    {
      "x": -10,
      "y": -3,
      "z": -10,
      "name": "Empty"
    },
    {
      "x": -10,
      "y": -2,
      "z": -10,
      "name": "Empty"
    },
    {
      "x": -10,
      "y": -1,
      "z": -10,
      "name": "Empty"
    },
    {
      "x": -10,
      "y": -9,
      "z": -9,
      "name": "Rock_Stone"
    },
    {
      "x": -10,
      "y": -8,
      "z": -9,
      "name": "Soil_Pathway"
    },
    {
      "x": -10,
      "y": -7,
      "z": -9,
      "name": "Furniture_Tavern_Barrel"
    },
    {
      "x": -10,
      "y": -6,
      "z": -9,
      "name": "Empty"
    },
    {
      "x": -10,
      "y": -5,
      "z": -9,
      "name": "Empty"
    },
    {
      "x": -10,
      "y": -4,
      "z": -9,
      "name": "Wood_Softwood_Planks_Half",
      "rotation": 8
    },
    {
      "x": -10,
      "y": -3,
      "z": -9,
      "name": "Empty"
    },
    {
      "x": -10,
      "y": -2,
      "z": -9,
      "name": "Empty"
    },
    {
      "x": -10,
      "y": -1,
      "z": -9,
      "name": "Empty"
    },
    {
      "x": -10,
      "y": -10,
      "z": -8,
      "name": "Rock_Stone"
    },
    {
      "x": -10,
      "y": -9,
      "z": -8,
      "name": "Rock_Stone"
    },
    {
      "x": -10,
      "y": -8,
      "z": -8,
      "name": "Soil_Pathway"
    },
    {
      "x": -10,
      "y": -7,
      "z": -8,
      "name": "Empty"
    },
    {
      "x": -10,
      "y": -6,
      "z": -8,
      "name": "Empty"
    },
    {
      "x": -10,
      "y": -5,
      "z": -8,
      "name": "Empty"
    },
    {
      "x": -10,
      "y": -4,
      "z": -8,
      "name": "Wood_Softwood_Planks_Half",
      "rotation": 8
    },
    {
      "x": -10,
      "y": -3,
      "z": -8,
      "name": "Empty"
    },
    {
      "x": -10,
      "y": -2,
      "z": -8,
      "name": "Empty"
    },
    {
      "x": -10,
      "y": -1,
      "z": -8,
      "name": "Empty"
    },
    {
      "x": -10,
      "y": -10,
      "z": -7,
      "name": "Rock_Stone"
    },
    {
      "x": -10,
      "y": -9,
      "z": -7,
      "name": "Rock_Stone"
    },
    {
      "x": -10,
      "y": -8,
      "z": -7,
      "name": "Rock_Stone_Cobble_Stairs"
    },
    {
      "x": -10,
      "y": -7,
      "z": -7,
      "name": "Empty"
    },
    {
      "x": -10,
      "y": -6,
      "z": -7,
      "name": "Empty"
    },
    {
      "x": -10,
      "y": -5,
      "z": -7,
      "name": "Empty"
    },
    {
      "x": -10,
      "y": -4,
      "z": -7,
      "name": "Wood_Softwood_Planks_Half",
      "rotation": 8
    },
    {
      "x": -10,
      "y": -3,
      "z": -7,
      "name": "Empty"
    },
    {
      "x": -10,
      "y": -2,
      "z": -7,
      "name": "Empty"
    },
    {
      "x": -10,
      "y": -1,
      "z": -7,
      "name": "Empty"
    },
    {
      "x": -10,
      "y": -10,
      "z": -6,
      "name": "Rock_Stone_Cobble"
    },
    {
      "x": -10,
      "y": -9,
      "z": -6,
      "name": "Rock_Stone_Cobble_Stairs"
    },
    {
      "x": -10,
      "y": -8,
      "z": -6,
      "name": "Empty"
    },
    {
      "x": -10,
      "y": -7,
      "z": -6,
      "name": "Empty"
    },
    {
      "x": -10,
      "y": -6,
      "z": -6,
      "name": "Empty"
    },
    {
      "x": -10,
      "y": -5,
      "z": -6,
      "name": "Empty"
    },
    {
      "x": -10,
      "y": -4,
      "z": -6,
      "name": "Wood_Softwood_Planks_Half",
      "rotation": 8
    },
    {
      "x": -10,
      "y": -3,
      "z": -6,
      "name": "Empty"
    },
    {
      "x": -10,
      "y": -2,
      "z": -6,
      "name": "Empty"
    },
    {
      "x": -10,
      "y": -1,
      "z": -6,
      "name": "Empty"
    },
    {
      "x": -10,
      "y": -10,
      "z": -5,
      "name": "Rock_Stone_Cobble"
    },
    {
      "x": -10,
      "y": -9,
      "z": -5,
      "name": "Empty"
    },
    {
      "x": -10,
      "y": -8,
      "z": -5,
      "name": "Empty"
    },
    {
      "x": -10,
      "y": -7,
      "z": -5,
      "name": "Empty"
    },
    {
      "x": -10,
      "y": -6,
      "z": -5,
      "name": "Empty"
    },
    {
      "x": -10,
      "y": -5,
      "z": -5,
      "name": "Empty"
    },
    {
      "x": -10,
      "y": -4,
      "z": -5,
      "name": "Wood_Softwood_Planks_Half",
      "rotation": 8
    },
    {
      "x": -10,
      "y": -3,
      "z": -5,
      "name": "Empty"
    },
    {
      "x": -10,
      "y": -2,
      "z": -5,
      "name": "Empty"
    },
    {
      "x": -10,
      "y": -1,
      "z": -5,
      "name": "Empty"
    },
    {
      "x": -10,
      "y": -10,
      "z": -4,
      "name": "Rock_Stone_Cobble"
    },
    {
      "x": -10,
      "y": -9,
      "z": -4,
      "name": "Empty"
    },
    {
      "x": -10,
      "y": -8,
      "z": -4,
      "name": "Empty"
    },
    {
      "x": -10,
      "y": -7,
      "z": -4,
      "name": "Empty"
    },
    {
      "x": -10,
      "y": -6,
      "z": -4,
      "name": "Empty"
    },
    {
      "x": -10,
      "y": -5,
      "z": -4,
      "name": "Wood_Softwood_Planks_Half",
      "rotation": 6
    },
    {
      "x": -10,
      "y": -4,
      "z": -4,
      "name": "Wood_Beech_Trunk",
      "rotation": 5
    },
    {
      "x": -10,
      "y": -3,
      "z": -4,
      "name": "Empty"
    },
    {
      "x": -10,
      "y": -2,
      "z": -4,
      "name": "Empty"
    },
    {
      "x": -10,
      "y": -1,
      "z": -4,
      "name": "Empty"
    },
    {
      "x": -10,
      "y": -10,
      "z": -3,
      "name": "Rock_Stone"
    },
    {
      "x": -10,
      "y": -9,
      "z": -3,
      "name": "Wood_Beech_Branch_Long"
    },
    {
      "x": -10,
      "y": -8,
      "z": -3,
      "name": "Wood_Beech_Branch_Long"
    },
    {
      "x": -10,
      "y": -7,
      "z": -3,
      "name": "Wood_Beech_Branch_Long"
    },
    {
      "x": -10,
      "y": -6,
      "z": -3,
      "name": "Wood_Beech_Branch_Long"
    },
    {
      "x": -10,
      "y": -5,
      "z": -3,
      "name": "Wood_Beech_Trunk",
      "rotation": 4
    },
    {
      "x": -10,
      "y": -4,
      "z": -3,
      "name": "Furniture_Village_Platform"
    },
    {
      "x": -10,
      "y": -3,
      "z": -3,
      "name": "Soil_Gravel_Half"
    },
    {
      "x": -10,
      "y": -2,
      "z": -3,
      "name": "Empty"
    },
    {
      "x": -10,
      "y": -10,
      "z": -2,
      "name": "Soil_Pathway"
    },
    {
      "x": -10,
      "y": -9,
      "z": -2,
      "name": "Empty"
    },
    {
      "x": -10,
      "y": -8,
      "z": -2,
      "name": "Empty"
    },
    {
      "x": -10,
      "y": -7,
      "z": -2,
      "name": "Empty"
    },
    {
      "x": -10,
      "y": -6,
      "z": -2,
      "name": "Empty"
    },
    {
      "x": -10,
      "y": -5,
      "z": -2,
      "name": "Wood_Beech_Trunk",
      "rotation": 4
    },
    {
      "x": -10,
      "y": -4,
      "z": -2,
      "name": "Furniture_Village_Platform"
    },
    {
      "x": -10,
      "y": -3,
      "z": -2,
      "name": "Soil_Gravel_Half"
    },
    {
      "x": -10,
      "y": -2,
      "z": -2,
      "name": "Empty"
    },
    {
      "x": -10,
      "y": -1,
      "z": -2,
      "name": "Empty"
    },
    {
      "x": -10,
      "y": -10,
      "z": -1,
      "name": "Soil_Gravel"
    },
    {
      "x": -10,
      "y": -9,
      "z": -1,
      "name": "Empty"
    },
    {
      "x": -10,
      "y": -8,
      "z": -1,
      "name": "Empty"
    },
    {
      "x": -10,
      "y": -7,
      "z": -1,
      "name": "Empty"
    },
    {
      "x": -10,
      "y": -6,
      "z": -1,
      "name": "Empty"
    },
    {
      "x": -10,
      "y": -5,
      "z": -1,
      "name": "Wood_Beech_Trunk",
      "rotation": 4
    },
    {
      "x": -10,
      "y": -4,
      "z": -1,
      "name": "Furniture_Village_Platform"
    },
    {
      "x": -10,
      "y": -3,
      "z": -1,
      "name": "Empty"
    },
    {
      "x": -10,
      "y": -2,
      "z": -1,
      "name": "Empty"
    },
    {
      "x": -10,
      "y": -1,
      "z": -1,
      "name": "Empty"
    },
    {
      "x": -10,
      "y": -10,
      "z": 0,
      "name": "Soil_Gravel"
    },
    {
      "x": -10,
      "y": -9,
      "z": 0,
      "name": "Empty"
    },
    {
      "x": -10,
      "y": -8,
      "z": 0,
      "name": "Empty"
    },
    {
      "x": -10,
      "y": -7,
      "z": 0,
      "name": "Empty"
    },
    {
      "x": -10,
      "y": -6,
      "z": 0,
      "name": "Empty"
    },
    {
      "x": -10,
      "y": -5,
      "z": 0,
      "name": "Wood_Beech_Trunk",
      "rotation": 4
    },
    {
      "x": -10,
      "y": -4,
      "z": 0,
      "name": "Wood_Beech_Trunk",
      "rotation": 5
    },
    {
      "x": -10,
      "y": -3,
      "z": 0,
      "name": "Rubble_Stone"
    },
    {
      "x": -10,
      "y": -2,
      "z": 0,
      "name": "Empty"
    },
    {
      "x": -10,
      "y": -1,
      "z": 0,
      "name": "Empty"
    },
    {
      "x": -10,
      "y": -10,
      "z": 1,
      "name": "Soil_Gravel"
    },
    {
      "x": -10,
      "y": -9,
      "z": 1,
      "name": "Soil_Gravel_Half"
    },
    {
      "x": -10,
      "y": -8,
      "z": 1,
      "name": "Empty"
    },
    {
      "x": -10,
      "y": -7,
      "z": 1,
      "name": "Empty"
    },
    {
      "x": -10,
      "y": -6,
      "z": 1,
      "name": "Empty"
    },
    {
      "x": -10,
      "y": -5,
      "z": 1,
      "name": "Wood_Beech_Trunk",
      "rotation": 4
    },
    {
      "x": -10,
      "y": -4,
      "z": 1,
      "name": "Furniture_Crude_Platform",
      "rotation": 1
    },
    {
      "x": -10,
      "y": -3,
      "z": 1,
      "name": "Rubble_Stone_Medium"
    },
    {
      "x": -10,
      "y": -2,
      "z": 1,
      "name": "Empty"
    },
    {
      "x": -10,
      "y": -1,
      "z": 1,
      "name": "Empty"
    },
    {
      "x": -10,
      "y": -10,
      "z": 2,
      "name": "Soil_Gravel"
    },
    {
      "x": -10,
      "y": -9,
      "z": 2,
      "name": "Soil_Gravel_Half"
    },
    {
      "x": -10,
      "y": -8,
      "z": 2,
      "name": "Empty"
    },
    {
      "x": -10,
      "y": -7,
      "z": 2,
      "name": "Empty"
    },
    {
      "x": -10,
      "y": -6,
      "z": 2,
      "name": "Empty"
    },
    {
      "x": -10,
      "y": -5,
      "z": 2,
      "name": "Wood_Beech_Trunk",
      "rotation": 4
    },
    {
      "x": -10,
      "y": -4,
      "z": 2,
      "name": "Furniture_Village_Platform"
    },
    {
      "x": -10,
      "y": -3,
      "z": 2,
      "name": "Soil_Gravel_Half"
    },
    {
      "x": -10,
      "y": -2,
      "z": 2,
      "name": "Rock_Stone_Stalactite_Large",
      "filler": 31744,
      "rotation": 8
    },
    {
      "x": -10,
      "y": -1,
      "z": 2,
      "name": "Rock_Stone_Stalactite_Large",
      "rotation": 8
    },
    {
      "x": -10,
      "y": 0,
      "z": 2,
      "name": "Rock_Stone"
    },
    {
      "x": -10,
      "y": -10,
      "z": 3,
      "name": "Rock_Stone"
    },
    {
      "x": -10,
      "y": -9,
      "z": 3,
      "name": "Rock_Stone"
    },
    {
      "x": -10,
      "y": -8,
      "z": 3,
      "name": "Rock_Stone"
    },
    {
      "x": -10,
      "y": -7,
      "z": 3,
      "name": "Wood_Beech_Branch_Long"
    },
    {
      "x": -10,
      "y": -6,
      "z": 3,
      "name": "Wood_Beech_Branch_Long"
    },
    {
      "x": -10,
      "y": -5,
      "z": 3,
      "name": "Wood_Beech_Trunk",
      "rotation": 4
    },
    {
      "x": -10,
      "y": -4,
      "z": 3,
      "name": "Wood_Beech_Trunk",
      "rotation": 5
    },
    {
      "x": -10,
      "y": -3,
      "z": 3,
      "name": "Soil_Gravel"
    },
    {
      "x": -10,
      "y": -2,
      "z": 3,
      "name": "Empty"
    },
    {
      "x": -10,
      "y": -1,
      "z": 3,
      "name": "Empty"
    },
    {
      "x": -10,
      "y": 0,
      "z": 3,
      "name": "Rock_Stone"
    },
    {
      "x": -10,
      "y": -8,
      "z": 4,
      "name": "Rock_Stone"
    },
    {
      "x": -10,
      "y": -7,
      "z": 4,
      "name": "Rock_Stone"
    },
    {
      "x": -10,
      "y": -6,
      "z": 4,
      "name": "Rock_Stone"
    },
    {
      "x": -10,
      "y": -5,
      "z": 4,
      "name": "Rock_Stone"
    },
    {
      "x": -10,
      "y": -4,
      "z": 4,
      "name": "Rock_Stone"
    },
    {
      "x": -10,
      "y": -3,
      "z": 4,
      "name": "Rock_Stone"
    },
    {
      "x": -10,
      "y": -2,
      "z": 4,
      "name": "Rock_Stone"
    },
    {
      "x": -10,
      "y": -1,
      "z": 4,
      "name": "Rock_Stone"
    },
    {
      "x": -10,
      "y": -7,
      "z": 5,
      "name": "Rock_Stone"
    },
    {
      "x": -10,
      "y": -6,
      "z": 5,
      "name": "Rock_Stone"
    },
    {
      "x": -10,
      "y": -5,
      "z": 5,
      "name": "Rock_Stone"
    },
    {
      "x": -9,
      "y": -8,
      "z": -11,
      "name": "Rock_Stone"
    },
    {
      "x": -9,
      "y": -7,
      "z": -11,
      "name": "Rock_Stone"
    },
    {
      "x": -9,
      "y": -6,
      "z": -11,
      "name": "Rock_Stone"
    },
    {
      "x": -9,
      "y": -5,
      "z": -11,
      "name": "Rock_Stone"
    },
    {
      "x": -9,
      "y": -9,
      "z": -10,
      "name": "Rock_Stone"
    },
    {
      "x": -9,
      "y": -8,
      "z": -10,
      "name": "Soil_Pathway"
    },
    {
      "x": -9,
      "y": -7,
      "z": -10,
      "name": "Furniture_Crude_Platform",
      "rotation": 1
    },
    {
      "x": -9,
      "y": -6,
      "z": -10,
      "name": "Furniture_Village_Crate"
    },
    {
      "x": -9,
      "y": -5,
      "z": -10,
      "name": "Furniture_Crude_Platform",
      "rotation": 1
    },
    {
      "x": -9,
      "y": -4,
      "z": -10,
      "name": "Wood_Softwood_Planks_Half",
      "rotation": 8
    },
    {
      "x": -9,
      "y": -3,
      "z": -10,
      "name": "Empty"
    },
    {
      "x": -9,
      "y": -2,
      "z": -10,
      "name": "Empty"
    },
    {
      "x": -9,
      "y": -1,
      "z": -10,
      "name": "Empty"
    },
    {
      "x": -9,
      "y": -9,
      "z": -9,
      "name": "Rock_Stone"
    },
    {
      "x": -9,
      "y": -8,
      "z": -9,
      "name": "Soil_Pathway"
    },
    {
      "x": -9,
      "y": -7,
      "z": -9,
      "name": "Empty"
    },
    {
      "x": -9,
      "y": -6,
      "z": -9,
      "name": "Empty"
    },
    {
      "x": -9,
      "y": -5,
      "z": -9,
      "name": "Empty"
    },
    {
      "x": -9,
      "y": -4,
      "z": -9,
      "name": "Wood_Softwood_Planks_Half",
      "rotation": 8
    },
    {
      "x": -9,
      "y": -3,
      "z": -9,
      "name": "Empty"
    },
    {
      "x": -9,
      "y": -2,
      "z": -9,
      "name": "Empty"
    },
    {
      "x": -9,
      "y": -1,
      "z": -9,
      "name": "Empty"
    },
    {
      "x": -9,
      "y": -10,
      "z": -8,
      "name": "Rock_Stone"
    },
    {
      "x": -9,
      "y": -9,
      "z": -8,
      "name": "Rock_Stone"
    },
    {
      "x": -9,
      "y": -8,
      "z": -8,
      "name": "Rock_Stone_Cobble"
    },
    {
      "x": -9,
      "y": -7,
      "z": -8,
      "name": "Empty"
    },
    {
      "x": -9,
      "y": -6,
      "z": -8,
      "name": "Empty"
    },
    {
      "x": -9,
      "y": -5,
      "z": -8,
      "name": "Empty"
    },
    {
      "x": -9,
      "y": -4,
      "z": -8,
      "name": "Wood_Softwood_Planks_Half",
      "rotation": 8
    },
    {
      "x": -9,
      "y": -3,
      "z": -8,
      "name": "Empty"
    },
    {
      "x": -9,
      "y": -2,
      "z": -8,
      "name": "Empty"
    },
    {
      "x": -9,
      "y": -1,
      "z": -8,
      "name": "Empty"
    },
    {
      "x": -9,
      "y": -10,
      "z": -7,
      "name": "Rock_Stone"
    },
    {
      "x": -9,
      "y": -9,
      "z": -7,
      "name": "Rock_Stone"
    },
    {
      "x": -9,
      "y": -8,
      "z": -7,
      "name": "Rock_Stone_Cobble_Stairs"
    },
    {
      "x": -9,
      "y": -7,
      "z": -7,
      "name": "Empty"
    },
    {
      "x": -9,
      "y": -6,
      "z": -7,
      "name": "Empty"
    },
    {
      "x": -9,
      "y": -5,
      "z": -7,
      "name": "Empty"
    },
    {
      "x": -9,
      "y": -4,
      "z": -7,
      "name": "Wood_Softwood_Planks_Half",
      "rotation": 8
    },
    {
      "x": -9,
      "y": -3,
      "z": -7,
      "name": "Empty"
    },
    {
      "x": -9,
      "y": -2,
      "z": -7,
      "name": "Empty"
    },
    {
      "x": -9,
      "y": -1,
      "z": -7,
      "name": "Empty"
    },
    {
      "x": -9,
      "y": -10,
      "z": -6,
      "name": "Rock_Stone_Cobble"
    },
    {
      "x": -9,
      "y": -9,
      "z": -6,
      "name": "Rock_Stone_Cobble_Stairs"
    },
    {
      "x": -9,
      "y": -8,
      "z": -6,
      "name": "Empty"
    },
    {
      "x": -9,
      "y": -7,
      "z": -6,
      "name": "Empty"
    },
    {
      "x": -9,
      "y": -6,
      "z": -6,
      "name": "Empty"
    },
    {
      "x": -9,
      "y": -5,
      "z": -6,
      "name": "Empty"
    },
    {
      "x": -9,
      "y": -4,
      "z": -6,
      "name": "Wood_Softwood_Planks_Half",
      "rotation": 8
    },
    {
      "x": -9,
      "y": -3,
      "z": -6,
      "name": "Empty"
    },
    {
      "x": -9,
      "y": -2,
      "z": -6,
      "name": "Empty"
    },
    {
      "x": -9,
      "y": -1,
      "z": -6,
      "name": "Empty"
    },
    {
      "x": -9,
      "y": -10,
      "z": -5,
      "name": "Rock_Stone_Cobble"
    },
    {
      "x": -9,
      "y": -9,
      "z": -5,
      "name": "Empty"
    },
    {
      "x": -9,
      "y": -8,
      "z": -5,
      "name": "Empty"
    },
    {
      "x": -9,
      "y": -7,
      "z": -5,
      "name": "Empty"
    },
    {
      "x": -9,
      "y": -6,
      "z": -5,
      "name": "Empty"
    },
    {
      "x": -9,
      "y": -5,
      "z": -5,
      "name": "Empty"
    },
    {
      "x": -9,
      "y": -4,
      "z": -5,
      "name": "Wood_Softwood_Planks_Half",
      "rotation": 8
    },
    {
      "x": -9,
      "y": -3,
      "z": -5,
      "name": "Empty"
    },
    {
      "x": -9,
      "y": -2,
      "z": -5,
      "name": "Empty"
    },
    {
      "x": -9,
      "y": -1,
      "z": -5,
      "name": "Empty"
    },
    {
      "x": -9,
      "y": 0,
      "z": -5,
      "name": "Rock_Stone"
    },
    {
      "x": -9,
      "y": -10,
      "z": -4,
      "name": "Soil_Pathway"
    },
    {
      "x": -9,
      "y": -9,
      "z": -4,
      "name": "Empty"
    },
    {
      "x": -9,
      "y": -8,
      "z": -4,
      "name": "Empty"
    },
    {
      "x": -9,
      "y": -7,
      "z": -4,
      "name": "Empty"
    },
    {
      "x": -9,
      "y": -6,
      "z": -4,
      "name": "Empty"
    },
    {
      "x": -9,
      "y": -5,
      "z": -4,
      "name": "Empty"
    },
    {
      "x": -9,
      "y": -4,
      "z": -4,
      "name": "Wood_Beech_Trunk",
      "rotation": 5
    },
    {
      "x": -9,
      "y": -3,
      "z": -4,
      "name": "Empty"
    },
    {
      "x": -9,
      "y": -2,
      "z": -4,
      "name": "Empty"
    },
    {
      "x": -9,
      "y": -1,
      "z": -4,
      "name": "Empty"
    },
    {
      "x": -9,
      "y": -10,
      "z": -3,
      "name": "Soil_Pathway"
    },
    {
      "x": -9,
      "y": -9,
      "z": -3,
      "name": "Empty"
    },
    {
      "x": -9,
      "y": -8,
      "z": -3,
      "name": "Empty"
    },
    {
      "x": -9,
      "y": -7,
      "z": -3,
      "name": "Empty"
    },
    {
      "x": -9,
      "y": -6,
      "z": -3,
      "name": "Empty"
    },
    {
      "x": -9,
      "y": -5,
      "z": -3,
      "name": "Empty"
    },
    {
      "x": -9,
      "y": -4,
      "z": -3,
      "name": "Furniture_Crude_Platform",
      "rotation": 1
    },
    {
      "x": -9,
      "y": -3,
      "z": -3,
      "name": "Empty"
    },
    {
      "x": -9,
      "y": -2,
      "z": -3,
      "name": "Empty"
    },
    {
      "x": -9,
      "y": -10,
      "z": -2,
      "name": "Soil_Pathway"
    },
    {
      "x": -9,
      "y": -9,
      "z": -2,
      "name": "Empty"
    },
    {
      "x": -9,
      "y": -8,
      "z": -2,
      "name": "Empty"
    },
    {
      "x": -9,
      "y": -7,
      "z": -2,
      "name": "Empty"
    },
    {
      "x": -9,
      "y": -6,
      "z": -2,
      "name": "Empty"
    },
    {
      "x": -9,
      "y": -5,
      "z": -2,
      "name": "Empty"
    },
    {
      "x": -9,
      "y": -4,
      "z": -2,
      "name": "Furniture_Village_Platform"
    },
    {
      "x": -9,
      "y": -3,
      "z": -2,
      "name": "Empty"
    },
    {
      "x": -9,
      "y": -2,
      "z": -2,
      "name": "Empty"
    },
    {
      "x": -9,
      "y": -1,
      "z": -2,
      "name": "Empty"
    },
    {
      "x": -9,
      "y": -10,
      "z": -1,
      "name": "Soil_Pathway"
    },
    {
      "x": -9,
      "y": -9,
      "z": -1,
      "name": "Empty"
    },
    {
      "x": -9,
      "y": -8,
      "z": -1,
      "name": "Empty"
    },
    {
      "x": -9,
      "y": -7,
      "z": -1,
      "name": "Empty"
    },
    {
      "x": -9,
      "y": -6,
      "z": -1,
      "name": "Empty"
    },
    {
      "x": -9,
      "y": -5,
      "z": -1,
      "name": "Empty"
    },
    {
      "x": -9,
      "y": -4,
      "z": -1,
      "name": "Furniture_Village_Platform"
    },
    {
      "x": -9,
      "y": -3,
      "z": -1,
      "name": "Empty"
    },
    {
      "x": -9,
      "y": -2,
      "z": -1,
      "name": "Empty"
    },
    {
      "x": -9,
      "y": -1,
      "z": -1,
      "name": "Empty"
    },
    {
      "x": -9,
      "y": 0,
      "z": -1,
      "name": "Rock_Stone"
    },
    {
      "x": -9,
      "y": -10,
      "z": 0,
      "name": "Soil_Pathway"
    },
    {
      "x": -9,
      "y": -9,
      "z": 0,
      "name": "Empty"
    },
    {
      "x": -9,
      "y": -8,
      "z": 0,
      "name": "Empty"
    },
    {
      "x": -9,
      "y": -7,
      "z": 0,
      "name": "Empty"
    },
    {
      "x": -9,
      "y": -6,
      "z": 0,
      "name": "Empty"
    },
    {
      "x": -9,
      "y": -5,
      "z": 0,
      "name": "Empty"
    },
    {
      "x": -9,
      "y": -4,
      "z": 0,
      "name": "Wood_Beech_Trunk",
      "rotation": 5
    },
    {
      "x": -9,
      "y": -3,
      "z": 0,
      "name": "Rubble_Stone"
    },
    {
      "x": -9,
      "y": -2,
      "z": 0,
      "name": "Empty"
    },
    {
      "x": -9,
      "y": -1,
      "z": 0,
      "name": "Rock_Stone_Stalactite_Small",
      "rotation": 8
    },
    {
      "x": -9,
      "y": 0,
      "z": 0,
      "name": "Rock_Stone"
    },
    {
      "x": -9,
      "y": -10,
      "z": 1,
      "name": "Soil_Gravel"
    },
    {
      "x": -9,
      "y": -9,
      "z": 1,
      "name": "Empty"
    },
    {
      "x": -9,
      "y": -8,
      "z": 1,
      "name": "Empty"
    },
    {
      "x": -9,
      "y": -7,
      "z": 1,
      "name": "Empty"
    },
    {
      "x": -9,
      "y": -6,
      "z": 1,
      "name": "Empty"
    },
    {
      "x": -9,
      "y": -5,
      "z": 1,
      "name": "Empty"
    },
    {
      "x": -9,
      "y": -4,
      "z": 1,
      "name": "Furniture_Village_Platform"
    },
    {
      "x": -9,
      "y": -3,
      "z": 1,
      "name": "Soil_Gravel_Half"
    },
    {
      "x": -9,
      "y": -2,
      "z": 1,
      "name": "Empty"
    },
    {
      "x": -9,
      "y": -1,
      "z": 1,
      "name": "Empty"
    },
    {
      "x": -9,
      "y": 0,
      "z": 1,
      "name": "Rock_Stone"
    },
    {
      "x": -9,
      "y": -10,
      "z": 2,
      "name": "Soil_Gravel"
    },
    {
      "x": -9,
      "y": -9,
      "z": 2,
      "name": "Soil_Gravel_Half"
    },
    {
      "x": -9,
      "y": -8,
      "z": 2,
      "name": "Empty"
    },
    {
      "x": -9,
      "y": -7,
      "z": 2,
      "name": "Empty"
    },
    {
      "x": -9,
      "y": -6,
      "z": 2,
      "name": "Empty"
    },
    {
      "x": -9,
      "y": -5,
      "z": 2,
      "name": "Empty"
    },
    {
      "x": -9,
      "y": -4,
      "z": 2,
      "name": "Furniture_Crude_Platform",
      "rotation": 1
    },
    {
      "x": -9,
      "y": -3,
      "z": 2,
      "name": "Soil_Gravel_Half"
    },
    {
      "x": -9,
      "y": -2,
      "z": 2,
      "name": "Empty"
    },
    {
      "x": -9,
      "y": -1,
      "z": 2,
      "name": "Empty"
    },
    {
      "x": -9,
      "y": 0,
      "z": 2,
      "name": "Rock_Stone"
    },
    {
      "x": -9,
      "y": -10,
      "z": 3,
      "name": "Rock_Stone"
    },
    {
      "x": -9,
      "y": -9,
      "z": 3,
      "name": "Rock_Stone"
    },
    {
      "x": -9,
      "y": -8,
      "z": 3,
      "name": "Empty"
    },
    {
      "x": -9,
      "y": -7,
      "z": 3,
      "name": "Empty"
    },
    {
      "x": -9,
      "y": -6,
      "z": 3,
      "name": "Empty"
    },
    {
      "x": -9,
      "y": -5,
      "z": 3,
      "name": "Empty"
    },
    {
      "x": -9,
      "y": -4,
      "z": 3,
      "name": "Wood_Beech_Trunk",
      "rotation": 5
    },
    {
      "x": -9,
      "y": -3,
      "z": 3,
      "name": "Soil_Gravel"
    },
    {
      "x": -9,
      "y": -2,
      "z": 3,
      "name": "Empty"
    },
    {
      "x": -9,
      "y": -1,
      "z": 3,
      "name": "Rock_Stone"
    },
    {
      "x": -9,
      "y": 0,
      "z": 3,
      "name": "Rock_Stone"
    },
    {
      "x": -9,
      "y": -10,
      "z": 4,
      "name": "Rock_Stone"
    },
    {
      "x": -9,
      "y": -9,
      "z": 4,
      "name": "Rock_Stone"
    },
    {
      "x": -9,
      "y": -8,
      "z": 4,
      "name": "Rock_Stone"
    },
    {
      "x": -9,
      "y": -7,
      "z": 4,
      "name": "Rock_Stone"
    },
    {
      "x": -9,
      "y": -6,
      "z": 4,
      "name": "Rock_Stone"
    },
    {
      "x": -9,
      "y": -5,
      "z": 4,
      "name": "Rock_Stone"
    },
    {
      "x": -9,
      "y": -4,
      "z": 4,
      "name": "Rock_Stone"
    },
    {
      "x": -9,
      "y": -3,
      "z": 4,
      "name": "Rock_Stone"
    },
    {
      "x": -9,
      "y": -2,
      "z": 4,
      "name": "Rock_Stone"
    },
    {
      "x": -9,
      "y": -1,
      "z": 4,
      "name": "Rock_Stone"
    },
    {
      "x": -9,
      "y": 0,
      "z": 4,
      "name": "Rock_Stone"
    },
    {
      "x": -9,
      "y": -8,
      "z": 5,
      "name": "Rock_Stone"
    },
    {
      "x": -9,
      "y": -7,
      "z": 5,
      "name": "Rock_Stone"
    },
    {
      "x": -9,
      "y": -6,
      "z": 5,
      "name": "Rock_Stone"
    },
    {
      "x": -9,
      "y": -5,
      "z": 5,
      "name": "Rock_Stone"
    },
    {
      "x": -9,
      "y": -4,
      "z": 5,
      "name": "Rock_Stone"
    },
    {
      "x": -9,
      "y": -3,
      "z": 5,
      "name": "Rock_Stone"
    },
    {
      "x": -9,
      "y": -2,
      "z": 5,
      "name": "Rock_Stone"
    },
    {
      "x": -9,
      "y": -7,
      "z": 6,
      "name": "Rock_Stone"
    },
    {
      "x": -8,
      "y": -9,
      "z": -11,
      "name": "Rock_Stone"
    },
    {
      "x": -8,
      "y": -8,
      "z": -11,
      "name": "Rock_Stone"
    },
    {
      "x": -8,
      "y": -7,
      "z": -11,
      "name": "Rock_Stone"
    },
    {
      "x": -8,
      "y": -6,
      "z": -11,
      "name": "Rock_Stone"
    },
    {
      "x": -8,
      "y": -5,
      "z": -11,
      "name": "Rock_Stone"
    },
    {
      "x": -8,
      "y": -10,
      "z": -10,
      "name": "Rock_Stone"
    },
    {
      "x": -8,
      "y": -9,
      "z": -10,
      "name": "Rock_Stone_Cobble"
    },
    {
      "x": -8,
      "y": -8,
      "z": -10,
      "name": "Rock_Stone_Brick"
    },
    {
      "x": -8,
      "y": -7,
      "z": -10,
      "name": "Wood_Softwood_Fence",
      "rotation": 1
    },
    {
      "x": -8,
      "y": -6,
      "z": -10,
      "name": "Empty"
    },
    {
      "x": -8,
      "y": -5,
      "z": -10,
      "name": "Empty"
    },
    {
      "x": -8,
      "y": -4,
      "z": -10,
      "name": "Wood_Softwood_Planks_Half",
      "rotation": 8
    },
    {
      "x": -8,
      "y": -3,
      "z": -10,
      "name": "Empty"
    },
    {
      "x": -8,
      "y": -2,
      "z": -10,
      "name": "Empty"
    },
    {
      "x": -8,
      "y": -1,
      "z": -10,
      "name": "Empty"
    },
    {
      "x": -8,
      "y": -10,
      "z": -9,
      "name": "Rock_Stone"
    },
    {
      "x": -8,
      "y": -9,
      "z": -9,
      "name": "Rock_Stone_Cobble"
    },
    {
      "x": -8,
      "y": -8,
      "z": -9,
      "name": "Rock_Stone_Brick"
    },
    {
      "x": -8,
      "y": -7,
      "z": -9,
      "name": "Wood_Softwood_Fence",
      "rotation": 1
    },
    {
      "x": -8,
      "y": -6,
      "z": -9,
      "name": "Empty"
    },
    {
      "x": -8,
      "y": -5,
      "z": -9,
      "name": "Empty"
    },
    {
      "x": -8,
      "y": -4,
      "z": -9,
      "name": "Wood_Softwood_Planks_Half",
      "rotation": 8
    },
    {
      "x": -8,
      "y": -3,
      "z": -9,
      "name": "Empty"
    },
    {
      "x": -8,
      "y": -2,
      "z": -9,
      "name": "Empty"
    },
    {
      "x": -8,
      "y": -1,
      "z": -9,
      "name": "Empty"
    },
    {
      "x": -8,
      "y": -10,
      "z": -8,
      "name": "Rock_Stone"
    },
    {
      "x": -8,
      "y": -9,
      "z": -8,
      "name": "Rock_Stone_Brick"
    },
    {
      "x": -8,
      "y": -8,
      "z": -8,
      "name": "Rock_Stone_Brick"
    },
    {
      "x": -8,
      "y": -7,
      "z": -8,
      "name": "Wood_Softwood_Fence",
      "rotation": 1
    },
    {
      "x": -8,
      "y": -6,
      "z": -8,
      "name": "Empty"
    },
    {
      "x": -8,
      "y": -5,
      "z": -8,
      "name": "Empty"
    },
    {
      "x": -8,
      "y": -4,
      "z": -8,
      "name": "Wood_Softwood_Planks_Half",
      "rotation": 8
    },
    {
      "x": -8,
      "y": -3,
      "z": -8,
      "name": "Empty"
    },
    {
      "x": -8,
      "y": -2,
      "z": -8,
      "name": "Empty"
    },
    {
      "x": -8,
      "y": -1,
      "z": -8,
      "name": "Empty"
    },
    {
      "x": -8,
      "y": 0,
      "z": -8,
      "name": "Rock_Stone"
    },
    {
      "x": -8,
      "y": -10,
      "z": -7,
      "name": "Rock_Stone"
    },
    {
      "x": -8,
      "y": -9,
      "z": -7,
      "name": "Rock_Stone_Brick"
    },
    {
      "x": -8,
      "y": -8,
      "z": -7,
      "name": "Rock_Stone_Brick"
    },
    {
      "x": -8,
      "y": -7,
      "z": -7,
      "name": "Wood_Softwood_Fence",
      "rotation": 1
    },
    {
      "x": -8,
      "y": -6,
      "z": -7,
      "name": "Empty"
    },
    {
      "x": -8,
      "y": -5,
      "z": -7,
      "name": "Empty"
    },
    {
      "x": -8,
      "y": -4,
      "z": -7,
      "name": "Wood_Softwood_Planks_Half",
      "rotation": 8
    },
    {
      "x": -8,
      "y": -3,
      "z": -7,
      "name": "Empty"
    },
    {
      "x": -8,
      "y": -2,
      "z": -7,
      "name": "Empty"
    },
    {
      "x": -8,
      "y": -1,
      "z": -7,
      "name": "Empty"
    },
    {
      "x": -8,
      "y": 0,
      "z": -7,
      "name": "Rock_Stone"
    },
    {
      "x": -8,
      "y": -10,
      "z": -6,
      "name": "Soil_Pathway"
    },
    {
      "x": -8,
      "y": -9,
      "z": -6,
      "name": "Empty"
    },
    {
      "x": -8,
      "y": -8,
      "z": -6,
      "name": "Empty"
    },
    {
      "x": -8,
      "y": -7,
      "z": -6,
      "name": "Empty"
    },
    {
      "x": -8,
      "y": -6,
      "z": -6,
      "name": "Empty"
    },
    {
      "x": -8,
      "y": -5,
      "z": -6,
      "name": "Empty"
    },
    {
      "x": -8,
      "y": -4,
      "z": -6,
      "name": "Wood_Softwood_Planks_Half",
      "rotation": 8
    },
    {
      "x": -8,
      "y": -3,
      "z": -6,
      "name": "Empty"
    },
    {
      "x": -8,
      "y": -2,
      "z": -6,
      "name": "Empty"
    },
    {
      "x": -8,
      "y": -1,
      "z": -6,
      "name": "Empty"
    },
    {
      "x": -8,
      "y": 0,
      "z": -6,
      "name": "Rock_Stone"
    },
    {
      "x": -8,
      "y": -10,
      "z": -5,
      "name": "Soil_Pathway"
    },
    {
      "x": -8,
      "y": -9,
      "z": -5,
      "name": "Empty"
    },
    {
      "x": -8,
      "y": -8,
      "z": -5,
      "name": "Empty"
    },
    {
      "x": -8,
      "y": -7,
      "z": -5,
      "name": "Empty"
    },
    {
      "x": -8,
      "y": -6,
      "z": -5,
      "name": "Empty"
    },
    {
      "x": -8,
      "y": -5,
      "z": -5,
      "name": "Empty"
    },
    {
      "x": -8,
      "y": -4,
      "z": -5,
      "name": "Wood_Softwood_Planks_Half",
      "rotation": 8
    },
    {
      "x": -8,
      "y": -3,
      "z": -5,
      "name": "Empty"
    },
    {
      "x": -8,
      "y": -2,
      "z": -5,
      "name": "Empty"
    },
    {
      "x": -8,
      "y": -1,
      "z": -5,
      "name": "Empty"
    },
    {
      "x": -8,
      "y": 0,
      "z": -5,
      "name": "Rock_Stone"
    },
    {
      "x": -8,
      "y": -10,
      "z": -4,
      "name": "Soil_Pathway"
    },
    {
      "x": -8,
      "y": -9,
      "z": -4,
      "name": "Empty"
    },
    {
      "x": -8,
      "y": -8,
      "z": -4,
      "name": "Empty"
    },
    {
      "x": -8,
      "y": -7,
      "z": -4,
      "name": "Empty"
    },
    {
      "x": -8,
      "y": -6,
      "z": -4,
      "name": "Empty"
    },
    {
      "x": -8,
      "y": -5,
      "z": -4,
      "name": "Empty"
    },
    {
      "x": -8,
      "y": -4,
      "z": -4,
      "name": "Wood_Beech_Trunk",
      "rotation": 5
    },
    {
      "x": -8,
      "y": -3,
      "z": -4,
      "name": "Empty"
    },
    {
      "x": -8,
      "y": -2,
      "z": -4,
      "name": "Empty"
    },
    {
      "x": -8,
      "y": -1,
      "z": -4,
      "name": "Rock_Stone"
    },
    {
      "x": -8,
      "y": -10,
      "z": -3,
      "name": "Soil_Pathway"
    },
    {
      "x": -8,
      "y": -9,
      "z": -3,
      "name": "Empty"
    },
    {
      "x": -8,
      "y": -8,
      "z": -3,
      "name": "Empty"
    },
    {
      "x": -8,
      "y": -7,
      "z": -3,
      "name": "Empty"
    },
    {
      "x": -8,
      "y": -6,
      "z": -3,
      "name": "Empty"
    },
    {
      "x": -8,
      "y": -5,
      "z": -3,
      "name": "Empty"
    },
    {
      "x": -8,
      "y": -4,
      "z": -3,
      "name": "Furniture_Crude_Platform",
      "rotation": 1
    },
    {
      "x": -8,
      "y": -3,
      "z": -3,
      "name": "Rubble_Stone"
    },
    {
      "x": -8,
      "y": -2,
      "z": -3,
      "name": "Rock_Stone_Stalactite_Small",
      "rotation": 8
    },
    {
      "x": -8,
      "y": -1,
      "z": -3,
      "name": "Rock_Stone"
    },
    {
      "x": -8,
      "y": -10,
      "z": -2,
      "name": "Soil_Pathway"
    },
    {
      "x": -8,
      "y": -9,
      "z": -2,
      "name": "Empty"
    },
    {
      "x": -8,
      "y": -8,
      "z": -2,
      "name": "Empty"
    },
    {
      "x": -8,
      "y": -7,
      "z": -2,
      "name": "Empty"
    },
    {
      "x": -8,
      "y": -6,
      "z": -2,
      "name": "Empty"
    },
    {
      "x": -8,
      "y": -5,
      "z": -2,
      "name": "Empty"
    },
    {
      "x": -8,
      "y": -4,
      "z": -2,
      "name": "Furniture_Crude_Platform",
      "rotation": 1
    },
    {
      "x": -8,
      "y": -3,
      "z": -2,
      "name": "Empty"
    },
    {
      "x": -8,
      "y": -2,
      "z": -2,
      "name": "Empty"
    },
    {
      "x": -8,
      "y": -1,
      "z": -2,
      "name": "Empty"
    },
    {
      "x": -8,
      "y": -10,
      "z": -1,
      "name": "Soil_Pathway"
    },
    {
      "x": -8,
      "y": -9,
      "z": -1,
      "name": "Empty"
    },
    {
      "x": -8,
      "y": -8,
      "z": -1,
      "name": "Empty"
    },
    {
      "x": -8,
      "y": -7,
      "z": -1,
      "name": "Empty"
    },
    {
      "x": -8,
      "y": -6,
      "z": -1,
      "name": "Empty"
    },
    {
      "x": -8,
      "y": -5,
      "z": -1,
      "name": "Empty"
    },
    {
      "x": -8,
      "y": -4,
      "z": -1,
      "name": "Furniture_Crude_Platform",
      "rotation": 1
    },
    {
      "x": -8,
      "y": -3,
      "z": -1,
      "name": "Empty"
    },
    {
      "x": -8,
      "y": -2,
      "z": -1,
      "name": "Empty"
    },
    {
      "x": -8,
      "y": -1,
      "z": -1,
      "name": "Empty"
    },
    {
      "x": -8,
      "y": 0,
      "z": -1,
      "name": "Rock_Stone"
    },
    {
      "x": -8,
      "y": -10,
      "z": 0,
      "name": "Soil_Pathway"
    },
    {
      "x": -8,
      "y": -9,
      "z": 0,
      "name": "Empty"
    },
    {
      "x": -8,
      "y": -8,
      "z": 0,
      "name": "Empty"
    },
    {
      "x": -8,
      "y": -7,
      "z": 0,
      "name": "Empty"
    },
    {
      "x": -8,
      "y": -6,
      "z": 0,
      "name": "Empty"
    },
    {
      "x": -8,
      "y": -5,
      "z": 0,
      "name": "Empty"
    },
    {
      "x": -8,
      "y": -4,
      "z": 0,
      "name": "Wood_Beech_Trunk",
      "rotation": 5
    },
    {
      "x": -8,
      "y": -3,
      "z": 0,
      "name": "Empty"
    },
    {
      "x": -8,
      "y": -2,
      "z": 0,
      "name": "Empty"
    },
    {
      "x": -8,
      "y": -1,
      "z": 0,
      "name": "Empty"
    },
    {
      "x": -8,
      "y": 0,
      "z": 0,
      "name": "Rock_Stone"
    },
    {
      "x": -8,
      "y": -10,
      "z": 1,
      "name": "Soil_Pathway"
    },
    {
      "x": -8,
      "y": -9,
      "z": 1,
      "name": "Empty"
    },
    {
      "x": -8,
      "y": -8,
      "z": 1,
      "name": "Empty"
    },
    {
      "x": -8,
      "y": -7,
      "z": 1,
      "name": "Empty"
    },
    {
      "x": -8,
      "y": -6,
      "z": 1,
      "name": "Empty"
    },
    {
      "x": -8,
      "y": -5,
      "z": 1,
      "name": "Empty"
    },
    {
      "x": -8,
      "y": -4,
      "z": 1,
      "name": "Furniture_Village_Platform"
    },
    {
      "x": -8,
      "y": -3,
      "z": 1,
      "name": "Soil_Gravel_Half"
    },
    {
      "x": -8,
      "y": -2,
      "z": 1,
      "name": "Empty"
    },
    {
      "x": -8,
      "y": -1,
      "z": 1,
      "name": "Empty"
    },
    {
      "x": -8,
      "y": 0,
      "z": 1,
      "name": "Rock_Stone"
    },
    {
      "x": -8,
      "y": -10,
      "z": 2,
      "name": "Rock_Stone"
    },
    {
      "x": -8,
      "y": -9,
      "z": 2,
      "name": "Empty"
    },
    {
      "x": -8,
      "y": -8,
      "z": 2,
      "name": "Empty"
    },
    {
      "x": -8,
      "y": -7,
      "z": 2,
      "name": "Empty"
    },
    {
      "x": -8,
      "y": -6,
      "z": 2,
      "name": "Empty"
    },
    {
      "x": -8,
      "y": -5,
      "z": 2,
      "name": "Empty"
    },
    {
      "x": -8,
      "y": -4,
      "z": 2,
      "name": "Furniture_Village_Platform"
    },
    {
      "x": -8,
      "y": -3,
      "z": 2,
      "name": "Soil_Gravel"
    },
    {
      "x": -8,
      "y": -2,
      "z": 2,
      "name": "Rubble_Stone"
    },
    {
      "x": -8,
      "y": -1,
      "z": 2,
      "name": "Rock_Stone"
    },
    {
      "x": -8,
      "y": 0,
      "z": 2,
      "name": "Rock_Stone"
    },
    {
      "x": -8,
      "y": -10,
      "z": 3,
      "name": "Rock_Stone"
    },
    {
      "x": -8,
      "y": -9,
      "z": 3,
      "name": "Empty"
    },
    {
      "x": -8,
      "y": -8,
      "z": 3,
      "name": "Empty"
    },
    {
      "x": -8,
      "y": -7,
      "z": 3,
      "name": "Empty"
    },
    {
      "x": -8,
      "y": -6,
      "z": 3,
      "name": "Empty"
    },
    {
      "x": -8,
      "y": -5,
      "z": 3,
      "name": "Empty"
    },
    {
      "x": -8,
      "y": -4,
      "z": 3,
      "name": "Wood_Beech_Trunk",
      "rotation": 5
    },
    {
      "x": -8,
      "y": -3,
      "z": 3,
      "name": "Soil_Gravel"
    },
    {
      "x": -8,
      "y": -2,
      "z": 3,
      "name": "Empty"
    },
    {
      "x": -8,
      "y": -1,
      "z": 3,
      "name": "Rock_Stone"
    },
    {
      "x": -8,
      "y": 0,
      "z": 3,
      "name": "Rock_Stone"
    },
    {
      "x": -8,
      "y": -10,
      "z": 4,
      "name": "Rock_Stone"
    },
    {
      "x": -8,
      "y": -9,
      "z": 4,
      "name": "Rock_Stone"
    },
    {
      "x": -8,
      "y": -8,
      "z": 4,
      "name": "Rock_Stone"
    },
    {
      "x": -8,
      "y": -7,
      "z": 4,
      "name": "Rock_Stone"
    },
    {
      "x": -8,
      "y": -6,
      "z": 4,
      "name": "Rock_Stone"
    },
    {
      "x": -8,
      "y": -5,
      "z": 4,
      "name": "Rock_Stone"
    },
    {
      "x": -8,
      "y": -4,
      "z": 4,
      "name": "Rock_Stone"
    },
    {
      "x": -8,
      "y": -3,
      "z": 4,
      "name": "Rock_Stone"
    },
    {
      "x": -8,
      "y": -2,
      "z": 4,
      "name": "Rock_Stone"
    },
    {
      "x": -8,
      "y": -1,
      "z": 4,
      "name": "Rock_Stone"
    },
    {
      "x": -8,
      "y": 0,
      "z": 4,
      "name": "Rock_Stone"
    },
    {
      "x": -8,
      "y": -9,
      "z": 5,
      "name": "Rock_Stone"
    },
    {
      "x": -8,
      "y": -8,
      "z": 5,
      "name": "Rock_Stone"
    },
    {
      "x": -8,
      "y": -7,
      "z": 5,
      "name": "Rock_Stone"
    },
    {
      "x": -8,
      "y": -6,
      "z": 5,
      "name": "Rock_Stone"
    },
    {
      "x": -8,
      "y": -5,
      "z": 5,
      "name": "Rock_Stone"
    },
    {
      "x": -8,
      "y": -4,
      "z": 5,
      "name": "Rock_Stone"
    },
    {
      "x": -8,
      "y": -3,
      "z": 5,
      "name": "Rock_Stone"
    },
    {
      "x": -8,
      "y": -2,
      "z": 5,
      "name": "Rock_Stone"
    },
    {
      "x": -8,
      "y": -8,
      "z": 6,
      "name": "Rock_Stone"
    },
    {
      "x": -8,
      "y": -7,
      "z": 6,
      "name": "Rock_Stone"
    },
    {
      "x": -8,
      "y": -6,
      "z": 6,
      "name": "Rock_Stone"
    },
    {
      "x": -8,
      "y": -5,
      "z": 6,
      "name": "Rock_Stone"
    },
    {
      "x": -8,
      "y": -4,
      "z": 6,
      "name": "Rock_Stone"
    },
    {
      "x": -8,
      "y": -3,
      "z": 6,
      "name": "Rock_Stone"
    },
    {
      "x": -7,
      "y": -9,
      "z": -11,
      "name": "Rock_Stone"
    },
    {
      "x": -7,
      "y": -8,
      "z": -11,
      "name": "Rock_Stone"
    },
    {
      "x": -7,
      "y": -7,
      "z": -11,
      "name": "Rock_Stone"
    },
    {
      "x": -7,
      "y": -6,
      "z": -11,
      "name": "Rock_Stone"
    },
    {
      "x": -7,
      "y": -5,
      "z": -11,
      "name": "Rock_Stone"
    },
    {
      "x": -7,
      "y": -10,
      "z": -10,
      "name": "Rock_Stone"
    },
    {
      "x": -7,
      "y": -9,
      "z": -10,
      "name": "Furniture_Village_Ladder",
      "rotation": 1
    },
    {
      "x": -7,
      "y": -8,
      "z": -10,
      "name": "Furniture_Village_Ladder",
      "rotation": 1
    },
    {
      "x": -7,
      "y": -7,
      "z": -10,
      "name": "Furniture_Village_Ladder",
      "rotation": 1
    },
    {
      "x": -7,
      "y": -6,
      "z": -10,
      "name": "Furniture_Village_Ladder",
      "rotation": 1
    },
    {
      "x": -7,
      "y": -5,
      "z": -10,
      "name": "Furniture_Village_Ladder",
      "rotation": 1
    },
    {
      "x": -7,
      "y": -4,
      "z": -10,
      "name": "Furniture_Village_Ladder",
      "rotation": 1
    },
    {
      "x": -7,
      "y": -3,
      "z": -10,
      "name": "Empty"
    },
    {
      "x": -7,
      "y": -2,
      "z": -10,
      "name": "Empty"
    },
    {
      "x": -7,
      "y": -1,
      "z": -10,
      "name": "Empty"
    },
    {
      "x": -7,
      "y": -10,
      "z": -9,
      "name": "Rock_Stone"
    },
    {
      "x": -7,
      "y": -9,
      "z": -9,
      "name": "Empty"
    },
    {
      "x": -7,
      "y": -8,
      "z": -9,
      "name": "Empty"
    },
    {
      "x": -7,
      "y": -7,
      "z": -9,
      "name": "Empty"
    },
    {
      "x": -7,
      "y": -6,
      "z": -9,
      "name": "Empty"
    },
    {
      "x": -7,
      "y": -5,
      "z": -9,
      "name": "Empty"
    },
    {
      "x": -7,
      "y": -4,
      "z": -9,
      "name": "Empty"
    },
    {
      "x": -7,
      "y": -3,
      "z": -9,
      "name": "Empty"
    },
    {
      "x": -7,
      "y": -2,
      "z": -9,
      "name": "Empty"
    },
    {
      "x": -7,
      "y": -10,
      "z": -8,
      "name": "Rock_Stone"
    },
    {
      "x": -7,
      "y": -9,
      "z": -8,
      "name": "Wood_Softwood_Beam"
    },
    {
      "x": -7,
      "y": -8,
      "z": -8,
      "name": "*Furniture_Crude_Torch_State_Definitions_Off"
    },
    {
      "x": -7,
      "y": -7,
      "z": -8,
      "name": "Empty"
    },
    {
      "x": -7,
      "y": -6,
      "z": -8,
      "name": "Empty"
    },
    {
      "x": -7,
      "y": -5,
      "z": -8,
      "name": "Empty"
    },
    {
      "x": -7,
      "y": -4,
      "z": -8,
      "name": "Empty"
    },
    {
      "x": -7,
      "y": -3,
      "z": -8,
      "name": "Empty"
    },
    {
      "x": -7,
      "y": -2,
      "z": -8,
      "name": "Empty"
    },
    {
      "x": -7,
      "y": -1,
      "z": -8,
      "name": "Rock_Stone"
    },
    {
      "x": -7,
      "y": 0,
      "z": -8,
      "name": "Rock_Stone"
    },
    {
      "x": -7,
      "y": -10,
      "z": -7,
      "name": "Soil_Pathway"
    },
    {
      "x": -7,
      "y": -9,
      "z": -7,
      "name": "Empty"
    },
    {
      "x": -7,
      "y": -8,
      "z": -7,
      "name": "Empty"
    },
    {
      "x": -7,
      "y": -7,
      "z": -7,
      "name": "Empty"
    },
    {
      "x": -7,
      "y": -6,
      "z": -7,
      "name": "Empty"
    },
    {
      "x": -7,
      "y": -5,
      "z": -7,
      "name": "Empty"
    },
    {
      "x": -7,
      "y": -4,
      "z": -7,
      "name": "Rock_Stone"
    },
    {
      "x": -7,
      "y": -3,
      "z": -7,
      "name": "Rock_Stone"
    },
    {
      "x": -7,
      "y": -2,
      "z": -7,
      "name": "Rock_Stone"
    },
    {
      "x": -7,
      "y": -1,
      "z": -7,
      "name": "Rock_Stone"
    },
    {
      "x": -7,
      "y": 0,
      "z": -7,
      "name": "Rock_Stone"
    },
    {
      "x": -7,
      "y": -10,
      "z": -6,
      "name": "Soil_Pathway"
    },
    {
      "x": -7,
      "y": -9,
      "z": -6,
      "name": "Empty"
    },
    {
      "x": -7,
      "y": -8,
      "z": -6,
      "name": "Empty"
    },
    {
      "x": -7,
      "y": -7,
      "z": -6,
      "name": "Empty"
    },
    {
      "x": -7,
      "y": -6,
      "z": -6,
      "name": "Empty"
    },
    {
      "x": -7,
      "y": -5,
      "z": -6,
      "name": "Empty"
    },
    {
      "x": -7,
      "y": -4,
      "z": -6,
      "name": "Rock_Stone"
    },
    {
      "x": -7,
      "y": -3,
      "z": -6,
      "name": "Rock_Stone"
    },
    {
      "x": -7,
      "y": -2,
      "z": -6,
      "name": "Rock_Stone"
    },
    {
      "x": -7,
      "y": -1,
      "z": -6,
      "name": "Rock_Stone"
    },
    {
      "x": -7,
      "y": 0,
      "z": -6,
      "name": "Rock_Stone"
    },
    {
      "x": -7,
      "y": -10,
      "z": -5,
      "name": "Soil_Pathway"
    },
    {
      "x": -7,
      "y": -9,
      "z": -5,
      "name": "Empty"
    },
    {
      "x": -7,
      "y": -8,
      "z": -5,
      "name": "Empty"
    },
    {
      "x": -7,
      "y": -7,
      "z": -5,
      "name": "Empty"
    },
    {
      "x": -7,
      "y": -6,
      "z": -5,
      "name": "Empty"
    },
    {
      "x": -7,
      "y": -5,
      "z": -5,
      "name": "Rock_Stone"
    },
    {
      "x": -7,
      "y": -4,
      "z": -5,
      "name": "Rock_Stone"
    },
    {
      "x": -7,
      "y": -3,
      "z": -5,
      "name": "Rock_Stone"
    },
    {
      "x": -7,
      "y": -2,
      "z": -5,
      "name": "Rock_Stone"
    },
    {
      "x": -7,
      "y": -1,
      "z": -5,
      "name": "Rock_Stone"
    },
    {
      "x": -7,
      "y": 0,
      "z": -5,
      "name": "Rock_Stone"
    },
    {
      "x": -7,
      "y": -10,
      "z": -4,
      "name": "Soil_Pathway"
    },
    {
      "x": -7,
      "y": -9,
      "z": -4,
      "name": "Empty"
    },
    {
      "x": -7,
      "y": -8,
      "z": -4,
      "name": "Empty"
    },
    {
      "x": -7,
      "y": -7,
      "z": -4,
      "name": "Empty"
    },
    {
      "x": -7,
      "y": -6,
      "z": -4,
      "name": "Empty"
    },
    {
      "x": -7,
      "y": -5,
      "z": -4,
      "name": "Rock_Stone"
    },
    {
      "x": -7,
      "y": -4,
      "z": -4,
      "name": "Rock_Stone"
    },
    {
      "x": -7,
      "y": -3,
      "z": -4,
      "name": "Rock_Stone"
    },
    {
      "x": -7,
      "y": -2,
      "z": -4,
      "name": "Rock_Stone"
    },
    {
      "x": -7,
      "y": -1,
      "z": -4,
      "name": "Rock_Stone"
    },
    {
      "x": -7,
      "y": -10,
      "z": -3,
      "name": "Soil_Pathway"
    },
    {
      "x": -7,
      "y": -9,
      "z": -3,
      "name": "Empty"
    },
    {
      "x": -7,
      "y": -8,
      "z": -3,
      "name": "Empty"
    },
    {
      "x": -7,
      "y": -7,
      "z": -3,
      "name": "Empty"
    },
    {
      "x": -7,
      "y": -6,
      "z": -3,
      "name": "Rock_Stone"
    },
    {
      "x": -7,
      "y": -5,
      "z": -3,
      "name": "Rock_Stone"
    },
    {
      "x": -7,
      "y": -4,
      "z": -3,
      "name": "Rock_Stone"
    },
    {
      "x": -7,
      "y": -3,
      "z": -3,
      "name": "Rock_Stone"
    },
    {
      "x": -7,
      "y": -2,
      "z": -3,
      "name": "Rock_Stone"
    },
    {
      "x": -7,
      "y": -1,
      "z": -3,
      "name": "Rock_Stone"
    },
    {
      "x": -7,
      "y": -10,
      "z": -2,
      "name": "Soil_Pathway"
    },
    {
      "x": -7,
      "y": -9,
      "z": -2,
      "name": "Empty"
    },
    {
      "x": -7,
      "y": -8,
      "z": -2,
      "name": "Empty"
    },
    {
      "x": -7,
      "y": -7,
      "z": -2,
      "name": "Empty"
    },
    {
      "x": -7,
      "y": -6,
      "z": -2,
      "name": "Empty"
    },
    {
      "x": -7,
      "y": -5,
      "z": -2,
      "name": "Empty"
    },
    {
      "x": -7,
      "y": -4,
      "z": -2,
      "name": "Rock_Stone"
    },
    {
      "x": -7,
      "y": -3,
      "z": -2,
      "name": "Rock_Stone"
    },
    {
      "x": -7,
      "y": -2,
      "z": -2,
      "name": "Rock_Stone"
    },
    {
      "x": -7,
      "y": -1,
      "z": -2,
      "name": "Rock_Stone"
    },
    {
      "x": -7,
      "y": 0,
      "z": -2,
      "name": "Rock_Stone"
    },
    {
      "x": -7,
      "y": -10,
      "z": -1,
      "name": "Soil_Pathway"
    },
    {
      "x": -7,
      "y": -9,
      "z": -1,
      "name": "Empty"
    },
    {
      "x": -7,
      "y": -8,
      "z": -1,
      "name": "Empty"
    },
    {
      "x": -7,
      "y": -7,
      "z": -1,
      "name": "Empty"
    },
    {
      "x": -7,
      "y": -6,
      "z": -1,
      "name": "Empty"
    },
    {
      "x": -7,
      "y": -5,
      "z": -1,
      "name": "Empty"
    },
    {
      "x": -7,
      "y": -4,
      "z": -1,
      "name": "Rock_Stone"
    },
    {
      "x": -7,
      "y": -3,
      "z": -1,
      "name": "Rock_Stone"
    },
    {
      "x": -7,
      "y": -2,
      "z": -1,
      "name": "Rock_Stone"
    },
    {
      "x": -7,
      "y": -1,
      "z": -1,
      "name": "Rock_Stone"
    },
    {
      "x": -7,
      "y": 0,
      "z": -1,
      "name": "Rock_Stone"
    },
    {
      "x": -7,
      "y": -10,
      "z": 0,
      "name": "Soil_Pathway"
    },
    {
      "x": -7,
      "y": -9,
      "z": 0,
      "name": "Empty"
    },
    {
      "x": -7,
      "y": -8,
      "z": 0,
      "name": "Empty"
    },
    {
      "x": -7,
      "y": -7,
      "z": 0,
      "name": "Empty"
    },
    {
      "x": -7,
      "y": -6,
      "z": 0,
      "name": "Empty"
    },
    {
      "x": -7,
      "y": -5,
      "z": 0,
      "name": "Empty"
    },
    {
      "x": -7,
      "y": -4,
      "z": 0,
      "name": "Rock_Stone"
    },
    {
      "x": -7,
      "y": -3,
      "z": 0,
      "name": "Rock_Stone"
    },
    {
      "x": -7,
      "y": -2,
      "z": 0,
      "name": "Rock_Stone"
    },
    {
      "x": -7,
      "y": -1,
      "z": 0,
      "name": "Rock_Stone"
    },
    {
      "x": -7,
      "y": 0,
      "z": 0,
      "name": "Rock_Stone"
    },
    {
      "x": -7,
      "y": -10,
      "z": 1,
      "name": "Soil_Pathway"
    },
    {
      "x": -7,
      "y": -9,
      "z": 1,
      "name": "Empty"
    },
    {
      "x": -7,
      "y": -8,
      "z": 1,
      "name": "Empty"
    },
    {
      "x": -7,
      "y": -7,
      "z": 1,
      "name": "Empty"
    },
    {
      "x": -7,
      "y": -6,
      "z": 1,
      "name": "Empty"
    },
    {
      "x": -7,
      "y": -5,
      "z": 1,
      "name": "Empty"
    },
    {
      "x": -7,
      "y": -4,
      "z": 1,
      "name": "Rock_Stone"
    },
    {
      "x": -7,
      "y": -3,
      "z": 1,
      "name": "Rock_Stone"
    },
    {
      "x": -7,
      "y": -2,
      "z": 1,
      "name": "Rock_Stone"
    },
    {
      "x": -7,
      "y": -1,
      "z": 1,
      "name": "Rock_Stone"
    },
    {
      "x": -7,
      "y": 0,
      "z": 1,
      "name": "Rock_Stone"
    },
    {
      "x": -7,
      "y": -10,
      "z": 2,
      "name": "Rock_Stone"
    },
    {
      "x": -7,
      "y": -9,
      "z": 2,
      "name": "Empty"
    },
    {
      "x": -7,
      "y": -8,
      "z": 2,
      "name": "Empty"
    },
    {
      "x": -7,
      "y": -7,
      "z": 2,
      "name": "Empty"
    },
    {
      "x": -7,
      "y": -6,
      "z": 2,
      "name": "Empty"
    },
    {
      "x": -7,
      "y": -5,
      "z": 2,
      "name": "Empty"
    },
    {
      "x": -7,
      "y": -4,
      "z": 2,
      "name": "Rock_Stone"
    },
    {
      "x": -7,
      "y": -3,
      "z": 2,
      "name": "Rock_Stone"
    },
    {
      "x": -7,
      "y": -2,
      "z": 2,
      "name": "Rock_Stone"
    },
    {
      "x": -7,
      "y": -1,
      "z": 2,
      "name": "Rock_Stone"
    },
    {
      "x": -7,
      "y": 0,
      "z": 2,
      "name": "Rock_Stone"
    },
    {
      "x": -7,
      "y": -10,
      "z": 3,
      "name": "Rock_Stone"
    },
    {
      "x": -7,
      "y": -9,
      "z": 3,
      "name": "Empty"
    },
    {
      "x": -7,
      "y": -8,
      "z": 3,
      "name": "Empty"
    },
    {
      "x": -7,
      "y": -7,
      "z": 3,
      "name": "Empty"
    },
    {
      "x": -7,
      "y": -6,
      "z": 3,
      "name": "Rock_Stone"
    },
    {
      "x": -7,
      "y": -5,
      "z": 3,
      "name": "Rock_Stone"
    },
    {
      "x": -7,
      "y": -4,
      "z": 3,
      "name": "Rock_Stone"
    },
    {
      "x": -7,
      "y": -3,
      "z": 3,
      "name": "Rock_Stone"
    },
    {
      "x": -7,
      "y": -2,
      "z": 3,
      "name": "Rock_Stone"
    },
    {
      "x": -7,
      "y": -1,
      "z": 3,
      "name": "Rock_Stone"
    },
    {
      "x": -7,
      "y": 0,
      "z": 3,
      "name": "Rock_Stone"
    },
    {
      "x": -7,
      "y": -10,
      "z": 4,
      "name": "Rock_Stone"
    },
    {
      "x": -7,
      "y": -9,
      "z": 4,
      "name": "Rock_Stone"
    },
    {
      "x": -7,
      "y": -8,
      "z": 4,
      "name": "Rock_Stone"
    },
    {
      "x": -7,
      "y": -7,
      "z": 4,
      "name": "Rock_Stone"
    },
    {
      "x": -7,
      "y": -6,
      "z": 4,
      "name": "Rock_Stone"
    },
    {
      "x": -7,
      "y": -5,
      "z": 4,
      "name": "Rock_Stone"
    },
    {
      "x": -7,
      "y": -4,
      "z": 4,
      "name": "Rock_Stone"
    },
    {
      "x": -7,
      "y": -3,
      "z": 4,
      "name": "Rock_Stone"
    },
    {
      "x": -7,
      "y": -2,
      "z": 4,
      "name": "Rock_Stone"
    },
    {
      "x": -7,
      "y": -1,
      "z": 4,
      "name": "Rock_Stone"
    },
    {
      "x": -7,
      "y": 0,
      "z": 4,
      "name": "Rock_Stone"
    },
    {
      "x": -7,
      "y": -9,
      "z": 5,
      "name": "Rock_Stone"
    },
    {
      "x": -7,
      "y": -8,
      "z": 5,
      "name": "Rock_Stone"
    },
    {
      "x": -7,
      "y": -7,
      "z": 5,
      "name": "Rock_Stone"
    },
    {
      "x": -7,
      "y": -6,
      "z": 5,
      "name": "Rock_Stone"
    },
    {
      "x": -7,
      "y": -5,
      "z": 5,
      "name": "Rock_Stone"
    },
    {
      "x": -7,
      "y": -4,
      "z": 5,
      "name": "Rock_Stone"
    },
    {
      "x": -7,
      "y": -3,
      "z": 5,
      "name": "Rock_Stone"
    },
    {
      "x": -7,
      "y": -2,
      "z": 5,
      "name": "Rock_Stone"
    },
    {
      "x": -7,
      "y": -1,
      "z": 5,
      "name": "Rock_Stone"
    },
    {
      "x": -7,
      "y": -8,
      "z": 6,
      "name": "Rock_Stone"
    },
    {
      "x": -7,
      "y": -7,
      "z": 6,
      "name": "Rock_Stone"
    },
    {
      "x": -7,
      "y": -6,
      "z": 6,
      "name": "Rock_Stone"
    },
    {
      "x": -7,
      "y": -5,
      "z": 6,
      "name": "Rock_Stone"
    },
    {
      "x": -7,
      "y": -4,
      "z": 6,
      "name": "Rock_Stone"
    },
    {
      "x": -7,
      "y": -3,
      "z": 6,
      "name": "Rock_Stone"
    },
    {
      "x": -6,
      "y": -9,
      "z": -11,
      "name": "Rock_Stone"
    },
    {
      "x": -6,
      "y": -8,
      "z": -11,
      "name": "Rock_Stone"
    },
    {
      "x": -6,
      "y": -7,
      "z": -11,
      "name": "Rock_Stone"
    },
    {
      "x": -6,
      "y": -6,
      "z": -11,
      "name": "Rock_Stone"
    },
    {
      "x": -6,
      "y": -5,
      "z": -11,
      "name": "Rock_Stone"
    },
    {
      "x": -6,
      "y": -4,
      "z": -11,
      "name": "Rock_Stone"
    },
    {
      "x": -6,
      "y": -3,
      "z": -11,
      "name": "Rock_Stone"
    },
    {
      "x": -6,
      "y": -10,
      "z": -10,
      "name": "Rock_Stone"
    },
    {
      "x": -6,
      "y": -9,
      "z": -10,
      "name": "Empty"
    },
    {
      "x": -6,
      "y": -8,
      "z": -10,
      "name": "Empty"
    },
    {
      "x": -6,
      "y": -7,
      "z": -10,
      "name": "Empty"
    },
    {
      "x": -6,
      "y": -6,
      "z": -10,
      "name": "Empty"
    },
    {
      "x": -6,
      "y": -5,
      "z": -10,
      "name": "Empty"
    },
    {
      "x": -6,
      "y": -4,
      "z": -10,
      "name": "Empty"
    },
    {
      "x": -6,
      "y": -3,
      "z": -10,
      "name": "Empty"
    },
    {
      "x": -6,
      "y": -2,
      "z": -10,
      "name": "Empty"
    },
    {
      "x": -6,
      "y": -10,
      "z": -9,
      "name": "Rock_Stone"
    },
    {
      "x": -6,
      "y": -9,
      "z": -9,
      "name": "Empty"
    },
    {
      "x": -6,
      "y": -8,
      "z": -9,
      "name": "Empty"
    },
    {
      "x": -6,
      "y": -7,
      "z": -9,
      "name": "Empty"
    },
    {
      "x": -6,
      "y": -6,
      "z": -9,
      "name": "Empty"
    },
    {
      "x": -6,
      "y": -5,
      "z": -9,
      "name": "Empty"
    },
    {
      "x": -6,
      "y": -4,
      "z": -9,
      "name": "Empty"
    },
    {
      "x": -6,
      "y": -3,
      "z": -9,
      "name": "Empty"
    },
    {
      "x": -6,
      "y": -2,
      "z": -9,
      "name": "Empty"
    },
    {
      "x": -6,
      "y": -1,
      "z": -9,
      "name": "Rock_Stone"
    },
    {
      "x": -6,
      "y": 0,
      "z": -9,
      "name": "Rock_Stone"
    },
    {
      "x": -6,
      "y": -10,
      "z": -8,
      "name": "Rock_Stone"
    },
    {
      "x": -6,
      "y": -9,
      "z": -8,
      "name": "Empty"
    },
    {
      "x": -6,
      "y": -8,
      "z": -8,
      "name": "Empty"
    },
    {
      "x": -6,
      "y": -7,
      "z": -8,
      "name": "Empty"
    },
    {
      "x": -6,
      "y": -6,
      "z": -8,
      "name": "Empty"
    },
    {
      "x": -6,
      "y": -5,
      "z": -8,
      "name": "Empty"
    },
    {
      "x": -6,
      "y": -4,
      "z": -8,
      "name": "Empty"
    },
    {
      "x": -6,
      "y": -3,
      "z": -8,
      "name": "Empty"
    },
    {
      "x": -6,
      "y": -2,
      "z": -8,
      "name": "Rock_Stone"
    },
    {
      "x": -6,
      "y": -1,
      "z": -8,
      "name": "Rock_Stone"
    },
    {
      "x": -6,
      "y": 0,
      "z": -8,
      "name": "Rock_Stone"
    },
    {
      "x": -6,
      "y": -10,
      "z": -7,
      "name": "Rock_Stone"
    },
    {
      "x": -6,
      "y": -9,
      "z": -7,
      "name": "Empty"
    },
    {
      "x": -6,
      "y": -8,
      "z": -7,
      "name": "Empty"
    },
    {
      "x": -6,
      "y": -7,
      "z": -7,
      "name": "Empty"
    },
    {
      "x": -6,
      "y": -6,
      "z": -7,
      "name": "Empty"
    },
    {
      "x": -6,
      "y": -5,
      "z": -7,
      "name": "Rock_Stone"
    },
    {
      "x": -6,
      "y": -4,
      "z": -7,
      "name": "Rock_Stone"
    },
    {
      "x": -6,
      "y": -3,
      "z": -7,
      "name": "Rock_Stone"
    },
    {
      "x": -6,
      "y": -2,
      "z": -7,
      "name": "Rock_Stone"
    },
    {
      "x": -6,
      "y": -1,
      "z": -7,
      "name": "Rock_Stone"
    },
    {
      "x": -6,
      "y": 0,
      "z": -7,
      "name": "Rock_Stone"
    },
    {
      "x": -6,
      "y": -10,
      "z": -6,
      "name": "Soil_Pathway"
    },
    {
      "x": -6,
      "y": -9,
      "z": -6,
      "name": "Empty"
    },
    {
      "x": -6,
      "y": -8,
      "z": -6,
      "name": "Empty"
    },
    {
      "x": -6,
      "y": -7,
      "z": -6,
      "name": "Empty"
    },
    {
      "x": -6,
      "y": -6,
      "z": -6,
      "name": "Empty"
    },
    {
      "x": -6,
      "y": -5,
      "z": -6,
      "name": "Rock_Stone"
    },
    {
      "x": -6,
      "y": -4,
      "z": -6,
      "name": "Rock_Stone"
    },
    {
      "x": -6,
      "y": -3,
      "z": -6,
      "name": "Rock_Stone"
    },
    {
      "x": -6,
      "y": -2,
      "z": -6,
      "name": "Rock_Stone"
    },
    {
      "x": -6,
      "y": -1,
      "z": -6,
      "name": "Rock_Stone"
    },
    {
      "x": -6,
      "y": 0,
      "z": -6,
      "name": "Rock_Stone"
    },
    {
      "x": -6,
      "y": -10,
      "z": -5,
      "name": "Rock_Stone"
    },
    {
      "x": -6,
      "y": -9,
      "z": -5,
      "name": "Empty"
    },
    {
      "x": -6,
      "y": -8,
      "z": -5,
      "name": "Empty"
    },
    {
      "x": -6,
      "y": -7,
      "z": -5,
      "name": "Empty"
    },
    {
      "x": -6,
      "y": -6,
      "z": -5,
      "name": "Rock_Stone"
    },
    {
      "x": -6,
      "y": -5,
      "z": -5,
      "name": "Rock_Stone"
    },
    {
      "x": -6,
      "y": -4,
      "z": -5,
      "name": "Rock_Stone"
    },
    {
      "x": -6,
      "y": -3,
      "z": -5,
      "name": "Rock_Stone"
    },
    {
      "x": -6,
      "y": -2,
      "z": -5,
      "name": "Rock_Stone"
    },
    {
      "x": -6,
      "y": -1,
      "z": -5,
      "name": "Rock_Stone"
    },
    {
      "x": -6,
      "y": 0,
      "z": -5,
      "name": "Rock_Stone"
    },
    {
      "x": -6,
      "y": -10,
      "z": -4,
      "name": "Rock_Stone"
    },
    {
      "x": -6,
      "y": -9,
      "z": -4,
      "name": "Empty"
    },
    {
      "x": -6,
      "y": -8,
      "z": -4,
      "name": "Empty"
    },
    {
      "x": -6,
      "y": -7,
      "z": -4,
      "name": "Rock_Stone"
    },
    {
      "x": -6,
      "y": -6,
      "z": -4,
      "name": "Rock_Stone"
    },
    {
      "x": -6,
      "y": -5,
      "z": -4,
      "name": "Rock_Stone"
    },
    {
      "x": -6,
      "y": -4,
      "z": -4,
      "name": "Rock_Stone"
    },
    {
      "x": -6,
      "y": -3,
      "z": -4,
      "name": "Rock_Stone"
    },
    {
      "x": -6,
      "y": -2,
      "z": -4,
      "name": "Rock_Stone"
    },
    {
      "x": -6,
      "y": -1,
      "z": -4,
      "name": "Rock_Stone"
    },
    {
      "x": -6,
      "y": -10,
      "z": -3,
      "name": "Rock_Stone"
    },
    {
      "x": -6,
      "y": -9,
      "z": -3,
      "name": "Rock_Stone"
    },
    {
      "x": -6,
      "y": -8,
      "z": -3,
      "name": "Rock_Stone"
    },
    {
      "x": -6,
      "y": -7,
      "z": -3,
      "name": "Rock_Stone"
    },
    {
      "x": -6,
      "y": -6,
      "z": -3,
      "name": "Rock_Stone"
    },
    {
      "x": -6,
      "y": -5,
      "z": -3,
      "name": "Rock_Stone"
    },
    {
      "x": -6,
      "y": -4,
      "z": -3,
      "name": "Rock_Stone"
    },
    {
      "x": -6,
      "y": -3,
      "z": -3,
      "name": "Rock_Stone"
    },
    {
      "x": -6,
      "y": -2,
      "z": -3,
      "name": "Rock_Stone"
    },
    {
      "x": -6,
      "y": -1,
      "z": -3,
      "name": "Rock_Stone"
    },
    {
      "x": -6,
      "y": -10,
      "z": -2,
      "name": "Rock_Stone"
    },
    {
      "x": -6,
      "y": -9,
      "z": -2,
      "name": "Empty"
    },
    {
      "x": -6,
      "y": -8,
      "z": -2,
      "name": "Empty"
    },
    {
      "x": -6,
      "y": -7,
      "z": -2,
      "name": "Empty"
    },
    {
      "x": -6,
      "y": -6,
      "z": -2,
      "name": "Empty"
    },
    {
      "x": -6,
      "y": -5,
      "z": -2,
      "name": "Empty"
    },
    {
      "x": -6,
      "y": -4,
      "z": -2,
      "name": "Rock_Stone"
    },
    {
      "x": -6,
      "y": -3,
      "z": -2,
      "name": "Rock_Stone"
    },
    {
      "x": -6,
      "y": -2,
      "z": -2,
      "name": "Rock_Stone"
    },
    {
      "x": -6,
      "y": -1,
      "z": -2,
      "name": "Rock_Stone"
    },
    {
      "x": -6,
      "y": 0,
      "z": -2,
      "name": "Rock_Stone"
    },
    {
      "x": -6,
      "y": -10,
      "z": -1,
      "name": "Soil_Pathway"
    },
    {
      "x": -6,
      "y": -9,
      "z": -1,
      "name": "Empty"
    },
    {
      "x": -6,
      "y": -8,
      "z": -1,
      "name": "Empty"
    },
    {
      "x": -6,
      "y": -7,
      "z": -1,
      "name": "Empty"
    },
    {
      "x": -6,
      "y": -6,
      "z": -1,
      "name": "Empty"
    },
    {
      "x": -6,
      "y": -5,
      "z": -1,
      "name": "Empty"
    },
    {
      "x": -6,
      "y": -4,
      "z": -1,
      "name": "Rock_Stone"
    },
    {
      "x": -6,
      "y": -3,
      "z": -1,
      "name": "Rock_Stone"
    },
    {
      "x": -6,
      "y": -2,
      "z": -1,
      "name": "Rock_Stone"
    },
    {
      "x": -6,
      "y": -1,
      "z": -1,
      "name": "Rock_Stone"
    },
    {
      "x": -6,
      "y": 0,
      "z": -1,
      "name": "Rock_Stone"
    },
    {
      "x": -6,
      "y": -10,
      "z": 0,
      "name": "Soil_Pathway"
    },
    {
      "x": -6,
      "y": -9,
      "z": 0,
      "name": "Empty"
    },
    {
      "x": -6,
      "y": -8,
      "z": 0,
      "name": "Empty"
    },
    {
      "x": -6,
      "y": -7,
      "z": 0,
      "name": "Empty"
    },
    {
      "x": -6,
      "y": -6,
      "z": 0,
      "name": "Empty"
    },
    {
      "x": -6,
      "y": -5,
      "z": 0,
      "name": "Empty"
    },
    {
      "x": -6,
      "y": -4,
      "z": 0,
      "name": "Rock_Stone"
    },
    {
      "x": -6,
      "y": -3,
      "z": 0,
      "name": "Rock_Stone"
    },
    {
      "x": -6,
      "y": -2,
      "z": 0,
      "name": "Rock_Stone"
    },
    {
      "x": -6,
      "y": -1,
      "z": 0,
      "name": "Rock_Stone"
    },
    {
      "x": -6,
      "y": 0,
      "z": 0,
      "name": "Rock_Stone"
    },
    {
      "x": -6,
      "y": -10,
      "z": 1,
      "name": "Soil_Pathway"
    },
    {
      "x": -6,
      "y": -9,
      "z": 1,
      "name": "Empty"
    },
    {
      "x": -6,
      "y": -8,
      "z": 1,
      "name": "Empty"
    },
    {
      "x": -6,
      "y": -7,
      "z": 1,
      "name": "Empty"
    },
    {
      "x": -6,
      "y": -6,
      "z": 1,
      "name": "Empty"
    },
    {
      "x": -6,
      "y": -5,
      "z": 1,
      "name": "Empty"
    },
    {
      "x": -6,
      "y": -4,
      "z": 1,
      "name": "Rock_Stone"
    },
    {
      "x": -6,
      "y": -3,
      "z": 1,
      "name": "Rock_Stone"
    },
    {
      "x": -6,
      "y": -2,
      "z": 1,
      "name": "Rock_Stone"
    },
    {
      "x": -6,
      "y": -1,
      "z": 1,
      "name": "Rock_Stone"
    },
    {
      "x": -6,
      "y": 0,
      "z": 1,
      "name": "Rock_Stone"
    },
    {
      "x": -6,
      "y": -10,
      "z": 2,
      "name": "Rock_Stone"
    },
    {
      "x": -6,
      "y": -9,
      "z": 2,
      "name": "Wood_Softwood_Beam"
    },
    {
      "x": -6,
      "y": -8,
      "z": 2,
      "name": "*Furniture_Crude_Torch_State_Definitions_Off"
    },
    {
      "x": -6,
      "y": -7,
      "z": 2,
      "name": "Empty"
    },
    {
      "x": -6,
      "y": -6,
      "z": 2,
      "name": "Empty"
    },
    {
      "x": -6,
      "y": -5,
      "z": 2,
      "name": "Rock_Stone"
    },
    {
      "x": -6,
      "y": -4,
      "z": 2,
      "name": "Rock_Stone"
    },
    {
      "x": -6,
      "y": -3,
      "z": 2,
      "name": "Rock_Stone"
    },
    {
      "x": -6,
      "y": -2,
      "z": 2,
      "name": "Rock_Stone"
    },
    {
      "x": -6,
      "y": -1,
      "z": 2,
      "name": "Rock_Stone"
    },
    {
      "x": -6,
      "y": 0,
      "z": 2,
      "name": "Rock_Stone"
    },
    {
      "x": -6,
      "y": -10,
      "z": 3,
      "name": "Rock_Stone"
    },
    {
      "x": -6,
      "y": -9,
      "z": 3,
      "name": "Rock_Stone"
    },
    {
      "x": -6,
      "y": -8,
      "z": 3,
      "name": "Rock_Stone"
    },
    {
      "x": -6,
      "y": -7,
      "z": 3,
      "name": "Rock_Stone"
    },
    {
      "x": -6,
      "y": -6,
      "z": 3,
      "name": "Rock_Stone"
    },
    {
      "x": -6,
      "y": -5,
      "z": 3,
      "name": "Rock_Stone"
    },
    {
      "x": -6,
      "y": -4,
      "z": 3,
      "name": "Rock_Stone"
    },
    {
      "x": -6,
      "y": -3,
      "z": 3,
      "name": "Rock_Stone"
    },
    {
      "x": -6,
      "y": -2,
      "z": 3,
      "name": "Rock_Stone"
    },
    {
      "x": -6,
      "y": -1,
      "z": 3,
      "name": "Rock_Stone"
    },
    {
      "x": -6,
      "y": 0,
      "z": 3,
      "name": "Rock_Stone"
    },
    {
      "x": -6,
      "y": -10,
      "z": 4,
      "name": "Rock_Stone"
    },
    {
      "x": -6,
      "y": -9,
      "z": 4,
      "name": "Rock_Stone"
    },
    {
      "x": -6,
      "y": -8,
      "z": 4,
      "name": "Rock_Stone"
    },
    {
      "x": -6,
      "y": -7,
      "z": 4,
      "name": "Rock_Stone"
    },
    {
      "x": -6,
      "y": -6,
      "z": 4,
      "name": "Rock_Stone"
    },
    {
      "x": -6,
      "y": -5,
      "z": 4,
      "name": "Rock_Stone"
    },
    {
      "x": -6,
      "y": -4,
      "z": 4,
      "name": "Rock_Stone"
    },
    {
      "x": -6,
      "y": -3,
      "z": 4,
      "name": "Rock_Stone"
    },
    {
      "x": -6,
      "y": -2,
      "z": 4,
      "name": "Rock_Stone"
    },
    {
      "x": -6,
      "y": -1,
      "z": 4,
      "name": "Rock_Stone"
    },
    {
      "x": -6,
      "y": 0,
      "z": 4,
      "name": "Rock_Stone"
    },
    {
      "x": -6,
      "y": -10,
      "z": 5,
      "name": "Rock_Stone"
    },
    {
      "x": -6,
      "y": -9,
      "z": 5,
      "name": "Rock_Stone"
    },
    {
      "x": -6,
      "y": -8,
      "z": 5,
      "name": "Rock_Stone"
    },
    {
      "x": -6,
      "y": -7,
      "z": 5,
      "name": "Rock_Stone"
    },
    {
      "x": -6,
      "y": -6,
      "z": 5,
      "name": "Rock_Stone"
    },
    {
      "x": -6,
      "y": -5,
      "z": 5,
      "name": "Rock_Stone"
    },
    {
      "x": -6,
      "y": -4,
      "z": 5,
      "name": "Rock_Stone"
    },
    {
      "x": -6,
      "y": -3,
      "z": 5,
      "name": "Rock_Stone"
    },
    {
      "x": -6,
      "y": -2,
      "z": 5,
      "name": "Rock_Stone"
    },
    {
      "x": -6,
      "y": -1,
      "z": 5,
      "name": "Rock_Stone"
    },
    {
      "x": -6,
      "y": -9,
      "z": 6,
      "name": "Rock_Stone"
    },
    {
      "x": -6,
      "y": -8,
      "z": 6,
      "name": "Rock_Stone"
    },
    {
      "x": -6,
      "y": -7,
      "z": 6,
      "name": "Rock_Stone"
    },
    {
      "x": -6,
      "y": -6,
      "z": 6,
      "name": "Rock_Stone"
    },
    {
      "x": -6,
      "y": -5,
      "z": 6,
      "name": "Rock_Stone"
    },
    {
      "x": -6,
      "y": -4,
      "z": 6,
      "name": "Rock_Stone"
    },
    {
      "x": -6,
      "y": -3,
      "z": 6,
      "name": "Rock_Stone"
    },
    {
      "x": -6,
      "y": -2,
      "z": 6,
      "name": "Rock_Stone"
    },
    {
      "x": -6,
      "y": -7,
      "z": 7,
      "name": "Rock_Stone"
    },
    {
      "x": -6,
      "y": -6,
      "z": 7,
      "name": "Rock_Stone"
    },
    {
      "x": -5,
      "y": -10,
      "z": -11,
      "name": "Rock_Stone"
    },
    {
      "x": -5,
      "y": -9,
      "z": -11,
      "name": "Rock_Stone"
    },
    {
      "x": -5,
      "y": -8,
      "z": -11,
      "name": "Rock_Stone"
    },
    {
      "x": -5,
      "y": -7,
      "z": -11,
      "name": "Rock_Stone"
    },
    {
      "x": -5,
      "y": -6,
      "z": -11,
      "name": "Rock_Stone"
    },
    {
      "x": -5,
      "y": -5,
      "z": -11,
      "name": "Rock_Stone"
    },
    {
      "x": -5,
      "y": -4,
      "z": -11,
      "name": "Rock_Stone"
    },
    {
      "x": -5,
      "y": -3,
      "z": -11,
      "name": "Rock_Stone"
    },
    {
      "x": -5,
      "y": -10,
      "z": -10,
      "name": "Rock_Stone"
    },
    {
      "x": -5,
      "y": -9,
      "z": -10,
      "name": "Empty"
    },
    {
      "x": -5,
      "y": -8,
      "z": -10,
      "name": "Empty"
    },
    {
      "x": -5,
      "y": -7,
      "z": -10,
      "name": "Empty"
    },
    {
      "x": -5,
      "y": -6,
      "z": -10,
      "name": "Empty"
    },
    {
      "x": -5,
      "y": -5,
      "z": -10,
      "name": "Empty"
    },
    {
      "x": -5,
      "y": -4,
      "z": -10,
      "name": "Empty"
    },
    {
      "x": -5,
      "y": -3,
      "z": -10,
      "name": "Furniture_Crude_Platform"
    },
    {
      "x": -5,
      "y": -2,
      "z": -10,
      "name": "Rock_Stone"
    },
    {
      "x": -5,
      "y": -10,
      "z": -9,
      "name": "Soil_Pathway"
    },
    {
      "x": -5,
      "y": -9,
      "z": -9,
      "name": "Empty"
    },
    {
      "x": -5,
      "y": -8,
      "z": -9,
      "name": "Empty"
    },
    {
      "x": -5,
      "y": -7,
      "z": -9,
      "name": "Empty"
    },
    {
      "x": -5,
      "y": -6,
      "z": -9,
      "name": "Empty"
    },
    {
      "x": -5,
      "y": -5,
      "z": -9,
      "name": "Empty"
    },
    {
      "x": -5,
      "y": -4,
      "z": -9,
      "name": "Empty"
    },
    {
      "x": -5,
      "y": -3,
      "z": -9,
      "name": "Furniture_Crude_Platform"
    },
    {
      "x": -5,
      "y": -2,
      "z": -9,
      "name": "Rock_Stone"
    },
    {
      "x": -5,
      "y": -1,
      "z": -9,
      "name": "Rock_Stone"
    },
    {
      "x": -5,
      "y": 0,
      "z": -9,
      "name": "Rock_Stone"
    },
    {
      "x": -5,
      "y": -10,
      "z": -8,
      "name": "Soil_Pathway"
    },
    {
      "x": -5,
      "y": -9,
      "z": -8,
      "name": "Empty"
    },
    {
      "x": -5,
      "y": -8,
      "z": -8,
      "name": "Empty"
    },
    {
      "x": -5,
      "y": -7,
      "z": -8,
      "name": "Empty"
    },
    {
      "x": -5,
      "y": -6,
      "z": -8,
      "name": "Empty"
    },
    {
      "x": -5,
      "y": -5,
      "z": -8,
      "name": "Empty"
    },
    {
      "x": -5,
      "y": -4,
      "z": -8,
      "name": "Empty"
    },
    {
      "x": -5,
      "y": -3,
      "z": -8,
      "name": "Furniture_Crude_Platform"
    },
    {
      "x": -5,
      "y": -2,
      "z": -8,
      "name": "Rock_Stone"
    },
    {
      "x": -5,
      "y": -1,
      "z": -8,
      "name": "Rock_Stone"
    },
    {
      "x": -5,
      "y": 0,
      "z": -8,
      "name": "Rock_Stone"
    },
    {
      "x": -5,
      "y": -10,
      "z": -7,
      "name": "Rock_Stone"
    },
    {
      "x": -5,
      "y": -9,
      "z": -7,
      "name": "Empty"
    },
    {
      "x": -5,
      "y": -8,
      "z": -7,
      "name": "Empty"
    },
    {
      "x": -5,
      "y": -7,
      "z": -7,
      "name": "Empty"
    },
    {
      "x": -5,
      "y": -6,
      "z": -7,
      "name": "Empty"
    },
    {
      "x": -5,
      "y": -5,
      "z": -7,
      "name": "Rock_Stone"
    },
    {
      "x": -5,
      "y": -4,
      "z": -7,
      "name": "Rock_Stone"
    },
    {
      "x": -5,
      "y": -3,
      "z": -7,
      "name": "Rock_Stone"
    },
    {
      "x": -5,
      "y": -2,
      "z": -7,
      "name": "Rock_Stone"
    },
    {
      "x": -5,
      "y": -1,
      "z": -7,
      "name": "Rock_Stone"
    },
    {
      "x": -5,
      "y": 0,
      "z": -7,
      "name": "Rock_Stone"
    },
    {
      "x": -5,
      "y": -10,
      "z": -6,
      "name": "Rock_Stone"
    },
    {
      "x": -5,
      "y": -9,
      "z": -6,
      "name": "Empty"
    },
    {
      "x": -5,
      "y": -8,
      "z": -6,
      "name": "Empty"
    },
    {
      "x": -5,
      "y": -7,
      "z": -6,
      "name": "Empty"
    },
    {
      "x": -5,
      "y": -6,
      "z": -6,
      "name": "Rock_Stone"
    },
    {
      "x": -5,
      "y": -5,
      "z": -6,
      "name": "Rock_Stone"
    },
    {
      "x": -5,
      "y": -4,
      "z": -6,
      "name": "Rock_Stone"
    },
    {
      "x": -5,
      "y": -3,
      "z": -6,
      "name": "Rock_Stone"
    },
    {
      "x": -5,
      "y": -2,
      "z": -6,
      "name": "Rock_Stone"
    },
    {
      "x": -5,
      "y": -1,
      "z": -6,
      "name": "Rock_Stone"
    },
    {
      "x": -5,
      "y": 0,
      "z": -6,
      "name": "Rock_Stone"
    },
    {
      "x": -5,
      "y": -10,
      "z": -5,
      "name": "Rock_Stone"
    },
    {
      "x": -5,
      "y": -9,
      "z": -5,
      "name": "Rock_Stone"
    },
    {
      "x": -5,
      "y": -8,
      "z": -5,
      "name": "Empty"
    },
    {
      "x": -5,
      "y": -7,
      "z": -5,
      "name": "Rock_Stone"
    },
    {
      "x": -5,
      "y": -6,
      "z": -5,
      "name": "Rock_Stone"
    },
    {
      "x": -5,
      "y": -5,
      "z": -5,
      "name": "Rock_Stone"
    },
    {
      "x": -5,
      "y": -4,
      "z": -5,
      "name": "Rock_Stone"
    },
    {
      "x": -5,
      "y": -3,
      "z": -5,
      "name": "Rock_Stone"
    },
    {
      "x": -5,
      "y": -2,
      "z": -5,
      "name": "Rock_Stone"
    },
    {
      "x": -5,
      "y": -1,
      "z": -5,
      "name": "Rock_Stone"
    },
    {
      "x": -5,
      "y": 0,
      "z": -5,
      "name": "Rock_Stone"
    },
    {
      "x": -5,
      "y": -10,
      "z": -4,
      "name": "Rock_Stone"
    },
    {
      "x": -5,
      "y": -9,
      "z": -4,
      "name": "Rock_Stone"
    },
    {
      "x": -5,
      "y": -8,
      "z": -4,
      "name": "Rock_Stone"
    },
    {
      "x": -5,
      "y": -7,
      "z": -4,
      "name": "Rock_Stone"
    },
    {
      "x": -5,
      "y": -6,
      "z": -4,
      "name": "Rock_Stone"
    },
    {
      "x": -5,
      "y": -5,
      "z": -4,
      "name": "Rock_Stone"
    },
    {
      "x": -5,
      "y": -4,
      "z": -4,
      "name": "Rock_Stone"
    },
    {
      "x": -5,
      "y": -3,
      "z": -4,
      "name": "Rock_Stone"
    },
    {
      "x": -5,
      "y": -2,
      "z": -4,
      "name": "Rock_Stone"
    },
    {
      "x": -5,
      "y": -1,
      "z": -4,
      "name": "Rock_Stone"
    },
    {
      "x": -5,
      "y": -10,
      "z": -3,
      "name": "Rock_Stone"
    },
    {
      "x": -5,
      "y": -9,
      "z": -3,
      "name": "Rock_Stone"
    },
    {
      "x": -5,
      "y": -8,
      "z": -3,
      "name": "Rock_Stone"
    },
    {
      "x": -5,
      "y": -7,
      "z": -3,
      "name": "Rock_Stone"
    },
    {
      "x": -5,
      "y": -6,
      "z": -3,
      "name": "Rock_Stone"
    },
    {
      "x": -5,
      "y": -5,
      "z": -3,
      "name": "Rock_Stone"
    },
    {
      "x": -5,
      "y": -4,
      "z": -3,
      "name": "Rock_Stone"
    },
    {
      "x": -5,
      "y": -3,
      "z": -3,
      "name": "Rock_Stone"
    },
    {
      "x": -5,
      "y": -2,
      "z": -3,
      "name": "Rock_Stone"
    },
    {
      "x": -5,
      "y": -1,
      "z": -3,
      "name": "Rock_Stone"
    },
    {
      "x": -5,
      "y": 0,
      "z": -3,
      "name": "Rock_Stone"
    },
    {
      "x": -5,
      "y": -10,
      "z": -2,
      "name": "Rock_Stone"
    },
    {
      "x": -5,
      "y": -9,
      "z": -2,
      "name": "Empty"
    },
    {
      "x": -5,
      "y": -8,
      "z": -2,
      "name": "Empty"
    },
    {
      "x": -5,
      "y": -7,
      "z": -2,
      "name": "Empty"
    },
    {
      "x": -5,
      "y": -6,
      "z": -2,
      "name": "Empty"
    },
    {
      "x": -5,
      "y": -5,
      "z": -2,
      "name": "Rock_Stone"
    },
    {
      "x": -5,
      "y": -4,
      "z": -2,
      "name": "Rock_Stone"
    },
    {
      "x": -5,
      "y": -3,
      "z": -2,
      "name": "Rock_Stone"
    },
    {
      "x": -5,
      "y": -2,
      "z": -2,
      "name": "Rock_Stone"
    },
    {
      "x": -5,
      "y": -1,
      "z": -2,
      "name": "Rock_Stone"
    },
    {
      "x": -5,
      "y": 0,
      "z": -2,
      "name": "Rock_Stone"
    },
    {
      "x": -5,
      "y": -10,
      "z": -1,
      "name": "Rock_Stone"
    },
    {
      "x": -5,
      "y": -9,
      "z": -1,
      "name": "Empty"
    },
    {
      "x": -5,
      "y": -8,
      "z": -1,
      "name": "Empty"
    },
    {
      "x": -5,
      "y": -7,
      "z": -1,
      "name": "Empty"
    },
    {
      "x": -5,
      "y": -6,
      "z": -1,
      "name": "Empty"
    },
    {
      "x": -5,
      "y": -5,
      "z": -1,
      "name": "Empty"
    },
    {
      "x": -5,
      "y": -4,
      "z": -1,
      "name": "Rock_Stone"
    },
    {
      "x": -5,
      "y": -3,
      "z": -1,
      "name": "Rock_Stone"
    },
    {
      "x": -5,
      "y": -2,
      "z": -1,
      "name": "Rock_Stone"
    },
    {
      "x": -5,
      "y": -1,
      "z": -1,
      "name": "Rock_Stone"
    },
    {
      "x": -5,
      "y": 0,
      "z": -1,
      "name": "Rock_Stone"
    },
    {
      "x": -5,
      "y": -10,
      "z": 0,
      "name": "Rock_Stone"
    },
    {
      "x": -5,
      "y": -9,
      "z": 0,
      "name": "Empty"
    },
    {
      "x": -5,
      "y": -8,
      "z": 0,
      "name": "Empty"
    },
    {
      "x": -5,
      "y": -7,
      "z": 0,
      "name": "Empty"
    },
    {
      "x": -5,
      "y": -6,
      "z": 0,
      "name": "Empty"
    },
    {
      "x": -5,
      "y": -5,
      "z": 0,
      "name": "Empty"
    },
    {
      "x": -5,
      "y": -4,
      "z": 0,
      "name": "Empty"
    },
    {
      "x": -5,
      "y": -3,
      "z": 0,
      "name": "Rock_Stone"
    },
    {
      "x": -5,
      "y": -2,
      "z": 0,
      "name": "Rock_Stone"
    },
    {
      "x": -5,
      "y": -1,
      "z": 0,
      "name": "Rock_Stone"
    },
    {
      "x": -5,
      "y": 0,
      "z": 0,
      "name": "Rock_Stone"
    },
    {
      "x": -5,
      "y": -10,
      "z": 1,
      "name": "Rock_Stone"
    },
    {
      "x": -5,
      "y": -9,
      "z": 1,
      "name": "Empty"
    },
    {
      "x": -5,
      "y": -8,
      "z": 1,
      "name": "Empty"
    },
    {
      "x": -5,
      "y": -7,
      "z": 1,
      "name": "Empty"
    },
    {
      "x": -5,
      "y": -6,
      "z": 1,
      "name": "Empty"
    },
    {
      "x": -5,
      "y": -5,
      "z": 1,
      "name": "Empty"
    },
    {
      "x": -5,
      "y": -4,
      "z": 1,
      "name": "Empty"
    },
    {
      "x": -5,
      "y": -3,
      "z": 1,
      "name": "Empty"
    },
    {
      "x": -5,
      "y": -2,
      "z": 1,
      "name": "Rock_Stone"
    },
    {
      "x": -5,
      "y": -1,
      "z": 1,
      "name": "Rock_Stone"
    },
    {
      "x": -5,
      "y": 0,
      "z": 1,
      "name": "Rock_Stone"
    },
    {
      "x": -5,
      "y": -10,
      "z": 2,
      "name": "Rock_Stone"
    },
    {
      "x": -5,
      "y": -9,
      "z": 2,
      "name": "Soil_Gravel_Half"
    },
    {
      "x": -5,
      "y": -8,
      "z": 2,
      "name": "Empty"
    },
    {
      "x": -5,
      "y": -7,
      "z": 2,
      "name": "Empty"
    },
    {
      "x": -5,
      "y": -6,
      "z": 2,
      "name": "Empty"
    },
    {
      "x": -5,
      "y": -5,
      "z": 2,
      "name": "Empty"
    },
    {
      "x": -5,
      "y": -4,
      "z": 2,
      "name": "Empty"
    },
    {
      "x": -5,
      "y": -3,
      "z": 2,
      "name": "Empty"
    },
    {
      "x": -5,
      "y": -2,
      "z": 2,
      "name": "Empty"
    },
    {
      "x": -5,
      "y": -1,
      "z": 2,
      "name": "Rock_Stone"
    },
    {
      "x": -5,
      "y": 0,
      "z": 2,
      "name": "Rock_Stone"
    },
    {
      "x": -5,
      "y": -10,
      "z": 3,
      "name": "Rock_Stone"
    },
    {
      "x": -5,
      "y": -9,
      "z": 3,
      "name": "Soil_Gravel"
    },
    {
      "x": -5,
      "y": -8,
      "z": 3,
      "name": "Empty"
    },
    {
      "x": -5,
      "y": -7,
      "z": 3,
      "name": "Empty"
    },
    {
      "x": -5,
      "y": -6,
      "z": 3,
      "name": "Empty"
    },
    {
      "x": -5,
      "y": -5,
      "z": 3,
      "name": "Empty"
    },
    {
      "x": -5,
      "y": -4,
      "z": 3,
      "name": "Empty"
    },
    {
      "x": -5,
      "y": -3,
      "z": 3,
      "name": "Empty"
    },
    {
      "x": -5,
      "y": -2,
      "z": 3,
      "name": "Rock_Stone"
    },
    {
      "x": -5,
      "y": -1,
      "z": 3,
      "name": "Rock_Stone"
    },
    {
      "x": -5,
      "y": 0,
      "z": 3,
      "name": "Rock_Stone"
    },
    {
      "x": -5,
      "y": -10,
      "z": 4,
      "name": "Rock_Stone"
    },
    {
      "x": -5,
      "y": -9,
      "z": 4,
      "name": "Rock_Stone"
    },
    {
      "x": -5,
      "y": -8,
      "z": 4,
      "name": "Rock_Stone"
    },
    {
      "x": -5,
      "y": -7,
      "z": 4,
      "name": "Rock_Stone"
    },
    {
      "x": -5,
      "y": -6,
      "z": 4,
      "name": "Rock_Stone"
    },
    {
      "x": -5,
      "y": -5,
      "z": 4,
      "name": "Rock_Stone"
    },
    {
      "x": -5,
      "y": -4,
      "z": 4,
      "name": "Rock_Stone"
    },
    {
      "x": -5,
      "y": -3,
      "z": 4,
      "name": "Rock_Stone"
    },
    {
      "x": -5,
      "y": -2,
      "z": 4,
      "name": "Rock_Stone"
    },
    {
      "x": -5,
      "y": -1,
      "z": 4,
      "name": "Rock_Stone"
    },
    {
      "x": -5,
      "y": 0,
      "z": 4,
      "name": "Rock_Stone"
    },
    {
      "x": -5,
      "y": -10,
      "z": 5,
      "name": "Rock_Stone"
    },
    {
      "x": -5,
      "y": -9,
      "z": 5,
      "name": "Rock_Stone"
    },
    {
      "x": -5,
      "y": -8,
      "z": 5,
      "name": "Rock_Stone"
    },
    {
      "x": -5,
      "y": -7,
      "z": 5,
      "name": "Rock_Stone"
    },
    {
      "x": -5,
      "y": -6,
      "z": 5,
      "name": "Rock_Stone"
    },
    {
      "x": -5,
      "y": -5,
      "z": 5,
      "name": "Rock_Stone"
    },
    {
      "x": -5,
      "y": -4,
      "z": 5,
      "name": "Rock_Stone"
    },
    {
      "x": -5,
      "y": -3,
      "z": 5,
      "name": "Rock_Stone"
    },
    {
      "x": -5,
      "y": -2,
      "z": 5,
      "name": "Rock_Stone"
    },
    {
      "x": -5,
      "y": -1,
      "z": 5,
      "name": "Rock_Stone"
    },
    {
      "x": -5,
      "y": -10,
      "z": 6,
      "name": "Rock_Stone"
    },
    {
      "x": -5,
      "y": -9,
      "z": 6,
      "name": "Rock_Stone"
    },
    {
      "x": -5,
      "y": -8,
      "z": 6,
      "name": "Rock_Stone"
    },
    {
      "x": -5,
      "y": -7,
      "z": 6,
      "name": "Rock_Stone"
    },
    {
      "x": -5,
      "y": -6,
      "z": 6,
      "name": "Rock_Stone"
    },
    {
      "x": -5,
      "y": -5,
      "z": 6,
      "name": "Rock_Stone"
    },
    {
