{
  "version": 8,
  "blockIdVersion": 8,
  "anchorX": 1,
  "anchorY": 7,
  "anchorZ": 1,
  "blocks": [
    {
      "x": -4,
      "y": 26,
      "z": -5,
      "name": "Rock_Basalt_Cobble_Roof",
      "rotation": 3
    },
    {
      "x": -4,
      "y": 24,
      "z": -4,
      "name": "Rock_Stone_Cobble_Half",
      "rotation": 7
    },
    {
      "x": -4,
      "y": 25,
      "z": -4,
      "name": "Rock_Stone_Cobble_Half",
      "rotation": 7
    },
    {
      "x": -4,
      "y": 26,
      "z": -4,
      "name": "Rock_Basalt_Cobble_Roof",
      "rotation": 3
    },
    {
      "x": -4,
      "y": 26,
      "z": -3,
      "name": "Rock_Basalt_Cobble_Roof",
      "rotation": 3
    },
    {
      "x": -4,
      "y": 12,
      "z": -2,
      "name": "Rock_Slate"
    },
    {
      "x": -4,
      "y": 13,
      "z": -2,
      "name": "Rock_Slate"
    },
    {
      "x": -4,
      "y": 14,
      "z": -2,
      "name": "Rock_Slate"
    },
    {
      "x": -4,
      "y": 15,
      "z": -2,
      "name": "Rock_Slate"
    },
    {
      "x": -4,
      "y": 16,
      "z": -2,
      "name": "Rock_Slate"
    },
    {
      "x": -4,
      "y": 17,
      "z": -2,
      "name": "Rock_Slate"
    },
    {
      "x": -4,
      "y": 18,
      "z": -2,
      "name": "Rock_Slate"
    },
    {
      "x": -4,
      "y": 19,
      "z": -2,
      "name": "Rock_Slate"
    },
    {
      "x": -4,
      "y": 20,
      "z": -2,
      "name": "Rock_Slate"
    },
    {
      "x": -4,
      "y": 21,
      "z": -2,
      "name": "Rock_Slate"
    },
    {
      "x": -4,
      "y": 26,
      "z": -2,
      "name": "Rock_Basalt_Cobble_Roof",
      "rotation": 3
    },
    {
      "x": -4,
      "y": 11,
      "z": -1,
      "name": "Rock_Slate"
    },
    {
      "x": -4,
      "y": 12,
      "z": -1,
      "name": "Rock_Slate"
    },
    {
      "x": -4,
      "y": 13,
      "z": -1,
      "name": "Rock_Slate"
    },
    {
      "x": -4,
      "y": 14,
      "z": -1,
      "name": "Rock_Slate"
    },
    {
      "x": -4,
      "y": 15,
      "z": -1,
      "name": "Rock_Slate"
    },
    {
      "x": -4,
      "y": 16,
      "z": -1,
      "name": "Rock_Slate"
    },
    {
      "x": -4,
      "y": 17,
      "z": -1,
      "name": "Rock_Slate"
    },
    {
      "x": -4,
      "y": 18,
      "z": -1,
      "name": "Rock_Slate"
    },
    {
      "x": -4,
      "y": 19,
      "z": -1,
      "name": "Rock_Slate"
    },
    {
      "x": -4,
      "y": 20,
      "z": -1,
      "name": "Rock_Slate"
    },
    {
      "x": -4,
      "y": 21,
      "z": -1,
      "name": "Rock_Slate"
    },
    {
      "x": -4,
      "y": 26,
      "z": -1,
      "name": "Rock_Basalt_Cobble_Roof_Hollow",
      "rotation": 3
    },
    {
      "x": -4,
      "y": 11,
      "z": 0,
      "name": "Rock_Slate"
    },
    {
      "x": -4,
      "y": 12,
      "z": 0,
      "name": "Rock_Slate"
    },
    {
      "x": -4,
      "y": 13,
      "z": 0,
      "name": "Rock_Slate"
    },
    {
      "x": -4,
      "y": 14,
      "z": 0,
      "name": "Rock_Slate"
    },
    {
      "x": -4,
      "y": 15,
      "z": 0,
      "name": "Rock_Slate"
    },
    {
      "x": -4,
      "y": 16,
      "z": 0,
      "name": "Rock_Slate"
    },
    {
      "x": -4,
      "y": 17,
      "z": 0,
      "name": "Rock_Slate"
    },
    {
      "x": -4,
      "y": 18,
      "z": 0,
      "name": "Rock_Slate"
    },
    {
      "x": -4,
      "y": 19,
      "z": 0,
      "name": "Rock_Slate"
    },
    {
      "x": -4,
      "y": 20,
      "z": 0,
      "name": "Rock_Slate"
    },
    {
      "x": -4,
      "y": 21,
      "z": 0,
      "name": "Rock_Slate"
    },
    {
      "x": -3,
      "y": 23,
      "z": -5,
      "name": "Rock_Stone_Cobble_Half",
      "rotation": 6
    },
    {
      "x": -3,
      "y": 24,
      "z": -5,
      "name": "Rock_Stone_Cobble_Half",
      "rotation": 6
    },
    {
      "x": -3,
      "y": 25,
      "z": -5,
      "name": "Rock_Stone_Cobble_Half",
      "rotation": 6
    },
    {
      "x": -3,
      "y": 26,
      "z": -5,
      "name": "Wood_Deadwood_Stairs",
      "rotation": 11
    },
    {
      "x": -3,
      "y": 27,
      "z": -5,
      "name": "Rock_Basalt_Cobble_Roof",
      "rotation": 3
    },
    {
      "x": -3,
      "y": 13,
      "z": -4,
      "name": "Rock_Slate"
    },
    {
      "x": -3,
      "y": 14,
      "z": -4,
      "name": "Rock_Slate"
    },
    {
      "x": -3,
      "y": 15,
      "z": -4,
      "name": "Rock_Slate"
    },
    {
      "x": -3,
      "y": 16,
      "z": -4,
      "name": "Rock_Slate"
    },
    {
      "x": -3,
      "y": 17,
      "z": -4,
      "name": "Rock_Slate"
    },
    {
      "x": -3,
      "y": 18,
      "z": -4,
      "name": "Rock_Slate"
    },
    {
      "x": -3,
      "y": 19,
      "z": -4,
      "name": "Rock_Slate"
    },
    {
      "x": -3,
      "y": 20,
      "z": -4,
      "name": "Rock_Slate"
    },
    {
      "x": -3,
      "y": 21,
      "z": -4,
      "name": "Rock_Slate"
    },
    {
      "x": -3,
      "y": 22,
      "z": -4,
      "name": "Rock_Slate"
    },
    {
      "x": -3,
      "y": 23,
      "z": -4,
      "name": "Rock_Slate"
    },
    {
      "x": -3,
      "y": 24,
      "z": -4,
      "name": "Rock_Stone_Cobble"
    },
    {
      "x": -3,
      "y": 25,
      "z": -4,
      "name": "Rock_Stone_Cobble"
    },
    {
      "x": -3,
      "y": 26,
      "z": -4,
      "name": "Rock_Stone_Cobble"
    },
    {
      "x": -3,
      "y": 27,
      "z": -4,
      "name": "Rock_Basalt_Cobble_Roof",
      "rotation": 3
    },
    {
      "x": -3,
      "y": 8,
      "z": -3,
      "name": "Rock_Slate"
    },
    {
      "x": -3,
      "y": 9,
      "z": -3,
      "name": "Rock_Slate"
    },
    {
      "x": -3,
      "y": 10,
      "z": -3,
      "name": "Rock_Slate"
    },
    {
      "x": -3,
      "y": 11,
      "z": -3,
      "name": "Rock_Slate"
    },
    {
      "x": -3,
      "y": 12,
      "z": -3,
      "name": "Rock_Slate"
    },
    {
      "x": -3,
      "y": 13,
      "z": -3,
      "name": "Rock_Slate"
    },
    {
      "x": -3,
      "y": 14,
      "z": -3,
      "name": "Rock_Slate"
    },
    {
      "x": -3,
      "y": 15,
      "z": -3,
      "name": "Rock_Slate"
    },
    {
      "x": -3,
      "y": 16,
      "z": -3,
      "name": "Rock_Slate"
    },
    {
      "x": -3,
      "y": 17,
      "z": -3,
      "name": "Rock_Slate"
    },
    {
      "x": -3,
      "y": 18,
      "z": -3,
      "name": "Rock_Slate"
    },
    {
      "x": -3,
      "y": 19,
      "z": -3,
      "name": "Rock_Slate"
    },
    {
      "x": -3,
      "y": 20,
      "z": -3,
      "name": "Rock_Slate"
    },
    {
      "x": -3,
      "y": 21,
      "z": -3,
      "name": "Rock_Slate"
    },
    {
      "x": -3,
      "y": 22,
      "z": -3,
      "name": "Rock_Slate"
    },
    {
      "x": -3,
      "y": 23,
      "z": -3,
      "name": "Rock_Slate"
    },
    {
      "x": -3,
      "y": 24,
      "z": -3,
      "name": "Rock_Stone_Cobble"
    },
    {
      "x": -3,
      "y": 25,
      "z": -3,
      "name": "Rock_Stone_Cobble"
    },
    {
      "x": -3,
      "y": 26,
      "z": -3,
      "name": "Rock_Stone_Cobble"
    },
    {
      "x": -3,
      "y": 27,
      "z": -3,
      "name": "Rock_Basalt_Cobble_Roof",
      "rotation": 3
    },
    {
      "x": -3,
      "y": 8,
      "z": -2,
      "name": "Rock_Slate"
    },
    {
      "x": -3,
      "y": 9,
      "z": -2,
      "name": "Rock_Slate"
    },
    {
      "x": -3,
      "y": 10,
      "z": -2,
      "name": "Rock_Slate"
    },
    {
      "x": -3,
      "y": 11,
      "z": -2,
      "name": "Rock_Slate"
    },
    {
      "x": -3,
      "y": 12,
      "z": -2,
      "name": "Rock_Slate"
    },
    {
      "x": -3,
      "y": 13,
      "z": -2,
      "name": "Rock_Slate"
    },
    {
      "x": -3,
      "y": 14,
      "z": -2,
      "name": "Rock_Slate"
    },
    {
      "x": -3,
      "y": 15,
      "z": -2,
      "name": "Rock_Slate"
    },
    {
      "x": -3,
      "y": 16,
      "z": -2,
      "name": "Rock_Slate"
    },
    {
      "x": -3,
      "y": 17,
      "z": -2,
      "name": "Rock_Slate"
    },
    {
      "x": -3,
      "y": 18,
      "z": -2,
      "name": "Rock_Slate"
    },
    {
      "x": -3,
      "y": 19,
      "z": -2,
      "name": "Rock_Slate"
    },
    {
      "x": -3,
      "y": 20,
      "z": -2,
      "name": "Rock_Slate"
    },
    {
      "x": -3,
      "y": 21,
      "z": -2,
      "name": "Rock_Slate"
    },
    {
      "x": -3,
      "y": 22,
      "z": -2,
      "name": "Rock_Slate"
    },
    {
      "x": -3,
      "y": 23,
      "z": -2,
      "name": "Rock_Slate"
    },
    {
      "x": -3,
      "y": 24,
      "z": -2,
      "name": "Rock_Stone_Cobble"
    },
    {
      "x": -3,
      "y": 25,
      "z": -2,
      "name": "Rock_Stone_Cobble"
    },
    {
      "x": -3,
      "y": 26,
      "z": -2,
      "name": "Rock_Stone_Cobble"
    },
    {
      "x": -3,
      "y": 27,
      "z": -2,
      "name": "Rock_Basalt_Cobble_Roof",
      "rotation": 3
    },
    {
      "x": -3,
      "y": 8,
      "z": -1,
      "name": "Rock_Slate"
    },
    {
      "x": -3,
      "y": 9,
      "z": -1,
      "name": "Rock_Slate"
    },
    {
      "x": -3,
      "y": 10,
      "z": -1,
      "name": "Rock_Slate"
    },
    {
      "x": -3,
      "y": 11,
      "z": -1,
      "name": "Rock_Slate"
    },
    {
      "x": -3,
      "y": 12,
      "z": -1,
      "name": "Rock_Slate"
    },
    {
      "x": -3,
      "y": 13,
      "z": -1,
      "name": "Rock_Slate"
    },
    {
      "x": -3,
      "y": 14,
      "z": -1,
      "name": "Rock_Slate"
    },
    {
      "x": -3,
      "y": 15,
      "z": -1,
      "name": "Rock_Slate"
    },
    {
      "x": -3,
      "y": 16,
      "z": -1,
      "name": "Rock_Slate"
    },
    {
      "x": -3,
      "y": 17,
      "z": -1,
      "name": "Rock_Slate"
    },
    {
      "x": -3,
      "y": 18,
      "z": -1,
      "name": "Rock_Slate"
    },
    {
      "x": -3,
      "y": 19,
      "z": -1,
      "name": "Rock_Slate"
    },
    {
      "x": -3,
      "y": 20,
      "z": -1,
      "name": "Soil_Ash"
    },
    {
      "x": -3,
      "y": 21,
      "z": -1,
      "name": "Soil_Ash"
    },
    {
      "x": -3,
      "y": 22,
      "z": -1,
      "name": "Rock_Stone_Cobble"
    },
    {
      "x": -3,
      "y": 23,
      "z": -1,
      "name": "Rock_Stone_Cobble"
    },
    {
      "x": -3,
      "y": 9,
      "z": 0,
      "name": "Rock_Slate"
    },
    {
      "x": -3,
      "y": 10,
      "z": 0,
      "name": "Rock_Slate"
    },
    {
      "x": -3,
      "y": 11,
      "z": 0,
      "name": "Rock_Slate"
    },
    {
      "x": -3,
      "y": 12,
      "z": 0,
      "name": "Rock_Slate"
    },
    {
      "x": -3,
      "y": 13,
      "z": 0,
      "name": "Rock_Slate"
    },
    {
      "x": -3,
      "y": 14,
      "z": 0,
      "name": "Rock_Slate"
    },
    {
      "x": -3,
      "y": 15,
      "z": 0,
      "name": "Rock_Slate"
    },
    {
      "x": -3,
      "y": 16,
      "z": 0,
      "name": "Rock_Slate"
    },
    {
      "x": -3,
      "y": 17,
      "z": 0,
      "name": "Rock_Slate"
    },
    {
      "x": -3,
      "y": 18,
      "z": 0,
      "name": "Rock_Slate"
    },
    {
      "x": -3,
      "y": 19,
      "z": 0,
      "name": "Rock_Slate"
    },
    {
      "x": -3,
      "y": 20,
      "z": 0,
      "name": "Rock_Slate"
    },
    {
      "x": -3,
      "y": 21,
      "z": 0,
      "name": "Soil_Ash"
    },
    {
      "x": -3,
      "y": 22,
      "z": 0,
      "name": "Rock_Stone_Cobble"
    },
    {
      "x": -3,
      "y": 9,
      "z": 1,
      "name": "Rock_Slate"
    },
    {
      "x": -3,
      "y": 10,
      "z": 1,
      "name": "Rock_Slate"
    },
    {
      "x": -3,
      "y": 11,
      "z": 1,
      "name": "Rock_Slate"
    },
    {
      "x": -3,
      "y": 12,
      "z": 1,
      "name": "Rock_Slate"
    },
    {
      "x": -3,
      "y": 13,
      "z": 1,
      "name": "Rock_Slate"
    },
    {
      "x": -3,
      "y": 14,
      "z": 1,
      "name": "Rock_Slate"
    },
    {
      "x": -3,
      "y": 15,
      "z": 1,
      "name": "Rock_Slate"
    },
    {
      "x": -3,
      "y": 16,
      "z": 1,
      "name": "Rock_Slate"
    },
    {
      "x": -3,
      "y": 17,
      "z": 1,
      "name": "Rock_Slate"
    },
    {
      "x": -3,
      "y": 18,
      "z": 1,
      "name": "Rock_Slate"
    },
    {
      "x": -3,
      "y": 19,
      "z": 1,
      "name": "Rock_Slate"
    },
    {
      "x": -3,
      "y": 20,
      "z": 1,
      "name": "Rock_Slate"
    },
    {
      "x": -3,
      "y": 21,
      "z": 1,
      "name": "Rock_Slate"
    },
    {
      "x": -3,
      "y": 22,
      "z": 1,
      "name": "Rock_Stone_Cobble"
    },
    {
      "x": -3,
      "y": 9,
      "z": 2,
      "name": "Rock_Slate"
    },
    {
      "x": -3,
      "y": 10,
      "z": 2,
      "name": "Rock_Slate"
    },
    {
      "x": -3,
      "y": 11,
      "z": 2,
      "name": "Rock_Slate"
    },
    {
      "x": -3,
      "y": 12,
      "z": 2,
      "name": "Rock_Slate"
    },
    {
      "x": -3,
      "y": 13,
      "z": 2,
      "name": "Rock_Slate"
    },
    {
      "x": -2,
      "y": 26,
      "z": -5,
      "name": "Wood_Deadwood_Planks_Half",
      "rotation": 8
    },
    {
      "x": -2,
      "y": 10,
      "z": -4,
      "name": "Rock_Slate"
    },
    {
      "x": -2,
      "y": 11,
      "z": -4,
      "name": "Rock_Slate"
    },
    {
      "x": -2,
      "y": 12,
      "z": -4,
      "name": "Rock_Slate"
    },
    {
      "x": -2,
      "y": 13,
      "z": -4,
      "name": "Rock_Slate"
    },
    {
      "x": -2,
      "y": 14,
      "z": -4,
      "name": "Rock_Slate"
    },
    {
      "x": -2,
      "y": 15,
      "z": -4,
      "name": "Rock_Slate"
    },
    {
      "x": -2,
      "y": 16,
      "z": -4,
      "name": "Rock_Slate"
    },
    {
      "x": -2,
      "y": 17,
      "z": -4,
      "name": "Rock_Slate"
    },
    {
      "x": -2,
      "y": 18,
      "z": -4,
      "name": "Rock_Slate"
    },
    {
      "x": -2,
      "y": 19,
      "z": -4,
      "name": "Rock_Slate"
    },
    {
      "x": -2,
      "y": 20,
      "z": -4,
      "name": "Rock_Slate"
    },
    {
      "x": -2,
      "y": 21,
      "z": -4,
      "name": "Rock_Slate"
    },
    {
      "x": -2,
      "y": 22,
      "z": -4,
      "name": "Rock_Slate"
    },
    {
      "x": -2,
      "y": 23,
      "z": -4,
      "name": "Rock_Slate"
    },
    {
      "x": -2,
      "y": 24,
      "z": -4,
      "name": "Rock_Stone_Cobble"
    },
    {
      "x": -2,
      "y": 25,
      "z": -4,
      "name": "Rock_Stone_Cobble"
    },
    {
      "x": -2,
      "y": 26,
      "z": -4,
      "name": "Rock_Stone_Cobble"
    },
    {
      "x": -2,
      "y": 27,
      "z": -4,
      "name": "Rubble_Stone_Medium"
    },
    {
      "x": -2,
      "y": 8,
      "z": -3,
      "name": "Rock_Slate"
    },
    {
      "x": -2,
      "y": 9,
      "z": -3,
      "name": "Rock_Slate"
    },
    {
      "x": -2,
      "y": 10,
      "z": -3,
      "name": "Rock_Slate"
    },
    {
      "x": -2,
      "y": 11,
      "z": -3,
      "name": "Rock_Slate"
    },
    {
      "x": -2,
      "y": 12,
      "z": -3,
      "name": "Rock_Slate"
    },
    {
      "x": -2,
      "y": 13,
      "z": -3,
      "name": "Rock_Slate"
    },
    {
      "x": -2,
      "y": 14,
      "z": -3,
      "name": "Rock_Slate"
    },
    {
      "x": -2,
      "y": 15,
      "z": -3,
      "name": "Rock_Slate"
    },
    {
      "x": -2,
      "y": 16,
      "z": -3,
      "name": "Rock_Slate"
    },
    {
      "x": -2,
      "y": 17,
      "z": -3,
      "name": "Rock_Slate"
    },
    {
      "x": -2,
      "y": 18,
      "z": -3,
      "name": "Rock_Slate"
    },
    {
      "x": -2,
      "y": 19,
      "z": -3,
      "name": "Rock_Slate"
    },
    {
      "x": -2,
      "y": 20,
      "z": -3,
      "name": "Soil_Ash"
    },
    {
      "x": -2,
      "y": 21,
      "z": -3,
      "name": "Soil_Ash"
    },
    {
      "x": -2,
      "y": 22,
      "z": -3,
      "name": "Soil_Ash"
    },
    {
      "x": -2,
      "y": 23,
      "z": -3,
      "name": "Soil_Ash"
    },
    {
      "x": -2,
      "y": 24,
      "z": -3,
      "name": "Furniture_Ancient_Table"
    },
    {
      "x": -2,
      "y": 8,
      "z": -2,
      "name": "Rock_Slate"
    },
    {
      "x": -2,
      "y": 9,
      "z": -2,
      "name": "Rock_Slate"
    },
    {
      "x": -2,
      "y": 10,
      "z": -2,
      "name": "Rock_Slate"
    },
    {
      "x": -2,
      "y": 11,
      "z": -2,
      "name": "Rock_Slate"
    },
    {
      "x": -2,
      "y": 12,
      "z": -2,
      "name": "Rock_Slate"
    },
    {
      "x": -2,
      "y": 13,
      "z": -2,
      "name": "Rock_Slate"
    },
    {
      "x": -2,
      "y": 14,
      "z": -2,
      "name": "Rock_Slate"
    },
    {
      "x": -2,
      "y": 15,
      "z": -2,
      "name": "Rock_Slate"
    },
    {
      "x": -2,
      "y": 16,
      "z": -2,
      "name": "Rock_Slate"
    },
    {
      "x": -2,
      "y": 17,
      "z": -2,
      "name": "Rock_Slate"
    },
    {
      "x": -2,
      "y": 18,
      "z": -2,
      "name": "Rock_Slate"
    },
    {
      "x": -2,
      "y": 19,
      "z": -2,
      "name": "Rock_Slate"
    },
    {
      "x": -2,
      "y": 20,
      "z": -2,
      "name": "Soil_Ash"
    },
    {
      "x": -2,
      "y": 21,
      "z": -2,
      "name": "Soil_Ash"
    },
    {
      "x": -2,
      "y": 22,
      "z": -2,
      "name": "Soil_Ash"
    },
    {
      "x": -2,
      "y": 23,
      "z": -2,
      "name": "Soil_Ash"
    },
    {
      "x": -2,
      "y": 24,
      "z": -2,
      "name": "Furniture_Ancient_Table",
      "filler": 32
    },
    {
      "x": -2,
      "y": 1,
      "z": -1,
      "name": "Rock_Slate"
    },
    {
      "x": -2,
      "y": 2,
      "z": -1,
      "name": "Rock_Slate"
    },
    {
      "x": -2,
      "y": 3,
      "z": -1,
      "name": "Rock_Slate"
    },
    {
      "x": -2,
      "y": 4,
      "z": -1,
      "name": "Rock_Slate"
    },
    {
      "x": -2,
      "y": 5,
      "z": -1,
      "name": "Rock_Slate"
    },
    {
      "x": -2,
      "y": 6,
      "z": -1,
      "name": "Rock_Slate"
    },
    {
      "x": -2,
      "y": 7,
      "z": -1,
      "name": "Rock_Slate"
    },
    {
      "x": -2,
      "y": 8,
      "z": -1,
      "name": "Rock_Slate"
    },
    {
      "x": -2,
      "y": 9,
      "z": -1,
      "name": "Rock_Slate"
    },
    {
      "x": -2,
      "y": 10,
      "z": -1,
      "name": "Rock_Slate"
    },
    {
      "x": -2,
      "y": 11,
      "z": -1,
      "name": "Rock_Slate"
    },
    {
      "x": -2,
      "y": 12,
      "z": -1,
      "name": "Rock_Slate"
    },
    {
      "x": -2,
      "y": 13,
      "z": -1,
      "name": "Rock_Slate"
    },
    {
      "x": -2,
      "y": 14,
      "z": -1,
      "name": "Rock_Slate"
    },
    {
      "x": -2,
      "y": 15,
      "z": -1,
      "name": "Rock_Slate"
    },
    {
      "x": -2,
      "y": 16,
      "z": -1,
      "name": "Rock_Slate"
    },
    {
      "x": -2,
      "y": 17,
      "z": -1,
      "name": "Rock_Slate"
    },
    {
      "x": -2,
      "y": 18,
      "z": -1,
      "name": "Rock_Slate"
    },
    {
      "x": -2,
      "y": 19,
      "z": -1,
      "name": "Rock_Slate"
    },
    {
      "x": -2,
      "y": 20,
      "z": -1,
      "name": "Rock_Slate"
    },
    {
      "x": -2,
      "y": 21,
      "z": -1,
      "name": "Rock_Slate"
    },
    {
      "x": -2,
      "y": 22,
      "z": -1,
      "name": "Rock_Slate"
    },
    {
      "x": -2,
      "y": 23,
      "z": -1,
      "name": "Rock_Slate"
    },
    {
      "x": -2,
      "y": 24,
      "z": -1,
      "name": "Rubble_Stone"
    },
    {
      "x": -2,
      "y": 0,
      "z": 0,
      "name": "Rock_Slate"
    },
    {
      "x": -2,
      "y": 1,
      "z": 0,
      "name": "Rock_Slate"
    },
    {
      "x": -2,
      "y": 2,
      "z": 0,
      "name": "Rock_Slate"
    },
    {
      "x": -2,
      "y": 3,
      "z": 0,
      "name": "Rock_Slate"
    },
    {
      "x": -2,
      "y": 4,
      "z": 0,
      "name": "Rock_Slate"
    },
    {
      "x": -2,
      "y": 5,
      "z": 0,
      "name": "Rock_Slate"
    },
    {
      "x": -2,
      "y": 6,
      "z": 0,
      "name": "Rock_Slate"
    },
    {
      "x": -2,
      "y": 7,
      "z": 0,
      "name": "Rock_Slate"
    },
    {
      "x": -2,
      "y": 8,
      "z": 0,
      "name": "Rock_Slate"
    },
    {
      "x": -2,
      "y": 9,
      "z": 0,
      "name": "Rock_Slate"
    },
    {
      "x": -2,
      "y": 10,
      "z": 0,
      "name": "Rock_Slate"
    },
    {
      "x": -2,
      "y": 11,
      "z": 0,
      "name": "Rock_Slate"
    },
    {
      "x": -2,
      "y": 12,
      "z": 0,
      "name": "Rock_Slate"
    },
    {
      "x": -2,
      "y": 13,
      "z": 0,
      "name": "Rock_Slate"
    },
    {
      "x": -2,
      "y": 14,
      "z": 0,
      "name": "Rock_Slate"
    },
    {
      "x": -2,
      "y": 15,
      "z": 0,
      "name": "Rock_Slate"
    },
    {
      "x": -2,
      "y": 16,
      "z": 0,
      "name": "Rock_Slate"
    },
    {
      "x": -2,
      "y": 17,
      "z": 0,
      "name": "Rock_Slate"
    },
    {
      "x": -2,
      "y": 18,
      "z": 0,
      "name": "Rock_Slate"
    },
    {
      "x": -2,
      "y": 19,
      "z": 0,
      "name": "Rock_Slate"
    },
    {
      "x": -2,
      "y": 20,
      "z": 0,
      "name": "Rock_Slate"
    },
    {
      "x": -2,
      "y": 21,
      "z": 0,
      "name": "Soil_Ash"
    },
    {
      "x": -2,
      "y": 0,
      "z": 1,
      "name": "Rock_Slate"
    },
    {
      "x": -2,
      "y": 1,
      "z": 1,
      "name": "Rock_Slate"
    },
    {
      "x": -2,
      "y": 2,
      "z": 1,
      "name": "Rock_Slate"
    },
    {
      "x": -2,
      "y": 3,
      "z": 1,
      "name": "Rock_Slate"
    },
    {
      "x": -2,
      "y": 4,
      "z": 1,
      "name": "Rock_Slate"
    },
    {
      "x": -2,
      "y": 5,
      "z": 1,
      "name": "Rock_Slate"
    },
    {
      "x": -2,
      "y": 6,
      "z": 1,
      "name": "Rock_Slate"
    },
    {
      "x": -2,
      "y": 7,
      "z": 1,
      "name": "Rock_Slate"
    },
    {
      "x": -2,
      "y": 8,
      "z": 1,
      "name": "Rock_Slate"
    },
    {
      "x": -2,
      "y": 9,
      "z": 1,
      "name": "Rock_Slate"
    },
    {
      "x": -2,
      "y": 10,
      "z": 1,
      "name": "Rock_Slate"
    },
    {
      "x": -2,
      "y": 11,
      "z": 1,
      "name": "Rock_Slate"
    },
    {
      "x": -2,
      "y": 12,
      "z": 1,
      "name": "Rock_Slate"
    },
    {
      "x": -2,
      "y": 13,
      "z": 1,
      "name": "Rock_Slate"
    },
    {
      "x": -2,
      "y": 14,
      "z": 1,
      "name": "Rock_Slate"
    },
    {
      "x": -2,
      "y": 15,
      "z": 1,
      "name": "Rock_Slate"
    },
    {
      "x": -2,
      "y": 16,
      "z": 1,
      "name": "Rock_Slate"
    },
    {
      "x": -2,
      "y": 17,
      "z": 1,
      "name": "Rock_Slate"
    },
    {
      "x": -2,
      "y": 18,
      "z": 1,
      "name": "Rock_Slate"
    },
    {
      "x": -2,
      "y": 19,
      "z": 1,
      "name": "Rock_Slate"
    },
    {
      "x": -2,
      "y": 20,
      "z": 1,
      "name": "Rock_Slate"
    },
    {
      "x": -2,
      "y": 21,
      "z": 1,
      "name": "Rock_Slate"
    },
    {
      "x": -2,
      "y": 0,
      "z": 2,
      "name": "Rock_Slate"
    },
    {
      "x": -2,
      "y": 1,
      "z": 2,
      "name": "Rock_Slate"
    },
    {
      "x": -2,
      "y": 2,
      "z": 2,
      "name": "Rock_Slate"
    },
    {
      "x": -2,
      "y": 3,
      "z": 2,
      "name": "Rock_Slate"
    },
    {
      "x": -2,
      "y": 4,
      "z": 2,
      "name": "Rock_Slate"
    },
    {
      "x": -2,
      "y": 5,
      "z": 2,
      "name": "Rock_Slate"
    },
    {
      "x": -2,
      "y": 6,
      "z": 2,
      "name": "Rock_Slate"
    },
    {
      "x": -2,
      "y": 7,
      "z": 2,
      "name": "Rock_Slate"
    },
    {
      "x": -2,
      "y": 8,
      "z": 2,
      "name": "Rock_Slate"
    },
    {
      "x": -2,
      "y": 9,
      "z": 2,
      "name": "Rock_Slate"
    },
    {
      "x": -2,
      "y": 10,
      "z": 2,
      "name": "Rock_Slate"
    },
    {
      "x": -2,
      "y": 11,
      "z": 2,
      "name": "Rock_Slate"
    },
    {
      "x": -2,
      "y": 12,
      "z": 2,
      "name": "Rock_Slate"
    },
    {
      "x": -2,
      "y": 13,
      "z": 2,
      "name": "Rock_Slate"
    },
    {
      "x": -2,
      "y": 14,
      "z": 2,
      "name": "Rock_Slate"
    },
    {
      "x": -2,
      "y": 15,
      "z": 2,
      "name": "Rock_Slate"
    },
    {
      "x": -2,
      "y": 16,
      "z": 2,
      "name": "Rock_Slate"
    },
    {
      "x": -2,
      "y": 1,
      "z": 3,
      "name": "Rock_Slate"
    },
    {
      "x": -2,
      "y": 2,
      "z": 3,
      "name": "Rock_Slate"
    },
    {
      "x": -2,
      "y": 3,
      "z": 3,
      "name": "Rock_Slate"
    },
    {
      "x": -2,
      "y": 4,
      "z": 3,
      "name": "Rock_Slate"
    },
    {
      "x": -2,
      "y": 5,
      "z": 3,
      "name": "Rock_Slate"
    },
    {
      "x": -2,
      "y": 6,
      "z": 3,
      "name": "Rock_Slate"
    },
    {
      "x": -2,
      "y": 7,
      "z": 3,
      "name": "Rock_Slate"
    },
    {
      "x": -2,
      "y": 8,
      "z": 3,
      "name": "Rock_Slate"
    },
    {
      "x": -2,
      "y": 9,
      "z": 3,
      "name": "Rock_Slate"
    },
    {
      "x": -2,
      "y": 10,
      "z": 3,
      "name": "Rock_Slate"
    },
    {
      "x": -2,
      "y": 11,
      "z": 3,
      "name": "Rock_Slate"
    },
    {
      "x": -2,
      "y": 12,
      "z": 3,
      "name": "Rock_Slate"
    },
    {
      "x": -2,
      "y": 13,
      "z": 3,
      "name": "Rock_Slate"
    },
    {
      "x": -2,
      "y": 14,
      "z": 3,
      "name": "Rock_Slate"
    },
    {
      "x": -2,
      "y": 15,
      "z": 3,
      "name": "Rock_Slate"
    },
    {
      "x": -2,
      "y": 16,
      "z": 3,
      "name": "Plant_Bush_Dead_Twisted"
    },
    {
      "x": -2,
      "y": 5,
      "z": 4,
      "name": "Rock_Slate"
    },
    {
      "x": -2,
      "y": 6,
      "z": 4,
      "name": "Rock_Slate"
    },
    {
      "x": -2,
      "y": 7,
      "z": 4,
      "name": "Rock_Slate"
    },
    {
      "x": -2,
      "y": 8,
      "z": 4,
      "name": "Rock_Slate"
    },
    {
      "x": -2,
      "y": 9,
      "z": 4,
      "name": "Rock_Slate"
    },
    {
      "x": -2,
      "y": 10,
      "z": 4,
      "name": "Rock_Slate"
    },
    {
      "x": -2,
      "y": 11,
      "z": 4,
      "name": "Rock_Slate"
    },
    {
      "x": -2,
      "y": 12,
      "z": 4,
      "name": "Rock_Slate"
    },
    {
      "x": -2,
      "y": 13,
      "z": 4,
      "name": "Rock_Slate"
    },
    {
      "x": -2,
      "y": 14,
      "z": 4,
      "name": "Rock_Slate"
    },
    {
      "x": -2,
      "y": 15,
      "z": 4,
      "name": "Rock_Slate"
    },
    {
      "x": -1,
      "y": 11,
      "z": -5,
      "name": "Rock_Slate"
    },
    {
      "x": -1,
      "y": 12,
      "z": -5,
      "name": "Rock_Slate"
    },
    {
      "x": -1,
      "y": 13,
      "z": -5,
      "name": "Rock_Slate"
    },
    {
      "x": -1,
      "y": 14,
      "z": -5,
      "name": "Rock_Slate"
    },
    {
      "x": -1,
      "y": 15,
      "z": -5,
      "name": "Rock_Slate"
    },
    {
      "x": -1,
      "y": 16,
      "z": -5,
      "name": "Rock_Slate"
    },
    {
      "x": -1,
      "y": 17,
      "z": -5,
      "name": "Rock_Slate"
    },
    {
      "x": -1,
      "y": 18,
      "z": -5,
      "name": "Rock_Slate"
    },
    {
      "x": -1,
      "y": 19,
      "z": -5,
      "name": "Rock_Slate"
    },
    {
      "x": -1,
      "y": 20,
      "z": -5,
      "name": "Rock_Slate"
    },
    {
      "x": -1,
      "y": 21,
      "z": -5,
      "name": "Rock_Slate"
    },
    {
      "x": -1,
      "y": 22,
      "z": -5,
      "name": "Rock_Slate"
    },
    {
      "x": -1,
      "y": 23,
      "z": -5,
      "name": "Rock_Slate"
    },
    {
      "x": -1,
      "y": 8,
      "z": -4,
      "name": "Rock_Slate"
    },
    {
      "x": -1,
      "y": 9,
      "z": -4,
      "name": "Rock_Slate"
    },
    {
      "x": -1,
      "y": 10,
      "z": -4,
      "name": "Rock_Slate"
    },
    {
      "x": -1,
      "y": 11,
      "z": -4,
      "name": "Rock_Slate"
    },
    {
      "x": -1,
      "y": 12,
      "z": -4,
      "name": "Rock_Slate"
    },
    {
      "x": -1,
      "y": 13,
      "z": -4,
      "name": "Rock_Slate"
    },
    {
      "x": -1,
      "y": 14,
      "z": -4,
      "name": "Rock_Slate"
    },
    {
      "x": -1,
      "y": 15,
      "z": -4,
      "name": "Rock_Slate"
    },
    {
      "x": -1,
      "y": 16,
      "z": -4,
      "name": "Rock_Slate"
    },
    {
      "x": -1,
      "y": 17,
      "z": -4,
      "name": "Rock_Slate"
    },
    {
      "x": -1,
      "y": 18,
      "z": -4,
      "name": "Rock_Slate"
    },
    {
      "x": -1,
      "y": 19,
      "z": -4,
      "name": "Rock_Slate"
    },
    {
      "x": -1,
      "y": 20,
      "z": -4,
      "name": "Soil_Ash"
    },
    {
      "x": -1,
      "y": 21,
      "z": -4,
      "name": "Soil_Ash"
    },
    {
      "x": -1,
      "y": 22,
      "z": -4,
      "name": "Soil_Ash"
    },
    {
      "x": -1,
      "y": 23,
      "z": -4,
      "name": "Soil_Ash"
    },
    {
      "x": -1,
      "y": 24,
      "z": -4,
      "name": "Rock_Stone_Cobble"
    },
    {
      "x": -1,
      "y": 25,
      "z": -4,
      "name": "Rock_Stone_Cobble"
    },
    {
      "x": -1,
      "y": 8,
      "z": -3,
      "name": "Rock_Slate"
    },
    {
      "x": -1,
      "y": 9,
      "z": -3,
      "name": "Rock_Slate"
    },
    {
      "x": -1,
      "y": 10,
      "z": -3,
      "name": "Rock_Slate"
    },
    {
      "x": -1,
      "y": 11,
      "z": -3,
      "name": "Rock_Slate"
    },
    {
      "x": -1,
      "y": 12,
      "z": -3,
      "name": "Rock_Slate"
    },
    {
      "x": -1,
      "y": 13,
      "z": -3,
      "name": "Rock_Slate"
    },
    {
      "x": -1,
      "y": 14,
      "z": -3,
      "name": "Rock_Slate"
    },
    {
      "x": -1,
      "y": 15,
      "z": -3,
      "name": "Rock_Slate"
    },
    {
      "x": -1,
      "y": 16,
      "z": -3,
      "name": "Rock_Slate"
    },
    {
      "x": -1,
      "y": 17,
      "z": -3,
      "name": "Rock_Slate"
    },
    {
      "x": -1,
      "y": 18,
      "z": -3,
      "name": "Rock_Slate"
    },
    {
      "x": -1,
      "y": 19,
      "z": -3,
      "name": "Rock_Slate"
    },
    {
      "x": -1,
      "y": 20,
      "z": -3,
      "name": "Soil_Ash"
    },
    {
      "x": -1,
      "y": 21,
      "z": -3,
      "name": "Soil_Ash"
    },
    {
      "x": -1,
      "y": 22,
      "z": -3,
      "name": "Soil_Ash"
    },
    {
      "x": -1,
      "y": 23,
      "z": -3,
      "name": "Soil_Ash"
    },
    {
      "x": -1,
      "y": 24,
      "z": -3,
      "name": "Furniture_Ancient_Table",
      "filler": 1
    },
    {
      "x": -1,
      "y": 1,
      "z": -2,
      "name": "Rock_Slate"
    },
    {
      "x": -1,
      "y": 2,
      "z": -2,
      "name": "Rock_Slate"
    },
    {
      "x": -1,
      "y": 3,
      "z": -2,
      "name": "Rock_Slate"
    },
    {
      "x": -1,
      "y": 4,
      "z": -2,
      "name": "Rock_Slate"
    },
    {
      "x": -1,
      "y": 5,
      "z": -2,
      "name": "Rock_Slate"
    },
    {
      "x": -1,
      "y": 6,
      "z": -2,
      "name": "Rock_Slate"
    },
    {
      "x": -1,
      "y": 7,
      "z": -2,
      "name": "Rock_Slate"
    },
    {
      "x": -1,
      "y": 8,
      "z": -2,
      "name": "Rock_Slate"
    },
    {
      "x": -1,
      "y": 9,
      "z": -2,
      "name": "Rock_Slate"
    },
    {
      "x": -1,
      "y": 10,
      "z": -2,
      "name": "Rock_Slate"
    },
    {
      "x": -1,
      "y": 11,
      "z": -2,
      "name": "Rock_Slate"
    },
    {
      "x": -1,
      "y": 12,
      "z": -2,
      "name": "Rock_Slate"
    },
    {
      "x": -1,
      "y": 13,
      "z": -2,
      "name": "Rock_Slate"
    },
    {
      "x": -1,
      "y": 14,
      "z": -2,
      "name": "Rock_Slate"
    },
    {
      "x": -1,
      "y": 15,
      "z": -2,
      "name": "Rock_Slate"
    },
    {
      "x": -1,
      "y": 16,
      "z": -2,
      "name": "Rock_Slate"
    },
    {
      "x": -1,
      "y": 17,
      "z": -2,
      "name": "Rock_Slate"
    },
    {
      "x": -1,
      "y": 18,
      "z": -2,
      "name": "Rock_Slate"
    },
    {
      "x": -1,
      "y": 19,
      "z": -2,
      "name": "Rock_Slate"
    },
    {
      "x": -1,
      "y": 20,
      "z": -2,
      "name": "Soil_Ash"
    },
    {
      "x": -1,
      "y": 21,
      "z": -2,
      "name": "Soil_Ash"
    },
    {
      "x": -1,
      "y": 22,
      "z": -2,
      "name": "Soil_Ash"
    },
    {
      "x": -1,
      "y": 23,
      "z": -2,
      "name": "Soil_Ash"
    },
    {
      "x": -1,
      "y": 24,
      "z": -2,
      "name": "Furniture_Ancient_Table",
      "filler": 33
    },
    {
      "x": -1,
      "y": 0,
      "z": -1,
      "name": "Rock_Slate"
    },
    {
      "x": -1,
      "y": 1,
      "z": -1,
      "name": "Rock_Slate"
    },
    {
      "x": -1,
      "y": 2,
      "z": -1,
      "name": "Rock_Slate"
    },
    {
      "x": -1,
      "y": 3,
      "z": -1,
      "name": "Rock_Slate"
    },
    {
      "x": -1,
      "y": 4,
      "z": -1,
      "name": "Rock_Slate"
    },
    {
      "x": -1,
      "y": 5,
      "z": -1,
      "name": "Rock_Slate"
    },
    {
      "x": -1,
      "y": 6,
      "z": -1,
      "name": "Rock_Slate"
    },
    {
      "x": -1,
      "y": 7,
      "z": -1,
      "name": "Rock_Slate"
    },
    {
      "x": -1,
      "y": 8,
      "z": -1,
      "name": "Rock_Slate"
    },
    {
      "x": -1,
      "y": 9,
      "z": -1,
      "name": "Rock_Slate"
    },
    {
      "x": -1,
      "y": 10,
      "z": -1,
      "name": "Rock_Slate"
    },
    {
      "x": -1,
      "y": 11,
      "z": -1,
      "name": "Rock_Slate"
    },
    {
      "x": -1,
      "y": 12,
      "z": -1,
      "name": "Rock_Slate"
    },
    {
      "x": -1,
      "y": 13,
      "z": -1,
      "name": "Rock_Slate"
    },
    {
      "x": -1,
      "y": 14,
      "z": -1,
      "name": "Rock_Slate"
    },
    {
      "x": -1,
      "y": 15,
      "z": -1,
      "name": "Rock_Slate"
    },
    {
      "x": -1,
      "y": 16,
      "z": -1,
      "name": "Rock_Slate"
    },
    {
      "x": -1,
      "y": 17,
      "z": -1,
      "name": "Rock_Slate"
    },
    {
      "x": -1,
      "y": 18,
      "z": -1,
      "name": "Rock_Slate"
    },
    {
      "x": -1,
      "y": 19,
      "z": -1,
      "name": "Rock_Slate"
    },
    {
      "x": -1,
      "y": 20,
      "z": -1,
      "name": "Soil_Ash"
    },
    {
      "x": -1,
      "y": 21,
      "z": -1,
      "name": "Soil_Ash"
    },
    {
      "x": -1,
      "y": 22,
      "z": -1,
      "name": "Soil_Ash"
    },
    {
      "x": -1,
      "y": 23,
      "z": -1,
      "name": "Soil_Ash"
    },
    {
      "x": -1,
      "y": 0,
      "z": 0,
      "name": "Rock_Slate"
    },
    {
      "x": -1,
      "y": 1,
      "z": 0,
      "name": "Rock_Slate"
    },
    {
      "x": -1,
      "y": 2,
      "z": 0,
      "name": "Rock_Slate"
    },
    {
      "x": -1,
      "y": 3,
      "z": 0,
      "name": "Rock_Slate"
    },
    {
      "x": -1,
      "y": 4,
      "z": 0,
      "name": "Rock_Slate"
    },
    {
      "x": -1,
      "y": 5,
      "z": 0,
      "name": "Rock_Slate"
    },
    {
      "x": -1,
      "y": 6,
      "z": 0,
      "name": "Rock_Slate"
    },
    {
      "x": -1,
      "y": 7,
      "z": 0,
      "name": "Rock_Slate"
    },
    {
      "x": -1,
      "y": 8,
      "z": 0,
      "name": "Rock_Slate"
    },
    {
      "x": -1,
      "y": 9,
      "z": 0,
      "name": "Rock_Slate"
    },
    {
      "x": -1,
      "y": 10,
      "z": 0,
      "name": "Rock_Slate"
    },
    {
      "x": -1,
      "y": 11,
      "z": 0,
      "name": "Rock_Slate"
    },
    {
      "x": -1,
      "y": 12,
      "z": 0,
      "name": "Rock_Slate"
    },
    {
      "x": -1,
      "y": 13,
      "z": 0,
      "name": "Rock_Slate"
    },
    {
      "x": -1,
      "y": 14,
      "z": 0,
      "name": "Rock_Slate"
    },
    {
      "x": -1,
      "y": 15,
      "z": 0,
      "name": "Rock_Slate"
    },
    {
      "x": -1,
      "y": 16,
      "z": 0,
      "name": "Rock_Slate"
    },
    {
      "x": -1,
      "y": 17,
      "z": 0,
      "name": "Rock_Slate"
    },
    {
      "x": -1,
      "y": 18,
      "z": 0,
      "name": "Rock_Slate"
    },
    {
      "x": -1,
      "y": 19,
      "z": 0,
      "name": "Rock_Slate"
    },
    {
      "x": -1,
      "y": 20,
      "z": 0,
      "name": "Rock_Slate"
    },
    {
      "x": -1,
      "y": 21,
      "z": 0,
      "name": "Rock_Slate"
    },
    {
      "x": -1,
      "y": 22,
      "z": 0,
      "name": "Rock_Slate"
    },
    {
      "x": -1,
      "y": 23,
      "z": 0,
      "name": "Rock_Slate"
    },
    {
      "x": -1,
      "y": 0,
      "z": 1,
      "name": "Rock_Slate"
    },
    {
      "x": -1,
      "y": 1,
      "z": 1,
      "name": "Rock_Slate"
    },
    {
      "x": -1,
      "y": 2,
      "z": 1,
      "name": "Rock_Slate"
    },
    {
      "x": -1,
      "y": 3,
      "z": 1,
      "name": "Rock_Slate"
    },
    {
      "x": -1,
      "y": 4,
      "z": 1,
      "name": "Rock_Slate"
    },
    {
      "x": -1,
      "y": 5,
      "z": 1,
      "name": "Rock_Slate"
    },
    {
      "x": -1,
      "y": 6,
      "z": 1,
      "name": "Rock_Slate"
    },
    {
      "x": -1,
      "y": 7,
      "z": 1,
      "name": "Rock_Slate"
    },
    {
      "x": -1,
      "y": 8,
      "z": 1,
      "name": "Rock_Slate"
    },
    {
      "x": -1,
      "y": 9,
      "z": 1,
      "name": "Rock_Slate"
    },
    {
      "x": -1,
      "y": 10,
      "z": 1,
      "name": "Rock_Slate"
    },
    {
      "x": -1,
      "y": 11,
      "z": 1,
      "name": "Rock_Slate"
    },
    {
      "x": -1,
      "y": 12,
      "z": 1,
      "name": "Rock_Slate"
    },
    {
      "x": -1,
      "y": 13,
      "z": 1,
      "name": "Rock_Slate"
    },
    {
      "x": -1,
      "y": 14,
      "z": 1,
      "name": "Rock_Slate"
    },
    {
      "x": -1,
      "y": 15,
      "z": 1,
      "name": "Rock_Slate"
    },
    {
      "x": -1,
      "y": 16,
      "z": 1,
      "name": "Rock_Slate"
    },
    {
      "x": -1,
      "y": 17,
      "z": 1,
      "name": "Rock_Slate"
    },
    {
      "x": -1,
      "y": 18,
      "z": 1,
      "name": "Rock_Slate"
    },
    {
      "x": -1,
      "y": 19,
      "z": 1,
      "name": "Rock_Slate"
    },
    {
      "x": -1,
      "y": 20,
      "z": 1,
      "name": "Rock_Slate"
    },
    {
      "x": -1,
      "y": 21,
      "z": 1,
      "name": "Rock_Slate"
    },
    {
      "x": -1,
      "y": 0,
      "z": 2,
      "name": "Rock_Slate"
    },
    {
      "x": -1,
      "y": 1,
      "z": 2,
      "name": "Rock_Slate"
    },
    {
      "x": -1,
      "y": 2,
      "z": 2,
      "name": "Rock_Slate"
    },
    {
      "x": -1,
      "y": 3,
      "z": 2,
      "name": "Rock_Slate"
    },
    {
      "x": -1,
      "y": 4,
      "z": 2,
      "name": "Rock_Slate"
    },
    {
      "x": -1,
      "y": 5,
      "z": 2,
      "name": "Rock_Slate"
    },
    {
      "x": -1,
      "y": 6,
      "z": 2,
      "name": "Rock_Slate"
    },
    {
      "x": -1,
      "y": 7,
      "z": 2,
      "name": "Rock_Slate"
    },
    {
      "x": -1,
      "y": 8,
      "z": 2,
      "name": "Rock_Slate"
    },
    {
      "x": -1,
      "y": 9,
      "z": 2,
      "name": "Rock_Slate"
    },
    {
      "x": -1,
      "y": 10,
      "z": 2,
      "name": "Rock_Slate"
    },
    {
      "x": -1,
      "y": 11,
      "z": 2,
      "name": "Rock_Slate"
    },
    {
      "x": -1,
      "y": 12,
      "z": 2,
      "name": "Rock_Slate"
    },
    {
      "x": -1,
      "y": 13,
      "z": 2,
      "name": "Rock_Slate"
    },
    {
      "x": -1,
      "y": 14,
      "z": 2,
      "name": "Rock_Slate"
    },
    {
      "x": -1,
      "y": 15,
      "z": 2,
      "name": "Rock_Slate"
    },
    {
      "x": -1,
      "y": 16,
      "z": 2,
      "name": "Soil_Ash"
    },
    {
      "x": -1,
      "y": 17,
      "z": 2,
      "name": "Plant_Bush_Dead_Twisted"
    },
    {
      "x": -1,
      "y": 0,
      "z": 3,
      "name": "Rock_Slate"
    },
    {
      "x": -1,
      "y": 1,
      "z": 3,
      "name": "Rock_Slate"
    },
    {
      "x": -1,
      "y": 2,
      "z": 3,
      "name": "Rock_Slate"
    },
    {
      "x": -1,
      "y": 3,
      "z": 3,
      "name": "Rock_Slate"
    },
    {
      "x": -1,
      "y": 4,
      "z": 3,
      "name": "Rock_Slate"
    },
    {
      "x": -1,
      "y": 5,
      "z": 3,
      "name": "Rock_Slate"
    },
    {
      "x": -1,
      "y": 6,
      "z": 3,
      "name": "Rock_Slate"
    },
    {
      "x": -1,
      "y": 7,
      "z": 3,
      "name": "Rock_Slate"
    },
    {
      "x": -1,
      "y": 8,
      "z": 3,
      "name": "Rock_Slate"
    },
    {
      "x": -1,
      "y": 9,
      "z": 3,
      "name": "Rock_Slate"
    },
    {
      "x": -1,
      "y": 10,
      "z": 3,
      "name": "Rock_Slate"
    },
    {
      "x": -1,
      "y": 11,
      "z": 3,
      "name": "Rock_Slate"
    },
    {
      "x": -1,
      "y": 12,
      "z": 3,
      "name": "Rock_Slate"
    },
    {
      "x": -1,
      "y": 13,
      "z": 3,
      "name": "Rock_Slate"
    },
    {
      "x": -1,
      "y": 14,
      "z": 3,
      "name": "Rock_Slate"
    },
    {
      "x": -1,
      "y": 15,
      "z": 3,
      "name": "Soil_Ash"
    },
    {
      "x": -1,
      "y": 1,
      "z": 4,
      "name": "Rock_Slate"
    },
    {
      "x": -1,
      "y": 2,
      "z": 4,
      "name": "Rock_Slate"
    },
    {
      "x": -1,
      "y": 3,
      "z": 4,
      "name": "Rock_Slate"
    },
    {
      "x": -1,
      "y": 4,
      "z": 4,
      "name": "Rock_Slate"
    },
    {
      "x": -1,
      "y": 5,
      "z": 4,
      "name": "Rock_Slate"
    },
    {
      "x": -1,
      "y": 6,
      "z": 4,
      "name": "Rock_Slate"
    },
    {
      "x": -1,
      "y": 7,
      "z": 4,
      "name": "Rock_Slate"
    },
    {
      "x": -1,
      "y": 8,
      "z": 4,
      "name": "Rock_Slate"
    },
    {
      "x": -1,
      "y": 9,
      "z": 4,
      "name": "Rock_Slate"
    },
    {
      "x": -1,
      "y": 10,
      "z": 4,
      "name": "Rock_Slate"
    },
    {
      "x": -1,
      "y": 11,
      "z": 4,
      "name": "Rock_Slate"
    },
    {
      "x": -1,
      "y": 12,
      "z": 4,
      "name": "Rock_Slate"
    },
    {
      "x": -1,
      "y": 13,
      "z": 4,
      "name": "Rock_Slate"
    },
    {
      "x": -1,
      "y": 14,
      "z": 4,
      "name": "Rock_Slate"
    },
    {
      "x": -1,
      "y": 15,
      "z": 4,
      "name": "Soil_Ash"
    },
    {
      "x": -1,
      "y": 16,
      "z": 4,
      "name": "Rubble_Slate_Medium"
    },
    {
      "x": -1,
      "y": 8,
      "z": 5,
      "name": "Rock_Slate"
    },
    {
      "x": -1,
      "y": 9,
      "z": 5,
      "name": "Rock_Slate"
    },
    {
      "x": -1,
      "y": 10,
      "z": 5,
      "name": "Rock_Slate"
    },
    {
      "x": -1,
      "y": 11,
      "z": 5,
      "name": "Rock_Slate"
    },
    {
      "x": -1,
      "y": 12,
      "z": 5,
      "name": "Rock_Slate"
    },
    {
      "x": -1,
      "y": 13,
      "z": 5,
      "name": "Rock_Slate"
    },
    {
      "x": -1,
      "y": 14,
      "z": 5,
      "name": "Rock_Slate"
    },
    {
      "x": -1,
      "y": 15,
      "z": 5,
      "name": "Rock_Slate"
    },
    {
      "x": 0,
      "y": 20,
      "z": -6,
      "name": "Rock_Slate"
    },
    {
      "x": 0,
      "y": 21,
      "z": -6,
      "name": "Rock_Slate"
    },
    {
      "x": 0,
      "y": 22,
      "z": -6,
      "name": "Rock_Slate"
    },
    {
      "x": 0,
      "y": 23,
      "z": -6,
      "name": "Rock_Slate"
    },
    {
      "x": 0,
      "y": 9,
      "z": -5,
      "name": "Rock_Slate"
    },
    {
      "x": 0,
      "y": 10,
      "z": -5,
      "name": "Rock_Slate"
    },
    {
      "x": 0,
      "y": 11,
      "z": -5,
      "name": "Rock_Slate"
    },
    {
      "x": 0,
      "y": 12,
      "z": -5,
      "name": "Rock_Slate"
    },
    {
      "x": 0,
      "y": 13,
      "z": -5,
      "name": "Rock_Slate"
    },
    {
      "x": 0,
      "y": 14,
      "z": -5,
      "name": "Rock_Slate"
    },
    {
      "x": 0,
      "y": 15,
      "z": -5,
      "name": "Rock_Slate"
    },
    {
      "x": 0,
      "y": 16,
      "z": -5,
      "name": "Rock_Slate"
    },
    {
      "x": 0,
      "y": 17,
      "z": -5,
      "name": "Rock_Slate"
    },
    {
      "x": 0,
      "y": 18,
      "z": -5,
      "name": "Rock_Slate"
    },
    {
      "x": 0,
      "y": 19,
      "z": -5,
      "name": "Rock_Slate"
    },
    {
      "x": 0,
      "y": 20,
      "z": -5,
      "name": "Soil_Ash"
    },
    {
      "x": 0,
      "y": 21,
      "z": -5,
      "name": "Soil_Ash"
    },
    {
      "x": 0,
      "y": 22,
      "z": -5,
      "name": "Soil_Ash"
    },
    {
      "x": 0,
      "y": 23,
      "z": -5,
      "name": "Soil_Ash"
    },
    {
      "x": 0,
      "y": 8,
      "z": -4,
      "name": "Rock_Slate"
    },
    {
      "x": 0,
      "y": 9,
      "z": -4,
      "name": "Rock_Slate"
    },
    {
      "x": 0,
      "y": 10,
      "z": -4,
      "name": "Rock_Slate"
    },
    {
      "x": 0,
      "y": 11,
      "z": -4,
      "name": "Rock_Slate"
    },
    {
      "x": 0,
      "y": 12,
      "z": -4,
      "name": "Rock_Slate"
    },
    {
      "x": 0,
      "y": 13,
      "z": -4,
      "name": "Rock_Slate"
    },
    {
      "x": 0,
      "y": 14,
      "z": -4,
      "name": "Rock_Slate"
    },
    {
      "x": 0,
      "y": 15,
      "z": -4,
      "name": "Rock_Slate"
    },
    {
      "x": 0,
      "y": 16,
      "z": -4,
      "name": "Rock_Slate"
    },
    {
      "x": 0,
      "y": 17,
      "z": -4,
      "name": "Rock_Slate"
    },
    {
      "x": 0,
      "y": 18,
      "z": -4,
      "name": "Rock_Slate"
    },
    {
      "x": 0,
      "y": 19,
      "z": -4,
      "name": "Rock_Slate"
    },
    {
      "x": 0,
      "y": 20,
      "z": -4,
      "name": "Soil_Ash"
    },
    {
      "x": 0,
      "y": 21,
      "z": -4,
      "name": "Soil_Ash"
    },
    {
      "x": 0,
      "y": 22,
      "z": -4,
      "name": "Soil_Ash"
    },
    {
      "x": 0,
      "y": 23,
      "z": -4,
      "name": "Soil_Ash"
    },
    {
      "x": 0,
      "y": 24,
      "z": -4,
      "name": "Rock_Stone_Cobble"
    },
    {
      "x": 0,
      "y": 25,
      "z": -4,
      "name": "Rock_Stone_Cobble"
    },
    {
      "x": 0,
      "y": 26,
      "z": -4,
      "name": "Rock_Stone_Cobble_Half"
    },
    {
      "x": 0,
      "y": 8,
      "z": -3,
      "name": "Rock_Slate"
    },
    {
      "x": 0,
      "y": 9,
      "z": -3,
      "name": "Rock_Slate"
    },
    {
      "x": 0,
      "y": 10,
      "z": -3,
      "name": "Rock_Slate"
    },
    {
      "x": 0,
      "y": 11,
      "z": -3,
      "name": "Rock_Slate"
    },
    {
      "x": 0,
      "y": 12,
      "z": -3,
      "name": "Rock_Slate"
    },
    {
      "x": 0,
      "y": 13,
      "z": -3,
      "name": "Rock_Slate"
    },
    {
      "x": 0,
      "y": 14,
      "z": -3,
      "name": "Rock_Slate"
    },
    {
      "x": 0,
      "y": 15,
      "z": -3,
      "name": "Rock_Slate"
    },
    {
      "x": 0,
      "y": 16,
      "z": -3,
      "name": "Rock_Slate"
    },
    {
      "x": 0,
      "y": 17,
      "z": -3,
      "name": "Rock_Slate"
    },
    {
      "x": 0,
      "y": 18,
      "z": -3,
      "name": "Rock_Slate"
    },
    {
      "x": 0,
      "y": 19,
      "z": -3,
      "name": "Rock_Slate"
    },
    {
      "x": 0,
      "y": 20,
      "z": -3,
      "name": "Soil_Ash"
    },
    {
      "x": 0,
      "y": 21,
      "z": -3,
      "name": "Soil_Ash"
    },
    {
      "x": 0,
      "y": 22,
      "z": -3,
      "name": "Soil_Ash"
    },
    {
      "x": 0,
      "y": 23,
      "z": -3,
      "name": "Soil_Ash"
    },
    {
      "x": 0,
      "y": 24,
      "z": -3,
      "name": "Furniture_Ancient_Chair",
      "rotation": 3
    },
    {
      "x": 0,
      "y": 0,
      "z": -2,
      "name": "Rock_Slate"
    },
    {
      "x": 0,
      "y": 1,
      "z": -2,
      "name": "Rock_Slate"
    },
    {
      "x": 0,
      "y": 2,
      "z": -2,
      "name": "Rock_Slate"
    },
    {
      "x": 0,
      "y": 3,
      "z": -2,
      "name": "Rock_Slate"
    },
    {
      "x": 0,
      "y": 4,
      "z": -2,
      "name": "Rock_Slate"
    },
    {
      "x": 0,
      "y": 5,
      "z": -2,
      "name": "Rock_Slate"
    },
    {
      "x": 0,
      "y": 6,
      "z": -2,
      "name": "Rock_Slate"
    },
    {
      "x": 0,
      "y": 7,
      "z": -2,
      "name": "Rock_Slate"
    },
    {
      "x": 0,
      "y": 8,
      "z": -2,
      "name": "Rock_Slate"
    },
    {
      "x": 0,
      "y": 9,
      "z": -2,
      "name": "Rock_Slate"
    },
    {
      "x": 0,
      "y": 10,
      "z": -2,
      "name": "Rock_Slate"
    },
    {
      "x": 0,
      "y": 11,
      "z": -2,
      "name": "Rock_Slate"
    },
    {
      "x": 0,
      "y": 12,
      "z": -2,
      "name": "Rock_Slate"
    },
    {
      "x": 0,
      "y": 13,
      "z": -2,
      "name": "Rock_Slate"
    },
    {
      "x": 0,
      "y": 14,
      "z": -2,
      "name": "Rock_Slate"
    },
    {
      "x": 0,
      "y": 15,
      "z": -2,
      "name": "Rock_Slate"
    },
    {
      "x": 0,
      "y": 16,
      "z": -2,
      "name": "Rock_Slate"
    },
    {
      "x": 0,
      "y": 17,
      "z": -2,
      "name": "Rock_Slate"
    },
    {
      "x": 0,
      "y": 18,
      "z": -2,
      "name": "Rock_Slate"
    },
    {
      "x": 0,
      "y": 19,
      "z": -2,
      "name": "Rock_Slate"
    },
    {
      "x": 0,
      "y": 20,
      "z": -2,
      "name": "Soil_Ash"
    },
    {
      "x": 0,
      "y": 21,
      "z": -2,
      "name": "Soil_Ash"
    },
    {
      "x": 0,
      "y": 22,
      "z": -2,
      "name": "Soil_Ash"
    },
    {
      "x": 0,
      "y": 23,
      "z": -2,
      "name": "Soil_Ash"
    },
    {
      "x": 0,
      "y": 24,
      "z": -2,
      "name": "Rubble_Slate"
    },
    {
      "x": 0,
      "y": 0,
      "z": -1,
      "name": "Rock_Slate"
    },
    {
      "x": 0,
      "y": 1,
      "z": -1,
      "name": "Rock_Slate"
    },
    {
      "x": 0,
      "y": 2,
      "z": -1,
      "name": "Rock_Slate"
    },
    {
      "x": 0,
      "y": 3,
      "z": -1,
      "name": "Rock_Slate"
    },
    {
      "x": 0,
      "y": 4,
      "z": -1,
      "name": "Rock_Slate"
    },
    {
      "x": 0,
      "y": 5,
      "z": -1,
      "name": "Rock_Slate"
    },
    {
      "x": 0,
      "y": 6,
      "z": -1,
      "name": "Rock_Slate"
    },
    {
      "x": 0,
      "y": 7,
      "z": -1,
      "name": "Rock_Slate"
    },
    {
      "x": 0,
      "y": 8,
      "z": -1,
      "name": "Rock_Slate"
    },
    {
      "x": 0,
      "y": 9,
      "z": -1,
      "name": "Rock_Slate"
    },
    {
      "x": 0,
      "y": 10,
      "z": -1,
      "name": "Rock_Slate"
    },
    {
      "x": 0,
      "y": 11,
      "z": -1,
      "name": "Rock_Slate"
    },
    {
      "x": 0,
      "y": 12,
      "z": -1,
      "name": "Rock_Slate"
    },
    {
      "x": 0,
      "y": 13,
      "z": -1,
      "name": "Rock_Slate"
    },
    {
      "x": 0,
      "y": 14,
      "z": -1,
      "name": "Rock_Slate"
    },
    {
      "x": 0,
      "y": 15,
      "z": -1,
      "name": "Rock_Slate"
    },
    {
      "x": 0,
      "y": 16,
      "z": -1,
      "name": "Rock_Slate"
    },
    {
      "x": 0,
      "y": 17,
      "z": -1,
      "name": "Rock_Slate"
    },
    {
      "x": 0,
      "y": 18,
      "z": -1,
      "name": "Rock_Slate"
    },
    {
      "x": 0,
      "y": 19,
      "z": -1,
      "name": "Rock_Slate"
    },
    {
      "x": 0,
      "y": 20,
      "z": -1,
      "name": "Soil_Ash"
    },
    {
      "x": 0,
      "y": 21,
      "z": -1,
      "name": "Soil_Ash"
    },
    {
      "x": 0,
      "y": 22,
      "z": -1,
      "name": "Soil_Ash"
    },
    {
      "x": 0,
      "y": 23,
      "z": -1,
      "name": "Soil_Ash"
    },
    {
      "x": 0,
      "y": 0,
      "z": 0,
      "name": "Rock_Slate"
    },
    {
      "x": 0,
      "y": 1,
      "z": 0,
      "name": "Rock_Slate"
    },
    {
      "x": 0,
      "y": 2,
      "z": 0,
      "name": "Rock_Slate"
    },
    {
      "x": 0,
      "y": 3,
      "z": 0,
      "name": "Rock_Slate"
    },
    {
      "x": 0,
      "y": 4,
      "z": 0,
      "name": "Rock_Slate"
    },
    {
      "x": 0,
      "y": 5,
      "z": 0,
      "name": "Rock_Slate"
    },
    {
      "x": 0,
      "y": 6,
      "z": 0,
      "name": "Rock_Slate"
    },
    {
      "x": 0,
      "y": 7,
      "z": 0,
      "name": "Rock_Slate"
    },
    {
      "x": 0,
      "y": 8,
      "z": 0,
      "name": "Rock_Slate"
    },
    {
      "x": 0,
      "y": 9,
      "z": 0,
      "name": "Rock_Slate"
    },
    {
      "x": 0,
      "y": 10,
      "z": 0,
      "name": "Rock_Slate"
    },
    {
      "x": 0,
      "y": 11,
      "z": 0,
      "name": "Rock_Slate"
    },
    {
      "x": 0,
      "y": 12,
      "z": 0,
      "name": "Rock_Slate"
    },
    {
      "x": 0,
      "y": 13,
      "z": 0,
      "name": "Rock_Slate"
    },
    {
      "x": 0,
      "y": 14,
      "z": 0,
      "name": "Rock_Slate"
    },
    {
      "x": 0,
      "y": 15,
      "z": 0,
      "name": "Rock_Slate"
    },
    {
      "x": 0,
      "y": 16,
      "z": 0,
      "name": "Rock_Slate"
    },
    {
      "x": 0,
      "y": 17,
      "z": 0,
      "name": "Rock_Slate"
    },
    {
      "x": 0,
      "y": 18,
      "z": 0,
      "name": "Rock_Slate"
    },
    {
      "x": 0,
      "y": 19,
      "z": 0,
      "name": "Rock_Slate"
    },
    {
      "x": 0,
      "y": 20,
      "z": 0,
      "name": "Soil_Ash"
    },
    {
      "x": 0,
      "y": 21,
      "z": 0,
      "name": "Soil_Ash"
    },
    {
      "x": 0,
      "y": 22,
      "z": 0,
      "name": "Soil_Ash"
    },
    {
      "x": 0,
      "y": 23,
      "z": 0,
      "name": "Soil_Ash"
    },
    {
      "x": 0,
      "y": 0,
      "z": 1,
      "name": "Rock_Slate"
    },
    {
      "x": 0,
      "y": 1,
      "z": 1,
      "name": "Rock_Slate"
    },
    {
      "x": 0,
      "y": 2,
      "z": 1,
      "name": "Rock_Slate"
    },
    {
      "x": 0,
      "y": 3,
      "z": 1,
      "name": "Rock_Slate"
    },
    {
      "x": 0,
      "y": 4,
      "z": 1,
      "name": "Rock_Slate"
    },
    {
      "x": 0,
      "y": 5,
      "z": 1,
      "name": "Rock_Slate"
    },
    {
      "x": 0,
      "y": 6,
      "z": 1,
      "name": "Rock_Slate"
    },
    {
      "x": 0,
      "y": 7,
      "z": 1,
      "name": "Rock_Slate"
    },
    {
      "x": 0,
      "y": 8,
      "z": 1,
      "name": "Rock_Slate"
    },
    {
      "x": 0,
      "y": 9,
      "z": 1,
      "name": "Rock_Slate"
    },
    {
      "x": 0,
      "y": 10,
      "z": 1,
      "name": "Rock_Slate"
    },
    {
      "x": 0,
      "y": 11,
      "z": 1,
      "name": "Rock_Slate"
    },
    {
      "x": 0,
      "y": 12,
      "z": 1,
      "name": "Rock_Slate"
    },
    {
      "x": 0,
      "y": 13,
      "z": 1,
      "name": "Rock_Slate"
    },
    {
      "x": 0,
      "y": 14,
      "z": 1,
      "name": "Rock_Slate"
    },
    {
      "x": 0,
      "y": 15,
      "z": 1,
      "name": "Rock_Slate"
    },
    {
      "x": 0,
      "y": 16,
      "z": 1,
      "name": "Soil_Ash"
    },
    {
      "x": 0,
      "y": 17,
      "z": 1,
      "name": "Plant_Bush_Dead_Twisted"
    },
    {
      "x": 0,
      "y": 0,
      "z": 2,
      "name": "Rock_Slate"
    },
    {
      "x": 0,
      "y": 1,
      "z": 2,
      "name": "Rock_Slate"
    },
    {
      "x": 0,
      "y": 2,
      "z": 2,
      "name": "Rock_Slate"
    },
    {
      "x": 0,
      "y": 3,
      "z": 2,
      "name": "Rock_Slate"
    },
    {
      "x": 0,
      "y": 4,
      "z": 2,
      "name": "Rock_Slate"
    },
    {
      "x": 0,
      "y": 5,
      "z": 2,
      "name": "Rock_Slate"
    },
    {
      "x": 0,
      "y": 6,
      "z": 2,
      "name": "Rock_Slate"
    },
    {
      "x": 0,
      "y": 7,
      "z": 2,
      "name": "Rock_Slate"
    },
    {
      "x": 0,
      "y": 8,
      "z": 2,
      "name": "Rock_Slate"
    },
    {
      "x": 0,
      "y": 9,
      "z": 2,
      "name": "Rock_Slate"
    },
    {
      "x": 0,
      "y": 10,
      "z": 2,
      "name": "Rock_Slate"
    },
    {
      "x": 0,
      "y": 11,
      "z": 2,
      "name": "Rock_Slate"
    },
    {
      "x": 0,
      "y": 12,
      "z": 2,
      "name": "Rock_Slate"
    },
    {
      "x": 0,
      "y": 13,
      "z": 2,
      "name": "Rock_Slate"
    },
    {
      "x": 0,
      "y": 14,
      "z": 2,
      "name": "Rock_Slate"
    },
    {
      "x": 0,
      "y": 15,
      "z": 2,
      "name": "Rock_Slate"
    },
    {
      "x": 0,
      "y": 16,
      "z": 2,
      "name": "Soil_Ash"
    },
    {
      "x": 0,
      "y": 17,
      "z": 2,
      "name": "Plant_Bush_Dead_Twisted"
    },
    {
      "x": 0,
      "y": 0,
      "z": 3,
      "name": "Rock_Slate"
    },
    {
      "x": 0,
      "y": 1,
      "z": 3,
      "name": "Rock_Slate"
    },
    {
      "x": 0,
      "y": 2,
      "z": 3,
      "name": "Rock_Slate"
    },
    {
      "x": 0,
      "y": 3,
      "z": 3,
      "name": "Rock_Slate"
    },
    {
      "x": 0,
      "y": 4,
      "z": 3,
      "name": "Rock_Slate"
    },
    {
      "x": 0,
      "y": 5,
      "z": 3,
      "name": "Rock_Slate"
    },
    {
      "x": 0,
      "y": 6,
      "z": 3,
      "name": "Rock_Slate"
    },
    {
      "x": 0,
      "y": 7,
      "z": 3,
      "name": "Rock_Slate"
    },
    {
      "x": 0,
      "y": 8,
      "z": 3,
      "name": "Rock_Slate"
    },
    {
      "x": 0,
      "y": 9,
      "z": 3,
      "name": "Rock_Slate"
    },
    {
      "x": 0,
      "y": 10,
      "z": 3,
      "name": "Rock_Slate"
    },
    {
      "x": 0,
      "y": 11,
      "z": 3,
      "name": "Rock_Slate"
    },
    {
      "x": 0,
      "y": 12,
      "z": 3,
      "name": "Rock_Slate"
    },
    {
      "x": 0,
      "y": 13,
      "z": 3,
      "name": "Rock_Slate"
    },
    {
      "x": 0,
      "y": 14,
      "z": 3,
      "name": "Rock_Slate"
    },
    {
      "x": 0,
      "y": 15,
      "z": 3,
      "name": "Soil_Ash"
    },
    {
      "x": 0,
      "y": 16,
      "z": 3,
      "name": "Soil_Ash"
    },
    {
      "x": 0,
      "y": 0,
      "z": 4,
      "name": "Rock_Slate"
    },
    {
      "x": 0,
      "y": 1,
      "z": 4,
      "name": "Rock_Slate"
    },
    {
      "x": 0,
      "y": 2,
      "z": 4,
      "name": "Rock_Slate"
    },
    {
      "x": 0,
      "y": 3,
      "z": 4,
      "name": "Rock_Slate"
    },
    {
      "x": 0,
      "y": 4,
      "z": 4,
      "name": "Rock_Slate"
    },
    {
      "x": 0,
      "y": 5,
      "z": 4,
      "name": "Rock_Slate"
    },
    {
      "x": 0,
      "y": 6,
      "z": 4,
      "name": "Rock_Slate"
    },
    {
      "x": 0,
      "y": 7,
      "z": 4,
      "name": "Rock_Slate"
    },
    {
      "x": 0,
      "y": 8,
      "z": 4,
      "name": "Rock_Slate"
    },
    {
      "x": 0,
      "y": 9,
      "z": 4,
      "name": "Rock_Slate"
    },
    {
      "x": 0,
      "y": 10,
      "z": 4,
      "name": "Rock_Slate"
    },
    {
      "x": 0,
      "y": 11,
      "z": 4,
      "name": "Rock_Slate"
    },
    {
      "x": 0,
      "y": 12,
      "z": 4,
      "name": "Rock_Slate"
    },
    {
      "x": 0,
      "y": 13,
      "z": 4,
      "name": "Rock_Slate"
    },
    {
      "x": 0,
      "y": 14,
      "z": 4,
      "name": "Rock_Slate"
    },
    {
      "x": 0,
      "y": 15,
      "z": 4,
      "name": "Soil_Ash"
    },
    {
      "x": 0,
      "y": 1,
      "z": 5,
      "name": "Rock_Slate"
    },
    {
      "x": 0,
      "y": 2,
      "z": 5,
      "name": "Rock_Slate"
    },
    {
      "x": 0,
      "y": 3,
      "z": 5,
      "name": "Rock_Slate"
    },
    {
      "x": 0,
      "y": 4,
      "z": 5,
      "name": "Rock_Slate"
    },
    {
      "x": 0,
      "y": 5,
      "z": 5,
      "name": "Rock_Slate"
    },
    {
      "x": 0,
      "y": 6,
      "z": 5,
      "name": "Rock_Slate"
    },
    {
      "x": 0,
      "y": 7,
      "z": 5,
      "name": "Rock_Slate"
    },
    {
      "x": 0,
      "y": 8,
      "z": 5,
      "name": "Rock_Slate"
    },
    {
      "x": 0,
      "y": 9,
      "z": 5,
      "name": "Rock_Slate"
    },
    {
      "x": 0,
      "y": 10,
      "z": 5,
      "name": "Rock_Slate"
    },
    {
      "x": 0,
      "y": 11,
      "z": 5,
      "name": "Rock_Slate"
    },
    {
      "x": 0,
      "y": 12,
      "z": 5,
      "name": "Rock_Slate"
    },
    {
      "x": 0,
      "y": 13,
      "z": 5,
      "name": "Rock_Slate"
    },
    {
      "x": 0,
      "y": 14,
      "z": 5,
      "name": "Soil_Ash"
    },
    {
      "x": 0,
      "y": 15,
      "z": 5,
      "name": "Soil_Ash"
    },
    {
      "x": 0,
      "y": 12,
      "z": 6,
      "name": "Rock_Slate"
    },
    {
      "x": 0,
      "y": 13,
      "z": 6,
      "name": "Rock_Slate"
    },
    {
      "x": 0,
      "y": 14,
      "z": 6,
      "name": "Rock_Slate"
    },
    {
      "x": 0,
      "y": 15,
      "z": 6,
      "name": "Rock_Slate"
    },
    {
      "x": 1,
      "y": 20,
      "z": -6,
      "name": "Rock_Slate"
    },
    {
      "x": 1,
      "y": 21,
      "z": -6,
      "name": "Rock_Slate"
    },
    {
      "x": 1,
      "y": 22,
      "z": -6,
      "name": "Rock_Slate"
    },
    {
      "x": 1,
      "y": 23,
      "z": -6,
      "name": "Rock_Slate"
    },
    {
      "x": 1,
      "y": 10,
      "z": -5,
      "name": "Rock_Slate"
    },
    {
      "x": 1,
      "y": 11,
      "z": -5,
      "name": "Rock_Slate"
    },
    {
      "x": 1,
      "y": 12,
      "z": -5,
      "name": "Rock_Slate"
    },
    {
      "x": 1,
      "y": 13,
      "z": -5,
      "name": "Rock_Slate"
    },
    {
      "x": 1,
      "y": 14,
      "z": -5,
      "name": "Rock_Slate"
    },
    {
      "x": 1,
      "y": 15,
      "z": -5,
      "name": "Rock_Slate"
    },
    {
      "x": 1,
      "y": 16,
      "z": -5,
      "name": "Rock_Slate"
    },
    {
      "x": 1,
      "y": 17,
      "z": -5,
      "name": "Rock_Slate"
    },
    {
      "x": 1,
      "y": 18,
      "z": -5,
      "name": "Rock_Slate"
    },
    {
      "x": 1,
      "y": 19,
      "z": -5,
      "name": "Rock_Slate"
    },
    {
      "x": 1,
      "y": 20,
      "z": -5,
      "name": "Soil_Ash"
    },
    {
      "x": 1,
      "y": 21,
      "z": -5,
      "name": "Soil_Ash"
    },
    {
      "x": 1,
      "y": 22,
      "z": -5,
      "name": "Soil_Ash"
    },
    {
      "x": 1,
      "y": 23,
      "z": -5,
      "name": "Soil_Ash"
    },
    {
      "x": 1,
      "y": 8,
      "z": -4,
      "name": "Rock_Slate"
    },
    {
      "x": 1,
      "y": 9,
      "z": -4,
      "name": "Rock_Slate"
    },
    {
      "x": 1,
      "y": 10,
      "z": -4,
      "name": "Rock_Slate"
    },
    {
      "x": 1,
      "y": 11,
      "z": -4,
      "name": "Rock_Slate"
    },
    {
      "x": 1,
      "y": 12,
      "z": -4,
      "name": "Rock_Slate"
    },
    {
      "x": 1,
      "y": 13,
      "z": -4,
      "name": "Rock_Slate"
    },
    {
      "x": 1,
      "y": 14,
      "z": -4,
      "name": "Rock_Slate"
    },
    {
      "x": 1,
      "y": 15,
      "z": -4,
      "name": "Rock_Slate"
    },
    {
      "x": 1,
      "y": 16,
      "z": -4,
      "name": "Rock_Slate"
    },
    {
      "x": 1,
      "y": 17,
      "z": -4,
      "name": "Rock_Slate"
    },
    {
      "x": 1,
      "y": 18,
      "z": -4,
      "name": "Rock_Slate"
    },
    {
      "x": 1,
      "y": 19,
      "z": -4,
      "name": "Rock_Slate"
    },
    {
      "x": 1,
      "y": 20,
      "z": -4,
      "name": "Soil_Ash"
    },
    {
      "x": 1,
      "y": 21,
      "z": -4,
      "name": "Soil_Ash"
    },
    {
      "x": 1,
      "y": 22,
      "z": -4,
      "name": "Soil_Ash"
    },
    {
      "x": 1,
      "y": 23,
      "z": -4,
      "name": "Soil_Ash"
    },
    {
      "x": 1,
      "y": 24,
      "z": -4,
      "name": "Furniture_Ancient_Door",
      "rotation": 2
    },
    {
      "x": 1,
      "y": 25,
      "z": -4,
      "name": "Furniture_Ancient_Door",
      "filler": 1024,
      "rotation": 2
    },
    {
      "x": 1,
      "y": 8,
      "z": -3,
      "name": "Rock_Slate"
    },
    {
      "x": 1,
      "y": 9,
      "z": -3,
      "name": "Rock_Slate"
    },
    {
      "x": 1,
      "y": 10,
      "z": -3,
      "name": "Rock_Slate"
    },
    {
      "x": 1,
      "y": 11,
      "z": -3,
      "name": "Rock_Slate"
    },
    {
      "x": 1,
      "y": 12,
      "z": -3,
      "name": "Rock_Slate"
    },
    {
      "x": 1,
      "y": 13,
      "z": -3,
      "name": "Rock_Slate"
    },
    {
      "x": 1,
      "y": 14,
      "z": -3,
      "name": "Rock_Slate"
    },
    {
      "x": 1,
      "y": 15,
      "z": -3,
      "name": "Rock_Slate"
    },
    {
      "x": 1,
      "y": 16,
      "z": -3,
      "name": "Rock_Slate"
    },
    {
      "x": 1,
      "y": 17,
      "z": -3,
      "name": "Rock_Slate"
    },
    {
      "x": 1,
      "y": 18,
      "z": -3,
      "name": "Rock_Slate"
    },
    {
      "x": 1,
      "y": 19,
      "z": -3,
      "name": "Rock_Slate"
    },
    {
      "x": 1,
      "y": 20,
      "z": -3,
      "name": "Soil_Ash"
    },
    {
      "x": 1,
      "y": 21,
      "z": -3,
      "name": "Soil_Ash"
    },
    {
      "x": 1,
      "y": 22,
      "z": -3,
      "name": "Soil_Ash"
    },
    {
      "x": 1,
      "y": 23,
      "z": -3,
      "name": "Soil_Ash"
    },
    {
      "x": 1,
      "y": 0,
      "z": -2,
      "name": "Rock_Slate"
    },
    {
      "x": 1,
      "y": 1,
      "z": -2,
      "name": "Rock_Slate"
    },
    {
      "x": 1,
      "y": 2,
      "z": -2,
      "name": "Rock_Slate"
    },
    {
      "x": 1,
      "y": 3,
      "z": -2,
      "name": "Rock_Slate"
    },
    {
      "x": 1,
      "y": 4,
      "z": -2,
      "name": "Rock_Slate"
    },
    {
      "x": 1,
      "y": 5,
      "z": -2,
      "name": "Rock_Slate"
    },
    {
      "x": 1,
      "y": 6,
      "z": -2,
      "name": "Rock_Slate"
    },
    {
      "x": 1,
      "y": 7,
      "z": -2,
      "name": "Rock_Slate"
    },
    {
      "x": 1,
      "y": 8,
      "z": -2,
      "name": "Rock_Slate"
    },
    {
      "x": 1,
      "y": 9,
      "z": -2,
      "name": "Rock_Slate"
    },
    {
      "x": 1,
      "y": 10,
      "z": -2,
      "name": "Rock_Slate"
    },
    {
      "x": 1,
      "y": 11,
      "z": -2,
      "name": "Rock_Slate"
    },
    {
      "x": 1,
      "y": 12,
      "z": -2,
      "name": "Rock_Slate"
    },
    {
      "x": 1,
      "y": 13,
      "z": -2,
      "name": "Rock_Slate"
    },
    {
      "x": 1,
      "y": 14,
      "z": -2,
      "name": "Rock_Slate"
    },
    {
      "x": 1,
      "y": 15,
      "z": -2,
      "name": "Rock_Slate"
    },
    {
      "x": 1,
      "y": 16,
      "z": -2,
      "name": "Rock_Slate"
    },
    {
      "x": 1,
      "y": 17,
      "z": -2,
      "name": "Rock_Slate"
    },
    {
      "x": 1,
      "y": 18,
      "z": -2,
      "name": "Rock_Slate"
    },
    {
      "x": 1,
      "y": 19,
      "z": -2,
      "name": "Rock_Slate"
    },
    {
      "x": 1,
      "y": 20,
      "z": -2,
      "name": "Soil_Ash"
    },
    {
      "x": 1,
      "y": 21,
      "z": -2,
      "name": "Soil_Ash"
    },
    {
      "x": 1,
      "y": 22,
      "z": -2,
      "name": "Soil_Ash"
    },
    {
      "x": 1,
      "y": 23,
      "z": -2,
      "name": "Soil_Ash"
    },
    {
      "x": 1,
      "y": 0,
      "z": -1,
      "name": "Rock_Slate"
    },
    {
      "x": 1,
      "y": 1,
      "z": -1,
      "name": "Rock_Slate"
    },
    {
      "x": 1,
      "y": 2,
      "z": -1,
      "name": "Rock_Slate"
    },
    {
      "x": 1,
      "y": 3,
      "z": -1,
      "name": "Rock_Slate"
    },
    {
      "x": 1,
      "y": 4,
      "z": -1,
      "name": "Rock_Slate"
    },
    {
      "x": 1,
      "y": 5,
      "z": -1,
      "name": "Rock_Slate"
    },
    {
      "x": 1,
      "y": 6,
      "z": -1,
      "name": "Rock_Slate"
    },
    {
      "x": 1,
      "y": 7,
      "z": -1,
      "name": "Rock_Slate"
    },
    {
      "x": 1,
      "y": 8,
      "z": -1,
      "name": "Rock_Slate"
    },
    {
      "x": 1,
      "y": 9,
      "z": -1,
      "name": "Rock_Slate"
    },
    {
      "x": 1,
      "y": 10,
      "z": -1,
      "name": "Rock_Slate"
    },
    {
      "x": 1,
      "y": 11,
      "z": -1,
      "name": "Rock_Slate"
    },
    {
      "x": 1,
      "y": 12,
      "z": -1,
      "name": "Rock_Slate"
    },
    {
      "x": 1,
      "y": 13,
      "z": -1,
      "name": "Rock_Slate"
    },
    {
      "x": 1,
      "y": 14,
      "z": -1,
      "name": "Rock_Slate"
    },
    {
      "x": 1,
      "y": 15,
      "z": -1,
      "name": "Rock_Slate"
    },
    {
      "x": 1,
      "y": 16,
      "z": -1,
      "name": "Rock_Slate"
    },
    {
      "x": 1,
      "y": 17,
      "z": -1,
      "name": "Rock_Slate"
    },
    {
      "x": 1,
      "y": 18,
      "z": -1,
      "name": "Rock_Slate"
    },
    {
      "x": 1,
      "y": 19,
      "z": -1,
      "name": "Rock_Slate"
    },
    {
      "x": 1,
      "y": 20,
      "z": -1,
      "name": "Soil_Ash"
    },
    {
      "x": 1,
      "y": 21,
      "z": -1,
      "name": "Soil_Ash"
    },
    {
      "x": 1,
      "y": 22,
      "z": -1,
      "name": "Soil_Ash"
    },
    {
      "x": 1,
      "y": 23,
      "z": -1,
      "name": "Soil_Ash"
    },
    {
      "x": 1,
      "y": 0,
      "z": 0,
      "name": "Rock_Slate"
    },
    {
      "x": 1,
      "y": 1,
      "z": 0,
      "name": "Rock_Slate"
    },
    {
      "x": 1,
      "y": 2,
      "z": 0,
      "name": "Rock_Slate"
    },
    {
      "x": 1,
      "y": 3,
      "z": 0,
      "name": "Rock_Slate"
    },
    {
      "x": 1,
      "y": 4,
      "z": 0,
      "name": "Rock_Slate"
    },
    {
      "x": 1,
      "y": 5,
      "z": 0,
      "name": "Rock_Slate"
    },
    {
      "x": 1,
      "y": 6,
      "z": 0,
      "name": "Rock_Slate"
    },
    {
      "x": 1,
      "y": 7,
      "z": 0,
      "name": "Rock_Slate"
    },
    {
      "x": 1,
      "y": 8,
      "z": 0,
      "name": "Rock_Slate"
    },
    {
      "x": 1,
      "y": 9,
      "z": 0,
      "name": "Rock_Slate"
    },
    {
      "x": 1,
      "y": 10,
      "z": 0,
      "name": "Rock_Slate"
    },
    {
      "x": 1,
      "y": 11,
      "z": 0,
      "name": "Rock_Slate"
    },
    {
      "x": 1,
      "y": 12,
      "z": 0,
      "name": "Rock_Slate"
    },
    {
      "x": 1,
      "y": 13,
      "z": 0,
      "name": "Rock_Slate"
    },
    {
      "x": 1,
      "y": 14,
      "z": 0,
      "name": "Rock_Slate"
    },
    {
      "x": 1,
      "y": 15,
      "z": 0,
      "name": "Rock_Slate"
    },
    {
      "x": 1,
      "y": 16,
      "z": 0,
      "name": "Rock_Slate"
    },
    {
      "x": 1,
      "y": 17,
      "z": 0,
      "name": "Rock_Slate"
    },
    {
      "x": 1,
      "y": 18,
      "z": 0,
      "name": "Rock_Slate"
    },
    {
      "x": 1,
      "y": 19,
      "z": 0,
      "name": "Rock_Slate"
    },
    {
      "x": 1,
      "y": 20,
      "z": 0,
      "name": "Soil_Ash"
    },
    {
      "x": 1,
      "y": 21,
      "z": 0,
      "name": "Soil_Ash"
    },
    {
      "x": 1,
      "y": 22,
      "z": 0,
      "name": "Soil_Ash"
    },
    {
      "x": 1,
      "y": 23,
      "z": 0,
      "name": "Soil_Ash"
    },
    {
      "x": 1,
      "y": 0,
      "z": 1,
      "name": "Rock_Slate"
    },
    {
      "x": 1,
      "y": 1,
      "z": 1,
      "name": "Rock_Slate"
    },
    {
      "x": 1,
      "y": 2,
      "z": 1,
      "name": "Rock_Slate"
    },
    {
      "x": 1,
      "y": 3,
      "z": 1,
      "name": "Rock_Slate"
    },
    {
      "x": 1,
      "y": 4,
      "z": 1,
      "name": "Rock_Slate"
    },
    {
      "x": 1,
      "y": 5,
      "z": 1,
      "name": "Rock_Slate"
    },
    {
      "x": 1,
      "y": 6,
      "z": 1,
      "name": "Rock_Slate"
    },
    {
      "x": 1,
      "y": 7,
      "z": 1,
      "name": "Rock_Slate"
    },
    {
      "x": 1,
      "y": 8,
      "z": 1,
      "name": "Rock_Slate"
    },
    {
      "x": 1,
      "y": 9,
      "z": 1,
      "name": "Rock_Slate"
    },
    {
      "x": 1,
      "y": 10,
      "z": 1,
      "name": "Rock_Slate"
    },
    {
      "x": 1,
      "y": 11,
      "z": 1,
      "name": "Rock_Slate"
    },
    {
      "x": 1,
      "y": 12,
      "z": 1,
      "name": "Rock_Slate"
    },
    {
      "x": 1,
      "y": 13,
      "z": 1,
      "name": "Rock_Slate"
    },
    {
      "x": 1,
      "y": 14,
      "z": 1,
      "name": "Rock_Slate"
    },
    {
      "x": 1,
      "y": 15,
      "z": 1,
      "name": "Rock_Slate"
    },
    {
      "x": 1,
      "y": 16,
      "z": 1,
      "name": "Rock_Slate"
    },
    {
      "x": 1,
      "y": 17,
      "z": 1,
      "name": "Rock_Slate"
    },
    {
      "x": 1,
      "y": 18,
      "z": 1,
      "name": "Rock_Slate"
    },
    {
      "x": 1,
      "y": 19,
      "z": 1,
      "name": "Rock_Slate"
    },
    {
      "x": 1,
      "y": 20,
      "z": 1,
      "name": "Rock_Slate"
    },
    {
      "x": 1,
      "y": 21,
      "z": 1,
      "name": "Rock_Slate"
    },
    {
      "x": 1,
      "y": 22,
      "z": 1,
      "name": "Soil_Ash"
    },
    {
      "x": 1,
      "y": 23,
      "z": 1,
      "name": "Soil_Ash"
    },
    {
      "x": 1,
      "y": 0,
      "z": 2,
      "name": "Rock_Slate"
    },
    {
      "x": 1,
      "y": 1,
      "z": 2,
      "name": "Rock_Slate"
    },
    {
      "x": 1,
      "y": 2,
      "z": 2,
      "name": "Rock_Slate"
    },
    {
      "x": 1,
      "y": 3,
      "z": 2,
      "name": "Rock_Slate"
    },
    {
      "x": 1,
      "y": 4,
      "z": 2,
      "name": "Rock_Slate"
    },
    {
      "x": 1,
      "y": 5,
      "z": 2,
      "name": "Rock_Slate"
    },
    {
      "x": 1,
      "y": 6,
      "z": 2,
      "name": "Rock_Slate"
    },
    {
      "x": 1,
      "y": 7,
      "z": 2,
      "name": "Rock_Slate"
    },
    {
      "x": 1,
      "y": 8,
      "z": 2,
      "name": "Rock_Slate"
    },
    {
      "x": 1,
      "y": 9,
      "z": 2,
      "name": "Rock_Slate"
    },
    {
      "x": 1,
      "y": 10,
      "z": 2,
      "name": "Rock_Slate"
    },
    {
      "x": 1,
      "y": 11,
      "z": 2,
      "name": "Rock_Slate"
    },
    {
      "x": 1,
      "y": 12,
      "z": 2,
      "name": "Rock_Slate"
    },
    {
      "x": 1,
      "y": 13,
      "z": 2,
      "name": "Rock_Slate"
    },
    {
      "x": 1,
      "y": 14,
      "z": 2,
      "name": "Rock_Slate"
    },
    {
      "x": 1,
      "y": 15,
      "z": 2,
      "name": "Rock_Slate"
    },
    {
      "x": 1,
      "y": 16,
      "z": 2,
      "name": "Soil_Ash"
    },
    {
      "x": 1,
      "y": 17,
      "z": 2,
      "name": "Furniture_Ancient_Wardrobe",
      "filler": 31
    },
    {
      "x": 1,
      "y": 18,
      "z": 2,
      "name": "Furniture_Ancient_Wardrobe",
      "filler": 1055
    },
    {
      "x": 1,
      "y": 0,
      "z": 3,
      "name": "Rock_Slate"
    },
    {
      "x": 1,
      "y": 1,
      "z": 3,
      "name": "Rock_Slate"
    },
    {
      "x": 1,
      "y": 2,
      "z": 3,
      "name": "Rock_Slate"
    },
    {
      "x": 1,
      "y": 3,
      "z": 3,
      "name": "Rock_Slate"
    },
    {
      "x": 1,
      "y": 4,
      "z": 3,
      "name": "Rock_Slate"
    },
    {
      "x": 1,
      "y": 5,
      "z": 3,
      "name": "Rock_Slate"
    },
    {
      "x": 1,
      "y": 6,
      "z": 3,
      "name": "Rock_Slate"
    },
    {
      "x": 1,
      "y": 7,
      "z": 3,
      "name": "Rock_Slate"
    },
    {
      "x": 1,
      "y": 8,
      "z": 3,
      "name": "Rock_Slate"
    },
    {
      "x": 1,
      "y": 9,
      "z": 3,
      "name": "Rock_Slate"
    },
    {
      "x": 1,
      "y": 10,
      "z": 3,
      "name": "Rock_Slate"
    },
    {
      "x": 1,
      "y": 11,
      "z": 3,
      "name": "Rock_Slate"
    },
    {
      "x": 1,
      "y": 12,
      "z": 3,
      "name": "Rock_Slate"
    },
    {
      "x": 1,
      "y": 13,
      "z": 3,
      "name": "Rock_Slate"
    },
    {
      "x": 1,
      "y": 14,
      "z": 3,
      "name": "Rock_Slate"
    },
    {
      "x": 1,
      "y": 15,
      "z": 3,
      "name": "Rock_Slate"
    },
    {
      "x": 1,
      "y": 16,
      "z": 3,
      "name": "Soil_Ash"
    },
    {
      "x": 1,
      "y": 0,
      "z": 4,
      "name": "Rock_Slate"
    },
    {
      "x": 1,
      "y": 1,
      "z": 4,
      "name": "Rock_Slate"
    },
    {
      "x": 1,
      "y": 2,
      "z": 4,
      "name": "Rock_Slate"
    },
    {
      "x": 1,
      "y": 3,
      "z": 4,
      "name": "Rock_Slate"
    },
    {
      "x": 1,
      "y": 4,
      "z": 4,
      "name": "Rock_Slate"
    },
    {
      "x": 1,
      "y": 5,
      "z": 4,
      "name": "Rock_Slate"
    },
    {
      "x": 1,
      "y": 6,
      "z": 4,
      "name": "Rock_Slate"
    },
    {
      "x": 1,
      "y": 7,
      "z": 4,
      "name": "Rock_Slate"
    },
    {
      "x": 1,
      "y": 8,
      "z": 4,
      "name": "Rock_Slate"
    },
    {
      "x": 1,
      "y": 9,
      "z": 4,
      "name": "Rock_Slate"
    },
    {
      "x": 1,
      "y": 10,
      "z": 4,
      "name": "Rock_Slate"
    },
    {
      "x": 1,
      "y": 11,
      "z": 4,
      "name": "Rock_Slate"
    },
    {
      "x": 1,
      "y": 12,
      "z": 4,
      "name": "Rock_Slate"
    },
    {
      "x": 1,
      "y": 13,
      "z": 4,
      "name": "Rock_Slate"
    },
    {
      "x": 1,
      "y": 14,
      "z": 4,
      "name": "Soil_Ash"
    },
    {
      "x": 1,
      "y": 15,
      "z": 4,
      "name": "Soil_Ash"
    },
    {
      "x": 1,
      "y": 1,
      "z": 5,
      "name": "Rock_Slate"
    },
    {
      "x": 1,
      "y": 2,
      "z": 5,
      "name": "Rock_Slate"
    },
    {
      "x": 1,
      "y": 3,
      "z": 5,
      "name": "Rock_Slate"
    },
    {
      "x": 1,
      "y": 4,
      "z": 5,
      "name": "Rock_Slate"
    },
    {
      "x": 1,
      "y": 5,
      "z": 5,
      "name": "Rock_Slate"
    },
    {
      "x": 1,
      "y": 6,
      "z": 5,
      "name": "Rock_Slate"
    },
    {
      "x": 1,
      "y": 7,
      "z": 5,
      "name": "Rock_Slate"
    },
    {
      "x": 1,
      "y": 8,
      "z": 5,
      "name": "Rock_Slate"
    },
    {
      "x": 1,
      "y": 9,
      "z": 5,
      "name": "Rock_Slate"
    },
    {
      "x": 1,
      "y": 10,
      "z": 5,
      "name": "Rock_Slate"
    },
    {
      "x": 1,
      "y": 11,
      "z": 5,
      "name": "Rock_Slate"
    },
    {
      "x": 1,
      "y": 12,
      "z": 5,
      "name": "Rock_Slate"
    },
    {
      "x": 1,
      "y": 13,
      "z": 5,
      "name": "Rock_Slate"
    },
    {
      "x": 1,
      "y": 14,
      "z": 5,
      "name": "Rock_Slate"
    },
    {
      "x": 1,
      "y": 15,
      "z": 5,
      "name": "Soil_Ash"
    },
    {
      "x": 1,
      "y": 11,
      "z": 6,
      "name": "Rock_Slate"
    },
    {
      "x": 1,
      "y": 12,
      "z": 6,
      "name": "Rock_Slate"
    },
    {
      "x": 1,
      "y": 13,
      "z": 6,
      "name": "Rock_Slate"
    },
    {
      "x": 1,
      "y": 14,
      "z": 6,
      "name": "Rock_Slate"
    },
    {
      "x": 1,
      "y": 15,
      "z": 6,
      "name": "Rock_Slate"
    },
    {
      "x": 2,
      "y": 19,
      "z": -5,
      "name": "Rock_Slate"
    },
    {
      "x": 2,
      "y": 20,
      "z": -5,
      "name": "Rock_Slate"
    },
    {
      "x": 2,
      "y": 21,
      "z": -5,
      "name": "Rock_Slate"
    },
    {
      "x": 2,
      "y": 22,
      "z": -5,
      "name": "Rock_Slate"
    },
    {
      "x": 2,
      "y": 23,
      "z": -5,
      "name": "Rock_Slate"
    },
    {
      "x": 2,
      "y": 8,
      "z": -4,
      "name": "Rock_Slate"
    },
    {
      "x": 2,
      "y": 9,
      "z": -4,
      "name": "Rock_Slate"
    },
    {
      "x": 2,
      "y": 10,
      "z": -4,
      "name": "Rock_Slate"
    },
    {
      "x": 2,
      "y": 11,
      "z": -4,
      "name": "Rock_Slate"
    },
    {
      "x": 2,
      "y": 12,
      "z": -4,
      "name": "Rock_Slate"
    },
    {
      "x": 2,
      "y": 13,
      "z": -4,
      "name": "Rock_Slate"
    },
    {
      "x": 2,
      "y": 14,
      "z": -4,
      "name": "Rock_Slate"
    },
    {
      "x": 2,
      "y": 15,
      "z": -4,
      "name": "Rock_Slate"
    },
    {
      "x": 2,
      "y": 16,
      "z": -4,
      "name": "Rock_Slate"
    },
    {
      "x": 2,
      "y": 17,
      "z": -4,
      "name": "Rock_Slate"
    },
    {
      "x": 2,
      "y": 18,
      "z": -4,
      "name": "Rock_Slate"
    },
    {
      "x": 2,
      "y": 19,
      "z": -4,
      "name": "Rock_Slate"
    },
    {
      "x": 2,
      "y": 20,
      "z": -4,
      "name": "Rock_Slate"
    },
    {
      "x": 2,
      "y": 21,
      "z": -4,
      "name": "Rock_Slate"
    },
    {
      "x": 2,
      "y": 22,
      "z": -4,
      "name": "Rock_Slate"
    },
    {
      "x": 2,
      "y": 23,
      "z": -4,
      "name": "Rock_Slate"
    },
    {
      "x": 2,
      "y": 24,
      "z": -4,
      "name": "Rock_Stone_Cobble"
    },
    {
      "x": 2,
      "y": 25,
      "z": -4,
      "name": "Rock_Stone_Cobble_Half",
      "rotation": 7
    },
    {
      "x": 2,
      "y": 8,
      "z": -3,
      "name": "Rock_Slate"
    },
    {
      "x": 2,
      "y": 9,
      "z": -3,
      "name": "Rock_Slate"
    },
    {
      "x": 2,
      "y": 10,
      "z": -3,
      "name": "Rock_Slate"
    },
    {
      "x": 2,
      "y": 11,
      "z": -3,
      "name": "Rock_Slate"
    },
    {
      "x": 2,
      "y": 12,
      "z": -3,
      "name": "Rock_Slate"
    },
    {
      "x": 2,
      "y": 13,
      "z": -3,
      "name": "Rock_Slate"
    },
    {
      "x": 2,
      "y": 14,
      "z": -3,
      "name": "Rock_Slate"
    },
    {
      "x": 2,
      "y": 15,
      "z": -3,
      "name": "Rock_Slate"
    },
    {
      "x": 2,
      "y": 16,
      "z": -3,
      "name": "Rock_Slate"
    },
    {
      "x": 2,
      "y": 17,
      "z": -3,
      "name": "Rock_Slate"
    },
    {
      "x": 2,
      "y": 18,
      "z": -3,
      "name": "Rock_Slate"
    },
    {
      "x": 2,
      "y": 19,
      "z": -3,
      "name": "Rock_Slate"
    },
    {
      "x": 2,
      "y": 20,
      "z": -3,
      "name": "Soil_Ash"
    },
    {
      "x": 2,
      "y": 21,
      "z": -3,
      "name": "Soil_Ash"
    },
    {
      "x": 2,
      "y": 22,
      "z": -3,
      "name": "Soil_Ash"
    },
    {
      "x": 2,
      "y": 23,
      "z": -3,
      "name": "Soil_Ash"
    },
    {
      "x": 2,
      "y": 1,
      "z": -2,
      "name": "Rock_Slate"
    },
    {
      "x": 2,
      "y": 2,
      "z": -2,
      "name": "Rock_Slate"
    },
    {
      "x": 2,
      "y": 3,
      "z": -2,
      "name": "Rock_Slate"
    },
    {
      "x": 2,
      "y": 4,
      "z": -2,
      "name": "Rock_Slate"
    },
    {
      "x": 2,
      "y": 5,
      "z": -2,
      "name": "Rock_Slate"
    },
    {
      "x": 2,
      "y": 6,
      "z": -2,
      "name": "Rock_Slate"
    },
    {
      "x": 2,
      "y": 7,
      "z": -2,
      "name": "Rock_Slate"
    },
    {
      "x": 2,
      "y": 8,
      "z": -2,
      "name": "Rock_Slate"
    },
    {
      "x": 2,
      "y": 9,
      "z": -2,
      "name": "Rock_Slate"
    },
    {
      "x": 2,
      "y": 10,
      "z": -2,
      "name": "Rock_Slate"
    },
    {
      "x": 2,
      "y": 11,
      "z": -2,
      "name": "Rock_Slate"
    },
    {
      "x": 2,
      "y": 12,
      "z": -2,
      "name": "Rock_Slate"
    },
    {
      "x": 2,
      "y": 13,
      "z": -2,
      "name": "Rock_Slate"
    },
    {
      "x": 2,
      "y": 14,
      "z": -2,
      "name": "Rock_Slate"
    },
    {
      "x": 2,
      "y": 15,
      "z": -2,
      "name": "Rock_Slate"
    },
    {
      "x": 2,
      "y": 16,
      "z": -2,
      "name": "Rock_Slate"
    },
    {
      "x": 2,
      "y": 17,
      "z": -2,
      "name": "Rock_Slate"
    },
    {
      "x": 2,
      "y": 18,
      "z": -2,
      "name": "Rock_Slate"
    },
    {
      "x": 2,
      "y": 19,
      "z": -2,
      "name": "Rock_Slate"
    },
    {
      "x": 2,
      "y": 20,
      "z": -2,
      "name": "Soil_Ash"
    },
    {
      "x": 2,
      "y": 21,
      "z": -2,
      "name": "Soil_Ash"
    },
    {
      "x": 2,
      "y": 22,
      "z": -2,
      "name": "Soil_Ash"
    },
    {
      "x": 2,
      "y": 23,
      "z": -2,
      "name": "Soil_Ash"
    },
    {
      "x": 2,
      "y": 24,
      "z": -2,
      "name": "Plant_Bush_Dead_Twisted"
    },
    {
      "x": 2,
      "y": 0,
      "z": -1,
      "name": "Rock_Slate"
    },
    {
      "x": 2,
      "y": 1,
      "z": -1,
      "name": "Rock_Slate"
    },
    {
      "x": 2,
      "y": 2,
      "z": -1,
      "name": "Rock_Slate"
    },
    {
      "x": 2,
      "y": 3,
      "z": -1,
      "name": "Rock_Slate"
    },
    {
      "x": 2,
      "y": 4,
      "z": -1,
      "name": "Rock_Slate"
    },
    {
      "x": 2,
      "y": 5,
      "z": -1,
      "name": "Rock_Slate"
    },
    {
      "x": 2,
      "y": 6,
      "z": -1,
      "name": "Rock_Slate"
    },
    {
      "x": 2,
      "y": 7,
      "z": -1,
      "name": "Rock_Slate"
    },
    {
      "x": 2,
      "y": 8,
      "z": -1,
      "name": "Rock_Slate"
    },
    {
      "x": 2,
      "y": 9,
      "z": -1,
      "name": "Rock_Slate"
    },
    {
      "x": 2,
      "y": 10,
      "z": -1,
      "name": "Rock_Slate"
    },
    {
      "x": 2,
      "y": 11,
      "z": -1,
      "name": "Rock_Slate"
    },
    {
      "x": 2,
      "y": 12,
      "z": -1,
      "name": "Rock_Slate"
    },
    {
      "x": 2,
      "y": 13,
      "z": -1,
      "name": "Rock_Slate"
    },
    {
      "x": 2,
      "y": 14,
      "z": -1,
      "name": "Rock_Slate"
    },
    {
      "x": 2,
      "y": 15,
      "z": -1,
      "name": "Rock_Slate"
    },
    {
      "x": 2,
      "y": 16,
      "z": -1,
      "name": "Rock_Slate"
    },
    {
      "x": 2,
      "y": 17,
      "z": -1,
      "name": "Rock_Slate"
    },
    {
      "x": 2,
      "y": 18,
      "z": -1,
      "name": "Rock_Slate"
    },
    {
      "x": 2,
      "y": 19,
      "z": -1,
      "name": "Rock_Slate"
    },
    {
      "x": 2,
      "y": 20,
      "z": -1,
      "name": "Soil_Ash"
    },
    {
      "x": 2,
      "y": 21,
      "z": -1,
      "name": "Soil_Ash"
    },
    {
      "x": 2,
      "y": 22,
      "z": -1,
      "name": "Soil_Ash"
    },
    {
      "x": 2,
      "y": 23,
      "z": -1,
      "name": "Soil_Ash"
    },
    {
      "x": 2,
      "y": 24,
      "z": -1,
      "name": "Plant_Bush_Dead_Twisted"
    },
    {
      "x": 2,
      "y": 0,
      "z": 0,
      "name": "Rock_Slate"
    },
    {
      "x": 2,
      "y": 1,
      "z": 0,
      "name": "Rock_Slate"
    },
    {
      "x": 2,
      "y": 2,
      "z": 0,
      "name": "Rock_Slate"
    },
    {
      "x": 2,
      "y": 3,
      "z": 0,
      "name": "Rock_Slate"
    },
    {
      "x": 2,
      "y": 4,
      "z": 0,
      "name": "Rock_Slate"
    },
    {
      "x": 2,
      "y": 5,
      "z": 0,
      "name": "Rock_Slate"
    },
    {
      "x": 2,
      "y": 6,
      "z": 0,
      "name": "Rock_Slate"
    },
    {
      "x": 2,
      "y": 7,
      "z": 0,
      "name": "Rock_Slate"
    },
    {
      "x": 2,
      "y": 8,
      "z": 0,
      "name": "Rock_Slate"
    },
    {
      "x": 2,
      "y": 9,
      "z": 0,
      "name": "Rock_Slate"
    },
    {
      "x": 2,
      "y": 10,
      "z": 0,
      "name": "Rock_Slate"
    },
    {
      "x": 2,
      "y": 11,
      "z": 0,
      "name": "Rock_Slate"
    },
    {
      "x": 2,
      "y": 12,
      "z": 0,
      "name": "Rock_Slate"
    },
    {
      "x": 2,
      "y": 13,
      "z": 0,
      "name": "Rock_Slate"
    },
    {
      "x": 2,
      "y": 14,
      "z": 0,
      "name": "Rock_Slate"
    },
    {
      "x": 2,
      "y": 15,
      "z": 0,
      "name": "Rock_Slate"
    },
    {
      "x": 2,
      "y": 16,
      "z": 0,
      "name": "Rock_Slate"
    },
    {
      "x": 2,
      "y": 17,
      "z": 0,
      "name": "Rock_Slate"
    },
    {
      "x": 2,
      "y": 18,
      "z": 0,
      "name": "Rock_Slate"
    },
    {
      "x": 2,
      "y": 19,
      "z": 0,
      "name": "Rock_Slate"
    },
    {
      "x": 2,
      "y": 20,
      "z": 0,
      "name": "Soil_Ash"
    },
    {
      "x": 2,
      "y": 21,
      "z": 0,
      "name": "Soil_Ash"
    },
    {
      "x": 2,
      "y": 22,
      "z": 0,
      "name": "Soil_Ash"
    },
    {
      "x": 2,
      "y": 23,
      "z": 0,
      "name": "Soil_Ash"
    },
    {
      "x": 2,
      "y": 0,
      "z": 1,
      "name": "Rock_Slate"
    },
    {
      "x": 2,
      "y": 1,
      "z": 1,
      "name": "Rock_Slate"
    },
    {
      "x": 2,
      "y": 2,
      "z": 1,
      "name": "Rock_Slate"
    },
    {
      "x": 2,
      "y": 3,
      "z": 1,
      "name": "Rock_Slate"
    },
    {
      "x": 2,
      "y": 4,
      "z": 1,
      "name": "Rock_Slate"
    },
    {
      "x": 2,
      "y": 5,
      "z": 1,
      "name": "Rock_Slate"
    },
    {
      "x": 2,
      "y": 6,
      "z": 1,
      "name": "Rock_Slate"
    },
    {
      "x": 2,
      "y": 7,
      "z": 1,
      "name": "Rock_Slate"
    },
    {
      "x": 2,
      "y": 8,
      "z": 1,
      "name": "Rock_Slate"
    },
    {
      "x": 2,
      "y": 9,
      "z": 1,
      "name": "Rock_Slate"
    },
    {
      "x": 2,
      "y": 10,
      "z": 1,
      "name": "Rock_Slate"
    },
    {
      "x": 2,
      "y": 11,
      "z": 1,
      "name": "Rock_Slate"
    },
    {
      "x": 2,
      "y": 12,
      "z": 1,
      "name": "Rock_Slate"
    },
    {
      "x": 2,
      "y": 13,
      "z": 1,
      "name": "Rock_Slate"
    },
    {
      "x": 2,
      "y": 14,
      "z": 1,
      "name": "Rock_Slate"
    },
    {
      "x": 2,
      "y": 15,
      "z": 1,
      "name": "Rock_Slate"
    },
    {
      "x": 2,
      "y": 16,
      "z": 1,
      "name": "Rock_Slate"
    },
    {
      "x": 2,
      "y": 17,
      "z": 1,
      "name": "Rock_Slate"
    },
    {
      "x": 2,
      "y": 18,
      "z": 1,
      "name": "Rock_Slate"
    },
    {
      "x": 2,
      "y": 19,
      "z": 1,
      "name": "Rock_Slate"
    },
    {
      "x": 2,
      "y": 20,
      "z": 1,
      "name": "Rock_Slate"
    },
    {
      "x": 2,
      "y": 21,
      "z": 1,
      "name": "Rock_Slate"
    },
    {
      "x": 2,
      "y": 22,
      "z": 1,
      "name": "Rock_Slate"
    },
    {
      "x": 2,
      "y": 23,
      "z": 1,
      "name": "Soil_Ash"
    },
    {
      "x": 2,
      "y": 24,
      "z": 1,
      "name": "Rubble_Stone_Medium"
    },
    {
      "x": 2,
      "y": 0,
      "z": 2,
      "name": "Rock_Slate"
    },
    {
      "x": 2,
      "y": 1,
      "z": 2,
      "name": "Rock_Slate"
    },
    {
      "x": 2,
      "y": 2,
      "z": 2,
      "name": "Rock_Slate"
    },
    {
      "x": 2,
      "y": 3,
      "z": 2,
      "name": "Rock_Slate"
    },
    {
      "x": 2,
      "y": 4,
      "z": 2,
      "name": "Rock_Slate"
    },
    {
      "x": 2,
      "y": 5,
      "z": 2,
      "name": "Rock_Slate"
    },
    {
      "x": 2,
      "y": 6,
      "z": 2,
      "name": "Rock_Slate"
    },
    {
      "x": 2,
      "y": 7,
      "z": 2,
      "name": "Rock_Slate"
    },
    {
      "x": 2,
      "y": 8,
      "z": 2,
      "name": "Rock_Slate"
    },
    {
      "x": 2,
      "y": 9,
      "z": 2,
      "name": "Rock_Slate"
    },
    {
      "x": 2,
      "y": 10,
      "z": 2,
      "name": "Rock_Slate"
    },
    {
      "x": 2,
      "y": 11,
      "z": 2,
      "name": "Rock_Slate"
    },
    {
      "x": 2,
      "y": 12,
      "z": 2,
      "name": "Rock_Slate"
    },
    {
      "x": 2,
      "y": 13,
      "z": 2,
      "name": "Rock_Slate"
    },
    {
      "x": 2,
      "y": 14,
      "z": 2,
      "name": "Rock_Slate"
    },
    {
      "x": 2,
      "y": 15,
      "z": 2,
      "name": "Rock_Slate"
    },
    {
      "x": 2,
      "y": 16,
      "z": 2,
      "name": "Soil_Ash"
    },
    {
      "x": 2,
      "y": 17,
      "z": 2,
      "name": "Furniture_Ancient_Wardrobe"
    },
    {
      "x": 2,
      "y": 18,
      "z": 2,
      "name": "Furniture_Ancient_Wardrobe",
      "filler": 1024
    },
    {
      "x": 2,
      "y": 0,
      "z": 3,
      "name": "Rock_Slate"
    },
    {
      "x": 2,
      "y": 1,
      "z": 3,
      "name": "Rock_Slate"
    },
    {
      "x": 2,
      "y": 2,
      "z": 3,
      "name": "Rock_Slate"
    },
    {
      "x": 2,
      "y": 3,
      "z": 3,
      "name": "Rock_Slate"
    },
    {
      "x": 2,
      "y": 4,
      "z": 3,
      "name": "Rock_Slate"
    },
    {
      "x": 2,
      "y": 5,
      "z": 3,
      "name": "Rock_Slate"
    },
    {
      "x": 2,
      "y": 6,
      "z": 3,
      "name": "Rock_Slate"
    },
    {
      "x": 2,
      "y": 7,
      "z": 3,
      "name": "Rock_Slate"
    },
    {
      "x": 2,
      "y": 8,
      "z": 3,
      "name": "Rock_Slate"
    },
    {
      "x": 2,
      "y": 9,
      "z": 3,
      "name": "Rock_Slate"
    },
    {
      "x": 2,
      "y": 10,
      "z": 3,
      "name": "Rock_Slate"
    },
    {
      "x": 2,
      "y": 11,
      "z": 3,
      "name": "Rock_Slate"
    },
    {
      "x": 2,
      "y": 12,
      "z": 3,
      "name": "Rock_Slate"
    },
    {
      "x": 2,
      "y": 13,
      "z": 3,
      "name": "Rock_Slate"
    },
    {
      "x": 2,
      "y": 14,
      "z": 3,
      "name": "Rock_Slate"
    },
    {
      "x": 2,
      "y": 15,
      "z": 3,
      "name": "Rock_Slate"
    },
    {
      "x": 2,
      "y": 16,
      "z": 3,
      "name": "Soil_Ash"
    },
    {
      "x": 2,
      "y": 17,
      "z": 3,
      "name": "Rubble_Stone"
    },
    {
      "x": 2,
      "y": 0,
      "z": 4,
      "name": "Rock_Slate"
    },
    {
      "x": 2,
      "y": 1,
      "z": 4,
      "name": "Rock_Slate"
    },
    {
      "x": 2,
      "y": 2,
      "z": 4,
      "name": "Rock_Slate"
    },
    {
      "x": 2,
      "y": 3,
      "z": 4,
      "name": "Rock_Slate"
    },
    {
      "x": 2,
      "y": 4,
      "z": 4,
      "name": "Rock_Slate"
    },
    {
      "x": 2,
      "y": 5,
      "z": 4,
      "name": "Rock_Slate"
    },
    {
      "x": 2,
      "y": 6,
      "z": 4,
      "name": "Rock_Slate"
    },
    {
      "x": 2,
      "y": 7,
      "z": 4,
      "name": "Rock_Slate"
    },
    {
      "x": 2,
      "y": 8,
      "z": 4,
      "name": "Rock_Slate"
    },
    {
      "x": 2,
      "y": 9,
      "z": 4,
      "name": "Rock_Slate"
    },
    {
      "x": 2,
      "y": 10,
      "z": 4,
      "name": "Rock_Slate"
    },
    {
      "x": 2,
      "y": 11,
      "z": 4,
      "name": "Rock_Slate"
    },
    {
      "x": 2,
      "y": 12,
      "z": 4,
      "name": "Rock_Slate"
    },
    {
      "x": 2,
      "y": 13,
      "z": 4,
      "name": "Rock_Slate"
    },
    {
      "x": 2,
      "y": 14,
      "z": 4,
      "name": "Rock_Slate"
    },
    {
      "x": 2,
      "y": 15,
      "z": 4,
      "name": "Rock_Slate"
    },
    {
      "x": 2,
      "y": 16,
      "z": 4,
      "name": "Soil_Ash"
    },
    {
      "x": 2,
      "y": 1,
      "z": 5,
      "name": "Rock_Slate"
    },
    {
      "x": 2,
      "y": 2,
      "z": 5,
      "name": "Rock_Slate"
    },
    {
      "x": 2,
      "y": 3,
      "z": 5,
      "name": "Rock_Slate"
    },
    {
      "x": 2,
      "y": 4,
      "z": 5,
      "name": "Rock_Slate"
    },
    {
      "x": 2,
      "y": 5,
      "z": 5,
      "name": "Rock_Slate"
    },
    {
      "x": 2,
      "y": 6,
      "z": 5,
      "name": "Rock_Slate"
    },
    {
      "x": 2,
      "y": 7,
      "z": 5,
      "name": "Rock_Slate"
    },
    {
      "x": 2,
      "y": 8,
      "z": 5,
      "name": "Rock_Slate"
    },
    {
      "x": 2,
      "y": 9,
      "z": 5,
      "name": "Rock_Slate"
    },
    {
      "x": 2,
      "y": 10,
      "z": 5,
      "name": "Rock_Slate"
    },
    {
      "x": 2,
      "y": 11,
      "z": 5,
      "name": "Rock_Slate"
    },
    {
      "x": 2,
      "y": 12,
      "z": 5,
      "name": "Rock_Slate"
    },
    {
      "x": 2,
      "y": 13,
      "z": 5,
      "name": "Rock_Slate"
    },
    {
      "x": 2,
      "y": 14,
      "z": 5,
      "name": "Rock_Slate"
    },
    {
      "x": 2,
      "y": 15,
      "z": 5,
      "name": "Rock_Slate"
    },
    {
      "x": 3,
      "y": 11,
      "z": -4,
      "name": "Rock_Slate"
    },
    {
      "x": 3,
      "y": 12,
      "z": -4,
      "name": "Rock_Slate"
    },
    {
      "x": 3,
      "y": 13,
      "z": -4,
      "name": "Rock_Slate"
    },
    {
      "x": 3,
      "y": 14,
      "z": -4,
      "name": "Rock_Slate"
    },
    {
      "x": 3,
      "y": 15,
      "z": -4,
      "name": "Rock_Slate"
    },
    {
      "x": 3,
      "y": 16,
      "z": -4,
      "name": "Rock_Slate"
    },
    {
      "x": 3,
      "y": 17,
      "z": -4,
      "name": "Rock_Slate"
    },
    {
      "x": 3,
      "y": 18,
      "z": -4,
      "name": "Rock_Slate"
    },
    {
      "x": 3,
      "y": 19,
      "z": -4,
      "name": "Rock_Slate"
    },
    {
      "x": 3,
      "y": 20,
      "z": -4,
      "name": "Rock_Slate"
    },
    {
      "x": 3,
      "y": 21,
      "z": -4,
      "name": "Rock_Slate"
    },
    {
      "x": 3,
      "y": 22,
      "z": -4,
      "name": "Rock_Slate"
    },
    {
      "x": 3,
      "y": 23,
      "z": -4,
      "name": "Rock_Slate"
    },
    {
      "x": 3,
      "y": 24,
      "z": -4,
      "name": "Rock_Stone_Cobble"
    },
    {
      "x": 3,
      "y": 25,
      "z": -4,
      "name": "Rock_Stone_Cobble"
    },
    {
      "x": 3,
      "y": 26,
      "z": -4,
      "name": "Rock_Stone_Cobble"
    },
    {
      "x": 3,
      "y": 27,
      "z": -4,
      "name": "Rock_Basalt_Cobble_Roof",
      "rotation": 1
    },
    {
      "x": 3,
      "y": 9,
      "z": -3,
      "name": "Rock_Slate"
    },
    {
      "x": 3,
      "y": 10,
      "z": -3,
      "name": "Rock_Slate"
    },
    {
      "x": 3,
      "y": 11,
      "z": -3,
      "name": "Rock_Slate"
    },
    {
      "x": 3,
      "y": 12,
      "z": -3,
      "name": "Rock_Slate"
    },
    {
      "x": 3,
      "y": 13,
      "z": -3,
      "name": "Rock_Slate"
    },
    {
      "x": 3,
      "y": 14,
      "z": -3,
      "name": "Rock_Slate"
    },
    {
      "x": 3,
      "y": 15,
      "z": -3,
      "name": "Rock_Slate"
    },
    {
      "x": 3,
      "y": 16,
      "z": -3,
      "name": "Rock_Slate"
    },
    {
      "x": 3,
      "y": 17,
      "z": -3,
      "name": "Rock_Slate"
    },
    {
      "x": 3,
      "y": 18,
      "z": -3,
      "name": "Rock_Slate"
    },
    {
      "x": 3,
