{
  "version": 8,
  "blockIdVersion": 8,
  "anchorX": 6,
  "anchorY": 6,
  "anchorZ": 5,
  "blocks": [
    {
      "x": 4,
      "y": 6,
      "z": 4,
      "name": "Rock_Slate"
    },
    {
      "x": 4,
      "y": 6,
      "z": 5,
      "name": "Rock_Slate"
    },
    {
      "x": 4,
      "y": 7,
      "z": 5,
      "name": "Rock_Slate"
    },
    {
      "x": 5,
      "y": 5,
      "z": 3,
      "name": "Rock_Slate"
    },
    {
      "x": 5,
      "y": 6,
      "z": 3,
      "name": "Rock_Slate"
    },
    {
      "x": 5,
      "y": 7,
      "z": 3,
      "name": "Rock_Slate"
    },
    {
      "x": 5,
      "y": 4,
      "z": 4,
      "name": "Rock_Slate"
    },
    {
      "x": 5,
      "y": 5,
      "z": 4,
      "name": "Rock_Slate"
    },
    {
      "x": 5,
      "y": 6,
      "z": 4,
      "name": "Rock_Slate"
    },
    {
      "x": 5,
      "y": 7,
      "z": 4,
      "name": "Rock_Slate"
    },
    {
      "x": 5,
      "y": 5,
      "z": 5,
      "name": "Rock_Slate"
    },
    {
      "x": 5,
      "y": 6,
      "z": 5,
      "name": "Rock_Slate"
    },
    {
      "x": 5,
      "y": 7,
      "z": 5,
      "name": "Rock_Slate"
    },
    {
      "x": 5,
      "y": 8,
      "z": 5,
      "name": "Rock_Slate"
    },
    {
      "x": 5,
      "y": 6,
      "z": 6,
      "name": "Rock_Slate"
    },
    {
      "x": 6,
      "y": 4,
      "z": 3,
      "name": "Rock_Slate"
    },
    {
      "x": 6,
      "y": 5,
      "z": 3,
      "name": "Rock_Slate"
    },
    {
      "x": 6,
      "y": 6,
      "z": 3,
      "name": "Rock_Slate"
    },
    {
      "x": 6,
      "y": 7,
      "z": 3,
      "name": "Rock_Slate"
    },
    {
      "x": 6,
      "y": 4,
      "z": 4,
      "name": "Rock_Slate"
    },
    {
      "x": 6,
      "y": 5,
      "z": 4,
      "name": "Rock_Slate"
    },
    {
      "x": 6,
      "y": 6,
      "z": 4,
      "name": "Rock_Slate"
    },
    {
      "x": 6,
      "y": 7,
      "z": 4,
      "name": "Rock_Slate"
    },
    {
      "x": 6,
      "y": 8,
      "z": 4,
      "name": "Rock_Slate"
    },
    {
      "x": 6,
      "y": 3,
      "z": 5,
      "name": "Rock_Slate"
    },
    {
      "x": 6,
      "y": 4,
      "z": 5,
      "name": "Rock_Slate"
    },
    {
      "x": 6,
      "y": 5,
      "z": 5,
      "name": "Rock_Slate"
    },
    {
      "x": 6,
      "y": 6,
      "z": 5,
      "name": "Rock_Slate"
    },
    {
      "x": 6,
      "y": 7,
      "z": 5,
      "name": "Rock_Slate"
    },
    {
      "x": 6,
      "y": 8,
      "z": 5,
      "name": "Rock_Slate"
    },
    {
      "x": 6,
      "y": 4,
      "z": 6,
      "name": "Rock_Slate"
    },
    {
      "x": 6,
      "y": 5,
      "z": 6,
      "name": "Rock_Slate"
    },
    {
      "x": 6,
      "y": 6,
      "z": 6,
      "name": "Rock_Slate"
    },
    {
      "x": 6,
      "y": 7,
      "z": 6,
      "name": "Rock_Slate"
    },
    {
      "x": 6,
      "y": 5,
      "z": 7,
      "name": "Rock_Slate"
    },
    {
      "x": 6,
      "y": 6,
      "z": 7,
      "name": "Rock_Slate"
    },
    {
      "x": 6,
      "y": 7,
      "z": 7,
      "name": "Rock_Slate"
    },
    {
      "x": 7,
      "y": 6,
      "z": 3,
      "name": "Rock_Slate"
    },
    {
      "x": 7,
      "y": 5,
      "z": 4,
      "name": "Rock_Slate"
    },
    {
      "x": 7,
      "y": 6,
      "z": 4,
      "name": "Rock_Slate"
    },
    {
      "x": 7,
      "y": 7,
      "z": 4,
      "name": "Rock_Slate"
    },
    {
      "x": 7,
      "y": 8,
      "z": 4,
      "name": "Rock_Slate"
    },
    {
      "x": 7,
      "y": 3,
      "z": 5,
      "name": "Rock_Slate"
    },
    {
      "x": 7,
      "y": 4,
      "z": 5,
      "name": "Rock_Slate"
    },
    {
      "x": 7,
      "y": 5,
      "z": 5,
      "name": "Rock_Slate"
    },
    {
      "x": 7,
      "y": 6,
      "z": 5,
      "name": "Rock_Slate"
    },
    {
      "x": 7,
      "y": 7,
      "z": 5,
      "name": "Rock_Slate"
    },
    {
      "x": 7,
      "y": 8,
      "z": 5,
      "name": "Rock_Slate"
    },
    {
      "x": 7,
      "y": 3,
      "z": 6,
      "name": "Rock_Slate"
    },
    {
      "x": 7,
      "y": 4,
      "z": 6,
      "name": "Rock_Slate"
    },
    {
      "x": 7,
      "y": 5,
      "z": 6,
      "name": "Rock_Slate"
    },
    {
      "x": 7,
      "y": 6,
      "z": 6,
      "name": "Rock_Slate"
    },
    {
      "x": 7,
      "y": 7,
      "z": 6,
      "name": "Rock_Slate"
    },
    {
      "x": 7,
      "y": 8,
      "z": 6,
      "name": "Rock_Slate"
    },
    {
      "x": 7,
      "y": 5,
      "z": 7,
      "name": "Rock_Slate"
    },
    {
      "x": 7,
      "y": 6,
      "z": 7,
      "name": "Rock_Slate"
    },
    {
      "x": 7,
      "y": 7,
      "z": 7,
      "name": "Rock_Slate"
    },
    {
      "x": 7,
      "y": 8,
      "z": 7,
      "name": "Rock_Slate"
    },
    {
      "x": 7,
      "y": 6,
      "z": 8,
      "name": "Rock_Slate"
    },
    {
      "x": 7,
      "y": 7,
      "z": 8,
      "name": "Rock_Slate"
    },
    {
      "x": 8,
      "y": 6,
      "z": 4,
      "name": "Rock_Slate"
    },
    {
      "x": 8,
      "y": 7,
      "z": 4,
      "name": "Rock_Slate"
    },
    {
      "x": 8,
      "y": 4,
      "z": 5,
      "name": "Rock_Slate"
    },
    {
      "x": 8,
      "y": 5,
      "z": 5,
      "name": "Rock_Slate"
    },
    {
      "x": 8,
      "y": 6,
      "z": 5,
      "name": "Rock_Slate"
    },
    {
      "x": 8,
      "y": 7,
      "z": 5,
      "name": "Rock_Slate"
    },
    {
      "x": 8,
      "y": 8,
      "z": 5,
      "name": "Rock_Slate"
    },
    {
      "x": 8,
      "y": 4,
      "z": 6,
      "name": "Rock_Slate"
    },
    {
      "x": 8,
      "y": 5,
      "z": 6,
      "name": "Rock_Slate"
    },
    {
      "x": 8,
      "y": 6,
      "z": 6,
      "name": "Rock_Slate"
    },
    {
      "x": 8,
      "y": 7,
      "z": 6,
      "name": "Rock_Slate"
    },
    {
      "x": 8,
      "y": 8,
      "z": 6,
      "name": "Rock_Slate"
    },
    {
      "x": 8,
      "y": 4,
      "z": 7,
      "name": "Rock_Slate"
    },
    {
      "x": 8,
      "y": 5,
      "z": 7,
      "name": "Rock_Slate"
    },
    {
      "x": 8,
      "y": 6,
      "z": 7,
      "name": "Rock_Slate"
    },
    {
      "x": 8,
      "y": 7,
      "z": 7,
      "name": "Rock_Slate"
    },
    {
      "x": 8,
      "y": 5,
      "z": 8,
      "name": "Rock_Slate"
    },
    {
      "x": 8,
      "y": 6,
      "z": 8,
      "name": "Rock_Slate"
    },
    {
      "x": 9,
      "y": 5,
      "z": 5,
      "name": "Rock_Slate"
    },
    {
      "x": 9,
      "y": 6,
      "z": 5,
      "name": "Rock_Slate"
    },
    {
      "x": 9,
      "y": 7,
      "z": 5,
      "name": "Rock_Slate"
    },
    {
      "x": 9,
      "y": 5,
      "z": 6,
      "name": "Rock_Slate"
    },
    {
      "x": 9,
      "y": 6,
      "z": 6,
      "name": "Rock_Slate"
    },
    {
      "x": 9,
      "y": 7,
      "z": 6,
      "name": "Rock_Slate"
    },
    {
      "x": 9,
      "y": 6,
      "z": 7,
      "name": "Rock_Slate"
    }
  ]
}