{
  "version": 8,
  "blockIdVersion": 8,
  "anchorX": 9,
  "anchorY": 3,
  "anchorZ": 7,
  "blocks": [
    {
      "x": 2,
      "y": 10,
      "z": 8,
      "name": "Plant_Leaves_Jungle"
    },
    {
      "x": 2,
      "y": 11,
      "z": 8,
      "name": "Plant_Leaves_Jungle"
    },
    {
      "x": 3,
      "y": 10,
      "z": 3,
      "name": "Plant_Leaves_Jungle"
    },
    {
      "x": 3,
      "y": 11,
      "z": 3,
      "name": "Plant_Leaves_Jungle"
    },
    {
      "x": 3,
      "y": 11,
      "z": 4,
      "name": "Plant_Leaves_Jungle"
    },
    {
      "x": 3,
      "y": 11,
      "z": 5,
      "name": "Plant_Leaves_Jungle"
    },
    {
      "x": 3,
      "y": 12,
      "z": 5,
      "name": "Plant_Leaves_Jungle"
    },
    {
      "x": 3,
      "y": 11,
      "z": 7,
      "name": "Plant_Leaves_Jungle"
    },
    {
      "x": 3,
      "y": 12,
      "z": 7,
      "name": "Plant_Leaves_Jungle"
    },
    {
      "x": 3,
      "y": 11,
      "z": 8,
      "name": "Plant_Leaves_Jungle"
    },
    {
      "x": 3,
      "y": 12,
      "z": 8,
      "name": "Plant_Leaves_Jungle"
    },
    {
      "x": 4,
      "y": 11,
      "z": 3,
      "name": "Plant_Leaves_Jungle"
    },
    {
      "x": 4,
      "y": 12,
      "z": 3,
      "name": "Plant_Leaves_Jungle"
    },
    {
      "x": 4,
      "y": 12,
      "z": 4,
      "name": "Plant_Leaves_Jungle"
    },
    {
      "x": 4,
      "y": 13,
      "z": 4,
      "name": "Plant_Leaves_Jungle"
    },
    {
      "x": 4,
      "y": 12,
      "z": 5,
      "name": "Plant_Leaves_Jungle"
    },
    {
      "x": 4,
      "y": 13,
      "z": 5,
      "name": "Plant_Leaves_Jungle"
    },
    {
      "x": 4,
      "y": 12,
      "z": 6,
      "name": "Plant_Leaves_Jungle"
    },
    {
      "x": 4,
      "y": 13,
      "z": 6,
      "name": "Plant_Leaves_Jungle"
    },
    {
      "x": 4,
      "y": 12,
      "z": 7,
      "name": "Plant_Leaves_Jungle"
    },
    {
      "x": 4,
      "y": 13,
      "z": 7,
      "name": "Plant_Leaves_Jungle"
    },
    {
      "x": 4,
      "y": 11,
      "z": 8,
      "name": "Plant_Leaves_Jungle"
    },
    {
      "x": 4,
      "y": 12,
      "z": 8,
      "name": "Plant_Leaves_Jungle"
    },
    {
      "x": 4,
      "y": 13,
      "z": 8,
      "name": "Plant_Leaves_Jungle"
    },
    {
      "x": 5,
      "y": 12,
      "z": 4,
      "name": "Plant_Leaves_Jungle"
    },
    {
      "x": 5,
      "y": 13,
      "z": 4,
      "name": "Plant_Leaves_Jungle"
    },
    {
      "x": 5,
      "y": 12,
      "z": 5,
      "name": "Wood_Jungle_Trunk_Full"
    },
    {
      "x": 5,
      "y": 13,
      "z": 5,
      "name": "Plant_Leaves_Jungle"
    },
    {
      "x": 5,
      "y": 12,
      "z": 6,
      "name": "Wood_Jungle_Trunk_Full"
    },
    {
      "x": 5,
      "y": 13,
      "z": 6,
      "name": "Plant_Leaves_Jungle"
    },
    {
      "x": 5,
      "y": 12,
      "z": 7,
      "name": "Plant_Leaves_Jungle"
    },
    {
      "x": 5,
      "y": 13,
      "z": 7,
      "name": "Plant_Leaves_Jungle"
    },
    {
      "x": 5,
      "y": 12,
      "z": 8,
      "name": "Plant_Leaves_Jungle"
    },
    {
      "x": 6,
      "y": 12,
      "z": 4,
      "name": "Plant_Leaves_Jungle"
    },
    {
      "x": 6,
      "y": 13,
      "z": 4,
      "name": "Plant_Leaves_Jungle"
    },
    {
      "x": 6,
      "y": 12,
      "z": 5,
      "name": "Plant_Leaves_Jungle"
    },
    {
      "x": 6,
      "y": 13,
      "z": 5,
      "name": "Plant_Leaves_Jungle"
    },
    {
      "x": 6,
      "y": 12,
      "z": 6,
      "name": "Wood_Jungle_Trunk_Full"
    },
    {
      "x": 6,
      "y": 13,
      "z": 6,
      "name": "Plant_Leaves_Jungle"
    },
    {
      "x": 6,
      "y": 12,
      "z": 7,
      "name": "Plant_Leaves_Jungle"
    },
    {
      "x": 6,
      "y": 13,
      "z": 7,
      "name": "Plant_Leaves_Jungle"
    },
    {
      "x": 6,
      "y": 12,
      "z": 8,
      "name": "Plant_Leaves_Jungle"
    },
    {
      "x": 6,
      "y": 13,
      "z": 8,
      "name": "Plant_Leaves_Jungle"
    },
    {
      "x": 7,
      "y": 12,
      "z": 4,
      "name": "Plant_Leaves_Jungle"
    },
    {
      "x": 7,
      "y": 13,
      "z": 5,
      "name": "Plant_Leaves_Jungle"
    },
    {
      "x": 7,
      "y": 12,
      "z": 6,
      "name": "Wood_Jungle_Trunk_Full"
    },
    {
      "x": 7,
      "y": 13,
      "z": 6,
      "name": "Plant_Leaves_Jungle"
    },
    {
      "x": 7,
      "y": 13,
      "z": 7,
      "name": "Plant_Leaves_Jungle"
    },
    {
      "x": 7,
      "y": 10,
      "z": 8,
      "name": "Plant_Leaves_Jungle"
    },
    {
      "x": 8,
      "y": 13,
      "z": 5,
      "name": "Plant_Leaves_Jungle"
    },
    {
      "x": 8,
      "y": 8,
      "z": 6,
      "name": "Wood_Jungle_Trunk_Full"
    },
    {
      "x": 8,
      "y": 9,
      "z": 6,
      "name": "Wood_Jungle_Trunk_Full"
    },
    {
      "x": 8,
      "y": 10,
      "z": 6,
      "name": "Wood_Jungle_Trunk_Full"
    },
    {
      "x": 8,
      "y": 11,
      "z": 6,
      "name": "Wood_Jungle_Trunk_Full"
    },
    {
      "x": 8,
      "y": 12,
      "z": 6,
      "name": "Wood_Jungle_Trunk_Full"
    },
    {
      "x": 8,
      "y": 13,
      "z": 6,
      "name": "Plant_Leaves_Jungle"
    },
    {
      "x": 8,
      "y": 10,
      "z": 7,
      "name": "Plant_Leaves_Jungle"
    },
    {
      "x": 8,
      "y": 11,
      "z": 7,
      "name": "Plant_Leaves_Jungle"
    },
    {
      "x": 8,
      "y": 13,
      "z": 7,
      "name": "Plant_Leaves_Jungle"
    },
    {
      "x": 8,
      "y": 10,
      "z": 8,
      "name": "Plant_Leaves_Jungle"
    },
    {
      "x": 8,
      "y": 11,
      "z": 8,
      "name": "Plant_Leaves_Jungle"
    },
    {
      "x": 8,
      "y": 10,
      "z": 9,
      "name": "Plant_Leaves_Jungle"
    },
    {
      "x": 9,
      "y": 7,
      "z": 6,
      "name": "Wood_Jungle_Trunk_Full"
    },
    {
      "x": 9,
      "y": 8,
      "z": 6,
      "name": "Wood_Jungle_Trunk_Full"
    },
    {
      "x": 9,
      "y": 9,
      "z": 6,
      "name": "Wood_Jungle_Trunk_Full"
    },
    {
      "x": 9,
      "y": 3,
      "z": 7,
      "name": "Wood_Jungle_Trunk_Full"
    },
    {
      "x": 9,
      "y": 4,
      "z": 7,
      "name": "Wood_Jungle_Trunk_Full"
    },
    {
      "x": 9,
      "y": 5,
      "z": 7,
      "name": "Wood_Jungle_Trunk_Full"
    },
    {
      "x": 9,
      "y": 6,
      "z": 7,
      "name": "Wood_Jungle_Trunk_Full"
    },
    {
      "x": 9,
      "y": 7,
      "z": 7,
      "name": "Wood_Jungle_Trunk_Full"
    },
    {
      "x": 9,
      "y": 11,
      "z": 7,
      "name": "Plant_Leaves_Jungle"
    },
    {
      "x": 9,
      "y": 7,
      "z": 8,
      "name": "Wood_Jungle_Trunk_Full"
    },
    {
      "x": 9,
      "y": 8,
      "z": 8,
      "name": "Wood_Jungle_Trunk_Full"
    },
    {
      "x": 9,
      "y": 9,
      "z": 8,
      "name": "Wood_Jungle_Trunk_Full"
    },
    {
      "x": 9,
      "y": 10,
      "z": 8,
      "name": "Wood_Jungle_Trunk_Full"
    },
    {
      "x": 9,
      "y": 11,
      "z": 8,
      "name": "Plant_Leaves_Jungle"
    },
    {
      "x": 9,
      "y": 10,
      "z": 9,
      "name": "Plant_Leaves_Jungle"
    },
    {
      "x": 9,
      "y": 13,
      "z": 11,
      "name": "Plant_Leaves_Jungle"
    },
    {
      "x": 9,
      "y": 12,
      "z": 12,
      "name": "Plant_Leaves_Jungle"
    },
    {
      "x": 9,
      "y": 13,
      "z": 12,
      "name": "Plant_Leaves_Jungle"
    },
    {
      "x": 9,
      "y": 12,
      "z": 13,
      "name": "Plant_Leaves_Jungle"
    },
    {
      "x": 10,
      "y": 9,
      "z": 8,
      "name": "Wood_Jungle_Trunk_Full"
    },
    {
      "x": 10,
      "y": 10,
      "z": 8,
      "name": "Wood_Jungle_Trunk_Full"
    },
    {
      "x": 10,
      "y": 11,
      "z": 8,
      "name": "Wood_Jungle_Trunk_Full"
    },
    {
      "x": 10,
      "y": 11,
      "z": 9,
      "name": "Wood_Jungle_Trunk_Full"
    },
    {
      "x": 10,
      "y": 12,
      "z": 10,
      "name": "Plant_Leaves_Jungle"
    },
    {
      "x": 10,
      "y": 13,
      "z": 10,
      "name": "Plant_Leaves_Jungle"
    },
    {
      "x": 10,
      "y": 12,
      "z": 11,
      "name": "Plant_Leaves_Jungle"
    },
    {
      "x": 10,
      "y": 13,
      "z": 11,
      "name": "Plant_Leaves_Jungle"
    },
    {
      "x": 10,
      "y": 12,
      "z": 12,
      "name": "Plant_Leaves_Jungle"
    },
    {
      "x": 10,
      "y": 13,
      "z": 12,
      "name": "Plant_Leaves_Jungle"
    },
    {
      "x": 10,
      "y": 12,
      "z": 13,
      "name": "Plant_Leaves_Jungle"
    },
    {
      "x": 10,
      "y": 13,
      "z": 13,
      "name": "Plant_Leaves_Jungle"
    },
    {
      "x": 11,
      "y": 12,
      "z": 8,
      "name": "Plant_Leaves_Jungle"
    },
    {
      "x": 11,
      "y": 12,
      "z": 9,
      "name": "Wood_Jungle_Trunk_Full"
    },
    {
      "x": 11,
      "y": 13,
      "z": 9,
      "name": "Plant_Leaves_Jungle"
    },
    {
      "x": 11,
      "y": 12,
      "z": 10,
      "name": "Wood_Jungle_Trunk_Full"
    },
    {
      "x": 11,
      "y": 13,
      "z": 10,
      "name": "Plant_Leaves_Jungle"
    },
    {
      "x": 11,
      "y": 12,
      "z": 11,
      "name": "Wood_Jungle_Trunk_Full"
    },
    {
      "x": 11,
      "y": 13,
      "z": 11,
      "name": "Plant_Leaves_Jungle"
    },
    {
      "x": 11,
      "y": 12,
      "z": 12,
      "name": "Plant_Leaves_Jungle"
    },
    {
      "x": 11,
      "y": 13,
      "z": 12,
      "name": "Plant_Leaves_Jungle"
    },
    {
      "x": 11,
      "y": 11,
      "z": 13,
      "name": "Plant_Leaves_Jungle"
    },
    {
      "x": 11,
      "y": 12,
      "z": 13,
      "name": "Plant_Leaves_Jungle"
    },
    {
      "x": 11,
      "y": 13,
      "z": 13,
      "name": "Plant_Leaves_Jungle"
    },
    {
      "x": 11,
      "y": 12,
      "z": 14,
      "name": "Plant_Leaves_Jungle"
    },
    {
      "x": 12,
      "y": 12,
      "z": 8,
      "name": "Plant_Leaves_Jungle"
    },
    {
      "x": 12,
      "y": 12,
      "z": 9,
      "name": "Plant_Leaves_Jungle"
    },
    {
      "x": 12,
      "y": 13,
      "z": 9,
      "name": "Plant_Leaves_Jungle"
    },
    {
      "x": 12,
      "y": 12,
      "z": 10,
      "name": "Plant_Leaves_Jungle"
    },
    {
      "x": 12,
      "y": 13,
      "z": 10,
      "name": "Plant_Leaves_Jungle"
    },
    {
      "x": 12,
      "y": 12,
      "z": 11,
      "name": "Plant_Leaves_Jungle"
    },
    {
      "x": 12,
      "y": 13,
      "z": 11,
      "name": "Plant_Leaves_Jungle"
    },
    {
      "x": 12,
      "y": 12,
      "z": 12,
      "name": "Plant_Leaves_Jungle"
    },
    {
      "x": 12,
      "y": 13,
      "z": 12,
      "name": "Plant_Leaves_Jungle"
    },
    {
      "x": 12,
      "y": 12,
      "z": 13,
      "name": "Plant_Leaves_Jungle"
    },
    {
      "x": 12,
      "y": 11,
      "z": 14,
      "name": "Plant_Leaves_Jungle"
    },
    {
      "x": 13,
      "y": 12,
      "z": 9,
      "name": "Plant_Leaves_Jungle"
    },
    {
      "x": 13,
      "y": 12,
      "z": 10,
      "name": "Plant_Leaves_Jungle"
    },
    {
      "x": 13,
      "y": 12,
      "z": 11,
      "name": "Plant_Leaves_Jungle"
    },
    {
      "x": 13,
      "y": 13,
      "z": 11,
      "name": "Plant_Leaves_Jungle"
    },
    {
      "x": 13,
      "y": 12,
      "z": 12,
      "name": "Plant_Leaves_Jungle"
    },
    {
      "x": 13,
      "y": 13,
      "z": 12,
      "name": "Plant_Leaves_Jungle"
    },
    {
      "x": 13,
      "y": 11,
      "z": 13,
      "name": "Plant_Leaves_Jungle"
    },
    {
      "x": 13,
      "y": 12,
      "z": 13,
      "name": "Plant_Leaves_Jungle"
    },
    {
      "x": 13,
      "y": 10,
      "z": 14,
      "name": "Plant_Leaves_Jungle"
    },
    {
      "x": 13,
      "y": 11,
      "z": 14,
      "name": "Plant_Leaves_Jungle"
    },
    {
      "x": 14,
      "y": 12,
      "z": 11,
      "name": "Plant_Leaves_Jungle"
    },
    {
      "x": 14,
      "y": 12,
      "z": 13,
      "name": "Plant_Leaves_Jungle"
    },
    {
      "x": 14,
      "y": 11,
      "z": 14,
      "name": "Plant_Leaves_Jungle"
    }
  ]
}