{
  "version": 8,
  "blockIdVersion": 8,
  "anchorX": 0,
  "anchorY": 3,
  "anchorZ": 0,
  "blocks": [
    {
      "x": -6,
      "y": 2,
      "z": -2,
      "name": "Soil_Dirt"
    },
    {
      "x": -6,
      "y": 3,
      "z": -2,
      "name": "Soil_Dirt"
    },
    {
      "x": -6,
      "y": 4,
      "z": -2,
      "name": "Soil_Grass"
    },
    {
      "x": -6,
      "y": 0,
      "z": -1,
      "name": "Soil_Dirt"
    },
    {
      "x": -6,
      "y": 1,
      "z": -1,
      "name": "Soil_Dirt"
    },
    {
      "x": -6,
      "y": 2,
      "z": -1,
      "name": "Soil_Dirt"
    },
    {
      "x": -6,
      "y": 3,
      "z": -1,
      "name": "Soil_Dirt"
    },
    {
      "x": -6,
      "y": 4,
      "z": -1,
      "name": "Soil_Grass"
    },
    {
      "x": -6,
      "y": 5,
      "z": -1,
      "name": "Plant_Grass_Sharp"
    },
    {
      "x": -5,
      "y": 0,
      "z": -3,
      "name": "Soil_Dirt"
    },
    {
      "x": -5,
      "y": 1,
      "z": -3,
      "name": "Soil_Dirt"
    },
    {
      "x": -5,
      "y": 2,
      "z": -3,
      "name": "Soil_Dirt"
    },
    {
      "x": -5,
      "y": 3,
      "z": -3,
      "name": "Soil_Dirt"
    },
    {
      "x": -5,
      "y": 4,
      "z": -3,
      "name": "Soil_Grass"
    },
    {
      "x": -5,
      "y": 5,
      "z": -3,
      "name": "Wood_Oak_Branch_Corner",
      "rotation": 8
    },
    {
      "x": -5,
      "y": 0,
      "z": -2,
      "name": "Soil_Dirt"
    },
    {
      "x": -5,
      "y": 1,
      "z": -2,
      "name": "Soil_Dirt"
    },
    {
      "x": -5,
      "y": 2,
      "z": -2,
      "name": "Soil_Dirt"
    },
    {
      "x": -5,
      "y": 3,
      "z": -2,
      "name": "Soil_Dirt"
    },
    {
      "x": -5,
      "y": 4,
      "z": -2,
      "name": "Soil_Grass"
    },
    {
      "x": -5,
      "y": 5,
      "z": -2,
      "name": "Wood_Oak_Branch_Long",
      "rotation": 4
    },
    {
      "x": -5,
      "y": 0,
      "z": -1,
      "name": "Soil_Dirt"
    },
    {
      "x": -5,
      "y": 1,
      "z": -1,
      "name": "Soil_Dirt"
    },
    {
      "x": -5,
      "y": 2,
      "z": -1,
      "name": "Soil_Dirt"
    },
    {
      "x": -5,
      "y": 3,
      "z": -1,
      "name": "Soil_Dirt"
    },
    {
      "x": -5,
      "y": 4,
      "z": -1,
      "name": "Soil_Grass"
    },
    {
      "x": -5,
      "y": 5,
      "z": -1,
      "name": "Wood_Oak_Branch_Long",
      "rotation": 4
    },
    {
      "x": -5,
      "y": 0,
      "z": 0,
      "name": "Soil_Dirt"
    },
    {
      "x": -5,
      "y": 1,
      "z": 0,
      "name": "Soil_Dirt"
    },
    {
      "x": -5,
      "y": 2,
      "z": 0,
      "name": "Soil_Dirt"
    },
    {
      "x": -5,
      "y": 3,
      "z": 0,
      "name": "Soil_Dirt"
    },
    {
      "x": -5,
      "y": 4,
      "z": 0,
      "name": "Soil_Grass"
    },
    {
      "x": -5,
      "y": 5,
      "z": 0,
      "name": "Wood_Oak_Branch_Corner"
    },
    {
      "x": -5,
      "y": 6,
      "z": 0,
      "name": "Wood_Oak_Branch_Corner",
      "rotation": 8
    },
    {
      "x": -5,
      "y": 0,
      "z": 1,
      "name": "Soil_Dirt"
    },
    {
      "x": -5,
      "y": 1,
      "z": 1,
      "name": "Soil_Dirt"
    },
    {
      "x": -5,
      "y": 2,
      "z": 1,
      "name": "Soil_Dirt"
    },
    {
      "x": -5,
      "y": 3,
      "z": 1,
      "name": "Soil_Dirt"
    },
    {
      "x": -5,
      "y": 4,
      "z": 1,
      "name": "Soil_Grass"
    },
    {
      "x": -5,
      "y": 5,
      "z": 1,
      "name": "Wood_Oak_Branch_Corner",
      "rotation": 2
    },
    {
      "x": -5,
      "y": 6,
      "z": 1,
      "name": "Wood_Oak_Branch_Corner",
      "rotation": 10
    },
    {
      "x": -5,
      "y": 1,
      "z": 2,
      "name": "Soil_Dirt"
    },
    {
      "x": -5,
      "y": 2,
      "z": 2,
      "name": "Soil_Dirt"
    },
    {
      "x": -5,
      "y": 3,
      "z": 2,
      "name": "Soil_Dirt"
    },
    {
      "x": -5,
      "y": 4,
      "z": 2,
      "name": "Soil_Grass"
    },
    {
      "x": -5,
      "y": 5,
      "z": 2,
      "name": "Wood_Oak_Branch_Corner",
      "rotation": 10
    },
    {
      "x": -4,
      "y": 1,
      "z": -4,
      "name": "Soil_Dirt"
    },
    {
      "x": -4,
      "y": 2,
      "z": -4,
      "name": "Soil_Dirt"
    },
    {
      "x": -4,
      "y": 3,
      "z": -4,
      "name": "Soil_Dirt"
    },
    {
      "x": -4,
      "y": 4,
      "z": -4,
      "name": "Soil_Leaves"
    },
    {
      "x": -4,
      "y": 5,
      "z": -4,
      "name": "Plant_Grass_Sharp"
    },
    {
      "x": -4,
      "y": 0,
      "z": -3,
      "name": "Soil_Dirt"
    },
    {
      "x": -4,
      "y": 1,
      "z": -3,
      "name": "Soil_Dirt"
    },
    {
      "x": -4,
      "y": 2,
      "z": -3,
      "name": "Soil_Dirt"
    },
    {
      "x": -4,
      "y": 3,
      "z": -3,
      "name": "Soil_Dirt"
    },
    {
      "x": -4,
      "y": 4,
      "z": -3,
      "name": "Soil_Leaves"
    },
    {
      "x": -4,
      "y": 5,
      "z": -3,
      "name": "Plant_Grass_Sharp"
    },
    {
      "x": -4,
      "y": 0,
      "z": -2,
      "name": "Soil_Dirt"
    },
    {
      "x": -4,
      "y": 1,
      "z": -2,
      "name": "Soil_Dirt"
    },
    {
      "x": -4,
      "y": 2,
      "z": -2,
      "name": "Soil_Dirt"
    },
    {
      "x": -4,
      "y": 3,
      "z": -2,
      "name": "Soil_Dirt"
    },
    {
      "x": -4,
      "y": 4,
      "z": -2,
      "name": "Soil_Dirt"
    },
    {
      "x": -4,
      "y": 5,
      "z": -2,
      "name": "Soil_Clay_Brick"
    },
    {
      "x": -4,
      "y": 0,
      "z": -1,
      "name": "Soil_Dirt"
    },
    {
      "x": -4,
      "y": 1,
      "z": -1,
      "name": "Soil_Dirt"
    },
    {
      "x": -4,
      "y": 2,
      "z": -1,
      "name": "Soil_Dirt"
    },
    {
      "x": -4,
      "y": 3,
      "z": -1,
      "name": "Soil_Dirt"
    },
    {
      "x": -4,
      "y": 4,
      "z": -1,
      "name": "Soil_Dirt"
    },
    {
      "x": -4,
      "y": 5,
      "z": -1,
      "name": "Soil_Dirt_Tilled",
      "components": {
        "Components": {
          "TilledSoil": {
            "Version": 1
          }
        }
      }
    },
    {
      "x": -4,
      "y": 0,
      "z": 0,
      "name": "Soil_Dirt"
    },
    {
      "x": -4,
      "y": 1,
      "z": 0,
      "name": "Soil_Dirt"
    },
    {
      "x": -4,
      "y": 2,
      "z": 0,
      "name": "Soil_Dirt"
    },
    {
      "x": -4,
      "y": 3,
      "z": 0,
      "name": "Soil_Dirt"
    },
    {
      "x": -4,
      "y": 4,
      "z": 0,
      "name": "Soil_Dirt"
    },
    {
      "x": -4,
      "y": 5,
      "z": 0,
      "name": "Soil_Clay_Brick_Half"
    },
    {
      "x": -4,
      "y": 0,
      "z": 1,
      "name": "Soil_Dirt"
    },
    {
      "x": -4,
      "y": 1,
      "z": 1,
      "name": "Soil_Dirt"
    },
    {
      "x": -4,
      "y": 2,
      "z": 1,
      "name": "Soil_Dirt"
    },
    {
      "x": -4,
      "y": 3,
      "z": 1,
      "name": "Soil_Dirt"
    },
    {
      "x": -4,
      "y": 4,
      "z": 1,
      "name": "Soil_Dirt"
    },
    {
      "x": -4,
      "y": 5,
      "z": 1,
      "name": "Soil_Clay_Brick_Half"
    },
    {
      "x": -4,
      "y": 0,
      "z": 2,
      "name": "Soil_Dirt"
    },
    {
      "x": -4,
      "y": 1,
      "z": 2,
      "name": "Soil_Dirt"
    },
    {
      "x": -4,
      "y": 2,
      "z": 2,
      "name": "Soil_Dirt"
    },
    {
      "x": -4,
      "y": 3,
      "z": 2,
      "name": "Soil_Dirt"
    },
    {
      "x": -4,
      "y": 4,
      "z": 2,
      "name": "Soil_Dirt"
    },
    {
      "x": -4,
      "y": 5,
      "z": 2,
      "name": "Soil_Clay_Brick_Half"
    },
    {
      "x": -4,
      "y": 0,
      "z": 3,
      "name": "Soil_Dirt"
    },
    {
      "x": -4,
      "y": 1,
      "z": 3,
      "name": "Soil_Dirt"
    },
    {
      "x": -4,
      "y": 2,
      "z": 3,
      "name": "Soil_Dirt"
    },
    {
      "x": -4,
      "y": 3,
      "z": 3,
      "name": "Soil_Dirt"
    },
    {
      "x": -4,
      "y": 4,
      "z": 3,
      "name": "Soil_Leaves"
    },
    {
      "x": -4,
      "y": 1,
      "z": 4,
      "name": "Soil_Dirt"
    },
    {
      "x": -4,
      "y": 2,
      "z": 4,
      "name": "Soil_Dirt"
    },
    {
      "x": -4,
      "y": 3,
      "z": 4,
      "name": "Soil_Dirt"
    },
    {
      "x": -4,
      "y": 4,
      "z": 4,
      "name": "Soil_Leaves"
    },
    {
      "x": -3,
      "y": 0,
      "z": -4,
      "name": "Soil_Dirt"
    },
    {
      "x": -3,
      "y": 1,
      "z": -4,
      "name": "Soil_Dirt"
    },
    {
      "x": -3,
      "y": 2,
      "z": -4,
      "name": "Soil_Dirt"
    },
    {
      "x": -3,
      "y": 3,
      "z": -4,
      "name": "Soil_Dirt"
    },
    {
      "x": -3,
      "y": 4,
      "z": -4,
      "name": "Soil_Leaves"
    },
    {
      "x": -3,
      "y": 0,
      "z": -3,
      "name": "Soil_Dirt"
    },
    {
      "x": -3,
      "y": 1,
      "z": -3,
      "name": "Soil_Dirt"
    },
    {
      "x": -3,
      "y": 2,
      "z": -3,
      "name": "Soil_Dirt"
    },
    {
      "x": -3,
      "y": 3,
      "z": -3,
      "name": "Soil_Dirt"
    },
    {
      "x": -3,
      "y": 4,
      "z": -3,
      "name": "Soil_Leaves"
    },
    {
      "x": -3,
      "y": 5,
      "z": -3,
      "name": "Plant_Grass_Sharp"
    },
    {
      "x": -3,
      "y": 0,
      "z": -2,
      "name": "Soil_Dirt"
    },
    {
      "x": -3,
      "y": 1,
      "z": -2,
      "name": "Soil_Dirt"
    },
    {
      "x": -3,
      "y": 2,
      "z": -2,
      "name": "Soil_Dirt"
    },
    {
      "x": -3,
      "y": 3,
      "z": -2,
      "name": "Soil_Dirt"
    },
    {
      "x": -3,
      "y": 4,
      "z": -2,
      "name": "Soil_Dirt"
    },
    {
      "x": -3,
      "y": 5,
      "z": -2,
      "name": "Soil_Clay_Brick"
    },
    {
      "x": -3,
      "y": 0,
      "z": -1,
      "name": "Soil_Dirt"
    },
    {
      "x": -3,
      "y": 1,
      "z": -1,
      "name": "Soil_Dirt"
    },
    {
      "x": -3,
      "y": 2,
      "z": -1,
      "name": "Soil_Dirt"
    },
    {
      "x": -3,
      "y": 3,
      "z": -1,
      "name": "Soil_Dirt"
    },
    {
      "x": -3,
      "y": 4,
      "z": -1,
      "name": "Soil_Dirt"
    },
    {
      "x": -3,
      "y": 5,
      "z": -1,
      "name": "Soil_Dirt_Tilled",
      "components": {
        "Components": {
          "TilledSoil": {
            "Version": 1
          }
        }
      }
    },
    {
      "x": -3,
      "y": 6,
      "z": -1,
      "name": "*Plant_Crop_Wheat_Block_State_Definitions_Stage3",
      "components": {
        "Components": {
          "FarmingBlock": {}
        }
      }
    },
    {
      "x": -3,
      "y": 0,
      "z": 0,
      "name": "Soil_Dirt"
    },
    {
      "x": -3,
      "y": 1,
      "z": 0,
      "name": "Soil_Dirt"
    },
    {
      "x": -3,
      "y": 2,
      "z": 0,
      "name": "Soil_Dirt"
    },
    {
      "x": -3,
      "y": 3,
      "z": 0,
      "name": "Soil_Dirt"
    },
    {
      "x": -3,
      "y": 4,
      "z": 0,
      "name": "Soil_Dirt"
    },
    {
      "x": -3,
      "y": 5,
      "z": 0,
      "name": "Soil_Dirt_Tilled",
      "components": {
        "Components": {
          "TilledSoil": {
            "Version": 1
          }
        }
      }
    },
    {
      "x": -3,
      "y": 6,
      "z": 0,
      "name": "*Plant_Crop_Wheat_Block_State_Definitions_StageFinal",
      "components": {
        "Components": {
          "FarmingBlock": {}
        }
      }
    },
    {
      "x": -3,
      "y": 7,
      "z": 0,
      "name": "*Plant_Crop_Wheat_Block_State_Definitions_StageFinal",
      "components": {
        "Components": {
          "FarmingBlock": {}
        }
      },
      "filler": 1024
    },
    {
      "x": -3,
      "y": 0,
      "z": 1,
      "name": "Soil_Dirt"
    },
    {
      "x": -3,
      "y": 1,
      "z": 1,
      "name": "Soil_Dirt"
    },
    {
      "x": -3,
      "y": 2,
      "z": 1,
      "name": "Soil_Dirt"
    },
    {
      "x": -3,
      "y": 3,
      "z": 1,
      "name": "Soil_Dirt"
    },
    {
      "x": -3,
      "y": 4,
      "z": 1,
      "name": "Soil_Dirt"
    },
    {
      "x": -3,
      "y": 5,
      "z": 1,
      "name": "Soil_Clay_Brick"
    },
    {
      "x": -3,
      "y": 0,
      "z": 2,
      "name": "Soil_Dirt"
    },
    {
      "x": -3,
      "y": 1,
      "z": 2,
      "name": "Soil_Dirt"
    },
    {
      "x": -3,
      "y": 2,
      "z": 2,
      "name": "Soil_Dirt"
    },
    {
      "x": -3,
      "y": 3,
      "z": 2,
      "name": "Soil_Dirt"
    },
    {
      "x": -3,
      "y": 4,
      "z": 2,
      "name": "Soil_Dirt"
    },
    {
      "x": -3,
      "y": 5,
      "z": 2,
      "name": "Soil_Clay_Brick"
    },
    {
      "x": -3,
      "y": 0,
      "z": 3,
      "name": "Soil_Dirt"
    },
    {
      "x": -3,
      "y": 1,
      "z": 3,
      "name": "Soil_Dirt"
    },
    {
      "x": -3,
      "y": 2,
      "z": 3,
      "name": "Soil_Dirt"
    },
    {
      "x": -3,
      "y": 3,
      "z": 3,
      "name": "Soil_Dirt"
    },
    {
      "x": -3,
      "y": 4,
      "z": 3,
      "name": "Soil_Leaves"
    },
    {
      "x": -3,
      "y": 5,
      "z": 3,
      "name": "Soil_Clay_Brick_Half"
    },
    {
      "x": -3,
      "y": 1,
      "z": 4,
      "name": "Soil_Dirt"
    },
    {
      "x": -3,
      "y": 2,
      "z": 4,
      "name": "Soil_Dirt"
    },
    {
      "x": -3,
      "y": 3,
      "z": 4,
      "name": "Soil_Dirt"
    },
    {
      "x": -3,
      "y": 4,
      "z": 4,
      "name": "Soil_Leaves"
    },
    {
      "x": -2,
      "y": 0,
      "z": -4,
      "name": "Soil_Dirt"
    },
    {
      "x": -2,
      "y": 1,
      "z": -4,
      "name": "Soil_Dirt"
    },
    {
      "x": -2,
      "y": 2,
      "z": -4,
      "name": "Soil_Dirt"
    },
    {
      "x": -2,
      "y": 3,
      "z": -4,
      "name": "Soil_Dirt"
    },
    {
      "x": -2,
      "y": 4,
      "z": -4,
      "name": "Soil_Leaves"
    },
    {
      "x": -2,
      "y": 0,
      "z": -3,
      "name": "Soil_Dirt"
    },
    {
      "x": -2,
      "y": 1,
      "z": -3,
      "name": "Soil_Dirt"
    },
    {
      "x": -2,
      "y": 2,
      "z": -3,
      "name": "Soil_Dirt"
    },
    {
      "x": -2,
      "y": 3,
      "z": -3,
      "name": "Soil_Dirt"
    },
    {
      "x": -2,
      "y": 4,
      "z": -3,
      "name": "Soil_Dirt"
    },
    {
      "x": -2,
      "y": 5,
      "z": -3,
      "name": "Soil_Clay_Brick_Half"
    },
    {
      "x": -2,
      "y": 0,
      "z": -2,
      "name": "Soil_Dirt"
    },
    {
      "x": -2,
      "y": 1,
      "z": -2,
      "name": "Soil_Dirt"
    },
    {
      "x": -2,
      "y": 2,
      "z": -2,
      "name": "Soil_Dirt"
    },
    {
      "x": -2,
      "y": 3,
      "z": -2,
      "name": "Soil_Dirt"
    },
    {
      "x": -2,
      "y": 4,
      "z": -2,
      "name": "Soil_Dirt"
    },
    {
      "x": -2,
      "y": 5,
      "z": -2,
      "name": "Soil_Clay_Brick"
    },
    {
      "x": -2,
      "y": 0,
      "z": -1,
      "name": "Soil_Dirt"
    },
    {
      "x": -2,
      "y": 1,
      "z": -1,
      "name": "Soil_Dirt"
    },
    {
      "x": -2,
      "y": 2,
      "z": -1,
      "name": "Soil_Dirt"
    },
    {
      "x": -2,
      "y": 3,
      "z": -1,
      "name": "Soil_Dirt"
    },
    {
      "x": -2,
      "y": 4,
      "z": -1,
      "name": "Soil_Dirt"
    },
    {
      "x": -2,
      "y": 5,
      "z": -1,
      "name": "Soil_Clay_Brick"
    },
    {
      "x": -2,
      "y": 0,
      "z": 0,
      "name": "Soil_Dirt"
    },
    {
      "x": -2,
      "y": 1,
      "z": 0,
      "name": "Soil_Dirt"
    },
    {
      "x": -2,
      "y": 2,
      "z": 0,
      "name": "Soil_Dirt"
    },
    {
      "x": -2,
      "y": 3,
      "z": 0,
      "name": "Soil_Dirt"
    },
    {
      "x": -2,
      "y": 4,
      "z": 0,
      "name": "Soil_Dirt"
    },
    {
      "x": -2,
      "y": 5,
      "z": 0,
      "name": "Soil_Dirt_Tilled",
      "components": {
        "Components": {
          "TilledSoil": {
            "Version": 1
          }
        }
      }
    },
    {
      "x": -2,
      "y": 0,
      "z": 1,
      "name": "Soil_Dirt"
    },
    {
      "x": -2,
      "y": 1,
      "z": 1,
      "name": "Soil_Dirt"
    },
    {
      "x": -2,
      "y": 2,
      "z": 1,
      "name": "Soil_Dirt"
    },
    {
      "x": -2,
      "y": 3,
      "z": 1,
      "name": "Soil_Dirt"
    },
    {
      "x": -2,
      "y": 4,
      "z": 1,
      "name": "Soil_Dirt"
    },
    {
      "x": -2,
      "y": 5,
      "z": 1,
      "name": "Soil_Dirt_Tilled",
      "components": {
        "Components": {
          "TilledSoil": {
            "Version": 1
          }
        }
      }
    },
    {
      "x": -2,
      "y": 0,
      "z": 2,
      "name": "Soil_Dirt"
    },
    {
      "x": -2,
      "y": 1,
      "z": 2,
      "name": "Soil_Dirt"
    },
    {
      "x": -2,
      "y": 2,
      "z": 2,
      "name": "Soil_Dirt"
    },
    {
      "x": -2,
      "y": 3,
      "z": 2,
      "name": "Soil_Dirt"
    },
    {
      "x": -2,
      "y": 4,
      "z": 2,
      "name": "Soil_Dirt"
    },
    {
      "x": -2,
      "y": 5,
      "z": 2,
      "name": "Soil_Dirt_Tilled",
      "components": {
        "Components": {
          "TilledSoil": {
            "Version": 1
          }
        }
      }
    },
    {
      "x": -2,
      "y": 6,
      "z": 2,
      "name": "*Plant_Crop_Wheat_Block_State_Definitions_Stage2",
      "components": {
        "Components": {
          "FarmingBlock": {}
        }
      }
    },
    {
      "x": -2,
      "y": 0,
      "z": 3,
      "name": "Soil_Dirt"
    },
    {
      "x": -2,
      "y": 1,
      "z": 3,
      "name": "Soil_Dirt"
    },
    {
      "x": -2,
      "y": 2,
      "z": 3,
      "name": "Soil_Dirt"
    },
    {
      "x": -2,
      "y": 3,
      "z": 3,
      "name": "Soil_Dirt"
    },
    {
      "x": -2,
      "y": 4,
      "z": 3,
      "name": "Soil_Leaves"
    },
    {
      "x": -2,
      "y": 5,
      "z": 3,
      "name": "Soil_Clay_Brick_Half"
    },
    {
      "x": -1,
      "y": 0,
      "z": -4,
      "name": "Soil_Dirt"
    },
    {
      "x": -1,
      "y": 1,
      "z": -4,
      "name": "Soil_Dirt"
    },
    {
      "x": -1,
      "y": 2,
      "z": -4,
      "name": "Soil_Dirt"
    },
    {
      "x": -1,
      "y": 3,
      "z": -4,
      "name": "Soil_Dirt"
    },
    {
      "x": -1,
      "y": 4,
      "z": -4,
      "name": "Soil_Leaves"
    },
    {
      "x": -1,
      "y": 5,
      "z": -4,
      "name": "Plant_Grass_Sharp"
    },
    {
      "x": -1,
      "y": 0,
      "z": -3,
      "name": "Soil_Dirt"
    },
    {
      "x": -1,
      "y": 1,
      "z": -3,
      "name": "Soil_Dirt"
    },
    {
      "x": -1,
      "y": 2,
      "z": -3,
      "name": "Soil_Dirt"
    },
    {
      "x": -1,
      "y": 3,
      "z": -3,
      "name": "Soil_Dirt"
    },
    {
      "x": -1,
      "y": 4,
      "z": -3,
      "name": "Soil_Grass"
    },
    {
      "x": -1,
      "y": 5,
      "z": -3,
      "name": "Soil_Clay_Brick_Half"
    },
    {
      "x": -1,
      "y": 0,
      "z": -2,
      "name": "Soil_Dirt"
    },
    {
      "x": -1,
      "y": 1,
      "z": -2,
      "name": "Soil_Dirt"
    },
    {
      "x": -1,
      "y": 2,
      "z": -2,
      "name": "Soil_Dirt"
    },
    {
      "x": -1,
      "y": 3,
      "z": -2,
      "name": "Soil_Dirt"
    },
    {
      "x": -1,
      "y": 4,
      "z": -2,
      "name": "Soil_Grass"
    },
    {
      "x": -1,
      "y": 5,
      "z": -2,
      "name": "Soil_Clay_Brick_Half"
    },
    {
      "x": -1,
      "y": 0,
      "z": -1,
      "name": "Soil_Dirt"
    },
    {
      "x": -1,
      "y": 1,
      "z": -1,
      "name": "Soil_Dirt"
    },
    {
      "x": -1,
      "y": 2,
      "z": -1,
      "name": "Soil_Dirt"
    },
    {
      "x": -1,
      "y": 3,
      "z": -1,
      "name": "Soil_Dirt"
    },
    {
      "x": -1,
      "y": 4,
      "z": -1,
      "name": "Soil_Dirt_Tilled",
      "components": {
        "Components": {
          "TilledSoil": {
            "Version": 1
          }
        }
      }
    },
    {
      "x": -1,
      "y": 0,
      "z": 0,
      "name": "Soil_Dirt"
    },
    {
      "x": -1,
      "y": 1,
      "z": 0,
      "name": "Soil_Dirt"
    },
    {
      "x": -1,
      "y": 2,
      "z": 0,
      "name": "Soil_Dirt"
    },
    {
      "x": -1,
      "y": 3,
      "z": 0,
      "name": "Soil_Dirt"
    },
    {
      "x": -1,
      "y": 4,
      "z": 0,
      "name": "Soil_Dirt"
    },
    {
      "x": -1,
      "y": 5,
      "z": 0,
      "name": "Soil_Dirt_Tilled",
      "components": {
        "Components": {
          "TilledSoil": {
            "Version": 1
          }
        }
      }
    },
    {
      "x": -1,
      "y": 6,
      "z": 0,
      "name": "*Plant_Crop_Wheat_Block_State_Definitions_Stage3",
      "components": {
        "Components": {
          "FarmingBlock": {}
        }
      }
    },
    {
      "x": -1,
      "y": 0,
      "z": 1,
      "name": "Soil_Dirt"
    },
    {
      "x": -1,
      "y": 1,
      "z": 1,
      "name": "Soil_Dirt"
    },
    {
      "x": -1,
      "y": 2,
      "z": 1,
      "name": "Soil_Dirt"
    },
    {
      "x": -1,
      "y": 3,
      "z": 1,
      "name": "Soil_Dirt"
    },
    {
      "x": -1,
      "y": 4,
      "z": 1,
      "name": "Soil_Dirt"
    },
    {
      "x": -1,
      "y": 5,
      "z": 1,
      "name": "Soil_Dirt_Tilled",
      "components": {
        "Components": {
          "TilledSoil": {
            "Version": 1
          }
        }
      }
    },
    {
      "x": -1,
      "y": 0,
      "z": 2,
      "name": "Soil_Dirt"
    },
    {
      "x": -1,
      "y": 1,
      "z": 2,
      "name": "Soil_Dirt"
    },
    {
      "x": -1,
      "y": 2,
      "z": 2,
      "name": "Soil_Dirt"
    },
    {
      "x": -1,
      "y": 3,
      "z": 2,
      "name": "Soil_Dirt"
    },
    {
      "x": -1,
      "y": 4,
      "z": 2,
      "name": "Soil_Dirt"
    },
    {
      "x": -1,
      "y": 5,
      "z": 2,
      "name": "Soil_Dirt_Tilled",
      "components": {
        "Components": {
          "TilledSoil": {
            "Version": 1
          }
        }
      }
    },
    {
      "x": -1,
      "y": 0,
      "z": 3,
      "name": "Soil_Dirt"
    },
    {
      "x": -1,
      "y": 1,
      "z": 3,
      "name": "Soil_Dirt"
    },
    {
      "x": -1,
      "y": 2,
      "z": 3,
      "name": "Soil_Dirt"
    },
    {
      "x": -1,
      "y": 3,
      "z": 3,
      "name": "Soil_Dirt"
    },
    {
      "x": -1,
      "y": 4,
      "z": 3,
      "name": "Soil_Leaves"
    },
    {
      "x": 0,
      "y": 2,
      "z": -4,
      "name": "Soil_Dirt"
    },
    {
      "x": 0,
      "y": 3,
      "z": -4,
      "name": "Soil_Dirt"
    },
    {
      "x": 0,
      "y": 4,
      "z": -4,
      "name": "Soil_Leaves"
    },
    {
      "x": 0,
      "y": 5,
      "z": -4,
      "name": "Plant_Grass_Sharp"
    },
    {
      "x": 0,
      "y": 0,
      "z": -3,
      "name": "Soil_Dirt"
    },
    {
      "x": 0,
      "y": 1,
      "z": -3,
      "name": "Soil_Dirt"
    },
    {
      "x": 0,
      "y": 2,
      "z": -3,
      "name": "Soil_Dirt"
    },
    {
      "x": 0,
      "y": 3,
      "z": -3,
      "name": "Soil_Dirt"
    },
    {
      "x": 0,
      "y": 4,
      "z": -3,
      "name": "Soil_Leaves"
    },
    {
      "x": 0,
      "y": 5,
      "z": -3,
      "name": "Plant_Grass_Sharp"
    },
    {
      "x": 0,
      "y": 0,
      "z": -2,
      "name": "Soil_Dirt"
    },
    {
      "x": 0,
      "y": 1,
      "z": -2,
      "name": "Soil_Dirt"
    },
    {
      "x": 0,
      "y": 2,
      "z": -2,
      "name": "Soil_Dirt"
    },
    {
      "x": 0,
      "y": 3,
      "z": -2,
      "name": "Soil_Dirt"
    },
    {
      "x": 0,
      "y": 4,
      "z": -2,
      "name": "Soil_Dirt_Tilled",
      "components": {
        "Components": {
          "TilledSoil": {
            "Version": 1
          }
        }
      }
    },
    {
      "x": 0,
      "y": 0,
      "z": -1,
      "name": "Soil_Dirt"
    },
    {
      "x": 0,
      "y": 1,
      "z": -1,
      "name": "Soil_Dirt"
    },
    {
      "x": 0,
      "y": 2,
      "z": -1,
      "name": "Soil_Dirt"
    },
    {
      "x": 0,
      "y": 3,
      "z": -1,
      "name": "Soil_Dirt"
    },
    {
      "x": 0,
      "y": 4,
      "z": -1,
      "name": "Soil_Dirt_Tilled",
      "components": {
        "Components": {
          "TilledSoil": {
            "Version": 1
          }
        }
      }
    },
    {
      "x": 0,
      "y": 0,
      "z": 0,
      "name": "Soil_Dirt"
    },
    {
      "x": 0,
      "y": 1,
      "z": 0,
      "name": "Soil_Dirt"
    },
    {
      "x": 0,
      "y": 2,
      "z": 0,
      "name": "Soil_Dirt"
    },
    {
      "x": 0,
      "y": 3,
      "z": 0,
      "name": "Soil_Dirt"
    },
    {
      "x": 0,
      "y": 4,
      "z": 0,
      "name": "Soil_Dirt_Tilled",
      "components": {
        "Components": {
          "TilledSoil": {
            "Version": 1
          }
        }
      }
    },
    {
      "x": 0,
      "y": 0,
      "z": 1,
      "name": "Soil_Dirt"
    },
    {
      "x": 0,
      "y": 1,
      "z": 1,
      "name": "Soil_Dirt"
    },
    {
      "x": 0,
      "y": 2,
      "z": 1,
      "name": "Soil_Dirt"
    },
    {
      "x": 0,
      "y": 3,
      "z": 1,
      "name": "Soil_Dirt"
    },
    {
      "x": 0,
      "y": 4,
      "z": 1,
      "name": "Soil_Dirt_Tilled",
      "components": {
        "Components": {
          "TilledSoil": {
            "Version": 1
          }
        }
      }
    },
    {
      "x": 0,
      "y": 0,
      "z": 2,
      "name": "Soil_Dirt"
    },
    {
      "x": 0,
      "y": 1,
      "z": 2,
      "name": "Soil_Dirt"
    },
    {
      "x": 0,
      "y": 2,
      "z": 2,
      "name": "Soil_Dirt"
    },
    {
      "x": 0,
      "y": 3,
      "z": 2,
      "name": "Soil_Dirt"
    },
    {
      "x": 0,
      "y": 4,
      "z": 2,
      "name": "Soil_Dirt_Tilled",
      "components": {
        "Components": {
          "TilledSoil": {
            "Version": 1
          }
        }
      }
    },
    {
      "x": 0,
      "y": 0,
      "z": 3,
      "name": "Soil_Dirt"
    },
    {
      "x": 0,
      "y": 1,
      "z": 3,
      "name": "Soil_Dirt"
    },
    {
      "x": 0,
      "y": 2,
      "z": 3,
      "name": "Soil_Dirt"
    },
    {
      "x": 0,
      "y": 3,
      "z": 3,
      "name": "Soil_Dirt"
    },
    {
      "x": 0,
      "y": 4,
      "z": 3,
      "name": "Soil_Dirt_Tilled",
      "components": {
        "Components": {
          "TilledSoil": {
            "Version": 1
          }
        }
      }
    },
    {
      "x": 1,
      "y": 0,
      "z": -3,
      "name": "Soil_Dirt"
    },
    {
      "x": 1,
      "y": 1,
      "z": -3,
      "name": "Soil_Dirt"
    },
    {
      "x": 1,
      "y": 2,
      "z": -3,
      "name": "Soil_Dirt"
    },
    {
      "x": 1,
      "y": 3,
      "z": -3,
      "name": "Soil_Dirt"
    },
    {
      "x": 1,
      "y": 4,
      "z": -3,
      "name": "Soil_Grass"
    },
    {
      "x": 1,
      "y": 5,
      "z": -3,
      "name": "Wood_Oak_Branch_Corner",
      "rotation": 3
    },
    {
      "x": 1,
      "y": 6,
      "z": -3,
      "name": "Wood_Oak_Branch_Corner",
      "rotation": 9
    },
    {
      "x": 1,
      "y": 0,
      "z": -2,
      "name": "Soil_Dirt"
    },
    {
      "x": 1,
      "y": 1,
      "z": -2,
      "name": "Soil_Dirt"
    },
    {
      "x": 1,
      "y": 2,
      "z": -2,
      "name": "Soil_Dirt"
    },
    {
      "x": 1,
      "y": 3,
      "z": -2,
      "name": "Soil_Dirt"
    },
    {
      "x": 1,
      "y": 4,
      "z": -2,
      "name": "Soil_Dirt_Tilled",
      "components": {
        "Components": {
          "TilledSoil": {
            "Version": 1
          }
        }
      }
    },
    {
      "x": 1,
      "y": 0,
      "z": -1,
      "name": "Soil_Dirt"
    },
    {
      "x": 1,
      "y": 1,
      "z": -1,
      "name": "Soil_Dirt"
    },
    {
      "x": 1,
      "y": 2,
      "z": -1,
      "name": "Soil_Dirt"
    },
    {
      "x": 1,
      "y": 3,
      "z": -1,
      "name": "Soil_Dirt"
    },
    {
      "x": 1,
      "y": 4,
      "z": -1,
      "name": "Soil_Dirt_Tilled",
      "components": {
        "Components": {
          "TilledSoil": {
            "Version": 1
          }
        }
      }
    },
    {
      "x": 1,
      "y": 0,
      "z": 0,
      "name": "Soil_Dirt"
    },
    {
      "x": 1,
      "y": 1,
      "z": 0,
      "name": "Soil_Dirt"
    },
    {
      "x": 1,
      "y": 2,
      "z": 0,
      "name": "Soil_Dirt"
    },
    {
      "x": 1,
      "y": 3,
      "z": 0,
      "name": "Soil_Dirt"
    },
    {
      "x": 1,
      "y": 4,
      "z": 0,
      "name": "Soil_Dirt_Tilled",
      "components": {
        "Components": {
          "TilledSoil": {
            "Version": 1
          }
        }
      }
    },
    {
      "x": 1,
      "y": 5,
      "z": 0,
      "name": "*Plant_Crop_Lettuce_Block_State_Definitions_Stage2",
      "components": {
        "Components": {
          "FarmingBlock": {}
        }
      }
    },
    {
      "x": 1,
      "y": 0,
      "z": 1,
      "name": "Soil_Dirt"
    },
    {
      "x": 1,
      "y": 1,
      "z": 1,
      "name": "Soil_Dirt"
    },
    {
      "x": 1,
      "y": 2,
      "z": 1,
      "name": "Soil_Dirt"
    },
    {
      "x": 1,
      "y": 3,
      "z": 1,
      "name": "Soil_Dirt"
    },
    {
      "x": 1,
      "y": 4,
      "z": 1,
      "name": "Soil_Dirt_Tilled",
      "components": {
        "Components": {
          "TilledSoil": {
            "Version": 1
          }
        }
      }
    },
    {
      "x": 1,
      "y": 5,
      "z": 1,
      "name": "Soil_Clay_Brick"
    },
    {
      "x": 1,
      "y": 0,
      "z": 2,
      "name": "Soil_Dirt"
    },
    {
      "x": 1,
      "y": 1,
      "z": 2,
      "name": "Soil_Dirt"
    },
    {
      "x": 1,
      "y": 2,
      "z": 2,
      "name": "Soil_Dirt"
    },
    {
      "x": 1,
      "y": 3,
      "z": 2,
      "name": "Soil_Dirt"
    },
    {
      "x": 1,
      "y": 4,
      "z": 2,
      "name": "Soil_Dirt_Tilled",
      "components": {
        "Components": {
          "TilledSoil": {
            "Version": 1
          }
        }
      }
    },
    {
      "x": 1,
      "y": 5,
      "z": 2,
      "name": "Soil_Clay_Brick"
    },
    {
      "x": 1,
      "y": 0,
      "z": 3,
      "name": "Soil_Dirt"
    },
    {
      "x": 1,
      "y": 1,
      "z": 3,
      "name": "Soil_Dirt"
    },
    {
      "x": 1,
      "y": 2,
      "z": 3,
      "name": "Soil_Dirt"
    },
    {
      "x": 1,
      "y": 3,
      "z": 3,
      "name": "Soil_Dirt"
    },
    {
      "x": 1,
      "y": 4,
      "z": 3,
      "name": "Soil_Dirt_Tilled",
      "components": {
        "Components": {
          "TilledSoil": {
            "Version": 1
          }
        }
      }
    },
    {
      "x": 1,
      "y": 5,
      "z": 3,
      "name": "Soil_Clay_Brick_Half"
    },
    {
      "x": 1,
      "y": 0,
      "z": 4,
      "name": "Soil_Dirt"
    },
    {
      "x": 1,
      "y": 1,
      "z": 4,
      "name": "Soil_Dirt"
    },
    {
      "x": 1,
      "y": 2,
      "z": 4,
      "name": "Soil_Dirt"
    },
    {
      "x": 1,
      "y": 3,
      "z": 4,
      "name": "Soil_Dirt"
    },
    {
      "x": 1,
      "y": 4,
      "z": 4,
      "name": "Soil_Grass"
    },
    {
      "x": 2,
      "y": 0,
      "z": -3,
      "name": "Soil_Dirt"
    },
    {
      "x": 2,
      "y": 1,
      "z": -3,
      "name": "Soil_Dirt"
    },
    {
      "x": 2,
      "y": 2,
      "z": -3,
      "name": "Soil_Dirt"
    },
    {
      "x": 2,
      "y": 3,
      "z": -3,
      "name": "Soil_Dirt"
    },
    {
      "x": 2,
      "y": 4,
      "z": -3,
      "name": "Soil_Grass"
    },
    {
      "x": 2,
      "y": 5,
      "z": -3,
      "name": "Wood_Oak_Branch_Corner",
      "rotation": 11
    },
    {
      "x": 2,
      "y": 6,
      "z": -3,
      "name": "Wood_Oak_Branch_Corner",
      "rotation": 1
    },
    {
      "x": 2,
      "y": 7,
      "z": -3,
      "name": "Wood_Oak_Branch_Long"
    },
    {
      "x": 2,
      "y": 8,
      "z": -3,
      "name": "Wood_Oak_Branch_Corner",
      "rotation": 9
    },
    {
      "x": 2,
      "y": 0,
      "z": -2,
      "name": "Soil_Dirt"
    },
    {
      "x": 2,
      "y": 1,
      "z": -2,
      "name": "Soil_Dirt"
    },
    {
      "x": 2,
      "y": 2,
      "z": -2,
      "name": "Soil_Dirt"
    },
    {
      "x": 2,
      "y": 3,
      "z": -2,
      "name": "Soil_Dirt"
    },
    {
      "x": 2,
      "y": 4,
      "z": -2,
      "name": "Soil_Dirt_Tilled",
      "components": {
        "Components": {
          "TilledSoil": {
            "Version": 1
          }
        }
      }
    },
    {
      "x": 2,
      "y": 5,
      "z": -2,
      "name": "*Plant_Crop_Lettuce_Block_State_Definitions_Stage1",
      "components": {
        "Components": {
          "FarmingBlock": {}
        }
      }
    },
    {
      "x": 2,
      "y": 0,
      "z": -1,
      "name": "Soil_Dirt"
    },
    {
      "x": 2,
      "y": 1,
      "z": -1,
      "name": "Soil_Dirt"
    },
    {
      "x": 2,
      "y": 2,
      "z": -1,
      "name": "Soil_Dirt"
    },
    {
      "x": 2,
      "y": 3,
      "z": -1,
      "name": "Soil_Dirt"
    },
    {
      "x": 2,
      "y": 4,
      "z": -1,
      "name": "Soil_Dirt_Tilled",
      "components": {
        "Components": {
          "TilledSoil": {
            "Version": 1
          }
        }
      }
    },
    {
      "x": 2,
      "y": 0,
      "z": 0,
      "name": "Soil_Dirt"
    },
    {
      "x": 2,
      "y": 1,
      "z": 0,
      "name": "Soil_Dirt"
    },
    {
      "x": 2,
      "y": 2,
      "z": 0,
      "name": "Soil_Dirt"
    },
    {
      "x": 2,
      "y": 3,
      "z": 0,
      "name": "Soil_Dirt"
    },
    {
      "x": 2,
      "y": 4,
      "z": 0,
      "name": "Soil_Dirt_Tilled",
      "components": {
        "Components": {
          "TilledSoil": {
            "Version": 1
          }
        }
      }
    },
    {
      "x": 2,
      "y": 0,
      "z": 1,
      "name": "Soil_Dirt"
    },
    {
      "x": 2,
      "y": 1,
      "z": 1,
      "name": "Soil_Dirt"
    },
    {
      "x": 2,
      "y": 2,
      "z": 1,
      "name": "Soil_Dirt"
    },
    {
      "x": 2,
      "y": 3,
      "z": 1,
      "name": "Soil_Dirt"
    },
    {
      "x": 2,
      "y": 4,
      "z": 1,
      "name": "Soil_Dirt"
    },
    {
      "x": 2,
      "y": 5,
      "z": 1,
      "name": "Soil_Dirt_Tilled",
      "components": {
        "Components": {
          "TilledSoil": {
            "Version": 1
          }
        }
      }
    },
    {
      "x": 2,
      "y": 0,
      "z": 2,
      "name": "Soil_Dirt"
    },
    {
      "x": 2,
      "y": 1,
      "z": 2,
      "name": "Soil_Dirt"
    },
    {
      "x": 2,
      "y": 2,
      "z": 2,
      "name": "Soil_Dirt"
    },
    {
      "x": 2,
      "y": 3,
      "z": 2,
      "name": "Soil_Dirt"
    },
    {
      "x": 2,
      "y": 4,
      "z": 2,
      "name": "Soil_Dirt"
    },
    {
      "x": 2,
      "y": 5,
      "z": 2,
      "name": "Soil_Dirt_Tilled",
      "components": {
        "Components": {
          "TilledSoil": {
            "Version": 1
          }
        }
      }
    },
    {
      "x": 2,
      "y": 0,
      "z": 3,
      "name": "Soil_Dirt"
    },
    {
      "x": 2,
      "y": 1,
      "z": 3,
      "name": "Soil_Dirt"
    },
    {
      "x": 2,
      "y": 2,
      "z": 3,
      "name": "Soil_Dirt"
    },
    {
      "x": 2,
      "y": 3,
      "z": 3,
      "name": "Soil_Dirt"
    },
    {
      "x": 2,
      "y": 4,
      "z": 3,
      "name": "Soil_Grass"
    },
    {
      "x": 2,
      "y": 5,
      "z": 3,
      "name": "Soil_Clay_Brick_Half"
    },
    {
      "x": 2,
      "y": 0,
      "z": 4,
      "name": "Soil_Dirt"
    },
    {
      "x": 2,
      "y": 1,
      "z": 4,
      "name": "Soil_Dirt"
    },
    {
      "x": 2,
      "y": 2,
      "z": 4,
      "name": "Soil_Dirt"
    },
    {
      "x": 2,
      "y": 3,
      "z": 4,
      "name": "Soil_Dirt"
    },
    {
      "x": 2,
      "y": 4,
      "z": 4,
      "name": "Soil_Grass"
    },
    {
      "x": 2,
      "y": 5,
      "z": 4,
      "name": "Plant_Grass_Sharp"
    },
    {
      "x": 3,
      "y": 0,
      "z": -3,
      "name": "Soil_Dirt"
    },
    {
      "x": 3,
      "y": 1,
      "z": -3,
      "name": "Soil_Dirt"
    },
    {
      "x": 3,
      "y": 2,
      "z": -3,
      "name": "Soil_Dirt"
    },
    {
      "x": 3,
      "y": 3,
      "z": -3,
      "name": "Soil_Dirt"
    },
    {
      "x": 3,
      "y": 4,
      "z": -3,
      "name": "Soil_Grass"
    },
    {
      "x": 3,
      "y": 5,
      "z": -3,
      "name": "Plant_Grass_Sharp"
    },
    {
      "x": 3,
      "y": 7,
      "z": -3,
      "name": "Wood_Oak_Branch_Corner",
      "rotation": 3
    },
    {
      "x": 3,
      "y": 8,
      "z": -3,
      "name": "Wood_Oak_Branch_Corner",
      "rotation": 11
    },
    {
      "x": 3,
      "y": 0,
      "z": -2,
      "name": "Soil_Dirt"
    },
    {
      "x": 3,
      "y": 1,
      "z": -2,
      "name": "Soil_Dirt"
    },
    {
      "x": 3,
      "y": 2,
      "z": -2,
      "name": "Soil_Dirt"
    },
    {
      "x": 3,
      "y": 3,
      "z": -2,
      "name": "Soil_Dirt"
    },
    {
      "x": 3,
      "y": 4,
      "z": -2,
      "name": "Soil_Dirt_Tilled",
      "components": {
        "Components": {
          "TilledSoil": {
            "Version": 1
          }
        }
      }
    },
    {
      "x": 3,
      "y": 0,
      "z": -1,
      "name": "Soil_Dirt"
    },
    {
      "x": 3,
      "y": 1,
      "z": -1,
      "name": "Soil_Dirt"
    },
    {
      "x": 3,
      "y": 2,
      "z": -1,
      "name": "Soil_Dirt"
    },
    {
      "x": 3,
      "y": 3,
      "z": -1,
      "name": "Soil_Dirt"
    },
    {
      "x": 3,
      "y": 4,
      "z": -1,
      "name": "Soil_Dirt_Tilled",
      "components": {
        "Components": {
          "TilledSoil": {
            "Version": 1
          }
        }
      }
    },
    {
      "x": 3,
      "y": 5,
      "z": -1,
      "name": "Soil_Dirt_Tilled",
      "components": {
        "Components": {
          "TilledSoil": {
            "Version": 1
          }
        }
      }
    },
    {
      "x": 3,
      "y": 0,
      "z": 0,
      "name": "Soil_Dirt"
    },
    {
      "x": 3,
      "y": 1,
      "z": 0,
      "name": "Soil_Dirt"
    },
    {
      "x": 3,
      "y": 2,
      "z": 0,
      "name": "Soil_Dirt"
    },
    {
      "x": 3,
      "y": 3,
      "z": 0,
      "name": "Soil_Dirt"
    },
    {
      "x": 3,
      "y": 4,
      "z": 0,
      "name": "Soil_Dirt_Tilled",
      "components": {
        "Components": {
          "TilledSoil": {
            "Version": 1
          }
        }
      }
    },
    {
      "x": 3,
      "y": 5,
      "z": 0,
      "name": "Soil_Dirt_Tilled",
      "components": {
        "Components": {
          "TilledSoil": {
            "Version": 1
          }
        }
      }
    },
    {
      "x": 3,
      "y": 6,
      "z": 0,
      "name": "*Plant_Crop_Lettuce_Block_State_Definitions_StageFinal",
      "components": {
        "Components": {
          "FarmingBlock": {}
        }
      }
    },
    {
      "x": 3,
      "y": 0,
      "z": 1,
      "name": "Soil_Dirt"
    },
    {
      "x": 3,
      "y": 1,
      "z": 1,
      "name": "Soil_Dirt"
    },
    {
      "x": 3,
      "y": 2,
      "z": 1,
      "name": "Soil_Dirt"
    },
    {
      "x": 3,
      "y": 3,
      "z": 1,
      "name": "Soil_Dirt"
    },
    {
      "x": 3,
      "y": 4,
      "z": 1,
      "name": "Soil_Dirt"
    },
    {
      "x": 3,
      "y": 5,
      "z": 1,
      "name": "Soil_Dirt_Tilled",
      "components": {
        "Components": {
          "TilledSoil": {
            "Version": 1
          }
        }
      }
    },
    {
      "x": 3,
      "y": 0,
      "z": 2,
      "name": "Soil_Dirt"
    },
    {
      "x": 3,
      "y": 1,
      "z": 2,
      "name": "Soil_Dirt"
    },
    {
      "x": 3,
      "y": 2,
      "z": 2,
      "name": "Soil_Dirt"
    },
    {
      "x": 3,
      "y": 3,
      "z": 2,
      "name": "Soil_Dirt"
    },
    {
      "x": 3,
      "y": 4,
      "z": 2,
      "name": "Soil_Dirt"
    },
    {
      "x": 3,
      "y": 5,
      "z": 2,
      "name": "Soil_Dirt_Tilled",
      "components": {
        "Components": {
          "TilledSoil": {
            "Version": 1
          }
        }
      }
    },
    {
      "x": 3,
      "y": 6,
      "z": 2,
      "name": "*Plant_Crop_Lettuce_Block_State_Definitions_StageFinal",
      "components": {
        "Components": {
          "FarmingBlock": {}
        }
      }
    },
    {
      "x": 3,
      "y": 0,
      "z": 3,
      "name": "Soil_Dirt"
    },
    {
      "x": 3,
      "y": 1,
      "z": 3,
      "name": "Soil_Dirt"
    },
    {
      "x": 3,
      "y": 2,
      "z": 3,
      "name": "Soil_Dirt"
    },
    {
      "x": 3,
      "y": 3,
      "z": 3,
      "name": "Soil_Dirt"
    },
    {
      "x": 3,
      "y": 4,
      "z": 3,
      "name": "Soil_Grass"
    },
    {
      "x": 3,
      "y": 5,
      "z": 3,
      "name": "Wood_Oak_Branch_Corner",
      "rotation": 9
    },
    {
      "x": 3,
      "y": 1,
      "z": 4,
      "name": "Soil_Dirt"
    },
    {
      "x": 3,
      "y": 2,
      "z": 4,
      "name": "Soil_Dirt"
    },
    {
      "x": 3,
      "y": 3,
      "z": 4,
      "name": "Soil_Dirt"
    },
    {
      "x": 3,
      "y": 4,
      "z": 4,
      "name": "Soil_Grass"
    },
    {
      "x": 3,
      "y": 5,
      "z": 4,
      "name": "Plant_Grass_Sharp"
    },
    {
      "x": 4,
      "y": 0,
      "z": -3,
      "name": "Soil_Dirt"
    },
    {
      "x": 4,
      "y": 1,
      "z": -3,
      "name": "Soil_Dirt"
    },
    {
      "x": 4,
      "y": 2,
      "z": -3,
      "name": "Soil_Dirt"
    },
    {
      "x": 4,
      "y": 3,
      "z": -3,
      "name": "Soil_Dirt"
    },
    {
      "x": 4,
      "y": 4,
      "z": -3,
      "name": "Soil_Grass"
    },
    {
      "x": 4,
      "y": 5,
      "z": -3,
      "name": "Wood_Oak_Branch_Long"
    },
    {
      "x": 4,
      "y": 6,
      "z": -3,
      "name": "Wood_Oak_Branch_Long"
    },
    {
      "x": 4,
      "y": 7,
      "z": -3,
      "name": "Wood_Oak_Branch_Corner",
      "rotation": 11
    },
    {
      "x": 4,
      "y": 0,
      "z": -2,
      "name": "Soil_Dirt"
    },
    {
      "x": 4,
      "y": 1,
      "z": -2,
      "name": "Soil_Dirt"
    },
    {
      "x": 4,
      "y": 2,
      "z": -2,
      "name": "Soil_Dirt"
    },
    {
      "x": 4,
      "y": 3,
      "z": -2,
      "name": "Soil_Dirt"
    },
    {
      "x": 4,
      "y": 4,
      "z": -2,
      "name": "Soil_Grass"
    },
    {
      "x": 4,
      "y": 5,
      "z": -2,
      "name": "Wood_Oak_Branch_Long"
    },
    {
      "x": 4,
      "y": 6,
      "z": -2,
      "name": "Wood_Oak_Branch_Long"
    },
    {
      "x": 4,
      "y": 7,
      "z": -2,
      "name": "Wood_Oak_Branch_Long"
    },
    {
      "x": 4,
      "y": 8,
      "z": -2,
      "name": "Wood_Oak_Branch_Long"
    },
    {
      "x": 4,
      "y": 9,
      "z": -2,
      "name": "Wood_Oak_Branch_Corner",
      "rotation": 8
    },
    {
      "x": 4,
      "y": 0,
      "z": -1,
      "name": "Soil_Dirt"
    },
    {
      "x": 4,
      "y": 1,
      "z": -1,
      "name": "Soil_Dirt"
    },
    {
      "x": 4,
      "y": 2,
      "z": -1,
      "name": "Soil_Dirt"
    },
    {
      "x": 4,
      "y": 3,
      "z": -1,
      "name": "Soil_Dirt"
    },
    {
      "x": 4,
      "y": 4,
      "z": -1,
      "name": "Soil_Dirt"
    },
    {
      "x": 4,
      "y": 5,
      "z": -1,
      "name": "Soil_Dirt_Tilled",
      "components": {
        "Components": {
          "TilledSoil": {
            "Version": 1
          }
        }
      }
    },
    {
      "x": 4,
      "y": 8,
      "z": -1,
      "name": "Furniture_Kweebec_Lantern"
    },
    {
      "x": 4,
      "y": 9,
      "z": -1,
      "name": "Wood_Oak_Branch_Corner",
      "rotation": 10
    },
    {
      "x": 4,
      "y": 0,
      "z": 0,
      "name": "Soil_Dirt"
    },
    {
      "x": 4,
      "y": 1,
      "z": 0,
      "name": "Soil_Dirt"
    },
    {
      "x": 4,
      "y": 2,
      "z": 0,
      "name": "Soil_Dirt"
    },
    {
      "x": 4,
      "y": 3,
      "z": 0,
      "name": "Soil_Dirt"
    },
    {
      "x": 4,
      "y": 4,
      "z": 0,
      "name": "Soil_Dirt"
    },
    {
      "x": 4,
      "y": 5,
      "z": 0,
      "name": "Soil_Dirt_Tilled",
      "components": {
        "Components": {
          "TilledSoil": {
            "Version": 1
          }
        }
      }
    },
    {
      "x": 4,
      "y": 0,
      "z": 1,
      "name": "Soil_Dirt"
    },
    {
      "x": 4,
      "y": 1,
      "z": 1,
      "name": "Soil_Dirt"
    },
    {
      "x": 4,
      "y": 2,
      "z": 1,
      "name": "Soil_Dirt"
    },
    {
      "x": 4,
      "y": 3,
      "z": 1,
      "name": "Soil_Dirt"
    },
    {
      "x": 4,
      "y": 4,
      "z": 1,
      "name": "Soil_Dirt"
    },
    {
      "x": 4,
      "y": 5,
      "z": 1,
      "name": "Soil_Clay_Brick"
    },
    {
      "x": 4,
      "y": 0,
      "z": 2,
      "name": "Soil_Dirt"
    },
    {
      "x": 4,
      "y": 1,
      "z": 2,
      "name": "Soil_Dirt"
    },
    {
      "x": 4,
      "y": 2,
      "z": 2,
      "name": "Soil_Dirt"
    },
    {
      "x": 4,
      "y": 3,
      "z": 2,
      "name": "Soil_Dirt"
    },
    {
      "x": 4,
      "y": 4,
      "z": 2,
      "name": "Soil_Dirt"
    },
    {
      "x": 4,
      "y": 5,
      "z": 2,
      "name": "Soil_Clay_Brick_Half"
    },
    {
      "x": 4,
      "y": 0,
      "z": 3,
      "name": "Soil_Dirt"
    },
    {
      "x": 4,
      "y": 1,
      "z": 3,
      "name": "Soil_Dirt"
    },
    {
      "x": 4,
      "y": 2,
      "z": 3,
      "name": "Soil_Dirt"
    },
    {
      "x": 4,
      "y": 3,
      "z": 3,
      "name": "Soil_Dirt"
    },
    {
      "x": 4,
      "y": 4,
      "z": 3,
      "name": "Soil_Grass"
    },
    {
      "x": 4,
      "y": 5,
      "z": 3,
      "name": "Wood_Oak_Branch_Long",
      "rotation": 5
    },
    {
      "x": 4,
      "y": 1,
      "z": 4,
      "name": "Soil_Dirt"
    },
    {
      "x": 4,
      "y": 2,
      "z": 4,
      "name": "Soil_Dirt"
    },
    {
      "x": 4,
      "y": 3,
      "z": 4,
      "name": "Soil_Dirt"
    },
    {
      "x": 4,
      "y": 4,
      "z": 4,
      "name": "Soil_Grass"
    },
    {
      "x": 5,
      "y": 0,
      "z": -3,
      "name": "Soil_Dirt"
    },
    {
      "x": 5,
      "y": 1,
      "z": -3,
      "name": "Soil_Dirt"
    },
    {
      "x": 5,
      "y": 2,
      "z": -3,
      "name": "Soil_Dirt"
    },
    {
      "x": 5,
      "y": 3,
      "z": -3,
      "name": "Soil_Dirt"
    },
    {
      "x": 5,
      "y": 4,
      "z": -3,
      "name": "Soil_Grass"
    },
    {
      "x": 5,
      "y": 0,
      "z": -2,
      "name": "Soil_Dirt"
    },
    {
      "x": 5,
      "y": 1,
      "z": -2,
      "name": "Soil_Dirt"
    },
    {
      "x": 5,
      "y": 2,
      "z": -2,
      "name": "Soil_Dirt"
    },
    {
      "x": 5,
      "y": 3,
      "z": -2,
      "name": "Soil_Dirt"
    },
    {
      "x": 5,
      "y": 4,
      "z": -2,
      "name": "Soil_Grass"
    },
    {
      "x": 5,
      "y": 5,
      "z": -2,
      "name": "Plant_Grass_Sharp"
    },
    {
      "x": 5,
      "y": 0,
      "z": -1,
      "name": "Soil_Dirt"
    },
    {
      "x": 5,
      "y": 1,
      "z": -1,
      "name": "Soil_Dirt"
    },
    {
      "x": 5,
      "y": 2,
      "z": -1,
      "name": "Soil_Dirt"
    },
    {
      "x": 5,
      "y": 3,
      "z": -1,
      "name": "Soil_Dirt"
    },
    {
      "x": 5,
      "y": 4,
      "z": -1,
      "name": "Soil_Grass"
    },
    {
      "x": 5,
      "y": 5,
      "z": -1,
      "name": "Plant_Grass_Sharp"
    },
    {
      "x": 5,
      "y": 0,
      "z": 0,
      "name": "Soil_Dirt"
    },
    {
      "x": 5,
      "y": 1,
      "z": 0,
      "name": "Soil_Dirt"
    },
    {
      "x": 5,
      "y": 2,
      "z": 0,
      "name": "Soil_Dirt"
    },
    {
      "x": 5,
      "y": 3,
      "z": 0,
      "name": "Soil_Dirt"
    },
    {
      "x": 5,
      "y": 4,
      "z": 0,
      "name": "Soil_Dirt"
    },
    {
      "x": 5,
      "y": 5,
      "z": 0,
      "name": "Soil_Clay_Brick_Half"
    },
    {
      "x": 5,
      "y": 0,
      "z": 1,
      "name": "Soil_Dirt"
    },
    {
      "x": 5,
      "y": 1,
      "z": 1,
      "name": "Soil_Dirt"
    },
    {
      "x": 5,
      "y": 2,
      "z": 1,
      "name": "Soil_Dirt"
    },
    {
      "x": 5,
      "y": 3,
      "z": 1,
      "name": "Soil_Dirt"
    },
    {
      "x": 5,
      "y": 4,
      "z": 1,
      "name": "Soil_Dirt"
    },
    {
      "x": 5,
      "y": 5,
      "z": 1,
      "name": "Soil_Clay_Brick_Half"
    },
    {
      "x": 5,
      "y": 0,
      "z": 2,
      "name": "Soil_Dirt"
    },
    {
      "x": 5,
      "y": 1,
      "z": 2,
      "name": "Soil_Dirt"
    },
    {
      "x": 5,
      "y": 2,
      "z": 2,
      "name": "Soil_Dirt"
    },
    {
      "x": 5,
      "y": 3,
      "z": 2,
      "name": "Soil_Dirt"
    },
    {
      "x": 5,
      "y": 4,
      "z": 2,
      "name": "Soil_Dirt"
    },
    {
      "x": 5,
      "y": 5,
      "z": 2,
      "name": "Soil_Clay_Brick_Half"
    },
    {
      "x": 5,
      "y": 0,
      "z": 3,
      "name": "Soil_Dirt"
    },
    {
      "x": 5,
      "y": 1,
      "z": 3,
      "name": "Soil_Dirt"
    },
    {
      "x": 5,
      "y": 2,
      "z": 3,
      "name": "Soil_Dirt"
    },
    {
      "x": 5,
      "y": 3,
      "z": 3,
      "name": "Soil_Dirt"
    },
    {
      "x": 5,
      "y": 4,
      "z": 3,
      "name": "Soil_Grass"
    },
    {
      "x": 5,
      "y": 5,
      "z": 3,
      "name": "Wood_Oak_Branch_Corner",
      "rotation": 11
    },
    {
      "x": 6,
      "y": 2,
      "z": -1,
      "name": "Soil_Dirt"
    },
    {
      "x": 6,
      "y": 3,
      "z": -1,
      "name": "Soil_Dirt"
    },
    {
      "x": 6,
      "y": 4,
      "z": -1,
      "name": "Soil_Grass"
    },
    {
      "x": 6,
      "y": 5,
      "z": -1,
      "name": "Plant_Grass_Sharp"
    },
    {
      "x": 6,
      "y": 0,
      "z": 0,
      "name": "Soil_Dirt"
    },
    {
      "x": 6,
      "y": 1,
      "z": 0,
      "name": "Soil_Dirt"
    },
    {
      "x": 6,
      "y": 2,
      "z": 0,
      "name": "Soil_Dirt"
    },
    {
      "x": 6,
      "y": 3,
      "z": 0,
      "name": "Soil_Dirt"
    },
    {
      "x": 6,
      "y": 4,
      "z": 0,
      "name": "Soil_Grass"
    },
    {
      "x": 6,
      "y": 1,
      "z": 1,
      "name": "Soil_Dirt"
    },
    {
      "x": 6,
      "y": 2,
      "z": 1,
      "name": "Soil_Dirt"
    },
    {
      "x": 6,
      "y": 3,
      "z": 1,
      "name": "Soil_Dirt"
    },
    {
      "x": 6,
      "y": 4,
      "z": 1,
      "name": "Soil_Grass"
    },
    {
      "x": 6,
      "y": 5,
      "z": 1,
      "name": "Plant_Grass_Sharp"
    }
  ]
}