{
  "version": 8,
  "blockIdVersion": 8,
  "anchorX": 3,
  "anchorY": 8,
  "anchorZ": 4,
  "blocks": [
    {
      "x": 2,
      "y": 5,
      "z": 4,
      "name": "Plant_Coral_Block_Blue"
    },
    {
      "x": 2,
      "y": 6,
      "z": 4,
      "name": "Plant_Coral_Block_Blue"
    },
    {
      "x": 2,
      "y": 7,
      "z": 4,
      "name": "Plant_Coral_Block_Purple"
    },
    {
      "x": 2,
      "y": 8,
      "z": 4,
      "name": "Plant_Coral_Block_Purple"
    },
    {
      "x": 2,
      "y": 9,
      "z": 4,
      "name": "Rock_Crystal_Purple_Large"
    },
    {
      "x": 2,
      "y": 8,
      "z": 5,
      "name": "Plant_Coral_Block_Blue"
    },
    {
      "x": 2,
      "y": 9,
      "z": 5,
      "name": "Plant_Coral_Block_Blue"
    },
    {
      "x": 2,
      "y": 10,
      "z": 5,
      "name": "Rock_Crystal_Purple_Large"
    },
    {
      "x": 3,
      "y": 8,
      "z": 3,
      "name": "Plant_Coral_Block_Blue"
    },
    {
      "x": 3,
      "y": 9,
      "z": 3,
      "name": "Plant_Coral_Block_Purple"
    },
    {
      "x": 3,
      "y": 10,
      "z": 3,
      "name": "Rock_Crystal_Purple_Small"
    },
    {
      "x": 3,
      "y": 4,
      "z": 4,
      "name": "Plant_Coral_Block_Blue"
    },
    {
      "x": 3,
      "y": 5,
      "z": 4,
      "name": "Plant_Coral_Block_Blue"
    },
    {
      "x": 3,
      "y": 6,
      "z": 4,
      "name": "Plant_Coral_Block_Blue"
    },
    {
      "x": 3,
      "y": 7,
      "z": 4,
      "name": "Plant_Coral_Block_Blue"
    },
    {
      "x": 3,
      "y": 8,
      "z": 4,
      "name": "Plant_Coral_Block_Blue"
    },
    {
      "x": 3,
      "y": 9,
      "z": 4,
      "name": "Plant_Coral_Block_Blue"
    },
    {
      "x": 3,
      "y": 10,
      "z": 4,
      "name": "Plant_Coral_Block_Purple"
    },
    {
      "x": 3,
      "y": 11,
      "z": 4,
      "name": "Plant_Coral_Block_Purple"
    },
    {
      "x": 3,
      "y": 12,
      "z": 4,
      "name": "Plant_Coral_Block_Purple"
    },
    {
      "x": 3,
      "y": 13,
      "z": 4,
      "name": "Rock_Crystal_Purple_Small"
    },
    {
      "x": 3,
      "y": 6,
      "z": 5,
      "name": "Plant_Coral_Block_Blue"
    },
    {
      "x": 3,
      "y": 7,
      "z": 5,
      "name": "Plant_Coral_Block_Blue"
    },
    {
      "x": 3,
      "y": 8,
      "z": 5,
      "name": "Plant_Coral_Block_Blue"
    },
    {
      "x": 3,
      "y": 9,
      "z": 5,
      "name": "Plant_Coral_Block_Purple"
    },
    {
      "x": 3,
      "y": 10,
      "z": 5,
      "name": "Plant_Coral_Block_Purple"
    },
    {
      "x": 3,
      "y": 11,
      "z": 5,
      "name": "Plant_Coral_Block_Purple"
    },
    {
      "x": 3,
      "y": 12,
      "z": 5,
      "name": "Rock_Crystal_Purple_Medium"
    },
    {
      "x": 4,
      "y": 7,
      "z": 3,
      "name": "Plant_Coral_Block_Purple"
    },
    {
      "x": 4,
      "y": 8,
      "z": 3,
      "name": "Plant_Coral_Block_Purple"
    },
    {
      "x": 4,
      "y": 9,
      "z": 3,
      "name": "Plant_Coral_Block_Purple"
    },
    {
      "x": 4,
      "y": 10,
      "z": 3,
      "name": "Plant_Coral_Block_Purple"
    },
    {
      "x": 4,
      "y": 7,
      "z": 4,
      "name": "Plant_Coral_Block_Blue"
    },
    {
      "x": 4,
      "y": 8,
      "z": 4,
      "name": "Plant_Coral_Block_Blue"
    },
    {
      "x": 4,
      "y": 9,
      "z": 4,
      "name": "Plant_Coral_Block_Purple"
    },
    {
      "x": 4,
      "y": 10,
      "z": 4,
      "name": "Plant_Coral_Block_Purple"
    },
    {
      "x": 4,
      "y": 11,
      "z": 4,
      "name": "Rock_Crystal_Purple_Large"
    },
    {
      "x": 4,
      "y": 8,
      "z": 5,
      "name": "Plant_Coral_Block_Purple"
    },
    {
      "x": 4,
      "y": 9,
      "z": 5,
      "name": "Plant_Coral_Block_Purple"
    }
  ]
}