{
  "version": 8,
  "blockIdVersion": 8,
  "anchorX": 1,
  "anchorY": 11,
  "anchorZ": 1,
  "blocks": [
    {
      "x": -7,
      "y": 11,
      "z": 3,
      "name": "Rock_Stone"
    },
    {
      "x": -7,
      "y": 12,
      "z": 3,
      "name": "Rock_Stone"
    },
    {
      "x": -7,
      "y": 13,
      "z": 3,
      "name": "Rock_Stone"
    },
    {
      "x": -7,
      "y": 14,
      "z": 3,
      "name": "Rock_Stone"
    },
    {
      "x": -7,
      "y": 15,
      "z": 3,
      "name": "Rock_Stone"
    },
    {
      "x": -7,
      "y": 12,
      "z": 4,
      "name": "Rock_Stone"
    },
    {
      "x": -7,
      "y": 13,
      "z": 4,
      "name": "Rock_Stone"
    },
    {
      "x": -7,
      "y": 14,
      "z": 4,
      "name": "Rock_Stone"
    },
    {
      "x": -6,
      "y": 13,
      "z": 1,
      "name": "Rock_Stone"
    },
    {
      "x": -6,
      "y": 14,
      "z": 1,
      "name": "Rock_Stone"
    },
    {
      "x": -6,
      "y": 15,
      "z": 1,
      "name": "Rock_Stone"
    },
    {
      "x": -6,
      "y": 16,
      "z": 1,
      "name": "Rock_Stone"
    },
    {
      "x": -6,
      "y": 34,
      "z": 1,
      "name": "Plant_Leaves_Ash",
      "support": 15
    },
    {
      "x": -6,
      "y": 12,
      "z": 2,
      "name": "Rock_Stone"
    },
    {
      "x": -6,
      "y": 13,
      "z": 2,
      "name": "Rock_Stone"
    },
    {
      "x": -6,
      "y": 14,
      "z": 2,
      "name": "Rock_Stone"
    },
    {
      "x": -6,
      "y": 15,
      "z": 2,
      "name": "Rock_Stone"
    },
    {
      "x": -6,
      "y": 16,
      "z": 2,
      "name": "Rock_Stone"
    },
    {
      "x": -6,
      "y": 17,
      "z": 2,
      "name": "Rock_Stone"
    },
    {
      "x": -6,
      "y": 18,
      "z": 2,
      "name": "Soil_Dirt"
    },
    {
      "x": -6,
      "y": 19,
      "z": 2,
      "name": "Soil_Grass"
    },
    {
      "x": -6,
      "y": 34,
      "z": 2,
      "name": "Plant_Leaves_Ash",
      "support": 15
    },
    {
      "x": -6,
      "y": 10,
      "z": 3,
      "name": "Rock_Stone"
    },
    {
      "x": -6,
      "y": 11,
      "z": 3,
      "name": "Rock_Stone"
    },
    {
      "x": -6,
      "y": 12,
      "z": 3,
      "name": "Rock_Stone"
    },
    {
      "x": -6,
      "y": 13,
      "z": 3,
      "name": "Rock_Stone"
    },
    {
      "x": -6,
      "y": 14,
      "z": 3,
      "name": "Rock_Stone"
    },
    {
      "x": -6,
      "y": 15,
      "z": 3,
      "name": "Soil_Dirt"
    },
    {
      "x": -6,
      "y": 16,
      "z": 3,
      "name": "Rock_Stone"
    },
    {
      "x": -6,
      "y": 17,
      "z": 3,
      "name": "Rock_Stone"
    },
    {
      "x": -6,
      "y": 18,
      "z": 3,
      "name": "Soil_Dirt"
    },
    {
      "x": -6,
      "y": 19,
      "z": 3,
      "name": "Soil_Grass"
    },
    {
      "x": -6,
      "y": 9,
      "z": 4,
      "name": "Rock_Stone"
    },
    {
      "x": -6,
      "y": 10,
      "z": 4,
      "name": "Rock_Stone"
    },
    {
      "x": -6,
      "y": 11,
      "z": 4,
      "name": "Rock_Stone"
    },
    {
      "x": -6,
      "y": 12,
      "z": 4,
      "name": "Rock_Stone"
    },
    {
      "x": -6,
      "y": 13,
      "z": 4,
      "name": "Rock_Stone"
    },
    {
      "x": -6,
      "y": 14,
      "z": 4,
      "name": "Rock_Stone"
    },
    {
      "x": -6,
      "y": 15,
      "z": 4,
      "name": "Rock_Stone"
    },
    {
      "x": -6,
      "y": 16,
      "z": 4,
      "name": "Rock_Stone"
    },
    {
      "x": -6,
      "y": 17,
      "z": 4,
      "name": "Rock_Stone"
    },
    {
      "x": -6,
      "y": 18,
      "z": 4,
      "name": "Soil_Grass"
    },
    {
      "x": -6,
      "y": 11,
      "z": 5,
      "name": "Rock_Stone"
    },
    {
      "x": -6,
      "y": 12,
      "z": 5,
      "name": "Rock_Stone"
    },
    {
      "x": -6,
      "y": 13,
      "z": 5,
      "name": "Rock_Stone"
    },
    {
      "x": -6,
      "y": 14,
      "z": 5,
      "name": "Rock_Stone"
    },
    {
      "x": -6,
      "y": 15,
      "z": 5,
      "name": "Rock_Stone"
    },
    {
      "x": -5,
      "y": 28,
      "z": 0,
      "name": "Plant_Vine_Hanging"
    },
    {
      "x": -5,
      "y": 29,
      "z": 0,
      "name": "Plant_Leaves_Ash",
      "support": 15
    },
    {
      "x": -5,
      "y": 33,
      "z": 0,
      "name": "Plant_Vine_Hanging"
    },
    {
      "x": -5,
      "y": 34,
      "z": 0,
      "name": "Plant_Leaves_Ash",
      "support": 15
    },
    {
      "x": -5,
      "y": 12,
      "z": 1,
      "name": "Rock_Stone"
    },
    {
      "x": -5,
      "y": 13,
      "z": 1,
      "name": "Rock_Stone"
    },
    {
      "x": -5,
      "y": 14,
      "z": 1,
      "name": "Rock_Stone"
    },
    {
      "x": -5,
      "y": 15,
      "z": 1,
      "name": "Rock_Stone"
    },
    {
      "x": -5,
      "y": 16,
      "z": 1,
      "name": "Rock_Stone"
    },
    {
      "x": -5,
      "y": 17,
      "z": 1,
      "name": "Rock_Stone"
    },
    {
      "x": -5,
      "y": 18,
      "z": 1,
      "name": "Soil_Grass"
    },
    {
      "x": -5,
      "y": 19,
      "z": 1,
      "name": "Plant_Bush"
    },
    {
      "x": -5,
      "y": 28,
      "z": 1,
      "name": "Plant_Leaves_Ash",
      "support": 15
    },
    {
      "x": -5,
      "y": 29,
      "z": 1,
      "name": "Plant_Leaves_Ash",
      "support": 15
    },
    {
      "x": -5,
      "y": 33,
      "z": 1,
      "name": "Plant_Leaves_Ash",
      "support": 15
    },
    {
      "x": -5,
      "y": 34,
      "z": 1,
      "name": "Plant_Leaves_Ash",
      "support": 15
    },
    {
      "x": -5,
      "y": 35,
      "z": 1,
      "name": "Plant_Leaves_Ash",
      "support": 15
    },
    {
      "x": -5,
      "y": 10,
      "z": 2,
      "name": "Rock_Stone"
    },
    {
      "x": -5,
      "y": 11,
      "z": 2,
      "name": "Rock_Stone"
    },
    {
      "x": -5,
      "y": 12,
      "z": 2,
      "name": "Rock_Stone"
    },
    {
      "x": -5,
      "y": 13,
      "z": 2,
      "name": "Rock_Stone"
    },
    {
      "x": -5,
      "y": 14,
      "z": 2,
      "name": "Rock_Stone"
    },
    {
      "x": -5,
      "y": 15,
      "z": 2,
      "name": "Rock_Stone"
    },
    {
      "x": -5,
      "y": 16,
      "z": 2,
      "name": "Soil_Dirt"
    },
    {
      "x": -5,
      "y": 17,
      "z": 2,
      "name": "Rock_Stone"
    },
    {
      "x": -5,
      "y": 18,
      "z": 2,
      "name": "Soil_Dirt"
    },
    {
      "x": -5,
      "y": 19,
      "z": 2,
      "name": "Soil_Grass"
    },
    {
      "x": -5,
      "y": 29,
      "z": 2,
      "name": "Plant_Leaves_Ash",
      "support": 15
    },
    {
      "x": -5,
      "y": 32,
      "z": 2,
      "name": "Plant_Vine_Hanging"
    },
    {
      "x": -5,
      "y": 33,
      "z": 2,
      "name": "Plant_Leaves_Ash",
      "support": 15
    },
    {
      "x": -5,
      "y": 34,
      "z": 2,
      "name": "Wood_Ash_Trunk_Full",
      "support": 15
    },
    {
      "x": -5,
      "y": 35,
      "z": 2,
      "name": "Plant_Leaves_Ash",
      "support": 15
    },
    {
      "x": -5,
      "y": 8,
      "z": 3,
      "name": "Rock_Stone"
    },
    {
      "x": -5,
      "y": 9,
      "z": 3,
      "name": "Rock_Stone"
    },
    {
      "x": -5,
      "y": 10,
      "z": 3,
      "name": "Rock_Stone"
    },
    {
      "x": -5,
      "y": 11,
      "z": 3,
      "name": "Rock_Stone"
    },
    {
      "x": -5,
      "y": 12,
      "z": 3,
      "name": "Rock_Stone"
    },
    {
      "x": -5,
      "y": 13,
      "z": 3,
      "name": "Rock_Stone"
    },
    {
      "x": -5,
      "y": 14,
      "z": 3,
      "name": "Rock_Stone"
    },
    {
      "x": -5,
      "y": 15,
      "z": 3,
      "name": "Rock_Stone"
    },
    {
      "x": -5,
      "y": 16,
      "z": 3,
      "name": "Soil_Dirt"
    },
    {
      "x": -5,
      "y": 17,
      "z": 3,
      "name": "Rock_Stone"
    },
    {
      "x": -5,
      "y": 18,
      "z": 3,
      "name": "Soil_Dirt"
    },
    {
      "x": -5,
      "y": 19,
      "z": 3,
      "name": "Soil_Dirt"
    },
    {
      "x": -5,
      "y": 20,
      "z": 3,
      "name": "Soil_Leaves"
    },
    {
      "x": -5,
      "y": 21,
      "z": 3,
      "name": "Plant_Grass_Lush"
    },
    {
      "x": -5,
      "y": 32,
      "z": 3,
      "name": "Plant_Leaves_Ash",
      "support": 15
    },
    {
      "x": -5,
      "y": 33,
      "z": 3,
      "name": "Plant_Leaves_Ash",
      "support": 15
    },
    {
      "x": -5,
      "y": 34,
      "z": 3,
      "name": "Plant_Leaves_Ash",
      "support": 15
    },
    {
      "x": -5,
      "y": 35,
      "z": 3,
      "name": "Plant_Leaves_Ash",
      "support": 15
    },
    {
      "x": -5,
      "y": 8,
      "z": 4,
      "name": "Rock_Stone"
    },
    {
      "x": -5,
      "y": 9,
      "z": 4,
      "name": "Rock_Stone"
    },
    {
      "x": -5,
      "y": 10,
      "z": 4,
      "name": "Rock_Stone"
    },
    {
      "x": -5,
      "y": 11,
      "z": 4,
      "name": "Rock_Stone"
    },
    {
      "x": -5,
      "y": 12,
      "z": 4,
      "name": "Rock_Stone"
    },
    {
      "x": -5,
      "y": 13,
      "z": 4,
      "name": "Rock_Stone"
    },
    {
      "x": -5,
      "y": 14,
      "z": 4,
      "name": "Rock_Stone"
    },
    {
      "x": -5,
      "y": 15,
      "z": 4,
      "name": "Rock_Stone"
    },
    {
      "x": -5,
      "y": 16,
      "z": 4,
      "name": "Soil_Dirt"
    },
    {
      "x": -5,
      "y": 17,
      "z": 4,
      "name": "Rock_Stone"
    },
    {
      "x": -5,
      "y": 18,
      "z": 4,
      "name": "Soil_Dirt"
    },
    {
      "x": -5,
      "y": 19,
      "z": 4,
      "name": "Soil_Dirt"
    },
    {
      "x": -5,
      "y": 20,
      "z": 4,
      "name": "Soil_Leaves"
    },
    {
      "x": -5,
      "y": 21,
      "z": 4,
      "name": "Plant_Grass_Lush_Short"
    },
    {
      "x": -5,
      "y": 8,
      "z": 5,
      "name": "Rock_Stone"
    },
    {
      "x": -5,
      "y": 9,
      "z": 5,
      "name": "Rock_Stone"
    },
    {
      "x": -5,
      "y": 10,
      "z": 5,
      "name": "Rock_Stone"
    },
    {
      "x": -5,
      "y": 11,
      "z": 5,
      "name": "Rock_Stone"
    },
    {
      "x": -5,
      "y": 12,
      "z": 5,
      "name": "Rock_Stone"
    },
    {
      "x": -5,
      "y": 13,
      "z": 5,
      "name": "Rock_Stone"
    },
    {
      "x": -5,
      "y": 14,
      "z": 5,
      "name": "Rock_Stone"
    },
    {
      "x": -5,
      "y": 15,
      "z": 5,
      "name": "Rock_Stone"
    },
    {
      "x": -5,
      "y": 16,
      "z": 5,
      "name": "Rock_Stone"
    },
    {
      "x": -5,
      "y": 17,
      "z": 5,
      "name": "Rock_Stone"
    },
    {
      "x": -5,
      "y": 18,
      "z": 5,
      "name": "Soil_Dirt"
    },
    {
      "x": -5,
      "y": 19,
      "z": 5,
      "name": "Soil_Grass"
    },
    {
      "x": -4,
      "y": 29,
      "z": -1,
      "name": "Plant_Leaves_Ash",
      "support": 15
    },
    {
      "x": -4,
      "y": 28,
      "z": 0,
      "name": "Plant_Leaves_Ash",
      "support": 15
    },
    {
      "x": -4,
      "y": 29,
      "z": 0,
      "name": "Plant_Leaves_Ash",
      "support": 15
    },
    {
      "x": -4,
      "y": 30,
      "z": 0,
      "name": "Plant_Leaves_Ash",
      "support": 15
    },
    {
      "x": -4,
      "y": 32,
      "z": 0,
      "name": "Plant_Leaves_Ash",
      "support": 15
    },
    {
      "x": -4,
      "y": 33,
      "z": 0,
      "name": "Plant_Leaves_Ash",
      "support": 15
    },
    {
      "x": -4,
      "y": 34,
      "z": 0,
      "name": "Plant_Leaves_Ash",
      "support": 15
    },
    {
      "x": -4,
      "y": 35,
      "z": 0,
      "name": "Plant_Leaves_Ash",
      "support": 15
    },
    {
      "x": -4,
      "y": 14,
      "z": 1,
      "name": "Rock_Stone"
    },
    {
      "x": -4,
      "y": 15,
      "z": 1,
      "name": "Rock_Stone"
    },
    {
      "x": -4,
      "y": 16,
      "z": 1,
      "name": "Rock_Stone"
    },
    {
      "x": -4,
      "y": 17,
      "z": 1,
      "name": "Rock_Stone"
    },
    {
      "x": -4,
      "y": 18,
      "z": 1,
      "name": "Soil_Dirt"
    },
    {
      "x": -4,
      "y": 19,
      "z": 1,
      "name": "Soil_Dirt"
    },
    {
      "x": -4,
      "y": 20,
      "z": 1,
      "name": "Soil_Dirt"
    },
    {
      "x": -4,
      "y": 21,
      "z": 1,
      "name": "Soil_Leaves"
    },
    {
      "x": -4,
      "y": 22,
      "z": 1,
      "name": "Plant_Grass_Lush_Short"
    },
    {
      "x": -4,
      "y": 29,
      "z": 1,
      "name": "Wood_Ash_Trunk_Full",
      "support": 15
    },
    {
      "x": -4,
      "y": 30,
      "z": 1,
      "name": "Plant_Leaves_Ash",
      "support": 15
    },
    {
      "x": -4,
      "y": 33,
      "z": 1,
      "name": "Plant_Leaves_Ash",
      "support": 15
    },
    {
      "x": -4,
      "y": 34,
      "z": 1,
      "name": "Plant_Leaves_Ash",
      "support": 15
    },
    {
      "x": -4,
      "y": 35,
      "z": 1,
      "name": "Plant_Leaves_Ash",
      "support": 15
    },
    {
      "x": -4,
      "y": 9,
      "z": 2,
      "name": "Rock_Stone"
    },
    {
      "x": -4,
      "y": 10,
      "z": 2,
      "name": "Rock_Stone"
    },
    {
      "x": -4,
      "y": 11,
      "z": 2,
      "name": "Rock_Stone"
    },
    {
      "x": -4,
      "y": 12,
      "z": 2,
      "name": "Rock_Stone"
    },
    {
      "x": -4,
      "y": 13,
      "z": 2,
      "name": "Rock_Stone"
    },
    {
      "x": -4,
      "y": 14,
      "z": 2,
      "name": "Rock_Stone"
    },
    {
      "x": -4,
      "y": 15,
      "z": 2,
      "name": "Rock_Stone"
    },
    {
      "x": -4,
      "y": 16,
      "z": 2,
      "name": "Soil_Dirt"
    },
    {
      "x": -4,
      "y": 17,
      "z": 2,
      "name": "Soil_Dirt"
    },
    {
      "x": -4,
      "y": 18,
      "z": 2,
      "name": "Soil_Dirt"
    },
    {
      "x": -4,
      "y": 19,
      "z": 2,
      "name": "Soil_Dirt"
    },
    {
      "x": -4,
      "y": 20,
      "z": 2,
      "name": "Soil_Dirt"
    },
    {
      "x": -4,
      "y": 21,
      "z": 2,
      "name": "Soil_Leaves"
    },
    {
      "x": -4,
      "y": 22,
      "z": 2,
      "name": "Plant_Crop_Mushroom_Common_Brown",
      "components": {
        "Components": {
          "FarmingBlock": {}
        }
      }
    },
    {
      "x": -4,
      "y": 27,
      "z": 2,
      "name": "Plant_Leaves_Ash",
      "support": 15
    },
    {
      "x": -4,
      "y": 28,
      "z": 2,
      "name": "Plant_Leaves_Ash",
      "support": 15
    },
    {
      "x": -4,
      "y": 29,
      "z": 2,
      "name": "Plant_Leaves_Ash",
      "support": 15
    },
    {
      "x": -4,
      "y": 30,
      "z": 2,
      "name": "Plant_Leaves_Ash",
      "support": 15
    },
    {
      "x": -4,
      "y": 34,
      "z": 2,
      "name": "Wood_Ash_Trunk_Full",
      "support": 15
    },
    {
      "x": -4,
      "y": 35,
      "z": 2,
      "name": "Plant_Leaves_Ash",
      "support": 15
    },
    {
      "x": -4,
      "y": 7,
      "z": 3,
      "name": "Rock_Stone"
    },
    {
      "x": -4,
      "y": 8,
      "z": 3,
      "name": "Rock_Stone"
    },
    {
      "x": -4,
      "y": 9,
      "z": 3,
      "name": "Rock_Stone"
    },
    {
      "x": -4,
      "y": 10,
      "z": 3,
      "name": "Rock_Stone"
    },
    {
      "x": -4,
      "y": 11,
      "z": 3,
      "name": "Rock_Stone"
    },
    {
      "x": -4,
      "y": 12,
      "z": 3,
      "name": "Rock_Stone"
    },
    {
      "x": -4,
      "y": 13,
      "z": 3,
      "name": "Rock_Stone"
    },
    {
      "x": -4,
      "y": 14,
      "z": 3,
      "name": "Rock_Stone"
    },
    {
      "x": -4,
      "y": 15,
      "z": 3,
      "name": "Rock_Stone"
    },
    {
      "x": -4,
      "y": 16,
      "z": 3,
      "name": "Soil_Dirt"
    },
    {
      "x": -4,
      "y": 17,
      "z": 3,
      "name": "Soil_Dirt"
    },
    {
      "x": -4,
      "y": 18,
      "z": 3,
      "name": "Soil_Dirt"
    },
    {
      "x": -4,
      "y": 19,
      "z": 3,
      "name": "Soil_Dirt"
    },
    {
      "x": -4,
      "y": 20,
      "z": 3,
      "name": "Soil_Dirt"
    },
    {
      "x": -4,
      "y": 21,
      "z": 3,
      "name": "Soil_Leaves"
    },
    {
      "x": -4,
      "y": 28,
      "z": 3,
      "name": "Plant_Vine_Hanging"
    },
    {
      "x": -4,
      "y": 29,
      "z": 3,
      "name": "Plant_Leaves_Ash",
      "support": 15
    },
    {
      "x": -4,
      "y": 34,
      "z": 3,
      "name": "Plant_Leaves_Ash",
      "support": 15
    },
    {
      "x": -4,
      "y": 35,
      "z": 3,
      "name": "Plant_Leaves_Ash",
      "support": 15
    },
    {
      "x": -4,
      "y": 7,
      "z": 4,
      "name": "Rock_Stone"
    },
    {
      "x": -4,
      "y": 8,
      "z": 4,
      "name": "Rock_Stone"
    },
    {
      "x": -4,
      "y": 9,
      "z": 4,
      "name": "Rock_Stone"
    },
    {
      "x": -4,
      "y": 10,
      "z": 4,
      "name": "Rock_Stone"
    },
    {
      "x": -4,
      "y": 11,
      "z": 4,
      "name": "Rock_Stone"
    },
    {
      "x": -4,
      "y": 12,
      "z": 4,
      "name": "Rock_Stone"
    },
    {
      "x": -4,
      "y": 13,
      "z": 4,
      "name": "Rock_Stone"
    },
    {
      "x": -4,
      "y": 14,
      "z": 4,
      "name": "Rock_Stone"
    },
    {
      "x": -4,
      "y": 15,
      "z": 4,
      "name": "Rock_Stone"
    },
    {
      "x": -4,
      "y": 16,
      "z": 4,
      "name": "Soil_Dirt"
    },
    {
      "x": -4,
      "y": 17,
      "z": 4,
      "name": "Soil_Dirt"
    },
    {
      "x": -4,
      "y": 18,
      "z": 4,
      "name": "Soil_Dirt"
    },
    {
      "x": -4,
      "y": 19,
      "z": 4,
      "name": "Soil_Dirt"
    },
    {
      "x": -4,
      "y": 20,
      "z": 4,
      "name": "Soil_Grass"
    },
    {
      "x": -4,
      "y": 21,
      "z": 4,
      "name": "Plant_Moss_Rug_Green"
    },
    {
      "x": -4,
      "y": 34,
      "z": 4,
      "name": "Plant_Leaves_Ash",
      "support": 15
    },
    {
      "x": -4,
      "y": 7,
      "z": 5,
      "name": "Rock_Stone"
    },
    {
      "x": -4,
      "y": 8,
      "z": 5,
      "name": "Rock_Stone"
    },
    {
      "x": -4,
      "y": 9,
      "z": 5,
      "name": "Rock_Stone"
    },
    {
      "x": -4,
      "y": 10,
      "z": 5,
      "name": "Rock_Stone"
    },
    {
      "x": -4,
      "y": 11,
      "z": 5,
      "name": "Rock_Stone"
    },
    {
      "x": -4,
      "y": 12,
      "z": 5,
      "name": "Rock_Stone"
    },
    {
      "x": -4,
      "y": 13,
      "z": 5,
      "name": "Rock_Stone"
    },
    {
      "x": -4,
      "y": 14,
      "z": 5,
      "name": "Rock_Stone"
    },
    {
      "x": -4,
      "y": 15,
      "z": 5,
      "name": "Rock_Stone"
    },
    {
      "x": -4,
      "y": 16,
      "z": 5,
      "name": "Rock_Stone"
    },
    {
      "x": -4,
      "y": 17,
      "z": 5,
      "name": "Soil_Dirt"
    },
    {
      "x": -4,
      "y": 18,
      "z": 5,
      "name": "Soil_Dirt"
    },
    {
      "x": -4,
      "y": 19,
      "z": 5,
      "name": "Soil_Dirt"
    },
    {
      "x": -4,
      "y": 20,
      "z": 5,
      "name": "Soil_Grass"
    },
    {
      "x": -4,
      "y": 21,
      "z": 5,
      "name": "Plant_Moss_Rug_Green"
    },
    {
      "x": -4,
      "y": 31,
      "z": 5,
      "name": "Plant_Vine_Hanging"
    },
    {
      "x": -4,
      "y": 32,
      "z": 5,
      "name": "Plant_Leaves_Ash",
      "support": 15
    },
    {
      "x": -4,
      "y": 9,
      "z": 6,
      "name": "Rock_Stone"
    },
    {
      "x": -4,
      "y": 10,
      "z": 6,
      "name": "Rock_Stone"
    },
    {
      "x": -4,
      "y": 11,
      "z": 6,
      "name": "Rock_Stone"
    },
    {
      "x": -4,
      "y": 17,
      "z": 6,
      "name": "Rock_Stone"
    },
    {
      "x": -4,
      "y": 18,
      "z": 6,
      "name": "Soil_Grass"
    },
    {
      "x": -4,
      "y": 31,
      "z": 6,
      "name": "Plant_Leaves_Ash",
      "support": 15
    },
    {
      "x": -4,
      "y": 32,
      "z": 6,
      "name": "Plant_Leaves_Ash",
      "support": 15
    },
    {
      "x": -4,
      "y": 36,
      "z": 6,
      "name": "Plant_Leaves_Ash",
      "support": 15
    },
    {
      "x": -4,
      "y": 32,
      "z": 7,
      "name": "Plant_Leaves_Ash",
      "support": 15
    },
    {
      "x": -4,
      "y": 35,
      "z": 7,
      "name": "Plant_Leaves_Ash",
      "support": 15
    },
    {
      "x": -4,
      "y": 36,
      "z": 7,
      "name": "Plant_Leaves_Ash",
      "support": 15
    },
    {
      "x": -4,
      "y": 37,
      "z": 7,
      "name": "Plant_Leaves_Ash",
      "support": 15
    },
    {
      "x": -4,
      "y": 36,
      "z": 8,
      "name": "Plant_Leaves_Ash",
      "support": 15
    },
    {
      "x": -3,
      "y": 30,
      "z": -4,
      "name": "Plant_Leaves_Ash",
      "support": 15
    },
    {
      "x": -3,
      "y": 29,
      "z": -3,
      "name": "Plant_Vine_Hanging"
    },
    {
      "x": -3,
      "y": 30,
      "z": -3,
      "name": "Plant_Leaves_Ash",
      "support": 15
    },
    {
      "x": -3,
      "y": 31,
      "z": -3,
      "name": "Plant_Leaves_Ash",
      "support": 15
    },
    {
      "x": -3,
      "y": 33,
      "z": -3,
      "name": "Plant_Leaves_Ash",
      "support": 15
    },
    {
      "x": -3,
      "y": 34,
      "z": -3,
      "name": "Plant_Leaves_Ash",
      "support": 15
    },
    {
      "x": -3,
      "y": 32,
      "z": -2,
      "name": "Plant_Vine_Hanging"
    },
    {
      "x": -3,
      "y": 33,
      "z": -2,
      "name": "Plant_Leaves_Ash",
      "support": 15
    },
    {
      "x": -3,
      "y": 34,
      "z": -2,
      "name": "Plant_Leaves_Ash",
      "support": 15
    },
    {
      "x": -3,
      "y": 35,
      "z": -2,
      "name": "Plant_Leaves_Ash",
      "support": 15
    },
    {
      "x": -3,
      "y": 28,
      "z": -1,
      "name": "Plant_Leaves_Ash",
      "support": 15
    },
    {
      "x": -3,
      "y": 29,
      "z": -1,
      "name": "Plant_Leaves_Ash",
      "support": 15
    },
    {
      "x": -3,
      "y": 30,
      "z": -1,
      "name": "Plant_Leaves_Ash",
      "support": 15
    },
    {
      "x": -3,
      "y": 34,
      "z": -1,
      "name": "Plant_Leaves_Ash",
      "support": 15
    },
    {
      "x": -3,
      "y": 18,
      "z": 0,
      "name": "Rock_Stone"
    },
    {
      "x": -3,
      "y": 19,
      "z": 0,
      "name": "Soil_Dirt"
    },
    {
      "x": -3,
      "y": 20,
      "z": 0,
      "name": "Soil_Grass"
    },
    {
      "x": -3,
      "y": 28,
      "z": 0,
      "name": "Plant_Leaves_Ash",
      "support": 15
    },
    {
      "x": -3,
      "y": 29,
      "z": 0,
      "name": "Plant_Leaves_Ash",
      "support": 15
    },
    {
      "x": -3,
      "y": 30,
      "z": 0,
      "name": "Plant_Leaves_Ash",
      "support": 15
    },
    {
      "x": -3,
      "y": 17,
      "z": 1,
      "name": "Rock_Stone"
    },
    {
      "x": -3,
      "y": 18,
      "z": 1,
      "name": "Soil_Dirt"
    },
    {
      "x": -3,
      "y": 19,
      "z": 1,
      "name": "Soil_Dirt"
    },
    {
      "x": -3,
      "y": 20,
      "z": 1,
      "name": "Soil_Dirt"
    },
    {
      "x": -3,
      "y": 21,
      "z": 1,
      "name": "Soil_Dirt"
    },
    {
      "x": -3,
      "y": 22,
      "z": 1,
      "name": "Soil_Grass"
    },
    {
      "x": -3,
      "y": 23,
      "z": 1,
      "name": "Plant_Moss_Rug_Green"
    },
    {
      "x": -3,
      "y": 29,
      "z": 1,
      "name": "Wood_Ash_Trunk_Full",
      "support": 15
    },
    {
      "x": -3,
      "y": 30,
      "z": 1,
      "name": "Plant_Leaves_Ash",
      "support": 15
    },
    {
      "x": -3,
      "y": 34,
      "z": 1,
      "name": "Wood_Ash_Trunk_Full",
      "support": 15
    },
    {
      "x": -3,
      "y": 37,
      "z": 1,
      "name": "Plant_Leaves_Ash",
      "support": 15
    },
    {
      "x": -3,
      "y": 10,
      "z": 2,
      "name": "Rock_Stone"
    },
    {
      "x": -3,
      "y": 11,
      "z": 2,
      "name": "Rock_Stone"
    },
    {
      "x": -3,
      "y": 15,
      "z": 2,
      "name": "Rock_Stone"
    },
    {
      "x": -3,
      "y": 16,
      "z": 2,
      "name": "Rock_Stone"
    },
    {
      "x": -3,
      "y": 17,
      "z": 2,
      "name": "Rock_Stone"
    },
    {
      "x": -3,
      "y": 18,
      "z": 2,
      "name": "Soil_Dirt"
    },
    {
      "x": -3,
      "y": 19,
      "z": 2,
      "name": "Soil_Dirt"
    },
    {
      "x": -3,
      "y": 20,
      "z": 2,
      "name": "Soil_Dirt"
    },
    {
      "x": -3,
      "y": 21,
      "z": 2,
      "name": "Soil_Dirt"
    },
    {
      "x": -3,
      "y": 22,
      "z": 2,
      "name": "Soil_Leaves"
    },
    {
      "x": -3,
      "y": 29,
      "z": 2,
      "name": "Plant_Leaves_Ash",
      "support": 15
    },
    {
      "x": -3,
      "y": 30,
      "z": 2,
      "name": "Plant_Leaves_Ash",
      "support": 15
    },
    {
      "x": -3,
      "y": 34,
      "z": 2,
      "name": "Wood_Ash_Trunk_Full",
      "support": 15
    },
    {
      "x": -3,
      "y": 37,
      "z": 2,
      "name": "Plant_Leaves_Ash",
      "support": 15
    },
    {
      "x": -3,
      "y": 38,
      "z": 2,
      "name": "Plant_Leaves_Ash",
      "support": 15
    },
    {
      "x": -3,
      "y": 6,
      "z": 3,
      "name": "Rock_Stone"
    },
    {
      "x": -3,
      "y": 7,
      "z": 3,
      "name": "Rock_Stone"
    },
    {
      "x": -3,
      "y": 8,
      "z": 3,
      "name": "Rock_Stone"
    },
    {
      "x": -3,
      "y": 9,
      "z": 3,
      "name": "Rock_Stone"
    },
    {
      "x": -3,
      "y": 10,
      "z": 3,
      "name": "Rock_Stone"
    },
    {
      "x": -3,
      "y": 11,
      "z": 3,
      "name": "Rock_Stone"
    },
    {
      "x": -3,
      "y": 12,
      "z": 3,
      "name": "Rock_Stone"
    },
    {
      "x": -3,
      "y": 13,
      "z": 3,
      "name": "Rock_Stone"
    },
    {
      "x": -3,
      "y": 14,
      "z": 3,
      "name": "Rock_Stone"
    },
    {
      "x": -3,
      "y": 15,
      "z": 3,
      "name": "Rock_Stone"
    },
    {
      "x": -3,
      "y": 16,
      "z": 3,
      "name": "Rock_Stone"
    },
    {
      "x": -3,
      "y": 17,
      "z": 3,
      "name": "Rock_Stone"
    },
    {
      "x": -3,
      "y": 18,
      "z": 3,
      "name": "Soil_Dirt"
    },
    {
      "x": -3,
      "y": 19,
      "z": 3,
      "name": "Soil_Dirt"
    },
    {
      "x": -3,
      "y": 20,
      "z": 3,
      "name": "Soil_Dirt"
    },
    {
      "x": -3,
      "y": 21,
      "z": 3,
      "name": "Soil_Dirt"
    },
    {
      "x": -3,
      "y": 22,
      "z": 3,
      "name": "Soil_Leaves"
    },
    {
      "x": -3,
      "y": 29,
      "z": 3,
      "name": "Plant_Leaves_Ash",
      "support": 15
    },
    {
      "x": -3,
      "y": 37,
      "z": 3,
      "name": "Plant_Leaves_Ash",
      "support": 15
    },
    {
      "x": -3,
      "y": 38,
      "z": 3,
      "name": "Plant_Leaves_Ash",
      "support": 15
    },
    {
      "x": -3,
      "y": 6,
      "z": 4,
      "name": "Rock_Stone"
    },
    {
      "x": -3,
      "y": 7,
      "z": 4,
      "name": "Rock_Stone"
    },
    {
      "x": -3,
      "y": 8,
      "z": 4,
      "name": "Rock_Stone"
    },
    {
      "x": -3,
      "y": 9,
      "z": 4,
      "name": "Rock_Stone"
    },
    {
      "x": -3,
      "y": 10,
      "z": 4,
      "name": "Rock_Stone"
    },
    {
      "x": -3,
      "y": 11,
      "z": 4,
      "name": "Rock_Stone"
    },
    {
      "x": -3,
      "y": 12,
      "z": 4,
      "name": "Rock_Stone"
    },
    {
      "x": -3,
      "y": 13,
      "z": 4,
      "name": "Rock_Stone"
    },
    {
      "x": -3,
      "y": 14,
      "z": 4,
      "name": "Rock_Stone"
    },
    {
      "x": -3,
      "y": 15,
      "z": 4,
      "name": "Rock_Stone"
    },
    {
      "x": -3,
      "y": 16,
      "z": 4,
      "name": "Rock_Stone"
    },
    {
      "x": -3,
      "y": 17,
      "z": 4,
      "name": "Rock_Stone"
    },
    {
      "x": -3,
      "y": 18,
      "z": 4,
      "name": "Soil_Dirt"
    },
    {
      "x": -3,
      "y": 19,
      "z": 4,
      "name": "Soil_Dirt"
    },
    {
      "x": -3,
      "y": 20,
      "z": 4,
      "name": "Soil_Dirt"
    },
    {
      "x": -3,
      "y": 21,
      "z": 4,
      "name": "Soil_Dirt"
    },
    {
      "x": -3,
      "y": 22,
      "z": 4,
      "name": "Soil_Leaves"
    },
    {
      "x": -3,
      "y": 23,
      "z": 4,
      "name": "Plant_Grass_Lush"
    },
    {
      "x": -3,
      "y": 33,
      "z": 4,
      "name": "Plant_Leaves_Ash",
      "support": 15
    },
    {
      "x": -3,
      "y": 37,
      "z": 4,
      "name": "Plant_Leaves_Ash",
      "support": 15
    },
    {
      "x": -3,
      "y": 6,
      "z": 5,
      "name": "Rock_Stone"
    },
    {
      "x": -3,
      "y": 7,
      "z": 5,
      "name": "Rock_Stone"
    },
    {
      "x": -3,
      "y": 8,
      "z": 5,
      "name": "Rock_Stone"
    },
    {
      "x": -3,
      "y": 9,
      "z": 5,
      "name": "Rock_Stone"
    },
    {
      "x": -3,
      "y": 10,
      "z": 5,
      "name": "Rock_Stone"
    },
    {
      "x": -3,
      "y": 11,
      "z": 5,
      "name": "Rock_Stone"
    },
    {
      "x": -3,
      "y": 12,
      "z": 5,
      "name": "Rock_Stone"
    },
    {
      "x": -3,
      "y": 15,
      "z": 5,
      "name": "Rock_Stone"
    },
    {
      "x": -3,
      "y": 16,
      "z": 5,
      "name": "Rock_Stone"
    },
    {
      "x": -3,
      "y": 17,
      "z": 5,
      "name": "Rock_Stone"
    },
    {
      "x": -3,
      "y": 18,
      "z": 5,
      "name": "Soil_Dirt"
    },
    {
      "x": -3,
      "y": 19,
      "z": 5,
      "name": "Soil_Dirt"
    },
    {
      "x": -3,
      "y": 20,
      "z": 5,
      "name": "Soil_Dirt"
    },
    {
      "x": -3,
      "y": 21,
      "z": 5,
      "name": "Soil_Grass"
    },
    {
      "x": -3,
      "y": 30,
      "z": 5,
      "name": "Plant_Leaves_Ash",
      "support": 15
    },
    {
      "x": -3,
      "y": 31,
      "z": 5,
      "name": "Plant_Leaves_Ash",
      "support": 15
    },
    {
      "x": -3,
      "y": 32,
      "z": 5,
      "name": "Plant_Leaves_Ash",
      "support": 15
    },
    {
      "x": -3,
      "y": 33,
      "z": 5,
      "name": "Plant_Leaves_Ash",
      "support": 15
    },
    {
      "x": -3,
      "y": 6,
      "z": 6,
      "name": "Rock_Stone"
    },
    {
      "x": -3,
      "y": 7,
      "z": 6,
      "name": "Rock_Stone"
    },
    {
      "x": -3,
      "y": 8,
      "z": 6,
      "name": "Rock_Stone"
    },
    {
      "x": -3,
      "y": 9,
      "z": 6,
      "name": "Rock_Stone"
    },
    {
      "x": -3,
      "y": 16,
      "z": 6,
      "name": "Rock_Stone"
    },
    {
      "x": -3,
      "y": 17,
      "z": 6,
      "name": "Rock_Stone"
    },
    {
      "x": -3,
      "y": 18,
      "z": 6,
      "name": "Soil_Dirt"
    },
    {
      "x": -3,
      "y": 19,
      "z": 6,
      "name": "Soil_Dirt"
    },
    {
      "x": -3,
      "y": 20,
      "z": 6,
      "name": "Soil_Grass"
    },
    {
      "x": -3,
      "y": 31,
      "z": 6,
      "name": "Plant_Leaves_Ash",
      "support": 15
    },
    {
      "x": -3,
      "y": 32,
      "z": 6,
      "name": "Wood_Ash_Trunk_Full",
      "support": 15
    },
    {
      "x": -3,
      "y": 33,
      "z": 6,
      "name": "Plant_Leaves_Ash",
      "support": 15
    },
    {
      "x": -3,
      "y": 34,
      "z": 6,
      "name": "Plant_Leaves_Ash",
      "support": 15
    },
    {
      "x": -3,
      "y": 36,
      "z": 6,
      "name": "Plant_Leaves_Ash",
      "support": 15
    },
    {
      "x": -3,
      "y": 18,
      "z": 7,
      "name": "Soil_Dirt"
    },
    {
      "x": -3,
      "y": 19,
      "z": 7,
      "name": "Soil_Grass"
    },
    {
      "x": -3,
      "y": 30,
      "z": 7,
      "name": "Plant_Vine_Hanging"
    },
    {
      "x": -3,
      "y": 31,
      "z": 7,
      "name": "Plant_Leaves_Ash",
      "support": 15
    },
    {
      "x": -3,
      "y": 32,
      "z": 7,
      "name": "Plant_Leaves_Ash",
      "support": 15
    },
    {
      "x": -3,
      "y": 33,
      "z": 7,
      "name": "Plant_Leaves_Ash",
      "support": 15
    },
    {
      "x": -3,
      "y": 36,
      "z": 7,
      "name": "Plant_Leaves_Ash",
      "support": 15
    },
    {
      "x": -3,
      "y": 37,
      "z": 7,
      "name": "Plant_Leaves_Ash",
      "support": 15
    },
    {
      "x": -3,
      "y": 30,
      "z": 8,
      "name": "Plant_Leaves_Ash",
      "support": 15
    },
    {
      "x": -3,
      "y": 31,
      "z": 8,
      "name": "Plant_Leaves_Ash",
      "support": 15
    },
    {
      "x": -3,
      "y": 32,
      "z": 8,
      "name": "Plant_Leaves_Ash",
      "support": 15
    },
    {
      "x": -3,
      "y": 33,
      "z": 8,
      "name": "Plant_Leaves_Ash",
      "support": 15
    },
    {
      "x": -3,
      "y": 34,
      "z": 8,
      "name": "Plant_Vine_Hanging"
    },
    {
      "x": -3,
      "y": 35,
      "z": 8,
      "name": "Plant_Leaves_Ash",
      "support": 15
    },
    {
      "x": -3,
      "y": 36,
      "z": 8,
      "name": "Plant_Leaves_Ash",
      "support": 15
    },
    {
      "x": -3,
      "y": 37,
      "z": 8,
      "name": "Plant_Leaves_Ash",
      "support": 15
    },
    {
      "x": -3,
      "y": 35,
      "z": 9,
      "name": "Plant_Leaves_Ash",
      "support": 15
    },
    {
      "x": -3,
      "y": 36,
      "z": 9,
      "name": "Plant_Leaves_Ash",
      "support": 15
    },
    {
      "x": -3,
      "y": 37,
      "z": 9,
      "name": "Plant_Leaves_Ash",
      "support": 15
    },
    {
      "x": -3,
      "y": 36,
      "z": 10,
      "name": "Plant_Leaves_Ash",
      "support": 15
    },
    {
      "x": -2,
      "y": 30,
      "z": -5,
      "name": "Plant_Leaves_Ash",
      "support": 15
    },
    {
      "x": -2,
      "y": 29,
      "z": -4,
      "name": "Plant_Leaves_Ash",
      "support": 15
    },
    {
      "x": -2,
      "y": 30,
      "z": -4,
      "name": "Plant_Leaves_Ash",
      "support": 15
    },
    {
      "x": -2,
      "y": 31,
      "z": -4,
      "name": "Plant_Leaves_Ash",
      "support": 15
    },
    {
      "x": -2,
      "y": 32,
      "z": -4,
      "name": "Plant_Vine_Hanging"
    },
    {
      "x": -2,
      "y": 33,
      "z": -4,
      "name": "Plant_Leaves_Ash",
      "support": 15
    },
    {
      "x": -2,
      "y": 34,
      "z": -4,
      "name": "Plant_Leaves_Ash",
      "support": 15
    },
    {
      "x": -2,
      "y": 28,
      "z": -3,
      "name": "Plant_Leaves_Ash",
      "support": 15
    },
    {
      "x": -2,
      "y": 29,
      "z": -3,
      "name": "Plant_Leaves_Ash",
      "support": 15
    },
    {
      "x": -2,
      "y": 30,
      "z": -3,
      "name": "Plant_Leaves_Ash",
      "support": 15
    },
    {
      "x": -2,
      "y": 31,
      "z": -3,
      "name": "Plant_Leaves_Ash",
      "support": 15
    },
    {
      "x": -2,
      "y": 32,
      "z": -3,
      "name": "Plant_Leaves_Ash",
      "support": 15
    },
    {
      "x": -2,
      "y": 33,
      "z": -3,
      "name": "Plant_Leaves_Ash",
      "support": 15
    },
    {
      "x": -2,
      "y": 34,
      "z": -3,
      "name": "Wood_Ash_Trunk_Full",
      "support": 15
    },
    {
      "x": -2,
      "y": 35,
      "z": -3,
      "name": "Plant_Leaves_Ash",
      "support": 15
    },
    {
      "x": -2,
      "y": 34,
      "z": -2,
      "name": "Wood_Ash_Trunk_Full",
      "support": 15
    },
    {
      "x": -2,
      "y": 35,
      "z": -2,
      "name": "Plant_Leaves_Ash",
      "support": 15
    },
    {
      "x": -2,
      "y": 35,
      "z": -1,
      "name": "Plant_Leaves_Ash",
      "support": 15
    },
    {
      "x": -2,
      "y": 17,
      "z": 0,
      "name": "Rock_Stone"
    },
    {
      "x": -2,
      "y": 18,
      "z": 0,
      "name": "Rock_Stone"
    },
    {
      "x": -2,
      "y": 19,
      "z": 0,
      "name": "Rock_Stone"
    },
    {
      "x": -2,
      "y": 20,
      "z": 0,
      "name": "Soil_Dirt"
    },
    {
      "x": -2,
      "y": 21,
      "z": 0,
      "name": "Soil_Grass"
    },
    {
      "x": -2,
      "y": 29,
      "z": 0,
      "name": "Wood_Ash_Trunk_Full",
      "support": 15
    },
    {
      "x": -2,
      "y": 17,
      "z": 1,
      "name": "Rock_Stone"
    },
    {
      "x": -2,
      "y": 18,
      "z": 1,
      "name": "Rock_Stone"
    },
    {
      "x": -2,
      "y": 19,
      "z": 1,
      "name": "Soil_Dirt"
    },
    {
      "x": -2,
      "y": 20,
      "z": 1,
      "name": "Soil_Dirt"
    },
    {
      "x": -2,
      "y": 21,
      "z": 1,
      "name": "Soil_Dirt"
    },
    {
      "x": -2,
      "y": 22,
      "z": 1,
      "name": "Soil_Grass"
    },
    {
      "x": -2,
      "y": 23,
      "z": 1,
      "name": "Plant_Moss_Rug_Green"
    },
    {
      "x": -2,
      "y": 29,
      "z": 1,
      "name": "Wood_Ash_Trunk_Full",
      "support": 15
    },
    {
      "x": -2,
      "y": 34,
      "z": 1,
      "name": "Wood_Ash_Trunk_Full",
      "support": 15
    },
    {
      "x": -2,
      "y": 38,
      "z": 1,
      "name": "Plant_Leaves_Ash",
      "support": 15
    },
    {
      "x": -2,
      "y": 16,
      "z": 2,
      "name": "Rock_Stone"
    },
    {
      "x": -2,
      "y": 17,
      "z": 2,
      "name": "Rock_Stone"
    },
    {
      "x": -2,
      "y": 18,
      "z": 2,
      "name": "Rock_Stone"
    },
    {
      "x": -2,
      "y": 19,
      "z": 2,
      "name": "Soil_Dirt"
    },
    {
      "x": -2,
      "y": 20,
      "z": 2,
      "name": "Soil_Dirt"
    },
    {
      "x": -2,
      "y": 21,
      "z": 2,
      "name": "Soil_Dirt"
    },
    {
      "x": -2,
      "y": 22,
      "z": 2,
      "name": "Soil_Grass"
    },
    {
      "x": -2,
      "y": 23,
      "z": 2,
      "name": "Plant_Moss_Rug_Green"
    },
    {
      "x": -2,
      "y": 37,
      "z": 2,
      "name": "Plant_Leaves_Ash",
      "support": 15
    },
    {
      "x": -2,
      "y": 38,
      "z": 2,
      "name": "Plant_Leaves_Ash",
      "support": 15
    },
    {
      "x": -2,
      "y": 6,
      "z": 3,
      "name": "Rock_Stone"
    },
    {
      "x": -2,
      "y": 7,
      "z": 3,
      "name": "Rock_Stone"
    },
    {
      "x": -2,
      "y": 8,
      "z": 3,
      "name": "Rock_Stone"
    },
    {
      "x": -2,
      "y": 9,
      "z": 3,
      "name": "Rock_Stone"
    },
    {
      "x": -2,
      "y": 16,
      "z": 3,
      "name": "Rock_Stone"
    },
    {
      "x": -2,
      "y": 17,
      "z": 3,
      "name": "Rock_Stone"
    },
    {
      "x": -2,
      "y": 18,
      "z": 3,
      "name": "Rock_Stone"
    },
    {
      "x": -2,
      "y": 19,
      "z": 3,
      "name": "Soil_Dirt"
    },
    {
      "x": -2,
      "y": 20,
      "z": 3,
      "name": "Soil_Dirt"
    },
    {
      "x": -2,
      "y": 21,
      "z": 3,
      "name": "Soil_Dirt"
    },
    {
      "x": -2,
      "y": 22,
      "z": 3,
      "name": "Soil_Leaves"
    },
    {
      "x": -2,
      "y": 23,
      "z": 3,
      "name": "Plant_Grass_Lush_Short"
    },
    {
      "x": -2,
      "y": 37,
      "z": 3,
      "name": "Wood_Ash_Trunk_Full",
      "support": 15
    },
    {
      "x": -2,
      "y": 38,
      "z": 3,
      "name": "Plant_Leaves_Ash",
      "support": 15
    },
    {
      "x": -2,
      "y": 39,
      "z": 3,
      "name": "Plant_Leaves_Ash",
      "support": 15
    },
    {
      "x": -2,
      "y": 5,
      "z": 4,
      "name": "Rock_Stone"
    },
    {
      "x": -2,
      "y": 6,
      "z": 4,
      "name": "Rock_Stone"
    },
    {
      "x": -2,
      "y": 7,
      "z": 4,
      "name": "Rock_Stone"
    },
    {
      "x": -2,
      "y": 8,
      "z": 4,
      "name": "Rock_Stone"
    },
    {
      "x": -2,
      "y": 9,
      "z": 4,
      "name": "Rock_Stone"
    },
    {
      "x": -2,
      "y": 10,
      "z": 4,
      "name": "Rock_Stone"
    },
    {
      "x": -2,
      "y": 11,
      "z": 4,
      "name": "Rock_Stone"
    },
    {
      "x": -2,
      "y": 16,
      "z": 4,
      "name": "Rock_Stone"
    },
    {
      "x": -2,
      "y": 17,
      "z": 4,
      "name": "Rock_Stone"
    },
    {
      "x": -2,
      "y": 18,
      "z": 4,
      "name": "Soil_Dirt"
    },
    {
      "x": -2,
      "y": 19,
      "z": 4,
      "name": "Soil_Dirt"
    },
    {
      "x": -2,
      "y": 20,
      "z": 4,
      "name": "Soil_Dirt"
    },
    {
      "x": -2,
      "y": 21,
      "z": 4,
      "name": "Soil_Dirt"
    },
    {
      "x": -2,
      "y": 22,
      "z": 4,
      "name": "Soil_Grass"
    },
    {
      "x": -2,
      "y": 37,
      "z": 4,
      "name": "Plant_Leaves_Ash",
      "support": 15
    },
    {
      "x": -2,
      "y": 38,
      "z": 4,
      "name": "Plant_Leaves_Ash",
      "support": 15
    },
    {
      "x": -2,
      "y": 5,
      "z": 5,
      "name": "Rock_Stone"
    },
    {
      "x": -2,
      "y": 6,
      "z": 5,
      "name": "Rock_Stone"
    },
    {
      "x": -2,
      "y": 7,
      "z": 5,
      "name": "Rock_Stone"
    },
    {
      "x": -2,
      "y": 8,
      "z": 5,
      "name": "Rock_Stone"
    },
    {
      "x": -2,
      "y": 9,
      "z": 5,
      "name": "Rock_Stone"
    },
    {
      "x": -2,
      "y": 10,
      "z": 5,
      "name": "Rock_Stone"
    },
    {
      "x": -2,
      "y": 16,
      "z": 5,
      "name": "Rock_Stone"
    },
    {
      "x": -2,
      "y": 17,
      "z": 5,
      "name": "Rock_Stone"
    },
    {
      "x": -2,
      "y": 18,
      "z": 5,
      "name": "Soil_Dirt"
    },
    {
      "x": -2,
      "y": 19,
      "z": 5,
      "name": "Soil_Dirt"
    },
    {
      "x": -2,
      "y": 20,
      "z": 5,
      "name": "Soil_Dirt"
    },
    {
      "x": -2,
      "y": 21,
      "z": 5,
      "name": "Soil_Dirt"
    },
    {
      "x": -2,
      "y": 22,
      "z": 5,
      "name": "Soil_Grass"
    },
    {
      "x": -2,
      "y": 31,
      "z": 5,
      "name": "Plant_Leaves_Ash",
      "support": 15
    },
    {
      "x": -2,
      "y": 32,
      "z": 5,
      "name": "Plant_Leaves_Ash",
      "support": 15
    },
    {
      "x": -2,
      "y": 33,
      "z": 5,
      "name": "Plant_Leaves_Ash",
      "support": 15
    },
    {
      "x": -2,
      "y": 5,
      "z": 6,
      "name": "Rock_Stone"
    },
    {
      "x": -2,
      "y": 6,
      "z": 6,
      "name": "Rock_Stone"
    },
    {
      "x": -2,
      "y": 7,
      "z": 6,
      "name": "Rock_Stone"
    },
    {
      "x": -2,
      "y": 8,
      "z": 6,
      "name": "Rock_Stone"
    },
    {
      "x": -2,
      "y": 16,
      "z": 6,
      "name": "Rock_Stone"
    },
    {
      "x": -2,
      "y": 17,
      "z": 6,
      "name": "Rock_Stone"
    },
    {
      "x": -2,
      "y": 18,
      "z": 6,
      "name": "Soil_Dirt"
    },
    {
      "x": -2,
      "y": 19,
      "z": 6,
      "name": "Soil_Dirt"
    },
    {
      "x": -2,
      "y": 20,
      "z": 6,
      "name": "Soil_Dirt"
    },
    {
      "x": -2,
      "y": 21,
      "z": 6,
      "name": "Soil_Dirt"
    },
    {
      "x": -2,
      "y": 22,
      "z": 6,
      "name": "Soil_Grass"
    },
    {
      "x": -2,
      "y": 32,
      "z": 6,
      "name": "Wood_Ash_Trunk_Full",
      "support": 15
    },
    {
      "x": -2,
      "y": 33,
      "z": 6,
      "name": "Plant_Leaves_Ash",
      "support": 15
    },
    {
      "x": -2,
      "y": 34,
      "z": 6,
      "name": "Plant_Leaves_Ash",
      "support": 15
    },
    {
      "x": -2,
      "y": 36,
      "z": 6,
      "name": "Plant_Leaves_Ash",
      "support": 15
    },
    {
      "x": -2,
      "y": 38,
      "z": 6,
      "name": "Plant_Leaves_Ash",
      "support": 15
    },
    {
      "x": -2,
      "y": 7,
      "z": 7,
      "name": "Rock_Stone"
    },
    {
      "x": -2,
      "y": 18,
      "z": 7,
      "name": "Soil_Dirt"
    },
    {
      "x": -2,
      "y": 19,
      "z": 7,
      "name": "Soil_Dirt"
    },
    {
      "x": -2,
      "y": 20,
      "z": 7,
      "name": "Soil_Grass"
    },
    {
      "x": -2,
      "y": 31,
      "z": 7,
      "name": "Plant_Leaves_Ash",
      "support": 15
    },
    {
      "x": -2,
      "y": 32,
      "z": 7,
      "name": "Plant_Leaves_Ash",
      "support": 15
    },
    {
      "x": -2,
      "y": 33,
      "z": 7,
      "name": "Plant_Leaves_Ash",
      "support": 15
    },
    {
      "x": -2,
      "y": 34,
      "z": 7,
      "name": "Plant_Leaves_Ash",
      "support": 15
    },
    {
      "x": -2,
      "y": 36,
      "z": 7,
      "name": "Wood_Ash_Trunk_Full",
      "support": 15
    },
    {
      "x": -2,
      "y": 37,
      "z": 7,
      "name": "Plant_Leaves_Ash",
      "support": 15
    },
    {
      "x": -2,
      "y": 38,
      "z": 7,
      "name": "Plant_Leaves_Ash",
      "support": 15
    },
    {
      "x": -2,
      "y": 31,
      "z": 8,
      "name": "Plant_Leaves_Ash",
      "support": 15
    },
    {
      "x": -2,
      "y": 32,
      "z": 8,
      "name": "Plant_Leaves_Ash",
      "support": 15
    },
    {
      "x": -2,
      "y": 33,
      "z": 8,
      "name": "Plant_Leaves_Ash",
      "support": 15
    },
    {
      "x": -2,
      "y": 36,
      "z": 8,
      "name": "Wood_Ash_Trunk_Full",
      "support": 15
    },
    {
      "x": -2,
      "y": 38,
      "z": 8,
      "name": "Plant_Leaves_Ash",
      "support": 15
    },
    {
      "x": -2,
      "y": 32,
      "z": 9,
      "name": "Plant_Leaves_Ash",
      "support": 15
    },
    {
      "x": -2,
      "y": 34,
      "z": 9,
      "name": "Plant_Vine_Hanging"
    },
    {
      "x": -2,
      "y": 35,
      "z": 9,
      "name": "Plant_Leaves_Ash",
      "support": 15
    },
    {
      "x": -2,
      "y": 36,
      "z": 9,
      "name": "Wood_Ash_Trunk_Full",
      "support": 15
    },
    {
      "x": -2,
      "y": 37,
      "z": 9,
      "name": "Plant_Leaves_Ash",
      "support": 15
    },
    {
      "x": -2,
      "y": 34,
      "z": 10,
      "name": "Plant_Leaves_Ash",
      "support": 15
    },
    {
      "x": -2,
      "y": 35,
      "z": 10,
      "name": "Plant_Leaves_Ash",
      "support": 15
    },
    {
      "x": -2,
      "y": 36,
      "z": 10,
      "name": "Plant_Leaves_Ash",
      "support": 15
    },
    {
      "x": -2,
      "y": 37,
      "z": 10,
      "name": "Plant_Leaves_Ash",
      "support": 15
    },
    {
      "x": -2,
      "y": 32,
      "z": 11,
      "name": "Plant_Leaves_Ash",
      "support": 15
    },
    {
      "x": -2,
      "y": 36,
      "z": 11,
      "name": "Plant_Leaves_Ash",
      "support": 15
    },
    {
      "x": -1,
      "y": 29,
      "z": -5,
      "name": "Plant_Vine_Hanging"
    },
    {
      "x": -1,
      "y": 30,
      "z": -5,
      "name": "Plant_Leaves_Ash",
      "support": 15
    },
    {
      "x": -1,
      "y": 31,
      "z": -5,
      "name": "Plant_Leaves_Ash",
      "support": 15
    },
    {
      "x": -1,
      "y": 29,
      "z": -4,
      "name": "Plant_Vine_Hanging"
    },
    {
      "x": -1,
      "y": 30,
      "z": -4,
      "name": "Wood_Ash_Trunk_Full",
      "support": 15
    },
    {
      "x": -1,
      "y": 31,
      "z": -4,
      "name": "Plant_Leaves_Ash",
      "support": 15
    },
    {
      "x": -1,
      "y": 32,
      "z": -4,
      "name": "Plant_Leaves_Ash",
      "support": 15
    },
    {
      "x": -1,
      "y": 33,
      "z": -4,
      "name": "Plant_Leaves_Ash",
      "support": 15
    },
    {
      "x": -1,
      "y": 34,
      "z": -4,
      "name": "Plant_Leaves_Ash",
      "support": 15
    },
    {
      "x": -1,
      "y": 35,
      "z": -4,
      "name": "Plant_Leaves_Ash",
      "support": 15
    },
    {
      "x": -1,
      "y": 30,
      "z": -3,
      "name": "Wood_Ash_Trunk_Full",
      "support": 15
    },
    {
      "x": -1,
      "y": 34,
      "z": -3,
      "name": "Plant_Leaves_Ash",
      "support": 15
    },
    {
      "x": -1,
      "y": 35,
      "z": -3,
      "name": "Plant_Leaves_Ash",
      "support": 15
    },
    {
      "x": -1,
      "y": 34,
      "z": -2,
      "name": "Wood_Ash_Trunk_Full",
      "support": 15
    },
    {
      "x": -1,
      "y": 35,
      "z": -2,
      "name": "Plant_Leaves_Ash",
      "support": 15
    },
    {
      "x": -1,
      "y": 36,
      "z": -2,
      "name": "Plant_Leaves_Ash",
      "support": 15
    },
    {
      "x": -1,
      "y": 19,
      "z": -1,
      "name": "Rock_Stone"
    },
    {
      "x": -1,
      "y": 20,
      "z": -1,
      "name": "Soil_Grass"
    },
    {
      "x": -1,
      "y": 34,
      "z": -1,
      "name": "Wood_Ash_Trunk_Full",
      "support": 15
    },
    {
      "x": -1,
      "y": 36,
      "z": -1,
      "name": "Plant_Leaves_Ash",
      "support": 15
    },
    {
      "x": -1,
      "y": 18,
      "z": 0,
      "name": "Rock_Stone"
    },
    {
      "x": -1,
      "y": 19,
      "z": 0,
      "name": "Rock_Stone"
    },
    {
      "x": -1,
      "y": 20,
      "z": 0,
      "name": "Soil_Dirt"
    },
    {
      "x": -1,
      "y": 21,
      "z": 0,
      "name": "Soil_Dirt"
    },
    {
      "x": -1,
      "y": 22,
      "z": 0,
      "name": "Soil_Grass"
    },
    {
      "x": -1,
      "y": 29,
      "z": 0,
      "name": "Wood_Ash_Trunk_Full",
      "support": 15
    },
    {
      "x": -1,
      "y": 17,
      "z": 1,
      "name": "Rock_Stone"
    },
    {
      "x": -1,
      "y": 18,
      "z": 1,
      "name": "Rock_Stone"
    },
    {
      "x": -1,
      "y": 19,
      "z": 1,
      "name": "Rock_Stone"
    },
    {
      "x": -1,
      "y": 20,
      "z": 1,
      "name": "Rock_Stone"
    },
    {
      "x": -1,
      "y": 21,
      "z": 1,
      "name": "Soil_Dirt"
    },
    {
      "x": -1,
      "y": 22,
      "z": 1,
      "name": "Soil_Grass"
    },
    {
      "x": -1,
      "y": 23,
      "z": 1,
      "name": "Plant_Moss_Rug_Green"
    },
    {
      "x": -1,
      "y": 34,
      "z": 1,
      "name": "Wood_Ash_Trunk_Full",
      "support": 15
    },
    {
      "x": -1,
      "y": 39,
      "z": 1,
      "name": "Plant_Leaves_Ash",
      "support": 15
    },
    {
      "x": -1,
      "y": 17,
      "z": 2,
      "name": "Rock_Stone"
    },
    {
      "x": -1,
      "y": 18,
      "z": 2,
      "name": "Rock_Stone"
    },
    {
      "x": -1,
      "y": 19,
      "z": 2,
      "name": "Rock_Stone"
    },
    {
      "x": -1,
      "y": 20,
      "z": 2,
      "name": "Soil_Dirt"
    },
    {
      "x": -1,
      "y": 21,
      "z": 2,
      "name": "Soil_Dirt"
    },
    {
      "x": -1,
      "y": 22,
      "z": 2,
      "name": "Soil_Dirt"
    },
    {
      "x": -1,
      "y": 23,
      "z": 2,
      "name": "Soil_Grass"
    },
    {
      "x": -1,
      "y": 34,
      "z": 2,
      "name": "Wood_Ash_Trunk_Full",
      "support": 15
    },
    {
      "x": -1,
      "y": 35,
      "z": 2,
      "name": "Wood_Ash_Trunk",
      "support": 15
    },
    {
      "x": -1,
      "y": 36,
      "z": 2,
      "name": "Wood_Ash_Trunk_Full",
      "support": 15
    },
    {
      "x": -1,
      "y": 38,
      "z": 2,
      "name": "Plant_Leaves_Ash",
      "support": 15
    },
    {
      "x": -1,
      "y": 39,
      "z": 2,
      "name": "Plant_Leaves_Ash",
      "support": 15
    },
    {
      "x": -1,
      "y": 6,
      "z": 3,
      "name": "Rock_Stone"
    },
    {
      "x": -1,
      "y": 7,
      "z": 3,
      "name": "Rock_Stone"
    },
    {
      "x": -1,
      "y": 16,
      "z": 3,
      "name": "Rock_Stone"
    },
    {
      "x": -1,
      "y": 17,
      "z": 3,
      "name": "Rock_Stone"
    },
    {
      "x": -1,
      "y": 18,
      "z": 3,
      "name": "Rock_Stone"
    },
    {
      "x": -1,
      "y": 19,
      "z": 3,
      "name": "Rock_Stone"
    },
    {
      "x": -1,
      "y": 20,
      "z": 3,
      "name": "Rock_Stone"
    },
    {
      "x": -1,
      "y": 21,
      "z": 3,
      "name": "Soil_Dirt"
    },
    {
      "x": -1,
      "y": 22,
      "z": 3,
      "name": "Soil_Dirt"
    },
    {
      "x": -1,
      "y": 23,
      "z": 3,
      "name": "Soil_Grass"
    },
    {
      "x": -1,
      "y": 36,
      "z": 3,
      "name": "Wood_Ash_Trunk_Full",
      "support": 15
    },
    {
      "x": -1,
      "y": 37,
      "z": 3,
      "name": "Wood_Ash_Trunk_Full",
      "support": 15
    },
    {
      "x": -1,
      "y": 38,
      "z": 3,
      "name": "Plant_Leaves_Ash",
      "support": 15
    },
    {
      "x": -1,
      "y": 39,
      "z": 3,
      "name": "Plant_Leaves_Ash",
      "support": 15
    },
    {
      "x": -1,
      "y": 5,
      "z": 4,
      "name": "Rock_Stone"
    },
    {
      "x": -1,
      "y": 6,
      "z": 4,
      "name": "Rock_Stone"
    },
    {
      "x": -1,
      "y": 7,
      "z": 4,
      "name": "Rock_Stone"
    },
    {
      "x": -1,
      "y": 8,
      "z": 4,
      "name": "Rock_Stone"
    },
    {
      "x": -1,
      "y": 16,
      "z": 4,
      "name": "Rock_Stone"
    },
    {
      "x": -1,
      "y": 17,
      "z": 4,
      "name": "Rock_Stone"
    },
    {
      "x": -1,
      "y": 18,
      "z": 4,
      "name": "Rock_Stone"
    },
    {
      "x": -1,
      "y": 19,
      "z": 4,
      "name": "Rock_Stone"
    },
    {
      "x": -1,
      "y": 20,
      "z": 4,
      "name": "Soil_Dirt"
    },
    {
      "x": -1,
      "y": 21,
      "z": 4,
      "name": "Soil_Dirt"
    },
    {
      "x": -1,
      "y": 22,
      "z": 4,
      "name": "Soil_Grass"
    },
    {
      "x": -1,
      "y": 38,
      "z": 4,
      "name": "Plant_Leaves_Ash",
      "support": 15
    },
    {
      "x": -1,
      "y": 39,
      "z": 4,
      "name": "Plant_Leaves_Ash",
      "support": 15
    },
    {
      "x": -1,
      "y": 4,
      "z": 5,
      "name": "Rock_Stone"
    },
    {
      "x": -1,
      "y": 5,
      "z": 5,
      "name": "Rock_Stone"
    },
    {
      "x": -1,
      "y": 6,
      "z": 5,
      "name": "Rock_Stone"
    },
    {
      "x": -1,
      "y": 7,
      "z": 5,
      "name": "Rock_Stone"
    },
    {
      "x": -1,
      "y": 8,
      "z": 5,
      "name": "Rock_Stone"
    },
    {
      "x": -1,
      "y": 16,
      "z": 5,
      "name": "Rock_Stone"
    },
    {
      "x": -1,
      "y": 17,
      "z": 5,
      "name": "Rock_Stone"
    },
    {
      "x": -1,
      "y": 18,
      "z": 5,
      "name": "Rock_Stone"
    },
    {
      "x": -1,
      "y": 19,
      "z": 5,
      "name": "Soil_Dirt"
    },
    {
      "x": -1,
      "y": 20,
      "z": 5,
      "name": "Soil_Dirt"
    },
    {
      "x": -1,
      "y": 21,
      "z": 5,
      "name": "Soil_Dirt"
    },
    {
      "x": -1,
      "y": 22,
      "z": 5,
      "name": "Soil_Grass"
    },
    {
      "x": -1,
      "y": 38,
      "z": 5,
      "name": "Plant_Leaves_Ash",
      "support": 15
    },
    {
      "x": -1,
      "y": 5,
      "z": 6,
      "name": "Rock_Stone"
    },
    {
      "x": -1,
      "y": 6,
      "z": 6,
      "name": "Rock_Stone"
    },
    {
      "x": -1,
      "y": 7,
      "z": 6,
      "name": "Rock_Stone"
    },
    {
      "x": -1,
      "y": 17,
      "z": 6,
      "name": "Rock_Stone"
    },
    {
      "x": -1,
      "y": 18,
      "z": 6,
      "name": "Rock_Stone"
    },
    {
      "x": -1,
      "y": 19,
      "z": 6,
      "name": "Soil_Dirt"
    },
    {
      "x": -1,
      "y": 20,
      "z": 6,
      "name": "Soil_Dirt"
    },
    {
      "x": -1,
      "y": 21,
      "z": 6,
      "name": "Soil_Dirt"
    },
    {
      "x": -1,
      "y": 22,
      "z": 6,
      "name": "Soil_Grass"
    },
    {
      "x": -1,
      "y": 32,
      "z": 6,
      "name": "Wood_Ash_Trunk_Full",
      "support": 15
    },
    {
      "x": -1,
      "y": 35,
      "z": 6,
      "name": "Wood_Ash_Trunk_Full",
      "support": 15
    },
    {
      "x": -1,
      "y": 36,
      "z": 6,
      "name": "Wood_Ash_Trunk_Full",
      "support": 15
    },
    {
      "x": -1,
      "y": 38,
      "z": 6,
      "name": "Plant_Leaves_Ash",
      "support": 15
    },
    {
      "x": -1,
      "y": 5,
      "z": 7,
      "name": "Rock_Stone"
    },
    {
      "x": -1,
      "y": 6,
      "z": 7,
      "name": "Rock_Stone"
    },
    {
      "x": -1,
      "y": 7,
      "z": 7,
      "name": "Rock_Stone"
    },
    {
      "x": -1,
      "y": 19,
      "z": 7,
      "name": "Soil_Dirt"
    },
    {
      "x": -1,
      "y": 20,
      "z": 7,
      "name": "Soil_Grass"
    },
    {
      "x": -1,
      "y": 21,
      "z": 7,
      "name": "Plant_Crop_Mushroom_Flatcap_Green",
      "components": {
        "Components": {
          "FarmingBlock": {}
        }
      }
    },
    {
      "x": -1,
      "y": 36,
      "z": 7,
      "name": "Wood_Ash_Trunk_Full",
      "support": 15
    },
    {
      "x": -1,
      "y": 37,
      "z": 7,
      "name": "Plant_Leaves_Ash",
      "support": 15
    },
    {
      "x": -1,
      "y": 38,
      "z": 7,
      "name": "Plant_Leaves_Ash",
      "support": 15
    },
    {
      "x": -1,
      "y": 37,
      "z": 8,
      "name": "Plant_Leaves_Ash",
      "support": 15
    },
    {
      "x": -1,
      "y": 38,
      "z": 8,
      "name": "Plant_Leaves_Ash",
      "support": 15
    },
    {
      "x": -1,
      "y": 32,
      "z": 9,
      "name": "Plant_Leaves_Ash",
      "support": 15
    },
    {
      "x": -1,
      "y": 36,
      "z": 9,
      "name": "Plant_Leaves_Ash",
      "support": 15
    },
    {
      "x": -1,
      "y": 37,
      "z": 9,
      "name": "Plant_Leaves_Ash",
      "support": 15
    },
    {
      "x": -1,
      "y": 31,
      "z": 10,
      "name": "Plant_Vine_Hanging"
    },
    {
      "x": -1,
      "y": 32,
      "z": 10,
      "name": "Plant_Leaves_Ash",
      "support": 15
    },
    {
      "x": -1,
      "y": 33,
      "z": 10,
      "name": "Plant_Leaves_Ash",
      "support": 15
    },
    {
      "x": -1,
      "y": 35,
      "z": 10,
      "name": "Plant_Leaves_Ash",
      "support": 15
    },
    {
      "x": -1,
      "y": 36,
      "z": 10,
      "name": "Plant_Leaves_Ash",
      "support": 15
    },
    {
      "x": -1,
      "y": 37,
      "z": 10,
      "name": "Plant_Leaves_Ash",
      "support": 15
    },
    {
      "x": -1,
      "y": 31,
      "z": 11,
      "name": "Plant_Leaves_Ash",
      "support": 15
    },
    {
      "x": -1,
      "y": 32,
      "z": 11,
      "name": "Plant_Leaves_Ash",
      "support": 15
    },
    {
      "x": -1,
      "y": 33,
      "z": 11,
      "name": "Plant_Leaves_Ash",
      "support": 15
    },
    {
      "x": 0,
      "y": 29,
      "z": -5,
      "name": "Plant_Leaves_Ash",
      "support": 15
    },
    {
      "x": 0,
      "y": 30,
      "z": -5,
      "name": "Plant_Leaves_Ash",
      "support": 15
    },
    {
      "x": 0,
      "y": 31,
      "z": -5,
      "name": "Plant_Leaves_Ash",
      "support": 15
    },
    {
      "x": 0,
      "y": 30,
      "z": -4,
      "name": "Plant_Leaves_Ash",
      "support": 15
    },
    {
      "x": 0,
      "y": 31,
      "z": -4,
      "name": "Plant_Leaves_Ash",
      "support": 15
    },
    {
      "x": 0,
      "y": 32,
      "z": -4,
      "name": "Plant_Leaves_Ash",
      "support": 15
    },
    {
      "x": 0,
      "y": 34,
      "z": -4,
      "name": "Plant_Leaves_Ash",
      "support": 15
    },
    {
      "x": 0,
      "y": 30,
      "z": -3,
      "name": "Wood_Ash_Trunk_Full",
      "support": 15
    },
    {
      "x": 0,
      "y": 35,
      "z": -3,
      "name": "Plant_Leaves_Ash",
      "support": 15
    },
    {
      "x": 0,
      "y": 30,
      "z": -2,
      "name": "Wood_Ash_Trunk_Full",
      "support": 15
    },
    {
      "x": 0,
      "y": 36,
      "z": -2,
      "name": "Plant_Leaves_Ash",
      "support": 15
    },
    {
      "x": 0,
      "y": 18,
      "z": -1,
      "name": "Rock_Stone"
    },
    {
      "x": 0,
      "y": 19,
      "z": -1,
      "name": "Rock_Stone"
    },
    {
      "x": 0,
      "y": 20,
      "z": -1,
      "name": "Soil_Grass"
    },
    {
      "x": 0,
      "y": 30,
      "z": -1,
      "name": "Wood_Ash_Trunk_Full",
      "support": 15
    },
    {
      "x": 0,
      "y": 34,
      "z": -1,
      "name": "Wood_Ash_Trunk_Full",
      "support": 15
    },
    {
      "x": 0,
      "y": 38,
      "z": -1,
      "name": "Plant_Leaves_Ash",
      "support": 15
    },
    {
      "x": 0,
      "y": 18,
      "z": 0,
      "name": "Rock_Stone"
    },
    {
      "x": 0,
      "y": 19,
      "z": 0,
      "name": "Rock_Stone"
    },
    {
      "x": 0,
      "y": 20,
      "z": 0,
      "name": "Rock_Stone"
    },
    {
      "x": 0,
      "y": 21,
      "z": 0,
      "name": "Soil_Dirt"
    },
    {
      "x": 0,
      "y": 22,
      "z": 0,
      "name": "Soil_Grass"
    },
    {
      "x": 0,
      "y": 29,
      "z": 0,
      "name": "Wood_Ash_Trunk_Full",
      "support": 15
    },
    {
      "x": 0,
      "y": 30,
      "z": 0,
      "name": "Wood_Ash_Trunk_Full",
      "support": 15
    },
    {
      "x": 0,
      "y": 34,
      "z": 0,
      "name": "Wood_Ash_Trunk_Full",
      "support": 15
    },
    {
      "x": 0,
      "y": 38,
      "z": 0,
      "name": "Plant_Leaves_Ash",
      "support": 15
    },
    {
      "x": 0,
      "y": 17,
      "z": 1,
      "name": "Rock_Stone"
    },
    {
      "x": 0,
      "y": 18,
      "z": 1,
      "name": "Rock_Stone"
    },
    {
      "x": 0,
      "y": 19,
      "z": 1,
      "name": "Rock_Stone"
    },
    {
      "x": 0,
      "y": 20,
      "z": 1,
      "name": "Rock_Stone"
    },
    {
      "x": 0,
      "y": 21,
      "z": 1,
      "name": "Soil_Dirt"
    },
    {
      "x": 0,
      "y": 22,
      "z": 1,
      "name": "Soil_Grass"
    },
    {
      "x": 0,
      "y": 34,
      "z": 1,
      "name": "Wood_Ash_Trunk_Full",
      "support": 15
    },
    {
      "x": 0,
      "y": 17,
      "z": 2,
      "name": "Rock_Stone"
    },
    {
      "x": 0,
      "y": 18,
      "z": 2,
      "name": "Rock_Stone"
    },
    {
      "x": 0,
      "y": 19,
      "z": 2,
      "name": "Rock_Stone"
    },
    {
      "x": 0,
      "y": 20,
      "z": 2,
      "name": "Rock_Stone"
    },
    {
      "x": 0,
      "y": 21,
      "z": 2,
      "name": "Wood_Ash_Roots"
    },
    {
      "x": 0,
      "y": 22,
      "z": 2,
      "name": "Wood_Ash_Trunk_Full",
      "support": 15
    },
    {
      "x": 0,
      "y": 23,
      "z": 2,
      "name": "Wood_Ash_Trunk",
      "support": 15
    },
    {
      "x": 0,
      "y": 24,
      "z": 2,
      "name": "Wood_Ash_Trunk_Full",
      "support": 15
    },
    {
      "x": 0,
      "y": 17,
      "z": 3,
      "name": "Rock_Stone"
    },
    {
      "x": 0,
      "y": 18,
      "z": 3,
      "name": "Rock_Stone"
    },
    {
      "x": 0,
      "y": 19,
      "z": 3,
      "name": "Rock_Stone"
    },
    {
      "x": 0,
      "y": 20,
      "z": 3,
      "name": "Rock_Stone"
    },
    {
      "x": 0,
      "y": 21,
      "z": 3,
      "name": "Rock_Stone"
    },
    {
      "x": 0,
      "y": 22,
      "z": 3,
      "name": "Soil_Dirt"
    },
    {
      "x": 0,
      "y": 23,
      "z": 3,
      "name": "Soil_Grass"
    },
    {
      "x": 0,
      "y": 5,
      "z": 4,
      "name": "Rock_Stone"
    },
    {
      "x": 0,
      "y": 6,
      "z": 4,
      "name": "Rock_Stone"
    },
    {
      "x": 0,
      "y": 7,
      "z": 4,
      "name": "Rock_Stone"
    },
    {
      "x": 0,
      "y": 16,
      "z": 4,
      "name": "Rock_Stone"
    },
    {
      "x": 0,
      "y": 17,
      "z": 4,
      "name": "Rock_Stone"
    },
    {
      "x": 0,
      "y": 18,
      "z": 4,
      "name": "Rock_Stone"
    },
    {
      "x": 0,
      "y": 19,
      "z": 4,
      "name": "Rock_Stone"
    },
    {
      "x": 0,
      "y": 20,
      "z": 4,
      "name": "Soil_Dirt"
    },
    {
      "x": 0,
      "y": 21,
      "z": 4,
      "name": "Soil_Dirt"
    },
    {
      "x": 0,
      "y": 22,
      "z": 4,
      "name": "Soil_Dirt"
    },
    {
      "x": 0,
      "y": 23,
      "z": 4,
      "name": "Soil_Grass"
    },
    {
      "x": 0,
      "y": 40,
      "z": 4,
      "name": "Plant_Leaves_Ash",
      "support": 15
    },
    {
      "x": 0,
      "y": 4,
      "z": 5,
      "name": "Rock_Stone"
    },
    {
      "x": 0,
      "y": 5,
      "z": 5,
      "name": "Rock_Stone"
    },
    {
      "x": 0,
      "y": 6,
      "z": 5,
      "name": "Rock_Stone"
    },
    {
      "x": 0,
      "y": 7,
      "z": 5,
      "name": "Rock_Stone"
    },
    {
      "x": 0,
      "y": 17,
      "z": 5,
      "name": "Rock_Stone"
    },
    {
      "x": 0,
      "y": 18,
      "z": 5,
      "name": "Rock_Stone"
    },
    {
      "x": 0,
      "y": 19,
      "z": 5,
      "name": "Rock_Stone"
    },
    {
      "x": 0,
      "y": 20,
      "z": 5,
      "name": "Soil_Dirt"
    },
    {
      "x": 0,
      "y": 21,
      "z": 5,
      "name": "Soil_Dirt"
    },
    {
      "x": 0,
      "y": 22,
      "z": 5,
      "name": "Soil_Dirt"
    },
    {
      "x": 0,
      "y": 23,
      "z": 5,
      "name": "Soil_Grass"
    },
    {
      "x": 0,
      "y": 34,
      "z": 5,
      "name": "Wood_Ash_Trunk_Full",
      "support": 15
    },
    {
      "x": 0,
      "y": 35,
      "z": 5,
      "name": "Wood_Ash_Trunk_Full",
      "support": 15
    },
    {
      "x": 0,
      "y": 39,
      "z": 5,
      "name": "Plant_Leaves_Ash",
      "support": 15
    },
    {
      "x": 0,
      "y": 40,
      "z": 5,
      "name": "Plant_Leaves_Ash",
      "support": 15
    },
    {
      "x": 0,
      "y": 4,
      "z": 6,
      "name": "Rock_Stone"
    },
    {
      "x": 0,
      "y": 5,
      "z": 6,
      "name": "Rock_Stone"
    },
    {
      "x": 0,
      "y": 6,
      "z": 6,
      "name": "Rock_Stone"
    },
    {
      "x": 0,
      "y": 7,
      "z": 6,
      "name": "Rock_Stone"
    },
    {
      "x": 0,
      "y": 18,
      "z": 6,
      "name": "Rock_Stone"
    },
    {
      "x": 0,
      "y": 19,
      "z": 6,
      "name": "Rock_Stone"
    },
    {
      "x": 0,
      "y": 20,
      "z": 6,
      "name": "Soil_Dirt"
    },
    {
      "x": 0,
      "y": 21,
      "z": 6,
      "name": "Soil_Dirt"
    },
    {
      "x": 0,
      "y": 22,
      "z": 6,
      "name": "Soil_Grass"
    },
    {
      "x": 0,
      "y": 32,
      "z": 6,
      "name": "Wood_Ash_Trunk_Full",
      "support": 15
    },
    {
      "x": 0,
      "y": 35,
      "z": 6,
      "name": "Wood_Ash_Trunk_Full",
      "support": 15
    },
    {
      "x": 0,
      "y": 38,
      "z": 6,
      "name": "Plant_Leaves_Ash",
      "support": 15
    },
    {
      "x": 0,
      "y": 39,
      "z": 6,
      "name": "Plant_Leaves_Ash",
      "support": 15
    },
    {
      "x": 0,
      "y": 4,
      "z": 7,
      "name": "Rock_Stone"
    },
    {
      "x": 0,
      "y": 5,
      "z": 7,
      "name": "Rock_Stone"
    },
    {
      "x": 0,
      "y": 19,
      "z": 7,
      "name": "Soil_Dirt"
    },
    {
      "x": 0,
      "y": 20,
      "z": 7,
      "name": "Soil_Dirt"
    },
    {
      "x": 0,
      "y": 21,
      "z": 7,
      "name": "Soil_Grass"
    },
    {
      "x": 0,
      "y": 38,
      "z": 7,
      "name": "Plant_Leaves_Ash",
      "support": 15
    },
    {
      "x": 0,
      "y": 38,
      "z": 8,
      "name": "Plant_Leaves_Ash",
      "support": 15
    },
    {
      "x": 0,
      "y": 32,
      "z": 9,
      "name": "Plant_Leaves_Ash",
      "support": 15
    },
    {
      "x": 0,
      "y": 36,
      "z": 9,
      "name": "Plant_Leaves_Ash",
      "support": 15
    },
    {
      "x": 0,
      "y": 32,
      "z": 10,
      "name": "Plant_Leaves_Ash",
      "support": 15
    },
    {
      "x": 0,
      "y": 35,
      "z": 10,
      "name": "Plant_Leaves_Ash",
      "support": 15
    },
    {
      "x": 0,
      "y": 32,
      "z": 11,
      "name": "Plant_Leaves_Ash",
      "support": 15
    },
    {
      "x": 0,
      "y": 33,
      "z": 11,
      "name": "Plant_Leaves_Ash",
      "support": 15
    },
    {
      "x": 0,
      "y": 34,
      "z": 11,
      "name": "Plant_Leaves_Ash",
      "support": 15
    },
    {
      "x": 0,
      "y": 30,
      "z": 12,
      "name": "Plant_Leaves_Ash",
      "support": 15
    },
    {
      "x": 0,
      "y": 31,
      "z": 12,
      "name": "Plant_Leaves_Ash",
      "support": 15
    },
    {
      "x": 0,
      "y": 32,
      "z": 12,
      "name": "Plant_Leaves_Ash",
      "support": 15
    },
    {
      "x": 0,
      "y": 33,
      "z": 12,
      "name": "Plant_Leaves_Ash",
      "support": 15
    },
    {
      "x": 1,
      "y": 31,
      "z": -5,
      "name": "Plant_Leaves_Ash",
      "support": 15
    },
    {
      "x": 1,
      "y": 30,
      "z": -4,
      "name": "Plant_Leaves_Ash",
      "support": 15
    },
    {
      "x": 1,
      "y": 31,
      "z": -4,
      "name": "Plant_Leaves_Ash",
      "support": 15
    },
    {
      "x": 1,
      "y": 36,
      "z": -3,
      "name": "Plant_Leaves_Ash",
      "support": 15
    },
    {
      "x": 1,
      "y": 37,
      "z": -3,
      "name": "Plant_Leaves_Ash",
      "support": 15
    },
    {
      "x": 1,
      "y": 37,
      "z": -2,
      "name": "Plant_Leaves_Ash",
      "support": 15
    },
    {
      "x": 1,
      "y": 38,
      "z": -2,
      "name": "Plant_Leaves_Ash",
      "support": 15
    },
    {
      "x": 1,
      "y": 18,
      "z": -1,
      "name": "Rock_Stone"
    },
    {
      "x": 1,
      "y": 19,
      "z": -1,
      "name": "Rock_Stone"
    },
    {
      "x": 1,
      "y": 20,
      "z": -1,
      "name": "Rock_Stone"
    },
    {
      "x": 1,
      "y": 21,
      "z": -1,
      "name": "Soil_Grass"
    },
    {
      "x": 1,
      "y": 37,
      "z": -1,
      "name": "Plant_Leaves_Ash",
      "support": 15
    },
    {
      "x": 1,
      "y": 38,
      "z": -1,
      "name": "Plant_Leaves_Ash",
      "support": 15
    },
    {
      "x": 1,
      "y": 39,
      "z": -1,
      "name": "Plant_Leaves_Ash",
      "support": 15
    },
    {
      "x": 1,
      "y": 18,
      "z": 0,
      "name": "Rock_Stone"
    },
    {
      "x": 1,
      "y": 19,
      "z": 0,
      "name": "Rock_Stone"
    },
    {
      "x": 1,
      "y": 20,
      "z": 0,
      "name": "Soil_Dirt"
    },
    {
      "x": 1,
      "y": 21,
      "z": 0,
      "name": "Soil_Dirt"
    },
    {
      "x": 1,
      "y": 22,
      "z": 0,
      "name": "Soil_Dirt"
    },
    {
      "x": 1,
      "y": 23,
      "z": 0,
      "name": "Soil_Grass"
    },
    {
      "x": 1,
      "y": 29,
      "z": 0,
      "name": "Wood_Ash_Trunk_Full",
      "support": 15
    },
    {
      "x": 1,
      "y": 34,
      "z": 0,
      "name": "Wood_Ash_Trunk_Full",
      "support": 15
    },
    {
      "x": 1,
      "y": 38,
      "z": 0,
      "name": "Plant_Leaves_Ash",
      "support": 15
    },
    {
      "x": 1,
      "y": 39,
      "z": 0,
      "name": "Plant_Leaves_Ash",
      "support": 15
    },
    {
      "x": 1,
      "y": 18,
      "z": 1,
      "name": "Rock_Stone"
    },
    {
      "x": 1,
      "y": 19,
      "z": 1,
      "name": "Rock_Stone"
    },
    {
      "x": 1,
      "y": 20,
      "z": 1,
      "name": "Rock_Stone"
    },
    {
      "x": 1,
      "y": 21,
      "z": 1,
      "name": "Soil_Dirt"
    },
    {
      "x": 1,
      "y": 22,
      "z": 1,
      "name": "Soil_Dirt"
    },
    {
      "x": 1,
      "y": 23,
      "z": 1,
      "name": "Soil_Grass"
    },
    {
      "x": 1,
      "y": 29,
      "z": 1,
      "name": "Wood_Ash_Trunk_Full",
      "support": 15
    },
    {
      "x": 1,
      "y": 17,
      "z": 2,
      "name": "Rock_Stone"
    },
    {
      "x": 1,
      "y": 18,
      "z": 2,
      "name": "Rock_Stone"
    },
    {
      "x": 1,
      "y": 19,
      "z": 2,
      "name": "Rock_Stone"
    },
    {
      "x": 1,
      "y": 20,
      "z": 2,
      "name": "Rock_Stone"
    },
    {
      "x": 1,
      "y": 21,
      "z": 2,
      "name": "Soil_Dirt"
    },
    {
      "x": 1,
      "y": 22,
      "z": 2,
      "name": "Soil_Dirt"
    },
    {
      "x": 1,
      "y": 23,
      "z": 2,
      "name": "Wood_Ash_Roots"
    },
    {
      "x": 1,
      "y": 24,
      "z": 2,
      "name": "Wood_Ash_Trunk_Full",
      "support": 15
    },
    {
      "x": 1,
      "y": 25,
      "z": 2,
      "name": "Wood_Ash_Trunk",
      "support": 15
    },
    {
      "x": 1,
      "y": 26,
      "z": 2,
      "name": "Wood_Ash_Trunk_Full",
      "support": 15
    },
    {
      "x": 1,
      "y": 17,
      "z": 3,
      "name": "Rock_Stone"
    },
    {
      "x": 1,
      "y": 18,
      "z": 3,
      "name": "Rock_Stone"
    },
    {
      "x": 1,
      "y": 19,
      "z": 3,
      "name": "Rock_Stone"
    },
    {
      "x": 1,
      "y": 20,
      "z": 3,
      "name": "Rock_Stone"
    },
    {
      "x": 1,
      "y": 21,
      "z": 3,
      "name": "Soil_Pathway"
    },
    {
      "x": 1,
      "y": 22,
      "z": 3,
      "name": "Soil_Pathway"
    },
    {
      "x": 1,
      "y": 23,
      "z": 3,
      "name": "Soil_Grass"
    },
    {
      "x": 1,
      "y": 40,
      "z": 3,
      "name": "Plant_Leaves_Ash",
      "support": 15
    },
    {
      "x": 1,
      "y": 41,
      "z": 3,
      "name": "Plant_Leaves_Ash",
      "support": 15
    },
    {
      "x": 1,
      "y": 17,
      "z": 4,
      "name": "Rock_Stone"
    },
    {
      "x": 1,
      "y": 18,
      "z": 4,
      "name": "Rock_Stone"
    },
    {
      "x": 1,
      "y": 19,
      "z": 4,
      "name": "Rock_Stone"
    },
    {
      "x": 1,
      "y": 20,
      "z": 4,
      "name": "Rock_Stone"
    },
    {
      "x": 1,
      "y": 21,
      "z": 4,
      "name": "Soil_Dirt"
    },
    {
      "x": 1,
      "y": 22,
      "z": 4,
      "name": "Soil_Dirt"
    },
    {
      "x": 1,
      "y": 23,
      "z": 4,
      "name": "Soil_Grass"
    },
    {
      "x": 1,
      "y": 26,
      "z": 4,
      "name": "Wood_Ash_Trunk_Full",
      "support": 15
    },
    {
      "x": 1,
      "y": 40,
      "z": 4,
      "name": "Plant_Leaves_Ash",
      "support": 15
    },
    {
      "x": 1,
      "y": 41,
      "z": 4,
      "name": "Plant_Leaves_Ash",
      "support": 15
    },
    {
      "x": 1,
      "y": 4,
      "z": 5,
      "name": "Rock_Stone"
    },
    {
      "x": 1,
      "y": 5,
      "z": 5,
      "name": "Rock_Stone"
    },
    {
      "x": 1,
      "y": 6,
      "z": 5,
      "name": "Rock_Stone"
    },
    {
      "x": 1,
      "y": 17,
      "z": 5,
      "name": "Rock_Stone"
    },
    {
      "x": 1,
      "y": 18,
      "z": 5,
      "name": "Rock_Stone"
    },
    {
      "x": 1,
      "y": 19,
      "z": 5,
      "name": "Rock_Stone"
    },
    {
      "x": 1,
      "y": 20,
      "z": 5,
      "name": "Soil_Dirt"
    },
    {
      "x": 1,
      "y": 21,
      "z": 5,
      "name": "Soil_Dirt"
    },
    {
      "x": 1,
      "y": 22,
      "z": 5,
      "name": "Soil_Dirt"
    },
    {
      "x": 1,
      "y": 23,
      "z": 5,
      "name": "Wood_Ash_Roots"
    },
    {
      "x": 1,
      "y": 24,
      "z": 5,
      "name": "Wood_Ash_Trunk_Full",
      "support": 15
    },
    {
      "x": 1,
      "y": 25,
      "z": 5,
      "name": "Wood_Ash_Trunk",
      "support": 15
    },
    {
      "x": 1,
      "y": 26,
      "z": 5,
      "name": "Wood_Ash_Trunk_Full",
      "support": 15
    },
    {
      "x": 1,
      "y": 30,
      "z": 5,
      "name": "Wood_Ash_Trunk_Full",
      "support": 15
    },
    {
      "x": 1,
      "y": 31,
      "z": 5,
      "name": "Wood_Ash_Trunk_Full",
      "support": 15
    },
    {
      "x": 1,
      "y": 32,
      "z": 5,
      "name": "Wood_Ash_Trunk",
      "support": 15
    },
    {
      "x": 1,
      "y": 33,
      "z": 5,
      "name": "Wood_Ash_Trunk",
      "support": 15
    },
    {
      "x": 1,
      "y": 34,
      "z": 5,
      "name": "Wood_Ash_Trunk_Full",
      "support": 15
    },
    {
      "x": 1,
      "y": 39,
      "z": 5,
      "name": "Plant_Leaves_Ash",
      "support": 15
    },
    {
      "x": 1,
      "y": 40,
      "z": 5,
      "name": "Plant_Leaves_Ash",
      "support": 15
    },
    {
      "x": 1,
      "y": 5,
      "z": 6,
      "name": "Rock_Stone"
    },
    {
      "x": 1,
      "y": 18,
      "z": 6,
      "name": "Rock_Stone"
    },
    {
      "x": 1,
      "y": 19,
      "z": 6,
      "name": "Rock_Stone"
    },
    {
      "x": 1,
      "y": 20,
      "z": 6,
      "name": "Soil_Dirt"
    },
    {
      "x": 1,
      "y": 21,
      "z": 6,
      "name": "Soil_Dirt"
    },
    {
      "x": 1,
      "y": 22,
      "z": 6,
      "name": "Wood_Ash_Roots"
    },
    {
      "x": 1,
      "y": 23,
      "z": 6,
      "name": "Wood_Ash_Trunk_Full",
      "support": 15
    },
    {
      "x": 1,
      "y": 24,
      "z": 6,
      "name": "Wood_Ash_Trunk_Full",
      "support": 15
    },
    {
      "x": 1,
      "y": 32,
      "z": 6,
      "name": "Wood_Ash_Trunk_Full",
      "support": 15
    },
    {
      "x": 1,
      "y": 39,
      "z": 6,
      "name": "Plant_Leaves_Ash",
      "support": 15
    },
    {
      "x": 1,
      "y": 40,
      "z": 6,
      "name": "Plant_Leaves_Ash",
      "support": 15
    },
    {
      "x": 1,
      "y": 5,
      "z": 7,
      "name": "Rock_Stone"
    },
    {
      "x": 1,
      "y": 18,
      "z": 7,
      "name": "Rock_Stone"
    },
    {
      "x": 1,
      "y": 19,
      "z": 7,
      "name": "Rock_Stone"
    },
    {
      "x": 1,
      "y": 20,
      "z": 7,
      "name": "Soil_Dirt"
    },
    {
      "x": 1,
      "y": 21,
      "z": 7,
      "name": "Soil_Dirt"
    },
    {
      "x": 1,
      "y": 22,
      "z": 7,
      "name": "Soil_Grass"
    },
    {
      "x": 1,
      "y": 32,
      "z": 7,
      "name": "Wood_Ash_Trunk_Full",
      "support": 15
    },
    {
      "x": 1,
      "y": 20,
      "z": 8,
      "name": "Soil_Dirt"
    },
    {
      "x": 1,
      "y": 21,
      "z": 8,
      "name": "Soil_Grass"
    },
    {
      "x": 1,
      "y": 32,
      "z": 8,
      "name": "Wood_Ash_Trunk_Full",
      "support": 15
    },
    {
      "x": 1,
      "y": 36,
      "z": 8,
      "name": "Plant_Leaves_Ash",
      "support": 15
    },
    {
      "x": 1,
      "y": 32,
      "z": 9,
      "name": "Wood_Ash_Trunk_Full",
      "support": 15
    },
    {
      "x": 1,
      "y": 35,
      "z": 9,
      "name": "Plant_Leaves_Ash",
      "support": 15
    },
    {
      "x": 1,
      "y": 36,
      "z": 9,
      "name": "Plant_Leaves_Ash",
      "support": 15
    },
    {
      "x": 1,
      "y": 37,
      "z": 9,
      "name": "Plant_Leaves_Ash",
      "support": 15
    },
    {
      "x": 1,
      "y": 32,
      "z": 10,
      "name": "Wood_Ash_Trunk_Full",
      "support": 15
    },
    {
      "x": 1,
      "y": 33,
      "z": 10,
      "name": "Plant_Leaves_Ash",
      "support": 15
    },
    {
      "x": 1,
      "y": 34,
      "z": 10,
      "name": "Plant_Leaves_Ash",
      "support": 15
    },
    {
      "x": 1,
      "y": 35,
      "z": 10,
      "name": "Plant_Leaves_Ash",
      "support": 15
    },
    {
      "x": 1,
      "y": 36,
      "z": 10,
      "name": "Plant_Leaves_Ash",
      "support": 15
    },
    {
      "x": 1,
      "y": 32,
      "z": 11,
      "name": "Wood_Ash_Trunk_Full",
      "support": 15
    },
    {
      "x": 1,
      "y": 33,
      "z": 11,
      "name": "Plant_Leaves_Ash",
      "support": 15
    },
    {
      "x": 1,
      "y": 34,
      "z": 11,
      "name": "Plant_Leaves_Ash",
      "support": 15
    },
    {
      "x": 1,
      "y": 31,
      "z": 12,
      "name": "Plant_Vine_Hanging"
    },
    {
      "x": 1,
      "y": 32,
      "z": 12,
      "name": "Plant_Leaves_Ash",
      "support": 15
    },
    {
      "x": 1,
      "y": 33,
      "z": 12,
      "name": "Plant_Leaves_Ash",
      "support": 15
    },
    {
      "x": 2,
      "y": 31,
      "z": -6,
      "name": "Plant_Leaves_Ash",
      "support": 15
    },
    {
      "x": 2,
      "y": 31,
      "z": -5,
      "name": "Plant_Leaves_Ash",
      "support": 15
    },
    {
      "x": 2,
      "y": 37,
      "z": -3,
      "name": "Plant_Leaves_Ash",
      "support": 15
    },
    {
      "x": 2,
      "y": 38,
      "z": -3,
      "name": "Plant_Leaves_Ash",
      "support": 15
    },
    {
      "x": 2,
      "y": 37,
      "z": -2,
      "name": "Plant_Leaves_Ash",
      "support": 15
    },
    {
      "x": 2,
      "y": 38,
      "z": -2,
      "name": "Plant_Leaves_Ash",
      "support": 15
    },
    {
      "x": 2,
      "y": 39,
      "z": -2,
      "name": "Plant_Leaves_Ash",
      "support": 15
    },
    {
      "x": 2,
      "y": 19,
      "z": -1,
      "name": "Rock_Stone"
    },
    {
      "x": 2,
      "y": 20,
      "z": -1,
      "name": "Rock_Stone"
    },
    {
      "x": 2,
      "y": 21,
      "z": -1,
      "name": "Soil_Grass"
    },
    {
      "x": 2,
      "y": 37,
      "z": -1,
      "name": "Wood_Ash_Trunk_Full",
      "support": 15
    },
    {
      "x": 2,
      "y": 38,
      "z": -1,
      "name": "Wood_Ash_Trunk_Full",
      "support": 15
    },
    {
      "x": 2,
      "y": 39,
      "z": -1,
      "name": "Plant_Leaves_Ash",
      "support": 15
    },
    {
      "x": 2,
      "y": 18,
      "z": 0,
      "name": "Rock_Stone"
    },
    {
      "x": 2,
      "y": 19,
      "z": 0,
      "name": "Rock_Stone"
    },
    {
      "x": 2,
      "y": 20,
      "z": 0,
      "name": "Rock_Stone"
    },
    {
      "x": 2,
      "y": 21,
      "z": 0,
      "name": "Soil_Dirt"
    },
    {
      "x": 2,
      "y": 22,
      "z": 0,
      "name": "Soil_Grass"
    },
    {
      "x": 2,
      "y": 29,
      "z": 0,
      "name": "Plant_Vine_Liana",
      "rotation": 2
    },
    {
      "x": 2,
      "y": 30,
      "z": 0,
      "name": "Plant_Vine_Liana",
      "rotation": 2
    },
    {
      "x": 2,
      "y": 33,
      "z": 0,
      "name": "Wood_Ash_Trunk_Full",
      "support": 15
    },
    {
      "x": 2,
      "y": 34,
      "z": 0,
      "name": "Wood_Ash_Trunk",
      "support": 15
    },
    {
      "x": 2,
      "y": 35,
      "z": 0,
      "name": "Wood_Ash_Trunk",
      "support": 15
    },
    {
      "x": 2,
      "y": 36,
      "z": 0,
      "name": "Wood_Ash_Trunk",
      "support": 15
    },
    {
      "x": 2,
      "y": 37,
      "z": 0,
      "name": "Wood_Ash_Trunk_Full",
      "support": 15
    },
    {
      "x": 2,
      "y": 38,
      "z": 0,
      "name": "Plant_Leaves_Ash",
      "support": 15
    },
    {
      "x": 2,
      "y": 39,
      "z": 0,
      "name": "Plant_Leaves_Ash",
      "support": 15
    },
    {
      "x": 2,
      "y": 18,
      "z": 1,
      "name": "Rock_Stone"
    },
    {
      "x": 2,
      "y": 19,
      "z": 1,
      "name": "Rock_Stone"
    },
    {
      "x": 2,
      "y": 20,
      "z": 1,
      "name": "Rock_Stone"
    },
    {
      "x": 2,
      "y": 21,
      "z": 1,
      "name": "Soil_Pathway"
    },
    {
      "x": 2,
      "y": 22,
      "z": 1,
      "name": "Soil_Pathway"
    },
    {
      "x": 2,
      "y": 23,
      "z": 1,
      "name": "Soil_Grass"
    },
    {
      "x": 2,
      "y": 27,
      "z": 1,
      "name": "Wood_Ash_Trunk_Full",
      "support": 15
    },
    {
      "x": 2,
      "y": 28,
      "z": 1,
      "name": "Wood_Ash_Trunk",
      "support": 15
    },
    {
      "x": 2,
      "y": 29,
      "z": 1,
      "name": "Wood_Ash_Trunk",
      "support": 15
    },
    {
      "x": 2,
      "y": 30,
      "z": 1,
      "name": "Wood_Ash_Trunk",
      "support": 15
    },
    {
      "x": 2,
      "y": 31,
      "z": 1,
      "name": "Wood_Ash_Trunk",
      "support": 15
    },
    {
      "x": 2,
      "y": 32,
      "z": 1,
      "name": "Wood_Ash_Trunk",
      "support": 15
    },
    {
      "x": 2,
      "y": 33,
      "z": 1,
      "name": "Wood_Ash_Trunk_Full",
      "support": 15
    },
    {
      "x": 2,
      "y": 17,
      "z": 2,
      "name": "Rock_Stone"
    },
    {
      "x": 2,
      "y": 18,
      "z": 2,
      "name": "Rock_Stone"
    },
    {
      "x": 2,
      "y": 19,
      "z": 2,
      "name": "Rock_Stone"
    },
    {
      "x": 2,
      "y": 20,
      "z": 2,
      "name": "Rock_Stone"
    },
    {
      "x": 2,
      "y": 21,
      "z": 2,
      "name": "Soil_Dirt"
    },
    {
      "x": 2,
      "y": 22,
      "z": 2,
      "name": "Soil_Dirt"
    },
    {
      "x": 2,
      "y": 23,
      "z": 2,
      "name": "Soil_Grass"
    },
    {
      "x": 2,
      "y": 25,
      "z": 2,
      "name": "Wood_Ash_Roots"
    },
    {
      "x": 2,
      "y": 26,
      "z": 2,
      "name": "Wood_Ash_Trunk_Full",
      "support": 15
    },
    {
      "x": 2,
      "y": 27,
      "z": 2,
      "name": "Wood_Ash_Trunk",
      "support": 15
    },
    {
      "x": 2,
      "y": 28,
      "z": 2,
      "name": "Wood_Ash_Trunk_Full",
      "support": 15
    },
    {
      "x": 2,
      "y": 17,
      "z": 3,
      "name": "Rock_Stone"
    },
    {
      "x": 2,
      "y": 18,
      "z": 3,
      "name": "Rock_Stone"
    },
    {
      "x": 2,
      "y": 19,
      "z": 3,
      "name": "Rock_Stone"
    },
    {
      "x": 2,
      "y": 20,
      "z": 3,
      "name": "Rock_Stone"
    },
    {
      "x": 2,
      "y": 21,
      "z": 3,
      "name": "Rock_Stone"
    },
    {
      "x": 2,
      "y": 22,
      "z": 3,
      "name": "Soil_Dirt"
    },
    {
      "x": 2,
      "y": 23,
      "z": 3,
      "name": "Soil_Grass"
    },
    {
      "x": 2,
      "y": 24,
      "z": 3,
      "name": "Plant_Crop_Mushroom_Flatcap_Green",
      "components": {
        "Components": {
          "FarmingBlock": {}
        }
      }
    },
    {
      "x": 2,
      "y": 26,
      "z": 3,
      "name": "Wood_Ash_Trunk_Full",
      "support": 15
    },
    {
      "x": 2,
      "y": 40,
      "z": 3,
      "name": "Plant_Leaves_Ash",
      "support": 15
    },
    {
      "x": 2,
      "y": 17,
      "z": 4,
      "name": "Rock_Stone"
    },
    {
      "x": 2,
      "y": 18,
      "z": 4,
      "name": "Rock_Stone"
    },
    {
      "x": 2,
      "y": 19,
      "z": 4,
      "name": "Rock_Stone"
    },
    {
      "x": 2,
      "y": 20,
      "z": 4,
      "name": "Rock_Stone"
    },
    {
      "x": 2,
      "y": 21,
      "z": 4,
      "name": "Soil_Dirt"
    },
    {
      "x": 2,
      "y": 22,
      "z": 4,
      "name": "Soil_Dirt"
    },
    {
      "x": 2,
      "y": 23,
      "z": 4,
      "name": "Soil_Grass"
    },
    {
      "x": 2,
      "y": 25,
      "z": 4,
      "name": "Wood_Ash_Roots"
    },
    {
      "x": 2,
      "y": 26,
      "z": 4,
      "name": "Wood_Ash_Trunk_Full",
      "support": 15
    },
    {
      "x": 2,
      "y": 27,
      "z": 4,
      "name": "Wood_Ash_Trunk",
      "support": 15
    },
    {
      "x": 2,
      "y": 28,
      "z": 4,
      "name": "Wood_Ash_Trunk",
      "support": 15
    },
    {
      "x": 2,
      "y": 29,
      "z": 4,
      "name": "Wood_Ash_Trunk",
      "support": 15
    },
    {
      "x": 2,
      "y": 30,
      "z": 4,
      "name": "Wood_Ash_Trunk_Full",
      "support": 15
    },
    {
      "x": 2,
      "y": 35,
      "z": 4,
      "name": "Wood_Ash_Trunk_Full",
      "support": 15
    },
    {
      "x": 2,
      "y": 36,
      "z": 4,
      "name": "Wood_Ash_Trunk",
      "support": 15
    },
    {
      "x": 2,
      "y": 37,
      "z": 4,
      "name": "Wood_Ash_Trunk",
      "support": 15
    },
    {
      "x": 2,
      "y": 38,
      "z": 4,
      "name": "Wood_Ash_Trunk",
      "support": 15
    },
    {
      "x": 2,
      "y": 39,
      "z": 4,
      "name": "Wood_Ash_Trunk",
      "support": 15
    },
    {
      "x": 2,
      "y": 40,
      "z": 4,
      "name": "Wood_Ash_Trunk",
      "support": 15
    },
    {
      "x": 2,
      "y": 41,
      "z": 4,
      "name": "Plant_Leaves_Ash",
      "support": 15
    },
    {
      "x": 2,
      "y": 17,
      "z": 5,
      "name": "Rock_Stone"
    },
    {
      "x": 2,
      "y": 18,
      "z": 5,
      "name": "Rock_Stone"
    },
    {
      "x": 2,
      "y": 19,
      "z": 5,
      "name": "Rock_Stone"
    },
    {
      "x": 2,
      "y": 20,
      "z": 5,
      "name": "Rock_Stone"
    },
    {
      "x": 2,
      "y": 21,
      "z": 5,
      "name": "Soil_Dirt"
    },
    {
      "x": 2,
      "y": 22,
      "z": 5,
      "name": "Soil_Dirt"
    },
    {
      "x": 2,
      "y": 23,
      "z": 5,
      "name": "Soil_Grass"
    },
    {
      "x": 2,
      "y": 25,
      "z": 5,
      "name": "Wood_Ash_Roots"
    },
    {
      "x": 2,
      "y": 26,
      "z": 5,
      "name": "Wood_Ash_Trunk_Full",
      "support": 15
    },
    {
      "x": 2,
      "y": 27,
      "z": 5,
      "name": "Plant_Vine_Liana"
    },
    {
      "x": 2,
      "y": 29,
      "z": 5,
      "name": "Plant_Vine_Wall"
    },
    {
      "x": 2,
      "y": 30,
      "z": 5,
      "name": "Wood_Ash_Trunk_Full",
      "support": 15
    },
    {
      "x": 2,
      "y": 31,
      "z": 5,
      "name": "Wood_Ash_Trunk_Full",
      "support": 15
    },
    {
      "x": 2,
      "y": 34,
      "z": 5,
      "name": "Wood_Ash_Trunk_Full",
      "support": 15
    },
    {
      "x": 2,
      "y": 35,
      "z": 5,
      "name": "Wood_Ash_Trunk_Full",
      "support": 15
    },
    {
      "x": 2,
      "y": 39,
      "z": 5,
      "name": "Plant_Leaves_Ash",
      "support": 15
    },
    {
      "x": 2,
      "y": 40,
      "z": 5,
      "name": "Plant_Leaves_Ash",
      "support": 15
    },
    {
      "x": 2,
      "y": 41,
      "z": 5,
      "name": "Plant_Leaves_Ash",
      "support": 15
    },
    {
      "x": 2,
      "y": 17,
      "z": 6,
      "name": "Rock_Stone"
    },
    {
      "x": 2,
      "y": 18,
      "z": 6,
      "name": "Rock_Stone"
    },
    {
      "x": 2,
      "y": 19,
      "z": 6,
      "name": "Rock_Stone"
    },
    {
      "x": 2,
      "y": 20,
      "z": 6,
      "name": "Rock_Stone"
    },
    {
      "x": 2,
      "y": 21,
      "z": 6,
      "name": "Soil_Dirt"
    },
    {
      "x": 2,
      "y": 22,
      "z": 6,
      "name": "Soil_Grass"
    },
    {
      "x": 2,
      "y": 23,
      "z": 6,
      "name": "Plant_Moss_Rug_Green"
    },
    {
      "x": 2,
      "y": 31,
      "z": 6,
      "name": "Wood_Ash_Trunk_Full",
      "support": 15
    },
    {
      "x": 2,
      "y": 35,
      "z": 6,
      "name": "Wood_Ash_Trunk_Full",
      "support": 15
    },
    {
      "x": 2,
      "y": 39,
      "z": 6,
      "name": "Plant_Leaves_Ash",
      "support": 15
    },
    {
      "x": 2,
      "y": 40,
      "z": 6,
      "name": "Plant_Leaves_Ash",
      "support": 15
    },
    {
      "x": 2,
      "y": 18,
      "z": 7,
      "name": "Rock_Stone"
    },
    {
      "x": 2,
      "y": 19,
      "z": 7,
      "name": "Rock_Stone"
    },
    {
      "x": 2,
      "y": 20,
      "z": 7,
      "name": "Soil_Dirt"
    },
    {
      "x": 2,
      "y": 21,
      "z": 7,
      "name": "Soil_Dirt"
    },
    {
      "x": 2,
      "y": 22,
      "z": 7,
      "name": "Soil_Grass"
    },
    {
      "x": 2,
      "y": 23,
      "z": 7,
      "name": "Plant_Moss_Rug_Green"
    },
    {
      "x": 2,
      "y": 35,
      "z": 7,
      "name": "Wood_Ash_Trunk_Full",
      "support": 15
    },
    {
      "x": 2,
      "y": 36,
      "z": 7,
      "name": "Wood_Ash_Trunk_Full",
      "support": 15
    },
    {
      "x": 2,
      "y": 39,
      "z": 7,
      "name": "Plant_Leaves_Ash",
      "support": 15
    },
    {
      "x": 2,
      "y": 20,
      "z": 8,
      "name": "Soil_Dirt"
    },
    {
      "x": 2,
      "y": 21,
      "z": 8,
      "name": "Soil_Grass"
    },
    {
      "x": 2,
      "y": 36,
      "z": 8,
      "name": "Wood_Ash_Trunk_Full",
      "support": 15
    },
    {
      "x": 2,
      "y": 37,
      "z": 8,
      "name": "Plant_Leaves_Ash",
      "support": 15
    },
    {
      "x": 2,
      "y": 35,
      "z": 9,
      "name": "Plant_Leaves_Ash",
      "support": 15
    },
    {
      "x": 2,
      "y": 36,
      "z": 9,
      "name": "Wood_Ash_Trunk_Full",
      "support": 15
    },
    {
      "x": 2,
      "y": 37,
      "z": 9,
      "name": "Plant_Leaves_Ash",
      "support": 15
    },
    {
      "x": 2,
      "y": 32,
      "z": 10,
      "name": "Plant_Leaves_Ash",
      "support": 15
    },
    {
      "x": 2,
      "y": 33,
      "z": 10,
      "name": "Plant_Leaves_Ash",
      "support": 15
    },
    {
      "x": 2,
      "y": 35,
      "z": 10,
      "name": "Plant_Leaves_Ash",
      "support": 15
    },
    {
      "x": 2,
      "y": 36,
      "z": 10,
      "name": "Plant_Leaves_Ash",
      "support": 15
    },
    {
      "x": 2,
      "y": 37,
      "z": 10,
      "name": "Plant_Leaves_Ash",
      "support": 15
    },
    {
      "x": 2,
      "y": 31,
      "z": 11,
      "name": "Plant_Leaves_Ash",
      "support": 15
    },
    {
      "x": 2,
      "y": 32,
      "z": 11,
      "name": "Plant_Leaves_Ash",
      "support": 15
    },
    {
      "x": 2,
      "y": 33,
      "z": 11,
      "name": "Plant_Leaves_Ash",
      "support": 15
    },
    {
      "x": 2,
      "y": 32,
      "z": 12,
      "name": "Plant_Leaves_Ash",
      "support": 15
    },
    {
      "x": 3,
      "y": 30,
      "z": -6,
      "name": "Plant_Leaves_Ash",
      "support": 15
    },
    {
      "x": 3,
      "y": 31,
      "z": -6,
      "name": "Plant_Leaves_Ash",
      "support": 15
    },
    {
      "x": 3,
      "y": 29,
      "z": -5,
      "name": "Plant_Leaves_Ash",
      "support": 15
    },
    {
      "x": 3,
      "y": 30,
      "z": -5,
      "name": "Plant_Leaves_Ash",
      "support": 15
    },
    {
      "x": 3,
      "y": 31,
      "z": -5,
      "name": "Plant_Leaves_Ash",
      "support": 15
    },
    {
      "x": 3,
      "y": 32,
      "z": -5,
      "name": "Plant_Leaves_Ash",
      "support": 15
    },
    {
      "x": 3,
      "y": 32,
      "z": -4,
      "name": "Plant_Leaves_Ash",
      "support": 15
    },
    {
      "x": 3,
      "y": 35,
      "z": -3,
      "name": "Plant_Leaves_Ash",
      "support": 15
    },
    {
      "x": 3,
      "y": 36,
      "z": -3,
      "name": "Plant_Leaves_Ash",
      "support": 15
    },
    {
      "x": 3,
      "y": 37,
      "z": -3,
      "name": "Plant_Leaves_Ash",
      "support": 15
    },
    {
      "x": 3,
      "y": 38,
      "z": -2,
      "name": "Plant_Leaves_Ash",
      "support": 15
    },
    {
      "x": 3,
      "y": 19,
      "z": -1,
      "name": "Rock_Stone"
    },
    {
      "x": 3,
      "y": 20,
      "z": -1,
      "name": "Rock_Stone"
    },
    {
      "x": 3,
      "y": 21,
      "z": -1,
      "name": "Soil_Grass"
    },
    {
      "x": 3,
      "y": 38,
      "z": -1,
      "name": "Plant_Leaves_Ash",
      "support": 15
    },
    {
      "x": 3,
      "y": 39,
      "z": -1,
      "name": "Plant_Leaves_Ash",
      "support": 15
    },
    {
      "x": 3,
      "y": 18,
      "z": 0,
      "name": "Rock_Stone"
    },
    {
      "x": 3,
      "y": 19,
      "z": 0,
      "name": "Rock_Stone"
    },
    {
      "x": 3,
      "y": 20,
      "z": 0,
      "name": "Soil_Pathway"
    },
    {
      "x": 3,
      "y": 21,
      "z": 0,
      "name": "Wood_Ash_Roots"
    },
    {
      "x": 3,
      "y": 22,
      "z": 0,
      "name": "Wood_Ash_Trunk_Full",
      "support": 15
    },
    {
      "x": 3,
      "y": 23,
      "z": 0,
      "name": "Wood_Ash_Trunk",
      "support": 15
    },
    {
      "x": 3,
      "y": 24,
      "z": 0,
      "name": "Wood_Ash_Trunk",
      "support": 15
    },
    {
      "x": 3,
      "y": 25,
      "z": 0,
      "name": "Wood_Ash_Trunk_Full",
      "support": 15
    },
    {
      "x": 3,
      "y": 28,
      "z": 0,
      "name": "Plant_Vine_Wall",
      "rotation": 2
    },
    {
      "x": 3,
      "y": 29,
      "z": 0,
      "name": "Wood_Ash_Trunk_Full",
      "support": 15
    },
    {
      "x": 3,
      "y": 30,
      "z": 0,
      "name": "Wood_Ash_Trunk",
      "support": 15
    },
    {
      "x": 3,
      "y": 31,
      "z": 0,
      "name": "Wood_Ash_Trunk_Full",
      "support": 15
    },
    {
      "x": 3,
      "y": 36,
      "z": 0,
      "name": "Wood_Ash_Trunk_Full",
      "support": 15
    },
    {
      "x": 3,
      "y": 18,
      "z": 1,
      "name": "Rock_Stone"
    },
    {
      "x": 3,
      "y": 19,
      "z": 1,
      "name": "Rock_Stone"
    },
    {
      "x": 3,
      "y": 20,
      "z": 1,
      "name": "Rock_Stone"
    },
    {
      "x": 3,
      "y": 21,
      "z": 1,
      "name": "Soil_Pathway"
    },
    {
      "x": 3,
      "y": 22,
      "z": 1,
      "name": "Soil_Pathway"
    },
    {
      "x": 3,
      "y": 23,
      "z": 1,
      "name": "Soil_Grass"
    },
    {
      "x": 3,
      "y": 24,
      "z": 1,
      "name": "Wood_Ash_Roots"
    },
    {
      "x": 3,
      "y": 25,
      "z": 1,
      "name": "Wood_Ash_Trunk_Full",
      "support": 15
    },
    {
      "x": 3,
      "y": 26,
      "z": 1,
      "name": "Wood_Ash_Trunk",
      "support": 15
    },
    {
      "x": 3,
      "y": 27,
      "z": 1,
      "name": "Wood_Ash_Trunk",
      "support": 15
    },
    {
      "x": 3,
      "y": 28,
      "z": 1,
      "name": "Wood_Ash_Trunk",
      "support": 15
    },
    {
      "x": 3,
      "y": 29,
      "z": 1,
      "name": "Wood_Ash_Trunk",
      "support": 15
    },
    {
      "x": 3,
      "y": 30,
      "z": 1,
      "name": "Wood_Ash_Trunk_Full",
      "support": 15
    },
    {
      "x": 3,
      "y": 17,
      "z": 2,
      "name": "Rock_Stone"
    },
    {
      "x": 3,
      "y": 18,
      "z": 2,
      "name": "Rock_Stone"
    },
    {
      "x": 3,
      "y": 19,
      "z": 2,
      "name": "Rock_Stone"
    },
    {
      "x": 3,
      "y": 20,
      "z": 2,
      "name": "Rock_Stone"
    },
    {
      "x": 3,
      "y": 21,
      "z": 2,
      "name": "Soil_Dirt"
    },
    {
      "x": 3,
      "y": 22,
      "z": 2,
      "name": "Soil_Dirt"
    },
    {
      "x": 3,
      "y": 23,
      "z": 2,
      "name": "Soil_Grass"
    },
    {
      "x": 3,
      "y": 26,
      "z": 2,
      "name": "Wood_Ash_Trunk_Full",
      "support": 15
    },
    {
      "x": 3,
      "y": 27,
      "z": 2,
      "name": "Wood_Ash_Trunk",
      "support": 15
    },
    {
      "x": 3,
      "y": 28,
      "z": 2,
      "name": "Wood_Ash_Trunk",
      "support": 15
    },
    {
      "x": 3,
      "y": 29,
      "z": 2,
      "name": "Wood_Ash_Trunk_Full",
      "support": 15
    },
    {
      "x": 3,
      "y": 17,
      "z": 3,
      "name": "Rock_Stone"
    },
    {
      "x": 3,
      "y": 18,
      "z": 3,
      "name": "Rock_Stone"
    },
    {
      "x": 3,
      "y": 19,
      "z": 3,
      "name": "Rock_Stone"
    },
    {
      "x": 3,
      "y": 20,
      "z": 3,
      "name": "Rock_Stone"
    },
    {
      "x": 3,
      "y": 21,
      "z": 3,
      "name": "Soil_Dirt"
    },
    {
      "x": 3,
      "y": 22,
      "z": 3,
      "name": "Soil_Dirt"
    },
    {
      "x": 3,
      "y": 23,
      "z": 3,
      "name": "Soil_Grass"
    },
    {
      "x": 3,
      "y": 27,
      "z": 3,
      "name": "Wood_Ash_Trunk_Full",
      "support": 15
    },
    {
      "x": 3,
      "y": 40,
      "z": 3,
      "name": "Plant_Leaves_Ash",
      "support": 15
    },
    {
      "x": 3,
      "y": 17,
      "z": 4,
      "name": "Rock_Stone"
    },
    {
      "x": 3,
      "y": 18,
      "z": 4,
      "name": "Rock_Stone"
    },
    {
      "x": 3,
      "y": 19,
      "z": 4,
      "name": "Rock_Stone"
    },
    {
      "x": 3,
      "y": 20,
      "z": 4,
      "name": "Rock_Stone"
    },
    {
      "x": 3,
      "y": 21,
      "z": 4,
      "name": "Soil_Dirt"
    },
    {
      "x": 3,
      "y": 22,
