{
  "version": 8,
  "blockIdVersion": 8,
  "anchorX": -1,
  "anchorY": 20,
  "anchorZ": 3,
  "blocks": [
    {
      "x": -15,
      "y": 23,
      "z": 8,
      "name": "Rock_Stone"
    },
    {
      "x": -15,
      "y": 24,
      "z": 8,
      "name": "Rock_Stone"
    },
    {
      "x": -15,
      "y": 25,
      "z": 8,
      "name": "Rock_Stone"
    },
    {
      "x": -15,
      "y": 26,
      "z": 8,
      "name": "Rock_Stone"
    },
    {
      "x": -15,
      "y": 27,
      "z": 8,
      "name": "Soil_Dirt"
    },
    {
      "x": -15,
      "y": 28,
      "z": 8,
      "name": "Soil_Grass"
    },
    {
      "x": -15,
      "y": 21,
      "z": 9,
      "name": "Rock_Stone"
    },
    {
      "x": -15,
      "y": 22,
      "z": 9,
      "name": "Rock_Stone"
    },
    {
      "x": -15,
      "y": 23,
      "z": 9,
      "name": "Rock_Stone"
    },
    {
      "x": -15,
      "y": 24,
      "z": 9,
      "name": "Rock_Stone"
    },
    {
      "x": -15,
      "y": 25,
      "z": 9,
      "name": "Rock_Stone"
    },
    {
      "x": -15,
      "y": 26,
      "z": 9,
      "name": "Soil_Dirt"
    },
    {
      "x": -15,
      "y": 27,
      "z": 9,
      "name": "Soil_Grass"
    },
    {
      "x": -15,
      "y": 19,
      "z": 10,
      "name": "Rock_Stone"
    },
    {
      "x": -15,
      "y": 20,
      "z": 10,
      "name": "Rock_Stone"
    },
    {
      "x": -15,
      "y": 21,
      "z": 10,
      "name": "Rock_Stone"
    },
    {
      "x": -15,
      "y": 22,
      "z": 10,
      "name": "Rock_Stone"
    },
    {
      "x": -15,
      "y": 23,
      "z": 10,
      "name": "Rock_Stone"
    },
    {
      "x": -15,
      "y": 24,
      "z": 10,
      "name": "Rock_Stone"
    },
    {
      "x": -15,
      "y": 25,
      "z": 10,
      "name": "Soil_Grass"
    },
    {
      "x": -15,
      "y": 24,
      "z": 11,
      "name": "Rock_Stone"
    },
    {
      "x": -15,
      "y": 25,
      "z": 11,
      "name": "Soil_Grass"
    },
    {
      "x": -14,
      "y": 26,
      "z": 6,
      "name": "Rock_Stone"
    },
    {
      "x": -14,
      "y": 27,
      "z": 6,
      "name": "Rock_Stone"
    },
    {
      "x": -14,
      "y": 23,
      "z": 7,
      "name": "Rock_Stone"
    },
    {
      "x": -14,
      "y": 24,
      "z": 7,
      "name": "Rock_Stone"
    },
    {
      "x": -14,
      "y": 25,
      "z": 7,
      "name": "Rock_Stone"
    },
    {
      "x": -14,
      "y": 26,
      "z": 7,
      "name": "Rock_Stone"
    },
    {
      "x": -14,
      "y": 27,
      "z": 7,
      "name": "Rock_Stone"
    },
    {
      "x": -14,
      "y": 28,
      "z": 7,
      "name": "Soil_Grass"
    },
    {
      "x": -14,
      "y": 19,
      "z": 8,
      "name": "Rock_Stone"
    },
    {
      "x": -14,
      "y": 20,
      "z": 8,
      "name": "Rock_Stone"
    },
    {
      "x": -14,
      "y": 21,
      "z": 8,
      "name": "Rock_Stone"
    },
    {
      "x": -14,
      "y": 22,
      "z": 8,
      "name": "Rock_Stone"
    },
    {
      "x": -14,
      "y": 23,
      "z": 8,
      "name": "Rock_Stone"
    },
    {
      "x": -14,
      "y": 24,
      "z": 8,
      "name": "Rock_Stone"
    },
    {
      "x": -14,
      "y": 25,
      "z": 8,
      "name": "Rock_Stone"
    },
    {
      "x": -14,
      "y": 26,
      "z": 8,
      "name": "Rock_Stone"
    },
    {
      "x": -14,
      "y": 27,
      "z": 8,
      "name": "Soil_Dirt"
    },
    {
      "x": -14,
      "y": 28,
      "z": 8,
      "name": "Soil_Grass"
    },
    {
      "x": -14,
      "y": 17,
      "z": 9,
      "name": "Rock_Stone"
    },
    {
      "x": -14,
      "y": 18,
      "z": 9,
      "name": "Rock_Stone"
    },
    {
      "x": -14,
      "y": 19,
      "z": 9,
      "name": "Rock_Stone"
    },
    {
      "x": -14,
      "y": 20,
      "z": 9,
      "name": "Rock_Stone"
    },
    {
      "x": -14,
      "y": 21,
      "z": 9,
      "name": "Rock_Stone"
    },
    {
      "x": -14,
      "y": 22,
      "z": 9,
      "name": "Rock_Stone"
    },
    {
      "x": -14,
      "y": 23,
      "z": 9,
      "name": "Rock_Stone"
    },
    {
      "x": -14,
      "y": 24,
      "z": 9,
      "name": "Rock_Stone"
    },
    {
      "x": -14,
      "y": 25,
      "z": 9,
      "name": "Rock_Stone"
    },
    {
      "x": -14,
      "y": 26,
      "z": 9,
      "name": "Soil_Dirt"
    },
    {
      "x": -14,
      "y": 27,
      "z": 9,
      "name": "Soil_Dirt"
    },
    {
      "x": -14,
      "y": 28,
      "z": 9,
      "name": "Soil_Dirt"
    },
    {
      "x": -14,
      "y": 29,
      "z": 9,
      "name": "Soil_Grass"
    },
    {
      "x": -14,
      "y": 16,
      "z": 10,
      "name": "Rock_Stone"
    },
    {
      "x": -14,
      "y": 17,
      "z": 10,
      "name": "Rock_Stone"
    },
    {
      "x": -14,
      "y": 18,
      "z": 10,
      "name": "Rock_Stone"
    },
    {
      "x": -14,
      "y": 19,
      "z": 10,
      "name": "Rock_Stone"
    },
    {
      "x": -14,
      "y": 20,
      "z": 10,
      "name": "Rock_Stone"
    },
    {
      "x": -14,
      "y": 21,
      "z": 10,
      "name": "Rock_Stone"
    },
    {
      "x": -14,
      "y": 22,
      "z": 10,
      "name": "Rock_Stone"
    },
    {
      "x": -14,
      "y": 23,
      "z": 10,
      "name": "Rock_Stone"
    },
    {
      "x": -14,
      "y": 24,
      "z": 10,
      "name": "Rock_Stone"
    },
    {
      "x": -14,
      "y": 25,
      "z": 10,
      "name": "Soil_Dirt"
    },
    {
      "x": -14,
      "y": 26,
      "z": 10,
      "name": "Soil_Dirt"
    },
    {
      "x": -14,
      "y": 27,
      "z": 10,
      "name": "Soil_Dirt"
    },
    {
      "x": -14,
      "y": 28,
      "z": 10,
      "name": "Soil_Dirt"
    },
    {
      "x": -14,
      "y": 29,
      "z": 10,
      "name": "Soil_Grass"
    },
    {
      "x": -14,
      "y": 18,
      "z": 11,
      "name": "Rock_Stone"
    },
    {
      "x": -14,
      "y": 19,
      "z": 11,
      "name": "Rock_Stone"
    },
    {
      "x": -14,
      "y": 20,
      "z": 11,
      "name": "Rock_Stone"
    },
    {
      "x": -14,
      "y": 21,
      "z": 11,
      "name": "Rock_Stone"
    },
    {
      "x": -14,
      "y": 22,
      "z": 11,
      "name": "Rock_Stone"
    },
    {
      "x": -14,
      "y": 23,
      "z": 11,
      "name": "Rock_Stone"
    },
    {
      "x": -14,
      "y": 24,
      "z": 11,
      "name": "Rock_Stone"
    },
    {
      "x": -14,
      "y": 25,
      "z": 11,
      "name": "Soil_Dirt"
    },
    {
      "x": -14,
      "y": 26,
      "z": 11,
      "name": "Soil_Dirt"
    },
    {
      "x": -14,
      "y": 27,
      "z": 11,
      "name": "Soil_Dirt"
    },
    {
      "x": -14,
      "y": 28,
      "z": 11,
      "name": "Soil_Grass"
    },
    {
      "x": -14,
      "y": 29,
      "z": 11,
      "name": "Plant_Moss_Rug_Green"
    },
    {
      "x": -14,
      "y": 20,
      "z": 12,
      "name": "Rock_Stone"
    },
    {
      "x": -14,
      "y": 21,
      "z": 12,
      "name": "Rock_Stone"
    },
    {
      "x": -14,
      "y": 22,
      "z": 12,
      "name": "Rock_Stone"
    },
    {
      "x": -14,
      "y": 23,
      "z": 12,
      "name": "Rock_Stone"
    },
    {
      "x": -14,
      "y": 24,
      "z": 12,
      "name": "Soil_Dirt"
    },
    {
      "x": -14,
      "y": 25,
      "z": 12,
      "name": "Soil_Dirt"
    },
    {
      "x": -14,
      "y": 26,
      "z": 12,
      "name": "Soil_Grass"
    },
    {
      "x": -14,
      "y": 23,
      "z": 13,
      "name": "Rock_Stone"
    },
    {
      "x": -14,
      "y": 24,
      "z": 13,
      "name": "Rock_Stone"
    },
    {
      "x": -14,
      "y": 25,
      "z": 13,
      "name": "Soil_Grass"
    },
    {
      "x": -13,
      "y": 28,
      "z": 4,
      "name": "Rock_Stone"
    },
    {
      "x": -13,
      "y": 29,
      "z": 4,
      "name": "Soil_Dirt"
    },
    {
      "x": -13,
      "y": 28,
      "z": 5,
      "name": "Soil_Dirt"
    },
    {
      "x": -13,
      "y": 29,
      "z": 5,
      "name": "Soil_Dirt"
    },
    {
      "x": -13,
      "y": 30,
      "z": 5,
      "name": "Rock_Stone"
    },
    {
      "x": -13,
      "y": 31,
      "z": 5,
      "name": "Rock_Stone"
    },
    {
      "x": -13,
      "y": 32,
      "z": 5,
      "name": "Rock_Stone"
    },
    {
      "x": -13,
      "y": 24,
      "z": 6,
      "name": "Rock_Stone"
    },
    {
      "x": -13,
      "y": 25,
      "z": 6,
      "name": "Rock_Stone"
    },
    {
      "x": -13,
      "y": 26,
      "z": 6,
      "name": "Rock_Stone"
    },
    {
      "x": -13,
      "y": 27,
      "z": 6,
      "name": "Rock_Stone"
    },
    {
      "x": -13,
      "y": 28,
      "z": 6,
      "name": "Soil_Dirt"
    },
    {
      "x": -13,
      "y": 29,
      "z": 6,
      "name": "Soil_Dirt"
    },
    {
      "x": -13,
      "y": 30,
      "z": 6,
      "name": "Rock_Stone"
    },
    {
      "x": -13,
      "y": 31,
      "z": 6,
      "name": "Rock_Stone"
    },
    {
      "x": -13,
      "y": 32,
      "z": 6,
      "name": "Rock_Stone"
    },
    {
      "x": -13,
      "y": 20,
      "z": 7,
      "name": "Rock_Stone"
    },
    {
      "x": -13,
      "y": 21,
      "z": 7,
      "name": "Rock_Stone"
    },
    {
      "x": -13,
      "y": 22,
      "z": 7,
      "name": "Rock_Stone"
    },
    {
      "x": -13,
      "y": 23,
      "z": 7,
      "name": "Rock_Stone"
    },
    {
      "x": -13,
      "y": 24,
      "z": 7,
      "name": "Rock_Stone"
    },
    {
      "x": -13,
      "y": 25,
      "z": 7,
      "name": "Rock_Stone"
    },
    {
      "x": -13,
      "y": 26,
      "z": 7,
      "name": "Rock_Stone"
    },
    {
      "x": -13,
      "y": 27,
      "z": 7,
      "name": "Soil_Dirt"
    },
    {
      "x": -13,
      "y": 28,
      "z": 7,
      "name": "Soil_Dirt"
    },
    {
      "x": -13,
      "y": 29,
      "z": 7,
      "name": "Soil_Dirt"
    },
    {
      "x": -13,
      "y": 30,
      "z": 7,
      "name": "Rock_Stone"
    },
    {
      "x": -13,
      "y": 31,
      "z": 7,
      "name": "Rock_Stone"
    },
    {
      "x": -13,
      "y": 32,
      "z": 7,
      "name": "Rock_Stone"
    },
    {
      "x": -13,
      "y": 33,
      "z": 7,
      "name": "Rock_Stone_Mossy"
    },
    {
      "x": -13,
      "y": 17,
      "z": 8,
      "name": "Rock_Stone"
    },
    {
      "x": -13,
      "y": 18,
      "z": 8,
      "name": "Rock_Stone"
    },
    {
      "x": -13,
      "y": 19,
      "z": 8,
      "name": "Rock_Stone"
    },
    {
      "x": -13,
      "y": 20,
      "z": 8,
      "name": "Rock_Stone"
    },
    {
      "x": -13,
      "y": 21,
      "z": 8,
      "name": "Rock_Stone"
    },
    {
      "x": -13,
      "y": 22,
      "z": 8,
      "name": "Rock_Stone"
    },
    {
      "x": -13,
      "y": 23,
      "z": 8,
      "name": "Rock_Stone"
    },
    {
      "x": -13,
      "y": 24,
      "z": 8,
      "name": "Rock_Stone"
    },
    {
      "x": -13,
      "y": 25,
      "z": 8,
      "name": "Rock_Stone"
    },
    {
      "x": -13,
      "y": 26,
      "z": 8,
      "name": "Rock_Stone"
    },
    {
      "x": -13,
      "y": 27,
      "z": 8,
      "name": "Soil_Dirt"
    },
    {
      "x": -13,
      "y": 28,
      "z": 8,
      "name": "Soil_Dirt"
    },
    {
      "x": -13,
      "y": 29,
      "z": 8,
      "name": "Rock_Stone"
    },
    {
      "x": -13,
      "y": 30,
      "z": 8,
      "name": "Rock_Stone"
    },
    {
      "x": -13,
      "y": 31,
      "z": 8,
      "name": "Rock_Stone_Mossy"
    },
    {
      "x": -13,
      "y": 32,
      "z": 8,
      "name": "Rock_Stone_Mossy"
    },
    {
      "x": -13,
      "y": 33,
      "z": 8,
      "name": "Rock_Stone_Mossy"
    },
    {
      "x": -13,
      "y": 15,
      "z": 9,
      "name": "Rock_Stone"
    },
    {
      "x": -13,
      "y": 16,
      "z": 9,
      "name": "Rock_Stone"
    },
    {
      "x": -13,
      "y": 17,
      "z": 9,
      "name": "Rock_Stone"
    },
    {
      "x": -13,
      "y": 18,
      "z": 9,
      "name": "Rock_Stone"
    },
    {
      "x": -13,
      "y": 19,
      "z": 9,
      "name": "Rock_Stone"
    },
    {
      "x": -13,
      "y": 20,
      "z": 9,
      "name": "Rock_Stone"
    },
    {
      "x": -13,
      "y": 21,
      "z": 9,
      "name": "Rock_Stone"
    },
    {
      "x": -13,
      "y": 22,
      "z": 9,
      "name": "Rock_Stone"
    },
    {
      "x": -13,
      "y": 23,
      "z": 9,
      "name": "Rock_Stone"
    },
    {
      "x": -13,
      "y": 24,
      "z": 9,
      "name": "Rock_Stone"
    },
    {
      "x": -13,
      "y": 25,
      "z": 9,
      "name": "Rock_Stone"
    },
    {
      "x": -13,
      "y": 26,
      "z": 9,
      "name": "Soil_Dirt"
    },
    {
      "x": -13,
      "y": 27,
      "z": 9,
      "name": "Soil_Dirt"
    },
    {
      "x": -13,
      "y": 28,
      "z": 9,
      "name": "Soil_Dirt"
    },
    {
      "x": -13,
      "y": 29,
      "z": 9,
      "name": "Rock_Stone"
    },
    {
      "x": -13,
      "y": 30,
      "z": 9,
      "name": "Rock_Stone"
    },
    {
      "x": -13,
      "y": 31,
      "z": 9,
      "name": "Rock_Stone"
    },
    {
      "x": -13,
      "y": 32,
      "z": 9,
      "name": "Soil_Gravel"
    },
    {
      "x": -13,
      "y": 14,
      "z": 10,
      "name": "Rock_Stone"
    },
    {
      "x": -13,
      "y": 15,
      "z": 10,
      "name": "Rock_Stone"
    },
    {
      "x": -13,
      "y": 16,
      "z": 10,
      "name": "Rock_Stone"
    },
    {
      "x": -13,
      "y": 17,
      "z": 10,
      "name": "Rock_Stone"
    },
    {
      "x": -13,
      "y": 18,
      "z": 10,
      "name": "Rock_Stone"
    },
    {
      "x": -13,
      "y": 19,
      "z": 10,
      "name": "Rock_Stone"
    },
    {
      "x": -13,
      "y": 20,
      "z": 10,
      "name": "Rock_Stone"
    },
    {
      "x": -13,
      "y": 21,
      "z": 10,
      "name": "Rock_Stone"
    },
    {
      "x": -13,
      "y": 22,
      "z": 10,
      "name": "Rock_Stone"
    },
    {
      "x": -13,
      "y": 23,
      "z": 10,
      "name": "Rock_Stone"
    },
    {
      "x": -13,
      "y": 24,
      "z": 10,
      "name": "Rock_Stone"
    },
    {
      "x": -13,
      "y": 25,
      "z": 10,
      "name": "Soil_Dirt"
    },
    {
      "x": -13,
      "y": 26,
      "z": 10,
      "name": "Soil_Dirt"
    },
    {
      "x": -13,
      "y": 27,
      "z": 10,
      "name": "Soil_Dirt"
    },
    {
      "x": -13,
      "y": 28,
      "z": 10,
      "name": "Soil_Dirt"
    },
    {
      "x": -13,
      "y": 29,
      "z": 10,
      "name": "Rock_Stone"
    },
    {
      "x": -13,
      "y": 30,
      "z": 10,
      "name": "Soil_Grass"
    },
    {
      "x": -13,
      "y": 15,
      "z": 11,
      "name": "Rock_Stone"
    },
    {
      "x": -13,
      "y": 16,
      "z": 11,
      "name": "Rock_Stone"
    },
    {
      "x": -13,
      "y": 17,
      "z": 11,
      "name": "Rock_Stone"
    },
    {
      "x": -13,
      "y": 18,
      "z": 11,
      "name": "Rock_Stone"
    },
    {
      "x": -13,
      "y": 19,
      "z": 11,
      "name": "Rock_Stone"
    },
    {
      "x": -13,
      "y": 20,
      "z": 11,
      "name": "Rock_Stone"
    },
    {
      "x": -13,
      "y": 21,
      "z": 11,
      "name": "Rock_Stone"
    },
    {
      "x": -13,
      "y": 22,
      "z": 11,
      "name": "Rock_Stone"
    },
    {
      "x": -13,
      "y": 23,
      "z": 11,
      "name": "Rock_Stone"
    },
    {
      "x": -13,
      "y": 24,
      "z": 11,
      "name": "Rock_Stone"
    },
    {
      "x": -13,
      "y": 25,
      "z": 11,
      "name": "Soil_Dirt"
    },
    {
      "x": -13,
      "y": 26,
      "z": 11,
      "name": "Soil_Dirt"
    },
    {
      "x": -13,
      "y": 27,
      "z": 11,
      "name": "Soil_Dirt"
    },
    {
      "x": -13,
      "y": 28,
      "z": 11,
      "name": "Soil_Grass"
    },
    {
      "x": -13,
      "y": 29,
      "z": 11,
      "name": "Plant_Crop_Mushroom_Flatcap_Green",
      "components": {
        "Components": {
          "FarmingBlock": {}
        }
      }
    },
    {
      "x": -13,
      "y": 17,
      "z": 12,
      "name": "Rock_Stone"
    },
    {
      "x": -13,
      "y": 18,
      "z": 12,
      "name": "Rock_Stone"
    },
    {
      "x": -13,
      "y": 19,
      "z": 12,
      "name": "Rock_Stone"
    },
    {
      "x": -13,
      "y": 20,
      "z": 12,
      "name": "Rock_Stone"
    },
    {
      "x": -13,
      "y": 21,
      "z": 12,
      "name": "Rock_Stone"
    },
    {
      "x": -13,
      "y": 22,
      "z": 12,
      "name": "Rock_Stone"
    },
    {
      "x": -13,
      "y": 23,
      "z": 12,
      "name": "Rock_Stone"
    },
    {
      "x": -13,
      "y": 24,
      "z": 12,
      "name": "Rock_Stone"
    },
    {
      "x": -13,
      "y": 25,
      "z": 12,
      "name": "Soil_Dirt"
    },
    {
      "x": -13,
      "y": 26,
      "z": 12,
      "name": "Soil_Dirt"
    },
    {
      "x": -13,
      "y": 27,
      "z": 12,
      "name": "Soil_Grass"
    },
    {
      "x": -13,
      "y": 28,
      "z": 12,
      "name": "Plant_Moss_Rug_Green"
    },
    {
      "x": -13,
      "y": 21,
      "z": 13,
      "name": "Rock_Stone"
    },
    {
      "x": -13,
      "y": 22,
      "z": 13,
      "name": "Rock_Stone"
    },
    {
      "x": -13,
      "y": 23,
      "z": 13,
      "name": "Rock_Stone"
    },
    {
      "x": -13,
      "y": 24,
      "z": 13,
      "name": "Rock_Stone"
    },
    {
      "x": -13,
      "y": 25,
      "z": 13,
      "name": "Soil_Dirt"
    },
    {
      "x": -13,
      "y": 26,
      "z": 13,
      "name": "Soil_Dirt"
    },
    {
      "x": -13,
      "y": 27,
      "z": 13,
      "name": "Soil_Grass"
    },
    {
      "x": -13,
      "y": 28,
      "z": 13,
      "name": "Plant_Moss_Rug_Green"
    },
    {
      "x": -12,
      "y": 29,
      "z": 3,
      "name": "Rock_Stone"
    },
    {
      "x": -12,
      "y": 30,
      "z": 3,
      "name": "Soil_Dirt"
    },
    {
      "x": -12,
      "y": 31,
      "z": 3,
      "name": "Soil_Grass"
    },
    {
      "x": -12,
      "y": 28,
      "z": 4,
      "name": "Rock_Stone"
    },
    {
      "x": -12,
      "y": 29,
      "z": 4,
      "name": "Rock_Stone"
    },
    {
      "x": -12,
      "y": 30,
      "z": 4,
      "name": "Rock_Stone"
    },
    {
      "x": -12,
      "y": 31,
      "z": 4,
      "name": "Rock_Stone"
    },
    {
      "x": -12,
      "y": 32,
      "z": 4,
      "name": "Rock_Stone"
    },
    {
      "x": -12,
      "y": 48,
      "z": 4,
      "name": "Plant_Leaves_Ash",
      "support": 15
    },
    {
      "x": -12,
      "y": 27,
      "z": 5,
      "name": "Rock_Stone"
    },
    {
      "x": -12,
      "y": 28,
      "z": 5,
      "name": "Soil_Dirt"
    },
    {
      "x": -12,
      "y": 29,
      "z": 5,
      "name": "Soil_Dirt"
    },
    {
      "x": -12,
      "y": 30,
      "z": 5,
      "name": "Rock_Stone"
    },
    {
      "x": -12,
      "y": 31,
      "z": 5,
      "name": "Rock_Stone"
    },
    {
      "x": -12,
      "y": 32,
      "z": 5,
      "name": "Rock_Stone"
    },
    {
      "x": -12,
      "y": 33,
      "z": 5,
      "name": "Rock_Stone"
    },
    {
      "x": -12,
      "y": 47,
      "z": 5,
      "name": "Plant_Leaves_Ash",
      "support": 15
    },
    {
      "x": -12,
      "y": 48,
      "z": 5,
      "name": "Plant_Leaves_Ash",
      "support": 15
    },
    {
      "x": -12,
      "y": 49,
      "z": 5,
      "name": "Plant_Leaves_Ash",
      "support": 15
    },
    {
      "x": -12,
      "y": 24,
      "z": 6,
      "name": "Rock_Stone"
    },
    {
      "x": -12,
      "y": 25,
      "z": 6,
      "name": "Rock_Stone"
    },
    {
      "x": -12,
      "y": 26,
      "z": 6,
      "name": "Rock_Stone"
    },
    {
      "x": -12,
      "y": 27,
      "z": 6,
      "name": "Rock_Stone"
    },
    {
      "x": -12,
      "y": 28,
      "z": 6,
      "name": "Soil_Dirt"
    },
    {
      "x": -12,
      "y": 29,
      "z": 6,
      "name": "Rock_Stone"
    },
    {
      "x": -12,
      "y": 30,
      "z": 6,
      "name": "Rock_Stone"
    },
    {
      "x": -12,
      "y": 31,
      "z": 6,
      "name": "Rock_Stone"
    },
    {
      "x": -12,
      "y": 32,
      "z": 6,
      "name": "Rock_Stone"
    },
    {
      "x": -12,
      "y": 33,
      "z": 6,
      "name": "Rock_Stone"
    },
    {
      "x": -12,
      "y": 34,
      "z": 6,
      "name": "Rock_Stone"
    },
    {
      "x": -12,
      "y": 47,
      "z": 6,
      "name": "Plant_Leaves_Ash",
      "support": 15
    },
    {
      "x": -12,
      "y": 48,
      "z": 6,
      "name": "Plant_Leaves_Ash",
      "support": 15
    },
    {
      "x": -12,
      "y": 49,
      "z": 6,
      "name": "Plant_Leaves_Ash",
      "support": 15
    },
    {
      "x": -12,
      "y": 19,
      "z": 7,
      "name": "Rock_Stone"
    },
    {
      "x": -12,
      "y": 20,
      "z": 7,
      "name": "Rock_Stone"
    },
    {
      "x": -12,
      "y": 21,
      "z": 7,
      "name": "Rock_Stone"
    },
    {
      "x": -12,
      "y": 22,
      "z": 7,
      "name": "Rock_Stone"
    },
    {
      "x": -12,
      "y": 23,
      "z": 7,
      "name": "Rock_Stone"
    },
    {
      "x": -12,
      "y": 24,
      "z": 7,
      "name": "Rock_Stone"
    },
    {
      "x": -12,
      "y": 25,
      "z": 7,
      "name": "Rock_Stone"
    },
    {
      "x": -12,
      "y": 26,
      "z": 7,
      "name": "Rock_Stone"
    },
    {
      "x": -12,
      "y": 27,
      "z": 7,
      "name": "Rock_Stone"
    },
    {
      "x": -12,
      "y": 28,
      "z": 7,
      "name": "Soil_Dirt"
    },
    {
      "x": -12,
      "y": 29,
      "z": 7,
      "name": "Soil_Dirt"
    },
    {
      "x": -12,
      "y": 30,
      "z": 7,
      "name": "Rock_Stone"
    },
    {
      "x": -12,
      "y": 31,
      "z": 7,
      "name": "Rock_Stone"
    },
    {
      "x": -12,
      "y": 32,
      "z": 7,
      "name": "Rock_Stone"
    },
    {
      "x": -12,
      "y": 33,
      "z": 7,
      "name": "Rock_Stone"
    },
    {
      "x": -12,
      "y": 34,
      "z": 7,
      "name": "Soil_Gravel"
    },
    {
      "x": -12,
      "y": 15,
      "z": 8,
      "name": "Rock_Stone"
    },
    {
      "x": -12,
      "y": 16,
      "z": 8,
      "name": "Rock_Stone"
    },
    {
      "x": -12,
      "y": 17,
      "z": 8,
      "name": "Rock_Stone"
    },
    {
      "x": -12,
      "y": 18,
      "z": 8,
      "name": "Rock_Stone"
    },
    {
      "x": -12,
      "y": 19,
      "z": 8,
      "name": "Rock_Stone"
    },
    {
      "x": -12,
      "y": 20,
      "z": 8,
      "name": "Rock_Stone"
    },
    {
      "x": -12,
      "y": 21,
      "z": 8,
      "name": "Rock_Stone"
    },
    {
      "x": -12,
      "y": 22,
      "z": 8,
      "name": "Rock_Stone"
    },
    {
      "x": -12,
      "y": 23,
      "z": 8,
      "name": "Rock_Stone"
    },
    {
      "x": -12,
      "y": 24,
      "z": 8,
      "name": "Rock_Stone"
    },
    {
      "x": -12,
      "y": 25,
      "z": 8,
      "name": "Rock_Stone"
    },
    {
      "x": -12,
      "y": 26,
      "z": 8,
      "name": "Rock_Stone"
    },
    {
      "x": -12,
      "y": 27,
      "z": 8,
      "name": "Rock_Stone"
    },
    {
      "x": -12,
      "y": 28,
      "z": 8,
      "name": "Soil_Dirt"
    },
    {
      "x": -12,
      "y": 29,
      "z": 8,
      "name": "Rock_Stone"
    },
    {
      "x": -12,
      "y": 30,
      "z": 8,
      "name": "Rock_Stone"
    },
    {
      "x": -12,
      "y": 31,
      "z": 8,
      "name": "Rock_Stone"
    },
    {
      "x": -12,
      "y": 32,
      "z": 8,
      "name": "Soil_Gravel"
    },
    {
      "x": -12,
      "y": 33,
      "z": 8,
      "name": "Rock_Stone_Mossy"
    },
    {
      "x": -12,
      "y": 13,
      "z": 9,
      "name": "Rock_Stone"
    },
    {
      "x": -12,
      "y": 14,
      "z": 9,
      "name": "Rock_Stone"
    },
    {
      "x": -12,
      "y": 15,
      "z": 9,
      "name": "Rock_Stone"
    },
    {
      "x": -12,
      "y": 16,
      "z": 9,
      "name": "Rock_Stone"
    },
    {
      "x": -12,
      "y": 17,
      "z": 9,
      "name": "Rock_Stone"
    },
    {
      "x": -12,
      "y": 18,
      "z": 9,
      "name": "Rock_Stone"
    },
    {
      "x": -12,
      "y": 19,
      "z": 9,
      "name": "Rock_Stone"
    },
    {
      "x": -12,
      "y": 20,
      "z": 9,
      "name": "Rock_Stone"
    },
    {
      "x": -12,
      "y": 21,
      "z": 9,
      "name": "Rock_Stone"
    },
    {
      "x": -12,
      "y": 22,
      "z": 9,
      "name": "Rock_Stone"
    },
    {
      "x": -12,
      "y": 23,
      "z": 9,
      "name": "Rock_Stone"
    },
    {
      "x": -12,
      "y": 24,
      "z": 9,
      "name": "Rock_Stone"
    },
    {
      "x": -12,
      "y": 25,
      "z": 9,
      "name": "Rock_Stone"
    },
    {
      "x": -12,
      "y": 26,
      "z": 9,
      "name": "Rock_Stone"
    },
    {
      "x": -12,
      "y": 27,
      "z": 9,
      "name": "Soil_Dirt"
    },
    {
      "x": -12,
      "y": 28,
      "z": 9,
      "name": "Rock_Stone"
    },
    {
      "x": -12,
      "y": 29,
      "z": 9,
      "name": "Rock_Stone"
    },
    {
      "x": -12,
      "y": 30,
      "z": 9,
      "name": "Soil_Gravel"
    },
    {
      "x": -12,
      "y": 31,
      "z": 9,
      "name": "Soil_Gravel"
    },
    {
      "x": -12,
      "y": 32,
      "z": 9,
      "name": "Soil_Gravel"
    },
    {
      "x": -12,
      "y": 44,
      "z": 9,
      "name": "Plant_Leaves_Ash",
      "support": 15
    },
    {
      "x": -12,
      "y": 45,
      "z": 9,
      "name": "Plant_Leaves_Ash",
      "support": 15
    },
    {
      "x": -12,
      "y": 46,
      "z": 9,
      "name": "Plant_Leaves_Ash",
      "support": 15
    },
    {
      "x": -12,
      "y": 14,
      "z": 10,
      "name": "Rock_Stone"
    },
    {
      "x": -12,
      "y": 15,
      "z": 10,
      "name": "Rock_Stone"
    },
    {
      "x": -12,
      "y": 16,
      "z": 10,
      "name": "Rock_Stone"
    },
    {
      "x": -12,
      "y": 17,
      "z": 10,
      "name": "Rock_Stone"
    },
    {
      "x": -12,
      "y": 18,
      "z": 10,
      "name": "Rock_Stone"
    },
    {
      "x": -12,
      "y": 19,
      "z": 10,
      "name": "Rock_Stone"
    },
    {
      "x": -12,
      "y": 20,
      "z": 10,
      "name": "Rock_Stone"
    },
    {
      "x": -12,
      "y": 21,
      "z": 10,
      "name": "Rock_Stone"
    },
    {
      "x": -12,
      "y": 22,
      "z": 10,
      "name": "Rock_Stone"
    },
    {
      "x": -12,
      "y": 23,
      "z": 10,
      "name": "Rock_Stone"
    },
    {
      "x": -12,
      "y": 24,
      "z": 10,
      "name": "Rock_Stone"
    },
    {
      "x": -12,
      "y": 25,
      "z": 10,
      "name": "Rock_Stone"
    },
    {
      "x": -12,
      "y": 26,
      "z": 10,
      "name": "Soil_Dirt"
    },
    {
      "x": -12,
      "y": 27,
      "z": 10,
      "name": "Soil_Dirt"
    },
    {
      "x": -12,
      "y": 28,
      "z": 10,
      "name": "Soil_Dirt"
    },
    {
      "x": -12,
      "y": 29,
      "z": 10,
      "name": "Rock_Stone"
    },
    {
      "x": -12,
      "y": 30,
      "z": 10,
      "name": "Rock_Stone"
    },
    {
      "x": -12,
      "y": 31,
      "z": 10,
      "name": "Rock_Stone"
    },
    {
      "x": -12,
      "y": 32,
      "z": 10,
      "name": "Soil_Gravel"
    },
    {
      "x": -12,
      "y": 46,
      "z": 10,
      "name": "Plant_Leaves_Ash",
      "support": 15
    },
    {
      "x": -12,
      "y": 47,
      "z": 10,
      "name": "Plant_Leaves_Ash",
      "support": 15
    },
    {
      "x": -12,
      "y": 14,
      "z": 11,
      "name": "Rock_Stone"
    },
    {
      "x": -12,
      "y": 15,
      "z": 11,
      "name": "Rock_Stone"
    },
    {
      "x": -12,
      "y": 16,
      "z": 11,
      "name": "Rock_Stone"
    },
    {
      "x": -12,
      "y": 17,
      "z": 11,
      "name": "Rock_Stone"
    },
    {
      "x": -12,
      "y": 18,
      "z": 11,
      "name": "Rock_Stone"
    },
    {
      "x": -12,
      "y": 19,
      "z": 11,
      "name": "Rock_Stone"
    },
    {
      "x": -12,
      "y": 20,
      "z": 11,
      "name": "Rock_Stone"
    },
    {
      "x": -12,
      "y": 21,
      "z": 11,
      "name": "Rock_Stone"
    },
    {
      "x": -12,
      "y": 22,
      "z": 11,
      "name": "Rock_Stone"
    },
    {
      "x": -12,
      "y": 23,
      "z": 11,
      "name": "Rock_Stone"
    },
    {
      "x": -12,
      "y": 24,
      "z": 11,
      "name": "Rock_Stone"
    },
    {
      "x": -12,
      "y": 25,
      "z": 11,
      "name": "Soil_Dirt"
    },
    {
      "x": -12,
      "y": 26,
      "z": 11,
      "name": "Soil_Dirt"
    },
    {
      "x": -12,
      "y": 27,
      "z": 11,
      "name": "Soil_Dirt"
    },
    {
      "x": -12,
      "y": 28,
      "z": 11,
      "name": "Soil_Dirt"
    },
    {
      "x": -12,
      "y": 29,
      "z": 11,
      "name": "Soil_Grass"
    },
    {
      "x": -12,
      "y": 30,
      "z": 11,
      "name": "Plant_Moss_Rug_Green"
    },
    {
      "x": -12,
      "y": 15,
      "z": 12,
      "name": "Rock_Stone"
    },
    {
      "x": -12,
      "y": 16,
      "z": 12,
      "name": "Rock_Stone"
    },
    {
      "x": -12,
      "y": 17,
      "z": 12,
      "name": "Rock_Stone"
    },
    {
      "x": -12,
      "y": 18,
      "z": 12,
      "name": "Rock_Stone"
    },
    {
      "x": -12,
      "y": 19,
      "z": 12,
      "name": "Rock_Stone"
    },
    {
      "x": -12,
      "y": 20,
      "z": 12,
      "name": "Rock_Stone"
    },
    {
      "x": -12,
      "y": 21,
      "z": 12,
      "name": "Rock_Stone"
    },
    {
      "x": -12,
      "y": 22,
      "z": 12,
      "name": "Rock_Stone"
    },
    {
      "x": -12,
      "y": 23,
      "z": 12,
      "name": "Rock_Stone"
    },
    {
      "x": -12,
      "y": 24,
      "z": 12,
      "name": "Rock_Stone"
    },
    {
      "x": -12,
      "y": 25,
      "z": 12,
      "name": "Soil_Dirt"
    },
    {
      "x": -12,
      "y": 26,
      "z": 12,
      "name": "Soil_Dirt"
    },
    {
      "x": -12,
      "y": 27,
      "z": 12,
      "name": "Soil_Dirt"
    },
    {
      "x": -12,
      "y": 28,
      "z": 12,
      "name": "Soil_Dirt"
    },
    {
      "x": -12,
      "y": 29,
      "z": 12,
      "name": "Soil_Grass"
    },
    {
      "x": -12,
      "y": 30,
      "z": 12,
      "name": "Plant_Moss_Rug_Green"
    },
    {
      "x": -12,
      "y": 18,
      "z": 13,
      "name": "Rock_Stone"
    },
    {
      "x": -12,
      "y": 19,
      "z": 13,
      "name": "Rock_Stone"
    },
    {
      "x": -12,
      "y": 20,
      "z": 13,
      "name": "Rock_Stone"
    },
    {
      "x": -12,
      "y": 21,
      "z": 13,
      "name": "Rock_Stone"
    },
    {
      "x": -12,
      "y": 22,
      "z": 13,
      "name": "Rock_Stone"
    },
    {
      "x": -12,
      "y": 23,
      "z": 13,
      "name": "Rock_Stone"
    },
    {
      "x": -12,
      "y": 24,
      "z": 13,
      "name": "Rock_Stone"
    },
    {
      "x": -12,
      "y": 25,
      "z": 13,
      "name": "Soil_Dirt"
    },
    {
      "x": -12,
      "y": 26,
      "z": 13,
      "name": "Soil_Dirt"
    },
    {
      "x": -12,
      "y": 27,
      "z": 13,
      "name": "Soil_Grass"
    },
    {
      "x": -12,
      "y": 28,
      "z": 13,
      "name": "Plant_Moss_Rug_Green"
    },
    {
      "x": -11,
      "y": 29,
      "z": 2,
      "name": "Rock_Stone"
    },
    {
      "x": -11,
      "y": 30,
      "z": 2,
      "name": "Soil_Grass"
    },
    {
      "x": -11,
      "y": 31,
      "z": 2,
      "name": "Plant_Moss_Rug_Green"
    },
    {
      "x": -11,
      "y": 46,
      "z": 2,
      "name": "Plant_Leaves_Ash",
      "support": 15
    },
    {
      "x": -11,
      "y": 47,
      "z": 2,
      "name": "Plant_Leaves_Ash",
      "support": 15
    },
    {
      "x": -11,
      "y": 29,
      "z": 3,
      "name": "Rock_Stone"
    },
    {
      "x": -11,
      "y": 30,
      "z": 3,
      "name": "Soil_Dirt"
    },
    {
      "x": -11,
      "y": 31,
      "z": 3,
      "name": "Soil_Dirt"
    },
    {
      "x": -11,
      "y": 32,
      "z": 3,
      "name": "Soil_Grass"
    },
    {
      "x": -11,
      "y": 44,
      "z": 3,
      "name": "Plant_Leaves_Ash",
      "support": 15
    },
    {
      "x": -11,
      "y": 45,
      "z": 3,
      "name": "Plant_Leaves_Ash",
      "support": 15
    },
    {
      "x": -11,
      "y": 46,
      "z": 3,
      "name": "Plant_Leaves_Ash",
      "support": 15
    },
    {
      "x": -11,
      "y": 47,
      "z": 3,
      "name": "Plant_Leaves_Ash",
      "support": 15
    },
    {
      "x": -11,
      "y": 49,
      "z": 3,
      "name": "Plant_Leaves_Ash",
      "support": 15
    },
    {
      "x": -11,
      "y": 51,
      "z": 3,
      "name": "Plant_Leaves_Ash",
      "support": 15
    },
    {
      "x": -11,
      "y": 52,
      "z": 3,
      "name": "Plant_Leaves_Ash",
      "support": 15
    },
    {
      "x": -11,
      "y": 26,
      "z": 4,
      "name": "Rock_Stone"
    },
    {
      "x": -11,
      "y": 27,
      "z": 4,
      "name": "Rock_Stone"
    },
    {
      "x": -11,
      "y": 28,
      "z": 4,
      "name": "Rock_Stone"
    },
    {
      "x": -11,
      "y": 29,
      "z": 4,
      "name": "Rock_Stone"
    },
    {
      "x": -11,
      "y": 30,
      "z": 4,
      "name": "Soil_Dirt"
    },
    {
      "x": -11,
      "y": 31,
      "z": 4,
      "name": "Soil_Dirt"
    },
    {
      "x": -11,
      "y": 32,
      "z": 4,
      "name": "Soil_Grass"
    },
    {
      "x": -11,
      "y": 33,
      "z": 4,
      "name": "Plant_Bush"
    },
    {
      "x": -11,
      "y": 43,
      "z": 4,
      "name": "Plant_Leaves_Ash",
      "support": 15
    },
    {
      "x": -11,
      "y": 48,
      "z": 4,
      "name": "Plant_Leaves_Ash",
      "support": 15
    },
    {
      "x": -11,
      "y": 49,
      "z": 4,
      "name": "Plant_Leaves_Ash",
      "support": 15
    },
    {
      "x": -11,
      "y": 52,
      "z": 4,
      "name": "Plant_Leaves_Ash",
      "support": 15
    },
    {
      "x": -11,
      "y": 26,
      "z": 5,
      "name": "Rock_Stone"
    },
    {
      "x": -11,
      "y": 27,
      "z": 5,
      "name": "Rock_Stone"
    },
    {
      "x": -11,
      "y": 28,
      "z": 5,
      "name": "Rock_Stone"
    },
    {
      "x": -11,
      "y": 29,
      "z": 5,
      "name": "Soil_Dirt"
    },
    {
      "x": -11,
      "y": 30,
      "z": 5,
      "name": "Rock_Stone"
    },
    {
      "x": -11,
      "y": 31,
      "z": 5,
      "name": "Rock_Stone"
    },
    {
      "x": -11,
      "y": 32,
      "z": 5,
      "name": "Rock_Stone"
    },
    {
      "x": -11,
      "y": 33,
      "z": 5,
      "name": "Rock_Stone"
    },
    {
      "x": -11,
      "y": 34,
      "z": 5,
      "name": "Plant_Bush"
    },
    {
      "x": -11,
      "y": 42,
      "z": 5,
      "name": "Plant_Leaves_Ash",
      "support": 15
    },
    {
      "x": -11,
      "y": 43,
      "z": 5,
      "name": "Plant_Leaves_Ash",
      "support": 15
    },
    {
      "x": -11,
      "y": 44,
      "z": 5,
      "name": "Plant_Leaves_Ash",
      "support": 15
    },
    {
      "x": -11,
      "y": 46,
      "z": 5,
      "name": "Plant_Leaves_Ash",
      "support": 15
    },
    {
      "x": -11,
      "y": 47,
      "z": 5,
      "name": "Plant_Leaves_Ash",
      "support": 15
    },
    {
      "x": -11,
      "y": 48,
      "z": 5,
      "name": "Wood_Ash_Trunk_Full",
      "support": 15
    },
    {
      "x": -11,
      "y": 49,
      "z": 5,
      "name": "Plant_Leaves_Ash",
      "support": 15
    },
    {
      "x": -11,
      "y": 50,
      "z": 5,
      "name": "Plant_Leaves_Ash",
      "support": 15
    },
    {
      "x": -11,
      "y": 52,
      "z": 5,
      "name": "Plant_Leaves_Ash",
      "support": 15
    },
    {
      "x": -11,
      "y": 53,
      "z": 5,
      "name": "Plant_Leaves_Ash",
      "support": 15
    },
    {
      "x": -11,
      "y": 24,
      "z": 6,
      "name": "Rock_Stone"
    },
    {
      "x": -11,
      "y": 25,
      "z": 6,
      "name": "Rock_Stone"
    },
    {
      "x": -11,
      "y": 26,
      "z": 6,
      "name": "Rock_Stone"
    },
    {
      "x": -11,
      "y": 27,
      "z": 6,
      "name": "Rock_Stone"
    },
    {
      "x": -11,
      "y": 28,
      "z": 6,
      "name": "Soil_Dirt"
    },
    {
      "x": -11,
      "y": 29,
      "z": 6,
      "name": "Soil_Dirt"
    },
    {
      "x": -11,
      "y": 30,
      "z": 6,
      "name": "Rock_Stone"
    },
    {
      "x": -11,
      "y": 31,
      "z": 6,
      "name": "Rock_Stone"
    },
    {
      "x": -11,
      "y": 32,
      "z": 6,
      "name": "Rock_Stone"
    },
    {
      "x": -11,
      "y": 33,
      "z": 6,
      "name": "Rock_Stone"
    },
    {
      "x": -11,
      "y": 34,
      "z": 6,
      "name": "Soil_Gravel"
    },
    {
      "x": -11,
      "y": 42,
      "z": 6,
      "name": "Plant_Leaves_Ash",
      "support": 15
    },
    {
      "x": -11,
      "y": 43,
      "z": 6,
      "name": "Plant_Leaves_Ash",
      "support": 15
    },
    {
      "x": -11,
      "y": 44,
      "z": 6,
      "name": "Plant_Leaves_Ash",
      "support": 15
    },
    {
      "x": -11,
      "y": 46,
      "z": 6,
      "name": "Plant_Vine_Hanging"
    },
    {
      "x": -11,
      "y": 47,
      "z": 6,
      "name": "Plant_Leaves_Ash",
      "support": 15
    },
    {
      "x": -11,
      "y": 48,
      "z": 6,
      "name": "Plant_Leaves_Ash",
      "support": 15
    },
    {
      "x": -11,
      "y": 49,
      "z": 6,
      "name": "Plant_Leaves_Ash",
      "support": 15
    },
    {
      "x": -11,
      "y": 50,
      "z": 6,
      "name": "Plant_Leaves_Ash",
      "support": 15
    },
    {
      "x": -11,
      "y": 52,
      "z": 6,
      "name": "Plant_Leaves_Ash",
      "support": 15
    },
    {
      "x": -11,
      "y": 53,
      "z": 6,
      "name": "Plant_Leaves_Ash",
      "support": 15
    },
    {
      "x": -11,
      "y": 54,
      "z": 6,
      "name": "Plant_Leaves_Ash",
      "support": 15
    },
    {
      "x": -11,
      "y": 22,
      "z": 7,
      "name": "Rock_Stone"
    },
    {
      "x": -11,
      "y": 23,
      "z": 7,
      "name": "Rock_Stone"
    },
    {
      "x": -11,
      "y": 24,
      "z": 7,
      "name": "Rock_Stone"
    },
    {
      "x": -11,
      "y": 25,
      "z": 7,
      "name": "Rock_Stone"
    },
    {
      "x": -11,
      "y": 26,
      "z": 7,
      "name": "Rock_Stone"
    },
    {
      "x": -11,
      "y": 27,
      "z": 7,
      "name": "Rock_Stone"
    },
    {
      "x": -11,
      "y": 28,
      "z": 7,
      "name": "Soil_Dirt"
    },
    {
      "x": -11,
      "y": 29,
      "z": 7,
      "name": "Soil_Dirt"
    },
    {
      "x": -11,
      "y": 30,
      "z": 7,
      "name": "Rock_Stone"
    },
    {
      "x": -11,
      "y": 31,
      "z": 7,
      "name": "Rock_Stone"
    },
    {
      "x": -11,
      "y": 32,
      "z": 7,
      "name": "Soil_Gravel"
    },
    {
      "x": -11,
      "y": 33,
      "z": 7,
      "name": "Soil_Gravel"
    },
    {
      "x": -11,
      "y": 34,
      "z": 7,
      "name": "Soil_Gravel"
    },
    {
      "x": -11,
      "y": 42,
      "z": 7,
      "name": "Plant_Vine_Hanging"
    },
    {
      "x": -11,
      "y": 43,
      "z": 7,
      "name": "Plant_Leaves_Ash",
      "support": 15
    },
    {
      "x": -11,
      "y": 47,
      "z": 7,
      "name": "Plant_Leaves_Ash",
      "support": 15
    },
    {
      "x": -11,
      "y": 49,
      "z": 7,
      "name": "Plant_Leaves_Ash",
      "support": 15
    },
    {
      "x": -11,
      "y": 52,
      "z": 7,
      "name": "Plant_Leaves_Ash",
      "support": 15
    },
    {
      "x": -11,
      "y": 53,
      "z": 7,
      "name": "Plant_Leaves_Ash",
      "support": 15
    },
    {
      "x": -11,
      "y": 14,
      "z": 8,
      "name": "Rock_Stone"
    },
    {
      "x": -11,
      "y": 15,
      "z": 8,
      "name": "Rock_Stone"
    },
    {
      "x": -11,
      "y": 16,
      "z": 8,
      "name": "Rock_Stone"
    },
    {
      "x": -11,
      "y": 17,
      "z": 8,
      "name": "Rock_Stone"
    },
    {
      "x": -11,
      "y": 18,
      "z": 8,
      "name": "Rock_Stone"
    },
    {
      "x": -11,
      "y": 19,
      "z": 8,
      "name": "Rock_Stone"
    },
    {
      "x": -11,
      "y": 20,
      "z": 8,
      "name": "Rock_Stone"
    },
    {
      "x": -11,
      "y": 21,
      "z": 8,
      "name": "Rock_Stone"
    },
    {
      "x": -11,
      "y": 22,
      "z": 8,
      "name": "Rock_Stone"
    },
    {
      "x": -11,
      "y": 23,
      "z": 8,
      "name": "Rock_Stone"
    },
    {
      "x": -11,
      "y": 24,
      "z": 8,
      "name": "Rock_Stone"
    },
    {
      "x": -11,
      "y": 25,
      "z": 8,
      "name": "Rock_Stone"
    },
    {
      "x": -11,
      "y": 26,
      "z": 8,
      "name": "Rock_Stone"
    },
    {
      "x": -11,
      "y": 27,
      "z": 8,
      "name": "Rock_Stone"
    },
    {
      "x": -11,
      "y": 28,
      "z": 8,
      "name": "Soil_Dirt"
    },
    {
      "x": -11,
      "y": 29,
      "z": 8,
      "name": "Rock_Stone"
    },
    {
      "x": -11,
      "y": 30,
      "z": 8,
      "name": "Rock_Stone"
    },
    {
      "x": -11,
      "y": 31,
      "z": 8,
      "name": "Rock_Stone"
    },
    {
      "x": -11,
      "y": 32,
      "z": 8,
      "name": "Rock_Stone_Mossy"
    },
    {
      "x": -11,
      "y": 33,
      "z": 8,
      "name": "Rock_Stone"
    },
    {
      "x": -11,
      "y": 34,
      "z": 8,
      "name": "Soil_Gravel"
    },
    {
      "x": -11,
      "y": 13,
      "z": 9,
      "name": "Rock_Stone"
    },
    {
      "x": -11,
      "y": 14,
      "z": 9,
      "name": "Rock_Stone"
    },
    {
      "x": -11,
      "y": 15,
      "z": 9,
      "name": "Rock_Stone"
    },
    {
      "x": -11,
      "y": 16,
      "z": 9,
      "name": "Rock_Stone"
    },
    {
      "x": -11,
      "y": 17,
      "z": 9,
      "name": "Rock_Stone"
    },
    {
      "x": -11,
      "y": 18,
      "z": 9,
      "name": "Rock_Stone"
    },
    {
      "x": -11,
      "y": 19,
      "z": 9,
      "name": "Rock_Stone"
    },
    {
      "x": -11,
      "y": 20,
      "z": 9,
      "name": "Rock_Stone"
    },
    {
      "x": -11,
      "y": 21,
      "z": 9,
      "name": "Rock_Stone"
    },
    {
      "x": -11,
      "y": 22,
      "z": 9,
      "name": "Rock_Stone"
    },
    {
      "x": -11,
      "y": 23,
      "z": 9,
      "name": "Rock_Stone"
    },
    {
      "x": -11,
      "y": 24,
      "z": 9,
      "name": "Rock_Stone"
    },
    {
      "x": -11,
      "y": 25,
      "z": 9,
      "name": "Rock_Stone"
    },
    {
      "x": -11,
      "y": 26,
      "z": 9,
      "name": "Rock_Stone"
    },
    {
      "x": -11,
      "y": 27,
      "z": 9,
      "name": "Rock_Stone"
    },
    {
      "x": -11,
      "y": 28,
      "z": 9,
      "name": "Soil_Dirt"
    },
    {
      "x": -11,
      "y": 29,
      "z": 9,
      "name": "Rock_Stone"
    },
    {
      "x": -11,
      "y": 30,
      "z": 9,
      "name": "Rock_Stone_Mossy"
    },
    {
      "x": -11,
      "y": 31,
      "z": 9,
      "name": "Rock_Stone_Mossy"
    },
    {
      "x": -11,
      "y": 32,
      "z": 9,
      "name": "Soil_Gravel"
    },
    {
      "x": -11,
      "y": 45,
      "z": 9,
      "name": "Plant_Leaves_Ash",
      "support": 15
    },
    {
      "x": -11,
      "y": 46,
      "z": 9,
      "name": "Plant_Leaves_Ash",
      "support": 15
    },
    {
      "x": -11,
      "y": 47,
      "z": 9,
      "name": "Plant_Leaves_Ash",
      "support": 15
    },
    {
      "x": -11,
      "y": 13,
      "z": 10,
      "name": "Rock_Stone"
    },
    {
      "x": -11,
      "y": 14,
      "z": 10,
      "name": "Rock_Stone"
    },
    {
      "x": -11,
      "y": 15,
      "z": 10,
      "name": "Rock_Stone"
    },
    {
      "x": -11,
      "y": 16,
      "z": 10,
      "name": "Rock_Stone"
    },
    {
      "x": -11,
      "y": 17,
      "z": 10,
      "name": "Rock_Stone"
    },
    {
      "x": -11,
      "y": 18,
      "z": 10,
      "name": "Rock_Stone"
    },
    {
      "x": -11,
      "y": 19,
      "z": 10,
      "name": "Rock_Stone"
    },
    {
      "x": -11,
      "y": 20,
      "z": 10,
      "name": "Rock_Stone"
    },
    {
      "x": -11,
      "y": 21,
      "z": 10,
      "name": "Rock_Stone"
    },
    {
      "x": -11,
      "y": 22,
      "z": 10,
      "name": "Rock_Stone"
    },
    {
      "x": -11,
      "y": 23,
      "z": 10,
      "name": "Rock_Stone"
    },
    {
      "x": -11,
      "y": 24,
      "z": 10,
      "name": "Rock_Stone"
    },
    {
      "x": -11,
      "y": 25,
      "z": 10,
      "name": "Rock_Stone"
    },
    {
      "x": -11,
      "y": 26,
      "z": 10,
      "name": "Rock_Stone"
    },
    {
      "x": -11,
      "y": 27,
      "z": 10,
      "name": "Soil_Dirt"
    },
    {
      "x": -11,
      "y": 28,
      "z": 10,
      "name": "Soil_Dirt"
    },
    {
      "x": -11,
      "y": 29,
      "z": 10,
      "name": "Rock_Stone"
    },
    {
      "x": -11,
      "y": 30,
      "z": 10,
      "name": "Rock_Stone"
    },
    {
      "x": -11,
      "y": 31,
      "z": 10,
      "name": "Rock_Stone"
    },
    {
      "x": -11,
      "y": 32,
      "z": 10,
      "name": "Rock_Stone_Mossy"
    },
    {
      "x": -11,
      "y": 44,
      "z": 10,
      "name": "Plant_Vine_Hanging"
    },
    {
      "x": -11,
      "y": 45,
      "z": 10,
      "name": "Plant_Leaves_Ash",
      "support": 15
    },
    {
      "x": -11,
      "y": 46,
      "z": 10,
      "name": "Wood_Ash_Trunk_Full",
      "support": 15
    },
    {
      "x": -11,
      "y": 47,
      "z": 10,
      "name": "Plant_Leaves_Ash",
      "support": 15
    },
    {
      "x": -11,
      "y": 48,
      "z": 10,
      "name": "Plant_Leaves_Ash",
      "support": 15
    },
    {
      "x": -11,
      "y": 14,
      "z": 11,
      "name": "Rock_Stone"
    },
    {
      "x": -11,
      "y": 15,
      "z": 11,
      "name": "Rock_Stone"
    },
    {
      "x": -11,
      "y": 16,
      "z": 11,
      "name": "Rock_Stone"
    },
    {
      "x": -11,
      "y": 17,
      "z": 11,
      "name": "Rock_Stone"
    },
    {
      "x": -11,
      "y": 18,
      "z": 11,
      "name": "Rock_Stone"
    },
    {
      "x": -11,
      "y": 19,
      "z": 11,
      "name": "Rock_Stone"
    },
    {
      "x": -11,
      "y": 20,
      "z": 11,
      "name": "Rock_Stone"
    },
    {
      "x": -11,
      "y": 21,
      "z": 11,
      "name": "Rock_Stone"
    },
    {
      "x": -11,
      "y": 22,
      "z": 11,
      "name": "Rock_Stone"
    },
    {
      "x": -11,
      "y": 23,
      "z": 11,
      "name": "Rock_Stone"
    },
    {
      "x": -11,
      "y": 24,
      "z": 11,
      "name": "Rock_Stone"
    },
    {
      "x": -11,
      "y": 25,
      "z": 11,
      "name": "Rock_Stone"
    },
    {
      "x": -11,
      "y": 26,
      "z": 11,
      "name": "Rock_Stone"
    },
    {
      "x": -11,
      "y": 27,
      "z": 11,
      "name": "Soil_Dirt"
    },
    {
      "x": -11,
      "y": 28,
      "z": 11,
      "name": "Soil_Dirt"
    },
    {
      "x": -11,
      "y": 29,
      "z": 11,
      "name": "Soil_Dirt"
    },
    {
      "x": -11,
      "y": 30,
      "z": 11,
      "name": "Soil_Grass"
    },
    {
      "x": -11,
      "y": 45,
      "z": 11,
      "name": "Plant_Leaves_Ash",
      "support": 15
    },
    {
      "x": -11,
      "y": 46,
      "z": 11,
      "name": "Plant_Leaves_Ash",
      "support": 15
    },
    {
      "x": -11,
      "y": 47,
      "z": 11,
      "name": "Plant_Leaves_Ash",
      "support": 15
    },
    {
      "x": -11,
      "y": 14,
      "z": 12,
      "name": "Rock_Stone"
    },
    {
      "x": -11,
      "y": 15,
      "z": 12,
      "name": "Rock_Stone"
    },
    {
      "x": -11,
      "y": 16,
      "z": 12,
      "name": "Rock_Stone"
    },
    {
      "x": -11,
      "y": 17,
      "z": 12,
      "name": "Rock_Stone"
    },
    {
      "x": -11,
      "y": 21,
      "z": 12,
      "name": "Rock_Stone"
    },
    {
      "x": -11,
      "y": 22,
      "z": 12,
      "name": "Rock_Stone"
    },
    {
      "x": -11,
      "y": 23,
      "z": 12,
      "name": "Rock_Stone"
    },
    {
      "x": -11,
      "y": 24,
      "z": 12,
      "name": "Rock_Stone"
    },
    {
      "x": -11,
      "y": 25,
      "z": 12,
      "name": "Rock_Stone"
    },
    {
      "x": -11,
      "y": 26,
      "z": 12,
      "name": "Soil_Dirt"
    },
    {
      "x": -11,
      "y": 27,
      "z": 12,
      "name": "Soil_Dirt"
    },
    {
      "x": -11,
      "y": 28,
      "z": 12,
      "name": "Soil_Dirt"
    },
    {
      "x": -11,
      "y": 29,
      "z": 12,
      "name": "Soil_Grass"
    },
    {
      "x": -11,
      "y": 46,
      "z": 12,
      "name": "Plant_Leaves_Ash",
      "support": 15
    },
    {
      "x": -11,
      "y": 23,
      "z": 13,
      "name": "Rock_Stone"
    },
    {
      "x": -11,
      "y": 24,
      "z": 13,
      "name": "Rock_Stone"
    },
    {
      "x": -11,
      "y": 25,
      "z": 13,
      "name": "Rock_Stone"
    },
    {
      "x": -11,
      "y": 26,
      "z": 13,
      "name": "Rock_Stone"
    },
    {
      "x": -11,
      "y": 27,
      "z": 13,
      "name": "Soil_Dirt"
    },
    {
      "x": -11,
      "y": 28,
      "z": 13,
      "name": "Soil_Grass"
    },
    {
      "x": -10,
      "y": 30,
      "z": 0,
      "name": "Soil_Grass"
    },
    {
      "x": -10,
      "y": 44,
      "z": 0,
      "name": "Plant_Leaves_Ash",
      "support": 15
    },
    {
      "x": -10,
      "y": 45,
      "z": 0,
      "name": "Plant_Leaves_Ash",
      "support": 15
    },
    {
      "x": -10,
      "y": 46,
      "z": 0,
      "name": "Plant_Leaves_Ash",
      "support": 15
    },
    {
      "x": -10,
      "y": 30,
      "z": 1,
      "name": "Soil_Dirt"
    },
    {
      "x": -10,
      "y": 31,
      "z": 1,
      "name": "Soil_Grass"
    },
    {
      "x": -10,
      "y": 46,
      "z": 1,
      "name": "Plant_Leaves_Ash",
      "support": 15
    },
    {
      "x": -10,
      "y": 47,
      "z": 1,
      "name": "Plant_Leaves_Ash",
      "support": 15
    },
    {
      "x": -10,
      "y": 48,
      "z": 1,
      "name": "Plant_Leaves_Ash",
      "support": 15
    },
    {
      "x": -10,
      "y": 28,
      "z": 2,
      "name": "Rock_Stone"
    },
    {
      "x": -10,
      "y": 29,
      "z": 2,
      "name": "Soil_Dirt"
    },
    {
      "x": -10,
      "y": 30,
      "z": 2,
      "name": "Soil_Dirt"
    },
    {
      "x": -10,
      "y": 31,
      "z": 2,
      "name": "Soil_Grass"
    },
    {
      "x": -10,
      "y": 44,
      "z": 2,
      "name": "Plant_Vine_Hanging"
    },
    {
      "x": -10,
      "y": 45,
      "z": 2,
      "name": "Plant_Leaves_Ash",
      "support": 15
    },
    {
      "x": -10,
      "y": 46,
      "z": 2,
      "name": "Plant_Leaves_Ash",
      "support": 15
    },
    {
      "x": -10,
      "y": 47,
      "z": 2,
      "name": "Wood_Ash_Trunk_Full",
      "support": 15
    },
    {
      "x": -10,
      "y": 48,
      "z": 2,
      "name": "Plant_Leaves_Ash",
      "support": 15
    },
    {
      "x": -10,
      "y": 50,
      "z": 2,
      "name": "Plant_Leaves_Ash",
      "support": 15
    },
    {
      "x": -10,
      "y": 51,
      "z": 2,
      "name": "Plant_Leaves_Ash",
      "support": 15
    },
    {
      "x": -10,
      "y": 52,
      "z": 2,
      "name": "Plant_Leaves_Ash",
      "support": 15
    },
    {
      "x": -10,
      "y": 27,
      "z": 3,
      "name": "Rock_Stone"
    },
    {
      "x": -10,
      "y": 28,
      "z": 3,
      "name": "Rock_Stone"
    },
    {
      "x": -10,
      "y": 29,
      "z": 3,
      "name": "Rock_Stone"
    },
    {
      "x": -10,
      "y": 30,
      "z": 3,
      "name": "Soil_Dirt"
    },
    {
      "x": -10,
      "y": 31,
      "z": 3,
      "name": "Soil_Dirt"
    },
    {
      "x": -10,
      "y": 32,
      "z": 3,
      "name": "Soil_Grass"
    },
    {
      "x": -10,
      "y": 46,
      "z": 3,
      "name": "Plant_Leaves_Ash",
      "support": 15
    },
    {
      "x": -10,
      "y": 47,
      "z": 3,
      "name": "Plant_Leaves_Ash",
      "support": 15
    },
    {
      "x": -10,
      "y": 48,
      "z": 3,
      "name": "Plant_Leaves_Ash",
      "support": 15
    },
    {
      "x": -10,
      "y": 49,
      "z": 3,
      "name": "Plant_Leaves_Ash",
      "support": 15
    },
    {
      "x": -10,
      "y": 51,
      "z": 3,
      "name": "Plant_Leaves_Ash",
      "support": 15
    },
    {
      "x": -10,
      "y": 52,
      "z": 3,
      "name": "Plant_Leaves_Ash",
      "support": 15
    },
    {
      "x": -10,
      "y": 53,
      "z": 3,
      "name": "Plant_Leaves_Ash",
      "support": 15
    },
    {
      "x": -10,
      "y": 26,
      "z": 4,
      "name": "Rock_Stone"
    },
    {
      "x": -10,
      "y": 27,
      "z": 4,
      "name": "Rock_Stone"
    },
    {
      "x": -10,
      "y": 28,
      "z": 4,
      "name": "Rock_Stone"
    },
    {
      "x": -10,
      "y": 29,
      "z": 4,
      "name": "Rock_Stone"
    },
    {
      "x": -10,
      "y": 30,
      "z": 4,
      "name": "Soil_Dirt"
    },
    {
      "x": -10,
      "y": 31,
      "z": 4,
      "name": "Soil_Dirt"
    },
    {
      "x": -10,
      "y": 32,
      "z": 4,
      "name": "Soil_Grass"
    },
    {
      "x": -10,
      "y": 40,
      "z": 4,
      "name": "Plant_Leaves_Ash",
      "support": 15
    },
    {
      "x": -10,
      "y": 41,
      "z": 4,
      "name": "Plant_Leaves_Ash",
      "support": 15
    },
    {
      "x": -10,
      "y": 42,
      "z": 4,
      "name": "Plant_Leaves_Ash",
      "support": 15
    },
    {
      "x": -10,
      "y": 43,
      "z": 4,
      "name": "Plant_Leaves_Ash",
      "support": 15
    },
    {
      "x": -10,
      "y": 44,
      "z": 4,
      "name": "Plant_Leaves_Ash",
      "support": 15
    },
    {
      "x": -10,
      "y": 49,
      "z": 4,
      "name": "Plant_Leaves_Ash",
      "support": 15
    },
    {
      "x": -10,
      "y": 53,
      "z": 4,
      "name": "Plant_Leaves_Ash",
      "support": 15
    },
    {
      "x": -10,
      "y": 54,
      "z": 4,
      "name": "Plant_Leaves_Ash",
      "support": 15
    },
    {
      "x": -10,
      "y": 26,
      "z": 5,
      "name": "Rock_Stone"
    },
    {
      "x": -10,
      "y": 27,
      "z": 5,
      "name": "Rock_Stone"
    },
    {
      "x": -10,
      "y": 28,
      "z": 5,
      "name": "Rock_Stone"
    },
    {
      "x": -10,
      "y": 29,
      "z": 5,
      "name": "Rock_Stone"
    },
    {
      "x": -10,
      "y": 30,
      "z": 5,
      "name": "Soil_Dirt"
    },
    {
      "x": -10,
      "y": 31,
      "z": 5,
      "name": "Soil_Dirt"
    },
    {
      "x": -10,
      "y": 32,
      "z": 5,
      "name": "Soil_Grass"
    },
    {
      "x": -10,
      "y": 33,
      "z": 5,
      "name": "Plant_Bush"
    },
    {
      "x": -10,
      "y": 41,
      "z": 5,
      "name": "Plant_Vine_Hanging"
    },
    {
      "x": -10,
      "y": 42,
      "z": 5,
      "name": "Plant_Leaves_Ash",
      "support": 15
    },
    {
      "x": -10,
      "y": 43,
      "z": 5,
      "name": "Wood_Ash_Trunk_Full",
      "support": 15
    },
    {
      "x": -10,
      "y": 44,
      "z": 5,
      "name": "Plant_Leaves_Ash",
      "support": 15
    },
    {
      "x": -10,
      "y": 48,
      "z": 5,
      "name": "Wood_Ash_Trunk_Full",
      "support": 15
    },
    {
      "x": -10,
      "y": 49,
      "z": 5,
      "name": "Plant_Leaves_Ash",
      "support": 15
    },
    {
      "x": -10,
      "y": 50,
      "z": 5,
      "name": "Plant_Leaves_Ash",
      "support": 15
    },
    {
      "x": -10,
      "y": 52,
      "z": 5,
      "name": "Plant_Leaves_Ash",
      "support": 15
    },
    {
      "x": -10,
      "y": 53,
      "z": 5,
      "name": "Plant_Leaves_Ash",
      "support": 15
    },
    {
      "x": -10,
      "y": 54,
      "z": 5,
      "name": "Plant_Leaves_Ash",
      "support": 15
    },
    {
      "x": -10,
      "y": 25,
      "z": 6,
      "name": "Rock_Stone"
    },
    {
      "x": -10,
      "y": 26,
      "z": 6,
      "name": "Rock_Stone"
    },
    {
      "x": -10,
      "y": 27,
      "z": 6,
      "name": "Rock_Stone"
    },
    {
      "x": -10,
      "y": 28,
      "z": 6,
      "name": "Rock_Stone"
    },
    {
      "x": -10,
      "y": 29,
      "z": 6,
      "name": "Rock_Stone"
    },
    {
      "x": -10,
      "y": 30,
      "z": 6,
      "name": "Soil_Dirt"
    },
    {
      "x": -10,
      "y": 31,
      "z": 6,
      "name": "Soil_Dirt"
    },
    {
      "x": -10,
      "y": 32,
      "z": 6,
      "name": "Soil_Grass"
    },
    {
      "x": -10,
      "y": 33,
      "z": 6,
      "name": "Plant_Bush"
    },
    {
      "x": -10,
      "y": 41,
      "z": 6,
      "name": "Plant_Leaves_Ash",
      "support": 15
    },
    {
      "x": -10,
      "y": 42,
      "z": 6,
      "name": "Plant_Leaves_Ash",
      "support": 15
    },
    {
      "x": -10,
      "y": 43,
      "z": 6,
      "name": "Plant_Leaves_Ash",
      "support": 15
    },
    {
      "x": -10,
      "y": 44,
      "z": 6,
      "name": "Plant_Leaves_Ash",
      "support": 15
    },
    {
      "x": -10,
      "y": 49,
      "z": 6,
      "name": "Plant_Leaves_Ash",
      "support": 15
    },
    {
      "x": -10,
      "y": 52,
      "z": 6,
      "name": "Plant_Leaves_Ash",
      "support": 15
    },
    {
      "x": -10,
      "y": 53,
      "z": 6,
      "name": "Wood_Ash_Trunk_Full",
      "support": 15
    },
    {
      "x": -10,
      "y": 54,
      "z": 6,
      "name": "Plant_Leaves_Ash",
      "support": 15
    },
    {
      "x": -10,
      "y": 24,
      "z": 7,
      "name": "Rock_Stone"
    },
    {
      "x": -10,
      "y": 25,
      "z": 7,
      "name": "Rock_Stone"
    },
    {
      "x": -10,
      "y": 26,
      "z": 7,
      "name": "Rock_Stone"
    },
    {
      "x": -10,
      "y": 27,
      "z": 7,
      "name": "Rock_Stone"
    },
    {
      "x": -10,
      "y": 28,
      "z": 7,
      "name": "Rock_Stone"
    },
    {
      "x": -10,
      "y": 29,
      "z": 7,
      "name": "Soil_Dirt"
    },
    {
      "x": -10,
      "y": 30,
      "z": 7,
      "name": "Rock_Stone"
    },
    {
      "x": -10,
      "y": 31,
      "z": 7,
      "name": "Rock_Stone"
    },
    {
      "x": -10,
      "y": 32,
      "z": 7,
      "name": "Rock_Stone"
    },
    {
      "x": -10,
      "y": 33,
      "z": 7,
      "name": "Rock_Stone"
    },
    {
      "x": -10,
      "y": 34,
      "z": 7,
      "name": "Soil_Gravel"
    },
    {
      "x": -10,
      "y": 40,
      "z": 7,
      "name": "Plant_Leaves_Ash",
      "support": 15
    },
    {
      "x": -10,
      "y": 41,
      "z": 7,
      "name": "Plant_Leaves_Ash",
      "support": 15
    },
    {
      "x": -10,
      "y": 42,
      "z": 7,
      "name": "Plant_Leaves_Ash",
      "support": 15
    },
    {
      "x": -10,
      "y": 43,
      "z": 7,
      "name": "Plant_Leaves_Ash",
      "support": 15
    },
    {
      "x": -10,
      "y": 45,
      "z": 7,
      "name": "Plant_Leaves_Ash",
      "support": 15
    },
    {
      "x": -10,
      "y": 46,
      "z": 7,
      "name": "Plant_Leaves_Ash",
      "support": 15
    },
    {
      "x": -10,
      "y": 47,
      "z": 7,
      "name": "Plant_Leaves_Ash",
      "support": 15
    },
    {
      "x": -10,
      "y": 48,
      "z": 7,
      "name": "Plant_Leaves_Ash",
      "support": 15
    },
    {
      "x": -10,
      "y": 49,
      "z": 7,
      "name": "Plant_Leaves_Ash",
      "support": 15
    },
    {
      "x": -10,
      "y": 50,
      "z": 7,
      "name": "Plant_Leaves_Ash",
      "support": 15
    },
    {
      "x": -10,
      "y": 51,
      "z": 7,
      "name": "Plant_Leaves_Ash",
      "support": 15
    },
    {
      "x": -10,
      "y": 52,
      "z": 7,
      "name": "Plant_Leaves_Ash",
      "support": 15
    },
    {
      "x": -10,
      "y": 53,
      "z": 7,
      "name": "Plant_Leaves_Ash",
      "support": 15
    },
    {
      "x": -10,
      "y": 54,
      "z": 7,
      "name": "Plant_Leaves_Ash",
      "support": 15
    },
    {
      "x": -10,
      "y": 13,
      "z": 8,
      "name": "Rock_Stone"
    },
    {
      "x": -10,
      "y": 14,
      "z": 8,
      "name": "Rock_Stone"
    },
    {
      "x": -10,
      "y": 15,
      "z": 8,
      "name": "Rock_Stone"
    },
    {
      "x": -10,
      "y": 16,
      "z": 8,
      "name": "Rock_Stone"
    },
    {
      "x": -10,
      "y": 23,
      "z": 8,
      "name": "Rock_Stone"
    },
    {
      "x": -10,
      "y": 24,
      "z": 8,
      "name": "Rock_Stone"
    },
    {
      "x": -10,
      "y": 25,
      "z": 8,
      "name": "Rock_Stone"
    },
    {
      "x": -10,
      "y": 26,
      "z": 8,
      "name": "Rock_Stone"
    },
    {
      "x": -10,
      "y": 27,
      "z": 8,
      "name": "Rock_Stone"
    },
    {
      "x": -10,
      "y": 28,
      "z": 8,
      "name": "Rock_Stone"
    },
    {
      "x": -10,
      "y": 29,
      "z": 8,
      "name": "Rock_Stone"
    },
    {
      "x": -10,
      "y": 30,
      "z": 8,
      "name": "Rock_Stone"
    },
    {
      "x": -10,
      "y": 31,
      "z": 8,
      "name": "Rock_Stone"
    },
    {
      "x": -10,
      "y": 32,
      "z": 8,
      "name": "Rock_Stone"
    },
    {
      "x": -10,
      "y": 33,
      "z": 8,
      "name": "Rock_Stone"
    },
    {
      "x": -10,
      "y": 34,
      "z": 8,
      "name": "Rock_Stone"
    },
    {
      "x": -10,
      "y": 42,
      "z": 8,
      "name": "Plant_Leaves_Ash",
      "support": 15
    },
    {
      "x": -10,
      "y": 47,
      "z": 8,
      "name": "Plant_Leaves_Ash",
      "support": 15
    },
    {
      "x": -10,
      "y": 48,
      "z": 8,
      "name": "Plant_Leaves_Ash",
      "support": 15
    },
    {
      "x": -10,
      "y": 49,
      "z": 8,
      "name": "Plant_Leaves_Ash",
      "support": 15
    },
    {
      "x": -10,
      "y": 51,
      "z": 8,
      "name": "Plant_Vine_Hanging"
    },
    {
      "x": -10,
      "y": 52,
      "z": 8,
      "name": "Plant_Leaves_Ash",
      "support": 15
    },
    {
      "x": -10,
      "y": 53,
      "z": 8,
      "name": "Plant_Leaves_Ash",
      "support": 15
    },
    {
      "x": -10,
      "y": 12,
      "z": 9,
      "name": "Rock_Stone"
    },
    {
      "x": -10,
      "y": 13,
      "z": 9,
      "name": "Rock_Stone"
    },
    {
      "x": -10,
      "y": 14,
      "z": 9,
      "name": "Rock_Stone"
    },
    {
      "x": -10,
      "y": 15,
      "z": 9,
      "name": "Rock_Stone"
    },
    {
      "x": -10,
      "y": 16,
      "z": 9,
      "name": "Rock_Stone"
    },
    {
      "x": -10,
      "y": 17,
      "z": 9,
      "name": "Rock_Stone"
    },
    {
      "x": -10,
      "y": 18,
      "z": 9,
      "name": "Rock_Stone"
    },
    {
      "x": -10,
      "y": 19,
      "z": 9,
      "name": "Rock_Stone"
    },
    {
      "x": -10,
      "y": 20,
      "z": 9,
      "name": "Rock_Stone"
    },
    {
      "x": -10,
      "y": 21,
      "z": 9,
      "name": "Rock_Stone"
    },
    {
      "x": -10,
      "y": 22,
      "z": 9,
      "name": "Rock_Stone"
    },
    {
      "x": -10,
      "y": 23,
      "z": 9,
      "name": "Rock_Stone"
    },
    {
      "x": -10,
      "y": 24,
      "z": 9,
      "name": "Rock_Stone"
    },
    {
      "x": -10,
      "y": 25,
      "z": 9,
      "name": "Rock_Stone"
    },
    {
      "x": -10,
      "y": 26,
      "z": 9,
      "name": "Rock_Stone"
    },
    {
      "x": -10,
      "y": 27,
      "z": 9,
      "name": "Rock_Stone"
    },
    {
      "x": -10,
      "y": 28,
      "z": 9,
      "name": "Rock_Stone"
    },
    {
      "x": -10,
      "y": 29,
      "z": 9,
      "name": "Soil_Dirt"
    },
    {
      "x": -10,
      "y": 30,
      "z": 9,
      "name": "Rock_Stone"
    },
    {
      "x": -10,
      "y": 31,
      "z": 9,
      "name": "Rock_Stone"
    },
    {
      "x": -10,
      "y": 32,
      "z": 9,
      "name": "Rock_Stone_Mossy"
    },
    {
      "x": -10,
      "y": 33,
      "z": 9,
      "name": "Rock_Stone"
    },
    {
      "x": -10,
      "y": 48,
      "z": 9,
      "name": "Plant_Leaves_Ash",
      "support": 15
    },
    {
      "x": -10,
      "y": 51,
      "z": 9,
      "name": "Plant_Leaves_Ash",
      "support": 15
    },
    {
      "x": -10,
      "y": 52,
      "z": 9,
      "name": "Plant_Leaves_Ash",
      "support": 15
    },
    {
      "x": -10,
      "y": 53,
      "z": 9,
      "name": "Plant_Leaves_Ash",
      "support": 15
    },
    {
      "x": -10,
      "y": 54,
      "z": 9,
      "name": "Plant_Leaves_Ash",
      "support": 15
    },
    {
      "x": -10,
      "y": 12,
      "z": 10,
      "name": "Rock_Stone"
    },
    {
      "x": -10,
      "y": 13,
      "z": 10,
      "name": "Rock_Stone"
    },
    {
      "x": -10,
      "y": 14,
      "z": 10,
      "name": "Rock_Stone"
    },
    {
      "x": -10,
      "y": 15,
      "z": 10,
      "name": "Rock_Stone"
    },
    {
      "x": -10,
      "y": 16,
      "z": 10,
      "name": "Rock_Stone"
    },
    {
      "x": -10,
      "y": 17,
      "z": 10,
      "name": "Rock_Stone"
    },
    {
      "x": -10,
      "y": 18,
      "z": 10,
      "name": "Rock_Stone"
    },
    {
      "x": -10,
      "y": 19,
      "z": 10,
      "name": "Rock_Stone"
    },
    {
      "x": -10,
      "y": 20,
      "z": 10,
      "name": "Rock_Stone"
    },
    {
      "x": -10,
      "y": 21,
      "z": 10,
      "name": "Rock_Stone"
    },
    {
      "x": -10,
      "y": 22,
      "z": 10,
      "name": "Rock_Stone"
    },
    {
      "x": -10,
      "y": 23,
      "z": 10,
      "name": "Rock_Stone"
    },
    {
      "x": -10,
      "y": 24,
      "z": 10,
      "name": "Rock_Stone"
    },
    {
      "x": -10,
      "y": 25,
      "z": 10,
      "name": "Rock_Stone"
    },
    {
      "x": -10,
      "y": 26,
      "z": 10,
      "name": "Rock_Stone"
    },
    {
      "x": -10,
      "y": 27,
      "z": 10,
      "name": "Rock_Stone"
    },
    {
      "x": -10,
      "y": 28,
      "z": 10,
      "name": "Soil_Dirt"
    },
    {
      "x": -10,
      "y": 29,
      "z": 10,
      "name": "Soil_Dirt"
    },
    {
      "x": -10,
      "y": 30,
      "z": 10,
      "name": "Soil_Dirt"
    },
    {
      "x": -10,
      "y": 31,
      "z": 10,
      "name": "Soil_Dirt"
    },
    {
      "x": -10,
      "y": 32,
      "z": 10,
      "name": "Rock_Stone"
    },
    {
      "x": -10,
      "y": 46,
      "z": 10,
      "name": "Wood_Ash_Trunk_Full",
      "support": 15
    },
    {
      "x": -10,
      "y": 47,
      "z": 10,
      "name": "Plant_Leaves_Ash",
      "support": 15
    },
    {
      "x": -10,
      "y": 48,
      "z": 10,
      "name": "Plant_Leaves_Ash",
      "support": 15
    },
    {
      "x": -10,
      "y": 50,
      "z": 10,
      "name": "Plant_Leaves_Ash",
      "support": 15
    },
    {
      "x": -10,
      "y": 51,
      "z": 10,
      "name": "Plant_Leaves_Ash",
      "support": 15
    },
    {
      "x": -10,
      "y": 52,
      "z": 10,
      "name": "Plant_Leaves_Ash",
      "support": 15
    },
    {
      "x": -10,
      "y": 53,
      "z": 10,
      "name": "Plant_Leaves_Ash",
      "support": 15
    },
    {
      "x": -10,
      "y": 12,
      "z": 11,
      "name": "Rock_Stone"
    },
    {
      "x": -10,
      "y": 13,
      "z": 11,
      "name": "Rock_Stone"
    },
    {
      "x": -10,
      "y": 14,
      "z": 11,
      "name": "Rock_Stone"
    },
    {
      "x": -10,
      "y": 15,
      "z": 11,
      "name": "Rock_Stone"
    },
    {
      "x": -10,
      "y": 16,
      "z": 11,
      "name": "Rock_Stone"
    },
    {
      "x": -10,
      "y": 17,
      "z": 11,
      "name": "Rock_Stone"
    },
    {
      "x": -10,
      "y": 18,
      "z": 11,
      "name": "Rock_Stone"
    },
    {
      "x": -10,
      "y": 19,
      "z": 11,
      "name": "Rock_Stone"
    },
    {
      "x": -10,
      "y": 20,
      "z": 11,
      "name": "Rock_Stone"
    },
    {
      "x": -10,
      "y": 21,
      "z": 11,
      "name": "Rock_Stone"
    },
    {
      "x": -10,
      "y": 22,
      "z": 11,
      "name": "Rock_Stone"
    },
    {
      "x": -10,
      "y": 23,
      "z": 11,
      "name": "Rock_Stone"
    },
    {
      "x": -10,
      "y": 24,
      "z": 11,
      "name": "Rock_Stone"
    },
    {
      "x": -10,
      "y": 25,
      "z": 11,
      "name": "Rock_Stone"
    },
    {
      "x": -10,
      "y": 26,
      "z": 11,
      "name": "Rock_Stone"
    },
    {
      "x": -10,
      "y": 27,
      "z": 11,
      "name": "Soil_Dirt"
    },
    {
      "x": -10,
      "y": 28,
      "z": 11,
      "name": "Soil_Dirt"
    },
    {
      "x": -10,
      "y": 29,
      "z": 11,
      "name": "Soil_Dirt"
    },
    {
      "x": -10,
      "y": 30,
      "z": 11,
      "name": "Soil_Grass"
    },
    {
      "x": -10,
      "y": 43,
      "z": 11,
      "name": "Plant_Leaves_Ash",
      "support": 15
    },
    {
      "x": -10,
      "y": 44,
      "z": 11,
      "name": "Plant_Leaves_Ash",
      "support": 15
    },
    {
      "x": -10,
      "y": 45,
      "z": 11,
      "name": "Plant_Leaves_Ash",
      "support": 15
    },
    {
      "x": -10,
      "y": 46,
      "z": 11,
      "name": "Plant_Leaves_Ash",
      "support": 15
    },
    {
      "x": -10,
      "y": 47,
      "z": 11,
      "name": "Plant_Leaves_Ash",
      "support": 15
    },
    {
      "x": -10,
      "y": 48,
      "z": 11,
      "name": "Plant_Leaves_Ash",
      "support": 15
    },
    {
      "x": -10,
      "y": 13,
      "z": 12,
      "name": "Rock_Stone"
    },
    {
      "x": -10,
      "y": 14,
      "z": 12,
      "name": "Rock_Stone"
    },
    {
      "x": -10,
      "y": 24,
      "z": 12,
      "name": "Rock_Stone"
    },
    {
      "x": -10,
      "y": 25,
      "z": 12,
      "name": "Rock_Stone"
    },
    {
      "x": -10,
      "y": 26,
      "z": 12,
      "name": "Rock_Stone"
    },
    {
      "x": -10,
      "y": 27,
      "z": 12,
      "name": "Soil_Dirt"
    },
    {
      "x": -10,
      "y": 28,
      "z": 12,
      "name": "Soil_Dirt"
    },
    {
      "x": -10,
      "y": 29,
      "z": 12,
      "name": "Soil_Grass"
    },
    {
      "x": -10,
      "y": 44,
      "z": 12,
      "name": "Plant_Vine_Hanging"
    },
    {
      "x": -10,
      "y": 45,
      "z": 12,
      "name": "Plant_Leaves_Ash",
      "support": 15
    },
    {
      "x": -10,
      "y": 46,
      "z": 12,
      "name": "Plant_Leaves_Ash",
      "support": 15
    },
    {
      "x": -10,
      "y": 47,
      "z": 12,
      "name": "Plant_Leaves_Ash",
      "support": 15
    },
    {
      "x": -10,
      "y": 26,
      "z": 13,
      "name": "Rock_Stone"
    },
    {
      "x": -10,
      "y": 27,
      "z": 13,
      "name": "Soil_Dirt"
    },
    {
      "x": -10,
      "y": 28,
      "z": 13,
      "name": "Soil_Grass"
    },
    {
      "x": -10,
      "y": 46,
      "z": 13,
      "name": "Plant_Leaves_Ash",
      "support": 15
    },
    {
      "x": -9,
      "y": 30,
      "z": -1,
      "name": "Rock_Stone"
    },
    {
      "x": -9,
      "y": 31,
      "z": -1,
      "name": "Soil_Grass"
    },
    {
      "x": -9,
      "y": 45,
      "z": -1,
      "name": "Plant_Vine_Hanging"
    },
    {
      "x": -9,
      "y": 46,
      "z": -1,
      "name": "Plant_Leaves_Ash",
      "support": 15
    },
    {
      "x": -9,
      "y": 47,
      "z": -1,
      "name": "Plant_Leaves_Ash",
      "support": 15
    },
    {
      "x": -9,
      "y": 30,
      "z": 0,
      "name": "Soil_Dirt"
    },
    {
      "x": -9,
      "y": 31,
      "z": 0,
      "name": "Soil_Dirt"
    },
    {
      "x": -9,
      "y": 32,
      "z": 0,
      "name": "Soil_Grass"
    },
    {
      "x": -9,
      "y": 44,
      "z": 0,
      "name": "Plant_Vine_Hanging"
    },
    {
      "x": -9,
      "y": 45,
      "z": 0,
      "name": "Plant_Leaves_Ash",
      "support": 15
    },
    {
      "x": -9,
      "y": 46,
      "z": 0,
      "name": "Plant_Leaves_Ash",
      "support": 15
    },
    {
      "x": -9,
      "y": 47,
      "z": 0,
      "name": "Plant_Leaves_Ash",
      "support": 15
    },
    {
      "x": -9,
      "y": 29,
      "z": 1,
      "name": "Rock_Stone"
    },
    {
      "x": -9,
      "y": 30,
      "z": 1,
      "name": "Soil_Dirt"
    },
    {
      "x": -9,
      "y": 31,
      "z": 1,
      "name": "Soil_Dirt"
    },
    {
      "x": -9,
      "y": 32,
      "z": 1,
      "name": "Soil_Grass"
    },
    {
      "x": -9,
      "y": 33,
      "z": 1,
      "name": "Plant_Moss_Rug_Green"
    },
    {
      "x": -9,
      "y": 47,
      "z": 1,
      "name": "Plant_Leaves_Ash",
      "support": 15
    },
    {
      "x": -9,
      "y": 48,
      "z": 1,
      "name": "Plant_Leaves_Ash",
      "support": 15
    },
    {
      "x": -9,
      "y": 50,
      "z": 1,
      "name": "Plant_Leaves_Ash",
      "support": 15
    },
    {
      "x": -9,
      "y": 51,
      "z": 1,
      "name": "Plant_Leaves_Ash",
      "support": 15
    },
    {
      "x": -9,
      "y": 52,
      "z": 1,
      "name": "Plant_Leaves_Ash",
      "support": 15
    },
    {
      "x": -9,
      "y": 28,
      "z": 2,
      "name": "Rock_Stone"
    },
    {
      "x": -9,
      "y": 29,
      "z": 2,
      "name": "Rock_Stone"
    },
    {
      "x": -9,
      "y": 30,
      "z": 2,
      "name": "Soil_Dirt"
    },
    {
      "x": -9,
      "y": 31,
      "z": 2,
      "name": "Soil_Dirt"
    },
    {
      "x": -9,
      "y": 32,
      "z": 2,
      "name": "Soil_Grass"
    },
    {
      "x": -9,
      "y": 33,
      "z": 2,
      "name": "Plant_Moss_Rug_Green"
    },
    {
      "x": -9,
      "y": 47,
      "z": 2,
      "name": "Wood_Ash_Trunk_Full",
      "support": 15
    },
    {
      "x": -9,
      "y": 51,
      "z": 2,
      "name": "Plant_Leaves_Ash",
      "support": 15
    },
    {
      "x": -9,
      "y": 52,
      "z": 2,
      "name": "Wood_Ash_Trunk_Full",
      "support": 15
    },
    {
      "x": -9,
      "y": 53,
      "z": 2,
      "name": "Plant_Leaves_Ash",
      "support": 15
    },
    {
      "x": -9,
      "y": 27,
      "z": 3,
      "name": "Rock_Stone"
    },
    {
      "x": -9,
      "y": 28,
      "z": 3,
      "name": "Rock_Stone"
    },
    {
      "x": -9,
      "y": 29,
      "z": 3,
      "name": "Rock_Stone"
    },
    {
      "x": -9,
      "y": 30,
      "z": 3,
      "name": "Soil_Dirt"
    },
    {
      "x": -9,
      "y": 31,
      "z": 3,
      "name": "Soil_Dirt"
    },
    {
      "x": -9,
      "y": 32,
      "z": 3,
      "name": "Soil_Dirt"
    },
    {
      "x": -9,
      "y": 33,
      "z": 3,
      "name": "Soil_Grass"
    },
    {
      "x": -9,
      "y": 47,
      "z": 3,
      "name": "Wood_Ash_Trunk_Full",
      "support": 15
    },
    {
      "x": -9,
      "y": 48,
      "z": 3,
      "name": "Wood_Ash_Trunk_Full",
      "support": 15
    },
    {
      "x": -9,
      "y": 52,
      "z": 3,
      "name": "Plant_Leaves_Ash",
      "support": 15
    },
    {
      "x": -9,
      "y": 53,
      "z": 3,
      "name": "Plant_Leaves_Ash",
      "support": 15
    },
    {
      "x": -9,
      "y": 26,
      "z": 4,
      "name": "Rock_Stone"
    },
    {
      "x": -9,
      "y": 27,
      "z": 4,
      "name": "Rock_Stone"
    },
    {
      "x": -9,
      "y": 28,
      "z": 4,
      "name": "Rock_Stone"
    },
    {
      "x": -9,
      "y": 29,
      "z": 4,
      "name": "Rock_Stone"
    },
    {
      "x": -9,
      "y": 30,
      "z": 4,
      "name": "Soil_Dirt"
    },
    {
      "x": -9,
      "y": 31,
      "z": 4,
      "name": "Soil_Dirt"
    },
    {
      "x": -9,
      "y": 32,
      "z": 4,
      "name": "Soil_Dirt"
    },
    {
      "x": -9,
      "y": 33,
      "z": 4,
      "name": "Soil_Grass"
    },
    {
      "x": -9,
      "y": 48,
      "z": 4,
      "name": "Wood_Ash_Trunk_Full",
      "support": 15
    },
    {
      "x": -9,
      "y": 26,
      "z": 5,
      "name": "Rock_Stone"
    },
    {
      "x": -9,
      "y": 27,
      "z": 5,
      "name": "Rock_Stone"
    },
    {
      "x": -9,
      "y": 28,
      "z": 5,
      "name": "Rock_Stone"
    },
    {
      "x": -9,
      "y": 29,
      "z": 5,
      "name": "Rock_Stone"
    },
    {
      "x": -9,
      "y": 30,
      "z": 5,
      "name": "Rock_Stone"
    },
    {
      "x": -9,
      "y": 31,
      "z": 5,
      "name": "Soil_Dirt"
    },
    {
      "x": -9,
      "y": 32,
      "z": 5,
      "name": "Soil_Dirt"
    },
    {
      "x": -9,
      "y": 33,
      "z": 5,
      "name": "Soil_Grass"
    },
    {
      "x": -9,
      "y": 43,
      "z": 5,
      "name": "Wood_Ash_Trunk_Full",
      "support": 15
    },
    {
      "x": -9,
      "y": 48,
      "z": 5,
      "name": "Wood_Ash_Trunk_Full",
      "support": 15
    },
    {
      "x": -9,
      "y": 53,
      "z": 5,
      "name": "Plant_Leaves_Ash",
      "support": 15
    },
    {
      "x": -9,
      "y": 25,
      "z": 6,
      "name": "Rock_Stone"
    },
    {
      "x": -9,
      "y": 26,
      "z": 6,
      "name": "Rock_Stone"
    },
    {
      "x": -9,
      "y": 27,
      "z": 6,
      "name": "Rock_Stone"
    },
    {
      "x": -9,
      "y": 28,
      "z": 6,
      "name": "Rock_Stone"
    },
    {
      "x": -9,
      "y": 29,
      "z": 6,
      "name": "Rock_Stone"
    },
    {
      "x": -9,
      "y": 30,
      "z": 6,
      "name": "Rock_Stone"
    },
    {
      "x": -9,
      "y": 31,
      "z": 6,
      "name": "Soil_Dirt"
    },
    {
      "x": -9,
      "y": 32,
      "z": 6,
      "name": "Soil_Grass"
    },
    {
      "x": -9,
      "y": 43,
      "z": 6,
      "name": "Wood_Ash_Trunk_Full",
      "support": 15
    },
    {
      "x": -9,
      "y": 48,
      "z": 6,
      "name": "Wood_Ash_Trunk_Full",
      "support": 15
    },
    {
      "x": -9,
      "y": 52,
      "z": 6,
      "name": "Plant_Leaves_Ash",
      "support": 15
    },
    {
      "x": -9,
      "y": 53,
      "z": 6,
      "name": "Wood_Ash_Trunk_Full",
      "support": 15
    },
    {
      "x": -9,
      "y": 25,
      "z": 7,
      "name": "Rock_Stone"
    },
    {
      "x": -9,
      "y": 26,
      "z": 7,
      "name": "Rock_Stone"
    },
    {
      "x": -9,
      "y": 27,
      "z": 7,
      "name": "Rock_Stone"
    },
    {
      "x": -9,
      "y": 28,
      "z": 7,
      "name": "Rock_Stone"
    },
    {
      "x": -9,
      "y": 29,
      "z": 7,
      "name": "Rock_Stone"
    },
    {
      "x": -9,
      "y": 30,
      "z": 7,
      "name": "Rock_Stone"
    },
    {
      "x": -9,
      "y": 31,
      "z": 7,
      "name": "Rock_Stone"
    },
    {
      "x": -9,
      "y": 32,
      "z": 7,
      "name": "Rock_Stone"
    },
    {
      "x": -9,
      "y": 33,
      "z": 7,
      "name": "Rock_Stone"
    },
    {
      "x": -9,
      "y": 34,
      "z": 7,
      "name": "Soil_Grass"
    },
    {
      "x": -9,
      "y": 47,
      "z": 7,
      "name": "Plant_Leaves_Ash",
      "support": 15
    },
    {
      "x": -9,
      "y": 48,
      "z": 7,
      "name": "Wood_Ash_Trunk_Full",
      "support": 15
    },
    {
      "x": -9,
      "y": 52,
      "z": 7,
      "name": "Plant_Leaves_Ash",
      "support": 15
    },
    {
      "x": -9,
      "y": 53,
      "z": 7,
      "name": "Plant_Leaves_Ash",
      "support": 15
    },
    {
      "x": -9,
      "y": 54,
      "z": 7,
      "name": "Plant_Leaves_Ash",
      "support": 15
    },
    {
      "x": -9,
      "y": 14,
      "z": 8,
      "name": "Rock_Stone"
    },
    {
      "x": -9,
      "y": 24,
      "z": 8,
      "name": "Rock_Stone"
    },
    {
      "x": -9,
      "y": 25,
      "z": 8,
      "name": "Rock_Stone"
    },
    {
      "x": -9,
      "y": 26,
      "z": 8,
      "name": "Rock_Stone"
    },
    {
      "x": -9,
      "y": 27,
      "z": 8,
      "name": "Rock_Stone"
    },
    {
      "x": -9,
      "y": 28,
      "z": 8,
      "name": "Rock_Stone"
    },
    {
      "x": -9,
      "y": 29,
      "z": 8,
      "name": "Rock_Stone"
    },
    {
      "x": -9,
      "y": 30,
      "z": 8,
      "name": "Rock_Stone"
    },
    {
      "x": -9,
      "y": 31,
      "z": 8,
      "name": "Rock_Stone"
    },
    {
      "x": -9,
      "y": 32,
      "z": 8,
      "name": "Rock_Stone"
    },
    {
      "x": -9,
      "y": 33,
      "z": 8,
      "name": "Rock_Stone"
    },
    {
      "x": -9,
      "y": 34,
      "z": 8,
      "name": "Rock_Stone_Mossy"
    },
    {
      "x": -9,
      "y": 46,
      "z": 8,
      "name": "Plant_Leaves_Ash",
      "support": 15
    },
    {
      "x": -9,
      "y": 47,
      "z": 8,
      "name": "Plant_Leaves_Ash",
      "support": 15
    },
    {
      "x": -9,
      "y": 48,
      "z": 8,
      "name": "Plant_Leaves_Ash",
      "support": 15
    },
    {
      "x": -9,
      "y": 52,
      "z": 8,
      "name": "Plant_Leaves_Ash",
      "support": 15
    },
    {
      "x": -9,
      "y": 53,
      "z": 8,
      "name": "Plant_Leaves_Ash",
      "support": 15
    },
    {
      "x": -9,
      "y": 12,
      "z": 9,
      "name": "Rock_Stone"
    },
    {
      "x": -9,
      "y": 13,
      "z": 9,
      "name": "Rock_Stone"
    },
    {
      "x": -9,
      "y": 14,
      "z": 9,
      "name": "Rock_Stone"
    },
    {
      "x": -9,
      "y": 15,
      "z": 9,
      "name": "Rock_Stone"
    },
    {
      "x": -9,
      "y": 16,
      "z": 9,
      "name": "Rock_Stone"
    },
    {
      "x": -9,
      "y": 24,
      "z": 9,
      "name": "Rock_Stone"
    },
    {
      "x": -9,
      "y": 25,
      "z": 9,
      "name": "Rock_Stone"
    },
    {
      "x": -9,
      "y": 26,
      "z": 9,
      "name": "Rock_Stone"
    },
    {
      "x": -9,
      "y": 27,
      "z": 9,
      "name": "Rock_Stone"
    },
    {
      "x": -9,
      "y": 28,
      "z": 9,
      "name": "Rock_Stone"
    },
    {
      "x": -9,
      "y": 29,
      "z": 9,
      "name": "Rock_Stone"
    },
    {
      "x": -9,
      "y": 30,
      "z": 9,
      "name": "Rock_Stone"
    },
    {
      "x": -9,
      "y": 31,
      "z": 9,
      "name": "Rock_Stone"
    },
    {
      "x": -9,
      "y": 32,
      "z": 9,
      "name": "Rock_Stone_Mossy"
    },
    {
      "x": -9,
      "y": 33,
      "z": 9,
      "name": "Rock_Stone_Mossy"
    },
    {
      "x": -9,
      "y": 34,
      "z": 9,
      "name": "Rock_Stone_Mossy"
    },
    {
      "x": -9,
      "y": 52,
      "z": 9,
      "name": "Plant_Leaves_Ash",
      "support": 15
    },
    {
      "x": -9,
      "y": 53,
      "z": 9,
      "name": "Plant_Leaves_Ash",
      "support": 15
    },
    {
      "x": -9,
      "y": 54,
      "z": 9,
      "name": "Plant_Leaves_Ash",
      "support": 15
    },
    {
      "x": -9,
      "y": 12,
      "z": 10,
      "name": "Rock_Stone"
    },
    {
      "x": -9,
      "y": 13,
      "z": 10,
      "name": "Rock_Stone"
    },
    {
      "x": -9,
      "y": 14,
      "z": 10,
      "name": "Rock_Stone"
    },
    {
      "x": -9,
      "y": 15,
      "z": 10,
      "name": "Rock_Stone"
    },
    {
      "x": -9,
      "y": 16,
      "z": 10,
      "name": "Rock_Stone"
    },
    {
      "x": -9,
      "y": 17,
      "z": 10,
      "name": "Rock_Stone"
    },
    {
      "x": -9,
      "y": 18,
      "z": 10,
      "name": "Rock_Stone"
    },
    {
      "x": -9,
      "y": 23,
      "z": 10,
      "name": "Rock_Stone"
    },
    {
      "x": -9,
      "y": 24,
      "z": 10,
      "name": "Rock_Stone"
    },
    {
      "x": -9,
      "y": 25,
      "z": 10,
      "name": "Rock_Stone"
    },
    {
      "x": -9,
      "y": 26,
      "z": 10,
      "name": "Rock_Stone"
    },
    {
      "x": -9,
      "y": 27,
      "z": 10,
      "name": "Rock_Stone"
    },
    {
      "x": -9,
      "y": 28,
      "z": 10,
      "name": "Rock_Stone"
    },
    {
      "x": -9,
      "y": 29,
      "z": 10,
      "name": "Soil_Dirt"
    },
    {
      "x": -9,
      "y": 30,
      "z": 10,
      "name": "Soil_Dirt"
    },
    {
      "x": -9,
      "y": 31,
      "z": 10,
      "name": "Soil_Grass"
    },
    {
      "x": -9,
      "y": 46,
      "z": 10,
      "name": "Wood_Ash_Trunk_Full",
      "support": 15
    },
    {
      "x": -9,
      "y": 52,
      "z": 10,
      "name": "Plant_Leaves_Ash",
      "support": 15
    },
    {
      "x": -9,
      "y": 53,
      "z": 10,
      "name": "Wood_Ash_Trunk_Full",
      "support": 15
    },
    {
      "x": -9,
      "y": 54,
      "z": 10,
      "name": "Plant_Leaves_Ash",
      "support": 15
    },
    {
      "x": -9,
      "y": 12,
      "z": 11,
      "name": "Rock_Stone"
    },
    {
      "x": -9,
      "y": 13,
      "z": 11,
      "name": "Rock_Stone"
    },
    {
      "x": -9,
      "y": 14,
      "z": 11,
      "name": "Rock_Stone"
    },
    {
      "x": -9,
      "y": 15,
      "z": 11,
      "name": "Rock_Stone"
    },
    {
      "x": -9,
      "y": 16,
      "z": 11,
      "name": "Rock_Stone"
    },
    {
      "x": -9,
      "y": 24,
      "z": 11,
      "name": "Rock_Stone"
    },
    {
      "x": -9,
      "y": 25,
      "z": 11,
      "name": "Rock_Stone"
    },
    {
      "x": -9,
      "y": 26,
      "z": 11,
      "name": "Rock_Stone"
    },
    {
      "x": -9,
      "y": 27,
      "z": 11,
      "name": "Rock_Stone"
    },
    {
      "x": -9,
      "y": 28,
      "z": 11,
      "name": "Rock_Stone"
    },
    {
      "x": -9,
      "y": 29,
      "z": 11,
      "name": "Soil_Dirt"
    },
    {
      "x": -9,
      "y": 30,
      "z": 11,
      "name": "Soil_Grass"
    },
    {
      "x": -9,
      "y": 50,
      "z": 11,
      "name": "Plant_Vine_Hanging"
    },
    {
      "x": -9,
      "y": 51,
      "z": 11,
      "name": "Plant_Leaves_Ash",
      "support": 15
    },
    {
      "x": -9,
      "y": 52,
      "z": 11,
      "name": "Plant_Leaves_Ash",
      "support": 15
    },
    {
      "x": -9,
      "y": 53,
      "z": 11,
      "name": "Plant_Leaves_Ash",
      "support": 15
    },
    {
      "x": -9,
      "y": 54,
      "z": 11,
      "name": "Plant_Leaves_Ash",
      "support": 15
    },
    {
      "x": -9,
      "y": 12,
      "z": 12,
      "name": "Rock_Stone"
    },
    {
      "x": -9,
      "y": 13,
      "z": 12,
      "name": "Rock_Stone"
    },
    {
      "x": -9,
      "y": 26,
      "z": 12,
      "name": "Rock_Stone"
    },
    {
      "x": -9,
      "y": 27,
      "z": 12,
      "name": "Rock_Stone"
    },
    {
      "x": -9,
      "y": 46,
      "z": 12,
      "name": "Plant_Leaves_Ash",
      "support": 15
    },
    {
      "x": -9,
      "y": 44,
      "z": 13,
      "name": "Plant_Leaves_Ash",
      "support": 15
    },
    {
      "x": -9,
      "y": 45,
      "z": 13,
      "name": "Plant_Leaves_Ash",
      "support": 15
    },
    {
      "x": -9,
      "y": 46,
      "z": 13,
      "name": "Plant_Leaves_Ash",
      "support": 15
    },
    {
      "x": -9,
      "y": 47,
      "z": 13,
      "name": "Plant_Leaves_Ash",
      "support": 15
    },
    {
      "x": -9,
      "y": 45,
      "z": 14,
      "name": "Plant_Leaves_Ash",
      "support": 15
    },
    {
      "x": -9,
      "y": 46,
      "z": 14,
      "name": "Plant_Leaves_Ash",
      "support": 15
    },
    {
      "x": -8,
      "y": 30,
      "z": -2,
      "name": "Rock_Stone"
    },
    {
      "x": -8,
      "y": 31,
      "z": -2,
      "name": "Soil_Grass"
    },
    {
      "x": -8,
      "y": 30,
      "z": -1,
      "name": "Soil_Dirt"
    },
    {
      "x": -8,
      "y": 31,
      "z": -1,
      "name": "Soil_Dirt"
    },
    {
      "x": -8,
      "y": 32,
      "z": -1,
      "name": "Soil_Grass"
    },
    {
      "x": -8,
      "y": 45,
      "z": -1,
      "name": "Plant_Leaves_Ash",
      "support": 15
    },
    {
      "x": -8,
      "y": 46,
      "z": -1,
      "name": "Plant_Leaves_Ash",
      "support": 15
    },
    {
      "x": -8,
      "y": 47,
      "z": -1,
      "name": "Plant_Leaves_Ash",
      "support": 15
    },
    {
      "x": -8,
      "y": 28,
      "z": 0,
      "name": "Rock_Stone"
    },
    {
      "x": -8,
      "y": 29,
      "z": 0,
      "name": "Rock_Stone"
    },
    {
      "x": -8,
      "y": 30,
      "z": 0,
      "name": "Rock_Stone"
    },
    {
      "x": -8,
      "y": 31,
      "z": 0,
      "name": "Soil_Dirt"
    },
    {
      "x": -8,
      "y": 32,
      "z": 0,
      "name": "Soil_Grass"
    },
    {
      "x": -8,
      "y": 46,
      "z": 0,
      "name": "Plant_Leaves_Ash",
      "support": 15
    },
    {
      "x": -8,
      "y": 47,
      "z": 0,
      "name": "Plant_Leaves_Ash",
      "support": 15
    },
    {
      "x": -8,
      "y": 48,
      "z": 0,
      "name": "Plant_Leaves_Ash",
      "support": 15
    },
    {
      "x": -8,
      "y": 51,
      "z": 0,
      "name": "Plant_Leaves_Ash",
      "support": 15
    },
    {
      "x": -8,
      "y": 52,
      "z": 0,
      "name": "Plant_Leaves_Ash",
      "support": 15
    },
    {
      "x": -8,
      "y": 27,
      "z": 1,
      "name": "Rock_Stone"
    },
    {
      "x": -8,
      "y": 28,
      "z": 1,
      "name": "Rock_Stone"
    },
    {
      "x": -8,
      "y": 29,
      "z": 1,
      "name": "Rock_Stone"
    },
    {
      "x": -8,
      "y": 30,
      "z": 1,
      "name": "Soil_Dirt"
    },
    {
      "x": -8,
      "y": 31,
      "z": 1,
      "name": "Soil_Dirt"
    },
    {
      "x": -8,
      "y": 32,
      "z": 1,
      "name": "Soil_Dirt"
    },
    {
      "x": -8,
      "y": 33,
      "z": 1,
      "name": "Soil_Grass"
    },
    {
      "x": -8,
      "y": 34,
      "z": 1,
      "name": "Plant_Moss_Rug_Green"
    },
    {
      "x": -8,
      "y": 51,
      "z": 1,
      "name": "Plant_Leaves_Ash",
      "support": 15
    },
    {
      "x": -8,
      "y": 52,
      "z": 1,
      "name": "Plant_Leaves_Ash",
      "support": 15
    },
    {
      "x": -8,
      "y": 53,
      "z": 1,
      "name": "Plant_Leaves_Ash",
      "support": 15
    },
    {
      "x": -8,
      "y": 27,
      "z": 2,
      "name": "Rock_Stone"
    },
    {
      "x": -8,
      "y": 28,
      "z": 2,
      "name": "Rock_Stone"
    },
    {
      "x": -8,
      "y": 29,
      "z": 2,
      "name": "Rock_Stone"
    },
    {
      "x": -8,
      "y": 30,
      "z": 2,
      "name": "Soil_Dirt"
    },
    {
      "x": -8,
      "y": 31,
      "z": 2,
      "name": "Soil_Dirt"
    },
    {
      "x": -8,
      "y": 32,
      "z": 2,
      "name": "Soil_Dirt"
    },
    {
      "x": -8,
      "y": 33,
      "z": 2,
      "name": "Soil_Leaves"
    },
    {
      "x": -8,
      "y": 34,
      "z": 2,
      "name": "Plant_Grass_Lush_Short"
    },
    {
      "x": -8,
      "y": 47,
      "z": 2,
      "name": "Wood_Ash_Trunk_Full",
      "support": 15
    },
    {
      "x": -8,
      "y": 52,
      "z": 2,
      "name": "Wood_Ash_Trunk_Full",
      "support": 15
    },
    {
      "x": -8,
      "y": 53,
      "z": 2,
      "name": "Plant_Leaves_Ash",
      "support": 15
    },
    {
      "x": -8,
      "y": 27,
      "z": 3,
      "name": "Rock_Stone"
    },
    {
      "x": -8,
      "y": 28,
      "z": 3,
      "name": "Rock_Stone"
    },
    {
      "x": -8,
      "y": 29,
      "z": 3,
      "name": "Rock_Stone"
    },
    {
      "x": -8,
      "y": 30,
      "z": 3,
      "name": "Soil_Dirt"
    },
    {
      "x": -8,
      "y": 31,
      "z": 3,
      "name": "Soil_Dirt"
    },
    {
      "x": -8,
      "y": 32,
      "z": 3,
      "name": "Soil_Dirt"
    },
    {
      "x": -8,
      "y": 33,
      "z": 3,
      "name": "Soil_Leaves"
    },
    {
      "x": -8,
      "y": 26,
      "z": 4,
      "name": "Rock_Stone"
    },
    {
      "x": -8,
      "y": 27,
      "z": 4,
      "name": "Rock_Stone"
    },
    {
      "x": -8,
      "y": 28,
      "z": 4,
      "name": "Rock_Stone"
    },
    {
      "x": -8,
      "y": 29,
      "z": 4,
      "name": "Rock_Stone"
    },
    {
      "x": -8,
      "y": 30,
      "z": 4,
      "name": "Rock_Stone"
    },
    {
      "x": -8,
      "y": 31,
      "z": 4,
      "name": "Soil_Dirt"
    },
    {
      "x": -8,
      "y": 32,
      "z": 4,
      "name": "Soil_Dirt"
    },
    {
      "x": -8,
      "y": 33,
      "z": 4,
      "name": "Soil_Grass"
    },
    {
      "x": -8,
      "y": 34,
      "z": 4,
      "name": "Plant_Moss_Rug_Green"
    },
    {
      "x": -8,
      "y": 54,
      "z": 4,
      "name": "Plant_Leaves_Ash",
      "support": 15
    },
    {
      "x": -8,
      "y": 26,
      "z": 5,
      "name": "Rock_Stone"
    },
    {
      "x": -8,
      "y": 27,
      "z": 5,
      "name": "Rock_Stone"
    },
    {
      "x": -8,
      "y": 28,
      "z": 5,
      "name": "Rock_Stone"
    },
    {
      "x": -8,
      "y": 29,
      "z": 5,
      "name": "Rock_Stone"
    },
    {
      "x": -8,
      "y": 30,
      "z": 5,
      "name": "Rock_Stone"
    },
    {
      "x": -8,
      "y": 31,
      "z": 5,
      "name": "Soil_Pathway"
    },
    {
      "x": -8,
      "y": 32,
      "z": 5,
      "name": "Soil_Pathway"
    },
    {
      "x": -8,
      "y": 33,
      "z": 5,
      "name": "Soil_Grass"
    },
    {
      "x": -8,
      "y": 54,
      "z": 5,
      "name": "Plant_Leaves_Ash",
      "support": 15
    },
    {
      "x": -8,
      "y": 26,
      "z": 6,
      "name": "Rock_Stone"
    },
    {
      "x": -8,
      "y": 27,
      "z": 6,
      "name": "Rock_Stone"
    },
    {
      "x": -8,
      "y": 28,
      "z": 6,
      "name": "Rock_Stone"
    },
    {
      "x": -8,
      "y": 29,
      "z": 6,
      "name": "Rock_Stone"
    },
    {
      "x": -8,
      "y": 30,
      "z": 6,
      "name": "Rock_Stone"
    },
    {
      "x": -8,
      "y": 31,
      "z": 6,
      "name": "Soil_Dirt"
    },
    {
      "x": -8,
      "y": 32,
      "z": 6,
      "name": "Soil_Grass"
    },
    {
      "x": -8,
      "y": 33,
      "z": 6,
      "name": "Soil_Grass"
    },
    {
      "x": -8,
      "y": 43,
      "z": 6,
      "name": "Wood_Ash_Trunk_Full",
      "support": 15
    },
    {
      "x": -8,
      "y": 53,
      "z": 6,
      "name": "Wood_Ash_Trunk_Full",
      "support": 15
    },
    {
      "x": -8,
      "y": 54,
      "z": 6,
      "name": "Plant_Leaves_Ash",
      "support": 15
    },
    {
      "x": -8,
      "y": 55,
      "z": 6,
      "name": "Plant_Leaves_Ash",
      "support": 15
    },
    {
      "x": -8,
      "y": 25,
      "z": 7,
      "name": "Rock_Stone"
    },
    {
      "x": -8,
      "y": 26,
      "z": 7,
      "name": "Rock_Stone"
    },
    {
      "x": -8,
      "y": 27,
      "z": 7,
      "name": "Rock_Stone"
    },
    {
      "x": -8,
      "y": 28,
      "z": 7,
      "name": "Rock_Stone"
    },
    {
      "x": -8,
      "y": 29,
      "z": 7,
      "name": "Rock_Stone"
    },
    {
      "x": -8,
      "y": 30,
      "z": 7,
      "name": "Rock_Stone"
    },
    {
      "x": -8,
      "y": 31,
      "z": 7,
      "name": "Soil_Dirt"
    },
    {
      "x": -8,
      "y": 32,
      "z": 7,
      "name": "Soil_Dirt"
    },
    {
      "x": -8,
      "y": 33,
      "z": 7,
      "name": "Soil_Grass"
    },
    {
      "x": -8,
      "y": 25,
      "z": 8,
      "name": "Rock_Stone"
    },
    {
      "x": -8,
      "y": 26,
      "z": 8,
      "name": "Rock_Stone"
    },
    {
      "x": -8,
      "y": 27,
      "z": 8,
      "name": "Rock_Stone"
    },
    {
      "x": -8,
      "y": 28,
      "z": 8,
      "name": "Rock_Stone"
    },
    {
      "x": -8,
      "y": 29,
      "z": 8,
      "name": "Rock_Stone"
    },
    {
      "x": -8,
      "y": 30,
      "z": 8,
      "name": "Soil_Dirt"
    },
    {
      "x": -8,
      "y": 31,
      "z": 8,
      "name": "Soil_Dirt"
    },
    {
      "x": -8,
      "y": 32,
      "z": 8,
      "name": "Rock_Stone"
    },
    {
      "x": -8,
      "y": 33,
      "z": 8,
      "name": "Soil_Grass"
    },
    {
      "x": -8,
      "y": 34,
      "z": 8,
      "name": "Plant_Moss_Rug_Green"
    },
    {
      "x": -8,
      "y": 13,
      "z": 9,
      "name": "Rock_Stone"
    },
    {
      "x": -8,
      "y": 14,
      "z": 9,
      "name": "Rock_Stone"
    },
    {
      "x": -8,
      "y": 25,
      "z": 9,
      "name": "Rock_Stone"
    },
    {
      "x": -8,
      "y": 26,
      "z": 9,
      "name": "Rock_Stone"
    },
    {
      "x": -8,
      "y": 27,
      "z": 9,
      "name": "Rock_Stone"
    },
    {
      "x": -8,
      "y": 28,
      "z": 9,
      "name": "Rock_Stone"
    },
    {
      "x": -8,
      "y": 29,
      "z": 9,
      "name": "Rock_Stone"
    },
    {
      "x": -8,
      "y": 30,
      "z": 9,
      "name": "Soil_Dirt"
    },
    {
      "x": -8,
      "y": 31,
      "z": 9,
      "name": "Soil_Dirt"
    },
    {
      "x": -8,
      "y": 32,
      "z": 9,
      "name": "Soil_Grass"
    },
    {
      "x": -8,
      "y": 33,
      "z": 9,
      "name": "Plant_Moss_Rug_Green"
    },
    {
      "x": -8,
      "y": 11,
      "z": 10,
      "name": "Rock_Stone"
    },
    {
      "x": -8,
      "y": 12,
      "z": 10,
      "name": "Rock_Stone"
    },
    {
      "x": -8,
      "y": 13,
      "z": 10,
      "name": "Rock_Stone"
    },
    {
      "x": -8,
      "y": 14,
      "z": 10,
      "name": "Rock_Stone"
    },
    {
      "x": -8,
      "y": 15,
      "z": 10,
      "name": "Rock_Stone"
    },
    {
      "x": -8,
      "y": 25,
      "z": 10,
      "name": "Rock_Stone"
    },
    {
      "x": -8,
      "y": 26,
      "z": 10,
      "name": "Rock_Stone"
    },
    {
      "x": -8,
      "y": 27,
      "z": 10,
      "name": "Rock_Stone"
    },
    {
      "x": -8,
      "y": 28,
      "z": 10,
      "name": "Rock_Stone"
    },
    {
      "x": -8,
      "y": 29,
      "z": 10,
      "name": "Rock_Stone"
    },
    {
      "x": -8,
      "y": 30,
      "z": 10,
      "name": "Soil_Grass"
    },
    {
      "x": -8,
      "y": 46,
      "z": 10,
      "name": "Wood_Ash_Trunk_Full",
      "support": 15
    },
    {
      "x": -8,
      "y": 52,
      "z": 10,
      "name": "Wood_Ash_Trunk_Full",
      "support": 15
    },
    {
      "x": -8,
      "y": 53,
      "z": 10,
      "name": "Wood_Ash_Trunk_Full",
      "support": 15
    },
    {
      "x": -8,
      "y": 54,
      "z": 10,
      "name": "Plant_Leaves_Ash",
      "support": 15
    },
    {
      "x": -8,
      "y": 12,
      "z": 11,
      "name": "Rock_Stone"
    },
    {
      "x": -8,
      "y": 13,
      "z": 11,
      "name": "Rock_Stone"
    },
    {
      "x": -8,
      "y": 14,
      "z": 11,
      "name": "Rock_Stone"
    },
    {
      "x": -8,
      "y": 27,
      "z": 11,
      "name": "Rock_Stone"
    },
    {
      "x": -8,
      "y": 28,
      "z": 11,
      "name": "Rock_Stone"
    },
    {
      "x": -8,
      "y": 29,
      "z": 11,
      "name": "Soil_Grass"
    },
    {
      "x": -8,
      "y": 46,
      "z": 11,
      "name": "Wood_Ash_Trunk_Full",
      "support": 15
    },
    {
      "x": -8,
      "y": 53,
      "z": 11,
      "name": "Plant_Leaves_Ash",
      "support": 15
    },
    {
      "x": -8,
      "y": 54,
      "z": 11,
      "name": "Plant_Leaves_Ash",
      "support": 15
    },
    {
      "x": -8,
      "y": 46,
      "z": 12,
      "name": "Wood_Ash_Trunk_Full",
      "support": 15
    },
    {
      "x": -8,
      "y": 44,
      "z": 13,
      "name": "Plant_Vine_Hanging"
    },
    {
      "x": -8,
      "y": 45,
      "z": 13,
      "name": "Plant_Leaves_Ash",
      "support": 15
    },
    {
      "x": -8,
