{
  "version": 8,
  "blockIdVersion": 8,
  "anchorX": 0,
  "anchorY": 10,
  "anchorZ": -1,
  "blocks": [
    {
      "x": -13,
      "y": 28,
      "z": -4,
      "name": "Wood_Ash_Trunk_Full",
      "support": 15
    },
    {
      "x": -13,
      "y": 29,
      "z": -4,
      "name": "Plant_Moss_Rug_Green"
    },
    {
      "x": -12,
      "y": 28,
      "z": -4,
      "name": "Wood_Ash_Trunk_Full",
      "support": 15
    },
    {
      "x": -12,
      "y": 29,
      "z": -4,
      "name": "Plant_Moss_Rug_Green"
    },
    {
      "x": -11,
      "y": 27,
      "z": -7,
      "name": "Wood_Ash_Trunk_Full",
      "support": 15
    },
    {
      "x": -11,
      "y": 28,
      "z": -7,
      "name": "Plant_Moss_Rug_Green"
    },
    {
      "x": -11,
      "y": 13,
      "z": -4,
      "name": "Rock_Stone"
    },
    {
      "x": -11,
      "y": 14,
      "z": -4,
      "name": "Rock_Stone"
    },
    {
      "x": -11,
      "y": 15,
      "z": -4,
      "name": "Rock_Stone"
    },
    {
      "x": -11,
      "y": 16,
      "z": -4,
      "name": "Rock_Stone"
    },
    {
      "x": -11,
      "y": 17,
      "z": -4,
      "name": "Soil_Grass"
    },
    {
      "x": -11,
      "y": 27,
      "z": -4,
      "name": "Wood_Ash_Trunk_Full",
      "support": 15
    },
    {
      "x": -11,
      "y": 28,
      "z": -4,
      "name": "Wood_Ash_Trunk_Full",
      "support": 15
    },
    {
      "x": -11,
      "y": 11,
      "z": -3,
      "name": "Rock_Stone"
    },
    {
      "x": -11,
      "y": 12,
      "z": -3,
      "name": "Rock_Stone"
    },
    {
      "x": -11,
      "y": 13,
      "z": -3,
      "name": "Rock_Stone"
    },
    {
      "x": -11,
      "y": 14,
      "z": -3,
      "name": "Rock_Stone"
    },
    {
      "x": -11,
      "y": 15,
      "z": -3,
      "name": "Rock_Stone"
    },
    {
      "x": -11,
      "y": 16,
      "z": -3,
      "name": "Rock_Stone"
    },
    {
      "x": -11,
      "y": 17,
      "z": -3,
      "name": "Soil_Grass"
    },
    {
      "x": -11,
      "y": 18,
      "z": -3,
      "name": "Plant_Moss_Rug_Green"
    },
    {
      "x": -11,
      "y": 12,
      "z": -2,
      "name": "Rock_Stone"
    },
    {
      "x": -11,
      "y": 13,
      "z": -2,
      "name": "Rock_Stone"
    },
    {
      "x": -10,
      "y": 27,
      "z": -7,
      "name": "Wood_Ash_Trunk_Full",
      "support": 15
    },
    {
      "x": -10,
      "y": 28,
      "z": -7,
      "name": "Plant_Moss_Rug_Green"
    },
    {
      "x": -10,
      "y": 13,
      "z": -6,
      "name": "Rock_Stone"
    },
    {
      "x": -10,
      "y": 14,
      "z": -6,
      "name": "Rock_Stone"
    },
    {
      "x": -10,
      "y": 27,
      "z": -6,
      "name": "Wood_Ash_Trunk_Full",
      "support": 15
    },
    {
      "x": -10,
      "y": 12,
      "z": -5,
      "name": "Rock_Stone"
    },
    {
      "x": -10,
      "y": 13,
      "z": -5,
      "name": "Rock_Stone"
    },
    {
      "x": -10,
      "y": 14,
      "z": -5,
      "name": "Rock_Stone"
    },
    {
      "x": -10,
      "y": 15,
      "z": -5,
      "name": "Rock_Stone"
    },
    {
      "x": -10,
      "y": 16,
      "z": -5,
      "name": "Rock_Stone"
    },
    {
      "x": -10,
      "y": 10,
      "z": -4,
      "name": "Rock_Stone"
    },
    {
      "x": -10,
      "y": 11,
      "z": -4,
      "name": "Rock_Stone"
    },
    {
      "x": -10,
      "y": 12,
      "z": -4,
      "name": "Rock_Stone"
    },
    {
      "x": -10,
      "y": 13,
      "z": -4,
      "name": "Rock_Stone"
    },
    {
      "x": -10,
      "y": 14,
      "z": -4,
      "name": "Rock_Stone"
    },
    {
      "x": -10,
      "y": 15,
      "z": -4,
      "name": "Rock_Stone"
    },
    {
      "x": -10,
      "y": 16,
      "z": -4,
      "name": "Soil_Dirt"
    },
    {
      "x": -10,
      "y": 17,
      "z": -4,
      "name": "Soil_Dirt"
    },
    {
      "x": -10,
      "y": 18,
      "z": -4,
      "name": "Soil_Grass"
    },
    {
      "x": -10,
      "y": 27,
      "z": -4,
      "name": "Wood_Ash_Trunk_Full",
      "support": 15
    },
    {
      "x": -10,
      "y": 8,
      "z": -3,
      "name": "Rock_Stone"
    },
    {
      "x": -10,
      "y": 9,
      "z": -3,
      "name": "Rock_Stone"
    },
    {
      "x": -10,
      "y": 10,
      "z": -3,
      "name": "Rock_Stone"
    },
    {
      "x": -10,
      "y": 11,
      "z": -3,
      "name": "Rock_Stone"
    },
    {
      "x": -10,
      "y": 12,
      "z": -3,
      "name": "Rock_Stone"
    },
    {
      "x": -10,
      "y": 13,
      "z": -3,
      "name": "Rock_Stone"
    },
    {
      "x": -10,
      "y": 14,
      "z": -3,
      "name": "Rock_Stone"
    },
    {
      "x": -10,
      "y": 15,
      "z": -3,
      "name": "Rock_Stone"
    },
    {
      "x": -10,
      "y": 16,
      "z": -3,
      "name": "Rock_Stone"
    },
    {
      "x": -10,
      "y": 17,
      "z": -3,
      "name": "Soil_Dirt"
    },
    {
      "x": -10,
      "y": 18,
      "z": -3,
      "name": "Soil_Grass"
    },
    {
      "x": -10,
      "y": 9,
      "z": -2,
      "name": "Rock_Stone"
    },
    {
      "x": -10,
      "y": 10,
      "z": -2,
      "name": "Rock_Stone"
    },
    {
      "x": -10,
      "y": 11,
      "z": -2,
      "name": "Rock_Stone"
    },
    {
      "x": -10,
      "y": 12,
      "z": -2,
      "name": "Rock_Stone"
    },
    {
      "x": -10,
      "y": 13,
      "z": -2,
      "name": "Rock_Stone"
    },
    {
      "x": -10,
      "y": 14,
      "z": -2,
      "name": "Rock_Stone"
    },
    {
      "x": -10,
      "y": 15,
      "z": -2,
      "name": "Rock_Stone"
    },
    {
      "x": -10,
      "y": 30,
      "z": -2,
      "name": "Wood_Ash_Trunk_Full",
      "support": 15
    },
    {
      "x": -10,
      "y": 31,
      "z": -2,
      "name": "Plant_Moss_Rug_Green"
    },
    {
      "x": -10,
      "y": 12,
      "z": -1,
      "name": "Rock_Stone"
    },
    {
      "x": -9,
      "y": 11,
      "z": -6,
      "name": "Rock_Stone"
    },
    {
      "x": -9,
      "y": 12,
      "z": -6,
      "name": "Rock_Stone"
    },
    {
      "x": -9,
      "y": 13,
      "z": -6,
      "name": "Rock_Stone"
    },
    {
      "x": -9,
      "y": 14,
      "z": -6,
      "name": "Rock_Stone"
    },
    {
      "x": -9,
      "y": 15,
      "z": -6,
      "name": "Rock_Stone"
    },
    {
      "x": -9,
      "y": 16,
      "z": -6,
      "name": "Rock_Stone"
    },
    {
      "x": -9,
      "y": 17,
      "z": -6,
      "name": "Soil_Grass"
    },
    {
      "x": -9,
      "y": 27,
      "z": -6,
      "name": "Wood_Ash_Trunk_Full",
      "support": 15
    },
    {
      "x": -9,
      "y": 28,
      "z": -6,
      "name": "Plant_Moss_Rug_Green"
    },
    {
      "x": -9,
      "y": 8,
      "z": -5,
      "name": "Rock_Stone"
    },
    {
      "x": -9,
      "y": 9,
      "z": -5,
      "name": "Rock_Stone"
    },
    {
      "x": -9,
      "y": 10,
      "z": -5,
      "name": "Rock_Stone"
    },
    {
      "x": -9,
      "y": 11,
      "z": -5,
      "name": "Rock_Stone"
    },
    {
      "x": -9,
      "y": 12,
      "z": -5,
      "name": "Rock_Stone"
    },
    {
      "x": -9,
      "y": 13,
      "z": -5,
      "name": "Rock_Stone"
    },
    {
      "x": -9,
      "y": 14,
      "z": -5,
      "name": "Rock_Stone"
    },
    {
      "x": -9,
      "y": 15,
      "z": -5,
      "name": "Soil_Dirt"
    },
    {
      "x": -9,
      "y": 16,
      "z": -5,
      "name": "Soil_Dirt"
    },
    {
      "x": -9,
      "y": 17,
      "z": -5,
      "name": "Wood_Ash_Trunk",
      "support": 15
    },
    {
      "x": -9,
      "y": 18,
      "z": -5,
      "name": "Wood_Ash_Trunk",
      "support": 15
    },
    {
      "x": -9,
      "y": 19,
      "z": -5,
      "name": "Wood_Ash_Trunk",
      "support": 15
    },
    {
      "x": -9,
      "y": 20,
      "z": -5,
      "name": "Wood_Ash_Trunk_Full",
      "support": 15
    },
    {
      "x": -9,
      "y": 27,
      "z": -5,
      "name": "Wood_Ash_Trunk_Full",
      "support": 15
    },
    {
      "x": -9,
      "y": 7,
      "z": -4,
      "name": "Rock_Stone"
    },
    {
      "x": -9,
      "y": 8,
      "z": -4,
      "name": "Rock_Stone"
    },
    {
      "x": -9,
      "y": 9,
      "z": -4,
      "name": "Rock_Stone"
    },
    {
      "x": -9,
      "y": 10,
      "z": -4,
      "name": "Rock_Stone"
    },
    {
      "x": -9,
      "y": 11,
      "z": -4,
      "name": "Rock_Stone"
    },
    {
      "x": -9,
      "y": 12,
      "z": -4,
      "name": "Rock_Stone"
    },
    {
      "x": -9,
      "y": 13,
      "z": -4,
      "name": "Rock_Stone"
    },
    {
      "x": -9,
      "y": 14,
      "z": -4,
      "name": "Rock_Stone"
    },
    {
      "x": -9,
      "y": 15,
      "z": -4,
      "name": "Rock_Stone"
    },
    {
      "x": -9,
      "y": 16,
      "z": -4,
      "name": "Soil_Dirt"
    },
    {
      "x": -9,
      "y": 17,
      "z": -4,
      "name": "Soil_Dirt"
    },
    {
      "x": -9,
      "y": 18,
      "z": -4,
      "name": "Soil_Dirt"
    },
    {
      "x": -9,
      "y": 19,
      "z": -4,
      "name": "Soil_Leaves"
    },
    {
      "x": -9,
      "y": 20,
      "z": -4,
      "name": "Plant_Grass_Lush_Short"
    },
    {
      "x": -9,
      "y": 27,
      "z": -4,
      "name": "Wood_Ash_Trunk_Full",
      "support": 15
    },
    {
      "x": -9,
      "y": 6,
      "z": -3,
      "name": "Rock_Stone"
    },
    {
      "x": -9,
      "y": 7,
      "z": -3,
      "name": "Rock_Stone"
    },
    {
      "x": -9,
      "y": 8,
      "z": -3,
      "name": "Rock_Stone"
    },
    {
      "x": -9,
      "y": 9,
      "z": -3,
      "name": "Rock_Stone"
    },
    {
      "x": -9,
      "y": 10,
      "z": -3,
      "name": "Rock_Stone"
    },
    {
      "x": -9,
      "y": 11,
      "z": -3,
      "name": "Rock_Stone"
    },
    {
      "x": -9,
      "y": 12,
      "z": -3,
      "name": "Rock_Stone"
    },
    {
      "x": -9,
      "y": 13,
      "z": -3,
      "name": "Rock_Stone"
    },
    {
      "x": -9,
      "y": 14,
      "z": -3,
      "name": "Rock_Stone"
    },
    {
      "x": -9,
      "y": 15,
      "z": -3,
      "name": "Rock_Stone"
    },
    {
      "x": -9,
      "y": 16,
      "z": -3,
      "name": "Soil_Dirt"
    },
    {
      "x": -9,
      "y": 17,
      "z": -3,
      "name": "Soil_Dirt"
    },
    {
      "x": -9,
      "y": 18,
      "z": -3,
      "name": "Soil_Dirt"
    },
    {
      "x": -9,
      "y": 19,
      "z": -3,
      "name": "Soil_Leaves"
    },
    {
      "x": -9,
      "y": 30,
      "z": -3,
      "name": "Wood_Ash_Trunk_Full",
      "support": 15
    },
    {
      "x": -9,
      "y": 31,
      "z": -3,
      "name": "Plant_Moss_Rug_Green"
    },
    {
      "x": -9,
      "y": 7,
      "z": -2,
      "name": "Rock_Stone"
    },
    {
      "x": -9,
      "y": 8,
      "z": -2,
      "name": "Rock_Stone"
    },
    {
      "x": -9,
      "y": 9,
      "z": -2,
      "name": "Rock_Stone"
    },
    {
      "x": -9,
      "y": 10,
      "z": -2,
      "name": "Rock_Stone"
    },
    {
      "x": -9,
      "y": 11,
      "z": -2,
      "name": "Rock_Stone"
    },
    {
      "x": -9,
      "y": 12,
      "z": -2,
      "name": "Rock_Stone"
    },
    {
      "x": -9,
      "y": 13,
      "z": -2,
      "name": "Rock_Stone"
    },
    {
      "x": -9,
      "y": 14,
      "z": -2,
      "name": "Rock_Stone"
    },
    {
      "x": -9,
      "y": 15,
      "z": -2,
      "name": "Rock_Stone"
    },
    {
      "x": -9,
      "y": 16,
      "z": -2,
      "name": "Rock_Stone"
    },
    {
      "x": -9,
      "y": 17,
      "z": -2,
      "name": "Soil_Dirt"
    },
    {
      "x": -9,
      "y": 18,
      "z": -2,
      "name": "Soil_Dirt"
    },
    {
      "x": -9,
      "y": 19,
      "z": -2,
      "name": "Soil_Grass"
    },
    {
      "x": -9,
      "y": 30,
      "z": -2,
      "name": "Wood_Ash_Trunk_Full",
      "support": 15
    },
    {
      "x": -9,
      "y": 9,
      "z": -1,
      "name": "Rock_Stone"
    },
    {
      "x": -9,
      "y": 10,
      "z": -1,
      "name": "Rock_Stone"
    },
    {
      "x": -9,
      "y": 11,
      "z": -1,
      "name": "Rock_Stone"
    },
    {
      "x": -9,
      "y": 12,
      "z": -1,
      "name": "Rock_Stone"
    },
    {
      "x": -9,
      "y": 13,
      "z": -1,
      "name": "Rock_Stone"
    },
    {
      "x": -8,
      "y": 12,
      "z": -6,
      "name": "Rock_Stone"
    },
    {
      "x": -8,
      "y": 13,
      "z": -6,
      "name": "Rock_Stone"
    },
    {
      "x": -8,
      "y": 14,
      "z": -6,
      "name": "Rock_Stone"
    },
    {
      "x": -8,
      "y": 15,
      "z": -6,
      "name": "Rock_Stone"
    },
    {
      "x": -8,
      "y": 16,
      "z": -6,
      "name": "Rock_Stone"
    },
    {
      "x": -8,
      "y": 17,
      "z": -6,
      "name": "Soil_Grass"
    },
    {
      "x": -8,
      "y": 7,
      "z": -5,
      "name": "Rock_Stone"
    },
    {
      "x": -8,
      "y": 8,
      "z": -5,
      "name": "Rock_Stone"
    },
    {
      "x": -8,
      "y": 9,
      "z": -5,
      "name": "Rock_Stone"
    },
    {
      "x": -8,
      "y": 10,
      "z": -5,
      "name": "Rock_Stone"
    },
    {
      "x": -8,
      "y": 11,
      "z": -5,
      "name": "Rock_Stone"
    },
    {
      "x": -8,
      "y": 12,
      "z": -5,
      "name": "Rock_Stone"
    },
    {
      "x": -8,
      "y": 13,
      "z": -5,
      "name": "Rock_Stone"
    },
    {
      "x": -8,
      "y": 14,
      "z": -5,
      "name": "Rock_Stone"
    },
    {
      "x": -8,
      "y": 15,
      "z": -5,
      "name": "Rock_Stone"
    },
    {
      "x": -8,
      "y": 16,
      "z": -5,
      "name": "Soil_Dirt"
    },
    {
      "x": -8,
      "y": 17,
      "z": -5,
      "name": "Wood_Ash_Trunk_Full",
      "support": 15
    },
    {
      "x": -8,
      "y": 18,
      "z": -5,
      "name": "Soil_Dirt"
    },
    {
      "x": -8,
      "y": 19,
      "z": -5,
      "name": "Wood_Ash_Roots"
    },
    {
      "x": -8,
      "y": 20,
      "z": -5,
      "name": "Wood_Ash_Trunk_Full",
      "support": 15
    },
    {
      "x": -8,
      "y": 21,
      "z": -5,
      "name": "Wood_Ash_Trunk_Full",
      "support": 15
    },
    {
      "x": -8,
      "y": 6,
      "z": -4,
      "name": "Rock_Stone"
    },
    {
      "x": -8,
      "y": 7,
      "z": -4,
      "name": "Rock_Stone"
    },
    {
      "x": -8,
      "y": 8,
      "z": -4,
      "name": "Rock_Stone"
    },
    {
      "x": -8,
      "y": 9,
      "z": -4,
      "name": "Rock_Stone"
    },
    {
      "x": -8,
      "y": 10,
      "z": -4,
      "name": "Rock_Stone"
    },
    {
      "x": -8,
      "y": 11,
      "z": -4,
      "name": "Rock_Stone"
    },
    {
      "x": -8,
      "y": 12,
      "z": -4,
      "name": "Rock_Stone"
    },
    {
      "x": -8,
      "y": 13,
      "z": -4,
      "name": "Rock_Stone"
    },
    {
      "x": -8,
      "y": 14,
      "z": -4,
      "name": "Rock_Stone"
    },
    {
      "x": -8,
      "y": 15,
      "z": -4,
      "name": "Rock_Stone"
    },
    {
      "x": -8,
      "y": 16,
      "z": -4,
      "name": "Soil_Dirt"
    },
    {
      "x": -8,
      "y": 17,
      "z": -4,
      "name": "Soil_Dirt"
    },
    {
      "x": -8,
      "y": 18,
      "z": -4,
      "name": "Soil_Dirt"
    },
    {
      "x": -8,
      "y": 19,
      "z": -4,
      "name": "Soil_Leaves"
    },
    {
      "x": -8,
      "y": 27,
      "z": -4,
      "name": "Wood_Ash_Trunk_Full",
      "support": 15
    },
    {
      "x": -8,
      "y": 6,
      "z": -3,
      "name": "Rock_Stone"
    },
    {
      "x": -8,
      "y": 7,
      "z": -3,
      "name": "Rock_Stone"
    },
    {
      "x": -8,
      "y": 8,
      "z": -3,
      "name": "Rock_Stone"
    },
    {
      "x": -8,
      "y": 9,
      "z": -3,
      "name": "Rock_Stone"
    },
    {
      "x": -8,
      "y": 10,
      "z": -3,
      "name": "Rock_Stone"
    },
    {
      "x": -8,
      "y": 11,
      "z": -3,
      "name": "Rock_Stone"
    },
    {
      "x": -8,
      "y": 12,
      "z": -3,
      "name": "Rock_Stone"
    },
    {
      "x": -8,
      "y": 13,
      "z": -3,
      "name": "Rock_Stone"
    },
    {
      "x": -8,
      "y": 14,
      "z": -3,
      "name": "Rock_Stone"
    },
    {
      "x": -8,
      "y": 15,
      "z": -3,
      "name": "Rock_Stone"
    },
    {
      "x": -8,
      "y": 16,
      "z": -3,
      "name": "Soil_Dirt"
    },
    {
      "x": -8,
      "y": 17,
      "z": -3,
      "name": "Soil_Dirt"
    },
    {
      "x": -8,
      "y": 18,
      "z": -3,
      "name": "Soil_Dirt"
    },
    {
      "x": -8,
      "y": 19,
      "z": -3,
      "name": "Soil_Dirt"
    },
    {
      "x": -8,
      "y": 20,
      "z": -3,
      "name": "Soil_Leaves"
    },
    {
      "x": -8,
      "y": 21,
      "z": -3,
      "name": "Plant_Crop_Mushroom_Common_Brown",
      "components": {
        "Components": {
          "FarmingBlock": {}
        }
      }
    },
    {
      "x": -8,
      "y": 30,
      "z": -3,
      "name": "Wood_Ash_Trunk_Full",
      "support": 15
    },
    {
      "x": -8,
      "y": 31,
      "z": -3,
      "name": "Plant_Moss_Green"
    },
    {
      "x": -8,
      "y": 6,
      "z": -2,
      "name": "Rock_Stone"
    },
    {
      "x": -8,
      "y": 7,
      "z": -2,
      "name": "Rock_Stone"
    },
    {
      "x": -8,
      "y": 8,
      "z": -2,
      "name": "Rock_Stone"
    },
    {
      "x": -8,
      "y": 9,
      "z": -2,
      "name": "Rock_Stone"
    },
    {
      "x": -8,
      "y": 10,
      "z": -2,
      "name": "Rock_Stone"
    },
    {
      "x": -8,
      "y": 11,
      "z": -2,
      "name": "Rock_Stone"
    },
    {
      "x": -8,
      "y": 12,
      "z": -2,
      "name": "Rock_Stone"
    },
    {
      "x": -8,
      "y": 13,
      "z": -2,
      "name": "Rock_Stone"
    },
    {
      "x": -8,
      "y": 14,
      "z": -2,
      "name": "Rock_Stone"
    },
    {
      "x": -8,
      "y": 15,
      "z": -2,
      "name": "Rock_Stone"
    },
    {
      "x": -8,
      "y": 16,
      "z": -2,
      "name": "Rock_Stone"
    },
    {
      "x": -8,
      "y": 17,
      "z": -2,
      "name": "Rock_Stone"
    },
    {
      "x": -8,
      "y": 18,
      "z": -2,
      "name": "Soil_Dirt"
    },
    {
      "x": -8,
      "y": 19,
      "z": -2,
      "name": "Soil_Dirt"
    },
    {
      "x": -8,
      "y": 20,
      "z": -2,
      "name": "Soil_Leaves"
    },
    {
      "x": -8,
      "y": 21,
      "z": -2,
      "name": "Plant_Grass_Lush"
    },
    {
      "x": -8,
      "y": 8,
      "z": -1,
      "name": "Rock_Stone"
    },
    {
      "x": -8,
      "y": 9,
      "z": -1,
      "name": "Rock_Stone"
    },
    {
      "x": -8,
      "y": 10,
      "z": -1,
      "name": "Rock_Stone"
    },
    {
      "x": -8,
      "y": 11,
      "z": -1,
      "name": "Rock_Stone"
    },
    {
      "x": -8,
      "y": 12,
      "z": -1,
      "name": "Rock_Stone"
    },
    {
      "x": -8,
      "y": 19,
      "z": -1,
      "name": "Soil_Dirt"
    },
    {
      "x": -8,
      "y": 20,
      "z": -1,
      "name": "Soil_Grass"
    },
    {
      "x": -8,
      "y": 27,
      "z": -1,
      "name": "Wood_Ash_Trunk_Full",
      "support": 15
    },
    {
      "x": -8,
      "y": 28,
      "z": -1,
      "name": "Plant_Moss_Green"
    },
    {
      "x": -8,
      "y": 27,
      "z": 0,
      "name": "Wood_Ash_Trunk_Full",
      "support": 15
    },
    {
      "x": -8,
      "y": 28,
      "z": 0,
      "name": "Plant_Moss_Rug_Green"
    },
    {
      "x": -8,
      "y": 27,
      "z": 1,
      "name": "Wood_Ash_Trunk_Full",
      "support": 15
    },
    {
      "x": -8,
      "y": 28,
      "z": 1,
      "name": "Plant_Moss_Rug_Green"
    },
    {
      "x": -7,
      "y": 30,
      "z": -7,
      "name": "Wood_Ash_Trunk_Full",
      "support": 15
    },
    {
      "x": -7,
      "y": 31,
      "z": -7,
      "name": "Wood_Ash_Trunk",
      "support": 15
    },
    {
      "x": -7,
      "y": 32,
      "z": -7,
      "name": "Wood_Ash_Trunk_Full",
      "support": 15
    },
    {
      "x": -7,
      "y": 15,
      "z": -6,
      "name": "Rock_Stone"
    },
    {
      "x": -7,
      "y": 16,
      "z": -6,
      "name": "Rock_Stone"
    },
    {
      "x": -7,
      "y": 17,
      "z": -6,
      "name": "Soil_Dirt"
    },
    {
      "x": -7,
      "y": 18,
      "z": -6,
      "name": "Soil_Grass"
    },
    {
      "x": -7,
      "y": 30,
      "z": -6,
      "name": "Wood_Ash_Trunk_Full",
      "support": 15
    },
    {
      "x": -7,
      "y": 31,
      "z": -6,
      "name": "Plant_Moss_Rug_Green"
    },
    {
      "x": -7,
      "y": 8,
      "z": -5,
      "name": "Rock_Stone"
    },
    {
      "x": -7,
      "y": 13,
      "z": -5,
      "name": "Rock_Stone"
    },
    {
      "x": -7,
      "y": 14,
      "z": -5,
      "name": "Rock_Stone"
    },
    {
      "x": -7,
      "y": 15,
      "z": -5,
      "name": "Rock_Stone"
    },
    {
      "x": -7,
      "y": 16,
      "z": -5,
      "name": "Soil_Dirt"
    },
    {
      "x": -7,
      "y": 17,
      "z": -5,
      "name": "Soil_Dirt"
    },
    {
      "x": -7,
      "y": 18,
      "z": -5,
      "name": "Soil_Dirt"
    },
    {
      "x": -7,
      "y": 19,
      "z": -5,
      "name": "Soil_Grass"
    },
    {
      "x": -7,
      "y": 20,
      "z": -5,
      "name": "Wood_Ash_Roots"
    },
    {
      "x": -7,
      "y": 21,
      "z": -5,
      "name": "Wood_Ash_Trunk_Full",
      "support": 15
    },
    {
      "x": -7,
      "y": 22,
      "z": -5,
      "name": "Wood_Ash_Trunk",
      "support": 15
    },
    {
      "x": -7,
      "y": 23,
      "z": -5,
      "name": "Wood_Ash_Trunk",
      "support": 15
    },
    {
      "x": -7,
      "y": 24,
      "z": -5,
      "name": "Wood_Ash_Trunk_Full",
      "support": 15
    },
    {
      "x": -7,
      "y": 29,
      "z": -5,
      "name": "Wood_Ash_Trunk_Full",
      "support": 15
    },
    {
      "x": -7,
      "y": 30,
      "z": -5,
      "name": "Wood_Ash_Trunk_Full",
      "support": 15
    },
    {
      "x": -7,
      "y": 31,
      "z": -5,
      "name": "Plant_Moss_Rug_Green"
    },
    {
      "x": -7,
      "y": 6,
      "z": -4,
      "name": "Rock_Stone"
    },
    {
      "x": -7,
      "y": 7,
      "z": -4,
      "name": "Rock_Stone"
    },
    {
      "x": -7,
      "y": 8,
      "z": -4,
      "name": "Rock_Stone"
    },
    {
      "x": -7,
      "y": 9,
      "z": -4,
      "name": "Rock_Stone"
    },
    {
      "x": -7,
      "y": 10,
      "z": -4,
      "name": "Rock_Stone"
    },
    {
      "x": -7,
      "y": 11,
      "z": -4,
      "name": "Rock_Stone"
    },
    {
      "x": -7,
      "y": 12,
      "z": -4,
      "name": "Rock_Stone"
    },
    {
      "x": -7,
      "y": 13,
      "z": -4,
      "name": "Rock_Stone"
    },
    {
      "x": -7,
      "y": 14,
      "z": -4,
      "name": "Rock_Stone"
    },
    {
      "x": -7,
      "y": 15,
      "z": -4,
      "name": "Rock_Stone"
    },
    {
      "x": -7,
      "y": 16,
      "z": -4,
      "name": "Soil_Dirt"
    },
    {
      "x": -7,
      "y": 17,
      "z": -4,
      "name": "Soil_Dirt"
    },
    {
      "x": -7,
      "y": 18,
      "z": -4,
      "name": "Soil_Dirt"
    },
    {
      "x": -7,
      "y": 19,
      "z": -4,
      "name": "Soil_Dirt"
    },
    {
      "x": -7,
      "y": 20,
      "z": -4,
      "name": "Soil_Leaves"
    },
    {
      "x": -7,
      "y": 25,
      "z": -4,
      "name": "Wood_Ash_Trunk_Full",
      "support": 15
    },
    {
      "x": -7,
      "y": 26,
      "z": -4,
      "name": "Wood_Ash_Trunk",
      "support": 15
    },
    {
      "x": -7,
      "y": 27,
      "z": -4,
      "name": "Wood_Ash_Trunk",
      "support": 15
    },
    {
      "x": -7,
      "y": 28,
      "z": -4,
      "name": "Wood_Ash_Trunk",
      "support": 15
    },
    {
      "x": -7,
      "y": 29,
      "z": -4,
      "name": "Wood_Ash_Trunk_Full",
      "support": 15
    },
    {
      "x": -7,
      "y": 5,
      "z": -3,
      "name": "Rock_Stone"
    },
    {
      "x": -7,
      "y": 6,
      "z": -3,
      "name": "Rock_Stone"
    },
    {
      "x": -7,
      "y": 7,
      "z": -3,
      "name": "Rock_Stone"
    },
    {
      "x": -7,
      "y": 8,
      "z": -3,
      "name": "Rock_Stone"
    },
    {
      "x": -7,
      "y": 9,
      "z": -3,
      "name": "Rock_Stone"
    },
    {
      "x": -7,
      "y": 10,
      "z": -3,
      "name": "Rock_Stone"
    },
    {
      "x": -7,
      "y": 11,
      "z": -3,
      "name": "Rock_Stone"
    },
    {
      "x": -7,
      "y": 12,
      "z": -3,
      "name": "Rock_Stone"
    },
    {
      "x": -7,
      "y": 13,
      "z": -3,
      "name": "Rock_Stone"
    },
    {
      "x": -7,
      "y": 14,
      "z": -3,
      "name": "Rock_Stone"
    },
    {
      "x": -7,
      "y": 15,
      "z": -3,
      "name": "Rock_Stone"
    },
    {
      "x": -7,
      "y": 16,
      "z": -3,
      "name": "Rock_Stone"
    },
    {
      "x": -7,
      "y": 17,
      "z": -3,
      "name": "Soil_Dirt"
    },
    {
      "x": -7,
      "y": 18,
      "z": -3,
      "name": "Soil_Dirt"
    },
    {
      "x": -7,
      "y": 19,
      "z": -3,
      "name": "Soil_Dirt"
    },
    {
      "x": -7,
      "y": 20,
      "z": -3,
      "name": "Soil_Leaves"
    },
    {
      "x": -7,
      "y": 27,
      "z": -3,
      "name": "Wood_Ash_Trunk_Full",
      "support": 15
    },
    {
      "x": -7,
      "y": 29,
      "z": -3,
      "name": "Wood_Ash_Trunk_Full",
      "support": 15
    },
    {
      "x": -7,
      "y": 30,
      "z": -3,
      "name": "Wood_Ash_Trunk",
      "support": 15
    },
    {
      "x": -7,
      "y": 31,
      "z": -3,
      "name": "Wood_Ash_Trunk",
      "support": 15
    },
    {
      "x": -7,
      "y": 32,
      "z": -3,
      "name": "Wood_Ash_Trunk_Full",
      "support": 15
    },
    {
      "x": -7,
      "y": 5,
      "z": -2,
      "name": "Rock_Stone"
    },
    {
      "x": -7,
      "y": 6,
      "z": -2,
      "name": "Rock_Stone"
    },
    {
      "x": -7,
      "y": 7,
      "z": -2,
      "name": "Rock_Stone"
    },
    {
      "x": -7,
      "y": 8,
      "z": -2,
      "name": "Rock_Stone"
    },
    {
      "x": -7,
      "y": 9,
      "z": -2,
      "name": "Rock_Stone"
    },
    {
      "x": -7,
      "y": 10,
      "z": -2,
      "name": "Rock_Stone"
    },
    {
      "x": -7,
      "y": 13,
      "z": -2,
      "name": "Rock_Stone"
    },
    {
      "x": -7,
      "y": 14,
      "z": -2,
      "name": "Rock_Stone"
    },
    {
      "x": -7,
      "y": 15,
      "z": -2,
      "name": "Rock_Stone"
    },
    {
      "x": -7,
      "y": 16,
      "z": -2,
      "name": "Rock_Stone"
    },
    {
      "x": -7,
      "y": 17,
      "z": -2,
      "name": "Rock_Stone"
    },
    {
      "x": -7,
      "y": 18,
      "z": -2,
      "name": "Rock_Stone"
    },
    {
      "x": -7,
      "y": 19,
      "z": -2,
      "name": "Soil_Dirt"
    },
    {
      "x": -7,
      "y": 20,
      "z": -2,
      "name": "Soil_Leaves"
    },
    {
      "x": -7,
      "y": 21,
      "z": -2,
      "name": "Plant_Grass_Lush_Short"
    },
    {
      "x": -7,
      "y": 27,
      "z": -2,
      "name": "Wood_Ash_Trunk_Full",
      "support": 15
    },
    {
      "x": -7,
      "y": 28,
      "z": -2,
      "name": "Plant_Moss_Rug_Green"
    },
    {
      "x": -7,
      "y": 32,
      "z": -2,
      "name": "Wood_Ash_Trunk_Full",
      "support": 15
    },
    {
      "x": -7,
      "y": 33,
      "z": -2,
      "name": "Wood_Ash_Trunk_Full",
      "support": 15
    },
    {
      "x": -7,
      "y": 7,
      "z": -1,
      "name": "Rock_Stone"
    },
    {
      "x": -7,
      "y": 8,
      "z": -1,
      "name": "Rock_Stone"
    },
    {
      "x": -7,
      "y": 9,
      "z": -1,
      "name": "Rock_Stone"
    },
    {
      "x": -7,
      "y": 17,
      "z": -1,
      "name": "Rock_Stone"
    },
    {
      "x": -7,
      "y": 18,
      "z": -1,
      "name": "Rock_Stone"
    },
    {
      "x": -7,
      "y": 19,
      "z": -1,
      "name": "Soil_Dirt"
    },
    {
      "x": -7,
      "y": 20,
      "z": -1,
      "name": "Soil_Grass"
    },
    {
      "x": -7,
      "y": 21,
      "z": -1,
      "name": "Plant_Moss_Rug_Green"
    },
    {
      "x": -7,
      "y": 27,
      "z": -1,
      "name": "Wood_Ash_Trunk_Full",
      "support": 15
    },
    {
      "x": -7,
      "y": 18,
      "z": 0,
      "name": "Rock_Stone"
    },
    {
      "x": -7,
      "y": 19,
      "z": 0,
      "name": "Soil_Grass"
    },
    {
      "x": -6,
      "y": 18,
      "z": -7,
      "name": "Wood_Ash_Roots"
    },
    {
      "x": -6,
      "y": 19,
      "z": -7,
      "name": "Wood_Ash_Trunk_Full",
      "support": 15
    },
    {
      "x": -6,
      "y": 20,
      "z": -7,
      "name": "Wood_Ash_Trunk",
      "support": 15
    },
    {
      "x": -6,
      "y": 21,
      "z": -7,
      "name": "Wood_Ash_Trunk_Full",
      "support": 15
    },
    {
      "x": -6,
      "y": 34,
      "z": -7,
      "name": "Wood_Ash_Trunk_Full",
      "support": 15
    },
    {
      "x": -6,
      "y": 15,
      "z": -6,
      "name": "Rock_Stone"
    },
    {
      "x": -6,
      "y": 16,
      "z": -6,
      "name": "Rock_Stone"
    },
    {
      "x": -6,
      "y": 17,
      "z": -6,
      "name": "Rock_Stone"
    },
    {
      "x": -6,
      "y": 18,
      "z": -6,
      "name": "Soil_Grass"
    },
    {
      "x": -6,
      "y": 21,
      "z": -6,
      "name": "Wood_Ash_Trunk_Full",
      "support": 15
    },
    {
      "x": -6,
      "y": 22,
      "z": -6,
      "name": "Wood_Ash_Trunk_Full",
      "support": 15
    },
    {
      "x": -6,
      "y": 15,
      "z": -5,
      "name": "Rock_Stone"
    },
    {
      "x": -6,
      "y": 16,
      "z": -5,
      "name": "Soil_Dirt"
    },
    {
      "x": -6,
      "y": 17,
      "z": -5,
      "name": "Soil_Dirt"
    },
    {
      "x": -6,
      "y": 18,
      "z": -5,
      "name": "Wood_Ash_Trunk_Full",
      "support": 15
    },
    {
      "x": -6,
      "y": 19,
      "z": -5,
      "name": "Soil_Grass"
    },
    {
      "x": -6,
      "y": 20,
      "z": -5,
      "name": "Wood_Ash_Roots"
    },
    {
      "x": -6,
      "y": 21,
      "z": -5,
      "name": "Wood_Ash_Trunk_Full",
      "support": 15
    },
    {
      "x": -6,
      "y": 22,
      "z": -5,
      "name": "Wood_Ash_Trunk",
      "support": 15
    },
    {
      "x": -6,
      "y": 23,
      "z": -5,
      "name": "Wood_Ash_Trunk",
      "support": 15
    },
    {
      "x": -6,
      "y": 24,
      "z": -5,
      "name": "Wood_Ash_Trunk",
      "support": 15
    },
    {
      "x": -6,
      "y": 25,
      "z": -5,
      "name": "Wood_Ash_Trunk_Full",
      "support": 15
    },
    {
      "x": -6,
      "y": 30,
      "z": -5,
      "name": "Wood_Ash_Trunk_Full",
      "support": 15
    },
    {
      "x": -6,
      "y": 31,
      "z": -5,
      "name": "Plant_Moss_Rug_Green"
    },
    {
      "x": -6,
      "y": 5,
      "z": -4,
      "name": "Rock_Stone"
    },
    {
      "x": -6,
      "y": 6,
      "z": -4,
      "name": "Rock_Stone"
    },
    {
      "x": -6,
      "y": 13,
      "z": -4,
      "name": "Rock_Stone"
    },
    {
      "x": -6,
      "y": 14,
      "z": -4,
      "name": "Rock_Stone"
    },
    {
      "x": -6,
      "y": 15,
      "z": -4,
      "name": "Rock_Stone"
    },
    {
      "x": -6,
      "y": 16,
      "z": -4,
      "name": "Rock_Stone"
    },
    {
      "x": -6,
      "y": 17,
      "z": -4,
      "name": "Wood_Ash_Trunk_Full",
      "support": 15
    },
    {
      "x": -6,
      "y": 18,
      "z": -4,
      "name": "Wood_Ash_Trunk_Full",
      "support": 15
    },
    {
      "x": -6,
      "y": 19,
      "z": -4,
      "name": "Soil_Dirt"
    },
    {
      "x": -6,
      "y": 20,
      "z": -4,
      "name": "Wood_Ash_Trunk",
      "support": 15
    },
    {
      "x": -6,
      "y": 21,
      "z": -4,
      "name": "Wood_Ash_Trunk_Full",
      "support": 15
    },
    {
      "x": -6,
      "y": 22,
      "z": -4,
      "name": "Wood_Ash_Trunk",
      "support": 15
    },
    {
      "x": -6,
      "y": 23,
      "z": -4,
      "name": "Wood_Ash_Trunk",
      "support": 15
    },
    {
      "x": -6,
      "y": 24,
      "z": -4,
      "name": "Wood_Ash_Trunk",
      "support": 15
    },
    {
      "x": -6,
      "y": 25,
      "z": -4,
      "name": "Wood_Ash_Trunk_Full",
      "support": 15
    },
    {
      "x": -6,
      "y": 5,
      "z": -3,
      "name": "Rock_Stone"
    },
    {
      "x": -6,
      "y": 6,
      "z": -3,
      "name": "Rock_Stone"
    },
    {
      "x": -6,
      "y": 7,
      "z": -3,
      "name": "Rock_Stone"
    },
    {
      "x": -6,
      "y": 11,
      "z": -3,
      "name": "Rock_Stone"
    },
    {
      "x": -6,
      "y": 12,
      "z": -3,
      "name": "Rock_Stone"
    },
    {
      "x": -6,
      "y": 13,
      "z": -3,
      "name": "Rock_Stone"
    },
    {
      "x": -6,
      "y": 14,
      "z": -3,
      "name": "Rock_Stone"
    },
    {
      "x": -6,
      "y": 15,
      "z": -3,
      "name": "Rock_Stone"
    },
    {
      "x": -6,
      "y": 16,
      "z": -3,
      "name": "Rock_Stone"
    },
    {
      "x": -6,
      "y": 17,
      "z": -3,
      "name": "Wood_Ash_Roots"
    },
    {
      "x": -6,
      "y": 18,
      "z": -3,
      "name": "Wood_Ash_Trunk_Full",
      "support": 15
    },
    {
      "x": -6,
      "y": 19,
      "z": -3,
      "name": "Wood_Ash_Trunk",
      "support": 15
    },
    {
      "x": -6,
      "y": 20,
      "z": -3,
      "name": "Wood_Ash_Trunk",
      "support": 15
    },
    {
      "x": -6,
      "y": 21,
      "z": -3,
      "name": "Wood_Ash_Trunk_Full",
      "support": 15
    },
    {
      "x": -6,
      "y": 4,
      "z": -2,
      "name": "Rock_Stone"
    },
    {
      "x": -6,
      "y": 5,
      "z": -2,
      "name": "Rock_Stone"
    },
    {
      "x": -6,
      "y": 6,
      "z": -2,
      "name": "Rock_Stone"
    },
    {
      "x": -6,
      "y": 15,
      "z": -2,
      "name": "Rock_Stone"
    },
    {
      "x": -6,
      "y": 16,
      "z": -2,
      "name": "Rock_Stone"
    },
    {
      "x": -6,
      "y": 17,
      "z": -2,
      "name": "Rock_Stone"
    },
    {
      "x": -6,
      "y": 18,
      "z": -2,
      "name": "Rock_Stone"
    },
    {
      "x": -6,
      "y": 19,
      "z": -2,
      "name": "Soil_Dirt"
    },
    {
      "x": -6,
      "y": 20,
      "z": -2,
      "name": "Soil_Grass"
    },
    {
      "x": -6,
      "y": 21,
      "z": -2,
      "name": "Plant_Moss_Rug_Green"
    },
    {
      "x": -6,
      "y": 5,
      "z": -1,
      "name": "Rock_Stone"
    },
    {
      "x": -6,
      "y": 17,
      "z": -1,
      "name": "Rock_Stone"
    },
    {
      "x": -6,
      "y": 18,
      "z": -1,
      "name": "Rock_Stone"
    },
    {
      "x": -6,
      "y": 19,
      "z": -1,
      "name": "Soil_Dirt"
    },
    {
      "x": -6,
      "y": 20,
      "z": -1,
      "name": "Soil_Grass"
    },
    {
      "x": -6,
      "y": 21,
      "z": -1,
      "name": "Plant_Moss_Rug_Green"
    },
    {
      "x": -6,
      "y": 18,
      "z": 0,
      "name": "Rock_Stone"
    },
    {
      "x": -6,
      "y": 19,
      "z": 0,
      "name": "Soil_Dirt"
    },
    {
      "x": -6,
      "y": 20,
      "z": 0,
      "name": "Soil_Grass"
    },
    {
      "x": -6,
      "y": 18,
      "z": 1,
      "name": "Rock_Stone"
    },
    {
      "x": -6,
      "y": 19,
      "z": 1,
      "name": "Soil_Grass"
    },
    {
      "x": -5,
      "y": 26,
      "z": -7,
      "name": "Wood_Ash_Trunk_Full",
      "support": 15
    },
    {
      "x": -5,
      "y": 27,
      "z": -7,
      "name": "Wood_Ash_Trunk",
      "support": 15
    },
    {
      "x": -5,
      "y": 28,
      "z": -7,
      "name": "Wood_Ash_Trunk_Full",
      "support": 15
    },
    {
      "x": -5,
      "y": 32,
      "z": -7,
      "name": "Wood_Ash_Trunk_Full",
      "support": 15
    },
    {
      "x": -5,
      "y": 33,
      "z": -7,
      "name": "Wood_Ash_Trunk",
      "support": 15
    },
    {
      "x": -5,
      "y": 34,
      "z": -7,
      "name": "Wood_Ash_Trunk_Full",
      "support": 15
    },
    {
      "x": -5,
      "y": 16,
      "z": -6,
      "name": "Rock_Stone"
    },
    {
      "x": -5,
      "y": 17,
      "z": -6,
      "name": "Soil_Dirt"
    },
    {
      "x": -5,
      "y": 18,
      "z": -6,
      "name": "Soil_Dirt"
    },
    {
      "x": -5,
      "y": 19,
      "z": -6,
      "name": "Soil_Grass"
    },
    {
      "x": -5,
      "y": 24,
      "z": -6,
      "name": "Wood_Ash_Trunk_Full",
      "support": 15
    },
    {
      "x": -5,
      "y": 25,
      "z": -6,
      "name": "Wood_Ash_Trunk",
      "support": 15
    },
    {
      "x": -5,
      "y": 26,
      "z": -6,
      "name": "Wood_Ash_Trunk_Full",
      "support": 15
    },
    {
      "x": -5,
      "y": 27,
      "z": -6,
      "name": "Plant_Moss_Rug_Green"
    },
    {
      "x": -5,
      "y": 15,
      "z": -5,
      "name": "Rock_Stone"
    },
    {
      "x": -5,
      "y": 16,
      "z": -5,
      "name": "Rock_Stone"
    },
    {
      "x": -5,
      "y": 17,
      "z": -5,
      "name": "Rock_Stone"
    },
    {
      "x": -5,
      "y": 18,
      "z": -5,
      "name": "Soil_Dirt"
    },
    {
      "x": -5,
      "y": 19,
      "z": -5,
      "name": "Wood_Ash_Roots"
    },
    {
      "x": -5,
      "y": 20,
      "z": -5,
      "name": "Wood_Ash_Trunk_Full",
      "support": 15
    },
    {
      "x": -5,
      "y": 21,
      "z": -5,
      "name": "Wood_Ash_Trunk",
      "support": 15
    },
    {
      "x": -5,
      "y": 22,
      "z": -5,
      "name": "Wood_Ash_Trunk",
      "support": 15
    },
    {
      "x": -5,
      "y": 23,
      "z": -5,
      "name": "Wood_Ash_Trunk",
      "support": 15
    },
    {
      "x": -5,
      "y": 24,
      "z": -5,
      "name": "Wood_Ash_Trunk_Full",
      "support": 15
    },
    {
      "x": -5,
      "y": 30,
      "z": -5,
      "name": "Wood_Ash_Trunk_Full",
      "support": 15
    },
    {
      "x": -5,
      "y": 31,
      "z": -5,
      "name": "Wood_Ash_Trunk_Full",
      "support": 15
    },
    {
      "x": -5,
      "y": 14,
      "z": -4,
      "name": "Rock_Stone"
    },
    {
      "x": -5,
      "y": 15,
      "z": -4,
      "name": "Rock_Stone"
    },
    {
      "x": -5,
      "y": 16,
      "z": -4,
      "name": "Rock_Stone"
    },
    {
      "x": -5,
      "y": 17,
      "z": -4,
      "name": "Rock_Stone"
    },
    {
      "x": -5,
      "y": 18,
      "z": -4,
      "name": "Soil_Dirt"
    },
    {
      "x": -5,
      "y": 19,
      "z": -4,
      "name": "Soil_Dirt"
    },
    {
      "x": -5,
      "y": 20,
      "z": -4,
      "name": "Wood_Ash_Roots"
    },
    {
      "x": -5,
      "y": 21,
      "z": -4,
      "name": "Wood_Ash_Trunk_Full",
      "support": 15
    },
    {
      "x": -5,
      "y": 22,
      "z": -4,
      "name": "Wood_Ash_Trunk",
      "support": 15
    },
    {
      "x": -5,
      "y": 23,
      "z": -4,
      "name": "Wood_Ash_Trunk_Full",
      "support": 15
    },
    {
      "x": -5,
      "y": 4,
      "z": -3,
      "name": "Rock_Stone"
    },
    {
      "x": -5,
      "y": 5,
      "z": -3,
      "name": "Rock_Stone"
    },
    {
      "x": -5,
      "y": 6,
      "z": -3,
      "name": "Rock_Stone"
    },
    {
      "x": -5,
      "y": 14,
      "z": -3,
      "name": "Rock_Stone"
    },
    {
      "x": -5,
      "y": 15,
      "z": -3,
      "name": "Rock_Stone"
    },
    {
      "x": -5,
      "y": 16,
      "z": -3,
      "name": "Rock_Stone"
    },
    {
      "x": -5,
      "y": 17,
      "z": -3,
      "name": "Rock_Stone"
    },
    {
      "x": -5,
      "y": 18,
      "z": -3,
      "name": "Soil_Dirt"
    },
    {
      "x": -5,
      "y": 19,
      "z": -3,
      "name": "Soil_Dirt"
    },
    {
      "x": -5,
      "y": 20,
      "z": -3,
      "name": "Soil_Grass"
    },
    {
      "x": -5,
      "y": 4,
      "z": -2,
      "name": "Rock_Stone"
    },
    {
      "x": -5,
      "y": 5,
      "z": -2,
      "name": "Rock_Stone"
    },
    {
      "x": -5,
      "y": 16,
      "z": -2,
      "name": "Rock_Stone"
    },
    {
      "x": -5,
      "y": 17,
      "z": -2,
      "name": "Rock_Stone"
    },
    {
      "x": -5,
      "y": 18,
      "z": -2,
      "name": "Rock_Stone"
    },
    {
      "x": -5,
      "y": 19,
      "z": -2,
      "name": "Soil_Dirt"
    },
    {
      "x": -5,
      "y": 20,
      "z": -2,
      "name": "Soil_Dirt"
    },
    {
      "x": -5,
      "y": 21,
      "z": -2,
      "name": "Soil_Grass"
    },
    {
      "x": -5,
      "y": 4,
      "z": -1,
      "name": "Rock_Stone"
    },
    {
      "x": -5,
      "y": 5,
      "z": -1,
      "name": "Rock_Stone"
    },
    {
      "x": -5,
      "y": 17,
      "z": -1,
      "name": "Rock_Stone"
    },
    {
      "x": -5,
      "y": 18,
      "z": -1,
      "name": "Rock_Stone"
    },
    {
      "x": -5,
      "y": 19,
      "z": -1,
      "name": "Soil_Dirt"
    },
    {
      "x": -5,
      "y": 20,
      "z": -1,
      "name": "Soil_Dirt"
    },
    {
      "x": -5,
      "y": 21,
      "z": -1,
      "name": "Soil_Grass"
    },
    {
      "x": -5,
      "y": 17,
      "z": 0,
      "name": "Rock_Stone"
    },
    {
      "x": -5,
      "y": 18,
      "z": 0,
      "name": "Rock_Stone"
    },
    {
      "x": -5,
      "y": 19,
      "z": 0,
      "name": "Soil_Dirt"
    },
    {
      "x": -5,
      "y": 20,
      "z": 0,
      "name": "Soil_Dirt"
    },
    {
      "x": -5,
      "y": 21,
      "z": 0,
      "name": "Soil_Leaves"
    },
    {
      "x": -5,
      "y": 17,
      "z": 1,
      "name": "Rock_Stone"
    },
    {
      "x": -5,
      "y": 18,
      "z": 1,
      "name": "Rock_Stone"
    },
    {
      "x": -5,
      "y": 19,
      "z": 1,
      "name": "Soil_Dirt"
    },
    {
      "x": -5,
      "y": 20,
      "z": 1,
      "name": "Soil_Grass"
    },
    {
      "x": -4,
      "y": 26,
      "z": -11,
      "name": "Wood_Ash_Trunk_Full",
      "support": 15
    },
    {
      "x": -4,
      "y": 26,
      "z": -10,
      "name": "Wood_Ash_Trunk_Full",
      "support": 15
    },
    {
      "x": -4,
      "y": 26,
      "z": -9,
      "name": "Wood_Ash_Trunk_Full",
      "support": 15
    },
    {
      "x": -4,
      "y": 27,
      "z": -9,
      "name": "Plant_Moss_Green"
    },
    {
      "x": -4,
      "y": 30,
      "z": -9,
      "name": "Wood_Ash_Trunk_Full",
      "support": 15
    },
    {
      "x": -4,
      "y": 31,
      "z": -9,
      "name": "Plant_Moss_Rug_Green"
    },
    {
      "x": -4,
      "y": 26,
      "z": -8,
      "name": "Wood_Ash_Trunk_Full",
      "support": 15
    },
    {
      "x": -4,
      "y": 30,
      "z": -8,
      "name": "Wood_Ash_Trunk_Full",
      "support": 15
    },
    {
      "x": -4,
      "y": 26,
      "z": -7,
      "name": "Wood_Ash_Trunk_Full",
      "support": 15
    },
    {
      "x": -4,
      "y": 28,
      "z": -7,
      "name": "Wood_Ash_Trunk_Full",
      "support": 15
    },
    {
      "x": -4,
      "y": 29,
      "z": -7,
      "name": "Wood_Ash_Trunk",
      "support": 15
    },
    {
      "x": -4,
      "y": 30,
      "z": -7,
      "name": "Wood_Ash_Trunk",
      "support": 15
    },
    {
      "x": -4,
      "y": 31,
      "z": -7,
      "name": "Wood_Ash_Trunk",
      "support": 15
    },
    {
      "x": -4,
      "y": 32,
      "z": -7,
      "name": "Wood_Ash_Trunk_Full",
      "support": 15
    },
    {
      "x": -4,
      "y": 16,
      "z": -6,
      "name": "Rock_Stone"
    },
    {
      "x": -4,
      "y": 17,
      "z": -6,
      "name": "Rock_Stone"
    },
    {
      "x": -4,
      "y": 18,
      "z": -6,
      "name": "Soil_Dirt"
    },
    {
      "x": -4,
      "y": 19,
      "z": -6,
      "name": "Soil_Grass"
    },
    {
      "x": -4,
      "y": 29,
      "z": -6,
      "name": "Wood_Ash_Trunk_Full",
      "support": 15
    },
    {
      "x": -4,
      "y": 16,
      "z": -5,
      "name": "Rock_Stone"
    },
    {
      "x": -4,
      "y": 17,
      "z": -5,
      "name": "Soil_Dirt"
    },
    {
      "x": -4,
      "y": 18,
      "z": -5,
      "name": "Soil_Dirt"
    },
    {
      "x": -4,
      "y": 19,
      "z": -5,
      "name": "Soil_Grass"
    },
    {
      "x": -4,
      "y": 31,
      "z": -5,
      "name": "Wood_Ash_Trunk_Full",
      "support": 15
    },
    {
      "x": -4,
      "y": 15,
      "z": -4,
      "name": "Rock_Stone"
    },
    {
      "x": -4,
      "y": 16,
      "z": -4,
      "name": "Rock_Stone"
    },
    {
      "x": -4,
      "y": 17,
      "z": -4,
      "name": "Rock_Stone"
    },
    {
      "x": -4,
      "y": 18,
      "z": -4,
      "name": "Soil_Dirt"
    },
    {
      "x": -4,
      "y": 19,
      "z": -4,
      "name": "Wood_Ash_Roots"
    },
    {
      "x": -4,
      "y": 20,
      "z": -4,
      "name": "Wood_Ash_Trunk_Full",
      "support": 15
    },
    {
      "x": -4,
      "y": 21,
      "z": -4,
      "name": "Wood_Ash_Trunk_Full",
      "support": 15
    },
    {
      "x": -4,
      "y": 4,
      "z": -3,
      "name": "Rock_Stone"
    },
    {
      "x": -4,
      "y": 15,
      "z": -3,
      "name": "Rock_Stone"
    },
    {
      "x": -4,
      "y": 16,
      "z": -3,
      "name": "Rock_Stone"
    },
    {
      "x": -4,
      "y": 17,
      "z": -3,
      "name": "Rock_Stone"
    },
    {
      "x": -4,
      "y": 18,
      "z": -3,
      "name": "Soil_Dirt"
    },
    {
      "x": -4,
      "y": 19,
      "z": -3,
      "name": "Soil_Dirt"
    },
    {
      "x": -4,
      "y": 20,
      "z": -3,
      "name": "Soil_Grass"
    },
    {
      "x": -4,
      "y": 3,
      "z": -2,
      "name": "Rock_Stone"
    },
    {
      "x": -4,
      "y": 4,
      "z": -2,
      "name": "Rock_Stone"
    },
    {
      "x": -4,
      "y": 5,
      "z": -2,
      "name": "Rock_Stone"
    },
    {
      "x": -4,
      "y": 16,
      "z": -2,
      "name": "Rock_Stone"
    },
    {
      "x": -4,
      "y": 17,
      "z": -2,
      "name": "Rock_Stone"
    },
    {
      "x": -4,
      "y": 18,
      "z": -2,
      "name": "Rock_Stone"
    },
    {
      "x": -4,
      "y": 19,
      "z": -2,
      "name": "Soil_Pathway"
    },
    {
      "x": -4,
      "y": 20,
      "z": -2,
      "name": "Soil_Pathway"
    },
    {
      "x": -4,
      "y": 21,
      "z": -2,
      "name": "Soil_Grass"
    },
    {
      "x": -4,
      "y": 16,
      "z": -1,
      "name": "Rock_Stone"
    },
    {
      "x": -4,
      "y": 17,
      "z": -1,
      "name": "Rock_Stone"
    },
    {
      "x": -4,
      "y": 18,
      "z": -1,
      "name": "Rock_Stone"
    },
    {
      "x": -4,
      "y": 19,
      "z": -1,
      "name": "Soil_Dirt"
    },
    {
      "x": -4,
      "y": 20,
      "z": -1,
      "name": "Soil_Dirt"
    },
    {
      "x": -4,
      "y": 21,
      "z": -1,
      "name": "Soil_Leaves"
    },
    {
      "x": -4,
      "y": 22,
      "z": -1,
      "name": "Plant_Grass_Lush_Tall"
    },
    {
      "x": -4,
      "y": 17,
      "z": 0,
      "name": "Rock_Stone"
    },
    {
      "x": -4,
      "y": 18,
      "z": 0,
      "name": "Rock_Stone"
    },
    {
      "x": -4,
      "y": 19,
      "z": 0,
      "name": "Soil_Dirt"
    },
    {
      "x": -4,
      "y": 20,
      "z": 0,
      "name": "Soil_Dirt"
    },
    {
      "x": -4,
      "y": 21,
      "z": 0,
      "name": "Soil_Leaves"
    },
    {
      "x": -4,
      "y": 22,
      "z": 0,
      "name": "Plant_Grass_Lush"
    },
    {
      "x": -4,
      "y": 17,
      "z": 1,
      "name": "Rock_Stone"
    },
    {
      "x": -4,
      "y": 18,
      "z": 1,
      "name": "Soil_Dirt"
    },
    {
      "x": -4,
      "y": 19,
      "z": 1,
      "name": "Soil_Dirt"
    },
    {
      "x": -4,
      "y": 20,
      "z": 1,
      "name": "Soil_Grass"
    },
    {
      "x": -4,
      "y": 18,
      "z": 2,
      "name": "Rock_Stone"
    },
    {
      "x": -4,
      "y": 19,
      "z": 2,
      "name": "Soil_Grass"
    },
    {
      "x": -3,
      "y": 31,
      "z": -11,
      "name": "Wood_Ash_Trunk_Full",
      "support": 15
    },
    {
      "x": -3,
      "y": 30,
      "z": -10,
      "name": "Wood_Ash_Trunk_Full",
      "support": 15
    },
    {
      "x": -3,
      "y": 31,
      "z": -10,
      "name": "Wood_Ash_Trunk_Full",
      "support": 15
    },
    {
      "x": -3,
      "y": 32,
      "z": -10,
      "name": "Plant_Moss_Rug_Green"
    },
    {
      "x": -3,
      "y": 30,
      "z": -9,
      "name": "Wood_Ash_Trunk_Full",
      "support": 15
    },
    {
      "x": -3,
      "y": 31,
      "z": -9,
      "name": "Plant_Moss_Green"
    },
    {
      "x": -3,
      "y": 26,
      "z": -8,
      "name": "Wood_Ash_Trunk_Full",
      "support": 15
    },
    {
      "x": -3,
      "y": 18,
      "z": -6,
      "name": "Soil_Dirt"
    },
    {
      "x": -3,
      "y": 19,
      "z": -6,
      "name": "Soil_Grass"
    },
    {
      "x": -3,
      "y": 29,
      "z": -6,
      "name": "Wood_Ash_Trunk_Full",
      "support": 15
    },
    {
      "x": -3,
      "y": 16,
      "z": -5,
      "name": "Rock_Stone"
    },
    {
      "x": -3,
      "y": 17,
      "z": -5,
      "name": "Rock_Stone"
    },
    {
      "x": -3,
      "y": 18,
      "z": -5,
      "name": "Soil_Dirt"
    },
    {
      "x": -3,
      "y": 19,
      "z": -5,
      "name": "Soil_Dirt"
    },
    {
      "x": -3,
      "y": 20,
      "z": -5,
      "name": "Soil_Grass"
    },
    {
      "x": -3,
      "y": 29,
      "z": -5,
      "name": "Wood_Ash_Trunk_Full",
      "support": 15
    },
    {
      "x": -3,
      "y": 30,
      "z": -5,
      "name": "Wood_Ash_Trunk_Full",
      "support": 15
    },
    {
      "x": -3,
      "y": 16,
      "z": -4,
      "name": "Rock_Stone"
    },
    {
      "x": -3,
      "y": 17,
      "z": -4,
      "name": "Wood_Ash_Roots"
    },
    {
      "x": -3,
      "y": 18,
      "z": -4,
      "name": "Wood_Ash_Trunk_Full",
      "support": 15
    },
    {
      "x": -3,
      "y": 19,
      "z": -4,
      "name": "Wood_Ash_Trunk",
      "support": 15
    },
    {
      "x": -3,
      "y": 20,
      "z": -4,
      "name": "Wood_Ash_Trunk_Full",
      "support": 15
    },
    {
      "x": -3,
      "y": 30,
      "z": -4,
      "name": "Wood_Ash_Trunk_Full",
      "support": 15
    },
    {
      "x": -3,
      "y": 31,
      "z": -4,
      "name": "Wood_Ash_Trunk_Full",
      "support": 15
    },
    {
      "x": -3,
      "y": 15,
      "z": -3,
      "name": "Rock_Stone"
    },
    {
      "x": -3,
      "y": 16,
      "z": -3,
      "name": "Rock_Stone"
    },
    {
      "x": -3,
      "y": 17,
      "z": -3,
      "name": "Rock_Stone"
    },
    {
      "x": -3,
      "y": 18,
      "z": -3,
      "name": "Soil_Dirt"
    },
    {
      "x": -3,
      "y": 19,
      "z": -3,
      "name": "Soil_Pathway"
    },
    {
      "x": -3,
      "y": 20,
      "z": -3,
      "name": "Soil_Pathway"
    },
    {
      "x": -3,
      "y": 21,
      "z": -3,
      "name": "Soil_Grass"
    },
    {
      "x": -3,
      "y": 4,
      "z": -2,
      "name": "Rock_Stone"
    },
    {
      "x": -3,
      "y": 16,
      "z": -2,
      "name": "Rock_Stone"
    },
    {
      "x": -3,
      "y": 17,
      "z": -2,
      "name": "Rock_Stone"
    },
    {
      "x": -3,
      "y": 18,
      "z": -2,
      "name": "Rock_Stone"
    },
    {
      "x": -3,
      "y": 19,
      "z": -2,
      "name": "Soil_Dirt"
    },
    {
      "x": -3,
      "y": 20,
      "z": -2,
      "name": "Soil_Dirt"
    },
    {
      "x": -3,
      "y": 21,
      "z": -2,
      "name": "Soil_Leaves"
    },
    {
      "x": -3,
      "y": 22,
      "z": -2,
      "name": "Plant_Grass_Lush_Short"
    },
    {
      "x": -3,
      "y": 16,
      "z": -1,
      "name": "Rock_Stone"
    },
    {
      "x": -3,
      "y": 17,
      "z": -1,
      "name": "Rock_Stone"
    },
    {
      "x": -3,
      "y": 18,
      "z": -1,
      "name": "Rock_Stone"
    },
    {
      "x": -3,
      "y": 19,
      "z": -1,
      "name": "Soil_Pathway"
    },
    {
      "x": -3,
      "y": 20,
      "z": -1,
      "name": "Soil_Pathway"
    },
    {
      "x": -3,
      "y": 21,
      "z": -1,
      "name": "Soil_Leaves"
    },
    {
      "x": -3,
      "y": 17,
      "z": 0,
      "name": "Rock_Stone"
    },
    {
      "x": -3,
      "y": 18,
      "z": 0,
      "name": "Rock_Stone"
    },
    {
      "x": -3,
      "y": 19,
      "z": 0,
      "name": "Soil_Dirt"
    },
    {
      "x": -3,
      "y": 20,
      "z": 0,
      "name": "Soil_Dirt"
    },
    {
      "x": -3,
      "y": 21,
      "z": 0,
      "name": "Soil_Leaves"
    },
    {
      "x": -3,
      "y": 17,
      "z": 1,
      "name": "Rock_Stone"
    },
    {
      "x": -3,
      "y": 18,
      "z": 1,
      "name": "Rock_Stone"
    },
    {
      "x": -3,
      "y": 19,
      "z": 1,
      "name": "Soil_Dirt"
    },
    {
      "x": -3,
      "y": 20,
      "z": 1,
      "name": "Soil_Dirt"
    },
    {
      "x": -3,
      "y": 21,
      "z": 1,
      "name": "Soil_Grass"
    },
    {
      "x": -3,
      "y": 17,
      "z": 2,
      "name": "Rock_Stone"
    },
    {
      "x": -3,
      "y": 18,
      "z": 2,
      "name": "Rock_Stone"
    },
    {
      "x": -3,
      "y": 19,
      "z": 2,
      "name": "Soil_Dirt"
    },
    {
      "x": -3,
      "y": 20,
      "z": 2,
      "name": "Soil_Grass"
    },
    {
      "x": -2,
      "y": 26,
      "z": -8,
      "name": "Wood_Ash_Trunk_Full",
      "support": 15
    },
    {
      "x": -2,
      "y": 18,
      "z": -6,
      "name": "Soil_Dirt"
    },
    {
      "x": -2,
      "y": 19,
      "z": -6,
      "name": "Soil_Grass"
    },
    {
      "x": -2,
      "y": 17,
      "z": -5,
      "name": "Rock_Stone"
    },
    {
      "x": -2,
      "y": 18,
      "z": -5,
      "name": "Soil_Dirt"
    },
    {
      "x": -2,
      "y": 19,
      "z": -5,
      "name": "Soil_Dirt"
    },
    {
      "x": -2,
      "y": 20,
      "z": -5,
      "name": "Soil_Grass"
    },
    {
      "x": -2,
      "y": 17,
      "z": -4,
      "name": "Rock_Stone"
    },
    {
      "x": -2,
      "y": 18,
      "z": -4,
      "name": "Soil_Dirt"
    },
    {
      "x": -2,
      "y": 19,
      "z": -4,
      "name": "Soil_Dirt"
    },
    {
      "x": -2,
      "y": 20,
      "z": -4,
      "name": "Soil_Grass"
    },
    {
      "x": -2,
      "y": 31,
      "z": -4,
      "name": "Wood_Ash_Trunk_Full",
      "support": 15
    },
    {
      "x": -2,
      "y": 16,
      "z": -3,
      "name": "Rock_Stone"
    },
    {
      "x": -2,
      "y": 17,
      "z": -3,
      "name": "Rock_Stone"
    },
    {
      "x": -2,
      "y": 18,
      "z": -3,
      "name": "Rock_Stone"
    },
    {
      "x": -2,
      "y": 19,
      "z": -3,
      "name": "Soil_Dirt"
    },
    {
      "x": -2,
      "y": 20,
      "z": -3,
      "name": "Soil_Dirt"
    },
    {
      "x": -2,
      "y": 21,
      "z": -3,
      "name": "Soil_Grass"
    },
    {
      "x": -2,
      "y": 31,
      "z": -3,
      "name": "Wood_Ash_Trunk_Full",
      "support": 15
    },
    {
      "x": -2,
      "y": 16,
      "z": -2,
      "name": "Rock_Stone"
    },
    {
      "x": -2,
      "y": 17,
      "z": -2,
      "name": "Rock_Stone"
    },
    {
      "x": -2,
      "y": 18,
      "z": -2,
      "name": "Rock_Stone"
    },
    {
      "x": -2,
      "y": 19,
      "z": -2,
      "name": "Rock_Stone"
    },
    {
      "x": -2,
      "y": 20,
      "z": -2,
      "name": "Soil_Dirt"
    },
    {
      "x": -2,
      "y": 21,
      "z": -2,
      "name": "Soil_Grass"
    },
    {
      "x": -2,
      "y": 17,
      "z": -1,
      "name": "Rock_Stone"
    },
    {
      "x": -2,
      "y": 18,
      "z": -1,
      "name": "Rock_Stone"
    },
    {
      "x": -2,
      "y": 19,
      "z": -1,
      "name": "Soil_Pathway"
    },
    {
      "x": -2,
      "y": 20,
      "z": -1,
      "name": "Soil_Pathway"
    },
    {
      "x": -2,
      "y": 21,
      "z": -1,
      "name": "Soil_Grass"
    },
    {
      "x": -2,
      "y": 17,
      "z": 0,
      "name": "Rock_Stone"
    },
    {
      "x": -2,
      "y": 18,
      "z": 0,
      "name": "Rock_Stone"
    },
    {
      "x": -2,
      "y": 19,
      "z": 0,
      "name": "Soil_Dirt"
    },
    {
      "x": -2,
      "y": 20,
      "z": 0,
      "name": "Soil_Dirt"
    },
    {
      "x": -2,
      "y": 21,
      "z": 0,
      "name": "Soil_Grass"
    },
    {
      "x": -2,
      "y": 17,
      "z": 1,
      "name": "Rock_Stone"
    },
    {
      "x": -2,
      "y": 18,
      "z": 1,
      "name": "Rock_Stone"
    },
    {
      "x": -2,
      "y": 19,
      "z": 1,
      "name": "Soil_Dirt"
    },
    {
      "x": -2,
      "y": 20,
      "z": 1,
      "name": "Soil_Dirt"
    },
    {
      "x": -2,
      "y": 21,
      "z": 1,
      "name": "Soil_Grass"
    },
    {
      "x": -2,
      "y": 17,
      "z": 2,
      "name": "Rock_Stone"
    },
    {
      "x": -2,
      "y": 18,
      "z": 2,
      "name": "Rock_Stone"
    },
    {
      "x": -2,
      "y": 19,
      "z": 2,
      "name": "Soil_Dirt"
    },
    {
      "x": -2,
      "y": 20,
      "z": 2,
      "name": "Soil_Dirt"
    },
    {
      "x": -2,
      "y": 21,
      "z": 2,
      "name": "Soil_Grass"
    },
    {
      "x": -2,
      "y": 18,
      "z": 3,
      "name": "Rock_Stone"
    },
    {
      "x": -2,
      "y": 19,
      "z": 3,
      "name": "Soil_Grass"
    },
    {
      "x": -2,
      "y": 20,
      "z": 3,
      "name": "Plant_Moss_Rug_Green"
    },
    {
      "x": -1,
      "y": 26,
      "z": -8,
      "name": "Wood_Ash_Trunk_Full",
      "support": 15
    },
    {
      "x": -1,
      "y": 18,
      "z": -6,
      "name": "Rock_Stone"
    },
    {
      "x": -1,
      "y": 19,
      "z": -6,
      "name": "Soil_Grass"
    },
    {
      "x": -1,
      "y": 17,
      "z": -5,
      "name": "Rock_Stone"
    },
    {
      "x": -1,
      "y": 18,
      "z": -5,
      "name": "Soil_Dirt"
    },
    {
      "x": -1,
      "y": 19,
      "z": -5,
      "name": "Soil_Dirt"
    },
    {
      "x": -1,
      "y": 20,
      "z": -5,
      "name": "Soil_Grass"
    },
    {
      "x": -1,
      "y": 17,
      "z": -4,
      "name": "Rock_Stone"
    },
    {
      "x": -1,
      "y": 18,
      "z": -4,
      "name": "Rock_Stone"
    },
    {
      "x": -1,
      "y": 19,
      "z": -4,
      "name": "Soil_Dirt"
    },
    {
      "x": -1,
      "y": 20,
      "z": -4,
      "name": "Soil_Grass"
    },
    {
      "x": -1,
      "y": 21,
      "z": -4,
      "name": "Plant_Bush"
    },
    {
      "x": -1,
      "y": 17,
      "z": -3,
      "name": "Rock_Stone"
    },
    {
      "x": -1,
      "y": 18,
      "z": -3,
      "name": "Rock_Stone"
    },
    {
      "x": -1,
      "y": 19,
      "z": -3,
      "name": "Soil_Dirt"
    },
    {
      "x": -1,
      "y": 20,
      "z": -3,
      "name": "Soil_Dirt"
    },
    {
      "x": -1,
      "y": 21,
      "z": -3,
      "name": "Soil_Grass"
    },
    {
      "x": -1,
      "y": 31,
      "z": -3,
      "name": "Wood_Ash_Trunk_Full",
      "support": 15
    },
    {
      "x": -1,
      "y": 17,
      "z": -2,
      "name": "Rock_Stone"
    },
    {
      "x": -1,
      "y": 18,
      "z": -2,
      "name": "Rock_Stone"
    },
    {
      "x": -1,
      "y": 19,
      "z": -2,
      "name": "Soil_Pathway"
    },
    {
      "x": -1,
      "y": 20,
      "z": -2,
      "name": "Soil_Pathway"
    },
    {
      "x": -1,
      "y": 21,
      "z": -2,
      "name": "Soil_Grass"
    },
    {
      "x": -1,
      "y": 17,
      "z": -1,
      "name": "Rock_Stone"
    },
    {
      "x": -1,
      "y": 18,
      "z": -1,
      "name": "Rock_Stone"
    },
    {
      "x": -1,
      "y": 19,
      "z": -1,
      "name": "Rock_Stone"
    },
    {
      "x": -1,
      "y": 20,
      "z": -1,
      "name": "Soil_Pathway"
    },
    {
      "x": -1,
      "y": 21,
      "z": -1,
      "name": "Soil_Pathway"
    },
    {
      "x": -1,
      "y": 22,
      "z": -1,
      "name": "Soil_Grass"
    },
    {
      "x": -1,
      "y": 17,
      "z": 0,
      "name": "Rock_Stone"
    },
    {
      "x": -1,
      "y": 18,
      "z": 0,
      "name": "Rock_Stone"
    },
    {
      "x": -1,
      "y": 19,
      "z": 0,
      "name": "Rock_Stone"
    },
    {
      "x": -1,
      "y": 20,
      "z": 0,
      "name": "Soil_Dirt"
    },
    {
      "x": -1,
      "y": 21,
      "z": 0,
      "name": "Soil_Dirt"
    },
    {
      "x": -1,
      "y": 22,
      "z": 0,
      "name": "Soil_Grass"
    },
    {
      "x": -1,
      "y": 23,
      "z": 0,
      "name": "Plant_Moss_Rug_Green"
    },
    {
      "x": -1,
      "y": 17,
      "z": 1,
      "name": "Rock_Stone"
    },
    {
      "x": -1,
      "y": 18,
      "z": 1,
      "name": "Rock_Stone"
    },
    {
      "x": -1,
      "y": 19,
      "z": 1,
      "name": "Rock_Stone"
    },
    {
      "x": -1,
      "y": 20,
      "z": 1,
      "name": "Soil_Dirt"
    },
    {
      "x": -1,
      "y": 21,
      "z": 1,
      "name": "Soil_Dirt"
    },
    {
      "x": -1,
      "y": 22,
      "z": 1,
      "name": "Soil_Grass"
    },
    {
      "x": -1,
      "y": 23,
      "z": 1,
      "name": "Plant_Moss_Rug_Green"
    },
    {
      "x": -1,
      "y": 17,
      "z": 2,
      "name": "Rock_Stone"
    },
    {
      "x": -1,
      "y": 18,
      "z": 2,
      "name": "Rock_Stone"
    },
    {
      "x": -1,
      "y": 19,
      "z": 2,
      "name": "Soil_Dirt"
    },
    {
      "x": -1,
      "y": 20,
      "z": 2,
      "name": "Soil_Dirt"
    },
    {
      "x": -1,
      "y": 21,
      "z": 2,
      "name": "Soil_Grass"
    },
    {
      "x": -1,
      "y": 17,
      "z": 3,
      "name": "Rock_Stone"
    },
    {
      "x": -1,
      "y": 18,
      "z": 3,
      "name": "Rock_Stone"
    },
    {
      "x": -1,
      "y": 19,
      "z": 3,
      "name": "Rock_Stone"
    },
    {
      "x": -1,
      "y": 20,
      "z": 3,
      "name": "Soil_Grass"
    },
    {
      "x": 0,
      "y": 18,
      "z": -6,
      "name": "Soil_Grass"
    },
    {
      "x": 0,
      "y": 17,
      "z": -5,
      "name": "Rock_Stone"
    },
    {
      "x": 0,
      "y": 18,
      "z": -5,
      "name": "Soil_Dirt"
    },
    {
      "x": 0,
      "y": 19,
      "z": -5,
      "name": "Soil_Dirt"
    },
    {
      "x": 0,
      "y": 20,
      "z": -5,
      "name": "Soil_Grass"
    },
    {
      "x": 0,
      "y": 17,
      "z": -4,
      "name": "Rock_Stone"
    },
    {
      "x": 0,
      "y": 18,
      "z": -4,
      "name": "Soil_Dirt"
    },
    {
      "x": 0,
      "y": 19,
      "z": -4,
      "name": "Soil_Dirt"
    },
    {
      "x": 0,
      "y": 20,
      "z": -4,
      "name": "Soil_Dirt"
    },
    {
      "x": 0,
      "y": 21,
      "z": -4,
      "name": "Soil_Grass"
    },
    {
      "x": 0,
      "y": 17,
      "z": -3,
      "name": "Rock_Stone"
    },
    {
      "x": 0,
      "y": 18,
      "z": -3,
      "name": "Rock_Stone"
    },
    {
      "x": 0,
      "y": 19,
      "z": -3,
      "name": "Soil_Dirt"
    },
    {
      "x": 0,
      "y": 20,
      "z": -3,
      "name": "Soil_Dirt"
    },
    {
      "x": 0,
      "y": 21,
      "z": -3,
      "name": "Soil_Grass"
    },
    {
      "x": 0,
      "y": 17,
      "z": -2,
      "name": "Rock_Stone"
    },
    {
      "x": 0,
      "y": 18,
      "z": -2,
      "name": "Rock_Stone"
    },
    {
      "x": 0,
      "y": 19,
      "z": -2,
      "name": "Rock_Stone"
    },
    {
      "x": 0,
      "y": 20,
      "z": -2,
      "name": "Soil_Dirt"
    },
    {
      "x": 0,
      "y": 21,
      "z": -2,
      "name": "Soil_Grass"
    },
    {
      "x": 0,
      "y": 17,
      "z": -1,
      "name": "Rock_Stone"
    },
    {
      "x": 0,
      "y": 18,
      "z": -1,
      "name": "Rock_Stone"
    },
    {
      "x": 0,
      "y": 19,
      "z": -1,
      "name": "Rock_Stone"
    },
    {
      "x": 0,
      "y": 20,
      "z": -1,
      "name": "Soil_Dirt"
    },
    {
      "x": 0,
      "y": 21,
      "z": -1,
      "name": "Soil_Dirt"
    },
    {
      "x": 0,
      "y": 22,
      "z": -1,
      "name": "Soil_Grass"
    },
    {
      "x": 0,
      "y": 17,
      "z": 0,
      "name": "Rock_Stone"
    },
    {
      "x": 0,
      "y": 18,
      "z": 0,
      "name": "Rock_Stone"
    },
    {
      "x": 0,
      "y": 19,
      "z": 0,
      "name": "Rock_Stone"
    },
    {
      "x": 0,
      "y": 20,
      "z": 0,
      "name": "Soil_Dirt"
    },
    {
      "x": 0,
      "y": 21,
      "z": 0,
      "name": "Soil_Dirt"
    },
    {
      "x": 0,
      "y": 22,
      "z": 0,
      "name": "Soil_Leaves"
    },
    {
      "x": 0,
      "y": 23,
      "z": 0,
      "name": "Plant_Grass_Lush_Short"
    },
    {
      "x": 0,
      "y": 17,
      "z": 1,
      "name": "Rock_Stone"
    },
    {
      "x": 0,
      "y": 18,
      "z": 1,
      "name": "Rock_Stone"
    },
    {
      "x": 0,
      "y": 19,
      "z": 1,
      "name": "Rock_Stone"
    },
    {
      "x": 0,
      "y": 20,
      "z": 1,
      "name": "Soil_Dirt"
    },
    {
      "x": 0,
      "y": 21,
      "z": 1,
      "name": "Soil_Dirt"
    },
    {
      "x": 0,
      "y": 22,
      "z": 1,
      "name": "Soil_Grass"
    },
    {
      "x": 0,
      "y": 23,
      "z": 1,
      "name": "Plant_Moss_Rug_Green"
    },
    {
      "x": 0,
      "y": 17,
      "z": 2,
      "name": "Rock_Stone"
    },
    {
      "x": 0,
      "y": 18,
      "z": 2,
      "name": "Rock_Stone"
    },
    {
      "x": 0,
      "y": 19,
      "z": 2,
      "name": "Rock_Stone"
    },
    {
      "x": 0,
      "y": 20,
      "z": 2,
      "name": "Soil_Dirt"
    },
    {
      "x": 0,
      "y": 21,
      "z": 2,
      "name": "Soil_Grass"
    },
    {
      "x": 0,
      "y": 22,
      "z": 2,
      "name": "Plant_Moss_Rug_Green"
    },
    {
      "x": 0,
      "y": 17,
      "z": 3,
      "name": "Rock_Stone"
    },
    {
      "x": 0,
      "y": 18,
      "z": 3,
      "name": "Rock_Stone"
    },
    {
      "x": 0,
      "y": 19,
      "z": 3,
      "name": "Rock_Stone"
    },
    {
      "x": 0,
      "y": 20,
      "z": 3,
      "name": "Soil_Dirt"
    },
    {
      "x": 0,
      "y": 21,
      "z": 3,
      "name": "Soil_Grass"
    },
    {
      "x": 0,
      "y": 22,
      "z": 3,
      "name": "Plant_Moss_Rug_Green"
    },
    {
      "x": 0,
      "y": 19,
      "z": 4,
      "name": "Rock_Stone"
    },
    {
      "x": 0,
      "y": 20,
      "z": 4,
      "name": "Soil_Grass"
    },
    {
      "x": 1,
      "y": 17,
      "z": -6,
      "name": "Rock_Stone"
    },
    {
      "x": 1,
      "y": 18,
      "z": -6,
      "name": "Soil_Grass"
    },
    {
      "x": 1,
      "y": 19,
      "z": -6,
      "name": "Plant_Moss_Rug_Green"
    },
    {
      "x": 1,
      "y": 17,
      "z": -5,
      "name": "Rock_Stone"
    },
    {
      "x": 1,
      "y": 18,
      "z": -5,
      "name": "Soil_Dirt"
    },
    {
      "x": 1,
      "y": 19,
      "z": -5,
      "name": "Soil_Dirt"
    },
    {
      "x": 1,
      "y": 20,
      "z": -5,
      "name": "Soil_Grass"
    },
    {
      "x": 1,
      "y": 17,
      "z": -4,
      "name": "Rock_Stone"
    },
    {
      "x": 1,
      "y": 18,
      "z": -4,
      "name": "Soil_Dirt"
    },
    {
      "x": 1,
      "y": 19,
      "z": -4,
      "name": "Soil_Dirt"
    },
    {
      "x": 1,
      "y": 20,
      "z": -4,
      "name": "Soil_Dirt"
    },
    {
      "x": 1,
      "y": 21,
      "z": -4,
      "name": "Soil_Grass"
    },
    {
      "x": 1,
      "y": 17,
      "z": -3,
      "name": "Rock_Stone"
    },
    {
      "x": 1,
      "y": 18,
      "z": -3,
      "name": "Soil_Dirt"
    },
    {
      "x": 1,
      "y": 19,
      "z": -3,
      "name": "Soil_Dirt"
    },
    {
      "x": 1,
      "y": 20,
      "z": -3,
      "name": "Soil_Dirt"
    },
    {
      "x": 1,
      "y": 21,
      "z": -3,
      "name": "Soil_Grass"
    },
    {
      "x": 1,
      "y": 17,
      "z": -2,
      "name": "Rock_Stone"
    },
    {
      "x": 1,
      "y": 18,
      "z": -2,
      "name": "Rock_Stone"
    },
    {
      "x": 1,
      "y": 19,
      "z": -2,
      "name": "Soil_Dirt"
    },
    {
      "x": 1,
      "y": 20,
      "z": -2,
      "name": "Soil_Dirt"
    },
    {
      "x": 1,
      "y": 21,
      "z": -2,
      "name": "Soil_Grass"
    },
    {
      "x": 1,
      "y": 17,
      "z": -1,
      "name": "Rock_Stone"
    },
    {
      "x": 1,
      "y": 18,
      "z": -1,
      "name": "Rock_Stone"
    },
    {
      "x": 1,
      "y": 19,
      "z": -1,
      "name": "Rock_Stone"
    },
    {
      "x": 1,
      "y": 20,
      "z": -1,
      "name": "Soil_Dirt"
    },
    {
      "x": 1,
      "y": 21,
      "z": -1,
      "name": "Soil_Dirt"
    },
    {
      "x": 1,
      "y": 22,
      "z": -1,
      "name": "Soil_Leaves"
    },
    {
      "x": 1,
      "y": 17,
      "z": 0,
      "name": "Rock_Stone"
    },
    {
      "x": 1,
      "y": 18,
      "z": 0,
      "name": "Rock_Stone"
    },
    {
      "x": 1,
      "y": 19,
      "z": 0,
      "name": "Rock_Stone"
    },
    {
      "x": 1,
      "y": 20,
      "z": 0,
      "name": "Soil_Dirt"
    },
    {
      "x": 1,
      "y": 21,
      "z": 0,
      "name": "Soil_Dirt"
    },
    {
      "x": 1,
      "y": 22,
      "z": 0,
      "name": "Soil_Leaves"
    },
    {
      "x": 1,
      "y": 17,
      "z": 1,
      "name": "Rock_Stone"
    },
    {
      "x": 1,
      "y": 18,
      "z": 1,
      "name": "Rock_Stone"
    },
    {
      "x": 1,
      "y": 19,
      "z": 1,
      "name": "Rock_Stone"
    },
    {
      "x": 1,
      "y": 20,
      "z": 1,
      "name": "Soil_Dirt"
    },
    {
      "x": 1,
      "y": 21,
      "z": 1,
      "name": "Soil_Dirt"
    },
    {
      "x": 1,
      "y": 22,
      "z": 1,
      "name": "Soil_Leaves"
    },
    {
      "x": 1,
      "y": 17,
      "z": 2,
      "name": "Rock_Stone"
    },
    {
      "x": 1,
      "y": 18,
      "z": 2,
      "name": "Rock_Stone"
    },
    {
      "x": 1,
      "y": 19,
      "z": 2,
      "name": "Rock_Stone"
    },
    {
      "x": 1,
      "y": 20,
      "z": 2,
      "name": "Soil_Dirt"
    },
    {
      "x": 1,
      "y": 21,
      "z": 2,
      "name": "Soil_Grass"
    },
    {
      "x": 1,
      "y": 22,
      "z": 2,
      "name": "Soil_Leaves"
    },
    {
      "x": 1,
      "y": 23,
      "z": 2,
      "name": "Plant_Grass_Lush_Short"
    },
    {
      "x": 1,
      "y": 17,
      "z": 3,
      "name": "Rock_Stone"
    },
    {
      "x": 1,
      "y": 18,
      "z": 3,
      "name": "Rock_Stone"
    },
    {
      "x": 1,
      "y": 19,
      "z": 3,
      "name": "Rock_Stone"
    },
    {
      "x": 1,
      "y": 20,
      "z": 3,
      "name": "Soil_Dirt"
    },
    {
      "x": 1,
      "y": 21,
      "z": 3,
      "name": "Soil_Grass"
    },
    {
      "x": 1,
      "y": 22,
      "z": 3,
      "name": "Plant_Moss_Rug_Green"
    },
    {
      "x": 1,
      "y": 18,
      "z": 4,
      "name": "Rock_Stone"
    },
    {
      "x": 1,
      "y": 19,
      "z": 4,
      "name": "Rock_Stone"
    },
    {
      "x": 1,
      "y": 20,
      "z": 4,
      "name": "Soil_Grass"
    },
    {
      "x": 2,
      "y": 18,
      "z": -6,
      "name": "Soil_Grass"
    },
    {
      "x": 2,
      "y": 19,
      "z": -6,
      "name": "Plant_Moss_Rug_Green"
    },
    {
      "x": 2,
      "y": 17,
      "z": -5,
      "name": "Soil_Dirt"
    },
    {
      "x": 2,
      "y": 18,
      "z": -5,
      "name": "Soil_Dirt"
    },
    {
      "x": 2,
      "y": 19,
      "z": -5,
      "name": "Soil_Grass"
    },
    {
      "x": 2,
      "y": 17,
      "z": -4,
      "name": "Rock_Stone"
    },
    {
      "x": 2,
      "y": 18,
      "z": -4,
      "name": "Soil_Dirt"
    },
    {
      "x": 2,
      "y": 19,
      "z": -4,
      "name": "Soil_Dirt"
    },
    {
      "x": 2,
      "y": 20,
      "z": -4,
      "name": "Soil_Dirt"
    },
    {
      "x": 2,
      "y": 21,
      "z": -4,
      "name": "Soil_Grass"
    },
    {
      "x": 2,
      "y": 17,
      "z": -3,
      "name": "Rock_Stone"
    },
    {
      "x": 2,
      "y": 18,
      "z": -3,
      "name": "Soil_Dirt"
    },
    {
      "x": 2,
      "y": 19,
      "z": -3,
      "name": "Soil_Dirt"
    },
    {
      "x": 2,
      "y": 20,
      "z": -3,
      "name": "Soil_Dirt"
    },
    {
      "x": 2,
      "y": 21,
      "z": -3,
      "name": "Soil_Grass"
    },
    {
      "x": 2,
      "y": 17,
      "z": -2,
      "name": "Rock_Stone"
    },
    {
      "x": 2,
      "y": 18,
      "z": -2,
      "name": "Rock_Stone"
    },
    {
      "x": 2,
      "y": 19,
      "z": -2,
      "name": "Soil_Dirt"
    },
    {
      "x": 2,
      "y": 20,
      "z": -2,
      "name": "Soil_Dirt"
    },
    {
      "x": 2,
      "y": 21,
      "z": -2,
      "name": "Soil_Grass"
    },
    {
      "x": 2,
      "y": 17,
      "z": -1,
      "name": "Rock_Stone"
    },
    {
      "x": 2,
      "y": 18,
      "z": -1,
      "name": "Rock_Stone"
    },
    {
      "x": 2,
      "y": 19,
      "z": -1,
      "name": "Rock_Stone"
    },
    {
      "x": 2,
      "y": 20,
      "z": -1,
      "name": "Soil_Dirt"
    },
    {
      "x": 2,
      "y": 21,
      "z": -1,
      "name": "Soil_Dirt"
    },
    {
      "x": 2,
      "y": 22,
      "z": -1,
      "name": "Soil_Leaves"
    },
    {
      "x": 2,
      "y": 17,
      "z": 0,
      "name": "Rock_Stone"
    },
    {
      "x": 2,
      "y": 18,
      "z": 0,
      "name": "Rock_Stone"
    },
    {
      "x": 2,
      "y": 19,
      "z": 0,
      "name": "Rock_Stone"
    },
    {
      "x": 2,
      "y": 20,
      "z": 0,
      "name": "Soil_Dirt"
    },
    {
      "x": 2,
      "y": 21,
      "z": 0,
      "name": "Soil_Dirt"
    },
    {
      "x": 2,
      "y": 22,
      "z": 0,
      "name": "Soil_Leaves"
    },
    {
      "x": 2,
      "y": 23,
      "z": 0,
      "name": "Plant_Crop_Mushroom_Cap_Red",
      "components": {
        "Components": {
          "FarmingBlock": {}
        }
      }
    },
    {
      "x": 2,
      "y": 17,
      "z": 1,
      "name": "Rock_Stone"
    },
    {
      "x": 2,
      "y": 18,
      "z": 1,
      "name": "Rock_Stone"
    },
    {
      "x": 2,
      "y": 19,
      "z": 1,
      "name": "Rock_Stone"
    },
    {
      "x": 2,
      "y": 20,
      "z": 1,
      "name": "Rock_Stone"
    },
    {
      "x": 2,
      "y": 21,
      "z": 1,
      "name": "Soil_Dirt"
    },
    {
      "x": 2,
      "y": 22,
      "z": 1,
      "name": "Soil_Leaves"
    },
    {
      "x": 2,
      "y": 23,
      "z": 1,
      "name": "Plant_Grass_Lush_Tall"
    },
    {
      "x": 2,
      "y": 17,
      "z": 2,
      "name": "Rock_Stone"
    },
    {
      "x": 2,
      "y": 18,
      "z": 2,
      "name": "Rock_Stone"
    },
    {
      "x": 2,
      "y": 19,
      "z": 2,
      "name": "Rock_Stone"
    },
    {
      "x": 2,
      "y": 20,
      "z": 2,
      "name": "Soil_Dirt"
    },
    {
      "x": 2,
      "y": 21,
      "z": 2,
      "name": "Rock_Stone"
    },
    {
      "x": 2,
      "y": 22,
      "z": 2,
      "name": "Soil_Leaves"
    },
    {
      "x": 2,
      "y": 17,
      "z": 3,
      "name": "Rock_Stone"
    },
    {
      "x": 2,
      "y": 18,
      "z": 3,
      "name": "Rock_Stone"
    },
    {
      "x": 2,
      "y": 19,
      "z": 3,
      "name": "Rock_Stone"
    },
    {
      "x": 2,
      "y": 20,
      "z": 3,
      "name": "Soil_Dirt"
    },
    {
      "x": 2,
      "y": 21,
      "z": 3,
      "name": "Soil_Grass"
    },
    {
      "x": 2,
      "y": 18,
      "z": 4,
      "name": "Rock_Stone"
    },
    {
      "x": 2,
      "y": 19,
      "z": 4,
      "name": "Rock_Stone"
    },
    {
      "x": 2,
      "y": 20,
      "z": 4,
      "name": "Rock_Stone"
    },
    {
      "x": 3,
      "y": 18,
      "z": -6,
      "name": "Soil_Grass"
    },
    {
      "x": 3,
      "y": 19,
      "z": -6,
      "name": "Plant_Moss_Rug_Green"
    },
    {
      "x": 3,
      "y": 17,
      "z": -5,
      "name": "Rock_Stone"
    },
    {
      "x": 3,
      "y": 18,
      "z": -5,
      "name": "Soil_Grass"
    },
    {
      "x": 3,
      "y": 19,
      "z": -5,
      "name": "Plant_Moss_Rug_Green"
    },
    {
      "x": 3,
      "y": 17,
      "z": -4,
      "name": "Rock_Stone"
    },
    {
      "x": 3,
      "y": 18,
      "z": -4,
      "name": "Soil_Dirt"
    },
    {
      "x": 3,
      "y": 19,
      "z": -4,
      "name": "Soil_Dirt"
    },
    {
      "x": 3,
      "y": 20,
      "z": -4,
      "name": "Soil_Dirt"
    },
    {
      "x": 3,
      "y": 21,
      "z": -4,
      "name": "Soil_Grass"
    },
    {
      "x": 3,
      "y": 17,
      "z": -3,
      "name": "Rock_Stone"
    },
    {
      "x": 3,
      "y": 18,
      "z": -3,
      "name": "Soil_Dirt"
    },
    {
      "x": 3,
      "y": 19,
      "z": -3,
      "name": "Soil_Dirt"
    },
    {
      "x": 3,
      "y": 20,
      "z": -3,
      "name": "Soil_Dirt"
    },
    {
      "x": 3,
      "y": 21,
      "z": -3,
      "name": "Soil_Grass"
    },
    {
      "x": 3,
      "y": 17,
      "z": -2,
      "name": "Rock_Stone"
    },
    {
      "x": 3,
      "y": 18,
      "z": -2,
      "name": "Rock_Stone"
    },
    {
      "x": 3,
      "y": 19,
      "z": -2,
      "name": "Rock_Stone"
    },
    {
      "x": 3,
      "y": 20,
      "z": -2,
      "name": "Soil_Dirt"
    },
    {
      "x": 3,
      "y": 21,
      "z": -2,
      "name": "Soil_Grass"
    },
    {
      "x": 3,
      "y": 17,
      "z": -1,
      "name": "Rock_Stone"
    },
    {
      "x": 3,
      "y": 18,
      "z": -1,
      "name": "Rock_Stone"
    },
    {
      "x": 3,
      "y": 19,
      "z": -1,
      "name": "Rock_Stone"
    },
    {
      "x": 3,
      "y": 20,
      "z": -1,
      "name": "Soil_Dirt"
    },
    {
      "x": 3,
      "y": 21,
      "z": -1,
      "name": "Soil_Dirt"
    },
    {
      "x": 3,
      "y": 22,
      "z": -1,
      "name": "Soil_Leaves"
    },
    {
      "x": 3,
      "y": 23,
      "z": -1,
      "name": "Plant_Grass_Lush_Short"
    },
    {
      "x": 3,
      "y": 17,
      "z": 0,
      "name": "Rock_Stone"
    },
    {
      "x": 3,
      "y": 18,
      "z": 0,
      "name": "Rock_Stone"
    },
    {
      "x": 3,
      "y": 19,
      "z": 0,
      "name": "Rock_Stone"
    },
    {
      "x": 3,
      "y": 20,
      "z": 0,
      "name": "Rock_Stone"
    },
    {
      "x": 3,
      "y": 21,
      "z": 0,
      "name": "Soil_Dirt"
    },
    {
      "x": 3,
      "y": 22,
      "z": 0,
      "name": "Soil_Leaves"
    },
    {
      "x": 3,
      "y": 1,
      "z": 1,
      "name": "Rock_Stone"
    },
    {
      "x": 3,
      "y": 17,
      "z": 1,
      "name": "Rock_Stone"
    },
    {
      "x": 3,
      "y": 18,
      "z": 1,
      "name": "Rock_Stone"
    },
    {
      "x": 3,
      "y": 19,
      "z": 1,
      "name": "Rock_Stone"
    },
    {
      "x": 3,
      "y": 20,
      "z": 1,
      "name": "Rock_Stone"
    },
    {
      "x": 3,
      "y": 21,
      "z": 1,
      "name": "Rock_Stone"
    },
    {
      "x": 3,
      "y": 22,
      "z": 1,
      "name": "Rock_Stone"
    },
    {
      "x": 3,
      "y": 23,
      "z": 1,
      "name": "Rock_Stone_Mossy"
    },
    {
      "x": 3,
      "y": 17,
      "z": 2,
      "name": "Rock_Stone"
    },
    {
      "x": 3,
      "y": 18,
      "z": 2,
      "name": "Rock_Stone"
    },
    {
      "x": 3,
      "y": 19,
      "z": 2,
      "name": "Rock_Stone"
    },
    {
      "x": 3,
      "y": 20,
      "z": 2,
      "name": "Rock_Stone"
    },
    {
      "x": 3,
      "y": 21,
      "z": 2,
      "name": "Rock_Stone"
    },
    {
      "x": 3,
      "y": 22,
      "z": 2,
      "name": "Rock_Stone"
    },
    {
      "x": 3,
      "y": 23,
      "z": 2,
      "name": "Rock_Stone"
    },
    {
      "x": 3,
      "y": 17,
      "z": 3,
      "name": "Rock_Stone"
    },
    {
      "x": 3,
      "y": 18,
      "z": 3,
      "name": "Rock_Stone"
    },
    {
      "x": 3,
      "y": 19,
      "z": 3,
      "name": "Rock_Stone"
    },
    {
      "x": 3,
      "y": 20,
      "z": 3,
      "name": "Rock_Stone"
    },
    {
      "x": 3,
      "y": 21,
      "z": 3,
      "name": "Rock_Stone"
    },
    {
      "x": 3,
      "y": 22,
      "z": 3,
      "name": "Rock_Stone"
    },
    {
      "x": 3,
      "y": 23,
      "z": 3,
      "name": "Rock_Stone"
    },
    {
      "x": 3,
      "y": 17,
      "z": 4,
      "name": "Rock_Stone"
    },
    {
      "x": 3,
      "y": 18,
      "z": 4,
      "name": "Rock_Stone"
    },
    {
      "x": 3,
      "y": 19,
      "z": 4,
      "name": "Rock_Stone"
    },
    {
      "x": 3,
      "y": 20,
      "z": 4,
      "name": "Soil_Gravel"
    },
    {
      "x": 3,
      "y": 21,
      "z": 4,
      "name": "Soil_Gravel"
    },
    {
      "x": 3,
      "y": 22,
      "z": 4,
      "name": "Plant_Bush"
    },
    {
      "x": 3,
      "y": 17,
      "z": 5,
      "name": "Rock_Stone"
    },
    {
      "x": 3,
      "y": 18,
      "z": 5,
      "name": "Soil_Gravel"
    },
    {
      "x": 3,
      "y": 19,
      "z": 5,
      "name": "Soil_Gravel"
    },
    {
      "x": 3,
      "y": 20,
      "z": 5,
      "name": "Soil_Gravel"
    },
    {
      "x": 3,
      "y": 21,
      "z": 5,
      "name": "Soil_Gravel"
    },
    {
      "x": 3,
      "y": 22,
      "z": 5,
      "name": "Plant_Bush"
    },
    {
      "x": 4,
      "y": 17,
      "z": -5,
      "name": "Rock_Stone"
    },
    {
      "x": 4,
      "y": 18,
      "z": -5,
      "name": "Soil_Grass"
    },
    {
      "x": 4,
      "y": 19,
      "z": -5,
      "name": "Plant_Moss_Rug_Green"
    },
    {
      "x": 4,
      "y": 17,
      "z": -4,
      "name": "Rock_Stone"
    },
    {
      "x": 4,
      "y": 18,
      "z": -4,
      "name": "Soil_Dirt"
    },
    {
      "x": 4,
      "y": 19,
      "z": -4,
      "name": "Soil_Dirt"
    },
    {
      "x": 4,
      "y": 20,
      "z": -4,
      "name": "Soil_Dirt"
    },
    {
      "x": 4,
      "y": 21,
      "z": -4,
      "name": "Soil_Grass"
    },
    {
      "x": 4,
      "y": 17,
      "z": -3,
      "name": "Rock_Stone"
    },
    {
      "x": 4,
      "y": 18,
      "z": -3,
      "name": "Rock_Stone"
    },
    {
      "x": 4,
      "y": 19,
      "z": -3,
      "name": "Soil_Dirt"
    },
    {
      "x": 4,
      "y": 20,
      "z": -3,
      "name": "Soil_Dirt"
    },
    {
      "x": 4,
      "y": 21,
      "z": -3,
      "name": "Soil_Grass"
    },
    {
      "x": 4,
      "y": 17,
      "z": -2,
      "name": "Rock_Stone"
    },
    {
      "x": 4,
      "y": 18,
      "z": -2,
      "name": "Rock_Stone"
    },
    {
      "x": 4,
      "y": 19,
      "z": -2,
      "name": "Rock_Stone"
    },
    {
      "x": 4,
      "y": 20,
      "z": -2,
      "name": "Soil_Dirt"
    },
    {
      "x": 4,
      "y": 21,
      "z": -2,
      "name": "Soil_Grass"
    },
    {
      "x": 4,
      "y": 22,
      "z": -2,
      "name": "Plant_Moss_Rug_Green"
    },
    {
      "x": 4,
      "y": 17,
      "z": -1,
      "name": "Rock_Stone"
    },
    {
      "x": 4,
      "y": 18,
      "z": -1,
      "name": "Rock_Stone"
    },
    {
      "x": 4,
      "y": 19,
      "z": -1,
      "name": "Rock_Stone"
    },
    {
      "x": 4,
      "y": 20,
      "z": -1,
      "name": "Soil_Dirt"
    },
    {
      "x": 4,
      "y": 21,
      "z": -1,
      "name": "Soil_Grass"
    },
    {
      "x": 4,
      "y": 1,
      "z": 0,
      "name": "Rock_Stone"
    },
    {
      "x": 4,
      "y": 17,
      "z": 0,
      "name": "Rock_Stone"
    },
    {
      "x": 4,
      "y": 18,
      "z": 0,
      "name": "Rock_Stone"
    },
    {
      "x": 4,
      "y": 19,
      "z": 0,
      "name": "Rock_Stone"
    },
    {
      "x": 4,
      "y": 20,
      "z": 0,
      "name": "Soil_Dirt"
    },
    {
      "x": 4,
      "y": 21,
      "z": 0,
      "name": "Rock_Stone"
    },
    {
      "x": 4,
      "y": 22,
      "z": 0,
      "name": "Soil_Grass"
    },
    {
      "x": 4,
      "y": 1,
      "z": 1,
      "name": "Rock_Stone"
    },
    {
      "x": 4,
      "y": 2,
      "z": 1,
      "name": "Rock_Stone"
    },
    {
      "x": 4,
      "y": 16,
      "z": 1,
      "name": "Rock_Stone"
    },
    {
      "x": 4,
      "y": 17,
      "z": 1,
      "name": "Rock_Stone"
    },
    {
      "x": 4,
      "y": 18,
      "z": 1,
      "name": "Rock_Stone"
    },
    {
      "x": 4,
      "y": 19,
      "z": 1,
      "name": "Rock_Stone"
    },
    {
      "x": 4,
      "y": 20,
      "z": 1,
      "name": "Rock_Stone"
    },
    {
      "x": 4,
      "y": 21,
      "z": 1,
      "name": "Rock_Stone_Mossy"
    },
    {
      "x": 4,
      "y": 22,
      "z": 1,
      "name": "Rock_Stone_Mossy"
    },
    {
      "x": 4,
      "y": 23,
      "z": 1,
      "name": "Rock_Stone_Mossy"
    },
    {
      "x": 4,
      "y": 16,
      "z": 2,
      "name": "Rock_Stone"
    },
    {
      "x": 4,
      "y": 17,
      "z": 2,
      "name": "Rock_Stone"
    },
    {
      "x": 4,
      "y": 18,
      "z": 2,
      "name": "Rock_Stone"
    },
    {
      "x": 4,
      "y": 19,
      "z": 2,
      "name": "Rock_Stone"
    },
    {
      "x": 4,
      "y": 20,
      "z": 2,
      "name": "Rock_Stone"
    },
    {
      "x": 4,
      "y": 21,
      "z": 2,
      "name": "Rock_Stone"
    },
    {
      "x": 4,
      "y": 22,
      "z": 2,
      "name": "Rock_Stone"
    },
    {
      "x": 4,
      "y": 23,
      "z": 2,
      "name": "Rock_Stone_Mossy"
    },
    {
      "x": 4,
      "y": 17,
      "z": 3,
      "name": "Rock_Stone"
    },
    {
      "x": 4,
      "y": 18,
      "z": 3,
      "name": "Rock_Stone"
    },
    {
      "x": 4,
      "y": 19,
      "z": 3,
      "name": "Rock_Stone"
    },
    {
      "x": 4,
      "y": 20,
      "z": 3,
      "name": "Rock_Stone"
    },
    {
      "x": 4,
      "y": 21,
      "z": 3,
      "name": "Rock_Stone"
    },
    {
      "x": 4,
      "y": 22,
      "z": 3,
      "name": "Rock_Stone_Mossy"
    },
    {
      "x": 4,
      "y": 23,
      "z": 3,
      "name": "Rock_Stone"
    },
    {
      "x": 4,
      "y": 17,
      "z": 4,
      "name": "Rock_Stone"
    },
    {
      "x": 4,
      "y": 18,
      "z": 4,
      "name": "Rock_Stone"
    },
    {
      "x": 4,
      "y": 19,
      "z": 4,
      "name": "Rock_Stone"
    },
    {
      "x": 4,
      "y": 20,
      "z": 4,
      "name": "Rock_Stone"
    },
    {
      "x": 4,
      "y": 21,
      "z": 4,
      "name": "Rock_Stone"
    },
    {
      "x": 4,
      "y": 22,
      "z": 4,
      "name": "Rock_Stone"
    },
    {
      "x": 4,
      "y": 23,
      "z": 4,
      "name": "Plant_Bush"
    },
    {
      "x": 4,
      "y": 17,
      "z": 5,
      "name": "Rock_Stone"
    },
    {
      "x": 4,
      "y": 18,
      "z": 5,
      "name": "Rock_Stone"
    },
    {
      "x": 4,
      "y": 19,
      "z": 5,
      "name": "Rock_Stone"
    },
    {
      "x": 4,
      "y": 20,
      "z": 5,
      "name": "Soil_Gravel"
    },
    {
      "x": 4,
      "y": 21,
      "z": 5,
      "name": "Soil_Gravel"
    },
    {
      "x": 4,
      "y": 18,
      "z": 6,
      "name": "Rock_Stone"
    },
    {
      "x": 4,
      "y": 19,
      "z": 6,
      "name": "Rock_Stone"
    },
    {
      "x": 5,
      "y": 17,
      "z": -4,
      "name": "Rock_Stone"
    },
    {
      "x": 5,
      "y": 18,
      "z": -4,
      "name": "Rock_Stone"
    },
    {
      "x": 5,
      "y": 19,
      "z": -4,
      "name": "Rock_Stone"
    },
    {
      "x": 5,
      "y": 20,
      "z": -4,
      "name": "Soil_Grass"
    },
    {
      "x": 5,
      "y": 17,
      "z": -3,
      "name": "Rock_Stone"
    },
    {
      "x": 5,
      "y": 18,
      "z": -3,
      "name": "Rock_Stone"
    },
    {
      "x": 5,
      "y": 19,
      "z": -3,
      "name": "Soil_Dirt"
    },
    {
      "x": 5,
      "y": 20,
      "z": -3,
      "name": "Soil_Dirt"
    },
    {
      "x": 5,
      "y": 21,
      "z": -3,
      "name": "Soil_Grass"
    },
    {
      "x": 5,
      "y": 22,
      "z": -3,
      "name": "Plant_Moss_Rug_Green"
    },
    {
      "x": 5,
      "y": 17,
      "z": -2,
      "name": "Rock_Stone"
    },
    {
      "x": 5,
      "y": 18,
      "z": -2,
      "name": "Rock_Stone"
    },
    {
      "x": 5,
      "y": 19,
      "z": -2,
      "name": "Soil_Dirt"
    },
    {
      "x": 5,
      "y": 20,
      "z": -2,
      "name": "Soil_Dirt"
    },
    {
      "x": 5,
      "y": 21,
      "z": -2,
      "name": "Soil_Grass"
    },
    {
      "x": 5,
      "y": 22,
      "z": -2,
      "name": "Plant_Moss_Rug_Green"
    },
    {
      "x": 5,
      "y": 17,
      "z": -1,
      "name": "Rock_Stone"
    },
    {
      "x": 5,
      "y": 18,
      "z": -1,
      "name": "Rock_Stone"
    },
    {
      "x": 5,
      "y": 19,
      "z": -1,
      "name": "Soil_Dirt"
    },
    {
      "x": 5,
      "y": 20,
      "z": -1,
      "name": "Soil_Dirt"
    },
    {
      "x": 5,
      "y": 21,
      "z": -1,
      "name": "Soil_Grass"
    },
    {
      "x": 5,
      "y": 22,
      "z": -1,
      "name": "Plant_Moss_Rug_Green"
    },
    {
      "x": 5,
      "y": 1,
      "z": 0,
      "name": "Rock_Stone"
    },
    {
      "x": 5,
      "y": 2,
      "z": 0,
      "name": "Rock_Stone"
    },
    {
      "x": 5,
      "y": 16,
      "z": 0,
      "name": "Rock_Stone"
    },
    {
      "x": 5,
      "y": 17,
      "z": 0,
      "name": "Rock_Stone"
    },
    {
      "x": 5,
      "y": 18,
      "z": 0,
      "name": "Rock_Stone"
    },
    {
      "x": 5,
      "y": 19,
      "z": 0,
      "name": "Rock_Stone"
    },
    {
      "x": 5,
      "y": 20,
      "z": 0,
      "name": "Soil_Dirt"
    },
    {
      "x": 5,
      "y": 21,
      "z": 0,
      "name": "Soil_Grass"
    },
    {
      "x": 5,
      "y": 1,
      "z": 1,
      "name": "Rock_Stone"
    },
    {
      "x": 5,
      "y": 2,
      "z": 1,
      "name": "Rock_Stone"
    },
    {
      "x": 5,
      "y": 16,
      "z": 1,
      "name": "Rock_Stone"
    },
    {
      "x": 5,
      "y": 17,
      "z": 1,
      "name": "Rock_Stone"
    },
    {
      "x": 5,
      "y": 18,
      "z": 1,
      "name": "Rock_Stone"
    },
    {
      "x": 5,
      "y": 19,
      "z": 1,
      "name": "Rock_Stone"
    },
    {
      "x": 5,
      "y": 20,
      "z": 1,
      "name": "Rock_Stone"
    },
    {
      "x": 5,
      "y": 21,
      "z": 1,
      "name": "Rock_Stone_Mossy"
    },
    {
      "x": 5,
      "y": 22,
      "z": 1,
      "name": "Rock_Stone_Mossy"
    },
    {
      "x": 5,
      "y": 23,
      "z": 1,
      "name": "Rock_Stone_Mossy"
    },
    {
      "x": 5,
      "y": 2,
      "z": 2,
      "name": "Rock_Stone"
    },
    {
      "x": 5,
      "y": 15,
      "z": 2,
      "name": "Rock_Stone"
    },
    {
      "x": 5,
      "y": 16,
      "z": 2,
      "name": "Rock_Stone"
    },
    {
      "x": 5,
      "y": 17,
      "z": 2,
      "name": "Rock_Stone"
    },
    {
      "x": 5,
      "y": 18,
      "z": 2,
      "name": "Rock_Stone"
    },
    {
      "x": 5,
      "y": 19,
      "z": 2,
      "name": "Rock_Stone"
    },
    {
      "x": 5,
      "y": 20,
      "z": 2,
      "name": "Rock_Stone"
    },
    {
      "x": 5,
      "y": 21,
      "z": 2,
      "name": "Rock_Stone"
    },
    {
      "x": 5,
      "y": 22,
      "z": 2,
      "name": "Rock_Stone_Mossy"
    },
    {
      "x": 5,
      "y": 23,
      "z": 2,
      "name": "Rock_Stone_Mossy"
    },
    {
      "x": 5,
      "y": 15,
      "z": 3,
      "name": "Rock_Stone"
    },
    {
      "x": 5,
      "y": 16,
      "z": 3,
      "name": "Rock_Stone"
    },
    {
      "x": 5,
      "y": 17,
      "z": 3,
      "name": "Rock_Stone"
    },
    {
      "x": 5,
      "y": 18,
      "z": 3,
      "name": "Rock_Stone"
    },
    {
      "x": 5,
      "y": 19,
      "z": 3,
      "name": "Rock_Stone"
    },
    {
      "x": 5,
      "y": 20,
      "z": 3,
      "name": "Rock_Stone_Mossy"
    },
    {
      "x": 5,
      "y": 21,
      "z": 3,
      "name": "Rock_Stone_Mossy"
    },
    {
      "x": 5,
      "y": 22,
      "z": 3,
      "name": "Rock_Stone_Mossy"
    },
    {
      "x": 5,
      "y": 15,
      "z": 4,
      "name": "Rock_Stone"
    },
    {
      "x": 5,
      "y": 16,
      "z": 4,
      "name": "Rock_Stone"
    },
    {
      "x": 5,
      "y": 17,
      "z": 4,
      "name": "Rock_Stone"
    },
    {
      "x": 5,
      "y": 18,
      "z": 4,
      "name": "Rock_Stone"
    },
    {
      "x": 5,
      "y": 19,
      "z": 4,
      "name": "Rock_Stone"
    },
    {
      "x": 5,
      "y": 20,
      "z": 4,
      "name": "Rock_Stone"
    },
    {
      "x": 5,
      "y": 21,
      "z": 4,
      "name": "Rock_Stone"
    },
    {
      "x": 5,
      "y": 22,
      "z": 4,
      "name": "Rock_Stone_Mossy"
    },
    {
      "x": 5,
      "y": 16,
      "z": 5,
      "name": "Rock_Stone"
    },
    {
      "x": 5,
      "y": 17,
      "z": 5,
      "name": "Rock_Stone"
    },
    {
      "x": 5,
      "y": 18,
      "z": 5,
      "name": "Rock_Stone"
    },
    {
      "x": 5,
      "y": 19,
      "z": 5,
      "name": "Rock_Stone"
    },
    {
      "x": 5,
      "y": 20,
      "z": 5,
      "name": "Soil_Gravel"
    },
    {
      "x": 5,
      "y": 21,
      "z": 5,
      "name": "Rock_Stone"
    },
    {
      "x": 5,
      "y": 17,
      "z": 6,
      "name": "Rock_Stone"
    },
    {
      "x": 5,
      "y": 18,
      "z": 6,
      "name": "Soil_Gravel"
    },
    {
      "x": 5,
      "y": 19,
      "z": 6,
      "name": "Soil_Gravel"
    },
    {
      "x": 5,
      "y": 20,
      "z": 6,
      "name": "Soil_Gravel"
    },
    {
      "x": 5,
      "y": 21,
      "z": 6,
      "name": "Soil_Gravel"
    },
    {
      "x": 6,
      "y": 18,
      "z": -4,
      "name": "Rock_Stone"
    },
    {
      "x": 6,
      "y": 19,
      "z": -4,
      "name": "Soil_Grass"
    },
    {
      "x": 6,
      "y": 17,
      "z": -3,
      "name": "Rock_Stone"
    },
    {
      "x": 6,
      "y": 18,
      "z": -3,
      "name": "Rock_Stone"
    },
    {
      "x": 6,
      "y": 19,
      "z": -3,
      "name": "Soil_Dirt"
    },
    {
      "x": 6,
      "y": 20,
      "z": -3,
      "name": "Soil_Dirt"
    },
    {
      "x": 6,
      "y": 21,
      "z": -3,
      "name": "Soil_Grass"
    },
    {
      "x": 6,
      "y": 22,
      "z": -3,
      "name": "Plant_Moss_Rug_Green"
    },
    {
      "x": 6,
      "y": 17,
      "z": -2,
      "name": "Rock_Stone"
    },
    {
      "x": 6,
      "y": 18,
      "z": -2,
      "name": "Rock_Stone"
    },
    {
      "x": 6,
      "y": 19,
      "z": -2,
      "name": "Soil_Dirt"
    },
    {
      "x": 6,
      "y": 20,
      "z": -2,
      "name": "Soil_Dirt"
    },
    {
      "x": 6,
      "y": 21,
      "z": -2,
      "name": "Soil_Leaves"
    },
    {
      "x": 6,
      "y": 22,
      "z": -2,
      "name": "Plant_Grass_Lush_Short"
    },
    {
      "x": 6,
      "y": 16,
      "z": -1,
      "name": "Rock_Stone"
    },
    {
      "x": 6,
      "y": 17,
      "z": -1,
      "name": "Rock_Stone"
    },
    {
      "x": 6,
      "y": 18,
      "z": -1,
      "name": "Rock_Stone"
    },
    {
      "x": 6,
      "y": 19,
      "z": -1,
      "name": "Soil_Dirt"
    },
    {
      "x": 6,
      "y": 20,
      "z": -1,
      "name": "Soil_Dirt"
    },
    {
      "x": 6,
      "y": 21,
      "z": -1,
      "name": "Soil_Leaves"
    },
    {
      "x": 6,
      "y": 2,
      "z": 0,
      "name": "Rock_Stone"
    },
    {
      "x": 6,
      "y": 16,
      "z": 0,
      "name": "Rock_Stone"
    },
    {
      "x": 6,
      "y": 17,
      "z": 0,
      "name": "Rock_Stone"
    },
    {
      "x": 6,
      "y": 18,
      "z": 0,
      "name": "Rock_Stone"
    },
    {
      "x": 6,
      "y": 19,
      "z": 0,
      "name": "Soil_Dirt"
    },
    {
      "x": 6,
      "y": 20,
      "z": 0,
      "name": "Soil_Dirt"
    },
    {
      "x": 6,
      "y": 21,
      "z": 0,
      "name": "Soil_Grass"
    },
    {
      "x": 6,
      "y": 1,
      "z": 1,
      "name": "Rock_Stone"
    },
    {
      "x": 6,
      "y": 2,
      "z": 1,
      "name": "Rock_Stone"
    },
    {
      "x": 6,
      "y": 3,
      "z": 1,
      "name": "Rock_Stone"
    },
    {
      "x": 6,
      "y": 4,
      "z": 1,
      "name": "Rock_Stone"
    },
    {
      "x": 6,
      "y": 15,
      "z": 1,
      "name": "Rock_Stone"
    },
    {
      "x": 6,
      "y": 16,
      "z": 1,
      "name": "Rock_Stone"
    },
    {
      "x": 6,
      "y": 17,
      "z": 1,
      "name": "Rock_Stone"
    },
    {
      "x": 6,
      "y": 18,
      "z": 1,
      "name": "Rock_Stone"
    },
    {
      "x": 6,
      "y": 19,
      "z": 1,
      "name": "Rock_Stone"
    },
    {
      "x": 6,
      "y": 20,
      "z": 1,
      "name": "Rock_Stone"
    },
    {
      "x": 6,
      "y": 21,
      "z": 1,
      "name": "Soil_Grass"
    },
    {
      "x": 6,
      "y": 1,
      "z": 2,
      "name": "Rock_Stone"
    },
    {
      "x": 6,
      "y": 2,
      "z": 2,
      "name": "Rock_Stone"
    },
    {
      "x": 6,
      "y": 3,
      "z": 2,
      "name": "Rock_Stone"
    },
    {
      "x": 6,
      "y": 4,
      "z": 2,
      "name": "Rock_Stone"
    },
    {
      "x": 6,
      "y": 5,
      "z": 2,
      "name": "Rock_Stone"
    },
    {
      "x": 6,
      "y": 15,
      "z": 2,
      "name": "Rock_Stone"
    },
    {
      "x": 6,
      "y": 16,
      "z": 2,
      "name": "Rock_Stone"
    },
    {
      "x": 6,
      "y": 17,
      "z": 2,
      "name": "Rock_Stone"
    },
    {
      "x": 6,
      "y": 18,
      "z": 2,
      "name": "Rock_Stone"
    },
    {
      "x": 6,
      "y": 19,
      "z": 2,
      "name": "Rock_Stone"
    },
    {
      "x": 6,
      "y": 20,
      "z": 2,
      "name": "Rock_Stone"
    },
    {
      "x": 6,
      "y": 21,
      "z": 2,
      "name": "Rock_Stone"
    },
    {
      "x": 6,
      "y": 22,
      "z": 2,
      "name": "Rock_Stone"
    },
    {
      "x": 6,
      "y": 15,
      "z": 3,
      "name": "Rock_Stone"
    },
    {
      "x": 6,
      "y": 16,
      "z": 3,
      "name": "Rock_Stone"
    },
    {
      "x": 6,
      "y": 17,
      "z": 3,
      "name": "Rock_Stone"
    },
    {
      "x": 6,
      "y": 18,
      "z": 3,
      "name": "Rock_Stone"
    },
    {
      "x": 6,
      "y": 19,
      "z": 3,
      "name": "Rock_Stone"
    },
    {
      "x": 6,
      "y": 20,
      "z": 3,
      "name": "Rock_Stone"
    },
    {
      "x": 6,
      "y": 21,
      "z": 3,
      "name": "Rock_Stone"
    },
    {
      "x": 6,
      "y": 22,
      "z": 3,
      "name": "Rock_Stone_Mossy"
    },
    {
      "x": 6,
      "y": 15,
      "z": 4,
      "name": "Rock_Stone"
    },
    {
      "x": 6,
      "y": 16,
      "z": 4,
      "name": "Rock_Stone"
    },
    {
      "x": 6,
      "y": 17,
      "z": 4,
      "name": "Rock_Stone"
    },
    {
      "x": 6,
      "y": 18,
      "z": 4,
      "name": "Rock_Stone"
    },
    {
      "x": 6,
      "y": 19,
      "z": 4,
      "name": "Rock_Stone"
    },
    {
      "x": 6,
      "y": 20,
      "z": 4,
      "name": "Rock_Stone"
    },
    {
      "x": 6,
      "y": 21,
      "z": 4,
      "name": "Rock_Stone"
    },
    {
      "x": 6,
      "y": 22,
      "z": 4,
      "name": "Rock_Stone"
    },
    {
      "x": 6,
      "y": 15,
      "z": 5,
      "name": "Rock_Stone"
    },
    {
      "x": 6,
      "y": 16,
      "z": 5,
      "name": "Rock_Stone"
    },
    {
      "x": 6,
      "y": 17,
      "z": 5,
      "name": "Rock_Stone"
