{
  "version": 8,
  "blockIdVersion": 10,
  "anchorX": -3,
  "anchorY": 10,
  "anchorZ": 1,
  "blocks": [
    {
      "x": -24,
      "y": 44,
      "z": 3,
      "name": "Plant_Leaves_Crystal"
    },
    {
      "x": -24,
      "y": 45,
      "z": 3,
      "name": "Plant_Leaves_Crystal"
    },
    {
      "x": -24,
      "y": 44,
      "z": 4,
      "name": "Plant_Leaves_Crystal"
    },
    {
      "x": -24,
      "y": 45,
      "z": 4,
      "name": "Plant_Leaves_Crystal"
    },
    {
      "x": -24,
      "y": 45,
      "z": 5,
      "name": "Plant_Leaves_Crystal"
    },
    {
      "x": -23,
      "y": 44,
      "z": 2,
      "name": "Plant_Leaves_Crystal"
    },
    {
      "x": -23,
      "y": 45,
      "z": 2,
      "name": "Plant_Leaves_Crystal"
    },
    {
      "x": -23,
      "y": 44,
      "z": 3,
      "name": "Plant_Leaves_Crystal"
    },
    {
      "x": -23,
      "y": 45,
      "z": 3,
      "name": "Plant_Leaves_Crystal"
    },
    {
      "x": -23,
      "y": 46,
      "z": 3,
      "name": "Plant_Leaves_Crystal"
    },
    {
      "x": -23,
      "y": 44,
      "z": 4,
      "name": "Plant_Leaves_Crystal"
    },
    {
      "x": -23,
      "y": 45,
      "z": 4,
      "name": "Plant_Leaves_Crystal"
    },
    {
      "x": -23,
      "y": 46,
      "z": 4,
      "name": "Plant_Leaves_Crystal"
    },
    {
      "x": -23,
      "y": 44,
      "z": 5,
      "name": "Plant_Leaves_Crystal"
    },
    {
      "x": -23,
      "y": 45,
      "z": 5,
      "name": "Plant_Leaves_Crystal"
    },
    {
      "x": -23,
      "y": 46,
      "z": 5,
      "name": "Plant_Leaves_Crystal"
    },
    {
      "x": -23,
      "y": 45,
      "z": 6,
      "name": "Plant_Leaves_Crystal"
    },
    {
      "x": -22,
      "y": 44,
      "z": -1,
      "name": "Plant_Leaves_Crystal"
    },
    {
      "x": -22,
      "y": 45,
      "z": -1,
      "name": "Plant_Leaves_Crystal"
    },
    {
      "x": -22,
      "y": 44,
      "z": 0,
      "name": "Plant_Leaves_Crystal"
    },
    {
      "x": -22,
      "y": 45,
      "z": 0,
      "name": "Plant_Leaves_Crystal"
    },
    {
      "x": -22,
      "y": 44,
      "z": 1,
      "name": "Plant_Leaves_Crystal"
    },
    {
      "x": -22,
      "y": 45,
      "z": 1,
      "name": "Plant_Leaves_Crystal"
    },
    {
      "x": -22,
      "y": 45,
      "z": 2,
      "name": "Plant_Leaves_Crystal"
    },
    {
      "x": -22,
      "y": 43,
      "z": 3,
      "name": "Plant_Fruit_Pinkberry",
      "rotation": 8
    },
    {
      "x": -22,
      "y": 44,
      "z": 3,
      "name": "Plant_Leaves_Crystal"
    },
    {
      "x": -22,
      "y": 45,
      "z": 3,
      "name": "Plant_Leaves_Crystal"
    },
    {
      "x": -22,
      "y": 46,
      "z": 3,
      "name": "Plant_Leaves_Crystal"
    },
    {
      "x": -22,
      "y": 47,
      "z": 3,
      "name": "Plant_Leaves_Crystal"
    },
    {
      "x": -22,
      "y": 44,
      "z": 4,
      "name": "Plant_Leaves_Crystal"
    },
    {
      "x": -22,
      "y": 45,
      "z": 4,
      "name": "Plant_Leaves_Crystal"
    },
    {
      "x": -22,
      "y": 46,
      "z": 4,
      "name": "Plant_Leaves_Crystal"
    },
    {
      "x": -22,
      "y": 47,
      "z": 4,
      "name": "Plant_Leaves_Crystal"
    },
    {
      "x": -22,
      "y": 44,
      "z": 5,
      "name": "Plant_Leaves_Crystal"
    },
    {
      "x": -22,
      "y": 45,
      "z": 5,
      "name": "Plant_Leaves_Crystal"
    },
    {
      "x": -22,
      "y": 46,
      "z": 5,
      "name": "Plant_Leaves_Crystal"
    },
    {
      "x": -22,
      "y": 47,
      "z": 5,
      "name": "Plant_Leaves_Crystal"
    },
    {
      "x": -22,
      "y": 44,
      "z": 6,
      "name": "Plant_Leaves_Crystal"
    },
    {
      "x": -22,
      "y": 45,
      "z": 6,
      "name": "Plant_Leaves_Crystal"
    },
    {
      "x": -22,
      "y": 46,
      "z": 6,
      "name": "Plant_Leaves_Crystal"
    },
    {
      "x": -22,
      "y": 45,
      "z": 7,
      "name": "Plant_Leaves_Crystal"
    },
    {
      "x": -21,
      "y": 44,
      "z": -3,
      "name": "Plant_Leaves_Crystal"
    },
    {
      "x": -21,
      "y": 42,
      "z": -2,
      "name": "Plant_Leaves_Crystal"
    },
    {
      "x": -21,
      "y": 43,
      "z": -2,
      "name": "Plant_Leaves_Crystal"
    },
    {
      "x": -21,
      "y": 44,
      "z": -2,
      "name": "Plant_Leaves_Crystal"
    },
    {
      "x": -21,
      "y": 43,
      "z": -1,
      "name": "Plant_Leaves_Crystal"
    },
    {
      "x": -21,
      "y": 44,
      "z": -1,
      "name": "Plant_Leaves_Crystal"
    },
    {
      "x": -21,
      "y": 45,
      "z": -1,
      "name": "Plant_Leaves_Crystal"
    },
    {
      "x": -21,
      "y": 46,
      "z": -1,
      "name": "Plant_Leaves_Crystal"
    },
    {
      "x": -21,
      "y": 44,
      "z": 0,
      "name": "Plant_Leaves_Crystal"
    },
    {
      "x": -21,
      "y": 45,
      "z": 0,
      "name": "Plant_Leaves_Crystal"
    },
    {
      "x": -21,
      "y": 46,
      "z": 0,
      "name": "Plant_Leaves_Crystal"
    },
    {
      "x": -21,
      "y": 44,
      "z": 1,
      "name": "Plant_Leaves_Crystal"
    },
    {
      "x": -21,
      "y": 47,
      "z": 2,
      "name": "Plant_Leaves_Crystal"
    },
    {
      "x": -21,
      "y": 44,
      "z": 3,
      "name": "Plant_Leaves_Crystal"
    },
    {
      "x": -21,
      "y": 45,
      "z": 3,
      "name": "Plant_Leaves_Crystal"
    },
    {
      "x": -21,
      "y": 46,
      "z": 3,
      "name": "Plant_Leaves_Crystal"
    },
    {
      "x": -21,
      "y": 47,
      "z": 3,
      "name": "Plant_Leaves_Crystal"
    },
    {
      "x": -21,
      "y": 43,
      "z": 4,
      "name": "Plant_Fruit_Pinkberry",
      "rotation": 8
    },
    {
      "x": -21,
      "y": 44,
      "z": 4,
      "name": "Plant_Leaves_Crystal"
    },
    {
      "x": -21,
      "y": 45,
      "z": 4,
      "name": "Plant_Leaves_Crystal"
    },
    {
      "x": -21,
      "y": 46,
      "z": 4,
      "name": "Plant_Leaves_Crystal"
    },
    {
      "x": -21,
      "y": 47,
      "z": 4,
      "name": "Plant_Leaves_Crystal"
    },
    {
      "x": -21,
      "y": 45,
      "z": 5,
      "name": "Plant_Leaves_Crystal"
    },
    {
      "x": -21,
      "y": 46,
      "z": 5,
      "name": "Plant_Leaves_Crystal"
    },
    {
      "x": -21,
      "y": 47,
      "z": 5,
      "name": "Plant_Leaves_Crystal"
    },
    {
      "x": -21,
      "y": 45,
      "z": 6,
      "name": "Plant_Leaves_Crystal"
    },
    {
      "x": -21,
      "y": 46,
      "z": 6,
      "name": "Plant_Leaves_Crystal"
    },
    {
      "x": -21,
      "y": 44,
      "z": 7,
      "name": "Plant_Leaves_Crystal"
    },
    {
      "x": -21,
      "y": 46,
      "z": 7,
      "name": "Plant_Leaves_Crystal"
    },
    {
      "x": -20,
      "y": 44,
      "z": -3,
      "name": "Plant_Leaves_Crystal"
    },
    {
      "x": -20,
      "y": 45,
      "z": -3,
      "name": "Plant_Leaves_Crystal"
    },
    {
      "x": -20,
      "y": 44,
      "z": -2,
      "name": "Plant_Leaves_Crystal"
    },
    {
      "x": -20,
      "y": 45,
      "z": -2,
      "name": "Plant_Leaves_Crystal"
    },
    {
      "x": -20,
      "y": 46,
      "z": -2,
      "name": "Plant_Leaves_Crystal"
    },
    {
      "x": -20,
      "y": 43,
      "z": -1,
      "name": "Plant_Leaves_Crystal"
    },
    {
      "x": -20,
      "y": 44,
      "z": -1,
      "name": "Plant_Leaves_Crystal"
    },
    {
      "x": -20,
      "y": 45,
      "z": -1,
      "name": "Plant_Leaves_Crystal"
    },
    {
      "x": -20,
      "y": 44,
      "z": 0,
      "name": "Plant_Leaves_Crystal"
    },
    {
      "x": -20,
      "y": 45,
      "z": 0,
      "name": "Plant_Leaves_Crystal"
    },
    {
      "x": -20,
      "y": 46,
      "z": 0,
      "name": "Plant_Leaves_Crystal"
    },
    {
      "x": -20,
      "y": 44,
      "z": 2,
      "name": "Plant_Leaves_Crystal"
    },
    {
      "x": -20,
      "y": 44,
      "z": 3,
      "name": "Wood_Crystal_Trunk_Full"
    },
    {
      "x": -20,
      "y": 45,
      "z": 3,
      "name": "Plant_Leaves_Crystal"
    },
    {
      "x": -20,
      "y": 47,
      "z": 3,
      "name": "Plant_Leaves_Crystal"
    },
    {
      "x": -20,
      "y": 44,
      "z": 4,
      "name": "Wood_Crystal_Trunk_Full"
    },
    {
      "x": -20,
      "y": 46,
      "z": 4,
      "name": "Plant_Leaves_Crystal"
    },
    {
      "x": -20,
      "y": 47,
      "z": 4,
      "name": "Plant_Leaves_Crystal"
    },
    {
      "x": -20,
      "y": 43,
      "z": 5,
      "name": "Plant_Fruit_Pinkberry"
    },
    {
      "x": -20,
      "y": 44,
      "z": 5,
      "name": "Plant_Leaves_Crystal"
    },
    {
      "x": -20,
      "y": 46,
      "z": 5,
      "name": "Plant_Leaves_Crystal"
    },
    {
      "x": -20,
      "y": 47,
      "z": 5,
      "name": "Plant_Leaves_Crystal"
    },
    {
      "x": -20,
      "y": 43,
      "z": 6,
      "name": "Plant_Fruit_Pinkberry"
    },
    {
      "x": -20,
      "y": 44,
      "z": 6,
      "name": "Plant_Leaves_Crystal"
    },
    {
      "x": -20,
      "y": 45,
      "z": 6,
      "name": "Plant_Leaves_Crystal"
    },
    {
      "x": -20,
      "y": 43,
      "z": 7,
      "name": "Plant_Leaves_Crystal"
    },
    {
      "x": -20,
      "y": 44,
      "z": 7,
      "name": "Plant_Leaves_Crystal"
    },
    {
      "x": -20,
      "y": 45,
      "z": 7,
      "name": "Plant_Leaves_Crystal"
    },
    {
      "x": -20,
      "y": 44,
      "z": 8,
      "name": "Plant_Leaves_Crystal"
    },
    {
      "x": -19,
      "y": 44,
      "z": -4,
      "name": "Plant_Leaves_Crystal"
    },
    {
      "x": -19,
      "y": 43,
      "z": -3,
      "name": "Plant_Leaves_Crystal"
    },
    {
      "x": -19,
      "y": 44,
      "z": -3,
      "name": "Plant_Leaves_Crystal"
    },
    {
      "x": -19,
      "y": 45,
      "z": -3,
      "name": "Plant_Leaves_Crystal"
    },
    {
      "x": -19,
      "y": 43,
      "z": -2,
      "name": "Plant_Leaves_Crystal"
    },
    {
      "x": -19,
      "y": 44,
      "z": -2,
      "name": "Plant_Leaves_Crystal"
    },
    {
      "x": -19,
      "y": 45,
      "z": -2,
      "name": "Plant_Leaves_Crystal"
    },
    {
      "x": -19,
      "y": 46,
      "z": -2,
      "name": "Plant_Leaves_Crystal"
    },
    {
      "x": -19,
      "y": 43,
      "z": -1,
      "name": "Plant_Leaves_Crystal"
    },
    {
      "x": -19,
      "y": 44,
      "z": -1,
      "name": "Plant_Leaves_Crystal"
    },
    {
      "x": -19,
      "y": 45,
      "z": -1,
      "name": "Plant_Leaves_Crystal"
    },
    {
      "x": -19,
      "y": 46,
      "z": -1,
      "name": "Plant_Leaves_Crystal"
    },
    {
      "x": -19,
      "y": 43,
      "z": 0,
      "name": "Wood_Crystal_Trunk_Full"
    },
    {
      "x": -19,
      "y": 44,
      "z": 0,
      "name": "Plant_Leaves_Crystal"
    },
    {
      "x": -19,
      "y": 46,
      "z": 0,
      "name": "Plant_Leaves_Crystal"
    },
    {
      "x": -19,
      "y": 44,
      "z": 3,
      "name": "Wood_Crystal_Trunk_Full"
    },
    {
      "x": -19,
      "y": 46,
      "z": 5,
      "name": "Plant_Leaves_Crystal"
    },
    {
      "x": -19,
      "y": 43,
      "z": 6,
      "name": "Plant_Leaves_Crystal"
    },
    {
      "x": -19,
      "y": 44,
      "z": 6,
      "name": "Plant_Leaves_Crystal"
    },
    {
      "x": -19,
      "y": 46,
      "z": 6,
      "name": "Plant_Leaves_Crystal"
    },
    {
      "x": -19,
      "y": 43,
      "z": 7,
      "name": "Plant_Leaves_Crystal"
    },
    {
      "x": -19,
      "y": 44,
      "z": 7,
      "name": "Plant_Leaves_Crystal"
    },
    {
      "x": -19,
      "y": 45,
      "z": 7,
      "name": "Plant_Leaves_Crystal"
    },
    {
      "x": -19,
      "y": 46,
      "z": 7,
      "name": "Plant_Leaves_Crystal"
    },
    {
      "x": -19,
      "y": 44,
      "z": 8,
      "name": "Plant_Leaves_Crystal"
    },
    {
      "x": -19,
      "y": 45,
      "z": 8,
      "name": "Plant_Leaves_Crystal"
    },
    {
      "x": -19,
      "y": 44,
      "z": 9,
      "name": "Plant_Leaves_Crystal"
    },
    {
      "x": -18,
      "y": 44,
      "z": -4,
      "name": "Plant_Leaves_Crystal"
    },
    {
      "x": -18,
      "y": 45,
      "z": -4,
      "name": "Plant_Leaves_Crystal"
    },
    {
      "x": -18,
      "y": 42,
      "z": -3,
      "name": "Plant_Leaves_Crystal"
    },
    {
      "x": -18,
      "y": 44,
      "z": -3,
      "name": "Plant_Leaves_Crystal"
    },
    {
      "x": -18,
      "y": 45,
      "z": -3,
      "name": "Plant_Leaves_Crystal"
    },
    {
      "x": -18,
      "y": 41,
      "z": -2,
      "name": "Plant_Fruit_Pinkberry",
      "rotation": 8
    },
    {
      "x": -18,
      "y": 42,
      "z": -2,
      "name": "Plant_Leaves_Crystal"
    },
    {
      "x": -18,
      "y": 44,
      "z": -2,
      "name": "Plant_Leaves_Crystal"
    },
    {
      "x": -18,
      "y": 45,
      "z": -2,
      "name": "Plant_Leaves_Crystal"
    },
    {
      "x": -18,
      "y": 46,
      "z": -2,
      "name": "Plant_Leaves_Crystal"
    },
    {
      "x": -18,
      "y": 42,
      "z": -1,
      "name": "Plant_Leaves_Crystal"
    },
    {
      "x": -18,
      "y": 44,
      "z": -1,
      "name": "Plant_Leaves_Crystal"
    },
    {
      "x": -18,
      "y": 45,
      "z": -1,
      "name": "Plant_Leaves_Crystal"
    },
    {
      "x": -18,
      "y": 46,
      "z": -1,
      "name": "Plant_Leaves_Crystal"
    },
    {
      "x": -18,
      "y": 42,
      "z": 0,
      "name": "Plant_Leaves_Crystal"
    },
    {
      "x": -18,
      "y": 43,
      "z": 0,
      "name": "Wood_Crystal_Trunk_Full"
    },
    {
      "x": -18,
      "y": 44,
      "z": 0,
      "name": "Plant_Leaves_Crystal"
    },
    {
      "x": -18,
      "y": 46,
      "z": 0,
      "name": "Plant_Leaves_Crystal"
    },
    {
      "x": -18,
      "y": 44,
      "z": 1,
      "name": "Plant_Leaves_Crystal"
    },
    {
      "x": -18,
      "y": 43,
      "z": 3,
      "name": "Wood_Crystal_Trunk_Full"
    },
    {
      "x": -18,
      "y": 44,
      "z": 3,
      "name": "Wood_Crystal_Trunk_Full"
    },
    {
      "x": -18,
      "y": 44,
      "z": 5,
      "name": "Plant_Leaves_Crystal"
    },
    {
      "x": -18,
      "y": 44,
      "z": 6,
      "name": "Plant_Leaves_Crystal"
    },
    {
      "x": -18,
      "y": 45,
      "z": 6,
      "name": "Plant_Leaves_Crystal"
    },
    {
      "x": -18,
      "y": 46,
      "z": 6,
      "name": "Plant_Leaves_Crystal"
    },
    {
      "x": -18,
      "y": 43,
      "z": 7,
      "name": "Plant_Leaves_Crystal"
    },
    {
      "x": -18,
      "y": 44,
      "z": 7,
      "name": "Plant_Leaves_Crystal"
    },
    {
      "x": -18,
      "y": 45,
      "z": 7,
      "name": "Plant_Leaves_Crystal"
    },
    {
      "x": -18,
      "y": 43,
      "z": 8,
      "name": "Plant_Leaves_Crystal"
    },
    {
      "x": -18,
      "y": 44,
      "z": 8,
      "name": "Plant_Leaves_Crystal"
    },
    {
      "x": -18,
      "y": 45,
      "z": 8,
      "name": "Plant_Leaves_Crystal"
    },
    {
      "x": -18,
      "y": 44,
      "z": 9,
      "name": "Plant_Leaves_Crystal"
    },
    {
      "x": -18,
      "y": 43,
      "z": 10,
      "name": "Plant_Leaves_Crystal"
    },
    {
      "x": -18,
      "y": 44,
      "z": 10,
      "name": "Plant_Leaves_Crystal"
    },
    {
      "x": -17,
      "y": 39,
      "z": -8,
      "name": "Plant_Leaves_Crystal"
    },
    {
      "x": -17,
      "y": 39,
      "z": -7,
      "name": "Plant_Leaves_Crystal"
    },
    {
      "x": -17,
      "y": 42,
      "z": -5,
      "name": "Plant_Leaves_Crystal"
    },
    {
      "x": -17,
      "y": 42,
      "z": -4,
      "name": "Plant_Leaves_Crystal"
    },
    {
      "x": -17,
      "y": 44,
      "z": -4,
      "name": "Plant_Leaves_Crystal"
    },
    {
      "x": -17,
      "y": 8,
      "z": -3,
      "name": "Wood_Crystal_Trunk_Full"
    },
    {
      "x": -17,
      "y": 41,
      "z": -3,
      "name": "Plant_Leaves_Crystal"
    },
    {
      "x": -17,
      "y": 42,
      "z": -3,
      "name": "Plant_Leaves_Crystal"
    },
    {
      "x": -17,
      "y": 44,
      "z": -3,
      "name": "Plant_Leaves_Crystal"
    },
    {
      "x": -17,
      "y": 45,
      "z": -3,
      "name": "Plant_Leaves_Crystal"
    },
    {
      "x": -17,
      "y": 7,
      "z": -2,
      "name": "Wood_Crystal_Roots"
    },
    {
      "x": -17,
      "y": 8,
      "z": -2,
      "name": "Wood_Crystal_Trunk_Full"
    },
    {
      "x": -17,
      "y": 41,
      "z": -2,
      "name": "Plant_Leaves_Crystal"
    },
    {
      "x": -17,
      "y": 42,
      "z": -2,
      "name": "Plant_Leaves_Crystal"
    },
    {
      "x": -17,
      "y": 44,
      "z": -2,
      "name": "Plant_Leaves_Crystal"
    },
    {
      "x": -17,
      "y": 45,
      "z": -2,
      "name": "Plant_Leaves_Crystal"
    },
    {
      "x": -17,
      "y": 42,
      "z": -1,
      "name": "Plant_Leaves_Crystal"
    },
    {
      "x": -17,
      "y": 43,
      "z": -1,
      "name": "Wood_Crystal_Trunk_Full"
    },
    {
      "x": -17,
      "y": 44,
      "z": -1,
      "name": "Plant_Leaves_Crystal"
    },
    {
      "x": -17,
      "y": 45,
      "z": -1,
      "name": "Plant_Leaves_Crystal"
    },
    {
      "x": -17,
      "y": 46,
      "z": -1,
      "name": "Plant_Leaves_Crystal"
    },
    {
      "x": -17,
      "y": 42,
      "z": 0,
      "name": "Plant_Leaves_Crystal"
    },
    {
      "x": -17,
      "y": 43,
      "z": 0,
      "name": "Wood_Crystal_Trunk_Full"
    },
    {
      "x": -17,
      "y": 43,
      "z": 1,
      "name": "Wood_Crystal_Trunk_Full"
    },
    {
      "x": -17,
      "y": 43,
      "z": 2,
      "name": "Wood_Crystal_Trunk_Full"
    },
    {
      "x": -17,
      "y": 43,
      "z": 3,
      "name": "Wood_Crystal_Trunk_Full"
    },
    {
      "x": -17,
      "y": 40,
      "z": 4,
      "name": "Plant_Leaves_Crystal"
    },
    {
      "x": -17,
      "y": 40,
      "z": 5,
      "name": "Plant_Leaves_Crystal"
    },
    {
      "x": -17,
      "y": 44,
      "z": 5,
      "name": "Plant_Leaves_Crystal"
    },
    {
      "x": -17,
      "y": 40,
      "z": 6,
      "name": "Plant_Leaves_Crystal"
    },
    {
      "x": -17,
      "y": 43,
      "z": 6,
      "name": "Wood_Crystal_Trunk_Full"
    },
    {
      "x": -17,
      "y": 44,
      "z": 6,
      "name": "Plant_Leaves_Crystal"
    },
    {
      "x": -17,
      "y": 43,
      "z": 7,
      "name": "Plant_Leaves_Crystal"
    },
    {
      "x": -17,
      "y": 44,
      "z": 7,
      "name": "Plant_Leaves_Crystal"
    },
    {
      "x": -17,
      "y": 45,
      "z": 7,
      "name": "Plant_Leaves_Crystal"
    },
    {
      "x": -17,
      "y": 43,
      "z": 8,
      "name": "Plant_Leaves_Crystal"
    },
    {
      "x": -17,
      "y": 44,
      "z": 8,
      "name": "Plant_Leaves_Crystal"
    },
    {
      "x": -17,
      "y": 43,
      "z": 9,
      "name": "Plant_Leaves_Crystal"
    },
    {
      "x": -17,
      "y": 44,
      "z": 9,
      "name": "Plant_Leaves_Crystal"
    },
    {
      "x": -17,
      "y": 45,
      "z": 9,
      "name": "Plant_Leaves_Crystal"
    },
    {
      "x": -17,
      "y": 43,
      "z": 10,
      "name": "Plant_Leaves_Crystal"
    },
    {
      "x": -17,
      "y": 44,
      "z": 10,
      "name": "Plant_Leaves_Crystal"
    },
    {
      "x": -17,
      "y": 44,
      "z": 11,
      "name": "Plant_Leaves_Crystal"
    },
    {
      "x": -16,
      "y": 39,
      "z": -10,
      "name": "Plant_Leaves_Crystal"
    },
    {
      "x": -16,
      "y": 39,
      "z": -9,
      "name": "Plant_Leaves_Crystal"
    },
    {
      "x": -16,
      "y": 38,
      "z": -8,
      "name": "Wood_Crystal_Branch_Corner",
      "rotation": 3
    },
    {
      "x": -16,
      "y": 39,
      "z": -8,
      "name": "Plant_Leaves_Crystal"
    },
    {
      "x": -16,
      "y": 39,
      "z": -7,
      "name": "Plant_Leaves_Crystal"
    },
    {
      "x": -16,
      "y": 40,
      "z": -7,
      "name": "Plant_Leaves_Crystal"
    },
    {
      "x": -16,
      "y": 39,
      "z": -6,
      "name": "Plant_Leaves_Crystal"
    },
    {
      "x": -16,
      "y": 42,
      "z": -5,
      "name": "Plant_Leaves_Crystal"
    },
    {
      "x": -16,
      "y": 44,
      "z": -5,
      "name": "Plant_Leaves_Crystal"
    },
    {
      "x": -16,
      "y": 40,
      "z": -4,
      "name": "Plant_Fruit_Pinkberry",
      "rotation": 8
    },
    {
      "x": -16,
      "y": 41,
      "z": -4,
      "name": "Plant_Leaves_Crystal"
    },
    {
      "x": -16,
      "y": 42,
      "z": -4,
      "name": "Plant_Leaves_Crystal"
    },
    {
      "x": -16,
      "y": 44,
      "z": -4,
      "name": "Plant_Leaves_Crystal"
    },
    {
      "x": -16,
      "y": 41,
      "z": -3,
      "name": "Plant_Leaves_Crystal"
    },
    {
      "x": -16,
      "y": 42,
      "z": -3,
      "name": "Plant_Leaves_Crystal"
    },
    {
      "x": -16,
      "y": 44,
      "z": -3,
      "name": "Plant_Leaves_Crystal"
    },
    {
      "x": -16,
      "y": 8,
      "z": -2,
      "name": "Wood_Crystal_Trunk"
    },
    {
      "x": -16,
      "y": 9,
      "z": -2,
      "name": "Wood_Crystal_Trunk_Full"
    },
    {
      "x": -16,
      "y": 41,
      "z": -2,
      "name": "Plant_Leaves_Crystal"
    },
    {
      "x": -16,
      "y": 42,
      "z": -2,
      "name": "Plant_Leaves_Crystal"
    },
    {
      "x": -16,
      "y": 44,
      "z": -2,
      "name": "Plant_Leaves_Crystal"
    },
    {
      "x": -16,
      "y": 7,
      "z": -1,
      "name": "Wood_Crystal_Roots"
    },
    {
      "x": -16,
      "y": 8,
      "z": -1,
      "name": "Wood_Crystal_Trunk"
    },
    {
      "x": -16,
      "y": 9,
      "z": -1,
      "name": "Wood_Crystal_Trunk_Full"
    },
    {
      "x": -16,
      "y": 41,
      "z": -1,
      "name": "Plant_Fruit_Pinkberry",
      "rotation": 8
    },
    {
      "x": -16,
      "y": 42,
      "z": -1,
      "name": "Plant_Leaves_Crystal"
    },
    {
      "x": -16,
      "y": 48,
      "z": -1,
      "name": "Plant_Leaves_Crystal"
    },
    {
      "x": -16,
      "y": 42,
      "z": 0,
      "name": "Plant_Leaves_Crystal"
    },
    {
      "x": -16,
      "y": 42,
      "z": 1,
      "name": "Plant_Leaves_Crystal"
    },
    {
      "x": -16,
      "y": 43,
      "z": 2,
      "name": "Wood_Crystal_Trunk_Full"
    },
    {
      "x": -16,
      "y": 39,
      "z": 3,
      "name": "Plant_Leaves_Crystal"
    },
    {
      "x": -16,
      "y": 40,
      "z": 3,
      "name": "Plant_Leaves_Crystal"
    },
    {
      "x": -16,
      "y": 40,
      "z": 4,
      "name": "Plant_Leaves_Crystal"
    },
    {
      "x": -16,
      "y": 40,
      "z": 5,
      "name": "Plant_Leaves_Crystal"
    },
    {
      "x": -16,
      "y": 41,
      "z": 5,
      "name": "Plant_Leaves_Crystal"
    },
    {
      "x": -16,
      "y": 40,
      "z": 6,
      "name": "Plant_Leaves_Crystal"
    },
    {
      "x": -16,
      "y": 41,
      "z": 6,
      "name": "Plant_Leaves_Crystal"
    },
    {
      "x": -16,
      "y": 43,
      "z": 6,
      "name": "Wood_Crystal_Trunk_Full"
    },
    {
      "x": -16,
      "y": 44,
      "z": 6,
      "name": "Plant_Leaves_Crystal"
    },
    {
      "x": -16,
      "y": 40,
      "z": 7,
      "name": "Plant_Leaves_Crystal"
    },
    {
      "x": -16,
      "y": 43,
      "z": 7,
      "name": "Wood_Crystal_Trunk_Full"
    },
    {
      "x": -16,
      "y": 46,
      "z": 7,
      "name": "Plant_Leaves_Crystal"
    },
    {
      "x": -16,
      "y": 40,
      "z": 8,
      "name": "Plant_Leaves_Crystal"
    },
    {
      "x": -16,
      "y": 44,
      "z": 8,
      "name": "Plant_Leaves_Crystal"
    },
    {
      "x": -16,
      "y": 45,
      "z": 8,
      "name": "Plant_Leaves_Crystal"
    },
    {
      "x": -16,
      "y": 46,
      "z": 8,
      "name": "Plant_Leaves_Crystal"
    },
    {
      "x": -16,
      "y": 44,
      "z": 9,
      "name": "Plant_Leaves_Crystal"
    },
    {
      "x": -16,
      "y": 45,
      "z": 9,
      "name": "Plant_Leaves_Crystal"
    },
    {
      "x": -16,
      "y": 43,
      "z": 10,
      "name": "Plant_Leaves_Crystal"
    },
    {
      "x": -16,
      "y": 44,
      "z": 10,
      "name": "Plant_Leaves_Crystal"
    },
    {
      "x": -16,
      "y": 45,
      "z": 10,
      "name": "Plant_Leaves_Crystal"
    },
    {
      "x": -16,
      "y": 44,
      "z": 11,
      "name": "Plant_Leaves_Crystal"
    },
    {
      "x": -15,
      "y": 37,
      "z": -11,
      "name": "Plant_Leaves_Crystal"
    },
    {
      "x": -15,
      "y": 39,
      "z": -11,
      "name": "Plant_Leaves_Crystal"
    },
    {
      "x": -15,
      "y": 39,
      "z": -10,
      "name": "Plant_Leaves_Crystal"
    },
    {
      "x": -15,
      "y": 40,
      "z": -10,
      "name": "Plant_Leaves_Crystal"
    },
    {
      "x": -15,
      "y": 38,
      "z": -9,
      "name": "Plant_Leaves_Crystal"
    },
    {
      "x": -15,
      "y": 39,
      "z": -9,
      "name": "Plant_Leaves_Crystal"
    },
    {
      "x": -15,
      "y": 40,
      "z": -9,
      "name": "Plant_Leaves_Crystal"
    },
    {
      "x": -15,
      "y": 38,
      "z": -8,
      "name": "Wood_Crystal_Branch_Long",
      "rotation": 5
    },
    {
      "x": -15,
      "y": 39,
      "z": -8,
      "name": "Plant_Leaves_Crystal"
    },
    {
      "x": -15,
      "y": 40,
      "z": -8,
      "name": "Plant_Leaves_Crystal"
    },
    {
      "x": -15,
      "y": 39,
      "z": -7,
      "name": "Plant_Leaves_Crystal"
    },
    {
      "x": -15,
      "y": 40,
      "z": -7,
      "name": "Plant_Leaves_Crystal"
    },
    {
      "x": -15,
      "y": 42,
      "z": -7,
      "name": "Plant_Leaves_Crystal"
    },
    {
      "x": -15,
      "y": 39,
      "z": -6,
      "name": "Plant_Leaves_Crystal"
    },
    {
      "x": -15,
      "y": 40,
      "z": -6,
      "name": "Plant_Leaves_Crystal"
    },
    {
      "x": -15,
      "y": 42,
      "z": -6,
      "name": "Plant_Leaves_Crystal"
    },
    {
      "x": -15,
      "y": 43,
      "z": -6,
      "name": "Plant_Leaves_Crystal"
    },
    {
      "x": -15,
      "y": 37,
      "z": -5,
      "name": "Plant_Leaves_Crystal"
    },
    {
      "x": -15,
      "y": 39,
      "z": -5,
      "name": "Plant_Leaves_Crystal"
    },
    {
      "x": -15,
      "y": 42,
      "z": -5,
      "name": "Plant_Leaves_Crystal"
    },
    {
      "x": -15,
      "y": 43,
      "z": -5,
      "name": "Plant_Leaves_Crystal"
    },
    {
      "x": -15,
      "y": 41,
      "z": -4,
      "name": "Plant_Leaves_Crystal"
    },
    {
      "x": -15,
      "y": 42,
      "z": -4,
      "name": "Plant_Leaves_Crystal"
    },
    {
      "x": -15,
      "y": 44,
      "z": -4,
      "name": "Plant_Leaves_Crystal"
    },
    {
      "x": -15,
      "y": 48,
      "z": -4,
      "name": "Plant_Leaves_Crystal"
    },
    {
      "x": -15,
      "y": 41,
      "z": -3,
      "name": "Plant_Leaves_Crystal"
    },
    {
      "x": -15,
      "y": 42,
      "z": -3,
      "name": "Plant_Leaves_Crystal"
    },
    {
      "x": -15,
      "y": 44,
      "z": -3,
      "name": "Plant_Leaves_Crystal"
    },
    {
      "x": -15,
      "y": 42,
      "z": -2,
      "name": "Plant_Leaves_Crystal"
    },
    {
      "x": -15,
      "y": 44,
      "z": -2,
      "name": "Plant_Leaves_Crystal"
    },
    {
      "x": -15,
      "y": 47,
      "z": -2,
      "name": "Plant_Leaves_Crystal"
    },
    {
      "x": -15,
      "y": 48,
      "z": -2,
      "name": "Plant_Leaves_Crystal"
    },
    {
      "x": -15,
      "y": 8,
      "z": -1,
      "name": "Wood_Crystal_Trunk"
    },
    {
      "x": -15,
      "y": 9,
      "z": -1,
      "name": "Wood_Crystal_Trunk_Full"
    },
    {
      "x": -15,
      "y": 41,
      "z": -1,
      "name": "Plant_Leaves_Crystal"
    },
    {
      "x": -15,
      "y": 42,
      "z": -1,
      "name": "Plant_Leaves_Crystal"
    },
    {
      "x": -15,
      "y": 44,
      "z": -1,
      "name": "Plant_Leaves_Crystal"
    },
    {
      "x": -15,
      "y": 47,
      "z": -1,
      "name": "Plant_Leaves_Crystal"
    },
    {
      "x": -15,
      "y": 48,
      "z": -1,
      "name": "Plant_Leaves_Crystal"
    },
    {
      "x": -15,
      "y": 49,
      "z": -1,
      "name": "Plant_Leaves_Crystal"
    },
    {
      "x": -15,
      "y": 8,
      "z": 0,
      "name": "Wood_Crystal_Trunk"
    },
    {
      "x": -15,
      "y": 9,
      "z": 0,
      "name": "Wood_Crystal_Trunk"
    },
    {
      "x": -15,
      "y": 10,
      "z": 0,
      "name": "Wood_Crystal_Trunk_Full"
    },
    {
      "x": -15,
      "y": 42,
      "z": 0,
      "name": "Plant_Leaves_Crystal"
    },
    {
      "x": -15,
      "y": 9,
      "z": 1,
      "name": "Wood_Crystal_Trunk"
    },
    {
      "x": -15,
      "y": 10,
      "z": 1,
      "name": "Wood_Crystal_Trunk_Full"
    },
    {
      "x": -15,
      "y": 42,
      "z": 1,
      "name": "Plant_Leaves_Crystal"
    },
    {
      "x": -15,
      "y": 48,
      "z": 1,
      "name": "Plant_Leaves_Crystal"
    },
    {
      "x": -15,
      "y": 40,
      "z": 2,
      "name": "Plant_Leaves_Crystal"
    },
    {
      "x": -15,
      "y": 42,
      "z": 2,
      "name": "Wood_Crystal_Trunk_Full"
    },
    {
      "x": -15,
      "y": 43,
      "z": 2,
      "name": "Wood_Crystal_Trunk_Full"
    },
    {
      "x": -15,
      "y": 39,
      "z": 3,
      "name": "Plant_Leaves_Crystal"
    },
    {
      "x": -15,
      "y": 40,
      "z": 3,
      "name": "Plant_Leaves_Crystal"
    },
    {
      "x": -15,
      "y": 43,
      "z": 3,
      "name": "Wood_Crystal_Trunk_Full"
    },
    {
      "x": -15,
      "y": 40,
      "z": 4,
      "name": "Plant_Leaves_Crystal"
    },
    {
      "x": -15,
      "y": 43,
      "z": 4,
      "name": "Wood_Crystal_Trunk_Full"
    },
    {
      "x": -15,
      "y": 49,
      "z": 4,
      "name": "Plant_Leaves_Crystal"
    },
    {
      "x": -15,
      "y": 40,
      "z": 5,
      "name": "Plant_Leaves_Crystal"
    },
    {
      "x": -15,
      "y": 41,
      "z": 5,
      "name": "Plant_Leaves_Crystal"
    },
    {
      "x": -15,
      "y": 43,
      "z": 5,
      "name": "Wood_Crystal_Trunk_Full"
    },
    {
      "x": -15,
      "y": 49,
      "z": 5,
      "name": "Plant_Leaves_Crystal"
    },
    {
      "x": -15,
      "y": 40,
      "z": 6,
      "name": "Plant_Leaves_Crystal"
    },
    {
      "x": -15,
      "y": 41,
      "z": 6,
      "name": "Plant_Leaves_Crystal"
    },
    {
      "x": -15,
      "y": 43,
      "z": 6,
      "name": "Wood_Crystal_Trunk_Full"
    },
    {
      "x": -15,
      "y": 46,
      "z": 6,
      "name": "Plant_Leaves_Crystal"
    },
    {
      "x": -15,
      "y": 49,
      "z": 6,
      "name": "Plant_Leaves_Crystal"
    },
    {
      "x": -15,
      "y": 40,
      "z": 7,
      "name": "Plant_Leaves_Crystal"
    },
    {
      "x": -15,
      "y": 44,
      "z": 7,
      "name": "Plant_Leaves_Crystal"
    },
    {
      "x": -15,
      "y": 45,
      "z": 7,
      "name": "Plant_Leaves_Crystal"
    },
    {
      "x": -15,
      "y": 46,
      "z": 7,
      "name": "Plant_Leaves_Crystal"
    },
    {
      "x": -15,
      "y": 39,
      "z": 8,
      "name": "Plant_Leaves_Crystal"
    },
    {
      "x": -15,
      "y": 40,
      "z": 8,
      "name": "Plant_Leaves_Crystal"
    },
    {
      "x": -15,
      "y": 43,
      "z": 8,
      "name": "Plant_Leaves_Crystal"
    },
    {
      "x": -15,
      "y": 44,
      "z": 8,
      "name": "Plant_Leaves_Crystal"
    },
    {
      "x": -15,
      "y": 45,
      "z": 8,
      "name": "Plant_Leaves_Crystal"
    },
    {
      "x": -15,
      "y": 46,
      "z": 8,
      "name": "Plant_Leaves_Crystal"
    },
    {
      "x": -15,
      "y": 40,
      "z": 9,
      "name": "Plant_Leaves_Crystal"
    },
    {
      "x": -15,
      "y": 43,
      "z": 9,
      "name": "Plant_Leaves_Crystal"
    },
    {
      "x": -15,
      "y": 44,
      "z": 9,
      "name": "Plant_Leaves_Crystal"
    },
    {
      "x": -15,
      "y": 45,
      "z": 9,
      "name": "Plant_Leaves_Crystal"
    },
    {
      "x": -15,
      "y": 41,
      "z": 10,
      "name": "Plant_Leaves_Crystal"
    },
    {
      "x": -15,
      "y": 43,
      "z": 10,
      "name": "Plant_Leaves_Crystal"
    },
    {
      "x": -15,
      "y": 44,
      "z": 10,
      "name": "Plant_Leaves_Crystal"
    },
    {
      "x": -15,
      "y": 45,
      "z": 10,
      "name": "Plant_Leaves_Crystal"
    },
    {
      "x": -15,
      "y": 44,
      "z": 11,
      "name": "Plant_Leaves_Crystal"
    },
    {
      "x": -14,
      "y": 38,
      "z": -13,
      "name": "Plant_Leaves_Crystal"
    },
    {
      "x": -14,
      "y": 38,
      "z": -12,
      "name": "Plant_Leaves_Crystal"
    },
    {
      "x": -14,
      "y": 37,
      "z": -11,
      "name": "Plant_Leaves_Crystal"
    },
    {
      "x": -14,
      "y": 38,
      "z": -11,
      "name": "Plant_Leaves_Crystal"
    },
    {
      "x": -14,
      "y": 39,
      "z": -11,
      "name": "Plant_Leaves_Crystal"
    },
    {
      "x": -14,
      "y": 40,
      "z": -11,
      "name": "Plant_Leaves_Crystal"
    },
    {
      "x": -14,
      "y": 39,
      "z": -10,
      "name": "Plant_Leaves_Crystal"
    },
    {
      "x": -14,
      "y": 40,
      "z": -10,
      "name": "Plant_Leaves_Crystal"
    },
    {
      "x": -14,
      "y": 38,
      "z": -9,
      "name": "Plant_Leaves_Crystal"
    },
    {
      "x": -14,
      "y": 39,
      "z": -9,
      "name": "Plant_Leaves_Crystal"
    },
    {
      "x": -14,
      "y": 40,
      "z": -9,
      "name": "Plant_Leaves_Crystal"
    },
    {
      "x": -14,
      "y": 29,
      "z": -8,
      "name": "Plant_Leaves_Crystal"
    },
    {
      "x": -14,
      "y": 38,
      "z": -8,
      "name": "Wood_Crystal_Trunk_Full"
    },
    {
      "x": -14,
      "y": 39,
      "z": -8,
      "name": "Plant_Leaves_Crystal"
    },
    {
      "x": -14,
      "y": 40,
      "z": -8,
      "name": "Plant_Leaves_Crystal"
    },
    {
      "x": -14,
      "y": 29,
      "z": -7,
      "name": "Plant_Leaves_Crystal"
    },
    {
      "x": -14,
      "y": 38,
      "z": -7,
      "name": "Wood_Crystal_Branch_Corner"
    },
    {
      "x": -14,
      "y": 39,
      "z": -7,
      "name": "Plant_Leaves_Crystal"
    },
    {
      "x": -14,
      "y": 40,
      "z": -7,
      "name": "Plant_Leaves_Crystal"
    },
    {
      "x": -14,
      "y": 42,
      "z": -7,
      "name": "Plant_Leaves_Crystal"
    },
    {
      "x": -14,
      "y": 39,
      "z": -6,
      "name": "Plant_Leaves_Crystal"
    },
    {
      "x": -14,
      "y": 40,
      "z": -6,
      "name": "Plant_Leaves_Crystal"
    },
    {
      "x": -14,
      "y": 42,
      "z": -6,
      "name": "Plant_Leaves_Crystal"
    },
    {
      "x": -14,
      "y": 43,
      "z": -6,
      "name": "Plant_Leaves_Crystal"
    },
    {
      "x": -14,
      "y": 37,
      "z": -5,
      "name": "Plant_Leaves_Crystal"
    },
    {
      "x": -14,
      "y": 39,
      "z": -5,
      "name": "Plant_Leaves_Crystal"
    },
    {
      "x": -14,
      "y": 42,
      "z": -5,
      "name": "Plant_Leaves_Crystal"
    },
    {
      "x": -14,
      "y": 43,
      "z": -5,
      "name": "Plant_Leaves_Crystal"
    },
    {
      "x": -14,
      "y": 37,
      "z": -4,
      "name": "Plant_Leaves_Crystal"
    },
    {
      "x": -14,
      "y": 41,
      "z": -4,
      "name": "Plant_Leaves_Crystal"
    },
    {
      "x": -14,
      "y": 42,
      "z": -4,
      "name": "Plant_Leaves_Crystal"
    },
    {
      "x": -14,
      "y": 48,
      "z": -4,
      "name": "Plant_Leaves_Crystal"
    },
    {
      "x": -14,
      "y": 41,
      "z": -3,
      "name": "Wood_Crystal_Trunk_Full"
    },
    {
      "x": -14,
      "y": 42,
      "z": -3,
      "name": "Plant_Leaves_Crystal"
    },
    {
      "x": -14,
      "y": 44,
      "z": -3,
      "name": "Plant_Leaves_Crystal"
    },
    {
      "x": -14,
      "y": 47,
      "z": -3,
      "name": "Plant_Leaves_Crystal"
    },
    {
      "x": -14,
      "y": 41,
      "z": -2,
      "name": "Wood_Crystal_Trunk_Full"
    },
    {
      "x": -14,
      "y": 44,
      "z": -2,
      "name": "Plant_Leaves_Crystal"
    },
    {
      "x": -14,
      "y": 47,
      "z": -2,
      "name": "Plant_Leaves_Crystal"
    },
    {
      "x": -14,
      "y": 48,
      "z": -2,
      "name": "Plant_Leaves_Crystal"
    },
    {
      "x": -14,
      "y": 49,
      "z": -2,
      "name": "Plant_Leaves_Crystal"
    },
    {
      "x": -14,
      "y": 9,
      "z": -1,
      "name": "Wood_Crystal_Trunk"
    },
    {
      "x": -14,
      "y": 10,
      "z": -1,
      "name": "Wood_Crystal_Trunk_Full"
    },
    {
      "x": -14,
      "y": 41,
      "z": -1,
      "name": "Plant_Leaves_Crystal"
    },
    {
      "x": -14,
      "y": 42,
      "z": -1,
      "name": "Plant_Leaves_Crystal"
    },
    {
      "x": -14,
      "y": 47,
      "z": -1,
      "name": "Plant_Leaves_Crystal"
    },
    {
      "x": -14,
      "y": 48,
      "z": -1,
      "name": "Plant_Leaves_Crystal"
    },
    {
      "x": -14,
      "y": 49,
      "z": -1,
      "name": "Plant_Leaves_Crystal"
    },
    {
      "x": -14,
      "y": 50,
      "z": -1,
      "name": "Plant_Leaves_Crystal"
    },
    {
      "x": -14,
      "y": 8,
      "z": 0,
      "name": "Wood_Crystal_Roots"
    },
    {
      "x": -14,
      "y": 9,
      "z": 0,
      "name": "Wood_Crystal_Trunk"
    },
    {
      "x": -14,
      "y": 10,
      "z": 0,
      "name": "Wood_Crystal_Trunk_Full"
    },
    {
      "x": -14,
      "y": 42,
      "z": 0,
      "name": "Plant_Leaves_Crystal"
    },
    {
      "x": -14,
      "y": 47,
      "z": 0,
      "name": "Plant_Leaves_Crystal"
    },
    {
      "x": -14,
      "y": 49,
      "z": 0,
      "name": "Plant_Leaves_Crystal"
    },
    {
      "x": -14,
      "y": 9,
      "z": 1,
      "name": "Wood_Crystal_Trunk"
    },
    {
      "x": -14,
      "y": 10,
      "z": 1,
      "name": "Wood_Crystal_Trunk"
    },
    {
      "x": -14,
      "y": 11,
      "z": 1,
      "name": "Wood_Crystal_Trunk_Full"
    },
    {
      "x": -14,
      "y": 48,
      "z": 1,
      "name": "Plant_Leaves_Crystal"
    },
    {
      "x": -14,
      "y": 49,
      "z": 1,
      "name": "Plant_Leaves_Crystal"
    },
    {
      "x": -14,
      "y": 39,
      "z": 2,
      "name": "Plant_Leaves_Crystal"
    },
    {
      "x": -14,
      "y": 40,
      "z": 2,
      "name": "Plant_Leaves_Crystal"
    },
    {
      "x": -14,
      "y": 42,
      "z": 2,
      "name": "Wood_Crystal_Trunk_Full"
    },
    {
      "x": -14,
      "y": 43,
      "z": 2,
      "name": "Wood_Crystal_Trunk_Full"
    },
    {
      "x": -14,
      "y": 48,
      "z": 2,
      "name": "Plant_Leaves_Crystal"
    },
    {
      "x": -14,
      "y": 39,
      "z": 3,
      "name": "Plant_Leaves_Crystal"
    },
    {
      "x": -14,
      "y": 40,
      "z": 3,
      "name": "Plant_Leaves_Crystal"
    },
    {
      "x": -14,
      "y": 49,
      "z": 3,
      "name": "Plant_Leaves_Crystal"
    },
    {
      "x": -14,
      "y": 39,
      "z": 4,
      "name": "Plant_Leaves_Crystal"
    },
    {
      "x": -14,
      "y": 40,
      "z": 4,
      "name": "Plant_Leaves_Crystal"
    },
    {
      "x": -14,
      "y": 41,
      "z": 4,
      "name": "Plant_Leaves_Crystal"
    },
    {
      "x": -14,
      "y": 49,
      "z": 4,
      "name": "Plant_Leaves_Crystal"
    },
    {
      "x": -14,
      "y": 40,
      "z": 5,
      "name": "Plant_Leaves_Crystal"
    },
    {
      "x": -14,
      "y": 41,
      "z": 5,
      "name": "Plant_Leaves_Crystal"
    },
    {
      "x": -14,
      "y": 45,
      "z": 5,
      "name": "Plant_Leaves_Crystal"
    },
    {
      "x": -14,
      "y": 49,
      "z": 5,
      "name": "Plant_Leaves_Crystal"
    },
    {
      "x": -14,
      "y": 40,
      "z": 6,
      "name": "Plant_Leaves_Crystal"
    },
    {
      "x": -14,
      "y": 45,
      "z": 6,
      "name": "Plant_Leaves_Crystal"
    },
    {
      "x": -14,
      "y": 46,
      "z": 6,
      "name": "Plant_Leaves_Crystal"
    },
    {
      "x": -14,
      "y": 49,
      "z": 6,
      "name": "Plant_Leaves_Crystal"
    },
    {
      "x": -14,
      "y": 40,
      "z": 7,
      "name": "Plant_Leaves_Crystal"
    },
    {
      "x": -14,
      "y": 41,
      "z": 7,
      "name": "Plant_Leaves_Crystal"
    },
    {
      "x": -14,
      "y": 43,
      "z": 7,
      "name": "Plant_Leaves_Crystal"
    },
    {
      "x": -14,
      "y": 44,
      "z": 7,
      "name": "Plant_Leaves_Crystal"
    },
    {
      "x": -14,
      "y": 45,
      "z": 7,
      "name": "Plant_Leaves_Crystal"
    },
    {
      "x": -14,
      "y": 49,
      "z": 7,
      "name": "Plant_Leaves_Crystal"
    },
    {
      "x": -14,
      "y": 40,
      "z": 8,
      "name": "Plant_Leaves_Crystal"
    },
    {
      "x": -14,
      "y": 41,
      "z": 8,
      "name": "Plant_Leaves_Crystal"
    },
    {
      "x": -14,
      "y": 43,
      "z": 8,
      "name": "Plant_Leaves_Crystal"
    },
    {
      "x": -14,
      "y": 44,
      "z": 8,
      "name": "Plant_Leaves_Crystal"
    },
    {
      "x": -14,
      "y": 45,
      "z": 8,
      "name": "Plant_Leaves_Crystal"
    },
    {
      "x": -14,
      "y": 46,
      "z": 8,
      "name": "Plant_Leaves_Crystal"
    },
    {
      "x": -14,
      "y": 41,
      "z": 9,
      "name": "Plant_Leaves_Crystal"
    },
    {
      "x": -14,
      "y": 43,
      "z": 9,
      "name": "Plant_Leaves_Crystal"
    },
    {
      "x": -14,
      "y": 44,
      "z": 9,
      "name": "Plant_Leaves_Crystal"
    },
    {
      "x": -14,
      "y": 45,
      "z": 9,
      "name": "Plant_Leaves_Crystal"
    },
    {
      "x": -14,
      "y": 41,
      "z": 10,
      "name": "Plant_Leaves_Crystal"
    },
    {
      "x": -14,
      "y": 42,
      "z": 10,
      "name": "Plant_Leaves_Crystal"
    },
    {
      "x": -14,
      "y": 44,
      "z": 10,
      "name": "Plant_Leaves_Crystal"
    },
    {
      "x": -14,
      "y": 41,
      "z": 11,
      "name": "Plant_Leaves_Crystal"
    },
    {
      "x": -14,
      "y": 41,
      "z": 12,
      "name": "Plant_Leaves_Crystal"
    },
    {
      "x": -13,
      "y": 38,
      "z": -13,
      "name": "Plant_Leaves_Crystal"
    },
    {
      "x": -13,
      "y": 38,
      "z": -12,
      "name": "Plant_Leaves_Crystal"
    },
    {
      "x": -13,
      "y": 39,
      "z": -12,
      "name": "Plant_Leaves_Crystal"
    },
    {
      "x": -13,
      "y": 38,
      "z": -11,
      "name": "Plant_Leaves_Crystal"
    },
    {
      "x": -13,
      "y": 39,
      "z": -11,
      "name": "Plant_Leaves_Crystal"
    },
    {
      "x": -13,
      "y": 40,
      "z": -11,
      "name": "Plant_Leaves_Crystal"
    },
    {
      "x": -13,
      "y": 29,
      "z": -10,
      "name": "Plant_Leaves_Crystal"
    },
    {
      "x": -13,
      "y": 38,
      "z": -10,
      "name": "Plant_Leaves_Crystal"
    },
    {
      "x": -13,
      "y": 39,
      "z": -10,
      "name": "Plant_Leaves_Crystal"
    },
    {
      "x": -13,
      "y": 40,
      "z": -10,
      "name": "Plant_Leaves_Crystal"
    },
    {
      "x": -13,
      "y": 47,
      "z": -10,
      "name": "Plant_Leaves_Crystal"
    },
    {
      "x": -13,
      "y": 26,
      "z": -9,
      "name": "Plant_Leaves_Crystal"
    },
    {
      "x": -13,
      "y": 27,
      "z": -9,
      "name": "Plant_Leaves_Crystal"
    },
    {
      "x": -13,
      "y": 28,
      "z": -9,
      "name": "Plant_Leaves_Crystal"
    },
    {
      "x": -13,
      "y": 29,
      "z": -9,
      "name": "Plant_Leaves_Crystal"
    },
    {
      "x": -13,
      "y": 39,
      "z": -9,
      "name": "Plant_Leaves_Crystal"
    },
    {
      "x": -13,
      "y": 40,
      "z": -9,
      "name": "Plant_Leaves_Crystal"
    },
    {
      "x": -13,
      "y": 46,
      "z": -9,
      "name": "Plant_Leaves_Crystal"
    },
    {
      "x": -13,
      "y": 47,
      "z": -9,
      "name": "Plant_Leaves_Crystal"
    },
    {
      "x": -13,
      "y": 29,
      "z": -8,
      "name": "Plant_Leaves_Crystal"
    },
    {
      "x": -13,
      "y": 38,
      "z": -8,
      "name": "Wood_Crystal_Trunk_Full"
    },
    {
      "x": -13,
      "y": 39,
      "z": -8,
      "name": "Plant_Leaves_Crystal"
    },
    {
      "x": -13,
      "y": 47,
      "z": -8,
      "name": "Plant_Leaves_Crystal"
    },
    {
      "x": -13,
      "y": 28,
      "z": -7,
      "name": "Plant_Leaves_Crystal"
    },
    {
      "x": -13,
      "y": 29,
      "z": -7,
      "name": "Plant_Leaves_Crystal"
    },
    {
      "x": -13,
      "y": 40,
      "z": -7,
      "name": "Plant_Leaves_Crystal"
    },
    {
      "x": -13,
      "y": 42,
      "z": -7,
      "name": "Plant_Leaves_Crystal"
    },
    {
      "x": -13,
      "y": 29,
      "z": -6,
      "name": "Plant_Leaves_Crystal"
    },
    {
      "x": -13,
      "y": 39,
      "z": -6,
      "name": "Plant_Leaves_Crystal"
    },
    {
      "x": -13,
      "y": 40,
      "z": -6,
      "name": "Plant_Leaves_Crystal"
    },
    {
      "x": -13,
      "y": 42,
      "z": -6,
      "name": "Plant_Leaves_Crystal"
    },
    {
      "x": -13,
      "y": 43,
      "z": -6,
      "name": "Plant_Leaves_Crystal"
    },
    {
      "x": -13,
      "y": 48,
      "z": -6,
      "name": "Plant_Leaves_Crystal"
    },
    {
      "x": -13,
      "y": 29,
      "z": -5,
      "name": "Plant_Leaves_Crystal"
    },
    {
      "x": -13,
      "y": 37,
      "z": -5,
      "name": "Plant_Leaves_Crystal"
    },
    {
      "x": -13,
      "y": 39,
      "z": -5,
      "name": "Plant_Leaves_Crystal"
    },
    {
      "x": -13,
      "y": 40,
      "z": -5,
      "name": "Plant_Leaves_Crystal"
    },
    {
      "x": -13,
      "y": 42,
      "z": -5,
      "name": "Plant_Leaves_Crystal"
    },
    {
      "x": -13,
      "y": 43,
      "z": -5,
      "name": "Plant_Leaves_Crystal"
    },
    {
      "x": -13,
      "y": 44,
      "z": -5,
      "name": "Plant_Leaves_Crystal"
    },
    {
      "x": -13,
      "y": 48,
      "z": -5,
      "name": "Plant_Leaves_Crystal"
    },
    {
      "x": -13,
      "y": 28,
      "z": -4,
      "name": "Plant_Leaves_Crystal"
    },
    {
      "x": -13,
      "y": 36,
      "z": -4,
      "name": "Plant_Leaves_Crystal"
    },
    {
      "x": -13,
      "y": 37,
      "z": -4,
      "name": "Plant_Leaves_Crystal"
    },
    {
      "x": -13,
      "y": 38,
      "z": -4,
      "name": "Plant_Leaves_Crystal"
    },
    {
      "x": -13,
      "y": 39,
      "z": -4,
      "name": "Plant_Leaves_Crystal"
    },
    {
      "x": -13,
      "y": 42,
      "z": -4,
      "name": "Plant_Leaves_Crystal"
    },
    {
      "x": -13,
      "y": 48,
      "z": -4,
      "name": "Plant_Leaves_Crystal"
    },
    {
      "x": -13,
      "y": 49,
      "z": -4,
      "name": "Plant_Leaves_Crystal"
    },
    {
      "x": -13,
      "y": 28,
      "z": -3,
      "name": "Plant_Leaves_Crystal"
    },
    {
      "x": -13,
      "y": 37,
      "z": -3,
      "name": "Plant_Leaves_Crystal"
    },
    {
      "x": -13,
      "y": 42,
      "z": -3,
      "name": "Plant_Leaves_Crystal"
    },
    {
      "x": -13,
      "y": 47,
      "z": -3,
      "name": "Plant_Leaves_Crystal"
    },
    {
      "x": -13,
      "y": 48,
      "z": -3,
      "name": "Plant_Leaves_Crystal"
    },
    {
      "x": -13,
      "y": 49,
      "z": -3,
      "name": "Plant_Leaves_Crystal"
    },
    {
      "x": -13,
      "y": 41,
      "z": -2,
      "name": "Wood_Crystal_Trunk_Full"
    },
    {
      "x": -13,
      "y": 47,
      "z": -2,
      "name": "Plant_Leaves_Crystal"
    },
    {
      "x": -13,
      "y": 49,
      "z": -2,
      "name": "Plant_Leaves_Crystal"
    },
    {
      "x": -13,
      "y": 50,
      "z": -2,
      "name": "Plant_Leaves_Crystal"
    },
    {
      "x": -13,
      "y": 10,
      "z": -1,
      "name": "Wood_Crystal_Trunk_Full"
    },
    {
      "x": -13,
      "y": 47,
      "z": -1,
      "name": "Plant_Leaves_Crystal"
    },
    {
      "x": -13,
      "y": 48,
      "z": -1,
      "name": "Plant_Leaves_Crystal"
    },
    {
      "x": -13,
      "y": 49,
      "z": -1,
      "name": "Plant_Leaves_Crystal"
    },
    {
      "x": -13,
      "y": 50,
      "z": -1,
      "name": "Plant_Leaves_Crystal"
    },
    {
      "x": -13,
      "y": 9,
      "z": 0,
      "name": "Wood_Crystal_Trunk"
    },
    {
      "x": -13,
      "y": 10,
      "z": 0,
      "name": "Wood_Crystal_Trunk_Full"
    },
    {
      "x": -13,
      "y": 38,
      "z": 0,
      "name": "Plant_Leaves_Crystal"
    },
    {
      "x": -13,
      "y": 42,
      "z": 0,
      "name": "Plant_Leaves_Crystal"
    },
    {
      "x": -13,
      "y": 47,
      "z": 0,
      "name": "Plant_Leaves_Crystal"
    },
    {
      "x": -13,
      "y": 48,
      "z": 0,
      "name": "Plant_Leaves_Crystal"
    },
    {
      "x": -13,
      "y": 49,
      "z": 0,
      "name": "Plant_Leaves_Crystal"
    },
    {
      "x": -13,
      "y": 8,
      "z": 1,
      "name": "Wood_Crystal_Roots"
    },
    {
      "x": -13,
      "y": 9,
      "z": 1,
      "name": "Wood_Crystal_Trunk"
    },
    {
      "x": -13,
      "y": 10,
      "z": 1,
      "name": "Wood_Crystal_Trunk"
    },
    {
      "x": -13,
      "y": 11,
      "z": 1,
      "name": "Wood_Crystal_Trunk_Full"
    },
    {
      "x": -13,
      "y": 39,
      "z": 1,
      "name": "Plant_Leaves_Crystal"
    },
    {
      "x": -13,
      "y": 42,
      "z": 1,
      "name": "Wood_Crystal_Trunk_Full"
    },
    {
      "x": -13,
      "y": 48,
      "z": 1,
      "name": "Plant_Leaves_Crystal"
    },
    {
      "x": -13,
      "y": 49,
      "z": 1,
      "name": "Plant_Leaves_Crystal"
    },
    {
      "x": -13,
      "y": 10,
      "z": 2,
      "name": "Wood_Crystal_Trunk"
    },
    {
      "x": -13,
      "y": 11,
      "z": 2,
      "name": "Wood_Crystal_Trunk_Full"
    },
    {
      "x": -13,
      "y": 39,
      "z": 2,
      "name": "Plant_Leaves_Crystal"
    },
    {
      "x": -13,
      "y": 40,
      "z": 2,
      "name": "Plant_Leaves_Crystal"
    },
    {
      "x": -13,
      "y": 42,
      "z": 2,
      "name": "Wood_Crystal_Trunk_Full"
    },
    {
      "x": -13,
      "y": 48,
      "z": 2,
      "name": "Plant_Leaves_Crystal"
    },
    {
      "x": -13,
      "y": 39,
      "z": 3,
      "name": "Plant_Leaves_Crystal"
    },
    {
      "x": -13,
      "y": 40,
      "z": 3,
      "name": "Plant_Leaves_Crystal"
    },
    {
      "x": -13,
      "y": 48,
      "z": 3,
      "name": "Wood_Crystal_Branch_Corner",
      "rotation": 3
    },
    {
      "x": -13,
      "y": 39,
      "z": 4,
      "name": "Plant_Leaves_Crystal"
    },
    {
      "x": -13,
      "y": 40,
      "z": 4,
      "name": "Plant_Leaves_Crystal"
    },
    {
      "x": -13,
      "y": 42,
      "z": 4,
      "name": "Wood_Crystal_Trunk_Full"
    },
    {
      "x": -13,
      "y": 48,
      "z": 4,
      "name": "Plant_Leaves_Crystal"
    },
    {
      "x": -13,
      "y": 49,
      "z": 4,
      "name": "Plant_Leaves_Crystal"
    },
    {
      "x": -13,
      "y": 38,
      "z": 5,
      "name": "Wood_Crystal_Roots"
    },
    {
      "x": -13,
      "y": 39,
      "z": 5,
      "name": "Wood_Crystal_Trunk_Full"
    },
    {
      "x": -13,
      "y": 40,
      "z": 5,
      "name": "Plant_Leaves_Crystal"
    },
    {
      "x": -13,
      "y": 45,
      "z": 5,
      "name": "Plant_Leaves_Crystal"
    },
    {
      "x": -13,
      "y": 30,
      "z": 6,
      "name": "Plant_Leaves_Crystal"
    },
    {
      "x": -13,
      "y": 40,
      "z": 6,
      "name": "Plant_Leaves_Crystal"
    },
    {
      "x": -13,
      "y": 42,
      "z": 6,
      "name": "Plant_Leaves_Crystal"
    },
    {
      "x": -13,
      "y": 43,
      "z": 6,
      "name": "Plant_Leaves_Crystal"
    },
    {
      "x": -13,
      "y": 44,
      "z": 6,
      "name": "Plant_Leaves_Crystal"
    },
    {
      "x": -13,
      "y": 45,
      "z": 6,
      "name": "Plant_Leaves_Crystal"
    },
    {
      "x": -13,
      "y": 49,
      "z": 6,
      "name": "Plant_Leaves_Crystal"
    },
    {
      "x": -13,
      "y": 30,
      "z": 7,
      "name": "Plant_Leaves_Crystal"
    },
    {
      "x": -13,
      "y": 40,
      "z": 7,
      "name": "Plant_Leaves_Crystal"
    },
    {
      "x": -13,
      "y": 43,
      "z": 7,
      "name": "Plant_Leaves_Crystal"
    },
    {
      "x": -13,
      "y": 44,
      "z": 7,
      "name": "Plant_Leaves_Crystal"
    },
    {
      "x": -13,
      "y": 45,
      "z": 7,
      "name": "Plant_Leaves_Crystal"
    },
    {
      "x": -13,
      "y": 46,
      "z": 7,
      "name": "Plant_Leaves_Crystal"
    },
    {
      "x": -13,
      "y": 30,
      "z": 8,
      "name": "Plant_Leaves_Crystal"
    },
    {
      "x": -13,
      "y": 40,
      "z": 8,
      "name": "Plant_Leaves_Crystal"
    },
    {
      "x": -13,
      "y": 43,
      "z": 8,
      "name": "Plant_Leaves_Crystal"
    },
    {
      "x": -13,
      "y": 44,
      "z": 8,
      "name": "Plant_Leaves_Crystal"
    },
    {
      "x": -13,
      "y": 45,
      "z": 8,
      "name": "Plant_Leaves_Crystal"
    },
    {
      "x": -13,
      "y": 40,
      "z": 9,
      "name": "Plant_Leaves_Crystal"
    },
    {
      "x": -13,
      "y": 41,
      "z": 9,
      "name": "Plant_Leaves_Crystal"
    },
    {
      "x": -13,
      "y": 42,
      "z": 9,
      "name": "Plant_Leaves_Crystal"
    },
    {
      "x": -13,
      "y": 43,
      "z": 9,
      "name": "Plant_Leaves_Crystal"
    },
    {
      "x": -13,
      "y": 44,
      "z": 9,
      "name": "Plant_Leaves_Crystal"
    },
    {
      "x": -13,
      "y": 41,
      "z": 10,
      "name": "Plant_Leaves_Crystal"
    },
    {
      "x": -13,
      "y": 42,
      "z": 10,
      "name": "Plant_Leaves_Crystal"
    },
    {
      "x": -13,
      "y": 41,
      "z": 11,
      "name": "Plant_Leaves_Crystal"
    },
    {
      "x": -13,
      "y": 42,
      "z": 11,
      "name": "Plant_Leaves_Crystal"
    },
    {
      "x": -13,
      "y": 41,
      "z": 12,
      "name": "Plant_Leaves_Crystal"
    },
    {
      "x": -13,
      "y": 42,
      "z": 12,
      "name": "Plant_Leaves_Crystal"
    },
    {
      "x": -12,
      "y": 38,
      "z": -14,
      "name": "Plant_Leaves_Crystal"
    },
    {
      "x": -12,
      "y": 38,
      "z": -13,
      "name": "Plant_Leaves_Crystal"
    },
    {
      "x": -12,
      "y": 39,
      "z": -13,
      "name": "Plant_Leaves_Crystal"
    },
    {
      "x": -12,
      "y": 37,
      "z": -12,
      "name": "Plant_Leaves_Crystal"
    },
    {
      "x": -12,
      "y": 38,
      "z": -12,
      "name": "Plant_Leaves_Crystal"
    },
    {
      "x": -12,
      "y": 39,
      "z": -12,
      "name": "Plant_Leaves_Crystal"
    },
    {
      "x": -12,
      "y": 29,
      "z": -11,
      "name": "Plant_Leaves_Crystal"
    },
    {
      "x": -12,
      "y": 36,
      "z": -11,
      "name": "Plant_Fruit_Pinkberry",
      "rotation": 8
    },
    {
      "x": -12,
      "y": 37,
      "z": -11,
      "name": "Plant_Leaves_Crystal"
    },
    {
      "x": -12,
      "y": 38,
      "z": -11,
      "name": "Plant_Leaves_Crystal"
    },
    {
      "x": -12,
      "y": 39,
      "z": -11,
      "name": "Plant_Leaves_Crystal"
    },
    {
      "x": -12,
      "y": 40,
      "z": -11,
      "name": "Plant_Leaves_Crystal"
    },
    {
      "x": -12,
      "y": 47,
      "z": -11,
      "name": "Plant_Leaves_Crystal"
    },
    {
      "x": -12,
      "y": 28,
      "z": -10,
      "name": "Plant_Leaves_Crystal"
    },
    {
      "x": -12,
      "y": 29,
      "z": -10,
      "name": "Plant_Leaves_Crystal"
    },
    {
      "x": -12,
      "y": 38,
      "z": -10,
      "name": "Wood_Crystal_Branch_Corner",
      "rotation": 2
    },
    {
      "x": -12,
      "y": 39,
      "z": -10,
      "name": "Plant_Leaves_Crystal"
    },
    {
      "x": -12,
      "y": 40,
      "z": -10,
      "name": "Plant_Leaves_Crystal"
    },
    {
      "x": -12,
      "y": 42,
      "z": -10,
      "name": "Plant_Leaves_Crystal"
    },
    {
      "x": -12,
      "y": 47,
      "z": -10,
      "name": "Plant_Leaves_Crystal"
    },
    {
      "x": -12,
      "y": 28,
      "z": -9,
      "name": "Plant_Leaves_Crystal"
    },
    {
      "x": -12,
      "y": 29,
      "z": -9,
      "name": "Plant_Leaves_Crystal"
    },
    {
      "x": -12,
      "y": 38,
      "z": -9,
      "name": "Wood_Crystal_Trunk_Full"
    },
    {
      "x": -12,
      "y": 39,
      "z": -9,
      "name": "Plant_Leaves_Crystal"
    },
    {
      "x": -12,
      "y": 40,
      "z": -9,
      "name": "Plant_Leaves_Crystal"
    },
    {
      "x": -12,
      "y": 42,
      "z": -9,
      "name": "Plant_Leaves_Crystal"
    },
    {
      "x": -12,
      "y": 46,
      "z": -9,
      "name": "Plant_Leaves_Crystal"
    },
    {
      "x": -12,
      "y": 47,
      "z": -9,
      "name": "Plant_Leaves_Crystal"
    },
    {
      "x": -12,
      "y": 48,
      "z": -9,
      "name": "Plant_Leaves_Crystal"
    },
    {
      "x": -12,
      "y": 28,
      "z": -8,
      "name": "Plant_Leaves_Crystal"
    },
    {
      "x": -12,
      "y": 29,
      "z": -8,
      "name": "Plant_Leaves_Crystal"
    },
    {
      "x": -12,
      "y": 30,
      "z": -8,
      "name": "Plant_Leaves_Crystal"
    },
    {
      "x": -12,
      "y": 37,
      "z": -8,
      "name": "Wood_Crystal_Roots"
    },
    {
      "x": -12,
      "y": 38,
      "z": -8,
      "name": "Wood_Crystal_Trunk_Full"
    },
    {
      "x": -12,
      "y": 39,
      "z": -8,
      "name": "Plant_Leaves_Crystal"
    },
    {
      "x": -12,
      "y": 40,
      "z": -8,
      "name": "Plant_Leaves_Crystal"
    },
    {
      "x": -12,
      "y": 46,
      "z": -8,
      "name": "Plant_Leaves_Crystal"
    },
    {
      "x": -12,
      "y": 47,
      "z": -8,
      "name": "Plant_Leaves_Crystal"
    },
    {
      "x": -12,
      "y": 28,
      "z": -7,
      "name": "Plant_Leaves_Crystal"
    },
    {
      "x": -12,
      "y": 29,
      "z": -7,
      "name": "Plant_Leaves_Crystal"
    },
    {
      "x": -12,
      "y": 37,
      "z": -7,
      "name": "Wood_Crystal_Roots"
    },
    {
      "x": -12,
      "y": 38,
      "z": -7,
      "name": "Wood_Crystal_Trunk_Full"
    },
    {
      "x": -12,
      "y": 40,
      "z": -7,
      "name": "Plant_Leaves_Crystal"
    },
    {
      "x": -12,
      "y": 47,
      "z": -7,
      "name": "Plant_Leaves_Crystal"
    },
    {
      "x": -12,
      "y": 29,
      "z": -6,
      "name": "Plant_Leaves_Crystal"
    },
    {
      "x": -12,
      "y": 40,
      "z": -6,
      "name": "Plant_Leaves_Crystal"
    },
    {
      "x": -12,
      "y": 47,
      "z": -6,
      "name": "Plant_Leaves_Crystal"
    },
    {
      "x": -12,
      "y": 28,
      "z": -5,
      "name": "Plant_Leaves_Crystal"
    },
    {
      "x": -12,
      "y": 29,
      "z": -5,
      "name": "Plant_Leaves_Crystal"
    },
    {
      "x": -12,
      "y": 37,
      "z": -5,
      "name": "Plant_Leaves_Crystal"
    },
    {
      "x": -12,
      "y": 39,
      "z": -5,
      "name": "Plant_Leaves_Crystal"
    },
    {
      "x": -12,
      "y": 43,
      "z": -5,
      "name": "Plant_Leaves_Crystal"
    },
    {
      "x": -12,
      "y": 48,
      "z": -5,
      "name": "Plant_Leaves_Crystal"
    },
    {
      "x": -12,
      "y": 25,
      "z": -4,
      "name": "Plant_Leaves_Crystal"
    },
    {
      "x": -12,
      "y": 26,
      "z": -4,
      "name": "Plant_Leaves_Crystal"
    },
    {
      "x": -12,
      "y": 27,
      "z": -4,
      "name": "Plant_Leaves_Crystal"
    },
    {
      "x": -12,
      "y": 28,
      "z": -4,
      "name": "Plant_Leaves_Crystal"
    },
    {
      "x": -12,
      "y": 36,
      "z": -4,
      "name": "Plant_Leaves_Crystal"
    },
    {
      "x": -12,
      "y": 37,
      "z": -4,
      "name": "Plant_Leaves_Crystal"
    },
    {
      "x": -12,
      "y": 38,
      "z": -4,
      "name": "Plant_Leaves_Crystal"
    },
    {
      "x": -12,
      "y": 39,
      "z": -4,
      "name": "Plant_Leaves_Crystal"
    },
    {
      "x": -12,
      "y": 42,
      "z": -4,
      "name": "Plant_Leaves_Crystal"
    },
    {
      "x": -12,
      "y": 47,
      "z": -4,
      "name": "Plant_Leaves_Crystal"
    },
    {
      "x": -12,
      "y": 48,
      "z": -4,
      "name": "Plant_Leaves_Crystal"
    },
    {
      "x": -12,
      "y": 28,
      "z": -3,
      "name": "Plant_Leaves_Crystal"
    },
    {
      "x": -12,
      "y": 36,
      "z": -3,
      "name": "Plant_Fruit_Pinkberry",
      "rotation": 8
    },
    {
      "x": -12,
      "y": 37,
      "z": -3,
      "name": "Plant_Leaves_Crystal"
    },
    {
      "x": -12,
      "y": 38,
      "z": -3,
      "name": "Plant_Leaves_Crystal"
    },
    {
      "x": -12,
      "y": 42,
      "z": -3,
      "name": "Plant_Leaves_Crystal"
    },
    {
      "x": -12,
      "y": 47,
      "z": -3,
      "name": "Plant_Leaves_Crystal"
    },
    {
      "x": -12,
      "y": 48,
      "z": -3,
      "name": "Plant_Leaves_Crystal"
    },
    {
      "x": -12,
      "y": 50,
      "z": -3,
      "name": "Plant_Leaves_Crystal"
    },
    {
      "x": -12,
      "y": 28,
      "z": -2,
      "name": "Plant_Leaves_Crystal"
    },
    {
      "x": -12,
      "y": 37,
      "z": -2,
      "name": "Plant_Leaves_Crystal"
    },
    {
      "x": -12,
      "y": 41,
      "z": -2,
      "name": "Wood_Crystal_Trunk_Full"
    },
    {
      "x": -12,
      "y": 47,
      "z": -2,
      "name": "Wood_Crystal_Trunk_Full"
    },
    {
      "x": -12,
      "y": 48,
      "z": -2,
      "name": "Plant_Leaves_Crystal"
    },
    {
      "x": -12,
      "y": 49,
      "z": -2,
      "name": "Plant_Leaves_Crystal"
    },
    {
      "x": -12,
      "y": 50,
      "z": -2,
      "name": "Plant_Leaves_Crystal"
    },
    {
      "x": -12,
      "y": 28,
      "z": -1,
      "name": "Plant_Leaves_Crystal"
    },
    {
      "x": -12,
      "y": 47,
      "z": -1,
      "name": "Plant_Leaves_Crystal"
    },
    {
      "x": -12,
      "y": 48,
      "z": -1,
      "name": "Plant_Leaves_Crystal"
    },
    {
      "x": -12,
      "y": 49,
      "z": -1,
      "name": "Plant_Leaves_Crystal"
    },
    {
      "x": -12,
      "y": 50,
      "z": -1,
      "name": "Plant_Leaves_Crystal"
    },
    {
      "x": -12,
      "y": 9,
      "z": 0,
      "name": "Wood_Crystal_Roots"
    },
    {
      "x": -12,
      "y": 10,
      "z": 0,
      "name": "Wood_Crystal_Trunk"
    },
    {
      "x": -12,
      "y": 11,
      "z": 0,
      "name": "Wood_Crystal_Trunk_Full"
    },
    {
      "x": -12,
      "y": 28,
      "z": 0,
      "name": "Plant_Leaves_Crystal"
    },
    {
      "x": -12,
      "y": 37,
      "z": 0,
      "name": "Plant_Leaves_Crystal"
    },
    {
      "x": -12,
      "y": 38,
      "z": 0,
      "name": "Plant_Leaves_Crystal"
    },
    {
      "x": -12,
      "y": 39,
      "z": 0,
      "name": "Plant_Leaves_Crystal"
    },
    {
      "x": -12,
      "y": 47,
      "z": 0,
      "name": "Plant_Leaves_Crystal"
    },
    {
      "x": -12,
      "y": 48,
      "z": 0,
      "name": "Plant_Leaves_Crystal"
    },
    {
      "x": -12,
      "y": 49,
      "z": 0,
      "name": "Plant_Leaves_Crystal"
    },
    {
      "x": -12,
      "y": 50,
      "z": 0,
      "name": "Plant_Leaves_Crystal"
    },
    {
      "x": -12,
      "y": 9,
      "z": 1,
      "name": "Wood_Crystal_Trunk"
    },
    {
      "x": -12,
      "y": 10,
      "z": 1,
      "name": "Wood_Crystal_Trunk"
    },
    {
      "x": -12,
      "y": 11,
      "z": 1,
      "name": "Wood_Crystal_Trunk"
    },
    {
      "x": -12,
      "y": 12,
      "z": 1,
      "name": "Wood_Crystal_Trunk_Full"
    },
    {
      "x": -12,
      "y": 37,
      "z": 1,
      "name": "Plant_Leaves_Crystal"
    },
    {
      "x": -12,
      "y": 38,
      "z": 1,
      "name": "Plant_Leaves_Crystal"
    },
    {
      "x": -12,
      "y": 39,
      "z": 1,
      "name": "Plant_Leaves_Crystal"
    },
    {
      "x": -12,
      "y": 42,
      "z": 1,
      "name": "Wood_Crystal_Trunk_Full"
    },
    {
      "x": -12,
      "y": 50,
      "z": 1,
      "name": "Plant_Leaves_Crystal"
    },
    {
      "x": -12,
      "y": 9,
      "z": 2,
      "name": "Wood_Crystal_Trunk"
    },
    {
      "x": -12,
      "y": 10,
      "z": 2,
      "name": "Wood_Crystal_Trunk"
    },
    {
      "x": -12,
      "y": 11,
      "z": 2,
      "name": "Wood_Crystal_Trunk"
    },
    {
      "x": -12,
      "y": 12,
      "z": 2,
      "name": "Wood_Crystal_Trunk_Full"
    },
    {
      "x": -12,
      "y": 37,
      "z": 2,
      "name": "Plant_Leaves_Crystal"
    },
    {
      "x": -12,
      "y": 38,
      "z": 2,
      "name": "Plant_Leaves_Crystal"
    },
    {
      "x": -12,
      "y": 39,
      "z": 2,
      "name": "Plant_Leaves_Crystal"
    },
    {
      "x": -12,
      "y": 42,
      "z": 2,
      "name": "Wood_Crystal_Trunk_Full"
    },
    {
      "x": -12,
      "y": 49,
      "z": 2,
      "name": "Plant_Leaves_Crystal"
    },
    {
      "x": -12,
      "y": 50,
      "z": 2,
      "name": "Plant_Leaves_Crystal"
    },
    {
      "x": -12,
      "y": 29,
      "z": 3,
      "name": "Plant_Leaves_Crystal"
    },
    {
      "x": -12,
      "y": 39,
      "z": 3,
      "name": "Plant_Leaves_Crystal"
    },
    {
      "x": -12,
      "y": 40,
      "z": 3,
      "name": "Plant_Leaves_Crystal"
    },
    {
      "x": -12,
      "y": 42,
      "z": 3,
      "name": "Wood_Crystal_Trunk_Full"
    },
    {
      "x": -12,
      "y": 44,
      "z": 3,
      "name": "Plant_Leaves_Crystal"
    },
    {
      "x": -12,
      "y": 48,
      "z": 3,
      "name": "Wood_Crystal_Branch_Long",
      "rotation": 5
    },
    {
      "x": -12,
      "y": 49,
      "z": 3,
      "name": "Plant_Leaves_Crystal"
    },
    {
      "x": -12,
      "y": 29,
      "z": 4,
      "name": "Plant_Leaves_Crystal"
    },
    {
      "x": -12,
      "y": 30,
      "z": 4,
      "name": "Plant_Leaves_Crystal"
    },
    {
      "x": -12,
      "y": 39,
      "z": 4,
      "name": "Plant_Leaves_Crystal"
    },
    {
      "x": -12,
      "y": 40,
      "z": 4,
      "name": "Plant_Leaves_Crystal"
    },
    {
      "x": -12,
      "y": 42,
      "z": 4,
      "name": "Wood_Crystal_Trunk_Full"
    },
    {
      "x": -12,
      "y": 44,
      "z": 4,
      "name": "Plant_Leaves_Crystal"
    },
    {
      "x": -12,
      "y": 45,
      "z": 4,
      "name": "Plant_Leaves_Crystal"
    },
    {
      "x": -12,
      "y": 48,
      "z": 4,
      "name": "Plant_Leaves_Crystal"
    },
    {
      "x": -12,
      "y": 49,
      "z": 4,
      "name": "Plant_Leaves_Crystal"
    },
    {
      "x": -12,
      "y": 28,
      "z": 5,
      "name": "Plant_Leaves_Crystal"
    },
    {
      "x": -12,
      "y": 30,
      "z": 5,
      "name": "Plant_Leaves_Crystal"
    },
    {
      "x": -12,
      "y": 38,
      "z": 5,
      "name": "Wood_Crystal_Roots"
    },
    {
      "x": -12,
      "y": 39,
      "z": 5,
      "name": "Wood_Crystal_Trunk_Full"
    },
    {
      "x": -12,
      "y": 40,
      "z": 5,
      "name": "Plant_Leaves_Crystal"
    },
    {
      "x": -12,
      "y": 42,
      "z": 5,
      "name": "Wood_Crystal_Trunk_Full"
    },
    {
      "x": -12,
      "y": 43,
      "z": 5,
      "name": "Plant_Leaves_Crystal"
    },
    {
      "x": -12,
      "y": 44,
      "z": 5,
      "name": "Plant_Leaves_Crystal"
    },
    {
      "x": -12,
      "y": 49,
      "z": 5,
      "name": "Plant_Leaves_Crystal"
    },
    {
      "x": -12,
      "y": 50,
      "z": 5,
      "name": "Plant_Leaves_Crystal"
    },
    {
      "x": -12,
      "y": 30,
      "z": 6,
      "name": "Plant_Leaves_Crystal"
    },
    {
      "x": -12,
      "y": 40,
      "z": 6,
      "name": "Plant_Leaves_Crystal"
    },
    {
      "x": -12,
      "y": 42,
      "z": 6,
      "name": "Wood_Crystal_Trunk_Full"
    },
    {
      "x": -12,
      "y": 43,
      "z": 6,
      "name": "Plant_Leaves_Crystal"
    },
    {
      "x": -12,
      "y": 44,
      "z": 6,
      "name": "Plant_Leaves_Crystal"
    },
    {
      "x": -12,
      "y": 45,
      "z": 6,
      "name": "Plant_Leaves_Crystal"
    },
    {
      "x": -12,
      "y": 50,
      "z": 6,
      "name": "Plant_Leaves_Crystal"
    },
    {
      "x": -12,
      "y": 29,
      "z": 7,
      "name": "Plant_Leaves_Crystal"
    },
    {
      "x": -12,
      "y": 30,
      "z": 7,
      "name": "Plant_Leaves_Crystal"
    },
    {
      "x": -12,
      "y": 31,
      "z": 7,
      "name": "Plant_Leaves_Crystal"
    },
    {
      "x": -12,
      "y": 42,
      "z": 7,
      "name": "Plant_Leaves_Crystal"
    },
    {
      "x": -12,
      "y": 43,
      "z": 7,
      "name": "Plant_Leaves_Crystal"
    },
    {
      "x": -12,
      "y": 44,
      "z": 7,
      "name": "Plant_Leaves_Crystal"
    },
    {
      "x": -12,
      "y": 50,
      "z": 7,
      "name": "Plant_Leaves_Crystal"
    },
    {
      "x": -12,
      "y": 30,
      "z": 8,
      "name": "Plant_Leaves_Crystal"
    },
    {
      "x": -12,
      "y": 42,
      "z": 8,
      "name": "Plant_Leaves_Crystal"
    },
    {
      "x": -12,
      "y": 43,
      "z": 8,
      "name": "Plant_Leaves_Crystal"
    },
    {
      "x": -12,
      "y": 44,
      "z": 8,
      "name": "Plant_Leaves_Crystal"
    },
    {
      "x": -12,
      "y": 29,
      "z": 9,
      "name": "Plant_Leaves_Crystal"
    },
    {
      "x": -12,
      "y": 40,
      "z": 9,
      "name": "Wood_Crystal_Trunk_Full"
    },
    {
      "x": -12,
      "y": 41,
      "z": 9,
      "name": "Plant_Leaves_Crystal"
    },
    {
      "x": -12,
      "y": 43,
      "z": 9,
      "name": "Plant_Leaves_Crystal"
    },
    {
      "x": -12,
      "y": 44,
      "z": 9,
      "name": "Plant_Leaves_Crystal"
    },
    {
      "x": -12,
      "y": 49,
      "z": 9,
      "name": "Plant_Leaves_Crystal"
    },
    {
      "x": -12,
      "y": 40,
      "z": 10,
      "name": "Plant_Leaves_Crystal"
    },
    {
      "x": -12,
      "y": 41,
      "z": 10,
      "name": "Plant_Leaves_Crystal"
    },
    {
      "x": -12,
      "y": 41,
      "z": 11,
      "name": "Plant_Leaves_Crystal"
    },
    {
      "x": -12,
      "y": 42,
      "z": 11,
      "name": "Plant_Leaves_Crystal"
    },
    {
      "x": -12,
      "y": 41,
      "z": 12,
      "name": "Plant_Leaves_Crystal"
    },
    {
      "x": -12,
      "y": 42,
      "z": 12,
      "name": "Plant_Leaves_Crystal"
    },
    {
      "x": -12,
      "y": 41,
      "z": 13,
      "name": "Plant_Leaves_Crystal"
    },
    {
      "x": -11,
      "y": 44,
      "z": -15,
      "name": "Plant_Leaves_Crystal"
    },
    {
      "x": -11,
      "y": 38,
      "z": -14,
      "name": "Plant_Leaves_Crystal"
    },
    {
      "x": -11,
      "y": 29,
      "z": -13,
      "name": "Plant_Leaves_Crystal"
    },
    {
      "x": -11,
      "y": 37,
      "z": -13,
      "name": "Plant_Leaves_Crystal"
    },
    {
      "x": -11,
      "y": 38,
      "z": -13,
      "name": "Plant_Leaves_Crystal"
    },
    {
      "x": -11,
      "y": 28,
      "z": -12,
      "name": "Plant_Leaves_Crystal"
    },
    {
      "x": -11,
      "y": 29,
      "z": -12,
      "name": "Plant_Leaves_Crystal"
    },
    {
      "x": -11,
      "y": 38,
      "z": -12,
      "name": "Plant_Leaves_Crystal"
    },
    {
      "x": -11,
      "y": 28,
      "z": -11,
      "name": "Plant_Leaves_Crystal"
    },
    {
      "x": -11,
      "y": 29,
      "z": -11,
      "name": "Plant_Leaves_Crystal"
    },
    {
      "x": -11,
      "y": 37,
      "z": -11,
      "name": "Plant_Leaves_Crystal"
    },
    {
      "x": -11,
      "y": 38,
      "z": -11,
      "name": "Plant_Leaves_Crystal"
    },
    {
      "x": -11,
      "y": 39,
      "z": -11,
      "name": "Plant_Leaves_Crystal"
    },
    {
      "x": -11,
      "y": 42,
      "z": -11,
      "name": "Plant_Leaves_Crystal"
    },
    {
      "x": -11,
      "y": 47,
      "z": -11,
      "name": "Plant_Leaves_Crystal"
    },
    {
      "x": -11,
      "y": 48,
      "z": -11,
      "name": "Plant_Leaves_Crystal"
    },
    {
      "x": -11,
      "y": 28,
      "z": -10,
      "name": "Plant_Leaves_Crystal"
    },
    {
      "x": -11,
      "y": 29,
      "z": -10,
      "name": "Plant_Leaves_Crystal"
    },
    {
      "x": -11,
      "y": 30,
      "z": -10,
      "name": "Plant_Leaves_Crystal"
    },
    {
      "x": -11,
      "y": 38,
      "z": -10,
      "name": "Plant_Leaves_Crystal"
    },
    {
      "x": -11,
      "y": 39,
      "z": -10,
      "name": "Plant_Leaves_Crystal"
    },
    {
      "x": -11,
      "y": 42,
      "z": -10,
      "name": "Plant_Leaves_Crystal"
    },
    {
      "x": -11,
      "y": 47,
      "z": -10,
      "name": "Plant_Leaves_Crystal"
    },
    {
      "x": -11,
      "y": 48,
      "z": -10,
      "name": "Plant_Leaves_Crystal"
    },
    {
      "x": -11,
      "y": 29,
      "z": -9,
      "name": "Plant_Leaves_Crystal"
    },
    {
      "x": -11,
      "y": 30,
      "z": -9,
      "name": "Plant_Leaves_Crystal"
    },
    {
      "x": -11,
      "y": 38,
      "z": -9,
      "name": "Plant_Leaves_Crystal"
    },
    {
      "x": -11,
      "y": 39,
      "z": -9,
      "name": "Plant_Leaves_Crystal"
    },
    {
      "x": -11,
      "y": 40,
      "z": -9,
      "name": "Plant_Leaves_Crystal"
    },
    {
      "x": -11,
      "y": 42,
      "z": -9,
      "name": "Plant_Leaves_Crystal"
    },
    {
      "x": -11,
      "y": 43,
      "z": -9,
      "name": "Plant_Leaves_Crystal"
    },
    {
      "x": -11,
      "y": 46,
      "z": -9,
      "name": "Plant_Leaves_Crystal"
    },
    {
      "x": -11,
      "y": 47,
      "z": -9,
      "name": "Plant_Leaves_Crystal"
    },
    {
      "x": -11,
      "y": 48,
      "z": -9,
      "name": "Plant_Leaves_Crystal"
    },
    {
      "x": -11,
      "y": 28,
      "z": -8,
      "name": "Wood_Crystal_Branch_Corner",
      "rotation": 3
    },
    {
      "x": -11,
      "y": 29,
      "z": -8,
      "name": "Plant_Leaves_Crystal"
    },
    {
      "x": -11,
      "y": 30,
      "z": -8,
      "name": "Plant_Leaves_Crystal"
    },
    {
      "x": -11,
      "y": 39,
      "z": -8,
      "name": "Plant_Leaves_Crystal"
    },
    {
      "x": -11,
      "y": 42,
      "z": -8,
      "name": "Plant_Leaves_Crystal"
    },
    {
      "x": -11,
      "y": 46,
      "z": -8,
      "name": "Plant_Leaves_Crystal"
    },
    {
      "x": -11,
      "y": 47,
      "z": -8,
      "name": "Plant_Leaves_Crystal"
    },
    {
      "x": -11,
      "y": 48,
      "z": -8,
      "name": "Plant_Leaves_Crystal"
    },
    {
      "x": -11,
      "y": 29,
      "z": -7,
      "name": "Plant_Leaves_Crystal"
    },
    {
      "x": -11,
      "y": 30,
      "z": -7,
      "name": "Plant_Leaves_Crystal"
    },
    {
      "x": -11,
      "y": 36,
      "z": -7,
      "name": "Wood_Crystal_Roots"
    },
    {
      "x": -11,
      "y": 37,
      "z": -7,
      "name": "Wood_Crystal_Trunk_Full"
    },
    {
      "x": -11,
      "y": 38,
      "z": -7,
      "name": "Wood_Crystal_Trunk_Full"
    },
    {
      "x": -11,
      "y": 40,
      "z": -7,
      "name": "Plant_Leaves_Crystal"
    },
    {
      "x": -11,
      "y": 47,
      "z": -7,
      "name": "Plant_Leaves_Crystal"
    },
    {
      "x": -11,
      "y": 29,
      "z": -6,
      "name": "Plant_Leaves_Crystal"
    },
    {
      "x": -11,
      "y": 30,
      "z": -6,
      "name": "Plant_Leaves_Crystal"
    },
    {
      "x": -11,
      "y": 38,
      "z": -6,
      "name": "Wood_Crystal_Trunk_Full"
    },
    {
      "x": -11,
      "y": 40,
      "z": -6,
      "name": "Plant_Leaves_Crystal"
    },
    {
      "x": -11,
      "y": 47,
      "z": -6,
      "name": "Plant_Leaves_Crystal"
    },
    {
      "x": -11,
      "y": 48,
      "z": -6,
      "name": "Plant_Leaves_Crystal"
    },
    {
      "x": -11,
      "y": 28,
      "z": -5,
      "name": "Plant_Leaves_Crystal"
    },
    {
      "x": -11,
      "y": 29,
      "z": -5,
      "name": "Plant_Leaves_Crystal"
    },
    {
      "x": -11,
      "y": 48,
      "z": -5,
      "name": "Plant_Leaves_Crystal"
    },
    {
      "x": -11,
      "y": 49,
      "z": -5,
      "name": "Plant_Leaves_Crystal"
    },
    {
      "x": -11,
      "y": 27,
      "z": -4,
      "name": "Plant_Leaves_Crystal"
    },
    {
      "x": -11,
      "y": 28,
      "z": -4,
      "name": "Plant_Leaves_Crystal"
    },
    {
      "x": -11,
      "y": 29,
      "z": -4,
      "name": "Plant_Leaves_Crystal"
    },
    {
      "x": -11,
      "y": 37,
      "z": -4,
      "name": "Plant_Leaves_Crystal"
    },
    {
      "x": -11,
      "y": 47,
      "z": -4,
      "name": "Wood_Crystal_Trunk_Full"
    },
    {
      "x": -11,
      "y": 48,
      "z": -4,
      "name": "Plant_Leaves_Crystal"
    },
    {
      "x": -11,
      "y": 49,
      "z": -4,
      "name": "Plant_Leaves_Crystal"
    },
    {
      "x": -11,
      "y": 28,
      "z": -3,
      "name": "Plant_Leaves_Crystal"
    },
    {
      "x": -11,
      "y": 47,
      "z": -3,
      "name": "Wood_Crystal_Trunk_Full"
    },
    {
      "x": -11,
      "y": 48,
      "z": -3,
      "name": "Plant_Leaves_Crystal"
    },
    {
      "x": -11,
      "y": 49,
      "z": -3,
      "name": "Plant_Leaves_Crystal"
    },
    {
      "x": -11,
      "y": 50,
      "z": -3,
      "name": "Plant_Leaves_Crystal"
    },
    {
      "x": -11,
      "y": 27,
      "z": -2,
      "name": "Plant_Leaves_Crystal"
    },
    {
      "x": -11,
      "y": 28,
      "z": -2,
      "name": "Plant_Leaves_Crystal"
    },
    {
      "x": -11,
      "y": 41,
      "z": -2,
      "name": "Wood_Crystal_Trunk_Full"
    },
    {
      "x": -11,
      "y": 47,
      "z": -2,
      "name": "Wood_Crystal_Trunk_Full"
    },
    {
      "x": -11,
      "y": 48,
      "z": -2,
      "name": "Plant_Leaves_Crystal"
    },
    {
      "x": -11,
      "y": 49,
      "z": -2,
      "name": "Plant_Leaves_Crystal"
    },
    {
      "x": -11,
      "y": 50,
      "z": -2,
      "name": "Plant_Leaves_Crystal"
    },
    {
      "x": -11,
      "y": 28,
      "z": -1,
      "name": "Plant_Leaves_Crystal"
    },
    {
      "x": -11,
      "y": 37,
      "z": -1,
      "name": "Plant_Leaves_Crystal"
    },
    {
      "x": -11,
      "y": 41,
      "z": -1,
      "name": "Wood_Crystal_Trunk_Full"
    },
    {
      "x": -11,
      "y": 48,
      "z": -1,
      "name": "Plant_Leaves_Crystal"
    },
    {
      "x": -11,
      "y": 50,
      "z": -1,
      "name": "Plant_Leaves_Crystal"
    },
    {
      "x": -11,
      "y": 10,
      "z": 0,
      "name": "Wood_Crystal_Trunk"
    },
    {
      "x": -11,
      "y": 11,
      "z": 0,
      "name": "Wood_Crystal_Trunk_Full"
    },
    {
      "x": -11,
      "y": 28,
      "z": 0,
      "name": "Plant_Leaves_Crystal"
    },
    {
      "x": -11,
      "y": 37,
      "z": 0,
      "name": "Plant_Leaves_Crystal"
    },
    {
      "x": -11,
      "y": 38,
      "z": 0,
      "name": "Plant_Leaves_Crystal"
    },
    {
      "x": -11,
      "y": 39,
      "z": 0,
      "name": "Plant_Leaves_Crystal"
    },
    {
      "x": -11,
      "y": 41,
      "z": 0,
      "name": "Wood_Crystal_Trunk_Full"
    },
    {
      "x": -11,
      "y": 48,
      "z": 0,
      "name": "Plant_Leaves_Crystal"
    },
    {
      "x": -11,
      "y": 50,
      "z": 0,
      "name": "Plant_Leaves_Crystal"
    },
    {
      "x": -11,
      "y": 9,
      "z": 1,
      "name": "Wood_Crystal_Trunk"
    },
    {
      "x": -11,
      "y": 10,
      "z": 1,
      "name": "Wood_Crystal_Trunk"
    },
    {
      "x": -11,
      "y": 11,
      "z": 1,
      "name": "Wood_Crystal_Trunk"
    },
    {
      "x": -11,
      "y": 12,
      "z": 1,
      "name": "Wood_Crystal_Trunk_Full"
    },
    {
      "x": -11,
      "y": 29,
      "z": 1,
      "name": "Plant_Leaves_Crystal"
    },
    {
      "x": -11,
      "y": 37,
      "z": 1,
      "name": "Plant_Leaves_Crystal"
    },
    {
      "x": -11,
      "y": 38,
      "z": 1,
      "name": "Plant_Leaves_Crystal"
    },
    {
      "x": -11,
      "y": 39,
      "z": 1,
      "name": "Plant_Leaves_Crystal"
    },
    {
      "x": -11,
      "y": 41,
      "z": 1,
      "name": "Wood_Crystal_Trunk_Full"
    },
    {
      "x": -11,
      "y": 42,
      "z": 1,
      "name": "Wood_Crystal_Trunk_Full"
    },
    {
      "x": -11,
      "y": 48,
      "z": 1,
      "name": "Plant_Leaves_Crystal"
    },
    {
      "x": -11,
      "y": 50,
      "z": 1,
      "name": "Plant_Leaves_Crystal"
    },
    {
      "x": -11,
      "y": 8,
      "z": 2,
      "name": "Wood_Crystal_Roots"
    },
    {
      "x": -11,
      "y": 9,
      "z": 2,
      "name": "Wood_Crystal_Trunk"
    },
    {
      "x": -11,
      "y": 10,
      "z": 2,
      "name": "Wood_Crystal_Trunk"
    },
    {
      "x": -11,
      "y": 11,
      "z": 2,
      "name": "Wood_Crystal_Trunk"
    },
    {
      "x": -11,
      "y": 12,
      "z": 2,
      "name": "Wood_Crystal_Trunk_Full"
    },
    {
      "x": -11,
      "y": 29,
      "z": 2,
      "name": "Plant_Leaves_Crystal"
    },
    {
      "x": -11,
      "y": 37,
      "z": 2,
      "name": "Plant_Leaves_Crystal"
    },
    {
      "x": -11,
      "y": 39,
      "z": 2,
      "name": "Plant_Leaves_Crystal"
    },
    {
      "x": -11,
      "y": 42,
      "z": 2,
      "name": "Wood_Crystal_Trunk_Full"
    },
    {
      "x": -11,
      "y": 50,
      "z": 2,
      "name": "Plant_Leaves_Crystal"
    },
    {
      "x": -11,
      "y": 10,
      "z": 3,
      "name": "Wood_Crystal_Trunk"
    },
    {
      "x": -11,
      "y": 11,
      "z": 3,
      "name": "Wood_Crystal_Trunk"
    },
    {
      "x": -11,
      "y": 12,
      "z": 3,
      "name": "Wood_Crystal_Trunk_Full"
    },
    {
      "x": -11,
      "y": 29,
      "z": 3,
      "name": "Plant_Leaves_Crystal"
    },
    {
      "x": -11,
      "y": 30,
      "z": 3,
      "name": "Plant_Leaves_Crystal"
    },
    {
      "x": -11,
      "y": 39,
      "z": 3,
      "name": "Plant_Leaves_Crystal"
    },
    {
      "x": -11,
      "y": 43,
      "z": 3,
      "name": "Plant_Leaves_Crystal"
    },
    {
      "x": -11,
      "y": 48,
      "z": 3,
      "name": "Wood_Crystal_Branch_Long",
      "rotation": 5
    },
    {
      "x": -11,
      "y": 49,
      "z": 3,
      "name": "Plant_Leaves_Crystal"
    },
    {
      "x": -11,
      "y": 28,
      "z": 4,
      "name": "Plant_Leaves_Crystal"
    },
    {
      "x": -11,
      "y": 29,
      "z": 4,
      "name": "Plant_Leaves_Crystal"
    },
    {
      "x": -11,
      "y": 30,
      "z": 4,
      "name": "Plant_Leaves_Crystal"
    },
    {
      "x": -11,
      "y": 39,
      "z": 4,
      "name": "Plant_Leaves_Crystal"
    },
    {
      "x": -11,
      "y": 43,
      "z": 4,
      "name": "Plant_Leaves_Crystal"
    },
    {
      "x": -11,
      "y": 44,
      "z": 4,
      "name": "Plant_Leaves_Crystal"
    },
    {
      "x": -11,
      "y": 49,
      "z": 4,
      "name": "Plant_Leaves_Crystal"
    },
    {
      "x": -11,
      "y": 50,
      "z": 4,
      "name": "Plant_Leaves_Crystal"
    },
    {
      "x": -11,
      "y": 51,
      "z": 4,
      "name": "Plant_Leaves_Crystal"
    },
    {
      "x": -11,
      "y": 26,
      "z": 5,
      "name": "Plant_Leaves_Crystal"
    },
    {
      "x": -11,
      "y": 27,
      "z": 5,
      "name": "Plant_Leaves_Crystal"
    },
    {
      "x": -11,
      "y": 28,
      "z": 5,
      "name": "Plant_Leaves_Crystal"
    },
    {
      "x": -11,
      "y": 29,
      "z": 5,
      "name": "Plant_Leaves_Crystal"
    },
    {
      "x": -11,
      "y": 30,
      "z": 5,
      "name": "Plant_Leaves_Crystal"
    },
    {
      "x": -11,
      "y": 31,
      "z": 5,
      "name": "Plant_Leaves_Crystal"
    },
    {
      "x": -11,
      "y": 39,
      "z": 5,
      "name": "Wood_Crystal_Trunk_Full"
    },
    {
      "x": -11,
      "y": 42,
      "z": 5,
      "name": "Wood_Crystal_Trunk_Full"
    },
    {
      "x": -11,
      "y": 43,
      "z": 5,
      "name": "Plant_Leaves_Crystal"
    },
    {
      "x": -11,
      "y": 44,
      "z": 5,
      "name": "Plant_Leaves_Crystal"
    },
    {
      "x": -11,
      "y": 49,
      "z": 5,
      "name": "Plant_Leaves_Crystal"
    },
    {
      "x": -11,
      "y": 50,
      "z": 5,
      "name": "Plant_Leaves_Crystal"
    },
    {
      "x": -11,
      "y": 29,
      "z": 6,
      "name": "Plant_Leaves_Crystal"
    },
    {
      "x": -11,
      "y": 30,
      "z": 6,
      "name": "Plant_Leaves_Crystal"
    },
    {
      "x": -11,
      "y": 31,
      "z": 6,
      "name": "Plant_Leaves_Crystal"
    },
    {
      "x": -11,
      "y": 42,
      "z": 6,
      "name": "Plant_Leaves_Crystal"
    },
    {
      "x": -11,
      "y": 43,
      "z": 6,
      "name": "Plant_Leaves_Crystal"
    },
    {
      "x": -11,
      "y": 44,
      "z": 6,
      "name": "Plant_Leaves_Crystal"
    },
    {
      "x": -11,
      "y": 48,
      "z": 6,
      "name": "Plant_Leaves_Crystal"
    },
    {
      "x": -11,
      "y": 50,
      "z": 6,
      "name": "Plant_Leaves_Crystal"
    },
    {
      "x": -11,
      "y": 30,
      "z": 7,
      "name": "Plant_Leaves_Crystal"
    },
    {
      "x": -11,
      "y": 31,
      "z": 7,
      "name": "Plant_Leaves_Crystal"
    },
    {
      "x": -11,
      "y": 42,
      "z": 7,
      "name": "Plant_Leaves_Crystal"
    },
    {
      "x": -11,
      "y": 43,
      "z": 7,
      "name": "Plant_Leaves_Crystal"
    },
    {
      "x": -11,
      "y": 44,
      "z": 7,
      "name": "Plant_Leaves_Crystal"
    },
    {
      "x": -11,
      "y": 48,
      "z": 7,
      "name": "Plant_Leaves_Crystal"
    },
    {
      "x": -11,
      "y": 50,
      "z": 7,
      "name": "Plant_Leaves_Crystal"
    },
    {
      "x": -11,
      "y": 29,
      "z": 8,
      "name": "Plant_Leaves_Crystal"
    },
    {
      "x": -11,
      "y": 30,
      "z": 8,
      "name": "Plant_Leaves_Crystal"
    },
    {
      "x": -11,
      "y": 39,
      "z": 8,
      "name": "Wood_Crystal_Roots"
    },
    {
      "x": -11,
      "y": 40,
      "z": 8,
      "name": "Wood_Crystal_Trunk_Full"
    },
    {
      "x": -11,
      "y": 43,
      "z": 8,
      "name": "Plant_Leaves_Crystal"
    },
    {
      "x": -11,
      "y": 48,
      "z": 8,
      "name": "Plant_Leaves_Crystal"
    },
    {
      "x": -11,
      "y": 29,
      "z": 9,
      "name": "Plant_Leaves_Crystal"
    },
    {
      "x": -11,
      "y": 30,
      "z": 9,
      "name": "Plant_Leaves_Crystal"
    },
    {
      "x": -11,
      "y": 39,
      "z": 9,
      "name": "Wood_Crystal_Roots"
    },
    {
      "x": -11,
      "y": 40,
      "z": 9,
      "name": "Wood_Crystal_Trunk_Full"
    },
    {
      "x": -11,
      "y": 41,
      "z": 9,
      "name": "Plant_Leaves_Crystal"
    },
    {
      "x": -11,
      "y": 42,
      "z": 9,
      "name": "Plant_Leaves_Crystal"
    },
    {
      "x": -11,
      "y": 43,
      "z": 9,
      "name": "Plant_Leaves_Crystal"
    },
    {
      "x": -11,
      "y": 48,
      "z": 9,
      "name": "Plant_Leaves_Crystal"
    },
    {
      "x": -11,
      "y": 49,
      "z": 9,
      "name": "Plant_Leaves_Crystal"
    },
    {
      "x": -11,
      "y": 30,
      "z": 10,
      "name": "Plant_Leaves_Crystal"
    },
    {
      "x": -11,
      "y": 40,
      "z": 10,
      "name": "Plant_Leaves_Crystal"
    },
    {
      "x": -11,
      "y": 41,
      "z": 10,
      "name": "Plant_Leaves_Crystal"
    },
    {
      "x": -11,
      "y": 42,
      "z": 10,
      "name": "Plant_Leaves_Crystal"
    },
    {
      "x": -11,
      "y": 48,
      "z": 10,
      "name": "Plant_Leaves_Crystal"
    },
    {
      "x": -11,
      "y": 49,
      "z": 10,
      "name": "Plant_Leaves_Crystal"
    },
    {
      "x": -11,
      "y": 41,
      "z": 11,
      "name": "Plant_Leaves_Crystal"
    },
    {
      "x": -11,
      "y": 42,
      "z": 11,
      "name": "Plant_Leaves_Crystal"
    },
    {
      "x": -11,
      "y": 40,
      "z": 12,
      "name": "Plant_Leaves_Crystal"
    },
    {
      "x": -11,
      "y": 41,
      "z": 12,
      "name": "Plant_Leaves_Crystal"
    },
    {
      "x": -11,
      "y": 42,
      "z": 12,
      "name": "Plant_Leaves_Crystal"
    },
    {
      "x": -11,
      "y": 41,
      "z": 13,
      "name": "Plant_Leaves_Crystal"
    },
    {
      "x": -11,
      "y": 44,
      "z": 13,
      "name": "Plant_Leaves_Crystal"
    },
    {
      "x": -11,
      "y": 44,
      "z": 14,
      "name": "Plant_Leaves_Crystal"
    },
    {
      "x": -10,
      "y": 44,
      "z": -16,
      "name": "Plant_Leaves_Crystal"
    },
    {
      "x": -10,
      "y": 43,
      "z": -15,
      "name": "Plant_Leaves_Crystal"
    },
    {
      "x": -10,
      "y": 44,
      "z": -15,
      "name": "Plant_Leaves_Crystal"
    },
    {
      "x": -10,
      "y": 38,
      "z": -14,
      "name": "Plant_Leaves_Crystal"
    },
    {
      "x": -10,
      "y": 44,
      "z": -14,
      "name": "Plant_Leaves_Crystal"
    },
    {
      "x": -10,
      "y": 29,
      "z": -13,
      "name": "Plant_Leaves_Crystal"
    },
    {
      "x": -10,
      "y": 38,
      "z": -13,
      "name": "Plant_Leaves_Crystal"
    },
    {
      "x": -10,
      "y": 39,
      "z": -13,
      "name": "Plant_Leaves_Crystal"
    },
    {
      "x": -10,
      "y": 28,
      "z": -12,
      "name": "Plant_Leaves_Crystal"
    },
    {
      "x": -10,
      "y": 29,
      "z": -12,
      "name": "Plant_Leaves_Crystal"
    },
    {
      "x": -10,
      "y": 38,
      "z": -12,
      "name": "Plant_Leaves_Crystal"
    },
    {
      "x": -10,
      "y": 39,
      "z": -12,
      "name": "Plant_Leaves_Crystal"
    },
    {
      "x": -10,
      "y": 42,
      "z": -12,
      "name": "Plant_Leaves_Crystal"
    },
    {
      "x": -10,
      "y": 28,
      "z": -11,
      "name": "Plant_Leaves_Crystal"
    },
    {
      "x": -10,
      "y": 29,
      "z": -11,
      "name": "Plant_Leaves_Crystal"
    },
    {
      "x": -10,
      "y": 30,
      "z": -11,
      "name": "Plant_Leaves_Crystal"
    },
    {
      "x": -10,
      "y": 38,
      "z": -11,
      "name": "Plant_Leaves_Crystal"
    },
    {
      "x": -10,
      "y": 42,
      "z": -11,
      "name": "Plant_Leaves_Crystal"
    },
    {
      "x": -10,
      "y": 46,
      "z": -11,
      "name": "Plant_Leaves_Crystal"
    },
    {
      "x": -10,
      "y": 47,
      "z": -11,
      "name": "Plant_Leaves_Crystal"
    },
    {
      "x": -10,
      "y": 28,
      "z": -10,
      "name": "Plant_Leaves_Crystal"
    },
    {
      "x": -10,
      "y": 29,
      "z": -10,
      "name": "Plant_Leaves_Crystal"
    },
    {
      "x": -10,
      "y": 30,
      "z": -10,
      "name": "Plant_Leaves_Crystal"
    },
    {
      "x": -10,
      "y": 37,
      "z": -10,
      "name": "Wood_Crystal_Trunk_Full"
    },
    {
      "x": -10,
      "y": 38,
      "z": -10,
      "name": "Plant_Leaves_Crystal"
    },
    {
      "x": -10,
      "y": 42,
      "z": -10,
      "name": "Plant_Leaves_Crystal"
    },
    {
      "x": -10,
      "y": 43,
      "z": -10,
      "name": "Plant_Leaves_Crystal"
    },
    {
      "x": -10,
      "y": 44,
      "z": -10,
      "name": "Plant_Leaves_Crystal"
    },
    {
      "x": -10,
      "y": 48,
      "z": -10,
      "name": "Plant_Leaves_Crystal"
    },
    {
      "x": -10,
      "y": 29,
      "z": -9,
      "name": "Plant_Leaves_Crystal"
    },
    {
      "x": -10,
      "y": 30,
      "z": -9,
      "name": "Plant_Leaves_Crystal"
    },
    {
      "x": -10,
      "y": 38,
      "z": -9,
      "name": "Plant_Leaves_Crystal"
    },
    {
      "x": -10,
      "y": 40,
      "z": -9,
      "name": "Plant_Leaves_Crystal"
    },
    {
      "x": -10,
      "y": 42,
      "z": -9,
      "name": "Plant_Leaves_Crystal"
    },
    {
      "x": -10,
      "y": 43,
      "z": -9,
      "name": "Plant_Leaves_Crystal"
    },
    {
      "x": -10,
      "y": 46,
      "z": -9,
      "name": "Plant_Leaves_Crystal"
    },
    {
      "x": -10,
      "y": 48,
      "z": -9,
      "name": "Plant_Leaves_Crystal"
    },
    {
      "x": -10,
      "y": 27,
      "z": -8,
      "name": "Wood_Crystal_Roots"
    },
    {
      "x": -10,
      "y": 28,
      "z": -8,
      "name": "Wood_Crystal_Trunk_Full"
    },
    {
      "x": -10,
      "y": 29,
      "z": -8,
      "name": "Plant_Leaves_Crystal"
    },
    {
      "x": -10,
      "y": 30,
      "z": -8,
      "name": "Plant_Leaves_Crystal"
    },
    {
      "x": -10,
      "y": 31,
      "z": -8,
      "name": "Plant_Leaves_Crystal"
    },
    {
      "x": -10,
      "y": 38,
      "z": -8,
      "name": "Plant_Leaves_Crystal"
    },
    {
      "x": -10,
      "y": 43,
      "z": -8,
      "name": "Plant_Leaves_Crystal"
    },
    {
      "x": -10,
      "y": 46,
      "z": -8,
      "name": "Wood_Crystal_Trunk_Full"
    },
    {
      "x": -10,
      "y": 47,
      "z": -8,
      "name": "Plant_Leaves_Crystal"
    },
    {
      "x": -10,
      "y": 48,
      "z": -8,
      "name": "Plant_Leaves_Crystal"
    },
    {
      "x": -10,
      "y": 28,
      "z": -7,
      "name": "Wood_Crystal_Branch_Corner",
      "rotation": 3
    },
    {
      "x": -10,
      "y": 29,
      "z": -7,
      "name": "Plant_Leaves_Crystal"
    },
    {
      "x": -10,
      "y": 37,
      "z": -7,
      "name": "Wood_Crystal_Trunk_Full"
    },
    {
      "x": -10,
      "y": 46,
      "z": -7,
      "name": "Plant_Leaves_Crystal"
    },
    {
      "x": -10,
      "y": 47,
      "z": -7,
      "name": "Plant_Leaves_Crystal"
    },
    {
      "x": -10,
      "y": 27,
      "z": -6,
      "name": "Plant_Fruit_Pinkberry",
      "rotation": 8
    },
    {
      "x": -10,
      "y": 28,
      "z": -6,
      "name": "Plant_Leaves_Crystal"
    },
    {
      "x": -10,
      "y": 30,
      "z": -6,
      "name": "Plant_Leaves_Crystal"
    },
    {
      "x": -10,
      "y": 31,
      "z": -6,
      "name": "Plant_Leaves_Crystal"
    },
    {
      "x": -10,
      "y": 37,
      "z": -6,
      "name": "Wood_Crystal_Trunk_Full"
    },
    {
      "x": -10,
      "y": 38,
      "z": -6,
      "name": "Wood_Crystal_Trunk_Full"
    },
    {
      "x": -10,
      "y": 28,
      "z": -5,
      "name": "Plant_Leaves_Crystal"
    },
    {
      "x": -10,
      "y": 29,
      "z": -5,
      "name": "Plant_Leaves_Crystal"
    },
    {
      "x": -10,
      "y": 30,
      "z": -5,
      "name": "Plant_Leaves_Crystal"
    },
    {
      "x": -10,
      "y": 37,
      "z": -5,
      "name": "Wood_Crystal_Trunk_Full"
    },
    {
      "x": -10,
      "y": 38,
      "z": -5,
      "name": "Wood_Crystal_Trunk_Full"
    },
    {
      "x": -10,
      "y": 48,
      "z": -5,
      "name": "Plant_Leaves_Crystal"
    },
    {
      "x": -10,
      "y": 28,
      "z": -4,
      "name": "Plant_Leaves_Crystal"
    },
    {
      "x": -10,
      "y": 29,
      "z": -4,
      "name": "Plant_Leaves_Crystal"
    },
    {
      "x": -10,
      "y": 37,
      "z": -4,
      "name": "Wood_Crystal_Trunk_Full"
    },
    {
      "x": -10,
      "y": 49,
      "z": -4,
      "name": "Plant_Leaves_Crystal"
    },
    {
      "x": -10,
      "y": 50,
      "z": -4,
      "name": "Plant_Leaves_Crystal"
    },
    {
      "x": -10,
      "y": 27,
      "z": -3,
      "name": "Wood_Crystal_Trunk_Full"
    },
    {
      "x": -10,
      "y": 28,
      "z": -3,
      "name": "Plant_Leaves_Crystal"
    },
    {
      "x": -10,
      "y": 29,
      "z": -3,
      "name": "Plant_Leaves_Crystal"
    },
    {
      "x": -10,
      "y": 37,
      "z": -3,
      "name": "Wood_Crystal_Trunk_Full"
    },
    {
      "x": -10,
      "y": 48,
      "z": -3,
      "name": "Plant_Leaves_Crystal"
    },
    {
      "x": -10,
      "y": 49,
      "z": -3,
      "name": "Plant_Leaves_Crystal"
    },
    {
      "x": -10,
      "y": 50,
      "z": -3,
      "name": "Plant_Leaves_Crystal"
    },
    {
      "x": -10,
      "y": 27,
      "z": -2,
      "name": "Wood_Crystal_Branch_Corner"
    },
    {
      "x": -10,
      "y": 28,
      "z": -2,
      "name": "Plant_Leaves_Crystal"
    },
    {
      "x": -10,
      "y": 47,
      "z": -2,
      "name": "Wood_Crystal_Trunk_Full"
    },
    {
      "x": -10,
      "y": 49,
      "z": -2,
      "name": "Plant_Leaves_Crystal"
    },
    {
      "x": -10,
      "y": 50,
      "z": -2,
      "name": "Plant_Leaves_Crystal"
    },
    {
      "x": -10,
      "y": 28,
      "z": -1,
      "name": "Plant_Leaves_Crystal"
    },
    {
      "x": -10,
      "y": 50,
      "z": -1,
      "name": "Plant_Leaves_Crystal"
    },
    {
      "x": -10,
      "y": 10,
      "z": 0,
      "name": "Wood_Crystal_Trunk"
    },
    {
      "x": -10,
      "y": 11,
      "z": 0,
      "name": "Wood_Crystal_Trunk"
    },
    {
      "x": -10,
      "y": 12,
      "z": 0,
      "name": "Wood_Crystal_Trunk_Full"
    },
    {
      "x": -10,
      "y": 28,
      "z": 0,
      "name": "Plant_Leaves_Crystal"
    },
    {
      "x": -10,
      "y": 36,
      "z": 0,
      "name": "Plant_Fruit_Pinkberry",
      "rotation": 8
    },
    {
      "x": -10,
      "y": 37,
      "z": 0,
      "name": "Plant_Leaves_Crystal"
    },
    {
      "x": -10,
      "y": 38,
      "z": 0,
      "name": "Plant_Leaves_Crystal"
    },
    {
      "x": -10,
      "y": 50,
      "z": 0,
      "name": "Plant_Leaves_Crystal"
    },
    {
      "x": -10,
      "y": 9,
      "z": 1,
      "name": "Wood_Crystal_Trunk"
    },
    {
      "x": -10,
      "y": 10,
      "z": 1,
      "name": "Wood_Crystal_Trunk"
    },
    {
      "x": -10,
      "y": 11,
      "z": 1,
      "name": "Wood_Crystal_Trunk"
    },
    {
      "x": -10,
      "y": 12,
      "z": 1,
      "name": "Wood_Crystal_Trunk"
    },
    {
      "x": -10,
      "y": 13,
      "z": 1,
      "name": "Wood_Crystal_Trunk_Full"
    },
    {
      "x": -10,
      "y": 29,
      "z": 1,
      "name": "Plant_Leaves_Crystal"
    },
    {
      "x": -10,
      "y": 37,
      "z": 1,
      "name": "Plant_Leaves_Crystal"
    },
    {
      "x": -10,
      "y": 38,
      "z": 1,
      "name": "Plant_Leaves_Crystal"
    },
    {
      "x": -10,
      "y": 39,
      "z": 1,
      "name": "Plant_Leaves_Crystal"
    },
    {
      "x": -10,
      "y": 40,
      "z": 1,
      "name": "Wood_Crystal_Trunk_Full"
    },
    {
      "x": -10,
      "y": 41,
      "z": 1,
      "name": "Wood_Crystal_Trunk"
    },
    {
      "x": -10,
      "y": 42,
      "z": 1,
      "name": "Wood_Crystal_Trunk_Full"
    },
    {
      "x": -10,
      "y": 9,
      "z": 2,
      "name": "Wood_Crystal_Roots"
    },
    {
      "x": -10,
      "y": 10,
      "z": 2,
      "name": "Wood_Crystal_Trunk"
    },
    {
      "x": -10,
      "y": 11,
      "z": 2,
      "name": "Wood_Crystal_Trunk"
    },
    {
      "x": -10,
      "y": 12,
      "z": 2,
      "name": "Wood_Crystal_Trunk"
    },
    {
      "x": -10,
      "y": 13,
      "z": 2,
      "name": "Wood_Crystal_Trunk_Full"
    },
    {
      "x": -10,
      "y": 29,
      "z": 2,
      "name": "Plant_Leaves_Crystal"
    },
    {
      "x": -10,
      "y": 30,
      "z": 2,
      "name": "Plant_Leaves_Crystal"
    },
    {
      "x": -10,
      "y": 37,
      "z": 2,
      "name": "Plant_Leaves_Crystal"
    },
    {
      "x": -10,
      "y": 38,
      "z": 2,
      "name": "Plant_Leaves_Crystal"
    },
    {
      "x": -10,
      "y": 39,
      "z": 2,
