{
  "version": 8,
  "blockIdVersion": 8,
  "anchorX": 9,
  "anchorY": 10,
  "anchorZ": 7,
  "blocks": [
    {
      "x": 4,
      "y": 18,
      "z": 8,
      "name": "Plant_Leaves_Bramble"
    },
    {
      "x": 4,
      "y": 18,
      "z": 9,
      "name": "Plant_Leaves_Bramble"
    },
    {
      "x": 5,
      "y": 18,
      "z": 6,
      "name": "Plant_Leaves_Bramble"
    },
    {
      "x": 5,
      "y": 18,
      "z": 7,
      "name": "Plant_Leaves_Bramble"
    },
    {
      "x": 5,
      "y": 20,
      "z": 7,
      "name": "Plant_Leaves_Bramble"
    },
    {
      "x": 5,
      "y": 17,
      "z": 8,
      "name": "Wood_Beech_Branch_Long",
      "rotation": 5
    },
    {
      "x": 5,
      "y": 18,
      "z": 8,
      "name": "Plant_Leaves_Bramble"
    },
    {
      "x": 5,
      "y": 20,
      "z": 8,
      "name": "Plant_Leaves_Bramble"
    },
    {
      "x": 5,
      "y": 18,
      "z": 9,
      "name": "Plant_Leaves_Bramble"
    },
    {
      "x": 5,
      "y": 19,
      "z": 9,
      "name": "Plant_Leaves_Bramble"
    },
    {
      "x": 5,
      "y": 20,
      "z": 9,
      "name": "Plant_Leaves_Bramble"
    },
    {
      "x": 5,
      "y": 19,
      "z": 10,
      "name": "Plant_Leaves_Bramble"
    },
    {
      "x": 6,
      "y": 18,
      "z": 5,
      "name": "Plant_Leaves_Bramble"
    },
    {
      "x": 6,
      "y": 18,
      "z": 6,
      "name": "Plant_Leaves_Bramble"
    },
    {
      "x": 6,
      "y": 20,
      "z": 7,
      "name": "Plant_Leaves_Bramble"
    },
    {
      "x": 6,
      "y": 17,
      "z": 8,
      "name": "Wood_Beech_Trunk_Full"
    },
    {
      "x": 6,
      "y": 18,
      "z": 8,
      "name": "Wood_Beech_Trunk"
    },
    {
      "x": 6,
      "y": 19,
      "z": 8,
      "name": "Wood_Beech_Trunk_Full"
    },
    {
      "x": 6,
      "y": 20,
      "z": 8,
      "name": "Plant_Leaves_Bramble"
    },
    {
      "x": 6,
      "y": 16,
      "z": 9,
      "name": "Plant_Leaves_Bramble"
    },
    {
      "x": 6,
      "y": 19,
      "z": 9,
      "name": "Wood_Beech_Branch_Corner"
    },
    {
      "x": 6,
      "y": 20,
      "z": 9,
      "name": "Plant_Leaves_Bramble"
    },
    {
      "x": 6,
      "y": 20,
      "z": 10,
      "name": "Plant_Leaves_Bramble"
    },
    {
      "x": 6,
      "y": 20,
      "z": 11,
      "name": "Plant_Leaves_Bramble"
    },
    {
      "x": 7,
      "y": 18,
      "z": 5,
      "name": "Plant_Leaves_Bramble"
    },
    {
      "x": 7,
      "y": 17,
      "z": 6,
      "name": "Wood_Beech_Branch_Corner",
      "rotation": 3
    },
    {
      "x": 7,
      "y": 18,
      "z": 6,
      "name": "Plant_Leaves_Bramble"
    },
    {
      "x": 7,
      "y": 19,
      "z": 6,
      "name": "Plant_Leaves_Bramble"
    },
    {
      "x": 7,
      "y": 20,
      "z": 6,
      "name": "Plant_Leaves_Bramble"
    },
    {
      "x": 7,
      "y": 18,
      "z": 7,
      "name": "Plant_Leaves_Bramble"
    },
    {
      "x": 7,
      "y": 20,
      "z": 7,
      "name": "Plant_Leaves_Bramble"
    },
    {
      "x": 7,
      "y": 15,
      "z": 8,
      "name": "Wood_Beech_Trunk_Full"
    },
    {
      "x": 7,
      "y": 16,
      "z": 8,
      "name": "Wood_Beech_Trunk"
    },
    {
      "x": 7,
      "y": 17,
      "z": 8,
      "name": "Wood_Beech_Trunk_Full"
    },
    {
      "x": 7,
      "y": 20,
      "z": 8,
      "name": "Plant_Leaves_Bramble"
    },
    {
      "x": 7,
      "y": 16,
      "z": 9,
      "name": "Plant_Leaves_Bramble"
    },
    {
      "x": 7,
      "y": 17,
      "z": 9,
      "name": "Plant_Leaves_Bramble"
    },
    {
      "x": 7,
      "y": 20,
      "z": 9,
      "name": "Plant_Leaves_Bramble"
    },
    {
      "x": 7,
      "y": 20,
      "z": 10,
      "name": "Plant_Leaves_Bramble"
    },
    {
      "x": 8,
      "y": 18,
      "z": 4,
      "name": "Plant_Leaves_Bramble"
    },
    {
      "x": 8,
      "y": 15,
      "z": 5,
      "name": "Wood_Beech_Branch_Long",
      "rotation": 4
    },
    {
      "x": 8,
      "y": 17,
      "z": 5,
      "name": "Plant_Leaves_Bramble"
    },
    {
      "x": 8,
      "y": 18,
      "z": 5,
      "name": "Plant_Leaves_Bramble"
    },
    {
      "x": 8,
      "y": 15,
      "z": 6,
      "name": "Wood_Beech_Trunk_Full"
    },
    {
      "x": 8,
      "y": 16,
      "z": 6,
      "name": "Wood_Beech_Trunk"
    },
    {
      "x": 8,
      "y": 17,
      "z": 6,
      "name": "Wood_Beech_Trunk_Full"
    },
    {
      "x": 8,
      "y": 18,
      "z": 6,
      "name": "Plant_Leaves_Bramble"
    },
    {
      "x": 8,
      "y": 19,
      "z": 6,
      "name": "Plant_Leaves_Bramble"
    },
    {
      "x": 8,
      "y": 14,
      "z": 7,
      "name": "Wood_Beech_Trunk_Full"
    },
    {
      "x": 8,
      "y": 15,
      "z": 7,
      "name": "Wood_Beech_Trunk_Full"
    },
    {
      "x": 8,
      "y": 18,
      "z": 7,
      "name": "Plant_Leaves_Bramble"
    },
    {
      "x": 8,
      "y": 15,
      "z": 8,
      "name": "Wood_Beech_Trunk_Full"
    },
    {
      "x": 8,
      "y": 16,
      "z": 8,
      "name": "Plant_Leaves_Bramble"
    },
    {
      "x": 8,
      "y": 15,
      "z": 9,
      "name": "Wood_Beech_Branch_Long",
      "rotation": 4
    },
    {
      "x": 8,
      "y": 16,
      "z": 9,
      "name": "Plant_Leaves_Bramble"
    },
    {
      "x": 8,
      "y": 17,
      "z": 9,
      "name": "Plant_Leaves_Bramble"
    },
    {
      "x": 8,
      "y": 20,
      "z": 9,
      "name": "Plant_Leaves_Bramble"
    },
    {
      "x": 8,
      "y": 16,
      "z": 10,
      "name": "Plant_Leaves_Bramble"
    },
    {
      "x": 9,
      "y": 18,
      "z": 4,
      "name": "Plant_Leaves_Bramble"
    },
    {
      "x": 9,
      "y": 18,
      "z": 5,
      "name": "Plant_Leaves_Bramble"
    },
    {
      "x": 9,
      "y": 6,
      "z": 6,
      "name": "Wood_Beech_Roots"
    },
    {
      "x": 9,
      "y": 7,
      "z": 6,
      "name": "Wood_Beech_Trunk_Full"
    },
    {
      "x": 9,
      "y": 12,
      "z": 6,
      "name": "Wood_Beech_Branch_Short",
      "rotation": 2
    },
    {
      "x": 9,
      "y": 18,
      "z": 6,
      "name": "Plant_Leaves_Bramble"
    },
    {
      "x": 9,
      "y": 8,
      "z": 7,
      "name": "Wood_Beech_Roots"
    },
    {
      "x": 9,
      "y": 9,
      "z": 7,
      "name": "Wood_Beech_Trunk"
    },
    {
      "x": 9,
      "y": 10,
      "z": 7,
      "name": "Wood_Beech_Trunk"
    },
    {
      "x": 9,
      "y": 11,
      "z": 7,
      "name": "Wood_Beech_Trunk"
    },
    {
      "x": 9,
      "y": 12,
      "z": 7,
      "name": "Wood_Beech_Trunk"
    },
    {
      "x": 9,
      "y": 13,
      "z": 7,
      "name": "Wood_Beech_Trunk"
    },
    {
      "x": 9,
      "y": 14,
      "z": 7,
      "name": "Wood_Beech_Trunk_Full"
    },
    {
      "x": 9,
      "y": 6,
      "z": 8,
      "name": "Wood_Beech_Roots"
    },
    {
      "x": 9,
      "y": 7,
      "z": 8,
      "name": "Wood_Beech_Trunk"
    },
    {
      "x": 9,
      "y": 8,
      "z": 8,
      "name": "Wood_Beech_Trunk"
    },
    {
      "x": 9,
      "y": 9,
      "z": 8,
      "name": "Wood_Beech_Trunk"
    },
    {
      "x": 9,
      "y": 10,
      "z": 8,
      "name": "Wood_Beech_Trunk"
    },
    {
      "x": 9,
      "y": 11,
      "z": 8,
      "name": "Wood_Beech_Trunk_Full"
    },
    {
      "x": 9,
      "y": 15,
      "z": 8,
      "name": "Plant_Leaves_Bramble"
    },
    {
      "x": 10,
      "y": 14,
      "z": 5,
      "name": "Wood_Beech_Branch_Corner",
      "rotation": 2
    },
    {
      "x": 10,
      "y": 5,
      "z": 6,
      "name": "Wood_Beech_Roots"
    },
    {
      "x": 10,
      "y": 6,
      "z": 6,
      "name": "Wood_Beech_Trunk"
    },
    {
      "x": 10,
      "y": 7,
      "z": 6,
      "name": "Wood_Beech_Trunk"
    },
    {
      "x": 10,
      "y": 8,
      "z": 6,
      "name": "Wood_Beech_Trunk"
    },
    {
      "x": 10,
      "y": 9,
      "z": 6,
      "name": "Wood_Beech_Trunk"
    },
    {
      "x": 10,
      "y": 10,
      "z": 6,
      "name": "Wood_Beech_Trunk_Full"
    },
    {
      "x": 10,
      "y": 14,
      "z": 6,
      "name": "Wood_Beech_Trunk_Full"
    },
    {
      "x": 10,
      "y": 15,
      "z": 6,
      "name": "Wood_Beech_Trunk"
    },
    {
      "x": 10,
      "y": 16,
      "z": 6,
      "name": "Wood_Beech_Trunk_Full"
    },
    {
      "x": 10,
      "y": 10,
      "z": 7,
      "name": "Wood_Beech_Trunk_Full"
    },
    {
      "x": 10,
      "y": 11,
      "z": 7,
      "name": "Wood_Beech_Trunk_Full"
    },
    {
      "x": 10,
      "y": 14,
      "z": 7,
      "name": "Wood_Beech_Trunk_Full"
    },
    {
      "x": 10,
      "y": 15,
      "z": 7,
      "name": "Plant_Leaves_Bramble"
    },
    {
      "x": 10,
      "y": 14,
      "z": 8,
      "name": "Plant_Leaves_Bramble"
    },
    {
      "x": 11,
      "y": 17,
      "z": 5,
      "name": "Plant_Leaves_Bramble"
    },
    {
      "x": 11,
      "y": 15,
      "z": 6,
      "name": "Plant_Leaves_Bramble"
    },
    {
      "x": 11,
      "y": 16,
      "z": 6,
      "name": "Wood_Beech_Trunk_Full"
    },
    {
      "x": 11,
      "y": 17,
      "z": 6,
      "name": "Wood_Beech_Trunk_Full"
    },
    {
      "x": 11,
      "y": 18,
      "z": 6,
      "name": "Plant_Leaves_Bramble"
    },
    {
      "x": 11,
      "y": 14,
      "z": 7,
      "name": "Wood_Beech_Branch_Long",
      "rotation": 5
    },
    {
      "x": 11,
      "y": 15,
      "z": 7,
      "name": "Plant_Leaves_Bramble"
    },
    {
      "x": 11,
      "y": 18,
      "z": 7,
      "name": "Plant_Leaves_Bramble"
    },
    {
      "x": 11,
      "y": 14,
      "z": 8,
      "name": "Plant_Leaves_Bramble"
    },
    {
      "x": 11,
      "y": 15,
      "z": 8,
      "name": "Plant_Leaves_Bramble"
    },
    {
      "x": 12,
      "y": 17,
      "z": 4,
      "name": "Plant_Leaves_Bramble"
    },
    {
      "x": 12,
      "y": 17,
      "z": 5,
      "name": "Plant_Leaves_Bramble"
    },
    {
      "x": 12,
      "y": 18,
      "z": 5,
      "name": "Plant_Leaves_Bramble"
    },
    {
      "x": 12,
      "y": 17,
      "z": 6,
      "name": "Wood_Beech_Trunk_Full"
    },
    {
      "x": 12,
      "y": 18,
      "z": 6,
      "name": "Plant_Leaves_Bramble"
    },
    {
      "x": 12,
      "y": 19,
      "z": 6,
      "name": "Plant_Leaves_Bramble"
    },
    {
      "x": 12,
      "y": 15,
      "z": 7,
      "name": "Plant_Leaves_Bramble"
    },
    {
      "x": 12,
      "y": 17,
      "z": 7,
      "name": "Wood_Beech_Branch_Corner"
    },
    {
      "x": 12,
      "y": 18,
      "z": 7,
      "name": "Plant_Leaves_Bramble"
    },
    {
      "x": 12,
      "y": 19,
      "z": 7,
      "name": "Plant_Leaves_Bramble"
    },
    {
      "x": 12,
      "y": 15,
      "z": 8,
      "name": "Plant_Leaves_Bramble"
    },
    {
      "x": 13,
      "y": 17,
      "z": 5,
      "name": "Plant_Leaves_Bramble"
    },
    {
      "x": 13,
      "y": 18,
      "z": 5,
      "name": "Plant_Leaves_Bramble"
    },
    {
      "x": 13,
      "y": 17,
      "z": 6,
      "name": "Wood_Beech_Branch_Long",
      "rotation": 5
    },
    {
      "x": 13,
      "y": 18,
      "z": 6,
      "name": "Plant_Leaves_Bramble"
    },
    {
      "x": 13,
      "y": 19,
      "z": 6,
      "name": "Plant_Leaves_Bramble"
    },
    {
      "x": 13,
      "y": 17,
      "z": 7,
      "name": "Plant_Leaves_Bramble"
    },
    {
      "x": 13,
      "y": 18,
      "z": 7,
      "name": "Plant_Leaves_Bramble"
    },
    {
      "x": 13,
      "y": 19,
      "z": 7,
      "name": "Plant_Leaves_Bramble"
    },
    {
      "x": 13,
      "y": 18,
      "z": 8,
      "name": "Plant_Leaves_Bramble"
    },
    {
      "x": 14,
      "y": 18,
      "z": 5,
      "name": "Plant_Leaves_Bramble"
    },
    {
      "x": 14,
      "y": 18,
      "z": 6,
      "name": "Plant_Leaves_Bramble"
    },
    {
      "x": 14,
      "y": 18,
      "z": 7,
      "name": "Plant_Leaves_Bramble"
    },
    {
      "x": 14,
      "y": 18,
      "z": 8,
      "name": "Plant_Leaves_Bramble"
    },
    {
      "x": 15,
      "y": 18,
      "z": 6,
      "name": "Plant_Leaves_Bramble"
    },
    {
      "x": 15,
      "y": 18,
      "z": 7,
      "name": "Plant_Leaves_Bramble"
    }
  ]
}