{
  "version": 8,
  "blockIdVersion": 8,
  "anchorX": 0,
  "anchorY": 0,
  "anchorZ": 0,
  "blocks": [
    {
      "x": -7,
      "y": -1,
      "z": 0,
      "name": "Rock_Stone"
    },
    {
      "x": -7,
      "y": 0,
      "z": 0,
      "name": "Rock_Stone"
    },
    {
      "x": -7,
      "y": 1,
      "z": 0,
      "name": "Rock_Stone"
    },
    {
      "x": -7,
      "y": 2,
      "z": 0,
      "name": "Rock_Stone"
    },
    {
      "x": -7,
      "y": 3,
      "z": 0,
      "name": "Rock_Stone"
    },
    {
      "x": -7,
      "y": 4,
      "z": 0,
      "name": "Rock_Stone"
    },
    {
      "x": -7,
      "y": 5,
      "z": 0,
      "name": "Rock_Stone"
    },
    {
      "x": -7,
      "y": 6,
      "z": 0,
      "name": "Rock_Stone"
    },
    {
      "x": -7,
      "y": 7,
      "z": 0,
      "name": "Rock_Stone"
    },
    {
      "x": -7,
      "y": 8,
      "z": 0,
      "name": "Rock_Stone"
    },
    {
      "x": -7,
      "y": 9,
      "z": 0,
      "name": "Rock_Stone"
    },
    {
      "x": -7,
      "y": 10,
      "z": 0,
      "name": "Rock_Stone"
    },
    {
      "x": -7,
      "y": 11,
      "z": 0,
      "name": "Rock_Stone"
    },
    {
      "x": -7,
      "y": 12,
      "z": 0,
      "name": "Rock_Stone"
    },
    {
      "x": -7,
      "y": -1,
      "z": 1,
      "name": "Rock_Stone"
    },
    {
      "x": -7,
      "y": 0,
      "z": 1,
      "name": "Rock_Stone"
    },
    {
      "x": -7,
      "y": 1,
      "z": 1,
      "name": "Rock_Stone"
    },
    {
      "x": -7,
      "y": 2,
      "z": 1,
      "name": "Rock_Stone"
    },
    {
      "x": -7,
      "y": 3,
      "z": 1,
      "name": "Rock_Stone"
    },
    {
      "x": -7,
      "y": 4,
      "z": 1,
      "name": "Rock_Stone"
    },
    {
      "x": -7,
      "y": 5,
      "z": 1,
      "name": "Rock_Stone"
    },
    {
      "x": -7,
      "y": 6,
      "z": 1,
      "name": "Rock_Stone"
    },
    {
      "x": -7,
      "y": 7,
      "z": 1,
      "name": "Rock_Stone"
    },
    {
      "x": -7,
      "y": 8,
      "z": 1,
      "name": "Rock_Stone"
    },
    {
      "x": -7,
      "y": 9,
      "z": 1,
      "name": "Rock_Stone"
    },
    {
      "x": -7,
      "y": 10,
      "z": 1,
      "name": "Rock_Stone"
    },
    {
      "x": -7,
      "y": 11,
      "z": 1,
      "name": "Rock_Stone"
    },
    {
      "x": -7,
      "y": 12,
      "z": 1,
      "name": "Rock_Stone"
    },
    {
      "x": -7,
      "y": -1,
      "z": 2,
      "name": "Rock_Stone"
    },
    {
      "x": -7,
      "y": 0,
      "z": 2,
      "name": "Rock_Stone"
    },
    {
      "x": -7,
      "y": 1,
      "z": 2,
      "name": "Rock_Stone"
    },
    {
      "x": -7,
      "y": 2,
      "z": 2,
      "name": "Rock_Stone"
    },
    {
      "x": -7,
      "y": 3,
      "z": 2,
      "name": "Rock_Stone"
    },
    {
      "x": -7,
      "y": 4,
      "z": 2,
      "name": "Rock_Stone"
    },
    {
      "x": -7,
      "y": 5,
      "z": 2,
      "name": "Rock_Stone"
    },
    {
      "x": -7,
      "y": 6,
      "z": 2,
      "name": "Rock_Stone"
    },
    {
      "x": -7,
      "y": 7,
      "z": 2,
      "name": "Rock_Stone"
    },
    {
      "x": -7,
      "y": 8,
      "z": 2,
      "name": "Rock_Stone"
    },
    {
      "x": -7,
      "y": 9,
      "z": 2,
      "name": "Rock_Stone"
    },
    {
      "x": -7,
      "y": 10,
      "z": 2,
      "name": "Rock_Stone"
    },
    {
      "x": -7,
      "y": 11,
      "z": 2,
      "name": "Rock_Stone"
    },
    {
      "x": -7,
      "y": 12,
      "z": 2,
      "name": "Rock_Stone"
    },
    {
      "x": -7,
      "y": -1,
      "z": 3,
      "name": "Rock_Stone"
    },
    {
      "x": -7,
      "y": 0,
      "z": 3,
      "name": "Rock_Stone"
    },
    {
      "x": -7,
      "y": 1,
      "z": 3,
      "name": "Rock_Stone"
    },
    {
      "x": -7,
      "y": 2,
      "z": 3,
      "name": "Rock_Stone"
    },
    {
      "x": -7,
      "y": 3,
      "z": 3,
      "name": "Rock_Stone"
    },
    {
      "x": -7,
      "y": 4,
      "z": 3,
      "name": "Rock_Stone"
    },
    {
      "x": -7,
      "y": 5,
      "z": 3,
      "name": "Rock_Stone"
    },
    {
      "x": -7,
      "y": 6,
      "z": 3,
      "name": "Rock_Stone"
    },
    {
      "x": -7,
      "y": 7,
      "z": 3,
      "name": "Rock_Stone"
    },
    {
      "x": -7,
      "y": 8,
      "z": 3,
      "name": "Rock_Stone"
    },
    {
      "x": -7,
      "y": 9,
      "z": 3,
      "name": "Rock_Stone"
    },
    {
      "x": -7,
      "y": 10,
      "z": 3,
      "name": "Rock_Stone"
    },
    {
      "x": -7,
      "y": 11,
      "z": 3,
      "name": "Rock_Stone"
    },
    {
      "x": -7,
      "y": 12,
      "z": 3,
      "name": "Rock_Stone"
    },
    {
      "x": -7,
      "y": -1,
      "z": 4,
      "name": "Rock_Stone"
    },
    {
      "x": -7,
      "y": 0,
      "z": 4,
      "name": "Rock_Stone"
    },
    {
      "x": -7,
      "y": 1,
      "z": 4,
      "name": "Rock_Stone"
    },
    {
      "x": -7,
      "y": 2,
      "z": 4,
      "name": "Rock_Stone"
    },
    {
      "x": -7,
      "y": 3,
      "z": 4,
      "name": "Rock_Stone"
    },
    {
      "x": -7,
      "y": 4,
      "z": 4,
      "name": "Rock_Stone"
    },
    {
      "x": -7,
      "y": 5,
      "z": 4,
      "name": "Rock_Stone"
    },
    {
      "x": -7,
      "y": 6,
      "z": 4,
      "name": "Rock_Stone"
    },
    {
      "x": -7,
      "y": 7,
      "z": 4,
      "name": "Rock_Stone"
    },
    {
      "x": -7,
      "y": 8,
      "z": 4,
      "name": "Rock_Stone"
    },
    {
      "x": -7,
      "y": 9,
      "z": 4,
      "name": "Rock_Stone"
    },
    {
      "x": -7,
      "y": 10,
      "z": 4,
      "name": "Rock_Stone"
    },
    {
      "x": -7,
      "y": 11,
      "z": 4,
      "name": "Rock_Stone"
    },
    {
      "x": -7,
      "y": 12,
      "z": 4,
      "name": "Rock_Stone"
    },
    {
      "x": -7,
      "y": -1,
      "z": 5,
      "name": "Rock_Stone"
    },
    {
      "x": -7,
      "y": 0,
      "z": 5,
      "name": "Rock_Stone"
    },
    {
      "x": -7,
      "y": 1,
      "z": 5,
      "name": "Rock_Stone"
    },
    {
      "x": -7,
      "y": 2,
      "z": 5,
      "name": "Rock_Stone"
    },
    {
      "x": -7,
      "y": 3,
      "z": 5,
      "name": "Rock_Stone"
    },
    {
      "x": -7,
      "y": 4,
      "z": 5,
      "name": "Rock_Stone"
    },
    {
      "x": -7,
      "y": 5,
      "z": 5,
      "name": "Rock_Stone"
    },
    {
      "x": -7,
      "y": 6,
      "z": 5,
      "name": "Rock_Stone"
    },
    {
      "x": -7,
      "y": 7,
      "z": 5,
      "name": "Rock_Stone"
    },
    {
      "x": -7,
      "y": 8,
      "z": 5,
      "name": "Rock_Stone"
    },
    {
      "x": -7,
      "y": 9,
      "z": 5,
      "name": "Rock_Stone"
    },
    {
      "x": -7,
      "y": 10,
      "z": 5,
      "name": "Rock_Stone"
    },
    {
      "x": -7,
      "y": 11,
      "z": 5,
      "name": "Rock_Stone"
    },
    {
      "x": -7,
      "y": 12,
      "z": 5,
      "name": "Rock_Stone"
    },
    {
      "x": -7,
      "y": -1,
      "z": 6,
      "name": "Rock_Stone"
    },
    {
      "x": -7,
      "y": 0,
      "z": 6,
      "name": "Rock_Stone"
    },
    {
      "x": -7,
      "y": 1,
      "z": 6,
      "name": "Rock_Stone"
    },
    {
      "x": -7,
      "y": 2,
      "z": 6,
      "name": "Rock_Stone"
    },
    {
      "x": -7,
      "y": 3,
      "z": 6,
      "name": "Rock_Stone"
    },
    {
      "x": -7,
      "y": 4,
      "z": 6,
      "name": "Rock_Stone"
    },
    {
      "x": -7,
      "y": 5,
      "z": 6,
      "name": "Rock_Stone"
    },
    {
      "x": -7,
      "y": 6,
      "z": 6,
      "name": "Rock_Stone"
    },
    {
      "x": -7,
      "y": 7,
      "z": 6,
      "name": "Rock_Stone"
    },
    {
      "x": -7,
      "y": 8,
      "z": 6,
      "name": "Rock_Stone"
    },
    {
      "x": -7,
      "y": 9,
      "z": 6,
      "name": "Rock_Stone"
    },
    {
      "x": -7,
      "y": 10,
      "z": 6,
      "name": "Rock_Stone"
    },
    {
      "x": -7,
      "y": 11,
      "z": 6,
      "name": "Rock_Stone"
    },
    {
      "x": -7,
      "y": 12,
      "z": 6,
      "name": "Rock_Stone"
    },
    {
      "x": -7,
      "y": -1,
      "z": 7,
      "name": "Rock_Stone"
    },
    {
      "x": -7,
      "y": 0,
      "z": 7,
      "name": "Rock_Stone"
    },
    {
      "x": -7,
      "y": 1,
      "z": 7,
      "name": "Rock_Stone"
    },
    {
      "x": -7,
      "y": 2,
      "z": 7,
      "name": "Rock_Stone"
    },
    {
      "x": -7,
      "y": 3,
      "z": 7,
      "name": "Rock_Stone"
    },
    {
      "x": -7,
      "y": 4,
      "z": 7,
      "name": "Rock_Stone"
    },
    {
      "x": -7,
      "y": 5,
      "z": 7,
      "name": "Rock_Stone"
    },
    {
      "x": -7,
      "y": 6,
      "z": 7,
      "name": "Rock_Stone"
    },
    {
      "x": -7,
      "y": 7,
      "z": 7,
      "name": "Rock_Stone"
    },
    {
      "x": -7,
      "y": 8,
      "z": 7,
      "name": "Rock_Stone"
    },
    {
      "x": -7,
      "y": 9,
      "z": 7,
      "name": "Rock_Stone"
    },
    {
      "x": -7,
      "y": 10,
      "z": 7,
      "name": "Rock_Stone"
    },
    {
      "x": -7,
      "y": 11,
      "z": 7,
      "name": "Rock_Stone"
    },
    {
      "x": -7,
      "y": 12,
      "z": 7,
      "name": "Rock_Stone"
    },
    {
      "x": -7,
      "y": -1,
      "z": 8,
      "name": "Rock_Stone"
    },
    {
      "x": -7,
      "y": 0,
      "z": 8,
      "name": "Rock_Stone"
    },
    {
      "x": -7,
      "y": 1,
      "z": 8,
      "name": "Rock_Stone"
    },
    {
      "x": -7,
      "y": 2,
      "z": 8,
      "name": "Rock_Stone"
    },
    {
      "x": -7,
      "y": 3,
      "z": 8,
      "name": "Rock_Stone"
    },
    {
      "x": -7,
      "y": 4,
      "z": 8,
      "name": "Rock_Stone"
    },
    {
      "x": -7,
      "y": 5,
      "z": 8,
      "name": "Rock_Stone"
    },
    {
      "x": -7,
      "y": 6,
      "z": 8,
      "name": "Rock_Stone"
    },
    {
      "x": -7,
      "y": 7,
      "z": 8,
      "name": "Rock_Stone"
    },
    {
      "x": -7,
      "y": 8,
      "z": 8,
      "name": "Rock_Stone"
    },
    {
      "x": -7,
      "y": 9,
      "z": 8,
      "name": "Rock_Stone"
    },
    {
      "x": -7,
      "y": 10,
      "z": 8,
      "name": "Rock_Stone"
    },
    {
      "x": -7,
      "y": 11,
      "z": 8,
      "name": "Rock_Stone"
    },
    {
      "x": -7,
      "y": 12,
      "z": 8,
      "name": "Rock_Stone"
    },
    {
      "x": -7,
      "y": -1,
      "z": 9,
      "name": "Rock_Stone"
    },
    {
      "x": -7,
      "y": 0,
      "z": 9,
      "name": "Rock_Stone"
    },
    {
      "x": -7,
      "y": 1,
      "z": 9,
      "name": "Rock_Stone"
    },
    {
      "x": -7,
      "y": 2,
      "z": 9,
      "name": "Rock_Stone"
    },
    {
      "x": -7,
      "y": 3,
      "z": 9,
      "name": "Rock_Stone"
    },
    {
      "x": -7,
      "y": 4,
      "z": 9,
      "name": "Rock_Stone"
    },
    {
      "x": -7,
      "y": 5,
      "z": 9,
      "name": "Rock_Stone"
    },
    {
      "x": -7,
      "y": 6,
      "z": 9,
      "name": "Rock_Stone"
    },
    {
      "x": -7,
      "y": 7,
      "z": 9,
      "name": "Rock_Stone"
    },
    {
      "x": -7,
      "y": 8,
      "z": 9,
      "name": "Rock_Stone"
    },
    {
      "x": -7,
      "y": 9,
      "z": 9,
      "name": "Rock_Stone"
    },
    {
      "x": -7,
      "y": 10,
      "z": 9,
      "name": "Rock_Stone"
    },
    {
      "x": -7,
      "y": 11,
      "z": 9,
      "name": "Rock_Stone"
    },
    {
      "x": -7,
      "y": 12,
      "z": 9,
      "name": "Rock_Stone"
    },
    {
      "x": -7,
      "y": -1,
      "z": 10,
      "name": "Rock_Stone"
    },
    {
      "x": -7,
      "y": 0,
      "z": 10,
      "name": "Rock_Stone"
    },
    {
      "x": -7,
      "y": 1,
      "z": 10,
      "name": "Rock_Stone"
    },
    {
      "x": -7,
      "y": 2,
      "z": 10,
      "name": "Rock_Stone"
    },
    {
      "x": -7,
      "y": 3,
      "z": 10,
      "name": "Rock_Stone"
    },
    {
      "x": -7,
      "y": 4,
      "z": 10,
      "name": "Rock_Stone"
    },
    {
      "x": -7,
      "y": 5,
      "z": 10,
      "name": "Rock_Stone"
    },
    {
      "x": -7,
      "y": 6,
      "z": 10,
      "name": "Rock_Stone"
    },
    {
      "x": -7,
      "y": 7,
      "z": 10,
      "name": "Rock_Stone"
    },
    {
      "x": -7,
      "y": 8,
      "z": 10,
      "name": "Rock_Stone"
    },
    {
      "x": -7,
      "y": 9,
      "z": 10,
      "name": "Rock_Stone"
    },
    {
      "x": -7,
      "y": 10,
      "z": 10,
      "name": "Rock_Stone"
    },
    {
      "x": -7,
      "y": 11,
      "z": 10,
      "name": "Rock_Stone"
    },
    {
      "x": -7,
      "y": 12,
      "z": 10,
      "name": "Rock_Stone"
    },
    {
      "x": -7,
      "y": -1,
      "z": 11,
      "name": "Rock_Stone"
    },
    {
      "x": -7,
      "y": 0,
      "z": 11,
      "name": "Rock_Stone"
    },
    {
      "x": -7,
      "y": 1,
      "z": 11,
      "name": "Rock_Stone"
    },
    {
      "x": -7,
      "y": 2,
      "z": 11,
      "name": "Rock_Stone"
    },
    {
      "x": -7,
      "y": 3,
      "z": 11,
      "name": "Rock_Stone"
    },
    {
      "x": -7,
      "y": 4,
      "z": 11,
      "name": "Rock_Stone"
    },
    {
      "x": -7,
      "y": 5,
      "z": 11,
      "name": "Rock_Stone"
    },
    {
      "x": -7,
      "y": 6,
      "z": 11,
      "name": "Rock_Stone"
    },
    {
      "x": -7,
      "y": 7,
      "z": 11,
      "name": "Rock_Stone"
    },
    {
      "x": -7,
      "y": 8,
      "z": 11,
      "name": "Rock_Stone"
    },
    {
      "x": -7,
      "y": 9,
      "z": 11,
      "name": "Rock_Stone"
    },
    {
      "x": -7,
      "y": 10,
      "z": 11,
      "name": "Rock_Stone"
    },
    {
      "x": -7,
      "y": 11,
      "z": 11,
      "name": "Rock_Stone"
    },
    {
      "x": -7,
      "y": 12,
      "z": 11,
      "name": "Rock_Stone"
    },
    {
      "x": -7,
      "y": -1,
      "z": 12,
      "name": "Rock_Stone"
    },
    {
      "x": -7,
      "y": 0,
      "z": 12,
      "name": "Rock_Stone"
    },
    {
      "x": -7,
      "y": 1,
      "z": 12,
      "name": "Rock_Stone"
    },
    {
      "x": -7,
      "y": 2,
      "z": 12,
      "name": "Rock_Stone"
    },
    {
      "x": -7,
      "y": 3,
      "z": 12,
      "name": "Rock_Stone"
    },
    {
      "x": -7,
      "y": 4,
      "z": 12,
      "name": "Rock_Stone"
    },
    {
      "x": -7,
      "y": 5,
      "z": 12,
      "name": "Rock_Stone"
    },
    {
      "x": -7,
      "y": 6,
      "z": 12,
      "name": "Rock_Stone"
    },
    {
      "x": -7,
      "y": 7,
      "z": 12,
      "name": "Rock_Stone"
    },
    {
      "x": -7,
      "y": 8,
      "z": 12,
      "name": "Rock_Stone"
    },
    {
      "x": -7,
      "y": 9,
      "z": 12,
      "name": "Rock_Stone"
    },
    {
      "x": -7,
      "y": 10,
      "z": 12,
      "name": "Rock_Stone"
    },
    {
      "x": -7,
      "y": 11,
      "z": 12,
      "name": "Rock_Stone"
    },
    {
      "x": -7,
      "y": 12,
      "z": 12,
      "name": "Rock_Stone"
    },
    {
      "x": -7,
      "y": -1,
      "z": 13,
      "name": "Rock_Stone"
    },
    {
      "x": -7,
      "y": 0,
      "z": 13,
      "name": "Rock_Stone"
    },
    {
      "x": -7,
      "y": 1,
      "z": 13,
      "name": "Rock_Stone"
    },
    {
      "x": -7,
      "y": 2,
      "z": 13,
      "name": "Rock_Stone"
    },
    {
      "x": -7,
      "y": 3,
      "z": 13,
      "name": "Rock_Stone"
    },
    {
      "x": -7,
      "y": 4,
      "z": 13,
      "name": "Rock_Stone"
    },
    {
      "x": -7,
      "y": 5,
      "z": 13,
      "name": "Rock_Stone"
    },
    {
      "x": -7,
      "y": 6,
      "z": 13,
      "name": "Rock_Stone"
    },
    {
      "x": -7,
      "y": 7,
      "z": 13,
      "name": "Rock_Stone"
    },
    {
      "x": -7,
      "y": 8,
      "z": 13,
      "name": "Rock_Stone"
    },
    {
      "x": -7,
      "y": 9,
      "z": 13,
      "name": "Rock_Stone"
    },
    {
      "x": -7,
      "y": 10,
      "z": 13,
      "name": "Rock_Stone"
    },
    {
      "x": -7,
      "y": 11,
      "z": 13,
      "name": "Rock_Stone"
    },
    {
      "x": -7,
      "y": 12,
      "z": 13,
      "name": "Rock_Stone"
    },
    {
      "x": -7,
      "y": -1,
      "z": 14,
      "name": "Rock_Stone"
    },
    {
      "x": -7,
      "y": 0,
      "z": 14,
      "name": "Rock_Stone"
    },
    {
      "x": -7,
      "y": 1,
      "z": 14,
      "name": "Rock_Stone"
    },
    {
      "x": -7,
      "y": 2,
      "z": 14,
      "name": "Rock_Stone"
    },
    {
      "x": -7,
      "y": 3,
      "z": 14,
      "name": "Rock_Stone"
    },
    {
      "x": -7,
      "y": 4,
      "z": 14,
      "name": "Rock_Stone"
    },
    {
      "x": -7,
      "y": 5,
      "z": 14,
      "name": "Rock_Stone"
    },
    {
      "x": -7,
      "y": 6,
      "z": 14,
      "name": "Rock_Stone"
    },
    {
      "x": -7,
      "y": 7,
      "z": 14,
      "name": "Rock_Stone"
    },
    {
      "x": -7,
      "y": 8,
      "z": 14,
      "name": "Rock_Stone"
    },
    {
      "x": -7,
      "y": 9,
      "z": 14,
      "name": "Rock_Stone"
    },
    {
      "x": -7,
      "y": 10,
      "z": 14,
      "name": "Rock_Stone"
    },
    {
      "x": -7,
      "y": 11,
      "z": 14,
      "name": "Rock_Stone"
    },
    {
      "x": -7,
      "y": 12,
      "z": 14,
      "name": "Rock_Stone"
    },
    {
      "x": -6,
      "y": -1,
      "z": 0,
      "name": "Rock_Stone"
    },
    {
      "x": -6,
      "y": 0,
      "z": 0,
      "name": "Rock_Stone"
    },
    {
      "x": -6,
      "y": 1,
      "z": 0,
      "name": "Rock_Stone"
    },
    {
      "x": -6,
      "y": 2,
      "z": 0,
      "name": "Rock_Stone"
    },
    {
      "x": -6,
      "y": 3,
      "z": 0,
      "name": "Rock_Stone"
    },
    {
      "x": -6,
      "y": 4,
      "z": 0,
      "name": "Rock_Stone"
    },
    {
      "x": -6,
      "y": 5,
      "z": 0,
      "name": "Rock_Stone"
    },
    {
      "x": -6,
      "y": 6,
      "z": 0,
      "name": "Rock_Stone"
    },
    {
      "x": -6,
      "y": 7,
      "z": 0,
      "name": "Rock_Stone"
    },
    {
      "x": -6,
      "y": 8,
      "z": 0,
      "name": "Rock_Stone"
    },
    {
      "x": -6,
      "y": 9,
      "z": 0,
      "name": "Rock_Stone"
    },
    {
      "x": -6,
      "y": 10,
      "z": 0,
      "name": "Rock_Stone"
    },
    {
      "x": -6,
      "y": 11,
      "z": 0,
      "name": "Rock_Stone"
    },
    {
      "x": -6,
      "y": 12,
      "z": 0,
      "name": "Rock_Stone"
    },
    {
      "x": -6,
      "y": -1,
      "z": 1,
      "name": "Rock_Stone"
    },
    {
      "x": -6,
      "y": 0,
      "z": 1,
      "name": "Rock_Stone"
    },
    {
      "x": -6,
      "y": 1,
      "z": 1,
      "name": "Rock_Stone"
    },
    {
      "x": -6,
      "y": 2,
      "z": 1,
      "name": "Rock_Stone"
    },
    {
      "x": -6,
      "y": 3,
      "z": 1,
      "name": "Rock_Stone"
    },
    {
      "x": -6,
      "y": 4,
      "z": 1,
      "name": "Rock_Stone"
    },
    {
      "x": -6,
      "y": 5,
      "z": 1,
      "name": "Rock_Stone"
    },
    {
      "x": -6,
      "y": 6,
      "z": 1,
      "name": "Rock_Stone"
    },
    {
      "x": -6,
      "y": 7,
      "z": 1,
      "name": "Rock_Stone"
    },
    {
      "x": -6,
      "y": 8,
      "z": 1,
      "name": "Rock_Stone"
    },
    {
      "x": -6,
      "y": 9,
      "z": 1,
      "name": "Rock_Stone"
    },
    {
      "x": -6,
      "y": 10,
      "z": 1,
      "name": "Rock_Stone"
    },
    {
      "x": -6,
      "y": 11,
      "z": 1,
      "name": "Rock_Stone"
    },
    {
      "x": -6,
      "y": 12,
      "z": 1,
      "name": "Rock_Stone"
    },
    {
      "x": -6,
      "y": -1,
      "z": 2,
      "name": "Rock_Stone"
    },
    {
      "x": -6,
      "y": 0,
      "z": 2,
      "name": "Rock_Stone"
    },
    {
      "x": -6,
      "y": 1,
      "z": 2,
      "name": "Rock_Stone"
    },
    {
      "x": -6,
      "y": 2,
      "z": 2,
      "name": "Rock_Stone"
    },
    {
      "x": -6,
      "y": 3,
      "z": 2,
      "name": "Rock_Stone"
    },
    {
      "x": -6,
      "y": 4,
      "z": 2,
      "name": "Rock_Stone"
    },
    {
      "x": -6,
      "y": 5,
      "z": 2,
      "name": "Rock_Stone"
    },
    {
      "x": -6,
      "y": 6,
      "z": 2,
      "name": "Rock_Stone"
    },
    {
      "x": -6,
      "y": 7,
      "z": 2,
      "name": "Rock_Stone"
    },
    {
      "x": -6,
      "y": 8,
      "z": 2,
      "name": "Rock_Stone"
    },
    {
      "x": -6,
      "y": 9,
      "z": 2,
      "name": "Rock_Stone"
    },
    {
      "x": -6,
      "y": 10,
      "z": 2,
      "name": "Rock_Stone"
    },
    {
      "x": -6,
      "y": 11,
      "z": 2,
      "name": "Rock_Stone"
    },
    {
      "x": -6,
      "y": 12,
      "z": 2,
      "name": "Rock_Stone"
    },
    {
      "x": -6,
      "y": -1,
      "z": 3,
      "name": "Rock_Stone"
    },
    {
      "x": -6,
      "y": 0,
      "z": 3,
      "name": "Rock_Stone"
    },
    {
      "x": -6,
      "y": 1,
      "z": 3,
      "name": "Rock_Stone"
    },
    {
      "x": -6,
      "y": 2,
      "z": 3,
      "name": "Rock_Stone"
    },
    {
      "x": -6,
      "y": 3,
      "z": 3,
      "name": "Rock_Stone"
    },
    {
      "x": -6,
      "y": 4,
      "z": 3,
      "name": "Rock_Stone"
    },
    {
      "x": -6,
      "y": 5,
      "z": 3,
      "name": "Rock_Stone"
    },
    {
      "x": -6,
      "y": 6,
      "z": 3,
      "name": "Rock_Stone"
    },
    {
      "x": -6,
      "y": 7,
      "z": 3,
      "name": "Rock_Stone"
    },
    {
      "x": -6,
      "y": 8,
      "z": 3,
      "name": "Rock_Stone"
    },
    {
      "x": -6,
      "y": 9,
      "z": 3,
      "name": "Rock_Stone"
    },
    {
      "x": -6,
      "y": 10,
      "z": 3,
      "name": "Rock_Stone"
    },
    {
      "x": -6,
      "y": 11,
      "z": 3,
      "name": "Rock_Stone"
    },
    {
      "x": -6,
      "y": 12,
      "z": 3,
      "name": "Rock_Stone"
    },
    {
      "x": -6,
      "y": -1,
      "z": 4,
      "name": "Rock_Stone"
    },
    {
      "x": -6,
      "y": 0,
      "z": 4,
      "name": "Rock_Stone"
    },
    {
      "x": -6,
      "y": 1,
      "z": 4,
      "name": "Rock_Stone"
    },
    {
      "x": -6,
      "y": 2,
      "z": 4,
      "name": "Rock_Stone"
    },
    {
      "x": -6,
      "y": 3,
      "z": 4,
      "name": "Rock_Stone"
    },
    {
      "x": -6,
      "y": 4,
      "z": 4,
      "name": "Rock_Stone"
    },
    {
      "x": -6,
      "y": 5,
      "z": 4,
      "name": "Rock_Stone"
    },
    {
      "x": -6,
      "y": 6,
      "z": 4,
      "name": "Rock_Stone"
    },
    {
      "x": -6,
      "y": 7,
      "z": 4,
      "name": "Rock_Stone"
    },
    {
      "x": -6,
      "y": 8,
      "z": 4,
      "name": "Rock_Stone"
    },
    {
      "x": -6,
      "y": 9,
      "z": 4,
      "name": "Rock_Stone"
    },
    {
      "x": -6,
      "y": 10,
      "z": 4,
      "name": "Rock_Stone"
    },
    {
      "x": -6,
      "y": 11,
      "z": 4,
      "name": "Rock_Stone"
    },
    {
      "x": -6,
      "y": 12,
      "z": 4,
      "name": "Rock_Stone"
    },
    {
      "x": -6,
      "y": -1,
      "z": 5,
      "name": "Rock_Stone"
    },
    {
      "x": -6,
      "y": 0,
      "z": 5,
      "name": "Rock_Stone"
    },
    {
      "x": -6,
      "y": 1,
      "z": 5,
      "name": "Rock_Stone"
    },
    {
      "x": -6,
      "y": 2,
      "z": 5,
      "name": "Rock_Stone"
    },
    {
      "x": -6,
      "y": 3,
      "z": 5,
      "name": "Rock_Stone"
    },
    {
      "x": -6,
      "y": 4,
      "z": 5,
      "name": "Rock_Stone"
    },
    {
      "x": -6,
      "y": 5,
      "z": 5,
      "name": "Rock_Stone"
    },
    {
      "x": -6,
      "y": 6,
      "z": 5,
      "name": "Rock_Stone"
    },
    {
      "x": -6,
      "y": 7,
      "z": 5,
      "name": "Rock_Stone"
    },
    {
      "x": -6,
      "y": 8,
      "z": 5,
      "name": "Rock_Stone"
    },
    {
      "x": -6,
      "y": 9,
      "z": 5,
      "name": "Rock_Stone"
    },
    {
      "x": -6,
      "y": 10,
      "z": 5,
      "name": "Rock_Stone"
    },
    {
      "x": -6,
      "y": 11,
      "z": 5,
      "name": "Rock_Stone"
    },
    {
      "x": -6,
      "y": 12,
      "z": 5,
      "name": "Rock_Stone"
    },
    {
      "x": -6,
      "y": -1,
      "z": 6,
      "name": "Rock_Stone"
    },
    {
      "x": -6,
      "y": 0,
      "z": 6,
      "name": "Rock_Stone"
    },
    {
      "x": -6,
      "y": 1,
      "z": 6,
      "name": "Rock_Stone"
    },
    {
      "x": -6,
      "y": 2,
      "z": 6,
      "name": "Rock_Stone"
    },
    {
      "x": -6,
      "y": 3,
      "z": 6,
      "name": "Rock_Stone"
    },
    {
      "x": -6,
      "y": 4,
      "z": 6,
      "name": "Rock_Stone"
    },
    {
      "x": -6,
      "y": 5,
      "z": 6,
      "name": "Rock_Stone"
    },
    {
      "x": -6,
      "y": 6,
      "z": 6,
      "name": "Rock_Stone"
    },
    {
      "x": -6,
      "y": 7,
      "z": 6,
      "name": "Rock_Stone"
    },
    {
      "x": -6,
      "y": 8,
      "z": 6,
      "name": "Rock_Stone"
    },
    {
      "x": -6,
      "y": 9,
      "z": 6,
      "name": "Rock_Stone"
    },
    {
      "x": -6,
      "y": 10,
      "z": 6,
      "name": "Rock_Stone"
    },
    {
      "x": -6,
      "y": 11,
      "z": 6,
      "name": "Rock_Stone"
    },
    {
      "x": -6,
      "y": 12,
      "z": 6,
      "name": "Rock_Stone"
    },
    {
      "x": -6,
      "y": -1,
      "z": 7,
      "name": "Rock_Stone"
    },
    {
      "x": -6,
      "y": 0,
      "z": 7,
      "name": "Rock_Stone"
    },
    {
      "x": -6,
      "y": 1,
      "z": 7,
      "name": "Rock_Stone"
    },
    {
      "x": -6,
      "y": 2,
      "z": 7,
      "name": "Rock_Stone"
    },
    {
      "x": -6,
      "y": 3,
      "z": 7,
      "name": "Rock_Stone"
    },
    {
      "x": -6,
      "y": 4,
      "z": 7,
      "name": "Rock_Stone_Cobble"
    },
    {
      "x": -6,
      "y": 5,
      "z": 7,
      "name": "Rock_Stone_Cobble"
    },
    {
      "x": -6,
      "y": 6,
      "z": 7,
      "name": "Empty"
    },
    {
      "x": -6,
      "y": 7,
      "z": 7,
      "name": "Empty"
    },
    {
      "x": -6,
      "y": 8,
      "z": 7,
      "name": "Rock_Stone"
    },
    {
      "x": -6,
      "y": 9,
      "z": 7,
      "name": "Rock_Stone"
    },
    {
      "x": -6,
      "y": 10,
      "z": 7,
      "name": "Rock_Stone"
    },
    {
      "x": -6,
      "y": 11,
      "z": 7,
      "name": "Rock_Stone"
    },
    {
      "x": -6,
      "y": 12,
      "z": 7,
      "name": "Rock_Stone"
    },
    {
      "x": -6,
      "y": -1,
      "z": 8,
      "name": "Rock_Stone"
    },
    {
      "x": -6,
      "y": 0,
      "z": 8,
      "name": "Rock_Stone"
    },
    {
      "x": -6,
      "y": 1,
      "z": 8,
      "name": "Rock_Stone"
    },
    {
      "x": -6,
      "y": 2,
      "z": 8,
      "name": "Rock_Stone"
    },
    {
      "x": -6,
      "y": 3,
      "z": 8,
      "name": "Rock_Stone"
    },
    {
      "x": -6,
      "y": 4,
      "z": 8,
      "name": "Rock_Stone_Cobble"
    },
    {
      "x": -6,
      "y": 5,
      "z": 8,
      "name": "Rock_Stone_Cobble"
    },
    {
      "x": -6,
      "y": 6,
      "z": 8,
      "name": "Empty"
    },
    {
      "x": -6,
      "y": 7,
      "z": 8,
      "name": "Empty"
    },
    {
      "x": -6,
      "y": 8,
      "z": 8,
      "name": "Empty"
    },
    {
      "x": -6,
      "y": 9,
      "z": 8,
      "name": "Rock_Stone"
    },
    {
      "x": -6,
      "y": 10,
      "z": 8,
      "name": "Rock_Stone"
    },
    {
      "x": -6,
      "y": 11,
      "z": 8,
      "name": "Rock_Stone"
    },
    {
      "x": -6,
      "y": 12,
      "z": 8,
      "name": "Rock_Stone"
    },
    {
      "x": -6,
      "y": -1,
      "z": 9,
      "name": "Rock_Stone"
    },
    {
      "x": -6,
      "y": 0,
      "z": 9,
      "name": "Rock_Stone"
    },
    {
      "x": -6,
      "y": 1,
      "z": 9,
      "name": "Rock_Stone"
    },
    {
      "x": -6,
      "y": 2,
      "z": 9,
      "name": "Rock_Stone"
    },
    {
      "x": -6,
      "y": 3,
      "z": 9,
      "name": "Rock_Stone"
    },
    {
      "x": -6,
      "y": 4,
      "z": 9,
      "name": "Rock_Stone"
    },
    {
      "x": -6,
      "y": 5,
      "z": 9,
      "name": "Empty"
    },
    {
      "x": -6,
      "y": 6,
      "z": 9,
      "name": "Empty"
    },
    {
      "x": -6,
      "y": 7,
      "z": 9,
      "name": "Empty"
    },
    {
      "x": -6,
      "y": 8,
      "z": 9,
      "name": "Empty"
    },
    {
      "x": -6,
      "y": 9,
      "z": 9,
      "name": "Empty"
    },
    {
      "x": -6,
      "y": 10,
      "z": 9,
      "name": "Rock_Stone"
    },
    {
      "x": -6,
      "y": 11,
      "z": 9,
      "name": "Rock_Stone"
    },
    {
      "x": -6,
      "y": 12,
      "z": 9,
      "name": "Rock_Stone"
    },
    {
      "x": -6,
      "y": -1,
      "z": 10,
      "name": "Rock_Stone"
    },
    {
      "x": -6,
      "y": 0,
      "z": 10,
      "name": "Rock_Stone"
    },
    {
      "x": -6,
      "y": 1,
      "z": 10,
      "name": "Rock_Stone"
    },
    {
      "x": -6,
      "y": 2,
      "z": 10,
      "name": "Rock_Stone"
    },
    {
      "x": -6,
      "y": 3,
      "z": 10,
      "name": "Rock_Stone"
    },
    {
      "x": -6,
      "y": 4,
      "z": 10,
      "name": "Rock_Stone"
    },
    {
      "x": -6,
      "y": 5,
      "z": 10,
      "name": "Empty"
    },
    {
      "x": -6,
      "y": 6,
      "z": 10,
      "name": "Empty"
    },
    {
      "x": -6,
      "y": 7,
      "z": 10,
      "name": "Rock_Stone"
    },
    {
      "x": -6,
      "y": 8,
      "z": 10,
      "name": "Rock_Stone"
    },
    {
      "x": -6,
      "y": 9,
      "z": 10,
      "name": "Rock_Stone"
    },
    {
      "x": -6,
      "y": 10,
      "z": 10,
      "name": "Rock_Stone"
    },
    {
      "x": -6,
      "y": 11,
      "z": 10,
      "name": "Rock_Stone"
    },
    {
      "x": -6,
      "y": 12,
      "z": 10,
      "name": "Rock_Stone"
    },
    {
      "x": -6,
      "y": -1,
      "z": 11,
      "name": "Rock_Stone"
    },
    {
      "x": -6,
      "y": 0,
      "z": 11,
      "name": "Rock_Stone"
    },
    {
      "x": -6,
      "y": 1,
      "z": 11,
      "name": "Rock_Stone"
    },
    {
      "x": -6,
      "y": 2,
      "z": 11,
      "name": "Rock_Stone"
    },
    {
      "x": -6,
      "y": 3,
      "z": 11,
      "name": "Rock_Stone"
    },
    {
      "x": -6,
      "y": 4,
      "z": 11,
      "name": "Rock_Stone"
    },
    {
      "x": -6,
      "y": 5,
      "z": 11,
      "name": "Rock_Stone"
    },
    {
      "x": -6,
      "y": 6,
      "z": 11,
      "name": "Rock_Stone"
    },
    {
      "x": -6,
      "y": 7,
      "z": 11,
      "name": "Rock_Stone"
    },
    {
      "x": -6,
      "y": 8,
      "z": 11,
      "name": "Rock_Stone"
    },
    {
      "x": -6,
      "y": 9,
      "z": 11,
      "name": "Rock_Stone"
    },
    {
      "x": -6,
      "y": 10,
      "z": 11,
      "name": "Rock_Stone"
    },
    {
      "x": -6,
      "y": 11,
      "z": 11,
      "name": "Rock_Stone"
    },
    {
      "x": -6,
      "y": 12,
      "z": 11,
      "name": "Rock_Stone"
    },
    {
      "x": -6,
      "y": -1,
      "z": 12,
      "name": "Rock_Stone"
    },
    {
      "x": -6,
      "y": 0,
      "z": 12,
      "name": "Rock_Stone"
    },
    {
      "x": -6,
      "y": 1,
      "z": 12,
      "name": "Rock_Stone"
    },
    {
      "x": -6,
      "y": 2,
      "z": 12,
      "name": "Rock_Stone"
    },
    {
      "x": -6,
      "y": 3,
      "z": 12,
      "name": "Empty"
    },
    {
      "x": -6,
      "y": 4,
      "z": 12,
      "name": "Rock_Stone"
    },
    {
      "x": -6,
      "y": 5,
      "z": 12,
      "name": "Rock_Stone"
    },
    {
      "x": -6,
      "y": 6,
      "z": 12,
      "name": "Rock_Stone"
    },
    {
      "x": -6,
      "y": 7,
      "z": 12,
      "name": "Rock_Stone"
    },
    {
      "x": -6,
      "y": 8,
      "z": 12,
      "name": "Rock_Stone"
    },
    {
      "x": -6,
      "y": 9,
      "z": 12,
      "name": "Rock_Stone"
    },
    {
      "x": -6,
      "y": 10,
      "z": 12,
      "name": "Rock_Stone"
    },
    {
      "x": -6,
      "y": 11,
      "z": 12,
      "name": "Rock_Stone"
    },
    {
      "x": -6,
      "y": 12,
      "z": 12,
      "name": "Rock_Stone"
    },
    {
      "x": -6,
      "y": -1,
      "z": 13,
      "name": "Rock_Stone"
    },
    {
      "x": -6,
      "y": 0,
      "z": 13,
      "name": "Rock_Stone"
    },
    {
      "x": -6,
      "y": 1,
      "z": 13,
      "name": "Rock_Stone"
    },
    {
      "x": -6,
      "y": 2,
      "z": 13,
      "name": "Empty"
    },
    {
      "x": -6,
      "y": 3,
      "z": 13,
      "name": "Empty"
    },
    {
      "x": -6,
      "y": 4,
      "z": 13,
      "name": "Empty"
    },
    {
      "x": -6,
      "y": 5,
      "z": 13,
      "name": "Rock_Stone"
    },
    {
      "x": -6,
      "y": 6,
      "z": 13,
      "name": "Rock_Stone"
    },
    {
      "x": -6,
      "y": 7,
      "z": 13,
      "name": "Rock_Stone"
    },
    {
      "x": -6,
      "y": 8,
      "z": 13,
      "name": "Rock_Stone"
    },
    {
      "x": -6,
      "y": 9,
      "z": 13,
      "name": "Rock_Stone"
    },
    {
      "x": -6,
      "y": 10,
      "z": 13,
      "name": "Rock_Stone"
    },
    {
      "x": -6,
      "y": 11,
      "z": 13,
      "name": "Rock_Stone"
    },
    {
      "x": -6,
      "y": 12,
      "z": 13,
      "name": "Rock_Stone"
    },
    {
      "x": -6,
      "y": -1,
      "z": 14,
      "name": "Rock_Stone"
    },
    {
      "x": -6,
      "y": 0,
      "z": 14,
      "name": "Rock_Stone"
    },
    {
      "x": -6,
      "y": 1,
      "z": 14,
      "name": "Rock_Stone"
    },
    {
      "x": -6,
      "y": 2,
      "z": 14,
      "name": "Rock_Stone"
    },
    {
      "x": -6,
      "y": 3,
      "z": 14,
      "name": "Rock_Stone"
    },
    {
      "x": -6,
      "y": 4,
      "z": 14,
      "name": "Rock_Stone"
    },
    {
      "x": -6,
      "y": 5,
      "z": 14,
      "name": "Rock_Stone"
    },
    {
      "x": -6,
      "y": 6,
      "z": 14,
      "name": "Rock_Stone"
    },
    {
      "x": -6,
      "y": 7,
      "z": 14,
      "name": "Rock_Stone"
    },
    {
      "x": -6,
      "y": 8,
      "z": 14,
      "name": "Rock_Stone"
    },
    {
      "x": -6,
      "y": 9,
      "z": 14,
      "name": "Rock_Stone"
    },
    {
      "x": -6,
      "y": 10,
      "z": 14,
      "name": "Rock_Stone"
    },
    {
      "x": -6,
      "y": 11,
      "z": 14,
      "name": "Rock_Stone"
    },
    {
      "x": -6,
      "y": 12,
      "z": 14,
      "name": "Rock_Stone"
    },
    {
      "x": -5,
      "y": -1,
      "z": 0,
      "name": "Rock_Stone"
    },
    {
      "x": -5,
      "y": 0,
      "z": 0,
      "name": "Rock_Stone"
    },
    {
      "x": -5,
      "y": 1,
      "z": 0,
      "name": "Rock_Stone"
    },
    {
      "x": -5,
      "y": 2,
      "z": 0,
      "name": "Rock_Stone"
    },
    {
      "x": -5,
      "y": 3,
      "z": 0,
      "name": "Rock_Stone"
    },
    {
      "x": -5,
      "y": 4,
      "z": 0,
      "name": "Rock_Stone"
    },
    {
      "x": -5,
      "y": 5,
      "z": 0,
      "name": "Rock_Stone"
    },
    {
      "x": -5,
      "y": 6,
      "z": 0,
      "name": "Rock_Stone"
    },
    {
      "x": -5,
      "y": 7,
      "z": 0,
      "name": "Rock_Stone"
    },
    {
      "x": -5,
      "y": 8,
      "z": 0,
      "name": "Rock_Stone"
    },
    {
      "x": -5,
      "y": 9,
      "z": 0,
      "name": "Rock_Stone"
    },
    {
      "x": -5,
      "y": 10,
      "z": 0,
      "name": "Rock_Stone"
    },
    {
      "x": -5,
      "y": 11,
      "z": 0,
      "name": "Rock_Stone"
    },
    {
      "x": -5,
      "y": 12,
      "z": 0,
      "name": "Rock_Stone"
    },
    {
      "x": -5,
      "y": -1,
      "z": 1,
      "name": "Rock_Stone"
    },
    {
      "x": -5,
      "y": 0,
      "z": 1,
      "name": "Rock_Stone"
    },
    {
      "x": -5,
      "y": 1,
      "z": 1,
      "name": "Rock_Stone"
    },
    {
      "x": -5,
      "y": 2,
      "z": 1,
      "name": "Rock_Stone"
    },
    {
      "x": -5,
      "y": 3,
      "z": 1,
      "name": "Rock_Stone"
    },
    {
      "x": -5,
      "y": 4,
      "z": 1,
      "name": "Rock_Stone"
    },
    {
      "x": -5,
      "y": 5,
      "z": 1,
      "name": "Rock_Stone"
    },
    {
      "x": -5,
      "y": 6,
      "z": 1,
      "name": "Rock_Stone"
    },
    {
      "x": -5,
      "y": 7,
      "z": 1,
      "name": "Rock_Stone"
    },
    {
      "x": -5,
      "y": 8,
      "z": 1,
      "name": "Rock_Stone"
    },
    {
      "x": -5,
      "y": 9,
      "z": 1,
      "name": "Rock_Stone"
    },
    {
      "x": -5,
      "y": 10,
      "z": 1,
      "name": "Rock_Stone"
    },
    {
      "x": -5,
      "y": 11,
      "z": 1,
      "name": "Rock_Stone"
    },
    {
      "x": -5,
      "y": 12,
      "z": 1,
      "name": "Rock_Stone"
    },
    {
      "x": -5,
      "y": -1,
      "z": 2,
      "name": "Rock_Stone"
    },
    {
      "x": -5,
      "y": 0,
      "z": 2,
      "name": "Rock_Stone"
    },
    {
      "x": -5,
      "y": 1,
      "z": 2,
      "name": "Rock_Stone"
    },
    {
      "x": -5,
      "y": 2,
      "z": 2,
      "name": "Rock_Stone"
    },
    {
      "x": -5,
      "y": 3,
      "z": 2,
      "name": "Rock_Stone"
    },
    {
      "x": -5,
      "y": 4,
      "z": 2,
      "name": "Rock_Stone"
    },
    {
      "x": -5,
      "y": 5,
      "z": 2,
      "name": "Rock_Stone"
    },
    {
      "x": -5,
      "y": 6,
      "z": 2,
      "name": "Rock_Stone"
    },
    {
      "x": -5,
      "y": 7,
      "z": 2,
      "name": "Rock_Stone"
    },
    {
      "x": -5,
      "y": 8,
      "z": 2,
      "name": "Rock_Stone"
    },
    {
      "x": -5,
      "y": 9,
      "z": 2,
      "name": "Rock_Stone"
    },
    {
      "x": -5,
      "y": 10,
      "z": 2,
      "name": "Rock_Stone"
    },
    {
      "x": -5,
      "y": 11,
      "z": 2,
      "name": "Rock_Stone"
    },
    {
      "x": -5,
      "y": 12,
      "z": 2,
      "name": "Rock_Stone"
    },
    {
      "x": -5,
      "y": -1,
      "z": 3,
      "name": "Rock_Stone"
    },
    {
      "x": -5,
      "y": 0,
      "z": 3,
      "name": "Rock_Stone"
    },
    {
      "x": -5,
      "y": 1,
      "z": 3,
      "name": "Rock_Stone"
    },
    {
      "x": -5,
      "y": 2,
      "z": 3,
      "name": "Rock_Stone"
    },
    {
      "x": -5,
      "y": 3,
      "z": 3,
      "name": "Rock_Stone"
    },
    {
      "x": -5,
      "y": 4,
      "z": 3,
      "name": "Rock_Stone"
    },
    {
      "x": -5,
      "y": 5,
      "z": 3,
      "name": "Rock_Stone"
    },
    {
      "x": -5,
      "y": 6,
      "z": 3,
      "name": "Rock_Stone"
    },
    {
      "x": -5,
      "y": 7,
      "z": 3,
      "name": "Rock_Stone"
    },
    {
      "x": -5,
      "y": 8,
      "z": 3,
      "name": "Rock_Stone"
    },
    {
      "x": -5,
      "y": 9,
      "z": 3,
      "name": "Rock_Stone"
    },
    {
      "x": -5,
      "y": 10,
      "z": 3,
      "name": "Rock_Stone"
    },
    {
      "x": -5,
      "y": 11,
      "z": 3,
      "name": "Rock_Stone"
    },
    {
      "x": -5,
      "y": 12,
      "z": 3,
      "name": "Rock_Stone"
    },
    {
      "x": -5,
      "y": -1,
      "z": 4,
      "name": "Rock_Stone"
    },
    {
      "x": -5,
      "y": 0,
      "z": 4,
      "name": "Rock_Stone"
    },
    {
      "x": -5,
      "y": 1,
      "z": 4,
      "name": "Rock_Stone"
    },
    {
      "x": -5,
      "y": 2,
      "z": 4,
      "name": "Rock_Stone"
    },
    {
      "x": -5,
      "y": 3,
      "z": 4,
      "name": "Rock_Stone"
    },
    {
      "x": -5,
      "y": 4,
      "z": 4,
      "name": "Rock_Stone"
    },
    {
      "x": -5,
      "y": 5,
      "z": 4,
      "name": "Rock_Stone"
    },
    {
      "x": -5,
      "y": 6,
      "z": 4,
      "name": "Rock_Stone"
    },
    {
      "x": -5,
      "y": 7,
      "z": 4,
      "name": "Rock_Stone"
    },
    {
      "x": -5,
      "y": 8,
      "z": 4,
      "name": "Rock_Stone"
    },
    {
      "x": -5,
      "y": 9,
      "z": 4,
      "name": "Rock_Stone"
    },
    {
      "x": -5,
      "y": 10,
      "z": 4,
      "name": "Rock_Stone"
    },
    {
      "x": -5,
      "y": 11,
      "z": 4,
      "name": "Rock_Stone"
    },
    {
      "x": -5,
      "y": 12,
      "z": 4,
      "name": "Rock_Stone"
    },
    {
      "x": -5,
      "y": -1,
      "z": 5,
      "name": "Rock_Stone"
    },
    {
      "x": -5,
      "y": 0,
      "z": 5,
      "name": "Rock_Stone"
    },
    {
      "x": -5,
      "y": 1,
      "z": 5,
      "name": "Rock_Stone"
    },
    {
      "x": -5,
      "y": 2,
      "z": 5,
      "name": "Rock_Stone"
    },
    {
      "x": -5,
      "y": 3,
      "z": 5,
      "name": "Rock_Stone"
    },
    {
      "x": -5,
      "y": 4,
      "z": 5,
      "name": "Rock_Stone"
    },
    {
      "x": -5,
      "y": 5,
      "z": 5,
      "name": "Rock_Stone"
    },
    {
      "x": -5,
      "y": 6,
      "z": 5,
      "name": "Rock_Stone"
    },
    {
      "x": -5,
      "y": 7,
      "z": 5,
      "name": "Rock_Stone"
    },
    {
      "x": -5,
      "y": 8,
      "z": 5,
      "name": "Rock_Stone"
    },
    {
      "x": -5,
      "y": 9,
      "z": 5,
      "name": "Rock_Stone"
    },
    {
      "x": -5,
      "y": 10,
      "z": 5,
      "name": "Rock_Stone"
    },
    {
      "x": -5,
      "y": 11,
      "z": 5,
      "name": "Rock_Stone"
    },
    {
      "x": -5,
      "y": 12,
      "z": 5,
      "name": "Rock_Stone"
    },
    {
      "x": -5,
      "y": -1,
      "z": 6,
      "name": "Rock_Stone"
    },
    {
      "x": -5,
      "y": 0,
      "z": 6,
      "name": "Rock_Stone"
    },
    {
      "x": -5,
      "y": 1,
      "z": 6,
      "name": "Rock_Stone"
    },
    {
      "x": -5,
      "y": 2,
      "z": 6,
      "name": "Rock_Stone"
    },
    {
      "x": -5,
      "y": 3,
      "z": 6,
      "name": "Rock_Stone"
    },
    {
      "x": -5,
      "y": 4,
      "z": 6,
      "name": "Rock_Stone_Cobble"
    },
    {
      "x": -5,
      "y": 5,
      "z": 6,
      "name": "Rock_Stone_Cobble"
    },
    {
      "x": -5,
      "y": 6,
      "z": 6,
      "name": "Empty"
    },
    {
      "x": -5,
      "y": 7,
      "z": 6,
      "name": "Empty"
    },
    {
      "x": -5,
      "y": 8,
      "z": 6,
      "name": "Empty"
    },
    {
      "x": -5,
      "y": 9,
      "z": 6,
      "name": "Empty"
    },
    {
      "x": -5,
      "y": 10,
      "z": 6,
      "name": "Rock_Stone"
    },
    {
      "x": -5,
      "y": 11,
      "z": 6,
      "name": "Rock_Stone"
    },
    {
      "x": -5,
      "y": 12,
      "z": 6,
      "name": "Rock_Stone"
    },
    {
      "x": -5,
      "y": -1,
      "z": 7,
      "name": "Rock_Stone"
    },
    {
      "x": -5,
      "y": 0,
      "z": 7,
      "name": "Rock_Stone"
    },
    {
      "x": -5,
      "y": 1,
      "z": 7,
      "name": "Rock_Stone"
    },
    {
      "x": -5,
      "y": 2,
      "z": 7,
      "name": "Rock_Stone"
    },
    {
      "x": -5,
      "y": 3,
      "z": 7,
      "name": "Rock_Stone"
    },
    {
      "x": -5,
      "y": 4,
      "z": 7,
      "name": "Ore_Copper_Stone"
    },
    {
      "x": -5,
      "y": 5,
      "z": 7,
      "name": "Ore_Copper_Stone"
    },
    {
      "x": -5,
      "y": 6,
      "z": 7,
      "name": "Empty"
    },
    {
      "x": -5,
      "y": 7,
      "z": 7,
      "name": "Empty"
    },
    {
      "x": -5,
      "y": 8,
      "z": 7,
      "name": "Empty"
    },
    {
      "x": -5,
      "y": 9,
      "z": 7,
      "name": "Empty"
    },
    {
      "x": -5,
      "y": 10,
      "z": 7,
      "name": "Empty"
    },
    {
      "x": -5,
      "y": 11,
      "z": 7,
      "name": "Rock_Stone"
    },
    {
      "x": -5,
      "y": 12,
      "z": 7,
      "name": "Rock_Stone"
    },
    {
      "x": -5,
      "y": -1,
      "z": 8,
      "name": "Rock_Stone"
    },
    {
      "x": -5,
      "y": 0,
      "z": 8,
      "name": "Rock_Stone"
    },
    {
      "x": -5,
      "y": 1,
      "z": 8,
      "name": "Rock_Stone"
    },
    {
      "x": -5,
      "y": 2,
      "z": 8,
      "name": "Rock_Stone"
    },
    {
      "x": -5,
      "y": 3,
      "z": 8,
      "name": "Rock_Stone"
    },
    {
      "x": -5,
      "y": 4,
      "z": 8,
      "name": "Ore_Copper_Stone"
    },
    {
      "x": -5,
      "y": 5,
      "z": 8,
      "name": "Ore_Copper_Stone"
    },
    {
      "x": -5,
      "y": 6,
      "z": 8,
      "name": "Empty"
    },
    {
      "x": -5,
      "y": 7,
      "z": 8,
      "name": "Empty"
    },
    {
      "x": -5,
      "y": 8,
      "z": 8,
      "name": "Empty"
    },
    {
      "x": -5,
      "y": 9,
      "z": 8,
      "name": "Empty"
    },
    {
      "x": -5,
      "y": 10,
      "z": 8,
      "name": "Rock_Stone"
    },
    {
      "x": -5,
      "y": 11,
      "z": 8,
      "name": "Rock_Stone"
    },
    {
      "x": -5,
      "y": 12,
      "z": 8,
      "name": "Rock_Stone"
    },
    {
      "x": -5,
      "y": -1,
      "z": 9,
      "name": "Rock_Stone"
    },
    {
      "x": -5,
      "y": 0,
      "z": 9,
      "name": "Rock_Stone"
    },
    {
      "x": -5,
      "y": 1,
      "z": 9,
      "name": "Rock_Stone"
    },
    {
      "x": -5,
      "y": 2,
      "z": 9,
      "name": "Rock_Stone"
    },
    {
      "x": -5,
      "y": 3,
      "z": 9,
      "name": "Rock_Stone"
    },
    {
      "x": -5,
      "y": 4,
      "z": 9,
      "name": "Ore_Copper_Stone"
    },
    {
      "x": -5,
      "y": 5,
      "z": 9,
      "name": "Ore_Copper_Stone"
    },
    {
      "x": -5,
      "y": 6,
      "z": 9,
      "name": "Empty"
    },
    {
      "x": -5,
      "y": 7,
      "z": 9,
      "name": "Empty"
    },
    {
      "x": -5,
      "y": 8,
      "z": 9,
      "name": "Empty"
    },
    {
      "x": -5,
      "y": 9,
      "z": 9,
      "name": "Empty"
    },
    {
      "x": -5,
      "y": 10,
      "z": 9,
      "name": "Rock_Stone"
    },
    {
      "x": -5,
      "y": 11,
      "z": 9,
      "name": "Rock_Stone"
    },
    {
      "x": -5,
      "y": 12,
      "z": 9,
      "name": "Rock_Stone"
    },
    {
      "x": -5,
      "y": -1,
      "z": 10,
      "name": "Rock_Stone"
    },
    {
      "x": -5,
      "y": 0,
      "z": 10,
      "name": "Rock_Stone"
    },
    {
      "x": -5,
      "y": 1,
      "z": 10,
      "name": "Rock_Stone"
    },
    {
      "x": -5,
      "y": 2,
      "z": 10,
      "name": "Rock_Stone"
    },
    {
      "x": -5,
      "y": 3,
      "z": 10,
      "name": "Rock_Stone"
    },
    {
      "x": -5,
      "y": 4,
      "z": 10,
      "name": "Ore_Copper_Stone"
    },
    {
      "x": -5,
      "y": 5,
      "z": 10,
      "name": "Empty"
    },
    {
      "x": -5,
      "y": 6,
      "z": 10,
      "name": "Empty"
    },
    {
      "x": -5,
      "y": 7,
      "z": 10,
      "name": "Empty"
    },
    {
      "x": -5,
      "y": 8,
      "z": 10,
      "name": "Empty"
    },
    {
      "x": -5,
      "y": 9,
      "z": 10,
      "name": "Empty"
    },
    {
      "x": -5,
      "y": 10,
      "z": 10,
      "name": "Rock_Stone"
    },
    {
      "x": -5,
      "y": 11,
      "z": 10,
      "name": "Rock_Stone"
    },
    {
      "x": -5,
      "y": 12,
      "z": 10,
      "name": "Rock_Stone"
    },
    {
      "x": -5,
      "y": -1,
      "z": 11,
      "name": "Rock_Stone"
    },
    {
      "x": -5,
      "y": 0,
      "z": 11,
      "name": "Rock_Stone"
    },
    {
      "x": -5,
      "y": 1,
      "z": 11,
      "name": "Rock_Stone"
    },
    {
      "x": -5,
      "y": 2,
      "z": 11,
      "name": "Rock_Stone"
    },
    {
      "x": -5,
      "y": 3,
      "z": 11,
      "name": "Rock_Stone"
    },
    {
      "x": -5,
      "y": 4,
      "z": 11,
      "name": "Rock_Stone_Cobble"
    },
    {
      "x": -5,
      "y": 5,
      "z": 11,
      "name": "Rock_Stone_Cobble"
    },
    {
      "x": -5,
      "y": 6,
      "z": 11,
      "name": "Empty"
    },
    {
      "x": -5,
      "y": 7,
      "z": 11,
      "name": "Empty"
    },
    {
      "x": -5,
      "y": 8,
      "z": 11,
      "name": "Empty"
    },
    {
      "x": -5,
      "y": 9,
      "z": 11,
      "name": "Rock_Stone"
    },
    {
      "x": -5,
      "y": 10,
      "z": 11,
      "name": "Rock_Stone"
    },
    {
      "x": -5,
      "y": 11,
      "z": 11,
      "name": "Rock_Stone"
    },
    {
      "x": -5,
      "y": 12,
      "z": 11,
      "name": "Rock_Stone"
    },
    {
      "x": -5,
      "y": -1,
      "z": 12,
      "name": "Rock_Stone"
    },
    {
      "x": -5,
      "y": 0,
      "z": 12,
      "name": "Rock_Stone"
    },
    {
      "x": -5,
      "y": 1,
      "z": 12,
      "name": "Rock_Stone"
    },
    {
      "x": -5,
      "y": 2,
      "z": 12,
      "name": "Rock_Stone"
    },
    {
      "x": -5,
      "y": 3,
      "z": 12,
      "name": "Rock_Stone"
    },
    {
      "x": -5,
      "y": 4,
      "z": 12,
      "name": "Rock_Stone"
    },
    {
      "x": -5,
      "y": 5,
      "z": 12,
      "name": "Rock_Stone_Cobble"
    },
    {
      "x": -5,
      "y": 6,
      "z": 12,
      "name": "Empty"
    },
    {
      "x": -5,
      "y": 7,
      "z": 12,
      "name": "Rock_Stone"
    },
    {
      "x": -5,
      "y": 8,
      "z": 12,
      "name": "Rock_Stone"
    },
    {
      "x": -5,
      "y": 9,
      "z": 12,
      "name": "Rock_Stone"
    },
    {
      "x": -5,
      "y": 10,
      "z": 12,
      "name": "Rock_Stone"
    },
    {
      "x": -5,
      "y": 11,
      "z": 12,
      "name": "Rock_Stone"
    },
    {
      "x": -5,
      "y": 12,
      "z": 12,
      "name": "Rock_Stone"
    },
    {
      "x": -5,
      "y": -1,
      "z": 13,
      "name": "Rock_Stone"
    },
    {
      "x": -5,
      "y": 0,
      "z": 13,
      "name": "Rock_Stone"
    },
    {
      "x": -5,
      "y": 1,
      "z": 13,
      "name": "Rock_Stone"
    },
    {
      "x": -5,
      "y": 2,
      "z": 13,
      "name": "Rock_Stone"
    },
    {
      "x": -5,
      "y": 3,
      "z": 13,
      "name": "Empty"
    },
    {
      "x": -5,
      "y": 4,
      "z": 13,
      "name": "Rock_Stone"
    },
    {
      "x": -5,
      "y": 5,
      "z": 13,
      "name": "Rock_Stone"
    },
    {
      "x": -5,
      "y": 6,
      "z": 13,
      "name": "Rock_Stone"
    },
    {
      "x": -5,
      "y": 7,
      "z": 13,
      "name": "Rock_Stone"
    },
    {
      "x": -5,
      "y": 8,
      "z": 13,
      "name": "Rock_Stone"
    },
    {
      "x": -5,
      "y": 9,
      "z": 13,
      "name": "Rock_Stone"
    },
    {
      "x": -5,
      "y": 10,
      "z": 13,
      "name": "Rock_Stone"
    },
    {
      "x": -5,
      "y": 11,
      "z": 13,
      "name": "Rock_Stone"
    },
    {
      "x": -5,
      "y": 12,
      "z": 13,
      "name": "Rock_Stone"
    },
    {
      "x": -5,
      "y": -1,
      "z": 14,
      "name": "Rock_Stone"
    },
    {
      "x": -5,
      "y": 0,
      "z": 14,
      "name": "Rock_Stone"
    },
    {
      "x": -5,
      "y": 1,
      "z": 14,
      "name": "Rock_Stone"
    },
    {
      "x": -5,
      "y": 2,
      "z": 14,
      "name": "Rock_Stone"
    },
    {
      "x": -5,
      "y": 3,
      "z": 14,
      "name": "Rock_Stone"
    },
    {
      "x": -5,
      "y": 4,
      "z": 14,
      "name": "Rock_Stone"
    },
    {
      "x": -5,
      "y": 5,
      "z": 14,
      "name": "Rock_Stone"
    },
    {
      "x": -5,
      "y": 6,
      "z": 14,
      "name": "Rock_Stone"
    },
    {
      "x": -5,
      "y": 7,
      "z": 14,
      "name": "Rock_Stone"
    },
    {
      "x": -5,
      "y": 8,
      "z": 14,
      "name": "Rock_Stone"
    },
    {
      "x": -5,
      "y": 9,
      "z": 14,
      "name": "Rock_Stone"
    },
    {
      "x": -5,
      "y": 10,
      "z": 14,
      "name": "Rock_Stone"
    },
    {
      "x": -5,
      "y": 11,
      "z": 14,
      "name": "Rock_Stone"
    },
    {
      "x": -5,
      "y": 12,
      "z": 14,
      "name": "Rock_Stone"
    },
    {
      "x": -4,
      "y": -1,
      "z": 0,
      "name": "Rock_Stone"
    },
    {
      "x": -4,
      "y": 0,
      "z": 0,
      "name": "Rock_Stone"
    },
    {
      "x": -4,
      "y": 1,
      "z": 0,
      "name": "Rock_Stone"
    },
    {
      "x": -4,
      "y": 2,
      "z": 0,
      "name": "Rock_Stone"
    },
    {
      "x": -4,
      "y": 3,
      "z": 0,
      "name": "Rock_Stone"
    },
    {
      "x": -4,
      "y": 4,
      "z": 0,
      "name": "Rock_Stone"
    },
    {
      "x": -4,
      "y": 5,
      "z": 0,
      "name": "Rock_Stone"
    },
    {
      "x": -4,
      "y": 6,
      "z": 0,
      "name": "Rock_Stone"
    },
    {
      "x": -4,
      "y": 7,
      "z": 0,
      "name": "Rock_Stone"
    },
    {
      "x": -4,
      "y": 8,
      "z": 0,
      "name": "Rock_Stone"
    },
    {
      "x": -4,
      "y": 9,
      "z": 0,
      "name": "Rock_Stone"
    },
    {
      "x": -4,
      "y": 10,
      "z": 0,
      "name": "Rock_Stone"
    },
    {
      "x": -4,
      "y": 11,
      "z": 0,
      "name": "Rock_Stone"
    },
    {
      "x": -4,
      "y": 12,
      "z": 0,
      "name": "Rock_Stone"
    },
    {
      "x": -4,
      "y": -1,
      "z": 1,
      "name": "Rock_Stone"
    },
    {
      "x": -4,
      "y": 0,
      "z": 1,
      "name": "Rock_Stone"
    },
    {
      "x": -4,
      "y": 1,
      "z": 1,
      "name": "Rock_Stone"
    },
    {
      "x": -4,
      "y": 2,
      "z": 1,
      "name": "Rock_Stone"
    },
    {
      "x": -4,
      "y": 3,
      "z": 1,
      "name": "Rock_Stone"
    },
    {
      "x": -4,
      "y": 4,
      "z": 1,
      "name": "Rock_Stone"
    },
    {
      "x": -4,
      "y": 5,
      "z": 1,
      "name": "Rock_Stone"
    },
    {
      "x": -4,
      "y": 6,
      "z": 1,
      "name": "Rock_Stone"
    },
    {
      "x": -4,
      "y": 7,
      "z": 1,
      "name": "Rock_Stone"
    },
    {
      "x": -4,
      "y": 8,
      "z": 1,
      "name": "Rock_Stone"
    },
    {
      "x": -4,
      "y": 9,
      "z": 1,
      "name": "Rock_Stone"
    },
    {
      "x": -4,
      "y": 10,
      "z": 1,
      "name": "Rock_Stone"
    },
    {
      "x": -4,
      "y": 11,
      "z": 1,
      "name": "Rock_Stone"
    },
    {
      "x": -4,
      "y": 12,
      "z": 1,
      "name": "Rock_Stone"
    },
    {
      "x": -4,
      "y": -1,
      "z": 2,
      "name": "Rock_Stone"
    },
    {
      "x": -4,
      "y": 0,
      "z": 2,
      "name": "Rock_Stone"
    },
    {
      "x": -4,
      "y": 1,
      "z": 2,
      "name": "Rock_Stone"
    },
    {
      "x": -4,
      "y": 2,
      "z": 2,
      "name": "Rock_Stone"
    },
    {
      "x": -4,
      "y": 3,
      "z": 2,
      "name": "Rock_Stone"
    },
    {
      "x": -4,
      "y": 4,
      "z": 2,
      "name": "Rock_Stone"
    },
    {
      "x": -4,
      "y": 5,
      "z": 2,
      "name": "Rock_Stone"
    },
    {
      "x": -4,
      "y": 6,
      "z": 2,
      "name": "Rock_Stone"
    },
    {
      "x": -4,
      "y": 7,
      "z": 2,
      "name": "Rock_Stone"
    },
    {
      "x": -4,
      "y": 8,
      "z": 2,
      "name": "Rock_Stone"
    },
    {
      "x": -4,
      "y": 9,
      "z": 2,
      "name": "Rock_Stone"
    },
    {
      "x": -4,
      "y": 10,
      "z": 2,
      "name": "Rock_Stone"
    },
    {
      "x": -4,
      "y": 11,
      "z": 2,
      "name": "Rock_Stone"
    },
    {
      "x": -4,
      "y": 12,
      "z": 2,
      "name": "Rock_Stone"
    },
    {
      "x": -4,
      "y": -1,
      "z": 3,
      "name": "Rock_Stone"
    },
    {
      "x": -4,
      "y": 0,
      "z": 3,
      "name": "Rock_Stone"
    },
    {
      "x": -4,
      "y": 1,
      "z": 3,
      "name": "Rock_Stone"
    },
    {
      "x": -4,
      "y": 2,
      "z": 3,
      "name": "Rock_Stone"
    },
    {
      "x": -4,
      "y": 3,
      "z": 3,
      "name": "Rock_Stone"
    },
    {
      "x": -4,
      "y": 4,
      "z": 3,
      "name": "Rock_Stone"
    },
    {
      "x": -4,
      "y": 5,
      "z": 3,
      "name": "Rock_Stone"
    },
    {
      "x": -4,
      "y": 6,
      "z": 3,
      "name": "Rock_Stone"
    },
    {
      "x": -4,
      "y": 7,
      "z": 3,
      "name": "Rock_Stone"
    },
    {
      "x": -4,
      "y": 8,
      "z": 3,
      "name": "Rock_Stone"
    },
    {
      "x": -4,
      "y": 9,
      "z": 3,
      "name": "Rock_Stone"
    },
    {
      "x": -4,
      "y": 10,
      "z": 3,
      "name": "Rock_Stone"
    },
    {
      "x": -4,
      "y": 11,
      "z": 3,
      "name": "Rock_Stone"
    },
    {
      "x": -4,
      "y": 12,
      "z": 3,
      "name": "Rock_Stone"
    },
    {
      "x": -4,
      "y": -1,
      "z": 4,
      "name": "Rock_Stone"
    },
    {
      "x": -4,
      "y": 0,
      "z": 4,
      "name": "Rock_Stone"
    },
    {
      "x": -4,
      "y": 1,
      "z": 4,
      "name": "Rock_Stone"
    },
    {
      "x": -4,
      "y": 2,
      "z": 4,
      "name": "Rock_Stone"
    },
    {
      "x": -4,
      "y": 3,
      "z": 4,
      "name": "Rock_Stone"
    },
    {
      "x": -4,
      "y": 4,
      "z": 4,
      "name": "Rock_Stone"
    },
    {
      "x": -4,
      "y": 5,
      "z": 4,
      "name": "Rock_Stone"
    },
    {
      "x": -4,
      "y": 6,
      "z": 4,
      "name": "Rock_Stone"
    },
    {
      "x": -4,
      "y": 7,
      "z": 4,
      "name": "Rock_Stone"
    },
    {
      "x": -4,
      "y": 8,
      "z": 4,
      "name": "Rock_Stone"
    },
    {
      "x": -4,
      "y": 9,
      "z": 4,
      "name": "Rock_Stone"
    },
    {
      "x": -4,
      "y": 10,
      "z": 4,
      "name": "Rock_Stone"
    },
    {
      "x": -4,
      "y": 11,
      "z": 4,
      "name": "Rock_Stone"
    },
    {
      "x": -4,
      "y": 12,
      "z": 4,
      "name": "Rock_Stone"
    },
    {
      "x": -4,
      "y": -1,
      "z": 5,
      "name": "Rock_Stone"
    },
    {
      "x": -4,
      "y": 0,
      "z": 5,
      "name": "Rock_Stone"
    },
    {
      "x": -4,
      "y": 1,
      "z": 5,
      "name": "Rock_Stone"
    },
    {
      "x": -4,
      "y": 2,
      "z": 5,
      "name": "Rock_Stone"
    },
    {
      "x": -4,
      "y": 3,
      "z": 5,
      "name": "Rock_Stone"
    },
    {
      "x": -4,
      "y": 4,
      "z": 5,
      "name": "Empty"
    },
    {
      "x": -4,
      "y": 5,
      "z": 5,
      "name": "Empty"
    },
    {
      "x": -4,
      "y": 6,
      "z": 5,
      "name": "Empty"
    },
    {
      "x": -4,
      "y": 7,
      "z": 5,
      "name": "Empty"
    },
    {
      "x": -4,
      "y": 8,
      "z": 5,
      "name": "Empty"
    },
    {
      "x": -4,
      "y": 9,
      "z": 5,
      "name": "Empty"
    },
    {
      "x": -4,
      "y": 10,
      "z": 5,
      "name": "Empty"
    },
    {
      "x": -4,
      "y": 11,
      "z": 5,
      "name": "Rock_Stone"
    },
    {
      "x": -4,
      "y": 12,
      "z": 5,
      "name": "Rock_Stone"
    },
    {
      "x": -4,
      "y": -1,
      "z": 6,
      "name": "Rock_Stone"
    },
    {
      "x": -4,
      "y": 0,
      "z": 6,
      "name": "Rock_Stone"
    },
    {
      "x": -4,
      "y": 1,
      "z": 6,
      "name": "Rock_Stone"
    },
    {
      "x": -4,
      "y": 2,
      "z": 6,
      "name": "Rock_Stone"
    },
    {
      "x": -4,
      "y": 3,
      "z": 6,
      "name": "Rock_Stone"
    },
    {
      "x": -4,
      "y": 4,
      "z": 6,
      "name": "Rock_Stone_Cobble"
    },
    {
      "x": -4,
      "y": 5,
      "z": 6,
      "name": "Rock_Stone_Cobble"
    },
    {
      "x": -4,
      "y": 6,
      "z": 6,
      "name": "Empty"
    },
    {
      "x": -4,
      "y": 7,
      "z": 6,
      "name": "Empty"
    },
    {
      "x": -4,
      "y": 8,
      "z": 6,
      "name": "Empty"
    },
    {
      "x": -4,
      "y": 9,
      "z": 6,
      "name": "Empty"
    },
    {
      "x": -4,
      "y": 10,
      "z": 6,
      "name": "Empty"
    },
    {
      "x": -4,
      "y": 11,
      "z": 6,
      "name": "Rock_Stone"
    },
    {
      "x": -4,
      "y": 12,
      "z": 6,
      "name": "Rock_Stone"
    },
    {
      "x": -4,
      "y": -1,
      "z": 7,
      "name": "Rock_Stone"
    },
    {
      "x": -4,
      "y": 0,
      "z": 7,
      "name": "Rock_Stone"
    },
    {
      "x": -4,
      "y": 1,
      "z": 7,
      "name": "Rock_Stone"
    },
    {
      "x": -4,
      "y": 2,
      "z": 7,
      "name": "Rock_Stone"
    },
    {
      "x": -4,
      "y": 3,
      "z": 7,
      "name": "Rock_Stone"
    },
    {
      "x": -4,
      "y": 4,
      "z": 7,
      "name": "Ore_Copper_Stone"
    },
    {
      "x": -4,
      "y": 5,
      "z": 7,
      "name": "Ore_Copper_Stone"
    },
    {
      "x": -4,
      "y": 6,
      "z": 7,
      "name": "Empty"
    },
    {
      "x": -4,
      "y": 7,
      "z": 7,
      "name": "Empty"
    },
    {
      "x": -4,
      "y": 8,
      "z": 7,
      "name": "Empty"
    },
    {
      "x": -4,
      "y": 9,
      "z": 7,
      "name": "Empty"
    },
    {
      "x": -4,
      "y": 10,
      "z": 7,
      "name": "Empty"
    },
    {
      "x": -4,
      "y": 11,
      "z": 7,
      "name": "Rock_Stone"
    },
    {
      "x": -4,
      "y": 12,
      "z": 7,
      "name": "Rock_Stone"
    },
    {
      "x": -4,
      "y": -1,
      "z": 8,
      "name": "Rock_Stone"
    },
    {
      "x": -4,
      "y": 0,
      "z": 8,
      "name": "Rock_Stone"
    },
    {
      "x": -4,
      "y": 1,
      "z": 8,
      "name": "Rock_Stone"
    },
    {
      "x": -4,
      "y": 2,
      "z": 8,
      "name": "Rock_Stone"
    },
    {
      "x": -4,
      "y": 3,
      "z": 8,
      "name": "Rock_Stone"
    },
    {
      "x": -4,
      "y": 4,
      "z": 8,
      "name": "Ore_Copper_Stone"
    },
    {
      "x": -4,
      "y": 5,
      "z": 8,
      "name": "Empty"
    },
    {
      "x": -4,
      "y": 6,
      "z": 8,
      "name": "Empty"
    },
    {
      "x": -4,
      "y": 7,
      "z": 8,
      "name": "Empty"
    },
    {
      "x": -4,
      "y": 8,
      "z": 8,
      "name": "Empty"
    },
    {
      "x": -4,
      "y": 9,
      "z": 8,
      "name": "Empty"
    },
    {
      "x": -4,
      "y": 10,
      "z": 8,
      "name": "Empty"
    },
    {
      "x": -4,
      "y": 11,
      "z": 8,
      "name": "Rock_Stone"
    },
    {
      "x": -4,
      "y": 12,
      "z": 8,
      "name": "Rock_Stone"
    },
    {
      "x": -4,
      "y": -1,
      "z": 9,
      "name": "Rock_Stone"
    },
    {
      "x": -4,
      "y": 0,
      "z": 9,
      "name": "Rock_Stone"
    },
    {
      "x": -4,
      "y": 1,
      "z": 9,
      "name": "Rock_Stone"
    },
    {
      "x": -4,
      "y": 2,
      "z": 9,
      "name": "Rock_Stone"
    },
    {
      "x": -4,
      "y": 3,
      "z": 9,
      "name": "Soil_Gravel"
    },
    {
      "x": -4,
      "y": 4,
      "z": 9,
      "name": "Ore_Copper_Stone"
    },
    {
      "x": -4,
      "y": 5,
      "z": 9,
      "name": "Empty"
    },
    {
      "x": -4,
      "y": 6,
      "z": 9,
      "name": "Empty"
    },
    {
      "x": -4,
      "y": 7,
      "z": 9,
      "name": "Empty"
    },
    {
      "x": -4,
      "y": 8,
      "z": 9,
      "name": "Empty"
    },
    {
      "x": -4,
      "y": 9,
      "z": 9,
      "name": "Empty"
    },
    {
      "x": -4,
      "y": 10,
      "z": 9,
      "name": "Empty"
    },
    {
      "x": -4,
      "y": 11,
      "z": 9,
      "name": "Rock_Stone"
    },
    {
      "x": -4,
      "y": 12,
      "z": 9,
      "name": "Rock_Stone"
    },
    {
      "x": -4,
      "y": -1,
      "z": 10,
      "name": "Rock_Stone"
    },
    {
      "x": -4,
      "y": 0,
      "z": 10,
      "name": "Rock_Stone"
    },
    {
      "x": -4,
      "y": 1,
      "z": 10,
      "name": "Rock_Stone"
    },
    {
      "x": -4,
      "y": 2,
      "z": 10,
      "name": "Rock_Stone"
    },
    {
      "x": -4,
      "y": 3,
      "z": 10,
      "name": "Rock_Stone"
    },
    {
      "x": -4,
      "y": 4,
      "z": 10,
      "name": "Empty"
    },
    {
      "x": -4,
      "y": 5,
      "z": 10,
      "name": "Empty"
    },
    {
      "x": -4,
      "y": 6,
      "z": 10,
      "name": "Empty"
    },
    {
      "x": -4,
      "y": 7,
      "z": 10,
      "name": "Empty"
    },
    {
      "x": -4,
      "y": 8,
      "z": 10,
      "name": "Empty"
    },
    {
      "x": -4,
      "y": 9,
      "z": 10,
      "name": "Rock_Stone_Stalactite_Small",
      "rotation": 8
    },
    {
      "x": -4,
      "y": 10,
      "z": 10,
      "name": "Rock_Stone"
    },
    {
      "x": -4,
      "y": 11,
      "z": 10,
      "name": "Rock_Stone"
    },
    {
      "x": -4,
      "y": 12,
      "z": 10,
      "name": "Rock_Stone"
    },
    {
      "x": -4,
      "y": -1,
      "z": 11,
      "name": "Rock_Stone"
    },
    {
      "x": -4,
      "y": 0,
      "z": 11,
      "name": "Rock_Stone"
    },
    {
      "x": -4,
      "y": 1,
      "z": 11,
      "name": "Rock_Stone"
    },
    {
      "x": -4,
      "y": 2,
      "z": 11,
      "name": "Rock_Stone"
    },
    {
      "x": -4,
      "y": 3,
      "z": 11,
      "name": "Rock_Stone"
    },
    {
      "x": -4,
      "y": 4,
      "z": 11,
      "name": "Empty"
    },
    {
      "x": -4,
      "y": 5,
      "z": 11,
      "name": "Empty"
    },
    {
      "x": -4,
      "y": 6,
      "z": 11,
      "name": "Empty"
    },
    {
      "x": -4,
      "y": 7,
      "z": 11,
      "name": "Empty"
    },
    {
      "x": -4,
      "y": 8,
      "z": 11,
      "name": "Rock_Stone_Stalactite_Large",
      "filler": 31744,
      "rotation": 8
    },
    {
      "x": -4,
      "y": 9,
      "z": 11,
      "name": "Rock_Stone_Stalactite_Large",
      "rotation": 8
    },
    {
      "x": -4,
      "y": 10,
      "z": 11,
      "name": "Rock_Stone"
    },
    {
      "x": -4,
      "y": 11,
      "z": 11,
      "name": "Rock_Stone"
    },
    {
      "x": -4,
      "y": 12,
      "z": 11,
      "name": "Rock_Stone"
    },
    {
      "x": -4,
      "y": -1,
      "z": 12,
      "name": "Rock_Stone"
    },
    {
      "x": -4,
      "y": 0,
      "z": 12,
      "name": "Rock_Stone"
    },
    {
      "x": -4,
      "y": 1,
      "z": 12,
      "name": "Rock_Stone"
    },
    {
      "x": -4,
      "y": 2,
      "z": 12,
      "name": "Rock_Stone"
    },
    {
      "x": -4,
      "y": 3,
      "z": 12,
      "name": "Rock_Stone"
    },
    {
      "x": -4,
      "y": 4,
      "z": 12,
      "name": "Rock_Stone_Cobble"
    },
    {
      "x": -4,
      "y": 5,
      "z": 12,
      "name": "Rock_Stone_Cobble"
    },
    {
      "x": -4,
      "y": 6,
      "z": 12,
      "name": "Plant_Moss_Yellow"
    },
    {
      "x": -4,
      "y": 7,
      "z": 12,
      "name": "Empty"
    },
    {
      "x": -4,
      "y": 8,
      "z": 12,
      "name": "Empty"
    },
    {
      "x": -4,
      "y": 9,
      "z": 12,
      "name": "Empty"
    },
    {
      "x": -4,
      "y": 10,
      "z": 12,
      "name": "Rock_Stone"
    },
    {
      "x": -4,
      "y": 11,
      "z": 12,
      "name": "Rock_Stone"
    },
    {
      "x": -4,
      "y": 12,
      "z": 12,
      "name": "Rock_Stone"
    },
    {
      "x": -4,
      "y": -1,
      "z": 13,
      "name": "Rock_Stone"
    },
    {
      "x": -4,
      "y": 0,
      "z": 13,
      "name": "Rock_Stone"
    },
    {
      "x": -4,
      "y": 1,
      "z": 13,
      "name": "Rock_Stone"
    },
    {
      "x": -4,
      "y": 2,
      "z": 13,
      "name": "Empty"
    },
    {
      "x": -4,
      "y": 3,
      "z": 13,
      "name": "Rock_Stone"
    },
    {
      "x": -4,
      "y": 4,
      "z": 13,
      "name": "Rock_Stone"
    },
    {
      "x": -4,
      "y": 5,
      "z": 13,
      "name": "Rock_Stone"
    },
    {
      "x": -4,
      "y": 6,
      "z": 13,
      "name": "Plant_Moss_Rug_Yellow"
    },
    {
      "x": -4,
      "y": 7,
      "z": 13,
      "name": "Empty"
    },
    {
      "x": -4,
      "y": 8,
      "z": 13,
      "name": "Rock_Stone"
    },
    {
      "x": -4,
      "y": 9,
      "z": 13,
      "name": "Rock_Stone"
    },
    {
      "x": -4,
      "y": 10,
      "z": 13,
      "name": "Rock_Stone"
    },
    {
      "x": -4,
      "y": 11,
      "z": 13,
      "name": "Rock_Stone"
    },
    {
      "x": -4,
      "y": 12,
      "z": 13,
      "name": "Rock_Stone"
    },
    {
      "x": -4,
      "y": -1,
      "z": 14,
      "name": "Rock_Stone"
    },
    {
      "x": -4,
      "y": 0,
      "z": 14,
      "name": "Rock_Stone"
    },
    {
      "x": -4,
      "y": 1,
      "z": 14,
      "name": "Rock_Stone"
    },
    {
      "x": -4,
      "y": 2,
      "z": 14,
      "name": "Rock_Stone"
    },
    {
      "x": -4,
      "y": 3,
      "z": 14,
      "name": "Rock_Stone"
    },
    {
      "x": -4,
      "y": 4,
      "z": 14,
      "name": "Rock_Stone"
    },
    {
      "x": -4,
      "y": 5,
      "z": 14,
      "name": "Rock_Stone"
    },
    {
      "x": -4,
      "y": 6,
      "z": 14,
      "name": "Rock_Stone"
    },
    {
      "x": -4,
      "y": 7,
      "z": 14,
      "name": "Rock_Stone"
    },
    {
      "x": -4,
      "y": 8,
      "z": 14,
      "name": "Rock_Stone"
    },
    {
      "x": -4,
      "y": 9,
      "z": 14,
      "name": "Rock_Stone"
    },
    {
      "x": -4,
      "y": 10,
      "z": 14,
      "name": "Rock_Stone"
    },
    {
      "x": -4,
      "y": 11,
      "z": 14,
      "name": "Rock_Stone"
    },
    {
      "x": -4,
      "y": 12,
      "z": 14,
      "name": "Rock_Stone"
    },
    {
      "x": -3,
      "y": -1,
      "z": 0,
      "name": "Rock_Stone"
    },
    {
      "x": -3,
      "y": 0,
      "z": 0,
      "name": "Rock_Stone"
    },
    {
      "x": -3,
      "y": 1,
      "z": 0,
      "name": "Empty"
    },
    {
      "x": -3,
      "y": 2,
      "z": 0,
      "name": "Empty"
    },
    {
      "x": -3,
      "y": 3,
      "z": 0,
      "name": "Empty"
    },
    {
      "x": -3,
      "y": 4,
      "z": 0,
      "name": "Empty"
    },
    {
      "x": -3,
      "y": 5,
      "z": 0,
      "name": "Empty"
    },
    {
      "x": -3,
      "y": 6,
      "z": 0,
      "name": "Rock_Stone"
    },
    {
      "x": -3,
      "y": 7,
      "z": 0,
      "name": "Rock_Stone"
    },
    {
      "x": -3,
      "y": 8,
      "z": 0,
      "name": "Rock_Stone"
    },
    {
      "x": -3,
      "y": 9,
      "z": 0,
      "name": "Rock_Stone"
    },
    {
      "x": -3,
      "y": 10,
      "z": 0,
      "name": "Rock_Stone"
    },
    {
      "x": -3,
      "y": 11,
      "z": 0,
      "name": "Rock_Stone"
    },
    {
      "x": -3,
      "y": 12,
      "z": 0,
      "name": "Rock_Stone"
    },
    {
      "x": -3,
      "y": -1,
      "z": 1,
      "name": "Rock_Stone"
    },
    {
      "x": -3,
      "y": 0,
      "z": 1,
      "name": "Rock_Stone"
    },
    {
      "x": -3,
      "y": 1,
      "z": 1,
      "name": "Rock_Stone_Cobble"
    },
    {
      "x": -3,
      "y": 2,
      "z": 1,
      "name": "Rock_Stone_Brick"
    },
    {
      "x": -3,
      "y": 3,
      "z": 1,
      "name": "Wood_Softwood_Fence",
      "rotation": 2
    },
    {
      "x": -3,
      "y": 4,
      "z": 1,
      "name": "Wood_Softwood_Fence",
      "rotation": 2
    },
    {
      "x": -3,
      "y": 5,
      "z": 1,
      "name": "Empty"
    },
    {
      "x": -3,
      "y": 6,
      "z": 1,
      "name": "Rock_Stone"
    },
    {
      "x": -3,
      "y": 7,
      "z": 1,
      "name": "Rock_Stone"
    },
    {
      "x": -3,
      "y": 8,
      "z": 1,
      "name": "Rock_Stone"
    },
    {
      "x": -3,
      "y": 9,
      "z": 1,
      "name": "Rock_Stone"
    },
    {
      "x": -3,
      "y": 10,
      "z": 1,
      "name": "Rock_Stone"
    },
    {
      "x": -3,
      "y": 11,
      "z": 1,
      "name": "Rock_Stone"
    },
    {
      "x": -3,
      "y": 12,
      "z": 1,
      "name": "Rock_Stone"
    },
    {
      "x": -3,
      "y": -1,
      "z": 2,
      "name": "Rock_Stone"
    },
    {
      "x": -3,
      "y": 0,
      "z": 2,
      "name": "Rock_Stone"
    },
    {
      "x": -3,
      "y": 1,
      "z": 2,
      "name": "Rock_Stone"
    },
    {
      "x": -3,
      "y": 2,
      "z": 2,
      "name": "Rock_Stone_Cobble"
    },
    {
      "x": -3,
      "y": 3,
      "z": 2,
      "name": "Empty"
    },
    {
      "x": -3,
      "y": 4,
      "z": 2,
      "name": "Empty"
    },
    {
      "x": -3,
      "y": 5,
      "z": 2,
      "name": "Empty"
    },
    {
      "x": -3,
      "y": 6,
      "z": 2,
      "name": "Empty"
    },
    {
      "x": -3,
      "y": 7,
      "z": 2,
      "name": "Rock_Stone"
    },
    {
      "x": -3,
      "y": 8,
      "z": 2,
      "name": "Rock_Stone"
    },
    {
      "x": -3,
      "y": 9,
      "z": 2,
      "name": "Rock_Stone"
    },
    {
      "x": -3,
      "y": 10,
      "z": 2,
      "name": "Rock_Stone"
    },
    {
      "x": -3,
      "y": 11,
      "z": 2,
      "name": "Rock_Stone"
    },
    {
      "x": -3,
      "y": 12,
      "z": 2,
      "name": "Rock_Stone"
    },
    {
      "x": -3,
      "y": -1,
      "z": 3,
      "name": "Rock_Stone"
    },
    {
      "x": -3,
      "y": 0,
      "z": 3,
      "name": "Rock_Stone"
    },
    {
      "x": -3,
      "y": 1,
      "z": 3,
      "name": "Rock_Stone"
    },
    {
      "x": -3,
      "y": 2,
      "z": 3,
      "name": "Rock_Stone"
    },
    {
      "x": -3,
      "y": 3,
      "z": 3,
      "name": "Rock_Stone_Stalactite_Small"
    },
    {
      "x": -3,
      "y": 4,
      "z": 3,
      "name": "Empty"
    },
    {
      "x": -3,
      "y": 5,
      "z": 3,
      "name": "Empty"
    },
    {
      "x": -3,
      "y": 6,
      "z": 3,
      "name": "Rock_Stone_Stalactite_Large",
      "filler": 31744,
      "rotation": 8
    },
    {
      "x": -3,
      "y": 7,
      "z": 3,
      "name": "Rock_Stone_Stalactite_Large",
      "rotation": 8
    },
    {
      "x": -3,
      "y": 8,
      "z": 3,
      "name": "Rock_Stone"
    },
    {
      "x": -3,
      "y": 9,
      "z": 3,
      "name": "Rock_Stone"
    },
    {
      "x": -3,
      "y": 10,
      "z": 3,
      "name": "Rock_Stone"
    },
    {
      "x": -3,
      "y": 11,
      "z": 3,
      "name": "Rock_Stone"
    },
    {
      "x": -3,
      "y": 12,
      "z": 3,
      "name": "Rock_Stone"
    },
    {
      "x": -3,
      "y": -1,
      "z": 4,
      "name": "Rock_Stone"
    },
    {
      "x": -3,
      "y": 0,
      "z": 4,
      "name": "Rock_Stone"
    },
    {
      "x": -3,
      "y": 1,
      "z": 4,
      "name": "Rock_Stone"
    },
    {
      "x": -3,
      "y": 2,
      "z": 4,
      "name": "Rock_Stone"
    },
    {
      "x": -3,
      "y": 3,
      "z": 4,
      "name": "Rock_Stone"
    },
    {
      "x": -3,
      "y": 4,
      "z": 4,
      "name": "Empty"
    },
    {
      "x": -3,
      "y": 5,
      "z": 4,
      "name": "Empty"
    },
    {
      "x": -3,
      "y": 6,
      "z": 4,
      "name": "Empty"
    },
    {
      "x": -3,
      "y": 7,
      "z": 4,
      "name": "Empty"
    },
    {
      "x": -3,
      "y": 8,
      "z": 4,
      "name": "Empty"
    },
    {
      "x": -3,
      "y": 9,
      "z": 4,
      "name": "Rock_Stone"
    },
    {
      "x": -3,
      "y": 10,
      "z": 4,
      "name": "Rock_Stone"
    },
    {
      "x": -3,
      "y": 11,
      "z": 4,
      "name": "Rock_Stone"
    },
    {
      "x": -3,
      "y": 12,
      "z": 4,
      "name": "Rock_Stone"
    },
    {
      "x": -3,
      "y": -1,
      "z": 5,
      "name": "Rock_Stone"
    },
    {
      "x": -3,
      "y": 0,
      "z": 5,
      "name": "Rock_Stone"
    },
    {
      "x": -3,
      "y": 1,
      "z": 5,
      "name": "Rock_Stone"
    },
    {
      "x": -3,
      "y": 2,
      "z": 5,
      "name": "Rock_Stone"
    },
    {
      "x": -3,
      "y": 3,
      "z": 5,
      "name": "Rock_Stone"
    },
    {
      "x": -3,
      "y": 4,
      "z": 5,
      "name": "Empty"
    },
    {
      "x": -3,
      "y": 5,
      "z": 5,
      "name": "Empty"
    },
    {
      "x": -3,
      "y": 6,
      "z": 5,
      "name": "Empty"
    },
    {
      "x": -3,
      "y": 7,
      "z": 5,
      "name": "Empty"
    },
    {
      "x": -3,
      "y": 8,
      "z": 5,
      "name": "Empty"
    },
    {
      "x": -3,
      "y": 9,
      "z": 5,
      "name": "Empty"
    },
    {
      "x": -3,
      "y": 10,
      "z": 5,
      "name": "Empty"
    },
    {
      "x": -3,
      "y": 11,
      "z": 5,
      "name": "Rock_Stone"
    },
    {
      "x": -3,
      "y": 12,
      "z": 5,
      "name": "Rock_Stone"
    },
    {
      "x": -3,
      "y": -1,
      "z": 6,
      "name": "Rock_Stone"
    },
    {
      "x": -3,
      "y": 0,
      "z": 6,
      "name": "Rock_Stone"
    },
    {
      "x": -3,
      "y": 1,
      "z": 6,
      "name": "Rock_Stone"
    },
    {
      "x": -3,
      "y": 2,
      "z": 6,
      "name": "Rock_Stone"
    },
    {
      "x": -3,
      "y": 3,
      "z": 6,
      "name": "Rock_Stone"
    },
    {
      "x": -3,
      "y": 4,
      "z": 6,
      "name": "Rock_Stone_Cobble"
    },
    {
      "x": -3,
      "y": 5,
      "z": 6,
      "name": "Empty"
    },
    {
      "x": -3,
      "y": 6,
      "z": 6,
      "name": "Empty"
    },
    {
      "x": -3,
      "y": 7,
      "z": 6,
      "name": "Empty"
    },
    {
      "x": -3,
      "y": 8,
      "z": 6,
      "name": "Empty"
    },
    {
      "x": -3,
      "y": 9,
      "z": 6,
      "name": "Empty"
    },
    {
      "x": -3,
      "y": 10,
      "z": 6,
      "name": "Empty"
    },
    {
      "x": -3,
      "y": 11,
      "z": 6,
      "name": "Rock_Stone"
    },
    {
      "x": -3,
      "y": 12,
      "z": 6,
      "name": "Rock_Stone"
    },
    {
      "x": -3,
      "y": -1,
      "z": 7,
      "name": "Rock_Stone"
    },
    {
      "x": -3,
      "y": 0,
      "z": 7,
      "name": "Rock_Stone"
    },
    {
      "x": -3,
      "y": 1,
      "z": 7,
      "name": "Rock_Stone"
    },
    {
      "x": -3,
      "y": 2,
      "z": 7,
      "name": "Rock_Stone"
    },
    {
      "x": -3,
      "y": 3,
      "z": 7,
      "name": "Rock_Stone"
    },
    {
      "x": -3,
      "y": 4,
      "z": 7,
      "name": "Rock_Stone_Cobble_Wall",
      "rotation": 1
    },
    {
      "x": -3,
      "y": 5,
      "z": 7,
      "name": "Empty"
    },
    {
      "x": -3,
      "y": 6,
      "z": 7,
      "name": "Empty"
    },
    {
      "x": -3,
      "y": 7,
      "z": 7,
      "name": "Empty"
    },
    {
      "x": -3,
      "y": 8,
      "z": 7,
      "name": "Empty"
    },
    {
      "x": -3,
      "y": 9,
      "z": 7,
      "name": "Empty"
    },
    {
      "x": -3,
      "y": 10,
      "z": 7,
      "name": "Empty"
    },
    {
      "x": -3,
      "y": 11,
      "z": 7,
      "name": "Empty"
    },
    {
      "x": -3,
      "y": 12,
      "z": 7,
      "name": "Rock_Stone"
    },
    {
      "x": -3,
      "y": -1,
      "z": 8,
      "name": "Rock_Stone"
    },
    {
      "x": -3,
      "y": 0,
      "z": 8,
      "name": "Rock_Stone"
    },
    {
      "x": -3,
      "y": 1,
      "z": 8,
      "name": "Rock_Stone"
    },
    {
      "x": -3,
      "y": 2,
      "z": 8,
      "name": "Rock_Stone"
    },
    {
      "x": -3,
      "y": 3,
      "z": 8,
      "name": "Rock_Stone"
    },
    {
      "x": -3,
      "y": 4,
      "z": 8,
      "name": "Wood_Softwood_Fence",
      "rotation": 1
    },
    {
      "x": -3,
      "y": 5,
      "z": 8,
      "name": "Empty"
    },
    {
      "x": -3,
      "y": 6,
      "z": 8,
      "name": "Empty"
    },
    {
      "x": -3,
      "y": 7,
      "z": 8,
      "name": "Empty"
    },
    {
      "x": -3,
      "y": 8,
      "z": 8,
      "name": "Empty"
    },
    {
      "x": -3,
      "y": 9,
      "z": 8,
      "name": "Empty"
    },
    {
      "x": -3,
      "y": 10,
      "z": 8,
      "name": "Empty"
    },
    {
      "x": -3,
      "y": 11,
      "z": 8,
      "name": "Empty"
    },
    {
      "x": -3,
      "y": 12,
      "z": 8,
      "name": "Rock_Stone"
    },
    {
      "x": -3,
      "y": -1,
      "z": 9,
      "name": "Rock_Stone"
    },
    {
      "x": -3,
      "y": 0,
      "z": 9,
      "name": "Rock_Stone"
    },
    {
      "x": -3,
      "y": 1,
      "z": 9,
      "name": "Rock_Stone"
    },
    {
      "x": -3,
      "y": 2,
      "z": 9,
      "name": "Rock_Stone"
    },
    {
      "x": -3,
      "y": 3,
      "z": 9,
      "name": "Soil_Gravel"
    },
    {
      "x": -3,
      "y": 4,
      "z": 9,
      "name": "Wood_Softwood_Fence",
      "rotation": 1
    },
    {
      "x": -3,
      "y": 5,
      "z": 9,
      "name": "Empty"
    },
    {
      "x": -3,
      "y": 6,
      "z": 9,
      "name": "Empty"
    },
    {
      "x": -3,
      "y": 7,
      "z": 9,
      "name": "Empty"
    },
    {
      "x": -3,
      "y": 8,
      "z": 9,
      "name": "Empty"
    },
    {
      "x": -3,
      "y": 9,
      "z": 9,
      "name": "Empty"
    },
    {
      "x": -3,
      "y": 10,
      "z": 9,
      "name": "Empty"
    },
    {
      "x": -3,
      "y": 11,
      "z": 9,
      "name": "Rock_Stone"
    },
    {
      "x": -3,
      "y": 12,
      "z": 9,
      "name": "Rock_Stone"
    },
    {
      "x": -3,
      "y": -1,
      "z": 10,
      "name": "Rock_Stone"
    },
    {
      "x": -3,
      "y": 0,
      "z": 10,
      "name": "Rock_Stone"
    },
    {
      "x": -3,
      "y": 1,
      "z": 10,
      "name": "Rock_Stone"
    },
    {
      "x": -3,
      "y": 2,
      "z": 10,
      "name": "Rock_Stone"
    },
    {
      "x": -3,
      "y": 3,
      "z": 10,
      "name": "Soil_Gravel"
    },
    {
      "x": -3,
      "y": 4,
      "z": 10,
      "name": "Empty"
    },
    {
      "x": -3,
      "y": 5,
      "z": 10,
      "name": "Empty"
    },
    {
      "x": -3,
      "y": 6,
      "z": 10,
      "name": "Empty"
    },
    {
      "x": -3,
      "y": 7,
      "z": 10,
      "name": "Empty"
    },
    {
      "x": -3,
      "y": 8,
      "z": 10,
      "name": "Empty"
    },
    {
      "x": -3,
      "y": 9,
      "z": 10,
      "name": "Empty"
    },
    {
      "x": -3,
      "y": 10,
      "z": 10,
      "name": "Empty"
    },
    {
      "x": -3,
      "y": 11,
      "z": 10,
      "name": "Rock_Stone"
    },
    {
      "x": -3,
      "y": 12,
      "z": 10,
      "name": "Rock_Stone"
    },
    {
      "x": -3,
      "y": -1,
      "z": 11,
      "name": "Rock_Stone"
    },
    {
      "x": -3,
      "y": 0,
      "z": 11,
      "name": "Rock_Stone"
    },
    {
      "x": -3,
      "y": 1,
      "z": 11,
      "name": "Rock_Stone"
    },
    {
      "x": -3,
      "y": 2,
      "z": 11,
      "name": "Rock_Stone"
    },
    {
      "x": -3,
      "y": 3,
      "z": 11,
      "name": "Rock_Stone"
    },
    {
      "x": -3,
      "y": 4,
      "z": 11,
      "name": "Empty"
    },
    {
      "x": -3,
      "y": 5,
      "z": 11,
      "name": "Empty"
    },
    {
      "x": -3,
      "y": 6,
      "z": 11,
      "name": "Empty"
    },
    {
      "x": -3,
      "y": 7,
      "z": 11,
      "name": "Empty"
    },
    {
      "x": -3,
      "y": 8,
      "z": 11,
      "name": "Empty"
    },
    {
      "x": -3,
      "y": 9,
      "z": 11,
      "name": "Empty"
    },
    {
      "x": -3,
      "y": 10,
      "z": 11,
      "name": "Empty"
    },
    {
      "x": -3,
      "y": 11,
      "z": 11,
      "name": "Rock_Stone"
    },
    {
      "x": -3,
      "y": 12,
      "z": 11,
      "name": "Rock_Stone"
    },
    {
      "x": -3,
      "y": -1,
      "z": 12,
      "name": "Rock_Stone"
    },
    {
      "x": -3,
      "y": 0,
      "z": 12,
      "name": "Rock_Stone"
    },
    {
      "x": -3,
      "y": 1,
      "z": 12,
      "name": "Rock_Stone"
    },
    {
      "x": -3,
      "y": 2,
      "z": 12,
      "name": "Rock_Stone"
    },
    {
      "x": -3,
      "y": 3,
      "z": 12,
      "name": "Rock_Stone"
    },
    {
      "x": -3,
      "y": 4,
      "z": 12,
      "name": "Rock_Stone_Cobble"
    },
    {
      "x": -3,
      "y": 5,
      "z": 12,
      "name": "Empty"
    },
    {
      "x": -3,
      "y": 6,
      "z": 12,
      "name": "Empty"
    },
    {
      "x": -3,
      "y": 7,
      "z": 12,
      "name": "Empty"
    },
    {
      "x": -3,
      "y": 8,
      "z": 12,
      "name": "Empty"
    },
    {
      "x": -3,
      "y": 9,
      "z": 12,
      "name": "Empty"
    },
    {
      "x": -3,
      "y": 10,
      "z": 12,
      "name": "Empty"
    },
    {
      "x": -3,
      "y": 11,
      "z": 12,
      "name": "Rock_Stone"
    },
    {
      "x": -3,
      "y": 12,
      "z": 12,
      "name": "Rock_Stone"
    },
    {
      "x": -3,
      "y": -1,
      "z": 13,
      "name": "Rock_Stone"
    },
    {
      "x": -3,
      "y": 0,
      "z": 13,
      "name": "Rock_Stone"
    },
    {
      "x": -3,
      "y": 1,
      "z": 13,
      "name": "Rock_Stone"
    },
    {
      "x": -3,
      "y": 2,
      "z": 13,
      "name": "Rock_Stone"
    },
    {
      "x": -3,
      "y": 3,
      "z": 13,
      "name": "Rock_Stone"
    },
    {
      "x": -3,
      "y": 4,
      "z": 13,
      "name": "Rock_Stone_Cobble"
    },
    {
      "x": -3,
      "y": 5,
      "z": 13,
      "name": "Rock_Stone_Cobble"
    },
    {
      "x": -3,
      "y": 6,
      "z": 13,
      "name": "Plant_Moss_Rug_Yellow"
    },
    {
      "x": -3,
      "y": 7,
      "z": 13,
      "name": "Empty"
    },
    {
      "x": -3,
      "y": 8,
      "z": 13,
      "name": "Empty"
    },
    {
      "x": -3,
      "y": 9,
      "z": 13,
      "name": "Empty"
    },
    {
      "x": -3,
      "y": 10,
      "z": 13,
      "name": "Rock_Stone"
    },
    {
      "x": -3,
      "y": 11,
      "z": 13,
      "name": "Rock_Stone"
    },
    {
      "x": -3,
      "y": 12,
      "z": 13,
      "name": "Rock_Stone"
    },
    {
      "x": -3,
      "y": -1,
      "z": 14,
      "name": "Rock_Stone"
    },
    {
      "x": -3,
      "y": 0,
      "z": 14,
      "name": "Rock_Stone"
    },
    {
      "x": -3,
      "y": 1,
      "z": 14,
      "name": "Rock_Stone"
    },
    {
      "x": -3,
      "y": 2,
      "z": 14,
      "name": "Rock_Stone"
    },
    {
      "x": -3,
      "y": 3,
      "z": 14,
      "name": "Rock_Stone"
    },
    {
      "x": -3,
      "y": 4,
      "z": 14,
      "name": "Empty"
    },
    {
      "x": -3,
      "y": 5,
      "z": 14,
      "name": "Empty"
    },
    {
      "x": -3,
      "y": 6,
      "z": 14,
      "name": "Empty"
    },
    {
      "x": -3,
      "y": 7,
      "z": 14,
      "name": "Empty"
    },
    {
      "x": -3,
      "y": 8,
      "z": 14,
      "name": "Empty"
    },
    {
      "x": -3,
      "y": 9,
      "z": 14,
      "name": "Rock_Stone"
    },
    {
      "x": -3,
      "y": 10,
      "z": 14,
      "name": "Rock_Stone"
    },
    {
      "x": -3,
      "y": 11,
      "z": 14,
      "name": "Rock_Stone"
    },
    {
      "x": -3,
      "y": 12,
      "z": 14,
      "name": "Rock_Stone"
    },
    {
      "x": -2,
      "y": -1,
      "z": 0,
      "name": "Rock_Stone"
    },
    {
      "x": -2,
      "y": 0,
      "z": 0,
      "name": "Rock_Stone"
    },
    {
      "x": -2,
      "y": 1,
      "z": 0,
      "name": "Empty"
    },
    {
      "x": -2,
      "y": 2,
      "z": 0,
      "name": "Empty"
    },
    {
      "x": -2,
      "y": 3,
      "z": 0,
      "name": "Empty"
    },
    {
      "x": -2,
      "y": 4,
      "z": 0,
      "name": "Empty"
    },
    {
      "x": -2,
      "y": 5,
      "z": 0,
      "name": "Empty"
    },
    {
      "x": -2,
      "y": 6,
      "z": 0,
      "name": "Empty"
    },
    {
      "x": -2,
      "y": 7,
      "z": 0,
      "name": "Rock_Stone"
    },
    {
      "x": -2,
      "y": 8,
      "z": 0,
      "name": "Rock_Stone"
    },
    {
      "x": -2,
      "y": 9,
      "z": 0,
      "name": "Rock_Stone"
    },
    {
      "x": -2,
      "y": 10,
      "z": 0,
      "name": "Rock_Stone"
    },
    {
      "x": -2,
      "y": 11,
      "z": 0,
      "name": "Rock_Stone"
    },
    {
      "x": -2,
      "y": 12,
      "z": 0,
      "name": "Rock_Stone"
    },
    {
      "x": -2,
      "y": -1,
      "z": 1,
      "name": "Rock_Stone"
    },
    {
      "x": -2,
      "y": 0,
      "z": 1,
      "name": "Rock_Stone"
    },
    {
      "x": -2,
      "y": 1,
      "z": 1,
      "name": "Rock_Stone_Cobble"
    },
    {
      "x": -2,
      "y": 2,
      "z": 1,
      "name": "Rock_Stone_Brick"
    },
    {
      "x": -2,
      "y": 3,
      "z": 1,
      "name": "Wood_Softwood_Fence",
      "rotation": 2
    },
    {
      "x": -2,
      "y": 4,
      "z": 1,
      "name": "Empty"
    },
    {
      "x": -2,
      "y": 5,
      "z": 1,
      "name": "Empty"
    },
    {
      "x": -2,
      "y": 6,
      "z": 1,
      "name": "Empty"
    },
    {
      "x": -2,
      "y": 7,
      "z": 1,
      "name": "Wood_Beech_Trunk",
      "rotation": 5
    },
    {
      "x": -2,
      "y": 8,
      "z": 1,
      "name": "Rock_Stone"
    },
    {
      "x": -2,
      "y": 9,
      "z": 1,
      "name": "Rock_Stone"
    },
    {
      "x": -2,
      "y": 10,
      "z": 1,
      "name": "Rock_Stone"
    },
    {
      "x": -2,
      "y": 11,
      "z": 1,
      "name": "Rock_Stone"
    },
    {
      "x": -2,
      "y": 12,
      "z": 1,
      "name": "Rock_Stone"
    },
    {
      "x": -2,
      "y": -1,
      "z": 2,
      "name": "Rock_Stone"
    },
    {
      "x": -2,
      "y": 0,
      "z": 2,
      "name": "Rock_Stone"
    },
    {
      "x": -2,
      "y": 1,
      "z": 2,
      "name": "Rock_Stone_Cobble"
    },
    {
      "x": -2,
      "y": 2,
      "z": 2,
      "name": "Rock_Stone_Cobble"
    },
    {
      "x": -2,
      "y": 3,
      "z": 2,
      "name": "Empty"
    },
    {
      "x": -2,
      "y": 4,
      "z": 2,
      "name": "Empty"
    },
    {
      "x": -2,
      "y": 5,
      "z": 2,
      "name": "Empty"
    },
    {
      "x": -2,
      "y": 6,
      "z": 2,
      "name": "Empty"
    },
    {
      "x": -2,
      "y": 7,
      "z": 2,
      "name": "Empty"
    },
    {
      "x": -2,
      "y": 8,
      "z": 2,
      "name": "Rock_Stone"
    },
    {
      "x": -2,
      "y": 9,
      "z": 2,
      "name": "Rock_Stone"
    },
    {
      "x": -2,
      "y": 10,
      "z": 2,
      "name": "Rock_Stone"
    },
    {
      "x": -2,
      "y": 11,
      "z": 2,
      "name": "Rock_Stone"
    },
    {
      "x": -2,
      "y": 12,
      "z": 2,
      "name": "Rock_Stone"
    },
    {
      "x": -2,
      "y": -1,
      "z": 3,
      "name": "Rock_Stone"
    },
    {
      "x": -2,
      "y": 0,
      "z": 3,
      "name": "Rock_Stone"
    },
    {
      "x": -2,
      "y": 1,
      "z": 3,
      "name": "Deco_Bone_Skulls"
    },
    {
      "x": -2,
      "y": 2,
      "z": 3,
      "name": "Empty"
    },
    {
      "x": -2,
      "y": 3,
      "z": 3,
      "name": "Empty"
    },
    {
      "x": -2,
      "y": 4,
      "z": 3,
      "name": "Empty"
    },
    {
      "x": -2,
      "y": 5,
      "z": 3,
      "name": "Empty"
    },
    {
      "x": -2,
      "y": 6,
      "z": 3,
      "name": "Empty"
    },
    {
      "x": -2,
      "y": 7,
      "z": 3,
      "name": "Rock_Stone_Stalactite_Large",
      "filler": 31744,
      "rotation": 8
    },
    {
      "x": -2,
      "y": 8,
      "z": 3,
      "name": "Rock_Stone_Stalactite_Large",
      "rotation": 8
    },
    {
      "x": -2,
      "y": 9,
      "z": 3,
      "name": "Rock_Stone"
    },
    {
      "x": -2,
      "y": 10,
      "z": 3,
      "name": "Rock_Stone"
    },
    {
      "x": -2,
      "y": 11,
      "z": 3,
      "name": "Rock_Stone"
    },
    {
      "x": -2,
      "y": 12,
      "z": 3,
      "name": "Rock_Stone"
    },
    {
      "x": -2,
      "y": -1,
      "z": 4,
      "name": "Rock_Stone"
    },
    {
      "x": -2,
      "y": 0,
      "z": 4,
      "name": "Rock_Stone"
    },
    {
      "x": -2,
      "y": 1,
      "z": 4,
      "name": "Rock_Stone"
    },
    {
      "x": -2,
      "y": 2,
      "z": 4,
      "name": "Rock_Stone"
    },
    {
      "x": -2,
      "y": 3,
      "z": 4,
      "name": "Rock_Stone"
    },
    {
      "x": -2,
      "y": 4,
      "z": 4,
      "name": "Empty"
    },
    {
      "x": -2,
      "y": 5,
      "z": 4,
      "name": "Empty"
    },
    {
      "x": -2,
      "y": 6,
      "z": 4,
      "name": "Empty"
    },
    {
      "x": -2,
      "y": 7,
      "z": 4,
      "name": "Empty"
    },
    {
      "x": -2,
      "y": 8,
      "z": 4,
      "name": "Empty"
    },
    {
      "x": -2,
      "y": 9,
      "z": 4,
      "name": "Empty"
    },
    {
      "x": -2,
      "y": 10,
      "z": 4,
      "name": "Empty"
    },
    {
      "x": -2,
      "y": 11,
      "z": 4,
      "name": "Rock_Stone"
    },
    {
      "x": -2,
      "y": 12,
      "z": 4,
      "name": "Rock_Stone"
    },
    {
      "x": -2,
      "y": -1,
      "z": 5,
      "name": "Rock_Stone"
    },
    {
      "x": -2,
      "y": 0,
      "z": 5,
      "name": "Rock_Stone"
    },
    {
      "x": -2,
      "y": 1,
      "z": 5,
      "name": "Rock_Stone"
    },
    {
      "x": -2,
      "y": 2,
      "z": 5,
      "name": "Rock_Stone"
    },
    {
      "x": -2,
      "y": 3,
      "z": 5,
      "name": "Rock_Stone"
    },
    {
      "x": -2,
      "y": 4,
      "z": 5,
      "name": "*Rail_State_Definitions_Corner_Left",
      "rotation": 1
    },
    {
      "x": -2,
      "y": 5,
      "z": 5,
      "name": "Empty"
    },
    {
      "x": -2,
      "y": 6,
      "z": 5,
      "name": "Empty"
    },
    {
      "x": -2,
      "y": 7,
      "z": 5,
      "name": "Empty"
    },
    {
      "x": -2,
      "y": 8,
      "z": 5,
      "name": "Empty"
    },
    {
      "x": -2,
      "y": 9,
      "z": 5,
      "name": "Empty"
    },
    {
      "x": -2,
      "y": 10,
      "z": 5,
      "name": "Empty"
    },
    {
      "x": -2,
      "y": 11,
      "z": 5,
      "name": "Empty"
    },
    {
      "x": -2,
      "y": 12,
      "z": 5,
      "name": "Rock_Stone"
    },
    {
      "x": -2,
      "y": -1,
      "z": 6,
      "name": "Rock_Stone"
    },
    {
      "x": -2,
      "y": 0,
      "z": 6,
      "name": "Rock_Stone"
    },
    {
      "x": -2,
      "y": 1,
      "z": 6,
      "name": "Rock_Stone"
    },
    {
      "x": -2,
      "y": 2,
      "z": 6,
      "name": "Rock_Stone"
    },
    {
      "x": -2,
      "y": 3,
      "z": 6,
      "name": "Rock_Stone"
    },
    {
      "x": -2,
      "y": 4,
      "z": 6,
      "name": "Rail"
    },
    {
      "x": -2,
      "y": 5,
      "z": 6,
      "name": "Empty"
    },
    {
      "x": -2,
      "y": 6,
      "z": 6,
      "name": "Empty"
    },
    {
      "x": -2,
      "y": 7,
      "z": 6,
      "name": "Empty"
    },
    {
      "x": -2,
      "y": 8,
      "z": 6,
      "name": "Empty"
    },
    {
      "x": -2,
      "y": 9,
      "z": 6,
      "name": "Empty"
    },
    {
      "x": -2,
      "y": 10,
      "z": 6,
      "name": "Empty"
    },
    {
      "x": -2,
      "y": 11,
      "z": 6,
      "name": "Empty"
    },
    {
      "x": -2,
      "y": 12,
      "z": 6,
      "name": "Rock_Stone"
    },
    {
      "x": -2,
      "y": -1,
      "z": 7,
      "name": "Rock_Stone"
    },
    {
      "x": -2,
      "y": 0,
      "z": 7,
      "name": "Rock_Stone"
    },
    {
      "x": -2,
      "y": 1,
      "z": 7,
      "name": "Rock_Stone"
    },
    {
      "x": -2,
      "y": 2,
      "z": 7,
      "name": "Rock_Stone"
    },
    {
      "x": -2,
      "y": 3,
      "z": 7,
      "name": "Rock_Stone"
    },
    {
      "x": -2,
      "y": 4,
      "z": 7,
      "name": "Rail"
    },
    {
      "x": -2,
      "y": 5,
      "z": 7,
      "name": "Empty"
    },
    {
      "x": -2,
      "y": 6,
      "z": 7,
      "name": "Empty"
    },
    {
      "x": -2,
      "y": 7,
      "z": 7,
      "name": "Empty"
    },
    {
      "x": -2,
      "y": 8,
      "z": 7,
      "name": "Empty"
    },
    {
      "x": -2,
      "y": 9,
      "z": 7,
      "name": "Empty"
    },
    {
      "x": -2,
      "y": 10,
      "z": 7,
      "name": "Empty"
    },
    {
      "x": -2,
      "y": 11,
      "z": 7,
      "name": "Empty"
    },
    {
      "x": -2,
      "y": 12,
      "z": 7,
      "name": "Rock_Stone"
    },
    {
      "x": -2,
      "y": -1,
      "z": 8,
      "name": "Rock_Stone"
    },
    {
      "x": -2,
      "y": 0,
      "z": 8,
      "name": "Rock_Stone"
    },
    {
      "x": -2,
      "y": 1,
      "z": 8,
      "name": "Rock_Stone"
    },
    {
      "x": -2,
      "y": 2,
      "z": 8,
      "name": "Rock_Stone"
    },
    {
      "x": -2,
      "y": 3,
      "z": 8,
      "name": "Soil_Gravel"
    },
    {
      "x": -2,
      "y": 4,
      "z": 8,
      "name": "Rail"
    },
    {
      "x": -2,
      "y": 5,
      "z": 8,
      "name": "Empty"
    },
    {
      "x": -2,
      "y": 6,
      "z": 8,
      "name": "Empty"
    },
    {
      "x": -2,
      "y": 7,
      "z": 8,
      "name": "Empty"
    },
    {
      "x": -2,
      "y": 8,
      "z": 8,
      "name": "Empty"
    },
    {
      "x": -2,
      "y": 9,
      "z": 8,
      "name": "Empty"
    },
    {
      "x": -2,
      "y": 10,
      "z": 8,
      "name": "Empty"
    },
    {
      "x": -2,
      "y": 11,
      "z": 8,
      "name": "Empty"
    },
    {
      "x": -2,
      "y": 12,
      "z": 8,
      "name": "Rock_Stone"
    },
    {
      "x": -2,
      "y": -1,
      "z": 9,
      "name": "Rock_Stone"
    },
    {
      "x": -2,
      "y": 0,
      "z": 9,
      "name": "Rock_Stone"
    },
    {
      "x": -2,
      "y": 1,
      "z": 9,
      "name": "Rock_Stone"
    },
    {
      "x": -2,
      "y": 2,
      "z": 9,
      "name": "Rock_Stone"
    },
    {
      "x": -2,
      "y": 3,
      "z": 9,
      "name": "Soil_Gravel"
    },
    {
      "x": -2,
      "y": 4,
      "z": 9,
      "name": "*Rail_State_Definitions_T",
      "rotation": 1
    },
    {
      "x": -2,
      "y": 5,
      "z": 9,
      "name": "Empty"
    },
    {
      "x": -2,
      "y": 6,
      "z": 9,
      "name": "Empty"
    },
    {
      "x": -2,
      "y": 7,
      "z": 9,
      "name": "Empty"
    },
    {
      "x": -2,
      "y": 8,
      "z": 9,
      "name": "Empty"
    },
    {
      "x": -2,
      "y": 9,
      "z": 9,
      "name": "Empty"
    },
    {
      "x": -2,
      "y": 10,
      "z": 9,
      "name": "Empty"
    },
    {
      "x": -2,
      "y": 11,
      "z": 9,
      "name": "Empty"
    },
    {
      "x": -2,
      "y": 12,
      "z": 9,
      "name": "Rock_Stone"
    },
    {
      "x": -2,
      "y": -1,
      "z": 10,
      "name": "Rock_Stone"
    },
    {
      "x": -2,
      "y": 0,
      "z": 10,
      "name": "Rock_Stone"
    },
    {
      "x": -2,
      "y": 1,
      "z": 10,
      "name": "Rock_Stone"
    },
    {
      "x": -2,
      "y": 2,
      "z": 10,
      "name": "Rock_Stone"
    },
    {
      "x": -2,
      "y": 3,
      "z": 10,
      "name": "Soil_Gravel"
    },
    {
      "x": -2,
      "y": 4,
      "z": 10,
      "name": "Rail"
    },
    {
      "x": -2,
      "y": 5,
      "z": 10,
      "name": "Empty"
    },
    {
      "x": -2,
      "y": 6,
      "z": 10,
      "name": "Empty"
    },
    {
