{
  "version": 8,
  "blockIdVersion": 8,
  "anchorX": 0,
  "anchorY": 2,
  "anchorZ": 1,
  "blocks": [
    {
      "x": -1,
      "y": 7,
      "z": 0,
      "name": "Plant_Leaves_Aspen"
    },
    {
      "x": -1,
      "y": 9,
      "z": 0,
      "name": "Plant_Leaves_Aspen"
    },
    {
      "x": -1,
      "y": 7,
      "z": 1,
      "name": "Plant_Leaves_Aspen"
    },
    {
      "x": -1,
      "y": 8,
      "z": 1,
      "name": "Plant_Leaves_Aspen"
    },
    {
      "x": -1,
      "y": 9,
      "z": 1,
      "name": "Plant_Leaves_Aspen"
    },
    {
      "x": -1,
      "y": 10,
      "z": 1,
      "name": "Plant_Leaves_Aspen"
    },
    {
      "x": -1,
      "y": 11,
      "z": 1,
      "name": "Plant_Leaves_Aspen"
    },
    {
      "x": -1,
      "y": 7,
      "z": 2,
      "name": "Plant_Leaves_Aspen"
    },
    {
      "x": -1,
      "y": 9,
      "z": 2,
      "name": "Plant_Leaves_Aspen"
    },
    {
      "x": -1,
      "y": 10,
      "z": 2,
      "name": "Plant_Leaves_Aspen"
    },
    {
      "x": 0,
      "y": 8,
      "z": 0,
      "name": "Plant_Leaves_Aspen"
    },
    {
      "x": 0,
      "y": 9,
      "z": 0,
      "name": "Plant_Leaves_Aspen"
    },
    {
      "x": 0,
      "y": 10,
      "z": 0,
      "name": "Plant_Leaves_Aspen"
    },
    {
      "x": 0,
      "y": 2,
      "z": 1,
      "name": "Wood_Aspen_Branch_Long"
    },
    {
      "x": 0,
      "y": 3,
      "z": 1,
      "name": "Wood_Aspen_Branch_Long"
    },
    {
      "x": 0,
      "y": 4,
      "z": 1,
      "name": "Wood_Aspen_Branch_Long"
    },
    {
      "x": 0,
      "y": 5,
      "z": 1,
      "name": "Wood_Aspen_Branch_Long"
    },
    {
      "x": 0,
      "y": 6,
      "z": 1,
      "name": "Wood_Aspen_Branch_Long"
    },
    {
      "x": 0,
      "y": 7,
      "z": 1,
      "name": "Wood_Aspen_Branch_Long"
    },
    {
      "x": 0,
      "y": 8,
      "z": 1,
      "name": "Wood_Aspen_Branch_Long"
    },
    {
      "x": 0,
      "y": 9,
      "z": 1,
      "name": "Wood_Aspen_Branch_Long"
    },
    {
      "x": 0,
      "y": 10,
      "z": 1,
      "name": "Plant_Leaves_Aspen"
    },
    {
      "x": 0,
      "y": 11,
      "z": 1,
      "name": "Plant_Leaves_Aspen"
    },
    {
      "x": 0,
      "y": 12,
      "z": 1,
      "name": "Plant_Leaves_Aspen"
    },
    {
      "x": 0,
      "y": 6,
      "z": 2,
      "name": "Plant_Leaves_Aspen"
    },
    {
      "x": 0,
      "y": 7,
      "z": 2,
      "name": "Plant_Leaves_Aspen"
    },
    {
      "x": 0,
      "y": 8,
      "z": 2,
      "name": "Plant_Leaves_Aspen"
    },
    {
      "x": 0,
      "y": 9,
      "z": 2,
      "name": "Plant_Leaves_Aspen"
    },
    {
      "x": 0,
      "y": 10,
      "z": 2,
      "name": "Plant_Leaves_Aspen"
    },
    {
      "x": 0,
      "y": 11,
      "z": 2,
      "name": "Plant_Leaves_Aspen"
    },
    {
      "x": 1,
      "y": 7,
      "z": 0,
      "name": "Plant_Leaves_Aspen"
    },
    {
      "x": 1,
      "y": 9,
      "z": 0,
      "name": "Plant_Leaves_Aspen"
    },
    {
      "x": 1,
      "y": 6,
      "z": 1,
      "name": "Plant_Leaves_Aspen"
    },
    {
      "x": 1,
      "y": 7,
      "z": 1,
      "name": "Plant_Leaves_Aspen"
    },
    {
      "x": 1,
      "y": 8,
      "z": 1,
      "name": "Plant_Leaves_Aspen"
    },
    {
      "x": 1,
      "y": 9,
      "z": 1,
      "name": "Plant_Leaves_Aspen"
    },
    {
      "x": 1,
      "y": 10,
      "z": 1,
      "name": "Plant_Leaves_Aspen"
    },
    {
      "x": 1,
      "y": 8,
      "z": 2,
      "name": "Plant_Leaves_Aspen"
    }
  ]
}