{
  "version": 8,
  "blockIdVersion": 8,
  "anchorX": 1,
  "anchorY": 6,
  "anchorZ": -2,
  "blocks": [
    {
      "x": -3,
      "y": 0,
      "z": -1,
      "name": "Rock_Basalt_Brick"
    },
    {
      "x": -3,
      "y": 1,
      "z": -1,
      "name": "Rock_Basalt_Brick"
    },
    {
      "x": -3,
      "y": 2,
      "z": -1,
      "name": "Rock_Basalt_Brick"
    },
    {
      "x": -3,
      "y": 3,
      "z": -1,
      "name": "Rock_Basalt_Brick"
    },
    {
      "x": -3,
      "y": 4,
      "z": -1,
      "name": "Rock_Basalt_Brick"
    },
    {
      "x": -3,
      "y": 5,
      "z": -1,
      "name": "Rock_Basalt_Cobble"
    },
    {
      "x": -3,
      "y": 6,
      "z": -1,
      "name": "Rock_Basalt_Cobble"
    },
    {
      "x": -3,
      "y": 7,
      "z": -1,
      "name": "Rock_Basalt_Cobble"
    },
    {
      "x": -3,
      "y": 8,
      "z": -1,
      "name": "Rock_Basalt_Cobble"
    },
    {
      "x": -3,
      "y": 9,
      "z": -1,
      "name": "Rock_Basalt_Cobble"
    },
    {
      "x": -3,
      "y": 0,
      "z": 0,
      "name": "Rock_Basalt_Brick"
    },
    {
      "x": -3,
      "y": 1,
      "z": 0,
      "name": "Rock_Basalt_Cobble"
    },
    {
      "x": -3,
      "y": 2,
      "z": 0,
      "name": "Rock_Basalt_Cobble"
    },
    {
      "x": -3,
      "y": 3,
      "z": 0,
      "name": "Rock_Basalt_Cobble"
    },
    {
      "x": -3,
      "y": 4,
      "z": 0,
      "name": "Rock_Basalt_Cobble"
    },
    {
      "x": -3,
      "y": 5,
      "z": 0,
      "name": "Rock_Basalt_Cobble"
    },
    {
      "x": -3,
      "y": 6,
      "z": 0,
      "name": "Rock_Basalt_Cobble"
    },
    {
      "x": -3,
      "y": 7,
      "z": 0,
      "name": "Rock_Basalt_Cobble"
    },
    {
      "x": -3,
      "y": 8,
      "z": 0,
      "name": "Rock_Basalt_Cobble"
    },
    {
      "x": -3,
      "y": 9,
      "z": 0,
      "name": "Rock_Basalt_Cobble"
    },
    {
      "x": -3,
      "y": 0,
      "z": 1,
      "name": "Rock_Basalt_Brick"
    },
    {
      "x": -3,
      "y": 1,
      "z": 1,
      "name": "Rock_Basalt_Cobble"
    },
    {
      "x": -3,
      "y": 2,
      "z": 1,
      "name": "Rock_Basalt_Cobble"
    },
    {
      "x": -3,
      "y": 3,
      "z": 1,
      "name": "Rock_Basalt_Cobble"
    },
    {
      "x": -3,
      "y": 4,
      "z": 1,
      "name": "Rock_Basalt_Cobble"
    },
    {
      "x": -3,
      "y": 5,
      "z": 1,
      "name": "Rock_Basalt_Cobble"
    },
    {
      "x": -3,
      "y": 6,
      "z": 1,
      "name": "Rock_Basalt_Cobble"
    },
    {
      "x": -3,
      "y": 7,
      "z": 1,
      "name": "Rock_Basalt_Cobble"
    },
    {
      "x": -3,
      "y": 8,
      "z": 1,
      "name": "Rock_Basalt_Cobble"
    },
    {
      "x": -3,
      "y": 9,
      "z": 1,
      "name": "Rock_Basalt_Cobble"
    },
    {
      "x": -3,
      "y": 0,
      "z": 2,
      "name": "Rock_Basalt_Brick"
    },
    {
      "x": -3,
      "y": 1,
      "z": 2,
      "name": "Rock_Basalt_Cobble"
    },
    {
      "x": -3,
      "y": 2,
      "z": 2,
      "name": "Rock_Basalt_Cobble"
    },
    {
      "x": -3,
      "y": 3,
      "z": 2,
      "name": "Rock_Basalt_Cobble"
    },
    {
      "x": -3,
      "y": 4,
      "z": 2,
      "name": "Rock_Basalt_Cobble"
    },
    {
      "x": -3,
      "y": 5,
      "z": 2,
      "name": "Rock_Basalt_Cobble"
    },
    {
      "x": -3,
      "y": 6,
      "z": 2,
      "name": "Rock_Basalt_Cobble"
    },
    {
      "x": -3,
      "y": 7,
      "z": 2,
      "name": "Rock_Basalt_Cobble"
    },
    {
      "x": -3,
      "y": 8,
      "z": 2,
      "name": "Rock_Basalt_Cobble"
    },
    {
      "x": -3,
      "y": 9,
      "z": 2,
      "name": "Rock_Basalt_Cobble"
    },
    {
      "x": -3,
      "y": 0,
      "z": 3,
      "name": "Rock_Basalt_Brick"
    },
    {
      "x": -3,
      "y": 1,
      "z": 3,
      "name": "Rock_Basalt_Cobble"
    },
    {
      "x": -3,
      "y": 2,
      "z": 3,
      "name": "Rock_Basalt_Cobble"
    },
    {
      "x": -3,
      "y": 3,
      "z": 3,
      "name": "Rock_Basalt_Cobble"
    },
    {
      "x": -3,
      "y": 4,
      "z": 3,
      "name": "Rock_Basalt_Cobble"
    },
    {
      "x": -3,
      "y": 5,
      "z": 3,
      "name": "Rock_Basalt_Cobble"
    },
    {
      "x": -3,
      "y": 6,
      "z": 3,
      "name": "Rock_Basalt_Cobble"
    },
    {
      "x": -3,
      "y": 7,
      "z": 3,
      "name": "Rock_Basalt_Cobble"
    },
    {
      "x": -3,
      "y": 8,
      "z": 3,
      "name": "Rock_Basalt_Cobble"
    },
    {
      "x": -3,
      "y": 9,
      "z": 3,
      "name": "Rock_Basalt_Brick"
    },
    {
      "x": -3,
      "y": 0,
      "z": 4,
      "name": "Rock_Basalt_Cobble"
    },
    {
      "x": -3,
      "y": 1,
      "z": 4,
      "name": "Rock_Basalt_Cobble"
    },
    {
      "x": -3,
      "y": 2,
      "z": 4,
      "name": "Rock_Basalt_Cobble"
    },
    {
      "x": -3,
      "y": 3,
      "z": 4,
      "name": "Rock_Basalt_Cobble"
    },
    {
      "x": -3,
      "y": 4,
      "z": 4,
      "name": "Rock_Basalt_Cobble"
    },
    {
      "x": -3,
      "y": 5,
      "z": 4,
      "name": "Rock_Basalt_Cobble"
    },
    {
      "x": -3,
      "y": 6,
      "z": 4,
      "name": "Rock_Basalt_Cobble"
    },
    {
      "x": -3,
      "y": 7,
      "z": 4,
      "name": "Rock_Basalt_Cobble"
    },
    {
      "x": -3,
      "y": 8,
      "z": 4,
      "name": "Rock_Basalt_Cobble"
    },
    {
      "x": -3,
      "y": 9,
      "z": 4,
      "name": "Rock_Basalt_Brick"
    },
    {
      "x": -3,
      "y": 0,
      "z": 5,
      "name": "Rock_Basalt_Cobble"
    },
    {
      "x": -3,
      "y": 1,
      "z": 5,
      "name": "Rock_Basalt_Cobble"
    },
    {
      "x": -3,
      "y": 2,
      "z": 5,
      "name": "Rock_Basalt_Cobble"
    },
    {
      "x": -3,
      "y": 3,
      "z": 5,
      "name": "Rock_Basalt_Cobble"
    },
    {
      "x": -3,
      "y": 4,
      "z": 5,
      "name": "Rock_Basalt_Cobble"
    },
    {
      "x": -3,
      "y": 5,
      "z": 5,
      "name": "Rock_Basalt_Cobble"
    },
    {
      "x": -3,
      "y": 6,
      "z": 5,
      "name": "Rock_Basalt_Cobble"
    },
    {
      "x": -3,
      "y": 7,
      "z": 5,
      "name": "Rock_Basalt_Cobble"
    },
    {
      "x": -3,
      "y": 8,
      "z": 5,
      "name": "Rock_Basalt_Cobble"
    },
    {
      "x": -3,
      "y": 9,
      "z": 5,
      "name": "Rock_Basalt_Cobble"
    },
    {
      "x": -3,
      "y": 0,
      "z": 6,
      "name": "Rock_Basalt_Cobble"
    },
    {
      "x": -3,
      "y": 1,
      "z": 6,
      "name": "Rock_Basalt_Cobble"
    },
    {
      "x": -3,
      "y": 2,
      "z": 6,
      "name": "Rock_Basalt_Cobble"
    },
    {
      "x": -3,
      "y": 3,
      "z": 6,
      "name": "Rock_Basalt_Cobble"
    },
    {
      "x": -3,
      "y": 4,
      "z": 6,
      "name": "Rock_Basalt_Cobble"
    },
    {
      "x": -3,
      "y": 5,
      "z": 6,
      "name": "Rock_Basalt_Cobble"
    },
    {
      "x": -3,
      "y": 6,
      "z": 6,
      "name": "Rock_Basalt_Cobble"
    },
    {
      "x": -3,
      "y": 7,
      "z": 6,
      "name": "Rock_Basalt_Cobble"
    },
    {
      "x": -3,
      "y": 8,
      "z": 6,
      "name": "Rock_Basalt_Cobble"
    },
    {
      "x": -3,
      "y": 9,
      "z": 6,
      "name": "Rock_Basalt_Cobble"
    },
    {
      "x": -3,
      "y": 0,
      "z": 7,
      "name": "Rock_Basalt_Cobble"
    },
    {
      "x": -3,
      "y": 1,
      "z": 7,
      "name": "Rock_Basalt_Cobble"
    },
    {
      "x": -3,
      "y": 2,
      "z": 7,
      "name": "Rock_Basalt_Cobble"
    },
    {
      "x": -3,
      "y": 3,
      "z": 7,
      "name": "Rock_Basalt_Cobble"
    },
    {
      "x": -3,
      "y": 4,
      "z": 7,
      "name": "Rock_Basalt_Cobble"
    },
    {
      "x": -3,
      "y": 5,
      "z": 7,
      "name": "Rock_Basalt_Cobble"
    },
    {
      "x": -3,
      "y": 6,
      "z": 7,
      "name": "Rock_Basalt_Cobble"
    },
    {
      "x": -3,
      "y": 7,
      "z": 7,
      "name": "Rock_Basalt_Cobble"
    },
    {
      "x": -3,
      "y": 8,
      "z": 7,
      "name": "Rock_Basalt_Cobble"
    },
    {
      "x": -3,
      "y": 9,
      "z": 7,
      "name": "Rock_Basalt_Cobble"
    },
    {
      "x": -3,
      "y": 0,
      "z": 8,
      "name": "Rock_Basalt_Cobble"
    },
    {
      "x": -3,
      "y": 1,
      "z": 8,
      "name": "Rock_Basalt_Cobble"
    },
    {
      "x": -3,
      "y": 2,
      "z": 8,
      "name": "Rock_Basalt_Cobble"
    },
    {
      "x": -3,
      "y": 3,
      "z": 8,
      "name": "Rock_Basalt_Cobble"
    },
    {
      "x": -3,
      "y": 4,
      "z": 8,
      "name": "Rock_Basalt_Cobble"
    },
    {
      "x": -3,
      "y": 5,
      "z": 8,
      "name": "Rock_Basalt_Cobble"
    },
    {
      "x": -3,
      "y": 6,
      "z": 8,
      "name": "Rock_Basalt_Cobble"
    },
    {
      "x": -3,
      "y": 7,
      "z": 8,
      "name": "Rock_Basalt_Cobble"
    },
    {
      "x": -3,
      "y": 8,
      "z": 8,
      "name": "Rock_Basalt_Cobble"
    },
    {
      "x": -3,
      "y": 9,
      "z": 8,
      "name": "Rock_Basalt_Cobble"
    },
    {
      "x": -2,
      "y": 0,
      "z": -1,
      "name": "Rock_Basalt_Brick"
    },
    {
      "x": -2,
      "y": 1,
      "z": -1,
      "name": "Rock_Basalt_Brick"
    },
    {
      "x": -2,
      "y": 2,
      "z": -1,
      "name": "Rock_Basalt_Brick"
    },
    {
      "x": -2,
      "y": 3,
      "z": -1,
      "name": "Rock_Basalt_Brick"
    },
    {
      "x": -2,
      "y": 4,
      "z": -1,
      "name": "Rock_Basalt_Brick"
    },
    {
      "x": -2,
      "y": 5,
      "z": -1,
      "name": "Rock_Basalt_Cobble"
    },
    {
      "x": -2,
      "y": 6,
      "z": -1,
      "name": "Rock_Basalt_Cobble"
    },
    {
      "x": -2,
      "y": 7,
      "z": -1,
      "name": "Rock_Basalt_Cobble"
    },
    {
      "x": -2,
      "y": 8,
      "z": -1,
      "name": "Rock_Basalt_Cobble"
    },
    {
      "x": -2,
      "y": 9,
      "z": -1,
      "name": "Rock_Basalt_Cobble"
    },
    {
      "x": -2,
      "y": 0,
      "z": 0,
      "name": "Rock_Basalt_Brick"
    },
    {
      "x": -2,
      "y": 1,
      "z": 0,
      "name": "Rock_Basalt_Brick"
    },
    {
      "x": -2,
      "y": 2,
      "z": 0,
      "name": "Rock_Basalt_Brick"
    },
    {
      "x": -2,
      "y": 3,
      "z": 0,
      "name": "Rock_Basalt_Brick"
    },
    {
      "x": -2,
      "y": 4,
      "z": 0,
      "name": "Rock_Basalt_Brick"
    },
    {
      "x": -2,
      "y": 5,
      "z": 0,
      "name": "Rock_Basalt_Brick"
    },
    {
      "x": -2,
      "y": 6,
      "z": 0,
      "name": "Rock_Basalt_Brick"
    },
    {
      "x": -2,
      "y": 7,
      "z": 0,
      "name": "Rock_Basalt_Brick"
    },
    {
      "x": -2,
      "y": 8,
      "z": 0,
      "name": "Rock_Basalt_Brick"
    },
    {
      "x": -2,
      "y": 9,
      "z": 0,
      "name": "Rock_Basalt_Cobble"
    },
    {
      "x": -2,
      "y": 0,
      "z": 1,
      "name": "Rock_Basalt_Brick"
    },
    {
      "x": -2,
      "y": 1,
      "z": 1,
      "name": "Rock_Basalt_Brick"
    },
    {
      "x": -2,
      "y": 2,
      "z": 1,
      "name": "Rock_Basalt_Brick"
    },
    {
      "x": -2,
      "y": 3,
      "z": 1,
      "name": "Rock_Basalt_Brick"
    },
    {
      "x": -2,
      "y": 4,
      "z": 1,
      "name": "Rock_Basalt_Brick"
    },
    {
      "x": -2,
      "y": 7,
      "z": 1,
      "name": "Rock_Basalt_Brick_Half",
      "rotation": 4
    },
    {
      "x": -2,
      "y": 8,
      "z": 1,
      "name": "Rock_Basalt_Brick"
    },
    {
      "x": -2,
      "y": 9,
      "z": 1,
      "name": "Rock_Basalt_Cobble"
    },
    {
      "x": -2,
      "y": 0,
      "z": 2,
      "name": "Rock_Basalt_Brick"
    },
    {
      "x": -2,
      "y": 1,
      "z": 2,
      "name": "Rock_Basalt_Brick"
    },
    {
      "x": -2,
      "y": 2,
      "z": 2,
      "name": "Rock_Basalt_Brick"
    },
    {
      "x": -2,
      "y": 3,
      "z": 2,
      "name": "Rock_Basalt_Brick_Stairs",
      "rotation": 3
    },
    {
      "x": -2,
      "y": 7,
      "z": 2,
      "name": "Empty"
    },
    {
      "x": -2,
      "y": 8,
      "z": 2,
      "name": "Rock_Basalt_Brick"
    },
    {
      "x": -2,
      "y": 9,
      "z": 2,
      "name": "Rock_Basalt_Cobble"
    },
    {
      "x": -2,
      "y": 0,
      "z": 3,
      "name": "Rock_Basalt_Brick"
    },
    {
      "x": -2,
      "y": 1,
      "z": 3,
      "name": "Rock_Basalt_Brick"
    },
    {
      "x": -2,
      "y": 2,
      "z": 3,
      "name": "Rock_Basalt_Brick_Stairs",
      "rotation": 1
    },
    {
      "x": -2,
      "y": 7,
      "z": 3,
      "name": "Empty"
    },
    {
      "x": -2,
      "y": 8,
      "z": 3,
      "name": "Rock_Basalt_Brick_Half",
      "rotation": 8
    },
    {
      "x": -2,
      "y": 9,
      "z": 3,
      "name": "Rock_Basalt_Brick"
    },
    {
      "x": -2,
      "y": 0,
      "z": 4,
      "name": "Soil_Dirt_Poisoned"
    },
    {
      "x": -2,
      "y": 7,
      "z": 4,
      "name": "Empty"
    },
    {
      "x": -2,
      "y": 8,
      "z": 4,
      "name": "Rock_Basalt_Brick_Half",
      "rotation": 8
    },
    {
      "x": -2,
      "y": 9,
      "z": 4,
      "name": "Rock_Basalt_Brick"
    },
    {
      "x": -2,
      "y": 0,
      "z": 5,
      "name": "Soil_Dirt_Poisoned"
    },
    {
      "x": -2,
      "y": 1,
      "z": 5,
      "name": "Plant_Reeds_Poison"
    },
    {
      "x": -2,
      "y": 7,
      "z": 5,
      "name": "Empty"
    },
    {
      "x": -2,
      "y": 8,
      "z": 5,
      "name": "Rock_Basalt_Brick"
    },
    {
      "x": -2,
      "y": 9,
      "z": 5,
      "name": "Rock_Basalt_Cobble"
    },
    {
      "x": -2,
      "y": 0,
      "z": 6,
      "name": "Soil_Dirt_Poisoned"
    },
    {
      "x": -2,
      "y": 1,
      "z": 6,
      "name": "Plant_Seaweed_Grass_Bulbs"
    },
    {
      "x": -2,
      "y": 2,
      "z": 6,
      "name": "Plant_Seaweed_Grass_Bulbs",
      "filler": 1024
    },
    {
      "x": -2,
      "y": 7,
      "z": 6,
      "name": "Rock_Basalt_Brick_Half",
      "rotation": 6
    },
    {
      "x": -2,
      "y": 8,
      "z": 6,
      "name": "Rock_Basalt_Brick"
    },
    {
      "x": -2,
      "y": 9,
      "z": 6,
      "name": "Rock_Basalt_Cobble"
    },
    {
      "x": -2,
      "y": 0,
      "z": 7,
      "name": "Soil_Dirt_Poisoned"
    },
    {
      "x": -2,
      "y": 1,
      "z": 7,
      "name": "Rock_Basalt_Brick"
    },
    {
      "x": -2,
      "y": 2,
      "z": 7,
      "name": "Rock_Basalt_Brick"
    },
    {
      "x": -2,
      "y": 3,
      "z": 7,
      "name": "Rock_Basalt_Brick"
    },
    {
      "x": -2,
      "y": 4,
      "z": 7,
      "name": "Rock_Basalt_Brick"
    },
    {
      "x": -2,
      "y": 5,
      "z": 7,
      "name": "Rock_Basalt_Brick"
    },
    {
      "x": -2,
      "y": 6,
      "z": 7,
      "name": "Rock_Basalt_Brick"
    },
    {
      "x": -2,
      "y": 7,
      "z": 7,
      "name": "Rock_Basalt_Brick"
    },
    {
      "x": -2,
      "y": 8,
      "z": 7,
      "name": "Rock_Basalt_Brick"
    },
    {
      "x": -2,
      "y": 9,
      "z": 7,
      "name": "Rock_Basalt_Cobble"
    },
    {
      "x": -2,
      "y": 0,
      "z": 8,
      "name": "Rock_Basalt_Cobble"
    },
    {
      "x": -2,
      "y": 1,
      "z": 8,
      "name": "Rock_Basalt_Cobble"
    },
    {
      "x": -2,
      "y": 2,
      "z": 8,
      "name": "Rock_Basalt_Cobble"
    },
    {
      "x": -2,
      "y": 3,
      "z": 8,
      "name": "Rock_Basalt_Cobble"
    },
    {
      "x": -2,
      "y": 4,
      "z": 8,
      "name": "Rock_Basalt_Cobble"
    },
    {
      "x": -2,
      "y": 5,
      "z": 8,
      "name": "Rock_Basalt_Cobble"
    },
    {
      "x": -2,
      "y": 6,
      "z": 8,
      "name": "Rock_Basalt_Cobble"
    },
    {
      "x": -2,
      "y": 7,
      "z": 8,
      "name": "Rock_Basalt_Cobble"
    },
    {
      "x": -2,
      "y": 8,
      "z": 8,
      "name": "Rock_Basalt_Cobble"
    },
    {
      "x": -2,
      "y": 9,
      "z": 8,
      "name": "Rock_Basalt_Cobble"
    },
    {
      "x": -1,
      "y": 0,
      "z": -1,
      "name": "Rock_Basalt_Brick"
    },
    {
      "x": -1,
      "y": 1,
      "z": -1,
      "name": "Rock_Basalt_Brick"
    },
    {
      "x": -1,
      "y": 2,
      "z": -1,
      "name": "Rock_Basalt_Brick"
    },
    {
      "x": -1,
      "y": 3,
      "z": -1,
      "name": "Rock_Basalt_Brick"
    },
    {
      "x": -1,
      "y": 4,
      "z": -1,
      "name": "Rock_Basalt_Brick"
    },
    {
      "x": -1,
      "y": 5,
      "z": -1,
      "name": "Rock_Basalt_Cobble"
    },
    {
      "x": -1,
      "y": 6,
      "z": -1,
      "name": "Rock_Basalt_Cobble"
    },
    {
      "x": -1,
      "y": 7,
      "z": -1,
      "name": "Rock_Basalt_Cobble"
    },
    {
      "x": -1,
      "y": 8,
      "z": -1,
      "name": "Rock_Basalt_Cobble"
    },
    {
      "x": -1,
      "y": 9,
      "z": -1,
      "name": "Rock_Basalt_Cobble"
    },
    {
      "x": -1,
      "y": 0,
      "z": 0,
      "name": "Rock_Basalt_Brick"
    },
    {
      "x": -1,
      "y": 1,
      "z": 0,
      "name": "Rock_Basalt_Brick"
    },
    {
      "x": -1,
      "y": 2,
      "z": 0,
      "name": "Rock_Basalt_Brick"
    },
    {
      "x": -1,
      "y": 3,
      "z": 0,
      "name": "Rock_Basalt_Brick"
    },
    {
      "x": -1,
      "y": 4,
      "z": 0,
      "name": "Rock_Basalt_Brick"
    },
    {
      "x": -1,
      "y": 7,
      "z": 0,
      "name": "Empty"
    },
    {
      "x": -1,
      "y": 8,
      "z": 0,
      "name": "Empty"
    },
    {
      "x": -1,
      "y": 9,
      "z": 0,
      "name": "Rock_Basalt_Cobble"
    },
    {
      "x": -1,
      "y": 0,
      "z": 1,
      "name": "Rock_Basalt_Brick"
    },
    {
      "x": -1,
      "y": 1,
      "z": 1,
      "name": "Rock_Basalt_Brick"
    },
    {
      "x": -1,
      "y": 2,
      "z": 1,
      "name": "Rock_Basalt_Brick"
    },
    {
      "x": -1,
      "y": 3,
      "z": 1,
      "name": "Rock_Basalt_Brick"
    },
    {
      "x": -1,
      "y": 4,
      "z": 1,
      "name": "Rock_Basalt_Brick"
    },
    {
      "x": -1,
      "y": 7,
      "z": 1,
      "name": "Empty"
    },
    {
      "x": -1,
      "y": 8,
      "z": 1,
      "name": "Empty"
    },
    {
      "x": -1,
      "y": 9,
      "z": 1,
      "name": "Rock_Basalt_Cobble"
    },
    {
      "x": -1,
      "y": 0,
      "z": 2,
      "name": "Rock_Basalt_Brick"
    },
    {
      "x": -1,
      "y": 1,
      "z": 2,
      "name": "Rock_Basalt_Brick"
    },
    {
      "x": -1,
      "y": 2,
      "z": 2,
      "name": "Rock_Basalt_Brick"
    },
    {
      "x": -1,
      "y": 3,
      "z": 2,
      "name": "Rock_Basalt_Brick"
    },
    {
      "x": -1,
      "y": 4,
      "z": 2,
      "name": "Rock_Basalt_Brick_Stairs",
      "rotation": 3
    },
    {
      "x": -1,
      "y": 7,
      "z": 2,
      "name": "Empty"
    },
    {
      "x": -1,
      "y": 8,
      "z": 2,
      "name": "Empty"
    },
    {
      "x": -1,
      "y": 9,
      "z": 2,
      "name": "Rock_Basalt_Cobble"
    },
    {
      "x": -1,
      "y": 0,
      "z": 3,
      "name": "Rock_Basalt_Brick"
    },
    {
      "x": -1,
      "y": 1,
      "z": 3,
      "name": "Rock_Basalt_Brick_Stairs",
      "rotation": 1
    },
    {
      "x": -1,
      "y": 7,
      "z": 3,
      "name": "Empty"
    },
    {
      "x": -1,
      "y": 8,
      "z": 3,
      "name": "Rock_Basalt_Brick_Half",
      "rotation": 8
    },
    {
      "x": -1,
      "y": 9,
      "z": 3,
      "name": "Rock_Basalt_Brick"
    },
    {
      "x": -1,
      "y": 0,
      "z": 4,
      "name": "Soil_Dirt_Poisoned"
    },
    {
      "x": -1,
      "y": 7,
      "z": 4,
      "name": "Empty"
    },
    {
      "x": -1,
      "y": 8,
      "z": 4,
      "name": "Rock_Basalt_Brick_Half",
      "rotation": 8
    },
    {
      "x": -1,
      "y": 9,
      "z": 4,
      "name": "Rock_Basalt_Brick"
    },
    {
      "x": -1,
      "y": 0,
      "z": 5,
      "name": "Soil_Dirt_Poisoned"
    },
    {
      "x": -1,
      "y": 7,
      "z": 5,
      "name": "Empty"
    },
    {
      "x": -1,
      "y": 8,
      "z": 5,
      "name": "Empty"
    },
    {
      "x": -1,
      "y": 9,
      "z": 5,
      "name": "Rock_Basalt_Cobble"
    },
    {
      "x": -1,
      "y": 0,
      "z": 6,
      "name": "Soil_Dirt_Poisoned"
    },
    {
      "x": -1,
      "y": 7,
      "z": 6,
      "name": "Empty"
    },
    {
      "x": -1,
      "y": 8,
      "z": 6,
      "name": "Empty"
    },
    {
      "x": -1,
      "y": 9,
      "z": 6,
      "name": "Rock_Basalt_Cobble"
    },
    {
      "x": -1,
      "y": 0,
      "z": 7,
      "name": "Soil_Dirt_Poisoned"
    },
    {
      "x": -1,
      "y": 1,
      "z": 7,
      "name": "Plant_Seaweed_Grass_Bulbs"
    },
    {
      "x": -1,
      "y": 2,
      "z": 7,
      "name": "Plant_Seaweed_Grass_Bulbs",
      "filler": 1024
    },
    {
      "x": -1,
      "y": 6,
      "z": 7,
      "name": "Rock_Basalt_Brick_Half",
      "rotation": 5
    },
    {
      "x": -1,
      "y": 7,
      "z": 7,
      "name": "Rock_Basalt_Brick"
    },
    {
      "x": -1,
      "y": 8,
      "z": 7,
      "name": "Rock_Basalt_Brick"
    },
    {
      "x": -1,
      "y": 9,
      "z": 7,
      "name": "Rock_Basalt_Cobble"
    },
    {
      "x": -1,
      "y": 0,
      "z": 8,
      "name": "Rock_Basalt_Cobble"
    },
    {
      "x": -1,
      "y": 1,
      "z": 8,
      "name": "Rock_Basalt_Cobble"
    },
    {
      "x": -1,
      "y": 2,
      "z": 8,
      "name": "Rock_Basalt_Cobble"
    },
    {
      "x": -1,
      "y": 3,
      "z": 8,
      "name": "Rock_Basalt_Cobble"
    },
    {
      "x": -1,
      "y": 4,
      "z": 8,
      "name": "Rock_Basalt_Cobble"
    },
    {
      "x": -1,
      "y": 5,
      "z": 8,
      "name": "Rock_Basalt_Cobble"
    },
    {
      "x": -1,
      "y": 6,
      "z": 8,
      "name": "Rock_Basalt_Cobble"
    },
    {
      "x": -1,
      "y": 7,
      "z": 8,
      "name": "Rock_Basalt_Cobble"
    },
    {
      "x": -1,
      "y": 8,
      "z": 8,
      "name": "Rock_Basalt_Cobble"
    },
    {
      "x": -1,
      "y": 9,
      "z": 8,
      "name": "Rock_Basalt_Cobble"
    },
    {
      "x": 0,
      "y": 0,
      "z": -1,
      "name": "Rock_Basalt_Brick"
    },
    {
      "x": 0,
      "y": 1,
      "z": -1,
      "name": "Rock_Basalt_Brick"
    },
    {
      "x": 0,
      "y": 2,
      "z": -1,
      "name": "Rock_Basalt_Brick"
    },
    {
      "x": 0,
      "y": 3,
      "z": -1,
      "name": "Rock_Basalt_Brick"
    },
    {
      "x": 0,
      "y": 4,
      "z": -1,
      "name": "Rock_Basalt_Brick"
    },
    {
      "x": 0,
      "y": 5,
      "z": -1,
      "name": "Rock_Basalt_Brick"
    },
    {
      "x": 0,
      "y": 6,
      "z": -1,
      "name": "Rock_Basalt_Brick"
    },
    {
      "x": 0,
      "y": 7,
      "z": -1,
      "name": "Rock_Basalt_Brick"
    },
    {
      "x": 0,
      "y": 8,
      "z": -1,
      "name": "Rock_Basalt_Brick"
    },
    {
      "x": 0,
      "y": 9,
      "z": -1,
      "name": "Rock_Basalt_Cobble"
    },
    {
      "x": 0,
      "y": 0,
      "z": 0,
      "name": "Rock_Basalt_Brick"
    },
    {
      "x": 0,
      "y": 1,
      "z": 0,
      "name": "Rock_Basalt_Brick"
    },
    {
      "x": 0,
      "y": 2,
      "z": 0,
      "name": "Rock_Basalt_Brick"
    },
    {
      "x": 0,
      "y": 3,
      "z": 0,
      "name": "Rock_Basalt_Brick"
    },
    {
      "x": 0,
      "y": 4,
      "z": 0,
      "name": "Rock_Basalt_Brick"
    },
    {
      "x": 0,
      "y": 5,
      "z": 0,
      "name": "Rock_Basalt_Brick_Stairs",
      "rotation": 9
    },
    {
      "x": 0,
      "y": 6,
      "z": 0,
      "name": "Rock_Basalt_Brick"
    },
    {
      "x": 0,
      "y": 7,
      "z": 0,
      "name": "Rock_Basalt_Brick"
    },
    {
      "x": 0,
      "y": 8,
      "z": 0,
      "name": "Rock_Basalt_Brick_Stairs",
      "rotation": 3
    },
    {
      "x": 0,
      "y": 9,
      "z": 0,
      "name": "Rock_Basalt_Cobble"
    },
    {
      "x": 0,
      "y": 0,
      "z": 1,
      "name": "Rock_Basalt_Brick"
    },
    {
      "x": 0,
      "y": 1,
      "z": 1,
      "name": "Rock_Basalt_Brick"
    },
    {
      "x": 0,
      "y": 2,
      "z": 1,
      "name": "Rock_Basalt_Brick"
    },
    {
      "x": 0,
      "y": 3,
      "z": 1,
      "name": "Rock_Basalt_Brick"
    },
    {
      "x": 0,
      "y": 4,
      "z": 1,
      "name": "Rock_Basalt_Brick"
    },
    {
      "x": 0,
      "y": 7,
      "z": 1,
      "name": "Empty"
    },
    {
      "x": 0,
      "y": 8,
      "z": 1,
      "name": "Empty"
    },
    {
      "x": 0,
      "y": 9,
      "z": 1,
      "name": "Rock_Basalt_Cobble"
    },
    {
      "x": 0,
      "y": 0,
      "z": 2,
      "name": "Rock_Basalt_Brick"
    },
    {
      "x": 0,
      "y": 1,
      "z": 2,
      "name": "Rock_Basalt_Brick"
    },
    {
      "x": 0,
      "y": 2,
      "z": 2,
      "name": "Rock_Basalt_Brick"
    },
    {
      "x": 0,
      "y": 3,
      "z": 2,
      "name": "Rock_Basalt_Brick"
    },
    {
      "x": 0,
      "y": 4,
      "z": 2,
      "name": "Rock_Basalt_Brick"
    },
    {
      "x": 0,
      "y": 7,
      "z": 2,
      "name": "Empty"
    },
    {
      "x": 0,
      "y": 8,
      "z": 2,
      "name": "Empty"
    },
    {
      "x": 0,
      "y": 9,
      "z": 2,
      "name": "Rock_Basalt_Cobble"
    },
    {
      "x": 0,
      "y": 0,
      "z": 3,
      "name": "Rock_Basalt_Brick"
    },
    {
      "x": 0,
      "y": 1,
      "z": 3,
      "name": "Rock_Basalt_Brick"
    },
    {
      "x": 0,
      "y": 2,
      "z": 3,
      "name": "Rock_Basalt_Brick"
    },
    {
      "x": 0,
      "y": 3,
      "z": 3,
      "name": "Rock_Basalt_Brick"
    },
    {
      "x": 0,
      "y": 4,
      "z": 3,
      "name": "Rock_Basalt_Brick"
    },
    {
      "x": 0,
      "y": 7,
      "z": 3,
      "name": "Empty"
    },
    {
      "x": 0,
      "y": 8,
      "z": 3,
      "name": "Empty"
    },
    {
      "x": 0,
      "y": 9,
      "z": 3,
      "name": "Rock_Basalt_Brick"
    },
    {
      "x": 0,
      "y": 0,
      "z": 4,
      "name": "Soil_Dirt_Poisoned"
    },
    {
      "x": 0,
      "y": 7,
      "z": 4,
      "name": "Plant_Crop_Mushroom_Boomshroom_Large",
      "rotation": 8
    },
    {
      "x": 0,
      "y": 8,
      "z": 4,
      "name": "Deco_Iron_Chain_Small"
    },
    {
      "x": 0,
      "y": 9,
      "z": 4,
      "name": "Rock_Basalt_Brick"
    },
    {
      "x": 0,
      "y": 0,
      "z": 5,
      "name": "Soil_Dirt_Poisoned"
    },
    {
      "x": 0,
      "y": 7,
      "z": 5,
      "name": "Empty"
    },
    {
      "x": 0,
      "y": 8,
      "z": 5,
      "name": "Empty"
    },
    {
      "x": 0,
      "y": 9,
      "z": 5,
      "name": "Rock_Basalt_Cobble"
    },
    {
      "x": 0,
      "y": 0,
      "z": 6,
      "name": "Soil_Dirt_Poisoned"
    },
    {
      "x": 0,
      "y": 7,
      "z": 6,
      "name": "Empty"
    },
    {
      "x": 0,
      "y": 8,
      "z": 6,
      "name": "Empty"
    },
    {
      "x": 0,
      "y": 9,
      "z": 6,
      "name": "Rock_Basalt_Cobble"
    },
    {
      "x": 0,
      "y": 0,
      "z": 7,
      "name": "Soil_Dirt_Poisoned"
    },
    {
      "x": 0,
      "y": 7,
      "z": 7,
      "name": "Empty"
    },
    {
      "x": 0,
      "y": 8,
      "z": 7,
      "name": "Rock_Basalt_Brick"
    },
    {
      "x": 0,
      "y": 9,
      "z": 7,
      "name": "Rock_Basalt_Cobble"
    },
    {
      "x": 0,
      "y": 0,
      "z": 8,
      "name": "Rock_Basalt_Cobble"
    },
    {
      "x": 0,
      "y": 1,
      "z": 8,
      "name": "Rock_Basalt_Cobble"
    },
    {
      "x": 0,
      "y": 2,
      "z": 8,
      "name": "Rock_Basalt_Cobble"
    },
    {
      "x": 0,
      "y": 3,
      "z": 8,
      "name": "Rock_Basalt_Cobble"
    },
    {
      "x": 0,
      "y": 4,
      "z": 8,
      "name": "Rock_Basalt_Cobble"
    },
    {
      "x": 0,
      "y": 5,
      "z": 8,
      "name": "Rock_Basalt_Cobble"
    },
    {
      "x": 0,
      "y": 6,
      "z": 8,
      "name": "Rock_Basalt_Cobble"
    },
    {
      "x": 0,
      "y": 7,
      "z": 8,
      "name": "Rock_Basalt_Cobble"
    },
    {
      "x": 0,
      "y": 8,
      "z": 8,
      "name": "Rock_Basalt_Cobble"
    },
    {
      "x": 0,
      "y": 9,
      "z": 8,
      "name": "Rock_Basalt_Cobble"
    },
    {
      "x": 1,
      "y": 0,
      "z": -1,
      "name": "Rock_Basalt_Brick"
    },
    {
      "x": 1,
      "y": 1,
      "z": -1,
      "name": "Rock_Basalt_Brick"
    },
    {
      "x": 1,
      "y": 2,
      "z": -1,
      "name": "Rock_Basalt_Brick"
    },
    {
      "x": 1,
      "y": 3,
      "z": -1,
      "name": "Rock_Basalt_Brick"
    },
    {
      "x": 1,
      "y": 4,
      "z": -1,
      "name": "Rock_Basalt_Brick"
    },
    {
      "x": 1,
      "y": 5,
      "z": -1,
      "name": "Rock_Basalt_Brick"
    },
    {
      "x": 1,
      "y": 8,
      "z": -1,
      "name": "Rock_Basalt_Brick"
    },
    {
      "x": 1,
      "y": 9,
      "z": -1,
      "name": "Rock_Basalt_Brick"
    },
    {
      "x": 1,
      "y": 0,
      "z": 0,
      "name": "Rock_Basalt_Brick"
    },
    {
      "x": 1,
      "y": 1,
      "z": 0,
      "name": "Rock_Basalt_Brick"
    },
    {
      "x": 1,
      "y": 2,
      "z": 0,
      "name": "Rock_Basalt_Brick"
    },
    {
      "x": 1,
      "y": 3,
      "z": 0,
      "name": "Rock_Basalt_Brick"
    },
    {
      "x": 1,
      "y": 4,
      "z": 0,
      "name": "Rock_Basalt_Brick"
    },
    {
      "x": 1,
      "y": 5,
      "z": 0,
      "name": "Rock_Basalt_Brick"
    },
    {
      "x": 1,
      "y": 7,
      "z": 0,
      "name": "Empty"
    },
    {
      "x": 1,
      "y": 8,
      "z": 0,
      "name": "Rock_Basalt_Brick"
    },
    {
      "x": 1,
      "y": 9,
      "z": 0,
      "name": "Rock_Basalt_Brick"
    },
    {
      "x": 1,
      "y": 0,
      "z": 1,
      "name": "Rock_Basalt_Brick"
    },
    {
      "x": 1,
      "y": 1,
      "z": 1,
      "name": "Rock_Basalt_Brick"
    },
    {
      "x": 1,
      "y": 2,
      "z": 1,
      "name": "Rock_Basalt_Brick"
    },
    {
      "x": 1,
      "y": 3,
      "z": 1,
      "name": "Rock_Basalt_Brick"
    },
    {
      "x": 1,
      "y": 4,
      "z": 1,
      "name": "Rock_Basalt_Brick"
    },
    {
      "x": 1,
      "y": 7,
      "z": 1,
      "name": "Empty"
    },
    {
      "x": 1,
      "y": 8,
      "z": 1,
      "name": "Rock_Basalt_Brick_Half",
      "rotation": 8
    },
    {
      "x": 1,
      "y": 9,
      "z": 1,
      "name": "Rock_Basalt_Brick"
    },
    {
      "x": 1,
      "y": 0,
      "z": 2,
      "name": "Rock_Basalt_Brick"
    },
    {
      "x": 1,
      "y": 1,
      "z": 2,
      "name": "Rock_Basalt_Brick"
    },
    {
      "x": 1,
      "y": 2,
      "z": 2,
      "name": "Rock_Basalt_Brick"
    },
    {
      "x": 1,
      "y": 3,
      "z": 2,
      "name": "Rock_Basalt_Brick"
    },
    {
      "x": 1,
      "y": 4,
      "z": 2,
      "name": "Rock_Basalt_Brick"
    },
    {
      "x": 1,
      "y": 7,
      "z": 2,
      "name": "Empty"
    },
    {
      "x": 1,
      "y": 8,
      "z": 2,
      "name": "Empty"
    },
    {
      "x": 1,
      "y": 9,
      "z": 2,
      "name": "Rock_Basalt_Brick"
    },
    {
      "x": 1,
      "y": 0,
      "z": 3,
      "name": "Rock_Basalt_Brick"
    },
    {
      "x": 1,
      "y": 1,
      "z": 3,
      "name": "Rock_Basalt_Brick"
    },
    {
      "x": 1,
      "y": 2,
      "z": 3,
      "name": "Rock_Basalt_Brick"
    },
    {
      "x": 1,
      "y": 3,
      "z": 3,
      "name": "Rock_Basalt_Brick"
    },
    {
      "x": 1,
      "y": 4,
      "z": 3,
      "name": "Rock_Basalt_Brick"
    },
    {
      "x": 1,
      "y": 7,
      "z": 3,
      "name": "Empty"
    },
    {
      "x": 1,
      "y": 8,
      "z": 3,
      "name": "Empty"
    },
    {
      "x": 1,
      "y": 9,
      "z": 3,
      "name": "Rock_Basalt_Brick"
    },
    {
      "x": 1,
      "y": 0,
      "z": 4,
      "name": "Soil_Dirt_Poisoned"
    },
    {
      "x": 1,
      "y": 7,
      "z": 4,
      "name": "Empty"
    },
    {
      "x": 1,
      "y": 8,
      "z": 4,
      "name": "Empty"
    },
    {
      "x": 1,
      "y": 9,
      "z": 4,
      "name": "Rock_Basalt_Brick"
    },
    {
      "x": 1,
      "y": 0,
      "z": 5,
      "name": "Soil_Dirt_Poisoned"
    },
    {
      "x": 1,
      "y": 7,
      "z": 5,
      "name": "Empty"
    },
    {
      "x": 1,
      "y": 8,
      "z": 5,
      "name": "Empty"
    },
    {
      "x": 1,
      "y": 9,
      "z": 5,
      "name": "Rock_Basalt_Brick"
    },
    {
      "x": 1,
      "y": 0,
      "z": 6,
      "name": "Soil_Dirt_Poisoned"
    },
    {
      "x": 1,
      "y": 7,
      "z": 6,
      "name": "Empty"
    },
    {
      "x": 1,
      "y": 8,
      "z": 6,
      "name": "Rock_Basalt_Brick_Half",
      "rotation": 8
    },
    {
      "x": 1,
      "y": 9,
      "z": 6,
      "name": "Rock_Basalt_Brick"
    },
    {
      "x": 1,
      "y": 0,
      "z": 7,
      "name": "Soil_Dirt_Poisoned"
    },
    {
      "x": 1,
      "y": 7,
      "z": 7,
      "name": "Empty"
    },
    {
      "x": 1,
      "y": 8,
      "z": 7,
      "name": "Rock_Basalt_Brick_Half",
      "rotation": 8
    },
    {
      "x": 1,
      "y": 9,
      "z": 7,
      "name": "Rock_Basalt_Brick"
    },
    {
      "x": 1,
      "y": 0,
      "z": 8,
      "name": "Rock_Basalt_Cobble"
    },
    {
      "x": 1,
      "y": 1,
      "z": 8,
      "name": "Rock_Basalt_Cobble"
    },
    {
      "x": 1,
      "y": 2,
      "z": 8,
      "name": "Rock_Basalt_Cobble"
    },
    {
      "x": 1,
      "y": 3,
      "z": 8,
      "name": "Rock_Basalt_Cobble"
    },
    {
      "x": 1,
      "y": 4,
      "z": 8,
      "name": "Rock_Basalt_Cobble"
    },
    {
      "x": 1,
      "y": 5,
      "z": 8,
      "name": "Rock_Basalt_Cobble"
    },
    {
      "x": 1,
      "y": 6,
      "z": 8,
      "name": "Rock_Basalt_Cobble"
    },
    {
      "x": 1,
      "y": 7,
      "z": 8,
      "name": "Rock_Basalt_Cobble"
    },
    {
      "x": 1,
      "y": 8,
      "z": 8,
      "name": "Rock_Basalt_Cobble"
    },
    {
      "x": 1,
      "y": 9,
      "z": 8,
      "name": "Rock_Basalt_Brick"
    },
    {
      "x": 2,
      "y": 0,
      "z": -1,
      "name": "Rock_Basalt_Brick"
    },
    {
      "x": 2,
      "y": 1,
      "z": -1,
      "name": "Rock_Basalt_Brick"
    },
    {
      "x": 2,
      "y": 2,
      "z": -1,
      "name": "Rock_Basalt_Brick"
    },
    {
      "x": 2,
      "y": 3,
      "z": -1,
      "name": "Rock_Basalt_Brick"
    },
    {
      "x": 2,
      "y": 4,
      "z": -1,
      "name": "Rock_Basalt_Brick"
    },
    {
      "x": 2,
      "y": 5,
      "z": -1,
      "name": "Rock_Basalt_Brick"
    },
    {
      "x": 2,
      "y": 8,
      "z": -1,
      "name": "Rock_Basalt_Brick"
    },
    {
      "x": 2,
      "y": 9,
      "z": -1,
      "name": "Rock_Basalt_Brick"
    },
    {
      "x": 2,
      "y": 0,
      "z": 0,
      "name": "Rock_Basalt_Brick"
    },
    {
      "x": 2,
      "y": 1,
      "z": 0,
      "name": "Rock_Basalt_Brick"
    },
    {
      "x": 2,
      "y": 2,
      "z": 0,
      "name": "Rock_Basalt_Brick"
    },
    {
      "x": 2,
      "y": 3,
      "z": 0,
      "name": "Rock_Basalt_Brick"
    },
    {
      "x": 2,
      "y": 4,
      "z": 0,
      "name": "Rock_Basalt_Brick"
    },
    {
      "x": 2,
      "y": 5,
      "z": 0,
      "name": "Rock_Basalt_Brick"
    },
    {
      "x": 2,
      "y": 7,
      "z": 0,
      "name": "Empty"
    },
    {
      "x": 2,
      "y": 8,
      "z": 0,
      "name": "Rock_Basalt_Brick"
    },
    {
      "x": 2,
      "y": 9,
      "z": 0,
      "name": "Rock_Basalt_Brick"
    },
    {
      "x": 2,
      "y": 0,
      "z": 1,
      "name": "Rock_Basalt_Brick"
    },
    {
      "x": 2,
      "y": 1,
      "z": 1,
      "name": "Rock_Basalt_Brick"
    },
    {
      "x": 2,
      "y": 2,
      "z": 1,
      "name": "Rock_Basalt_Brick"
    },
    {
      "x": 2,
      "y": 3,
      "z": 1,
      "name": "Rock_Basalt_Brick"
    },
    {
      "x": 2,
      "y": 4,
      "z": 1,
      "name": "Rock_Basalt_Brick"
    },
    {
      "x": 2,
      "y": 7,
      "z": 1,
      "name": "Empty"
    },
    {
      "x": 2,
      "y": 8,
      "z": 1,
      "name": "Rock_Basalt_Brick_Half",
      "rotation": 8
    },
    {
      "x": 2,
      "y": 9,
      "z": 1,
      "name": "Rock_Basalt_Brick"
    },
    {
      "x": 2,
      "y": 0,
      "z": 2,
      "name": "Rock_Basalt_Brick"
    },
    {
      "x": 2,
      "y": 1,
      "z": 2,
      "name": "Rock_Basalt_Brick"
    },
    {
      "x": 2,
      "y": 2,
      "z": 2,
      "name": "Rock_Basalt_Brick"
    },
    {
      "x": 2,
      "y": 3,
      "z": 2,
      "name": "Rock_Basalt_Brick"
    },
    {
      "x": 2,
      "y": 4,
      "z": 2,
      "name": "Rock_Basalt_Brick"
    },
    {
      "x": 2,
      "y": 7,
      "z": 2,
      "name": "Empty"
    },
    {
      "x": 2,
      "y": 8,
      "z": 2,
      "name": "Empty"
    },
    {
      "x": 2,
      "y": 9,
      "z": 2,
      "name": "Rock_Basalt_Brick"
    },
    {
      "x": 2,
      "y": 0,
      "z": 3,
      "name": "Rock_Basalt_Brick"
    },
    {
      "x": 2,
      "y": 1,
      "z": 3,
      "name": "Rock_Basalt_Brick"
    },
    {
      "x": 2,
      "y": 2,
      "z": 3,
      "name": "Rock_Basalt_Brick"
    },
    {
      "x": 2,
      "y": 3,
      "z": 3,
      "name": "Rock_Basalt_Brick"
    },
    {
      "x": 2,
      "y": 4,
      "z": 3,
      "name": "Rock_Basalt_Brick"
    },
    {
      "x": 2,
      "y": 7,
      "z": 3,
      "name": "Empty"
    },
    {
      "x": 2,
      "y": 8,
      "z": 3,
      "name": "Empty"
    },
    {
      "x": 2,
      "y": 9,
      "z": 3,
      "name": "Rock_Basalt_Brick"
    },
    {
      "x": 2,
      "y": 0,
      "z": 4,
      "name": "Soil_Dirt_Poisoned"
    },
    {
      "x": 2,
      "y": 7,
      "z": 4,
      "name": "Empty"
    },
    {
      "x": 2,
      "y": 8,
      "z": 4,
      "name": "Empty"
    },
    {
      "x": 2,
      "y": 9,
      "z": 4,
      "name": "Rock_Basalt_Brick"
    },
    {
      "x": 2,
      "y": 0,
      "z": 5,
      "name": "Soil_Dirt_Poisoned"
    },
    {
      "x": 2,
      "y": 7,
      "z": 5,
      "name": "Empty"
    },
    {
      "x": 2,
      "y": 8,
      "z": 5,
      "name": "Empty"
    },
    {
      "x": 2,
      "y": 9,
      "z": 5,
      "name": "Rock_Basalt_Brick"
    },
    {
      "x": 2,
      "y": 0,
      "z": 6,
      "name": "Soil_Dirt_Poisoned"
    },
    {
      "x": 2,
      "y": 7,
      "z": 6,
      "name": "Empty"
    },
    {
      "x": 2,
      "y": 8,
      "z": 6,
      "name": "Rock_Basalt_Brick_Half",
      "rotation": 8
    },
    {
      "x": 2,
      "y": 9,
      "z": 6,
      "name": "Rock_Basalt_Brick"
    },
    {
      "x": 2,
      "y": 0,
      "z": 7,
      "name": "Soil_Dirt_Poisoned"
    },
    {
      "x": 2,
      "y": 7,
      "z": 7,
      "name": "Empty"
    },
    {
      "x": 2,
      "y": 8,
      "z": 7,
      "name": "Rock_Basalt_Brick_Half",
      "rotation": 8
    },
    {
      "x": 2,
      "y": 9,
      "z": 7,
      "name": "Rock_Basalt_Brick"
    },
    {
      "x": 2,
      "y": 0,
      "z": 8,
      "name": "Rock_Basalt_Cobble"
    },
    {
      "x": 2,
      "y": 1,
      "z": 8,
      "name": "Rock_Basalt_Cobble"
    },
    {
      "x": 2,
      "y": 2,
      "z": 8,
      "name": "Rock_Basalt_Cobble"
    },
    {
      "x": 2,
      "y": 3,
      "z": 8,
      "name": "Rock_Basalt_Cobble"
    },
    {
      "x": 2,
      "y": 4,
      "z": 8,
      "name": "Rock_Basalt_Cobble"
    },
    {
      "x": 2,
      "y": 5,
      "z": 8,
      "name": "Rock_Basalt_Cobble"
    },
    {
      "x": 2,
      "y": 6,
      "z": 8,
      "name": "Rock_Basalt_Cobble"
    },
    {
      "x": 2,
      "y": 7,
      "z": 8,
      "name": "Rock_Basalt_Cobble"
    },
    {
      "x": 2,
      "y": 8,
      "z": 8,
      "name": "Rock_Basalt_Cobble"
    },
    {
      "x": 2,
      "y": 9,
      "z": 8,
      "name": "Rock_Basalt_Brick"
    },
    {
      "x": 3,
      "y": 0,
      "z": -1,
      "name": "Rock_Basalt_Brick"
    },
    {
      "x": 3,
      "y": 1,
      "z": -1,
      "name": "Rock_Basalt_Brick"
    },
    {
      "x": 3,
      "y": 2,
      "z": -1,
      "name": "Rock_Basalt_Brick"
    },
    {
      "x": 3,
      "y": 3,
      "z": -1,
      "name": "Rock_Basalt_Brick"
    },
    {
      "x": 3,
      "y": 4,
      "z": -1,
      "name": "Rock_Basalt_Brick"
    },
    {
      "x": 3,
      "y": 5,
      "z": -1,
      "name": "Rock_Basalt_Brick"
    },
    {
      "x": 3,
      "y": 6,
      "z": -1,
      "name": "Rock_Basalt_Brick"
    },
    {
      "x": 3,
      "y": 7,
      "z": -1,
      "name": "Rock_Basalt_Brick"
    },
    {
      "x": 3,
      "y": 8,
      "z": -1,
      "name": "Rock_Basalt_Brick"
    },
    {
      "x": 3,
      "y": 9,
      "z": -1,
      "name": "Rock_Basalt_Cobble"
    },
    {
      "x": 3,
      "y": 0,
      "z": 0,
      "name": "Rock_Basalt_Brick"
    },
    {
      "x": 3,
      "y": 1,
      "z": 0,
      "name": "Rock_Basalt_Brick"
    },
    {
      "x": 3,
      "y": 2,
      "z": 0,
      "name": "Rock_Basalt_Brick"
    },
    {
      "x": 3,
      "y": 3,
      "z": 0,
      "name": "Rock_Basalt_Brick"
    },
    {
      "x": 3,
      "y": 4,
      "z": 0,
      "name": "Rock_Basalt_Brick"
    },
    {
      "x": 3,
      "y": 5,
      "z": 0,
      "name": "Rock_Basalt_Brick_Stairs",
      "rotation": 11
    },
    {
      "x": 3,
      "y": 6,
      "z": 0,
      "name": "Rock_Basalt_Brick"
    },
    {
      "x": 3,
      "y": 7,
      "z": 0,
      "name": "Rock_Basalt_Brick"
    },
    {
      "x": 3,
      "y": 8,
      "z": 0,
      "name": "Rock_Basalt_Brick_Stairs",
      "rotation": 1
    },
    {
      "x": 3,
      "y": 9,
      "z": 0,
      "name": "Rock_Basalt_Cobble"
    },
    {
      "x": 3,
      "y": 0,
      "z": 1,
      "name": "Rock_Basalt_Brick"
    },
    {
      "x": 3,
      "y": 1,
      "z": 1,
      "name": "Rock_Basalt_Brick"
    },
    {
      "x": 3,
      "y": 2,
      "z": 1,
      "name": "Rock_Basalt_Brick"
    },
    {
      "x": 3,
      "y": 3,
      "z": 1,
      "name": "Rock_Basalt_Brick"
    },
    {
      "x": 3,
      "y": 4,
      "z": 1,
      "name": "Rock_Basalt_Brick"
    },
    {
      "x": 3,
      "y": 7,
      "z": 1,
      "name": "Empty"
    },
    {
      "x": 3,
      "y": 8,
      "z": 1,
      "name": "Empty"
    },
    {
      "x": 3,
      "y": 9,
      "z": 1,
      "name": "Rock_Basalt_Cobble"
    },
    {
      "x": 3,
      "y": 0,
      "z": 2,
      "name": "Rock_Basalt_Brick"
    },
    {
      "x": 3,
      "y": 1,
      "z": 2,
      "name": "Rock_Basalt_Brick"
    },
    {
      "x": 3,
      "y": 2,
      "z": 2,
      "name": "Rock_Basalt_Brick"
    },
    {
      "x": 3,
      "y": 3,
      "z": 2,
      "name": "Rock_Basalt_Brick"
    },
    {
      "x": 3,
      "y": 4,
      "z": 2,
      "name": "Rock_Basalt_Brick"
    },
    {
      "x": 3,
      "y": 7,
      "z": 2,
      "name": "Empty"
    },
    {
      "x": 3,
      "y": 8,
      "z": 2,
      "name": "Empty"
    },
    {
      "x": 3,
      "y": 9,
      "z": 2,
      "name": "Rock_Basalt_Cobble"
    },
    {
      "x": 3,
      "y": 0,
      "z": 3,
      "name": "Rock_Basalt_Brick"
    },
    {
      "x": 3,
      "y": 1,
      "z": 3,
      "name": "Rock_Basalt_Brick"
    },
    {
      "x": 3,
      "y": 2,
      "z": 3,
      "name": "Rock_Basalt_Brick"
    },
    {
      "x": 3,
      "y": 3,
      "z": 3,
      "name": "Rock_Basalt_Brick"
    },
    {
      "x": 3,
      "y": 4,
      "z": 3,
      "name": "Rock_Basalt_Brick"
    },
    {
      "x": 3,
      "y": 7,
      "z": 3,
      "name": "Empty"
    },
    {
      "x": 3,
      "y": 8,
      "z": 3,
      "name": "Empty"
    },
    {
      "x": 3,
      "y": 9,
      "z": 3,
      "name": "Rock_Basalt_Brick"
    },
    {
      "x": 3,
      "y": 0,
      "z": 4,
      "name": "Soil_Dirt_Poisoned"
    },
    {
      "x": 3,
      "y": 7,
      "z": 4,
      "name": "Plant_Crop_Mushroom_Boomshroom_Large",
      "rotation": 8
    },
    {
      "x": 3,
      "y": 8,
      "z": 4,
      "name": "Deco_Iron_Chain_Small"
    },
    {
      "x": 3,
      "y": 9,
      "z": 4,
      "name": "Rock_Basalt_Brick"
    },
    {
      "x": 3,
      "y": 0,
      "z": 5,
      "name": "Soil_Dirt_Poisoned"
    },
    {
      "x": 3,
      "y": 1,
      "z": 5,
      "name": "Plant_Seaweed_Grass_Bulbs"
    },
    {
      "x": 3,
      "y": 2,
      "z": 5,
      "name": "Plant_Seaweed_Grass_Bulbs",
      "filler": 1024
    },
    {
      "x": 3,
      "y": 7,
      "z": 5,
      "name": "Empty"
    },
    {
      "x": 3,
      "y": 8,
      "z": 5,
      "name": "Empty"
    },
    {
      "x": 3,
      "y": 9,
      "z": 5,
      "name": "Rock_Basalt_Cobble"
    },
    {
      "x": 3,
      "y": 0,
      "z": 6,
      "name": "Soil_Dirt_Poisoned"
    },
    {
      "x": 3,
      "y": 1,
      "z": 6,
      "name": "Plant_Reeds_Poison"
    },
    {
      "x": 3,
      "y": 7,
      "z": 6,
      "name": "Empty"
    },
    {
      "x": 3,
      "y": 8,
      "z": 6,
      "name": "Empty"
    },
    {
      "x": 3,
      "y": 9,
      "z": 6,
      "name": "Rock_Basalt_Cobble"
    },
    {
      "x": 3,
      "y": 0,
      "z": 7,
      "name": "Soil_Dirt_Poisoned"
    },
    {
      "x": 3,
      "y": 7,
      "z": 7,
      "name": "Empty"
    },
    {
      "x": 3,
      "y": 8,
      "z": 7,
      "name": "Rock_Basalt_Brick"
    },
    {
      "x": 3,
      "y": 9,
      "z": 7,
      "name": "Rock_Basalt_Cobble"
    },
    {
      "x": 3,
      "y": 0,
      "z": 8,
      "name": "Rock_Basalt_Cobble"
    },
    {
      "x": 3,
      "y": 1,
      "z": 8,
      "name": "Rock_Basalt_Cobble"
    },
    {
      "x": 3,
      "y": 2,
      "z": 8,
      "name": "Rock_Basalt_Cobble"
    },
    {
      "x": 3,
      "y": 3,
      "z": 8,
      "name": "Rock_Basalt_Cobble"
    },
    {
      "x": 3,
      "y": 4,
      "z": 8,
      "name": "Rock_Basalt_Cobble"
    },
    {
      "x": 3,
      "y": 5,
      "z": 8,
      "name": "Rock_Basalt_Cobble"
    },
    {
      "x": 3,
      "y": 6,
      "z": 8,
      "name": "Rock_Basalt_Cobble"
    },
    {
      "x": 3,
      "y": 7,
      "z": 8,
      "name": "Rock_Basalt_Cobble"
    },
    {
      "x": 3,
      "y": 8,
      "z": 8,
      "name": "Rock_Basalt_Cobble"
    },
    {
      "x": 3,
      "y": 9,
      "z": 8,
      "name": "Rock_Basalt_Cobble"
    },
    {
      "x": 4,
      "y": 0,
      "z": -1,
      "name": "Rock_Basalt_Brick"
    },
    {
      "x": 4,
      "y": 1,
      "z": -1,
      "name": "Rock_Basalt_Brick"
    },
    {
      "x": 4,
      "y": 2,
      "z": -1,
      "name": "Rock_Basalt_Brick"
    },
    {
      "x": 4,
      "y": 3,
      "z": -1,
      "name": "Rock_Basalt_Brick"
    },
    {
      "x": 4,
      "y": 4,
      "z": -1,
      "name": "Rock_Basalt_Brick"
    },
    {
      "x": 4,
      "y": 5,
      "z": -1,
      "name": "Rock_Basalt_Cobble"
    },
    {
      "x": 4,
      "y": 6,
      "z": -1,
      "name": "Rock_Basalt_Cobble"
    },
    {
      "x": 4,
      "y": 7,
      "z": -1,
      "name": "Rock_Basalt_Cobble"
    },
    {
      "x": 4,
      "y": 8,
      "z": -1,
      "name": "Rock_Basalt_Cobble"
    },
    {
      "x": 4,
      "y": 9,
      "z": -1,
      "name": "Rock_Basalt_Cobble"
    },
    {
      "x": 4,
      "y": 0,
      "z": 0,
      "name": "Rock_Basalt_Brick"
    },
    {
      "x": 4,
      "y": 1,
      "z": 0,
      "name": "Rock_Basalt_Brick"
    },
    {
      "x": 4,
      "y": 2,
      "z": 0,
      "name": "Rock_Basalt_Brick"
    },
    {
      "x": 4,
      "y": 3,
      "z": 0,
      "name": "Rock_Basalt_Brick"
    },
    {
      "x": 4,
      "y": 4,
      "z": 0,
      "name": "Rock_Basalt_Brick"
    },
    {
      "x": 4,
      "y": 7,
      "z": 0,
      "name": "Empty"
    },
    {
      "x": 4,
      "y": 8,
      "z": 0,
      "name": "Empty"
    },
    {
      "x": 4,
      "y": 9,
      "z": 0,
      "name": "Rock_Basalt_Cobble"
    },
    {
      "x": 4,
      "y": 0,
      "z": 1,
      "name": "Rock_Basalt_Brick"
    },
    {
      "x": 4,
      "y": 1,
      "z": 1,
      "name": "Rock_Basalt_Brick"
    },
    {
      "x": 4,
      "y": 2,
      "z": 1,
      "name": "Rock_Basalt_Brick"
    },
    {
      "x": 4,
      "y": 3,
      "z": 1,
      "name": "Rock_Basalt_Brick"
    },
    {
      "x": 4,
      "y": 4,
      "z": 1,
      "name": "Rock_Basalt_Brick"
    },
    {
      "x": 4,
      "y": 7,
      "z": 1,
      "name": "Empty"
    },
    {
      "x": 4,
      "y": 8,
      "z": 1,
      "name": "Empty"
    },
    {
      "x": 4,
      "y": 9,
      "z": 1,
      "name": "Rock_Basalt_Cobble"
    },
    {
      "x": 4,
      "y": 0,
      "z": 2,
      "name": "Rock_Basalt_Brick"
    },
    {
      "x": 4,
      "y": 1,
      "z": 2,
      "name": "Rock_Basalt_Brick"
    },
    {
      "x": 4,
      "y": 2,
      "z": 2,
      "name": "Rock_Basalt_Brick"
    },
    {
      "x": 4,
      "y": 3,
      "z": 2,
      "name": "Rock_Basalt_Brick"
    },
    {
      "x": 4,
      "y": 4,
      "z": 2,
      "name": "Rock_Basalt_Brick_Stairs",
      "rotation": 1
    },
    {
      "x": 4,
      "y": 7,
      "z": 2,
      "name": "Empty"
    },
    {
      "x": 4,
      "y": 8,
      "z": 2,
      "name": "Empty"
    },
    {
      "x": 4,
      "y": 9,
      "z": 2,
      "name": "Rock_Basalt_Cobble"
    },
    {
      "x": 4,
      "y": 0,
      "z": 3,
      "name": "Rock_Basalt_Brick"
    },
    {
      "x": 4,
      "y": 1,
      "z": 3,
      "name": "Rock_Basalt_Brick_Stairs",
      "rotation": 3
    },
    {
      "x": 4,
      "y": 7,
      "z": 3,
      "name": "Empty"
    },
    {
      "x": 4,
      "y": 8,
      "z": 3,
      "name": "Rock_Basalt_Brick_Half",
      "rotation": 8
    },
    {
      "x": 4,
      "y": 9,
      "z": 3,
      "name": "Rock_Basalt_Brick"
    },
    {
      "x": 4,
      "y": 0,
      "z": 4,
      "name": "Soil_Dirt_Poisoned"
    },
    {
      "x": 4,
      "y": 7,
      "z": 4,
      "name": "Empty"
    },
    {
      "x": 4,
      "y": 8,
      "z": 4,
      "name": "Rock_Basalt_Brick_Half",
      "rotation": 8
    },
    {
      "x": 4,
      "y": 9,
      "z": 4,
      "name": "Rock_Basalt_Brick"
    },
    {
      "x": 4,
      "y": 0,
      "z": 5,
      "name": "Soil_Dirt_Poisoned"
    },
    {
      "x": 4,
      "y": 1,
      "z": 5,
      "name": "Plant_Seaweed_Grass_Bulbs"
    },
    {
      "x": 4,
      "y": 2,
      "z": 5,
      "name": "Plant_Seaweed_Grass_Bulbs",
      "filler": 1024
    },
    {
      "x": 4,
      "y": 7,
      "z": 5,
      "name": "Empty"
    },
    {
      "x": 4,
      "y": 8,
      "z": 5,
      "name": "Empty"
    },
    {
      "x": 4,
      "y": 9,
      "z": 5,
      "name": "Rock_Basalt_Cobble"
    },
    {
      "x": 4,
      "y": 0,
      "z": 6,
      "name": "Soil_Dirt_Poisoned"
    },
    {
      "x": 4,
      "y": 1,
      "z": 6,
      "name": "Plant_Seaweed_Grass_Bulbs"
    },
    {
      "x": 4,
      "y": 2,
      "z": 6,
      "name": "Plant_Seaweed_Grass_Bulbs",
      "filler": 1024
    },
    {
      "x": 4,
      "y": 7,
      "z": 6,
      "name": "Empty"
    },
    {
      "x": 4,
      "y": 8,
      "z": 6,
      "name": "Empty"
    },
    {
      "x": 4,
      "y": 9,
      "z": 6,
      "name": "Rock_Basalt_Cobble"
    },
    {
      "x": 4,
      "y": 0,
      "z": 7,
      "name": "Soil_Dirt_Poisoned"
    },
    {
      "x": 4,
      "y": 6,
      "z": 7,
      "name": "Rock_Basalt_Brick_Half",
      "rotation": 7
    },
    {
      "x": 4,
      "y": 7,
      "z": 7,
      "name": "Rock_Basalt_Brick"
    },
    {
      "x": 4,
      "y": 8,
      "z": 7,
      "name": "Rock_Basalt_Brick"
    },
    {
      "x": 4,
      "y": 9,
      "z": 7,
      "name": "Rock_Basalt_Cobble"
    },
    {
      "x": 4,
      "y": 0,
      "z": 8,
      "name": "Rock_Basalt_Cobble"
    },
    {
      "x": 4,
      "y": 1,
      "z": 8,
      "name": "Rock_Basalt_Cobble"
    },
    {
      "x": 4,
      "y": 2,
      "z": 8,
      "name": "Rock_Basalt_Cobble"
    },
    {
      "x": 4,
      "y": 3,
      "z": 8,
      "name": "Rock_Basalt_Cobble"
    },
    {
      "x": 4,
      "y": 4,
      "z": 8,
      "name": "Rock_Basalt_Cobble"
    },
    {
      "x": 4,
      "y": 5,
      "z": 8,
      "name": "Rock_Basalt_Cobble"
    },
    {
      "x": 4,
      "y": 6,
      "z": 8,
      "name": "Rock_Basalt_Cobble"
    },
    {
      "x": 4,
      "y": 7,
      "z": 8,
      "name": "Rock_Basalt_Cobble"
    },
    {
      "x": 4,
      "y": 8,
      "z": 8,
      "name": "Rock_Basalt_Cobble"
    },
    {
      "x": 4,
      "y": 9,
      "z": 8,
      "name": "Rock_Basalt_Cobble"
    },
    {
      "x": 5,
      "y": 0,
      "z": -1,
      "name": "Rock_Basalt_Brick"
    },
    {
      "x": 5,
      "y": 1,
      "z": -1,
      "name": "Rock_Basalt_Brick"
    },
    {
      "x": 5,
      "y": 2,
      "z": -1,
      "name": "Rock_Basalt_Brick"
    },
    {
      "x": 5,
      "y": 3,
      "z": -1,
      "name": "Rock_Basalt_Brick"
    },
    {
      "x": 5,
      "y": 4,
      "z": -1,
      "name": "Rock_Basalt_Brick"
    },
    {
      "x": 5,
      "y": 5,
      "z": -1,
      "name": "Rock_Basalt_Cobble"
    },
    {
      "x": 5,
      "y": 6,
      "z": -1,
      "name": "Rock_Basalt_Cobble"
    },
    {
      "x": 5,
      "y": 7,
      "z": -1,
      "name": "Rock_Basalt_Cobble"
    },
    {
      "x": 5,
      "y": 8,
      "z": -1,
      "name": "Rock_Basalt_Cobble"
    },
    {
      "x": 5,
      "y": 9,
      "z": -1,
      "name": "Rock_Basalt_Cobble"
    },
    {
      "x": 5,
      "y": 0,
      "z": 0,
      "name": "Rock_Basalt_Brick"
    },
    {
      "x": 5,
      "y": 1,
      "z": 0,
      "name": "Rock_Basalt_Brick"
    },
    {
      "x": 5,
      "y": 2,
      "z": 0,
      "name": "Rock_Basalt_Brick"
    },
    {
      "x": 5,
      "y": 3,
      "z": 0,
      "name": "Rock_Basalt_Brick"
    },
    {
      "x": 5,
      "y": 4,
      "z": 0,
      "name": "Rock_Basalt_Brick"
    },
    {
      "x": 5,
      "y": 5,
      "z": 0,
      "name": "Rock_Basalt_Brick"
    },
    {
      "x": 5,
      "y": 6,
      "z": 0,
      "name": "Rock_Basalt_Brick"
    },
    {
      "x": 5,
      "y": 7,
      "z": 0,
      "name": "Rock_Basalt_Brick"
    },
    {
      "x": 5,
      "y": 8,
      "z": 0,
      "name": "Rock_Basalt_Brick"
    },
    {
      "x": 5,
      "y": 9,
      "z": 0,
      "name": "Rock_Basalt_Cobble"
    },
    {
      "x": 5,
      "y": 0,
      "z": 1,
      "name": "Rock_Basalt_Brick"
    },
    {
      "x": 5,
      "y": 1,
      "z": 1,
      "name": "Rock_Basalt_Brick"
    },
    {
      "x": 5,
      "y": 2,
      "z": 1,
      "name": "Rock_Basalt_Brick"
    },
    {
      "x": 5,
      "y": 3,
      "z": 1,
      "name": "Rock_Basalt_Brick"
    },
    {
      "x": 5,
      "y": 4,
      "z": 1,
      "name": "Rock_Basalt_Brick"
    },
    {
      "x": 5,
      "y": 7,
      "z": 1,
      "name": "Rock_Basalt_Brick_Half",
      "rotation": 4
    },
    {
      "x": 5,
      "y": 8,
      "z": 1,
      "name": "Rock_Basalt_Brick"
    },
    {
      "x": 5,
      "y": 9,
      "z": 1,
      "name": "Rock_Basalt_Cobble"
    },
    {
      "x": 5,
      "y": 0,
      "z": 2,
      "name": "Rock_Basalt_Brick"
    },
    {
      "x": 5,
      "y": 1,
      "z": 2,
      "name": "Rock_Basalt_Brick"
    },
    {
      "x": 5,
      "y": 2,
      "z": 2,
      "name": "Rock_Basalt_Brick"
    },
    {
      "x": 5,
      "y": 3,
      "z": 2,
      "name": "Rock_Basalt_Brick_Stairs",
      "rotation": 1
    },
    {
      "x": 5,
      "y": 7,
      "z": 2,
      "name": "Empty"
    },
    {
      "x": 5,
      "y": 8,
      "z": 2,
      "name": "Rock_Basalt_Brick"
    },
    {
      "x": 5,
      "y": 9,
      "z": 2,
      "name": "Rock_Basalt_Cobble"
    },
    {
      "x": 5,
      "y": 0,
      "z": 3,
      "name": "Rock_Basalt_Brick"
    },
    {
      "x": 5,
      "y": 1,
      "z": 3,
      "name": "Rock_Basalt_Brick"
    },
    {
      "x": 5,
      "y": 2,
      "z": 3,
      "name": "Rock_Basalt_Brick_Stairs",
      "rotation": 3
    },
    {
      "x": 5,
      "y": 7,
      "z": 3,
      "name": "Empty"
    },
    {
      "x": 5,
      "y": 8,
      "z": 3,
      "name": "Rock_Basalt_Brick_Half",
      "rotation": 8
    },
    {
      "x": 5,
      "y": 9,
      "z": 3,
      "name": "Rock_Basalt_Brick"
    },
    {
      "x": 5,
      "y": 0,
      "z": 4,
      "name": "Soil_Dirt_Poisoned"
    },
    {
      "x": 5,
      "y": 7,
      "z": 4,
      "name": "Empty"
    },
    {
      "x": 5,
      "y": 8,
      "z": 4,
      "name": "Rock_Basalt_Brick_Half",
      "rotation": 8
    },
    {
      "x": 5,
      "y": 9,
      "z": 4,
      "name": "Rock_Basalt_Brick"
    },
    {
      "x": 5,
      "y": 0,
      "z": 5,
      "name": "Soil_Dirt_Poisoned"
    },
    {
      "x": 5,
      "y": 7,
      "z": 5,
      "name": "Empty"
    },
    {
      "x": 5,
      "y": 8,
      "z": 5,
      "name": "Rock_Basalt_Brick"
    },
    {
      "x": 5,
      "y": 9,
      "z": 5,
      "name": "Rock_Basalt_Cobble"
    },
    {
      "x": 5,
      "y": 0,
      "z": 6,
      "name": "Soil_Dirt_Poisoned"
    },
    {
      "x": 5,
      "y": 7,
      "z": 6,
      "name": "Rock_Basalt_Brick_Half",
      "rotation": 6
    },
    {
      "x": 5,
      "y": 8,
      "z": 6,
      "name": "Rock_Basalt_Brick"
    },
    {
      "x": 5,
      "y": 9,
      "z": 6,
      "name": "Rock_Basalt_Cobble"
    },
    {
      "x": 5,
      "y": 0,
      "z": 7,
      "name": "Soil_Dirt_Poisoned"
    },
    {
      "x": 5,
      "y": 1,
      "z": 7,
      "name": "Rock_Basalt_Brick"
    },
    {
      "x": 5,
      "y": 2,
      "z": 7,
      "name": "Rock_Basalt_Brick"
    },
    {
      "x": 5,
      "y": 3,
      "z": 7,
      "name": "Rock_Basalt_Brick"
    },
    {
      "x": 5,
      "y": 4,
      "z": 7,
      "name": "Rock_Basalt_Brick"
    },
    {
      "x": 5,
      "y": 5,
      "z": 7,
      "name": "Rock_Basalt_Brick"
    },
    {
      "x": 5,
      "y": 6,
      "z": 7,
      "name": "Rock_Basalt_Brick"
    },
    {
      "x": 5,
      "y": 7,
      "z": 7,
      "name": "Rock_Basalt_Brick"
    },
    {
      "x": 5,
      "y": 8,
      "z": 7,
      "name": "Rock_Basalt_Brick"
    },
    {
      "x": 5,
      "y": 9,
      "z": 7,
      "name": "Rock_Basalt_Cobble"
    },
    {
      "x": 5,
      "y": 0,
      "z": 8,
      "name": "Rock_Basalt_Cobble"
    },
    {
      "x": 5,
      "y": 1,
      "z": 8,
      "name": "Rock_Basalt_Cobble"
    },
    {
      "x": 5,
      "y": 2,
      "z": 8,
      "name": "Rock_Basalt_Cobble"
    },
    {
      "x": 5,
      "y": 3,
      "z": 8,
      "name": "Rock_Basalt_Cobble"
    },
    {
      "x": 5,
      "y": 4,
      "z": 8,
      "name": "Rock_Basalt_Cobble"
    },
    {
      "x": 5,
      "y": 5,
      "z": 8,
      "name": "Rock_Basalt_Cobble"
    },
    {
      "x": 5,
      "y": 6,
      "z": 8,
      "name": "Rock_Basalt_Cobble"
    },
    {
      "x": 5,
      "y": 7,
      "z": 8,
      "name": "Rock_Basalt_Cobble"
    },
    {
      "x": 5,
      "y": 8,
      "z": 8,
      "name": "Rock_Basalt_Cobble"
    },
    {
      "x": 5,
      "y": 9,
      "z": 8,
      "name": "Rock_Basalt_Cobble"
    },
    {
      "x": 6,
      "y": 0,
      "z": -1,
      "name": "Rock_Basalt_Brick"
    },
    {
      "x": 6,
      "y": 1,
      "z": -1,
      "name": "Rock_Basalt_Brick"
    },
    {
      "x": 6,
      "y": 2,
      "z": -1,
      "name": "Rock_Basalt_Brick"
    },
    {
      "x": 6,
      "y": 3,
      "z": -1,
      "name": "Rock_Basalt_Brick"
    },
    {
      "x": 6,
      "y": 4,
      "z": -1,
      "name": "Rock_Basalt_Brick"
    },
    {
      "x": 6,
      "y": 5,
      "z": -1,
      "name": "Rock_Basalt_Cobble"
    },
    {
      "x": 6,
      "y": 6,
      "z": -1,
      "name": "Rock_Basalt_Cobble"
    },
    {
      "x": 6,
      "y": 7,
      "z": -1,
      "name": "Rock_Basalt_Cobble"
    },
    {
      "x": 6,
      "y": 8,
      "z": -1,
      "name": "Rock_Basalt_Cobble"
    },
    {
      "x": 6,
      "y": 9,
      "z": -1,
      "name": "Rock_Basalt_Cobble"
    },
    {
      "x": 6,
      "y": 0,
      "z": 0,
      "name": "Rock_Basalt_Brick"
    },
    {
      "x": 6,
      "y": 1,
      "z": 0,
      "name": "Rock_Basalt_Cobble"
    },
    {
      "x": 6,
      "y": 2,
      "z": 0,
      "name": "Rock_Basalt_Cobble"
    },
    {
      "x": 6,
      "y": 3,
      "z": 0,
      "name": "Rock_Basalt_Cobble"
    },
    {
      "x": 6,
      "y": 4,
      "z": 0,
      "name": "Rock_Basalt_Cobble"
    },
    {
      "x": 6,
      "y": 5,
      "z": 0,
      "name": "Rock_Basalt_Cobble"
    },
    {
      "x": 6,
      "y": 6,
      "z": 0,
      "name": "Rock_Basalt_Cobble"
    },
    {
      "x": 6,
      "y": 7,
      "z": 0,
      "name": "Rock_Basalt_Cobble"
    },
    {
      "x": 6,
      "y": 8,
      "z": 0,
      "name": "Rock_Basalt_Cobble"
    },
    {
      "x": 6,
      "y": 9,
      "z": 0,
      "name": "Rock_Basalt_Cobble"
    },
    {
      "x": 6,
      "y": 0,
      "z": 1,
      "name": "Rock_Basalt_Brick"
    },
    {
      "x": 6,
      "y": 1,
      "z": 1,
      "name": "Rock_Basalt_Cobble"
    },
    {
      "x": 6,
      "y": 2,
      "z": 1,
      "name": "Rock_Basalt_Cobble"
    },
    {
      "x": 6,
      "y": 3,
      "z": 1,
      "name": "Rock_Basalt_Cobble"
    },
    {
      "x": 6,
      "y": 4,
      "z": 1,
      "name": "Rock_Basalt_Cobble"
    },
    {
      "x": 6,
      "y": 5,
      "z": 1,
      "name": "Rock_Basalt_Cobble"
    },
    {
      "x": 6,
      "y": 6,
      "z": 1,
      "name": "Rock_Basalt_Cobble"
    },
    {
      "x": 6,
      "y": 7,
      "z": 1,
      "name": "Rock_Basalt_Cobble"
    },
    {
      "x": 6,
      "y": 8,
      "z": 1,
      "name": "Rock_Basalt_Cobble"
    },
    {
      "x": 6,
      "y": 9,
      "z": 1,
      "name": "Rock_Basalt_Cobble"
    },
    {
      "x": 6,
      "y": 0,
      "z": 2,
      "name": "Rock_Basalt_Brick"
    },
    {
      "x": 6,
      "y": 1,
      "z": 2,
      "name": "Rock_Basalt_Cobble"
    },
    {
      "x": 6,
      "y": 2,
      "z": 2,
      "name": "Rock_Basalt_Cobble"
    },
    {
      "x": 6,
      "y": 3,
      "z": 2,
      "name": "Rock_Basalt_Cobble"
    },
    {
      "x": 6,
      "y": 4,
      "z": 2,
      "name": "Rock_Basalt_Cobble"
    },
    {
      "x": 6,
      "y": 5,
      "z": 2,
      "name": "Rock_Basalt_Cobble"
    },
    {
      "x": 6,
      "y": 6,
      "z": 2,
      "name": "Rock_Basalt_Cobble"
    },
    {
      "x": 6,
      "y": 7,
      "z": 2,
      "name": "Rock_Basalt_Cobble"
    },
    {
      "x": 6,
      "y": 8,
      "z": 2,
      "name": "Rock_Basalt_Cobble"
    },
    {
      "x": 6,
      "y": 9,
      "z": 2,
      "name": "Rock_Basalt_Cobble"
    },
    {
      "x": 6,
      "y": 0,
      "z": 3,
      "name": "Rock_Basalt_Brick"
    },
    {
      "x": 6,
      "y": 1,
      "z": 3,
      "name": "Rock_Basalt_Cobble"
    },
    {
      "x": 6,
      "y": 2,
      "z": 3,
      "name": "Rock_Basalt_Cobble"
    },
    {
      "x": 6,
      "y": 3,
      "z": 3,
      "name": "Rock_Basalt_Cobble"
    },
    {
      "x": 6,
      "y": 4,
      "z": 3,
      "name": "Rock_Basalt_Cobble"
    },
    {
      "x": 6,
      "y": 5,
      "z": 3,
      "name": "Rock_Basalt_Cobble"
    },
    {
      "x": 6,
      "y": 6,
      "z": 3,
      "name": "Rock_Basalt_Cobble"
    },
    {
      "x": 6,
      "y": 7,
      "z": 3,
      "name": "Rock_Basalt_Cobble"
    },
    {
      "x": 6,
      "y": 8,
      "z": 3,
      "name": "Rock_Basalt_Cobble"
    },
    {
      "x": 6,
      "y": 9,
      "z": 3,
      "name": "Rock_Basalt_Brick"
    },
    {
      "x": 6,
      "y": 0,
      "z": 4,
      "name": "Rock_Basalt_Cobble"
    },
    {
      "x": 6,
      "y": 1,
      "z": 4,
      "name": "Rock_Basalt_Cobble"
    },
    {
      "x": 6,
      "y": 2,
      "z": 4,
      "name": "Rock_Basalt_Cobble"
    },
    {
      "x": 6,
      "y": 3,
      "z": 4,
      "name": "Rock_Basalt_Cobble"
    },
    {
      "x": 6,
      "y": 4,
      "z": 4,
      "name": "Rock_Basalt_Cobble"
    },
    {
      "x": 6,
      "y": 5,
      "z": 4,
      "name": "Rock_Basalt_Cobble"
    },
    {
      "x": 6,
      "y": 6,
      "z": 4,
      "name": "Rock_Basalt_Cobble"
    },
    {
      "x": 6,
      "y": 7,
      "z": 4,
      "name": "Rock_Basalt_Cobble"
    },
    {
      "x": 6,
      "y": 8,
      "z": 4,
      "name": "Rock_Basalt_Cobble"
    },
    {
      "x": 6,
      "y": 9,
      "z": 4,
      "name": "Rock_Basalt_Brick"
    },
    {
      "x": 6,
      "y": 0,
      "z": 5,
      "name": "Rock_Basalt_Cobble"
    },
    {
      "x": 6,
      "y": 1,
      "z": 5,
      "name": "Rock_Basalt_Cobble"
    },
    {
      "x": 6,
      "y": 2,
      "z": 5,
      "name": "Rock_Basalt_Cobble"
    },
    {
      "x": 6,
      "y": 3,
      "z": 5,
      "name": "Rock_Basalt_Cobble"
    },
    {
      "x": 6,
      "y": 4,
      "z": 5,
      "name": "Rock_Basalt_Cobble"
    },
    {
      "x": 6,
      "y": 5,
      "z": 5,
      "name": "Rock_Basalt_Cobble"
    },
    {
      "x": 6,
      "y": 6,
      "z": 5,
      "name": "Rock_Basalt_Cobble"
    },
    {
      "x": 6,
      "y": 7,
      "z": 5,
      "name": "Rock_Basalt_Cobble"
    },
    {
      "x": 6,
      "y": 8,
      "z": 5,
      "name": "Rock_Basalt_Cobble"
    },
    {
      "x": 6,
      "y": 9,
      "z": 5,
      "name": "Rock_Basalt_Cobble"
    },
    {
      "x": 6,
      "y": 0,
      "z": 6,
      "name": "Rock_Basalt_Cobble"
    },
    {
      "x": 6,
      "y": 1,
      "z": 6,
      "name": "Rock_Basalt_Cobble"
    },
    {
      "x": 6,
      "y": 2,
      "z": 6,
      "name": "Rock_Basalt_Cobble"
    },
    {
      "x": 6,
      "y": 3,
      "z": 6,
      "name": "Rock_Basalt_Cobble"
    },
    {
      "x": 6,
      "y": 4,
      "z": 6,
      "name": "Rock_Basalt_Cobble"
    },
    {
      "x": 6,
      "y": 5,
      "z": 6,
      "name": "Rock_Basalt_Cobble"
    },
    {
      "x": 6,
      "y": 6,
      "z": 6,
      "name": "Rock_Basalt_Cobble"
    },
    {
      "x": 6,
      "y": 7,
      "z": 6,
      "name": "Rock_Basalt_Cobble"
    },
    {
      "x": 6,
      "y": 8,
      "z": 6,
      "name": "Rock_Basalt_Cobble"
    },
    {
      "x": 6,
      "y": 9,
      "z": 6,
      "name": "Rock_Basalt_Cobble"
    },
    {
      "x": 6,
      "y": 0,
      "z": 7,
      "name": "Rock_Basalt_Cobble"
    },
    {
      "x": 6,
      "y": 1,
      "z": 7,
      "name": "Rock_Basalt_Cobble"
    },
    {
      "x": 6,
      "y": 2,
      "z": 7,
      "name": "Rock_Basalt_Cobble"
    },
    {
      "x": 6,
      "y": 3,
      "z": 7,
      "name": "Rock_Basalt_Cobble"
    },
    {
      "x": 6,
      "y": 4,
      "z": 7,
      "name": "Rock_Basalt_Cobble"
    },
    {
      "x": 6,
      "y": 5,
      "z": 7,
      "name": "Rock_Basalt_Cobble"
    },
    {
      "x": 6,
      "y": 6,
      "z": 7,
      "name": "Rock_Basalt_Cobble"
    },
    {
      "x": 6,
      "y": 7,
      "z": 7,
      "name": "Rock_Basalt_Cobble"
    },
    {
      "x": 6,
      "y": 8,
      "z": 7,
      "name": "Rock_Basalt_Cobble"
    },
    {
      "x": 6,
      "y": 9,
      "z": 7,
      "name": "Rock_Basalt_Cobble"
    },
    {
      "x": 6,
      "y": 0,
      "z": 8,
      "name": "Rock_Basalt_Cobble"
    },
    {
      "x": 6,
      "y": 1,
      "z": 8,
      "name": "Rock_Basalt_Cobble"
    },
    {
      "x": 6,
      "y": 2,
      "z": 8,
      "name": "Rock_Basalt_Cobble"
    },
    {
      "x": 6,
      "y": 3,
      "z": 8,
      "name": "Rock_Basalt_Cobble"
    },
    {
      "x": 6,
      "y": 4,
      "z": 8,
      "name": "Rock_Basalt_Cobble"
    },
    {
      "x": 6,
      "y": 5,
      "z": 8,
      "name": "Rock_Basalt_Cobble"
    },
    {
      "x": 6,
      "y": 6,
      "z": 8,
      "name": "Rock_Basalt_Cobble"
    },
    {
      "x": 6,
      "y": 7,
      "z": 8,
      "name": "Rock_Basalt_Cobble"
    },
    {
      "x": 6,
      "y": 8,
      "z": 8,
      "name": "Rock_Basalt_Cobble"
    },
    {
      "x": 6,
      "y": 9,
      "z": 8,
      "name": "Rock_Basalt_Cobble"
    }
  ],
  "fluids": [
    {
      "x": -2,
      "y": 5,
      "z": 1,
      "name": "Water_Source",
      "level": 1
    },
    {
      "x": -2,
      "y": 6,
      "z": 1,
      "name": "Water_Source",
      "level": 1
    },
    {
      "x": -2,
      "y": 3,
      "z": 2,
      "name": "Water",
      "level": 8
    },
    {
      "x": -2,
      "y": 4,
      "z": 2,
      "name": "Water_Source",
      "level": 1
    },
    {
      "x": -2,
      "y": 5,
      "z": 2,
      "name": "Water_Source",
      "level": 1
    },
    {
      "x": -2,
      "y": 6,
      "z": 2,
      "name": "Water_Source",
      "level": 1
    },
    {
      "x": -2,
      "y": 2,
      "z": 3,
      "name": "Water",
      "level": 8
    },
    {
      "x": -2,
      "y": 3,
      "z": 3,
      "name": "Water_Source",
      "level": 1
    },
    {
      "x": -2,
      "y": 4,
      "z": 3,
      "name": "Water_Source",
      "level": 1
    },
    {
      "x": -2,
      "y": 5,
      "z": 3,
      "name": "Water_Source",
      "level": 1
    },
    {
      "x": -2,
      "y": 6,
      "z": 3,
      "name": "Water_Source",
      "level": 1
    },
    {
      "x": -2,
      "y": 1,
      "z": 4,
      "name": "Water_Source",
      "level": 1
    },
    {
      "x": -2,
      "y": 2,
      "z": 4,
      "name": "Water_Source",
      "level": 1
    },
    {
      "x": -2,
      "y": 3,
      "z": 4,
      "name": "Water_Source",
      "level": 1
    },
    {
      "x": -2,
      "y": 4,
      "z": 4,
      "name": "Water_Source",
      "level": 1
    },
    {
      "x": -2,
      "y": 5,
      "z": 4,
      "name": "Water_Source",
      "level": 1
    },
    {
      "x": -2,
      "y": 6,
      "z": 4,
      "name": "Water_Source",
      "level": 1
    },
    {
      "x": -2,
      "y": 1,
      "z": 5,
      "name": "Water",
      "level": 8
    },
    {
      "x": -2,
      "y": 2,
      "z": 5,
      "name": "Water_Source",
      "level": 1
    },
    {
      "x": -2,
      "y": 3,
      "z": 5,
      "name": "Water_Source",
      "level": 1
    },
    {
      "x": -2,
      "y": 4,
      "z": 5,
      "name": "Water_Source",
      "level": 1
    },
    {
      "x": -2,
      "y": 5,
      "z": 5,
      "name": "Water_Source",
      "level": 1
    },
    {
      "x": -2,
      "y": 6,
      "z": 5,
      "name": "Water_Source",
      "level": 1
    },
    {
      "x": -2,
      "y": 1,
      "z": 6,
      "name": "Water",
      "level": 8
    },
    {
      "x": -2,
      "y": 2,
      "z": 6,
      "name": "Water",
      "level": 8
    },
    {
      "x": -2,
      "y": 3,
      "z": 6,
      "name": "Water_Source",
      "level": 1
    },
    {
      "x": -2,
      "y": 4,
      "z": 6,
      "name": "Water_Source",
      "level": 1
    },
    {
      "x": -2,
      "y": 5,
      "z": 6,
      "name": "Water_Source",
      "level": 1
    },
    {
      "x": -2,
      "y": 6,
      "z": 6,
      "name": "Water_Source",
      "level": 1
    },
    {
      "x": -1,
      "y": 5,
      "z": 0,
      "name": "Water_Source",
      "level": 1
    },
    {
      "x": -1,
      "y": 6,
      "z": 0,
      "name": "Water_Source",
      "level": 1
    },
    {
      "x": -1,
      "y": 5,
      "z": 1,
      "name": "Water_Source",
      "level": 1
    },
    {
      "x": -1,
      "y": 6,
      "z": 1,
      "name": "Water_Source",
      "level": 1
    },
    {
      "x": -1,
      "y": 4,
      "z": 2,
      "name": "Water",
      "level": 8
    },
    {
      "x": -1,
      "y": 5,
      "z": 2,
      "name": "Water_Source",
      "level": 1
    },
    {
      "x": -1,
      "y": 6,
      "z": 2,
      "name": "Water_Source",
      "level": 1
    },
    {
      "x": -1,
      "y": 1,
      "z": 3,
      "name": "Water",
      "level": 8
    },
    {
      "x": -1,
      "y": 2,
      "z": 3,
      "name": "Water_Source",
      "level": 1
    },
    {
      "x": -1,
      "y": 3,
      "z": 3,
      "name": "Water_Source",
      "level": 1
    },
    {
      "x": -1,
      "y": 4,
      "z": 3,
      "name": "Water_Source",
      "level": 1
    },
    {
      "x": -1,
      "y": 5,
      "z": 3,
      "name": "Water_Source",
      "level": 1
    },
    {
      "x": -1,
      "y": 6,
      "z": 3,
      "name": "Water_Source",
      "level": 1
    },
    {
      "x": -1,
      "y": 1,
      "z": 4,
      "name": "Water_Source",
      "level": 1
    },
    {
      "x": -1,
      "y": 2,
      "z": 4,
      "name": "Water_Source",
      "level": 1
    },
    {
      "x": -1,
      "y": 3,
      "z": 4,
      "name": "Water_Source",
      "level": 1
    },
    {
      "x": -1,
      "y": 4,
      "z": 4,
      "name": "Water_Source",
      "level": 1
    },
    {
      "x": -1,
      "y": 5,
      "z": 4,
      "name": "Water_Source",
      "level": 1
    },
    {
      "x": -1,
      "y": 6,
      "z": 4,
      "name": "Water_Source",
      "level": 1
    },
    {
      "x": -1,
      "y": 1,
      "z": 5,
      "name": "Water_Source",
      "level": 1
    },
    {
      "x": -1,
      "y": 2,
      "z": 5,
      "name": "Water_Source",
      "level": 1
    },
    {
      "x": -1,
      "y": 3,
      "z": 5,
      "name": "Water_Source",
      "level": 1
    },
    {
      "x": -1,
      "y": 4,
      "z": 5,
      "name": "Water_Source",
      "level": 1
    },
    {
      "x": -1,
      "y": 5,
      "z": 5,
      "name": "Water_Source",
      "level": 1
    },
    {
      "x": -1,
      "y": 6,
      "z": 5,
      "name": "Water_Source",
      "level": 1
    },
    {
      "x": -1,
      "y": 1,
      "z": 6,
      "name": "Water_Source",
      "level": 1
    },
    {
      "x": -1,
      "y": 2,
      "z": 6,
      "name": "Water_Source",
      "level": 1
    },
    {
      "x": -1,
      "y": 3,
      "z": 6,
      "name": "Water_Source",
      "level": 1
    },
    {
      "x": -1,
      "y": 4,
      "z": 6,
      "name": "Water_Source",
      "level": 1
    },
    {
      "x": -1,
      "y": 5,
      "z": 6,
      "name": "Water_Source",
      "level": 1
    },
    {
      "x": -1,
      "y": 6,
      "z": 6,
      "name": "Water_Source",
      "level": 1
    },
    {
      "x": -1,
      "y": 1,
      "z": 7,
      "name": "Water",
      "level": 8
    },
    {
      "x": -1,
      "y": 2,
      "z": 7,
      "name": "Water",
      "level": 8
    },
    {
      "x": -1,
      "y": 3,
      "z": 7,
      "name": "Water_Source",
      "level": 1
    },
    {
      "x": -1,
      "y": 4,
      "z": 7,
      "name": "Water_Source",
      "level": 1
    },
    {
      "x": -1,
      "y": 5,
      "z": 7,
      "name": "Water_Source",
      "level": 1
    },
    {
      "x": -1,
      "y": 6,
      "z": 7,
      "name": "Water",
      "level": 8
    },
    {
      "x": 0,
      "y": 5,
      "z": 0,
      "name": "Water",
      "level": 8
    },
    {
      "x": 0,
      "y": 5,
      "z": 1,
      "name": "Water_Source",
      "level": 1
    },
    {
      "x": 0,
      "y": 6,
      "z": 1,
      "name": "Water_Source",
      "level": 1
    },
    {
      "x": 0,
      "y": 5,
      "z": 2,
      "name": "Water_Source",
      "level": 1
    },
    {
      "x": 0,
      "y": 6,
      "z": 2,
      "name": "Water_Source",
      "level": 1
    },
    {
      "x": 0,
      "y": 5,
      "z": 3,
      "name": "Water_Source",
      "level": 1
    },
    {
      "x": 0,
      "y": 6,
      "z": 3,
      "name": "Water_Source",
      "level": 1
    },
    {
      "x": 0,
      "y": 1,
      "z": 4,
      "name": "Water_Source",
      "level": 1
    },
    {
      "x": 0,
      "y": 2,
      "z": 4,
      "name": "Water_Source",
      "level": 1
    },
    {
      "x": 0,
      "y": 3,
      "z": 4,
      "name": "Water_Source",
      "level": 1
    },
    {
      "x": 0,
      "y": 4,
      "z": 4,
      "name": "Water_Source",
      "level": 1
    },
    {
      "x": 0,
      "y": 5,
      "z": 4,
      "name": "Water_Source",
      "level": 1
    },
    {
      "x": 0,
      "y": 6,
      "z": 4,
      "name": "Water_Source",
      "level": 1
    },
    {
      "x": 0,
      "y": 1,
      "z": 5,
      "name": "Water_Source",
      "level": 1
    },
    {
      "x": 0,
      "y": 2,
      "z": 5,
      "name": "Water_Source",
      "level": 1
    },
    {
      "x": 0,
      "y": 3,
      "z": 5,
      "name": "Water_Source",
      "level": 1
    },
    {
      "x": 0,
      "y": 4,
      "z": 5,
      "name": "Water_Source",
      "level": 1
    },
    {
      "x": 0,
      "y": 5,
      "z": 5,
      "name": "Water_Source",
      "level": 1
    },
    {
      "x": 0,
      "y": 6,
      "z": 5,
      "name": "Water_Source",
      "level": 1
    },
    {
      "x": 0,
      "y": 1,
      "z": 6,
      "name": "Water_Source",
      "level": 1
    },
    {
      "x": 0,
      "y": 2,
      "z": 6,
      "name": "Water_Source",
      "level": 1
    },
    {
      "x": 0,
      "y": 3,
      "z": 6,
      "name": "Water_Source",
      "level": 1
    },
    {
      "x": 0,
      "y": 4,
      "z": 6,
      "name": "Water_Source",
      "level": 1
    },
    {
      "x": 0,
      "y": 5,
      "z": 6,
      "name": "Water_Source",
      "level": 1
    },
    {
      "x": 0,
      "y": 6,
      "z": 6,
      "name": "Water_Source",
      "level": 1
    },
    {
      "x": 0,
      "y": 1,
      "z": 7,
      "name": "Water_Source",
      "level": 1
    },
    {
      "x": 0,
      "y": 2,
      "z": 7,
      "name": "Water_Source",
      "level": 1
    },
    {
      "x": 0,
      "y": 3,
      "z": 7,
      "name": "Water_Source",
      "level": 1
    },
    {
      "x": 0,
      "y": 4,
      "z": 7,
      "name": "Water_Source",
      "level": 1
    },
    {
      "x": 0,
      "y": 5,
      "z": 7,
      "name": "Water_Source",
      "level": 1
    },
    {
      "x": 0,
      "y": 6,
      "z": 7,
      "name": "Water_Source",
      "level": 1
    },
    {
      "x": 1,
      "y": 6,
      "z": -2,
      "name": "Water_Source",
      "level": 1
    },
    {
      "x": 1,
      "y": 6,
      "z": -1,
      "name": "Water_Source",
      "level": 1
    },
    {
      "x": 1,
      "y": 7,
      "z": -1,
      "name": "Water_Source",
      "level": 1
    },
    {
      "x": 1,
      "y": 6,
      "z": 0,
      "name": "Water_Source",
      "level": 1
    },
    {
      "x": 1,
      "y": 5,
      "z": 1,
      "name": "Water_Source",
      "level": 1
    },
    {
      "x": 1,
      "y": 6,
      "z": 1,
      "name": "Water_Source",
      "level": 1
    },
    {
      "x": 1,
      "y": 5,
      "z": 2,
      "name": "Water_Source",
      "level": 1
    },
    {
      "x": 1,
      "y": 6,
      "z": 2,
      "name": "Water_Source",
      "level": 1
    },
    {
      "x": 1,
      "y": 5,
      "z": 3,
      "name": "Water_Source",
      "level": 1
    },
    {
      "x": 1,
      "y": 6,
      "z": 3,
      "name": "Water_Source",
      "level": 1
    },
    {
      "x": 1,
      "y": 1,
      "z": 4,
      "name": "Water_Source",
      "level": 1
    },
    {
      "x": 1,
      "y": 2,
      "z": 4,
      "name": "Water_Source",
      "level": 1
    },
    {
      "x": 1,
      "y": 3,
      "z": 4,
      "name": "Water_Source",
      "level": 1
    },
    {
      "x": 1,
      "y": 4,
      "z": 4,
      "name": "Water_Source",
      "level": 1
    },
    {
      "x": 1,
      "y": 5,
      "z": 4,
      "name": "Water_Source",
      "level": 1
    },
    {
      "x": 1,
      "y": 6,
      "z": 4,
      "name": "Water_Source",
      "level": 1
    },
    {
      "x": 1,
      "y": 1,
      "z": 5,
      "name": "Water_Source",
      "level": 1
    },
    {
      "x": 1,
      "y": 2,
      "z": 5,
      "name": "Water_Source",
      "level": 1
    },
    {
      "x": 1,
      "y": 3,
      "z": 5,
      "name": "Water_Source",
      "level": 1
    },
    {
      "x": 1,
      "y": 4,
      "z": 5,
      "name": "Water_Source",
      "level": 1
    },
    {
      "x": 1,
      "y": 5,
      "z": 5,
      "name": "Water_Source",
      "level": 1
    },
    {
      "x": 1,
      "y": 6,
      "z": 5,
      "name": "Water_Source",
      "level": 1
    },
    {
      "x": 1,
      "y": 1,
      "z": 6,
      "name": "Water_Source",
      "level": 1
    },
    {
      "x": 1,
      "y": 2,
      "z": 6,
      "name": "Water_Source",
      "level": 1
    },
    {
      "x": 1,
      "y": 3,
      "z": 6,
      "name": "Water_Source",
      "level": 1
    },
    {
      "x": 1,
      "y": 4,
      "z": 6,
      "name": "Water_Source",
      "level": 1
    },
    {
      "x": 1,
      "y": 5,
      "z": 6,
      "name": "Water_Source",
      "level": 1
    },
    {
      "x": 1,
      "y": 6,
      "z": 6,
      "name": "Water_Source",
      "level": 1
    },
    {
      "x": 1,
      "y": 1,
      "z": 7,
      "name": "Water_Source",
      "level": 1
    },
    {
      "x": 1,
      "y": 2,
      "z": 7,
      "name": "Water_Source",
      "level": 1
    },
    {
      "x": 1,
      "y": 3,
      "z": 7,
      "name": "Water_Source",
      "level": 1
    },
    {
      "x": 1,
      "y": 4,
      "z": 7,
      "name": "Water_Source",
      "level": 1
    },
    {
      "x": 1,
      "y": 5,
      "z": 7,
      "name": "Water_Source",
      "level": 1
    },
    {
      "x": 1,
      "y": 6,
      "z": 7,
      "name": "Water_Source",
      "level": 1
    },
    {
      "x": 2,
      "y": 6,
      "z": -1,
      "name": "Water_Source",
      "level": 1
    },
    {
      "x": 2,
      "y": 7,
      "z": -1,
      "name": "Water_Source",
      "level": 1
    },
    {
      "x": 2,
      "y": 6,
      "z": 0,
      "name": "Water_Source",
      "level": 1
    },
    {
      "x": 2,
      "y": 5,
      "z": 1,
      "name": "Water_Source",
      "level": 1
    },
    {
      "x": 2,
      "y": 6,
      "z": 1,
      "name": "Water_Source",
      "level": 1
    },
    {
      "x": 2,
      "y": 5,
      "z": 2,
      "name": "Water_Source",
      "level": 1
    },
    {
      "x": 2,
      "y": 6,
      "z": 2,
      "name": "Water_Source",
      "level": 1
    },
    {
      "x": 2,
      "y": 5,
      "z": 3,
      "name": "Water_Source",
      "level": 1
    },
    {
      "x": 2,
      "y": 6,
      "z": 3,
      "name": "Water_Source",
      "level": 1
    },
    {
      "x": 2,
      "y": 1,
      "z": 4,
      "name": "Water_Source",
      "level": 1
    },
    {
      "x": 2,
      "y": 2,
      "z": 4,
      "name": "Water_Source",
      "level": 1
    },
    {
      "x": 2,
      "y": 3,
      "z": 4,
      "name": "Water_Source",
      "level": 1
    },
    {
      "x": 2,
      "y": 4,
      "z": 4,
      "name": "Water_Source",
      "level": 1
    },
    {
      "x": 2,
      "y": 5,
      "z": 4,
      "name": "Water_Source",
      "level": 1
    },
    {
      "x": 2,
      "y": 6,
      "z": 4,
      "name": "Water_Source",
      "level": 1
    },
    {
      "x": 2,
      "y": 1,
      "z": 5,
      "name": "Water_Source",
      "level": 1
    },
    {
      "x": 2,
      "y": 2,
      "z": 5,
      "name": "Water_Source",
      "level": 1
    },
    {
      "x": 2,
      "y": 3,
      "z": 5,
      "name": "Water_Source",
      "level": 1
    },
    {
      "x": 2,
      "y": 4,
      "z": 5,
      "name": "Water_Source",
      "level": 1
    },
    {
      "x": 2,
      "y": 5,
      "z": 5,
      "name": "Water_Source",
      "level": 1
    },
    {
      "x": 2,
      "y": 6,
      "z": 5,
      "name": "Water_Source",
      "level": 1
    },
    {
      "x": 2,
      "y": 1,
      "z": 6,
      "name": "Water_Source",
      "level": 1
    },
    {
      "x": 2,
      "y": 2,
      "z": 6,
      "name": "Water_Source",
      "level": 1
    },
    {
      "x": 2,
      "y": 3,
      "z": 6,
      "name": "Water_Source",
      "level": 1
    },
    {
      "x": 2,
      "y": 4,
      "z": 6,
      "name": "Water_Source",
      "level": 1
    },
    {
      "x": 2,
      "y": 5,
      "z": 6,
      "name": "Water_Source",
      "level": 1
    },
    {
      "x": 2,
      "y": 6,
      "z": 6,
      "name": "Water_Source",
      "level": 1
    },
    {
      "x": 2,
      "y": 1,
      "z": 7,
      "name": "Water_Source",
      "level": 1
    },
    {
      "x": 2,
      "y": 2,
      "z": 7,
      "name": "Water_Source",
      "level": 1
    },
    {
      "x": 2,
      "y": 3,
      "z": 7,
      "name": "Water_Source",
      "level": 1
    },
    {
      "x": 2,
      "y": 4,
      "z": 7,
      "name": "Water_Source",
      "level": 1
    },
    {
      "x": 2,
      "y": 5,
      "z": 7,
      "name": "Water_Source",
      "level": 1
    },
    {
      "x": 2,
      "y": 6,
      "z": 7,
      "name": "Water_Source",
      "level": 1
    },
    {
      "x": 3,
      "y": 5,
      "z": 0,
      "name": "Water",
      "level": 8
    },
    {
      "x": 3,
      "y": 5,
      "z": 1,
      "name": "Water_Source",
      "level": 1
    },
    {
      "x": 3,
      "y": 6,
      "z": 1,
      "name": "Water_Source",
      "level": 1
    },
    {
      "x": 3,
      "y": 5,
      "z": 2,
      "name": "Water_Source",
      "level": 1
    },
    {
      "x": 3,
      "y": 6,
      "z": 2,
      "name": "Water_Source",
      "level": 1
    },
    {
      "x": 3,
      "y": 5,
      "z": 3,
      "name": "Water_Source",
      "level": 1
    },
    {
      "x": 3,
      "y": 6,
      "z": 3,
      "name": "Water_Source",
      "level": 1
    },
    {
      "x": 3,
      "y": 1,
      "z": 4,
      "name": "Water_Source",
      "level": 1
    },
    {
      "x": 3,
      "y": 2,
      "z": 4,
      "name": "Water_Source",
      "level": 1
    },
    {
      "x": 3,
      "y": 3,
      "z": 4,
      "name": "Water_Source",
      "level": 1
    },
    {
      "x": 3,
      "y": 4,
      "z": 4,
      "name": "Water_Source",
      "level": 1
    },
    {
      "x": 3,
      "y": 5,
      "z": 4,
      "name": "Water_Source",
      "level": 1
    },
    {
      "x": 3,
      "y": 6,
      "z": 4,
      "name": "Water_Source",
      "level": 1
    },
    {
      "x": 3,
      "y": 1,
      "z": 5,
      "name": "Water",
      "level": 8
    },
    {
      "x": 3,
      "y": 2,
      "z": 5,
      "name": "Water",
      "level": 8
    },
    {
      "x": 3,
      "y": 3,
      "z": 5,
      "name": "Water_Source",
      "level": 1
    },
    {
      "x": 3,
      "y": 4,
      "z": 5,
      "name": "Water_Source",
      "level": 1
    },
    {
      "x": 3,
      "y": 5,
      "z": 5,
      "name": "Water_Source",
      "level": 1
    },
    {
      "x": 3,
      "y": 6,
      "z": 5,
      "name": "Water_Source",
      "level": 1
    },
    {
      "x": 3,
      "y": 1,
      "z": 6,
      "name": "Water",
      "level": 8
    },
    {
      "x": 3,
      "y": 2,
      "z": 6,
      "name": "Water_Source",
      "level": 1
    },
    {
      "x": 3,
      "y": 3,
      "z": 6,
      "name": "Water_Source",
      "level": 1
    },
    {
      "x": 3,
      "y": 4,
      "z": 6,
      "name": "Water_Source",
      "level": 1
    },
    {
      "x": 3,
      "y": 5,
      "z": 6,
      "name": "Water_Source",
      "level": 1
    },
    {
      "x": 3,
      "y": 6,
      "z": 6,
      "name": "Water_Source",
      "level": 1
    },
    {
      "x": 3,
      "y": 1,
      "z": 7,
      "name": "Water_Source",
      "level": 1
    },
    {
      "x": 3,
      "y": 2,
      "z": 7,
      "name": "Water_Source",
      "level": 1
    },
    {
      "x": 3,
      "y": 3,
      "z": 7,
      "name": "Water_Source",
      "level": 1
    },
    {
      "x": 3,
      "y": 4,
      "z": 7,
      "name": "Water_Source",
      "level": 1
    },
    {
      "x": 3,
      "y": 5,
      "z": 7,
      "name": "Water_Source",
      "level": 1
    },
    {
      "x": 3,
      "y": 6,
      "z": 7,
      "name": "Water_Source",
      "level": 1
    },
    {
      "x": 4,
      "y": 5,
      "z": 0,
      "name": "Water_Source",
      "level": 1
    },
    {
      "x": 4,
      "y": 6,
      "z": 0,
      "name": "Water_Source",
      "level": 1
    },
    {
      "x": 4,
      "y": 5,
      "z": 1,
      "name": "Water_Source",
      "level": 1
    },
    {
      "x": 4,
      "y": 6,
      "z": 1,
      "name": "Water_Source",
      "level": 1
    },
    {
      "x": 4,
      "y": 4,
      "z": 2,
      "name": "Water",
      "level": 8
    },
    {
      "x": 4,
      "y": 5,
      "z": 2,
      "name": "Water_Source",
      "level": 1
    },
    {
      "x": 4,
      "y": 6,
      "z": 2,
      "name": "Water_Source",
      "level": 1
    },
    {
      "x": 4,
      "y": 1,
      "z": 3,
      "name": "Water",
      "level": 8
    },
    {
      "x": 4,
      "y": 2,
      "z": 3,
      "name": "Water_Source",
      "level": 1
    },
    {
      "x": 4,
      "y": 3,
      "z": 3,
      "name": "Water_Source",
      "level": 1
    },
    {
      "x": 4,
      "y": 4,
      "z": 3,
      "name": "Water_Source",
      "level": 1
    },
    {
      "x": 4,
      "y": 5,
      "z": 3,
      "name": "Water_Source",
      "level": 1
    },
    {
      "x": 4,
      "y": 6,
      "z": 3,
      "name": "Water_Source",
      "level": 1
    },
    {
      "x": 4,
      "y": 1,
      "z": 4,
      "name": "Water_Source",
      "level": 1
    },
    {
      "x": 4,
      "y": 2,
      "z": 4,
      "name": "Water_Source",
      "level": 1
    },
    {
      "x": 4,
      "y": 3,
      "z": 4,
      "name": "Water_Source",
      "level": 1
    },
    {
      "x": 4,
      "y": 4,
      "z": 4,
      "name": "Water_Source",
      "level": 1
    },
    {
      "x": 4,
      "y": 5,
      "z": 4,
      "name": "Water_Source",
      "level": 1
    },
    {
      "x": 4,
      "y": 6,
      "z": 4,
      "name": "Water_Source",
      "level": 1
    },
    {
      "x": 4,
      "y": 1,
      "z": 5,
      "name": "Water",
      "level": 8
    },
    {
      "x": 4,
      "y": 2,
      "z": 5,
      "name": "Water",
      "level": 8
    },
    {
      "x": 4,
      "y": 3,
      "z": 5,
      "name": "Water_Source",
      "level": 1
    },
    {
      "x": 4,
      "y": 4,
      "z": 5,
      "name": "Water_Source",
      "level": 1
    },
    {
      "x": 4,
      "y": 5,
      "z": 5,
      "name": "Water_Source",
      "level": 1
    },
    {
      "x": 4,
      "y": 6,
      "z": 5,
      "name": "Water_Source",
      "level": 1
    },
    {
      "x": 4,
      "y": 1,
      "z": 6,
      "name": "Water",
      "level": 8
    },
    {
      "x": 4,
      "y": 2,
      "z": 6,
      "name": "Water",
      "level": 8
    },
    {
      "x": 4,
      "y": 3,
      "z": 6,
      "name": "Water_Source",
      "level": 1
    },
    {
      "x": 4,
      "y": 4,
      "z": 6,
      "name": "Water_Source",
      "level": 1
    },
    {
      "x": 4,
      "y": 5,
      "z": 6,
      "name": "Water_Source",
      "level": 1
    },
    {
      "x": 4,
      "y": 6,
      "z": 6,
      "name": "Water_Source",
      "level": 1
    },
    {
      "x": 4,
      "y": 1,
      "z": 7,
      "name": "Water_Source",
      "level": 1
    },
    {
      "x": 4,
      "y": 2,
      "z": 7,
      "name": "Water_Source",
      "level": 1
    },
    {
      "x": 4,
      "y": 3,
      "z": 7,
      "name": "Water_Source",
      "level": 1
    },
    {
      "x": 4,
      "y": 4,
      "z": 7,
      "name": "Water_Source",
      "level": 1
    },
    {
      "x": 4,
      "y": 5,
      "z": 7,
      "name": "Water_Source",
      "level": 1
    },
    {
      "x": 4,
      "y": 6,
      "z": 7,
      "name": "Water",
      "level": 8
    },
    {
      "x": 5,
      "y": 5,
      "z": 1,
      "name": "Water_Source",
      "level": 1
    },
    {
      "x": 5,
      "y": 6,
      "z": 1,
      "name": "Water_Source",
      "level": 1
    },
    {
      "x": 5,
      "y": 3,
      "z": 2,
      "name": "Water",
      "level": 8
    },
    {
      "x": 5,
      "y": 4,
      "z": 2,
      "name": "Water_Source",
      "level": 1
    },
    {
      "x": 5,
      "y": 5,
      "z": 2,
      "name": "Water_Source",
      "level": 1
    },
    {
      "x": 5,
      "y": 6,
      "z": 2,
      "name": "Water_Source",
      "level": 1
    },
    {
      "x": 5,
      "y": 2,
      "z": 3,
      "name": "Water",
      "level": 8
    },
    {
      "x": 5,
      "y": 3,
      "z": 3,
      "name": "Water_Source",
      "level": 1
    },
    {
      "x": 5,
      "y": 4,
      "z": 3,
      "name": "Water_Source",
      "level": 1
    },
    {
      "x": 5,
      "y": 5,
      "z": 3,
      "name": "Water_Source",
      "level": 1
    },
    {
      "x": 5,
      "y": 6,
      "z": 3,
      "name": "Water_Source",
      "level": 1
    },
    {
      "x": 5,
      "y": 1,
      "z": 4,
      "name": "Water_Source",
      "level": 1
    },
    {
      "x": 5,
      "y": 2,
      "z": 4,
      "name": "Water_Source",
      "level": 1
    },
    {
      "x": 5,
      "y": 3,
      "z": 4,
      "name": "Water_Source",
      "level": 1
    },
    {
      "x": 5,
      "y": 4,
      "z": 4,
      "name": "Water_Source",
      "level": 1
    },
    {
      "x": 5,
      "y": 5,
      "z": 4,
      "name": "Water_Source",
      "level": 1
    },
    {
      "x": 5,
      "y": 6,
      "z": 4,
      "name": "Water_Source",
      "level": 1
    },
    {
      "x": 5,
      "y": 1,
      "z": 5,
      "name": "Water_Source",
      "level": 1
    },
    {
      "x": 5,
      "y": 2,
      "z": 5,
      "name": "Water_Source",
      "level": 1
    },
    {
      "x": 5,
      "y": 3,
      "z": 5,
      "name": "Water_Source",
      "level": 1
    },
    {
      "x": 5,
      "y": 4,
      "z": 5,
      "name": "Water_Source",
      "level": 1
    },
    {
      "x": 5,
      "y": 5,
      "z": 5,
      "name": "Water_Source",
      "level": 1
    },
    {
      "x": 5,
      "y": 6,
      "z": 5,
      "name": "Water_Source",
      "level": 1
    },
    {
      "x": 5,
      "y": 1,
      "z": 6,
      "name": "Water_Source",
      "level": 1
    },
    {
      "x": 5,
      "y": 2,
      "z": 6,
      "name": "Water_Source",
      "level": 1
    },
    {
      "x": 5,
      "y": 3,
      "z": 6,
      "name": "Water_Source",
      "level": 1
    },
    {
      "x": 5,
      "y": 4,
      "z": 6,
      "name": "Water_Source",
      "level": 1
    },
    {
      "x": 5,
      "y": 5,
      "z": 6,
      "name": "Water_Source",
      "level": 1
    },
    {
      "x": 5,
      "y": 6,
      "z": 6,
      "name": "Water_Source",
      "level": 1
    }
  ]
}