{
  "version": 8,
  "blockIdVersion": 8,
  "anchorX": -2,
  "anchorY": 13,
  "anchorZ": 3,
  "blocks": [
    {
      "x": -9,
      "y": 2,
      "z": 5,
      "name": "Rock_Volcanic"
    },
    {
      "x": -9,
      "y": 2,
      "z": 6,
      "name": "Rock_Volcanic"
    },
    {
      "x": -9,
      "y": 2,
      "z": 7,
      "name": "Rock_Volcanic"
    },
    {
      "x": -8,
      "y": 3,
      "z": 4,
      "name": "Rock_Volcanic"
    },
    {
      "x": -8,
      "y": 4,
      "z": 4,
      "name": "Rock_Volcanic"
    },
    {
      "x": -8,
      "y": 5,
      "z": 4,
      "name": "Rock_Volcanic"
    },
    {
      "x": -8,
      "y": 1,
      "z": 5,
      "name": "Rock_Volcanic"
    },
    {
      "x": -8,
      "y": 2,
      "z": 5,
      "name": "Rock_Volcanic"
    },
    {
      "x": -8,
      "y": 3,
      "z": 5,
      "name": "Rock_Volcanic"
    },
    {
      "x": -8,
      "y": 4,
      "z": 5,
      "name": "Rock_Volcanic"
    },
    {
      "x": -8,
      "y": 5,
      "z": 5,
      "name": "Rock_Volcanic"
    },
    {
      "x": -8,
      "y": 1,
      "z": 6,
      "name": "Rock_Volcanic"
    },
    {
      "x": -8,
      "y": 2,
      "z": 6,
      "name": "Rock_Volcanic"
    },
    {
      "x": -8,
      "y": 3,
      "z": 6,
      "name": "Rock_Volcanic"
    },
    {
      "x": -8,
      "y": 4,
      "z": 6,
      "name": "Rock_Volcanic"
    },
    {
      "x": -8,
      "y": 5,
      "z": 6,
      "name": "Rock_Volcanic"
    },
    {
      "x": -8,
      "y": 1,
      "z": 7,
      "name": "Rock_Volcanic"
    },
    {
      "x": -8,
      "y": 2,
      "z": 7,
      "name": "Rock_Volcanic"
    },
    {
      "x": -8,
      "y": 3,
      "z": 7,
      "name": "Rock_Volcanic"
    },
    {
      "x": -8,
      "y": 4,
      "z": 7,
      "name": "Rock_Volcanic"
    },
    {
      "x": -8,
      "y": 2,
      "z": 8,
      "name": "Rock_Volcanic"
    },
    {
      "x": -7,
      "y": 3,
      "z": 3,
      "name": "Rock_Volcanic"
    },
    {
      "x": -7,
      "y": 4,
      "z": 3,
      "name": "Rock_Volcanic"
    },
    {
      "x": -7,
      "y": 5,
      "z": 3,
      "name": "Rock_Volcanic"
    },
    {
      "x": -7,
      "y": 6,
      "z": 3,
      "name": "Rock_Volcanic"
    },
    {
      "x": -7,
      "y": 7,
      "z": 3,
      "name": "Rock_Volcanic"
    },
    {
      "x": -7,
      "y": 1,
      "z": 4,
      "name": "Rock_Volcanic"
    },
    {
      "x": -7,
      "y": 2,
      "z": 4,
      "name": "Rock_Volcanic"
    },
    {
      "x": -7,
      "y": 3,
      "z": 4,
      "name": "Rock_Volcanic"
    },
    {
      "x": -7,
      "y": 4,
      "z": 4,
      "name": "Rock_Volcanic"
    },
    {
      "x": -7,
      "y": 5,
      "z": 4,
      "name": "Rock_Volcanic"
    },
    {
      "x": -7,
      "y": 6,
      "z": 4,
      "name": "Rock_Volcanic"
    },
    {
      "x": -7,
      "y": 7,
      "z": 4,
      "name": "Rock_Volcanic"
    },
    {
      "x": -7,
      "y": 0,
      "z": 5,
      "name": "Rock_Volcanic"
    },
    {
      "x": -7,
      "y": 1,
      "z": 5,
      "name": "Rock_Volcanic"
    },
    {
      "x": -7,
      "y": 2,
      "z": 5,
      "name": "Rock_Volcanic"
    },
    {
      "x": -7,
      "y": 3,
      "z": 5,
      "name": "Rock_Volcanic"
    },
    {
      "x": -7,
      "y": 4,
      "z": 5,
      "name": "Rock_Volcanic"
    },
    {
      "x": -7,
      "y": 5,
      "z": 5,
      "name": "Rock_Volcanic"
    },
    {
      "x": -7,
      "y": 6,
      "z": 5,
      "name": "Rock_Volcanic"
    },
    {
      "x": -7,
      "y": 0,
      "z": 6,
      "name": "Rock_Volcanic"
    },
    {
      "x": -7,
      "y": 1,
      "z": 6,
      "name": "Rock_Volcanic"
    },
    {
      "x": -7,
      "y": 2,
      "z": 6,
      "name": "Rock_Volcanic"
    },
    {
      "x": -7,
      "y": 3,
      "z": 6,
      "name": "Rock_Volcanic"
    },
    {
      "x": -7,
      "y": 4,
      "z": 6,
      "name": "Rock_Volcanic"
    },
    {
      "x": -7,
      "y": 5,
      "z": 6,
      "name": "Rock_Volcanic"
    },
    {
      "x": -7,
      "y": 6,
      "z": 6,
      "name": "Rock_Volcanic"
    },
    {
      "x": -7,
      "y": 0,
      "z": 7,
      "name": "Rock_Volcanic"
    },
    {
      "x": -7,
      "y": 1,
      "z": 7,
      "name": "Rock_Volcanic"
    },
    {
      "x": -7,
      "y": 2,
      "z": 7,
      "name": "Rock_Volcanic"
    },
    {
      "x": -7,
      "y": 3,
      "z": 7,
      "name": "Rock_Volcanic"
    },
    {
      "x": -7,
      "y": 4,
      "z": 7,
      "name": "Rock_Volcanic"
    },
    {
      "x": -7,
      "y": 5,
      "z": 7,
      "name": "Rock_Volcanic"
    },
    {
      "x": -7,
      "y": 1,
      "z": 8,
      "name": "Rock_Volcanic"
    },
    {
      "x": -7,
      "y": 2,
      "z": 8,
      "name": "Rock_Volcanic"
    },
    {
      "x": -7,
      "y": 3,
      "z": 8,
      "name": "Rock_Volcanic"
    },
    {
      "x": -7,
      "y": 4,
      "z": 8,
      "name": "Rock_Volcanic"
    },
    {
      "x": -7,
      "y": 2,
      "z": 9,
      "name": "Rock_Volcanic"
    },
    {
      "x": -6,
      "y": 4,
      "z": 2,
      "name": "Rock_Volcanic"
    },
    {
      "x": -6,
      "y": 5,
      "z": 2,
      "name": "Rock_Volcanic"
    },
    {
      "x": -6,
      "y": 6,
      "z": 2,
      "name": "Rock_Volcanic"
    },
    {
      "x": -6,
      "y": 7,
      "z": 2,
      "name": "Rock_Volcanic"
    },
    {
      "x": -6,
      "y": 8,
      "z": 2,
      "name": "Rock_Volcanic"
    },
    {
      "x": -6,
      "y": 2,
      "z": 3,
      "name": "Rock_Volcanic"
    },
    {
      "x": -6,
      "y": 3,
      "z": 3,
      "name": "Rock_Volcanic"
    },
    {
      "x": -6,
      "y": 4,
      "z": 3,
      "name": "Rock_Volcanic"
    },
    {
      "x": -6,
      "y": 5,
      "z": 3,
      "name": "Rock_Volcanic"
    },
    {
      "x": -6,
      "y": 6,
      "z": 3,
      "name": "Rock_Volcanic"
    },
    {
      "x": -6,
      "y": 7,
      "z": 3,
      "name": "Rock_Volcanic"
    },
    {
      "x": -6,
      "y": 8,
      "z": 3,
      "name": "Rock_Volcanic"
    },
    {
      "x": -6,
      "y": 1,
      "z": 4,
      "name": "Rock_Volcanic"
    },
    {
      "x": -6,
      "y": 2,
      "z": 4,
      "name": "Rock_Volcanic"
    },
    {
      "x": -6,
      "y": 3,
      "z": 4,
      "name": "Rock_Volcanic"
    },
    {
      "x": -6,
      "y": 4,
      "z": 4,
      "name": "Rock_Volcanic"
    },
    {
      "x": -6,
      "y": 5,
      "z": 4,
      "name": "Rock_Volcanic"
    },
    {
      "x": -6,
      "y": 6,
      "z": 4,
      "name": "Rock_Volcanic"
    },
    {
      "x": -6,
      "y": 7,
      "z": 4,
      "name": "Rock_Volcanic"
    },
    {
      "x": -6,
      "y": 8,
      "z": 4,
      "name": "Rock_Volcanic"
    },
    {
      "x": -6,
      "y": 0,
      "z": 5,
      "name": "Rock_Volcanic"
    },
    {
      "x": -6,
      "y": 1,
      "z": 5,
      "name": "Rock_Volcanic"
    },
    {
      "x": -6,
      "y": 2,
      "z": 5,
      "name": "Rock_Volcanic"
    },
    {
      "x": -6,
      "y": 3,
      "z": 5,
      "name": "Rock_Volcanic"
    },
    {
      "x": -6,
      "y": 4,
      "z": 5,
      "name": "Rock_Volcanic"
    },
    {
      "x": -6,
      "y": 5,
      "z": 5,
      "name": "Rock_Volcanic"
    },
    {
      "x": -6,
      "y": 6,
      "z": 5,
      "name": "Rock_Volcanic"
    },
    {
      "x": -6,
      "y": 7,
      "z": 5,
      "name": "Rock_Volcanic"
    },
    {
      "x": -6,
      "y": 0,
      "z": 6,
      "name": "Rock_Volcanic"
    },
    {
      "x": -6,
      "y": 1,
      "z": 6,
      "name": "Rock_Volcanic"
    },
    {
      "x": -6,
      "y": 2,
      "z": 6,
      "name": "Rock_Volcanic"
    },
    {
      "x": -6,
      "y": 3,
      "z": 6,
      "name": "Rock_Volcanic"
    },
    {
      "x": -6,
      "y": 4,
      "z": 6,
      "name": "Rock_Volcanic"
    },
    {
      "x": -6,
      "y": 5,
      "z": 6,
      "name": "Rock_Volcanic"
    },
    {
      "x": -6,
      "y": 6,
      "z": 6,
      "name": "Rock_Volcanic"
    },
    {
      "x": -6,
      "y": 7,
      "z": 6,
      "name": "Rock_Volcanic"
    },
    {
      "x": -6,
      "y": 0,
      "z": 7,
      "name": "Rock_Volcanic"
    },
    {
      "x": -6,
      "y": 1,
      "z": 7,
      "name": "Rock_Volcanic"
    },
    {
      "x": -6,
      "y": 2,
      "z": 7,
      "name": "Rock_Volcanic"
    },
    {
      "x": -6,
      "y": 3,
      "z": 7,
      "name": "Rock_Volcanic"
    },
    {
      "x": -6,
      "y": 4,
      "z": 7,
      "name": "Rock_Volcanic"
    },
    {
      "x": -6,
      "y": 5,
      "z": 7,
      "name": "Rock_Volcanic"
    },
    {
      "x": -6,
      "y": 6,
      "z": 7,
      "name": "Rock_Volcanic"
    },
    {
      "x": -6,
      "y": 1,
      "z": 8,
      "name": "Rock_Volcanic"
    },
    {
      "x": -6,
      "y": 2,
      "z": 8,
      "name": "Rock_Volcanic"
    },
    {
      "x": -6,
      "y": 3,
      "z": 8,
      "name": "Rock_Volcanic"
    },
    {
      "x": -6,
      "y": 4,
      "z": 8,
      "name": "Rock_Volcanic"
    },
    {
      "x": -6,
      "y": 5,
      "z": 8,
      "name": "Rock_Volcanic"
    },
    {
      "x": -6,
      "y": 2,
      "z": 9,
      "name": "Rock_Volcanic"
    },
    {
      "x": -5,
      "y": 5,
      "z": 1,
      "name": "Rock_Volcanic"
    },
    {
      "x": -5,
      "y": 6,
      "z": 1,
      "name": "Rock_Volcanic"
    },
    {
      "x": -5,
      "y": 7,
      "z": 1,
      "name": "Rock_Volcanic"
    },
    {
      "x": -5,
      "y": 8,
      "z": 1,
      "name": "Rock_Volcanic"
    },
    {
      "x": -5,
      "y": 9,
      "z": 1,
      "name": "Rock_Volcanic"
    },
    {
      "x": -5,
      "y": 4,
      "z": 2,
      "name": "Rock_Volcanic"
    },
    {
      "x": -5,
      "y": 5,
      "z": 2,
      "name": "Rock_Volcanic"
    },
    {
      "x": -5,
      "y": 6,
      "z": 2,
      "name": "Rock_Volcanic"
    },
    {
      "x": -5,
      "y": 7,
      "z": 2,
      "name": "Rock_Volcanic"
    },
    {
      "x": -5,
      "y": 8,
      "z": 2,
      "name": "Rock_Volcanic"
    },
    {
      "x": -5,
      "y": 9,
      "z": 2,
      "name": "Rock_Volcanic"
    },
    {
      "x": -5,
      "y": 10,
      "z": 2,
      "name": "Rock_Volcanic"
    },
    {
      "x": -5,
      "y": 2,
      "z": 3,
      "name": "Rock_Volcanic"
    },
    {
      "x": -5,
      "y": 3,
      "z": 3,
      "name": "Rock_Volcanic"
    },
    {
      "x": -5,
      "y": 4,
      "z": 3,
      "name": "Rock_Volcanic"
    },
    {
      "x": -5,
      "y": 5,
      "z": 3,
      "name": "Rock_Volcanic"
    },
    {
      "x": -5,
      "y": 6,
      "z": 3,
      "name": "Rock_Volcanic"
    },
    {
      "x": -5,
      "y": 7,
      "z": 3,
      "name": "Rock_Volcanic"
    },
    {
      "x": -5,
      "y": 8,
      "z": 3,
      "name": "Rock_Volcanic"
    },
    {
      "x": -5,
      "y": 9,
      "z": 3,
      "name": "Rock_Volcanic"
    },
    {
      "x": -5,
      "y": 10,
      "z": 3,
      "name": "Rock_Volcanic"
    },
    {
      "x": -5,
      "y": 1,
      "z": 4,
      "name": "Rock_Volcanic"
    },
    {
      "x": -5,
      "y": 2,
      "z": 4,
      "name": "Rock_Volcanic"
    },
    {
      "x": -5,
      "y": 3,
      "z": 4,
      "name": "Rock_Volcanic"
    },
    {
      "x": -5,
      "y": 4,
      "z": 4,
      "name": "Rock_Volcanic"
    },
    {
      "x": -5,
      "y": 5,
      "z": 4,
      "name": "Rock_Volcanic"
    },
    {
      "x": -5,
      "y": 6,
      "z": 4,
      "name": "Rock_Volcanic"
    },
    {
      "x": -5,
      "y": 7,
      "z": 4,
      "name": "Rock_Volcanic"
    },
    {
      "x": -5,
      "y": 8,
      "z": 4,
      "name": "Rock_Volcanic"
    },
    {
      "x": -5,
      "y": 9,
      "z": 4,
      "name": "Rock_Volcanic"
    },
    {
      "x": -5,
      "y": 0,
      "z": 5,
      "name": "Rock_Volcanic"
    },
    {
      "x": -5,
      "y": 1,
      "z": 5,
      "name": "Rock_Volcanic"
    },
    {
      "x": -5,
      "y": 2,
      "z": 5,
      "name": "Rock_Volcanic"
    },
    {
      "x": -5,
      "y": 3,
      "z": 5,
      "name": "Rock_Volcanic"
    },
    {
      "x": -5,
      "y": 4,
      "z": 5,
      "name": "Rock_Volcanic"
    },
    {
      "x": -5,
      "y": 5,
      "z": 5,
      "name": "Rock_Volcanic"
    },
    {
      "x": -5,
      "y": 6,
      "z": 5,
      "name": "Rock_Volcanic"
    },
    {
      "x": -5,
      "y": 7,
      "z": 5,
      "name": "Rock_Volcanic"
    },
    {
      "x": -5,
      "y": 8,
      "z": 5,
      "name": "Rock_Volcanic"
    },
    {
      "x": -5,
      "y": 0,
      "z": 6,
      "name": "Rock_Volcanic"
    },
    {
      "x": -5,
      "y": 1,
      "z": 6,
      "name": "Rock_Volcanic"
    },
    {
      "x": -5,
      "y": 2,
      "z": 6,
      "name": "Rock_Volcanic"
    },
    {
      "x": -5,
      "y": 3,
      "z": 6,
      "name": "Rock_Volcanic"
    },
    {
      "x": -5,
      "y": 4,
      "z": 6,
      "name": "Rock_Volcanic"
    },
    {
      "x": -5,
      "y": 5,
      "z": 6,
      "name": "Rock_Volcanic"
    },
    {
      "x": -5,
      "y": 6,
      "z": 6,
      "name": "Rock_Volcanic"
    },
    {
      "x": -5,
      "y": 7,
      "z": 6,
      "name": "Rock_Volcanic"
    },
    {
      "x": -5,
      "y": 8,
      "z": 6,
      "name": "Rock_Volcanic"
    },
    {
      "x": -5,
      "y": 0,
      "z": 7,
      "name": "Rock_Volcanic"
    },
    {
      "x": -5,
      "y": 1,
      "z": 7,
      "name": "Rock_Volcanic"
    },
    {
      "x": -5,
      "y": 2,
      "z": 7,
      "name": "Rock_Volcanic"
    },
    {
      "x": -5,
      "y": 3,
      "z": 7,
      "name": "Rock_Volcanic"
    },
    {
      "x": -5,
      "y": 4,
      "z": 7,
      "name": "Rock_Volcanic"
    },
    {
      "x": -5,
      "y": 5,
      "z": 7,
      "name": "Rock_Volcanic"
    },
    {
      "x": -5,
      "y": 6,
      "z": 7,
      "name": "Rock_Volcanic"
    },
    {
      "x": -5,
      "y": 2,
      "z": 8,
      "name": "Rock_Volcanic"
    },
    {
      "x": -5,
      "y": 3,
      "z": 8,
      "name": "Rock_Volcanic"
    },
    {
      "x": -5,
      "y": 4,
      "z": 8,
      "name": "Rock_Volcanic"
    },
    {
      "x": -5,
      "y": 5,
      "z": 8,
      "name": "Rock_Volcanic"
    },
    {
      "x": -4,
      "y": 8,
      "z": 0,
      "name": "Rock_Volcanic"
    },
    {
      "x": -4,
      "y": 9,
      "z": 0,
      "name": "Rock_Volcanic"
    },
    {
      "x": -4,
      "y": 10,
      "z": 0,
      "name": "Rock_Volcanic"
    },
    {
      "x": -4,
      "y": 11,
      "z": 0,
      "name": "Rock_Volcanic"
    },
    {
      "x": -4,
      "y": 5,
      "z": 1,
      "name": "Rock_Volcanic"
    },
    {
      "x": -4,
      "y": 6,
      "z": 1,
      "name": "Rock_Volcanic"
    },
    {
      "x": -4,
      "y": 7,
      "z": 1,
      "name": "Rock_Volcanic"
    },
    {
      "x": -4,
      "y": 8,
      "z": 1,
      "name": "Rock_Volcanic"
    },
    {
      "x": -4,
      "y": 9,
      "z": 1,
      "name": "Rock_Volcanic"
    },
    {
      "x": -4,
      "y": 10,
      "z": 1,
      "name": "Rock_Volcanic"
    },
    {
      "x": -4,
      "y": 11,
      "z": 1,
      "name": "Rock_Volcanic"
    },
    {
      "x": -4,
      "y": 12,
      "z": 1,
      "name": "Rock_Volcanic"
    },
    {
      "x": -4,
      "y": 4,
      "z": 2,
      "name": "Rock_Volcanic"
    },
    {
      "x": -4,
      "y": 5,
      "z": 2,
      "name": "Rock_Volcanic"
    },
    {
      "x": -4,
      "y": 6,
      "z": 2,
      "name": "Rock_Volcanic"
    },
    {
      "x": -4,
      "y": 7,
      "z": 2,
      "name": "Rock_Volcanic"
    },
    {
      "x": -4,
      "y": 8,
      "z": 2,
      "name": "Rock_Volcanic"
    },
    {
      "x": -4,
      "y": 9,
      "z": 2,
      "name": "Rock_Volcanic"
    },
    {
      "x": -4,
      "y": 10,
      "z": 2,
      "name": "Rock_Volcanic"
    },
    {
      "x": -4,
      "y": 11,
      "z": 2,
      "name": "Rock_Volcanic"
    },
    {
      "x": -4,
      "y": 12,
      "z": 2,
      "name": "Rock_Volcanic"
    },
    {
      "x": -4,
      "y": 3,
      "z": 3,
      "name": "Rock_Volcanic"
    },
    {
      "x": -4,
      "y": 4,
      "z": 3,
      "name": "Rock_Volcanic"
    },
    {
      "x": -4,
      "y": 5,
      "z": 3,
      "name": "Rock_Volcanic"
    },
    {
      "x": -4,
      "y": 6,
      "z": 3,
      "name": "Rock_Volcanic"
    },
    {
      "x": -4,
      "y": 7,
      "z": 3,
      "name": "Rock_Volcanic"
    },
    {
      "x": -4,
      "y": 8,
      "z": 3,
      "name": "Rock_Volcanic"
    },
    {
      "x": -4,
      "y": 9,
      "z": 3,
      "name": "Rock_Volcanic"
    },
    {
      "x": -4,
      "y": 10,
      "z": 3,
      "name": "Rock_Volcanic"
    },
    {
      "x": -4,
      "y": 11,
      "z": 3,
      "name": "Rock_Volcanic"
    },
    {
      "x": -4,
      "y": 12,
      "z": 3,
      "name": "Rock_Volcanic"
    },
    {
      "x": -4,
      "y": 2,
      "z": 4,
      "name": "Rock_Volcanic"
    },
    {
      "x": -4,
      "y": 3,
      "z": 4,
      "name": "Rock_Volcanic"
    },
    {
      "x": -4,
      "y": 4,
      "z": 4,
      "name": "Rock_Volcanic"
    },
    {
      "x": -4,
      "y": 5,
      "z": 4,
      "name": "Rock_Volcanic"
    },
    {
      "x": -4,
      "y": 6,
      "z": 4,
      "name": "Rock_Volcanic"
    },
    {
      "x": -4,
      "y": 7,
      "z": 4,
      "name": "Rock_Volcanic"
    },
    {
      "x": -4,
      "y": 8,
      "z": 4,
      "name": "Rock_Volcanic"
    },
    {
      "x": -4,
      "y": 9,
      "z": 4,
      "name": "Rock_Volcanic"
    },
    {
      "x": -4,
      "y": 10,
      "z": 4,
      "name": "Rock_Volcanic"
    },
    {
      "x": -4,
      "y": 1,
      "z": 5,
      "name": "Rock_Volcanic"
    },
    {
      "x": -4,
      "y": 2,
      "z": 5,
      "name": "Rock_Volcanic"
    },
    {
      "x": -4,
      "y": 3,
      "z": 5,
      "name": "Rock_Volcanic"
    },
    {
      "x": -4,
      "y": 4,
      "z": 5,
      "name": "Rock_Volcanic"
    },
    {
      "x": -4,
      "y": 5,
      "z": 5,
      "name": "Rock_Volcanic"
    },
    {
      "x": -4,
      "y": 6,
      "z": 5,
      "name": "Rock_Volcanic"
    },
    {
      "x": -4,
      "y": 7,
      "z": 5,
      "name": "Rock_Volcanic"
    },
    {
      "x": -4,
      "y": 8,
      "z": 5,
      "name": "Rock_Volcanic"
    },
    {
      "x": -4,
      "y": 9,
      "z": 5,
      "name": "Rock_Volcanic"
    },
    {
      "x": -4,
      "y": 1,
      "z": 6,
      "name": "Rock_Volcanic"
    },
    {
      "x": -4,
      "y": 2,
      "z": 6,
      "name": "Rock_Volcanic"
    },
    {
      "x": -4,
      "y": 3,
      "z": 6,
      "name": "Rock_Volcanic"
    },
    {
      "x": -4,
      "y": 4,
      "z": 6,
      "name": "Rock_Volcanic"
    },
    {
      "x": -4,
      "y": 5,
      "z": 6,
      "name": "Rock_Volcanic"
    },
    {
      "x": -4,
      "y": 6,
      "z": 6,
      "name": "Rock_Volcanic"
    },
    {
      "x": -4,
      "y": 7,
      "z": 6,
      "name": "Rock_Volcanic"
    },
    {
      "x": -4,
      "y": 8,
      "z": 6,
      "name": "Rock_Volcanic"
    },
    {
      "x": -4,
      "y": 1,
      "z": 7,
      "name": "Rock_Volcanic"
    },
    {
      "x": -4,
      "y": 2,
      "z": 7,
      "name": "Rock_Volcanic"
    },
    {
      "x": -4,
      "y": 3,
      "z": 7,
      "name": "Rock_Volcanic"
    },
    {
      "x": -4,
      "y": 4,
      "z": 7,
      "name": "Rock_Volcanic"
    },
    {
      "x": -4,
      "y": 5,
      "z": 7,
      "name": "Rock_Volcanic"
    },
    {
      "x": -4,
      "y": 6,
      "z": 7,
      "name": "Rock_Volcanic"
    },
    {
      "x": -4,
      "y": 7,
      "z": 7,
      "name": "Rock_Volcanic"
    },
    {
      "x": -4,
      "y": 2,
      "z": 8,
      "name": "Rock_Volcanic"
    },
    {
      "x": -4,
      "y": 3,
      "z": 8,
      "name": "Rock_Volcanic"
    },
    {
      "x": -4,
      "y": 4,
      "z": 8,
      "name": "Rock_Volcanic"
    },
    {
      "x": -4,
      "y": 5,
      "z": 8,
      "name": "Rock_Volcanic"
    },
    {
      "x": -3,
      "y": 7,
      "z": 0,
      "name": "Rock_Volcanic"
    },
    {
      "x": -3,
      "y": 8,
      "z": 0,
      "name": "Rock_Volcanic"
    },
    {
      "x": -3,
      "y": 9,
      "z": 0,
      "name": "Rock_Volcanic"
    },
    {
      "x": -3,
      "y": 10,
      "z": 0,
      "name": "Rock_Volcanic"
    },
    {
      "x": -3,
      "y": 11,
      "z": 0,
      "name": "Rock_Volcanic"
    },
    {
      "x": -3,
      "y": 12,
      "z": 0,
      "name": "Rock_Volcanic"
    },
    {
      "x": -3,
      "y": 13,
      "z": 0,
      "name": "Rock_Volcanic"
    },
    {
      "x": -3,
      "y": 6,
      "z": 1,
      "name": "Rock_Volcanic"
    },
    {
      "x": -3,
      "y": 7,
      "z": 1,
      "name": "Rock_Volcanic"
    },
    {
      "x": -3,
      "y": 8,
      "z": 1,
      "name": "Rock_Volcanic"
    },
    {
      "x": -3,
      "y": 9,
      "z": 1,
      "name": "Rock_Volcanic"
    },
    {
      "x": -3,
      "y": 10,
      "z": 1,
      "name": "Rock_Volcanic"
    },
    {
      "x": -3,
      "y": 11,
      "z": 1,
      "name": "Rock_Volcanic"
    },
    {
      "x": -3,
      "y": 12,
      "z": 1,
      "name": "Rock_Volcanic"
    },
    {
      "x": -3,
      "y": 13,
      "z": 1,
      "name": "Rock_Volcanic"
    },
    {
      "x": -3,
      "y": 5,
      "z": 2,
      "name": "Rock_Volcanic"
    },
    {
      "x": -3,
      "y": 6,
      "z": 2,
      "name": "Rock_Volcanic"
    },
    {
      "x": -3,
      "y": 7,
      "z": 2,
      "name": "Rock_Volcanic"
    },
    {
      "x": -3,
      "y": 8,
      "z": 2,
      "name": "Rock_Volcanic"
    },
    {
      "x": -3,
      "y": 9,
      "z": 2,
      "name": "Rock_Volcanic"
    },
    {
      "x": -3,
      "y": 10,
      "z": 2,
      "name": "Rock_Volcanic"
    },
    {
      "x": -3,
      "y": 11,
      "z": 2,
      "name": "Rock_Volcanic"
    },
    {
      "x": -3,
      "y": 12,
      "z": 2,
      "name": "Rock_Volcanic"
    },
    {
      "x": -3,
      "y": 13,
      "z": 2,
      "name": "Rock_Volcanic"
    },
    {
      "x": -3,
      "y": 4,
      "z": 3,
      "name": "Rock_Volcanic"
    },
    {
      "x": -3,
      "y": 5,
      "z": 3,
      "name": "Rock_Volcanic"
    },
    {
      "x": -3,
      "y": 6,
      "z": 3,
      "name": "Rock_Volcanic"
    },
    {
      "x": -3,
      "y": 7,
      "z": 3,
      "name": "Rock_Volcanic"
    },
    {
      "x": -3,
      "y": 8,
      "z": 3,
      "name": "Rock_Volcanic"
    },
    {
      "x": -3,
      "y": 9,
      "z": 3,
      "name": "Rock_Volcanic"
    },
    {
      "x": -3,
      "y": 10,
      "z": 3,
      "name": "Rock_Volcanic"
    },
    {
      "x": -3,
      "y": 11,
      "z": 3,
      "name": "Rock_Volcanic"
    },
    {
      "x": -3,
      "y": 12,
      "z": 3,
      "name": "Rock_Volcanic"
    },
    {
      "x": -3,
      "y": 3,
      "z": 4,
      "name": "Rock_Volcanic"
    },
    {
      "x": -3,
      "y": 4,
      "z": 4,
      "name": "Rock_Volcanic"
    },
    {
      "x": -3,
      "y": 5,
      "z": 4,
      "name": "Rock_Volcanic"
    },
    {
      "x": -3,
      "y": 6,
      "z": 4,
      "name": "Rock_Volcanic"
    },
    {
      "x": -3,
      "y": 7,
      "z": 4,
      "name": "Rock_Volcanic"
    },
    {
      "x": -3,
      "y": 8,
      "z": 4,
      "name": "Rock_Volcanic"
    },
    {
      "x": -3,
      "y": 9,
      "z": 4,
      "name": "Rock_Volcanic"
    },
    {
      "x": -3,
      "y": 10,
      "z": 4,
      "name": "Rock_Volcanic"
    },
    {
      "x": -3,
      "y": 11,
      "z": 4,
      "name": "Rock_Volcanic"
    },
    {
      "x": -3,
      "y": 2,
      "z": 5,
      "name": "Rock_Volcanic"
    },
    {
      "x": -3,
      "y": 3,
      "z": 5,
      "name": "Rock_Volcanic"
    },
    {
      "x": -3,
      "y": 4,
      "z": 5,
      "name": "Rock_Volcanic"
    },
    {
      "x": -3,
      "y": 5,
      "z": 5,
      "name": "Rock_Volcanic"
    },
    {
      "x": -3,
      "y": 6,
      "z": 5,
      "name": "Rock_Volcanic"
    },
    {
      "x": -3,
      "y": 7,
      "z": 5,
      "name": "Rock_Volcanic"
    },
    {
      "x": -3,
      "y": 8,
      "z": 5,
      "name": "Rock_Volcanic"
    },
    {
      "x": -3,
      "y": 9,
      "z": 5,
      "name": "Rock_Volcanic"
    },
    {
      "x": -3,
      "y": 10,
      "z": 5,
      "name": "Rock_Volcanic"
    },
    {
      "x": -3,
      "y": 1,
      "z": 6,
      "name": "Rock_Volcanic"
    },
    {
      "x": -3,
      "y": 2,
      "z": 6,
      "name": "Rock_Volcanic"
    },
    {
      "x": -3,
      "y": 3,
      "z": 6,
      "name": "Rock_Volcanic"
    },
    {
      "x": -3,
      "y": 4,
      "z": 6,
      "name": "Rock_Volcanic"
    },
    {
      "x": -3,
      "y": 5,
      "z": 6,
      "name": "Rock_Volcanic"
    },
    {
      "x": -3,
      "y": 6,
      "z": 6,
      "name": "Rock_Volcanic"
    },
    {
      "x": -3,
      "y": 7,
      "z": 6,
      "name": "Rock_Volcanic"
    },
    {
      "x": -3,
      "y": 8,
      "z": 6,
      "name": "Rock_Volcanic"
    },
    {
      "x": -3,
      "y": 1,
      "z": 7,
      "name": "Rock_Volcanic"
    },
    {
      "x": -3,
      "y": 2,
      "z": 7,
      "name": "Rock_Volcanic"
    },
    {
      "x": -3,
      "y": 3,
      "z": 7,
      "name": "Rock_Volcanic"
    },
    {
      "x": -3,
      "y": 4,
      "z": 7,
      "name": "Rock_Volcanic"
    },
    {
      "x": -3,
      "y": 5,
      "z": 7,
      "name": "Rock_Volcanic"
    },
    {
      "x": -3,
      "y": 6,
      "z": 7,
      "name": "Rock_Volcanic"
    },
    {
      "x": -3,
      "y": 7,
      "z": 7,
      "name": "Rock_Volcanic"
    },
    {
      "x": -3,
      "y": 2,
      "z": 8,
      "name": "Rock_Volcanic"
    },
    {
      "x": -3,
      "y": 3,
      "z": 8,
      "name": "Rock_Volcanic"
    },
    {
      "x": -3,
      "y": 4,
      "z": 8,
      "name": "Rock_Volcanic"
    },
    {
      "x": -3,
      "y": 5,
      "z": 8,
      "name": "Rock_Volcanic"
    },
    {
      "x": -3,
      "y": 3,
      "z": 9,
      "name": "Rock_Volcanic"
    },
    {
      "x": -2,
      "y": 10,
      "z": -1,
      "name": "Rock_Volcanic"
    },
    {
      "x": -2,
      "y": 11,
      "z": -1,
      "name": "Rock_Volcanic"
    },
    {
      "x": -2,
      "y": 12,
      "z": -1,
      "name": "Rock_Volcanic"
    },
    {
      "x": -2,
      "y": 13,
      "z": -1,
      "name": "Rock_Volcanic"
    },
    {
      "x": -2,
      "y": 14,
      "z": -1,
      "name": "Rock_Volcanic"
    },
    {
      "x": -2,
      "y": 8,
      "z": 0,
      "name": "Rock_Volcanic"
    },
    {
      "x": -2,
      "y": 9,
      "z": 0,
      "name": "Rock_Volcanic"
    },
    {
      "x": -2,
      "y": 10,
      "z": 0,
      "name": "Rock_Volcanic"
    },
    {
      "x": -2,
      "y": 11,
      "z": 0,
      "name": "Rock_Volcanic"
    },
    {
      "x": -2,
      "y": 12,
      "z": 0,
      "name": "Rock_Volcanic"
    },
    {
      "x": -2,
      "y": 13,
      "z": 0,
      "name": "Rock_Volcanic"
    },
    {
      "x": -2,
      "y": 14,
      "z": 0,
      "name": "Rock_Volcanic"
    },
    {
      "x": -2,
      "y": 6,
      "z": 1,
      "name": "Rock_Volcanic"
    },
    {
      "x": -2,
      "y": 7,
      "z": 1,
      "name": "Rock_Volcanic"
    },
    {
      "x": -2,
      "y": 8,
      "z": 1,
      "name": "Rock_Volcanic"
    },
    {
      "x": -2,
      "y": 9,
      "z": 1,
      "name": "Rock_Volcanic"
    },
    {
      "x": -2,
      "y": 10,
      "z": 1,
      "name": "Rock_Volcanic"
    },
    {
      "x": -2,
      "y": 11,
      "z": 1,
      "name": "Rock_Volcanic"
    },
    {
      "x": -2,
      "y": 12,
      "z": 1,
      "name": "Rock_Volcanic"
    },
    {
      "x": -2,
      "y": 13,
      "z": 1,
      "name": "Rock_Volcanic"
    },
    {
      "x": -2,
      "y": 14,
      "z": 1,
      "name": "Rock_Volcanic"
    },
    {
      "x": -2,
      "y": 5,
      "z": 2,
      "name": "Rock_Volcanic"
    },
    {
      "x": -2,
      "y": 6,
      "z": 2,
      "name": "Rock_Volcanic"
    },
    {
      "x": -2,
      "y": 7,
      "z": 2,
      "name": "Rock_Volcanic"
    },
    {
      "x": -2,
      "y": 8,
      "z": 2,
      "name": "Rock_Volcanic"
    },
    {
      "x": -2,
      "y": 9,
      "z": 2,
      "name": "Rock_Volcanic"
    },
    {
      "x": -2,
      "y": 10,
      "z": 2,
      "name": "Rock_Volcanic"
    },
    {
      "x": -2,
      "y": 11,
      "z": 2,
      "name": "Rock_Volcanic"
    },
    {
      "x": -2,
      "y": 12,
      "z": 2,
      "name": "Rock_Volcanic"
    },
    {
      "x": -2,
      "y": 13,
      "z": 2,
      "name": "Rock_Volcanic"
    },
    {
      "x": -2,
      "y": 4,
      "z": 3,
      "name": "Rock_Volcanic"
    },
    {
      "x": -2,
      "y": 5,
      "z": 3,
      "name": "Rock_Volcanic"
    },
    {
      "x": -2,
      "y": 6,
      "z": 3,
      "name": "Rock_Volcanic"
    },
    {
      "x": -2,
      "y": 7,
      "z": 3,
      "name": "Rock_Volcanic"
    },
    {
      "x": -2,
      "y": 8,
      "z": 3,
      "name": "Rock_Volcanic"
    },
    {
      "x": -2,
      "y": 9,
      "z": 3,
      "name": "Rock_Volcanic"
    },
    {
      "x": -2,
      "y": 10,
      "z": 3,
      "name": "Rock_Volcanic"
    },
    {
      "x": -2,
      "y": 11,
      "z": 3,
      "name": "Rock_Volcanic"
    },
    {
      "x": -2,
      "y": 12,
      "z": 3,
      "name": "Rock_Volcanic"
    },
    {
      "x": -2,
      "y": 3,
      "z": 4,
      "name": "Rock_Volcanic"
    },
    {
      "x": -2,
      "y": 4,
      "z": 4,
      "name": "Rock_Volcanic"
    },
    {
      "x": -2,
      "y": 5,
      "z": 4,
      "name": "Rock_Volcanic"
    },
    {
      "x": -2,
      "y": 6,
      "z": 4,
      "name": "Rock_Volcanic"
    },
    {
      "x": -2,
      "y": 7,
      "z": 4,
      "name": "Rock_Volcanic"
    },
    {
      "x": -2,
      "y": 8,
      "z": 4,
      "name": "Rock_Volcanic"
    },
    {
      "x": -2,
      "y": 9,
      "z": 4,
      "name": "Rock_Volcanic"
    },
    {
      "x": -2,
      "y": 10,
      "z": 4,
      "name": "Rock_Volcanic"
    },
    {
      "x": -2,
      "y": 11,
      "z": 4,
      "name": "Rock_Volcanic"
    },
    {
      "x": -2,
      "y": 3,
      "z": 5,
      "name": "Rock_Volcanic"
    },
    {
      "x": -2,
      "y": 4,
      "z": 5,
      "name": "Rock_Volcanic"
    },
    {
      "x": -2,
      "y": 5,
      "z": 5,
      "name": "Rock_Volcanic"
    },
    {
      "x": -2,
      "y": 6,
      "z": 5,
      "name": "Rock_Volcanic"
    },
    {
      "x": -2,
      "y": 7,
      "z": 5,
      "name": "Rock_Volcanic"
    },
    {
      "x": -2,
      "y": 8,
      "z": 5,
      "name": "Rock_Volcanic"
    },
    {
      "x": -2,
      "y": 9,
      "z": 5,
      "name": "Rock_Volcanic"
    },
    {
      "x": -2,
      "y": 10,
      "z": 5,
      "name": "Rock_Volcanic"
    },
    {
      "x": -2,
      "y": 2,
      "z": 6,
      "name": "Rock_Volcanic"
    },
    {
      "x": -2,
      "y": 3,
      "z": 6,
      "name": "Rock_Volcanic"
    },
    {
      "x": -2,
      "y": 4,
      "z": 6,
      "name": "Rock_Volcanic"
    },
    {
      "x": -2,
      "y": 5,
      "z": 6,
      "name": "Rock_Volcanic"
    },
    {
      "x": -2,
      "y": 6,
      "z": 6,
      "name": "Rock_Volcanic"
    },
    {
      "x": -2,
      "y": 7,
      "z": 6,
      "name": "Rock_Volcanic"
    },
    {
      "x": -2,
      "y": 8,
      "z": 6,
      "name": "Rock_Volcanic"
    },
    {
      "x": -2,
      "y": 2,
      "z": 7,
      "name": "Rock_Volcanic"
    },
    {
      "x": -2,
      "y": 3,
      "z": 7,
      "name": "Rock_Volcanic"
    },
    {
      "x": -2,
      "y": 4,
      "z": 7,
      "name": "Rock_Volcanic"
    },
    {
      "x": -2,
      "y": 5,
      "z": 7,
      "name": "Rock_Volcanic"
    },
    {
      "x": -2,
      "y": 6,
      "z": 7,
      "name": "Rock_Volcanic"
    },
    {
      "x": -2,
      "y": 3,
      "z": 8,
      "name": "Rock_Volcanic"
    },
    {
      "x": -1,
      "y": 13,
      "z": -2,
      "name": "Rock_Volcanic"
    },
    {
      "x": -1,
      "y": 14,
      "z": -2,
      "name": "Rock_Volcanic"
    },
    {
      "x": -1,
      "y": 10,
      "z": -1,
      "name": "Rock_Volcanic"
    },
    {
      "x": -1,
      "y": 11,
      "z": -1,
      "name": "Rock_Volcanic"
    },
    {
      "x": -1,
      "y": 12,
      "z": -1,
      "name": "Rock_Volcanic"
    },
    {
      "x": -1,
      "y": 13,
      "z": -1,
      "name": "Rock_Volcanic"
    },
    {
      "x": -1,
      "y": 14,
      "z": -1,
      "name": "Rock_Volcanic"
    },
    {
      "x": -1,
      "y": 15,
      "z": -1,
      "name": "Rock_Volcanic"
    },
    {
      "x": -1,
      "y": 8,
      "z": 0,
      "name": "Rock_Volcanic"
    },
    {
      "x": -1,
      "y": 9,
      "z": 0,
      "name": "Rock_Volcanic"
    },
    {
      "x": -1,
      "y": 10,
      "z": 0,
      "name": "Rock_Volcanic"
    },
    {
      "x": -1,
      "y": 11,
      "z": 0,
      "name": "Rock_Volcanic"
    },
    {
      "x": -1,
      "y": 12,
      "z": 0,
      "name": "Rock_Volcanic"
    },
    {
      "x": -1,
      "y": 13,
      "z": 0,
      "name": "Rock_Volcanic"
    },
    {
      "x": -1,
      "y": 14,
      "z": 0,
      "name": "Rock_Volcanic"
    },
    {
      "x": -1,
      "y": 15,
      "z": 0,
      "name": "Rock_Volcanic"
    },
    {
      "x": -1,
      "y": 7,
      "z": 1,
      "name": "Rock_Volcanic"
    },
    {
      "x": -1,
      "y": 8,
      "z": 1,
      "name": "Rock_Volcanic"
    },
    {
      "x": -1,
      "y": 9,
      "z": 1,
      "name": "Rock_Volcanic"
    },
    {
      "x": -1,
      "y": 10,
      "z": 1,
      "name": "Rock_Volcanic"
    },
    {
      "x": -1,
      "y": 11,
      "z": 1,
      "name": "Rock_Volcanic"
    },
    {
      "x": -1,
      "y": 12,
      "z": 1,
      "name": "Rock_Volcanic"
    },
    {
      "x": -1,
      "y": 13,
      "z": 1,
      "name": "Rock_Volcanic"
    },
    {
      "x": -1,
      "y": 14,
      "z": 1,
      "name": "Rock_Volcanic"
    },
    {
      "x": -1,
      "y": 15,
      "z": 1,
      "name": "Rock_Volcanic"
    },
    {
      "x": -1,
      "y": 6,
      "z": 2,
      "name": "Rock_Volcanic"
    },
    {
      "x": -1,
      "y": 7,
      "z": 2,
      "name": "Rock_Volcanic"
    },
    {
      "x": -1,
      "y": 8,
      "z": 2,
      "name": "Rock_Volcanic"
    },
    {
      "x": -1,
      "y": 9,
      "z": 2,
      "name": "Rock_Volcanic"
    },
    {
      "x": -1,
      "y": 10,
      "z": 2,
      "name": "Rock_Volcanic"
    },
    {
      "x": -1,
      "y": 11,
      "z": 2,
      "name": "Rock_Volcanic"
    },
    {
      "x": -1,
      "y": 12,
      "z": 2,
      "name": "Rock_Volcanic"
    },
    {
      "x": -1,
      "y": 13,
      "z": 2,
      "name": "Rock_Volcanic"
    },
    {
      "x": -1,
      "y": 14,
      "z": 2,
      "name": "Rock_Volcanic"
    },
    {
      "x": -1,
      "y": 5,
      "z": 3,
      "name": "Rock_Volcanic"
    },
    {
      "x": -1,
      "y": 6,
      "z": 3,
      "name": "Rock_Volcanic"
    },
    {
      "x": -1,
      "y": 7,
      "z": 3,
      "name": "Rock_Volcanic"
    },
    {
      "x": -1,
      "y": 8,
      "z": 3,
      "name": "Rock_Volcanic"
    },
    {
      "x": -1,
      "y": 9,
      "z": 3,
      "name": "Rock_Volcanic"
    },
    {
      "x": -1,
      "y": 10,
      "z": 3,
      "name": "Rock_Volcanic"
    },
    {
      "x": -1,
      "y": 11,
      "z": 3,
      "name": "Rock_Volcanic"
    },
    {
      "x": -1,
      "y": 12,
      "z": 3,
      "name": "Rock_Volcanic"
    },
    {
      "x": -1,
      "y": 13,
      "z": 3,
      "name": "Rock_Volcanic"
    },
    {
      "x": -1,
      "y": 5,
      "z": 4,
      "name": "Rock_Volcanic"
    },
    {
      "x": -1,
      "y": 6,
      "z": 4,
      "name": "Rock_Volcanic"
    },
    {
      "x": -1,
      "y": 7,
      "z": 4,
      "name": "Rock_Volcanic"
    },
    {
      "x": -1,
      "y": 8,
      "z": 4,
      "name": "Rock_Volcanic"
    },
    {
      "x": -1,
      "y": 9,
      "z": 4,
      "name": "Rock_Volcanic"
    },
    {
      "x": -1,
      "y": 10,
      "z": 4,
      "name": "Rock_Volcanic"
    },
    {
      "x": -1,
      "y": 11,
      "z": 4,
      "name": "Rock_Volcanic"
    },
    {
      "x": -1,
      "y": 4,
      "z": 5,
      "name": "Rock_Volcanic"
    },
    {
      "x": -1,
      "y": 5,
      "z": 5,
      "name": "Rock_Volcanic"
    },
    {
      "x": -1,
      "y": 6,
      "z": 5,
      "name": "Rock_Volcanic"
    },
    {
      "x": -1,
      "y": 7,
      "z": 5,
      "name": "Rock_Volcanic"
    },
    {
      "x": -1,
      "y": 8,
      "z": 5,
      "name": "Rock_Volcanic"
    },
    {
      "x": -1,
      "y": 9,
      "z": 5,
      "name": "Rock_Volcanic"
    },
    {
      "x": -1,
      "y": 10,
      "z": 5,
      "name": "Rock_Volcanic"
    },
    {
      "x": -1,
      "y": 3,
      "z": 6,
      "name": "Rock_Volcanic"
    },
    {
      "x": -1,
      "y": 4,
      "z": 6,
      "name": "Rock_Volcanic"
    },
    {
      "x": -1,
      "y": 5,
      "z": 6,
      "name": "Rock_Volcanic"
    },
    {
      "x": -1,
      "y": 6,
      "z": 6,
      "name": "Rock_Volcanic"
    },
    {
      "x": -1,
      "y": 7,
      "z": 6,
      "name": "Rock_Volcanic"
    },
    {
      "x": -1,
      "y": 3,
      "z": 7,
      "name": "Rock_Volcanic"
    },
    {
      "x": -1,
      "y": 4,
      "z": 7,
      "name": "Rock_Volcanic"
    },
    {
      "x": -1,
      "y": 5,
      "z": 7,
      "name": "Rock_Volcanic"
    },
    {
      "x": 0,
      "y": 13,
      "z": -2,
      "name": "Rock_Volcanic"
    },
    {
      "x": 0,
      "y": 14,
      "z": -2,
      "name": "Rock_Volcanic"
    },
    {
      "x": 0,
      "y": 15,
      "z": -2,
      "name": "Rock_Volcanic"
    },
    {
      "x": 0,
      "y": 16,
      "z": -2,
      "name": "Rock_Volcanic_Cracked_Poisoned"
    },
    {
      "x": 0,
      "y": 10,
      "z": -1,
      "name": "Rock_Volcanic"
    },
    {
      "x": 0,
      "y": 11,
      "z": -1,
      "name": "Rock_Volcanic"
    },
    {
      "x": 0,
      "y": 12,
      "z": -1,
      "name": "Rock_Volcanic"
    },
    {
      "x": 0,
      "y": 13,
      "z": -1,
      "name": "Rock_Volcanic"
    },
    {
      "x": 0,
      "y": 14,
      "z": -1,
      "name": "Rock_Volcanic"
    },
    {
      "x": 0,
      "y": 15,
      "z": -1,
      "name": "Rock_Volcanic"
    },
    {
      "x": 0,
      "y": 8,
      "z": 0,
      "name": "Rock_Volcanic"
    },
    {
      "x": 0,
      "y": 9,
      "z": 0,
      "name": "Rock_Volcanic"
    },
    {
      "x": 0,
      "y": 10,
      "z": 0,
      "name": "Rock_Volcanic"
    },
    {
      "x": 0,
      "y": 11,
      "z": 0,
      "name": "Rock_Volcanic"
    },
    {
      "x": 0,
      "y": 12,
      "z": 0,
      "name": "Rock_Volcanic"
    },
    {
      "x": 0,
      "y": 13,
      "z": 0,
      "name": "Rock_Volcanic"
    },
    {
      "x": 0,
      "y": 14,
      "z": 0,
      "name": "Rock_Volcanic"
    },
    {
      "x": 0,
      "y": 15,
      "z": 0,
      "name": "Rock_Volcanic"
    },
    {
      "x": 0,
      "y": 7,
      "z": 1,
      "name": "Rock_Volcanic"
    },
    {
      "x": 0,
      "y": 8,
      "z": 1,
      "name": "Rock_Volcanic"
    },
    {
      "x": 0,
      "y": 9,
      "z": 1,
      "name": "Rock_Volcanic"
    },
    {
      "x": 0,
      "y": 10,
      "z": 1,
      "name": "Rock_Volcanic"
    },
    {
      "x": 0,
      "y": 11,
      "z": 1,
      "name": "Rock_Volcanic"
    },
    {
      "x": 0,
      "y": 12,
      "z": 1,
      "name": "Rock_Volcanic"
    },
    {
      "x": 0,
      "y": 13,
      "z": 1,
      "name": "Rock_Volcanic"
    },
    {
      "x": 0,
      "y": 14,
      "z": 1,
      "name": "Rock_Volcanic"
    },
    {
      "x": 0,
      "y": 15,
      "z": 1,
      "name": "Rock_Volcanic"
    },
    {
      "x": 0,
      "y": 6,
      "z": 2,
      "name": "Rock_Volcanic"
    },
    {
      "x": 0,
      "y": 7,
      "z": 2,
      "name": "Rock_Volcanic"
    },
    {
      "x": 0,
      "y": 8,
      "z": 2,
      "name": "Rock_Volcanic"
    },
    {
      "x": 0,
      "y": 9,
      "z": 2,
      "name": "Rock_Volcanic"
    },
    {
      "x": 0,
      "y": 10,
      "z": 2,
      "name": "Rock_Volcanic"
    },
    {
      "x": 0,
      "y": 11,
      "z": 2,
      "name": "Rock_Volcanic"
    },
    {
      "x": 0,
      "y": 12,
      "z": 2,
      "name": "Rock_Volcanic"
    },
    {
      "x": 0,
      "y": 13,
      "z": 2,
      "name": "Rock_Volcanic"
    },
    {
      "x": 0,
      "y": 14,
      "z": 2,
      "name": "Rock_Volcanic"
    },
    {
      "x": 0,
      "y": 6,
      "z": 3,
      "name": "Rock_Volcanic"
    },
    {
      "x": 0,
      "y": 7,
      "z": 3,
      "name": "Rock_Volcanic"
    },
    {
      "x": 0,
      "y": 8,
      "z": 3,
      "name": "Rock_Volcanic"
    },
    {
      "x": 0,
      "y": 9,
      "z": 3,
      "name": "Rock_Volcanic"
    },
    {
      "x": 0,
      "y": 10,
      "z": 3,
      "name": "Rock_Volcanic"
    },
    {
      "x": 0,
      "y": 11,
      "z": 3,
      "name": "Rock_Volcanic"
    },
    {
      "x": 0,
      "y": 12,
      "z": 3,
      "name": "Rock_Volcanic"
    },
    {
      "x": 0,
      "y": 13,
      "z": 3,
      "name": "Rock_Volcanic"
    },
    {
      "x": 0,
      "y": 14,
      "z": 3,
      "name": "Rock_Volcanic"
    },
    {
      "x": 0,
      "y": 6,
      "z": 4,
      "name": "Rock_Volcanic"
    },
    {
      "x": 0,
      "y": 7,
      "z": 4,
      "name": "Rock_Volcanic"
    },
    {
      "x": 0,
      "y": 8,
      "z": 4,
      "name": "Rock_Volcanic"
    },
    {
      "x": 0,
      "y": 9,
      "z": 4,
      "name": "Rock_Volcanic"
    },
    {
      "x": 0,
      "y": 10,
      "z": 4,
      "name": "Rock_Volcanic"
    },
    {
      "x": 0,
      "y": 11,
      "z": 4,
      "name": "Rock_Volcanic"
    },
    {
      "x": 0,
      "y": 12,
      "z": 4,
      "name": "Rock_Volcanic"
    },
    {
      "x": 0,
      "y": 6,
      "z": 5,
      "name": "Rock_Volcanic"
    },
    {
      "x": 0,
      "y": 7,
      "z": 5,
      "name": "Rock_Volcanic"
    },
    {
      "x": 0,
      "y": 8,
      "z": 5,
      "name": "Rock_Volcanic"
    },
    {
      "x": 0,
      "y": 9,
      "z": 5,
      "name": "Rock_Volcanic"
    },
    {
      "x": 0,
      "y": 10,
      "z": 5,
      "name": "Rock_Volcanic"
    },
    {
      "x": 1,
      "y": 16,
      "z": -3,
      "name": "Rock_Volcanic"
    },
    {
      "x": 1,
      "y": 17,
      "z": -3,
      "name": "Rock_Volcanic_Cracked_Poisoned"
    },
    {
      "x": 1,
      "y": 14,
      "z": -2,
      "name": "Rock_Volcanic"
    },
    {
      "x": 1,
      "y": 15,
      "z": -2,
      "name": "Rock_Volcanic"
    },
    {
      "x": 1,
      "y": 16,
      "z": -2,
      "name": "Rock_Volcanic_Cracked_Poisoned"
    },
    {
      "x": 1,
      "y": 17,
      "z": -2,
      "name": "Rock_Volcanic_Cracked_Poisoned"
    },
    {
      "x": 1,
      "y": 12,
      "z": -1,
      "name": "Rock_Volcanic"
    },
    {
      "x": 1,
      "y": 13,
      "z": -1,
      "name": "Rock_Volcanic"
    },
    {
      "x": 1,
      "y": 14,
      "z": -1,
      "name": "Rock_Volcanic"
    },
    {
      "x": 1,
      "y": 15,
      "z": -1,
      "name": "Rock_Volcanic"
    },
    {
      "x": 1,
      "y": 16,
      "z": -1,
      "name": "Rock_Volcanic_Cracked_Poisoned"
    },
    {
      "x": 1,
      "y": 17,
      "z": -1,
      "name": "Rock_Volcanic_Cracked_Poisoned"
    },
    {
      "x": 1,
      "y": 10,
      "z": 0,
      "name": "Rock_Volcanic"
    },
    {
      "x": 1,
      "y": 11,
      "z": 0,
      "name": "Rock_Volcanic"
    },
    {
      "x": 1,
      "y": 12,
      "z": 0,
      "name": "Rock_Volcanic"
    },
    {
      "x": 1,
      "y": 13,
      "z": 0,
      "name": "Rock_Volcanic"
    },
    {
      "x": 1,
      "y": 14,
      "z": 0,
      "name": "Rock_Volcanic"
    },
    {
      "x": 1,
      "y": 15,
      "z": 0,
      "name": "Rock_Volcanic"
    },
    {
      "x": 1,
      "y": 16,
      "z": 0,
      "name": "Rock_Volcanic_Cracked_Poisoned"
    },
    {
      "x": 1,
      "y": 8,
      "z": 1,
      "name": "Rock_Volcanic"
    },
    {
      "x": 1,
      "y": 9,
      "z": 1,
      "name": "Rock_Volcanic"
    },
    {
      "x": 1,
      "y": 10,
      "z": 1,
      "name": "Rock_Volcanic"
    },
    {
      "x": 1,
      "y": 11,
      "z": 1,
      "name": "Rock_Volcanic"
    },
    {
      "x": 1,
      "y": 12,
      "z": 1,
      "name": "Rock_Volcanic"
    },
    {
      "x": 1,
      "y": 13,
      "z": 1,
      "name": "Rock_Volcanic"
    },
    {
      "x": 1,
      "y": 14,
      "z": 1,
      "name": "Rock_Volcanic"
    },
    {
      "x": 1,
      "y": 15,
      "z": 1,
      "name": "Rock_Volcanic"
    },
    {
      "x": 1,
      "y": 7,
      "z": 2,
      "name": "Rock_Volcanic"
    },
    {
      "x": 1,
      "y": 8,
      "z": 2,
      "name": "Rock_Volcanic"
    },
    {
      "x": 1,
      "y": 9,
      "z": 2,
      "name": "Rock_Volcanic"
    },
    {
      "x": 1,
      "y": 10,
      "z": 2,
      "name": "Rock_Volcanic"
    },
    {
      "x": 1,
      "y": 11,
      "z": 2,
      "name": "Rock_Volcanic"
    },
    {
      "x": 1,
      "y": 12,
      "z": 2,
      "name": "Rock_Volcanic"
    },
    {
      "x": 1,
      "y": 13,
      "z": 2,
      "name": "Rock_Volcanic"
    },
    {
      "x": 1,
      "y": 14,
      "z": 2,
      "name": "Rock_Volcanic"
    },
    {
      "x": 1,
      "y": 15,
      "z": 2,
      "name": "Rock_Volcanic"
    },
    {
      "x": 1,
      "y": 7,
      "z": 3,
      "name": "Rock_Volcanic"
    },
    {
      "x": 1,
      "y": 8,
      "z": 3,
      "name": "Rock_Volcanic"
    },
    {
      "x": 1,
      "y": 9,
      "z": 3,
      "name": "Rock_Volcanic"
    },
    {
      "x": 1,
      "y": 10,
      "z": 3,
      "name": "Rock_Volcanic"
    },
    {
      "x": 1,
      "y": 11,
      "z": 3,
      "name": "Rock_Volcanic"
    },
    {
      "x": 1,
      "y": 12,
      "z": 3,
      "name": "Rock_Volcanic"
    },
    {
      "x": 1,
      "y": 13,
      "z": 3,
      "name": "Rock_Volcanic"
    },
    {
      "x": 1,
      "y": 14,
      "z": 3,
      "name": "Rock_Volcanic"
    },
    {
      "x": 1,
      "y": 7,
      "z": 4,
      "name": "Rock_Volcanic"
    },
    {
      "x": 1,
      "y": 8,
      "z": 4,
      "name": "Rock_Volcanic"
    },
    {
      "x": 1,
      "y": 9,
      "z": 4,
      "name": "Rock_Volcanic"
    },
    {
      "x": 1,
      "y": 10,
      "z": 4,
      "name": "Rock_Volcanic"
    },
    {
      "x": 1,
      "y": 11,
      "z": 4,
      "name": "Rock_Volcanic"
    },
    {
      "x": 1,
      "y": 12,
      "z": 4,
      "name": "Rock_Volcanic"
    },
    {
      "x": 1,
      "y": 8,
      "z": 5,
      "name": "Rock_Volcanic"
    },
    {
      "x": 1,
      "y": 9,
      "z": 5,
      "name": "Rock_Volcanic"
    },
    {
      "x": 2,
      "y": 17,
      "z": -4,
      "name": "Rock_Volcanic"
    },
    {
      "x": 2,
      "y": 16,
      "z": -3,
      "name": "Rock_Volcanic"
    },
    {
      "x": 2,
      "y": 17,
      "z": -3,
      "name": "Rock_Volcanic_Cracked_Poisoned"
    },
    {
      "x": 2,
      "y": 15,
      "z": -2,
      "name": "Rock_Volcanic"
    },
    {
      "x": 2,
      "y": 16,
      "z": -2,
      "name": "Rock_Volcanic_Cracked_Poisoned"
    },
    {
      "x": 2,
      "y": 17,
      "z": -2,
      "name": "Rock_Volcanic_Cracked_Poisoned"
    },
    {
      "x": 2,
      "y": 13,
      "z": -1,
      "name": "Rock_Volcanic"
    },
    {
      "x": 2,
      "y": 14,
      "z": -1,
      "name": "Rock_Volcanic"
    },
    {
      "x": 2,
      "y": 15,
      "z": -1,
      "name": "Rock_Volcanic"
    },
    {
      "x": 2,
      "y": 16,
      "z": -1,
      "name": "Rock_Volcanic_Cracked_Poisoned"
    },
    {
      "x": 2,
      "y": 17,
      "z": -1,
      "name": "Rock_Volcanic_Cracked_Poisoned"
    },
    {
      "x": 2,
      "y": 12,
      "z": 0,
      "name": "Rock_Volcanic"
    },
    {
      "x": 2,
      "y": 13,
      "z": 0,
      "name": "Rock_Volcanic"
    },
    {
      "x": 2,
      "y": 14,
      "z": 0,
      "name": "Rock_Volcanic"
    },
    {
      "x": 2,
      "y": 15,
      "z": 0,
      "name": "Rock_Volcanic_Cracked_Poisoned"
    },
    {
      "x": 2,
      "y": 16,
      "z": 0,
      "name": "Rock_Volcanic_Cracked_Poisoned"
    },
    {
      "x": 2,
      "y": 10,
      "z": 1,
      "name": "Rock_Volcanic"
    },
    {
      "x": 2,
      "y": 11,
      "z": 1,
      "name": "Rock_Volcanic"
    },
    {
      "x": 2,
      "y": 12,
      "z": 1,
      "name": "Rock_Volcanic"
    },
    {
      "x": 2,
      "y": 13,
      "z": 1,
      "name": "Rock_Volcanic"
    },
    {
      "x": 2,
      "y": 14,
      "z": 1,
      "name": "Rock_Volcanic"
    },
    {
      "x": 2,
      "y": 15,
      "z": 1,
      "name": "Rock_Volcanic_Cracked_Poisoned"
    },
    {
      "x": 2,
      "y": 16,
      "z": 1,
      "name": "Rock_Volcanic_Cracked_Poisoned"
    },
    {
      "x": 2,
      "y": 10,
      "z": 2,
      "name": "Rock_Volcanic"
    },
    {
      "x": 2,
      "y": 11,
      "z": 2,
      "name": "Rock_Volcanic"
    },
    {
      "x": 2,
      "y": 12,
      "z": 2,
      "name": "Rock_Volcanic"
    },
    {
      "x": 2,
      "y": 13,
      "z": 2,
      "name": "Rock_Volcanic"
    },
    {
      "x": 2,
      "y": 14,
      "z": 2,
      "name": "Rock_Volcanic"
    },
    {
      "x": 2,
      "y": 15,
      "z": 2,
      "name": "Rock_Volcanic_Cracked_Poisoned"
    },
    {
      "x": 2,
      "y": 11,
      "z": 3,
      "name": "Rock_Volcanic"
    },
    {
      "x": 2,
      "y": 12,
      "z": 3,
      "name": "Rock_Volcanic"
    },
    {
      "x": 2,
      "y": 13,
      "z": 3,
      "name": "Rock_Volcanic"
    },
    {
      "x": 3,
      "y": 17,
      "z": -4,
      "name": "Rock_Volcanic"
    },
    {
      "x": 3,
      "y": 18,
      "z": -4,
      "name": "Rock_Volcanic"
    },
    {
      "x": 3,
      "y": 16,
      "z": -3,
      "name": "Rock_Volcanic"
    },
    {
      "x": 3,
      "y": 17,
      "z": -3,
      "name": "Rock_Volcanic"
    },
    {
      "x": 3,
      "y": 18,
      "z": -3,
      "name": "Rock_Volcanic"
    },
    {
      "x": 3,
      "y": 15,
      "z": -2,
      "name": "Rock_Volcanic"
    },
    {
      "x": 3,
      "y": 16,
      "z": -2,
      "name": "Rock_Volcanic"
    },
    {
      "x": 3,
      "y": 17,
      "z": -2,
      "name": "Rock_Volcanic_Cracked_Poisoned"
    },
    {
      "x": 3,
      "y": 18,
      "z": -2,
      "name": "Rock_Volcanic"
    },
    {
      "x": 3,
      "y": 14,
      "z": -1,
      "name": "Rock_Volcanic"
    },
    {
      "x": 3,
      "y": 15,
      "z": -1,
      "name": "Rock_Volcanic"
    },
    {
      "x": 3,
      "y": 16,
      "z": -1,
      "name": "Rock_Volcanic_Cracked_Poisoned"
    },
    {
      "x": 3,
      "y": 17,
      "z": -1,
      "name": "Rock_Volcanic_Cracked_Poisoned"
    },
    {
      "x": 3,
      "y": 14,
      "z": 0,
      "name": "Rock_Volcanic"
    },
    {
      "x": 3,
      "y": 15,
      "z": 0,
      "name": "Rock_Volcanic_Cracked_Poisoned"
    },
    {
      "x": 3,
      "y": 16,
      "z": 0,
      "name": "Rock_Volcanic_Cracked_Poisoned"
    },
    {
      "x": 3,
      "y": 13,
      "z": 1,
      "name": "Rock_Volcanic"
    },
    {
      "x": 3,
      "y": 14,
      "z": 1,
      "name": "Rock_Volcanic"
    },
    {
      "x": 3,
      "y": 15,
      "z": 1,
      "name": "Rock_Volcanic_Cracked_Poisoned"
    },
    {
      "x": 3,
      "y": 16,
      "z": 1,
      "name": "Rock_Volcanic_Cracked_Poisoned"
    },
    {
      "x": 4,
      "y": 17,
      "z": -4,
      "name": "Rock_Volcanic"
    },
    {
      "x": 4,
      "y": 18,
      "z": -4,
      "name": "Rock_Volcanic"
    },
    {
      "x": 4,
      "y": 19,
      "z": -4,
      "name": "Rock_Volcanic"
    },
    {
      "x": 4,
      "y": 16,
      "z": -3,
      "name": "Rock_Volcanic"
    },
    {
      "x": 4,
      "y": 17,
      "z": -3,
      "name": "Rock_Volcanic"
    },
    {
      "x": 4,
      "y": 18,
      "z": -3,
      "name": "Rock_Volcanic"
    },
    {
      "x": 4,
      "y": 19,
      "z": -3,
      "name": "Rock_Volcanic"
    },
    {
      "x": 4,
      "y": 15,
      "z": -2,
      "name": "Rock_Volcanic"
    },
    {
      "x": 4,
      "y": 16,
      "z": -2,
      "name": "Rock_Volcanic"
    },
    {
      "x": 4,
      "y": 17,
      "z": -2,
      "name": "Rock_Volcanic"
    },
    {
      "x": 4,
      "y": 18,
      "z": -2,
      "name": "Rock_Volcanic"
    },
    {
      "x": 4,
      "y": 15,
      "z": -1,
      "name": "Rock_Volcanic"
    },
    {
      "x": 4,
      "y": 16,
      "z": -1,
      "name": "Rock_Volcanic_Cracked_Poisoned"
    },
    {
      "x": 4,
      "y": 17,
      "z": -1,
      "name": "Rock_Volcanic"
    },
    {
      "x": 4,
      "y": 18,
      "z": -1,
      "name": "Rock_Volcanic"
    },
    {
      "x": 4,
      "y": 15,
      "z": 0,
      "name": "Rock_Volcanic_Cracked_Poisoned"
    },
    {
      "x": 4,
      "y": 16,
      "z": 0,
      "name": "Rock_Volcanic_Cracked_Poisoned"
    },
    {
      "x": 5,
      "y": 18,
      "z": -5,
      "name": "Rock_Volcanic"
    },
    {
      "x": 5,
      "y": 19,
      "z": -5,
      "name": "Rock_Volcanic_Cracked_Poisoned"
    },
    {
      "x": 5,
      "y": 17,
      "z": -4,
      "name": "Rock_Volcanic"
    },
    {
      "x": 5,
      "y": 18,
      "z": -4,
      "name": "Rock_Volcanic"
    },
    {
      "x": 5,
      "y": 19,
      "z": -4,
      "name": "Rock_Volcanic_Cracked_Poisoned"
    },
    {
      "x": 5,
      "y": 16,
      "z": -3,
      "name": "Rock_Volcanic"
    },
    {
      "x": 5,
      "y": 17,
      "z": -3,
      "name": "Rock_Volcanic"
    },
    {
      "x": 5,
      "y": 18,
      "z": -3,
      "name": "Rock_Volcanic"
    },
    {
      "x": 5,
      "y": 19,
      "z": -3,
      "name": "Rock_Volcanic"
    },
    {
      "x": 5,
      "y": 16,
      "z": -2,
      "name": "Rock_Volcanic"
    },
    {
      "x": 5,
      "y": 17,
      "z": -2,
      "name": "Rock_Volcanic"
    },
    {
      "x": 5,
      "y": 18,
      "z": -2,
      "name": "Rock_Volcanic"
    },
    {
      "x": 5,
      "y": 16,
      "z": -1,
      "name": "Rock_Volcanic"
    },
    {
      "x": 5,
      "y": 17,
      "z": -1,
      "name": "Rock_Volcanic"
    },
    {
      "x": 5,
      "y": 18,
      "z": -1,
      "name": "Rock_Volcanic"
    },
    {
      "x": 6,
      "y": 19,
      "z": -6,
      "name": "Rock_Volcanic_Cracked_Poisoned"
    },
    {
      "x": 6,
      "y": 20,
      "z": -6,
      "name": "Rock_Volcanic_Cracked_Poisoned"
    },
    {
      "x": 6,
      "y": 21,
      "z": -6,
      "name": "Rock_Volcanic_Cracked_Poisoned"
    },
    {
      "x": 6,
      "y": 18,
      "z": -5,
      "name": "Rock_Volcanic"
    },
    {
      "x": 6,
      "y": 19,
      "z": -5,
      "name": "Rock_Volcanic_Cracked_Poisoned"
    },
    {
      "x": 6,
      "y": 20,
      "z": -5,
      "name": "Rock_Volcanic_Cracked_Poisoned"
    },
    {
      "x": 6,
      "y": 17,
      "z": -4,
      "name": "Rock_Volcanic"
    },
    {
      "x": 6,
      "y": 18,
      "z": -4,
      "name": "Rock_Volcanic"
    },
    {
      "x": 6,
      "y": 19,
      "z": -4,
      "name": "Rock_Volcanic_Cracked_Poisoned"
    },
    {
      "x": 6,
      "y": 20,
      "z": -4,
      "name": "Rock_Volcanic_Cracked_Poisoned"
    },
    {
      "x": 6,
      "y": 17,
      "z": -3,
      "name": "Rock_Volcanic"
    },
    {
      "x": 6,
      "y": 18,
      "z": -3,
      "name": "Rock_Volcanic"
    },
    {
      "x": 6,
      "y": 19,
      "z": -3,
      "name": "Rock_Volcanic"
    },
    {
      "x": 6,
      "y": 17,
      "z": -2,
      "name": "Rock_Volcanic"
    },
    {
      "x": 6,
      "y": 18,
      "z": -2,
      "name": "Rock_Volcanic"
    },
    {
      "x": 7,
      "y": 21,
      "z": -7,
      "name": "Rock_Volcanic_Cracked_Poisoned"
    },
    {
      "x": 7,
      "y": 22,
      "z": -7,
      "name": "Rock_Volcanic_Cracked_Poisoned"
    },
    {
      "x": 7,
      "y": 19,
      "z": -6,
      "name": "Rock_Volcanic_Cracked_Poisoned"
    },
    {
      "x": 7,
      "y": 20,
      "z": -6,
      "name": "Rock_Volcanic_Cracked_Poisoned"
    },
    {
      "x": 7,
      "y": 21,
      "z": -6,
      "name": "Rock_Volcanic_Cracked_Poisoned"
    },
    {
      "x": 7,
      "y": 18,
      "z": -5,
      "name": "Rock_Volcanic"
    },
    {
      "x": 7,
      "y": 19,
      "z": -5,
      "name": "Rock_Volcanic_Cracked_Poisoned"
    },
    {
      "x": 7,
      "y": 20,
      "z": -5,
      "name": "Rock_Volcanic_Cracked_Poisoned"
    },
    {
      "x": 7,
      "y": 21,
      "z": -5,
      "name": "Rock_Volcanic_Cracked_Poisoned"
    },
    {
      "x": 7,
      "y": 18,
      "z": -4,
      "name": "Rock_Volcanic"
    },
    {
      "x": 7,
      "y": 19,
      "z": -4,
      "name": "Rock_Volcanic_Cracked_Poisoned"
    },
    {
      "x": 7,
      "y": 20,
      "z": -4,
      "name": "Rock_Volcanic_Cracked_Poisoned"
    },
    {
      "x": 7,
      "y": 18,
      "z": -3,
      "name": "Rock_Volcanic"
    },
    {
      "x": 7,
      "y": 19,
      "z": -3,
      "name": "Rock_Volcanic"
    },
    {
      "x": 8,
      "y": 20,
      "z": -7,
      "name": "Rock_Volcanic"
    },
    {
      "x": 8,
      "y": 21,
      "z": -7,
      "name": "Rock_Volcanic_Cracked_Poisoned"
    },
    {
      "x": 8,
      "y": 22,
      "z": -7,
      "name": "Rock_Volcanic_Cracked_Poisoned"
    },
    {
      "x": 8,
      "y": 19,
      "z": -6,
      "name": "Rock_Volcanic"
    },
    {
      "x": 8,
      "y": 20,
      "z": -6,
      "name": "Rock_Volcanic_Cracked_Poisoned"
    },
    {
      "x": 8,
      "y": 21,
      "z": -6,
      "name": "Rock_Volcanic_Cracked_Poisoned"
    },
    {
      "x": 8,
      "y": 22,
      "z": -6,
      "name": "Rock_Volcanic_Cracked_Poisoned"
    },
    {
      "x": 8,
      "y": 19,
      "z": -5,
      "name": "Rock_Volcanic"
    },
    {
      "x": 8,
      "y": 20,
      "z": -5,
      "name": "Rock_Volcanic_Cracked_Poisoned"
    },
    {
      "x": 8,
      "y": 21,
      "z": -5,
      "name": "Rock_Volcanic_Cracked_Poisoned"
    },
    {
      "x": 8,
      "y": 19,
      "z": -4,
      "name": "Rock_Volcanic"
    },
    {
      "x": 8,
      "y": 20,
      "z": -4,
      "name": "Rock_Volcanic_Cracked_Poisoned"
    },
    {
      "x": 9,
      "y": 22,
      "z": -8,
      "name": "Rock_Volcanic_Cracked_Poisoned"
    },
    {
      "x": 9,
      "y": 23,
      "z": -8,
      "name": "Rock_Volcanic_Cracked_Poisoned"
    },
    {
      "x": 9,
      "y": 21,
      "z": -7,
      "name": "Rock_Volcanic_Cracked_Poisoned"
    },
    {
      "x": 9,
      "y": 22,
      "z": -7,
      "name": "Rock_Volcanic_Cracked_Poisoned"
    },
    {
      "x": 9,
      "y": 23,
      "z": -7,
      "name": "Rock_Volcanic_Cracked_Poisoned"
    }
  ]
}