{
  "version": 8,
  "blockIdVersion": 8,
  "anchorX": 0,
  "anchorY": 10,
  "anchorZ": 0,
  "blocks": [
    {
      "x": -9,
      "y": 16,
      "z": -10,
      "name": "Rock_Shale_Cobble_Half",
      "rotation": 7
    },
    {
      "x": -9,
      "y": 17,
      "z": -10,
      "name": "*Rock_Shale_Cobble_Wall_State_Definitions_Corner",
      "rotation": 1
    },
    {
      "x": -9,
      "y": 18,
      "z": -10,
      "name": "Furniture_Human_Ruins_Torch",
      "rotation": 3
    },
    {
      "x": -9,
      "y": 16,
      "z": -9,
      "name": "Rock_Shale_Cobble_Half",
      "rotation": 7
    },
    {
      "x": -9,
      "y": 17,
      "z": -9,
      "name": "Rock_Shale_Cobble_Wall",
      "rotation": 3
    },
    {
      "x": -9,
      "y": 16,
      "z": -8,
      "name": "Rock_Shale_Cobble_Half",
      "rotation": 7
    },
    {
      "x": -9,
      "y": 17,
      "z": -8,
      "name": "Rock_Shale_Cobble_Wall",
      "rotation": 3
    },
    {
      "x": -9,
      "y": 16,
      "z": -7,
      "name": "Rock_Shale_Cobble_Half",
      "rotation": 7
    },
    {
      "x": -9,
      "y": 17,
      "z": -7,
      "name": "Rock_Shale_Cobble_Wall",
      "rotation": 3
    },
    {
      "x": -9,
      "y": 16,
      "z": -6,
      "name": "Rock_Shale_Cobble_Half",
      "rotation": 7
    },
    {
      "x": -9,
      "y": 17,
      "z": -6,
      "name": "Rock_Shale_Cobble_Wall",
      "rotation": 3
    },
    {
      "x": -9,
      "y": 16,
      "z": -5,
      "name": "Rock_Shale_Cobble_Half",
      "rotation": 7
    },
    {
      "x": -9,
      "y": 17,
      "z": -5,
      "name": "Rock_Shale_Cobble_Wall",
      "rotation": 3
    },
    {
      "x": -9,
      "y": 16,
      "z": -4,
      "name": "Rock_Shale_Cobble_Half",
      "rotation": 7
    },
    {
      "x": -9,
      "y": 17,
      "z": -4,
      "name": "Rock_Shale_Cobble_Wall",
      "rotation": 3
    },
    {
      "x": -9,
      "y": 18,
      "z": -4,
      "name": "Furniture_Crude_Candle"
    },
    {
      "x": -9,
      "y": 16,
      "z": -3,
      "name": "Rock_Shale_Cobble_Half",
      "rotation": 7
    },
    {
      "x": -9,
      "y": 17,
      "z": -3,
      "name": "Rock_Shale_Cobble_Wall",
      "rotation": 3
    },
    {
      "x": -9,
      "y": 9,
      "z": -2,
      "name": "Soil_Dirt_Cold"
    },
    {
      "x": -9,
      "y": 10,
      "z": -2,
      "name": "Soil_Dirt_Cold"
    },
    {
      "x": -9,
      "y": 8,
      "z": -1,
      "name": "Soil_Dirt_Cold"
    },
    {
      "x": -9,
      "y": 9,
      "z": -1,
      "name": "Soil_Dirt_Cold"
    },
    {
      "x": -9,
      "y": 10,
      "z": -1,
      "name": "Soil_Dirt_Cold"
    },
    {
      "x": -9,
      "y": 16,
      "z": -1,
      "name": "Rock_Shale_Cobble_Half",
      "rotation": 7
    },
    {
      "x": -9,
      "y": 17,
      "z": -1,
      "name": "Rock_Shale_Cobble_Wall",
      "rotation": 3
    },
    {
      "x": -9,
      "y": 8,
      "z": 0,
      "name": "Soil_Dirt_Cold"
    },
    {
      "x": -9,
      "y": 9,
      "z": 0,
      "name": "Soil_Dirt_Cold"
    },
    {
      "x": -9,
      "y": 10,
      "z": 0,
      "name": "Soil_Dirt_Cold"
    },
    {
      "x": -9,
      "y": 16,
      "z": 0,
      "name": "Rock_Shale_Cobble_Half",
      "rotation": 7
    },
    {
      "x": -9,
      "y": 17,
      "z": 0,
      "name": "Rock_Shale_Cobble_Wall",
      "rotation": 3
    },
    {
      "x": -9,
      "y": 16,
      "z": 1,
      "name": "Rock_Shale_Cobble_Half",
      "rotation": 7
    },
    {
      "x": -9,
      "y": 17,
      "z": 1,
      "name": "Rock_Shale_Cobble_Wall",
      "rotation": 3
    },
    {
      "x": -9,
      "y": 16,
      "z": 2,
      "name": "Rock_Shale_Cobble_Half",
      "rotation": 7
    },
    {
      "x": -9,
      "y": 17,
      "z": 2,
      "name": "Rock_Shale_Cobble_Wall",
      "rotation": 3
    },
    {
      "x": -9,
      "y": 16,
      "z": 3,
      "name": "Rock_Shale_Cobble_Half",
      "rotation": 7
    },
    {
      "x": -9,
      "y": 17,
      "z": 3,
      "name": "Rock_Shale_Cobble_Wall",
      "rotation": 3
    },
    {
      "x": -8,
      "y": 11,
      "z": -10,
      "name": "Rock_Basalt_Brick"
    },
    {
      "x": -8,
      "y": 12,
      "z": -10,
      "name": "Rock_Basalt_Brick"
    },
    {
      "x": -8,
      "y": 13,
      "z": -10,
      "name": "Rock_Basalt_Brick"
    },
    {
      "x": -8,
      "y": 14,
      "z": -10,
      "name": "Rock_Shale_Brick"
    },
    {
      "x": -8,
      "y": 15,
      "z": -10,
      "name": "Rock_Shale_Brick"
    },
    {
      "x": -8,
      "y": 16,
      "z": -10,
      "name": "Rock_Shale_Cobble"
    },
    {
      "x": -8,
      "y": 17,
      "z": -10,
      "name": "Rock_Shale_Cobble_Wall",
      "rotation": 2
    },
    {
      "x": -8,
      "y": 6,
      "z": -9,
      "name": "Rock_Shale"
    },
    {
      "x": -8,
      "y": 7,
      "z": -9,
      "name": "Rock_Shale"
    },
    {
      "x": -8,
      "y": 8,
      "z": -9,
      "name": "Rock_Shale"
    },
    {
      "x": -8,
      "y": 9,
      "z": -9,
      "name": "Rock_Basalt_Brick"
    },
    {
      "x": -8,
      "y": 10,
      "z": -9,
      "name": "Rock_Basalt_Brick"
    },
    {
      "x": -8,
      "y": 11,
      "z": -9,
      "name": "Rock_Basalt_Brick"
    },
    {
      "x": -8,
      "y": 12,
      "z": -9,
      "name": "Rock_Basalt_Brick"
    },
    {
      "x": -8,
      "y": 13,
      "z": -9,
      "name": "Rock_Basalt_Brick"
    },
    {
      "x": -8,
      "y": 14,
      "z": -9,
      "name": "Rock_Basalt_Brick"
    },
    {
      "x": -8,
      "y": 15,
      "z": -9,
      "name": "Rock_Shale_Brick"
    },
    {
      "x": -8,
      "y": 16,
      "z": -9,
      "name": "Rock_Shale_Cobble"
    },
    {
      "x": -8,
      "y": 17,
      "z": -9,
      "name": "Empty"
    },
    {
      "x": -8,
      "y": 5,
      "z": -8,
      "name": "Rock_Shale"
    },
    {
      "x": -8,
      "y": 6,
      "z": -8,
      "name": "Rock_Shale"
    },
    {
      "x": -8,
      "y": 7,
      "z": -8,
      "name": "Rock_Shale"
    },
    {
      "x": -8,
      "y": 8,
      "z": -8,
      "name": "Rock_Shale"
    },
    {
      "x": -8,
      "y": 9,
      "z": -8,
      "name": "Rock_Basalt_Brick"
    },
    {
      "x": -8,
      "y": 10,
      "z": -8,
      "name": "Rock_Basalt_Brick"
    },
    {
      "x": -8,
      "y": 11,
      "z": -8,
      "name": "Rock_Basalt_Brick"
    },
    {
      "x": -8,
      "y": 12,
      "z": -8,
      "name": "Rock_Basalt_Brick"
    },
    {
      "x": -8,
      "y": 13,
      "z": -8,
      "name": "Furniture_Ancient_Window",
      "rotation": 1
    },
    {
      "x": -8,
      "y": 14,
      "z": -8,
      "name": "Rock_Shale_Brick"
    },
    {
      "x": -8,
      "y": 15,
      "z": -8,
      "name": "Rock_Shale_Brick"
    },
    {
      "x": -8,
      "y": 16,
      "z": -8,
      "name": "Rock_Shale_Cobble"
    },
    {
      "x": -8,
      "y": 5,
      "z": -7,
      "name": "Rock_Shale"
    },
    {
      "x": -8,
      "y": 6,
      "z": -7,
      "name": "Rock_Shale"
    },
    {
      "x": -8,
      "y": 7,
      "z": -7,
      "name": "Rock_Shale"
    },
    {
      "x": -8,
      "y": 8,
      "z": -7,
      "name": "Rock_Shale"
    },
    {
      "x": -8,
      "y": 9,
      "z": -7,
      "name": "Rock_Basalt_Brick"
    },
    {
      "x": -8,
      "y": 10,
      "z": -7,
      "name": "Rock_Basalt_Brick"
    },
    {
      "x": -8,
      "y": 11,
      "z": -7,
      "name": "Rock_Basalt_Brick"
    },
    {
      "x": -8,
      "y": 12,
      "z": -7,
      "name": "Rock_Basalt_Brick"
    },
    {
      "x": -8,
      "y": 13,
      "z": -7,
      "name": "Rock_Basalt_Brick"
    },
    {
      "x": -8,
      "y": 14,
      "z": -7,
      "name": "Rock_Shale_Brick"
    },
    {
      "x": -8,
      "y": 15,
      "z": -7,
      "name": "Rock_Shale_Brick"
    },
    {
      "x": -8,
      "y": 16,
      "z": -7,
      "name": "Rock_Shale_Cobble"
    },
    {
      "x": -8,
      "y": 5,
      "z": -6,
      "name": "Rock_Shale"
    },
    {
      "x": -8,
      "y": 6,
      "z": -6,
      "name": "Rock_Shale"
    },
    {
      "x": -8,
      "y": 7,
      "z": -6,
      "name": "Rock_Shale"
    },
    {
      "x": -8,
      "y": 8,
      "z": -6,
      "name": "Rock_Shale"
    },
    {
      "x": -8,
      "y": 9,
      "z": -6,
      "name": "Rock_Basalt_Brick"
    },
    {
      "x": -8,
      "y": 10,
      "z": -6,
      "name": "Rock_Basalt_Brick"
    },
    {
      "x": -8,
      "y": 11,
      "z": -6,
      "name": "Rock_Basalt_Brick"
    },
    {
      "x": -8,
      "y": 12,
      "z": -6,
      "name": "Rock_Basalt_Brick"
    },
    {
      "x": -8,
      "y": 13,
      "z": -6,
      "name": "Rock_Shale_Brick"
    },
    {
      "x": -8,
      "y": 14,
      "z": -6,
      "name": "Rock_Shale_Brick"
    },
    {
      "x": -8,
      "y": 15,
      "z": -6,
      "name": "Rock_Shale_Brick"
    },
    {
      "x": -8,
      "y": 16,
      "z": -6,
      "name": "Rock_Shale_Cobble"
    },
    {
      "x": -8,
      "y": 5,
      "z": -5,
      "name": "Rock_Shale"
    },
    {
      "x": -8,
      "y": 6,
      "z": -5,
      "name": "Rock_Shale"
    },
    {
      "x": -8,
      "y": 7,
      "z": -5,
      "name": "Rock_Shale"
    },
    {
      "x": -8,
      "y": 8,
      "z": -5,
      "name": "Rock_Shale"
    },
    {
      "x": -8,
      "y": 9,
      "z": -5,
      "name": "Rock_Shale"
    },
    {
      "x": -8,
      "y": 10,
      "z": -5,
      "name": "Rock_Basalt_Brick"
    },
    {
      "x": -8,
      "y": 11,
      "z": -5,
      "name": "Rock_Basalt_Brick"
    },
    {
      "x": -8,
      "y": 12,
      "z": -5,
      "name": "Rock_Basalt_Brick"
    },
    {
      "x": -8,
      "y": 13,
      "z": -5,
      "name": "Rock_Shale_Brick"
    },
    {
      "x": -8,
      "y": 14,
      "z": -5,
      "name": "Rock_Shale_Brick"
    },
    {
      "x": -8,
      "y": 15,
      "z": -5,
      "name": "Rock_Shale_Brick"
    },
    {
      "x": -8,
      "y": 16,
      "z": -5,
      "name": "Rock_Shale_Cobble"
    },
    {
      "x": -8,
      "y": 5,
      "z": -4,
      "name": "Rock_Shale"
    },
    {
      "x": -8,
      "y": 6,
      "z": -4,
      "name": "Rock_Shale"
    },
    {
      "x": -8,
      "y": 7,
      "z": -4,
      "name": "Rock_Shale"
    },
    {
      "x": -8,
      "y": 8,
      "z": -4,
      "name": "Rock_Shale"
    },
    {
      "x": -8,
      "y": 9,
      "z": -4,
      "name": "Rock_Shale"
    },
    {
      "x": -8,
      "y": 10,
      "z": -4,
      "name": "Rock_Basalt_Brick"
    },
    {
      "x": -8,
      "y": 11,
      "z": -4,
      "name": "Rock_Basalt_Brick"
    },
    {
      "x": -8,
      "y": 12,
      "z": -4,
      "name": "Rock_Basalt_Brick"
    },
    {
      "x": -8,
      "y": 13,
      "z": -4,
      "name": "Furniture_Ancient_Window",
      "rotation": 1
    },
    {
      "x": -8,
      "y": 14,
      "z": -4,
      "name": "Rock_Shale_Brick"
    },
    {
      "x": -8,
      "y": 15,
      "z": -4,
      "name": "Rock_Shale_Brick"
    },
    {
      "x": -8,
      "y": 16,
      "z": -4,
      "name": "Rock_Shale_Cobble"
    },
    {
      "x": -8,
      "y": 5,
      "z": -3,
      "name": "Rock_Shale"
    },
    {
      "x": -8,
      "y": 6,
      "z": -3,
      "name": "Rock_Shale"
    },
    {
      "x": -8,
      "y": 7,
      "z": -3,
      "name": "Rock_Shale"
    },
    {
      "x": -8,
      "y": 8,
      "z": -3,
      "name": "Rock_Shale"
    },
    {
      "x": -8,
      "y": 9,
      "z": -3,
      "name": "Rock_Shale"
    },
    {
      "x": -8,
      "y": 10,
      "z": -3,
      "name": "Rock_Basalt_Brick"
    },
    {
      "x": -8,
      "y": 11,
      "z": -3,
      "name": "Rock_Basalt_Brick"
    },
    {
      "x": -8,
      "y": 12,
      "z": -3,
      "name": "Rock_Basalt_Brick"
    },
    {
      "x": -8,
      "y": 13,
      "z": -3,
      "name": "Rock_Shale_Brick"
    },
    {
      "x": -8,
      "y": 14,
      "z": -3,
      "name": "Rock_Shale_Brick"
    },
    {
      "x": -8,
      "y": 15,
      "z": -3,
      "name": "Rock_Shale_Brick"
    },
    {
      "x": -8,
      "y": 16,
      "z": -3,
      "name": "Rock_Shale_Cobble"
    },
    {
      "x": -8,
      "y": 6,
      "z": -2,
      "name": "Rock_Shale"
    },
    {
      "x": -8,
      "y": 7,
      "z": -2,
      "name": "Rock_Shale"
    },
    {
      "x": -8,
      "y": 8,
      "z": -2,
      "name": "Rock_Shale"
    },
    {
      "x": -8,
      "y": 9,
      "z": -2,
      "name": "Rock_Shale"
    },
    {
      "x": -8,
      "y": 10,
      "z": -2,
      "name": "Rock_Basalt_Brick"
    },
    {
      "x": -8,
      "y": 11,
      "z": -2,
      "name": "Rock_Basalt_Brick"
    },
    {
      "x": -8,
      "y": 12,
      "z": -2,
      "name": "Rock_Basalt_Brick"
    },
    {
      "x": -8,
      "y": 13,
      "z": -2,
      "name": "Rock_Shale_Brick_Half",
      "rotation": 4
    },
    {
      "x": -8,
      "y": 14,
      "z": -2,
      "name": "Rock_Shale_Brick_Half",
      "rotation": 4
    },
    {
      "x": -8,
      "y": 15,
      "z": -2,
      "name": "Empty"
    },
    {
      "x": -8,
      "y": 16,
      "z": -2,
      "name": "Empty"
    },
    {
      "x": -8,
      "y": 6,
      "z": -1,
      "name": "Rock_Shale"
    },
    {
      "x": -8,
      "y": 7,
      "z": -1,
      "name": "Rock_Shale"
    },
    {
      "x": -8,
      "y": 8,
      "z": -1,
      "name": "Rock_Shale"
    },
    {
      "x": -8,
      "y": 9,
      "z": -1,
      "name": "Soil_Dirt_Cold"
    },
    {
      "x": -8,
      "y": 10,
      "z": -1,
      "name": "Soil_Dirt_Cold"
    },
    {
      "x": -8,
      "y": 11,
      "z": -1,
      "name": "Empty"
    },
    {
      "x": -8,
      "y": 12,
      "z": -1,
      "name": "Empty"
    },
    {
      "x": -8,
      "y": 13,
      "z": -1,
      "name": "Empty"
    },
    {
      "x": -8,
      "y": 14,
      "z": -1,
      "name": "Empty"
    },
    {
      "x": -8,
      "y": 15,
      "z": -1,
      "name": "Rock_Shale_Brick"
    },
    {
      "x": -8,
      "y": 16,
      "z": -1,
      "name": "Rock_Shale_Cobble"
    },
    {
      "x": -8,
      "y": 7,
      "z": 0,
      "name": "Rock_Shale"
    },
    {
      "x": -8,
      "y": 8,
      "z": 0,
      "name": "Rock_Shale"
    },
    {
      "x": -8,
      "y": 9,
      "z": 0,
      "name": "Rock_Shale"
    },
    {
      "x": -8,
      "y": 10,
      "z": 0,
      "name": "Rock_Basalt_Brick"
    },
    {
      "x": -8,
      "y": 11,
      "z": 0,
      "name": "Rock_Basalt_Brick"
    },
    {
      "x": -8,
      "y": 12,
      "z": 0,
      "name": "Rock_Basalt_Brick"
    },
    {
      "x": -8,
      "y": 13,
      "z": 0,
      "name": "Rock_Basalt_Brick"
    },
    {
      "x": -8,
      "y": 14,
      "z": 0,
      "name": "Rock_Shale_Brick"
    },
    {
      "x": -8,
      "y": 15,
      "z": 0,
      "name": "Rock_Shale_Brick"
    },
    {
      "x": -8,
      "y": 16,
      "z": 0,
      "name": "Rock_Shale_Cobble"
    },
    {
      "x": -8,
      "y": 10,
      "z": 1,
      "name": "Rock_Basalt_Brick"
    },
    {
      "x": -8,
      "y": 11,
      "z": 1,
      "name": "Rock_Basalt_Brick"
    },
    {
      "x": -8,
      "y": 12,
      "z": 1,
      "name": "Rock_Basalt_Brick"
    },
    {
      "x": -8,
      "y": 13,
      "z": 1,
      "name": "Rock_Shale_Brick"
    },
    {
      "x": -8,
      "y": 14,
      "z": 1,
      "name": "Rock_Shale_Brick"
    },
    {
      "x": -8,
      "y": 15,
      "z": 1,
      "name": "Rock_Shale_Brick"
    },
    {
      "x": -8,
      "y": 16,
      "z": 1,
      "name": "Rock_Shale_Cobble"
    },
    {
      "x": -8,
      "y": 11,
      "z": 2,
      "name": "Rock_Shale_Cobble"
    },
    {
      "x": -8,
      "y": 12,
      "z": 2,
      "name": "Rock_Shale_Cobble"
    },
    {
      "x": -8,
      "y": 13,
      "z": 2,
      "name": "Rock_Shale_Brick"
    },
    {
      "x": -8,
      "y": 14,
      "z": 2,
      "name": "Rock_Shale_Brick"
    },
    {
      "x": -8,
      "y": 15,
      "z": 2,
      "name": "Rock_Shale_Brick"
    },
    {
      "x": -8,
      "y": 16,
      "z": 2,
      "name": "Rock_Shale_Cobble"
    },
    {
      "x": -8,
      "y": 12,
      "z": 3,
      "name": "Rock_Shale_Brick"
    },
    {
      "x": -8,
      "y": 13,
      "z": 3,
      "name": "Rock_Shale_Brick"
    },
    {
      "x": -8,
      "y": 14,
      "z": 3,
      "name": "Rock_Shale_Brick"
    },
    {
      "x": -8,
      "y": 15,
      "z": 3,
      "name": "Rock_Shale_Brick"
    },
    {
      "x": -8,
      "y": 16,
      "z": 3,
      "name": "Rock_Shale_Cobble"
    },
    {
      "x": -8,
      "y": 15,
      "z": 4,
      "name": "Rock_Shale_Brick"
    },
    {
      "x": -8,
      "y": 16,
      "z": 4,
      "name": "Rock_Shale_Cobble"
    },
    {
      "x": -8,
      "y": 15,
      "z": 5,
      "name": "Rock_Shale_Brick_Half",
      "rotation": 4
    },
    {
      "x": -8,
      "y": 16,
      "z": 5,
      "name": "Rock_Shale_Cobble_Half",
      "rotation": 4
    },
    {
      "x": -8,
      "y": 17,
      "z": 5,
      "name": "Rock_Shale_Cobble_Wall"
    },
    {
      "x": -7,
      "y": 15,
      "z": -12,
      "name": "Rock_Shale_Brick_Half",
      "rotation": 8
    },
    {
      "x": -7,
      "y": 16,
      "z": -12,
      "name": "Rock_Basalt_Cobble_Roof",
      "rotation": 3
    },
    {
      "x": -7,
      "y": 15,
      "z": -11,
      "name": "Rock_Shale_Brick"
    },
    {
      "x": -7,
      "y": 16,
      "z": -11,
      "name": "Rock_Basalt_Cobble_Roof",
      "rotation": 3
    },
    {
      "x": -7,
      "y": 7,
      "z": -10,
      "name": "Rock_Shale"
    },
    {
      "x": -7,
      "y": 8,
      "z": -10,
      "name": "Rock_Shale"
    },
    {
      "x": -7,
      "y": 9,
      "z": -10,
      "name": "Rock_Basalt_Brick"
    },
    {
      "x": -7,
      "y": 10,
      "z": -10,
      "name": "Rock_Basalt_Brick"
    },
    {
      "x": -7,
      "y": 11,
      "z": -10,
      "name": "Rock_Basalt_Brick"
    },
    {
      "x": -7,
      "y": 12,
      "z": -10,
      "name": "Rock_Basalt_Brick"
    },
    {
      "x": -7,
      "y": 13,
      "z": -10,
      "name": "Rock_Basalt_Brick"
    },
    {
      "x": -7,
      "y": 14,
      "z": -10,
      "name": "Rock_Shale_Brick"
    },
    {
      "x": -7,
      "y": 15,
      "z": -10,
      "name": "Rock_Shale_Brick"
    },
    {
      "x": -7,
      "y": 16,
      "z": -10,
      "name": "Rock_Shale_Cobble"
    },
    {
      "x": -7,
      "y": 17,
      "z": -10,
      "name": "Rock_Shale_Cobble_Wall",
      "rotation": 2
    },
    {
      "x": -7,
      "y": 6,
      "z": -9,
      "name": "Rock_Shale"
    },
    {
      "x": -7,
      "y": 7,
      "z": -9,
      "name": "Rock_Shale"
    },
    {
      "x": -7,
      "y": 8,
      "z": -9,
      "name": "Rock_Shale"
    },
    {
      "x": -7,
      "y": 9,
      "z": -9,
      "name": "Rock_Basalt_Brick"
    },
    {
      "x": -7,
      "y": 10,
      "z": -9,
      "name": "Rock_Basalt_Brick"
    },
    {
      "x": -7,
      "y": 11,
      "z": -9,
      "name": "Wood_Deadwood_Planks"
    },
    {
      "x": -7,
      "y": 12,
      "z": -9,
      "name": "Furniture_Village_Crate",
      "components": {
        "Components": {
          "container": {
            "Position": {
              "X": -7,
              "Y": 2,
              "Z": -9
            },
            "Custom": false,
            "AllowViewing": true,
            "ItemContainer": {
              "Capacity": 20,
              "Items": {}
            }
          }
        }
      }
    },
    {
      "x": -7,
      "y": 13,
      "z": -9,
      "name": "Furniture_Ancient_Barrel"
    },
    {
      "x": -7,
      "y": 14,
      "z": -9,
      "name": "Empty"
    },
    {
      "x": -7,
      "y": 15,
      "z": -9,
      "name": "Rock_Shale_Brick"
    },
    {
      "x": -7,
      "y": 16,
      "z": -9,
      "name": "Rock_Shale_Cobble"
    },
    {
      "x": -7,
      "y": 17,
      "z": -9,
      "name": "Block_Spawner_Block",
      "components": {
        "Components": {
          "BlockSpawner": {
            "BlockSpawnerId": "Zone3_Outlander_Tier1"
          }
        }
      }
    },
    {
      "x": -7,
      "y": 5,
      "z": -8,
      "name": "Rock_Shale"
    },
    {
      "x": -7,
      "y": 6,
      "z": -8,
      "name": "Rock_Shale"
    },
    {
      "x": -7,
      "y": 7,
      "z": -8,
      "name": "Rock_Shale"
    },
    {
      "x": -7,
      "y": 8,
      "z": -8,
      "name": "Rock_Shale"
    },
    {
      "x": -7,
      "y": 9,
      "z": -8,
      "name": "Rock_Basalt_Brick"
    },
    {
      "x": -7,
      "y": 10,
      "z": -8,
      "name": "Rock_Basalt_Brick"
    },
    {
      "x": -7,
      "y": 11,
      "z": -8,
      "name": "Wood_Deadwood_Planks"
    },
    {
      "x": -7,
      "y": 12,
      "z": -8,
      "name": "Furniture_Tavern_Barrel"
    },
    {
      "x": -7,
      "y": 13,
      "z": -8,
      "name": "Empty"
    },
    {
      "x": -7,
      "y": 14,
      "z": -8,
      "name": "Empty"
    },
    {
      "x": -7,
      "y": 15,
      "z": -8,
      "name": "Rock_Shale_Brick"
    },
    {
      "x": -7,
      "y": 16,
      "z": -8,
      "name": "Rock_Shale_Cobble"
    },
    {
      "x": -7,
      "y": 5,
      "z": -7,
      "name": "Rock_Shale"
    },
    {
      "x": -7,
      "y": 6,
      "z": -7,
      "name": "Rock_Shale"
    },
    {
      "x": -7,
      "y": 7,
      "z": -7,
      "name": "Rock_Shale"
    },
    {
      "x": -7,
      "y": 8,
      "z": -7,
      "name": "Rock_Shale"
    },
    {
      "x": -7,
      "y": 9,
      "z": -7,
      "name": "Rock_Basalt_Brick"
    },
    {
      "x": -7,
      "y": 10,
      "z": -7,
      "name": "Rock_Basalt_Brick"
    },
    {
      "x": -7,
      "y": 11,
      "z": -7,
      "name": "Wood_Deadwood_Planks"
    },
    {
      "x": -7,
      "y": 12,
      "z": -7,
      "name": "Furniture_Lumberjack_Wardrobe",
      "rotation": 1
    },
    {
      "x": -7,
      "y": 13,
      "z": -7,
      "name": "Furniture_Lumberjack_Wardrobe",
      "filler": 1024,
      "rotation": 1
    },
    {
      "x": -7,
      "y": 14,
      "z": -7,
      "name": "Empty"
    },
    {
      "x": -7,
      "y": 15,
      "z": -7,
      "name": "Rock_Shale_Brick"
    },
    {
      "x": -7,
      "y": 16,
      "z": -7,
      "name": "Rock_Shale_Cobble"
    },
    {
      "x": -7,
      "y": 5,
      "z": -6,
      "name": "Rock_Shale"
    },
    {
      "x": -7,
      "y": 6,
      "z": -6,
      "name": "Rock_Shale"
    },
    {
      "x": -7,
      "y": 7,
      "z": -6,
      "name": "Rock_Shale"
    },
    {
      "x": -7,
      "y": 8,
      "z": -6,
      "name": "Rock_Shale"
    },
    {
      "x": -7,
      "y": 9,
      "z": -6,
      "name": "Rock_Basalt_Brick"
    },
    {
      "x": -7,
      "y": 10,
      "z": -6,
      "name": "Rock_Basalt_Brick"
    },
    {
      "x": -7,
      "y": 11,
      "z": -6,
      "name": "Wood_Deadwood_Planks"
    },
    {
      "x": -7,
      "y": 12,
      "z": -6,
      "name": "Furniture_Lumberjack_Wardrobe",
      "filler": 32,
      "rotation": 1
    },
    {
      "x": -7,
      "y": 13,
      "z": -6,
      "name": "Furniture_Lumberjack_Wardrobe",
      "filler": 1056,
      "rotation": 1
    },
    {
      "x": -7,
      "y": 14,
      "z": -6,
      "name": "Empty"
    },
    {
      "x": -7,
      "y": 15,
      "z": -6,
      "name": "Rock_Shale_Brick"
    },
    {
      "x": -7,
      "y": 16,
      "z": -6,
      "name": "Rock_Shale_Cobble"
    },
    {
      "x": -7,
      "y": 4,
      "z": -5,
      "name": "Rock_Shale"
    },
    {
      "x": -7,
      "y": 5,
      "z": -5,
      "name": "Rock_Shale"
    },
    {
      "x": -7,
      "y": 6,
      "z": -5,
      "name": "Rock_Shale"
    },
    {
      "x": -7,
      "y": 7,
      "z": -5,
      "name": "Rock_Shale"
    },
    {
      "x": -7,
      "y": 8,
      "z": -5,
      "name": "Rock_Shale"
    },
    {
      "x": -7,
      "y": 9,
      "z": -5,
      "name": "Rock_Shale"
    },
    {
      "x": -7,
      "y": 10,
      "z": -5,
      "name": "Rock_Basalt_Brick"
    },
    {
      "x": -7,
      "y": 11,
      "z": -5,
      "name": "Wood_Deadwood_Planks"
    },
    {
      "x": -7,
      "y": 12,
      "z": -5,
      "name": "Furniture_Lumberjack_Platform",
      "rotation": 1
    },
    {
      "x": -7,
      "y": 13,
      "z": -5,
      "name": "Empty"
    },
    {
      "x": -7,
      "y": 14,
      "z": -5,
      "name": "Empty"
    },
    {
      "x": -7,
      "y": 15,
      "z": -5,
      "name": "Rock_Shale_Brick"
    },
    {
      "x": -7,
      "y": 16,
      "z": -5,
      "name": "Rock_Shale_Cobble"
    },
    {
      "x": -7,
      "y": 4,
      "z": -4,
      "name": "Rock_Shale"
    },
    {
      "x": -7,
      "y": 5,
      "z": -4,
      "name": "Rock_Shale"
    },
    {
      "x": -7,
      "y": 6,
      "z": -4,
      "name": "Rock_Shale"
    },
    {
      "x": -7,
      "y": 7,
      "z": -4,
      "name": "Rock_Shale"
    },
    {
      "x": -7,
      "y": 8,
      "z": -4,
      "name": "Rock_Shale"
    },
    {
      "x": -7,
      "y": 9,
      "z": -4,
      "name": "Rock_Shale"
    },
    {
      "x": -7,
      "y": 10,
      "z": -4,
      "name": "Rock_Basalt_Brick"
    },
    {
      "x": -7,
      "y": 11,
      "z": -4,
      "name": "Wood_Deadwood_Planks"
    },
    {
      "x": -7,
      "y": 12,
      "z": -4,
      "name": "Furniture_Lumberjack_Platform",
      "rotation": 1
    },
    {
      "x": -7,
      "y": 13,
      "z": -4,
      "name": "Container_Bucket"
    },
    {
      "x": -7,
      "y": 14,
      "z": -4,
      "name": "Empty"
    },
    {
      "x": -7,
      "y": 15,
      "z": -4,
      "name": "Rock_Shale_Brick"
    },
    {
      "x": -7,
      "y": 16,
      "z": -4,
      "name": "Rock_Shale_Cobble"
    },
    {
      "x": -7,
      "y": 4,
      "z": -3,
      "name": "Rock_Shale"
    },
    {
      "x": -7,
      "y": 5,
      "z": -3,
      "name": "Rock_Shale"
    },
    {
      "x": -7,
      "y": 6,
      "z": -3,
      "name": "Rock_Shale"
    },
    {
      "x": -7,
      "y": 7,
      "z": -3,
      "name": "Rock_Shale"
    },
    {
      "x": -7,
      "y": 8,
      "z": -3,
      "name": "Rock_Shale"
    },
    {
      "x": -7,
      "y": 9,
      "z": -3,
      "name": "Rock_Shale"
    },
    {
      "x": -7,
      "y": 10,
      "z": -3,
      "name": "Rock_Basalt_Brick"
    },
    {
      "x": -7,
      "y": 11,
      "z": -3,
      "name": "Wood_Deadwood_Planks"
    },
    {
      "x": -7,
      "y": 12,
      "z": -3,
      "name": "Empty"
    },
    {
      "x": -7,
      "y": 13,
      "z": -3,
      "name": "Empty"
    },
    {
      "x": -7,
      "y": 14,
      "z": -3,
      "name": "Empty"
    },
    {
      "x": -7,
      "y": 15,
      "z": -3,
      "name": "Rock_Shale_Brick"
    },
    {
      "x": -7,
      "y": 16,
      "z": -3,
      "name": "Rock_Shale_Cobble"
    },
    {
      "x": -7,
      "y": 4,
      "z": -2,
      "name": "Rock_Shale"
    },
    {
      "x": -7,
      "y": 5,
      "z": -2,
      "name": "Rock_Shale"
    },
    {
      "x": -7,
      "y": 6,
      "z": -2,
      "name": "Rock_Shale"
    },
    {
      "x": -7,
      "y": 7,
      "z": -2,
      "name": "Rock_Shale"
    },
    {
      "x": -7,
      "y": 8,
      "z": -2,
      "name": "Rock_Shale"
    },
    {
      "x": -7,
      "y": 9,
      "z": -2,
      "name": "Rock_Shale"
    },
    {
      "x": -7,
      "y": 10,
      "z": -2,
      "name": "Rock_Basalt_Brick"
    },
    {
      "x": -7,
      "y": 11,
      "z": -2,
      "name": "Wood_Deadwood_Planks"
    },
    {
      "x": -7,
      "y": 12,
      "z": -2,
      "name": "Empty"
    },
    {
      "x": -7,
      "y": 13,
      "z": -2,
      "name": "Empty"
    },
    {
      "x": -7,
      "y": 14,
      "z": -2,
      "name": "Empty"
    },
    {
      "x": -7,
      "y": 15,
      "z": -2,
      "name": "Rock_Shale_Brick_Half",
      "rotation": 8
    },
    {
      "x": -7,
      "y": 16,
      "z": -2,
      "name": "Rock_Shale_Cobble"
    },
    {
      "x": -7,
      "y": 5,
      "z": -1,
      "name": "Rock_Shale"
    },
    {
      "x": -7,
      "y": 6,
      "z": -1,
      "name": "Rock_Shale"
    },
    {
      "x": -7,
      "y": 7,
      "z": -1,
      "name": "Rock_Shale"
    },
    {
      "x": -7,
      "y": 8,
      "z": -1,
      "name": "Rock_Shale"
    },
    {
      "x": -7,
      "y": 9,
      "z": -1,
      "name": "Rock_Shale"
    },
    {
      "x": -7,
      "y": 10,
      "z": -1,
      "name": "Rock_Basalt_Brick"
    },
    {
      "x": -7,
      "y": 11,
      "z": -1,
      "name": "Wood_Deadwood_Planks"
    },
    {
      "x": -7,
      "y": 12,
      "z": -1,
      "name": "Empty"
    },
    {
      "x": -7,
      "y": 13,
      "z": -1,
      "name": "Empty"
    },
    {
      "x": -7,
      "y": 14,
      "z": -1,
      "name": "Empty"
    },
    {
      "x": -7,
      "y": 15,
      "z": -1,
      "name": "Rock_Shale_Brick"
    },
    {
      "x": -7,
      "y": 16,
      "z": -1,
      "name": "Rock_Shale_Cobble"
    },
    {
      "x": -7,
      "y": 5,
      "z": 0,
      "name": "Rock_Shale"
    },
    {
      "x": -7,
      "y": 6,
      "z": 0,
      "name": "Rock_Shale"
    },
    {
      "x": -7,
      "y": 7,
      "z": 0,
      "name": "Rock_Shale"
    },
    {
      "x": -7,
      "y": 8,
      "z": 0,
      "name": "Rock_Shale"
    },
    {
      "x": -7,
      "y": 9,
      "z": 0,
      "name": "Rock_Shale"
    },
    {
      "x": -7,
      "y": 10,
      "z": 0,
      "name": "Rock_Basalt_Brick"
    },
    {
      "x": -7,
      "y": 11,
      "z": 0,
      "name": "Wood_Deadwood_Planks"
    },
    {
      "x": -7,
      "y": 12,
      "z": 0,
      "name": "Furniture_Village_Crate",
      "components": {
        "Components": {
          "container": {
            "Position": {
              "X": -7,
              "Y": 2,
              "Z": 0
            },
            "Custom": false,
            "AllowViewing": true,
            "ItemContainer": {
              "Capacity": 20,
              "Items": {}
            }
          }
        }
      }
    },
    {
      "x": -7,
      "y": 13,
      "z": 0,
      "name": "Empty"
    },
    {
      "x": -7,
      "y": 14,
      "z": 0,
      "name": "Empty"
    },
    {
      "x": -7,
      "y": 15,
      "z": 0,
      "name": "Rock_Shale_Brick"
    },
    {
      "x": -7,
      "y": 16,
      "z": 0,
      "name": "Rock_Shale_Cobble"
    },
    {
      "x": -7,
      "y": 6,
      "z": 1,
      "name": "Rock_Shale"
    },
    {
      "x": -7,
      "y": 7,
      "z": 1,
      "name": "Rock_Shale"
    },
    {
      "x": -7,
      "y": 8,
      "z": 1,
      "name": "Rock_Shale"
    },
    {
      "x": -7,
      "y": 9,
      "z": 1,
      "name": "Rock_Shale"
    },
    {
      "x": -7,
      "y": 10,
      "z": 1,
      "name": "Rock_Basalt_Brick"
    },
    {
      "x": -7,
      "y": 11,
      "z": 1,
      "name": "Rock_Basalt_Brick"
    },
    {
      "x": -7,
      "y": 12,
      "z": 1,
      "name": "Rock_Basalt_Brick"
    },
    {
      "x": -7,
      "y": 13,
      "z": 1,
      "name": "Rock_Shale_Brick"
    },
    {
      "x": -7,
      "y": 14,
      "z": 1,
      "name": "Rock_Shale_Brick"
    },
    {
      "x": -7,
      "y": 15,
      "z": 1,
      "name": "Rock_Shale_Brick"
    },
    {
      "x": -7,
      "y": 16,
      "z": 1,
      "name": "Rock_Shale_Cobble"
    },
    {
      "x": -7,
      "y": 9,
      "z": 2,
      "name": "Rock_Shale_Cobble"
    },
    {
      "x": -7,
      "y": 10,
      "z": 2,
      "name": "Rock_Shale_Cobble"
    },
    {
      "x": -7,
      "y": 11,
      "z": 2,
      "name": "Rock_Shale_Cobble"
    },
    {
      "x": -7,
      "y": 12,
      "z": 2,
      "name": "Rock_Shale_Cobble"
    },
    {
      "x": -7,
      "y": 13,
      "z": 2,
      "name": "Rock_Shale_Brick"
    },
    {
      "x": -7,
      "y": 14,
      "z": 2,
      "name": "Rock_Shale_Brick"
    },
    {
      "x": -7,
      "y": 15,
      "z": 2,
      "name": "Rock_Shale_Brick"
    },
    {
      "x": -7,
      "y": 16,
      "z": 2,
      "name": "Rock_Shale_Cobble"
    },
    {
      "x": -7,
      "y": 10,
      "z": 3,
      "name": "Rock_Shale_Cobble"
    },
    {
      "x": -7,
      "y": 11,
      "z": 3,
      "name": "Rock_Shale_Cobble"
    },
    {
      "x": -7,
      "y": 12,
      "z": 3,
      "name": "Rock_Shale_Brick"
    },
    {
      "x": -7,
      "y": 13,
      "z": 3,
      "name": "Rock_Shale_Brick"
    },
    {
      "x": -7,
      "y": 14,
      "z": 3,
      "name": "Rock_Shale_Brick"
    },
    {
      "x": -7,
      "y": 15,
      "z": 3,
      "name": "Rock_Shale_Brick"
    },
    {
      "x": -7,
      "y": 16,
      "z": 3,
      "name": "Rock_Shale_Cobble"
    },
    {
      "x": -7,
      "y": 9,
      "z": 4,
      "name": "Soil_Dirt_Cold"
    },
    {
      "x": -7,
      "y": 10,
      "z": 4,
      "name": "Soil_Dirt_Cold"
    },
    {
      "x": -7,
      "y": 13,
      "z": 4,
      "name": "Rock_Shale_Brick"
    },
    {
      "x": -7,
      "y": 14,
      "z": 4,
      "name": "Rock_Shale_Brick"
    },
    {
      "x": -7,
      "y": 15,
      "z": 4,
      "name": "Rock_Shale_Brick"
    },
    {
      "x": -7,
      "y": 16,
      "z": 4,
      "name": "Rock_Shale_Cobble"
    },
    {
      "x": -7,
      "y": 8,
      "z": 5,
      "name": "Soil_Dirt_Cold"
    },
    {
      "x": -7,
      "y": 9,
      "z": 5,
      "name": "Soil_Dirt_Cold"
    },
    {
      "x": -7,
      "y": 10,
      "z": 5,
      "name": "Soil_Dirt_Cold"
    },
    {
      "x": -7,
      "y": 15,
      "z": 5,
      "name": "Rock_Shale_Brick"
    },
    {
      "x": -7,
      "y": 16,
      "z": 5,
      "name": "Rock_Shale_Cobble"
    },
    {
      "x": -7,
      "y": 17,
      "z": 5,
      "name": "Rock_Shale_Cobble_Wall"
    },
    {
      "x": -7,
      "y": 8,
      "z": 6,
      "name": "Soil_Dirt_Cold"
    },
    {
      "x": -7,
      "y": 9,
      "z": 6,
      "name": "Soil_Dirt_Cold"
    },
    {
      "x": -7,
      "y": 10,
      "z": 6,
      "name": "Soil_Dirt_Cold"
    },
    {
      "x": -7,
      "y": 8,
      "z": 7,
      "name": "Soil_Dirt_Cold"
    },
    {
      "x": -7,
      "y": 9,
      "z": 7,
      "name": "Soil_Dirt_Cold"
    },
    {
      "x": -7,
      "y": 10,
      "z": 7,
      "name": "Soil_Dirt_Cold"
    },
    {
      "x": -7,
      "y": 9,
      "z": 8,
      "name": "Soil_Dirt_Cold"
    },
    {
      "x": -7,
      "y": 10,
      "z": 8,
      "name": "Soil_Dirt_Cold"
    },
    {
      "x": -7,
      "y": 7,
      "z": 9,
      "name": "Rock_Shale"
    },
    {
      "x": -7,
      "y": 8,
      "z": 9,
      "name": "Rock_Basalt_Brick"
    },
    {
      "x": -7,
      "y": 9,
      "z": 9,
      "name": "Rock_Basalt_Brick"
    },
    {
      "x": -7,
      "y": 10,
      "z": 9,
      "name": "Rock_Basalt_Brick"
    },
    {
      "x": -7,
      "y": 11,
      "z": 9,
      "name": "Rock_Basalt_Brick"
    },
    {
      "x": -7,
      "y": 12,
      "z": 9,
      "name": "Rock_Shale_Brick"
    },
    {
      "x": -7,
      "y": 13,
      "z": 9,
      "name": "Rock_Shale_Brick"
    },
    {
      "x": -7,
      "y": 14,
      "z": 9,
      "name": "Rock_Shale_Brick"
    },
    {
      "x": -7,
      "y": 15,
      "z": 9,
      "name": "Rock_Shale_Cobble"
    },
    {
      "x": -7,
      "y": 16,
      "z": 9,
      "name": "Rock_Shale_Cobble"
    },
    {
      "x": -7,
      "y": 17,
      "z": 9,
      "name": "Rock_Shale_Cobble_Half",
      "rotation": 6
    },
    {
      "x": -7,
      "y": 18,
      "z": 9,
      "name": "Rock_Shale_Brick"
    },
    {
      "x": -7,
      "y": 19,
      "z": 9,
      "name": "*Rock_Shale_Cobble_Wall_State_Definitions_Corner",
      "rotation": 1
    },
    {
      "x": -7,
      "y": 6,
      "z": 10,
      "name": "Rock_Shale"
    },
    {
      "x": -7,
      "y": 7,
      "z": 10,
      "name": "Rock_Shale"
    },
    {
      "x": -7,
      "y": 8,
      "z": 10,
      "name": "Rock_Basalt_Brick"
    },
    {
      "x": -7,
      "y": 9,
      "z": 10,
      "name": "Rock_Basalt_Brick"
    },
    {
      "x": -7,
      "y": 10,
      "z": 10,
      "name": "Rock_Basalt_Brick"
    },
    {
      "x": -7,
      "y": 11,
      "z": 10,
      "name": "Rock_Shale_Brick"
    },
    {
      "x": -7,
      "y": 12,
      "z": 10,
      "name": "Rock_Shale_Brick"
    },
    {
      "x": -7,
      "y": 13,
      "z": 10,
      "name": "Rock_Shale_Brick"
    },
    {
      "x": -7,
      "y": 14,
      "z": 10,
      "name": "Rock_Shale_Brick"
    },
    {
      "x": -7,
      "y": 15,
      "z": 10,
      "name": "Rock_Shale_Cobble"
    },
    {
      "x": -7,
      "y": 16,
      "z": 10,
      "name": "Rock_Shale_Cobble"
    },
    {
      "x": -7,
      "y": 17,
      "z": 10,
      "name": "Rock_Shale_Cobble"
    },
    {
      "x": -7,
      "y": 18,
      "z": 10,
      "name": "Rock_Shale_Brick"
    },
    {
      "x": -7,
      "y": 19,
      "z": 10,
      "name": "Rock_Shale_Cobble_Wall",
      "rotation": 3
    },
    {
      "x": -7,
      "y": 9,
      "z": 11,
      "name": "Rock_Basalt_Brick"
    },
    {
      "x": -7,
      "y": 10,
      "z": 11,
      "name": "Rock_Basalt_Brick"
    },
    {
      "x": -7,
      "y": 11,
      "z": 11,
      "name": "Rock_Basalt_Brick"
    },
    {
      "x": -7,
      "y": 12,
      "z": 11,
      "name": "Rock_Basalt_Brick"
    },
    {
      "x": -7,
      "y": 13,
      "z": 11,
      "name": "Rock_Shale_Brick"
    },
    {
      "x": -7,
      "y": 14,
      "z": 11,
      "name": "Rock_Shale_Brick"
    },
    {
      "x": -7,
      "y": 15,
      "z": 11,
      "name": "Rock_Shale_Brick"
    },
    {
      "x": -7,
      "y": 16,
      "z": 11,
      "name": "Rock_Shale_Cobble"
    },
    {
      "x": -7,
      "y": 17,
      "z": 11,
      "name": "Rock_Shale_Cobble"
    },
    {
      "x": -7,
      "y": 18,
      "z": 11,
      "name": "Rock_Shale_Brick"
    },
    {
      "x": -7,
      "y": 19,
      "z": 11,
      "name": "Rock_Shale_Cobble_Wall",
      "rotation": 3
    },
    {
      "x": -7,
      "y": 14,
      "z": 12,
      "name": "Rock_Shale_Brick_Half",
      "rotation": 7
    },
    {
      "x": -7,
      "y": 15,
      "z": 12,
      "name": "Rock_Shale_Brick_Half",
      "rotation": 7
    },
    {
      "x": -7,
      "y": 16,
      "z": 12,
      "name": "Rock_Shale_Cobble_Half",
      "rotation": 7
    },
    {
      "x": -7,
      "y": 17,
      "z": 12,
      "name": "Rock_Shale_Cobble_Half",
      "rotation": 7
    },
    {
      "x": -7,
      "y": 18,
      "z": 12,
      "name": "Rock_Shale_Brick"
    },
    {
      "x": -7,
      "y": 19,
      "z": 12,
      "name": "*Rock_Shale_Cobble_Wall_State_Definitions_Corner",
      "rotation": 2
    },
    {
      "x": -6,
      "y": 15,
      "z": -12,
      "name": "Rock_Shale_Brick"
    },
    {
      "x": -6,
      "y": 16,
      "z": -12,
      "name": "Rock_Basalt_Cobble"
    },
    {
      "x": -6,
      "y": 17,
      "z": -12,
      "name": "Rock_Basalt_Cobble_Roof",
      "rotation": 3
    },
    {
      "x": -6,
      "y": 6,
      "z": -11,
      "name": "Rock_Shale"
    },
    {
      "x": -6,
      "y": 7,
      "z": -11,
      "name": "Rock_Shale"
    },
    {
      "x": -6,
      "y": 8,
      "z": -11,
      "name": "Rock_Shale"
    },
    {
      "x": -6,
      "y": 9,
      "z": -11,
      "name": "Rock_Basalt_Brick"
    },
    {
      "x": -6,
      "y": 10,
      "z": -11,
      "name": "Rock_Basalt_Brick"
    },
    {
      "x": -6,
      "y": 11,
      "z": -11,
      "name": "Rock_Basalt_Brick"
    },
    {
      "x": -6,
      "y": 12,
      "z": -11,
      "name": "Rock_Basalt_Brick"
    },
    {
      "x": -6,
      "y": 13,
      "z": -11,
      "name": "Rock_Basalt_Brick"
    },
    {
      "x": -6,
      "y": 14,
      "z": -11,
      "name": "Rock_Shale_Brick"
    },
    {
      "x": -6,
      "y": 15,
      "z": -11,
      "name": "Rock_Shale_Cobble"
    },
    {
      "x": -6,
      "y": 16,
      "z": -11,
      "name": "Rock_Basalt_Cobble"
    },
    {
      "x": -6,
      "y": 17,
      "z": -11,
      "name": "Rock_Basalt_Cobble_Roof",
      "rotation": 3
    },
    {
      "x": -6,
      "y": 4,
      "z": -10,
      "name": "Rock_Shale"
    },
    {
      "x": -6,
      "y": 5,
      "z": -10,
      "name": "Rock_Shale"
    },
    {
      "x": -6,
      "y": 6,
      "z": -10,
      "name": "Rock_Shale"
    },
    {
      "x": -6,
      "y": 7,
      "z": -10,
      "name": "Rock_Shale"
    },
    {
      "x": -6,
      "y": 8,
      "z": -10,
      "name": "Rock_Shale"
    },
    {
      "x": -6,
      "y": 9,
      "z": -10,
      "name": "Rock_Basalt_Brick"
    },
    {
      "x": -6,
      "y": 10,
      "z": -10,
      "name": "Rock_Basalt_Brick"
    },
    {
      "x": -6,
      "y": 11,
      "z": -10,
      "name": "Rock_Basalt_Brick"
    },
    {
      "x": -6,
      "y": 12,
      "z": -10,
      "name": "Rock_Basalt_Brick"
    },
    {
      "x": -6,
      "y": 13,
      "z": -10,
      "name": "Rock_Basalt_Brick"
    },
    {
      "x": -6,
      "y": 14,
      "z": -10,
      "name": "Rock_Shale_Brick"
    },
    {
      "x": -6,
      "y": 15,
      "z": -10,
      "name": "Rock_Shale_Brick"
    },
    {
      "x": -6,
      "y": 16,
      "z": -10,
      "name": "Rock_Basalt_Cobble"
    },
    {
      "x": -6,
      "y": 17,
      "z": -10,
      "name": "Rock_Basalt_Cobble_Roof",
      "rotation": 3
    },
    {
      "x": -6,
      "y": 4,
      "z": -9,
      "name": "Rock_Shale"
    },
    {
      "x": -6,
      "y": 5,
      "z": -9,
      "name": "Rock_Shale"
    },
    {
      "x": -6,
      "y": 6,
      "z": -9,
      "name": "Rock_Shale"
    },
    {
      "x": -6,
      "y": 7,
      "z": -9,
      "name": "Rock_Shale"
    },
    {
      "x": -6,
      "y": 8,
      "z": -9,
      "name": "Rock_Shale"
    },
    {
      "x": -6,
      "y": 9,
      "z": -9,
      "name": "Rock_Basalt_Brick"
    },
    {
      "x": -6,
      "y": 10,
      "z": -9,
      "name": "Rock_Basalt_Brick"
    },
    {
      "x": -6,
      "y": 11,
      "z": -9,
      "name": "Wood_Deadwood_Planks"
    },
    {
      "x": -6,
      "y": 12,
      "z": -9,
      "name": "Empty"
    },
    {
      "x": -6,
      "y": 13,
      "z": -9,
      "name": "Empty"
    },
    {
      "x": -6,
      "y": 14,
      "z": -9,
      "name": "Empty"
    },
    {
      "x": -6,
      "y": 15,
      "z": -9,
      "name": "Empty"
    },
    {
      "x": -6,
      "y": 16,
      "z": -9,
      "name": "Wood_Fir_Trunk",
      "rotation": 4
    },
    {
      "x": -6,
      "y": 17,
      "z": -9,
      "name": "Rock_Basalt_Cobble_Roof",
      "rotation": 3
    },
    {
      "x": -6,
      "y": 3,
      "z": -8,
      "name": "Rock_Shale"
    },
    {
      "x": -6,
      "y": 4,
      "z": -8,
      "name": "Rock_Shale"
    },
    {
      "x": -6,
      "y": 5,
      "z": -8,
      "name": "Rock_Shale"
    },
    {
      "x": -6,
      "y": 6,
      "z": -8,
      "name": "Rock_Shale"
    },
    {
      "x": -6,
      "y": 7,
      "z": -8,
      "name": "Rock_Shale"
    },
    {
      "x": -6,
      "y": 8,
      "z": -8,
      "name": "Rock_Shale"
    },
    {
      "x": -6,
      "y": 9,
      "z": -8,
      "name": "Rock_Basalt_Brick"
    },
    {
      "x": -6,
      "y": 10,
      "z": -8,
      "name": "Rock_Basalt_Brick"
    },
    {
      "x": -6,
      "y": 11,
      "z": -8,
      "name": "Wood_Deadwood_Planks"
    },
    {
      "x": -6,
      "y": 12,
      "z": -8,
      "name": "Empty"
    },
    {
      "x": -6,
      "y": 13,
      "z": -8,
      "name": "Empty"
    },
    {
      "x": -6,
      "y": 14,
      "z": -8,
      "name": "Empty"
    },
    {
      "x": -6,
      "y": 15,
      "z": -8,
      "name": "Empty"
    },
    {
      "x": -6,
      "y": 16,
      "z": -8,
      "name": "Wood_Fir_Trunk",
      "rotation": 4
    },
    {
      "x": -6,
      "y": 17,
      "z": -8,
      "name": "Rock_Basalt_Cobble_Roof",
      "rotation": 3
    },
    {
      "x": -6,
      "y": 3,
      "z": -7,
      "name": "Rock_Shale"
    },
    {
      "x": -6,
      "y": 4,
      "z": -7,
      "name": "Rock_Shale"
    },
    {
      "x": -6,
      "y": 5,
      "z": -7,
      "name": "Rock_Shale"
    },
    {
      "x": -6,
      "y": 6,
      "z": -7,
      "name": "Rock_Shale"
    },
    {
      "x": -6,
      "y": 7,
      "z": -7,
      "name": "Rock_Shale"
    },
    {
      "x": -6,
      "y": 8,
      "z": -7,
      "name": "Rock_Shale"
    },
    {
      "x": -6,
      "y": 9,
      "z": -7,
      "name": "Rock_Basalt_Brick"
    },
    {
      "x": -6,
      "y": 10,
      "z": -7,
      "name": "Rock_Basalt_Brick"
    },
    {
      "x": -6,
      "y": 11,
      "z": -7,
      "name": "Wood_Deadwood_Planks"
    },
    {
      "x": -6,
      "y": 12,
      "z": -7,
      "name": "Empty"
    },
    {
      "x": -6,
      "y": 13,
      "z": -7,
      "name": "Empty"
    },
    {
      "x": -6,
      "y": 14,
      "z": -7,
      "name": "Empty"
    },
    {
      "x": -6,
      "y": 15,
      "z": -7,
      "name": "Empty"
    },
    {
      "x": -6,
      "y": 16,
      "z": -7,
      "name": "Wood_Fir_Trunk",
      "rotation": 4
    },
    {
      "x": -6,
      "y": 17,
      "z": -7,
      "name": "Rock_Basalt_Cobble_Roof",
      "rotation": 3
    },
    {
      "x": -6,
      "y": 3,
      "z": -6,
      "name": "Rock_Shale"
    },
    {
      "x": -6,
      "y": 4,
      "z": -6,
      "name": "Rock_Shale"
    },
    {
      "x": -6,
      "y": 5,
      "z": -6,
      "name": "Rock_Shale"
    },
    {
      "x": -6,
      "y": 6,
      "z": -6,
      "name": "Rock_Shale"
    },
    {
      "x": -6,
      "y": 7,
      "z": -6,
      "name": "Rock_Shale"
    },
    {
      "x": -6,
      "y": 8,
      "z": -6,
      "name": "Rock_Shale"
    },
    {
      "x": -6,
      "y": 9,
      "z": -6,
      "name": "Rock_Basalt_Brick"
    },
    {
      "x": -6,
      "y": 10,
      "z": -6,
      "name": "Rock_Basalt_Brick"
    },
    {
      "x": -6,
      "y": 11,
      "z": -6,
      "name": "Wood_Deadwood_Planks"
    },
    {
      "x": -6,
      "y": 12,
      "z": -6,
      "name": "Empty"
    },
    {
      "x": -6,
      "y": 13,
      "z": -6,
      "name": "Empty"
    },
    {
      "x": -6,
      "y": 14,
      "z": -6,
      "name": "Empty"
    },
    {
      "x": -6,
      "y": 15,
      "z": -6,
      "name": "Empty"
    },
    {
      "x": -6,
      "y": 16,
      "z": -6,
      "name": "Wood_Fir_Trunk",
      "rotation": 4
    },
    {
      "x": -6,
      "y": 17,
      "z": -6,
      "name": "Rock_Basalt_Cobble_Roof",
      "rotation": 3
    },
    {
      "x": -6,
      "y": 3,
      "z": -5,
      "name": "Rock_Shale"
    },
    {
      "x": -6,
      "y": 4,
      "z": -5,
      "name": "Rock_Shale"
    },
    {
      "x": -6,
      "y": 5,
      "z": -5,
      "name": "Rock_Shale"
    },
    {
      "x": -6,
      "y": 6,
      "z": -5,
      "name": "Rock_Shale"
    },
    {
      "x": -6,
      "y": 7,
      "z": -5,
      "name": "Rock_Shale"
    },
    {
      "x": -6,
      "y": 8,
      "z": -5,
      "name": "Rock_Shale"
    },
    {
      "x": -6,
      "y": 9,
      "z": -5,
      "name": "Rock_Shale"
    },
    {
      "x": -6,
      "y": 10,
      "z": -5,
      "name": "Rock_Basalt_Brick"
    },
    {
      "x": -6,
      "y": 11,
      "z": -5,
      "name": "Wood_Deadwood_Planks"
    },
    {
      "x": -6,
      "y": 12,
      "z": -5,
      "name": "Empty"
    },
    {
      "x": -6,
      "y": 13,
      "z": -5,
      "name": "Empty"
    },
    {
      "x": -6,
      "y": 14,
      "z": -5,
      "name": "Empty"
    },
    {
      "x": -6,
      "y": 15,
      "z": -5,
      "name": "Empty"
    },
    {
      "x": -6,
      "y": 16,
      "z": -5,
      "name": "Wood_Fir_Trunk",
      "rotation": 4
    },
    {
      "x": -6,
      "y": 17,
      "z": -5,
      "name": "Rock_Basalt_Cobble_Roof",
      "rotation": 3
    },
    {
      "x": -6,
      "y": 3,
      "z": -4,
      "name": "Rock_Shale"
    },
    {
      "x": -6,
      "y": 4,
      "z": -4,
      "name": "Rock_Shale"
    },
    {
      "x": -6,
      "y": 5,
      "z": -4,
      "name": "Rock_Shale"
    },
    {
      "x": -6,
      "y": 6,
      "z": -4,
      "name": "Rock_Shale"
    },
    {
      "x": -6,
      "y": 7,
      "z": -4,
      "name": "Rock_Shale"
    },
    {
      "x": -6,
      "y": 8,
      "z": -4,
      "name": "Rock_Shale"
    },
    {
      "x": -6,
      "y": 9,
      "z": -4,
      "name": "Rock_Shale"
    },
    {
      "x": -6,
      "y": 10,
      "z": -4,
      "name": "Rock_Basalt_Brick"
    },
    {
      "x": -6,
      "y": 11,
      "z": -4,
      "name": "Wood_Deadwood_Planks"
    },
    {
      "x": -6,
      "y": 12,
      "z": -4,
      "name": "Empty"
    },
    {
      "x": -6,
      "y": 13,
      "z": -4,
      "name": "Empty"
    },
    {
      "x": -6,
      "y": 14,
      "z": -4,
      "name": "Empty"
    },
    {
      "x": -6,
      "y": 15,
      "z": -4,
      "name": "Empty"
    },
    {
      "x": -6,
      "y": 16,
      "z": -4,
      "name": "Wood_Fir_Trunk",
      "rotation": 4
    },
    {
      "x": -6,
      "y": 17,
      "z": -4,
      "name": "Rock_Basalt_Cobble_Roof",
      "rotation": 3
    },
    {
      "x": -6,
      "y": 3,
      "z": -3,
      "name": "Rock_Shale"
    },
    {
      "x": -6,
      "y": 4,
      "z": -3,
      "name": "Rock_Shale"
    },
    {
      "x": -6,
      "y": 5,
      "z": -3,
      "name": "Rock_Shale"
    },
    {
      "x": -6,
      "y": 6,
      "z": -3,
      "name": "Rock_Shale"
    },
    {
      "x": -6,
      "y": 7,
      "z": -3,
      "name": "Rock_Shale"
    },
    {
      "x": -6,
      "y": 8,
      "z": -3,
      "name": "Rock_Shale"
    },
    {
      "x": -6,
      "y": 9,
      "z": -3,
      "name": "Rock_Shale"
    },
    {
      "x": -6,
      "y": 10,
      "z": -3,
      "name": "Rock_Basalt_Brick"
    },
    {
      "x": -6,
      "y": 11,
      "z": -3,
      "name": "Wood_Deadwood_Planks"
    },
    {
      "x": -6,
      "y": 12,
      "z": -3,
      "name": "Empty"
    },
    {
      "x": -6,
      "y": 13,
      "z": -3,
      "name": "Empty"
    },
    {
      "x": -6,
      "y": 14,
      "z": -3,
      "name": "Empty"
    },
    {
      "x": -6,
      "y": 15,
      "z": -3,
      "name": "Empty"
    },
    {
      "x": -6,
      "y": 16,
      "z": -3,
      "name": "Wood_Fir_Trunk",
      "rotation": 4
    },
    {
      "x": -6,
      "y": 17,
      "z": -3,
      "name": "Rock_Basalt_Cobble_Roof",
      "rotation": 3
    },
    {
      "x": -6,
      "y": 3,
      "z": -2,
      "name": "Rock_Shale"
    },
    {
      "x": -6,
      "y": 4,
      "z": -2,
      "name": "Rock_Shale"
    },
    {
      "x": -6,
      "y": 5,
      "z": -2,
      "name": "Rock_Shale"
    },
    {
      "x": -6,
      "y": 6,
      "z": -2,
      "name": "Rock_Shale"
    },
    {
      "x": -6,
      "y": 7,
      "z": -2,
      "name": "Rock_Shale"
    },
    {
      "x": -6,
      "y": 8,
      "z": -2,
      "name": "Rock_Shale"
    },
    {
      "x": -6,
      "y": 9,
      "z": -2,
      "name": "Rock_Shale"
    },
    {
      "x": -6,
      "y": 10,
      "z": -2,
      "name": "Rock_Basalt_Brick"
    },
    {
      "x": -6,
      "y": 11,
      "z": -2,
      "name": "Wood_Deadwood_Planks"
    },
    {
      "x": -6,
      "y": 12,
      "z": -2,
      "name": "Empty"
    },
    {
      "x": -6,
      "y": 13,
      "z": -2,
      "name": "Empty"
    },
    {
      "x": -6,
      "y": 14,
      "z": -2,
      "name": "Empty"
    },
    {
      "x": -6,
      "y": 15,
      "z": -2,
      "name": "Empty"
    },
    {
      "x": -6,
      "y": 16,
      "z": -2,
      "name": "Wood_Fir_Trunk",
      "rotation": 4
    },
    {
      "x": -6,
      "y": 17,
      "z": -2,
      "name": "Rock_Basalt_Cobble_Roof",
      "rotation": 3
    },
    {
      "x": -6,
      "y": 3,
      "z": -1,
      "name": "Rock_Shale"
    },
    {
      "x": -6,
      "y": 4,
      "z": -1,
      "name": "Rock_Shale"
    },
    {
      "x": -6,
      "y": 5,
      "z": -1,
      "name": "Rock_Shale"
    },
    {
      "x": -6,
      "y": 6,
      "z": -1,
      "name": "Rock_Shale"
    },
    {
      "x": -6,
      "y": 7,
      "z": -1,
      "name": "Rock_Shale"
    },
    {
      "x": -6,
      "y": 8,
      "z": -1,
      "name": "Rock_Shale"
    },
    {
      "x": -6,
      "y": 9,
      "z": -1,
      "name": "Rock_Shale"
    },
    {
      "x": -6,
      "y": 10,
      "z": -1,
      "name": "Rock_Basalt_Brick"
    },
    {
      "x": -6,
      "y": 11,
      "z": -1,
      "name": "Wood_Deadwood_Planks"
    },
    {
      "x": -6,
      "y": 12,
      "z": -1,
      "name": "Empty"
    },
    {
      "x": -6,
      "y": 13,
      "z": -1,
      "name": "Empty"
    },
    {
      "x": -6,
      "y": 14,
      "z": -1,
      "name": "Empty"
    },
    {
      "x": -6,
      "y": 15,
      "z": -1,
      "name": "Empty"
    },
    {
      "x": -6,
      "y": 16,
      "z": -1,
      "name": "Wood_Fir_Trunk",
      "rotation": 4
    },
    {
      "x": -6,
      "y": 17,
      "z": -1,
      "name": "Rock_Basalt_Cobble_Roof",
      "rotation": 3
    },
    {
      "x": -6,
      "y": 3,
      "z": 0,
      "name": "Rock_Shale"
    },
    {
      "x": -6,
      "y": 4,
      "z": 0,
      "name": "Rock_Shale"
    },
    {
      "x": -6,
      "y": 5,
      "z": 0,
      "name": "Rock_Shale"
    },
    {
      "x": -6,
      "y": 6,
      "z": 0,
      "name": "Rock_Shale"
    },
    {
      "x": -6,
      "y": 7,
      "z": 0,
      "name": "Rock_Shale"
    },
    {
      "x": -6,
      "y": 8,
      "z": 0,
      "name": "Rock_Shale"
    },
    {
      "x": -6,
      "y": 9,
      "z": 0,
      "name": "Rock_Shale"
    },
    {
      "x": -6,
      "y": 10,
      "z": 0,
      "name": "Rock_Basalt_Brick"
    },
    {
      "x": -6,
      "y": 11,
      "z": 0,
      "name": "Wood_Deadwood_Planks"
    },
    {
      "x": -6,
      "y": 12,
      "z": 0,
      "name": "Furniture_Tavern_Barrel"
    },
    {
      "x": -6,
      "y": 13,
      "z": 0,
      "name": "Wood_Fir_Branch_Corner",
      "rotation": 2
    },
    {
      "x": -6,
      "y": 14,
      "z": 0,
      "name": "Furniture_Human_Ruins_Torch",
      "rotation": 2
    },
    {
      "x": -6,
      "y": 15,
      "z": 0,
      "name": "Empty"
    },
    {
      "x": -6,
      "y": 16,
      "z": 0,
      "name": "Wood_Fir_Trunk",
      "rotation": 4
    },
    {
      "x": -6,
      "y": 17,
      "z": 0,
      "name": "Rock_Basalt_Cobble_Roof",
      "rotation": 3
    },
    {
      "x": -6,
      "y": 4,
      "z": 1,
      "name": "Rock_Shale"
    },
    {
      "x": -6,
      "y": 5,
      "z": 1,
      "name": "Rock_Shale"
    },
    {
      "x": -6,
      "y": 6,
      "z": 1,
      "name": "Rock_Shale"
    },
    {
      "x": -6,
      "y": 7,
      "z": 1,
      "name": "Rock_Shale"
    },
    {
      "x": -6,
      "y": 8,
      "z": 1,
      "name": "Rock_Shale"
    },
    {
      "x": -6,
      "y": 9,
      "z": 1,
      "name": "Rock_Shale"
    },
    {
      "x": -6,
      "y": 10,
      "z": 1,
      "name": "Rock_Basalt_Brick"
    },
    {
      "x": -6,
      "y": 11,
      "z": 1,
      "name": "Rock_Basalt_Brick"
    },
    {
      "x": -6,
      "y": 12,
      "z": 1,
      "name": "Rock_Basalt_Brick"
    },
    {
      "x": -6,
      "y": 13,
      "z": 1,
      "name": "Rock_Shale_Brick"
    },
    {
      "x": -6,
      "y": 14,
      "z": 1,
      "name": "Rock_Shale_Brick"
    },
    {
      "x": -6,
      "y": 15,
      "z": 1,
      "name": "Rock_Shale_Brick"
    },
    {
      "x": -6,
      "y": 16,
      "z": 1,
      "name": "Rock_Basalt_Cobble"
    },
    {
      "x": -6,
      "y": 17,
      "z": 1,
      "name": "Rock_Basalt_Cobble_Roof",
      "rotation": 3
    },
    {
      "x": -6,
      "y": 5,
      "z": 2,
      "name": "Rock_Shale"
    },
    {
      "x": -6,
      "y": 6,
      "z": 2,
      "name": "Rock_Shale"
    },
    {
      "x": -6,
      "y": 7,
      "z": 2,
      "name": "Rock_Shale"
    },
    {
      "x": -6,
      "y": 8,
      "z": 2,
      "name": "Rock_Shale"
    },
    {
      "x": -6,
      "y": 9,
      "z": 2,
      "name": "Rock_Shale"
    },
    {
      "x": -6,
      "y": 10,
      "z": 2,
      "name": "Rock_Shale_Cobble"
    },
    {
      "x": -6,
      "y": 11,
      "z": 2,
      "name": "Rock_Shale_Cobble"
    },
    {
      "x": -6,
      "y": 12,
      "z": 2,
      "name": "Rock_Shale_Cobble"
    },
    {
      "x": -6,
      "y": 13,
      "z": 2,
      "name": "Rock_Shale_Brick"
    },
    {
      "x": -6,
      "y": 14,
      "z": 2,
      "name": "Rock_Shale_Brick"
    },
    {
      "x": -6,
      "y": 15,
      "z": 2,
      "name": "Rock_Shale_Brick"
    },
    {
      "x": -6,
      "y": 16,
      "z": 2,
      "name": "Rock_Basalt_Cobble"
    },
    {
      "x": -6,
      "y": 17,
      "z": 2,
      "name": "Rock_Basalt_Cobble_Roof",
      "rotation": 3
    },
    {
      "x": -6,
      "y": 5,
      "z": 3,
      "name": "Rock_Shale"
    },
    {
      "x": -6,
      "y": 6,
      "z": 3,
      "name": "Rock_Shale"
    },
    {
      "x": -6,
      "y": 7,
      "z": 3,
      "name": "Rock_Shale"
    },
    {
      "x": -6,
      "y": 8,
      "z": 3,
      "name": "Rock_Shale"
    },
    {
      "x": -6,
      "y": 9,
      "z": 3,
      "name": "Rock_Shale_Cobble"
    },
    {
      "x": -6,
      "y": 10,
      "z": 3,
      "name": "Rock_Shale_Cobble"
    },
    {
      "x": -6,
      "y": 11,
      "z": 3,
      "name": "Rock_Shale_Cobble"
    },
    {
      "x": -6,
      "y": 12,
      "z": 3,
      "name": "Rock_Shale_Brick"
    },
    {
      "x": -6,
      "y": 13,
      "z": 3,
      "name": "Rock_Shale_Brick"
    },
    {
      "x": -6,
      "y": 14,
      "z": 3,
      "name": "Rock_Shale_Brick"
    },
    {
      "x": -6,
      "y": 15,
      "z": 3,
      "name": "Rock_Shale_Brick"
    },
    {
      "x": -6,
      "y": 16,
      "z": 3,
      "name": "Rock_Basalt_Cobble"
    },
    {
      "x": -6,
      "y": 17,
      "z": 3,
      "name": "Rock_Basalt_Cobble_Roof",
      "rotation": 3
    },
    {
      "x": -6,
      "y": 4,
      "z": 4,
      "name": "Rock_Shale"
    },
    {
      "x": -6,
      "y": 5,
      "z": 4,
      "name": "Rock_Shale"
    },
    {
      "x": -6,
      "y": 6,
      "z": 4,
      "name": "Rock_Shale"
    },
    {
      "x": -6,
      "y": 7,
      "z": 4,
      "name": "Rock_Shale"
    },
    {
      "x": -6,
      "y": 8,
      "z": 4,
      "name": "Rock_Shale"
    },
    {
      "x": -6,
      "y": 9,
      "z": 4,
      "name": "Rock_Shale_Cobble"
    },
    {
      "x": -6,
      "y": 10,
      "z": 4,
      "name": "Rock_Shale_Cobble"
    },
    {
      "x": -6,
      "y": 11,
      "z": 4,
      "name": "Rock_Shale_Cobble"
    },
    {
      "x": -6,
      "y": 12,
      "z": 4,
      "name": "Rock_Shale_Brick"
    },
    {
      "x": -6,
      "y": 13,
      "z": 4,
      "name": "Rock_Shale_Brick"
    },
    {
      "x": -6,
      "y": 14,
      "z": 4,
      "name": "Rock_Shale_Brick"
    },
    {
      "x": -6,
      "y": 15,
      "z": 4,
      "name": "Rock_Shale_Brick"
    },
    {
      "x": -6,
      "y": 16,
      "z": 4,
      "name": "Rock_Shale_Cobble"
    },
    {
      "x": -6,
      "y": 4,
      "z": 5,
      "name": "Rock_Shale"
    },
    {
      "x": -6,
      "y": 5,
      "z": 5,
      "name": "Rock_Shale"
    },
    {
      "x": -6,
      "y": 6,
      "z": 5,
      "name": "Rock_Shale"
    },
    {
      "x": -6,
      "y": 7,
      "z": 5,
      "name": "Rock_Shale"
    },
    {
      "x": -6,
      "y": 8,
      "z": 5,
      "name": "Rock_Shale"
    },
    {
      "x": -6,
      "y": 9,
      "z": 5,
      "name": "Soil_Dirt_Cold"
    },
    {
      "x": -6,
      "y": 10,
      "z": 5,
      "name": "Soil_Dirt_Cold"
    },
    {
      "x": -6,
      "y": 11,
      "z": 5,
      "name": "Empty"
    },
    {
      "x": -6,
      "y": 12,
      "z": 5,
      "name": "Empty"
    },
    {
      "x": -6,
      "y": 13,
      "z": 5,
      "name": "Empty"
    },
    {
      "x": -6,
      "y": 14,
      "z": 5,
      "name": "Rock_Shale_Brick_Half",
      "rotation": 4
    },
    {
      "x": -6,
      "y": 15,
      "z": 5,
      "name": "Rock_Shale_Brick"
    },
    {
      "x": -6,
      "y": 16,
      "z": 5,
      "name": "Rock_Shale_Cobble"
    },
    {
      "x": -6,
      "y": 4,
      "z": 6,
      "name": "Rock_Shale"
    },
    {
      "x": -6,
      "y": 5,
      "z": 6,
      "name": "Rock_Shale"
    },
    {
      "x": -6,
      "y": 6,
      "z": 6,
      "name": "Rock_Shale"
    },
    {
      "x": -6,
      "y": 7,
      "z": 6,
      "name": "Rock_Shale"
    },
    {
      "x": -6,
      "y": 8,
      "z": 6,
      "name": "Rock_Shale"
    },
    {
      "x": -6,
      "y": 9,
      "z": 6,
      "name": "Soil_Dirt_Cold"
    },
    {
      "x": -6,
      "y": 10,
      "z": 6,
      "name": "Soil_Dirt_Cold"
    },
    {
      "x": -6,
      "y": 11,
      "z": 6,
      "name": "Empty"
    },
    {
      "x": -6,
      "y": 12,
      "z": 6,
      "name": "Empty"
    },
    {
      "x": -6,
      "y": 13,
      "z": 6,
      "name": "Empty"
    },
    {
      "x": -6,
      "y": 14,
      "z": 6,
      "name": "Empty"
    },
    {
      "x": -6,
      "y": 15,
      "z": 6,
      "name": "Rock_Shale_Brick_Half",
      "rotation": 8
    },
    {
      "x": -6,
      "y": 16,
      "z": 6,
      "name": "Rock_Shale_Cobble"
    },
    {
      "x": -6,
      "y": 3,
      "z": 7,
      "name": "Rock_Shale"
    },
    {
      "x": -6,
      "y": 4,
      "z": 7,
      "name": "Rock_Shale"
    },
    {
      "x": -6,
      "y": 5,
      "z": 7,
      "name": "Rock_Shale"
    },
    {
      "x": -6,
      "y": 6,
      "z": 7,
      "name": "Rock_Shale"
    },
    {
      "x": -6,
      "y": 7,
      "z": 7,
      "name": "Rock_Shale"
    },
    {
      "x": -6,
      "y": 8,
      "z": 7,
      "name": "Rock_Shale_Cobble"
    },
    {
      "x": -6,
      "y": 9,
      "z": 7,
      "name": "Soil_Dirt_Cold"
    },
    {
      "x": -6,
      "y": 10,
      "z": 7,
      "name": "Soil_Dirt_Cold"
    },
    {
      "x": -6,
      "y": 11,
      "z": 7,
      "name": "Empty"
    },
    {
      "x": -6,
      "y": 12,
      "z": 7,
      "name": "Empty"
    },
    {
      "x": -6,
      "y": 13,
      "z": 7,
      "name": "Empty"
    },
    {
      "x": -6,
      "y": 14,
      "z": 7,
      "name": "Rock_Shale_Brick_Half",
      "rotation": 6
    },
    {
      "x": -6,
      "y": 15,
      "z": 7,
      "name": "Rock_Shale_Brick"
    },
    {
      "x": -6,
      "y": 16,
      "z": 7,
      "name": "Rock_Shale_Cobble"
    },
    {
      "x": -6,
      "y": 17,
      "z": 7,
      "name": "Rock_Shale_Cobble_Stairs",
      "rotation": 2
    },
    {
      "x": -6,
      "y": 2,
      "z": 8,
      "name": "Rock_Shale"
    },
    {
      "x": -6,
      "y": 3,
      "z": 8,
      "name": "Rock_Shale"
    },
    {
      "x": -6,
      "y": 4,
      "z": 8,
      "name": "Rock_Shale"
    },
    {
      "x": -6,
      "y": 5,
      "z": 8,
      "name": "Rock_Shale"
    },
    {
      "x": -6,
      "y": 6,
      "z": 8,
      "name": "Rock_Shale"
    },
    {
      "x": -6,
      "y": 7,
      "z": 8,
      "name": "Rock_Shale"
    },
    {
      "x": -6,
      "y": 8,
      "z": 8,
      "name": "Rock_Shale_Cobble"
    },
    {
      "x": -6,
      "y": 9,
      "z": 8,
      "name": "Rock_Shale_Cobble"
    },
    {
      "x": -6,
      "y": 10,
      "z": 8,
      "name": "Rock_Shale_Cobble"
    },
    {
      "x": -6,
      "y": 11,
      "z": 8,
      "name": "Rock_Shale_Cobble"
    },
    {
      "x": -6,
      "y": 12,
      "z": 8,
      "name": "Rock_Shale_Cobble"
    },
    {
      "x": -6,
      "y": 13,
      "z": 8,
      "name": "Rock_Shale_Brick"
    },
    {
      "x": -6,
      "y": 14,
      "z": 8,
      "name": "Rock_Shale_Brick"
    },
    {
      "x": -6,
      "y": 15,
      "z": 8,
      "name": "Rock_Shale_Brick"
    },
    {
      "x": -6,
      "y": 16,
      "z": 8,
      "name": "Rock_Shale_Cobble"
    },
    {
      "x": -6,
      "y": 17,
      "z": 8,
      "name": "Rock_Shale_Cobble"
    },
    {
      "x": -6,
      "y": 18,
      "z": 8,
      "name": "Rock_Shale_Cobble_Stairs",
      "rotation": 2
    },
    {
      "x": -6,
      "y": 1,
      "z": 9,
      "name": "Rock_Shale"
    },
    {
      "x": -6,
      "y": 2,
      "z": 9,
      "name": "Rock_Shale"
    },
    {
      "x": -6,
      "y": 3,
      "z": 9,
      "name": "Rock_Shale"
    },
    {
      "x": -6,
      "y": 4,
      "z": 9,
      "name": "Rock_Shale"
    },
    {
      "x": -6,
      "y": 5,
      "z": 9,
      "name": "Rock_Shale"
    },
    {
      "x": -6,
      "y": 6,
      "z": 9,
      "name": "Rock_Shale"
    },
    {
      "x": -6,
      "y": 7,
      "z": 9,
      "name": "Rock_Basalt_Brick"
    },
    {
      "x": -6,
      "y": 8,
      "z": 9,
      "name": "Rock_Basalt_Brick"
    },
    {
      "x": -6,
      "y": 9,
      "z": 9,
      "name": "Rock_Basalt_Brick"
    },
    {
      "x": -6,
      "y": 10,
      "z": 9,
      "name": "Rock_Shale_Cobble"
    },
    {
      "x": -6,
      "y": 11,
      "z": 9,
      "name": "Rock_Shale_Cobble"
    },
    {
      "x": -6,
      "y": 12,
      "z": 9,
      "name": "Rock_Shale_Brick"
    },
    {
      "x": -6,
      "y": 13,
      "z": 9,
      "name": "Rock_Shale_Brick"
    },
    {
      "x": -6,
      "y": 14,
      "z": 9,
      "name": "Rock_Shale_Brick"
    },
    {
      "x": -6,
      "y": 15,
      "z": 9,
      "name": "Rock_Shale_Cobble"
    },
    {
      "x": -6,
      "y": 16,
      "z": 9,
      "name": "Rock_Shale_Cobble"
    },
    {
      "x": -6,
      "y": 17,
      "z": 9,
      "name": "Rock_Shale_Cobble"
    },
    {
      "x": -6,
      "y": 18,
      "z": 9,
      "name": "Rock_Shale_Cobble"
    },
    {
      "x": -6,
      "y": 2,
      "z": 10,
      "name": "Rock_Shale"
    },
    {
      "x": -6,
      "y": 3,
      "z": 10,
      "name": "Rock_Shale"
    },
    {
      "x": -6,
      "y": 4,
      "z": 10,
      "name": "Rock_Shale"
    },
    {
      "x": -6,
      "y": 5,
      "z": 10,
      "name": "Rock_Shale"
    },
    {
      "x": -6,
      "y": 6,
      "z": 10,
      "name": "Rock_Shale"
    },
    {
      "x": -6,
      "y": 7,
      "z": 10,
      "name": "Rock_Basalt_Brick"
    },
    {
      "x": -6,
      "y": 8,
      "z": 10,
      "name": "Rock_Basalt_Brick"
    },
    {
      "x": -6,
      "y": 9,
      "z": 10,
      "name": "Rock_Basalt_Brick"
    },
    {
      "x": -6,
      "y": 10,
      "z": 10,
      "name": "Rock_Basalt_Brick"
    },
    {
      "x": -6,
      "y": 11,
      "z": 10,
      "name": "Rock_Basalt_Brick"
    },
    {
      "x": -6,
      "y": 12,
      "z": 10,
      "name": "Rock_Shale_Brick"
    },
    {
      "x": -6,
      "y": 13,
      "z": 10,
      "name": "Rock_Shale_Brick"
    },
    {
      "x": -6,
      "y": 14,
      "z": 10,
      "name": "Rock_Shale_Brick"
    },
    {
      "x": -6,
      "y": 15,
      "z": 10,
      "name": "Rock_Shale_Cobble"
    },
    {
      "x": -6,
      "y": 16,
      "z": 10,
      "name": "Rock_Shale_Cobble"
    },
    {
      "x": -6,
      "y": 17,
      "z": 10,
      "name": "Rock_Shale_Cobble"
    },
    {
      "x": -6,
      "y": 18,
      "z": 10,
      "name": "Rock_Shale_Cobble"
    },
    {
      "x": -6,
      "y": 19,
      "z": 10,
      "name": "Wood_Fir_Trunk",
      "rotation": 5
    },
    {
      "x": -6,
      "y": 20,
      "z": 10,
      "name": "Deco_Fire"
    },
    {
      "x": -6,
      "y": 5,
      "z": 11,
      "name": "Rock_Shale"
    },
    {
      "x": -6,
      "y": 6,
      "z": 11,
      "name": "Rock_Shale"
    },
    {
      "x": -6,
      "y": 7,
      "z": 11,
      "name": "Rock_Basalt_Brick"
    },
    {
      "x": -6,
      "y": 8,
      "z": 11,
      "name": "Rock_Basalt_Brick"
    },
    {
      "x": -6,
      "y": 9,
      "z": 11,
      "name": "Rock_Basalt_Brick"
    },
    {
      "x": -6,
      "y": 10,
      "z": 11,
      "name": "Rock_Basalt_Brick"
    },
    {
      "x": -6,
      "y": 11,
      "z": 11,
      "name": "Rock_Basalt_Brick"
    },
    {
      "x": -6,
      "y": 12,
      "z": 11,
      "name": "Rock_Basalt_Brick"
    },
    {
      "x": -6,
      "y": 13,
      "z": 11,
      "name": "Rock_Shale_Brick"
    },
    {
      "x": -6,
      "y": 14,
      "z": 11,
      "name": "Rock_Shale_Brick"
    },
    {
      "x": -6,
      "y": 15,
      "z": 11,
      "name": "Rock_Shale_Brick"
    },
    {
      "x": -6,
      "y": 16,
      "z": 11,
      "name": "Rock_Shale_Cobble"
    },
    {
      "x": -6,
      "y": 17,
      "z": 11,
      "name": "Rock_Shale_Cobble"
    },
    {
      "x": -6,
      "y": 18,
      "z": 11,
      "name": "Rock_Shale_Cobble"
    },
    {
      "x": -6,
      "y": 19,
      "z": 11,
      "name": "Wood_Fir_Trunk",
      "rotation": 4
    },
    {
      "x": -6,
      "y": 20,
      "z": 11,
      "name": "Deco_Fire"
    },
    {
      "x": -6,
      "y": 10,
      "z": 12,
      "name": "Rock_Basalt_Brick"
    },
    {
      "x": -6,
      "y": 11,
      "z": 12,
      "name": "Rock_Basalt_Brick"
    },
    {
      "x": -6,
      "y": 12,
      "z": 12,
      "name": "Rock_Basalt_Brick"
    },
    {
      "x": -6,
      "y": 13,
      "z": 12,
      "name": "Rock_Basalt_Brick"
    },
    {
      "x": -6,
      "y": 14,
      "z": 12,
      "name": "Rock_Shale_Brick"
    },
    {
      "x": -6,
      "y": 15,
      "z": 12,
      "name": "Rock_Shale_Brick"
    },
    {
      "x": -6,
      "y": 16,
      "z": 12,
      "name": "Rock_Shale_Cobble"
    },
    {
      "x": -6,
      "y": 17,
      "z": 12,
      "name": "Rock_Shale_Cobble"
    },
    {
      "x": -6,
      "y": 18,
      "z": 12,
      "name": "Rock_Shale_Brick"
    },
    {
      "x": -6,
      "y": 19,
      "z": 12,
      "name": "Rock_Shale_Cobble_Wall"
    },
    {
      "x": -5,
      "y": 15,
      "z": -12,
      "name": "Rock_Shale_Brick_Half",
      "rotation": 6
    },
    {
      "x": -5,
      "y": 16,
      "z": -12,
      "name": "Rock_Shale_Brick"
    },
    {
      "x": -5,
      "y": 17,
      "z": -12,
      "name": "Rock_Basalt_Cobble"
    },
    {
      "x": -5,
      "y": 18,
      "z": -12,
      "name": "Rock_Basalt_Cobble_Roof",
      "rotation": 3
    },
    {
      "x": -5,
      "y": 5,
      "z": -11,
      "name": "Rock_Shale"
    },
    {
      "x": -5,
      "y": 6,
      "z": -11,
      "name": "Rock_Shale"
    },
    {
      "x": -5,
      "y": 7,
      "z": -11,
      "name": "Rock_Shale"
    },
    {
      "x": -5,
      "y": 8,
      "z": -11,
      "name": "Rock_Shale"
    },
    {
      "x": -5,
      "y": 9,
      "z": -11,
      "name": "Rock_Basalt_Brick"
    },
    {
      "x": -5,
      "y": 10,
      "z": -11,
      "name": "Rock_Basalt_Brick"
    },
    {
      "x": -5,
      "y": 11,
      "z": -11,
      "name": "Rock_Basalt_Brick"
    },
    {
      "x": -5,
      "y": 12,
      "z": -11,
      "name": "Rock_Shale_Brick"
    },
    {
      "x": -5,
      "y": 13,
      "z": -11,
      "name": "Rock_Shale_Brick"
    },
    {
      "x": -5,
      "y": 14,
      "z": -11,
      "name": "Rock_Shale_Brick"
    },
    {
      "x": -5,
      "y": 15,
      "z": -11,
      "name": "Rock_Shale_Brick"
    },
    {
      "x": -5,
      "y": 16,
      "z": -11,
      "name": "Rock_Shale_Brick"
    },
    {
      "x": -5,
      "y": 17,
      "z": -11,
      "name": "Rock_Basalt_Cobble"
    },
    {
      "x": -5,
      "y": 18,
      "z": -11,
      "name": "Rock_Basalt_Cobble_Roof",
      "rotation": 3
    },
    {
      "x": -5,
      "y": 3,
      "z": -10,
      "name": "Rock_Shale"
    },
    {
      "x": -5,
      "y": 4,
      "z": -10,
      "name": "Rock_Shale"
    },
    {
      "x": -5,
      "y": 5,
      "z": -10,
      "name": "Rock_Shale"
    },
    {
      "x": -5,
      "y": 6,
      "z": -10,
      "name": "Rock_Shale"
    },
    {
      "x": -5,
      "y": 7,
      "z": -10,
      "name": "Rock_Shale"
    },
    {
      "x": -5,
      "y": 8,
      "z": -10,
      "name": "Rock_Shale"
    },
    {
      "x": -5,
      "y": 9,
      "z": -10,
      "name": "Soil_Dirt_Cold"
    },
    {
      "x": -5,
      "y": 10,
      "z": -10,
      "name": "Soil_Dirt_Cold"
    },
    {
      "x": -5,
      "y": 11,
      "z": -10,
      "name": "Wood_Fir_Trunk",
      "rotation": 4
    },
    {
      "x": -5,
      "y": 12,
      "z": -10,
      "name": "Empty"
    },
    {
      "x": -5,
      "y": 13,
      "z": -10,
      "name": "Empty"
    },
    {
      "x": -5,
      "y": 14,
      "z": -10,
      "name": "Empty"
    },
    {
      "x": -5,
      "y": 15,
      "z": -10,
      "name": "Empty"
    },
    {
      "x": -5,
      "y": 16,
      "z": -10,
      "name": "Wood_Fir_Trunk",
      "rotation": 5
    },
    {
      "x": -5,
      "y": 17,
      "z": -10,
      "name": "Wood_Fir_Trunk",
      "rotation": 4
    },
    {
      "x": -5,
      "y": 18,
      "z": -10,
      "name": "Rock_Basalt_Cobble_Roof",
      "rotation": 3
    },
    {
      "x": -5,
      "y": 2,
      "z": -9,
      "name": "Rock_Shale"
    },
    {
      "x": -5,
      "y": 3,
      "z": -9,
      "name": "Rock_Shale"
    },
    {
      "x": -5,
      "y": 4,
      "z": -9,
      "name": "Rock_Shale"
    },
    {
      "x": -5,
      "y": 5,
      "z": -9,
      "name": "Rock_Shale"
    },
    {
      "x": -5,
      "y": 6,
      "z": -9,
      "name": "Rock_Shale"
    },
    {
      "x": -5,
      "y": 7,
      "z": -9,
      "name": "Rock_Shale"
    },
    {
      "x": -5,
      "y": 8,
      "z": -9,
      "name": "Rock_Shale"
    },
    {
      "x": -5,
      "y": 9,
      "z": -9,
      "name": "Soil_Dirt_Cold"
    },
    {
      "x": -5,
      "y": 10,
      "z": -9,
      "name": "Soil_Dirt_Cold"
    },
    {
      "x": -5,
      "y": 11,
      "z": -9,
      "name": "Wood_Fir_Trunk",
      "rotation": 4
    },
    {
      "x": -5,
      "y": 12,
      "z": -9,
      "name": "Furniture_Lumberjack_Chair",
      "rotation": 1
    },
    {
      "x": -5,
      "y": 13,
      "z": -9,
      "name": "Empty"
    },
    {
      "x": -5,
      "y": 14,
      "z": -9,
      "name": "Empty"
    },
    {
      "x": -5,
      "y": 15,
      "z": -9,
      "name": "Empty"
    },
    {
      "x": -5,
      "y": 16,
      "z": -9,
      "name": "Rock_Shale_Brick_Half",
      "rotation": 5
    },
    {
      "x": -5,
      "y": 17,
      "z": -9,
      "name": "Wood_Fir_Trunk",
      "rotation": 4
    },
    {
      "x": -5,
      "y": 18,
      "z": -9,
      "name": "Rock_Basalt_Cobble_Roof",
      "rotation": 3
    },
    {
      "x": -5,
      "y": 1,
      "z": -8,
      "name": "Rock_Shale"
    },
    {
      "x": -5,
      "y": 2,
      "z": -8,
      "name": "Rock_Shale"
    },
    {
      "x": -5,
      "y": 3,
      "z": -8,
      "name": "Rock_Shale"
    },
    {
      "x": -5,
      "y": 4,
      "z": -8,
      "name": "Rock_Shale"
    },
    {
      "x": -5,
      "y": 5,
      "z": -8,
      "name": "Rock_Shale"
    },
    {
      "x": -5,
      "y": 6,
      "z": -8,
      "name": "Rock_Shale"
    },
    {
      "x": -5,
      "y": 7,
      "z": -8,
      "name": "Rock_Shale"
    },
    {
      "x": -5,
      "y": 8,
      "z": -8,
      "name": "Rock_Shale"
    },
    {
      "x": -5,
      "y": 9,
      "z": -8,
      "name": "Soil_Dirt_Cold"
    },
    {
      "x": -5,
      "y": 10,
      "z": -8,
      "name": "Soil_Dirt_Cold"
    },
    {
      "x": -5,
      "y": 11,
      "z": -8,
      "name": "Wood_Fir_Trunk",
      "rotation": 4
    },
    {
      "x": -5,
      "y": 12,
      "z": -8,
      "name": "Empty"
    },
    {
      "x": -5,
      "y": 13,
      "z": -8,
      "name": "Empty"
    },
    {
      "x": -5,
      "y": 14,
      "z": -8,
      "name": "Empty"
    },
    {
      "x": -5,
      "y": 15,
      "z": -8,
      "name": "Empty"
    },
    {
      "x": -5,
      "y": 16,
      "z": -8,
      "name": "Wood_Fir_Trunk",
      "rotation": 5
    },
    {
      "x": -5,
      "y": 17,
      "z": -8,
      "name": "Wood_Fir_Trunk",
      "rotation": 4
    },
    {
      "x": -5,
      "y": 18,
      "z": -8,
      "name": "Rock_Basalt_Cobble_Roof",
      "rotation": 3
    },
    {
      "x": -5,
      "y": 1,
      "z": -7,
      "name": "Rock_Shale"
    },
    {
      "x": -5,
      "y": 2,
      "z": -7,
      "name": "Rock_Shale"
    },
    {
      "x": -5,
      "y": 3,
      "z": -7,
      "name": "Rock_Shale"
    },
    {
      "x": -5,
      "y": 4,
      "z": -7,
      "name": "Rock_Shale"
    },
    {
      "x": -5,
      "y": 5,
      "z": -7,
      "name": "Rock_Shale"
    },
    {
      "x": -5,
      "y": 6,
      "z": -7,
      "name": "Rock_Shale"
    },
    {
      "x": -5,
      "y": 7,
      "z": -7,
      "name": "Rock_Shale"
    },
    {
      "x": -5,
      "y": 8,
      "z": -7,
      "name": "Rock_Shale"
    },
    {
      "x": -5,
      "y": 9,
      "z": -7,
      "name": "Soil_Dirt_Cold"
    },
    {
      "x": -5,
      "y": 10,
      "z": -7,
      "name": "Soil_Dirt_Cold"
    },
    {
      "x": -5,
      "y": 11,
      "z": -7,
      "name": "Wood_Fir_Trunk",
      "rotation": 4
    },
    {
      "x": -5,
      "y": 12,
      "z": -7,
      "name": "Furniture_Lumberjack_Chair",
      "rotation": 1
    },
    {
      "x": -5,
      "y": 13,
      "z": -7,
      "name": "Empty"
    },
    {
      "x": -5,
      "y": 14,
      "z": -7,
      "name": "Empty"
    },
    {
      "x": -5,
      "y": 15,
      "z": -7,
      "name": "Empty"
    },
    {
      "x": -5,
      "y": 16,
      "z": -7,
      "name": "Rock_Shale_Brick_Half",
      "rotation": 5
    },
    {
      "x": -5,
      "y": 17,
      "z": -7,
      "name": "Wood_Fir_Trunk",
      "rotation": 4
    },
    {
      "x": -5,
      "y": 18,
      "z": -7,
      "name": "Rock_Basalt_Cobble_Roof",
      "rotation": 3
    },
    {
      "x": -5,
      "y": 1,
      "z": -6,
      "name": "Rock_Shale"
    },
    {
      "x": -5,
      "y": 2,
      "z": -6,
      "name": "Rock_Shale"
    },
    {
      "x": -5,
      "y": 3,
      "z": -6,
      "name": "Rock_Shale"
    },
    {
      "x": -5,
      "y": 4,
      "z": -6,
      "name": "Rock_Shale"
    },
    {
      "x": -5,
      "y": 5,
      "z": -6,
      "name": "Rock_Shale"
    },
    {
      "x": -5,
      "y": 6,
      "z": -6,
      "name": "Rock_Shale"
    },
    {
      "x": -5,
      "y": 7,
      "z": -6,
      "name": "Rock_Shale"
    },
    {
      "x": -5,
      "y": 8,
      "z": -6,
      "name": "Rock_Shale"
    },
    {
      "x": -5,
      "y": 9,
      "z": -6,
      "name": "Soil_Dirt_Cold"
    },
    {
      "x": -5,
      "y": 10,
      "z": -6,
      "name": "Soil_Dirt_Cold"
    },
    {
      "x": -5,
      "y": 11,
      "z": -6,
      "name": "Wood_Fir_Trunk",
      "rotation": 4
    },
    {
      "x": -5,
      "y": 12,
      "z": -6,
      "name": "Empty"
    },
    {
      "x": -5,
      "y": 13,
      "z": -6,
      "name": "Empty"
    },
    {
      "x": -5,
      "y": 14,
      "z": -6,
      "name": "Empty"
    },
    {
      "x": -5,
      "y": 15,
      "z": -6,
      "name": "Empty"
    },
    {
      "x": -5,
      "y": 16,
      "z": -6,
      "name": "Rock_Shale_Brick_Half",
      "rotation": 5
    },
    {
      "x": -5,
      "y": 17,
      "z": -6,
      "name": "Wood_Fir_Trunk",
      "rotation": 4
    },
    {
      "x": -5,
      "y": 18,
      "z": -6,
      "name": "Rock_Basalt_Cobble_Roof",
      "rotation": 3
    },
    {
      "x": -5,
      "y": 1,
      "z": -5,
      "name": "Rock_Shale"
    },
    {
      "x": -5,
      "y": 2,
      "z": -5,
      "name": "Rock_Shale"
    },
    {
      "x": -5,
      "y": 3,
      "z": -5,
      "name": "Rock_Shale"
    },
    {
      "x": -5,
      "y": 4,
      "z": -5,
      "name": "Rock_Shale"
    },
    {
      "x": -5,
      "y": 5,
      "z": -5,
      "name": "Rock_Shale"
    },
    {
      "x": -5,
      "y": 6,
      "z": -5,
      "name": "Rock_Shale"
    },
    {
      "x": -5,
      "y": 7,
      "z": -5,
      "name": "Rock_Shale"
    },
    {
      "x": -5,
      "y": 8,
      "z": -5,
      "name": "Rock_Shale"
    },
    {
      "x": -5,
      "y": 9,
      "z": -5,
      "name": "Soil_Dirt_Cold"
    },
    {
      "x": -5,
      "y": 10,
      "z": -5,
      "name": "Soil_Dirt_Cold"
    },
    {
      "x": -5,
      "y": 11,
      "z": -5,
      "name": "Wood_Fir_Trunk",
      "rotation": 4
    },
    {
      "x": -5,
      "y": 12,
      "z": -5,
      "name": "Empty"
    },
    {
      "x": -5,
      "y": 13,
      "z": -5,
      "name": "Empty"
    },
    {
      "x": -5,
      "y": 14,
      "z": -5,
      "name": "Empty"
    },
    {
      "x": -5,
      "y": 15,
      "z": -5,
      "name": "Empty"
    },
    {
      "x": -5,
      "y": 16,
      "z": -5,
      "name": "Rock_Shale_Brick_Half",
      "rotation": 5
    },
    {
      "x": -5,
      "y": 17,
      "z": -5,
      "name": "Wood_Fir_Trunk",
      "rotation": 4
    },
    {
      "x": -5,
      "y": 18,
      "z": -5,
      "name": "Rock_Basalt_Cobble_Roof",
      "rotation": 3
    },
    {
      "x": -5,
      "y": 1,
      "z": -4,
      "name": "Rock_Shale"
    },
    {
      "x": -5,
      "y": 2,
      "z": -4,
      "name": "Rock_Shale"
    },
    {
      "x": -5,
      "y": 3,
      "z": -4,
      "name": "Rock_Shale"
    },
    {
      "x": -5,
      "y": 4,
      "z": -4,
      "name": "Rock_Shale"
    },
    {
      "x": -5,
      "y": 5,
      "z": -4,
      "name": "Rock_Shale"
    },
    {
      "x": -5,
      "y": 6,
      "z": -4,
      "name": "Rock_Shale"
    },
    {
      "x": -5,
      "y": 7,
      "z": -4,
      "name": "Rock_Shale"
    },
    {
      "x": -5,
      "y": 8,
      "z": -4,
      "name": "Rock_Shale"
    },
    {
      "x": -5,
      "y": 9,
      "z": -4,
      "name": "Soil_Dirt_Cold"
    },
    {
      "x": -5,
      "y": 10,
      "z": -4,
      "name": "Soil_Dirt_Cold"
    },
    {
      "x": -5,
      "y": 11,
      "z": -4,
      "name": "Wood_Fir_Trunk",
      "rotation": 4
    },
    {
      "x": -5,
      "y": 12,
      "z": -4,
      "name": "Empty"
    },
    {
      "x": -5,
      "y": 13,
      "z": -4,
      "name": "Empty"
    },
    {
      "x": -5,
      "y": 14,
      "z": -4,
      "name": "Empty"
    },
    {
      "x": -5,
      "y": 15,
      "z": -4,
      "name": "Empty"
    },
    {
      "x": -5,
      "y": 16,
      "z": -4,
      "name": "Rock_Shale_Brick_Half",
      "rotation": 5
    },
    {
      "x": -5,
      "y": 17,
      "z": -4,
      "name": "Wood_Fir_Trunk",
      "rotation": 4
    },
    {
      "x": -5,
      "y": 18,
      "z": -4,
      "name": "Rock_Basalt_Cobble_Roof",
      "rotation": 3
    },
    {
      "x": -5,
      "y": 1,
      "z": -3,
      "name": "Rock_Shale"
    },
    {
      "x": -5,
      "y": 2,
      "z": -3,
      "name": "Rock_Shale"
    },
    {
      "x": -5,
      "y": 3,
      "z": -3,
      "name": "Rock_Shale"
    },
    {
      "x": -5,
      "y": 4,
      "z": -3,
      "name": "Rock_Shale"
    },
    {
      "x": -5,
      "y": 5,
      "z": -3,
      "name": "Rock_Shale"
    },
    {
      "x": -5,
      "y": 6,
      "z": -3,
      "name": "Rock_Shale"
    },
    {
      "x": -5,
      "y": 7,
      "z": -3,
      "name": "Rock_Shale"
    },
    {
      "x": -5,
      "y": 8,
      "z": -3,
      "name": "Rock_Shale"
    },
    {
      "x": -5,
      "y": 9,
      "z": -3,
      "name": "Soil_Dirt_Cold"
    },
    {
      "x": -5,
      "y": 10,
      "z": -3,
      "name": "Soil_Dirt_Cold"
    },
    {
      "x": -5,
      "y": 11,
      "z": -3,
      "name": "Wood_Fir_Trunk",
      "rotation": 4
    },
    {
      "x": -5,
      "y": 12,
      "z": -3,
      "name": "Empty"
    },
    {
      "x": -5,
      "y": 13,
      "z": -3,
      "name": "Empty"
    },
    {
      "x": -5,
      "y": 14,
      "z": -3,
      "name": "Empty"
    },
    {
      "x": -5,
      "y": 15,
      "z": -3,
      "name": "Empty"
    },
    {
      "x": -5,
      "y": 16,
      "z": -3,
      "name": "Rock_Shale_Brick_Half",
      "rotation": 5
    },
    {
      "x": -5,
      "y": 17,
      "z": -3,
      "name": "Wood_Fir_Trunk",
      "rotation": 4
    },
    {
      "x": -5,
      "y": 18,
      "z": -3,
      "name": "Rock_Basalt_Cobble_Roof",
      "rotation": 3
    },
    {
      "x": -5,
      "y": 1,
      "z": -2,
      "name": "Rock_Shale"
    },
    {
      "x": -5,
      "y": 2,
      "z": -2,
      "name": "Rock_Shale"
    },
    {
      "x": -5,
      "y": 3,
      "z": -2,
      "name": "Rock_Shale"
    },
    {
      "x": -5,
      "y": 4,
      "z": -2,
      "name": "Rock_Shale"
    },
    {
      "x": -5,
      "y": 5,
      "z": -2,
      "name": "Rock_Shale"
    },
    {
      "x": -5,
      "y": 6,
      "z": -2,
      "name": "Rock_Shale"
    },
    {
      "x": -5,
      "y": 7,
      "z": -2,
      "name": "Rock_Shale"
    },
    {
      "x": -5,
      "y": 8,
      "z": -2,
      "name": "Rock_Shale"
    },
    {
      "x": -5,
      "y": 9,
      "z": -2,
      "name": "Soil_Dirt_Cold"
    },
    {
      "x": -5,
      "y": 10,
      "z": -2,
      "name": "Soil_Dirt_Cold"
    },
    {
      "x": -5,
      "y": 11,
      "z": -2,
      "name": "Wood_Fir_Trunk",
      "rotation": 4
    },
    {
      "x": -5,
      "y": 12,
      "z": -2,
      "name": "Empty"
    },
    {
      "x": -5,
      "y": 13,
      "z": -2,
      "name": "Empty"
    },
    {
      "x": -5,
      "y": 14,
      "z": -2,
      "name": "Empty"
    },
    {
      "x": -5,
      "y": 15,
      "z": -2,
      "name": "Empty"
    },
    {
      "x": -5,
      "y": 16,
      "z": -2,
      "name": "Rock_Shale_Brick_Half",
      "rotation": 5
    },
    {
      "x": -5,
      "y": 17,
      "z": -2,
      "name": "Wood_Fir_Trunk",
      "rotation": 4
    },
    {
      "x": -5,
      "y": 18,
      "z": -2,
      "name": "Rock_Basalt_Cobble_Roof",
      "rotation": 3
    },
    {
      "x": -5,
      "y": 2,
      "z": -1,
      "name": "Rock_Shale"
    },
    {
      "x": -5,
      "y": 3,
      "z": -1,
      "name": "Rock_Shale"
    },
    {
      "x": -5,
      "y": 4,
      "z": -1,
      "name": "Rock_Shale"
    },
    {
      "x": -5,
      "y": 5,
      "z": -1,
      "name": "Rock_Shale"
    },
    {
      "x": -5,
      "y": 6,
      "z": -1,
      "name": "Rock_Shale"
    },
    {
      "x": -5,
      "y": 7,
      "z": -1,
      "name": "Rock_Shale"
    },
    {
      "x": -5,
      "y": 8,
      "z": -1,
      "name": "Rock_Shale"
    },
    {
      "x": -5,
      "y": 9,
      "z": -1,
      "name": "Soil_Dirt_Cold"
    },
    {
      "x": -5,
      "y": 10,
      "z": -1,
      "name": "Soil_Dirt_Cold"
    },
    {
      "x": -5,
      "y": 11,
      "z": -1,
      "name": "Wood_Fir_Trunk",
      "rotation": 4
    },
    {
      "x": -5,
      "y": 12,
      "z": -1,
      "name": "Empty"
    },
    {
      "x": -5,
      "y": 13,
      "z": -1,
      "name": "Empty"
    },
    {
      "x": -5,
      "y": 14,
      "z": -1,
      "name": "Empty"
    },
    {
      "x": -5,
      "y": 15,
      "z": -1,
      "name": "Empty"
    },
    {
      "x": -5,
      "y": 16,
      "z": -1,
      "name": "Rock_Shale_Brick_Half",
      "rotation": 5
    },
    {
      "x": -5,
      "y": 17,
      "z": -1,
      "name": "Wood_Fir_Trunk",
      "rotation": 4
    },
    {
      "x": -5,
      "y": 18,
      "z": -1,
      "name": "Rock_Basalt_Cobble_Roof",
      "rotation": 3
    },
    {
      "x": -5,
      "y": 2,
      "z": 0,
      "name": "Rock_Shale"
    },
    {
      "x": -5,
      "y": 3,
      "z": 0,
      "name": "Rock_Shale"
    },
    {
      "x": -5,
      "y": 4,
      "z": 0,
      "name": "Rock_Shale"
    },
    {
      "x": -5,
      "y": 5,
      "z": 0,
      "name": "Rock_Shale"
    },
    {
      "x": -5,
      "y": 6,
      "z": 0,
      "name": "Rock_Shale"
    },
    {
      "x": -5,
      "y": 7,
      "z": 0,
      "name": "Rock_Shale"
    },
    {
      "x": -5,
      "y": 8,
      "z": 0,
      "name": "Rock_Shale"
    },
    {
      "x": -5,
      "y": 9,
      "z": 0,
      "name": "Soil_Dirt_Cold"
    },
    {
      "x": -5,
      "y": 10,
      "z": 0,
      "name": "Soil_Dirt_Cold"
    },
    {
      "x": -5,
      "y": 11,
      "z": 0,
      "name": "Wood_Fir_Trunk",
      "rotation": 4
    },
    {
      "x": -5,
      "y": 12,
      "z": 0,
      "name": "Empty"
    },
    {
      "x": -5,
      "y": 13,
      "z": 0,
      "name": "Empty"
    },
    {
      "x": -5,
      "y": 14,
      "z": 0,
      "name": "Empty"
    },
    {
      "x": -5,
      "y": 15,
      "z": 0,
      "name": "Empty"
    },
    {
      "x": -5,
      "y": 16,
      "z": 0,
      "name": "Rock_Shale_Brick_Half",
      "rotation": 5
    },
    {
      "x": -5,
      "y": 17,
      "z": 0,
      "name": "Wood_Fir_Trunk",
      "rotation": 4
    },
    {
      "x": -5,
      "y": 18,
      "z": 0,
      "name": "Rock_Basalt_Cobble_Roof",
      "rotation": 3
    },
    {
      "x": -5,
      "y": 2,
      "z": 1,
      "name": "Rock_Shale"
    },
    {
      "x": -5,
      "y": 3,
      "z": 1,
      "name": "Rock_Shale"
    },
    {
      "x": -5,
      "y": 4,
      "z": 1,
      "name": "Rock_Shale"
    },
    {
      "x": -5,
      "y": 5,
      "z": 1,
      "name": "Rock_Shale"
    },
    {
      "x": -5,
      "y": 6,
      "z": 1,
      "name": "Rock_Shale"
    },
    {
      "x": -5,
      "y": 7,
      "z": 1,
      "name": "Rock_Shale"
    },
    {
      "x": -5,
      "y": 8,
      "z": 1,
      "name": "Rock_Shale"
    },
    {
      "x": -5,
      "y": 9,
      "z": 1,
      "name": "Soil_Dirt_Cold"
    },
    {
      "x": -5,
      "y": 10,
      "z": 1,
      "name": "Soil_Dirt_Cold"
    },
    {
      "x": -5,
      "y": 11,
      "z": 1,
      "name": "Wood_Fir_Trunk",
      "rotation": 4
    },
    {
      "x": -5,
      "y": 12,
      "z": 1,
      "name": "Empty"
    },
    {
      "x": -5,
      "y": 13,
      "z": 1,
      "name": "Empty"
    },
    {
      "x": -5,
      "y": 14,
      "z": 1,
      "name": "Empty"
    },
    {
      "x": -5,
      "y": 15,
      "z": 1,
      "name": "Empty"
    },
    {
      "x": -5,
      "y": 16,
      "z": 1,
      "name": "Wood_Fir_Trunk",
      "rotation": 5
    },
    {
      "x": -5,
      "y": 17,
      "z": 1,
      "name": "Wood_Fir_Trunk",
      "rotation": 4
    },
    {
      "x": -5,
      "y": 18,
      "z": 1,
      "name": "Rock_Basalt_Cobble_Roof",
      "rotation": 3
    },
    {
      "x": -5,
      "y": 3,
      "z": 2,
      "name": "Rock_Shale"
    },
    {
      "x": -5,
      "y": 4,
      "z": 2,
      "name": "Rock_Shale"
    },
    {
      "x": -5,
      "y": 5,
      "z": 2,
      "name": "Rock_Shale"
    },
    {
      "x": -5,
      "y": 6,
      "z": 2,
      "name": "Rock_Shale"
    },
    {
      "x": -5,
      "y": 7,
      "z": 2,
      "name": "Rock_Shale"
    },
    {
      "x": -5,
      "y": 8,
      "z": 2,
      "name": "Rock_Shale"
    },
    {
      "x": -5,
      "y": 9,
      "z": 2,
      "name": "Rock_Shale"
    },
    {
      "x": -5,
      "y": 10,
      "z": 2,
      "name": "Rock_Basalt_Brick"
    },
    {
      "x": -5,
      "y": 11,
      "z": 2,
      "name": "Rock_Basalt_Brick"
    },
    {
      "x": -5,
      "y": 12,
      "z": 2,
      "name": "Rock_Basalt_Brick"
    },
    {
      "x": -5,
      "y": 13,
      "z": 2,
      "name": "Rock_Basalt_Brick"
    },
    {
      "x": -5,
      "y": 14,
      "z": 2,
      "name": "Rock_Shale_Brick"
    },
    {
      "x": -5,
      "y": 15,
      "z": 2,
      "name": "Rock_Shale_Brick"
    },
    {
      "x": -5,
      "y": 16,
      "z": 2,
      "name": "Rock_Shale_Brick"
    },
    {
      "x": -5,
      "y": 17,
      "z": 2,
      "name": "Rock_Basalt_Cobble"
    },
    {
      "x": -5,
      "y": 18,
      "z": 2,
      "name": "Rock_Basalt_Cobble_Roof",
      "rotation": 3
    },
    {
      "x": -5,
      "y": 4,
      "z": 3,
      "name": "Rock_Shale"
    },
    {
      "x": -5,
      "y": 5,
      "z": 3,
      "name": "Rock_Shale"
    },
    {
      "x": -5,
      "y": 6,
      "z": 3,
      "name": "Rock_Shale"
    },
    {
      "x": -5,
      "y": 7,
      "z": 3,
      "name": "Rock_Shale"
    },
    {
      "x": -5,
      "y": 8,
      "z": 3,
      "name": "Rock_Shale"
    },
    {
      "x": -5,
      "y": 9,
      "z": 3,
      "name": "Rock_Shale_Cobble"
    },
    {
      "x": -5,
      "y": 10,
      "z": 3,
      "name": "Rock_Shale_Cobble"
    },
    {
      "x": -5,
      "y": 11,
      "z": 3,
      "name": "Rock_Shale_Cobble"
    },
    {
      "x": -5,
      "y": 12,
      "z": 3,
      "name": "Rock_Shale_Brick"
    },
    {
      "x": -5,
      "y": 13,
      "z": 3,
      "name": "Rock_Shale_Brick"
    },
    {
      "x": -5,
      "y": 14,
      "z": 3,
      "name": "Rock_Shale_Brick"
    },
    {
      "x": -5,
      "y": 15,
      "z": 3,
      "name": "Rock_Shale_Brick"
    },
    {
      "x": -5,
      "y": 16,
      "z": 3,
      "name": "Rock_Shale_Brick"
    },
    {
      "x": -5,
      "y": 17,
      "z": 3,
      "name": "Rock_Basalt_Cobble"
    },
    {
      "x": -5,
      "y": 18,
      "z": 3,
      "name": "Rock_Basalt_Cobble_Roof",
      "rotation": 3
    },
    {
      "x": -5,
      "y": 4,
      "z": 4,
      "name": "Rock_Shale"
    },
    {
      "x": -5,
      "y": 5,
      "z": 4,
      "name": "Rock_Shale"
    },
    {
      "x": -5,
      "y": 6,
      "z": 4,
      "name": "Rock_Shale"
    },
    {
      "x": -5,
      "y": 7,
      "z": 4,
      "name": "Rock_Shale"
    },
    {
      "x": -5,
      "y": 8,
      "z": 4,
      "name": "Rock_Shale"
    },
    {
      "x": -5,
      "y": 9,
      "z": 4,
      "name": "Rock_Shale_Cobble"
    },
    {
      "x": -5,
      "y": 10,
      "z": 4,
      "name": "Rock_Shale_Cobble"
    },
    {
      "x": -5,
      "y": 11,
      "z": 4,
      "name": "Rock_Shale_Cobble"
    },
    {
      "x": -5,
      "y": 12,
      "z": 4,
      "name": "Rock_Shale_Brick"
    },
    {
      "x": -5,
      "y": 13,
      "z": 4,
      "name": "Rock_Shale_Brick"
    },
    {
      "x": -5,
      "y": 14,
      "z": 4,
      "name": "Rock_Shale_Brick"
    },
    {
      "x": -5,
      "y": 15,
      "z": 4,
      "name": "Rock_Shale_Brick"
    },
    {
      "x": -5,
      "y": 16,
      "z": 4,
      "name": "Rock_Shale_Cobble"
    },
    {
      "x": -5,
      "y": 4,
      "z": 5,
      "name": "Rock_Shale"
    },
    {
      "x": -5,
      "y": 5,
      "z": 5,
      "name": "Rock_Shale"
    },
    {
      "x": -5,
      "y": 6,
      "z": 5,
      "name": "Rock_Shale"
    },
    {
      "x": -5,
      "y": 7,
      "z": 5,
      "name": "Rock_Shale"
    },
    {
      "x": -5,
      "y": 8,
      "z": 5,
      "name": "Rock_Shale"
    },
    {
      "x": -5,
      "y": 9,
      "z": 5,
      "name": "Soil_Dirt_Cold"
    },
    {
      "x": -5,
      "y": 10,
      "z": 5,
      "name": "Soil_Dirt_Cold"
    },
    {
      "x": -5,
      "y": 11,
      "z": 5,
      "name": "Empty"
    },
    {
      "x": -5,
      "y": 12,
      "z": 5,
      "name": "Empty"
    },
    {
      "x": -5,
      "y": 13,
      "z": 5,
      "name": "Empty"
    },
    {
      "x": -5,
      "y": 14,
      "z": 5,
      "name": "Rock_Shale_Brick_Half",
      "rotation": 4
    },
    {
      "x": -5,
      "y": 15,
      "z": 5,
      "name": "Rock_Shale_Brick"
    },
    {
      "x": -5,
      "y": 16,
      "z": 5,
      "name": "Rock_Shale_Cobble"
    },
    {
      "x": -5,
      "y": 3,
      "z": 6,
      "name": "Rock_Shale"
    },
    {
      "x": -5,
      "y": 4,
      "z": 6,
      "name": "Rock_Shale"
    },
    {
      "x": -5,
      "y": 5,
      "z": 6,
      "name": "Rock_Shale"
    },
    {
      "x": -5,
      "y": 6,
      "z": 6,
      "name": "Rock_Shale"
    },
    {
      "x": -5,
      "y": 7,
      "z": 6,
      "name": "Rock_Shale"
    },
    {
      "x": -5,
      "y": 8,
      "z": 6,
      "name": "Rock_Shale"
    },
    {
      "x": -5,
      "y": 9,
      "z": 6,
      "name": "Soil_Dirt_Cold"
    },
    {
      "x": -5,
      "y": 10,
      "z": 6,
      "name": "Soil_Dirt_Cold"
    },
    {
      "x": -5,
      "y": 11,
      "z": 6,
      "name": "Empty"
    },
    {
      "x": -5,
      "y": 12,
      "z": 6,
      "name": "Empty"
    },
    {
      "x": -5,
      "y": 13,
      "z": 6,
      "name": "Empty"
    },
    {
      "x": -5,
      "y": 14,
      "z": 6,
      "name": "Empty"
    },
    {
      "x": -5,
      "y": 15,
      "z": 6,
      "name": "Rock_Shale_Brick_Half",
      "rotation": 8
    },
    {
      "x": -5,
      "y": 16,
      "z": 6,
      "name": "Rock_Shale_Cobble"
    },
    {
      "x": -5,
      "y": 3,
      "z": 7,
      "name": "Rock_Shale"
    },
    {
      "x": -5,
      "y": 4,
      "z": 7,
      "name": "Rock_Shale"
    },
    {
      "x": -5,
      "y": 5,
      "z": 7,
      "name": "Rock_Shale"
    },
    {
      "x": -5,
      "y": 6,
      "z": 7,
      "name": "Rock_Shale"
    },
    {
      "x": -5,
      "y": 7,
      "z": 7,
      "name": "Rock_Shale"
    },
    {
      "x": -5,
      "y": 8,
      "z": 7,
      "name": "Rock_Shale"
    },
    {
      "x": -5,
      "y": 9,
      "z": 7,
      "name": "Soil_Dirt_Cold"
    },
    {
      "x": -5,
      "y": 10,
      "z": 7,
      "name": "Soil_Dirt_Cold"
    },
    {
      "x": -5,
      "y": 11,
      "z": 7,
      "name": "Empty"
    },
    {
      "x": -5,
      "y": 12,
      "z": 7,
      "name": "Empty"
    },
    {
      "x": -5,
      "y": 13,
      "z": 7,
      "name": "Empty"
    },
    {
      "x": -5,
      "y": 14,
      "z": 7,
      "name": "Rock_Shale_Brick_Half",
      "rotation": 6
    },
    {
      "x": -5,
      "y": 15,
      "z": 7,
      "name": "Rock_Shale_Brick"
    },
    {
      "x": -5,
      "y": 16,
      "z": 7,
      "name": "Rock_Shale_Cobble"
    },
    {
      "x": -5,
      "y": 17,
      "z": 7,
      "name": "Rock_Shale_Cobble_Stairs",
      "rotation": 2
    },
    {
      "x": -5,
      "y": 1,
      "z": 8,
      "name": "Rock_Shale"
    },
    {
      "x": -5,
      "y": 2,
      "z": 8,
      "name": "Rock_Shale"
    },
    {
      "x": -5,
      "y": 3,
      "z": 8,
      "name": "Rock_Shale"
    },
    {
      "x": -5,
      "y": 4,
      "z": 8,
      "name": "Rock_Shale"
    },
    {
      "x": -5,
      "y": 5,
      "z": 8,
      "name": "Rock_Shale"
    },
    {
      "x": -5,
      "y": 6,
      "z": 8,
      "name": "Rock_Shale"
    },
    {
      "x": -5,
      "y": 7,
      "z": 8,
      "name": "Rock_Shale"
    },
    {
      "x": -5,
      "y": 8,
      "z": 8,
      "name": "Rock_Shale"
    },
    {
      "x": -5,
      "y": 9,
      "z": 8,
      "name": "Rock_Shale_Cobble"
    },
    {
      "x": -5,
      "y": 10,
      "z": 8,
      "name": "Rock_Shale_Cobble"
    },
    {
      "x": -5,
      "y": 11,
      "z": 8,
      "name": "Rock_Shale_Cobble"
    },
    {
      "x": -5,
      "y": 12,
      "z": 8,
      "name": "Rock_Shale_Cobble"
    },
    {
      "x": -5,
      "y": 13,
      "z": 8,
