{
  "version": 8,
  "blockIdVersion": 8,
  "anchorX": 2,
  "anchorY": 61,
  "anchorZ": 21,
  "blocks": [
    {
      "x": -8,
      "y": 58,
      "z": 18,
      "name": "Rock_Shale_Cobble"
    },
    {
      "x": -8,
      "y": 59,
      "z": 18,
      "name": "Rock_Shale_Cobble"
    },
    {
      "x": -8,
      "y": 60,
      "z": 18,
      "name": "Rock_Shale_Cobble_Stairs",
      "rotation": 3
    },
    {
      "x": -8,
      "y": 62,
      "z": 18,
      "name": "Empty"
    },
    {
      "x": -8,
      "y": 63,
      "z": 18,
      "name": "Empty"
    },
    {
      "x": -8,
      "y": 64,
      "z": 18,
      "name": "Empty"
    },
    {
      "x": -8,
      "y": 65,
      "z": 18,
      "name": "Empty"
    },
    {
      "x": -8,
      "y": 66,
      "z": 18,
      "name": "Empty"
    },
    {
      "x": -8,
      "y": 67,
      "z": 18,
      "name": "Empty"
    },
    {
      "x": -8,
      "y": 68,
      "z": 18,
      "name": "Empty"
    },
    {
      "x": -8,
      "y": 58,
      "z": 19,
      "name": "Rock_Shale_Cobble"
    },
    {
      "x": -8,
      "y": 59,
      "z": 19,
      "name": "Rock_Shale_Cobble"
    },
    {
      "x": -8,
      "y": 60,
      "z": 19,
      "name": "Rock_Shale_Cobble_Stairs",
      "rotation": 3
    },
    {
      "x": -8,
      "y": 62,
      "z": 19,
      "name": "Empty"
    },
    {
      "x": -8,
      "y": 63,
      "z": 19,
      "name": "Empty"
    },
    {
      "x": -8,
      "y": 64,
      "z": 19,
      "name": "Empty"
    },
    {
      "x": -8,
      "y": 65,
      "z": 19,
      "name": "Empty"
    },
    {
      "x": -8,
      "y": 66,
      "z": 19,
      "name": "Empty"
    },
    {
      "x": -8,
      "y": 67,
      "z": 19,
      "name": "Empty"
    },
    {
      "x": -8,
      "y": 68,
      "z": 19,
      "name": "Empty"
    },
    {
      "x": -7,
      "y": 57,
      "z": 18,
      "name": "Rock_Shale"
    },
    {
      "x": -7,
      "y": 58,
      "z": 18,
      "name": "Rock_Shale_Cobble"
    },
    {
      "x": -7,
      "y": 59,
      "z": 18,
      "name": "Rock_Shale_Cobble"
    },
    {
      "x": -7,
      "y": 60,
      "z": 18,
      "name": "Rock_Shale_Cobble"
    },
    {
      "x": -7,
      "y": 61,
      "z": 18,
      "name": "Rock_Shale_Cobble_Stairs",
      "rotation": 3
    },
    {
      "x": -7,
      "y": 62,
      "z": 18,
      "name": "Empty"
    },
    {
      "x": -7,
      "y": 63,
      "z": 18,
      "name": "Empty"
    },
    {
      "x": -7,
      "y": 64,
      "z": 18,
      "name": "Empty"
    },
    {
      "x": -7,
      "y": 65,
      "z": 18,
      "name": "Empty"
    },
    {
      "x": -7,
      "y": 66,
      "z": 18,
      "name": "Empty"
    },
    {
      "x": -7,
      "y": 67,
      "z": 18,
      "name": "Empty"
    },
    {
      "x": -7,
      "y": 68,
      "z": 18,
      "name": "Empty"
    },
    {
      "x": -7,
      "y": 69,
      "z": 18,
      "name": "Empty"
    },
    {
      "x": -7,
      "y": 57,
      "z": 19,
      "name": "Rock_Shale"
    },
    {
      "x": -7,
      "y": 58,
      "z": 19,
      "name": "Rock_Shale_Cobble"
    },
    {
      "x": -7,
      "y": 59,
      "z": 19,
      "name": "Rock_Shale_Cobble"
    },
    {
      "x": -7,
      "y": 60,
      "z": 19,
      "name": "Rock_Shale_Cobble"
    },
    {
      "x": -7,
      "y": 61,
      "z": 19,
      "name": "Rock_Shale_Cobble_Stairs",
      "rotation": 3
    },
    {
      "x": -7,
      "y": 62,
      "z": 19,
      "name": "Empty"
    },
    {
      "x": -7,
      "y": 63,
      "z": 19,
      "name": "Empty"
    },
    {
      "x": -7,
      "y": 64,
      "z": 19,
      "name": "Empty"
    },
    {
      "x": -7,
      "y": 65,
      "z": 19,
      "name": "Empty"
    },
    {
      "x": -7,
      "y": 66,
      "z": 19,
      "name": "Empty"
    },
    {
      "x": -7,
      "y": 67,
      "z": 19,
      "name": "Empty"
    },
    {
      "x": -7,
      "y": 68,
      "z": 19,
      "name": "Empty"
    },
    {
      "x": -7,
      "y": 69,
      "z": 19,
      "name": "Empty"
    },
    {
      "x": -6,
      "y": 56,
      "z": 18,
      "name": "Rock_Shale"
    },
    {
      "x": -6,
      "y": 57,
      "z": 18,
      "name": "Rock_Shale"
    },
    {
      "x": -6,
      "y": 58,
      "z": 18,
      "name": "Rock_Shale"
    },
    {
      "x": -6,
      "y": 59,
      "z": 18,
      "name": "Rock_Shale_Cobble"
    },
    {
      "x": -6,
      "y": 60,
      "z": 18,
      "name": "Rock_Shale_Cobble"
    },
    {
      "x": -6,
      "y": 61,
      "z": 18,
      "name": "Rock_Shale_Cobble"
    },
    {
      "x": -6,
      "y": 62,
      "z": 18,
      "name": "Rock_Shale_Cobble_Stairs",
      "rotation": 3
    },
    {
      "x": -6,
      "y": 63,
      "z": 18,
      "name": "Empty"
    },
    {
      "x": -6,
      "y": 64,
      "z": 18,
      "name": "Empty"
    },
    {
      "x": -6,
      "y": 65,
      "z": 18,
      "name": "Empty"
    },
    {
      "x": -6,
      "y": 66,
      "z": 18,
      "name": "Empty"
    },
    {
      "x": -6,
      "y": 67,
      "z": 18,
      "name": "Empty"
    },
    {
      "x": -6,
      "y": 68,
      "z": 18,
      "name": "Empty"
    },
    {
      "x": -6,
      "y": 69,
      "z": 18,
      "name": "Empty"
    },
    {
      "x": -6,
      "y": 70,
      "z": 18,
      "name": "Empty"
    },
    {
      "x": -6,
      "y": 56,
      "z": 19,
      "name": "Rock_Shale"
    },
    {
      "x": -6,
      "y": 57,
      "z": 19,
      "name": "Rock_Shale"
    },
    {
      "x": -6,
      "y": 58,
      "z": 19,
      "name": "Rock_Shale"
    },
    {
      "x": -6,
      "y": 59,
      "z": 19,
      "name": "Rock_Shale"
    },
    {
      "x": -6,
      "y": 60,
      "z": 19,
      "name": "Rock_Shale_Cobble"
    },
    {
      "x": -6,
      "y": 61,
      "z": 19,
      "name": "Rock_Shale_Cobble"
    },
    {
      "x": -6,
      "y": 62,
      "z": 19,
      "name": "Rock_Shale_Cobble_Stairs",
      "rotation": 3
    },
    {
      "x": -6,
      "y": 63,
      "z": 19,
      "name": "Empty"
    },
    {
      "x": -6,
      "y": 64,
      "z": 19,
      "name": "Empty"
    },
    {
      "x": -6,
      "y": 65,
      "z": 19,
      "name": "Empty"
    },
    {
      "x": -6,
      "y": 66,
      "z": 19,
      "name": "Empty"
    },
    {
      "x": -6,
      "y": 67,
      "z": 19,
      "name": "Empty"
    },
    {
      "x": -6,
      "y": 68,
      "z": 19,
      "name": "Empty"
    },
    {
      "x": -6,
      "y": 69,
      "z": 19,
      "name": "Empty"
    },
    {
      "x": -6,
      "y": 70,
      "z": 19,
      "name": "Empty"
    },
    {
      "x": -6,
      "y": 57,
      "z": 20,
      "name": "Rock_Shale"
    },
    {
      "x": -6,
      "y": 58,
      "z": 20,
      "name": "Rock_Shale"
    },
    {
      "x": -6,
      "y": 59,
      "z": 20,
      "name": "Rock_Shale"
    },
    {
      "x": -6,
      "y": 60,
      "z": 20,
      "name": "Rock_Shale"
    },
    {
      "x": -6,
      "y": 61,
      "z": 20,
      "name": "Rock_Shale"
    },
    {
      "x": -6,
      "y": 62,
      "z": 20,
      "name": "Rock_Basalt_Brick"
    },
    {
      "x": -6,
      "y": 63,
      "z": 20,
      "name": "Rock_Basalt_Brick"
    },
    {
      "x": -6,
      "y": 64,
      "z": 20,
      "name": "Rock_Basalt_Cobble_Half",
      "rotation": 6
    },
    {
      "x": -6,
      "y": 65,
      "z": 20,
      "name": "Rock_Basalt_Cobble_Half",
      "rotation": 6
    },
    {
      "x": -6,
      "y": 66,
      "z": 20,
      "name": "Rock_Shale_Brick_Half",
      "rotation": 6
    },
    {
      "x": -6,
      "y": 67,
      "z": 20,
      "name": "Rock_Shale_Brick_Half",
      "rotation": 6
    },
    {
      "x": -6,
      "y": 68,
      "z": 20,
      "name": "*Rock_Shale_Cobble_Wall_State_Definitions_Corner",
      "rotation": 1
    },
    {
      "x": -6,
      "y": 69,
      "z": 20,
      "name": "Furniture_Human_Ruins_Torch",
      "rotation": 2
    },
    {
      "x": -6,
      "y": 70,
      "z": 20,
      "name": "Empty"
    },
    {
      "x": -6,
      "y": 71,
      "z": 20,
      "name": "Empty"
    },
    {
      "x": -6,
      "y": 72,
      "z": 20,
      "name": "Empty"
    },
    {
      "x": -6,
      "y": 57,
      "z": 21,
      "name": "Rock_Shale"
    },
    {
      "x": -6,
      "y": 58,
      "z": 21,
      "name": "Rock_Shale"
    },
    {
      "x": -6,
      "y": 59,
      "z": 21,
      "name": "Rock_Shale"
    },
    {
      "x": -6,
      "y": 60,
      "z": 21,
      "name": "Rock_Shale"
    },
    {
      "x": -6,
      "y": 61,
      "z": 21,
      "name": "Rock_Basalt_Brick"
    },
    {
      "x": -6,
      "y": 62,
      "z": 21,
      "name": "Rock_Basalt_Brick"
    },
    {
      "x": -6,
      "y": 63,
      "z": 21,
      "name": "Rock_Basalt_Cobble"
    },
    {
      "x": -6,
      "y": 64,
      "z": 21,
      "name": "Rock_Basalt_Cobble"
    },
    {
      "x": -6,
      "y": 65,
      "z": 21,
      "name": "Rock_Basalt_Cobble"
    },
    {
      "x": -6,
      "y": 66,
      "z": 21,
      "name": "Rock_Shale_Brick"
    },
    {
      "x": -6,
      "y": 67,
      "z": 21,
      "name": "Rock_Shale_Brick"
    },
    {
      "x": -6,
      "y": 68,
      "z": 21,
      "name": "Rock_Shale_Cobble_Wall",
      "rotation": 3
    },
    {
      "x": -6,
      "y": 69,
      "z": 21,
      "name": "Empty"
    },
    {
      "x": -6,
      "y": 70,
      "z": 21,
      "name": "Empty"
    },
    {
      "x": -6,
      "y": 71,
      "z": 21,
      "name": "Empty"
    },
    {
      "x": -6,
      "y": 72,
      "z": 21,
      "name": "Empty"
    },
    {
      "x": -6,
      "y": 73,
      "z": 21,
      "name": "Empty"
    },
    {
      "x": -6,
      "y": 57,
      "z": 22,
      "name": "Rock_Shale"
    },
    {
      "x": -6,
      "y": 58,
      "z": 22,
      "name": "Rock_Shale"
    },
    {
      "x": -6,
      "y": 59,
      "z": 22,
      "name": "Rock_Shale"
    },
    {
      "x": -6,
      "y": 60,
      "z": 22,
      "name": "Rock_Shale"
    },
    {
      "x": -6,
      "y": 61,
      "z": 22,
      "name": "Rock_Basalt_Brick"
    },
    {
      "x": -6,
      "y": 62,
      "z": 22,
      "name": "Rock_Basalt_Brick"
    },
    {
      "x": -6,
      "y": 63,
      "z": 22,
      "name": "Rock_Basalt_Cobble"
    },
    {
      "x": -6,
      "y": 64,
      "z": 22,
      "name": "Rock_Shale_Brick"
    },
    {
      "x": -6,
      "y": 65,
      "z": 22,
      "name": "Rock_Shale_Brick"
    },
    {
      "x": -6,
      "y": 66,
      "z": 22,
      "name": "Rock_Shale_Brick"
    },
    {
      "x": -6,
      "y": 67,
      "z": 22,
      "name": "Rock_Shale_Brick"
    },
    {
      "x": -6,
      "y": 68,
      "z": 22,
      "name": "Rock_Shale_Cobble_Wall",
      "rotation": 3
    },
    {
      "x": -6,
      "y": 69,
      "z": 22,
      "name": "Empty"
    },
    {
      "x": -6,
      "y": 70,
      "z": 22,
      "name": "Empty"
    },
    {
      "x": -6,
      "y": 71,
      "z": 22,
      "name": "Empty"
    },
    {
      "x": -6,
      "y": 72,
      "z": 22,
      "name": "Empty"
    },
    {
      "x": -6,
      "y": 73,
      "z": 22,
      "name": "Empty"
    },
    {
      "x": -6,
      "y": 57,
      "z": 23,
      "name": "Rock_Shale"
    },
    {
      "x": -6,
      "y": 58,
      "z": 23,
      "name": "Rock_Shale"
    },
    {
      "x": -6,
      "y": 59,
      "z": 23,
      "name": "Rock_Shale"
    },
    {
      "x": -6,
      "y": 60,
      "z": 23,
      "name": "Rock_Shale"
    },
    {
      "x": -6,
      "y": 61,
      "z": 23,
      "name": "Rock_Basalt_Brick"
    },
    {
      "x": -6,
      "y": 62,
      "z": 23,
      "name": "Rock_Basalt_Brick"
    },
    {
      "x": -6,
      "y": 63,
      "z": 23,
      "name": "Rock_Basalt_Brick"
    },
    {
      "x": -6,
      "y": 64,
      "z": 23,
      "name": "Rock_Basalt_Brick"
    },
    {
      "x": -6,
      "y": 65,
      "z": 23,
      "name": "Furniture_Ancient_Window",
      "rotation": 1
    },
    {
      "x": -6,
      "y": 66,
      "z": 23,
      "name": "Rock_Shale_Brick"
    },
    {
      "x": -6,
      "y": 67,
      "z": 23,
      "name": "Rock_Shale_Brick"
    },
    {
      "x": -6,
      "y": 68,
      "z": 23,
      "name": "Rock_Shale_Cobble_Wall",
      "rotation": 3
    },
    {
      "x": -6,
      "y": 69,
      "z": 23,
      "name": "Empty"
    },
    {
      "x": -6,
      "y": 70,
      "z": 23,
      "name": "Empty"
    },
    {
      "x": -6,
      "y": 71,
      "z": 23,
      "name": "Empty"
    },
    {
      "x": -6,
      "y": 72,
      "z": 23,
      "name": "Empty"
    },
    {
      "x": -6,
      "y": 73,
      "z": 23,
      "name": "Empty"
    },
    {
      "x": -6,
      "y": 57,
      "z": 24,
      "name": "Rock_Shale"
    },
    {
      "x": -6,
      "y": 58,
      "z": 24,
      "name": "Rock_Shale"
    },
    {
      "x": -6,
      "y": 59,
      "z": 24,
      "name": "Rock_Shale"
    },
    {
      "x": -6,
      "y": 60,
      "z": 24,
      "name": "Rock_Shale"
    },
    {
      "x": -6,
      "y": 61,
      "z": 24,
      "name": "Rock_Shale"
    },
    {
      "x": -6,
      "y": 62,
      "z": 24,
      "name": "Rock_Basalt_Brick"
    },
    {
      "x": -6,
      "y": 63,
      "z": 24,
      "name": "Rock_Basalt_Brick"
    },
    {
      "x": -6,
      "y": 64,
      "z": 24,
      "name": "Rock_Basalt_Brick"
    },
    {
      "x": -6,
      "y": 65,
      "z": 24,
      "name": "Rock_Basalt_Brick"
    },
    {
      "x": -6,
      "y": 66,
      "z": 24,
      "name": "Rock_Shale_Brick"
    },
    {
      "x": -6,
      "y": 67,
      "z": 24,
      "name": "Rock_Shale_Brick"
    },
    {
      "x": -6,
      "y": 68,
      "z": 24,
      "name": "Rock_Shale_Cobble_Wall",
      "rotation": 3
    },
    {
      "x": -6,
      "y": 69,
      "z": 24,
      "name": "Empty"
    },
    {
      "x": -6,
      "y": 70,
      "z": 24,
      "name": "Empty"
    },
    {
      "x": -6,
      "y": 71,
      "z": 24,
      "name": "Empty"
    },
    {
      "x": -6,
      "y": 72,
      "z": 24,
      "name": "Empty"
    },
    {
      "x": -6,
      "y": 73,
      "z": 24,
      "name": "Empty"
    },
    {
      "x": -6,
      "y": 58,
      "z": 25,
      "name": "Rock_Shale"
    },
    {
      "x": -6,
      "y": 59,
      "z": 25,
      "name": "Rock_Shale"
    },
    {
      "x": -6,
      "y": 60,
      "z": 25,
      "name": "Rock_Shale"
    },
    {
      "x": -6,
      "y": 61,
      "z": 25,
      "name": "Rock_Basalt_Brick"
    },
    {
      "x": -6,
      "y": 62,
      "z": 25,
      "name": "Rock_Basalt_Brick"
    },
    {
      "x": -6,
      "y": 63,
      "z": 25,
      "name": "Rock_Basalt_Brick"
    },
    {
      "x": -6,
      "y": 64,
      "z": 25,
      "name": "Rock_Basalt_Brick"
    },
    {
      "x": -6,
      "y": 65,
      "z": 25,
      "name": "Rock_Shale_Brick"
    },
    {
      "x": -6,
      "y": 66,
      "z": 25,
      "name": "Rock_Shale_Brick"
    },
    {
      "x": -6,
      "y": 67,
      "z": 25,
      "name": "Rock_Shale_Brick"
    },
    {
      "x": -6,
      "y": 68,
      "z": 25,
      "name": "*Rock_Shale_Cobble_Wall_State_Definitions_Corner",
      "rotation": 2
    },
    {
      "x": -6,
      "y": 69,
      "z": 25,
      "name": "Furniture_Human_Ruins_Torch",
      "rotation": 3
    },
    {
      "x": -6,
      "y": 70,
      "z": 25,
      "name": "Empty"
    },
    {
      "x": -6,
      "y": 71,
      "z": 25,
      "name": "Empty"
    },
    {
      "x": -6,
      "y": 72,
      "z": 25,
      "name": "Empty"
    },
    {
      "x": -5,
      "y": 56,
      "z": 18,
      "name": "Rock_Shale"
    },
    {
      "x": -5,
      "y": 57,
      "z": 18,
      "name": "Rock_Shale"
    },
    {
      "x": -5,
      "y": 58,
      "z": 18,
      "name": "Rock_Shale"
    },
    {
      "x": -5,
      "y": 59,
      "z": 18,
      "name": "Rock_Shale"
    },
    {
      "x": -5,
      "y": 60,
      "z": 18,
      "name": "Rock_Shale"
    },
    {
      "x": -5,
      "y": 61,
      "z": 18,
      "name": "Rock_Shale_Cobble"
    },
    {
      "x": -5,
      "y": 62,
      "z": 18,
      "name": "Rock_Shale_Cobble"
    },
    {
      "x": -5,
      "y": 63,
      "z": 18,
      "name": "Rock_Shale_Cobble_Stairs",
      "rotation": 3
    },
    {
      "x": -5,
      "y": 64,
      "z": 18,
      "name": "Empty"
    },
    {
      "x": -5,
      "y": 65,
      "z": 18,
      "name": "Empty"
    },
    {
      "x": -5,
      "y": 66,
      "z": 18,
      "name": "Empty"
    },
    {
      "x": -5,
      "y": 67,
      "z": 18,
      "name": "Empty"
    },
    {
      "x": -5,
      "y": 68,
      "z": 18,
      "name": "Empty"
    },
    {
      "x": -5,
      "y": 69,
      "z": 18,
      "name": "Empty"
    },
    {
      "x": -5,
      "y": 70,
      "z": 18,
      "name": "Empty"
    },
    {
      "x": -5,
      "y": 71,
      "z": 18,
      "name": "Empty"
    },
    {
      "x": -5,
      "y": 55,
      "z": 19,
      "name": "Rock_Shale"
    },
    {
      "x": -5,
      "y": 56,
      "z": 19,
      "name": "Rock_Shale"
    },
    {
      "x": -5,
      "y": 57,
      "z": 19,
      "name": "Rock_Shale"
    },
    {
      "x": -5,
      "y": 58,
      "z": 19,
      "name": "Rock_Shale"
    },
    {
      "x": -5,
      "y": 59,
      "z": 19,
      "name": "Rock_Shale"
    },
    {
      "x": -5,
      "y": 60,
      "z": 19,
      "name": "Rock_Shale"
    },
    {
      "x": -5,
      "y": 61,
      "z": 19,
      "name": "Rock_Shale_Cobble"
    },
    {
      "x": -5,
      "y": 62,
      "z": 19,
      "name": "Rock_Shale_Cobble"
    },
    {
      "x": -5,
      "y": 63,
      "z": 19,
      "name": "Rock_Shale_Cobble_Stairs",
      "rotation": 3
    },
    {
      "x": -5,
      "y": 64,
      "z": 19,
      "name": "Empty"
    },
    {
      "x": -5,
      "y": 65,
      "z": 19,
      "name": "Empty"
    },
    {
      "x": -5,
      "y": 66,
      "z": 19,
      "name": "Empty"
    },
    {
      "x": -5,
      "y": 67,
      "z": 19,
      "name": "Empty"
    },
    {
      "x": -5,
      "y": 68,
      "z": 19,
      "name": "Empty"
    },
    {
      "x": -5,
      "y": 69,
      "z": 19,
      "name": "Empty"
    },
    {
      "x": -5,
      "y": 70,
      "z": 19,
      "name": "Empty"
    },
    {
      "x": -5,
      "y": 71,
      "z": 19,
      "name": "Empty"
    },
    {
      "x": -5,
      "y": 55,
      "z": 20,
      "name": "Rock_Shale"
    },
    {
      "x": -5,
      "y": 56,
      "z": 20,
      "name": "Rock_Shale"
    },
    {
      "x": -5,
      "y": 57,
      "z": 20,
      "name": "Rock_Shale"
    },
    {
      "x": -5,
      "y": 58,
      "z": 20,
      "name": "Rock_Shale"
    },
    {
      "x": -5,
      "y": 59,
      "z": 20,
      "name": "Rock_Shale"
    },
    {
      "x": -5,
      "y": 60,
      "z": 20,
      "name": "Rock_Shale"
    },
    {
      "x": -5,
      "y": 61,
      "z": 20,
      "name": "Rock_Shale"
    },
    {
      "x": -5,
      "y": 62,
      "z": 20,
      "name": "Rock_Basalt_Brick"
    },
    {
      "x": -5,
      "y": 63,
      "z": 20,
      "name": "Rock_Basalt_Brick"
    },
    {
      "x": -5,
      "y": 64,
      "z": 20,
      "name": "Rock_Basalt_Cobble"
    },
    {
      "x": -5,
      "y": 65,
      "z": 20,
      "name": "Rock_Shale_Brick"
    },
    {
      "x": -5,
      "y": 66,
      "z": 20,
      "name": "Rock_Shale_Brick"
    },
    {
      "x": -5,
      "y": 67,
      "z": 20,
      "name": "Rock_Shale_Brick_Half"
    },
    {
      "x": -5,
      "y": 68,
      "z": 20,
      "name": "Empty"
    },
    {
      "x": -5,
      "y": 69,
      "z": 20,
      "name": "Empty"
    },
    {
      "x": -5,
      "y": 70,
      "z": 20,
      "name": "Empty"
    },
    {
      "x": -5,
      "y": 71,
      "z": 20,
      "name": "Empty"
    },
    {
      "x": -5,
      "y": 72,
      "z": 20,
      "name": "Empty"
    },
    {
      "x": -5,
      "y": 73,
      "z": 20,
      "name": "Empty"
    },
    {
      "x": -5,
      "y": 74,
      "z": 20,
      "name": "Empty"
    },
    {
      "x": -5,
      "y": 55,
      "z": 21,
      "name": "Rock_Shale"
    },
    {
      "x": -5,
      "y": 56,
      "z": 21,
      "name": "Rock_Shale"
    },
    {
      "x": -5,
      "y": 57,
      "z": 21,
      "name": "Rock_Shale"
    },
    {
      "x": -5,
      "y": 58,
      "z": 21,
      "name": "Rock_Shale"
    },
    {
      "x": -5,
      "y": 59,
      "z": 21,
      "name": "Rock_Shale"
    },
    {
      "x": -5,
      "y": 60,
      "z": 21,
      "name": "Rock_Shale"
    },
    {
      "x": -5,
      "y": 61,
      "z": 21,
      "name": "Rock_Shale"
    },
    {
      "x": -5,
      "y": 62,
      "z": 21,
      "name": "Rock_Shale"
    },
    {
      "x": -5,
      "y": 63,
      "z": 21,
      "name": "Soil_Dirt_Cold"
    },
    {
      "x": -5,
      "y": 64,
      "z": 21,
      "name": "Furniture_Lumberjack_Shelf"
    },
    {
      "x": -5,
      "y": 65,
      "z": 21,
      "name": "Empty"
    },
    {
      "x": -5,
      "y": 66,
      "z": 21,
      "name": "Empty"
    },
    {
      "x": -5,
      "y": 67,
      "z": 21,
      "name": "Rock_Shale_Cobble"
    },
    {
      "x": -5,
      "y": 68,
      "z": 21,
      "name": "Empty"
    },
    {
      "x": -5,
      "y": 69,
      "z": 21,
      "name": "Empty"
    },
    {
      "x": -5,
      "y": 70,
      "z": 21,
      "name": "Empty"
    },
    {
      "x": -5,
      "y": 71,
      "z": 21,
      "name": "Empty"
    },
    {
      "x": -5,
      "y": 72,
      "z": 21,
      "name": "Empty"
    },
    {
      "x": -5,
      "y": 73,
      "z": 21,
      "name": "Empty"
    },
    {
      "x": -5,
      "y": 74,
      "z": 21,
      "name": "Empty"
    },
    {
      "x": -5,
      "y": 55,
      "z": 22,
      "name": "Rock_Shale"
    },
    {
      "x": -5,
      "y": 56,
      "z": 22,
      "name": "Rock_Shale"
    },
    {
      "x": -5,
      "y": 57,
      "z": 22,
      "name": "Rock_Shale"
    },
    {
      "x": -5,
      "y": 58,
      "z": 22,
      "name": "Rock_Shale"
    },
    {
      "x": -5,
      "y": 59,
      "z": 22,
      "name": "Rock_Shale"
    },
    {
      "x": -5,
      "y": 60,
      "z": 22,
      "name": "Rock_Shale"
    },
    {
      "x": -5,
      "y": 61,
      "z": 22,
      "name": "Rock_Shale"
    },
    {
      "x": -5,
      "y": 62,
      "z": 22,
      "name": "Rock_Shale"
    },
    {
      "x": -5,
      "y": 63,
      "z": 22,
      "name": "Soil_Dirt_Cold"
    },
    {
      "x": -5,
      "y": 64,
      "z": 22,
      "name": "Bench_Lumbermill",
      "rotation": 1
    },
    {
      "x": -5,
      "y": 65,
      "z": 22,
      "name": "Empty"
    },
    {
      "x": -5,
      "y": 66,
      "z": 22,
      "name": "Empty"
    },
    {
      "x": -5,
      "y": 67,
      "z": 22,
      "name": "Rock_Shale_Cobble"
    },
    {
      "x": -5,
      "y": 68,
      "z": 22,
      "name": "Empty"
    },
    {
      "x": -5,
      "y": 69,
      "z": 22,
      "name": "Empty"
    },
    {
      "x": -5,
      "y": 70,
      "z": 22,
      "name": "Empty"
    },
    {
      "x": -5,
      "y": 71,
      "z": 22,
      "name": "Empty"
    },
    {
      "x": -5,
      "y": 72,
      "z": 22,
      "name": "Empty"
    },
    {
      "x": -5,
      "y": 73,
      "z": 22,
      "name": "Empty"
    },
    {
      "x": -5,
      "y": 74,
      "z": 22,
      "name": "Empty"
    },
    {
      "x": -5,
      "y": 56,
      "z": 23,
      "name": "Rock_Shale"
    },
    {
      "x": -5,
      "y": 57,
      "z": 23,
      "name": "Rock_Shale"
    },
    {
      "x": -5,
      "y": 58,
      "z": 23,
      "name": "Rock_Shale"
    },
    {
      "x": -5,
      "y": 59,
      "z": 23,
      "name": "Rock_Shale"
    },
    {
      "x": -5,
      "y": 60,
      "z": 23,
      "name": "Rock_Shale"
    },
    {
      "x": -5,
      "y": 61,
      "z": 23,
      "name": "Rock_Shale"
    },
    {
      "x": -5,
      "y": 62,
      "z": 23,
      "name": "Rock_Shale"
    },
    {
      "x": -5,
      "y": 63,
      "z": 23,
      "name": "Soil_Dirt_Cold"
    },
    {
      "x": -5,
      "y": 64,
      "z": 23,
      "name": "Bench_Lumbermill",
      "filler": 32,
      "rotation": 1
    },
    {
      "x": -5,
      "y": 65,
      "z": 23,
      "name": "Empty"
    },
    {
      "x": -5,
      "y": 66,
      "z": 23,
      "name": "Empty"
    },
    {
      "x": -5,
      "y": 67,
      "z": 23,
      "name": "Rock_Shale_Cobble"
    },
    {
      "x": -5,
      "y": 68,
      "z": 23,
      "name": "Empty"
    },
    {
      "x": -5,
      "y": 69,
      "z": 23,
      "name": "Empty"
    },
    {
      "x": -5,
      "y": 70,
      "z": 23,
      "name": "Empty"
    },
    {
      "x": -5,
      "y": 71,
      "z": 23,
      "name": "Empty"
    },
    {
      "x": -5,
      "y": 72,
      "z": 23,
      "name": "Empty"
    },
    {
      "x": -5,
      "y": 73,
      "z": 23,
      "name": "Empty"
    },
    {
      "x": -5,
      "y": 74,
      "z": 23,
      "name": "Empty"
    },
    {
      "x": -5,
      "y": 56,
      "z": 24,
      "name": "Rock_Shale"
    },
    {
      "x": -5,
      "y": 57,
      "z": 24,
      "name": "Rock_Shale"
    },
    {
      "x": -5,
      "y": 58,
      "z": 24,
      "name": "Rock_Shale"
    },
    {
      "x": -5,
      "y": 59,
      "z": 24,
      "name": "Rock_Shale"
    },
    {
      "x": -5,
      "y": 60,
      "z": 24,
      "name": "Rock_Shale"
    },
    {
      "x": -5,
      "y": 61,
      "z": 24,
      "name": "Rock_Shale"
    },
    {
      "x": -5,
      "y": 62,
      "z": 24,
      "name": "Rock_Shale"
    },
    {
      "x": -5,
      "y": 63,
      "z": 24,
      "name": "Soil_Dirt_Cold"
    },
    {
      "x": -5,
      "y": 64,
      "z": 24,
      "name": "Furniture_Village_Crate",
      "components": {
        "Components": {
          "container": {
            "Position": {
              "X": -7,
              "Y": 3,
              "Z": 3
            },
            "Custom": false,
            "AllowViewing": true,
            "ItemContainer": {
              "Capacity": 20,
              "Items": {
                "0": {
                  "Id": "Plant_Fruit_Berries_Red",
                  "Quantity": 1,
                  "Durability": 0.0,
                  "MaxDurability": 0.0,
                  "OverrideDroppedItemAnimation": false
                }
              }
            }
          }
        }
      }
    },
    {
      "x": -5,
      "y": 65,
      "z": 24,
      "name": "Furniture_Ancient_Barrel"
    },
    {
      "x": -5,
      "y": 66,
      "z": 24,
      "name": "Empty"
    },
    {
      "x": -5,
      "y": 67,
      "z": 24,
      "name": "Rock_Shale_Cobble"
    },
    {
      "x": -5,
      "y": 68,
      "z": 24,
      "name": "Empty"
    },
    {
      "x": -5,
      "y": 69,
      "z": 24,
      "name": "Empty"
    },
    {
      "x": -5,
      "y": 70,
      "z": 24,
      "name": "Empty"
    },
    {
      "x": -5,
      "y": 71,
      "z": 24,
      "name": "Empty"
    },
    {
      "x": -5,
      "y": 72,
      "z": 24,
      "name": "Empty"
    },
    {
      "x": -5,
      "y": 73,
      "z": 24,
      "name": "Empty"
    },
    {
      "x": -5,
      "y": 74,
      "z": 24,
      "name": "Empty"
    },
    {
      "x": -5,
      "y": 57,
      "z": 25,
      "name": "Rock_Shale"
    },
    {
      "x": -5,
      "y": 58,
      "z": 25,
      "name": "Rock_Shale"
    },
    {
      "x": -5,
      "y": 59,
      "z": 25,
      "name": "Rock_Shale"
    },
    {
      "x": -5,
      "y": 60,
      "z": 25,
      "name": "Rock_Shale"
    },
    {
      "x": -5,
      "y": 61,
      "z": 25,
      "name": "Rock_Basalt_Brick"
    },
    {
      "x": -5,
      "y": 62,
      "z": 25,
      "name": "Rock_Basalt_Brick"
    },
    {
      "x": -5,
      "y": 63,
      "z": 25,
      "name": "Rock_Basalt_Brick"
    },
    {
      "x": -5,
      "y": 64,
      "z": 25,
      "name": "Rock_Basalt_Brick"
    },
    {
      "x": -5,
      "y": 65,
      "z": 25,
      "name": "Rock_Shale_Brick"
    },
    {
      "x": -5,
      "y": 66,
      "z": 25,
      "name": "Rock_Shale_Brick"
    },
    {
      "x": -5,
      "y": 67,
      "z": 25,
      "name": "Rock_Shale_Brick"
    },
    {
      "x": -5,
      "y": 68,
      "z": 25,
      "name": "Rock_Shale_Cobble_Wall"
    },
    {
      "x": -5,
      "y": 69,
      "z": 25,
      "name": "Empty"
    },
    {
      "x": -5,
      "y": 70,
      "z": 25,
      "name": "Empty"
    },
    {
      "x": -5,
      "y": 71,
      "z": 25,
      "name": "Empty"
    },
    {
      "x": -5,
      "y": 72,
      "z": 25,
      "name": "Empty"
    },
    {
      "x": -5,
      "y": 73,
      "z": 25,
      "name": "Empty"
    },
    {
      "x": -5,
      "y": 74,
      "z": 25,
      "name": "Empty"
    },
    {
      "x": -4,
      "y": 64,
      "z": 14,
      "name": "Rock_Shale_Brick_Half",
      "rotation": 7
    },
    {
      "x": -4,
      "y": 65,
      "z": 14,
      "name": "*Rock_Shale_Cobble_Wall_State_Definitions_Corner",
      "rotation": 1
    },
    {
      "x": -4,
      "y": 66,
      "z": 14,
      "name": "Furniture_Human_Ruins_Torch",
      "rotation": 3
    },
    {
      "x": -4,
      "y": 67,
      "z": 14,
      "name": "Empty"
    },
    {
      "x": -4,
      "y": 68,
      "z": 14,
      "name": "Empty"
    },
    {
      "x": -4,
      "y": 69,
      "z": 14,
      "name": "Empty"
    },
    {
      "x": -4,
      "y": 70,
      "z": 14,
      "name": "Empty"
    },
    {
      "x": -4,
      "y": 63,
      "z": 15,
      "name": "Rock_Shale_Brick_Half",
      "rotation": 7
    },
    {
      "x": -4,
      "y": 64,
      "z": 15,
      "name": "Rock_Shale_Brick_Half",
      "rotation": 7
    },
    {
      "x": -4,
      "y": 65,
      "z": 15,
      "name": "Rock_Shale_Cobble_Wall",
      "rotation": 3
    },
    {
      "x": -4,
      "y": 66,
      "z": 15,
      "name": "Empty"
    },
    {
      "x": -4,
      "y": 67,
      "z": 15,
      "name": "Empty"
    },
    {
      "x": -4,
      "y": 68,
      "z": 15,
      "name": "Empty"
    },
    {
      "x": -4,
      "y": 69,
      "z": 15,
      "name": "Empty"
    },
    {
      "x": -4,
      "y": 70,
      "z": 15,
      "name": "Empty"
    },
    {
      "x": -4,
      "y": 63,
      "z": 16,
      "name": "Rock_Shale_Brick"
    },
    {
      "x": -4,
      "y": 64,
      "z": 16,
      "name": "Rock_Shale_Brick"
    },
    {
      "x": -4,
      "y": 65,
      "z": 16,
      "name": "Rock_Shale_Cobble_Wall",
      "rotation": 3
    },
    {
      "x": -4,
      "y": 66,
      "z": 16,
      "name": "Empty"
    },
    {
      "x": -4,
      "y": 67,
      "z": 16,
      "name": "Empty"
    },
    {
      "x": -4,
      "y": 68,
      "z": 16,
      "name": "Empty"
    },
    {
      "x": -4,
      "y": 69,
      "z": 16,
      "name": "Empty"
    },
    {
      "x": -4,
      "y": 70,
      "z": 16,
      "name": "Empty"
    },
    {
      "x": -4,
      "y": 71,
      "z": 16,
      "name": "Empty"
    },
    {
      "x": -4,
      "y": 72,
      "z": 16,
      "name": "Empty"
    },
    {
      "x": -4,
      "y": 62,
      "z": 17,
      "name": "Rock_Shale_Brick"
    },
    {
      "x": -4,
      "y": 63,
      "z": 17,
      "name": "Rock_Shale_Brick"
    },
    {
      "x": -4,
      "y": 64,
      "z": 17,
      "name": "Rock_Shale_Brick"
    },
    {
      "x": -4,
      "y": 65,
      "z": 17,
      "name": "Rock_Shale_Cobble_Wall",
      "rotation": 3
    },
    {
      "x": -4,
      "y": 66,
      "z": 17,
      "name": "Empty"
    },
    {
      "x": -4,
      "y": 67,
      "z": 17,
      "name": "Empty"
    },
    {
      "x": -4,
      "y": 68,
      "z": 17,
      "name": "Empty"
    },
    {
      "x": -4,
      "y": 69,
      "z": 17,
      "name": "Empty"
    },
    {
      "x": -4,
      "y": 70,
      "z": 17,
      "name": "Empty"
    },
    {
      "x": -4,
      "y": 71,
      "z": 17,
      "name": "Empty"
    },
    {
      "x": -4,
      "y": 72,
      "z": 17,
      "name": "Empty"
    },
    {
      "x": -4,
      "y": 56,
      "z": 18,
      "name": "Rock_Shale"
    },
    {
      "x": -4,
      "y": 57,
      "z": 18,
      "name": "Rock_Shale"
    },
    {
      "x": -4,
      "y": 58,
      "z": 18,
      "name": "Rock_Shale"
    },
    {
      "x": -4,
      "y": 59,
      "z": 18,
      "name": "Rock_Shale"
    },
    {
      "x": -4,
      "y": 60,
      "z": 18,
      "name": "Rock_Shale"
    },
    {
      "x": -4,
      "y": 61,
      "z": 18,
      "name": "Rock_Shale"
    },
    {
      "x": -4,
      "y": 62,
      "z": 18,
      "name": "Rock_Shale"
    },
    {
      "x": -4,
      "y": 63,
      "z": 18,
      "name": "Rock_Shale_Cobble"
    },
    {
      "x": -4,
      "y": 64,
      "z": 18,
      "name": "Rock_Shale_Cobble_Stairs",
      "rotation": 3
    },
    {
      "x": -4,
      "y": 65,
      "z": 18,
      "name": "Empty"
    },
    {
      "x": -4,
      "y": 66,
      "z": 18,
      "name": "Empty"
    },
    {
      "x": -4,
      "y": 67,
      "z": 18,
      "name": "Empty"
    },
    {
      "x": -4,
      "y": 68,
      "z": 18,
      "name": "Empty"
    },
    {
      "x": -4,
      "y": 69,
      "z": 18,
      "name": "Empty"
    },
    {
      "x": -4,
      "y": 70,
      "z": 18,
      "name": "Empty"
    },
    {
      "x": -4,
      "y": 71,
      "z": 18,
      "name": "Empty"
    },
    {
      "x": -4,
      "y": 72,
      "z": 18,
      "name": "Empty"
    },
    {
      "x": -4,
      "y": 55,
      "z": 19,
      "name": "Rock_Shale"
    },
    {
      "x": -4,
      "y": 56,
      "z": 19,
      "name": "Rock_Shale"
    },
    {
      "x": -4,
      "y": 57,
      "z": 19,
      "name": "Rock_Shale"
    },
    {
      "x": -4,
      "y": 58,
      "z": 19,
      "name": "Rock_Shale"
    },
    {
      "x": -4,
      "y": 59,
      "z": 19,
      "name": "Rock_Shale"
    },
    {
      "x": -4,
      "y": 60,
      "z": 19,
      "name": "Rock_Shale"
    },
    {
      "x": -4,
      "y": 61,
      "z": 19,
      "name": "Rock_Shale"
    },
    {
      "x": -4,
      "y": 62,
      "z": 19,
      "name": "Rock_Shale"
    },
    {
      "x": -4,
      "y": 63,
      "z": 19,
      "name": "Rock_Shale_Cobble"
    },
    {
      "x": -4,
      "y": 64,
      "z": 19,
      "name": "Rock_Shale_Cobble_Stairs",
      "rotation": 3
    },
    {
      "x": -4,
      "y": 65,
      "z": 19,
      "name": "Empty"
    },
    {
      "x": -4,
      "y": 66,
      "z": 19,
      "name": "Empty"
    },
    {
      "x": -4,
      "y": 67,
      "z": 19,
      "name": "Empty"
    },
    {
      "x": -4,
      "y": 68,
      "z": 19,
      "name": "Empty"
    },
    {
      "x": -4,
      "y": 69,
      "z": 19,
      "name": "Empty"
    },
    {
      "x": -4,
      "y": 70,
      "z": 19,
      "name": "Empty"
    },
    {
      "x": -4,
      "y": 71,
      "z": 19,
      "name": "Empty"
    },
    {
      "x": -4,
      "y": 72,
      "z": 19,
      "name": "Empty"
    },
    {
      "x": -4,
      "y": 55,
      "z": 20,
      "name": "Rock_Shale"
    },
    {
      "x": -4,
      "y": 56,
      "z": 20,
      "name": "Rock_Shale"
    },
    {
      "x": -4,
      "y": 57,
      "z": 20,
      "name": "Rock_Shale"
    },
    {
      "x": -4,
      "y": 58,
      "z": 20,
      "name": "Rock_Shale"
    },
    {
      "x": -4,
      "y": 59,
      "z": 20,
      "name": "Rock_Shale"
    },
    {
      "x": -4,
      "y": 60,
      "z": 20,
      "name": "Rock_Shale"
    },
    {
      "x": -4,
      "y": 61,
      "z": 20,
      "name": "Rock_Shale"
    },
    {
      "x": -4,
      "y": 62,
      "z": 20,
      "name": "Rock_Shale"
    },
    {
      "x": -4,
      "y": 63,
      "z": 20,
      "name": "Rock_Basalt_Brick"
    },
    {
      "x": -4,
      "y": 64,
      "z": 20,
      "name": "Rock_Basalt_Brick"
    },
    {
      "x": -4,
      "y": 65,
      "z": 20,
      "name": "Rock_Shale_Brick"
    },
    {
      "x": -4,
      "y": 66,
      "z": 20,
      "name": "Rock_Shale_Brick"
    },
    {
      "x": -4,
      "y": 67,
      "z": 20,
      "name": "Rock_Shale_Brick"
    },
    {
      "x": -4,
      "y": 68,
      "z": 20,
      "name": "Rock_Shale_Cobble_Wall",
      "rotation": 2
    },
    {
      "x": -4,
      "y": 69,
      "z": 20,
      "name": "Empty"
    },
    {
      "x": -4,
      "y": 70,
      "z": 20,
      "name": "Empty"
    },
    {
      "x": -4,
      "y": 71,
      "z": 20,
      "name": "Empty"
    },
    {
      "x": -4,
      "y": 72,
      "z": 20,
      "name": "Empty"
    },
    {
      "x": -4,
      "y": 73,
      "z": 20,
      "name": "Empty"
    },
    {
      "x": -4,
      "y": 74,
      "z": 20,
      "name": "Empty"
    },
    {
      "x": -4,
      "y": 55,
      "z": 21,
      "name": "Rock_Shale"
    },
    {
      "x": -4,
      "y": 56,
      "z": 21,
      "name": "Rock_Shale"
    },
    {
      "x": -4,
      "y": 57,
      "z": 21,
      "name": "Rock_Shale"
    },
    {
      "x": -4,
      "y": 58,
      "z": 21,
      "name": "Rock_Shale"
    },
    {
      "x": -4,
      "y": 59,
      "z": 21,
      "name": "Rock_Shale"
    },
    {
      "x": -4,
      "y": 60,
      "z": 21,
      "name": "Rock_Shale"
    },
    {
      "x": -4,
      "y": 61,
      "z": 21,
      "name": "Rock_Shale"
    },
    {
      "x": -4,
      "y": 62,
      "z": 21,
      "name": "Rock_Shale"
    },
    {
      "x": -4,
      "y": 63,
      "z": 21,
      "name": "Soil_Dirt_Cold"
    },
    {
      "x": -4,
      "y": 64,
      "z": 21,
      "name": "Furniture_Lumberjack_Platform"
    },
    {
      "x": -4,
      "y": 65,
      "z": 21,
      "name": "Empty"
    },
    {
      "x": -4,
      "y": 66,
      "z": 21,
      "name": "Empty"
    },
    {
      "x": -4,
      "y": 67,
      "z": 21,
      "name": "Rock_Shale_Cobble"
    },
    {
      "x": -4,
      "y": 68,
      "z": 21,
      "name": "Empty"
    },
    {
      "x": -4,
      "y": 69,
      "z": 21,
      "name": "Empty"
    },
    {
      "x": -4,
      "y": 70,
      "z": 21,
      "name": "Empty"
    },
    {
      "x": -4,
      "y": 71,
      "z": 21,
      "name": "Empty"
    },
    {
      "x": -4,
      "y": 72,
      "z": 21,
      "name": "Empty"
    },
    {
      "x": -4,
      "y": 73,
      "z": 21,
      "name": "Empty"
    },
    {
      "x": -4,
      "y": 74,
      "z": 21,
      "name": "Empty"
    },
    {
      "x": -4,
      "y": 55,
      "z": 22,
      "name": "Rock_Shale"
    },
    {
      "x": -4,
      "y": 56,
      "z": 22,
      "name": "Rock_Shale"
    },
    {
      "x": -4,
      "y": 57,
      "z": 22,
      "name": "Rock_Shale"
    },
    {
      "x": -4,
      "y": 58,
      "z": 22,
      "name": "Rock_Shale"
    },
    {
      "x": -4,
      "y": 59,
      "z": 22,
      "name": "Rock_Shale"
    },
    {
      "x": -4,
      "y": 60,
      "z": 22,
      "name": "Rock_Shale"
    },
    {
      "x": -4,
      "y": 61,
      "z": 22,
      "name": "Rock_Shale"
    },
    {
      "x": -4,
      "y": 62,
      "z": 22,
      "name": "Rock_Shale"
    },
    {
      "x": -4,
      "y": 63,
      "z": 22,
      "name": "Soil_Dirt_Cold"
    },
    {
      "x": -4,
      "y": 64,
      "z": 22,
      "name": "Empty"
    },
    {
      "x": -4,
      "y": 65,
      "z": 22,
      "name": "Empty"
    },
    {
      "x": -4,
      "y": 66,
      "z": 22,
      "name": "Empty"
    },
    {
      "x": -4,
      "y": 67,
      "z": 22,
      "name": "Rock_Shale_Cobble"
    },
    {
      "x": -4,
      "y": 68,
      "z": 22,
      "name": "Empty"
    },
    {
      "x": -4,
      "y": 69,
      "z": 22,
      "name": "Empty"
    },
    {
      "x": -4,
      "y": 70,
      "z": 22,
      "name": "Empty"
    },
    {
      "x": -4,
      "y": 71,
      "z": 22,
      "name": "Empty"
    },
    {
      "x": -4,
      "y": 72,
      "z": 22,
      "name": "Empty"
    },
    {
      "x": -4,
      "y": 73,
      "z": 22,
      "name": "Empty"
    },
    {
      "x": -4,
      "y": 74,
      "z": 22,
      "name": "Empty"
    },
    {
      "x": -4,
      "y": 55,
      "z": 23,
      "name": "Rock_Shale"
    },
    {
      "x": -4,
      "y": 56,
      "z": 23,
      "name": "Rock_Shale"
    },
    {
      "x": -4,
      "y": 57,
      "z": 23,
      "name": "Rock_Shale"
    },
    {
      "x": -4,
      "y": 58,
      "z": 23,
      "name": "Rock_Shale"
    },
    {
      "x": -4,
      "y": 59,
      "z": 23,
      "name": "Rock_Shale"
    },
    {
      "x": -4,
      "y": 60,
      "z": 23,
      "name": "Rock_Shale"
    },
    {
      "x": -4,
      "y": 61,
      "z": 23,
      "name": "Rock_Shale"
    },
    {
      "x": -4,
      "y": 62,
      "z": 23,
      "name": "Rock_Shale"
    },
    {
      "x": -4,
      "y": 63,
      "z": 23,
      "name": "Soil_Dirt_Cold"
    },
    {
      "x": -4,
      "y": 64,
      "z": 23,
      "name": "Empty"
    },
    {
      "x": -4,
      "y": 65,
      "z": 23,
      "name": "Empty"
    },
    {
      "x": -4,
      "y": 66,
      "z": 23,
      "name": "Empty"
    },
    {
      "x": -4,
      "y": 67,
      "z": 23,
      "name": "Rock_Shale_Cobble"
    },
    {
      "x": -4,
      "y": 68,
      "z": 23,
      "name": "Empty"
    },
    {
      "x": -4,
      "y": 69,
      "z": 23,
      "name": "Empty"
    },
    {
      "x": -4,
      "y": 70,
      "z": 23,
      "name": "Empty"
    },
    {
      "x": -4,
      "y": 71,
      "z": 23,
      "name": "Empty"
    },
    {
      "x": -4,
      "y": 72,
      "z": 23,
      "name": "Empty"
    },
    {
      "x": -4,
      "y": 73,
      "z": 23,
      "name": "Empty"
    },
    {
      "x": -4,
      "y": 74,
      "z": 23,
      "name": "Empty"
    },
    {
      "x": -4,
      "y": 55,
      "z": 24,
      "name": "Rock_Shale"
    },
    {
      "x": -4,
      "y": 56,
      "z": 24,
      "name": "Rock_Shale"
    },
    {
      "x": -4,
      "y": 57,
      "z": 24,
      "name": "Rock_Shale"
    },
    {
      "x": -4,
      "y": 58,
      "z": 24,
      "name": "Rock_Shale"
    },
    {
      "x": -4,
      "y": 59,
      "z": 24,
      "name": "Rock_Shale"
    },
    {
      "x": -4,
      "y": 60,
      "z": 24,
      "name": "Rock_Shale"
    },
    {
      "x": -4,
      "y": 61,
      "z": 24,
      "name": "Rock_Shale"
    },
    {
      "x": -4,
      "y": 62,
      "z": 24,
      "name": "Rock_Shale"
    },
    {
      "x": -4,
      "y": 63,
      "z": 24,
      "name": "Soil_Dirt_Cold"
    },
    {
      "x": -4,
      "y": 64,
      "z": 24,
      "name": "Empty"
    },
    {
      "x": -4,
      "y": 65,
      "z": 24,
      "name": "Empty"
    },
    {
      "x": -4,
      "y": 66,
      "z": 24,
      "name": "Empty"
    },
    {
      "x": -4,
      "y": 67,
      "z": 24,
      "name": "Rock_Shale_Cobble"
    },
    {
      "x": -4,
      "y": 68,
      "z": 24,
      "name": "Empty"
    },
    {
      "x": -4,
      "y": 69,
      "z": 24,
      "name": "Empty"
    },
    {
      "x": -4,
      "y": 70,
      "z": 24,
      "name": "Empty"
    },
    {
      "x": -4,
      "y": 71,
      "z": 24,
      "name": "Empty"
    },
    {
      "x": -4,
      "y": 72,
      "z": 24,
      "name": "Empty"
    },
    {
      "x": -4,
      "y": 73,
      "z": 24,
      "name": "Empty"
    },
    {
      "x": -4,
      "y": 74,
      "z": 24,
      "name": "Empty"
    },
    {
      "x": -4,
      "y": 56,
      "z": 25,
      "name": "Rock_Shale"
    },
    {
      "x": -4,
      "y": 57,
      "z": 25,
      "name": "Rock_Shale"
    },
    {
      "x": -4,
      "y": 58,
      "z": 25,
      "name": "Rock_Shale"
    },
    {
      "x": -4,
      "y": 59,
      "z": 25,
      "name": "Rock_Shale"
    },
    {
      "x": -4,
      "y": 60,
      "z": 25,
      "name": "Rock_Shale"
    },
    {
      "x": -4,
      "y": 61,
      "z": 25,
      "name": "Rock_Shale"
    },
    {
      "x": -4,
      "y": 62,
      "z": 25,
      "name": "Rock_Basalt_Brick"
    },
    {
      "x": -4,
      "y": 63,
      "z": 25,
      "name": "Rock_Basalt_Brick"
    },
    {
      "x": -4,
      "y": 64,
      "z": 25,
      "name": "Rock_Basalt_Brick"
    },
    {
      "x": -4,
      "y": 65,
      "z": 25,
      "name": "Rock_Shale_Brick"
    },
    {
      "x": -4,
      "y": 66,
      "z": 25,
      "name": "Rock_Shale_Brick"
    },
    {
      "x": -4,
      "y": 67,
      "z": 25,
      "name": "Rock_Shale_Brick"
    },
    {
      "x": -4,
      "y": 68,
      "z": 25,
      "name": "Rock_Shale_Cobble_Wall"
    },
    {
      "x": -4,
      "y": 69,
      "z": 25,
      "name": "Empty"
    },
    {
      "x": -4,
      "y": 70,
      "z": 25,
      "name": "Empty"
    },
    {
      "x": -4,
      "y": 71,
      "z": 25,
      "name": "Empty"
    },
    {
      "x": -4,
      "y": 72,
      "z": 25,
      "name": "Empty"
    },
    {
      "x": -4,
      "y": 73,
      "z": 25,
      "name": "Empty"
    },
    {
      "x": -4,
      "y": 74,
      "z": 25,
      "name": "Empty"
    },
    {
      "x": -4,
      "y": 63,
      "z": 26,
      "name": "Rock_Shale_Cobble_Half",
      "rotation": 7
    },
    {
      "x": -4,
      "y": 64,
      "z": 26,
      "name": "Rock_Shale_Cobble"
    },
    {
      "x": -4,
      "y": 65,
      "z": 26,
      "name": "Rock_Shale_Brick"
    },
    {
      "x": -4,
      "y": 66,
      "z": 26,
      "name": "Rock_Shale_Brick"
    },
    {
      "x": -4,
      "y": 67,
      "z": 26,
      "name": "Rock_Shale_Cobble_Wall",
      "rotation": 3
    },
    {
      "x": -4,
      "y": 68,
      "z": 26,
      "name": "Empty"
    },
    {
      "x": -4,
      "y": 69,
      "z": 26,
      "name": "Empty"
    },
    {
      "x": -4,
      "y": 70,
      "z": 26,
      "name": "Empty"
    },
    {
      "x": -4,
      "y": 71,
      "z": 26,
      "name": "Empty"
    },
    {
      "x": -4,
      "y": 72,
      "z": 26,
      "name": "Empty"
    },
    {
      "x": -4,
      "y": 63,
      "z": 27,
      "name": "Rock_Shale_Cobble_Half",
      "rotation": 7
    },
    {
      "x": -4,
      "y": 64,
      "z": 27,
      "name": "Rock_Shale_Cobble"
    },
    {
      "x": -4,
      "y": 65,
      "z": 27,
      "name": "Rock_Shale_Brick"
    },
    {
      "x": -4,
      "y": 66,
      "z": 27,
      "name": "Rock_Shale_Brick"
    },
    {
      "x": -4,
      "y": 67,
      "z": 27,
      "name": "Rock_Shale_Cobble_Wall",
      "rotation": 3
    },
    {
      "x": -4,
      "y": 68,
      "z": 27,
      "name": "Empty"
    },
    {
      "x": -4,
      "y": 69,
      "z": 27,
      "name": "Empty"
    },
    {
      "x": -4,
      "y": 70,
      "z": 27,
      "name": "Empty"
    },
    {
      "x": -4,
      "y": 71,
      "z": 27,
      "name": "Empty"
    },
    {
      "x": -4,
      "y": 72,
      "z": 27,
      "name": "Empty"
    },
    {
      "x": -4,
      "y": 65,
      "z": 28,
      "name": "Rock_Shale_Brick_Half",
      "rotation": 7
    },
    {
      "x": -4,
      "y": 66,
      "z": 28,
      "name": "Rock_Shale_Brick_Half",
      "rotation": 7
    },
    {
      "x": -4,
      "y": 67,
      "z": 28,
      "name": "*Rock_Shale_Cobble_Wall_State_Definitions_Corner",
      "rotation": 2
    },
    {
      "x": -4,
      "y": 68,
      "z": 28,
      "name": "Empty"
    },
    {
      "x": -4,
      "y": 69,
      "z": 28,
      "name": "Empty"
    },
    {
      "x": -4,
      "y": 70,
      "z": 28,
      "name": "Empty"
    },
    {
      "x": -4,
      "y": 71,
      "z": 28,
      "name": "Empty"
    },
    {
      "x": -4,
      "y": 72,
      "z": 28,
      "name": "Empty"
    },
    {
      "x": -3,
      "y": 62,
      "z": 14,
      "name": "Rock_Shale_Brick"
    },
    {
      "x": -3,
      "y": 63,
      "z": 14,
      "name": "Rock_Shale_Brick"
    },
    {
      "x": -3,
      "y": 64,
      "z": 14,
      "name": "Rock_Shale_Brick"
    },
    {
      "x": -3,
      "y": 65,
      "z": 14,
      "name": "Rock_Shale_Cobble_Wall",
      "rotation": 2
    },
    {
      "x": -3,
      "y": 66,
      "z": 14,
      "name": "Empty"
    },
    {
      "x": -3,
      "y": 67,
      "z": 14,
      "name": "Empty"
    },
    {
      "x": -3,
      "y": 68,
      "z": 14,
      "name": "Empty"
    },
    {
      "x": -3,
      "y": 69,
      "z": 14,
      "name": "Empty"
    },
    {
      "x": -3,
      "y": 70,
      "z": 14,
      "name": "Empty"
    },
    {
      "x": -3,
      "y": 71,
      "z": 14,
      "name": "Empty"
    },
    {
      "x": -3,
      "y": 59,
      "z": 15,
      "name": "Rock_Shale"
    },
    {
      "x": -3,
      "y": 60,
      "z": 15,
      "name": "Rock_Shale"
    },
    {
      "x": -3,
      "y": 61,
      "z": 15,
      "name": "Rock_Shale_Cobble"
    },
    {
      "x": -3,
      "y": 62,
      "z": 15,
      "name": "Rock_Shale_Cobble"
    },
    {
      "x": -3,
      "y": 63,
      "z": 15,
      "name": "Rock_Shale_Brick"
    },
    {
      "x": -3,
      "y": 64,
      "z": 15,
      "name": "Soil_Dirt_Cold"
    },
    {
      "x": -3,
      "y": 65,
      "z": 15,
      "name": "Empty"
    },
    {
      "x": -3,
      "y": 66,
      "z": 15,
      "name": "Empty"
    },
    {
      "x": -3,
      "y": 67,
      "z": 15,
      "name": "Empty"
    },
    {
      "x": -3,
      "y": 68,
      "z": 15,
      "name": "Empty"
    },
    {
      "x": -3,
      "y": 69,
      "z": 15,
      "name": "Empty"
    },
    {
      "x": -3,
      "y": 70,
      "z": 15,
      "name": "Empty"
    },
    {
      "x": -3,
      "y": 71,
      "z": 15,
      "name": "Empty"
    },
    {
      "x": -3,
      "y": 55,
      "z": 16,
      "name": "Rock_Shale"
    },
    {
      "x": -3,
      "y": 56,
      "z": 16,
      "name": "Rock_Shale"
    },
    {
      "x": -3,
      "y": 57,
      "z": 16,
      "name": "Rock_Shale"
    },
    {
      "x": -3,
      "y": 58,
      "z": 16,
      "name": "Rock_Shale"
    },
    {
      "x": -3,
      "y": 59,
      "z": 16,
      "name": "Rock_Shale"
    },
    {
      "x": -3,
      "y": 60,
      "z": 16,
      "name": "Rock_Shale"
    },
    {
      "x": -3,
      "y": 61,
      "z": 16,
      "name": "Rock_Shale_Cobble"
    },
    {
      "x": -3,
      "y": 62,
      "z": 16,
      "name": "Rock_Shale_Cobble"
    },
    {
      "x": -3,
      "y": 63,
      "z": 16,
      "name": "Rock_Shale_Brick"
    },
    {
      "x": -3,
      "y": 64,
      "z": 16,
      "name": "Soil_Dirt_Cold"
    },
    {
      "x": -3,
      "y": 65,
      "z": 16,
      "name": "Empty"
    },
    {
      "x": -3,
      "y": 66,
      "z": 16,
      "name": "Empty"
    },
    {
      "x": -3,
      "y": 67,
      "z": 16,
      "name": "Empty"
    },
    {
      "x": -3,
      "y": 68,
      "z": 16,
      "name": "Empty"
    },
    {
      "x": -3,
      "y": 69,
      "z": 16,
      "name": "Empty"
    },
    {
      "x": -3,
      "y": 70,
      "z": 16,
      "name": "Empty"
    },
    {
      "x": -3,
      "y": 71,
      "z": 16,
      "name": "Empty"
    },
    {
      "x": -3,
      "y": 72,
      "z": 16,
      "name": "Empty"
    },
    {
      "x": -3,
      "y": 55,
      "z": 17,
      "name": "Rock_Shale"
    },
    {
      "x": -3,
      "y": 56,
      "z": 17,
      "name": "Rock_Shale"
    },
    {
      "x": -3,
      "y": 57,
      "z": 17,
      "name": "Rock_Shale"
    },
    {
      "x": -3,
      "y": 58,
      "z": 17,
      "name": "Rock_Shale"
    },
    {
      "x": -3,
      "y": 59,
      "z": 17,
      "name": "Rock_Shale"
    },
    {
      "x": -3,
      "y": 60,
      "z": 17,
      "name": "Rock_Shale"
    },
    {
      "x": -3,
      "y": 61,
      "z": 17,
      "name": "Rock_Shale"
    },
    {
      "x": -3,
      "y": 62,
      "z": 17,
      "name": "Rock_Shale_Cobble"
    },
    {
      "x": -3,
      "y": 63,
      "z": 17,
      "name": "Rock_Shale_Cobble"
    },
    {
      "x": -3,
      "y": 64,
      "z": 17,
      "name": "Soil_Dirt_Cold"
    },
    {
      "x": -3,
      "y": 65,
      "z": 17,
      "name": "Empty"
    },
    {
      "x": -3,
      "y": 66,
      "z": 17,
      "name": "Empty"
    },
    {
      "x": -3,
      "y": 67,
      "z": 17,
      "name": "Empty"
    },
    {
      "x": -3,
      "y": 68,
      "z": 17,
      "name": "Empty"
    },
    {
      "x": -3,
      "y": 69,
      "z": 17,
      "name": "Empty"
    },
    {
      "x": -3,
      "y": 70,
      "z": 17,
      "name": "Empty"
    },
    {
      "x": -3,
      "y": 71,
      "z": 17,
      "name": "Empty"
    },
    {
      "x": -3,
      "y": 72,
      "z": 17,
      "name": "Empty"
    },
    {
      "x": -3,
      "y": 54,
      "z": 18,
      "name": "Rock_Shale"
    },
    {
      "x": -3,
      "y": 55,
      "z": 18,
      "name": "Rock_Shale"
    },
    {
      "x": -3,
      "y": 56,
      "z": 18,
      "name": "Rock_Shale"
    },
    {
      "x": -3,
      "y": 57,
      "z": 18,
      "name": "Rock_Shale"
    },
    {
      "x": -3,
      "y": 58,
      "z": 18,
      "name": "Rock_Shale"
    },
    {
      "x": -3,
      "y": 59,
      "z": 18,
      "name": "Rock_Shale"
    },
    {
      "x": -3,
      "y": 60,
      "z": 18,
      "name": "Rock_Shale"
    },
    {
      "x": -3,
      "y": 61,
      "z": 18,
      "name": "Rock_Shale"
    },
    {
      "x": -3,
      "y": 62,
      "z": 18,
      "name": "Rock_Shale"
    },
    {
      "x": -3,
      "y": 63,
      "z": 18,
      "name": "Rock_Shale_Cobble"
    },
    {
      "x": -3,
      "y": 64,
      "z": 18,
      "name": "Soil_Dirt_Cold"
    },
    {
      "x": -3,
      "y": 65,
      "z": 18,
      "name": "Empty"
    },
    {
      "x": -3,
      "y": 66,
      "z": 18,
      "name": "Empty"
    },
    {
      "x": -3,
      "y": 67,
      "z": 18,
      "name": "Empty"
    },
    {
      "x": -3,
      "y": 68,
      "z": 18,
      "name": "Empty"
    },
    {
      "x": -3,
      "y": 69,
      "z": 18,
      "name": "Empty"
    },
    {
      "x": -3,
      "y": 70,
      "z": 18,
      "name": "Empty"
    },
    {
      "x": -3,
      "y": 71,
      "z": 18,
      "name": "Empty"
    },
    {
      "x": -3,
      "y": 72,
      "z": 18,
      "name": "Empty"
    },
    {
      "x": -3,
      "y": 54,
      "z": 19,
      "name": "Rock_Shale"
    },
    {
      "x": -3,
      "y": 55,
      "z": 19,
      "name": "Rock_Shale"
    },
    {
      "x": -3,
      "y": 56,
      "z": 19,
      "name": "Rock_Shale"
    },
    {
      "x": -3,
      "y": 57,
      "z": 19,
      "name": "Rock_Shale"
    },
    {
      "x": -3,
      "y": 58,
      "z": 19,
      "name": "Rock_Shale"
    },
    {
      "x": -3,
      "y": 59,
      "z": 19,
      "name": "Rock_Shale"
    },
    {
      "x": -3,
      "y": 60,
      "z": 19,
      "name": "Rock_Shale"
    },
    {
      "x": -3,
      "y": 61,
      "z": 19,
      "name": "Rock_Shale"
    },
    {
      "x": -3,
      "y": 62,
      "z": 19,
      "name": "Rock_Shale"
    },
    {
      "x": -3,
      "y": 63,
      "z": 19,
      "name": "Rock_Shale_Cobble"
    },
    {
      "x": -3,
      "y": 64,
      "z": 19,
      "name": "Soil_Dirt_Cold"
    },
    {
      "x": -3,
      "y": 65,
      "z": 19,
      "name": "Empty"
    },
    {
      "x": -3,
      "y": 66,
      "z": 19,
      "name": "Empty"
    },
    {
      "x": -3,
      "y": 67,
      "z": 19,
      "name": "Empty"
    },
    {
      "x": -3,
      "y": 68,
      "z": 19,
      "name": "Empty"
    },
    {
      "x": -3,
      "y": 69,
      "z": 19,
      "name": "Empty"
    },
    {
      "x": -3,
      "y": 70,
      "z": 19,
      "name": "Empty"
    },
    {
      "x": -3,
      "y": 71,
      "z": 19,
      "name": "Empty"
    },
    {
      "x": -3,
      "y": 72,
      "z": 19,
      "name": "Empty"
    },
    {
      "x": -3,
      "y": 54,
      "z": 20,
      "name": "Rock_Shale"
    },
    {
      "x": -3,
      "y": 55,
      "z": 20,
      "name": "Rock_Shale"
    },
    {
      "x": -3,
      "y": 56,
      "z": 20,
      "name": "Rock_Shale"
    },
    {
      "x": -3,
      "y": 57,
      "z": 20,
      "name": "Rock_Shale"
    },
    {
      "x": -3,
      "y": 58,
      "z": 20,
      "name": "Rock_Shale"
    },
    {
      "x": -3,
      "y": 59,
      "z": 20,
      "name": "Rock_Shale"
    },
    {
      "x": -3,
      "y": 60,
      "z": 20,
      "name": "Rock_Shale"
    },
    {
      "x": -3,
      "y": 61,
      "z": 20,
      "name": "Rock_Shale"
    },
    {
      "x": -3,
      "y": 62,
      "z": 20,
      "name": "Rock_Shale"
    },
    {
      "x": -3,
      "y": 63,
      "z": 20,
      "name": "Rock_Basalt_Brick"
    },
    {
      "x": -3,
      "y": 64,
      "z": 20,
      "name": "Rock_Basalt_Brick"
    },
    {
      "x": -3,
      "y": 65,
      "z": 20,
      "name": "Rock_Shale_Brick"
    },
    {
      "x": -3,
      "y": 66,
      "z": 20,
      "name": "Rock_Shale_Brick"
    },
    {
      "x": -3,
      "y": 67,
      "z": 20,
      "name": "Rock_Shale_Brick"
    },
    {
      "x": -3,
      "y": 68,
      "z": 20,
      "name": "Rock_Shale_Cobble_Wall",
      "rotation": 2
    },
    {
      "x": -3,
      "y": 69,
      "z": 20,
      "name": "Empty"
    },
    {
      "x": -3,
      "y": 70,
      "z": 20,
      "name": "Empty"
    },
    {
      "x": -3,
      "y": 71,
      "z": 20,
      "name": "Empty"
    },
    {
      "x": -3,
      "y": 72,
      "z": 20,
      "name": "Empty"
    },
    {
      "x": -3,
      "y": 73,
      "z": 20,
      "name": "Empty"
    },
    {
      "x": -3,
      "y": 74,
      "z": 20,
      "name": "Empty"
    },
    {
      "x": -3,
      "y": 54,
      "z": 21,
      "name": "Rock_Shale"
    },
    {
      "x": -3,
      "y": 55,
      "z": 21,
      "name": "Rock_Shale"
    },
    {
      "x": -3,
      "y": 56,
      "z": 21,
      "name": "Rock_Shale"
    },
    {
      "x": -3,
      "y": 57,
      "z": 21,
      "name": "Rock_Shale"
    },
    {
      "x": -3,
      "y": 58,
      "z": 21,
      "name": "Rock_Shale"
    },
    {
      "x": -3,
      "y": 59,
      "z": 21,
      "name": "Rock_Shale"
    },
    {
      "x": -3,
      "y": 60,
      "z": 21,
      "name": "Rock_Shale"
    },
    {
      "x": -3,
      "y": 61,
      "z": 21,
      "name": "Rock_Shale"
    },
    {
      "x": -3,
      "y": 62,
      "z": 21,
      "name": "Rock_Shale"
    },
    {
      "x": -3,
      "y": 63,
      "z": 21,
      "name": "Soil_Dirt_Cold"
    },
    {
      "x": -3,
      "y": 64,
      "z": 21,
      "name": "Furniture_Lumberjack_Platform"
    },
    {
      "x": -3,
      "y": 65,
      "z": 21,
      "name": "Furniture_Lumberjack_Lantern"
    },
    {
      "x": -3,
      "y": 66,
      "z": 21,
      "name": "Empty"
    },
    {
      "x": -3,
      "y": 67,
      "z": 21,
      "name": "Rock_Shale_Cobble"
    },
    {
      "x": -3,
      "y": 68,
      "z": 21,
      "name": "Empty"
    },
    {
      "x": -3,
      "y": 69,
      "z": 21,
      "name": "Empty"
    },
    {
      "x": -3,
      "y": 70,
      "z": 21,
      "name": "Empty"
    },
    {
      "x": -3,
      "y": 71,
      "z": 21,
      "name": "Empty"
    },
    {
      "x": -3,
      "y": 72,
      "z": 21,
      "name": "Empty"
    },
    {
      "x": -3,
      "y": 73,
      "z": 21,
      "name": "Empty"
    },
    {
      "x": -3,
      "y": 74,
      "z": 21,
      "name": "Empty"
    },
    {
      "x": -3,
      "y": 54,
      "z": 22,
      "name": "Rock_Shale"
    },
    {
      "x": -3,
      "y": 55,
      "z": 22,
      "name": "Rock_Shale"
    },
    {
      "x": -3,
      "y": 56,
      "z": 22,
      "name": "Rock_Shale"
    },
    {
      "x": -3,
      "y": 57,
      "z": 22,
      "name": "Rock_Shale"
    },
    {
      "x": -3,
      "y": 58,
      "z": 22,
      "name": "Rock_Shale"
    },
    {
      "x": -3,
      "y": 59,
      "z": 22,
      "name": "Rock_Shale"
    },
    {
      "x": -3,
      "y": 60,
      "z": 22,
      "name": "Rock_Shale"
    },
    {
      "x": -3,
      "y": 61,
      "z": 22,
      "name": "Rock_Shale"
    },
    {
      "x": -3,
      "y": 62,
      "z": 22,
      "name": "Rock_Shale"
    },
    {
      "x": -3,
      "y": 63,
      "z": 22,
      "name": "Soil_Dirt_Cold"
    },
    {
      "x": -3,
      "y": 64,
      "z": 22,
      "name": "Empty"
    },
    {
      "x": -3,
      "y": 65,
      "z": 22,
      "name": "Empty"
    },
    {
      "x": -3,
      "y": 66,
      "z": 22,
      "name": "Empty"
    },
    {
      "x": -3,
      "y": 67,
      "z": 22,
      "name": "Rock_Shale_Cobble"
    },
    {
      "x": -3,
      "y": 68,
      "z": 22,
      "name": "Empty"
    },
    {
      "x": -3,
      "y": 69,
      "z": 22,
      "name": "Empty"
    },
    {
      "x": -3,
      "y": 70,
      "z": 22,
      "name": "Empty"
    },
    {
      "x": -3,
      "y": 71,
      "z": 22,
      "name": "Empty"
    },
    {
      "x": -3,
      "y": 72,
      "z": 22,
      "name": "Empty"
    },
    {
      "x": -3,
      "y": 73,
      "z": 22,
      "name": "Empty"
    },
    {
      "x": -3,
      "y": 74,
      "z": 22,
      "name": "Empty"
    },
    {
      "x": -3,
      "y": 55,
      "z": 23,
      "name": "Rock_Shale"
    },
    {
      "x": -3,
      "y": 56,
      "z": 23,
      "name": "Rock_Shale"
    },
    {
      "x": -3,
      "y": 57,
      "z": 23,
      "name": "Rock_Shale"
    },
    {
      "x": -3,
      "y": 58,
      "z": 23,
      "name": "Rock_Shale"
    },
    {
      "x": -3,
      "y": 59,
      "z": 23,
      "name": "Rock_Shale"
    },
    {
      "x": -3,
      "y": 60,
      "z": 23,
      "name": "Rock_Shale"
    },
    {
      "x": -3,
      "y": 61,
      "z": 23,
      "name": "Rock_Shale"
    },
    {
      "x": -3,
      "y": 62,
      "z": 23,
      "name": "Rock_Shale"
    },
    {
      "x": -3,
      "y": 63,
      "z": 23,
      "name": "Soil_Dirt_Cold"
    },
    {
      "x": -3,
      "y": 64,
      "z": 23,
      "name": "Empty"
    },
    {
      "x": -3,
      "y": 65,
      "z": 23,
      "name": "Empty"
    },
    {
      "x": -3,
      "y": 66,
      "z": 23,
      "name": "Empty"
    },
    {
      "x": -3,
      "y": 67,
      "z": 23,
      "name": "Rock_Shale_Cobble"
    },
    {
      "x": -3,
      "y": 68,
      "z": 23,
      "name": "Empty"
    },
    {
      "x": -3,
      "y": 69,
      "z": 23,
      "name": "Empty"
    },
    {
      "x": -3,
      "y": 70,
      "z": 23,
      "name": "Empty"
    },
    {
      "x": -3,
      "y": 71,
      "z": 23,
      "name": "Empty"
    },
    {
      "x": -3,
      "y": 72,
      "z": 23,
      "name": "Empty"
    },
    {
      "x": -3,
      "y": 73,
      "z": 23,
      "name": "Empty"
    },
    {
      "x": -3,
      "y": 74,
      "z": 23,
      "name": "Empty"
    },
    {
      "x": -3,
      "y": 55,
      "z": 24,
      "name": "Rock_Shale"
    },
    {
      "x": -3,
      "y": 56,
      "z": 24,
      "name": "Rock_Shale"
    },
    {
      "x": -3,
      "y": 57,
      "z": 24,
      "name": "Rock_Shale"
    },
    {
      "x": -3,
      "y": 58,
      "z": 24,
      "name": "Rock_Shale"
    },
    {
      "x": -3,
      "y": 59,
      "z": 24,
      "name": "Rock_Shale"
    },
    {
      "x": -3,
      "y": 60,
      "z": 24,
      "name": "Rock_Shale"
    },
    {
      "x": -3,
      "y": 61,
      "z": 24,
      "name": "Rock_Shale"
    },
    {
      "x": -3,
      "y": 62,
      "z": 24,
      "name": "Rock_Shale"
    },
    {
      "x": -3,
      "y": 63,
      "z": 24,
      "name": "Soil_Dirt_Cold"
    },
    {
      "x": -3,
      "y": 64,
      "z": 24,
      "name": "Empty"
    },
    {
      "x": -3,
      "y": 65,
      "z": 24,
      "name": "Empty"
    },
    {
      "x": -3,
      "y": 66,
      "z": 24,
      "name": "Empty"
    },
    {
      "x": -3,
      "y": 67,
      "z": 24,
      "name": "Rock_Shale_Cobble"
    },
    {
      "x": -3,
      "y": 68,
      "z": 24,
      "name": "Empty"
    },
    {
      "x": -3,
      "y": 69,
      "z": 24,
      "name": "Empty"
    },
    {
      "x": -3,
      "y": 70,
      "z": 24,
      "name": "Empty"
    },
    {
      "x": -3,
      "y": 71,
      "z": 24,
      "name": "Empty"
    },
    {
      "x": -3,
      "y": 72,
      "z": 24,
      "name": "Empty"
    },
    {
      "x": -3,
      "y": 73,
      "z": 24,
      "name": "Empty"
    },
    {
      "x": -3,
      "y": 74,
      "z": 24,
      "name": "Empty"
    },
    {
      "x": -3,
      "y": 56,
      "z": 25,
      "name": "Rock_Shale"
    },
    {
      "x": -3,
      "y": 57,
      "z": 25,
      "name": "Rock_Shale"
    },
    {
      "x": -3,
      "y": 58,
      "z": 25,
      "name": "Rock_Shale"
    },
    {
      "x": -3,
      "y": 59,
      "z": 25,
      "name": "Rock_Shale"
    },
    {
      "x": -3,
      "y": 60,
      "z": 25,
      "name": "Rock_Shale"
    },
    {
      "x": -3,
      "y": 61,
      "z": 25,
      "name": "Rock_Shale"
    },
    {
      "x": -3,
      "y": 62,
      "z": 25,
      "name": "Rock_Shale"
    },
    {
      "x": -3,
      "y": 63,
      "z": 25,
      "name": "Rock_Basalt_Brick"
    },
    {
      "x": -3,
      "y": 64,
      "z": 25,
      "name": "Rock_Basalt_Brick"
    },
    {
      "x": -3,
      "y": 65,
      "z": 25,
      "name": "Rock_Shale_Brick"
    },
    {
      "x": -3,
      "y": 66,
      "z": 25,
      "name": "Rock_Shale_Cobble"
    },
    {
      "x": -3,
      "y": 67,
      "z": 25,
      "name": "Rock_Shale_Cobble_Stairs"
    },
    {
      "x": -3,
      "y": 68,
      "z": 25,
      "name": "Empty"
    },
    {
      "x": -3,
      "y": 69,
      "z": 25,
      "name": "Empty"
    },
    {
      "x": -3,
      "y": 70,
      "z": 25,
      "name": "Empty"
    },
    {
      "x": -3,
      "y": 71,
      "z": 25,
      "name": "Empty"
    },
    {
      "x": -3,
      "y": 72,
      "z": 25,
      "name": "Empty"
    },
    {
      "x": -3,
      "y": 73,
      "z": 25,
      "name": "Empty"
    },
    {
      "x": -3,
      "y": 74,
      "z": 25,
      "name": "Empty"
    },
    {
      "x": -3,
      "y": 59,
      "z": 26,
      "name": "Rock_Shale"
    },
    {
      "x": -3,
      "y": 60,
      "z": 26,
      "name": "Rock_Shale"
    },
    {
      "x": -3,
      "y": 61,
      "z": 26,
      "name": "Rock_Shale_Cobble"
    },
    {
      "x": -3,
      "y": 62,
      "z": 26,
      "name": "Rock_Shale_Cobble"
    },
    {
      "x": -3,
      "y": 63,
      "z": 26,
      "name": "Rock_Shale_Cobble"
    },
    {
      "x": -3,
      "y": 64,
      "z": 26,
      "name": "Rock_Shale_Cobble"
    },
    {
      "x": -3,
      "y": 65,
      "z": 26,
      "name": "Rock_Shale_Cobble"
    },
    {
      "x": -3,
      "y": 66,
      "z": 26,
      "name": "Rock_Shale_Cobble"
    },
    {
      "x": -3,
      "y": 67,
      "z": 26,
      "name": "Empty"
    },
    {
      "x": -3,
      "y": 68,
      "z": 26,
      "name": "Empty"
    },
    {
      "x": -3,
      "y": 69,
      "z": 26,
      "name": "Empty"
    },
    {
      "x": -3,
      "y": 70,
      "z": 26,
      "name": "Empty"
    },
    {
      "x": -3,
      "y": 71,
      "z": 26,
      "name": "Empty"
    },
    {
      "x": -3,
      "y": 72,
      "z": 26,
      "name": "Empty"
    },
    {
      "x": -3,
      "y": 59,
      "z": 27,
      "name": "Rock_Shale"
    },
    {
      "x": -3,
      "y": 60,
      "z": 27,
      "name": "Rock_Shale"
    },
    {
      "x": -3,
      "y": 61,
      "z": 27,
      "name": "Rock_Shale"
    },
    {
      "x": -3,
      "y": 62,
      "z": 27,
      "name": "Rock_Shale_Cobble"
    },
    {
      "x": -3,
      "y": 63,
      "z": 27,
      "name": "Rock_Shale_Cobble"
    },
    {
      "x": -3,
      "y": 64,
      "z": 27,
      "name": "Rock_Shale_Cobble"
    },
    {
      "x": -3,
      "y": 65,
      "z": 27,
      "name": "Rock_Shale_Cobble"
    },
    {
      "x": -3,
      "y": 66,
      "z": 27,
      "name": "Rock_Shale_Cobble"
    },
    {
      "x": -3,
      "y": 67,
      "z": 27,
      "name": "Empty"
    },
    {
      "x": -3,
      "y": 68,
      "z": 27,
      "name": "Empty"
    },
    {
      "x": -3,
      "y": 69,
      "z": 27,
      "name": "Empty"
    },
    {
      "x": -3,
      "y": 70,
      "z": 27,
      "name": "Empty"
    },
    {
      "x": -3,
      "y": 71,
      "z": 27,
      "name": "Empty"
    },
    {
      "x": -3,
      "y": 72,
      "z": 27,
      "name": "Empty"
    },
    {
      "x": -3,
      "y": 61,
      "z": 28,
      "name": "Rock_Shale"
    },
    {
      "x": -3,
      "y": 62,
      "z": 28,
      "name": "Rock_Shale_Cobble"
    },
    {
      "x": -3,
      "y": 63,
      "z": 28,
      "name": "Rock_Shale_Cobble"
    },
    {
      "x": -3,
      "y": 64,
      "z": 28,
      "name": "Rock_Shale_Cobble"
    },
    {
      "x": -3,
      "y": 65,
      "z": 28,
      "name": "Rock_Shale_Brick"
    },
    {
      "x": -3,
      "y": 66,
      "z": 28,
      "name": "Rock_Shale_Brick"
    },
    {
      "x": -3,
      "y": 67,
      "z": 28,
      "name": "Rock_Shale_Cobble_Wall"
    },
    {
      "x": -3,
      "y": 68,
      "z": 28,
      "name": "Empty"
    },
    {
      "x": -3,
      "y": 69,
      "z": 28,
      "name": "Empty"
    },
    {
      "x": -3,
      "y": 70,
      "z": 28,
      "name": "Empty"
    },
    {
      "x": -3,
      "y": 71,
      "z": 28,
      "name": "Empty"
    },
    {
      "x": -3,
      "y": 72,
      "z": 28,
      "name": "Empty"
    },
    {
      "x": -3,
      "y": 58,
      "z": 32,
      "name": "Rock_Shale"
    },
    {
      "x": -3,
      "y": 59,
      "z": 32,
      "name": "Rock_Shale"
    },
    {
      "x": -3,
      "y": 60,
      "z": 32,
      "name": "Rock_Shale"
    },
    {
      "x": -3,
      "y": 61,
      "z": 32,
      "name": "Rock_Basalt_Brick"
    },
    {
      "x": -3,
      "y": 62,
      "z": 32,
      "name": "Rock_Basalt_Brick"
    },
    {
      "x": -3,
      "y": 63,
      "z": 32,
      "name": "Rock_Basalt_Brick"
    },
    {
      "x": -3,
      "y": 64,
      "z": 32,
      "name": "Rock_Basalt_Brick"
    },
    {
      "x": -3,
      "y": 65,
      "z": 32,
      "name": "Rock_Shale_Brick"
    },
    {
      "x": -3,
      "y": 66,
      "z": 32,
      "name": "Rock_Shale_Brick"
    },
    {
      "x": -3,
      "y": 67,
      "z": 32,
      "name": "Rock_Shale_Cobble_Half",
      "rotation": 6
    },
    {
      "x": -3,
      "y": 68,
      "z": 32,
      "name": "Rock_Shale_Cobble_Half",
      "rotation": 6
    },
    {
      "x": -3,
      "y": 69,
      "z": 32,
      "name": "Rock_Shale_Cobble_Half",
      "rotation": 6
    },
    {
      "x": -3,
      "y": 70,
      "z": 32,
      "name": "Rock_Shale_Brick"
    },
    {
      "x": -3,
      "y": 71,
      "z": 32,
      "name": "*Rock_Shale_Cobble_Wall_State_Definitions_Corner",
      "rotation": 1
    },
    {
      "x": -3,
      "y": 72,
      "z": 32,
      "name": "Empty"
    },
    {
      "x": -3,
      "y": 73,
      "z": 32,
      "name": "Empty"
    },
    {
      "x": -3,
      "y": 74,
      "z": 32,
      "name": "Empty"
    },
    {
      "x": -3,
      "y": 55,
      "z": 33,
      "name": "Rock_Shale"
    },
    {
      "x": -3,
      "y": 56,
      "z": 33,
      "name": "Rock_Shale"
    },
    {
      "x": -3,
      "y": 57,
      "z": 33,
      "name": "Rock_Shale"
    },
    {
      "x": -3,
      "y": 58,
      "z": 33,
      "name": "Rock_Shale"
    },
    {
      "x": -3,
      "y": 59,
      "z": 33,
      "name": "Rock_Shale"
    },
    {
      "x": -3,
      "y": 60,
      "z": 33,
      "name": "Rock_Shale"
    },
    {
      "x": -3,
      "y": 61,
      "z": 33,
      "name": "Rock_Basalt_Brick"
    },
    {
      "x": -3,
      "y": 62,
      "z": 33,
      "name": "Rock_Basalt_Brick"
    },
    {
      "x": -3,
      "y": 63,
      "z": 33,
      "name": "Rock_Basalt_Brick"
    },
    {
      "x": -3,
      "y": 64,
      "z": 33,
      "name": "Rock_Basalt_Brick"
    },
    {
      "x": -3,
      "y": 65,
      "z": 33,
      "name": "Rock_Basalt_Brick"
    },
    {
      "x": -3,
      "y": 66,
      "z": 33,
      "name": "Rock_Shale_Brick"
    },
    {
      "x": -3,
      "y": 67,
      "z": 33,
      "name": "Rock_Shale_Cobble"
    },
    {
      "x": -3,
      "y": 68,
      "z": 33,
      "name": "Rock_Shale_Cobble"
    },
    {
      "x": -3,
      "y": 69,
      "z": 33,
      "name": "Rock_Shale_Cobble"
    },
    {
      "x": -3,
      "y": 70,
      "z": 33,
      "name": "Rock_Shale_Brick"
    },
    {
      "x": -3,
      "y": 71,
      "z": 33,
      "name": "Rock_Shale_Cobble_Wall",
      "rotation": 3
    },
    {
      "x": -3,
      "y": 72,
      "z": 33,
      "name": "Empty"
    },
    {
      "x": -3,
      "y": 73,
      "z": 33,
      "name": "Empty"
    },
    {
      "x": -3,
      "y": 74,
      "z": 33,
      "name": "Empty"
    },
    {
      "x": -3,
      "y": 75,
      "z": 33,
      "name": "Empty"
    },
    {
      "x": -3,
      "y": 56,
      "z": 34,
      "name": "Rock_Shale"
    },
    {
      "x": -3,
      "y": 57,
      "z": 34,
      "name": "Rock_Shale"
    },
    {
      "x": -3,
      "y": 58,
      "z": 34,
      "name": "Rock_Shale"
    },
    {
      "x": -3,
      "y": 59,
      "z": 34,
      "name": "Rock_Shale"
    },
    {
      "x": -3,
      "y": 60,
      "z": 34,
      "name": "Rock_Shale"
    },
    {
      "x": -3,
      "y": 61,
      "z": 34,
      "name": "Rock_Shale"
    },
    {
      "x": -3,
      "y": 62,
      "z": 34,
      "name": "Rock_Basalt_Brick"
    },
    {
      "x": -3,
      "y": 63,
      "z": 34,
      "name": "Rock_Basalt_Brick"
    },
    {
      "x": -3,
      "y": 64,
      "z": 34,
      "name": "Rock_Basalt_Brick"
    },
    {
      "x": -3,
      "y": 65,
      "z": 34,
      "name": "Rock_Shale_Brick"
    },
    {
      "x": -3,
      "y": 66,
      "z": 34,
      "name": "Rock_Shale_Brick"
    },
    {
      "x": -3,
      "y": 67,
      "z": 34,
      "name": "Rock_Shale_Cobble"
    },
    {
      "x": -3,
      "y": 68,
      "z": 34,
      "name": "Rock_Shale_Cobble_Half",
      "rotation": 4
    },
    {
      "x": -3,
      "y": 69,
      "z": 34,
      "name": "Rock_Shale_Cobble_Half",
      "rotation": 4
    },
    {
      "x": -3,
      "y": 70,
      "z": 34,
      "name": "Empty"
    },
    {
      "x": -3,
      "y": 71,
      "z": 34,
      "name": "Empty"
    },
    {
      "x": -3,
      "y": 72,
      "z": 34,
      "name": "Empty"
    },
    {
      "x": -3,
      "y": 73,
      "z": 34,
      "name": "Empty"
    },
    {
      "x": -3,
      "y": 74,
      "z": 34,
      "name": "Empty"
    },
    {
      "x": -3,
      "y": 75,
      "z": 34,
      "name": "Empty"
    },
    {
      "x": -3,
      "y": 57,
      "z": 35,
      "name": "Rock_Shale"
    },
    {
      "x": -3,
      "y": 58,
      "z": 35,
      "name": "Rock_Shale"
    },
    {
      "x": -3,
      "y": 59,
      "z": 35,
      "name": "Rock_Shale"
    },
    {
      "x": -3,
      "y": 60,
      "z": 35,
      "name": "Rock_Shale"
    },
    {
      "x": -3,
      "y": 61,
      "z": 35,
      "name": "Rock_Shale"
    },
    {
      "x": -3,
      "y": 62,
      "z": 35,
      "name": "Rock_Basalt_Cobble"
    },
    {
      "x": -3,
      "y": 63,
      "z": 35,
      "name": "Rock_Basalt_Cobble"
    },
    {
      "x": -3,
      "y": 64,
      "z": 35,
      "name": "Rock_Basalt_Cobble_Half",
      "rotation": 7
    },
    {
      "x": -3,
      "y": 65,
      "z": 35,
      "name": "Rock_Shale_Brick_Half",
      "rotation": 7
    },
    {
      "x": -3,
      "y": 66,
      "z": 35,
      "name": "Rock_Shale_Brick_Half",
      "rotation": 7
    },
    {
      "x": -3,
      "y": 70,
      "z": 35,
      "name": "Empty"
    },
    {
      "x": -3,
      "y": 71,
      "z": 35,
      "name": "Empty"
    },
    {
      "x": -3,
      "y": 72,
      "z": 35,
      "name": "Empty"
    },
    {
      "x": -3,
      "y": 73,
      "z": 35,
      "name": "Empty"
    },
    {
      "x": -3,
      "y": 74,
      "z": 35,
      "name": "Empty"
    },
    {
      "x": -2,
      "y": 60,
      "z": 14,
      "name": "Rock_Shale_Cobble"
    },
    {
      "x": -2,
      "y": 61,
      "z": 14,
      "name": "Rock_Shale_Brick"
    },
    {
      "x": -2,
      "y": 62,
      "z": 14,
      "name": "Rock_Shale_Brick"
    },
    {
      "x": -2,
      "y": 63,
      "z": 14,
      "name": "Rock_Shale_Brick"
    },
    {
      "x": -2,
      "y": 64,
      "z": 14,
      "name": "Rock_Shale_Brick"
    },
    {
      "x": -2,
      "y": 65,
      "z": 14,
      "name": "Rock_Shale_Cobble_Wall",
      "rotation": 2
    },
    {
      "x": -2,
      "y": 66,
      "z": 14,
      "name": "Empty"
    },
    {
      "x": -2,
      "y": 67,
      "z": 14,
      "name": "Empty"
    },
    {
      "x": -2,
      "y": 68,
      "z": 14,
      "name": "Empty"
    },
    {
      "x": -2,
      "y": 69,
      "z": 14,
      "name": "Empty"
    },
    {
      "x": -2,
      "y": 70,
      "z": 14,
      "name": "Empty"
    },
    {
      "x": -2,
      "y": 71,
      "z": 14,
      "name": "Empty"
    },
    {
      "x": -2,
      "y": 56,
      "z": 15,
      "name": "Rock_Shale"
    },
    {
      "x": -2,
      "y": 57,
      "z": 15,
      "name": "Rock_Shale"
    },
    {
      "x": -2,
      "y": 58,
      "z": 15,
      "name": "Rock_Shale"
    },
    {
      "x": -2,
      "y": 59,
      "z": 15,
      "name": "Rock_Shale"
    },
    {
      "x": -2,
      "y": 60,
      "z": 15,
      "name": "Rock_Shale"
    },
    {
      "x": -2,
      "y": 61,
      "z": 15,
      "name": "Rock_Shale"
    },
    {
      "x": -2,
      "y": 62,
      "z": 15,
      "name": "Rock_Shale"
    },
    {
      "x": -2,
      "y": 63,
      "z": 15,
      "name": "Rock_Shale"
    },
    {
      "x": -2,
      "y": 64,
      "z": 15,
      "name": "Soil_Dirt_Cold"
    },
    {
      "x": -2,
      "y": 65,
      "z": 15,
      "name": "Empty"
    },
    {
      "x": -2,
      "y": 66,
      "z": 15,
      "name": "Empty"
    },
    {
      "x": -2,
      "y": 67,
      "z": 15,
      "name": "Empty"
    },
    {
      "x": -2,
      "y": 68,
      "z": 15,
      "name": "Empty"
    },
    {
      "x": -2,
      "y": 69,
      "z": 15,
      "name": "Empty"
    },
    {
      "x": -2,
      "y": 70,
      "z": 15,
      "name": "Empty"
    },
    {
      "x": -2,
      "y": 71,
      "z": 15,
      "name": "Empty"
    },
    {
      "x": -2,
      "y": 72,
      "z": 15,
      "name": "Empty"
    },
    {
      "x": -2,
      "y": 55,
      "z": 16,
      "name": "Rock_Shale"
    },
    {
      "x": -2,
      "y": 56,
      "z": 16,
      "name": "Rock_Shale"
    },
    {
      "x": -2,
      "y": 57,
      "z": 16,
      "name": "Rock_Shale"
    },
    {
      "x": -2,
      "y": 58,
      "z": 16,
      "name": "Rock_Shale"
    },
    {
      "x": -2,
      "y": 59,
      "z": 16,
      "name": "Rock_Shale"
    },
    {
      "x": -2,
      "y": 60,
      "z": 16,
      "name": "Rock_Shale"
    },
    {
      "x": -2,
      "y": 61,
      "z": 16,
      "name": "Rock_Shale"
    },
    {
      "x": -2,
      "y": 62,
      "z": 16,
      "name": "Rock_Shale"
    },
    {
      "x": -2,
      "y": 63,
      "z": 16,
      "name": "Rock_Shale_Cobble"
    },
    {
      "x": -2,
      "y": 64,
      "z": 16,
      "name": "Soil_Dirt_Cold"
    },
    {
      "x": -2,
      "y": 65,
      "z": 16,
      "name": "Empty"
    },
    {
      "x": -2,
      "y": 66,
      "z": 16,
      "name": "Empty"
    },
    {
      "x": -2,
      "y": 67,
      "z": 16,
      "name": "Empty"
    },
    {
      "x": -2,
      "y": 68,
      "z": 16,
      "name": "Empty"
    },
    {
      "x": -2,
      "y": 69,
      "z": 16,
      "name": "Empty"
    },
    {
      "x": -2,
      "y": 70,
      "z": 16,
      "name": "Empty"
    },
    {
      "x": -2,
      "y": 71,
      "z": 16,
      "name": "Empty"
    },
    {
      "x": -2,
      "y": 72,
      "z": 16,
      "name": "Empty"
    },
    {
      "x": -2,
      "y": 73,
      "z": 16,
      "name": "Empty"
    },
    {
      "x": -2,
      "y": 74,
      "z": 16,
      "name": "Empty"
    },
    {
      "x": -2,
      "y": 75,
      "z": 16,
      "name": "Empty"
    },
    {
      "x": -2,
      "y": 76,
      "z": 16,
      "name": "Empty"
    },
    {
      "x": -2,
      "y": 77,
      "z": 16,
      "name": "Empty"
    },
    {
      "x": -2,
      "y": 78,
      "z": 16,
      "name": "Empty"
    },
    {
      "x": -2,
      "y": 79,
      "z": 16,
      "name": "Empty"
    },
    {
      "x": -2,
      "y": 54,
      "z": 17,
      "name": "Rock_Shale"
    },
    {
      "x": -2,
      "y": 55,
      "z": 17,
      "name": "Rock_Shale"
    },
    {
      "x": -2,
      "y": 56,
      "z": 17,
      "name": "Rock_Shale"
    },
    {
      "x": -2,
      "y": 57,
      "z": 17,
      "name": "Rock_Shale"
    },
    {
      "x": -2,
      "y": 58,
      "z": 17,
      "name": "Rock_Shale"
    },
    {
      "x": -2,
      "y": 59,
      "z": 17,
      "name": "Rock_Shale"
    },
    {
      "x": -2,
      "y": 60,
      "z": 17,
      "name": "Rock_Shale"
    },
    {
      "x": -2,
      "y": 61,
      "z": 17,
      "name": "Rock_Shale"
    },
    {
      "x": -2,
      "y": 62,
      "z": 17,
      "name": "Rock_Shale"
    },
    {
      "x": -2,
      "y": 63,
      "z": 17,
      "name": "Rock_Shale_Cobble"
    },
    {
      "x": -2,
      "y": 64,
      "z": 17,
      "name": "Soil_Dirt_Cold"
    },
    {
      "x": -2,
      "y": 65,
      "z": 17,
      "name": "Empty"
    },
    {
      "x": -2,
      "y": 66,
      "z": 17,
      "name": "Empty"
    },
    {
      "x": -2,
      "y": 67,
      "z": 17,
      "name": "Empty"
    },
    {
      "x": -2,
      "y": 68,
      "z": 17,
      "name": "Empty"
    },
    {
      "x": -2,
      "y": 69,
      "z": 17,
      "name": "Empty"
    },
    {
      "x": -2,
      "y": 70,
      "z": 17,
      "name": "Empty"
    },
    {
      "x": -2,
      "y": 71,
      "z": 17,
      "name": "Empty"
    },
    {
      "x": -2,
      "y": 72,
      "z": 17,
      "name": "Empty"
    },
    {
      "x": -2,
      "y": 73,
      "z": 17,
      "name": "Empty"
    },
    {
      "x": -2,
      "y": 74,
      "z": 17,
      "name": "Empty"
    },
    {
      "x": -2,
      "y": 75,
      "z": 17,
      "name": "Empty"
    },
    {
      "x": -2,
      "y": 76,
      "z": 17,
      "name": "Empty"
    },
    {
      "x": -2,
      "y": 77,
      "z": 17,
      "name": "Empty"
    },
    {
      "x": -2,
      "y": 78,
      "z": 17,
      "name": "Empty"
    },
    {
      "x": -2,
      "y": 79,
      "z": 17,
      "name": "Empty"
    },
    {
      "x": -2,
      "y": 80,
      "z": 17,
      "name": "Empty"
    },
    {
      "x": -2,
      "y": 54,
      "z": 18,
      "name": "Rock_Shale"
    },
    {
      "x": -2,
      "y": 55,
      "z": 18,
      "name": "Rock_Shale"
    },
    {
      "x": -2,
      "y": 56,
      "z": 18,
      "name": "Rock_Shale"
    },
    {
      "x": -2,
      "y": 57,
      "z": 18,
      "name": "Rock_Shale"
    },
    {
      "x": -2,
      "y": 58,
      "z": 18,
      "name": "Rock_Shale"
    },
    {
      "x": -2,
      "y": 59,
      "z": 18,
      "name": "Rock_Shale"
    },
    {
      "x": -2,
      "y": 60,
      "z": 18,
      "name": "Rock_Shale"
    },
    {
      "x": -2,
      "y": 61,
      "z": 18,
      "name": "Rock_Shale"
    },
    {
      "x": -2,
      "y": 62,
      "z": 18,
      "name": "Rock_Shale"
    },
    {
      "x": -2,
      "y": 63,
      "z": 18,
      "name": "Rock_Shale_Cobble"
    },
    {
      "x": -2,
      "y": 64,
      "z": 18,
      "name": "Soil_Dirt_Cold"
    },
    {
      "x": -2,
      "y": 65,
      "z": 18,
      "name": "Empty"
    },
    {
      "x": -2,
      "y": 66,
      "z": 18,
      "name": "Empty"
    },
    {
      "x": -2,
      "y": 67,
      "z": 18,
      "name": "Empty"
    },
    {
      "x": -2,
      "y": 68,
      "z": 18,
      "name": "Empty"
    },
    {
      "x": -2,
      "y": 69,
      "z": 18,
      "name": "Empty"
    },
    {
      "x": -2,
      "y": 70,
      "z": 18,
      "name": "Empty"
    },
    {
      "x": -2,
      "y": 71,
      "z": 18,
      "name": "Empty"
    },
    {
      "x": -2,
      "y": 72,
      "z": 18,
      "name": "Rock_Shale_Cobble_Half",
      "rotation": 7
    },
    {
      "x": -2,
      "y": 73,
      "z": 18,
      "name": "Empty"
    },
    {
      "x": -2,
      "y": 74,
      "z": 18,
      "name": "Empty"
    },
    {
      "x": -2,
      "y": 75,
      "z": 18,
      "name": "Empty"
    },
    {
      "x": -2,
      "y": 76,
      "z": 18,
      "name": "Empty"
    },
    {
      "x": -2,
      "y": 77,
      "z": 18,
      "name": "Empty"
    },
    {
      "x": -2,
      "y": 78,
      "z": 18,
      "name": "Empty"
    },
    {
      "x": -2,
      "y": 79,
      "z": 18,
      "name": "Empty"
    },
    {
      "x": -2,
      "y": 80,
      "z": 18,
      "name": "Empty"
    },
    {
      "x": -2,
      "y": 54,
      "z": 19,
      "name": "Rock_Shale"
    },
    {
      "x": -2,
      "y": 55,
      "z": 19,
      "name": "Rock_Shale"
    },
    {
      "x": -2,
      "y": 56,
      "z": 19,
      "name": "Rock_Shale"
    },
    {
      "x": -2,
      "y": 57,
      "z": 19,
      "name": "Rock_Shale"
    },
    {
      "x": -2,
      "y": 58,
      "z": 19,
      "name": "Rock_Shale"
    },
    {
      "x": -2,
      "y": 59,
      "z": 19,
      "name": "Rock_Shale"
    },
    {
      "x": -2,
      "y": 60,
      "z": 19,
      "name": "Rock_Shale"
    },
    {
      "x": -2,
      "y": 61,
      "z": 19,
      "name": "Rock_Shale"
    },
    {
      "x": -2,
      "y": 62,
      "z": 19,
      "name": "Rock_Shale"
    },
    {
      "x": -2,
      "y": 63,
      "z": 19,
      "name": "Rock_Shale_Cobble"
    },
    {
      "x": -2,
      "y": 64,
      "z": 19,
      "name": "Soil_Dirt_Cold"
    },
    {
      "x": -2,
      "y": 65,
      "z": 19,
      "name": "Empty"
    },
    {
      "x": -2,
      "y": 66,
      "z": 19,
      "name": "Empty"
    },
    {
      "x": -2,
      "y": 67,
      "z": 19,
      "name": "Empty"
    },
    {
      "x": -2,
      "y": 68,
      "z": 19,
      "name": "Empty"
    },
    {
      "x": -2,
      "y": 69,
      "z": 19,
      "name": "Empty"
    },
    {
      "x": -2,
      "y": 70,
      "z": 19,
      "name": "Empty"
    },
    {
      "x": -2,
      "y": 71,
      "z": 19,
      "name": "Rock_Shale_Cobble_Half",
      "rotation": 7
    },
    {
      "x": -2,
      "y": 72,
      "z": 19,
      "name": "Rock_Shale_Cobble_Half",
      "rotation": 7
    },
    {
      "x": -2,
      "y": 73,
      "z": 19,
      "name": "Rock_Shale_Brick"
    },
    {
      "x": -2,
      "y": 74,
      "z": 19,
      "name": "Rock_Shale_Cobble_Half"
    },
    {
      "x": -2,
      "y": 75,
      "z": 19,
      "name": "Empty"
    },
    {
      "x": -2,
      "y": 76,
      "z": 19,
      "name": "Empty"
    },
    {
      "x": -2,
      "y": 77,
      "z": 19,
      "name": "Empty"
    },
    {
      "x": -2,
      "y": 78,
      "z": 19,
      "name": "Empty"
    },
    {
      "x": -2,
      "y": 79,
      "z": 19,
      "name": "Empty"
    },
    {
      "x": -2,
      "y": 80,
      "z": 19,
      "name": "Empty"
    },
    {
      "x": -2,
      "y": 54,
      "z": 20,
      "name": "Rock_Shale"
    },
    {
      "x": -2,
      "y": 55,
      "z": 20,
      "name": "Rock_Shale"
    },
    {
      "x": -2,
      "y": 56,
      "z": 20,
      "name": "Rock_Shale"
    },
    {
      "x": -2,
      "y": 57,
      "z": 20,
      "name": "Rock_Shale"
    },
    {
      "x": -2,
      "y": 58,
      "z": 20,
      "name": "Rock_Shale"
    },
    {
      "x": -2,
      "y": 59,
      "z": 20,
      "name": "Rock_Shale"
    },
    {
      "x": -2,
      "y": 60,
      "z": 20,
      "name": "Rock_Shale"
    },
    {
      "x": -2,
      "y": 61,
      "z": 20,
      "name": "Rock_Shale"
    },
    {
      "x": -2,
      "y": 62,
      "z": 20,
      "name": "Rock_Shale"
    },
    {
      "x": -2,
      "y": 63,
      "z": 20,
      "name": "Rock_Basalt_Brick"
    },
    {
      "x": -2,
      "y": 64,
      "z": 20,
      "name": "Rock_Basalt_Brick"
    },
    {
      "x": -2,
      "y": 65,
      "z": 20,
      "name": "Rock_Shale_Brick"
    },
    {
      "x": -2,
      "y": 66,
      "z": 20,
      "name": "Rock_Shale_Brick"
    },
    {
      "x": -2,
      "y": 67,
      "z": 20,
      "name": "Rock_Shale_Brick"
    },
    {
      "x": -2,
      "y": 68,
      "z": 20,
      "name": "Rock_Shale_Cobble_Wall",
      "rotation": 2
    },
    {
      "x": -2,
      "y": 69,
      "z": 20,
      "name": "Empty"
    },
    {
      "x": -2,
      "y": 70,
      "z": 20,
      "name": "Empty"
    },
    {
      "x": -2,
      "y": 71,
      "z": 20,
      "name": "Empty"
    },
    {
      "x": -2,
      "y": 72,
      "z": 20,
      "name": "Rock_Shale_Brick_Half",
      "rotation": 7
    },
    {
      "x": -2,
      "y": 73,
      "z": 20,
      "name": "Rock_Shale_Brick_Half",
      "rotation": 7
    },
    {
      "x": -2,
      "y": 74,
      "z": 20,
      "name": "Rock_Shale_Cobble"
    },
    {
      "x": -2,
      "y": 75,
      "z": 20,
      "name": "Rock_Shale_Cobble_Wall",
      "rotation": 3
    },
    {
      "x": -2,
      "y": 76,
      "z": 20,
      "name": "Empty"
    },
    {
      "x": -2,
      "y": 77,
      "z": 20,
      "name": "Empty"
    },
    {
      "x": -2,
      "y": 78,
      "z": 20,
      "name": "Empty"
    },
    {
      "x": -2,
      "y": 79,
      "z": 20,
      "name": "Empty"
    },
    {
      "x": -2,
      "y": 80,
      "z": 20,
      "name": "Empty"
    },
    {
      "x": -2,
      "y": 54,
      "z": 21,
      "name": "Rock_Shale"
    },
    {
      "x": -2,
      "y": 55,
      "z": 21,
      "name": "Rock_Shale"
    },
    {
      "x": -2,
      "y": 56,
      "z": 21,
      "name": "Rock_Shale"
    },
    {
      "x": -2,
      "y": 57,
      "z": 21,
      "name": "Rock_Shale"
    },
    {
      "x": -2,
      "y": 58,
      "z": 21,
      "name": "Rock_Shale"
    },
    {
      "x": -2,
      "y": 59,
      "z": 21,
      "name": "Rock_Shale"
    },
    {
      "x": -2,
      "y": 60,
      "z": 21,
      "name": "Rock_Shale"
    },
    {
      "x": -2,
      "y": 61,
      "z": 21,
      "name": "Rock_Shale"
    },
    {
      "x": -2,
      "y": 62,
      "z": 21,
      "name": "Rock_Shale"
    },
    {
      "x": -2,
      "y": 63,
      "z": 21,
      "name": "Soil_Dirt_Cold"
    },
    {
      "x": -2,
      "y": 64,
      "z": 21,
      "name": "Furniture_Lumberjack_Platform"
    },
    {
      "x": -2,
      "y": 65,
      "z": 21,
      "name": "Empty"
    },
    {
      "x": -2,
      "y": 66,
      "z": 21,
      "name": "Empty"
    },
    {
      "x": -2,
      "y": 67,
      "z": 21,
      "name": "Rock_Shale_Cobble"
    },
    {
      "x": -2,
      "y": 68,
      "z": 21,
      "name": "Wood_Fir_Trunk"
    },
    {
      "x": -2,
      "y": 69,
      "z": 21,
      "name": "Wood_Fir_Trunk"
    },
    {
      "x": -2,
      "y": 70,
      "z": 21,
      "name": "Wood_Fir_Branch_Long"
    },
    {
      "x": -2,
      "y": 71,
      "z": 21,
      "name": "Survival_Trap_Spike_Wood_Large"
    },
    {
      "x": -2,
      "y": 72,
      "z": 21,
      "name": "Empty"
    },
    {
      "x": -2,
      "y": 73,
      "z": 21,
      "name": "Rock_Shale_Brick"
    },
    {
      "x": -2,
      "y": 74,
      "z": 21,
      "name": "Rock_Shale_Cobble"
    },
    {
      "x": -2,
      "y": 75,
      "z": 21,
      "name": "Rock_Shale_Cobble_Wall",
      "rotation": 3
    },
    {
      "x": -2,
      "y": 76,
      "z": 21,
      "name": "Empty"
    },
    {
      "x": -2,
      "y": 77,
      "z": 21,
      "name": "Empty"
    },
    {
      "x": -2,
      "y": 78,
      "z": 21,
      "name": "Empty"
    },
    {
      "x": -2,
      "y": 79,
      "z": 21,
      "name": "Empty"
    },
    {
      "x": -2,
      "y": 80,
      "z": 21,
      "name": "Empty"
    },
    {
      "x": -2,
      "y": 54,
      "z": 22,
      "name": "Rock_Shale"
    },
    {
      "x": -2,
      "y": 55,
      "z": 22,
      "name": "Rock_Shale"
    },
    {
      "x": -2,
      "y": 56,
      "z": 22,
      "name": "Rock_Shale"
    },
    {
      "x": -2,
      "y": 57,
      "z": 22,
      "name": "Rock_Shale"
    },
    {
      "x": -2,
      "y": 58,
      "z": 22,
      "name": "Rock_Shale"
    },
    {
      "x": -2,
      "y": 59,
      "z": 22,
      "name": "Rock_Shale"
    },
    {
      "x": -2,
      "y": 60,
      "z": 22,
      "name": "Rock_Shale"
    },
    {
      "x": -2,
      "y": 61,
      "z": 22,
      "name": "Rock_Shale"
    },
    {
      "x": -2,
      "y": 62,
      "z": 22,
      "name": "Rock_Shale"
    },
    {
      "x": -2,
      "y": 63,
      "z": 22,
      "name": "Soil_Dirt_Cold"
    },
    {
      "x": -2,
      "y": 64,
      "z": 22,
      "name": "Empty"
    },
    {
      "x": -2,
      "y": 65,
      "z": 22,
      "name": "Empty"
    },
    {
      "x": -2,
      "y": 66,
      "z": 22,
      "name": "Empty"
    },
    {
      "x": -2,
      "y": 67,
      "z": 22,
      "name": "Rock_Shale_Cobble"
    },
    {
      "x": -2,
      "y": 68,
      "z": 22,
      "name": "Empty"
    },
    {
      "x": -2,
      "y": 69,
      "z": 22,
      "name": "Empty"
    },
    {
      "x": -2,
      "y": 70,
      "z": 22,
      "name": "Empty"
    },
    {
      "x": -2,
      "y": 71,
      "z": 22,
      "name": "Empty"
    },
    {
      "x": -2,
      "y": 72,
      "z": 22,
      "name": "Empty"
    },
    {
      "x": -2,
      "y": 73,
      "z": 22,
      "name": "Empty"
    },
    {
      "x": -2,
      "y": 74,
      "z": 22,
      "name": "Empty"
    },
    {
      "x": -2,
      "y": 75,
      "z": 22,
      "name": "Empty"
    },
    {
      "x": -2,
      "y": 76,
      "z": 22,
      "name": "Empty"
    },
    {
      "x": -2,
      "y": 77,
      "z": 22,
      "name": "Empty"
    },
    {
      "x": -2,
      "y": 78,
      "z": 22,
      "name": "Empty"
    },
    {
      "x": -2,
      "y": 79,
      "z": 22,
      "name": "Empty"
    },
    {
      "x": -2,
      "y": 80,
      "z": 22,
      "name": "Empty"
    },
    {
      "x": -2,
      "y": 54,
      "z": 23,
      "name": "Rock_Shale"
    },
    {
      "x": -2,
      "y": 55,
      "z": 23,
      "name": "Rock_Shale"
    },
    {
      "x": -2,
      "y": 56,
      "z": 23,
      "name": "Rock_Shale"
    },
    {
      "x": -2,
      "y": 57,
      "z": 23,
      "name": "Rock_Shale"
    },
    {
      "x": -2,
      "y": 58,
      "z": 23,
      "name": "Rock_Shale"
    },
    {
      "x": -2,
      "y": 59,
      "z": 23,
      "name": "Rock_Shale"
    },
    {
      "x": -2,
      "y": 60,
      "z": 23,
      "name": "Rock_Shale"
    },
    {
      "x": -2,
      "y": 61,
      "z": 23,
      "name": "Rock_Shale"
    },
    {
      "x": -2,
      "y": 62,
      "z": 23,
      "name": "Rock_Shale"
    },
    {
      "x": -2,
      "y": 63,
      "z": 23,
      "name": "Soil_Dirt_Cold"
    },
    {
      "x": -2,
      "y": 64,
      "z": 23,
      "name": "Empty"
    },
    {
      "x": -2,
      "y": 65,
      "z": 23,
      "name": "Empty"
    },
    {
      "x": -2,
      "y": 66,
      "z": 23,
      "name": "Empty"
    },
    {
      "x": -2,
      "y": 67,
      "z": 23,
      "name": "Rock_Shale_Cobble"
    },
    {
      "x": -2,
      "y": 68,
      "z": 23,
      "name": "Empty"
    },
    {
      "x": -2,
      "y": 69,
      "z": 23,
      "name": "Empty"
    },
    {
      "x": -2,
      "y": 70,
      "z": 23,
      "name": "Empty"
    },
    {
      "x": -2,
      "y": 71,
      "z": 23,
      "name": "Empty"
    },
    {
      "x": -2,
      "y": 72,
      "z": 23,
      "name": "Empty"
    },
    {
      "x": -2,
      "y": 73,
      "z": 23,
      "name": "Empty"
    },
    {
      "x": -2,
      "y": 74,
      "z": 23,
      "name": "Empty"
    },
    {
      "x": -2,
      "y": 75,
      "z": 23,
      "name": "Empty"
    },
    {
      "x": -2,
      "y": 76,
      "z": 23,
      "name": "Empty"
    },
    {
      "x": -2,
      "y": 77,
      "z": 23,
      "name": "Empty"
    },
    {
      "x": -2,
      "y": 78,
      "z": 23,
      "name": "Empty"
    },
    {
      "x": -2,
      "y": 79,
      "z": 23,
      "name": "Empty"
    },
    {
      "x": -2,
      "y": 80,
      "z": 23,
      "name": "Empty"
    },
    {
      "x": -2,
      "y": 55,
      "z": 24,
      "name": "Rock_Shale"
    },
    {
      "x": -2,
      "y": 56,
      "z": 24,
      "name": "Rock_Shale"
    },
    {
      "x": -2,
      "y": 57,
      "z": 24,
      "name": "Rock_Shale"
    },
    {
      "x": -2,
      "y": 58,
      "z": 24,
      "name": "Rock_Shale"
    },
    {
      "x": -2,
      "y": 59,
      "z": 24,
      "name": "Rock_Shale"
    },
    {
      "x": -2,
      "y": 60,
      "z": 24,
      "name": "Rock_Shale"
    },
    {
      "x": -2,
      "y": 61,
      "z": 24,
      "name": "Rock_Shale"
    },
    {
      "x": -2,
      "y": 62,
      "z": 24,
      "name": "Rock_Shale"
    },
    {
      "x": -2,
      "y": 63,
      "z": 24,
      "name": "Soil_Dirt_Cold"
    },
    {
      "x": -2,
      "y": 64,
      "z": 24,
      "name": "Furniture_Village_Crate",
      "components": {
        "Components": {
          "container": {
            "Position": {
              "X": -4,
              "Y": 3,
              "Z": 3
            },
            "Custom": false,
            "AllowViewing": true,
            "ItemContainer": {
              "Capacity": 20,
              "Items": {
                "0": {
                  "Id": "Ingredient_Leather_Light",
                  "Quantity": 2,
                  "Durability": 0.0,
                  "MaxDurability": 0.0,
                  "OverrideDroppedItemAnimation": false
                },
                "1": {
                  "Id": "Ore_Iron",
                  "Quantity": 4,
                  "Durability": 0.0,
                  "MaxDurability": 0.0,
                  "OverrideDroppedItemAnimation": false
                }
              }
            }
          }
        }
      }
    },
    {
      "x": -2,
      "y": 65,
      "z": 24,
      "name": "Empty"
    },
    {
      "x": -2,
      "y": 66,
      "z": 24,
      "name": "Empty"
    },
    {
      "x": -2,
      "y": 67,
      "z": 24,
      "name": "Rock_Shale_Cobble"
    },
    {
      "x": -2,
      "y": 68,
      "z": 24,
      "name": "Empty"
    },
    {
      "x": -2,
      "y": 69,
      "z": 24,
      "name": "Empty"
    },
    {
      "x": -2,
      "y": 70,
      "z": 24,
      "name": "Empty"
    },
    {
      "x": -2,
      "y": 71,
      "z": 24,
      "name": "Empty"
    },
    {
      "x": -2,
      "y": 72,
      "z": 24,
      "name": "Empty"
    },
    {
      "x": -2,
      "y": 73,
      "z": 24,
      "name": "Empty"
    },
    {
      "x": -2,
      "y": 74,
      "z": 24,
      "name": "Empty"
    },
    {
      "x": -2,
      "y": 75,
      "z": 24,
      "name": "Empty"
    },
    {
      "x": -2,
      "y": 76,
      "z": 24,
      "name": "Empty"
    },
    {
      "x": -2,
      "y": 77,
      "z": 24,
      "name": "Empty"
    },
    {
      "x": -2,
      "y": 78,
      "z": 24,
      "name": "Empty"
    },
    {
      "x": -2,
      "y": 79,
      "z": 24,
      "name": "Empty"
    },
