{
  "version": 8,
  "blockIdVersion": 8,
  "anchorX": -1,
  "anchorY": 7,
  "anchorZ": 0,
  "blocks": [
    {
      "x": -4,
      "y": 4,
      "z": -3,
      "name": "Rock_Marble"
    },
    {
      "x": -4,
      "y": 5,
      "z": -3,
      "name": "Rock_Marble"
    },
    {
      "x": -4,
      "y": 6,
      "z": -3,
      "name": "Rock_Marble"
    },
    {
      "x": -4,
      "y": 7,
      "z": -3,
      "name": "Rock_Marble"
    },
    {
      "x": -4,
      "y": 4,
      "z": -2,
      "name": "Rock_Marble"
    },
    {
      "x": -4,
      "y": 5,
      "z": -2,
      "name": "Rock_Marble"
    },
    {
      "x": -4,
      "y": 6,
      "z": -2,
      "name": "Rock_Marble"
    },
    {
      "x": -4,
      "y": 7,
      "z": -2,
      "name": "Rock_Marble"
    },
    {
      "x": -4,
      "y": 8,
      "z": -2,
      "name": "Rock_Marble"
    },
    {
      "x": -4,
      "y": 5,
      "z": -1,
      "name": "Rock_Marble"
    },
    {
      "x": -4,
      "y": 6,
      "z": -1,
      "name": "Rock_Marble"
    },
    {
      "x": -4,
      "y": 7,
      "z": -1,
      "name": "Rock_Marble"
    },
    {
      "x": -4,
      "y": 8,
      "z": -1,
      "name": "Rock_Marble"
    },
    {
      "x": -3,
      "y": 4,
      "z": -3,
      "name": "Rock_Marble"
    },
    {
      "x": -3,
      "y": 5,
      "z": -3,
      "name": "Rock_Marble"
    },
    {
      "x": -3,
      "y": 6,
      "z": -3,
      "name": "Rock_Marble"
    },
    {
      "x": -3,
      "y": 7,
      "z": -3,
      "name": "Rock_Marble"
    },
    {
      "x": -3,
      "y": 4,
      "z": -2,
      "name": "Rock_Marble"
    },
    {
      "x": -3,
      "y": 5,
      "z": -2,
      "name": "Rock_Marble"
    },
    {
      "x": -3,
      "y": 6,
      "z": -2,
      "name": "Rock_Marble"
    },
    {
      "x": -3,
      "y": 7,
      "z": -2,
      "name": "Rock_Marble"
    },
    {
      "x": -3,
      "y": 8,
      "z": -2,
      "name": "Rock_Marble"
    },
    {
      "x": -3,
      "y": 5,
      "z": -1,
      "name": "Rock_Marble"
    },
    {
      "x": -3,
      "y": 6,
      "z": -1,
      "name": "Rock_Marble"
    },
    {
      "x": -3,
      "y": 7,
      "z": -1,
      "name": "Rock_Marble"
    },
    {
      "x": -3,
      "y": 8,
      "z": -1,
      "name": "Rock_Marble"
    },
    {
      "x": -3,
      "y": 9,
      "z": -1,
      "name": "Soil_Grass"
    },
    {
      "x": -3,
      "y": 6,
      "z": 0,
      "name": "Rock_Marble"
    },
    {
      "x": -3,
      "y": 7,
      "z": 0,
      "name": "Rock_Marble"
    },
    {
      "x": -3,
      "y": 8,
      "z": 0,
      "name": "Soil_Dirt"
    },
    {
      "x": -3,
      "y": 9,
      "z": 0,
      "name": "Soil_Grass"
    },
    {
      "x": -2,
      "y": 5,
      "z": -3,
      "name": "Rock_Marble"
    },
    {
      "x": -2,
      "y": 6,
      "z": -3,
      "name": "Rock_Marble"
    },
    {
      "x": -2,
      "y": 5,
      "z": -2,
      "name": "Rock_Marble"
    },
    {
      "x": -2,
      "y": 6,
      "z": -2,
      "name": "Rock_Marble"
    },
    {
      "x": -2,
      "y": 7,
      "z": -2,
      "name": "Rock_Marble"
    },
    {
      "x": -2,
      "y": 8,
      "z": -2,
      "name": "Rock_Marble"
    },
    {
      "x": -2,
      "y": 5,
      "z": -1,
      "name": "Rock_Marble"
    },
    {
      "x": -2,
      "y": 6,
      "z": -1,
      "name": "Rock_Marble"
    },
    {
      "x": -2,
      "y": 7,
      "z": -1,
      "name": "Rock_Marble"
    },
    {
      "x": -2,
      "y": 8,
      "z": -1,
      "name": "Rock_Marble"
    },
    {
      "x": -2,
      "y": 9,
      "z": -1,
      "name": "Soil_Grass"
    },
    {
      "x": -2,
      "y": 10,
      "z": -1,
      "name": "Prefab_Spawner_Block",
      "components": {
        "Components": {
          "prefabspawner": {
            "PrefabPath": "Trees.Birch.*",
            "FitHeightmap": false,
            "InheritSeed": true,
            "InheritHeightCondition": true
          }
        }
      },
      "rotation": 2
    },
    {
      "x": -2,
      "y": 6,
      "z": 0,
      "name": "Rock_Marble"
    },
    {
      "x": -2,
      "y": 7,
      "z": 0,
      "name": "Rock_Marble"
    },
    {
      "x": -2,
      "y": 8,
      "z": 0,
      "name": "Soil_Dirt"
    },
    {
      "x": -2,
      "y": 9,
      "z": 0,
      "name": "Soil_Grass"
    },
    {
      "x": -1,
      "y": 7,
      "z": -1,
      "name": "Rock_Marble"
    },
    {
      "x": -1,
      "y": 8,
      "z": -1,
      "name": "Rock_Marble"
    },
    {
      "x": -1,
      "y": 7,
      "z": 0,
      "name": "Rock_Marble"
    },
    {
      "x": -1,
      "y": 8,
      "z": 0,
      "name": "Soil_Dirt"
    },
    {
      "x": -1,
      "y": 9,
      "z": 0,
      "name": "Soil_Grass"
    },
    {
      "x": -1,
      "y": 6,
      "z": 1,
      "name": "Rock_Marble"
    },
    {
      "x": -1,
      "y": 7,
      "z": 1,
      "name": "Rock_Marble"
    },
    {
      "x": -1,
      "y": 8,
      "z": 1,
      "name": "Rock_Marble"
    },
    {
      "x": -1,
      "y": 9,
      "z": 1,
      "name": "Rock_Marble"
    },
    {
      "x": -1,
      "y": 10,
      "z": 1,
      "name": "Rock_Marble"
    },
    {
      "x": -1,
      "y": 11,
      "z": 1,
      "name": "Rock_Marble"
    },
    {
      "x": -1,
      "y": 6,
      "z": 2,
      "name": "Rock_Marble"
    },
    {
      "x": -1,
      "y": 7,
      "z": 2,
      "name": "Rock_Marble"
    },
    {
      "x": -1,
      "y": 8,
      "z": 2,
      "name": "Rock_Marble"
    },
    {
      "x": -1,
      "y": 9,
      "z": 2,
      "name": "Rock_Marble"
    },
    {
      "x": -1,
      "y": 10,
      "z": 2,
      "name": "Rock_Marble"
    },
    {
      "x": -1,
      "y": 11,
      "z": 2,
      "name": "Rock_Marble"
    },
    {
      "x": -1,
      "y": 8,
      "z": 3,
      "name": "Rock_Marble"
    },
    {
      "x": -1,
      "y": 9,
      "z": 3,
      "name": "Rock_Marble"
    },
    {
      "x": 0,
      "y": 6,
      "z": 1,
      "name": "Rock_Marble"
    },
    {
      "x": 0,
      "y": 7,
      "z": 1,
      "name": "Rock_Marble"
    },
    {
      "x": 0,
      "y": 8,
      "z": 1,
      "name": "Rock_Marble"
    },
    {
      "x": 0,
      "y": 9,
      "z": 1,
      "name": "Rock_Marble"
    },
    {
      "x": 0,
      "y": 10,
      "z": 1,
      "name": "Rock_Marble"
    },
    {
      "x": 0,
      "y": 11,
      "z": 1,
      "name": "Rock_Marble"
    },
    {
      "x": 0,
      "y": 6,
      "z": 2,
      "name": "Rock_Marble"
    },
    {
      "x": 0,
      "y": 7,
      "z": 2,
      "name": "Rock_Marble"
    },
    {
      "x": 0,
      "y": 8,
      "z": 2,
      "name": "Rock_Marble"
    },
    {
      "x": 0,
      "y": 9,
      "z": 2,
      "name": "Rock_Marble"
    },
    {
      "x": 0,
      "y": 10,
      "z": 2,
      "name": "Rock_Marble"
    },
    {
      "x": 0,
      "y": 11,
      "z": 2,
      "name": "Rock_Marble"
    },
    {
      "x": 0,
      "y": 6,
      "z": 3,
      "name": "Rock_Marble"
    },
    {
      "x": 0,
      "y": 7,
      "z": 3,
      "name": "Rock_Marble"
    },
    {
      "x": 0,
      "y": 8,
      "z": 3,
      "name": "Rock_Marble"
    },
    {
      "x": 0,
      "y": 9,
      "z": 3,
      "name": "Rock_Marble"
    },
    {
      "x": 1,
      "y": 5,
      "z": -3,
      "name": "Rock_Marble"
    },
    {
      "x": 1,
      "y": 6,
      "z": -3,
      "name": "Rock_Marble"
    },
    {
      "x": 1,
      "y": 7,
      "z": -3,
      "name": "Rock_Marble"
    },
    {
      "x": 1,
      "y": 8,
      "z": -3,
      "name": "Rock_Marble"
    },
    {
      "x": 1,
      "y": 5,
      "z": -2,
      "name": "Rock_Marble"
    },
    {
      "x": 1,
      "y": 6,
      "z": -2,
      "name": "Rock_Marble"
    },
    {
      "x": 1,
      "y": 7,
      "z": -2,
      "name": "Rock_Marble"
    },
    {
      "x": 1,
      "y": 8,
      "z": -2,
      "name": "Rock_Marble"
    },
    {
      "x": 1,
      "y": 6,
      "z": -1,
      "name": "Rock_Marble"
    },
    {
      "x": 1,
      "y": 7,
      "z": -1,
      "name": "Rock_Marble"
    },
    {
      "x": 1,
      "y": 7,
      "z": 1,
      "name": "Rock_Marble"
    },
    {
      "x": 1,
      "y": 8,
      "z": 1,
      "name": "Rock_Marble"
    },
    {
      "x": 1,
      "y": 9,
      "z": 1,
      "name": "Rock_Marble"
    },
    {
      "x": 1,
      "y": 10,
      "z": 1,
      "name": "Rock_Marble"
    },
    {
      "x": 1,
      "y": 6,
      "z": 2,
      "name": "Rock_Marble"
    },
    {
      "x": 1,
      "y": 7,
      "z": 2,
      "name": "Rock_Marble"
    },
    {
      "x": 1,
      "y": 8,
      "z": 2,
      "name": "Rock_Marble"
    },
    {
      "x": 1,
      "y": 9,
      "z": 2,
      "name": "Rock_Marble"
    },
    {
      "x": 1,
      "y": 10,
      "z": 2,
      "name": "Rock_Marble"
    },
    {
      "x": 1,
      "y": 6,
      "z": 3,
      "name": "Rock_Marble"
    },
    {
      "x": 1,
      "y": 7,
      "z": 3,
      "name": "Rock_Marble"
    },
    {
      "x": 1,
      "y": 8,
      "z": 3,
      "name": "Rock_Marble"
    },
    {
      "x": 2,
      "y": 5,
      "z": -4,
      "name": "Rock_Marble"
    },
    {
      "x": 2,
      "y": 6,
      "z": -4,
      "name": "Rock_Marble"
    },
    {
      "x": 2,
      "y": 4,
      "z": -3,
      "name": "Rock_Marble"
    },
    {
      "x": 2,
      "y": 5,
      "z": -3,
      "name": "Rock_Marble"
    },
    {
      "x": 2,
      "y": 6,
      "z": -3,
      "name": "Rock_Marble"
    },
    {
      "x": 2,
      "y": 7,
      "z": -3,
      "name": "Rock_Marble"
    },
    {
      "x": 2,
      "y": 8,
      "z": -3,
      "name": "Rock_Marble"
    },
    {
      "x": 2,
      "y": 4,
      "z": -2,
      "name": "Rock_Marble"
    },
    {
      "x": 2,
      "y": 5,
      "z": -2,
      "name": "Rock_Marble"
    },
    {
      "x": 2,
      "y": 6,
      "z": -2,
      "name": "Rock_Marble"
    },
    {
      "x": 2,
      "y": 7,
      "z": -2,
      "name": "Rock_Marble"
    },
    {
      "x": 2,
      "y": 8,
      "z": -2,
      "name": "Rock_Marble"
    },
    {
      "x": 2,
      "y": 6,
      "z": -1,
      "name": "Rock_Marble"
    },
    {
      "x": 2,
      "y": 7,
      "z": -1,
      "name": "Rock_Marble"
    },
    {
      "x": 2,
      "y": 8,
      "z": -1,
      "name": "Rock_Marble"
    },
    {
      "x": 3,
      "y": 4,
      "z": -4,
      "name": "Rock_Marble"
    },
    {
      "x": 3,
      "y": 5,
      "z": -4,
      "name": "Rock_Marble"
    },
    {
      "x": 3,
      "y": 6,
      "z": -4,
      "name": "Rock_Marble"
    },
    {
      "x": 3,
      "y": 4,
      "z": -3,
      "name": "Rock_Marble"
    },
    {
      "x": 3,
      "y": 5,
      "z": -3,
      "name": "Rock_Marble"
    },
    {
      "x": 3,
      "y": 6,
      "z": -3,
      "name": "Rock_Marble"
    },
    {
      "x": 3,
      "y": 7,
      "z": -3,
      "name": "Rock_Marble"
    },
    {
      "x": 3,
      "y": 4,
      "z": -2,
      "name": "Rock_Marble"
    },
    {
      "x": 3,
      "y": 5,
      "z": -2,
      "name": "Rock_Marble"
    },
    {
      "x": 3,
      "y": 6,
      "z": -2,
      "name": "Rock_Marble"
    },
    {
      "x": 3,
      "y": 7,
      "z": -2,
      "name": "Rock_Marble"
    },
    {
      "x": 3,
      "y": 8,
      "z": -2,
      "name": "Rock_Marble"
    },
    {
      "x": 3,
      "y": 6,
      "z": -1,
      "name": "Rock_Marble"
    },
    {
      "x": 3,
      "y": 7,
      "z": -1,
      "name": "Rock_Marble"
    },
    {
      "x": 3,
      "y": 8,
      "z": -1,
      "name": "Rock_Marble"
    },
    {
      "x": 4,
      "y": 4,
      "z": -4,
      "name": "Rock_Marble"
    },
    {
      "x": 4,
      "y": 5,
      "z": -4,
      "name": "Rock_Marble"
    },
    {
      "x": 4,
      "y": 4,
      "z": -3,
      "name": "Rock_Marble"
    },
    {
      "x": 4,
      "y": 5,
      "z": -3,
      "name": "Rock_Marble"
    },
    {
      "x": 4,
      "y": 6,
      "z": -3,
      "name": "Rock_Marble"
    },
    {
      "x": 4,
      "y": 7,
      "z": -3,
      "name": "Rock_Marble"
    },
    {
      "x": 4,
      "y": 5,
      "z": -2,
      "name": "Rock_Marble"
    },
    {
      "x": 4,
      "y": 6,
      "z": -2,
      "name": "Rock_Marble"
    },
    {
      "x": 4,
      "y": 7,
      "z": -2,
      "name": "Rock_Marble"
    }
  ]
}