{
  "version": 8,
  "blockIdVersion": 8,
  "anchorX": 23,
  "anchorY": 23,
  "anchorZ": 19,
  "blocks": [
    {
      "x": 7,
      "y": 29,
      "z": 28,
      "name": "Rock_Stone"
    },
    {
      "x": 7,
      "y": 30,
      "z": 28,
      "name": "Rock_Stone"
    },
    {
      "x": 7,
      "y": 31,
      "z": 28,
      "name": "Rock_Stone"
    },
    {
      "x": 7,
      "y": 32,
      "z": 28,
      "name": "Rock_Stone"
    },
    {
      "x": 7,
      "y": 26,
      "z": 29,
      "name": "Rock_Stone"
    },
    {
      "x": 7,
      "y": 27,
      "z": 29,
      "name": "Rock_Stone"
    },
    {
      "x": 7,
      "y": 28,
      "z": 29,
      "name": "Rock_Stone"
    },
    {
      "x": 7,
      "y": 29,
      "z": 29,
      "name": "Rock_Stone"
    },
    {
      "x": 7,
      "y": 30,
      "z": 29,
      "name": "Rock_Stone"
    },
    {
      "x": 7,
      "y": 31,
      "z": 29,
      "name": "Rock_Stone"
    },
    {
      "x": 7,
      "y": 32,
      "z": 29,
      "name": "Rock_Stone"
    },
    {
      "x": 7,
      "y": 33,
      "z": 29,
      "name": "Rock_Stone"
    },
    {
      "x": 7,
      "y": 25,
      "z": 30,
      "name": "Rock_Stone"
    },
    {
      "x": 7,
      "y": 26,
      "z": 30,
      "name": "Rock_Stone"
    },
    {
      "x": 7,
      "y": 27,
      "z": 30,
      "name": "Rock_Stone"
    },
    {
      "x": 7,
      "y": 28,
      "z": 30,
      "name": "Rock_Stone"
    },
    {
      "x": 7,
      "y": 29,
      "z": 30,
      "name": "Rock_Stone"
    },
    {
      "x": 7,
      "y": 30,
      "z": 30,
      "name": "Rock_Stone"
    },
    {
      "x": 8,
      "y": 30,
      "z": 27,
      "name": "Rock_Stone"
    },
    {
      "x": 8,
      "y": 31,
      "z": 27,
      "name": "Rock_Stone"
    },
    {
      "x": 8,
      "y": 32,
      "z": 27,
      "name": "Rock_Stone"
    },
    {
      "x": 8,
      "y": 33,
      "z": 27,
      "name": "Rock_Stone"
    },
    {
      "x": 8,
      "y": 23,
      "z": 28,
      "name": "Rock_Stone"
    },
    {
      "x": 8,
      "y": 24,
      "z": 28,
      "name": "Rock_Stone"
    },
    {
      "x": 8,
      "y": 27,
      "z": 28,
      "name": "Rock_Stone"
    },
    {
      "x": 8,
      "y": 28,
      "z": 28,
      "name": "Rock_Stone"
    },
    {
      "x": 8,
      "y": 29,
      "z": 28,
      "name": "Rock_Stone"
    },
    {
      "x": 8,
      "y": 30,
      "z": 28,
      "name": "Rock_Stone"
    },
    {
      "x": 8,
      "y": 31,
      "z": 28,
      "name": "Rock_Stone"
    },
    {
      "x": 8,
      "y": 32,
      "z": 28,
      "name": "Rock_Stone"
    },
    {
      "x": 8,
      "y": 33,
      "z": 28,
      "name": "Rock_Stone"
    },
    {
      "x": 8,
      "y": 34,
      "z": 28,
      "name": "Soil_Dirt"
    },
    {
      "x": 8,
      "y": 35,
      "z": 28,
      "name": "Soil_Grass"
    },
    {
      "x": 8,
      "y": 36,
      "z": 28,
      "name": "Plant_Grass_Lush"
    },
    {
      "x": 8,
      "y": 22,
      "z": 29,
      "name": "Rock_Stone"
    },
    {
      "x": 8,
      "y": 23,
      "z": 29,
      "name": "Rock_Stone"
    },
    {
      "x": 8,
      "y": 24,
      "z": 29,
      "name": "Rock_Stone"
    },
    {
      "x": 8,
      "y": 25,
      "z": 29,
      "name": "Rock_Stone"
    },
    {
      "x": 8,
      "y": 26,
      "z": 29,
      "name": "Rock_Stone"
    },
    {
      "x": 8,
      "y": 27,
      "z": 29,
      "name": "Rock_Stone"
    },
    {
      "x": 8,
      "y": 28,
      "z": 29,
      "name": "Rock_Stone"
    },
    {
      "x": 8,
      "y": 29,
      "z": 29,
      "name": "Rock_Stone"
    },
    {
      "x": 8,
      "y": 30,
      "z": 29,
      "name": "Rock_Stone"
    },
    {
      "x": 8,
      "y": 31,
      "z": 29,
      "name": "Rock_Stone"
    },
    {
      "x": 8,
      "y": 32,
      "z": 29,
      "name": "Rock_Stone"
    },
    {
      "x": 8,
      "y": 33,
      "z": 29,
      "name": "Rock_Stone"
    },
    {
      "x": 8,
      "y": 34,
      "z": 29,
      "name": "Soil_Grass"
    },
    {
      "x": 8,
      "y": 22,
      "z": 30,
      "name": "Rock_Stone"
    },
    {
      "x": 8,
      "y": 23,
      "z": 30,
      "name": "Rock_Stone"
    },
    {
      "x": 8,
      "y": 24,
      "z": 30,
      "name": "Rock_Stone"
    },
    {
      "x": 8,
      "y": 25,
      "z": 30,
      "name": "Rock_Stone"
    },
    {
      "x": 8,
      "y": 26,
      "z": 30,
      "name": "Rock_Stone"
    },
    {
      "x": 8,
      "y": 27,
      "z": 30,
      "name": "Rock_Stone"
    },
    {
      "x": 8,
      "y": 28,
      "z": 30,
      "name": "Rock_Stone"
    },
    {
      "x": 8,
      "y": 29,
      "z": 30,
      "name": "Rock_Stone"
    },
    {
      "x": 8,
      "y": 30,
      "z": 30,
      "name": "Rock_Stone"
    },
    {
      "x": 8,
      "y": 31,
      "z": 30,
      "name": "Rock_Stone"
    },
    {
      "x": 8,
      "y": 32,
      "z": 30,
      "name": "Soil_Dirt"
    },
    {
      "x": 8,
      "y": 33,
      "z": 30,
      "name": "Soil_Grass"
    },
    {
      "x": 8,
      "y": 23,
      "z": 31,
      "name": "Rock_Stone"
    },
    {
      "x": 8,
      "y": 24,
      "z": 31,
      "name": "Rock_Stone"
    },
    {
      "x": 8,
      "y": 25,
      "z": 31,
      "name": "Rock_Stone"
    },
    {
      "x": 8,
      "y": 26,
      "z": 31,
      "name": "Rock_Stone"
    },
    {
      "x": 8,
      "y": 27,
      "z": 31,
      "name": "Rock_Stone"
    },
    {
      "x": 8,
      "y": 28,
      "z": 31,
      "name": "Rock_Stone"
    },
    {
      "x": 8,
      "y": 29,
      "z": 31,
      "name": "Rock_Stone"
    },
    {
      "x": 8,
      "y": 30,
      "z": 31,
      "name": "Rock_Stone"
    },
    {
      "x": 8,
      "y": 31,
      "z": 31,
      "name": "Rock_Stone"
    },
    {
      "x": 8,
      "y": 32,
      "z": 31,
      "name": "Soil_Dirt"
    },
    {
      "x": 8,
      "y": 33,
      "z": 31,
      "name": "Soil_Grass"
    },
    {
      "x": 8,
      "y": 34,
      "z": 31,
      "name": "Plant_Grass_Sharp"
    },
    {
      "x": 8,
      "y": 25,
      "z": 32,
      "name": "Rock_Stone"
    },
    {
      "x": 8,
      "y": 26,
      "z": 32,
      "name": "Rock_Stone"
    },
    {
      "x": 8,
      "y": 27,
      "z": 32,
      "name": "Rock_Stone"
    },
    {
      "x": 8,
      "y": 28,
      "z": 32,
      "name": "Rock_Stone"
    },
    {
      "x": 8,
      "y": 29,
      "z": 32,
      "name": "Rock_Stone"
    },
    {
      "x": 8,
      "y": 30,
      "z": 32,
      "name": "Rock_Stone"
    },
    {
      "x": 9,
      "y": 20,
      "z": 26,
      "name": "Rock_Stone"
    },
    {
      "x": 9,
      "y": 21,
      "z": 26,
      "name": "Rock_Stone"
    },
    {
      "x": 9,
      "y": 22,
      "z": 26,
      "name": "Rock_Stone"
    },
    {
      "x": 9,
      "y": 33,
      "z": 26,
      "name": "Rock_Stone"
    },
    {
      "x": 9,
      "y": 34,
      "z": 26,
      "name": "Soil_Dirt"
    },
    {
      "x": 9,
      "y": 19,
      "z": 27,
      "name": "Rock_Stone"
    },
    {
      "x": 9,
      "y": 20,
      "z": 27,
      "name": "Rock_Stone"
    },
    {
      "x": 9,
      "y": 21,
      "z": 27,
      "name": "Rock_Stone"
    },
    {
      "x": 9,
      "y": 22,
      "z": 27,
      "name": "Rock_Stone"
    },
    {
      "x": 9,
      "y": 23,
      "z": 27,
      "name": "Rock_Stone"
    },
    {
      "x": 9,
      "y": 24,
      "z": 27,
      "name": "Rock_Stone"
    },
    {
      "x": 9,
      "y": 25,
      "z": 27,
      "name": "Rock_Stone"
    },
    {
      "x": 9,
      "y": 28,
      "z": 27,
      "name": "Rock_Stone"
    },
    {
      "x": 9,
      "y": 29,
      "z": 27,
      "name": "Rock_Stone"
    },
    {
      "x": 9,
      "y": 30,
      "z": 27,
      "name": "Rock_Stone"
    },
    {
      "x": 9,
      "y": 31,
      "z": 27,
      "name": "Rock_Stone"
    },
    {
      "x": 9,
      "y": 32,
      "z": 27,
      "name": "Rock_Stone"
    },
    {
      "x": 9,
      "y": 33,
      "z": 27,
      "name": "Rock_Stone"
    },
    {
      "x": 9,
      "y": 34,
      "z": 27,
      "name": "Soil_Dirt"
    },
    {
      "x": 9,
      "y": 35,
      "z": 27,
      "name": "Soil_Dirt"
    },
    {
      "x": 9,
      "y": 36,
      "z": 27,
      "name": "Soil_Grass"
    },
    {
      "x": 9,
      "y": 19,
      "z": 28,
      "name": "Rock_Stone"
    },
    {
      "x": 9,
      "y": 20,
      "z": 28,
      "name": "Rock_Stone"
    },
    {
      "x": 9,
      "y": 21,
      "z": 28,
      "name": "Rock_Stone"
    },
    {
      "x": 9,
      "y": 22,
      "z": 28,
      "name": "Rock_Stone"
    },
    {
      "x": 9,
      "y": 23,
      "z": 28,
      "name": "Rock_Stone"
    },
    {
      "x": 9,
      "y": 24,
      "z": 28,
      "name": "Rock_Stone"
    },
    {
      "x": 9,
      "y": 25,
      "z": 28,
      "name": "Rock_Stone"
    },
    {
      "x": 9,
      "y": 26,
      "z": 28,
      "name": "Rock_Stone"
    },
    {
      "x": 9,
      "y": 27,
      "z": 28,
      "name": "Rock_Stone"
    },
    {
      "x": 9,
      "y": 28,
      "z": 28,
      "name": "Rock_Stone"
    },
    {
      "x": 9,
      "y": 29,
      "z": 28,
      "name": "Rock_Stone"
    },
    {
      "x": 9,
      "y": 30,
      "z": 28,
      "name": "Rock_Stone"
    },
    {
      "x": 9,
      "y": 31,
      "z": 28,
      "name": "Rock_Stone"
    },
    {
      "x": 9,
      "y": 32,
      "z": 28,
      "name": "Rock_Stone"
    },
    {
      "x": 9,
      "y": 33,
      "z": 28,
      "name": "Soil_Dirt"
    },
    {
      "x": 9,
      "y": 34,
      "z": 28,
      "name": "Soil_Dirt"
    },
    {
      "x": 9,
      "y": 35,
      "z": 28,
      "name": "Soil_Dirt"
    },
    {
      "x": 9,
      "y": 36,
      "z": 28,
      "name": "Soil_Grass"
    },
    {
      "x": 9,
      "y": 37,
      "z": 28,
      "name": "Plant_Bush_Green"
    },
    {
      "x": 9,
      "y": 38,
      "z": 28,
      "name": "Plant_Bush_Green",
      "filler": 1024
    },
    {
      "x": 9,
      "y": 20,
      "z": 29,
      "name": "Rock_Stone"
    },
    {
      "x": 9,
      "y": 21,
      "z": 29,
      "name": "Rock_Stone"
    },
    {
      "x": 9,
      "y": 22,
      "z": 29,
      "name": "Rock_Stone"
    },
    {
      "x": 9,
      "y": 23,
      "z": 29,
      "name": "Rock_Stone"
    },
    {
      "x": 9,
      "y": 24,
      "z": 29,
      "name": "Rock_Stone"
    },
    {
      "x": 9,
      "y": 25,
      "z": 29,
      "name": "Rock_Stone"
    },
    {
      "x": 9,
      "y": 26,
      "z": 29,
      "name": "Rock_Stone"
    },
    {
      "x": 9,
      "y": 27,
      "z": 29,
      "name": "Rock_Stone"
    },
    {
      "x": 9,
      "y": 28,
      "z": 29,
      "name": "Rock_Stone"
    },
    {
      "x": 9,
      "y": 29,
      "z": 29,
      "name": "Rock_Stone"
    },
    {
      "x": 9,
      "y": 30,
      "z": 29,
      "name": "Rock_Stone"
    },
    {
      "x": 9,
      "y": 31,
      "z": 29,
      "name": "Rock_Stone"
    },
    {
      "x": 9,
      "y": 32,
      "z": 29,
      "name": "Rock_Stone"
    },
    {
      "x": 9,
      "y": 33,
      "z": 29,
      "name": "Rock_Stone"
    },
    {
      "x": 9,
      "y": 34,
      "z": 29,
      "name": "Soil_Dirt"
    },
    {
      "x": 9,
      "y": 35,
      "z": 29,
      "name": "Soil_Dirt"
    },
    {
      "x": 9,
      "y": 36,
      "z": 29,
      "name": "Soil_Grass"
    },
    {
      "x": 9,
      "y": 37,
      "z": 29,
      "name": "Plant_Grass_Sharp"
    },
    {
      "x": 9,
      "y": 21,
      "z": 30,
      "name": "Rock_Stone"
    },
    {
      "x": 9,
      "y": 22,
      "z": 30,
      "name": "Rock_Stone"
    },
    {
      "x": 9,
      "y": 23,
      "z": 30,
      "name": "Rock_Stone"
    },
    {
      "x": 9,
      "y": 24,
      "z": 30,
      "name": "Rock_Stone"
    },
    {
      "x": 9,
      "y": 25,
      "z": 30,
      "name": "Rock_Stone"
    },
    {
      "x": 9,
      "y": 26,
      "z": 30,
      "name": "Rock_Stone"
    },
    {
      "x": 9,
      "y": 27,
      "z": 30,
      "name": "Rock_Stone"
    },
    {
      "x": 9,
      "y": 28,
      "z": 30,
      "name": "Rock_Stone"
    },
    {
      "x": 9,
      "y": 29,
      "z": 30,
      "name": "Rock_Stone"
    },
    {
      "x": 9,
      "y": 30,
      "z": 30,
      "name": "Rock_Stone"
    },
    {
      "x": 9,
      "y": 31,
      "z": 30,
      "name": "Rock_Stone"
    },
    {
      "x": 9,
      "y": 32,
      "z": 30,
      "name": "Soil_Dirt"
    },
    {
      "x": 9,
      "y": 33,
      "z": 30,
      "name": "Soil_Dirt"
    },
    {
      "x": 9,
      "y": 34,
      "z": 30,
      "name": "Soil_Dirt"
    },
    {
      "x": 9,
      "y": 35,
      "z": 30,
      "name": "Soil_Grass"
    },
    {
      "x": 9,
      "y": 36,
      "z": 30,
      "name": "Plant_Grass_Sharp"
    },
    {
      "x": 9,
      "y": 22,
      "z": 31,
      "name": "Rock_Stone"
    },
    {
      "x": 9,
      "y": 23,
      "z": 31,
      "name": "Rock_Stone"
    },
    {
      "x": 9,
      "y": 24,
      "z": 31,
      "name": "Rock_Stone"
    },
    {
      "x": 9,
      "y": 25,
      "z": 31,
      "name": "Rock_Stone"
    },
    {
      "x": 9,
      "y": 26,
      "z": 31,
      "name": "Rock_Stone"
    },
    {
      "x": 9,
      "y": 27,
      "z": 31,
      "name": "Rock_Stone"
    },
    {
      "x": 9,
      "y": 28,
      "z": 31,
      "name": "Rock_Stone"
    },
    {
      "x": 9,
      "y": 29,
      "z": 31,
      "name": "Rock_Stone"
    },
    {
      "x": 9,
      "y": 30,
      "z": 31,
      "name": "Rock_Stone"
    },
    {
      "x": 9,
      "y": 31,
      "z": 31,
      "name": "Rock_Stone"
    },
    {
      "x": 9,
      "y": 32,
      "z": 31,
      "name": "Soil_Dirt"
    },
    {
      "x": 9,
      "y": 33,
      "z": 31,
      "name": "Soil_Dirt"
    },
    {
      "x": 9,
      "y": 34,
      "z": 31,
      "name": "Soil_Grass"
    },
    {
      "x": 9,
      "y": 35,
      "z": 31,
      "name": "Plant_Grass_Sharp"
    },
    {
      "x": 9,
      "y": 24,
      "z": 32,
      "name": "Rock_Stone"
    },
    {
      "x": 9,
      "y": 25,
      "z": 32,
      "name": "Rock_Stone"
    },
    {
      "x": 9,
      "y": 26,
      "z": 32,
      "name": "Rock_Stone"
    },
    {
      "x": 9,
      "y": 27,
      "z": 32,
      "name": "Rock_Stone"
    },
    {
      "x": 9,
      "y": 28,
      "z": 32,
      "name": "Rock_Stone"
    },
    {
      "x": 9,
      "y": 29,
      "z": 32,
      "name": "Rock_Stone"
    },
    {
      "x": 9,
      "y": 30,
      "z": 32,
      "name": "Rock_Stone"
    },
    {
      "x": 9,
      "y": 31,
      "z": 32,
      "name": "Soil_Dirt"
    },
    {
      "x": 9,
      "y": 32,
      "z": 32,
      "name": "Soil_Dirt"
    },
    {
      "x": 9,
      "y": 33,
      "z": 32,
      "name": "Soil_Dirt"
    },
    {
      "x": 9,
      "y": 34,
      "z": 32,
      "name": "Soil_Grass"
    },
    {
      "x": 10,
      "y": 19,
      "z": 26,
      "name": "Rock_Stone"
    },
    {
      "x": 10,
      "y": 20,
      "z": 26,
      "name": "Rock_Stone"
    },
    {
      "x": 10,
      "y": 21,
      "z": 26,
      "name": "Rock_Stone"
    },
    {
      "x": 10,
      "y": 22,
      "z": 26,
      "name": "Rock_Stone"
    },
    {
      "x": 10,
      "y": 23,
      "z": 26,
      "name": "Rock_Stone"
    },
    {
      "x": 10,
      "y": 32,
      "z": 26,
      "name": "Rock_Stone"
    },
    {
      "x": 10,
      "y": 33,
      "z": 26,
      "name": "Rock_Stone"
    },
    {
      "x": 10,
      "y": 34,
      "z": 26,
      "name": "Soil_Dirt"
    },
    {
      "x": 10,
      "y": 35,
      "z": 26,
      "name": "Soil_Grass"
    },
    {
      "x": 10,
      "y": 19,
      "z": 27,
      "name": "Rock_Stone"
    },
    {
      "x": 10,
      "y": 20,
      "z": 27,
      "name": "Rock_Stone"
    },
    {
      "x": 10,
      "y": 21,
      "z": 27,
      "name": "Rock_Stone"
    },
    {
      "x": 10,
      "y": 22,
      "z": 27,
      "name": "Rock_Stone"
    },
    {
      "x": 10,
      "y": 23,
      "z": 27,
      "name": "Rock_Stone"
    },
    {
      "x": 10,
      "y": 24,
      "z": 27,
      "name": "Rock_Stone"
    },
    {
      "x": 10,
      "y": 25,
      "z": 27,
      "name": "Rock_Stone"
    },
    {
      "x": 10,
      "y": 29,
      "z": 27,
      "name": "Rock_Stone"
    },
    {
      "x": 10,
      "y": 30,
      "z": 27,
      "name": "Rock_Stone"
    },
    {
      "x": 10,
      "y": 31,
      "z": 27,
      "name": "Rock_Stone"
    },
    {
      "x": 10,
      "y": 32,
      "z": 27,
      "name": "Rock_Stone"
    },
    {
      "x": 10,
      "y": 33,
      "z": 27,
      "name": "Rock_Stone"
    },
    {
      "x": 10,
      "y": 34,
      "z": 27,
      "name": "Soil_Dirt"
    },
    {
      "x": 10,
      "y": 35,
      "z": 27,
      "name": "Soil_Dirt"
    },
    {
      "x": 10,
      "y": 36,
      "z": 27,
      "name": "Soil_Grass"
    },
    {
      "x": 10,
      "y": 20,
      "z": 28,
      "name": "Rock_Stone"
    },
    {
      "x": 10,
      "y": 21,
      "z": 28,
      "name": "Rock_Stone"
    },
    {
      "x": 10,
      "y": 22,
      "z": 28,
      "name": "Rock_Stone"
    },
    {
      "x": 10,
      "y": 23,
      "z": 28,
      "name": "Rock_Stone"
    },
    {
      "x": 10,
      "y": 24,
      "z": 28,
      "name": "Rock_Stone"
    },
    {
      "x": 10,
      "y": 25,
      "z": 28,
      "name": "Rock_Stone"
    },
    {
      "x": 10,
      "y": 26,
      "z": 28,
      "name": "Rock_Stone"
    },
    {
      "x": 10,
      "y": 27,
      "z": 28,
      "name": "Rock_Stone"
    },
    {
      "x": 10,
      "y": 28,
      "z": 28,
      "name": "Rock_Stone"
    },
    {
      "x": 10,
      "y": 29,
      "z": 28,
      "name": "Rock_Stone"
    },
    {
      "x": 10,
      "y": 30,
      "z": 28,
      "name": "Rock_Stone"
    },
    {
      "x": 10,
      "y": 31,
      "z": 28,
      "name": "Rock_Stone"
    },
    {
      "x": 10,
      "y": 32,
      "z": 28,
      "name": "Rock_Stone"
    },
    {
      "x": 10,
      "y": 33,
      "z": 28,
      "name": "Rock_Stone"
    },
    {
      "x": 10,
      "y": 34,
      "z": 28,
      "name": "Soil_Dirt"
    },
    {
      "x": 10,
      "y": 35,
      "z": 28,
      "name": "Soil_Dirt"
    },
    {
      "x": 10,
      "y": 36,
      "z": 28,
      "name": "Soil_Dirt"
    },
    {
      "x": 10,
      "y": 37,
      "z": 28,
      "name": "Soil_Leaves"
    },
    {
      "x": 10,
      "y": 19,
      "z": 29,
      "name": "Rock_Stone"
    },
    {
      "x": 10,
      "y": 20,
      "z": 29,
      "name": "Rock_Stone"
    },
    {
      "x": 10,
      "y": 21,
      "z": 29,
      "name": "Rock_Stone"
    },
    {
      "x": 10,
      "y": 22,
      "z": 29,
      "name": "Rock_Stone"
    },
    {
      "x": 10,
      "y": 23,
      "z": 29,
      "name": "Rock_Stone"
    },
    {
      "x": 10,
      "y": 24,
      "z": 29,
      "name": "Rock_Stone"
    },
    {
      "x": 10,
      "y": 25,
      "z": 29,
      "name": "Rock_Stone"
    },
    {
      "x": 10,
      "y": 26,
      "z": 29,
      "name": "Rock_Stone"
    },
    {
      "x": 10,
      "y": 27,
      "z": 29,
      "name": "Rock_Stone"
    },
    {
      "x": 10,
      "y": 28,
      "z": 29,
      "name": "Rock_Stone"
    },
    {
      "x": 10,
      "y": 29,
      "z": 29,
      "name": "Rock_Stone"
    },
    {
      "x": 10,
      "y": 30,
      "z": 29,
      "name": "Rock_Stone"
    },
    {
      "x": 10,
      "y": 31,
      "z": 29,
      "name": "Rock_Stone"
    },
    {
      "x": 10,
      "y": 32,
      "z": 29,
      "name": "Rock_Stone"
    },
    {
      "x": 10,
      "y": 33,
      "z": 29,
      "name": "Rock_Stone"
    },
    {
      "x": 10,
      "y": 34,
      "z": 29,
      "name": "Soil_Dirt"
    },
    {
      "x": 10,
      "y": 35,
      "z": 29,
      "name": "Soil_Dirt"
    },
    {
      "x": 10,
      "y": 36,
      "z": 29,
      "name": "Soil_Dirt"
    },
    {
      "x": 10,
      "y": 37,
      "z": 29,
      "name": "Soil_Leaves"
    },
    {
      "x": 10,
      "y": 38,
      "z": 29,
      "name": "Plant_Grass_Sharp"
    },
    {
      "x": 10,
      "y": 21,
      "z": 30,
      "name": "Rock_Stone"
    },
    {
      "x": 10,
      "y": 22,
      "z": 30,
      "name": "Rock_Stone"
    },
    {
      "x": 10,
      "y": 23,
      "z": 30,
      "name": "Rock_Stone"
    },
    {
      "x": 10,
      "y": 24,
      "z": 30,
      "name": "Rock_Stone"
    },
    {
      "x": 10,
      "y": 25,
      "z": 30,
      "name": "Rock_Stone"
    },
    {
      "x": 10,
      "y": 26,
      "z": 30,
      "name": "Rock_Stone"
    },
    {
      "x": 10,
      "y": 27,
      "z": 30,
      "name": "Rock_Stone"
    },
    {
      "x": 10,
      "y": 28,
      "z": 30,
      "name": "Rock_Stone"
    },
    {
      "x": 10,
      "y": 29,
      "z": 30,
      "name": "Rock_Stone"
    },
    {
      "x": 10,
      "y": 30,
      "z": 30,
      "name": "Rock_Stone"
    },
    {
      "x": 10,
      "y": 31,
      "z": 30,
      "name": "Rock_Stone"
    },
    {
      "x": 10,
      "y": 32,
      "z": 30,
      "name": "Soil_Dirt"
    },
    {
      "x": 10,
      "y": 33,
      "z": 30,
      "name": "Soil_Dirt"
    },
    {
      "x": 10,
      "y": 34,
      "z": 30,
      "name": "Soil_Dirt"
    },
    {
      "x": 10,
      "y": 35,
      "z": 30,
      "name": "Soil_Dirt"
    },
    {
      "x": 10,
      "y": 36,
      "z": 30,
      "name": "Soil_Dirt"
    },
    {
      "x": 10,
      "y": 37,
      "z": 30,
      "name": "Soil_Leaves"
    },
    {
      "x": 10,
      "y": 22,
      "z": 31,
      "name": "Rock_Stone"
    },
    {
      "x": 10,
      "y": 23,
      "z": 31,
      "name": "Rock_Stone"
    },
    {
      "x": 10,
      "y": 24,
      "z": 31,
      "name": "Rock_Stone"
    },
    {
      "x": 10,
      "y": 25,
      "z": 31,
      "name": "Rock_Stone"
    },
    {
      "x": 10,
      "y": 26,
      "z": 31,
      "name": "Rock_Stone"
    },
    {
      "x": 10,
      "y": 27,
      "z": 31,
      "name": "Rock_Stone"
    },
    {
      "x": 10,
      "y": 28,
      "z": 31,
      "name": "Rock_Stone"
    },
    {
      "x": 10,
      "y": 29,
      "z": 31,
      "name": "Rock_Stone"
    },
    {
      "x": 10,
      "y": 30,
      "z": 31,
      "name": "Rock_Stone"
    },
    {
      "x": 10,
      "y": 31,
      "z": 31,
      "name": "Rock_Stone"
    },
    {
      "x": 10,
      "y": 32,
      "z": 31,
      "name": "Soil_Dirt"
    },
    {
      "x": 10,
      "y": 33,
      "z": 31,
      "name": "Soil_Dirt"
    },
    {
      "x": 10,
      "y": 34,
      "z": 31,
      "name": "Soil_Dirt"
    },
    {
      "x": 10,
      "y": 35,
      "z": 31,
      "name": "Soil_Dirt"
    },
    {
      "x": 10,
      "y": 36,
      "z": 31,
      "name": "Soil_Leaves"
    },
    {
      "x": 10,
      "y": 37,
      "z": 31,
      "name": "Plant_Grass_Lush"
    },
    {
      "x": 10,
      "y": 24,
      "z": 32,
      "name": "Rock_Stone"
    },
    {
      "x": 10,
      "y": 25,
      "z": 32,
      "name": "Rock_Stone"
    },
    {
      "x": 10,
      "y": 26,
      "z": 32,
      "name": "Rock_Stone"
    },
    {
      "x": 10,
      "y": 27,
      "z": 32,
      "name": "Rock_Stone"
    },
    {
      "x": 10,
      "y": 28,
      "z": 32,
      "name": "Rock_Stone"
    },
    {
      "x": 10,
      "y": 29,
      "z": 32,
      "name": "Rock_Stone"
    },
    {
      "x": 10,
      "y": 30,
      "z": 32,
      "name": "Rock_Stone"
    },
    {
      "x": 10,
      "y": 31,
      "z": 32,
      "name": "Rock_Stone"
    },
    {
      "x": 10,
      "y": 32,
      "z": 32,
      "name": "Soil_Dirt"
    },
    {
      "x": 10,
      "y": 33,
      "z": 32,
      "name": "Soil_Dirt"
    },
    {
      "x": 10,
      "y": 34,
      "z": 32,
      "name": "Soil_Dirt"
    },
    {
      "x": 10,
      "y": 35,
      "z": 32,
      "name": "Soil_Grass"
    },
    {
      "x": 10,
      "y": 36,
      "z": 32,
      "name": "Plant_Grass_Lush"
    },
    {
      "x": 10,
      "y": 31,
      "z": 33,
      "name": "Rock_Stone"
    },
    {
      "x": 10,
      "y": 32,
      "z": 33,
      "name": "Soil_Dirt"
    },
    {
      "x": 11,
      "y": 18,
      "z": 25,
      "name": "Rock_Stone"
    },
    {
      "x": 11,
      "y": 19,
      "z": 25,
      "name": "Rock_Stone"
    },
    {
      "x": 11,
      "y": 20,
      "z": 25,
      "name": "Rock_Stone"
    },
    {
      "x": 11,
      "y": 21,
      "z": 25,
      "name": "Rock_Stone"
    },
    {
      "x": 11,
      "y": 35,
      "z": 25,
      "name": "Rock_Stone"
    },
    {
      "x": 11,
      "y": 36,
      "z": 25,
      "name": "Soil_Grass"
    },
    {
      "x": 11,
      "y": 18,
      "z": 26,
      "name": "Rock_Stone"
    },
    {
      "x": 11,
      "y": 19,
      "z": 26,
      "name": "Rock_Stone"
    },
    {
      "x": 11,
      "y": 20,
      "z": 26,
      "name": "Rock_Stone"
    },
    {
      "x": 11,
      "y": 21,
      "z": 26,
      "name": "Rock_Stone"
    },
    {
      "x": 11,
      "y": 22,
      "z": 26,
      "name": "Rock_Stone"
    },
    {
      "x": 11,
      "y": 32,
      "z": 26,
      "name": "Rock_Stone"
    },
    {
      "x": 11,
      "y": 33,
      "z": 26,
      "name": "Rock_Stone"
    },
    {
      "x": 11,
      "y": 34,
      "z": 26,
      "name": "Rock_Stone"
    },
    {
      "x": 11,
      "y": 35,
      "z": 26,
      "name": "Soil_Dirt"
    },
    {
      "x": 11,
      "y": 36,
      "z": 26,
      "name": "Soil_Dirt"
    },
    {
      "x": 11,
      "y": 37,
      "z": 26,
      "name": "Soil_Pathway"
    },
    {
      "x": 11,
      "y": 19,
      "z": 27,
      "name": "Rock_Stone"
    },
    {
      "x": 11,
      "y": 20,
      "z": 27,
      "name": "Rock_Stone"
    },
    {
      "x": 11,
      "y": 21,
      "z": 27,
      "name": "Rock_Stone"
    },
    {
      "x": 11,
      "y": 22,
      "z": 27,
      "name": "Rock_Stone"
    },
    {
      "x": 11,
      "y": 23,
      "z": 27,
      "name": "Rock_Stone"
    },
    {
      "x": 11,
      "y": 24,
      "z": 27,
      "name": "Rock_Stone"
    },
    {
      "x": 11,
      "y": 31,
      "z": 27,
      "name": "Rock_Stone"
    },
    {
      "x": 11,
      "y": 32,
      "z": 27,
      "name": "Rock_Stone"
    },
    {
      "x": 11,
      "y": 33,
      "z": 27,
      "name": "Rock_Stone"
    },
    {
      "x": 11,
      "y": 34,
      "z": 27,
      "name": "Soil_Dirt"
    },
    {
      "x": 11,
      "y": 35,
      "z": 27,
      "name": "Soil_Dirt"
    },
    {
      "x": 11,
      "y": 36,
      "z": 27,
      "name": "Soil_Dirt"
    },
    {
      "x": 11,
      "y": 37,
      "z": 27,
      "name": "Soil_Pathway"
    },
    {
      "x": 11,
      "y": 19,
      "z": 28,
      "name": "Rock_Stone"
    },
    {
      "x": 11,
      "y": 20,
      "z": 28,
      "name": "Rock_Stone"
    },
    {
      "x": 11,
      "y": 21,
      "z": 28,
      "name": "Rock_Stone"
    },
    {
      "x": 11,
      "y": 22,
      "z": 28,
      "name": "Rock_Stone"
    },
    {
      "x": 11,
      "y": 23,
      "z": 28,
      "name": "Rock_Stone"
    },
    {
      "x": 11,
      "y": 24,
      "z": 28,
      "name": "Rock_Stone"
    },
    {
      "x": 11,
      "y": 25,
      "z": 28,
      "name": "Rock_Stone"
    },
    {
      "x": 11,
      "y": 30,
      "z": 28,
      "name": "Rock_Stone"
    },
    {
      "x": 11,
      "y": 31,
      "z": 28,
      "name": "Rock_Stone"
    },
    {
      "x": 11,
      "y": 32,
      "z": 28,
      "name": "Rock_Stone"
    },
    {
      "x": 11,
      "y": 33,
      "z": 28,
      "name": "Rock_Stone"
    },
    {
      "x": 11,
      "y": 34,
      "z": 28,
      "name": "Soil_Dirt"
    },
    {
      "x": 11,
      "y": 35,
      "z": 28,
      "name": "Soil_Dirt"
    },
    {
      "x": 11,
      "y": 36,
      "z": 28,
      "name": "Soil_Dirt"
    },
    {
      "x": 11,
      "y": 37,
      "z": 28,
      "name": "Soil_Pathway"
    },
    {
      "x": 11,
      "y": 38,
      "z": 28,
      "name": "Plant_Grass_Sharp"
    },
    {
      "x": 11,
      "y": 19,
      "z": 29,
      "name": "Rock_Stone"
    },
    {
      "x": 11,
      "y": 20,
      "z": 29,
      "name": "Rock_Stone"
    },
    {
      "x": 11,
      "y": 21,
      "z": 29,
      "name": "Rock_Stone"
    },
    {
      "x": 11,
      "y": 22,
      "z": 29,
      "name": "Rock_Stone"
    },
    {
      "x": 11,
      "y": 23,
      "z": 29,
      "name": "Rock_Stone"
    },
    {
      "x": 11,
      "y": 24,
      "z": 29,
      "name": "Rock_Stone"
    },
    {
      "x": 11,
      "y": 25,
      "z": 29,
      "name": "Rock_Stone"
    },
    {
      "x": 11,
      "y": 26,
      "z": 29,
      "name": "Rock_Stone"
    },
    {
      "x": 11,
      "y": 27,
      "z": 29,
      "name": "Rock_Stone"
    },
    {
      "x": 11,
      "y": 28,
      "z": 29,
      "name": "Rock_Stone"
    },
    {
      "x": 11,
      "y": 29,
      "z": 29,
      "name": "Rock_Stone"
    },
    {
      "x": 11,
      "y": 30,
      "z": 29,
      "name": "Rock_Stone"
    },
    {
      "x": 11,
      "y": 31,
      "z": 29,
      "name": "Rock_Stone"
    },
    {
      "x": 11,
      "y": 32,
      "z": 29,
      "name": "Rock_Stone"
    },
    {
      "x": 11,
      "y": 33,
      "z": 29,
      "name": "Rock_Stone"
    },
    {
      "x": 11,
      "y": 34,
      "z": 29,
      "name": "Soil_Dirt"
    },
    {
      "x": 11,
      "y": 35,
      "z": 29,
      "name": "Soil_Dirt"
    },
    {
      "x": 11,
      "y": 36,
      "z": 29,
      "name": "Soil_Dirt"
    },
    {
      "x": 11,
      "y": 37,
      "z": 29,
      "name": "Soil_Pathway"
    },
    {
      "x": 11,
      "y": 23,
      "z": 30,
      "name": "Rock_Stone"
    },
    {
      "x": 11,
      "y": 24,
      "z": 30,
      "name": "Rock_Stone"
    },
    {
      "x": 11,
      "y": 25,
      "z": 30,
      "name": "Rock_Stone"
    },
    {
      "x": 11,
      "y": 26,
      "z": 30,
      "name": "Rock_Stone"
    },
    {
      "x": 11,
      "y": 27,
      "z": 30,
      "name": "Rock_Stone"
    },
    {
      "x": 11,
      "y": 28,
      "z": 30,
      "name": "Rock_Stone"
    },
    {
      "x": 11,
      "y": 29,
      "z": 30,
      "name": "Rock_Stone"
    },
    {
      "x": 11,
      "y": 30,
      "z": 30,
      "name": "Rock_Stone"
    },
    {
      "x": 11,
      "y": 31,
      "z": 30,
      "name": "Rock_Stone"
    },
    {
      "x": 11,
      "y": 32,
      "z": 30,
      "name": "Rock_Stone"
    },
    {
      "x": 11,
      "y": 33,
      "z": 30,
      "name": "Soil_Dirt"
    },
    {
      "x": 11,
      "y": 34,
      "z": 30,
      "name": "Soil_Dirt"
    },
    {
      "x": 11,
      "y": 35,
      "z": 30,
      "name": "Soil_Dirt"
    },
    {
      "x": 11,
      "y": 36,
      "z": 30,
      "name": "Soil_Dirt"
    },
    {
      "x": 11,
      "y": 37,
      "z": 30,
      "name": "Soil_Pathway"
    },
    {
      "x": 11,
      "y": 38,
      "z": 30,
      "name": "Plant_Grass_Sharp"
    },
    {
      "x": 11,
      "y": 25,
      "z": 31,
      "name": "Rock_Stone"
    },
    {
      "x": 11,
      "y": 26,
      "z": 31,
      "name": "Rock_Stone"
    },
    {
      "x": 11,
      "y": 27,
      "z": 31,
      "name": "Rock_Stone"
    },
    {
      "x": 11,
      "y": 28,
      "z": 31,
      "name": "Rock_Stone"
    },
    {
      "x": 11,
      "y": 29,
      "z": 31,
      "name": "Rock_Stone"
    },
    {
      "x": 11,
      "y": 30,
      "z": 31,
      "name": "Rock_Stone"
    },
    {
      "x": 11,
      "y": 31,
      "z": 31,
      "name": "Rock_Stone"
    },
    {
      "x": 11,
      "y": 32,
      "z": 31,
      "name": "Soil_Dirt"
    },
    {
      "x": 11,
      "y": 33,
      "z": 31,
      "name": "Soil_Dirt"
    },
    {
      "x": 11,
      "y": 34,
      "z": 31,
      "name": "Soil_Dirt"
    },
    {
      "x": 11,
      "y": 35,
      "z": 31,
      "name": "Soil_Dirt"
    },
    {
      "x": 11,
      "y": 36,
      "z": 31,
      "name": "Soil_Dirt"
    },
    {
      "x": 11,
      "y": 37,
      "z": 31,
      "name": "Soil_Pathway"
    },
    {
      "x": 11,
      "y": 29,
      "z": 32,
      "name": "Rock_Stone"
    },
    {
      "x": 11,
      "y": 30,
      "z": 32,
      "name": "Rock_Stone"
    },
    {
      "x": 11,
      "y": 31,
      "z": 32,
      "name": "Rock_Stone"
    },
    {
      "x": 11,
      "y": 32,
      "z": 32,
      "name": "Soil_Dirt"
    },
    {
      "x": 11,
      "y": 33,
      "z": 32,
      "name": "Soil_Dirt"
    },
    {
      "x": 11,
      "y": 34,
      "z": 32,
      "name": "Soil_Dirt"
    },
    {
      "x": 11,
      "y": 35,
      "z": 32,
      "name": "Soil_Grass"
    },
    {
      "x": 11,
      "y": 31,
      "z": 33,
      "name": "Rock_Stone"
    },
    {
      "x": 11,
      "y": 32,
      "z": 33,
      "name": "Soil_Dirt"
    },
    {
      "x": 11,
      "y": 33,
      "z": 33,
      "name": "Soil_Dirt"
    },
    {
      "x": 11,
      "y": 34,
      "z": 33,
      "name": "Soil_Grass"
    },
    {
      "x": 12,
      "y": 16,
      "z": 24,
      "name": "Rock_Stone"
    },
    {
      "x": 12,
      "y": 17,
      "z": 24,
      "name": "Rock_Stone"
    },
    {
      "x": 12,
      "y": 18,
      "z": 24,
      "name": "Rock_Stone"
    },
    {
      "x": 12,
      "y": 19,
      "z": 24,
      "name": "Rock_Stone"
    },
    {
      "x": 12,
      "y": 16,
      "z": 25,
      "name": "Rock_Stone"
    },
    {
      "x": 12,
      "y": 17,
      "z": 25,
      "name": "Rock_Stone"
    },
    {
      "x": 12,
      "y": 18,
      "z": 25,
      "name": "Rock_Stone"
    },
    {
      "x": 12,
      "y": 19,
      "z": 25,
      "name": "Rock_Stone"
    },
    {
      "x": 12,
      "y": 20,
      "z": 25,
      "name": "Rock_Stone"
    },
    {
      "x": 12,
      "y": 21,
      "z": 25,
      "name": "Rock_Stone"
    },
    {
      "x": 12,
      "y": 34,
      "z": 25,
      "name": "Rock_Stone"
    },
    {
      "x": 12,
      "y": 35,
      "z": 25,
      "name": "Rock_Stone"
    },
    {
      "x": 12,
      "y": 36,
      "z": 25,
      "name": "Soil_Dirt"
    },
    {
      "x": 12,
      "y": 37,
      "z": 25,
      "name": "Soil_Pathway"
    },
    {
      "x": 12,
      "y": 17,
      "z": 26,
      "name": "Rock_Stone"
    },
    {
      "x": 12,
      "y": 18,
      "z": 26,
      "name": "Rock_Stone"
    },
    {
      "x": 12,
      "y": 19,
      "z": 26,
      "name": "Rock_Stone"
    },
    {
      "x": 12,
      "y": 20,
      "z": 26,
      "name": "Rock_Stone"
    },
    {
      "x": 12,
      "y": 21,
      "z": 26,
      "name": "Rock_Stone"
    },
    {
      "x": 12,
      "y": 33,
      "z": 26,
      "name": "Rock_Stone"
    },
    {
      "x": 12,
      "y": 34,
      "z": 26,
      "name": "Rock_Stone"
    },
    {
      "x": 12,
      "y": 35,
      "z": 26,
      "name": "Soil_Dirt"
    },
    {
      "x": 12,
      "y": 36,
      "z": 26,
      "name": "Soil_Dirt"
    },
    {
      "x": 12,
      "y": 37,
      "z": 26,
      "name": "Soil_Pathway"
    },
    {
      "x": 12,
      "y": 17,
      "z": 27,
      "name": "Rock_Stone"
    },
    {
      "x": 12,
      "y": 18,
      "z": 27,
      "name": "Rock_Stone"
    },
    {
      "x": 12,
      "y": 19,
      "z": 27,
      "name": "Rock_Stone"
    },
    {
      "x": 12,
      "y": 20,
      "z": 27,
      "name": "Rock_Stone"
    },
    {
      "x": 12,
      "y": 21,
      "z": 27,
      "name": "Rock_Stone"
    },
    {
      "x": 12,
      "y": 22,
      "z": 27,
      "name": "Rock_Stone"
    },
    {
      "x": 12,
      "y": 23,
      "z": 27,
      "name": "Rock_Stone"
    },
    {
      "x": 12,
      "y": 31,
      "z": 27,
      "name": "Rock_Stone"
    },
    {
      "x": 12,
      "y": 32,
      "z": 27,
      "name": "Rock_Stone"
    },
    {
      "x": 12,
      "y": 33,
      "z": 27,
      "name": "Rock_Stone"
    },
    {
      "x": 12,
      "y": 34,
      "z": 27,
      "name": "Rock_Stone"
    },
    {
      "x": 12,
      "y": 35,
      "z": 27,
      "name": "Soil_Dirt"
    },
    {
      "x": 12,
      "y": 36,
      "z": 27,
      "name": "Soil_Dirt"
    },
    {
      "x": 12,
      "y": 37,
      "z": 27,
      "name": "Soil_Dirt"
    },
    {
      "x": 12,
      "y": 38,
      "z": 27,
      "name": "Soil_Pathway"
    },
    {
      "x": 12,
      "y": 19,
      "z": 28,
      "name": "Rock_Stone"
    },
    {
      "x": 12,
      "y": 20,
      "z": 28,
      "name": "Rock_Stone"
    },
    {
      "x": 12,
      "y": 21,
      "z": 28,
      "name": "Rock_Stone"
    },
    {
      "x": 12,
      "y": 22,
      "z": 28,
      "name": "Rock_Stone"
    },
    {
      "x": 12,
      "y": 23,
      "z": 28,
      "name": "Rock_Stone"
    },
    {
      "x": 12,
      "y": 24,
      "z": 28,
      "name": "Rock_Stone"
    },
    {
      "x": 12,
      "y": 31,
      "z": 28,
      "name": "Rock_Stone"
    },
    {
      "x": 12,
      "y": 32,
      "z": 28,
      "name": "Rock_Stone"
    },
    {
      "x": 12,
      "y": 33,
      "z": 28,
      "name": "Rock_Stone"
    },
    {
      "x": 12,
      "y": 34,
      "z": 28,
      "name": "Rock_Stone"
    },
    {
      "x": 12,
      "y": 35,
      "z": 28,
      "name": "Soil_Dirt"
    },
    {
      "x": 12,
      "y": 36,
      "z": 28,
      "name": "Soil_Dirt"
    },
    {
      "x": 12,
      "y": 37,
      "z": 28,
      "name": "Soil_Dirt"
    },
    {
      "x": 12,
      "y": 38,
      "z": 28,
      "name": "Soil_Pathway"
    },
    {
      "x": 12,
      "y": 21,
      "z": 29,
      "name": "Rock_Stone"
    },
    {
      "x": 12,
      "y": 22,
      "z": 29,
      "name": "Rock_Stone"
    },
    {
      "x": 12,
      "y": 23,
      "z": 29,
      "name": "Rock_Stone"
    },
    {
      "x": 12,
      "y": 24,
      "z": 29,
      "name": "Rock_Stone"
    },
    {
      "x": 12,
      "y": 25,
      "z": 29,
      "name": "Rock_Stone"
    },
    {
      "x": 12,
      "y": 26,
      "z": 29,
      "name": "Rock_Stone"
    },
    {
      "x": 12,
      "y": 29,
      "z": 29,
      "name": "Rock_Stone"
    },
    {
      "x": 12,
      "y": 30,
      "z": 29,
      "name": "Rock_Stone"
    },
    {
      "x": 12,
      "y": 31,
      "z": 29,
      "name": "Rock_Stone"
    },
    {
      "x": 12,
      "y": 32,
      "z": 29,
      "name": "Rock_Stone"
    },
    {
      "x": 12,
      "y": 33,
      "z": 29,
      "name": "Rock_Stone"
    },
    {
      "x": 12,
      "y": 34,
      "z": 29,
      "name": "Rock_Stone"
    },
    {
      "x": 12,
      "y": 35,
      "z": 29,
      "name": "Soil_Dirt"
    },
    {
      "x": 12,
      "y": 36,
      "z": 29,
      "name": "Soil_Dirt"
    },
    {
      "x": 12,
      "y": 37,
      "z": 29,
      "name": "Soil_Dirt"
    },
    {
      "x": 12,
      "y": 38,
      "z": 29,
      "name": "Soil_Pathway"
    },
    {
      "x": 12,
      "y": 24,
      "z": 30,
      "name": "Rock_Stone"
    },
    {
      "x": 12,
      "y": 25,
      "z": 30,
      "name": "Rock_Stone"
    },
    {
      "x": 12,
      "y": 26,
      "z": 30,
      "name": "Rock_Stone"
    },
    {
      "x": 12,
      "y": 29,
      "z": 30,
      "name": "Rock_Stone"
    },
    {
      "x": 12,
      "y": 30,
      "z": 30,
      "name": "Rock_Stone"
    },
    {
      "x": 12,
      "y": 31,
      "z": 30,
      "name": "Rock_Stone"
    },
    {
      "x": 12,
      "y": 32,
      "z": 30,
      "name": "Rock_Stone"
    },
    {
      "x": 12,
      "y": 33,
      "z": 30,
      "name": "Rock_Stone"
    },
    {
      "x": 12,
      "y": 34,
      "z": 30,
      "name": "Soil_Dirt"
    },
    {
      "x": 12,
      "y": 35,
      "z": 30,
      "name": "Soil_Dirt"
    },
    {
      "x": 12,
      "y": 36,
      "z": 30,
      "name": "Soil_Dirt"
    },
    {
      "x": 12,
      "y": 37,
      "z": 30,
      "name": "Soil_Dirt"
    },
    {
      "x": 12,
      "y": 38,
      "z": 30,
      "name": "Soil_Pathway"
    },
    {
      "x": 12,
      "y": 28,
      "z": 31,
      "name": "Rock_Stone"
    },
    {
      "x": 12,
      "y": 29,
      "z": 31,
      "name": "Rock_Stone"
    },
    {
      "x": 12,
      "y": 30,
      "z": 31,
      "name": "Rock_Stone"
    },
    {
      "x": 12,
      "y": 31,
      "z": 31,
      "name": "Rock_Stone"
    },
    {
      "x": 12,
      "y": 32,
      "z": 31,
      "name": "Rock_Stone"
    },
    {
      "x": 12,
      "y": 33,
      "z": 31,
      "name": "Soil_Dirt"
    },
    {
      "x": 12,
      "y": 34,
      "z": 31,
      "name": "Soil_Dirt"
    },
    {
      "x": 12,
      "y": 35,
      "z": 31,
      "name": "Soil_Dirt"
    },
    {
      "x": 12,
      "y": 36,
      "z": 31,
      "name": "Soil_Dirt"
    },
    {
      "x": 12,
      "y": 37,
      "z": 31,
      "name": "Soil_Pathway"
    },
    {
      "x": 12,
      "y": 30,
      "z": 32,
      "name": "Rock_Stone"
    },
    {
      "x": 12,
      "y": 31,
      "z": 32,
      "name": "Rock_Stone"
    },
    {
      "x": 12,
      "y": 32,
      "z": 32,
      "name": "Rock_Stone"
    },
    {
      "x": 12,
      "y": 33,
      "z": 32,
      "name": "Soil_Dirt"
    },
    {
      "x": 12,
      "y": 34,
      "z": 32,
      "name": "Soil_Dirt"
    },
    {
      "x": 12,
      "y": 35,
      "z": 32,
      "name": "Soil_Dirt"
    },
    {
      "x": 12,
      "y": 36,
      "z": 32,
      "name": "Soil_Leaves"
    },
    {
      "x": 12,
      "y": 32,
      "z": 33,
      "name": "Rock_Stone"
    },
    {
      "x": 12,
      "y": 33,
      "z": 33,
      "name": "Soil_Dirt"
    },
    {
      "x": 13,
      "y": 16,
      "z": 23,
      "name": "Rock_Stone"
    },
    {
      "x": 13,
      "y": 16,
      "z": 24,
      "name": "Rock_Stone"
    },
    {
      "x": 13,
      "y": 17,
      "z": 24,
      "name": "Rock_Stone"
    },
    {
      "x": 13,
      "y": 18,
      "z": 24,
      "name": "Rock_Stone"
    },
    {
      "x": 13,
      "y": 19,
      "z": 24,
      "name": "Rock_Stone"
    },
    {
      "x": 13,
      "y": 34,
      "z": 24,
      "name": "Rock_Stone"
    },
    {
      "x": 13,
      "y": 35,
      "z": 24,
      "name": "Rock_Stone"
    },
    {
      "x": 13,
      "y": 36,
      "z": 24,
      "name": "Soil_Dirt"
    },
    {
      "x": 13,
      "y": 37,
      "z": 24,
      "name": "Soil_Pathway"
    },
    {
      "x": 13,
      "y": 16,
      "z": 25,
      "name": "Rock_Stone"
    },
    {
      "x": 13,
      "y": 17,
      "z": 25,
      "name": "Rock_Stone"
    },
    {
      "x": 13,
      "y": 18,
      "z": 25,
      "name": "Rock_Stone"
    },
    {
      "x": 13,
      "y": 19,
      "z": 25,
      "name": "Rock_Stone"
    },
    {
      "x": 13,
      "y": 20,
      "z": 25,
      "name": "Rock_Stone"
    },
    {
      "x": 13,
      "y": 34,
      "z": 25,
      "name": "Rock_Stone"
    },
    {
      "x": 13,
      "y": 35,
      "z": 25,
      "name": "Soil_Dirt"
    },
    {
      "x": 13,
      "y": 36,
      "z": 25,
      "name": "Soil_Dirt"
    },
    {
      "x": 13,
      "y": 37,
      "z": 25,
      "name": "Soil_Dirt"
    },
    {
      "x": 13,
      "y": 38,
      "z": 25,
      "name": "Soil_Pathway"
    },
    {
      "x": 13,
      "y": 17,
      "z": 26,
      "name": "Rock_Stone"
    },
    {
      "x": 13,
      "y": 18,
      "z": 26,
      "name": "Rock_Stone"
    },
    {
      "x": 13,
      "y": 19,
      "z": 26,
      "name": "Rock_Stone"
    },
    {
      "x": 13,
      "y": 20,
      "z": 26,
      "name": "Rock_Stone"
    },
    {
      "x": 13,
      "y": 34,
      "z": 26,
      "name": "Rock_Stone"
    },
    {
      "x": 13,
      "y": 35,
      "z": 26,
      "name": "Rock_Stone"
    },
    {
      "x": 13,
      "y": 36,
      "z": 26,
      "name": "Soil_Dirt"
    },
    {
      "x": 13,
      "y": 37,
      "z": 26,
      "name": "Soil_Dirt"
    },
    {
      "x": 13,
      "y": 38,
      "z": 26,
      "name": "Soil_Dirt"
    },
    {
      "x": 13,
      "y": 39,
      "z": 26,
      "name": "Soil_Pathway"
    },
    {
      "x": 13,
      "y": 17,
      "z": 27,
      "name": "Rock_Stone"
    },
    {
      "x": 13,
      "y": 18,
      "z": 27,
      "name": "Rock_Stone"
    },
    {
      "x": 13,
      "y": 19,
      "z": 27,
      "name": "Rock_Stone"
    },
    {
      "x": 13,
      "y": 20,
      "z": 27,
      "name": "Rock_Stone"
    },
    {
      "x": 13,
      "y": 21,
      "z": 27,
      "name": "Rock_Stone"
    },
    {
      "x": 13,
      "y": 32,
      "z": 27,
      "name": "Rock_Stone"
    },
    {
      "x": 13,
      "y": 33,
      "z": 27,
      "name": "Rock_Stone"
    },
    {
      "x": 13,
      "y": 34,
      "z": 27,
      "name": "Rock_Stone"
    },
    {
      "x": 13,
      "y": 35,
      "z": 27,
      "name": "Soil_Dirt"
    },
    {
      "x": 13,
      "y": 36,
      "z": 27,
      "name": "Soil_Dirt"
    },
    {
      "x": 13,
      "y": 37,
      "z": 27,
      "name": "Soil_Dirt"
    },
    {
      "x": 13,
      "y": 38,
      "z": 27,
      "name": "Soil_Dirt"
    },
    {
      "x": 13,
      "y": 39,
      "z": 27,
      "name": "Soil_Pathway"
    },
    {
      "x": 13,
      "y": 31,
      "z": 28,
      "name": "Rock_Stone"
    },
    {
      "x": 13,
      "y": 32,
      "z": 28,
      "name": "Rock_Stone"
    },
    {
      "x": 13,
      "y": 33,
      "z": 28,
      "name": "Rock_Stone"
    },
    {
      "x": 13,
      "y": 34,
      "z": 28,
      "name": "Rock_Stone"
    },
    {
      "x": 13,
      "y": 35,
      "z": 28,
      "name": "Soil_Dirt"
    },
    {
      "x": 13,
      "y": 36,
      "z": 28,
      "name": "Soil_Dirt"
    },
    {
      "x": 13,
      "y": 37,
      "z": 28,
      "name": "Soil_Dirt"
    },
    {
      "x": 13,
      "y": 38,
      "z": 28,
      "name": "Soil_Dirt"
    },
    {
      "x": 13,
      "y": 39,
      "z": 28,
      "name": "Soil_Pathway"
    },
    {
      "x": 13,
      "y": 31,
      "z": 29,
      "name": "Rock_Stone"
    },
    {
      "x": 13,
      "y": 32,
      "z": 29,
      "name": "Rock_Stone"
    },
    {
      "x": 13,
      "y": 33,
      "z": 29,
      "name": "Rock_Stone"
    },
    {
      "x": 13,
      "y": 34,
      "z": 29,
      "name": "Rock_Stone"
    },
    {
      "x": 13,
      "y": 35,
      "z": 29,
      "name": "Soil_Dirt"
    },
    {
      "x": 13,
      "y": 36,
      "z": 29,
      "name": "Soil_Dirt"
    },
    {
      "x": 13,
      "y": 37,
      "z": 29,
      "name": "Soil_Dirt"
    },
    {
      "x": 13,
      "y": 38,
      "z": 29,
      "name": "Soil_Pathway"
    },
    {
      "x": 13,
      "y": 31,
      "z": 30,
      "name": "Rock_Stone"
    },
    {
      "x": 13,
      "y": 32,
      "z": 30,
      "name": "Rock_Stone"
    },
    {
      "x": 13,
      "y": 33,
      "z": 30,
      "name": "Rock_Stone"
    },
    {
      "x": 13,
      "y": 34,
      "z": 30,
      "name": "Rock_Stone"
    },
    {
      "x": 13,
      "y": 35,
      "z": 30,
      "name": "Soil_Dirt"
    },
    {
      "x": 13,
      "y": 36,
      "z": 30,
      "name": "Soil_Dirt"
    },
    {
      "x": 13,
      "y": 37,
      "z": 30,
      "name": "Soil_Dirt"
    },
    {
      "x": 13,
      "y": 38,
      "z": 30,
      "name": "Soil_Pathway"
    },
    {
      "x": 13,
      "y": 30,
      "z": 31,
      "name": "Rock_Stone"
    },
    {
      "x": 13,
      "y": 31,
      "z": 31,
      "name": "Rock_Stone"
    },
    {
      "x": 13,
      "y": 32,
      "z": 31,
      "name": "Rock_Stone"
    },
    {
      "x": 13,
      "y": 33,
      "z": 31,
      "name": "Rock_Stone"
    },
    {
      "x": 13,
      "y": 34,
      "z": 31,
      "name": "Rock_Stone"
    },
    {
      "x": 13,
      "y": 35,
      "z": 31,
      "name": "Soil_Dirt"
    },
    {
      "x": 13,
      "y": 36,
      "z": 31,
      "name": "Soil_Dirt"
    },
    {
      "x": 13,
      "y": 37,
      "z": 31,
      "name": "Soil_Dirt"
    },
    {
      "x": 13,
      "y": 38,
      "z": 31,
      "name": "Soil_Pathway"
    },
    {
      "x": 13,
      "y": 31,
      "z": 32,
      "name": "Rock_Stone"
    },
    {
      "x": 13,
      "y": 32,
      "z": 32,
      "name": "Rock_Stone"
    },
    {
      "x": 13,
      "y": 33,
      "z": 32,
      "name": "Rock_Stone"
    },
    {
      "x": 13,
      "y": 34,
      "z": 32,
      "name": "Rock_Stone"
    },
    {
      "x": 13,
      "y": 35,
      "z": 32,
      "name": "Soil_Dirt"
    },
    {
      "x": 13,
      "y": 36,
      "z": 32,
      "name": "Soil_Dirt"
    },
    {
      "x": 13,
      "y": 37,
      "z": 32,
      "name": "Soil_Leaves"
    },
    {
      "x": 13,
      "y": 38,
      "z": 32,
      "name": "Plant_Grass_Lush"
    },
    {
      "x": 14,
      "y": 36,
      "z": 22,
      "name": "Soil_Dirt"
    },
    {
      "x": 14,
      "y": 37,
      "z": 22,
      "name": "Soil_Grass"
    },
    {
      "x": 14,
      "y": 15,
      "z": 23,
      "name": "Rock_Stone"
    },
    {
      "x": 14,
      "y": 16,
      "z": 23,
      "name": "Rock_Stone"
    },
    {
      "x": 14,
      "y": 35,
      "z": 23,
      "name": "Rock_Stone"
    },
    {
      "x": 14,
      "y": 36,
      "z": 23,
      "name": "Soil_Dirt"
    },
    {
      "x": 14,
      "y": 37,
      "z": 23,
      "name": "Soil_Dirt"
    },
    {
      "x": 14,
      "y": 38,
      "z": 23,
      "name": "Soil_Leaves"
    },
    {
      "x": 14,
      "y": 39,
      "z": 23,
      "name": "Plant_Grass_Sharp"
    },
    {
      "x": 14,
      "y": 15,
      "z": 24,
      "name": "Rock_Stone"
    },
    {
      "x": 14,
      "y": 16,
      "z": 24,
      "name": "Rock_Stone"
    },
    {
      "x": 14,
      "y": 17,
      "z": 24,
      "name": "Rock_Stone"
    },
    {
      "x": 14,
      "y": 34,
      "z": 24,
      "name": "Rock_Stone"
    },
    {
      "x": 14,
      "y": 35,
      "z": 24,
      "name": "Soil_Dirt"
    },
    {
      "x": 14,
      "y": 36,
      "z": 24,
      "name": "Soil_Dirt"
    },
    {
      "x": 14,
      "y": 37,
      "z": 24,
      "name": "Soil_Dirt"
    },
    {
      "x": 14,
      "y": 38,
      "z": 24,
      "name": "Soil_Pathway"
    },
    {
      "x": 14,
      "y": 16,
      "z": 25,
      "name": "Rock_Stone"
    },
    {
      "x": 14,
      "y": 17,
      "z": 25,
      "name": "Rock_Stone"
    },
    {
      "x": 14,
      "y": 18,
      "z": 25,
      "name": "Rock_Stone"
    },
    {
      "x": 14,
      "y": 34,
      "z": 25,
      "name": "Rock_Stone"
    },
    {
      "x": 14,
      "y": 35,
      "z": 25,
      "name": "Rock_Stone"
    },
    {
      "x": 14,
      "y": 36,
      "z": 25,
      "name": "Soil_Dirt"
    },
    {
      "x": 14,
      "y": 37,
      "z": 25,
      "name": "Soil_Dirt"
    },
    {
      "x": 14,
      "y": 38,
      "z": 25,
      "name": "Soil_Dirt"
    },
    {
      "x": 14,
      "y": 39,
      "z": 25,
      "name": "Soil_Pathway"
    },
    {
      "x": 14,
      "y": 16,
      "z": 26,
      "name": "Rock_Stone"
    },
    {
      "x": 14,
      "y": 17,
      "z": 26,
      "name": "Rock_Stone"
    },
    {
      "x": 14,
      "y": 18,
      "z": 26,
      "name": "Rock_Stone"
    },
    {
      "x": 14,
      "y": 34,
      "z": 26,
      "name": "Rock_Stone"
    },
    {
      "x": 14,
      "y": 35,
      "z": 26,
      "name": "Rock_Stone"
    },
    {
      "x": 14,
      "y": 36,
      "z": 26,
      "name": "Soil_Dirt"
    },
    {
      "x": 14,
      "y": 37,
      "z": 26,
      "name": "Soil_Dirt"
    },
    {
      "x": 14,
      "y": 38,
      "z": 26,
      "name": "Soil_Dirt"
    },
    {
      "x": 14,
      "y": 39,
      "z": 26,
      "name": "Soil_Pathway"
    },
    {
      "x": 14,
      "y": 32,
      "z": 27,
      "name": "Rock_Stone"
    },
    {
      "x": 14,
      "y": 33,
      "z": 27,
      "name": "Rock_Stone"
    },
    {
      "x": 14,
      "y": 34,
      "z": 27,
      "name": "Rock_Stone"
    },
    {
      "x": 14,
      "y": 35,
      "z": 27,
      "name": "Rock_Stone"
    },
    {
      "x": 14,
      "y": 36,
      "z": 27,
      "name": "Soil_Dirt"
    },
    {
      "x": 14,
      "y": 37,
      "z": 27,
      "name": "Soil_Dirt"
    },
    {
      "x": 14,
      "y": 38,
      "z": 27,
      "name": "Soil_Dirt"
    },
    {
      "x": 14,
      "y": 39,
      "z": 27,
      "name": "Soil_Pathway"
    },
    {
      "x": 14,
      "y": 32,
      "z": 28,
      "name": "Rock_Stone"
    },
    {
      "x": 14,
      "y": 33,
      "z": 28,
      "name": "Rock_Stone"
    },
    {
      "x": 14,
      "y": 34,
      "z": 28,
      "name": "Rock_Stone"
    },
    {
      "x": 14,
      "y": 35,
      "z": 28,
      "name": "Rock_Stone"
    },
    {
      "x": 14,
      "y": 36,
      "z": 28,
      "name": "Soil_Dirt"
    },
    {
      "x": 14,
      "y": 37,
      "z": 28,
      "name": "Soil_Dirt"
    },
    {
      "x": 14,
      "y": 38,
      "z": 28,
      "name": "Soil_Dirt"
    },
    {
      "x": 14,
      "y": 39,
      "z": 28,
      "name": "Soil_Pathway"
    },
    {
      "x": 14,
      "y": 32,
      "z": 29,
      "name": "Rock_Stone"
    },
    {
      "x": 14,
      "y": 33,
      "z": 29,
      "name": "Rock_Stone"
    },
    {
      "x": 14,
      "y": 34,
      "z": 29,
      "name": "Rock_Stone"
    },
    {
      "x": 14,
      "y": 35,
      "z": 29,
      "name": "Rock_Stone"
    },
    {
      "x": 14,
      "y": 36,
      "z": 29,
      "name": "Soil_Dirt"
    },
    {
      "x": 14,
      "y": 37,
      "z": 29,
      "name": "Soil_Dirt"
    },
    {
      "x": 14,
      "y": 38,
      "z": 29,
      "name": "Soil_Dirt"
    },
    {
      "x": 14,
      "y": 39,
      "z": 29,
      "name": "Soil_Pathway"
    },
    {
      "x": 14,
      "y": 32,
      "z": 30,
      "name": "Rock_Stone"
    },
    {
      "x": 14,
      "y": 33,
      "z": 30,
      "name": "Rock_Stone"
    },
    {
      "x": 14,
      "y": 34,
      "z": 30,
      "name": "Rock_Stone"
    },
    {
      "x": 14,
      "y": 35,
      "z": 30,
      "name": "Rock_Stone"
    },
    {
      "x": 14,
      "y": 36,
      "z": 30,
      "name": "Soil_Dirt"
    },
    {
      "x": 14,
      "y": 37,
      "z": 30,
      "name": "Soil_Dirt"
    },
    {
      "x": 14,
      "y": 38,
      "z": 30,
      "name": "Soil_Dirt"
    },
    {
      "x": 14,
      "y": 39,
      "z": 30,
      "name": "Soil_Pathway"
    },
    {
      "x": 14,
      "y": 33,
      "z": 31,
      "name": "Rock_Stone"
    },
    {
      "x": 14,
      "y": 34,
      "z": 31,
      "name": "Rock_Stone"
    },
    {
      "x": 14,
      "y": 35,
      "z": 31,
      "name": "Rock_Stone"
    },
    {
      "x": 14,
      "y": 36,
      "z": 31,
      "name": "Soil_Dirt"
    },
    {
      "x": 14,
      "y": 37,
      "z": 31,
      "name": "Soil_Dirt"
    },
    {
      "x": 14,
      "y": 38,
      "z": 31,
      "name": "Soil_Dirt"
    },
    {
      "x": 14,
      "y": 39,
      "z": 31,
      "name": "Soil_Pathway"
    },
    {
      "x": 14,
      "y": 33,
      "z": 32,
      "name": "Rock_Stone"
    },
    {
      "x": 14,
      "y": 34,
      "z": 32,
      "name": "Rock_Stone"
    },
    {
      "x": 14,
      "y": 35,
      "z": 32,
      "name": "Rock_Stone"
    },
    {
      "x": 14,
      "y": 36,
      "z": 32,
      "name": "Soil_Dirt"
    },
    {
      "x": 14,
      "y": 37,
      "z": 32,
      "name": "Soil_Dirt"
    },
    {
      "x": 14,
      "y": 38,
      "z": 32,
      "name": "Soil_Leaves"
    },
    {
      "x": 14,
      "y": 35,
      "z": 33,
      "name": "Rock_Stone"
    },
    {
      "x": 14,
      "y": 36,
      "z": 33,
      "name": "Soil_Grass"
    },
    {
      "x": 15,
      "y": 37,
      "z": 20,
      "name": "Rock_Stone"
    },
    {
      "x": 15,
      "y": 36,
      "z": 21,
      "name": "Rock_Stone"
    },
    {
      "x": 15,
      "y": 37,
      "z": 21,
      "name": "Rock_Stone"
    },
    {
      "x": 15,
      "y": 38,
      "z": 21,
      "name": "Soil_Grass"
    },
    {
      "x": 15,
      "y": 35,
      "z": 22,
      "name": "Rock_Stone"
    },
    {
      "x": 15,
      "y": 36,
      "z": 22,
      "name": "Soil_Dirt"
    },
    {
      "x": 15,
      "y": 37,
      "z": 22,
      "name": "Soil_Dirt"
    },
    {
      "x": 15,
      "y": 38,
      "z": 22,
      "name": "Soil_Dirt"
    },
    {
      "x": 15,
      "y": 39,
      "z": 22,
      "name": "Soil_Grass"
    },
    {
      "x": 15,
      "y": 40,
      "z": 22,
      "name": "Plant_Grass_Sharp"
    },
    {
      "x": 15,
      "y": 15,
      "z": 23,
      "name": "Rock_Stone"
    },
    {
      "x": 15,
      "y": 35,
      "z": 23,
      "name": "Rock_Stone"
    },
    {
      "x": 15,
      "y": 36,
      "z": 23,
      "name": "Soil_Dirt"
    },
    {
      "x": 15,
      "y": 37,
      "z": 23,
      "name": "Soil_Dirt"
    },
    {
      "x": 15,
      "y": 38,
      "z": 23,
      "name": "Soil_Dirt"
    },
    {
      "x": 15,
      "y": 39,
      "z": 23,
      "name": "Soil_Leaves"
    },
    {
      "x": 15,
      "y": 15,
      "z": 24,
      "name": "Rock_Stone"
    },
    {
      "x": 15,
      "y": 16,
      "z": 24,
      "name": "Rock_Stone"
    },
    {
      "x": 15,
      "y": 34,
      "z": 24,
      "name": "Rock_Stone"
    },
    {
      "x": 15,
      "y": 35,
      "z": 24,
      "name": "Rock_Stone"
    },
    {
      "x": 15,
      "y": 36,
      "z": 24,
      "name": "Soil_Dirt"
    },
    {
      "x": 15,
      "y": 37,
      "z": 24,
      "name": "Soil_Dirt"
    },
    {
      "x": 15,
      "y": 38,
      "z": 24,
      "name": "Soil_Dirt"
    },
    {
      "x": 15,
      "y": 39,
      "z": 24,
      "name": "Soil_Pathway"
    },
    {
      "x": 15,
      "y": 15,
      "z": 25,
      "name": "Rock_Stone"
    },
    {
      "x": 15,
      "y": 16,
      "z": 25,
      "name": "Rock_Stone"
    },
    {
      "x": 15,
      "y": 34,
      "z": 25,
      "name": "Rock_Stone"
    },
    {
      "x": 15,
      "y": 35,
      "z": 25,
      "name": "Rock_Stone"
    },
    {
      "x": 15,
      "y": 36,
      "z": 25,
      "name": "Soil_Dirt"
    },
    {
      "x": 15,
      "y": 37,
      "z": 25,
      "name": "Soil_Dirt"
    },
    {
      "x": 15,
      "y": 38,
      "z": 25,
      "name": "Soil_Dirt"
    },
    {
      "x": 15,
      "y": 39,
      "z": 25,
      "name": "Soil_Pathway"
    },
    {
      "x": 15,
      "y": 34,
      "z": 26,
      "name": "Rock_Stone"
    },
    {
      "x": 15,
      "y": 35,
      "z": 26,
      "name": "Rock_Stone"
    },
    {
      "x": 15,
      "y": 36,
      "z": 26,
      "name": "Soil_Dirt"
    },
    {
      "x": 15,
      "y": 37,
      "z": 26,
      "name": "Soil_Dirt"
    },
    {
      "x": 15,
      "y": 38,
      "z": 26,
      "name": "Soil_Dirt"
    },
    {
      "x": 15,
      "y": 39,
      "z": 26,
      "name": "Soil_Pathway"
    },
    {
      "x": 15,
      "y": 34,
      "z": 27,
      "name": "Rock_Stone"
    },
    {
      "x": 15,
      "y": 35,
      "z": 27,
      "name": "Rock_Stone"
    },
    {
      "x": 15,
      "y": 36,
      "z": 27,
      "name": "Rock_Stone"
    },
    {
      "x": 15,
      "y": 37,
      "z": 27,
      "name": "Soil_Dirt"
    },
    {
      "x": 15,
      "y": 38,
      "z": 27,
      "name": "Soil_Dirt"
    },
    {
      "x": 15,
      "y": 39,
      "z": 27,
      "name": "Rock_Chalk"
    },
    {
      "x": 15,
      "y": 40,
      "z": 27,
      "name": "Rock_Chalk"
    },
    {
      "x": 15,
      "y": 41,
      "z": 27,
      "name": "Rock_Chalk"
    },
    {
      "x": 15,
      "y": 33,
      "z": 28,
      "name": "Rock_Stone"
    },
    {
      "x": 15,
      "y": 34,
      "z": 28,
      "name": "Rock_Stone"
    },
    {
      "x": 15,
      "y": 35,
      "z": 28,
      "name": "Rock_Stone"
    },
    {
      "x": 15,
      "y": 36,
      "z": 28,
      "name": "Rock_Stone"
    },
    {
      "x": 15,
      "y": 37,
      "z": 28,
      "name": "Soil_Dirt"
    },
    {
      "x": 15,
      "y": 38,
      "z": 28,
      "name": "Soil_Dirt"
    },
    {
      "x": 15,
      "y": 39,
      "z": 28,
      "name": "Soil_Dirt"
    },
    {
      "x": 15,
      "y": 40,
      "z": 28,
      "name": "Soil_Pathway"
    },
    {
      "x": 15,
      "y": 33,
      "z": 29,
      "name": "Rock_Stone"
    },
    {
      "x": 15,
      "y": 34,
      "z": 29,
      "name": "Rock_Stone"
    },
    {
      "x": 15,
      "y": 35,
      "z": 29,
      "name": "Rock_Stone"
    },
    {
      "x": 15,
      "y": 36,
      "z": 29,
      "name": "Soil_Dirt"
    },
    {
      "x": 15,
      "y": 37,
      "z": 29,
      "name": "Soil_Dirt"
    },
    {
      "x": 15,
      "y": 38,
      "z": 29,
      "name": "Soil_Dirt"
    },
    {
      "x": 15,
      "y": 39,
      "z": 29,
      "name": "Soil_Dirt"
    },
    {
      "x": 15,
      "y": 40,
      "z": 29,
      "name": "Soil_Pathway"
    },
    {
      "x": 15,
      "y": 33,
      "z": 30,
      "name": "Rock_Stone"
    },
    {
      "x": 15,
      "y": 34,
      "z": 30,
      "name": "Rock_Stone"
    },
    {
      "x": 15,
      "y": 35,
      "z": 30,
      "name": "Rock_Stone"
    },
    {
      "x": 15,
      "y": 36,
      "z": 30,
      "name": "Soil_Dirt"
    },
    {
      "x": 15,
      "y": 37,
      "z": 30,
      "name": "Soil_Dirt"
    },
    {
      "x": 15,
      "y": 38,
      "z": 30,
      "name": "Soil_Dirt"
    },
    {
      "x": 15,
      "y": 39,
      "z": 30,
      "name": "Soil_Pathway"
    },
    {
      "x": 15,
      "y": 33,
      "z": 31,
      "name": "Rock_Stone"
    },
    {
      "x": 15,
      "y": 34,
      "z": 31,
      "name": "Rock_Stone"
    },
    {
      "x": 15,
      "y": 35,
      "z": 31,
      "name": "Rock_Stone"
    },
    {
      "x": 15,
      "y": 36,
      "z": 31,
      "name": "Soil_Dirt"
    },
    {
      "x": 15,
      "y": 37,
      "z": 31,
      "name": "Soil_Dirt"
    },
    {
      "x": 15,
      "y": 38,
      "z": 31,
      "name": "Soil_Dirt"
    },
    {
      "x": 15,
      "y": 39,
      "z": 31,
      "name": "Soil_Pathway"
    },
    {
      "x": 15,
      "y": 34,
      "z": 32,
      "name": "Rock_Stone"
    },
    {
      "x": 15,
      "y": 35,
      "z": 32,
      "name": "Rock_Stone"
    },
    {
      "x": 15,
      "y": 36,
      "z": 32,
      "name": "Rock_Stone"
    },
    {
      "x": 15,
      "y": 37,
      "z": 32,
      "name": "Soil_Dirt"
    },
    {
      "x": 15,
      "y": 38,
      "z": 32,
      "name": "Soil_Grass"
    },
    {
      "x": 15,
      "y": 39,
      "z": 32,
      "name": "Plant_Grass_Lush"
    },
    {
      "x": 15,
      "y": 35,
      "z": 33,
      "name": "Rock_Stone"
    },
    {
      "x": 15,
      "y": 36,
      "z": 33,
      "name": "Rock_Stone"
    },
    {
      "x": 15,
      "y": 37,
      "z": 33,
      "name": "Soil_Grass"
    },
    {
      "x": 16,
      "y": 38,
      "z": 19,
      "name": "Soil_Dirt"
    },
    {
      "x": 16,
      "y": 39,
      "z": 19,
      "name": "Soil_Pathway"
    },
    {
      "x": 16,
      "y": 36,
      "z": 20,
      "name": "Rock_Stone"
    },
    {
      "x": 16,
      "y": 37,
      "z": 20,
      "name": "Rock_Stone"
    },
    {
      "x": 16,
      "y": 38,
      "z": 20,
      "name": "Soil_Dirt"
    },
    {
      "x": 16,
      "y": 39,
      "z": 20,
      "name": "Soil_Pathway"
    },
    {
      "x": 16,
      "y": 35,
      "z": 21,
      "name": "Rock_Stone"
    },
    {
      "x": 16,
      "y": 36,
      "z": 21,
      "name": "Rock_Stone"
    },
    {
      "x": 16,
      "y": 37,
      "z": 21,
      "name": "Rock_Stone"
    },
    {
      "x": 16,
      "y": 38,
      "z": 21,
      "name": "Soil_Dirt"
    },
    {
      "x": 16,
      "y": 39,
      "z": 21,
      "name": "Soil_Dirt"
    },
    {
      "x": 16,
      "y": 40,
      "z": 21,
      "name": "Soil_Grass"
    },
    {
      "x": 16,
      "y": 41,
      "z": 21,
      "name": "Plant_Grass_Sharp"
    },
    {
      "x": 16,
      "y": 35,
      "z": 22,
      "name": "Rock_Stone"
    },
    {
      "x": 16,
      "y": 36,
      "z": 22,
      "name": "Rock_Stone"
    },
    {
      "x": 16,
      "y": 37,
      "z": 22,
      "name": "Soil_Dirt"
    },
    {
      "x": 16,
      "y": 38,
      "z": 22,
      "name": "Soil_Dirt"
    },
    {
      "x": 16,
      "y": 39,
      "z": 22,
      "name": "Soil_Dirt"
    },
    {
      "x": 16,
      "y": 40,
      "z": 22,
      "name": "Soil_Grass"
    },
    {
      "x": 16,
      "y": 35,
      "z": 23,
      "name": "Rock_Stone"
    },
    {
      "x": 16,
      "y": 36,
      "z": 23,
      "name": "Soil_Dirt"
    },
    {
      "x": 16,
      "y": 37,
      "z": 23,
      "name": "Soil_Dirt"
    },
    {
      "x": 16,
      "y": 38,
      "z": 23,
      "name": "Soil_Dirt"
    },
    {
      "x": 16,
      "y": 39,
      "z": 23,
      "name": "Soil_Dirt"
    },
    {
      "x": 16,
      "y": 40,
      "z": 23,
      "name": "Soil_Leaves"
    },
    {
      "x": 16,
      "y": 35,
      "z": 24,
      "name": "Rock_Stone"
    },
    {
      "x": 16,
      "y": 36,
      "z": 24,
      "name": "Soil_Dirt"
    },
    {
      "x": 16,
      "y": 37,
      "z": 24,
      "name": "Soil_Dirt"
    },
    {
      "x": 16,
      "y": 38,
      "z": 24,
      "name": "Soil_Dirt"
    },
    {
      "x": 16,
      "y": 39,
      "z": 24,
      "name": "Soil_Dirt"
    },
    {
      "x": 16,
      "y": 40,
      "z": 24,
      "name": "Soil_Leaves"
    },
    {
      "x": 16,
      "y": 41,
      "z": 24,
      "name": "Plant_Grass_Sharp"
    },
    {
      "x": 16,
      "y": 34,
      "z": 25,
      "name": "Rock_Stone"
    },
    {
      "x": 16,
      "y": 35,
      "z": 25,
      "name": "Rock_Stone"
    },
    {
      "x": 16,
      "y": 36,
      "z": 25,
      "name": "Soil_Dirt"
    },
    {
      "x": 16,
      "y": 37,
      "z": 25,
      "name": "Soil_Dirt"
    },
    {
      "x": 16,
      "y": 38,
      "z": 25,
      "name": "Soil_Dirt"
    },
    {
      "x": 16,
      "y": 39,
      "z": 25,
      "name": "Soil_Dirt"
    },
    {
      "x": 16,
      "y": 40,
      "z": 25,
      "name": "Soil_Leaves"
    },
    {
      "x": 16,
      "y": 34,
      "z": 26,
      "name": "Rock_Stone"
    },
    {
      "x": 16,
      "y": 35,
      "z": 26,
      "name": "Rock_Stone"
    },
    {
      "x": 16,
      "y": 36,
      "z": 26,
      "name": "Rock_Stone"
    },
    {
      "x": 16,
      "y": 37,
      "z": 26,
      "name": "Soil_Dirt"
    },
    {
      "x": 16,
      "y": 38,
      "z": 26,
      "name": "Soil_Dirt"
    },
    {
      "x": 16,
      "y": 39,
      "z": 26,
      "name": "Soil_Dirt"
    },
    {
      "x": 16,
      "y": 40,
      "z": 26,
      "name": "Rock_Chalk"
    },
    {
      "x": 16,
      "y": 41,
      "z": 26,
      "name": "Rock_Chalk"
    },
    {
      "x": 16,
      "y": 49,
      "z": 26,
      "name": "Plant_Leaves_Birch",
      "support": 15
    },
    {
      "x": 16,
      "y": 34,
      "z": 27,
      "name": "Rock_Stone"
    },
    {
      "x": 16,
      "y": 35,
      "z": 27,
      "name": "Rock_Stone"
    },
    {
      "x": 16,
      "y": 36,
      "z": 27,
      "name": "Rock_Stone"
    },
    {
      "x": 16,
      "y": 37,
      "z": 27,
      "name": "Soil_Dirt"
    },
    {
      "x": 16,
      "y": 38,
      "z": 27,
      "name": "Rock_Chalk"
    },
    {
      "x": 16,
      "y": 39,
      "z": 27,
      "name": "Rock_Chalk"
    },
    {
      "x": 16,
      "y": 40,
      "z": 27,
      "name": "Rock_Chalk"
    },
    {
      "x": 16,
      "y": 41,
      "z": 27,
      "name": "Rock_Chalk"
    },
    {
      "x": 16,
      "y": 48,
      "z": 27,
      "name": "Plant_Leaves_Birch",
      "support": 15
    },
    {
      "x": 16,
      "y": 49,
      "z": 27,
      "name": "Plant_Leaves_Birch",
      "support": 15
    },
    {
      "x": 16,
      "y": 50,
      "z": 27,
      "name": "Plant_Leaves_Birch",
      "support": 15
    },
    {
      "x": 16,
      "y": 53,
      "z": 27,
      "name": "Plant_Leaves_Birch",
      "support": 15
    },
    {
      "x": 16,
      "y": 34,
      "z": 28,
      "name": "Rock_Stone"
    },
    {
      "x": 16,
      "y": 35,
      "z": 28,
      "name": "Rock_Stone"
    },
    {
      "x": 16,
      "y": 36,
      "z": 28,
      "name": "Rock_Stone"
    },
    {
      "x": 16,
      "y": 37,
      "z": 28,
      "name": "Rock_Stone"
    },
    {
      "x": 16,
      "y": 38,
      "z": 28,
      "name": "Rock_Chalk"
    },
    {
      "x": 16,
      "y": 39,
      "z": 28,
      "name": "Rock_Chalk"
    },
    {
      "x": 16,
      "y": 40,
      "z": 28,
      "name": "Rock_Chalk"
    },
    {
      "x": 16,
      "y": 41,
      "z": 28,
      "name": "Rock_Chalk"
    },
    {
      "x": 16,
      "y": 49,
      "z": 28,
      "name": "Plant_Leaves_Birch",
      "support": 15
    },
    {
      "x": 16,
      "y": 50,
      "z": 28,
      "name": "Plant_Leaves_Birch",
      "support": 15
    },
    {
      "x": 16,
      "y": 33,
      "z": 29,
      "name": "Rock_Stone"
    },
    {
      "x": 16,
      "y": 34,
      "z": 29,
      "name": "Rock_Stone"
    },
    {
      "x": 16,
      "y": 35,
      "z": 29,
      "name": "Rock_Stone"
    },
    {
      "x": 16,
      "y": 36,
      "z": 29,
      "name": "Rock_Stone"
    },
    {
      "x": 16,
      "y": 37,
      "z": 29,
      "name": "Rock_Stone"
    },
    {
      "x": 16,
      "y": 38,
      "z": 29,
      "name": "Soil_Dirt"
    },
    {
      "x": 16,
      "y": 39,
      "z": 29,
      "name": "Soil_Dirt"
    },
    {
      "x": 16,
      "y": 40,
      "z": 29,
      "name": "Soil_Grass_Sunny"
    },
    {
      "x": 16,
      "y": 48,
      "z": 29,
      "name": "Plant_Leaves_Birch",
      "support": 15
    },
    {
      "x": 16,
      "y": 33,
      "z": 30,
      "name": "Rock_Stone"
    },
    {
      "x": 16,
      "y": 34,
      "z": 30,
      "name": "Rock_Stone"
    },
    {
      "x": 16,
      "y": 35,
      "z": 30,
      "name": "Rock_Stone"
    },
    {
      "x": 16,
      "y": 36,
      "z": 30,
      "name": "Rock_Stone"
    },
    {
      "x": 16,
      "y": 37,
      "z": 30,
      "name": "Rock_Stone"
    },
    {
      "x": 16,
      "y": 38,
      "z": 30,
      "name": "Soil_Dirt"
    },
    {
      "x": 16,
      "y": 39,
      "z": 30,
      "name": "Soil_Dirt"
    },
    {
      "x": 16,
      "y": 40,
      "z": 30,
      "name": "Soil_Grass_Sunny"
    },
    {
      "x": 16,
      "y": 47,
      "z": 30,
      "name": "Plant_Leaves_Birch",
      "support": 15
    },
    {
      "x": 16,
      "y": 48,
      "z": 30,
      "name": "Plant_Leaves_Birch",
      "support": 15
    },
    {
      "x": 16,
      "y": 33,
      "z": 31,
      "name": "Rock_Stone"
    },
    {
      "x": 16,
      "y": 34,
      "z": 31,
      "name": "Rock_Stone"
    },
    {
      "x": 16,
      "y": 35,
      "z": 31,
      "name": "Rock_Stone"
    },
    {
      "x": 16,
      "y": 36,
      "z": 31,
      "name": "Rock_Stone"
    },
    {
      "x": 16,
      "y": 37,
      "z": 31,
      "name": "Rock_Stone"
    },
    {
      "x": 16,
      "y": 38,
      "z": 31,
      "name": "Soil_Dirt"
    },
    {
      "x": 16,
      "y": 39,
      "z": 31,
      "name": "Soil_Grass_Sunny"
    },
    {
      "x": 16,
      "y": 40,
      "z": 31,
      "name": "Plant_Grass_Sharp"
    },
    {
      "x": 16,
      "y": 47,
      "z": 31,
      "name": "Plant_Leaves_Birch",
      "support": 15
    },
    {
      "x": 16,
      "y": 48,
      "z": 31,
      "name": "Plant_Leaves_Birch",
      "support": 15
    },
    {
      "x": 16,
      "y": 49,
      "z": 31,
      "name": "Plant_Leaves_Birch",
      "support": 15
    },
    {
      "x": 16,
      "y": 34,
      "z": 32,
      "name": "Rock_Stone"
    },
    {
      "x": 16,
      "y": 35,
      "z": 32,
      "name": "Rock_Stone"
    },
    {
      "x": 16,
      "y": 36,
      "z": 32,
      "name": "Rock_Stone"
    },
    {
      "x": 16,
      "y": 37,
      "z": 32,
      "name": "Rock_Stone"
    },
    {
      "x": 16,
      "y": 38,
      "z": 32,
      "name": "Soil_Dirt"
    },
    {
      "x": 16,
      "y": 39,
      "z": 32,
      "name": "Soil_Grass"
    },
    {
      "x": 16,
      "y": 36,
      "z": 33,
      "name": "Rock_Stone"
    },
    {
      "x": 16,
      "y": 37,
      "z": 33,
      "name": "Rock_Stone"
    },
    {
      "x": 17,
      "y": 37,
      "z": 18,
      "name": "Rock_Stone"
    },
    {
      "x": 17,
      "y": 38,
      "z": 18,
      "name": "Soil_Dirt"
    },
    {
      "x": 17,
      "y": 39,
      "z": 18,
      "name": "Soil_Pathway"
    },
    {
      "x": 17,
      "y": 37,
      "z": 19,
      "name": "Rock_Stone"
    },
    {
      "x": 17,
      "y": 38,
      "z": 19,
      "name": "Soil_Dirt"
    },
    {
      "x": 17,
      "y": 39,
      "z": 19,
      "name": "Soil_Pathway"
    },
    {
      "x": 17,
      "y": 36,
      "z": 20,
      "name": "Rock_Stone"
    },
    {
      "x": 17,
      "y": 37,
      "z": 20,
      "name": "Soil_Dirt"
    },
    {
      "x": 17,
      "y": 38,
      "z": 20,
      "name": "Soil_Dirt"
    },
    {
      "x": 17,
      "y": 39,
      "z": 20,
      "name": "Soil_Dirt"
    },
    {
      "x": 17,
      "y": 40,
      "z": 20,
      "name": "Soil_Pathway"
    },
    {
      "x": 17,
      "y": 35,
      "z": 21,
      "name": "Rock_Stone"
    },
    {
      "x": 17,
      "y": 36,
      "z": 21,
      "name": "Rock_Stone"
    },
    {
      "x": 17,
      "y": 37,
      "z": 21,
      "name": "Soil_Dirt"
    },
    {
      "x": 17,
      "y": 38,
      "z": 21,
      "name": "Soil_Dirt"
    },
    {
      "x": 17,
      "y": 39,
      "z": 21,
      "name": "Soil_Dirt"
    },
    {
      "x": 17,
      "y": 40,
      "z": 21,
      "name": "Soil_Pathway"
    },
    {
      "x": 17,
      "y": 35,
      "z": 22,
      "name": "Rock_Stone"
    },
    {
      "x": 17,
      "y": 36,
      "z": 22,
      "name": "Rock_Stone"
    },
    {
      "x": 17,
      "y": 37,
      "z": 22,
      "name": "Rock_Stone"
    },
    {
      "x": 17,
      "y": 38,
      "z": 22,
      "name": "Soil_Dirt"
    },
    {
      "x": 17,
      "y": 39,
      "z": 22,
      "name": "Soil_Dirt"
    },
    {
      "x": 17,
      "y": 40,
      "z": 22,
      "name": "Soil_Grass"
    },
    {
      "x": 17,
      "y": 41,
      "z": 22,
      "name": "Plant_Grass_Sharp"
    },
    {
      "x": 17,
      "y": 35,
      "z": 23,
      "name": "Rock_Stone"
    },
    {
      "x": 17,
      "y": 36,
      "z": 23,
      "name": "Rock_Stone"
    },
    {
      "x": 17,
      "y": 37,
      "z": 23,
      "name": "Rock_Stone"
    },
    {
      "x": 17,
      "y": 38,
      "z": 23,
      "name": "Soil_Dirt"
    },
    {
      "x": 17,
      "y": 39,
      "z": 23,
      "name": "Soil_Dirt"
    },
    {
      "x": 17,
      "y": 40,
      "z": 23,
      "name": "Soil_Grass"
    },
    {
      "x": 17,
      "y": 41,
      "z": 23,
      "name": "Plant_Grass_Lush"
    },
    {
      "x": 17,
      "y": 35,
      "z": 24,
      "name": "Rock_Stone"
    },
    {
      "x": 17,
      "y": 36,
      "z": 24,
      "name": "Rock_Stone"
    },
    {
      "x": 17,
      "y": 37,
      "z": 24,
      "name": "Soil_Dirt"
    },
    {
      "x": 17,
      "y": 38,
      "z": 24,
      "name": "Soil_Dirt"
    },
    {
      "x": 17,
      "y": 39,
      "z": 24,
      "name": "Soil_Dirt"
    },
    {
      "x": 17,
      "y": 40,
      "z": 24,
      "name": "Soil_Grass"
    },
    {
      "x": 17,
      "y": 35,
      "z": 25,
      "name": "Rock_Stone"
    },
    {
      "x": 17,
      "y": 36,
      "z": 25,
      "name": "Rock_Stone"
    },
    {
      "x": 17,
      "y": 37,
      "z": 25,
      "name": "Soil_Dirt"
    },
    {
      "x": 17,
      "y": 38,
      "z": 25,
      "name": "Soil_Dirt"
    },
    {
      "x": 17,
      "y": 39,
      "z": 25,
      "name": "Soil_Dirt"
    },
    {
      "x": 17,
      "y": 40,
      "z": 25,
      "name": "Soil_Dirt"
    },
    {
      "x": 17,
      "y": 41,
      "z": 25,
      "name": "Soil_Grass"
    },
    {
      "x": 17,
      "y": 35,
      "z": 26,
      "name": "Rock_Stone"
    },
    {
      "x": 17,
      "y": 36,
      "z": 26,
      "name": "Rock_Stone"
    },
    {
      "x": 17,
      "y": 37,
      "z": 26,
      "name": "Soil_Dirt"
    },
    {
      "x": 17,
      "y": 38,
      "z": 26,
      "name": "Soil_Dirt"
    },
    {
      "x": 17,
      "y": 39,
      "z": 26,
      "name": "Rock_Chalk"
    },
    {
      "x": 17,
      "y": 40,
      "z": 26,
      "name": "Rock_Chalk"
    },
    {
      "x": 17,
      "y": 41,
      "z": 26,
      "name": "Rock_Chalk"
    },
    {
      "x": 17,
      "y": 48,
      "z": 26,
      "name": "Plant_Leaves_Birch",
      "support": 15
    },
    {
      "x": 17,
      "y": 49,
      "z": 26,
      "name": "Plant_Leaves_Birch",
      "support": 15
    },
    {
      "x": 17,
      "y": 50,
      "z": 26,
      "name": "Plant_Leaves_Birch",
      "support": 15
    },
    {
      "x": 17,
      "y": 53,
      "z": 26,
      "name": "Plant_Leaves_Birch",
      "support": 15
    },
    {
      "x": 17,
      "y": 34,
      "z": 27,
      "name": "Rock_Stone"
    },
    {
      "x": 17,
      "y": 35,
      "z": 27,
      "name": "Rock_Stone"
    },
    {
      "x": 17,
      "y": 36,
      "z": 27,
      "name": "Rock_Stone"
    },
    {
      "x": 17,
      "y": 37,
      "z": 27,
      "name": "Rock_Stone"
    },
    {
      "x": 17,
      "y": 38,
      "z": 27,
      "name": "Rock_Chalk"
    },
    {
      "x": 17,
      "y": 39,
      "z": 27,
      "name": "Rock_Chalk"
    },
    {
      "x": 17,
      "y": 40,
      "z": 27,
      "name": "Rock_Chalk"
    },
    {
      "x": 17,
      "y": 41,
      "z": 27,
      "name": "Rock_Chalk"
    },
    {
      "x": 17,
      "y": 47,
      "z": 27,
      "name": "Plant_Leaves_Birch",
      "support": 15
    },
    {
      "x": 17,
      "y": 48,
      "z": 27,
      "name": "Plant_Leaves_Birch",
      "support": 15
    },
    {
      "x": 17,
      "y": 49,
      "z": 27,
      "name": "Plant_Leaves_Birch",
      "support": 15
    },
    {
      "x": 17,
      "y": 50,
      "z": 27,
      "name": "Plant_Leaves_Birch",
      "support": 15
    },
    {
      "x": 17,
      "y": 51,
      "z": 27,
      "name": "Plant_Leaves_Birch",
      "support": 15
    },
    {
      "x": 17,
      "y": 53,
      "z": 27,
      "name": "Plant_Leaves_Birch",
      "support": 15
    },
    {
      "x": 17,
      "y": 54,
      "z": 27,
      "name": "Plant_Leaves_Birch",
      "support": 15
    },
    {
      "x": 17,
      "y": 34,
      "z": 28,
      "name": "Rock_Stone"
    },
    {
      "x": 17,
      "y": 35,
      "z": 28,
      "name": "Rock_Stone"
    },
    {
      "x": 17,
      "y": 36,
      "z": 28,
      "name": "Rock_Stone"
    },
    {
      "x": 17,
      "y": 37,
      "z": 28,
      "name": "Rock_Stone"
    },
    {
      "x": 17,
      "y": 38,
      "z": 28,
      "name": "Soil_Dirt"
    },
    {
      "x": 17,
      "y": 39,
      "z": 28,
      "name": "Rock_Chalk"
    },
    {
      "x": 17,
      "y": 40,
      "z": 28,
      "name": "Rock_Chalk"
    },
    {
      "x": 17,
      "y": 41,
      "z": 28,
      "name": "Soil_Grass"
    },
    {
      "x": 17,
      "y": 46,
      "z": 28,
      "name": "Plant_Leaves_Birch",
      "support": 15
    },
    {
      "x": 17,
      "y": 47,
      "z": 28,
      "name": "Plant_Leaves_Birch",
      "support": 15
    },
    {
      "x": 17,
      "y": 50,
      "z": 28,
      "name": "Wood_Birch_Branch_Corner",
      "support": 15,
      "rotation": 3
    },
    {
      "x": 17,
      "y": 51,
      "z": 28,
      "name": "Plant_Leaves_Birch",
      "support": 15
    },
    {
      "x": 17,
      "y": 54,
      "z": 28,
      "name": "Plant_Leaves_Birch",
      "support": 15
    },
    {
      "x": 17,
      "y": 34,
      "z": 29,
      "name": "Rock_Stone"
    },
    {
      "x": 17,
      "y": 35,
      "z": 29,
      "name": "Rock_Stone"
    },
    {
      "x": 17,
      "y": 36,
      "z": 29,
      "name": "Rock_Stone"
    },
    {
      "x": 17,
      "y": 37,
      "z": 29,
      "name": "Rock_Stone"
    },
    {
      "x": 17,
      "y": 38,
      "z": 29,
      "name": "Soil_Dirt"
    },
    {
      "x": 17,
      "y": 39,
      "z": 29,
      "name": "Soil_Dirt"
    },
    {
      "x": 17,
      "y": 40,
      "z": 29,
      "name": "Soil_Grass_Sunny"
    },
    {
      "x": 17,
      "y": 41,
      "z": 29,
      "name": "Plant_Grass_Sharp"
    },
    {
      "x": 17,
      "y": 44,
      "z": 29,
      "name": "Plant_Leaves_Birch",
      "support": 15
    },
    {
      "x": 17,
      "y": 45,
      "z": 29,
      "name": "Plant_Leaves_Birch",
      "support": 15
    },
    {
      "x": 17,
      "y": 49,
      "z": 29,
      "name": "Plant_Leaves_Birch",
      "support": 15
    },
    {
      "x": 17,
      "y": 52,
      "z": 29,
      "name": "Plant_Leaves_Birch",
      "support": 15
    },
    {
      "x": 17,
      "y": 34,
      "z": 30,
      "name": "Rock_Stone"
    },
    {
      "x": 17,
      "y": 35,
      "z": 30,
      "name": "Rock_Stone"
    },
    {
      "x": 17,
      "y": 36,
      "z": 30,
      "name": "Rock_Stone"
    },
    {
      "x": 17,
      "y": 37,
      "z": 30,
      "name": "Soil_Dirt"
    },
    {
      "x": 17,
      "y": 38,
      "z": 30,
      "name": "Soil_Dirt"
    },
    {
      "x": 17,
      "y": 39,
      "z": 30,
      "name": "Soil_Dirt"
    },
    {
      "x": 17,
      "y": 40,
      "z": 30,
      "name": "Soil_Grass_Sunny"
    },
    {
      "x": 17,
      "y": 48,
      "z": 30,
      "name": "Plant_Leaves_Birch",
      "support": 15
    },
    {
      "x": 17,
      "y": 49,
      "z": 30,
      "name": "Plant_Leaves_Birch",
      "support": 15
    },
    {
      "x": 17,
      "y": 51,
      "z": 30,
      "name": "Plant_Leaves_Birch",
      "support": 15
    },
    {
      "x": 17,
      "y": 52,
      "z": 30,
      "name": "Plant_Leaves_Birch",
      "support": 15
    },
    {
      "x": 17,
      "y": 53,
      "z": 30,
      "name": "Plant_Leaves_Birch",
      "support": 15
    },
    {
      "x": 17,
      "y": 35,
      "z": 31,
      "name": "Rock_Stone"
    },
    {
      "x": 17,
      "y": 36,
      "z": 31,
      "name": "Rock_Stone"
    },
    {
      "x": 17,
      "y": 37,
      "z": 31,
      "name": "Rock_Stone"
    },
    {
      "x": 17,
      "y": 38,
      "z": 31,
      "name": "Soil_Dirt"
    },
    {
      "x": 17,
      "y": 39,
      "z": 31,
      "name": "Soil_Grass_Sunny"
    },
    {
      "x": 17,
      "y": 47,
      "z": 31,
      "name": "Plant_Leaves_Birch",
      "support": 15
    },
    {
      "x": 17,
      "y": 48,
      "z": 31,
      "name": "Plant_Leaves_Birch",
      "support": 15
    },
    {
      "x": 17,
      "y": 49,
      "z": 31,
      "name": "Plant_Leaves_Birch",
      "support": 15
    },
    {
      "x": 17,
      "y": 51,
      "z": 31,
      "name": "Plant_Leaves_Birch",
      "support": 15
    },
    {
      "x": 17,
      "y": 52,
      "z": 31,
      "name": "Plant_Leaves_Birch",
      "support": 15
    },
    {
      "x": 17,
      "y": 35,
      "z": 32,
      "name": "Rock_Stone"
    },
    {
      "x": 17,
      "y": 36,
      "z": 32,
      "name": "Rock_Stone"
    },
    {
      "x": 17,
      "y": 37,
      "z": 32,
      "name": "Rock_Stone"
    },
    {
      "x": 17,
      "y": 38,
      "z": 32,
      "name": "Soil_Dirt"
    },
    {
      "x": 17,
      "y": 39,
      "z": 32,
      "name": "Soil_Grass"
    },
    {
      "x": 17,
      "y": 47,
      "z": 32,
      "name": "Plant_Leaves_Birch",
      "support": 15
    },
    {
      "x": 17,
      "y": 48,
      "z": 32,
      "name": "Plant_Leaves_Birch",
      "support": 15
    },
    {
      "x": 18,
      "y": 38,
      "z": 17,
      "name": "Soil_Pathway"
    },
    {
      "x": 18,
      "y": 36,
      "z": 18,
      "name": "Rock_Stone"
    },
    {
      "x": 18,
      "y": 37,
      "z": 18,
      "name": "Rock_Stone"
    },
    {
      "x": 18,
      "y": 38,
      "z": 18,
      "name": "Soil_Dirt"
    },
    {
      "x": 18,
      "y": 39,
      "z": 18,
      "name": "Soil_Dirt"
    },
    {
      "x": 18,
      "y": 40,
      "z": 18,
      "name": "Soil_Pathway"
    },
    {
      "x": 18,
      "y": 36,
      "z": 19,
      "name": "Rock_Stone"
    },
    {
      "x": 18,
      "y": 37,
      "z": 19,
      "name": "Rock_Stone"
    },
    {
      "x": 18,
      "y": 38,
      "z": 19,
      "name": "Soil_Dirt"
    },
    {
      "x": 18,
      "y": 39,
      "z": 19,
      "name": "Soil_Dirt"
    },
    {
      "x": 18,
      "y": 40,
      "z": 19,
      "name": "Soil_Pathway"
    },
    {
      "x": 18,
      "y": 36,
      "z": 20,
      "name": "Rock_Stone"
    },
    {
      "x": 18,
      "y": 37,
      "z": 20,
      "name": "Rock_Stone"
    },
    {
      "x": 18,
      "y": 38,
      "z": 20,
      "name": "Soil_Dirt"
    },
    {
      "x": 18,
      "y": 39,
      "z": 20,
      "name": "Soil_Dirt"
    },
    {
      "x": 18,
      "y": 40,
      "z": 20,
      "name": "Soil_Pathway"
    },
    {
      "x": 18,
      "y": 36,
      "z": 21,
      "name": "Rock_Stone"
    },
    {
      "x": 18,
      "y": 37,
      "z": 21,
      "name": "Rock_Stone"
    },
    {
      "x": 18,
      "y": 38,
      "z": 21,
      "name": "Soil_Dirt"
    },
    {
      "x": 18,
      "y": 39,
      "z": 21,
      "name": "Soil_Dirt"
    },
    {
      "x": 18,
      "y": 40,
      "z": 21,
      "name": "Soil_Dirt"
    },
    {
      "x": 18,
      "y": 41,
      "z": 21,
      "name": "Soil_Pathway"
    },
    {
      "x": 18,
      "y": 35,
      "z": 22,
      "name": "Rock_Stone"
    },
    {
      "x": 18,
      "y": 36,
      "z": 22,
      "name": "Rock_Stone"
    },
    {
      "x": 18,
      "y": 37,
      "z": 22,
      "name": "Rock_Stone"
    },
    {
      "x": 18,
      "y": 38,
      "z": 22,
      "name": "Soil_Dirt"
    },
    {
      "x": 18,
      "y": 39,
      "z": 22,
      "name": "Soil_Dirt"
    },
    {
      "x": 18,
      "y": 40,
      "z": 22,
      "name": "Soil_Dirt"
    },
    {
      "x": 18,
      "y": 41,
      "z": 22,
      "name": "Soil_Leaves"
    },
    {
      "x": 18,
      "y": 35,
      "z": 23,
      "name": "Rock_Stone"
    },
    {
      "x": 18,
      "y": 36,
      "z": 23,
      "name": "Rock_Stone"
    },
    {
      "x": 18,
      "y": 37,
      "z": 23,
      "name": "Rock_Stone"
    },
    {
      "x": 18,
      "y": 38,
      "z": 23,
      "name": "Soil_Dirt"
    },
    {
      "x": 18,
      "y": 39,
      "z": 23,
      "name": "Soil_Dirt"
    },
    {
      "x": 18,
      "y": 40,
      "z": 23,
      "name": "Soil_Dirt"
    },
    {
      "x": 18,
      "y": 41,
      "z": 23,
      "name": "Soil_Grass"
    },
    {
      "x": 18,
      "y": 35,
      "z": 24,
      "name": "Rock_Stone"
    },
    {
      "x": 18,
      "y": 36,
      "z": 24,
      "name": "Rock_Stone"
    },
    {
      "x": 18,
      "y": 37,
      "z": 24,
      "name": "Rock_Stone"
    },
    {
      "x": 18,
      "y": 38,
      "z": 24,
      "name": "Rock_Stone"
    },
    {
      "x": 18,
      "y": 39,
      "z": 24,
      "name": "Soil_Dirt"
    },
    {
      "x": 18,
      "y": 40,
      "z": 24,
      "name": "Soil_Dirt"
    },
    {
      "x": 18,
      "y": 41,
      "z": 24,
      "name": "Soil_Grass"
    },
    {
      "x": 18,
      "y": 42,
      "z": 24,
      "name": "Plant_Grass_Sharp"
    },
    {
      "x": 18,
      "y": 35,
      "z": 25,
      "name": "Rock_Stone"
    },
    {
      "x": 18,
      "y": 36,
      "z": 25,
      "name": "Rock_Stone"
    },
    {
      "x": 18,
      "y": 37,
      "z": 25,
      "name": "Rock_Stone"
    },
    {
      "x": 18,
      "y": 38,
      "z": 25,
      "name": "Rock_Stone"
    },
    {
      "x": 18,
      "y": 39,
      "z": 25,
      "name": "Soil_Dirt"
    },
    {
      "x": 18,
      "y": 40,
      "z": 25,
      "name": "Soil_Dirt"
    },
    {
      "x": 18,
      "y": 41,
      "z": 25,
      "name": "Soil_Grass"
    },
    {
      "x": 18,
      "y": 42,
      "z": 25,
      "name": "Plant_Grass_Lush"
    },
    {
      "x": 18,
      "y": 49,
      "z": 25,
      "name": "Plant_Leaves_Birch",
      "support": 15
    },
    {
      "x": 18,
      "y": 52,
      "z": 25,
      "name": "Plant_Leaves_Birch",
      "support": 15
    },
    {
      "x": 18,
      "y": 53,
      "z": 25,
      "name": "Plant_Leaves_Birch",
      "support": 15
    },
    {
      "x": 18,
      "y": 35,
      "z": 26,
      "name": "Rock_Stone"
    },
    {
      "x": 18,
      "y": 36,
      "z": 26,
      "name": "Rock_Stone"
    },
    {
      "x": 18,
      "y": 37,
      "z": 26,
      "name": "Rock_Stone"
    },
    {
      "x": 18,
      "y": 38,
      "z": 26,
      "name": "Rock_Stone"
    },
    {
      "x": 18,
      "y": 39,
      "z": 26,
      "name": "Soil_Dirt"
    },
    {
      "x": 18,
      "y": 40,
      "z": 26,
      "name": "Soil_Dirt"
    },
    {
      "x": 18,
      "y": 41,
      "z": 26,
      "name": "Soil_Grass"
    },
    {
      "x": 18,
      "y": 42,
      "z": 26,
      "name": "Plant_Grass_Lush"
    },
    {
      "x": 18,
      "y": 47,
      "z": 26,
      "name": "Plant_Leaves_Birch",
      "support": 15
    },
    {
      "x": 18,
      "y": 48,
      "z": 26,
      "name": "Plant_Leaves_Birch",
      "support": 15
    },
    {
      "x": 18,
      "y": 49,
      "z": 26,
      "name": "Plant_Leaves_Birch",
      "support": 15
    },
    {
      "x": 18,
      "y": 50,
      "z": 26,
      "name": "Plant_Leaves_Birch",
      "support": 15
    },
    {
      "x": 18,
      "y": 53,
      "z": 26,
      "name": "Plant_Leaves_Birch",
      "support": 15
    },
    {
      "x": 18,
      "y": 35,
      "z": 27,
      "name": "Rock_Stone"
    },
    {
      "x": 18,
      "y": 36,
      "z": 27,
      "name": "Rock_Stone"
    },
    {
      "x": 18,
      "y": 37,
      "z": 27,
      "name": "Rock_Stone"
    },
    {
      "x": 18,
      "y": 38,
      "z": 27,
      "name": "Rock_Stone"
    },
    {
      "x": 18,
      "y": 39,
      "z": 27,
      "name": "Soil_Dirt"
    },
    {
      "x": 18,
      "y": 40,
      "z": 27,
      "name": "Soil_Dirt"
    },
    {
      "x": 18,
      "y": 41,
      "z": 27,
      "name": "Soil_Grass"
    },
    {
      "x": 18,
      "y": 45,
      "z": 27,
      "name": "Plant_Leaves_Birch",
      "support": 15
    },
    {
      "x": 18,
      "y": 53,
      "z": 27,
      "name": "Wood_Birch_Branch_Long",
      "support": 15,
      "rotation": 5
    },
    {
      "x": 18,
      "y": 54,
      "z": 27,
      "name": "Plant_Leaves_Birch",
      "support": 15
    },
    {
      "x": 18,
      "y": 34,
      "z": 28,
      "name": "Wood_Birch_Roots"
    },
    {
      "x": 18,
      "y": 35,
      "z": 28,
      "name": "Wood_Birch_Trunk_Full",
      "support": 15
    },
    {
      "x": 18,
      "y": 36,
      "z": 28,
      "name": "Wood_Birch_Trunk_Full",
      "support": 15
    },
    {
      "x": 18,
      "y": 37,
      "z": 28,
      "name": "Rock_Stone"
    },
    {
      "x": 18,
      "y": 38,
      "z": 28,
      "name": "Soil_Dirt"
    },
    {
      "x": 18,
      "y": 39,
      "z": 28,
      "name": "Soil_Dirt"
    },
    {
      "x": 18,
      "y": 40,
      "z": 28,
      "name": "Soil_Dirt"
    },
    {
      "x": 18,
      "y": 41,
      "z": 28,
      "name": "Soil_Grass"
    },
    {
      "x": 18,
      "y": 42,
      "z": 28,
      "name": "Plant_Grass_Sharp"
    },
    {
      "x": 18,
      "y": 44,
      "z": 28,
      "name": "Plant_Leaves_Birch",
      "support": 15
    },
    {
      "x": 18,
      "y": 45,
      "z": 28,
      "name": "Plant_Leaves_Birch",
      "support": 15
    },
    {
      "x": 18,
      "y": 50,
      "z": 28,
      "name": "Wood_Birch_Trunk_Full",
      "support": 15
    },
    {
      "x": 18,
      "y": 54,
      "z": 28,
      "name": "Plant_Leaves_Birch",
      "support": 15
    },
    {
      "x": 18,
      "y": 56,
      "z": 28,
      "name": "Plant_Leaves_Birch",
      "support": 15
    },
    {
      "x": 18,
      "y": 35,
      "z": 29,
      "name": "Rock_Stone"
    },
    {
      "x": 18,
      "y": 36,
      "z": 29,
      "name": "Rock_Stone"
    },
    {
      "x": 18,
      "y": 37,
      "z": 29,
      "name": "Rock_Stone"
    },
    {
      "x": 18,
      "y": 38,
      "z": 29,
      "name": "Soil_Dirt"
    },
    {
      "x": 18,
      "y": 39,
      "z": 29,
      "name": "Soil_Dirt"
    },
    {
      "x": 18,
      "y": 40,
      "z": 29,
      "name": "Soil_Dirt"
    },
    {
      "x": 18,
      "y": 41,
      "z": 29,
      "name": "Soil_Grass_Sunny"
    },
    {
      "x": 18,
      "y": 45,
      "z": 29,
      "name": "Plant_Leaves_Birch",
      "support": 15
    },
    {
      "x": 18,
      "y": 46,
      "z": 29,
      "name": "Plant_Leaves_Birch",
      "support": 15
    },
    {
      "x": 18,
      "y": 48,
      "z": 29,
      "name": "Wood_Birch_Trunk_Full",
      "support": 15
    },
    {
      "x": 18,
      "y": 49,
      "z": 29,
      "name": "Wood_Birch_Trunk_Full",
      "support": 15
    },
    {
      "x": 18,
      "y": 50,
      "z": 29,
      "name": "Wood_Birch_Trunk_Full",
      "support": 15
    },
    {
      "x": 18,
      "y": 51,
      "z": 29,
      "name": "Wood_Birch_Trunk_Full",
      "support": 15
    },
    {
      "x": 18,
      "y": 52,
      "z": 29,
      "name": "Wood_Birch_Trunk_Full",
      "support": 15
    },
    {
      "x": 18,
      "y": 57,
      "z": 29,
      "name": "Plant_Leaves_Birch",
      "support": 15
    },
    {
      "x": 18,
      "y": 35,
      "z": 30,
      "name": "Rock_Stone"
    },
    {
      "x": 18,
      "y": 36,
      "z": 30,
      "name": "Rock_Stone"
    },
    {
      "x": 18,
      "y": 37,
      "z": 30,
      "name": "Rock_Stone"
    },
    {
      "x": 18,
      "y": 38,
      "z": 30,
      "name": "Soil_Dirt"
    },
    {
      "x": 18,
      "y": 39,
      "z": 30,
      "name": "Soil_Dirt"
    },
    {
      "x": 18,
      "y": 40,
      "z": 30,
      "name": "Soil_Grass_Sunny"
    },
    {
      "x": 18,
      "y": 41,
      "z": 30,
      "name": "Plant_Grass_Sharp"
    },
    {
      "x": 18,
      "y": 45,
      "z": 30,
      "name": "Plant_Leaves_Birch",
      "support": 15
    },
    {
      "x": 18,
      "y": 48,
      "z": 30,
      "name": "Wood_Birch_Trunk_Full",
      "support": 15
    },
    {
      "x": 18,
      "y": 52,
      "z": 30,
      "name": "Wood_Birch_Branch_Long",
      "support": 15,
      "rotation": 4
    },
    {
      "x": 18,
      "y": 55,
      "z": 30,
      "name": "Plant_Leaves_Birch",
      "support": 15
    },
    {
      "x": 18,
      "y": 57,
      "z": 30,
      "name": "Plant_Leaves_Birch",
      "support": 15
    },
    {
      "x": 18,
      "y": 36,
      "z": 31,
      "name": "Rock_Stone"
    },
    {
      "x": 18,
      "y": 37,
      "z": 31,
      "name": "Rock_Stone"
    },
    {
      "x": 18,
      "y": 38,
      "z": 31,
      "name": "Soil_Dirt"
    },
    {
      "x": 18,
      "y": 39,
      "z": 31,
      "name": "Soil_Dirt"
    },
    {
      "x": 18,
      "y": 40,
      "z": 31,
      "name": "Soil_Grass_Sunny"
    },
    {
      "x": 18,
      "y": 48,
      "z": 31,
      "name": "Wood_Birch_Branch_Long",
      "support": 15,
      "rotation": 4
    },
    {
      "x": 18,
      "y": 49,
      "z": 31,
      "name": "Plant_Leaves_Birch",
      "support": 15
    },
    {
      "x": 18,
      "y": 52,
      "z": 31,
      "name": "Plant_Leaves_Birch",
      "support": 15
    },
    {
      "x": 18,
      "y": 53,
      "z": 31,
      "name": "Plant_Leaves_Birch",
      "support": 15
    },
    {
      "x": 18,
      "y": 55,
      "z": 31,
      "name": "Plant_Leaves_Birch",
      "support": 15
    },
    {
      "x": 18,
      "y": 37,
      "z": 32,
      "name": "Rock_Stone"
    },
    {
      "x": 18,
      "y": 38,
      "z": 32,
      "name": "Soil_Grass_Sunny"
    },
    {
      "x": 18,
      "y": 46,
      "z": 32,
      "name": "Plant_Leaves_Birch",
      "support": 15
    },
    {
      "x": 18,
      "y": 47,
      "z": 32,
      "name": "Plant_Leaves_Birch",
      "support": 15
    },
    {
      "x": 18,
      "y": 48,
      "z": 32,
      "name": "Plant_Leaves_Birch",
      "support": 15
    },
    {
      "x": 18,
      "y": 49,
      "z": 32,
      "name": "Plant_Leaves_Birch",
      "support": 15
    },
    {
      "x": 18,
      "y": 52,
      "z": 32,
      "name": "Plant_Leaves_Birch",
      "support": 15
    },
    {
      "x": 18,
      "y": 54,
      "z": 32,
      "name": "Plant_Leaves_Birch",
      "support": 15
    },
    {
      "x": 18,
      "y": 47,
      "z": 33,
      "name": "Plant_Leaves_Birch",
      "support": 15
    },
    {
      "x": 18,
      "y": 48,
      "z": 33,
      "name": "Plant_Leaves_Birch",
      "support": 15
    },
    {
      "x": 19,
      "y": 37,
      "z": 17,
      "name": "Rock_Stone"
    },
    {
      "x": 19,
      "y": 38,
      "z": 17,
      "name": "Soil_Dirt"
    },
    {
      "x": 19,
      "y": 39,
      "z": 17,
      "name": "Soil_Pathway"
    },
    {
      "x": 19,
      "y": 37,
      "z": 18,
      "name": "Rock_Stone"
    },
    {
      "x": 19,
      "y": 38,
      "z": 18,
      "name": "Soil_Dirt"
    },
    {
      "x": 19,
      "y": 39,
      "z": 18,
      "name": "Soil_Dirt"
    },
    {
      "x": 19,
      "y": 40,
      "z": 18,
      "name": "Soil_Pathway"
    },
    {
      "x": 19,
      "y": 37,
      "z": 19,
      "name": "Rock_Stone"
    },
    {
      "x": 19,
      "y": 38,
      "z": 19,
      "name": "Soil_Dirt"
    },
    {
      "x": 19,
      "y": 39,
      "z": 19,
      "name": "Soil_Dirt"
    },
    {
      "x": 19,
      "y": 40,
      "z": 19,
      "name": "Soil_Pathway"
    },
    {
      "x": 19,
      "y": 37,
      "z": 20,
      "name": "Rock_Stone"
    },
    {
      "x": 19,
      "y": 38,
      "z": 20,
      "name": "Soil_Dirt"
    },
    {
      "x": 19,
      "y": 39,
      "z": 20,
      "name": "Soil_Dirt"
    },
    {
      "x": 19,
      "y": 40,
      "z": 20,
      "name": "Soil_Dirt"
    },
    {
      "x": 19,
      "y": 41,
      "z": 20,
      "name": "Soil_Pathway"
    },
    {
      "x": 19,
      "y": 36,
      "z": 21,
      "name": "Rock_Stone"
    },
    {
      "x": 19,
      "y": 37,
      "z": 21,
      "name": "Rock_Stone"
    },
    {
      "x": 19,
      "y": 38,
      "z": 21,
      "name": "Soil_Dirt"
    },
    {
      "x": 19,
      "y": 39,
      "z": 21,
      "name": "Soil_Dirt"
    },
    {
      "x": 19,
      "y": 40,
      "z": 21,
      "name": "Soil_Dirt"
    },
    {
      "x": 19,
      "y": 41,
      "z": 21,
      "name": "Soil_Pathway"
    },
    {
      "x": 19,
      "y": 36,
      "z": 22,
      "name": "Rock_Stone"
    },
    {
      "x": 19,
      "y": 37,
      "z": 22,
      "name": "Rock_Stone"
    },
    {
      "x": 19,
      "y": 38,
      "z": 22,
      "name": "Soil_Dirt"
    },
    {
      "x": 19,
      "y": 39,
      "z": 22,
      "name": "Soil_Dirt"
    },
    {
      "x": 19,
      "y": 40,
      "z": 22,
      "name": "Soil_Dirt"
    },
    {
      "x": 19,
      "y": 41,
      "z": 22,
      "name": "Soil_Pathway"
    },
    {
      "x": 19,
      "y": 35,
      "z": 23,
      "name": "Rock_Stone"
    },
    {
