{
  "version": 8,
  "blockIdVersion": 8,
  "anchorX": 2,
  "anchorY": 4,
  "anchorZ": 1,
  "blocks": [
    {
      "x": -1,
      "y": 6,
      "z": -1,
      "name": "Plant_Coral_Block_Orange"
    },
    {
      "x": -1,
      "y": 7,
      "z": -1,
      "name": "Plant_Coral_Block_Orange"
    },
    {
      "x": -1,
      "y": 8,
      "z": -1,
      "name": "Plant_Coral_Block_Orange"
    },
    {
      "x": -1,
      "y": 9,
      "z": -1,
      "name": "Plant_Coral_Block_Orange"
    },
    {
      "x": -1,
      "y": 10,
      "z": -1,
      "name": "Plant_Coral_Block_Orange"
    },
    {
      "x": -1,
      "y": 3,
      "z": 0,
      "name": "Plant_Coral_Block_Orange"
    },
    {
      "x": -1,
      "y": 4,
      "z": 0,
      "name": "Plant_Coral_Block_Orange"
    },
    {
      "x": -1,
      "y": 5,
      "z": 0,
      "name": "Plant_Coral_Block_Orange"
    },
    {
      "x": -1,
      "y": 6,
      "z": 0,
      "name": "Plant_Coral_Block_Orange"
    },
    {
      "x": -1,
      "y": 7,
      "z": 0,
      "name": "Plant_Coral_Block_Orange"
    },
    {
      "x": -1,
      "y": 8,
      "z": 0,
      "name": "Plant_Coral_Block_Orange"
    },
    {
      "x": -1,
      "y": 9,
      "z": 0,
      "name": "Plant_Coral_Block_Orange"
    },
    {
      "x": -1,
      "y": 2,
      "z": 1,
      "name": "Plant_Coral_Block_Orange"
    },
    {
      "x": -1,
      "y": 3,
      "z": 1,
      "name": "Plant_Coral_Block_Orange"
    },
    {
      "x": -1,
      "y": 4,
      "z": 1,
      "name": "Plant_Coral_Block_Orange"
    },
    {
      "x": -1,
      "y": 5,
      "z": 1,
      "name": "Plant_Coral_Block_Orange"
    },
    {
      "x": -1,
      "y": 6,
      "z": 1,
      "name": "Plant_Coral_Block_Orange"
    },
    {
      "x": -1,
      "y": 7,
      "z": 1,
      "name": "Plant_Coral_Block_Orange"
    },
    {
      "x": -1,
      "y": 8,
      "z": 1,
      "name": "Plant_Coral_Block_Orange"
    },
    {
      "x": -1,
      "y": 9,
      "z": 1,
      "name": "Plant_Coral_Block_Orange"
    },
    {
      "x": -1,
      "y": 2,
      "z": 2,
      "name": "Plant_Coral_Block_Orange"
    },
    {
      "x": -1,
      "y": 3,
      "z": 2,
      "name": "Plant_Coral_Block_Orange"
    },
    {
      "x": -1,
      "y": 4,
      "z": 2,
      "name": "Plant_Coral_Block_Orange"
    },
    {
      "x": -1,
      "y": 5,
      "z": 2,
      "name": "Plant_Coral_Block_Orange"
    },
    {
      "x": 0,
      "y": 6,
      "z": -2,
      "name": "Plant_Coral_Block_Orange"
    },
    {
      "x": 0,
      "y": 7,
      "z": -2,
      "name": "Plant_Coral_Block_Orange"
    },
    {
      "x": 0,
      "y": 8,
      "z": -2,
      "name": "Plant_Coral_Block_Orange"
    },
    {
      "x": 0,
      "y": 9,
      "z": -2,
      "name": "Plant_Coral_Block_Orange"
    },
    {
      "x": 0,
      "y": 10,
      "z": -2,
      "name": "Plant_Coral_Block_Orange"
    },
    {
      "x": 0,
      "y": 3,
      "z": -1,
      "name": "Plant_Coral_Block_Orange"
    },
    {
      "x": 0,
      "y": 4,
      "z": -1,
      "name": "Plant_Coral_Block_Orange"
    },
    {
      "x": 0,
      "y": 5,
      "z": -1,
      "name": "Plant_Coral_Block_Orange"
    },
    {
      "x": 0,
      "y": 6,
      "z": -1,
      "name": "Rock_Slate"
    },
    {
      "x": 0,
      "y": 7,
      "z": -1,
      "name": "Rock_Slate"
    },
    {
      "x": 0,
      "y": 8,
      "z": -1,
      "name": "Rock_Slate"
    },
    {
      "x": 0,
      "y": 9,
      "z": -1,
      "name": "Rock_Slate"
    },
    {
      "x": 0,
      "y": 0,
      "z": 0,
      "name": "Plant_Coral_Block_Orange"
    },
    {
      "x": 0,
      "y": 1,
      "z": 0,
      "name": "Plant_Coral_Block_Orange"
    },
    {
      "x": 0,
      "y": 2,
      "z": 0,
      "name": "Plant_Coral_Block_Orange"
    },
    {
      "x": 0,
      "y": 3,
      "z": 0,
      "name": "Rock_Slate"
    },
    {
      "x": 0,
      "y": 4,
      "z": 0,
      "name": "Rock_Slate"
    },
    {
      "x": 0,
      "y": 5,
      "z": 0,
      "name": "Rock_Slate"
    },
    {
      "x": 0,
      "y": 6,
      "z": 0,
      "name": "Rock_Slate"
    },
    {
      "x": 0,
      "y": 7,
      "z": 0,
      "name": "Rock_Slate"
    },
    {
      "x": 0,
      "y": 8,
      "z": 0,
      "name": "Rock_Slate"
    },
    {
      "x": 0,
      "y": 0,
      "z": 1,
      "name": "Plant_Coral_Block_Orange"
    },
    {
      "x": 0,
      "y": 1,
      "z": 1,
      "name": "Plant_Coral_Block_Orange"
    },
    {
      "x": 0,
      "y": 2,
      "z": 1,
      "name": "Plant_Coral_Block_Orange"
    },
    {
      "x": 0,
      "y": 3,
      "z": 1,
      "name": "Rock_Slate"
    },
    {
      "x": 0,
      "y": 4,
      "z": 1,
      "name": "Rock_Slate"
    },
    {
      "x": 0,
      "y": 5,
      "z": 1,
      "name": "Rock_Slate"
    },
    {
      "x": 0,
      "y": 6,
      "z": 1,
      "name": "Rock_Slate"
    },
    {
      "x": 0,
      "y": 7,
      "z": 1,
      "name": "Rock_Slate"
    },
    {
      "x": 0,
      "y": 8,
      "z": 1,
      "name": "Rock_Slate"
    },
    {
      "x": 0,
      "y": 0,
      "z": 2,
      "name": "Plant_Coral_Block_Orange"
    },
    {
      "x": 0,
      "y": 1,
      "z": 2,
      "name": "Plant_Coral_Block_Orange"
    },
    {
      "x": 0,
      "y": 2,
      "z": 2,
      "name": "Plant_Coral_Block_Orange"
    },
    {
      "x": 0,
      "y": 3,
      "z": 2,
      "name": "Rock_Slate"
    },
    {
      "x": 0,
      "y": 4,
      "z": 2,
      "name": "Rock_Slate"
    },
    {
      "x": 0,
      "y": 5,
      "z": 2,
      "name": "Rock_Slate"
    },
    {
      "x": 0,
      "y": 6,
      "z": 2,
      "name": "Plant_Coral_Block_Orange"
    },
    {
      "x": 0,
      "y": 7,
      "z": 2,
      "name": "Plant_Coral_Block_Orange"
    },
    {
      "x": 0,
      "y": 8,
      "z": 2,
      "name": "Plant_Coral_Block_Orange"
    },
    {
      "x": 0,
      "y": 9,
      "z": 2,
      "name": "Plant_Coral_Block_Orange"
    },
    {
      "x": 0,
      "y": 3,
      "z": 3,
      "name": "Plant_Coral_Block_Orange"
    },
    {
      "x": 0,
      "y": 4,
      "z": 3,
      "name": "Plant_Coral_Block_Orange"
    },
    {
      "x": 0,
      "y": 5,
      "z": 3,
      "name": "Plant_Coral_Block_Orange"
    },
    {
      "x": 0,
      "y": 6,
      "z": 3,
      "name": "Plant_Coral_Block_Orange"
    },
    {
      "x": 1,
      "y": 5,
      "z": -2,
      "name": "Plant_Coral_Block_Orange"
    },
    {
      "x": 1,
      "y": 6,
      "z": -2,
      "name": "Plant_Coral_Block_Orange"
    },
    {
      "x": 1,
      "y": 7,
      "z": -2,
      "name": "Plant_Coral_Block_Orange"
    },
    {
      "x": 1,
      "y": 8,
      "z": -2,
      "name": "Plant_Coral_Block_Orange"
    },
    {
      "x": 1,
      "y": 9,
      "z": -2,
      "name": "Plant_Coral_Block_Orange"
    },
    {
      "x": 1,
      "y": 10,
      "z": -2,
      "name": "Plant_Coral_Block_Orange"
    },
    {
      "x": 1,
      "y": 0,
      "z": -1,
      "name": "Plant_Coral_Block_Orange"
    },
    {
      "x": 1,
      "y": 1,
      "z": -1,
      "name": "Plant_Coral_Block_Orange"
    },
    {
      "x": 1,
      "y": 2,
      "z": -1,
      "name": "Plant_Coral_Block_Orange"
    },
    {
      "x": 1,
      "y": 3,
      "z": -1,
      "name": "Plant_Coral_Block_Orange"
    },
    {
      "x": 1,
      "y": 4,
      "z": -1,
      "name": "Plant_Coral_Block_Orange"
    },
    {
      "x": 1,
      "y": 5,
      "z": -1,
      "name": "Plant_Coral_Block_Orange"
    },
    {
      "x": 1,
      "y": 6,
      "z": -1,
      "name": "Rock_Slate"
    },
    {
      "x": 1,
      "y": 7,
      "z": -1,
      "name": "Rock_Slate"
    },
    {
      "x": 1,
      "y": 8,
      "z": -1,
      "name": "Rock_Slate"
    },
    {
      "x": 1,
      "y": 9,
      "z": -1,
      "name": "Rock_Slate"
    },
    {
      "x": 1,
      "y": 0,
      "z": 0,
      "name": "Rock_Slate"
    },
    {
      "x": 1,
      "y": 1,
      "z": 0,
      "name": "Rock_Slate"
    },
    {
      "x": 1,
      "y": 2,
      "z": 0,
      "name": "Rock_Slate"
    },
    {
      "x": 1,
      "y": 3,
      "z": 0,
      "name": "Rock_Slate"
    },
    {
      "x": 1,
      "y": 4,
      "z": 0,
      "name": "Rock_Slate"
    },
    {
      "x": 1,
      "y": 5,
      "z": 0,
      "name": "Rock_Slate"
    },
    {
      "x": 1,
      "y": 6,
      "z": 0,
      "name": "Rock_Slate"
    },
    {
      "x": 1,
      "y": 7,
      "z": 0,
      "name": "Rock_Slate"
    },
    {
      "x": 1,
      "y": 8,
      "z": 0,
      "name": "Rock_Slate"
    },
    {
      "x": 1,
      "y": 0,
      "z": 1,
      "name": "Rock_Slate"
    },
    {
      "x": 1,
      "y": 1,
      "z": 1,
      "name": "Rock_Slate"
    },
    {
      "x": 1,
      "y": 2,
      "z": 1,
      "name": "Rock_Slate"
    },
    {
      "x": 1,
      "y": 3,
      "z": 1,
      "name": "Rock_Slate"
    },
    {
      "x": 1,
      "y": 4,
      "z": 1,
      "name": "Rock_Slate"
    },
    {
      "x": 1,
      "y": 5,
      "z": 1,
      "name": "Rock_Slate"
    },
    {
      "x": 1,
      "y": 6,
      "z": 1,
      "name": "Rock_Slate"
    },
    {
      "x": 1,
      "y": 7,
      "z": 1,
      "name": "Rock_Slate"
    },
    {
      "x": 1,
      "y": 0,
      "z": 2,
      "name": "Rock_Slate"
    },
    {
      "x": 1,
      "y": 1,
      "z": 2,
      "name": "Rock_Slate"
    },
    {
      "x": 1,
      "y": 2,
      "z": 2,
      "name": "Rock_Slate"
    },
    {
      "x": 1,
      "y": 3,
      "z": 2,
      "name": "Rock_Slate"
    },
    {
      "x": 1,
      "y": 4,
      "z": 2,
      "name": "Rock_Slate"
    },
    {
      "x": 1,
      "y": 5,
      "z": 2,
      "name": "Rock_Slate"
    },
    {
      "x": 1,
      "y": 6,
      "z": 2,
      "name": "Plant_Coral_Block_Orange"
    },
    {
      "x": 1,
      "y": 7,
      "z": 2,
      "name": "Plant_Coral_Block_Orange"
    },
    {
      "x": 1,
      "y": 8,
      "z": 2,
      "name": "Plant_Coral_Block_Orange"
    },
    {
      "x": 1,
      "y": 0,
      "z": 3,
      "name": "Plant_Coral_Block_Orange"
    },
    {
      "x": 1,
      "y": 1,
      "z": 3,
      "name": "Plant_Coral_Block_Orange"
    },
    {
      "x": 1,
      "y": 2,
      "z": 3,
      "name": "Plant_Coral_Block_Orange"
    },
    {
      "x": 1,
      "y": 3,
      "z": 3,
      "name": "Plant_Coral_Block_Orange"
    },
    {
      "x": 1,
      "y": 4,
      "z": 3,
      "name": "Plant_Coral_Block_Orange"
    },
    {
      "x": 1,
      "y": 5,
      "z": 3,
      "name": "Plant_Coral_Block_Orange"
    },
    {
      "x": 1,
      "y": 6,
      "z": 3,
      "name": "Plant_Coral_Block_Orange"
    },
    {
      "x": 2,
      "y": 5,
      "z": -2,
      "name": "Plant_Coral_Block_Orange"
    },
    {
      "x": 2,
      "y": 6,
      "z": -2,
      "name": "Plant_Coral_Block_Orange"
    },
    {
      "x": 2,
      "y": 7,
      "z": -2,
      "name": "Plant_Coral_Block_Orange"
    },
    {
      "x": 2,
      "y": 8,
      "z": -2,
      "name": "Plant_Coral_Block_Orange"
    },
    {
      "x": 2,
      "y": 9,
      "z": -2,
      "name": "Plant_Coral_Block_Orange"
    },
    {
      "x": 2,
      "y": 10,
      "z": -2,
      "name": "Plant_Coral_Block_Orange"
    },
    {
      "x": 2,
      "y": 0,
      "z": -1,
      "name": "Plant_Coral_Block_Orange"
    },
    {
      "x": 2,
      "y": 1,
      "z": -1,
      "name": "Plant_Coral_Block_Orange"
    },
    {
      "x": 2,
      "y": 2,
      "z": -1,
      "name": "Plant_Coral_Block_Orange"
    },
    {
      "x": 2,
      "y": 3,
      "z": -1,
      "name": "Plant_Coral_Block_Orange"
    },
    {
      "x": 2,
      "y": 4,
      "z": -1,
      "name": "Plant_Coral_Block_Orange"
    },
    {
      "x": 2,
      "y": 5,
      "z": -1,
      "name": "Plant_Coral_Block_Orange"
    },
    {
      "x": 2,
      "y": 6,
      "z": -1,
      "name": "Rock_Slate"
    },
    {
      "x": 2,
      "y": 7,
      "z": -1,
      "name": "Rock_Slate"
    },
    {
      "x": 2,
      "y": 8,
      "z": -1,
      "name": "Rock_Slate"
    },
    {
      "x": 2,
      "y": 9,
      "z": -1,
      "name": "Rock_Slate"
    },
    {
      "x": 2,
      "y": 0,
      "z": 0,
      "name": "Rock_Slate"
    },
    {
      "x": 2,
      "y": 1,
      "z": 0,
      "name": "Rock_Slate"
    },
    {
      "x": 2,
      "y": 2,
      "z": 0,
      "name": "Rock_Slate"
    },
    {
      "x": 2,
      "y": 3,
      "z": 0,
      "name": "Rock_Slate"
    },
    {
      "x": 2,
      "y": 4,
      "z": 0,
      "name": "Rock_Slate"
    },
    {
      "x": 2,
      "y": 5,
      "z": 0,
      "name": "Rock_Slate"
    },
    {
      "x": 2,
      "y": 6,
      "z": 0,
      "name": "Rock_Slate"
    },
    {
      "x": 2,
      "y": 7,
      "z": 0,
      "name": "Rock_Slate"
    },
    {
      "x": 2,
      "y": 8,
      "z": 0,
      "name": "Rock_Slate"
    },
    {
      "x": 2,
      "y": 0,
      "z": 1,
      "name": "Rock_Slate"
    },
    {
      "x": 2,
      "y": 1,
      "z": 1,
      "name": "Rock_Slate"
    },
    {
      "x": 2,
      "y": 2,
      "z": 1,
      "name": "Rock_Slate"
    },
    {
      "x": 2,
      "y": 3,
      "z": 1,
      "name": "Rock_Slate"
    },
    {
      "x": 2,
      "y": 4,
      "z": 1,
      "name": "Rock_Slate"
    },
    {
      "x": 2,
      "y": 5,
      "z": 1,
      "name": "Rock_Slate"
    },
    {
      "x": 2,
      "y": 6,
      "z": 1,
      "name": "Rock_Slate"
    },
    {
      "x": 2,
      "y": 7,
      "z": 1,
      "name": "Rock_Slate"
    },
    {
      "x": 2,
      "y": 0,
      "z": 2,
      "name": "Rock_Slate"
    },
    {
      "x": 2,
      "y": 1,
      "z": 2,
      "name": "Rock_Slate"
    },
    {
      "x": 2,
      "y": 2,
      "z": 2,
      "name": "Rock_Slate"
    },
    {
      "x": 2,
      "y": 3,
      "z": 2,
      "name": "Rock_Slate"
    },
    {
      "x": 2,
      "y": 4,
      "z": 2,
      "name": "Rock_Slate"
    },
    {
      "x": 2,
      "y": 5,
      "z": 2,
      "name": "Rock_Slate"
    },
    {
      "x": 2,
      "y": 6,
      "z": 2,
      "name": "Plant_Coral_Block_Orange"
    },
    {
      "x": 2,
      "y": 7,
      "z": 2,
      "name": "Plant_Coral_Block_Orange"
    },
    {
      "x": 2,
      "y": 8,
      "z": 2,
      "name": "Plant_Coral_Block_Orange"
    },
    {
      "x": 2,
      "y": 0,
      "z": 3,
      "name": "Plant_Coral_Block_Orange"
    },
    {
      "x": 2,
      "y": 1,
      "z": 3,
      "name": "Plant_Coral_Block_Orange"
    },
    {
      "x": 2,
      "y": 2,
      "z": 3,
      "name": "Plant_Coral_Block_Orange"
    },
    {
      "x": 2,
      "y": 3,
      "z": 3,
      "name": "Plant_Coral_Block_Orange"
    },
    {
      "x": 2,
      "y": 4,
      "z": 3,
      "name": "Plant_Coral_Block_Orange"
    },
    {
      "x": 2,
      "y": 5,
      "z": 3,
      "name": "Plant_Coral_Block_Orange"
    },
    {
      "x": 3,
      "y": 0,
      "z": -1,
      "name": "Plant_Coral_Block_Orange"
    },
    {
      "x": 3,
      "y": 1,
      "z": -1,
      "name": "Plant_Coral_Block_Orange"
    },
    {
      "x": 3,
      "y": 2,
      "z": -1,
      "name": "Plant_Coral_Block_Orange"
    },
    {
      "x": 3,
      "y": 6,
      "z": -1,
      "name": "Plant_Coral_Block_Orange"
    },
    {
      "x": 3,
      "y": 7,
      "z": -1,
      "name": "Plant_Coral_Block_Orange"
    },
    {
      "x": 3,
      "y": 8,
      "z": -1,
      "name": "Plant_Coral_Block_Orange"
    },
    {
      "x": 3,
      "y": 9,
      "z": -1,
      "name": "Plant_Coral_Block_Orange"
    },
    {
      "x": 3,
      "y": 0,
      "z": 0,
      "name": "Rock_Slate"
    },
    {
      "x": 3,
      "y": 1,
      "z": 0,
      "name": "Rock_Slate"
    },
    {
      "x": 3,
      "y": 2,
      "z": 0,
      "name": "Rock_Slate"
    },
    {
      "x": 3,
      "y": 3,
      "z": 0,
      "name": "Plant_Coral_Block_Orange"
    },
    {
      "x": 3,
      "y": 4,
      "z": 0,
      "name": "Plant_Coral_Block_Orange"
    },
    {
      "x": 3,
      "y": 5,
      "z": 0,
      "name": "Plant_Coral_Block_Orange"
    },
    {
      "x": 3,
      "y": 6,
      "z": 0,
      "name": "Plant_Coral_Block_Orange"
    },
    {
      "x": 3,
      "y": 7,
      "z": 0,
      "name": "Plant_Coral_Block_Orange"
    },
    {
      "x": 3,
      "y": 8,
      "z": 0,
      "name": "Plant_Coral_Block_Orange"
    },
    {
      "x": 3,
      "y": 9,
      "z": 0,
      "name": "Plant_Coral_Block_Orange"
    },
    {
      "x": 3,
      "y": 0,
      "z": 1,
      "name": "Rock_Slate"
    },
    {
      "x": 3,
      "y": 1,
      "z": 1,
      "name": "Rock_Slate"
    },
    {
      "x": 3,
      "y": 2,
      "z": 1,
      "name": "Rock_Slate"
    },
    {
      "x": 3,
      "y": 3,
      "z": 1,
      "name": "Plant_Coral_Block_Orange"
    },
    {
      "x": 3,
      "y": 4,
      "z": 1,
      "name": "Plant_Coral_Block_Orange"
    },
    {
      "x": 3,
      "y": 5,
      "z": 1,
      "name": "Plant_Coral_Block_Orange"
    },
    {
      "x": 3,
      "y": 6,
      "z": 1,
      "name": "Plant_Coral_Block_Orange"
    },
    {
      "x": 3,
      "y": 7,
      "z": 1,
      "name": "Plant_Coral_Block_Orange"
    },
    {
      "x": 3,
      "y": 8,
      "z": 1,
      "name": "Plant_Coral_Block_Orange"
    },
    {
      "x": 3,
      "y": 0,
      "z": 2,
      "name": "Rock_Slate"
    },
    {
      "x": 3,
      "y": 1,
      "z": 2,
      "name": "Rock_Slate"
    },
    {
      "x": 3,
      "y": 2,
      "z": 2,
      "name": "Rock_Slate"
    },
    {
      "x": 3,
      "y": 3,
      "z": 2,
      "name": "Plant_Coral_Block_Orange"
    },
    {
      "x": 3,
      "y": 4,
      "z": 2,
      "name": "Plant_Coral_Block_Orange"
    },
    {
      "x": 3,
      "y": 5,
      "z": 2,
      "name": "Plant_Coral_Block_Orange"
    },
    {
      "x": 3,
      "y": 0,
      "z": 3,
      "name": "Plant_Coral_Block_Orange"
    },
    {
      "x": 3,
      "y": 1,
      "z": 3,
      "name": "Plant_Coral_Block_Orange"
    },
    {
      "x": 3,
      "y": 2,
      "z": 3,
      "name": "Plant_Coral_Block_Orange"
    },
    {
      "x": 4,
      "y": 0,
      "z": 0,
      "name": "Plant_Coral_Block_Orange"
    },
    {
      "x": 4,
      "y": 1,
      "z": 0,
      "name": "Plant_Coral_Block_Orange"
    },
    {
      "x": 4,
      "y": 2,
      "z": 0,
      "name": "Plant_Coral_Block_Orange"
    },
    {
      "x": 4,
      "y": 0,
      "z": 1,
      "name": "Plant_Coral_Block_Orange"
    },
    {
      "x": 4,
      "y": 1,
      "z": 1,
      "name": "Plant_Coral_Block_Orange"
    },
    {
      "x": 4,
      "y": 2,
      "z": 1,
      "name": "Plant_Coral_Block_Orange"
    },
    {
      "x": 4,
      "y": 3,
      "z": 1,
      "name": "Plant_Coral_Block_Orange"
    },
    {
      "x": 4,
      "y": 0,
      "z": 2,
      "name": "Plant_Coral_Block_Orange"
    },
    {
      "x": 4,
      "y": 1,
      "z": 2,
      "name": "Plant_Coral_Block_Orange"
    },
    {
      "x": 4,
      "y": 2,
      "z": 2,
      "name": "Plant_Coral_Block_Orange"
    },
    {
      "x": 4,
      "y": 3,
      "z": 2,
      "name": "Plant_Coral_Block_Orange"
    }
  ],
  "entities": [
    {
      "Components": {
        "Nameplate": {
          "Text": "Ocean_Fish"
        },
        "HiddenFromAdventurePlayer": {},
        "SpawnMarkerComponent": {
          "SpawnMarker": "Ocean_Fish",
          "RespawnTime": 0.0,
          "SpawnCount": 0
        },
        "Transform": {
          "Position": {
            "X": 1.8752753906246653,
            "Y": 10.362239086914144,
            "Z": 0.7578667968759873
          },
          "Rotation": {
            "Pitch": 0.0,
            "Yaw": 20.562273025512695,
            "Roll": 0.0
          }
        },
        "Model": {
          "Model": {
            "Id": "Mannequin",
            "Scale": 1.0
          }
        },
        "UUID": {
          "UUID": {
            "$binary": "5tHgVYfrOqSq+6DlMkgYlQ==",
            "$type": "04"
          }
        },
        "HeadRotation": {
          "Rotation": {
            "Pitch": 0.0,
            "Yaw": 17.42068099975586,
            "Roll": 0.0
          }
        }
      }
    }
  ]
}