{
  "version": 8,
  "blockIdVersion": 8,
  "anchorX": -3,
  "anchorY": 9,
  "anchorZ": -1,
  "blocks": [
    {
      "x": -6,
      "y": 6,
      "z": -7,
      "name": "Rock_Shale_Cobble_Half",
      "rotation": 7
    },
    {
      "x": -6,
      "y": 7,
      "z": -7,
      "name": "Rock_Shale_Cobble_Half",
      "rotation": 7
    },
    {
      "x": -6,
      "y": 8,
      "z": -7,
      "name": "Rock_Shale_Brick_Ornate"
    },
    {
      "x": -6,
      "y": 3,
      "z": -6,
      "name": "Rock_Shale"
    },
    {
      "x": -6,
      "y": 4,
      "z": -6,
      "name": "Rock_Shale_Cobble"
    },
    {
      "x": -6,
      "y": 5,
      "z": -6,
      "name": "Rock_Shale_Cobble_Half",
      "rotation": 7
    },
    {
      "x": -6,
      "y": 6,
      "z": -6,
      "name": "Rock_Shale_Cobble_Half",
      "rotation": 7
    },
    {
      "x": -6,
      "y": 7,
      "z": -6,
      "name": "Rock_Shale_Cobble_Half",
      "rotation": 7
    },
    {
      "x": -6,
      "y": 8,
      "z": -6,
      "name": "Rock_Shale"
    },
    {
      "x": -6,
      "y": 9,
      "z": -6,
      "name": "Rock_Shale"
    },
    {
      "x": -6,
      "y": 1,
      "z": -5,
      "name": "Rock_Shale"
    },
    {
      "x": -6,
      "y": 2,
      "z": -5,
      "name": "Rock_Shale"
    },
    {
      "x": -6,
      "y": 3,
      "z": -5,
      "name": "Rock_Shale"
    },
    {
      "x": -6,
      "y": 4,
      "z": -5,
      "name": "Rock_Shale_Cobble"
    },
    {
      "x": -6,
      "y": 5,
      "z": -5,
      "name": "Rock_Shale_Cobble"
    },
    {
      "x": -6,
      "y": 6,
      "z": -5,
      "name": "Rock_Shale_Cobble"
    },
    {
      "x": -6,
      "y": 7,
      "z": -5,
      "name": "Rock_Shale_Cobble"
    },
    {
      "x": -6,
      "y": 8,
      "z": -5,
      "name": "Rock_Shale_Brick"
    },
    {
      "x": -6,
      "y": 9,
      "z": -5,
      "name": "Rock_Basalt_Cobble"
    },
    {
      "x": -6,
      "y": 10,
      "z": -5,
      "name": "Rock_Basalt_Cobble"
    },
    {
      "x": -6,
      "y": 11,
      "z": -5,
      "name": "Rock_Basalt_Cobble"
    },
    {
      "x": -6,
      "y": 12,
      "z": -5,
      "name": "Rock_Basalt_Cobble"
    },
    {
      "x": -6,
      "y": 13,
      "z": -5,
      "name": "Rock_Basalt_Cobble"
    },
    {
      "x": -6,
      "y": 14,
      "z": -5,
      "name": "Rubble_Basalt"
    },
    {
      "x": -6,
      "y": 1,
      "z": -4,
      "name": "Rock_Shale"
    },
    {
      "x": -6,
      "y": 2,
      "z": -4,
      "name": "Rock_Shale"
    },
    {
      "x": -6,
      "y": 3,
      "z": -4,
      "name": "Rock_Shale"
    },
    {
      "x": -6,
      "y": 4,
      "z": -4,
      "name": "Rock_Shale_Cobble"
    },
    {
      "x": -6,
      "y": 5,
      "z": -4,
      "name": "Rock_Shale_Cobble"
    },
    {
      "x": -6,
      "y": 6,
      "z": -4,
      "name": "Rock_Shale_Cobble"
    },
    {
      "x": -6,
      "y": 7,
      "z": -4,
      "name": "Rock_Shale_Cobble"
    },
    {
      "x": -6,
      "y": 8,
      "z": -4,
      "name": "Rock_Shale_Cobble"
    },
    {
      "x": -6,
      "y": 9,
      "z": -4,
      "name": "Rock_Basalt_Cobble"
    },
    {
      "x": -6,
      "y": 10,
      "z": -4,
      "name": "Rock_Basalt_Cobble"
    },
    {
      "x": -6,
      "y": 11,
      "z": -4,
      "name": "Rock_Basalt_Cobble"
    },
    {
      "x": -6,
      "y": 12,
      "z": -4,
      "name": "Rock_Basalt_Cobble"
    },
    {
      "x": -6,
      "y": 13,
      "z": -4,
      "name": "Rock_Basalt_Cobble"
    },
    {
      "x": -6,
      "y": 14,
      "z": -4,
      "name": "Plant_Moss_Rug_Lime"
    },
    {
      "x": -6,
      "y": 2,
      "z": -3,
      "name": "Rock_Shale"
    },
    {
      "x": -6,
      "y": 3,
      "z": -3,
      "name": "Rock_Shale"
    },
    {
      "x": -6,
      "y": 4,
      "z": -3,
      "name": "Rock_Shale_Cobble"
    },
    {
      "x": -6,
      "y": 5,
      "z": -3,
      "name": "Rock_Shale_Cobble"
    },
    {
      "x": -6,
      "y": 6,
      "z": -3,
      "name": "Rock_Shale_Cobble"
    },
    {
      "x": -6,
      "y": 7,
      "z": -3,
      "name": "Rock_Shale_Cobble"
    },
    {
      "x": -6,
      "y": 8,
      "z": -3,
      "name": "Rock_Shale_Cobble"
    },
    {
      "x": -6,
      "y": 9,
      "z": -3,
      "name": "Rock_Shale_Cobble"
    },
    {
      "x": -6,
      "y": 10,
      "z": -3,
      "name": "Rock_Basalt_Cobble"
    },
    {
      "x": -6,
      "y": 11,
      "z": -3,
      "name": "Rock_Basalt_Cobble"
    },
    {
      "x": -6,
      "y": 12,
      "z": -3,
      "name": "Rock_Basalt_Cobble"
    },
    {
      "x": -6,
      "y": 13,
      "z": -3,
      "name": "Rock_Basalt_Cobble"
    },
    {
      "x": -5,
      "y": 4,
      "z": -7,
      "name": "Rock_Shale"
    },
    {
      "x": -5,
      "y": 5,
      "z": -7,
      "name": "Rock_Shale_Cobble"
    },
    {
      "x": -5,
      "y": 6,
      "z": -7,
      "name": "Rock_Shale_Cobble"
    },
    {
      "x": -5,
      "y": 7,
      "z": -7,
      "name": "Rock_Shale_Cobble"
    },
    {
      "x": -5,
      "y": 8,
      "z": -7,
      "name": "Rock_Shale_Brick_Ornate"
    },
    {
      "x": -5,
      "y": 9,
      "z": -7,
      "name": "Rock_Shale_Brick_Smooth"
    },
    {
      "x": -5,
      "y": 10,
      "z": -7,
      "name": "Rock_Shale_Brick_Smooth"
    },
    {
      "x": -5,
      "y": 11,
      "z": -7,
      "name": "Rock_Shale_Brick"
    },
    {
      "x": -5,
      "y": 12,
      "z": -7,
      "name": "Rock_Shale_Brick"
    },
    {
      "x": -5,
      "y": 0,
      "z": -6,
      "name": "Rock_Shale"
    },
    {
      "x": -5,
      "y": 1,
      "z": -6,
      "name": "Rock_Shale"
    },
    {
      "x": -5,
      "y": 2,
      "z": -6,
      "name": "Rock_Shale"
    },
    {
      "x": -5,
      "y": 3,
      "z": -6,
      "name": "Rock_Shale"
    },
    {
      "x": -5,
      "y": 4,
      "z": -6,
      "name": "Rock_Shale"
    },
    {
      "x": -5,
      "y": 5,
      "z": -6,
      "name": "Rock_Shale_Cobble"
    },
    {
      "x": -5,
      "y": 6,
      "z": -6,
      "name": "Rock_Shale_Cobble"
    },
    {
      "x": -5,
      "y": 7,
      "z": -6,
      "name": "Rock_Shale_Cobble"
    },
    {
      "x": -5,
      "y": 8,
      "z": -6,
      "name": "Rock_Shale"
    },
    {
      "x": -5,
      "y": 9,
      "z": -6,
      "name": "Rock_Basalt_Cobble"
    },
    {
      "x": -5,
      "y": 10,
      "z": -6,
      "name": "Rock_Basalt_Cobble"
    },
    {
      "x": -5,
      "y": 11,
      "z": -6,
      "name": "Rock_Basalt_Cobble"
    },
    {
      "x": -5,
      "y": 0,
      "z": -5,
      "name": "Rock_Shale"
    },
    {
      "x": -5,
      "y": 1,
      "z": -5,
      "name": "Rock_Shale"
    },
    {
      "x": -5,
      "y": 2,
      "z": -5,
      "name": "Rock_Shale"
    },
    {
      "x": -5,
      "y": 3,
      "z": -5,
      "name": "Rock_Shale"
    },
    {
      "x": -5,
      "y": 4,
      "z": -5,
      "name": "Rock_Shale_Cobble"
    },
    {
      "x": -5,
      "y": 5,
      "z": -5,
      "name": "Rock_Shale_Cobble"
    },
    {
      "x": -5,
      "y": 6,
      "z": -5,
      "name": "Rock_Shale_Cobble"
    },
    {
      "x": -5,
      "y": 7,
      "z": -5,
      "name": "Rock_Shale_Cobble"
    },
    {
      "x": -5,
      "y": 8,
      "z": -5,
      "name": "Rock_Shale_Brick"
    },
    {
      "x": -5,
      "y": 9,
      "z": -5,
      "name": "Rock_Shale_Brick"
    },
    {
      "x": -5,
      "y": 10,
      "z": -5,
      "name": "Rock_Basalt_Cobble"
    },
    {
      "x": -5,
      "y": 11,
      "z": -5,
      "name": "Rock_Basalt_Cobble"
    },
    {
      "x": -5,
      "y": 12,
      "z": -5,
      "name": "Rock_Basalt_Cobble"
    },
    {
      "x": -5,
      "y": 13,
      "z": -5,
      "name": "Rock_Shale_Brick"
    },
    {
      "x": -5,
      "y": 14,
      "z": -5,
      "name": "Rock_Shale_Brick"
    },
    {
      "x": -5,
      "y": 0,
      "z": -4,
      "name": "Rock_Shale"
    },
    {
      "x": -5,
      "y": 1,
      "z": -4,
      "name": "Rock_Shale"
    },
    {
      "x": -5,
      "y": 2,
      "z": -4,
      "name": "Rock_Shale"
    },
    {
      "x": -5,
      "y": 3,
      "z": -4,
      "name": "Rock_Shale"
    },
    {
      "x": -5,
      "y": 4,
      "z": -4,
      "name": "Rock_Shale_Cobble"
    },
    {
      "x": -5,
      "y": 5,
      "z": -4,
      "name": "Rock_Shale_Cobble"
    },
    {
      "x": -5,
      "y": 6,
      "z": -4,
      "name": "Rock_Shale_Cobble"
    },
    {
      "x": -5,
      "y": 7,
      "z": -4,
      "name": "Rock_Shale_Cobble"
    },
    {
      "x": -5,
      "y": 8,
      "z": -4,
      "name": "Rock_Shale_Cobble"
    },
    {
      "x": -5,
      "y": 9,
      "z": -4,
      "name": "Rock_Shale_Cobble"
    },
    {
      "x": -5,
      "y": 10,
      "z": -4,
      "name": "Rock_Basalt_Cobble"
    },
    {
      "x": -5,
      "y": 11,
      "z": -4,
      "name": "Rock_Basalt_Cobble"
    },
    {
      "x": -5,
      "y": 12,
      "z": -4,
      "name": "Rock_Basalt_Cobble"
    },
    {
      "x": -5,
      "y": 13,
      "z": -4,
      "name": "Rock_Basalt_Cobble"
    },
    {
      "x": -5,
      "y": 14,
      "z": -4,
      "name": "Plant_Moss_Rug_Lime"
    },
    {
      "x": -5,
      "y": 1,
      "z": -3,
      "name": "Rock_Shale"
    },
    {
      "x": -5,
      "y": 2,
      "z": -3,
      "name": "Rock_Shale"
    },
    {
      "x": -5,
      "y": 3,
      "z": -3,
      "name": "Rock_Shale"
    },
    {
      "x": -5,
      "y": 4,
      "z": -3,
      "name": "Rock_Shale_Cobble"
    },
    {
      "x": -5,
      "y": 5,
      "z": -3,
      "name": "Rock_Shale_Cobble"
    },
    {
      "x": -5,
      "y": 6,
      "z": -3,
      "name": "Rock_Shale_Cobble"
    },
    {
      "x": -5,
      "y": 7,
      "z": -3,
      "name": "Rock_Shale_Cobble"
    },
    {
      "x": -5,
      "y": 8,
      "z": -3,
      "name": "Rock_Shale_Cobble"
    },
    {
      "x": -5,
      "y": 9,
      "z": -3,
      "name": "Rock_Shale_Cobble"
    },
    {
      "x": -5,
      "y": 10,
      "z": -3,
      "name": "Rock_Basalt_Cobble"
    },
    {
      "x": -5,
      "y": 11,
      "z": -3,
      "name": "Rock_Basalt_Cobble"
    },
    {
      "x": -5,
      "y": 12,
      "z": -3,
      "name": "Rock_Basalt_Cobble"
    },
    {
      "x": -5,
      "y": 13,
      "z": -3,
      "name": "Rock_Basalt_Cobble"
    },
    {
      "x": -5,
      "y": 14,
      "z": -3,
      "name": "Plant_Moss_Rug_Lime"
    },
    {
      "x": -4,
      "y": 2,
      "z": -7,
      "name": "Rock_Shale"
    },
    {
      "x": -4,
      "y": 3,
      "z": -7,
      "name": "Rock_Shale"
    },
    {
      "x": -4,
      "y": 4,
      "z": -7,
      "name": "Rock_Shale"
    },
    {
      "x": -4,
      "y": 5,
      "z": -7,
      "name": "Rock_Shale_Cobble"
    },
    {
      "x": -4,
      "y": 6,
      "z": -7,
      "name": "Rock_Shale_Cobble"
    },
    {
      "x": -4,
      "y": 7,
      "z": -7,
      "name": "Rock_Shale_Cobble"
    },
    {
      "x": -4,
      "y": 8,
      "z": -7,
      "name": "Rock_Shale_Brick_Ornate"
    },
    {
      "x": -4,
      "y": 9,
      "z": -7,
      "name": "Rock_Shale_Brick_Smooth"
    },
    {
      "x": -4,
      "y": 10,
      "z": -7,
      "name": "Rock_Shale_Brick_Smooth"
    },
    {
      "x": -4,
      "y": 11,
      "z": -7,
      "name": "Rock_Shale_Brick"
    },
    {
      "x": -4,
      "y": 12,
      "z": -7,
      "name": "Rock_Shale_Brick"
    },
    {
      "x": -4,
      "y": 13,
      "z": -7,
      "name": "Rock_Shale_Brick"
    },
    {
      "x": -4,
      "y": 14,
      "z": -7,
      "name": "Rock_Shale_Brick"
    },
    {
      "x": -4,
      "y": 15,
      "z": -7,
      "name": "Rock_Shale_Brick"
    },
    {
      "x": -4,
      "y": 0,
      "z": -6,
      "name": "Rock_Shale"
    },
    {
      "x": -4,
      "y": 1,
      "z": -6,
      "name": "Rock_Shale"
    },
    {
      "x": -4,
      "y": 2,
      "z": -6,
      "name": "Rock_Shale"
    },
    {
      "x": -4,
      "y": 3,
      "z": -6,
      "name": "Rock_Shale"
    },
    {
      "x": -4,
      "y": 4,
      "z": -6,
      "name": "Rock_Shale"
    },
    {
      "x": -4,
      "y": 5,
      "z": -6,
      "name": "Rock_Shale_Cobble"
    },
    {
      "x": -4,
      "y": 6,
      "z": -6,
      "name": "Rock_Shale_Cobble"
    },
    {
      "x": -4,
      "y": 7,
      "z": -6,
      "name": "Rock_Shale_Cobble"
    },
    {
      "x": -4,
      "y": 8,
      "z": -6,
      "name": "Rock_Shale"
    },
    {
      "x": -4,
      "y": 9,
      "z": -6,
      "name": "Rock_Shale"
    },
    {
      "x": -4,
      "y": 10,
      "z": -6,
      "name": "Rock_Basalt_Cobble"
    },
    {
      "x": -4,
      "y": 11,
      "z": -6,
      "name": "Rock_Basalt_Cobble"
    },
    {
      "x": -4,
      "y": 12,
      "z": -6,
      "name": "Rock_Basalt_Cobble"
    },
    {
      "x": -4,
      "y": 13,
      "z": -6,
      "name": "Rock_Shale"
    },
    {
      "x": -4,
      "y": 14,
      "z": -6,
      "name": "Rock_Shale"
    },
    {
      "x": -4,
      "y": 0,
      "z": -5,
      "name": "Rock_Shale"
    },
    {
      "x": -4,
      "y": 1,
      "z": -5,
      "name": "Rock_Shale"
    },
    {
      "x": -4,
      "y": 2,
      "z": -5,
      "name": "Rock_Shale"
    },
    {
      "x": -4,
      "y": 3,
      "z": -5,
      "name": "Rock_Shale"
    },
    {
      "x": -4,
      "y": 4,
      "z": -5,
      "name": "Rock_Shale"
    },
    {
      "x": -4,
      "y": 5,
      "z": -5,
      "name": "Rock_Shale_Cobble"
    },
    {
      "x": -4,
      "y": 6,
      "z": -5,
      "name": "Rock_Shale_Cobble"
    },
    {
      "x": -4,
      "y": 7,
      "z": -5,
      "name": "Rock_Shale_Cobble"
    },
    {
      "x": -4,
      "y": 8,
      "z": -5,
      "name": "Rock_Shale_Brick"
    },
    {
      "x": -4,
      "y": 9,
      "z": -5,
      "name": "Rock_Shale_Brick"
    },
    {
      "x": -4,
      "y": 10,
      "z": -5,
      "name": "Rock_Shale_Brick"
    },
    {
      "x": -4,
      "y": 11,
      "z": -5,
      "name": "Rock_Shale_Brick"
    },
    {
      "x": -4,
      "y": 12,
      "z": -5,
      "name": "Rock_Shale_Brick"
    },
    {
      "x": -4,
      "y": 13,
      "z": -5,
      "name": "Rock_Shale_Brick"
    },
    {
      "x": -4,
      "y": 14,
      "z": -5,
      "name": "Rock_Shale_Brick"
    },
    {
      "x": -4,
      "y": 15,
      "z": -5,
      "name": "Rock_Shale_Brick"
    },
    {
      "x": -4,
      "y": 0,
      "z": -4,
      "name": "Rock_Shale"
    },
    {
      "x": -4,
      "y": 1,
      "z": -4,
      "name": "Rock_Shale"
    },
    {
      "x": -4,
      "y": 2,
      "z": -4,
      "name": "Rock_Shale"
    },
    {
      "x": -4,
      "y": 3,
      "z": -4,
      "name": "Rock_Shale"
    },
    {
      "x": -4,
      "y": 4,
      "z": -4,
      "name": "Rock_Shale_Cobble"
    },
    {
      "x": -4,
      "y": 5,
      "z": -4,
      "name": "Rock_Shale_Cobble"
    },
    {
      "x": -4,
      "y": 6,
      "z": -4,
      "name": "Rock_Shale_Cobble"
    },
    {
      "x": -4,
      "y": 7,
      "z": -4,
      "name": "Rock_Shale_Cobble"
    },
    {
      "x": -4,
      "y": 8,
      "z": -4,
      "name": "Rock_Shale_Cobble"
    },
    {
      "x": -4,
      "y": 9,
      "z": -4,
      "name": "Rock_Shale_Cobble"
    },
    {
      "x": -4,
      "y": 10,
      "z": -4,
      "name": "Rock_Basalt_Cobble"
    },
    {
      "x": -4,
      "y": 11,
      "z": -4,
      "name": "Rock_Basalt_Cobble"
    },
    {
      "x": -4,
      "y": 12,
      "z": -4,
      "name": "Rock_Basalt_Cobble"
    },
    {
      "x": -4,
      "y": 13,
      "z": -4,
      "name": "Soil_Grass_Cold"
    },
    {
      "x": -4,
      "y": 14,
      "z": -4,
      "name": "Plant_Moss_Rug_Green"
    },
    {
      "x": -4,
      "y": 0,
      "z": -3,
      "name": "Rock_Shale"
    },
    {
      "x": -4,
      "y": 1,
      "z": -3,
      "name": "Rock_Shale"
    },
    {
      "x": -4,
      "y": 2,
      "z": -3,
      "name": "Rock_Shale"
    },
    {
      "x": -4,
      "y": 3,
      "z": -3,
      "name": "Rock_Shale"
    },
    {
      "x": -4,
      "y": 4,
      "z": -3,
      "name": "Rock_Shale_Cobble"
    },
    {
      "x": -4,
      "y": 5,
      "z": -3,
      "name": "Rock_Shale_Cobble"
    },
    {
      "x": -4,
      "y": 6,
      "z": -3,
      "name": "Rock_Shale_Cobble"
    },
    {
      "x": -4,
      "y": 7,
      "z": -3,
      "name": "Rock_Shale_Cobble"
    },
    {
      "x": -4,
      "y": 8,
      "z": -3,
      "name": "Rock_Shale_Cobble"
    },
    {
      "x": -4,
      "y": 9,
      "z": -3,
      "name": "Rock_Basalt_Cobble"
    },
    {
      "x": -4,
      "y": 10,
      "z": -3,
      "name": "Rock_Basalt_Cobble"
    },
    {
      "x": -4,
      "y": 11,
      "z": -3,
      "name": "Rock_Basalt_Cobble"
    },
    {
      "x": -4,
      "y": 12,
      "z": -3,
      "name": "Soil_Dirt_Cold"
    },
    {
      "x": -4,
      "y": 13,
      "z": -3,
      "name": "Soil_Grass_Cold"
    },
    {
      "x": -4,
      "y": 14,
      "z": -3,
      "name": "Plant_Moss_Rug_Lime"
    },
    {
      "x": -3,
      "y": 1,
      "z": -7,
      "name": "Rock_Shale"
    },
    {
      "x": -3,
      "y": 2,
      "z": -7,
      "name": "Rock_Shale"
    },
    {
      "x": -3,
      "y": 3,
      "z": -7,
      "name": "Rock_Shale"
    },
    {
      "x": -3,
      "y": 4,
      "z": -7,
      "name": "Rock_Shale_Cobble_Half",
      "rotation": 6
    },
    {
      "x": -3,
      "y": 5,
      "z": -7,
      "name": "Rock_Shale_Cobble"
    },
    {
      "x": -3,
      "y": 6,
      "z": -7,
      "name": "Rock_Shale_Cobble"
    },
    {
      "x": -3,
      "y": 7,
      "z": -7,
      "name": "Rock_Shale_Cobble"
    },
    {
      "x": -3,
      "y": 8,
      "z": -7,
      "name": "Rock_Shale_Brick_Smooth"
    },
    {
      "x": -3,
      "y": 9,
      "z": -7,
      "name": "Rock_Shale_Cobble"
    },
    {
      "x": -3,
      "y": 10,
      "z": -7,
      "name": "Rock_Shale_Cobble"
    },
    {
      "x": -3,
      "y": 11,
      "z": -7,
      "name": "Rock_Shale_Cobble"
    },
    {
      "x": -3,
      "y": 12,
      "z": -7,
      "name": "Rock_Shale_Brick_Smooth"
    },
    {
      "x": -3,
      "y": 13,
      "z": -7,
      "name": "Rock_Shale_Brick_Smooth"
    },
    {
      "x": -3,
      "y": 14,
      "z": -7,
      "name": "Rock_Shale_Brick_Smooth"
    },
    {
      "x": -3,
      "y": 15,
      "z": -7,
      "name": "Rock_Shale_Brick_Smooth"
    },
    {
      "x": -3,
      "y": 16,
      "z": -7,
      "name": "Rock_Shale_Brick_Smooth"
    },
    {
      "x": -3,
      "y": 0,
      "z": -6,
      "name": "Rock_Shale"
    },
    {
      "x": -3,
      "y": 1,
      "z": -6,
      "name": "Rock_Shale"
    },
    {
      "x": -3,
      "y": 2,
      "z": -6,
      "name": "Rock_Shale"
    },
    {
      "x": -3,
      "y": 3,
      "z": -6,
      "name": "Rock_Shale"
    },
    {
      "x": -3,
      "y": 4,
      "z": -6,
      "name": "Rock_Shale"
    },
    {
      "x": -3,
      "y": 5,
      "z": -6,
      "name": "Rock_Shale_Cobble"
    },
    {
      "x": -3,
      "y": 6,
      "z": -6,
      "name": "Rock_Shale_Cobble"
    },
    {
      "x": -3,
      "y": 7,
      "z": -6,
      "name": "Rock_Shale_Cobble"
    },
    {
      "x": -3,
      "y": 8,
      "z": -6,
      "name": "Rock_Shale"
    },
    {
      "x": -3,
      "y": 9,
      "z": -6,
      "name": "Rock_Shale"
    },
    {
      "x": -3,
      "y": 10,
      "z": -6,
      "name": "Rock_Shale"
    },
    {
      "x": -3,
      "y": 11,
      "z": -6,
      "name": "Rock_Shale"
    },
    {
      "x": -3,
      "y": 12,
      "z": -6,
      "name": "Rock_Shale"
    },
    {
      "x": -3,
      "y": 13,
      "z": -6,
      "name": "Rock_Shale"
    },
    {
      "x": -3,
      "y": 14,
      "z": -6,
      "name": "Rock_Shale"
    },
    {
      "x": -3,
      "y": 15,
      "z": -6,
      "name": "Rock_Shale"
    },
    {
      "x": -3,
      "y": 0,
      "z": -5,
      "name": "Rock_Shale"
    },
    {
      "x": -3,
      "y": 1,
      "z": -5,
      "name": "Rock_Shale"
    },
    {
      "x": -3,
      "y": 2,
      "z": -5,
      "name": "Rock_Shale"
    },
    {
      "x": -3,
      "y": 3,
      "z": -5,
      "name": "Rock_Shale"
    },
    {
      "x": -3,
      "y": 4,
      "z": -5,
      "name": "Rock_Shale"
    },
    {
      "x": -3,
      "y": 5,
      "z": -5,
      "name": "Rock_Shale_Cobble"
    },
    {
      "x": -3,
      "y": 6,
      "z": -5,
      "name": "Rock_Shale_Cobble"
    },
    {
      "x": -3,
      "y": 7,
      "z": -5,
      "name": "Rock_Shale_Cobble"
    },
    {
      "x": -3,
      "y": 8,
      "z": -5,
      "name": "Rock_Shale_Brick"
    },
    {
      "x": -3,
      "y": 9,
      "z": -5,
      "name": "Rock_Shale_Brick"
    },
    {
      "x": -3,
      "y": 10,
      "z": -5,
      "name": "Rock_Shale_Brick"
    },
    {
      "x": -3,
      "y": 11,
      "z": -5,
      "name": "Rock_Shale_Brick"
    },
    {
      "x": -3,
      "y": 12,
      "z": -5,
      "name": "Rock_Shale_Brick"
    },
    {
      "x": -3,
      "y": 13,
      "z": -5,
      "name": "Rock_Shale_Brick"
    },
    {
      "x": -3,
      "y": 14,
      "z": -5,
      "name": "Rock_Shale_Brick"
    },
    {
      "x": -3,
      "y": 15,
      "z": -5,
      "name": "Rock_Shale_Brick"
    },
    {
      "x": -3,
      "y": 16,
      "z": -5,
      "name": "Rock_Shale_Brick"
    },
    {
      "x": -3,
      "y": 17,
      "z": -5,
      "name": "Rock_Shale_Brick"
    },
    {
      "x": -3,
      "y": 0,
      "z": -4,
      "name": "Rock_Shale"
    },
    {
      "x": -3,
      "y": 1,
      "z": -4,
      "name": "Rock_Shale"
    },
    {
      "x": -3,
      "y": 2,
      "z": -4,
      "name": "Rock_Shale"
    },
    {
      "x": -3,
      "y": 3,
      "z": -4,
      "name": "Rock_Shale"
    },
    {
      "x": -3,
      "y": 4,
      "z": -4,
      "name": "Rock_Shale_Cobble"
    },
    {
      "x": -3,
      "y": 5,
      "z": -4,
      "name": "Rock_Shale_Cobble"
    },
    {
      "x": -3,
      "y": 6,
      "z": -4,
      "name": "Rock_Shale_Cobble"
    },
    {
      "x": -3,
      "y": 7,
      "z": -4,
      "name": "Rock_Shale_Cobble"
    },
    {
      "x": -3,
      "y": 8,
      "z": -4,
      "name": "Rock_Shale_Cobble"
    },
    {
      "x": -3,
      "y": 9,
      "z": -4,
      "name": "Rock_Shale_Cobble"
    },
    {
      "x": -3,
      "y": 10,
      "z": -4,
      "name": "Rock_Shale_Cobble"
    },
    {
      "x": -3,
      "y": 11,
      "z": -4,
      "name": "Soil_Dirt_Cold"
    },
    {
      "x": -3,
      "y": 12,
      "z": -4,
      "name": "Soil_Dirt_Cold"
    },
    {
      "x": -3,
      "y": 13,
      "z": -4,
      "name": "Soil_Grass_Cold"
    },
    {
      "x": -3,
      "y": 14,
      "z": -4,
      "name": "Plant_Grass_Winter"
    },
    {
      "x": -3,
      "y": 0,
      "z": -3,
      "name": "Rock_Shale"
    },
    {
      "x": -3,
      "y": 1,
      "z": -3,
      "name": "Rock_Shale"
    },
    {
      "x": -3,
      "y": 2,
      "z": -3,
      "name": "Rock_Shale"
    },
    {
      "x": -3,
      "y": 3,
      "z": -3,
      "name": "Rock_Shale"
    },
    {
      "x": -3,
      "y": 4,
      "z": -3,
      "name": "Rock_Shale"
    },
    {
      "x": -3,
      "y": 5,
      "z": -3,
      "name": "Rock_Shale"
    },
    {
      "x": -3,
      "y": 6,
      "z": -3,
      "name": "Rock_Shale"
    },
    {
      "x": -3,
      "y": 7,
      "z": -3,
      "name": "Rock_Shale_Cobble"
    },
    {
      "x": -3,
      "y": 8,
      "z": -3,
      "name": "Rock_Shale_Cobble"
    },
    {
      "x": -3,
      "y": 9,
      "z": -3,
      "name": "Rock_Shale_Cobble"
    },
    {
      "x": -3,
      "y": 10,
      "z": -3,
      "name": "Rock_Basalt_Cobble"
    },
    {
      "x": -3,
      "y": 11,
      "z": -3,
      "name": "Soil_Dirt_Cold"
    },
    {
      "x": -3,
      "y": 12,
      "z": -3,
      "name": "Soil_Dirt_Cold"
    },
    {
      "x": -3,
      "y": 13,
      "z": -3,
      "name": "Soil_Grass_Cold"
    },
    {
      "x": -3,
      "y": 14,
      "z": -3,
      "name": "Plant_Fern_Winter"
    },
    {
      "x": -3,
      "y": 0,
      "z": -2,
      "name": "Rock_Shale"
    },
    {
      "x": -3,
      "y": 1,
      "z": -2,
      "name": "Rock_Shale"
    },
    {
      "x": -3,
      "y": 2,
      "z": -2,
      "name": "Rock_Shale"
    },
    {
      "x": -3,
      "y": 3,
      "z": -2,
      "name": "Rock_Shale"
    },
    {
      "x": -3,
      "y": 4,
      "z": -2,
      "name": "Rock_Shale"
    },
    {
      "x": -3,
      "y": 5,
      "z": -2,
      "name": "Rock_Shale"
    },
    {
      "x": -3,
      "y": 6,
      "z": -2,
      "name": "Rock_Shale"
    },
    {
      "x": -3,
      "y": 7,
      "z": -2,
      "name": "Rock_Shale"
    },
    {
      "x": -3,
      "y": 8,
      "z": -2,
      "name": "Rock_Shale_Cobble"
    },
    {
      "x": -3,
      "y": 9,
      "z": -2,
      "name": "Rock_Basalt_Cobble"
    },
    {
      "x": -3,
      "y": 10,
      "z": -2,
      "name": "Rock_Basalt_Cobble"
    },
    {
      "x": -3,
      "y": 11,
      "z": -2,
      "name": "Rock_Basalt_Cobble"
    },
    {
      "x": -3,
      "y": 12,
      "z": -2,
      "name": "Soil_Dirt_Cold"
    },
    {
      "x": -3,
      "y": 13,
      "z": -2,
      "name": "Soil_Grass_Cold"
    },
    {
      "x": -3,
      "y": 1,
      "z": -1,
      "name": "Rock_Shale"
    },
    {
      "x": -3,
      "y": 2,
      "z": -1,
      "name": "Rock_Shale"
    },
    {
      "x": -3,
      "y": 3,
      "z": -1,
      "name": "Rock_Shale_Cobble"
    },
    {
      "x": -3,
      "y": 4,
      "z": -1,
      "name": "Rock_Shale_Cobble_Half",
      "rotation": 7
    },
    {
      "x": -3,
      "y": 5,
      "z": -1,
      "name": "Rock_Shale_Cobble_Half",
      "rotation": 7
    },
    {
      "x": -3,
      "y": 6,
      "z": -1,
      "name": "Rock_Shale_Cobble_Half",
      "rotation": 7
    },
    {
      "x": -3,
      "y": 7,
      "z": -1,
      "name": "Rock_Shale_Cobble"
    },
    {
      "x": -3,
      "y": 8,
      "z": -1,
      "name": "Rock_Shale_Cobble"
    },
    {
      "x": -3,
      "y": 9,
      "z": -1,
      "name": "Rock_Shale_Cobble"
    },
    {
      "x": -3,
      "y": 10,
      "z": -1,
      "name": "Rock_Shale_Cobble"
    },
    {
      "x": -3,
      "y": 11,
      "z": -1,
      "name": "Rock_Basalt_Cobble"
    },
    {
      "x": -3,
      "y": 12,
      "z": -1,
      "name": "Rock_Basalt_Cobble"
    },
    {
      "x": -3,
      "y": 13,
      "z": -1,
      "name": "Soil_Grass_Cold"
    },
    {
      "x": -3,
      "y": 1,
      "z": 0,
      "name": "Rock_Shale"
    },
    {
      "x": -3,
      "y": 2,
      "z": 0,
      "name": "Rock_Shale"
    },
    {
      "x": -3,
      "y": 3,
      "z": 0,
      "name": "Rock_Shale"
    },
    {
      "x": -3,
      "y": 4,
      "z": 0,
      "name": "Rock_Shale_Cobble"
    },
    {
      "x": -3,
      "y": 5,
      "z": 0,
      "name": "Rock_Shale_Cobble_Half",
      "rotation": 7
    },
    {
      "x": -3,
      "y": 6,
      "z": 0,
      "name": "Rock_Shale_Cobble_Half",
      "rotation": 7
    },
    {
      "x": -3,
      "y": 7,
      "z": 0,
      "name": "Rock_Shale_Cobble_Half",
      "rotation": 7
    },
    {
      "x": -3,
      "y": 8,
      "z": 0,
      "name": "Rock_Shale_Cobble"
    },
    {
      "x": -3,
      "y": 9,
      "z": 0,
      "name": "Rock_Shale_Cobble"
    },
    {
      "x": -3,
      "y": 10,
      "z": 0,
      "name": "Rock_Shale_Cobble"
    },
    {
      "x": -3,
      "y": 11,
      "z": 0,
      "name": "Rock_Shale_Cobble"
    },
    {
      "x": -3,
      "y": 12,
      "z": 0,
      "name": "Rock_Shale_Cobble"
    },
    {
      "x": -3,
      "y": 13,
      "z": 0,
      "name": "Soil_Pathway"
    },
    {
      "x": -3,
      "y": 1,
      "z": 1,
      "name": "Rock_Shale_Cobble"
    },
    {
      "x": -3,
      "y": 2,
      "z": 1,
      "name": "Rock_Shale"
    },
    {
      "x": -3,
      "y": 3,
      "z": 1,
      "name": "Rock_Shale"
    },
    {
      "x": -3,
      "y": 4,
      "z": 1,
      "name": "Rock_Shale"
    },
    {
      "x": -3,
      "y": 5,
      "z": 1,
      "name": "Rock_Shale"
    },
    {
      "x": -3,
      "y": 6,
      "z": 1,
      "name": "Rock_Shale"
    },
    {
      "x": -3,
      "y": 7,
      "z": 1,
      "name": "Rock_Shale_Cobble_Half",
      "rotation": 7
    },
    {
      "x": -3,
      "y": 8,
      "z": 1,
      "name": "Rock_Shale_Cobble_Half",
      "rotation": 7
    },
    {
      "x": -3,
      "y": 9,
      "z": 1,
      "name": "Rock_Shale_Cobble"
    },
    {
      "x": -3,
      "y": 10,
      "z": 1,
      "name": "Rock_Shale_Cobble"
    },
    {
      "x": -3,
      "y": 11,
      "z": 1,
      "name": "Rock_Shale_Cobble"
    },
    {
      "x": -3,
      "y": 12,
      "z": 1,
      "name": "Rock_Shale_Cobble"
    },
    {
      "x": -3,
      "y": 13,
      "z": 1,
      "name": "Soil_Pathway"
    },
    {
      "x": -3,
      "y": 2,
      "z": 2,
      "name": "Rock_Shale"
    },
    {
      "x": -3,
      "y": 3,
      "z": 2,
      "name": "Rock_Shale"
    },
    {
      "x": -3,
      "y": 4,
      "z": 2,
      "name": "Rock_Shale"
    },
    {
      "x": -3,
      "y": 5,
      "z": 2,
      "name": "Rock_Shale"
    },
    {
      "x": -3,
      "y": 6,
      "z": 2,
      "name": "Rock_Shale"
    },
    {
      "x": -3,
      "y": 7,
      "z": 2,
      "name": "Rock_Shale"
    },
    {
      "x": -3,
      "y": 8,
      "z": 2,
      "name": "Rock_Shale_Cobble"
    },
    {
      "x": -3,
      "y": 9,
      "z": 2,
      "name": "Rock_Shale_Cobble"
    },
    {
      "x": -3,
      "y": 10,
      "z": 2,
      "name": "Rock_Shale_Cobble"
    },
    {
      "x": -3,
      "y": 11,
      "z": 2,
      "name": "Rock_Shale_Cobble"
    },
    {
      "x": -3,
      "y": 12,
      "z": 2,
      "name": "Rock_Shale_Cobble"
    },
    {
      "x": -3,
      "y": 2,
      "z": 3,
      "name": "Rock_Shale"
    },
    {
      "x": -3,
      "y": 3,
      "z": 3,
      "name": "Rock_Shale"
    },
    {
      "x": -3,
      "y": 4,
      "z": 3,
      "name": "Rock_Shale"
    },
    {
      "x": -3,
      "y": 5,
      "z": 3,
      "name": "Rock_Shale"
    },
    {
      "x": -3,
      "y": 6,
      "z": 3,
      "name": "Rock_Shale_Cobble"
    },
    {
      "x": -3,
      "y": 7,
      "z": 3,
      "name": "Rock_Shale_Cobble"
    },
    {
      "x": -3,
      "y": 8,
      "z": 3,
      "name": "Rock_Shale_Cobble"
    },
    {
      "x": -3,
      "y": 9,
      "z": 3,
      "name": "Rock_Shale_Cobble"
    },
    {
      "x": -3,
      "y": 10,
      "z": 3,
      "name": "Rock_Shale_Cobble"
    },
    {
      "x": -3,
      "y": 3,
      "z": 4,
      "name": "Rock_Shale"
    },
    {
      "x": -3,
      "y": 4,
      "z": 4,
      "name": "Rock_Shale"
    },
    {
      "x": -3,
      "y": 5,
      "z": 4,
      "name": "Rock_Shale"
    },
    {
      "x": -3,
      "y": 6,
      "z": 4,
      "name": "Rock_Shale_Cobble"
    },
    {
      "x": -3,
      "y": 7,
      "z": 4,
      "name": "Rock_Shale_Cobble"
    },
    {
      "x": -3,
      "y": 8,
      "z": 4,
      "name": "Rock_Shale_Cobble"
    },
    {
      "x": -3,
      "y": 9,
      "z": 4,
      "name": "Rock_Shale_Cobble"
    },
    {
      "x": -2,
      "y": 0,
      "z": -7,
      "name": "Rock_Shale"
    },
    {
      "x": -2,
      "y": 1,
      "z": -7,
      "name": "Rock_Shale"
    },
    {
      "x": -2,
      "y": 2,
      "z": -7,
      "name": "Rock_Shale"
    },
    {
      "x": -2,
      "y": 3,
      "z": -7,
      "name": "Rock_Shale"
    },
    {
      "x": -2,
      "y": 4,
      "z": -7,
      "name": "Rock_Shale_Cobble_Half",
      "rotation": 6
    },
    {
      "x": -2,
      "y": 5,
      "z": -7,
      "name": "Rock_Shale_Cobble"
    },
    {
      "x": -2,
      "y": 6,
      "z": -7,
      "name": "Rock_Shale_Cobble"
    },
    {
      "x": -2,
      "y": 7,
      "z": -7,
      "name": "Rock_Shale_Cobble_Half",
      "rotation": 6
    },
    {
      "x": -2,
      "y": 8,
      "z": -7,
      "name": "Rock_Shale_Cobble_Half",
      "rotation": 6
    },
    {
      "x": -2,
      "y": 9,
      "z": -7,
      "name": "Rock_Shale_Cobble_Half",
      "rotation": 6
    },
    {
      "x": -2,
      "y": 10,
      "z": -7,
      "name": "Rock_Shale_Cobble_Half",
      "rotation": 6
    },
    {
      "x": -2,
      "y": 11,
      "z": -7,
      "name": "Rock_Shale_Brick"
    },
    {
      "x": -2,
      "y": 12,
      "z": -7,
      "name": "Rock_Shale_Brick"
    },
    {
      "x": -2,
      "y": 13,
      "z": -7,
      "name": "Rock_Shale_Brick"
    },
    {
      "x": -2,
      "y": 14,
      "z": -7,
      "name": "Rock_Shale_Brick"
    },
    {
      "x": -2,
      "y": 15,
      "z": -7,
      "name": "Rock_Shale_Brick"
    },
    {
      "x": -2,
      "y": 16,
      "z": -7,
      "name": "Rock_Shale_Brick"
    },
    {
      "x": -2,
      "y": 17,
      "z": -7,
      "name": "Rock_Shale_Brick"
    },
    {
      "x": -2,
      "y": 18,
      "z": -7,
      "name": "Rock_Shale_Brick"
    },
    {
      "x": -2,
      "y": 0,
      "z": -6,
      "name": "Rock_Shale"
    },
    {
      "x": -2,
      "y": 1,
      "z": -6,
      "name": "Rock_Shale"
    },
    {
      "x": -2,
      "y": 2,
      "z": -6,
      "name": "Rock_Shale"
    },
    {
      "x": -2,
      "y": 3,
      "z": -6,
      "name": "Rock_Shale"
    },
    {
      "x": -2,
      "y": 4,
      "z": -6,
      "name": "Rock_Shale"
    },
    {
      "x": -2,
      "y": 5,
      "z": -6,
      "name": "Rock_Shale_Cobble"
    },
    {
      "x": -2,
      "y": 6,
      "z": -6,
      "name": "Rock_Shale_Cobble"
    },
    {
      "x": -2,
      "y": 7,
      "z": -6,
      "name": "Rock_Shale_Cobble"
    },
    {
      "x": -2,
      "y": 8,
      "z": -6,
      "name": "Rock_Shale"
    },
    {
      "x": -2,
      "y": 9,
      "z": -6,
      "name": "Rock_Shale"
    },
    {
      "x": -2,
      "y": 10,
      "z": -6,
      "name": "Rock_Shale"
    },
    {
      "x": -2,
      "y": 11,
      "z": -6,
      "name": "Rock_Shale"
    },
    {
      "x": -2,
      "y": 12,
      "z": -6,
      "name": "Rock_Shale"
    },
    {
      "x": -2,
      "y": 13,
      "z": -6,
      "name": "Rock_Shale"
    },
    {
      "x": -2,
      "y": 14,
      "z": -6,
      "name": "Rock_Shale"
    },
    {
      "x": -2,
      "y": 15,
      "z": -6,
      "name": "Rock_Shale"
    },
    {
      "x": -2,
      "y": 16,
      "z": -6,
      "name": "Rock_Shale"
    },
    {
      "x": -2,
      "y": 0,
      "z": -5,
      "name": "Rock_Shale"
    },
    {
      "x": -2,
      "y": 1,
      "z": -5,
      "name": "Rock_Shale"
    },
    {
      "x": -2,
      "y": 2,
      "z": -5,
      "name": "Rock_Shale"
    },
    {
      "x": -2,
      "y": 3,
      "z": -5,
      "name": "Rock_Shale"
    },
    {
      "x": -2,
      "y": 4,
      "z": -5,
      "name": "Rock_Shale"
    },
    {
      "x": -2,
      "y": 5,
      "z": -5,
      "name": "Rock_Shale_Cobble"
    },
    {
      "x": -2,
      "y": 6,
      "z": -5,
      "name": "Rock_Shale_Cobble"
    },
    {
      "x": -2,
      "y": 7,
      "z": -5,
      "name": "Rock_Shale_Cobble"
    },
    {
      "x": -2,
      "y": 8,
      "z": -5,
      "name": "Rock_Shale_Brick"
    },
    {
      "x": -2,
      "y": 9,
      "z": -5,
      "name": "Rock_Shale_Brick"
    },
    {
      "x": -2,
      "y": 10,
      "z": -5,
      "name": "Rock_Shale_Brick"
    },
    {
      "x": -2,
      "y": 11,
      "z": -5,
      "name": "Rock_Shale_Brick"
    },
    {
      "x": -2,
      "y": 12,
      "z": -5,
      "name": "Rock_Shale_Brick"
    },
    {
      "x": -2,
      "y": 13,
      "z": -5,
      "name": "Rock_Shale_Brick"
    },
    {
      "x": -2,
      "y": 14,
      "z": -5,
      "name": "Rock_Shale_Brick"
    },
    {
      "x": -2,
      "y": 15,
      "z": -5,
      "name": "Rock_Shale_Brick"
    },
    {
      "x": -2,
      "y": 16,
      "z": -5,
      "name": "Rock_Shale_Brick"
    },
    {
      "x": -2,
      "y": 17,
      "z": -5,
      "name": "Soil_Dirt_Cold"
    },
    {
      "x": -2,
      "y": 18,
      "z": -5,
      "name": "Soil_Grass_Cold"
    },
    {
      "x": -2,
      "y": 0,
      "z": -4,
      "name": "Rock_Shale"
    },
    {
      "x": -2,
      "y": 1,
      "z": -4,
      "name": "Rock_Shale"
    },
    {
      "x": -2,
      "y": 2,
      "z": -4,
      "name": "Rock_Shale"
    },
    {
      "x": -2,
      "y": 3,
      "z": -4,
      "name": "Rock_Shale"
    },
    {
      "x": -2,
      "y": 4,
      "z": -4,
      "name": "Rock_Shale_Cobble"
    },
    {
      "x": -2,
      "y": 5,
      "z": -4,
      "name": "Rock_Shale_Cobble"
    },
    {
      "x": -2,
      "y": 6,
      "z": -4,
      "name": "Rock_Shale_Cobble"
    },
    {
      "x": -2,
      "y": 7,
      "z": -4,
      "name": "Rock_Shale_Cobble"
    },
    {
      "x": -2,
      "y": 8,
      "z": -4,
      "name": "Rock_Shale_Cobble"
    },
    {
      "x": -2,
      "y": 9,
      "z": -4,
      "name": "Rock_Shale_Cobble"
    },
    {
      "x": -2,
      "y": 10,
      "z": -4,
      "name": "Rock_Shale_Cobble"
    },
    {
      "x": -2,
      "y": 11,
      "z": -4,
      "name": "Soil_Dirt_Cold"
    },
    {
      "x": -2,
      "y": 12,
      "z": -4,
      "name": "Soil_Dirt_Cold"
    },
    {
      "x": -2,
      "y": 13,
      "z": -4,
      "name": "Soil_Grass_Cold"
    },
    {
      "x": -2,
      "y": 0,
      "z": -3,
      "name": "Rock_Shale"
    },
    {
      "x": -2,
      "y": 1,
      "z": -3,
      "name": "Rock_Shale"
    },
    {
      "x": -2,
      "y": 2,
      "z": -3,
      "name": "Rock_Shale"
    },
    {
      "x": -2,
      "y": 3,
      "z": -3,
      "name": "Rock_Shale_Cobble"
    },
    {
      "x": -2,
      "y": 4,
      "z": -3,
      "name": "Rock_Shale_Cobble"
    },
    {
      "x": -2,
      "y": 5,
      "z": -3,
      "name": "Rock_Shale_Cobble"
    },
    {
      "x": -2,
      "y": 6,
      "z": -3,
      "name": "Rock_Shale_Cobble"
    },
    {
      "x": -2,
      "y": 7,
      "z": -3,
      "name": "Rock_Shale_Cobble"
    },
    {
      "x": -2,
      "y": 8,
      "z": -3,
      "name": "Rock_Shale_Cobble"
    },
    {
      "x": -2,
      "y": 9,
      "z": -3,
      "name": "Rock_Shale_Cobble"
    },
    {
      "x": -2,
      "y": 10,
      "z": -3,
      "name": "Rock_Shale_Cobble"
    },
    {
      "x": -2,
      "y": 11,
      "z": -3,
      "name": "Rock_Shale_Cobble"
    },
    {
      "x": -2,
      "y": 12,
      "z": -3,
      "name": "Soil_Dirt_Cold"
    },
    {
      "x": -2,
      "y": 13,
      "z": -3,
      "name": "Soil_Grass_Cold"
    },
    {
      "x": -2,
      "y": 14,
      "z": -3,
      "name": "Plant_Fern_Winter"
    },
    {
      "x": -2,
      "y": 0,
      "z": -2,
      "name": "Rock_Shale"
    },
    {
      "x": -2,
      "y": 1,
      "z": -2,
      "name": "Rock_Shale"
    },
    {
      "x": -2,
      "y": 2,
      "z": -2,
      "name": "Rock_Shale"
    },
    {
      "x": -2,
      "y": 3,
      "z": -2,
      "name": "Rock_Shale_Cobble"
    },
    {
      "x": -2,
      "y": 4,
      "z": -2,
      "name": "Rock_Shale"
    },
    {
      "x": -2,
      "y": 5,
      "z": -2,
      "name": "Rock_Shale"
    },
    {
      "x": -2,
      "y": 6,
      "z": -2,
      "name": "Rock_Shale"
    },
    {
      "x": -2,
      "y": 7,
      "z": -2,
      "name": "Rock_Shale_Cobble"
    },
    {
      "x": -2,
      "y": 8,
      "z": -2,
      "name": "Rock_Shale_Cobble"
    },
    {
      "x": -2,
      "y": 9,
      "z": -2,
      "name": "Rock_Shale_Cobble"
    },
    {
      "x": -2,
      "y": 10,
      "z": -2,
      "name": "Rock_Basalt_Cobble"
    },
    {
      "x": -2,
      "y": 11,
      "z": -2,
      "name": "Rock_Basalt_Cobble"
    },
    {
      "x": -2,
      "y": 12,
      "z": -2,
      "name": "Rock_Basalt_Cobble"
    },
    {
      "x": -2,
      "y": 13,
      "z": -2,
      "name": "Soil_Grass_Cold"
    },
    {
      "x": -2,
      "y": 0,
      "z": -1,
      "name": "Rock_Shale"
    },
    {
      "x": -2,
      "y": 1,
      "z": -1,
      "name": "Rock_Shale"
    },
    {
      "x": -2,
      "y": 2,
      "z": -1,
      "name": "Rock_Shale"
    },
    {
      "x": -2,
      "y": 3,
      "z": -1,
      "name": "Rock_Shale_Cobble"
    },
    {
      "x": -2,
      "y": 4,
      "z": -1,
      "name": "Rock_Shale_Cobble"
    },
    {
      "x": -2,
      "y": 5,
      "z": -1,
      "name": "Rock_Shale_Cobble"
    },
    {
      "x": -2,
      "y": 6,
      "z": -1,
      "name": "Rock_Shale_Cobble"
    },
    {
      "x": -2,
      "y": 7,
      "z": -1,
      "name": "Rock_Shale_Cobble"
    },
    {
      "x": -2,
      "y": 8,
      "z": -1,
      "name": "Rock_Shale_Cobble"
    },
    {
      "x": -2,
      "y": 9,
      "z": -1,
      "name": "Rock_Shale_Cobble"
    },
    {
      "x": -2,
      "y": 10,
      "z": -1,
      "name": "Rock_Shale_Cobble"
    },
    {
      "x": -2,
      "y": 11,
      "z": -1,
      "name": "Rock_Shale_Cobble"
    },
    {
      "x": -2,
      "y": 12,
      "z": -1,
      "name": "Rock_Shale_Cobble"
    },
    {
      "x": -2,
      "y": 13,
      "z": -1,
      "name": "Soil_Grass_Cold"
    },
    {
      "x": -2,
      "y": 14,
      "z": -1,
      "name": "Plant_Fern_Forest"
    },
    {
      "x": -2,
      "y": 0,
      "z": 0,
      "name": "Rock_Shale_Cobble"
    },
    {
      "x": -2,
      "y": 1,
      "z": 0,
      "name": "Rock_Shale"
    },
    {
      "x": -2,
      "y": 2,
      "z": 0,
      "name": "Rock_Shale"
    },
    {
      "x": -2,
      "y": 3,
      "z": 0,
      "name": "Rock_Shale"
    },
    {
      "x": -2,
      "y": 4,
      "z": 0,
      "name": "Rock_Shale"
    },
    {
      "x": -2,
      "y": 5,
      "z": 0,
      "name": "Rock_Shale_Cobble"
    },
    {
      "x": -2,
      "y": 6,
      "z": 0,
      "name": "Rock_Shale_Cobble"
    },
    {
      "x": -2,
      "y": 7,
      "z": 0,
      "name": "Rock_Shale_Cobble"
    },
    {
      "x": -2,
      "y": 8,
      "z": 0,
      "name": "Rock_Shale_Cobble"
    },
    {
      "x": -2,
      "y": 9,
      "z": 0,
      "name": "Rock_Shale_Cobble"
    },
    {
      "x": -2,
      "y": 10,
      "z": 0,
      "name": "Rock_Shale_Cobble"
    },
    {
      "x": -2,
      "y": 11,
      "z": 0,
      "name": "Rock_Shale_Cobble"
    },
    {
      "x": -2,
      "y": 12,
      "z": 0,
      "name": "Rock_Shale_Cobble"
    },
    {
      "x": -2,
      "y": 13,
      "z": 0,
      "name": "Soil_Pathway"
    },
    {
      "x": -2,
      "y": 18,
      "z": 0,
      "name": "Plant_Moss_Wall_Green",
      "rotation": 3
    },
    {
      "x": -2,
      "y": 1,
      "z": 1,
      "name": "Rock_Shale"
    },
    {
      "x": -2,
      "y": 2,
      "z": 1,
      "name": "Rock_Shale"
    },
    {
      "x": -2,
      "y": 3,
      "z": 1,
      "name": "Rock_Shale"
    },
    {
      "x": -2,
      "y": 4,
      "z": 1,
      "name": "Rock_Shale"
    },
    {
      "x": -2,
      "y": 5,
      "z": 1,
      "name": "Rock_Shale"
    },
    {
      "x": -2,
      "y": 6,
      "z": 1,
      "name": "Rock_Shale"
    },
    {
      "x": -2,
      "y": 7,
      "z": 1,
      "name": "Rock_Shale"
    },
    {
      "x": -2,
      "y": 8,
      "z": 1,
      "name": "Rock_Shale_Cobble"
    },
    {
      "x": -2,
      "y": 9,
      "z": 1,
      "name": "Rock_Shale_Cobble"
    },
    {
      "x": -2,
      "y": 10,
      "z": 1,
      "name": "Rock_Shale_Cobble"
    },
    {
      "x": -2,
      "y": 11,
      "z": 1,
      "name": "Rock_Shale_Cobble"
    },
    {
      "x": -2,
      "y": 12,
      "z": 1,
      "name": "Rock_Shale_Cobble"
    },
    {
      "x": -2,
      "y": 13,
      "z": 1,
      "name": "Rock_Shale_Brick_Smooth"
    },
    {
      "x": -2,
      "y": 1,
      "z": 2,
      "name": "Rock_Shale"
    },
    {
      "x": -2,
      "y": 2,
      "z": 2,
      "name": "Rock_Shale"
    },
    {
      "x": -2,
      "y": 3,
      "z": 2,
      "name": "Rock_Shale"
    },
    {
      "x": -2,
      "y": 4,
      "z": 2,
      "name": "Rock_Shale"
    },
    {
      "x": -2,
      "y": 5,
      "z": 2,
      "name": "Rock_Shale"
    },
    {
      "x": -2,
      "y": 6,
      "z": 2,
      "name": "Rock_Shale_Cobble"
    },
    {
      "x": -2,
      "y": 7,
      "z": 2,
      "name": "Rock_Shale_Cobble"
    },
    {
      "x": -2,
      "y": 8,
      "z": 2,
      "name": "Rock_Shale_Cobble"
    },
    {
      "x": -2,
      "y": 9,
      "z": 2,
      "name": "Rock_Shale_Cobble"
    },
    {
      "x": -2,
      "y": 10,
      "z": 2,
      "name": "Rock_Shale_Cobble"
    },
    {
      "x": -2,
      "y": 11,
      "z": 2,
      "name": "Rock_Shale_Cobble"
    },
    {
      "x": -2,
      "y": 12,
      "z": 2,
      "name": "Rock_Shale_Cobble"
    },
    {
      "x": -2,
      "y": 13,
      "z": 2,
      "name": "Rock_Shale_Brick_Smooth"
    },
    {
      "x": -2,
      "y": 2,
      "z": 3,
      "name": "Rock_Shale"
    },
    {
      "x": -2,
      "y": 3,
      "z": 3,
      "name": "Rock_Shale"
    },
    {
      "x": -2,
      "y": 4,
      "z": 3,
      "name": "Rock_Shale"
    },
    {
      "x": -2,
      "y": 5,
      "z": 3,
      "name": "Rock_Shale"
    },
    {
      "x": -2,
      "y": 6,
      "z": 3,
      "name": "Rock_Shale_Cobble"
    },
    {
      "x": -2,
      "y": 7,
      "z": 3,
      "name": "Rock_Shale_Cobble"
    },
    {
      "x": -2,
      "y": 8,
      "z": 3,
      "name": "Rock_Shale_Cobble"
    },
    {
      "x": -2,
      "y": 9,
      "z": 3,
      "name": "Rock_Shale_Cobble"
    },
    {
      "x": -2,
      "y": 10,
      "z": 3,
      "name": "Rock_Shale_Cobble"
    },
    {
      "x": -2,
      "y": 11,
      "z": 3,
      "name": "Rock_Shale_Cobble"
    },
    {
      "x": -2,
      "y": 12,
      "z": 3,
      "name": "Rock_Shale_Cobble"
    },
    {
      "x": -2,
      "y": 13,
      "z": 3,
      "name": "Rock_Shale_Brick_Smooth"
    },
    {
      "x": -2,
      "y": 2,
      "z": 4,
      "name": "Rock_Shale"
    },
    {
      "x": -2,
      "y": 3,
      "z": 4,
      "name": "Rock_Shale"
    },
    {
      "x": -2,
      "y": 4,
      "z": 4,
      "name": "Rock_Shale"
    },
    {
      "x": -2,
      "y": 5,
      "z": 4,
      "name": "Rock_Shale"
    },
    {
      "x": -2,
      "y": 6,
      "z": 4,
      "name": "Rock_Shale"
    },
    {
      "x": -2,
      "y": 7,
      "z": 4,
      "name": "Rock_Shale"
    },
    {
      "x": -2,
      "y": 8,
      "z": 4,
      "name": "Rock_Shale"
    },
    {
      "x": -2,
      "y": 9,
      "z": 4,
      "name": "Rock_Shale_Cobble"
    },
    {
      "x": -2,
      "y": 10,
      "z": 4,
      "name": "Rock_Shale_Cobble"
    },
    {
      "x": -2,
      "y": 11,
      "z": 4,
      "name": "Rock_Shale_Cobble"
    },
    {
      "x": -2,
      "y": 12,
      "z": 4,
      "name": "Rock_Shale_Cobble"
    },
    {
      "x": -1,
      "y": 18,
      "z": -8,
      "name": "Rock_Shale_Brick"
    },
    {
      "x": -1,
      "y": 0,
      "z": -7,
      "name": "Rock_Shale"
    },
    {
      "x": -1,
      "y": 1,
      "z": -7,
      "name": "Rock_Shale"
    },
    {
      "x": -1,
      "y": 2,
      "z": -7,
      "name": "Rock_Shale"
    },
    {
      "x": -1,
      "y": 3,
      "z": -7,
      "name": "Rock_Shale_Cobble_Half",
      "rotation": 6
    },
    {
      "x": -1,
      "y": 4,
      "z": -7,
      "name": "Rock_Shale_Cobble_Half",
      "rotation": 6
    },
    {
      "x": -1,
      "y": 5,
      "z": -7,
      "name": "Rock_Shale_Cobble"
    },
    {
      "x": -1,
      "y": 6,
      "z": -7,
      "name": "Rock_Shale_Cobble"
    },
    {
      "x": -1,
      "y": 7,
      "z": -7,
      "name": "Rock_Shale_Cobble_Half",
      "rotation": 6
    },
    {
      "x": -1,
      "y": 8,
      "z": -7,
      "name": "Rock_Shale_Cobble_Half",
      "rotation": 6
    },
    {
      "x": -1,
      "y": 9,
      "z": -7,
      "name": "Rock_Shale_Cobble"
    },
    {
      "x": -1,
      "y": 10,
      "z": -7,
      "name": "Rock_Shale_Cobble"
    },
    {
      "x": -1,
      "y": 11,
      "z": -7,
      "name": "Rock_Shale_Brick"
    },
    {
      "x": -1,
      "y": 12,
      "z": -7,
      "name": "Rock_Shale_Brick"
    },
    {
      "x": -1,
      "y": 13,
      "z": -7,
      "name": "Rock_Shale_Brick"
    },
    {
      "x": -1,
      "y": 14,
      "z": -7,
      "name": "Rock_Shale_Brick"
    },
    {
      "x": -1,
      "y": 15,
      "z": -7,
      "name": "Rock_Shale_Brick"
    },
    {
      "x": -1,
      "y": 16,
      "z": -7,
      "name": "Rock_Shale_Brick"
    },
    {
      "x": -1,
      "y": 17,
      "z": -7,
      "name": "Rock_Shale_Brick"
    },
    {
      "x": -1,
      "y": 18,
      "z": -7,
      "name": "Rock_Shale_Brick"
    },
    {
      "x": -1,
      "y": 19,
      "z": -7,
      "name": "Rock_Shale_Brick"
    },
    {
      "x": -1,
      "y": 20,
      "z": -7,
      "name": "Rock_Shale_Brick"
    },
    {
      "x": -1,
      "y": 0,
      "z": -6,
      "name": "Rock_Shale"
    },
    {
      "x": -1,
      "y": 1,
      "z": -6,
      "name": "Rock_Shale"
    },
    {
      "x": -1,
      "y": 2,
      "z": -6,
      "name": "Rock_Shale"
    },
    {
      "x": -1,
      "y": 3,
      "z": -6,
      "name": "Rock_Shale"
    },
    {
      "x": -1,
      "y": 4,
      "z": -6,
      "name": "Rock_Shale"
    },
    {
      "x": -1,
      "y": 5,
      "z": -6,
      "name": "Rock_Shale_Cobble"
    },
    {
      "x": -1,
      "y": 6,
      "z": -6,
      "name": "Rock_Shale_Cobble"
    },
    {
      "x": -1,
      "y": 7,
      "z": -6,
      "name": "Rock_Shale_Cobble"
    },
    {
      "x": -1,
      "y": 8,
      "z": -6,
      "name": "Rock_Shale"
    },
    {
      "x": -1,
      "y": 9,
      "z": -6,
      "name": "Rock_Shale"
    },
    {
      "x": -1,
      "y": 10,
      "z": -6,
      "name": "Rock_Shale"
    },
    {
      "x": -1,
      "y": 11,
      "z": -6,
      "name": "Rock_Shale"
    },
    {
      "x": -1,
      "y": 12,
      "z": -6,
      "name": "Rock_Shale"
    },
    {
      "x": -1,
      "y": 13,
      "z": -6,
      "name": "Rock_Shale"
    },
    {
      "x": -1,
      "y": 14,
      "z": -6,
      "name": "Rock_Shale"
    },
    {
      "x": -1,
      "y": 15,
      "z": -6,
      "name": "Rock_Shale"
    },
    {
      "x": -1,
      "y": 16,
      "z": -6,
      "name": "Rock_Shale"
    },
    {
      "x": -1,
      "y": 17,
      "z": -6,
      "name": "Soil_Dirt_Cold"
    },
    {
      "x": -1,
      "y": 18,
      "z": -6,
      "name": "Soil_Grass_Cold"
    },
    {
      "x": -1,
      "y": 0,
      "z": -5,
      "name": "Rock_Shale"
    },
    {
      "x": -1,
      "y": 1,
      "z": -5,
      "name": "Rock_Shale"
    },
    {
      "x": -1,
      "y": 2,
      "z": -5,
      "name": "Rock_Shale"
    },
    {
      "x": -1,
      "y": 3,
      "z": -5,
      "name": "Rock_Shale"
    },
    {
      "x": -1,
      "y": 4,
      "z": -5,
      "name": "Rock_Shale_Cobble"
    },
    {
      "x": -1,
      "y": 5,
      "z": -5,
      "name": "Rock_Shale_Cobble"
    },
    {
      "x": -1,
      "y": 6,
      "z": -5,
      "name": "Rock_Shale_Cobble"
    },
    {
      "x": -1,
      "y": 7,
      "z": -5,
      "name": "Rock_Shale_Cobble"
    },
    {
      "x": -1,
      "y": 8,
      "z": -5,
      "name": "Rock_Shale_Brick"
    },
    {
      "x": -1,
      "y": 9,
      "z": -5,
      "name": "Rock_Shale_Brick"
    },
    {
      "x": -1,
      "y": 10,
      "z": -5,
      "name": "Rock_Shale_Brick"
    },
    {
      "x": -1,
      "y": 11,
      "z": -5,
      "name": "Rock_Shale_Brick"
    },
    {
      "x": -1,
      "y": 12,
      "z": -5,
      "name": "Rock_Shale_Brick"
    },
    {
      "x": -1,
      "y": 13,
      "z": -5,
      "name": "Rock_Shale_Brick"
    },
    {
      "x": -1,
      "y": 14,
      "z": -5,
      "name": "Rock_Shale_Brick"
    },
    {
      "x": -1,
      "y": 15,
      "z": -5,
      "name": "Rock_Shale_Brick"
    },
    {
      "x": -1,
      "y": 16,
      "z": -5,
      "name": "Rock_Shale_Brick"
    },
    {
      "x": -1,
      "y": 17,
      "z": -5,
      "name": "Rock_Shale_Brick"
    },
    {
      "x": -1,
      "y": 18,
      "z": -5,
      "name": "Soil_Grass_Cold"
    },
    {
      "x": -1,
      "y": 19,
      "z": -5,
      "name": "Plant_Fern_Forest"
    },
    {
      "x": -1,
      "y": 0,
      "z": -4,
      "name": "Rock_Shale"
    },
    {
      "x": -1,
      "y": 1,
      "z": -4,
      "name": "Rock_Shale"
    },
    {
      "x": -1,
      "y": 2,
      "z": -4,
      "name": "Rock_Shale"
    },
    {
      "x": -1,
      "y": 3,
      "z": -4,
      "name": "Rock_Shale"
    },
    {
      "x": -1,
      "y": 4,
      "z": -4,
      "name": "Rock_Shale_Cobble"
    },
    {
      "x": -1,
      "y": 5,
      "z": -4,
      "name": "Rock_Shale_Cobble"
    },
    {
      "x": -1,
      "y": 6,
      "z": -4,
      "name": "Rock_Shale_Cobble"
    },
    {
      "x": -1,
      "y": 7,
      "z": -4,
      "name": "Rock_Shale_Cobble"
    },
    {
      "x": -1,
      "y": 8,
      "z": -4,
      "name": "Rock_Shale_Brick"
    },
    {
      "x": -1,
      "y": 9,
      "z": -4,
      "name": "Rock_Shale_Brick"
    },
    {
      "x": -1,
      "y": 10,
      "z": -4,
      "name": "Rock_Shale_Brick"
    },
    {
      "x": -1,
      "y": 11,
      "z": -4,
      "name": "Rock_Shale_Brick"
    },
    {
      "x": -1,
      "y": 12,
      "z": -4,
      "name": "Rock_Shale_Brick"
    },
    {
      "x": -1,
      "y": 13,
      "z": -4,
      "name": "Rock_Shale_Brick"
    },
    {
      "x": -1,
      "y": 14,
      "z": -4,
      "name": "Rock_Shale_Brick"
    },
    {
      "x": -1,
      "y": 15,
      "z": -4,
      "name": "Rock_Shale_Brick"
    },
    {
      "x": -1,
      "y": 16,
      "z": -4,
      "name": "Rock_Shale_Brick"
    },
    {
      "x": -1,
      "y": 17,
      "z": -4,
      "name": "Soil_Dirt_Cold"
    },
    {
      "x": -1,
      "y": 18,
      "z": -4,
      "name": "Soil_Grass_Cold"
    },
    {
      "x": -1,
      "y": 0,
      "z": -3,
      "name": "Rock_Shale"
    },
    {
      "x": -1,
      "y": 1,
      "z": -3,
      "name": "Rock_Shale"
    },
    {
      "x": -1,
      "y": 2,
      "z": -3,
      "name": "Rock_Shale"
    },
    {
      "x": -1,
      "y": 3,
      "z": -3,
      "name": "Rock_Shale_Cobble"
    },
    {
      "x": -1,
      "y": 4,
      "z": -3,
      "name": "Rock_Shale_Cobble"
    },
    {
      "x": -1,
      "y": 5,
      "z": -3,
      "name": "Rock_Shale_Cobble"
    },
    {
      "x": -1,
      "y": 6,
      "z": -3,
      "name": "Rock_Shale_Cobble"
    },
    {
      "x": -1,
      "y": 7,
      "z": -3,
      "name": "Rock_Shale_Cobble"
    },
    {
      "x": -1,
      "y": 8,
      "z": -3,
      "name": "Rock_Shale_Brick"
    },
    {
      "x": -1,
      "y": 9,
      "z": -3,
      "name": "Rock_Shale_Brick"
    },
    {
      "x": -1,
      "y": 10,
      "z": -3,
      "name": "Rock_Shale_Brick"
    },
    {
      "x": -1,
      "y": 11,
      "z": -3,
      "name": "Rock_Shale_Brick"
    },
    {
      "x": -1,
      "y": 12,
      "z": -3,
      "name": "Rock_Shale_Brick"
    },
    {
      "x": -1,
      "y": 13,
      "z": -3,
      "name": "Rock_Shale_Brick"
    },
    {
      "x": -1,
      "y": 14,
      "z": -3,
      "name": "Rock_Shale_Brick"
    },
    {
      "x": -1,
      "y": 15,
      "z": -3,
      "name": "Rock_Shale_Brick"
    },
    {
      "x": -1,
      "y": 16,
      "z": -3,
      "name": "Rock_Shale_Brick"
    },
    {
      "x": -1,
      "y": 17,
      "z": -3,
      "name": "Soil_Pebbles_Frozen"
    },
    {
      "x": -1,
      "y": 18,
      "z": -3,
      "name": "Soil_Grass_Cold"
    },
    {
      "x": -1,
      "y": 19,
      "z": -3,
      "name": "Plant_Moss_Rug_Lime"
    },
    {
      "x": -1,
      "y": 0,
      "z": -2,
      "name": "Rock_Shale"
    },
    {
      "x": -1,
      "y": 1,
      "z": -2,
      "name": "Rock_Shale"
    },
    {
      "x": -1,
      "y": 2,
      "z": -2,
      "name": "Rock_Shale"
    },
    {
      "x": -1,
      "y": 3,
      "z": -2,
      "name": "Rock_Shale_Cobble"
    },
    {
      "x": -1,
      "y": 4,
      "z": -2,
      "name": "Rock_Shale_Cobble"
    },
    {
      "x": -1,
      "y": 5,
      "z": -2,
      "name": "Rock_Shale_Cobble"
    },
    {
      "x": -1,
      "y": 6,
      "z": -2,
      "name": "Rock_Shale_Cobble"
    },
    {
      "x": -1,
      "y": 7,
      "z": -2,
      "name": "Rock_Shale_Cobble"
    },
    {
      "x": -1,
      "y": 8,
      "z": -2,
      "name": "Rock_Shale_Brick"
    },
    {
      "x": -1,
      "y": 9,
      "z": -2,
      "name": "Rock_Shale_Brick"
    },
    {
      "x": -1,
      "y": 10,
      "z": -2,
      "name": "Rock_Shale_Brick"
    },
    {
      "x": -1,
      "y": 11,
      "z": -2,
      "name": "Rock_Shale_Brick"
    },
    {
      "x": -1,
      "y": 12,
      "z": -2,
      "name": "Rock_Shale_Brick"
    },
    {
      "x": -1,
      "y": 13,
      "z": -2,
      "name": "Soil_Grass_Cold"
    },
    {
      "x": -1,
      "y": 16,
      "z": -2,
      "name": "Soil_Pebbles_Frozen"
    },
    {
      "x": -1,
      "y": 17,
      "z": -2,
      "name": "Soil_Pebbles_Frozen"
    },
    {
      "x": -1,
      "y": 18,
      "z": -2,
      "name": "Soil_Pebbles_Frozen"
    },
    {
      "x": -1,
      "y": 19,
      "z": -2,
      "name": "Plant_Moss_Rug_Lime"
    },
    {
      "x": -1,
      "y": 0,
      "z": -1,
      "name": "Rock_Shale_Cobble"
    },
    {
      "x": -1,
      "y": 1,
      "z": -1,
      "name": "Rock_Shale"
    },
    {
      "x": -1,
      "y": 2,
      "z": -1,
      "name": "Rock_Shale_Cobble"
    },
    {
      "x": -1,
      "y": 3,
      "z": -1,
      "name": "Rock_Shale_Cobble"
    },
    {
      "x": -1,
      "y": 4,
      "z": -1,
      "name": "Rock_Shale_Cobble"
    },
    {
      "x": -1,
      "y": 5,
      "z": -1,
      "name": "Rock_Shale_Cobble"
    },
    {
      "x": -1,
      "y": 6,
      "z": -1,
      "name": "Rock_Shale_Cobble"
    },
    {
      "x": -1,
      "y": 7,
      "z": -1,
      "name": "Rock_Shale_Cobble"
    },
    {
      "x": -1,
      "y": 8,
      "z": -1,
      "name": "Rock_Shale_Brick"
    },
    {
      "x": -1,
      "y": 9,
      "z": -1,
      "name": "Rock_Shale_Brick"
    },
    {
      "x": -1,
      "y": 10,
      "z": -1,
      "name": "Rock_Shale_Brick"
    },
    {
      "x": -1,
      "y": 11,
      "z": -1,
      "name": "Rock_Shale_Brick"
    },
    {
      "x": -1,
      "y": 12,
      "z": -1,
      "name": "Rock_Shale_Brick"
    },
    {
      "x": -1,
      "y": 13,
      "z": -1,
      "name": "Soil_Pathway"
    },
    {
      "x": -1,
      "y": 16,
      "z": -1,
      "name": "Rock_Shale_Brick_Half",
      "rotation": 8
    },
    {
      "x": -1,
      "y": 17,
      "z": -1,
      "name": "Rock_Basalt_Cobble"
    },
    {
      "x": -1,
      "y": 18,
      "z": -1,
      "name": "Rock_Basalt_Cobble"
    },
    {
      "x": -1,
      "y": 19,
      "z": -1,
      "name": "Plant_Moss_Rug_Lime"
    },
    {
      "x": -1,
      "y": 0,
      "z": 0,
      "name": "Rock_Shale"
    },
    {
      "x": -1,
      "y": 1,
      "z": 0,
      "name": "Rock_Shale"
    },
    {
      "x": -1,
      "y": 2,
      "z": 0,
      "name": "Rock_Shale"
    },
    {
      "x": -1,
      "y": 3,
      "z": 0,
      "name": "Rock_Shale"
    },
    {
      "x": -1,
      "y": 4,
      "z": 0,
      "name": "Rock_Shale_Cobble"
    },
    {
      "x": -1,
      "y": 5,
      "z": 0,
      "name": "Rock_Shale_Cobble"
    },
    {
      "x": -1,
      "y": 6,
      "z": 0,
      "name": "Rock_Shale_Cobble"
    },
    {
      "x": -1,
      "y": 7,
      "z": 0,
      "name": "Rock_Shale_Cobble"
    },
    {
      "x": -1,
      "y": 8,
      "z": 0,
      "name": "Rock_Shale_Brick"
    },
    {
      "x": -1,
      "y": 9,
      "z": 0,
      "name": "Rock_Shale_Brick"
    },
    {
      "x": -1,
      "y": 10,
      "z": 0,
      "name": "Rock_Shale_Brick"
    },
    {
      "x": -1,
      "y": 11,
      "z": 0,
      "name": "Rock_Shale_Brick"
    },
    {
      "x": -1,
      "y": 12,
      "z": 0,
      "name": "Rock_Shale_Brick"
    },
    {
      "x": -1,
      "y": 13,
      "z": 0,
      "name": "Rock_Shale_Brick"
    },
    {
      "x": -1,
      "y": 16,
      "z": 0,
      "name": "Rock_Basalt_Cobble"
    },
    {
      "x": -1,
      "y": 17,
      "z": 0,
      "name": "Rock_Basalt_Cobble"
    },
    {
      "x": -1,
      "y": 18,
      "z": 0,
      "name": "Rock_Basalt_Cobble"
    },
    {
      "x": -1,
      "y": 19,
      "z": 0,
      "name": "Plant_Moss_Rug_Green"
    },
    {
      "x": -1,
      "y": 0,
      "z": 1,
      "name": "Rock_Shale"
    },
    {
      "x": -1,
      "y": 1,
      "z": 1,
      "name": "Rock_Shale"
    },
    {
      "x": -1,
      "y": 2,
      "z": 1,
      "name": "Rock_Shale"
    },
    {
      "x": -1,
      "y": 3,
      "z": 1,
      "name": "Rock_Shale"
    },
    {
      "x": -1,
      "y": 4,
      "z": 1,
      "name": "Rock_Shale"
    },
    {
      "x": -1,
      "y": 5,
      "z": 1,
      "name": "Rock_Shale_Cobble"
    },
    {
      "x": -1,
      "y": 6,
      "z": 1,
      "name": "Rock_Shale_Cobble"
    },
    {
      "x": -1,
      "y": 7,
      "z": 1,
      "name": "Rock_Shale_Cobble"
    },
    {
      "x": -1,
      "y": 8,
      "z": 1,
      "name": "Rock_Shale_Brick"
    },
    {
      "x": -1,
      "y": 9,
      "z": 1,
      "name": "Rock_Shale_Brick"
    },
    {
      "x": -1,
      "y": 10,
      "z": 1,
      "name": "Rock_Shale_Brick"
    },
    {
      "x": -1,
      "y": 11,
      "z": 1,
      "name": "Rock_Shale_Brick"
    },
    {
      "x": -1,
      "y": 12,
      "z": 1,
      "name": "Rock_Shale_Brick"
    },
    {
      "x": -1,
      "y": 13,
      "z": 1,
      "name": "Rock_Shale_Brick"
    },
    {
      "x": -1,
      "y": 14,
      "z": 1,
      "name": "Rock_Shale_Brick"
    },
    {
      "x": -1,
      "y": 15,
      "z": 1,
      "name": "Rock_Shale_Brick"
    },
    {
      "x": -1,
      "y": 16,
      "z": 1,
      "name": "Rock_Shale_Brick"
    },
    {
      "x": -1,
      "y": 17,
      "z": 1,
      "name": "Rock_Basalt_Cobble"
    },
    {
      "x": -1,
      "y": 18,
      "z": 1,
      "name": "Rock_Basalt_Cobble"
    },
    {
      "x": -1,
      "y": 19,
      "z": 1,
      "name": "Rubble_Basalt"
    },
    {
      "x": -1,
      "y": 0,
      "z": 2,
      "name": "Rock_Shale"
    },
    {
      "x": -1,
      "y": 1,
      "z": 2,
      "name": "Rock_Shale"
    },
    {
      "x": -1,
      "y": 2,
      "z": 2,
      "name": "Rock_Shale"
    },
    {
      "x": -1,
      "y": 3,
      "z": 2,
      "name": "Rock_Shale"
    },
    {
      "x": -1,
      "y": 4,
      "z": 2,
      "name": "Rock_Shale"
    },
    {
      "x": -1,
      "y": 5,
      "z": 2,
      "name": "Rock_Shale"
    },
    {
      "x": -1,
      "y": 6,
      "z": 2,
      "name": "Rock_Shale_Cobble"
    },
    {
      "x": -1,
      "y": 7,
      "z": 2,
      "name": "Rock_Shale_Cobble"
    },
    {
      "x": -1,
      "y": 8,
      "z": 2,
      "name": "Rock_Shale_Brick"
    },
    {
      "x": -1,
      "y": 9,
      "z": 2,
      "name": "Rock_Shale_Brick"
    },
    {
      "x": -1,
      "y": 10,
      "z": 2,
      "name": "Rock_Shale_Brick"
    },
    {
      "x": -1,
      "y": 11,
      "z": 2,
      "name": "Rock_Shale_Brick"
    },
    {
      "x": -1,
      "y": 12,
      "z": 2,
      "name": "Rock_Shale_Brick"
    },
    {
      "x": -1,
      "y": 13,
      "z": 2,
      "name": "Rock_Shale_Brick"
    },
    {
      "x": -1,
      "y": 14,
      "z": 2,
      "name": "Rock_Shale_Brick"
    },
    {
      "x": -1,
      "y": 15,
      "z": 2,
      "name": "Rock_Shale_Brick"
    },
    {
      "x": -1,
      "y": 16,
      "z": 2,
      "name": "Rock_Shale_Brick"
    },
    {
      "x": -1,
      "y": 17,
      "z": 2,
      "name": "Rock_Shale_Brick"
    },
    {
      "x": -1,
      "y": 18,
      "z": 2,
      "name": "Rock_Shale_Brick"
    },
    {
      "x": -1,
      "y": 1,
      "z": 3,
      "name": "Rock_Shale"
    },
    {
      "x": -1,
      "y": 2,
      "z": 3,
      "name": "Rock_Shale"
    },
    {
      "x": -1,
      "y": 3,
      "z": 3,
      "name": "Rock_Shale"
    },
    {
      "x": -1,
      "y": 4,
      "z": 3,
      "name": "Rock_Shale"
    },
    {
      "x": -1,
      "y": 5,
      "z": 3,
      "name": "Rock_Shale"
    },
    {
      "x": -1,
      "y": 6,
      "z": 3,
      "name": "Rock_Shale"
    },
    {
      "x": -1,
      "y": 7,
      "z": 3,
      "name": "Rock_Shale"
    },
    {
      "x": -1,
      "y": 8,
      "z": 3,
      "name": "Rock_Shale_Brick"
    },
    {
      "x": -1,
      "y": 9,
      "z": 3,
      "name": "Rock_Shale"
    },
    {
      "x": -1,
      "y": 10,
      "z": 3,
      "name": "Rock_Shale"
    },
    {
      "x": -1,
      "y": 11,
      "z": 3,
      "name": "Rock_Shale"
    },
    {
      "x": -1,
      "y": 12,
      "z": 3,
      "name": "Rock_Shale_Brick"
    },
    {
      "x": -1,
      "y": 13,
      "z": 3,
      "name": "Rock_Shale_Brick"
    },
    {
      "x": -1,
      "y": 14,
      "z": 3,
      "name": "Rock_Shale_Brick"
    },
    {
      "x": -1,
      "y": 15,
      "z": 3,
      "name": "Rock_Shale_Brick"
    },
    {
      "x": -1,
      "y": 16,
      "z": 3,
      "name": "Rock_Shale_Brick"
    },
    {
      "x": -1,
      "y": 17,
      "z": 3,
      "name": "Rock_Shale_Brick"
    },
    {
      "x": -1,
      "y": 18,
      "z": 3,
      "name": "Rock_Shale_Brick"
    },
    {
      "x": -1,
      "y": 2,
      "z": 4,
      "name": "Rock_Shale"
    },
    {
      "x": -1,
      "y": 3,
      "z": 4,
      "name": "Rock_Shale"
    },
    {
      "x": -1,
      "y": 4,
      "z": 4,
      "name": "Rock_Shale"
    },
    {
      "x": -1,
      "y": 5,
      "z": 4,
      "name": "Rock_Shale"
    },
    {
      "x": -1,
      "y": 6,
      "z": 4,
      "name": "Rock_Shale"
    },
    {
      "x": -1,
      "y": 7,
      "z": 4,
      "name": "Rock_Shale"
    },
    {
      "x": -1,
      "y": 8,
      "z": 4,
      "name": "Rock_Shale"
    },
    {
      "x": -1,
      "y": 9,
      "z": 4,
      "name": "Rock_Shale_Cobble_Half",
      "rotation": 4
    },
    {
      "x": -1,
      "y": 10,
      "z": 4,
      "name": "Rock_Shale_Cobble_Half",
      "rotation": 4
    },
    {
      "x": -1,
      "y": 11,
      "z": 4,
      "name": "Rock_Shale_Cobble_Half",
      "rotation": 4
    },
    {
      "x": -1,
      "y": 12,
      "z": 4,
      "name": "Rock_Shale_Cobble_Half",
      "rotation": 4
    },
    {
      "x": -1,
      "y": 13,
      "z": 4,
      "name": "Rock_Shale_Brick"
    },
    {
      "x": -1,
      "y": 14,
      "z": 4,
      "name": "Rock_Shale_Brick"
    },
    {
      "x": 0,
      "y": 17,
      "z": -8,
      "name": "Rock_Shale_Brick"
    },
    {
      "x": 0,
      "y": 18,
      "z": -8,
      "name": "Rock_Shale_Brick"
    },
    {
      "x": 0,
      "y": 1,
      "z": -7,
      "name": "Rock_Shale"
    },
    {
      "x": 0,
      "y": 2,
      "z": -7,
      "name": "Rock_Shale_Cobble_Half",
      "rotation": 6
    },
    {
      "x": 0,
      "y": 3,
      "z": -7,
      "name": "Rock_Shale_Cobble_Half",
      "rotation": 6
    },
    {
      "x": 0,
      "y": 4,
      "z": -7,
      "name": "Rock_Shale_Cobble"
    },
    {
      "x": 0,
      "y": 5,
      "z": -7,
      "name": "Rock_Shale_Cobble"
    },
    {
      "x": 0,
      "y": 6,
      "z": -7,
      "name": "Rock_Shale_Cobble"
    },
    {
      "x": 0,
      "y": 7,
      "z": -7,
      "name": "Rock_Shale_Cobble"
    },
    {
      "x": 0,
      "y": 8,
      "z": -7,
      "name": "Rock_Shale_Cobble"
    },
    {
      "x": 0,
      "y": 9,
      "z": -7,
      "name": "Rock_Shale_Cobble"
    },
    {
      "x": 0,
      "y": 10,
      "z": -7,
      "name": "Rock_Shale_Cobble"
    },
    {
      "x": 0,
      "y": 11,
      "z": -7,
      "name": "Rock_Shale_Brick"
    },
    {
      "x": 0,
      "y": 12,
      "z": -7,
      "name": "Rock_Shale_Brick"
    },
    {
      "x": 0,
      "y": 13,
      "z": -7,
      "name": "Rock_Shale_Brick"
    },
    {
      "x": 0,
      "y": 14,
      "z": -7,
      "name": "Rock_Shale_Brick"
    },
    {
      "x": 0,
      "y": 15,
      "z": -7,
      "name": "Rock_Shale_Brick"
    },
    {
      "x": 0,
      "y": 16,
      "z": -7,
      "name": "Rock_Shale_Brick"
    },
    {
      "x": 0,
      "y": 17,
      "z": -7,
      "name": "Rock_Shale_Brick"
    },
    {
      "x": 0,
      "y": 18,
      "z": -7,
      "name": "Rock_Shale_Brick"
    },
    {
      "x": 0,
      "y": 19,
      "z": -7,
      "name": "Rock_Shale_Brick"
    },
    {
      "x": 0,
      "y": 20,
      "z": -7,
      "name": "Rock_Shale_Brick"
    },
    {
      "x": 0,
      "y": 0,
      "z": -6,
      "name": "Rock_Shale"
    },
    {
      "x": 0,
      "y": 1,
      "z": -6,
      "name": "Rock_Shale"
    },
    {
      "x": 0,
      "y": 2,
      "z": -6,
      "name": "Rock_Shale"
    },
    {
      "x": 0,
      "y": 3,
      "z": -6,
      "name": "Rock_Shale"
    },
    {
      "x": 0,
      "y": 4,
      "z": -6,
      "name": "Rock_Shale_Cobble"
    },
    {
      "x": 0,
      "y": 5,
      "z": -6,
      "name": "Rock_Shale_Cobble"
    },
    {
      "x": 0,
      "y": 6,
      "z": -6,
      "name": "Rock_Shale_Cobble"
    },
    {
      "x": 0,
      "y": 7,
      "z": -6,
      "name": "Rock_Shale_Cobble"
    },
    {
      "x": 0,
      "y": 8,
      "z": -6,
      "name": "Rock_Shale"
    },
    {
      "x": 0,
      "y": 9,
      "z": -6,
      "name": "Rock_Shale"
    },
    {
      "x": 0,
      "y": 10,
      "z": -6,
      "name": "Rock_Shale"
    },
    {
      "x": 0,
      "y": 11,
      "z": -6,
      "name": "Rock_Shale"
    },
    {
      "x": 0,
      "y": 12,
      "z": -6,
      "name": "Rock_Shale"
    },
    {
      "x": 0,
      "y": 13,
      "z": -6,
      "name": "Rock_Shale"
    },
    {
      "x": 0,
      "y": 14,
      "z": -6,
      "name": "Rock_Shale"
    },
    {
      "x": 0,
      "y": 15,
      "z": -6,
      "name": "Rock_Shale"
    },
    {
      "x": 0,
      "y": 16,
      "z": -6,
      "name": "Rock_Shale"
    },
    {
      "x": 0,
      "y": 17,
      "z": -6,
      "name": "Soil_Dirt_Cold"
    },
    {
      "x": 0,
      "y": 18,
      "z": -6,
      "name": "Soil_Grass_Cold"
    },
    {
      "x": 0,
      "y": 0,
      "z": -5,
      "name": "Rock_Shale"
    },
    {
      "x": 0,
      "y": 1,
      "z": -5,
      "name": "Rock_Shale"
    },
    {
      "x": 0,
      "y": 2,
      "z": -5,
      "name": "Rock_Shale"
    },
    {
      "x": 0,
      "y": 3,
      "z": -5,
      "name": "Rock_Shale"
    },
    {
      "x": 0,
      "y": 4,
      "z": -5,
      "name": "Rock_Shale_Cobble"
    },
    {
      "x": 0,
      "y": 5,
      "z": -5,
      "name": "Rock_Shale_Cobble"
    },
    {
      "x": 0,
      "y": 6,
      "z": -5,
      "name": "Rock_Shale_Cobble"
    },
    {
      "x": 0,
      "y": 7,
      "z": -5,
      "name": "Rock_Shale_Cobble"
    },
    {
      "x": 0,
      "y": 8,
      "z": -5,
      "name": "Rock_Shale"
    },
    {
      "x": 0,
      "y": 9,
      "z": -5,
      "name": "Rock_Shale"
    },
    {
      "x": 0,
      "y": 10,
      "z": -5,
      "name": "Rock_Shale"
    },
    {
      "x": 0,
      "y": 11,
      "z": -5,
      "name": "Rock_Shale"
    },
    {
      "x": 0,
      "y": 12,
      "z": -5,
      "name": "Rock_Shale"
    },
    {
      "x": 0,
      "y": 13,
      "z": -5,
      "name": "Rock_Shale"
    },
    {
      "x": 0,
      "y": 14,
      "z": -5,
      "name": "Rock_Shale"
    },
    {
      "x": 0,
      "y": 15,
      "z": -5,
      "name": "Rock_Shale"
    },
    {
      "x": 0,
      "y": 16,
      "z": -5,
      "name": "Rock_Shale"
    },
    {
      "x": 0,
      "y": 17,
      "z": -5,
      "name": "Rock_Shale"
    },
    {
      "x": 0,
      "y": 18,
      "z": -5,
      "name": "Soil_Grass_Cold"
    },
    {
      "x": 0,
      "y": 0,
      "z": -4,
      "name": "Rock_Shale"
    },
    {
      "x": 0,
      "y": 1,
      "z": -4,
      "name": "Rock_Shale"
    },
    {
      "x": 0,
      "y": 2,
      "z": -4,
      "name": "Rock_Shale"
    },
    {
      "x": 0,
      "y": 3,
      "z": -4,
      "name": "Rock_Shale"
    },
    {
      "x": 0,
      "y": 4,
      "z": -4,
      "name": "Rock_Shale_Cobble"
    },
    {
      "x": 0,
      "y": 5,
      "z": -4,
      "name": "Rock_Shale_Cobble"
    },
    {
      "x": 0,
      "y": 6,
      "z": -4,
      "name": "Rock_Shale_Cobble"
    },
    {
      "x": 0,
      "y": 7,
      "z": -4,
      "name": "Rock_Shale_Cobble"
    },
    {
      "x": 0,
      "y": 8,
      "z": -4,
      "name": "Rock_Shale"
    },
    {
      "x": 0,
      "y": 9,
      "z": -4,
      "name": "Rock_Shale"
    },
    {
      "x": 0,
      "y": 10,
      "z": -4,
      "name": "Rock_Shale"
    },
    {
      "x": 0,
      "y": 11,
      "z": -4,
      "name": "Rock_Shale"
    },
    {
      "x": 0,
      "y": 12,
      "z": -4,
      "name": "Rock_Shale"
    },
    {
      "x": 0,
      "y": 13,
      "z": -4,
      "name": "Rock_Shale"
    },
    {
      "x": 0,
      "y": 14,
      "z": -4,
      "name": "Rock_Shale"
    },
    {
      "x": 0,
      "y": 15,
      "z": -4,
      "name": "Rock_Shale"
    },
    {
      "x": 0,
      "y": 16,
      "z": -4,
      "name": "Rock_Shale"
    },
    {
      "x": 0,
      "y": 17,
      "z": -4,
      "name": "Rock_Shale"
    },
    {
      "x": 0,
      "y": 18,
      "z": -4,
      "name": "Soil_Grass_Cold"
    },
    {
      "x": 0,
      "y": 19,
      "z": -4,
      "name": "Plant_Fern_Winter"
    },
    {
      "x": 0,
      "y": 0,
      "z": -3,
      "name": "Rock_Shale"
    },
    {
      "x": 0,
      "y": 1,
      "z": -3,
      "name": "Rock_Shale"
    },
    {
      "x": 0,
      "y": 2,
      "z": -3,
      "name": "Rock_Shale"
    },
    {
      "x": 0,
      "y": 3,
      "z": -3,
      "name": "Rock_Shale"
    },
    {
      "x": 0,
      "y": 4,
      "z": -3,
      "name": "Rock_Shale_Cobble"
    },
    {
      "x": 0,
      "y": 5,
      "z": -3,
      "name": "Rock_Shale_Cobble"
    },
    {
      "x": 0,
      "y": 6,
      "z": -3,
      "name": "Rock_Shale_Cobble"
    },
    {
      "x": 0,
      "y": 7,
      "z": -3,
      "name": "Rock_Shale_Cobble"
    },
    {
      "x": 0,
      "y": 8,
      "z": -3,
      "name": "Rock_Shale"
    },
    {
      "x": 0,
      "y": 9,
      "z": -3,
      "name": "Rock_Shale"
    },
    {
      "x": 0,
      "y": 10,
      "z": -3,
      "name": "Rock_Shale"
    },
    {
      "x": 0,
      "y": 11,
      "z": -3,
      "name": "Rock_Shale"
    },
    {
      "x": 0,
      "y": 12,
      "z": -3,
      "name": "Rock_Shale"
    },
    {
      "x": 0,
      "y": 13,
      "z": -3,
      "name": "Rock_Shale"
    },
    {
      "x": 0,
      "y": 14,
      "z": -3,
      "name": "Rock_Shale_Brick"
    },
    {
      "x": 0,
      "y": 15,
      "z": -3,
      "name": "Rock_Shale_Brick"
    },
    {
      "x": 0,
      "y": 16,
      "z": -3,
      "name": "Rock_Shale"
    },
    {
      "x": 0,
      "y": 17,
      "z": -3,
      "name": "Rock_Shale"
    },
    {
      "x": 0,
      "y": 18,
      "z": -3,
      "name": "Soil_Grass_Cold"
    },
    {
      "x": 0,
      "y": 19,
      "z": -3,
      "name": "Plant_Grass_Winter"
    },
    {
      "x": 0,
      "y": 20,
      "z": -3,
      "name": "Wood_Torch_Wall",
      "rotation": 3
    },
    {
      "x": 0,
      "y": 0,
      "z": -2,
      "name": "Rock_Shale"
    },
    {
      "x": 0,
      "y": 1,
      "z": -2,
      "name": "Rock_Shale"
    },
    {
      "x": 0,
      "y": 2,
      "z": -2,
      "name": "Rock_Shale"
    },
    {
      "x": 0,
      "y": 3,
      "z": -2,
      "name": "Rock_Shale_Cobble"
    },
    {
      "x": 0,
      "y": 4,
      "z": -2,
      "name": "Rock_Shale_Cobble"
    },
    {
      "x": 0,
      "y": 5,
      "z": -2,
      "name": "Rock_Shale_Cobble"
    },
    {
      "x": 0,
      "y": 6,
      "z": -2,
      "name": "Rock_Shale_Cobble"
    },
    {
      "x": 0,
      "y": 7,
      "z": -2,
      "name": "Rock_Shale_Cobble"
    },
    {
      "x": 0,
      "y": 8,
      "z": -2,
      "name": "Rock_Shale"
    },
    {
      "x": 0,
      "y": 9,
      "z": -2,
      "name": "Rock_Shale"
    },
    {
      "x": 0,
      "y": 10,
      "z": -2,
      "name": "Rock_Shale"
    },
    {
      "x": 0,
      "y": 11,
      "z": -2,
      "name": "Rock_Shale"
    },
    {
      "x": 0,
      "y": 12,
      "z": -2,
      "name": "Rock_Shale"
    },
    {
      "x": 0,
      "y": 13,
      "z": -2,
      "name": "Soil_Pathway"
    },
    {
      "x": 0,
      "y": 14,
      "z": -2,
      "name": "Block_Spawner_Block",
      "components": {
        "Components": {
          "PlacedByInteraction": {
            "WhoPlacedUuid": {
              "$binary": "5OYreBmdMS+xlzjMlwn5JQ==",
              "$type": "04"
            }
          },
          "BlockSpawner": {
            "BlockSpawnerId": "Zone1_Encounters_Tier1"
          }
        }
      }
    },
    {
      "x": 0,
      "y": 16,
      "z": -2,
      "name": "Rock_Shale_Brick"
    },
    {
      "x": 0,
      "y": 17,
      "z": -2,
      "name": "Rock_Shale"
    },
    {
      "x": 0,
      "y": 18,
      "z": -2,
      "name": "Soil_Grass_Cold"
    },
    {
      "x": 0,
      "y": 19,
      "z": -2,
      "name": "Block_Spawner_Block",
      "components": {
        "Components": {
          "PlacedByInteraction": {
            "WhoPlacedUuid": {
              "$binary": "5OYreBmdMS+xlzjMlwn5JQ==",
              "$type": "04"
            }
          },
          "BlockSpawner": {
            "BlockSpawnerId": "Zone1_Encounters_Tier1"
          }
        }
      },
      "rotation": 3
    },
    {
      "x": 0,
      "y": 0,
      "z": -1,
      "name": "Rock_Shale"
    },
    {
      "x": 0,
      "y": 1,
      "z": -1,
      "name": "Rock_Shale"
    },
    {
      "x": 0,
      "y": 2,
      "z": -1,
      "name": "Rock_Shale"
    },
    {
      "x": 0,
      "y": 3,
      "z": -1,
      "name": "Rock_Shale_Cobble"
    },
    {
      "x": 0,
      "y": 4,
      "z": -1,
      "name": "Rock_Shale_Cobble"
    },
    {
      "x": 0,
      "y": 5,
      "z": -1,
      "name": "Rock_Shale_Cobble"
    },
    {
      "x": 0,
      "y": 6,
      "z": -1,
      "name": "Rock_Shale_Cobble"
    },
    {
      "x": 0,
      "y": 7,
      "z": -1,
      "name": "Rock_Shale_Cobble"
    },
    {
      "x": 0,
      "y": 8,
      "z": -1,
      "name": "Rock_Shale"
    },
    {
      "x": 0,
      "y": 9,
      "z": -1,
      "name": "Rock_Shale"
    },
    {
      "x": 0,
      "y": 10,
      "z": -1,
      "name": "Rock_Shale"
    },
    {
      "x": 0,
      "y": 11,
      "z": -1,
      "name": "Rock_Shale"
    },
    {
      "x": 0,
      "y": 12,
      "z": -1,
      "name": "Rock_Shale"
    },
    {
      "x": 0,
      "y": 13,
      "z": -1,
      "name": "Rock_Shale_Brick"
    },
    {
      "x": 0,
      "y": 16,
      "z": -1,
      "name": "Rock_Shale_Brick_Half",
      "rotation": 8
    },
    {
      "x": 0,
      "y": 17,
      "z": -1,
      "name": "Rock_Shale_Brick"
    },
    {
      "x": 0,
      "y": 18,
      "z": -1,
      "name": "Rock_Basalt_Cobble"
    },
    {
      "x": 0,
      "y": 19,
      "z": -1,
      "name": "Plant_Moss_Rug_Lime"
    },
    {
      "x": 0,
      "y": 0,
      "z": 0,
      "name": "Rock_Shale"
    },
    {
      "x": 0,
      "y": 1,
      "z": 0,
      "name": "Rock_Shale"
    },
    {
      "x": 0,
      "y": 2,
      "z": 0,
      "name": "Rock_Shale"
    },
    {
      "x": 0,
      "y": 3,
      "z": 0,
      "name": "Rock_Shale_Cobble"
    },
    {
      "x": 0,
      "y": 4,
      "z": 0,
      "name": "Rock_Shale_Cobble"
    },
    {
      "x": 0,
      "y": 5,
      "z": 0,
      "name": "Rock_Shale_Cobble"
    },
    {
      "x": 0,
      "y": 6,
      "z": 0,
      "name": "Rock_Shale_Cobble"
    },
    {
      "x": 0,
      "y": 7,
      "z": 0,
      "name": "Rock_Shale_Cobble"
    },
    {
      "x": 0,
      "y": 8,
      "z": 0,
      "name": "Rock_Shale"
    },
    {
      "x": 0,
      "y": 9,
      "z": 0,
      "name": "Rock_Shale"
    },
    {
      "x": 0,
      "y": 10,
      "z": 0,
      "name": "Rock_Shale"
    },
    {
      "x": 0,
      "y": 11,
      "z": 0,
      "name": "Rock_Shale"
    },
    {
      "x": 0,
      "y": 12,
      "z": 0,
      "name": "Rock_Shale"
    },
    {
      "x": 0,
      "y": 13,
      "z": 0,
      "name": "Rock_Shale_Brick"
    },
    {
      "x": 0,
      "y": 16,
      "z": 0,
      "name": "Rock_Shale_Brick"
    },
    {
      "x": 0,
      "y": 17,
      "z": 0,
      "name": "Rock_Basalt_Cobble"
    },
    {
      "x": 0,
      "y": 18,
      "z": 0,
      "name": "Rock_Basalt_Cobble"
    },
    {
      "x": 0,
      "y": 19,
      "z": 0,
      "name": "Plant_Moss_Rug_Lime"
    },
    {
      "x": 0,
      "y": 0,
      "z": 1,
      "name": "Rock_Shale"
    },
    {
      "x": 0,
      "y": 1,
      "z": 1,
      "name": "Rock_Shale"
    },
    {
      "x": 0,
      "y": 2,
      "z": 1,
      "name": "Rock_Shale"
    },
    {
      "x": 0,
      "y": 3,
      "z": 1,
      "name": "Rock_Shale"
    },
    {
      "x": 0,
      "y": 4,
      "z": 1,
      "name": "Rock_Shale"
    },
    {
      "x": 0,
      "y": 5,
      "z": 1,
      "name": "Rock_Shale_Cobble"
    },
    {
      "x": 0,
      "y": 6,
      "z": 1,
      "name": "Rock_Shale_Cobble"
    },
    {
      "x": 0,
      "y": 7,
      "z": 1,
      "name": "Rock_Shale_Cobble"
    },
    {
      "x": 0,
      "y": 8,
      "z": 1,
      "name": "Rock_Shale"
    },
    {
      "x": 0,
      "y": 9,
      "z": 1,
      "name": "Rock_Shale"
    },
    {
      "x": 0,
      "y": 10,
      "z": 1,
      "name": "Rock_Shale"
    },
    {
      "x": 0,
      "y": 11,
      "z": 1,
      "name": "Rock_Shale"
    },
    {
      "x": 0,
      "y": 12,
      "z": 1,
      "name": "Rock_Shale"
    },
    {
      "x": 0,
      "y": 13,
      "z": 1,
      "name": "Rock_Shale"
    },
    {
      "x": 0,
      "y": 14,
      "z": 1,
      "name": "Rock_Shale_Brick"
    },
    {
      "x": 0,
      "y": 15,
      "z": 1,
      "name": "Rock_Shale_Brick"
    },
    {
      "x": 0,
      "y": 16,
      "z": 1,
      "name": "Rock_Shale"
    },
    {
      "x": 0,
      "y": 17,
      "z": 1,
      "name": "Rock_Basalt_Cobble"
    },
    {
      "x": 0,
      "y": 18,
      "z": 1,
      "name": "Rock_Basalt_Cobble"
    },
    {
      "x": 0,
      "y": 19,
      "z": 1,
      "name": "Plant_Moss_Rug_Green"
    },
    {
      "x": 0,
      "y": 0,
      "z": 2,
      "name": "Rock_Shale"
    },
    {
      "x": 0,
      "y": 1,
      "z": 2,
      "name": "Rock_Shale"
    },
    {
      "x": 0,
      "y": 2,
      "z": 2,
      "name": "Rock_Shale"
    },
    {
      "x": 0,
      "y": 3,
      "z": 2,
      "name": "Rock_Shale"
    },
    {
      "x": 0,
      "y": 4,
      "z": 2,
      "name": "Rock_Shale"
    },
    {
      "x": 0,
      "y": 5,
      "z": 2,
      "name": "Rock_Shale_Cobble"
    },
    {
      "x": 0,
      "y": 6,
      "z": 2,
      "name": "Rock_Shale_Cobble"
    },
    {
      "x": 0,
      "y": 7,
      "z": 2,
      "name": "Rock_Shale_Cobble"
    },
    {
      "x": 0,
      "y": 8,
      "z": 2,
      "name": "Rock_Shale"
    },
    {
      "x": 0,
      "y": 9,
      "z": 2,
      "name": "Rock_Shale"
    },
    {
      "x": 0,
      "y": 10,
      "z": 2,
      "name": "Rock_Shale"
    },
    {
      "x": 0,
      "y": 11,
      "z": 2,
      "name": "Rock_Shale"
    },
    {
      "x": 0,
      "y": 12,
      "z": 2,
      "name": "Rock_Shale"
    },
    {
      "x": 0,
      "y": 13,
      "z": 2,
      "name": "Rock_Shale"
    },
    {
      "x": 0,
      "y": 14,
      "z": 2,
      "name": "Rock_Shale"
    },
    {
      "x": 0,
      "y": 15,
      "z": 2,
      "name": "Rock_Shale"
    },
    {
      "x": 0,
      "y": 16,
      "z": 2,
      "name": "Soil_Pebbles_Frozen"
    },
    {
      "x": 0,
      "y": 17,
      "z": 2,
      "name": "Soil_Pebbles_Frozen"
    },
    {
      "x": 0,
      "y": 18,
      "z": 2,
      "name": "Soil_Pebbles_Frozen"
    },
    {
      "x": 0,
      "y": 19,
      "z": 2,
      "name": "Rubble_Basalt"
    },
    {
      "x": 0,
      "y": 0,
      "z": 3,
      "name": "Rock_Shale"
    },
    {
      "x": 0,
      "y": 1,
      "z": 3,
      "name": "Rock_Shale"
    },
    {
      "x": 0,
      "y": 2,
      "z": 3,
      "name": "Rock_Shale"
    },
    {
      "x": 0,
      "y": 3,
      "z": 3,
      "name": "Rock_Shale"
    },
    {
      "x": 0,
      "y": 4,
      "z": 3,
      "name": "Rock_Shale"
    },
    {
      "x": 0,
      "y": 5,
      "z": 3,
      "name": "Rock_Shale"
    },
    {
      "x": 0,
      "y": 6,
      "z": 3,
      "name": "Rock_Shale_Cobble"
    },
    {
      "x": 0,
      "y": 7,
      "z": 3,
      "name": "Rock_Shale_Cobble"
    },
    {
      "x": 0,
      "y": 8,
      "z": 3,
      "name": "Rock_Shale"
    },
    {
      "x": 0,
      "y": 9,
      "z": 3,
      "name": "Rock_Shale"
    },
    {
      "x": 0,
      "y": 10,
      "z": 3,
      "name": "Rock_Shale"
    },
    {
      "x": 0,
      "y": 11,
      "z": 3,
      "name": "Rock_Shale"
    },
    {
      "x": 0,
      "y": 12,
      "z": 3,
      "name": "Rock_Shale"
    },
    {
      "x": 0,
      "y": 13,
      "z": 3,
      "name": "Rock_Shale"
    },
    {
      "x": 0,
      "y": 14,
      "z": 3,
      "name": "Rock_Shale"
    },
    {
      "x": 0,
      "y": 15,
      "z": 3,
      "name": "Rock_Shale"
    },
    {
      "x": 0,
      "y": 16,
      "z": 3,
      "name": "Rock_Shale"
    },
    {
      "x": 0,
      "y": 17,
      "z": 3,
      "name": "Soil_Pebbles_Frozen"
    },
    {
      "x": 0,
      "y": 1,
      "z": 4,
      "name": "Rock_Shale"
    },
    {
      "x": 0,
      "y": 2,
      "z": 4,
      "name": "Rock_Shale"
    },
    {
      "x": 0,
      "y": 3,
      "z": 4,
      "name": "Rock_Shale"
    },
    {
      "x": 0,
      "y": 4,
      "z": 4,
      "name": "Rock_Shale"
    },
    {
      "x": 0,
      "y": 5,
      "z": 4,
      "name": "Rock_Shale"
    },
    {
      "x": 0,
      "y": 6,
      "z": 4,
      "name": "Rock_Shale"
    },
    {
      "x": 0,
      "y": 7,
      "z": 4,
      "name": "Rock_Shale"
    },
    {
      "x": 0,
      "y": 8,
      "z": 4,
      "name": "Rock_Shale_Brick"
    },
    {
      "x": 0,
      "y": 9,
      "z": 4,
      "name": "Rock_Shale"
    },
    {
      "x": 0,
      "y": 10,
      "z": 4,
      "name": "Rock_Shale_Cobble_Half",
      "rotation": 4
    },
    {
      "x": 0,
      "y": 11,
      "z": 4,
      "name": "Rock_Shale_Cobble_Half",
      "rotation": 4
    },
    {
      "x": 0,
      "y": 12,
      "z": 4,
      "name": "Rock_Shale_Brick"
    },
    {
      "x": 0,
      "y": 13,
      "z": 4,
      "name": "Rock_Shale_Brick"
    },
    {
      "x": 0,
      "y": 14,
      "z": 4,
      "name": "Rock_Shale_Brick"
    },
    {
      "x": 0,
      "y": 15,
      "z": 4,
      "name": "Rock_Shale_Brick"
    },
    {
      "x": 0,
      "y": 16,
      "z": 4,
      "name": "Rock_Shale_Brick"
    },
    {
      "x": 1,
      "y": 17,
      "z": -8,
      "name": "Rock_Shale_Brick"
    },
    {
      "x": 1,
      "y": 18,
      "z": -8,
      "name": "Rock_Shale_Brick"
    },
    {
      "x": 1,
      "y": 2,
      "z": -7,
      "name": "Rock_Shale_Cobble_Half",
      "rotation": 6
    },
    {
      "x": 1,
      "y": 3,
      "z": -7,
      "name": "Rock_Shale_Cobble_Half",
      "rotation": 6
    },
    {
      "x": 1,
      "y": 4,
      "z": -7,
      "name": "Rock_Shale_Cobble"
    },
    {
      "x": 1,
      "y": 5,
      "z": -7,
      "name": "Rock_Shale_Cobble"
    },
    {
      "x": 1,
      "y": 6,
      "z": -7,
      "name": "Rock_Shale_Cobble"
    },
    {
      "x": 1,
      "y": 7,
      "z": -7,
      "name": "Rock_Shale_Cobble"
    },
    {
      "x": 1,
      "y": 8,
      "z": -7,
      "name": "Rock_Shale_Cobble"
    },
    {
      "x": 1,
      "y": 9,
      "z": -7,
      "name": "Rock_Shale_Cobble"
    },
    {
      "x": 1,
      "y": 10,
      "z": -7,
      "name": "Rock_Shale_Cobble"
    },
    {
      "x": 1,
      "y": 11,
      "z": -7,
      "name": "Rock_Shale_Cobble"
    },
    {
      "x": 1,
      "y": 12,
      "z": -7,
      "name": "Rock_Shale_Brick_Smooth"
    },
    {
      "x": 1,
      "y": 13,
      "z": -7,
      "name": "Rock_Shale_Brick_Smooth"
    },
    {
      "x": 1,
      "y": 14,
      "z": -7,
      "name": "Rock_Shale_Brick_Smooth"
    },
    {
      "x": 1,
      "y": 15,
      "z": -7,
      "name": "Rock_Shale_Brick_Smooth"
    },
    {
      "x": 1,
      "y": 16,
      "z": -7,
      "name": "Rock_Shale_Brick_Smooth"
    },
    {
      "x": 1,
      "y": 17,
      "z": -7,
      "name": "Rock_Shale_Brick"
    },
    {
      "x": 1,
      "y": 18,
      "z": -7,
      "name": "Rock_Shale_Brick"
    },
    {
      "x": 1,
      "y": 19,
      "z": -7,
      "name": "Rock_Shale_Brick"
    },
    {
      "x": 1,
      "y": 20,
      "z": -7,
      "name": "Rock_Shale_Brick"
    },
    {
      "x": 1,
      "y": 1,
      "z": -6,
      "name": "Rock_Shale"
    },
    {
      "x": 1,
      "y": 2,
      "z": -6,
      "name": "Rock_Shale"
    },
    {
      "x": 1,
      "y": 3,
      "z": -6,
      "name": "Rock_Shale"
    },
    {
      "x": 1,
      "y": 4,
      "z": -6,
      "name": "Rock_Shale_Cobble"
    },
    {
      "x": 1,
      "y": 5,
      "z": -6,
      "name": "Rock_Shale_Cobble"
    },
    {
      "x": 1,
      "y": 6,
      "z": -6,
      "name": "Rock_Shale_Cobble"
    },
    {
      "x": 1,
      "y": 7,
      "z": -6,
      "name": "Rock_Shale_Cobble"
    },
    {
      "x": 1,
      "y": 8,
      "z": -6,
      "name": "Rock_Shale_Brick_Ornate"
    },
    {
      "x": 1,
      "y": 9,
      "z": -6,
      "name": "Rock_Shale_Cobble"
    },
    {
      "x": 1,
      "y": 10,
      "z": -6,
      "name": "Rock_Shale_Cobble"
    },
    {
      "x": 1,
      "y": 11,
      "z": -6,
      "name": "Rock_Shale_Brick"
    },
    {
      "x": 1,
      "y": 12,
      "z": -6,
      "name": "Rock_Shale_Brick"
    },
    {
      "x": 1,
      "y": 13,
      "z": -6,
      "name": "Rock_Shale_Brick"
    },
    {
      "x": 1,
      "y": 14,
      "z": -6,
      "name": "Rock_Shale_Brick"
    },
    {
      "x": 1,
      "y": 15,
      "z": -6,
      "name": "Rock_Shale_Brick"
    },
    {
      "x": 1,
      "y": 16,
      "z": -6,
      "name": "Rock_Shale_Brick"
    },
    {
      "x": 1,
      "y": 17,
      "z": -6,
      "name": "Rock_Shale_Brick"
    },
    {
      "x": 1,
      "y": 18,
      "z": -6,
      "name": "Rock_Shale_Brick"
    },
    {
      "x": 1,
      "y": 19,
      "z": -6,
      "name": "Rock_Shale_Brick"
    },
    {
      "x": 1,
      "y": 20,
      "z": -6,
      "name": "Rock_Shale_Brick"
    },
    {
      "x": 1,
      "y": 1,
      "z": -5,
      "name": "Rock_Shale"
    },
    {
      "x": 1,
      "y": 2,
      "z": -5,
      "name": "Rock_Shale"
    },
    {
      "x": 1,
      "y": 3,
      "z": -5,
      "name": "Rock_Shale"
    },
    {
      "x": 1,
      "y": 4,
      "z": -5,
      "name": "Rock_Shale_Cobble"
    },
    {
      "x": 1,
      "y": 5,
      "z": -5,
      "name": "Rock_Shale_Cobble"
    },
    {
      "x": 1,
      "y": 6,
      "z": -5,
      "name": "Rock_Shale_Cobble"
    },
    {
      "x": 1,
      "y": 7,
      "z": -5,
      "name": "Rock_Shale_Cobble"
    },
    {
      "x": 1,
      "y": 8,
      "z": -5,
      "name": "Rock_Shale_Brick_Ornate"
    },
    {
      "x": 1,
      "y": 9,
      "z": -5,
      "name": "Rock_Shale_Brick_Smooth"
    },
    {
      "x": 1,
      "y": 10,
      "z": -5,
      "name": "Rock_Shale_Brick_Smooth"
    },
    {
      "x": 1,
      "y": 11,
      "z": -5,
      "name": "Rock_Shale_Brick"
    },
    {
      "x": 1,
      "y": 12,
      "z": -5,
      "name": "Rock_Shale_Brick"
    },
    {
      "x": 1,
      "y": 13,
      "z": -5,
      "name": "Rock_Shale_Brick"
    },
    {
      "x": 1,
      "y": 14,
      "z": -5,
      "name": "Rock_Shale_Brick"
    },
    {
      "x": 1,
      "y": 15,
      "z": -5,
      "name": "Rock_Shale_Brick"
    },
    {
      "x": 1,
      "y": 16,
      "z": -5,
      "name": "Rock_Shale_Brick"
    },
    {
      "x": 1,
      "y": 17,
      "z": -5,
      "name": "Rock_Shale_Brick"
    },
    {
      "x": 1,
      "y": 18,
      "z": -5,
      "name": "Rock_Shale_Brick"
    },
    {
      "x": 1,
      "y": 19,
      "z": -5,
      "name": "Rock_Shale_Brick"
    },
    {
      "x": 1,
      "y": 20,
      "z": -5,
      "name": "Rock_Shale_Brick"
    },
    {
      "x": 1,
      "y": 0,
      "z": -4,
      "name": "Rock_Shale"
    },
    {
      "x": 1,
      "y": 1,
      "z": -4,
      "name": "Rock_Shale"
    },
    {
      "x": 1,
      "y": 2,
      "z": -4,
      "name": "Rock_Shale"
    },
    {
      "x": 1,
      "y": 3,
      "z": -4,
      "name": "Rock_Shale"
    },
    {
      "x": 1,
      "y": 4,
      "z": -4,
      "name": "Rock_Shale_Cobble"
    },
    {
      "x": 1,
      "y": 5,
      "z": -4,
      "name": "Rock_Shale_Cobble"
    },
    {
      "x": 1,
      "y": 6,
      "z": -4,
      "name": "Rock_Shale_Cobble"
    },
    {
      "x": 1,
      "y": 7,
      "z": -4,
      "name": "Rock_Shale_Cobble"
    },
    {
      "x": 1,
      "y": 8,
      "z": -4,
      "name": "Rock_Shale_Brick_Ornate"
    },
    {
      "x": 1,
      "y": 9,
      "z": -4,
      "name": "Rock_Shale_Brick_Smooth"
    },
    {
      "x": 1,
      "y": 10,
      "z": -4,
      "name": "Rock_Shale_Brick_Smooth"
    },
    {
      "x": 1,
      "y": 11,
      "z": -4,
      "name": "Rock_Shale_Brick"
    },
    {
      "x": 1,
      "y": 12,
      "z": -4,
      "name": "Rock_Shale_Brick"
    },
    {
      "x": 1,
      "y": 13,
      "z": -4,
      "name": "Rock_Shale_Brick"
    },
    {
      "x": 1,
      "y": 14,
      "z": -4,
      "name": "Rock_Shale_Brick"
    },
    {
      "x": 1,
      "y": 15,
      "z": -4,
      "name": "Rock_Shale_Brick"
    },
    {
      "x": 1,
      "y": 16,
      "z": -4,
      "name": "Rock_Shale_Brick"
    },
    {
      "x": 1,
      "y": 17,
      "z": -4,
      "name": "Rock_Shale_Brick"
    },
    {
      "x": 1,
      "y": 18,
      "z": -4,
      "name": "Rock_Shale_Brick"
    },
    {
      "x": 1,
      "y": 19,
      "z": -4,
      "name": "Rock_Shale_Brick"
    },
    {
      "x": 1,
      "y": 0,
      "z": -3,
      "name": "Rock_Shale"
    },
    {
      "x": 1,
      "y": 1,
      "z": -3,
      "name": "Rock_Shale"
    },
    {
      "x": 1,
      "y": 2,
      "z": -3,
      "name": "Rock_Shale"
    },
    {
      "x": 1,
      "y": 3,
      "z": -3,
      "name": "Rock_Shale"
    },
    {
      "x": 1,
      "y": 4,
      "z": -3,
      "name": "Rock_Shale_Cobble"
    },
    {
      "x": 1,
      "y": 5,
      "z": -3,
      "name": "Rock_Shale_Cobble"
    },
    {
      "x": 1,
      "y": 6,
      "z": -3,
      "name": "Rock_Shale_Cobble"
    },
    {
      "x": 1,
      "y": 7,
      "z": -3,
      "name": "Rock_Shale_Cobble"
    },
    {
      "x": 1,
      "y": 8,
      "z": -3,
      "name": "Rock_Shale_Brick_Smooth"
    },
    {
      "x": 1,
      "y": 9,
      "z": -3,
      "name": "Rock_Shale_Brick_Smooth"
    },
    {
      "x": 1,
      "y": 10,
      "z": -3,
      "name": "Rock_Shale_Brick_Smooth"
    },
    {
      "x": 1,
      "y": 11,
      "z": -3,
      "name": "Rock_Shale_Brick_Smooth"
    },
    {
      "x": 1,
      "y": 12,
      "z": -3,
      "name": "Rock_Shale_Brick_Smooth"
    },
    {
      "x": 1,
      "y": 13,
      "z": -3,
      "name": "Rock_Shale_Brick_Smooth"
    },
    {
      "x": 1,
      "y": 14,
      "z": -3,
      "name": "Rock_Shale_Brick_Smooth"
    },
    {
      "x": 1,
      "y": 15,
      "z": -3,
      "name": "Rock_Shale_Brick_Smooth"
    },
    {
      "x": 1,
      "y": 16,
      "z": -3,
      "name": "Rock_Shale_Brick_Smooth"
    },
    {
      "x": 1,
      "y": 17,
      "z": -3,
      "name": "Rock_Shale_Brick"
    },
    {
      "x": 1,
      "y": 18,
      "z": -3,
      "name": "Rock_Shale_Brick"
    },
    {
      "x": 1,
      "y": 19,
      "z": -3,
      "name": "Rock_Shale_Brick"
    },
    {
      "x": 1,
      "y": 20,
      "z": -3,
      "name": "Rock_Shale_Brick"
    },
    {
      "x": 1,
      "y": 0,
      "z": -2,
      "name": "Rock_Shale"
    },
    {
      "x": 1,
      "y": 1,
      "z": -2,
      "name": "Rock_Shale"
    },
    {
      "x": 1,
      "y": 2,
      "z": -2,
      "name": "Rock_Shale"
    },
    {
      "x": 1,
      "y": 3,
      "z": -2,
      "name": "Rock_Shale"
    },
    {
      "x": 1,
      "y": 4,
      "z": -2,
      "name": "Rock_Shale_Cobble"
    },
    {
      "x": 1,
      "y": 5,
      "z": -2,
      "name": "Rock_Shale_Cobble"
    },
    {
      "x": 1,
      "y": 6,
      "z": -2,
      "name": "Rock_Shale_Cobble"
    },
    {
      "x": 1,
      "y": 7,
      "z": -2,
      "name": "Rock_Shale_Cobble"
    },
    {
      "x": 1,
      "y": 8,
      "z": -2,
      "name": "Rock_Shale_Brick_Ornate"
    },
    {
      "x": 1,
      "y": 9,
      "z": -2,
      "name": "Rock_Shale_Cobble"
    },
    {
      "x": 1,
      "y": 10,
      "z": -2,
      "name": "Rock_Shale_Cobble"
    },
    {
      "x": 1,
      "y": 11,
      "z": -2,
      "name": "Rock_Shale_Brick"
    },
    {
      "x": 1,
      "y": 12,
      "z": -2,
      "name": "Rock_Shale_Brick"
    },
    {
      "x": 1,
      "y": 13,
      "z": -2,
      "name": "Rock_Shale_Brick_Half"
    },
    {
      "x": 1,
      "y": 15,
      "z": -2,
      "name": "Wood_Torch_Wall"
    },
    {
      "x": 1,
      "y": 16,
      "z": -2,
      "name": "Rock_Shale_Brick"
    },
    {
      "x": 1,
      "y": 17,
      "z": -2,
      "name": "Rock_Shale_Brick"
    },
    {
      "x": 1,
      "y": 18,
      "z": -2,
      "name": "Rock_Shale_Brick"
    },
    {
      "x": 1,
      "y": 19,
      "z": -2,
      "name": "Rock_Shale_Brick"
    },
    {
      "x": 1,
      "y": 20,
      "z": -2,
      "name": "Rock_Shale_Brick"
    },
    {
      "x": 1,
      "y": 0,
      "z": -1,
      "name": "Rock_Shale"
    },
    {
      "x": 1,
      "y": 1,
      "z": -1,
      "name": "Rock_Shale"
    },
    {
      "x": 1,
      "y": 2,
      "z": -1,
      "name": "Rock_Shale"
    },
    {
      "x": 1,
      "y": 3,
      "z": -1,
      "name": "Rock_Shale_Cobble"
    },
    {
      "x": 1,
      "y": 4,
      "z": -1,
      "name": "Rock_Shale_Cobble"
    },
    {
      "x": 1,
      "y": 5,
      "z": -1,
      "name": "Rock_Shale_Cobble"
    },
    {
      "x": 1,
      "y": 6,
      "z": -1,
      "name": "Rock_Shale_Cobble"
    },
    {
      "x": 1,
      "y": 7,
      "z": -1,
      "name": "Rock_Shale_Cobble"
    },
    {
      "x": 1,
      "y": 8,
      "z": -1,
      "name": "Rock_Shale_Brick_Ornate"
    },
