{
  "version": 8,
  "blockIdVersion": 8,
  "anchorX": 11,
  "anchorY": 5,
  "anchorZ": 17,
  "blocks": [
    {
      "x": -4,
      "y": 45,
      "z": 13,
      "name": "Wood_Dry_Trunk",
      "support": 15,
      "rotation": 4
    },
    {
      "x": -4,
      "y": 46,
      "z": 13,
      "name": "Rock_Sandstone_Brick"
    },
    {
      "x": -4,
      "y": 47,
      "z": 13,
      "name": "Rock_Sandstone_Brick"
    },
    {
      "x": -4,
      "y": 48,
      "z": 13,
      "name": "Rock_Sandstone_Brick"
    },
    {
      "x": -4,
      "y": 49,
      "z": 13,
      "name": "Rock_Sandstone_Brick"
    },
    {
      "x": -4,
      "y": 50,
      "z": 13,
      "name": "Rock_Sandstone_Brick"
    },
    {
      "x": -4,
      "y": 45,
      "z": 14,
      "name": "Wood_Dry_Trunk",
      "support": 15,
      "rotation": 4
    },
    {
      "x": -4,
      "y": 46,
      "z": 14,
      "name": "Rock_Sandstone_Brick"
    },
    {
      "x": -4,
      "y": 47,
      "z": 14,
      "name": "Rock_Sandstone_Brick"
    },
    {
      "x": -4,
      "y": 48,
      "z": 14,
      "name": "Rock_Sandstone_Brick"
    },
    {
      "x": -4,
      "y": 49,
      "z": 14,
      "name": "Rock_Sandstone_Brick"
    },
    {
      "x": -4,
      "y": 50,
      "z": 14,
      "name": "Rock_Sandstone_Brick"
    },
    {
      "x": -4,
      "y": 51,
      "z": 14,
      "name": "Rock_Sandstone_Brick"
    },
    {
      "x": -4,
      "y": 45,
      "z": 15,
      "name": "Wood_Dry_Trunk",
      "support": 15,
      "rotation": 4
    },
    {
      "x": -4,
      "y": 46,
      "z": 15,
      "name": "Rock_Sandstone_Brick"
    },
    {
      "x": -4,
      "y": 47,
      "z": 15,
      "name": "Rock_Sandstone_Brick"
    },
    {
      "x": -4,
      "y": 48,
      "z": 15,
      "name": "Rock_Sandstone_Brick"
    },
    {
      "x": -4,
      "y": 49,
      "z": 15,
      "name": "Rock_Sandstone_Brick"
    },
    {
      "x": -4,
      "y": 50,
      "z": 15,
      "name": "Rock_Sandstone_Brick"
    },
    {
      "x": -4,
      "y": 45,
      "z": 16,
      "name": "Wood_Dry_Trunk",
      "support": 15,
      "rotation": 4
    },
    {
      "x": -4,
      "y": 46,
      "z": 16,
      "name": "Rock_Sandstone_Brick"
    },
    {
      "x": -4,
      "y": 47,
      "z": 16,
      "name": "Rock_Sandstone_Brick"
    },
    {
      "x": -4,
      "y": 48,
      "z": 16,
      "name": "Rock_Sandstone_Brick"
    },
    {
      "x": -4,
      "y": 49,
      "z": 16,
      "name": "Rock_Sandstone_Brick"
    },
    {
      "x": -4,
      "y": 45,
      "z": 17,
      "name": "Wood_Dry_Trunk",
      "support": 15,
      "rotation": 4
    },
    {
      "x": -4,
      "y": 46,
      "z": 17,
      "name": "Rock_Sandstone_Brick"
    },
    {
      "x": -4,
      "y": 47,
      "z": 17,
      "name": "Rock_Sandstone_Brick"
    },
    {
      "x": -4,
      "y": 48,
      "z": 17,
      "name": "Rock_Sandstone_Brick"
    },
    {
      "x": -4,
      "y": 49,
      "z": 17,
      "name": "Rock_Sandstone_Brick"
    },
    {
      "x": -3,
      "y": 45,
      "z": 12,
      "name": "Wood_Dry_Trunk",
      "support": 15,
      "rotation": 4
    },
    {
      "x": -3,
      "y": 46,
      "z": 12,
      "name": "Wood_Drywood_Planks"
    },
    {
      "x": -3,
      "y": 47,
      "z": 12,
      "name": "Rock_Sandstone_Brick"
    },
    {
      "x": -3,
      "y": 48,
      "z": 12,
      "name": "Rock_Sandstone_Brick"
    },
    {
      "x": -3,
      "y": 49,
      "z": 12,
      "name": "Rock_Sandstone_Brick"
    },
    {
      "x": -3,
      "y": 50,
      "z": 12,
      "name": "Rock_Sandstone_Brick"
    },
    {
      "x": -3,
      "y": 45,
      "z": 13,
      "name": "Wood_Dry_Trunk",
      "support": 15,
      "rotation": 4
    },
    {
      "x": -3,
      "y": 46,
      "z": 13,
      "name": "Wood_Drywood_Planks"
    },
    {
      "x": -3,
      "y": 47,
      "z": 13,
      "name": "Furniture_Crude_Platform"
    },
    {
      "x": -3,
      "y": 48,
      "z": 13,
      "name": "Furniture_Crude_Platform"
    },
    {
      "x": -3,
      "y": 49,
      "z": 13,
      "name": "Furniture_Crude_Platform"
    },
    {
      "x": -3,
      "y": 50,
      "z": 13,
      "name": "Furniture_Crude_Platform"
    },
    {
      "x": -3,
      "y": 45,
      "z": 14,
      "name": "Wood_Dry_Trunk",
      "support": 15,
      "rotation": 4
    },
    {
      "x": -3,
      "y": 46,
      "z": 14,
      "name": "Wood_Drywood_Planks"
    },
    {
      "x": -3,
      "y": 47,
      "z": 14,
      "name": "Furniture_Crude_Platform",
      "rotation": 1
    },
    {
      "x": -3,
      "y": 48,
      "z": 14,
      "name": "Furniture_Crude_Platform",
      "rotation": 1
    },
    {
      "x": -3,
      "y": 49,
      "z": 14,
      "name": "Furniture_Crude_Platform",
      "rotation": 1
    },
    {
      "x": -3,
      "y": 50,
      "z": 14,
      "name": "Empty"
    },
    {
      "x": -3,
      "y": 45,
      "z": 15,
      "name": "Wood_Dry_Trunk",
      "support": 15,
      "rotation": 4
    },
    {
      "x": -3,
      "y": 46,
      "z": 15,
      "name": "Wood_Drywood_Planks"
    },
    {
      "x": -3,
      "y": 47,
      "z": 15,
      "name": "Empty"
    },
    {
      "x": -3,
      "y": 48,
      "z": 15,
      "name": "Empty"
    },
    {
      "x": -3,
      "y": 49,
      "z": 15,
      "name": "Empty"
    },
    {
      "x": -3,
      "y": 50,
      "z": 15,
      "name": "Empty"
    },
    {
      "x": -3,
      "y": 45,
      "z": 16,
      "name": "Wood_Dry_Trunk",
      "support": 15,
      "rotation": 4
    },
    {
      "x": -3,
      "y": 46,
      "z": 16,
      "name": "Wood_Drywood_Planks"
    },
    {
      "x": -3,
      "y": 47,
      "z": 16,
      "name": "Empty"
    },
    {
      "x": -3,
      "y": 48,
      "z": 16,
      "name": "Empty"
    },
    {
      "x": -3,
      "y": 49,
      "z": 16,
      "name": "Empty"
    },
    {
      "x": -3,
      "y": 45,
      "z": 17,
      "name": "Wood_Dry_Trunk",
      "support": 15,
      "rotation": 4
    },
    {
      "x": -3,
      "y": 46,
      "z": 17,
      "name": "Wood_Drywood_Planks"
    },
    {
      "x": -3,
      "y": 47,
      "z": 17,
      "name": "Rock_Sandstone_Brick"
    },
    {
      "x": -3,
      "y": 48,
      "z": 17,
      "name": "Empty"
    },
    {
      "x": -3,
      "y": 49,
      "z": 17,
      "name": "Empty"
    },
    {
      "x": -3,
      "y": 45,
      "z": 18,
      "name": "Wood_Dry_Trunk",
      "support": 15,
      "rotation": 4
    },
    {
      "x": -3,
      "y": 46,
      "z": 18,
      "name": "Wood_Drywood_Planks"
    },
    {
      "x": -3,
      "y": 47,
      "z": 18,
      "name": "Rock_Sandstone_Brick"
    },
    {
      "x": -3,
      "y": 48,
      "z": 18,
      "name": "Rock_Sandstone_Brick"
    },
    {
      "x": -3,
      "y": 49,
      "z": 18,
      "name": "Rock_Sandstone_Brick"
    },
    {
      "x": -3,
      "y": 45,
      "z": 19,
      "name": "Wood_Dry_Trunk",
      "support": 15,
      "rotation": 4
    },
    {
      "x": -3,
      "y": 46,
      "z": 19,
      "name": "Wood_Drywood_Planks"
    },
    {
      "x": -3,
      "y": 47,
      "z": 19,
      "name": "Rock_Sandstone_Brick"
    },
    {
      "x": -3,
      "y": 48,
      "z": 19,
      "name": "Rock_Sandstone_Brick"
    },
    {
      "x": -3,
      "y": 45,
      "z": 20,
      "name": "Wood_Dry_Trunk",
      "support": 15,
      "rotation": 4
    },
    {
      "x": -3,
      "y": 46,
      "z": 20,
      "name": "Wood_Drywood_Planks"
    },
    {
      "x": -2,
      "y": 45,
      "z": 12,
      "name": "Wood_Dry_Trunk",
      "support": 15,
      "rotation": 4
    },
    {
      "x": -2,
      "y": 46,
      "z": 12,
      "name": "Wood_Drywood_Planks"
    },
    {
      "x": -2,
      "y": 47,
      "z": 12,
      "name": "Rock_Sandstone_Brick"
    },
    {
      "x": -2,
      "y": 48,
      "z": 12,
      "name": "Rock_Sandstone_Brick"
    },
    {
      "x": -2,
      "y": 45,
      "z": 13,
      "name": "Wood_Dry_Trunk",
      "support": 15,
      "rotation": 4
    },
    {
      "x": -2,
      "y": 46,
      "z": 13,
      "name": "Wood_Drywood_Planks"
    },
    {
      "x": -2,
      "y": 47,
      "z": 13,
      "name": "Furniture_Crude_Platform"
    },
    {
      "x": -2,
      "y": 48,
      "z": 13,
      "name": "Furniture_Crude_Platform"
    },
    {
      "x": -2,
      "y": 49,
      "z": 13,
      "name": "Empty"
    },
    {
      "x": -2,
      "y": 45,
      "z": 14,
      "name": "Wood_Dry_Trunk",
      "support": 15,
      "rotation": 4
    },
    {
      "x": -2,
      "y": 46,
      "z": 14,
      "name": "Wood_Drywood_Planks"
    },
    {
      "x": -2,
      "y": 47,
      "z": 14,
      "name": "Furniture_Crude_Table"
    },
    {
      "x": -2,
      "y": 48,
      "z": 14,
      "name": "Furniture_Crude_Candle"
    },
    {
      "x": -2,
      "y": 49,
      "z": 14,
      "name": "Empty"
    },
    {
      "x": -2,
      "y": 50,
      "z": 14,
      "name": "Empty"
    },
    {
      "x": -2,
      "y": 45,
      "z": 15,
      "name": "Wood_Dry_Trunk",
      "support": 15,
      "rotation": 4
    },
    {
      "x": -2,
      "y": 46,
      "z": 15,
      "name": "Wood_Drywood_Planks"
    },
    {
      "x": -2,
      "y": 47,
      "z": 15,
      "name": "Furniture_Crude_Table",
      "filler": 32
    },
    {
      "x": -2,
      "y": 48,
      "z": 15,
      "name": "Empty"
    },
    {
      "x": -2,
      "y": 49,
      "z": 15,
      "name": "Empty"
    },
    {
      "x": -2,
      "y": 50,
      "z": 15,
      "name": "Empty"
    },
    {
      "x": -2,
      "y": 45,
      "z": 16,
      "name": "Wood_Dry_Trunk",
      "support": 15,
      "rotation": 4
    },
    {
      "x": -2,
      "y": 46,
      "z": 16,
      "name": "Wood_Drywood_Planks"
    },
    {
      "x": -2,
      "y": 47,
      "z": 16,
      "name": "Furniture_Crude_Stool"
    },
    {
      "x": -2,
      "y": 48,
      "z": 16,
      "name": "Empty"
    },
    {
      "x": -2,
      "y": 49,
      "z": 16,
      "name": "Empty"
    },
    {
      "x": -2,
      "y": 50,
      "z": 16,
      "name": "Empty"
    },
    {
      "x": -2,
      "y": 45,
      "z": 17,
      "name": "Wood_Dry_Trunk",
      "support": 15,
      "rotation": 4
    },
    {
      "x": -2,
      "y": 46,
      "z": 17,
      "name": "Wood_Drywood_Planks"
    },
    {
      "x": -2,
      "y": 47,
      "z": 17,
      "name": "Furniture_Ancient_Barrel"
    },
    {
      "x": -2,
      "y": 48,
      "z": 17,
      "name": "Empty"
    },
    {
      "x": -2,
      "y": 49,
      "z": 17,
      "name": "Empty"
    },
    {
      "x": -2,
      "y": 45,
      "z": 18,
      "name": "Wood_Dry_Trunk",
      "support": 15,
      "rotation": 4
    },
    {
      "x": -2,
      "y": 46,
      "z": 18,
      "name": "Wood_Drywood_Planks"
    },
    {
      "x": -2,
      "y": 47,
      "z": 18,
      "name": "Furniture_Ancient_Barrel"
    },
    {
      "x": -2,
      "y": 48,
      "z": 18,
      "name": "Furniture_Ancient_Barrel"
    },
    {
      "x": -2,
      "y": 49,
      "z": 18,
      "name": "Empty"
    },
    {
      "x": -2,
      "y": 45,
      "z": 19,
      "name": "Wood_Dry_Trunk",
      "support": 15,
      "rotation": 4
    },
    {
      "x": -2,
      "y": 46,
      "z": 19,
      "name": "Wood_Drywood_Planks"
    },
    {
      "x": -2,
      "y": 47,
      "z": 19,
      "name": "Block_Spawner_Block",
      "components": {
        "Components": {
          "BlockSpawner": {
            "BlockSpawnerId": "Zone2_Encounters_Tier2"
          }
        }
      },
      "rotation": 2
    },
    {
      "x": -2,
      "y": 48,
      "z": 19,
      "name": "Empty"
    },
    {
      "x": -2,
      "y": 49,
      "z": 19,
      "name": "Empty"
    },
    {
      "x": -2,
      "y": 45,
      "z": 20,
      "name": "Wood_Dry_Trunk",
      "support": 15,
      "rotation": 4
    },
    {
      "x": -2,
      "y": 46,
      "z": 20,
      "name": "Wood_Drywood_Planks"
    },
    {
      "x": -1,
      "y": 45,
      "z": 12,
      "name": "Wood_Dry_Trunk",
      "support": 15,
      "rotation": 4
    },
    {
      "x": -1,
      "y": 46,
      "z": 12,
      "name": "Wood_Drywood_Planks"
    },
    {
      "x": -1,
      "y": 47,
      "z": 12,
      "name": "Empty"
    },
    {
      "x": -1,
      "y": 48,
      "z": 12,
      "name": "Empty"
    },
    {
      "x": -1,
      "y": 49,
      "z": 12,
      "name": "Empty"
    },
    {
      "x": -1,
      "y": 45,
      "z": 13,
      "name": "Wood_Dry_Trunk",
      "support": 15,
      "rotation": 4
    },
    {
      "x": -1,
      "y": 46,
      "z": 13,
      "name": "Wood_Drywood_Planks"
    },
    {
      "x": -1,
      "y": 47,
      "z": 13,
      "name": "Empty"
    },
    {
      "x": -1,
      "y": 48,
      "z": 13,
      "name": "Empty"
    },
    {
      "x": -1,
      "y": 49,
      "z": 13,
      "name": "Empty"
    },
    {
      "x": -1,
      "y": 45,
      "z": 14,
      "name": "Wood_Dry_Trunk",
      "support": 15,
      "rotation": 4
    },
    {
      "x": -1,
      "y": 46,
      "z": 14,
      "name": "Wood_Drywood_Planks"
    },
    {
      "x": -1,
      "y": 47,
      "z": 14,
      "name": "Furniture_Crude_Table",
      "filler": 1
    },
    {
      "x": -1,
      "y": 48,
      "z": 14,
      "name": "Empty"
    },
    {
      "x": -1,
      "y": 49,
      "z": 14,
      "name": "Empty"
    },
    {
      "x": -1,
      "y": 50,
      "z": 14,
      "name": "Empty"
    },
    {
      "x": -1,
      "y": 45,
      "z": 15,
      "name": "Wood_Dry_Trunk",
      "support": 15,
      "rotation": 4
    },
    {
      "x": -1,
      "y": 46,
      "z": 15,
      "name": "Wood_Drywood_Planks"
    },
    {
      "x": -1,
      "y": 47,
      "z": 15,
      "name": "Furniture_Crude_Table",
      "filler": 33
    },
    {
      "x": -1,
      "y": 48,
      "z": 15,
      "name": "Empty"
    },
    {
      "x": -1,
      "y": 49,
      "z": 15,
      "name": "Empty"
    },
    {
      "x": -1,
      "y": 50,
      "z": 15,
      "name": "Empty"
    },
    {
      "x": -1,
      "y": 45,
      "z": 16,
      "name": "Wood_Dry_Trunk",
      "support": 15,
      "rotation": 4
    },
    {
      "x": -1,
      "y": 46,
      "z": 16,
      "name": "Wood_Drywood_Planks"
    },
    {
      "x": -1,
      "y": 47,
      "z": 16,
      "name": "Empty"
    },
    {
      "x": -1,
      "y": 48,
      "z": 16,
      "name": "Empty"
    },
    {
      "x": -1,
      "y": 49,
      "z": 16,
      "name": "Empty"
    },
    {
      "x": -1,
      "y": 50,
      "z": 16,
      "name": "Empty"
    },
    {
      "x": -1,
      "y": 45,
      "z": 17,
      "name": "Wood_Dry_Trunk",
      "support": 15,
      "rotation": 4
    },
    {
      "x": -1,
      "y": 46,
      "z": 17,
      "name": "Wood_Drywood_Planks"
    },
    {
      "x": -1,
      "y": 47,
      "z": 17,
      "name": "Empty"
    },
    {
      "x": -1,
      "y": 48,
      "z": 17,
      "name": "Empty"
    },
    {
      "x": -1,
      "y": 49,
      "z": 17,
      "name": "Empty"
    },
    {
      "x": -1,
      "y": 45,
      "z": 18,
      "name": "Wood_Dry_Trunk",
      "support": 15,
      "rotation": 4
    },
    {
      "x": -1,
      "y": 46,
      "z": 18,
      "name": "Wood_Drywood_Planks"
    },
    {
      "x": -1,
      "y": 47,
      "z": 18,
      "name": "Furniture_Ancient_Barrel"
    },
    {
      "x": -1,
      "y": 48,
      "z": 18,
      "name": "Empty"
    },
    {
      "x": -1,
      "y": 49,
      "z": 18,
      "name": "Empty"
    },
    {
      "x": -1,
      "y": 45,
      "z": 19,
      "name": "Wood_Dry_Trunk",
      "support": 15,
      "rotation": 4
    },
    {
      "x": -1,
      "y": 46,
      "z": 19,
      "name": "Wood_Drywood_Planks"
    },
    {
      "x": -1,
      "y": 47,
      "z": 19,
      "name": "Empty"
    },
    {
      "x": -1,
      "y": 48,
      "z": 19,
      "name": "Empty"
    },
    {
      "x": -1,
      "y": 49,
      "z": 19,
      "name": "Empty"
    },
    {
      "x": -1,
      "y": 45,
      "z": 20,
      "name": "Wood_Dry_Trunk",
      "support": 15,
      "rotation": 4
    },
    {
      "x": -1,
      "y": 46,
      "z": 20,
      "name": "Wood_Drywood_Planks"
    },
    {
      "x": -1,
      "y": 47,
      "z": 20,
      "name": "Empty"
    },
    {
      "x": -1,
      "y": 48,
      "z": 20,
      "name": "Empty"
    },
    {
      "x": -1,
      "y": 49,
      "z": 20,
      "name": "Empty"
    },
    {
      "x": -1,
      "y": 50,
      "z": 20,
      "name": "Empty"
    },
    {
      "x": 0,
      "y": 45,
      "z": 11,
      "name": "Wood_Dry_Trunk",
      "support": 15,
      "rotation": 4
    },
    {
      "x": 0,
      "y": 46,
      "z": 11,
      "name": "Wood_Drywood_Planks"
    },
    {
      "x": 0,
      "y": 48,
      "z": 11,
      "name": "Empty"
    },
    {
      "x": 0,
      "y": 49,
      "z": 11,
      "name": "Empty"
    },
    {
      "x": 0,
      "y": 45,
      "z": 12,
      "name": "Wood_Dry_Trunk",
      "support": 15,
      "rotation": 4
    },
    {
      "x": 0,
      "y": 46,
      "z": 12,
      "name": "Wood_Drywood_Planks"
    },
    {
      "x": 0,
      "y": 47,
      "z": 12,
      "name": "Empty"
    },
    {
      "x": 0,
      "y": 48,
      "z": 12,
      "name": "Empty"
    },
    {
      "x": 0,
      "y": 49,
      "z": 12,
      "name": "Empty"
    },
    {
      "x": 0,
      "y": 45,
      "z": 13,
      "name": "Wood_Dry_Trunk",
      "support": 15,
      "rotation": 4
    },
    {
      "x": 0,
      "y": 46,
      "z": 13,
      "name": "Wood_Drywood_Planks"
    },
    {
      "x": 0,
      "y": 47,
      "z": 13,
      "name": "Empty"
    },
    {
      "x": 0,
      "y": 48,
      "z": 13,
      "name": "Empty"
    },
    {
      "x": 0,
      "y": 49,
      "z": 13,
      "name": "Empty"
    },
    {
      "x": 0,
      "y": 45,
      "z": 14,
      "name": "Wood_Dry_Trunk",
      "support": 15,
      "rotation": 4
    },
    {
      "x": 0,
      "y": 46,
      "z": 14,
      "name": "Wood_Drywood_Planks"
    },
    {
      "x": 0,
      "y": 47,
      "z": 14,
      "name": "Empty"
    },
    {
      "x": 0,
      "y": 48,
      "z": 14,
      "name": "Empty"
    },
    {
      "x": 0,
      "y": 49,
      "z": 14,
      "name": "Empty"
    },
    {
      "x": 0,
      "y": 50,
      "z": 14,
      "name": "Empty"
    },
    {
      "x": 0,
      "y": 45,
      "z": 15,
      "name": "Wood_Dry_Trunk",
      "support": 15,
      "rotation": 4
    },
    {
      "x": 0,
      "y": 46,
      "z": 15,
      "name": "Wood_Drywood_Planks"
    },
    {
      "x": 0,
      "y": 47,
      "z": 15,
      "name": "Furniture_Crude_Stool"
    },
    {
      "x": 0,
      "y": 48,
      "z": 15,
      "name": "Empty"
    },
    {
      "x": 0,
      "y": 49,
      "z": 15,
      "name": "Empty"
    },
    {
      "x": 0,
      "y": 50,
      "z": 15,
      "name": "Empty"
    },
    {
      "x": 0,
      "y": 45,
      "z": 16,
      "name": "Wood_Dry_Trunk",
      "support": 15,
      "rotation": 4
    },
    {
      "x": 0,
      "y": 46,
      "z": 16,
      "name": "Wood_Drywood_Planks"
    },
    {
      "x": 0,
      "y": 47,
      "z": 16,
      "name": "Empty"
    },
    {
      "x": 0,
      "y": 48,
      "z": 16,
      "name": "Empty"
    },
    {
      "x": 0,
      "y": 49,
      "z": 16,
      "name": "Empty"
    },
    {
      "x": 0,
      "y": 50,
      "z": 16,
      "name": "Empty"
    },
    {
      "x": 0,
      "y": 45,
      "z": 17,
      "name": "Wood_Dry_Trunk",
      "support": 15,
      "rotation": 4
    },
    {
      "x": 0,
      "y": 46,
      "z": 17,
      "name": "Wood_Drywood_Planks"
    },
    {
      "x": 0,
      "y": 47,
      "z": 17,
      "name": "Empty"
    },
    {
      "x": 0,
      "y": 48,
      "z": 17,
      "name": "Empty"
    },
    {
      "x": 0,
      "y": 49,
      "z": 17,
      "name": "Empty"
    },
    {
      "x": 0,
      "y": 45,
      "z": 18,
      "name": "Wood_Dry_Trunk",
      "support": 15,
      "rotation": 4
    },
    {
      "x": 0,
      "y": 46,
      "z": 18,
      "name": "Wood_Drywood_Planks"
    },
    {
      "x": 0,
      "y": 47,
      "z": 18,
      "name": "Empty"
    },
    {
      "x": 0,
      "y": 48,
      "z": 18,
      "name": "Empty"
    },
    {
      "x": 0,
      "y": 49,
      "z": 18,
      "name": "Empty"
    },
    {
      "x": 0,
      "y": 45,
      "z": 19,
      "name": "Wood_Dry_Trunk",
      "support": 15,
      "rotation": 4
    },
    {
      "x": 0,
      "y": 46,
      "z": 19,
      "name": "Wood_Drywood_Planks"
    },
    {
      "x": 0,
      "y": 47,
      "z": 19,
      "name": "Empty"
    },
    {
      "x": 0,
      "y": 48,
      "z": 19,
      "name": "Empty"
    },
    {
      "x": 0,
      "y": 49,
      "z": 19,
      "name": "Empty"
    },
    {
      "x": 0,
      "y": 50,
      "z": 19,
      "name": "Empty"
    },
    {
      "x": 0,
      "y": 45,
      "z": 20,
      "name": "Wood_Dry_Trunk",
      "support": 15,
      "rotation": 4
    },
    {
      "x": 0,
      "y": 46,
      "z": 20,
      "name": "Wood_Drywood_Planks"
    },
    {
      "x": 0,
      "y": 47,
      "z": 20,
      "name": "Empty"
    },
    {
      "x": 0,
      "y": 48,
      "z": 20,
      "name": "Empty"
    },
    {
      "x": 0,
      "y": 49,
      "z": 20,
      "name": "Empty"
    },
    {
      "x": 0,
      "y": 50,
      "z": 20,
      "name": "Empty"
    },
    {
      "x": 0,
      "y": 46,
      "z": 21,
      "name": "Wood_Drywood_Planks"
    },
    {
      "x": 1,
      "y": 45,
      "z": 11,
      "name": "Wood_Dry_Trunk",
      "support": 15,
      "rotation": 4
    },
    {
      "x": 1,
      "y": 46,
      "z": 11,
      "name": "Wood_Drywood_Planks"
    },
    {
      "x": 1,
      "y": 49,
      "z": 11,
      "name": "Empty"
    },
    {
      "x": 1,
      "y": 45,
      "z": 12,
      "name": "Wood_Dry_Trunk",
      "support": 15,
      "rotation": 4
    },
    {
      "x": 1,
      "y": 46,
      "z": 12,
      "name": "Wood_Drywood_Planks"
    },
    {
      "x": 1,
      "y": 47,
      "z": 12,
      "name": "Furniture_Ancient_Barrel"
    },
    {
      "x": 1,
      "y": 48,
      "z": 12,
      "name": "Empty"
    },
    {
      "x": 1,
      "y": 49,
      "z": 12,
      "name": "Empty"
    },
    {
      "x": 1,
      "y": 45,
      "z": 13,
      "name": "Wood_Dry_Trunk",
      "support": 15,
      "rotation": 4
    },
    {
      "x": 1,
      "y": 46,
      "z": 13,
      "name": "Wood_Drywood_Planks"
    },
    {
      "x": 1,
      "y": 47,
      "z": 13,
      "name": "Furniture_Ancient_Barrel"
    },
    {
      "x": 1,
      "y": 48,
      "z": 13,
      "name": "Furniture_Ancient_Barrel"
    },
    {
      "x": 1,
      "y": 49,
      "z": 13,
      "name": "Empty"
    },
    {
      "x": 1,
      "y": 45,
      "z": 14,
      "name": "Wood_Dry_Trunk",
      "support": 15,
      "rotation": 4
    },
    {
      "x": 1,
      "y": 46,
      "z": 14,
      "name": "Wood_Drywood_Planks"
    },
    {
      "x": 1,
      "y": 47,
      "z": 14,
      "name": "Empty"
    },
    {
      "x": 1,
      "y": 48,
      "z": 14,
      "name": "Empty"
    },
    {
      "x": 1,
      "y": 49,
      "z": 14,
      "name": "Empty"
    },
    {
      "x": 1,
      "y": 50,
      "z": 14,
      "name": "Empty"
    },
    {
      "x": 1,
      "y": 45,
      "z": 15,
      "name": "Wood_Dry_Trunk",
      "support": 15,
      "rotation": 4
    },
    {
      "x": 1,
      "y": 46,
      "z": 15,
      "name": "Wood_Drywood_Planks"
    },
    {
      "x": 1,
      "y": 47,
      "z": 15,
      "name": "Empty"
    },
    {
      "x": 1,
      "y": 48,
      "z": 15,
      "name": "Empty"
    },
    {
      "x": 1,
      "y": 49,
      "z": 15,
      "name": "Empty"
    },
    {
      "x": 1,
      "y": 50,
      "z": 15,
      "name": "Empty"
    },
    {
      "x": 1,
      "y": 45,
      "z": 16,
      "name": "Wood_Dry_Trunk",
      "support": 15,
      "rotation": 4
    },
    {
      "x": 1,
      "y": 46,
      "z": 16,
      "name": "Wood_Drywood_Planks"
    },
    {
      "x": 1,
      "y": 47,
      "z": 16,
      "name": "Empty"
    },
    {
      "x": 1,
      "y": 48,
      "z": 16,
      "name": "Empty"
    },
    {
      "x": 1,
      "y": 49,
      "z": 16,
      "name": "Empty"
    },
    {
      "x": 1,
      "y": 50,
      "z": 16,
      "name": "Empty"
    },
    {
      "x": 1,
      "y": 45,
      "z": 17,
      "name": "Wood_Dry_Trunk",
      "support": 15,
      "rotation": 4
    },
    {
      "x": 1,
      "y": 46,
      "z": 17,
      "name": "Wood_Drywood_Planks"
    },
    {
      "x": 1,
      "y": 47,
      "z": 17,
      "name": "Empty"
    },
    {
      "x": 1,
      "y": 48,
      "z": 17,
      "name": "Empty"
    },
    {
      "x": 1,
      "y": 49,
      "z": 17,
      "name": "Empty"
    },
    {
      "x": 1,
      "y": 50,
      "z": 17,
      "name": "Empty"
    },
    {
      "x": 1,
      "y": 45,
      "z": 18,
      "name": "Wood_Dry_Trunk",
      "support": 15,
      "rotation": 4
    },
    {
      "x": 1,
      "y": 46,
      "z": 18,
      "name": "Wood_Drywood_Planks"
    },
    {
      "x": 1,
      "y": 47,
      "z": 18,
      "name": "Empty"
    },
    {
      "x": 1,
      "y": 48,
      "z": 18,
      "name": "Empty"
    },
    {
      "x": 1,
      "y": 49,
      "z": 18,
      "name": "Empty"
    },
    {
      "x": 1,
      "y": 50,
      "z": 18,
      "name": "Empty"
    },
    {
      "x": 1,
      "y": 45,
      "z": 19,
      "name": "Wood_Dry_Trunk",
      "support": 15,
      "rotation": 4
    },
    {
      "x": 1,
      "y": 46,
      "z": 19,
      "name": "Wood_Drywood_Planks"
    },
    {
      "x": 1,
      "y": 47,
      "z": 19,
      "name": "Empty"
    },
    {
      "x": 1,
      "y": 48,
      "z": 19,
      "name": "Empty"
    },
    {
      "x": 1,
      "y": 49,
      "z": 19,
      "name": "Empty"
    },
    {
      "x": 1,
      "y": 50,
      "z": 19,
      "name": "Empty"
    },
    {
      "x": 1,
      "y": 45,
      "z": 20,
      "name": "Wood_Dry_Trunk",
      "support": 15,
      "rotation": 4
    },
    {
      "x": 1,
      "y": 46,
      "z": 20,
      "name": "Wood_Drywood_Planks"
    },
    {
      "x": 1,
      "y": 47,
      "z": 20,
      "name": "Empty"
    },
    {
      "x": 1,
      "y": 48,
      "z": 20,
      "name": "Empty"
    },
    {
      "x": 1,
      "y": 49,
      "z": 20,
      "name": "Empty"
    },
    {
      "x": 1,
      "y": 50,
      "z": 20,
      "name": "Empty"
    },
    {
      "x": 2,
      "y": 45,
      "z": 11,
      "name": "Wood_Dry_Trunk",
      "support": 15,
      "rotation": 4
    },
    {
      "x": 2,
      "y": 46,
      "z": 11,
      "name": "Wood_Drywood_Planks"
    },
    {
      "x": 2,
      "y": 45,
      "z": 12,
      "name": "Wood_Dry_Trunk",
      "support": 15,
      "rotation": 4
    },
    {
      "x": 2,
      "y": 46,
      "z": 12,
      "name": "Wood_Drywood_Planks"
    },
    {
      "x": 2,
      "y": 47,
      "z": 12,
      "name": "Furniture_Ancient_Barrel"
    },
    {
      "x": 2,
      "y": 48,
      "z": 12,
      "name": "Furniture_Ancient_Barrel"
    },
    {
      "x": 2,
      "y": 49,
      "z": 12,
      "name": "Furniture_Ancient_Barrel"
    },
    {
      "x": 2,
      "y": 45,
      "z": 13,
      "name": "Wood_Dry_Trunk",
      "support": 15,
      "rotation": 4
    },
    {
      "x": 2,
      "y": 46,
      "z": 13,
      "name": "Wood_Drywood_Planks"
    },
    {
      "x": 2,
      "y": 47,
      "z": 13,
      "name": "Furniture_Ancient_Barrel"
    },
    {
      "x": 2,
      "y": 48,
      "z": 13,
      "name": "Empty"
    },
    {
      "x": 2,
      "y": 49,
      "z": 13,
      "name": "Empty"
    },
    {
      "x": 2,
      "y": 45,
      "z": 14,
      "name": "Wood_Dry_Trunk",
      "support": 15,
      "rotation": 4
    },
    {
      "x": 2,
      "y": 46,
      "z": 14,
      "name": "Wood_Drywood_Planks"
    },
    {
      "x": 2,
      "y": 47,
      "z": 14,
      "name": "Empty"
    },
    {
      "x": 2,
      "y": 48,
      "z": 14,
      "name": "Empty"
    },
    {
      "x": 2,
      "y": 49,
      "z": 14,
      "name": "Empty"
    },
    {
      "x": 2,
      "y": 45,
      "z": 15,
      "name": "Wood_Dry_Trunk",
      "support": 15,
      "rotation": 4
    },
    {
      "x": 2,
      "y": 46,
      "z": 15,
      "name": "Wood_Drywood_Planks"
    },
    {
      "x": 2,
      "y": 47,
      "z": 15,
      "name": "Empty"
    },
    {
      "x": 2,
      "y": 48,
      "z": 15,
      "name": "Empty"
    },
    {
      "x": 2,
      "y": 49,
      "z": 15,
      "name": "Empty"
    },
    {
      "x": 2,
      "y": 45,
      "z": 16,
      "name": "Wood_Dry_Trunk",
      "support": 15,
      "rotation": 4
    },
    {
      "x": 2,
      "y": 46,
      "z": 16,
      "name": "Wood_Drywood_Planks"
    },
    {
      "x": 2,
      "y": 47,
      "z": 16,
      "name": "Empty"
    },
    {
      "x": 2,
      "y": 48,
      "z": 16,
      "name": "Empty"
    },
    {
      "x": 2,
      "y": 49,
      "z": 16,
      "name": "Empty"
    },
    {
      "x": 2,
      "y": 50,
      "z": 16,
      "name": "Empty"
    },
    {
      "x": 2,
      "y": 45,
      "z": 17,
      "name": "Wood_Dry_Trunk",
      "support": 15,
      "rotation": 4
    },
    {
      "x": 2,
      "y": 46,
      "z": 17,
      "name": "Wood_Drywood_Planks"
    },
    {
      "x": 2,
      "y": 47,
      "z": 17,
      "name": "Empty"
    },
    {
      "x": 2,
      "y": 48,
      "z": 17,
      "name": "Empty"
    },
    {
      "x": 2,
      "y": 49,
      "z": 17,
      "name": "Empty"
    },
    {
      "x": 2,
      "y": 50,
      "z": 17,
      "name": "Empty"
    },
    {
      "x": 2,
      "y": 45,
      "z": 18,
      "name": "Wood_Dry_Trunk",
      "support": 15,
      "rotation": 4
    },
    {
      "x": 2,
      "y": 46,
      "z": 18,
      "name": "Wood_Drywood_Planks"
    },
    {
      "x": 2,
      "y": 47,
      "z": 18,
      "name": "Empty"
    },
    {
      "x": 2,
      "y": 48,
      "z": 18,
      "name": "Empty"
    },
    {
      "x": 2,
      "y": 49,
      "z": 18,
      "name": "Empty"
    },
    {
      "x": 2,
      "y": 50,
      "z": 18,
      "name": "Empty"
    },
    {
      "x": 2,
      "y": 45,
      "z": 19,
      "name": "Wood_Dry_Trunk",
      "support": 15,
      "rotation": 4
    },
    {
      "x": 2,
      "y": 46,
      "z": 19,
      "name": "Wood_Drywood_Planks"
    },
    {
      "x": 2,
      "y": 47,
      "z": 19,
      "name": "Empty"
    },
    {
      "x": 2,
      "y": 48,
      "z": 19,
      "name": "Empty"
    },
    {
      "x": 2,
      "y": 49,
      "z": 19,
      "name": "Empty"
    },
    {
      "x": 2,
      "y": 50,
      "z": 19,
      "name": "Empty"
    },
    {
      "x": 2,
      "y": 45,
      "z": 20,
      "name": "Wood_Dry_Trunk",
      "support": 15,
      "rotation": 4
    },
    {
      "x": 2,
      "y": 46,
      "z": 20,
      "name": "Wood_Drywood_Planks"
    },
    {
      "x": 2,
      "y": 47,
      "z": 20,
      "name": "Empty"
    },
    {
      "x": 2,
      "y": 48,
      "z": 20,
      "name": "Empty"
    },
    {
      "x": 2,
      "y": 49,
      "z": 20,
      "name": "Empty"
    },
    {
      "x": 2,
      "y": 50,
      "z": 20,
      "name": "Empty"
    },
    {
      "x": 3,
      "y": 45,
      "z": 12,
      "name": "Wood_Dry_Trunk",
      "support": 15,
      "rotation": 4
    },
    {
      "x": 3,
      "y": 46,
      "z": 12,
      "name": "Wood_Drywood_Planks"
    },
    {
      "x": 3,
      "y": 47,
      "z": 12,
      "name": "Rock_Sandstone_Brick"
    },
    {
      "x": 3,
      "y": 45,
      "z": 13,
      "name": "Wood_Dry_Trunk",
      "support": 15,
      "rotation": 4
    },
    {
      "x": 3,
      "y": 46,
      "z": 13,
      "name": "Wood_Drywood_Planks"
    },
    {
      "x": 3,
      "y": 47,
      "z": 13,
      "name": "Furniture_Crude_Stool"
    },
    {
      "x": 3,
      "y": 48,
      "z": 13,
      "name": "Empty"
    },
    {
      "x": 3,
      "y": 49,
      "z": 13,
      "name": "Empty"
    },
    {
      "x": 3,
      "y": 45,
      "z": 14,
      "name": "Wood_Dry_Trunk",
      "support": 15,
      "rotation": 4
    },
    {
      "x": 3,
      "y": 46,
      "z": 14,
      "name": "Wood_Drywood_Planks"
    },
    {
      "x": 3,
      "y": 47,
      "z": 14,
      "name": "Empty"
    },
    {
      "x": 3,
      "y": 48,
      "z": 14,
      "name": "Empty"
    },
    {
      "x": 3,
      "y": 49,
      "z": 14,
      "name": "Empty"
    },
    {
      "x": 3,
      "y": 45,
      "z": 15,
      "name": "Wood_Dry_Trunk",
      "support": 15,
      "rotation": 4
    },
    {
      "x": 3,
      "y": 46,
      "z": 15,
      "name": "Wood_Drywood_Planks"
    },
    {
      "x": 3,
      "y": 47,
      "z": 15,
      "name": "Empty"
    },
    {
      "x": 3,
      "y": 48,
      "z": 15,
      "name": "Empty"
    },
    {
      "x": 3,
      "y": 49,
      "z": 15,
      "name": "Empty"
    },
    {
      "x": 3,
      "y": 45,
      "z": 16,
      "name": "Wood_Dry_Trunk",
      "support": 15,
      "rotation": 4
    },
    {
      "x": 3,
      "y": 46,
      "z": 16,
      "name": "Wood_Drywood_Planks"
    },
    {
      "x": 3,
      "y": 47,
      "z": 16,
      "name": "Furniture_Crude_Stool"
    },
    {
      "x": 3,
      "y": 48,
      "z": 16,
      "name": "Empty"
    },
    {
      "x": 3,
      "y": 49,
      "z": 16,
      "name": "Empty"
    },
    {
      "x": 3,
      "y": 50,
      "z": 16,
      "name": "Empty"
    },
    {
      "x": 3,
      "y": 45,
      "z": 17,
      "name": "Wood_Dry_Trunk",
      "support": 15,
      "rotation": 4
    },
    {
      "x": 3,
      "y": 46,
      "z": 17,
      "name": "Wood_Drywood_Planks"
    },
    {
      "x": 3,
      "y": 47,
      "z": 17,
      "name": "Furniture_Crude_Platform"
    },
    {
      "x": 3,
      "y": 48,
      "z": 17,
      "name": "Furniture_Crude_Platform"
    },
    {
      "x": 3,
      "y": 49,
      "z": 17,
      "name": "Empty"
    },
    {
      "x": 3,
      "y": 50,
      "z": 17,
      "name": "Empty"
    },
    {
      "x": 3,
      "y": 45,
      "z": 18,
      "name": "Wood_Dry_Trunk",
      "support": 15,
      "rotation": 4
    },
    {
      "x": 3,
      "y": 46,
      "z": 18,
      "name": "Wood_Drywood_Planks"
    },
    {
      "x": 3,
      "y": 47,
      "z": 18,
      "name": "Rock_Sandstone_Brick"
    },
    {
      "x": 3,
      "y": 48,
      "z": 18,
      "name": "Rock_Sandstone_Brick"
    },
    {
      "x": 3,
      "y": 49,
      "z": 18,
      "name": "Rock_Sandstone_Brick"
    },
    {
      "x": 3,
      "y": 50,
      "z": 18,
      "name": "Rock_Sandstone_Brick"
    },
    {
      "x": 3,
      "y": 45,
      "z": 19,
      "name": "Wood_Dry_Trunk",
      "support": 15,
      "rotation": 4
    },
    {
      "x": 3,
      "y": 46,
      "z": 19,
      "name": "Wood_Drywood_Planks"
    },
    {
      "x": 3,
      "y": 47,
      "z": 19,
      "name": "Rock_Sandstone_Brick"
    },
    {
      "x": 3,
      "y": 48,
      "z": 19,
      "name": "Rock_Sandstone_Brick"
    },
    {
      "x": 3,
      "y": 49,
      "z": 19,
      "name": "Rock_Sandstone_Brick"
    },
    {
      "x": 3,
      "y": 45,
      "z": 20,
      "name": "Wood_Dry_Trunk",
      "support": 15,
      "rotation": 4
    },
    {
      "x": 3,
      "y": 46,
      "z": 20,
      "name": "Wood_Drywood_Planks"
    },
    {
      "x": 3,
      "y": 48,
      "z": 20,
      "name": "Empty"
    },
    {
      "x": 3,
      "y": 49,
      "z": 20,
      "name": "Empty"
    },
    {
      "x": 3,
      "y": 50,
      "z": 20,
      "name": "Empty"
    },
    {
      "x": 4,
      "y": 45,
      "z": 12,
      "name": "Wood_Dry_Trunk",
      "support": 15,
      "rotation": 4
    },
    {
      "x": 4,
      "y": 46,
      "z": 12,
      "name": "Wood_Drywood_Planks"
    },
    {
      "x": 4,
      "y": 47,
      "z": 12,
      "name": "Rock_Sandstone_Brick"
    },
    {
      "x": 4,
      "y": 48,
      "z": 12,
      "name": "Rock_Sandstone_Brick"
    },
    {
      "x": 4,
      "y": 49,
      "z": 12,
      "name": "Rock_Sandstone_Brick"
    },
    {
      "x": 4,
      "y": 45,
      "z": 13,
      "name": "Wood_Dry_Trunk",
      "support": 15,
      "rotation": 4
    },
    {
      "x": 4,
      "y": 46,
      "z": 13,
      "name": "Wood_Drywood_Planks"
    },
    {
      "x": 4,
      "y": 47,
      "z": 13,
      "name": "Furniture_Village_Counter",
      "filler": 31
    },
    {
      "x": 4,
      "y": 48,
      "z": 13,
      "name": "Furniture_Crude_Shelf"
    },
    {
      "x": 4,
      "y": 49,
      "z": 13,
      "name": "Furniture_Crude_Shelf"
    },
    {
      "x": 4,
      "y": 45,
      "z": 14,
      "name": "Wood_Dry_Trunk",
      "support": 15,
      "rotation": 4
    },
    {
      "x": 4,
      "y": 46,
      "z": 14,
      "name": "Wood_Drywood_Planks"
    },
    {
      "x": 4,
      "y": 47,
      "z": 14,
      "name": "Empty"
    },
    {
      "x": 4,
      "y": 48,
      "z": 14,
      "name": "Empty"
    },
    {
      "x": 4,
      "y": 49,
      "z": 14,
      "name": "Empty"
    },
    {
      "x": 4,
      "y": 45,
      "z": 15,
      "name": "Wood_Dry_Trunk",
      "support": 15,
      "rotation": 4
    },
    {
      "x": 4,
      "y": 46,
      "z": 15,
      "name": "Wood_Drywood_Planks"
    },
    {
      "x": 4,
      "y": 47,
      "z": 15,
      "name": "Furniture_Crude_Stool"
    },
    {
      "x": 4,
      "y": 48,
      "z": 15,
      "name": "Empty"
    },
    {
      "x": 4,
      "y": 49,
      "z": 15,
      "name": "Empty"
    },
    {
      "x": 4,
      "y": 45,
      "z": 16,
      "name": "Wood_Dry_Trunk",
      "support": 15,
      "rotation": 4
    },
    {
      "x": 4,
      "y": 46,
      "z": 16,
      "name": "Wood_Drywood_Planks"
    },
    {
      "x": 4,
      "y": 47,
      "z": 16,
      "name": "Furniture_Crude_Table"
    },
    {
      "x": 4,
      "y": 48,
      "z": 16,
      "name": "Furniture_Crude_Candle"
    },
    {
      "x": 4,
      "y": 49,
      "z": 16,
      "name": "Empty"
    },
    {
      "x": 4,
      "y": 50,
      "z": 16,
      "name": "Empty"
    },
    {
      "x": 4,
      "y": 45,
      "z": 17,
      "name": "Wood_Dry_Trunk",
      "support": 15,
      "rotation": 4
    },
    {
      "x": 4,
      "y": 46,
      "z": 17,
      "name": "Wood_Drywood_Planks"
    },
    {
      "x": 4,
      "y": 47,
      "z": 17,
      "name": "Furniture_Crude_Table",
      "filler": 32
    },
    {
      "x": 4,
      "y": 48,
      "z": 17,
      "name": "Furniture_Crude_Platform"
    },
    {
      "x": 4,
      "y": 49,
      "z": 17,
      "name": "Furniture_Crude_Platform"
    },
    {
      "x": 4,
      "y": 50,
      "z": 17,
      "name": "Empty"
    },
    {
      "x": 4,
      "y": 45,
      "z": 18,
      "name": "Wood_Dry_Trunk",
      "support": 15,
      "rotation": 4
    },
    {
      "x": 4,
      "y": 46,
      "z": 18,
      "name": "Rock_Sandstone_Brick"
    },
    {
      "x": 4,
      "y": 47,
      "z": 18,
      "name": "Rock_Sandstone_Brick"
    },
    {
      "x": 4,
      "y": 48,
      "z": 18,
      "name": "Rock_Sandstone_Brick"
    },
    {
      "x": 4,
      "y": 49,
      "z": 18,
      "name": "Rock_Sandstone_Brick"
    },
    {
      "x": 5,
      "y": 45,
      "z": 12,
      "name": "Wood_Dry_Trunk",
      "support": 15,
      "rotation": 4
    },
    {
      "x": 5,
      "y": 46,
      "z": 12,
      "name": "Wood_Drywood_Planks"
    },
    {
      "x": 5,
      "y": 47,
      "z": 12,
      "name": "Rock_Sandstone_Brick"
    },
    {
      "x": 5,
      "y": 48,
      "z": 12,
      "name": "Rock_Sandstone_Brick"
    },
    {
      "x": 5,
      "y": 49,
      "z": 12,
      "name": "Rock_Sandstone_Brick"
    },
    {
      "x": 5,
      "y": 45,
      "z": 13,
      "name": "Wood_Dry_Trunk",
      "support": 15,
      "rotation": 4
    },
    {
      "x": 5,
      "y": 46,
      "z": 13,
      "name": "Wood_Drywood_Planks"
    },
    {
      "x": 5,
      "y": 47,
      "z": 13,
      "name": "Furniture_Village_Counter"
    },
    {
      "x": 5,
      "y": 48,
      "z": 13,
      "name": "Furniture_Crude_Shelf"
    },
    {
      "x": 5,
      "y": 49,
      "z": 13,
      "name": "Furniture_Crude_Shelf"
    },
    {
      "x": 5,
      "y": 45,
      "z": 14,
      "name": "Wood_Dry_Trunk",
      "support": 15,
      "rotation": 4
    },
    {
      "x": 5,
      "y": 46,
      "z": 14,
      "name": "Wood_Drywood_Planks"
    },
    {
      "x": 5,
      "y": 47,
      "z": 14,
      "name": "Empty"
    },
    {
      "x": 5,
      "y": 48,
      "z": 14,
      "name": "Empty"
    },
    {
      "x": 5,
      "y": 49,
      "z": 14,
      "name": "Empty"
    },
    {
      "x": 5,
      "y": 45,
      "z": 15,
      "name": "Wood_Dry_Trunk",
      "support": 15,
      "rotation": 4
    },
    {
      "x": 5,
      "y": 46,
      "z": 15,
      "name": "Wood_Drywood_Planks"
    },
    {
      "x": 5,
      "y": 47,
      "z": 15,
      "name": "Empty"
    },
    {
      "x": 5,
      "y": 48,
      "z": 15,
      "name": "Empty"
    },
    {
      "x": 5,
      "y": 49,
      "z": 15,
      "name": "Empty"
    },
    {
      "x": 5,
      "y": 45,
      "z": 16,
      "name": "Wood_Dry_Trunk",
      "support": 15,
      "rotation": 4
    },
    {
      "x": 5,
      "y": 46,
      "z": 16,
      "name": "Wood_Drywood_Planks"
    },
    {
      "x": 5,
      "y": 47,
      "z": 16,
      "name": "Furniture_Crude_Table",
      "filler": 1
    },
    {
      "x": 5,
      "y": 48,
      "z": 16,
      "name": "Empty"
    },
    {
      "x": 5,
      "y": 49,
      "z": 16,
      "name": "Empty"
    },
    {
      "x": 5,
      "y": 45,
      "z": 17,
      "name": "Wood_Dry_Trunk",
      "support": 15,
      "rotation": 4
    },
    {
      "x": 5,
      "y": 46,
      "z": 17,
      "name": "Wood_Drywood_Planks"
    },
    {
      "x": 5,
      "y": 47,
      "z": 17,
      "name": "Furniture_Crude_Table",
      "filler": 33
    },
    {
      "x": 5,
      "y": 48,
      "z": 17,
      "name": "Empty"
    },
    {
      "x": 5,
      "y": 49,
      "z": 17,
      "name": "Empty"
    },
    {
      "x": 5,
      "y": 50,
      "z": 17,
      "name": "Empty"
    },
    {
      "x": 5,
      "y": 45,
      "z": 18,
      "name": "Wood_Dry_Trunk",
      "support": 15,
      "rotation": 4
    },
    {
      "x": 5,
      "y": 46,
      "z": 18,
      "name": "Rock_Sandstone_Brick"
    },
    {
      "x": 5,
      "y": 47,
      "z": 18,
      "name": "Rock_Sandstone_Brick"
    },
    {
      "x": 5,
      "y": 48,
      "z": 18,
      "name": "Rock_Sandstone_Brick"
    },
    {
      "x": 5,
      "y": 49,
      "z": 18,
      "name": "Rock_Sandstone_Brick"
    },
    {
      "x": 6,
      "y": 45,
      "z": 13,
      "name": "Wood_Dry_Trunk",
      "support": 15,
      "rotation": 4
    },
    {
      "x": 6,
      "y": 46,
      "z": 13,
      "name": "Wood_Drywood_Planks"
    },
    {
      "x": 6,
      "y": 47,
      "z": 13,
      "name": "Rock_Sandstone_Brick"
    },
    {
      "x": 6,
      "y": 48,
      "z": 13,
      "name": "Rock_Sandstone_Brick"
    },
    {
      "x": 6,
      "y": 49,
      "z": 13,
      "name": "Rock_Sandstone_Brick"
    },
    {
      "x": 6,
      "y": 50,
      "z": 13,
      "name": "Rock_Sandstone_Brick"
    },
    {
      "x": 6,
      "y": 45,
      "z": 14,
      "name": "Wood_Dry_Trunk",
      "support": 15,
      "rotation": 4
    },
    {
      "x": 6,
      "y": 46,
      "z": 14,
      "name": "Wood_Drywood_Planks"
    },
    {
      "x": 6,
      "y": 47,
      "z": 14,
      "name": "Empty"
    },
    {
      "x": 6,
      "y": 48,
      "z": 14,
      "name": "Empty"
    },
    {
      "x": 6,
      "y": 49,
      "z": 14,
      "name": "Empty"
    },
    {
      "x": 6,
      "y": 45,
      "z": 15,
      "name": "Wood_Dry_Trunk",
      "support": 15,
      "rotation": 4
    },
    {
      "x": 6,
      "y": 46,
      "z": 15,
      "name": "Wood_Drywood_Planks"
    },
    {
      "x": 6,
      "y": 47,
      "z": 15,
      "name": "Empty"
    },
    {
      "x": 6,
      "y": 48,
      "z": 15,
      "name": "Empty"
    },
    {
      "x": 6,
      "y": 49,
      "z": 15,
      "name": "Empty"
    },
    {
      "x": 6,
      "y": 45,
      "z": 16,
      "name": "Wood_Dry_Trunk",
      "support": 15,
      "rotation": 4
    },
    {
      "x": 6,
      "y": 46,
      "z": 16,
      "name": "Wood_Drywood_Planks"
    },
    {
      "x": 6,
      "y": 47,
      "z": 16,
      "name": "Furniture_Crude_Stool"
    },
    {
      "x": 6,
      "y": 48,
      "z": 16,
      "name": "Empty"
    },
    {
      "x": 6,
      "y": 49,
      "z": 16,
      "name": "Empty"
    },
    {
      "x": 6,
      "y": 45,
      "z": 17,
      "name": "Wood_Dry_Trunk",
      "support": 15,
      "rotation": 4
    },
    {
      "x": 6,
      "y": 46,
      "z": 17,
      "name": "Wood_Drywood_Planks"
    },
    {
      "x": 6,
      "y": 45,
      "z": 18,
      "name": "Wood_Dry_Trunk",
      "support": 15,
      "rotation": 4
    },
    {
      "x": 6,
      "y": 46,
      "z": 18,
      "name": "Rock_Sandstone_Brick"
    },
    {
      "x": 6,
      "y": 47,
      "z": 18,
      "name": "Rock_Sandstone_Brick"
    },
    {
      "x": 7,
      "y": 45,
      "z": 14,
      "name": "Wood_Dry_Trunk",
      "support": 15,
      "rotation": 4
    },
    {
      "x": 7,
      "y": 46,
      "z": 14,
      "name": "Wood_Drywood_Planks"
    },
    {
      "x": 7,
      "y": 47,
      "z": 14,
      "name": "Block_Spawner_Block",
      "components": {
        "Components": {
          "BlockSpawner": {
            "BlockSpawnerId": "Zone2_Encounters_Tier2"
          }
        }
      },
      "rotation": 2
    },
    {
      "x": 7,
      "y": 48,
      "z": 14,
      "name": "Empty"
    },
    {
      "x": 7,
      "y": 45,
      "z": 15,
      "name": "Wood_Dry_Trunk",
      "support": 15,
      "rotation": 4
    },
    {
      "x": 7,
      "y": 46,
      "z": 15,
      "name": "Wood_Drywood_Planks"
    },
    {
      "x": 7,
      "y": 47,
      "z": 15,
      "name": "Empty"
    },
    {
      "x": 7,
      "y": 48,
      "z": 15,
      "name": "Empty"
    },
    {
      "x": 7,
      "y": 49,
      "z": 15,
      "name": "Empty"
    },
    {
      "x": 7,
      "y": 45,
      "z": 16,
      "name": "Wood_Dry_Trunk",
      "support": 15,
      "rotation": 4
    },
    {
      "x": 7,
      "y": 46,
      "z": 16,
      "name": "Wood_Drywood_Planks"
    },
    {
      "x": 7,
      "y": 45,
      "z": 17,
      "name": "Wood_Dry_Trunk",
      "support": 15,
      "rotation": 4
    },
    {
      "x": 7,
      "y": 46,
      "z": 17,
      "name": "Wood_Drywood_Planks"
    },
    {
      "x": 7,
      "y": 45,
      "z": 18,
      "name": "Wood_Dry_Trunk",
      "support": 15,
      "rotation": 4
    },
    {
      "x": 7,
      "y": 46,
      "z": 18,
      "name": "Wood_Drywood_Planks"
    }
  ]
}