{
  "version": 8,
  "blockIdVersion": 10,
  "anchorX": 0,
  "anchorY": 7,
  "anchorZ": 1,
  "blocks": [
    {
      "x": -12,
      "y": 9,
      "z": 0,
      "name": "Soil_Gravel_Sand"
    },
    {
      "x": -12,
      "y": 9,
      "z": 1,
      "name": "Soil_Gravel_Sand"
    },
    {
      "x": -12,
      "y": 10,
      "z": 1,
      "name": "Soil_Gravel_Sand_Half"
    },
    {
      "x": -12,
      "y": 9,
      "z": 2,
      "name": "Soil_Gravel_Sand"
    },
    {
      "x": -12,
      "y": 10,
      "z": 2,
      "name": "Soil_Gravel_Sand_Half"
    },
    {
      "x": -12,
      "y": 9,
      "z": 3,
      "name": "Soil_Gravel_Sand"
    },
    {
      "x": -11,
      "y": 9,
      "z": -2,
      "name": "Soil_Gravel_Sand"
    },
    {
      "x": -11,
      "y": 9,
      "z": -1,
      "name": "Soil_Gravel_Sand"
    },
    {
      "x": -11,
      "y": 10,
      "z": -1,
      "name": "Soil_Gravel_Sand_Half"
    },
    {
      "x": -11,
      "y": 9,
      "z": 0,
      "name": "Soil_Gravel_Sand"
    },
    {
      "x": -11,
      "y": 10,
      "z": 0,
      "name": "Soil_Gravel_Sand"
    },
    {
      "x": -11,
      "y": 9,
      "z": 1,
      "name": "Soil_Gravel_Sand"
    },
    {
      "x": -11,
      "y": 10,
      "z": 1,
      "name": "Soil_Gravel_Sand"
    },
    {
      "x": -11,
      "y": 9,
      "z": 2,
      "name": "Soil_Gravel_Sand"
    },
    {
      "x": -11,
      "y": 10,
      "z": 2,
      "name": "Soil_Gravel_Sand"
    },
    {
      "x": -11,
      "y": 9,
      "z": 3,
      "name": "Soil_Gravel_Sand"
    },
    {
      "x": -11,
      "y": 10,
      "z": 3,
      "name": "Soil_Gravel_Sand"
    },
    {
      "x": -11,
      "y": 9,
      "z": 4,
      "name": "Soil_Gravel_Sand"
    },
    {
      "x": -11,
      "y": 10,
      "z": 4,
      "name": "Soil_Gravel_Sand_Half"
    },
    {
      "x": -11,
      "y": 9,
      "z": 5,
      "name": "Soil_Gravel_Sand"
    },
    {
      "x": -10,
      "y": 9,
      "z": -3,
      "name": "Soil_Gravel_Sand"
    },
    {
      "x": -10,
      "y": 9,
      "z": -2,
      "name": "Soil_Gravel_Sand"
    },
    {
      "x": -10,
      "y": 10,
      "z": -2,
      "name": "Soil_Gravel_Sand"
    },
    {
      "x": -10,
      "y": 2,
      "z": -1,
      "name": "Soil_Dirt_Dry"
    },
    {
      "x": -10,
      "y": 3,
      "z": -1,
      "name": "Soil_Dirt_Dry"
    },
    {
      "x": -10,
      "y": 4,
      "z": -1,
      "name": "Soil_Dirt_Dry"
    },
    {
      "x": -10,
      "y": 5,
      "z": -1,
      "name": "Soil_Dirt_Dry"
    },
    {
      "x": -10,
      "y": 6,
      "z": -1,
      "name": "Soil_Dirt_Dry"
    },
    {
      "x": -10,
      "y": 7,
      "z": -1,
      "name": "Soil_Dirt_Dry"
    },
    {
      "x": -10,
      "y": 8,
      "z": -1,
      "name": "Soil_Dirt_Dry"
    },
    {
      "x": -10,
      "y": 9,
      "z": -1,
      "name": "Soil_Gravel_Sand"
    },
    {
      "x": -10,
      "y": 10,
      "z": -1,
      "name": "Soil_Gravel_Sand"
    },
    {
      "x": -10,
      "y": 2,
      "z": 0,
      "name": "Soil_Dirt_Dry"
    },
    {
      "x": -10,
      "y": 3,
      "z": 0,
      "name": "Soil_Dirt_Dry"
    },
    {
      "x": -10,
      "y": 4,
      "z": 0,
      "name": "Soil_Dirt_Dry"
    },
    {
      "x": -10,
      "y": 5,
      "z": 0,
      "name": "Soil_Dirt_Dry"
    },
    {
      "x": -10,
      "y": 6,
      "z": 0,
      "name": "Soil_Dirt_Dry"
    },
    {
      "x": -10,
      "y": 7,
      "z": 0,
      "name": "Soil_Dirt_Dry"
    },
    {
      "x": -10,
      "y": 8,
      "z": 0,
      "name": "Soil_Dirt_Dry"
    },
    {
      "x": -10,
      "y": 9,
      "z": 0,
      "name": "Soil_Dirt_Dry"
    },
    {
      "x": -10,
      "y": 10,
      "z": 0,
      "name": "Soil_Gravel_Sand"
    },
    {
      "x": -10,
      "y": 11,
      "z": 0,
      "name": "Soil_Gravel_Sand_Half"
    },
    {
      "x": -10,
      "y": 2,
      "z": 1,
      "name": "Soil_Dirt_Dry"
    },
    {
      "x": -10,
      "y": 3,
      "z": 1,
      "name": "Soil_Dirt_Dry"
    },
    {
      "x": -10,
      "y": 4,
      "z": 1,
      "name": "Soil_Dirt_Dry"
    },
    {
      "x": -10,
      "y": 5,
      "z": 1,
      "name": "Soil_Dirt_Dry"
    },
    {
      "x": -10,
      "y": 6,
      "z": 1,
      "name": "Soil_Dirt_Dry"
    },
    {
      "x": -10,
      "y": 7,
      "z": 1,
      "name": "Soil_Dirt_Dry"
    },
    {
      "x": -10,
      "y": 8,
      "z": 1,
      "name": "Soil_Dirt_Dry"
    },
    {
      "x": -10,
      "y": 9,
      "z": 1,
      "name": "Soil_Gravel_Sand"
    },
    {
      "x": -10,
      "y": 10,
      "z": 1,
      "name": "Soil_Gravel_Sand"
    },
    {
      "x": -10,
      "y": 11,
      "z": 1,
      "name": "Soil_Gravel_Sand_Half"
    },
    {
      "x": -10,
      "y": 2,
      "z": 2,
      "name": "Soil_Dirt_Dry"
    },
    {
      "x": -10,
      "y": 3,
      "z": 2,
      "name": "Soil_Dirt_Dry"
    },
    {
      "x": -10,
      "y": 4,
      "z": 2,
      "name": "Soil_Dirt_Dry"
    },
    {
      "x": -10,
      "y": 5,
      "z": 2,
      "name": "Soil_Dirt_Dry"
    },
    {
      "x": -10,
      "y": 6,
      "z": 2,
      "name": "Soil_Dirt_Dry"
    },
    {
      "x": -10,
      "y": 7,
      "z": 2,
      "name": "Soil_Dirt_Dry"
    },
    {
      "x": -10,
      "y": 8,
      "z": 2,
      "name": "Soil_Dirt_Dry"
    },
    {
      "x": -10,
      "y": 9,
      "z": 2,
      "name": "Soil_Gravel_Sand"
    },
    {
      "x": -10,
      "y": 10,
      "z": 2,
      "name": "Soil_Gravel_Sand"
    },
    {
      "x": -10,
      "y": 11,
      "z": 2,
      "name": "Soil_Gravel_Sand_Half"
    },
    {
      "x": -10,
      "y": 2,
      "z": 3,
      "name": "Soil_Dirt_Dry"
    },
    {
      "x": -10,
      "y": 3,
      "z": 3,
      "name": "Soil_Dirt_Dry"
    },
    {
      "x": -10,
      "y": 4,
      "z": 3,
      "name": "Soil_Dirt_Dry"
    },
    {
      "x": -10,
      "y": 5,
      "z": 3,
      "name": "Soil_Dirt_Dry"
    },
    {
      "x": -10,
      "y": 6,
      "z": 3,
      "name": "Soil_Dirt_Dry"
    },
    {
      "x": -10,
      "y": 7,
      "z": 3,
      "name": "Soil_Dirt_Dry"
    },
    {
      "x": -10,
      "y": 8,
      "z": 3,
      "name": "Soil_Dirt_Dry"
    },
    {
      "x": -10,
      "y": 9,
      "z": 3,
      "name": "Soil_Gravel_Sand"
    },
    {
      "x": -10,
      "y": 10,
      "z": 3,
      "name": "Soil_Gravel_Sand"
    },
    {
      "x": -10,
      "y": 11,
      "z": 3,
      "name": "Soil_Gravel_Sand_Half"
    },
    {
      "x": -10,
      "y": 9,
      "z": 4,
      "name": "Soil_Gravel_Sand"
    },
    {
      "x": -10,
      "y": 10,
      "z": 4,
      "name": "Soil_Gravel_Sand"
    },
    {
      "x": -10,
      "y": 9,
      "z": 5,
      "name": "Soil_Gravel_Sand"
    },
    {
      "x": -10,
      "y": 10,
      "z": 5,
      "name": "Soil_Gravel_Sand"
    },
    {
      "x": -10,
      "y": 9,
      "z": 6,
      "name": "Soil_Gravel_Sand"
    },
    {
      "x": -10,
      "y": 10,
      "z": 6,
      "name": "Soil_Gravel_Sand_Half"
    },
    {
      "x": -9,
      "y": 2,
      "z": -3,
      "name": "Soil_Dirt_Dry"
    },
    {
      "x": -9,
      "y": 3,
      "z": -3,
      "name": "Soil_Dirt_Dry"
    },
    {
      "x": -9,
      "y": 4,
      "z": -3,
      "name": "Soil_Dirt_Dry"
    },
    {
      "x": -9,
      "y": 5,
      "z": -3,
      "name": "Soil_Dirt_Dry"
    },
    {
      "x": -9,
      "y": 6,
      "z": -3,
      "name": "Soil_Dirt_Dry"
    },
    {
      "x": -9,
      "y": 7,
      "z": -3,
      "name": "Soil_Dirt_Dry"
    },
    {
      "x": -9,
      "y": 8,
      "z": -3,
      "name": "Soil_Dirt_Dry"
    },
    {
      "x": -9,
      "y": 9,
      "z": -3,
      "name": "Soil_Dirt_Dry"
    },
    {
      "x": -9,
      "y": 10,
      "z": -3,
      "name": "Soil_Grass_Dry"
    },
    {
      "x": -9,
      "y": 2,
      "z": -2,
      "name": "Soil_Dirt_Dry"
    },
    {
      "x": -9,
      "y": 3,
      "z": -2,
      "name": "Soil_Dirt_Dry"
    },
    {
      "x": -9,
      "y": 4,
      "z": -2,
      "name": "Soil_Dirt_Dry"
    },
    {
      "x": -9,
      "y": 5,
      "z": -2,
      "name": "Soil_Dirt_Dry"
    },
    {
      "x": -9,
      "y": 6,
      "z": -2,
      "name": "Soil_Dirt_Dry"
    },
    {
      "x": -9,
      "y": 7,
      "z": -2,
      "name": "Soil_Dirt_Dry"
    },
    {
      "x": -9,
      "y": 8,
      "z": -2,
      "name": "Soil_Dirt_Dry"
    },
    {
      "x": -9,
      "y": 9,
      "z": -2,
      "name": "Soil_Dirt_Dry"
    },
    {
      "x": -9,
      "y": 10,
      "z": -2,
      "name": "Soil_Gravel_Sand"
    },
    {
      "x": -9,
      "y": 11,
      "z": -2,
      "name": "Soil_Gravel_Sand"
    },
    {
      "x": -9,
      "y": 2,
      "z": -1,
      "name": "Soil_Dirt_Dry"
    },
    {
      "x": -9,
      "y": 3,
      "z": -1,
      "name": "Soil_Dirt_Dry"
    },
    {
      "x": -9,
      "y": 4,
      "z": -1,
      "name": "Soil_Dirt_Dry"
    },
    {
      "x": -9,
      "y": 5,
      "z": -1,
      "name": "Soil_Dirt_Dry"
    },
    {
      "x": -9,
      "y": 6,
      "z": -1,
      "name": "Soil_Dirt_Dry"
    },
    {
      "x": -9,
      "y": 7,
      "z": -1,
      "name": "Soil_Dirt_Dry"
    },
    {
      "x": -9,
      "y": 8,
      "z": -1,
      "name": "Soil_Dirt_Dry"
    },
    {
      "x": -9,
      "y": 9,
      "z": -1,
      "name": "Soil_Dirt_Dry"
    },
    {
      "x": -9,
      "y": 10,
      "z": -1,
      "name": "Soil_Dirt_Dry"
    },
    {
      "x": -9,
      "y": 11,
      "z": -1,
      "name": "Soil_Gravel_Sand"
    },
    {
      "x": -9,
      "y": 2,
      "z": 0,
      "name": "Soil_Dirt_Dry"
    },
    {
      "x": -9,
      "y": 3,
      "z": 0,
      "name": "Soil_Dirt_Dry"
    },
    {
      "x": -9,
      "y": 4,
      "z": 0,
      "name": "Soil_Dirt_Dry"
    },
    {
      "x": -9,
      "y": 5,
      "z": 0,
      "name": "Soil_Dirt_Dry"
    },
    {
      "x": -9,
      "y": 6,
      "z": 0,
      "name": "Soil_Dirt_Dry"
    },
    {
      "x": -9,
      "y": 7,
      "z": 0,
      "name": "Soil_Dirt_Dry"
    },
    {
      "x": -9,
      "y": 8,
      "z": 0,
      "name": "Soil_Dirt_Dry"
    },
    {
      "x": -9,
      "y": 9,
      "z": 0,
      "name": "Soil_Dirt_Dry"
    },
    {
      "x": -9,
      "y": 10,
      "z": 0,
      "name": "Soil_Gravel_Sand"
    },
    {
      "x": -9,
      "y": 11,
      "z": 0,
      "name": "Soil_Gravel_Sand"
    },
    {
      "x": -9,
      "y": 2,
      "z": 1,
      "name": "Soil_Dirt_Dry"
    },
    {
      "x": -9,
      "y": 3,
      "z": 1,
      "name": "Soil_Dirt_Dry"
    },
    {
      "x": -9,
      "y": 4,
      "z": 1,
      "name": "Soil_Dirt_Dry"
    },
    {
      "x": -9,
      "y": 5,
      "z": 1,
      "name": "Soil_Dirt_Dry"
    },
    {
      "x": -9,
      "y": 6,
      "z": 1,
      "name": "Soil_Dirt_Dry"
    },
    {
      "x": -9,
      "y": 7,
      "z": 1,
      "name": "Soil_Dirt_Dry"
    },
    {
      "x": -9,
      "y": 8,
      "z": 1,
      "name": "Soil_Dirt_Dry"
    },
    {
      "x": -9,
      "y": 9,
      "z": 1,
      "name": "Soil_Gravel_Sand"
    },
    {
      "x": -9,
      "y": 10,
      "z": 1,
      "name": "Soil_Gravel_Sand"
    },
    {
      "x": -9,
      "y": 11,
      "z": 1,
      "name": "Soil_Gravel_Sand"
    },
    {
      "x": -9,
      "y": 2,
      "z": 2,
      "name": "Soil_Dirt_Dry"
    },
    {
      "x": -9,
      "y": 3,
      "z": 2,
      "name": "Soil_Dirt_Dry"
    },
    {
      "x": -9,
      "y": 4,
      "z": 2,
      "name": "Soil_Dirt_Dry"
    },
    {
      "x": -9,
      "y": 5,
      "z": 2,
      "name": "Soil_Dirt_Dry"
    },
    {
      "x": -9,
      "y": 6,
      "z": 2,
      "name": "Soil_Dirt_Dry"
    },
    {
      "x": -9,
      "y": 7,
      "z": 2,
      "name": "Soil_Dirt_Dry"
    },
    {
      "x": -9,
      "y": 8,
      "z": 2,
      "name": "Soil_Dirt_Dry"
    },
    {
      "x": -9,
      "y": 9,
      "z": 2,
      "name": "Soil_Gravel_Sand"
    },
    {
      "x": -9,
      "y": 10,
      "z": 2,
      "name": "Soil_Gravel_Sand"
    },
    {
      "x": -9,
      "y": 11,
      "z": 2,
      "name": "Soil_Gravel_Sand"
    },
    {
      "x": -9,
      "y": 2,
      "z": 3,
      "name": "Soil_Dirt_Dry"
    },
    {
      "x": -9,
      "y": 3,
      "z": 3,
      "name": "Soil_Dirt_Dry"
    },
    {
      "x": -9,
      "y": 4,
      "z": 3,
      "name": "Soil_Dirt_Dry"
    },
    {
      "x": -9,
      "y": 5,
      "z": 3,
      "name": "Soil_Dirt_Dry"
    },
    {
      "x": -9,
      "y": 6,
      "z": 3,
      "name": "Soil_Dirt_Dry"
    },
    {
      "x": -9,
      "y": 7,
      "z": 3,
      "name": "Soil_Dirt_Dry"
    },
    {
      "x": -9,
      "y": 8,
      "z": 3,
      "name": "Soil_Dirt_Dry"
    },
    {
      "x": -9,
      "y": 9,
      "z": 3,
      "name": "Soil_Gravel_Sand"
    },
    {
      "x": -9,
      "y": 10,
      "z": 3,
      "name": "Soil_Gravel_Sand"
    },
    {
      "x": -9,
      "y": 11,
      "z": 3,
      "name": "Soil_Gravel_Sand"
    },
    {
      "x": -9,
      "y": 2,
      "z": 4,
      "name": "Soil_Dirt_Dry"
    },
    {
      "x": -9,
      "y": 3,
      "z": 4,
      "name": "Soil_Dirt_Dry"
    },
    {
      "x": -9,
      "y": 4,
      "z": 4,
      "name": "Soil_Dirt_Dry"
    },
    {
      "x": -9,
      "y": 5,
      "z": 4,
      "name": "Soil_Dirt_Dry"
    },
    {
      "x": -9,
      "y": 6,
      "z": 4,
      "name": "Soil_Dirt_Dry"
    },
    {
      "x": -9,
      "y": 7,
      "z": 4,
      "name": "Soil_Dirt_Dry"
    },
    {
      "x": -9,
      "y": 8,
      "z": 4,
      "name": "Soil_Dirt_Dry"
    },
    {
      "x": -9,
      "y": 9,
      "z": 4,
      "name": "Soil_Dirt_Dry"
    },
    {
      "x": -9,
      "y": 10,
      "z": 4,
      "name": "Soil_Gravel_Sand"
    },
    {
      "x": -9,
      "y": 11,
      "z": 4,
      "name": "Soil_Gravel_Sand_Half"
    },
    {
      "x": -9,
      "y": 2,
      "z": 5,
      "name": "Soil_Dirt_Dry"
    },
    {
      "x": -9,
      "y": 3,
      "z": 5,
      "name": "Soil_Dirt_Dry"
    },
    {
      "x": -9,
      "y": 4,
      "z": 5,
      "name": "Soil_Dirt_Dry"
    },
    {
      "x": -9,
      "y": 5,
      "z": 5,
      "name": "Soil_Dirt_Dry"
    },
    {
      "x": -9,
      "y": 6,
      "z": 5,
      "name": "Soil_Dirt_Dry"
    },
    {
      "x": -9,
      "y": 7,
      "z": 5,
      "name": "Soil_Dirt_Dry"
    },
    {
      "x": -9,
      "y": 8,
      "z": 5,
      "name": "Soil_Dirt_Dry"
    },
    {
      "x": -9,
      "y": 9,
      "z": 5,
      "name": "Soil_Dirt_Dry"
    },
    {
      "x": -9,
      "y": 10,
      "z": 5,
      "name": "Soil_Dirt_Dry"
    },
    {
      "x": -9,
      "y": 11,
      "z": 5,
      "name": "Soil_Gravel_Sand_Half"
    },
    {
      "x": -9,
      "y": 2,
      "z": 6,
      "name": "Soil_Dirt_Dry"
    },
    {
      "x": -9,
      "y": 3,
      "z": 6,
      "name": "Soil_Dirt_Dry"
    },
    {
      "x": -9,
      "y": 4,
      "z": 6,
      "name": "Soil_Dirt_Dry"
    },
    {
      "x": -9,
      "y": 5,
      "z": 6,
      "name": "Soil_Dirt_Dry"
    },
    {
      "x": -9,
      "y": 6,
      "z": 6,
      "name": "Soil_Dirt_Dry"
    },
    {
      "x": -9,
      "y": 7,
      "z": 6,
      "name": "Soil_Dirt_Dry"
    },
    {
      "x": -9,
      "y": 8,
      "z": 6,
      "name": "Soil_Dirt_Dry"
    },
    {
      "x": -9,
      "y": 9,
      "z": 6,
      "name": "Soil_Dirt_Dry"
    },
    {
      "x": -9,
      "y": 10,
      "z": 6,
      "name": "Soil_Grass_Dry"
    },
    {
      "x": -8,
      "y": 2,
      "z": -4,
      "name": "Soil_Dirt_Dry"
    },
    {
      "x": -8,
      "y": 3,
      "z": -4,
      "name": "Soil_Dirt_Dry"
    },
    {
      "x": -8,
      "y": 4,
      "z": -4,
      "name": "Soil_Dirt_Dry"
    },
    {
      "x": -8,
      "y": 5,
      "z": -4,
      "name": "Soil_Dirt_Dry"
    },
    {
      "x": -8,
      "y": 6,
      "z": -4,
      "name": "Soil_Dirt_Dry"
    },
    {
      "x": -8,
      "y": 7,
      "z": -4,
      "name": "Soil_Dirt_Dry"
    },
    {
      "x": -8,
      "y": 8,
      "z": -4,
      "name": "Soil_Dirt_Dry"
    },
    {
      "x": -8,
      "y": 9,
      "z": -4,
      "name": "Soil_Dirt_Dry"
    },
    {
      "x": -8,
      "y": 10,
      "z": -4,
      "name": "Soil_Dirt_Dry"
    },
    {
      "x": -8,
      "y": 11,
      "z": -4,
      "name": "Soil_Grass_Dry"
    },
    {
      "x": -8,
      "y": 2,
      "z": -3,
      "name": "Soil_Dirt_Dry"
    },
    {
      "x": -8,
      "y": 3,
      "z": -3,
      "name": "Soil_Dirt_Dry"
    },
    {
      "x": -8,
      "y": 4,
      "z": -3,
      "name": "Soil_Dirt_Dry"
    },
    {
      "x": -8,
      "y": 5,
      "z": -3,
      "name": "Soil_Dirt_Dry"
    },
    {
      "x": -8,
      "y": 6,
      "z": -3,
      "name": "Soil_Dirt_Dry"
    },
    {
      "x": -8,
      "y": 7,
      "z": -3,
      "name": "Soil_Dirt_Dry"
    },
    {
      "x": -8,
      "y": 8,
      "z": -3,
      "name": "Soil_Dirt_Dry"
    },
    {
      "x": -8,
      "y": 9,
      "z": -3,
      "name": "Soil_Dirt_Dry"
    },
    {
      "x": -8,
      "y": 10,
      "z": -3,
      "name": "Soil_Dirt_Dry"
    },
    {
      "x": -8,
      "y": 11,
      "z": -3,
      "name": "Soil_Grass_Dry"
    },
    {
      "x": -8,
      "y": 2,
      "z": -2,
      "name": "Soil_Dirt_Dry"
    },
    {
      "x": -8,
      "y": 3,
      "z": -2,
      "name": "Soil_Dirt_Dry"
    },
    {
      "x": -8,
      "y": 4,
      "z": -2,
      "name": "Soil_Dirt_Dry"
    },
    {
      "x": -8,
      "y": 5,
      "z": -2,
      "name": "Soil_Dirt_Dry"
    },
    {
      "x": -8,
      "y": 6,
      "z": -2,
      "name": "Soil_Dirt_Dry"
    },
    {
      "x": -8,
      "y": 7,
      "z": -2,
      "name": "Soil_Dirt_Dry"
    },
    {
      "x": -8,
      "y": 8,
      "z": -2,
      "name": "Soil_Dirt_Dry"
    },
    {
      "x": -8,
      "y": 9,
      "z": -2,
      "name": "Soil_Dirt_Dry"
    },
    {
      "x": -8,
      "y": 10,
      "z": -2,
      "name": "Soil_Dirt_Dry"
    },
    {
      "x": -8,
      "y": 11,
      "z": -2,
      "name": "Soil_Gravel_Sand"
    },
    {
      "x": -8,
      "y": 2,
      "z": -1,
      "name": "Soil_Dirt_Dry"
    },
    {
      "x": -8,
      "y": 3,
      "z": -1,
      "name": "Soil_Dirt_Dry"
    },
    {
      "x": -8,
      "y": 4,
      "z": -1,
      "name": "Soil_Dirt_Dry"
    },
    {
      "x": -8,
      "y": 5,
      "z": -1,
      "name": "Soil_Dirt_Dry"
    },
    {
      "x": -8,
      "y": 6,
      "z": -1,
      "name": "Soil_Dirt_Dry"
    },
    {
      "x": -8,
      "y": 7,
      "z": -1,
      "name": "Soil_Dirt_Dry"
    },
    {
      "x": -8,
      "y": 8,
      "z": -1,
      "name": "Soil_Dirt_Dry"
    },
    {
      "x": -8,
      "y": 9,
      "z": -1,
      "name": "Soil_Dirt_Dry"
    },
    {
      "x": -8,
      "y": 10,
      "z": -1,
      "name": "Soil_Dirt_Dry"
    },
    {
      "x": -8,
      "y": 11,
      "z": -1,
      "name": "Soil_Dirt_Dry"
    },
    {
      "x": -8,
      "y": 12,
      "z": -1,
      "name": "Soil_Gravel_Sand_Half"
    },
    {
      "x": -8,
      "y": 2,
      "z": 0,
      "name": "Soil_Dirt_Dry"
    },
    {
      "x": -8,
      "y": 3,
      "z": 0,
      "name": "Soil_Dirt_Dry"
    },
    {
      "x": -8,
      "y": 4,
      "z": 0,
      "name": "Soil_Dirt_Dry"
    },
    {
      "x": -8,
      "y": 5,
      "z": 0,
      "name": "Soil_Dirt_Dry"
    },
    {
      "x": -8,
      "y": 6,
      "z": 0,
      "name": "Soil_Dirt_Dry"
    },
    {
      "x": -8,
      "y": 7,
      "z": 0,
      "name": "Soil_Dirt_Dry"
    },
    {
      "x": -8,
      "y": 8,
      "z": 0,
      "name": "Soil_Dirt_Dry"
    },
    {
      "x": -8,
      "y": 9,
      "z": 0,
      "name": "Soil_Dirt_Dry"
    },
    {
      "x": -8,
      "y": 10,
      "z": 0,
      "name": "Soil_Dirt_Dry"
    },
    {
      "x": -8,
      "y": 11,
      "z": 0,
      "name": "Soil_Gravel_Sand"
    },
    {
      "x": -8,
      "y": 12,
      "z": 0,
      "name": "Soil_Gravel_Sand_Half"
    },
    {
      "x": -8,
      "y": 2,
      "z": 1,
      "name": "Soil_Dirt_Dry"
    },
    {
      "x": -8,
      "y": 3,
      "z": 1,
      "name": "Soil_Dirt_Dry"
    },
    {
      "x": -8,
      "y": 4,
      "z": 1,
      "name": "Soil_Dirt_Dry"
    },
    {
      "x": -8,
      "y": 5,
      "z": 1,
      "name": "Soil_Dirt_Dry"
    },
    {
      "x": -8,
      "y": 6,
      "z": 1,
      "name": "Soil_Dirt_Dry"
    },
    {
      "x": -8,
      "y": 7,
      "z": 1,
      "name": "Soil_Dirt_Dry"
    },
    {
      "x": -8,
      "y": 8,
      "z": 1,
      "name": "Soil_Dirt_Dry"
    },
    {
      "x": -8,
      "y": 9,
      "z": 1,
      "name": "Soil_Dirt_Dry"
    },
    {
      "x": -8,
      "y": 10,
      "z": 1,
      "name": "Soil_Gravel_Sand"
    },
    {
      "x": -8,
      "y": 11,
      "z": 1,
      "name": "Soil_Gravel_Sand"
    },
    {
      "x": -8,
      "y": 12,
      "z": 1,
      "name": "Soil_Gravel_Sand_Half"
    },
    {
      "x": -8,
      "y": 2,
      "z": 2,
      "name": "Soil_Dirt_Dry"
    },
    {
      "x": -8,
      "y": 3,
      "z": 2,
      "name": "Soil_Dirt_Dry"
    },
    {
      "x": -8,
      "y": 4,
      "z": 2,
      "name": "Soil_Dirt_Dry"
    },
    {
      "x": -8,
      "y": 5,
      "z": 2,
      "name": "Soil_Dirt_Dry"
    },
    {
      "x": -8,
      "y": 6,
      "z": 2,
      "name": "Soil_Dirt_Dry"
    },
    {
      "x": -8,
      "y": 7,
      "z": 2,
      "name": "Soil_Dirt_Dry"
    },
    {
      "x": -8,
      "y": 8,
      "z": 2,
      "name": "Soil_Dirt_Dry"
    },
    {
      "x": -8,
      "y": 9,
      "z": 2,
      "name": "Soil_Gravel_Sand"
    },
    {
      "x": -8,
      "y": 10,
      "z": 2,
      "name": "Soil_Gravel_Sand"
    },
    {
      "x": -8,
      "y": 11,
      "z": 2,
      "name": "Soil_Gravel_Sand"
    },
    {
      "x": -8,
      "y": 12,
      "z": 2,
      "name": "Soil_Gravel_Sand_Half"
    },
    {
      "x": -8,
      "y": 2,
      "z": 3,
      "name": "Soil_Dirt_Dry"
    },
    {
      "x": -8,
      "y": 3,
      "z": 3,
      "name": "Soil_Dirt_Dry"
    },
    {
      "x": -8,
      "y": 4,
      "z": 3,
      "name": "Soil_Dirt_Dry"
    },
    {
      "x": -8,
      "y": 5,
      "z": 3,
      "name": "Soil_Dirt_Dry"
    },
    {
      "x": -8,
      "y": 6,
      "z": 3,
      "name": "Soil_Dirt_Dry"
    },
    {
      "x": -8,
      "y": 7,
      "z": 3,
      "name": "Soil_Dirt_Dry"
    },
    {
      "x": -8,
      "y": 8,
      "z": 3,
      "name": "Soil_Dirt_Dry"
    },
    {
      "x": -8,
      "y": 9,
      "z": 3,
      "name": "Soil_Dirt_Dry"
    },
    {
      "x": -8,
      "y": 10,
      "z": 3,
      "name": "Soil_Gravel_Sand"
    },
    {
      "x": -8,
      "y": 11,
      "z": 3,
      "name": "Soil_Gravel_Sand"
    },
    {
      "x": -8,
      "y": 12,
      "z": 3,
      "name": "Soil_Gravel_Sand_Half"
    },
    {
      "x": -8,
      "y": 2,
      "z": 4,
      "name": "Soil_Dirt_Dry"
    },
    {
      "x": -8,
      "y": 3,
      "z": 4,
      "name": "Soil_Dirt_Dry"
    },
    {
      "x": -8,
      "y": 4,
      "z": 4,
      "name": "Soil_Dirt_Dry"
    },
    {
      "x": -8,
      "y": 5,
      "z": 4,
      "name": "Soil_Dirt_Dry"
    },
    {
      "x": -8,
      "y": 6,
      "z": 4,
      "name": "Soil_Dirt_Dry"
    },
    {
      "x": -8,
      "y": 7,
      "z": 4,
      "name": "Soil_Dirt_Dry"
    },
    {
      "x": -8,
      "y": 8,
      "z": 4,
      "name": "Soil_Dirt_Dry"
    },
    {
      "x": -8,
      "y": 9,
      "z": 4,
      "name": "Soil_Dirt_Dry"
    },
    {
      "x": -8,
      "y": 10,
      "z": 4,
      "name": "Soil_Gravel_Sand"
    },
    {
      "x": -8,
      "y": 11,
      "z": 4,
      "name": "Soil_Gravel_Sand"
    },
    {
      "x": -8,
      "y": 2,
      "z": 5,
      "name": "Soil_Dirt_Dry"
    },
    {
      "x": -8,
      "y": 3,
      "z": 5,
      "name": "Soil_Dirt_Dry"
    },
    {
      "x": -8,
      "y": 4,
      "z": 5,
      "name": "Soil_Dirt_Dry"
    },
    {
      "x": -8,
      "y": 5,
      "z": 5,
      "name": "Soil_Dirt_Dry"
    },
    {
      "x": -8,
      "y": 6,
      "z": 5,
      "name": "Soil_Dirt_Dry"
    },
    {
      "x": -8,
      "y": 7,
      "z": 5,
      "name": "Soil_Dirt_Dry"
    },
    {
      "x": -8,
      "y": 8,
      "z": 5,
      "name": "Soil_Dirt_Dry"
    },
    {
      "x": -8,
      "y": 9,
      "z": 5,
      "name": "Soil_Dirt_Dry"
    },
    {
      "x": -8,
      "y": 10,
      "z": 5,
      "name": "Soil_Dirt_Dry"
    },
    {
      "x": -8,
      "y": 11,
      "z": 5,
      "name": "Soil_Gravel_Sand"
    },
    {
      "x": -8,
      "y": 2,
      "z": 6,
      "name": "Soil_Dirt_Dry"
    },
    {
      "x": -8,
      "y": 3,
      "z": 6,
      "name": "Soil_Dirt_Dry"
    },
    {
      "x": -8,
      "y": 4,
      "z": 6,
      "name": "Soil_Dirt_Dry"
    },
    {
      "x": -8,
      "y": 5,
      "z": 6,
      "name": "Soil_Dirt_Dry"
    },
    {
      "x": -8,
      "y": 6,
      "z": 6,
      "name": "Soil_Dirt_Dry"
    },
    {
      "x": -8,
      "y": 7,
      "z": 6,
      "name": "Soil_Dirt_Dry"
    },
    {
      "x": -8,
      "y": 8,
      "z": 6,
      "name": "Soil_Dirt_Dry"
    },
    {
      "x": -8,
      "y": 9,
      "z": 6,
      "name": "Soil_Dirt_Dry"
    },
    {
      "x": -8,
      "y": 10,
      "z": 6,
      "name": "Soil_Dirt_Dry"
    },
    {
      "x": -8,
      "y": 11,
      "z": 6,
      "name": "Soil_Grass_Dry"
    },
    {
      "x": -8,
      "y": 2,
      "z": 7,
      "name": "Soil_Clay"
    },
    {
      "x": -8,
      "y": 3,
      "z": 7,
      "name": "Soil_Clay"
    },
    {
      "x": -8,
      "y": 4,
      "z": 7,
      "name": "Soil_Clay"
    },
    {
      "x": -8,
      "y": 5,
      "z": 7,
      "name": "Soil_Clay"
    },
    {
      "x": -8,
      "y": 6,
      "z": 7,
      "name": "Soil_Clay"
    },
    {
      "x": -8,
      "y": 7,
      "z": 7,
      "name": "Soil_Clay"
    },
    {
      "x": -8,
      "y": 8,
      "z": 7,
      "name": "Soil_Clay"
    },
    {
      "x": -8,
      "y": 9,
      "z": 7,
      "name": "Soil_Clay"
    },
    {
      "x": -8,
      "y": 10,
      "z": 7,
      "name": "Rock_Sandstone_Cobble"
    },
    {
      "x": -8,
      "y": 11,
      "z": 7,
      "name": "Rock_Sandstone_Cobble"
    },
    {
      "x": -8,
      "y": 12,
      "z": 7,
      "name": "Rock_Sandstone_Cobble"
    },
    {
      "x": -8,
      "y": 4,
      "z": 8,
      "name": "Soil_Dirt_Dry"
    },
    {
      "x": -8,
      "y": 5,
      "z": 8,
      "name": "Soil_Dirt_Dry"
    },
    {
      "x": -8,
      "y": 6,
      "z": 8,
      "name": "Soil_Dirt_Dry"
    },
    {
      "x": -8,
      "y": 7,
      "z": 8,
      "name": "Soil_Dirt_Dry"
    },
    {
      "x": -8,
      "y": 8,
      "z": 8,
      "name": "Soil_Dirt_Dry"
    },
    {
      "x": -8,
      "y": 9,
      "z": 8,
      "name": "Soil_Grass_Dry"
    },
    {
      "x": -7,
      "y": 2,
      "z": -5,
      "name": "Soil_Dirt_Dry"
    },
    {
      "x": -7,
      "y": 3,
      "z": -5,
      "name": "Soil_Dirt_Dry"
    },
    {
      "x": -7,
      "y": 4,
      "z": -5,
      "name": "Soil_Dirt_Dry"
    },
    {
      "x": -7,
      "y": 5,
      "z": -5,
      "name": "Soil_Dirt_Dry"
    },
    {
      "x": -7,
      "y": 6,
      "z": -5,
      "name": "Soil_Dirt_Dry"
    },
    {
      "x": -7,
      "y": 7,
      "z": -5,
      "name": "Soil_Dirt_Dry"
    },
    {
      "x": -7,
      "y": 8,
      "z": -5,
      "name": "Soil_Dirt_Dry"
    },
    {
      "x": -7,
      "y": 9,
      "z": -5,
      "name": "Soil_Dirt_Dry"
    },
    {
      "x": -7,
      "y": 10,
      "z": -5,
      "name": "Soil_Dirt_Dry"
    },
    {
      "x": -7,
      "y": 11,
      "z": -5,
      "name": "Soil_Grass_Dry"
    },
    {
      "x": -7,
      "y": 2,
      "z": -4,
      "name": "Soil_Dirt_Dry"
    },
    {
      "x": -7,
      "y": 3,
      "z": -4,
      "name": "Soil_Dirt_Dry"
    },
    {
      "x": -7,
      "y": 4,
      "z": -4,
      "name": "Soil_Dirt_Dry"
    },
    {
      "x": -7,
      "y": 5,
      "z": -4,
      "name": "Soil_Dirt_Dry"
    },
    {
      "x": -7,
      "y": 6,
      "z": -4,
      "name": "Soil_Dirt_Dry"
    },
    {
      "x": -7,
      "y": 7,
      "z": -4,
      "name": "Soil_Dirt_Dry"
    },
    {
      "x": -7,
      "y": 8,
      "z": -4,
      "name": "Soil_Dirt_Dry"
    },
    {
      "x": -7,
      "y": 9,
      "z": -4,
      "name": "Soil_Dirt_Dry"
    },
    {
      "x": -7,
      "y": 10,
      "z": -4,
      "name": "Soil_Dirt_Dry"
    },
    {
      "x": -7,
      "y": 11,
      "z": -4,
      "name": "Soil_Grass_Dry"
    },
    {
      "x": -7,
      "y": 2,
      "z": -3,
      "name": "Soil_Dirt_Dry"
    },
    {
      "x": -7,
      "y": 3,
      "z": -3,
      "name": "Soil_Dirt_Dry"
    },
    {
      "x": -7,
      "y": 4,
      "z": -3,
      "name": "Soil_Dirt_Dry"
    },
    {
      "x": -7,
      "y": 5,
      "z": -3,
      "name": "Soil_Dirt_Dry"
    },
    {
      "x": -7,
      "y": 6,
      "z": -3,
      "name": "Soil_Dirt_Dry"
    },
    {
      "x": -7,
      "y": 7,
      "z": -3,
      "name": "Soil_Dirt_Dry"
    },
    {
      "x": -7,
      "y": 8,
      "z": -3,
      "name": "Soil_Dirt_Dry"
    },
    {
      "x": -7,
      "y": 9,
      "z": -3,
      "name": "Soil_Dirt_Dry"
    },
    {
      "x": -7,
      "y": 10,
      "z": -3,
      "name": "Soil_Dirt_Dry"
    },
    {
      "x": -7,
      "y": 11,
      "z": -3,
      "name": "Soil_Gravel_Sand"
    },
    {
      "x": -7,
      "y": 12,
      "z": -3,
      "name": "Soil_Gravel_Sand_Half"
    },
    {
      "x": -7,
      "y": 2,
      "z": -2,
      "name": "Soil_Dirt_Dry"
    },
    {
      "x": -7,
      "y": 3,
      "z": -2,
      "name": "Soil_Dirt_Dry"
    },
    {
      "x": -7,
      "y": 4,
      "z": -2,
      "name": "Soil_Dirt_Dry"
    },
    {
      "x": -7,
      "y": 5,
      "z": -2,
      "name": "Soil_Dirt_Dry"
    },
    {
      "x": -7,
      "y": 6,
      "z": -2,
      "name": "Soil_Dirt_Dry"
    },
    {
      "x": -7,
      "y": 7,
      "z": -2,
      "name": "Soil_Dirt_Dry"
    },
    {
      "x": -7,
      "y": 8,
      "z": -2,
      "name": "Soil_Dirt_Dry"
    },
    {
      "x": -7,
      "y": 9,
      "z": -2,
      "name": "Soil_Dirt_Dry"
    },
    {
      "x": -7,
      "y": 10,
      "z": -2,
      "name": "Soil_Dirt_Dry"
    },
    {
      "x": -7,
      "y": 11,
      "z": -2,
      "name": "Soil_Gravel_Sand"
    },
    {
      "x": -7,
      "y": 12,
      "z": -2,
      "name": "Soil_Gravel_Sand_Half"
    },
    {
      "x": -7,
      "y": 2,
      "z": -1,
      "name": "Soil_Dirt_Dry"
    },
    {
      "x": -7,
      "y": 3,
      "z": -1,
      "name": "Soil_Dirt_Dry"
    },
    {
      "x": -7,
      "y": 4,
      "z": -1,
      "name": "Soil_Dirt_Dry"
    },
    {
      "x": -7,
      "y": 5,
      "z": -1,
      "name": "Soil_Dirt_Dry"
    },
    {
      "x": -7,
      "y": 6,
      "z": -1,
      "name": "Soil_Dirt_Dry"
    },
    {
      "x": -7,
      "y": 7,
      "z": -1,
      "name": "Soil_Dirt_Dry"
    },
    {
      "x": -7,
      "y": 8,
      "z": -1,
      "name": "Soil_Dirt_Dry"
    },
    {
      "x": -7,
      "y": 9,
      "z": -1,
      "name": "Soil_Dirt_Dry"
    },
    {
      "x": -7,
      "y": 10,
      "z": -1,
      "name": "Soil_Dirt_Dry"
    },
    {
      "x": -7,
      "y": 11,
      "z": -1,
      "name": "Soil_Gravel_Sand"
    },
    {
      "x": -7,
      "y": 12,
      "z": -1,
      "name": "Soil_Gravel_Sand"
    },
    {
      "x": -7,
      "y": 2,
      "z": 0,
      "name": "Soil_Dirt_Dry"
    },
    {
      "x": -7,
      "y": 3,
      "z": 0,
      "name": "Soil_Dirt_Dry"
    },
    {
      "x": -7,
      "y": 4,
      "z": 0,
      "name": "Soil_Dirt_Dry"
    },
    {
      "x": -7,
      "y": 5,
      "z": 0,
      "name": "Soil_Dirt_Dry"
    },
    {
      "x": -7,
      "y": 6,
      "z": 0,
      "name": "Soil_Dirt_Dry"
    },
    {
      "x": -7,
      "y": 7,
      "z": 0,
      "name": "Soil_Dirt_Dry"
    },
    {
      "x": -7,
      "y": 8,
      "z": 0,
      "name": "Soil_Dirt_Dry"
    },
    {
      "x": -7,
      "y": 9,
      "z": 0,
      "name": "Soil_Dirt_Dry"
    },
    {
      "x": -7,
      "y": 10,
      "z": 0,
      "name": "Soil_Gravel_Sand"
    },
    {
      "x": -7,
      "y": 11,
      "z": 0,
      "name": "Soil_Gravel_Sand"
    },
    {
      "x": -7,
      "y": 12,
      "z": 0,
      "name": "Soil_Gravel_Sand"
    },
    {
      "x": -7,
      "y": 13,
      "z": 0,
      "name": "Empty"
    },
    {
      "x": -7,
      "y": 14,
      "z": 0,
      "name": "Empty"
    },
    {
      "x": -7,
      "y": 15,
      "z": 0,
      "name": "Empty"
    },
    {
      "x": -7,
      "y": 16,
      "z": 0,
      "name": "Empty"
    },
    {
      "x": -7,
      "y": 17,
      "z": 0,
      "name": "Empty"
    },
    {
      "x": -7,
      "y": 18,
      "z": 0,
      "name": "Empty"
    },
    {
      "x": -7,
      "y": 2,
      "z": 1,
      "name": "Soil_Dirt_Dry"
    },
    {
      "x": -7,
      "y": 3,
      "z": 1,
      "name": "Soil_Dirt_Dry"
    },
    {
      "x": -7,
      "y": 4,
      "z": 1,
      "name": "Soil_Dirt_Dry"
    },
    {
      "x": -7,
      "y": 5,
      "z": 1,
      "name": "Soil_Dirt_Dry"
    },
    {
      "x": -7,
      "y": 6,
      "z": 1,
      "name": "Soil_Dirt_Dry"
    },
    {
      "x": -7,
      "y": 7,
      "z": 1,
      "name": "Soil_Dirt_Dry"
    },
    {
      "x": -7,
      "y": 8,
      "z": 1,
      "name": "Soil_Dirt_Dry"
    },
    {
      "x": -7,
      "y": 9,
      "z": 1,
      "name": "Soil_Dirt_Dry"
    },
    {
      "x": -7,
      "y": 10,
      "z": 1,
      "name": "Soil_Gravel_Sand"
    },
    {
      "x": -7,
      "y": 11,
      "z": 1,
      "name": "Soil_Gravel_Sand"
    },
    {
      "x": -7,
      "y": 12,
      "z": 1,
      "name": "Soil_Gravel_Sand"
    },
    {
      "x": -7,
      "y": 13,
      "z": 1,
      "name": "Empty"
    },
    {
      "x": -7,
      "y": 14,
      "z": 1,
      "name": "Empty"
    },
    {
      "x": -7,
      "y": 15,
      "z": 1,
      "name": "Empty"
    },
    {
      "x": -7,
      "y": 16,
      "z": 1,
      "name": "Empty"
    },
    {
      "x": -7,
      "y": 17,
      "z": 1,
      "name": "Empty"
    },
    {
      "x": -7,
      "y": 18,
      "z": 1,
      "name": "Empty"
    },
    {
      "x": -7,
      "y": 2,
      "z": 2,
      "name": "Soil_Dirt_Dry"
    },
    {
      "x": -7,
      "y": 3,
      "z": 2,
      "name": "Soil_Dirt_Dry"
    },
    {
      "x": -7,
      "y": 4,
      "z": 2,
      "name": "Soil_Dirt_Dry"
    },
    {
      "x": -7,
      "y": 5,
      "z": 2,
      "name": "Soil_Dirt_Dry"
    },
    {
      "x": -7,
      "y": 6,
      "z": 2,
      "name": "Soil_Dirt_Dry"
    },
    {
      "x": -7,
      "y": 7,
      "z": 2,
      "name": "Soil_Dirt_Dry"
    },
    {
      "x": -7,
      "y": 8,
      "z": 2,
      "name": "Soil_Dirt_Dry"
    },
    {
      "x": -7,
      "y": 9,
      "z": 2,
      "name": "Soil_Dirt_Dry"
    },
    {
      "x": -7,
      "y": 10,
      "z": 2,
      "name": "Soil_Gravel_Sand"
    },
    {
      "x": -7,
      "y": 11,
      "z": 2,
      "name": "Soil_Gravel_Sand"
    },
    {
      "x": -7,
      "y": 12,
      "z": 2,
      "name": "Soil_Gravel_Sand"
    },
    {
      "x": -7,
      "y": 13,
      "z": 2,
      "name": "Empty"
    },
    {
      "x": -7,
      "y": 14,
      "z": 2,
      "name": "Empty"
    },
    {
      "x": -7,
      "y": 15,
      "z": 2,
      "name": "Empty"
    },
    {
      "x": -7,
      "y": 16,
      "z": 2,
      "name": "Empty"
    },
    {
      "x": -7,
      "y": 17,
      "z": 2,
      "name": "Empty"
    },
    {
      "x": -7,
      "y": 18,
      "z": 2,
      "name": "Empty"
    },
    {
      "x": -7,
      "y": 2,
      "z": 3,
      "name": "Soil_Dirt_Dry"
    },
    {
      "x": -7,
      "y": 3,
      "z": 3,
      "name": "Soil_Dirt_Dry"
    },
    {
      "x": -7,
      "y": 4,
      "z": 3,
      "name": "Soil_Dirt_Dry"
    },
    {
      "x": -7,
      "y": 5,
      "z": 3,
      "name": "Soil_Dirt_Dry"
    },
    {
      "x": -7,
      "y": 6,
      "z": 3,
      "name": "Soil_Dirt_Dry"
    },
    {
      "x": -7,
      "y": 7,
      "z": 3,
      "name": "Soil_Dirt_Dry"
    },
    {
      "x": -7,
      "y": 8,
      "z": 3,
      "name": "Soil_Dirt_Dry"
    },
    {
      "x": -7,
      "y": 9,
      "z": 3,
      "name": "Soil_Dirt_Dry"
    },
    {
      "x": -7,
      "y": 10,
      "z": 3,
      "name": "Soil_Gravel_Sand"
    },
    {
      "x": -7,
      "y": 11,
      "z": 3,
      "name": "Soil_Gravel_Sand"
    },
    {
      "x": -7,
      "y": 12,
      "z": 3,
      "name": "Soil_Gravel_Sand"
    },
    {
      "x": -7,
      "y": 13,
      "z": 3,
      "name": "Empty"
    },
    {
      "x": -7,
      "y": 14,
      "z": 3,
      "name": "Empty"
    },
    {
      "x": -7,
      "y": 15,
      "z": 3,
      "name": "Empty"
    },
    {
      "x": -7,
      "y": 16,
      "z": 3,
      "name": "Empty"
    },
    {
      "x": -7,
      "y": 17,
      "z": 3,
      "name": "Empty"
    },
    {
      "x": -7,
      "y": 18,
      "z": 3,
      "name": "Empty"
    },
    {
      "x": -7,
      "y": 2,
      "z": 4,
      "name": "Soil_Dirt_Dry"
    },
    {
      "x": -7,
      "y": 3,
      "z": 4,
      "name": "Soil_Dirt_Dry"
    },
    {
      "x": -7,
      "y": 4,
      "z": 4,
      "name": "Soil_Dirt_Dry"
    },
    {
      "x": -7,
      "y": 5,
      "z": 4,
      "name": "Soil_Dirt_Dry"
    },
    {
      "x": -7,
      "y": 6,
      "z": 4,
      "name": "Soil_Dirt_Dry"
    },
    {
      "x": -7,
      "y": 7,
      "z": 4,
      "name": "Soil_Dirt_Dry"
    },
    {
      "x": -7,
      "y": 8,
      "z": 4,
      "name": "Soil_Dirt_Dry"
    },
    {
      "x": -7,
      "y": 9,
      "z": 4,
      "name": "Soil_Dirt_Dry"
    },
    {
      "x": -7,
      "y": 10,
      "z": 4,
      "name": "Soil_Dirt_Dry"
    },
    {
      "x": -7,
      "y": 11,
      "z": 4,
      "name": "Soil_Gravel_Sand"
    },
    {
      "x": -7,
      "y": 12,
      "z": 4,
      "name": "Soil_Gravel_Sand_Half"
    },
    {
      "x": -7,
      "y": 13,
      "z": 4,
      "name": "Empty"
    },
    {
      "x": -7,
      "y": 14,
      "z": 4,
      "name": "Empty"
    },
    {
      "x": -7,
      "y": 15,
      "z": 4,
      "name": "Empty"
    },
    {
      "x": -7,
      "y": 16,
      "z": 4,
      "name": "Empty"
    },
    {
      "x": -7,
      "y": 17,
      "z": 4,
      "name": "Empty"
    },
    {
      "x": -7,
      "y": 18,
      "z": 4,
      "name": "Empty"
    },
    {
      "x": -7,
      "y": 2,
      "z": 5,
      "name": "Soil_Dirt_Dry"
    },
    {
      "x": -7,
      "y": 3,
      "z": 5,
      "name": "Soil_Dirt_Dry"
    },
    {
      "x": -7,
      "y": 4,
      "z": 5,
      "name": "Soil_Dirt_Dry"
    },
    {
      "x": -7,
      "y": 5,
      "z": 5,
      "name": "Soil_Dirt_Dry"
    },
    {
      "x": -7,
      "y": 6,
      "z": 5,
      "name": "Soil_Dirt_Dry"
    },
    {
      "x": -7,
      "y": 7,
      "z": 5,
      "name": "Soil_Dirt_Dry"
    },
    {
      "x": -7,
      "y": 8,
      "z": 5,
      "name": "Soil_Dirt_Dry"
    },
    {
      "x": -7,
      "y": 9,
      "z": 5,
      "name": "Soil_Dirt_Dry"
    },
    {
      "x": -7,
      "y": 10,
      "z": 5,
      "name": "Soil_Dirt_Dry"
    },
    {
      "x": -7,
      "y": 11,
      "z": 5,
      "name": "Soil_Dirt_Dry"
    },
    {
      "x": -7,
      "y": 12,
      "z": 5,
      "name": "Soil_Gravel_Sand_Half"
    },
    {
      "x": -7,
      "y": 2,
      "z": 6,
      "name": "Soil_Dirt_Dry"
    },
    {
      "x": -7,
      "y": 3,
      "z": 6,
      "name": "Soil_Dirt_Dry"
    },
    {
      "x": -7,
      "y": 4,
      "z": 6,
      "name": "Soil_Dirt_Dry"
    },
    {
      "x": -7,
      "y": 5,
      "z": 6,
      "name": "Soil_Dirt_Dry"
    },
    {
      "x": -7,
      "y": 6,
      "z": 6,
      "name": "Soil_Dirt_Dry"
    },
    {
      "x": -7,
      "y": 7,
      "z": 6,
      "name": "Soil_Dirt_Dry"
    },
    {
      "x": -7,
      "y": 8,
      "z": 6,
      "name": "Soil_Dirt_Dry"
    },
    {
      "x": -7,
      "y": 9,
      "z": 6,
      "name": "Soil_Dirt_Dry"
    },
    {
      "x": -7,
      "y": 10,
      "z": 6,
      "name": "Soil_Dirt_Dry"
    },
    {
      "x": -7,
      "y": 11,
      "z": 6,
      "name": "Soil_Grass_Dry"
    },
    {
      "x": -7,
      "y": 2,
      "z": 7,
      "name": "Soil_Clay"
    },
    {
      "x": -7,
      "y": 3,
      "z": 7,
      "name": "Soil_Clay"
    },
    {
      "x": -7,
      "y": 4,
      "z": 7,
      "name": "Soil_Clay"
    },
    {
      "x": -7,
      "y": 5,
      "z": 7,
      "name": "Soil_Clay"
    },
    {
      "x": -7,
      "y": 6,
      "z": 7,
      "name": "Soil_Clay"
    },
    {
      "x": -7,
      "y": 7,
      "z": 7,
      "name": "Soil_Clay"
    },
    {
      "x": -7,
      "y": 8,
      "z": 7,
      "name": "Soil_Clay"
    },
    {
      "x": -7,
      "y": 9,
      "z": 7,
      "name": "Soil_Clay"
    },
    {
      "x": -7,
      "y": 10,
      "z": 7,
      "name": "Rock_Sandstone_Cobble"
    },
    {
      "x": -7,
      "y": 11,
      "z": 7,
      "name": "Rock_Sandstone_Cobble"
    },
    {
      "x": -7,
      "y": 12,
      "z": 7,
      "name": "Rock_Sandstone_Cobble"
    },
    {
      "x": -7,
      "y": 13,
      "z": 7,
      "name": "Rock_Sandstone_Cobble"
    },
    {
      "x": -7,
      "y": 2,
      "z": 8,
      "name": "Soil_Clay"
    },
    {
      "x": -7,
      "y": 3,
      "z": 8,
      "name": "Soil_Clay"
    },
    {
      "x": -7,
      "y": 4,
      "z": 8,
      "name": "Soil_Clay"
    },
    {
      "x": -7,
      "y": 5,
      "z": 8,
      "name": "Soil_Clay"
    },
    {
      "x": -7,
      "y": 6,
      "z": 8,
      "name": "Soil_Clay"
    },
    {
      "x": -7,
      "y": 7,
      "z": 8,
      "name": "Soil_Clay"
    },
    {
      "x": -7,
      "y": 8,
      "z": 8,
      "name": "Soil_Clay"
    },
    {
      "x": -7,
      "y": 9,
      "z": 8,
      "name": "Soil_Clay"
    },
    {
      "x": -7,
      "y": 10,
      "z": 8,
      "name": "Soil_Grass_Dry"
    },
    {
      "x": -7,
      "y": 4,
      "z": 9,
      "name": "Soil_Dirt_Dry"
    },
    {
      "x": -7,
      "y": 5,
      "z": 9,
      "name": "Soil_Dirt_Dry"
    },
    {
      "x": -7,
      "y": 6,
      "z": 9,
      "name": "Soil_Dirt_Dry"
    },
    {
      "x": -7,
      "y": 7,
      "z": 9,
      "name": "Soil_Dirt_Dry"
    },
    {
      "x": -7,
      "y": 8,
      "z": 9,
      "name": "Soil_Dirt_Dry"
    },
    {
      "x": -7,
      "y": 9,
      "z": 9,
      "name": "Soil_Grass_Dry"
    },
    {
      "x": -6,
      "y": 2,
      "z": -6,
      "name": "Soil_Dirt_Dry"
    },
    {
      "x": -6,
      "y": 3,
      "z": -6,
      "name": "Soil_Dirt_Dry"
    },
    {
      "x": -6,
      "y": 4,
      "z": -6,
      "name": "Soil_Dirt_Dry"
    },
    {
      "x": -6,
      "y": 5,
      "z": -6,
      "name": "Soil_Dirt_Dry"
    },
    {
      "x": -6,
      "y": 6,
      "z": -6,
      "name": "Soil_Dirt_Dry"
    },
    {
      "x": -6,
      "y": 7,
      "z": -6,
      "name": "Soil_Dirt_Dry"
    },
    {
      "x": -6,
      "y": 8,
      "z": -6,
      "name": "Soil_Dirt_Dry"
    },
    {
      "x": -6,
      "y": 9,
      "z": -6,
      "name": "Soil_Dirt_Dry"
    },
    {
      "x": -6,
      "y": 10,
      "z": -6,
      "name": "Soil_Dirt_Dry"
    },
    {
      "x": -6,
      "y": 11,
      "z": -6,
      "name": "Soil_Grass_Dry"
    },
    {
      "x": -6,
      "y": 2,
      "z": -5,
      "name": "Soil_Dirt_Dry"
    },
    {
      "x": -6,
      "y": 3,
      "z": -5,
      "name": "Soil_Dirt_Dry"
    },
    {
      "x": -6,
      "y": 4,
      "z": -5,
      "name": "Soil_Dirt_Dry"
    },
    {
      "x": -6,
      "y": 5,
      "z": -5,
      "name": "Soil_Dirt_Dry"
    },
    {
      "x": -6,
      "y": 6,
      "z": -5,
      "name": "Soil_Dirt_Dry"
    },
    {
      "x": -6,
      "y": 7,
      "z": -5,
      "name": "Soil_Dirt_Dry"
    },
    {
      "x": -6,
      "y": 8,
      "z": -5,
      "name": "Soil_Dirt_Dry"
    },
    {
      "x": -6,
      "y": 9,
      "z": -5,
      "name": "Soil_Dirt_Dry"
    },
    {
      "x": -6,
      "y": 10,
      "z": -5,
      "name": "Soil_Dirt_Dry"
    },
    {
      "x": -6,
      "y": 11,
      "z": -5,
      "name": "Soil_Dirt_Dry"
    },
    {
      "x": -6,
      "y": 12,
      "z": -5,
      "name": "Soil_Grass_Dry"
    },
    {
      "x": -6,
      "y": 2,
      "z": -4,
      "name": "Soil_Dirt_Dry"
    },
    {
      "x": -6,
      "y": 3,
      "z": -4,
      "name": "Soil_Dirt_Dry"
    },
    {
      "x": -6,
      "y": 4,
      "z": -4,
      "name": "Soil_Dirt_Dry"
    },
    {
      "x": -6,
      "y": 5,
      "z": -4,
      "name": "Soil_Dirt_Dry"
    },
    {
      "x": -6,
      "y": 6,
      "z": -4,
      "name": "Soil_Dirt_Dry"
    },
    {
      "x": -6,
      "y": 7,
      "z": -4,
      "name": "Soil_Dirt_Dry"
    },
    {
      "x": -6,
      "y": 8,
      "z": -4,
      "name": "Soil_Dirt_Dry"
    },
    {
      "x": -6,
      "y": 9,
      "z": -4,
      "name": "Soil_Dirt_Dry"
    },
    {
      "x": -6,
      "y": 10,
      "z": -4,
      "name": "Soil_Dirt_Dry"
    },
    {
      "x": -6,
      "y": 11,
      "z": -4,
      "name": "Soil_Dirt_Dry"
    },
    {
      "x": -6,
      "y": 12,
      "z": -4,
      "name": "Soil_Grass_Dry"
    },
    {
      "x": -6,
      "y": 2,
      "z": -3,
      "name": "Soil_Dirt_Dry"
    },
    {
      "x": -6,
      "y": 3,
      "z": -3,
      "name": "Soil_Dirt_Dry"
    },
    {
      "x": -6,
      "y": 4,
      "z": -3,
      "name": "Soil_Dirt_Dry"
    },
    {
      "x": -6,
      "y": 5,
      "z": -3,
      "name": "Soil_Dirt_Dry"
    },
    {
      "x": -6,
      "y": 6,
      "z": -3,
      "name": "Soil_Dirt_Dry"
    },
    {
      "x": -6,
      "y": 7,
      "z": -3,
      "name": "Soil_Dirt_Dry"
    },
    {
      "x": -6,
      "y": 8,
      "z": -3,
      "name": "Soil_Dirt_Dry"
    },
    {
      "x": -6,
      "y": 9,
      "z": -3,
      "name": "Soil_Dirt_Dry"
    },
    {
      "x": -6,
      "y": 10,
      "z": -3,
      "name": "Soil_Dirt_Dry"
    },
    {
      "x": -6,
      "y": 11,
      "z": -3,
      "name": "Soil_Dirt_Dry"
    },
    {
      "x": -6,
      "y": 12,
      "z": -3,
      "name": "Soil_Gravel_Sand"
    },
    {
      "x": -6,
      "y": 2,
      "z": -2,
      "name": "Soil_Dirt_Dry"
    },
    {
      "x": -6,
      "y": 3,
      "z": -2,
      "name": "Soil_Dirt_Dry"
    },
    {
      "x": -6,
      "y": 4,
      "z": -2,
      "name": "Soil_Dirt_Dry"
    },
    {
      "x": -6,
      "y": 5,
      "z": -2,
      "name": "Soil_Dirt_Dry"
    },
    {
      "x": -6,
      "y": 6,
      "z": -2,
      "name": "Soil_Dirt_Dry"
    },
    {
      "x": -6,
      "y": 7,
      "z": -2,
      "name": "Soil_Dirt_Dry"
    },
    {
      "x": -6,
      "y": 8,
      "z": -2,
      "name": "Soil_Dirt_Dry"
    },
    {
      "x": -6,
      "y": 9,
      "z": -2,
      "name": "Soil_Dirt_Dry"
    },
    {
      "x": -6,
      "y": 10,
      "z": -2,
      "name": "Soil_Dirt_Dry"
    },
    {
      "x": -6,
      "y": 11,
      "z": -2,
      "name": "Soil_Dirt_Dry"
    },
    {
      "x": -6,
      "y": 12,
      "z": -2,
      "name": "Soil_Gravel_Sand"
    },
    {
      "x": -6,
      "y": 13,
      "z": -2,
      "name": "Empty"
    },
    {
      "x": -6,
      "y": 14,
      "z": -2,
      "name": "Empty"
    },
    {
      "x": -6,
      "y": 15,
      "z": -2,
      "name": "Empty"
    },
    {
      "x": -6,
      "y": 16,
      "z": -2,
      "name": "Empty"
    },
    {
      "x": -6,
      "y": 17,
      "z": -2,
      "name": "Empty"
    },
    {
      "x": -6,
      "y": 18,
      "z": -2,
      "name": "Empty"
    },
    {
      "x": -6,
      "y": 2,
      "z": -1,
      "name": "Soil_Dirt_Dry"
    },
    {
      "x": -6,
      "y": 3,
      "z": -1,
      "name": "Soil_Dirt_Dry"
    },
    {
      "x": -6,
      "y": 4,
      "z": -1,
      "name": "Soil_Dirt_Dry"
    },
    {
      "x": -6,
      "y": 5,
      "z": -1,
      "name": "Soil_Dirt_Dry"
    },
    {
      "x": -6,
      "y": 6,
      "z": -1,
      "name": "Soil_Dirt_Dry"
    },
    {
      "x": -6,
      "y": 7,
      "z": -1,
      "name": "Soil_Dirt_Dry"
    },
    {
      "x": -6,
      "y": 8,
      "z": -1,
      "name": "Soil_Dirt_Dry"
    },
    {
      "x": -6,
      "y": 9,
      "z": -1,
      "name": "Soil_Dirt_Dry"
    },
    {
      "x": -6,
      "y": 10,
      "z": -1,
      "name": "Soil_Dirt_Dry"
    },
    {
      "x": -6,
      "y": 11,
      "z": -1,
      "name": "Soil_Dirt_Dry"
    },
    {
      "x": -6,
      "y": 12,
      "z": -1,
      "name": "Soil_Gravel_Sand"
    },
    {
      "x": -6,
      "y": 13,
      "z": -1,
      "name": "Empty"
    },
    {
      "x": -6,
      "y": 14,
      "z": -1,
      "name": "Empty"
    },
    {
      "x": -6,
      "y": 15,
      "z": -1,
      "name": "Empty"
    },
    {
      "x": -6,
      "y": 16,
      "z": -1,
      "name": "Empty"
    },
    {
      "x": -6,
      "y": 17,
      "z": -1,
      "name": "Empty"
    },
    {
      "x": -6,
      "y": 18,
      "z": -1,
      "name": "Empty"
    },
    {
      "x": -6,
      "y": 2,
      "z": 0,
      "name": "Soil_Dirt_Dry"
    },
    {
      "x": -6,
      "y": 3,
      "z": 0,
      "name": "Soil_Dirt_Dry"
    },
    {
      "x": -6,
      "y": 4,
      "z": 0,
      "name": "Soil_Dirt_Dry"
    },
    {
      "x": -6,
      "y": 5,
      "z": 0,
      "name": "Soil_Dirt_Dry"
    },
    {
      "x": -6,
      "y": 6,
      "z": 0,
      "name": "Soil_Dirt_Dry"
    },
    {
      "x": -6,
      "y": 7,
      "z": 0,
      "name": "Soil_Dirt_Dry"
    },
    {
      "x": -6,
      "y": 8,
      "z": 0,
      "name": "Soil_Dirt_Dry"
    },
    {
      "x": -6,
      "y": 9,
      "z": 0,
      "name": "Soil_Dirt_Dry"
    },
    {
      "x": -6,
      "y": 10,
      "z": 0,
      "name": "Soil_Dirt_Dry"
    },
    {
      "x": -6,
      "y": 11,
      "z": 0,
      "name": "Soil_Gravel_Sand"
    },
    {
      "x": -6,
      "y": 12,
      "z": 0,
      "name": "Soil_Gravel_Sand"
    },
    {
      "x": -6,
      "y": 13,
      "z": 0,
      "name": "Empty"
    },
    {
      "x": -6,
      "y": 14,
      "z": 0,
      "name": "Empty"
    },
    {
      "x": -6,
      "y": 15,
      "z": 0,
      "name": "Empty"
    },
    {
      "x": -6,
      "y": 16,
      "z": 0,
      "name": "Empty"
    },
    {
      "x": -6,
      "y": 17,
      "z": 0,
      "name": "Empty"
    },
    {
      "x": -6,
      "y": 18,
      "z": 0,
      "name": "Empty"
    },
    {
      "x": -6,
      "y": 2,
      "z": 1,
      "name": "Soil_Dirt_Dry"
    },
    {
      "x": -6,
      "y": 3,
      "z": 1,
      "name": "Soil_Dirt_Dry"
    },
    {
      "x": -6,
      "y": 4,
      "z": 1,
      "name": "Soil_Dirt_Dry"
    },
    {
      "x": -6,
      "y": 5,
      "z": 1,
      "name": "Soil_Dirt_Dry"
    },
    {
      "x": -6,
      "y": 6,
      "z": 1,
      "name": "Soil_Dirt_Dry"
    },
    {
      "x": -6,
      "y": 7,
      "z": 1,
      "name": "Soil_Dirt_Dry"
    },
    {
      "x": -6,
      "y": 8,
      "z": 1,
      "name": "Soil_Dirt_Dry"
    },
    {
      "x": -6,
      "y": 9,
      "z": 1,
      "name": "Soil_Dirt_Dry"
    },
    {
      "x": -6,
      "y": 10,
      "z": 1,
      "name": "Soil_Gravel_Sand"
    },
    {
      "x": -6,
      "y": 11,
      "z": 1,
      "name": "Soil_Gravel_Sand"
    },
    {
      "x": -6,
      "y": 12,
      "z": 1,
      "name": "Soil_Gravel_Sand"
    },
    {
      "x": -6,
      "y": 13,
      "z": 1,
      "name": "Empty"
    },
    {
      "x": -6,
      "y": 14,
      "z": 1,
      "name": "Empty"
    },
    {
      "x": -6,
      "y": 15,
      "z": 1,
      "name": "Empty"
    },
    {
      "x": -6,
      "y": 16,
      "z": 1,
      "name": "Empty"
    },
    {
      "x": -6,
      "y": 17,
      "z": 1,
      "name": "Empty"
    },
    {
      "x": -6,
      "y": 18,
      "z": 1,
      "name": "Empty"
    },
    {
      "x": -6,
      "y": 2,
      "z": 2,
      "name": "Soil_Dirt_Dry"
    },
    {
      "x": -6,
      "y": 3,
      "z": 2,
      "name": "Soil_Dirt_Dry"
    },
    {
      "x": -6,
      "y": 4,
      "z": 2,
      "name": "Soil_Dirt_Dry"
    },
    {
      "x": -6,
      "y": 5,
      "z": 2,
      "name": "Soil_Dirt_Dry"
    },
    {
      "x": -6,
      "y": 6,
      "z": 2,
      "name": "Soil_Dirt_Dry"
    },
    {
      "x": -6,
      "y": 7,
      "z": 2,
      "name": "Soil_Dirt_Dry"
    },
    {
      "x": -6,
      "y": 8,
      "z": 2,
      "name": "Soil_Dirt_Dry"
    },
    {
      "x": -6,
      "y": 9,
      "z": 2,
      "name": "Soil_Dirt_Dry"
    },
    {
      "x": -6,
      "y": 10,
      "z": 2,
      "name": "Soil_Dirt_Dry"
    },
    {
      "x": -6,
      "y": 11,
      "z": 2,
      "name": "Soil_Gravel_Sand"
    },
    {
      "x": -6,
      "y": 12,
      "z": 2,
      "name": "Soil_Gravel_Sand"
    },
    {
      "x": -6,
      "y": 13,
      "z": 2,
      "name": "Empty"
    },
    {
      "x": -6,
      "y": 14,
      "z": 2,
      "name": "Empty"
    },
    {
      "x": -6,
      "y": 15,
      "z": 2,
      "name": "Empty"
    },
    {
      "x": -6,
      "y": 16,
      "z": 2,
      "name": "Empty"
    },
    {
      "x": -6,
      "y": 17,
      "z": 2,
      "name": "Empty"
    },
    {
      "x": -6,
      "y": 18,
      "z": 2,
      "name": "Empty"
    },
    {
      "x": -6,
      "y": 2,
      "z": 3,
      "name": "Soil_Dirt_Dry"
    },
    {
      "x": -6,
      "y": 3,
      "z": 3,
      "name": "Soil_Dirt_Dry"
    },
    {
      "x": -6,
      "y": 4,
      "z": 3,
      "name": "Soil_Dirt_Dry"
    },
    {
      "x": -6,
      "y": 5,
      "z": 3,
      "name": "Soil_Dirt_Dry"
    },
    {
      "x": -6,
      "y": 6,
      "z": 3,
      "name": "Soil_Dirt_Dry"
    },
    {
      "x": -6,
      "y": 7,
      "z": 3,
      "name": "Soil_Dirt_Dry"
    },
    {
      "x": -6,
      "y": 8,
      "z": 3,
      "name": "Soil_Dirt_Dry"
    },
    {
      "x": -6,
      "y": 9,
      "z": 3,
      "name": "Soil_Dirt_Dry"
    },
    {
      "x": -6,
      "y": 10,
      "z": 3,
      "name": "Soil_Gravel_Sand"
    },
    {
      "x": -6,
      "y": 11,
      "z": 3,
      "name": "Soil_Gravel_Sand"
    },
    {
      "x": -6,
      "y": 12,
      "z": 3,
      "name": "Soil_Gravel_Sand"
    },
    {
      "x": -6,
      "y": 13,
      "z": 3,
      "name": "Rubble_Sandstone"
    },
    {
      "x": -6,
      "y": 14,
      "z": 3,
      "name": "Empty"
    },
    {
      "x": -6,
      "y": 15,
      "z": 3,
      "name": "Empty"
    },
    {
      "x": -6,
      "y": 16,
      "z": 3,
      "name": "Empty"
    },
    {
      "x": -6,
      "y": 17,
      "z": 3,
      "name": "Empty"
    },
    {
      "x": -6,
      "y": 18,
      "z": 3,
      "name": "Empty"
    },
    {
      "x": -6,
      "y": 2,
      "z": 4,
      "name": "Soil_Dirt_Dry"
    },
    {
      "x": -6,
      "y": 3,
      "z": 4,
      "name": "Soil_Dirt_Dry"
    },
    {
      "x": -6,
      "y": 4,
      "z": 4,
      "name": "Soil_Dirt_Dry"
    },
    {
      "x": -6,
      "y": 5,
      "z": 4,
      "name": "Soil_Dirt_Dry"
    },
    {
      "x": -6,
      "y": 6,
      "z": 4,
      "name": "Soil_Dirt_Dry"
    },
    {
      "x": -6,
      "y": 7,
      "z": 4,
      "name": "Soil_Dirt_Dry"
    },
    {
      "x": -6,
      "y": 8,
      "z": 4,
      "name": "Soil_Dirt_Dry"
    },
    {
      "x": -6,
      "y": 9,
      "z": 4,
      "name": "Soil_Dirt_Dry"
    },
    {
      "x": -6,
      "y": 10,
      "z": 4,
      "name": "Soil_Dirt_Dry"
    },
    {
      "x": -6,
      "y": 11,
      "z": 4,
      "name": "Soil_Gravel_Sand"
    },
    {
      "x": -6,
      "y": 12,
      "z": 4,
      "name": "Soil_Gravel_Sand"
    },
    {
      "x": -6,
      "y": 13,
      "z": 4,
      "name": "Empty"
    },
    {
      "x": -6,
      "y": 14,
      "z": 4,
      "name": "Empty"
    },
    {
      "x": -6,
      "y": 15,
      "z": 4,
      "name": "Empty"
    },
    {
      "x": -6,
      "y": 16,
      "z": 4,
      "name": "Empty"
    },
    {
      "x": -6,
      "y": 17,
      "z": 4,
      "name": "Empty"
    },
    {
      "x": -6,
      "y": 18,
      "z": 4,
      "name": "Empty"
    },
    {
      "x": -6,
      "y": 2,
      "z": 5,
      "name": "Soil_Dirt_Dry"
    },
    {
      "x": -6,
      "y": 3,
      "z": 5,
      "name": "Soil_Dirt_Dry"
    },
    {
      "x": -6,
      "y": 4,
      "z": 5,
      "name": "Soil_Dirt_Dry"
    },
    {
      "x": -6,
      "y": 5,
      "z": 5,
      "name": "Soil_Dirt_Dry"
    },
    {
      "x": -6,
      "y": 6,
      "z": 5,
      "name": "Soil_Dirt_Dry"
    },
    {
      "x": -6,
      "y": 7,
      "z": 5,
      "name": "Soil_Dirt_Dry"
    },
    {
      "x": -6,
      "y": 8,
      "z": 5,
      "name": "Soil_Dirt_Dry"
    },
    {
      "x": -6,
      "y": 9,
      "z": 5,
      "name": "Soil_Dirt_Dry"
    },
    {
      "x": -6,
      "y": 10,
      "z": 5,
      "name": "Soil_Dirt_Dry"
    },
    {
      "x": -6,
      "y": 11,
      "z": 5,
      "name": "Soil_Dirt_Dry"
    },
    {
      "x": -6,
      "y": 12,
      "z": 5,
      "name": "Soil_Gravel_Sand"
    },
    {
      "x": -6,
      "y": 13,
      "z": 5,
      "name": "Empty"
    },
    {
      "x": -6,
      "y": 14,
      "z": 5,
      "name": "Empty"
    },
    {
      "x": -6,
      "y": 15,
      "z": 5,
      "name": "Empty"
    },
    {
      "x": -6,
      "y": 16,
      "z": 5,
      "name": "Empty"
    },
    {
      "x": -6,
      "y": 17,
      "z": 5,
      "name": "Empty"
    },
    {
      "x": -6,
      "y": 18,
      "z": 5,
      "name": "Empty"
    },
    {
      "x": -6,
      "y": 2,
      "z": 6,
      "name": "Soil_Dirt_Dry"
    },
    {
      "x": -6,
      "y": 3,
      "z": 6,
      "name": "Soil_Dirt_Dry"
    },
    {
      "x": -6,
      "y": 4,
      "z": 6,
      "name": "Soil_Dirt_Dry"
    },
    {
      "x": -6,
      "y": 5,
      "z": 6,
      "name": "Soil_Dirt_Dry"
    },
    {
      "x": -6,
      "y": 6,
      "z": 6,
      "name": "Soil_Dirt_Dry"
    },
    {
      "x": -6,
      "y": 7,
      "z": 6,
      "name": "Soil_Dirt_Dry"
    },
    {
      "x": -6,
      "y": 8,
      "z": 6,
      "name": "Soil_Dirt_Dry"
    },
    {
      "x": -6,
      "y": 9,
      "z": 6,
      "name": "Soil_Dirt_Dry"
    },
    {
      "x": -6,
      "y": 10,
      "z": 6,
      "name": "Soil_Dirt_Dry"
    },
    {
      "x": -6,
      "y": 11,
      "z": 6,
      "name": "Soil_Dirt_Dry"
    },
    {
      "x": -6,
      "y": 12,
      "z": 6,
      "name": "Soil_Grass_Dry"
    },
    {
      "x": -6,
      "y": 13,
      "z": 6,
      "name": "Empty"
    },
    {
      "x": -6,
      "y": 14,
      "z": 6,
      "name": "Empty"
    },
    {
      "x": -6,
      "y": 15,
      "z": 6,
      "name": "Empty"
    },
    {
      "x": -6,
      "y": 16,
      "z": 6,
      "name": "Empty"
    },
    {
      "x": -6,
      "y": 17,
      "z": 6,
      "name": "Empty"
    },
    {
      "x": -6,
      "y": 18,
      "z": 6,
      "name": "Empty"
    },
    {
      "x": -6,
      "y": 2,
      "z": 7,
      "name": "Soil_Dirt_Dry"
    },
    {
      "x": -6,
      "y": 3,
      "z": 7,
      "name": "Soil_Dirt_Dry"
    },
    {
      "x": -6,
      "y": 4,
      "z": 7,
      "name": "Soil_Dirt_Dry"
    },
    {
      "x": -6,
      "y": 5,
      "z": 7,
      "name": "Soil_Dirt_Dry"
    },
    {
      "x": -6,
      "y": 6,
      "z": 7,
      "name": "Soil_Dirt_Dry"
    },
    {
      "x": -6,
      "y": 7,
      "z": 7,
      "name": "Soil_Dirt_Dry"
    },
    {
      "x": -6,
      "y": 8,
      "z": 7,
      "name": "Soil_Dirt_Dry"
    },
    {
      "x": -6,
      "y": 9,
      "z": 7,
      "name": "Soil_Dirt_Dry"
    },
    {
      "x": -6,
      "y": 10,
      "z": 7,
      "name": "Soil_Dirt_Dry"
    },
    {
      "x": -6,
      "y": 11,
      "z": 7,
      "name": "Soil_Dirt_Dry"
    },
    {
      "x": -6,
      "y": 12,
      "z": 7,
      "name": "Soil_Dirt_Dry"
    },
    {
      "x": -6,
      "y": 13,
      "z": 7,
      "name": "Rock_Sandstone_Cobble"
    },
    {
      "x": -6,
      "y": 2,
      "z": 8,
      "name": "Soil_Clay"
    },
    {
      "x": -6,
      "y": 3,
      "z": 8,
      "name": "Soil_Clay"
    },
    {
      "x": -6,
      "y": 4,
      "z": 8,
      "name": "Wood_Dry_Trunk",
      "support": 15
    },
    {
      "x": -6,
      "y": 5,
      "z": 8,
      "name": "Wood_Dry_Trunk",
      "support": 15
    },
    {
      "x": -6,
      "y": 6,
      "z": 8,
      "name": "Wood_Dry_Trunk",
      "support": 15
    },
    {
      "x": -6,
      "y": 7,
      "z": 8,
      "name": "Wood_Dry_Trunk",
      "support": 15
    },
    {
      "x": -6,
      "y": 8,
      "z": 8,
      "name": "Wood_Dry_Trunk",
      "support": 15
    },
    {
      "x": -6,
      "y": 9,
      "z": 8,
      "name": "Wood_Dry_Trunk",
      "support": 15
    },
    {
      "x": -6,
      "y": 10,
      "z": 8,
      "name": "Wood_Dry_Trunk",
      "support": 15
    },
    {
      "x": -6,
      "y": 11,
      "z": 8,
      "name": "Wood_Dry_Trunk",
      "support": 15
    },
    {
      "x": -6,
      "y": 12,
      "z": 8,
      "name": "Wood_Dry_Trunk",
      "support": 15
    },
    {
      "x": -6,
      "y": 13,
      "z": 8,
      "name": "Wood_Dry_Trunk",
      "support": 15
    },
    {
      "x": -6,
      "y": 14,
      "z": 8,
      "name": "Wood_Dry_Branch_Long"
    },
    {
      "x": -6,
      "y": 4,
      "z": 9,
      "name": "Soil_Dirt_Dry"
    },
    {
      "x": -6,
      "y": 5,
      "z": 9,
      "name": "Soil_Dirt_Dry"
    },
    {
      "x": -6,
      "y": 6,
      "z": 9,
      "name": "Soil_Dirt_Dry"
    },
    {
      "x": -6,
      "y": 7,
      "z": 9,
      "name": "Soil_Dirt_Dry"
    },
    {
      "x": -6,
      "y": 8,
      "z": 9,
      "name": "Soil_Dirt_Dry"
    },
    {
      "x": -6,
      "y": 9,
      "z": 9,
      "name": "Soil_Dirt_Dry"
    },
    {
      "x": -6,
      "y": 10,
      "z": 9,
      "name": "Soil_Grass_Dry"
    },
    {
      "x": -6,
      "y": 4,
      "z": 10,
      "name": "Soil_Dirt_Dry"
    },
    {
      "x": -6,
      "y": 5,
      "z": 10,
      "name": "Soil_Dirt_Dry"
    },
    {
      "x": -6,
      "y": 6,
      "z": 10,
      "name": "Soil_Dirt_Dry"
    },
    {
      "x": -6,
      "y": 7,
      "z": 10,
      "name": "Soil_Dirt_Dry"
    },
    {
      "x": -6,
      "y": 8,
      "z": 10,
      "name": "Soil_Dirt_Dry"
    },
    {
      "x": -6,
      "y": 9,
      "z": 10,
      "name": "Soil_Grass_Dry"
    },
    {
      "x": -5,
      "y": 9,
      "z": -9,
      "name": "Soil_Gravel_Sand"
    },
    {
      "x": -5,
      "y": 9,
      "z": -8,
      "name": "Soil_Gravel_Sand"
    },
    {
      "x": -5,
      "y": 10,
      "z": -8,
      "name": "Soil_Gravel_Sand"
    },
    {
      "x": -5,
      "y": 2,
      "z": -7,
      "name": "Soil_Dirt_Dry"
    },
    {
      "x": -5,
      "y": 3,
      "z": -7,
      "name": "Soil_Dirt_Dry"
    },
    {
      "x": -5,
      "y": 4,
      "z": -7,
      "name": "Soil_Dirt_Dry"
    },
    {
      "x": -5,
      "y": 5,
      "z": -7,
      "name": "Soil_Dirt_Dry"
    },
    {
      "x": -5,
      "y": 6,
      "z": -7,
      "name": "Soil_Dirt_Dry"
    },
    {
      "x": -5,
      "y": 7,
      "z": -7,
      "name": "Soil_Dirt_Dry"
    },
    {
      "x": -5,
      "y": 8,
      "z": -7,
      "name": "Soil_Dirt_Dry"
    },
    {
      "x": -5,
      "y": 9,
      "z": -7,
      "name": "Soil_Dirt_Dry"
    },
    {
      "x": -5,
      "y": 10,
      "z": -7,
      "name": "Soil_Dirt_Dry"
    },
    {
      "x": -5,
      "y": 11,
      "z": -7,
      "name": "Soil_Grass_Dry"
    },
    {
      "x": -5,
      "y": 2,
      "z": -6,
      "name": "Soil_Dirt_Dry"
    },
    {
      "x": -5,
      "y": 3,
      "z": -6,
      "name": "Soil_Dirt_Dry"
    },
    {
      "x": -5,
      "y": 4,
      "z": -6,
      "name": "Soil_Dirt_Dry"
    },
    {
      "x": -5,
      "y": 5,
      "z": -6,
      "name": "Soil_Dirt_Dry"
    },
    {
      "x": -5,
      "y": 6,
      "z": -6,
      "name": "Soil_Dirt_Dry"
    },
    {
      "x": -5,
      "y": 7,
      "z": -6,
      "name": "Soil_Dirt_Dry"
    },
    {
      "x": -5,
      "y": 8,
      "z": -6,
      "name": "Soil_Dirt_Dry"
    },
    {
      "x": -5,
      "y": 9,
      "z": -6,
      "name": "Soil_Dirt_Dry"
    },
    {
      "x": -5,
      "y": 10,
      "z": -6,
      "name": "Soil_Dirt_Dry"
    },
    {
      "x": -5,
      "y": 11,
      "z": -6,
      "name": "Soil_Gravel_Sand"
    },
    {
      "x": -5,
      "y": 2,
      "z": -5,
      "name": "Soil_Dirt_Dry"
    },
    {
      "x": -5,
      "y": 3,
      "z": -5,
      "name": "Soil_Dirt_Dry"
    },
    {
      "x": -5,
      "y": 4,
      "z": -5,
      "name": "Soil_Dirt_Dry"
    },
    {
      "x": -5,
      "y": 5,
      "z": -5,
      "name": "Soil_Dirt_Dry"
    },
    {
      "x": -5,
      "y": 6,
      "z": -5,
      "name": "Soil_Dirt_Dry"
    },
    {
      "x": -5,
      "y": 7,
      "z": -5,
      "name": "Soil_Dirt_Dry"
    },
    {
      "x": -5,
      "y": 8,
      "z": -5,
      "name": "Soil_Dirt_Dry"
    },
    {
      "x": -5,
      "y": 9,
      "z": -5,
      "name": "Soil_Dirt_Dry"
    },
    {
      "x": -5,
      "y": 10,
      "z": -5,
      "name": "Soil_Dirt_Dry"
    },
    {
      "x": -5,
      "y": 11,
      "z": -5,
      "name": "Soil_Dirt_Dry"
    },
    {
      "x": -5,
      "y": 12,
      "z": -5,
      "name": "Soil_Grass_Dry"
    },
    {
      "x": -5,
      "y": 2,
      "z": -4,
      "name": "Soil_Dirt_Dry"
    },
    {
      "x": -5,
      "y": 3,
      "z": -4,
      "name": "Soil_Dirt_Dry"
    },
    {
      "x": -5,
      "y": 4,
      "z": -4,
      "name": "Soil_Dirt_Dry"
    },
    {
      "x": -5,
      "y": 5,
      "z": -4,
      "name": "Soil_Dirt_Dry"
    },
    {
      "x": -5,
      "y": 6,
      "z": -4,
      "name": "Soil_Dirt_Dry"
    },
    {
      "x": -5,
      "y": 7,
      "z": -4,
      "name": "Soil_Dirt_Dry"
    },
    {
      "x": -5,
      "y": 8,
      "z": -4,
      "name": "Soil_Dirt_Dry"
    },
    {
      "x": -5,
      "y": 9,
      "z": -4,
      "name": "Soil_Dirt_Dry"
    },
    {
      "x": -5,
      "y": 10,
      "z": -4,
      "name": "Soil_Dirt_Dry"
    },
    {
      "x": -5,
      "y": 11,
      "z": -4,
      "name": "Soil_Dirt_Dry"
    },
    {
      "x": -5,
      "y": 12,
      "z": -4,
      "name": "Soil_Gravel_Sand"
    },
    {
      "x": -5,
      "y": 2,
      "z": -3,
      "name": "Soil_Dirt_Dry"
    },
    {
      "x": -5,
      "y": 3,
      "z": -3,
      "name": "Soil_Dirt_Dry"
    },
    {
      "x": -5,
      "y": 4,
      "z": -3,
      "name": "Soil_Dirt_Dry"
    },
    {
      "x": -5,
      "y": 5,
      "z": -3,
      "name": "Soil_Dirt_Dry"
    },
    {
      "x": -5,
      "y": 6,
      "z": -3,
      "name": "Soil_Dirt_Dry"
    },
    {
      "x": -5,
      "y": 7,
      "z": -3,
      "name": "Soil_Dirt_Dry"
    },
    {
      "x": -5,
      "y": 8,
      "z": -3,
      "name": "Soil_Dirt_Dry"
    },
    {
      "x": -5,
      "y": 9,
      "z": -3,
      "name": "Soil_Dirt_Dry"
    },
    {
      "x": -5,
      "y": 10,
      "z": -3,
      "name": "Soil_Dirt_Dry"
    },
    {
      "x": -5,
      "y": 11,
      "z": -3,
      "name": "Soil_Dirt_Dry"
    },
    {
      "x": -5,
      "y": 12,
      "z": -3,
      "name": "Soil_Gravel_Sand"
    },
    {
      "x": -5,
      "y": 13,
      "z": -3,
      "name": "Empty"
    },
    {
      "x": -5,
      "y": 14,
      "z": -3,
      "name": "Empty"
    },
    {
      "x": -5,
      "y": 15,
      "z": -3,
      "name": "Empty"
    },
    {
      "x": -5,
      "y": 16,
      "z": -3,
      "name": "Empty"
    },
    {
      "x": -5,
      "y": 17,
      "z": -3,
      "name": "Empty"
    },
    {
      "x": -5,
      "y": 18,
      "z": -3,
      "name": "Empty"
    },
    {
      "x": -5,
      "y": 2,
      "z": -2,
      "name": "Soil_Dirt_Dry"
    },
    {
      "x": -5,
      "y": 3,
      "z": -2,
      "name": "Soil_Dirt_Dry"
    },
    {
      "x": -5,
      "y": 4,
      "z": -2,
      "name": "Soil_Dirt_Dry"
    },
    {
      "x": -5,
      "y": 5,
      "z": -2,
      "name": "Soil_Dirt_Dry"
    },
    {
      "x": -5,
      "y": 6,
      "z": -2,
      "name": "Soil_Dirt_Dry"
    },
    {
      "x": -5,
      "y": 7,
      "z": -2,
      "name": "Soil_Dirt_Dry"
    },
    {
      "x": -5,
      "y": 8,
      "z": -2,
      "name": "Soil_Dirt_Dry"
    },
    {
      "x": -5,
      "y": 9,
      "z": -2,
      "name": "Soil_Dirt_Dry"
    },
    {
      "x": -5,
      "y": 10,
      "z": -2,
      "name": "Soil_Dirt_Dry"
    },
    {
      "x": -5,
      "y": 11,
      "z": -2,
      "name": "Soil_Dirt_Dry"
    },
    {
      "x": -5,
      "y": 12,
      "z": -2,
      "name": "Soil_Gravel_Sand"
    },
    {
      "x": -5,
      "y": 13,
      "z": -2,
      "name": "Empty"
    },
    {
      "x": -5,
      "y": 14,
      "z": -2,
      "name": "Empty"
    },
    {
      "x": -5,
      "y": 15,
      "z": -2,
      "name": "Empty"
    },
    {
      "x": -5,
      "y": 16,
      "z": -2,
      "name": "Empty"
    },
    {
      "x": -5,
      "y": 17,
      "z": -2,
      "name": "Empty"
    },
    {
      "x": -5,
      "y": 18,
      "z": -2,
      "name": "Empty"
    },
    {
      "x": -5,
      "y": 2,
      "z": -1,
      "name": "Soil_Dirt_Dry"
    },
    {
      "x": -5,
      "y": 3,
      "z": -1,
      "name": "Soil_Dirt_Dry"
    },
    {
      "x": -5,
      "y": 4,
      "z": -1,
      "name": "Soil_Dirt_Dry"
    },
    {
      "x": -5,
      "y": 5,
      "z": -1,
      "name": "Soil_Dirt_Dry"
    },
    {
      "x": -5,
      "y": 6,
      "z": -1,
      "name": "Soil_Dirt_Dry"
    },
    {
      "x": -5,
      "y": 7,
      "z": -1,
      "name": "Soil_Dirt_Dry"
    },
    {
      "x": -5,
      "y": 8,
      "z": -1,
      "name": "Soil_Dirt_Dry"
    },
    {
      "x": -5,
      "y": 9,
      "z": -1,
      "name": "Soil_Dirt_Dry"
    },
    {
      "x": -5,
      "y": 10,
      "z": -1,
      "name": "Soil_Dirt_Dry"
    },
    {
      "x": -5,
      "y": 11,
      "z": -1,
      "name": "Soil_Gravel_Sand"
    },
    {
      "x": -5,
      "y": 12,
      "z": -1,
      "name": "Soil_Gravel_Sand"
    },
    {
      "x": -5,
      "y": 13,
      "z": -1,
      "name": "Empty"
    },
    {
      "x": -5,
      "y": 14,
      "z": -1,
      "name": "Empty"
    },
    {
      "x": -5,
      "y": 15,
      "z": -1,
      "name": "Empty"
    },
    {
      "x": -5,
      "y": 16,
      "z": -1,
      "name": "Empty"
    },
    {
      "x": -5,
      "y": 17,
      "z": -1,
      "name": "Empty"
    },
    {
      "x": -5,
      "y": 18,
      "z": -1,
      "name": "Empty"
    },
    {
      "x": -5,
      "y": 2,
      "z": 0,
      "name": "Soil_Dirt_Dry"
    },
    {
      "x": -5,
      "y": 3,
      "z": 0,
      "name": "Soil_Dirt_Dry"
    },
    {
      "x": -5,
      "y": 4,
      "z": 0,
      "name": "Soil_Dirt_Dry"
    },
    {
      "x": -5,
      "y": 5,
      "z": 0,
      "name": "Soil_Dirt_Dry"
    },
    {
      "x": -5,
      "y": 6,
      "z": 0,
      "name": "Soil_Dirt_Dry"
    },
    {
      "x": -5,
      "y": 7,
      "z": 0,
      "name": "Soil_Dirt_Dry"
    },
    {
      "x": -5,
      "y": 8,
      "z": 0,
      "name": "Soil_Dirt_Dry"
    },
    {
      "x": -5,
      "y": 9,
      "z": 0,
      "name": "Soil_Dirt_Dry"
    },
    {
      "x": -5,
      "y": 10,
      "z": 0,
      "name": "Soil_Dirt_Dry"
    },
    {
      "x": -5,
      "y": 11,
      "z": 0,
      "name": "Soil_Gravel_Sand"
    },
    {
      "x": -5,
      "y": 12,
      "z": 0,
      "name": "Soil_Gravel_Sand"
    },
    {
      "x": -5,
      "y": 13,
      "z": 0,
      "name": "Empty"
    },
    {
      "x": -5,
      "y": 14,
      "z": 0,
      "name": "Empty"
    },
    {
      "x": -5,
      "y": 15,
      "z": 0,
      "name": "Empty"
    },
    {
      "x": -5,
      "y": 16,
      "z": 0,
      "name": "Empty"
    },
    {
      "x": -5,
      "y": 17,
      "z": 0,
      "name": "Empty"
    },
    {
      "x": -5,
      "y": 18,
      "z": 0,
      "name": "Empty"
    },
    {
      "x": -5,
      "y": 2,
      "z": 1,
      "name": "Soil_Dirt_Dry"
    },
    {
      "x": -5,
      "y": 3,
      "z": 1,
      "name": "Soil_Dirt_Dry"
    },
    {
      "x": -5,
      "y": 4,
      "z": 1,
      "name": "Soil_Dirt_Dry"
    },
    {
      "x": -5,
      "y": 5,
      "z": 1,
      "name": "Soil_Dirt_Dry"
    },
    {
      "x": -5,
      "y": 6,
      "z": 1,
      "name": "Soil_Dirt_Dry"
    },
    {
      "x": -5,
      "y": 7,
      "z": 1,
      "name": "Soil_Dirt_Dry"
    },
    {
      "x": -5,
      "y": 8,
      "z": 1,
      "name": "Soil_Dirt_Dry"
    },
    {
      "x": -5,
      "y": 9,
      "z": 1,
      "name": "Soil_Dirt_Dry"
    },
    {
      "x": -5,
      "y": 10,
      "z": 1,
      "name": "Soil_Gravel_Sand"
    },
    {
      "x": -5,
      "y": 11,
      "z": 1,
      "name": "Soil_Gravel_Sand"
    },
    {
      "x": -5,
      "y": 12,
      "z": 1,
      "name": "Soil_Gravel_Sand"
    },
    {
      "x": -5,
      "y": 13,
      "z": 1,
      "name": "Empty"
    },
    {
      "x": -5,
      "y": 14,
      "z": 1,
      "name": "Empty"
    },
    {
      "x": -5,
      "y": 15,
      "z": 1,
      "name": "Empty"
    },
    {
      "x": -5,
      "y": 16,
      "z": 1,
      "name": "Empty"
    },
    {
      "x": -5,
      "y": 17,
      "z": 1,
      "name": "Empty"
    },
    {
      "x": -5,
      "y": 18,
      "z": 1,
      "name": "Empty"
    },
    {
      "x": -5,
      "y": 2,
      "z": 2,
      "name": "Soil_Dirt_Dry"
    },
    {
      "x": -5,
      "y": 3,
      "z": 2,
      "name": "Soil_Dirt_Dry"
    },
    {
      "x": -5,
      "y": 4,
      "z": 2,
      "name": "Soil_Dirt_Dry"
    },
    {
      "x": -5,
      "y": 5,
      "z": 2,
      "name": "Soil_Dirt_Dry"
    },
    {
      "x": -5,
      "y": 6,
      "z": 2,
      "name": "Soil_Dirt_Dry"
    },
    {
      "x": -5,
      "y": 7,
      "z": 2,
      "name": "Soil_Dirt_Dry"
    },
    {
      "x": -5,
      "y": 8,
      "z": 2,
      "name": "Soil_Dirt_Dry"
    },
    {
      "x": -5,
      "y": 9,
      "z": 2,
      "name": "Soil_Dirt_Dry"
    },
    {
      "x": -5,
      "y": 10,
      "z": 2,
      "name": "Soil_Gravel_Sand"
    },
    {
      "x": -5,
      "y": 11,
      "z": 2,
      "name": "Soil_Gravel_Sand"
    },
    {
      "x": -5,
      "y": 12,
      "z": 2,
      "name": "Soil_Gravel_Sand"
    },
    {
      "x": -5,
      "y": 13,
      "z": 2,
      "name": "Empty"
    },
    {
      "x": -5,
      "y": 14,
      "z": 2,
      "name": "Empty"
    },
    {
      "x": -5,
      "y": 15,
      "z": 2,
      "name": "Empty"
    },
    {
      "x": -5,
      "y": 16,
      "z": 2,
      "name": "Empty"
    },
    {
      "x": -5,
      "y": 17,
      "z": 2,
      "name": "Empty"
    },
    {
      "x": -5,
      "y": 18,
      "z": 2,
      "name": "Empty"
    },
    {
      "x": -5,
      "y": 2,
      "z": 3,
      "name": "Soil_Dirt_Dry"
    },
    {
      "x": -5,
      "y": 3,
      "z": 3,
      "name": "Soil_Dirt_Dry"
    },
    {
      "x": -5,
      "y": 4,
      "z": 3,
      "name": "Soil_Dirt_Dry"
    },
    {
      "x": -5,
      "y": 5,
      "z": 3,
      "name": "Soil_Dirt_Dry"
    },
    {
      "x": -5,
      "y": 6,
      "z": 3,
      "name": "Soil_Dirt_Dry"
    },
    {
      "x": -5,
      "y": 7,
      "z": 3,
      "name": "Soil_Dirt_Dry"
    },
    {
      "x": -5,
      "y": 8,
      "z": 3,
      "name": "Soil_Dirt_Dry"
    },
    {
      "x": -5,
      "y": 9,
      "z": 3,
      "name": "Soil_Dirt_Dry"
    },
    {
      "x": -5,
      "y": 10,
      "z": 3,
      "name": "Soil_Gravel_Sand"
    },
    {
      "x": -5,
      "y": 11,
      "z": 3,
      "name": "Soil_Gravel_Sand"
    },
    {
      "x": -5,
      "y": 12,
      "z": 3,
      "name": "Soil_Gravel_Sand"
    },
    {
      "x": -5,
      "y": 13,
      "z": 3,
      "name": "Empty"
    },
    {
      "x": -5,
      "y": 14,
      "z": 3,
      "name": "Empty"
    },
    {
      "x": -5,
      "y": 15,
      "z": 3,
      "name": "Empty"
    },
    {
      "x": -5,
      "y": 16,
      "z": 3,
      "name": "Empty"
    },
    {
      "x": -5,
      "y": 17,
      "z": 3,
      "name": "Empty"
    },
    {
      "x": -5,
      "y": 18,
      "z": 3,
      "name": "Empty"
    },
    {
      "x": -5,
      "y": 2,
      "z": 4,
      "name": "Soil_Dirt_Dry"
    },
    {
      "x": -5,
      "y": 3,
      "z": 4,
      "name": "Soil_Dirt_Dry"
    },
    {
      "x": -5,
      "y": 4,
      "z": 4,
      "name": "Soil_Dirt_Dry"
    },
    {
      "x": -5,
      "y": 5,
      "z": 4,
      "name": "Soil_Dirt_Dry"
    },
    {
      "x": -5,
      "y": 6,
      "z": 4,
      "name": "Soil_Dirt_Dry"
    },
    {
      "x": -5,
      "y": 7,
      "z": 4,
      "name": "Soil_Dirt_Dry"
    },
    {
      "x": -5,
      "y": 8,
      "z": 4,
      "name": "Soil_Dirt_Dry"
    },
    {
      "x": -5,
      "y": 9,
      "z": 4,
      "name": "Soil_Dirt_Dry"
    },
    {
      "x": -5,
      "y": 10,
      "z": 4,
      "name": "Soil_Gravel_Sand"
    },
    {
      "x": -5,
      "y": 11,
      "z": 4,
      "name": "Soil_Gravel_Sand"
    },
    {
      "x": -5,
      "y": 12,
      "z": 4,
      "name": "Soil_Gravel_Sand"
    },
    {
      "x": -5,
      "y": 13,
      "z": 4,
      "name": "Empty"
    },
    {
      "x": -5,
      "y": 14,
      "z": 4,
      "name": "Empty"
    },
    {
      "x": -5,
      "y": 15,
      "z": 4,
      "name": "Empty"
    },
    {
      "x": -5,
      "y": 16,
      "z": 4,
      "name": "Empty"
    },
    {
      "x": -5,
      "y": 17,
      "z": 4,
      "name": "Empty"
    },
    {
      "x": -5,
      "y": 18,
      "z": 4,
      "name": "Empty"
    },
    {
      "x": -5,
      "y": 2,
      "z": 5,
      "name": "Soil_Dirt_Dry"
    },
    {
      "x": -5,
      "y": 3,
      "z": 5,
      "name": "Soil_Dirt_Dry"
    },
    {
      "x": -5,
      "y": 4,
      "z": 5,
      "name": "Soil_Dirt_Dry"
    },
    {
      "x": -5,
      "y": 5,
      "z": 5,
      "name": "Soil_Dirt_Dry"
    },
    {
      "x": -5,
      "y": 6,
      "z": 5,
      "name": "Soil_Dirt_Dry"
    },
    {
      "x": -5,
      "y": 7,
      "z": 5,
      "name": "Soil_Dirt_Dry"
    },
    {
      "x": -5,
      "y": 8,
      "z": 5,
      "name": "Soil_Dirt_Dry"
    },
    {
      "x": -5,
      "y": 9,
      "z": 5,
      "name": "Soil_Dirt_Dry"
    },
    {
      "x": -5,
      "y": 10,
      "z": 5,
      "name": "Soil_Dirt_Dry"
    },
    {
      "x": -5,
      "y": 11,
      "z": 5,
      "name": "Soil_Gravel_Sand"
    },
    {
      "x": -5,
      "y": 12,
      "z": 5,
      "name": "Soil_Gravel_Sand"
    },
    {
      "x": -5,
      "y": 13,
      "z": 5,
      "name": "Empty"
    },
    {
      "x": -5,
      "y": 14,
      "z": 5,
      "name": "Empty"
    },
    {
      "x": -5,
      "y": 15,
      "z": 5,
      "name": "Empty"
    },
    {
      "x": -5,
      "y": 16,
      "z": 5,
      "name": "Empty"
    },
    {
      "x": -5,
      "y": 17,
      "z": 5,
      "name": "Empty"
    },
    {
      "x": -5,
      "y": 18,
      "z": 5,
      "name": "Empty"
    },
    {
      "x": -5,
      "y": 2,
      "z": 6,
      "name": "Soil_Dirt_Dry"
    },
    {
      "x": -5,
      "y": 3,
      "z": 6,
      "name": "Soil_Dirt_Dry"
    },
    {
      "x": -5,
      "y": 4,
      "z": 6,
      "name": "Soil_Dirt_Dry"
    },
    {
      "x": -5,
      "y": 5,
      "z": 6,
      "name": "Soil_Dirt_Dry"
    },
    {
      "x": -5,
      "y": 6,
      "z": 6,
      "name": "Soil_Dirt_Dry"
    },
    {
      "x": -5,
      "y": 7,
      "z": 6,
      "name": "Soil_Dirt_Dry"
    },
    {
      "x": -5,
      "y": 8,
      "z": 6,
      "name": "Soil_Dirt_Dry"
    },
    {
      "x": -5,
      "y": 9,
      "z": 6,
      "name": "Soil_Dirt_Dry"
    },
    {
      "x": -5,
      "y": 10,
      "z": 6,
      "name": "Soil_Dirt_Dry"
    },
    {
      "x": -5,
      "y": 11,
      "z": 6,
      "name": "Soil_Dirt_Dry"
    },
    {
      "x": -5,
      "y": 12,
      "z": 6,
      "name": "Soil_Gravel_Sand"
    },
    {
      "x": -5,
      "y": 13,
      "z": 6,
      "name": "Empty"
    },
    {
      "x": -5,
      "y": 14,
      "z": 6,
      "name": "Empty"
    },
    {
      "x": -5,
      "y": 15,
      "z": 6,
      "name": "Empty"
    },
    {
      "x": -5,
      "y": 16,
      "z": 6,
      "name": "Empty"
    },
    {
      "x": -5,
      "y": 17,
      "z": 6,
      "name": "Empty"
    },
    {
      "x": -5,
      "y": 18,
      "z": 6,
      "name": "Empty"
    },
    {
      "x": -5,
      "y": 2,
      "z": 7,
      "name": "Soil_Dirt_Dry"
    },
    {
      "x": -5,
      "y": 3,
      "z": 7,
      "name": "Soil_Dirt_Dry"
    },
    {
      "x": -5,
      "y": 4,
      "z": 7,
      "name": "Soil_Dirt_Dry"
    },
    {
      "x": -5,
      "y": 5,
      "z": 7,
      "name": "Soil_Dirt_Dry"
    },
    {
      "x": -5,
      "y": 6,
      "z": 7,
      "name": "Soil_Dirt_Dry"
    },
    {
      "x": -5,
      "y": 7,
      "z": 7,
      "name": "Soil_Dirt_Dry"
    },
    {
      "x": -5,
      "y": 8,
      "z": 7,
      "name": "Soil_Dirt_Dry"
    },
    {
      "x": -5,
      "y": 9,
      "z": 7,
      "name": "Soil_Dirt_Dry"
    },
    {
      "x": -5,
      "y": 10,
      "z": 7,
      "name": "Soil_Dirt_Dry"
    },
    {
      "x": -5,
      "y": 11,
      "z": 7,
      "name": "Soil_Dirt_Dry"
    },
    {
      "x": -5,
      "y": 12,
      "z": 7,
      "name": "Soil_Grass_Dry"
    },
    {
      "x": -5,
      "y": 13,
      "z": 7,
      "name": "Empty"
    },
    {
      "x": -5,
      "y": 14,
      "z": 7,
      "name": "Empty"
    },
    {
      "x": -5,
      "y": 15,
      "z": 7,
      "name": "Empty"
    },
    {
      "x": -5,
      "y": 16,
      "z": 7,
      "name": "Empty"
    },
    {
      "x": -5,
      "y": 17,
      "z": 7,
      "name": "Empty"
    },
    {
      "x": -5,
      "y": 18,
      "z": 7,
      "name": "Empty"
    },
    {
      "x": -5,
      "y": 2,
      "z": 8,
      "name": "Soil_Clay"
    },
    {
      "x": -5,
      "y": 3,
      "z": 8,
      "name": "Soil_Clay"
    },
    {
      "x": -5,
      "y": 4,
      "z": 8,
      "name": "Soil_Clay"
    },
    {
      "x": -5,
      "y": 5,
      "z": 8,
      "name": "Soil_Clay"
    },
    {
      "x": -5,
      "y": 6,
      "z": 8,
      "name": "Soil_Clay"
    },
    {
      "x": -5,
      "y": 7,
      "z": 8,
      "name": "Soil_Clay"
    },
    {
      "x": -5,
      "y": 8,
      "z": 8,
      "name": "Rock_Sandstone_Cobble"
    },
    {
      "x": -5,
      "y": 9,
      "z": 8,
      "name": "Rock_Sandstone_Cobble"
    },
    {
      "x": -5,
      "y": 10,
      "z": 8,
      "name": "Rock_Sandstone_Cobble"
    },
    {
      "x": -5,
      "y": 11,
      "z": 8,
      "name": "Rock_Sandstone_Cobble"
    },
    {
      "x": -5,
      "y": 12,
      "z": 8,
      "name": "Rock_Sandstone_Cobble"
    },
    {
      "x": -5,
      "y": 13,
      "z": 8,
      "name": "Rock_Sandstone_Cobble"
    },
    {
      "x": -5,
      "y": 2,
      "z": 9,
      "name": "Soil_Clay"
    },
    {
      "x": -5,
      "y": 3,
      "z": 9,
      "name": "Soil_Clay"
    },
    {
      "x": -5,
      "y": 4,
      "z": 9,
      "name": "Soil_Clay"
    },
    {
      "x": -5,
      "y": 5,
      "z": 9,
      "name": "Soil_Clay"
    },
    {
      "x": -5,
      "y": 6,
      "z": 9,
      "name": "Soil_Clay"
    },
    {
      "x": -5,
      "y": 7,
      "z": 9,
      "name": "Soil_Clay"
    },
    {
      "x": -5,
      "y": 8,
      "z": 9,
      "name": "Soil_Clay"
    },
    {
      "x": -5,
      "y": 9,
      "z": 9,
      "name": "Soil_Clay"
    },
    {
      "x": -5,
      "y": 10,
      "z": 9,
      "name": "Soil_Clay"
    },
    {
      "x": -5,
      "y": 11,
      "z": 9,
      "name": "Soil_Clay"
    },
    {
      "x": -5,
      "y": 4,
      "z": 10,
      "name": "Soil_Dirt_Dry"
    },
    {
      "x": -5,
      "y": 5,
      "z": 10,
      "name": "Soil_Dirt_Dry"
    },
    {
      "x": -5,
      "y": 6,
      "z": 10,
      "name": "Soil_Dirt_Dry"
    },
    {
      "x": -5,
      "y": 7,
      "z": 10,
      "name": "Soil_Dirt_Dry"
    },
    {
      "x": -5,
      "y": 8,
      "z": 10,
      "name": "Soil_Dirt_Dry"
    },
    {
      "x": -5,
      "y": 9,
      "z": 10,
      "name": "Soil_Grass_Dry"
    },
    {
      "x": -4,
      "y": 9,
      "z": -10,
      "name": "Soil_Gravel_Sand"
    },
    {
      "x": -4,
      "y": 9,
      "z": -9,
      "name": "Soil_Gravel_Sand"
    },
    {
      "x": -4,
      "y": 10,
      "z": -9,
      "name": "Soil_Gravel_Sand"
    },
    {
      "x": -4,
      "y": 2,
      "z": -8,
      "name": "Soil_Dirt_Dry"
    },
    {
      "x": -4,
      "y": 3,
      "z": -8,
      "name": "Soil_Dirt_Dry"
    },
    {
      "x": -4,
      "y": 4,
      "z": -8,
      "name": "Soil_Dirt_Dry"
    },
    {
      "x": -4,
      "y": 5,
      "z": -8,
      "name": "Soil_Dirt_Dry"
    },
    {
      "x": -4,
      "y": 6,
      "z": -8,
      "name": "Soil_Dirt_Dry"
    },
    {
      "x": -4,
      "y": 7,
      "z": -8,
      "name": "Soil_Dirt_Dry"
    },
    {
      "x": -4,
      "y": 8,
      "z": -8,
      "name": "Soil_Dirt_Dry"
    },
    {
      "x": -4,
      "y": 9,
      "z": -8,
      "name": "Soil_Dirt_Dry"
    },
    {
      "x": -4,
      "y": 10,
      "z": -8,
      "name": "Soil_Grass_Dry"
    },
    {
      "x": -4,
      "y": 2,
      "z": -7,
      "name": "Soil_Dirt_Dry"
    },
    {
      "x": -4,
      "y": 3,
      "z": -7,
      "name": "Soil_Dirt_Dry"
    },
    {
      "x": -4,
      "y": 4,
      "z": -7,
      "name": "Soil_Dirt_Dry"
    },
    {
      "x": -4,
      "y": 5,
      "z": -7,
      "name": "Soil_Dirt_Dry"
    },
    {
      "x": -4,
      "y": 6,
      "z": -7,
      "name": "Soil_Dirt_Dry"
    },
    {
      "x": -4,
      "y": 7,
      "z": -7,
      "name": "Soil_Dirt_Dry"
    },
    {
      "x": -4,
      "y": 8,
      "z": -7,
      "name": "Soil_Dirt_Dry"
    },
    {
      "x": -4,
      "y": 9,
      "z": -7,
      "name": "Soil_Dirt_Dry"
    },
    {
      "x": -4,
      "y": 10,
      "z": -7,
      "name": "Soil_Dirt_Dry"
    },
    {
      "x": -4,
      "y": 11,
      "z": -7,
      "name": "Soil_Gravel_Sand"
    },
    {
      "x": -4,
      "y": 2,
      "z": -6,
      "name": "Soil_Dirt_Dry"
    },
    {
      "x": -4,
      "y": 3,
      "z": -6,
      "name": "Soil_Dirt_Dry"
    },
    {
      "x": -4,
      "y": 4,
      "z": -6,
      "name": "Soil_Dirt_Dry"
    },
    {
      "x": -4,
      "y": 5,
      "z": -6,
      "name": "Soil_Dirt_Dry"
    },
    {
      "x": -4,
      "y": 6,
      "z": -6,
      "name": "Soil_Dirt_Dry"
    },
    {
      "x": -4,
      "y": 7,
      "z": -6,
      "name": "Soil_Dirt_Dry"
    },
    {
      "x": -4,
      "y": 8,
      "z": -6,
      "name": "Soil_Dirt_Dry"
    },
    {
      "x": -4,
      "y": 9,
      "z": -6,
      "name": "Soil_Dirt_Dry"
    },
    {
      "x": -4,
      "y": 10,
      "z": -6,
      "name": "Soil_Gravel_Sand"
    },
    {
      "x": -4,
      "y": 11,
      "z": -6,
      "name": "Soil_Gravel_Sand"
    },
    {
      "x": -4,
      "y": 12,
      "z": -6,
      "name": "Soil_Gravel_Sand_Half"
    },
    {
      "x": -4,
      "y": 2,
      "z": -5,
      "name": "Soil_Dirt_Dry"
    },
    {
      "x": -4,
      "y": 3,
      "z": -5,
      "name": "Soil_Dirt_Dry"
    },
    {
      "x": -4,
      "y": 4,
      "z": -5,
      "name": "Soil_Dirt_Dry"
    },
    {
      "x": -4,
      "y": 5,
      "z": -5,
      "name": "Soil_Dirt_Dry"
    },
    {
      "x": -4,
      "y": 6,
      "z": -5,
      "name": "Soil_Dirt_Dry"
    },
    {
      "x": -4,
      "y": 7,
      "z": -5,
      "name": "Soil_Dirt_Dry"
    },
    {
      "x": -4,
      "y": 8,
      "z": -5,
      "name": "Soil_Dirt_Dry"
    },
    {
      "x": -4,
      "y": 9,
      "z": -5,
      "name": "Soil_Dirt_Dry"
    },
    {
      "x": -4,
      "y": 10,
      "z": -5,
      "name": "Soil_Dirt_Dry"
    },
    {
      "x": -4,
      "y": 11,
      "z": -5,
      "name": "Soil_Gravel_Sand"
    },
    {
      "x": -4,
      "y": 12,
      "z": -5,
      "name": "Soil_Gravel_Sand"
    },
    {
      "x": -4,
      "y": 2,
      "z": -4,
      "name": "Soil_Dirt_Dry"
    },
    {
      "x": -4,
      "y": 3,
      "z": -4,
      "name": "Soil_Dirt_Dry"
    },
    {
      "x": -4,
      "y": 4,
      "z": -4,
      "name": "Soil_Dirt_Dry"
    },
    {
      "x": -4,
      "y": 5,
      "z": -4,
      "name": "Soil_Dirt_Dry"
    },
    {
      "x": -4,
      "y": 6,
      "z": -4,
      "name": "Soil_Dirt_Dry"
    },
    {
      "x": -4,
      "y": 7,
      "z": -4,
      "name": "Soil_Dirt_Dry"
    },
    {
      "x": -4,
      "y": 8,
      "z": -4,
      "name": "Soil_Dirt_Dry"
    },
    {
      "x": -4,
      "y": 9,
      "z": -4,
      "name": "Soil_Dirt_Dry"
    },
    {
      "x": -4,
      "y": 10,
      "z": -4,
      "name": "Soil_Dirt_Dry"
    },
    {
      "x": -4,
      "y": 11,
      "z": -4,
      "name": "Soil_Dirt_Dry"
    },
    {
      "x": -4,
      "y": 12,
      "z": -4,
      "name": "Soil_Gravel_Sand"
    },
    {
      "x": -4,
      "y": 13,
      "z": -4,
      "name": "Empty"
    },
    {
      "x": -4,
      "y": 14,
      "z": -4,
      "name": "Empty"
    },
    {
      "x": -4,
      "y": 15,
      "z": -4,
      "name": "Empty"
    },
    {
      "x": -4,
      "y": 16,
      "z": -4,
      "name": "Empty"
    },
    {
      "x": -4,
      "y": 17,
      "z": -4,
      "name": "Empty"
    },
    {
      "x": -4,
      "y": 18,
      "z": -4,
      "name": "Empty"
    },
    {
      "x": -4,
      "y": 2,
      "z": -3,
      "name": "Soil_Dirt_Dry"
    },
    {
      "x": -4,
      "y": 3,
      "z": -3,
      "name": "Soil_Dirt_Dry"
    },
    {
      "x": -4,
      "y": 4,
      "z": -3,
      "name": "Soil_Dirt_Dry"
    },
    {
      "x": -4,
      "y": 5,
      "z": -3,
      "name": "Soil_Dirt_Dry"
    },
    {
      "x": -4,
      "y": 6,
      "z": -3,
      "name": "Soil_Dirt_Dry"
    },
    {
      "x": -4,
      "y": 7,
      "z": -3,
      "name": "Soil_Dirt_Dry"
    },
    {
      "x": -4,
      "y": 8,
      "z": -3,
      "name": "Soil_Dirt_Dry"
    },
    {
      "x": -4,
      "y": 9,
      "z": -3,
      "name": "Soil_Dirt_Dry"
    },
    {
      "x": -4,
      "y": 10,
      "z": -3,
      "name": "Soil_Dirt_Dry"
    },
    {
      "x": -4,
      "y": 11,
      "z": -3,
      "name": "Soil_Dirt_Dry"
    },
    {
      "x": -4,
      "y": 12,
      "z": -3,
      "name": "Soil_Gravel_Sand"
    },
    {
      "x": -4,
      "y": 13,
      "z": -3,
      "name": "Empty"
    },
    {
      "x": -4,
      "y": 14,
      "z": -3,
      "name": "Empty"
    },
    {
      "x": -4,
      "y": 15,
      "z": -3,
      "name": "Empty"
    },
    {
      "x": -4,
      "y": 16,
      "z": -3,
      "name": "Empty"
    },
    {
      "x": -4,
      "y": 17,
      "z": -3,
      "name": "Empty"
    },
    {
      "x": -4,
      "y": 18,
      "z": -3,
      "name": "Empty"
    },
    {
      "x": -4,
      "y": 2,
      "z": -2,
      "name": "Soil_Dirt_Dry"
    },
    {
      "x": -4,
      "y": 3,
      "z": -2,
      "name": "Soil_Dirt_Dry"
    },
    {
      "x": -4,
      "y": 4,
      "z": -2,
      "name": "Soil_Dirt_Dry"
    },
    {
      "x": -4,
      "y": 5,
      "z": -2,
      "name": "Soil_Dirt_Dry"
    },
    {
      "x": -4,
      "y": 6,
      "z": -2,
      "name": "Soil_Dirt_Dry"
    },
    {
      "x": -4,
      "y": 7,
      "z": -2,
      "name": "Soil_Dirt_Dry"
    },
    {
      "x": -4,
      "y": 8,
      "z": -2,
      "name": "Soil_Dirt_Dry"
    },
    {
      "x": -4,
      "y": 9,
      "z": -2,
      "name": "Soil_Dirt_Dry"
    },
    {
      "x": -4,
      "y": 10,
      "z": -2,
      "name": "Soil_Dirt_Dry"
    },
    {
      "x": -4,
      "y": 11,
      "z": -2,
      "name": "Soil_Gravel_Sand"
    },
    {
      "x": -4,
      "y": 12,
      "z": -2,
      "name": "Soil_Gravel_Sand"
    },
    {
      "x": -4,
      "y": 13,
      "z": -2,
      "name": "Empty"
    },
    {
      "x": -4,
      "y": 14,
      "z": -2,
      "name": "Empty"
    },
    {
      "x": -4,
      "y": 15,
      "z": -2,
      "name": "Empty"
    },
    {
      "x": -4,
      "y": 16,
      "z": -2,
      "name": "Empty"
    },
    {
      "x": -4,
      "y": 17,
      "z": -2,
      "name": "Empty"
    },
    {
      "x": -4,
      "y": 18,
      "z": -2,
      "name": "Empty"
    },
    {
      "x": -4,
      "y": 2,
      "z": -1,
      "name": "Soil_Dirt_Dry"
    },
    {
      "x": -4,
      "y": 3,
      "z": -1,
      "name": "Soil_Dirt_Dry"
    },
    {
      "x": -4,
      "y": 4,
      "z": -1,
      "name": "Soil_Dirt_Dry"
    },
    {
      "x": -4,
      "y": 5,
      "z": -1,
      "name": "Soil_Dirt_Dry"
    },
    {
      "x": -4,
      "y": 6,
      "z": -1,
      "name": "Soil_Dirt_Dry"
    },
    {
      "x": -4,
      "y": 7,
      "z": -1,
      "name": "Soil_Dirt_Dry"
    },
    {
      "x": -4,
      "y": 8,
      "z": -1,
      "name": "Soil_Dirt_Dry"
    },
    {
      "x": -4,
      "y": 9,
      "z": -1,
      "name": "Soil_Dirt_Dry"
    },
    {
      "x": -4,
      "y": 10,
      "z": -1,
      "name": "Soil_Gravel_Sand"
    },
    {
      "x": -4,
      "y": 11,
      "z": -1,
      "name": "Soil_Gravel_Sand"
    },
    {
      "x": -4,
      "y": 12,
      "z": -1,
      "name": "Soil_Gravel_Sand"
    },
    {
      "x": -4,
      "y": 13,
      "z": -1,
      "name": "Empty"
    },
    {
      "x": -4,
      "y": 14,
      "z": -1,
      "name": "Empty"
    },
    {
      "x": -4,
      "y": 15,
      "z": -1,
      "name": "Empty"
    },
    {
      "x": -4,
      "y": 16,
      "z": -1,
      "name": "Empty"
    },
    {
      "x": -4,
      "y": 17,
      "z": -1,
      "name": "Empty"
    },
    {
      "x": -4,
      "y": 18,
      "z": -1,
      "name": "Empty"
    },
    {
      "x": -4,
      "y": 2,
      "z": 0,
      "name": "Soil_Dirt_Dry"
    },
    {
      "x": -4,
      "y": 3,
      "z": 0,
      "name": "Soil_Dirt_Dry"
    },
    {
      "x": -4,
      "y": 4,
      "z": 0,
      "name": "Soil_Dirt_Dry"
    },
    {
      "x": -4,
      "y": 5,
      "z": 0,
      "name": "Soil_Dirt_Dry"
    },
    {
      "x": -4,
      "y": 6,
      "z": 0,
      "name": "Soil_Dirt_Dry"
    },
    {
      "x": -4,
      "y": 7,
      "z": 0,
      "name": "Soil_Dirt_Dry"
    },
    {
      "x": -4,
      "y": 8,
      "z": 0,
      "name": "Soil_Dirt_Dry"
    },
    {
      "x": -4,
      "y": 9,
      "z": 0,
      "name": "Soil_Dirt_Dry"
    },
    {
      "x": -4,
      "y": 10,
      "z": 0,
      "name": "Soil_Gravel_Sand"
    },
    {
      "x": -4,
      "y": 11,
      "z": 0,
      "name": "Soil_Gravel_Sand"
    },
    {
      "x": -4,
      "y": 12,
      "z": 0,
      "name": "Soil_Gravel_Sand"
    },
    {
      "x": -4,
      "y": 13,
      "z": 0,
      "name": "Empty"
    },
    {
      "x": -4,
      "y": 14,
      "z": 0,
      "name": "Empty"
    },
    {
      "x": -4,
      "y": 15,
      "z": 0,
      "name": "Empty"
    },
    {
      "x": -4,
      "y": 16,
      "z": 0,
      "name": "Empty"
    },
    {
      "x": -4,
      "y": 17,
      "z": 0,
      "name": "Empty"
    },
    {
      "x": -4,
      "y": 18,
      "z": 0,
      "name": "Empty"
    },
    {
      "x": -4,
      "y": 2,
      "z": 1,
      "name": "Soil_Dirt_Dry"
    },
    {
      "x": -4,
      "y": 3,
      "z": 1,
      "name": "Soil_Dirt_Dry"
    },
    {
      "x": -4,
      "y": 4,
      "z": 1,
      "name": "Soil_Dirt_Dry"
    },
    {
      "x": -4,
      "y": 5,
      "z": 1,
      "name": "Soil_Dirt_Dry"
    },
    {
      "x": -4,
      "y": 6,
      "z": 1,
      "name": "Soil_Dirt_Dry"
    },
    {
      "x": -4,
      "y": 7,
      "z": 1,
      "name": "Soil_Dirt_Dry"
    },
    {
      "x": -4,
      "y": 8,
      "z": 1,
      "name": "Soil_Dirt_Dry"
    },
    {
      "x": -4,
      "y": 9,
      "z": 1,
      "name": "Soil_Dirt_Dry"
    },
    {
      "x": -4,
      "y": 10,
      "z": 1,
      "name": "Soil_Gravel_Sand"
    },
    {
      "x": -4,
      "y": 11,
      "z": 1,
      "name": "Soil_Gravel_Sand"
    },
    {
      "x": -4,
      "y": 12,
      "z": 1,
      "name": "Soil_Gravel_Sand"
    },
    {
      "x": -4,
      "y": 13,
      "z": 1,
      "name": "Empty"
    },
    {
      "x": -4,
      "y": 14,
      "z": 1,
      "name": "Empty"
    },
    {
      "x": -4,
      "y": 15,
      "z": 1,
      "name": "Empty"
    },
    {
      "x": -4,
      "y": 16,
      "z": 1,
      "name": "Empty"
    },
    {
      "x": -4,
      "y": 17,
      "z": 1,
      "name": "Empty"
    },
    {
      "x": -4,
      "y": 18,
      "z": 1,
      "name": "Empty"
    },
    {
      "x": -4,
      "y": 2,
      "z": 2,
      "name": "Soil_Dirt_Dry"
    },
    {
      "x": -4,
      "y": 3,
      "z": 2,
      "name": "Soil_Dirt_Dry"
    },
    {
      "x": -4,
      "y": 4,
      "z": 2,
      "name": "Soil_Dirt_Dry"
    },
    {
      "x": -4,
      "y": 5,
      "z": 2,
      "name": "Soil_Dirt_Dry"
    },
    {
      "x": -4,
      "y": 6,
      "z": 2,
      "name": "Soil_Dirt_Dry"
    },
    {
      "x": -4,
      "y": 7,
      "z": 2,
      "name": "Soil_Dirt_Dry"
    },
    {
      "x": -4,
      "y": 8,
      "z": 2,
      "name": "Soil_Dirt_Dry"
    },
    {
      "x": -4,
      "y": 9,
      "z": 2,
      "name": "Soil_Dirt_Dry"
    },
    {
      "x": -4,
      "y": 10,
      "z": 2,
      "name": "Soil_Gravel_Sand"
    },
    {
      "x": -4,
      "y": 11,
      "z": 2,
      "name": "Soil_Gravel_Sand"
    },
    {
      "x": -4,
      "y": 12,
      "z": 2,
      "name": "Soil_Gravel_Sand"
    },
    {
      "x": -4,
      "y": 13,
      "z": 2,
      "name": "Empty"
    },
    {
      "x": -4,
      "y": 14,
      "z": 2,
      "name": "Empty"
    },
    {
      "x": -4,
      "y": 15,
      "z": 2,
      "name": "Empty"
    },
    {
      "x": -4,
      "y": 16,
      "z": 2,
      "name": "Empty"
    },
    {
      "x": -4,
      "y": 17,
      "z": 2,
      "name": "Empty"
    },
    {
      "x": -4,
      "y": 18,
      "z": 2,
      "name": "Empty"
    },
    {
      "x": -4,
      "y": 2,
      "z": 3,
      "name": "Soil_Dirt_Dry"
    },
    {
      "x": -4,
      "y": 3,
      "z": 3,
      "name": "Soil_Dirt_Dry"
    },
    {
      "x": -4,
      "y": 4,
      "z": 3,
      "name": "Soil_Dirt_Dry"
    },
    {
      "x": -4,
      "y": 5,
      "z": 3,
      "name": "Soil_Dirt_Dry"
    },
    {
      "x": -4,
      "y": 6,
      "z": 3,
      "name": "Soil_Dirt_Dry"
    },
    {
      "x": -4,
      "y": 7,
      "z": 3,
      "name": "Soil_Dirt_Dry"
    },
    {
      "x": -4,
      "y": 8,
      "z": 3,
      "name": "Soil_Dirt_Dry"
    },
    {
      "x": -4,
      "y": 9,
      "z": 3,
      "name": "Soil_Dirt_Dry"
    },
    {
