{
  "version": 8,
  "blockIdVersion": 8,
  "anchorX": 13,
  "anchorY": 7,
  "anchorZ": 8,
  "blocks": [
    {
      "x": 7,
      "y": 15,
      "z": 6,
      "name": "Plant_Leaves_Beech"
    },
    {
      "x": 7,
      "y": 12,
      "z": 7,
      "name": "Plant_Leaves_Beech"
    },
    {
      "x": 7,
      "y": 15,
      "z": 7,
      "name": "Plant_Leaves_Beech"
    },
    {
      "x": 7,
      "y": 16,
      "z": 7,
      "name": "Plant_Leaves_Beech"
    },
    {
      "x": 7,
      "y": 12,
      "z": 8,
      "name": "Plant_Leaves_Beech"
    },
    {
      "x": 7,
      "y": 13,
      "z": 8,
      "name": "Plant_Leaves_Beech"
    },
    {
      "x": 7,
      "y": 15,
      "z": 8,
      "name": "Plant_Leaves_Beech"
    },
    {
      "x": 7,
      "y": 16,
      "z": 8,
      "name": "Plant_Leaves_Beech"
    },
    {
      "x": 7,
      "y": 17,
      "z": 8,
      "name": "Plant_Leaves_Beech"
    },
    {
      "x": 7,
      "y": 12,
      "z": 9,
      "name": "Plant_Leaves_Beech"
    },
    {
      "x": 7,
      "y": 15,
      "z": 9,
      "name": "Plant_Leaves_Beech"
    },
    {
      "x": 7,
      "y": 16,
      "z": 9,
      "name": "Plant_Leaves_Beech"
    },
    {
      "x": 8,
      "y": 15,
      "z": 5,
      "name": "Plant_Leaves_Beech"
    },
    {
      "x": 8,
      "y": 16,
      "z": 5,
      "name": "Plant_Leaves_Beech"
    },
    {
      "x": 8,
      "y": 12,
      "z": 6,
      "name": "Plant_Leaves_Beech"
    },
    {
      "x": 8,
      "y": 13,
      "z": 6,
      "name": "Plant_Leaves_Beech"
    },
    {
      "x": 8,
      "y": 15,
      "z": 6,
      "name": "Plant_Leaves_Beech"
    },
    {
      "x": 8,
      "y": 16,
      "z": 6,
      "name": "Plant_Leaves_Beech"
    },
    {
      "x": 8,
      "y": 11,
      "z": 7,
      "name": "Plant_Leaves_Beech"
    },
    {
      "x": 8,
      "y": 12,
      "z": 7,
      "name": "Plant_Leaves_Beech"
    },
    {
      "x": 8,
      "y": 13,
      "z": 7,
      "name": "Plant_Leaves_Beech"
    },
    {
      "x": 8,
      "y": 15,
      "z": 7,
      "name": "Plant_Leaves_Beech"
    },
    {
      "x": 8,
      "y": 16,
      "z": 7,
      "name": "Plant_Leaves_Beech"
    },
    {
      "x": 8,
      "y": 17,
      "z": 7,
      "name": "Plant_Leaves_Beech"
    },
    {
      "x": 8,
      "y": 12,
      "z": 8,
      "name": "Wood_Beech_Branch_Corner",
      "rotation": 3
    },
    {
      "x": 8,
      "y": 13,
      "z": 8,
      "name": "Plant_Leaves_Beech"
    },
    {
      "x": 8,
      "y": 14,
      "z": 8,
      "name": "Plant_Leaves_Beech"
    },
    {
      "x": 8,
      "y": 15,
      "z": 8,
      "name": "Wood_Beech_Branch_Corner",
      "rotation": 3
    },
    {
      "x": 8,
      "y": 16,
      "z": 8,
      "name": "Plant_Leaves_Beech"
    },
    {
      "x": 8,
      "y": 17,
      "z": 8,
      "name": "Plant_Leaves_Beech"
    },
    {
      "x": 8,
      "y": 12,
      "z": 9,
      "name": "Plant_Leaves_Beech"
    },
    {
      "x": 8,
      "y": 13,
      "z": 9,
      "name": "Plant_Leaves_Beech"
    },
    {
      "x": 8,
      "y": 14,
      "z": 9,
      "name": "Plant_Leaves_Beech"
    },
    {
      "x": 8,
      "y": 15,
      "z": 9,
      "name": "Plant_Leaves_Beech"
    },
    {
      "x": 8,
      "y": 16,
      "z": 9,
      "name": "Plant_Leaves_Beech"
    },
    {
      "x": 8,
      "y": 17,
      "z": 9,
      "name": "Plant_Leaves_Beech"
    },
    {
      "x": 8,
      "y": 12,
      "z": 10,
      "name": "Plant_Leaves_Beech"
    },
    {
      "x": 8,
      "y": 16,
      "z": 10,
      "name": "Plant_Leaves_Beech"
    },
    {
      "x": 9,
      "y": 15,
      "z": 4,
      "name": "Plant_Leaves_Beech"
    },
    {
      "x": 9,
      "y": 12,
      "z": 5,
      "name": "Plant_Leaves_Beech"
    },
    {
      "x": 9,
      "y": 14,
      "z": 5,
      "name": "Plant_Leaves_Beech"
    },
    {
      "x": 9,
      "y": 15,
      "z": 5,
      "name": "Plant_Leaves_Beech"
    },
    {
      "x": 9,
      "y": 16,
      "z": 5,
      "name": "Plant_Leaves_Beech"
    },
    {
      "x": 9,
      "y": 11,
      "z": 6,
      "name": "Plant_Leaves_Beech"
    },
    {
      "x": 9,
      "y": 12,
      "z": 6,
      "name": "Plant_Leaves_Beech"
    },
    {
      "x": 9,
      "y": 13,
      "z": 6,
      "name": "Plant_Leaves_Beech"
    },
    {
      "x": 9,
      "y": 14,
      "z": 6,
      "name": "Plant_Leaves_Beech"
    },
    {
      "x": 9,
      "y": 15,
      "z": 6,
      "name": "Plant_Leaves_Beech"
    },
    {
      "x": 9,
      "y": 11,
      "z": 7,
      "name": "Plant_Leaves_Beech"
    },
    {
      "x": 9,
      "y": 12,
      "z": 7,
      "name": "Plant_Leaves_Beech"
    },
    {
      "x": 9,
      "y": 13,
      "z": 7,
      "name": "Plant_Leaves_Beech"
    },
    {
      "x": 9,
      "y": 15,
      "z": 7,
      "name": "Plant_Leaves_Beech"
    },
    {
      "x": 9,
      "y": 16,
      "z": 7,
      "name": "Plant_Leaves_Beech"
    },
    {
      "x": 9,
      "y": 12,
      "z": 8,
      "name": "Wood_Beech_Branch_Long",
      "rotation": 5
    },
    {
      "x": 9,
      "y": 15,
      "z": 8,
      "name": "Wood_Beech_Branch_Long",
      "rotation": 5
    },
    {
      "x": 9,
      "y": 17,
      "z": 8,
      "name": "Plant_Leaves_Beech"
    },
    {
      "x": 9,
      "y": 18,
      "z": 8,
      "name": "Plant_Leaves_Beech"
    },
    {
      "x": 9,
      "y": 19,
      "z": 8,
      "name": "Plant_Leaves_Beech"
    },
    {
      "x": 9,
      "y": 20,
      "z": 8,
      "name": "Plant_Leaves_Beech"
    },
    {
      "x": 9,
      "y": 12,
      "z": 9,
      "name": "Plant_Leaves_Beech"
    },
    {
      "x": 9,
      "y": 13,
      "z": 9,
      "name": "Plant_Leaves_Beech"
    },
    {
      "x": 9,
      "y": 17,
      "z": 9,
      "name": "Plant_Leaves_Beech"
    },
    {
      "x": 9,
      "y": 19,
      "z": 9,
      "name": "Plant_Leaves_Beech"
    },
    {
      "x": 9,
      "y": 12,
      "z": 10,
      "name": "Plant_Leaves_Beech"
    },
    {
      "x": 9,
      "y": 13,
      "z": 10,
      "name": "Plant_Leaves_Beech"
    },
    {
      "x": 9,
      "y": 15,
      "z": 11,
      "name": "Plant_Leaves_Beech"
    },
    {
      "x": 9,
      "y": 16,
      "z": 11,
      "name": "Plant_Leaves_Beech"
    },
    {
      "x": 10,
      "y": 15,
      "z": 4,
      "name": "Plant_Leaves_Beech"
    },
    {
      "x": 10,
      "y": 14,
      "z": 5,
      "name": "Plant_Leaves_Beech"
    },
    {
      "x": 10,
      "y": 15,
      "z": 5,
      "name": "Plant_Leaves_Beech"
    },
    {
      "x": 10,
      "y": 16,
      "z": 5,
      "name": "Plant_Leaves_Beech"
    },
    {
      "x": 10,
      "y": 14,
      "z": 6,
      "name": "Plant_Leaves_Beech"
    },
    {
      "x": 10,
      "y": 15,
      "z": 6,
      "name": "Plant_Leaves_Beech"
    },
    {
      "x": 10,
      "y": 16,
      "z": 6,
      "name": "Plant_Leaves_Beech"
    },
    {
      "x": 10,
      "y": 18,
      "z": 7,
      "name": "Plant_Leaves_Beech"
    },
    {
      "x": 10,
      "y": 20,
      "z": 7,
      "name": "Plant_Leaves_Beech"
    },
    {
      "x": 10,
      "y": 12,
      "z": 8,
      "name": "Wood_Beech_Branch_Long",
      "rotation": 5
    },
    {
      "x": 10,
      "y": 15,
      "z": 8,
      "name": "Wood_Beech_Branch_Long",
      "rotation": 5
    },
    {
      "x": 10,
      "y": 18,
      "z": 8,
      "name": "Plant_Leaves_Beech"
    },
    {
      "x": 10,
      "y": 20,
      "z": 8,
      "name": "Plant_Leaves_Beech"
    },
    {
      "x": 10,
      "y": 21,
      "z": 8,
      "name": "Plant_Leaves_Beech"
    },
    {
      "x": 10,
      "y": 23,
      "z": 8,
      "name": "Plant_Leaves_Beech"
    },
    {
      "x": 10,
      "y": 24,
      "z": 8,
      "name": "Plant_Leaves_Beech"
    },
    {
      "x": 10,
      "y": 18,
      "z": 9,
      "name": "Plant_Leaves_Beech"
    },
    {
      "x": 10,
      "y": 20,
      "z": 9,
      "name": "Plant_Leaves_Beech"
    },
    {
      "x": 10,
      "y": 21,
      "z": 9,
      "name": "Plant_Leaves_Beech"
    },
    {
      "x": 10,
      "y": 13,
      "z": 10,
      "name": "Plant_Leaves_Beech"
    },
    {
      "x": 10,
      "y": 17,
      "z": 10,
      "name": "Plant_Leaves_Beech"
    },
    {
      "x": 10,
      "y": 19,
      "z": 10,
      "name": "Plant_Leaves_Beech"
    },
    {
      "x": 10,
      "y": 16,
      "z": 11,
      "name": "Plant_Leaves_Beech"
    },
    {
      "x": 10,
      "y": 12,
      "z": 12,
      "name": "Plant_Leaves_Beech"
    },
    {
      "x": 10,
      "y": 15,
      "z": 12,
      "name": "Plant_Leaves_Beech"
    },
    {
      "x": 10,
      "y": 16,
      "z": 12,
      "name": "Plant_Leaves_Beech"
    },
    {
      "x": 11,
      "y": 14,
      "z": 4,
      "name": "Plant_Leaves_Beech"
    },
    {
      "x": 11,
      "y": 15,
      "z": 4,
      "name": "Plant_Leaves_Beech"
    },
    {
      "x": 11,
      "y": 17,
      "z": 5,
      "name": "Plant_Leaves_Beech"
    },
    {
      "x": 11,
      "y": 20,
      "z": 5,
      "name": "Plant_Leaves_Beech"
    },
    {
      "x": 11,
      "y": 15,
      "z": 6,
      "name": "Wood_Beech_Branch_Long",
      "rotation": 5
    },
    {
      "x": 11,
      "y": 17,
      "z": 6,
      "name": "Plant_Leaves_Beech"
    },
    {
      "x": 11,
      "y": 18,
      "z": 6,
      "name": "Plant_Leaves_Beech"
    },
    {
      "x": 11,
      "y": 18,
      "z": 7,
      "name": "Plant_Leaves_Beech"
    },
    {
      "x": 11,
      "y": 20,
      "z": 7,
      "name": "Plant_Leaves_Beech"
    },
    {
      "x": 11,
      "y": 21,
      "z": 7,
      "name": "Plant_Leaves_Beech"
    },
    {
      "x": 11,
      "y": 23,
      "z": 7,
      "name": "Plant_Leaves_Beech"
    },
    {
      "x": 11,
      "y": 24,
      "z": 7,
      "name": "Plant_Leaves_Beech"
    },
    {
      "x": 11,
      "y": 12,
      "z": 8,
      "name": "Wood_Beech_Trunk_Full"
    },
    {
      "x": 11,
      "y": 15,
      "z": 8,
      "name": "Wood_Beech_Trunk_Full"
    },
    {
      "x": 11,
      "y": 18,
      "z": 8,
      "name": "Wood_Beech_Branch_Long",
      "rotation": 5
    },
    {
      "x": 11,
      "y": 20,
      "z": 8,
      "name": "Wood_Beech_Branch_Long",
      "rotation": 5
    },
    {
      "x": 11,
      "y": 23,
      "z": 8,
      "name": "Plant_Leaves_Beech"
    },
    {
      "x": 11,
      "y": 24,
      "z": 8,
      "name": "Plant_Leaves_Beech"
    },
    {
      "x": 11,
      "y": 15,
      "z": 9,
      "name": "Wood_Beech_Branch_Long",
      "rotation": 4
    },
    {
      "x": 11,
      "y": 18,
      "z": 9,
      "name": "Plant_Leaves_Beech"
    },
    {
      "x": 11,
      "y": 20,
      "z": 9,
      "name": "Plant_Leaves_Beech"
    },
    {
      "x": 11,
      "y": 21,
      "z": 9,
      "name": "Plant_Leaves_Beech"
    },
    {
      "x": 11,
      "y": 24,
      "z": 9,
      "name": "Plant_Leaves_Beech"
    },
    {
      "x": 11,
      "y": 15,
      "z": 10,
      "name": "Wood_Beech_Branch_Long",
      "rotation": 4
    },
    {
      "x": 11,
      "y": 23,
      "z": 10,
      "name": "Plant_Leaves_Beech"
    },
    {
      "x": 11,
      "y": 15,
      "z": 11,
      "name": "Wood_Beech_Branch_Long",
      "rotation": 4
    },
    {
      "x": 11,
      "y": 17,
      "z": 11,
      "name": "Plant_Leaves_Beech"
    },
    {
      "x": 11,
      "y": 11,
      "z": 12,
      "name": "Plant_Leaves_Beech"
    },
    {
      "x": 11,
      "y": 12,
      "z": 12,
      "name": "Plant_Leaves_Beech"
    },
    {
      "x": 11,
      "y": 13,
      "z": 12,
      "name": "Plant_Leaves_Beech"
    },
    {
      "x": 11,
      "y": 15,
      "z": 12,
      "name": "Wood_Beech_Branch_Corner"
    },
    {
      "x": 11,
      "y": 16,
      "z": 12,
      "name": "Plant_Leaves_Beech"
    },
    {
      "x": 11,
      "y": 17,
      "z": 12,
      "name": "Plant_Leaves_Beech"
    },
    {
      "x": 11,
      "y": 12,
      "z": 13,
      "name": "Plant_Leaves_Beech"
    },
    {
      "x": 11,
      "y": 13,
      "z": 13,
      "name": "Plant_Leaves_Beech"
    },
    {
      "x": 11,
      "y": 15,
      "z": 13,
      "name": "Plant_Leaves_Beech"
    },
    {
      "x": 11,
      "y": 16,
      "z": 13,
      "name": "Plant_Leaves_Beech"
    },
    {
      "x": 12,
      "y": 15,
      "z": 3,
      "name": "Plant_Leaves_Beech"
    },
    {
      "x": 12,
      "y": 16,
      "z": 3,
      "name": "Plant_Leaves_Beech"
    },
    {
      "x": 12,
      "y": 13,
      "z": 4,
      "name": "Plant_Leaves_Beech"
    },
    {
      "x": 12,
      "y": 14,
      "z": 4,
      "name": "Plant_Leaves_Beech"
    },
    {
      "x": 12,
      "y": 15,
      "z": 4,
      "name": "Plant_Leaves_Beech"
    },
    {
      "x": 12,
      "y": 16,
      "z": 4,
      "name": "Plant_Leaves_Beech"
    },
    {
      "x": 12,
      "y": 17,
      "z": 4,
      "name": "Plant_Leaves_Beech"
    },
    {
      "x": 12,
      "y": 20,
      "z": 4,
      "name": "Plant_Leaves_Beech"
    },
    {
      "x": 12,
      "y": 17,
      "z": 5,
      "name": "Plant_Leaves_Beech"
    },
    {
      "x": 12,
      "y": 18,
      "z": 5,
      "name": "Plant_Leaves_Beech"
    },
    {
      "x": 12,
      "y": 21,
      "z": 5,
      "name": "Plant_Leaves_Beech"
    },
    {
      "x": 12,
      "y": 22,
      "z": 5,
      "name": "Plant_Leaves_Beech"
    },
    {
      "x": 12,
      "y": 15,
      "z": 6,
      "name": "Wood_Beech_Branch_Long",
      "rotation": 5
    },
    {
      "x": 12,
      "y": 18,
      "z": 6,
      "name": "Plant_Leaves_Beech"
    },
    {
      "x": 12,
      "y": 19,
      "z": 6,
      "name": "Plant_Leaves_Beech"
    },
    {
      "x": 12,
      "y": 21,
      "z": 6,
      "name": "Plant_Leaves_Beech"
    },
    {
      "x": 12,
      "y": 24,
      "z": 6,
      "name": "Plant_Leaves_Beech"
    },
    {
      "x": 12,
      "y": 26,
      "z": 6,
      "name": "Plant_Leaves_Beech"
    },
    {
      "x": 12,
      "y": 18,
      "z": 7,
      "name": "Plant_Leaves_Beech"
    },
    {
      "x": 12,
      "y": 23,
      "z": 7,
      "name": "Plant_Leaves_Beech"
    },
    {
      "x": 12,
      "y": 24,
      "z": 7,
      "name": "Plant_Leaves_Beech"
    },
    {
      "x": 12,
      "y": 26,
      "z": 7,
      "name": "Plant_Leaves_Beech"
    },
    {
      "x": 12,
      "y": 27,
      "z": 7,
      "name": "Plant_Leaves_Beech"
    },
    {
      "x": 12,
      "y": 12,
      "z": 8,
      "name": "Wood_Beech_Trunk_Full"
    },
    {
      "x": 12,
      "y": 15,
      "z": 8,
      "name": "Wood_Beech_Trunk_Full"
    },
    {
      "x": 12,
      "y": 18,
      "z": 8,
      "name": "Wood_Beech_Branch_Long",
      "rotation": 5
    },
    {
      "x": 12,
      "y": 20,
      "z": 8,
      "name": "Wood_Beech_Branch_Long",
      "rotation": 5
    },
    {
      "x": 12,
      "y": 23,
      "z": 8,
      "name": "Wood_Beech_Branch_Long",
      "rotation": 5
    },
    {
      "x": 12,
      "y": 26,
      "z": 8,
      "name": "Plant_Leaves_Beech"
    },
    {
      "x": 12,
      "y": 24,
      "z": 9,
      "name": "Plant_Leaves_Beech"
    },
    {
      "x": 12,
      "y": 25,
      "z": 9,
      "name": "Plant_Leaves_Beech"
    },
    {
      "x": 12,
      "y": 19,
      "z": 10,
      "name": "Plant_Leaves_Beech"
    },
    {
      "x": 12,
      "y": 20,
      "z": 10,
      "name": "Plant_Leaves_Beech"
    },
    {
      "x": 12,
      "y": 23,
      "z": 10,
      "name": "Plant_Leaves_Beech"
    },
    {
      "x": 12,
      "y": 24,
      "z": 10,
      "name": "Plant_Leaves_Beech"
    },
    {
      "x": 12,
      "y": 25,
      "z": 10,
      "name": "Plant_Leaves_Beech"
    },
    {
      "x": 12,
      "y": 19,
      "z": 11,
      "name": "Plant_Leaves_Beech"
    },
    {
      "x": 12,
      "y": 20,
      "z": 11,
      "name": "Plant_Leaves_Beech"
    },
    {
      "x": 12,
      "y": 23,
      "z": 11,
      "name": "Plant_Leaves_Beech"
    },
    {
      "x": 12,
      "y": 11,
      "z": 12,
      "name": "Plant_Leaves_Beech"
    },
    {
      "x": 12,
      "y": 12,
      "z": 12,
      "name": "Plant_Leaves_Beech"
    },
    {
      "x": 12,
      "y": 13,
      "z": 12,
      "name": "Plant_Leaves_Beech"
    },
    {
      "x": 12,
      "y": 16,
      "z": 12,
      "name": "Plant_Leaves_Beech"
    },
    {
      "x": 12,
      "y": 17,
      "z": 12,
      "name": "Plant_Leaves_Beech"
    },
    {
      "x": 12,
      "y": 11,
      "z": 13,
      "name": "Plant_Leaves_Beech"
    },
    {
      "x": 12,
      "y": 12,
      "z": 13,
      "name": "Plant_Leaves_Beech"
    },
    {
      "x": 12,
      "y": 13,
      "z": 13,
      "name": "Plant_Leaves_Beech"
    },
    {
      "x": 12,
      "y": 15,
      "z": 13,
      "name": "Plant_Leaves_Beech"
    },
    {
      "x": 12,
      "y": 16,
      "z": 13,
      "name": "Plant_Leaves_Beech"
    },
    {
      "x": 12,
      "y": 12,
      "z": 14,
      "name": "Plant_Leaves_Beech"
    },
    {
      "x": 13,
      "y": 13,
      "z": 3,
      "name": "Plant_Leaves_Beech"
    },
    {
      "x": 13,
      "y": 14,
      "z": 3,
      "name": "Plant_Leaves_Beech"
    },
    {
      "x": 13,
      "y": 15,
      "z": 3,
      "name": "Plant_Leaves_Beech"
    },
    {
      "x": 13,
      "y": 15,
      "z": 4,
      "name": "Wood_Beech_Branch_Long",
      "rotation": 4
    },
    {
      "x": 13,
      "y": 16,
      "z": 4,
      "name": "Plant_Leaves_Beech"
    },
    {
      "x": 13,
      "y": 17,
      "z": 4,
      "name": "Plant_Leaves_Beech"
    },
    {
      "x": 13,
      "y": 20,
      "z": 4,
      "name": "Plant_Leaves_Beech"
    },
    {
      "x": 13,
      "y": 21,
      "z": 4,
      "name": "Plant_Leaves_Beech"
    },
    {
      "x": 13,
      "y": 15,
      "z": 5,
      "name": "Wood_Beech_Branch_Long",
      "rotation": 4
    },
    {
      "x": 13,
      "y": 18,
      "z": 5,
      "name": "Plant_Leaves_Beech"
    },
    {
      "x": 13,
      "y": 21,
      "z": 5,
      "name": "Plant_Leaves_Beech"
    },
    {
      "x": 13,
      "y": 22,
      "z": 5,
      "name": "Plant_Leaves_Beech"
    },
    {
      "x": 13,
      "y": 14,
      "z": 6,
      "name": "Wood_Beech_Trunk_Full"
    },
    {
      "x": 13,
      "y": 15,
      "z": 6,
      "name": "Wood_Beech_Trunk_Full"
    },
    {
      "x": 13,
      "y": 16,
      "z": 6,
      "name": "Wood_Beech_Branch_Long"
    },
    {
      "x": 13,
      "y": 17,
      "z": 6,
      "name": "Wood_Beech_Branch_Long"
    },
    {
      "x": 13,
      "y": 18,
      "z": 6,
      "name": "Plant_Leaves_Beech"
    },
    {
      "x": 13,
      "y": 19,
      "z": 6,
      "name": "Plant_Leaves_Beech"
    },
    {
      "x": 13,
      "y": 21,
      "z": 6,
      "name": "Wood_Beech_Branch_Long",
      "rotation": 4
    },
    {
      "x": 13,
      "y": 25,
      "z": 6,
      "name": "Plant_Leaves_Beech"
    },
    {
      "x": 13,
      "y": 26,
      "z": 6,
      "name": "Plant_Leaves_Beech"
    },
    {
      "x": 13,
      "y": 27,
      "z": 6,
      "name": "Plant_Leaves_Beech"
    },
    {
      "x": 13,
      "y": 14,
      "z": 7,
      "name": "Wood_Beech_Trunk_Full"
    },
    {
      "x": 13,
      "y": 21,
      "z": 7,
      "name": "Wood_Beech_Branch_Long",
      "rotation": 4
    },
    {
      "x": 13,
      "y": 23,
      "z": 7,
      "name": "Wood_Beech_Branch_Corner",
      "rotation": 2
    },
    {
      "x": 13,
      "y": 24,
      "z": 7,
      "name": "Wood_Beech_Branch_Long"
    },
    {
      "x": 13,
      "y": 25,
      "z": 7,
      "name": "Wood_Beech_Branch_Long"
    },
    {
      "x": 13,
      "y": 26,
      "z": 7,
      "name": "Wood_Beech_Branch_Long"
    },
    {
      "x": 13,
      "y": 27,
      "z": 7,
      "name": "Plant_Leaves_Beech"
    },
    {
      "x": 13,
      "y": 5,
      "z": 8,
      "name": "Wood_Beech_Trunk"
    },
    {
      "x": 13,
      "y": 6,
      "z": 8,
      "name": "Wood_Beech_Trunk"
    },
    {
      "x": 13,
      "y": 7,
      "z": 8,
      "name": "Wood_Beech_Trunk"
    },
    {
      "x": 13,
      "y": 8,
      "z": 8,
      "name": "Wood_Beech_Trunk"
    },
    {
      "x": 13,
      "y": 9,
      "z": 8,
      "name": "Wood_Beech_Trunk"
    },
    {
      "x": 13,
      "y": 10,
      "z": 8,
      "name": "Wood_Beech_Trunk"
    },
    {
      "x": 13,
      "y": 11,
      "z": 8,
      "name": "Wood_Beech_Trunk"
    },
    {
      "x": 13,
      "y": 12,
      "z": 8,
      "name": "Wood_Beech_Trunk_Full"
    },
    {
      "x": 13,
      "y": 13,
      "z": 8,
      "name": "Wood_Beech_Trunk"
    },
    {
      "x": 13,
      "y": 14,
      "z": 8,
      "name": "Wood_Beech_Trunk"
    },
    {
      "x": 13,
      "y": 15,
      "z": 8,
      "name": "Wood_Beech_Trunk_Full"
    },
    {
      "x": 13,
      "y": 16,
      "z": 8,
      "name": "Wood_Beech_Trunk"
    },
    {
      "x": 13,
      "y": 17,
      "z": 8,
      "name": "Wood_Beech_Trunk"
    },
    {
      "x": 13,
      "y": 18,
      "z": 8,
      "name": "Wood_Beech_Trunk"
    },
    {
      "x": 13,
      "y": 19,
      "z": 8,
      "name": "Wood_Beech_Trunk"
    },
    {
      "x": 13,
      "y": 20,
      "z": 8,
      "name": "Wood_Beech_Trunk"
    },
    {
      "x": 13,
      "y": 21,
      "z": 8,
      "name": "Wood_Beech_Trunk"
    },
    {
      "x": 13,
      "y": 22,
      "z": 8,
      "name": "Wood_Beech_Trunk"
    },
    {
      "x": 13,
      "y": 23,
      "z": 8,
      "name": "Wood_Beech_Trunk_Full"
    },
    {
      "x": 13,
      "y": 27,
      "z": 8,
      "name": "Plant_Leaves_Beech"
    },
    {
      "x": 13,
      "y": 12,
      "z": 9,
      "name": "Wood_Beech_Trunk_Full"
    },
    {
      "x": 13,
      "y": 19,
      "z": 9,
      "name": "Wood_Beech_Branch_Long",
      "rotation": 4
    },
    {
      "x": 13,
      "y": 22,
      "z": 9,
      "name": "Wood_Beech_Branch_Corner"
    },
    {
      "x": 13,
      "y": 23,
      "z": 9,
      "name": "Wood_Beech_Branch_Long"
    },
    {
      "x": 13,
      "y": 24,
      "z": 9,
      "name": "Wood_Beech_Branch_Long"
    },
    {
      "x": 13,
      "y": 25,
      "z": 9,
      "name": "Wood_Beech_Branch_Long"
    },
    {
      "x": 13,
      "y": 26,
      "z": 9,
      "name": "Plant_Leaves_Beech"
    },
    {
      "x": 13,
      "y": 12,
      "z": 10,
      "name": "Wood_Beech_Trunk_Full"
    },
    {
      "x": 13,
      "y": 19,
      "z": 10,
      "name": "Wood_Beech_Branch_Long",
      "rotation": 4
    },
    {
      "x": 13,
      "y": 23,
      "z": 10,
      "name": "Plant_Leaves_Beech"
    },
    {
      "x": 13,
      "y": 24,
      "z": 10,
      "name": "Plant_Leaves_Beech"
    },
    {
      "x": 13,
      "y": 25,
      "z": 10,
      "name": "Plant_Leaves_Beech"
    },
    {
      "x": 13,
      "y": 12,
      "z": 11,
      "name": "Wood_Beech_Branch_Long",
      "rotation": 4
    },
    {
      "x": 13,
      "y": 19,
      "z": 11,
      "name": "Plant_Leaves_Beech"
    },
    {
      "x": 13,
      "y": 20,
      "z": 11,
      "name": "Plant_Leaves_Beech"
    },
    {
      "x": 13,
      "y": 21,
      "z": 11,
      "name": "Plant_Leaves_Beech"
    },
    {
      "x": 13,
      "y": 24,
      "z": 11,
      "name": "Plant_Leaves_Beech"
    },
    {
      "x": 13,
      "y": 12,
      "z": 12,
      "name": "Wood_Beech_Branch_Long",
      "rotation": 4
    },
    {
      "x": 13,
      "y": 16,
      "z": 12,
      "name": "Plant_Leaves_Beech"
    },
    {
      "x": 13,
      "y": 18,
      "z": 12,
      "name": "Plant_Leaves_Beech"
    },
    {
      "x": 13,
      "y": 19,
      "z": 12,
      "name": "Plant_Leaves_Beech"
    },
    {
      "x": 13,
      "y": 20,
      "z": 12,
      "name": "Plant_Leaves_Beech"
    },
    {
      "x": 13,
      "y": 12,
      "z": 13,
      "name": "Wood_Beech_Branch_Corner"
    },
    {
      "x": 13,
      "y": 13,
      "z": 13,
      "name": "Plant_Leaves_Beech"
    },
    {
      "x": 13,
      "y": 14,
      "z": 13,
      "name": "Plant_Leaves_Beech"
    },
    {
      "x": 13,
      "y": 15,
      "z": 13,
      "name": "Plant_Leaves_Beech"
    },
    {
      "x": 13,
      "y": 12,
      "z": 14,
      "name": "Plant_Leaves_Beech"
    },
    {
      "x": 13,
      "y": 13,
      "z": 14,
      "name": "Plant_Leaves_Beech"
    },
    {
      "x": 14,
      "y": 14,
      "z": 3,
      "name": "Plant_Leaves_Beech"
    },
    {
      "x": 14,
      "y": 15,
      "z": 3,
      "name": "Plant_Leaves_Beech"
    },
    {
      "x": 14,
      "y": 16,
      "z": 3,
      "name": "Plant_Leaves_Beech"
    },
    {
      "x": 14,
      "y": 14,
      "z": 4,
      "name": "Plant_Leaves_Beech"
    },
    {
      "x": 14,
      "y": 15,
      "z": 4,
      "name": "Plant_Leaves_Beech"
    },
    {
      "x": 14,
      "y": 16,
      "z": 4,
      "name": "Plant_Leaves_Beech"
    },
    {
      "x": 14,
      "y": 18,
      "z": 5,
      "name": "Plant_Leaves_Beech"
    },
    {
      "x": 14,
      "y": 21,
      "z": 5,
      "name": "Plant_Leaves_Beech"
    },
    {
      "x": 14,
      "y": 15,
      "z": 6,
      "name": "Wood_Beech_Branch_Long",
      "rotation": 5
    },
    {
      "x": 14,
      "y": 17,
      "z": 6,
      "name": "Plant_Leaves_Beech"
    },
    {
      "x": 14,
      "y": 18,
      "z": 6,
      "name": "Plant_Leaves_Beech"
    },
    {
      "x": 14,
      "y": 21,
      "z": 6,
      "name": "Plant_Leaves_Beech"
    },
    {
      "x": 14,
      "y": 24,
      "z": 6,
      "name": "Plant_Leaves_Beech"
    },
    {
      "x": 14,
      "y": 17,
      "z": 7,
      "name": "Plant_Leaves_Beech"
    },
    {
      "x": 14,
      "y": 24,
      "z": 7,
      "name": "Plant_Leaves_Beech"
    },
    {
      "x": 14,
      "y": 26,
      "z": 7,
      "name": "Plant_Leaves_Beech"
    },
    {
      "x": 14,
      "y": 27,
      "z": 7,
      "name": "Plant_Leaves_Beech"
    },
    {
      "x": 14,
      "y": 13,
      "z": 8,
      "name": "Wood_Beech_Trunk_Full"
    },
    {
      "x": 14,
      "y": 21,
      "z": 8,
      "name": "Wood_Beech_Branch_Long",
      "rotation": 5
    },
    {
      "x": 14,
      "y": 23,
      "z": 8,
      "name": "Wood_Beech_Branch_Corner",
      "rotation": 1
    },
    {
      "x": 14,
      "y": 24,
      "z": 8,
      "name": "Plant_Leaves_Beech"
    },
    {
      "x": 14,
      "y": 25,
      "z": 8,
      "name": "Plant_Leaves_Beech"
    },
    {
      "x": 14,
      "y": 27,
      "z": 8,
      "name": "Plant_Leaves_Beech"
    },
    {
      "x": 14,
      "y": 25,
      "z": 9,
      "name": "Plant_Leaves_Beech"
    },
    {
      "x": 14,
      "y": 26,
      "z": 9,
      "name": "Plant_Leaves_Beech"
    },
    {
      "x": 14,
      "y": 19,
      "z": 10,
      "name": "Plant_Leaves_Beech"
    },
    {
      "x": 14,
      "y": 24,
      "z": 10,
      "name": "Plant_Leaves_Beech"
    },
    {
      "x": 14,
      "y": 25,
      "z": 10,
      "name": "Plant_Leaves_Beech"
    },
    {
      "x": 14,
      "y": 19,
      "z": 11,
      "name": "Plant_Leaves_Beech"
    },
    {
      "x": 14,
      "y": 20,
      "z": 11,
      "name": "Plant_Leaves_Beech"
    },
    {
      "x": 14,
      "y": 21,
      "z": 11,
      "name": "Plant_Leaves_Beech"
    },
    {
      "x": 14,
      "y": 12,
      "z": 12,
      "name": "Plant_Leaves_Beech"
    },
    {
      "x": 14,
      "y": 13,
      "z": 12,
      "name": "Plant_Leaves_Beech"
    },
    {
      "x": 14,
      "y": 18,
      "z": 12,
      "name": "Plant_Leaves_Beech"
    },
    {
      "x": 14,
      "y": 12,
      "z": 13,
      "name": "Plant_Leaves_Beech"
    },
    {
      "x": 14,
      "y": 13,
      "z": 13,
      "name": "Plant_Leaves_Beech"
    },
    {
      "x": 14,
      "y": 14,
      "z": 13,
      "name": "Plant_Leaves_Beech"
    },
    {
      "x": 14,
      "y": 12,
      "z": 14,
      "name": "Plant_Leaves_Beech"
    },
    {
      "x": 15,
      "y": 15,
      "z": 3,
      "name": "Plant_Leaves_Beech"
    },
    {
      "x": 15,
      "y": 13,
      "z": 4,
      "name": "Plant_Leaves_Beech"
    },
    {
      "x": 15,
      "y": 14,
      "z": 4,
      "name": "Plant_Leaves_Beech"
    },
    {
      "x": 15,
      "y": 15,
      "z": 4,
      "name": "Plant_Leaves_Beech"
    },
    {
      "x": 15,
      "y": 16,
      "z": 4,
      "name": "Plant_Leaves_Beech"
    },
    {
      "x": 15,
      "y": 13,
      "z": 5,
      "name": "Plant_Leaves_Beech"
    },
    {
      "x": 15,
      "y": 14,
      "z": 5,
      "name": "Plant_Leaves_Beech"
    },
    {
      "x": 15,
      "y": 15,
      "z": 5,
      "name": "Plant_Leaves_Beech"
    },
    {
      "x": 15,
      "y": 16,
      "z": 5,
      "name": "Plant_Leaves_Beech"
    },
    {
      "x": 15,
      "y": 14,
      "z": 6,
      "name": "Wood_Beech_Branch_Long",
      "rotation": 4
    },
    {
      "x": 15,
      "y": 15,
      "z": 6,
      "name": "Wood_Beech_Branch_Long",
      "rotation": 5
    },
    {
      "x": 15,
      "y": 16,
      "z": 6,
      "name": "Plant_Leaves_Beech"
    },
    {
      "x": 15,
      "y": 17,
      "z": 6,
      "name": "Plant_Leaves_Beech"
    },
    {
      "x": 15,
      "y": 19,
      "z": 6,
      "name": "Plant_Leaves_Beech"
    },
    {
      "x": 15,
      "y": 20,
      "z": 6,
      "name": "Plant_Leaves_Beech"
    },
    {
      "x": 15,
      "y": 23,
      "z": 6,
      "name": "Plant_Leaves_Beech"
    },
    {
      "x": 15,
      "y": 24,
      "z": 6,
      "name": "Plant_Leaves_Beech"
    },
    {
      "x": 15,
      "y": 14,
      "z": 7,
      "name": "Wood_Beech_Branch_Long",
      "rotation": 4
    },
    {
      "x": 15,
      "y": 17,
      "z": 7,
      "name": "Plant_Leaves_Beech"
    },
    {
      "x": 15,
      "y": 18,
      "z": 7,
      "name": "Plant_Leaves_Beech"
    },
    {
      "x": 15,
      "y": 20,
      "z": 7,
      "name": "Plant_Leaves_Beech"
    },
    {
      "x": 15,
      "y": 21,
      "z": 7,
      "name": "Plant_Leaves_Beech"
    },
    {
      "x": 15,
      "y": 24,
      "z": 7,
      "name": "Plant_Leaves_Beech"
    },
    {
      "x": 15,
      "y": 25,
      "z": 7,
      "name": "Plant_Leaves_Beech"
    },
    {
      "x": 15,
      "y": 13,
      "z": 8,
      "name": "Wood_Beech_Trunk_Full"
    },
    {
      "x": 15,
      "y": 14,
      "z": 8,
      "name": "Wood_Beech_Trunk_Full"
    },
    {
      "x": 15,
      "y": 15,
      "z": 8,
      "name": "Wood_Beech_Branch_Long"
    },
    {
      "x": 15,
      "y": 16,
      "z": 8,
      "name": "Wood_Beech_Branch_Long"
    },
    {
      "x": 15,
      "y": 17,
      "z": 8,
      "name": "Plant_Leaves_Beech"
    },
    {
      "x": 15,
      "y": 18,
      "z": 8,
      "name": "Plant_Leaves_Beech"
    },
    {
      "x": 15,
      "y": 21,
      "z": 8,
      "name": "Wood_Beech_Branch_Long",
      "rotation": 5
    },
    {
      "x": 15,
      "y": 24,
      "z": 8,
      "name": "Plant_Leaves_Beech"
    },
    {
      "x": 15,
      "y": 25,
      "z": 8,
      "name": "Plant_Leaves_Beech"
    },
    {
      "x": 15,
      "y": 14,
      "z": 9,
      "name": "Wood_Beech_Branch_Long",
      "rotation": 4
    },
    {
      "x": 15,
      "y": 17,
      "z": 9,
      "name": "Plant_Leaves_Beech"
    },
    {
      "x": 15,
      "y": 21,
      "z": 9,
      "name": "Plant_Leaves_Beech"
    },
    {
      "x": 15,
      "y": 24,
      "z": 9,
      "name": "Plant_Leaves_Beech"
    },
    {
      "x": 15,
      "y": 25,
      "z": 9,
      "name": "Plant_Leaves_Beech"
    },
    {
      "x": 15,
      "y": 14,
      "z": 10,
      "name": "Wood_Beech_Branch_Long",
      "rotation": 4
    },
    {
      "x": 15,
      "y": 15,
      "z": 10,
      "name": "Plant_Leaves_Beech"
    },
    {
      "x": 15,
      "y": 19,
      "z": 10,
      "name": "Plant_Leaves_Beech"
    },
    {
      "x": 15,
      "y": 20,
      "z": 10,
      "name": "Plant_Leaves_Beech"
    },
    {
      "x": 15,
      "y": 21,
      "z": 10,
      "name": "Plant_Leaves_Beech"
    },
    {
      "x": 15,
      "y": 13,
      "z": 11,
      "name": "Plant_Leaves_Beech"
    },
    {
      "x": 15,
      "y": 14,
      "z": 11,
      "name": "Plant_Leaves_Beech"
    },
    {
      "x": 15,
      "y": 18,
      "z": 11,
      "name": "Plant_Leaves_Beech"
    },
    {
      "x": 15,
      "y": 19,
      "z": 11,
      "name": "Plant_Leaves_Beech"
    },
    {
      "x": 15,
      "y": 20,
      "z": 11,
      "name": "Plant_Leaves_Beech"
    },
    {
      "x": 15,
      "y": 12,
      "z": 12,
      "name": "Plant_Leaves_Beech"
    },
    {
      "x": 15,
      "y": 13,
      "z": 12,
      "name": "Plant_Leaves_Beech"
    },
    {
      "x": 15,
      "y": 12,
      "z": 13,
      "name": "Plant_Leaves_Beech"
    },
    {
      "x": 16,
      "y": 13,
      "z": 4,
      "name": "Plant_Leaves_Beech"
    },
    {
      "x": 16,
      "y": 14,
      "z": 4,
      "name": "Plant_Leaves_Beech"
    },
    {
      "x": 16,
      "y": 13,
      "z": 5,
      "name": "Plant_Leaves_Beech"
    },
    {
      "x": 16,
      "y": 14,
      "z": 5,
      "name": "Plant_Leaves_Beech"
    },
    {
      "x": 16,
      "y": 15,
      "z": 5,
      "name": "Plant_Leaves_Beech"
    },
    {
      "x": 16,
      "y": 15,
      "z": 6,
      "name": "Plant_Leaves_Beech"
    },
    {
      "x": 16,
      "y": 16,
      "z": 6,
      "name": "Plant_Leaves_Beech"
    },
    {
      "x": 16,
      "y": 20,
      "z": 6,
      "name": "Plant_Leaves_Beech"
    },
    {
      "x": 16,
      "y": 21,
      "z": 6,
      "name": "Plant_Leaves_Beech"
    },
    {
      "x": 16,
      "y": 16,
      "z": 7,
      "name": "Plant_Leaves_Beech"
    },
    {
      "x": 16,
      "y": 17,
      "z": 7,
      "name": "Plant_Leaves_Beech"
    },
    {
      "x": 16,
      "y": 19,
      "z": 7,
      "name": "Plant_Leaves_Beech"
    },
    {
      "x": 16,
      "y": 20,
      "z": 7,
      "name": "Plant_Leaves_Beech"
    },
    {
      "x": 16,
      "y": 21,
      "z": 7,
      "name": "Plant_Leaves_Beech"
    },
    {
      "x": 16,
      "y": 22,
      "z": 7,
      "name": "Plant_Leaves_Beech"
    },
    {
      "x": 16,
      "y": 23,
      "z": 7,
      "name": "Plant_Leaves_Beech"
    },
    {
      "x": 16,
      "y": 24,
      "z": 7,
      "name": "Plant_Leaves_Beech"
    },
    {
      "x": 16,
      "y": 14,
      "z": 8,
      "name": "Wood_Beech_Branch_Long",
      "rotation": 5
    },
    {
      "x": 16,
      "y": 17,
      "z": 8,
      "name": "Plant_Leaves_Beech"
    },
    {
      "x": 16,
      "y": 20,
      "z": 8,
      "name": "Plant_Leaves_Beech"
    },
    {
      "x": 16,
      "y": 21,
      "z": 8,
      "name": "Plant_Leaves_Beech"
    },
    {
      "x": 16,
      "y": 22,
      "z": 8,
      "name": "Plant_Leaves_Beech"
    },
    {
      "x": 16,
      "y": 23,
      "z": 8,
      "name": "Plant_Leaves_Beech"
    },
    {
      "x": 16,
      "y": 24,
      "z": 8,
      "name": "Plant_Leaves_Beech"
    },
    {
      "x": 16,
      "y": 25,
      "z": 8,
      "name": "Plant_Leaves_Beech"
    },
    {
      "x": 16,
      "y": 17,
      "z": 9,
      "name": "Plant_Leaves_Beech"
    },
    {
      "x": 16,
      "y": 20,
      "z": 9,
      "name": "Plant_Leaves_Beech"
    },
    {
      "x": 16,
      "y": 21,
      "z": 9,
      "name": "Plant_Leaves_Beech"
    },
    {
      "x": 16,
      "y": 22,
      "z": 9,
      "name": "Plant_Leaves_Beech"
    },
    {
      "x": 16,
      "y": 24,
      "z": 9,
      "name": "Plant_Leaves_Beech"
    },
    {
      "x": 16,
      "y": 15,
      "z": 10,
      "name": "Plant_Leaves_Beech"
    },
    {
      "x": 16,
      "y": 20,
      "z": 10,
      "name": "Plant_Leaves_Beech"
    },
    {
      "x": 16,
      "y": 14,
      "z": 11,
      "name": "Plant_Leaves_Beech"
    },
    {
      "x": 17,
      "y": 14,
      "z": 5,
      "name": "Plant_Leaves_Beech"
    },
    {
      "x": 17,
      "y": 13,
      "z": 6,
      "name": "Plant_Leaves_Beech"
    },
    {
      "x": 17,
      "y": 14,
      "z": 6,
      "name": "Plant_Leaves_Beech"
    },
    {
      "x": 17,
      "y": 12,
      "z": 7,
      "name": "Plant_Leaves_Beech"
    },
    {
      "x": 17,
      "y": 13,
      "z": 7,
      "name": "Plant_Leaves_Beech"
    },
    {
      "x": 17,
      "y": 14,
      "z": 7,
      "name": "Plant_Leaves_Beech"
    },
    {
      "x": 17,
      "y": 15,
      "z": 7,
      "name": "Plant_Leaves_Beech"
    },
    {
      "x": 17,
      "y": 16,
      "z": 7,
      "name": "Plant_Leaves_Beech"
    },
    {
      "x": 17,
      "y": 20,
      "z": 7,
      "name": "Plant_Leaves_Beech"
    },
    {
      "x": 17,
      "y": 21,
      "z": 7,
      "name": "Plant_Leaves_Beech"
    },
    {
      "x": 17,
      "y": 14,
      "z": 8,
      "name": "Wood_Beech_Branch_Long",
      "rotation": 5
    },
    {
      "x": 17,
      "y": 15,
      "z": 8,
      "name": "Plant_Leaves_Beech"
    },
    {
      "x": 17,
      "y": 16,
      "z": 8,
      "name": "Plant_Leaves_Beech"
    },
    {
      "x": 17,
      "y": 20,
      "z": 8,
      "name": "Plant_Leaves_Beech"
    },
    {
      "x": 17,
      "y": 21,
      "z": 8,
      "name": "Plant_Leaves_Beech"
    },
    {
      "x": 17,
      "y": 14,
      "z": 9,
      "name": "Plant_Leaves_Beech"
    },
    {
      "x": 17,
      "y": 15,
      "z": 9,
      "name": "Plant_Leaves_Beech"
    },
    {
      "x": 17,
      "y": 14,
      "z": 10,
      "name": "Plant_Leaves_Beech"
    },
    {
      "x": 17,
      "y": 15,
      "z": 10,
      "name": "Plant_Leaves_Beech"
    },
    {
      "x": 18,
      "y": 14,
      "z": 7,
      "name": "Plant_Leaves_Beech"
    },
    {
      "x": 18,
      "y": 15,
      "z": 7,
      "name": "Plant_Leaves_Beech"
    },
    {
      "x": 18,
      "y": 12,
      "z": 8,
      "name": "Plant_Leaves_Beech"
    },
    {
      "x": 18,
      "y": 13,
      "z": 8,
      "name": "Plant_Leaves_Beech"
    },
    {
      "x": 18,
      "y": 14,
      "z": 8,
      "name": "Plant_Leaves_Beech"
    },
    {
      "x": 18,
      "y": 13,
      "z": 9,
      "name": "Plant_Leaves_Beech"
    },
    {
      "x": 18,
      "y": 14,
      "z": 9,
      "name": "Plant_Leaves_Beech"
    },
    {
      "x": 18,
      "y": 15,
      "z": 9,
      "name": "Plant_Leaves_Beech"
    },
    {
      "x": 18,
      "y": 14,
      "z": 10,
      "name": "Plant_Leaves_Beech"
    }
  ]
}