{
  "version": 8,
  "blockIdVersion": 8,
  "anchorX": 4,
  "anchorY": 4,
  "anchorZ": 2,
  "blocks": [
    {
      "x": 1,
      "y": 8,
      "z": 1,
      "name": "Wood_Fir_Trunk_Full"
    },
    {
      "x": 1,
      "y": 9,
      "z": 1,
      "name": "Wood_Fir_Trunk_Full"
    },
    {
      "x": 1,
      "y": 10,
      "z": 1,
      "name": "Wood_Fir_Trunk_Full"
    },
    {
      "x": 2,
      "y": 6,
      "z": 1,
      "name": "Wood_Fir_Trunk_Full"
    },
    {
      "x": 2,
      "y": 7,
      "z": 1,
      "name": "Wood_Fir_Trunk_Full"
    },
    {
      "x": 2,
      "y": 8,
      "z": 1,
      "name": "Wood_Fir_Trunk_Full"
    },
    {
      "x": 2,
      "y": 4,
      "z": 2,
      "name": "Wood_Fir_Trunk_Full"
    },
    {
      "x": 2,
      "y": 5,
      "z": 2,
      "name": "Wood_Fir_Trunk_Full"
    },
    {
      "x": 2,
      "y": 6,
      "z": 2,
      "name": "Wood_Fir_Trunk_Full"
    },
    {
      "x": 2,
      "y": 13,
      "z": 2,
      "name": "Plant_Crop_Mushroom_Block_Green"
    },
    {
      "x": 2,
      "y": 13,
      "z": 3,
      "name": "Plant_Crop_Mushroom_Block_Green"
    },
    {
      "x": 2,
      "y": 14,
      "z": 3,
      "name": "Plant_Crop_Mushroom_Block_Green"
    },
    {
      "x": 2,
      "y": 13,
      "z": 4,
      "name": "Plant_Crop_Mushroom_Block_Green"
    },
    {
      "x": 2,
      "y": 14,
      "z": 4,
      "name": "Plant_Crop_Mushroom_Block_Green"
    },
    {
      "x": 2,
      "y": 13,
      "z": 5,
      "name": "Plant_Crop_Mushroom_Block_Green"
    },
    {
      "x": 2,
      "y": 14,
      "z": 5,
      "name": "Plant_Crop_Mushroom_Block_Green"
    },
    {
      "x": 2,
      "y": 13,
      "z": 6,
      "name": "Plant_Crop_Mushroom_Block_Green"
    },
    {
      "x": 3,
      "y": 13,
      "z": 1,
      "name": "Plant_Crop_Mushroom_Block_Green"
    },
    {
      "x": 3,
      "y": 1,
      "z": 2,
      "name": "Wood_Fir_Trunk_Full"
    },
    {
      "x": 3,
      "y": 2,
      "z": 2,
      "name": "Wood_Fir_Trunk_Full"
    },
    {
      "x": 3,
      "y": 3,
      "z": 2,
      "name": "Wood_Fir_Trunk_Full"
    },
    {
      "x": 3,
      "y": 4,
      "z": 2,
      "name": "Wood_Fir_Trunk_Full"
    },
    {
      "x": 3,
      "y": 5,
      "z": 2,
      "name": "Wood_Fir_Trunk_Full"
    },
    {
      "x": 3,
      "y": 13,
      "z": 2,
      "name": "Plant_Crop_Mushroom_Block_Green"
    },
    {
      "x": 3,
      "y": 14,
      "z": 2,
      "name": "Plant_Crop_Mushroom_Block_Green"
    },
    {
      "x": 3,
      "y": 1,
      "z": 3,
      "name": "Wood_Fir_Trunk_Full"
    },
    {
      "x": 3,
      "y": 2,
      "z": 3,
      "name": "Wood_Fir_Trunk_Full"
    },
    {
      "x": 3,
      "y": 3,
      "z": 3,
      "name": "Wood_Fir_Trunk_Full"
    },
    {
      "x": 3,
      "y": 4,
      "z": 3,
      "name": "Wood_Fir_Trunk_Full"
    },
    {
      "x": 3,
      "y": 5,
      "z": 3,
      "name": "Wood_Fir_Trunk_Full"
    },
    {
      "x": 3,
      "y": 6,
      "z": 3,
      "name": "Wood_Fir_Trunk_Full"
    },
    {
      "x": 3,
      "y": 7,
      "z": 3,
      "name": "Wood_Fir_Trunk_Full"
    },
    {
      "x": 3,
      "y": 14,
      "z": 3,
      "name": "Plant_Crop_Mushroom_Block_Green"
    },
    {
      "x": 3,
      "y": 15,
      "z": 3,
      "name": "Plant_Crop_Mushroom_Block_Green"
    },
    {
      "x": 3,
      "y": 14,
      "z": 4,
      "name": "Plant_Crop_Mushroom_Block_Green"
    },
    {
      "x": 3,
      "y": 15,
      "z": 4,
      "name": "Plant_Crop_Mushroom_Block_Green"
    },
    {
      "x": 3,
      "y": 14,
      "z": 5,
      "name": "Plant_Crop_Mushroom_Block_Green"
    },
    {
      "x": 3,
      "y": 15,
      "z": 5,
      "name": "Plant_Crop_Mushroom_Block_Green"
    },
    {
      "x": 3,
      "y": 13,
      "z": 6,
      "name": "Plant_Crop_Mushroom_Block_Green"
    },
    {
      "x": 3,
      "y": 14,
      "z": 6,
      "name": "Plant_Crop_Mushroom_Block_Green"
    },
    {
      "x": 3,
      "y": 13,
      "z": 7,
      "name": "Plant_Crop_Mushroom_Block_Green"
    },
    {
      "x": 4,
      "y": 13,
      "z": 1,
      "name": "Plant_Crop_Mushroom_Block_Green"
    },
    {
      "x": 4,
      "y": 14,
      "z": 1,
      "name": "Plant_Crop_Mushroom_Block_Green"
    },
    {
      "x": 4,
      "y": 0,
      "z": 2,
      "name": "Wood_Fir_Trunk_Full"
    },
    {
      "x": 4,
      "y": 1,
      "z": 2,
      "name": "Wood_Fir_Trunk_Full"
    },
    {
      "x": 4,
      "y": 2,
      "z": 2,
      "name": "Wood_Fir_Trunk_Full"
    },
    {
      "x": 4,
      "y": 3,
      "z": 2,
      "name": "Wood_Fir_Trunk_Full"
    },
    {
      "x": 4,
      "y": 4,
      "z": 2,
      "name": "Wood_Fir_Trunk_Full"
    },
    {
      "x": 4,
      "y": 14,
      "z": 2,
      "name": "Plant_Crop_Mushroom_Block_Green"
    },
    {
      "x": 4,
      "y": 15,
      "z": 2,
      "name": "Plant_Crop_Mushroom_Block_Green"
    },
    {
      "x": 4,
      "y": 3,
      "z": 3,
      "name": "Wood_Fir_Trunk_Full"
    },
    {
      "x": 4,
      "y": 4,
      "z": 3,
      "name": "Wood_Fir_Trunk_Full"
    },
    {
      "x": 4,
      "y": 5,
      "z": 3,
      "name": "Wood_Fir_Trunk_Full"
    },
    {
      "x": 4,
      "y": 6,
      "z": 3,
      "name": "Wood_Fir_Trunk_Full"
    },
    {
      "x": 4,
      "y": 7,
      "z": 3,
      "name": "Wood_Fir_Trunk_Full"
    },
    {
      "x": 4,
      "y": 8,
      "z": 3,
      "name": "Wood_Fir_Trunk_Full"
    },
    {
      "x": 4,
      "y": 14,
      "z": 3,
      "name": "Plant_Crop_Mushroom_Block_Green"
    },
    {
      "x": 4,
      "y": 15,
      "z": 3,
      "name": "Plant_Crop_Mushroom_Block_Green"
    },
    {
      "x": 4,
      "y": 6,
      "z": 4,
      "name": "Wood_Fir_Trunk_Full"
    },
    {
      "x": 4,
      "y": 7,
      "z": 4,
      "name": "Wood_Fir_Trunk_Full"
    },
    {
      "x": 4,
      "y": 8,
      "z": 4,
      "name": "Wood_Fir_Trunk_Full"
    },
    {
      "x": 4,
      "y": 9,
      "z": 4,
      "name": "Wood_Fir_Trunk_Full"
    },
    {
      "x": 4,
      "y": 10,
      "z": 4,
      "name": "Wood_Fir_Trunk_Full"
    },
    {
      "x": 4,
      "y": 14,
      "z": 4,
      "name": "Rock_Crystal_Green_Block"
    },
    {
      "x": 4,
      "y": 15,
      "z": 4,
      "name": "Plant_Crop_Mushroom_Block_Green"
    },
    {
      "x": 4,
      "y": 14,
      "z": 5,
      "name": "Plant_Crop_Mushroom_Block_Green"
    },
    {
      "x": 4,
      "y": 15,
      "z": 5,
      "name": "Plant_Crop_Mushroom_Block_Green"
    },
    {
      "x": 4,
      "y": 14,
      "z": 6,
      "name": "Plant_Crop_Mushroom_Block_Green"
    },
    {
      "x": 4,
      "y": 15,
      "z": 6,
      "name": "Plant_Crop_Mushroom_Block_Green"
    },
    {
      "x": 4,
      "y": 13,
      "z": 7,
      "name": "Plant_Crop_Mushroom_Block_Green"
    },
    {
      "x": 4,
      "y": 14,
      "z": 7,
      "name": "Plant_Crop_Mushroom_Block_Green"
    },
    {
      "x": 5,
      "y": 12,
      "z": 1,
      "name": "Plant_Crop_Mushroom_Block_Green"
    },
    {
      "x": 5,
      "y": 13,
      "z": 1,
      "name": "Plant_Crop_Mushroom_Block_Green"
    },
    {
      "x": 5,
      "y": 14,
      "z": 1,
      "name": "Plant_Crop_Mushroom_Block_Green"
    },
    {
      "x": 5,
      "y": 14,
      "z": 2,
      "name": "Plant_Crop_Mushroom_Block_Green"
    },
    {
      "x": 5,
      "y": 15,
      "z": 2,
      "name": "Plant_Crop_Mushroom_Block_Green"
    },
    {
      "x": 5,
      "y": 14,
      "z": 3,
      "name": "Rock_Crystal_Green_Block"
    },
    {
      "x": 5,
      "y": 15,
      "z": 3,
      "name": "Plant_Crop_Mushroom_Block_Green"
    },
    {
      "x": 5,
      "y": 9,
      "z": 4,
      "name": "Wood_Fir_Trunk_Full"
    },
    {
      "x": 5,
      "y": 10,
      "z": 4,
      "name": "Wood_Fir_Trunk_Full"
    },
    {
      "x": 5,
      "y": 11,
      "z": 4,
      "name": "Wood_Fir_Trunk_Full"
    },
    {
      "x": 5,
      "y": 12,
      "z": 4,
      "name": "Wood_Fir_Trunk_Full"
    },
    {
      "x": 5,
      "y": 13,
      "z": 4,
      "name": "Wood_Fir_Trunk_Full"
    },
    {
      "x": 5,
      "y": 14,
      "z": 4,
      "name": "Wood_Fir_Trunk_Full"
    },
    {
      "x": 5,
      "y": 15,
      "z": 4,
      "name": "Plant_Crop_Mushroom_Block_Green"
    },
    {
      "x": 5,
      "y": 14,
      "z": 5,
      "name": "Rock_Crystal_Green_Block"
    },
    {
      "x": 5,
      "y": 15,
      "z": 5,
      "name": "Plant_Crop_Mushroom_Block_Green"
    },
    {
      "x": 5,
      "y": 14,
      "z": 6,
      "name": "Plant_Crop_Mushroom_Block_Green"
    },
    {
      "x": 5,
      "y": 15,
      "z": 6,
      "name": "Plant_Crop_Mushroom_Block_Green"
    },
    {
      "x": 5,
      "y": 13,
      "z": 7,
      "name": "Plant_Crop_Mushroom_Block_Green"
    },
    {
      "x": 5,
      "y": 14,
      "z": 7,
      "name": "Plant_Crop_Mushroom_Block_Green"
    },
    {
      "x": 6,
      "y": 12,
      "z": 1,
      "name": "Plant_Crop_Mushroom_Block_Green"
    },
    {
      "x": 6,
      "y": 13,
      "z": 1,
      "name": "Plant_Crop_Mushroom_Block_Green"
    },
    {
      "x": 6,
      "y": 14,
      "z": 1,
      "name": "Plant_Crop_Mushroom_Block_Green"
    },
    {
      "x": 6,
      "y": 13,
      "z": 2,
      "name": "Plant_Crop_Mushroom_Block_Green"
    },
    {
      "x": 6,
      "y": 14,
      "z": 2,
      "name": "Plant_Crop_Mushroom_Block_Green"
    },
    {
      "x": 6,
      "y": 15,
      "z": 2,
      "name": "Plant_Crop_Mushroom_Block_Green"
    },
    {
      "x": 6,
      "y": 14,
      "z": 3,
      "name": "Plant_Crop_Mushroom_Block_Green"
    },
    {
      "x": 6,
      "y": 15,
      "z": 3,
      "name": "Plant_Crop_Mushroom_Block_Green"
    },
    {
      "x": 6,
      "y": 14,
      "z": 4,
      "name": "Rock_Crystal_Green_Block"
    },
    {
      "x": 6,
      "y": 15,
      "z": 4,
      "name": "Plant_Crop_Mushroom_Block_Green"
    },
    {
      "x": 6,
      "y": 14,
      "z": 5,
      "name": "Plant_Crop_Mushroom_Block_Green"
    },
    {
      "x": 6,
      "y": 15,
      "z": 5,
      "name": "Plant_Crop_Mushroom_Block_Green"
    },
    {
      "x": 6,
      "y": 13,
      "z": 6,
      "name": "Plant_Crop_Mushroom_Block_Green"
    },
    {
      "x": 6,
      "y": 14,
      "z": 6,
      "name": "Plant_Crop_Mushroom_Block_Green"
    },
    {
      "x": 6,
      "y": 15,
      "z": 6,
      "name": "Plant_Crop_Mushroom_Block_Green"
    },
    {
      "x": 6,
      "y": 12,
      "z": 7,
      "name": "Plant_Crop_Mushroom_Block_Green"
    },
    {
      "x": 6,
      "y": 13,
      "z": 7,
      "name": "Plant_Crop_Mushroom_Block_Green"
    },
    {
      "x": 6,
      "y": 14,
      "z": 7,
      "name": "Plant_Crop_Mushroom_Block_Green"
    },
    {
      "x": 7,
      "y": 12,
      "z": 1,
      "name": "Plant_Crop_Mushroom_Block_Green"
    },
    {
      "x": 7,
      "y": 13,
      "z": 1,
      "name": "Plant_Crop_Mushroom_Block_Green"
    },
    {
      "x": 7,
      "y": 12,
      "z": 2,
      "name": "Plant_Crop_Mushroom_Block_Green"
    },
    {
      "x": 7,
      "y": 13,
      "z": 2,
      "name": "Plant_Crop_Mushroom_Block_Green"
    },
    {
      "x": 7,
      "y": 14,
      "z": 2,
      "name": "Plant_Crop_Mushroom_Block_Green"
    },
    {
      "x": 7,
      "y": 13,
      "z": 3,
      "name": "Plant_Crop_Mushroom_Block_Green"
    },
    {
      "x": 7,
      "y": 14,
      "z": 3,
      "name": "Plant_Crop_Mushroom_Block_Green"
    },
    {
      "x": 7,
      "y": 15,
      "z": 3,
      "name": "Plant_Crop_Mushroom_Block_Green"
    },
    {
      "x": 7,
      "y": 13,
      "z": 4,
      "name": "Plant_Crop_Mushroom_Block_Green"
    },
    {
      "x": 7,
      "y": 14,
      "z": 4,
      "name": "Plant_Crop_Mushroom_Block_Green"
    },
    {
      "x": 7,
      "y": 15,
      "z": 4,
      "name": "Plant_Crop_Mushroom_Block_Green"
    },
    {
      "x": 7,
      "y": 13,
      "z": 5,
      "name": "Plant_Crop_Mushroom_Block_Green"
    },
    {
      "x": 7,
      "y": 14,
      "z": 5,
      "name": "Plant_Crop_Mushroom_Block_Green"
    },
    {
      "x": 7,
      "y": 15,
      "z": 5,
      "name": "Plant_Crop_Mushroom_Block_Green"
    },
    {
      "x": 7,
      "y": 13,
      "z": 6,
      "name": "Plant_Crop_Mushroom_Block_Green"
    },
    {
      "x": 7,
      "y": 14,
      "z": 6,
      "name": "Plant_Crop_Mushroom_Block_Green"
    },
    {
      "x": 7,
      "y": 15,
      "z": 6,
      "name": "Plant_Crop_Mushroom_Block_Green"
    },
    {
      "x": 7,
      "y": 12,
      "z": 7,
      "name": "Plant_Crop_Mushroom_Block_Green"
    },
    {
      "x": 7,
      "y": 13,
      "z": 7,
      "name": "Plant_Crop_Mushroom_Block_Green"
    },
    {
      "x": 8,
      "y": 12,
      "z": 2,
      "name": "Plant_Crop_Mushroom_Block_Green"
    },
    {
      "x": 8,
      "y": 12,
      "z": 3,
      "name": "Plant_Crop_Mushroom_Block_Green"
    },
    {
      "x": 8,
      "y": 13,
      "z": 3,
      "name": "Plant_Crop_Mushroom_Block_Green"
    },
    {
      "x": 8,
      "y": 13,
      "z": 4,
      "name": "Plant_Crop_Mushroom_Block_Green"
    },
    {
      "x": 8,
      "y": 14,
      "z": 4,
      "name": "Plant_Crop_Mushroom_Block_Green"
    },
    {
      "x": 8,
      "y": 13,
      "z": 5,
      "name": "Plant_Crop_Mushroom_Block_Green"
    },
    {
      "x": 8,
      "y": 14,
      "z": 5,
      "name": "Plant_Crop_Mushroom_Block_Green"
    },
    {
      "x": 8,
      "y": 12,
      "z": 6,
      "name": "Plant_Crop_Mushroom_Block_Green"
    },
    {
      "x": 8,
      "y": 13,
      "z": 6,
      "name": "Plant_Crop_Mushroom_Block_Green"
    },
    {
      "x": 8,
      "y": 14,
      "z": 6,
      "name": "Plant_Crop_Mushroom_Block_Green"
    },
    {
      "x": 8,
      "y": 12,
      "z": 7,
      "name": "Plant_Crop_Mushroom_Block_Green"
    },
    {
      "x": 9,
      "y": 12,
      "z": 4,
      "name": "Plant_Crop_Mushroom_Block_Green"
    },
    {
      "x": 9,
      "y": 13,
      "z": 4,
      "name": "Plant_Crop_Mushroom_Block_Green"
    },
    {
      "x": 9,
      "y": 12,
      "z": 5,
      "name": "Plant_Crop_Mushroom_Block_Green"
    },
    {
      "x": 9,
      "y": 13,
      "z": 5,
      "name": "Plant_Crop_Mushroom_Block_Green"
    },
    {
      "x": 9,
      "y": 12,
      "z": 6,
      "name": "Plant_Crop_Mushroom_Block_Green"
    }
  ]
}