{
  "version": 8,
  "blockIdVersion": 8,
  "anchorX": 3,
  "anchorY": 4,
  "anchorZ": 4,
  "blocks": [
    {
      "x": 1,
      "y": 11,
      "z": 2,
      "name": "Plant_Crop_Mushroom_Block_Green"
    },
    {
      "x": 1,
      "y": 11,
      "z": 3,
      "name": "Plant_Crop_Mushroom_Block_Green"
    },
    {
      "x": 1,
      "y": 12,
      "z": 3,
      "name": "Plant_Crop_Mushroom_Block_Green"
    },
    {
      "x": 1,
      "y": 11,
      "z": 4,
      "name": "Plant_Crop_Mushroom_Block_Green"
    },
    {
      "x": 1,
      "y": 12,
      "z": 4,
      "name": "Plant_Crop_Mushroom_Block_Green"
    },
    {
      "x": 1,
      "y": 11,
      "z": 5,
      "name": "Plant_Crop_Mushroom_Block_Green"
    },
    {
      "x": 1,
      "y": 12,
      "z": 5,
      "name": "Plant_Crop_Mushroom_Block_Green"
    },
    {
      "x": 1,
      "y": 11,
      "z": 6,
      "name": "Plant_Crop_Mushroom_Block_Green"
    },
    {
      "x": 2,
      "y": 10,
      "z": 1,
      "name": "Plant_Crop_Mushroom_Block_Green"
    },
    {
      "x": 2,
      "y": 10,
      "z": 2,
      "name": "Plant_Crop_Mushroom_Block_Green"
    },
    {
      "x": 2,
      "y": 11,
      "z": 2,
      "name": "Plant_Crop_Mushroom_Block_Green"
    },
    {
      "x": 2,
      "y": 12,
      "z": 2,
      "name": "Plant_Crop_Mushroom_Block_Green"
    },
    {
      "x": 2,
      "y": 11,
      "z": 3,
      "name": "Plant_Crop_Mushroom_Block_Green"
    },
    {
      "x": 2,
      "y": 12,
      "z": 3,
      "name": "Plant_Crop_Mushroom_Block_Green"
    },
    {
      "x": 2,
      "y": 12,
      "z": 4,
      "name": "Plant_Crop_Mushroom_Block_Green"
    },
    {
      "x": 2,
      "y": 13,
      "z": 4,
      "name": "Plant_Crop_Mushroom_Block_Green"
    },
    {
      "x": 2,
      "y": 2,
      "z": 5,
      "name": "Wood_Fir_Trunk_Full"
    },
    {
      "x": 2,
      "y": 3,
      "z": 5,
      "name": "Wood_Fir_Trunk_Full"
    },
    {
      "x": 2,
      "y": 4,
      "z": 5,
      "name": "Wood_Fir_Trunk_Full"
    },
    {
      "x": 2,
      "y": 12,
      "z": 5,
      "name": "Plant_Crop_Mushroom_Block_Green"
    },
    {
      "x": 2,
      "y": 13,
      "z": 5,
      "name": "Plant_Crop_Mushroom_Block_Green"
    },
    {
      "x": 2,
      "y": 11,
      "z": 6,
      "name": "Plant_Crop_Mushroom_Block_Green"
    },
    {
      "x": 2,
      "y": 12,
      "z": 6,
      "name": "Plant_Crop_Mushroom_Block_Green"
    },
    {
      "x": 3,
      "y": 10,
      "z": 1,
      "name": "Plant_Crop_Mushroom_Block_Green"
    },
    {
      "x": 3,
      "y": 11,
      "z": 1,
      "name": "Plant_Crop_Mushroom_Block_Green"
    },
    {
      "x": 3,
      "y": 11,
      "z": 2,
      "name": "Plant_Crop_Mushroom_Block_Green"
    },
    {
      "x": 3,
      "y": 12,
      "z": 2,
      "name": "Plant_Crop_Mushroom_Block_Green"
    },
    {
      "x": 3,
      "y": 13,
      "z": 2,
      "name": "Plant_Crop_Mushroom_Block_Green"
    },
    {
      "x": 3,
      "y": 12,
      "z": 3,
      "name": "Plant_Crop_Mushroom_Block_Green"
    },
    {
      "x": 3,
      "y": 13,
      "z": 3,
      "name": "Plant_Crop_Mushroom_Block_Green"
    },
    {
      "x": 3,
      "y": 0,
      "z": 4,
      "name": "Wood_Fir_Trunk_Full"
    },
    {
      "x": 3,
      "y": 1,
      "z": 4,
      "name": "Wood_Fir_Trunk_Full"
    },
    {
      "x": 3,
      "y": 2,
      "z": 4,
      "name": "Wood_Fir_Trunk_Full"
    },
    {
      "x": 3,
      "y": 3,
      "z": 4,
      "name": "Wood_Fir_Trunk_Full"
    },
    {
      "x": 3,
      "y": 4,
      "z": 4,
      "name": "Wood_Fir_Trunk_Full"
    },
    {
      "x": 3,
      "y": 12,
      "z": 4,
      "name": "Rock_Crystal_Green_Block"
    },
    {
      "x": 3,
      "y": 13,
      "z": 4,
      "name": "Plant_Crop_Mushroom_Block_Green"
    },
    {
      "x": 3,
      "y": 1,
      "z": 5,
      "name": "Wood_Fir_Trunk_Full"
    },
    {
      "x": 3,
      "y": 2,
      "z": 5,
      "name": "Wood_Fir_Trunk_Full"
    },
    {
      "x": 3,
      "y": 3,
      "z": 5,
      "name": "Wood_Fir_Trunk_Full"
    },
    {
      "x": 3,
      "y": 4,
      "z": 5,
      "name": "Wood_Fir_Trunk_Full"
    },
    {
      "x": 3,
      "y": 5,
      "z": 5,
      "name": "Wood_Fir_Trunk_Full"
    },
    {
      "x": 3,
      "y": 6,
      "z": 5,
      "name": "Wood_Fir_Trunk_Full"
    },
    {
      "x": 3,
      "y": 12,
      "z": 5,
      "name": "Plant_Crop_Mushroom_Block_Green"
    },
    {
      "x": 3,
      "y": 13,
      "z": 5,
      "name": "Plant_Crop_Mushroom_Block_Green"
    },
    {
      "x": 3,
      "y": 12,
      "z": 6,
      "name": "Plant_Crop_Mushroom_Block_Green"
    },
    {
      "x": 3,
      "y": 13,
      "z": 6,
      "name": "Plant_Crop_Mushroom_Block_Green"
    },
    {
      "x": 3,
      "y": 11,
      "z": 7,
      "name": "Plant_Crop_Mushroom_Block_Green"
    },
    {
      "x": 3,
      "y": 12,
      "z": 7,
      "name": "Plant_Crop_Mushroom_Block_Green"
    },
    {
      "x": 4,
      "y": 10,
      "z": 1,
      "name": "Plant_Crop_Mushroom_Block_Green"
    },
    {
      "x": 4,
      "y": 11,
      "z": 1,
      "name": "Plant_Crop_Mushroom_Block_Green"
    },
    {
      "x": 4,
      "y": 12,
      "z": 1,
      "name": "Plant_Crop_Mushroom_Block_Green"
    },
    {
      "x": 4,
      "y": 11,
      "z": 2,
      "name": "Plant_Crop_Mushroom_Block_Green"
    },
    {
      "x": 4,
      "y": 12,
      "z": 2,
      "name": "Plant_Crop_Mushroom_Block_Green"
    },
    {
      "x": 4,
      "y": 13,
      "z": 2,
      "name": "Plant_Crop_Mushroom_Block_Green"
    },
    {
      "x": 4,
      "y": 12,
      "z": 3,
      "name": "Rock_Crystal_Green_Block"
    },
    {
      "x": 4,
      "y": 13,
      "z": 3,
      "name": "Plant_Crop_Mushroom_Block_Green"
    },
    {
      "x": 4,
      "y": 8,
      "z": 4,
      "name": "Wood_Fir_Trunk_Full"
    },
    {
      "x": 4,
      "y": 9,
      "z": 4,
      "name": "Wood_Fir_Trunk_Full"
    },
    {
      "x": 4,
      "y": 10,
      "z": 4,
      "name": "Wood_Fir_Trunk_Full"
    },
    {
      "x": 4,
      "y": 11,
      "z": 4,
      "name": "Wood_Fir_Trunk_Full"
    },
    {
      "x": 4,
      "y": 12,
      "z": 4,
      "name": "Wood_Fir_Trunk_Full"
    },
    {
      "x": 4,
      "y": 13,
      "z": 4,
      "name": "Plant_Crop_Mushroom_Block_Green"
    },
    {
      "x": 4,
      "y": 5,
      "z": 5,
      "name": "Wood_Fir_Trunk_Full"
    },
    {
      "x": 4,
      "y": 6,
      "z": 5,
      "name": "Wood_Fir_Trunk_Full"
    },
    {
      "x": 4,
      "y": 7,
      "z": 5,
      "name": "Wood_Fir_Trunk_Full"
    },
    {
      "x": 4,
      "y": 8,
      "z": 5,
      "name": "Wood_Fir_Trunk_Full"
    },
    {
      "x": 4,
      "y": 12,
      "z": 5,
      "name": "Rock_Crystal_Green_Block"
    },
    {
      "x": 4,
      "y": 13,
      "z": 5,
      "name": "Plant_Crop_Mushroom_Block_Green"
    },
    {
      "x": 4,
      "y": 12,
      "z": 6,
      "name": "Plant_Crop_Mushroom_Block_Green"
    },
    {
      "x": 4,
      "y": 13,
      "z": 6,
      "name": "Plant_Crop_Mushroom_Block_Green"
    },
    {
      "x": 4,
      "y": 11,
      "z": 7,
      "name": "Plant_Crop_Mushroom_Block_Green"
    },
    {
      "x": 4,
      "y": 12,
      "z": 7,
      "name": "Plant_Crop_Mushroom_Block_Green"
    },
    {
      "x": 5,
      "y": 10,
      "z": 1,
      "name": "Plant_Crop_Mushroom_Block_Green"
    },
    {
      "x": 5,
      "y": 11,
      "z": 1,
      "name": "Plant_Crop_Mushroom_Block_Green"
    },
    {
      "x": 5,
      "y": 12,
      "z": 1,
      "name": "Plant_Crop_Mushroom_Block_Green"
    },
    {
      "x": 5,
      "y": 11,
      "z": 2,
      "name": "Plant_Crop_Mushroom_Block_Green"
    },
    {
      "x": 5,
      "y": 12,
      "z": 2,
      "name": "Plant_Crop_Mushroom_Block_Green"
    },
    {
      "x": 5,
      "y": 12,
      "z": 3,
      "name": "Plant_Crop_Mushroom_Block_Green"
    },
    {
      "x": 5,
      "y": 13,
      "z": 3,
      "name": "Plant_Crop_Mushroom_Block_Green"
    },
    {
      "x": 5,
      "y": 12,
      "z": 4,
      "name": "Rock_Crystal_Green_Block"
    },
    {
      "x": 5,
      "y": 13,
      "z": 4,
      "name": "Plant_Crop_Mushroom_Block_Green"
    },
    {
      "x": 5,
      "y": 12,
      "z": 5,
      "name": "Plant_Crop_Mushroom_Block_Green"
    },
    {
      "x": 5,
      "y": 13,
      "z": 5,
      "name": "Plant_Crop_Mushroom_Block_Green"
    },
    {
      "x": 5,
      "y": 11,
      "z": 6,
      "name": "Plant_Crop_Mushroom_Block_Green"
    },
    {
      "x": 5,
      "y": 12,
      "z": 6,
      "name": "Plant_Crop_Mushroom_Block_Green"
    },
    {
      "x": 5,
      "y": 11,
      "z": 7,
      "name": "Plant_Crop_Mushroom_Block_Green"
    },
    {
      "x": 6,
      "y": 10,
      "z": 1,
      "name": "Plant_Crop_Mushroom_Block_Green"
    },
    {
      "x": 6,
      "y": 11,
      "z": 1,
      "name": "Plant_Crop_Mushroom_Block_Green"
    },
    {
      "x": 6,
      "y": 11,
      "z": 2,
      "name": "Plant_Crop_Mushroom_Block_Green"
    },
    {
      "x": 6,
      "y": 12,
      "z": 2,
      "name": "Plant_Crop_Mushroom_Block_Green"
    },
    {
      "x": 6,
      "y": 11,
      "z": 3,
      "name": "Plant_Crop_Mushroom_Block_Green"
    },
    {
      "x": 6,
      "y": 12,
      "z": 3,
      "name": "Plant_Crop_Mushroom_Block_Green"
    },
    {
      "x": 6,
      "y": 11,
      "z": 4,
      "name": "Plant_Crop_Mushroom_Block_Green"
    },
    {
      "x": 6,
      "y": 12,
      "z": 4,
      "name": "Plant_Crop_Mushroom_Block_Green"
    },
    {
      "x": 6,
      "y": 11,
      "z": 5,
      "name": "Plant_Crop_Mushroom_Block_Green"
    },
    {
      "x": 6,
      "y": 12,
      "z": 5,
      "name": "Plant_Crop_Mushroom_Block_Green"
    },
    {
      "x": 6,
      "y": 10,
      "z": 6,
      "name": "Plant_Crop_Mushroom_Block_Green"
    },
    {
      "x": 6,
      "y": 11,
      "z": 6,
      "name": "Plant_Crop_Mushroom_Block_Green"
    },
    {
      "x": 6,
      "y": 12,
      "z": 6,
      "name": "Plant_Crop_Mushroom_Block_Green"
    },
    {
      "x": 6,
      "y": 10,
      "z": 7,
      "name": "Plant_Crop_Mushroom_Block_Green"
    },
    {
      "x": 7,
      "y": 10,
      "z": 1,
      "name": "Plant_Crop_Mushroom_Block_Green"
    },
    {
      "x": 7,
      "y": 10,
      "z": 2,
      "name": "Plant_Crop_Mushroom_Block_Green"
    },
    {
      "x": 7,
      "y": 11,
      "z": 2,
      "name": "Plant_Crop_Mushroom_Block_Green"
    },
    {
      "x": 7,
      "y": 10,
      "z": 3,
      "name": "Plant_Crop_Mushroom_Block_Green"
    },
    {
      "x": 7,
      "y": 11,
      "z": 3,
      "name": "Plant_Crop_Mushroom_Block_Green"
    },
    {
      "x": 7,
      "y": 10,
      "z": 4,
      "name": "Plant_Crop_Mushroom_Block_Green"
    },
    {
      "x": 7,
      "y": 11,
      "z": 4,
      "name": "Plant_Crop_Mushroom_Block_Green"
    },
    {
      "x": 7,
      "y": 10,
      "z": 5,
      "name": "Plant_Crop_Mushroom_Block_Green"
    },
    {
      "x": 7,
      "y": 11,
      "z": 5,
      "name": "Plant_Crop_Mushroom_Block_Green"
    },
    {
      "x": 7,
      "y": 10,
      "z": 6,
      "name": "Plant_Crop_Mushroom_Block_Green"
    }
  ]
}