{
  "version": 8,
  "blockIdVersion": 8,
  "anchorX": 0,
  "anchorY": 4,
  "anchorZ": -5,
  "blocks": [
    {
      "x": -9,
      "y": 5,
      "z": -4,
      "name": "Soil_Mud_Dry"
    },
    {
      "x": -9,
      "y": 6,
      "z": -4,
      "name": "Soil_Mud_Dry"
    },
    {
      "x": -9,
      "y": 7,
      "z": -4,
      "name": "Soil_Mud_Dry"
    },
    {
      "x": -9,
      "y": 8,
      "z": -4,
      "name": "Soil_Mud_Dry"
    },
    {
      "x": -9,
      "y": 9,
      "z": -4,
      "name": "Soil_Mud_Dry"
    },
    {
      "x": -9,
      "y": 10,
      "z": -4,
      "name": "Soil_Mud_Dry"
    },
    {
      "x": -9,
      "y": 11,
      "z": -4,
      "name": "Soil_Mud_Dry"
    },
    {
      "x": -9,
      "y": 12,
      "z": -4,
      "name": "Soil_Mud_Dry"
    },
    {
      "x": -9,
      "y": 13,
      "z": -4,
      "name": "Soil_Mud_Dry"
    },
    {
      "x": -9,
      "y": 14,
      "z": -4,
      "name": "Soil_Mud_Dry"
    },
    {
      "x": -9,
      "y": 5,
      "z": -3,
      "name": "Soil_Mud_Dry"
    },
    {
      "x": -9,
      "y": 6,
      "z": -3,
      "name": "Soil_Mud_Dry"
    },
    {
      "x": -9,
      "y": 7,
      "z": -3,
      "name": "Soil_Mud_Dry"
    },
    {
      "x": -9,
      "y": 8,
      "z": -3,
      "name": "Soil_Mud_Dry"
    },
    {
      "x": -9,
      "y": 9,
      "z": -3,
      "name": "Soil_Mud_Dry"
    },
    {
      "x": -9,
      "y": 10,
      "z": -3,
      "name": "Soil_Mud_Dry"
    },
    {
      "x": -9,
      "y": 11,
      "z": -3,
      "name": "Soil_Mud_Dry"
    },
    {
      "x": -9,
      "y": 12,
      "z": -3,
      "name": "Soil_Mud_Dry"
    },
    {
      "x": -9,
      "y": 13,
      "z": -3,
      "name": "Soil_Mud_Dry"
    },
    {
      "x": -9,
      "y": 14,
      "z": -3,
      "name": "Soil_Mud_Dry"
    },
    {
      "x": -9,
      "y": 5,
      "z": -2,
      "name": "Soil_Mud_Dry"
    },
    {
      "x": -9,
      "y": 6,
      "z": -2,
      "name": "Soil_Mud_Dry"
    },
    {
      "x": -9,
      "y": 7,
      "z": -2,
      "name": "Soil_Mud_Dry"
    },
    {
      "x": -9,
      "y": 8,
      "z": -2,
      "name": "Soil_Mud_Dry"
    },
    {
      "x": -9,
      "y": 9,
      "z": -2,
      "name": "Soil_Mud_Dry"
    },
    {
      "x": -9,
      "y": 10,
      "z": -2,
      "name": "Soil_Mud_Dry"
    },
    {
      "x": -9,
      "y": 11,
      "z": -2,
      "name": "Soil_Mud_Dry"
    },
    {
      "x": -9,
      "y": 12,
      "z": -2,
      "name": "Soil_Mud_Dry"
    },
    {
      "x": -9,
      "y": 13,
      "z": -2,
      "name": "Soil_Mud_Dry"
    },
    {
      "x": -9,
      "y": 14,
      "z": -2,
      "name": "Soil_Mud_Dry"
    },
    {
      "x": -9,
      "y": 5,
      "z": -1,
      "name": "Soil_Mud_Dry"
    },
    {
      "x": -9,
      "y": 6,
      "z": -1,
      "name": "Soil_Mud_Dry"
    },
    {
      "x": -9,
      "y": 7,
      "z": -1,
      "name": "Soil_Mud_Dry"
    },
    {
      "x": -9,
      "y": 8,
      "z": -1,
      "name": "Soil_Mud_Dry"
    },
    {
      "x": -9,
      "y": 9,
      "z": -1,
      "name": "Soil_Mud_Dry"
    },
    {
      "x": -9,
      "y": 10,
      "z": -1,
      "name": "Soil_Mud_Dry"
    },
    {
      "x": -9,
      "y": 11,
      "z": -1,
      "name": "Soil_Mud_Dry"
    },
    {
      "x": -9,
      "y": 12,
      "z": -1,
      "name": "Soil_Mud_Dry"
    },
    {
      "x": -9,
      "y": 13,
      "z": -1,
      "name": "Soil_Mud_Dry"
    },
    {
      "x": -9,
      "y": 14,
      "z": -1,
      "name": "Soil_Mud_Dry"
    },
    {
      "x": -9,
      "y": 5,
      "z": 0,
      "name": "Soil_Mud_Dry"
    },
    {
      "x": -9,
      "y": 6,
      "z": 0,
      "name": "Soil_Mud_Dry"
    },
    {
      "x": -9,
      "y": 7,
      "z": 0,
      "name": "Soil_Mud_Dry"
    },
    {
      "x": -9,
      "y": 8,
      "z": 0,
      "name": "Soil_Mud_Dry"
    },
    {
      "x": -9,
      "y": 9,
      "z": 0,
      "name": "Soil_Mud_Dry"
    },
    {
      "x": -9,
      "y": 10,
      "z": 0,
      "name": "Soil_Mud_Dry"
    },
    {
      "x": -9,
      "y": 11,
      "z": 0,
      "name": "Soil_Mud_Dry"
    },
    {
      "x": -9,
      "y": 12,
      "z": 0,
      "name": "Soil_Mud_Dry"
    },
    {
      "x": -9,
      "y": 13,
      "z": 0,
      "name": "Soil_Mud_Dry"
    },
    {
      "x": -9,
      "y": 14,
      "z": 0,
      "name": "Soil_Mud_Dry"
    },
    {
      "x": -9,
      "y": 5,
      "z": 1,
      "name": "Soil_Mud_Dry"
    },
    {
      "x": -9,
      "y": 6,
      "z": 1,
      "name": "Soil_Mud_Dry"
    },
    {
      "x": -9,
      "y": 7,
      "z": 1,
      "name": "Soil_Mud_Dry"
    },
    {
      "x": -9,
      "y": 8,
      "z": 1,
      "name": "Soil_Mud_Dry"
    },
    {
      "x": -9,
      "y": 9,
      "z": 1,
      "name": "Soil_Mud_Dry"
    },
    {
      "x": -9,
      "y": 10,
      "z": 1,
      "name": "Soil_Mud_Dry"
    },
    {
      "x": -9,
      "y": 11,
      "z": 1,
      "name": "Soil_Mud_Dry"
    },
    {
      "x": -9,
      "y": 12,
      "z": 1,
      "name": "Soil_Mud_Dry"
    },
    {
      "x": -9,
      "y": 13,
      "z": 1,
      "name": "Soil_Mud_Dry"
    },
    {
      "x": -9,
      "y": 14,
      "z": 1,
      "name": "Soil_Mud_Dry"
    },
    {
      "x": -9,
      "y": 5,
      "z": 2,
      "name": "Soil_Mud_Dry"
    },
    {
      "x": -9,
      "y": 6,
      "z": 2,
      "name": "Soil_Mud_Dry"
    },
    {
      "x": -9,
      "y": 7,
      "z": 2,
      "name": "Soil_Mud_Dry"
    },
    {
      "x": -9,
      "y": 8,
      "z": 2,
      "name": "Soil_Mud_Dry"
    },
    {
      "x": -9,
      "y": 9,
      "z": 2,
      "name": "Soil_Mud_Dry"
    },
    {
      "x": -9,
      "y": 10,
      "z": 2,
      "name": "Soil_Mud_Dry"
    },
    {
      "x": -9,
      "y": 11,
      "z": 2,
      "name": "Soil_Mud_Dry"
    },
    {
      "x": -9,
      "y": 12,
      "z": 2,
      "name": "Soil_Mud_Dry"
    },
    {
      "x": -9,
      "y": 13,
      "z": 2,
      "name": "Soil_Mud_Dry"
    },
    {
      "x": -9,
      "y": 14,
      "z": 2,
      "name": "Soil_Mud_Dry"
    },
    {
      "x": -9,
      "y": 15,
      "z": 2,
      "name": "Soil_Mud_Dry"
    },
    {
      "x": -9,
      "y": 5,
      "z": 3,
      "name": "Soil_Mud_Dry"
    },
    {
      "x": -9,
      "y": 6,
      "z": 3,
      "name": "Soil_Mud_Dry"
    },
    {
      "x": -9,
      "y": 7,
      "z": 3,
      "name": "Soil_Mud_Dry"
    },
    {
      "x": -9,
      "y": 8,
      "z": 3,
      "name": "Soil_Mud_Dry"
    },
    {
      "x": -9,
      "y": 9,
      "z": 3,
      "name": "Soil_Mud_Dry"
    },
    {
      "x": -9,
      "y": 10,
      "z": 3,
      "name": "Soil_Mud_Dry"
    },
    {
      "x": -9,
      "y": 11,
      "z": 3,
      "name": "Soil_Mud_Dry"
    },
    {
      "x": -9,
      "y": 12,
      "z": 3,
      "name": "Soil_Mud_Dry"
    },
    {
      "x": -9,
      "y": 13,
      "z": 3,
      "name": "Soil_Mud_Dry"
    },
    {
      "x": -9,
      "y": 14,
      "z": 3,
      "name": "Soil_Mud_Dry"
    },
    {
      "x": -9,
      "y": 5,
      "z": 4,
      "name": "Soil_Mud_Dry"
    },
    {
      "x": -9,
      "y": 6,
      "z": 4,
      "name": "Soil_Mud_Dry"
    },
    {
      "x": -9,
      "y": 7,
      "z": 4,
      "name": "Soil_Mud_Dry"
    },
    {
      "x": -9,
      "y": 8,
      "z": 4,
      "name": "Soil_Mud_Dry"
    },
    {
      "x": -9,
      "y": 9,
      "z": 4,
      "name": "Soil_Mud_Dry"
    },
    {
      "x": -9,
      "y": 10,
      "z": 4,
      "name": "Soil_Mud_Dry"
    },
    {
      "x": -9,
      "y": 11,
      "z": 4,
      "name": "Soil_Mud_Dry"
    },
    {
      "x": -9,
      "y": 12,
      "z": 4,
      "name": "Soil_Mud_Dry"
    },
    {
      "x": -9,
      "y": 13,
      "z": 4,
      "name": "Soil_Mud_Dry"
    },
    {
      "x": -9,
      "y": 14,
      "z": 4,
      "name": "Soil_Mud_Dry"
    },
    {
      "x": -8,
      "y": 5,
      "z": -5,
      "name": "Soil_Mud_Dry"
    },
    {
      "x": -8,
      "y": 6,
      "z": -5,
      "name": "Soil_Mud_Dry"
    },
    {
      "x": -8,
      "y": 7,
      "z": -5,
      "name": "Soil_Mud_Dry"
    },
    {
      "x": -8,
      "y": 8,
      "z": -5,
      "name": "Soil_Mud_Dry"
    },
    {
      "x": -8,
      "y": 9,
      "z": -5,
      "name": "Soil_Mud_Dry"
    },
    {
      "x": -8,
      "y": 10,
      "z": -5,
      "name": "Soil_Mud_Dry"
    },
    {
      "x": -8,
      "y": 11,
      "z": -5,
      "name": "Soil_Mud_Dry"
    },
    {
      "x": -8,
      "y": 12,
      "z": -5,
      "name": "Soil_Mud_Dry"
    },
    {
      "x": -8,
      "y": 13,
      "z": -5,
      "name": "Soil_Mud_Dry"
    },
    {
      "x": -8,
      "y": 14,
      "z": -5,
      "name": "Soil_Mud_Dry"
    },
    {
      "x": -8,
      "y": 5,
      "z": -4,
      "name": "Soil_Mud_Dry"
    },
    {
      "x": -8,
      "y": 6,
      "z": -4,
      "name": "Soil_Mud_Dry"
    },
    {
      "x": -8,
      "y": 7,
      "z": -4,
      "name": "Soil_Mud_Dry"
    },
    {
      "x": -8,
      "y": 8,
      "z": -4,
      "name": "Soil_Mud_Dry"
    },
    {
      "x": -8,
      "y": 9,
      "z": -4,
      "name": "Soil_Mud_Dry"
    },
    {
      "x": -8,
      "y": 10,
      "z": -4,
      "name": "Soil_Mud_Dry"
    },
    {
      "x": -8,
      "y": 11,
      "z": -4,
      "name": "Soil_Mud_Dry"
    },
    {
      "x": -8,
      "y": 12,
      "z": -4,
      "name": "Soil_Mud_Dry"
    },
    {
      "x": -8,
      "y": 13,
      "z": -4,
      "name": "Soil_Mud_Dry"
    },
    {
      "x": -8,
      "y": 14,
      "z": -4,
      "name": "Soil_Mud_Dry"
    },
    {
      "x": -8,
      "y": 5,
      "z": -3,
      "name": "Soil_Mud_Dry"
    },
    {
      "x": -8,
      "y": 6,
      "z": -3,
      "name": "Soil_Mud_Dry"
    },
    {
      "x": -8,
      "y": 7,
      "z": -3,
      "name": "Soil_Mud_Dry"
    },
    {
      "x": -8,
      "y": 8,
      "z": -3,
      "name": "Soil_Mud_Dry"
    },
    {
      "x": -8,
      "y": 9,
      "z": -3,
      "name": "Soil_Mud_Dry"
    },
    {
      "x": -8,
      "y": 10,
      "z": -3,
      "name": "Soil_Mud_Dry"
    },
    {
      "x": -8,
      "y": 11,
      "z": -3,
      "name": "Soil_Mud_Dry"
    },
    {
      "x": -8,
      "y": 12,
      "z": -3,
      "name": "Soil_Mud_Dry"
    },
    {
      "x": -8,
      "y": 13,
      "z": -3,
      "name": "Soil_Mud_Dry"
    },
    {
      "x": -8,
      "y": 14,
      "z": -3,
      "name": "Soil_Mud_Dry"
    },
    {
      "x": -8,
      "y": 15,
      "z": -3,
      "name": "Soil_Mud_Dry"
    },
    {
      "x": -8,
      "y": 5,
      "z": -2,
      "name": "Soil_Mud_Dry"
    },
    {
      "x": -8,
      "y": 6,
      "z": -2,
      "name": "Soil_Mud_Dry"
    },
    {
      "x": -8,
      "y": 7,
      "z": -2,
      "name": "Empty"
    },
    {
      "x": -8,
      "y": 8,
      "z": -2,
      "name": "Empty"
    },
    {
      "x": -8,
      "y": 9,
      "z": -2,
      "name": "Soil_Mud_Dry"
    },
    {
      "x": -8,
      "y": 10,
      "z": -2,
      "name": "Soil_Mud_Dry"
    },
    {
      "x": -8,
      "y": 11,
      "z": -2,
      "name": "Soil_Mud_Dry"
    },
    {
      "x": -8,
      "y": 12,
      "z": -2,
      "name": "Soil_Mud_Dry"
    },
    {
      "x": -8,
      "y": 13,
      "z": -2,
      "name": "Soil_Mud_Dry"
    },
    {
      "x": -8,
      "y": 14,
      "z": -2,
      "name": "Soil_Mud_Dry"
    },
    {
      "x": -8,
      "y": 15,
      "z": -2,
      "name": "Soil_Mud_Dry"
    },
    {
      "x": -8,
      "y": 4,
      "z": -1,
      "name": "Soil_Mud_Dry"
    },
    {
      "x": -8,
      "y": 5,
      "z": -1,
      "name": "Soil_Mud_Dry"
    },
    {
      "x": -8,
      "y": 6,
      "z": -1,
      "name": "Empty"
    },
    {
      "x": -8,
      "y": 7,
      "z": -1,
      "name": "Empty"
    },
    {
      "x": -8,
      "y": 8,
      "z": -1,
      "name": "Empty"
    },
    {
      "x": -8,
      "y": 9,
      "z": -1,
      "name": "Empty"
    },
    {
      "x": -8,
      "y": 10,
      "z": -1,
      "name": "Empty"
    },
    {
      "x": -8,
      "y": 11,
      "z": -1,
      "name": "Soil_Mud_Dry"
    },
    {
      "x": -8,
      "y": 12,
      "z": -1,
      "name": "Soil_Mud_Dry"
    },
    {
      "x": -8,
      "y": 13,
      "z": -1,
      "name": "Soil_Mud_Dry"
    },
    {
      "x": -8,
      "y": 14,
      "z": -1,
      "name": "Soil_Mud_Dry"
    },
    {
      "x": -8,
      "y": 15,
      "z": -1,
      "name": "Soil_Mud_Dry"
    },
    {
      "x": -8,
      "y": 4,
      "z": 0,
      "name": "Soil_Mud_Dry"
    },
    {
      "x": -8,
      "y": 5,
      "z": 0,
      "name": "Soil_Mud_Dry"
    },
    {
      "x": -8,
      "y": 6,
      "z": 0,
      "name": "Empty"
    },
    {
      "x": -8,
      "y": 7,
      "z": 0,
      "name": "Empty"
    },
    {
      "x": -8,
      "y": 8,
      "z": 0,
      "name": "Empty"
    },
    {
      "x": -8,
      "y": 9,
      "z": 0,
      "name": "Empty"
    },
    {
      "x": -8,
      "y": 10,
      "z": 0,
      "name": "Empty"
    },
    {
      "x": -8,
      "y": 11,
      "z": 0,
      "name": "Soil_Mud_Dry"
    },
    {
      "x": -8,
      "y": 12,
      "z": 0,
      "name": "Soil_Mud_Dry"
    },
    {
      "x": -8,
      "y": 13,
      "z": 0,
      "name": "Soil_Mud_Dry"
    },
    {
      "x": -8,
      "y": 14,
      "z": 0,
      "name": "Soil_Mud_Dry"
    },
    {
      "x": -8,
      "y": 15,
      "z": 0,
      "name": "Soil_Mud_Dry"
    },
    {
      "x": -8,
      "y": 5,
      "z": 1,
      "name": "Soil_Mud_Dry"
    },
    {
      "x": -8,
      "y": 6,
      "z": 1,
      "name": "Soil_Mud_Dry"
    },
    {
      "x": -8,
      "y": 7,
      "z": 1,
      "name": "Soil_Mud_Dry"
    },
    {
      "x": -8,
      "y": 8,
      "z": 1,
      "name": "Empty"
    },
    {
      "x": -8,
      "y": 9,
      "z": 1,
      "name": "Empty"
    },
    {
      "x": -8,
      "y": 10,
      "z": 1,
      "name": "Empty"
    },
    {
      "x": -8,
      "y": 11,
      "z": 1,
      "name": "Soil_Mud_Dry"
    },
    {
      "x": -8,
      "y": 12,
      "z": 1,
      "name": "Soil_Mud_Dry"
    },
    {
      "x": -8,
      "y": 13,
      "z": 1,
      "name": "Soil_Mud_Dry"
    },
    {
      "x": -8,
      "y": 14,
      "z": 1,
      "name": "Soil_Mud_Dry"
    },
    {
      "x": -8,
      "y": 15,
      "z": 1,
      "name": "Soil_Mud_Dry"
    },
    {
      "x": -8,
      "y": 4,
      "z": 2,
      "name": "Soil_Mud_Dry"
    },
    {
      "x": -8,
      "y": 5,
      "z": 2,
      "name": "Soil_Mud_Dry"
    },
    {
      "x": -8,
      "y": 6,
      "z": 2,
      "name": "Soil_Mud_Dry"
    },
    {
      "x": -8,
      "y": 7,
      "z": 2,
      "name": "Soil_Mud_Dry"
    },
    {
      "x": -8,
      "y": 8,
      "z": 2,
      "name": "Empty"
    },
    {
      "x": -8,
      "y": 9,
      "z": 2,
      "name": "Empty"
    },
    {
      "x": -8,
      "y": 10,
      "z": 2,
      "name": "Soil_Mud_Dry"
    },
    {
      "x": -8,
      "y": 11,
      "z": 2,
      "name": "Soil_Mud_Dry"
    },
    {
      "x": -8,
      "y": 12,
      "z": 2,
      "name": "Soil_Mud_Dry"
    },
    {
      "x": -8,
      "y": 13,
      "z": 2,
      "name": "Soil_Mud_Dry"
    },
    {
      "x": -8,
      "y": 14,
      "z": 2,
      "name": "Soil_Mud_Dry"
    },
    {
      "x": -8,
      "y": 15,
      "z": 2,
      "name": "Soil_Mud_Dry"
    },
    {
      "x": -8,
      "y": 4,
      "z": 3,
      "name": "Soil_Mud_Dry"
    },
    {
      "x": -8,
      "y": 5,
      "z": 3,
      "name": "Soil_Mud_Dry"
    },
    {
      "x": -8,
      "y": 6,
      "z": 3,
      "name": "Soil_Mud_Dry"
    },
    {
      "x": -8,
      "y": 7,
      "z": 3,
      "name": "Soil_Mud_Dry"
    },
    {
      "x": -8,
      "y": 8,
      "z": 3,
      "name": "Soil_Mud_Dry"
    },
    {
      "x": -8,
      "y": 9,
      "z": 3,
      "name": "Soil_Mud_Dry"
    },
    {
      "x": -8,
      "y": 10,
      "z": 3,
      "name": "Soil_Mud_Dry"
    },
    {
      "x": -8,
      "y": 11,
      "z": 3,
      "name": "Soil_Mud_Dry"
    },
    {
      "x": -8,
      "y": 12,
      "z": 3,
      "name": "Soil_Mud_Dry"
    },
    {
      "x": -8,
      "y": 13,
      "z": 3,
      "name": "Soil_Mud_Dry"
    },
    {
      "x": -8,
      "y": 14,
      "z": 3,
      "name": "Soil_Mud_Dry"
    },
    {
      "x": -8,
      "y": 15,
      "z": 3,
      "name": "Soil_Mud_Dry"
    },
    {
      "x": -8,
      "y": 5,
      "z": 4,
      "name": "Soil_Mud_Dry"
    },
    {
      "x": -8,
      "y": 6,
      "z": 4,
      "name": "Soil_Mud_Dry"
    },
    {
      "x": -8,
      "y": 7,
      "z": 4,
      "name": "Soil_Mud_Dry"
    },
    {
      "x": -8,
      "y": 8,
      "z": 4,
      "name": "Soil_Mud_Dry"
    },
    {
      "x": -8,
      "y": 9,
      "z": 4,
      "name": "Soil_Mud_Dry"
    },
    {
      "x": -8,
      "y": 10,
      "z": 4,
      "name": "Soil_Mud_Dry"
    },
    {
      "x": -8,
      "y": 11,
      "z": 4,
      "name": "Soil_Mud_Dry"
    },
    {
      "x": -8,
      "y": 12,
      "z": 4,
      "name": "Soil_Mud_Dry"
    },
    {
      "x": -8,
      "y": 13,
      "z": 4,
      "name": "Soil_Mud_Dry"
    },
    {
      "x": -8,
      "y": 14,
      "z": 4,
      "name": "Soil_Mud_Dry"
    },
    {
      "x": -8,
      "y": 15,
      "z": 4,
      "name": "Soil_Mud_Dry"
    },
    {
      "x": -8,
      "y": 5,
      "z": 5,
      "name": "Soil_Mud_Dry"
    },
    {
      "x": -8,
      "y": 6,
      "z": 5,
      "name": "Soil_Mud_Dry"
    },
    {
      "x": -8,
      "y": 7,
      "z": 5,
      "name": "Soil_Mud_Dry"
    },
    {
      "x": -8,
      "y": 8,
      "z": 5,
      "name": "Soil_Mud_Dry"
    },
    {
      "x": -8,
      "y": 9,
      "z": 5,
      "name": "Soil_Mud_Dry"
    },
    {
      "x": -8,
      "y": 10,
      "z": 5,
      "name": "Soil_Mud_Dry"
    },
    {
      "x": -8,
      "y": 11,
      "z": 5,
      "name": "Soil_Mud_Dry"
    },
    {
      "x": -8,
      "y": 12,
      "z": 5,
      "name": "Soil_Mud_Dry"
    },
    {
      "x": -8,
      "y": 13,
      "z": 5,
      "name": "Soil_Mud_Dry"
    },
    {
      "x": -8,
      "y": 14,
      "z": 5,
      "name": "Soil_Mud_Dry"
    },
    {
      "x": -7,
      "y": 5,
      "z": -5,
      "name": "Soil_Mud_Dry"
    },
    {
      "x": -7,
      "y": 6,
      "z": -5,
      "name": "Soil_Mud_Dry"
    },
    {
      "x": -7,
      "y": 7,
      "z": -5,
      "name": "Soil_Mud_Dry"
    },
    {
      "x": -7,
      "y": 8,
      "z": -5,
      "name": "Soil_Mud_Dry"
    },
    {
      "x": -7,
      "y": 9,
      "z": -5,
      "name": "Soil_Mud_Dry"
    },
    {
      "x": -7,
      "y": 10,
      "z": -5,
      "name": "Soil_Mud_Dry"
    },
    {
      "x": -7,
      "y": 11,
      "z": -5,
      "name": "Soil_Mud_Dry"
    },
    {
      "x": -7,
      "y": 12,
      "z": -5,
      "name": "Soil_Mud_Dry"
    },
    {
      "x": -7,
      "y": 13,
      "z": -5,
      "name": "Soil_Mud_Dry"
    },
    {
      "x": -7,
      "y": 14,
      "z": -5,
      "name": "Soil_Mud_Dry"
    },
    {
      "x": -7,
      "y": 4,
      "z": -4,
      "name": "Soil_Mud_Dry"
    },
    {
      "x": -7,
      "y": 5,
      "z": -4,
      "name": "Soil_Mud_Dry"
    },
    {
      "x": -7,
      "y": 6,
      "z": -4,
      "name": "Soil_Mud_Dry"
    },
    {
      "x": -7,
      "y": 7,
      "z": -4,
      "name": "Soil_Mud_Dry"
    },
    {
      "x": -7,
      "y": 8,
      "z": -4,
      "name": "Soil_Mud_Dry"
    },
    {
      "x": -7,
      "y": 9,
      "z": -4,
      "name": "Soil_Mud_Dry"
    },
    {
      "x": -7,
      "y": 10,
      "z": -4,
      "name": "Soil_Mud_Dry"
    },
    {
      "x": -7,
      "y": 11,
      "z": -4,
      "name": "Soil_Mud_Dry"
    },
    {
      "x": -7,
      "y": 12,
      "z": -4,
      "name": "Soil_Mud_Dry"
    },
    {
      "x": -7,
      "y": 13,
      "z": -4,
      "name": "Soil_Mud_Dry"
    },
    {
      "x": -7,
      "y": 14,
      "z": -4,
      "name": "Soil_Mud_Dry"
    },
    {
      "x": -7,
      "y": 15,
      "z": -4,
      "name": "Soil_Mud_Dry"
    },
    {
      "x": -7,
      "y": 4,
      "z": -3,
      "name": "Soil_Mud_Dry"
    },
    {
      "x": -7,
      "y": 5,
      "z": -3,
      "name": "Soil_Mud_Dry"
    },
    {
      "x": -7,
      "y": 6,
      "z": -3,
      "name": "Soil_Mud_Dry"
    },
    {
      "x": -7,
      "y": 7,
      "z": -3,
      "name": "Soil_Mud_Dry"
    },
    {
      "x": -7,
      "y": 8,
      "z": -3,
      "name": "Soil_Mud_Dry"
    },
    {
      "x": -7,
      "y": 9,
      "z": -3,
      "name": "Soil_Mud_Dry"
    },
    {
      "x": -7,
      "y": 10,
      "z": -3,
      "name": "Empty"
    },
    {
      "x": -7,
      "y": 11,
      "z": -3,
      "name": "Empty"
    },
    {
      "x": -7,
      "y": 12,
      "z": -3,
      "name": "Empty"
    },
    {
      "x": -7,
      "y": 13,
      "z": -3,
      "name": "Soil_Mud_Dry"
    },
    {
      "x": -7,
      "y": 14,
      "z": -3,
      "name": "Soil_Mud_Dry"
    },
    {
      "x": -7,
      "y": 15,
      "z": -3,
      "name": "Soil_Mud_Dry"
    },
    {
      "x": -7,
      "y": 16,
      "z": -3,
      "name": "Soil_Mud_Dry"
    },
    {
      "x": -7,
      "y": 4,
      "z": -2,
      "name": "Soil_Mud_Dry"
    },
    {
      "x": -7,
      "y": 5,
      "z": -2,
      "name": "Empty"
    },
    {
      "x": -7,
      "y": 6,
      "z": -2,
      "name": "Empty"
    },
    {
      "x": -7,
      "y": 7,
      "z": -2,
      "name": "Empty"
    },
    {
      "x": -7,
      "y": 8,
      "z": -2,
      "name": "Empty"
    },
    {
      "x": -7,
      "y": 9,
      "z": -2,
      "name": "Empty"
    },
    {
      "x": -7,
      "y": 10,
      "z": -2,
      "name": "Empty"
    },
    {
      "x": -7,
      "y": 11,
      "z": -2,
      "name": "Empty"
    },
    {
      "x": -7,
      "y": 12,
      "z": -2,
      "name": "Empty"
    },
    {
      "x": -7,
      "y": 13,
      "z": -2,
      "name": "Soil_Mud_Dry"
    },
    {
      "x": -7,
      "y": 14,
      "z": -2,
      "name": "Soil_Mud_Dry"
    },
    {
      "x": -7,
      "y": 15,
      "z": -2,
      "name": "Soil_Mud_Dry"
    },
    {
      "x": -7,
      "y": 16,
      "z": -2,
      "name": "Soil_Mud_Dry"
    },
    {
      "x": -7,
      "y": 4,
      "z": -1,
      "name": "Soil_Mud_Dry"
    },
    {
      "x": -7,
      "y": 5,
      "z": -1,
      "name": "Empty"
    },
    {
      "x": -7,
      "y": 6,
      "z": -1,
      "name": "Empty"
    },
    {
      "x": -7,
      "y": 7,
      "z": -1,
      "name": "Deco_Scarak_Eggsacks",
      "rotation": 8
    },
    {
      "x": -7,
      "y": 8,
      "z": -1,
      "name": "Soil_Hive"
    },
    {
      "x": -7,
      "y": 9,
      "z": -1,
      "name": "Soil_Hive"
    },
    {
      "x": -7,
      "y": 10,
      "z": -1,
      "name": "Soil_Hive"
    },
    {
      "x": -7,
      "y": 11,
      "z": -1,
      "name": "Empty"
    },
    {
      "x": -7,
      "y": 12,
      "z": -1,
      "name": "Empty"
    },
    {
      "x": -7,
      "y": 13,
      "z": -1,
      "name": "Empty"
    },
    {
      "x": -7,
      "y": 14,
      "z": -1,
      "name": "Soil_Mud_Dry"
    },
    {
      "x": -7,
      "y": 15,
      "z": -1,
      "name": "Soil_Mud_Dry"
    },
    {
      "x": -7,
      "y": 16,
      "z": -1,
      "name": "Soil_Mud_Dry"
    },
    {
      "x": -7,
      "y": 3,
      "z": 0,
      "name": "Soil_Mud_Dry"
    },
    {
      "x": -7,
      "y": 4,
      "z": 0,
      "name": "Soil_Mud_Dry"
    },
    {
      "x": -7,
      "y": 5,
      "z": 0,
      "name": "Soil_Mud_Dry"
    },
    {
      "x": -7,
      "y": 6,
      "z": 0,
      "name": "Soil_Hive"
    },
    {
      "x": -7,
      "y": 7,
      "z": 0,
      "name": "Soil_Hive"
    },
    {
      "x": -7,
      "y": 8,
      "z": 0,
      "name": "Soil_Hive"
    },
    {
      "x": -7,
      "y": 9,
      "z": 0,
      "name": "Empty"
    },
    {
      "x": -7,
      "y": 10,
      "z": 0,
      "name": "Soil_Hive"
    },
    {
      "x": -7,
      "y": 11,
      "z": 0,
      "name": "Soil_Hive"
    },
    {
      "x": -7,
      "y": 12,
      "z": 0,
      "name": "Soil_Hive"
    },
    {
      "x": -7,
      "y": 13,
      "z": 0,
      "name": "Soil_Hive"
    },
    {
      "x": -7,
      "y": 14,
      "z": 0,
      "name": "Soil_Mud_Dry"
    },
    {
      "x": -7,
      "y": 15,
      "z": 0,
      "name": "Soil_Mud_Dry"
    },
    {
      "x": -7,
      "y": 16,
      "z": 0,
      "name": "Soil_Mud_Dry"
    },
    {
      "x": -7,
      "y": 4,
      "z": 1,
      "name": "Soil_Mud_Dry"
    },
    {
      "x": -7,
      "y": 5,
      "z": 1,
      "name": "Soil_Mud_Dry"
    },
    {
      "x": -7,
      "y": 6,
      "z": 1,
      "name": "Empty"
    },
    {
      "x": -7,
      "y": 7,
      "z": 1,
      "name": "Empty"
    },
    {
      "x": -7,
      "y": 8,
      "z": 1,
      "name": "Empty"
    },
    {
      "x": -7,
      "y": 9,
      "z": 1,
      "name": "Empty"
    },
    {
      "x": -7,
      "y": 10,
      "z": 1,
      "name": "Empty"
    },
    {
      "x": -7,
      "y": 11,
      "z": 1,
      "name": "Empty"
    },
    {
      "x": -7,
      "y": 12,
      "z": 1,
      "name": "Soil_Hive"
    },
    {
      "x": -7,
      "y": 13,
      "z": 1,
      "name": "Soil_Mud_Dry"
    },
    {
      "x": -7,
      "y": 14,
      "z": 1,
      "name": "Soil_Mud_Dry"
    },
    {
      "x": -7,
      "y": 15,
      "z": 1,
      "name": "Soil_Mud_Dry"
    },
    {
      "x": -7,
      "y": 16,
      "z": 1,
      "name": "Soil_Mud_Dry"
    },
    {
      "x": -7,
      "y": 4,
      "z": 2,
      "name": "Soil_Mud_Dry"
    },
    {
      "x": -7,
      "y": 5,
      "z": 2,
      "name": "Soil_Mud_Dry"
    },
    {
      "x": -7,
      "y": 6,
      "z": 2,
      "name": "Soil_Mud_Dry"
    },
    {
      "x": -7,
      "y": 7,
      "z": 2,
      "name": "Empty"
    },
    {
      "x": -7,
      "y": 8,
      "z": 2,
      "name": "Empty"
    },
    {
      "x": -7,
      "y": 9,
      "z": 2,
      "name": "Empty"
    },
    {
      "x": -7,
      "y": 10,
      "z": 2,
      "name": "Empty"
    },
    {
      "x": -7,
      "y": 11,
      "z": 2,
      "name": "Empty"
    },
    {
      "x": -7,
      "y": 12,
      "z": 2,
      "name": "Soil_Hive"
    },
    {
      "x": -7,
      "y": 13,
      "z": 2,
      "name": "Soil_Mud_Dry"
    },
    {
      "x": -7,
      "y": 14,
      "z": 2,
      "name": "Soil_Mud_Dry"
    },
    {
      "x": -7,
      "y": 15,
      "z": 2,
      "name": "Soil_Mud_Dry"
    },
    {
      "x": -7,
      "y": 16,
      "z": 2,
      "name": "Soil_Mud_Dry"
    },
    {
      "x": -7,
      "y": 3,
      "z": 3,
      "name": "Soil_Mud_Dry"
    },
    {
      "x": -7,
      "y": 4,
      "z": 3,
      "name": "Soil_Mud_Dry"
    },
    {
      "x": -7,
      "y": 5,
      "z": 3,
      "name": "Soil_Mud_Dry"
    },
    {
      "x": -7,
      "y": 6,
      "z": 3,
      "name": "Soil_Mud_Dry"
    },
    {
      "x": -7,
      "y": 7,
      "z": 3,
      "name": "Soil_Mud_Dry"
    },
    {
      "x": -7,
      "y": 8,
      "z": 3,
      "name": "Soil_Mud_Dry"
    },
    {
      "x": -7,
      "y": 9,
      "z": 3,
      "name": "Soil_Mud_Dry"
    },
    {
      "x": -7,
      "y": 10,
      "z": 3,
      "name": "Soil_Mud_Dry"
    },
    {
      "x": -7,
      "y": 11,
      "z": 3,
      "name": "Empty"
    },
    {
      "x": -7,
      "y": 12,
      "z": 3,
      "name": "Empty"
    },
    {
      "x": -7,
      "y": 13,
      "z": 3,
      "name": "Soil_Mud_Dry"
    },
    {
      "x": -7,
      "y": 14,
      "z": 3,
      "name": "Soil_Mud_Dry"
    },
    {
      "x": -7,
      "y": 15,
      "z": 3,
      "name": "Soil_Mud_Dry"
    },
    {
      "x": -7,
      "y": 16,
      "z": 3,
      "name": "Soil_Mud_Dry"
    },
    {
      "x": -7,
      "y": 4,
      "z": 4,
      "name": "Soil_Mud_Dry"
    },
    {
      "x": -7,
      "y": 5,
      "z": 4,
      "name": "Soil_Mud_Dry"
    },
    {
      "x": -7,
      "y": 6,
      "z": 4,
      "name": "Soil_Mud_Dry"
    },
    {
      "x": -7,
      "y": 7,
      "z": 4,
      "name": "Soil_Mud_Dry"
    },
    {
      "x": -7,
      "y": 8,
      "z": 4,
      "name": "Soil_Mud_Dry"
    },
    {
      "x": -7,
      "y": 9,
      "z": 4,
      "name": "Soil_Mud_Dry"
    },
    {
      "x": -7,
      "y": 10,
      "z": 4,
      "name": "Soil_Mud_Dry"
    },
    {
      "x": -7,
      "y": 11,
      "z": 4,
      "name": "Soil_Mud_Dry"
    },
    {
      "x": -7,
      "y": 12,
      "z": 4,
      "name": "Soil_Mud_Dry"
    },
    {
      "x": -7,
      "y": 13,
      "z": 4,
      "name": "Soil_Mud_Dry"
    },
    {
      "x": -7,
      "y": 14,
      "z": 4,
      "name": "Soil_Mud_Dry"
    },
    {
      "x": -7,
      "y": 15,
      "z": 4,
      "name": "Soil_Mud_Dry"
    },
    {
      "x": -7,
      "y": 4,
      "z": 5,
      "name": "Soil_Mud_Dry"
    },
    {
      "x": -7,
      "y": 5,
      "z": 5,
      "name": "Soil_Mud_Dry"
    },
    {
      "x": -7,
      "y": 6,
      "z": 5,
      "name": "Soil_Mud_Dry"
    },
    {
      "x": -7,
      "y": 7,
      "z": 5,
      "name": "Soil_Mud_Dry"
    },
    {
      "x": -7,
      "y": 8,
      "z": 5,
      "name": "Soil_Mud_Dry"
    },
    {
      "x": -7,
      "y": 9,
      "z": 5,
      "name": "Soil_Mud_Dry"
    },
    {
      "x": -7,
      "y": 10,
      "z": 5,
      "name": "Soil_Mud_Dry"
    },
    {
      "x": -7,
      "y": 11,
      "z": 5,
      "name": "Soil_Mud_Dry"
    },
    {
      "x": -7,
      "y": 12,
      "z": 5,
      "name": "Soil_Mud_Dry"
    },
    {
      "x": -7,
      "y": 13,
      "z": 5,
      "name": "Soil_Mud_Dry"
    },
    {
      "x": -7,
      "y": 14,
      "z": 5,
      "name": "Soil_Mud_Dry"
    },
    {
      "x": -6,
      "y": 4,
      "z": -5,
      "name": "Soil_Mud_Dry"
    },
    {
      "x": -6,
      "y": 5,
      "z": -5,
      "name": "Soil_Mud_Dry"
    },
    {
      "x": -6,
      "y": 6,
      "z": -5,
      "name": "Soil_Mud_Dry"
    },
    {
      "x": -6,
      "y": 7,
      "z": -5,
      "name": "Soil_Mud_Dry"
    },
    {
      "x": -6,
      "y": 8,
      "z": -5,
      "name": "Soil_Mud_Dry"
    },
    {
      "x": -6,
      "y": 9,
      "z": -5,
      "name": "Soil_Mud_Dry"
    },
    {
      "x": -6,
      "y": 10,
      "z": -5,
      "name": "Soil_Mud_Dry"
    },
    {
      "x": -6,
      "y": 11,
      "z": -5,
      "name": "Soil_Mud_Dry"
    },
    {
      "x": -6,
      "y": 12,
      "z": -5,
      "name": "Soil_Mud_Dry"
    },
    {
      "x": -6,
      "y": 13,
      "z": -5,
      "name": "Soil_Mud_Dry"
    },
    {
      "x": -6,
      "y": 14,
      "z": -5,
      "name": "Soil_Mud_Dry"
    },
    {
      "x": -6,
      "y": 15,
      "z": -5,
      "name": "Soil_Mud_Dry"
    },
    {
      "x": -6,
      "y": 4,
      "z": -4,
      "name": "Soil_Mud_Dry"
    },
    {
      "x": -6,
      "y": 5,
      "z": -4,
      "name": "Soil_Mud_Dry"
    },
    {
      "x": -6,
      "y": 6,
      "z": -4,
      "name": "Soil_Mud_Dry"
    },
    {
      "x": -6,
      "y": 7,
      "z": -4,
      "name": "Soil_Mud_Dry"
    },
    {
      "x": -6,
      "y": 8,
      "z": -4,
      "name": "Empty"
    },
    {
      "x": -6,
      "y": 9,
      "z": -4,
      "name": "Empty"
    },
    {
      "x": -6,
      "y": 10,
      "z": -4,
      "name": "Empty"
    },
    {
      "x": -6,
      "y": 11,
      "z": -4,
      "name": "Soil_Mud_Dry"
    },
    {
      "x": -6,
      "y": 12,
      "z": -4,
      "name": "Soil_Mud_Dry"
    },
    {
      "x": -6,
      "y": 13,
      "z": -4,
      "name": "Soil_Mud_Dry"
    },
    {
      "x": -6,
      "y": 14,
      "z": -4,
      "name": "Soil_Mud_Dry"
    },
    {
      "x": -6,
      "y": 15,
      "z": -4,
      "name": "Soil_Mud_Dry"
    },
    {
      "x": -6,
      "y": 3,
      "z": -3,
      "name": "Soil_Mud_Dry"
    },
    {
      "x": -6,
      "y": 4,
      "z": -3,
      "name": "Soil_Mud_Dry"
    },
    {
      "x": -6,
      "y": 5,
      "z": -3,
      "name": "Empty"
    },
    {
      "x": -6,
      "y": 6,
      "z": -3,
      "name": "Empty"
    },
    {
      "x": -6,
      "y": 7,
      "z": -3,
      "name": "Empty"
    },
    {
      "x": -6,
      "y": 8,
      "z": -3,
      "name": "Empty"
    },
    {
      "x": -6,
      "y": 9,
      "z": -3,
      "name": "Empty"
    },
    {
      "x": -6,
      "y": 10,
      "z": -3,
      "name": "Empty"
    },
    {
      "x": -6,
      "y": 11,
      "z": -3,
      "name": "Empty"
    },
    {
      "x": -6,
      "y": 12,
      "z": -3,
      "name": "Empty"
    },
    {
      "x": -6,
      "y": 13,
      "z": -3,
      "name": "Soil_Mud_Dry"
    },
    {
      "x": -6,
      "y": 14,
      "z": -3,
      "name": "Soil_Mud_Dry"
    },
    {
      "x": -6,
      "y": 15,
      "z": -3,
      "name": "Soil_Mud_Dry"
    },
    {
      "x": -6,
      "y": 16,
      "z": -3,
      "name": "Soil_Mud_Dry"
    },
    {
      "x": -6,
      "y": 4,
      "z": -2,
      "name": "Soil_Mud_Dry"
    },
    {
      "x": -6,
      "y": 5,
      "z": -2,
      "name": "Empty"
    },
    {
      "x": -6,
      "y": 6,
      "z": -2,
      "name": "Empty"
    },
    {
      "x": -6,
      "y": 7,
      "z": -2,
      "name": "Empty"
    },
    {
      "x": -6,
      "y": 8,
      "z": -2,
      "name": "Empty"
    },
    {
      "x": -6,
      "y": 9,
      "z": -2,
      "name": "Empty"
    },
    {
      "x": -6,
      "y": 10,
      "z": -2,
      "name": "Empty"
    },
    {
      "x": -6,
      "y": 11,
      "z": -2,
      "name": "Empty"
    },
    {
      "x": -6,
      "y": 12,
      "z": -2,
      "name": "Empty"
    },
    {
      "x": -6,
      "y": 13,
      "z": -2,
      "name": "Soil_Mud_Dry"
    },
    {
      "x": -6,
      "y": 14,
      "z": -2,
      "name": "Soil_Mud_Dry"
    },
    {
      "x": -6,
      "y": 15,
      "z": -2,
      "name": "Soil_Mud_Dry"
    },
    {
      "x": -6,
      "y": 16,
      "z": -2,
      "name": "Soil_Mud_Dry"
    },
    {
      "x": -6,
      "y": 4,
      "z": -1,
      "name": "Soil_Mud_Dry"
    },
    {
      "x": -6,
      "y": 5,
      "z": -1,
      "name": "Empty"
    },
    {
      "x": -6,
      "y": 6,
      "z": -1,
      "name": "Empty"
    },
    {
      "x": -6,
      "y": 7,
      "z": -1,
      "name": "Empty"
    },
    {
      "x": -6,
      "y": 8,
      "z": -1,
      "name": "Deco_Scarak_Eggsacks",
      "rotation": 5
    },
    {
      "x": -6,
      "y": 9,
      "z": -1,
      "name": "Empty"
    },
    {
      "x": -6,
      "y": 10,
      "z": -1,
      "name": "Empty"
    },
    {
      "x": -6,
      "y": 11,
      "z": -1,
      "name": "Empty"
    },
    {
      "x": -6,
      "y": 12,
      "z": -1,
      "name": "Empty"
    },
    {
      "x": -6,
      "y": 13,
      "z": -1,
      "name": "Empty"
    },
    {
      "x": -6,
      "y": 14,
      "z": -1,
      "name": "Empty"
    },
    {
      "x": -6,
      "y": 15,
      "z": -1,
      "name": "Soil_Mud_Dry"
    },
    {
      "x": -6,
      "y": 16,
      "z": -1,
      "name": "Soil_Mud_Dry"
    },
    {
      "x": -6,
      "y": 4,
      "z": 0,
      "name": "Soil_Hive"
    },
    {
      "x": -6,
      "y": 5,
      "z": 0,
      "name": "Soil_Hive"
    },
    {
      "x": -6,
      "y": 6,
      "z": 0,
      "name": "Soil_Hive"
    },
    {
      "x": -6,
      "y": 7,
      "z": 0,
      "name": "Deco_Scarak_Eggsacks"
    },
    {
      "x": -6,
      "y": 8,
      "z": 0,
      "name": "Empty"
    },
    {
      "x": -6,
      "y": 9,
      "z": 0,
      "name": "Empty"
    },
    {
      "x": -6,
      "y": 10,
      "z": 0,
      "name": "Empty"
    },
    {
      "x": -6,
      "y": 11,
      "z": 0,
      "name": "Empty"
    },
    {
      "x": -6,
      "y": 12,
      "z": 0,
      "name": "Empty"
    },
    {
      "x": -6,
      "y": 13,
      "z": 0,
      "name": "Empty"
    },
    {
      "x": -6,
      "y": 14,
      "z": 0,
      "name": "Empty"
    },
    {
      "x": -6,
      "y": 15,
      "z": 0,
      "name": "Soil_Mud_Dry"
    },
    {
      "x": -6,
      "y": 16,
      "z": 0,
      "name": "Soil_Mud_Dry"
    },
    {
      "x": -6,
      "y": 3,
      "z": 1,
      "name": "Soil_Mud_Dry"
    },
    {
      "x": -6,
      "y": 4,
      "z": 1,
      "name": "Soil_Mud_Dry"
    },
    {
      "x": -6,
      "y": 5,
      "z": 1,
      "name": "Empty"
    },
    {
      "x": -6,
      "y": 6,
      "z": 1,
      "name": "Empty"
    },
    {
      "x": -6,
      "y": 7,
      "z": 1,
      "name": "Empty"
    },
    {
      "x": -6,
      "y": 8,
      "z": 1,
      "name": "Empty"
    },
    {
      "x": -6,
      "y": 9,
      "z": 1,
      "name": "Empty"
    },
    {
      "x": -6,
      "y": 10,
      "z": 1,
      "name": "Empty"
    },
    {
      "x": -6,
      "y": 11,
      "z": 1,
      "name": "Empty"
    },
    {
      "x": -6,
      "y": 12,
      "z": 1,
      "name": "Empty"
    },
    {
      "x": -6,
      "y": 13,
      "z": 1,
      "name": "Empty"
    },
    {
      "x": -6,
      "y": 14,
      "z": 1,
      "name": "Empty"
    },
    {
      "x": -6,
      "y": 15,
      "z": 1,
      "name": "Soil_Mud_Dry"
    },
    {
      "x": -6,
      "y": 16,
      "z": 1,
      "name": "Soil_Mud_Dry"
    },
    {
      "x": -6,
      "y": 3,
      "z": 2,
      "name": "Soil_Mud_Dry"
    },
    {
      "x": -6,
      "y": 4,
      "z": 2,
      "name": "Soil_Mud_Dry"
    },
    {
      "x": -6,
      "y": 5,
      "z": 2,
      "name": "Empty"
    },
    {
      "x": -6,
      "y": 6,
      "z": 2,
      "name": "Empty"
    },
    {
      "x": -6,
      "y": 7,
      "z": 2,
      "name": "Empty"
    },
    {
      "x": -6,
      "y": 8,
      "z": 2,
      "name": "Empty"
    },
    {
      "x": -6,
      "y": 9,
      "z": 2,
      "name": "Empty"
    },
    {
      "x": -6,
      "y": 10,
      "z": 2,
      "name": "Empty"
    },
    {
      "x": -6,
      "y": 11,
      "z": 2,
      "name": "Empty"
    },
    {
      "x": -6,
      "y": 12,
      "z": 2,
      "name": "Deco_Scarak_Eggsacks",
      "rotation": 8
    },
    {
      "x": -6,
      "y": 13,
      "z": 2,
      "name": "Soil_Hive"
    },
    {
      "x": -6,
      "y": 14,
      "z": 2,
      "name": "Soil_Mud_Dry"
    },
    {
      "x": -6,
      "y": 15,
      "z": 2,
      "name": "Soil_Mud_Dry"
    },
    {
      "x": -6,
      "y": 16,
      "z": 2,
      "name": "Soil_Mud_Dry"
    },
    {
      "x": -6,
      "y": 3,
      "z": 3,
      "name": "Soil_Mud_Dry"
    },
    {
      "x": -6,
      "y": 4,
      "z": 3,
      "name": "Soil_Mud_Dry"
    },
    {
      "x": -6,
      "y": 5,
      "z": 3,
      "name": "Soil_Mud_Dry"
    },
    {
      "x": -6,
      "y": 6,
      "z": 3,
      "name": "Empty"
    },
    {
      "x": -6,
      "y": 7,
      "z": 3,
      "name": "Empty"
    },
    {
      "x": -6,
      "y": 8,
      "z": 3,
      "name": "Empty"
    },
    {
      "x": -6,
      "y": 9,
      "z": 3,
      "name": "Empty"
    },
    {
      "x": -6,
      "y": 10,
      "z": 3,
      "name": "Empty"
    },
    {
      "x": -6,
      "y": 11,
      "z": 3,
      "name": "Empty"
    },
    {
      "x": -6,
      "y": 12,
      "z": 3,
      "name": "Empty"
    },
    {
      "x": -6,
      "y": 13,
      "z": 3,
      "name": "Soil_Mud_Dry"
    },
    {
      "x": -6,
      "y": 14,
      "z": 3,
      "name": "Soil_Mud_Dry"
    },
    {
      "x": -6,
      "y": 15,
      "z": 3,
      "name": "Soil_Mud_Dry"
    },
    {
      "x": -6,
      "y": 16,
      "z": 3,
      "name": "Soil_Mud_Dry"
    },
    {
      "x": -6,
      "y": 4,
      "z": 4,
      "name": "Soil_Mud_Dry"
    },
    {
      "x": -6,
      "y": 5,
      "z": 4,
      "name": "Soil_Mud_Dry"
    },
    {
      "x": -6,
      "y": 6,
      "z": 4,
      "name": "Soil_Mud_Dry"
    },
    {
      "x": -6,
      "y": 7,
      "z": 4,
      "name": "Soil_Mud_Dry"
    },
    {
      "x": -6,
      "y": 8,
      "z": 4,
      "name": "Empty"
    },
    {
      "x": -6,
      "y": 9,
      "z": 4,
      "name": "Empty"
    },
    {
      "x": -6,
      "y": 10,
      "z": 4,
      "name": "Empty"
    },
    {
      "x": -6,
      "y": 11,
      "z": 4,
      "name": "Soil_Mud_Dry"
    },
    {
      "x": -6,
      "y": 12,
      "z": 4,
      "name": "Soil_Mud_Dry"
    },
    {
      "x": -6,
      "y": 13,
      "z": 4,
      "name": "Soil_Mud_Dry"
    },
    {
      "x": -6,
      "y": 14,
      "z": 4,
      "name": "Soil_Mud_Dry"
    },
    {
      "x": -6,
      "y": 15,
      "z": 4,
      "name": "Soil_Mud_Dry"
    },
    {
      "x": -6,
      "y": 3,
      "z": 5,
      "name": "Soil_Mud_Dry"
    },
    {
      "x": -6,
      "y": 4,
      "z": 5,
      "name": "Soil_Mud_Dry"
    },
    {
      "x": -6,
      "y": 5,
      "z": 5,
      "name": "Soil_Mud_Dry"
    },
    {
      "x": -6,
      "y": 6,
      "z": 5,
      "name": "Soil_Mud_Dry"
    },
    {
      "x": -6,
      "y": 7,
      "z": 5,
      "name": "Soil_Mud_Dry"
    },
    {
      "x": -6,
      "y": 8,
      "z": 5,
      "name": "Soil_Mud_Dry"
    },
    {
      "x": -6,
      "y": 9,
      "z": 5,
      "name": "Soil_Mud_Dry"
    },
    {
      "x": -6,
      "y": 10,
      "z": 5,
      "name": "Soil_Mud_Dry"
    },
    {
      "x": -6,
      "y": 11,
      "z": 5,
      "name": "Soil_Mud_Dry"
    },
    {
      "x": -6,
      "y": 12,
      "z": 5,
      "name": "Soil_Mud_Dry"
    },
    {
      "x": -6,
      "y": 13,
      "z": 5,
      "name": "Soil_Mud_Dry"
    },
    {
      "x": -6,
      "y": 14,
      "z": 5,
      "name": "Soil_Mud_Dry"
    },
    {
      "x": -6,
      "y": 15,
      "z": 5,
      "name": "Soil_Mud_Dry"
    },
    {
      "x": -5,
      "y": 3,
      "z": -5,
      "name": "Soil_Mud_Dry"
    },
    {
      "x": -5,
      "y": 4,
      "z": -5,
      "name": "Soil_Mud_Dry"
    },
    {
      "x": -5,
      "y": 5,
      "z": -5,
      "name": "Soil_Mud_Dry"
    },
    {
      "x": -5,
      "y": 6,
      "z": -5,
      "name": "Soil_Mud_Dry"
    },
    {
      "x": -5,
      "y": 7,
      "z": -5,
      "name": "Soil_Mud_Dry"
    },
    {
      "x": -5,
      "y": 8,
      "z": -5,
      "name": "Soil_Mud_Dry"
    },
    {
      "x": -5,
      "y": 9,
      "z": -5,
      "name": "Soil_Mud_Dry"
    },
    {
      "x": -5,
      "y": 10,
      "z": -5,
      "name": "Soil_Mud_Dry"
    },
    {
      "x": -5,
      "y": 11,
      "z": -5,
      "name": "Soil_Mud_Dry"
    },
    {
      "x": -5,
      "y": 12,
      "z": -5,
      "name": "Soil_Mud_Dry"
    },
    {
      "x": -5,
      "y": 13,
      "z": -5,
      "name": "Soil_Mud_Dry"
    },
    {
      "x": -5,
      "y": 14,
      "z": -5,
      "name": "Soil_Mud_Dry"
    },
    {
      "x": -5,
      "y": 15,
      "z": -5,
      "name": "Soil_Mud_Dry"
    },
    {
      "x": -5,
      "y": 16,
      "z": -5,
      "name": "Soil_Mud_Dry"
    },
    {
      "x": -5,
      "y": 3,
      "z": -4,
      "name": "Soil_Mud_Dry"
    },
    {
      "x": -5,
      "y": 4,
      "z": -4,
      "name": "Soil_Mud_Dry"
    },
    {
      "x": -5,
      "y": 5,
      "z": -4,
      "name": "Soil_Mud_Dry"
    },
    {
      "x": -5,
      "y": 6,
      "z": -4,
      "name": "Soil_Mud_Dry"
    },
    {
      "x": -5,
      "y": 7,
      "z": -4,
      "name": "Empty"
    },
    {
      "x": -5,
      "y": 8,
      "z": -4,
      "name": "Empty"
    },
    {
      "x": -5,
      "y": 9,
      "z": -4,
      "name": "Empty"
    },
    {
      "x": -5,
      "y": 10,
      "z": -4,
      "name": "Empty"
    },
    {
      "x": -5,
      "y": 11,
      "z": -4,
      "name": "Empty"
    },
    {
      "x": -5,
      "y": 12,
      "z": -4,
      "name": "Empty"
    },
    {
      "x": -5,
      "y": 13,
      "z": -4,
      "name": "Soil_Mud_Dry"
    },
    {
      "x": -5,
      "y": 14,
      "z": -4,
      "name": "Soil_Mud_Dry"
    },
    {
      "x": -5,
      "y": 15,
      "z": -4,
      "name": "Soil_Mud_Dry"
    },
    {
      "x": -5,
      "y": 16,
      "z": -4,
      "name": "Soil_Mud_Dry"
    },
    {
      "x": -5,
      "y": 3,
      "z": -3,
      "name": "Soil_Mud_Dry"
    },
    {
      "x": -5,
      "y": 4,
      "z": -3,
      "name": "Soil_Mud_Dry"
    },
    {
      "x": -5,
      "y": 5,
      "z": -3,
      "name": "Empty"
    },
    {
      "x": -5,
      "y": 6,
      "z": -3,
      "name": "Empty"
    },
    {
      "x": -5,
      "y": 7,
      "z": -3,
      "name": "Empty"
    },
    {
      "x": -5,
      "y": 8,
      "z": -3,
      "name": "Empty"
    },
    {
      "x": -5,
      "y": 9,
      "z": -3,
      "name": "Empty"
    },
    {
      "x": -5,
      "y": 10,
      "z": -3,
      "name": "Empty"
    },
    {
      "x": -5,
      "y": 11,
      "z": -3,
      "name": "Empty"
    },
    {
      "x": -5,
      "y": 12,
      "z": -3,
      "name": "Empty"
    },
    {
      "x": -5,
      "y": 13,
      "z": -3,
      "name": "Soil_Mud_Dry"
    },
    {
      "x": -5,
      "y": 14,
      "z": -3,
      "name": "Soil_Mud_Dry"
    },
    {
      "x": -5,
      "y": 15,
      "z": -3,
      "name": "Soil_Mud_Dry"
    },
    {
      "x": -5,
      "y": 16,
      "z": -3,
      "name": "Soil_Mud_Dry"
    },
    {
      "x": -5,
      "y": 3,
      "z": -2,
      "name": "Soil_Mud_Dry"
    },
    {
      "x": -5,
      "y": 4,
      "z": -2,
      "name": "Soil_Mud_Dry"
    },
    {
      "x": -5,
      "y": 5,
      "z": -2,
      "name": "Empty"
    },
    {
      "x": -5,
      "y": 6,
      "z": -2,
      "name": "Empty"
    },
    {
      "x": -5,
      "y": 7,
      "z": -2,
      "name": "Empty"
    },
    {
      "x": -5,
      "y": 8,
      "z": -2,
      "name": "Empty"
    },
    {
      "x": -5,
      "y": 9,
      "z": -2,
      "name": "Empty"
    },
    {
      "x": -5,
      "y": 10,
      "z": -2,
      "name": "Empty"
    },
    {
      "x": -5,
      "y": 11,
      "z": -2,
      "name": "Empty"
    },
    {
      "x": -5,
      "y": 12,
      "z": -2,
      "name": "Empty"
    },
    {
      "x": -5,
      "y": 13,
      "z": -2,
      "name": "Soil_Mud_Dry"
    },
    {
      "x": -5,
      "y": 14,
      "z": -2,
      "name": "Soil_Mud_Dry"
    },
    {
      "x": -5,
      "y": 15,
      "z": -2,
      "name": "Soil_Mud_Dry"
    },
    {
      "x": -5,
      "y": 16,
      "z": -2,
      "name": "Soil_Mud_Dry"
    },
    {
      "x": -5,
      "y": 3,
      "z": -1,
      "name": "Soil_Mud_Dry"
    },
    {
      "x": -5,
      "y": 4,
      "z": -1,
      "name": "Soil_Roots_Poisoned"
    },
    {
      "x": -5,
      "y": 5,
      "z": -1,
      "name": "Soil_Roots_Poisoned"
    },
    {
      "x": -5,
      "y": 6,
      "z": -1,
      "name": "Empty"
    },
    {
      "x": -5,
      "y": 7,
      "z": -1,
      "name": "Empty"
    },
    {
      "x": -5,
      "y": 8,
      "z": -1,
      "name": "Empty"
    },
    {
      "x": -5,
      "y": 9,
      "z": -1,
      "name": "Empty"
    },
    {
      "x": -5,
      "y": 10,
      "z": -1,
      "name": "Empty"
    },
    {
      "x": -5,
      "y": 11,
      "z": -1,
      "name": "Empty"
    },
    {
      "x": -5,
      "y": 12,
      "z": -1,
      "name": "Empty"
    },
    {
      "x": -5,
      "y": 13,
      "z": -1,
      "name": "Empty"
    },
    {
      "x": -5,
      "y": 14,
      "z": -1,
      "name": "Empty"
    },
    {
      "x": -5,
      "y": 15,
      "z": -1,
      "name": "Soil_Mud_Dry"
    },
    {
      "x": -5,
      "y": 16,
      "z": -1,
      "name": "Soil_Mud_Dry"
    },
    {
      "x": -5,
      "y": 3,
      "z": 0,
      "name": "Soil_Mud_Dry"
    },
    {
      "x": -5,
      "y": 4,
      "z": 0,
      "name": "Soil_Dirt_Poisoned"
    },
    {
      "x": -5,
      "y": 5,
      "z": 0,
      "name": "Empty"
    },
    {
      "x": -5,
      "y": 6,
      "z": 0,
      "name": "Empty"
    },
    {
      "x": -5,
      "y": 7,
      "z": 0,
      "name": "Empty"
    },
    {
      "x": -5,
      "y": 8,
      "z": 0,
      "name": "Empty"
    },
    {
      "x": -5,
      "y": 9,
      "z": 0,
      "name": "Empty"
    },
    {
      "x": -5,
      "y": 10,
      "z": 0,
      "name": "Empty"
    },
    {
      "x": -5,
      "y": 11,
      "z": 0,
      "name": "Empty"
    },
    {
      "x": -5,
      "y": 12,
      "z": 0,
      "name": "Empty"
    },
    {
      "x": -5,
      "y": 13,
      "z": 0,
      "name": "Empty"
    },
    {
      "x": -5,
      "y": 14,
      "z": 0,
      "name": "Empty"
    },
    {
      "x": -5,
      "y": 15,
      "z": 0,
      "name": "Soil_Mud_Dry"
    },
    {
      "x": -5,
      "y": 16,
      "z": 0,
      "name": "Soil_Mud_Dry"
    },
    {
      "x": -5,
      "y": 3,
      "z": 1,
      "name": "Soil_Mud_Dry"
    },
    {
      "x": -5,
      "y": 4,
      "z": 1,
      "name": "Soil_Dirt_Poisoned"
    },
    {
      "x": -5,
      "y": 5,
      "z": 1,
      "name": "Empty"
    },
    {
      "x": -5,
      "y": 6,
      "z": 1,
      "name": "Empty"
    },
    {
      "x": -5,
      "y": 7,
      "z": 1,
      "name": "Empty"
    },
    {
      "x": -5,
      "y": 8,
      "z": 1,
      "name": "Empty"
    },
    {
      "x": -5,
      "y": 9,
      "z": 1,
      "name": "Empty"
    },
    {
      "x": -5,
      "y": 10,
      "z": 1,
      "name": "Empty"
    },
    {
      "x": -5,
      "y": 11,
      "z": 1,
      "name": "Empty"
    },
    {
      "x": -5,
      "y": 12,
      "z": 1,
      "name": "Empty"
    },
    {
      "x": -5,
      "y": 13,
      "z": 1,
      "name": "Empty"
    },
    {
      "x": -5,
      "y": 14,
      "z": 1,
      "name": "Empty"
    },
    {
      "x": -5,
      "y": 15,
      "z": 1,
      "name": "Soil_Mud_Dry"
    },
    {
      "x": -5,
      "y": 16,
      "z": 1,
      "name": "Soil_Mud_Dry"
    },
    {
      "x": -5,
      "y": 3,
      "z": 2,
      "name": "Soil_Mud_Dry"
    },
    {
      "x": -5,
      "y": 4,
      "z": 2,
      "name": "Soil_Dirt_Poisoned"
    },
    {
      "x": -5,
      "y": 5,
      "z": 2,
      "name": "Empty"
    },
    {
      "x": -5,
      "y": 6,
      "z": 2,
      "name": "Empty"
    },
    {
      "x": -5,
      "y": 7,
      "z": 2,
      "name": "Empty"
    },
    {
      "x": -5,
      "y": 8,
      "z": 2,
      "name": "Empty"
    },
    {
      "x": -5,
      "y": 9,
      "z": 2,
      "name": "Empty"
    },
    {
      "x": -5,
      "y": 10,
      "z": 2,
      "name": "Empty"
    },
    {
      "x": -5,
      "y": 11,
      "z": 2,
      "name": "Empty"
    },
    {
      "x": -5,
      "y": 12,
      "z": 2,
      "name": "Empty"
    },
    {
      "x": -5,
      "y": 13,
      "z": 2,
      "name": "Soil_Hive"
    },
    {
      "x": -5,
      "y": 14,
      "z": 2,
      "name": "Soil_Mud_Dry"
    },
    {
      "x": -5,
      "y": 15,
      "z": 2,
      "name": "Soil_Mud_Dry"
    },
    {
      "x": -5,
      "y": 16,
      "z": 2,
      "name": "Soil_Mud_Dry"
    },
    {
      "x": -5,
      "y": 3,
      "z": 3,
      "name": "Soil_Mud_Dry"
    },
    {
      "x": -5,
      "y": 4,
      "z": 3,
      "name": "Soil_Mud_Dry"
    },
    {
      "x": -5,
      "y": 5,
      "z": 3,
      "name": "Soil_Mud_Dry"
    },
    {
      "x": -5,
      "y": 6,
      "z": 3,
      "name": "Empty"
    },
    {
      "x": -5,
      "y": 7,
      "z": 3,
      "name": "Empty"
    },
    {
      "x": -5,
      "y": 8,
      "z": 3,
      "name": "Empty"
    },
    {
      "x": -5,
      "y": 9,
      "z": 3,
      "name": "Empty"
    },
    {
      "x": -5,
      "y": 10,
      "z": 3,
      "name": "Empty"
    },
    {
      "x": -5,
      "y": 11,
      "z": 3,
      "name": "Empty"
    },
    {
      "x": -5,
      "y": 12,
      "z": 3,
      "name": "Empty"
    },
    {
      "x": -5,
      "y": 13,
      "z": 3,
      "name": "Soil_Mud_Dry"
    },
    {
      "x": -5,
      "y": 14,
      "z": 3,
      "name": "Soil_Mud_Dry"
    },
    {
      "x": -5,
      "y": 15,
      "z": 3,
      "name": "Soil_Mud_Dry"
    },
    {
      "x": -5,
      "y": 16,
      "z": 3,
      "name": "Soil_Mud_Dry"
    },
    {
      "x": -5,
      "y": 3,
      "z": 4,
      "name": "Soil_Mud_Dry"
    },
    {
      "x": -5,
      "y": 4,
      "z": 4,
      "name": "Soil_Mud_Dry"
    },
    {
      "x": -5,
      "y": 5,
      "z": 4,
      "name": "Soil_Mud_Dry"
    },
    {
      "x": -5,
      "y": 6,
      "z": 4,
      "name": "Soil_Mud_Dry"
    },
    {
      "x": -5,
      "y": 7,
      "z": 4,
      "name": "Empty"
    },
    {
      "x": -5,
      "y": 8,
      "z": 4,
      "name": "Empty"
    },
    {
      "x": -5,
      "y": 9,
      "z": 4,
      "name": "Empty"
    },
    {
      "x": -5,
      "y": 10,
      "z": 4,
      "name": "Empty"
    },
    {
      "x": -5,
      "y": 11,
      "z": 4,
      "name": "Empty"
    },
    {
      "x": -5,
      "y": 12,
      "z": 4,
      "name": "Soil_Mud_Dry"
    },
    {
      "x": -5,
      "y": 13,
      "z": 4,
      "name": "Soil_Mud_Dry"
    },
    {
      "x": -5,
      "y": 14,
      "z": 4,
      "name": "Soil_Mud_Dry"
    },
    {
      "x": -5,
      "y": 15,
      "z": 4,
      "name": "Soil_Mud_Dry"
    },
    {
      "x": -5,
      "y": 16,
      "z": 4,
      "name": "Soil_Mud_Dry"
    },
    {
      "x": -5,
      "y": 3,
      "z": 5,
      "name": "Soil_Mud_Dry"
    },
    {
      "x": -5,
      "y": 4,
      "z": 5,
      "name": "Soil_Mud_Dry"
    },
    {
      "x": -5,
      "y": 5,
      "z": 5,
      "name": "Soil_Mud_Dry"
    },
    {
      "x": -5,
      "y": 6,
      "z": 5,
      "name": "Soil_Mud_Dry"
    },
    {
      "x": -5,
      "y": 7,
      "z": 5,
      "name": "Soil_Mud_Dry"
    },
    {
      "x": -5,
      "y": 8,
      "z": 5,
      "name": "Soil_Mud_Dry"
    },
    {
      "x": -5,
      "y": 9,
      "z": 5,
      "name": "Soil_Mud_Dry"
    },
    {
      "x": -5,
      "y": 10,
      "z": 5,
      "name": "Soil_Mud_Dry"
    },
    {
      "x": -5,
      "y": 11,
      "z": 5,
      "name": "Soil_Mud_Dry"
    },
    {
      "x": -5,
      "y": 12,
      "z": 5,
      "name": "Soil_Mud_Dry"
    },
    {
      "x": -5,
      "y": 13,
      "z": 5,
      "name": "Soil_Mud_Dry"
    },
    {
      "x": -5,
      "y": 14,
      "z": 5,
      "name": "Soil_Mud_Dry"
    },
    {
      "x": -5,
      "y": 15,
      "z": 5,
      "name": "Soil_Mud_Dry"
    },
    {
      "x": -5,
      "y": 16,
      "z": 5,
      "name": "Soil_Mud_Dry"
    },
    {
      "x": -4,
      "y": 3,
      "z": -5,
      "name": "Soil_Mud_Dry"
    },
    {
      "x": -4,
      "y": 4,
      "z": -5,
      "name": "Soil_Mud_Dry"
    },
    {
      "x": -4,
      "y": 5,
      "z": -5,
      "name": "Soil_Mud_Dry"
    },
    {
      "x": -4,
      "y": 6,
      "z": -5,
      "name": "Soil_Mud_Dry"
    },
    {
      "x": -4,
      "y": 7,
      "z": -5,
      "name": "Soil_Mud_Dry"
    },
    {
      "x": -4,
      "y": 8,
      "z": -5,
      "name": "Soil_Mud_Dry"
    },
    {
      "x": -4,
      "y": 9,
      "z": -5,
      "name": "Soil_Mud_Dry"
    },
    {
      "x": -4,
      "y": 10,
      "z": -5,
      "name": "Soil_Mud_Dry"
    },
    {
      "x": -4,
      "y": 11,
      "z": -5,
      "name": "Soil_Mud_Dry"
    },
    {
      "x": -4,
      "y": 12,
      "z": -5,
      "name": "Soil_Mud_Dry"
    },
    {
      "x": -4,
      "y": 13,
      "z": -5,
      "name": "Soil_Mud_Dry"
    },
    {
      "x": -4,
      "y": 14,
      "z": -5,
      "name": "Soil_Mud_Dry"
    },
    {
      "x": -4,
      "y": 15,
      "z": -5,
      "name": "Soil_Mud_Dry"
    },
    {
      "x": -4,
      "y": 16,
      "z": -5,
      "name": "Soil_Mud_Dry"
    },
    {
      "x": -4,
      "y": 3,
      "z": -4,
      "name": "Soil_Mud_Dry"
    },
    {
      "x": -4,
      "y": 4,
      "z": -4,
      "name": "Soil_Mud_Dry"
    },
    {
      "x": -4,
      "y": 5,
      "z": -4,
      "name": "Soil_Mud_Dry"
    },
    {
      "x": -4,
      "y": 6,
      "z": -4,
      "name": "Soil_Mud_Dry"
    },
    {
      "x": -4,
      "y": 7,
      "z": -4,
      "name": "Empty"
    },
    {
      "x": -4,
      "y": 8,
      "z": -4,
      "name": "Empty"
    },
    {
      "x": -4,
      "y": 9,
      "z": -4,
      "name": "Empty"
    },
    {
      "x": -4,
      "y": 10,
      "z": -4,
      "name": "Empty"
    },
    {
      "x": -4,
      "y": 11,
      "z": -4,
      "name": "Empty"
    },
    {
      "x": -4,
      "y": 12,
      "z": -4,
      "name": "Empty"
    },
    {
      "x": -4,
      "y": 13,
      "z": -4,
      "name": "Soil_Mud_Dry"
    },
    {
      "x": -4,
      "y": 14,
      "z": -4,
      "name": "Soil_Mud_Dry"
    },
    {
      "x": -4,
      "y": 15,
      "z": -4,
      "name": "Soil_Mud_Dry"
    },
    {
      "x": -4,
      "y": 16,
      "z": -4,
      "name": "Soil_Mud_Dry"
    },
    {
      "x": -4,
      "y": 3,
      "z": -3,
      "name": "Soil_Mud_Dry"
    },
    {
      "x": -4,
      "y": 4,
      "z": -3,
      "name": "Soil_Hive"
    },
    {
      "x": -4,
      "y": 5,
      "z": -3,
      "name": "Soil_Hive"
    },
    {
      "x": -4,
      "y": 6,
      "z": -3,
      "name": "Soil_Hive"
    },
    {
      "x": -4,
      "y": 7,
      "z": -3,
      "name": "Soil_Hive"
    },
    {
      "x": -4,
      "y": 8,
      "z": -3,
      "name": "Soil_Hive"
    },
    {
      "x": -4,
      "y": 9,
      "z": -3,
      "name": "Empty"
    },
    {
      "x": -4,
      "y": 10,
      "z": -3,
      "name": "Empty"
    },
    {
      "x": -4,
      "y": 11,
      "z": -3,
      "name": "Empty"
    },
    {
      "x": -4,
      "y": 12,
      "z": -3,
      "name": "Empty"
    },
    {
      "x": -4,
      "y": 13,
      "z": -3,
      "name": "Soil_Mud_Dry"
    },
    {
      "x": -4,
      "y": 14,
      "z": -3,
      "name": "Soil_Mud_Dry"
    },
    {
      "x": -4,
      "y": 15,
      "z": -3,
      "name": "Soil_Mud_Dry"
    },
    {
      "x": -4,
      "y": 16,
      "z": -3,
      "name": "Soil_Mud_Dry"
    },
    {
      "x": -4,
      "y": 3,
      "z": -2,
      "name": "Soil_Mud_Dry"
    },
    {
      "x": -4,
      "y": 4,
      "z": -2,
      "name": "Soil_Mud_Dry"
    },
    {
      "x": -4,
      "y": 5,
      "z": -2,
      "name": "Empty"
    },
    {
      "x": -4,
      "y": 6,
      "z": -2,
      "name": "Empty"
    },
    {
      "x": -4,
      "y": 7,
      "z": -2,
      "name": "Empty"
    },
    {
      "x": -4,
      "y": 8,
      "z": -2,
      "name": "Empty"
    },
    {
      "x": -4,
      "y": 9,
      "z": -2,
      "name": "Empty"
    },
    {
      "x": -4,
      "y": 10,
      "z": -2,
      "name": "Empty"
    },
    {
      "x": -4,
      "y": 11,
      "z": -2,
      "name": "Empty"
    },
    {
      "x": -4,
      "y": 12,
      "z": -2,
      "name": "Empty"
    },
    {
      "x": -4,
      "y": 13,
      "z": -2,
      "name": "Empty"
    },
    {
      "x": -4,
      "y": 14,
      "z": -2,
      "name": "Soil_Mud_Dry"
    },
    {
      "x": -4,
      "y": 15,
      "z": -2,
      "name": "Soil_Mud_Dry"
    },
    {
      "x": -4,
      "y": 16,
      "z": -2,
      "name": "Soil_Mud_Dry"
    },
    {
      "x": -4,
      "y": 3,
      "z": -1,
      "name": "Soil_Mud_Dry"
    },
    {
      "x": -4,
      "y": 4,
      "z": -1,
      "name": "Soil_Roots_Poisoned"
    },
    {
      "x": -4,
      "y": 5,
      "z": -1,
      "name": "Empty"
    },
    {
      "x": -4,
      "y": 6,
      "z": -1,
      "name": "Empty"
    },
    {
      "x": -4,
      "y": 7,
      "z": -1,
      "name": "Empty"
    },
    {
      "x": -4,
      "y": 8,
      "z": -1,
      "name": "Empty"
    },
    {
      "x": -4,
      "y": 9,
      "z": -1,
      "name": "Empty"
    },
    {
      "x": -4,
      "y": 10,
      "z": -1,
      "name": "Empty"
    },
    {
      "x": -4,
      "y": 11,
      "z": -1,
      "name": "Empty"
    },
    {
      "x": -4,
      "y": 12,
      "z": -1,
      "name": "Empty"
    },
    {
      "x": -4,
      "y": 13,
      "z": -1,
      "name": "Empty"
    },
    {
      "x": -4,
      "y": 14,
      "z": -1,
      "name": "Empty"
    },
    {
      "x": -4,
      "y": 15,
      "z": -1,
      "name": "Soil_Mud_Dry"
    },
    {
      "x": -4,
      "y": 16,
      "z": -1,
      "name": "Soil_Mud_Dry"
    },
    {
      "x": -4,
      "y": 3,
      "z": 0,
      "name": "Soil_Dirt_Poisoned"
    },
    {
      "x": -4,
      "y": 4,
      "z": 0,
      "name": "Soil_Roots_Poisoned"
    },
    {
      "x": -4,
      "y": 5,
      "z": 0,
      "name": "Empty"
    },
    {
      "x": -4,
      "y": 6,
      "z": 0,
      "name": "Empty"
    },
    {
      "x": -4,
      "y": 7,
      "z": 0,
      "name": "Empty"
    },
    {
      "x": -4,
      "y": 8,
      "z": 0,
      "name": "Empty"
    },
    {
      "x": -4,
      "y": 9,
      "z": 0,
      "name": "Empty"
    },
    {
      "x": -4,
      "y": 10,
      "z": 0,
      "name": "Empty"
    },
    {
      "x": -4,
      "y": 11,
      "z": 0,
      "name": "Empty"
    },
    {
      "x": -4,
      "y": 12,
      "z": 0,
      "name": "Empty"
    },
    {
      "x": -4,
      "y": 13,
      "z": 0,
      "name": "Empty"
    },
    {
      "x": -4,
      "y": 14,
      "z": 0,
      "name": "Empty"
    },
    {
      "x": -4,
      "y": 15,
      "z": 0,
      "name": "Soil_Mud_Dry"
    },
    {
      "x": -4,
      "y": 16,
      "z": 0,
      "name": "Soil_Mud_Dry"
    },
    {
      "x": -4,
      "y": 3,
      "z": 1,
      "name": "Soil_Dirt_Poisoned"
    },
    {
      "x": -4,
      "y": 4,
      "z": 1,
      "name": "Soil_Dirt_Poisoned"
    },
    {
      "x": -4,
      "y": 5,
      "z": 1,
      "name": "Plant_Bramble_Dead_Twisted"
    },
    {
      "x": -4,
      "y": 6,
      "z": 1,
      "name": "Empty"
    },
    {
      "x": -4,
      "y": 7,
      "z": 1,
      "name": "Empty"
    },
    {
      "x": -4,
      "y": 8,
      "z": 1,
      "name": "Empty"
    },
    {
      "x": -4,
      "y": 9,
      "z": 1,
      "name": "Empty"
    },
    {
      "x": -4,
      "y": 10,
      "z": 1,
      "name": "Empty"
    },
    {
      "x": -4,
      "y": 11,
      "z": 1,
      "name": "Empty"
    },
    {
      "x": -4,
      "y": 12,
      "z": 1,
      "name": "Empty"
    },
    {
      "x": -4,
      "y": 13,
      "z": 1,
      "name": "Wood_Dry_Roots"
    },
    {
      "x": -4,
      "y": 14,
      "z": 1,
      "name": "Soil_Hive"
    },
    {
      "x": -4,
      "y": 15,
      "z": 1,
      "name": "Soil_Mud_Dry"
    },
    {
      "x": -4,
      "y": 16,
      "z": 1,
      "name": "Soil_Mud_Dry"
    },
    {
      "x": -4,
      "y": 3,
      "z": 2,
      "name": "Soil_Dirt_Poisoned"
    },
    {
      "x": -4,
      "y": 4,
      "z": 2,
      "name": "Soil_Dirt_Poisoned"
    },
    {
      "x": -4,
      "y": 5,
      "z": 2,
      "name": "Empty"
    },
    {
      "x": -4,
      "y": 6,
      "z": 2,
      "name": "Empty"
    },
    {
      "x": -4,
      "y": 7,
      "z": 2,
      "name": "Empty"
    },
    {
      "x": -4,
      "y": 8,
      "z": 2,
      "name": "Empty"
    },
    {
      "x": -4,
      "y": 9,
      "z": 2,
      "name": "Empty"
    },
    {
      "x": -4,
      "y": 10,
      "z": 2,
      "name": "Empty"
    },
    {
      "x": -4,
      "y": 11,
      "z": 2,
      "name": "Empty"
    },
    {
      "x": -4,
      "y": 12,
      "z": 2,
      "name": "Wood_Dry_Roots"
    },
    {
      "x": -4,
      "y": 13,
      "z": 2,
      "name": "Soil_Hive"
    },
    {
      "x": -4,
      "y": 14,
      "z": 2,
      "name": "Soil_Mud_Dry"
    },
    {
      "x": -4,
      "y": 15,
      "z": 2,
      "name": "Soil_Mud_Dry"
    },
    {
      "x": -4,
      "y": 16,
      "z": 2,
      "name": "Soil_Mud_Dry"
    },
    {
      "x": -4,
      "y": 3,
      "z": 3,
      "name": "Soil_Mud_Dry"
    },
    {
      "x": -4,
      "y": 4,
      "z": 3,
      "name": "Soil_Dirt_Poisoned"
    },
    {
      "x": -4,
      "y": 5,
      "z": 3,
      "name": "Empty"
    },
    {
      "x": -4,
      "y": 6,
      "z": 3,
      "name": "Empty"
    },
    {
      "x": -4,
      "y": 7,
      "z": 3,
      "name": "Empty"
    },
    {
      "x": -4,
      "y": 8,
      "z": 3,
      "name": "Empty"
    },
    {
      "x": -4,
      "y": 9,
      "z": 3,
      "name": "Empty"
    },
    {
      "x": -4,
      "y": 10,
      "z": 3,
      "name": "Empty"
    },
    {
      "x": -4,
      "y": 11,
      "z": 3,
      "name": "Empty"
    },
    {
      "x": -4,
      "y": 12,
      "z": 3,
      "name": "Empty"
    },
    {
      "x": -4,
      "y": 13,
      "z": 3,
      "name": "Soil_Mud_Dry"
    },
    {
      "x": -4,
      "y": 14,
      "z": 3,
      "name": "Soil_Mud_Dry"
    },
    {
      "x": -4,
      "y": 15,
      "z": 3,
      "name": "Soil_Mud_Dry"
    },
    {
      "x": -4,
      "y": 16,
      "z": 3,
      "name": "Soil_Mud_Dry"
    },
    {
      "x": -4,
      "y": 3,
      "z": 4,
      "name": "Soil_Mud_Dry"
    },
    {
      "x": -4,
      "y": 4,
      "z": 4,
      "name": "Soil_Mud_Dry"
    },
    {
      "x": -4,
      "y": 5,
      "z": 4,
      "name": "Soil_Mud_Dry"
    },
    {
      "x": -4,
      "y": 6,
      "z": 4,
      "name": "Soil_Mud_Dry"
    },
    {
      "x": -4,
      "y": 7,
      "z": 4,
      "name": "Soil_Mud_Dry"
    },
    {
      "x": -4,
      "y": 8,
      "z": 4,
      "name": "Soil_Mud_Dry"
    },
    {
      "x": -4,
      "y": 9,
      "z": 4,
      "name": "Soil_Mud_Dry"
    },
    {
      "x": -4,
      "y": 10,
      "z": 4,
      "name": "Soil_Mud_Dry"
    },
    {
      "x": -4,
      "y": 11,
      "z": 4,
      "name": "Soil_Mud_Dry"
    },
    {
      "x": -4,
      "y": 12,
      "z": 4,
      "name": "Soil_Mud_Dry"
    },
    {
      "x": -4,
      "y": 13,
      "z": 4,
      "name": "Soil_Mud_Dry"
    },
    {
      "x": -4,
      "y": 14,
      "z": 4,
      "name": "Soil_Mud_Dry"
    },
    {
      "x": -4,
      "y": 15,
      "z": 4,
      "name": "Soil_Mud_Dry"
    },
    {
      "x": -4,
      "y": 16,
      "z": 4,
      "name": "Soil_Mud_Dry"
    },
    {
      "x": -4,
      "y": 3,
      "z": 5,
      "name": "Soil_Mud_Dry"
    },
    {
      "x": -4,
      "y": 4,
      "z": 5,
      "name": "Soil_Mud_Dry"
    },
    {
      "x": -4,
      "y": 5,
      "z": 5,
      "name": "Soil_Mud_Dry"
    },
    {
      "x": -4,
      "y": 6,
      "z": 5,
      "name": "Soil_Mud_Dry"
    },
    {
      "x": -4,
      "y": 7,
      "z": 5,
      "name": "Soil_Mud_Dry"
    },
    {
      "x": -4,
      "y": 8,
      "z": 5,
      "name": "Soil_Mud_Dry"
    },
    {
      "x": -4,
      "y": 9,
      "z": 5,
      "name": "Soil_Mud_Dry"
    },
    {
      "x": -4,
      "y": 10,
      "z": 5,
      "name": "Soil_Mud_Dry"
    },
    {
      "x": -4,
      "y": 11,
      "z": 5,
      "name": "Soil_Mud_Dry"
    },
    {
      "x": -4,
      "y": 12,
      "z": 5,
      "name": "Soil_Mud_Dry"
    },
    {
      "x": -4,
      "y": 13,
      "z": 5,
      "name": "Soil_Mud_Dry"
    },
    {
      "x": -4,
      "y": 14,
      "z": 5,
      "name": "Soil_Mud_Dry"
    },
    {
      "x": -4,
      "y": 15,
      "z": 5,
      "name": "Soil_Mud_Dry"
    },
    {
      "x": -4,
      "y": 16,
      "z": 5,
      "name": "Soil_Mud_Dry"
    },
    {
      "x": -3,
      "y": 3,
      "z": -5,
      "name": "Soil_Mud_Dry"
    },
    {
      "x": -3,
      "y": 4,
      "z": -5,
      "name": "Soil_Mud_Dry"
    },
    {
      "x": -3,
      "y": 5,
      "z": -5,
      "name": "Empty"
    },
    {
      "x": -3,
      "y": 6,
      "z": -5,
      "name": "Empty"
    },
    {
      "x": -3,
      "y": 7,
      "z": -5,
      "name": "Empty"
    },
    {
      "x": -3,
      "y": 8,
      "z": -5,
      "name": "Empty"
    },
    {
      "x": -3,
      "y": 9,
      "z": -5,
      "name": "Soil_Mud_Dry"
    },
    {
      "x": -3,
      "y": 10,
      "z": -5,
      "name": "Soil_Mud_Dry"
    },
    {
      "x": -3,
      "y": 11,
      "z": -5,
      "name": "Soil_Mud_Dry"
    },
    {
      "x": -3,
      "y": 12,
      "z": -5,
      "name": "Soil_Mud_Dry"
    },
    {
      "x": -3,
      "y": 13,
      "z": -5,
      "name": "Soil_Mud_Dry"
    },
    {
      "x": -3,
      "y": 14,
      "z": -5,
      "name": "Soil_Mud_Dry"
    },
    {
      "x": -3,
      "y": 15,
      "z": -5,
      "name": "Soil_Mud_Dry"
    },
    {
      "x": -3,
      "y": 16,
      "z": -5,
      "name": "Soil_Mud_Dry"
    },
    {
      "x": -3,
      "y": 3,
      "z": -4,
      "name": "Soil_Mud_Dry"
    },
    {
      "x": -3,
      "y": 4,
      "z": -4,
      "name": "Soil_Dirt_Poisoned"
    },
    {
      "x": -3,
      "y": 5,
      "z": -4,
      "name": "Empty"
    },
    {
      "x": -3,
      "y": 6,
      "z": -4,
      "name": "Empty"
    },
    {
      "x": -3,
      "y": 7,
      "z": -4,
      "name": "Empty"
    },
    {
      "x": -3,
      "y": 8,
      "z": -4,
      "name": "Soil_Hive"
    },
    {
      "x": -3,
      "y": 9,
      "z": -4,
      "name": "Soil_Hive"
    },
    {
      "x": -3,
      "y": 10,
      "z": -4,
      "name": "Soil_Hive"
    },
    {
      "x": -3,
      "y": 11,
      "z": -4,
      "name": "Empty"
    },
    {
      "x": -3,
      "y": 12,
      "z": -4,
      "name": "Empty"
    },
    {
      "x": -3,
      "y": 13,
      "z": -4,
      "name": "Soil_Mud_Dry"
    },
    {
      "x": -3,
      "y": 14,
      "z": -4,
      "name": "Soil_Mud_Dry"
    },
    {
      "x": -3,
      "y": 15,
      "z": -4,
      "name": "Soil_Mud_Dry"
    },
    {
      "x": -3,
      "y": 16,
      "z": -4,
      "name": "Soil_Mud_Dry"
    },
    {
      "x": -3,
      "y": 3,
      "z": -3,
      "name": "Soil_Mud_Dry"
    },
    {
      "x": -3,
      "y": 4,
      "z": -3,
      "name": "Soil_Dirt_Poisoned"
    },
    {
      "x": -3,
      "y": 5,
      "z": -3,
      "name": "Soil_Hive"
    },
    {
      "x": -3,
      "y": 6,
      "z": -3,
      "name": "Empty"
    },
    {
      "x": -3,
      "y": 7,
      "z": -3,
      "name": "Empty"
    },
    {
      "x": -3,
      "y": 8,
      "z": -3,
      "name": "Empty"
    },
    {
      "x": -3,
      "y": 9,
      "z": -3,
      "name": "Empty"
    },
    {
      "x": -3,
      "y": 10,
      "z": -3,
      "name": "Empty"
    },
    {
      "x": -3,
      "y": 11,
      "z": -3,
      "name": "Empty"
    },
    {
      "x": -3,
      "y": 12,
      "z": -3,
      "name": "Empty"
    },
    {
      "x": -3,
      "y": 13,
      "z": -3,
      "name": "Soil_Mud_Dry"
    },
    {
      "x": -3,
      "y": 14,
      "z": -3,
      "name": "Soil_Mud_Dry"
    },
    {
      "x": -3,
      "y": 15,
      "z": -3,
      "name": "Soil_Mud_Dry"
    },
    {
      "x": -3,
      "y": 16,
      "z": -3,
      "name": "Soil_Mud_Dry"
    },
    {
      "x": -3,
      "y": 3,
      "z": -2,
      "name": "Soil_Mud_Dry"
    },
    {
      "x": -3,
      "y": 4,
      "z": -2,
      "name": "Soil_Dirt_Poisoned"
    },
    {
      "x": -3,
      "y": 5,
      "z": -2,
      "name": "Empty"
    },
    {
      "x": -3,
      "y": 6,
      "z": -2,
      "name": "Empty"
    },
    {
      "x": -3,
      "y": 7,
      "z": -2,
      "name": "Empty"
    },
    {
      "x": -3,
      "y": 8,
      "z": -2,
      "name": "Empty"
    },
    {
      "x": -3,
      "y": 9,
      "z": -2,
      "name": "Empty"
    },
    {
      "x": -3,
      "y": 10,
      "z": -2,
      "name": "Empty"
    },
    {
      "x": -3,
      "y": 11,
      "z": -2,
      "name": "Empty"
    },
    {
      "x": -3,
      "y": 12,
      "z": -2,
      "name": "Empty"
    },
    {
      "x": -3,
      "y": 13,
      "z": -2,
      "name": "Empty"
    },
    {
      "x": -3,
      "y": 14,
      "z": -2,
      "name": "Soil_Mud_Dry"
    },
    {
      "x": -3,
      "y": 15,
      "z": -2,
      "name": "Soil_Mud_Dry"
    },
    {
      "x": -3,
      "y": 16,
      "z": -2,
      "name": "Soil_Mud_Dry"
    },
    {
      "x": -3,
      "y": 3,
      "z": -1,
      "name": "Soil_Mud_Dry"
    },
    {
      "x": -3,
      "y": 4,
      "z": -1,
      "name": "Soil_Dirt_Poisoned"
    },
    {
      "x": -3,
      "y": 5,
      "z": -1,
      "name": "Empty"
    },
    {
      "x": -3,
      "y": 6,
      "z": -1,
      "name": "Empty"
    },
    {
      "x": -3,
      "y": 7,
      "z": -1,
      "name": "Empty"
    },
    {
      "x": -3,
      "y": 8,
      "z": -1,
      "name": "Empty"
    },
    {
      "x": -3,
      "y": 9,
      "z": -1,
      "name": "Empty"
    },
    {
      "x": -3,
      "y": 10,
      "z": -1,
      "name": "Empty"
    },
    {
      "x": -3,
      "y": 11,
      "z": -1,
      "name": "Empty"
    },
    {
      "x": -3,
      "y": 12,
      "z": -1,
      "name": "Empty"
    },
    {
      "x": -3,
      "y": 13,
      "z": -1,
      "name": "Empty"
    },
    {
      "x": -3,
      "y": 14,
      "z": -1,
      "name": "Empty"
    },
    {
      "x": -3,
      "y": 15,
      "z": -1,
      "name": "Soil_Mud_Dry"
    },
    {
      "x": -3,
      "y": 16,
      "z": -1,
      "name": "Soil_Mud_Dry"
    },
    {
      "x": -3,
      "y": 3,
      "z": 0,
      "name": "Soil_Dirt_Poisoned"
    },
    {
      "x": -3,
      "y": 4,
      "z": 0,
      "name": "Soil_Dirt_Poisoned"
    },
    {
      "x": -3,
      "y": 5,
      "z": 0,
      "name": "Empty"
    },
    {
      "x": -3,
      "y": 6,
      "z": 0,
      "name": "Empty"
    },
    {
      "x": -3,
      "y": 7,
      "z": 0,
      "name": "Empty"
    },
    {
      "x": -3,
      "y": 8,
      "z": 0,
      "name": "Empty"
    },
    {
      "x": -3,
      "y": 9,
      "z": 0,
      "name": "Empty"
    },
    {
      "x": -3,
      "y": 10,
      "z": 0,
      "name": "Empty"
    },
    {
      "x": -3,
      "y": 11,
      "z": 0,
      "name": "Empty"
    },
    {
      "x": -3,
      "y": 12,
      "z": 0,
      "name": "Empty"
    },
    {
      "x": -3,
      "y": 13,
      "z": 0,
      "name": "Empty"
    },
    {
      "x": -3,
      "y": 14,
      "z": 0,
      "name": "Empty"
    },
    {
      "x": -3,
      "y": 15,
      "z": 0,
      "name": "Soil_Mud_Dry"
    },
    {
      "x": -3,
      "y": 16,
      "z": 0,
      "name": "Soil_Mud_Dry"
    },
    {
      "x": -3,
      "y": 3,
      "z": 1,
      "name": "Soil_Dirt_Poisoned"
    },
    {
      "x": -3,
      "y": 4,
      "z": 1,
      "name": "Soil_Dirt_Poisoned"
    },
    {
      "x": -3,
      "y": 5,
      "z": 1,
      "name": "Plant_Bramble_Dead_Lavathorn"
    },
    {
      "x": -3,
      "y": 6,
      "z": 1,
      "name": "Empty"
    },
    {
      "x": -3,
      "y": 7,
      "z": 1,
      "name": "Empty"
    },
    {
      "x": -3,
      "y": 8,
      "z": 1,
      "name": "Empty"
    },
    {
      "x": -3,
      "y": 9,
      "z": 1,
      "name": "Empty"
    },
    {
      "x": -3,
      "y": 10,
      "z": 1,
      "name": "Empty"
    },
    {
      "x": -3,
      "y": 11,
      "z": 1,
      "name": "Empty"
    },
    {
      "x": -3,
      "y": 12,
      "z": 1,
      "name": "Empty"
    },
    {
      "x": -3,
      "y": 13,
      "z": 1,
      "name": "Wood_Dry_Roots"
    },
    {
      "x": -3,
      "y": 14,
      "z": 1,
      "name": "Soil_Hive"
    },
    {
      "x": -3,
      "y": 15,
      "z": 1,
      "name": "Soil_Mud_Dry"
    },
    {
      "x": -3,
      "y": 16,
      "z": 1,
      "name": "Soil_Mud_Dry"
    },
    {
      "x": -3,
      "y": 3,
      "z": 2,
      "name": "Soil_Dirt_Poisoned"
    },
    {
      "x": -3,
      "y": 4,
      "z": 2,
      "name": "Soil_Roots_Poisoned"
    },
    {
      "x": -3,
      "y": 5,
      "z": 2,
      "name": "Empty"
    },
    {
      "x": -3,
      "y": 6,
      "z": 2,
      "name": "Empty"
    },
    {
      "x": -3,
      "y": 7,
      "z": 2,
      "name": "Empty"
    },
    {
      "x": -3,
      "y": 8,
      "z": 2,
      "name": "Empty"
    },
    {
      "x": -3,
      "y": 9,
      "z": 2,
      "name": "Empty"
    },
    {
      "x": -3,
      "y": 10,
      "z": 2,
      "name": "Empty"
    },
    {
      "x": -3,
      "y": 11,
      "z": 2,
      "name": "Empty"
    },
    {
      "x": -3,
      "y": 12,
      "z": 2,
      "name": "Empty"
    },
    {
      "x": -3,
      "y": 13,
      "z": 2,
      "name": "Empty"
    },
    {
      "x": -3,
      "y": 14,
      "z": 2,
      "name": "Empty"
    },
    {
      "x": -3,
      "y": 15,
      "z": 2,
      "name": "Soil_Mud_Dry"
    },
    {
      "x": -3,
      "y": 16,
      "z": 2,
      "name": "Soil_Mud_Dry"
    },
    {
      "x": -3,
      "y": 3,
      "z": 3,
      "name": "Soil_Dirt_Poisoned"
    },
    {
      "x": -3,
      "y": 4,
      "z": 3,
      "name": "Soil_Dirt_Poisoned"
    },
    {
      "x": -3,
      "y": 5,
      "z": 3,
      "name": "Plant_Crop_Mushroom_Glowing_Orange"
    },
    {
      "x": -3,
      "y": 6,
      "z": 3,
      "name": "Empty"
    },
    {
      "x": -3,
      "y": 7,
      "z": 3,
      "name": "Empty"
    },
    {
      "x": -3,
      "y": 8,
      "z": 3,
      "name": "Empty"
    },
    {
      "x": -3,
      "y": 9,
      "z": 3,
      "name": "Empty"
    },
    {
      "x": -3,
      "y": 10,
      "z": 3,
      "name": "Empty"
    },
    {
      "x": -3,
      "y": 11,
      "z": 3,
      "name": "Empty"
    },
    {
      "x": -3,
      "y": 12,
      "z": 3,
      "name": "Empty"
    },
    {
      "x": -3,
      "y": 13,
      "z": 3,
      "name": "Soil_Mud_Dry"
    },
    {
      "x": -3,
      "y": 14,
      "z": 3,
      "name": "Soil_Mud_Dry"
    },
    {
      "x": -3,
      "y": 15,
      "z": 3,
      "name": "Soil_Mud_Dry"
    },
    {
      "x": -3,
      "y": 16,
      "z": 3,
      "name": "Soil_Mud_Dry"
    },
    {
      "x": -3,
      "y": 3,
      "z": 4,
      "name": "Soil_Mud_Dry"
    },
    {
      "x": -3,
      "y": 4,
      "z": 4,
      "name": "Soil_Dirt_Poisoned"
    },
    {
      "x": -3,
      "y": 5,
      "z": 4,
      "name": "Soil_Dirt_Poisoned"
    },
    {
      "x": -3,
      "y": 6,
      "z": 4,
      "name": "Empty"
    },
    {
      "x": -3,
      "y": 7,
      "z": 4,
      "name": "Empty"
    },
    {
      "x": -3,
      "y": 8,
      "z": 4,
      "name": "Empty"
    },
    {
      "x": -3,
      "y": 9,
      "z": 4,
      "name": "Soil_Mud_Dry"
    },
    {
      "x": -3,
      "y": 10,
      "z": 4,
      "name": "Soil_Mud_Dry"
    },
    {
      "x": -3,
      "y": 11,
      "z": 4,
      "name": "Soil_Mud_Dry"
    },
    {
      "x": -3,
      "y": 12,
      "z": 4,
      "name": "Soil_Mud_Dry"
    },
    {
      "x": -3,
      "y": 13,
      "z": 4,
      "name": "Soil_Mud_Dry"
    },
    {
      "x": -3,
      "y": 14,
      "z": 4,
      "name": "Soil_Mud_Dry"
    },
    {
      "x": -3,
      "y": 15,
      "z": 4,
      "name": "Soil_Mud_Dry"
    },
    {
      "x": -3,
      "y": 16,
      "z": 4,
      "name": "Soil_Mud_Dry"
    },
    {
      "x": -3,
      "y": 3,
      "z": 5,
      "name": "Soil_Mud_Dry"
    },
    {
      "x": -3,
      "y": 4,
      "z": 5,
      "name": "Soil_Mud_Dry"
    },
    {
      "x": -3,
      "y": 5,
      "z": 5,
      "name": "Soil_Dirt_Poisoned"
    },
    {
      "x": -3,
      "y": 6,
      "z": 5,
      "name": "Soil_Mud_Dry"
    },
    {
      "x": -3,
      "y": 7,
      "z": 5,
      "name": "Soil_Mud_Dry"
    },
    {
      "x": -3,
      "y": 8,
      "z": 5,
      "name": "Soil_Mud_Dry"
    },
    {
      "x": -3,
      "y": 9,
      "z": 5,
      "name": "Soil_Mud_Dry"
    },
    {
      "x": -3,
      "y": 10,
      "z": 5,
      "name": "Soil_Mud_Dry"
    },
    {
      "x": -3,
      "y": 11,
      "z": 5,
      "name": "Soil_Mud_Dry"
    },
    {
      "x": -3,
      "y": 12,
      "z": 5,
      "name": "Soil_Mud_Dry"
    },
    {
      "x": -3,
      "y": 13,
      "z": 5,
      "name": "Soil_Mud_Dry"
    },
    {
      "x": -3,
      "y": 14,
      "z": 5,
      "name": "Soil_Mud_Dry"
    },
    {
      "x": -3,
      "y": 15,
      "z": 5,
      "name": "Soil_Mud_Dry"
    },
    {
      "x": -3,
      "y": 16,
      "z": 5,
      "name": "Soil_Mud_Dry"
    },
    {
      "x": -2,
      "y": 3,
      "z": -5,
      "name": "Soil_Mud_Dry"
    },
    {
      "x": -2,
      "y": 4,
      "z": -5,
      "name": "Soil_Dirt_Poisoned"
    },
    {
      "x": -2,
      "y": 5,
      "z": -5,
      "name": "Empty"
    },
    {
      "x": -2,
      "y": 6,
      "z": -5,
      "name": "Empty"
    },
    {
      "x": -2,
      "y": 7,
      "z": -5,
      "name": "Empty"
    },
    {
      "x": -2,
      "y": 8,
      "z": -5,
      "name": "Empty"
    },
    {
      "x": -2,
      "y": 9,
      "z": -5,
      "name": "Empty"
    },
    {
      "x": -2,
      "y": 10,
      "z": -5,
      "name": "Soil_Mud_Dry"
    },
    {
      "x": -2,
      "y": 11,
      "z": -5,
      "name": "Soil_Mud_Dry"
    },
    {
      "x": -2,
      "y": 12,
      "z": -5,
      "name": "Soil_Mud_Dry"
    },
    {
      "x": -2,
      "y": 13,
      "z": -5,
      "name": "Soil_Mud_Dry"
    },
    {
      "x": -2,
      "y": 14,
      "z": -5,
      "name": "Soil_Mud_Dry"
    },
    {
      "x": -2,
      "y": 15,
      "z": -5,
      "name": "Soil_Mud_Dry"
    },
    {
      "x": -2,
      "y": 16,
      "z": -5,
      "name": "Soil_Mud_Dry"
    },
    {
      "x": -2,
      "y": 3,
      "z": -4,
      "name": "Soil_Dirt_Poisoned"
    },
    {
      "x": -2,
      "y": 4,
      "z": -4,
      "name": "Soil_Dirt_Poisoned"
    },
    {
      "x": -2,
      "y": 5,
      "z": -4,
      "name": "Empty"
    },
    {
      "x": -2,
      "y": 6,
      "z": -4,
      "name": "Empty"
    },
    {
      "x": -2,
      "y": 7,
      "z": -4,
      "name": "Empty"
    },
    {
      "x": -2,
      "y": 8,
      "z": -4,
      "name": "Empty"
    },
    {
      "x": -2,
      "y": 9,
      "z": -4,
      "name": "Empty"
    },
    {
      "x": -2,
      "y": 10,
      "z": -4,
      "name": "Soil_Hive"
    },
    {
      "x": -2,
      "y": 11,
      "z": -4,
      "name": "Soil_Hive"
    },
    {
      "x": -2,
      "y": 12,
      "z": -4,
      "name": "Soil_Hive"
    },
    {
      "x": -2,
      "y": 13,
      "z": -4,
      "name": "Soil_Mud_Dry"
    },
    {
      "x": -2,
      "y": 14,
      "z": -4,
      "name": "Soil_Mud_Dry"
    },
    {
      "x": -2,
      "y": 15,
      "z": -4,
      "name": "Soil_Mud_Dry"
    },
    {
      "x": -2,
      "y": 16,
      "z": -4,
      "name": "Soil_Mud_Dry"
    },
    {
      "x": -2,
      "y": 3,
      "z": -3,
      "name": "Soil_Dirt_Poisoned"
    },
    {
      "x": -2,
      "y": 4,
      "z": -3,
      "name": "Soil_Dirt_Poisoned"
    },
    {
      "x": -2,
      "y": 5,
      "z": -3,
      "name": "Empty"
    },
    {
      "x": -2,
      "y": 6,
      "z": -3,
      "name": "Empty"
    },
    {
      "x": -2,
      "y": 7,
      "z": -3,
      "name": "Empty"
    },
    {
      "x": -2,
      "y": 8,
      "z": -3,
      "name": "Empty"
    },
    {
      "x": -2,
      "y": 9,
      "z": -3,
      "name": "Empty"
    },
    {
      "x": -2,
      "y": 10,
      "z": -3,
      "name": "Empty"
    },
    {
      "x": -2,
      "y": 11,
      "z": -3,
      "name": "Empty"
    },
    {
      "x": -2,
      "y": 12,
      "z": -3,
      "name": "Empty"
    },
    {
      "x": -2,
      "y": 13,
      "z": -3,
      "name": "Soil_Hive"
    },
    {
      "x": -2,
      "y": 14,
      "z": -3,
      "name": "Soil_Mud_Dry"
    },
    {
      "x": -2,
      "y": 15,
      "z": -3,
      "name": "Soil_Mud_Dry"
    },
    {
      "x": -2,
      "y": 16,
      "z": -3,
      "name": "Soil_Mud_Dry"
    },
    {
      "x": -2,
      "y": 3,
      "z": -2,
      "name": "Soil_Dirt_Poisoned"
    },
    {
      "x": -2,
      "y": 4,
      "z": -2,
      "name": "Empty"
    },
    {
      "x": -2,
      "y": 5,
      "z": -2,
      "name": "Empty"
    },
    {
      "x": -2,
      "y": 6,
      "z": -2,
      "name": "Empty"
    },
    {
      "x": -2,
      "y": 7,
      "z": -2,
      "name": "Empty"
    },
    {
      "x": -2,
      "y": 8,
      "z": -2,
      "name": "Empty"
    },
    {
      "x": -2,
      "y": 9,
      "z": -2,
      "name": "Empty"
    },
    {
      "x": -2,
      "y": 10,
      "z": -2,
      "name": "Empty"
    },
    {
      "x": -2,
      "y": 11,
      "z": -2,
      "name": "Empty"
    },
    {
      "x": -2,
      "y": 12,
      "z": -2,
      "name": "Empty"
    },
    {
      "x": -2,
      "y": 13,
      "z": -2,
      "name": "Soil_Hive"
    },
    {
      "x": -2,
      "y": 14,
      "z": -2,
      "name": "Soil_Mud_Dry"
    },
    {
      "x": -2,
      "y": 15,
      "z": -2,
      "name": "Soil_Mud_Dry"
    },
    {
      "x": -2,
      "y": 16,
      "z": -2,
      "name": "Soil_Mud_Dry"
    },
    {
      "x": -2,
      "y": 3,
      "z": -1,
      "name": "Soil_Mud_Dry"
    },
    {
      "x": -2,
      "y": 4,
      "z": -1,
      "name": "Empty"
    },
    {
      "x": -2,
      "y": 5,
      "z": -1,
      "name": "Empty"
    },
    {
      "x": -2,
      "y": 6,
      "z": -1,
      "name": "Empty"
    },
    {
      "x": -2,
      "y": 7,
      "z": -1,
      "name": "Empty"
    },
    {
      "x": -2,
      "y": 8,
      "z": -1,
      "name": "Empty"
    },
    {
      "x": -2,
      "y": 9,
      "z": -1,
      "name": "Empty"
    },
    {
      "x": -2,
      "y": 10,
      "z": -1,
      "name": "Empty"
    },
    {
      "x": -2,
      "y": 11,
      "z": -1,
      "name": "Empty"
    },
    {
      "x": -2,
      "y": 12,
      "z": -1,
      "name": "Empty"
    },
    {
      "x": -2,
      "y": 13,
      "z": -1,
      "name": "Empty"
    },
    {
      "x": -2,
      "y": 14,
      "z": -1,
      "name": "Soil_Hive"
    },
    {
      "x": -2,
      "y": 15,
      "z": -1,
      "name": "Soil_Mud_Dry"
    },
    {
      "x": -2,
      "y": 16,
      "z": -1,
      "name": "Soil_Mud_Dry"
    },
    {
      "x": -2,
      "y": 3,
      "z": 0,
      "name": "Soil_Dirt_Poisoned"
    },
    {
      "x": -2,
      "y": 4,
      "z": 0,
      "name": "Soil_Dirt_Poisoned"
    },
    {
      "x": -2,
      "y": 5,
      "z": 0,
      "name": "Empty"
    },
    {
      "x": -2,
      "y": 6,
      "z": 0,
      "name": "Empty"
    },
    {
      "x": -2,
      "y": 7,
      "z": 0,
      "name": "Empty"
    },
    {
      "x": -2,
      "y": 8,
      "z": 0,
      "name": "Empty"
    },
    {
      "x": -2,
      "y": 9,
      "z": 0,
      "name": "Empty"
    },
    {
      "x": -2,
      "y": 10,
      "z": 0,
      "name": "Empty"
    },
    {
      "x": -2,
      "y": 11,
      "z": 0,
      "name": "Empty"
    },
    {
      "x": -2,
      "y": 12,
      "z": 0,
      "name": "Empty"
    },
    {
      "x": -2,
      "y": 13,
      "z": 0,
      "name": "Empty"
    },
    {
      "x": -2,
      "y": 14,
      "z": 0,
      "name": "Soil_Hive"
    },
    {
      "x": -2,
      "y": 15,
      "z": 0,
      "name": "Soil_Mud_Dry"
    },
    {
      "x": -2,
      "y": 16,
      "z": 0,
      "name": "Soil_Mud_Dry"
    },
    {
      "x": -2,
      "y": 3,
      "z": 1,
      "name": "Soil_Dirt_Poisoned"
    },
    {
      "x": -2,
      "y": 4,
      "z": 1,
      "name": "Soil_Dirt_Poisoned"
    },
    {
      "x": -2,
      "y": 5,
      "z": 1,
      "name": "Empty"
    },
    {
      "x": -2,
      "y": 6,
      "z": 1,
      "name": "Empty"
    },
    {
      "x": -2,
      "y": 7,
      "z": 1,
      "name": "Empty"
    },
    {
      "x": -2,
      "y": 8,
      "z": 1,
      "name": "Empty"
    },
    {
      "x": -2,
      "y": 9,
      "z": 1,
      "name": "Empty"
    },
    {
      "x": -2,
      "y": 10,
      "z": 1,
      "name": "Empty"
    },
    {
      "x": -2,
      "y": 11,
      "z": 1,
      "name": "Empty"
    },
    {
      "x": -2,
      "y": 12,
      "z": 1,
      "name": "Empty"
    },
    {
      "x": -2,
      "y": 13,
      "z": 1,
      "name": "Empty"
    },
    {
      "x": -2,
      "y": 14,
      "z": 1,
      "name": "Soil_Hive"
    },
    {
      "x": -2,
      "y": 15,
      "z": 1,
      "name": "Soil_Mud_Dry"
    },
    {
      "x": -2,
      "y": 16,
      "z": 1,
      "name": "Soil_Mud_Dry"
    },
    {
      "x": -2,
      "y": 3,
      "z": 2,
      "name": "Soil_Dirt_Poisoned"
    },
    {
      "x": -2,
      "y": 4,
      "z": 2,
      "name": "Soil_Roots_Poisoned"
    },
    {
      "x": -2,
      "y": 5,
      "z": 2,
      "name": "Plant_Crop_Mushroom_Glowing_Orange"
    },
    {
      "x": -2,
      "y": 6,
      "z": 2,
      "name": "Empty"
    },
    {
      "x": -2,
      "y": 7,
      "z": 2,
      "name": "Empty"
    },
    {
      "x": -2,
      "y": 8,
      "z": 2,
      "name": "Empty"
    },
    {
      "x": -2,
      "y": 9,
      "z": 2,
      "name": "Empty"
    },
    {
      "x": -2,
      "y": 10,
      "z": 2,
      "name": "Empty"
    },
    {
      "x": -2,
      "y": 11,
      "z": 2,
      "name": "Empty"
    },
    {
      "x": -2,
      "y": 12,
      "z": 2,
      "name": "Empty"
    },
    {
      "x": -2,
      "y": 13,
      "z": 2,
      "name": "Soil_Hive"
    },
    {
      "x": -2,
      "y": 14,
      "z": 2,
      "name": "Empty"
    },
    {
      "x": -2,
      "y": 15,
      "z": 2,
      "name": "Soil_Mud_Dry"
    },
    {
      "x": -2,
      "y": 16,
      "z": 2,
      "name": "Soil_Mud_Dry"
    },
    {
      "x": -2,
      "y": 3,
      "z": 3,
      "name": "Soil_Dirt_Poisoned"
    },
    {
      "x": -2,
      "y": 4,
      "z": 3,
      "name": "Soil_Roots_Poisoned"
    },
    {
      "x": -2,
      "y": 5,
      "z": 3,
      "name": "Empty"
    },
    {
      "x": -2,
      "y": 6,
      "z": 3,
      "name": "Empty"
    },
    {
      "x": -2,
      "y": 7,
      "z": 3,
      "name": "Empty"
    },
    {
      "x": -2,
      "y": 8,
      "z": 3,
      "name": "Empty"
    },
    {
      "x": -2,
      "y": 9,
      "z": 3,
      "name": "Empty"
    },
    {
      "x": -2,
      "y": 10,
      "z": 3,
      "name": "Empty"
    },
    {
      "x": -2,
      "y": 11,
      "z": 3,
      "name": "Empty"
    },
    {
      "x": -2,
      "y": 12,
      "z": 3,
      "name": "Soil_Hive"
    },
    {
      "x": -2,
      "y": 13,
      "z": 3,
      "name": "Soil_Hive"
    },
    {
      "x": -2,
      "y": 14,
      "z": 3,
      "name": "Soil_Mud_Dry"
    },
    {
      "x": -2,
      "y": 15,
      "z": 3,
      "name": "Soil_Mud_Dry"
    },
    {
      "x": -2,
      "y": 16,
      "z": 3,
      "name": "Soil_Mud_Dry"
    },
    {
      "x": -2,
      "y": 3,
      "z": 4,
      "name": "Soil_Mud_Dry"
    },
    {
      "x": -2,
      "y": 4,
      "z": 4,
      "name": "Soil_Dirt_Poisoned"
    },
    {
      "x": -2,
      "y": 5,
      "z": 4,
      "name": "Soil_Dirt_Poisoned"
    },
    {
      "x": -2,
      "y": 6,
      "z": 4,
      "name": "Empty"
    },
    {
      "x": -2,
      "y": 7,
      "z": 4,
      "name": "Empty"
    },
    {
      "x": -2,
      "y": 8,
      "z": 4,
      "name": "Empty"
    },
    {
      "x": -2,
      "y": 9,
      "z": 4,
      "name": "Empty"
    },
    {
      "x": -2,
      "y": 10,
      "z": 4,
      "name": "Empty"
    },
    {
      "x": -2,
      "y": 11,
      "z": 4,
      "name": "Soil_Mud_Dry"
    },
    {
      "x": -2,
      "y": 12,
      "z": 4,
      "name": "Soil_Mud_Dry"
    },
    {
      "x": -2,
      "y": 13,
      "z": 4,
      "name": "Soil_Mud_Dry"
    },
    {
      "x": -2,
      "y": 14,
      "z": 4,
      "name": "Soil_Mud_Dry"
    },
    {
      "x": -2,
      "y": 15,
      "z": 4,
      "name": "Soil_Mud_Dry"
    },
    {
      "x": -2,
      "y": 16,
      "z": 4,
      "name": "Soil_Mud_Dry"
    },
    {
      "x": -2,
      "y": 3,
      "z": 5,
      "name": "Soil_Mud_Dry"
    },
    {
      "x": -2,
      "y": 4,
      "z": 5,
      "name": "Soil_Dirt_Poisoned"
    },
    {
      "x": -2,
      "y": 5,
      "z": 5,
      "name": "Soil_Dirt_Poisoned"
    },
    {
      "x": -2,
      "y": 6,
      "z": 5,
      "name": "Soil_Dirt_Poisoned"
    },
    {
      "x": -2,
      "y": 7,
      "z": 5,
      "name": "Soil_Mud_Dry"
    },
    {
      "x": -2,
      "y": 8,
      "z": 5,
      "name": "Soil_Mud_Dry"
    },
    {
      "x": -2,
      "y": 9,
      "z": 5,
      "name": "Soil_Mud_Dry"
    },
    {
      "x": -2,
      "y": 10,
      "z": 5,
      "name": "Soil_Mud_Dry"
    },
    {
      "x": -2,
      "y": 11,
      "z": 5,
      "name": "Soil_Mud_Dry"
    },
    {
      "x": -2,
      "y": 12,
      "z": 5,
      "name": "Soil_Mud_Dry"
    },
    {
      "x": -2,
      "y": 13,
      "z": 5,
      "name": "Soil_Mud_Dry"
    },
    {
      "x": -2,
      "y": 14,
      "z": 5,
      "name": "Soil_Mud_Dry"
    },
    {
      "x": -2,
      "y": 15,
      "z": 5,
      "name": "Soil_Mud_Dry"
    },
    {
      "x": -2,
      "y": 16,
      "z": 5,
      "name": "Soil_Mud_Dry"
    },
    {
      "x": -1,
      "y": 3,
      "z": -5,
      "name": "Soil_Mud_Dry"
    },
    {
      "x": -1,
      "y": 4,
      "z": -5,
      "name": "Soil_Dirt_Poisoned"
    },
    {
      "x": -1,
      "y": 5,
      "z": -5,
      "name": "Empty"
    },
    {
      "x": -1,
      "y": 6,
      "z": -5,
      "name": "Empty"
    },
    {
      "x": -1,
      "y": 7,
      "z": -5,
      "name": "Empty"
    },
    {
      "x": -1,
      "y": 8,
      "z": -5,
      "name": "Empty"
    },
    {
      "x": -1,
      "y": 9,
      "z": -5,
      "name": "Empty"
    },
    {
      "x": -1,
      "y": 10,
      "z": -5,
      "name": "Soil_Mud_Dry"
    },
    {
      "x": -1,
      "y": 11,
      "z": -5,
      "name": "Soil_Mud_Dry"
    },
    {
      "x": -1,
      "y": 12,
      "z": -5,
      "name": "Soil_Mud_Dry"
    },
    {
      "x": -1,
      "y": 13,
      "z": -5,
      "name": "Soil_Mud_Dry"
    },
    {
      "x": -1,
      "y": 14,
      "z": -5,
      "name": "Soil_Mud_Dry"
    },
    {
      "x": -1,
      "y": 15,
      "z": -5,
      "name": "Soil_Mud_Dry"
    },
    {
      "x": -1,
      "y": 16,
      "z": -5,
      "name": "Soil_Mud_Dry"
    },
    {
      "x": -1,
      "y": 3,
      "z": -4,
      "name": "Soil_Dirt_Poisoned"
    },
    {
      "x": -1,
      "y": 4,
      "z": -4,
      "name": "Soil_Dirt_Poisoned"
    },
    {
      "x": -1,
      "y": 5,
      "z": -4,
      "name": "Empty"
    },
    {
      "x": -1,
      "y": 6,
      "z": -4,
      "name": "Empty"
    },
    {
      "x": -1,
      "y": 7,
      "z": -4,
      "name": "Empty"
    },
    {
      "x": -1,
      "y": 8,
      "z": -4,
      "name": "Empty"
    },
    {
      "x": -1,
      "y": 9,
      "z": -4,
      "name": "Empty"
    },
    {
      "x": -1,
      "y": 10,
      "z": -4,
      "name": "Empty"
    },
    {
      "x": -1,
      "y": 11,
      "z": -4,
      "name": "Soil_Hive"
    },
    {
      "x": -1,
      "y": 12,
      "z": -4,
      "name": "Soil_Mud_Dry"
    },
    {
      "x": -1,
      "y": 13,
      "z": -4,
      "name": "Soil_Mud_Dry"
    },
    {
      "x": -1,
      "y": 14,
      "z": -4,
      "name": "Soil_Mud_Dry"
    },
    {
      "x": -1,
      "y": 15,
      "z": -4,
      "name": "Soil_Mud_Dry"
    },
    {
      "x": -1,
      "y": 16,
      "z": -4,
      "name": "Soil_Mud_Dry"
    },
    {
      "x": -1,
      "y": 3,
      "z": -3,
      "name": "Soil_Dirt_Poisoned"
    },
    {
      "x": -1,
      "y": 4,
      "z": -3,
      "name": "Soil_Dirt_Poisoned"
    },
    {
      "x": -1,
      "y": 5,
      "z": -3,
      "name": "Empty"
    },
    {
      "x": -1,
      "y": 6,
      "z": -3,
      "name": "Empty"
    },
    {
      "x": -1,
      "y": 7,
      "z": -3,
      "name": "Empty"
    },
    {
      "x": -1,
      "y": 8,
      "z": -3,
      "name": "Empty"
    },
    {
      "x": -1,
      "y": 9,
      "z": -3,
      "name": "Empty"
    },
    {
      "x": -1,
      "y": 10,
      "z": -3,
      "name": "Empty"
    },
    {
      "x": -1,
      "y": 11,
      "z": -3,
      "name": "Empty"
    },
    {
      "x": -1,
      "y": 12,
      "z": -3,
      "name": "Empty"
    },
    {
      "x": -1,
      "y": 13,
      "z": -3,
      "name": "Empty"
    },
    {
      "x": -1,
      "y": 14,
      "z": -3,
      "name": "Soil_Mud_Dry"
    },
    {
      "x": -1,
      "y": 15,
      "z": -3,
      "name": "Soil_Mud_Dry"
    },
    {
      "x": -1,
      "y": 16,
      "z": -3,
      "name": "Soil_Mud_Dry"
    },
    {
      "x": -1,
      "y": 3,
      "z": -2,
      "name": "Soil_Dirt_Poisoned"
    },
    {
      "x": -1,
      "y": 4,
      "z": -2,
      "name": "Empty"
    },
    {
      "x": -1,
      "y": 5,
      "z": -2,
      "name": "Empty"
    },
    {
      "x": -1,
      "y": 6,
      "z": -2,
      "name": "Empty"
    },
    {
      "x": -1,
      "y": 7,
      "z": -2,
      "name": "Empty"
    },
    {
      "x": -1,
      "y": 8,
      "z": -2,
      "name": "Empty"
    },
    {
      "x": -1,
      "y": 9,
      "z": -2,
      "name": "Empty"
    },
    {
      "x": -1,
      "y": 10,
      "z": -2,
      "name": "Empty"
    },
    {
      "x": -1,
      "y": 11,
      "z": -2,
      "name": "Empty"
    },
    {
      "x": -1,
      "y": 12,
      "z": -2,
      "name": "Empty"
    },
    {
      "x": -1,
      "y": 13,
      "z": -2,
      "name": "Empty"
    },
    {
      "x": -1,
      "y": 14,
      "z": -2,
      "name": "Soil_Mud_Dry"
    },
    {
      "x": -1,
      "y": 15,
      "z": -2,
      "name": "Soil_Mud_Dry"
    },
    {
      "x": -1,
      "y": 16,
      "z": -2,
      "name": "Soil_Mud_Dry"
    },
    {
      "x": -1,
      "y": 3,
      "z": -1,
      "name": "Empty"
    },
    {
      "x": -1,
      "y": 4,
      "z": -1,
      "name": "Empty"
    },
    {
      "x": -1,
      "y": 5,
      "z": -1,
      "name": "Empty"
    },
    {
      "x": -1,
      "y": 6,
      "z": -1,
      "name": "Empty"
    },
    {
      "x": -1,
      "y": 7,
      "z": -1,
      "name": "Empty"
    },
    {
      "x": -1,
      "y": 8,
      "z": -1,
      "name": "Empty"
    },
    {
      "x": -1,
      "y": 9,
      "z": -1,
      "name": "Empty"
    },
    {
      "x": -1,
      "y": 10,
      "z": -1,
      "name": "Empty"
    },
    {
      "x": -1,
      "y": 11,
      "z": -1,
      "name": "Empty"
    },
    {
      "x": -1,
      "y": 12,
      "z": -1,
      "name": "Empty"
    },
    {
      "x": -1,
      "y": 13,
      "z": -1,
      "name": "Empty"
    },
    {
      "x": -1,
      "y": 14,
      "z": -1,
      "name": "Soil_Hive"
    },
    {
      "x": -1,
      "y": 15,
      "z": -1,
      "name": "Soil_Mud_Dry"
    },
    {
      "x": -1,
      "y": 16,
      "z": -1,
      "name": "Soil_Mud_Dry"
    },
    {
      "x": -1,
      "y": 3,
      "z": 0,
      "name": "Empty"
    },
    {
      "x": -1,
      "y": 4,
      "z": 0,
      "name": "Empty"
    },
    {
      "x": -1,
      "y": 5,
      "z": 0,
      "name": "Empty"
    },
    {
      "x": -1,
      "y": 6,
      "z": 0,
      "name": "Empty"
    },
    {
      "x": -1,
      "y": 7,
      "z": 0,
      "name": "Empty"
    },
    {
      "x": -1,
      "y": 8,
      "z": 0,
      "name": "Empty"
    },
    {
      "x": -1,
      "y": 9,
      "z": 0,
      "name": "Empty"
    },
    {
      "x": -1,
      "y": 10,
      "z": 0,
      "name": "Empty"
    },
    {
      "x": -1,
      "y": 11,
      "z": 0,
      "name": "Empty"
    },
    {
      "x": -1,
      "y": 12,
      "z": 0,
      "name": "Empty"
    },
    {
      "x": -1,
      "y": 13,
      "z": 0,
      "name": "Empty"
    },
    {
      "x": -1,
      "y": 14,
      "z": 0,
      "name": "Empty"
    },
    {
      "x": -1,
