{
  "version": 8,
  "blockIdVersion": 10,
  "anchorX": 1,
  "anchorY": 8,
  "anchorZ": 2,
  "blocks": [
    {
      "x": -5,
      "y": 6,
      "z": 0,
      "name": "Soil_Gravel_Sand"
    },
    {
      "x": -5,
      "y": 7,
      "z": 0,
      "name": "Soil_Gravel_Sand"
    },
    {
      "x": -5,
      "y": 9,
      "z": 0,
      "name": "Deco_Bone_Full"
    },
    {
      "x": -5,
      "y": 10,
      "z": 0,
      "name": "Deco_Bone_Full"
    },
    {
      "x": -5,
      "y": 5,
      "z": 1,
      "name": "Soil_Gravel_Sand"
    },
    {
      "x": -5,
      "y": 6,
      "z": 1,
      "name": "Soil_Gravel_Sand"
    },
    {
      "x": -5,
      "y": 7,
      "z": 1,
      "name": "Soil_Gravel_Sand"
    },
    {
      "x": -5,
      "y": 8,
      "z": 1,
      "name": "Deco_Bone_Full"
    },
    {
      "x": -5,
      "y": 9,
      "z": 1,
      "name": "Deco_Bone_Full"
    },
    {
      "x": -5,
      "y": 10,
      "z": 1,
      "name": "Deco_Bone_Full"
    },
    {
      "x": -5,
      "y": 11,
      "z": 1,
      "name": "Deco_Bone_Full"
    },
    {
      "x": -5,
      "y": 12,
      "z": 1,
      "name": "Deco_Bone_Full"
    },
    {
      "x": -5,
      "y": 5,
      "z": 2,
      "name": "Soil_Gravel_Sand"
    },
    {
      "x": -5,
      "y": 6,
      "z": 2,
      "name": "Soil_Gravel_Sand"
    },
    {
      "x": -5,
      "y": 7,
      "z": 2,
      "name": "Soil_Gravel_Sand"
    },
    {
      "x": -5,
      "y": 8,
      "z": 2,
      "name": "Soil_Gravel_Sand"
    },
    {
      "x": -5,
      "y": 9,
      "z": 2,
      "name": "Rock_Sandstone_Cobble"
    },
    {
      "x": -5,
      "y": 10,
      "z": 2,
      "name": "Deco_Bone_Full"
    },
    {
      "x": -5,
      "y": 11,
      "z": 2,
      "name": "Deco_Bone_Full"
    },
    {
      "x": -5,
      "y": 12,
      "z": 2,
      "name": "Deco_Bone_Full"
    },
    {
      "x": -5,
      "y": 13,
      "z": 2,
      "name": "Deco_Bone_Full"
    },
    {
      "x": -5,
      "y": 14,
      "z": 2,
      "name": "Deco_Bone_Full"
    },
    {
      "x": -5,
      "y": 15,
      "z": 2,
      "name": "Deco_Bone_Full"
    },
    {
      "x": -5,
      "y": 6,
      "z": 3,
      "name": "Rock_Sandstone_Cobble"
    },
    {
      "x": -5,
      "y": 7,
      "z": 3,
      "name": "Rock_Sandstone_Cobble"
    },
    {
      "x": -5,
      "y": 8,
      "z": 3,
      "name": "Rock_Sandstone_Cobble"
    },
    {
      "x": -4,
      "y": 5,
      "z": 0,
      "name": "Soil_Gravel_Sand"
    },
    {
      "x": -4,
      "y": 6,
      "z": 0,
      "name": "Soil_Gravel_Sand"
    },
    {
      "x": -4,
      "y": 7,
      "z": 0,
      "name": "Soil_Gravel_Sand"
    },
    {
      "x": -4,
      "y": 8,
      "z": 0,
      "name": "Deco_Bone_Full"
    },
    {
      "x": -4,
      "y": 9,
      "z": 0,
      "name": "Deco_Bone_Full"
    },
    {
      "x": -4,
      "y": 10,
      "z": 0,
      "name": "Deco_Bone_Full"
    },
    {
      "x": -4,
      "y": 11,
      "z": 0,
      "name": "Deco_Bone_Full"
    },
    {
      "x": -4,
      "y": 5,
      "z": 1,
      "name": "Soil_Gravel_Sand"
    },
    {
      "x": -4,
      "y": 6,
      "z": 1,
      "name": "Soil_Gravel_Sand"
    },
    {
      "x": -4,
      "y": 7,
      "z": 1,
      "name": "Soil_Gravel_Sand"
    },
    {
      "x": -4,
      "y": 8,
      "z": 1,
      "name": "Deco_Bone_Full"
    },
    {
      "x": -4,
      "y": 9,
      "z": 1,
      "name": "Deco_Bone_Full"
    },
    {
      "x": -4,
      "y": 10,
      "z": 1,
      "name": "Deco_Bone_Full"
    },
    {
      "x": -4,
      "y": 11,
      "z": 1,
      "name": "Deco_Bone_Full"
    },
    {
      "x": -4,
      "y": 12,
      "z": 1,
      "name": "Deco_Bone_Full"
    },
    {
      "x": -4,
      "y": 13,
      "z": 1,
      "name": "Deco_Bone_Full"
    },
    {
      "x": -4,
      "y": 14,
      "z": 1,
      "name": "Deco_Bone_Full"
    },
    {
      "x": -4,
      "y": 15,
      "z": 1,
      "name": "Deco_Bone_Full"
    },
    {
      "x": -4,
      "y": 16,
      "z": 1,
      "name": "Deco_Bone_Full"
    },
    {
      "x": -4,
      "y": 17,
      "z": 1,
      "name": "Deco_Bone_Full"
    },
    {
      "x": -4,
      "y": 18,
      "z": 1,
      "name": "Deco_Bone_Full"
    },
    {
      "x": -4,
      "y": 19,
      "z": 1,
      "name": "Deco_Bone_Full"
    },
    {
      "x": -4,
      "y": 20,
      "z": 1,
      "name": "Deco_Bone_Full"
    },
    {
      "x": -4,
      "y": 5,
      "z": 2,
      "name": "Soil_Gravel_Sand"
    },
    {
      "x": -4,
      "y": 6,
      "z": 2,
      "name": "Soil_Gravel_Sand"
    },
    {
      "x": -4,
      "y": 7,
      "z": 2,
      "name": "Soil_Gravel_Sand"
    },
    {
      "x": -4,
      "y": 8,
      "z": 2,
      "name": "Deco_Bone_Full"
    },
    {
      "x": -4,
      "y": 9,
      "z": 2,
      "name": "Deco_Bone_Full"
    },
    {
      "x": -4,
      "y": 10,
      "z": 2,
      "name": "Deco_Bone_Full"
    },
    {
      "x": -4,
      "y": 11,
      "z": 2,
      "name": "Deco_Bone_Full"
    },
    {
      "x": -4,
      "y": 12,
      "z": 2,
      "name": "Deco_Bone_Full"
    },
    {
      "x": -4,
      "y": 13,
      "z": 2,
      "name": "Deco_Bone_Full"
    },
    {
      "x": -4,
      "y": 14,
      "z": 2,
      "name": "Deco_Bone_Full"
    },
    {
      "x": -4,
      "y": 15,
      "z": 2,
      "name": "Deco_Bone_Full"
    },
    {
      "x": -4,
      "y": 16,
      "z": 2,
      "name": "Deco_Bone_Full"
    },
    {
      "x": -4,
      "y": 17,
      "z": 2,
      "name": "Deco_Bone_Full"
    },
    {
      "x": -4,
      "y": 5,
      "z": 3,
      "name": "Soil_Gravel_Sand"
    },
    {
      "x": -4,
      "y": 6,
      "z": 3,
      "name": "Soil_Gravel_Sand"
    },
    {
      "x": -4,
      "y": 7,
      "z": 3,
      "name": "Soil_Gravel_Sand"
    },
    {
      "x": -4,
      "y": 8,
      "z": 3,
      "name": "Soil_Gravel_Sand"
    },
    {
      "x": -4,
      "y": 9,
      "z": 3,
      "name": "Deco_Bone_Full"
    },
    {
      "x": -4,
      "y": 10,
      "z": 3,
      "name": "Deco_Bone_Full"
    },
    {
      "x": -4,
      "y": 11,
      "z": 3,
      "name": "Deco_Bone_Full"
    },
    {
      "x": -4,
      "y": 12,
      "z": 3,
      "name": "Deco_Bone_Full"
    },
    {
      "x": -4,
      "y": 13,
      "z": 3,
      "name": "Deco_Bone_Full"
    },
    {
      "x": -4,
      "y": 14,
      "z": 3,
      "name": "Deco_Bone_Full"
    },
    {
      "x": -4,
      "y": 6,
      "z": 4,
      "name": "Soil_Gravel_Sand"
    },
    {
      "x": -4,
      "y": 7,
      "z": 4,
      "name": "Rock_Sandstone_Cobble"
    },
    {
      "x": -3,
      "y": 5,
      "z": 0,
      "name": "Soil_Gravel_Sand"
    },
    {
      "x": -3,
      "y": 6,
      "z": 0,
      "name": "Soil_Gravel_Sand"
    },
    {
      "x": -3,
      "y": 7,
      "z": 0,
      "name": "Soil_Gravel_Sand"
    },
    {
      "x": -3,
      "y": 8,
      "z": 0,
      "name": "Deco_Bone_Full"
    },
    {
      "x": -3,
      "y": 9,
      "z": 0,
      "name": "Deco_Bone_Full"
    },
    {
      "x": -3,
      "y": 10,
      "z": 0,
      "name": "Deco_Bone_Full"
    },
    {
      "x": -3,
      "y": 5,
      "z": 1,
      "name": "Soil_Gravel_Sand"
    },
    {
      "x": -3,
      "y": 6,
      "z": 1,
      "name": "Soil_Gravel_Sand"
    },
    {
      "x": -3,
      "y": 7,
      "z": 1,
      "name": "Soil_Gravel_Sand"
    },
    {
      "x": -3,
      "y": 8,
      "z": 1,
      "name": "Deco_Bone_Full"
    },
    {
      "x": -3,
      "y": 9,
      "z": 1,
      "name": "Deco_Bone_Full"
    },
    {
      "x": -3,
      "y": 10,
      "z": 1,
      "name": "Deco_Bone_Full"
    },
    {
      "x": -3,
      "y": 11,
      "z": 1,
      "name": "Deco_Bone_Full"
    },
    {
      "x": -3,
      "y": 12,
      "z": 1,
      "name": "Deco_Bone_Full"
    },
    {
      "x": -3,
      "y": 13,
      "z": 1,
      "name": "Deco_Bone_Full"
    },
    {
      "x": -3,
      "y": 5,
      "z": 2,
      "name": "Soil_Gravel_Sand"
    },
    {
      "x": -3,
      "y": 6,
      "z": 2,
      "name": "Soil_Gravel_Sand"
    },
    {
      "x": -3,
      "y": 7,
      "z": 2,
      "name": "Soil_Gravel_Sand"
    },
    {
      "x": -3,
      "y": 8,
      "z": 2,
      "name": "Deco_Bone_Full"
    },
    {
      "x": -3,
      "y": 9,
      "z": 2,
      "name": "Deco_Bone_Full"
    },
    {
      "x": -3,
      "y": 10,
      "z": 2,
      "name": "Deco_Bone_Full"
    },
    {
      "x": -3,
      "y": 11,
      "z": 2,
      "name": "Deco_Bone_Full"
    },
    {
      "x": -3,
      "y": 12,
      "z": 2,
      "name": "Deco_Bone_Full"
    },
    {
      "x": -3,
      "y": 13,
      "z": 2,
      "name": "Deco_Bone_Full"
    },
    {
      "x": -3,
      "y": 14,
      "z": 2,
      "name": "Deco_Bone_Full"
    },
    {
      "x": -3,
      "y": 15,
      "z": 2,
      "name": "Deco_Bone_Full"
    },
    {
      "x": -3,
      "y": 5,
      "z": 3,
      "name": "Soil_Gravel_Sand"
    },
    {
      "x": -3,
      "y": 6,
      "z": 3,
      "name": "Soil_Gravel_Sand"
    },
    {
      "x": -3,
      "y": 7,
      "z": 3,
      "name": "Soil_Gravel_Sand"
    },
    {
      "x": -3,
      "y": 8,
      "z": 3,
      "name": "Deco_Bone_Full"
    },
    {
      "x": -3,
      "y": 9,
      "z": 3,
      "name": "Deco_Bone_Full"
    },
    {
      "x": -3,
      "y": 10,
      "z": 3,
      "name": "Deco_Bone_Full"
    },
    {
      "x": -3,
      "y": 11,
      "z": 3,
      "name": "Deco_Bone_Full"
    },
    {
      "x": -3,
      "y": 12,
      "z": 3,
      "name": "Deco_Bone_Full"
    },
    {
      "x": -3,
      "y": 5,
      "z": 4,
      "name": "Soil_Gravel_Sand"
    },
    {
      "x": -3,
      "y": 6,
      "z": 4,
      "name": "Soil_Gravel_Sand"
    },
    {
      "x": -3,
      "y": 7,
      "z": 4,
      "name": "Soil_Gravel_Sand"
    },
    {
      "x": -2,
      "y": 5,
      "z": -1,
      "name": "Soil_Gravel_Sand"
    },
    {
      "x": -2,
      "y": 6,
      "z": -1,
      "name": "Soil_Gravel_Sand"
    },
    {
      "x": -2,
      "y": 4,
      "z": 0,
      "name": "Soil_Gravel_Sand"
    },
    {
      "x": -2,
      "y": 5,
      "z": 0,
      "name": "Soil_Gravel_Sand"
    },
    {
      "x": -2,
      "y": 6,
      "z": 0,
      "name": "Soil_Gravel_Sand"
    },
    {
      "x": -2,
      "y": 7,
      "z": 0,
      "name": "Soil_Gravel_Sand"
    },
    {
      "x": -2,
      "y": 8,
      "z": 0,
      "name": "Soil_Gravel_Sand"
    },
    {
      "x": -2,
      "y": 4,
      "z": 1,
      "name": "Soil_Gravel_Sand"
    },
    {
      "x": -2,
      "y": 5,
      "z": 1,
      "name": "Soil_Gravel_Sand"
    },
    {
      "x": -2,
      "y": 6,
      "z": 1,
      "name": "Soil_Gravel_Sand"
    },
    {
      "x": -2,
      "y": 7,
      "z": 1,
      "name": "Soil_Gravel_Sand"
    },
    {
      "x": -2,
      "y": 8,
      "z": 1,
      "name": "Deco_Bone_Full"
    },
    {
      "x": -2,
      "y": 9,
      "z": 1,
      "name": "Deco_Bone_Full"
    },
    {
      "x": -2,
      "y": 4,
      "z": 2,
      "name": "Soil_Gravel_Sand"
    },
    {
      "x": -2,
      "y": 5,
      "z": 2,
      "name": "Soil_Gravel_Sand"
    },
    {
      "x": -2,
      "y": 6,
      "z": 2,
      "name": "Soil_Gravel_Sand"
    },
    {
      "x": -2,
      "y": 7,
      "z": 2,
      "name": "Soil_Gravel_Sand"
    },
    {
      "x": -2,
      "y": 8,
      "z": 2,
      "name": "Soil_Gravel_Sand"
    },
    {
      "x": -2,
      "y": 9,
      "z": 2,
      "name": "Deco_Bone_Full"
    },
    {
      "x": -2,
      "y": 10,
      "z": 2,
      "name": "Deco_Bone_Full"
    },
    {
      "x": -2,
      "y": 11,
      "z": 2,
      "name": "Deco_Bone_Full"
    },
    {
      "x": -2,
      "y": 4,
      "z": 3,
      "name": "Soil_Gravel_Sand"
    },
    {
      "x": -2,
      "y": 5,
      "z": 3,
      "name": "Soil_Gravel_Sand"
    },
    {
      "x": -2,
      "y": 6,
      "z": 3,
      "name": "Soil_Gravel_Sand"
    },
    {
      "x": -2,
      "y": 7,
      "z": 3,
      "name": "Soil_Gravel_Sand"
    },
    {
      "x": -2,
      "y": 8,
      "z": 3,
      "name": "Soil_Gravel_Sand"
    },
    {
      "x": -2,
      "y": 5,
      "z": 4,
      "name": "Soil_Gravel_Sand"
    },
    {
      "x": -2,
      "y": 6,
      "z": 4,
      "name": "Wood_Dry_Trunk",
      "support": 15
    },
    {
      "x": -2,
      "y": 7,
      "z": 4,
      "name": "Wood_Dry_Trunk",
      "support": 15
    },
    {
      "x": -2,
      "y": 8,
      "z": 4,
      "name": "Wood_Dry_Trunk",
      "support": 15
    },
    {
      "x": -2,
      "y": 9,
      "z": 4,
      "name": "Wood_Dry_Trunk",
      "support": 15
    },
    {
      "x": -2,
      "y": 10,
      "z": 4,
      "name": "Wood_Dry_Trunk",
      "support": 15
    },
    {
      "x": -2,
      "y": 11,
      "z": 4,
      "name": "Wood_Dry_Branch_Long",
      "support": 15
    },
    {
      "x": -1,
      "y": 5,
      "z": -1,
      "name": "Soil_Gravel_Sand"
    },
    {
      "x": -1,
      "y": 6,
      "z": -1,
      "name": "Soil_Gravel_Sand"
    },
    {
      "x": -1,
      "y": 4,
      "z": 0,
      "name": "Soil_Gravel_Sand"
    },
    {
      "x": -1,
      "y": 5,
      "z": 0,
      "name": "Soil_Gravel_Sand"
    },
    {
      "x": -1,
      "y": 6,
      "z": 0,
      "name": "Soil_Gravel_Sand"
    },
    {
      "x": -1,
      "y": 7,
      "z": 0,
      "name": "Soil_Gravel_Sand"
    },
    {
      "x": -1,
      "y": 8,
      "z": 0,
      "name": "Soil_Gravel_Sand"
    },
    {
      "x": -1,
      "y": 4,
      "z": 1,
      "name": "Soil_Gravel_Sand"
    },
    {
      "x": -1,
      "y": 5,
      "z": 1,
      "name": "Soil_Gravel_Sand"
    },
    {
      "x": -1,
      "y": 6,
      "z": 1,
      "name": "Soil_Gravel_Sand"
    },
    {
      "x": -1,
      "y": 7,
      "z": 1,
      "name": "Soil_Gravel_Sand"
    },
    {
      "x": -1,
      "y": 8,
      "z": 1,
      "name": "Soil_Gravel_Sand"
    },
    {
      "x": -1,
      "y": 4,
      "z": 2,
      "name": "Soil_Gravel_Sand"
    },
    {
      "x": -1,
      "y": 5,
      "z": 2,
      "name": "Soil_Gravel_Sand"
    },
    {
      "x": -1,
      "y": 6,
      "z": 2,
      "name": "Soil_Gravel_Sand"
    },
    {
      "x": -1,
      "y": 7,
      "z": 2,
      "name": "Soil_Gravel_Sand"
    },
    {
      "x": -1,
      "y": 8,
      "z": 2,
      "name": "Soil_Gravel_Sand"
    },
    {
      "x": -1,
      "y": 4,
      "z": 3,
      "name": "Soil_Gravel_Sand"
    },
    {
      "x": -1,
      "y": 5,
      "z": 3,
      "name": "Soil_Gravel_Sand"
    },
    {
      "x": -1,
      "y": 6,
      "z": 3,
      "name": "Soil_Gravel_Sand"
    },
    {
      "x": -1,
      "y": 7,
      "z": 3,
      "name": "Soil_Gravel_Sand"
    },
    {
      "x": -1,
      "y": 8,
      "z": 3,
      "name": "Soil_Gravel_Sand"
    },
    {
      "x": -1,
      "y": 5,
      "z": 4,
      "name": "Soil_Gravel_Sand"
    },
    {
      "x": -1,
      "y": 6,
      "z": 4,
      "name": "Soil_Gravel_Sand"
    },
    {
      "x": -1,
      "y": 7,
      "z": 4,
      "name": "Soil_Gravel_Sand"
    },
    {
      "x": 0,
      "y": 4,
      "z": -1,
      "name": "Soil_Gravel_Sand"
    },
    {
      "x": 0,
      "y": 5,
      "z": -1,
      "name": "Soil_Gravel_Sand"
    },
    {
      "x": 0,
      "y": 6,
      "z": -1,
      "name": "Soil_Gravel_Sand"
    },
    {
      "x": 0,
      "y": 4,
      "z": 0,
      "name": "Soil_Gravel_Sand"
    },
    {
      "x": 0,
      "y": 5,
      "z": 0,
      "name": "Soil_Gravel_Sand"
    },
    {
      "x": 0,
      "y": 6,
      "z": 0,
      "name": "Soil_Gravel_Sand"
    },
    {
      "x": 0,
      "y": 7,
      "z": 0,
      "name": "Soil_Gravel_Sand"
    },
    {
      "x": 0,
      "y": 4,
      "z": 1,
      "name": "Soil_Gravel_Sand"
    },
    {
      "x": 0,
      "y": 5,
      "z": 1,
      "name": "Soil_Gravel_Sand"
    },
    {
      "x": 0,
      "y": 6,
      "z": 1,
      "name": "Soil_Gravel_Sand"
    },
    {
      "x": 0,
      "y": 7,
      "z": 1,
      "name": "Soil_Gravel_Sand"
    },
    {
      "x": 0,
      "y": 8,
      "z": 1,
      "name": "Soil_Gravel_Sand"
    },
    {
      "x": 0,
      "y": 4,
      "z": 2,
      "name": "Soil_Gravel_Sand"
    },
    {
      "x": 0,
      "y": 5,
      "z": 2,
      "name": "Soil_Gravel_Sand"
    },
    {
      "x": 0,
      "y": 6,
      "z": 2,
      "name": "Soil_Gravel_Sand"
    },
    {
      "x": 0,
      "y": 7,
      "z": 2,
      "name": "Soil_Gravel_Sand"
    },
    {
      "x": 0,
      "y": 8,
      "z": 2,
      "name": "Soil_Gravel_Sand"
    },
    {
      "x": 0,
      "y": 4,
      "z": 3,
      "name": "Soil_Gravel_Sand"
    },
    {
      "x": 0,
      "y": 5,
      "z": 3,
      "name": "Soil_Gravel_Sand"
    },
    {
      "x": 0,
      "y": 6,
      "z": 3,
      "name": "Soil_Gravel_Sand"
    },
    {
      "x": 0,
      "y": 7,
      "z": 3,
      "name": "Soil_Gravel_Sand"
    },
    {
      "x": 0,
      "y": 8,
      "z": 3,
      "name": "Soil_Gravel_Sand"
    },
    {
      "x": 0,
      "y": 4,
      "z": 4,
      "name": "Soil_Gravel_Sand"
    },
    {
      "x": 0,
      "y": 5,
      "z": 4,
      "name": "Soil_Gravel_Sand"
    },
    {
      "x": 0,
      "y": 6,
      "z": 4,
      "name": "Soil_Gravel_Sand"
    },
    {
      "x": 0,
      "y": 7,
      "z": 4,
      "name": "Soil_Gravel_Sand"
    },
    {
      "x": 1,
      "y": 4,
      "z": -1,
      "name": "Soil_Gravel_Sand"
    },
    {
      "x": 1,
      "y": 5,
      "z": -1,
      "name": "Soil_Gravel_Sand"
    },
    {
      "x": 1,
      "y": 6,
      "z": -1,
      "name": "Soil_Gravel_Sand"
    },
    {
      "x": 1,
      "y": 4,
      "z": 0,
      "name": "Soil_Gravel_Sand"
    },
    {
      "x": 1,
      "y": 5,
      "z": 0,
      "name": "Soil_Gravel_Sand"
    },
    {
      "x": 1,
      "y": 6,
      "z": 0,
      "name": "Soil_Gravel_Sand"
    },
    {
      "x": 1,
      "y": 7,
      "z": 0,
      "name": "Soil_Gravel_Sand"
    },
    {
      "x": 1,
      "y": 4,
      "z": 1,
      "name": "Soil_Gravel_Sand"
    },
    {
      "x": 1,
      "y": 5,
      "z": 1,
      "name": "Soil_Gravel_Sand"
    },
    {
      "x": 1,
      "y": 6,
      "z": 1,
      "name": "Soil_Gravel_Sand"
    },
    {
      "x": 1,
      "y": 7,
      "z": 1,
      "name": "Soil_Gravel_Sand"
    },
    {
      "x": 1,
      "y": 8,
      "z": 1,
      "name": "Soil_Gravel_Sand"
    },
    {
      "x": 1,
      "y": 4,
      "z": 2,
      "name": "Soil_Gravel_Sand"
    },
    {
      "x": 1,
      "y": 5,
      "z": 2,
      "name": "Soil_Gravel_Sand"
    },
    {
      "x": 1,
      "y": 6,
      "z": 2,
      "name": "Soil_Gravel_Sand"
    },
    {
      "x": 1,
      "y": 7,
      "z": 2,
      "name": "Soil_Gravel_Sand"
    },
    {
      "x": 1,
      "y": 8,
      "z": 2,
      "name": "Soil_Gravel_Sand"
    },
    {
      "x": 1,
      "y": 4,
      "z": 3,
      "name": "Soil_Gravel_Sand"
    },
    {
      "x": 1,
      "y": 5,
      "z": 3,
      "name": "Soil_Gravel_Sand"
    },
    {
      "x": 1,
      "y": 6,
      "z": 3,
      "name": "Soil_Gravel_Sand"
    },
    {
      "x": 1,
      "y": 7,
      "z": 3,
      "name": "Soil_Gravel_Sand"
    },
    {
      "x": 1,
      "y": 4,
      "z": 4,
      "name": "Soil_Gravel_Sand"
    },
    {
      "x": 1,
      "y": 5,
      "z": 4,
      "name": "Soil_Gravel_Sand"
    },
    {
      "x": 1,
      "y": 6,
      "z": 4,
      "name": "Soil_Gravel_Sand"
    },
    {
      "x": 1,
      "y": 7,
      "z": 4,
      "name": "Soil_Gravel_Sand"
    },
    {
      "x": 2,
      "y": 4,
      "z": -1,
      "name": "Soil_Gravel_Sand"
    },
    {
      "x": 2,
      "y": 5,
      "z": -1,
      "name": "Soil_Gravel_Sand"
    },
    {
      "x": 2,
      "y": 6,
      "z": -1,
      "name": "Soil_Gravel_Sand"
    },
    {
      "x": 2,
      "y": 7,
      "z": -1,
      "name": "Soil_Gravel_Sand"
    },
    {
      "x": 2,
      "y": 4,
      "z": 0,
      "name": "Soil_Gravel_Sand"
    },
    {
      "x": 2,
      "y": 5,
      "z": 0,
      "name": "Soil_Gravel_Sand"
    },
    {
      "x": 2,
      "y": 6,
      "z": 0,
      "name": "Soil_Gravel_Sand"
    },
    {
      "x": 2,
      "y": 7,
      "z": 0,
      "name": "Soil_Gravel_Sand"
    },
    {
      "x": 2,
      "y": 4,
      "z": 1,
      "name": "Soil_Gravel_Sand"
    },
    {
      "x": 2,
      "y": 5,
      "z": 1,
      "name": "Soil_Gravel_Sand"
    },
    {
      "x": 2,
      "y": 6,
      "z": 1,
      "name": "Soil_Gravel_Sand"
    },
    {
      "x": 2,
      "y": 7,
      "z": 1,
      "name": "Soil_Gravel_Sand"
    },
    {
      "x": 2,
      "y": 8,
      "z": 1,
      "name": "Soil_Gravel_Sand"
    },
    {
      "x": 2,
      "y": 4,
      "z": 2,
      "name": "Soil_Gravel_Sand"
    },
    {
      "x": 2,
      "y": 5,
      "z": 2,
      "name": "Soil_Gravel_Sand"
    },
    {
      "x": 2,
      "y": 6,
      "z": 2,
      "name": "Soil_Gravel_Sand"
    },
    {
      "x": 2,
      "y": 7,
      "z": 2,
      "name": "Soil_Gravel_Sand"
    },
    {
      "x": 2,
      "y": 8,
      "z": 2,
      "name": "Soil_Gravel_Sand"
    },
    {
      "x": 2,
      "y": 4,
      "z": 3,
      "name": "Soil_Gravel_Sand"
    },
    {
      "x": 2,
      "y": 5,
      "z": 3,
      "name": "Soil_Gravel_Sand"
    },
    {
      "x": 2,
      "y": 6,
      "z": 3,
      "name": "Soil_Gravel_Sand"
    },
    {
      "x": 2,
      "y": 7,
      "z": 3,
      "name": "Soil_Gravel_Sand"
    },
    {
      "x": 2,
      "y": 4,
      "z": 4,
      "name": "Soil_Gravel_Sand"
    },
    {
      "x": 2,
      "y": 5,
      "z": 4,
      "name": "Soil_Gravel_Sand"
    },
    {
      "x": 2,
      "y": 6,
      "z": 4,
      "name": "Soil_Gravel_Sand"
    },
    {
      "x": 3,
      "y": 4,
      "z": -1,
      "name": "Soil_Gravel_Sand"
    },
    {
      "x": 3,
      "y": 5,
      "z": -1,
      "name": "Soil_Gravel_Sand"
    },
    {
      "x": 3,
      "y": 6,
      "z": -1,
      "name": "Soil_Gravel_Sand"
    },
    {
      "x": 3,
      "y": 7,
      "z": -1,
      "name": "Soil_Gravel_Sand"
    },
    {
      "x": 3,
      "y": 4,
      "z": 0,
      "name": "Soil_Gravel_Sand"
    },
    {
      "x": 3,
      "y": 5,
      "z": 0,
      "name": "Soil_Gravel_Sand"
    },
    {
      "x": 3,
      "y": 6,
      "z": 0,
      "name": "Soil_Gravel_Sand"
    },
    {
      "x": 3,
      "y": 7,
      "z": 0,
      "name": "Soil_Gravel_Sand"
    },
    {
      "x": 3,
      "y": 4,
      "z": 1,
      "name": "Soil_Gravel_Sand"
    },
    {
      "x": 3,
      "y": 5,
      "z": 1,
      "name": "Soil_Gravel_Sand"
    },
    {
      "x": 3,
      "y": 6,
      "z": 1,
      "name": "Soil_Gravel_Sand"
    },
    {
      "x": 3,
      "y": 7,
      "z": 1,
      "name": "Soil_Gravel_Sand"
    },
    {
      "x": 3,
      "y": 8,
      "z": 1,
      "name": "Soil_Gravel_Sand"
    },
    {
      "x": 3,
      "y": 4,
      "z": 2,
      "name": "Soil_Gravel_Sand"
    },
    {
      "x": 3,
      "y": 5,
      "z": 2,
      "name": "Soil_Gravel_Sand"
    },
    {
      "x": 3,
      "y": 6,
      "z": 2,
      "name": "Soil_Gravel_Sand"
    },
    {
      "x": 3,
      "y": 7,
      "z": 2,
      "name": "Soil_Gravel_Sand"
    },
    {
      "x": 3,
      "y": 8,
      "z": 2,
      "name": "Soil_Gravel_Sand"
    },
    {
      "x": 3,
      "y": 4,
      "z": 3,
      "name": "Soil_Gravel_Sand"
    },
    {
      "x": 3,
      "y": 5,
      "z": 3,
      "name": "Soil_Gravel_Sand"
    },
    {
      "x": 3,
      "y": 6,
      "z": 3,
      "name": "Soil_Gravel_Sand"
    },
    {
      "x": 3,
      "y": 7,
      "z": 3,
      "name": "Soil_Gravel_Sand"
    },
    {
      "x": 3,
      "y": 4,
      "z": 4,
      "name": "Soil_Gravel_Sand"
    },
    {
      "x": 3,
      "y": 5,
      "z": 4,
      "name": "Soil_Gravel_Sand"
    },
    {
      "x": 3,
      "y": 6,
      "z": 4,
      "name": "Soil_Gravel_Sand"
    },
    {
      "x": 4,
      "y": 4,
      "z": -1,
      "name": "Soil_Gravel_Sand"
    },
    {
      "x": 4,
      "y": 5,
      "z": -1,
      "name": "Soil_Gravel_Sand"
    },
    {
      "x": 4,
      "y": 6,
      "z": -1,
      "name": "Soil_Gravel_Sand"
    },
    {
      "x": 4,
      "y": 7,
      "z": -1,
      "name": "Soil_Gravel_Sand"
    },
    {
      "x": 4,
      "y": 4,
      "z": 0,
      "name": "Soil_Gravel_Sand"
    },
    {
      "x": 4,
      "y": 5,
      "z": 0,
      "name": "Soil_Gravel_Sand"
    },
    {
      "x": 4,
      "y": 6,
      "z": 0,
      "name": "Soil_Gravel_Sand"
    },
    {
      "x": 4,
      "y": 7,
      "z": 0,
      "name": "Soil_Gravel_Sand"
    },
    {
      "x": 4,
      "y": 8,
      "z": 0,
      "name": "Deco_Bone_Full"
    },
    {
      "x": 4,
      "y": 9,
      "z": 0,
      "name": "Deco_Bone_Full"
    },
    {
      "x": 4,
      "y": 10,
      "z": 0,
      "name": "Deco_Bone_Full"
    },
    {
      "x": 4,
      "y": 4,
      "z": 1,
      "name": "Soil_Gravel_Sand"
    },
    {
      "x": 4,
      "y": 5,
      "z": 1,
      "name": "Soil_Gravel_Sand"
    },
    {
      "x": 4,
      "y": 6,
      "z": 1,
      "name": "Soil_Gravel_Sand"
    },
    {
      "x": 4,
      "y": 7,
      "z": 1,
      "name": "Soil_Gravel_Sand"
    },
    {
      "x": 4,
      "y": 8,
      "z": 1,
      "name": "Soil_Gravel_Sand"
    },
    {
      "x": 4,
      "y": 9,
      "z": 1,
      "name": "Deco_Bone_Full"
    },
    {
      "x": 4,
      "y": 10,
      "z": 1,
      "name": "Deco_Bone_Full"
    },
    {
      "x": 4,
      "y": 11,
      "z": 1,
      "name": "Deco_Bone_Full"
    },
    {
      "x": 4,
      "y": 4,
      "z": 2,
      "name": "Soil_Gravel_Sand"
    },
    {
      "x": 4,
      "y": 5,
      "z": 2,
      "name": "Soil_Gravel_Sand"
    },
    {
      "x": 4,
      "y": 6,
      "z": 2,
      "name": "Soil_Gravel_Sand"
    },
    {
      "x": 4,
      "y": 7,
      "z": 2,
      "name": "Soil_Gravel_Sand"
    },
    {
      "x": 4,
      "y": 8,
      "z": 2,
      "name": "Soil_Gravel_Sand"
    },
    {
      "x": 4,
      "y": 9,
      "z": 2,
      "name": "Soil_Gravel_Sand"
    },
    {
      "x": 4,
      "y": 4,
      "z": 3,
      "name": "Soil_Gravel_Sand"
    },
    {
      "x": 4,
      "y": 5,
      "z": 3,
      "name": "Soil_Gravel_Sand"
    },
    {
      "x": 4,
      "y": 6,
      "z": 3,
      "name": "Soil_Gravel_Sand"
    },
    {
      "x": 4,
      "y": 7,
      "z": 3,
      "name": "Soil_Gravel_Sand"
    },
    {
      "x": 4,
      "y": 8,
      "z": 3,
      "name": "Soil_Gravel_Sand"
    },
    {
      "x": 4,
      "y": 5,
      "z": 4,
      "name": "Soil_Gravel_Sand"
    },
    {
      "x": 4,
      "y": 6,
      "z": 4,
      "name": "Soil_Gravel_Sand"
    },
    {
      "x": 5,
      "y": 4,
      "z": -1,
      "name": "Soil_Gravel_Sand"
    },
    {
      "x": 5,
      "y": 5,
      "z": -1,
      "name": "Soil_Gravel_Sand"
    },
    {
      "x": 5,
      "y": 6,
      "z": -1,
      "name": "Soil_Gravel_Sand"
    },
    {
      "x": 5,
      "y": 7,
      "z": -1,
      "name": "Soil_Gravel_Sand"
    },
    {
      "x": 5,
      "y": 8,
      "z": -1,
      "name": "Deco_Bone_Full"
    },
    {
      "x": 5,
      "y": 9,
      "z": -1,
      "name": "Deco_Bone_Full"
    },
    {
      "x": 5,
      "y": 10,
      "z": -1,
      "name": "Deco_Bone_Full"
    },
    {
      "x": 5,
      "y": 4,
      "z": 0,
      "name": "Soil_Gravel_Sand"
    },
    {
      "x": 5,
      "y": 5,
      "z": 0,
      "name": "Soil_Gravel_Sand"
    },
    {
      "x": 5,
      "y": 6,
      "z": 0,
      "name": "Soil_Gravel_Sand"
    },
    {
      "x": 5,
      "y": 7,
      "z": 0,
      "name": "Soil_Gravel_Sand"
    },
    {
      "x": 5,
      "y": 8,
      "z": 0,
      "name": "Deco_Bone_Full"
    },
    {
      "x": 5,
      "y": 9,
      "z": 0,
      "name": "Deco_Bone_Full"
    },
    {
      "x": 5,
      "y": 10,
      "z": 0,
      "name": "Deco_Bone_Full"
    },
    {
      "x": 5,
      "y": 11,
      "z": 0,
      "name": "Deco_Bone_Full"
    },
    {
      "x": 5,
      "y": 12,
      "z": 0,
      "name": "Deco_Bone_Full"
    },
    {
      "x": 5,
      "y": 13,
      "z": 0,
      "name": "Deco_Bone_Full"
    },
    {
      "x": 5,
      "y": 4,
      "z": 1,
      "name": "Soil_Gravel_Sand"
    },
    {
      "x": 5,
      "y": 5,
      "z": 1,
      "name": "Soil_Gravel_Sand"
    },
    {
      "x": 5,
      "y": 6,
      "z": 1,
      "name": "Soil_Gravel_Sand"
    },
    {
      "x": 5,
      "y": 7,
      "z": 1,
      "name": "Soil_Gravel_Sand"
    },
    {
      "x": 5,
      "y": 8,
      "z": 1,
      "name": "Deco_Bone_Full"
    },
    {
      "x": 5,
      "y": 9,
      "z": 1,
      "name": "Deco_Bone_Full"
    },
    {
      "x": 5,
      "y": 10,
      "z": 1,
      "name": "Deco_Bone_Full"
    },
    {
      "x": 5,
      "y": 11,
      "z": 1,
      "name": "Deco_Bone_Full"
    },
    {
      "x": 5,
      "y": 12,
      "z": 1,
      "name": "Deco_Bone_Full"
    },
    {
      "x": 5,
      "y": 13,
      "z": 1,
      "name": "Deco_Bone_Full"
    },
    {
      "x": 5,
      "y": 4,
      "z": 2,
      "name": "Soil_Gravel_Sand"
    },
    {
      "x": 5,
      "y": 5,
      "z": 2,
      "name": "Soil_Gravel_Sand"
    },
    {
      "x": 5,
      "y": 6,
      "z": 2,
      "name": "Soil_Gravel_Sand"
    },
    {
      "x": 5,
      "y": 7,
      "z": 2,
      "name": "Soil_Gravel_Sand"
    },
    {
      "x": 5,
      "y": 8,
      "z": 2,
      "name": "Deco_Bone_Full"
    },
    {
      "x": 5,
      "y": 9,
      "z": 2,
      "name": "Deco_Bone_Full"
    },
    {
      "x": 5,
      "y": 10,
      "z": 2,
      "name": "Deco_Bone_Full"
    },
    {
      "x": 5,
      "y": 11,
      "z": 2,
      "name": "Deco_Bone_Full"
    },
    {
      "x": 5,
      "y": 12,
      "z": 2,
      "name": "Deco_Bone_Full"
    },
    {
      "x": 5,
      "y": 4,
      "z": 3,
      "name": "Soil_Gravel_Sand"
    },
    {
      "x": 5,
      "y": 5,
      "z": 3,
      "name": "Soil_Gravel_Sand"
    },
    {
      "x": 5,
      "y": 6,
      "z": 3,
      "name": "Soil_Gravel_Sand"
    },
    {
      "x": 5,
      "y": 7,
      "z": 3,
      "name": "Soil_Gravel_Sand"
    },
    {
      "x": 5,
      "y": 8,
      "z": 3,
      "name": "Soil_Gravel_Sand"
    },
    {
      "x": 5,
      "y": 9,
      "z": 3,
      "name": "Rock_Sandstone_Cobble"
    },
    {
      "x": 5,
      "y": 5,
      "z": 4,
      "name": "Soil_Gravel_Sand"
    },
    {
      "x": 5,
      "y": 6,
      "z": 4,
      "name": "Soil_Gravel_Sand"
    },
    {
      "x": 6,
      "y": 6,
      "z": -1,
      "name": "Soil_Gravel_Sand"
    },
    {
      "x": 6,
      "y": 7,
      "z": -1,
      "name": "Soil_Gravel_Sand"
    },
    {
      "x": 6,
      "y": 8,
      "z": -1,
      "name": "Deco_Bone_Full"
    },
    {
      "x": 6,
      "y": 9,
      "z": -1,
      "name": "Deco_Bone_Full"
    },
    {
      "x": 6,
      "y": 10,
      "z": -1,
      "name": "Deco_Bone_Full"
    },
    {
      "x": 6,
      "y": 11,
      "z": -1,
      "name": "Deco_Bone_Full"
    },
    {
      "x": 6,
      "y": 4,
      "z": 0,
      "name": "Soil_Gravel_Sand"
    },
    {
      "x": 6,
      "y": 5,
      "z": 0,
      "name": "Soil_Gravel_Sand"
    },
    {
      "x": 6,
      "y": 6,
      "z": 0,
      "name": "Soil_Gravel_Sand"
    },
    {
      "x": 6,
      "y": 7,
      "z": 0,
      "name": "Soil_Gravel_Sand"
    },
    {
      "x": 6,
      "y": 8,
      "z": 0,
      "name": "Deco_Bone_Full"
    },
    {
      "x": 6,
      "y": 9,
      "z": 0,
      "name": "Deco_Bone_Full"
    },
    {
      "x": 6,
      "y": 10,
      "z": 0,
      "name": "Deco_Bone_Full"
    },
    {
      "x": 6,
      "y": 11,
      "z": 0,
      "name": "Deco_Bone_Full"
    },
    {
      "x": 6,
      "y": 12,
      "z": 0,
      "name": "Deco_Bone_Full"
    },
    {
      "x": 6,
      "y": 13,
      "z": 0,
      "name": "Deco_Bone_Full"
    },
    {
      "x": 6,
      "y": 14,
      "z": 0,
      "name": "Deco_Bone_Full"
    },
    {
      "x": 6,
      "y": 4,
      "z": 1,
      "name": "Soil_Gravel_Sand"
    },
    {
      "x": 6,
      "y": 5,
      "z": 1,
      "name": "Soil_Gravel_Sand"
    },
    {
      "x": 6,
      "y": 6,
      "z": 1,
      "name": "Soil_Gravel_Sand"
    },
    {
      "x": 6,
      "y": 7,
      "z": 1,
      "name": "Soil_Gravel_Sand"
    },
    {
      "x": 6,
      "y": 8,
      "z": 1,
      "name": "Deco_Bone_Full"
    },
    {
      "x": 6,
      "y": 9,
      "z": 1,
      "name": "Deco_Bone_Full"
    },
    {
      "x": 6,
      "y": 10,
      "z": 1,
      "name": "Deco_Bone_Full"
    },
    {
      "x": 6,
      "y": 11,
      "z": 1,
      "name": "Deco_Bone_Full"
    },
    {
      "x": 6,
      "y": 12,
      "z": 1,
      "name": "Deco_Bone_Full"
    },
    {
      "x": 6,
      "y": 13,
      "z": 1,
      "name": "Deco_Bone_Full"
    },
    {
      "x": 6,
      "y": 14,
      "z": 1,
      "name": "Deco_Bone_Full"
    },
    {
      "x": 6,
      "y": 5,
      "z": 2,
      "name": "Soil_Gravel_Sand"
    },
    {
      "x": 6,
      "y": 6,
      "z": 2,
      "name": "Soil_Gravel_Sand"
    },
    {
      "x": 6,
      "y": 7,
      "z": 2,
      "name": "Soil_Gravel_Sand"
    },
    {
      "x": 6,
      "y": 8,
      "z": 2,
      "name": "Soil_Gravel_Sand"
    },
    {
      "x": 6,
      "y": 9,
      "z": 2,
      "name": "Deco_Bone_Full"
    },
    {
      "x": 6,
      "y": 10,
      "z": 2,
      "name": "Deco_Bone_Full"
    },
    {
      "x": 6,
      "y": 11,
      "z": 2,
      "name": "Deco_Bone_Full"
    },
    {
      "x": 6,
      "y": 12,
      "z": 2,
      "name": "Deco_Bone_Full"
    },
    {
      "x": 6,
      "y": 13,
      "z": 2,
      "name": "Deco_Bone_Full"
    },
    {
      "x": 6,
      "y": 14,
      "z": 2,
      "name": "Deco_Bone_Full"
    },
    {
      "x": 6,
      "y": 5,
      "z": 3,
      "name": "Soil_Gravel_Sand"
    },
    {
      "x": 6,
      "y": 6,
      "z": 3,
      "name": "Soil_Gravel_Sand"
    },
    {
      "x": 6,
      "y": 7,
      "z": 3,
      "name": "Wood_Dry_Trunk",
      "support": 15
    },
    {
      "x": 6,
      "y": 8,
      "z": 3,
      "name": "Wood_Dry_Trunk",
      "support": 15
    },
    {
      "x": 6,
      "y": 9,
      "z": 3,
      "name": "Wood_Dry_Trunk",
      "support": 15
    },
    {
      "x": 6,
      "y": 10,
      "z": 3,
      "name": "Wood_Dry_Trunk",
      "support": 15
    },
    {
      "x": 6,
      "y": 11,
      "z": 3,
      "name": "Wood_Dry_Branch_Long",
      "support": 15
    },
    {
      "x": 7,
      "y": 9,
      "z": -1,
      "name": "Deco_Bone_Full"
    },
    {
      "x": 7,
      "y": 10,
      "z": -1,
      "name": "Deco_Bone_Full"
    },
    {
      "x": 7,
      "y": 5,
      "z": 0,
      "name": "Soil_Gravel_Sand"
    },
    {
      "x": 7,
      "y": 6,
      "z": 0,
      "name": "Soil_Gravel_Sand"
    },
    {
      "x": 7,
      "y": 7,
      "z": 0,
      "name": "Soil_Gravel_Sand"
    },
    {
      "x": 7,
      "y": 8,
      "z": 0,
      "name": "Deco_Bone_Full"
    },
    {
      "x": 7,
      "y": 9,
      "z": 0,
      "name": "Deco_Bone_Full"
    },
    {
      "x": 7,
      "y": 10,
      "z": 0,
      "name": "Deco_Bone_Full"
    },
    {
      "x": 7,
      "y": 11,
      "z": 0,
      "name": "Deco_Bone_Full"
    },
    {
      "x": 7,
      "y": 12,
      "z": 0,
      "name": "Deco_Bone_Full"
    },
    {
      "x": 7,
      "y": 5,
      "z": 1,
      "name": "Soil_Gravel_Sand"
    },
    {
      "x": 7,
      "y": 6,
      "z": 1,
      "name": "Soil_Gravel_Sand"
    },
    {
      "x": 7,
      "y": 7,
      "z": 1,
      "name": "Soil_Gravel_Sand"
    },
    {
      "x": 7,
      "y": 8,
      "z": 1,
      "name": "Soil_Gravel_Sand"
    },
    {
      "x": 7,
      "y": 10,
      "z": 1,
      "name": "Deco_Bone_Full"
    },
    {
      "x": 7,
      "y": 11,
      "z": 1,
      "name": "Deco_Bone_Full"
    },
    {
      "x": 7,
      "y": 12,
      "z": 1,
      "name": "Deco_Bone_Full"
    },
    {
      "x": 7,
      "y": 13,
      "z": 1,
      "name": "Deco_Bone_Full"
    },
    {
      "x": 7,
      "y": 14,
      "z": 1,
      "name": "Deco_Bone_Full"
    },
    {
      "x": 7,
      "y": 15,
      "z": 1,
      "name": "Deco_Bone_Full"
    },
    {
      "x": 7,
      "y": 5,
      "z": 2,
      "name": "Soil_Gravel_Sand"
    },
    {
      "x": 7,
      "y": 6,
      "z": 2,
      "name": "Soil_Gravel_Sand"
    },
    {
      "x": 7,
      "y": 7,
      "z": 2,
      "name": "Soil_Gravel_Sand"
    },
    {
      "x": 7,
      "y": 8,
      "z": 2,
      "name": "Rock_Sandstone_Cobble"
    },
    {
      "x": 7,
      "y": 6,
      "z": 3,
      "name": "Soil_Gravel_Sand"
    },
    {
      "x": 7,
      "y": 7,
      "z": 3,
      "name": "Soil_Gravel_Sand"
    },
    {
      "x": 8,
      "y": 6,
      "z": 0,
      "name": "Soil_Gravel_Sand"
    },
    {
      "x": 8,
      "y": 7,
      "z": 0,
      "name": "Soil_Gravel_Sand"
    },
    {
      "x": 8,
      "y": 5,
      "z": 1,
      "name": "Soil_Gravel_Sand"
    },
    {
      "x": 8,
      "y": 6,
      "z": 1,
      "name": "Soil_Gravel_Sand"
    },
    {
      "x": 8,
      "y": 7,
      "z": 1,
      "name": "Wood_Dry_Trunk",
      "support": 15
    },
    {
      "x": 8,
      "y": 8,
      "z": 1,
      "name": "Wood_Dry_Trunk",
      "support": 15
    },
    {
      "x": 8,
      "y": 5,
      "z": 2,
      "name": "Soil_Gravel_Sand"
    },
    {
      "x": 8,
      "y": 6,
      "z": 2,
      "name": "Soil_Gravel_Sand"
    }
  ]
}