{
  "version": 8,
  "blockIdVersion": 8,
  "anchorX": 3,
  "anchorY": 10,
  "anchorZ": 8,
  "blocks": [
    {
      "x": 1,
      "y": 13,
      "z": 7,
      "name": "Wood_Redwood_Branch_Long",
      "rotation": 5
    },
    {
      "x": 1,
      "y": 11,
      "z": 8,
      "name": "Wood_Redwood_Trunk",
      "rotation": 5
    },
    {
      "x": 1,
      "y": 11,
      "z": 9,
      "name": "Wood_Redwood_Branch_Long",
      "rotation": 4
    },
    {
      "x": 2,
      "y": 7,
      "z": 7,
      "name": "Wood_Redwood_Trunk"
    },
    {
      "x": 2,
      "y": 8,
      "z": 7,
      "name": "Wood_Redwood_Trunk"
    },
    {
      "x": 2,
      "y": 9,
      "z": 7,
      "name": "Wood_Redwood_Trunk"
    },
    {
      "x": 2,
      "y": 10,
      "z": 7,
      "name": "Wood_Redwood_Trunk"
    },
    {
      "x": 2,
      "y": 11,
      "z": 7,
      "name": "Wood_Redwood_Trunk"
    },
    {
      "x": 2,
      "y": 12,
      "z": 7,
      "name": "Wood_Redwood_Trunk"
    },
    {
      "x": 2,
      "y": 13,
      "z": 7,
      "name": "Wood_Redwood_Trunk"
    },
    {
      "x": 2,
      "y": 14,
      "z": 7,
      "name": "Wood_Redwood_Trunk"
    },
    {
      "x": 2,
      "y": 8,
      "z": 8,
      "name": "Wood_Redwood_Trunk"
    },
    {
      "x": 2,
      "y": 9,
      "z": 8,
      "name": "Wood_Redwood_Trunk"
    },
    {
      "x": 2,
      "y": 10,
      "z": 8,
      "name": "Wood_Redwood_Trunk"
    },
    {
      "x": 2,
      "y": 11,
      "z": 8,
      "name": "Wood_Redwood_Trunk"
    },
    {
      "x": 2,
      "y": 12,
      "z": 8,
      "name": "Wood_Redwood_Trunk"
    },
    {
      "x": 2,
      "y": 13,
      "z": 8,
      "name": "Wood_Redwood_Trunk"
    },
    {
      "x": 3,
      "y": 5,
      "z": 6,
      "name": "Wood_Redwood_Trunk"
    },
    {
      "x": 3,
      "y": 6,
      "z": 6,
      "name": "Wood_Redwood_Trunk"
    },
    {
      "x": 3,
      "y": 7,
      "z": 6,
      "name": "Wood_Redwood_Trunk"
    },
    {
      "x": 3,
      "y": 8,
      "z": 6,
      "name": "Wood_Redwood_Trunk"
    },
    {
      "x": 3,
      "y": 9,
      "z": 6,
      "name": "Wood_Redwood_Trunk"
    },
    {
      "x": 3,
      "y": 10,
      "z": 6,
      "name": "Wood_Redwood_Trunk"
    },
    {
      "x": 3,
      "y": 11,
      "z": 6,
      "name": "Wood_Redwood_Trunk"
    },
    {
      "x": 3,
      "y": 12,
      "z": 6,
      "name": "Wood_Redwood_Trunk"
    },
    {
      "x": 3,
      "y": 13,
      "z": 6,
      "name": "Wood_Redwood_Trunk"
    },
    {
      "x": 3,
      "y": 14,
      "z": 6,
      "name": "Wood_Redwood_Trunk"
    },
    {
      "x": 3,
      "y": 8,
      "z": 7,
      "name": "Soil_Pebbles"
    },
    {
      "x": 3,
      "y": 9,
      "z": 7,
      "name": "Empty"
    },
    {
      "x": 3,
      "y": 10,
      "z": 7,
      "name": "Empty"
    },
    {
      "x": 3,
      "y": 11,
      "z": 7,
      "name": "Empty"
    },
    {
      "x": 3,
      "y": 12,
      "z": 7,
      "name": "Empty"
    },
    {
      "x": 3,
      "y": 13,
      "z": 7,
      "name": "Empty"
    },
    {
      "x": 3,
      "y": 14,
      "z": 7,
      "name": "Empty"
    },
    {
      "x": 3,
      "y": 8,
      "z": 8,
      "name": "Soil_Pebbles"
    },
    {
      "x": 3,
      "y": 9,
      "z": 8,
      "name": "Soil_Pebbles"
    },
    {
      "x": 3,
      "y": 10,
      "z": 8,
      "name": "Wood_Redwood_Trunk"
    },
    {
      "x": 3,
      "y": 11,
      "z": 8,
      "name": "Empty"
    },
    {
      "x": 3,
      "y": 12,
      "z": 8,
      "name": "Empty"
    },
    {
      "x": 3,
      "y": 13,
      "z": 8,
      "name": "Empty"
    },
    {
      "x": 3,
      "y": 14,
      "z": 8,
      "name": "Empty"
    },
    {
      "x": 3,
      "y": 7,
      "z": 9,
      "name": "Wood_Redwood_Trunk"
    },
    {
      "x": 3,
      "y": 8,
      "z": 9,
      "name": "Wood_Redwood_Trunk"
    },
    {
      "x": 3,
      "y": 9,
      "z": 9,
      "name": "Wood_Redwood_Trunk"
    },
    {
      "x": 3,
      "y": 10,
      "z": 9,
      "name": "Wood_Redwood_Trunk"
    },
    {
      "x": 3,
      "y": 11,
      "z": 9,
      "name": "Wood_Redwood_Trunk"
    },
    {
      "x": 3,
      "y": 12,
      "z": 9,
      "name": "Wood_Redwood_Trunk"
    },
    {
      "x": 4,
      "y": 12,
      "z": 5,
      "name": "Wood_Redwood_Trunk",
      "rotation": 4
    },
    {
      "x": 4,
      "y": 6,
      "z": 6,
      "name": "Wood_Redwood_Trunk"
    },
    {
      "x": 4,
      "y": 7,
      "z": 6,
      "name": "Wood_Redwood_Trunk"
    },
    {
      "x": 4,
      "y": 8,
      "z": 6,
      "name": "Wood_Redwood_Trunk"
    },
    {
      "x": 4,
      "y": 9,
      "z": 6,
      "name": "Wood_Redwood_Trunk"
    },
    {
      "x": 4,
      "y": 10,
      "z": 6,
      "name": "Wood_Redwood_Trunk"
    },
    {
      "x": 4,
      "y": 11,
      "z": 6,
      "name": "Wood_Redwood_Trunk"
    },
    {
      "x": 4,
      "y": 12,
      "z": 6,
      "name": "Wood_Redwood_Trunk"
    },
    {
      "x": 4,
      "y": 13,
      "z": 6,
      "name": "Wood_Redwood_Trunk"
    },
    {
      "x": 4,
      "y": 14,
      "z": 6,
      "name": "Wood_Redwood_Trunk"
    },
    {
      "x": 4,
      "y": 15,
      "z": 6,
      "name": "Wood_Redwood_Trunk"
    },
    {
      "x": 4,
      "y": 8,
      "z": 7,
      "name": "Soil_Pebbles"
    },
    {
      "x": 4,
      "y": 9,
      "z": 7,
      "name": "Deco_Bone_Skulls"
    },
    {
      "x": 4,
      "y": 10,
      "z": 7,
      "name": "Empty"
    },
    {
      "x": 4,
      "y": 11,
      "z": 7,
      "name": "Empty"
    },
    {
      "x": 4,
      "y": 12,
      "z": 7,
      "name": "Empty"
    },
    {
      "x": 4,
      "y": 13,
      "z": 7,
      "name": "Empty"
    },
    {
      "x": 4,
      "y": 14,
      "z": 7,
      "name": "Empty"
    },
    {
      "x": 4,
      "y": 8,
      "z": 8,
      "name": "Soil_Pebbles"
    },
    {
      "x": 4,
      "y": 9,
      "z": 8,
      "name": "Soil_Pebbles"
    },
    {
      "x": 4,
      "y": 10,
      "z": 8,
      "name": "Empty"
    },
    {
      "x": 4,
      "y": 11,
      "z": 8,
      "name": "Empty"
    },
    {
      "x": 4,
      "y": 12,
      "z": 8,
      "name": "Empty"
    },
    {
      "x": 4,
      "y": 13,
      "z": 8,
      "name": "Empty"
    },
    {
      "x": 4,
      "y": 14,
      "z": 8,
      "name": "Empty"
    },
    {
      "x": 4,
      "y": 6,
      "z": 9,
      "name": "Wood_Redwood_Trunk"
    },
    {
      "x": 4,
      "y": 7,
      "z": 9,
      "name": "Wood_Redwood_Trunk"
    },
    {
      "x": 4,
      "y": 8,
      "z": 9,
      "name": "Wood_Redwood_Trunk"
    },
    {
      "x": 4,
      "y": 9,
      "z": 9,
      "name": "Wood_Redwood_Trunk"
    },
    {
      "x": 4,
      "y": 10,
      "z": 9,
      "name": "Wood_Redwood_Trunk"
    },
    {
      "x": 5,
      "y": 8,
      "z": 7,
      "name": "Wood_Redwood_Trunk"
    },
    {
      "x": 5,
      "y": 9,
      "z": 7,
      "name": "Wood_Redwood_Trunk"
    },
    {
      "x": 5,
      "y": 10,
      "z": 7,
      "name": "Wood_Redwood_Trunk"
    },
    {
      "x": 5,
      "y": 11,
      "z": 7,
      "name": "Wood_Redwood_Trunk"
    },
    {
      "x": 5,
      "y": 12,
      "z": 7,
      "name": "Wood_Redwood_Trunk"
    },
    {
      "x": 5,
      "y": 13,
      "z": 7,
      "name": "Wood_Redwood_Trunk"
    },
    {
      "x": 5,
      "y": 9,
      "z": 8,
      "name": "Wood_Redwood_Trunk"
    },
    {
      "x": 5,
      "y": 10,
      "z": 8,
      "name": "Wood_Redwood_Trunk"
    },
    {
      "x": 5,
      "y": 11,
      "z": 8,
      "name": "Wood_Redwood_Trunk"
    },
    {
      "x": 5,
      "y": 12,
      "z": 8,
      "name": "Wood_Redwood_Trunk"
    },
    {
      "x": 5,
      "y": 12,
      "z": 9,
      "name": "Wood_Redwood_Branch_Short"
    }
  ]
}