{
  "version": 8,
  "blockIdVersion": 8,
  "anchorX": 1,
  "anchorY": 10,
  "anchorZ": 0,
  "blocks": [
    {
      "x": -9,
      "y": 8,
      "z": -2,
      "name": "Plant_Coral_Block_Pink"
    },
    {
      "x": -9,
      "y": 7,
      "z": -1,
      "name": "Plant_Coral_Block_Pink"
    },
    {
      "x": -9,
      "y": 8,
      "z": -1,
      "name": "Plant_Coral_Block_Pink"
    },
    {
      "x": -9,
      "y": 9,
      "z": -1,
      "name": "Plant_Coral_Block_Pink"
    },
    {
      "x": -9,
      "y": 7,
      "z": 0,
      "name": "Plant_Coral_Block_Pink"
    },
    {
      "x": -9,
      "y": 8,
      "z": 0,
      "name": "Plant_Coral_Block_Pink"
    },
    {
      "x": -9,
      "y": 9,
      "z": 0,
      "name": "Plant_Coral_Block_Pink"
    },
    {
      "x": -9,
      "y": 7,
      "z": 1,
      "name": "Plant_Coral_Block_Pink"
    },
    {
      "x": -9,
      "y": 8,
      "z": 1,
      "name": "Plant_Coral_Block_Pink"
    },
    {
      "x": -9,
      "y": 9,
      "z": 1,
      "name": "Plant_Coral_Block_Pink"
    },
    {
      "x": -9,
      "y": 8,
      "z": 2,
      "name": "Plant_Coral_Block_Pink"
    },
    {
      "x": -8,
      "y": 7,
      "z": -4,
      "name": "Plant_Coral_Block_Pink"
    },
    {
      "x": -8,
      "y": 8,
      "z": -4,
      "name": "Plant_Coral_Block_Pink"
    },
    {
      "x": -8,
      "y": 9,
      "z": -4,
      "name": "Plant_Coral_Block_Violet"
    },
    {
      "x": -8,
      "y": 10,
      "z": -4,
      "name": "Plant_Coral_Block_Violet"
    },
    {
      "x": -8,
      "y": 7,
      "z": -3,
      "name": "Plant_Coral_Block_Pink"
    },
    {
      "x": -8,
      "y": 8,
      "z": -3,
      "name": "Plant_Coral_Block_Pink"
    },
    {
      "x": -8,
      "y": 9,
      "z": -3,
      "name": "Plant_Coral_Block_Violet"
    },
    {
      "x": -8,
      "y": 10,
      "z": -3,
      "name": "Plant_Coral_Block_Violet"
    },
    {
      "x": -8,
      "y": 6,
      "z": -2,
      "name": "Plant_Coral_Block_Pink"
    },
    {
      "x": -8,
      "y": 7,
      "z": -2,
      "name": "Plant_Coral_Block_Pink"
    },
    {
      "x": -8,
      "y": 8,
      "z": -2,
      "name": "Plant_Coral_Block_Pink"
    },
    {
      "x": -8,
      "y": 9,
      "z": -2,
      "name": "Plant_Coral_Block_Pink"
    },
    {
      "x": -8,
      "y": 10,
      "z": -2,
      "name": "Plant_Coral_Block_Violet"
    },
    {
      "x": -8,
      "y": 11,
      "z": -2,
      "name": "Plant_Coral_Block_Violet"
    },
    {
      "x": -8,
      "y": 6,
      "z": -1,
      "name": "Plant_Coral_Block_Pink"
    },
    {
      "x": -8,
      "y": 7,
      "z": -1,
      "name": "Plant_Coral_Block_Pink"
    },
    {
      "x": -8,
      "y": 8,
      "z": -1,
      "name": "Plant_Coral_Block_Pink"
    },
    {
      "x": -8,
      "y": 9,
      "z": -1,
      "name": "Plant_Coral_Block_Pink"
    },
    {
      "x": -8,
      "y": 10,
      "z": -1,
      "name": "Plant_Coral_Block_Violet"
    },
    {
      "x": -8,
      "y": 11,
      "z": -1,
      "name": "Plant_Coral_Block_Violet"
    },
    {
      "x": -8,
      "y": 6,
      "z": 0,
      "name": "Plant_Coral_Block_Pink"
    },
    {
      "x": -8,
      "y": 7,
      "z": 0,
      "name": "Plant_Coral_Block_Pink"
    },
    {
      "x": -8,
      "y": 8,
      "z": 0,
      "name": "Plant_Coral_Block_Pink"
    },
    {
      "x": -8,
      "y": 9,
      "z": 0,
      "name": "Plant_Coral_Block_Pink"
    },
    {
      "x": -8,
      "y": 10,
      "z": 0,
      "name": "Plant_Coral_Block_Pink"
    },
    {
      "x": -8,
      "y": 11,
      "z": 0,
      "name": "Plant_Coral_Bush_Pink"
    },
    {
      "x": -8,
      "y": 6,
      "z": 1,
      "name": "Plant_Coral_Block_Pink"
    },
    {
      "x": -8,
      "y": 7,
      "z": 1,
      "name": "Plant_Coral_Block_Pink"
    },
    {
      "x": -8,
      "y": 8,
      "z": 1,
      "name": "Plant_Coral_Block_Pink"
    },
    {
      "x": -8,
      "y": 9,
      "z": 1,
      "name": "Plant_Coral_Block_Pink"
    },
    {
      "x": -8,
      "y": 10,
      "z": 1,
      "name": "Plant_Coral_Block_Violet"
    },
    {
      "x": -8,
      "y": 11,
      "z": 1,
      "name": "Plant_Coral_Block_Violet"
    },
    {
      "x": -8,
      "y": 6,
      "z": 2,
      "name": "Plant_Coral_Block_Pink"
    },
    {
      "x": -8,
      "y": 7,
      "z": 2,
      "name": "Plant_Coral_Block_Pink"
    },
    {
      "x": -8,
      "y": 8,
      "z": 2,
      "name": "Plant_Coral_Block_Pink"
    },
    {
      "x": -8,
      "y": 9,
      "z": 2,
      "name": "Plant_Coral_Block_Pink"
    },
    {
      "x": -8,
      "y": 10,
      "z": 2,
      "name": "Plant_Coral_Block_Violet"
    },
    {
      "x": -8,
      "y": 11,
      "z": 2,
      "name": "Plant_Coral_Block_Violet"
    },
    {
      "x": -8,
      "y": 7,
      "z": 3,
      "name": "Plant_Coral_Block_Pink"
    },
    {
      "x": -8,
      "y": 8,
      "z": 3,
      "name": "Plant_Coral_Block_Pink"
    },
    {
      "x": -8,
      "y": 9,
      "z": 3,
      "name": "Plant_Coral_Block_Violet"
    },
    {
      "x": -8,
      "y": 10,
      "z": 3,
      "name": "Plant_Coral_Block_Violet"
    },
    {
      "x": -8,
      "y": 7,
      "z": 4,
      "name": "Plant_Coral_Block_Pink"
    },
    {
      "x": -8,
      "y": 8,
      "z": 4,
      "name": "Plant_Coral_Block_Pink"
    },
    {
      "x": -8,
      "y": 9,
      "z": 4,
      "name": "Plant_Coral_Block_Pink"
    },
    {
      "x": -7,
      "y": 8,
      "z": -6,
      "name": "Plant_Coral_Block_Pink"
    },
    {
      "x": -7,
      "y": 7,
      "z": -5,
      "name": "Plant_Coral_Block_Pink"
    },
    {
      "x": -7,
      "y": 8,
      "z": -5,
      "name": "Plant_Coral_Block_Pink"
    },
    {
      "x": -7,
      "y": 9,
      "z": -5,
      "name": "Plant_Coral_Block_Pink"
    },
    {
      "x": -7,
      "y": 6,
      "z": -4,
      "name": "Plant_Coral_Block_Pink"
    },
    {
      "x": -7,
      "y": 7,
      "z": -4,
      "name": "Plant_Coral_Block_Pink"
    },
    {
      "x": -7,
      "y": 8,
      "z": -4,
      "name": "Plant_Coral_Block_Pink"
    },
    {
      "x": -7,
      "y": 9,
      "z": -4,
      "name": "Plant_Coral_Block_Pink"
    },
    {
      "x": -7,
      "y": 10,
      "z": -4,
      "name": "Plant_Coral_Block_Violet"
    },
    {
      "x": -7,
      "y": 11,
      "z": -4,
      "name": "Plant_Coral_Block_Violet"
    },
    {
      "x": -7,
      "y": 6,
      "z": -3,
      "name": "Plant_Coral_Block_Pink"
    },
    {
      "x": -7,
      "y": 7,
      "z": -3,
      "name": "Plant_Coral_Block_Pink"
    },
    {
      "x": -7,
      "y": 8,
      "z": -3,
      "name": "Plant_Coral_Block_Pink"
    },
    {
      "x": -7,
      "y": 9,
      "z": -3,
      "name": "Plant_Coral_Block_Pink"
    },
    {
      "x": -7,
      "y": 10,
      "z": -3,
      "name": "Plant_Coral_Block_Pink"
    },
    {
      "x": -7,
      "y": 6,
      "z": -2,
      "name": "Plant_Coral_Block_Pink"
    },
    {
      "x": -7,
      "y": 7,
      "z": -2,
      "name": "Plant_Coral_Block_Pink"
    },
    {
      "x": -7,
      "y": 8,
      "z": -2,
      "name": "Plant_Coral_Block_Pink"
    },
    {
      "x": -7,
      "y": 9,
      "z": -2,
      "name": "Plant_Coral_Block_Pink"
    },
    {
      "x": -7,
      "y": 10,
      "z": -2,
      "name": "Plant_Coral_Block_Pink"
    },
    {
      "x": -7,
      "y": 6,
      "z": -1,
      "name": "Plant_Coral_Block_Pink"
    },
    {
      "x": -7,
      "y": 7,
      "z": -1,
      "name": "Plant_Coral_Block_Pink"
    },
    {
      "x": -7,
      "y": 8,
      "z": -1,
      "name": "Plant_Coral_Block_Pink"
    },
    {
      "x": -7,
      "y": 9,
      "z": -1,
      "name": "Plant_Coral_Block_Pink"
    },
    {
      "x": -7,
      "y": 10,
      "z": -1,
      "name": "Plant_Coral_Block_Violet"
    },
    {
      "x": -7,
      "y": 11,
      "z": -1,
      "name": "Plant_Coral_Block_Violet"
    },
    {
      "x": -7,
      "y": 6,
      "z": 0,
      "name": "Plant_Coral_Block_Pink"
    },
    {
      "x": -7,
      "y": 7,
      "z": 0,
      "name": "Plant_Coral_Block_Pink"
    },
    {
      "x": -7,
      "y": 8,
      "z": 0,
      "name": "Plant_Coral_Block_Pink"
    },
    {
      "x": -7,
      "y": 9,
      "z": 0,
      "name": "Plant_Coral_Block_Pink"
    },
    {
      "x": -7,
      "y": 10,
      "z": 0,
      "name": "Plant_Coral_Block_Pink"
    },
    {
      "x": -7,
      "y": 11,
      "z": 0,
      "name": "Plant_Coral_Bush_Pink"
    },
    {
      "x": -7,
      "y": 6,
      "z": 1,
      "name": "Plant_Coral_Block_Pink"
    },
    {
      "x": -7,
      "y": 7,
      "z": 1,
      "name": "Plant_Coral_Block_Pink"
    },
    {
      "x": -7,
      "y": 8,
      "z": 1,
      "name": "Plant_Coral_Block_Pink"
    },
    {
      "x": -7,
      "y": 9,
      "z": 1,
      "name": "Plant_Coral_Block_Pink"
    },
    {
      "x": -7,
      "y": 10,
      "z": 1,
      "name": "Plant_Coral_Block_Violet"
    },
    {
      "x": -7,
      "y": 11,
      "z": 1,
      "name": "Plant_Coral_Block_Violet"
    },
    {
      "x": -7,
      "y": 6,
      "z": 2,
      "name": "Plant_Coral_Block_Pink"
    },
    {
      "x": -7,
      "y": 7,
      "z": 2,
      "name": "Plant_Coral_Block_Pink"
    },
    {
      "x": -7,
      "y": 8,
      "z": 2,
      "name": "Plant_Coral_Block_Pink"
    },
    {
      "x": -7,
      "y": 9,
      "z": 2,
      "name": "Plant_Coral_Block_Pink"
    },
    {
      "x": -7,
      "y": 10,
      "z": 2,
      "name": "Plant_Coral_Block_Pink"
    },
    {
      "x": -7,
      "y": 6,
      "z": 3,
      "name": "Plant_Coral_Block_Pink"
    },
    {
      "x": -7,
      "y": 7,
      "z": 3,
      "name": "Plant_Coral_Block_Pink"
    },
    {
      "x": -7,
      "y": 8,
      "z": 3,
      "name": "Plant_Coral_Block_Pink"
    },
    {
      "x": -7,
      "y": 9,
      "z": 3,
      "name": "Plant_Coral_Block_Pink"
    },
    {
      "x": -7,
      "y": 10,
      "z": 3,
      "name": "Plant_Coral_Block_Violet"
    },
    {
      "x": -7,
      "y": 11,
      "z": 3,
      "name": "Plant_Coral_Block_Violet"
    },
    {
      "x": -7,
      "y": 6,
      "z": 4,
      "name": "Plant_Coral_Block_Pink"
    },
    {
      "x": -7,
      "y": 7,
      "z": 4,
      "name": "Plant_Coral_Block_Pink"
    },
    {
      "x": -7,
      "y": 8,
      "z": 4,
      "name": "Plant_Coral_Block_Pink"
    },
    {
      "x": -7,
      "y": 9,
      "z": 4,
      "name": "Plant_Coral_Block_Pink"
    },
    {
      "x": -7,
      "y": 10,
      "z": 4,
      "name": "Plant_Coral_Block_Pink"
    },
    {
      "x": -7,
      "y": 7,
      "z": 5,
      "name": "Plant_Coral_Block_Pink"
    },
    {
      "x": -7,
      "y": 8,
      "z": 5,
      "name": "Plant_Coral_Block_Pink"
    },
    {
      "x": -7,
      "y": 9,
      "z": 5,
      "name": "Plant_Coral_Block_Pink"
    },
    {
      "x": -7,
      "y": 8,
      "z": 6,
      "name": "Plant_Coral_Block_Pink"
    },
    {
      "x": -6,
      "y": 8,
      "z": -7,
      "name": "Plant_Coral_Block_Pink"
    },
    {
      "x": -6,
      "y": 7,
      "z": -6,
      "name": "Plant_Coral_Block_Pink"
    },
    {
      "x": -6,
      "y": 8,
      "z": -6,
      "name": "Plant_Coral_Block_Pink"
    },
    {
      "x": -6,
      "y": 9,
      "z": -6,
      "name": "Plant_Coral_Block_Pink"
    },
    {
      "x": -6,
      "y": 6,
      "z": -5,
      "name": "Plant_Coral_Block_Pink"
    },
    {
      "x": -6,
      "y": 7,
      "z": -5,
      "name": "Plant_Coral_Block_Pink"
    },
    {
      "x": -6,
      "y": 8,
      "z": -5,
      "name": "Plant_Coral_Block_Pink"
    },
    {
      "x": -6,
      "y": 9,
      "z": -5,
      "name": "Plant_Coral_Block_Pink"
    },
    {
      "x": -6,
      "y": 10,
      "z": -5,
      "name": "Plant_Coral_Block_Pink"
    },
    {
      "x": -6,
      "y": 6,
      "z": -4,
      "name": "Plant_Coral_Block_Pink"
    },
    {
      "x": -6,
      "y": 7,
      "z": -4,
      "name": "Plant_Coral_Block_Pink"
    },
    {
      "x": -6,
      "y": 8,
      "z": -4,
      "name": "Plant_Coral_Block_Pink"
    },
    {
      "x": -6,
      "y": 9,
      "z": -4,
      "name": "Plant_Coral_Block_Pink"
    },
    {
      "x": -6,
      "y": 10,
      "z": -4,
      "name": "Plant_Coral_Block_Violet"
    },
    {
      "x": -6,
      "y": 11,
      "z": -4,
      "name": "Plant_Coral_Block_Violet"
    },
    {
      "x": -6,
      "y": 5,
      "z": -3,
      "name": "Plant_Coral_Block_Pink"
    },
    {
      "x": -6,
      "y": 6,
      "z": -3,
      "name": "Plant_Coral_Block_Pink"
    },
    {
      "x": -6,
      "y": 7,
      "z": -3,
      "name": "Plant_Coral_Block_Pink"
    },
    {
      "x": -6,
      "y": 8,
      "z": -3,
      "name": "Plant_Coral_Block_Pink"
    },
    {
      "x": -6,
      "y": 9,
      "z": -3,
      "name": "Plant_Coral_Block_Pink"
    },
    {
      "x": -6,
      "y": 10,
      "z": -3,
      "name": "Plant_Coral_Block_Pink"
    },
    {
      "x": -6,
      "y": 11,
      "z": -3,
      "name": "Plant_Coral_Block_Violet"
    },
    {
      "x": -6,
      "y": 12,
      "z": -3,
      "name": "Plant_Coral_Block_Violet"
    },
    {
      "x": -6,
      "y": 5,
      "z": -2,
      "name": "Plant_Coral_Block_Pink"
    },
    {
      "x": -6,
      "y": 6,
      "z": -2,
      "name": "Plant_Coral_Block_Pink"
    },
    {
      "x": -6,
      "y": 7,
      "z": -2,
      "name": "Plant_Coral_Block_Pink"
    },
    {
      "x": -6,
      "y": 8,
      "z": -2,
      "name": "Plant_Coral_Block_Pink"
    },
    {
      "x": -6,
      "y": 9,
      "z": -2,
      "name": "Plant_Coral_Block_Pink"
    },
    {
      "x": -6,
      "y": 10,
      "z": -2,
      "name": "Plant_Coral_Block_Pink"
    },
    {
      "x": -6,
      "y": 11,
      "z": -2,
      "name": "Plant_Coral_Block_Pink"
    },
    {
      "x": -6,
      "y": 12,
      "z": -2,
      "name": "Plant_Coral_Bush_Pink"
    },
    {
      "x": -6,
      "y": 5,
      "z": -1,
      "name": "Plant_Coral_Block_Pink"
    },
    {
      "x": -6,
      "y": 6,
      "z": -1,
      "name": "Plant_Coral_Block_Pink"
    },
    {
      "x": -6,
      "y": 7,
      "z": -1,
      "name": "Plant_Coral_Block_Pink"
    },
    {
      "x": -6,
      "y": 8,
      "z": -1,
      "name": "Plant_Coral_Block_Pink"
    },
    {
      "x": -6,
      "y": 9,
      "z": -1,
      "name": "Plant_Coral_Block_Pink"
    },
    {
      "x": -6,
      "y": 10,
      "z": -1,
      "name": "Plant_Coral_Block_Pink"
    },
    {
      "x": -6,
      "y": 11,
      "z": -1,
      "name": "Plant_Coral_Block_Violet"
    },
    {
      "x": -6,
      "y": 12,
      "z": -1,
      "name": "Plant_Coral_Block_Violet"
    },
    {
      "x": -6,
      "y": 5,
      "z": 0,
      "name": "Plant_Coral_Block_Pink"
    },
    {
      "x": -6,
      "y": 6,
      "z": 0,
      "name": "Plant_Coral_Block_Pink"
    },
    {
      "x": -6,
      "y": 7,
      "z": 0,
      "name": "Plant_Coral_Block_Pink"
    },
    {
      "x": -6,
      "y": 8,
      "z": 0,
      "name": "Plant_Coral_Block_Pink"
    },
    {
      "x": -6,
      "y": 9,
      "z": 0,
      "name": "Plant_Coral_Block_Pink"
    },
    {
      "x": -6,
      "y": 10,
      "z": 0,
      "name": "Plant_Coral_Block_Pink"
    },
    {
      "x": -6,
      "y": 11,
      "z": 0,
      "name": "Plant_Coral_Block_Violet"
    },
    {
      "x": -6,
      "y": 12,
      "z": 0,
      "name": "Plant_Coral_Block_Violet"
    },
    {
      "x": -6,
      "y": 5,
      "z": 1,
      "name": "Plant_Coral_Block_Pink"
    },
    {
      "x": -6,
      "y": 6,
      "z": 1,
      "name": "Plant_Coral_Block_Pink"
    },
    {
      "x": -6,
      "y": 7,
      "z": 1,
      "name": "Plant_Coral_Block_Pink"
    },
    {
      "x": -6,
      "y": 8,
      "z": 1,
      "name": "Plant_Coral_Block_Pink"
    },
    {
      "x": -6,
      "y": 9,
      "z": 1,
      "name": "Plant_Coral_Block_Pink"
    },
    {
      "x": -6,
      "y": 10,
      "z": 1,
      "name": "Plant_Coral_Block_Pink"
    },
    {
      "x": -6,
      "y": 11,
      "z": 1,
      "name": "Plant_Coral_Block_Violet"
    },
    {
      "x": -6,
      "y": 12,
      "z": 1,
      "name": "Plant_Coral_Block_Violet"
    },
    {
      "x": -6,
      "y": 5,
      "z": 2,
      "name": "Plant_Coral_Block_Pink"
    },
    {
      "x": -6,
      "y": 6,
      "z": 2,
      "name": "Plant_Coral_Block_Pink"
    },
    {
      "x": -6,
      "y": 7,
      "z": 2,
      "name": "Plant_Coral_Block_Pink"
    },
    {
      "x": -6,
      "y": 8,
      "z": 2,
      "name": "Plant_Coral_Block_Pink"
    },
    {
      "x": -6,
      "y": 9,
      "z": 2,
      "name": "Plant_Coral_Block_Pink"
    },
    {
      "x": -6,
      "y": 10,
      "z": 2,
      "name": "Plant_Coral_Block_Pink"
    },
    {
      "x": -6,
      "y": 11,
      "z": 2,
      "name": "Plant_Coral_Block_Pink"
    },
    {
      "x": -6,
      "y": 5,
      "z": 3,
      "name": "Plant_Coral_Block_Pink"
    },
    {
      "x": -6,
      "y": 6,
      "z": 3,
      "name": "Plant_Coral_Block_Pink"
    },
    {
      "x": -6,
      "y": 7,
      "z": 3,
      "name": "Plant_Coral_Block_Pink"
    },
    {
      "x": -6,
      "y": 8,
      "z": 3,
      "name": "Plant_Coral_Block_Pink"
    },
    {
      "x": -6,
      "y": 9,
      "z": 3,
      "name": "Plant_Coral_Block_Pink"
    },
    {
      "x": -6,
      "y": 10,
      "z": 3,
      "name": "Plant_Coral_Block_Pink"
    },
    {
      "x": -6,
      "y": 11,
      "z": 3,
      "name": "Plant_Coral_Block_Violet"
    },
    {
      "x": -6,
      "y": 12,
      "z": 3,
      "name": "Plant_Coral_Block_Violet"
    },
    {
      "x": -6,
      "y": 6,
      "z": 4,
      "name": "Plant_Coral_Block_Pink"
    },
    {
      "x": -6,
      "y": 7,
      "z": 4,
      "name": "Plant_Coral_Block_Pink"
    },
    {
      "x": -6,
      "y": 8,
      "z": 4,
      "name": "Plant_Coral_Block_Pink"
    },
    {
      "x": -6,
      "y": 9,
      "z": 4,
      "name": "Plant_Coral_Block_Pink"
    },
    {
      "x": -6,
      "y": 10,
      "z": 4,
      "name": "Plant_Coral_Block_Violet"
    },
    {
      "x": -6,
      "y": 11,
      "z": 4,
      "name": "Plant_Coral_Block_Violet"
    },
    {
      "x": -6,
      "y": 6,
      "z": 5,
      "name": "Plant_Coral_Block_Pink"
    },
    {
      "x": -6,
      "y": 7,
      "z": 5,
      "name": "Plant_Coral_Block_Pink"
    },
    {
      "x": -6,
      "y": 8,
      "z": 5,
      "name": "Plant_Coral_Block_Pink"
    },
    {
      "x": -6,
      "y": 9,
      "z": 5,
      "name": "Plant_Coral_Block_Pink"
    },
    {
      "x": -6,
      "y": 10,
      "z": 5,
      "name": "Plant_Coral_Block_Pink"
    },
    {
      "x": -6,
      "y": 11,
      "z": 5,
      "name": "Plant_Coral_Model_Pink"
    },
    {
      "x": -6,
      "y": 7,
      "z": 6,
      "name": "Plant_Coral_Block_Pink"
    },
    {
      "x": -6,
      "y": 8,
      "z": 6,
      "name": "Plant_Coral_Block_Pink"
    },
    {
      "x": -6,
      "y": 9,
      "z": 6,
      "name": "Plant_Coral_Block_Violet"
    },
    {
      "x": -6,
      "y": 10,
      "z": 6,
      "name": "Plant_Coral_Block_Violet"
    },
    {
      "x": -6,
      "y": 8,
      "z": 7,
      "name": "Plant_Coral_Block_Pink"
    },
    {
      "x": -5,
      "y": 7,
      "z": -7,
      "name": "Plant_Coral_Block_Pink"
    },
    {
      "x": -5,
      "y": 8,
      "z": -7,
      "name": "Plant_Coral_Block_Pink"
    },
    {
      "x": -5,
      "y": 9,
      "z": -7,
      "name": "Plant_Coral_Block_Violet"
    },
    {
      "x": -5,
      "y": 10,
      "z": -7,
      "name": "Plant_Coral_Block_Violet"
    },
    {
      "x": -5,
      "y": 6,
      "z": -6,
      "name": "Plant_Coral_Block_Pink"
    },
    {
      "x": -5,
      "y": 7,
      "z": -6,
      "name": "Plant_Coral_Block_Pink"
    },
    {
      "x": -5,
      "y": 8,
      "z": -6,
      "name": "Plant_Coral_Block_Pink"
    },
    {
      "x": -5,
      "y": 9,
      "z": -6,
      "name": "Plant_Coral_Block_Pink"
    },
    {
      "x": -5,
      "y": 10,
      "z": -6,
      "name": "Plant_Coral_Block_Violet"
    },
    {
      "x": -5,
      "y": 11,
      "z": -6,
      "name": "Plant_Coral_Block_Violet"
    },
    {
      "x": -5,
      "y": 6,
      "z": -5,
      "name": "Plant_Coral_Block_Pink"
    },
    {
      "x": -5,
      "y": 7,
      "z": -5,
      "name": "Plant_Coral_Block_Pink"
    },
    {
      "x": -5,
      "y": 8,
      "z": -5,
      "name": "Plant_Coral_Block_Pink"
    },
    {
      "x": -5,
      "y": 9,
      "z": -5,
      "name": "Plant_Coral_Block_Pink"
    },
    {
      "x": -5,
      "y": 10,
      "z": -5,
      "name": "Plant_Coral_Block_Pink"
    },
    {
      "x": -5,
      "y": 5,
      "z": -4,
      "name": "Plant_Coral_Block_Pink"
    },
    {
      "x": -5,
      "y": 6,
      "z": -4,
      "name": "Plant_Coral_Block_Pink"
    },
    {
      "x": -5,
      "y": 7,
      "z": -4,
      "name": "Plant_Coral_Block_Pink"
    },
    {
      "x": -5,
      "y": 8,
      "z": -4,
      "name": "Plant_Coral_Block_Pink"
    },
    {
      "x": -5,
      "y": 9,
      "z": -4,
      "name": "Plant_Coral_Block_Pink"
    },
    {
      "x": -5,
      "y": 10,
      "z": -4,
      "name": "Plant_Coral_Block_Pink"
    },
    {
      "x": -5,
      "y": 11,
      "z": -4,
      "name": "Plant_Coral_Block_Pink"
    },
    {
      "x": -5,
      "y": 5,
      "z": -3,
      "name": "Plant_Coral_Block_Pink"
    },
    {
      "x": -5,
      "y": 6,
      "z": -3,
      "name": "Plant_Coral_Block_Pink"
    },
    {
      "x": -5,
      "y": 7,
      "z": -3,
      "name": "Plant_Coral_Block_Pink"
    },
    {
      "x": -5,
      "y": 8,
      "z": -3,
      "name": "Plant_Coral_Block_Pink"
    },
    {
      "x": -5,
      "y": 9,
      "z": -3,
      "name": "Plant_Coral_Block_Pink"
    },
    {
      "x": -5,
      "y": 10,
      "z": -3,
      "name": "Plant_Coral_Block_Pink"
    },
    {
      "x": -5,
      "y": 11,
      "z": -3,
      "name": "Plant_Coral_Block_Violet"
    },
    {
      "x": -5,
      "y": 12,
      "z": -3,
      "name": "Plant_Coral_Block_Violet"
    },
    {
      "x": -5,
      "y": 5,
      "z": -2,
      "name": "Plant_Coral_Block_Pink"
    },
    {
      "x": -5,
      "y": 6,
      "z": -2,
      "name": "Plant_Coral_Block_Pink"
    },
    {
      "x": -5,
      "y": 7,
      "z": -2,
      "name": "Plant_Coral_Block_Pink"
    },
    {
      "x": -5,
      "y": 8,
      "z": -2,
      "name": "Plant_Coral_Block_Pink"
    },
    {
      "x": -5,
      "y": 9,
      "z": -2,
      "name": "Plant_Coral_Block_Pink"
    },
    {
      "x": -5,
      "y": 10,
      "z": -2,
      "name": "Plant_Coral_Block_Pink"
    },
    {
      "x": -5,
      "y": 11,
      "z": -2,
      "name": "Plant_Coral_Block_Pink"
    },
    {
      "x": -5,
      "y": 12,
      "z": -2,
      "name": "Plant_Coral_Bush_Pink"
    },
    {
      "x": -5,
      "y": 5,
      "z": -1,
      "name": "Plant_Coral_Block_Pink"
    },
    {
      "x": -5,
      "y": 6,
      "z": -1,
      "name": "Plant_Coral_Block_Pink"
    },
    {
      "x": -5,
      "y": 7,
      "z": -1,
      "name": "Plant_Coral_Block_Pink"
    },
    {
      "x": -5,
      "y": 8,
      "z": -1,
      "name": "Plant_Coral_Block_Pink"
    },
    {
      "x": -5,
      "y": 9,
      "z": -1,
      "name": "Plant_Coral_Block_Pink"
    },
    {
      "x": -5,
      "y": 10,
      "z": -1,
      "name": "Plant_Coral_Block_Pink"
    },
    {
      "x": -5,
      "y": 11,
      "z": -1,
      "name": "Plant_Coral_Block_Pink"
    },
    {
      "x": -5,
      "y": 5,
      "z": 0,
      "name": "Plant_Coral_Block_Pink"
    },
    {
      "x": -5,
      "y": 6,
      "z": 0,
      "name": "Plant_Coral_Block_Pink"
    },
    {
      "x": -5,
      "y": 7,
      "z": 0,
      "name": "Plant_Coral_Block_Pink"
    },
    {
      "x": -5,
      "y": 8,
      "z": 0,
      "name": "Plant_Coral_Block_Pink"
    },
    {
      "x": -5,
      "y": 9,
      "z": 0,
      "name": "Plant_Coral_Block_Pink"
    },
    {
      "x": -5,
      "y": 10,
      "z": 0,
      "name": "Plant_Coral_Block_Pink"
    },
    {
      "x": -5,
      "y": 11,
      "z": 0,
      "name": "Plant_Coral_Block_Pink"
    },
    {
      "x": -5,
      "y": 12,
      "z": 0,
      "name": "Plant_Coral_Bush_Pink"
    },
    {
      "x": -5,
      "y": 5,
      "z": 1,
      "name": "Plant_Coral_Block_Pink"
    },
    {
      "x": -5,
      "y": 6,
      "z": 1,
      "name": "Plant_Coral_Block_Pink"
    },
    {
      "x": -5,
      "y": 7,
      "z": 1,
      "name": "Plant_Coral_Block_Pink"
    },
    {
      "x": -5,
      "y": 8,
      "z": 1,
      "name": "Plant_Coral_Block_Pink"
    },
    {
      "x": -5,
      "y": 9,
      "z": 1,
      "name": "Plant_Coral_Block_Pink"
    },
    {
      "x": -5,
      "y": 10,
      "z": 1,
      "name": "Plant_Coral_Block_Pink"
    },
    {
      "x": -5,
      "y": 11,
      "z": 1,
      "name": "Plant_Coral_Block_Pink"
    },
    {
      "x": -5,
      "y": 5,
      "z": 2,
      "name": "Plant_Coral_Block_Pink"
    },
    {
      "x": -5,
      "y": 6,
      "z": 2,
      "name": "Plant_Coral_Block_Pink"
    },
    {
      "x": -5,
      "y": 7,
      "z": 2,
      "name": "Plant_Coral_Block_Pink"
    },
    {
      "x": -5,
      "y": 8,
      "z": 2,
      "name": "Plant_Coral_Block_Pink"
    },
    {
      "x": -5,
      "y": 9,
      "z": 2,
      "name": "Plant_Coral_Block_Pink"
    },
    {
      "x": -5,
      "y": 10,
      "z": 2,
      "name": "Plant_Coral_Block_Pink"
    },
    {
      "x": -5,
      "y": 11,
      "z": 2,
      "name": "Plant_Coral_Block_Pink"
    },
    {
      "x": -5,
      "y": 5,
      "z": 3,
      "name": "Plant_Coral_Block_Pink"
    },
    {
      "x": -5,
      "y": 6,
      "z": 3,
      "name": "Plant_Coral_Block_Pink"
    },
    {
      "x": -5,
      "y": 7,
      "z": 3,
      "name": "Plant_Coral_Block_Pink"
    },
    {
      "x": -5,
      "y": 8,
      "z": 3,
      "name": "Plant_Coral_Block_Pink"
    },
    {
      "x": -5,
      "y": 9,
      "z": 3,
      "name": "Plant_Coral_Block_Pink"
    },
    {
      "x": -5,
      "y": 10,
      "z": 3,
      "name": "Plant_Coral_Block_Pink"
    },
    {
      "x": -5,
      "y": 11,
      "z": 3,
      "name": "Plant_Coral_Block_Pink"
    },
    {
      "x": -5,
      "y": 5,
      "z": 4,
      "name": "Plant_Coral_Block_Pink"
    },
    {
      "x": -5,
      "y": 6,
      "z": 4,
      "name": "Plant_Coral_Block_Pink"
    },
    {
      "x": -5,
      "y": 7,
      "z": 4,
      "name": "Plant_Coral_Block_Pink"
    },
    {
      "x": -5,
      "y": 8,
      "z": 4,
      "name": "Plant_Coral_Block_Pink"
    },
    {
      "x": -5,
      "y": 9,
      "z": 4,
      "name": "Plant_Coral_Block_Pink"
    },
    {
      "x": -5,
      "y": 10,
      "z": 4,
      "name": "Plant_Coral_Block_Pink"
    },
    {
      "x": -5,
      "y": 11,
      "z": 4,
      "name": "Plant_Coral_Block_Violet"
    },
    {
      "x": -5,
      "y": 12,
      "z": 4,
      "name": "Plant_Coral_Block_Violet"
    },
    {
      "x": -5,
      "y": 6,
      "z": 5,
      "name": "Plant_Coral_Block_Pink"
    },
    {
      "x": -5,
      "y": 7,
      "z": 5,
      "name": "Plant_Coral_Block_Pink"
    },
    {
      "x": -5,
      "y": 8,
      "z": 5,
      "name": "Plant_Coral_Block_Pink"
    },
    {
      "x": -5,
      "y": 9,
      "z": 5,
      "name": "Plant_Coral_Block_Pink"
    },
    {
      "x": -5,
      "y": 10,
      "z": 5,
      "name": "Plant_Coral_Block_Pink"
    },
    {
      "x": -5,
      "y": 11,
      "z": 5,
      "name": "Plant_Coral_Model_Pink"
    },
    {
      "x": -5,
      "y": 6,
      "z": 6,
      "name": "Plant_Coral_Block_Pink"
    },
    {
      "x": -5,
      "y": 7,
      "z": 6,
      "name": "Plant_Coral_Block_Pink"
    },
    {
      "x": -5,
      "y": 8,
      "z": 6,
      "name": "Plant_Coral_Block_Pink"
    },
    {
      "x": -5,
      "y": 9,
      "z": 6,
      "name": "Plant_Coral_Block_Pink"
    },
    {
      "x": -5,
      "y": 10,
      "z": 6,
      "name": "Plant_Coral_Block_Violet"
    },
    {
      "x": -5,
      "y": 11,
      "z": 6,
      "name": "Plant_Coral_Block_Violet"
    },
    {
      "x": -5,
      "y": 7,
      "z": 7,
      "name": "Plant_Coral_Block_Pink"
    },
    {
      "x": -5,
      "y": 8,
      "z": 7,
      "name": "Plant_Coral_Block_Pink"
    },
    {
      "x": -5,
      "y": 9,
      "z": 7,
      "name": "Plant_Coral_Block_Pink"
    },
    {
      "x": -4,
      "y": 7,
      "z": -8,
      "name": "Plant_Coral_Block_Pink"
    },
    {
      "x": -4,
      "y": 8,
      "z": -8,
      "name": "Plant_Coral_Block_Pink"
    },
    {
      "x": -4,
      "y": 9,
      "z": -8,
      "name": "Plant_Coral_Block_Violet"
    },
    {
      "x": -4,
      "y": 10,
      "z": -8,
      "name": "Plant_Coral_Block_Violet"
    },
    {
      "x": -4,
      "y": 6,
      "z": -7,
      "name": "Plant_Coral_Block_Pink"
    },
    {
      "x": -4,
      "y": 7,
      "z": -7,
      "name": "Plant_Coral_Block_Pink"
    },
    {
      "x": -4,
      "y": 8,
      "z": -7,
      "name": "Plant_Coral_Block_Pink"
    },
    {
      "x": -4,
      "y": 9,
      "z": -7,
      "name": "Plant_Coral_Block_Pink"
    },
    {
      "x": -4,
      "y": 10,
      "z": -7,
      "name": "Plant_Coral_Block_Pink"
    },
    {
      "x": -4,
      "y": 6,
      "z": -6,
      "name": "Plant_Coral_Block_Pink"
    },
    {
      "x": -4,
      "y": 7,
      "z": -6,
      "name": "Plant_Coral_Block_Pink"
    },
    {
      "x": -4,
      "y": 8,
      "z": -6,
      "name": "Plant_Coral_Block_Pink"
    },
    {
      "x": -4,
      "y": 9,
      "z": -6,
      "name": "Plant_Coral_Block_Pink"
    },
    {
      "x": -4,
      "y": 10,
      "z": -6,
      "name": "Plant_Coral_Block_Violet"
    },
    {
      "x": -4,
      "y": 11,
      "z": -6,
      "name": "Plant_Coral_Block_Violet"
    },
    {
      "x": -4,
      "y": 5,
      "z": -5,
      "name": "Plant_Coral_Block_Pink"
    },
    {
      "x": -4,
      "y": 6,
      "z": -5,
      "name": "Plant_Coral_Block_Pink"
    },
    {
      "x": -4,
      "y": 7,
      "z": -5,
      "name": "Plant_Coral_Block_Pink"
    },
    {
      "x": -4,
      "y": 8,
      "z": -5,
      "name": "Plant_Coral_Block_Pink"
    },
    {
      "x": -4,
      "y": 9,
      "z": -5,
      "name": "Plant_Coral_Block_Pink"
    },
    {
      "x": -4,
      "y": 10,
      "z": -5,
      "name": "Plant_Coral_Block_Pink"
    },
    {
      "x": -4,
      "y": 11,
      "z": -5,
      "name": "Plant_Coral_Block_Violet"
    },
    {
      "x": -4,
      "y": 12,
      "z": -5,
      "name": "Plant_Coral_Block_Violet"
    },
    {
      "x": -4,
      "y": 5,
      "z": -4,
      "name": "Plant_Coral_Block_Pink"
    },
    {
      "x": -4,
      "y": 6,
      "z": -4,
      "name": "Plant_Coral_Block_Pink"
    },
    {
      "x": -4,
      "y": 7,
      "z": -4,
      "name": "Plant_Coral_Block_Pink"
    },
    {
      "x": -4,
      "y": 8,
      "z": -4,
      "name": "Plant_Coral_Block_Pink"
    },
    {
      "x": -4,
      "y": 9,
      "z": -4,
      "name": "Plant_Coral_Block_Pink"
    },
    {
      "x": -4,
      "y": 10,
      "z": -4,
      "name": "Plant_Coral_Block_Pink"
    },
    {
      "x": -4,
      "y": 11,
      "z": -4,
      "name": "Plant_Coral_Block_Pink"
    },
    {
      "x": -4,
      "y": 12,
      "z": -4,
      "name": "Plant_Coral_Model_Pink"
    },
    {
      "x": -4,
      "y": 5,
      "z": -3,
      "name": "Plant_Coral_Block_Pink"
    },
    {
      "x": -4,
      "y": 6,
      "z": -3,
      "name": "Plant_Coral_Block_Pink"
    },
    {
      "x": -4,
      "y": 7,
      "z": -3,
      "name": "Plant_Coral_Block_Pink"
    },
    {
      "x": -4,
      "y": 8,
      "z": -3,
      "name": "Plant_Coral_Block_Pink"
    },
    {
      "x": -4,
      "y": 9,
      "z": -3,
      "name": "Plant_Coral_Block_Pink"
    },
    {
      "x": -4,
      "y": 10,
      "z": -3,
      "name": "Plant_Coral_Block_Pink"
    },
    {
      "x": -4,
      "y": 11,
      "z": -3,
      "name": "Plant_Coral_Block_Violet"
    },
    {
      "x": -4,
      "y": 12,
      "z": -3,
      "name": "Plant_Coral_Block_Violet"
    },
    {
      "x": -4,
      "y": 5,
      "z": -2,
      "name": "Plant_Coral_Block_Pink"
    },
    {
      "x": -4,
      "y": 6,
      "z": -2,
      "name": "Plant_Coral_Block_Pink"
    },
    {
      "x": -4,
      "y": 7,
      "z": -2,
      "name": "Plant_Coral_Block_Pink"
    },
    {
      "x": -4,
      "y": 8,
      "z": -2,
      "name": "Plant_Coral_Block_Pink"
    },
    {
      "x": -4,
      "y": 9,
      "z": -2,
      "name": "Plant_Coral_Block_Pink"
    },
    {
      "x": -4,
      "y": 10,
      "z": -2,
      "name": "Plant_Coral_Block_Pink"
    },
    {
      "x": -4,
      "y": 11,
      "z": -2,
      "name": "Plant_Coral_Block_Violet"
    },
    {
      "x": -4,
      "y": 12,
      "z": -2,
      "name": "Plant_Coral_Block_Violet"
    },
    {
      "x": -4,
      "y": 5,
      "z": -1,
      "name": "Plant_Coral_Block_Pink"
    },
    {
      "x": -4,
      "y": 6,
      "z": -1,
      "name": "Plant_Coral_Block_Pink"
    },
    {
      "x": -4,
      "y": 7,
      "z": -1,
      "name": "Plant_Coral_Block_Pink"
    },
    {
      "x": -4,
      "y": 8,
      "z": -1,
      "name": "Plant_Coral_Block_Pink"
    },
    {
      "x": -4,
      "y": 9,
      "z": -1,
      "name": "Plant_Coral_Block_Pink"
    },
    {
      "x": -4,
      "y": 10,
      "z": -1,
      "name": "Plant_Coral_Block_Pink"
    },
    {
      "x": -4,
      "y": 11,
      "z": -1,
      "name": "Plant_Coral_Block_Violet"
    },
    {
      "x": -4,
      "y": 12,
      "z": -1,
      "name": "Plant_Coral_Block_Violet"
    },
    {
      "x": -4,
      "y": 5,
      "z": 0,
      "name": "Plant_Coral_Block_Pink"
    },
    {
      "x": -4,
      "y": 6,
      "z": 0,
      "name": "Plant_Coral_Block_Pink"
    },
    {
      "x": -4,
      "y": 7,
      "z": 0,
      "name": "Plant_Coral_Block_Pink"
    },
    {
      "x": -4,
      "y": 8,
      "z": 0,
      "name": "Plant_Coral_Block_Pink"
    },
    {
      "x": -4,
      "y": 9,
      "z": 0,
      "name": "Plant_Coral_Block_Pink"
    },
    {
      "x": -4,
      "y": 10,
      "z": 0,
      "name": "Plant_Coral_Block_Pink"
    },
    {
      "x": -4,
      "y": 11,
      "z": 0,
      "name": "Plant_Coral_Block_Violet"
    },
    {
      "x": -4,
      "y": 12,
      "z": 0,
      "name": "Plant_Coral_Block_Violet"
    },
    {
      "x": -4,
      "y": 5,
      "z": 1,
      "name": "Plant_Coral_Block_Pink"
    },
    {
      "x": -4,
      "y": 6,
      "z": 1,
      "name": "Plant_Coral_Block_Pink"
    },
    {
      "x": -4,
      "y": 7,
      "z": 1,
      "name": "Plant_Coral_Block_Pink"
    },
    {
      "x": -4,
      "y": 8,
      "z": 1,
      "name": "Plant_Coral_Block_Pink"
    },
    {
      "x": -4,
      "y": 9,
      "z": 1,
      "name": "Plant_Coral_Block_Pink"
    },
    {
      "x": -4,
      "y": 10,
      "z": 1,
      "name": "Plant_Coral_Block_Pink"
    },
    {
      "x": -4,
      "y": 11,
      "z": 1,
      "name": "Plant_Coral_Block_Violet"
    },
    {
      "x": -4,
      "y": 12,
      "z": 1,
      "name": "Plant_Coral_Block_Violet"
    },
    {
      "x": -4,
      "y": 5,
      "z": 2,
      "name": "Plant_Coral_Block_Pink"
    },
    {
      "x": -4,
      "y": 6,
      "z": 2,
      "name": "Plant_Coral_Block_Pink"
    },
    {
      "x": -4,
      "y": 7,
      "z": 2,
      "name": "Plant_Coral_Block_Pink"
    },
    {
      "x": -4,
      "y": 8,
      "z": 2,
      "name": "Plant_Coral_Block_Pink"
    },
    {
      "x": -4,
      "y": 9,
      "z": 2,
      "name": "Plant_Coral_Block_Pink"
    },
    {
      "x": -4,
      "y": 10,
      "z": 2,
      "name": "Plant_Coral_Block_Pink"
    },
    {
      "x": -4,
      "y": 11,
      "z": 2,
      "name": "Plant_Coral_Block_Violet"
    },
    {
      "x": -4,
      "y": 12,
      "z": 2,
      "name": "Plant_Coral_Block_Violet"
    },
    {
      "x": -4,
      "y": 5,
      "z": 3,
      "name": "Plant_Coral_Block_Pink"
    },
    {
      "x": -4,
      "y": 6,
      "z": 3,
      "name": "Plant_Coral_Block_Pink"
    },
    {
      "x": -4,
      "y": 7,
      "z": 3,
      "name": "Plant_Coral_Block_Pink"
    },
    {
      "x": -4,
      "y": 8,
      "z": 3,
      "name": "Plant_Coral_Block_Pink"
    },
    {
      "x": -4,
      "y": 9,
      "z": 3,
      "name": "Plant_Coral_Block_Pink"
    },
    {
      "x": -4,
      "y": 10,
      "z": 3,
      "name": "Plant_Coral_Block_Pink"
    },
    {
      "x": -4,
      "y": 11,
      "z": 3,
      "name": "Plant_Coral_Block_Pink"
    },
    {
      "x": -4,
      "y": 5,
      "z": 4,
      "name": "Plant_Coral_Block_Pink"
    },
    {
      "x": -4,
      "y": 6,
      "z": 4,
      "name": "Plant_Coral_Block_Pink"
    },
    {
      "x": -4,
      "y": 7,
      "z": 4,
      "name": "Plant_Coral_Block_Pink"
    },
    {
      "x": -4,
      "y": 8,
      "z": 4,
      "name": "Plant_Coral_Block_Pink"
    },
    {
      "x": -4,
      "y": 9,
      "z": 4,
      "name": "Plant_Coral_Block_Pink"
    },
    {
      "x": -4,
      "y": 10,
      "z": 4,
      "name": "Plant_Coral_Block_Pink"
    },
    {
      "x": -4,
      "y": 11,
      "z": 4,
      "name": "Plant_Coral_Block_Violet"
    },
    {
      "x": -4,
      "y": 12,
      "z": 4,
      "name": "Plant_Coral_Block_Violet"
    },
    {
      "x": -4,
      "y": 5,
      "z": 5,
      "name": "Plant_Coral_Block_Pink"
    },
    {
      "x": -4,
      "y": 6,
      "z": 5,
      "name": "Plant_Coral_Block_Pink"
    },
    {
      "x": -4,
      "y": 7,
      "z": 5,
      "name": "Plant_Coral_Block_Pink"
    },
    {
      "x": -4,
      "y": 8,
      "z": 5,
      "name": "Plant_Coral_Block_Pink"
    },
    {
      "x": -4,
      "y": 9,
      "z": 5,
      "name": "Plant_Coral_Block_Pink"
    },
    {
      "x": -4,
      "y": 10,
      "z": 5,
      "name": "Plant_Coral_Block_Pink"
    },
    {
      "x": -4,
      "y": 11,
      "z": 5,
      "name": "Plant_Coral_Block_Violet"
    },
    {
      "x": -4,
      "y": 12,
      "z": 5,
      "name": "Plant_Coral_Block_Violet"
    },
    {
      "x": -4,
      "y": 6,
      "z": 6,
      "name": "Plant_Coral_Block_Pink"
    },
    {
      "x": -4,
      "y": 7,
      "z": 6,
      "name": "Plant_Coral_Block_Pink"
    },
    {
      "x": -4,
      "y": 8,
      "z": 6,
      "name": "Plant_Coral_Block_Pink"
    },
    {
      "x": -4,
      "y": 9,
      "z": 6,
      "name": "Plant_Coral_Block_Pink"
    },
    {
      "x": -4,
      "y": 10,
      "z": 6,
      "name": "Plant_Coral_Block_Violet"
    },
    {
      "x": -4,
      "y": 11,
      "z": 6,
      "name": "Plant_Coral_Block_Violet"
    },
    {
      "x": -4,
      "y": 6,
      "z": 7,
      "name": "Plant_Coral_Block_Pink"
    },
    {
      "x": -4,
      "y": 7,
      "z": 7,
      "name": "Plant_Coral_Block_Pink"
    },
    {
      "x": -4,
      "y": 8,
      "z": 7,
      "name": "Plant_Coral_Block_Pink"
    },
    {
      "x": -4,
      "y": 9,
      "z": 7,
      "name": "Plant_Coral_Block_Pink"
    },
    {
      "x": -4,
      "y": 10,
      "z": 7,
      "name": "Plant_Coral_Block_Violet"
    },
    {
      "x": -4,
      "y": 11,
      "z": 7,
      "name": "Plant_Coral_Block_Violet"
    },
    {
      "x": -4,
      "y": 7,
      "z": 8,
      "name": "Plant_Coral_Block_Pink"
    },
    {
      "x": -4,
      "y": 8,
      "z": 8,
      "name": "Plant_Coral_Block_Pink"
    },
    {
      "x": -4,
      "y": 9,
      "z": 8,
      "name": "Plant_Coral_Block_Pink"
    },
    {
      "x": -3,
      "y": 7,
      "z": -8,
      "name": "Plant_Coral_Block_Pink"
    },
    {
      "x": -3,
      "y": 8,
      "z": -8,
      "name": "Plant_Coral_Block_Pink"
    },
    {
      "x": -3,
      "y": 9,
      "z": -8,
      "name": "Plant_Coral_Block_Pink"
    },
    {
      "x": -3,
      "y": 6,
      "z": -7,
      "name": "Plant_Coral_Block_Pink"
    },
    {
      "x": -3,
      "y": 7,
      "z": -7,
      "name": "Plant_Coral_Block_Pink"
    },
    {
      "x": -3,
      "y": 8,
      "z": -7,
      "name": "Plant_Coral_Block_Pink"
    },
    {
      "x": -3,
      "y": 9,
      "z": -7,
      "name": "Plant_Coral_Block_Pink"
    },
    {
      "x": -3,
      "y": 10,
      "z": -7,
      "name": "Plant_Coral_Block_Pink"
    },
    {
      "x": -3,
      "y": 5,
      "z": -6,
      "name": "Plant_Coral_Block_Pink"
    },
    {
      "x": -3,
      "y": 6,
      "z": -6,
      "name": "Plant_Coral_Block_Pink"
    },
    {
      "x": -3,
      "y": 7,
      "z": -6,
      "name": "Plant_Coral_Block_Pink"
    },
    {
      "x": -3,
      "y": 8,
      "z": -6,
      "name": "Plant_Coral_Block_Pink"
    },
    {
      "x": -3,
      "y": 9,
      "z": -6,
      "name": "Plant_Coral_Block_Pink"
    },
    {
      "x": -3,
      "y": 10,
      "z": -6,
      "name": "Plant_Coral_Block_Pink"
    },
    {
      "x": -3,
      "y": 11,
      "z": -6,
      "name": "Plant_Coral_Block_Pink"
    },
    {
      "x": -3,
      "y": 5,
      "z": -5,
      "name": "Plant_Coral_Block_Pink"
    },
    {
      "x": -3,
      "y": 6,
      "z": -5,
      "name": "Plant_Coral_Block_Pink"
    },
    {
      "x": -3,
      "y": 7,
      "z": -5,
      "name": "Plant_Coral_Block_Pink"
    },
    {
      "x": -3,
      "y": 8,
      "z": -5,
      "name": "Plant_Coral_Block_Pink"
    },
    {
      "x": -3,
      "y": 9,
      "z": -5,
      "name": "Plant_Coral_Block_Pink"
    },
    {
      "x": -3,
      "y": 10,
      "z": -5,
      "name": "Plant_Coral_Block_Pink"
    },
    {
      "x": -3,
      "y": 11,
      "z": -5,
      "name": "Plant_Coral_Block_Violet"
    },
    {
      "x": -3,
      "y": 12,
      "z": -5,
      "name": "Plant_Coral_Block_Violet"
    },
    {
      "x": -3,
      "y": 5,
      "z": -4,
      "name": "Plant_Coral_Block_Pink"
    },
    {
      "x": -3,
      "y": 6,
      "z": -4,
      "name": "Plant_Coral_Block_Pink"
    },
    {
      "x": -3,
      "y": 7,
      "z": -4,
      "name": "Plant_Coral_Block_Pink"
    },
    {
      "x": -3,
      "y": 8,
      "z": -4,
      "name": "Plant_Coral_Block_Pink"
    },
    {
      "x": -3,
      "y": 9,
      "z": -4,
      "name": "Plant_Coral_Block_Pink"
    },
    {
      "x": -3,
      "y": 10,
      "z": -4,
      "name": "Plant_Coral_Block_Pink"
    },
    {
      "x": -3,
      "y": 11,
      "z": -4,
      "name": "Plant_Coral_Block_Pink"
    },
    {
      "x": -3,
      "y": 5,
      "z": -3,
      "name": "Plant_Coral_Block_Pink"
    },
    {
      "x": -3,
      "y": 6,
      "z": -3,
      "name": "Plant_Coral_Block_Pink"
    },
    {
      "x": -3,
      "y": 7,
      "z": -3,
      "name": "Plant_Coral_Block_Pink"
    },
    {
      "x": -3,
      "y": 8,
      "z": -3,
      "name": "Plant_Coral_Block_Pink"
    },
    {
      "x": -3,
      "y": 9,
      "z": -3,
      "name": "Plant_Coral_Block_Pink"
    },
    {
      "x": -3,
      "y": 10,
      "z": -3,
      "name": "Plant_Coral_Block_Pink"
    },
    {
      "x": -3,
      "y": 11,
      "z": -3,
      "name": "Plant_Coral_Block_Pink"
    },
    {
      "x": -3,
      "y": 12,
      "z": -3,
      "name": "Plant_Coral_Model_Pink"
    },
    {
      "x": -3,
      "y": 4,
      "z": -2,
      "name": "Plant_Coral_Block_Pink"
    },
    {
      "x": -3,
      "y": 5,
      "z": -2,
      "name": "Plant_Coral_Block_Pink"
    },
    {
      "x": -3,
      "y": 6,
      "z": -2,
      "name": "Plant_Coral_Block_Pink"
    },
    {
      "x": -3,
      "y": 7,
      "z": -2,
      "name": "Plant_Coral_Block_Pink"
    },
    {
      "x": -3,
      "y": 8,
      "z": -2,
      "name": "Plant_Coral_Block_Pink"
    },
    {
      "x": -3,
      "y": 9,
      "z": -2,
      "name": "Plant_Coral_Block_Pink"
    },
    {
      "x": -3,
      "y": 10,
      "z": -2,
      "name": "Plant_Coral_Block_Pink"
    },
    {
      "x": -3,
      "y": 11,
      "z": -2,
      "name": "Plant_Coral_Block_Pink"
    },
    {
      "x": -3,
      "y": 12,
      "z": -2,
      "name": "Plant_Coral_Block_Pink"
    },
    {
      "x": -3,
      "y": 13,
      "z": -2,
      "name": "Plant_Coral_Model_Pink"
    },
    {
      "x": -3,
      "y": 4,
      "z": -1,
      "name": "Plant_Coral_Block_Pink"
    },
    {
      "x": -3,
      "y": 5,
      "z": -1,
      "name": "Plant_Coral_Block_Pink"
    },
    {
      "x": -3,
      "y": 6,
      "z": -1,
      "name": "Plant_Coral_Block_Pink"
    },
    {
      "x": -3,
      "y": 7,
      "z": -1,
      "name": "Plant_Coral_Block_Pink"
    },
    {
      "x": -3,
      "y": 8,
      "z": -1,
      "name": "Plant_Coral_Block_Pink"
    },
    {
      "x": -3,
      "y": 9,
      "z": -1,
      "name": "Plant_Coral_Block_Pink"
    },
    {
      "x": -3,
      "y": 10,
      "z": -1,
      "name": "Plant_Coral_Block_Pink"
    },
    {
      "x": -3,
      "y": 11,
      "z": -1,
      "name": "Plant_Coral_Block_Pink"
    },
    {
      "x": -3,
      "y": 12,
      "z": -1,
      "name": "Plant_Coral_Block_Pink"
    },
    {
      "x": -3,
      "y": 4,
      "z": 0,
      "name": "Plant_Coral_Block_Pink"
    },
    {
      "x": -3,
      "y": 5,
      "z": 0,
      "name": "Plant_Coral_Block_Pink"
    },
    {
      "x": -3,
      "y": 6,
      "z": 0,
      "name": "Plant_Coral_Block_Pink"
    },
    {
      "x": -3,
      "y": 7,
      "z": 0,
      "name": "Plant_Coral_Block_Pink"
    },
    {
      "x": -3,
      "y": 8,
      "z": 0,
      "name": "Plant_Coral_Block_Pink"
    },
    {
      "x": -3,
      "y": 9,
      "z": 0,
      "name": "Plant_Coral_Block_Pink"
    },
    {
      "x": -3,
      "y": 10,
      "z": 0,
      "name": "Plant_Coral_Block_Pink"
    },
    {
      "x": -3,
      "y": 11,
      "z": 0,
      "name": "Plant_Coral_Block_Pink"
    },
    {
      "x": -3,
      "y": 12,
      "z": 0,
      "name": "Plant_Coral_Block_Pink"
    },
    {
      "x": -3,
      "y": 4,
      "z": 1,
      "name": "Plant_Coral_Block_Pink"
    },
    {
      "x": -3,
      "y": 5,
      "z": 1,
      "name": "Plant_Coral_Block_Pink"
    },
    {
      "x": -3,
      "y": 6,
      "z": 1,
      "name": "Plant_Coral_Block_Pink"
    },
    {
      "x": -3,
      "y": 7,
      "z": 1,
      "name": "Plant_Coral_Block_Pink"
    },
    {
      "x": -3,
      "y": 8,
      "z": 1,
      "name": "Plant_Coral_Block_Pink"
    },
    {
      "x": -3,
      "y": 9,
      "z": 1,
      "name": "Plant_Coral_Block_Pink"
    },
    {
      "x": -3,
      "y": 10,
      "z": 1,
      "name": "Plant_Coral_Block_Pink"
    },
    {
      "x": -3,
      "y": 11,
      "z": 1,
      "name": "Plant_Coral_Block_Pink"
    },
    {
      "x": -3,
      "y": 12,
      "z": 1,
      "name": "Plant_Coral_Block_Pink"
    },
    {
      "x": -3,
      "y": 4,
      "z": 2,
      "name": "Plant_Coral_Block_Pink"
    },
    {
      "x": -3,
      "y": 5,
      "z": 2,
      "name": "Plant_Coral_Block_Pink"
    },
    {
      "x": -3,
      "y": 6,
      "z": 2,
      "name": "Plant_Coral_Block_Pink"
    },
    {
      "x": -3,
      "y": 7,
      "z": 2,
      "name": "Plant_Coral_Block_Pink"
    },
    {
      "x": -3,
      "y": 8,
      "z": 2,
      "name": "Plant_Coral_Block_Pink"
    },
    {
      "x": -3,
      "y": 9,
      "z": 2,
      "name": "Plant_Coral_Block_Pink"
    },
    {
      "x": -3,
      "y": 10,
      "z": 2,
      "name": "Plant_Coral_Block_Pink"
    },
    {
      "x": -3,
      "y": 11,
      "z": 2,
      "name": "Plant_Coral_Block_Pink"
    },
    {
      "x": -3,
      "y": 12,
      "z": 2,
      "name": "Plant_Coral_Block_Violet"
    },
    {
      "x": -3,
      "y": 13,
      "z": 2,
      "name": "Plant_Coral_Block_Violet"
    },
    {
      "x": -3,
      "y": 5,
      "z": 3,
      "name": "Plant_Coral_Block_Pink"
    },
    {
      "x": -3,
      "y": 6,
      "z": 3,
      "name": "Plant_Coral_Block_Pink"
    },
    {
      "x": -3,
      "y": 7,
      "z": 3,
      "name": "Plant_Coral_Block_Pink"
    },
    {
      "x": -3,
      "y": 8,
      "z": 3,
      "name": "Plant_Coral_Block_Pink"
    },
    {
      "x": -3,
      "y": 9,
      "z": 3,
      "name": "Plant_Coral_Block_Pink"
    },
    {
      "x": -3,
      "y": 10,
      "z": 3,
      "name": "Plant_Coral_Block_Pink"
    },
    {
      "x": -3,
      "y": 11,
      "z": 3,
      "name": "Plant_Coral_Block_Pink"
    },
    {
      "x": -3,
      "y": 12,
      "z": 3,
      "name": "Plant_Coral_Bush_Pink"
    },
    {
      "x": -3,
      "y": 5,
      "z": 4,
      "name": "Plant_Coral_Block_Pink"
    },
    {
      "x": -3,
      "y": 6,
      "z": 4,
      "name": "Plant_Coral_Block_Pink"
    },
    {
      "x": -3,
      "y": 7,
      "z": 4,
      "name": "Plant_Coral_Block_Pink"
    },
    {
      "x": -3,
      "y": 8,
      "z": 4,
      "name": "Plant_Coral_Block_Pink"
    },
    {
      "x": -3,
      "y": 9,
      "z": 4,
      "name": "Plant_Coral_Block_Pink"
    },
    {
      "x": -3,
      "y": 10,
      "z": 4,
      "name": "Plant_Coral_Block_Pink"
    },
    {
      "x": -3,
      "y": 11,
      "z": 4,
      "name": "Plant_Coral_Block_Pink"
    },
    {
      "x": -3,
      "y": 5,
      "z": 5,
      "name": "Plant_Coral_Block_Pink"
    },
    {
      "x": -3,
      "y": 6,
      "z": 5,
      "name": "Plant_Coral_Block_Pink"
    },
    {
      "x": -3,
      "y": 7,
      "z": 5,
      "name": "Plant_Coral_Block_Pink"
    },
    {
      "x": -3,
      "y": 8,
      "z": 5,
      "name": "Plant_Coral_Block_Pink"
    },
    {
      "x": -3,
      "y": 9,
      "z": 5,
      "name": "Plant_Coral_Block_Pink"
    },
    {
      "x": -3,
      "y": 10,
      "z": 5,
      "name": "Plant_Coral_Block_Pink"
    },
    {
      "x": -3,
      "y": 11,
      "z": 5,
      "name": "Plant_Coral_Block_Pink"
    },
    {
      "x": -3,
      "y": 12,
      "z": 5,
      "name": "Plant_Coral_Bush_Pink"
    },
    {
      "x": -3,
      "y": 5,
      "z": 6,
      "name": "Plant_Coral_Block_Pink"
    },
    {
      "x": -3,
      "y": 6,
      "z": 6,
      "name": "Plant_Coral_Block_Pink"
    },
    {
      "x": -3,
      "y": 7,
      "z": 6,
      "name": "Plant_Coral_Block_Pink"
    },
    {
      "x": -3,
      "y": 8,
      "z": 6,
      "name": "Plant_Coral_Block_Pink"
    },
    {
      "x": -3,
      "y": 9,
      "z": 6,
      "name": "Plant_Coral_Block_Pink"
    },
    {
      "x": -3,
      "y": 10,
      "z": 6,
      "name": "Plant_Coral_Block_Pink"
    },
    {
      "x": -3,
      "y": 11,
      "z": 6,
      "name": "Plant_Coral_Block_Pink"
    },
    {
      "x": -3,
      "y": 6,
      "z": 7,
      "name": "Plant_Coral_Block_Pink"
    },
    {
      "x": -3,
      "y": 7,
      "z": 7,
      "name": "Plant_Coral_Block_Pink"
    },
    {
      "x": -3,
      "y": 8,
      "z": 7,
      "name": "Plant_Coral_Block_Pink"
    },
    {
      "x": -3,
      "y": 9,
      "z": 7,
      "name": "Plant_Coral_Block_Pink"
    },
    {
      "x": -3,
      "y": 10,
      "z": 7,
      "name": "Plant_Coral_Block_Violet"
    },
    {
      "x": -3,
      "y": 11,
      "z": 7,
      "name": "Plant_Coral_Block_Violet"
    },
    {
      "x": -3,
      "y": 7,
      "z": 8,
      "name": "Plant_Coral_Block_Pink"
    },
    {
      "x": -3,
      "y": 8,
      "z": 8,
      "name": "Plant_Coral_Block_Pink"
    },
    {
      "x": -3,
      "y": 9,
      "z": 8,
      "name": "Plant_Coral_Block_Pink"
    },
    {
      "x": -2,
      "y": 8,
      "z": -9,
      "name": "Plant_Coral_Block_Pink"
    },
    {
      "x": -2,
      "y": 6,
      "z": -8,
      "name": "Plant_Coral_Block_Pink"
    },
    {
      "x": -2,
      "y": 7,
      "z": -8,
      "name": "Plant_Coral_Block_Pink"
    },
    {
      "x": -2,
      "y": 8,
      "z": -8,
      "name": "Plant_Coral_Block_Pink"
    },
    {
      "x": -2,
      "y": 9,
      "z": -8,
      "name": "Plant_Coral_Block_Violet"
    },
    {
      "x": -2,
      "y": 10,
      "z": -8,
      "name": "Plant_Coral_Block_Violet"
    },
    {
      "x": -2,
      "y": 11,
      "z": -8,
      "name": "Plant_Coral_Block_Violet"
    },
    {
      "x": -2,
      "y": 6,
      "z": -7,
      "name": "Plant_Coral_Block_Pink"
    },
    {
      "x": -2,
      "y": 7,
      "z": -7,
      "name": "Plant_Coral_Block_Pink"
    },
    {
      "x": -2,
      "y": 8,
      "z": -7,
      "name": "Plant_Coral_Block_Pink"
    },
    {
      "x": -2,
      "y": 9,
      "z": -7,
      "name": "Plant_Coral_Block_Pink"
    },
    {
      "x": -2,
      "y": 10,
      "z": -7,
      "name": "Plant_Coral_Block_Violet"
    },
    {
      "x": -2,
      "y": 11,
      "z": -7,
      "name": "Plant_Coral_Block_Violet"
    },
    {
      "x": -2,
      "y": 5,
      "z": -6,
      "name": "Plant_Coral_Block_Pink"
    },
    {
      "x": -2,
      "y": 6,
      "z": -6,
      "name": "Plant_Coral_Block_Pink"
    },
    {
      "x": -2,
      "y": 7,
      "z": -6,
      "name": "Plant_Coral_Block_Pink"
    },
    {
      "x": -2,
      "y": 8,
      "z": -6,
      "name": "Plant_Coral_Block_Pink"
    },
    {
      "x": -2,
      "y": 9,
      "z": -6,
      "name": "Plant_Coral_Block_Pink"
    },
    {
      "x": -2,
      "y": 10,
      "z": -6,
      "name": "Plant_Coral_Block_Pink"
    },
    {
      "x": -2,
      "y": 11,
      "z": -6,
      "name": "Plant_Coral_Block_Pink"
    },
    {
      "x": -2,
      "y": 5,
      "z": -5,
      "name": "Plant_Coral_Block_Pink"
    },
    {
      "x": -2,
      "y": 6,
      "z": -5,
      "name": "Plant_Coral_Block_Pink"
    },
    {
      "x": -2,
      "y": 7,
      "z": -5,
      "name": "Plant_Coral_Block_Pink"
    },
    {
      "x": -2,
      "y": 8,
      "z": -5,
      "name": "Plant_Coral_Block_Pink"
    },
    {
      "x": -2,
      "y": 9,
      "z": -5,
      "name": "Plant_Coral_Block_Pink"
    },
    {
      "x": -2,
      "y": 10,
      "z": -5,
      "name": "Plant_Coral_Block_Pink"
    },
    {
      "x": -2,
      "y": 11,
      "z": -5,
      "name": "Plant_Coral_Block_Violet"
    },
    {
      "x": -2,
      "y": 12,
      "z": -5,
      "name": "Plant_Coral_Block_Violet"
    },
    {
      "x": -2,
      "y": 5,
      "z": -4,
      "name": "Plant_Coral_Block_Pink"
    },
    {
      "x": -2,
      "y": 6,
      "z": -4,
      "name": "Plant_Coral_Block_Pink"
    },
    {
      "x": -2,
      "y": 7,
      "z": -4,
      "name": "Plant_Coral_Block_Pink"
    },
    {
      "x": -2,
      "y": 8,
      "z": -4,
      "name": "Plant_Coral_Block_Pink"
    },
    {
      "x": -2,
      "y": 9,
      "z": -4,
      "name": "Plant_Coral_Block_Pink"
    },
    {
      "x": -2,
      "y": 10,
      "z": -4,
      "name": "Plant_Coral_Block_Pink"
    },
    {
      "x": -2,
      "y": 11,
      "z": -4,
      "name": "Plant_Coral_Block_Violet"
    },
    {
      "x": -2,
      "y": 12,
      "z": -4,
      "name": "Plant_Coral_Block_Violet"
    },
    {
      "x": -2,
      "y": 4,
      "z": -3,
      "name": "Plant_Coral_Block_Pink"
    },
    {
      "x": -2,
      "y": 5,
      "z": -3,
      "name": "Plant_Coral_Block_Pink"
    },
    {
      "x": -2,
      "y": 6,
      "z": -3,
      "name": "Plant_Coral_Block_Pink"
    },
    {
      "x": -2,
      "y": 7,
      "z": -3,
      "name": "Plant_Coral_Block_Pink"
    },
    {
      "x": -2,
      "y": 8,
      "z": -3,
      "name": "Plant_Coral_Block_Pink"
    },
    {
      "x": -2,
      "y": 9,
      "z": -3,
      "name": "Plant_Coral_Block_Pink"
    },
    {
      "x": -2,
      "y": 10,
      "z": -3,
      "name": "Plant_Coral_Block_Pink"
    },
    {
      "x": -2,
      "y": 11,
      "z": -3,
      "name": "Plant_Coral_Block_Pink"
    },
    {
      "x": -2,
      "y": 12,
      "z": -3,
      "name": "Plant_Coral_Block_Violet"
    },
    {
      "x": -2,
      "y": 13,
      "z": -3,
      "name": "Plant_Coral_Block_Violet"
    },
    {
      "x": -2,
      "y": 4,
      "z": -2,
      "name": "Plant_Coral_Block_Pink"
    },
    {
      "x": -2,
      "y": 5,
      "z": -2,
      "name": "Plant_Coral_Block_Pink"
    },
    {
      "x": -2,
      "y": 6,
      "z": -2,
      "name": "Plant_Coral_Block_Pink"
    },
    {
      "x": -2,
      "y": 7,
      "z": -2,
      "name": "Plant_Coral_Block_Pink"
    },
    {
      "x": -2,
      "y": 8,
      "z": -2,
      "name": "Plant_Coral_Block_Pink"
    },
    {
      "x": -2,
      "y": 9,
      "z": -2,
      "name": "Plant_Coral_Block_Pink"
    },
    {
      "x": -2,
      "y": 10,
      "z": -2,
      "name": "Plant_Coral_Block_Pink"
    },
    {
      "x": -2,
      "y": 11,
      "z": -2,
      "name": "Plant_Coral_Block_Pink"
    },
    {
      "x": -2,
      "y": 12,
      "z": -2,
      "name": "Plant_Coral_Block_Violet"
    },
    {
      "x": -2,
      "y": 13,
      "z": -2,
      "name": "Plant_Coral_Block_Violet"
    },
    {
      "x": -2,
      "y": 4,
      "z": -1,
      "name": "Plant_Coral_Block_Pink"
    },
    {
      "x": -2,
      "y": 5,
      "z": -1,
      "name": "Plant_Coral_Block_Pink"
    },
    {
      "x": -2,
      "y": 6,
      "z": -1,
      "name": "Plant_Coral_Block_Pink"
    },
    {
      "x": -2,
      "y": 7,
      "z": -1,
      "name": "Plant_Coral_Block_Pink"
    },
    {
      "x": -2,
      "y": 8,
      "z": -1,
      "name": "Plant_Coral_Block_Pink"
    },
    {
      "x": -2,
      "y": 9,
      "z": -1,
      "name": "Plant_Coral_Block_Pink"
    },
    {
      "x": -2,
      "y": 10,
      "z": -1,
      "name": "Plant_Coral_Block_Pink"
    },
    {
      "x": -2,
      "y": 11,
      "z": -1,
      "name": "Plant_Coral_Block_Pink"
    },
    {
      "x": -2,
      "y": 12,
      "z": -1,
      "name": "Plant_Coral_Block_Violet"
    },
    {
      "x": -2,
      "y": 13,
      "z": -1,
      "name": "Plant_Coral_Block_Violet"
    },
    {
      "x": -2,
      "y": 4,
      "z": 0,
      "name": "Plant_Coral_Block_Pink"
    },
    {
      "x": -2,
      "y": 5,
      "z": 0,
      "name": "Plant_Coral_Block_Pink"
    },
    {
      "x": -2,
      "y": 6,
      "z": 0,
      "name": "Plant_Coral_Block_Pink"
    },
    {
      "x": -2,
      "y": 7,
      "z": 0,
      "name": "Plant_Coral_Block_Pink"
    },
    {
      "x": -2,
      "y": 8,
      "z": 0,
      "name": "Plant_Coral_Block_Pink"
    },
    {
      "x": -2,
      "y": 9,
      "z": 0,
      "name": "Plant_Coral_Block_Pink"
    },
    {
      "x": -2,
      "y": 10,
      "z": 0,
      "name": "Plant_Coral_Block_Pink"
    },
    {
      "x": -2,
      "y": 11,
      "z": 0,
      "name": "Plant_Coral_Block_Pink"
    },
    {
      "x": -2,
      "y": 12,
      "z": 0,
      "name": "Plant_Coral_Block_Violet"
    },
    {
      "x": -2,
      "y": 13,
      "z": 0,
      "name": "Plant_Coral_Block_Violet"
    },
    {
      "x": -2,
      "y": 4,
      "z": 1,
      "name": "Plant_Coral_Block_Pink"
    },
    {
      "x": -2,
      "y": 5,
      "z": 1,
      "name": "Plant_Coral_Block_Pink"
    },
    {
      "x": -2,
      "y": 6,
      "z": 1,
      "name": "Plant_Coral_Block_Pink"
    },
    {
      "x": -2,
      "y": 7,
      "z": 1,
      "name": "Plant_Coral_Block_Pink"
    },
    {
      "x": -2,
      "y": 8,
      "z": 1,
      "name": "Plant_Coral_Block_Pink"
    },
    {
      "x": -2,
      "y": 9,
      "z": 1,
      "name": "Plant_Coral_Block_Pink"
    },
    {
      "x": -2,
      "y": 10,
      "z": 1,
      "name": "Plant_Coral_Block_Pink"
    },
    {
      "x": -2,
      "y": 11,
      "z": 1,
      "name": "Plant_Coral_Block_Pink"
    },
    {
      "x": -2,
      "y": 12,
      "z": 1,
      "name": "Plant_Coral_Block_Pink"
    },
    {
      "x": -2,
      "y": 4,
      "z": 2,
      "name": "Plant_Coral_Block_Pink"
    },
    {
      "x": -2,
      "y": 5,
      "z": 2,
      "name": "Plant_Coral_Block_Pink"
    },
    {
      "x": -2,
      "y": 6,
      "z": 2,
      "name": "Plant_Coral_Block_Pink"
    },
    {
      "x": -2,
      "y": 7,
      "z": 2,
      "name": "Plant_Coral_Block_Pink"
    },
    {
      "x": -2,
      "y": 8,
      "z": 2,
      "name": "Plant_Coral_Block_Pink"
    },
    {
      "x": -2,
      "y": 9,
      "z": 2,
      "name": "Plant_Coral_Block_Pink"
    },
    {
      "x": -2,
      "y": 10,
      "z": 2,
      "name": "Plant_Coral_Block_Pink"
    },
    {
      "x": -2,
      "y": 11,
      "z": 2,
      "name": "Plant_Coral_Block_Pink"
    },
    {
      "x": -2,
      "y": 12,
      "z": 2,
      "name": "Plant_Coral_Block_Violet"
    },
    {
      "x": -2,
      "y": 13,
      "z": 2,
      "name": "Plant_Coral_Block_Violet"
    },
    {
      "x": -2,
      "y": 4,
      "z": 3,
      "name": "Plant_Coral_Block_Pink"
    },
    {
      "x": -2,
      "y": 5,
      "z": 3,
      "name": "Plant_Coral_Block_Pink"
    },
    {
      "x": -2,
      "y": 6,
      "z": 3,
      "name": "Plant_Coral_Block_Pink"
    },
    {
      "x": -2,
      "y": 7,
      "z": 3,
      "name": "Plant_Coral_Block_Pink"
    },
    {
      "x": -2,
      "y": 8,
      "z": 3,
      "name": "Plant_Coral_Block_Pink"
    },
    {
      "x": -2,
      "y": 9,
      "z": 3,
      "name": "Plant_Coral_Block_Pink"
    },
    {
      "x": -2,
      "y": 10,
      "z": 3,
      "name": "Plant_Coral_Block_Pink"
    },
    {
      "x": -2,
      "y": 11,
      "z": 3,
      "name": "Plant_Coral_Block_Pink"
    },
    {
      "x": -2,
      "y": 12,
      "z": 3,
      "name": "Plant_Coral_Block_Violet"
    },
    {
      "x": -2,
      "y": 13,
      "z": 3,
      "name": "Plant_Coral_Block_Violet"
    },
    {
      "x": -2,
      "y": 5,
      "z": 4,
      "name": "Plant_Coral_Block_Pink"
    },
    {
      "x": -2,
      "y": 6,
      "z": 4,
      "name": "Plant_Coral_Block_Pink"
    },
    {
      "x": -2,
      "y": 7,
      "z": 4,
      "name": "Plant_Coral_Block_Pink"
    },
    {
      "x": -2,
      "y": 8,
      "z": 4,
      "name": "Plant_Coral_Block_Pink"
    },
    {
      "x": -2,
      "y": 9,
      "z": 4,
      "name": "Plant_Coral_Block_Pink"
    },
    {
      "x": -2,
      "y": 10,
      "z": 4,
      "name": "Plant_Coral_Block_Pink"
    },
    {
      "x": -2,
      "y": 11,
      "z": 4,
      "name": "Plant_Coral_Block_Violet"
    },
    {
      "x": -2,
      "y": 12,
      "z": 4,
      "name": "Plant_Coral_Block_Violet"
    },
    {
      "x": -2,
      "y": 5,
      "z": 5,
      "name": "Plant_Coral_Block_Pink"
    },
    {
      "x": -2,
      "y": 6,
      "z": 5,
      "name": "Plant_Coral_Block_Pink"
    },
    {
      "x": -2,
      "y": 7,
      "z": 5,
      "name": "Plant_Coral_Block_Pink"
    },
    {
      "x": -2,
      "y": 8,
      "z": 5,
      "name": "Plant_Coral_Block_Pink"
    },
    {
      "x": -2,
      "y": 9,
      "z": 5,
      "name": "Plant_Coral_Block_Pink"
    },
    {
      "x": -2,
      "y": 10,
      "z": 5,
      "name": "Plant_Coral_Block_Pink"
    },
    {
      "x": -2,
      "y": 11,
      "z": 5,
      "name": "Plant_Coral_Block_Violet"
    },
    {
      "x": -2,
      "y": 12,
      "z": 5,
      "name": "Plant_Coral_Block_Violet"
    },
    {
      "x": -2,
      "y": 5,
      "z": 6,
      "name": "Plant_Coral_Block_Pink"
    },
    {
      "x": -2,
      "y": 6,
      "z": 6,
      "name": "Plant_Coral_Block_Pink"
    },
    {
      "x": -2,
      "y": 7,
      "z": 6,
      "name": "Plant_Coral_Block_Pink"
    },
    {
      "x": -2,
      "y": 8,
      "z": 6,
      "name": "Plant_Coral_Block_Pink"
    },
    {
      "x": -2,
      "y": 9,
      "z": 6,
      "name": "Plant_Coral_Block_Pink"
    },
    {
      "x": -2,
      "y": 10,
      "z": 6,
      "name": "Plant_Coral_Block_Pink"
    },
    {
      "x": -2,
      "y": 11,
      "z": 6,
      "name": "Plant_Coral_Block_Pink"
    },
    {
      "x": -2,
      "y": 6,
      "z": 7,
      "name": "Plant_Coral_Block_Pink"
    },
    {
      "x": -2,
      "y": 7,
      "z": 7,
      "name": "Plant_Coral_Block_Pink"
    },
    {
      "x": -2,
      "y": 8,
      "z": 7,
      "name": "Plant_Coral_Block_Pink"
    },
    {
      "x": -2,
      "y": 9,
      "z": 7,
      "name": "Plant_Coral_Block_Pink"
    },
    {
      "x": -2,
      "y": 10,
      "z": 7,
      "name": "Plant_Coral_Block_Violet"
    },
    {
      "x": -2,
      "y": 11,
      "z": 7,
      "name": "Plant_Coral_Block_Violet"
    },
    {
      "x": -2,
      "y": 6,
      "z": 8,
      "name": "Plant_Coral_Block_Pink"
    },
    {
      "x": -2,
      "y": 7,
      "z": 8,
      "name": "Plant_Coral_Block_Pink"
    },
    {
      "x": -2,
      "y": 8,
      "z": 8,
      "name": "Plant_Coral_Block_Pink"
    },
    {
      "x": -2,
      "y": 9,
      "z": 8,
      "name": "Plant_Coral_Block_Pink"
    },
    {
      "x": -2,
      "y": 10,
      "z": 8,
      "name": "Plant_Coral_Block_Violet"
    },
    {
      "x": -2,
      "y": 11,
      "z": 8,
      "name": "Plant_Coral_Block_Violet"
    },
    {
      "x": -2,
      "y": 8,
      "z": 9,
      "name": "Plant_Coral_Block_Pink"
    },
    {
      "x": -1,
      "y": 7,
      "z": -9,
      "name": "Plant_Coral_Block_Pink"
    },
    {
      "x": -1,
      "y": 8,
      "z": -9,
      "name": "Plant_Coral_Block_Pink"
    },
    {
      "x": -1,
      "y": 9,
      "z": -9,
      "name": "Plant_Coral_Block_Violet"
    },
    {
      "x": -1,
      "y": 10,
      "z": -9,
      "name": "Plant_Coral_Block_Violet"
    },
    {
      "x": -1,
      "y": 6,
      "z": -8,
      "name": "Plant_Coral_Block_Pink"
    },
    {
      "x": -1,
      "y": 7,
      "z": -8,
      "name": "Plant_Coral_Block_Pink"
    },
    {
      "x": -1,
      "y": 8,
      "z": -8,
      "name": "Plant_Coral_Block_Pink"
    },
    {
      "x": -1,
      "y": 9,
      "z": -8,
      "name": "Plant_Coral_Block_Pink"
    },
    {
      "x": -1,
      "y": 10,
      "z": -8,
      "name": "Plant_Coral_Block_Pink"
    },
    {
      "x": -1,
      "y": 11,
      "z": -8,
      "name": "Plant_Coral_Bush_Pink"
    },
    {
      "x": -1,
      "y": 6,
      "z": -7,
      "name": "Plant_Coral_Block_Pink"
    },
    {
      "x": -1,
      "y": 7,
      "z": -7,
      "name": "Plant_Coral_Block_Pink"
    },
    {
      "x": -1,
      "y": 8,
      "z": -7,
      "name": "Plant_Coral_Block_Pink"
    },
    {
      "x": -1,
      "y": 9,
      "z": -7,
      "name": "Plant_Coral_Block_Pink"
    },
    {
      "x": -1,
      "y": 10,
      "z": -7,
      "name": "Plant_Coral_Block_Violet"
    },
    {
      "x": -1,
      "y": 11,
      "z": -7,
      "name": "Plant_Coral_Block_Violet"
    },
    {
      "x": -1,
      "y": 5,
      "z": -6,
      "name": "Plant_Coral_Block_Pink"
    },
    {
      "x": -1,
      "y": 6,
      "z": -6,
      "name": "Plant_Coral_Block_Pink"
    },
    {
      "x": -1,
      "y": 7,
      "z": -6,
      "name": "Plant_Coral_Block_Pink"
    },
    {
      "x": -1,
      "y": 8,
      "z": -6,
      "name": "Plant_Coral_Block_Pink"
    },
    {
      "x": -1,
      "y": 9,
      "z": -6,
      "name": "Plant_Coral_Block_Pink"
    },
    {
      "x": -1,
      "y": 10,
      "z": -6,
      "name": "Plant_Coral_Block_Pink"
    },
    {
      "x": -1,
      "y": 11,
      "z": -6,
      "name": "Plant_Coral_Block_Pink"
    },
    {
      "x": -1,
      "y": 12,
      "z": -6,
      "name": "Plant_Coral_Bush_Pink"
    },
    {
      "x": -1,
      "y": 5,
      "z": -5,
      "name": "Plant_Coral_Block_Pink"
    },
    {
      "x": -1,
      "y": 6,
      "z": -5,
      "name": "Plant_Coral_Block_Pink"
    },
    {
      "x": -1,
      "y": 7,
      "z": -5,
      "name": "Plant_Coral_Block_Pink"
    },
    {
      "x": -1,
      "y": 8,
      "z": -5,
      "name": "Plant_Coral_Block_Pink"
    },
    {
      "x": -1,
      "y": 9,
      "z": -5,
      "name": "Plant_Coral_Block_Pink"
    },
    {
      "x": -1,
      "y": 10,
      "z": -5,
      "name": "Plant_Coral_Block_Pink"
    },
    {
      "x": -1,
      "y": 11,
      "z": -5,
      "name": "Plant_Coral_Block_Pink"
    },
    {
      "x": -1,
      "y": 5,
      "z": -4,
      "name": "Plant_Coral_Block_Pink"
    },
    {
      "x": -1,
      "y": 6,
      "z": -4,
      "name": "Plant_Coral_Block_Pink"
    },
    {
      "x": -1,
      "y": 7,
      "z": -4,
      "name": "Plant_Coral_Block_Pink"
    },
    {
      "x": -1,
      "y": 8,
      "z": -4,
      "name": "Plant_Coral_Block_Pink"
    },
    {
      "x": -1,
      "y": 9,
      "z": -4,
      "name": "Plant_Coral_Block_Pink"
    },
    {
      "x": -1,
      "y": 10,
      "z": -4,
      "name": "Plant_Coral_Block_Pink"
    },
    {
      "x": -1,
      "y": 11,
      "z": -4,
      "name": "Plant_Coral_Block_Pink"
    },
    {
      "x": -1,
      "y": 4,
      "z": -3,
      "name": "Plant_Coral_Block_Pink"
    },
    {
      "x": -1,
      "y": 5,
      "z": -3,
      "name": "Plant_Coral_Block_Pink"
    },
    {
      "x": -1,
      "y": 6,
      "z": -3,
      "name": "Plant_Coral_Block_Pink"
    },
    {
      "x": -1,
      "y": 7,
      "z": -3,
      "name": "Plant_Coral_Block_Pink"
    },
    {
      "x": -1,
      "y": 8,
      "z": -3,
      "name": "Plant_Coral_Block_Pink"
    },
    {
      "x": -1,
      "y": 9,
      "z": -3,
      "name": "Plant_Coral_Block_Pink"
    },
    {
      "x": -1,
      "y": 10,
      "z": -3,
      "name": "Plant_Coral_Block_Pink"
    },
    {
      "x": -1,
      "y": 11,
      "z": -3,
      "name": "Plant_Coral_Block_Pink"
    },
    {
      "x": -1,
      "y": 12,
      "z": -3,
      "name": "Plant_Coral_Block_Pink"
    },
    {
      "x": -1,
      "y": 4,
      "z": -2,
      "name": "Plant_Coral_Block_Pink"
    },
    {
      "x": -1,
      "y": 5,
      "z": -2,
      "name": "Plant_Coral_Block_Pink"
    },
    {
      "x": -1,
      "y": 6,
      "z": -2,
      "name": "Plant_Coral_Block_Pink"
    },
    {
      "x": -1,
      "y": 7,
      "z": -2,
      "name": "Plant_Coral_Block_Pink"
    },
    {
      "x": -1,
      "y": 8,
      "z": -2,
      "name": "Plant_Coral_Block_Pink"
    },
    {
      "x": -1,
      "y": 9,
      "z": -2,
      "name": "Plant_Coral_Block_Pink"
    },
    {
      "x": -1,
      "y": 10,
      "z": -2,
      "name": "Plant_Coral_Block_Pink"
    },
    {
      "x": -1,
      "y": 11,
      "z": -2,
      "name": "Plant_Coral_Block_Pink"
    },
    {
      "x": -1,
      "y": 12,
      "z": -2,
      "name": "Plant_Coral_Block_Pink"
    },
    {
      "x": -1,
      "y": 4,
      "z": -1,
      "name": "Plant_Coral_Block_Pink"
    },
    {
      "x": -1,
      "y": 5,
      "z": -1,
      "name": "Plant_Coral_Block_Pink"
    },
    {
      "x": -1,
      "y": 6,
      "z": -1,
      "name": "Plant_Coral_Block_Pink"
    },
    {
      "x": -1,
      "y": 7,
      "z": -1,
      "name": "Plant_Coral_Block_Pink"
    },
    {
      "x": -1,
      "y": 8,
      "z": -1,
      "name": "Plant_Coral_Block_Pink"
    },
    {
      "x": -1,
      "y": 9,
      "z": -1,
      "name": "Plant_Coral_Block_Pink"
    },
    {
      "x": -1,
      "y": 10,
      "z": -1,
      "name": "Plant_Coral_Block_Pink"
    },
    {
      "x": -1,
      "y": 11,
      "z": -1,
      "name": "Plant_Coral_Block_Pink"
    },
    {
      "x": -1,
      "y": 12,
      "z": -1,
      "name": "Plant_Coral_Block_Pink"
    },
    {
      "x": -1,
      "y": 4,
      "z": 0,
      "name": "Plant_Coral_Block_Pink"
    },
    {
      "x": -1,
      "y": 5,
      "z": 0,
      "name": "Plant_Coral_Block_Pink"
    },
    {
      "x": -1,
      "y": 6,
      "z": 0,
      "name": "Plant_Coral_Block_Pink"
    },
    {
      "x": -1,
      "y": 7,
      "z": 0,
      "name": "Plant_Coral_Block_Pink"
    },
    {
      "x": -1,
      "y": 8,
      "z": 0,
      "name": "Plant_Coral_Block_Pink"
    },
    {
      "x": -1,
      "y": 9,
      "z": 0,
      "name": "Plant_Coral_Block_Pink"
    },
    {
      "x": -1,
      "y": 10,
      "z": 0,
      "name": "Plant_Coral_Block_Pink"
    },
    {
      "x": -1,
      "y": 11,
      "z": 0,
      "name": "Plant_Coral_Block_Pink"
    },
    {
      "x": -1,
      "y": 12,
      "z": 0,
      "name": "Plant_Coral_Block_Violet"
    },
    {
      "x": -1,
      "y": 13,
      "z": 0,
      "name": "Plant_Coral_Block_Violet"
    },
    {
      "x": -1,
      "y": 4,
      "z": 1,
      "name": "Plant_Coral_Block_Pink"
    },
    {
      "x": -1,
      "y": 5,
      "z": 1,
      "name": "Plant_Coral_Block_Pink"
    },
    {
      "x": -1,
      "y": 6,
      "z": 1,
      "name": "Plant_Coral_Block_Pink"
    },
    {
      "x": -1,
      "y": 7,
      "z": 1,
      "name": "Plant_Coral_Block_Pink"
    },
    {
      "x": -1,
      "y": 8,
      "z": 1,
      "name": "Plant_Coral_Block_Pink"
    },
    {
      "x": -1,
      "y": 9,
      "z": 1,
      "name": "Plant_Coral_Block_Pink"
    },
    {
      "x": -1,
      "y": 10,
      "z": 1,
      "name": "Plant_Coral_Block_Pink"
    },
    {
      "x": -1,
      "y": 11,
      "z": 1,
      "name": "Plant_Coral_Block_Pink"
    },
    {
      "x": -1,
      "y": 12,
      "z": 1,
      "name": "Plant_Coral_Block_Pink"
    },
    {
      "x": -1,
      "y": 13,
      "z": 1,
      "name": "Plant_Coral_Bush_Pink"
    },
    {
      "x": -1,
      "y": 4,
      "z": 2,
      "name": "Plant_Coral_Block_Pink"
    },
    {
      "x": -1,
      "y": 5,
      "z": 2,
      "name": "Plant_Coral_Block_Pink"
    },
    {
      "x": -1,
      "y": 6,
      "z": 2,
      "name": "Plant_Coral_Block_Pink"
    },
    {
      "x": -1,
      "y": 7,
      "z": 2,
      "name": "Plant_Coral_Block_Pink"
    },
    {
      "x": -1,
      "y": 8,
      "z": 2,
      "name": "Plant_Coral_Block_Pink"
    },
    {
      "x": -1,
      "y": 9,
      "z": 2,
      "name": "Plant_Coral_Block_Pink"
    },
    {
      "x": -1,
      "y": 10,
      "z": 2,
      "name": "Plant_Coral_Block_Pink"
    },
    {
      "x": -1,
      "y": 11,
      "z": 2,
      "name": "Plant_Coral_Block_Pink"
    },
    {
      "x": -1,
      "y": 12,
      "z": 2,
      "name": "Plant_Coral_Block_Pink"
    },
    {
      "x": -1,
      "y": 4,
      "z": 3,
      "name": "Plant_Coral_Block_Pink"
    },
    {
      "x": -1,
      "y": 5,
      "z": 3,
      "name": "Plant_Coral_Block_Pink"
    },
    {
      "x": -1,
      "y": 6,
      "z": 3,
      "name": "Plant_Coral_Block_Pink"
    },
    {
      "x": -1,
      "y": 7,
      "z": 3,
      "name": "Plant_Coral_Block_Pink"
    },
    {
      "x": -1,
      "y": 8,
      "z": 3,
      "name": "Plant_Coral_Block_Pink"
    },
    {
      "x": -1,
      "y": 9,
      "z": 3,
      "name": "Plant_Coral_Block_Pink"
    },
    {
      "x": -1,
      "y": 10,
      "z": 3,
      "name": "Plant_Coral_Block_Pink"
    },
    {
      "x": -1,
      "y": 11,
      "z": 3,
      "name": "Plant_Coral_Block_Pink"
    },
    {
      "x": -1,
      "y": 12,
      "z": 3,
      "name": "Plant_Coral_Block_Pink"
    },
    {
      "x": -1,
      "y": 13,
      "z": 3,
      "name": "Plant_Coral_Bush_Pink"
    },
    {
      "x": -1,
      "y": 5,
      "z": 4,
      "name": "Plant_Coral_Block_Pink"
    },
    {
      "x": -1,
      "y": 6,
      "z": 4,
      "name": "Plant_Coral_Block_Pink"
    },
    {
      "x": -1,
      "y": 7,
      "z": 4,
      "name": "Plant_Coral_Block_Pink"
    },
    {
      "x": -1,
      "y": 8,
      "z": 4,
      "name": "Plant_Coral_Block_Pink"
    },
    {
      "x": -1,
      "y": 9,
      "z": 4,
      "name": "Plant_Coral_Block_Pink"
    },
    {
      "x": -1,
      "y": 10,
      "z": 4,
      "name": "Plant_Coral_Block_Pink"
    },
    {
      "x": -1,
      "y": 11,
      "z": 4,
      "name": "Plant_Coral_Block_Pink"
    },
    {
      "x": -1,
      "y": 5,
      "z": 5,
      "name": "Plant_Coral_Block_Pink"
    },
    {
      "x": -1,
      "y": 6,
      "z": 5,
      "name": "Plant_Coral_Block_Pink"
    },
    {
      "x": -1,
      "y": 7,
      "z": 5,
      "name": "Plant_Coral_Block_Pink"
    },
    {
      "x": -1,
      "y": 8,
      "z": 5,
      "name": "Plant_Coral_Block_Pink"
    },
    {
      "x": -1,
      "y": 9,
      "z": 5,
      "name": "Plant_Coral_Block_Pink"
    },
    {
      "x": -1,
      "y": 10,
      "z": 5,
      "name": "Plant_Coral_Block_Pink"
    },
    {
      "x": -1,
      "y": 11,
      "z": 5,
      "name": "Plant_Coral_Block_Violet"
    },
    {
      "x": -1,
      "y": 12,
      "z": 5,
      "name": "Plant_Coral_Block_Violet"
    },
    {
      "x": -1,
      "y": 5,
      "z": 6,
      "name": "Plant_Coral_Block_Pink"
    },
    {
      "x": -1,
      "y": 6,
      "z": 6,
      "name": "Plant_Coral_Block_Pink"
    },
    {
      "x": -1,
      "y": 7,
      "z": 6,
      "name": "Plant_Coral_Block_Pink"
    },
    {
      "x": -1,
      "y": 8,
      "z": 6,
      "name": "Plant_Coral_Block_Pink"
    },
    {
      "x": -1,
      "y": 9,
      "z": 6,
      "name": "Plant_Coral_Block_Pink"
    },
    {
      "x": -1,
      "y": 10,
      "z": 6,
      "name": "Plant_Coral_Block_Pink"
    },
    {
      "x": -1,
      "y": 11,
      "z": 6,
      "name": "Plant_Coral_Block_Pink"
    },
    {
      "x": -1,
      "y": 12,
      "z": 6,
      "name": "Plant_Coral_Bush_Pink"
    },
    {
      "x": -1,
      "y": 6,
      "z": 7,
      "name": "Plant_Coral_Block_Pink"
    },
    {
      "x": -1,
      "y": 7,
      "z": 7,
      "name": "Plant_Coral_Block_Pink"
    },
    {
      "x": -1,
      "y": 8,
      "z": 7,
      "name": "Plant_Coral_Block_Pink"
    },
    {
      "x": -1,
      "y": 9,
      "z": 7,
      "name": "Plant_Coral_Block_Pink"
    },
    {
      "x": -1,
      "y": 10,
      "z": 7,
      "name": "Plant_Coral_Block_Pink"
    },
    {
      "x": -1,
      "y": 11,
      "z": 7,
      "name": "Plant_Coral_Bush_Pink"
    },
    {
      "x": -1,
      "y": 6,
      "z": 8,
      "name": "Plant_Coral_Block_Pink"
    },
    {
      "x": -1,
      "y": 7,
      "z": 8,
      "name": "Plant_Coral_Block_Pink"
    },
    {
      "x": -1,
      "y": 8,
      "z": 8,
      "name": "Plant_Coral_Block_Pink"
    },
    {
      "x": -1,
      "y": 9,
      "z": 8,
      "name": "Plant_Coral_Block_Pink"
    },
    {
      "x": -1,
      "y": 10,
      "z": 8,
      "name": "Plant_Coral_Block_Violet"
    },
    {
      "x": -1,
      "y": 11,
      "z": 8,
      "name": "Plant_Coral_Block_Violet"
    },
    {
      "x": -1,
      "y": 7,
      "z": 9,
      "name": "Plant_Coral_Block_Pink"
    },
    {
      "x": -1,
      "y": 8,
      "z": 9,
      "name": "Plant_Coral_Block_Pink"
    },
    {
      "x": -1,
      "y": 9,
      "z": 9,
      "name": "Plant_Coral_Block_Violet"
    },
    {
      "x": -1,
      "y": 10,
      "z": 9,
      "name": "Plant_Coral_Block_Violet"
    },
    {
      "x": 0,
      "y": 7,
      "z": -9,
      "name": "Plant_Coral_Block_Pink"
    },
    {
      "x": 0,
      "y": 8,
      "z": -9,
      "name": "Plant_Coral_Block_Pink"
    },
    {
      "x": 0,
      "y": 9,
      "z": -9,
      "name": "Plant_Coral_Block_Violet"
    },
    {
      "x": 0,
      "y": 10,
      "z": -9,
      "name": "Plant_Coral_Block_Violet"
    },
    {
      "x": 0,
      "y": 6,
      "z": -8,
      "name": "Plant_Coral_Block_Pink"
    },
    {
      "x": 0,
      "y": 7,
      "z": -8,
      "name": "Plant_Coral_Block_Pink"
    },
    {
      "x": 0,
      "y": 8,
      "z": -8,
      "name": "Plant_Coral_Block_Pink"
    },
    {
      "x": 0,
      "y": 9,
      "z": -8,
      "name": "Plant_Coral_Block_Pink"
    },
    {
      "x": 0,
      "y": 10,
      "z": -8,
      "name": "Plant_Coral_Block_Pink"
    },
    {
      "x": 0,
      "y": 11,
      "z": -8,
      "name": "Plant_Coral_Bush_Pink"
    },
    {
      "x": 0,
      "y": 6,
      "z": -7,
      "name": "Plant_Coral_Block_Pink"
    },
    {
      "x": 0,
      "y": 7,
      "z": -7,
      "name": "Plant_Coral_Block_Pink"
    },
    {
      "x": 0,
      "y": 8,
      "z": -7,
      "name": "Plant_Coral_Block_Pink"
    },
    {
      "x": 0,
      "y": 9,
      "z": -7,
      "name": "Plant_Coral_Block_Pink"
    },
    {
      "x": 0,
      "y": 10,
      "z": -7,
      "name": "Plant_Coral_Block_Violet"
    },
    {
      "x": 0,
      "y": 11,
      "z": -7,
      "name": "Plant_Coral_Block_Violet"
    },
    {
      "x": 0,
      "y": 5,
      "z": -6,
      "name": "Plant_Coral_Block_Pink"
    },
    {
      "x": 0,
      "y": 6,
      "z": -6,
      "name": "Plant_Coral_Block_Pink"
    },
    {
      "x": 0,
      "y": 7,
      "z": -6,
      "name": "Plant_Coral_Block_Pink"
    },
    {
      "x": 0,
      "y": 8,
      "z": -6,
      "name": "Plant_Coral_Block_Pink"
    },
    {
      "x": 0,
      "y": 9,
      "z": -6,
      "name": "Plant_Coral_Block_Pink"
    },
    {
      "x": 0,
      "y": 10,
      "z": -6,
      "name": "Plant_Coral_Block_Pink"
    },
    {
      "x": 0,
      "y": 11,
      "z": -6,
      "name": "Plant_Coral_Block_Pink"
    },
    {
      "x": 0,
      "y": 12,
      "z": -6,
      "name": "Plant_Coral_Bush_Pink"
    },
    {
      "x": 0,
      "y": 5,
      "z": -5,
      "name": "Plant_Coral_Block_Pink"
    },
    {
      "x": 0,
      "y": 6,
      "z": -5,
      "name": "Plant_Coral_Block_Pink"
    },
    {
      "x": 0,
      "y": 7,
      "z": -5,
      "name": "Plant_Coral_Block_Pink"
    },
    {
      "x": 0,
      "y": 8,
      "z": -5,
      "name": "Plant_Coral_Block_Pink"
    },
    {
      "x": 0,
      "y": 9,
      "z": -5,
      "name": "Plant_Coral_Block_Pink"
    },
    {
      "x": 0,
      "y": 10,
      "z": -5,
      "name": "Plant_Coral_Block_Pink"
    },
    {
      "x": 0,
      "y": 11,
      "z": -5,
      "name": "Plant_Coral_Block_Pink"
    },
    {
      "x": 0,
      "y": 5,
      "z": -4,
      "name": "Plant_Coral_Block_Pink"
    },
    {
      "x": 0,
      "y": 6,
      "z": -4,
      "name": "Plant_Coral_Block_Pink"
    },
    {
      "x": 0,
      "y": 7,
      "z": -4,
      "name": "Plant_Coral_Block_Pink"
    },
    {
      "x": 0,
      "y": 8,
      "z": -4,
      "name": "Plant_Coral_Block_Pink"
    },
    {
      "x": 0,
      "y": 9,
      "z": -4,
      "name": "Plant_Coral_Block_Pink"
    },
    {
      "x": 0,
      "y": 10,
      "z": -4,
      "name": "Plant_Coral_Block_Pink"
    },
    {
      "x": 0,
      "y": 11,
      "z": -4,
      "name": "Plant_Coral_Block_Violet"
    },
    {
      "x": 0,
      "y": 12,
      "z": -4,
      "name": "Plant_Coral_Block_Violet"
    },
    {
      "x": 0,
      "y": 4,
      "z": -3,
      "name": "Plant_Coral_Block_Pink"
    },
    {
      "x": 0,
      "y": 5,
      "z": -3,
      "name": "Plant_Coral_Block_Pink"
    },
    {
      "x": 0,
      "y": 6,
      "z": -3,
      "name": "Plant_Coral_Block_Pink"
    },
    {
      "x": 0,
      "y": 7,
      "z": -3,
      "name": "Plant_Coral_Block_Pink"
    },
    {
      "x": 0,
      "y": 8,
      "z": -3,
      "name": "Plant_Coral_Block_Pink"
    },
    {
      "x": 0,
      "y": 9,
      "z": -3,
      "name": "Plant_Coral_Block_Pink"
    },
    {
      "x": 0,
      "y": 10,
      "z": -3,
      "name": "Plant_Coral_Block_Pink"
    },
    {
      "x": 0,
      "y": 11,
      "z": -3,
      "name": "Plant_Coral_Block_Pink"
    },
    {
      "x": 0,
      "y": 12,
      "z": -3,
      "name": "Plant_Coral_Block_Violet"
    },
    {
      "x": 0,
      "y": 13,
      "z": -3,
      "name": "Plant_Coral_Block_Violet"
    },
    {
      "x": 0,
      "y": 4,
      "z": -2,
      "name": "Plant_Coral_Block_Pink"
    },
    {
      "x": 0,
      "y": 5,
      "z": -2,
      "name": "Plant_Coral_Block_Pink"
    },
    {
      "x": 0,
      "y": 6,
      "z": -2,
      "name": "Plant_Coral_Block_Pink"
    },
    {
      "x": 0,
      "y": 7,
      "z": -2,
      "name": "Plant_Coral_Block_Pink"
    },
    {
      "x": 0,
      "y": 8,
      "z": -2,
      "name": "Plant_Coral_Block_Pink"
    },
    {
      "x": 0,
      "y": 9,
      "z": -2,
      "name": "Plant_Coral_Block_Pink"
    },
    {
      "x": 0,
      "y": 10,
      "z": -2,
      "name": "Plant_Coral_Block_Pink"
    },
    {
      "x": 0,
      "y": 11,
      "z": -2,
      "name": "Plant_Coral_Block_Pink"
    },
    {
      "x": 0,
      "y": 12,
      "z": -2,
      "name": "Plant_Coral_Block_Violet"
    },
    {
      "x": 0,
      "y": 13,
      "z": -2,
      "name": "Plant_Coral_Block_Violet"
    },
    {
      "x": 0,
      "y": 4,
      "z": -1,
      "name": "Plant_Coral_Block_Pink"
    },
    {
      "x": 0,
      "y": 5,
      "z": -1,
      "name": "Plant_Coral_Block_Pink"
    },
    {
      "x": 0,
      "y": 6,
      "z": -1,
      "name": "Plant_Coral_Block_Pink"
    },
    {
      "x": 0,
      "y": 7,
      "z": -1,
      "name": "Plant_Coral_Block_Pink"
    },
    {
      "x": 0,
      "y": 8,
      "z": -1,
      "name": "Plant_Coral_Block_Pink"
    },
    {
      "x": 0,
      "y": 9,
      "z": -1,
      "name": "Plant_Coral_Block_Pink"
    },
    {
      "x": 0,
      "y": 10,
      "z": -1,
      "name": "Plant_Coral_Block_Pink"
    },
    {
      "x": 0,
      "y": 11,
      "z": -1,
      "name": "Plant_Coral_Block_Pink"
    },
    {
      "x": 0,
      "y": 12,
      "z": -1,
      "name": "Plant_Coral_Block_Pink"
    },
    {
      "x": 0,
      "y": 4,
      "z": 0,
      "name": "Plant_Coral_Block_Pink"
    },
    {
      "x": 0,
      "y": 5,
      "z": 0,
      "name": "Plant_Coral_Block_Pink"
    },
    {
      "x": 0,
      "y": 6,
      "z": 0,
      "name": "Plant_Coral_Block_Pink"
    },
    {
      "x": 0,
      "y": 7,
      "z": 0,
      "name": "Plant_Coral_Block_Pink"
    },
    {
      "x": 0,
      "y": 8,
      "z": 0,
      "name": "Plant_Coral_Block_Pink"
    },
    {
      "x": 0,
      "y": 9,
      "z": 0,
      "name": "Plant_Coral_Block_Pink"
    },
    {
      "x": 0,
      "y": 10,
      "z": 0,
      "name": "Plant_Coral_Block_Pink"
    },
    {
      "x": 0,
      "y": 11,
      "z": 0,
      "name": "Plant_Coral_Block_Pink"
    },
    {
      "x": 0,
      "y": 12,
      "z": 0,
      "name": "Plant_Coral_Block_Violet"
    },
    {
      "x": 0,
      "y": 13,
      "z": 0,
      "name": "Plant_Coral_Block_Violet"
    },
    {
      "x": 0,
      "y": 4,
      "z": 1,
      "name": "Plant_Coral_Block_Pink"
    },
    {
      "x": 0,
      "y": 5,
      "z": 1,
      "name": "Plant_Coral_Block_Pink"
    },
    {
      "x": 0,
      "y": 6,
      "z": 1,
      "name": "Plant_Coral_Block_Pink"
    },
    {
      "x": 0,
      "y": 7,
      "z": 1,
      "name": "Plant_Coral_Block_Pink"
    },
    {
      "x": 0,
      "y": 8,
      "z": 1,
      "name": "Plant_Coral_Block_Pink"
    },
    {
      "x": 0,
      "y": 9,
      "z": 1,
      "name": "Plant_Coral_Block_Pink"
    },
    {
      "x": 0,
      "y": 10,
      "z": 1,
      "name": "Plant_Coral_Block_Pink"
    },
    {
      "x": 0,
      "y": 11,
      "z": 1,
      "name": "Plant_Coral_Block_Pink"
    },
    {
      "x": 0,
      "y": 12,
      "z": 1,
      "name": "Plant_Coral_Block_Violet"
    },
    {
      "x": 0,
      "y": 13,
      "z": 1,
      "name": "Plant_Coral_Block_Violet"
    },
    {
      "x": 0,
      "y": 4,
      "z": 2,
      "name": "Plant_Coral_Block_Pink"
    },
    {
      "x": 0,
      "y": 5,
      "z": 2,
      "name": "Plant_Coral_Block_Pink"
    },
    {
      "x": 0,
      "y": 6,
      "z": 2,
      "name": "Plant_Coral_Block_Pink"
    },
    {
      "x": 0,
      "y": 7,
      "z": 2,
      "name": "Plant_Coral_Block_Pink"
    },
    {
      "x": 0,
      "y": 8,
      "z": 2,
      "name": "Plant_Coral_Block_Pink"
    },
    {
      "x": 0,
      "y": 9,
      "z": 2,
      "name": "Plant_Coral_Block_Pink"
    },
    {
      "x": 0,
      "y": 10,
      "z": 2,
      "name": "Plant_Coral_Block_Pink"
    },
    {
      "x": 0,
      "y": 11,
      "z": 2,
      "name": "Plant_Coral_Block_Pink"
    },
    {
      "x": 0,
      "y": 12,
      "z": 2,
      "name": "Plant_Coral_Block_Violet"
    },
    {
      "x": 0,
      "y": 13,
      "z": 2,
      "name": "Plant_Coral_Block_Violet"
    },
    {
      "x": 0,
      "y": 4,
      "z": 3,
      "name": "Plant_Coral_Block_Pink"
    },
    {
      "x": 0,
      "y": 5,
      "z": 3,
      "name": "Plant_Coral_Block_Pink"
    },
    {
      "x": 0,
      "y": 6,
      "z": 3,
      "name": "Plant_Coral_Block_Pink"
    },
    {
      "x": 0,
      "y": 7,
      "z": 3,
      "name": "Plant_Coral_Block_Pink"
    },
    {
      "x": 0,
      "y": 8,
      "z": 3,
      "name": "Plant_Coral_Block_Pink"
    },
    {
      "x": 0,
      "y": 9,
      "z": 3,
      "name": "Plant_Coral_Block_Pink"
    },
    {
      "x": 0,
      "y": 10,
      "z": 3,
      "name": "Plant_Coral_Block_Pink"
    },
    {
      "x": 0,
      "y": 11,
      "z": 3,
      "name": "Plant_Coral_Block_Pink"
    },
    {
      "x": 0,
      "y": 12,
      "z": 3,
      "name": "Plant_Coral_Block_Violet"
    },
    {
      "x": 0,
      "y": 13,
      "z": 3,
      "name": "Plant_Coral_Block_Violet"
    },
    {
      "x": 0,
      "y": 5,
      "z": 4,
      "name": "Plant_Coral_Block_Pink"
    },
    {
      "x": 0,
      "y": 6,
      "z": 4,
      "name": "Plant_Coral_Block_Pink"
    },
    {
      "x": 0,
      "y": 7,
      "z": 4,
      "name": "Plant_Coral_Block_Pink"
    },
    {
      "x": 0,
      "y": 8,
      "z": 4,
      "name": "Plant_Coral_Block_Pink"
    },
    {
      "x": 0,
      "y": 9,
      "z": 4,
      "name": "Plant_Coral_Block_Pink"
    },
    {
      "x": 0,
      "y": 10,
      "z": 4,
      "name": "Plant_Coral_Block_Pink"
    },
    {
      "x": 0,
      "y": 11,
      "z": 4,
      "name": "Plant_Coral_Block_Pink"
    },
    {
      "x": 0,
      "y": 5,
      "z": 5,
      "name": "Plant_Coral_Block_Pink"
    },
    {
      "x": 0,
      "y": 6,
      "z": 5,
      "name": "Plant_Coral_Block_Pink"
    },
    {
      "x": 0,
      "y": 7,
      "z": 5,
      "name": "Plant_Coral_Block_Pink"
    },
    {
      "x": 0,
      "y": 8,
      "z": 5,
      "name": "Plant_Coral_Block_Pink"
    },
    {
      "x": 0,
      "y": 9,
      "z": 5,
      "name": "Plant_Coral_Block_Pink"
    },
    {
      "x": 0,
      "y": 10,
      "z": 5,
      "name": "Plant_Coral_Block_Pink"
    },
    {
      "x": 0,
      "y": 11,
      "z": 5,
      "name": "Plant_Coral_Block_Violet"
    },
    {
      "x": 0,
      "y": 12,
      "z": 5,
      "name": "Plant_Coral_Block_Violet"
    },
    {
      "x": 0,
      "y": 5,
      "z": 6,
      "name": "Plant_Coral_Block_Pink"
    },
    {
      "x": 0,
      "y": 6,
      "z": 6,
      "name": "Plant_Coral_Block_Pink"
    },
    {
      "x": 0,
      "y": 7,
      "z": 6,
      "name": "Plant_Coral_Block_Pink"
    },
    {
      "x": 0,
      "y": 8,
      "z": 6,
      "name": "Plant_Coral_Block_Pink"
    },
    {
      "x": 0,
      "y": 9,
      "z": 6,
      "name": "Plant_Coral_Block_Pink"
    },
    {
      "x": 0,
      "y": 10,
      "z": 6,
      "name": "Plant_Coral_Block_Pink"
    },
    {
      "x": 0,
      "y": 11,
      "z": 6,
      "name": "Plant_Coral_Block_Violet"
    },
    {
      "x": 0,
      "y": 12,
      "z": 6,
      "name": "Plant_Coral_Block_Violet"
    },
    {
      "x": 0,
      "y": 6,
      "z": 7,
      "name": "Plant_Coral_Block_Pink"
    },
    {
      "x": 0,
      "y": 7,
      "z": 7,
      "name": "Plant_Coral_Block_Pink"
    },
    {
      "x": 0,
      "y": 8,
      "z": 7,
      "name": "Plant_Coral_Block_Pink"
    },
    {
      "x": 0,
      "y": 9,
      "z": 7,
      "name": "Plant_Coral_Block_Pink"
    },
    {
      "x": 0,
      "y": 10,
      "z": 7,
      "name": "Plant_Coral_Block_Pink"
    },
    {
      "x": 0,
      "y": 6,
      "z": 8,
      "name": "Plant_Coral_Block_Pink"
    },
    {
      "x": 0,
      "y": 7,
      "z": 8,
      "name": "Plant_Coral_Block_Pink"
    },
    {
      "x": 0,
      "y": 8,
      "z": 8,
      "name": "Plant_Coral_Block_Pink"
    },
    {
      "x": 0,
      "y": 9,
      "z": 8,
      "name": "Plant_Coral_Block_Pink"
    },
    {
      "x": 0,
      "y": 10,
      "z": 8,
      "name": "Plant_Coral_Block_Pink"
    },
    {
      "x": 0,
      "y": 7,
      "z": 9,
      "name": "Plant_Coral_Block_Pink"
    },
    {
      "x": 0,
      "y": 8,
      "z": 9,
      "name": "Plant_Coral_Block_Pink"
    },
    {
      "x": 0,
      "y": 9,
      "z": 9,
      "name": "Plant_Coral_Block_Violet"
    },
    {
      "x": 0,
      "y": 10,
      "z": 9,
      "name": "Plant_Coral_Block_Violet"
    },
    {
      "x": 1,
      "y": 7,
      "z": -9,
      "name": "Plant_Coral_Block_Pink"
    },
    {
      "x": 1,
      "y": 8,
      "z": -9,
      "name": "Plant_Coral_Block_Pink"
    },
    {
      "x": 1,
      "y": 9,
      "z": -9,
      "name": "Plant_Coral_Block_Violet"
    },
    {
      "x": 1,
      "y": 10,
      "z": -9,
      "name": "Plant_Coral_Block_Violet"
    },
    {
      "x": 1,
      "y": 6,
      "z": -8,
      "name": "Plant_Coral_Block_Pink"
    },
    {
      "x": 1,
      "y": 7,
      "z": -8,
      "name": "Plant_Coral_Block_Pink"
    },
    {
      "x": 1,
      "y": 8,
      "z": -8,
      "name": "Plant_Coral_Block_Pink"
    },
    {
      "x": 1,
      "y": 9,
      "z": -8,
      "name": "Plant_Coral_Block_Pink"
    },
    {
      "x": 1,
      "y": 10,
      "z": -8,
      "name": "Plant_Coral_Block_Pink"
    },
    {
      "x": 1,
      "y": 6,
      "z": -7,
      "name": "Plant_Coral_Block_Pink"
    },
    {
      "x": 1,
      "y": 7,
      "z": -7,
      "name": "Plant_Coral_Block_Pink"
    },
    {
      "x": 1,
      "y": 8,
      "z": -7,
      "name": "Plant_Coral_Block_Pink"
    },
    {
      "x": 1,
      "y": 9,
      "z": -7,
      "name": "Plant_Coral_Block_Pink"
    },
    {
      "x": 1,
      "y": 10,
      "z": -7,
      "name": "Plant_Coral_Block_Violet"
    },
    {
      "x": 1,
      "y": 11,
      "z": -7,
      "name": "Plant_Coral_Block_Violet"
    },
    {
      "x": 1,
      "y": 5,
      "z": -6,
      "name": "Plant_Coral_Block_Pink"
    },
    {
      "x": 1,
      "y": 6,
      "z": -6,
      "name": "Plant_Coral_Block_Pink"
    },
    {
      "x": 1,
      "y": 7,
      "z": -6,
      "name": "Plant_Coral_Block_Pink"
    },
    {
      "x": 1,
      "y": 8,
      "z": -6,
      "name": "Plant_Coral_Block_Pink"
    },
    {
      "x": 1,
      "y": 9,
      "z": -6,
      "name": "Plant_Coral_Block_Pink"
    },
    {
      "x": 1,
      "y": 10,
      "z": -6,
      "name": "Plant_Coral_Block_Pink"
    },
    {
      "x": 1,
      "y": 11,
      "z": -6,
      "name": "Plant_Coral_Block_Pink"
    },
    {
      "x": 1,
      "y": 5,
      "z": -5,
      "name": "Plant_Coral_Block_Pink"
    },
    {
      "x": 1,
      "y": 6,
      "z": -5,
      "name": "Plant_Coral_Block_Pink"
    },
    {
      "x": 1,
      "y": 7,
      "z": -5,
      "name": "Plant_Coral_Block_Pink"
    },
    {
      "x": 1,
      "y": 8,
      "z": -5,
      "name": "Plant_Coral_Block_Pink"
    },
    {
      "x": 1,
      "y": 9,
      "z": -5,
      "name": "Plant_Coral_Block_Pink"
    },
    {
      "x": 1,
      "y": 10,
      "z": -5,
      "name": "Plant_Coral_Block_Pink"
    },
    {
      "x": 1,
      "y": 11,
      "z": -5,
      "name": "Plant_Coral_Block_Violet"
    },
    {
      "x": 1,
      "y": 12,
      "z": -5,
      "name": "Plant_Coral_Block_Violet"
    },
    {
      "x": 1,
      "y": 5,
      "z": -4,
      "name": "Plant_Coral_Block_Pink"
    },
    {
      "x": 1,
      "y": 6,
      "z": -4,
      "name": "Plant_Coral_Block_Pink"
    },
    {
      "x": 1,
      "y": 7,
      "z": -4,
      "name": "Plant_Coral_Block_Pink"
    },
    {
      "x": 1,
      "y": 8,
      "z": -4,
      "name": "Plant_Coral_Block_Pink"
    },
    {
      "x": 1,
      "y": 9,
      "z": -4,
      "name": "Plant_Coral_Block_Pink"
    },
    {
      "x": 1,
      "y": 10,
      "z": -4,
      "name": "Plant_Coral_Block_Pink"
    },
    {
      "x": 1,
      "y": 11,
      "z": -4,
      "name": "Plant_Coral_Block_Violet"
    },
    {
      "x": 1,
      "y": 12,
      "z": -4,
      "name": "Plant_Coral_Block_Violet"
    },
    {
      "x": 1,
      "y": 4,
      "z": -3,
      "name": "Plant_Coral_Block_Pink"
    },
    {
      "x": 1,
      "y": 5,
      "z": -3,
      "name": "Plant_Coral_Block_Pink"
    },
    {
      "x": 1,
      "y": 6,
      "z": -3,
      "name": "Plant_Coral_Block_Pink"
    },
    {
      "x": 1,
      "y": 7,
      "z": -3,
      "name": "Plant_Coral_Block_Pink"
    },
    {
      "x": 1,
      "y": 8,
      "z": -3,
      "name": "Plant_Coral_Block_Pink"
    },
    {
      "x": 1,
      "y": 9,
      "z": -3,
      "name": "Plant_Coral_Block_Pink"
    },
    {
      "x": 1,
      "y": 10,
      "z": -3,
      "name": "Plant_Coral_Block_Pink"
    },
    {
      "x": 1,
      "y": 11,
      "z": -3,
      "name": "Plant_Coral_Block_Pink"
    },
    {
      "x": 1,
      "y": 12,
      "z": -3,
      "name": "Plant_Coral_Block_Pink"
    },
    {
      "x": 1,
      "y": 4,
      "z": -2,
      "name": "Plant_Coral_Block_Pink"
    },
    {
      "x": 1,
      "y": 5,
      "z": -2,
      "name": "Plant_Coral_Block_Pink"
    },
    {
      "x": 1,
      "y": 6,
      "z": -2,
      "name": "Plant_Coral_Block_Pink"
    },
    {
      "x": 1,
      "y": 7,
      "z": -2,
      "name": "Plant_Coral_Block_Pink"
    },
    {
      "x": 1,
      "y": 8,
      "z": -2,
      "name": "Plant_Coral_Block_Pink"
    },
    {
      "x": 1,
      "y": 9,
      "z": -2,
      "name": "Plant_Coral_Block_Pink"
    },
    {
      "x": 1,
      "y": 10,
      "z": -2,
      "name": "Plant_Coral_Block_Pink"
    },
    {
      "x": 1,
      "y": 11,
      "z": -2,
      "name": "Plant_Coral_Block_Pink"
    },
    {
      "x": 1,
      "y": 12,
      "z": -2,
      "name": "Plant_Coral_Block_Violet"
    },
    {
      "x": 1,
      "y": 13,
      "z": -2,
      "name": "Plant_Coral_Block_Violet"
    },
    {
      "x": 1,
      "y": 4,
      "z": -1,
      "name": "Plant_Coral_Block_Pink"
    },
    {
      "x": 1,
      "y": 5,
      "z": -1,
      "name": "Plant_Coral_Block_Pink"
    },
    {
      "x": 1,
      "y": 6,
      "z": -1,
      "name": "Plant_Coral_Block_Pink"
    },
    {
      "x": 1,
      "y": 7,
      "z": -1,
      "name": "Plant_Coral_Block_Pink"
    },
    {
      "x": 1,
      "y": 8,
      "z": -1,
      "name": "Plant_Coral_Block_Pink"
    },
    {
      "x": 1,
      "y": 9,
      "z": -1,
      "name": "Plant_Coral_Block_Pink"
    },
    {
      "x": 1,
      "y": 10,
      "z": -1,
      "name": "Plant_Coral_Block_Pink"
    },
    {
      "x": 1,
      "y": 11,
      "z": -1,
      "name": "Plant_Coral_Block_Pink"
    },
    {
      "x": 1,
      "y": 12,
      "z": -1,
      "name": "Plant_Coral_Block_Pink"
    },
    {
      "x": 1,
      "y": 4,
      "z": 0,
      "name": "Plant_Coral_Block_Pink"
    },
    {
      "x": 1,
      "y": 5,
      "z": 0,
      "name": "Plant_Coral_Block_Pink"
    },
    {
      "x": 1,
      "y": 6,
      "z": 0,
      "name": "Plant_Coral_Block_Pink"
    },
    {
      "x": 1,
      "y": 7,
      "z": 0,
      "name": "Plant_Coral_Block_Pink"
    },
    {
      "x": 1,
      "y": 8,
      "z": 0,
      "name": "Plant_Coral_Block_Pink"
    },
    {
      "x": 1,
      "y": 9,
      "z": 0,
      "name": "Plant_Coral_Block_Pink"
    },
    {
      "x": 1,
      "y": 10,
      "z": 0,
      "name": "Plant_Coral_Block_Pink"
    },
    {
      "x": 1,
      "y": 11,
      "z": 0,
