{
  "version": 8,
  "blockIdVersion": 8,
  "anchorX": 5,
  "anchorY": 3,
  "anchorZ": 4,
  "blocks": [
    {
      "x": 3,
      "y": 7,
      "z": 1,
      "name": "Rock_Sandstone"
    },
    {
      "x": 3,
      "y": 8,
      "z": 1,
      "name": "Rock_Sandstone"
    },
    {
      "x": 3,
      "y": 7,
      "z": 2,
      "name": "Rock_Sandstone"
    },
    {
      "x": 3,
      "y": 8,
      "z": 2,
      "name": "Rock_Sandstone"
    },
    {
      "x": 3,
      "y": 7,
      "z": 3,
      "name": "Rock_Sandstone"
    },
    {
      "x": 3,
      "y": 8,
      "z": 3,
      "name": "Rock_Sandstone_Brick_Stairs"
    },
    {
      "x": 3,
      "y": 7,
      "z": 5,
      "name": "Rock_Sandstone"
    },
    {
      "x": 3,
      "y": 8,
      "z": 5,
      "name": "Rock_Sandstone_Brick_Stairs",
      "rotation": 2
    },
    {
      "x": 3,
      "y": 7,
      "z": 6,
      "name": "Rock_Sandstone"
    },
    {
      "x": 3,
      "y": 8,
      "z": 6,
      "name": "Rock_Sandstone"
    },
    {
      "x": 3,
      "y": 7,
      "z": 7,
      "name": "Rock_Sandstone"
    },
    {
      "x": 3,
      "y": 8,
      "z": 7,
      "name": "Rock_Sandstone"
    },
    {
      "x": 4,
      "y": 2,
      "z": 1,
      "name": "Rock_Sandstone"
    },
    {
      "x": 4,
      "y": 3,
      "z": 1,
      "name": "Rock_Sandstone"
    },
    {
      "x": 4,
      "y": 4,
      "z": 1,
      "name": "Rock_Sandstone_Brick_Smooth"
    },
    {
      "x": 4,
      "y": 5,
      "z": 1,
      "name": "Rock_Sandstone_Brick_Smooth"
    },
    {
      "x": 4,
      "y": 6,
      "z": 1,
      "name": "Rock_Sandstone_Brick_Smooth"
    },
    {
      "x": 4,
      "y": 7,
      "z": 1,
      "name": "Rock_Sandstone_Brick_Smooth"
    },
    {
      "x": 4,
      "y": 8,
      "z": 1,
      "name": "Rock_Sandstone"
    },
    {
      "x": 4,
      "y": 1,
      "z": 2,
      "name": "Rock_Sandstone"
    },
    {
      "x": 4,
      "y": 2,
      "z": 2,
      "name": "Rock_Sandstone"
    },
    {
      "x": 4,
      "y": 3,
      "z": 2,
      "name": "Rock_Sandstone"
    },
    {
      "x": 4,
      "y": 4,
      "z": 2,
      "name": "Rock_Sandstone_Brick"
    },
    {
      "x": 4,
      "y": 5,
      "z": 2,
      "name": "*Rock_Sandstone_Brick_Stairs_State_Definitions_Corner_Right",
      "rotation": 3
    },
    {
      "x": 4,
      "y": 6,
      "z": 2,
      "name": "*Rock_Sandstone_Brick_Stairs_State_Definitions_Corner_Right",
      "rotation": 10
    },
    {
      "x": 4,
      "y": 7,
      "z": 2,
      "name": "Rock_Sandstone"
    },
    {
      "x": 4,
      "y": 8,
      "z": 2,
      "name": "Rock_Sandstone"
    },
    {
      "x": 4,
      "y": 0,
      "z": 3,
      "name": "Rock_Sandstone"
    },
    {
      "x": 4,
      "y": 1,
      "z": 3,
      "name": "Rock_Sandstone"
    },
    {
      "x": 4,
      "y": 2,
      "z": 3,
      "name": "Rock_Sandstone"
    },
    {
      "x": 4,
      "y": 3,
      "z": 3,
      "name": "Rock_Sandstone"
    },
    {
      "x": 4,
      "y": 4,
      "z": 3,
      "name": "Rock_Sandstone_Brick"
    },
    {
      "x": 4,
      "y": 5,
      "z": 3,
      "name": "*Rock_Sandstone_Brick_Stairs_State_Definitions_Corner_Right"
    },
    {
      "x": 4,
      "y": 6,
      "z": 3,
      "name": "*Rock_Sandstone_Brick_Stairs_State_Definitions_Corner_Right",
      "rotation": 11
    },
    {
      "x": 4,
      "y": 7,
      "z": 3,
      "name": "Rock_Sandstone"
    },
    {
      "x": 4,
      "y": 0,
      "z": 4,
      "name": "Rock_Sandstone"
    },
    {
      "x": 4,
      "y": 1,
      "z": 4,
      "name": "Rock_Sandstone"
    },
    {
      "x": 4,
      "y": 2,
      "z": 4,
      "name": "Rock_Sandstone"
    },
    {
      "x": 4,
      "y": 3,
      "z": 4,
      "name": "Rock_Sandstone"
    },
    {
      "x": 4,
      "y": 4,
      "z": 4,
      "name": "Rock_Sandstone_Brick_Smooth"
    },
    {
      "x": 4,
      "y": 5,
      "z": 4,
      "name": "Rock_Sandstone_Brick_Smooth"
    },
    {
      "x": 4,
      "y": 6,
      "z": 4,
      "name": "Rock_Sandstone_Brick_Smooth"
    },
    {
      "x": 4,
      "y": 7,
      "z": 4,
      "name": "Rock_Sandstone_Brick_Smooth"
    },
    {
      "x": 4,
      "y": 1,
      "z": 5,
      "name": "Rock_Sandstone"
    },
    {
      "x": 4,
      "y": 2,
      "z": 5,
      "name": "Rock_Sandstone"
    },
    {
      "x": 4,
      "y": 3,
      "z": 5,
      "name": "Rock_Sandstone"
    },
    {
      "x": 4,
      "y": 4,
      "z": 5,
      "name": "Rock_Sandstone_Brick"
    },
    {
      "x": 4,
      "y": 5,
      "z": 5,
      "name": "*Rock_Sandstone_Brick_Stairs_State_Definitions_Corner_Right",
      "rotation": 3
    },
    {
      "x": 4,
      "y": 6,
      "z": 5,
      "name": "*Rock_Sandstone_Brick_Stairs_State_Definitions_Corner_Right",
      "rotation": 10
    },
    {
      "x": 4,
      "y": 7,
      "z": 5,
      "name": "Rock_Sandstone"
    },
    {
      "x": 4,
      "y": 1,
      "z": 6,
      "name": "Rock_Sandstone"
    },
    {
      "x": 4,
      "y": 2,
      "z": 6,
      "name": "Rock_Sandstone"
    },
    {
      "x": 4,
      "y": 3,
      "z": 6,
      "name": "Rock_Sandstone"
    },
    {
      "x": 4,
      "y": 4,
      "z": 6,
      "name": "Rock_Sandstone"
    },
    {
      "x": 4,
      "y": 5,
      "z": 6,
      "name": "*Rock_Sandstone_Brick_Stairs_State_Definitions_Corner_Right"
    },
    {
      "x": 4,
      "y": 6,
      "z": 6,
      "name": "*Rock_Sandstone_Brick_Stairs_State_Definitions_Corner_Right",
      "rotation": 11
    },
    {
      "x": 4,
      "y": 7,
      "z": 6,
      "name": "Rock_Sandstone"
    },
    {
      "x": 4,
      "y": 8,
      "z": 6,
      "name": "Rock_Sandstone"
    },
    {
      "x": 4,
      "y": 2,
      "z": 7,
      "name": "Rock_Sandstone"
    },
    {
      "x": 4,
      "y": 3,
      "z": 7,
      "name": "Rock_Sandstone"
    },
    {
      "x": 4,
      "y": 4,
      "z": 7,
      "name": "Rock_Sandstone"
    },
    {
      "x": 4,
      "y": 5,
      "z": 7,
      "name": "Rock_Sandstone_Brick_Smooth"
    },
    {
      "x": 4,
      "y": 6,
      "z": 7,
      "name": "Rock_Sandstone_Brick_Smooth"
    },
    {
      "x": 4,
      "y": 7,
      "z": 7,
      "name": "Rock_Sandstone_Brick_Smooth"
    },
    {
      "x": 4,
      "y": 8,
      "z": 7,
      "name": "Rock_Sandstone"
    },
    {
      "x": 5,
      "y": 1,
      "z": 1,
      "name": "Rock_Sandstone"
    },
    {
      "x": 5,
      "y": 2,
      "z": 1,
      "name": "Rock_Sandstone"
    },
    {
      "x": 5,
      "y": 3,
      "z": 1,
      "name": "Rock_Sandstone"
    },
    {
      "x": 5,
      "y": 4,
      "z": 1,
      "name": "Rock_Sandstone"
    },
    {
      "x": 5,
      "y": 5,
      "z": 1,
      "name": "Rock_Sandstone"
    },
    {
      "x": 5,
      "y": 6,
      "z": 1,
      "name": "Rock_Sandstone"
    },
    {
      "x": 5,
      "y": 7,
      "z": 1,
      "name": "Rock_Sandstone"
    },
    {
      "x": 5,
      "y": 0,
      "z": 2,
      "name": "Rock_Sandstone"
    },
    {
      "x": 5,
      "y": 1,
      "z": 2,
      "name": "Rock_Sandstone"
    },
    {
      "x": 5,
      "y": 2,
      "z": 2,
      "name": "Rock_Sandstone"
    },
    {
      "x": 5,
      "y": 3,
      "z": 2,
      "name": "Rock_Sandstone"
    },
    {
      "x": 5,
      "y": 4,
      "z": 2,
      "name": "Rock_Sandstone"
    },
    {
      "x": 5,
      "y": 5,
      "z": 2,
      "name": "Rock_Sandstone"
    },
    {
      "x": 5,
      "y": 6,
      "z": 2,
      "name": "Rock_Sandstone"
    },
    {
      "x": 5,
      "y": 7,
      "z": 2,
      "name": "Rock_Sandstone"
    },
    {
      "x": 5,
      "y": 0,
      "z": 3,
      "name": "Rock_Sandstone"
    },
    {
      "x": 5,
      "y": 1,
      "z": 3,
      "name": "Rock_Sandstone"
    },
    {
      "x": 5,
      "y": 2,
      "z": 3,
      "name": "Rock_Sandstone"
    },
    {
      "x": 5,
      "y": 3,
      "z": 3,
      "name": "Rock_Sandstone"
    },
    {
      "x": 5,
      "y": 4,
      "z": 3,
      "name": "Rock_Sandstone"
    },
    {
      "x": 5,
      "y": 5,
      "z": 3,
      "name": "Rock_Sandstone"
    },
    {
      "x": 5,
      "y": 6,
      "z": 3,
      "name": "Rock_Sandstone"
    },
    {
      "x": 5,
      "y": 7,
      "z": 3,
      "name": "Rock_Sandstone"
    },
    {
      "x": 5,
      "y": 0,
      "z": 4,
      "name": "Rock_Sandstone"
    },
    {
      "x": 5,
      "y": 1,
      "z": 4,
      "name": "Rock_Sandstone"
    },
    {
      "x": 5,
      "y": 2,
      "z": 4,
      "name": "Rock_Sandstone"
    },
    {
      "x": 5,
      "y": 3,
      "z": 4,
      "name": "Rock_Sandstone"
    },
    {
      "x": 5,
      "y": 4,
      "z": 4,
      "name": "Rock_Sandstone"
    },
    {
      "x": 5,
      "y": 5,
      "z": 4,
      "name": "Rock_Sandstone"
    },
    {
      "x": 5,
      "y": 6,
      "z": 4,
      "name": "Rock_Sandstone"
    },
    {
      "x": 5,
      "y": 7,
      "z": 4,
      "name": "Rock_Sandstone"
    },
    {
      "x": 5,
      "y": 0,
      "z": 5,
      "name": "Rock_Sandstone"
    },
    {
      "x": 5,
      "y": 1,
      "z": 5,
      "name": "Rock_Sandstone"
    },
    {
      "x": 5,
      "y": 2,
      "z": 5,
      "name": "Rock_Sandstone"
    },
    {
      "x": 5,
      "y": 3,
      "z": 5,
      "name": "Rock_Sandstone"
    },
    {
      "x": 5,
      "y": 4,
      "z": 5,
      "name": "Rock_Sandstone"
    },
    {
      "x": 5,
      "y": 5,
      "z": 5,
      "name": "Rock_Sandstone"
    },
    {
      "x": 5,
      "y": 6,
      "z": 5,
      "name": "Rock_Sandstone"
    },
    {
      "x": 5,
      "y": 7,
      "z": 5,
      "name": "Rock_Sandstone"
    },
    {
      "x": 5,
      "y": 1,
      "z": 6,
      "name": "Rock_Sandstone"
    },
    {
      "x": 5,
      "y": 2,
      "z": 6,
      "name": "Rock_Sandstone"
    },
    {
      "x": 5,
      "y": 3,
      "z": 6,
      "name": "Rock_Sandstone"
    },
    {
      "x": 5,
      "y": 4,
      "z": 6,
      "name": "Rock_Sandstone"
    },
    {
      "x": 5,
      "y": 5,
      "z": 6,
      "name": "Rock_Sandstone"
    },
    {
      "x": 5,
      "y": 6,
      "z": 6,
      "name": "Rock_Sandstone"
    },
    {
      "x": 5,
      "y": 7,
      "z": 6,
      "name": "Rock_Sandstone"
    },
    {
      "x": 5,
      "y": 1,
      "z": 7,
      "name": "Rock_Sandstone"
    },
    {
      "x": 5,
      "y": 2,
      "z": 7,
      "name": "Rock_Sandstone"
    },
    {
      "x": 5,
      "y": 3,
      "z": 7,
      "name": "Rock_Sandstone"
    },
    {
      "x": 5,
      "y": 4,
      "z": 7,
      "name": "Rock_Sandstone"
    },
    {
      "x": 5,
      "y": 5,
      "z": 7,
      "name": "Rock_Sandstone"
    },
    {
      "x": 5,
      "y": 6,
      "z": 7,
      "name": "Rock_Sandstone"
    },
    {
      "x": 5,
      "y": 7,
      "z": 7,
      "name": "Rock_Sandstone"
    },
    {
      "x": 6,
      "y": 2,
      "z": 1,
      "name": "Rock_Sandstone"
    },
    {
      "x": 6,
      "y": 3,
      "z": 1,
      "name": "Rock_Sandstone_Brick_Smooth"
    },
    {
      "x": 6,
      "y": 4,
      "z": 1,
      "name": "Rock_Sandstone_Brick_Smooth"
    },
    {
      "x": 6,
      "y": 5,
      "z": 1,
      "name": "Rock_Sandstone_Brick_Smooth"
    },
    {
      "x": 6,
      "y": 6,
      "z": 1,
      "name": "Rock_Sandstone_Brick_Smooth"
    },
    {
      "x": 6,
      "y": 7,
      "z": 1,
      "name": "Rock_Sandstone_Brick_Smooth"
    },
    {
      "x": 6,
      "y": 8,
      "z": 1,
      "name": "Rock_Sandstone"
    },
    {
      "x": 6,
      "y": 1,
      "z": 2,
      "name": "Rock_Sandstone"
    },
    {
      "x": 6,
      "y": 2,
      "z": 2,
      "name": "Rock_Sandstone"
    },
    {
      "x": 6,
      "y": 3,
      "z": 2,
      "name": "Rock_Sandstone"
    },
    {
      "x": 6,
      "y": 4,
      "z": 2,
      "name": "Rock_Sandstone_Brick"
    },
    {
      "x": 6,
      "y": 5,
      "z": 2,
      "name": "*Rock_Sandstone_Brick_Stairs_State_Definitions_Corner_Right",
      "rotation": 2
    },
    {
      "x": 6,
      "y": 6,
      "z": 2,
      "name": "*Rock_Sandstone_Brick_Stairs_State_Definitions_Corner_Right",
      "rotation": 9
    },
    {
      "x": 6,
      "y": 7,
      "z": 2,
      "name": "Rock_Sandstone"
    },
    {
      "x": 6,
      "y": 8,
      "z": 2,
      "name": "Rock_Sandstone"
    },
    {
      "x": 6,
      "y": 0,
      "z": 3,
      "name": "Rock_Sandstone"
    },
    {
      "x": 6,
      "y": 1,
      "z": 3,
      "name": "Rock_Sandstone"
    },
    {
      "x": 6,
      "y": 2,
      "z": 3,
      "name": "Rock_Sandstone"
    },
    {
      "x": 6,
      "y": 3,
      "z": 3,
      "name": "Rock_Sandstone"
    },
    {
      "x": 6,
      "y": 4,
      "z": 3,
      "name": "Rock_Sandstone_Brick"
    },
    {
      "x": 6,
      "y": 5,
      "z": 3,
      "name": "*Rock_Sandstone_Brick_Stairs_State_Definitions_Corner_Right",
      "rotation": 1
    },
    {
      "x": 6,
      "y": 6,
      "z": 3,
      "name": "*Rock_Sandstone_Brick_Stairs_State_Definitions_Corner_Right",
      "rotation": 8
    },
    {
      "x": 6,
      "y": 7,
      "z": 3,
      "name": "Rock_Sandstone"
    },
    {
      "x": 6,
      "y": 0,
      "z": 4,
      "name": "Rock_Sandstone"
    },
    {
      "x": 6,
      "y": 1,
      "z": 4,
      "name": "Rock_Sandstone"
    },
    {
      "x": 6,
      "y": 2,
      "z": 4,
      "name": "Rock_Sandstone"
    },
    {
      "x": 6,
      "y": 3,
      "z": 4,
      "name": "Rock_Sandstone"
    },
    {
      "x": 6,
      "y": 4,
      "z": 4,
      "name": "Rock_Sandstone_Brick_Smooth"
    },
    {
      "x": 6,
      "y": 5,
      "z": 4,
      "name": "Rock_Sandstone_Brick_Smooth"
    },
    {
      "x": 6,
      "y": 6,
      "z": 4,
      "name": "Rock_Sandstone_Brick_Smooth"
    },
    {
      "x": 6,
      "y": 7,
      "z": 4,
      "name": "Rock_Sandstone_Brick_Smooth"
    },
    {
      "x": 6,
      "y": 1,
      "z": 5,
      "name": "Rock_Sandstone"
    },
    {
      "x": 6,
      "y": 2,
      "z": 5,
      "name": "Rock_Sandstone"
    },
    {
      "x": 6,
      "y": 3,
      "z": 5,
      "name": "Rock_Sandstone"
    },
    {
      "x": 6,
      "y": 4,
      "z": 5,
      "name": "Rock_Sandstone_Brick"
    },
    {
      "x": 6,
      "y": 5,
      "z": 5,
      "name": "*Rock_Sandstone_Brick_Stairs_State_Definitions_Corner_Right",
      "rotation": 2
    },
    {
      "x": 6,
      "y": 6,
      "z": 5,
      "name": "*Rock_Sandstone_Brick_Stairs_State_Definitions_Corner_Right",
      "rotation": 9
    },
    {
      "x": 6,
      "y": 7,
      "z": 5,
      "name": "Rock_Sandstone"
    },
    {
      "x": 6,
      "y": 1,
      "z": 6,
      "name": "Rock_Sandstone"
    },
    {
      "x": 6,
      "y": 2,
      "z": 6,
      "name": "Rock_Sandstone"
    },
    {
      "x": 6,
      "y": 3,
      "z": 6,
      "name": "Rock_Sandstone"
    },
    {
      "x": 6,
      "y": 4,
      "z": 6,
      "name": "Rock_Sandstone_Brick"
    },
    {
      "x": 6,
      "y": 5,
      "z": 6,
      "name": "*Rock_Sandstone_Brick_Stairs_State_Definitions_Corner_Right",
      "rotation": 1
    },
    {
      "x": 6,
      "y": 6,
      "z": 6,
      "name": "*Rock_Sandstone_Brick_Stairs_State_Definitions_Corner_Right",
      "rotation": 8
    },
    {
      "x": 6,
      "y": 7,
      "z": 6,
      "name": "Rock_Sandstone"
    },
    {
      "x": 6,
      "y": 8,
      "z": 6,
      "name": "Rock_Sandstone"
    },
    {
      "x": 6,
      "y": 2,
      "z": 7,
      "name": "Rock_Sandstone"
    },
    {
      "x": 6,
      "y": 3,
      "z": 7,
      "name": "Rock_Sandstone"
    },
    {
      "x": 6,
      "y": 4,
      "z": 7,
      "name": "Rock_Sandstone_Brick_Smooth"
    },
    {
      "x": 6,
      "y": 5,
      "z": 7,
      "name": "Rock_Sandstone_Brick_Smooth"
    },
    {
      "x": 6,
      "y": 6,
      "z": 7,
      "name": "Rock_Sandstone_Brick_Smooth"
    },
    {
      "x": 6,
      "y": 7,
      "z": 7,
      "name": "Rock_Sandstone_Brick_Smooth"
    },
    {
      "x": 6,
      "y": 8,
      "z": 7,
      "name": "Rock_Sandstone"
    },
    {
      "x": 7,
      "y": 7,
      "z": 1,
      "name": "Rock_Sandstone"
    },
    {
      "x": 7,
      "y": 8,
      "z": 1,
      "name": "Rock_Sandstone"
    },
    {
      "x": 7,
      "y": 7,
      "z": 2,
      "name": "Rock_Sandstone"
    },
    {
      "x": 7,
      "y": 8,
      "z": 2,
      "name": "Rock_Sandstone"
    },
    {
      "x": 7,
      "y": 7,
      "z": 3,
      "name": "Rock_Sandstone"
    },
    {
      "x": 7,
      "y": 8,
      "z": 3,
      "name": "Rock_Sandstone_Brick_Stairs"
    },
    {
      "x": 7,
      "y": 7,
      "z": 5,
      "name": "Rock_Sandstone"
    },
    {
      "x": 7,
      "y": 8,
      "z": 5,
      "name": "Rock_Sandstone_Brick_Stairs",
      "rotation": 2
    },
    {
      "x": 7,
      "y": 7,
      "z": 6,
      "name": "Rock_Sandstone"
    },
    {
      "x": 7,
      "y": 8,
      "z": 6,
      "name": "Rock_Sandstone"
    },
    {
      "x": 7,
      "y": 7,
      "z": 7,
      "name": "Rock_Sandstone"
    },
    {
      "x": 7,
      "y": 8,
      "z": 7,
      "name": "Rock_Sandstone"
    }
  ]
}