{
  "version": 8,
  "blockIdVersion": 8,
  "anchorX": 7,
  "anchorY": 5,
  "anchorZ": 4,
  "blocks": [
    {
      "x": 3,
      "y": 2,
      "z": 2,
      "name": "Rock_Sandstone"
    },
    {
      "x": 3,
      "y": 3,
      "z": 2,
      "name": "Rock_Sandstone"
    },
    {
      "x": 3,
      "y": 4,
      "z": 2,
      "name": "Rock_Sandstone"
    },
    {
      "x": 3,
      "y": 5,
      "z": 2,
      "name": "Rock_Sandstone"
    },
    {
      "x": 3,
      "y": 1,
      "z": 3,
      "name": "Rock_Sandstone"
    },
    {
      "x": 3,
      "y": 2,
      "z": 3,
      "name": "Rock_Sandstone"
    },
    {
      "x": 3,
      "y": 3,
      "z": 3,
      "name": "Rock_Sandstone"
    },
    {
      "x": 3,
      "y": 4,
      "z": 3,
      "name": "Rock_Sandstone"
    },
    {
      "x": 3,
      "y": 5,
      "z": 3,
      "name": "Rock_Sandstone"
    },
    {
      "x": 3,
      "y": 6,
      "z": 3,
      "name": "Rock_Sandstone"
    },
    {
      "x": 3,
      "y": 5,
      "z": 4,
      "name": "Rock_Sandstone"
    },
    {
      "x": 3,
      "y": 6,
      "z": 4,
      "name": "Rock_Sandstone"
    },
    {
      "x": 3,
      "y": 5,
      "z": 5,
      "name": "Rock_Sandstone"
    },
    {
      "x": 3,
      "y": 6,
      "z": 5,
      "name": "Rock_Sandstone"
    },
    {
      "x": 3,
      "y": 1,
      "z": 6,
      "name": "Rock_Sandstone"
    },
    {
      "x": 3,
      "y": 2,
      "z": 6,
      "name": "Rock_Sandstone"
    },
    {
      "x": 3,
      "y": 3,
      "z": 6,
      "name": "Rock_Sandstone"
    },
    {
      "x": 3,
      "y": 4,
      "z": 6,
      "name": "Rock_Sandstone"
    },
    {
      "x": 3,
      "y": 5,
      "z": 6,
      "name": "Rock_Sandstone"
    },
    {
      "x": 3,
      "y": 6,
      "z": 6,
      "name": "Rock_Sandstone"
    },
    {
      "x": 3,
      "y": 2,
      "z": 7,
      "name": "Rock_Sandstone"
    },
    {
      "x": 3,
      "y": 3,
      "z": 7,
      "name": "Rock_Sandstone"
    },
    {
      "x": 3,
      "y": 4,
      "z": 7,
      "name": "Rock_Sandstone"
    },
    {
      "x": 3,
      "y": 5,
      "z": 7,
      "name": "Rock_Sandstone"
    },
    {
      "x": 3,
      "y": 6,
      "z": 7,
      "name": "Rock_Sandstone"
    },
    {
      "x": 4,
      "y": 1,
      "z": 2,
      "name": "Rock_Sandstone"
    },
    {
      "x": 4,
      "y": 2,
      "z": 2,
      "name": "Rock_Sandstone"
    },
    {
      "x": 4,
      "y": 3,
      "z": 2,
      "name": "Rock_Sandstone"
    },
    {
      "x": 4,
      "y": 4,
      "z": 2,
      "name": "Rock_Sandstone"
    },
    {
      "x": 4,
      "y": 5,
      "z": 2,
      "name": "Rock_Sandstone"
    },
    {
      "x": 4,
      "y": 6,
      "z": 2,
      "name": "Rock_Sandstone"
    },
    {
      "x": 4,
      "y": 1,
      "z": 3,
      "name": "Rock_Sandstone"
    },
    {
      "x": 4,
      "y": 2,
      "z": 3,
      "name": "Rock_Sandstone"
    },
    {
      "x": 4,
      "y": 3,
      "z": 3,
      "name": "Rock_Sandstone"
    },
    {
      "x": 4,
      "y": 4,
      "z": 3,
      "name": "Rock_Sandstone"
    },
    {
      "x": 4,
      "y": 5,
      "z": 3,
      "name": "Rock_Sandstone"
    },
    {
      "x": 4,
      "y": 6,
      "z": 3,
      "name": "Rock_Sandstone"
    },
    {
      "x": 4,
      "y": 7,
      "z": 3,
      "name": "Soil_Gravel_Sand_White"
    },
    {
      "x": 4,
      "y": 5,
      "z": 4,
      "name": "Rock_Sandstone"
    },
    {
      "x": 4,
      "y": 6,
      "z": 4,
      "name": "Rock_Sandstone"
    },
    {
      "x": 4,
      "y": 7,
      "z": 4,
      "name": "Soil_Gravel_Sand_White"
    },
    {
      "x": 4,
      "y": 5,
      "z": 5,
      "name": "Rock_Sandstone"
    },
    {
      "x": 4,
      "y": 6,
      "z": 5,
      "name": "Rock_Sandstone"
    },
    {
      "x": 4,
      "y": 7,
      "z": 5,
      "name": "Soil_Gravel_Sand_White"
    },
    {
      "x": 4,
      "y": 1,
      "z": 6,
      "name": "Rock_Sandstone"
    },
    {
      "x": 4,
      "y": 2,
      "z": 6,
      "name": "Rock_Sandstone"
    },
    {
      "x": 4,
      "y": 3,
      "z": 6,
      "name": "Rock_Sandstone"
    },
    {
      "x": 4,
      "y": 4,
      "z": 6,
      "name": "Rock_Sandstone"
    },
    {
      "x": 4,
      "y": 5,
      "z": 6,
      "name": "Rock_Sandstone"
    },
    {
      "x": 4,
      "y": 6,
      "z": 6,
      "name": "Rock_Sandstone"
    },
    {
      "x": 4,
      "y": 1,
      "z": 7,
      "name": "Rock_Sandstone"
    },
    {
      "x": 4,
      "y": 2,
      "z": 7,
      "name": "Rock_Sandstone"
    },
    {
      "x": 4,
      "y": 3,
      "z": 7,
      "name": "Rock_Sandstone"
    },
    {
      "x": 4,
      "y": 4,
      "z": 7,
      "name": "Rock_Sandstone"
    },
    {
      "x": 4,
      "y": 5,
      "z": 7,
      "name": "Rock_Sandstone"
    },
    {
      "x": 4,
      "y": 6,
      "z": 7,
      "name": "Rock_Sandstone"
    },
    {
      "x": 5,
      "y": 5,
      "z": 2,
      "name": "Rock_Sandstone_Brick_Decorative"
    },
    {
      "x": 5,
      "y": 6,
      "z": 2,
      "name": "Rock_Sandstone_Brick"
    },
    {
      "x": 5,
      "y": 7,
      "z": 2,
      "name": "Rock_Sandstone_Brick_Smooth_Half"
    },
    {
      "x": 5,
      "y": 6,
      "z": 3,
      "name": "Rock_Sandstone"
    },
    {
      "x": 5,
      "y": 7,
      "z": 3,
      "name": "Soil_Gravel_Sand_White"
    },
    {
      "x": 5,
      "y": 6,
      "z": 4,
      "name": "Rock_Sandstone"
    },
    {
      "x": 5,
      "y": 7,
      "z": 4,
      "name": "Soil_Gravel_Sand_White"
    },
    {
      "x": 5,
      "y": 6,
      "z": 5,
      "name": "Rock_Sandstone"
    },
    {
      "x": 5,
      "y": 7,
      "z": 5,
      "name": "Soil_Gravel_Sand_White"
    },
    {
      "x": 5,
      "y": 5,
      "z": 6,
      "name": "Rock_Sandstone"
    },
    {
      "x": 5,
      "y": 6,
      "z": 6,
      "name": "Rock_Sandstone"
    },
    {
      "x": 5,
      "y": 7,
      "z": 6,
      "name": "Rock_Sandstone_Brick"
    },
    {
      "x": 5,
      "y": 8,
      "z": 6,
      "name": "Rock_Sandstone_Brick"
    },
    {
      "x": 5,
      "y": 9,
      "z": 6,
      "name": "Rock_Sandstone_Brick_Pillar_Base",
      "rotation": 8
    },
    {
      "x": 5,
      "y": 5,
      "z": 7,
      "name": "Rock_Sandstone_Brick_Decorative"
    },
    {
      "x": 5,
      "y": 6,
      "z": 7,
      "name": "Rock_Sandstone_Brick_Decorative"
    },
    {
      "x": 6,
      "y": 6,
      "z": 2,
      "name": "Rock_Sandstone"
    },
    {
      "x": 6,
      "y": 6,
      "z": 3,
      "name": "Rock_Sandstone"
    },
    {
      "x": 6,
      "y": 7,
      "z": 3,
      "name": "Soil_Gravel_Sand_White"
    },
    {
      "x": 6,
      "y": 6,
      "z": 4,
      "name": "Rock_Sandstone"
    },
    {
      "x": 6,
      "y": 7,
      "z": 4,
      "name": "Rock_Sandstone"
    },
    {
      "x": 6,
      "y": 8,
      "z": 4,
      "name": "Soil_Gravel_Sand_White"
    },
    {
      "x": 6,
      "y": 6,
      "z": 5,
      "name": "Rock_Sandstone"
    },
    {
      "x": 6,
      "y": 7,
      "z": 5,
      "name": "Rock_Sandstone"
    },
    {
      "x": 6,
      "y": 8,
      "z": 5,
      "name": "Soil_Gravel_Sand_White"
    },
    {
      "x": 6,
      "y": 6,
      "z": 6,
      "name": "Rock_Sandstone"
    },
    {
      "x": 6,
      "y": 7,
      "z": 6,
      "name": "Rock_Sandstone_Brick"
    },
    {
      "x": 6,
      "y": 8,
      "z": 6,
      "name": "Rock_Sandstone_Brick_Stairs",
      "rotation": 1
    },
    {
      "x": 6,
      "y": 9,
      "z": 6,
      "name": "Rock_Sandstone_Brick_Smooth_Half",
      "rotation": 8
    },
    {
      "x": 6,
      "y": 5,
      "z": 7,
      "name": "Rock_Sandstone"
    },
    {
      "x": 6,
      "y": 6,
      "z": 7,
      "name": "Rock_Sandstone"
    },
    {
      "x": 7,
      "y": 6,
      "z": 2,
      "name": "Rock_Sandstone"
    },
    {
      "x": 7,
      "y": 6,
      "z": 3,
      "name": "Rock_Sandstone"
    },
    {
      "x": 7,
      "y": 7,
      "z": 3,
      "name": "Rock_Sandstone_Brick"
    },
    {
      "x": 7,
      "y": 8,
      "z": 3,
      "name": "Rock_Sandstone_Brick"
    },
    {
      "x": 7,
      "y": 9,
      "z": 3,
      "name": "Rock_Sandstone_Brick_Pillar_Base",
      "rotation": 8
    },
    {
      "x": 7,
      "y": 5,
      "z": 4,
      "name": "Rock_Sandstone"
    },
    {
      "x": 7,
      "y": 6,
      "z": 4,
      "name": "Rock_Sandstone"
    },
    {
      "x": 7,
      "y": 7,
      "z": 4,
      "name": "Rock_Sandstone"
    },
    {
      "x": 7,
      "y": 8,
      "z": 4,
      "name": "Soil_Gravel_Sand_White"
    },
    {
      "x": 7,
      "y": 6,
      "z": 5,
      "name": "Rock_Sandstone"
    },
    {
      "x": 7,
      "y": 7,
      "z": 5,
      "name": "Rock_Sandstone"
    },
    {
      "x": 7,
      "y": 8,
      "z": 5,
      "name": "Soil_Gravel_Sand_White"
    },
    {
      "x": 7,
      "y": 6,
      "z": 6,
      "name": "Rock_Sandstone"
    },
    {
      "x": 7,
      "y": 7,
      "z": 6,
      "name": "Rock_Sandstone_Brick"
    },
    {
      "x": 7,
      "y": 8,
      "z": 6,
      "name": "Rock_Sandstone_Brick"
    },
    {
      "x": 7,
      "y": 9,
      "z": 6,
      "name": "Rock_Sandstone_Brick_Pillar_Base",
      "rotation": 8
    },
    {
      "x": 7,
      "y": 5,
      "z": 7,
      "name": "Rock_Sandstone"
    },
    {
      "x": 7,
      "y": 6,
      "z": 7,
      "name": "Rock_Sandstone"
    },
    {
      "x": 8,
      "y": 6,
      "z": 2,
      "name": "Rock_Sandstone"
    },
    {
      "x": 8,
      "y": 6,
      "z": 3,
      "name": "Rock_Sandstone"
    },
    {
      "x": 8,
      "y": 7,
      "z": 3,
      "name": "Rock_Sandstone_Brick"
    },
    {
      "x": 8,
      "y": 8,
      "z": 3,
      "name": "Rock_Sandstone_Brick_Stairs",
      "rotation": 3
    },
    {
      "x": 8,
      "y": 9,
      "z": 3,
      "name": "Rock_Sandstone_Brick_Smooth_Half",
      "rotation": 8
    },
    {
      "x": 8,
      "y": 6,
      "z": 4,
      "name": "Rock_Sandstone"
    },
    {
      "x": 8,
      "y": 7,
      "z": 4,
      "name": "Rock_Sandstone"
    },
    {
      "x": 8,
      "y": 8,
      "z": 4,
      "name": "Soil_Gravel_Sand_White"
    },
    {
      "x": 8,
      "y": 6,
      "z": 5,
      "name": "Rock_Sandstone"
    },
    {
      "x": 8,
      "y": 7,
      "z": 5,
      "name": "Rock_Sandstone"
    },
    {
      "x": 8,
      "y": 8,
      "z": 5,
      "name": "Soil_Gravel_Sand_White"
    },
    {
      "x": 8,
      "y": 6,
      "z": 6,
      "name": "Rock_Sandstone"
    },
    {
      "x": 8,
      "y": 7,
      "z": 6,
      "name": "Rock_Sandstone_Brick"
    },
    {
      "x": 8,
      "y": 8,
      "z": 6,
      "name": "Rock_Sandstone_Brick_Stairs",
      "rotation": 3
    },
    {
      "x": 8,
      "y": 9,
      "z": 6,
      "name": "Rock_Sandstone_Brick_Smooth_Half",
      "rotation": 8
    },
    {
      "x": 8,
      "y": 6,
      "z": 7,
      "name": "Rock_Sandstone"
    },
    {
      "x": 9,
      "y": 5,
      "z": 2,
      "name": "Rock_Sandstone_Brick_Decorative"
    },
    {
      "x": 9,
      "y": 6,
      "z": 2,
      "name": "Rock_Sandstone_Brick_Decorative"
    },
    {
      "x": 9,
      "y": 7,
      "z": 2,
      "name": "Rock_Sandstone_Brick_Smooth_Half"
    },
    {
      "x": 9,
      "y": 6,
      "z": 3,
      "name": "Rock_Sandstone"
    },
    {
      "x": 9,
      "y": 7,
      "z": 3,
      "name": "Rock_Sandstone_Brick"
    },
    {
      "x": 9,
      "y": 8,
      "z": 3,
      "name": "Rock_Sandstone_Brick"
    },
    {
      "x": 9,
      "y": 9,
      "z": 3,
      "name": "Rock_Sandstone_Brick_Pillar_Base",
      "rotation": 8
    },
    {
      "x": 9,
      "y": 6,
      "z": 4,
      "name": "Rock_Sandstone"
    },
    {
      "x": 9,
      "y": 7,
      "z": 4,
      "name": "Rock_Sandstone"
    },
    {
      "x": 9,
      "y": 8,
      "z": 4,
      "name": "Rock_Sandstone"
    },
    {
      "x": 9,
      "y": 6,
      "z": 5,
      "name": "Rock_Sandstone"
    },
    {
      "x": 9,
      "y": 7,
      "z": 5,
      "name": "Rock_Sandstone"
    },
    {
      "x": 9,
      "y": 8,
      "z": 5,
      "name": "Soil_Gravel_Sand_White"
    },
    {
      "x": 9,
      "y": 6,
      "z": 6,
      "name": "Rock_Sandstone"
    },
    {
      "x": 9,
      "y": 7,
      "z": 6,
      "name": "Rock_Sandstone_Brick"
    },
    {
      "x": 9,
      "y": 8,
      "z": 6,
      "name": "Rock_Sandstone_Brick"
    },
    {
      "x": 9,
      "y": 9,
      "z": 6,
      "name": "Rock_Sandstone_Brick_Pillar_Base",
      "rotation": 8
    },
    {
      "x": 9,
      "y": 5,
      "z": 7,
      "name": "Rock_Sandstone_Brick_Decorative"
    },
    {
      "x": 9,
      "y": 6,
      "z": 7,
      "name": "Rock_Sandstone_Brick"
    },
    {
      "x": 9,
      "y": 7,
      "z": 7,
      "name": "Rock_Sandstone_Brick_Smooth_Half"
    },
    {
      "x": 10,
      "y": 2,
      "z": 2,
      "name": "Rock_Sandstone"
    },
    {
      "x": 10,
      "y": 3,
      "z": 2,
      "name": "Rock_Sandstone"
    },
    {
      "x": 10,
      "y": 4,
      "z": 2,
      "name": "Rock_Sandstone"
    },
    {
      "x": 10,
      "y": 5,
      "z": 2,
      "name": "Rock_Sandstone"
    },
    {
      "x": 10,
      "y": 6,
      "z": 2,
      "name": "Rock_Sandstone"
    },
    {
      "x": 10,
      "y": 3,
      "z": 3,
      "name": "Rock_Sandstone"
    },
    {
      "x": 10,
      "y": 4,
      "z": 3,
      "name": "Rock_Sandstone"
    },
    {
      "x": 10,
      "y": 5,
      "z": 3,
      "name": "Rock_Sandstone"
    },
    {
      "x": 10,
      "y": 6,
      "z": 3,
      "name": "Rock_Sandstone"
    },
    {
      "x": 10,
      "y": 7,
      "z": 3,
      "name": "Rock_Sandstone_Brick"
    },
    {
      "x": 10,
      "y": 8,
      "z": 3,
      "name": "Rock_Sandstone_Brick_Stairs",
      "rotation": 1
    },
    {
      "x": 10,
      "y": 9,
      "z": 3,
      "name": "Rock_Sandstone_Brick_Smooth_Half",
      "rotation": 8
    },
    {
      "x": 10,
      "y": 6,
      "z": 4,
      "name": "Rock_Sandstone"
    },
    {
      "x": 10,
      "y": 7,
      "z": 4,
      "name": "Rock_Sandstone"
    },
    {
      "x": 10,
      "y": 8,
      "z": 4,
      "name": "Rock_Sandstone"
    },
    {
      "x": 10,
      "y": 6,
      "z": 5,
      "name": "Rock_Sandstone"
    },
    {
      "x": 10,
      "y": 7,
      "z": 5,
      "name": "Rock_Sandstone"
    },
    {
      "x": 10,
      "y": 8,
      "z": 5,
      "name": "Rock_Sandstone"
    },
    {
      "x": 10,
      "y": 4,
      "z": 6,
      "name": "Rock_Sandstone"
    },
    {
      "x": 10,
      "y": 5,
      "z": 6,
      "name": "Rock_Sandstone"
    },
    {
      "x": 10,
      "y": 6,
      "z": 6,
      "name": "Rock_Sandstone"
    },
    {
      "x": 10,
      "y": 7,
      "z": 6,
      "name": "Rock_Sandstone_Brick"
    },
    {
      "x": 10,
      "y": 8,
      "z": 6,
      "name": "Rock_Sandstone_Brick_Stairs",
      "rotation": 1
    },
    {
      "x": 10,
      "y": 9,
      "z": 6,
      "name": "Rock_Sandstone_Brick_Smooth_Half",
      "rotation": 8
    },
    {
      "x": 10,
      "y": 0,
      "z": 7,
      "name": "Rock_Sandstone"
    },
    {
      "x": 10,
      "y": 1,
      "z": 7,
      "name": "Rock_Sandstone"
    },
    {
      "x": 10,
      "y": 2,
      "z": 7,
      "name": "Rock_Sandstone"
    },
    {
      "x": 10,
      "y": 3,
      "z": 7,
      "name": "Rock_Sandstone"
    },
    {
      "x": 10,
      "y": 4,
      "z": 7,
      "name": "Rock_Sandstone"
    },
    {
      "x": 10,
      "y": 5,
      "z": 7,
      "name": "Rock_Sandstone"
    },
    {
      "x": 10,
      "y": 6,
      "z": 7,
      "name": "Rock_Sandstone"
    },
    {
      "x": 11,
      "y": 2,
      "z": 2,
      "name": "Rock_Sandstone"
    },
    {
      "x": 11,
      "y": 3,
      "z": 2,
      "name": "Rock_Sandstone"
    },
    {
      "x": 11,
      "y": 4,
      "z": 2,
      "name": "Rock_Sandstone"
    },
    {
      "x": 11,
      "y": 5,
      "z": 2,
      "name": "Rock_Sandstone"
    },
    {
      "x": 11,
      "y": 6,
      "z": 2,
      "name": "Rock_Sandstone"
    },
    {
      "x": 11,
      "y": 2,
      "z": 3,
      "name": "Rock_Sandstone"
    },
    {
      "x": 11,
      "y": 3,
      "z": 3,
      "name": "Rock_Sandstone"
    },
    {
      "x": 11,
      "y": 4,
      "z": 3,
      "name": "Rock_Sandstone"
    },
    {
      "x": 11,
      "y": 5,
      "z": 3,
      "name": "Rock_Sandstone"
    },
    {
      "x": 11,
      "y": 6,
      "z": 3,
      "name": "Rock_Sandstone"
    },
    {
      "x": 11,
      "y": 7,
      "z": 3,
      "name": "Rock_Sandstone_Brick"
    },
    {
      "x": 11,
      "y": 8,
      "z": 3,
      "name": "Rock_Sandstone_Brick"
    },
    {
      "x": 11,
      "y": 9,
      "z": 3,
      "name": "Rock_Sandstone_Brick_Pillar_Base",
      "rotation": 8
    },
    {
      "x": 11,
      "y": 6,
      "z": 4,
      "name": "Rock_Sandstone"
    },
    {
      "x": 11,
      "y": 7,
      "z": 4,
      "name": "Rock_Sandstone"
    },
    {
      "x": 11,
      "y": 8,
      "z": 4,
      "name": "Rock_Sandstone"
    },
    {
      "x": 11,
      "y": 6,
      "z": 5,
      "name": "Rock_Sandstone"
    },
    {
      "x": 11,
      "y": 7,
      "z": 5,
      "name": "Rock_Sandstone"
    },
    {
      "x": 11,
      "y": 8,
      "z": 5,
      "name": "Rock_Sandstone"
    },
    {
      "x": 11,
      "y": 0,
      "z": 6,
      "name": "Rock_Sandstone"
    },
    {
      "x": 11,
      "y": 1,
      "z": 6,
      "name": "Rock_Sandstone"
    },
    {
      "x": 11,
      "y": 2,
      "z": 6,
      "name": "Rock_Sandstone"
    },
    {
      "x": 11,
      "y": 3,
      "z": 6,
      "name": "Rock_Sandstone"
    },
    {
      "x": 11,
      "y": 4,
      "z": 6,
      "name": "Rock_Sandstone"
    },
    {
      "x": 11,
      "y": 5,
      "z": 6,
      "name": "Rock_Sandstone"
    },
    {
      "x": 11,
      "y": 6,
      "z": 6,
      "name": "Rock_Sandstone"
    },
    {
      "x": 11,
      "y": 7,
      "z": 6,
      "name": "Rock_Sandstone_Brick"
    },
    {
      "x": 11,
      "y": 8,
      "z": 6,
      "name": "Rock_Sandstone_Brick"
    },
    {
      "x": 11,
      "y": 9,
      "z": 6,
      "name": "Rock_Sandstone_Brick_Pillar_Base",
      "rotation": 8
    },
    {
      "x": 11,
      "y": 0,
      "z": 7,
      "name": "Rock_Sandstone"
    },
    {
      "x": 11,
      "y": 1,
      "z": 7,
      "name": "Rock_Sandstone"
    },
    {
      "x": 11,
      "y": 2,
      "z": 7,
      "name": "Rock_Sandstone"
    },
    {
      "x": 11,
      "y": 3,
      "z": 7,
      "name": "Rock_Sandstone"
    },
    {
      "x": 11,
      "y": 4,
      "z": 7,
      "name": "Rock_Sandstone"
    },
    {
      "x": 11,
      "y": 5,
      "z": 7,
      "name": "Rock_Sandstone"
    },
    {
      "x": 11,
      "y": 6,
      "z": 7,
      "name": "Rock_Sandstone"
    }
  ]
}