{
  "version": 8,
  "blockIdVersion": 3,
  "anchorX": 0,
  "anchorY": 0,
  "anchorZ": 0,
  "blocks": [
    {
      "x": -1,
      "y": 4,
      "z": -1,
      "name": "Plant_Leaves_Oak"
    },
    {
      "x": -1,
      "y": 3,
      "z": 0,
      "name": "Plant_Leaves_Oak"
    },
    {
      "x": -1,
      "y": 4,
      "z": 0,
      "name": "Plant_Leaves_Oak"
    },
    {
      "x": -1,
      "y": 5,
      "z": 0,
      "name": "Plant_Leaves_Oak"
    },
    {
      "x": -1,
      "y": 3,
      "z": 1,
      "name": "Plant_Leaves_Oak"
    },
    {
      "x": 0,
      "y": 3,
      "z": -2,
      "name": "Plant_Leaves_Oak"
    },
    {
      "x": 0,
      "y": 4,
      "z": -2,
      "name": "Plant_Leaves_Oak"
    },
    {
      "x": 0,
      "y": 3,
      "z": -1,
      "name": "Plant_Leaves_Oak"
    },
    {
      "x": 0,
      "y": 4,
      "z": -1,
      "name": "Plant_Leaves_Oak"
    },
    {
      "x": 0,
      "y": 5,
      "z": -1,
      "name": "Plant_Leaves_Oak"
    },
    {
      "x": 0,
      "y": 0,
      "z": 0,
      "name": "Wood_Oak_Branch_Long"
    },
    {
      "x": 0,
      "y": 1,
      "z": 0,
      "name": "Wood_Oak_Branch_Long"
    },
    {
      "x": 0,
      "y": 2,
      "z": 0,
      "name": "Wood_Oak_Branch_Long"
    },
    {
      "x": 0,
      "y": 3,
      "z": 0,
      "name": "Wood_Oak_Branch_Long"
    },
    {
      "x": 0,
      "y": 4,
      "z": 0,
      "name": "Plant_Leaves_Oak"
    },
    {
      "x": 0,
      "y": 5,
      "z": 0,
      "name": "Plant_Leaves_Oak"
    },
    {
      "x": 0,
      "y": 6,
      "z": 0,
      "name": "Plant_Leaves_Oak"
    },
    {
      "x": 0,
      "y": 3,
      "z": 1,
      "name": "Plant_Leaves_Oak"
    },
    {
      "x": 0,
      "y": 4,
      "z": 1,
      "name": "Plant_Leaves_Oak"
    },
    {
      "x": 0,
      "y": 5,
      "z": 1,
      "name": "Plant_Leaves_Oak"
    },
    {
      "x": 0,
      "y": 3,
      "z": 2,
      "name": "Plant_Leaves_Oak"
    },
    {
      "x": 1,
      "y": 3,
      "z": -1,
      "name": "Plant_Leaves_Oak"
    },
    {
      "x": 1,
      "y": 4,
      "z": -1,
      "name": "Plant_Leaves_Oak"
    },
    {
      "x": 1,
      "y": 5,
      "z": -1,
      "name": "Plant_Leaves_Oak"
    },
    {
      "x": 1,
      "y": 3,
      "z": 0,
      "name": "Plant_Leaves_Oak"
    },
    {
      "x": 1,
      "y": 4,
      "z": 0,
      "name": "Plant_Leaves_Oak"
    },
    {
      "x": 1,
      "y": 5,
      "z": 0,
      "name": "Plant_Leaves_Oak"
    },
    {
      "x": 1,
      "y": 3,
      "z": 1,
      "name": "Plant_Leaves_Oak"
    },
    {
      "x": 1,
      "y": 4,
      "z": 1,
      "name": "Plant_Leaves_Oak"
    },
    {
      "x": 1,
      "y": 3,
      "z": 2,
      "name": "Plant_Leaves_Oak"
    },
    {
      "x": 2,
      "y": 4,
      "z": -1,
      "name": "Plant_Leaves_Oak"
    },
    {
      "x": 2,
      "y": 3,
      "z": 0,
      "name": "Plant_Leaves_Oak"
    },
    {
      "x": 2,
      "y": 4,
      "z": 0,
      "name": "Plant_Leaves_Oak"
    }
  ]
}