{
  "version": 8,
  "blockIdVersion": 10,
  "anchorX": -8,
  "anchorY": 17,
  "anchorZ": -2,
  "blocks": [
    {
      "x": -49,
      "y": 12,
      "z": -8,
      "name": "Rock_Stone"
    },
    {
      "x": -49,
      "y": 13,
      "z": -8,
      "name": "Rock_Stone"
    },
    {
      "x": -49,
      "y": 14,
      "z": -8,
      "name": "Rock_Stone"
    },
    {
      "x": -49,
      "y": 15,
      "z": -8,
      "name": "Rock_Stone"
    },
    {
      "x": -49,
      "y": 16,
      "z": -8,
      "name": "Rock_Stone"
    },
    {
      "x": -49,
      "y": 17,
      "z": -8,
      "name": "Rock_Stone"
    },
    {
      "x": -49,
      "y": 18,
      "z": -8,
      "name": "Rock_Stone"
    },
    {
      "x": -49,
      "y": 12,
      "z": -7,
      "name": "Rock_Stone"
    },
    {
      "x": -49,
      "y": 13,
      "z": -7,
      "name": "Rock_Stone"
    },
    {
      "x": -49,
      "y": 14,
      "z": -7,
      "name": "Rock_Stone"
    },
    {
      "x": -49,
      "y": 15,
      "z": -7,
      "name": "Rock_Stone"
    },
    {
      "x": -49,
      "y": 16,
      "z": -7,
      "name": "Rock_Stone"
    },
    {
      "x": -49,
      "y": 17,
      "z": -7,
      "name": "Rock_Stone"
    },
    {
      "x": -49,
      "y": 18,
      "z": -7,
      "name": "Rock_Stone"
    },
    {
      "x": -49,
      "y": 12,
      "z": -6,
      "name": "Rock_Stone"
    },
    {
      "x": -49,
      "y": 13,
      "z": -6,
      "name": "Rock_Stone"
    },
    {
      "x": -49,
      "y": 14,
      "z": -6,
      "name": "Rock_Stone"
    },
    {
      "x": -49,
      "y": 15,
      "z": -6,
      "name": "Rock_Stone"
    },
    {
      "x": -49,
      "y": 16,
      "z": -6,
      "name": "Rock_Stone"
    },
    {
      "x": -49,
      "y": 17,
      "z": -6,
      "name": "Rock_Stone"
    },
    {
      "x": -49,
      "y": 18,
      "z": -6,
      "name": "Rock_Stone"
    },
    {
      "x": -48,
      "y": 12,
      "z": -9,
      "name": "Rock_Stone"
    },
    {
      "x": -48,
      "y": 13,
      "z": -9,
      "name": "Rock_Stone"
    },
    {
      "x": -48,
      "y": 14,
      "z": -9,
      "name": "Rock_Stone"
    },
    {
      "x": -48,
      "y": 15,
      "z": -9,
      "name": "Rock_Stone"
    },
    {
      "x": -48,
      "y": 16,
      "z": -9,
      "name": "Rock_Stone"
    },
    {
      "x": -48,
      "y": 17,
      "z": -9,
      "name": "Rock_Stone"
    },
    {
      "x": -48,
      "y": 18,
      "z": -9,
      "name": "Rock_Stone"
    },
    {
      "x": -48,
      "y": 12,
      "z": -8,
      "name": "Rock_Stone"
    },
    {
      "x": -48,
      "y": 13,
      "z": -8,
      "name": "Rock_Stone"
    },
    {
      "x": -48,
      "y": 14,
      "z": -8,
      "name": "Rock_Stone"
    },
    {
      "x": -48,
      "y": 15,
      "z": -8,
      "name": "Rock_Stone"
    },
    {
      "x": -48,
      "y": 16,
      "z": -8,
      "name": "Rock_Stone"
    },
    {
      "x": -48,
      "y": 17,
      "z": -8,
      "name": "Rock_Stone"
    },
    {
      "x": -48,
      "y": 18,
      "z": -8,
      "name": "Rock_Stone"
    },
    {
      "x": -48,
      "y": 12,
      "z": -7,
      "name": "Rock_Stone"
    },
    {
      "x": -48,
      "y": 13,
      "z": -7,
      "name": "Rock_Stone"
    },
    {
      "x": -48,
      "y": 14,
      "z": -7,
      "name": "Rock_Stone"
    },
    {
      "x": -48,
      "y": 15,
      "z": -7,
      "name": "Rock_Stone"
    },
    {
      "x": -48,
      "y": 16,
      "z": -7,
      "name": "Rock_Stone"
    },
    {
      "x": -48,
      "y": 17,
      "z": -7,
      "name": "Rock_Stone"
    },
    {
      "x": -48,
      "y": 18,
      "z": -7,
      "name": "Rock_Stone"
    },
    {
      "x": -48,
      "y": 12,
      "z": -6,
      "name": "Rock_Stone"
    },
    {
      "x": -48,
      "y": 13,
      "z": -6,
      "name": "Rock_Stone"
    },
    {
      "x": -48,
      "y": 14,
      "z": -6,
      "name": "Rock_Stone"
    },
    {
      "x": -48,
      "y": 15,
      "z": -6,
      "name": "Rock_Stone"
    },
    {
      "x": -48,
      "y": 16,
      "z": -6,
      "name": "Rock_Stone"
    },
    {
      "x": -48,
      "y": 17,
      "z": -6,
      "name": "Rock_Stone"
    },
    {
      "x": -48,
      "y": 18,
      "z": -6,
      "name": "Rock_Stone"
    },
    {
      "x": -48,
      "y": 12,
      "z": -5,
      "name": "Rock_Stone"
    },
    {
      "x": -48,
      "y": 13,
      "z": -5,
      "name": "Rock_Stone"
    },
    {
      "x": -48,
      "y": 14,
      "z": -5,
      "name": "Rock_Stone"
    },
    {
      "x": -48,
      "y": 15,
      "z": -5,
      "name": "Rock_Stone"
    },
    {
      "x": -48,
      "y": 16,
      "z": -5,
      "name": "Rock_Stone"
    },
    {
      "x": -48,
      "y": 17,
      "z": -5,
      "name": "Rock_Stone"
    },
    {
      "x": -48,
      "y": 18,
      "z": -5,
      "name": "Rock_Stone"
    },
    {
      "x": -48,
      "y": 9,
      "z": -4,
      "name": "Rock_Stone"
    },
    {
      "x": -48,
      "y": 10,
      "z": -4,
      "name": "Rock_Stone"
    },
    {
      "x": -48,
      "y": 11,
      "z": -4,
      "name": "Rock_Stone"
    },
    {
      "x": -48,
      "y": 12,
      "z": -4,
      "name": "Rock_Stone"
    },
    {
      "x": -48,
      "y": 13,
      "z": -4,
      "name": "Rock_Stone"
    },
    {
      "x": -48,
      "y": 14,
      "z": -4,
      "name": "Rock_Stone"
    },
    {
      "x": -48,
      "y": 15,
      "z": -4,
      "name": "Rock_Stone"
    },
    {
      "x": -48,
      "y": 9,
      "z": -3,
      "name": "Rock_Stone"
    },
    {
      "x": -48,
      "y": 10,
      "z": -3,
      "name": "Rock_Stone"
    },
    {
      "x": -48,
      "y": 11,
      "z": -3,
      "name": "Rock_Stone"
    },
    {
      "x": -48,
      "y": 12,
      "z": -3,
      "name": "Rock_Stone"
    },
    {
      "x": -48,
      "y": 13,
      "z": -3,
      "name": "Rock_Stone"
    },
    {
      "x": -48,
      "y": 14,
      "z": -3,
      "name": "Rock_Stone"
    },
    {
      "x": -48,
      "y": 15,
      "z": -3,
      "name": "Rock_Stone"
    },
    {
      "x": -48,
      "y": 9,
      "z": -2,
      "name": "Rock_Stone"
    },
    {
      "x": -48,
      "y": 10,
      "z": -2,
      "name": "Rock_Stone"
    },
    {
      "x": -48,
      "y": 11,
      "z": -2,
      "name": "Rock_Stone"
    },
    {
      "x": -48,
      "y": 12,
      "z": -2,
      "name": "Rock_Stone"
    },
    {
      "x": -47,
      "y": 12,
      "z": -9,
      "name": "Rock_Stone"
    },
    {
      "x": -47,
      "y": 13,
      "z": -9,
      "name": "Rock_Stone"
    },
    {
      "x": -47,
      "y": 14,
      "z": -9,
      "name": "Rock_Stone"
    },
    {
      "x": -47,
      "y": 15,
      "z": -9,
      "name": "Rock_Stone"
    },
    {
      "x": -47,
      "y": 16,
      "z": -9,
      "name": "Rock_Stone"
    },
    {
      "x": -47,
      "y": 17,
      "z": -9,
      "name": "Rock_Stone"
    },
    {
      "x": -47,
      "y": 18,
      "z": -9,
      "name": "Rock_Stone"
    },
    {
      "x": -47,
      "y": 12,
      "z": -8,
      "name": "Rock_Stone"
    },
    {
      "x": -47,
      "y": 13,
      "z": -8,
      "name": "Rock_Stone"
    },
    {
      "x": -47,
      "y": 14,
      "z": -8,
      "name": "Rock_Stone"
    },
    {
      "x": -47,
      "y": 15,
      "z": -8,
      "name": "Rock_Stone"
    },
    {
      "x": -47,
      "y": 16,
      "z": -8,
      "name": "Rock_Stone"
    },
    {
      "x": -47,
      "y": 17,
      "z": -8,
      "name": "Rock_Stone"
    },
    {
      "x": -47,
      "y": 18,
      "z": -8,
      "name": "Rock_Stone"
    },
    {
      "x": -47,
      "y": 19,
      "z": -8,
      "name": "Rock_Stone"
    },
    {
      "x": -47,
      "y": 12,
      "z": -7,
      "name": "Rock_Stone"
    },
    {
      "x": -47,
      "y": 13,
      "z": -7,
      "name": "Rock_Stone"
    },
    {
      "x": -47,
      "y": 14,
      "z": -7,
      "name": "Rock_Stone"
    },
    {
      "x": -47,
      "y": 15,
      "z": -7,
      "name": "Rock_Stone"
    },
    {
      "x": -47,
      "y": 16,
      "z": -7,
      "name": "Rock_Stone"
    },
    {
      "x": -47,
      "y": 17,
      "z": -7,
      "name": "Rock_Stone"
    },
    {
      "x": -47,
      "y": 18,
      "z": -7,
      "name": "Rock_Stone"
    },
    {
      "x": -47,
      "y": 19,
      "z": -7,
      "name": "Rock_Stone"
    },
    {
      "x": -47,
      "y": 12,
      "z": -6,
      "name": "Rock_Stone"
    },
    {
      "x": -47,
      "y": 13,
      "z": -6,
      "name": "Rock_Stone"
    },
    {
      "x": -47,
      "y": 14,
      "z": -6,
      "name": "Rock_Stone"
    },
    {
      "x": -47,
      "y": 15,
      "z": -6,
      "name": "Rock_Stone"
    },
    {
      "x": -47,
      "y": 16,
      "z": -6,
      "name": "Rock_Stone"
    },
    {
      "x": -47,
      "y": 17,
      "z": -6,
      "name": "Rock_Stone"
    },
    {
      "x": -47,
      "y": 18,
      "z": -6,
      "name": "Rock_Stone"
    },
    {
      "x": -47,
      "y": 9,
      "z": -5,
      "name": "Rock_Stone"
    },
    {
      "x": -47,
      "y": 10,
      "z": -5,
      "name": "Rock_Stone"
    },
    {
      "x": -47,
      "y": 11,
      "z": -5,
      "name": "Rock_Stone"
    },
    {
      "x": -47,
      "y": 12,
      "z": -5,
      "name": "Rock_Stone"
    },
    {
      "x": -47,
      "y": 13,
      "z": -5,
      "name": "Rock_Stone"
    },
    {
      "x": -47,
      "y": 14,
      "z": -5,
      "name": "Rock_Stone"
    },
    {
      "x": -47,
      "y": 15,
      "z": -5,
      "name": "Rock_Stone"
    },
    {
      "x": -47,
      "y": 16,
      "z": -5,
      "name": "Rock_Stone"
    },
    {
      "x": -47,
      "y": 17,
      "z": -5,
      "name": "Rock_Stone"
    },
    {
      "x": -47,
      "y": 18,
      "z": -5,
      "name": "Rock_Stone"
    },
    {
      "x": -47,
      "y": 9,
      "z": -4,
      "name": "Rock_Stone"
    },
    {
      "x": -47,
      "y": 10,
      "z": -4,
      "name": "Rock_Stone"
    },
    {
      "x": -47,
      "y": 11,
      "z": -4,
      "name": "Rock_Stone"
    },
    {
      "x": -47,
      "y": 12,
      "z": -4,
      "name": "Rock_Stone"
    },
    {
      "x": -47,
      "y": 13,
      "z": -4,
      "name": "Rock_Stone"
    },
    {
      "x": -47,
      "y": 14,
      "z": -4,
      "name": "Rock_Stone"
    },
    {
      "x": -47,
      "y": 15,
      "z": -4,
      "name": "Rock_Stone"
    },
    {
      "x": -47,
      "y": 16,
      "z": -4,
      "name": "Rock_Stone_Mossy"
    },
    {
      "x": -47,
      "y": 17,
      "z": -4,
      "name": "Rock_Stone"
    },
    {
      "x": -47,
      "y": 18,
      "z": -4,
      "name": "Rock_Stone"
    },
    {
      "x": -47,
      "y": 9,
      "z": -3,
      "name": "Rock_Stone"
    },
    {
      "x": -47,
      "y": 10,
      "z": -3,
      "name": "Rock_Stone"
    },
    {
      "x": -47,
      "y": 11,
      "z": -3,
      "name": "Rock_Stone"
    },
    {
      "x": -47,
      "y": 12,
      "z": -3,
      "name": "Rock_Stone"
    },
    {
      "x": -47,
      "y": 13,
      "z": -3,
      "name": "Rock_Stone"
    },
    {
      "x": -47,
      "y": 14,
      "z": -3,
      "name": "Rock_Stone"
    },
    {
      "x": -47,
      "y": 15,
      "z": -3,
      "name": "Rock_Stone_Mossy"
    },
    {
      "x": -47,
      "y": 9,
      "z": -2,
      "name": "Rock_Stone"
    },
    {
      "x": -47,
      "y": 10,
      "z": -2,
      "name": "Rock_Stone"
    },
    {
      "x": -47,
      "y": 11,
      "z": -2,
      "name": "Rock_Stone"
    },
    {
      "x": -47,
      "y": 12,
      "z": -2,
      "name": "Rock_Stone"
    },
    {
      "x": -47,
      "y": 13,
      "z": -2,
      "name": "Rock_Stone"
    },
    {
      "x": -47,
      "y": 14,
      "z": -2,
      "name": "Rock_Stone_Mossy"
    },
    {
      "x": -47,
      "y": 9,
      "z": -1,
      "name": "Rock_Stone"
    },
    {
      "x": -47,
      "y": 10,
      "z": -1,
      "name": "Rock_Stone"
    },
    {
      "x": -47,
      "y": 11,
      "z": -1,
      "name": "Rock_Stone"
    },
    {
      "x": -47,
      "y": 12,
      "z": -1,
      "name": "Rock_Stone"
    },
    {
      "x": -47,
      "y": 13,
      "z": -1,
      "name": "Rock_Stone"
    },
    {
      "x": -47,
      "y": 14,
      "z": -1,
      "name": "Rock_Stone"
    },
    {
      "x": -46,
      "y": 12,
      "z": -10,
      "name": "Rock_Stone"
    },
    {
      "x": -46,
      "y": 13,
      "z": -10,
      "name": "Rock_Stone"
    },
    {
      "x": -46,
      "y": 14,
      "z": -10,
      "name": "Rock_Stone"
    },
    {
      "x": -46,
      "y": 15,
      "z": -10,
      "name": "Rock_Stone"
    },
    {
      "x": -46,
      "y": 16,
      "z": -10,
      "name": "Rock_Stone"
    },
    {
      "x": -46,
      "y": 12,
      "z": -9,
      "name": "Rock_Stone"
    },
    {
      "x": -46,
      "y": 13,
      "z": -9,
      "name": "Rock_Stone"
    },
    {
      "x": -46,
      "y": 14,
      "z": -9,
      "name": "Rock_Stone"
    },
    {
      "x": -46,
      "y": 15,
      "z": -9,
      "name": "Rock_Stone"
    },
    {
      "x": -46,
      "y": 16,
      "z": -9,
      "name": "Rock_Stone"
    },
    {
      "x": -46,
      "y": 17,
      "z": -9,
      "name": "Rock_Stone"
    },
    {
      "x": -46,
      "y": 18,
      "z": -9,
      "name": "Rock_Stone"
    },
    {
      "x": -46,
      "y": 19,
      "z": -9,
      "name": "Rock_Stone"
    },
    {
      "x": -46,
      "y": 12,
      "z": -8,
      "name": "Rock_Stone"
    },
    {
      "x": -46,
      "y": 13,
      "z": -8,
      "name": "Rock_Stone"
    },
    {
      "x": -46,
      "y": 14,
      "z": -8,
      "name": "Rock_Stone"
    },
    {
      "x": -46,
      "y": 15,
      "z": -8,
      "name": "Rock_Stone"
    },
    {
      "x": -46,
      "y": 16,
      "z": -8,
      "name": "Rock_Stone"
    },
    {
      "x": -46,
      "y": 17,
      "z": -8,
      "name": "Rock_Stone"
    },
    {
      "x": -46,
      "y": 18,
      "z": -8,
      "name": "Rock_Stone"
    },
    {
      "x": -46,
      "y": 19,
      "z": -8,
      "name": "Rock_Stone"
    },
    {
      "x": -46,
      "y": 8,
      "z": -7,
      "name": "Rock_Stone"
    },
    {
      "x": -46,
      "y": 9,
      "z": -7,
      "name": "Rock_Stone"
    },
    {
      "x": -46,
      "y": 10,
      "z": -7,
      "name": "Rock_Stone"
    },
    {
      "x": -46,
      "y": 11,
      "z": -7,
      "name": "Rock_Stone"
    },
    {
      "x": -46,
      "y": 12,
      "z": -7,
      "name": "Rock_Stone"
    },
    {
      "x": -46,
      "y": 13,
      "z": -7,
      "name": "Rock_Stone"
    },
    {
      "x": -46,
      "y": 14,
      "z": -7,
      "name": "Rock_Stone"
    },
    {
      "x": -46,
      "y": 15,
      "z": -7,
      "name": "Rock_Stone"
    },
    {
      "x": -46,
      "y": 16,
      "z": -7,
      "name": "Rock_Stone"
    },
    {
      "x": -46,
      "y": 17,
      "z": -7,
      "name": "Rock_Stone"
    },
    {
      "x": -46,
      "y": 18,
      "z": -7,
      "name": "Rock_Stone"
    },
    {
      "x": -46,
      "y": 19,
      "z": -7,
      "name": "Rock_Stone"
    },
    {
      "x": -46,
      "y": 20,
      "z": -7,
      "name": "Rock_Stone"
    },
    {
      "x": -46,
      "y": 8,
      "z": -6,
      "name": "Rock_Stone"
    },
    {
      "x": -46,
      "y": 9,
      "z": -6,
      "name": "Rock_Stone"
    },
    {
      "x": -46,
      "y": 10,
      "z": -6,
      "name": "Rock_Stone"
    },
    {
      "x": -46,
      "y": 11,
      "z": -6,
      "name": "Rock_Stone"
    },
    {
      "x": -46,
      "y": 12,
      "z": -6,
      "name": "Rock_Stone"
    },
    {
      "x": -46,
      "y": 13,
      "z": -6,
      "name": "Rock_Stone"
    },
    {
      "x": -46,
      "y": 14,
      "z": -6,
      "name": "Rock_Stone"
    },
    {
      "x": -46,
      "y": 15,
      "z": -6,
      "name": "Rock_Stone"
    },
    {
      "x": -46,
      "y": 16,
      "z": -6,
      "name": "Rock_Stone"
    },
    {
      "x": -46,
      "y": 17,
      "z": -6,
      "name": "Rock_Stone"
    },
    {
      "x": -46,
      "y": 18,
      "z": -6,
      "name": "Rock_Stone"
    },
    {
      "x": -46,
      "y": 19,
      "z": -6,
      "name": "Rock_Stone"
    },
    {
      "x": -46,
      "y": 20,
      "z": -6,
      "name": "Rock_Stone"
    },
    {
      "x": -46,
      "y": 21,
      "z": -6,
      "name": "Rock_Stone"
    },
    {
      "x": -46,
      "y": 8,
      "z": -5,
      "name": "Rock_Stone"
    },
    {
      "x": -46,
      "y": 9,
      "z": -5,
      "name": "Rock_Stone"
    },
    {
      "x": -46,
      "y": 10,
      "z": -5,
      "name": "Rock_Stone"
    },
    {
      "x": -46,
      "y": 11,
      "z": -5,
      "name": "Rock_Stone"
    },
    {
      "x": -46,
      "y": 12,
      "z": -5,
      "name": "Rock_Stone"
    },
    {
      "x": -46,
      "y": 13,
      "z": -5,
      "name": "Rock_Stone"
    },
    {
      "x": -46,
      "y": 14,
      "z": -5,
      "name": "Rock_Stone"
    },
    {
      "x": -46,
      "y": 15,
      "z": -5,
      "name": "Rock_Stone"
    },
    {
      "x": -46,
      "y": 16,
      "z": -5,
      "name": "Rock_Stone"
    },
    {
      "x": -46,
      "y": 17,
      "z": -5,
      "name": "Rock_Stone"
    },
    {
      "x": -46,
      "y": 18,
      "z": -5,
      "name": "Rock_Stone"
    },
    {
      "x": -46,
      "y": 19,
      "z": -5,
      "name": "Rock_Stone"
    },
    {
      "x": -46,
      "y": 20,
      "z": -5,
      "name": "Rock_Stone_Mossy"
    },
    {
      "x": -46,
      "y": 21,
      "z": -5,
      "name": "Rock_Stone"
    },
    {
      "x": -46,
      "y": 8,
      "z": -4,
      "name": "Rock_Stone"
    },
    {
      "x": -46,
      "y": 9,
      "z": -4,
      "name": "Rock_Stone"
    },
    {
      "x": -46,
      "y": 10,
      "z": -4,
      "name": "Rock_Stone"
    },
    {
      "x": -46,
      "y": 11,
      "z": -4,
      "name": "Rock_Stone"
    },
    {
      "x": -46,
      "y": 12,
      "z": -4,
      "name": "Rock_Stone"
    },
    {
      "x": -46,
      "y": 13,
      "z": -4,
      "name": "Rock_Stone"
    },
    {
      "x": -46,
      "y": 14,
      "z": -4,
      "name": "Rock_Stone"
    },
    {
      "x": -46,
      "y": 15,
      "z": -4,
      "name": "Rock_Stone_Mossy"
    },
    {
      "x": -46,
      "y": 16,
      "z": -4,
      "name": "Rock_Stone_Mossy"
    },
    {
      "x": -46,
      "y": 17,
      "z": -4,
      "name": "Rock_Stone_Mossy"
    },
    {
      "x": -46,
      "y": 18,
      "z": -4,
      "name": "Rock_Stone"
    },
    {
      "x": -46,
      "y": 19,
      "z": -4,
      "name": "Rock_Stone_Mossy"
    },
    {
      "x": -46,
      "y": 20,
      "z": -4,
      "name": "Rock_Stone_Mossy"
    },
    {
      "x": -46,
      "y": 8,
      "z": -3,
      "name": "Rock_Stone"
    },
    {
      "x": -46,
      "y": 9,
      "z": -3,
      "name": "Rock_Stone"
    },
    {
      "x": -46,
      "y": 10,
      "z": -3,
      "name": "Rock_Stone"
    },
    {
      "x": -46,
      "y": 11,
      "z": -3,
      "name": "Rock_Stone"
    },
    {
      "x": -46,
      "y": 12,
      "z": -3,
      "name": "Rock_Stone"
    },
    {
      "x": -46,
      "y": 13,
      "z": -3,
      "name": "Rock_Stone"
    },
    {
      "x": -46,
      "y": 14,
      "z": -3,
      "name": "Rock_Stone_Mossy"
    },
    {
      "x": -46,
      "y": 15,
      "z": -3,
      "name": "Rock_Stone_Mossy"
    },
    {
      "x": -46,
      "y": 16,
      "z": -3,
      "name": "Rock_Stone_Mossy"
    },
    {
      "x": -46,
      "y": 17,
      "z": -3,
      "name": "Rock_Stone_Mossy"
    },
    {
      "x": -46,
      "y": 18,
      "z": -3,
      "name": "Rock_Stone_Mossy"
    },
    {
      "x": -46,
      "y": 19,
      "z": -3,
      "name": "Rock_Stone_Mossy"
    },
    {
      "x": -46,
      "y": 20,
      "z": -3,
      "name": "Rock_Stone_Mossy"
    },
    {
      "x": -46,
      "y": 9,
      "z": -2,
      "name": "Rock_Stone"
    },
    {
      "x": -46,
      "y": 10,
      "z": -2,
      "name": "Rock_Stone"
    },
    {
      "x": -46,
      "y": 11,
      "z": -2,
      "name": "Rock_Stone"
    },
    {
      "x": -46,
      "y": 12,
      "z": -2,
      "name": "Rock_Stone"
    },
    {
      "x": -46,
      "y": 13,
      "z": -2,
      "name": "Rock_Stone"
    },
    {
      "x": -46,
      "y": 14,
      "z": -2,
      "name": "Rock_Stone_Mossy"
    },
    {
      "x": -46,
      "y": 15,
      "z": -2,
      "name": "Rock_Stone_Mossy"
    },
    {
      "x": -46,
      "y": 16,
      "z": -2,
      "name": "Rock_Stone_Mossy"
    },
    {
      "x": -46,
      "y": 9,
      "z": -1,
      "name": "Rock_Stone"
    },
    {
      "x": -46,
      "y": 10,
      "z": -1,
      "name": "Rock_Stone"
    },
    {
      "x": -46,
      "y": 11,
      "z": -1,
      "name": "Rock_Stone"
    },
    {
      "x": -46,
      "y": 12,
      "z": -1,
      "name": "Rock_Stone"
    },
    {
      "x": -46,
      "y": 13,
      "z": -1,
      "name": "Rock_Stone"
    },
    {
      "x": -46,
      "y": 14,
      "z": -1,
      "name": "Rock_Stone_Mossy"
    },
    {
      "x": -46,
      "y": 15,
      "z": -1,
      "name": "Rock_Stone_Mossy"
    },
    {
      "x": -46,
      "y": 16,
      "z": -1,
      "name": "Rock_Stone_Mossy"
    },
    {
      "x": -46,
      "y": 9,
      "z": 0,
      "name": "Rock_Stone"
    },
    {
      "x": -46,
      "y": 10,
      "z": 0,
      "name": "Rock_Stone"
    },
    {
      "x": -46,
      "y": 11,
      "z": 0,
      "name": "Rock_Stone"
    },
    {
      "x": -46,
      "y": 12,
      "z": 0,
      "name": "Rock_Stone"
    },
    {
      "x": -46,
      "y": 13,
      "z": 0,
      "name": "Rock_Stone"
    },
    {
      "x": -46,
      "y": 14,
      "z": 0,
      "name": "Rock_Stone"
    },
    {
      "x": -46,
      "y": 15,
      "z": 0,
      "name": "Rock_Stone_Mossy"
    },
    {
      "x": -46,
      "y": 7,
      "z": 5,
      "name": "Rock_Stone"
    },
    {
      "x": -46,
      "y": 8,
      "z": 5,
      "name": "Rock_Stone"
    },
    {
      "x": -46,
      "y": 9,
      "z": 5,
      "name": "Rock_Stone"
    },
    {
      "x": -46,
      "y": 10,
      "z": 5,
      "name": "Rock_Stone"
    },
    {
      "x": -46,
      "y": 11,
      "z": 5,
      "name": "Rock_Stone"
    },
    {
      "x": -46,
      "y": 12,
      "z": 5,
      "name": "Rock_Stone"
    },
    {
      "x": -46,
      "y": 13,
      "z": 5,
      "name": "Rock_Stone"
    },
    {
      "x": -46,
      "y": 14,
      "z": 5,
      "name": "Rock_Stone"
    },
    {
      "x": -46,
      "y": 7,
      "z": 6,
      "name": "Rock_Stone"
    },
    {
      "x": -46,
      "y": 8,
      "z": 6,
      "name": "Rock_Stone"
    },
    {
      "x": -46,
      "y": 9,
      "z": 6,
      "name": "Rock_Stone"
    },
    {
      "x": -46,
      "y": 10,
      "z": 6,
      "name": "Rock_Stone"
    },
    {
      "x": -46,
      "y": 11,
      "z": 6,
      "name": "Rock_Stone"
    },
    {
      "x": -46,
      "y": 12,
      "z": 6,
      "name": "Rock_Stone"
    },
    {
      "x": -46,
      "y": 13,
      "z": 6,
      "name": "Rock_Stone"
    },
    {
      "x": -46,
      "y": 7,
      "z": 7,
      "name": "Rock_Stone"
    },
    {
      "x": -46,
      "y": 8,
      "z": 7,
      "name": "Rock_Stone"
    },
    {
      "x": -46,
      "y": 9,
      "z": 7,
      "name": "Rock_Stone"
    },
    {
      "x": -46,
      "y": 10,
      "z": 7,
      "name": "Rock_Stone"
    },
    {
      "x": -46,
      "y": 11,
      "z": 7,
      "name": "Rock_Stone"
    },
    {
      "x": -46,
      "y": 12,
      "z": 7,
      "name": "Rock_Stone"
    },
    {
      "x": -46,
      "y": 13,
      "z": 7,
      "name": "Rock_Stone"
    },
    {
      "x": -45,
      "y": 7,
      "z": -12,
      "name": "Rock_Stone"
    },
    {
      "x": -45,
      "y": 8,
      "z": -12,
      "name": "Rock_Stone"
    },
    {
      "x": -45,
      "y": 9,
      "z": -12,
      "name": "Rock_Stone"
    },
    {
      "x": -45,
      "y": 10,
      "z": -12,
      "name": "Rock_Stone"
    },
    {
      "x": -45,
      "y": 11,
      "z": -12,
      "name": "Rock_Stone"
    },
    {
      "x": -45,
      "y": 12,
      "z": -12,
      "name": "Rock_Stone"
    },
    {
      "x": -45,
      "y": 13,
      "z": -12,
      "name": "Rock_Stone"
    },
    {
      "x": -45,
      "y": 7,
      "z": -11,
      "name": "Rock_Stone"
    },
    {
      "x": -45,
      "y": 8,
      "z": -11,
      "name": "Rock_Stone"
    },
    {
      "x": -45,
      "y": 9,
      "z": -11,
      "name": "Rock_Stone"
    },
    {
      "x": -45,
      "y": 10,
      "z": -11,
      "name": "Rock_Stone"
    },
    {
      "x": -45,
      "y": 11,
      "z": -11,
      "name": "Rock_Stone"
    },
    {
      "x": -45,
      "y": 12,
      "z": -11,
      "name": "Rock_Stone"
    },
    {
      "x": -45,
      "y": 13,
      "z": -11,
      "name": "Rock_Stone"
    },
    {
      "x": -45,
      "y": 7,
      "z": -10,
      "name": "Rock_Stone"
    },
    {
      "x": -45,
      "y": 8,
      "z": -10,
      "name": "Rock_Stone"
    },
    {
      "x": -45,
      "y": 9,
      "z": -10,
      "name": "Rock_Stone"
    },
    {
      "x": -45,
      "y": 10,
      "z": -10,
      "name": "Rock_Stone"
    },
    {
      "x": -45,
      "y": 11,
      "z": -10,
      "name": "Rock_Stone"
    },
    {
      "x": -45,
      "y": 12,
      "z": -10,
      "name": "Rock_Stone"
    },
    {
      "x": -45,
      "y": 13,
      "z": -10,
      "name": "Rock_Stone"
    },
    {
      "x": -45,
      "y": 14,
      "z": -10,
      "name": "Rock_Stone"
    },
    {
      "x": -45,
      "y": 15,
      "z": -10,
      "name": "Rock_Stone"
    },
    {
      "x": -45,
      "y": 16,
      "z": -10,
      "name": "Rock_Stone"
    },
    {
      "x": -45,
      "y": 17,
      "z": -10,
      "name": "Rock_Stone"
    },
    {
      "x": -45,
      "y": 8,
      "z": -9,
      "name": "Rock_Stone"
    },
    {
      "x": -45,
      "y": 9,
      "z": -9,
      "name": "Rock_Stone"
    },
    {
      "x": -45,
      "y": 10,
      "z": -9,
      "name": "Rock_Stone"
    },
    {
      "x": -45,
      "y": 11,
      "z": -9,
      "name": "Rock_Stone"
    },
    {
      "x": -45,
      "y": 12,
      "z": -9,
      "name": "Rock_Stone"
    },
    {
      "x": -45,
      "y": 13,
      "z": -9,
      "name": "Rock_Stone"
    },
    {
      "x": -45,
      "y": 14,
      "z": -9,
      "name": "Rock_Stone"
    },
    {
      "x": -45,
      "y": 15,
      "z": -9,
      "name": "Rock_Stone"
    },
    {
      "x": -45,
      "y": 16,
      "z": -9,
      "name": "Rock_Stone"
    },
    {
      "x": -45,
      "y": 17,
      "z": -9,
      "name": "Rock_Stone"
    },
    {
      "x": -45,
      "y": 18,
      "z": -9,
      "name": "Rock_Stone"
    },
    {
      "x": -45,
      "y": 19,
      "z": -9,
      "name": "Rock_Stone"
    },
    {
      "x": -45,
      "y": 8,
      "z": -8,
      "name": "Rock_Stone"
    },
    {
      "x": -45,
      "y": 9,
      "z": -8,
      "name": "Rock_Stone"
    },
    {
      "x": -45,
      "y": 10,
      "z": -8,
      "name": "Rock_Stone"
    },
    {
      "x": -45,
      "y": 11,
      "z": -8,
      "name": "Rock_Stone"
    },
    {
      "x": -45,
      "y": 12,
      "z": -8,
      "name": "Rock_Stone"
    },
    {
      "x": -45,
      "y": 13,
      "z": -8,
      "name": "Rock_Stone"
    },
    {
      "x": -45,
      "y": 14,
      "z": -8,
      "name": "Rock_Stone"
    },
    {
      "x": -45,
      "y": 15,
      "z": -8,
      "name": "Rock_Stone"
    },
    {
      "x": -45,
      "y": 16,
      "z": -8,
      "name": "Rock_Stone"
    },
    {
      "x": -45,
      "y": 17,
      "z": -8,
      "name": "Rock_Stone"
    },
    {
      "x": -45,
      "y": 18,
      "z": -8,
      "name": "Rock_Stone"
    },
    {
      "x": -45,
      "y": 19,
      "z": -8,
      "name": "Rock_Stone"
    },
    {
      "x": -45,
      "y": 8,
      "z": -7,
      "name": "Rock_Stone"
    },
    {
      "x": -45,
      "y": 9,
      "z": -7,
      "name": "Rock_Stone"
    },
    {
      "x": -45,
      "y": 10,
      "z": -7,
      "name": "Rock_Stone"
    },
    {
      "x": -45,
      "y": 11,
      "z": -7,
      "name": "Rock_Stone"
    },
    {
      "x": -45,
      "y": 12,
      "z": -7,
      "name": "Rock_Stone"
    },
    {
      "x": -45,
      "y": 13,
      "z": -7,
      "name": "Rock_Stone"
    },
    {
      "x": -45,
      "y": 14,
      "z": -7,
      "name": "Rock_Stone"
    },
    {
      "x": -45,
      "y": 15,
      "z": -7,
      "name": "Rock_Stone"
    },
    {
      "x": -45,
      "y": 16,
      "z": -7,
      "name": "Rock_Stone"
    },
    {
      "x": -45,
      "y": 17,
      "z": -7,
      "name": "Rock_Stone"
    },
    {
      "x": -45,
      "y": 18,
      "z": -7,
      "name": "Rock_Stone"
    },
    {
      "x": -45,
      "y": 19,
      "z": -7,
      "name": "Rock_Stone"
    },
    {
      "x": -45,
      "y": 20,
      "z": -7,
      "name": "Rock_Stone"
    },
    {
      "x": -45,
      "y": 21,
      "z": -7,
      "name": "Rock_Stone"
    },
    {
      "x": -45,
      "y": 8,
      "z": -6,
      "name": "Rock_Stone"
    },
    {
      "x": -45,
      "y": 9,
      "z": -6,
      "name": "Rock_Stone"
    },
    {
      "x": -45,
      "y": 10,
      "z": -6,
      "name": "Rock_Stone"
    },
    {
      "x": -45,
      "y": 11,
      "z": -6,
      "name": "Rock_Stone"
    },
    {
      "x": -45,
      "y": 12,
      "z": -6,
      "name": "Rock_Stone"
    },
    {
      "x": -45,
      "y": 13,
      "z": -6,
      "name": "Rock_Stone"
    },
    {
      "x": -45,
      "y": 14,
      "z": -6,
      "name": "Rock_Stone"
    },
    {
      "x": -45,
      "y": 15,
      "z": -6,
      "name": "Rock_Stone"
    },
    {
      "x": -45,
      "y": 16,
      "z": -6,
      "name": "Rock_Stone"
    },
    {
      "x": -45,
      "y": 17,
      "z": -6,
      "name": "Rock_Stone"
    },
    {
      "x": -45,
      "y": 18,
      "z": -6,
      "name": "Rock_Stone"
    },
    {
      "x": -45,
      "y": 19,
      "z": -6,
      "name": "Rock_Stone"
    },
    {
      "x": -45,
      "y": 20,
      "z": -6,
      "name": "Rock_Stone"
    },
    {
      "x": -45,
      "y": 21,
      "z": -6,
      "name": "Rock_Stone"
    },
    {
      "x": -45,
      "y": 8,
      "z": -5,
      "name": "Rock_Stone"
    },
    {
      "x": -45,
      "y": 9,
      "z": -5,
      "name": "Rock_Stone"
    },
    {
      "x": -45,
      "y": 10,
      "z": -5,
      "name": "Rock_Stone"
    },
    {
      "x": -45,
      "y": 11,
      "z": -5,
      "name": "Rock_Stone"
    },
    {
      "x": -45,
      "y": 12,
      "z": -5,
      "name": "Rock_Stone"
    },
    {
      "x": -45,
      "y": 13,
      "z": -5,
      "name": "Rock_Stone"
    },
    {
      "x": -45,
      "y": 14,
      "z": -5,
      "name": "Rock_Stone"
    },
    {
      "x": -45,
      "y": 15,
      "z": -5,
      "name": "Rock_Stone"
    },
    {
      "x": -45,
      "y": 16,
      "z": -5,
      "name": "Rock_Stone"
    },
    {
      "x": -45,
      "y": 17,
      "z": -5,
      "name": "Rock_Stone"
    },
    {
      "x": -45,
      "y": 18,
      "z": -5,
      "name": "Rock_Stone"
    },
    {
      "x": -45,
      "y": 19,
      "z": -5,
      "name": "Rock_Stone_Mossy"
    },
    {
      "x": -45,
      "y": 20,
      "z": -5,
      "name": "Rock_Stone_Mossy"
    },
    {
      "x": -45,
      "y": 21,
      "z": -5,
      "name": "Rock_Stone_Mossy"
    },
    {
      "x": -45,
      "y": 22,
      "z": -5,
      "name": "Plant_Moss_Rug_Green"
    },
    {
      "x": -45,
      "y": 8,
      "z": -4,
      "name": "Rock_Stone"
    },
    {
      "x": -45,
      "y": 9,
      "z": -4,
      "name": "Rock_Stone"
    },
    {
      "x": -45,
      "y": 10,
      "z": -4,
      "name": "Rock_Stone"
    },
    {
      "x": -45,
      "y": 11,
      "z": -4,
      "name": "Rock_Stone"
    },
    {
      "x": -45,
      "y": 12,
      "z": -4,
      "name": "Rock_Stone"
    },
    {
      "x": -45,
      "y": 13,
      "z": -4,
      "name": "Rock_Stone"
    },
    {
      "x": -45,
      "y": 14,
      "z": -4,
      "name": "Rock_Stone"
    },
    {
      "x": -45,
      "y": 15,
      "z": -4,
      "name": "Rock_Stone"
    },
    {
      "x": -45,
      "y": 16,
      "z": -4,
      "name": "Rock_Stone_Mossy"
    },
    {
      "x": -45,
      "y": 17,
      "z": -4,
      "name": "Rock_Stone"
    },
    {
      "x": -45,
      "y": 18,
      "z": -4,
      "name": "Rock_Stone_Mossy"
    },
    {
      "x": -45,
      "y": 19,
      "z": -4,
      "name": "Rock_Stone_Mossy"
    },
    {
      "x": -45,
      "y": 20,
      "z": -4,
      "name": "Rock_Stone_Mossy"
    },
    {
      "x": -45,
      "y": 21,
      "z": -4,
      "name": "Plant_Moss_Block_Green"
    },
    {
      "x": -45,
      "y": 22,
      "z": -4,
      "name": "Plant_Moss_Rug_Green"
    },
    {
      "x": -45,
      "y": 8,
      "z": -3,
      "name": "Rock_Stone"
    },
    {
      "x": -45,
      "y": 9,
      "z": -3,
      "name": "Rock_Stone"
    },
    {
      "x": -45,
      "y": 10,
      "z": -3,
      "name": "Rock_Stone"
    },
    {
      "x": -45,
      "y": 11,
      "z": -3,
      "name": "Rock_Stone"
    },
    {
      "x": -45,
      "y": 12,
      "z": -3,
      "name": "Rock_Stone"
    },
    {
      "x": -45,
      "y": 13,
      "z": -3,
      "name": "Rock_Stone"
    },
    {
      "x": -45,
      "y": 14,
      "z": -3,
      "name": "Rock_Stone"
    },
    {
      "x": -45,
      "y": 15,
      "z": -3,
      "name": "Rock_Stone_Mossy"
    },
    {
      "x": -45,
      "y": 16,
      "z": -3,
      "name": "Rock_Stone_Mossy"
    },
    {
      "x": -45,
      "y": 17,
      "z": -3,
      "name": "Rock_Stone_Mossy"
    },
    {
      "x": -45,
      "y": 18,
      "z": -3,
      "name": "Rock_Stone_Mossy"
    },
    {
      "x": -45,
      "y": 19,
      "z": -3,
      "name": "Plant_Moss_Block_Green"
    },
    {
      "x": -45,
      "y": 20,
      "z": -3,
      "name": "Plant_Moss_Block_Green"
    },
    {
      "x": -45,
      "y": 21,
      "z": -3,
      "name": "Plant_Moss_Wall_Green"
    },
    {
      "x": -45,
      "y": 9,
      "z": -2,
      "name": "Rock_Stone"
    },
    {
      "x": -45,
      "y": 10,
      "z": -2,
      "name": "Rock_Stone"
    },
    {
      "x": -45,
      "y": 11,
      "z": -2,
      "name": "Rock_Stone"
    },
    {
      "x": -45,
      "y": 12,
      "z": -2,
      "name": "Rock_Stone"
    },
    {
      "x": -45,
      "y": 13,
      "z": -2,
      "name": "Rock_Stone"
    },
    {
      "x": -45,
      "y": 14,
      "z": -2,
      "name": "Rock_Stone_Mossy"
    },
    {
      "x": -45,
      "y": 15,
      "z": -2,
      "name": "Rock_Stone_Mossy"
    },
    {
      "x": -45,
      "y": 16,
      "z": -2,
      "name": "Rock_Stone_Mossy"
    },
    {
      "x": -45,
      "y": 9,
      "z": -1,
      "name": "Rock_Stone"
    },
    {
      "x": -45,
      "y": 10,
      "z": -1,
      "name": "Rock_Stone"
    },
    {
      "x": -45,
      "y": 11,
      "z": -1,
      "name": "Rock_Stone"
    },
    {
      "x": -45,
      "y": 12,
      "z": -1,
      "name": "Rock_Stone"
    },
    {
      "x": -45,
      "y": 13,
      "z": -1,
      "name": "Rock_Stone"
    },
    {
      "x": -45,
      "y": 14,
      "z": -1,
      "name": "Rock_Stone"
    },
    {
      "x": -45,
      "y": 15,
      "z": -1,
      "name": "Rock_Stone_Mossy"
    },
    {
      "x": -45,
      "y": 16,
      "z": -1,
      "name": "Rock_Stone_Mossy"
    },
    {
      "x": -45,
      "y": 9,
      "z": 0,
      "name": "Rock_Stone"
    },
    {
      "x": -45,
      "y": 10,
      "z": 0,
      "name": "Rock_Stone"
    },
    {
      "x": -45,
      "y": 11,
      "z": 0,
      "name": "Rock_Stone"
    },
    {
      "x": -45,
      "y": 12,
      "z": 0,
      "name": "Rock_Stone"
    },
    {
      "x": -45,
      "y": 13,
      "z": 0,
      "name": "Rock_Stone"
    },
    {
      "x": -45,
      "y": 14,
      "z": 0,
      "name": "Rock_Stone"
    },
    {
      "x": -45,
      "y": 15,
      "z": 0,
      "name": "Rock_Stone"
    },
    {
      "x": -45,
      "y": 16,
      "z": 0,
      "name": "Rock_Stone_Mossy"
    },
    {
      "x": -45,
      "y": 7,
      "z": 4,
      "name": "Rock_Stone"
    },
    {
      "x": -45,
      "y": 8,
      "z": 4,
      "name": "Rock_Stone"
    },
    {
      "x": -45,
      "y": 9,
      "z": 4,
      "name": "Rock_Stone"
    },
    {
      "x": -45,
      "y": 10,
      "z": 4,
      "name": "Rock_Stone"
    },
    {
      "x": -45,
      "y": 11,
      "z": 4,
      "name": "Rock_Stone"
    },
    {
      "x": -45,
      "y": 12,
      "z": 4,
      "name": "Rock_Stone"
    },
    {
      "x": -45,
      "y": 13,
      "z": 4,
      "name": "Rock_Stone"
    },
    {
      "x": -45,
      "y": 14,
      "z": 4,
      "name": "Rock_Stone"
    },
    {
      "x": -45,
      "y": 7,
      "z": 5,
      "name": "Rock_Stone"
    },
    {
      "x": -45,
      "y": 8,
      "z": 5,
      "name": "Rock_Stone"
    },
    {
      "x": -45,
      "y": 9,
      "z": 5,
      "name": "Rock_Stone"
    },
    {
      "x": -45,
      "y": 10,
      "z": 5,
      "name": "Rock_Stone"
    },
    {
      "x": -45,
      "y": 11,
      "z": 5,
      "name": "Rock_Stone"
    },
    {
      "x": -45,
      "y": 12,
      "z": 5,
      "name": "Rock_Stone"
    },
    {
      "x": -45,
      "y": 13,
      "z": 5,
      "name": "Rock_Stone"
    },
    {
      "x": -45,
      "y": 14,
      "z": 5,
      "name": "Rock_Stone"
    },
    {
      "x": -45,
      "y": 7,
      "z": 6,
      "name": "Rock_Stone"
    },
    {
      "x": -45,
      "y": 8,
      "z": 6,
      "name": "Rock_Stone"
    },
    {
      "x": -45,
      "y": 9,
      "z": 6,
      "name": "Rock_Stone"
    },
    {
      "x": -45,
      "y": 10,
      "z": 6,
      "name": "Rock_Stone"
    },
    {
      "x": -45,
      "y": 11,
      "z": 6,
      "name": "Rock_Stone"
    },
    {
      "x": -45,
      "y": 12,
      "z": 6,
      "name": "Rock_Stone"
    },
    {
      "x": -45,
      "y": 13,
      "z": 6,
      "name": "Rock_Stone"
    },
    {
      "x": -45,
      "y": 14,
      "z": 6,
      "name": "Rock_Stone"
    },
    {
      "x": -45,
      "y": 7,
      "z": 7,
      "name": "Rock_Stone"
    },
    {
      "x": -45,
      "y": 8,
      "z": 7,
      "name": "Rock_Stone"
    },
    {
      "x": -45,
      "y": 9,
      "z": 7,
      "name": "Rock_Stone"
    },
    {
      "x": -45,
      "y": 10,
      "z": 7,
      "name": "Rock_Stone"
    },
    {
      "x": -45,
      "y": 11,
      "z": 7,
      "name": "Rock_Stone"
    },
    {
      "x": -45,
      "y": 12,
      "z": 7,
      "name": "Rock_Stone"
    },
    {
      "x": -45,
      "y": 13,
      "z": 7,
      "name": "Rock_Stone"
    },
    {
      "x": -45,
      "y": 7,
      "z": 8,
      "name": "Rock_Stone"
    },
    {
      "x": -45,
      "y": 8,
      "z": 8,
      "name": "Rock_Stone"
    },
    {
      "x": -45,
      "y": 9,
      "z": 8,
      "name": "Rock_Stone"
    },
    {
      "x": -45,
      "y": 10,
      "z": 8,
      "name": "Rock_Stone"
    },
    {
      "x": -44,
      "y": 7,
      "z": -13,
      "name": "Rock_Stone"
    },
    {
      "x": -44,
      "y": 8,
      "z": -13,
      "name": "Rock_Stone"
    },
    {
      "x": -44,
      "y": 9,
      "z": -13,
      "name": "Rock_Stone"
    },
    {
      "x": -44,
      "y": 10,
      "z": -13,
      "name": "Rock_Stone"
    },
    {
      "x": -44,
      "y": 11,
      "z": -13,
      "name": "Rock_Stone"
    },
    {
      "x": -44,
      "y": 12,
      "z": -13,
      "name": "Rock_Stone"
    },
    {
      "x": -44,
      "y": 13,
      "z": -13,
      "name": "Rock_Stone"
    },
    {
      "x": -44,
      "y": 7,
      "z": -12,
      "name": "Rock_Stone"
    },
    {
      "x": -44,
      "y": 8,
      "z": -12,
      "name": "Rock_Stone"
    },
    {
      "x": -44,
      "y": 9,
      "z": -12,
      "name": "Rock_Stone"
    },
    {
      "x": -44,
      "y": 10,
      "z": -12,
      "name": "Rock_Stone"
    },
    {
      "x": -44,
      "y": 11,
      "z": -12,
      "name": "Rock_Stone"
    },
    {
      "x": -44,
      "y": 12,
      "z": -12,
      "name": "Rock_Stone"
    },
    {
      "x": -44,
      "y": 13,
      "z": -12,
      "name": "Rock_Stone"
    },
    {
      "x": -44,
      "y": 7,
      "z": -11,
      "name": "Rock_Stone"
    },
    {
      "x": -44,
      "y": 8,
      "z": -11,
      "name": "Rock_Stone"
    },
    {
      "x": -44,
      "y": 9,
      "z": -11,
      "name": "Rock_Stone"
    },
    {
      "x": -44,
      "y": 10,
      "z": -11,
      "name": "Rock_Stone"
    },
    {
      "x": -44,
      "y": 11,
      "z": -11,
      "name": "Rock_Stone"
    },
    {
      "x": -44,
      "y": 12,
      "z": -11,
      "name": "Rock_Stone"
    },
    {
      "x": -44,
      "y": 13,
      "z": -11,
      "name": "Rock_Stone"
    },
    {
      "x": -44,
      "y": 7,
      "z": -10,
      "name": "Rock_Stone"
    },
    {
      "x": -44,
      "y": 8,
      "z": -10,
      "name": "Rock_Stone"
    },
    {
      "x": -44,
      "y": 9,
      "z": -10,
      "name": "Rock_Stone"
    },
    {
      "x": -44,
      "y": 10,
      "z": -10,
      "name": "Rock_Stone"
    },
    {
      "x": -44,
      "y": 11,
      "z": -10,
      "name": "Rock_Stone"
    },
    {
      "x": -44,
      "y": 12,
      "z": -10,
      "name": "Rock_Stone"
    },
    {
      "x": -44,
      "y": 13,
      "z": -10,
      "name": "Rock_Stone"
    },
    {
      "x": -44,
      "y": 14,
      "z": -10,
      "name": "Soil_Pathway"
    },
    {
      "x": -44,
      "y": 15,
      "z": -10,
      "name": "Soil_Pathway"
    },
    {
      "x": -44,
      "y": 16,
      "z": -10,
      "name": "Soil_Pathway"
    },
    {
      "x": -44,
      "y": 17,
      "z": -10,
      "name": "Soil_Pathway"
    },
    {
      "x": -44,
      "y": 7,
      "z": -9,
      "name": "Rock_Stone"
    },
    {
      "x": -44,
      "y": 8,
      "z": -9,
      "name": "Rock_Stone"
    },
    {
      "x": -44,
      "y": 9,
      "z": -9,
      "name": "Rock_Stone"
    },
    {
      "x": -44,
      "y": 10,
      "z": -9,
      "name": "Rock_Stone"
    },
    {
      "x": -44,
      "y": 11,
      "z": -9,
      "name": "Rock_Stone"
    },
    {
      "x": -44,
      "y": 12,
      "z": -9,
      "name": "Rock_Stone"
    },
    {
      "x": -44,
      "y": 13,
      "z": -9,
      "name": "Rock_Stone"
    },
    {
      "x": -44,
      "y": 14,
      "z": -9,
      "name": "Rock_Stone"
    },
    {
      "x": -44,
      "y": 15,
      "z": -9,
      "name": "Rock_Stone"
    },
    {
      "x": -44,
      "y": 16,
      "z": -9,
      "name": "Rock_Stone"
    },
    {
      "x": -44,
      "y": 17,
      "z": -9,
      "name": "Rock_Stone"
    },
    {
      "x": -44,
      "y": 18,
      "z": -9,
      "name": "Rock_Stone"
    },
    {
      "x": -44,
      "y": 19,
      "z": -9,
      "name": "Rock_Stone"
    },
    {
      "x": -44,
      "y": 8,
      "z": -8,
      "name": "Rock_Stone"
    },
    {
      "x": -44,
      "y": 9,
      "z": -8,
      "name": "Rock_Stone"
    },
    {
      "x": -44,
      "y": 10,
      "z": -8,
      "name": "Rock_Stone"
    },
    {
      "x": -44,
      "y": 11,
      "z": -8,
      "name": "Rock_Stone"
    },
    {
      "x": -44,
      "y": 12,
      "z": -8,
      "name": "Rock_Stone"
    },
    {
      "x": -44,
      "y": 13,
      "z": -8,
      "name": "Rock_Stone"
    },
    {
      "x": -44,
      "y": 14,
      "z": -8,
      "name": "Rock_Stone"
    },
    {
      "x": -44,
      "y": 15,
      "z": -8,
      "name": "Rock_Stone"
    },
    {
      "x": -44,
      "y": 16,
      "z": -8,
      "name": "Rock_Stone"
    },
    {
      "x": -44,
      "y": 17,
      "z": -8,
      "name": "Rock_Stone"
    },
    {
      "x": -44,
      "y": 18,
      "z": -8,
      "name": "Rock_Stone"
    },
    {
      "x": -44,
      "y": 19,
      "z": -8,
      "name": "Rock_Stone"
    },
    {
      "x": -44,
      "y": 20,
      "z": -8,
      "name": "Rock_Stone"
    },
    {
      "x": -44,
      "y": 8,
      "z": -7,
      "name": "Rock_Stone"
    },
    {
      "x": -44,
      "y": 9,
      "z": -7,
      "name": "Rock_Stone"
    },
    {
      "x": -44,
      "y": 10,
      "z": -7,
      "name": "Rock_Stone"
    },
    {
      "x": -44,
      "y": 11,
      "z": -7,
      "name": "Rock_Stone"
    },
    {
      "x": -44,
      "y": 12,
      "z": -7,
      "name": "Rock_Stone"
    },
    {
      "x": -44,
      "y": 13,
      "z": -7,
      "name": "Rock_Stone"
    },
    {
      "x": -44,
      "y": 14,
      "z": -7,
      "name": "Rock_Stone"
    },
    {
      "x": -44,
      "y": 15,
      "z": -7,
      "name": "Rock_Stone"
    },
    {
      "x": -44,
      "y": 16,
      "z": -7,
      "name": "Rock_Stone"
    },
    {
      "x": -44,
      "y": 17,
      "z": -7,
      "name": "Rock_Stone"
    },
    {
      "x": -44,
      "y": 18,
      "z": -7,
      "name": "Rock_Stone"
    },
    {
      "x": -44,
      "y": 19,
      "z": -7,
      "name": "Rock_Stone"
    },
    {
      "x": -44,
      "y": 20,
      "z": -7,
      "name": "Rock_Stone"
    },
    {
      "x": -44,
      "y": 21,
      "z": -7,
      "name": "Rock_Stone"
    },
    {
      "x": -44,
      "y": 8,
      "z": -6,
      "name": "Rock_Stone"
    },
    {
      "x": -44,
      "y": 9,
      "z": -6,
      "name": "Rock_Stone"
    },
    {
      "x": -44,
      "y": 10,
      "z": -6,
      "name": "Rock_Stone"
    },
    {
      "x": -44,
      "y": 11,
      "z": -6,
      "name": "Rock_Stone"
    },
    {
      "x": -44,
      "y": 12,
      "z": -6,
      "name": "Rock_Stone"
    },
    {
      "x": -44,
      "y": 13,
      "z": -6,
      "name": "Rock_Stone"
    },
    {
      "x": -44,
      "y": 14,
      "z": -6,
      "name": "Rock_Stone"
    },
    {
      "x": -44,
      "y": 15,
      "z": -6,
      "name": "Rock_Stone"
    },
    {
      "x": -44,
      "y": 16,
      "z": -6,
      "name": "Rock_Stone"
    },
    {
      "x": -44,
      "y": 17,
      "z": -6,
      "name": "Rock_Stone"
    },
    {
      "x": -44,
      "y": 18,
      "z": -6,
      "name": "Rock_Stone"
    },
    {
      "x": -44,
      "y": 19,
      "z": -6,
      "name": "Rock_Stone"
    },
    {
      "x": -44,
      "y": 20,
      "z": -6,
      "name": "Rock_Stone"
    },
    {
      "x": -44,
      "y": 21,
      "z": -6,
      "name": "Rock_Stone"
    },
    {
      "x": -44,
      "y": 22,
      "z": -6,
      "name": "Plant_Moss_Rug_Green"
    },
    {
      "x": -44,
      "y": 8,
      "z": -5,
      "name": "Rock_Stone"
    },
    {
      "x": -44,
      "y": 9,
      "z": -5,
      "name": "Rock_Stone"
    },
    {
      "x": -44,
      "y": 10,
      "z": -5,
      "name": "Rock_Stone"
    },
    {
      "x": -44,
      "y": 11,
      "z": -5,
      "name": "Rock_Stone"
    },
    {
      "x": -44,
      "y": 12,
      "z": -5,
      "name": "Rock_Stone"
    },
    {
      "x": -44,
      "y": 13,
      "z": -5,
      "name": "Rock_Stone"
    },
    {
      "x": -44,
      "y": 14,
      "z": -5,
      "name": "Rock_Stone"
    },
    {
      "x": -44,
      "y": 15,
      "z": -5,
      "name": "Rock_Stone"
    },
    {
      "x": -44,
      "y": 16,
      "z": -5,
      "name": "Rock_Stone"
    },
    {
      "x": -44,
      "y": 17,
      "z": -5,
      "name": "Rock_Stone"
    },
    {
      "x": -44,
      "y": 18,
      "z": -5,
      "name": "Rock_Stone"
    },
    {
      "x": -44,
      "y": 19,
      "z": -5,
      "name": "Rock_Stone"
    },
    {
      "x": -44,
      "y": 20,
      "z": -5,
      "name": "Rock_Stone_Mossy"
    },
    {
      "x": -44,
      "y": 21,
      "z": -5,
      "name": "Rock_Stone"
    },
    {
      "x": -44,
      "y": 22,
      "z": -5,
      "name": "Plant_Moss_Rug_Green"
    },
    {
      "x": -44,
      "y": 8,
      "z": -4,
      "name": "Rock_Stone"
    },
    {
      "x": -44,
      "y": 9,
      "z": -4,
      "name": "Rock_Stone"
    },
    {
      "x": -44,
      "y": 10,
      "z": -4,
      "name": "Rock_Stone"
    },
    {
      "x": -44,
      "y": 11,
      "z": -4,
      "name": "Rock_Stone"
    },
    {
      "x": -44,
      "y": 12,
      "z": -4,
      "name": "Rock_Stone"
    },
    {
      "x": -44,
      "y": 13,
      "z": -4,
      "name": "Rock_Stone"
    },
    {
      "x": -44,
      "y": 14,
      "z": -4,
      "name": "Rock_Stone"
    },
    {
      "x": -44,
      "y": 15,
      "z": -4,
      "name": "Rock_Stone"
    },
    {
      "x": -44,
      "y": 16,
      "z": -4,
      "name": "Rock_Stone"
    },
    {
      "x": -44,
      "y": 17,
      "z": -4,
      "name": "Rock_Stone"
    },
    {
      "x": -44,
      "y": 18,
      "z": -4,
      "name": "Rock_Stone_Mossy"
    },
    {
      "x": -44,
      "y": 19,
      "z": -4,
      "name": "Rock_Stone_Mossy"
    },
    {
      "x": -44,
      "y": 20,
      "z": -4,
      "name": "Plant_Moss_Block_Green"
    },
    {
      "x": -44,
      "y": 21,
      "z": -4,
      "name": "Plant_Moss_Block_Green"
    },
    {
      "x": -44,
      "y": 8,
      "z": -3,
      "name": "Rock_Stone"
    },
    {
      "x": -44,
      "y": 9,
      "z": -3,
      "name": "Rock_Stone"
    },
    {
      "x": -44,
      "y": 10,
      "z": -3,
      "name": "Rock_Stone"
    },
    {
      "x": -44,
      "y": 11,
      "z": -3,
      "name": "Rock_Stone"
    },
    {
      "x": -44,
      "y": 12,
      "z": -3,
      "name": "Rock_Stone"
    },
    {
      "x": -44,
      "y": 13,
      "z": -3,
      "name": "Rock_Stone"
    },
    {
      "x": -44,
      "y": 14,
      "z": -3,
      "name": "Rock_Stone"
    },
    {
      "x": -44,
      "y": 15,
      "z": -3,
      "name": "Rock_Stone"
    },
    {
      "x": -44,
      "y": 16,
      "z": -3,
      "name": "Rock_Stone_Mossy"
    },
    {
      "x": -44,
      "y": 17,
      "z": -3,
      "name": "Rock_Stone_Mossy"
    },
    {
      "x": -44,
      "y": 18,
      "z": -3,
      "name": "Rock_Stone_Mossy"
    },
    {
      "x": -44,
      "y": 19,
      "z": -3,
      "name": "Plant_Moss_Block_Green"
    },
    {
      "x": -44,
      "y": 8,
      "z": -2,
      "name": "Rock_Stone"
    },
    {
      "x": -44,
      "y": 9,
      "z": -2,
      "name": "Rock_Stone"
    },
    {
      "x": -44,
      "y": 10,
      "z": -2,
      "name": "Rock_Stone"
    },
    {
      "x": -44,
      "y": 11,
      "z": -2,
      "name": "Rock_Stone"
    },
    {
      "x": -44,
      "y": 12,
      "z": -2,
      "name": "Rock_Stone"
    },
    {
      "x": -44,
      "y": 13,
      "z": -2,
      "name": "Rock_Stone"
    },
    {
      "x": -44,
      "y": 14,
      "z": -2,
      "name": "Rock_Stone"
    },
    {
      "x": -44,
      "y": 15,
      "z": -2,
      "name": "Rock_Stone_Mossy"
    },
    {
      "x": -44,
      "y": 16,
      "z": -2,
      "name": "Rock_Stone_Mossy"
    },
    {
      "x": -44,
      "y": 17,
      "z": -2,
      "name": "Rock_Stone_Mossy"
    },
    {
      "x": -44,
      "y": 18,
      "z": -2,
      "name": "Plant_Moss_Block_Green"
    },
    {
      "x": -44,
      "y": 19,
      "z": -2,
      "name": "Plant_Moss_Block_Green"
    },
    {
      "x": -44,
      "y": 8,
      "z": -1,
      "name": "Rock_Stone"
    },
    {
      "x": -44,
      "y": 9,
      "z": -1,
      "name": "Rock_Stone"
    },
    {
      "x": -44,
      "y": 10,
      "z": -1,
      "name": "Rock_Stone"
    },
    {
      "x": -44,
      "y": 11,
      "z": -1,
      "name": "Rock_Stone"
    },
    {
      "x": -44,
      "y": 12,
      "z": -1,
      "name": "Rock_Stone"
    },
    {
      "x": -44,
      "y": 13,
      "z": -1,
      "name": "Rock_Stone"
    },
    {
      "x": -44,
      "y": 14,
      "z": -1,
      "name": "Rock_Stone"
    },
    {
      "x": -44,
      "y": 15,
      "z": -1,
      "name": "Rock_Stone"
    },
    {
      "x": -44,
      "y": 16,
      "z": -1,
      "name": "Rock_Stone_Mossy"
    },
    {
      "x": -44,
      "y": 17,
      "z": -1,
      "name": "Rock_Stone_Mossy"
    },
    {
      "x": -44,
      "y": 18,
      "z": -1,
      "name": "Rock_Stone_Mossy"
    },
    {
      "x": -44,
      "y": 19,
      "z": -1,
      "name": "Rock_Stone_Mossy"
    },
    {
      "x": -44,
      "y": 20,
      "z": -1,
      "name": "Plant_Moss_Rug_Green"
    },
    {
      "x": -44,
      "y": 9,
      "z": 0,
      "name": "Rock_Stone"
    },
    {
      "x": -44,
      "y": 10,
      "z": 0,
      "name": "Rock_Stone"
    },
    {
      "x": -44,
      "y": 11,
      "z": 0,
      "name": "Rock_Stone"
    },
    {
      "x": -44,
      "y": 12,
      "z": 0,
      "name": "Rock_Stone"
    },
    {
      "x": -44,
      "y": 13,
      "z": 0,
      "name": "Rock_Stone"
    },
    {
      "x": -44,
      "y": 14,
      "z": 0,
      "name": "Rock_Stone"
    },
    {
      "x": -44,
      "y": 15,
      "z": 0,
      "name": "Rock_Stone"
    },
    {
      "x": -44,
      "y": 16,
      "z": 0,
      "name": "Rock_Stone"
    },
    {
      "x": -44,
      "y": 7,
      "z": 3,
      "name": "Rock_Stone"
    },
    {
      "x": -44,
      "y": 8,
      "z": 3,
      "name": "Rock_Stone"
    },
    {
      "x": -44,
      "y": 9,
      "z": 3,
      "name": "Rock_Stone"
    },
    {
      "x": -44,
      "y": 10,
      "z": 3,
      "name": "Rock_Stone"
    },
    {
      "x": -44,
      "y": 11,
      "z": 3,
      "name": "Rock_Stone"
    },
    {
      "x": -44,
      "y": 12,
      "z": 3,
      "name": "Rock_Stone"
    },
    {
      "x": -44,
      "y": 13,
      "z": 3,
      "name": "Rock_Stone"
    },
    {
      "x": -44,
      "y": 14,
      "z": 3,
      "name": "Rock_Stone"
    },
    {
      "x": -44,
      "y": 15,
      "z": 3,
      "name": "Rock_Stone"
    },
    {
      "x": -44,
      "y": 16,
      "z": 3,
      "name": "Rock_Stone"
    },
    {
      "x": -44,
      "y": 17,
      "z": 3,
      "name": "Rock_Stone"
    },
    {
      "x": -44,
      "y": 18,
      "z": 3,
      "name": "Rock_Stone"
    },
    {
      "x": -44,
      "y": 19,
      "z": 3,
      "name": "Rock_Stone"
    },
    {
      "x": -44,
      "y": 20,
      "z": 3,
      "name": "Rock_Stone"
    },
    {
      "x": -44,
      "y": 7,
      "z": 4,
      "name": "Rock_Stone"
    },
    {
      "x": -44,
      "y": 8,
      "z": 4,
      "name": "Rock_Stone"
    },
    {
      "x": -44,
      "y": 9,
      "z": 4,
      "name": "Rock_Stone"
    },
    {
      "x": -44,
      "y": 10,
      "z": 4,
      "name": "Rock_Stone"
    },
    {
      "x": -44,
      "y": 11,
      "z": 4,
      "name": "Rock_Stone"
    },
    {
      "x": -44,
      "y": 12,
      "z": 4,
      "name": "Rock_Stone"
    },
    {
      "x": -44,
      "y": 13,
      "z": 4,
      "name": "Rock_Stone"
    },
    {
      "x": -44,
      "y": 14,
      "z": 4,
      "name": "Rock_Stone"
    },
    {
      "x": -44,
      "y": 15,
      "z": 4,
      "name": "Rock_Stone"
    },
    {
      "x": -44,
      "y": 16,
      "z": 4,
      "name": "Rock_Stone"
    },
    {
      "x": -44,
      "y": 17,
      "z": 4,
      "name": "Rock_Stone"
    },
    {
      "x": -44,
      "y": 18,
      "z": 4,
      "name": "Rock_Stone"
    },
    {
      "x": -44,
      "y": 19,
      "z": 4,
      "name": "Rock_Stone"
    },
    {
      "x": -44,
      "y": 20,
      "z": 4,
      "name": "Rock_Stone"
    },
    {
      "x": -44,
      "y": 21,
      "z": 4,
      "name": "Rock_Stone"
    },
    {
      "x": -44,
      "y": 7,
      "z": 5,
      "name": "Rock_Stone"
    },
    {
      "x": -44,
      "y": 8,
      "z": 5,
      "name": "Rock_Stone"
    },
    {
      "x": -44,
      "y": 9,
      "z": 5,
      "name": "Rock_Stone"
    },
    {
      "x": -44,
      "y": 10,
      "z": 5,
      "name": "Rock_Stone"
    },
    {
      "x": -44,
      "y": 11,
      "z": 5,
      "name": "Rock_Stone"
    },
    {
      "x": -44,
      "y": 12,
      "z": 5,
      "name": "Rock_Stone"
    },
    {
      "x": -44,
      "y": 13,
      "z": 5,
      "name": "Rock_Stone"
    },
    {
      "x": -44,
      "y": 14,
      "z": 5,
      "name": "Rock_Stone"
    },
    {
      "x": -44,
      "y": 15,
      "z": 5,
      "name": "Rock_Stone"
    },
    {
      "x": -44,
      "y": 16,
      "z": 5,
      "name": "Rock_Stone"
    },
    {
      "x": -44,
      "y": 17,
      "z": 5,
      "name": "Rock_Stone"
    },
    {
      "x": -44,
      "y": 18,
      "z": 5,
      "name": "Rock_Stone"
    },
    {
      "x": -44,
      "y": 19,
      "z": 5,
      "name": "Rock_Stone"
    },
    {
      "x": -44,
      "y": 20,
      "z": 5,
      "name": "Rock_Stone"
    },
    {
      "x": -44,
      "y": 21,
      "z": 5,
      "name": "Rock_Stone"
    },
    {
      "x": -44,
      "y": 7,
      "z": 6,
      "name": "Rock_Stone"
    },
    {
      "x": -44,
      "y": 8,
      "z": 6,
      "name": "Rock_Stone"
    },
    {
      "x": -44,
      "y": 9,
      "z": 6,
      "name": "Rock_Stone"
    },
    {
      "x": -44,
      "y": 10,
      "z": 6,
      "name": "Rock_Stone"
    },
    {
      "x": -44,
      "y": 11,
      "z": 6,
      "name": "Rock_Stone"
    },
    {
      "x": -44,
      "y": 12,
      "z": 6,
      "name": "Rock_Stone"
    },
    {
      "x": -44,
      "y": 13,
      "z": 6,
      "name": "Rock_Stone"
    },
    {
      "x": -44,
      "y": 14,
      "z": 6,
      "name": "Rock_Stone"
    },
    {
      "x": -44,
      "y": 7,
      "z": 7,
      "name": "Rock_Stone"
    },
    {
      "x": -44,
      "y": 8,
      "z": 7,
      "name": "Rock_Stone"
    },
    {
      "x": -44,
      "y": 9,
      "z": 7,
      "name": "Rock_Stone"
    },
    {
      "x": -44,
      "y": 10,
      "z": 7,
      "name": "Rock_Stone"
    },
    {
      "x": -44,
      "y": 11,
      "z": 7,
      "name": "Rock_Stone"
    },
    {
      "x": -44,
      "y": 12,
      "z": 7,
      "name": "Rock_Stone"
    },
    {
      "x": -44,
      "y": 7,
      "z": 8,
      "name": "Rock_Stone"
    },
    {
      "x": -44,
      "y": 8,
      "z": 8,
      "name": "Rock_Stone"
    },
    {
      "x": -44,
      "y": 9,
      "z": 8,
      "name": "Rock_Stone"
    },
    {
      "x": -44,
      "y": 10,
      "z": 8,
      "name": "Rock_Stone"
    },
    {
      "x": -44,
      "y": 11,
      "z": 8,
      "name": "Rock_Stone"
    },
    {
      "x": -44,
      "y": 12,
      "z": 8,
      "name": "Rock_Stone"
    },
    {
      "x": -44,
      "y": 7,
      "z": 9,
      "name": "Rock_Stone"
    },
    {
      "x": -44,
      "y": 8,
      "z": 9,
      "name": "Rock_Stone"
    },
    {
      "x": -44,
      "y": 9,
      "z": 9,
      "name": "Rock_Stone"
    },
    {
      "x": -44,
      "y": 10,
      "z": 9,
      "name": "Rock_Stone"
    },
    {
      "x": -44,
      "y": 11,
      "z": 9,
      "name": "Rock_Stone"
    },
    {
      "x": -44,
      "y": 12,
      "z": 9,
      "name": "Rock_Stone"
    },
    {
      "x": -43,
      "y": 7,
      "z": -14,
      "name": "Rock_Stone"
    },
    {
      "x": -43,
      "y": 8,
      "z": -14,
      "name": "Rock_Stone"
    },
    {
      "x": -43,
      "y": 9,
      "z": -14,
      "name": "Rock_Stone"
    },
    {
      "x": -43,
      "y": 10,
      "z": -14,
      "name": "Rock_Stone"
    },
    {
      "x": -43,
      "y": 11,
      "z": -14,
      "name": "Rock_Stone"
    },
    {
      "x": -43,
      "y": 12,
      "z": -14,
      "name": "Rock_Stone"
    },
    {
      "x": -43,
      "y": 13,
      "z": -14,
      "name": "Rock_Stone"
    },
    {
      "x": -43,
      "y": 14,
      "z": -14,
      "name": "Rock_Stone"
    },
    {
      "x": -43,
      "y": 7,
      "z": -13,
      "name": "Rock_Stone"
    },
    {
      "x": -43,
      "y": 8,
      "z": -13,
      "name": "Rock_Stone"
    },
    {
      "x": -43,
      "y": 9,
      "z": -13,
      "name": "Rock_Stone"
    },
    {
      "x": -43,
      "y": 10,
      "z": -13,
      "name": "Rock_Stone"
    },
    {
      "x": -43,
      "y": 11,
      "z": -13,
      "name": "Rock_Stone"
    },
    {
      "x": -43,
      "y": 12,
      "z": -13,
      "name": "Rock_Stone"
    },
    {
      "x": -43,
      "y": 13,
      "z": -13,
      "name": "Rock_Stone"
    },
    {
      "x": -43,
      "y": 14,
      "z": -13,
      "name": "Rock_Stone"
    },
    {
      "x": -43,
      "y": 7,
      "z": -12,
      "name": "Rock_Stone"
    },
    {
      "x": -43,
      "y": 8,
      "z": -12,
      "name": "Rock_Stone"
    },
    {
      "x": -43,
      "y": 9,
      "z": -12,
      "name": "Rock_Stone"
    },
    {
      "x": -43,
      "y": 10,
      "z": -12,
      "name": "Rock_Stone"
    },
    {
      "x": -43,
      "y": 11,
      "z": -12,
      "name": "Rock_Stone"
    },
    {
      "x": -43,
      "y": 12,
      "z": -12,
      "name": "Rock_Stone"
    },
    {
      "x": -43,
      "y": 13,
      "z": -12,
      "name": "Rock_Stone"
    },
    {
      "x": -43,
      "y": 7,
      "z": -11,
      "name": "Rock_Stone"
    },
    {
      "x": -43,
      "y": 8,
      "z": -11,
      "name": "Rock_Stone"
    },
    {
      "x": -43,
      "y": 9,
      "z": -11,
      "name": "Rock_Stone"
    },
    {
      "x": -43,
      "y": 10,
      "z": -11,
      "name": "Rock_Stone"
    },
    {
      "x": -43,
      "y": 11,
      "z": -11,
      "name": "Rock_Stone"
    },
    {
      "x": -43,
      "y": 12,
      "z": -11,
      "name": "Rock_Stone"
    },
    {
      "x": -43,
      "y": 13,
      "z": -11,
      "name": "Rock_Stone"
    },
    {
      "x": -43,
      "y": 7,
      "z": -10,
      "name": "Rock_Stone"
    },
    {
      "x": -43,
      "y": 8,
      "z": -10,
      "name": "Rock_Stone"
    },
    {
      "x": -43,
      "y": 9,
      "z": -10,
      "name": "Rock_Stone"
    },
    {
      "x": -43,
      "y": 10,
      "z": -10,
      "name": "Rock_Stone"
    },
    {
      "x": -43,
      "y": 11,
      "z": -10,
      "name": "Rock_Stone"
    },
    {
      "x": -43,
      "y": 12,
      "z": -10,
      "name": "Rock_Stone"
    },
    {
      "x": -43,
      "y": 13,
      "z": -10,
      "name": "Rock_Stone"
    },
    {
      "x": -43,
      "y": 14,
      "z": -10,
      "name": "Soil_Pathway"
    },
    {
      "x": -43,
      "y": 15,
      "z": -10,
      "name": "Soil_Pathway"
    },
    {
      "x": -43,
      "y": 16,
      "z": -10,
      "name": "Soil_Pathway"
    },
    {
      "x": -43,
      "y": 17,
      "z": -10,
      "name": "Soil_Dirt"
    },
    {
      "x": -43,
      "y": 18,
      "z": -10,
      "name": "Soil_Dirt"
    },
    {
      "x": -43,
      "y": 7,
      "z": -9,
      "name": "Rock_Stone"
    },
    {
      "x": -43,
      "y": 8,
      "z": -9,
      "name": "Rock_Stone"
    },
    {
      "x": -43,
      "y": 9,
      "z": -9,
      "name": "Rock_Stone"
    },
    {
      "x": -43,
      "y": 10,
      "z": -9,
      "name": "Rock_Stone"
    },
    {
      "x": -43,
      "y": 11,
      "z": -9,
      "name": "Rock_Stone"
    },
    {
      "x": -43,
      "y": 12,
      "z": -9,
      "name": "Rock_Stone"
    },
    {
      "x": -43,
      "y": 13,
      "z": -9,
      "name": "Rock_Stone"
    },
    {
      "x": -43,
      "y": 14,
      "z": -9,
      "name": "Rock_Stone"
    },
    {
      "x": -43,
      "y": 15,
      "z": -9,
      "name": "Soil_Dirt"
    },
    {
      "x": -43,
      "y": 16,
      "z": -9,
      "name": "Soil_Dirt"
    },
    {
      "x": -43,
      "y": 17,
      "z": -9,
      "name": "Soil_Dirt"
    },
    {
      "x": -43,
      "y": 18,
      "z": -9,
      "name": "Soil_Dirt"
    },
    {
      "x": -43,
      "y": 19,
      "z": -9,
      "name": "Empty"
    },
    {
      "x": -43,
      "y": 20,
      "z": -9,
      "name": "Empty"
    },
    {
      "x": -43,
      "y": 21,
      "z": -9,
      "name": "Empty"
    },
    {
      "x": -43,
      "y": 22,
      "z": -9,
      "name": "Empty"
    },
    {
      "x": -43,
      "y": 23,
      "z": -9,
      "name": "Empty"
    },
    {
      "x": -43,
      "y": 24,
      "z": -9,
      "name": "Empty"
    },
    {
      "x": -43,
      "y": 25,
      "z": -9,
      "name": "Empty"
    },
    {
      "x": -43,
      "y": 26,
      "z": -9,
      "name": "Empty"
    },
    {
      "x": -43,
      "y": 27,
      "z": -9,
      "name": "Empty"
    },
    {
      "x": -43,
      "y": 28,
      "z": -9,
      "name": "Empty"
    },
    {
      "x": -43,
      "y": 29,
      "z": -9,
      "name": "Empty"
    },
    {
      "x": -43,
      "y": 30,
      "z": -9,
      "name": "Empty"
    },
    {
      "x": -43,
      "y": 31,
      "z": -9,
      "name": "Empty"
    },
    {
      "x": -43,
      "y": 32,
      "z": -9,
      "name": "Empty"
    },
    {
      "x": -43,
      "y": 33,
      "z": -9,
      "name": "Empty"
    },
    {
      "x": -43,
      "y": 34,
      "z": -9,
      "name": "Empty"
    },
    {
      "x": -43,
      "y": 35,
      "z": -9,
      "name": "Empty"
    },
    {
      "x": -43,
      "y": 36,
      "z": -9,
      "name": "Empty"
    },
    {
      "x": -43,
      "y": 37,
      "z": -9,
      "name": "Empty"
    },
    {
      "x": -43,
      "y": 7,
      "z": -8,
      "name": "Rock_Stone"
    },
    {
      "x": -43,
      "y": 8,
      "z": -8,
      "name": "Rock_Stone"
    },
    {
      "x": -43,
      "y": 9,
      "z": -8,
      "name": "Rock_Stone"
    },
    {
      "x": -43,
      "y": 10,
      "z": -8,
      "name": "Rock_Stone"
    },
    {
      "x": -43,
      "y": 11,
      "z": -8,
      "name": "Rock_Stone"
    },
    {
      "x": -43,
      "y": 12,
      "z": -8,
      "name": "Rock_Stone"
    },
    {
      "x": -43,
      "y": 13,
      "z": -8,
      "name": "Rock_Stone"
    },
    {
      "x": -43,
      "y": 14,
      "z": -8,
      "name": "Rock_Stone"
    },
    {
      "x": -43,
      "y": 15,
      "z": -8,
      "name": "Rock_Stone"
    },
    {
      "x": -43,
      "y": 16,
      "z": -8,
      "name": "Rock_Stone"
    },
    {
      "x": -43,
      "y": 17,
      "z": -8,
      "name": "Rock_Stone"
    },
    {
      "x": -43,
      "y": 18,
      "z": -8,
      "name": "Rock_Stone"
    },
    {
      "x": -43,
      "y": 19,
      "z": -8,
      "name": "Rock_Stone"
    },
    {
      "x": -43,
      "y": 20,
      "z": -8,
      "name": "Empty"
    },
    {
      "x": -43,
      "y": 21,
      "z": -8,
      "name": "Empty"
    },
    {
      "x": -43,
      "y": 22,
      "z": -8,
      "name": "Empty"
    },
    {
      "x": -43,
      "y": 23,
      "z": -8,
      "name": "Empty"
    },
    {
      "x": -43,
      "y": 24,
      "z": -8,
      "name": "Empty"
    },
    {
      "x": -43,
      "y": 25,
      "z": -8,
      "name": "Empty"
    },
    {
      "x": -43,
      "y": 26,
      "z": -8,
      "name": "Empty"
    },
    {
      "x": -43,
      "y": 27,
      "z": -8,
      "name": "Empty"
    },
    {
      "x": -43,
      "y": 28,
      "z": -8,
      "name": "Empty"
    },
    {
      "x": -43,
      "y": 29,
      "z": -8,
      "name": "Empty"
    },
    {
      "x": -43,
      "y": 30,
      "z": -8,
      "name": "Empty"
    },
    {
      "x": -43,
      "y": 31,
      "z": -8,
      "name": "Empty"
    },
    {
      "x": -43,
      "y": 32,
      "z": -8,
      "name": "Empty"
    },
    {
      "x": -43,
      "y": 33,
      "z": -8,
      "name": "Empty"
    },
    {
      "x": -43,
      "y": 34,
      "z": -8,
      "name": "Empty"
    },
    {
      "x": -43,
      "y": 35,
      "z": -8,
      "name": "Empty"
    },
    {
      "x": -43,
      "y": 36,
      "z": -8,
      "name": "Empty"
    },
    {
      "x": -43,
      "y": 37,
      "z": -8,
      "name": "Empty"
    },
    {
      "x": -43,
      "y": 8,
      "z": -7,
      "name": "Soil_Pathway"
    },
    {
      "x": -43,
      "y": 9,
      "z": -7,
      "name": "Soil_Pathway"
    },
    {
      "x": -43,
      "y": 10,
      "z": -7,
      "name": "Soil_Pathway"
    },
    {
      "x": -43,
      "y": 11,
      "z": -7,
      "name": "Soil_Pathway"
    },
    {
      "x": -43,
      "y": 12,
      "z": -7,
      "name": "Rock_Stone"
    },
    {
      "x": -43,
      "y": 13,
      "z": -7,
      "name": "Rock_Stone"
    },
    {
      "x": -43,
      "y": 14,
      "z": -7,
      "name": "Rock_Stone"
    },
    {
      "x": -43,
      "y": 15,
      "z": -7,
      "name": "Rock_Stone"
    },
    {
      "x": -43,
      "y": 16,
      "z": -7,
      "name": "Rock_Stone"
    },
    {
      "x": -43,
      "y": 17,
      "z": -7,
      "name": "Rock_Stone"
    },
    {
      "x": -43,
      "y": 18,
      "z": -7,
      "name": "Rock_Stone"
    },
    {
      "x": -43,
      "y": 19,
      "z": -7,
      "name": "Rock_Stone"
    },
    {
      "x": -43,
      "y": 20,
      "z": -7,
      "name": "Empty"
    },
    {
      "x": -43,
      "y": 21,
      "z": -7,
      "name": "Empty"
    },
    {
      "x": -43,
      "y": 22,
      "z": -7,
      "name": "Empty"
    },
    {
      "x": -43,
      "y": 23,
      "z": -7,
      "name": "Empty"
    },
    {
      "x": -43,
      "y": 24,
      "z": -7,
      "name": "Empty"
    },
    {
      "x": -43,
      "y": 25,
      "z": -7,
      "name": "Empty"
    },
    {
      "x": -43,
      "y": 26,
      "z": -7,
      "name": "Empty"
    },
    {
      "x": -43,
      "y": 27,
      "z": -7,
      "name": "Empty"
    },
    {
      "x": -43,
      "y": 28,
      "z": -7,
      "name": "Empty"
    },
    {
      "x": -43,
      "y": 29,
      "z": -7,
      "name": "Empty"
    },
    {
      "x": -43,
      "y": 30,
      "z": -7,
      "name": "Empty"
    },
    {
      "x": -43,
      "y": 31,
      "z": -7,
      "name": "Empty"
    },
    {
      "x": -43,
      "y": 32,
      "z": -7,
      "name": "Empty"
    },
    {
      "x": -43,
      "y": 33,
      "z": -7,
      "name": "Empty"
    },
    {
      "x": -43,
      "y": 34,
      "z": -7,
      "name": "Empty"
    },
    {
      "x": -43,
      "y": 35,
      "z": -7,
      "name": "Empty"
    },
    {
      "x": -43,
      "y": 36,
      "z": -7,
      "name": "Empty"
    },
    {
      "x": -43,
      "y": 37,
      "z": -7,
      "name": "Empty"
    },
    {
      "x": -43,
      "y": 8,
      "z": -6,
      "name": "Rock_Stone"
    },
    {
      "x": -43,
      "y": 9,
      "z": -6,
      "name": "Rock_Stone"
    },
    {
      "x": -43,
      "y": 10,
      "z": -6,
      "name": "Rock_Stone"
    },
    {
      "x": -43,
      "y": 11,
      "z": -6,
      "name": "Rock_Stone"
    },
    {
      "x": -43,
      "y": 12,
      "z": -6,
      "name": "Rock_Stone"
    },
    {
      "x": -43,
      "y": 13,
      "z": -6,
      "name": "Rock_Stone"
    },
    {
      "x": -43,
      "y": 14,
      "z": -6,
      "name": "Rock_Stone"
    },
    {
      "x": -43,
      "y": 15,
      "z": -6,
      "name": "Rock_Stone"
    },
    {
      "x": -43,
      "y": 16,
      "z": -6,
      "name": "Rock_Stone"
    },
    {
      "x": -43,
      "y": 17,
      "z": -6,
      "name": "Rock_Stone"
    },
    {
      "x": -43,
      "y": 18,
      "z": -6,
      "name": "Rock_Stone"
    },
    {
      "x": -43,
      "y": 19,
      "z": -6,
      "name": "Rock_Stone"
    },
    {
      "x": -43,
      "y": 20,
      "z": -6,
      "name": "Rock_Stone"
    },
    {
      "x": -43,
      "y": 21,
      "z": -6,
      "name": "Plant_Moss_Wall_Green",
      "rotation": 1
    },
    {
      "x": -43,
      "y": 22,
      "z": -6,
      "name": "Empty"
    },
    {
      "x": -43,
      "y": 23,
      "z": -6,
      "name": "Empty"
    },
    {
      "x": -43,
      "y": 24,
      "z": -6,
      "name": "Empty"
    },
    {
      "x": -43,
      "y": 25,
      "z": -6,
      "name": "Empty"
    },
    {
      "x": -43,
      "y": 26,
      "z": -6,
      "name": "Empty"
    },
    {
      "x": -43,
      "y": 27,
      "z": -6,
      "name": "Empty"
    },
    {
      "x": -43,
      "y": 28,
      "z": -6,
      "name": "Empty"
    },
    {
      "x": -43,
      "y": 29,
      "z": -6,
      "name": "Empty"
    },
    {
      "x": -43,
      "y": 30,
      "z": -6,
      "name": "Empty"
    },
    {
      "x": -43,
      "y": 31,
      "z": -6,
      "name": "Empty"
    },
    {
      "x": -43,
      "y": 32,
      "z": -6,
      "name": "Empty"
    },
    {
      "x": -43,
      "y": 33,
      "z": -6,
      "name": "Empty"
    },
    {
      "x": -43,
      "y": 34,
      "z": -6,
      "name": "Empty"
    },
    {
      "x": -43,
      "y": 35,
      "z": -6,
      "name": "Empty"
    },
    {
      "x": -43,
      "y": 36,
      "z": -6,
      "name": "Empty"
    },
    {
      "x": -43,
      "y": 37,
      "z": -6,
      "name": "Empty"
    },
    {
      "x": -43,
      "y": 8,
      "z": -5,
      "name": "Rock_Stone"
    },
    {
      "x": -43,
      "y": 9,
      "z": -5,
      "name": "Rock_Stone"
    },
    {
      "x": -43,
      "y": 10,
      "z": -5,
      "name": "Rock_Stone"
    },
    {
      "x": -43,
      "y": 11,
      "z": -5,
      "name": "Rock_Stone"
    },
    {
      "x": -43,
      "y": 12,
      "z": -5,
      "name": "Rock_Stone"
    },
    {
      "x": -43,
      "y": 13,
      "z": -5,
      "name": "Rock_Stone"
    },
    {
      "x": -43,
      "y": 14,
      "z": -5,
      "name": "Rock_Stone"
    },
    {
      "x": -43,
      "y": 15,
      "z": -5,
      "name": "Rock_Stone"
    },
    {
      "x": -43,
      "y": 16,
      "z": -5,
      "name": "Rock_Stone"
    },
    {
      "x": -43,
      "y": 17,
      "z": -5,
      "name": "Rock_Stone"
    },
    {
      "x": -43,
      "y": 18,
      "z": -5,
      "name": "Rock_Stone"
    },
    {
      "x": -43,
      "y": 19,
      "z": -5,
      "name": "Rock_Stone"
    },
    {
      "x": -43,
      "y": 20,
      "z": -5,
      "name": "Rock_Stone"
    },
    {
      "x": -43,
      "y": 21,
      "z": -5,
      "name": "Rock_Stone"
    },
    {
      "x": -43,
      "y": 22,
      "z": -5,
      "name": "Empty"
    },
    {
      "x": -43,
      "y": 23,
      "z": -5,
      "name": "Empty"
    },
    {
      "x": -43,
      "y": 24,
      "z": -5,
      "name": "Empty"
    },
    {
      "x": -43,
      "y": 25,
      "z": -5,
      "name": "Empty"
    },
    {
      "x": -43,
      "y": 26,
      "z": -5,
      "name": "Empty"
    },
    {
      "x": -43,
      "y": 27,
      "z": -5,
      "name": "Empty"
    },
    {
      "x": -43,
      "y": 28,
      "z": -5,
      "name": "Empty"
    },
    {
      "x": -43,
      "y": 29,
      "z": -5,
      "name": "Empty"
    },
    {
      "x": -43,
      "y": 30,
      "z": -5,
      "name": "Empty"
    },
    {
      "x": -43,
      "y": 31,
      "z": -5,
      "name": "Empty"
    },
    {
      "x": -43,
      "y": 32,
      "z": -5,
      "name": "Empty"
    },
    {
      "x": -43,
      "y": 33,
      "z": -5,
      "name": "Empty"
    },
    {
      "x": -43,
      "y": 34,
      "z": -5,
      "name": "Empty"
    },
    {
      "x": -43,
      "y": 35,
      "z": -5,
      "name": "Empty"
    },
    {
      "x": -43,
      "y": 36,
      "z": -5,
      "name": "Empty"
    },
    {
      "x": -43,
      "y": 37,
      "z": -5,
      "name": "Empty"
    },
    {
      "x": -43,
      "y": 8,
      "z": -4,
      "name": "Rock_Stone"
    },
    {
      "x": -43,
      "y": 9,
      "z": -4,
      "name": "Rock_Stone"
    },
    {
      "x": -43,
      "y": 10,
      "z": -4,
      "name": "Rock_Stone"
    },
    {
      "x": -43,
      "y": 11,
      "z": -4,
      "name": "Rock_Stone"
    },
    {
      "x": -43,
      "y": 12,
      "z": -4,
      "name": "Rock_Stone"
    },
    {
      "x": -43,
      "y": 13,
      "z": -4,
      "name": "Rock_Stone"
    },
    {
      "x": -43,
      "y": 14,
      "z": -4,
      "name": "Rock_Stone"
    },
    {
      "x": -43,
      "y": 15,
      "z": -4,
      "name": "Rock_Stone"
    },
    {
      "x": -43,
      "y": 16,
      "z": -4,
      "name": "Rock_Stone"
    },
    {
      "x": -43,
      "y": 17,
      "z": -4,
      "name": "Rock_Stone"
    },
    {
      "x": -43,
      "y": 18,
      "z": -4,
      "name": "Rock_Stone"
    },
    {
      "x": -43,
      "y": 19,
      "z": -4,
      "name": "Rock_Stone_Mossy"
    },
    {
      "x": -43,
      "y": 20,
      "z": -4,
      "name": "Rock_Stone_Mossy"
    },
    {
      "x": -43,
      "y": 21,
      "z": -4,
      "name": "Rock_Stone"
    },
    {
      "x": -43,
      "y": 22,
      "z": -4,
      "name": "Empty"
    },
    {
      "x": -43,
      "y": 23,
      "z": -4,
      "name": "Empty"
    },
    {
      "x": -43,
      "y": 24,
      "z": -4,
      "name": "Empty"
    },
    {
      "x": -43,
      "y": 25,
      "z": -4,
      "name": "Empty"
    },
    {
      "x": -43,
      "y": 26,
      "z": -4,
      "name": "Empty"
    },
    {
      "x": -43,
      "y": 27,
      "z": -4,
      "name": "Empty"
    },
    {
      "x": -43,
      "y": 28,
      "z": -4,
      "name": "Empty"
    },
    {
      "x": -43,
      "y": 29,
      "z": -4,
      "name": "Empty"
    },
    {
      "x": -43,
      "y": 30,
      "z": -4,
      "name": "Empty"
    },
    {
      "x": -43,
      "y": 31,
      "z": -4,
      "name": "Empty"
    },
    {
      "x": -43,
      "y": 32,
      "z": -4,
      "name": "Empty"
    },
    {
      "x": -43,
      "y": 33,
      "z": -4,
      "name": "Empty"
    },
    {
      "x": -43,
      "y": 34,
      "z": -4,
      "name": "Empty"
    },
    {
      "x": -43,
      "y": 35,
      "z": -4,
      "name": "Empty"
    },
    {
      "x": -43,
      "y": 36,
      "z": -4,
      "name": "Empty"
    },
    {
      "x": -43,
      "y": 37,
      "z": -4,
      "name": "Empty"
    },
    {
      "x": -43,
      "y": 8,
      "z": -3,
      "name": "Rock_Stone"
    },
    {
      "x": -43,
      "y": 9,
      "z": -3,
      "name": "Rock_Stone"
    },
    {
      "x": -43,
      "y": 10,
      "z": -3,
      "name": "Rock_Stone"
    },
    {
      "x": -43,
      "y": 11,
      "z": -3,
      "name": "Rock_Stone"
    },
    {
      "x": -43,
      "y": 12,
      "z": -3,
      "name": "Rock_Stone"
    },
    {
      "x": -43,
      "y": 13,
      "z": -3,
      "name": "Rock_Stone"
    },
    {
      "x": -43,
      "y": 14,
      "z": -3,
      "name": "Rock_Stone"
    },
    {
      "x": -43,
      "y": 15,
      "z": -3,
      "name": "Rock_Stone"
    },
    {
      "x": -43,
      "y": 16,
      "z": -3,
      "name": "Rock_Stone"
    },
    {
      "x": -43,
      "y": 17,
      "z": -3,
      "name": "Rock_Stone"
    },
    {
      "x": -43,
      "y": 18,
      "z": -3,
      "name": "Rock_Stone_Mossy"
    },
    {
      "x": -43,
      "y": 19,
      "z": -3,
      "name": "Plant_Moss_Block_Green"
    },
    {
      "x": -43,
      "y": 20,
      "z": -3,
      "name": "Plant_Moss_Rug_Green"
    },
    {
      "x": -43,
      "y": 21,
      "z": -3,
      "name": "Empty"
    },
    {
      "x": -43,
      "y": 22,
      "z": -3,
      "name": "Empty"
    },
    {
      "x": -43,
      "y": 23,
      "z": -3,
      "name": "Empty"
    },
    {
      "x": -43,
      "y": 24,
      "z": -3,
      "name": "Empty"
    },
    {
      "x": -43,
      "y": 25,
      "z": -3,
      "name": "Empty"
    },
    {
      "x": -43,
      "y": 26,
      "z": -3,
      "name": "Empty"
    },
    {
      "x": -43,
      "y": 27,
      "z": -3,
      "name": "Empty"
    },
    {
      "x": -43,
      "y": 28,
      "z": -3,
      "name": "Empty"
    },
    {
      "x": -43,
      "y": 29,
      "z": -3,
      "name": "Empty"
    },
    {
      "x": -43,
      "y": 30,
      "z": -3,
      "name": "Empty"
    },
    {
      "x": -43,
      "y": 31,
      "z": -3,
      "name": "Empty"
    },
    {
      "x": -43,
      "y": 32,
      "z": -3,
      "name": "Empty"
    },
    {
      "x": -43,
      "y": 33,
      "z": -3,
      "name": "Empty"
    },
    {
      "x": -43,
      "y": 34,
      "z": -3,
      "name": "Empty"
    },
    {
      "x": -43,
      "y": 35,
      "z": -3,
      "name": "Empty"
    },
    {
      "x": -43,
      "y": 36,
      "z": -3,
      "name": "Empty"
    },
    {
      "x": -43,
      "y": 37,
      "z": -3,
      "name": "Empty"
    },
    {
      "x": -43,
      "y": 8,
      "z": -2,
      "name": "Rock_Stone"
    },
    {
      "x": -43,
      "y": 9,
      "z": -2,
      "name": "Rock_Stone"
    },
    {
      "x": -43,
      "y": 10,
      "z": -2,
      "name": "Rock_Stone"
    },
    {
      "x": -43,
      "y": 11,
      "z": -2,
      "name": "Rock_Stone"
    },
    {
      "x": -43,
      "y": 12,
      "z": -2,
      "name": "Rock_Stone"
    },
    {
      "x": -43,
      "y": 13,
      "z": -2,
      "name": "Rock_Stone"
    },
    {
      "x": -43,
      "y": 14,
      "z": -2,
      "name": "Rock_Stone"
    },
    {
      "x": -43,
      "y": 15,
      "z": -2,
      "name": "Rock_Stone"
    },
    {
      "x": -43,
      "y": 16,
      "z": -2,
      "name": "Rock_Stone"
    },
    {
      "x": -43,
      "y": 17,
      "z": -2,
      "name": "Rock_Stone_Mossy"
    },
    {
      "x": -43,
      "y": 18,
      "z": -2,
      "name": "Rock_Stone_Mossy"
    },
    {
      "x": -43,
      "y": 19,
      "z": -2,
      "name": "Rock_Stone_Mossy"
    },
    {
      "x": -43,
      "y": 20,
      "z": -2,
      "name": "Empty"
    },
    {
      "x": -43,
      "y": 21,
      "z": -2,
      "name": "Empty"
    },
    {
      "x": -43,
      "y": 22,
      "z": -2,
      "name": "Empty"
    },
    {
      "x": -43,
      "y": 23,
      "z": -2,
      "name": "Empty"
    },
    {
      "x": -43,
      "y": 24,
      "z": -2,
      "name": "Empty"
    },
    {
      "x": -43,
      "y": 25,
      "z": -2,
      "name": "Empty"
    },
    {
      "x": -43,
      "y": 26,
      "z": -2,
      "name": "Empty"
    },
    {
      "x": -43,
      "y": 27,
      "z": -2,
      "name": "Empty"
    },
    {
      "x": -43,
      "y": 28,
      "z": -2,
      "name": "Empty"
    },
    {
      "x": -43,
      "y": 29,
      "z": -2,
      "name": "Empty"
    },
    {
      "x": -43,
      "y": 30,
      "z": -2,
      "name": "Empty"
    },
    {
      "x": -43,
      "y": 31,
      "z": -2,
      "name": "Empty"
    },
    {
      "x": -43,
      "y": 32,
      "z": -2,
      "name": "Empty"
    },
    {
      "x": -43,
      "y": 33,
      "z": -2,
      "name": "Empty"
    },
    {
      "x": -43,
      "y": 34,
      "z": -2,
      "name": "Empty"
    },
    {
      "x": -43,
      "y": 35,
      "z": -2,
      "name": "Empty"
    },
    {
      "x": -43,
      "y": 36,
      "z": -2,
      "name": "Empty"
    },
    {
      "x": -43,
      "y": 37,
      "z": -2,
      "name": "Empty"
    },
    {
      "x": -43,
      "y": 8,
      "z": -1,
      "name": "Rock_Stone"
    },
    {
      "x": -43,
      "y": 9,
      "z": -1,
      "name": "Rock_Stone"
    },
    {
      "x": -43,
      "y": 10,
      "z": -1,
      "name": "Rock_Stone"
    },
    {
      "x": -43,
      "y": 11,
      "z": -1,
      "name": "Rock_Stone"
    },
    {
      "x": -43,
      "y": 12,
      "z": -1,
      "name": "Rock_Stone"
    },
    {
      "x": -43,
      "y": 13,
      "z": -1,
      "name": "Rock_Stone"
    },
    {
      "x": -43,
      "y": 14,
      "z": -1,
      "name": "Rock_Stone"
    },
    {
      "x": -43,
      "y": 15,
      "z": -1,
      "name": "Rock_Stone"
    },
    {
      "x": -43,
      "y": 16,
      "z": -1,
      "name": "Rock_Stone"
    },
    {
      "x": -43,
      "y": 17,
      "z": -1,
      "name": "Rock_Stone"
    },
    {
      "x": -43,
      "y": 18,
      "z": -1,
      "name": "Rock_Stone_Mossy"
    },
    {
      "x": -43,
      "y": 19,
      "z": -1,
      "name": "Rock_Stone_Mossy"
    },
    {
      "x": -43,
      "y": 20,
      "z": -1,
      "name": "Empty"
    },
    {
      "x": -43,
      "y": 21,
      "z": -1,
      "name": "Empty"
    },
    {
      "x": -43,
      "y": 22,
      "z": -1,
      "name": "Empty"
    },
    {
      "x": -43,
      "y": 23,
      "z": -1,
      "name": "Empty"
    },
    {
      "x": -43,
      "y": 24,
      "z": -1,
      "name": "Empty"
    },
    {
      "x": -43,
      "y": 25,
      "z": -1,
      "name": "Empty"
    },
    {
      "x": -43,
      "y": 26,
      "z": -1,
      "name": "Empty"
    },
    {
      "x": -43,
      "y": 27,
      "z": -1,
      "name": "Empty"
    },
    {
      "x": -43,
      "y": 28,
      "z": -1,
      "name": "Empty"
    },
    {
      "x": -43,
      "y": 29,
      "z": -1,
      "name": "Empty"
    },
    {
      "x": -43,
      "y": 30,
      "z": -1,
      "name": "Empty"
    },
    {
      "x": -43,
      "y": 31,
      "z": -1,
      "name": "Empty"
    },
    {
      "x": -43,
      "y": 32,
      "z": -1,
      "name": "Empty"
    },
    {
      "x": -43,
      "y": 33,
      "z": -1,
      "name": "Empty"
    },
    {
      "x": -43,
      "y": 34,
      "z": -1,
      "name": "Empty"
    },
    {
      "x": -43,
      "y": 35,
      "z": -1,
      "name": "Empty"
    },
    {
      "x": -43,
      "y": 36,
      "z": -1,
      "name": "Empty"
    },
    {
      "x": -43,
      "y": 37,
      "z": -1,
      "name": "Empty"
    },
    {
      "x": -43,
      "y": 8,
      "z": 0,
      "name": "Rock_Stone"
    },
    {
      "x": -43,
      "y": 9,
      "z": 0,
      "name": "Rock_Stone"
    },
    {
      "x": -43,
      "y": 10,
      "z": 0,
      "name": "Rock_Stone"
    },
    {
      "x": -43,
      "y": 11,
      "z": 0,
      "name": "Rock_Stone"
    },
    {
      "x": -43,
      "y": 12,
      "z": 0,
      "name": "Rock_Stone"
    },
    {
      "x": -43,
      "y": 13,
      "z": 0,
      "name": "Rock_Stone"
    },
    {
      "x": -43,
      "y": 14,
      "z": 0,
      "name": "Rock_Stone"
    },
    {
      "x": -43,
      "y": 15,
      "z": 0,
      "name": "Rock_Stone"
    },
    {
      "x": -43,
      "y": 16,
      "z": 0,
      "name": "Rock_Stone"
    },
    {
      "x": -43,
      "y": 17,
      "z": 0,
      "name": "Rock_Stone"
    },
    {
      "x": -43,
      "y": 18,
      "z": 0,
      "name": "Rock_Stone"
    },
    {
      "x": -43,
      "y": 19,
      "z": 0,
      "name": "Rock_Stone_Mossy"
    },
    {
      "x": -43,
      "y": 20,
      "z": 0,
      "name": "Rock_Stone"
    },
    {
      "x": -43,
      "y": 21,
      "z": 0,
      "name": "Empty"
    },
    {
      "x": -43,
      "y": 22,
      "z": 0,
      "name": "Empty"
    },
    {
      "x": -43,
      "y": 23,
      "z": 0,
      "name": "Empty"
    },
    {
      "x": -43,
      "y": 24,
      "z": 0,
      "name": "Empty"
    },
    {
      "x": -43,
      "y": 25,
      "z": 0,
      "name": "Empty"
    },
    {
      "x": -43,
      "y": 26,
      "z": 0,
      "name": "Empty"
    },
    {
      "x": -43,
      "y": 27,
      "z": 0,
      "name": "Empty"
    },
    {
      "x": -43,
      "y": 28,
      "z": 0,
      "name": "Empty"
    },
    {
      "x": -43,
      "y": 29,
      "z": 0,
      "name": "Empty"
    },
    {
      "x": -43,
      "y": 30,
      "z": 0,
      "name": "Empty"
    },
    {
      "x": -43,
      "y": 31,
      "z": 0,
      "name": "Empty"
    },
    {
      "x": -43,
      "y": 32,
      "z": 0,
      "name": "Empty"
    },
    {
      "x": -43,
      "y": 33,
      "z": 0,
      "name": "Empty"
    },
    {
      "x": -43,
      "y": 34,
      "z": 0,
      "name": "Empty"
    },
    {
      "x": -43,
      "y": 35,
      "z": 0,
      "name": "Empty"
    },
    {
      "x": -43,
      "y": 36,
      "z": 0,
      "name": "Empty"
    },
    {
      "x": -43,
      "y": 37,
      "z": 0,
      "name": "Empty"
    },
    {
      "x": -43,
      "y": 8,
      "z": 1,
      "name": "Rock_Stone"
    },
    {
      "x": -43,
      "y": 9,
      "z": 1,
      "name": "Rock_Stone"
    },
    {
      "x": -43,
      "y": 10,
      "z": 1,
      "name": "Rock_Stone"
    },
    {
      "x": -43,
      "y": 11,
      "z": 1,
      "name": "Rock_Stone"
    },
    {
      "x": -43,
      "y": 12,
      "z": 1,
      "name": "Rock_Stone"
    },
    {
      "x": -43,
      "y": 13,
      "z": 1,
      "name": "Rock_Stone"
    },
    {
      "x": -43,
      "y": 14,
      "z": 1,
      "name": "Rock_Stone"
    },
    {
      "x": -43,
      "y": 15,
      "z": 1,
      "name": "Rock_Stone"
    },
    {
      "x": -43,
      "y": 16,
      "z": 1,
      "name": "Rock_Stone"
    },
    {
      "x": -43,
      "y": 17,
      "z": 1,
      "name": "Rock_Stone"
    },
    {
      "x": -43,
      "y": 18,
      "z": 1,
      "name": "Rock_Stone"
    },
    {
      "x": -43,
      "y": 19,
      "z": 1,
      "name": "Rock_Stone"
    },
    {
      "x": -43,
      "y": 20,
      "z": 1,
      "name": "Rock_Stone"
    },
    {
      "x": -43,
      "y": 21,
      "z": 1,
      "name": "Plant_Moss_Rug_Green"
    },
    {
      "x": -43,
      "y": 22,
      "z": 1,
      "name": "Empty"
    },
    {
      "x": -43,
      "y": 23,
      "z": 1,
      "name": "Empty"
    },
    {
      "x": -43,
      "y": 24,
      "z": 1,
      "name": "Empty"
    },
    {
      "x": -43,
      "y": 25,
      "z": 1,
      "name": "Empty"
    },
    {
      "x": -43,
      "y": 26,
      "z": 1,
      "name": "Empty"
    },
    {
      "x": -43,
      "y": 27,
      "z": 1,
      "name": "Empty"
    },
    {
      "x": -43,
      "y": 28,
      "z": 1,
      "name": "Empty"
    },
    {
      "x": -43,
      "y": 29,
      "z": 1,
      "name": "Empty"
    },
    {
      "x": -43,
      "y": 30,
      "z": 1,
      "name": "Empty"
    },
    {
      "x": -43,
      "y": 31,
      "z": 1,
      "name": "Empty"
    },
    {
      "x": -43,
      "y": 32,
      "z": 1,
      "name": "Empty"
    },
    {
      "x": -43,
      "y": 33,
      "z": 1,
      "name": "Empty"
    },
    {
      "x": -43,
      "y": 34,
      "z": 1,
      "name": "Empty"
    },
    {
      "x": -43,
      "y": 35,
      "z": 1,
      "name": "Empty"
    },
    {
      "x": -43,
      "y": 36,
      "z": 1,
      "name": "Empty"
    },
    {
      "x": -43,
      "y": 37,
      "z": 1,
      "name": "Empty"
    },
    {
      "x": -43,
      "y": 8,
      "z": 2,
      "name": "Rock_Stone"
    },
    {
      "x": -43,
      "y": 9,
      "z": 2,
      "name": "Rock_Stone"
    },
    {
      "x": -43,
      "y": 10,
      "z": 2,
      "name": "Rock_Stone"
    },
    {
      "x": -43,
      "y": 11,
      "z": 2,
      "name": "Rock_Stone"
    },
    {
      "x": -43,
      "y": 12,
      "z": 2,
      "name": "Rock_Stone"
    },
    {
      "x": -43,
      "y": 13,
      "z": 2,
      "name": "Rock_Stone"
    },
    {
      "x": -43,
      "y": 14,
      "z": 2,
      "name": "Rock_Stone"
    },
    {
      "x": -43,
      "y": 15,
      "z": 2,
      "name": "Rock_Stone"
    },
    {
      "x": -43,
      "y": 16,
      "z": 2,
      "name": "Rock_Stone"
    },
    {
      "x": -43,
      "y": 17,
      "z": 2,
      "name": "Rock_Stone"
    },
    {
      "x": -43,
      "y": 18,
      "z": 2,
      "name": "Rock_Stone"
    },
    {
      "x": -43,
      "y": 19,
      "z": 2,
      "name": "Rock_Stone"
    },
    {
      "x": -43,
      "y": 20,
      "z": 2,
      "name": "Rock_Stone_Mossy"
    },
    {
      "x": -43,
      "y": 21,
      "z": 2,
      "name": "Plant_Moss_Block_Green"
    },
    {
      "x": -43,
      "y": 22,
      "z": 2,
      "name": "Empty"
    },
    {
      "x": -43,
      "y": 23,
      "z": 2,
      "name": "Empty"
    },
    {
      "x": -43,
      "y": 24,
      "z": 2,
      "name": "Empty"
    },
    {
      "x": -43,
      "y": 25,
      "z": 2,
      "name": "Empty"
    },
    {
      "x": -43,
      "y": 26,
      "z": 2,
      "name": "Empty"
    },
    {
      "x": -43,
      "y": 27,
      "z": 2,
      "name": "Empty"
    },
    {
      "x": -43,
      "y": 28,
      "z": 2,
      "name": "Empty"
    },
    {
      "x": -43,
      "y": 29,
      "z": 2,
      "name": "Empty"
    },
    {
      "x": -43,
      "y": 30,
      "z": 2,
      "name": "Empty"
    },
    {
      "x": -43,
      "y": 31,
      "z": 2,
      "name": "Empty"
    },
    {
      "x": -43,
      "y": 32,
      "z": 2,
      "name": "Empty"
    },
    {
      "x": -43,
      "y": 33,
      "z": 2,
      "name": "Empty"
    },
    {
      "x": -43,
      "y": 34,
      "z": 2,
      "name": "Empty"
    },
    {
      "x": -43,
      "y": 35,
      "z": 2,
      "name": "Empty"
    },
    {
      "x": -43,
      "y": 36,
      "z": 2,
      "name": "Empty"
    },
    {
      "x": -43,
      "y": 37,
      "z": 2,
      "name": "Empty"
    },
    {
      "x": -43,
      "y": 7,
      "z": 3,
      "name": "Rock_Stone"
    },
    {
      "x": -43,
      "y": 8,
      "z": 3,
      "name": "Rock_Stone"
    },
    {
      "x": -43,
      "y": 9,
      "z": 3,
      "name": "Rock_Stone"
    },
    {
      "x": -43,
      "y": 10,
      "z": 3,
      "name": "Rock_Stone"
    },
    {
      "x": -43,
      "y": 11,
      "z": 3,
      "name": "Rock_Stone"
    },
    {
      "x": -43,
      "y": 12,
      "z": 3,
      "name": "Rock_Stone"
    },
    {
      "x": -43,
      "y": 13,
      "z": 3,
      "name": "Rock_Stone"
    },
    {
      "x": -43,
      "y": 14,
      "z": 3,
      "name": "Rock_Stone"
    },
    {
      "x": -43,
      "y": 15,
      "z": 3,
      "name": "Rock_Stone"
    },
    {
      "x": -43,
      "y": 16,
      "z": 3,
      "name": "Rock_Stone"
    },
    {
      "x": -43,
      "y": 17,
      "z": 3,
      "name": "Rock_Stone"
    },
    {
      "x": -43,
      "y": 18,
      "z": 3,
      "name": "Rock_Stone"
    },
    {
      "x": -43,
      "y": 19,
      "z": 3,
      "name": "Rock_Stone_Mossy"
    },
    {
      "x": -43,
      "y": 20,
      "z": 3,
      "name": "Rock_Stone_Mossy"
    },
    {
      "x": -43,
      "y": 21,
      "z": 3,
      "name": "Rock_Stone_Mossy"
    },
    {
      "x": -43,
      "y": 22,
      "z": 3,
      "name": "Empty"
    },
    {
      "x": -43,
      "y": 23,
      "z": 3,
      "name": "Empty"
    },
    {
      "x": -43,
      "y": 24,
      "z": 3,
      "name": "Empty"
    },
    {
      "x": -43,
      "y": 25,
      "z": 3,
      "name": "Empty"
    },
    {
      "x": -43,
      "y": 26,
      "z": 3,
      "name": "Empty"
    },
    {
      "x": -43,
      "y": 27,
      "z": 3,
      "name": "Empty"
    },
    {
      "x": -43,
      "y": 28,
      "z": 3,
      "name": "Empty"
    },
    {
      "x": -43,
      "y": 29,
      "z": 3,
      "name": "Empty"
    },
    {
      "x": -43,
      "y": 30,
      "z": 3,
      "name": "Empty"
    },
    {
      "x": -43,
      "y": 31,
      "z": 3,
      "name": "Empty"
    },
    {
      "x": -43,
      "y": 32,
      "z": 3,
      "name": "Empty"
    },
    {
      "x": -43,
      "y": 33,
      "z": 3,
      "name": "Empty"
    },
    {
      "x": -43,
      "y": 34,
      "z": 3,
      "name": "Empty"
    },
    {
      "x": -43,
      "y": 35,
      "z": 3,
      "name": "Empty"
    },
    {
      "x": -43,
      "y": 36,
      "z": 3,
      "name": "Empty"
    },
    {
      "x": -43,
      "y": 37,
      "z": 3,
      "name": "Empty"
    },
    {
      "x": -43,
      "y": 7,
      "z": 4,
      "name": "Rock_Stone"
    },
    {
      "x": -43,
      "y": 8,
      "z": 4,
      "name": "Rock_Stone"
    },
    {
      "x": -43,
      "y": 9,
      "z": 4,
      "name": "Rock_Stone"
    },
    {
      "x": -43,
      "y": 10,
      "z": 4,
      "name": "Rock_Stone"
    },
    {
      "x": -43,
      "y": 11,
      "z": 4,
      "name": "Rock_Stone"
    },
    {
      "x": -43,
      "y": 12,
      "z": 4,
      "name": "Rock_Stone"
    },
    {
      "x": -43,
      "y": 13,
      "z": 4,
      "name": "Rock_Stone"
    },
    {
      "x": -43,
      "y": 14,
      "z": 4,
      "name": "Rock_Stone"
    },
    {
      "x": -43,
      "y": 15,
      "z": 4,
      "name": "Rock_Stone"
    },
    {
      "x": -43,
      "y": 16,
      "z": 4,
      "name": "Rock_Stone"
    },
    {
      "x": -43,
      "y": 17,
      "z": 4,
      "name": "Rock_Stone"
    },
    {
      "x": -43,
      "y": 18,
      "z": 4,
      "name": "Rock_Stone"
    },
    {
      "x": -43,
      "y": 19,
      "z": 4,
      "name": "Rock_Stone"
    },
    {
      "x": -43,
      "y": 20,
      "z": 4,
      "name": "Rock_Stone_Mossy"
    },
    {
      "x": -43,
      "y": 21,
      "z": 4,
      "name": "Rock_Stone"
    },
    {
      "x": -43,
      "y": 7,
      "z": 5,
      "name": "Rock_Stone"
    },
    {
      "x": -43,
      "y": 8,
      "z": 5,
      "name": "Rock_Stone"
    },
    {
      "x": -43,
      "y": 9,
      "z": 5,
      "name": "Rock_Stone"
    },
    {
      "x": -43,
      "y": 10,
      "z": 5,
      "name": "Rock_Stone"
    },
    {
      "x": -43,
      "y": 11,
      "z": 5,
      "name": "Rock_Stone"
    },
    {
      "x": -43,
      "y": 12,
      "z": 5,
      "name": "Rock_Stone"
    },
    {
      "x": -43,
      "y": 13,
      "z": 5,
      "name": "Rock_Stone"
    },
    {
      "x": -43,
      "y": 14,
      "z": 5,
      "name": "Rock_Stone"
    },
    {
      "x": -43,
      "y": 15,
      "z": 5,
      "name": "Rock_Stone"
    },
    {
      "x": -43,
      "y": 16,
      "z": 5,
      "name": "Rock_Stone"
    },
    {
      "x": -43,
      "y": 17,
      "z": 5,
      "name": "Rock_Stone"
    },
    {
      "x": -43,
      "y": 18,
      "z": 5,
      "name": "Rock_Stone"
    },
    {
      "x": -43,
      "y": 19,
      "z": 5,
      "name": "Rock_Stone"
    },
    {
      "x": -43,
      "y": 20,
      "z": 5,
      "name": "Rock_Stone"
    },
    {
      "x": -43,
      "y": 21,
      "z": 5,
      "name": "Rock_Stone"
    },
    {
      "x": -43,
      "y": 7,
      "z": 6,
      "name": "Rock_Stone"
    },
    {
      "x": -43,
      "y": 8,
      "z": 6,
      "name": "Rock_Stone"
    },
    {
      "x": -43,
      "y": 9,
      "z": 6,
      "name": "Rock_Stone"
    },
    {
      "x": -43,
      "y": 10,
      "z": 6,
      "name": "Rock_Stone"
    },
    {
      "x": -43,
      "y": 11,
      "z": 6,
      "name": "Rock_Stone"
    },
    {
      "x": -43,
      "y": 12,
      "z": 6,
      "name": "Rock_Stone"
    },
    {
      "x": -43,
      "y": 13,
      "z": 6,
      "name": "Rock_Stone"
    },
    {
      "x": -43,
      "y": 14,
      "z": 6,
      "name": "Rock_Stone"
    },
    {
      "x": -43,
      "y": 15,
      "z": 6,
      "name": "Rock_Stone"
    },
    {
      "x": -43,
      "y": 16,
      "z": 6,
      "name": "Rock_Stone"
    },
    {
      "x": -43,
      "y": 17,
      "z": 6,
      "name": "Rock_Stone"
    },
    {
      "x": -43,
      "y": 18,
      "z": 6,
      "name": "Rock_Stone"
    },
    {
      "x": -43,
      "y": 19,
      "z": 6,
      "name": "Rock_Stone"
    },
    {
      "x": -43,
      "y": 7,
      "z": 7,
      "name": "Rock_Stone"
    },
    {
      "x": -43,
      "y": 8,
      "z": 7,
      "name": "Rock_Stone"
    },
    {
      "x": -43,
      "y": 9,
      "z": 7,
      "name": "Rock_Stone"
    },
    {
      "x": -43,
      "y": 10,
      "z": 7,
      "name": "Rock_Stone"
    },
    {
      "x": -43,
      "y": 11,
      "z": 7,
      "name": "Rock_Stone"
    },
    {
      "x": -43,
      "y": 12,
      "z": 7,
      "name": "Rock_Stone"
    },
    {
      "x": -43,
      "y": 13,
