{
  "version": 8,
  "blockIdVersion": 10,
  "anchorX": -5,
  "anchorY": 17,
  "anchorZ": -4,
  "blocks": [
    {
      "x": -35,
      "y": 12,
      "z": -11,
      "name": "Rock_Stone"
    },
    {
      "x": -35,
      "y": 13,
      "z": -11,
      "name": "Rock_Stone"
    },
    {
      "x": -35,
      "y": 14,
      "z": -11,
      "name": "Rock_Stone"
    },
    {
      "x": -35,
      "y": 15,
      "z": -11,
      "name": "Rock_Stone"
    },
    {
      "x": -35,
      "y": 16,
      "z": -11,
      "name": "Rock_Stone"
    },
    {
      "x": -35,
      "y": 17,
      "z": -11,
      "name": "Rock_Stone"
    },
    {
      "x": -35,
      "y": 18,
      "z": -11,
      "name": "Rock_Stone"
    },
    {
      "x": -35,
      "y": 12,
      "z": -10,
      "name": "Rock_Stone"
    },
    {
      "x": -35,
      "y": 13,
      "z": -10,
      "name": "Rock_Stone"
    },
    {
      "x": -35,
      "y": 14,
      "z": -10,
      "name": "Rock_Stone"
    },
    {
      "x": -35,
      "y": 15,
      "z": -10,
      "name": "Rock_Stone"
    },
    {
      "x": -35,
      "y": 16,
      "z": -10,
      "name": "Rock_Stone"
    },
    {
      "x": -35,
      "y": 17,
      "z": -10,
      "name": "Rock_Stone"
    },
    {
      "x": -35,
      "y": 18,
      "z": -10,
      "name": "Rock_Stone"
    },
    {
      "x": -35,
      "y": 12,
      "z": -9,
      "name": "Rock_Stone"
    },
    {
      "x": -35,
      "y": 13,
      "z": -9,
      "name": "Rock_Stone"
    },
    {
      "x": -35,
      "y": 14,
      "z": -9,
      "name": "Rock_Stone"
    },
    {
      "x": -35,
      "y": 15,
      "z": -9,
      "name": "Rock_Stone"
    },
    {
      "x": -35,
      "y": 16,
      "z": -9,
      "name": "Rock_Stone"
    },
    {
      "x": -35,
      "y": 17,
      "z": -9,
      "name": "Rock_Stone"
    },
    {
      "x": -35,
      "y": 18,
      "z": -9,
      "name": "Rock_Stone"
    },
    {
      "x": -35,
      "y": 12,
      "z": -8,
      "name": "Rock_Stone"
    },
    {
      "x": -35,
      "y": 13,
      "z": -8,
      "name": "Rock_Stone"
    },
    {
      "x": -35,
      "y": 14,
      "z": -8,
      "name": "Rock_Stone"
    },
    {
      "x": -35,
      "y": 15,
      "z": -8,
      "name": "Rock_Stone"
    },
    {
      "x": -35,
      "y": 16,
      "z": -8,
      "name": "Rock_Stone"
    },
    {
      "x": -35,
      "y": 17,
      "z": -8,
      "name": "Rock_Stone"
    },
    {
      "x": -35,
      "y": 18,
      "z": -8,
      "name": "Rock_Stone"
    },
    {
      "x": -35,
      "y": 12,
      "z": -7,
      "name": "Rock_Stone"
    },
    {
      "x": -35,
      "y": 13,
      "z": -7,
      "name": "Rock_Stone"
    },
    {
      "x": -35,
      "y": 14,
      "z": -7,
      "name": "Rock_Stone"
    },
    {
      "x": -35,
      "y": 15,
      "z": -7,
      "name": "Rock_Stone"
    },
    {
      "x": -35,
      "y": 16,
      "z": -7,
      "name": "Rock_Stone"
    },
    {
      "x": -35,
      "y": 17,
      "z": -7,
      "name": "Rock_Stone"
    },
    {
      "x": -35,
      "y": 18,
      "z": -7,
      "name": "Rock_Stone"
    },
    {
      "x": -35,
      "y": 9,
      "z": -6,
      "name": "Rock_Stone"
    },
    {
      "x": -35,
      "y": 10,
      "z": -6,
      "name": "Rock_Stone"
    },
    {
      "x": -35,
      "y": 11,
      "z": -6,
      "name": "Rock_Stone"
    },
    {
      "x": -35,
      "y": 12,
      "z": -6,
      "name": "Rock_Stone"
    },
    {
      "x": -35,
      "y": 13,
      "z": -6,
      "name": "Rock_Stone"
    },
    {
      "x": -35,
      "y": 14,
      "z": -6,
      "name": "Rock_Stone"
    },
    {
      "x": -35,
      "y": 15,
      "z": -6,
      "name": "Rock_Stone"
    },
    {
      "x": -35,
      "y": 9,
      "z": -5,
      "name": "Rock_Stone"
    },
    {
      "x": -35,
      "y": 10,
      "z": -5,
      "name": "Rock_Stone"
    },
    {
      "x": -35,
      "y": 11,
      "z": -5,
      "name": "Rock_Stone"
    },
    {
      "x": -35,
      "y": 12,
      "z": -5,
      "name": "Rock_Stone"
    },
    {
      "x": -35,
      "y": 13,
      "z": -5,
      "name": "Rock_Stone"
    },
    {
      "x": -35,
      "y": 14,
      "z": -5,
      "name": "Rock_Stone"
    },
    {
      "x": -35,
      "y": 15,
      "z": -5,
      "name": "Rock_Stone"
    },
    {
      "x": -35,
      "y": 9,
      "z": -4,
      "name": "Rock_Stone"
    },
    {
      "x": -35,
      "y": 10,
      "z": -4,
      "name": "Rock_Stone"
    },
    {
      "x": -35,
      "y": 11,
      "z": -4,
      "name": "Rock_Stone"
    },
    {
      "x": -35,
      "y": 12,
      "z": -4,
      "name": "Rock_Stone"
    },
    {
      "x": -34,
      "y": 12,
      "z": -11,
      "name": "Rock_Stone"
    },
    {
      "x": -34,
      "y": 13,
      "z": -11,
      "name": "Rock_Stone"
    },
    {
      "x": -34,
      "y": 14,
      "z": -11,
      "name": "Rock_Stone"
    },
    {
      "x": -34,
      "y": 15,
      "z": -11,
      "name": "Rock_Stone"
    },
    {
      "x": -34,
      "y": 16,
      "z": -11,
      "name": "Rock_Stone"
    },
    {
      "x": -34,
      "y": 17,
      "z": -11,
      "name": "Rock_Stone"
    },
    {
      "x": -34,
      "y": 18,
      "z": -11,
      "name": "Rock_Stone"
    },
    {
      "x": -34,
      "y": 12,
      "z": -10,
      "name": "Rock_Stone"
    },
    {
      "x": -34,
      "y": 13,
      "z": -10,
      "name": "Rock_Stone"
    },
    {
      "x": -34,
      "y": 14,
      "z": -10,
      "name": "Rock_Stone"
    },
    {
      "x": -34,
      "y": 15,
      "z": -10,
      "name": "Rock_Stone"
    },
    {
      "x": -34,
      "y": 16,
      "z": -10,
      "name": "Rock_Stone"
    },
    {
      "x": -34,
      "y": 17,
      "z": -10,
      "name": "Rock_Stone"
    },
    {
      "x": -34,
      "y": 18,
      "z": -10,
      "name": "Rock_Stone"
    },
    {
      "x": -34,
      "y": 19,
      "z": -10,
      "name": "Rock_Stone"
    },
    {
      "x": -34,
      "y": 12,
      "z": -9,
      "name": "Rock_Stone"
    },
    {
      "x": -34,
      "y": 13,
      "z": -9,
      "name": "Rock_Stone"
    },
    {
      "x": -34,
      "y": 14,
      "z": -9,
      "name": "Rock_Stone"
    },
    {
      "x": -34,
      "y": 15,
      "z": -9,
      "name": "Rock_Stone"
    },
    {
      "x": -34,
      "y": 16,
      "z": -9,
      "name": "Rock_Stone"
    },
    {
      "x": -34,
      "y": 17,
      "z": -9,
      "name": "Rock_Stone"
    },
    {
      "x": -34,
      "y": 18,
      "z": -9,
      "name": "Rock_Stone"
    },
    {
      "x": -34,
      "y": 19,
      "z": -9,
      "name": "Rock_Stone"
    },
    {
      "x": -34,
      "y": 12,
      "z": -8,
      "name": "Rock_Stone"
    },
    {
      "x": -34,
      "y": 13,
      "z": -8,
      "name": "Rock_Stone"
    },
    {
      "x": -34,
      "y": 14,
      "z": -8,
      "name": "Rock_Stone"
    },
    {
      "x": -34,
      "y": 15,
      "z": -8,
      "name": "Rock_Stone"
    },
    {
      "x": -34,
      "y": 16,
      "z": -8,
      "name": "Rock_Stone"
    },
    {
      "x": -34,
      "y": 17,
      "z": -8,
      "name": "Rock_Stone"
    },
    {
      "x": -34,
      "y": 18,
      "z": -8,
      "name": "Rock_Stone"
    },
    {
      "x": -34,
      "y": 9,
      "z": -7,
      "name": "Rock_Stone"
    },
    {
      "x": -34,
      "y": 10,
      "z": -7,
      "name": "Rock_Stone"
    },
    {
      "x": -34,
      "y": 11,
      "z": -7,
      "name": "Rock_Stone"
    },
    {
      "x": -34,
      "y": 12,
      "z": -7,
      "name": "Rock_Stone"
    },
    {
      "x": -34,
      "y": 13,
      "z": -7,
      "name": "Rock_Stone"
    },
    {
      "x": -34,
      "y": 14,
      "z": -7,
      "name": "Rock_Stone"
    },
    {
      "x": -34,
      "y": 15,
      "z": -7,
      "name": "Rock_Stone"
    },
    {
      "x": -34,
      "y": 16,
      "z": -7,
      "name": "Rock_Stone"
    },
    {
      "x": -34,
      "y": 17,
      "z": -7,
      "name": "Rock_Stone"
    },
    {
      "x": -34,
      "y": 18,
      "z": -7,
      "name": "Rock_Stone"
    },
    {
      "x": -34,
      "y": 9,
      "z": -6,
      "name": "Rock_Stone"
    },
    {
      "x": -34,
      "y": 10,
      "z": -6,
      "name": "Rock_Stone"
    },
    {
      "x": -34,
      "y": 11,
      "z": -6,
      "name": "Rock_Stone"
    },
    {
      "x": -34,
      "y": 12,
      "z": -6,
      "name": "Rock_Stone"
    },
    {
      "x": -34,
      "y": 13,
      "z": -6,
      "name": "Rock_Stone"
    },
    {
      "x": -34,
      "y": 14,
      "z": -6,
      "name": "Rock_Stone"
    },
    {
      "x": -34,
      "y": 15,
      "z": -6,
      "name": "Rock_Stone"
    },
    {
      "x": -34,
      "y": 16,
      "z": -6,
      "name": "Rock_Stone_Mossy"
    },
    {
      "x": -34,
      "y": 17,
      "z": -6,
      "name": "Rock_Stone"
    },
    {
      "x": -34,
      "y": 18,
      "z": -6,
      "name": "Rock_Stone"
    },
    {
      "x": -34,
      "y": 9,
      "z": -5,
      "name": "Rock_Stone"
    },
    {
      "x": -34,
      "y": 10,
      "z": -5,
      "name": "Rock_Stone"
    },
    {
      "x": -34,
      "y": 11,
      "z": -5,
      "name": "Rock_Stone"
    },
    {
      "x": -34,
      "y": 12,
      "z": -5,
      "name": "Rock_Stone"
    },
    {
      "x": -34,
      "y": 13,
      "z": -5,
      "name": "Rock_Stone"
    },
    {
      "x": -34,
      "y": 14,
      "z": -5,
      "name": "Rock_Stone"
    },
    {
      "x": -34,
      "y": 15,
      "z": -5,
      "name": "Rock_Stone_Mossy"
    },
    {
      "x": -34,
      "y": 9,
      "z": -4,
      "name": "Rock_Stone"
    },
    {
      "x": -34,
      "y": 10,
      "z": -4,
      "name": "Rock_Stone"
    },
    {
      "x": -34,
      "y": 11,
      "z": -4,
      "name": "Rock_Stone"
    },
    {
      "x": -34,
      "y": 12,
      "z": -4,
      "name": "Rock_Stone"
    },
    {
      "x": -34,
      "y": 13,
      "z": -4,
      "name": "Rock_Stone"
    },
    {
      "x": -34,
      "y": 14,
      "z": -4,
      "name": "Rock_Stone_Mossy"
    },
    {
      "x": -34,
      "y": 9,
      "z": -3,
      "name": "Rock_Stone"
    },
    {
      "x": -34,
      "y": 10,
      "z": -3,
      "name": "Rock_Stone"
    },
    {
      "x": -34,
      "y": 11,
      "z": -3,
      "name": "Rock_Stone"
    },
    {
      "x": -34,
      "y": 12,
      "z": -3,
      "name": "Rock_Stone"
    },
    {
      "x": -34,
      "y": 13,
      "z": -3,
      "name": "Rock_Stone"
    },
    {
      "x": -34,
      "y": 14,
      "z": -3,
      "name": "Rock_Stone"
    },
    {
      "x": -33,
      "y": 12,
      "z": -12,
      "name": "Rock_Stone"
    },
    {
      "x": -33,
      "y": 13,
      "z": -12,
      "name": "Rock_Stone"
    },
    {
      "x": -33,
      "y": 14,
      "z": -12,
      "name": "Rock_Stone"
    },
    {
      "x": -33,
      "y": 15,
      "z": -12,
      "name": "Rock_Stone"
    },
    {
      "x": -33,
      "y": 16,
      "z": -12,
      "name": "Soil_Dirt"
    },
    {
      "x": -33,
      "y": 12,
      "z": -11,
      "name": "Rock_Stone"
    },
    {
      "x": -33,
      "y": 13,
      "z": -11,
      "name": "Rock_Stone"
    },
    {
      "x": -33,
      "y": 14,
      "z": -11,
      "name": "Rock_Stone"
    },
    {
      "x": -33,
      "y": 15,
      "z": -11,
      "name": "Rock_Stone"
    },
    {
      "x": -33,
      "y": 16,
      "z": -11,
      "name": "Rock_Stone"
    },
    {
      "x": -33,
      "y": 17,
      "z": -11,
      "name": "Rock_Stone"
    },
    {
      "x": -33,
      "y": 18,
      "z": -11,
      "name": "Rock_Stone"
    },
    {
      "x": -33,
      "y": 19,
      "z": -11,
      "name": "Rock_Stone"
    },
    {
      "x": -33,
      "y": 12,
      "z": -10,
      "name": "Rock_Stone"
    },
    {
      "x": -33,
      "y": 13,
      "z": -10,
      "name": "Rock_Stone"
    },
    {
      "x": -33,
      "y": 14,
      "z": -10,
      "name": "Rock_Stone"
    },
    {
      "x": -33,
      "y": 15,
      "z": -10,
      "name": "Rock_Stone"
    },
    {
      "x": -33,
      "y": 16,
      "z": -10,
      "name": "Rock_Stone"
    },
    {
      "x": -33,
      "y": 17,
      "z": -10,
      "name": "Rock_Stone"
    },
    {
      "x": -33,
      "y": 18,
      "z": -10,
      "name": "Rock_Stone"
    },
    {
      "x": -33,
      "y": 19,
      "z": -10,
      "name": "Rock_Stone"
    },
    {
      "x": -33,
      "y": 8,
      "z": -9,
      "name": "Rock_Stone"
    },
    {
      "x": -33,
      "y": 9,
      "z": -9,
      "name": "Rock_Stone"
    },
    {
      "x": -33,
      "y": 10,
      "z": -9,
      "name": "Rock_Stone"
    },
    {
      "x": -33,
      "y": 11,
      "z": -9,
      "name": "Rock_Stone"
    },
    {
      "x": -33,
      "y": 12,
      "z": -9,
      "name": "Rock_Stone"
    },
    {
      "x": -33,
      "y": 13,
      "z": -9,
      "name": "Rock_Stone"
    },
    {
      "x": -33,
      "y": 14,
      "z": -9,
      "name": "Rock_Stone"
    },
    {
      "x": -33,
      "y": 15,
      "z": -9,
      "name": "Rock_Stone"
    },
    {
      "x": -33,
      "y": 16,
      "z": -9,
      "name": "Rock_Stone"
    },
    {
      "x": -33,
      "y": 17,
      "z": -9,
      "name": "Rock_Stone"
    },
    {
      "x": -33,
      "y": 18,
      "z": -9,
      "name": "Rock_Stone"
    },
    {
      "x": -33,
      "y": 19,
      "z": -9,
      "name": "Rock_Stone"
    },
    {
      "x": -33,
      "y": 20,
      "z": -9,
      "name": "Rock_Stone"
    },
    {
      "x": -33,
      "y": 8,
      "z": -8,
      "name": "Rock_Stone"
    },
    {
      "x": -33,
      "y": 9,
      "z": -8,
      "name": "Rock_Stone"
    },
    {
      "x": -33,
      "y": 10,
      "z": -8,
      "name": "Rock_Stone"
    },
    {
      "x": -33,
      "y": 11,
      "z": -8,
      "name": "Rock_Stone"
    },
    {
      "x": -33,
      "y": 12,
      "z": -8,
      "name": "Rock_Stone"
    },
    {
      "x": -33,
      "y": 13,
      "z": -8,
      "name": "Rock_Stone"
    },
    {
      "x": -33,
      "y": 14,
      "z": -8,
      "name": "Rock_Stone"
    },
    {
      "x": -33,
      "y": 15,
      "z": -8,
      "name": "Rock_Stone"
    },
    {
      "x": -33,
      "y": 16,
      "z": -8,
      "name": "Rock_Stone"
    },
    {
      "x": -33,
      "y": 17,
      "z": -8,
      "name": "Rock_Stone"
    },
    {
      "x": -33,
      "y": 18,
      "z": -8,
      "name": "Rock_Stone"
    },
    {
      "x": -33,
      "y": 19,
      "z": -8,
      "name": "Rock_Stone"
    },
    {
      "x": -33,
      "y": 20,
      "z": -8,
      "name": "Rock_Stone"
    },
    {
      "x": -33,
      "y": 21,
      "z": -8,
      "name": "Rock_Stone"
    },
    {
      "x": -33,
      "y": 8,
      "z": -7,
      "name": "Rock_Stone"
    },
    {
      "x": -33,
      "y": 9,
      "z": -7,
      "name": "Rock_Stone"
    },
    {
      "x": -33,
      "y": 10,
      "z": -7,
      "name": "Rock_Stone"
    },
    {
      "x": -33,
      "y": 11,
      "z": -7,
      "name": "Rock_Stone"
    },
    {
      "x": -33,
      "y": 12,
      "z": -7,
      "name": "Rock_Stone"
    },
    {
      "x": -33,
      "y": 13,
      "z": -7,
      "name": "Rock_Stone"
    },
    {
      "x": -33,
      "y": 14,
      "z": -7,
      "name": "Rock_Stone"
    },
    {
      "x": -33,
      "y": 15,
      "z": -7,
      "name": "Rock_Stone"
    },
    {
      "x": -33,
      "y": 16,
      "z": -7,
      "name": "Rock_Stone"
    },
    {
      "x": -33,
      "y": 17,
      "z": -7,
      "name": "Rock_Stone"
    },
    {
      "x": -33,
      "y": 18,
      "z": -7,
      "name": "Rock_Stone"
    },
    {
      "x": -33,
      "y": 19,
      "z": -7,
      "name": "Rock_Stone"
    },
    {
      "x": -33,
      "y": 20,
      "z": -7,
      "name": "Rock_Stone_Mossy"
    },
    {
      "x": -33,
      "y": 21,
      "z": -7,
      "name": "Rock_Stone"
    },
    {
      "x": -33,
      "y": 8,
      "z": -6,
      "name": "Rock_Stone"
    },
    {
      "x": -33,
      "y": 9,
      "z": -6,
      "name": "Rock_Stone"
    },
    {
      "x": -33,
      "y": 10,
      "z": -6,
      "name": "Rock_Stone"
    },
    {
      "x": -33,
      "y": 11,
      "z": -6,
      "name": "Rock_Stone"
    },
    {
      "x": -33,
      "y": 12,
      "z": -6,
      "name": "Rock_Stone"
    },
    {
      "x": -33,
      "y": 13,
      "z": -6,
      "name": "Rock_Stone"
    },
    {
      "x": -33,
      "y": 14,
      "z": -6,
      "name": "Rock_Stone"
    },
    {
      "x": -33,
      "y": 15,
      "z": -6,
      "name": "Rock_Stone_Mossy"
    },
    {
      "x": -33,
      "y": 16,
      "z": -6,
      "name": "Rock_Stone_Mossy"
    },
    {
      "x": -33,
      "y": 17,
      "z": -6,
      "name": "Rock_Stone_Mossy"
    },
    {
      "x": -33,
      "y": 18,
      "z": -6,
      "name": "Rock_Stone"
    },
    {
      "x": -33,
      "y": 19,
      "z": -6,
      "name": "Rock_Stone_Mossy"
    },
    {
      "x": -33,
      "y": 20,
      "z": -6,
      "name": "Rock_Stone_Mossy"
    },
    {
      "x": -33,
      "y": 8,
      "z": -5,
      "name": "Rock_Stone"
    },
    {
      "x": -33,
      "y": 9,
      "z": -5,
      "name": "Rock_Stone"
    },
    {
      "x": -33,
      "y": 10,
      "z": -5,
      "name": "Rock_Stone"
    },
    {
      "x": -33,
      "y": 11,
      "z": -5,
      "name": "Rock_Stone"
    },
    {
      "x": -33,
      "y": 12,
      "z": -5,
      "name": "Rock_Stone"
    },
    {
      "x": -33,
      "y": 13,
      "z": -5,
      "name": "Rock_Stone"
    },
    {
      "x": -33,
      "y": 14,
      "z": -5,
      "name": "Rock_Stone_Mossy"
    },
    {
      "x": -33,
      "y": 15,
      "z": -5,
      "name": "Rock_Stone_Mossy"
    },
    {
      "x": -33,
      "y": 16,
      "z": -5,
      "name": "Rock_Stone_Mossy"
    },
    {
      "x": -33,
      "y": 17,
      "z": -5,
      "name": "Rock_Stone_Mossy"
    },
    {
      "x": -33,
      "y": 18,
      "z": -5,
      "name": "Rock_Stone_Mossy"
    },
    {
      "x": -33,
      "y": 19,
      "z": -5,
      "name": "Rock_Stone_Mossy"
    },
    {
      "x": -33,
      "y": 20,
      "z": -5,
      "name": "Rock_Stone_Mossy"
    },
    {
      "x": -33,
      "y": 9,
      "z": -4,
      "name": "Rock_Stone"
    },
    {
      "x": -33,
      "y": 10,
      "z": -4,
      "name": "Rock_Stone"
    },
    {
      "x": -33,
      "y": 11,
      "z": -4,
      "name": "Rock_Stone"
    },
    {
      "x": -33,
      "y": 12,
      "z": -4,
      "name": "Rock_Stone"
    },
    {
      "x": -33,
      "y": 13,
      "z": -4,
      "name": "Rock_Stone"
    },
    {
      "x": -33,
      "y": 14,
      "z": -4,
      "name": "Rock_Stone_Mossy"
    },
    {
      "x": -33,
      "y": 15,
      "z": -4,
      "name": "Rock_Stone_Mossy"
    },
    {
      "x": -33,
      "y": 16,
      "z": -4,
      "name": "Rock_Stone_Mossy"
    },
    {
      "x": -33,
      "y": 9,
      "z": -3,
      "name": "Rock_Stone"
    },
    {
      "x": -33,
      "y": 10,
      "z": -3,
      "name": "Rock_Stone"
    },
    {
      "x": -33,
      "y": 11,
      "z": -3,
      "name": "Rock_Stone"
    },
    {
      "x": -33,
      "y": 12,
      "z": -3,
      "name": "Rock_Stone"
    },
    {
      "x": -33,
      "y": 13,
      "z": -3,
      "name": "Rock_Stone"
    },
    {
      "x": -33,
      "y": 14,
      "z": -3,
      "name": "Rock_Stone_Mossy"
    },
    {
      "x": -33,
      "y": 15,
      "z": -3,
      "name": "Rock_Stone_Mossy"
    },
    {
      "x": -33,
      "y": 16,
      "z": -3,
      "name": "Rock_Stone_Mossy"
    },
    {
      "x": -33,
      "y": 9,
      "z": -2,
      "name": "Rock_Stone"
    },
    {
      "x": -33,
      "y": 10,
      "z": -2,
      "name": "Rock_Stone"
    },
    {
      "x": -33,
      "y": 11,
      "z": -2,
      "name": "Rock_Stone"
    },
    {
      "x": -33,
      "y": 12,
      "z": -2,
      "name": "Rock_Stone"
    },
    {
      "x": -33,
      "y": 13,
      "z": -2,
      "name": "Rock_Stone"
    },
    {
      "x": -33,
      "y": 14,
      "z": -2,
      "name": "Rock_Stone"
    },
    {
      "x": -33,
      "y": 15,
      "z": -2,
      "name": "Rock_Stone_Mossy"
    },
    {
      "x": -33,
      "y": 8,
      "z": 3,
      "name": "Rock_Stone"
    },
    {
      "x": -33,
      "y": 9,
      "z": 3,
      "name": "Rock_Stone"
    },
    {
      "x": -33,
      "y": 10,
      "z": 3,
      "name": "Rock_Stone"
    },
    {
      "x": -33,
      "y": 11,
      "z": 3,
      "name": "Rock_Stone"
    },
    {
      "x": -33,
      "y": 12,
      "z": 3,
      "name": "Rock_Stone"
    },
    {
      "x": -33,
      "y": 13,
      "z": 3,
      "name": "Rock_Stone"
    },
    {
      "x": -33,
      "y": 7,
      "z": 4,
      "name": "Rock_Stone"
    },
    {
      "x": -33,
      "y": 8,
      "z": 4,
      "name": "Rock_Stone"
    },
    {
      "x": -33,
      "y": 9,
      "z": 4,
      "name": "Rock_Stone"
    },
    {
      "x": -33,
      "y": 10,
      "z": 4,
      "name": "Rock_Stone"
    },
    {
      "x": -33,
      "y": 11,
      "z": 4,
      "name": "Rock_Stone"
    },
    {
      "x": -33,
      "y": 12,
      "z": 4,
      "name": "Rock_Stone"
    },
    {
      "x": -33,
      "y": 13,
      "z": 4,
      "name": "Rock_Stone"
    },
    {
      "x": -33,
      "y": 8,
      "z": 5,
      "name": "Rock_Stone"
    },
    {
      "x": -33,
      "y": 9,
      "z": 5,
      "name": "Rock_Stone"
    },
    {
      "x": -33,
      "y": 10,
      "z": 5,
      "name": "Rock_Stone"
    },
    {
      "x": -33,
      "y": 11,
      "z": 5,
      "name": "Rock_Stone"
    },
    {
      "x": -32,
      "y": 7,
      "z": -14,
      "name": "Rock_Stone"
    },
    {
      "x": -32,
      "y": 8,
      "z": -14,
      "name": "Rock_Stone"
    },
    {
      "x": -32,
      "y": 9,
      "z": -14,
      "name": "Rock_Stone"
    },
    {
      "x": -32,
      "y": 10,
      "z": -14,
      "name": "Rock_Stone"
    },
    {
      "x": -32,
      "y": 11,
      "z": -14,
      "name": "Rock_Stone"
    },
    {
      "x": -32,
      "y": 12,
      "z": -14,
      "name": "Rock_Stone"
    },
    {
      "x": -32,
      "y": 13,
      "z": -14,
      "name": "Rock_Stone"
    },
    {
      "x": -32,
      "y": 14,
      "z": -14,
      "name": "Soil_Dirt"
    },
    {
      "x": -32,
      "y": 7,
      "z": -13,
      "name": "Rock_Stone"
    },
    {
      "x": -32,
      "y": 8,
      "z": -13,
      "name": "Rock_Stone"
    },
    {
      "x": -32,
      "y": 9,
      "z": -13,
      "name": "Rock_Stone"
    },
    {
      "x": -32,
      "y": 10,
      "z": -13,
      "name": "Rock_Stone"
    },
    {
      "x": -32,
      "y": 11,
      "z": -13,
      "name": "Rock_Stone"
    },
    {
      "x": -32,
      "y": 12,
      "z": -13,
      "name": "Rock_Stone"
    },
    {
      "x": -32,
      "y": 13,
      "z": -13,
      "name": "Rock_Stone"
    },
    {
      "x": -32,
      "y": 14,
      "z": -13,
      "name": "Soil_Dirt"
    },
    {
      "x": -32,
      "y": 15,
      "z": -13,
      "name": "Soil_Dirt"
    },
    {
      "x": -32,
      "y": 7,
      "z": -12,
      "name": "Rock_Stone"
    },
    {
      "x": -32,
      "y": 8,
      "z": -12,
      "name": "Rock_Stone"
    },
    {
      "x": -32,
      "y": 9,
      "z": -12,
      "name": "Rock_Stone"
    },
    {
      "x": -32,
      "y": 10,
      "z": -12,
      "name": "Rock_Stone"
    },
    {
      "x": -32,
      "y": 11,
      "z": -12,
      "name": "Rock_Stone"
    },
    {
      "x": -32,
      "y": 12,
      "z": -12,
      "name": "Rock_Stone"
    },
    {
      "x": -32,
      "y": 13,
      "z": -12,
      "name": "Rock_Stone"
    },
    {
      "x": -32,
      "y": 14,
      "z": -12,
      "name": "Rock_Stone"
    },
    {
      "x": -32,
      "y": 15,
      "z": -12,
      "name": "Rock_Stone"
    },
    {
      "x": -32,
      "y": 16,
      "z": -12,
      "name": "Rock_Stone"
    },
    {
      "x": -32,
      "y": 17,
      "z": -12,
      "name": "Soil_Dirt"
    },
    {
      "x": -32,
      "y": 8,
      "z": -11,
      "name": "Rock_Stone"
    },
    {
      "x": -32,
      "y": 9,
      "z": -11,
      "name": "Rock_Stone"
    },
    {
      "x": -32,
      "y": 10,
      "z": -11,
      "name": "Rock_Stone"
    },
    {
      "x": -32,
      "y": 11,
      "z": -11,
      "name": "Rock_Stone"
    },
    {
      "x": -32,
      "y": 12,
      "z": -11,
      "name": "Rock_Stone"
    },
    {
      "x": -32,
      "y": 13,
      "z": -11,
      "name": "Rock_Stone"
    },
    {
      "x": -32,
      "y": 14,
      "z": -11,
      "name": "Rock_Stone"
    },
    {
      "x": -32,
      "y": 15,
      "z": -11,
      "name": "Rock_Stone"
    },
    {
      "x": -32,
      "y": 16,
      "z": -11,
      "name": "Rock_Stone"
    },
    {
      "x": -32,
      "y": 17,
      "z": -11,
      "name": "Rock_Stone"
    },
    {
      "x": -32,
      "y": 18,
      "z": -11,
      "name": "Rock_Stone"
    },
    {
      "x": -32,
      "y": 19,
      "z": -11,
      "name": "Rock_Stone"
    },
    {
      "x": -32,
      "y": 8,
      "z": -10,
      "name": "Rock_Stone"
    },
    {
      "x": -32,
      "y": 9,
      "z": -10,
      "name": "Rock_Stone"
    },
    {
      "x": -32,
      "y": 10,
      "z": -10,
      "name": "Rock_Stone"
    },
    {
      "x": -32,
      "y": 11,
      "z": -10,
      "name": "Rock_Stone"
    },
    {
      "x": -32,
      "y": 12,
      "z": -10,
      "name": "Rock_Stone"
    },
    {
      "x": -32,
      "y": 13,
      "z": -10,
      "name": "Rock_Stone"
    },
    {
      "x": -32,
      "y": 14,
      "z": -10,
      "name": "Rock_Stone"
    },
    {
      "x": -32,
      "y": 15,
      "z": -10,
      "name": "Rock_Stone"
    },
    {
      "x": -32,
      "y": 16,
      "z": -10,
      "name": "Rock_Stone"
    },
    {
      "x": -32,
      "y": 17,
      "z": -10,
      "name": "Rock_Stone"
    },
    {
      "x": -32,
      "y": 18,
      "z": -10,
      "name": "Rock_Stone"
    },
    {
      "x": -32,
      "y": 19,
      "z": -10,
      "name": "Rock_Stone"
    },
    {
      "x": -32,
      "y": 8,
      "z": -9,
      "name": "Rock_Stone"
    },
    {
      "x": -32,
      "y": 9,
      "z": -9,
      "name": "Rock_Stone"
    },
    {
      "x": -32,
      "y": 10,
      "z": -9,
      "name": "Rock_Stone"
    },
    {
      "x": -32,
      "y": 11,
      "z": -9,
      "name": "Rock_Stone"
    },
    {
      "x": -32,
      "y": 12,
      "z": -9,
      "name": "Rock_Stone"
    },
    {
      "x": -32,
      "y": 13,
      "z": -9,
      "name": "Rock_Stone"
    },
    {
      "x": -32,
      "y": 14,
      "z": -9,
      "name": "Rock_Stone"
    },
    {
      "x": -32,
      "y": 15,
      "z": -9,
      "name": "Rock_Stone"
    },
    {
      "x": -32,
      "y": 16,
      "z": -9,
      "name": "Rock_Stone"
    },
    {
      "x": -32,
      "y": 17,
      "z": -9,
      "name": "Rock_Stone"
    },
    {
      "x": -32,
      "y": 18,
      "z": -9,
      "name": "Rock_Stone"
    },
    {
      "x": -32,
      "y": 19,
      "z": -9,
      "name": "Rock_Stone"
    },
    {
      "x": -32,
      "y": 20,
      "z": -9,
      "name": "Rock_Stone"
    },
    {
      "x": -32,
      "y": 21,
      "z": -9,
      "name": "Rock_Stone"
    },
    {
      "x": -32,
      "y": 8,
      "z": -8,
      "name": "Rock_Stone"
    },
    {
      "x": -32,
      "y": 9,
      "z": -8,
      "name": "Rock_Stone"
    },
    {
      "x": -32,
      "y": 10,
      "z": -8,
      "name": "Rock_Stone"
    },
    {
      "x": -32,
      "y": 11,
      "z": -8,
      "name": "Rock_Stone"
    },
    {
      "x": -32,
      "y": 12,
      "z": -8,
      "name": "Rock_Stone"
    },
    {
      "x": -32,
      "y": 13,
      "z": -8,
      "name": "Rock_Stone"
    },
    {
      "x": -32,
      "y": 14,
      "z": -8,
      "name": "Rock_Stone"
    },
    {
      "x": -32,
      "y": 15,
      "z": -8,
      "name": "Rock_Stone"
    },
    {
      "x": -32,
      "y": 16,
      "z": -8,
      "name": "Rock_Stone"
    },
    {
      "x": -32,
      "y": 17,
      "z": -8,
      "name": "Rock_Stone"
    },
    {
      "x": -32,
      "y": 18,
      "z": -8,
      "name": "Rock_Stone"
    },
    {
      "x": -32,
      "y": 19,
      "z": -8,
      "name": "Rock_Stone"
    },
    {
      "x": -32,
      "y": 20,
      "z": -8,
      "name": "Rock_Stone"
    },
    {
      "x": -32,
      "y": 21,
      "z": -8,
      "name": "Rock_Stone"
    },
    {
      "x": -32,
      "y": 8,
      "z": -7,
      "name": "Rock_Stone"
    },
    {
      "x": -32,
      "y": 9,
      "z": -7,
      "name": "Rock_Stone"
    },
    {
      "x": -32,
      "y": 10,
      "z": -7,
      "name": "Rock_Stone"
    },
    {
      "x": -32,
      "y": 11,
      "z": -7,
      "name": "Rock_Stone"
    },
    {
      "x": -32,
      "y": 12,
      "z": -7,
      "name": "Rock_Stone"
    },
    {
      "x": -32,
      "y": 13,
      "z": -7,
      "name": "Rock_Stone"
    },
    {
      "x": -32,
      "y": 14,
      "z": -7,
      "name": "Rock_Stone"
    },
    {
      "x": -32,
      "y": 15,
      "z": -7,
      "name": "Rock_Stone"
    },
    {
      "x": -32,
      "y": 16,
      "z": -7,
      "name": "Rock_Stone"
    },
    {
      "x": -32,
      "y": 17,
      "z": -7,
      "name": "Rock_Stone"
    },
    {
      "x": -32,
      "y": 18,
      "z": -7,
      "name": "Rock_Stone"
    },
    {
      "x": -32,
      "y": 19,
      "z": -7,
      "name": "Rock_Stone_Mossy"
    },
    {
      "x": -32,
      "y": 20,
      "z": -7,
      "name": "Rock_Stone_Mossy"
    },
    {
      "x": -32,
      "y": 21,
      "z": -7,
      "name": "Rock_Stone_Mossy"
    },
    {
      "x": -32,
      "y": 22,
      "z": -7,
      "name": "Plant_Moss_Rug_Green"
    },
    {
      "x": -32,
      "y": 8,
      "z": -6,
      "name": "Rock_Stone"
    },
    {
      "x": -32,
      "y": 9,
      "z": -6,
      "name": "Rock_Stone"
    },
    {
      "x": -32,
      "y": 10,
      "z": -6,
      "name": "Rock_Stone"
    },
    {
      "x": -32,
      "y": 11,
      "z": -6,
      "name": "Rock_Stone"
    },
    {
      "x": -32,
      "y": 12,
      "z": -6,
      "name": "Rock_Stone"
    },
    {
      "x": -32,
      "y": 13,
      "z": -6,
      "name": "Rock_Stone"
    },
    {
      "x": -32,
      "y": 14,
      "z": -6,
      "name": "Rock_Stone"
    },
    {
      "x": -32,
      "y": 15,
      "z": -6,
      "name": "Rock_Stone"
    },
    {
      "x": -32,
      "y": 16,
      "z": -6,
      "name": "Rock_Stone_Mossy"
    },
    {
      "x": -32,
      "y": 17,
      "z": -6,
      "name": "Rock_Stone"
    },
    {
      "x": -32,
      "y": 18,
      "z": -6,
      "name": "Rock_Stone_Mossy"
    },
    {
      "x": -32,
      "y": 19,
      "z": -6,
      "name": "Rock_Stone_Mossy"
    },
    {
      "x": -32,
      "y": 20,
      "z": -6,
      "name": "Rock_Stone_Mossy"
    },
    {
      "x": -32,
      "y": 21,
      "z": -6,
      "name": "Plant_Moss_Block_Green"
    },
    {
      "x": -32,
      "y": 22,
      "z": -6,
      "name": "Plant_Moss_Rug_Green"
    },
    {
      "x": -32,
      "y": 8,
      "z": -5,
      "name": "Rock_Stone"
    },
    {
      "x": -32,
      "y": 9,
      "z": -5,
      "name": "Rock_Stone"
    },
    {
      "x": -32,
      "y": 10,
      "z": -5,
      "name": "Rock_Stone"
    },
    {
      "x": -32,
      "y": 11,
      "z": -5,
      "name": "Rock_Stone"
    },
    {
      "x": -32,
      "y": 12,
      "z": -5,
      "name": "Rock_Stone"
    },
    {
      "x": -32,
      "y": 13,
      "z": -5,
      "name": "Rock_Stone"
    },
    {
      "x": -32,
      "y": 14,
      "z": -5,
      "name": "Rock_Stone"
    },
    {
      "x": -32,
      "y": 15,
      "z": -5,
      "name": "Rock_Stone_Mossy"
    },
    {
      "x": -32,
      "y": 16,
      "z": -5,
      "name": "Rock_Stone_Mossy"
    },
    {
      "x": -32,
      "y": 17,
      "z": -5,
      "name": "Rock_Stone_Mossy"
    },
    {
      "x": -32,
      "y": 18,
      "z": -5,
      "name": "Rock_Stone_Mossy"
    },
    {
      "x": -32,
      "y": 19,
      "z": -5,
      "name": "Plant_Moss_Block_Green"
    },
    {
      "x": -32,
      "y": 20,
      "z": -5,
      "name": "Plant_Moss_Block_Green"
    },
    {
      "x": -32,
      "y": 21,
      "z": -5,
      "name": "Plant_Moss_Wall_Green"
    },
    {
      "x": -32,
      "y": 9,
      "z": -4,
      "name": "Rock_Stone"
    },
    {
      "x": -32,
      "y": 10,
      "z": -4,
      "name": "Rock_Stone"
    },
    {
      "x": -32,
      "y": 11,
      "z": -4,
      "name": "Rock_Stone"
    },
    {
      "x": -32,
      "y": 12,
      "z": -4,
      "name": "Rock_Stone"
    },
    {
      "x": -32,
      "y": 13,
      "z": -4,
      "name": "Rock_Stone"
    },
    {
      "x": -32,
      "y": 14,
      "z": -4,
      "name": "Rock_Stone_Mossy"
    },
    {
      "x": -32,
      "y": 15,
      "z": -4,
      "name": "Rock_Stone_Mossy"
    },
    {
      "x": -32,
      "y": 16,
      "z": -4,
      "name": "Rock_Stone_Mossy"
    },
    {
      "x": -32,
      "y": 9,
      "z": -3,
      "name": "Rock_Stone"
    },
    {
      "x": -32,
      "y": 10,
      "z": -3,
      "name": "Rock_Stone"
    },
    {
      "x": -32,
      "y": 11,
      "z": -3,
      "name": "Rock_Stone"
    },
    {
      "x": -32,
      "y": 12,
      "z": -3,
      "name": "Rock_Stone"
    },
    {
      "x": -32,
      "y": 13,
      "z": -3,
      "name": "Rock_Stone"
    },
    {
      "x": -32,
      "y": 14,
      "z": -3,
      "name": "Rock_Stone"
    },
    {
      "x": -32,
      "y": 15,
      "z": -3,
      "name": "Rock_Stone_Mossy"
    },
    {
      "x": -32,
      "y": 16,
      "z": -3,
      "name": "Rock_Stone_Mossy"
    },
    {
      "x": -32,
      "y": 9,
      "z": -2,
      "name": "Rock_Stone"
    },
    {
      "x": -32,
      "y": 10,
      "z": -2,
      "name": "Rock_Stone"
    },
    {
      "x": -32,
      "y": 11,
      "z": -2,
      "name": "Rock_Stone"
    },
    {
      "x": -32,
      "y": 12,
      "z": -2,
      "name": "Rock_Stone"
    },
    {
      "x": -32,
      "y": 13,
      "z": -2,
      "name": "Rock_Stone"
    },
    {
      "x": -32,
      "y": 14,
      "z": -2,
      "name": "Rock_Stone"
    },
    {
      "x": -32,
      "y": 15,
      "z": -2,
      "name": "Rock_Stone"
    },
    {
      "x": -32,
      "y": 16,
      "z": -2,
      "name": "Rock_Stone_Mossy"
    },
    {
      "x": -32,
      "y": 7,
      "z": 2,
      "name": "Rock_Stone"
    },
    {
      "x": -32,
      "y": 8,
      "z": 2,
      "name": "Rock_Stone"
    },
    {
      "x": -32,
      "y": 9,
      "z": 2,
      "name": "Rock_Stone"
    },
    {
      "x": -32,
      "y": 10,
      "z": 2,
      "name": "Rock_Stone"
    },
    {
      "x": -32,
      "y": 11,
      "z": 2,
      "name": "Rock_Stone"
    },
    {
      "x": -32,
      "y": 12,
      "z": 2,
      "name": "Rock_Stone"
    },
    {
      "x": -32,
      "y": 13,
      "z": 2,
      "name": "Rock_Stone"
    },
    {
      "x": -32,
      "y": 14,
      "z": 2,
      "name": "Rock_Stone"
    },
    {
      "x": -32,
      "y": 15,
      "z": 2,
      "name": "Rock_Stone"
    },
    {
      "x": -32,
      "y": 16,
      "z": 2,
      "name": "Rock_Stone"
    },
    {
      "x": -32,
      "y": 17,
      "z": 2,
      "name": "Rock_Stone"
    },
    {
      "x": -32,
      "y": 7,
      "z": 3,
      "name": "Rock_Stone"
    },
    {
      "x": -32,
      "y": 8,
      "z": 3,
      "name": "Rock_Stone"
    },
    {
      "x": -32,
      "y": 9,
      "z": 3,
      "name": "Rock_Stone"
    },
    {
      "x": -32,
      "y": 10,
      "z": 3,
      "name": "Rock_Stone"
    },
    {
      "x": -32,
      "y": 11,
      "z": 3,
      "name": "Rock_Stone"
    },
    {
      "x": -32,
      "y": 12,
      "z": 3,
      "name": "Rock_Stone"
    },
    {
      "x": -32,
      "y": 13,
      "z": 3,
      "name": "Rock_Stone"
    },
    {
      "x": -32,
      "y": 14,
      "z": 3,
      "name": "Rock_Stone"
    },
    {
      "x": -32,
      "y": 15,
      "z": 3,
      "name": "Rock_Stone_Mossy"
    },
    {
      "x": -32,
      "y": 16,
      "z": 3,
      "name": "Rock_Stone_Mossy"
    },
    {
      "x": -32,
      "y": 17,
      "z": 3,
      "name": "Rock_Stone"
    },
    {
      "x": -32,
      "y": 18,
      "z": 3,
      "name": "Rock_Stone"
    },
    {
      "x": -32,
      "y": 7,
      "z": 4,
      "name": "Rock_Stone"
    },
    {
      "x": -32,
      "y": 8,
      "z": 4,
      "name": "Rock_Stone"
    },
    {
      "x": -32,
      "y": 9,
      "z": 4,
      "name": "Rock_Stone"
    },
    {
      "x": -32,
      "y": 10,
      "z": 4,
      "name": "Rock_Stone"
    },
    {
      "x": -32,
      "y": 11,
      "z": 4,
      "name": "Rock_Stone"
    },
    {
      "x": -32,
      "y": 12,
      "z": 4,
      "name": "Rock_Stone"
    },
    {
      "x": -32,
      "y": 13,
      "z": 4,
      "name": "Rock_Stone"
    },
    {
      "x": -32,
      "y": 14,
      "z": 4,
      "name": "Rock_Stone_Mossy"
    },
    {
      "x": -32,
      "y": 15,
      "z": 4,
      "name": "Rock_Stone_Mossy"
    },
    {
      "x": -32,
      "y": 16,
      "z": 4,
      "name": "Rock_Stone_Mossy"
    },
    {
      "x": -32,
      "y": 17,
      "z": 4,
      "name": "Rock_Stone_Mossy"
    },
    {
      "x": -32,
      "y": 7,
      "z": 5,
      "name": "Rock_Stone"
    },
    {
      "x": -32,
      "y": 8,
      "z": 5,
      "name": "Rock_Stone"
    },
    {
      "x": -32,
      "y": 9,
      "z": 5,
      "name": "Rock_Stone"
    },
    {
      "x": -32,
      "y": 10,
      "z": 5,
      "name": "Rock_Stone"
    },
    {
      "x": -32,
      "y": 11,
      "z": 5,
      "name": "Rock_Stone"
    },
    {
      "x": -32,
      "y": 12,
      "z": 5,
      "name": "Rock_Stone"
    },
    {
      "x": -32,
      "y": 13,
      "z": 5,
      "name": "Rock_Stone_Mossy"
    },
    {
      "x": -32,
      "y": 14,
      "z": 5,
      "name": "Rock_Stone_Mossy"
    },
    {
      "x": -32,
      "y": 7,
      "z": 6,
      "name": "Rock_Stone"
    },
    {
      "x": -32,
      "y": 8,
      "z": 6,
      "name": "Rock_Stone"
    },
    {
      "x": -32,
      "y": 9,
      "z": 6,
      "name": "Rock_Stone"
    },
    {
      "x": -32,
      "y": 10,
      "z": 6,
      "name": "Rock_Stone"
    },
    {
      "x": -32,
      "y": 11,
      "z": 6,
      "name": "Rock_Stone_Mossy"
    },
    {
      "x": -32,
      "y": 12,
      "z": 6,
      "name": "Rock_Stone_Mossy"
    },
    {
      "x": -32,
      "y": 13,
      "z": 6,
      "name": "Rock_Stone_Mossy"
    },
    {
      "x": -31,
      "y": 7,
      "z": -15,
      "name": "Rock_Stone"
    },
    {
      "x": -31,
      "y": 8,
      "z": -15,
      "name": "Rock_Stone"
    },
    {
      "x": -31,
      "y": 9,
      "z": -15,
      "name": "Rock_Stone"
    },
    {
      "x": -31,
      "y": 10,
      "z": -15,
      "name": "Rock_Stone"
    },
    {
      "x": -31,
      "y": 11,
      "z": -15,
      "name": "Rock_Stone"
    },
    {
      "x": -31,
      "y": 12,
      "z": -15,
      "name": "Rock_Stone"
    },
    {
      "x": -31,
      "y": 13,
      "z": -15,
      "name": "Rock_Stone"
    },
    {
      "x": -31,
      "y": 14,
      "z": -15,
      "name": "Rock_Stone"
    },
    {
      "x": -31,
      "y": 15,
      "z": -15,
      "name": "Soil_Dirt"
    },
    {
      "x": -31,
      "y": 7,
      "z": -14,
      "name": "Rock_Stone"
    },
    {
      "x": -31,
      "y": 8,
      "z": -14,
      "name": "Rock_Stone"
    },
    {
      "x": -31,
      "y": 9,
      "z": -14,
      "name": "Rock_Stone"
    },
    {
      "x": -31,
      "y": 10,
      "z": -14,
      "name": "Rock_Stone"
    },
    {
      "x": -31,
      "y": 11,
      "z": -14,
      "name": "Rock_Stone"
    },
    {
      "x": -31,
      "y": 12,
      "z": -14,
      "name": "Rock_Stone"
    },
    {
      "x": -31,
      "y": 13,
      "z": -14,
      "name": "Rock_Stone"
    },
    {
      "x": -31,
      "y": 14,
      "z": -14,
      "name": "Rock_Stone"
    },
    {
      "x": -31,
      "y": 15,
      "z": -14,
      "name": "Soil_Dirt"
    },
    {
      "x": -31,
      "y": 16,
      "z": -14,
      "name": "Soil_Dirt"
    },
    {
      "x": -31,
      "y": 7,
      "z": -13,
      "name": "Rock_Stone"
    },
    {
      "x": -31,
      "y": 8,
      "z": -13,
      "name": "Rock_Stone"
    },
    {
      "x": -31,
      "y": 9,
      "z": -13,
      "name": "Rock_Stone"
    },
    {
      "x": -31,
      "y": 10,
      "z": -13,
      "name": "Rock_Stone"
    },
    {
      "x": -31,
      "y": 11,
      "z": -13,
      "name": "Rock_Stone"
    },
    {
      "x": -31,
      "y": 12,
      "z": -13,
      "name": "Rock_Stone"
    },
    {
      "x": -31,
      "y": 13,
      "z": -13,
      "name": "Rock_Stone"
    },
    {
      "x": -31,
      "y": 14,
      "z": -13,
      "name": "Rock_Stone"
    },
    {
      "x": -31,
      "y": 15,
      "z": -13,
      "name": "Soil_Dirt"
    },
    {
      "x": -31,
      "y": 16,
      "z": -13,
      "name": "Soil_Dirt"
    },
    {
      "x": -31,
      "y": 17,
      "z": -13,
      "name": "Soil_Dirt"
    },
    {
      "x": -31,
      "y": 7,
      "z": -12,
      "name": "Rock_Stone"
    },
    {
      "x": -31,
      "y": 8,
      "z": -12,
      "name": "Rock_Stone"
    },
    {
      "x": -31,
      "y": 9,
      "z": -12,
      "name": "Rock_Stone"
    },
    {
      "x": -31,
      "y": 10,
      "z": -12,
      "name": "Rock_Stone"
    },
    {
      "x": -31,
      "y": 11,
      "z": -12,
      "name": "Rock_Stone"
    },
    {
      "x": -31,
      "y": 12,
      "z": -12,
      "name": "Rock_Stone"
    },
    {
      "x": -31,
      "y": 13,
      "z": -12,
      "name": "Rock_Stone"
    },
    {
      "x": -31,
      "y": 14,
      "z": -12,
      "name": "Soil_Pathway"
    },
    {
      "x": -31,
      "y": 15,
      "z": -12,
      "name": "Soil_Pathway"
    },
    {
      "x": -31,
      "y": 16,
      "z": -12,
      "name": "Soil_Pathway"
    },
    {
      "x": -31,
      "y": 17,
      "z": -12,
      "name": "Soil_Pathway"
    },
    {
      "x": -31,
      "y": 18,
      "z": -12,
      "name": "Soil_Dirt"
    },
    {
      "x": -31,
      "y": 7,
      "z": -11,
      "name": "Rock_Stone"
    },
    {
      "x": -31,
      "y": 8,
      "z": -11,
      "name": "Rock_Stone"
    },
    {
      "x": -31,
      "y": 9,
      "z": -11,
      "name": "Rock_Stone"
    },
    {
      "x": -31,
      "y": 10,
      "z": -11,
      "name": "Rock_Stone"
    },
    {
      "x": -31,
      "y": 11,
      "z": -11,
      "name": "Rock_Stone"
    },
    {
      "x": -31,
      "y": 12,
      "z": -11,
      "name": "Rock_Stone"
    },
    {
      "x": -31,
      "y": 13,
      "z": -11,
      "name": "Rock_Stone"
    },
    {
      "x": -31,
      "y": 14,
      "z": -11,
      "name": "Rock_Stone"
    },
    {
      "x": -31,
      "y": 15,
      "z": -11,
      "name": "Rock_Stone"
    },
    {
      "x": -31,
      "y": 16,
      "z": -11,
      "name": "Rock_Stone"
    },
    {
      "x": -31,
      "y": 17,
      "z": -11,
      "name": "Rock_Stone"
    },
    {
      "x": -31,
      "y": 18,
      "z": -11,
      "name": "Rock_Stone"
    },
    {
      "x": -31,
      "y": 19,
      "z": -11,
      "name": "Rock_Stone"
    },
    {
      "x": -31,
      "y": 8,
      "z": -10,
      "name": "Rock_Stone"
    },
    {
      "x": -31,
      "y": 9,
      "z": -10,
      "name": "Rock_Stone"
    },
    {
      "x": -31,
      "y": 10,
      "z": -10,
      "name": "Rock_Stone"
    },
    {
      "x": -31,
      "y": 11,
      "z": -10,
      "name": "Rock_Stone"
    },
    {
      "x": -31,
      "y": 12,
      "z": -10,
      "name": "Rock_Stone"
    },
    {
      "x": -31,
      "y": 13,
      "z": -10,
      "name": "Rock_Stone"
    },
    {
      "x": -31,
      "y": 14,
      "z": -10,
      "name": "Rock_Stone"
    },
    {
      "x": -31,
      "y": 15,
      "z": -10,
      "name": "Rock_Stone"
    },
    {
      "x": -31,
      "y": 16,
      "z": -10,
      "name": "Rock_Stone"
    },
    {
      "x": -31,
      "y": 17,
      "z": -10,
      "name": "Rock_Stone"
    },
    {
      "x": -31,
      "y": 18,
      "z": -10,
      "name": "Rock_Stone"
    },
    {
      "x": -31,
      "y": 19,
      "z": -10,
      "name": "Rock_Stone"
    },
    {
      "x": -31,
      "y": 20,
      "z": -10,
      "name": "Rock_Stone"
    },
    {
      "x": -31,
      "y": 8,
      "z": -9,
      "name": "Rock_Stone"
    },
    {
      "x": -31,
      "y": 9,
      "z": -9,
      "name": "Rock_Stone"
    },
    {
      "x": -31,
      "y": 10,
      "z": -9,
      "name": "Rock_Stone"
    },
    {
      "x": -31,
      "y": 11,
      "z": -9,
      "name": "Rock_Stone"
    },
    {
      "x": -31,
      "y": 12,
      "z": -9,
      "name": "Rock_Stone"
    },
    {
      "x": -31,
      "y": 13,
      "z": -9,
      "name": "Rock_Stone"
    },
    {
      "x": -31,
      "y": 14,
      "z": -9,
      "name": "Rock_Stone"
    },
    {
      "x": -31,
      "y": 15,
      "z": -9,
      "name": "Rock_Stone"
    },
    {
      "x": -31,
      "y": 16,
      "z": -9,
      "name": "Rock_Stone"
    },
    {
      "x": -31,
      "y": 17,
      "z": -9,
      "name": "Rock_Stone"
    },
    {
      "x": -31,
      "y": 18,
      "z": -9,
      "name": "Rock_Stone"
    },
    {
      "x": -31,
      "y": 19,
      "z": -9,
      "name": "Rock_Stone"
    },
    {
      "x": -31,
      "y": 20,
      "z": -9,
      "name": "Rock_Stone"
    },
    {
      "x": -31,
      "y": 21,
      "z": -9,
      "name": "Rock_Stone"
    },
    {
      "x": -31,
      "y": 8,
      "z": -8,
      "name": "Rock_Stone"
    },
    {
      "x": -31,
      "y": 9,
      "z": -8,
      "name": "Rock_Stone"
    },
    {
      "x": -31,
      "y": 10,
      "z": -8,
      "name": "Rock_Stone"
    },
    {
      "x": -31,
      "y": 11,
      "z": -8,
      "name": "Rock_Stone"
    },
    {
      "x": -31,
      "y": 12,
      "z": -8,
      "name": "Rock_Stone"
    },
    {
      "x": -31,
      "y": 13,
      "z": -8,
      "name": "Rock_Stone"
    },
    {
      "x": -31,
      "y": 14,
      "z": -8,
      "name": "Rock_Stone"
    },
    {
      "x": -31,
      "y": 15,
      "z": -8,
      "name": "Rock_Stone"
    },
    {
      "x": -31,
      "y": 16,
      "z": -8,
      "name": "Rock_Stone"
    },
    {
      "x": -31,
      "y": 17,
      "z": -8,
      "name": "Rock_Stone"
    },
    {
      "x": -31,
      "y": 18,
      "z": -8,
      "name": "Rock_Stone"
    },
    {
      "x": -31,
      "y": 19,
      "z": -8,
      "name": "Rock_Stone"
    },
    {
      "x": -31,
      "y": 20,
      "z": -8,
      "name": "Rock_Stone"
    },
    {
      "x": -31,
      "y": 21,
      "z": -8,
      "name": "Rock_Stone"
    },
    {
      "x": -31,
      "y": 22,
      "z": -8,
      "name": "Plant_Moss_Rug_Green"
    },
    {
      "x": -31,
      "y": 8,
      "z": -7,
      "name": "Rock_Stone"
    },
    {
      "x": -31,
      "y": 9,
      "z": -7,
      "name": "Rock_Stone"
    },
    {
      "x": -31,
      "y": 10,
      "z": -7,
      "name": "Rock_Stone"
    },
    {
      "x": -31,
      "y": 11,
      "z": -7,
      "name": "Rock_Stone"
    },
    {
      "x": -31,
      "y": 12,
      "z": -7,
      "name": "Rock_Stone"
    },
    {
      "x": -31,
      "y": 13,
      "z": -7,
      "name": "Rock_Stone"
    },
    {
      "x": -31,
      "y": 14,
      "z": -7,
      "name": "Rock_Stone"
    },
    {
      "x": -31,
      "y": 15,
      "z": -7,
      "name": "Rock_Stone"
    },
    {
      "x": -31,
      "y": 16,
      "z": -7,
      "name": "Rock_Stone"
    },
    {
      "x": -31,
      "y": 17,
      "z": -7,
      "name": "Rock_Stone"
    },
    {
      "x": -31,
      "y": 18,
      "z": -7,
      "name": "Rock_Stone"
    },
    {
      "x": -31,
      "y": 19,
      "z": -7,
      "name": "Rock_Stone"
    },
    {
      "x": -31,
      "y": 20,
      "z": -7,
      "name": "Rock_Stone_Mossy"
    },
    {
      "x": -31,
      "y": 21,
      "z": -7,
      "name": "Rock_Stone"
    },
    {
      "x": -31,
      "y": 22,
      "z": -7,
      "name": "Plant_Moss_Rug_Green"
    },
    {
      "x": -31,
      "y": 8,
      "z": -6,
      "name": "Rock_Stone"
    },
    {
      "x": -31,
      "y": 9,
      "z": -6,
      "name": "Rock_Stone"
    },
    {
      "x": -31,
      "y": 10,
      "z": -6,
      "name": "Rock_Stone"
    },
    {
      "x": -31,
      "y": 11,
      "z": -6,
      "name": "Rock_Stone"
    },
    {
      "x": -31,
      "y": 12,
      "z": -6,
      "name": "Rock_Stone"
    },
    {
      "x": -31,
      "y": 13,
      "z": -6,
      "name": "Rock_Stone"
    },
    {
      "x": -31,
      "y": 14,
      "z": -6,
      "name": "Rock_Stone"
    },
    {
      "x": -31,
      "y": 15,
      "z": -6,
      "name": "Rock_Stone"
    },
    {
      "x": -31,
      "y": 16,
      "z": -6,
      "name": "Rock_Stone"
    },
    {
      "x": -31,
      "y": 17,
      "z": -6,
      "name": "Rock_Stone"
    },
    {
      "x": -31,
      "y": 18,
      "z": -6,
      "name": "Rock_Stone_Mossy"
    },
    {
      "x": -31,
      "y": 19,
      "z": -6,
      "name": "Rock_Stone_Mossy"
    },
    {
      "x": -31,
      "y": 20,
      "z": -6,
      "name": "Plant_Moss_Block_Green"
    },
    {
      "x": -31,
      "y": 21,
      "z": -6,
      "name": "Plant_Moss_Block_Green"
    },
    {
      "x": -31,
      "y": 8,
      "z": -5,
      "name": "Rock_Stone"
    },
    {
      "x": -31,
      "y": 9,
      "z": -5,
      "name": "Rock_Stone"
    },
    {
      "x": -31,
      "y": 10,
      "z": -5,
      "name": "Rock_Stone"
    },
    {
      "x": -31,
      "y": 11,
      "z": -5,
      "name": "Rock_Stone"
    },
    {
      "x": -31,
      "y": 12,
      "z": -5,
      "name": "Rock_Stone"
    },
    {
      "x": -31,
      "y": 13,
      "z": -5,
      "name": "Rock_Stone"
    },
    {
      "x": -31,
      "y": 14,
      "z": -5,
      "name": "Rock_Stone"
    },
    {
      "x": -31,
      "y": 15,
      "z": -5,
      "name": "Rock_Stone"
    },
    {
      "x": -31,
      "y": 16,
      "z": -5,
      "name": "Rock_Stone_Mossy"
    },
    {
      "x": -31,
      "y": 17,
      "z": -5,
      "name": "Rock_Stone_Mossy"
    },
    {
      "x": -31,
      "y": 18,
      "z": -5,
      "name": "Rock_Stone_Mossy"
    },
    {
      "x": -31,
      "y": 19,
      "z": -5,
      "name": "Plant_Moss_Block_Green"
    },
    {
      "x": -31,
      "y": 8,
      "z": -4,
      "name": "Rock_Stone"
    },
    {
      "x": -31,
      "y": 9,
      "z": -4,
      "name": "Rock_Stone"
    },
    {
      "x": -31,
      "y": 10,
      "z": -4,
      "name": "Rock_Stone"
    },
    {
      "x": -31,
      "y": 11,
      "z": -4,
      "name": "Rock_Stone"
    },
    {
      "x": -31,
      "y": 12,
      "z": -4,
      "name": "Rock_Stone"
    },
    {
      "x": -31,
      "y": 13,
      "z": -4,
      "name": "Rock_Stone"
    },
    {
      "x": -31,
      "y": 14,
      "z": -4,
      "name": "Rock_Stone"
    },
    {
      "x": -31,
      "y": 15,
      "z": -4,
      "name": "Rock_Stone_Mossy"
    },
    {
      "x": -31,
      "y": 16,
      "z": -4,
      "name": "Rock_Stone_Mossy"
    },
    {
      "x": -31,
      "y": 17,
      "z": -4,
      "name": "Rock_Stone_Mossy"
    },
    {
      "x": -31,
      "y": 18,
      "z": -4,
      "name": "Plant_Moss_Block_Green"
    },
    {
      "x": -31,
      "y": 19,
      "z": -4,
      "name": "Plant_Moss_Block_Green"
    },
    {
      "x": -31,
      "y": 8,
      "z": -3,
      "name": "Rock_Stone"
    },
    {
      "x": -31,
      "y": 9,
      "z": -3,
      "name": "Rock_Stone"
    },
    {
      "x": -31,
      "y": 10,
      "z": -3,
      "name": "Rock_Stone"
    },
    {
      "x": -31,
      "y": 11,
      "z": -3,
      "name": "Rock_Stone"
    },
    {
      "x": -31,
      "y": 12,
      "z": -3,
      "name": "Rock_Stone"
    },
    {
      "x": -31,
      "y": 13,
      "z": -3,
      "name": "Rock_Stone"
    },
    {
      "x": -31,
      "y": 14,
      "z": -3,
      "name": "Rock_Stone"
    },
    {
      "x": -31,
      "y": 15,
      "z": -3,
      "name": "Rock_Stone"
    },
    {
      "x": -31,
      "y": 16,
      "z": -3,
      "name": "Rock_Stone_Mossy"
    },
    {
      "x": -31,
      "y": 17,
      "z": -3,
      "name": "Rock_Stone_Mossy"
    },
    {
      "x": -31,
      "y": 18,
      "z": -3,
      "name": "Rock_Stone_Mossy"
    },
    {
      "x": -31,
      "y": 19,
      "z": -3,
      "name": "Rock_Stone_Mossy"
    },
    {
      "x": -31,
      "y": 20,
      "z": -3,
      "name": "Plant_Moss_Rug_Green"
    },
    {
      "x": -31,
      "y": 9,
      "z": -2,
      "name": "Rock_Stone"
    },
    {
      "x": -31,
      "y": 10,
      "z": -2,
      "name": "Rock_Stone"
    },
    {
      "x": -31,
      "y": 11,
      "z": -2,
      "name": "Rock_Stone"
    },
    {
      "x": -31,
      "y": 12,
      "z": -2,
      "name": "Rock_Stone"
    },
    {
      "x": -31,
      "y": 13,
      "z": -2,
      "name": "Rock_Stone"
    },
    {
      "x": -31,
      "y": 14,
      "z": -2,
      "name": "Rock_Stone"
    },
    {
      "x": -31,
      "y": 15,
      "z": -2,
      "name": "Rock_Stone"
    },
    {
      "x": -31,
      "y": 16,
      "z": -2,
      "name": "Rock_Stone"
    },
    {
      "x": -31,
      "y": 7,
      "z": 1,
      "name": "Rock_Stone"
    },
    {
      "x": -31,
      "y": 8,
      "z": 1,
      "name": "Rock_Stone"
    },
    {
      "x": -31,
      "y": 9,
      "z": 1,
      "name": "Rock_Stone"
    },
    {
      "x": -31,
      "y": 10,
      "z": 1,
      "name": "Rock_Stone"
    },
    {
      "x": -31,
      "y": 11,
      "z": 1,
      "name": "Rock_Stone"
    },
    {
      "x": -31,
      "y": 12,
      "z": 1,
      "name": "Rock_Stone"
    },
    {
      "x": -31,
      "y": 13,
      "z": 1,
      "name": "Rock_Stone"
    },
    {
      "x": -31,
      "y": 14,
      "z": 1,
      "name": "Rock_Stone"
    },
    {
      "x": -31,
      "y": 15,
      "z": 1,
      "name": "Rock_Stone"
    },
    {
      "x": -31,
      "y": 16,
      "z": 1,
      "name": "Rock_Stone"
    },
    {
      "x": -31,
      "y": 17,
      "z": 1,
      "name": "Rock_Stone"
    },
    {
      "x": -31,
      "y": 18,
      "z": 1,
      "name": "Rock_Stone"
    },
    {
      "x": -31,
      "y": 19,
      "z": 1,
      "name": "Rock_Stone"
    },
    {
      "x": -31,
      "y": 20,
      "z": 1,
      "name": "Rock_Stone"
    },
    {
      "x": -31,
      "y": 7,
      "z": 2,
      "name": "Rock_Stone"
    },
    {
      "x": -31,
      "y": 8,
      "z": 2,
      "name": "Rock_Stone"
    },
    {
      "x": -31,
      "y": 9,
      "z": 2,
      "name": "Rock_Stone"
    },
    {
      "x": -31,
      "y": 10,
      "z": 2,
      "name": "Rock_Stone"
    },
    {
      "x": -31,
      "y": 11,
      "z": 2,
      "name": "Rock_Stone"
    },
    {
      "x": -31,
      "y": 12,
      "z": 2,
      "name": "Rock_Stone"
    },
    {
      "x": -31,
      "y": 13,
      "z": 2,
      "name": "Rock_Stone"
    },
    {
      "x": -31,
      "y": 14,
      "z": 2,
      "name": "Rock_Stone"
    },
    {
      "x": -31,
      "y": 15,
      "z": 2,
      "name": "Rock_Stone"
    },
    {
      "x": -31,
      "y": 16,
      "z": 2,
      "name": "Rock_Stone"
    },
    {
      "x": -31,
      "y": 17,
      "z": 2,
      "name": "Rock_Stone"
    },
    {
      "x": -31,
      "y": 18,
      "z": 2,
      "name": "Rock_Stone"
    },
    {
      "x": -31,
      "y": 19,
      "z": 2,
      "name": "Rock_Stone"
    },
    {
      "x": -31,
      "y": 20,
      "z": 2,
      "name": "Rock_Stone"
    },
    {
      "x": -31,
      "y": 21,
      "z": 2,
      "name": "Rock_Stone"
    },
    {
      "x": -31,
      "y": 7,
      "z": 3,
      "name": "Rock_Stone"
    },
    {
      "x": -31,
      "y": 8,
      "z": 3,
      "name": "Rock_Stone"
    },
    {
      "x": -31,
      "y": 9,
      "z": 3,
      "name": "Rock_Stone"
    },
    {
      "x": -31,
      "y": 10,
      "z": 3,
      "name": "Rock_Stone"
    },
    {
      "x": -31,
      "y": 11,
      "z": 3,
      "name": "Rock_Stone"
    },
    {
      "x": -31,
      "y": 12,
      "z": 3,
      "name": "Rock_Stone"
    },
    {
      "x": -31,
      "y": 13,
      "z": 3,
      "name": "Rock_Stone"
    },
    {
      "x": -31,
      "y": 14,
      "z": 3,
      "name": "Rock_Stone"
    },
    {
      "x": -31,
      "y": 15,
      "z": 3,
      "name": "Rock_Stone"
    },
    {
      "x": -31,
      "y": 16,
      "z": 3,
      "name": "Rock_Stone"
    },
    {
      "x": -31,
      "y": 17,
      "z": 3,
      "name": "Rock_Stone"
    },
    {
      "x": -31,
      "y": 18,
      "z": 3,
      "name": "Rock_Stone"
    },
    {
      "x": -31,
      "y": 19,
      "z": 3,
      "name": "Rock_Stone"
    },
    {
      "x": -31,
      "y": 20,
      "z": 3,
      "name": "Rock_Stone"
    },
    {
      "x": -31,
      "y": 21,
      "z": 3,
      "name": "Rock_Stone"
    },
    {
      "x": -31,
      "y": 7,
      "z": 4,
      "name": "Rock_Stone"
    },
    {
      "x": -31,
      "y": 8,
      "z": 4,
      "name": "Rock_Stone"
    },
    {
      "x": -31,
      "y": 9,
      "z": 4,
      "name": "Rock_Stone"
    },
    {
      "x": -31,
      "y": 10,
      "z": 4,
      "name": "Rock_Stone"
    },
    {
      "x": -31,
      "y": 11,
      "z": 4,
      "name": "Rock_Stone"
    },
    {
      "x": -31,
      "y": 12,
      "z": 4,
      "name": "Rock_Stone"
    },
    {
      "x": -31,
      "y": 13,
      "z": 4,
      "name": "Rock_Stone"
    },
    {
      "x": -31,
      "y": 14,
      "z": 4,
      "name": "Rock_Stone"
    },
    {
      "x": -31,
      "y": 15,
      "z": 4,
      "name": "Rock_Stone"
    },
    {
      "x": -31,
      "y": 16,
      "z": 4,
      "name": "Rock_Stone"
    },
    {
      "x": -31,
      "y": 17,
      "z": 4,
      "name": "Rock_Stone"
    },
    {
      "x": -31,
      "y": 18,
      "z": 4,
      "name": "Rock_Stone_Mossy"
    },
    {
      "x": -31,
      "y": 7,
      "z": 5,
      "name": "Rock_Stone"
    },
    {
      "x": -31,
      "y": 8,
      "z": 5,
      "name": "Rock_Stone"
    },
    {
      "x": -31,
      "y": 9,
      "z": 5,
      "name": "Rock_Stone"
    },
    {
      "x": -31,
      "y": 10,
      "z": 5,
      "name": "Rock_Stone"
    },
    {
      "x": -31,
      "y": 11,
      "z": 5,
      "name": "Rock_Stone"
    },
    {
      "x": -31,
      "y": 12,
      "z": 5,
      "name": "Rock_Stone"
    },
    {
      "x": -31,
      "y": 13,
      "z": 5,
      "name": "Rock_Stone"
    },
    {
      "x": -31,
      "y": 14,
      "z": 5,
      "name": "Rock_Stone"
    },
    {
      "x": -31,
      "y": 15,
      "z": 5,
      "name": "Rock_Stone_Mossy"
    },
    {
      "x": -31,
      "y": 16,
      "z": 5,
      "name": "Rock_Stone_Mossy"
    },
    {
      "x": -31,
      "y": 17,
      "z": 5,
      "name": "Rock_Stone_Mossy"
    },
    {
      "x": -31,
      "y": 7,
      "z": 6,
      "name": "Rock_Stone"
    },
    {
      "x": -31,
      "y": 8,
      "z": 6,
      "name": "Rock_Stone"
    },
    {
      "x": -31,
      "y": 9,
      "z": 6,
      "name": "Rock_Stone"
    },
    {
      "x": -31,
      "y": 10,
      "z": 6,
      "name": "Rock_Stone"
    },
    {
      "x": -31,
      "y": 11,
      "z": 6,
      "name": "Rock_Stone"
    },
    {
      "x": -31,
      "y": 12,
      "z": 6,
      "name": "Rock_Stone"
    },
    {
      "x": -31,
      "y": 13,
      "z": 6,
      "name": "Rock_Stone_Mossy"
    },
    {
      "x": -31,
      "y": 14,
      "z": 6,
      "name": "Rock_Stone_Mossy"
    },
    {
      "x": -31,
      "y": 15,
      "z": 6,
      "name": "Rock_Stone_Mossy"
    },
    {
      "x": -31,
      "y": 9,
      "z": 7,
      "name": "Rock_Stone"
    },
    {
      "x": -31,
      "y": 10,
      "z": 7,
      "name": "Rock_Stone"
    },
    {
      "x": -31,
      "y": 11,
      "z": 7,
      "name": "Rock_Stone"
    },
    {
      "x": -31,
      "y": 12,
      "z": 7,
      "name": "Rock_Stone_Mossy"
    },
    {
      "x": -30,
      "y": 7,
      "z": -16,
      "name": "Rock_Stone"
    },
    {
      "x": -30,
      "y": 8,
      "z": -16,
      "name": "Rock_Stone"
    },
    {
      "x": -30,
      "y": 9,
      "z": -16,
      "name": "Rock_Stone"
    },
    {
      "x": -30,
      "y": 10,
      "z": -16,
      "name": "Rock_Stone"
    },
    {
      "x": -30,
      "y": 11,
      "z": -16,
      "name": "Rock_Stone"
    },
    {
      "x": -30,
      "y": 12,
      "z": -16,
      "name": "Rock_Stone"
    },
    {
      "x": -30,
      "y": 13,
      "z": -16,
      "name": "Rock_Stone"
    },
    {
      "x": -30,
      "y": 14,
      "z": -16,
      "name": "Rock_Stone"
    },
    {
      "x": -30,
      "y": 15,
      "z": -16,
      "name": "Soil_Dirt"
    },
    {
      "x": -30,
      "y": 16,
      "z": -16,
      "name": "Soil_Dirt"
    },
    {
      "x": -30,
      "y": 7,
      "z": -15,
      "name": "Rock_Stone"
    },
    {
      "x": -30,
      "y": 8,
      "z": -15,
      "name": "Rock_Stone"
    },
    {
      "x": -30,
      "y": 9,
      "z": -15,
      "name": "Rock_Stone"
    },
    {
      "x": -30,
      "y": 10,
      "z": -15,
      "name": "Rock_Stone"
    },
    {
      "x": -30,
      "y": 11,
      "z": -15,
      "name": "Rock_Stone"
    },
    {
      "x": -30,
      "y": 12,
      "z": -15,
      "name": "Rock_Stone"
    },
    {
      "x": -30,
      "y": 13,
      "z": -15,
      "name": "Rock_Stone"
    },
    {
      "x": -30,
      "y": 14,
      "z": -15,
      "name": "Rock_Stone"
    },
    {
      "x": -30,
      "y": 15,
      "z": -15,
      "name": "Rock_Stone"
    },
    {
      "x": -30,
      "y": 16,
      "z": -15,
      "name": "Soil_Dirt"
    },
    {
      "x": -30,
      "y": 7,
      "z": -14,
      "name": "Rock_Stone"
    },
    {
      "x": -30,
      "y": 8,
      "z": -14,
      "name": "Rock_Stone"
    },
    {
      "x": -30,
      "y": 9,
      "z": -14,
      "name": "Rock_Stone"
    },
    {
      "x": -30,
      "y": 10,
      "z": -14,
      "name": "Rock_Stone"
    },
    {
      "x": -30,
      "y": 11,
      "z": -14,
      "name": "Rock_Stone"
    },
    {
      "x": -30,
      "y": 12,
      "z": -14,
      "name": "Rock_Stone"
    },
    {
      "x": -30,
      "y": 13,
      "z": -14,
      "name": "Rock_Stone"
    },
    {
      "x": -30,
      "y": 14,
      "z": -14,
      "name": "Rock_Stone"
    },
    {
      "x": -30,
      "y": 15,
      "z": -14,
      "name": "Rock_Stone"
    },
    {
      "x": -30,
      "y": 16,
      "z": -14,
      "name": "Soil_Dirt"
    },
    {
      "x": -30,
      "y": 17,
      "z": -14,
      "name": "Soil_Dirt"
    },
    {
      "x": -30,
      "y": 18,
      "z": -14,
      "name": "Empty"
    },
    {
      "x": -30,
      "y": 19,
      "z": -14,
      "name": "Empty"
    },
    {
      "x": -30,
      "y": 20,
      "z": -14,
      "name": "Empty"
    },
    {
      "x": -30,
      "y": 21,
      "z": -14,
      "name": "Empty"
    },
    {
      "x": -30,
      "y": 22,
      "z": -14,
      "name": "Empty"
    },
    {
      "x": -30,
      "y": 23,
      "z": -14,
      "name": "Empty"
    },
    {
      "x": -30,
      "y": 24,
      "z": -14,
      "name": "Empty"
    },
    {
      "x": -30,
      "y": 25,
      "z": -14,
      "name": "Empty"
    },
    {
      "x": -30,
      "y": 26,
      "z": -14,
      "name": "Empty"
    },
    {
      "x": -30,
      "y": 27,
      "z": -14,
      "name": "Empty"
    },
    {
      "x": -30,
      "y": 28,
      "z": -14,
      "name": "Empty"
    },
    {
      "x": -30,
      "y": 29,
      "z": -14,
      "name": "Empty"
    },
    {
      "x": -30,
      "y": 30,
      "z": -14,
      "name": "Empty"
    },
    {
      "x": -30,
      "y": 31,
      "z": -14,
      "name": "Empty"
    },
    {
      "x": -30,
      "y": 32,
      "z": -14,
      "name": "Empty"
    },
    {
      "x": -30,
      "y": 33,
      "z": -14,
      "name": "Empty"
    },
    {
      "x": -30,
      "y": 34,
      "z": -14,
      "name": "Empty"
    },
    {
      "x": -30,
      "y": 35,
      "z": -14,
      "name": "Empty"
    },
    {
      "x": -30,
      "y": 36,
      "z": -14,
      "name": "Empty"
    },
    {
      "x": -30,
      "y": 7,
      "z": -13,
      "name": "Rock_Stone"
    },
    {
      "x": -30,
      "y": 8,
      "z": -13,
      "name": "Rock_Stone"
    },
    {
      "x": -30,
      "y": 9,
      "z": -13,
      "name": "Rock_Stone"
    },
    {
      "x": -30,
      "y": 10,
      "z": -13,
      "name": "Rock_Stone"
    },
    {
      "x": -30,
      "y": 11,
      "z": -13,
      "name": "Rock_Stone"
    },
    {
      "x": -30,
      "y": 12,
      "z": -13,
      "name": "Rock_Stone"
    },
    {
      "x": -30,
      "y": 13,
      "z": -13,
      "name": "Rock_Stone"
    },
    {
      "x": -30,
      "y": 14,
      "z": -13,
      "name": "Rock_Stone"
    },
    {
      "x": -30,
      "y": 15,
      "z": -13,
      "name": "Rock_Stone"
    },
    {
      "x": -30,
      "y": 16,
      "z": -13,
      "name": "Soil_Dirt"
    },
    {
      "x": -30,
      "y": 17,
      "z": -13,
      "name": "Soil_Dirt"
    },
    {
      "x": -30,
      "y": 18,
      "z": -13,
      "name": "Empty"
    },
    {
      "x": -30,
      "y": 19,
      "z": -13,
      "name": "Empty"
    },
    {
      "x": -30,
      "y": 20,
      "z": -13,
      "name": "Empty"
    },
    {
      "x": -30,
      "y": 21,
      "z": -13,
      "name": "Empty"
    },
    {
      "x": -30,
      "y": 22,
      "z": -13,
      "name": "Empty"
    },
    {
      "x": -30,
      "y": 23,
      "z": -13,
      "name": "Empty"
    },
    {
      "x": -30,
      "y": 24,
      "z": -13,
      "name": "Empty"
    },
    {
      "x": -30,
      "y": 25,
      "z": -13,
      "name": "Empty"
    },
    {
      "x": -30,
      "y": 26,
      "z": -13,
      "name": "Empty"
    },
    {
      "x": -30,
      "y": 27,
      "z": -13,
      "name": "Empty"
    },
    {
      "x": -30,
      "y": 28,
      "z": -13,
      "name": "Empty"
    },
    {
      "x": -30,
      "y": 29,
      "z": -13,
      "name": "Empty"
    },
    {
      "x": -30,
      "y": 30,
      "z": -13,
      "name": "Empty"
    },
    {
      "x": -30,
      "y": 31,
      "z": -13,
      "name": "Empty"
    },
    {
      "x": -30,
      "y": 32,
      "z": -13,
      "name": "Empty"
    },
    {
      "x": -30,
      "y": 33,
      "z": -13,
      "name": "Empty"
    },
    {
      "x": -30,
      "y": 34,
      "z": -13,
      "name": "Empty"
    },
    {
      "x": -30,
      "y": 35,
      "z": -13,
      "name": "Empty"
    },
    {
      "x": -30,
      "y": 36,
      "z": -13,
      "name": "Empty"
    },
    {
      "x": -30,
      "y": 7,
      "z": -12,
      "name": "Rock_Stone"
    },
    {
      "x": -30,
      "y": 8,
      "z": -12,
      "name": "Rock_Stone"
    },
    {
      "x": -30,
      "y": 9,
      "z": -12,
      "name": "Rock_Stone"
    },
    {
      "x": -30,
      "y": 10,
      "z": -12,
      "name": "Rock_Stone"
    },
    {
      "x": -30,
      "y": 11,
      "z": -12,
      "name": "Rock_Stone"
    },
    {
      "x": -30,
      "y": 12,
      "z": -12,
      "name": "Rock_Stone"
    },
    {
      "x": -30,
      "y": 13,
      "z": -12,
      "name": "Rock_Stone"
    },
    {
      "x": -30,
      "y": 14,
      "z": -12,
      "name": "Soil_Pathway"
    },
    {
      "x": -30,
      "y": 15,
      "z": -12,
      "name": "Soil_Pathway"
    },
    {
      "x": -30,
      "y": 16,
      "z": -12,
      "name": "Soil_Pathway"
    },
    {
      "x": -30,
      "y": 17,
      "z": -12,
      "name": "Soil_Dirt"
    },
    {
      "x": -30,
      "y": 18,
      "z": -12,
      "name": "Soil_Dirt"
    },
    {
      "x": -30,
      "y": 19,
      "z": -12,
      "name": "Soil_Leaves"
    },
    {
      "x": -30,
      "y": 20,
      "z": -12,
      "name": "Plant_Grass_Sharp",
      "support": 15
    },
    {
      "x": -30,
      "y": 21,
      "z": -12,
      "name": "Empty"
    },
    {
      "x": -30,
      "y": 22,
      "z": -12,
      "name": "Empty"
    },
    {
      "x": -30,
      "y": 23,
      "z": -12,
      "name": "Empty"
    },
    {
      "x": -30,
      "y": 24,
      "z": -12,
      "name": "Empty"
    },
    {
      "x": -30,
      "y": 25,
      "z": -12,
      "name": "Empty"
    },
    {
      "x": -30,
      "y": 26,
      "z": -12,
      "name": "Empty"
    },
    {
      "x": -30,
      "y": 27,
      "z": -12,
      "name": "Empty"
    },
    {
      "x": -30,
      "y": 28,
      "z": -12,
      "name": "Empty"
    },
    {
      "x": -30,
      "y": 29,
      "z": -12,
      "name": "Empty"
    },
    {
      "x": -30,
      "y": 30,
      "z": -12,
      "name": "Empty"
    },
    {
      "x": -30,
      "y": 31,
      "z": -12,
      "name": "Empty"
    },
    {
      "x": -30,
      "y": 32,
      "z": -12,
      "name": "Empty"
    },
    {
      "x": -30,
      "y": 33,
      "z": -12,
      "name": "Empty"
    },
    {
      "x": -30,
      "y": 34,
      "z": -12,
      "name": "Empty"
    },
    {
      "x": -30,
      "y": 35,
      "z": -12,
      "name": "Empty"
    },
    {
      "x": -30,
      "y": 36,
      "z": -12,
      "name": "Empty"
    },
    {
      "x": -30,
      "y": 7,
      "z": -11,
      "name": "Rock_Stone"
    },
    {
      "x": -30,
      "y": 8,
      "z": -11,
      "name": "Rock_Stone"
    },
    {
      "x": -30,
      "y": 9,
      "z": -11,
      "name": "Rock_Stone"
    },
    {
      "x": -30,
      "y": 10,
      "z": -11,
      "name": "Rock_Stone"
    },
    {
      "x": -30,
      "y": 11,
      "z": -11,
      "name": "Rock_Stone"
    },
    {
      "x": -30,
      "y": 12,
      "z": -11,
      "name": "Rock_Stone"
    },
    {
      "x": -30,
      "y": 13,
      "z": -11,
      "name": "Rock_Stone"
    },
    {
      "x": -30,
      "y": 14,
      "z": -11,
      "name": "Rock_Stone"
    },
    {
      "x": -30,
      "y": 15,
      "z": -11,
      "name": "Soil_Dirt"
    },
    {
      "x": -30,
      "y": 16,
      "z": -11,
      "name": "Soil_Dirt"
    },
    {
      "x": -30,
      "y": 17,
      "z": -11,
      "name": "Soil_Dirt"
    },
    {
      "x": -30,
      "y": 18,
      "z": -11,
      "name": "Soil_Dirt"
    },
    {
      "x": -30,
      "y": 19,
      "z": -11,
      "name": "Soil_Leaves"
    },
    {
      "x": -30,
      "y": 20,
      "z": -11,
      "name": "Plant_Bramble_Moss_Twisted"
    },
    {
      "x": -30,
      "y": 21,
      "z": -11,
      "name": "Empty"
    },
    {
      "x": -30,
      "y": 22,
      "z": -11,
      "name": "Empty"
    },
    {
      "x": -30,
      "y": 23,
      "z": -11,
      "name": "Empty"
    },
    {
      "x": -30,
      "y": 24,
      "z": -11,
      "name": "Empty"
    },
    {
      "x": -30,
      "y": 25,
      "z": -11,
      "name": "Empty"
    },
    {
      "x": -30,
      "y": 26,
      "z": -11,
      "name": "Empty"
    },
    {
      "x": -30,
      "y": 27,
      "z": -11,
      "name": "Empty"
    },
    {
      "x": -30,
      "y": 28,
      "z": -11,
      "name": "Empty"
    },
    {
      "x": -30,
      "y": 29,
      "z": -11,
      "name": "Empty"
    },
    {
      "x": -30,
      "y": 30,
      "z": -11,
      "name": "Empty"
    },
    {
      "x": -30,
      "y": 31,
      "z": -11,
      "name": "Empty"
    },
    {
      "x": -30,
      "y": 32,
      "z": -11,
      "name": "Empty"
    },
    {
      "x": -30,
      "y": 33,
      "z": -11,
      "name": "Empty"
    },
    {
      "x": -30,
      "y": 34,
      "z": -11,
      "name": "Empty"
    },
    {
      "x": -30,
      "y": 35,
      "z": -11,
      "name": "Empty"
    },
    {
      "x": -30,
      "y": 36,
      "z": -11,
      "name": "Empty"
    },
    {
      "x": -30,
      "y": 7,
      "z": -10,
      "name": "Rock_Stone"
    },
    {
      "x": -30,
      "y": 8,
      "z": -10,
      "name": "Rock_Stone"
    },
    {
      "x": -30,
      "y": 9,
      "z": -10,
      "name": "Rock_Stone"
    },
    {
      "x": -30,
      "y": 10,
      "z": -10,
      "name": "Rock_Stone"
    },
    {
      "x": -30,
      "y": 11,
      "z": -10,
      "name": "Rock_Stone"
    },
    {
      "x": -30,
      "y": 12,
      "z": -10,
      "name": "Rock_Stone"
    },
    {
      "x": -30,
      "y": 13,
      "z": -10,
      "name": "Rock_Stone"
    },
    {
      "x": -30,
      "y": 14,
      "z": -10,
      "name": "Rock_Stone"
    },
    {
      "x": -30,
      "y": 15,
      "z": -10,
      "name": "Rock_Stone"
    },
    {
      "x": -30,
      "y": 16,
      "z": -10,
      "name": "Rock_Stone"
    },
    {
      "x": -30,
      "y": 17,
      "z": -10,
      "name": "Rock_Stone"
    },
    {
      "x": -30,
      "y": 18,
      "z": -10,
      "name": "Rock_Stone"
    },
    {
      "x": -30,
      "y": 19,
      "z": -10,
      "name": "Rock_Stone"
    },
    {
      "x": -30,
      "y": 20,
      "z": -10,
      "name": "Empty"
    },
    {
      "x": -30,
      "y": 21,
      "z": -10,
      "name": "Empty"
    },
    {
      "x": -30,
      "y": 22,
      "z": -10,
      "name": "Empty"
    },
    {
      "x": -30,
      "y": 23,
      "z": -10,
      "name": "Empty"
    },
    {
      "x": -30,
      "y": 24,
      "z": -10,
      "name": "Empty"
    },
    {
      "x": -30,
      "y": 25,
      "z": -10,
      "name": "Empty"
    },
    {
      "x": -30,
      "y": 26,
      "z": -10,
      "name": "Empty"
    },
    {
      "x": -30,
      "y": 27,
      "z": -10,
      "name": "Empty"
    },
    {
      "x": -30,
      "y": 28,
      "z": -10,
      "name": "Empty"
    },
    {
      "x": -30,
      "y": 29,
      "z": -10,
      "name": "Empty"
    },
    {
      "x": -30,
      "y": 30,
      "z": -10,
      "name": "Empty"
    },
    {
      "x": -30,
      "y": 31,
      "z": -10,
      "name": "Empty"
    },
    {
      "x": -30,
      "y": 32,
      "z": -10,
      "name": "Empty"
    },
    {
      "x": -30,
      "y": 33,
      "z": -10,
      "name": "Empty"
    },
    {
      "x": -30,
      "y": 34,
      "z": -10,
      "name": "Empty"
    },
    {
      "x": -30,
      "y": 35,
      "z": -10,
      "name": "Empty"
    },
    {
      "x": -30,
      "y": 36,
      "z": -10,
      "name": "Empty"
    },
    {
      "x": -30,
      "y": 8,
      "z": -9,
      "name": "Soil_Pathway"
    },
    {
      "x": -30,
      "y": 9,
      "z": -9,
      "name": "Soil_Pathway"
    },
    {
      "x": -30,
      "y": 10,
      "z": -9,
      "name": "Soil_Pathway"
    },
    {
      "x": -30,
      "y": 11,
      "z": -9,
      "name": "Soil_Pathway"
    },
    {
      "x": -30,
      "y": 12,
      "z": -9,
      "name": "Rock_Stone"
    },
    {
      "x": -30,
      "y": 13,
      "z": -9,
      "name": "Rock_Stone"
    },
    {
      "x": -30,
      "y": 14,
      "z": -9,
      "name": "Rock_Stone"
    },
    {
      "x": -30,
      "y": 15,
      "z": -9,
      "name": "Rock_Stone"
    },
    {
      "x": -30,
      "y": 16,
      "z": -9,
      "name": "Rock_Stone"
    },
    {
      "x": -30,
      "y": 17,
      "z": -9,
      "name": "Rock_Stone"
    },
    {
      "x": -30,
      "y": 18,
      "z": -9,
      "name": "Rock_Stone"
    },
    {
      "x": -30,
      "y": 19,
      "z": -9,
      "name": "Rock_Stone"
    },
    {
      "x": -30,
      "y": 20,
      "z": -9,
      "name": "Empty"
    },
    {
      "x": -30,
      "y": 21,
      "z": -9,
      "name": "Empty"
    },
    {
      "x": -30,
      "y": 22,
      "z": -9,
      "name": "Empty"
    },
    {
      "x": -30,
      "y": 23,
      "z": -9,
      "name": "Empty"
    },
    {
      "x": -30,
      "y": 24,
      "z": -9,
      "name": "Empty"
    },
    {
      "x": -30,
      "y": 25,
      "z": -9,
      "name": "Empty"
    },
    {
      "x": -30,
      "y": 26,
      "z": -9,
      "name": "Empty"
    },
    {
      "x": -30,
      "y": 27,
      "z": -9,
      "name": "Empty"
    },
    {
      "x": -30,
      "y": 28,
      "z": -9,
      "name": "Empty"
    },
    {
      "x": -30,
      "y": 29,
      "z": -9,
      "name": "Empty"
    },
    {
      "x": -30,
      "y": 30,
      "z": -9,
      "name": "Empty"
    },
    {
      "x": -30,
      "y": 31,
      "z": -9,
      "name": "Empty"
    },
    {
      "x": -30,
      "y": 32,
      "z": -9,
      "name": "Empty"
    },
    {
      "x": -30,
      "y": 33,
      "z": -9,
      "name": "Empty"
    },
    {
      "x": -30,
      "y": 34,
      "z": -9,
      "name": "Empty"
    },
    {
      "x": -30,
      "y": 35,
      "z": -9,
      "name": "Empty"
    },
    {
      "x": -30,
      "y": 36,
      "z": -9,
      "name": "Empty"
    },
    {
      "x": -30,
      "y": 8,
      "z": -8,
      "name": "Rock_Stone"
    },
    {
      "x": -30,
      "y": 9,
      "z": -8,
      "name": "Rock_Stone"
    },
    {
      "x": -30,
      "y": 10,
      "z": -8,
      "name": "Rock_Stone"
    },
    {
      "x": -30,
      "y": 11,
      "z": -8,
      "name": "Rock_Stone"
    },
    {
      "x": -30,
      "y": 12,
      "z": -8,
      "name": "Rock_Stone"
    },
    {
      "x": -30,
      "y": 13,
      "z": -8,
      "name": "Rock_Stone"
    },
    {
      "x": -30,
      "y": 14,
      "z": -8,
      "name": "Rock_Stone"
    },
    {
      "x": -30,
      "y": 15,
      "z": -8,
      "name": "Rock_Stone"
    },
    {
      "x": -30,
      "y": 16,
      "z": -8,
      "name": "Rock_Stone"
    },
    {
      "x": -30,
      "y": 17,
      "z": -8,
      "name": "Rock_Stone"
    },
    {
      "x": -30,
      "y": 18,
      "z": -8,
      "name": "Rock_Stone"
    },
    {
      "x": -30,
      "y": 19,
      "z": -8,
      "name": "Rock_Stone"
    },
    {
      "x": -30,
      "y": 20,
      "z": -8,
      "name": "Rock_Stone"
    },
    {
      "x": -30,
      "y": 21,
      "z": -8,
      "name": "Plant_Moss_Wall_Green",
      "rotation": 1
    },
    {
      "x": -30,
      "y": 22,
      "z": -8,
      "name": "Empty"
    },
    {
      "x": -30,
      "y": 23,
      "z": -8,
      "name": "Empty"
    },
    {
      "x": -30,
      "y": 24,
      "z": -8,
      "name": "Empty"
    },
    {
      "x": -30,
      "y": 25,
      "z": -8,
      "name": "Empty"
    },
    {
      "x": -30,
      "y": 26,
      "z": -8,
      "name": "Empty"
    },
    {
      "x": -30,
      "y": 27,
      "z": -8,
      "name": "Empty"
    },
    {
      "x": -30,
      "y": 28,
      "z": -8,
      "name": "Empty"
    },
    {
      "x": -30,
      "y": 29,
      "z": -8,
      "name": "Empty"
    },
    {
      "x": -30,
      "y": 30,
      "z": -8,
      "name": "Empty"
    },
    {
      "x": -30,
      "y": 31,
      "z": -8,
      "name": "Empty"
    },
    {
      "x": -30,
      "y": 32,
      "z": -8,
      "name": "Empty"
    },
    {
      "x": -30,
      "y": 33,
      "z": -8,
      "name": "Empty"
    },
    {
      "x": -30,
      "y": 34,
      "z": -8,
      "name": "Empty"
    },
    {
      "x": -30,
      "y": 35,
      "z": -8,
      "name": "Empty"
    },
    {
      "x": -30,
      "y": 36,
      "z": -8,
      "name": "Empty"
    },
    {
      "x": -30,
      "y": 8,
      "z": -7,
      "name": "Rock_Stone"
    },
    {
      "x": -30,
      "y": 9,
      "z": -7,
      "name": "Rock_Stone"
    },
    {
      "x": -30,
      "y": 10,
      "z": -7,
      "name": "Rock_Stone"
    },
    {
      "x": -30,
      "y": 11,
      "z": -7,
      "name": "Rock_Stone"
    },
    {
      "x": -30,
      "y": 12,
      "z": -7,
      "name": "Rock_Stone"
    },
    {
      "x": -30,
      "y": 13,
      "z": -7,
      "name": "Rock_Stone"
    },
    {
      "x": -30,
      "y": 14,
      "z": -7,
      "name": "Rock_Stone"
    },
    {
      "x": -30,
      "y": 15,
      "z": -7,
      "name": "Rock_Stone"
    },
    {
      "x": -30,
      "y": 16,
      "z": -7,
      "name": "Rock_Stone"
    },
    {
      "x": -30,
      "y": 17,
      "z": -7,
      "name": "Rock_Stone"
    },
    {
      "x": -30,
      "y": 18,
      "z": -7,
      "name": "Rock_Stone"
    },
    {
      "x": -30,
      "y": 19,
      "z": -7,
      "name": "Rock_Stone"
    },
    {
      "x": -30,
      "y": 20,
      "z": -7,
      "name": "Rock_Stone"
    },
    {
      "x": -30,
      "y": 21,
      "z": -7,
      "name": "Rock_Stone"
    },
    {
      "x": -30,
      "y": 22,
      "z": -7,
      "name": "Empty"
    },
    {
      "x": -30,
      "y": 23,
      "z": -7,
      "name": "Empty"
    },
    {
      "x": -30,
      "y": 24,
      "z": -7,
      "name": "Empty"
    },
    {
      "x": -30,
      "y": 25,
      "z": -7,
      "name": "Empty"
    },
    {
      "x": -30,
      "y": 26,
      "z": -7,
      "name": "Empty"
    },
    {
      "x": -30,
      "y": 27,
      "z": -7,
      "name": "Empty"
    },
    {
      "x": -30,
      "y": 28,
      "z": -7,
      "name": "Empty"
    },
    {
      "x": -30,
      "y": 29,
      "z": -7,
      "name": "Empty"
    },
    {
      "x": -30,
      "y": 30,
      "z": -7,
      "name": "Empty"
    },
    {
      "x": -30,
      "y": 31,
      "z": -7,
      "name": "Empty"
    },
    {
      "x": -30,
      "y": 32,
      "z": -7,
      "name": "Empty"
    },
    {
      "x": -30,
      "y": 33,
      "z": -7,
      "name": "Empty"
    },
    {
      "x": -30,
      "y": 34,
      "z": -7,
      "name": "Empty"
    },
    {
      "x": -30,
      "y": 35,
      "z": -7,
      "name": "Empty"
    },
    {
      "x": -30,
      "y": 36,
      "z": -7,
      "name": "Empty"
    },
    {
      "x": -30,
      "y": 8,
      "z": -6,
      "name": "Rock_Stone"
    },
    {
      "x": -30,
      "y": 9,
      "z": -6,
      "name": "Rock_Stone"
    },
    {
      "x": -30,
      "y": 10,
      "z": -6,
      "name": "Rock_Stone"
    },
    {
      "x": -30,
      "y": 11,
      "z": -6,
      "name": "Rock_Stone"
    },
    {
      "x": -30,
      "y": 12,
      "z": -6,
      "name": "Rock_Stone"
    },
    {
      "x": -30,
      "y": 13,
      "z": -6,
      "name": "Rock_Stone"
    },
    {
      "x": -30,
      "y": 14,
      "z": -6,
      "name": "Rock_Stone"
    },
    {
      "x": -30,
      "y": 15,
      "z": -6,
      "name": "Rock_Stone"
    },
    {
      "x": -30,
      "y": 16,
      "z": -6,
      "name": "Rock_Stone"
    },
    {
      "x": -30,
      "y": 17,
      "z": -6,
      "name": "Rock_Stone"
    },
    {
      "x": -30,
      "y": 18,
      "z": -6,
      "name": "Rock_Stone"
    },
    {
      "x": -30,
      "y": 19,
      "z": -6,
      "name": "Rock_Stone_Mossy"
    },
    {
      "x": -30,
      "y": 20,
      "z": -6,
      "name": "Rock_Stone_Mossy"
    },
    {
      "x": -30,
      "y": 21,
      "z": -6,
      "name": "Rock_Stone"
    },
    {
      "x": -30,
      "y": 22,
      "z": -6,
      "name": "Empty"
    },
    {
      "x": -30,
      "y": 23,
      "z": -6,
      "name": "Empty"
    },
    {
      "x": -30,
      "y": 24,
      "z": -6,
      "name": "Empty"
    },
    {
      "x": -30,
      "y": 25,
      "z": -6,
      "name": "Empty"
    },
    {
      "x": -30,
      "y": 26,
      "z": -6,
      "name": "Empty"
    },
    {
      "x": -30,
      "y": 27,
      "z": -6,
      "name": "Empty"
    },
    {
      "x": -30,
      "y": 28,
      "z": -6,
      "name": "Empty"
    },
    {
      "x": -30,
      "y": 29,
      "z": -6,
      "name": "Empty"
    },
    {
      "x": -30,
      "y": 30,
      "z": -6,
      "name": "Empty"
    },
    {
      "x": -30,
      "y": 31,
      "z": -6,
      "name": "Empty"
    },
    {
      "x": -30,
      "y": 32,
      "z": -6,
      "name": "Empty"
    },
    {
      "x": -30,
      "y": 33,
      "z": -6,
      "name": "Empty"
    },
    {
      "x": -30,
      "y": 34,
      "z": -6,
      "name": "Empty"
    },
    {
      "x": -30,
      "y": 35,
      "z": -6,
      "name": "Empty"
    },
    {
      "x": -30,
      "y": 36,
      "z": -6,
      "name": "Empty"
    },
    {
      "x": -30,
      "y": 8,
      "z": -5,
      "name": "Rock_Stone"
    },
    {
      "x": -30,
      "y": 9,
      "z": -5,
      "name": "Rock_Stone"
    },
    {
      "x": -30,
      "y": 10,
      "z": -5,
      "name": "Rock_Stone"
    },
    {
      "x": -30,
      "y": 11,
      "z": -5,
      "name": "Rock_Stone"
    },
    {
      "x": -30,
      "y": 12,
      "z": -5,
      "name": "Rock_Stone"
    },
    {
      "x": -30,
      "y": 13,
      "z": -5,
      "name": "Rock_Stone"
    },
    {
      "x": -30,
      "y": 14,
      "z": -5,
      "name": "Rock_Stone"
    },
    {
      "x": -30,
      "y": 15,
      "z": -5,
      "name": "Rock_Stone"
    },
    {
      "x": -30,
      "y": 16,
      "z": -5,
      "name": "Rock_Stone"
    },
    {
      "x": -30,
      "y": 17,
      "z": -5,
      "name": "Rock_Stone"
    },
    {
      "x": -30,
      "y": 18,
      "z": -5,
      "name": "Rock_Stone_Mossy"
    },
    {
      "x": -30,
      "y": 19,
      "z": -5,
      "name": "Plant_Moss_Block_Green"
    },
    {
      "x": -30,
      "y": 20,
      "z": -5,
      "name": "Plant_Moss_Rug_Green"
    },
    {
      "x": -30,
      "y": 8,
      "z": -4,
      "name": "Rock_Stone"
    },
    {
      "x": -30,
      "y": 9,
      "z": -4,
      "name": "Rock_Stone"
    },
    {
      "x": -30,
      "y": 10,
      "z": -4,
      "name": "Rock_Stone"
    },
    {
      "x": -30,
      "y": 11,
      "z": -4,
      "name": "Rock_Stone"
    },
    {
      "x": -30,
      "y": 12,
      "z": -4,
      "name": "Rock_Stone"
    },
    {
      "x": -30,
      "y": 13,
      "z": -4,
      "name": "Rock_Stone"
    },
    {
      "x": -30,
      "y": 14,
      "z": -4,
      "name": "Rock_Stone"
    },
    {
      "x": -30,
      "y": 15,
      "z": -4,
      "name": "Rock_Stone"
    },
    {
      "x": -30,
      "y": 16,
      "z": -4,
      "name": "Rock_Stone"
    },
    {
      "x": -30,
      "y": 17,
      "z": -4,
      "name": "Rock_Stone_Mossy"
    },
    {
      "x": -30,
      "y": 18,
      "z": -4,
      "name": "Rock_Stone_Mossy"
    },
    {
      "x": -30,
      "y": 19,
      "z": -4,
      "name": "Rock_Stone_Mossy"
    },
    {
      "x": -30,
      "y": 8,
      "z": -3,
      "name": "Rock_Stone"
    },
    {
      "x": -30,
      "y": 9,
      "z": -3,
      "name": "Rock_Stone"
    },
    {
      "x": -30,
      "y": 10,
      "z": -3,
      "name": "Rock_Stone"
    },
    {
      "x": -30,
      "y": 11,
      "z": -3,
      "name": "Rock_Stone"
    },
    {
      "x": -30,
      "y": 12,
      "z": -3,
      "name": "Rock_Stone"
    },
    {
      "x": -30,
      "y": 13,
      "z": -3,
      "name": "Rock_Stone"
    },
    {
      "x": -30,
      "y": 14,
      "z": -3,
      "name": "Rock_Stone"
    },
    {
      "x": -30,
      "y": 15,
      "z": -3,
      "name": "Rock_Stone"
    },
    {
      "x": -30,
      "y": 16,
      "z": -3,
      "name": "Rock_Stone"
    },
    {
      "x": -30,
      "y": 17,
      "z": -3,
      "name": "Rock_Stone"
    },
    {
      "x": -30,
      "y": 18,
      "z": -3,
      "name": "Rock_Stone_Mossy"
    },
    {
      "x": -30,
      "y": 19,
      "z": -3,
      "name": "Rock_Stone_Mossy"
    },
    {
      "x": -30,
      "y": 8,
      "z": -2,
      "name": "Rock_Stone"
    },
    {
      "x": -30,
      "y": 9,
      "z": -2,
      "name": "Rock_Stone"
    },
    {
      "x": -30,
      "y": 10,
      "z": -2,
      "name": "Rock_Stone"
    },
    {
      "x": -30,
      "y": 11,
      "z": -2,
      "name": "Rock_Stone"
    },
    {
      "x": -30,
      "y": 12,
      "z": -2,
      "name": "Rock_Stone"
    },
    {
      "x": -30,
      "y": 13,
      "z": -2,
      "name": "Rock_Stone"
    },
    {
      "x": -30,
      "y": 14,
      "z": -2,
      "name": "Rock_Stone"
    },
    {
      "x": -30,
      "y": 15,
      "z": -2,
      "name": "Rock_Stone"
    },
    {
      "x": -30,
      "y": 16,
      "z": -2,
      "name": "Rock_Stone"
    },
    {
      "x": -30,
      "y": 17,
      "z": -2,
      "name": "Rock_Stone"
    },
    {
      "x": -30,
      "y": 18,
      "z": -2,
      "name": "Rock_Stone"
    },
    {
      "x": -30,
      "y": 19,
      "z": -2,
      "name": "Rock_Stone_Mossy"
    },
    {
      "x": -30,
      "y": 20,
      "z": -2,
      "name": "Rock_Stone"
    },
    {
      "x": -30,
      "y": 8,
      "z": -1,
      "name": "Rock_Stone"
    },
    {
      "x": -30,
      "y": 9,
      "z": -1,
      "name": "Rock_Stone"
    },
    {
      "x": -30,
      "y": 10,
      "z": -1,
      "name": "Rock_Stone"
    },
    {
      "x": -30,
      "y": 11,
      "z": -1,
      "name": "Rock_Stone"
    },
    {
      "x": -30,
      "y": 12,
      "z": -1,
      "name": "Rock_Stone"
    },
    {
      "x": -30,
      "y": 13,
      "z": -1,
      "name": "Rock_Stone"
    },
    {
      "x": -30,
      "y": 14,
      "z": -1,
      "name": "Rock_Stone"
    },
    {
      "x": -30,
      "y": 15,
      "z": -1,
      "name": "Rock_Stone"
    },
    {
      "x": -30,
      "y": 16,
      "z": -1,
      "name": "Rock_Stone"
    },
    {
      "x": -30,
      "y": 17,
      "z": -1,
      "name": "Rock_Stone"
    },
    {
      "x": -30,
      "y": 18,
      "z": -1,
      "name": "Rock_Stone"
    },
    {
      "x": -30,
      "y": 19,
      "z": -1,
      "name": "Rock_Stone"
    },
    {
      "x": -30,
      "y": 20,
      "z": -1,
      "name": "Rock_Stone"
    },
    {
      "x": -30,
      "y": 21,
      "z": -1,
      "name": "Plant_Moss_Rug_Green"
    },
    {
      "x": -30,
      "y": 8,
      "z": 0,
      "name": "Rock_Stone"
    },
    {
      "x": -30,
      "y": 9,
      "z": 0,
      "name": "Rock_Stone"
    },
    {
      "x": -30,
      "y": 10,
      "z": 0,
      "name": "Rock_Stone"
    },
    {
      "x": -30,
      "y": 11,
      "z": 0,
      "name": "Rock_Stone"
    },
    {
      "x": -30,
      "y": 12,
      "z": 0,
      "name": "Rock_Stone"
    },
    {
      "x": -30,
      "y": 13,
      "z": 0,
      "name": "Rock_Stone"
    },
    {
      "x": -30,
      "y": 14,
      "z": 0,
      "name": "Rock_Stone"
    },
    {
      "x": -30,
      "y": 15,
      "z": 0,
      "name": "Rock_Stone"
    },
    {
      "x": -30,
      "y": 16,
      "z": 0,
      "name": "Rock_Stone"
    },
    {
      "x": -30,
      "y": 17,
      "z": 0,
      "name": "Rock_Stone"
    },
    {
      "x": -30,
      "y": 18,
      "z": 0,
      "name": "Rock_Stone"
    },
    {
      "x": -30,
      "y": 19,
      "z": 0,
      "name": "Rock_Stone"
    },
    {
      "x": -30,
      "y": 20,
      "z": 0,
      "name": "Rock_Stone_Mossy"
    },
    {
      "x": -30,
      "y": 21,
      "z": 0,
      "name": "Plant_Moss_Block_Green"
    },
    {
      "x": -30,
      "y": 7,
      "z": 1,
      "name": "Rock_Stone"
    },
    {
      "x": -30,
      "y": 8,
      "z": 1,
      "name": "Rock_Stone"
    },
    {
      "x": -30,
      "y": 9,
      "z": 1,
      "name": "Rock_Stone"
    },
    {
      "x": -30,
      "y": 10,
      "z": 1,
      "name": "Rock_Stone"
    },
    {
      "x": -30,
      "y": 11,
      "z": 1,
      "name": "Rock_Stone"
    },
    {
      "x": -30,
      "y": 12,
      "z": 1,
      "name": "Rock_Stone"
    },
    {
      "x": -30,
      "y": 13,
      "z": 1,
      "name": "Rock_Stone"
    },
    {
      "x": -30,
      "y": 14,
      "z": 1,
      "name": "Rock_Stone"
    },
    {
      "x": -30,
      "y": 15,
      "z": 1,
      "name": "Rock_Stone"
    },
    {
      "x": -30,
      "y": 16,
      "z": 1,
      "name": "Rock_Stone"
    },
    {
      "x": -30,
      "y": 17,
      "z": 1,
      "name": "Rock_Stone"
    },
    {
      "x": -30,
      "y": 18,
      "z": 1,
      "name": "Rock_Stone"
    },
    {
      "x": -30,
      "y": 19,
      "z": 1,
      "name": "Rock_Stone_Mossy"
    },
    {
      "x": -30,
      "y": 20,
      "z": 1,
      "name": "Rock_Stone_Mossy"
    },
    {
      "x": -30,
      "y": 21,
      "z": 1,
      "name": "Rock_Stone_Mossy"
    },
    {
      "x": -30,
      "y": 7,
      "z": 2,
      "name": "Rock_Stone"
    },
    {
      "x": -30,
      "y": 8,
      "z": 2,
      "name": "Rock_Stone"
    },
    {
      "x": -30,
      "y": 9,
      "z": 2,
      "name": "Rock_Stone"
    },
    {
      "x": -30,
      "y": 10,
      "z": 2,
      "name": "Rock_Stone"
    },
    {
      "x": -30,
      "y": 11,
      "z": 2,
      "name": "Rock_Stone"
    },
    {
      "x": -30,
      "y": 12,
      "z": 2,
      "name": "Rock_Stone"
    },
    {
      "x": -30,
      "y": 13,
      "z": 2,
      "name": "Rock_Stone"
    },
    {
      "x": -30,
      "y": 14,
      "z": 2,
      "name": "Rock_Stone"
    },
    {
      "x": -30,
      "y": 15,
      "z": 2,
      "name": "Rock_Stone"
    },
    {
      "x": -30,
      "y": 16,
      "z": 2,
      "name": "Rock_Stone"
    },
    {
      "x": -30,
      "y": 17,
      "z": 2,
      "name": "Rock_Stone"
    },
    {
      "x": -30,
      "y": 18,
      "z": 2,
      "name": "Rock_Stone"
    },
    {
      "x": -30,
      "y": 19,
      "z": 2,
      "name": "Rock_Stone"
    },
    {
      "x": -30,
      "y": 20,
      "z": 2,
      "name": "Rock_Stone_Mossy"
    },
    {
      "x": -30,
      "y": 21,
      "z": 2,
      "name": "Rock_Stone"
    },
    {
      "x": -30,
      "y": 7,
      "z": 3,
      "name": "Rock_Stone"
    },
    {
      "x": -30,
      "y": 8,
      "z": 3,
      "name": "Rock_Stone"
    },
    {
      "x": -30,
      "y": 9,
      "z": 3,
      "name": "Rock_Stone"
    },
    {
      "x": -30,
      "y": 10,
      "z": 3,
      "name": "Rock_Stone"
    },
    {
      "x": -30,
      "y": 11,
      "z": 3,
      "name": "Rock_Stone"
    },
    {
      "x": -30,
      "y": 12,
      "z": 3,
      "name": "Rock_Stone"
    },
    {
      "x": -30,
      "y": 13,
      "z": 3,
      "name": "Rock_Stone"
    },
    {
      "x": -30,
      "y": 14,
      "z": 3,
      "name": "Rock_Stone"
    },
    {
      "x": -30,
      "y": 15,
      "z": 3,
      "name": "Rock_Stone"
    },
    {
      "x": -30,
      "y": 16,
      "z": 3,
      "name": "Rock_Stone"
    },
    {
      "x": -30,
      "y": 17,
      "z": 3,
      "name": "Rock_Stone"
    },
    {
      "x": -30,
      "y": 18,
      "z": 3,
      "name": "Rock_Stone"
    },
    {
      "x": -30,
      "y": 19,
      "z": 3,
      "name": "Rock_Stone"
    },
    {
      "x": -30,
      "y": 20,
      "z": 3,
      "name": "Rock_Stone"
    },
    {
      "x": -30,
      "y": 21,
      "z": 3,
      "name": "Rock_Stone_Mossy"
    },
    {
      "x": -30,
      "y": 7,
      "z": 4,
      "name": "Rock_Stone"
    },
    {
      "x": -30,
      "y": 8,
      "z": 4,
      "name": "Rock_Stone"
    },
    {
      "x": -30,
      "y": 9,
      "z": 4,
      "name": "Rock_Stone"
    },
    {
      "x": -30,
      "y": 10,
      "z": 4,
      "name": "Rock_Stone"
    },
    {
      "x": -30,
      "y": 11,
      "z": 4,
      "name": "Rock_Stone"
    },
    {
      "x": -30,
      "y": 12,
      "z": 4,
      "name": "Rock_Stone"
    },
    {
      "x": -30,
      "y": 13,
      "z": 4,
      "name": "Rock_Stone"
    },
    {
      "x": -30,
      "y": 14,
      "z": 4,
      "name": "Rock_Stone"
    },
    {
      "x": -30,
      "y": 15,
      "z": 4,
      "name": "Rock_Stone"
    },
    {
      "x": -30,
      "y": 16,
      "z": 4,
      "name": "Rock_Stone"
    },
    {
      "x": -30,
      "y": 17,
      "z": 4,
      "name": "Rock_Stone"
    },
    {
      "x": -30,
      "y": 18,
      "z": 4,
      "name": "Rock_Stone"
    },
    {
      "x": -30,
      "y": 19,
      "z": 4,
      "name": "Rock_Stone_Mossy"
    },
    {
      "x": -30,
      "y": 7,
      "z": 5,
      "name": "Rock_Stone"
    },
    {
      "x": -30,
      "y": 8,
      "z": 5,
      "name": "Rock_Stone"
    },
    {
      "x": -30,
      "y": 9,
      "z": 5,
      "name": "Rock_Stone"
    },
    {
      "x": -30,
      "y": 10,
      "z": 5,
      "name": "Rock_Stone"
    },
    {
      "x": -30,
      "y": 11,
      "z": 5,
      "name": "Rock_Stone"
    },
    {
      "x": -30,
      "y": 12,
      "z": 5,
      "name": "Rock_Stone"
    },
    {
      "x": -30,
      "y": 13,
      "z": 5,
      "name": "Rock_Stone"
    },
    {
      "x": -30,
      "y": 14,
      "z": 5,
      "name": "Rock_Stone"
    },
    {
      "x": -30,
      "y": 15,
      "z": 5,
      "name": "Rock_Stone"
    },
    {
      "x": -30,
      "y": 16,
      "z": 5,
      "name": "Rock_Stone"
    },
    {
      "x": -30,
      "y": 17,
      "z": 5,
      "name": "Rock_Stone"
    },
    {
      "x": -30,
      "y": 18,
      "z": 5,
      "name": "Rock_Stone_Mossy"
    },
    {
      "x": -30,
      "y": 7,
      "z": 6,
      "name": "Rock_Stone"
    },
    {
      "x": -30,
      "y": 8,
      "z": 6,
      "name": "Rock_Stone"
    },
    {
      "x": -30,
      "y": 9,
      "z": 6,
      "name": "Rock_Stone"
    },
    {
      "x": -30,
      "y": 10,
      "z": 6,
      "name": "Rock_Stone"
    },
    {
      "x": -30,
      "y": 11,
      "z": 6,
      "name": "Rock_Stone"
    },
    {
      "x": -30,
      "y": 12,
      "z": 6,
      "name": "Rock_Stone"
    },
    {
      "x": -30,
      "y": 13,
      "z": 6,
      "name": "Rock_Stone"
    },
    {
      "x": -30,
      "y": 14,
      "z": 6,
      "name": "Rock_Stone"
    },
    {
      "x": -30,
      "y": 15,
      "z": 6,
      "name": "Rock_Stone_Mossy"
    },
    {
      "x": -30,
      "y": 16,
      "z": 6,
      "name": "Rock_Stone_Mossy"
    },
    {
      "x": -30,
      "y": 17,
      "z": 6,
      "name": "Rock_Stone"
    },
    {
      "x": -30,
      "y": 8,
      "z": 7,
      "name": "Rock_Stone"
    },
    {
      "x": -30,
      "y": 9,
      "z": 7,
      "name": "Rock_Stone"
    },
    {
      "x": -30,
      "y": 10,
      "z": 7,
      "name": "Rock_Stone"
    },
    {
      "x": -30,
      "y": 11,
      "z": 7,
      "name": "Rock_Stone"
    },
    {
      "x": -30,
      "y": 12,
      "z": 7,
      "name": "Rock_Stone"
    },
    {
      "x": -30,
      "y": 13,
      "z": 7,
      "name": "Rock_Stone_Mossy"
    },
    {
      "x": -30,
      "y": 14,
      "z": 7,
      "name": "Rock_Stone"
    },
    {
      "x": -29,
      "y": 7,
      "z": -16,
      "name": "Rock_Stone"
    },
    {
      "x": -29,
      "y": 8,
      "z": -16,
      "name": "Rock_Stone"
    },
    {
      "x": -29,
      "y": 9,
      "z": -16,
      "name": "Rock_Stone"
    },
    {
      "x": -29,
      "y": 10,
      "z": -16,
      "name": "Rock_Stone"
    },
    {
      "x": -29,
      "y": 11,
      "z": -16,
      "name": "Rock_Stone"
    },
    {
      "x": -29,
      "y": 12,
      "z": -16,
      "name": "Rock_Stone"
    },
    {
      "x": -29,
      "y": 13,
      "z": -16,
      "name": "Rock_Stone"
    },
    {
      "x": -29,
      "y": 14,
      "z": -16,
      "name": "Rock_Stone"
    },
    {
      "x": -29,
      "y": 15,
      "z": -16,
      "name": "Rock_Stone"
    },
    {
      "x": -29,
      "y": 16,
      "z": -16,
      "name": "Soil_Dirt"
    },
    {
      "x": -29,
      "y": 17,
      "z": -16,
      "name": "Empty"
    },
    {
      "x": -29,
      "y": 18,
