{
  "version": 8,
  "blockIdVersion": 8,
  "anchorX": 8,
  "anchorY": 6,
  "anchorZ": 2,
  "blocks": [
    {
      "x": 5,
      "y": 3,
      "z": 5,
      "name": "Wood_Burnt_Trunk"
    },
    {
      "x": 5,
      "y": 4,
      "z": 5,
      "name": "Wood_Burnt_Trunk"
    },
    {
      "x": 6,
      "y": 7,
      "z": 3,
      "name": "Wood_Burnt_Trunk"
    },
    {
      "x": 6,
      "y": 13,
      "z": 3,
      "name": "Wood_Burnt_Branch_Long",
      "rotation": 5
    },
    {
      "x": 6,
      "y": 4,
      "z": 4,
      "name": "Wood_Burnt_Trunk"
    },
    {
      "x": 6,
      "y": 5,
      "z": 4,
      "name": "Wood_Burnt_Trunk"
    },
    {
      "x": 6,
      "y": 6,
      "z": 4,
      "name": "Wood_Burnt_Trunk"
    },
    {
      "x": 6,
      "y": 7,
      "z": 4,
      "name": "Wood_Burnt_Trunk"
    },
    {
      "x": 6,
      "y": 8,
      "z": 4,
      "name": "Wood_Burnt_Trunk"
    },
    {
      "x": 6,
      "y": 4,
      "z": 5,
      "name": "Wood_Burnt_Trunk"
    },
    {
      "x": 7,
      "y": 7,
      "z": 1,
      "name": "Wood_Burnt_Trunk"
    },
    {
      "x": 7,
      "y": 8,
      "z": 1,
      "name": "Wood_Burnt_Trunk"
    },
    {
      "x": 7,
      "y": 9,
      "z": 1,
      "name": "Wood_Burnt_Trunk"
    },
    {
      "x": 7,
      "y": 7,
      "z": 2,
      "name": "Wood_Burnt_Trunk"
    },
    {
      "x": 7,
      "y": 8,
      "z": 2,
      "name": "Wood_Burnt_Trunk"
    },
    {
      "x": 7,
      "y": 9,
      "z": 2,
      "name": "Wood_Burnt_Trunk"
    },
    {
      "x": 7,
      "y": 10,
      "z": 2,
      "name": "Wood_Burnt_Trunk"
    },
    {
      "x": 7,
      "y": 11,
      "z": 2,
      "name": "Wood_Burnt_Trunk"
    },
    {
      "x": 7,
      "y": 12,
      "z": 2,
      "name": "Wood_Burnt_Trunk"
    },
    {
      "x": 7,
      "y": 13,
      "z": 2,
      "name": "Wood_Burnt_Trunk"
    },
    {
      "x": 7,
      "y": 6,
      "z": 3,
      "name": "Wood_Burnt_Trunk"
    },
    {
      "x": 7,
      "y": 7,
      "z": 3,
      "name": "Wood_Burnt_Trunk"
    },
    {
      "x": 7,
      "y": 8,
      "z": 3,
      "name": "Wood_Burnt_Trunk"
    },
    {
      "x": 7,
      "y": 9,
      "z": 3,
      "name": "Wood_Burnt_Trunk"
    },
    {
      "x": 7,
      "y": 10,
      "z": 3,
      "name": "Wood_Burnt_Trunk"
    },
    {
      "x": 7,
      "y": 11,
      "z": 3,
      "name": "Wood_Burnt_Trunk"
    },
    {
      "x": 7,
      "y": 12,
      "z": 3,
      "name": "Wood_Burnt_Trunk"
    },
    {
      "x": 7,
      "y": 13,
      "z": 3,
      "name": "Wood_Burnt_Trunk"
    },
    {
      "x": 7,
      "y": 14,
      "z": 3,
      "name": "Wood_Burnt_Trunk"
    },
    {
      "x": 7,
      "y": 15,
      "z": 3,
      "name": "Wood_Burnt_Trunk"
    },
    {
      "x": 7,
      "y": 6,
      "z": 4,
      "name": "Wood_Burnt_Trunk"
    },
    {
      "x": 7,
      "y": 7,
      "z": 4,
      "name": "Wood_Burnt_Trunk"
    },
    {
      "x": 7,
      "y": 8,
      "z": 4,
      "name": "Wood_Burnt_Trunk"
    },
    {
      "x": 8,
      "y": 3,
      "z": 0,
      "name": "Wood_Burnt_Trunk"
    },
    {
      "x": 8,
      "y": 4,
      "z": 0,
      "name": "Wood_Burnt_Trunk"
    },
    {
      "x": 8,
      "y": 4,
      "z": 1,
      "name": "Wood_Burnt_Trunk"
    },
    {
      "x": 8,
      "y": 5,
      "z": 1,
      "name": "Wood_Burnt_Trunk"
    },
    {
      "x": 8,
      "y": 6,
      "z": 1,
      "name": "Wood_Burnt_Trunk"
    },
    {
      "x": 8,
      "y": 7,
      "z": 1,
      "name": "Wood_Burnt_Trunk"
    },
    {
      "x": 8,
      "y": 15,
      "z": 1,
      "name": "Wood_Burnt_Branch_Corner",
      "rotation": 2
    },
    {
      "x": 8,
      "y": 6,
      "z": 2,
      "name": "Wood_Burnt_Trunk"
    },
    {
      "x": 8,
      "y": 7,
      "z": 2,
      "name": "Wood_Burnt_Trunk"
    },
    {
      "x": 8,
      "y": 8,
      "z": 2,
      "name": "Wood_Burnt_Trunk"
    },
    {
      "x": 8,
      "y": 9,
      "z": 2,
      "name": "Wood_Burnt_Trunk"
    },
    {
      "x": 8,
      "y": 10,
      "z": 2,
      "name": "Wood_Burnt_Trunk"
    },
    {
      "x": 8,
      "y": 11,
      "z": 2,
      "name": "Wood_Burnt_Trunk"
    },
    {
      "x": 8,
      "y": 12,
      "z": 2,
      "name": "Wood_Burnt_Trunk"
    },
    {
      "x": 8,
      "y": 13,
      "z": 2,
      "name": "Wood_Burnt_Trunk"
    },
    {
      "x": 8,
      "y": 14,
      "z": 2,
      "name": "Wood_Burnt_Trunk"
    },
    {
      "x": 8,
      "y": 15,
      "z": 2,
      "name": "Wood_Burnt_Trunk"
    },
    {
      "x": 8,
      "y": 16,
      "z": 2,
      "name": "Wood_Burnt_Trunk"
    },
    {
      "x": 8,
      "y": 17,
      "z": 2,
      "name": "Wood_Burnt_Trunk"
    },
    {
      "x": 8,
      "y": 4,
      "z": 3,
      "name": "Wood_Burnt_Trunk"
    },
    {
      "x": 8,
      "y": 5,
      "z": 3,
      "name": "Wood_Burnt_Trunk"
    },
    {
      "x": 8,
      "y": 6,
      "z": 3,
      "name": "Wood_Burnt_Trunk"
    },
    {
      "x": 8,
      "y": 7,
      "z": 3,
      "name": "Wood_Burnt_Trunk"
    },
    {
      "x": 8,
      "y": 8,
      "z": 3,
      "name": "Wood_Burnt_Trunk"
    },
    {
      "x": 8,
      "y": 9,
      "z": 3,
      "name": "Wood_Burnt_Trunk"
    },
    {
      "x": 8,
      "y": 10,
      "z": 3,
      "name": "Wood_Burnt_Trunk"
    },
    {
      "x": 8,
      "y": 11,
      "z": 3,
      "name": "Wood_Burnt_Trunk"
    },
    {
      "x": 8,
      "y": 12,
      "z": 3,
      "name": "Wood_Burnt_Trunk"
    },
    {
      "x": 9,
      "y": 6,
      "z": 2,
      "name": "Wood_Burnt_Trunk"
    },
    {
      "x": 9,
      "y": 7,
      "z": 2,
      "name": "Wood_Burnt_Trunk"
    },
    {
      "x": 9,
      "y": 12,
      "z": 3,
      "name": "Wood_Burnt_Branch_Short",
      "rotation": 1
    }
  ]
}