{
  "version": 8,
  "blockIdVersion": 8,
  "anchorX": 0,
  "anchorY": 0,
  "anchorZ": 0,
  "blocks": [
    {
      "x": -5,
      "y": -16,
      "z": -5,
      "name": "Rock_Stone"
    },
    {
      "x": -5,
      "y": -15,
      "z": -5,
      "name": "Rock_Stone"
    },
    {
      "x": -5,
      "y": -14,
      "z": -5,
      "name": "Rock_Stone"
    },
    {
      "x": -5,
      "y": -13,
      "z": -5,
      "name": "Rock_Stone"
    },
    {
      "x": -5,
      "y": -12,
      "z": -5,
      "name": "Rock_Stone"
    },
    {
      "x": -5,
      "y": -11,
      "z": -5,
      "name": "Rock_Stone"
    },
    {
      "x": -5,
      "y": -10,
      "z": -5,
      "name": "Rock_Stone"
    },
    {
      "x": -5,
      "y": -9,
      "z": -5,
      "name": "Rock_Stone"
    },
    {
      "x": -5,
      "y": -8,
      "z": -5,
      "name": "Rock_Stone"
    },
    {
      "x": -5,
      "y": -7,
      "z": -5,
      "name": "Rock_Stone"
    },
    {
      "x": -5,
      "y": -6,
      "z": -5,
      "name": "Rock_Stone"
    },
    {
      "x": -5,
      "y": -5,
      "z": -5,
      "name": "Rock_Stone"
    },
    {
      "x": -5,
      "y": -4,
      "z": -5,
      "name": "Rock_Stone"
    },
    {
      "x": -5,
      "y": -16,
      "z": -4,
      "name": "Rock_Stone"
    },
    {
      "x": -5,
      "y": -15,
      "z": -4,
      "name": "Rock_Stone"
    },
    {
      "x": -5,
      "y": -14,
      "z": -4,
      "name": "Rock_Stone"
    },
    {
      "x": -5,
      "y": -13,
      "z": -4,
      "name": "Rock_Stone"
    },
    {
      "x": -5,
      "y": -12,
      "z": -4,
      "name": "Rock_Stone"
    },
    {
      "x": -5,
      "y": -11,
      "z": -4,
      "name": "Rock_Stone"
    },
    {
      "x": -5,
      "y": -10,
      "z": -4,
      "name": "Rock_Stone"
    },
    {
      "x": -5,
      "y": -9,
      "z": -4,
      "name": "Rock_Stone"
    },
    {
      "x": -5,
      "y": -8,
      "z": -4,
      "name": "Rock_Stone"
    },
    {
      "x": -5,
      "y": -7,
      "z": -4,
      "name": "Rock_Stone"
    },
    {
      "x": -5,
      "y": -6,
      "z": -4,
      "name": "Rock_Stone"
    },
    {
      "x": -5,
      "y": -5,
      "z": -4,
      "name": "Rock_Stone"
    },
    {
      "x": -5,
      "y": -4,
      "z": -4,
      "name": "Rock_Stone"
    },
    {
      "x": -5,
      "y": -16,
      "z": -3,
      "name": "Rock_Stone"
    },
    {
      "x": -5,
      "y": -15,
      "z": -3,
      "name": "Rock_Stone"
    },
    {
      "x": -5,
      "y": -14,
      "z": -3,
      "name": "Rock_Stone"
    },
    {
      "x": -5,
      "y": -13,
      "z": -3,
      "name": "Rock_Stone"
    },
    {
      "x": -5,
      "y": -12,
      "z": -3,
      "name": "Rock_Stone"
    },
    {
      "x": -5,
      "y": -11,
      "z": -3,
      "name": "Rock_Stone"
    },
    {
      "x": -5,
      "y": -10,
      "z": -3,
      "name": "Rock_Stone"
    },
    {
      "x": -5,
      "y": -9,
      "z": -3,
      "name": "Rock_Stone"
    },
    {
      "x": -5,
      "y": -8,
      "z": -3,
      "name": "Rock_Stone"
    },
    {
      "x": -5,
      "y": -7,
      "z": -3,
      "name": "Rock_Stone"
    },
    {
      "x": -5,
      "y": -6,
      "z": -3,
      "name": "Rock_Stone"
    },
    {
      "x": -5,
      "y": -5,
      "z": -3,
      "name": "Rock_Stone"
    },
    {
      "x": -5,
      "y": -4,
      "z": -3,
      "name": "Rock_Stone"
    },
    {
      "x": -5,
      "y": -16,
      "z": -2,
      "name": "Rock_Stone"
    },
    {
      "x": -5,
      "y": -15,
      "z": -2,
      "name": "Rock_Stone"
    },
    {
      "x": -5,
      "y": -14,
      "z": -2,
      "name": "Rock_Stone"
    },
    {
      "x": -5,
      "y": -13,
      "z": -2,
      "name": "Rock_Stone"
    },
    {
      "x": -5,
      "y": -12,
      "z": -2,
      "name": "Rock_Stone"
    },
    {
      "x": -5,
      "y": -11,
      "z": -2,
      "name": "Rock_Stone"
    },
    {
      "x": -5,
      "y": -10,
      "z": -2,
      "name": "Rock_Stone"
    },
    {
      "x": -5,
      "y": -9,
      "z": -2,
      "name": "Rock_Stone"
    },
    {
      "x": -5,
      "y": -8,
      "z": -2,
      "name": "Rock_Stone"
    },
    {
      "x": -5,
      "y": -7,
      "z": -2,
      "name": "Rock_Stone"
    },
    {
      "x": -5,
      "y": -6,
      "z": -2,
      "name": "Rock_Stone"
    },
    {
      "x": -5,
      "y": -5,
      "z": -2,
      "name": "Rock_Stone"
    },
    {
      "x": -5,
      "y": -4,
      "z": -2,
      "name": "Rock_Stone"
    },
    {
      "x": -5,
      "y": -16,
      "z": -1,
      "name": "Rock_Stone"
    },
    {
      "x": -5,
      "y": -15,
      "z": -1,
      "name": "Rock_Stone"
    },
    {
      "x": -5,
      "y": -14,
      "z": -1,
      "name": "Rock_Stone"
    },
    {
      "x": -5,
      "y": -13,
      "z": -1,
      "name": "Rock_Stone"
    },
    {
      "x": -5,
      "y": -12,
      "z": -1,
      "name": "Rock_Stone"
    },
    {
      "x": -5,
      "y": -11,
      "z": -1,
      "name": "Rock_Stone"
    },
    {
      "x": -5,
      "y": -10,
      "z": -1,
      "name": "Rock_Stone"
    },
    {
      "x": -5,
      "y": -9,
      "z": -1,
      "name": "Rock_Stone"
    },
    {
      "x": -5,
      "y": -8,
      "z": -1,
      "name": "Rock_Stone"
    },
    {
      "x": -5,
      "y": -7,
      "z": -1,
      "name": "Rock_Stone"
    },
    {
      "x": -5,
      "y": -6,
      "z": -1,
      "name": "Rock_Stone"
    },
    {
      "x": -5,
      "y": -5,
      "z": -1,
      "name": "Rock_Stone"
    },
    {
      "x": -5,
      "y": -4,
      "z": -1,
      "name": "Rock_Stone"
    },
    {
      "x": -5,
      "y": -16,
      "z": 0,
      "name": "Rock_Stone"
    },
    {
      "x": -5,
      "y": -15,
      "z": 0,
      "name": "Rock_Stone"
    },
    {
      "x": -5,
      "y": -14,
      "z": 0,
      "name": "Rock_Stone"
    },
    {
      "x": -5,
      "y": -13,
      "z": 0,
      "name": "Rock_Stone"
    },
    {
      "x": -5,
      "y": -12,
      "z": 0,
      "name": "Rock_Stone"
    },
    {
      "x": -5,
      "y": -11,
      "z": 0,
      "name": "Rock_Stone"
    },
    {
      "x": -5,
      "y": -10,
      "z": 0,
      "name": "Rock_Stone"
    },
    {
      "x": -5,
      "y": -9,
      "z": 0,
      "name": "Rock_Stone"
    },
    {
      "x": -5,
      "y": -8,
      "z": 0,
      "name": "Rock_Stone"
    },
    {
      "x": -5,
      "y": -7,
      "z": 0,
      "name": "Rock_Stone"
    },
    {
      "x": -5,
      "y": -6,
      "z": 0,
      "name": "Rock_Stone"
    },
    {
      "x": -5,
      "y": -5,
      "z": 0,
      "name": "Rock_Stone"
    },
    {
      "x": -5,
      "y": -4,
      "z": 0,
      "name": "Rock_Stone_Mossy"
    },
    {
      "x": -5,
      "y": -16,
      "z": 1,
      "name": "Rock_Stone"
    },
    {
      "x": -5,
      "y": -15,
      "z": 1,
      "name": "Rock_Stone"
    },
    {
      "x": -5,
      "y": -14,
      "z": 1,
      "name": "Rock_Stone"
    },
    {
      "x": -5,
      "y": -13,
      "z": 1,
      "name": "Rock_Stone"
    },
    {
      "x": -5,
      "y": -12,
      "z": 1,
      "name": "Rock_Stone"
    },
    {
      "x": -5,
      "y": -11,
      "z": 1,
      "name": "Rock_Stone"
    },
    {
      "x": -5,
      "y": -10,
      "z": 1,
      "name": "Rock_Stone"
    },
    {
      "x": -5,
      "y": -9,
      "z": 1,
      "name": "Rock_Stone"
    },
    {
      "x": -5,
      "y": -8,
      "z": 1,
      "name": "Rock_Stone"
    },
    {
      "x": -5,
      "y": -7,
      "z": 1,
      "name": "Rock_Stone"
    },
    {
      "x": -5,
      "y": -6,
      "z": 1,
      "name": "Rock_Stone"
    },
    {
      "x": -5,
      "y": -5,
      "z": 1,
      "name": "Rock_Stone_Mossy"
    },
    {
      "x": -5,
      "y": -4,
      "z": 1,
      "name": "Rock_Stone_Mossy"
    },
    {
      "x": -5,
      "y": -16,
      "z": 2,
      "name": "Rock_Stone"
    },
    {
      "x": -5,
      "y": -15,
      "z": 2,
      "name": "Rock_Stone"
    },
    {
      "x": -5,
      "y": -14,
      "z": 2,
      "name": "Rock_Stone"
    },
    {
      "x": -5,
      "y": -13,
      "z": 2,
      "name": "Rock_Stone"
    },
    {
      "x": -5,
      "y": -12,
      "z": 2,
      "name": "Rock_Stone"
    },
    {
      "x": -5,
      "y": -11,
      "z": 2,
      "name": "Rock_Stone"
    },
    {
      "x": -5,
      "y": -10,
      "z": 2,
      "name": "Rock_Stone"
    },
    {
      "x": -5,
      "y": -9,
      "z": 2,
      "name": "Rock_Stone"
    },
    {
      "x": -5,
      "y": -8,
      "z": 2,
      "name": "Rock_Stone"
    },
    {
      "x": -5,
      "y": -7,
      "z": 2,
      "name": "Rock_Stone"
    },
    {
      "x": -5,
      "y": -6,
      "z": 2,
      "name": "Rock_Stone_Mossy"
    },
    {
      "x": -5,
      "y": -5,
      "z": 2,
      "name": "Rock_Stone_Mossy"
    },
    {
      "x": -5,
      "y": -4,
      "z": 2,
      "name": "Rock_Stone_Mossy"
    },
    {
      "x": -5,
      "y": -16,
      "z": 3,
      "name": "Rock_Stone"
    },
    {
      "x": -5,
      "y": -15,
      "z": 3,
      "name": "Rock_Stone"
    },
    {
      "x": -5,
      "y": -14,
      "z": 3,
      "name": "Rock_Stone"
    },
    {
      "x": -5,
      "y": -13,
      "z": 3,
      "name": "Rock_Stone"
    },
    {
      "x": -5,
      "y": -12,
      "z": 3,
      "name": "Rock_Stone"
    },
    {
      "x": -5,
      "y": -11,
      "z": 3,
      "name": "Rock_Stone"
    },
    {
      "x": -5,
      "y": -10,
      "z": 3,
      "name": "Rock_Stone"
    },
    {
      "x": -5,
      "y": -9,
      "z": 3,
      "name": "Rock_Stone"
    },
    {
      "x": -5,
      "y": -8,
      "z": 3,
      "name": "Rock_Stone"
    },
    {
      "x": -5,
      "y": -7,
      "z": 3,
      "name": "Rock_Stone_Mossy"
    },
    {
      "x": -5,
      "y": -6,
      "z": 3,
      "name": "Rock_Stone_Mossy"
    },
    {
      "x": -5,
      "y": -5,
      "z": 3,
      "name": "Rock_Stone_Mossy"
    },
    {
      "x": -5,
      "y": -4,
      "z": 3,
      "name": "Rock_Stone_Mossy"
    },
    {
      "x": -5,
      "y": -16,
      "z": 4,
      "name": "Rock_Stone"
    },
    {
      "x": -5,
      "y": -15,
      "z": 4,
      "name": "Rock_Stone"
    },
    {
      "x": -5,
      "y": -14,
      "z": 4,
      "name": "Rock_Stone"
    },
    {
      "x": -5,
      "y": -13,
      "z": 4,
      "name": "Rock_Stone"
    },
    {
      "x": -5,
      "y": -12,
      "z": 4,
      "name": "Rock_Stone"
    },
    {
      "x": -5,
      "y": -11,
      "z": 4,
      "name": "Rock_Stone"
    },
    {
      "x": -5,
      "y": -10,
      "z": 4,
      "name": "Rock_Stone"
    },
    {
      "x": -5,
      "y": -9,
      "z": 4,
      "name": "Rock_Stone"
    },
    {
      "x": -5,
      "y": -8,
      "z": 4,
      "name": "Rock_Stone"
    },
    {
      "x": -5,
      "y": -7,
      "z": 4,
      "name": "Rock_Stone_Mossy"
    },
    {
      "x": -5,
      "y": -6,
      "z": 4,
      "name": "Plant_Moss_Block_Green"
    },
    {
      "x": -5,
      "y": -5,
      "z": 4,
      "name": "Plant_Moss_Block_Green"
    },
    {
      "x": -5,
      "y": -4,
      "z": 4,
      "name": "Plant_Moss_Block_Green"
    },
    {
      "x": -5,
      "y": -16,
      "z": 5,
      "name": "Rock_Stone"
    },
    {
      "x": -5,
      "y": -15,
      "z": 5,
      "name": "Rock_Stone"
    },
    {
      "x": -5,
      "y": -14,
      "z": 5,
      "name": "Rock_Stone"
    },
    {
      "x": -5,
      "y": -13,
      "z": 5,
      "name": "Rock_Stone"
    },
    {
      "x": -5,
      "y": -12,
      "z": 5,
      "name": "Rock_Stone"
    },
    {
      "x": -5,
      "y": -11,
      "z": 5,
      "name": "Rock_Stone"
    },
    {
      "x": -5,
      "y": -10,
      "z": 5,
      "name": "Rock_Stone"
    },
    {
      "x": -5,
      "y": -9,
      "z": 5,
      "name": "Rock_Stone"
    },
    {
      "x": -5,
      "y": -8,
      "z": 5,
      "name": "Rock_Stone"
    },
    {
      "x": -5,
      "y": -7,
      "z": 5,
      "name": "Rock_Stone_Mossy"
    },
    {
      "x": -5,
      "y": -6,
      "z": 5,
      "name": "Plant_Moss_Block_Green"
    },
    {
      "x": -5,
      "y": -5,
      "z": 5,
      "name": "Plant_Moss_Block_Green"
    },
    {
      "x": -5,
      "y": -4,
      "z": 5,
      "name": "Plant_Moss_Block_Green"
    },
    {
      "x": -5,
      "y": -16,
      "z": 6,
      "name": "Rock_Stone"
    },
    {
      "x": -5,
      "y": -15,
      "z": 6,
      "name": "Rock_Stone"
    },
    {
      "x": -5,
      "y": -14,
      "z": 6,
      "name": "Rock_Stone"
    },
    {
      "x": -5,
      "y": -13,
      "z": 6,
      "name": "Rock_Stone"
    },
    {
      "x": -5,
      "y": -12,
      "z": 6,
      "name": "Rock_Stone"
    },
    {
      "x": -5,
      "y": -11,
      "z": 6,
      "name": "Rock_Stone"
    },
    {
      "x": -5,
      "y": -10,
      "z": 6,
      "name": "Rock_Stone"
    },
    {
      "x": -5,
      "y": -9,
      "z": 6,
      "name": "Rock_Stone"
    },
    {
      "x": -5,
      "y": -8,
      "z": 6,
      "name": "Rock_Stone"
    },
    {
      "x": -5,
      "y": -7,
      "z": 6,
      "name": "Rock_Stone"
    },
    {
      "x": -5,
      "y": -6,
      "z": 6,
      "name": "Plant_Moss_Block_Green"
    },
    {
      "x": -5,
      "y": -5,
      "z": 6,
      "name": "Plant_Moss_Block_Green"
    },
    {
      "x": -5,
      "y": -4,
      "z": 6,
      "name": "Plant_Moss_Block_Green"
    },
    {
      "x": -5,
      "y": -16,
      "z": 7,
      "name": "Rock_Stone"
    },
    {
      "x": -5,
      "y": -15,
      "z": 7,
      "name": "Rock_Stone"
    },
    {
      "x": -5,
      "y": -14,
      "z": 7,
      "name": "Rock_Stone"
    },
    {
      "x": -5,
      "y": -13,
      "z": 7,
      "name": "Rock_Stone"
    },
    {
      "x": -5,
      "y": -12,
      "z": 7,
      "name": "Rock_Stone"
    },
    {
      "x": -5,
      "y": -11,
      "z": 7,
      "name": "Rock_Stone"
    },
    {
      "x": -5,
      "y": -10,
      "z": 7,
      "name": "Rock_Stone"
    },
    {
      "x": -5,
      "y": -9,
      "z": 7,
      "name": "Rock_Stone"
    },
    {
      "x": -5,
      "y": -8,
      "z": 7,
      "name": "Rock_Stone"
    },
    {
      "x": -5,
      "y": -7,
      "z": 7,
      "name": "Rock_Stone"
    },
    {
      "x": -5,
      "y": -6,
      "z": 7,
      "name": "Rock_Stone_Mossy"
    },
    {
      "x": -5,
      "y": -5,
      "z": 7,
      "name": "Rock_Stone_Mossy"
    },
    {
      "x": -5,
      "y": -4,
      "z": 7,
      "name": "Rock_Stone_Mossy"
    },
    {
      "x": -4,
      "y": -16,
      "z": -5,
      "name": "Rock_Stone"
    },
    {
      "x": -4,
      "y": -15,
      "z": -5,
      "name": "Rock_Stone"
    },
    {
      "x": -4,
      "y": -14,
      "z": -5,
      "name": "Rock_Stone"
    },
    {
      "x": -4,
      "y": -13,
      "z": -5,
      "name": "Rock_Stone"
    },
    {
      "x": -4,
      "y": -12,
      "z": -5,
      "name": "Rock_Stone"
    },
    {
      "x": -4,
      "y": -11,
      "z": -5,
      "name": "Rock_Stone"
    },
    {
      "x": -4,
      "y": -10,
      "z": -5,
      "name": "Rock_Stone"
    },
    {
      "x": -4,
      "y": -9,
      "z": -5,
      "name": "Rock_Stone"
    },
    {
      "x": -4,
      "y": -8,
      "z": -5,
      "name": "Rock_Stone"
    },
    {
      "x": -4,
      "y": -7,
      "z": -5,
      "name": "Rock_Stone"
    },
    {
      "x": -4,
      "y": -6,
      "z": -5,
      "name": "Rock_Stone"
    },
    {
      "x": -4,
      "y": -5,
      "z": -5,
      "name": "Rock_Stone"
    },
    {
      "x": -4,
      "y": -4,
      "z": -5,
      "name": "Rock_Stone"
    },
    {
      "x": -4,
      "y": -16,
      "z": -4,
      "name": "Rock_Stone"
    },
    {
      "x": -4,
      "y": -15,
      "z": -4,
      "name": "Rock_Stone"
    },
    {
      "x": -4,
      "y": -14,
      "z": -4,
      "name": "Rock_Stone"
    },
    {
      "x": -4,
      "y": -13,
      "z": -4,
      "name": "Rock_Stone"
    },
    {
      "x": -4,
      "y": -12,
      "z": -4,
      "name": "Rock_Stone"
    },
    {
      "x": -4,
      "y": -11,
      "z": -4,
      "name": "Rock_Stone"
    },
    {
      "x": -4,
      "y": -10,
      "z": -4,
      "name": "Rock_Stone"
    },
    {
      "x": -4,
      "y": -9,
      "z": -4,
      "name": "Rock_Stone"
    },
    {
      "x": -4,
      "y": -8,
      "z": -4,
      "name": "Rock_Stone"
    },
    {
      "x": -4,
      "y": -7,
      "z": -4,
      "name": "Rock_Stone"
    },
    {
      "x": -4,
      "y": -6,
      "z": -4,
      "name": "Rock_Stone"
    },
    {
      "x": -4,
      "y": -5,
      "z": -4,
      "name": "Rock_Stone"
    },
    {
      "x": -4,
      "y": -4,
      "z": -4,
      "name": "Rock_Stone"
    },
    {
      "x": -4,
      "y": -16,
      "z": -3,
      "name": "Rock_Stone"
    },
    {
      "x": -4,
      "y": -15,
      "z": -3,
      "name": "Rock_Stone"
    },
    {
      "x": -4,
      "y": -14,
      "z": -3,
      "name": "Rock_Stone"
    },
    {
      "x": -4,
      "y": -13,
      "z": -3,
      "name": "Rock_Stone"
    },
    {
      "x": -4,
      "y": -12,
      "z": -3,
      "name": "Rock_Stone"
    },
    {
      "x": -4,
      "y": -11,
      "z": -3,
      "name": "Rock_Stone"
    },
    {
      "x": -4,
      "y": -10,
      "z": -3,
      "name": "Rock_Stone"
    },
    {
      "x": -4,
      "y": -9,
      "z": -3,
      "name": "Rock_Stone"
    },
    {
      "x": -4,
      "y": -8,
      "z": -3,
      "name": "Rock_Stone"
    },
    {
      "x": -4,
      "y": -7,
      "z": -3,
      "name": "Rock_Stone"
    },
    {
      "x": -4,
      "y": -6,
      "z": -3,
      "name": "Rock_Stone"
    },
    {
      "x": -4,
      "y": -5,
      "z": -3,
      "name": "Rock_Stone"
    },
    {
      "x": -4,
      "y": -4,
      "z": -3,
      "name": "Rock_Stone"
    },
    {
      "x": -4,
      "y": -16,
      "z": -2,
      "name": "Rock_Stone"
    },
    {
      "x": -4,
      "y": -15,
      "z": -2,
      "name": "Rock_Stone"
    },
    {
      "x": -4,
      "y": -14,
      "z": -2,
      "name": "Rock_Stone"
    },
    {
      "x": -4,
      "y": -13,
      "z": -2,
      "name": "Rock_Stone"
    },
    {
      "x": -4,
      "y": -12,
      "z": -2,
      "name": "Rock_Stone"
    },
    {
      "x": -4,
      "y": -11,
      "z": -2,
      "name": "Rock_Stone"
    },
    {
      "x": -4,
      "y": -10,
      "z": -2,
      "name": "Rock_Stone"
    },
    {
      "x": -4,
      "y": -9,
      "z": -2,
      "name": "Rock_Stone"
    },
    {
      "x": -4,
      "y": -8,
      "z": -2,
      "name": "Rock_Stone"
    },
    {
      "x": -4,
      "y": -7,
      "z": -2,
      "name": "Rock_Stone"
    },
    {
      "x": -4,
      "y": -6,
      "z": -2,
      "name": "Rock_Stone"
    },
    {
      "x": -4,
      "y": -5,
      "z": -2,
      "name": "Rock_Stone"
    },
    {
      "x": -4,
      "y": -4,
      "z": -2,
      "name": "Rock_Stone"
    },
    {
      "x": -4,
      "y": -16,
      "z": -1,
      "name": "Rock_Stone"
    },
    {
      "x": -4,
      "y": -15,
      "z": -1,
      "name": "Rock_Stone"
    },
    {
      "x": -4,
      "y": -14,
      "z": -1,
      "name": "Rock_Stone"
    },
    {
      "x": -4,
      "y": -13,
      "z": -1,
      "name": "Rock_Stone"
    },
    {
      "x": -4,
      "y": -12,
      "z": -1,
      "name": "Rock_Stone"
    },
    {
      "x": -4,
      "y": -11,
      "z": -1,
      "name": "Rock_Stone"
    },
    {
      "x": -4,
      "y": -10,
      "z": -1,
      "name": "Rock_Stone"
    },
    {
      "x": -4,
      "y": -9,
      "z": -1,
      "name": "Rock_Stone"
    },
    {
      "x": -4,
      "y": -8,
      "z": -1,
      "name": "Rock_Stone"
    },
    {
      "x": -4,
      "y": -7,
      "z": -1,
      "name": "Rock_Stone"
    },
    {
      "x": -4,
      "y": -6,
      "z": -1,
      "name": "Rock_Stone"
    },
    {
      "x": -4,
      "y": -5,
      "z": -1,
      "name": "Rock_Stone"
    },
    {
      "x": -4,
      "y": -4,
      "z": -1,
      "name": "Rock_Stone"
    },
    {
      "x": -4,
      "y": -3,
      "z": -1,
      "name": "Rock_Stone"
    },
    {
      "x": -4,
      "y": -2,
      "z": -1,
      "name": "Rock_Stone"
    },
    {
      "x": -4,
      "y": -1,
      "z": -1,
      "name": "Rock_Stone"
    },
    {
      "x": -4,
      "y": -16,
      "z": 0,
      "name": "Rock_Stone"
    },
    {
      "x": -4,
      "y": -15,
      "z": 0,
      "name": "Rock_Stone"
    },
    {
      "x": -4,
      "y": -14,
      "z": 0,
      "name": "Rock_Stone"
    },
    {
      "x": -4,
      "y": -13,
      "z": 0,
      "name": "Rock_Stone"
    },
    {
      "x": -4,
      "y": -12,
      "z": 0,
      "name": "Rock_Stone"
    },
    {
      "x": -4,
      "y": -11,
      "z": 0,
      "name": "Rock_Stone"
    },
    {
      "x": -4,
      "y": -10,
      "z": 0,
      "name": "Rock_Stone"
    },
    {
      "x": -4,
      "y": -9,
      "z": 0,
      "name": "Rock_Stone"
    },
    {
      "x": -4,
      "y": -8,
      "z": 0,
      "name": "Rock_Stone"
    },
    {
      "x": -4,
      "y": -7,
      "z": 0,
      "name": "Rock_Stone"
    },
    {
      "x": -4,
      "y": -6,
      "z": 0,
      "name": "Rock_Stone"
    },
    {
      "x": -4,
      "y": -5,
      "z": 0,
      "name": "Rock_Stone"
    },
    {
      "x": -4,
      "y": -4,
      "z": 0,
      "name": "Rock_Stone"
    },
    {
      "x": -4,
      "y": -3,
      "z": 0,
      "name": "Rock_Stone"
    },
    {
      "x": -4,
      "y": -2,
      "z": 0,
      "name": "Rock_Stone"
    },
    {
      "x": -4,
      "y": -1,
      "z": 0,
      "name": "Rock_Stone"
    },
    {
      "x": -4,
      "y": -16,
      "z": 1,
      "name": "Rock_Stone"
    },
    {
      "x": -4,
      "y": -15,
      "z": 1,
      "name": "Rock_Stone"
    },
    {
      "x": -4,
      "y": -14,
      "z": 1,
      "name": "Rock_Stone"
    },
    {
      "x": -4,
      "y": -13,
      "z": 1,
      "name": "Rock_Stone"
    },
    {
      "x": -4,
      "y": -12,
      "z": 1,
      "name": "Rock_Stone"
    },
    {
      "x": -4,
      "y": -11,
      "z": 1,
      "name": "Rock_Stone"
    },
    {
      "x": -4,
      "y": -10,
      "z": 1,
      "name": "Rock_Stone"
    },
    {
      "x": -4,
      "y": -9,
      "z": 1,
      "name": "Rock_Stone"
    },
    {
      "x": -4,
      "y": -8,
      "z": 1,
      "name": "Rock_Stone"
    },
    {
      "x": -4,
      "y": -7,
      "z": 1,
      "name": "Rock_Stone"
    },
    {
      "x": -4,
      "y": -6,
      "z": 1,
      "name": "Rock_Stone_Mossy"
    },
    {
      "x": -4,
      "y": -5,
      "z": 1,
      "name": "Empty"
    },
    {
      "x": -4,
      "y": -4,
      "z": 1,
      "name": "Empty"
    },
    {
      "x": -4,
      "y": -3,
      "z": 1,
      "name": "Rock_Quartzite_Brick_Smooth"
    },
    {
      "x": -4,
      "y": -2,
      "z": 1,
      "name": "Rock_Quartzite_Brick_Smooth"
    },
    {
      "x": -4,
      "y": -1,
      "z": 1,
      "name": "Rock_Quartzite_Brick_Smooth"
    },
    {
      "x": -4,
      "y": -16,
      "z": 2,
      "name": "Rock_Stone"
    },
    {
      "x": -4,
      "y": -15,
      "z": 2,
      "name": "Rock_Stone"
    },
    {
      "x": -4,
      "y": -14,
      "z": 2,
      "name": "Rock_Stone"
    },
    {
      "x": -4,
      "y": -13,
      "z": 2,
      "name": "Rock_Stone"
    },
    {
      "x": -4,
      "y": -12,
      "z": 2,
      "name": "Rock_Stone"
    },
    {
      "x": -4,
      "y": -11,
      "z": 2,
      "name": "Rock_Stone"
    },
    {
      "x": -4,
      "y": -10,
      "z": 2,
      "name": "Rock_Stone"
    },
    {
      "x": -4,
      "y": -9,
      "z": 2,
      "name": "Rock_Stone"
    },
    {
      "x": -4,
      "y": -8,
      "z": 2,
      "name": "Rock_Stone"
    },
    {
      "x": -4,
      "y": -7,
      "z": 2,
      "name": "Rock_Stone_Mossy"
    },
    {
      "x": -4,
      "y": -6,
      "z": 2,
      "name": "Rock_Stone_Mossy"
    },
    {
      "x": -4,
      "y": -5,
      "z": 2,
      "name": "Empty"
    },
    {
      "x": -4,
      "y": -4,
      "z": 2,
      "name": "Empty"
    },
    {
      "x": -4,
      "y": -3,
      "z": 2,
      "name": "Rock_Quartzite_Brick_Smooth"
    },
    {
      "x": -4,
      "y": -2,
      "z": 2,
      "name": "Rock_Quartzite_Brick_Smooth"
    },
    {
      "x": -4,
      "y": -1,
      "z": 2,
      "name": "Rock_Quartzite_Brick_Smooth"
    },
    {
      "x": -4,
      "y": -16,
      "z": 3,
      "name": "Rock_Stone"
    },
    {
      "x": -4,
      "y": -15,
      "z": 3,
      "name": "Rock_Stone"
    },
    {
      "x": -4,
      "y": -14,
      "z": 3,
      "name": "Rock_Stone"
    },
    {
      "x": -4,
      "y": -13,
      "z": 3,
      "name": "Rock_Stone"
    },
    {
      "x": -4,
      "y": -12,
      "z": 3,
      "name": "Rock_Stone"
    },
    {
      "x": -4,
      "y": -11,
      "z": 3,
      "name": "Rock_Stone"
    },
    {
      "x": -4,
      "y": -10,
      "z": 3,
      "name": "Rock_Stone"
    },
    {
      "x": -4,
      "y": -9,
      "z": 3,
      "name": "Rock_Stone"
    },
    {
      "x": -4,
      "y": -8,
      "z": 3,
      "name": "Rock_Stone_Mossy"
    },
    {
      "x": -4,
      "y": -7,
      "z": 3,
      "name": "Rock_Stone_Mossy"
    },
    {
      "x": -4,
      "y": -6,
      "z": 3,
      "name": "Plant_Moss_Block_Green"
    },
    {
      "x": -4,
      "y": -5,
      "z": 3,
      "name": "Plant_Moss_Block_Green"
    },
    {
      "x": -4,
      "y": -4,
      "z": 3,
      "name": "Empty"
    },
    {
      "x": -4,
      "y": -3,
      "z": 3,
      "name": "Rock_Quartzite_Brick_Smooth"
    },
    {
      "x": -4,
      "y": -2,
      "z": 3,
      "name": "Rock_Quartzite_Brick_Smooth"
    },
    {
      "x": -4,
      "y": -1,
      "z": 3,
      "name": "Rock_Quartzite_Brick_Smooth"
    },
    {
      "x": -4,
      "y": -16,
      "z": 4,
      "name": "Rock_Stone"
    },
    {
      "x": -4,
      "y": -15,
      "z": 4,
      "name": "Rock_Stone"
    },
    {
      "x": -4,
      "y": -14,
      "z": 4,
      "name": "Rock_Stone"
    },
    {
      "x": -4,
      "y": -13,
      "z": 4,
      "name": "Rock_Stone"
    },
    {
      "x": -4,
      "y": -12,
      "z": 4,
      "name": "Rock_Stone"
    },
    {
      "x": -4,
      "y": -11,
      "z": 4,
      "name": "Rock_Stone"
    },
    {
      "x": -4,
      "y": -10,
      "z": 4,
      "name": "Rock_Stone"
    },
    {
      "x": -4,
      "y": -9,
      "z": 4,
      "name": "Rock_Stone"
    },
    {
      "x": -4,
      "y": -8,
      "z": 4,
      "name": "Rock_Stone_Mossy"
    },
    {
      "x": -4,
      "y": -7,
      "z": 4,
      "name": "Rock_Stone_Mossy"
    },
    {
      "x": -4,
      "y": -6,
      "z": 4,
      "name": "Plant_Moss_Block_Green"
    },
    {
      "x": -4,
      "y": -5,
      "z": 4,
      "name": "Plant_Moss_Block_Green"
    },
    {
      "x": -4,
      "y": -4,
      "z": 4,
      "name": "Empty"
    },
    {
      "x": -4,
      "y": -3,
      "z": 4,
      "name": "Rock_Quartzite_Brick_Smooth"
    },
    {
      "x": -4,
      "y": -2,
      "z": 4,
      "name": "Rock_Quartzite_Brick_Smooth"
    },
    {
      "x": -4,
      "y": -1,
      "z": 4,
      "name": "Rock_Quartzite_Brick_Smooth"
    },
    {
      "x": -4,
      "y": -16,
      "z": 5,
      "name": "Rock_Stone"
    },
    {
      "x": -4,
      "y": -15,
      "z": 5,
      "name": "Rock_Stone"
    },
    {
      "x": -4,
      "y": -14,
      "z": 5,
      "name": "Rock_Stone"
    },
    {
      "x": -4,
      "y": -13,
      "z": 5,
      "name": "Rock_Stone"
    },
    {
      "x": -4,
      "y": -12,
      "z": 5,
      "name": "Rock_Stone"
    },
    {
      "x": -4,
      "y": -11,
      "z": 5,
      "name": "Rock_Stone"
    },
    {
      "x": -4,
      "y": -10,
      "z": 5,
      "name": "Rock_Stone"
    },
    {
      "x": -4,
      "y": -9,
      "z": 5,
      "name": "Rock_Stone"
    },
    {
      "x": -4,
      "y": -8,
      "z": 5,
      "name": "Rock_Stone_Mossy"
    },
    {
      "x": -4,
      "y": -7,
      "z": 5,
      "name": "Rock_Stone_Mossy"
    },
    {
      "x": -4,
      "y": -6,
      "z": 5,
      "name": "Rock_Stone_Mossy"
    },
    {
      "x": -4,
      "y": -5,
      "z": 5,
      "name": "Plant_Moss_Block_Green"
    },
    {
      "x": -4,
      "y": -4,
      "z": 5,
      "name": "Plant_Moss_Block_Green"
    },
    {
      "x": -4,
      "y": -3,
      "z": 5,
      "name": "Rock_Quartzite_Brick_Smooth"
    },
    {
      "x": -4,
      "y": -2,
      "z": 5,
      "name": "Rock_Quartzite_Brick_Smooth"
    },
    {
      "x": -4,
      "y": -1,
      "z": 5,
      "name": "Rock_Quartzite_Brick_Smooth"
    },
    {
      "x": -4,
      "y": -16,
      "z": 6,
      "name": "Rock_Stone"
    },
    {
      "x": -4,
      "y": -15,
      "z": 6,
      "name": "Rock_Stone"
    },
    {
      "x": -4,
      "y": -14,
      "z": 6,
      "name": "Rock_Stone"
    },
    {
      "x": -4,
      "y": -13,
      "z": 6,
      "name": "Rock_Stone"
    },
    {
      "x": -4,
      "y": -12,
      "z": 6,
      "name": "Rock_Stone"
    },
    {
      "x": -4,
      "y": -11,
      "z": 6,
      "name": "Rock_Stone"
    },
    {
      "x": -4,
      "y": -10,
      "z": 6,
      "name": "Rock_Stone"
    },
    {
      "x": -4,
      "y": -9,
      "z": 6,
      "name": "Rock_Stone"
    },
    {
      "x": -4,
      "y": -8,
      "z": 6,
      "name": "Rock_Stone"
    },
    {
      "x": -4,
      "y": -7,
      "z": 6,
      "name": "Rock_Stone_Mossy"
    },
    {
      "x": -4,
      "y": -6,
      "z": 6,
      "name": "Rock_Stone_Mossy"
    },
    {
      "x": -4,
      "y": -5,
      "z": 6,
      "name": "Rock_Stone_Mossy"
    },
    {
      "x": -4,
      "y": -4,
      "z": 6,
      "name": "Plant_Moss_Block_Green"
    },
    {
      "x": -4,
      "y": -3,
      "z": 6,
      "name": "Rock_Quartzite"
    },
    {
      "x": -4,
      "y": -2,
      "z": 6,
      "name": "Rock_Quartzite"
    },
    {
      "x": -4,
      "y": -1,
      "z": 6,
      "name": "Soil_Dirt"
    },
    {
      "x": -4,
      "y": -16,
      "z": 7,
      "name": "Rock_Stone"
    },
    {
      "x": -4,
      "y": -15,
      "z": 7,
      "name": "Rock_Stone"
    },
    {
      "x": -4,
      "y": -14,
      "z": 7,
      "name": "Rock_Stone"
    },
    {
      "x": -4,
      "y": -13,
      "z": 7,
      "name": "Rock_Stone"
    },
    {
      "x": -4,
      "y": -12,
      "z": 7,
      "name": "Rock_Stone"
    },
    {
      "x": -4,
      "y": -11,
      "z": 7,
      "name": "Rock_Stone"
    },
    {
      "x": -4,
      "y": -10,
      "z": 7,
      "name": "Rock_Stone"
    },
    {
      "x": -4,
      "y": -9,
      "z": 7,
      "name": "Rock_Stone"
    },
    {
      "x": -4,
      "y": -8,
      "z": 7,
      "name": "Rock_Stone"
    },
    {
      "x": -4,
      "y": -7,
      "z": 7,
      "name": "Rock_Stone"
    },
    {
      "x": -4,
      "y": -6,
      "z": 7,
      "name": "Plant_Moss_Block_Green"
    },
    {
      "x": -4,
      "y": -5,
      "z": 7,
      "name": "Plant_Moss_Block_Green"
    },
    {
      "x": -4,
      "y": -4,
      "z": 7,
      "name": "Plant_Moss_Block_Green"
    },
    {
      "x": -4,
      "y": -3,
      "z": 7,
      "name": "Rock_Stone"
    },
    {
      "x": -4,
      "y": -2,
      "z": 7,
      "name": "Rock_Stone"
    },
    {
      "x": -4,
      "y": -1,
      "z": 7,
      "name": "Rock_Stone"
    },
    {
      "x": -3,
      "y": -16,
      "z": -5,
      "name": "Rock_Stone"
    },
    {
      "x": -3,
      "y": -15,
      "z": -5,
      "name": "Rock_Stone"
    },
    {
      "x": -3,
      "y": -14,
      "z": -5,
      "name": "Rock_Stone"
    },
    {
      "x": -3,
      "y": -13,
      "z": -5,
      "name": "Rock_Stone"
    },
    {
      "x": -3,
      "y": -12,
      "z": -5,
      "name": "Rock_Stone"
    },
    {
      "x": -3,
      "y": -11,
      "z": -5,
      "name": "Rock_Stone"
    },
    {
      "x": -3,
      "y": -10,
      "z": -5,
      "name": "Rock_Stone"
    },
    {
      "x": -3,
      "y": -9,
      "z": -5,
      "name": "Rock_Stone"
    },
    {
      "x": -3,
      "y": -8,
      "z": -5,
      "name": "Rock_Stone"
    },
    {
      "x": -3,
      "y": -7,
      "z": -5,
      "name": "Rock_Stone"
    },
    {
      "x": -3,
      "y": -6,
      "z": -5,
      "name": "Rock_Stone"
    },
    {
      "x": -3,
      "y": -5,
      "z": -5,
      "name": "Rock_Stone"
    },
    {
      "x": -3,
      "y": -4,
      "z": -5,
      "name": "Rock_Stone"
    },
    {
      "x": -3,
      "y": -16,
      "z": -4,
      "name": "Rock_Stone"
    },
    {
      "x": -3,
      "y": -15,
      "z": -4,
      "name": "Rock_Stone"
    },
    {
      "x": -3,
      "y": -14,
      "z": -4,
      "name": "Rock_Stone"
    },
    {
      "x": -3,
      "y": -13,
      "z": -4,
      "name": "Rock_Stone"
    },
    {
      "x": -3,
      "y": -12,
      "z": -4,
      "name": "Rock_Stone"
    },
    {
      "x": -3,
      "y": -11,
      "z": -4,
      "name": "Rock_Stone"
    },
    {
      "x": -3,
      "y": -10,
      "z": -4,
      "name": "Rock_Stone"
    },
    {
      "x": -3,
      "y": -9,
      "z": -4,
      "name": "Rock_Stone"
    },
    {
      "x": -3,
      "y": -8,
      "z": -4,
      "name": "Rock_Stone"
    },
    {
      "x": -3,
      "y": -7,
      "z": -4,
      "name": "Rock_Stone"
    },
    {
      "x": -3,
      "y": -6,
      "z": -4,
      "name": "Rock_Stone"
    },
    {
      "x": -3,
      "y": -5,
      "z": -4,
      "name": "Rock_Stone"
    },
    {
      "x": -3,
      "y": -4,
      "z": -4,
      "name": "Rock_Stone"
    },
    {
      "x": -3,
      "y": -16,
      "z": -3,
      "name": "Rock_Stone"
    },
    {
      "x": -3,
      "y": -15,
      "z": -3,
      "name": "Rock_Stone"
    },
    {
      "x": -3,
      "y": -14,
      "z": -3,
      "name": "Rock_Stone"
    },
    {
      "x": -3,
      "y": -13,
      "z": -3,
      "name": "Rock_Stone"
    },
    {
      "x": -3,
      "y": -12,
      "z": -3,
      "name": "Rock_Stone"
    },
    {
      "x": -3,
      "y": -11,
      "z": -3,
      "name": "Rock_Stone"
    },
    {
      "x": -3,
      "y": -10,
      "z": -3,
      "name": "Rock_Stone"
    },
    {
      "x": -3,
      "y": -9,
      "z": -3,
      "name": "Rock_Stone"
    },
    {
      "x": -3,
      "y": -8,
      "z": -3,
      "name": "Rock_Stone"
    },
    {
      "x": -3,
      "y": -7,
      "z": -3,
      "name": "Rock_Stone"
    },
    {
      "x": -3,
      "y": -6,
      "z": -3,
      "name": "Rock_Stone"
    },
    {
      "x": -3,
      "y": -5,
      "z": -3,
      "name": "Rock_Stone"
    },
    {
      "x": -3,
      "y": -4,
      "z": -3,
      "name": "Rock_Stone"
    },
    {
      "x": -3,
      "y": -16,
      "z": -2,
      "name": "Rock_Stone"
    },
    {
      "x": -3,
      "y": -15,
      "z": -2,
      "name": "Rock_Stone"
    },
    {
      "x": -3,
      "y": -14,
      "z": -2,
      "name": "Rock_Stone"
    },
    {
      "x": -3,
      "y": -13,
      "z": -2,
      "name": "Rock_Stone"
    },
    {
      "x": -3,
      "y": -12,
      "z": -2,
      "name": "Rock_Stone"
    },
    {
      "x": -3,
      "y": -11,
      "z": -2,
      "name": "Rock_Stone"
    },
    {
      "x": -3,
      "y": -10,
      "z": -2,
      "name": "Rock_Stone"
    },
    {
      "x": -3,
      "y": -9,
      "z": -2,
      "name": "Rock_Stone"
    },
    {
      "x": -3,
      "y": -8,
      "z": -2,
      "name": "Rock_Stone"
    },
    {
      "x": -3,
      "y": -7,
      "z": -2,
      "name": "Rock_Stone"
    },
    {
      "x": -3,
      "y": -6,
      "z": -2,
      "name": "Rock_Stone"
    },
    {
      "x": -3,
      "y": -5,
      "z": -2,
      "name": "Rock_Stone"
    },
    {
      "x": -3,
      "y": -4,
      "z": -2,
      "name": "Rock_Stone"
    },
    {
      "x": -3,
      "y": -16,
      "z": -1,
      "name": "Rock_Stone"
    },
    {
      "x": -3,
      "y": -15,
      "z": -1,
      "name": "Rock_Stone"
    },
    {
      "x": -3,
      "y": -14,
      "z": -1,
      "name": "Rock_Stone"
    },
    {
      "x": -3,
      "y": -13,
      "z": -1,
      "name": "Rock_Stone"
    },
    {
      "x": -3,
      "y": -12,
      "z": -1,
      "name": "Rock_Stone"
    },
    {
      "x": -3,
      "y": -11,
      "z": -1,
      "name": "Rock_Stone"
    },
    {
      "x": -3,
      "y": -10,
      "z": -1,
      "name": "Rock_Stone"
    },
    {
      "x": -3,
      "y": -9,
      "z": -1,
      "name": "Rock_Stone"
    },
    {
      "x": -3,
      "y": -8,
      "z": -1,
      "name": "Rock_Stone"
    },
    {
      "x": -3,
      "y": -7,
      "z": -1,
      "name": "Rock_Stone"
    },
    {
      "x": -3,
      "y": -6,
      "z": -1,
      "name": "Rock_Stone"
    },
    {
      "x": -3,
      "y": -5,
      "z": -1,
      "name": "Rock_Stone"
    },
    {
      "x": -3,
      "y": -4,
      "z": -1,
      "name": "Rock_Stone"
    },
    {
      "x": -3,
      "y": -3,
      "z": -1,
      "name": "Rock_Quartzite_Brick_Smooth"
    },
    {
      "x": -3,
      "y": -2,
      "z": -1,
      "name": "Rock_Quartzite_Brick_Smooth"
    },
    {
      "x": -3,
      "y": -1,
      "z": -1,
      "name": "Rock_Quartzite_Brick_Smooth"
    },
    {
      "x": -3,
      "y": -16,
      "z": 0,
      "name": "Rock_Stone"
    },
    {
      "x": -3,
      "y": -15,
      "z": 0,
      "name": "Rock_Stone"
    },
    {
      "x": -3,
      "y": -14,
      "z": 0,
      "name": "Rock_Stone"
    },
    {
      "x": -3,
      "y": -13,
      "z": 0,
      "name": "Rock_Stone"
    },
    {
      "x": -3,
      "y": -12,
      "z": 0,
      "name": "Rock_Stone"
    },
    {
      "x": -3,
      "y": -11,
      "z": 0,
      "name": "Rock_Stone"
    },
    {
      "x": -3,
      "y": -10,
      "z": 0,
      "name": "Soil_Mud_Dry"
    },
    {
      "x": -3,
      "y": -9,
      "z": 0,
      "name": "Rock_Stone"
    },
    {
      "x": -3,
      "y": -8,
      "z": 0,
      "name": "Rock_Stone"
    },
    {
      "x": -3,
      "y": -7,
      "z": 0,
      "name": "Rock_Stone"
    },
    {
      "x": -3,
      "y": -6,
      "z": 0,
      "name": "Rock_Stone"
    },
    {
      "x": -3,
      "y": -5,
      "z": 0,
      "name": "Rock_Stone"
    },
    {
      "x": -3,
      "y": -4,
      "z": 0,
      "name": "Rock_Stone"
    },
    {
      "x": -3,
      "y": -3,
      "z": 0,
      "name": "Rock_Quartzite_Brick_Smooth"
    },
    {
      "x": -3,
      "y": -2,
      "z": 0,
      "name": "Rock_Quartzite_Brick_Smooth"
    },
    {
      "x": -3,
      "y": -1,
      "z": 0,
      "name": "Rock_Quartzite_Brick_Smooth"
    },
    {
      "x": -3,
      "y": -16,
      "z": 1,
      "name": "Rock_Stone"
    },
    {
      "x": -3,
      "y": -15,
      "z": 1,
      "name": "Rock_Stone"
    },
    {
      "x": -3,
      "y": -14,
      "z": 1,
      "name": "Rock_Stone"
    },
    {
      "x": -3,
      "y": -13,
      "z": 1,
      "name": "Rock_Stone"
    },
    {
      "x": -3,
      "y": -12,
      "z": 1,
      "name": "Rock_Stone"
    },
    {
      "x": -3,
      "y": -11,
      "z": 1,
      "name": "Rock_Stone"
    },
    {
      "x": -3,
      "y": -10,
      "z": 1,
      "name": "Soil_Mud_Dry"
    },
    {
      "x": -3,
      "y": -9,
      "z": 1,
      "name": "Rock_Stone"
    },
    {
      "x": -3,
      "y": -8,
      "z": 1,
      "name": "Rock_Stone"
    },
    {
      "x": -3,
      "y": -7,
      "z": 1,
      "name": "Rock_Stone_Mossy"
    },
    {
      "x": -3,
      "y": -6,
      "z": 1,
      "name": "Plant_Crop_Mushroom_Glowing_Blue"
    },
    {
      "x": -3,
      "y": -5,
      "z": 1,
      "name": "Empty"
    },
    {
      "x": -3,
      "y": -4,
      "z": 1,
      "name": "Empty"
    },
    {
      "x": -3,
      "y": -3,
      "z": 1,
      "name": "Rock_Quartzite_Brick_Smooth"
    },
    {
      "x": -3,
      "y": -2,
      "z": 1,
      "name": "Rock_Quartzite_Brick_Smooth"
    },
    {
      "x": -3,
      "y": -1,
      "z": 1,
      "name": "Rock_Quartzite_Brick_Smooth"
    },
    {
      "x": -3,
      "y": -16,
      "z": 2,
      "name": "Rock_Stone"
    },
    {
      "x": -3,
      "y": -15,
      "z": 2,
      "name": "Rock_Stone"
    },
    {
      "x": -3,
      "y": -14,
      "z": 2,
      "name": "Rock_Stone"
    },
    {
      "x": -3,
      "y": -13,
      "z": 2,
      "name": "Rock_Stone"
    },
    {
      "x": -3,
      "y": -12,
      "z": 2,
      "name": "Rock_Stone"
    },
    {
      "x": -3,
      "y": -11,
      "z": 2,
      "name": "Rock_Stone"
    },
    {
      "x": -3,
      "y": -10,
      "z": 2,
      "name": "Soil_Mud_Dry"
    },
    {
      "x": -3,
      "y": -9,
      "z": 2,
      "name": "Rock_Stone"
    },
    {
      "x": -3,
      "y": -8,
      "z": 2,
      "name": "Rock_Stone_Mossy"
    },
    {
      "x": -3,
      "y": -7,
      "z": 2,
      "name": "Rock_Stone_Mossy"
    },
    {
      "x": -3,
      "y": -6,
      "z": 2,
      "name": "Plant_Moss_Block_Green"
    },
    {
      "x": -3,
      "y": -5,
      "z": 2,
      "name": "Plant_Moss_Rug_Green"
    },
    {
      "x": -3,
      "y": -4,
      "z": 2,
      "name": "Empty"
    },
    {
      "x": -3,
      "y": -3,
      "z": 2,
      "name": "Plant_Moss_Wall_Green",
      "rotation": 1
    },
    {
      "x": -3,
      "y": -2,
      "z": 2,
      "name": "Plant_Moss_Wall_Green",
      "rotation": 1
    },
    {
      "x": -3,
      "y": -1,
      "z": 2,
      "name": "Plant_Moss_Wall_Green",
      "rotation": 1
    },
    {
      "x": -3,
      "y": -16,
      "z": 3,
      "name": "Rock_Stone"
    },
    {
      "x": -3,
      "y": -15,
      "z": 3,
      "name": "Rock_Stone"
    },
    {
      "x": -3,
      "y": -14,
      "z": 3,
      "name": "Rock_Stone"
    },
    {
      "x": -3,
      "y": -13,
      "z": 3,
      "name": "Rock_Stone"
    },
    {
      "x": -3,
      "y": -12,
      "z": 3,
      "name": "Rock_Stone"
    },
    {
      "x": -3,
      "y": -11,
      "z": 3,
      "name": "Rock_Stone"
    },
    {
      "x": -3,
      "y": -10,
      "z": 3,
      "name": "Rock_Stone"
    },
    {
      "x": -3,
      "y": -9,
      "z": 3,
      "name": "Rock_Stone_Mossy"
    },
    {
      "x": -3,
      "y": -8,
      "z": 3,
      "name": "Rock_Stone_Mossy"
    },
    {
      "x": -3,
      "y": -7,
      "z": 3,
      "name": "Plant_Moss_Block_Green"
    },
    {
      "x": -3,
      "y": -6,
      "z": 3,
      "name": "Plant_Moss_Block_Green"
    },
    {
      "x": -3,
      "y": -5,
      "z": 3,
      "name": "Plant_Moss_Rug_Green"
    },
    {
      "x": -3,
      "y": -4,
      "z": 3,
      "name": "Empty"
    },
    {
      "x": -3,
      "y": -3,
      "z": 3,
      "name": "Soil_Pathway_Half",
      "rotation": 8
    },
    {
      "x": -3,
      "y": -2,
      "z": 3,
      "name": "Soil_Pathway_Half"
    },
    {
      "x": -3,
      "y": -1,
      "z": 3,
      "name": "Plant_Moss_Wall_Green",
      "rotation": 1
    },
    {
      "x": -3,
      "y": -16,
      "z": 4,
      "name": "Rock_Stone"
    },
    {
      "x": -3,
      "y": -15,
      "z": 4,
      "name": "Rock_Stone"
    },
    {
      "x": -3,
      "y": -14,
      "z": 4,
      "name": "Rock_Stone"
    },
    {
      "x": -3,
      "y": -13,
      "z": 4,
      "name": "Rock_Stone"
    },
    {
      "x": -3,
      "y": -12,
      "z": 4,
      "name": "Rock_Stone"
    },
    {
      "x": -3,
      "y": -11,
      "z": 4,
      "name": "Rock_Stone"
    },
    {
      "x": -3,
      "y": -10,
      "z": 4,
      "name": "Rock_Stone"
    },
    {
      "x": -3,
      "y": -9,
      "z": 4,
      "name": "Rock_Stone_Mossy"
    },
    {
      "x": -3,
      "y": -8,
      "z": 4,
      "name": "Rock_Stone_Mossy"
    },
    {
      "x": -3,
      "y": -7,
      "z": 4,
      "name": "Plant_Moss_Block_Green"
    },
    {
      "x": -3,
      "y": -6,
      "z": 4,
      "name": "Plant_Moss_Block_Green"
    },
    {
      "x": -3,
      "y": -5,
      "z": 4,
      "name": "Plant_Moss_Block_Green"
    },
    {
      "x": -3,
      "y": -4,
      "z": 4,
      "name": "Empty"
    },
    {
      "x": -3,
      "y": -3,
      "z": 4,
      "name": "*Soil_Pathway_Half_State_Definitions_Block",
      "rotation": 8
    },
    {
      "x": -3,
      "y": -2,
      "z": 4,
      "name": "Soil_Pathway"
    },
    {
      "x": -3,
      "y": -1,
      "z": 4,
      "name": "Empty"
    },
    {
      "x": -3,
      "y": -16,
      "z": 5,
      "name": "Rock_Stone"
    },
    {
      "x": -3,
      "y": -15,
      "z": 5,
      "name": "Rock_Stone"
    },
    {
      "x": -3,
      "y": -14,
      "z": 5,
      "name": "Rock_Stone"
    },
    {
      "x": -3,
      "y": -13,
      "z": 5,
      "name": "Rock_Stone"
    },
    {
      "x": -3,
      "y": -12,
      "z": 5,
      "name": "Rock_Stone"
    },
    {
      "x": -3,
      "y": -11,
      "z": 5,
      "name": "Rock_Stone"
    },
    {
      "x": -3,
      "y": -10,
      "z": 5,
      "name": "Rock_Stone"
    },
    {
      "x": -3,
      "y": -9,
      "z": 5,
      "name": "Rock_Stone_Mossy"
    },
    {
      "x": -3,
      "y": -8,
      "z": 5,
      "name": "Rock_Stone_Mossy"
    },
    {
      "x": -3,
      "y": -7,
      "z": 5,
      "name": "Rock_Stone_Mossy"
    },
    {
      "x": -3,
      "y": -6,
      "z": 5,
      "name": "Plant_Moss_Block_Green"
    },
    {
      "x": -3,
      "y": -5,
      "z": 5,
      "name": "Plant_Moss_Block_Green"
    },
    {
      "x": -3,
      "y": -4,
      "z": 5,
      "name": "Plant_Moss_Block_Green"
    },
    {
      "x": -3,
      "y": -3,
      "z": 5,
      "name": "Soil_Mud_Dry"
    },
    {
      "x": -3,
      "y": -2,
      "z": 5,
      "name": "Soil_Pathway"
    },
    {
      "x": -3,
      "y": -1,
      "z": 5,
      "name": "Soil_Pathway"
    },
    {
      "x": -3,
      "y": -16,
      "z": 6,
      "name": "Rock_Stone"
    },
    {
      "x": -3,
      "y": -15,
      "z": 6,
      "name": "Rock_Stone"
    },
    {
      "x": -3,
      "y": -14,
      "z": 6,
      "name": "Rock_Stone"
    },
    {
      "x": -3,
      "y": -13,
      "z": 6,
      "name": "Rock_Stone"
    },
    {
      "x": -3,
      "y": -12,
      "z": 6,
      "name": "Rock_Stone"
    },
    {
      "x": -3,
      "y": -11,
      "z": 6,
      "name": "Rock_Stone"
    },
    {
      "x": -3,
      "y": -10,
      "z": 6,
      "name": "Rock_Stone"
    },
    {
      "x": -3,
      "y": -9,
      "z": 6,
      "name": "Rock_Stone_Mossy"
    },
    {
      "x": -3,
      "y": -8,
      "z": 6,
      "name": "Rock_Stone_Mossy"
    },
    {
      "x": -3,
      "y": -7,
      "z": 6,
      "name": "Rock_Stone_Mossy"
    },
    {
      "x": -3,
      "y": -6,
      "z": 6,
      "name": "Rock_Stone_Mossy"
    },
    {
      "x": -3,
      "y": -5,
      "z": 6,
      "name": "Plant_Moss_Block_Green"
    },
    {
      "x": -3,
      "y": -4,
      "z": 6,
      "name": "Plant_Moss_Block_Green"
    },
    {
      "x": -3,
      "y": -3,
      "z": 6,
      "name": "Rock_Quartzite"
    },
    {
      "x": -3,
      "y": -2,
      "z": 6,
      "name": "Rock_Quartzite"
    },
    {
      "x": -3,
      "y": -1,
      "z": 6,
      "name": "Soil_Dirt"
    },
    {
      "x": -3,
      "y": -16,
      "z": 7,
      "name": "Rock_Stone"
    },
    {
      "x": -3,
      "y": -15,
      "z": 7,
      "name": "Rock_Stone"
    },
    {
      "x": -3,
      "y": -14,
      "z": 7,
      "name": "Rock_Stone"
    },
    {
      "x": -3,
      "y": -13,
      "z": 7,
      "name": "Rock_Stone"
    },
    {
      "x": -3,
      "y": -12,
      "z": 7,
      "name": "Rock_Stone"
    },
    {
      "x": -3,
      "y": -11,
      "z": 7,
      "name": "Rock_Stone"
    },
    {
      "x": -3,
      "y": -10,
      "z": 7,
      "name": "Rock_Stone"
    },
    {
      "x": -3,
      "y": -9,
      "z": 7,
      "name": "Rock_Stone"
    },
    {
      "x": -3,
      "y": -8,
      "z": 7,
      "name": "Rock_Stone"
    },
    {
      "x": -3,
      "y": -7,
      "z": 7,
      "name": "Plant_Moss_Block_Green"
    },
    {
      "x": -3,
      "y": -6,
      "z": 7,
      "name": "Plant_Moss_Block_Green"
    },
    {
      "x": -3,
      "y": -5,
      "z": 7,
      "name": "Plant_Moss_Block_Green"
    },
    {
      "x": -3,
      "y": -4,
      "z": 7,
      "name": "Plant_Moss_Block_Green"
    },
    {
      "x": -3,
      "y": -3,
      "z": 7,
      "name": "Rock_Stone"
    },
    {
      "x": -3,
      "y": -2,
      "z": 7,
      "name": "Rock_Stone"
    },
    {
      "x": -3,
      "y": -1,
      "z": 7,
      "name": "Rock_Stone"
    },
    {
      "x": -2,
      "y": -16,
      "z": -5,
      "name": "Rock_Stone"
    },
    {
      "x": -2,
      "y": -15,
      "z": -5,
      "name": "Rock_Stone"
    },
    {
      "x": -2,
      "y": -14,
      "z": -5,
      "name": "Rock_Stone"
    },
    {
      "x": -2,
      "y": -13,
      "z": -5,
      "name": "Rock_Stone"
    },
    {
      "x": -2,
      "y": -12,
      "z": -5,
      "name": "Rock_Stone"
    },
    {
      "x": -2,
      "y": -11,
      "z": -5,
      "name": "Rock_Stone"
    },
    {
      "x": -2,
      "y": -10,
      "z": -5,
      "name": "Rock_Stone"
    },
    {
      "x": -2,
      "y": -9,
      "z": -5,
      "name": "Rock_Stone"
    },
    {
      "x": -2,
      "y": -8,
      "z": -5,
      "name": "Rock_Stone"
    },
    {
      "x": -2,
      "y": -7,
      "z": -5,
      "name": "Rock_Stone"
    },
    {
      "x": -2,
      "y": -6,
      "z": -5,
      "name": "Rock_Stone"
    },
    {
      "x": -2,
      "y": -5,
      "z": -5,
      "name": "Rock_Stone"
    },
    {
      "x": -2,
      "y": -4,
      "z": -5,
      "name": "Rock_Stone"
    },
    {
      "x": -2,
      "y": -16,
      "z": -4,
      "name": "Rock_Stone"
    },
    {
      "x": -2,
      "y": -15,
      "z": -4,
      "name": "Rock_Stone"
    },
    {
      "x": -2,
      "y": -14,
      "z": -4,
      "name": "Rock_Stone"
    },
    {
      "x": -2,
      "y": -13,
      "z": -4,
      "name": "Rock_Stone"
    },
    {
      "x": -2,
      "y": -12,
      "z": -4,
      "name": "Rock_Stone"
    },
    {
      "x": -2,
      "y": -11,
      "z": -4,
      "name": "Rock_Stone"
    },
    {
      "x": -2,
      "y": -10,
      "z": -4,
      "name": "Rock_Stone"
    },
    {
      "x": -2,
      "y": -9,
      "z": -4,
      "name": "Rock_Stone"
    },
    {
      "x": -2,
      "y": -8,
      "z": -4,
      "name": "Rock_Stone"
    },
    {
      "x": -2,
      "y": -7,
      "z": -4,
      "name": "Rock_Stone"
    },
    {
      "x": -2,
      "y": -6,
      "z": -4,
      "name": "Rock_Stone"
    },
    {
      "x": -2,
      "y": -5,
      "z": -4,
      "name": "Rock_Stone"
    },
    {
      "x": -2,
      "y": -4,
      "z": -4,
      "name": "Rock_Stone"
    },
    {
      "x": -2,
      "y": -16,
      "z": -3,
      "name": "Rock_Stone"
    },
    {
      "x": -2,
      "y": -15,
      "z": -3,
      "name": "Rock_Stone"
    },
    {
      "x": -2,
      "y": -14,
      "z": -3,
      "name": "Rock_Stone"
    },
    {
      "x": -2,
      "y": -13,
      "z": -3,
      "name": "Rock_Stone"
    },
    {
      "x": -2,
      "y": -12,
      "z": -3,
      "name": "Rock_Stone"
    },
    {
      "x": -2,
      "y": -11,
      "z": -3,
      "name": "Rock_Stone"
    },
    {
      "x": -2,
      "y": -10,
      "z": -3,
      "name": "Rock_Stone"
    },
    {
      "x": -2,
      "y": -9,
      "z": -3,
      "name": "Rock_Stone"
    },
    {
      "x": -2,
      "y": -8,
      "z": -3,
      "name": "Rock_Stone"
    },
    {
      "x": -2,
      "y": -7,
      "z": -3,
      "name": "Rock_Stone"
    },
    {
      "x": -2,
      "y": -6,
      "z": -3,
      "name": "Rock_Stone"
    },
    {
      "x": -2,
      "y": -5,
      "z": -3,
      "name": "Rock_Stone"
    },
    {
      "x": -2,
      "y": -4,
      "z": -3,
      "name": "Rock_Stone"
    },
    {
      "x": -2,
      "y": -16,
      "z": -2,
      "name": "Rock_Stone"
    },
    {
      "x": -2,
      "y": -15,
      "z": -2,
      "name": "Rock_Stone"
    },
    {
      "x": -2,
      "y": -14,
      "z": -2,
      "name": "Rock_Stone"
    },
    {
      "x": -2,
      "y": -13,
      "z": -2,
      "name": "Rock_Stone"
    },
    {
      "x": -2,
      "y": -12,
      "z": -2,
      "name": "Rock_Stone"
    },
    {
      "x": -2,
      "y": -11,
      "z": -2,
      "name": "Rock_Stone"
    },
    {
      "x": -2,
      "y": -10,
      "z": -2,
      "name": "Rock_Stone"
    },
    {
      "x": -2,
      "y": -9,
      "z": -2,
      "name": "Soil_Mud_Dry"
    },
    {
      "x": -2,
      "y": -8,
      "z": -2,
      "name": "Rock_Stone"
    },
    {
      "x": -2,
      "y": -7,
      "z": -2,
      "name": "Rock_Stone"
    },
    {
      "x": -2,
      "y": -6,
      "z": -2,
      "name": "Rock_Stone"
    },
    {
      "x": -2,
      "y": -5,
      "z": -2,
      "name": "Rock_Stone"
    },
    {
      "x": -2,
      "y": -4,
      "z": -2,
      "name": "Rock_Stone"
    },
    {
      "x": -2,
      "y": -16,
      "z": -1,
      "name": "Rock_Stone"
    },
    {
      "x": -2,
      "y": -15,
      "z": -1,
      "name": "Rock_Stone"
    },
    {
      "x": -2,
      "y": -14,
      "z": -1,
      "name": "Rock_Stone"
    },
    {
      "x": -2,
      "y": -13,
      "z": -1,
      "name": "Rock_Stone"
    },
    {
      "x": -2,
      "y": -12,
      "z": -1,
      "name": "Rock_Stone"
    },
    {
      "x": -2,
      "y": -11,
      "z": -1,
      "name": "Rock_Stone"
    },
    {
      "x": -2,
      "y": -10,
      "z": -1,
      "name": "Soil_Mud_Dry"
    },
    {
      "x": -2,
      "y": -9,
      "z": -1,
      "name": "Rock_Stone"
    },
    {
      "x": -2,
      "y": -8,
      "z": -1,
      "name": "Plant_Crop_Mushroom_Block_Green_Trunk"
    },
    {
      "x": -2,
      "y": -7,
      "z": -1,
      "name": "Plant_Crop_Mushroom_Block_Green_Trunk"
    },
    {
      "x": -2,
      "y": -6,
      "z": -1,
      "name": "Plant_Crop_Mushroom_Block_Green_Trunk"
    },
    {
      "x": -2,
      "y": -5,
      "z": -1,
      "name": "Plant_Crop_Mushroom_Block_Green_Trunk"
    },
    {
      "x": -2,
      "y": -4,
      "z": -1,
      "name": "Plant_Crop_Mushroom_Block_Green"
    },
    {
      "x": -2,
      "y": -3,
      "z": -1,
      "name": "Rock_Quartzite_Brick_Smooth"
    },
    {
      "x": -2,
      "y": -2,
      "z": -1,
      "name": "Rock_Quartzite_Brick_Smooth"
    },
    {
      "x": -2,
      "y": -1,
      "z": -1,
      "name": "Rock_Quartzite_Brick_Smooth"
    },
    {
      "x": -2,
      "y": -16,
      "z": 0,
      "name": "Rock_Stone"
    },
    {
      "x": -2,
      "y": -15,
      "z": 0,
      "name": "Rock_Stone"
    },
    {
      "x": -2,
      "y": -14,
      "z": 0,
      "name": "Rock_Stone"
    },
    {
      "x": -2,
      "y": -13,
      "z": 0,
      "name": "Soil_Mud_Dry"
    },
    {
      "x": -2,
      "y": -12,
      "z": 0,
      "name": "Soil_Mud_Dry"
    },
    {
      "x": -2,
      "y": -11,
      "z": 0,
      "name": "Soil_Mud_Dry"
    },
    {
      "x": -2,
      "y": -10,
      "z": 0,
      "name": "Soil_Mud_Dry"
    },
    {
      "x": -2,
      "y": -9,
      "z": 0,
      "name": "Rock_Stone"
    },
    {
      "x": -2,
      "y": -8,
      "z": 0,
      "name": "Rock_Stone"
    },
    {
      "x": -2,
      "y": -7,
      "z": 0,
      "name": "Rock_Stone"
    },
    {
      "x": -2,
      "y": -6,
      "z": 0,
      "name": "Empty"
    },
    {
      "x": -2,
      "y": -5,
      "z": 0,
      "name": "Plant_Crop_Mushroom_Block_Green_Mycelium",
      "rotation": 8
    },
    {
      "x": -2,
      "y": -4,
      "z": 0,
      "name": "Plant_Crop_Mushroom_Block_Green"
    },
    {
      "x": -2,
      "y": -3,
      "z": 0,
      "name": "Rock_Quartzite_Brick_Smooth"
    },
    {
      "x": -2,
      "y": -2,
      "z": 0,
      "name": "Rock_Quartzite_Brick_Smooth"
    },
    {
      "x": -2,
      "y": -1,
      "z": 0,
      "name": "Rock_Quartzite_Brick_Smooth"
    },
    {
      "x": -2,
      "y": -16,
      "z": 1,
      "name": "Rock_Stone"
    },
    {
      "x": -2,
      "y": -15,
      "z": 1,
      "name": "Rock_Stone"
    },
    {
      "x": -2,
      "y": -14,
      "z": 1,
      "name": "Rock_Stone"
    },
    {
      "x": -2,
      "y": -13,
      "z": 1,
      "name": "Rock_Stone"
    },
    {
      "x": -2,
      "y": -12,
      "z": 1,
      "name": "Soil_Mud_Dry"
    },
    {
      "x": -2,
      "y": -11,
      "z": 1,
      "name": "Soil_Mud_Dry"
    },
    {
      "x": -2,
      "y": -10,
      "z": 1,
      "name": "Soil_Mud_Dry"
    },
    {
      "x": -2,
      "y": -9,
      "z": 1,
      "name": "Empty"
    },
    {
      "x": -2,
      "y": -8,
      "z": 1,
      "name": "Plant_Moss_Wall_Green",
      "rotation": 2
    },
    {
      "x": -2,
      "y": -7,
      "z": 1,
      "name": "Empty"
    },
    {
      "x": -2,
      "y": -6,
      "z": 1,
      "name": "Empty"
    },
    {
      "x": -2,
      "y": -5,
      "z": 1,
      "name": "Empty"
    },
    {
      "x": -2,
      "y": -4,
      "z": 1,
      "name": "Empty"
    },
    {
      "x": -2,
      "y": -3,
      "z": 1,
      "name": "Empty"
    },
    {
      "x": -2,
      "y": -2,
      "z": 1,
      "name": "Empty"
    },
    {
      "x": -2,
      "y": -1,
      "z": 1,
      "name": "Empty"
    },
    {
      "x": -2,
      "y": -16,
      "z": 2,
      "name": "Rock_Stone"
    },
    {
      "x": -2,
      "y": -15,
      "z": 2,
      "name": "Rock_Stone"
    },
    {
      "x": -2,
      "y": -14,
      "z": 2,
      "name": "Rock_Stone"
    },
    {
      "x": -2,
      "y": -13,
      "z": 2,
      "name": "Soil_Mud_Dry"
    },
    {
      "x": -2,
      "y": -12,
      "z": 2,
      "name": "Soil_Mud_Dry"
    },
    {
      "x": -2,
      "y": -11,
      "z": 2,
      "name": "Soil_Mud_Dry"
    },
    {
      "x": -2,
      "y": -10,
      "z": 2,
      "name": "Soil_Mud_Dry"
    },
    {
      "x": -2,
      "y": -9,
      "z": 2,
      "name": "Soil_Mud_Dry"
    },
    {
      "x": -2,
      "y": -8,
      "z": 2,
      "name": "Rock_Stone_Mossy"
    },
    {
      "x": -2,
      "y": -7,
      "z": 2,
      "name": "Plant_Moss_Wall_Green",
      "rotation": 1
    },
    {
      "x": -2,
      "y": -6,
      "z": 2,
      "name": "Plant_Moss_Wall_Green",
      "rotation": 1
    },
    {
      "x": -2,
      "y": -5,
      "z": 2,
      "name": "Empty"
    },
    {
      "x": -2,
      "y": -4,
      "z": 2,
      "name": "Empty"
    },
    {
      "x": -2,
      "y": -3,
      "z": 2,
      "name": "Empty"
    },
    {
      "x": -2,
      "y": -2,
      "z": 2,
      "name": "Empty"
    },
    {
      "x": -2,
      "y": -1,
      "z": 2,
      "name": "Empty"
    },
    {
      "x": -2,
      "y": -16,
      "z": 3,
      "name": "Rock_Stone"
    },
    {
      "x": -2,
      "y": -15,
      "z": 3,
      "name": "Rock_Stone"
    },
    {
      "x": -2,
      "y": -14,
      "z": 3,
      "name": "Soil_Mud_Dry"
    },
    {
      "x": -2,
      "y": -13,
      "z": 3,
      "name": "Soil_Mud_Dry"
    },
    {
      "x": -2,
      "y": -12,
      "z": 3,
      "name": "Soil_Mud_Dry"
    },
    {
      "x": -2,
      "y": -11,
      "z": 3,
      "name": "Soil_Mud_Dry"
    },
    {
      "x": -2,
      "y": -10,
      "z": 3,
      "name": "Soil_Mud_Dry"
    },
    {
      "x": -2,
      "y": -9,
      "z": 3,
      "name": "Soil_Mud_Dry"
    },
    {
      "x": -2,
      "y": -8,
      "z": 3,
      "name": "Rock_Stone_Mossy"
    },
    {
      "x": -2,
      "y": -7,
      "z": 3,
      "name": "Plant_Moss_Block_Green"
    },
    {
      "x": -2,
      "y": -6,
      "z": 3,
      "name": "Plant_Moss_Wall_Green",
      "rotation": 1
    },
    {
      "x": -2,
      "y": -5,
      "z": 3,
      "name": "Empty"
    },
    {
      "x": -2,
      "y": -4,
      "z": 3,
      "name": "Empty"
    },
    {
      "x": -2,
      "y": -3,
      "z": 3,
      "name": "Empty"
    },
    {
      "x": -2,
      "y": -2,
      "z": 3,
      "name": "Plant_Moss_Wall_Green",
      "rotation": 2
    },
    {
      "x": -2,
      "y": -1,
      "z": 3,
      "name": "Empty"
    },
    {
      "x": -2,
      "y": -16,
      "z": 4,
      "name": "Rock_Stone"
    },
    {
      "x": -2,
      "y": -15,
      "z": 4,
      "name": "Rock_Stone"
    },
    {
      "x": -2,
      "y": -14,
      "z": 4,
      "name": "Rock_Stone"
    },
    {
      "x": -2,
      "y": -13,
      "z": 4,
      "name": "Rock_Stone"
    },
    {
      "x": -2,
      "y": -12,
      "z": 4,
      "name": "Soil_Mud_Dry"
    },
    {
      "x": -2,
      "y": -11,
      "z": 4,
      "name": "Soil_Mud_Dry"
    },
    {
      "x": -2,
      "y": -10,
      "z": 4,
      "name": "Soil_Mud_Dry"
    },
    {
      "x": -2,
      "y": -9,
      "z": 4,
      "name": "Rock_Stone_Mossy"
    },
    {
      "x": -2,
      "y": -8,
      "z": 4,
      "name": "Plant_Moss_Block_Green"
    },
    {
      "x": -2,
      "y": -7,
      "z": 4,
      "name": "Plant_Moss_Block_Green"
    },
    {
      "x": -2,
      "y": -6,
      "z": 4,
      "name": "Plant_Moss_Block_Green"
    },
    {
      "x": -2,
      "y": -5,
      "z": 4,
      "name": "Empty"
    },
    {
      "x": -2,
      "y": -4,
      "z": 4,
      "name": "Empty"
    },
    {
      "x": -2,
      "y": -3,
      "z": 4,
      "name": "Soil_Pathway_Half",
      "rotation": 8
    },
    {
      "x": -2,
      "y": -2,
      "z": 4,
      "name": "Soil_Pathway"
    },
    {
      "x": -2,
      "y": -1,
      "z": 4,
      "name": "Soil_Pathway_Half"
    },
    {
      "x": -2,
      "y": -16,
      "z": 5,
      "name": "Rock_Stone"
    },
    {
      "x": -2,
      "y": -15,
      "z": 5,
      "name": "Rock_Stone"
    },
    {
      "x": -2,
      "y": -14,
      "z": 5,
      "name": "Rock_Stone"
    },
    {
      "x": -2,
      "y": -13,
      "z": 5,
      "name": "Rock_Stone"
    },
    {
      "x": -2,
      "y": -12,
      "z": 5,
      "name": "Rock_Stone"
    },
    {
      "x": -2,
      "y": -11,
      "z": 5,
      "name": "Rock_Stone"
    },
    {
      "x": -2,
      "y": -10,
      "z": 5,
      "name": "Rock_Stone"
    },
    {
      "x": -2,
      "y": -9,
      "z": 5,
      "name": "Rock_Stone_Mossy"
    },
    {
      "x": -2,
      "y": -8,
      "z": 5,
      "name": "Plant_Moss_Block_Green"
    },
    {
      "x": -2,
      "y": -7,
      "z": 5,
      "name": "Plant_Moss_Block_Green"
    },
    {
      "x": -2,
      "y": -6,
      "z": 5,
      "name": "Plant_Moss_Block_Green"
    },
    {
      "x": -2,
      "y": -5,
      "z": 5,
      "name": "Plant_Moss_Block_Green"
    },
    {
      "x": -2,
      "y": -4,
      "z": 5,
      "name": "Empty"
    },
    {
      "x": -2,
      "y": -3,
      "z": 5,
      "name": "Soil_Mud_Dry"
    },
    {
      "x": -2,
      "y": -2,
      "z": 5,
      "name": "Soil_Pathway"
    },
    {
      "x": -2,
      "y": -1,
      "z": 5,
      "name": "Soil_Pathway"
    },
    {
      "x": -2,
      "y": -16,
      "z": 6,
      "name": "Rock_Stone"
    },
    {
      "x": -2,
      "y": -15,
      "z": 6,
      "name": "Rock_Stone"
    },
    {
      "x": -2,
      "y": -14,
      "z": 6,
      "name": "Rock_Stone"
    },
    {
      "x": -2,
      "y": -13,
      "z": 6,
      "name": "Rock_Stone"
    },
    {
      "x": -2,
      "y": -12,
      "z": 6,
      "name": "Rock_Stone"
    },
    {
      "x": -2,
      "y": -11,
      "z": 6,
      "name": "Rock_Stone"
    },
    {
      "x": -2,
      "y": -10,
      "z": 6,
      "name": "Rock_Stone"
    },
    {
      "x": -2,
      "y": -9,
      "z": 6,
      "name": "Rock_Stone_Mossy"
    },
    {
      "x": -2,
      "y": -8,
      "z": 6,
      "name": "Rock_Stone_Mossy"
    },
    {
      "x": -2,
      "y": -7,
      "z": 6,
      "name": "Rock_Stone_Mossy"
    },
    {
      "x": -2,
      "y": -6,
      "z": 6,
      "name": "Rock_Stone_Mossy"
    },
    {
      "x": -2,
      "y": -5,
      "z": 6,
      "name": "Plant_Moss_Block_Green"
    },
    {
      "x": -2,
      "y": -4,
      "z": 6,
      "name": "Plant_Moss_Block_Green"
    },
    {
      "x": -2,
      "y": -3,
      "z": 6,
      "name": "Rock_Quartzite"
    },
    {
      "x": -2,
      "y": -2,
      "z": 6,
      "name": "Rock_Quartzite"
    },
    {
      "x": -2,
      "y": -1,
      "z": 6,
      "name": "Soil_Dirt"
    },
    {
      "x": -2,
      "y": -16,
      "z": 7,
      "name": "Rock_Stone"
    },
    {
      "x": -2,
      "y": -15,
      "z": 7,
      "name": "Rock_Stone"
    },
    {
      "x": -2,
      "y": -14,
      "z": 7,
      "name": "Rock_Stone"
    },
    {
      "x": -2,
      "y": -13,
      "z": 7,
      "name": "Rock_Stone"
    },
    {
      "x": -2,
      "y": -12,
      "z": 7,
      "name": "Rock_Stone"
    },
    {
      "x": -2,
      "y": -11,
      "z": 7,
      "name": "Rock_Stone"
    },
    {
      "x": -2,
      "y": -10,
      "z": 7,
      "name": "Rock_Stone"
    },
    {
      "x": -2,
      "y": -9,
      "z": 7,
      "name": "Rock_Stone_Mossy"
    },
    {
      "x": -2,
      "y": -8,
      "z": 7,
      "name": "Rock_Stone_Mossy"
    },
    {
      "x": -2,
      "y": -7,
      "z": 7,
      "name": "Plant_Moss_Block_Green"
    },
    {
      "x": -2,
      "y": -6,
      "z": 7,
      "name": "Plant_Moss_Block_Green"
    },
    {
      "x": -2,
      "y": -5,
      "z": 7,
      "name": "Plant_Moss_Block_Green"
    },
    {
      "x": -2,
      "y": -4,
      "z": 7,
      "name": "Plant_Moss_Block_Green"
    },
    {
      "x": -2,
      "y": -3,
      "z": 7,
      "name": "Rock_Stone"
    },
    {
      "x": -2,
      "y": -2,
      "z": 7,
      "name": "Rock_Stone"
    },
    {
      "x": -2,
      "y": -1,
      "z": 7,
      "name": "Rock_Stone"
    },
    {
      "x": -1,
      "y": -16,
      "z": -5,
      "name": "Rock_Stone"
    },
    {
      "x": -1,
      "y": -15,
      "z": -5,
      "name": "Rock_Stone"
    },
    {
      "x": -1,
      "y": -14,
      "z": -5,
      "name": "Rock_Stone"
    },
    {
      "x": -1,
      "y": -13,
      "z": -5,
      "name": "Rock_Stone"
    },
    {
      "x": -1,
      "y": -12,
      "z": -5,
      "name": "Rock_Stone"
    },
    {
      "x": -1,
      "y": -11,
      "z": -5,
      "name": "Rock_Stone"
    },
    {
      "x": -1,
      "y": -10,
      "z": -5,
      "name": "Rock_Stone"
    },
    {
      "x": -1,
      "y": -9,
      "z": -5,
      "name": "Rock_Stone"
    },
    {
      "x": -1,
      "y": -8,
      "z": -5,
      "name": "Rock_Stone"
    },
    {
      "x": -1,
      "y": -7,
      "z": -5,
      "name": "Rock_Stone"
    },
    {
      "x": -1,
      "y": -6,
      "z": -5,
      "name": "Rock_Stone"
    },
    {
      "x": -1,
      "y": -5,
      "z": -5,
      "name": "Rock_Stone"
    },
    {
      "x": -1,
      "y": -4,
      "z": -5,
      "name": "Rock_Stone"
    },
    {
      "x": -1,
      "y": -16,
      "z": -4,
      "name": "Rock_Stone"
    },
    {
      "x": -1,
      "y": -15,
      "z": -4,
      "name": "Rock_Stone"
    },
    {
      "x": -1,
      "y": -14,
      "z": -4,
      "name": "Rock_Stone"
    },
    {
      "x": -1,
      "y": -13,
      "z": -4,
      "name": "Rock_Stone"
    },
    {
      "x": -1,
      "y": -12,
      "z": -4,
      "name": "Rock_Stone"
    },
    {
      "x": -1,
      "y": -11,
      "z": -4,
      "name": "Rock_Stone"
    },
    {
      "x": -1,
      "y": -10,
      "z": -4,
      "name": "Rock_Stone"
    },
    {
      "x": -1,
      "y": -9,
      "z": -4,
      "name": "Rock_Stone"
    },
    {
      "x": -1,
      "y": -8,
      "z": -4,
      "name": "Rock_Stone"
    },
    {
      "x": -1,
      "y": -7,
      "z": -4,
      "name": "Rock_Stone"
    },
    {
      "x": -1,
      "y": -6,
      "z": -4,
      "name": "Rock_Stone"
    },
    {
      "x": -1,
      "y": -5,
      "z": -4,
      "name": "Rock_Stone"
    },
    {
      "x": -1,
      "y": -4,
      "z": -4,
      "name": "Rock_Stone"
    },
    {
      "x": -1,
      "y": -16,
      "z": -3,
      "name": "Rock_Stone"
    },
    {
      "x": -1,
      "y": -15,
      "z": -3,
      "name": "Rock_Stone"
    },
    {
      "x": -1,
      "y": -14,
      "z": -3,
      "name": "Rock_Stone"
    },
    {
      "x": -1,
      "y": -13,
      "z": -3,
      "name": "Rock_Stone"
    },
    {
      "x": -1,
      "y": -12,
      "z": -3,
      "name": "Rock_Stone"
    },
    {
      "x": -1,
      "y": -11,
      "z": -3,
      "name": "Rock_Stone"
    },
    {
      "x": -1,
      "y": -10,
      "z": -3,
      "name": "Rock_Stone"
    },
    {
      "x": -1,
      "y": -9,
      "z": -3,
      "name": "Rock_Stone"
    },
    {
      "x": -1,
      "y": -8,
      "z": -3,
      "name": "Rock_Stone"
    },
    {
      "x": -1,
      "y": -7,
      "z": -3,
      "name": "Rock_Stone"
    },
    {
      "x": -1,
      "y": -6,
      "z": -3,
      "name": "Rock_Stone"
    },
    {
      "x": -1,
      "y": -5,
      "z": -3,
      "name": "Rock_Stone"
    },
    {
      "x": -1,
      "y": -4,
      "z": -3,
      "name": "Rock_Stone"
    },
    {
      "x": -1,
      "y": -16,
      "z": -2,
      "name": "Rock_Stone"
    },
    {
      "x": -1,
      "y": -15,
      "z": -2,
      "name": "Rock_Stone"
    },
    {
      "x": -1,
      "y": -14,
      "z": -2,
      "name": "Rock_Stone"
    },
    {
      "x": -1,
      "y": -13,
      "z": -2,
      "name": "Rock_Stone"
    },
    {
      "x": -1,
      "y": -12,
      "z": -2,
      "name": "Soil_Mud_Dry"
    },
    {
      "x": -1,
      "y": -11,
      "z": -2,
      "name": "Soil_Mud_Dry"
    },
    {
      "x": -1,
      "y": -10,
      "z": -2,
      "name": "Soil_Mud_Dry"
    },
    {
      "x": -1,
      "y": -9,
      "z": -2,
      "name": "Soil_Mud_Dry"
    },
    {
      "x": -1,
      "y": -8,
      "z": -2,
      "name": "Plant_Crop_Mushroom_Block_Green_Trunk"
    },
    {
      "x": -1,
      "y": -7,
      "z": -2,
      "name": "Plant_Crop_Mushroom_Block_Green_Trunk"
    },
    {
      "x": -1,
      "y": -6,
      "z": -2,
      "name": "Plant_Crop_Mushroom_Block_Green_Trunk"
    },
    {
      "x": -1,
      "y": -5,
      "z": -2,
      "name": "Rock_Stone"
    },
    {
      "x": -1,
      "y": -4,
      "z": -2,
      "name": "Rock_Stone"
    },
    {
      "x": -1,
      "y": -16,
      "z": -1,
      "name": "Rock_Stone"
    },
    {
      "x": -1,
      "y": -15,
      "z": -1,
      "name": "Rock_Stone"
    },
    {
      "x": -1,
      "y": -14,
      "z": -1,
      "name": "Rock_Stone"
    },
    {
      "x": -1,
      "y": -13,
      "z": -1,
      "name": "Soil_Mud_Dry"
    },
    {
      "x": -1,
      "y": -12,
      "z": -1,
      "name": "Soil_Mud_Dry"
    },
    {
      "x": -1,
      "y": -11,
      "z": -1,
      "name": "Soil_Mud_Dry"
    },
    {
      "x": -1,
      "y": -10,
      "z": -1,
      "name": "Soil_Mud_Dry"
    },
    {
      "x": -1,
      "y": -9,
      "z": -1,
      "name": "Soil_Mud_Dry"
    },
    {
      "x": -1,
      "y": -8,
      "z": -1,
      "name": "Empty"
    },
    {
      "x": -1,
      "y": -7,
      "z": -1,
      "name": "Empty"
    },
    {
      "x": -1,
      "y": -6,
      "z": -1,
      "name": "Plant_Crop_Mushroom_Block_Green_Trunk"
    },
    {
      "x": -1,
      "y": -5,
      "z": -1,
      "name": "Plant_Crop_Mushroom_Block_Green_Trunk"
    },
    {
      "x": -1,
      "y": -4,
      "z": -1,
      "name": "Plant_Crop_Mushroom_Block_Green"
    },
    {
      "x": -1,
      "y": -3,
      "z": -1,
      "name": "Rock_Quartzite_Brick_Smooth"
    },
    {
      "x": -1,
      "y": -2,
      "z": -1,
      "name": "Rock_Quartzite_Brick_Smooth"
    },
    {
      "x": -1,
      "y": -1,
      "z": -1,
      "name": "Rock_Quartzite_Brick_Smooth"
    },
    {
      "x": -1,
      "y": -16,
      "z": 0,
      "name": "Rock_Stone"
    },
    {
      "x": -1,
      "y": -15,
      "z": 0,
      "name": "Rock_Stone"
    },
    {
      "x": -1,
      "y": -14,
      "z": 0,
      "name": "Rock_Stone"
    },
    {
      "x": -1,
      "y": -13,
      "z": 0,
      "name": "Soil_Mud_Dry"
    },
    {
      "x": -1,
      "y": -12,
      "z": 0,
      "name": "Soil_Mud_Dry"
    },
    {
      "x": -1,
      "y": -11,
      "z": 0,
      "name": "Soil_Mud_Dry"
    },
    {
      "x": -1,
      "y": -10,
      "z": 0,
      "name": "Soil_Mud_Dry"
    },
    {
      "x": -1,
      "y": -9,
      "z": 0,
      "name": "Plant_Moss_Rug_Green"
    },
    {
      "x": -1,
      "y": -8,
      "z": 0,
      "name": "Empty"
    },
    {
      "x": -1,
      "y": -7,
      "z": 0,
      "name": "Empty"
    },
    {
      "x": -1,
      "y": -6,
      "z": 0,
      "name": "Empty"
    },
    {
      "x": -1,
      "y": -5,
      "z": 0,
      "name": "Plant_Crop_Mushroom_Block_Green_Mycelium",
      "rotation": 8
    },
    {
      "x": -1,
      "y": -4,
      "z": 0,
      "name": "Plant_Crop_Mushroom_Block_Green"
    },
    {
      "x": -1,
      "y": -3,
      "z": 0,
      "name": "Empty"
    },
    {
      "x": -1,
      "y": -2,
      "z": 0,
      "name": "Soil_Mud_Dry"
    },
    {
      "x": -1,
      "y": -1,
      "z": 0,
      "name": "Soil_Dirt"
    },
    {
      "x": -1,
      "y": -16,
      "z": 1,
      "name": "Rock_Stone"
    },
    {
      "x": -1,
      "y": -15,
      "z": 1,
      "name": "Rock_Stone"
    },
    {
      "x": -1,
      "y": -14,
      "z": 1,
      "name": "Rock_Stone"
    },
    {
      "x": -1,
      "y": -13,
      "z": 1,
      "name": "Soil_Mud_Dry"
    },
    {
      "x": -1,
      "y": -12,
      "z": 1,
      "name": "Plant_Moss_Wall_Green",
      "rotation": 1
    },
    {
      "x": -1,
      "y": -11,
      "z": 1,
      "name": "Plant_Moss_Wall_Green",
      "rotation": 1
    },
    {
      "x": -1,
      "y": -10,
      "z": 1,
      "name": "Plant_Moss_Wall_Green",
      "rotation": 1
    },
    {
      "x": -1,
      "y": -9,
      "z": 1,
      "name": "Empty"
    },
    {
      "x": -1,
      "y": -8,
      "z": 1,
      "name": "Empty"
    },
    {
      "x": -1,
      "y": -7,
      "z": 1,
      "name": "Empty"
    },
    {
      "x": -1,
      "y": -6,
      "z": 1,
      "name": "Empty"
    },
    {
      "x": -1,
      "y": -5,
      "z": 1,
      "name": "Empty"
    },
    {
      "x": -1,
      "y": -4,
      "z": 1,
      "name": "Empty"
    },
    {
      "x": -1,
      "y": -3,
      "z": 1,
      "name": "Empty"
    },
    {
      "x": -1,
      "y": -2,
      "z": 1,
      "name": "Empty"
    },
    {
      "x": -1,
      "y": -1,
      "z": 1,
      "name": "Empty"
    },
    {
      "x": -1,
      "y": -16,
      "z": 2,
      "name": "Rock_Stone"
    },
    {
      "x": -1,
      "y": -15,
      "z": 2,
      "name": "Rock_Stone"
    },
    {
      "x": -1,
      "y": -14,
      "z": 2,
      "name": "Soil_Mud_Dry"
    },
    {
      "x": -1,
      "y": -13,
      "z": 2,
      "name": "Plant_Moss_Wall_Green",
      "rotation": 1
    },
    {
      "x": -1,
      "y": -12,
      "z": 2,
      "name": "Plant_Moss_Wall_Green",
      "rotation": 1
    },
    {
      "x": -1,
      "y": -11,
      "z": 2,
      "name": "Plant_Moss_Wall_Green",
      "rotation": 1
    },
    {
      "x": -1,
      "y": -10,
      "z": 2,
      "name": "Empty"
    },
    {
      "x": -1,
      "y": -9,
      "z": 2,
      "name": "Plant_Moss_Wall_Green",
      "rotation": 1
    },
    {
      "x": -1,
      "y": -8,
      "z": 2,
      "name": "Plant_Moss_Wall_Green",
      "rotation": 1
    },
    {
      "x": -1,
      "y": -7,
      "z": 2,
      "name": "Empty"
    },
    {
      "x": -1,
      "y": -6,
      "z": 2,
      "name": "Empty"
    },
    {
      "x": -1,
      "y": -5,
      "z": 2,
      "name": "Empty"
    },
    {
      "x": -1,
      "y": -4,
      "z": 2,
      "name": "Empty"
    },
    {
      "x": -1,
      "y": -3,
      "z": 2,
      "name": "Empty"
    },
    {
      "x": -1,
      "y": -2,
      "z": 2,
      "name": "Empty"
    },
    {
      "x": -1,
      "y": -1,
      "z": 2,
      "name": "Empty"
    },
    {
      "x": -1,
      "y": -16,
      "z": 3,
      "name": "Rock_Stone"
    },
    {
      "x": -1,
      "y": -15,
      "z": 3,
      "name": "Rock_Stone"
    },
    {
      "x": -1,
      "y": -14,
      "z": 3,
      "name": "Soil_Mud_Dry"
    },
    {
      "x": -1,
      "y": -13,
      "z": 3,
      "name": "Soil_Mud_Dry"
    },
    {
      "x": -1,
      "y": -12,
      "z": 3,
      "name": "Soil_Mud_Dry"
    },
    {
      "x": -1,
      "y": -11,
      "z": 3,
      "name": "Survival_Trap_Spike_Wood"
    },
    {
      "x": -1,
      "y": -10,
      "z": 3,
      "name": "Empty"
    },
    {
      "x": -1,
      "y": -9,
      "z": 3,
      "name": "Empty"
    },
    {
      "x": -1,
      "y": -8,
      "z": 3,
      "name": "Empty"
    },
    {
      "x": -1,
      "y": -7,
      "z": 3,
      "name": "Empty"
    },
    {
      "x": -1,
      "y": -6,
      "z": 3,
      "name": "Empty"
    },
    {
      "x": -1,
      "y": -5,
      "z": 3,
      "name": "Empty"
    },
    {
      "x": -1,
      "y": -4,
      "z": 3,
      "name": "Empty"
    },
    {
      "x": -1,
      "y": -3,
      "z": 3,
      "name": "Empty"
    },
    {
      "x": -1,
      "y": -2,
      "z": 3,
      "name": "Empty"
    },
    {
      "x": -1,
      "y": -1,
      "z": 3,
      "name": "Empty"
    },
    {
      "x": -1,
      "y": -16,
      "z": 4,
      "name": "Rock_Stone"
    },
    {
      "x": -1,
      "y": -15,
      "z": 4,
      "name": "Rock_Stone"
    },
    {
      "x": -1,
      "y": -14,
      "z": 4,
      "name": "Rock_Stone"
    },
    {
      "x": -1,
      "y": -13,
      "z": 4,
      "name": "Soil_Mud_Dry"
    },
    {
      "x": -1,
      "y": -12,
      "z": 4,
      "name": "Soil_Mud_Dry"
    },
    {
      "x": -1,
      "y": -11,
      "z": 4,
      "name": "Soil_Mud_Dry"
    },
    {
      "x": -1,
      "y": -10,
      "z": 4,
      "name": "Rock_Stone"
    },
    {
      "x": -1,
      "y": -9,
      "z": 4,
      "name": "Rock_Stone_Mossy"
    },
    {
      "x": -1,
      "y": -8,
      "z": 4,
      "name": "Plant_Moss_Block_Green"
    },
    {
      "x": -1,
      "y": -7,
      "z": 4,
      "name": "Empty"
    },
    {
      "x": -1,
      "y": -6,
      "z": 4,
      "name": "Empty"
    },
    {
      "x": -1,
      "y": -5,
      "z": 4,
      "name": "Empty"
    },
    {
      "x": -1,
      "y": -4,
      "z": 4,
      "name": "Empty"
    },
    {
      "x": -1,
      "y": -3,
      "z": 4,
      "name": "Empty"
    },
    {
      "x": -1,
      "y": -2,
      "z": 4,
      "name": "Plant_Moss_Wall_Green",
      "rotation": 1
    },
    {
      "x": -1,
      "y": -1,
      "z": 4,
      "name": "Empty"
    },
    {
      "x": -1,
      "y": -16,
      "z": 5,
      "name": "Rock_Stone"
    },
    {
      "x": -1,
      "y": -15,
      "z": 5,
      "name": "Rock_Stone"
    },
    {
      "x": -1,
      "y": -14,
      "z": 5,
      "name": "Rock_Stone"
    },
    {
      "x": -1,
      "y": -13,
      "z": 5,
      "name": "Soil_Mud_Dry"
    },
    {
      "x": -1,
      "y": -12,
      "z": 5,
      "name": "Soil_Mud_Dry"
    },
    {
      "x": -1,
      "y": -11,
      "z": 5,
      "name": "Rock_Stone"
    },
    {
      "x": -1,
      "y": -10,
      "z": 5,
      "name": "Rock_Stone"
    },
    {
      "x": -1,
      "y": -9,
      "z": 5,
      "name": "Rock_Stone_Mossy"
    },
    {
      "x": -1,
      "y": -8,
      "z": 5,
      "name": "Plant_Moss_Block_Green"
    },
    {
      "x": -1,
      "y": -7,
      "z": 5,
      "name": "Plant_Moss_Block_Green"
    },
    {
      "x": -1,
      "y": -6,
      "z": 5,
      "name": "Plant_Moss_Block_Green"
    },
    {
      "x": -1,
      "y": -5,
      "z": 5,
      "name": "Plant_Moss_Block_Green"
    },
    {
      "x": -1,
      "y": -4,
      "z": 5,
      "name": "Empty"
    },
    {
      "x": -1,
      "y": -3,
      "z": 5,
      "name": "Soil_Mud_Dry"
    },
    {
      "x": -1,
      "y": -2,
      "z": 5,
      "name": "Soil_Pathway"
    },
    {
      "x": -1,
      "y": -1,
      "z": 5,
      "name": "Soil_Pathway"
    },
    {
      "x": -1,
      "y": -16,
      "z": 6,
      "name": "Rock_Stone"
    },
    {
      "x": -1,
      "y": -15,
      "z": 6,
      "name": "Rock_Stone"
    },
    {
      "x": -1,
      "y": -14,
      "z": 6,
      "name": "Rock_Stone"
    },
    {
      "x": -1,
      "y": -13,
      "z": 6,
      "name": "Soil_Mud_Dry"
    },
    {
      "x": -1,
      "y": -12,
      "z": 6,
      "name": "Soil_Mud_Dry"
    },
    {
      "x": -1,
      "y": -11,
      "z": 6,
      "name": "Rock_Stone"
    },
    {
      "x": -1,
      "y": -10,
      "z": 6,
      "name": "Rock_Stone"
    },
    {
      "x": -1,
      "y": -9,
      "z": 6,
      "name": "Rock_Stone_Mossy"
    },
    {
      "x": -1,
      "y": -8,
      "z": 6,
      "name": "Plant_Moss_Block_Green"
    },
    {
      "x": -1,
      "y": -7,
      "z": 6,
      "name": "Rock_Stone_Mossy"
    },
    {
      "x": -1,
      "y": -6,
      "z": 6,
      "name": "Rock_Stone_Mossy"
    },
    {
      "x": -1,
      "y": -5,
      "z": 6,
      "name": "Plant_Moss_Block_Green"
    },
    {
      "x": -1,
      "y": -4,
      "z": 6,
      "name": "Plant_Moss_Block_Green"
    },
    {
      "x": -1,
      "y": -3,
      "z": 6,
      "name": "Rock_Quartzite"
    },
    {
      "x": -1,
      "y": -2,
      "z": 6,
      "name": "Rock_Quartzite"
    },
    {
      "x": -1,
      "y": -1,
      "z": 6,
      "name": "Soil_Pathway"
    },
    {
      "x": -1,
      "y": -16,
      "z": 7,
      "name": "Rock_Stone"
    },
    {
      "x": -1,
      "y": -15,
      "z": 7,
      "name": "Rock_Stone"
    },
    {
      "x": -1,
      "y": -14,
      "z": 7,
      "name": "Rock_Stone"
    },
    {
      "x": -1,
      "y": -13,
      "z": 7,
      "name": "Rock_Stone"
    },
    {
      "x": -1,
      "y": -12,
      "z": 7,
      "name": "Soil_Mud_Dry"
    },
    {
      "x": -1,
      "y": -11,
      "z": 7,
      "name": "Rock_Stone"
    },
    {
      "x": -1,
      "y": -10,
      "z": 7,
      "name": "Rock_Stone"
    },
    {
      "x": -1,
      "y": -9,
      "z": 7,
      "name": "Rock_Stone_Mossy"
    },
    {
      "x": -1,
      "y": -8,
      "z": 7,
      "name": "Rock_Stone_Mossy"
    },
    {
      "x": -1,
      "y": -7,
      "z": 7,
      "name": "Plant_Moss_Block_Green"
    },
    {
      "x": -1,
      "y": -6,
      "z": 7,
      "name": "Plant_Moss_Block_Green"
    },
    {
      "x": -1,
      "y": -5,
      "z": 7,
      "name": "Plant_Moss_Block_Green"
    },
    {
      "x": -1,
      "y": -4,
      "z": 7,
      "name": "Plant_Moss_Block_Green"
    },
    {
      "x": -1,
      "y": -3,
      "z": 7,
      "name": "Rock_Stone"
    },
    {
      "x": -1,
      "y": -2,
      "z": 7,
      "name": "Rock_Stone"
    },
    {
      "x": -1,
      "y": -1,
      "z": 7,
      "name": "Rock_Stone"
    },
    {
      "x": 0,
      "y": -16,
      "z": -5,
      "name": "Rock_Stone"
    },
    {
      "x": 0,
      "y": -15,
      "z": -5,
      "name": "Rock_Stone"
    },
    {
      "x": 0,
      "y": -14,
      "z": -5,
      "name": "Rock_Stone"
    },
    {
      "x": 0,
      "y": -13,
      "z": -5,
      "name": "Rock_Stone"
    },
    {
      "x": 0,
      "y": -12,
      "z": -5,
      "name": "Rock_Stone"
    },
    {
      "x": 0,
      "y": -11,
      "z": -5,
      "name": "Rock_Stone"
    },
    {
      "x": 0,
      "y": -10,
      "z": -5,
      "name": "Rock_Stone"
    },
    {
      "x": 0,
      "y": -9,
      "z": -5,
      "name": "Rock_Stone"
    },
    {
      "x": 0,
      "y": -8,
      "z": -5,
      "name": "Rock_Stone"
    },
    {
      "x": 0,
      "y": -7,
      "z": -5,
      "name": "Rock_Stone"
    },
    {
      "x": 0,
      "y": -6,
      "z": -5,
      "name": "Rock_Stone"
    },
    {
      "x": 0,
      "y": -5,
      "z": -5,
      "name": "Rock_Stone"
    },
    {
      "x": 0,
      "y": -4,
      "z": -5,
      "name": "Rock_Stone"
    },
    {
      "x": 0,
      "y": -16,
      "z": -4,
      "name": "Rock_Stone"
    },
    {
      "x": 0,
      "y": -15,
      "z": -4,
      "name": "Rock_Stone"
    },
    {
      "x": 0,
      "y": -14,
      "z": -4,
      "name": "Rock_Stone"
    },
    {
      "x": 0,
      "y": -13,
      "z": -4,
      "name": "Rock_Stone"
    },
    {
      "x": 0,
      "y": -12,
      "z": -4,
      "name": "Rock_Stone"
    },
    {
      "x": 0,
      "y": -11,
      "z": -4,
      "name": "Rock_Stone"
    },
    {
      "x": 0,
      "y": -10,
      "z": -4,
      "name": "Rock_Stone"
    },
    {
      "x": 0,
      "y": -9,
      "z": -4,
      "name": "Rock_Stone"
    },
    {
      "x": 0,
      "y": -8,
      "z": -4,
      "name": "Rock_Stone"
    },
    {
      "x": 0,
      "y": -7,
      "z": -4,
      "name": "Rock_Stone"
    },
    {
      "x": 0,
      "y": -6,
      "z": -4,
      "name": "Rock_Stone"
    },
    {
      "x": 0,
      "y": -5,
      "z": -4,
      "name": "Rock_Stone"
    },
    {
      "x": 0,
      "y": -4,
      "z": -4,
      "name": "Rock_Stone"
    },
    {
      "x": 0,
      "y": -16,
      "z": -3,
      "name": "Rock_Stone"
    },
    {
      "x": 0,
      "y": -15,
      "z": -3,
      "name": "Rock_Stone"
    },
    {
      "x": 0,
      "y": -14,
      "z": -3,
      "name": "Rock_Stone"
    },
    {
      "x": 0,
      "y": -13,
      "z": -3,
      "name": "Rock_Stone"
    },
    {
      "x": 0,
      "y": -12,
      "z": -3,
      "name": "Rock_Stone"
    },
    {
      "x": 0,
      "y": -11,
      "z": -3,
      "name": "Rock_Stone"
    },
    {
      "x": 0,
      "y": -10,
      "z": -3,
      "name": "Rock_Stone"
    },
    {
      "x": 0,
      "y": -9,
      "z": -3,
      "name": "Rock_Stone"
    },
    {
      "x": 0,
      "y": -8,
      "z": -3,
      "name": "Rock_Stone"
    },
    {
      "x": 0,
      "y": -7,
      "z": -3,
      "name": "Rock_Stone"
    },
    {
      "x": 0,
      "y": -6,
      "z": -3,
      "name": "Rock_Stone"
    },
    {
      "x": 0,
      "y": -5,
      "z": -3,
      "name": "Rock_Stone"
    },
    {
      "x": 0,
      "y": -4,
      "z": -3,
      "name": "Rock_Stone"
    },
    {
      "x": 0,
      "y": -16,
      "z": -2,
      "name": "Rock_Stone"
    },
    {
      "x": 0,
      "y": -15,
      "z": -2,
      "name": "Rock_Stone"
    },
    {
      "x": 0,
      "y": -14,
      "z": -2,
      "name": "Rock_Stone"
    },
    {
      "x": 0,
      "y": -13,
      "z": -2,
      "name": "Soil_Mud_Dry"
    },
    {
      "x": 0,
      "y": -12,
      "z": -2,
      "name": "Soil_Mud_Dry"
    },
    {
      "x": 0,
      "y": -11,
      "z": -2,
      "name": "Soil_Mud_Dry"
    },
    {
      "x": 0,
      "y": -10,
      "z": -2,
      "name": "Soil_Mud_Dry"
    },
    {
      "x": 0,
      "y": -9,
      "z": -2,
      "name": "Soil_Mud_Dry"
    },
    {
      "x": 0,
      "y": -8,
      "z": -2,
      "name": "Rock_Stone"
    },
    {
      "x": 0,
      "y": -7,
      "z": -2,
      "name": "Rock_Stone"
    },
    {
      "x": 0,
      "y": -6,
      "z": -2,
      "name": "Rock_Stone"
    },
    {
      "x": 0,
      "y": -5,
      "z": -2,
      "name": "Rock_Stone"
    },
    {
      "x": 0,
      "y": -4,
      "z": -2,
      "name": "Rock_Stone"
    },
    {
      "x": 0,
      "y": -16,
      "z": -1,
      "name": "Rock_Stone"
    },
    {
      "x": 0,
      "y": -15,
      "z": -1,
      "name": "Rock_Stone"
    },
    {
      "x": 0,
      "y": -14,
      "z": -1,
      "name": "Rock_Stone"
    },
    {
      "x": 0,
      "y": -13,
      "z": -1,
      "name": "Soil_Mud_Dry"
    },
    {
      "x": 0,
      "y": -12,
      "z": -1,
      "name": "Soil_Mud_Dry"
    },
    {
      "x": 0,
      "y": -11,
      "z": -1,
      "name": "Plant_Moss_Rug_Green"
    },
    {
      "x": 0,
      "y": -10,
      "z": -1,
      "name": "Empty"
    },
    {
      "x": 0,
      "y": -9,
      "z": -1,
      "name": "Empty"
    },
    {
      "x": 0,
      "y": -8,
      "z": -1,
      "name": "Empty"
    },
    {
      "x": 0,
      "y": -7,
      "z": -1,
      "name": "Empty"
    },
    {
      "x": 0,
      "y": -6,
      "z": -1,
      "name": "Empty"
    },
    {
      "x": 0,
      "y": -5,
      "z": -1,
      "name": "Plant_Crop_Mushroom_Block_Green_Mycelium",
      "rotation": 8
    },
    {
      "x": 0,
      "y": -4,
      "z": -1,
      "name": "Plant_Crop_Mushroom_Block_Green"
    },
    {
      "x": 0,
      "y": -3,
      "z": -1,
      "name": "Rock_Quartzite_Brick_Smooth"
    },
    {
      "x": 0,
      "y": -2,
      "z": -1,
      "name": "Rock_Quartzite_Brick_Smooth"
    },
    {
      "x": 0,
      "y": -1,
      "z": -1,
      "name": "Rock_Quartzite_Brick_Smooth"
    },
    {
      "x": 0,
      "y": -16,
      "z": 0,
      "name": "Rock_Stone"
    },
    {
      "x": 0,
      "y": -15,
      "z": 0,
      "name": "Rock_Stone"
    },
    {
      "x": 0,
      "y": -14,
      "z": 0,
      "name": "Soil_Pathway"
    },
    {
      "x": 0,
      "y": -13,
      "z": 0,
      "name": "Survival_Trap_Spike_Wood"
    },
    {
      "x": 0,
      "y": -12,
      "z": 0,
      "name": "Plant_Moss_Wall_Green"
    },
    {
      "x": 0,
      "y": -11,
      "z": 0,
      "name": "Plant_Moss_Wall_Green",
      "rotation": 1
    },
    {
      "x": 0,
      "y": -10,
      "z": 0,
      "name": "Plant_Moss_Wall_Green",
      "rotation": 1
    },
    {
      "x": 0,
      "y": -9,
      "z": 0,
      "name": "Empty"
    },
    {
      "x": 0,
      "y": -8,
      "z": 0,
      "name": "Empty"
    },
    {
      "x": 0,
      "y": -7,
      "z": 0,
      "name": "Empty"
    },
    {
      "x": 0,
      "y": -6,
      "z": 0,
      "name": "Empty"
    },
    {
      "x": 0,
      "y": -5,
      "z": 0,
      "name": "Empty"
    },
    {
      "x": 0,
      "y": -4,
      "z": 0,
      "name": "Empty"
    },
    {
      "x": 0,
      "y": -3,
      "z": 0,
      "name": "Empty"
    },
    {
      "x": 0,
      "y": -2,
      "z": 0,
      "name": "Soil_Mud_Dry"
    },
    {
      "x": 0,
      "y": -1,
      "z": 0,
      "name": "Soil_Dirt"
    },
    {
      "x": 0,
      "y": 0,
      "z": 0,
      "name": "Soil_Dirt"
    },
    {
      "x": 0,
      "y": -16,
      "z": 1,
      "name": "Rock_Stone"
    },
    {
      "x": 0,
      "y": -15,
      "z": 1,
      "name": "Rock_Stone"
    },
    {
      "x": 0,
      "y": -14,
      "z": 1,
      "name": "Soil_Pathway"
    },
    {
      "x": 0,
      "y": -13,
      "z": 1,
      "name": "Plant_Moss_Rug_Green"
    },
    {
      "x": 0,
      "y": -12,
      "z": 1,
      "name": "Empty"
    },
    {
      "x": 0,
      "y": -11,
      "z": 1,
      "name": "Empty"
    },
    {
      "x": 0,
      "y": -10,
      "z": 1,
      "name": "Empty"
    },
    {
      "x": 0,
      "y": -9,
      "z": 1,
      "name": "Empty"
    },
    {
      "x": 0,
      "y": -8,
      "z": 1,
      "name": "Empty"
    },
    {
      "x": 0,
      "y": -7,
      "z": 1,
      "name": "Empty"
    },
    {
      "x": 0,
      "y": -6,
      "z": 1,
      "name": "Empty"
    },
    {
      "x": 0,
      "y": -5,
      "z": 1,
      "name": "Empty"
    },
    {
      "x": 0,
      "y": -4,
      "z": 1,
      "name": "Empty"
    },
    {
      "x": 0,
      "y": -3,
      "z": 1,
      "name": "Plant_Roots_Cave",
      "rotation": 10
    },
    {
      "x": 0,
      "y": -2,
      "z": 1,
      "name": "Soil_Mud_Dry"
    },
    {
      "x": 0,
      "y": -1,
      "z": 1,
      "name": "Soil_Dirt"
    },
    {
      "x": 0,
      "y": -16,
      "z": 2,
      "name": "Rock_Stone"
    },
    {
      "x": 0,
      "y": -15,
      "z": 2,
      "name": "Soil_Mud_Dry"
    },
    {
      "x": 0,
      "y": -14,
      "z": 2,
      "name": "Soil_Mud_Dry"
    },
    {
      "x": 0,
      "y": -13,
      "z": 2,
      "name": "Survival_Trap_Spike_Wood"
    },
    {
      "x": 0,
      "y": -12,
      "z": 2,
      "name": "Empty"
    },
    {
      "x": 0,
      "y": -11,
      "z": 2,
      "name": "Empty"
    },
    {
      "x": 0,
      "y": -10,
      "z": 2,
      "name": "Empty"
    },
    {
      "x": 0,
      "y": -9,
      "z": 2,
      "name": "Empty"
    },
    {
      "x": 0,
      "y": -8,
      "z": 2,
      "name": "Empty"
    },
    {
      "x": 0,
      "y": -7,
      "z": 2,
      "name": "Empty"
    },
    {
      "x": 0,
      "y": -6,
      "z": 2,
      "name": "Empty"
    },
    {
      "x": 0,
      "y": -5,
      "z": 2,
      "name": "Empty"
    },
    {
      "x": 0,
      "y": -4,
      "z": 2,
      "name": "Empty"
    },
    {
      "x": 0,
      "y": -3,
      "z": 2,
      "name": "Plant_Roots_Cave",
      "rotation": 10
    },
    {
      "x": 0,
      "y": -2,
      "z": 2,
      "name": "Soil_Mud_Dry"
    },
    {
      "x": 0,
      "y": -1,
      "z": 2,
      "name": "Soil_Pathway"
    },
    {
      "x": 0,
      "y": -16,
      "z": 3,
      "name": "Soil_Mud_Dry"
    },
    {
      "x": 0,
      "y": -15,
      "z": 3,
      "name": "Soil_Mud_Dry"
    },
    {
      "x": 0,
      "y": -14,
      "z": 3,
      "name": "Soil_Mud_Dry"
    },
    {
      "x": 0,
      "y": -13,
      "z": 3,
      "name": "Soil_Mud_Dry"
    },
    {
      "x": 0,
      "y": -12,
      "z": 3,
      "name": "Survival_Trap_Spike_Wood"
    },
    {
      "x": 0,
      "y": -11,
      "z": 3,
      "name": "Empty"
    },
    {
      "x": 0,
      "y": -10,
      "z": 3,
      "name": "Empty"
    },
    {
      "x": 0,
      "y": -9,
      "z": 3,
      "name": "Empty"
    },
    {
      "x": 0,
      "y": -8,
      "z": 3,
      "name": "Empty"
    },
    {
      "x": 0,
      "y": -7,
      "z": 3,
      "name": "Empty"
    },
    {
      "x": 0,
      "y": -6,
      "z": 3,
      "name": "Empty"
    },
    {
      "x": 0,
      "y": -5,
      "z": 3,
      "name": "Empty"
    },
    {
      "x": 0,
      "y": -4,
      "z": 3,
      "name": "Empty"
    },
    {
      "x": 0,
      "y": -3,
      "z": 3,
      "name": "Empty"
    },
    {
      "x": 0,
      "y": -2,
      "z": 3,
      "name": "Empty"
    },
    {
      "x": 0,
      "y": -1,
      "z": 3,
      "name": "Empty"
    },
    {
      "x": 0,
      "y": -16,
      "z": 4,
      "name": "Rock_Stone"
    },
    {
      "x": 0,
      "y": -15,
      "z": 4,
      "name": "Rock_Stone"
    },
    {
      "x": 0,
      "y": -14,
      "z": 4,
      "name": "Soil_Mud_Dry"
    },
    {
      "x": 0,
      "y": -13,
      "z": 4,
      "name": "Soil_Mud_Dry"
    },
    {
      "x": 0,
      "y": -12,
      "z": 4,
      "name": "Soil_Mud_Dry"
    },
    {
      "x": 0,
      "y": -11,
      "z": 4,
      "name": "Soil_Mud_Dry"
    },
    {
      "x": 0,
      "y": -10,
      "z": 4,
      "name": "Plant_Crop_Mushroom_Cap_Brown",
      "components": {
        "Components": {
          "FarmingBlock": {}
        }
      }
    },
    {
      "x": 0,
      "y": -9,
      "z": 4,
      "name": "Empty"
    },
    {
      "x": 0,
      "y": -8,
      "z": 4,
      "name": "Empty"
    },
    {
      "x": 0,
      "y": -7,
      "z": 4,
      "name": "Empty"
    },
    {
      "x": 0,
      "y": -6,
      "z": 4,
      "name": "Empty"
    },
    {
      "x": 0,
      "y": -5,
      "z": 4,
      "name": "Empty"
    },
    {
      "x": 0,
      "y": -4,
      "z": 4,
      "name": "Empty"
    },
    {
      "x": 0,
      "y": -3,
      "z": 4,
      "name": "Empty"
    },
    {
      "x": 0,
      "y": -2,
      "z": 4,
      "name": "Soil_Mud_Dry"
    },
    {
      "x": 0,
      "y": -1,
      "z": 4,
      "name": "Soil_Pathway"
    },
    {
      "x": 0,
      "y": -16,
      "z": 5,
      "name": "Rock_Stone"
    },
    {
      "x": 0,
      "y": -15,
      "z": 5,
      "name": "Rock_Stone"
    },
    {
      "x": 0,
      "y": -14,
      "z": 5,
      "name": "Soil_Mud_Dry"
    },
    {
      "x": 0,
      "y": -13,
      "z": 5,
      "name": "Soil_Mud_Dry"
    },
    {
      "x": 0,
      "y": -12,
      "z": 5,
      "name": "Soil_Mud_Dry"
    },
    {
      "x": 0,
      "y": -11,
      "z": 5,
      "name": "Rock_Stone"
    },
    {
      "x": 0,
      "y": -10,
      "z": 5,
      "name": "Empty"
    },
    {
      "x": 0,
      "y": -9,
      "z": 5,
      "name": "Empty"
    },
    {
      "x": 0,
      "y": -8,
      "z": 5,
      "name": "Rock_Stone_Mossy"
    },
    {
      "x": 0,
      "y": -7,
      "z": 5,
      "name": "Plant_Moss_Block_Green"
    },
    {
      "x": 0,
      "y": -6,
      "z": 5,
      "name": "Plant_Moss_Block_Green"
    },
    {
      "x": 0,
      "y": -5,
      "z": 5,
      "name": "Plant_Moss_Block_Green"
    },
    {
      "x": 0,
      "y": -4,
      "z": 5,
      "name": "Plant_Moss_Block_Green"
    },
    {
      "x": 0,
      "y": -3,
      "z": 5,
      "name": "Soil_Mud_Dry"
    },
    {
      "x": 0,
      "y": -2,
      "z": 5,
      "name": "Soil_Mud_Dry"
    },
    {
      "x": 0,
      "y": -1,
      "z": 5,
      "name": "Soil_Pathway"
    },
    {
      "x": 0,
      "y": -16,
      "z": 6,
      "name": "Rock_Stone"
    },
    {
      "x": 0,
      "y": -15,
      "z": 6,
      "name": "Soil_Dirt"
    },
    {
      "x": 0,
      "y": -14,
      "z": 6,
      "name": "Soil_Mud_Dry"
    },
    {
      "x": 0,
      "y": -13,
      "z": 6,
      "name": "Soil_Mud_Dry"
    },
    {
      "x": 0,
      "y": -12,
      "z": 6,
      "name": "Plant_Moss_Rug_Green"
    },
    {
      "x": 0,
      "y": -11,
      "z": 6,
      "name": "Empty"
    },
    {
      "x": 0,
      "y": -10,
      "z": 6,
      "name": "Empty"
    },
    {
      "x": 0,
      "y": -9,
      "z": 6,
      "name": "Empty"
    },
    {
      "x": 0,
      "y": -8,
      "z": 6,
      "name": "Rock_Stone_Mossy"
    },
    {
      "x": 0,
      "y": -7,
      "z": 6,
      "name": "Plant_Moss_Block_Green"
    },
    {
      "x": 0,
      "y": -6,
      "z": 6,
      "name": "Plant_Moss_Block_Green"
    },
    {
      "x": 0,
      "y": -5,
      "z": 6,
      "name": "Plant_Moss_Block_Green"
    },
    {
      "x": 0,
      "y": -4,
      "z": 6,
      "name": "Plant_Moss_Block_Green"
    },
    {
      "x": 0,
      "y": -3,
      "z": 6,
      "name": "Rock_Quartzite"
    },
    {
      "x": 0,
      "y": -2,
      "z": 6,
      "name": "Rock_Quartzite"
    },
    {
      "x": 0,
      "y": -1,
      "z": 6,
      "name": "Soil_Pathway"
    },
    {
      "x": 0,
      "y": -16,
      "z": 7,
      "name": "Rock_Stone"
    },
    {
      "x": 0,
      "y": -15,
      "z": 7,
      "name": "Soil_Dirt"
    },
    {
      "x": 0,
      "y": -14,
      "z": 7,
      "name": "Soil_Mud_Dry"
    },
    {
      "x": 0,
      "y": -13,
      "z": 7,
      "name": "Soil_Mud_Dry"
    },
    {
      "x": 0,
      "y": -12,
      "z": 7,
      "name": "Soil_Mud_Dry"
    },
    {
      "x": 0,
      "y": -11,
      "z": 7,
      "name": "Empty"
    },
    {
      "x": 0,
      "y": -10,
      "z": 7,
      "name": "Rock_Stone"
    },
    {
      "x": 0,
      "y": -9,
      "z": 7,
      "name": "Rock_Stone_Mossy"
    },
    {
      "x": 0,
      "y": -8,
      "z": 7,
      "name": "Rock_Stone_Mossy"
    },
    {
      "x": 0,
      "y": -7,
      "z": 7,
      "name": "Rock_Stone_Mossy"
    },
    {
      "x": 0,
      "y": -6,
