{
  "version": 8,
  "blockIdVersion": 8,
  "anchorX": -1,
  "anchorY": 13,
  "anchorZ": 0,
  "blocks": [
    {
      "x": -5,
      "y": 10,
      "z": -4,
      "name": "Rock_Sandstone_Red"
    },
    {
      "x": -5,
      "y": 11,
      "z": -4,
      "name": "Rock_Sandstone_Red"
    },
    {
      "x": -5,
      "y": 12,
      "z": -4,
      "name": "Soil_Sand_Red"
    },
    {
      "x": -5,
      "y": 10,
      "z": -3,
      "name": "Rock_Sandstone_Red"
    },
    {
      "x": -5,
      "y": 11,
      "z": -3,
      "name": "Rock_Sandstone_Red"
    },
    {
      "x": -5,
      "y": 12,
      "z": -3,
      "name": "Rock_Sandstone_Red"
    },
    {
      "x": -5,
      "y": 13,
      "z": -3,
      "name": "Wood_Drywood_Planks"
    },
    {
      "x": -5,
      "y": 10,
      "z": -2,
      "name": "Rock_Sandstone_Red"
    },
    {
      "x": -5,
      "y": 11,
      "z": -2,
      "name": "Rock_Sandstone_Red"
    },
    {
      "x": -5,
      "y": 12,
      "z": -2,
      "name": "Soil_Sand_Red"
    },
    {
      "x": -4,
      "y": 11,
      "z": -5,
      "name": "Rock_Sandstone_Red"
    },
    {
      "x": -4,
      "y": 12,
      "z": -5,
      "name": "Rock_Sandstone_Red"
    },
    {
      "x": -4,
      "y": 13,
      "z": -5,
      "name": "Wood_Drywood_Planks"
    },
    {
      "x": -4,
      "y": 10,
      "z": -4,
      "name": "Rock_Sandstone_Red"
    },
    {
      "x": -4,
      "y": 11,
      "z": -4,
      "name": "Rock_Sandstone_Red"
    },
    {
      "x": -4,
      "y": 12,
      "z": -4,
      "name": "Rock_Sandstone_Red"
    },
    {
      "x": -4,
      "y": 13,
      "z": -4,
      "name": "Wood_Drywood_Planks"
    },
    {
      "x": -4,
      "y": 14,
      "z": -4,
      "name": "Wood_Drywood_Planks"
    },
    {
      "x": -4,
      "y": 15,
      "z": -4,
      "name": "Wood_Drywood_Planks_Half",
      "rotation": 6
    },
    {
      "x": -4,
      "y": 9,
      "z": -3,
      "name": "Rock_Sandstone_Red"
    },
    {
      "x": -4,
      "y": 10,
      "z": -3,
      "name": "Rock_Sandstone_Red"
    },
    {
      "x": -4,
      "y": 11,
      "z": -3,
      "name": "Rock_Sandstone_Red"
    },
    {
      "x": -4,
      "y": 12,
      "z": -3,
      "name": "Rock_Sandstone_Red"
    },
    {
      "x": -4,
      "y": 13,
      "z": -3,
      "name": "Wood_Dry_Trunk"
    },
    {
      "x": -4,
      "y": 14,
      "z": -3,
      "name": "Wood_Dry_Trunk"
    },
    {
      "x": -4,
      "y": 15,
      "z": -3,
      "name": "Wood_Dry_Trunk"
    },
    {
      "x": -4,
      "y": 16,
      "z": -3,
      "name": "Wood_Dry_Trunk"
    },
    {
      "x": -4,
      "y": 9,
      "z": -2,
      "name": "Rock_Sandstone_Red"
    },
    {
      "x": -4,
      "y": 10,
      "z": -2,
      "name": "Rock_Sandstone_Red"
    },
    {
      "x": -4,
      "y": 11,
      "z": -2,
      "name": "Rock_Sandstone_Red"
    },
    {
      "x": -4,
      "y": 12,
      "z": -2,
      "name": "Rock_Sandstone_Red"
    },
    {
      "x": -4,
      "y": 13,
      "z": -2,
      "name": "Soil_Sand_Red"
    },
    {
      "x": -4,
      "y": 9,
      "z": -1,
      "name": "Rock_Sandstone_Red"
    },
    {
      "x": -4,
      "y": 10,
      "z": -1,
      "name": "Rock_Sandstone_Red"
    },
    {
      "x": -4,
      "y": 11,
      "z": -1,
      "name": "Rock_Sandstone_Red"
    },
    {
      "x": -4,
      "y": 12,
      "z": -1,
      "name": "Rock_Sandstone_Red"
    },
    {
      "x": -4,
      "y": 13,
      "z": -1,
      "name": "Soil_Sand_Red"
    },
    {
      "x": -4,
      "y": 10,
      "z": 0,
      "name": "Rock_Sandstone_Red"
    },
    {
      "x": -4,
      "y": 11,
      "z": 0,
      "name": "Rock_Sandstone_Red"
    },
    {
      "x": -4,
      "y": 12,
      "z": 0,
      "name": "Soil_Sand_Red"
    },
    {
      "x": -4,
      "y": 11,
      "z": 2,
      "name": "Rock_Sandstone_Red"
    },
    {
      "x": -4,
      "y": 12,
      "z": 2,
      "name": "Rock_Sandstone_Red"
    },
    {
      "x": -4,
      "y": 13,
      "z": 2,
      "name": "Soil_Sand_Red"
    },
    {
      "x": -4,
      "y": 10,
      "z": 3,
      "name": "Rock_Sandstone_Red"
    },
    {
      "x": -4,
      "y": 11,
      "z": 3,
      "name": "Rock_Sandstone_Red"
    },
    {
      "x": -4,
      "y": 12,
      "z": 3,
      "name": "Rock_Sandstone_Red"
    },
    {
      "x": -4,
      "y": 13,
      "z": 3,
      "name": "Rock_Sandstone_Red"
    },
    {
      "x": -4,
      "y": 14,
      "z": 3,
      "name": "Plant_Bush_Arid_Sharp"
    },
    {
      "x": -4,
      "y": 10,
      "z": 4,
      "name": "Rock_Sandstone_Red"
    },
    {
      "x": -4,
      "y": 11,
      "z": 4,
      "name": "Rock_Sandstone_Red"
    },
    {
      "x": -4,
      "y": 12,
      "z": 4,
      "name": "Rock_Sandstone_Red"
    },
    {
      "x": -4,
      "y": 13,
      "z": 4,
      "name": "Soil_Sand_Red"
    },
    {
      "x": -3,
      "y": 10,
      "z": -5,
      "name": "Rock_Sandstone_Red"
    },
    {
      "x": -3,
      "y": 11,
      "z": -5,
      "name": "Rock_Sandstone_Red"
    },
    {
      "x": -3,
      "y": 12,
      "z": -5,
      "name": "Soil_Sand_Red"
    },
    {
      "x": -3,
      "y": 9,
      "z": -4,
      "name": "Rock_Sandstone_Red"
    },
    {
      "x": -3,
      "y": 10,
      "z": -4,
      "name": "Rock_Sandstone_Red"
    },
    {
      "x": -3,
      "y": 11,
      "z": -4,
      "name": "Rock_Sandstone_Red"
    },
    {
      "x": -3,
      "y": 12,
      "z": -4,
      "name": "Rock_Sandstone_Red"
    },
    {
      "x": -3,
      "y": 13,
      "z": -4,
      "name": "Soil_Sand_Red"
    },
    {
      "x": -3,
      "y": 9,
      "z": -3,
      "name": "Rock_Sandstone_Red"
    },
    {
      "x": -3,
      "y": 10,
      "z": -3,
      "name": "Rock_Sandstone_Red"
    },
    {
      "x": -3,
      "y": 11,
      "z": -3,
      "name": "Rock_Sandstone_Red"
    },
    {
      "x": -3,
      "y": 12,
      "z": -3,
      "name": "Rock_Sandstone_Red"
    },
    {
      "x": -3,
      "y": 13,
      "z": -3,
      "name": "Soil_Sand_Red"
    },
    {
      "x": -3,
      "y": 9,
      "z": -2,
      "name": "Rock_Sandstone_Red"
    },
    {
      "x": -3,
      "y": 10,
      "z": -2,
      "name": "Rock_Sandstone_Red"
    },
    {
      "x": -3,
      "y": 11,
      "z": -2,
      "name": "Rock_Sandstone_Red"
    },
    {
      "x": -3,
      "y": 12,
      "z": -2,
      "name": "Rock_Sandstone_Red"
    },
    {
      "x": -3,
      "y": 13,
      "z": -2,
      "name": "Soil_Sand_Red"
    },
    {
      "x": -3,
      "y": 9,
      "z": -1,
      "name": "Rock_Sandstone_Red"
    },
    {
      "x": -3,
      "y": 10,
      "z": -1,
      "name": "Rock_Sandstone_Red"
    },
    {
      "x": -3,
      "y": 11,
      "z": -1,
      "name": "Rock_Sandstone_Red"
    },
    {
      "x": -3,
      "y": 12,
      "z": -1,
      "name": "Soil_Sand_Red"
    },
    {
      "x": -3,
      "y": 13,
      "z": -1,
      "name": "Soil_Sand_Red"
    },
    {
      "x": -3,
      "y": 9,
      "z": 0,
      "name": "Rock_Sandstone_Red"
    },
    {
      "x": -3,
      "y": 10,
      "z": 0,
      "name": "Rock_Sandstone_Red"
    },
    {
      "x": -3,
      "y": 11,
      "z": 0,
      "name": "Rock_Sandstone_Red"
    },
    {
      "x": -3,
      "y": 12,
      "z": 0,
      "name": "Rock_Sandstone_Red"
    },
    {
      "x": -3,
      "y": 13,
      "z": 0,
      "name": "Soil_Sand_Red"
    },
    {
      "x": -3,
      "y": 9,
      "z": 1,
      "name": "Rock_Sandstone_Red"
    },
    {
      "x": -3,
      "y": 10,
      "z": 1,
      "name": "Rock_Sandstone_Red"
    },
    {
      "x": -3,
      "y": 11,
      "z": 1,
      "name": "Rock_Sandstone_Red"
    },
    {
      "x": -3,
      "y": 12,
      "z": 1,
      "name": "Rock_Sandstone_Red"
    },
    {
      "x": -3,
      "y": 13,
      "z": 1,
      "name": "Soil_Sand_Red"
    },
    {
      "x": -3,
      "y": 9,
      "z": 2,
      "name": "Rock_Sandstone_Red"
    },
    {
      "x": -3,
      "y": 10,
      "z": 2,
      "name": "Rock_Sandstone_Red"
    },
    {
      "x": -3,
      "y": 11,
      "z": 2,
      "name": "Rock_Sandstone_Red"
    },
    {
      "x": -3,
      "y": 12,
      "z": 2,
      "name": "Rock_Sandstone_Red"
    },
    {
      "x": -3,
      "y": 13,
      "z": 2,
      "name": "Soil_Sand_Red"
    },
    {
      "x": -3,
      "y": 9,
      "z": 3,
      "name": "Rock_Sandstone_Red"
    },
    {
      "x": -3,
      "y": 10,
      "z": 3,
      "name": "Rock_Sandstone_Red"
    },
    {
      "x": -3,
      "y": 11,
      "z": 3,
      "name": "Rock_Sandstone_Red"
    },
    {
      "x": -3,
      "y": 12,
      "z": 3,
      "name": "Rock_Sandstone_Red"
    },
    {
      "x": -3,
      "y": 13,
      "z": 3,
      "name": "Soil_Sand_Red"
    },
    {
      "x": -3,
      "y": 14,
      "z": 3,
      "name": "Furniture_Village_Pot"
    },
    {
      "x": -3,
      "y": 10,
      "z": 4,
      "name": "Rock_Sandstone_Red"
    },
    {
      "x": -3,
      "y": 11,
      "z": 4,
      "name": "Rock_Sandstone_Red"
    },
    {
      "x": -3,
      "y": 12,
      "z": 4,
      "name": "Rock_Sandstone_Red"
    },
    {
      "x": -3,
      "y": 13,
      "z": 4,
      "name": "Rock_Sandstone_Red"
    },
    {
      "x": -3,
      "y": 12,
      "z": 5,
      "name": "Rock_Sandstone_Red"
    },
    {
      "x": -3,
      "y": 13,
      "z": 5,
      "name": "Soil_Sand_Red"
    },
    {
      "x": -2,
      "y": 10,
      "z": -5,
      "name": "Rock_Sandstone_Red"
    },
    {
      "x": -2,
      "y": 11,
      "z": -5,
      "name": "Rock_Sandstone_Red"
    },
    {
      "x": -2,
      "y": 12,
      "z": -5,
      "name": "Rock_Sandstone_Red"
    },
    {
      "x": -2,
      "y": 9,
      "z": -4,
      "name": "Rock_Sandstone_Red"
    },
    {
      "x": -2,
      "y": 10,
      "z": -4,
      "name": "Rock_Sandstone_Red"
    },
    {
      "x": -2,
      "y": 11,
      "z": -4,
      "name": "Rock_Sandstone_Red"
    },
    {
      "x": -2,
      "y": 12,
      "z": -4,
      "name": "Rock_Sandstone_Red"
    },
    {
      "x": -2,
      "y": 13,
      "z": -4,
      "name": "Rock_Sandstone_Red"
    },
    {
      "x": -2,
      "y": 9,
      "z": -3,
      "name": "Rock_Sandstone_Red"
    },
    {
      "x": -2,
      "y": 10,
      "z": -3,
      "name": "Rock_Sandstone_Red"
    },
    {
      "x": -2,
      "y": 11,
      "z": -3,
      "name": "Rock_Sandstone_Red"
    },
    {
      "x": -2,
      "y": 12,
      "z": -3,
      "name": "Rock_Sandstone_Red"
    },
    {
      "x": -2,
      "y": 13,
      "z": -3,
      "name": "Soil_Sand_Red"
    },
    {
      "x": -2,
      "y": 9,
      "z": -2,
      "name": "Rock_Sandstone_Red"
    },
    {
      "x": -2,
      "y": 10,
      "z": -2,
      "name": "Rock_Sandstone_Red"
    },
    {
      "x": -2,
      "y": 11,
      "z": -2,
      "name": "Rock_Sandstone_Red"
    },
    {
      "x": -2,
      "y": 12,
      "z": -2,
      "name": "Rock_Sandstone_Red"
    },
    {
      "x": -2,
      "y": 13,
      "z": -2,
      "name": "Soil_Sand_Red"
    },
    {
      "x": -2,
      "y": 1,
      "z": -1,
      "name": "Rock_Sandstone_Cobble"
    },
    {
      "x": -2,
      "y": 9,
      "z": -1,
      "name": "Rock_Sandstone_Red"
    },
    {
      "x": -2,
      "y": 10,
      "z": -1,
      "name": "Rock_Sandstone_Red"
    },
    {
      "x": -2,
      "y": 11,
      "z": -1,
      "name": "Rock_Sandstone_Red"
    },
    {
      "x": -2,
      "y": 12,
      "z": -1,
      "name": "Rock_Sandstone_Red"
    },
    {
      "x": -2,
      "y": 13,
      "z": -1,
      "name": "Soil_Sand_Red"
    },
    {
      "x": -2,
      "y": 14,
      "z": -1,
      "name": "Empty"
    },
    {
      "x": -2,
      "y": 15,
      "z": -1,
      "name": "Empty"
    },
    {
      "x": -2,
      "y": 16,
      "z": -1,
      "name": "Empty"
    },
    {
      "x": -2,
      "y": 17,
      "z": -1,
      "name": "Empty"
    },
    {
      "x": -2,
      "y": 1,
      "z": 0,
      "name": "Rock_Sandstone_Cobble"
    },
    {
      "x": -2,
      "y": 2,
      "z": 0,
      "name": "Rock_Sandstone_Cobble"
    },
    {
      "x": -2,
      "y": 9,
      "z": 0,
      "name": "Rock_Sandstone_Red"
    },
    {
      "x": -2,
      "y": 10,
      "z": 0,
      "name": "Rock_Sandstone_Red"
    },
    {
      "x": -2,
      "y": 11,
      "z": 0,
      "name": "Rock_Sandstone_Red"
    },
    {
      "x": -2,
      "y": 12,
      "z": 0,
      "name": "Rock_Sandstone_Red"
    },
    {
      "x": -2,
      "y": 13,
      "z": 0,
      "name": "Rock_Sandstone_Red"
    },
    {
      "x": -2,
      "y": 14,
      "z": 0,
      "name": "Empty"
    },
    {
      "x": -2,
      "y": 15,
      "z": 0,
      "name": "Empty"
    },
    {
      "x": -2,
      "y": 16,
      "z": 0,
      "name": "Empty"
    },
    {
      "x": -2,
      "y": 17,
      "z": 0,
      "name": "Empty"
    },
    {
      "x": -2,
      "y": 9,
      "z": 1,
      "name": "Rock_Sandstone_Red"
    },
    {
      "x": -2,
      "y": 10,
      "z": 1,
      "name": "Rock_Sandstone_Red"
    },
    {
      "x": -2,
      "y": 11,
      "z": 1,
      "name": "Rock_Sandstone_Red"
    },
    {
      "x": -2,
      "y": 12,
      "z": 1,
      "name": "Rock_Sandstone_Red"
    },
    {
      "x": -2,
      "y": 13,
      "z": 1,
      "name": "Soil_Sand_Red"
    },
    {
      "x": -2,
      "y": 14,
      "z": 1,
      "name": "Empty"
    },
    {
      "x": -2,
      "y": 15,
      "z": 1,
      "name": "Empty"
    },
    {
      "x": -2,
      "y": 16,
      "z": 1,
      "name": "Empty"
    },
    {
      "x": -2,
      "y": 17,
      "z": 1,
      "name": "Empty"
    },
    {
      "x": -2,
      "y": 9,
      "z": 2,
      "name": "Rock_Sandstone_Red"
    },
    {
      "x": -2,
      "y": 10,
      "z": 2,
      "name": "Rock_Sandstone_Red"
    },
    {
      "x": -2,
      "y": 11,
      "z": 2,
      "name": "Rock_Sandstone_Red"
    },
    {
      "x": -2,
      "y": 12,
      "z": 2,
      "name": "Rock_Sandstone_Red"
    },
    {
      "x": -2,
      "y": 13,
      "z": 2,
      "name": "Soil_Sand_Red"
    },
    {
      "x": -2,
      "y": 9,
      "z": 3,
      "name": "Rock_Sandstone_Red"
    },
    {
      "x": -2,
      "y": 10,
      "z": 3,
      "name": "Rock_Sandstone_Red"
    },
    {
      "x": -2,
      "y": 11,
      "z": 3,
      "name": "Rock_Sandstone_Red"
    },
    {
      "x": -2,
      "y": 12,
      "z": 3,
      "name": "Rock_Sandstone_Red"
    },
    {
      "x": -2,
      "y": 13,
      "z": 3,
      "name": "Soil_Sand_Red"
    },
    {
      "x": -2,
      "y": 9,
      "z": 4,
      "name": "Rock_Sandstone_Red"
    },
    {
      "x": -2,
      "y": 10,
      "z": 4,
      "name": "Rock_Sandstone_Red"
    },
    {
      "x": -2,
      "y": 11,
      "z": 4,
      "name": "Rock_Sandstone_Red"
    },
    {
      "x": -2,
      "y": 12,
      "z": 4,
      "name": "Rock_Sandstone_Red"
    },
    {
      "x": -2,
      "y": 13,
      "z": 4,
      "name": "Soil_Sand_Red"
    },
    {
      "x": -2,
      "y": 11,
      "z": 5,
      "name": "Rock_Sandstone_Red"
    },
    {
      "x": -2,
      "y": 12,
      "z": 5,
      "name": "Rock_Sandstone_Red"
    },
    {
      "x": -2,
      "y": 13,
      "z": 5,
      "name": "Soil_Sand_Red"
    },
    {
      "x": -1,
      "y": 10,
      "z": -4,
      "name": "Rock_Sandstone_Red"
    },
    {
      "x": -1,
      "y": 11,
      "z": -4,
      "name": "Rock_Sandstone_Red"
    },
    {
      "x": -1,
      "y": 12,
      "z": -4,
      "name": "Soil_Sand_Red"
    },
    {
      "x": -1,
      "y": 9,
      "z": -3,
      "name": "Rock_Sandstone_Red"
    },
    {
      "x": -1,
      "y": 10,
      "z": -3,
      "name": "Rock_Sandstone_Red"
    },
    {
      "x": -1,
      "y": 11,
      "z": -3,
      "name": "Rock_Sandstone_Red"
    },
    {
      "x": -1,
      "y": 12,
      "z": -3,
      "name": "Soil_Sand_Red"
    },
    {
      "x": -1,
      "y": 13,
      "z": -3,
      "name": "Soil_Sand_Red"
    },
    {
      "x": -1,
      "y": 1,
      "z": -2,
      "name": "Rock_Sandstone_Cobble"
    },
    {
      "x": -1,
      "y": 2,
      "z": -2,
      "name": "Rock_Sandstone_Cobble"
    },
    {
      "x": -1,
      "y": 9,
      "z": -2,
      "name": "Rock_Sandstone_Red"
    },
    {
      "x": -1,
      "y": 10,
      "z": -2,
      "name": "Rock_Sandstone_Red"
    },
    {
      "x": -1,
      "y": 11,
      "z": -2,
      "name": "Rock_Sandstone_Red"
    },
    {
      "x": -1,
      "y": 12,
      "z": -2,
      "name": "Rock_Sandstone_Red"
    },
    {
      "x": -1,
      "y": 13,
      "z": -2,
      "name": "Rock_Sandstone_Red"
    },
    {
      "x": -1,
      "y": 14,
      "z": -2,
      "name": "Empty"
    },
    {
      "x": -1,
      "y": 15,
      "z": -2,
      "name": "Empty"
    },
    {
      "x": -1,
      "y": 16,
      "z": -2,
      "name": "Empty"
    },
    {
      "x": -1,
      "y": 17,
      "z": -2,
      "name": "Empty"
    },
    {
      "x": -1,
      "y": 0,
      "z": -1,
      "name": "Rock_Sandstone_Cobble"
    },
    {
      "x": -1,
      "y": 1,
      "z": -1,
      "name": "Deco_Pot_Clay_Broken"
    },
    {
      "x": -1,
      "y": 2,
      "z": -1,
      "name": "Empty"
    },
    {
      "x": -1,
      "y": 3,
      "z": -1,
      "name": "Empty"
    },
    {
      "x": -1,
      "y": 4,
      "z": -1,
      "name": "Empty"
    },
    {
      "x": -1,
      "y": 5,
      "z": -1,
      "name": "Empty"
    },
    {
      "x": -1,
      "y": 9,
      "z": -1,
      "name": "Rock_Sandstone_Red"
    },
    {
      "x": -1,
      "y": 10,
      "z": -1,
      "name": "Rock_Sandstone_Red"
    },
    {
      "x": -1,
      "y": 11,
      "z": -1,
      "name": "Rock_Sandstone_Red"
    },
    {
      "x": -1,
      "y": 12,
      "z": -1,
      "name": "Rock_Sandstone_Cobble"
    },
    {
      "x": -1,
      "y": 13,
      "z": -1,
      "name": "Rock_Sandstone_Red"
    },
    {
      "x": -1,
      "y": 14,
      "z": -1,
      "name": "Wood_Drywood_Planks_Half",
      "rotation": 7
    },
    {
      "x": -1,
      "y": 15,
      "z": -1,
      "name": "Empty"
    },
    {
      "x": -1,
      "y": 16,
      "z": -1,
      "name": "Empty"
    },
    {
      "x": -1,
      "y": 17,
      "z": -1,
      "name": "Wood_Dry_Branch_Short",
      "rotation": 2
    },
    {
      "x": -1,
      "y": 0,
      "z": 0,
      "name": "Rock_Sandstone_Cobble"
    },
    {
      "x": -1,
      "y": 1,
      "z": 0,
      "name": "Empty"
    },
    {
      "x": -1,
      "y": 2,
      "z": 0,
      "name": "Empty"
    },
    {
      "x": -1,
      "y": 3,
      "z": 0,
      "name": "Empty"
    },
    {
      "x": -1,
      "y": 4,
      "z": 0,
      "name": "Empty"
    },
    {
      "x": -1,
      "y": 5,
      "z": 0,
      "name": "Empty"
    },
    {
      "x": -1,
      "y": 6,
      "z": 0,
      "name": "Empty"
    },
    {
      "x": -1,
      "y": 10,
      "z": 0,
      "name": "Rock_Sandstone_Red"
    },
    {
      "x": -1,
      "y": 11,
      "z": 0,
      "name": "Rock_Sandstone_Cobble"
    },
    {
      "x": -1,
      "y": 12,
      "z": 0,
      "name": "Rock_Sandstone_Cobble"
    },
    {
      "x": -1,
      "y": 13,
      "z": 0,
      "name": "Rock_Sandstone_Red"
    },
    {
      "x": -1,
      "y": 14,
      "z": 0,
      "name": "Wood_Dry_Trunk"
    },
    {
      "x": -1,
      "y": 15,
      "z": 0,
      "name": "Wood_Dry_Branch_Long"
    },
    {
      "x": -1,
      "y": 16,
      "z": 0,
      "name": "Wood_Dry_Branch_Long"
    },
    {
      "x": -1,
      "y": 17,
      "z": 0,
      "name": "Wood_Dry_Trunk",
      "rotation": 5
    },
    {
      "x": -1,
      "y": 1,
      "z": 1,
      "name": "Rock_Sandstone_Cobble"
    },
    {
      "x": -1,
      "y": 2,
      "z": 1,
      "name": "Rock_Sandstone_Cobble"
    },
    {
      "x": -1,
      "y": 3,
      "z": 1,
      "name": "Empty"
    },
    {
      "x": -1,
      "y": 4,
      "z": 1,
      "name": "Empty"
    },
    {
      "x": -1,
      "y": 5,
      "z": 1,
      "name": "Empty"
    },
    {
      "x": -1,
      "y": 10,
      "z": 1,
      "name": "Rock_Sandstone_Cobble"
    },
    {
      "x": -1,
      "y": 11,
      "z": 1,
      "name": "Rock_Sandstone_Cobble"
    },
    {
      "x": -1,
      "y": 12,
      "z": 1,
      "name": "Rock_Sandstone_Cobble"
    },
    {
      "x": -1,
      "y": 13,
      "z": 1,
      "name": "Rock_Sandstone_Red"
    },
    {
      "x": -1,
      "y": 14,
      "z": 1,
      "name": "Wood_Drywood_Planks_Half",
      "rotation": 7
    },
    {
      "x": -1,
      "y": 15,
      "z": 1,
      "name": "Empty"
    },
    {
      "x": -1,
      "y": 16,
      "z": 1,
      "name": "Empty"
    },
    {
      "x": -1,
      "y": 17,
      "z": 1,
      "name": "Wood_Dry_Branch_Short"
    },
    {
      "x": -1,
      "y": 8,
      "z": 2,
      "name": "Rock_Sandstone_Red"
    },
    {
      "x": -1,
      "y": 9,
      "z": 2,
      "name": "Rock_Sandstone_Red"
    },
    {
      "x": -1,
      "y": 10,
      "z": 2,
      "name": "Rock_Sandstone_Red"
    },
    {
      "x": -1,
      "y": 12,
      "z": 2,
      "name": "Rock_Sandstone_Red"
    },
    {
      "x": -1,
      "y": 13,
      "z": 2,
      "name": "Soil_Sand_Red"
    },
    {
      "x": -1,
      "y": 14,
      "z": 2,
      "name": "Empty"
    },
    {
      "x": -1,
      "y": 15,
      "z": 2,
      "name": "Empty"
    },
    {
      "x": -1,
      "y": 16,
      "z": 2,
      "name": "Empty"
    },
    {
      "x": -1,
      "y": 17,
      "z": 2,
      "name": "Empty"
    },
    {
      "x": -1,
      "y": 8,
      "z": 3,
      "name": "Rock_Sandstone_Red"
    },
    {
      "x": -1,
      "y": 9,
      "z": 3,
      "name": "Rock_Sandstone_Red"
    },
    {
      "x": -1,
      "y": 10,
      "z": 3,
      "name": "Rock_Sandstone_Red"
    },
    {
      "x": -1,
      "y": 11,
      "z": 3,
      "name": "Rock_Sandstone_Red"
    },
    {
      "x": -1,
      "y": 12,
      "z": 3,
      "name": "Rock_Sandstone_Red"
    },
    {
      "x": -1,
      "y": 13,
      "z": 3,
      "name": "Soil_Sand_Red"
    },
    {
      "x": -1,
      "y": 9,
      "z": 4,
      "name": "Rock_Sandstone_Red"
    },
    {
      "x": -1,
      "y": 10,
      "z": 4,
      "name": "Rock_Sandstone_Red"
    },
    {
      "x": -1,
      "y": 11,
      "z": 4,
      "name": "Rock_Sandstone_Red"
    },
    {
      "x": -1,
      "y": 12,
      "z": 4,
      "name": "Rock_Sandstone_Red"
    },
    {
      "x": -1,
      "y": 13,
      "z": 4,
      "name": "Soil_Sand_Red"
    },
    {
      "x": -1,
      "y": 10,
      "z": 5,
      "name": "Rock_Sandstone_Red"
    },
    {
      "x": -1,
      "y": 11,
      "z": 5,
      "name": "Rock_Sandstone_Red"
    },
    {
      "x": -1,
      "y": 12,
      "z": 5,
      "name": "Rock_Sandstone_Red"
    },
    {
      "x": 0,
      "y": 10,
      "z": -3,
      "name": "Rock_Sandstone_Red"
    },
    {
      "x": 0,
      "y": 11,
      "z": -3,
      "name": "Rock_Sandstone_Red"
    },
    {
      "x": 0,
      "y": 12,
      "z": -3,
      "name": "Soil_Sand_Red"
    },
    {
      "x": 0,
      "y": 1,
      "z": -2,
      "name": "Rock_Sandstone_Cobble"
    },
    {
      "x": 0,
      "y": 2,
      "z": -2,
      "name": "Rock_Sandstone_Cobble"
    },
    {
      "x": 0,
      "y": 11,
      "z": -2,
      "name": "Rock_Sandstone_Cobble"
    },
    {
      "x": 0,
      "y": 12,
      "z": -2,
      "name": "Rock_Sandstone_Cobble"
    },
    {
      "x": 0,
      "y": 13,
      "z": -2,
      "name": "Soil_Sand_Red"
    },
    {
      "x": 0,
      "y": 14,
      "z": -2,
      "name": "Empty"
    },
    {
      "x": 0,
      "y": 15,
      "z": -2,
      "name": "Empty"
    },
    {
      "x": 0,
      "y": 16,
      "z": -2,
      "name": "Empty"
    },
    {
      "x": 0,
      "y": 17,
      "z": -2,
      "name": "Empty"
    },
    {
      "x": 0,
      "y": 0,
      "z": -1,
      "name": "Rock_Sandstone_Cobble"
    },
    {
      "x": 0,
      "y": 1,
      "z": -1,
      "name": "Empty"
    },
    {
      "x": 0,
      "y": 2,
      "z": -1,
      "name": "Empty"
    },
    {
      "x": 0,
      "y": 3,
      "z": -1,
      "name": "Empty"
    },
    {
      "x": 0,
      "y": 4,
      "z": -1,
      "name": "Empty"
    },
    {
      "x": 0,
      "y": 5,
      "z": -1,
      "name": "Empty"
    },
    {
      "x": 0,
      "y": 6,
      "z": -1,
      "name": "Empty"
    },
    {
      "x": 0,
      "y": 7,
      "z": -1,
      "name": "Empty"
    },
    {
      "x": 0,
      "y": 8,
      "z": -1,
      "name": "Empty"
    },
    {
      "x": 0,
      "y": 9,
      "z": -1,
      "name": "Empty"
    },
    {
      "x": 0,
      "y": 10,
      "z": -1,
      "name": "Empty"
    },
    {
      "x": 0,
      "y": 11,
      "z": -1,
      "name": "Empty"
    },
    {
      "x": 0,
      "y": 12,
      "z": -1,
      "name": "Empty"
    },
    {
      "x": 0,
      "y": 13,
      "z": -1,
      "name": "Empty"
    },
    {
      "x": 0,
      "y": 14,
      "z": -1,
      "name": "Empty"
    },
    {
      "x": 0,
      "y": 15,
      "z": -1,
      "name": "Empty"
    },
    {
      "x": 0,
      "y": 16,
      "z": -1,
      "name": "Empty"
    },
    {
      "x": 0,
      "y": 17,
      "z": -1,
      "name": "Empty"
    },
    {
      "x": 0,
      "y": 0,
      "z": 0,
      "name": "Rock_Sandstone_Cobble"
    },
    {
      "x": 0,
      "y": 1,
      "z": 0,
      "name": "Block_Spawner_Block",
      "components": {
        "Components": {
          "PlacedByInteraction": {
            "WhoPlacedUuid": {
              "$binary": "qA/t28wKPUewuu66t1XEYQ==",
              "$type": "04"
            }
          },
          "BlockSpawner": {
            "BlockSpawnerId": "Zone2_Encounters_Tier2"
          }
        }
      },
      "rotation": 2
    },
    {
      "x": 0,
      "y": 2,
      "z": 0,
      "name": "Empty"
    },
    {
      "x": 0,
      "y": 3,
      "z": 0,
      "name": "Deco_Rope"
    },
    {
      "x": 0,
      "y": 4,
      "z": 0,
      "name": "Deco_Rope"
    },
    {
      "x": 0,
      "y": 5,
      "z": 0,
      "name": "Deco_Rope"
    },
    {
      "x": 0,
      "y": 6,
      "z": 0,
      "name": "Deco_Rope"
    },
    {
      "x": 0,
      "y": 7,
      "z": 0,
      "name": "Deco_Rope"
    },
    {
      "x": 0,
      "y": 8,
      "z": 0,
      "name": "Deco_Rope"
    },
    {
      "x": 0,
      "y": 9,
      "z": 0,
      "name": "Deco_Rope"
    },
    {
      "x": 0,
      "y": 10,
      "z": 0,
      "name": "Deco_Rope"
    },
    {
      "x": 0,
      "y": 11,
      "z": 0,
      "name": "Deco_Rope"
    },
    {
      "x": 0,
      "y": 12,
      "z": 0,
      "name": "Deco_Rope"
    },
    {
      "x": 0,
      "y": 13,
      "z": 0,
      "name": "Deco_Rope"
    },
    {
      "x": 0,
      "y": 14,
      "z": 0,
      "name": "Deco_Rope"
    },
    {
      "x": 0,
      "y": 15,
      "z": 0,
      "name": "Deco_Rope"
    },
    {
      "x": 0,
      "y": 16,
      "z": 0,
      "name": "Deco_Rope"
    },
    {
      "x": 0,
      "y": 17,
      "z": 0,
      "name": "Wood_Dry_Trunk",
      "rotation": 5
    },
    {
      "x": 0,
      "y": 0,
      "z": 1,
      "name": "Rock_Sandstone_Cobble"
    },
    {
      "x": 0,
      "y": 1,
      "z": 1,
      "name": "Empty"
    },
    {
      "x": 0,
      "y": 2,
      "z": 1,
      "name": "Empty"
    },
    {
      "x": 0,
      "y": 3,
      "z": 1,
      "name": "Empty"
    },
    {
      "x": 0,
      "y": 4,
      "z": 1,
      "name": "Empty"
    },
    {
      "x": 0,
      "y": 5,
      "z": 1,
      "name": "Empty"
    },
    {
      "x": 0,
      "y": 6,
      "z": 1,
      "name": "Empty"
    },
    {
      "x": 0,
      "y": 7,
      "z": 1,
      "name": "Empty"
    },
    {
      "x": 0,
      "y": 8,
      "z": 1,
      "name": "Empty"
    },
    {
      "x": 0,
      "y": 9,
      "z": 1,
      "name": "Empty"
    },
    {
      "x": 0,
      "y": 10,
      "z": 1,
      "name": "Empty"
    },
    {
      "x": 0,
      "y": 11,
      "z": 1,
      "name": "Empty"
    },
    {
      "x": 0,
      "y": 12,
      "z": 1,
      "name": "Empty"
    },
    {
      "x": 0,
      "y": 13,
      "z": 1,
      "name": "Empty"
    },
    {
      "x": 0,
      "y": 14,
      "z": 1,
      "name": "Empty"
    },
    {
      "x": 0,
      "y": 15,
      "z": 1,
      "name": "Empty"
    },
    {
      "x": 0,
      "y": 16,
      "z": 1,
      "name": "Empty"
    },
    {
      "x": 0,
      "y": 17,
      "z": 1,
      "name": "Empty"
    },
    {
      "x": 0,
      "y": 1,
      "z": 2,
      "name": "Rock_Sandstone_Cobble"
    },
    {
      "x": 0,
      "y": 2,
      "z": 2,
      "name": "Rock_Sandstone_Cobble"
    },
    {
      "x": 0,
      "y": 8,
      "z": 2,
      "name": "Rock_Sandstone_Red"
    },
    {
      "x": 0,
      "y": 9,
      "z": 2,
      "name": "Rock_Sandstone_Red"
    },
    {
      "x": 0,
      "y": 10,
      "z": 2,
      "name": "Rock_Sandstone_Red"
    },
    {
      "x": 0,
      "y": 11,
      "z": 2,
      "name": "Rock_Sandstone_Cobble"
    },
    {
      "x": 0,
      "y": 12,
      "z": 2,
      "name": "Rock_Sandstone_Cobble"
    },
    {
      "x": 0,
      "y": 13,
      "z": 2,
      "name": "Rock_Sandstone_Red"
    },
    {
      "x": 0,
      "y": 14,
      "z": 2,
      "name": "Wood_Drywood_Planks_Half",
      "rotation": 4
    },
    {
      "x": 0,
      "y": 15,
      "z": 2,
      "name": "Empty"
    },
    {
      "x": 0,
      "y": 16,
      "z": 2,
      "name": "Empty"
    },
    {
      "x": 0,
      "y": 17,
      "z": 2,
      "name": "Empty"
    },
    {
      "x": 0,
      "y": 8,
      "z": 3,
      "name": "Rock_Sandstone_Red"
    },
    {
      "x": 0,
      "y": 9,
      "z": 3,
      "name": "Rock_Sandstone_Red"
    },
    {
      "x": 0,
      "y": 10,
      "z": 3,
      "name": "Rock_Sandstone_Red"
    },
    {
      "x": 0,
      "y": 11,
      "z": 3,
      "name": "Rock_Sandstone_Red"
    },
    {
      "x": 0,
      "y": 12,
      "z": 3,
      "name": "Rock_Sandstone_Red"
    },
    {
      "x": 0,
      "y": 13,
      "z": 3,
      "name": "Soil_Sand_Red"
    },
    {
      "x": 0,
      "y": 8,
      "z": 4,
      "name": "Rock_Sandstone_Red"
    },
    {
      "x": 0,
      "y": 9,
      "z": 4,
      "name": "Rock_Sandstone_Red"
    },
    {
      "x": 0,
      "y": 10,
      "z": 4,
      "name": "Rock_Sandstone_Red"
    },
    {
      "x": 0,
      "y": 11,
      "z": 4,
      "name": "Rock_Sandstone_Red"
    },
    {
      "x": 0,
      "y": 12,
      "z": 4,
      "name": "Soil_Sand_Red"
    },
    {
      "x": 0,
      "y": 9,
      "z": 5,
      "name": "Rock_Sandstone_Red"
    },
    {
      "x": 0,
      "y": 10,
      "z": 5,
      "name": "Rock_Sandstone_Red"
    },
    {
      "x": 0,
      "y": 11,
      "z": 5,
      "name": "Rock_Sandstone_Red"
    },
    {
      "x": 0,
      "y": 12,
      "z": 5,
      "name": "Soil_Sand_Red"
    },
    {
      "x": 1,
      "y": 1,
      "z": -2,
      "name": "Rock_Sandstone_Cobble"
    },
    {
      "x": 1,
      "y": 2,
      "z": -2,
      "name": "Rock_Sandstone_Cobble"
    },
    {
      "x": 1,
      "y": 12,
      "z": -2,
      "name": "Rock_Sandstone_Red"
    },
    {
      "x": 1,
      "y": 13,
      "z": -2,
      "name": "Soil_Sand_Red"
    },
    {
      "x": 1,
      "y": 0,
      "z": -1,
      "name": "Rock_Sandstone_Cobble"
    },
    {
      "x": 1,
      "y": 1,
      "z": -1,
      "name": "Deco_Bone_Pile"
    },
    {
      "x": 1,
      "y": 2,
      "z": -1,
      "name": "Empty"
    },
    {
      "x": 1,
      "y": 3,
      "z": -1,
      "name": "Empty"
    },
    {
      "x": 1,
      "y": 4,
      "z": -1,
      "name": "Empty"
    },
    {
      "x": 1,
      "y": 5,
      "z": -1,
      "name": "Empty"
    },
    {
      "x": 1,
      "y": 12,
      "z": -1,
      "name": "Rock_Sandstone_Cobble"
    },
    {
      "x": 1,
      "y": 13,
      "z": -1,
      "name": "Rock_Sandstone_Red"
    },
    {
      "x": 1,
      "y": 14,
      "z": -1,
      "name": "Wood_Drywood_Planks_Half"
    },
    {
      "x": 1,
      "y": 15,
      "z": -1,
      "name": "Empty"
    },
    {
      "x": 1,
      "y": 16,
      "z": -1,
      "name": "Empty"
    },
    {
      "x": 1,
      "y": 17,
      "z": -1,
      "name": "Empty"
    },
    {
      "x": 1,
      "y": 0,
      "z": 0,
      "name": "Rock_Sandstone_Cobble"
    },
    {
      "x": 1,
      "y": 1,
      "z": 0,
      "name": "Empty"
    },
    {
      "x": 1,
      "y": 2,
      "z": 0,
      "name": "Empty"
    },
    {
      "x": 1,
      "y": 3,
      "z": 0,
      "name": "Empty"
    },
    {
      "x": 1,
      "y": 4,
      "z": 0,
      "name": "Empty"
    },
    {
      "x": 1,
      "y": 5,
      "z": 0,
      "name": "Empty"
    },
    {
      "x": 1,
      "y": 6,
      "z": 0,
      "name": "Empty"
    },
    {
      "x": 1,
      "y": 10,
      "z": 0,
      "name": "Rock_Sandstone_Red"
    },
    {
      "x": 1,
      "y": 11,
      "z": 0,
      "name": "Rock_Sandstone_Cobble"
    },
    {
      "x": 1,
      "y": 12,
      "z": 0,
      "name": "Rock_Sandstone_Cobble"
    },
    {
      "x": 1,
      "y": 13,
      "z": 0,
      "name": "Rock_Sandstone_Cobble"
    },
    {
      "x": 1,
      "y": 14,
      "z": 0,
      "name": "Wood_Dry_Trunk"
    },
    {
      "x": 1,
      "y": 15,
      "z": 0,
      "name": "Wood_Dry_Branch_Long"
    },
    {
      "x": 1,
      "y": 16,
      "z": 0,
      "name": "Empty"
    },
    {
      "x": 1,
      "y": 17,
      "z": 0,
      "name": "Empty"
    },
    {
      "x": 1,
      "y": 0,
      "z": 1,
      "name": "Rock_Sandstone_Cobble"
    },
    {
      "x": 1,
      "y": 1,
      "z": 1,
      "name": "Furniture_Village_Pot"
    },
    {
      "x": 1,
      "y": 2,
      "z": 1,
      "name": "Empty"
    },
    {
      "x": 1,
      "y": 3,
      "z": 1,
      "name": "Empty"
    },
    {
      "x": 1,
      "y": 4,
      "z": 1,
      "name": "Empty"
    },
    {
      "x": 1,
      "y": 5,
      "z": 1,
      "name": "Empty"
    },
    {
      "x": 1,
      "y": 9,
      "z": 1,
      "name": "Rock_Sandstone_Red"
    },
    {
      "x": 1,
      "y": 10,
      "z": 1,
      "name": "Rock_Sandstone_Red"
    },
    {
      "x": 1,
      "y": 11,
      "z": 1,
      "name": "Rock_Sandstone_Red"
    },
    {
      "x": 1,
      "y": 12,
      "z": 1,
      "name": "Rock_Sandstone_Cobble"
    },
    {
      "x": 1,
      "y": 13,
      "z": 1,
      "name": "Rock_Sandstone_Red"
    },
    {
      "x": 1,
      "y": 14,
      "z": 1,
      "name": "Wood_Drywood_Planks_Half",
      "rotation": 5
    },
    {
      "x": 1,
      "y": 15,
      "z": 1,
      "name": "Empty"
    },
    {
      "x": 1,
      "y": 16,
      "z": 1,
      "name": "Empty"
    },
    {
      "x": 1,
      "y": 17,
      "z": 1,
      "name": "Empty"
    },
    {
      "x": 1,
      "y": 1,
      "z": 2,
      "name": "Rock_Sandstone_Cobble"
    },
    {
      "x": 1,
      "y": 2,
      "z": 2,
      "name": "Rock_Sandstone_Cobble"
    },
    {
      "x": 1,
      "y": 8,
      "z": 2,
      "name": "Rock_Sandstone_Red"
    },
    {
      "x": 1,
      "y": 9,
      "z": 2,
      "name": "Rock_Sandstone_Red"
    },
    {
      "x": 1,
      "y": 10,
      "z": 2,
      "name": "Rock_Sandstone_Red"
    },
    {
      "x": 1,
      "y": 11,
      "z": 2,
      "name": "Rock_Sandstone_Red"
    },
    {
      "x": 1,
      "y": 12,
      "z": 2,
      "name": "Rock_Sandstone_Red"
    },
    {
      "x": 1,
      "y": 13,
      "z": 2,
      "name": "Soil_Sand_Red"
    },
    {
      "x": 1,
      "y": 14,
      "z": 2,
      "name": "Empty"
    },
    {
      "x": 1,
      "y": 15,
      "z": 2,
      "name": "Empty"
    },
    {
      "x": 1,
      "y": 16,
      "z": 2,
      "name": "Empty"
    },
    {
      "x": 1,
      "y": 17,
      "z": 2,
      "name": "Empty"
    },
    {
      "x": 1,
      "y": 8,
      "z": 3,
      "name": "Rock_Sandstone_Red"
    },
    {
      "x": 1,
      "y": 9,
      "z": 3,
      "name": "Rock_Sandstone_Red"
    },
    {
      "x": 1,
      "y": 10,
      "z": 3,
      "name": "Rock_Sandstone_Red"
    },
    {
      "x": 1,
      "y": 11,
      "z": 3,
      "name": "Rock_Sandstone_Red"
    },
    {
      "x": 1,
      "y": 12,
      "z": 3,
      "name": "Rock_Sandstone_Red"
    },
    {
      "x": 1,
      "y": 13,
      "z": 3,
      "name": "Soil_Sand_Red"
    },
    {
      "x": 1,
      "y": 8,
      "z": 4,
      "name": "Rock_Sandstone_Red"
    },
    {
      "x": 1,
      "y": 9,
      "z": 4,
      "name": "Rock_Sandstone_Red"
    },
    {
      "x": 1,
      "y": 10,
      "z": 4,
      "name": "Rock_Sandstone_Red"
    },
    {
      "x": 1,
      "y": 11,
      "z": 4,
      "name": "Rock_Sandstone_Red"
    },
    {
      "x": 1,
      "y": 12,
      "z": 4,
      "name": "Soil_Sand_Red"
    },
    {
      "x": 1,
      "y": 9,
      "z": 5,
      "name": "Rock_Sandstone_Red"
    },
    {
      "x": 1,
      "y": 10,
      "z": 5,
      "name": "Rock_Sandstone_Red"
    },
    {
      "x": 1,
      "y": 11,
      "z": 5,
      "name": "Rock_Sandstone_Red"
    },
    {
      "x": 1,
      "y": 12,
      "z": 5,
      "name": "Soil_Sand_Red"
    },
    {
      "x": 2,
      "y": 1,
      "z": -1,
      "name": "Rock_Sandstone_Cobble"
    },
    {
      "x": 2,
      "y": 12,
      "z": -1,
      "name": "Rock_Sandstone_Red"
    },
    {
      "x": 2,
      "y": 13,
      "z": -1,
      "name": "Soil_Sand_Red"
    },
    {
      "x": 2,
      "y": 1,
      "z": 0,
      "name": "Rock_Sandstone_Cobble"
    },
    {
      "x": 2,
      "y": 2,
      "z": 0,
      "name": "Rock_Sandstone_Cobble"
    },
    {
      "x": 2,
      "y": 10,
      "z": 0,
      "name": "Rock_Sandstone_Red"
    },
    {
      "x": 2,
      "y": 11,
      "z": 0,
      "name": "Rock_Sandstone_Red"
    },
    {
      "x": 2,
      "y": 12,
      "z": 0,
      "name": "Rock_Sandstone_Red"
    },
    {
      "x": 2,
      "y": 13,
      "z": 0,
      "name": "Rock_Sandstone_Red"
    },
    {
      "x": 2,
      "y": 1,
      "z": 1,
      "name": "Rock_Sandstone_Cobble"
    },
    {
      "x": 2,
      "y": 2,
      "z": 1,
      "name": "Rock_Sandstone_Cobble"
    },
    {
      "x": 2,
      "y": 9,
      "z": 1,
      "name": "Rock_Sandstone_Red"
    },
    {
      "x": 2,
      "y": 10,
      "z": 1,
      "name": "Rock_Sandstone_Red"
    },
    {
      "x": 2,
      "y": 11,
      "z": 1,
      "name": "Rock_Sandstone_Red"
    },
    {
      "x": 2,
      "y": 12,
      "z": 1,
      "name": "Rock_Sandstone_Red"
    },
    {
      "x": 2,
      "y": 13,
      "z": 1,
      "name": "Soil_Sand_Red"
    },
    {
      "x": 2,
      "y": 8,
      "z": 2,
      "name": "Rock_Sandstone_Red"
    },
    {
      "x": 2,
      "y": 9,
      "z": 2,
      "name": "Rock_Sandstone_Red"
    },
    {
      "x": 2,
      "y": 10,
      "z": 2,
      "name": "Rock_Sandstone_Red"
    },
    {
      "x": 2,
      "y": 11,
      "z": 2,
      "name": "Rock_Sandstone_Red"
    },
    {
      "x": 2,
      "y": 12,
      "z": 2,
      "name": "Rock_Sandstone_Red"
    },
    {
      "x": 2,
      "y": 13,
      "z": 2,
      "name": "Soil_Sand_Red"
    },
    {
      "x": 2,
      "y": 8,
      "z": 3,
      "name": "Rock_Sandstone_Red"
    },
    {
      "x": 2,
      "y": 9,
      "z": 3,
      "name": "Rock_Sandstone_Red"
    },
    {
      "x": 2,
      "y": 10,
      "z": 3,
      "name": "Rock_Sandstone_Red"
    },
    {
      "x": 2,
      "y": 11,
      "z": 3,
      "name": "Rock_Sandstone_Red"
    },
    {
      "x": 2,
      "y": 12,
      "z": 3,
      "name": "Rock_Sandstone_Red"
    },
    {
      "x": 2,
      "y": 13,
      "z": 3,
      "name": "Soil_Sand_Red"
    },
    {
      "x": 2,
      "y": 8,
      "z": 4,
      "name": "Rock_Sandstone_Red"
    },
    {
      "x": 2,
      "y": 9,
      "z": 4,
      "name": "Rock_Sandstone_Red"
    },
    {
      "x": 2,
      "y": 10,
      "z": 4,
      "name": "Rock_Sandstone_Red"
    },
    {
      "x": 2,
      "y": 11,
      "z": 4,
      "name": "Rock_Sandstone_Red"
    },
    {
      "x": 2,
      "y": 12,
      "z": 4,
      "name": "Rock_Sandstone_Red"
    },
    {
      "x": 2,
      "y": 13,
      "z": 4,
      "name": "Soil_Sand_Red"
    },
    {
      "x": 2,
      "y": 9,
      "z": 5,
      "name": "Rock_Sandstone_Red"
    },
    {
      "x": 2,
      "y": 10,
      "z": 5,
      "name": "Rock_Sandstone_Red"
    },
    {
      "x": 2,
      "y": 11,
      "z": 5,
      "name": "Rock_Sandstone_Red"
    },
    {
      "x": 2,
      "y": 12,
      "z": 5,
      "name": "Rock_Sandstone_Red"
    },
    {
      "x": 3,
      "y": 10,
      "z": 1,
      "name": "Rock_Sandstone_Red"
    },
    {
      "x": 3,
      "y": 11,
      "z": 1,
      "name": "Rock_Sandstone_Red"
    },
    {
      "x": 3,
      "y": 12,
      "z": 1,
      "name": "Soil_Sand_Red"
    },
    {
      "x": 3,
      "y": 13,
      "z": 1,
      "name": "Soil_Sand_Red"
    },
    {
      "x": 3,
      "y": 9,
      "z": 2,
      "name": "Rock_Sandstone_Red"
    },
    {
      "x": 3,
      "y": 10,
      "z": 2,
      "name": "Rock_Sandstone_Red"
    },
    {
      "x": 3,
      "y": 11,
      "z": 2,
      "name": "Rock_Sandstone_Red"
    },
    {
      "x": 3,
      "y": 12,
      "z": 2,
      "name": "Rock_Sandstone_Red"
    },
    {
      "x": 3,
      "y": 13,
      "z": 2,
      "name": "Soil_Sand_Red"
    },
    {
      "x": 3,
      "y": 9,
      "z": 3,
      "name": "Rock_Sandstone_Red"
    },
    {
      "x": 3,
      "y": 10,
      "z": 3,
      "name": "Rock_Sandstone_Red"
    },
    {
      "x": 3,
      "y": 11,
      "z": 3,
      "name": "Rock_Sandstone_Red"
    },
    {
      "x": 3,
      "y": 12,
      "z": 3,
      "name": "Rock_Sandstone_Red"
    },
    {
      "x": 3,
      "y": 13,
      "z": 3,
      "name": "Soil_Sand_Red"
    },
    {
      "x": 3,
      "y": 9,
      "z": 4,
      "name": "Rock_Sandstone_Red"
    },
    {
      "x": 3,
      "y": 10,
      "z": 4,
      "name": "Rock_Sandstone_Red"
    },
    {
      "x": 3,
      "y": 11,
      "z": 4,
      "name": "Rock_Sandstone_Red"
    },
    {
      "x": 3,
      "y": 12,
      "z": 4,
      "name": "Rock_Sandstone_Red"
    },
    {
      "x": 3,
      "y": 13,
      "z": 4,
      "name": "Soil_Sand_Red"
    },
    {
      "x": 3,
      "y": 14,
      "z": 4,
      "name": "Furniture_Tavern_Barrel"
    },
    {
      "x": 3,
      "y": 9,
      "z": 5,
      "name": "Rock_Sandstone_Red"
    },
    {
      "x": 3,
      "y": 10,
      "z": 5,
      "name": "Rock_Sandstone_Red"
    },
    {
      "x": 3,
      "y": 11,
      "z": 5,
      "name": "Rock_Sandstone_Red"
    },
    {
      "x": 3,
      "y": 12,
      "z": 5,
      "name": "Rock_Sandstone_Red"
    },
    {
      "x": 3,
      "y": 13,
      "z": 5,
      "name": "Soil_Sand_Red"
    },
    {
      "x": 3,
      "y": 10,
      "z": 6,
      "name": "Rock_Sandstone_Red"
    },
    {
      "x": 3,
      "y": 11,
      "z": 6,
      "name": "Rock_Sandstone_Red"
    },
    {
      "x": 3,
      "y": 12,
      "z": 6,
      "name": "Rock_Sandstone_Red"
    },
    {
      "x": 4,
      "y": 11,
      "z": 1,
      "name": "Rock_Sandstone_Red"
    },
    {
      "x": 4,
      "y": 12,
      "z": 1,
      "name": "Rock_Sandstone_Red"
    },
    {
      "x": 4,
      "y": 10,
      "z": 2,
      "name": "Rock_Sandstone_Red"
    },
    {
      "x": 4,
      "y": 11,
      "z": 2,
      "name": "Rock_Sandstone_Red"
    },
    {
      "x": 4,
      "y": 12,
      "z": 2,
      "name": "Rock_Sandstone_Red"
    },
    {
      "x": 4,
      "y": 13,
      "z": 2,
      "name": "Wood_Dry_Trunk"
    },
    {
      "x": 4,
      "y": 14,
      "z": 2,
      "name": "Wood_Dry_Trunk"
    },
    {
      "x": 4,
      "y": 9,
      "z": 3,
      "name": "Rock_Sandstone_Red"
    },
    {
      "x": 4,
      "y": 10,
      "z": 3,
      "name": "Rock_Sandstone_Red"
    },
    {
      "x": 4,
      "y": 11,
      "z": 3,
      "name": "Rock_Sandstone_Red"
    },
    {
      "x": 4,
      "y": 12,
      "z": 3,
      "name": "Rock_Sandstone_Red"
    },
    {
      "x": 4,
      "y": 13,
      "z": 3,
      "name": "Wood_Drywood_Planks"
    },
    {
      "x": 4,
      "y": 14,
      "z": 3,
      "name": "Wood_Drywood_Planks"
    },
    {
      "x": 4,
      "y": 15,
      "z": 3,
      "name": "Wood_Drywood_Planks_Half"
    },
    {
      "x": 4,
      "y": 9,
      "z": 4,
      "name": "Rock_Sandstone_Red"
    },
    {
      "x": 4,
      "y": 10,
      "z": 4,
      "name": "Rock_Sandstone_Red"
    },
    {
      "x": 4,
      "y": 11,
      "z": 4,
      "name": "Rock_Sandstone_Red"
    },
    {
      "x": 4,
      "y": 12,
      "z": 4,
      "name": "Rock_Sandstone_Red"
    },
    {
      "x": 4,
      "y": 13,
      "z": 4,
      "name": "Soil_Sand_Red"
    },
    {
      "x": 4,
      "y": 14,
      "z": 4,
      "name": "Soil_Sand_Red"
    },
    {
      "x": 4,
      "y": 15,
      "z": 4,
      "name": "Wood_Drywood_Planks"
    },
    {
      "x": 4,
      "y": 9,
      "z": 5,
      "name": "Rock_Sandstone_Red"
    },
    {
      "x": 4,
      "y": 10,
      "z": 5,
      "name": "Rock_Sandstone_Red"
    },
    {
      "x": 4,
      "y": 11,
      "z": 5,
      "name": "Rock_Sandstone_Red"
    },
    {
      "x": 4,
      "y": 12,
      "z": 5,
      "name": "Rock_Sandstone_Red"
    },
    {
      "x": 4,
      "y": 13,
      "z": 5,
      "name": "Wood_Dry_Trunk"
    },
    {
      "x": 4,
      "y": 14,
      "z": 5,
      "name": "Wood_Dry_Trunk"
    },
    {
      "x": 4,
      "y": 15,
      "z": 5,
      "name": "Wood_Dry_Trunk"
    },
    {
      "x": 4,
      "y": 16,
      "z": 5,
      "name": "Wood_Dry_Trunk"
    },
    {
      "x": 4,
      "y": 10,
      "z": 6,
      "name": "Rock_Sandstone_Red"
    },
    {
      "x": 4,
      "y": 11,
      "z": 6,
      "name": "Rock_Sandstone_Red"
    },
    {
      "x": 4,
      "y": 12,
      "z": 6,
      "name": "Rock_Sandstone_Red"
    },
    {
      "x": 5,
      "y": 11,
      "z": 2,
      "name": "Rock_Sandstone_Red"
    },
    {
      "x": 5,
      "y": 12,
      "z": 2,
      "name": "Soil_Sand_Red"
    },
    {
      "x": 5,
      "y": 10,
      "z": 3,
      "name": "Rock_Sandstone_Red"
    },
    {
      "x": 5,
      "y": 11,
      "z": 3,
      "name": "Rock_Sandstone_Red"
    },
    {
      "x": 5,
      "y": 12,
      "z": 3,
      "name": "Soil_Sand_Red"
    },
    {
      "x": 5,
      "y": 10,
      "z": 4,
      "name": "Rock_Sandstone_Red"
    },
    {
      "x": 5,
      "y": 11,
      "z": 4,
      "name": "Rock_Sandstone_Red"
    },
    {
      "x": 5,
      "y": 12,
      "z": 4,
      "name": "Rock_Sandstone_Red"
    },
    {
      "x": 5,
      "y": 13,
      "z": 4,
      "name": "Soil_Sand_Red"
    },
    {
      "x": 5,
      "y": 10,
      "z": 5,
      "name": "Rock_Sandstone_Red"
    },
    {
      "x": 5,
      "y": 11,
      "z": 5,
      "name": "Rock_Sandstone_Red"
    },
    {
      "x": 5,
      "y": 12,
      "z": 5,
      "name": "Rock_Sandstone_Red"
    },
    {
      "x": 5,
      "y": 13,
      "z": 5,
      "name": "Wood_Drywood_Planks"
    },
    {
      "x": 5,
      "y": 14,
      "z": 5,
      "name": "Wood_Drywood_Planks"
    },
    {
      "x": 5,
      "y": 15,
      "z": 5,
      "name": "Wood_Drywood_Planks_Half",
      "rotation": 5
    }
  ]
}