{
  "version": 8,
  "blockIdVersion": 8,
  "anchorX": 0,
  "anchorY": 0,
  "anchorZ": 0,
  "blocks": [
    {
      "x": -12,
      "y": 12,
      "z": 9,
      "name": "Rock_Basalt"
    },
    {
      "x": -12,
      "y": 13,
      "z": 9,
      "name": "Rock_Basalt"
    },
    {
      "x": -11,
      "y": 11,
      "z": -9,
      "name": "Rock_Basalt"
    },
    {
      "x": -11,
      "y": 12,
      "z": -9,
      "name": "Rock_Basalt"
    },
    {
      "x": -11,
      "y": 12,
      "z": -8,
      "name": "Rock_Basalt"
    },
    {
      "x": -11,
      "y": 13,
      "z": -8,
      "name": "Rock_Basalt"
    },
    {
      "x": -10,
      "y": 10,
      "z": -9,
      "name": "Rock_Basalt"
    },
    {
      "x": -10,
      "y": 11,
      "z": -9,
      "name": "Rock_Basalt"
    },
    {
      "x": -10,
      "y": 12,
      "z": -9,
      "name": "Rock_Basalt"
    },
    {
      "x": -10,
      "y": 11,
      "z": -8,
      "name": "Rock_Basalt"
    },
    {
      "x": -10,
      "y": 12,
      "z": -8,
      "name": "Rock_Basalt"
    },
    {
      "x": -10,
      "y": 13,
      "z": -8,
      "name": "Rock_Basalt"
    },
    {
      "x": -10,
      "y": 14,
      "z": -7,
      "name": "Rock_Basalt"
    },
    {
      "x": -10,
      "y": 15,
      "z": -6,
      "name": "Rock_Basalt"
    },
    {
      "x": -10,
      "y": 15,
      "z": -5,
      "name": "Rock_Basalt"
    },
    {
      "x": -10,
      "y": 16,
      "z": -5,
      "name": "Rock_Basalt"
    },
    {
      "x": -10,
      "y": 16,
      "z": -4,
      "name": "Rock_Basalt"
    },
    {
      "x": -10,
      "y": 17,
      "z": -4,
      "name": "Rock_Basalt"
    },
    {
      "x": -9,
      "y": 9,
      "z": -10,
      "name": "Rock_Basalt"
    },
    {
      "x": -9,
      "y": 10,
      "z": -10,
      "name": "Rock_Basalt"
    },
    {
      "x": -9,
      "y": 11,
      "z": -10,
      "name": "Rock_Basalt"
    },
    {
      "x": -9,
      "y": 12,
      "z": -10,
      "name": "Rock_Basalt"
    },
    {
      "x": -9,
      "y": 10,
      "z": -9,
      "name": "Rock_Basalt"
    },
    {
      "x": -9,
      "y": 11,
      "z": -9,
      "name": "Rock_Basalt"
    },
    {
      "x": -9,
      "y": 12,
      "z": -9,
      "name": "Rock_Basalt"
    },
    {
      "x": -9,
      "y": 13,
      "z": -9,
      "name": "Rock_Basalt"
    },
    {
      "x": -9,
      "y": 11,
      "z": -8,
      "name": "Rock_Basalt"
    },
    {
      "x": -9,
      "y": 12,
      "z": -8,
      "name": "Rock_Basalt"
    },
    {
      "x": -9,
      "y": 13,
      "z": -8,
      "name": "Rock_Basalt"
    },
    {
      "x": -9,
      "y": 14,
      "z": -8,
      "name": "Rock_Basalt"
    },
    {
      "x": -9,
      "y": 12,
      "z": -7,
      "name": "Rock_Volcanic"
    },
    {
      "x": -9,
      "y": 13,
      "z": -7,
      "name": "Rock_Volcanic"
    },
    {
      "x": -9,
      "y": 14,
      "z": -7,
      "name": "Rock_Basalt"
    },
    {
      "x": -9,
      "y": 15,
      "z": -7,
      "name": "Rock_Basalt"
    },
    {
      "x": -9,
      "y": 13,
      "z": -6,
      "name": "Rock_Volcanic"
    },
    {
      "x": -9,
      "y": 14,
      "z": -6,
      "name": "Rock_Volcanic"
    },
    {
      "x": -9,
      "y": 15,
      "z": -6,
      "name": "Rock_Basalt"
    },
    {
      "x": -9,
      "y": 16,
      "z": -6,
      "name": "Rock_Basalt"
    },
    {
      "x": -9,
      "y": 14,
      "z": -5,
      "name": "Rock_Volcanic"
    },
    {
      "x": -9,
      "y": 15,
      "z": -5,
      "name": "Rock_Volcanic"
    },
    {
      "x": -9,
      "y": 16,
      "z": -5,
      "name": "Rock_Basalt"
    },
    {
      "x": -9,
      "y": 17,
      "z": -5,
      "name": "Rock_Basalt"
    },
    {
      "x": -9,
      "y": 15,
      "z": -4,
      "name": "Rock_Volcanic"
    },
    {
      "x": -9,
      "y": 16,
      "z": -4,
      "name": "Rock_Volcanic"
    },
    {
      "x": -9,
      "y": 17,
      "z": -4,
      "name": "Rock_Basalt"
    },
    {
      "x": -9,
      "y": 18,
      "z": -4,
      "name": "Rock_Basalt"
    },
    {
      "x": -9,
      "y": 18,
      "z": -3,
      "name": "Rock_Basalt"
    },
    {
      "x": -9,
      "y": 19,
      "z": -3,
      "name": "Rock_Basalt"
    },
    {
      "x": -8,
      "y": 9,
      "z": -12,
      "name": "Rock_Basalt"
    },
    {
      "x": -8,
      "y": 10,
      "z": -12,
      "name": "Rock_Basalt"
    },
    {
      "x": -8,
      "y": 11,
      "z": -12,
      "name": "Rock_Basalt"
    },
    {
      "x": -8,
      "y": 12,
      "z": -12,
      "name": "Rock_Basalt"
    },
    {
      "x": -8,
      "y": 9,
      "z": -11,
      "name": "Rock_Basalt"
    },
    {
      "x": -8,
      "y": 10,
      "z": -11,
      "name": "Rock_Basalt"
    },
    {
      "x": -8,
      "y": 11,
      "z": -11,
      "name": "Rock_Basalt"
    },
    {
      "x": -8,
      "y": 12,
      "z": -11,
      "name": "Rock_Basalt"
    },
    {
      "x": -8,
      "y": 10,
      "z": -10,
      "name": "Rock_Basalt"
    },
    {
      "x": -8,
      "y": 11,
      "z": -10,
      "name": "Rock_Basalt"
    },
    {
      "x": -8,
      "y": 12,
      "z": -10,
      "name": "Rock_Basalt"
    },
    {
      "x": -8,
      "y": 13,
      "z": -10,
      "name": "Rock_Basalt"
    },
    {
      "x": -8,
      "y": 11,
      "z": -9,
      "name": "Rock_Basalt"
    },
    {
      "x": -8,
      "y": 12,
      "z": -9,
      "name": "Rock_Basalt"
    },
    {
      "x": -8,
      "y": 13,
      "z": -9,
      "name": "Rock_Basalt"
    },
    {
      "x": -8,
      "y": 12,
      "z": -8,
      "name": "Rock_Basalt"
    },
    {
      "x": -8,
      "y": 13,
      "z": -8,
      "name": "Rock_Basalt"
    },
    {
      "x": -8,
      "y": 14,
      "z": -8,
      "name": "Rock_Basalt"
    },
    {
      "x": -8,
      "y": 15,
      "z": -8,
      "name": "Rock_Basalt"
    },
    {
      "x": -8,
      "y": 13,
      "z": -7,
      "name": "Rock_Volcanic"
    },
    {
      "x": -8,
      "y": 14,
      "z": -7,
      "name": "Rock_Volcanic"
    },
    {
      "x": -8,
      "y": 15,
      "z": -7,
      "name": "Rock_Basalt"
    },
    {
      "x": -8,
      "y": 16,
      "z": -7,
      "name": "Rock_Basalt"
    },
    {
      "x": -8,
      "y": 14,
      "z": -6,
      "name": "Rock_Volcanic"
    },
    {
      "x": -8,
      "y": 15,
      "z": -6,
      "name": "Rock_Volcanic"
    },
    {
      "x": -8,
      "y": 16,
      "z": -6,
      "name": "Rock_Basalt"
    },
    {
      "x": -8,
      "y": 17,
      "z": -6,
      "name": "Rock_Basalt"
    },
    {
      "x": -8,
      "y": 15,
      "z": -5,
      "name": "Rock_Volcanic"
    },
    {
      "x": -8,
      "y": 16,
      "z": -5,
      "name": "Rock_Volcanic"
    },
    {
      "x": -8,
      "y": 17,
      "z": -5,
      "name": "Rock_Basalt"
    },
    {
      "x": -8,
      "y": 18,
      "z": -5,
      "name": "Rock_Basalt"
    },
    {
      "x": -8,
      "y": 16,
      "z": -4,
      "name": "Rock_Volcanic"
    },
    {
      "x": -8,
      "y": 17,
      "z": -4,
      "name": "Rock_Volcanic"
    },
    {
      "x": -8,
      "y": 18,
      "z": -4,
      "name": "Rock_Basalt"
    },
    {
      "x": -8,
      "y": 19,
      "z": -4,
      "name": "Rock_Basalt"
    },
    {
      "x": -8,
      "y": 18,
      "z": -3,
      "name": "Rock_Basalt"
    },
    {
      "x": -8,
      "y": 19,
      "z": -3,
      "name": "Rock_Basalt"
    },
    {
      "x": -8,
      "y": 12,
      "z": 12,
      "name": "Rock_Basalt"
    },
    {
      "x": -8,
      "y": 13,
      "z": 12,
      "name": "Rock_Basalt"
    },
    {
      "x": -8,
      "y": 9,
      "z": 13,
      "name": "Rock_Basalt"
    },
    {
      "x": -8,
      "y": 10,
      "z": 13,
      "name": "Rock_Basalt"
    },
    {
      "x": -8,
      "y": 11,
      "z": 13,
      "name": "Rock_Basalt"
    },
    {
      "x": -8,
      "y": 12,
      "z": 13,
      "name": "Rock_Basalt"
    },
    {
      "x": -7,
      "y": 9,
      "z": -16,
      "name": "Rock_Basalt"
    },
    {
      "x": -7,
      "y": 10,
      "z": -16,
      "name": "Rock_Basalt"
    },
    {
      "x": -7,
      "y": 11,
      "z": -16,
      "name": "Rock_Basalt"
    },
    {
      "x": -7,
      "y": 12,
      "z": -16,
      "name": "Rock_Basalt"
    },
    {
      "x": -7,
      "y": 9,
      "z": -15,
      "name": "Rock_Basalt"
    },
    {
      "x": -7,
      "y": 10,
      "z": -15,
      "name": "Rock_Basalt"
    },
    {
      "x": -7,
      "y": 11,
      "z": -15,
      "name": "Rock_Basalt"
    },
    {
      "x": -7,
      "y": 12,
      "z": -15,
      "name": "Rock_Basalt"
    },
    {
      "x": -7,
      "y": 10,
      "z": -14,
      "name": "Rock_Basalt"
    },
    {
      "x": -7,
      "y": 11,
      "z": -14,
      "name": "Rock_Basalt"
    },
    {
      "x": -7,
      "y": 12,
      "z": -14,
      "name": "Rock_Basalt"
    },
    {
      "x": -7,
      "y": 10,
      "z": -13,
      "name": "Rock_Basalt"
    },
    {
      "x": -7,
      "y": 11,
      "z": -13,
      "name": "Rock_Basalt"
    },
    {
      "x": -7,
      "y": 12,
      "z": -13,
      "name": "Rock_Basalt"
    },
    {
      "x": -7,
      "y": 10,
      "z": -12,
      "name": "Rock_Basalt"
    },
    {
      "x": -7,
      "y": 11,
      "z": -12,
      "name": "Rock_Basalt"
    },
    {
      "x": -7,
      "y": 12,
      "z": -12,
      "name": "Rock_Basalt"
    },
    {
      "x": -7,
      "y": 13,
      "z": -12,
      "name": "Rock_Basalt"
    },
    {
      "x": -7,
      "y": 10,
      "z": -11,
      "name": "Rock_Basalt"
    },
    {
      "x": -7,
      "y": 11,
      "z": -11,
      "name": "Rock_Basalt"
    },
    {
      "x": -7,
      "y": 12,
      "z": -11,
      "name": "Rock_Basalt"
    },
    {
      "x": -7,
      "y": 13,
      "z": -11,
      "name": "Rock_Basalt"
    },
    {
      "x": -7,
      "y": 10,
      "z": -10,
      "name": "Rock_Basalt"
    },
    {
      "x": -7,
      "y": 11,
      "z": -10,
      "name": "Rock_Basalt"
    },
    {
      "x": -7,
      "y": 12,
      "z": -10,
      "name": "Rock_Basalt"
    },
    {
      "x": -7,
      "y": 13,
      "z": -10,
      "name": "Rock_Basalt"
    },
    {
      "x": -7,
      "y": 11,
      "z": -9,
      "name": "Rock_Basalt"
    },
    {
      "x": -7,
      "y": 12,
      "z": -9,
      "name": "Rock_Basalt"
    },
    {
      "x": -7,
      "y": 13,
      "z": -9,
      "name": "Rock_Basalt"
    },
    {
      "x": -7,
      "y": 14,
      "z": -9,
      "name": "Rock_Basalt"
    },
    {
      "x": -7,
      "y": 12,
      "z": -8,
      "name": "Rock_Volcanic"
    },
    {
      "x": -7,
      "y": 13,
      "z": -8,
      "name": "Rock_Volcanic"
    },
    {
      "x": -7,
      "y": 14,
      "z": -8,
      "name": "Rock_Basalt"
    },
    {
      "x": -7,
      "y": 15,
      "z": -8,
      "name": "Rock_Basalt"
    },
    {
      "x": -7,
      "y": 13,
      "z": -7,
      "name": "Rock_Volcanic"
    },
    {
      "x": -7,
      "y": 14,
      "z": -7,
      "name": "Rock_Volcanic"
    },
    {
      "x": -7,
      "y": 15,
      "z": -7,
      "name": "Rock_Basalt"
    },
    {
      "x": -7,
      "y": 16,
      "z": -7,
      "name": "Rock_Basalt"
    },
    {
      "x": -7,
      "y": 14,
      "z": -6,
      "name": "Rock_Volcanic"
    },
    {
      "x": -7,
      "y": 15,
      "z": -6,
      "name": "Rock_Volcanic"
    },
    {
      "x": -7,
      "y": 16,
      "z": -6,
      "name": "Rock_Basalt"
    },
    {
      "x": -7,
      "y": 17,
      "z": -6,
      "name": "Rock_Basalt"
    },
    {
      "x": -7,
      "y": 15,
      "z": -5,
      "name": "Rock_Volcanic"
    },
    {
      "x": -7,
      "y": 16,
      "z": -5,
      "name": "Rock_Volcanic"
    },
    {
      "x": -7,
      "y": 17,
      "z": -5,
      "name": "Rock_Basalt"
    },
    {
      "x": -7,
      "y": 18,
      "z": -5,
      "name": "Rock_Basalt"
    },
    {
      "x": -7,
      "y": 16,
      "z": -4,
      "name": "Rock_Volcanic"
    },
    {
      "x": -7,
      "y": 17,
      "z": -4,
      "name": "Rock_Volcanic"
    },
    {
      "x": -7,
      "y": 18,
      "z": -4,
      "name": "Rock_Basalt"
    },
    {
      "x": -7,
      "y": 19,
      "z": -4,
      "name": "Rock_Basalt"
    },
    {
      "x": -7,
      "y": 19,
      "z": -3,
      "name": "Rock_Basalt"
    },
    {
      "x": -7,
      "y": 20,
      "z": -3,
      "name": "Rock_Basalt"
    },
    {
      "x": -7,
      "y": 21,
      "z": -2,
      "name": "Rock_Basalt"
    },
    {
      "x": -7,
      "y": 21,
      "z": 6,
      "name": "Rock_Basalt"
    },
    {
      "x": -7,
      "y": 20,
      "z": 8,
      "name": "Rock_Basalt"
    },
    {
      "x": -7,
      "y": 19,
      "z": 9,
      "name": "Rock_Basalt"
    },
    {
      "x": -7,
      "y": 16,
      "z": 10,
      "name": "Rock_Basalt"
    },
    {
      "x": -7,
      "y": 17,
      "z": 10,
      "name": "Rock_Basalt"
    },
    {
      "x": -7,
      "y": 13,
      "z": 11,
      "name": "Rock_Volcanic"
    },
    {
      "x": -7,
      "y": 14,
      "z": 11,
      "name": "Rock_Volcanic"
    },
    {
      "x": -7,
      "y": 15,
      "z": 11,
      "name": "Rock_Basalt"
    },
    {
      "x": -7,
      "y": 16,
      "z": 11,
      "name": "Rock_Basalt"
    },
    {
      "x": -7,
      "y": 12,
      "z": 12,
      "name": "Rock_Basalt"
    },
    {
      "x": -7,
      "y": 13,
      "z": 12,
      "name": "Rock_Basalt"
    },
    {
      "x": -7,
      "y": 14,
      "z": 12,
      "name": "Rock_Basalt"
    },
    {
      "x": -7,
      "y": 10,
      "z": 13,
      "name": "Rock_Basalt"
    },
    {
      "x": -7,
      "y": 11,
      "z": 13,
      "name": "Rock_Basalt"
    },
    {
      "x": -7,
      "y": 12,
      "z": 13,
      "name": "Rock_Basalt"
    },
    {
      "x": -7,
      "y": 13,
      "z": 13,
      "name": "Rock_Basalt"
    },
    {
      "x": -7,
      "y": 9,
      "z": 14,
      "name": "Rock_Basalt"
    },
    {
      "x": -7,
      "y": 10,
      "z": 14,
      "name": "Rock_Basalt"
    },
    {
      "x": -7,
      "y": 11,
      "z": 14,
      "name": "Rock_Basalt"
    },
    {
      "x": -7,
      "y": 12,
      "z": 14,
      "name": "Rock_Basalt"
    },
    {
      "x": -6,
      "y": 9,
      "z": -16,
      "name": "Rock_Basalt"
    },
    {
      "x": -6,
      "y": 10,
      "z": -16,
      "name": "Rock_Basalt"
    },
    {
      "x": -6,
      "y": 11,
      "z": -16,
      "name": "Rock_Basalt"
    },
    {
      "x": -6,
      "y": 12,
      "z": -16,
      "name": "Rock_Basalt"
    },
    {
      "x": -6,
      "y": 10,
      "z": -15,
      "name": "Rock_Basalt"
    },
    {
      "x": -6,
      "y": 11,
      "z": -15,
      "name": "Rock_Basalt"
    },
    {
      "x": -6,
      "y": 12,
      "z": -15,
      "name": "Rock_Basalt"
    },
    {
      "x": -6,
      "y": 10,
      "z": -14,
      "name": "Rock_Basalt"
    },
    {
      "x": -6,
      "y": 11,
      "z": -14,
      "name": "Rock_Basalt"
    },
    {
      "x": -6,
      "y": 12,
      "z": -14,
      "name": "Rock_Basalt"
    },
    {
      "x": -6,
      "y": 13,
      "z": -14,
      "name": "Rock_Basalt"
    },
    {
      "x": -6,
      "y": 10,
      "z": -13,
      "name": "Rock_Basalt"
    },
    {
      "x": -6,
      "y": 11,
      "z": -13,
      "name": "Rock_Basalt"
    },
    {
      "x": -6,
      "y": 12,
      "z": -13,
      "name": "Rock_Basalt"
    },
    {
      "x": -6,
      "y": 13,
      "z": -13,
      "name": "Rock_Basalt"
    },
    {
      "x": -6,
      "y": 10,
      "z": -12,
      "name": "Rock_Basalt"
    },
    {
      "x": -6,
      "y": 11,
      "z": -12,
      "name": "Rock_Basalt"
    },
    {
      "x": -6,
      "y": 12,
      "z": -12,
      "name": "Rock_Basalt"
    },
    {
      "x": -6,
      "y": 13,
      "z": -12,
      "name": "Rock_Basalt"
    },
    {
      "x": -6,
      "y": 11,
      "z": -11,
      "name": "Rock_Basalt"
    },
    {
      "x": -6,
      "y": 12,
      "z": -11,
      "name": "Rock_Basalt"
    },
    {
      "x": -6,
      "y": 13,
      "z": -11,
      "name": "Rock_Basalt"
    },
    {
      "x": -6,
      "y": 14,
      "z": -11,
      "name": "Rock_Basalt"
    },
    {
      "x": -6,
      "y": 11,
      "z": -10,
      "name": "Rock_Basalt"
    },
    {
      "x": -6,
      "y": 12,
      "z": -10,
      "name": "Rock_Basalt"
    },
    {
      "x": -6,
      "y": 13,
      "z": -10,
      "name": "Rock_Basalt"
    },
    {
      "x": -6,
      "y": 14,
      "z": -10,
      "name": "Rock_Basalt"
    },
    {
      "x": -6,
      "y": 12,
      "z": -9,
      "name": "Rock_Basalt"
    },
    {
      "x": -6,
      "y": 13,
      "z": -9,
      "name": "Rock_Basalt"
    },
    {
      "x": -6,
      "y": 14,
      "z": -9,
      "name": "Rock_Basalt"
    },
    {
      "x": -6,
      "y": 15,
      "z": -9,
      "name": "Rock_Basalt"
    },
    {
      "x": -6,
      "y": 13,
      "z": -8,
      "name": "Rock_Volcanic"
    },
    {
      "x": -6,
      "y": 14,
      "z": -8,
      "name": "Rock_Volcanic"
    },
    {
      "x": -6,
      "y": 15,
      "z": -8,
      "name": "Rock_Basalt"
    },
    {
      "x": -6,
      "y": 16,
      "z": -8,
      "name": "Rock_Basalt"
    },
    {
      "x": -6,
      "y": 14,
      "z": -7,
      "name": "Rock_Volcanic"
    },
    {
      "x": -6,
      "y": 15,
      "z": -7,
      "name": "Rock_Volcanic"
    },
    {
      "x": -6,
      "y": 16,
      "z": -7,
      "name": "Rock_Basalt"
    },
    {
      "x": -6,
      "y": 17,
      "z": -7,
      "name": "Rock_Basalt"
    },
    {
      "x": -6,
      "y": 15,
      "z": -6,
      "name": "Rock_Volcanic"
    },
    {
      "x": -6,
      "y": 16,
      "z": -6,
      "name": "Rock_Volcanic"
    },
    {
      "x": -6,
      "y": 17,
      "z": -6,
      "name": "Rock_Basalt"
    },
    {
      "x": -6,
      "y": 18,
      "z": -6,
      "name": "Rock_Basalt"
    },
    {
      "x": -6,
      "y": 16,
      "z": -5,
      "name": "Rock_Volcanic"
    },
    {
      "x": -6,
      "y": 17,
      "z": -5,
      "name": "Rock_Volcanic"
    },
    {
      "x": -6,
      "y": 18,
      "z": -5,
      "name": "Rock_Basalt"
    },
    {
      "x": -6,
      "y": 19,
      "z": -5,
      "name": "Rock_Basalt"
    },
    {
      "x": -6,
      "y": 17,
      "z": -4,
      "name": "Rock_Volcanic"
    },
    {
      "x": -6,
      "y": 18,
      "z": -4,
      "name": "Rock_Volcanic"
    },
    {
      "x": -6,
      "y": 19,
      "z": -4,
      "name": "Rock_Basalt"
    },
    {
      "x": -6,
      "y": 20,
      "z": -4,
      "name": "Rock_Basalt"
    },
    {
      "x": -6,
      "y": 19,
      "z": -3,
      "name": "Rock_Basalt"
    },
    {
      "x": -6,
      "y": 20,
      "z": -3,
      "name": "Rock_Basalt"
    },
    {
      "x": -6,
      "y": 21,
      "z": -3,
      "name": "Rock_Basalt"
    },
    {
      "x": -6,
      "y": 22,
      "z": 2,
      "name": "Rock_Basalt"
    },
    {
      "x": -6,
      "y": 22,
      "z": 3,
      "name": "Rock_Basalt"
    },
    {
      "x": -6,
      "y": 21,
      "z": 4,
      "name": "Rock_Basalt"
    },
    {
      "x": -6,
      "y": 22,
      "z": 4,
      "name": "Rock_Basalt"
    },
    {
      "x": -6,
      "y": 21,
      "z": 5,
      "name": "Rock_Basalt"
    },
    {
      "x": -6,
      "y": 22,
      "z": 5,
      "name": "Rock_Basalt"
    },
    {
      "x": -6,
      "y": 18,
      "z": 6,
      "name": "Rock_Volcanic"
    },
    {
      "x": -6,
      "y": 19,
      "z": 6,
      "name": "Rock_Volcanic"
    },
    {
      "x": -6,
      "y": 20,
      "z": 6,
      "name": "Rock_Basalt"
    },
    {
      "x": -6,
      "y": 21,
      "z": 6,
      "name": "Rock_Basalt"
    },
    {
      "x": -6,
      "y": 22,
      "z": 6,
      "name": "Rock_Basalt"
    },
    {
      "x": -6,
      "y": 18,
      "z": 7,
      "name": "Rock_Volcanic"
    },
    {
      "x": -6,
      "y": 19,
      "z": 7,
      "name": "Rock_Volcanic"
    },
    {
      "x": -6,
      "y": 20,
      "z": 7,
      "name": "Rock_Basalt"
    },
    {
      "x": -6,
      "y": 21,
      "z": 7,
      "name": "Rock_Basalt"
    },
    {
      "x": -6,
      "y": 17,
      "z": 8,
      "name": "Rock_Volcanic"
    },
    {
      "x": -6,
      "y": 18,
      "z": 8,
      "name": "Rock_Volcanic"
    },
    {
      "x": -6,
      "y": 19,
      "z": 8,
      "name": "Rock_Basalt"
    },
    {
      "x": -6,
      "y": 20,
      "z": 8,
      "name": "Rock_Basalt"
    },
    {
      "x": -6,
      "y": 21,
      "z": 8,
      "name": "Rock_Basalt"
    },
    {
      "x": -6,
      "y": 16,
      "z": 9,
      "name": "Rock_Volcanic"
    },
    {
      "x": -6,
      "y": 17,
      "z": 9,
      "name": "Rock_Volcanic"
    },
    {
      "x": -6,
      "y": 18,
      "z": 9,
      "name": "Rock_Basalt"
    },
    {
      "x": -6,
      "y": 19,
      "z": 9,
      "name": "Rock_Basalt"
    },
    {
      "x": -6,
      "y": 20,
      "z": 9,
      "name": "Rock_Basalt"
    },
    {
      "x": -6,
      "y": 15,
      "z": 10,
      "name": "Rock_Volcanic"
    },
    {
      "x": -6,
      "y": 16,
      "z": 10,
      "name": "Rock_Volcanic"
    },
    {
      "x": -6,
      "y": 17,
      "z": 10,
      "name": "Rock_Basalt"
    },
    {
      "x": -6,
      "y": 18,
      "z": 10,
      "name": "Rock_Basalt"
    },
    {
      "x": -6,
      "y": 14,
      "z": 11,
      "name": "Rock_Volcanic"
    },
    {
      "x": -6,
      "y": 15,
      "z": 11,
      "name": "Rock_Volcanic"
    },
    {
      "x": -6,
      "y": 16,
      "z": 11,
      "name": "Rock_Basalt"
    },
    {
      "x": -6,
      "y": 17,
      "z": 11,
      "name": "Rock_Basalt"
    },
    {
      "x": -6,
      "y": 13,
      "z": 12,
      "name": "Rock_Volcanic"
    },
    {
      "x": -6,
      "y": 14,
      "z": 12,
      "name": "Rock_Volcanic"
    },
    {
      "x": -6,
      "y": 15,
      "z": 12,
      "name": "Rock_Basalt"
    },
    {
      "x": -6,
      "y": 16,
      "z": 12,
      "name": "Rock_Basalt"
    },
    {
      "x": -6,
      "y": 11,
      "z": 13,
      "name": "Rock_Basalt"
    },
    {
      "x": -6,
      "y": 12,
      "z": 13,
      "name": "Rock_Basalt"
    },
    {
      "x": -6,
      "y": 13,
      "z": 13,
      "name": "Rock_Basalt"
    },
    {
      "x": -6,
      "y": 14,
      "z": 13,
      "name": "Rock_Basalt"
    },
    {
      "x": -6,
      "y": 11,
      "z": 14,
      "name": "Rock_Basalt"
    },
    {
      "x": -6,
      "y": 12,
      "z": 14,
      "name": "Rock_Basalt"
    },
    {
      "x": -6,
      "y": 13,
      "z": 14,
      "name": "Rock_Basalt"
    },
    {
      "x": -6,
      "y": 10,
      "z": 15,
      "name": "Rock_Basalt"
    },
    {
      "x": -6,
      "y": 11,
      "z": 15,
      "name": "Rock_Basalt"
    },
    {
      "x": -6,
      "y": 12,
      "z": 15,
      "name": "Rock_Basalt"
    },
    {
      "x": -5,
      "y": 9,
      "z": -16,
      "name": "Rock_Basalt"
    },
    {
      "x": -5,
      "y": 10,
      "z": -16,
      "name": "Rock_Basalt"
    },
    {
      "x": -5,
      "y": 11,
      "z": -16,
      "name": "Rock_Basalt"
    },
    {
      "x": -5,
      "y": 12,
      "z": -16,
      "name": "Rock_Basalt"
    },
    {
      "x": -5,
      "y": 10,
      "z": -15,
      "name": "Rock_Basalt"
    },
    {
      "x": -5,
      "y": 11,
      "z": -15,
      "name": "Rock_Basalt"
    },
    {
      "x": -5,
      "y": 12,
      "z": -15,
      "name": "Rock_Basalt"
    },
    {
      "x": -5,
      "y": 10,
      "z": -14,
      "name": "Rock_Basalt"
    },
    {
      "x": -5,
      "y": 11,
      "z": -14,
      "name": "Rock_Basalt"
    },
    {
      "x": -5,
      "y": 12,
      "z": -14,
      "name": "Rock_Basalt"
    },
    {
      "x": -5,
      "y": 13,
      "z": -14,
      "name": "Rock_Basalt"
    },
    {
      "x": -5,
      "y": 11,
      "z": -13,
      "name": "Rock_Basalt"
    },
    {
      "x": -5,
      "y": 12,
      "z": -13,
      "name": "Rock_Basalt"
    },
    {
      "x": -5,
      "y": 13,
      "z": -13,
      "name": "Rock_Basalt"
    },
    {
      "x": -5,
      "y": 11,
      "z": -12,
      "name": "Rock_Basalt"
    },
    {
      "x": -5,
      "y": 12,
      "z": -12,
      "name": "Rock_Basalt"
    },
    {
      "x": -5,
      "y": 13,
      "z": -12,
      "name": "Rock_Basalt"
    },
    {
      "x": -5,
      "y": 14,
      "z": -12,
      "name": "Rock_Basalt"
    },
    {
      "x": -5,
      "y": 11,
      "z": -11,
      "name": "Rock_Basalt"
    },
    {
      "x": -5,
      "y": 12,
      "z": -11,
      "name": "Rock_Basalt"
    },
    {
      "x": -5,
      "y": 13,
      "z": -11,
      "name": "Rock_Basalt"
    },
    {
      "x": -5,
      "y": 14,
      "z": -11,
      "name": "Rock_Basalt"
    },
    {
      "x": -5,
      "y": 12,
      "z": -10,
      "name": "Rock_Basalt"
    },
    {
      "x": -5,
      "y": 13,
      "z": -10,
      "name": "Rock_Basalt"
    },
    {
      "x": -5,
      "y": 14,
      "z": -10,
      "name": "Rock_Basalt"
    },
    {
      "x": -5,
      "y": 15,
      "z": -10,
      "name": "Rock_Basalt"
    },
    {
      "x": -5,
      "y": 12,
      "z": -9,
      "name": "Rock_Volcanic"
    },
    {
      "x": -5,
      "y": 13,
      "z": -9,
      "name": "Rock_Volcanic"
    },
    {
      "x": -5,
      "y": 14,
      "z": -9,
      "name": "Rock_Basalt"
    },
    {
      "x": -5,
      "y": 15,
      "z": -9,
      "name": "Rock_Basalt"
    },
    {
      "x": -5,
      "y": 13,
      "z": -8,
      "name": "Rock_Volcanic"
    },
    {
      "x": -5,
      "y": 14,
      "z": -8,
      "name": "Rock_Volcanic"
    },
    {
      "x": -5,
      "y": 15,
      "z": -8,
      "name": "Rock_Basalt"
    },
    {
      "x": -5,
      "y": 16,
      "z": -8,
      "name": "Rock_Basalt"
    },
    {
      "x": -5,
      "y": 14,
      "z": -7,
      "name": "Rock_Volcanic"
    },
    {
      "x": -5,
      "y": 15,
      "z": -7,
      "name": "Rock_Volcanic"
    },
    {
      "x": -5,
      "y": 16,
      "z": -7,
      "name": "Rock_Basalt"
    },
    {
      "x": -5,
      "y": 17,
      "z": -7,
      "name": "Rock_Basalt"
    },
    {
      "x": -5,
      "y": 15,
      "z": -6,
      "name": "Rock_Volcanic"
    },
    {
      "x": -5,
      "y": 16,
      "z": -6,
      "name": "Rock_Volcanic"
    },
    {
      "x": -5,
      "y": 17,
      "z": -6,
      "name": "Rock_Basalt"
    },
    {
      "x": -5,
      "y": 18,
      "z": -6,
      "name": "Rock_Basalt"
    },
    {
      "x": -5,
      "y": 16,
      "z": -5,
      "name": "Rock_Volcanic"
    },
    {
      "x": -5,
      "y": 17,
      "z": -5,
      "name": "Rock_Volcanic"
    },
    {
      "x": -5,
      "y": 18,
      "z": -5,
      "name": "Rock_Basalt"
    },
    {
      "x": -5,
      "y": 19,
      "z": -5,
      "name": "Rock_Basalt"
    },
    {
      "x": -5,
      "y": 17,
      "z": -4,
      "name": "Rock_Volcanic"
    },
    {
      "x": -5,
      "y": 18,
      "z": -4,
      "name": "Rock_Volcanic"
    },
    {
      "x": -5,
      "y": 19,
      "z": -4,
      "name": "Rock_Basalt"
    },
    {
      "x": -5,
      "y": 20,
      "z": -4,
      "name": "Rock_Basalt"
    },
    {
      "x": -5,
      "y": 20,
      "z": -3,
      "name": "Rock_Basalt"
    },
    {
      "x": -5,
      "y": 21,
      "z": -3,
      "name": "Rock_Basalt"
    },
    {
      "x": -5,
      "y": 21,
      "z": 3,
      "name": "Rock_Basalt"
    },
    {
      "x": -5,
      "y": 22,
      "z": 3,
      "name": "Rock_Basalt"
    },
    {
      "x": -5,
      "y": 19,
      "z": 4,
      "name": "Rock_Volcanic"
    },
    {
      "x": -5,
      "y": 20,
      "z": 4,
      "name": "Rock_Volcanic"
    },
    {
      "x": -5,
      "y": 21,
      "z": 4,
      "name": "Rock_Basalt"
    },
    {
      "x": -5,
      "y": 22,
      "z": 4,
      "name": "Rock_Basalt"
    },
    {
      "x": -5,
      "y": 23,
      "z": 4,
      "name": "Rock_Basalt"
    },
    {
      "x": -5,
      "y": 19,
      "z": 5,
      "name": "Rock_Volcanic"
    },
    {
      "x": -5,
      "y": 20,
      "z": 5,
      "name": "Rock_Volcanic"
    },
    {
      "x": -5,
      "y": 21,
      "z": 5,
      "name": "Rock_Basalt"
    },
    {
      "x": -5,
      "y": 22,
      "z": 5,
      "name": "Rock_Basalt"
    },
    {
      "x": -5,
      "y": 23,
      "z": 5,
      "name": "Rock_Basalt"
    },
    {
      "x": -5,
      "y": 19,
      "z": 6,
      "name": "Rock_Volcanic"
    },
    {
      "x": -5,
      "y": 20,
      "z": 6,
      "name": "Rock_Volcanic"
    },
    {
      "x": -5,
      "y": 21,
      "z": 6,
      "name": "Rock_Basalt"
    },
    {
      "x": -5,
      "y": 22,
      "z": 6,
      "name": "Rock_Basalt"
    },
    {
      "x": -5,
      "y": 19,
      "z": 7,
      "name": "Rock_Volcanic"
    },
    {
      "x": -5,
      "y": 20,
      "z": 7,
      "name": "Rock_Volcanic"
    },
    {
      "x": -5,
      "y": 21,
      "z": 7,
      "name": "Rock_Basalt"
    },
    {
      "x": -5,
      "y": 22,
      "z": 7,
      "name": "Rock_Basalt"
    },
    {
      "x": -5,
      "y": 18,
      "z": 8,
      "name": "Rock_Volcanic"
    },
    {
      "x": -5,
      "y": 19,
      "z": 8,
      "name": "Rock_Volcanic"
    },
    {
      "x": -5,
      "y": 20,
      "z": 8,
      "name": "Rock_Basalt"
    },
    {
      "x": -5,
      "y": 21,
      "z": 8,
      "name": "Rock_Basalt"
    },
    {
      "x": -5,
      "y": 17,
      "z": 9,
      "name": "Rock_Volcanic"
    },
    {
      "x": -5,
      "y": 18,
      "z": 9,
      "name": "Rock_Volcanic"
    },
    {
      "x": -5,
      "y": 19,
      "z": 9,
      "name": "Rock_Basalt"
    },
    {
      "x": -5,
      "y": 20,
      "z": 9,
      "name": "Rock_Basalt"
    },
    {
      "x": -5,
      "y": 16,
      "z": 10,
      "name": "Rock_Volcanic"
    },
    {
      "x": -5,
      "y": 17,
      "z": 10,
      "name": "Rock_Volcanic"
    },
    {
      "x": -5,
      "y": 18,
      "z": 10,
      "name": "Rock_Basalt"
    },
    {
      "x": -5,
      "y": 19,
      "z": 10,
      "name": "Rock_Basalt"
    },
    {
      "x": -5,
      "y": 15,
      "z": 11,
      "name": "Rock_Volcanic"
    },
    {
      "x": -5,
      "y": 16,
      "z": 11,
      "name": "Rock_Volcanic"
    },
    {
      "x": -5,
      "y": 17,
      "z": 11,
      "name": "Rock_Basalt"
    },
    {
      "x": -5,
      "y": 18,
      "z": 11,
      "name": "Rock_Basalt"
    },
    {
      "x": -5,
      "y": 14,
      "z": 12,
      "name": "Rock_Volcanic"
    },
    {
      "x": -5,
      "y": 15,
      "z": 12,
      "name": "Rock_Volcanic"
    },
    {
      "x": -5,
      "y": 16,
      "z": 12,
      "name": "Rock_Basalt"
    },
    {
      "x": -5,
      "y": 12,
      "z": 13,
      "name": "Rock_Volcanic"
    },
    {
      "x": -5,
      "y": 13,
      "z": 13,
      "name": "Rock_Volcanic"
    },
    {
      "x": -5,
      "y": 14,
      "z": 13,
      "name": "Rock_Basalt"
    },
    {
      "x": -5,
      "y": 15,
      "z": 13,
      "name": "Rock_Basalt"
    },
    {
      "x": -5,
      "y": 11,
      "z": 14,
      "name": "Rock_Basalt"
    },
    {
      "x": -5,
      "y": 12,
      "z": 14,
      "name": "Rock_Basalt"
    },
    {
      "x": -5,
      "y": 13,
      "z": 14,
      "name": "Rock_Basalt"
    },
    {
      "x": -5,
      "y": 14,
      "z": 14,
      "name": "Rock_Basalt"
    },
    {
      "x": -5,
      "y": 11,
      "z": 15,
      "name": "Rock_Basalt"
    },
    {
      "x": -5,
      "y": 12,
      "z": 15,
      "name": "Rock_Basalt"
    },
    {
      "x": -5,
      "y": 13,
      "z": 15,
      "name": "Rock_Basalt"
    },
    {
      "x": -5,
      "y": 10,
      "z": 16,
      "name": "Rock_Basalt"
    },
    {
      "x": -5,
      "y": 11,
      "z": 16,
      "name": "Rock_Basalt"
    },
    {
      "x": -5,
      "y": 12,
      "z": 16,
      "name": "Rock_Basalt"
    },
    {
      "x": -4,
      "y": 9,
      "z": -16,
      "name": "Rock_Basalt"
    },
    {
      "x": -4,
      "y": 10,
      "z": -16,
      "name": "Rock_Basalt"
    },
    {
      "x": -4,
      "y": 11,
      "z": -16,
      "name": "Rock_Basalt"
    },
    {
      "x": -4,
      "y": 12,
      "z": -16,
      "name": "Rock_Basalt"
    },
    {
      "x": -4,
      "y": 10,
      "z": -15,
      "name": "Rock_Basalt"
    },
    {
      "x": -4,
      "y": 11,
      "z": -15,
      "name": "Rock_Basalt"
    },
    {
      "x": -4,
      "y": 12,
      "z": -15,
      "name": "Rock_Basalt"
    },
    {
      "x": -4,
      "y": 13,
      "z": -15,
      "name": "Rock_Basalt"
    },
    {
      "x": -4,
      "y": 10,
      "z": -14,
      "name": "Rock_Basalt"
    },
    {
      "x": -4,
      "y": 11,
      "z": -14,
      "name": "Rock_Basalt"
    },
    {
      "x": -4,
      "y": 12,
      "z": -14,
      "name": "Rock_Basalt"
    },
    {
      "x": -4,
      "y": 13,
      "z": -14,
      "name": "Rock_Basalt"
    },
    {
      "x": -4,
      "y": 11,
      "z": -13,
      "name": "Rock_Basalt"
    },
    {
      "x": -4,
      "y": 12,
      "z": -13,
      "name": "Rock_Basalt"
    },
    {
      "x": -4,
      "y": 13,
      "z": -13,
      "name": "Rock_Basalt"
    },
    {
      "x": -4,
      "y": 14,
      "z": -13,
      "name": "Rock_Basalt"
    },
    {
      "x": -4,
      "y": 12,
      "z": -12,
      "name": "Rock_Basalt"
    },
    {
      "x": -4,
      "y": 13,
      "z": -12,
      "name": "Rock_Basalt"
    },
    {
      "x": -4,
      "y": 14,
      "z": -12,
      "name": "Rock_Basalt"
    },
    {
      "x": -4,
      "y": 12,
      "z": -11,
      "name": "Rock_Basalt"
    },
    {
      "x": -4,
      "y": 13,
      "z": -11,
      "name": "Rock_Basalt"
    },
    {
      "x": -4,
      "y": 14,
      "z": -11,
      "name": "Rock_Basalt"
    },
    {
      "x": -4,
      "y": 15,
      "z": -11,
      "name": "Rock_Basalt"
    },
    {
      "x": -4,
      "y": 12,
      "z": -10,
      "name": "Rock_Volcanic"
    },
    {
      "x": -4,
      "y": 13,
      "z": -10,
      "name": "Rock_Volcanic"
    },
    {
      "x": -4,
      "y": 14,
      "z": -10,
      "name": "Rock_Basalt"
    },
    {
      "x": -4,
      "y": 15,
      "z": -10,
      "name": "Rock_Basalt"
    },
    {
      "x": -4,
      "y": 13,
      "z": -9,
      "name": "Rock_Volcanic"
    },
    {
      "x": -4,
      "y": 14,
      "z": -9,
      "name": "Rock_Volcanic"
    },
    {
      "x": -4,
      "y": 15,
      "z": -9,
      "name": "Rock_Basalt"
    },
    {
      "x": -4,
      "y": 16,
      "z": -9,
      "name": "Rock_Basalt"
    },
    {
      "x": -4,
      "y": 14,
      "z": -8,
      "name": "Rock_Volcanic"
    },
    {
      "x": -4,
      "y": 15,
      "z": -8,
      "name": "Rock_Volcanic"
    },
    {
      "x": -4,
      "y": 16,
      "z": -8,
      "name": "Rock_Basalt"
    },
    {
      "x": -4,
      "y": 17,
      "z": -8,
      "name": "Rock_Basalt"
    },
    {
      "x": -4,
      "y": 15,
      "z": -7,
      "name": "Rock_Volcanic"
    },
    {
      "x": -4,
      "y": 16,
      "z": -7,
      "name": "Rock_Volcanic"
    },
    {
      "x": -4,
      "y": 17,
      "z": -7,
      "name": "Rock_Basalt"
    },
    {
      "x": -4,
      "y": 18,
      "z": -7,
      "name": "Rock_Basalt"
    },
    {
      "x": -4,
      "y": 16,
      "z": -6,
      "name": "Rock_Volcanic"
    },
    {
      "x": -4,
      "y": 17,
      "z": -6,
      "name": "Rock_Volcanic"
    },
    {
      "x": -4,
      "y": 18,
      "z": -6,
      "name": "Rock_Basalt"
    },
    {
      "x": -4,
      "y": 19,
      "z": -6,
      "name": "Rock_Basalt"
    },
    {
      "x": -4,
      "y": 17,
      "z": -5,
      "name": "Rock_Volcanic"
    },
    {
      "x": -4,
      "y": 18,
      "z": -5,
      "name": "Rock_Volcanic"
    },
    {
      "x": -4,
      "y": 19,
      "z": -5,
      "name": "Rock_Basalt"
    },
    {
      "x": -4,
      "y": 20,
      "z": -5,
      "name": "Rock_Basalt"
    },
    {
      "x": -4,
      "y": 18,
      "z": -4,
      "name": "Rock_Volcanic"
    },
    {
      "x": -4,
      "y": 19,
      "z": -4,
      "name": "Rock_Volcanic"
    },
    {
      "x": -4,
      "y": 20,
      "z": -4,
      "name": "Rock_Basalt"
    },
    {
      "x": -4,
      "y": 21,
      "z": -4,
      "name": "Rock_Basalt"
    },
    {
      "x": -4,
      "y": 21,
      "z": -3,
      "name": "Rock_Basalt"
    },
    {
      "x": -4,
      "y": 22,
      "z": -3,
      "name": "Rock_Basalt"
    },
    {
      "x": -4,
      "y": 22,
      "z": 3,
      "name": "Rock_Basalt"
    },
    {
      "x": -4,
      "y": 23,
      "z": 3,
      "name": "Rock_Basalt"
    },
    {
      "x": -4,
      "y": 20,
      "z": 4,
      "name": "Rock_Volcanic"
    },
    {
      "x": -4,
      "y": 21,
      "z": 4,
      "name": "Rock_Volcanic"
    },
    {
      "x": -4,
      "y": 22,
      "z": 4,
      "name": "Rock_Basalt"
    },
    {
      "x": -4,
      "y": 23,
      "z": 4,
      "name": "Rock_Basalt"
    },
    {
      "x": -4,
      "y": 20,
      "z": 5,
      "name": "Rock_Volcanic"
    },
    {
      "x": -4,
      "y": 21,
      "z": 5,
      "name": "Rock_Volcanic"
    },
    {
      "x": -4,
      "y": 22,
      "z": 5,
      "name": "Rock_Basalt"
    },
    {
      "x": -4,
      "y": 23,
      "z": 5,
      "name": "Rock_Basalt"
    },
    {
      "x": -4,
      "y": 20,
      "z": 6,
      "name": "Rock_Volcanic"
    },
    {
      "x": -4,
      "y": 21,
      "z": 6,
      "name": "Rock_Volcanic"
    },
    {
      "x": -4,
      "y": 22,
      "z": 6,
      "name": "Rock_Basalt"
    },
    {
      "x": -4,
      "y": 23,
      "z": 6,
      "name": "Rock_Basalt"
    },
    {
      "x": -4,
      "y": 19,
      "z": 7,
      "name": "Rock_Volcanic"
    },
    {
      "x": -4,
      "y": 20,
      "z": 7,
      "name": "Rock_Volcanic"
    },
    {
      "x": -4,
      "y": 21,
      "z": 7,
      "name": "Rock_Basalt"
    },
    {
      "x": -4,
      "y": 22,
      "z": 7,
      "name": "Rock_Basalt"
    },
    {
      "x": -4,
      "y": 23,
      "z": 7,
      "name": "Rock_Basalt"
    },
    {
      "x": -4,
      "y": 19,
      "z": 8,
      "name": "Rock_Volcanic"
    },
    {
      "x": -4,
      "y": 20,
      "z": 8,
      "name": "Rock_Volcanic"
    },
    {
      "x": -4,
      "y": 21,
      "z": 8,
      "name": "Rock_Basalt"
    },
    {
      "x": -4,
      "y": 22,
      "z": 8,
      "name": "Rock_Basalt"
    },
    {
      "x": -4,
      "y": 18,
      "z": 9,
      "name": "Rock_Volcanic"
    },
    {
      "x": -4,
      "y": 19,
      "z": 9,
      "name": "Rock_Volcanic"
    },
    {
      "x": -4,
      "y": 20,
      "z": 9,
      "name": "Rock_Basalt"
    },
    {
      "x": -4,
      "y": 21,
      "z": 9,
      "name": "Rock_Basalt"
    },
    {
      "x": -4,
      "y": 17,
      "z": 10,
      "name": "Rock_Volcanic"
    },
    {
      "x": -4,
      "y": 18,
      "z": 10,
      "name": "Rock_Volcanic"
    },
    {
      "x": -4,
      "y": 19,
      "z": 10,
      "name": "Rock_Basalt"
    },
    {
      "x": -4,
      "y": 20,
      "z": 10,
      "name": "Rock_Basalt"
    },
    {
      "x": -4,
      "y": 15,
      "z": 11,
      "name": "Rock_Volcanic"
    },
    {
      "x": -4,
      "y": 16,
      "z": 11,
      "name": "Rock_Volcanic"
    },
    {
      "x": -4,
      "y": 17,
      "z": 11,
      "name": "Rock_Basalt"
    },
    {
      "x": -4,
      "y": 18,
      "z": 11,
      "name": "Rock_Basalt"
    },
    {
      "x": -4,
      "y": 14,
      "z": 12,
      "name": "Rock_Volcanic"
    },
    {
      "x": -4,
      "y": 15,
      "z": 12,
      "name": "Rock_Volcanic"
    },
    {
      "x": -4,
      "y": 16,
      "z": 12,
      "name": "Rock_Basalt"
    },
    {
      "x": -4,
      "y": 17,
      "z": 12,
      "name": "Rock_Basalt"
    },
    {
      "x": -4,
      "y": 13,
      "z": 13,
      "name": "Rock_Volcanic"
    },
    {
      "x": -4,
      "y": 14,
      "z": 13,
      "name": "Rock_Volcanic"
    },
    {
      "x": -4,
      "y": 15,
      "z": 13,
      "name": "Rock_Basalt"
    },
    {
      "x": -4,
      "y": 16,
      "z": 13,
      "name": "Rock_Basalt"
    },
    {
      "x": -4,
      "y": 12,
      "z": 14,
      "name": "Rock_Basalt"
    },
    {
      "x": -4,
      "y": 13,
      "z": 14,
      "name": "Rock_Basalt"
    },
    {
      "x": -4,
      "y": 14,
      "z": 14,
      "name": "Rock_Basalt"
    },
    {
      "x": -4,
      "y": 15,
      "z": 14,
      "name": "Rock_Basalt"
    },
    {
      "x": -4,
      "y": 11,
      "z": 15,
      "name": "Rock_Basalt"
    },
    {
      "x": -4,
      "y": 12,
      "z": 15,
      "name": "Rock_Basalt"
    },
    {
      "x": -4,
      "y": 13,
      "z": 15,
      "name": "Rock_Basalt"
    },
    {
      "x": -4,
      "y": 14,
      "z": 15,
      "name": "Rock_Basalt"
    },
    {
      "x": -4,
      "y": 10,
      "z": 16,
      "name": "Rock_Basalt"
    },
    {
      "x": -4,
      "y": 11,
      "z": 16,
      "name": "Rock_Basalt"
    },
    {
      "x": -4,
      "y": 12,
      "z": 16,
      "name": "Rock_Basalt"
    },
    {
      "x": -4,
      "y": 13,
      "z": 16,
      "name": "Rock_Basalt"
    },
    {
      "x": -4,
      "y": 9,
      "z": 17,
      "name": "Rock_Basalt"
    },
    {
      "x": -4,
      "y": 10,
      "z": 17,
      "name": "Rock_Basalt"
    },
    {
      "x": -4,
      "y": 11,
      "z": 17,
      "name": "Rock_Basalt"
    },
    {
      "x": -4,
      "y": 12,
      "z": 17,
      "name": "Rock_Basalt"
    },
    {
      "x": -3,
      "y": 9,
      "z": -16,
      "name": "Rock_Basalt"
    },
    {
      "x": -3,
      "y": 10,
      "z": -16,
      "name": "Rock_Basalt"
    },
    {
      "x": -3,
      "y": 11,
      "z": -16,
      "name": "Rock_Basalt"
    },
    {
      "x": -3,
      "y": 12,
      "z": -16,
      "name": "Rock_Basalt"
    },
    {
      "x": -3,
      "y": 10,
      "z": -15,
      "name": "Rock_Basalt"
    },
    {
      "x": -3,
      "y": 11,
      "z": -15,
      "name": "Rock_Basalt"
    },
    {
      "x": -3,
      "y": 12,
      "z": -15,
      "name": "Rock_Basalt"
    },
    {
      "x": -3,
      "y": 13,
      "z": -15,
      "name": "Rock_Basalt"
    },
    {
      "x": -3,
      "y": 11,
      "z": -14,
      "name": "Rock_Basalt"
    },
    {
      "x": -3,
      "y": 12,
      "z": -14,
      "name": "Rock_Basalt"
    },
    {
      "x": -3,
      "y": 13,
      "z": -14,
      "name": "Rock_Basalt"
    },
    {
      "x": -3,
      "y": 11,
      "z": -13,
      "name": "Rock_Basalt"
    },
    {
      "x": -3,
      "y": 12,
      "z": -13,
      "name": "Rock_Basalt"
    },
    {
      "x": -3,
      "y": 13,
      "z": -13,
      "name": "Rock_Basalt"
    },
    {
      "x": -3,
      "y": 14,
      "z": -13,
      "name": "Rock_Basalt"
    },
    {
      "x": -3,
      "y": 12,
      "z": -12,
      "name": "Rock_Basalt"
    },
    {
      "x": -3,
      "y": 13,
      "z": -12,
      "name": "Rock_Basalt"
    },
    {
      "x": -3,
      "y": 14,
      "z": -12,
      "name": "Rock_Basalt"
    },
    {
      "x": -3,
      "y": 15,
      "z": -12,
      "name": "Rock_Basalt"
    },
    {
      "x": -3,
      "y": 13,
      "z": -11,
      "name": "Rock_Volcanic"
    },
    {
      "x": -3,
      "y": 14,
      "z": -11,
      "name": "Rock_Volcanic"
    },
    {
      "x": -3,
      "y": 15,
      "z": -11,
      "name": "Rock_Basalt"
    },
    {
      "x": -3,
      "y": 16,
      "z": -11,
      "name": "Rock_Basalt"
    },
    {
      "x": -3,
      "y": 13,
      "z": -10,
      "name": "Rock_Volcanic"
    },
    {
      "x": -3,
      "y": 14,
      "z": -10,
      "name": "Rock_Volcanic"
    },
    {
      "x": -3,
      "y": 15,
      "z": -10,
      "name": "Rock_Basalt"
    },
    {
      "x": -3,
      "y": 16,
      "z": -10,
      "name": "Rock_Basalt"
    },
    {
      "x": -3,
      "y": 14,
      "z": -9,
      "name": "Rock_Volcanic"
    },
    {
      "x": -3,
      "y": 15,
      "z": -9,
      "name": "Rock_Volcanic"
    },
    {
      "x": -3,
      "y": 16,
      "z": -9,
      "name": "Rock_Basalt"
    },
    {
      "x": -3,
      "y": 17,
      "z": -9,
      "name": "Rock_Basalt"
    },
    {
      "x": -3,
      "y": 15,
      "z": -8,
      "name": "Rock_Volcanic"
    },
    {
      "x": -3,
      "y": 16,
      "z": -8,
      "name": "Rock_Volcanic"
    },
    {
      "x": -3,
      "y": 17,
      "z": -8,
      "name": "Rock_Basalt"
    },
    {
      "x": -3,
      "y": 15,
      "z": -7,
      "name": "Rock_Volcanic"
    },
    {
      "x": -3,
      "y": 16,
      "z": -7,
      "name": "Rock_Volcanic"
    },
    {
      "x": -3,
      "y": 17,
      "z": -7,
      "name": "Rock_Basalt"
    },
    {
      "x": -3,
      "y": 18,
      "z": -7,
      "name": "Rock_Basalt"
    },
    {
      "x": -3,
      "y": 16,
      "z": -6,
      "name": "Rock_Volcanic"
    },
    {
      "x": -3,
      "y": 17,
      "z": -6,
      "name": "Rock_Volcanic"
    },
    {
      "x": -3,
      "y": 18,
      "z": -6,
      "name": "Rock_Basalt"
    },
    {
      "x": -3,
      "y": 19,
      "z": -6,
      "name": "Rock_Basalt"
    },
    {
      "x": -3,
      "y": 20,
      "z": -6,
      "name": "Rock_Basalt"
    },
    {
      "x": -3,
      "y": 17,
      "z": -5,
      "name": "Rock_Volcanic"
    },
    {
      "x": -3,
      "y": 18,
      "z": -5,
      "name": "Rock_Volcanic"
    },
    {
      "x": -3,
      "y": 19,
      "z": -5,
      "name": "Rock_Basalt"
    },
    {
      "x": -3,
      "y": 20,
      "z": -5,
      "name": "Rock_Basalt"
    },
    {
      "x": -3,
      "y": 21,
      "z": -5,
      "name": "Rock_Basalt"
    },
    {
      "x": -3,
      "y": 18,
      "z": -4,
      "name": "Rock_Volcanic"
    },
    {
      "x": -3,
      "y": 19,
      "z": -4,
      "name": "Rock_Volcanic"
    },
    {
      "x": -3,
      "y": 20,
      "z": -4,
      "name": "Rock_Basalt"
    },
    {
      "x": -3,
      "y": 21,
      "z": -4,
      "name": "Rock_Basalt"
    },
    {
      "x": -3,
      "y": 22,
      "z": -4,
      "name": "Rock_Basalt"
    },
    {
      "x": -3,
      "y": 22,
      "z": 3,
      "name": "Rock_Basalt"
    },
    {
      "x": -3,
      "y": 23,
      "z": 3,
      "name": "Rock_Basalt"
    },
    {
      "x": -3,
      "y": 24,
      "z": 3,
      "name": "Rock_Basalt"
    },
    {
      "x": -3,
      "y": 20,
      "z": 4,
      "name": "Rock_Volcanic"
    },
    {
      "x": -3,
      "y": 21,
      "z": 4,
      "name": "Rock_Volcanic"
    },
    {
      "x": -3,
      "y": 22,
      "z": 4,
      "name": "Rock_Basalt"
    },
    {
      "x": -3,
      "y": 23,
      "z": 4,
      "name": "Rock_Basalt"
    },
    {
      "x": -3,
      "y": 24,
      "z": 4,
      "name": "Rock_Basalt"
    },
    {
      "x": -3,
      "y": 20,
      "z": 5,
      "name": "Rock_Volcanic"
    },
    {
      "x": -3,
      "y": 21,
      "z": 5,
      "name": "Rock_Volcanic"
    },
    {
      "x": -3,
      "y": 22,
      "z": 5,
      "name": "Rock_Basalt"
    },
    {
      "x": -3,
      "y": 23,
      "z": 5,
      "name": "Rock_Basalt"
    },
    {
      "x": -3,
      "y": 24,
      "z": 5,
      "name": "Rock_Basalt"
    },
    {
      "x": -3,
      "y": 20,
      "z": 6,
      "name": "Rock_Volcanic"
    },
    {
      "x": -3,
      "y": 21,
      "z": 6,
      "name": "Rock_Volcanic"
    },
    {
      "x": -3,
      "y": 22,
      "z": 6,
      "name": "Rock_Basalt"
    },
    {
      "x": -3,
      "y": 23,
      "z": 6,
      "name": "Rock_Basalt"
    },
    {
      "x": -3,
      "y": 24,
      "z": 6,
      "name": "Rock_Basalt"
    },
    {
      "x": -3,
      "y": 20,
      "z": 7,
      "name": "Rock_Volcanic"
    },
    {
      "x": -3,
      "y": 21,
      "z": 7,
      "name": "Rock_Volcanic"
    },
    {
      "x": -3,
      "y": 22,
      "z": 7,
      "name": "Rock_Basalt"
    },
    {
      "x": -3,
      "y": 23,
      "z": 7,
      "name": "Rock_Basalt"
    },
    {
      "x": -3,
      "y": 19,
      "z": 8,
      "name": "Rock_Volcanic"
    },
    {
      "x": -3,
      "y": 20,
      "z": 8,
      "name": "Rock_Volcanic"
    },
    {
      "x": -3,
      "y": 21,
      "z": 8,
      "name": "Rock_Basalt"
    },
    {
      "x": -3,
      "y": 22,
      "z": 8,
      "name": "Rock_Basalt"
    },
    {
      "x": -3,
      "y": 18,
      "z": 9,
      "name": "Rock_Volcanic"
    },
    {
      "x": -3,
      "y": 19,
      "z": 9,
      "name": "Rock_Volcanic"
    },
    {
      "x": -3,
      "y": 20,
      "z": 9,
      "name": "Rock_Basalt"
    },
    {
      "x": -3,
      "y": 21,
      "z": 9,
      "name": "Rock_Basalt"
    },
    {
      "x": -3,
      "y": 17,
      "z": 10,
      "name": "Rock_Volcanic"
    },
    {
      "x": -3,
      "y": 18,
      "z": 10,
      "name": "Rock_Volcanic"
    },
    {
      "x": -3,
      "y": 19,
      "z": 10,
      "name": "Rock_Basalt"
    },
    {
      "x": -3,
      "y": 20,
      "z": 10,
      "name": "Rock_Basalt"
    },
    {
      "x": -3,
      "y": 16,
      "z": 11,
      "name": "Rock_Volcanic"
    },
    {
      "x": -3,
      "y": 17,
      "z": 11,
      "name": "Rock_Volcanic"
    },
    {
      "x": -3,
      "y": 18,
      "z": 11,
      "name": "Rock_Basalt"
    },
    {
      "x": -3,
      "y": 19,
      "z": 11,
      "name": "Rock_Basalt"
    },
    {
      "x": -3,
      "y": 15,
      "z": 12,
      "name": "Rock_Volcanic"
    },
    {
      "x": -3,
      "y": 16,
      "z": 12,
      "name": "Rock_Volcanic"
    },
    {
      "x": -3,
      "y": 17,
      "z": 12,
      "name": "Rock_Basalt"
    },
    {
      "x": -3,
      "y": 18,
      "z": 12,
      "name": "Rock_Basalt"
    },
    {
      "x": -3,
      "y": 14,
      "z": 13,
      "name": "Rock_Volcanic"
    },
    {
      "x": -3,
      "y": 15,
      "z": 13,
      "name": "Rock_Volcanic"
    },
    {
      "x": -3,
      "y": 16,
      "z": 13,
      "name": "Rock_Basalt"
    },
    {
      "x": -3,
      "y": 12,
      "z": 14,
      "name": "Rock_Volcanic"
    },
    {
      "x": -3,
      "y": 13,
      "z": 14,
      "name": "Rock_Volcanic"
    },
    {
      "x": -3,
      "y": 14,
      "z": 14,
      "name": "Rock_Basalt"
    },
    {
      "x": -3,
      "y": 15,
      "z": 14,
      "name": "Rock_Basalt"
    },
    {
      "x": -3,
      "y": 12,
      "z": 15,
      "name": "Rock_Basalt"
    },
    {
      "x": -3,
      "y": 13,
      "z": 15,
      "name": "Rock_Basalt"
    },
    {
      "x": -3,
      "y": 14,
      "z": 15,
      "name": "Rock_Basalt"
    },
    {
      "x": -3,
      "y": 11,
      "z": 16,
      "name": "Rock_Basalt"
    },
    {
      "x": -3,
      "y": 12,
      "z": 16,
      "name": "Rock_Basalt"
    },
    {
      "x": -3,
      "y": 13,
      "z": 16,
      "name": "Rock_Basalt"
    },
    {
      "x": -3,
      "y": 10,
      "z": 17,
      "name": "Rock_Basalt"
    },
    {
      "x": -3,
      "y": 11,
      "z": 17,
      "name": "Rock_Basalt"
    },
    {
      "x": -3,
      "y": 12,
      "z": 17,
      "name": "Rock_Basalt"
    },
    {
      "x": -2,
      "y": 10,
      "z": -16,
      "name": "Rock_Basalt"
    },
    {
      "x": -2,
      "y": 11,
      "z": -16,
      "name": "Rock_Basalt"
    },
    {
      "x": -2,
      "y": 12,
      "z": -16,
      "name": "Rock_Basalt"
    },
    {
      "x": -2,
      "y": 10,
      "z": -15,
      "name": "Rock_Basalt"
    },
    {
      "x": -2,
      "y": 11,
      "z": -15,
      "name": "Rock_Basalt"
    },
    {
      "x": -2,
      "y": 12,
      "z": -15,
      "name": "Rock_Basalt"
    },
    {
      "x": -2,
      "y": 13,
      "z": -15,
      "name": "Rock_Basalt"
    },
    {
      "x": -2,
      "y": 11,
      "z": -14,
      "name": "Rock_Basalt"
    },
    {
      "x": -2,
      "y": 12,
      "z": -14,
      "name": "Rock_Basalt"
    },
    {
      "x": -2,
      "y": 13,
      "z": -14,
      "name": "Rock_Basalt"
    },
    {
      "x": -2,
      "y": 14,
      "z": -14,
      "name": "Rock_Basalt"
    },
    {
      "x": -2,
      "y": 12,
      "z": -13,
      "name": "Rock_Basalt"
    },
    {
      "x": -2,
      "y": 13,
      "z": -13,
      "name": "Rock_Basalt"
    },
    {
      "x": -2,
      "y": 14,
      "z": -13,
      "name": "Rock_Basalt"
    },
    {
      "x": -2,
      "y": 15,
      "z": -13,
      "name": "Rock_Basalt"
    },
    {
      "x": -2,
      "y": 13,
      "z": -12,
      "name": "Rock_Volcanic"
    },
    {
      "x": -2,
      "y": 14,
      "z": -12,
      "name": "Rock_Volcanic"
    },
    {
      "x": -2,
      "y": 15,
      "z": -12,
      "name": "Rock_Basalt"
    },
    {
      "x": -2,
      "y": 16,
      "z": -12,
      "name": "Rock_Basalt"
    },
    {
      "x": -2,
      "y": 14,
      "z": -11,
      "name": "Rock_Volcanic"
    },
    {
      "x": -2,
      "y": 15,
      "z": -11,
      "name": "Rock_Volcanic"
    },
    {
      "x": -2,
      "y": 16,
      "z": -11,
      "name": "Rock_Basalt"
    },
    {
      "x": -2,
      "y": 14,
      "z": -10,
      "name": "Rock_Volcanic"
    },
    {
      "x": -2,
      "y": 15,
      "z": -10,
      "name": "Rock_Volcanic"
    },
    {
      "x": -2,
      "y": 16,
      "z": -10,
      "name": "Rock_Basalt"
    },
    {
      "x": -2,
      "y": 17,
      "z": -10,
      "name": "Rock_Basalt"
    },
    {
      "x": -2,
      "y": 15,
      "z": -9,
      "name": "Rock_Volcanic"
    },
    {
      "x": -2,
      "y": 16,
      "z": -9,
      "name": "Rock_Volcanic"
    },
    {
      "x": -2,
      "y": 17,
      "z": -9,
      "name": "Rock_Basalt"
    },
    {
      "x": -2,
      "y": 18,
      "z": -9,
      "name": "Rock_Basalt"
    },
    {
      "x": -2,
      "y": 16,
      "z": -8,
      "name": "Rock_Volcanic"
    },
    {
      "x": -2,
      "y": 17,
      "z": -8,
      "name": "Rock_Volcanic"
    },
    {
      "x": -2,
      "y": 18,
      "z": -8,
      "name": "Rock_Basalt"
    },
    {
      "x": -2,
      "y": 19,
      "z": -8,
      "name": "Rock_Basalt"
    },
    {
      "x": -2,
      "y": 16,
      "z": -7,
      "name": "Rock_Volcanic"
    },
    {
      "x": -2,
      "y": 17,
      "z": -7,
      "name": "Rock_Volcanic"
    },
    {
      "x": -2,
      "y": 18,
      "z": -7,
      "name": "Rock_Basalt"
    },
    {
      "x": -2,
      "y": 19,
      "z": -7,
      "name": "Rock_Basalt"
    },
    {
      "x": -2,
      "y": 17,
      "z": -6,
      "name": "Rock_Volcanic"
    },
    {
      "x": -2,
      "y": 18,
      "z": -6,
      "name": "Rock_Volcanic"
    },
    {
      "x": -2,
      "y": 19,
      "z": -6,
      "name": "Rock_Basalt"
    },
    {
      "x": -2,
      "y": 20,
      "z": -6,
      "name": "Rock_Basalt"
    },
    {
      "x": -2,
      "y": 18,
      "z": -5,
      "name": "Rock_Volcanic"
    },
    {
      "x": -2,
      "y": 19,
      "z": -5,
      "name": "Rock_Volcanic"
    },
    {
      "x": -2,
      "y": 20,
      "z": -5,
      "name": "Rock_Basalt"
    },
    {
      "x": -2,
      "y": 21,
      "z": -5,
      "name": "Rock_Basalt"
    },
    {
      "x": -2,
      "y": 21,
      "z": -4,
      "name": "Rock_Basalt"
    },
    {
      "x": -2,
      "y": 22,
      "z": -4,
      "name": "Rock_Basalt"
    },
    {
      "x": -2,
      "y": 23,
      "z": 3,
      "name": "Rock_Basalt"
    },
    {
      "x": -2,
      "y": 24,
      "z": 3,
      "name": "Rock_Basalt"
    },
    {
      "x": -2,
      "y": 21,
      "z": 4,
      "name": "Rock_Volcanic"
    },
    {
      "x": -2,
      "y": 22,
      "z": 4,
      "name": "Rock_Volcanic"
    },
    {
      "x": -2,
      "y": 23,
      "z": 4,
      "name": "Rock_Basalt"
    },
    {
      "x": -2,
      "y": 24,
      "z": 4,
      "name": "Rock_Basalt"
    },
    {
      "x": -2,
      "y": 21,
      "z": 5,
      "name": "Rock_Volcanic"
    },
    {
      "x": -2,
      "y": 22,
      "z": 5,
      "name": "Rock_Volcanic"
    },
    {
      "x": -2,
      "y": 23,
      "z": 5,
      "name": "Rock_Basalt"
    },
    {
      "x": -2,
      "y": 24,
      "z": 5,
      "name": "Rock_Basalt"
    },
    {
      "x": -2,
      "y": 21,
      "z": 6,
      "name": "Rock_Volcanic"
    },
    {
      "x": -2,
      "y": 22,
      "z": 6,
      "name": "Rock_Volcanic"
    },
    {
      "x": -2,
      "y": 23,
      "z": 6,
      "name": "Rock_Basalt"
    },
    {
      "x": -2,
      "y": 24,
      "z": 6,
      "name": "Rock_Basalt"
    },
    {
      "x": -2,
      "y": 20,
      "z": 7,
      "name": "Rock_Volcanic"
    },
    {
      "x": -2,
      "y": 21,
      "z": 7,
      "name": "Rock_Volcanic"
    },
    {
      "x": -2,
      "y": 22,
      "z": 7,
      "name": "Rock_Basalt"
    },
    {
      "x": -2,
      "y": 23,
      "z": 7,
      "name": "Rock_Basalt"
    },
    {
      "x": -2,
      "y": 19,
      "z": 8,
      "name": "Rock_Volcanic"
    },
    {
      "x": -2,
      "y": 20,
      "z": 8,
      "name": "Rock_Volcanic"
    },
    {
      "x": -2,
      "y": 21,
      "z": 8,
      "name": "Rock_Basalt"
    },
    {
      "x": -2,
      "y": 22,
      "z": 8,
      "name": "Rock_Basalt"
    },
    {
      "x": -2,
      "y": 23,
      "z": 8,
      "name": "Rock_Basalt"
    },
    {
      "x": -2,
      "y": 18,
      "z": 9,
      "name": "Rock_Volcanic"
    },
    {
      "x": -2,
      "y": 19,
      "z": 9,
      "name": "Rock_Volcanic"
    },
    {
      "x": -2,
      "y": 20,
      "z": 9,
      "name": "Rock_Basalt"
    },
    {
      "x": -2,
      "y": 21,
      "z": 9,
      "name": "Rock_Basalt"
    },
    {
      "x": -2,
      "y": 22,
      "z": 9,
      "name": "Rock_Basalt"
    },
    {
      "x": -2,
      "y": 17,
      "z": 10,
      "name": "Rock_Volcanic"
    },
    {
      "x": -2,
      "y": 18,
      "z": 10,
      "name": "Rock_Volcanic"
    },
    {
      "x": -2,
      "y": 19,
      "z": 10,
      "name": "Rock_Basalt"
    },
    {
      "x": -2,
      "y": 20,
      "z": 10,
      "name": "Rock_Basalt"
    },
    {
      "x": -2,
      "y": 16,
      "z": 11,
      "name": "Rock_Volcanic"
    },
    {
      "x": -2,
      "y": 17,
      "z": 11,
      "name": "Rock_Volcanic"
    },
    {
      "x": -2,
      "y": 18,
      "z": 11,
      "name": "Rock_Basalt"
    },
    {
      "x": -2,
      "y": 19,
      "z": 11,
      "name": "Rock_Basalt"
    },
    {
      "x": -2,
      "y": 15,
      "z": 12,
      "name": "Rock_Volcanic"
    },
    {
      "x": -2,
      "y": 16,
      "z": 12,
      "name": "Rock_Volcanic"
    },
    {
      "x": -2,
      "y": 17,
      "z": 12,
      "name": "Rock_Basalt"
    },
    {
      "x": -2,
      "y": 18,
      "z": 12,
      "name": "Rock_Basalt"
    },
    {
      "x": -2,
      "y": 14,
      "z": 13,
      "name": "Rock_Volcanic"
    },
    {
      "x": -2,
      "y": 15,
      "z": 13,
      "name": "Rock_Volcanic"
    },
    {
      "x": -2,
      "y": 16,
      "z": 13,
      "name": "Rock_Basalt"
    },
    {
      "x": -2,
      "y": 17,
      "z": 13,
      "name": "Rock_Basalt"
    },
    {
      "x": -2,
      "y": 13,
      "z": 14,
      "name": "Rock_Volcanic"
    },
    {
      "x": -2,
      "y": 14,
      "z": 14,
      "name": "Rock_Volcanic"
    },
    {
      "x": -2,
      "y": 15,
      "z": 14,
      "name": "Rock_Basalt"
    },
    {
      "x": -2,
      "y": 16,
      "z": 14,
      "name": "Rock_Basalt"
    },
    {
      "x": -2,
      "y": 12,
      "z": 15,
      "name": "Rock_Basalt"
    },
    {
      "x": -2,
      "y": 13,
      "z": 15,
      "name": "Rock_Basalt"
    },
    {
      "x": -2,
      "y": 14,
      "z": 15,
      "name": "Rock_Basalt"
    },
    {
      "x": -2,
      "y": 15,
      "z": 15,
      "name": "Rock_Basalt"
    },
    {
      "x": -2,
      "y": 11,
      "z": 16,
      "name": "Rock_Basalt"
    },
    {
      "x": -2,
      "y": 12,
      "z": 16,
      "name": "Rock_Basalt"
    },
    {
      "x": -2,
      "y": 13,
      "z": 16,
      "name": "Rock_Basalt"
    },
    {
      "x": -2,
      "y": 9,
      "z": 17,
      "name": "Rock_Basalt"
    },
    {
      "x": -2,
      "y": 10,
      "z": 17,
      "name": "Rock_Basalt"
    },
    {
      "x": -2,
      "y": 11,
      "z": 17,
      "name": "Rock_Basalt"
    },
    {
      "x": -2,
      "y": 12,
      "z": 17,
      "name": "Rock_Basalt"
    },
    {
      "x": -1,
      "y": 10,
      "z": -16,
      "name": "Rock_Basalt"
    },
    {
      "x": -1,
      "y": 11,
      "z": -16,
      "name": "Rock_Basalt"
    },
    {
      "x": -1,
      "y": 12,
      "z": -16,
      "name": "Rock_Basalt"
    },
    {
      "x": -1,
      "y": 13,
      "z": -16,
      "name": "Rock_Basalt"
    },
    {
      "x": -1,
      "y": 11,
      "z": -15,
      "name": "Rock_Basalt"
    },
    {
      "x": -1,
      "y": 12,
      "z": -15,
      "name": "Rock_Basalt"
    },
    {
      "x": -1,
      "y": 13,
      "z": -15,
      "name": "Rock_Basalt"
    },
    {
      "x": -1,
      "y": 14,
      "z": -15,
      "name": "Rock_Basalt"
    },
    {
      "x": -1,
      "y": 12,
      "z": -14,
      "name": "Rock_Basalt"
    },
    {
      "x": -1,
      "y": 13,
      "z": -14,
      "name": "Rock_Basalt"
    },
    {
      "x": -1,
      "y": 14,
      "z": -14,
      "name": "Rock_Basalt"
    },
    {
      "x": -1,
      "y": 15,
      "z": -14,
      "name": "Rock_Basalt"
    },
    {
      "x": -1,
      "y": 13,
      "z": -13,
      "name": "Rock_Volcanic"
    },
    {
      "x": -1,
      "y": 14,
      "z": -13,
      "name": "Rock_Volcanic"
    },
    {
      "x": -1,
      "y": 15,
      "z": -13,
      "name": "Rock_Basalt"
    },
    {
      "x": -1,
      "y": 16,
      "z": -13,
      "name": "Rock_Basalt"
    },
    {
      "x": -1,
      "y": 14,
      "z": -12,
      "name": "Rock_Volcanic"
    },
    {
      "x": -1,
      "y": 15,
      "z": -12,
      "name": "Rock_Volcanic"
    },
    {
      "x": -1,
      "y": 16,
      "z": -12,
      "name": "Rock_Basalt"
    },
    {
      "x": -1,
      "y": 17,
      "z": -12,
      "name": "Rock_Basalt"
    },
    {
      "x": -1,
      "y": 14,
      "z": -11,
      "name": "Rock_Volcanic"
    },
    {
      "x": -1,
      "y": 15,
      "z": -11,
      "name": "Rock_Volcanic"
    },
    {
      "x": -1,
      "y": 16,
      "z": -11,
      "name": "Rock_Basalt"
    },
    {
      "x": -1,
      "y": 17,
      "z": -11,
      "name": "Rock_Basalt"
    },
    {
      "x": -1,
      "y": 15,
      "z": -10,
      "name": "Rock_Volcanic"
    },
    {
      "x": -1,
      "y": 16,
      "z": -10,
      "name": "Rock_Volcanic"
    },
    {
      "x": -1,
      "y": 17,
      "z": -10,
      "name": "Rock_Basalt"
    },
    {
      "x": -1,
      "y": 18,
      "z": -10,
      "name": "Rock_Basalt"
    },
    {
      "x": -1,
      "y": 16,
      "z": -9,
      "name": "Rock_Volcanic"
    },
    {
      "x": -1,
      "y": 17,
      "z": -9,
      "name": "Rock_Volcanic"
    },
    {
      "x": -1,
      "y": 18,
      "z": -9,
      "name": "Rock_Basalt"
    },
    {
      "x": -1,
      "y": 19,
      "z": -9,
      "name": "Rock_Basalt"
    },
    {
      "x": -1,
      "y": 17,
      "z": -8,
      "name": "Rock_Volcanic"
    },
    {
      "x": -1,
      "y": 18,
      "z": -8,
      "name": "Rock_Volcanic"
    },
    {
      "x": -1,
      "y": 19,
      "z": -8,
      "name": "Rock_Basalt"
    },
    {
      "x": -1,
      "y": 20,
      "z": -8,
      "name": "Rock_Basalt"
    },
    {
      "x": -1,
      "y": 17,
      "z": -7,
      "name": "Rock_Volcanic"
    },
    {
      "x": -1,
      "y": 18,
      "z": -7,
      "name": "Rock_Volcanic"
    },
    {
      "x": -1,
      "y": 19,
      "z": -7,
      "name": "Rock_Basalt"
    },
    {
      "x": -1,
      "y": 20,
      "z": -7,
      "name": "Rock_Basalt"
    },
    {
      "x": -1,
      "y": 21,
      "z": -7,
      "name": "Rock_Basalt"
    },
    {
      "x": -1,
      "y": 18,
      "z": -6,
      "name": "Rock_Volcanic"
    },
    {
      "x": -1,
      "y": 19,
      "z": -6,
      "name": "Rock_Volcanic"
    },
    {
      "x": -1,
      "y": 20,
      "z": -6,
      "name": "Rock_Basalt"
    },
    {
      "x": -1,
      "y": 21,
      "z": -6,
      "name": "Rock_Basalt"
    },
    {
      "x": -1,
      "y": 19,
      "z": -5,
      "name": "Rock_Volcanic"
    },
    {
      "x": -1,
      "y": 20,
      "z": -5,
      "name": "Rock_Volcanic"
    },
    {
      "x": -1,
      "y": 21,
      "z": -5,
      "name": "Rock_Basalt"
    },
    {
      "x": -1,
      "y": 22,
      "z": -5,
      "name": "Rock_Basalt"
    },
    {
      "x": -1,
      "y": 23,
      "z": -4,
      "name": "Rock_Basalt"
    },
    {
      "x": -1,
      "y": 21,
      "z": 4,
      "name": "Rock_Volcanic"
    },
    {
      "x": -1,
      "y": 22,
      "z": 4,
      "name": "Rock_Volcanic"
    },
    {
      "x": -1,
      "y": 23,
      "z": 4,
      "name": "Rock_Basalt"
    },
    {
      "x": -1,
      "y": 24,
      "z": 4,
      "name": "Rock_Basalt"
    },
    {
      "x": -1,
      "y": 21,
      "z": 5,
      "name": "Rock_Volcanic"
    },
    {
      "x": -1,
      "y": 22,
      "z": 5,
      "name": "Rock_Volcanic"
    },
    {
      "x": -1,
      "y": 23,
      "z": 5,
      "name": "Rock_Basalt"
    },
    {
      "x": -1,
      "y": 24,
      "z": 5,
      "name": "Rock_Basalt"
    },
    {
      "x": -1,
      "y": 21,
      "z": 6,
      "name": "Rock_Volcanic"
    },
    {
      "x": -1,
      "y": 22,
      "z": 6,
      "name": "Rock_Volcanic"
    },
    {
      "x": -1,
      "y": 23,
      "z": 6,
      "name": "Rock_Basalt"
    },
    {
      "x": -1,
      "y": 24,
      "z": 6,
      "name": "Rock_Basalt"
    },
    {
      "x": -1,
      "y": 20,
      "z": 7,
      "name": "Rock_Volcanic"
    },
    {
      "x": -1,
      "y": 21,
      "z": 7,
      "name": "Rock_Volcanic"
    },
    {
      "x": -1,
      "y": 22,
      "z": 7,
      "name": "Rock_Basalt"
    },
    {
      "x": -1,
      "y": 23,
      "z": 7,
      "name": "Rock_Basalt"
    },
    {
      "x": -1,
      "y": 24,
      "z": 7,
      "name": "Rock_Basalt"
    },
    {
      "x": -1,
      "y": 20,
      "z": 8,
      "name": "Rock_Volcanic"
    },
    {
      "x": -1,
      "y": 21,
      "z": 8,
      "name": "Rock_Volcanic"
    },
    {
      "x": -1,
      "y": 22,
      "z": 8,
      "name": "Rock_Basalt"
    },
    {
      "x": -1,
      "y": 23,
      "z": 8,
      "name": "Rock_Basalt"
    },
    {
      "x": -1,
      "y": 19,
      "z": 9,
      "name": "Rock_Volcanic"
    },
    {
      "x": -1,
      "y": 20,
      "z": 9,
      "name": "Rock_Volcanic"
    },
    {
      "x": -1,
      "y": 21,
      "z": 9,
      "name": "Rock_Basalt"
    },
    {
      "x": -1,
      "y": 22,
      "z": 9,
      "name": "Rock_Basalt"
    },
    {
      "x": -1,
      "y": 17,
      "z": 10,
      "name": "Rock_Volcanic"
    },
    {
      "x": -1,
      "y": 18,
      "z": 10,
      "name": "Rock_Volcanic"
    },
    {
      "x": -1,
      "y": 19,
      "z": 10,
      "name": "Rock_Basalt"
    },
    {
      "x": -1,
      "y": 20,
      "z": 10,
      "name": "Rock_Basalt"
    },
    {
      "x": -1,
      "y": 21,
      "z": 10,
      "name": "Rock_Basalt"
    },
    {
      "x": -1,
      "y": 16,
      "z": 11,
      "name": "Rock_Volcanic"
    },
    {
      "x": -1,
      "y": 17,
      "z": 11,
      "name": "Rock_Volcanic"
    },
    {
      "x": -1,
      "y": 18,
      "z": 11,
      "name": "Rock_Basalt"
    },
    {
      "x": -1,
      "y": 19,
      "z": 11,
      "name": "Rock_Basalt"
    },
    {
      "x": -1,
      "y": 15,
      "z": 12,
      "name": "Rock_Volcanic"
    },
    {
      "x": -1,
      "y": 16,
      "z": 12,
      "name": "Rock_Volcanic"
    },
    {
      "x": -1,
      "y": 17,
      "z": 12,
      "name": "Rock_Basalt"
    },
    {
      "x": -1,
      "y": 18,
      "z": 12,
      "name": "Rock_Basalt"
    },
    {
      "x": -1,
      "y": 14,
      "z": 13,
      "name": "Rock_Volcanic"
    },
    {
      "x": -1,
      "y": 15,
      "z": 13,
      "name": "Rock_Volcanic"
    },
    {
      "x": -1,
      "y": 16,
      "z": 13,
      "name": "Rock_Basalt"
    },
    {
      "x": -1,
      "y": 17,
      "z": 13,
      "name": "Rock_Basalt"
    },
    {
      "x": -1,
      "y": 13,
      "z": 14,
      "name": "Rock_Volcanic"
    },
    {
      "x": -1,
      "y": 14,
      "z": 14,
      "name": "Rock_Volcanic"
    },
    {
      "x": -1,
      "y": 15,
      "z": 14,
      "name": "Rock_Basalt"
    },
    {
      "x": -1,
      "y": 16,
      "z": 14,
      "name": "Rock_Basalt"
    },
    {
      "x": -1,
      "y": 12,
      "z": 15,
      "name": "Rock_Basalt"
    },
    {
      "x": -1,
      "y": 13,
      "z": 15,
      "name": "Rock_Basalt"
    },
    {
      "x": -1,
      "y": 14,
      "z": 15,
      "name": "Rock_Basalt"
    },
    {
      "x": -1,
      "y": 15,
      "z": 15,
      "name": "Rock_Basalt"
    },
    {
      "x": -1,
      "y": 10,
      "z": 16,
      "name": "Rock_Basalt"
    },
    {
      "x": -1,
      "y": 11,
      "z": 16,
      "name": "Rock_Basalt"
    },
    {
      "x": -1,
      "y": 12,
      "z": 16,
      "name": "Rock_Basalt"
    },
    {
      "x": -1,
      "y": 13,
      "z": 16,
      "name": "Rock_Basalt"
    },
    {
      "x": 0,
      "y": 10,
      "z": -17,
      "name": "Rock_Basalt"
    },
    {
      "x": 0,
      "y": 11,
      "z": -17,
      "name": "Rock_Basalt"
    },
    {
      "x": 0,
      "y": 12,
      "z": -17,
      "name": "Rock_Basalt"
    },
    {
      "x": 0,
      "y": 11,
      "z": -16,
      "name": "Rock_Basalt"
    },
    {
      "x": 0,
      "y": 12,
      "z": -16,
      "name": "Rock_Basalt"
    },
    {
      "x": 0,
      "y": 13,
      "z": -16,
      "name": "Rock_Basalt"
    },
    {
      "x": 0,
      "y": 14,
      "z": -16,
      "name": "Rock_Basalt"
    },
    {
      "x": 0,
      "y": 12,
      "z": -15,
      "name": "Rock_Basalt"
    },
    {
      "x": 0,
      "y": 13,
      "z": -15,
      "name": "Rock_Basalt"
    },
    {
      "x": 0,
      "y": 14,
      "z": -15,
      "name": "Rock_Basalt"
    },
    {
      "x": 0,
      "y": 15,
      "z": -15,
      "name": "Rock_Basalt"
    },
    {
      "x": 0,
      "y": 13,
      "z": -14,
      "name": "Rock_Volcanic"
    },
    {
      "x": 0,
      "y": 14,
      "z": -14,
      "name": "Rock_Volcanic"
    },
    {
      "x": 0,
      "y": 15,
      "z": -14,
      "name": "Rock_Basalt"
    },
    {
      "x": 0,
      "y": 16,
      "z": -14,
      "name": "Rock_Basalt"
    },
    {
      "x": 0,
      "y": 14,
      "z": -13,
      "name": "Rock_Volcanic"
    },
    {
      "x": 0,
      "y": 15,
      "z": -13,
      "name": "Rock_Volcanic"
    },
    {
      "x": 0,
      "y": 16,
      "z": -13,
      "name": "Rock_Basalt"
    },
    {
      "x": 0,
      "y": 17,
      "z": -13,
      "name": "Rock_Basalt"
    },
    {
      "x": 0,
      "y": 14,
      "z": -12,
      "name": "Rock_Volcanic"
    },
    {
      "x": 0,
      "y": 15,
      "z": -12,
      "name": "Rock_Volcanic"
    },
    {
      "x": 0,
      "y": 16,
      "z": -12,
      "name": "Rock_Basalt"
    },
    {
      "x": 0,
      "y": 17,
      "z": -12,
      "name": "Rock_Basalt"
    },
    {
      "x": 0,
      "y": 15,
      "z": -11,
      "name": "Rock_Volcanic"
    },
    {
      "x": 0,
      "y": 16,
      "z": -11,
      "name": "Rock_Volcanic"
    },
    {
      "x": 0,
      "y": 17,
      "z": -11,
      "name": "Rock_Basalt"
    },
    {
      "x": 0,
      "y": 18,
      "z": -11,
      "name": "Rock_Basalt"
    },
    {
      "x": 0,
      "y": 16,
      "z": -10,
      "name": "Rock_Volcanic"
    },
    {
      "x": 0,
      "y": 17,
      "z": -10,
      "name": "Rock_Volcanic"
    },
    {
      "x": 0,
      "y": 18,
      "z": -10,
      "name": "Rock_Basalt"
    },
    {
      "x": 0,
      "y": 19,
      "z": -10,
      "name": "Rock_Basalt"
    },
    {
      "x": 0,
      "y": 17,
      "z": -9,
      "name": "Rock_Volcanic"
    },
    {
      "x": 0,
      "y": 18,
      "z": -9,
      "name": "Rock_Volcanic"
    },
    {
      "x": 0,
      "y": 19,
      "z": -9,
      "name": "Rock_Basalt"
    },
    {
      "x": 0,
      "y": 20,
      "z": -9,
      "name": "Rock_Basalt"
    },
    {
      "x": 0,
      "y": 18,
      "z": -8,
      "name": "Rock_Volcanic"
    },
    {
      "x": 0,
      "y": 19,
      "z": -8,
      "name": "Rock_Volcanic"
    },
    {
      "x": 0,
      "y": 20,
      "z": -8,
      "name": "Rock_Basalt"
    },
    {
      "x": 0,
      "y": 21,
      "z": -8,
      "name": "Rock_Basalt"
    },
    {
      "x": 0,
      "y": 18,
      "z": -7,
      "name": "Rock_Volcanic"
    },
    {
      "x": 0,
      "y": 19,
      "z": -7,
      "name": "Rock_Volcanic"
    },
    {
      "x": 0,
      "y": 20,
      "z": -7,
      "name": "Rock_Basalt"
    },
    {
      "x": 0,
      "y": 21,
      "z": -7,
      "name": "Rock_Basalt"
    },
    {
      "x": 0,
      "y": 19,
      "z": -6,
      "name": "Rock_Volcanic"
    },
    {
      "x": 0,
      "y": 20,
      "z": -6,
      "name": "Rock_Volcanic"
    },
    {
      "x": 0,
      "y": 21,
      "z": -6,
      "name": "Rock_Basalt"
    },
    {
      "x": 0,
      "y": 22,
      "z": -6,
      "name": "Rock_Basalt"
    },
    {
      "x": 0,
      "y": 22,
      "z": -5,
      "name": "Rock_Basalt"
    },
    {
      "x": 0,
      "y": 23,
      "z": -5,
      "name": "Rock_Basalt"
    },
    {
      "x": 0,
      "y": 23,
      "z": -1,
      "name": "Rock_Basalt"
    },
    {
      "x": 0,
      "y": 24,
      "z": -1,
      "name": "Rock_Basalt"
    },
    {
      "x": 0,
      "y": 21,
      "z": 4,
      "name": "Rock_Volcanic"
    },
    {
      "x": 0,
      "y": 22,
      "z": 4,
      "name": "Rock_Volcanic"
    },
    {
      "x": 0,
      "y": 23,
      "z": 4,
      "name": "Rock_Basalt"
    },
    {
      "x": 0,
      "y": 21,
      "z": 5,
      "name": "Rock_Volcanic"
    },
    {
      "x": 0,
      "y": 22,
      "z": 5,
      "name": "Rock_Volcanic"
    },
    {
      "x": 0,
      "y": 23,
      "z": 5,
      "name": "Rock_Basalt"
    },
    {
      "x": 0,
      "y": 21,
      "z": 6,
      "name": "Rock_Volcanic"
    },
    {
      "x": 0,
      "y": 22,
      "z": 6,
      "name": "Rock_Volcanic"
    },
    {
      "x": 0,
      "y": 23,
      "z": 6,
      "name": "Rock_Basalt"
    },
    {
      "x": 0,
      "y": 24,
      "z": 6,
      "name": "Rock_Basalt"
    },
    {
      "x": 0,
      "y": 20,
      "z": 7,
      "name": "Rock_Volcanic"
    },
    {
      "x": 0,
      "y": 21,
      "z": 7,
      "name": "Rock_Volcanic"
    },
    {
      "x": 0,
      "y": 22,
      "z": 7,
      "name": "Rock_Basalt"
    },
    {
      "x": 0,
      "y": 23,
      "z": 7,
      "name": "Rock_Basalt"
    },
    {
      "x": 0,
      "y": 24,
      "z": 7,
      "name": "Rock_Basalt"
    },
    {
      "x": 0,
      "y": 20,
      "z": 8,
      "name": "Rock_Volcanic"
    },
    {
      "x": 0,
      "y": 21,
      "z": 8,
      "name": "Rock_Volcanic"
    },
    {
      "x": 0,
      "y": 22,
      "z": 8,
      "name": "Rock_Basalt"
    },
    {
      "x": 0,
      "y": 23,
      "z": 8,
      "name": "Rock_Basalt"
    },
    {
      "x": 0,
      "y": 19,
      "z": 9,
      "name": "Rock_Volcanic"
    },
    {
      "x": 0,
      "y": 20,
      "z": 9,
      "name": "Rock_Volcanic"
    },
    {
      "x": 0,
      "y": 21,
      "z": 9,
      "name": "Rock_Basalt"
    },
    {
      "x": 0,
      "y": 22,
      "z": 9,
      "name": "Rock_Basalt"
    },
    {
      "x": 0,
      "y": 17,
      "z": 10,
      "name": "Rock_Volcanic"
    },
    {
      "x": 0,
      "y": 18,
      "z": 10,
      "name": "Rock_Volcanic"
    },
    {
      "x": 0,
      "y": 19,
      "z": 10,
      "name": "Rock_Basalt"
    },
    {
      "x": 0,
      "y": 20,
      "z": 10,
      "name": "Rock_Basalt"
    },
    {
      "x": 0,
      "y": 21,
      "z": 10,
      "name": "Rock_Basalt"
    },
    {
      "x": 0,
      "y": 16,
      "z": 11,
      "name": "Rock_Volcanic"
    },
    {
      "x": 0,
      "y": 17,
      "z": 11,
      "name": "Rock_Volcanic"
    },
    {
      "x": 0,
      "y": 18,
      "z": 11,
      "name": "Rock_Basalt"
    },
    {
      "x": 0,
      "y": 19,
      "z": 11,
      "name": "Rock_Basalt"
    },
    {
      "x": 0,
      "y": 15,
      "z": 12,
      "name": "Rock_Volcanic"
    },
    {
      "x": 0,
      "y": 16,
      "z": 12,
      "name": "Rock_Volcanic"
    },
    {
      "x": 0,
      "y": 17,
      "z": 12,
      "name": "Rock_Basalt"
    },
    {
      "x": 0,
      "y": 18,
      "z": 12,
      "name": "Rock_Basalt"
    },
    {
      "x": 0,
      "y": 14,
      "z": 13,
      "name": "Rock_Volcanic"
    },
    {
      "x": 0,
      "y": 15,
      "z": 13,
      "name": "Rock_Volcanic"
    },
    {
      "x": 0,
      "y": 16,
      "z": 13,
      "name": "Rock_Basalt"
    },
    {
      "x": 0,
      "y": 17,
      "z": 13,
      "name": "Rock_Basalt"
    },
    {
      "x": 0,
      "y": 13,
      "z": 14,
      "name": "Rock_Volcanic"
    },
    {
      "x": 0,
      "y": 14,
      "z": 14,
      "name": "Rock_Volcanic"
    },
    {
      "x": 0,
      "y": 15,
      "z": 14,
      "name": "Rock_Basalt"
    },
    {
      "x": 0,
      "y": 16,
      "z": 14,
      "name": "Rock_Basalt"
    },
    {
      "x": 0,
      "y": 12,
      "z": 15,
      "name": "Rock_Basalt"
    },
    {
      "x": 0,
      "y": 13,
      "z": 15,
      "name": "Rock_Basalt"
    },
    {
      "x": 0,
      "y": 14,
      "z": 15,
      "name": "Rock_Basalt"
    },
    {
      "x": 0,
      "y": 10,
      "z": 16,
      "name": "Rock_Basalt"
    },
    {
      "x": 0,
      "y": 11,
      "z": 16,
      "name": "Rock_Basalt"
    },
    {
      "x": 0,
      "y": 12,
      "z": 16,
      "name": "Rock_Basalt"
    },
    {
      "x": 0,
      "y": 13,
      "z": 16,
      "name": "Rock_Basalt"
    },
    {
      "x": 1,
      "y": 10,
      "z": -17,
      "name": "Rock_Basalt"
    },
    {
      "x": 1,
      "y": 11,
      "z": -17,
      "name": "Rock_Basalt"
    },
    {
      "x": 1,
      "y": 12,
      "z": -17,
      "name": "Rock_Basalt"
    },
    {
      "x": 1,
      "y": 13,
      "z": -17,
      "name": "Rock_Basalt"
    },
    {
      "x": 1,
      "y": 11,
      "z": -16,
      "name": "Rock_Basalt"
    },
    {
      "x": 1,
      "y": 12,
      "z": -16,
      "name": "Rock_Basalt"
    },
    {
      "x": 1,
      "y": 13,
      "z": -16,
      "name": "Rock_Basalt"
    },
    {
      "x": 1,
      "y": 14,
      "z": -16,
      "name": "Rock_Basalt"
    },
    {
      "x": 1,
      "y": 13,
      "z": -15,
      "name": "Rock_Volcanic"
    },
    {
      "x": 1,
      "y": 14,
      "z": -15,
      "name": "Rock_Volcanic"
    },
    {
      "x": 1,
      "y": 15,
      "z": -15,
      "name": "Rock_Basalt"
    },
    {
      "x": 1,
      "y": 16,
      "z": -15,
      "name": "Rock_Basalt"
    },
    {
      "x": 1,
      "y": 14,
      "z": -14,
      "name": "Rock_Volcanic"
    },
    {
      "x": 1,
      "y": 15,
      "z": -14,
      "name": "Rock_Volcanic"
    },
    {
      "x": 1,
      "y": 16,
      "z": -14,
      "name": "Rock_Basalt"
    },
    {
      "x": 1,
      "y": 17,
      "z": -14,
      "name": "Rock_Basalt"
    },
    {
      "x": 1,
      "y": 14,
      "z": -13,
      "name": "Rock_Volcanic"
    },
    {
      "x": 1,
      "y": 15,
      "z": -13,
      "name": "Rock_Volcanic"
    },
    {
      "x": 1,
      "y": 16,
      "z": -13,
      "name": "Rock_Basalt"
    },
    {
      "x": 1,
      "y": 17,
      "z": -13,
      "name": "Rock_Basalt"
    },
    {
      "x": 1,
      "y": 15,
      "z": -12,
      "name": "Rock_Volcanic"
    },
    {
      "x": 1,
      "y": 16,
      "z": -12,
      "name": "Rock_Volcanic"
    },
    {
      "x": 1,
      "y": 17,
      "z": -12,
      "name": "Rock_Basalt"
    },
    {
      "x": 1,
      "y": 18,
      "z": -12,
      "name": "Rock_Basalt"
    },
    {
      "x": 1,
      "y": 16,
      "z": -11,
      "name": "Rock_Volcanic"
    },
    {
      "x": 1,
      "y": 17,
      "z": -11,
      "name": "Rock_Volcanic"
    },
    {
      "x": 1,
      "y": 18,
      "z": -11,
      "name": "Rock_Basalt"
    },
    {
      "x": 1,
      "y": 19,
      "z": -11,
      "name": "Rock_Basalt"
    },
    {
      "x": 1,
      "y": 16,
      "z": -10,
      "name": "Rock_Volcanic"
    },
    {
      "x": 1,
      "y": 17,
      "z": -10,
      "name": "Rock_Volcanic"
    },
    {
      "x": 1,
      "y": 18,
      "z": -10,
      "name": "Rock_Basalt"
    },
    {
      "x": 1,
      "y": 19,
      "z": -10,
      "name": "Rock_Basalt"
    },
    {
      "x": 1,
      "y": 20,
      "z": -10,
      "name": "Rock_Basalt"
    },
    {
      "x": 1,
      "y": 17,
      "z": -9,
      "name": "Rock_Volcanic"
    },
    {
      "x": 1,
      "y": 18,
      "z": -9,
      "name": "Rock_Volcanic"
    },
    {
      "x": 1,
      "y": 19,
      "z": -9,
      "name": "Rock_Basalt"
    },
    {
      "x": 1,
      "y": 20,
      "z": -9,
      "name": "Rock_Basalt"
    },
    {
      "x": 1,
      "y": 18,
      "z": -8,
      "name": "Rock_Volcanic"
    },
    {
      "x": 1,
      "y": 19,
      "z": -8,
      "name": "Rock_Volcanic"
    },
    {
      "x": 1,
      "y": 20,
      "z": -8,
      "name": "Rock_Basalt"
    },
    {
      "x": 1,
      "y": 21,
      "z": -8,
      "name": "Rock_Basalt"
    },
    {
      "x": 1,
      "y": 19,
      "z": -7,
      "name": "Rock_Volcanic"
    },
    {
      "x": 1,
      "y": 20,
      "z": -7,
      "name": "Rock_Volcanic"
    },
    {
      "x": 1,
      "y": 21,
      "z": -7,
      "name": "Rock_Basalt"
    },
    {
      "x": 1,
      "y": 22,
      "z": -7,
      "name": "Rock_Basalt"
    },
    {
      "x": 1,
      "y": 22,
      "z": -6,
      "name": "Rock_Basalt"
    },
    {
      "x": 1,
      "y": 23,
      "z": -6,
      "name": "Rock_Basalt"
    },
    {
      "x": 1,
      "y": 23,
      "z": -2,
      "name": "Rock_Basalt"
    },
    {
      "x": 1,
      "y": 24,
      "z": -2,
      "name": "Rock_Basalt"
    },
    {
      "x": 1,
      "y": 21,
      "z": -1,
      "name": "Rock_Volcanic"
    },
    {
      "x": 1,
      "y": 22,
      "z": -1,
      "name": "Rock_Volcanic"
    },
    {
      "x": 1,
      "y": 23,
      "z": -1,
      "name": "Rock_Basalt"
    },
    {
      "x": 1,
      "y": 21,
      "z": 5,
      "name": "Rock_Volcanic"
    },
    {
      "x": 1,
      "y": 22,
      "z": 5,
      "name": "Rock_Volcanic"
    },
    {
      "x": 1,
      "y": 23,
      "z": 5,
      "name": "Rock_Basalt"
    },
    {
      "x": 1,
      "y": 21,
      "z": 6,
      "name": "Rock_Volcanic"
    },
    {
      "x": 1,
      "y": 22,
      "z": 6,
      "name": "Rock_Volcanic"
    },
    {
      "x": 1,
      "y": 23,
      "z": 6,
      "name": "Rock_Basalt"
    },
    {
      "x": 1,
      "y": 24,
      "z": 6,
      "name": "Rock_Basalt"
    },
    {
      "x": 1,
      "y": 20,
      "z": 7,
      "name": "Rock_Volcanic"
    },
    {
      "x": 1,
      "y": 21,
      "z": 7,
      "name": "Rock_Volcanic"
    },
    {
      "x": 1,
      "y": 22,
      "z": 7,
      "name": "Rock_Basalt"
    },
    {
      "x": 1,
      "y": 23,
      "z": 7,
      "name": "Rock_Basalt"
    },
    {
      "x": 1,
      "y": 24,
      "z": 7,
      "name": "Rock_Basalt"
    },
    {
      "x": 1,
      "y": 19,
      "z": 8,
      "name": "Rock_Volcanic"
    },
    {
      "x": 1,
      "y": 20,
      "z": 8,
      "name": "Rock_Volcanic"
    },
    {
      "x": 1,
      "y": 21,
      "z": 8,
      "name": "Rock_Basalt"
    },
    {
      "x": 1,
      "y": 22,
      "z": 8,
      "name": "Rock_Basalt"
    },
    {
      "x": 1,
      "y": 23,
      "z": 8,
      "name": "Rock_Basalt"
    },
    {
      "x": 1,
      "y": 18,
      "z": 9,
      "name": "Rock_Volcanic"
    },
    {
      "x": 1,
      "y": 19,
      "z": 9,
      "name": "Rock_Volcanic"
    },
    {
      "x": 1,
      "y": 20,
      "z": 9,
      "name": "Rock_Basalt"
    },
    {
      "x": 1,
      "y": 21,
      "z": 9,
      "name": "Rock_Basalt"
    },
    {
      "x": 1,
      "y": 17,
      "z": 10,
      "name": "Rock_Volcanic"
    },
    {
      "x": 1,
      "y": 18,
      "z": 10,
      "name": "Rock_Volcanic"
    },
    {
      "x": 1,
      "y": 19,
      "z": 10,
      "name": "Rock_Basalt"
    },
    {
      "x": 1,
      "y": 20,
      "z": 10,
      "name": "Rock_Basalt"
    },
    {
      "x": 1,
      "y": 16,
      "z": 11,
      "name": "Rock_Volcanic"
    },
    {
      "x": 1,
      "y": 17,
      "z": 11,
      "name": "Rock_Volcanic"
    },
    {
      "x": 1,
      "y": 18,
      "z": 11,
      "name": "Rock_Basalt"
    },
    {
      "x": 1,
      "y": 19,
      "z": 11,
      "name": "Rock_Basalt"
    },
    {
      "x": 1,
      "y": 15,
      "z": 12,
      "name": "Rock_Volcanic"
    },
    {
      "x": 1,
      "y": 16,
      "z": 12,
      "name": "Rock_Volcanic"
    },
    {
      "x": 1,
      "y": 17,
      "z": 12,
      "name": "Rock_Basalt"
    },
    {
      "x": 1,
      "y": 18,
      "z": 12,
      "name": "Rock_Basalt"
    },
    {
      "x": 1,
      "y": 14,
      "z": 13,
      "name": "Rock_Volcanic"
    },
    {
      "x": 1,
      "y": 15,
      "z": 13,
      "name": "Rock_Volcanic"
    },
    {
      "x": 1,
      "y": 16,
      "z": 13,
      "name": "Rock_Basalt"
    },
    {
      "x": 1,
      "y": 17,
      "z": 13,
      "name": "Rock_Basalt"
    },
    {
      "x": 1,
      "y": 13,
      "z": 14,
      "name": "Rock_Volcanic"
    },
    {
      "x": 1,
      "y": 14,
      "z": 14,
      "name": "Rock_Volcanic"
    },
    {
      "x": 1,
      "y": 15,
      "z": 14,
      "name": "Rock_Basalt"
    },
    {
      "x": 1,
      "y": 11,
      "z": 15,
      "name": "Rock_Basalt"
    },
    {
      "x": 1,
      "y": 12,
      "z": 15,
      "name": "Rock_Basalt"
    },
    {
      "x": 1,
      "y": 13,
      "z": 15,
      "name": "Rock_Basalt"
    },
    {
      "x": 1,
      "y": 14,
      "z": 15,
      "name": "Rock_Basalt"
    },
    {
      "x": 1,
      "y": 10,
      "z": 16,
      "name": "Rock_Basalt"
    },
    {
      "x": 1,
      "y": 11,
      "z": 16,
      "name": "Rock_Basalt"
    },
    {
      "x": 1,
      "y": 12,
      "z": 16,
      "name": "Rock_Basalt"
    },
    {
      "x": 2,
      "y": 10,
      "z": -18,
      "name": "Rock_Basalt"
    },
    {
      "x": 2,
      "y": 11,
      "z": -18,
      "name": "Rock_Basalt"
    },
    {
      "x": 2,
      "y": 12,
      "z": -18,
      "name": "Rock_Basalt"
    },
    {
      "x": 2,
      "y": 11,
      "z": -17,
      "name": "Rock_Basalt"
    },
    {
      "x": 2,
      "y": 12,
      "z": -17,
      "name": "Rock_Basalt"
    },
    {
      "x": 2,
      "y": 13,
      "z": -17,
      "name": "Rock_Basalt"
    },
    {
      "x": 2,
      "y": 14,
      "z": -17,
      "name": "Rock_Basalt"
    },
    {
      "x": 2,
      "y": 12,
      "z": -16,
      "name": "Rock_Volcanic"
    },
    {
      "x": 2,
      "y": 13,
      "z": -16,
      "name": "Rock_Volcanic"
    },
    {
      "x": 2,
      "y": 14,
      "z": -16,
      "name": "Rock_Basalt"
    },
    {
      "x": 2,
      "y": 15,
      "z": -16,
      "name": "Rock_Basalt"
    },
    {
      "x": 2,
      "y": 13,
      "z": -15,
      "name": "Rock_Volcanic"
    },
    {
      "x": 2,
      "y": 14,
      "z": -15,
      "name": "Rock_Volcanic"
    },
    {
      "x": 2,
      "y": 15,
      "z": -15,
      "name": "Rock_Basalt"
    },
    {
      "x": 2,
      "y": 16,
      "z": -15,
      "name": "Rock_Basalt"
    },
    {
      "x": 2,
      "y": 14,
      "z": -14,
      "name": "Rock_Volcanic"
    },
    {
      "x": 2,
      "y": 15,
      "z": -14,
      "name": "Rock_Volcanic"
    },
    {
      "x": 2,
      "y": 16,
      "z": -14,
      "name": "Rock_Basalt"
    },
    {
      "x": 2,
      "y": 17,
      "z": -14,
      "name": "Rock_Basalt"
    },
    {
      "x": 2,
      "y": 15,
      "z": -13,
      "name": "Rock_Volcanic"
    },
    {
      "x": 2,
      "y": 16,
      "z": -13,
      "name": "Rock_Volcanic"
    },
    {
      "x": 2,
      "y": 17,
      "z": -13,
      "name": "Rock_Basalt"
    },
    {
      "x": 2,
      "y": 18,
      "z": -13,
      "name": "Rock_Basalt"
    },
    {
      "x": 2,
      "y": 16,
      "z": -12,
      "name": "Rock_Volcanic"
    },
    {
      "x": 2,
      "y": 17,
      "z": -12,
      "name": "Rock_Volcanic"
    },
    {
      "x": 2,
      "y": 18,
      "z": -12,
      "name": "Rock_Basalt"
    },
    {
      "x": 2,
      "y": 19,
      "z": -12,
      "name": "Rock_Basalt"
    },
    {
      "x": 2,
      "y": 16,
      "z": -11,
      "name": "Rock_Volcanic"
    },
    {
      "x": 2,
      "y": 17,
      "z": -11,
      "name": "Rock_Volcanic"
    },
    {
      "x": 2,
      "y": 18,
      "z": -11,
      "name": "Rock_Basalt"
    },
    {
      "x": 2,
      "y": 19,
      "z": -11,
      "name": "Rock_Basalt"
    },
    {
      "x": 2,
      "y": 17,
      "z": -10,
      "name": "Rock_Volcanic"
    },
    {
      "x": 2,
      "y": 18,
      "z": -10,
      "name": "Rock_Volcanic"
    },
    {
      "x": 2,
      "y": 19,
      "z": -10,
      "name": "Rock_Basalt"
    },
    {
      "x": 2,
      "y": 20,
      "z": -10,
      "name": "Rock_Basalt"
    },
    {
      "x": 2,
      "y": 18,
      "z": -9,
      "name": "Rock_Volcanic"
    },
    {
      "x": 2,
      "y": 19,
      "z": -9,
      "name": "Rock_Volcanic"
    },
    {
      "x": 2,
      "y": 20,
      "z": -9,
      "name": "Rock_Basalt"
    },
    {
      "x": 2,
      "y": 21,
      "z": -9,
      "name": "Rock_Basalt"
    },
    {
      "x": 2,
      "y": 19,
      "z": -8,
      "name": "Rock_Volcanic"
    },
    {
      "x": 2,
      "y": 20,
      "z": -8,
      "name": "Rock_Volcanic"
    },
    {
      "x": 2,
      "y": 21,
      "z": -8,
      "name": "Rock_Basalt"
    },
    {
      "x": 2,
      "y": 22,
      "z": -8,
      "name": "Rock_Basalt"
    },
    {
      "x": 2,
      "y": 19,
      "z": -7,
      "name": "Rock_Volcanic"
    },
    {
      "x": 2,
      "y": 20,
      "z": -7,
      "name": "Rock_Volcanic"
    },
    {
      "x": 2,
      "y": 21,
      "z": -7,
      "name": "Rock_Basalt"
    },
    {
      "x": 2,
      "y": 22,
      "z": -7,
      "name": "Rock_Basalt"
    },
    {
      "x": 2,
      "y": 23,
      "z": -7,
      "name": "Rock_Basalt"
    },
    {
      "x": 2,
      "y": 23,
      "z": -3,
      "name": "Rock_Basalt"
    },
    {
      "x": 2,
      "y": 24,
      "z": -3,
      "name": "Rock_Basalt"
    },
    {
      "x": 2,
      "y": 21,
      "z": -2,
      "name": "Rock_Volcanic"
    },
    {
      "x": 2,
      "y": 22,
      "z": -2,
      "name": "Rock_Volcanic"
    },
    {
      "x": 2,
      "y": 23,
      "z": -2,
      "name": "Rock_Basalt"
    },
    {
      "x": 2,
      "y": 22,
      "z": -1,
      "name": "Rock_Volcanic"
    },
    {
      "x": 2,
      "y": 23,
      "z": -1,
      "name": "Rock_Volcanic"
    },
    {
      "x": 2,
      "y": 22,
      "z": 0,
      "name": "Rock_Volcanic"
    },
    {
      "x": 2,
      "y": 23,
      "z": 0,
      "name": "Rock_Volcanic"
    },
    {
      "x": 2,
      "y": 21,
      "z": 5,
      "name": "Rock_Volcanic"
    },
    {
      "x": 2,
      "y": 22,
      "z": 5,
      "name": "Rock_Volcanic"
    },
    {
      "x": 2,
      "y": 23,
      "z": 5,
      "name": "Rock_Basalt"
    },
    {
      "x": 2,
      "y": 21,
      "z": 6,
      "name": "Rock_Volcanic"
    },
    {
      "x": 2,
      "y": 22,
      "z": 6,
      "name": "Rock_Volcanic"
    },
    {
      "x": 2,
      "y": 23,
      "z": 6,
      "name": "Rock_Basalt"
    },
    {
      "x": 2,
      "y": 24,
      "z": 6,
      "name": "Rock_Basalt"
    },
    {
      "x": 2,
      "y": 20,
      "z": 7,
      "name": "Rock_Volcanic"
    },
    {
      "x": 2,
      "y": 21,
      "z": 7,
      "name": "Rock_Volcanic"
    },
    {
      "x": 2,
      "y": 22,
      "z": 7,
      "name": "Rock_Basalt"
    },
    {
      "x": 2,
      "y": 23,
      "z": 7,
      "name": "Rock_Basalt"
    },
    {
      "x": 2,
      "y": 19,
      "z": 8,
      "name": "Rock_Volcanic"
    },
    {
      "x": 2,
      "y": 20,
      "z": 8,
      "name": "Rock_Volcanic"
    },
    {
      "x": 2,
      "y": 21,
      "z": 8,
      "name": "Rock_Basalt"
    },
    {
      "x": 2,
      "y": 22,
      "z": 8,
      "name": "Rock_Basalt"
    },
    {
      "x": 2,
      "y": 18,
      "z": 9,
      "name": "Rock_Volcanic"
    },
    {
      "x": 2,
      "y": 19,
      "z": 9,
      "name": "Rock_Volcanic"
    },
    {
      "x": 2,
      "y": 20,
      "z": 9,
      "name": "Rock_Basalt"
    },
    {
      "x": 2,
      "y": 21,
      "z": 9,
      "name": "Rock_Basalt"
    },
    {
      "x": 2,
      "y": 17,
      "z": 10,
      "name": "Rock_Volcanic"
    },
    {
      "x": 2,
      "y": 18,
      "z": 10,
      "name": "Rock_Volcanic"
    },
    {
      "x": 2,
      "y": 19,
      "z": 10,
      "name": "Rock_Basalt"
    },
    {
      "x": 2,
      "y": 20,
      "z": 10,
      "name": "Rock_Basalt"
    },
    {
      "x": 2,
      "y": 15,
      "z": 11,
      "name": "Rock_Volcanic"
    },
    {
      "x": 2,
      "y": 16,
      "z": 11,
      "name": "Rock_Volcanic"
    },
    {
      "x": 2,
      "y": 17,
      "z": 11,
      "name": "Rock_Basalt"
    },
    {
      "x": 2,
      "y": 18,
      "z": 11,
      "name": "Rock_Basalt"
    },
    {
      "x": 2,
      "y": 14,
      "z": 12,
      "name": "Rock_Volcanic"
    },
    {
      "x": 2,
      "y": 15,
      "z": 12,
      "name": "Rock_Volcanic"
    },
    {
      "x": 2,
      "y": 16,
      "z": 12,
      "name": "Rock_Basalt"
    },
    {
      "x": 2,
      "y": 17,
      "z": 12,
      "name": "Rock_Basalt"
    },
    {
      "x": 2,
      "y": 13,
      "z": 13,
      "name": "Rock_Volcanic"
    },
    {
      "x": 2,
      "y": 14,
      "z": 13,
      "name": "Rock_Volcanic"
    },
    {
      "x": 2,
      "y": 15,
      "z": 13,
      "name": "Rock_Basalt"
    },
    {
      "x": 2,
      "y": 16,
      "z": 13,
      "name": "Rock_Basalt"
    },
    {
      "x": 2,
      "y": 12,
      "z": 14,
      "name": "Rock_Basalt"
    },
    {
      "x": 2,
      "y": 13,
      "z": 14,
      "name": "Rock_Basalt"
    },
    {
      "x": 2,
      "y": 14,
      "z": 14,
      "name": "Rock_Basalt"
    },
    {
      "x": 2,
      "y": 15,
      "z": 14,
      "name": "Rock_Basalt"
    },
    {
      "x": 2,
      "y": 11,
      "z": 15,
      "name": "Rock_Basalt"
    },
    {
      "x": 2,
      "y": 12,
      "z": 15,
      "name": "Rock_Basalt"
    },
    {
      "x": 2,
      "y": 13,
      "z": 15,
      "name": "Rock_Basalt"
    },
    {
      "x": 2,
      "y": 14,
      "z": 15,
      "name": "Rock_Basalt"
    },
    {
      "x": 2,
      "y": 9,
      "z": 16,
      "name": "Rock_Basalt"
    },
    {
      "x": 2,
      "y": 10,
      "z": 16,
      "name": "Rock_Basalt"
    },
    {
      "x": 2,
      "y": 11,
      "z": 16,
      "name": "Rock_Basalt"
    },
    {
      "x": 2,
      "y": 12,
      "z": 16,
      "name": "Rock_Basalt"
    },
    {
      "x": 3,
      "y": 9,
      "z": -19,
      "name": "Rock_Basalt"
    },
    {
      "x": 3,
      "y": 10,
      "z": -19,
      "name": "Rock_Basalt"
    },
    {
      "x": 3,
      "y": 11,
      "z": -19,
      "name": "Rock_Basalt"
    },
    {
      "x": 3,
      "y": 12,
      "z": -19,
      "name": "Rock_Basalt"
    },
    {
      "x": 3,
      "y": 10,
      "z": -18,
      "name": "Rock_Basalt"
    },
    {
      "x": 3,
      "y": 11,
      "z": -18,
      "name": "Rock_Basalt"
    },
    {
      "x": 3,
      "y": 12,
      "z": -18,
      "name": "Rock_Basalt"
    },
    {
      "x": 3,
      "y": 13,
      "z": -18,
      "name": "Rock_Basalt"
    },
    {
      "x": 3,
      "y": 11,
      "z": -17,
      "name": "Rock_Basalt"
    },
    {
      "x": 3,
      "y": 12,
      "z": -17,
      "name": "Rock_Basalt"
    },
    {
      "x": 3,
      "y": 13,
      "z": -17,
      "name": "Rock_Basalt"
    },
    {
      "x": 3,
      "y": 14,
      "z": -17,
      "name": "Rock_Basalt"
    },
    {
      "x": 3,
      "y": 13,
      "z": -16,
      "name": "Rock_Volcanic"
    },
    {
      "x": 3,
      "y": 14,
      "z": -16,
      "name": "Rock_Volcanic"
    },
    {
      "x": 3,
      "y": 15,
      "z": -16,
      "name": "Rock_Basalt"
    },
    {
      "x": 3,
      "y": 14,
      "z": -15,
      "name": "Rock_Volcanic"
    },
    {
      "x": 3,
      "y": 15,
      "z": -15,
      "name": "Rock_Volcanic"
    },
    {
      "x": 3,
      "y": 16,
      "z": -15,
      "name": "Rock_Basalt"
    },
    {
      "x": 3,
      "y": 17,
      "z": -15,
      "name": "Rock_Basalt"
    },
    {
      "x": 3,
      "y": 15,
      "z": -14,
      "name": "Rock_Volcanic"
    },
    {
      "x": 3,
      "y": 16,
      "z": -14,
      "name": "Rock_Volcanic"
    },
    {
      "x": 3,
      "y": 17,
      "z": -14,
      "name": "Rock_Basalt"
    },
    {
      "x": 3,
      "y": 15,
      "z": -13,
      "name": "Rock_Volcanic"
    },
    {
      "x": 3,
      "y": 16,
      "z": -13,
      "name": "Rock_Volcanic"
    },
    {
      "x": 3,
      "y": 17,
      "z": -13,
      "name": "Rock_Basalt"
    },
    {
      "x": 3,
      "y": 18,
      "z": -13,
      "name": "Rock_Basalt"
    },
    {
      "x": 3,
      "y": 16,
      "z": -12,
      "name": "Rock_Volcanic"
    },
    {
      "x": 3,
      "y": 17,
      "z": -12,
      "name": "Rock_Volcanic"
    },
    {
      "x": 3,
      "y": 18,
      "z": -12,
      "name": "Rock_Basalt"
    },
    {
      "x": 3,
      "y": 19,
      "z": -12,
      "name": "Rock_Basalt"
    },
    {
      "x": 3,
      "y": 16,
      "z": -11,
      "name": "Rock_Volcanic"
    },
    {
      "x": 3,
      "y": 17,
      "z": -11,
      "name": "Rock_Volcanic"
    },
    {
      "x": 3,
      "y": 18,
      "z": -11,
      "name": "Rock_Basalt"
    },
    {
      "x": 3,
      "y": 19,
      "z": -11,
      "name": "Rock_Basalt"
    },
    {
      "x": 3,
      "y": 20,
      "z": -11,
      "name": "Rock_Basalt"
    },
    {
      "x": 3,
      "y": 17,
      "z": -10,
      "name": "Rock_Volcanic"
    },
    {
      "x": 3,
      "y": 18,
      "z": -10,
      "name": "Rock_Volcanic"
    },
    {
      "x": 3,
      "y": 19,
      "z": -10,
      "name": "Rock_Basalt"
    },
    {
      "x": 3,
      "y": 20,
      "z": -10,
      "name": "Rock_Basalt"
    },
    {
      "x": 3,
      "y": 18,
      "z": -9,
      "name": "Rock_Volcanic"
    },
    {
      "x": 3,
      "y": 19,
      "z": -9,
      "name": "Rock_Volcanic"
    },
    {
      "x": 3,
      "y": 20,
      "z": -9,
      "name": "Rock_Basalt"
    },
    {
      "x": 3,
      "y": 21,
      "z": -9,
      "name": "Rock_Basalt"
    },
    {
      "x": 3,
      "y": 19,
      "z": -8,
      "name": "Rock_Volcanic"
    },
    {
      "x": 3,
      "y": 20,
      "z": -8,
      "name": "Rock_Volcanic"
    },
    {
      "x": 3,
      "y": 21,
      "z": -8,
      "name": "Rock_Basalt"
    },
    {
      "x": 3,
      "y": 22,
      "z": -8,
