{
  "version": 8,
  "blockIdVersion": 8,
  "anchorX": 0,
  "anchorY": 0,
  "anchorZ": 0,
  "blocks": [
    {
      "x": -25,
      "y": 1,
      "z": -3,
      "name": "Rock_Basalt"
    },
    {
      "x": -25,
      "y": 2,
      "z": -3,
      "name": "Rock_Basalt"
    },
    {
      "x": -25,
      "y": 3,
      "z": -3,
      "name": "Rock_Basalt"
    },
    {
      "x": -25,
      "y": 4,
      "z": -3,
      "name": "Rock_Basalt"
    },
    {
      "x": -25,
      "y": 0,
      "z": -2,
      "name": "Rock_Basalt"
    },
    {
      "x": -25,
      "y": 1,
      "z": -2,
      "name": "Rock_Basalt"
    },
    {
      "x": -25,
      "y": 2,
      "z": -2,
      "name": "Rock_Basalt"
    },
    {
      "x": -25,
      "y": 3,
      "z": -2,
      "name": "Rock_Basalt"
    },
    {
      "x": -25,
      "y": 4,
      "z": -2,
      "name": "Rock_Basalt"
    },
    {
      "x": -25,
      "y": 5,
      "z": -2,
      "name": "Rock_Basalt"
    },
    {
      "x": -25,
      "y": 0,
      "z": -1,
      "name": "Rock_Basalt"
    },
    {
      "x": -25,
      "y": 1,
      "z": -1,
      "name": "Rock_Basalt"
    },
    {
      "x": -25,
      "y": 2,
      "z": -1,
      "name": "Rock_Basalt"
    },
    {
      "x": -25,
      "y": 3,
      "z": -1,
      "name": "Rock_Basalt"
    },
    {
      "x": -25,
      "y": 4,
      "z": -1,
      "name": "Rock_Basalt"
    },
    {
      "x": -25,
      "y": 5,
      "z": -1,
      "name": "Rock_Basalt"
    },
    {
      "x": -25,
      "y": 6,
      "z": -1,
      "name": "Rock_Basalt"
    },
    {
      "x": -25,
      "y": -1,
      "z": 0,
      "name": "Rock_Basalt"
    },
    {
      "x": -25,
      "y": 0,
      "z": 0,
      "name": "Rock_Basalt"
    },
    {
      "x": -25,
      "y": 4,
      "z": 0,
      "name": "Rock_Basalt"
    },
    {
      "x": -25,
      "y": 5,
      "z": 0,
      "name": "Rock_Basalt"
    },
    {
      "x": -25,
      "y": 6,
      "z": 0,
      "name": "Rock_Basalt"
    },
    {
      "x": -25,
      "y": 7,
      "z": 0,
      "name": "Rock_Basalt"
    },
    {
      "x": -25,
      "y": 5,
      "z": 1,
      "name": "Rock_Basalt"
    },
    {
      "x": -25,
      "y": 6,
      "z": 1,
      "name": "Rock_Basalt"
    },
    {
      "x": -25,
      "y": 7,
      "z": 1,
      "name": "Rock_Basalt"
    },
    {
      "x": -25,
      "y": 8,
      "z": 1,
      "name": "Rock_Basalt"
    },
    {
      "x": -25,
      "y": 6,
      "z": 2,
      "name": "Rock_Basalt"
    },
    {
      "x": -25,
      "y": 7,
      "z": 2,
      "name": "Rock_Basalt"
    },
    {
      "x": -25,
      "y": 8,
      "z": 2,
      "name": "Rock_Basalt"
    },
    {
      "x": -25,
      "y": 6,
      "z": 3,
      "name": "Rock_Basalt"
    },
    {
      "x": -25,
      "y": 7,
      "z": 3,
      "name": "Rock_Basalt"
    },
    {
      "x": -25,
      "y": 8,
      "z": 3,
      "name": "Rock_Basalt"
    },
    {
      "x": -25,
      "y": -2,
      "z": 4,
      "name": "Rock_Basalt"
    },
    {
      "x": -25,
      "y": 7,
      "z": 4,
      "name": "Rock_Basalt"
    },
    {
      "x": -25,
      "y": 8,
      "z": 4,
      "name": "Rock_Basalt"
    },
    {
      "x": -25,
      "y": -2,
      "z": 5,
      "name": "Rock_Basalt"
    },
    {
      "x": -25,
      "y": -1,
      "z": 5,
      "name": "Rock_Basalt"
    },
    {
      "x": -25,
      "y": 7,
      "z": 5,
      "name": "Rock_Basalt"
    },
    {
      "x": -25,
      "y": 8,
      "z": 5,
      "name": "Rock_Basalt"
    },
    {
      "x": -25,
      "y": -2,
      "z": 6,
      "name": "Rock_Basalt"
    },
    {
      "x": -25,
      "y": -1,
      "z": 6,
      "name": "Rock_Basalt"
    },
    {
      "x": -25,
      "y": 6,
      "z": 6,
      "name": "Rock_Basalt"
    },
    {
      "x": -25,
      "y": 7,
      "z": 6,
      "name": "Rock_Basalt"
    },
    {
      "x": -25,
      "y": -1,
      "z": 7,
      "name": "Rock_Basalt"
    },
    {
      "x": -25,
      "y": 7,
      "z": 7,
      "name": "Rock_Basalt"
    },
    {
      "x": -25,
      "y": -1,
      "z": 8,
      "name": "Rock_Basalt"
    },
    {
      "x": -25,
      "y": 0,
      "z": 8,
      "name": "Rock_Basalt"
    },
    {
      "x": -25,
      "y": 0,
      "z": 9,
      "name": "Rock_Basalt"
    },
    {
      "x": -25,
      "y": 1,
      "z": 9,
      "name": "Rock_Basalt"
    },
    {
      "x": -25,
      "y": 1,
      "z": 10,
      "name": "Rock_Basalt"
    },
    {
      "x": -25,
      "y": 2,
      "z": 10,
      "name": "Rock_Basalt"
    },
    {
      "x": -25,
      "y": 3,
      "z": 10,
      "name": "Rock_Basalt"
    },
    {
      "x": -25,
      "y": 4,
      "z": 10,
      "name": "Rock_Basalt"
    },
    {
      "x": -25,
      "y": 5,
      "z": 10,
      "name": "Rock_Basalt"
    },
    {
      "x": -25,
      "y": 2,
      "z": 11,
      "name": "Rock_Basalt"
    },
    {
      "x": -25,
      "y": 3,
      "z": 11,
      "name": "Rock_Basalt"
    },
    {
      "x": -25,
      "y": 4,
      "z": 11,
      "name": "Rock_Basalt"
    },
    {
      "x": -25,
      "y": 5,
      "z": 11,
      "name": "Rock_Basalt"
    },
    {
      "x": -24,
      "y": 1,
      "z": -5,
      "name": "Rock_Basalt"
    },
    {
      "x": -24,
      "y": 2,
      "z": -5,
      "name": "Rock_Basalt"
    },
    {
      "x": -24,
      "y": 3,
      "z": -5,
      "name": "Rock_Basalt"
    },
    {
      "x": -24,
      "y": 4,
      "z": -5,
      "name": "Rock_Basalt"
    },
    {
      "x": -24,
      "y": 0,
      "z": -4,
      "name": "Rock_Basalt"
    },
    {
      "x": -24,
      "y": 1,
      "z": -4,
      "name": "Rock_Basalt"
    },
    {
      "x": -24,
      "y": 2,
      "z": -4,
      "name": "Rock_Basalt"
    },
    {
      "x": -24,
      "y": 3,
      "z": -4,
      "name": "Rock_Basalt"
    },
    {
      "x": -24,
      "y": 4,
      "z": -4,
      "name": "Rock_Basalt"
    },
    {
      "x": -24,
      "y": 5,
      "z": -4,
      "name": "Rock_Basalt"
    },
    {
      "x": -24,
      "y": 6,
      "z": -4,
      "name": "Rock_Basalt"
    },
    {
      "x": -24,
      "y": -1,
      "z": -3,
      "name": "Rock_Basalt"
    },
    {
      "x": -24,
      "y": 0,
      "z": -3,
      "name": "Rock_Basalt"
    },
    {
      "x": -24,
      "y": 1,
      "z": -3,
      "name": "Rock_Basalt"
    },
    {
      "x": -24,
      "y": 2,
      "z": -3,
      "name": "Rock_Basalt"
    },
    {
      "x": -24,
      "y": 3,
      "z": -3,
      "name": "Rock_Basalt"
    },
    {
      "x": -24,
      "y": 4,
      "z": -3,
      "name": "Rock_Basalt"
    },
    {
      "x": -24,
      "y": 5,
      "z": -3,
      "name": "Rock_Basalt"
    },
    {
      "x": -24,
      "y": 6,
      "z": -3,
      "name": "Rock_Basalt"
    },
    {
      "x": -24,
      "y": 7,
      "z": -3,
      "name": "Rock_Basalt"
    },
    {
      "x": -24,
      "y": -1,
      "z": -2,
      "name": "Rock_Basalt"
    },
    {
      "x": -24,
      "y": 0,
      "z": -2,
      "name": "Rock_Basalt"
    },
    {
      "x": -24,
      "y": 1,
      "z": -2,
      "name": "Rock_Basalt"
    },
    {
      "x": -24,
      "y": 2,
      "z": -2,
      "name": "Rock_Basalt"
    },
    {
      "x": -24,
      "y": 3,
      "z": -2,
      "name": "Rock_Basalt"
    },
    {
      "x": -24,
      "y": 4,
      "z": -2,
      "name": "Rock_Basalt"
    },
    {
      "x": -24,
      "y": 5,
      "z": -2,
      "name": "Rock_Basalt"
    },
    {
      "x": -24,
      "y": 6,
      "z": -2,
      "name": "Rock_Basalt"
    },
    {
      "x": -24,
      "y": 7,
      "z": -2,
      "name": "Rock_Basalt"
    },
    {
      "x": -24,
      "y": 8,
      "z": -2,
      "name": "Rock_Basalt"
    },
    {
      "x": -24,
      "y": -2,
      "z": -1,
      "name": "Rock_Basalt"
    },
    {
      "x": -24,
      "y": -1,
      "z": -1,
      "name": "Rock_Basalt"
    },
    {
      "x": -24,
      "y": 0,
      "z": -1,
      "name": "Rock_Basalt"
    },
    {
      "x": -24,
      "y": 1,
      "z": -1,
      "name": "Rock_Basalt"
    },
    {
      "x": -24,
      "y": 2,
      "z": -1,
      "name": "Rock_Basalt"
    },
    {
      "x": -24,
      "y": 3,
      "z": -1,
      "name": "Rock_Basalt"
    },
    {
      "x": -24,
      "y": 4,
      "z": -1,
      "name": "Rock_Basalt"
    },
    {
      "x": -24,
      "y": 5,
      "z": -1,
      "name": "Rock_Basalt"
    },
    {
      "x": -24,
      "y": 6,
      "z": -1,
      "name": "Rock_Basalt"
    },
    {
      "x": -24,
      "y": 7,
      "z": -1,
      "name": "Rock_Basalt"
    },
    {
      "x": -24,
      "y": 8,
      "z": -1,
      "name": "Rock_Basalt"
    },
    {
      "x": -24,
      "y": 9,
      "z": -1,
      "name": "Rock_Basalt"
    },
    {
      "x": -24,
      "y": -1,
      "z": 0,
      "name": "Rock_Basalt"
    },
    {
      "x": -24,
      "y": 0,
      "z": 0,
      "name": "Rock_Basalt"
    },
    {
      "x": -24,
      "y": 1,
      "z": 0,
      "name": "Rock_Basalt"
    },
    {
      "x": -24,
      "y": 2,
      "z": 0,
      "name": "Rock_Basalt"
    },
    {
      "x": -24,
      "y": 3,
      "z": 0,
      "name": "Rock_Basalt"
    },
    {
      "x": -24,
      "y": 4,
      "z": 0,
      "name": "Rock_Basalt"
    },
    {
      "x": -24,
      "y": 5,
      "z": 0,
      "name": "Rock_Basalt"
    },
    {
      "x": -24,
      "y": 6,
      "z": 0,
      "name": "Rock_Basalt"
    },
    {
      "x": -24,
      "y": 7,
      "z": 0,
      "name": "Rock_Basalt"
    },
    {
      "x": -24,
      "y": 8,
      "z": 0,
      "name": "Rock_Basalt"
    },
    {
      "x": -24,
      "y": 9,
      "z": 0,
      "name": "Rock_Basalt"
    },
    {
      "x": -24,
      "y": 0,
      "z": 1,
      "name": "Rock_Basalt"
    },
    {
      "x": -24,
      "y": 1,
      "z": 1,
      "name": "Rock_Volcanic"
    },
    {
      "x": -24,
      "y": 2,
      "z": 1,
      "name": "Rock_Volcanic"
    },
    {
      "x": -24,
      "y": 3,
      "z": 1,
      "name": "Rock_Volcanic"
    },
    {
      "x": -24,
      "y": 4,
      "z": 1,
      "name": "Rock_Basalt"
    },
    {
      "x": -24,
      "y": 5,
      "z": 1,
      "name": "Rock_Basalt"
    },
    {
      "x": -24,
      "y": 6,
      "z": 1,
      "name": "Rock_Basalt"
    },
    {
      "x": -24,
      "y": 7,
      "z": 1,
      "name": "Rock_Basalt"
    },
    {
      "x": -24,
      "y": 8,
      "z": 1,
      "name": "Rock_Basalt"
    },
    {
      "x": -24,
      "y": 9,
      "z": 1,
      "name": "Rock_Basalt"
    },
    {
      "x": -24,
      "y": 10,
      "z": 1,
      "name": "Rock_Basalt"
    },
    {
      "x": -24,
      "y": 2,
      "z": 2,
      "name": "Rock_Volcanic"
    },
    {
      "x": -24,
      "y": 3,
      "z": 2,
      "name": "Rock_Volcanic"
    },
    {
      "x": -24,
      "y": 4,
      "z": 2,
      "name": "Rock_Volcanic"
    },
    {
      "x": -24,
      "y": 5,
      "z": 2,
      "name": "Rock_Basalt"
    },
    {
      "x": -24,
      "y": 6,
      "z": 2,
      "name": "Rock_Basalt"
    },
    {
      "x": -24,
      "y": 7,
      "z": 2,
      "name": "Rock_Basalt"
    },
    {
      "x": -24,
      "y": 8,
      "z": 2,
      "name": "Rock_Basalt"
    },
    {
      "x": -24,
      "y": 9,
      "z": 2,
      "name": "Rock_Basalt"
    },
    {
      "x": -24,
      "y": 10,
      "z": 2,
      "name": "Rock_Basalt"
    },
    {
      "x": -24,
      "y": 4,
      "z": 3,
      "name": "Rock_Volcanic"
    },
    {
      "x": -24,
      "y": 5,
      "z": 3,
      "name": "Rock_Basalt"
    },
    {
      "x": -24,
      "y": 6,
      "z": 3,
      "name": "Rock_Basalt"
    },
    {
      "x": -24,
      "y": 7,
      "z": 3,
      "name": "Rock_Basalt"
    },
    {
      "x": -24,
      "y": 8,
      "z": 3,
      "name": "Rock_Basalt"
    },
    {
      "x": -24,
      "y": 9,
      "z": 3,
      "name": "Rock_Basalt"
    },
    {
      "x": -24,
      "y": 10,
      "z": 3,
      "name": "Rock_Basalt"
    },
    {
      "x": -24,
      "y": -3,
      "z": 4,
      "name": "Rock_Basalt"
    },
    {
      "x": -24,
      "y": -2,
      "z": 4,
      "name": "Rock_Basalt"
    },
    {
      "x": -24,
      "y": 5,
      "z": 4,
      "name": "Rock_Volcanic"
    },
    {
      "x": -24,
      "y": 6,
      "z": 4,
      "name": "Rock_Basalt"
    },
    {
      "x": -24,
      "y": 7,
      "z": 4,
      "name": "Rock_Basalt"
    },
    {
      "x": -24,
      "y": 8,
      "z": 4,
      "name": "Rock_Basalt"
    },
    {
      "x": -24,
      "y": 9,
      "z": 4,
      "name": "Rock_Basalt"
    },
    {
      "x": -24,
      "y": 10,
      "z": 4,
      "name": "Rock_Basalt"
    },
    {
      "x": -24,
      "y": -3,
      "z": 5,
      "name": "Rock_Basalt"
    },
    {
      "x": -24,
      "y": -2,
      "z": 5,
      "name": "Rock_Basalt"
    },
    {
      "x": -24,
      "y": -1,
      "z": 5,
      "name": "Rock_Basalt"
    },
    {
      "x": -24,
      "y": 5,
      "z": 5,
      "name": "Rock_Volcanic"
    },
    {
      "x": -24,
      "y": 6,
      "z": 5,
      "name": "Rock_Basalt"
    },
    {
      "x": -24,
      "y": 7,
      "z": 5,
      "name": "Rock_Basalt"
    },
    {
      "x": -24,
      "y": 8,
      "z": 5,
      "name": "Rock_Basalt"
    },
    {
      "x": -24,
      "y": 9,
      "z": 5,
      "name": "Rock_Basalt"
    },
    {
      "x": -24,
      "y": -3,
      "z": 6,
      "name": "Rock_Basalt"
    },
    {
      "x": -24,
      "y": -2,
      "z": 6,
      "name": "Rock_Basalt"
    },
    {
      "x": -24,
      "y": -1,
      "z": 6,
      "name": "Rock_Basalt"
    },
    {
      "x": -24,
      "y": 0,
      "z": 6,
      "name": "Rock_Basalt"
    },
    {
      "x": -24,
      "y": 6,
      "z": 6,
      "name": "Rock_Basalt"
    },
    {
      "x": -24,
      "y": 7,
      "z": 6,
      "name": "Rock_Basalt"
    },
    {
      "x": -24,
      "y": 8,
      "z": 6,
      "name": "Rock_Basalt"
    },
    {
      "x": -24,
      "y": -3,
      "z": 7,
      "name": "Rock_Basalt"
    },
    {
      "x": -24,
      "y": -2,
      "z": 7,
      "name": "Rock_Basalt"
    },
    {
      "x": -24,
      "y": -1,
      "z": 7,
      "name": "Rock_Basalt"
    },
    {
      "x": -24,
      "y": 0,
      "z": 7,
      "name": "Rock_Basalt"
    },
    {
      "x": -24,
      "y": 7,
      "z": 7,
      "name": "Rock_Basalt"
    },
    {
      "x": -24,
      "y": 8,
      "z": 7,
      "name": "Rock_Basalt"
    },
    {
      "x": -24,
      "y": -2,
      "z": 8,
      "name": "Rock_Basalt"
    },
    {
      "x": -24,
      "y": -1,
      "z": 8,
      "name": "Rock_Basalt"
    },
    {
      "x": -24,
      "y": 0,
      "z": 8,
      "name": "Rock_Basalt"
    },
    {
      "x": -24,
      "y": 1,
      "z": 8,
      "name": "Rock_Basalt"
    },
    {
      "x": -24,
      "y": 2,
      "z": 8,
      "name": "Rock_Volcanic"
    },
    {
      "x": -24,
      "y": 8,
      "z": 8,
      "name": "Rock_Basalt"
    },
    {
      "x": -24,
      "y": -2,
      "z": 9,
      "name": "Rock_Basalt"
    },
    {
      "x": -24,
      "y": -1,
      "z": 9,
      "name": "Rock_Basalt"
    },
    {
      "x": -24,
      "y": 0,
      "z": 9,
      "name": "Rock_Basalt"
    },
    {
      "x": -24,
      "y": 1,
      "z": 9,
      "name": "Rock_Basalt"
    },
    {
      "x": -24,
      "y": 2,
      "z": 9,
      "name": "Rock_Basalt"
    },
    {
      "x": -24,
      "y": 3,
      "z": 9,
      "name": "Rock_Basalt"
    },
    {
      "x": -24,
      "y": 4,
      "z": 9,
      "name": "Rock_Basalt"
    },
    {
      "x": -24,
      "y": -1,
      "z": 10,
      "name": "Rock_Basalt"
    },
    {
      "x": -24,
      "y": 0,
      "z": 10,
      "name": "Rock_Basalt"
    },
    {
      "x": -24,
      "y": 1,
      "z": 10,
      "name": "Rock_Basalt"
    },
    {
      "x": -24,
      "y": 2,
      "z": 10,
      "name": "Rock_Basalt"
    },
    {
      "x": -24,
      "y": 3,
      "z": 10,
      "name": "Rock_Basalt"
    },
    {
      "x": -24,
      "y": 4,
      "z": 10,
      "name": "Rock_Basalt"
    },
    {
      "x": -24,
      "y": 5,
      "z": 10,
      "name": "Rock_Basalt"
    },
    {
      "x": -24,
      "y": 0,
      "z": 11,
      "name": "Rock_Basalt"
    },
    {
      "x": -24,
      "y": 1,
      "z": 11,
      "name": "Rock_Basalt"
    },
    {
      "x": -24,
      "y": 2,
      "z": 11,
      "name": "Rock_Basalt"
    },
    {
      "x": -24,
      "y": 3,
      "z": 11,
      "name": "Rock_Basalt"
    },
    {
      "x": -24,
      "y": 4,
      "z": 11,
      "name": "Rock_Basalt"
    },
    {
      "x": -24,
      "y": 5,
      "z": 11,
      "name": "Rock_Basalt"
    },
    {
      "x": -24,
      "y": 6,
      "z": 11,
      "name": "Rock_Basalt"
    },
    {
      "x": -24,
      "y": 7,
      "z": 11,
      "name": "Rock_Basalt"
    },
    {
      "x": -24,
      "y": 1,
      "z": 12,
      "name": "Rock_Basalt"
    },
    {
      "x": -24,
      "y": 2,
      "z": 12,
      "name": "Rock_Basalt"
    },
    {
      "x": -24,
      "y": 3,
      "z": 12,
      "name": "Rock_Basalt"
    },
    {
      "x": -24,
      "y": 4,
      "z": 12,
      "name": "Rock_Basalt"
    },
    {
      "x": -24,
      "y": 5,
      "z": 12,
      "name": "Rock_Basalt"
    },
    {
      "x": -24,
      "y": 6,
      "z": 12,
      "name": "Rock_Basalt"
    },
    {
      "x": -24,
      "y": 3,
      "z": 13,
      "name": "Rock_Basalt"
    },
    {
      "x": -24,
      "y": 4,
      "z": 13,
      "name": "Rock_Basalt"
    },
    {
      "x": -23,
      "y": -1,
      "z": -6,
      "name": "Rock_Basalt"
    },
    {
      "x": -23,
      "y": 0,
      "z": -6,
      "name": "Rock_Basalt"
    },
    {
      "x": -23,
      "y": 1,
      "z": -6,
      "name": "Rock_Basalt"
    },
    {
      "x": -23,
      "y": 2,
      "z": -6,
      "name": "Rock_Basalt"
    },
    {
      "x": -23,
      "y": 3,
      "z": -6,
      "name": "Rock_Basalt"
    },
    {
      "x": -23,
      "y": 4,
      "z": -6,
      "name": "Rock_Basalt"
    },
    {
      "x": -23,
      "y": 5,
      "z": -6,
      "name": "Rock_Basalt"
    },
    {
      "x": -23,
      "y": -2,
      "z": -5,
      "name": "Rock_Basalt"
    },
    {
      "x": -23,
      "y": -1,
      "z": -5,
      "name": "Rock_Basalt"
    },
    {
      "x": -23,
      "y": 0,
      "z": -5,
      "name": "Rock_Basalt"
    },
    {
      "x": -23,
      "y": 1,
      "z": -5,
      "name": "Rock_Basalt"
    },
    {
      "x": -23,
      "y": 2,
      "z": -5,
      "name": "Rock_Basalt"
    },
    {
      "x": -23,
      "y": 3,
      "z": -5,
      "name": "Rock_Basalt"
    },
    {
      "x": -23,
      "y": 4,
      "z": -5,
      "name": "Rock_Basalt"
    },
    {
      "x": -23,
      "y": 5,
      "z": -5,
      "name": "Rock_Basalt"
    },
    {
      "x": -23,
      "y": 6,
      "z": -5,
      "name": "Rock_Basalt"
    },
    {
      "x": -23,
      "y": 7,
      "z": -5,
      "name": "Rock_Basalt"
    },
    {
      "x": -23,
      "y": -2,
      "z": -4,
      "name": "Rock_Basalt"
    },
    {
      "x": -23,
      "y": -1,
      "z": -4,
      "name": "Rock_Basalt"
    },
    {
      "x": -23,
      "y": 0,
      "z": -4,
      "name": "Rock_Basalt"
    },
    {
      "x": -23,
      "y": 1,
      "z": -4,
      "name": "Rock_Basalt"
    },
    {
      "x": -23,
      "y": 2,
      "z": -4,
      "name": "Rock_Basalt"
    },
    {
      "x": -23,
      "y": 3,
      "z": -4,
      "name": "Rock_Basalt"
    },
    {
      "x": -23,
      "y": 4,
      "z": -4,
      "name": "Rock_Basalt"
    },
    {
      "x": -23,
      "y": 5,
      "z": -4,
      "name": "Rock_Basalt"
    },
    {
      "x": -23,
      "y": 6,
      "z": -4,
      "name": "Rock_Basalt"
    },
    {
      "x": -23,
      "y": 7,
      "z": -4,
      "name": "Rock_Basalt"
    },
    {
      "x": -23,
      "y": 8,
      "z": -4,
      "name": "Rock_Basalt"
    },
    {
      "x": -23,
      "y": -3,
      "z": -3,
      "name": "Rock_Basalt"
    },
    {
      "x": -23,
      "y": -2,
      "z": -3,
      "name": "Rock_Basalt"
    },
    {
      "x": -23,
      "y": -1,
      "z": -3,
      "name": "Rock_Basalt"
    },
    {
      "x": -23,
      "y": 0,
      "z": -3,
      "name": "Rock_Basalt"
    },
    {
      "x": -23,
      "y": 1,
      "z": -3,
      "name": "Rock_Basalt"
    },
    {
      "x": -23,
      "y": 2,
      "z": -3,
      "name": "Rock_Basalt"
    },
    {
      "x": -23,
      "y": 3,
      "z": -3,
      "name": "Rock_Basalt"
    },
    {
      "x": -23,
      "y": 4,
      "z": -3,
      "name": "Rock_Basalt"
    },
    {
      "x": -23,
      "y": 5,
      "z": -3,
      "name": "Rock_Basalt"
    },
    {
      "x": -23,
      "y": 6,
      "z": -3,
      "name": "Rock_Basalt"
    },
    {
      "x": -23,
      "y": 7,
      "z": -3,
      "name": "Rock_Basalt"
    },
    {
      "x": -23,
      "y": 8,
      "z": -3,
      "name": "Rock_Basalt"
    },
    {
      "x": -23,
      "y": 9,
      "z": -3,
      "name": "Rock_Basalt"
    },
    {
      "x": -23,
      "y": -2,
      "z": -2,
      "name": "Rock_Basalt"
    },
    {
      "x": -23,
      "y": -1,
      "z": -2,
      "name": "Rock_Basalt"
    },
    {
      "x": -23,
      "y": 0,
      "z": -2,
      "name": "Rock_Basalt"
    },
    {
      "x": -23,
      "y": 1,
      "z": -2,
      "name": "Rock_Volcanic"
    },
    {
      "x": -23,
      "y": 2,
      "z": -2,
      "name": "Rock_Volcanic"
    },
    {
      "x": -23,
      "y": 3,
      "z": -2,
      "name": "Rock_Volcanic"
    },
    {
      "x": -23,
      "y": 4,
      "z": -2,
      "name": "Rock_Volcanic"
    },
    {
      "x": -23,
      "y": 5,
      "z": -2,
      "name": "Rock_Basalt"
    },
    {
      "x": -23,
      "y": 6,
      "z": -2,
      "name": "Rock_Basalt"
    },
    {
      "x": -23,
      "y": 7,
      "z": -2,
      "name": "Rock_Basalt"
    },
    {
      "x": -23,
      "y": 8,
      "z": -2,
      "name": "Rock_Basalt"
    },
    {
      "x": -23,
      "y": 9,
      "z": -2,
      "name": "Rock_Basalt"
    },
    {
      "x": -23,
      "y": 10,
      "z": -2,
      "name": "Rock_Basalt"
    },
    {
      "x": -23,
      "y": -2,
      "z": -1,
      "name": "Rock_Basalt"
    },
    {
      "x": -23,
      "y": -1,
      "z": -1,
      "name": "Rock_Basalt"
    },
    {
      "x": -23,
      "y": 0,
      "z": -1,
      "name": "Rock_Volcanic"
    },
    {
      "x": -23,
      "y": 1,
      "z": -1,
      "name": "Rock_Volcanic"
    },
    {
      "x": -23,
      "y": 2,
      "z": -1,
      "name": "Rock_Volcanic"
    },
    {
      "x": -23,
      "y": 3,
      "z": -1,
      "name": "Rock_Volcanic"
    },
    {
      "x": -23,
      "y": 4,
      "z": -1,
      "name": "Rock_Volcanic"
    },
    {
      "x": -23,
      "y": 5,
      "z": -1,
      "name": "Rock_Volcanic"
    },
    {
      "x": -23,
      "y": 6,
      "z": -1,
      "name": "Rock_Basalt"
    },
    {
      "x": -23,
      "y": 7,
      "z": -1,
      "name": "Rock_Basalt"
    },
    {
      "x": -23,
      "y": 8,
      "z": -1,
      "name": "Rock_Basalt"
    },
    {
      "x": -23,
      "y": 9,
      "z": -1,
      "name": "Rock_Basalt"
    },
    {
      "x": -23,
      "y": 10,
      "z": -1,
      "name": "Rock_Basalt"
    },
    {
      "x": -23,
      "y": -1,
      "z": 0,
      "name": "Rock_Basalt"
    },
    {
      "x": -23,
      "y": 0,
      "z": 0,
      "name": "Rock_Volcanic"
    },
    {
      "x": -23,
      "y": 1,
      "z": 0,
      "name": "Rock_Volcanic"
    },
    {
      "x": -23,
      "y": 2,
      "z": 0,
      "name": "Rock_Volcanic"
    },
    {
      "x": -23,
      "y": 3,
      "z": 0,
      "name": "Rock_Volcanic"
    },
    {
      "x": -23,
      "y": 4,
      "z": 0,
      "name": "Rock_Volcanic"
    },
    {
      "x": -23,
      "y": 5,
      "z": 0,
      "name": "Rock_Volcanic"
    },
    {
      "x": -23,
      "y": 6,
      "z": 0,
      "name": "Rock_Volcanic"
    },
    {
      "x": -23,
      "y": 7,
      "z": 0,
      "name": "Rock_Basalt"
    },
    {
      "x": -23,
      "y": 8,
      "z": 0,
      "name": "Rock_Basalt"
    },
    {
      "x": -23,
      "y": 9,
      "z": 0,
      "name": "Rock_Basalt"
    },
    {
      "x": -23,
      "y": 10,
      "z": 0,
      "name": "Rock_Basalt"
    },
    {
      "x": -23,
      "y": 11,
      "z": 0,
      "name": "Rock_Basalt"
    },
    {
      "x": -23,
      "y": 1,
      "z": 1,
      "name": "Rock_Volcanic"
    },
    {
      "x": -23,
      "y": 2,
      "z": 1,
      "name": "Rock_Volcanic"
    },
    {
      "x": -23,
      "y": 3,
      "z": 1,
      "name": "Rock_Volcanic"
    },
    {
      "x": -23,
      "y": 4,
      "z": 1,
      "name": "Rock_Volcanic"
    },
    {
      "x": -23,
      "y": 5,
      "z": 1,
      "name": "Rock_Volcanic"
    },
    {
      "x": -23,
      "y": 6,
      "z": 1,
      "name": "Rock_Volcanic"
    },
    {
      "x": -23,
      "y": 7,
      "z": 1,
      "name": "Rock_Volcanic"
    },
    {
      "x": -23,
      "y": 8,
      "z": 1,
      "name": "Rock_Basalt"
    },
    {
      "x": -23,
      "y": 9,
      "z": 1,
      "name": "Rock_Basalt"
    },
    {
      "x": -23,
      "y": 10,
      "z": 1,
      "name": "Rock_Basalt"
    },
    {
      "x": -23,
      "y": 11,
      "z": 1,
      "name": "Rock_Basalt"
    },
    {
      "x": -23,
      "y": 2,
      "z": 2,
      "name": "Rock_Volcanic"
    },
    {
      "x": -23,
      "y": 3,
      "z": 2,
      "name": "Rock_Volcanic"
    },
    {
      "x": -23,
      "y": 4,
      "z": 2,
      "name": "Rock_Volcanic"
    },
    {
      "x": -23,
      "y": 5,
      "z": 2,
      "name": "Rock_Volcanic"
    },
    {
      "x": -23,
      "y": 6,
      "z": 2,
      "name": "Rock_Volcanic"
    },
    {
      "x": -23,
      "y": 7,
      "z": 2,
      "name": "Rock_Volcanic"
    },
    {
      "x": -23,
      "y": 8,
      "z": 2,
      "name": "Rock_Volcanic"
    },
    {
      "x": -23,
      "y": 9,
      "z": 2,
      "name": "Rock_Basalt"
    },
    {
      "x": -23,
      "y": 10,
      "z": 2,
      "name": "Rock_Basalt"
    },
    {
      "x": -23,
      "y": 11,
      "z": 2,
      "name": "Rock_Basalt"
    },
    {
      "x": -23,
      "y": 3,
      "z": 3,
      "name": "Rock_Volcanic"
    },
    {
      "x": -23,
      "y": 4,
      "z": 3,
      "name": "Rock_Volcanic"
    },
    {
      "x": -23,
      "y": 5,
      "z": 3,
      "name": "Rock_Volcanic"
    },
    {
      "x": -23,
      "y": 6,
      "z": 3,
      "name": "Rock_Volcanic"
    },
    {
      "x": -23,
      "y": 7,
      "z": 3,
      "name": "Rock_Volcanic"
    },
    {
      "x": -23,
      "y": 8,
      "z": 3,
      "name": "Rock_Volcanic"
    },
    {
      "x": -23,
      "y": 9,
      "z": 3,
      "name": "Rock_Basalt"
    },
    {
      "x": -23,
      "y": 10,
      "z": 3,
      "name": "Rock_Basalt"
    },
    {
      "x": -23,
      "y": 11,
      "z": 3,
      "name": "Rock_Basalt"
    },
    {
      "x": -23,
      "y": -3,
      "z": 4,
      "name": "Rock_Basalt"
    },
    {
      "x": -23,
      "y": 4,
      "z": 4,
      "name": "Rock_Volcanic"
    },
    {
      "x": -23,
      "y": 5,
      "z": 4,
      "name": "Rock_Volcanic"
    },
    {
      "x": -23,
      "y": 6,
      "z": 4,
      "name": "Rock_Volcanic"
    },
    {
      "x": -23,
      "y": 7,
      "z": 4,
      "name": "Rock_Volcanic"
    },
    {
      "x": -23,
      "y": 8,
      "z": 4,
      "name": "Rock_Basalt"
    },
    {
      "x": -23,
      "y": 9,
      "z": 4,
      "name": "Rock_Basalt"
    },
    {
      "x": -23,
      "y": 10,
      "z": 4,
      "name": "Rock_Basalt"
    },
    {
      "x": -23,
      "y": 11,
      "z": 4,
      "name": "Rock_Basalt"
    },
    {
      "x": -23,
      "y": -3,
      "z": 5,
      "name": "Rock_Basalt"
    },
    {
      "x": -23,
      "y": -2,
      "z": 5,
      "name": "Rock_Basalt"
    },
    {
      "x": -23,
      "y": 5,
      "z": 5,
      "name": "Rock_Volcanic"
    },
    {
      "x": -23,
      "y": 6,
      "z": 5,
      "name": "Rock_Volcanic"
    },
    {
      "x": -23,
      "y": 7,
      "z": 5,
      "name": "Rock_Volcanic"
    },
    {
      "x": -23,
      "y": 8,
      "z": 5,
      "name": "Rock_Basalt"
    },
    {
      "x": -23,
      "y": 9,
      "z": 5,
      "name": "Rock_Basalt"
    },
    {
      "x": -23,
      "y": 10,
      "z": 5,
      "name": "Rock_Basalt"
    },
    {
      "x": -23,
      "y": 11,
      "z": 5,
      "name": "Rock_Basalt"
    },
    {
      "x": -23,
      "y": -3,
      "z": 6,
      "name": "Rock_Basalt"
    },
    {
      "x": -23,
      "y": -2,
      "z": 6,
      "name": "Rock_Basalt"
    },
    {
      "x": -23,
      "y": 6,
      "z": 6,
      "name": "Rock_Volcanic"
    },
    {
      "x": -23,
      "y": 7,
      "z": 6,
      "name": "Rock_Volcanic"
    },
    {
      "x": -23,
      "y": 8,
      "z": 6,
      "name": "Rock_Basalt"
    },
    {
      "x": -23,
      "y": 9,
      "z": 6,
      "name": "Rock_Basalt"
    },
    {
      "x": -23,
      "y": 10,
      "z": 6,
      "name": "Rock_Basalt"
    },
    {
      "x": -23,
      "y": -4,
      "z": 7,
      "name": "Rock_Basalt"
    },
    {
      "x": -23,
      "y": -3,
      "z": 7,
      "name": "Rock_Basalt"
    },
    {
      "x": -23,
      "y": -2,
      "z": 7,
      "name": "Rock_Basalt"
    },
    {
      "x": -23,
      "y": -1,
      "z": 7,
      "name": "Rock_Volcanic"
    },
    {
      "x": -23,
      "y": 0,
      "z": 7,
      "name": "Rock_Volcanic"
    },
    {
      "x": -23,
      "y": 7,
      "z": 7,
      "name": "Rock_Basalt"
    },
    {
      "x": -23,
      "y": 8,
      "z": 7,
      "name": "Rock_Basalt"
    },
    {
      "x": -23,
      "y": 9,
      "z": 7,
      "name": "Rock_Basalt"
    },
    {
      "x": -23,
      "y": -3,
      "z": 8,
      "name": "Rock_Basalt"
    },
    {
      "x": -23,
      "y": -2,
      "z": 8,
      "name": "Rock_Basalt"
    },
    {
      "x": -23,
      "y": -1,
      "z": 8,
      "name": "Rock_Basalt"
    },
    {
      "x": -23,
      "y": 0,
      "z": 8,
      "name": "Rock_Volcanic"
    },
    {
      "x": -23,
      "y": 1,
      "z": 8,
      "name": "Rock_Volcanic"
    },
    {
      "x": -23,
      "y": 2,
      "z": 8,
      "name": "Rock_Volcanic"
    },
    {
      "x": -23,
      "y": -3,
      "z": 9,
      "name": "Rock_Basalt"
    },
    {
      "x": -23,
      "y": -2,
      "z": 9,
      "name": "Rock_Basalt"
    },
    {
      "x": -23,
      "y": -1,
      "z": 9,
      "name": "Rock_Basalt"
    },
    {
      "x": -23,
      "y": 0,
      "z": 9,
      "name": "Rock_Volcanic"
    },
    {
      "x": -23,
      "y": 1,
      "z": 9,
      "name": "Rock_Volcanic"
    },
    {
      "x": -23,
      "y": 2,
      "z": 9,
      "name": "Rock_Volcanic"
    },
    {
      "x": -23,
      "y": 3,
      "z": 9,
      "name": "Rock_Volcanic"
    },
    {
      "x": -23,
      "y": -2,
      "z": 10,
      "name": "Rock_Basalt"
    },
    {
      "x": -23,
      "y": -1,
      "z": 10,
      "name": "Rock_Basalt"
    },
    {
      "x": -23,
      "y": 0,
      "z": 10,
      "name": "Rock_Basalt"
    },
    {
      "x": -23,
      "y": 1,
      "z": 10,
      "name": "Rock_Basalt"
    },
    {
      "x": -23,
      "y": 2,
      "z": 10,
      "name": "Rock_Volcanic"
    },
    {
      "x": -23,
      "y": 3,
      "z": 10,
      "name": "Rock_Volcanic"
    },
    {
      "x": -23,
      "y": 4,
      "z": 10,
      "name": "Rock_Volcanic"
    },
    {
      "x": -23,
      "y": -1,
      "z": 11,
      "name": "Rock_Basalt"
    },
    {
      "x": -23,
      "y": 0,
      "z": 11,
      "name": "Rock_Basalt"
    },
    {
      "x": -23,
      "y": 1,
      "z": 11,
      "name": "Rock_Basalt"
    },
    {
      "x": -23,
      "y": 2,
      "z": 11,
      "name": "Rock_Basalt"
    },
    {
      "x": -23,
      "y": 3,
      "z": 11,
      "name": "Rock_Volcanic"
    },
    {
      "x": -23,
      "y": 4,
      "z": 11,
      "name": "Rock_Basalt"
    },
    {
      "x": -23,
      "y": 5,
      "z": 11,
      "name": "Rock_Basalt"
    },
    {
      "x": -23,
      "y": 6,
      "z": 11,
      "name": "Rock_Basalt"
    },
    {
      "x": -23,
      "y": 9,
      "z": 11,
      "name": "Rock_Basalt"
    },
    {
      "x": -23,
      "y": 0,
      "z": 12,
      "name": "Rock_Basalt"
    },
    {
      "x": -23,
      "y": 1,
      "z": 12,
      "name": "Rock_Basalt"
    },
    {
      "x": -23,
      "y": 2,
      "z": 12,
      "name": "Rock_Basalt"
    },
    {
      "x": -23,
      "y": 3,
      "z": 12,
      "name": "Rock_Basalt"
    },
    {
      "x": -23,
      "y": 4,
      "z": 12,
      "name": "Rock_Basalt"
    },
    {
      "x": -23,
      "y": 5,
      "z": 12,
      "name": "Rock_Basalt"
    },
    {
      "x": -23,
      "y": 6,
      "z": 12,
      "name": "Rock_Basalt"
    },
    {
      "x": -23,
      "y": 7,
      "z": 12,
      "name": "Rock_Basalt"
    },
    {
      "x": -23,
      "y": 8,
      "z": 12,
      "name": "Rock_Basalt"
    },
    {
      "x": -23,
      "y": 1,
      "z": 13,
      "name": "Rock_Basalt"
    },
    {
      "x": -23,
      "y": 2,
      "z": 13,
      "name": "Rock_Basalt"
    },
    {
      "x": -23,
      "y": 3,
      "z": 13,
      "name": "Rock_Basalt"
    },
    {
      "x": -23,
      "y": 4,
      "z": 13,
      "name": "Rock_Basalt"
    },
    {
      "x": -23,
      "y": 5,
      "z": 13,
      "name": "Rock_Basalt"
    },
    {
      "x": -23,
      "y": 6,
      "z": 13,
      "name": "Rock_Basalt"
    },
    {
      "x": -23,
      "y": 7,
      "z": 13,
      "name": "Rock_Basalt"
    },
    {
      "x": -23,
      "y": 3,
      "z": 14,
      "name": "Rock_Basalt"
    },
    {
      "x": -23,
      "y": 4,
      "z": 14,
      "name": "Rock_Basalt"
    },
    {
      "x": -23,
      "y": 5,
      "z": 14,
      "name": "Rock_Basalt"
    },
    {
      "x": -22,
      "y": 2,
      "z": -8,
      "name": "Rock_Basalt"
    },
    {
      "x": -22,
      "y": 3,
      "z": -8,
      "name": "Rock_Basalt"
    },
    {
      "x": -22,
      "y": 1,
      "z": -7,
      "name": "Rock_Basalt"
    },
    {
      "x": -22,
      "y": 2,
      "z": -7,
      "name": "Rock_Basalt"
    },
    {
      "x": -22,
      "y": 3,
      "z": -7,
      "name": "Rock_Basalt"
    },
    {
      "x": -22,
      "y": 4,
      "z": -7,
      "name": "Rock_Basalt"
    },
    {
      "x": -22,
      "y": 5,
      "z": -7,
      "name": "Rock_Basalt"
    },
    {
      "x": -22,
      "y": 6,
      "z": -7,
      "name": "Rock_Basalt"
    },
    {
      "x": -22,
      "y": 0,
      "z": -6,
      "name": "Rock_Basalt"
    },
    {
      "x": -22,
      "y": 1,
      "z": -6,
      "name": "Rock_Basalt"
    },
    {
      "x": -22,
      "y": 2,
      "z": -6,
      "name": "Rock_Basalt"
    },
    {
      "x": -22,
      "y": 3,
      "z": -6,
      "name": "Rock_Basalt"
    },
    {
      "x": -22,
      "y": 4,
      "z": -6,
      "name": "Rock_Basalt"
    },
    {
      "x": -22,
      "y": 5,
      "z": -6,
      "name": "Rock_Basalt"
    },
    {
      "x": -22,
      "y": 6,
      "z": -6,
      "name": "Rock_Basalt"
    },
    {
      "x": -22,
      "y": 7,
      "z": -6,
      "name": "Rock_Basalt"
    },
    {
      "x": -22,
      "y": 8,
      "z": -6,
      "name": "Rock_Basalt"
    },
    {
      "x": -22,
      "y": -1,
      "z": -5,
      "name": "Rock_Basalt"
    },
    {
      "x": -22,
      "y": 0,
      "z": -5,
      "name": "Rock_Basalt"
    },
    {
      "x": -22,
      "y": 1,
      "z": -5,
      "name": "Rock_Basalt"
    },
    {
      "x": -22,
      "y": 2,
      "z": -5,
      "name": "Rock_Volcanic"
    },
    {
      "x": -22,
      "y": 3,
      "z": -5,
      "name": "Rock_Basalt"
    },
    {
      "x": -22,
      "y": 4,
      "z": -5,
      "name": "Rock_Basalt"
    },
    {
      "x": -22,
      "y": 5,
      "z": -5,
      "name": "Rock_Basalt"
    },
    {
      "x": -22,
      "y": 6,
      "z": -5,
      "name": "Rock_Basalt"
    },
    {
      "x": -22,
      "y": 7,
      "z": -5,
      "name": "Rock_Basalt"
    },
    {
      "x": -22,
      "y": 8,
      "z": -5,
      "name": "Rock_Basalt"
    },
    {
      "x": -22,
      "y": 9,
      "z": -5,
      "name": "Rock_Basalt"
    },
    {
      "x": -22,
      "y": -2,
      "z": -4,
      "name": "Rock_Basalt"
    },
    {
      "x": -22,
      "y": -1,
      "z": -4,
      "name": "Rock_Basalt"
    },
    {
      "x": -22,
      "y": 0,
      "z": -4,
      "name": "Rock_Volcanic"
    },
    {
      "x": -22,
      "y": 1,
      "z": -4,
      "name": "Rock_Volcanic"
    },
    {
      "x": -22,
      "y": 2,
      "z": -4,
      "name": "Rock_Volcanic"
    },
    {
      "x": -22,
      "y": 3,
      "z": -4,
      "name": "Rock_Volcanic"
    },
    {
      "x": -22,
      "y": 4,
      "z": -4,
      "name": "Rock_Volcanic"
    },
    {
      "x": -22,
      "y": 5,
      "z": -4,
      "name": "Rock_Volcanic"
    },
    {
      "x": -22,
      "y": 6,
      "z": -4,
      "name": "Rock_Basalt"
    },
    {
      "x": -22,
      "y": 7,
      "z": -4,
      "name": "Rock_Basalt"
    },
    {
      "x": -22,
      "y": 8,
      "z": -4,
      "name": "Rock_Basalt"
    },
    {
      "x": -22,
      "y": 9,
      "z": -4,
      "name": "Rock_Basalt"
    },
    {
      "x": -22,
      "y": 10,
      "z": -4,
      "name": "Rock_Basalt"
    },
    {
      "x": -22,
      "y": -2,
      "z": -3,
      "name": "Rock_Basalt"
    },
    {
      "x": -22,
      "y": -1,
      "z": -3,
      "name": "Rock_Basalt"
    },
    {
      "x": -22,
      "y": 0,
      "z": -3,
      "name": "Rock_Volcanic"
    },
    {
      "x": -22,
      "y": 1,
      "z": -3,
      "name": "Rock_Volcanic"
    },
    {
      "x": -22,
      "y": 2,
      "z": -3,
      "name": "Rock_Volcanic"
    },
    {
      "x": -22,
      "y": 3,
      "z": -3,
      "name": "Rock_Volcanic"
    },
    {
      "x": -22,
      "y": 4,
      "z": -3,
      "name": "Rock_Volcanic"
    },
    {
      "x": -22,
      "y": 5,
      "z": -3,
      "name": "Rock_Volcanic"
    },
    {
      "x": -22,
      "y": 6,
      "z": -3,
      "name": "Rock_Volcanic"
    },
    {
      "x": -22,
      "y": 7,
      "z": -3,
      "name": "Rock_Basalt"
    },
    {
      "x": -22,
      "y": 8,
      "z": -3,
      "name": "Rock_Basalt"
    },
    {
      "x": -22,
      "y": 9,
      "z": -3,
      "name": "Rock_Basalt"
    },
    {
      "x": -22,
      "y": 10,
      "z": -3,
      "name": "Rock_Basalt"
    },
    {
      "x": -22,
      "y": -2,
      "z": -2,
      "name": "Rock_Basalt"
    },
    {
      "x": -22,
      "y": -1,
      "z": -2,
      "name": "Rock_Volcanic"
    },
    {
      "x": -22,
      "y": 0,
      "z": -2,
      "name": "Rock_Volcanic"
    },
    {
      "x": -22,
      "y": 1,
      "z": -2,
      "name": "Rock_Volcanic"
    },
    {
      "x": -22,
      "y": 2,
      "z": -2,
      "name": "Rock_Volcanic"
    },
    {
      "x": -22,
      "y": 3,
      "z": -2,
      "name": "Rock_Volcanic"
    },
    {
      "x": -22,
      "y": 4,
      "z": -2,
      "name": "Rock_Volcanic"
    },
    {
      "x": -22,
      "y": 5,
      "z": -2,
      "name": "Rock_Volcanic"
    },
    {
      "x": -22,
      "y": 6,
      "z": -2,
      "name": "Rock_Volcanic"
    },
    {
      "x": -22,
      "y": 7,
      "z": -2,
      "name": "Rock_Volcanic"
    },
    {
      "x": -22,
      "y": 8,
      "z": -2,
      "name": "Rock_Basalt"
    },
    {
      "x": -22,
      "y": 9,
      "z": -2,
      "name": "Rock_Basalt"
    },
    {
      "x": -22,
      "y": 10,
      "z": -2,
      "name": "Rock_Basalt"
    },
    {
      "x": -22,
      "y": 11,
      "z": -2,
      "name": "Rock_Basalt"
    },
    {
      "x": -22,
      "y": -2,
      "z": -1,
      "name": "Rock_Basalt"
    },
    {
      "x": -22,
      "y": -1,
      "z": -1,
      "name": "Rock_Volcanic"
    },
    {
      "x": -22,
      "y": 0,
      "z": -1,
      "name": "Rock_Volcanic"
    },
    {
      "x": -22,
      "y": 1,
      "z": -1,
      "name": "Rock_Volcanic"
    },
    {
      "x": -22,
      "y": 2,
      "z": -1,
      "name": "Rock_Volcanic"
    },
    {
      "x": -22,
      "y": 3,
      "z": -1,
      "name": "Rock_Volcanic"
    },
    {
      "x": -22,
      "y": 4,
      "z": -1,
      "name": "Rock_Volcanic"
    },
    {
      "x": -22,
      "y": 5,
      "z": -1,
      "name": "Rock_Volcanic"
    },
    {
      "x": -22,
      "y": 6,
      "z": -1,
      "name": "Rock_Volcanic"
    },
    {
      "x": -22,
      "y": 7,
      "z": -1,
      "name": "Rock_Volcanic"
    },
    {
      "x": -22,
      "y": 8,
      "z": -1,
      "name": "Rock_Volcanic"
    },
    {
      "x": -22,
      "y": 9,
      "z": -1,
      "name": "Rock_Basalt"
    },
    {
      "x": -22,
      "y": 10,
      "z": -1,
      "name": "Rock_Basalt"
    },
    {
      "x": -22,
      "y": 11,
      "z": -1,
      "name": "Rock_Basalt"
    },
    {
      "x": -22,
      "y": 0,
      "z": 0,
      "name": "Rock_Volcanic"
    },
    {
      "x": -22,
      "y": 1,
      "z": 0,
      "name": "Rock_Volcanic"
    },
    {
      "x": -22,
      "y": 2,
      "z": 0,
      "name": "Rock_Volcanic"
    },
    {
      "x": -22,
      "y": 3,
      "z": 0,
      "name": "Rock_Volcanic"
    },
    {
      "x": -22,
      "y": 4,
      "z": 0,
      "name": "Rock_Volcanic"
    },
    {
      "x": -22,
      "y": 5,
      "z": 0,
      "name": "Rock_Volcanic"
    },
    {
      "x": -22,
      "y": 6,
      "z": 0,
      "name": "Rock_Volcanic"
    },
    {
      "x": -22,
      "y": 7,
      "z": 0,
      "name": "Rock_Volcanic"
    },
    {
      "x": -22,
      "y": 8,
      "z": 0,
      "name": "Rock_Volcanic"
    },
    {
      "x": -22,
      "y": 9,
      "z": 0,
      "name": "Rock_Volcanic"
    },
    {
      "x": -22,
      "y": 10,
      "z": 0,
      "name": "Rock_Basalt"
    },
    {
      "x": -22,
      "y": 11,
      "z": 0,
      "name": "Rock_Basalt"
    },
    {
      "x": -22,
      "y": 12,
      "z": 0,
      "name": "Rock_Basalt"
    },
    {
      "x": -22,
      "y": 4,
      "z": 1,
      "name": "Rock_Volcanic"
    },
    {
      "x": -22,
      "y": 5,
      "z": 1,
      "name": "Rock_Volcanic"
    },
    {
      "x": -22,
      "y": 6,
      "z": 1,
      "name": "Rock_Volcanic"
    },
    {
      "x": -22,
      "y": 7,
      "z": 1,
      "name": "Rock_Volcanic"
    },
    {
      "x": -22,
      "y": 8,
      "z": 1,
      "name": "Rock_Volcanic"
    },
    {
      "x": -22,
      "y": 9,
      "z": 1,
      "name": "Rock_Volcanic"
    },
    {
      "x": -22,
      "y": 10,
      "z": 1,
      "name": "Rock_Basalt"
    },
    {
      "x": -22,
      "y": 11,
      "z": 1,
      "name": "Rock_Basalt"
    },
    {
      "x": -22,
      "y": 12,
      "z": 1,
      "name": "Rock_Basalt"
    },
    {
      "x": -22,
      "y": 5,
      "z": 2,
      "name": "Rock_Volcanic"
    },
    {
      "x": -22,
      "y": 6,
      "z": 2,
      "name": "Rock_Volcanic"
    },
    {
      "x": -22,
      "y": 7,
      "z": 2,
      "name": "Rock_Volcanic"
    },
    {
      "x": -22,
      "y": 8,
      "z": 2,
      "name": "Rock_Volcanic"
    },
    {
      "x": -22,
      "y": 9,
      "z": 2,
      "name": "Rock_Volcanic"
    },
    {
      "x": -22,
      "y": 10,
      "z": 2,
      "name": "Rock_Volcanic"
    },
    {
      "x": -22,
      "y": 11,
      "z": 2,
      "name": "Rock_Basalt"
    },
    {
      "x": -22,
      "y": 12,
      "z": 2,
      "name": "Rock_Basalt"
    },
    {
      "x": -22,
      "y": 5,
      "z": 3,
      "name": "Rock_Volcanic"
    },
    {
      "x": -22,
      "y": 6,
      "z": 3,
      "name": "Rock_Volcanic"
    },
    {
      "x": -22,
      "y": 7,
      "z": 3,
      "name": "Rock_Volcanic"
    },
    {
      "x": -22,
      "y": 8,
      "z": 3,
      "name": "Rock_Volcanic"
    },
    {
      "x": -22,
      "y": 9,
      "z": 3,
      "name": "Rock_Volcanic"
    },
    {
      "x": -22,
      "y": 10,
      "z": 3,
      "name": "Rock_Volcanic"
    },
    {
      "x": -22,
      "y": 11,
      "z": 3,
      "name": "Rock_Basalt"
    },
    {
      "x": -22,
      "y": 12,
      "z": 3,
      "name": "Rock_Basalt"
    },
    {
      "x": -22,
      "y": 6,
      "z": 4,
      "name": "Rock_Volcanic"
    },
    {
      "x": -22,
      "y": 7,
      "z": 4,
      "name": "Rock_Volcanic"
    },
    {
      "x": -22,
      "y": 8,
      "z": 4,
      "name": "Rock_Volcanic"
    },
    {
      "x": -22,
      "y": 9,
      "z": 4,
      "name": "Rock_Volcanic"
    },
    {
      "x": -22,
      "y": 10,
      "z": 4,
      "name": "Rock_Basalt"
    },
    {
      "x": -22,
      "y": 11,
      "z": 4,
      "name": "Rock_Basalt"
    },
    {
      "x": -22,
      "y": 12,
      "z": 4,
      "name": "Rock_Basalt"
    },
    {
      "x": -22,
      "y": 6,
      "z": 5,
      "name": "Rock_Volcanic"
    },
    {
      "x": -22,
      "y": 7,
      "z": 5,
      "name": "Rock_Volcanic"
    },
    {
      "x": -22,
      "y": 8,
      "z": 5,
      "name": "Rock_Volcanic"
    },
    {
      "x": -22,
      "y": 9,
      "z": 5,
      "name": "Rock_Volcanic"
    },
    {
      "x": -22,
      "y": 10,
      "z": 5,
      "name": "Rock_Basalt"
    },
    {
      "x": -22,
      "y": 11,
      "z": 5,
      "name": "Rock_Basalt"
    },
    {
      "x": -22,
      "y": 12,
      "z": 5,
      "name": "Rock_Basalt"
    },
    {
      "x": -22,
      "y": 6,
      "z": 6,
      "name": "Rock_Volcanic"
    },
    {
      "x": -22,
      "y": 7,
      "z": 6,
      "name": "Rock_Volcanic"
    },
    {
      "x": -22,
      "y": 8,
      "z": 6,
      "name": "Rock_Volcanic"
    },
    {
      "x": -22,
      "y": 9,
      "z": 6,
      "name": "Rock_Basalt"
    },
    {
      "x": -22,
      "y": 10,
      "z": 6,
      "name": "Rock_Basalt"
    },
    {
      "x": -22,
      "y": 11,
      "z": 6,
      "name": "Rock_Basalt"
    },
    {
      "x": -22,
      "y": -4,
      "z": 7,
      "name": "Rock_Basalt"
    },
    {
      "x": -22,
      "y": -3,
      "z": 7,
      "name": "Rock_Basalt"
    },
    {
      "x": -22,
      "y": -2,
      "z": 7,
      "name": "Rock_Volcanic"
    },
    {
      "x": -22,
      "y": -1,
      "z": 7,
      "name": "Rock_Volcanic"
    },
    {
      "x": -22,
      "y": 0,
      "z": 7,
      "name": "Rock_Volcanic"
    },
    {
      "x": -22,
      "y": 9,
      "z": 7,
      "name": "Rock_Basalt"
    },
    {
      "x": -22,
      "y": 10,
      "z": 7,
      "name": "Rock_Basalt"
    },
    {
      "x": -22,
      "y": 11,
      "z": 7,
      "name": "Rock_Basalt"
    },
    {
      "x": -22,
      "y": -4,
      "z": 8,
      "name": "Rock_Basalt"
    },
    {
      "x": -22,
      "y": -3,
      "z": 8,
      "name": "Rock_Basalt"
    },
    {
      "x": -22,
      "y": -2,
      "z": 8,
      "name": "Rock_Volcanic"
    },
    {
      "x": -22,
      "y": -1,
      "z": 8,
      "name": "Rock_Volcanic"
    },
    {
      "x": -22,
      "y": 0,
      "z": 8,
      "name": "Rock_Volcanic"
    },
    {
      "x": -22,
      "y": 1,
      "z": 8,
      "name": "Rock_Volcanic"
    },
    {
      "x": -22,
      "y": -4,
      "z": 9,
      "name": "Rock_Basalt"
    },
    {
      "x": -22,
      "y": -3,
      "z": 9,
      "name": "Rock_Basalt"
    },
    {
      "x": -22,
      "y": -2,
      "z": 9,
      "name": "Rock_Basalt"
    },
    {
      "x": -22,
      "y": -1,
      "z": 9,
      "name": "Rock_Volcanic"
    },
    {
      "x": -22,
      "y": 0,
      "z": 9,
      "name": "Rock_Volcanic"
    },
    {
      "x": -22,
      "y": 1,
      "z": 9,
      "name": "Rock_Volcanic"
    },
    {
      "x": -22,
      "y": 2,
      "z": 9,
      "name": "Rock_Volcanic"
    },
    {
      "x": -22,
      "y": 3,
      "z": 9,
      "name": "Rock_Volcanic"
    },
    {
      "x": -22,
      "y": -3,
      "z": 10,
      "name": "Rock_Basalt"
    },
    {
      "x": -22,
      "y": -2,
      "z": 10,
      "name": "Rock_Basalt"
    },
    {
      "x": -22,
      "y": -1,
      "z": 10,
      "name": "Rock_Basalt"
    },
    {
      "x": -22,
      "y": 0,
      "z": 10,
      "name": "Rock_Volcanic"
    },
    {
      "x": -22,
      "y": 1,
      "z": 10,
      "name": "Rock_Volcanic"
    },
    {
      "x": -22,
      "y": 2,
      "z": 10,
      "name": "Rock_Volcanic"
    },
    {
      "x": -22,
      "y": 3,
      "z": 10,
      "name": "Rock_Volcanic"
    },
    {
      "x": -22,
      "y": 4,
      "z": 10,
      "name": "Rock_Volcanic"
    },
    {
      "x": -22,
      "y": -2,
      "z": 11,
      "name": "Rock_Basalt"
    },
    {
      "x": -22,
      "y": -1,
      "z": 11,
      "name": "Rock_Basalt"
    },
    {
      "x": -22,
      "y": 0,
      "z": 11,
      "name": "Rock_Basalt"
    },
    {
      "x": -22,
      "y": 1,
      "z": 11,
      "name": "Rock_Volcanic"
    },
    {
      "x": -22,
      "y": 2,
      "z": 11,
      "name": "Rock_Volcanic"
    },
    {
      "x": -22,
      "y": 3,
      "z": 11,
      "name": "Rock_Volcanic"
    },
    {
      "x": -22,
      "y": 4,
      "z": 11,
      "name": "Rock_Volcanic"
    },
    {
      "x": -22,
      "y": 5,
      "z": 11,
      "name": "Rock_Volcanic"
    },
    {
      "x": -22,
      "y": 6,
      "z": 11,
      "name": "Rock_Volcanic"
    },
    {
      "x": -22,
      "y": -1,
      "z": 12,
      "name": "Rock_Basalt"
    },
    {
      "x": -22,
      "y": 0,
      "z": 12,
      "name": "Rock_Basalt"
    },
    {
      "x": -22,
      "y": 1,
      "z": 12,
      "name": "Rock_Basalt"
    },
    {
      "x": -22,
      "y": 2,
      "z": 12,
      "name": "Rock_Volcanic"
    },
    {
      "x": -22,
      "y": 3,
      "z": 12,
      "name": "Rock_Volcanic"
    },
    {
      "x": -22,
      "y": 4,
      "z": 12,
      "name": "Rock_Volcanic"
    },
    {
      "x": -22,
      "y": 5,
      "z": 12,
      "name": "Rock_Volcanic"
    },
    {
      "x": -22,
      "y": 6,
      "z": 12,
      "name": "Rock_Volcanic"
    },
    {
      "x": -22,
      "y": 7,
      "z": 12,
      "name": "Rock_Basalt"
    },
    {
      "x": -22,
      "y": 8,
      "z": 12,
      "name": "Rock_Basalt"
    },
    {
      "x": -22,
      "y": 9,
      "z": 12,
      "name": "Rock_Basalt"
    },
    {
      "x": -22,
      "y": 0,
      "z": 13,
      "name": "Rock_Basalt"
    },
    {
      "x": -22,
      "y": 1,
      "z": 13,
      "name": "Rock_Basalt"
    },
    {
      "x": -22,
      "y": 2,
      "z": 13,
      "name": "Rock_Basalt"
    },
    {
      "x": -22,
      "y": 3,
      "z": 13,
      "name": "Rock_Basalt"
    },
    {
      "x": -22,
      "y": 4,
      "z": 13,
      "name": "Rock_Basalt"
    },
    {
      "x": -22,
      "y": 5,
      "z": 13,
      "name": "Rock_Basalt"
    },
    {
      "x": -22,
      "y": 6,
      "z": 13,
      "name": "Rock_Basalt"
    },
    {
      "x": -22,
      "y": 7,
      "z": 13,
      "name": "Rock_Basalt"
    },
    {
      "x": -22,
      "y": 8,
      "z": 13,
      "name": "Rock_Basalt"
    },
    {
      "x": -22,
      "y": 9,
      "z": 13,
      "name": "Rock_Basalt"
    },
    {
      "x": -22,
      "y": 1,
      "z": 14,
      "name": "Rock_Basalt"
    },
    {
      "x": -22,
      "y": 2,
      "z": 14,
      "name": "Rock_Basalt"
    },
    {
      "x": -22,
      "y": 3,
      "z": 14,
      "name": "Rock_Basalt"
    },
    {
      "x": -22,
      "y": 4,
      "z": 14,
      "name": "Rock_Basalt"
    },
    {
      "x": -22,
      "y": 5,
      "z": 14,
      "name": "Rock_Basalt"
    },
    {
      "x": -22,
      "y": 6,
      "z": 14,
      "name": "Rock_Basalt"
    },
    {
      "x": -22,
      "y": 7,
      "z": 14,
      "name": "Rock_Basalt"
    },
    {
      "x": -22,
      "y": 3,
      "z": 15,
      "name": "Rock_Basalt"
    },
    {
      "x": -22,
      "y": 4,
      "z": 15,
      "name": "Rock_Basalt"
    },
    {
      "x": -21,
      "y": 4,
      "z": -9,
      "name": "Rock_Basalt"
    },
    {
      "x": -21,
      "y": 2,
      "z": -8,
      "name": "Rock_Basalt"
    },
    {
      "x": -21,
      "y": 3,
      "z": -8,
      "name": "Rock_Basalt"
    },
    {
      "x": -21,
      "y": 4,
      "z": -8,
      "name": "Rock_Basalt"
    },
    {
      "x": -21,
      "y": 5,
      "z": -8,
      "name": "Rock_Basalt"
    },
    {
      "x": -21,
      "y": 6,
      "z": -8,
      "name": "Rock_Basalt"
    },
    {
      "x": -21,
      "y": 7,
      "z": -8,
      "name": "Rock_Basalt"
    },
    {
      "x": -21,
      "y": 1,
      "z": -7,
      "name": "Rock_Basalt"
    },
    {
      "x": -21,
      "y": 2,
      "z": -7,
      "name": "Rock_Basalt"
    },
    {
      "x": -21,
      "y": 3,
      "z": -7,
      "name": "Rock_Basalt"
    },
    {
      "x": -21,
      "y": 4,
      "z": -7,
      "name": "Rock_Basalt"
    },
    {
      "x": -21,
      "y": 5,
      "z": -7,
      "name": "Rock_Basalt"
    },
    {
      "x": -21,
      "y": 6,
      "z": -7,
      "name": "Rock_Basalt"
    },
    {
      "x": -21,
      "y": 7,
      "z": -7,
      "name": "Rock_Basalt"
    },
    {
      "x": -21,
      "y": 8,
      "z": -7,
      "name": "Rock_Basalt"
    },
    {
      "x": -21,
      "y": 1,
      "z": -6,
      "name": "Rock_Volcanic"
    },
    {
      "x": -21,
      "y": 2,
      "z": -6,
      "name": "Rock_Volcanic"
    },
    {
      "x": -21,
      "y": 3,
      "z": -6,
      "name": "Rock_Volcanic"
    },
    {
      "x": -21,
      "y": 4,
      "z": -6,
      "name": "Rock_Volcanic"
    },
    {
      "x": -21,
      "y": 5,
      "z": -6,
      "name": "Rock_Basalt"
    },
    {
      "x": -21,
      "y": 6,
      "z": -6,
      "name": "Rock_Basalt"
    },
    {
      "x": -21,
      "y": 7,
      "z": -6,
      "name": "Rock_Basalt"
    },
    {
      "x": -21,
      "y": 8,
      "z": -6,
      "name": "Rock_Basalt"
    },
    {
      "x": -21,
      "y": 9,
      "z": -6,
      "name": "Rock_Basalt"
    },
    {
      "x": -21,
      "y": 10,
      "z": -6,
      "name": "Rock_Basalt"
    },
    {
      "x": -21,
      "y": 0,
      "z": -5,
      "name": "Rock_Volcanic"
    },
    {
      "x": -21,
      "y": 1,
      "z": -5,
      "name": "Rock_Volcanic"
    },
    {
      "x": -21,
      "y": 2,
      "z": -5,
      "name": "Rock_Volcanic"
    },
    {
      "x": -21,
      "y": 3,
      "z": -5,
      "name": "Rock_Volcanic"
    },
    {
      "x": -21,
      "y": 4,
      "z": -5,
      "name": "Rock_Volcanic"
    },
    {
      "x": -21,
      "y": 5,
      "z": -5,
      "name": "Rock_Volcanic"
    },
    {
      "x": -21,
      "y": 6,
      "z": -5,
      "name": "Rock_Volcanic"
    },
    {
      "x": -21,
      "y": 7,
      "z": -5,
      "name": "Rock_Volcanic"
    },
    {
      "x": -21,
      "y": 8,
      "z": -5,
      "name": "Rock_Basalt"
    },
    {
      "x": -21,
      "y": 9,
      "z": -5,
      "name": "Rock_Basalt"
    },
    {
      "x": -21,
      "y": 10,
      "z": -5,
      "name": "Rock_Basalt"
    },
    {
      "x": -21,
      "y": 11,
      "z": -5,
      "name": "Rock_Basalt"
    },
    {
      "x": -21,
      "y": -1,
      "z": -4,
      "name": "Rock_Volcanic"
    },
    {
      "x": -21,
      "y": 0,
      "z": -4,
      "name": "Rock_Volcanic"
    },
    {
      "x": -21,
      "y": 1,
      "z": -4,
      "name": "Rock_Volcanic"
    },
    {
      "x": -21,
      "y": 2,
      "z": -4,
      "name": "Rock_Volcanic"
    },
    {
      "x": -21,
      "y": 3,
      "z": -4,
      "name": "Rock_Volcanic"
    },
    {
      "x": -21,
      "y": 4,
      "z": -4,
      "name": "Rock_Volcanic"
    },
    {
      "x": -21,
      "y": 5,
      "z": -4,
      "name": "Rock_Volcanic"
    },
    {
      "x": -21,
      "y": 6,
      "z": -4,
      "name": "Rock_Volcanic"
    },
    {
      "x": -21,
      "y": 7,
      "z": -4,
      "name": "Rock_Volcanic"
    },
    {
      "x": -21,
      "y": 8,
      "z": -4,
      "name": "Rock_Volcanic"
    },
    {
      "x": -21,
      "y": 9,
      "z": -4,
      "name": "Rock_Basalt"
    },
    {
      "x": -21,
      "y": 10,
      "z": -4,
      "name": "Rock_Basalt"
    },
    {
      "x": -21,
      "y": 11,
      "z": -4,
      "name": "Rock_Basalt"
    },
    {
      "x": -21,
      "y": -1,
      "z": -3,
      "name": "Rock_Volcanic"
    },
    {
      "x": -21,
      "y": 0,
      "z": -3,
      "name": "Rock_Volcanic"
    },
    {
      "x": -21,
      "y": 1,
      "z": -3,
      "name": "Rock_Volcanic"
    },
    {
      "x": -21,
      "y": 2,
      "z": -3,
      "name": "Rock_Volcanic"
    },
    {
      "x": -21,
      "y": 3,
      "z": -3,
      "name": "Rock_Volcanic"
    },
    {
      "x": -21,
      "y": 4,
      "z": -3,
      "name": "Rock_Volcanic"
    },
    {
      "x": -21,
      "y": 5,
      "z": -3,
      "name": "Rock_Volcanic"
    },
    {
      "x": -21,
      "y": 6,
      "z": -3,
      "name": "Rock_Volcanic"
    },
    {
      "x": -21,
      "y": 7,
      "z": -3,
      "name": "Rock_Volcanic"
    },
    {
      "x": -21,
      "y": 8,
      "z": -3,
      "name": "Rock_Volcanic"
    },
    {
      "x": -21,
      "y": 9,
      "z": -3,
      "name": "Rock_Volcanic"
    },
    {
      "x": -21,
      "y": 10,
      "z": -3,
      "name": "Rock_Basalt"
    },
    {
      "x": -21,
      "y": 11,
      "z": -3,
      "name": "Rock_Basalt"
    },
    {
      "x": -21,
      "y": 12,
      "z": -3,
      "name": "Rock_Basalt"
    },
    {
      "x": -21,
      "y": -1,
      "z": -2,
      "name": "Rock_Volcanic"
    },
    {
      "x": -21,
      "y": 0,
      "z": -2,
      "name": "Rock_Volcanic"
    },
    {
      "x": -21,
      "y": 5,
      "z": -2,
      "name": "Rock_Volcanic"
    },
    {
      "x": -21,
      "y": 6,
      "z": -2,
      "name": "Rock_Volcanic"
    },
    {
      "x": -21,
      "y": 7,
      "z": -2,
      "name": "Rock_Volcanic"
    },
    {
      "x": -21,
      "y": 8,
      "z": -2,
      "name": "Rock_Volcanic"
    },
    {
      "x": -21,
      "y": 9,
      "z": -2,
      "name": "Rock_Volcanic"
    },
    {
      "x": -21,
      "y": 10,
      "z": -2,
      "name": "Rock_Basalt"
    },
    {
      "x": -21,
      "y": 11,
      "z": -2,
      "name": "Rock_Basalt"
    },
    {
      "x": -21,
      "y": 12,
      "z": -2,
      "name": "Rock_Basalt"
    },
    {
      "x": -21,
      "y": -1,
      "z": -1,
      "name": "Rock_Volcanic"
    },
    {
      "x": -21,
      "y": 6,
      "z": -1,
      "name": "Rock_Volcanic"
    },
    {
      "x": -21,
      "y": 7,
      "z": -1,
      "name": "Rock_Volcanic"
    },
    {
      "x": -21,
      "y": 8,
      "z": -1,
      "name": "Rock_Volcanic"
    },
    {
      "x": -21,
      "y": 9,
      "z": -1,
      "name": "Rock_Volcanic"
    },
    {
      "x": -21,
      "y": 10,
      "z": -1,
      "name": "Rock_Volcanic"
    },
    {
      "x": -21,
      "y": 11,
      "z": -1,
      "name": "Rock_Basalt"
    },
    {
      "x": -21,
      "y": 12,
      "z": -1,
      "name": "Rock_Basalt"
    },
    {
      "x": -21,
      "y": 13,
      "z": -1,
      "name": "Rock_Basalt"
    },
    {
      "x": -21,
      "y": 7,
      "z": 0,
      "name": "Rock_Volcanic"
    },
    {
      "x": -21,
      "y": 8,
      "z": 0,
      "name": "Rock_Volcanic"
    },
    {
      "x": -21,
      "y": 9,
      "z": 0,
      "name": "Rock_Volcanic"
    },
    {
      "x": -21,
      "y": 10,
      "z": 0,
      "name": "Rock_Volcanic"
    },
    {
      "x": -21,
      "y": 11,
      "z": 0,
      "name": "Rock_Basalt"
    },
    {
      "x": -21,
      "y": 12,
      "z": 0,
      "name": "Rock_Basalt"
    },
    {
      "x": -21,
      "y": 13,
      "z": 0,
      "name": "Rock_Basalt"
    },
    {
      "x": -21,
      "y": 8,
      "z": 1,
      "name": "Rock_Volcanic"
    },
    {
      "x": -21,
      "y": 9,
      "z": 1,
      "name": "Rock_Volcanic"
    },
    {
      "x": -21,
      "y": 10,
      "z": 1,
      "name": "Rock_Volcanic"
    },
    {
      "x": -21,
      "y": 11,
      "z": 1,
      "name": "Rock_Volcanic"
    },
    {
      "x": -21,
      "y": 12,
      "z": 1,
      "name": "Rock_Basalt"
    },
    {
      "x": -21,
      "y": 13,
      "z": 1,
      "name": "Rock_Basalt"
    },
    {
      "x": -21,
      "y": 9,
      "z": 2,
      "name": "Rock_Volcanic"
    },
    {
      "x": -21,
      "y": 10,
      "z": 2,
      "name": "Rock_Volcanic"
    },
    {
      "x": -21,
      "y": 11,
      "z": 2,
      "name": "Rock_Volcanic"
    },
    {
      "x": -21,
      "y": 12,
      "z": 2,
      "name": "Rock_Basalt"
    },
    {
      "x": -21,
      "y": 13,
      "z": 2,
      "name": "Rock_Basalt"
    },
    {
      "x": -21,
      "y": 14,
      "z": 2,
      "name": "Rock_Basalt"
    },
    {
      "x": -21,
      "y": 9,
      "z": 3,
      "name": "Rock_Volcanic"
    },
    {
      "x": -21,
      "y": 10,
      "z": 3,
      "name": "Rock_Volcanic"
    },
    {
      "x": -21,
      "y": 11,
      "z": 3,
      "name": "Rock_Volcanic"
    },
    {
      "x": -21,
      "y": 12,
      "z": 3,
      "name": "Rock_Basalt"
    },
    {
      "x": -21,
      "y": 13,
      "z": 3,
      "name": "Rock_Basalt"
    },
    {
      "x": -21,
      "y": 14,
      "z": 3,
      "name": "Rock_Basalt"
    },
    {
      "x": -21,
      "y": 8,
      "z": 4,
      "name": "Rock_Volcanic"
    },
    {
      "x": -21,
      "y": 9,
      "z": 4,
      "name": "Rock_Volcanic"
    },
    {
      "x": -21,
      "y": 10,
      "z": 4,
      "name": "Rock_Volcanic"
    },
    {
      "x": -21,
      "y": 11,
      "z": 4,
      "name": "Rock_Volcanic"
    },
    {
      "x": -21,
      "y": 12,
      "z": 4,
      "name": "Rock_Basalt"
    },
    {
      "x": -21,
      "y": 13,
      "z": 4,
      "name": "Rock_Basalt"
    },
    {
      "x": -21,
      "y": 8,
      "z": 5,
      "name": "Rock_Volcanic"
    },
    {
      "x": -21,
      "y": 9,
      "z": 5,
      "name": "Rock_Volcanic"
    },
    {
      "x": -21,
      "y": 10,
      "z": 5,
      "name": "Rock_Volcanic"
    },
    {
      "x": -21,
      "y": 11,
      "z": 5,
      "name": "Rock_Basalt"
    },
    {
      "x": -21,
      "y": 12,
      "z": 5,
      "name": "Rock_Basalt"
    },
    {
      "x": -21,
      "y": 13,
      "z": 5,
      "name": "Rock_Basalt"
    },
    {
      "x": -21,
      "y": 8,
      "z": 6,
      "name": "Rock_Volcanic"
    },
    {
      "x": -21,
      "y": 9,
      "z": 6,
      "name": "Rock_Volcanic"
    },
    {
      "x": -21,
      "y": 10,
      "z": 6,
      "name": "Rock_Volcanic"
    },
    {
      "x": -21,
      "y": 11,
      "z": 6,
      "name": "Rock_Basalt"
    },
    {
      "x": -21,
      "y": 12,
      "z": 6,
      "name": "Rock_Basalt"
    },
    {
      "x": -21,
      "y": -4,
      "z": 7,
      "name": "Rock_Basalt"
    },
    {
      "x": -21,
      "y": -3,
      "z": 7,
      "name": "Rock_Volcanic"
    },
    {
      "x": -21,
      "y": -2,
      "z": 7,
      "name": "Rock_Volcanic"
    },
    {
      "x": -21,
      "y": 10,
      "z": 7,
      "name": "Rock_Basalt"
    },
    {
      "x": -21,
      "y": 11,
      "z": 7,
      "name": "Rock_Basalt"
    },
    {
      "x": -21,
      "y": 12,
      "z": 7,
      "name": "Rock_Basalt"
    },
    {
      "x": -21,
      "y": -4,
      "z": 8,
      "name": "Rock_Basalt"
    },
    {
      "x": -21,
      "y": -3,
      "z": 8,
      "name": "Rock_Volcanic"
    },
    {
      "x": -21,
      "y": -2,
      "z": 8,
      "name": "Rock_Volcanic"
    },
    {
      "x": -21,
      "y": -1,
      "z": 8,
      "name": "Rock_Volcanic"
    },
    {
      "x": -21,
      "y": -4,
      "z": 9,
      "name": "Rock_Basalt"
    },
    {
      "x": -21,
      "y": -3,
      "z": 9,
      "name": "Rock_Volcanic"
    },
    {
      "x": -21,
      "y": -2,
      "z": 9,
      "name": "Rock_Volcanic"
    },
    {
      "x": -21,
      "y": -1,
      "z": 9,
      "name": "Rock_Volcanic"
    },
    {
      "x": -21,
      "y": -4,
      "z": 10,
      "name": "Rock_Basalt"
    },
    {
      "x": -21,
      "y": -3,
      "z": 10,
      "name": "Rock_Basalt"
    },
    {
      "x": -21,
      "y": -2,
      "z": 10,
      "name": "Rock_Volcanic"
    },
    {
      "x": -21,
      "y": -1,
      "z": 10,
      "name": "Rock_Volcanic"
    },
    {
      "x": -21,
      "y": 0,
      "z": 10,
      "name": "Rock_Volcanic"
    },
    {
      "x": -21,
      "y": 1,
      "z": 10,
      "name": "Rock_Volcanic"
    },
    {
      "x": -21,
      "y": -3,
      "z": 11,
      "name": "Rock_Basalt"
    },
    {
      "x": -21,
      "y": -2,
      "z": 11,
      "name": "Rock_Basalt"
    },
    {
      "x": -21,
      "y": -1,
      "z": 11,
      "name": "Rock_Volcanic"
    },
    {
      "x": -21,
      "y": 0,
      "z": 11,
      "name": "Rock_Volcanic"
    },
    {
      "x": -21,
      "y": 1,
      "z": 11,
      "name": "Rock_Volcanic"
    },
    {
      "x": -21,
      "y": 2,
      "z": 11,
      "name": "Rock_Volcanic"
    },
    {
      "x": -21,
      "y": 4,
      "z": 11,
      "name": "Rock_Volcanic"
    },
    {
      "x": -21,
      "y": 5,
      "z": 11,
      "name": "Rock_Volcanic"
    },
    {
      "x": -21,
      "y": 6,
      "z": 11,
      "name": "Rock_Volcanic"
    },
    {
      "x": -21,
      "y": -2,
      "z": 12,
      "name": "Rock_Basalt"
    },
    {
      "x": -21,
      "y": -1,
      "z": 12,
      "name": "Rock_Basalt"
    },
    {
      "x": -21,
      "y": 0,
      "z": 12,
      "name": "Rock_Volcanic"
    },
    {
      "x": -21,
      "y": 1,
      "z": 12,
      "name": "Rock_Volcanic"
    },
    {
      "x": -21,
      "y": 2,
      "z": 12,
      "name": "Rock_Volcanic"
    },
    {
      "x": -21,
      "y": 3,
      "z": 12,
      "name": "Rock_Volcanic"
    },
    {
      "x": -21,
      "y": 4,
      "z": 12,
      "name": "Rock_Volcanic"
    },
    {
      "x": -21,
      "y": 5,
      "z": 12,
      "name": "Rock_Volcanic"
    },
    {
      "x": -21,
      "y": 6,
      "z": 12,
      "name": "Rock_Volcanic"
    },
    {
      "x": -21,
      "y": 7,
      "z": 12,
      "name": "Rock_Volcanic"
    },
    {
      "x": -21,
      "y": 9,
      "z": 12,
      "name": "Rock_Basalt"
    },
    {
      "x": -21,
      "y": 11,
      "z": 12,
      "name": "Rock_Basalt"
    },
    {
      "x": -21,
      "y": -1,
      "z": 13,
      "name": "Rock_Basalt"
    },
    {
      "x": -21,
      "y": 0,
      "z": 13,
      "name": "Rock_Basalt"
    },
    {
      "x": -21,
      "y": 1,
      "z": 13,
      "name": "Rock_Volcanic"
    },
    {
      "x": -21,
      "y": 2,
      "z": 13,
      "name": "Rock_Volcanic"
    },
    {
      "x": -21,
      "y": 3,
      "z": 13,
      "name": "Rock_Volcanic"
    },
    {
      "x": -21,
      "y": 4,
      "z": 13,
      "name": "Rock_Volcanic"
    },
    {
      "x": -21,
      "y": 5,
      "z": 13,
      "name": "Rock_Volcanic"
    },
    {
      "x": -21,
      "y": 6,
      "z": 13,
      "name": "Rock_Volcanic"
    },
    {
      "x": -21,
      "y": 7,
      "z": 13,
      "name": "Rock_Volcanic"
    },
    {
      "x": -21,
      "y": 8,
      "z": 13,
      "name": "Rock_Basalt"
    },
    {
      "x": -21,
      "y": 9,
      "z": 13,
      "name": "Rock_Basalt"
    },
    {
      "x": -21,
      "y": 10,
      "z": 13,
      "name": "Rock_Basalt"
    },
    {
      "x": -21,
      "y": 0,
      "z": 14,
      "name": "Rock_Basalt"
    },
    {
      "x": -21,
      "y": 1,
      "z": 14,
      "name": "Rock_Basalt"
    },
    {
      "x": -21,
      "y": 2,
      "z": 14,
      "name": "Rock_Basalt"
    },
    {
      "x": -21,
      "y": 3,
      "z": 14,
      "name": "Rock_Basalt"
    },
    {
      "x": -21,
      "y": 4,
      "z": 14,
      "name": "Rock_Volcanic"
    },
    {
      "x": -21,
      "y": 5,
      "z": 14,
      "name": "Rock_Basalt"
    },
    {
      "x": -21,
      "y": 6,
      "z": 14,
      "name": "Rock_Basalt"
    },
    {
      "x": -21,
      "y": 7,
      "z": 14,
      "name": "Rock_Basalt"
    },
    {
      "x": -21,
      "y": 8,
      "z": 14,
      "name": "Rock_Basalt"
    },
    {
      "x": -21,
      "y": 9,
      "z": 14,
      "name": "Rock_Basalt"
    },
    {
      "x": -21,
      "y": 1,
      "z": 15,
      "name": "Rock_Basalt"
    },
    {
      "x": -21,
      "y": 2,
      "z": 15,
      "name": "Rock_Basalt"
    },
    {
      "x": -21,
      "y": 3,
      "z": 15,
      "name": "Rock_Basalt"
    },
    {
      "x": -21,
      "y": 4,
      "z": 15,
      "name": "Rock_Basalt"
    },
    {
      "x": -21,
      "y": 5,
      "z": 15,
      "name": "Rock_Basalt"
    },
    {
      "x": -21,
      "y": 6,
      "z": 15,
      "name": "Rock_Basalt"
    },
    {
      "x": -21,
      "y": 3,
      "z": 16,
      "name": "Rock_Basalt"
    },
    {
      "x": -20,
      "y": -1,
      "z": -13,
      "name": "Rock_Basalt"
    },
    {
      "x": -20,
      "y": 0,
      "z": -13,
      "name": "Rock_Basalt"
    },
    {
      "x": -20,
      "y": -2,
      "z": -12,
      "name": "Rock_Basalt"
    },
    {
      "x": -20,
      "y": -1,
      "z": -12,
      "name": "Rock_Basalt"
    },
    {
      "x": -20,
      "y": 0,
      "z": -12,
      "name": "Rock_Basalt"
    },
    {
      "x": -20,
      "y": 1,
      "z": -12,
      "name": "Rock_Basalt"
    },
    {
      "x": -20,
      "y": -3,
      "z": -11,
      "name": "Rock_Basalt"
    },
    {
      "x": -20,
      "y": -2,
      "z": -11,
      "name": "Rock_Basalt"
    },
    {
      "x": -20,
      "y": -1,
      "z": -11,
      "name": "Rock_Basalt"
    },
    {
      "x": -20,
      "y": 0,
      "z": -11,
      "name": "Rock_Basalt"
    },
    {
      "x": -20,
      "y": -3,
      "z": -10,
      "name": "Rock_Basalt"
    },
    {
      "x": -20,
      "y": -2,
      "z": -10,
      "name": "Rock_Basalt"
    },
    {
      "x": -20,
      "y": 5,
      "z": -10,
      "name": "Rock_Basalt"
    },
    {
      "x": -20,
      "y": -4,
      "z": -9,
      "name": "Rock_Basalt"
    },
    {
      "x": -20,
      "y": -3,
      "z": -9,
      "name": "Rock_Basalt"
    },
    {
      "x": -20,
      "y": 4,
      "z": -9,
      "name": "Rock_Basalt"
    },
    {
      "x": -20,
      "y": 5,
      "z": -9,
      "name": "Rock_Basalt"
    },
    {
      "x": -20,
      "y": 6,
      "z": -9,
      "name": "Rock_Basalt"
    },
    {
      "x": -20,
      "y": 7,
      "z": -9,
      "name": "Rock_Basalt"
    },
    {
      "x": -20,
      "y": 3,
      "z": -8,
      "name": "Rock_Basalt"
    },
    {
      "x": -20,
      "y": 4,
      "z": -8,
      "name": "Rock_Basalt"
    },
    {
      "x": -20,
      "y": 5,
      "z": -8,
      "name": "Rock_Basalt"
    },
    {
      "x": -20,
      "y": 6,
      "z": -8,
      "name": "Rock_Basalt"
    },
    {
      "x": -20,
      "y": 7,
      "z": -8,
      "name": "Rock_Basalt"
    },
    {
      "x": -20,
      "y": 8,
      "z": -8,
      "name": "Rock_Basalt"
    },
    {
      "x": -20,
      "y": 9,
      "z": -8,
      "name": "Rock_Basalt"
    },
    {
      "x": -20,
      "y": 2,
      "z": -7,
      "name": "Rock_Volcanic"
    },
    {
      "x": -20,
      "y": 3,
      "z": -7,
      "name": "Rock_Volcanic"
    },
    {
      "x": -20,
      "y": 4,
      "z": -7,
      "name": "Rock_Volcanic"
    },
    {
      "x": -20,
      "y": 5,
      "z": -7,
      "name": "Rock_Volcanic"
    },
    {
      "x": -20,
      "y": 6,
      "z": -7,
      "name": "Rock_Basalt"
    },
    {
      "x": -20,
      "y": 7,
      "z": -7,
      "name": "Rock_Basalt"
    },
    {
      "x": -20,
      "y": 8,
      "z": -7,
      "name": "Rock_Basalt"
    },
    {
      "x": -20,
      "y": 9,
      "z": -7,
      "name": "Rock_Basalt"
    },
    {
      "x": -20,
      "y": 10,
      "z": -7,
      "name": "Rock_Basalt"
    },
    {
      "x": -20,
      "y": 1,
      "z": -6,
      "name": "Rock_Volcanic"
    },
    {
      "x": -20,
      "y": 2,
      "z": -6,
      "name": "Rock_Volcanic"
    },
    {
      "x": -20,
      "y": 3,
      "z": -6,
      "name": "Rock_Volcanic"
    },
    {
      "x": -20,
      "y": 4,
      "z": -6,
      "name": "Rock_Volcanic"
    },
    {
      "x": -20,
      "y": 5,
      "z": -6,
      "name": "Rock_Volcanic"
    },
    {
      "x": -20,
      "y": 6,
      "z": -6,
      "name": "Rock_Volcanic"
    },
    {
      "x": -20,
      "y": 7,
      "z": -6,
      "name": "Rock_Volcanic"
    },
    {
      "x": -20,
      "y": 8,
      "z": -6,
      "name": "Rock_Volcanic"
    },
    {
      "x": -20,
      "y": 9,
      "z": -6,
      "name": "Rock_Basalt"
    },
    {
      "x": -20,
      "y": 10,
      "z": -6,
      "name": "Rock_Basalt"
    },
    {
      "x": -20,
      "y": 11,
      "z": -6,
      "name": "Rock_Basalt"
    },
    {
      "x": -20,
      "y": 0,
      "z": -5,
      "name": "Rock_Volcanic"
    },
    {
      "x": -20,
      "y": 1,
      "z": -5,
      "name": "Rock_Volcanic"
    },
    {
      "x": -20,
      "y": 3,
      "z": -5,
      "name": "Rock_Volcanic"
    },
    {
      "x": -20,
      "y": 4,
      "z": -5,
      "name": "Rock_Volcanic"
    },
    {
      "x": -20,
      "y": 5,
      "z": -5,
      "name": "Rock_Volcanic"
    },
    {
      "x": -20,
      "y": 6,
      "z": -5,
      "name": "Rock_Volcanic"
    },
    {
      "x": -20,
      "y": 7,
      "z": -5,
      "name": "Rock_Volcanic"
    },
    {
      "x": -20,
      "y": 8,
      "z": -5,
      "name": "Rock_Volcanic"
    },
    {
      "x": -20,
      "y": 9,
      "z": -5,
      "name": "Rock_Volcanic"
    },
    {
      "x": -20,
      "y": 10,
      "z": -5,
      "name": "Rock_Basalt"
    },
    {
      "x": -20,
      "y": 11,
      "z": -5,
      "name": "Rock_Basalt"
    },
    {
      "x": -20,
      "y": 12,
      "z": -5,
      "name": "Rock_Basalt"
    },
    {
      "x": -20,
      "y": -1,
      "z": -4,
      "name": "Rock_Volcanic"
    },
    {
      "x": -20,
      "y": 6,
      "z": -4,
      "name": "Rock_Volcanic"
    },
    {
      "x": -20,
      "y": 7,
      "z": -4,
      "name": "Rock_Volcanic"
    },
    {
      "x": -20,
      "y": 8,
      "z": -4,
      "name": "Rock_Volcanic"
    },
    {
      "x": -20,
      "y": 9,
      "z": -4,
      "name": "Rock_Volcanic"
    },
    {
      "x": -20,
      "y": 10,
      "z": -4,
      "name": "Rock_Volcanic"
    },
    {
      "x": -20,
      "y": 11,
      "z": -4,
      "name": "Rock_Basalt"
    },
    {
      "x": -20,
      "y": 12,
      "z": -4,
      "name": "Rock_Basalt"
    },
    {
      "x": -20,
      "y": 13,
      "z": -4,
      "name": "Rock_Basalt"
    },
    {
      "x": -20,
      "y": -1,
      "z": -3,
      "name": "Rock_Volcanic"
    },
    {
      "x": -20,
      "y": 7,
      "z": -3,
      "name": "Rock_Volcanic"
    },
    {
      "x": -20,
      "y": 8,
      "z": -3,
      "name": "Rock_Volcanic"
    },
    {
      "x": -20,
      "y": 9,
      "z": -3,
      "name": "Rock_Volcanic"
    },
    {
      "x": -20,
      "y": 10,
      "z": -3,
      "name": "Rock_Volcanic"
    },
    {
      "x": -20,
      "y": 11,
      "z": -3,
      "name": "Rock_Basalt"
    },
    {
      "x": -20,
      "y": 12,
      "z": -3,
      "name": "Rock_Basalt"
    },
    {
      "x": -20,
      "y": 13,
      "z": -3,
      "name": "Rock_Basalt"
    },
    {
      "x": -20,
      "y": 14,
      "z": -3,
      "name": "Rock_Basalt"
    },
    {
      "x": -20,
      "y": 8,
      "z": -2,
      "name": "Rock_Volcanic"
    },
    {
      "x": -20,
      "y": 9,
      "z": -2,
      "name": "Rock_Volcanic"
    },
    {
      "x": -20,
      "y": 10,
      "z": -2,
      "name": "Rock_Volcanic"
    },
    {
      "x": -20,
      "y": 11,
      "z": -2,
      "name": "Rock_Volcanic"
    },
    {
      "x": -20,
      "y": 12,
      "z": -2,
      "name": "Rock_Basalt"
    },
    {
      "x": -20,
      "y": 13,
      "z": -2,
      "name": "Rock_Basalt"
    },
    {
      "x": -20,
      "y": 14,
      "z": -2,
      "name": "Rock_Basalt"
    },
    {
      "x": -20,
      "y": 9,
      "z": -1,
      "name": "Rock_Volcanic"
    },
    {
      "x": -20,
      "y": 10,
      "z": -1,
      "name": "Rock_Volcanic"
    },
    {
      "x": -20,
      "y": 11,
      "z": -1,
      "name": "Rock_Volcanic"
    },
    {
      "x": -20,
      "y": 12,
      "z": -1,
      "name": "Rock_Basalt"
    },
    {
      "x": -20,
      "y": 13,
      "z": -1,
      "name": "Rock_Basalt"
    },
    {
      "x": -20,
      "y": 14,
      "z": -1,
      "name": "Rock_Basalt"
    },
    {
      "x": -20,
      "y": 10,
      "z": 0,
      "name": "Rock_Volcanic"
    },
    {
      "x": -20,
      "y": 11,
      "z": 0,
      "name": "Rock_Volcanic"
    },
    {
      "x": -20,
      "y": 12,
      "z": 0,
      "name": "Rock_Volcanic"
    },
    {
      "x": -20,
      "y": 13,
      "z": 0,
      "name": "Rock_Basalt"
    },
    {
      "x": -20,
      "y": 14,
      "z": 0,
      "name": "Rock_Basalt"
    },
    {
      "x": -20,
      "y": 15,
      "z": 0,
      "name": "Rock_Basalt"
    },
    {
      "x": -20,
      "y": 10,
      "z": 1,
      "name": "Rock_Volcanic"
    },
    {
      "x": -20,
      "y": 11,
      "z": 1,
      "name": "Rock_Volcanic"
    },
    {
      "x": -20,
      "y": 12,
      "z": 1,
      "name": "Rock_Volcanic"
    },
    {
      "x": -20,
      "y": 13,
      "z": 1,
      "name": "Rock_Basalt"
    },
    {
      "x": -20,
      "y": 14,
      "z": 1,
      "name": "Rock_Basalt"
    },
    {
      "x": -20,
      "y": 15,
      "z": 1,
      "name": "Rock_Basalt"
    },
    {
      "x": -20,
      "y": 11,
      "z": 2,
      "name": "Rock_Volcanic"
    },
    {
      "x": -20,
      "y": 12,
      "z": 2,
      "name": "Rock_Volcanic"
    },
    {
      "x": -20,
      "y": 13,
      "z": 2,
      "name": "Rock_Basalt"
    },
    {
      "x": -20,
      "y": 14,
      "z": 2,
      "name": "Rock_Basalt"
    },
    {
      "x": -20,
      "y": 15,
      "z": 2,
      "name": "Rock_Basalt"
    },
    {
      "x": -20,
      "y": 11,
      "z": 3,
      "name": "Rock_Volcanic"
    },
    {
      "x": -20,
      "y": 12,
      "z": 3,
      "name": "Rock_Volcanic"
    },
    {
      "x": -20,
      "y": 13,
      "z": 3,
      "name": "Rock_Basalt"
    },
    {
      "x": -20,
      "y": 14,
      "z": 3,
      "name": "Rock_Basalt"
    },
    {
      "x": -20,
      "y": 15,
      "z": 3,
      "name": "Rock_Basalt"
    },
    {
      "x": -20,
      "y": 10,
      "z": 4,
      "name": "Rock_Volcanic"
    },
    {
      "x": -20,
      "y": 11,
      "z": 4,
      "name": "Rock_Volcanic"
    },
    {
      "x": -20,
      "y": 12,
      "z": 4,
      "name": "Rock_Volcanic"
    },
    {
      "x": -20,
      "y": 13,
      "z": 4,
      "name": "Rock_Basalt"
    },
    {
      "x": -20,
      "y": 14,
      "z": 4,
      "name": "Rock_Basalt"
    },
    {
      "x": -20,
      "y": 10,
      "z": 5,
      "name": "Rock_Volcanic"
    },
    {
      "x": -20,
      "y": 11,
      "z": 5,
      "name": "Rock_Volcanic"
    },
    {
      "x": -20,
      "y": 12,
      "z": 5,
      "name": "Rock_Volcanic"
    },
    {
      "x": -20,
      "y": 13,
      "z": 5,
      "name": "Rock_Basalt"
    },
    {
      "x": -20,
      "y": 14,
      "z": 5,
      "name": "Rock_Basalt"
    },
    {
      "x": -20,
      "y": 9,
      "z": 6,
      "name": "Rock_Volcanic"
    },
    {
      "x": -20,
      "y": 10,
      "z": 6,
      "name": "Rock_Volcanic"
    },
    {
      "x": -20,
      "y": 11,
      "z": 6,
      "name": "Rock_Volcanic"
    },
    {
      "x": -20,
      "y": 12,
      "z": 6,
      "name": "Rock_Basalt"
    },
    {
      "x": -20,
      "y": 13,
      "z": 6,
      "name": "Rock_Basalt"
    },
    {
      "x": -20,
      "y": -3,
      "z": 7,
      "name": "Rock_Volcanic"
    },
    {
      "x": -20,
      "y": 11,
      "z": 7,
      "name": "Rock_Basalt"
    },
    {
      "x": -20,
      "y": 12,
      "z": 7,
      "name": "Rock_Basalt"
    },
    {
      "x": -20,
      "y": 13,
      "z": 7,
      "name": "Rock_Basalt"
    },
    {
      "x": -20,
      "y": -3,
      "z": 8,
      "name": "Rock_Volcanic"
    },
    {
      "x": -20,
      "y": -4,
      "z": 9,
      "name": "Rock_Basalt"
    },
    {
      "x": -20,
      "y": -3,
      "z": 9,
      "name": "Rock_Volcanic"
    },
    {
      "x": -20,
      "y": -2,
      "z": 9,
      "name": "Rock_Volcanic"
    },
    {
      "x": -20,
      "y": -4,
      "z": 10,
      "name": "Rock_Basalt"
    },
    {
      "x": -20,
      "y": -3,
      "z": 10,
      "name": "Rock_Volcanic"
    },
    {
      "x": -20,
      "y": -2,
      "z": 10,
      "name": "Rock_Volcanic"
    },
    {
      "x": -20,
      "y": -1,
      "z": 10,
      "name": "Rock_Volcanic"
    },
    {
      "x": -20,
      "y": -4,
      "z": 11,
      "name": "Rock_Basalt"
    },
    {
      "x": -20,
      "y": -3,
      "z": 11,
      "name": "Rock_Basalt"
    },
    {
      "x": -20,
      "y": -2,
      "z": 11,
      "name": "Rock_Volcanic"
    },
    {
      "x": -20,
      "y": -1,
      "z": 11,
      "name": "Rock_Volcanic"
    },
    {
      "x": -20,
      "y": 0,
      "z": 11,
      "name": "Rock_Volcanic"
    },
    {
      "x": -20,
      "y": -3,
      "z": 12,
      "name": "Rock_Basalt"
    },
    {
      "x": -20,
      "y": -2,
      "z": 12,
      "name": "Rock_Basalt"
    },
    {
      "x": -20,
      "y": -1,
      "z": 12,
      "name": "Rock_Volcanic"
    },
    {
      "x": -20,
      "y": 0,
      "z": 12,
      "name": "Rock_Volcanic"
    },
    {
      "x": -20,
      "y": 1,
      "z": 12,
      "name": "Rock_Volcanic"
    },
    {
      "x": -20,
      "y": 7,
      "z": 12,
      "name": "Rock_Volcanic"
    },
    {
      "x": -20,
      "y": 12,
      "z": 12,
      "name": "Rock_Basalt"
    },
    {
      "x": -20,
      "y": -2,
      "z": 13,
      "name": "Rock_Basalt"
    },
    {
      "x": -20,
      "y": -1,
      "z": 13,
      "name": "Rock_Basalt"
    },
    {
      "x": -20,
      "y": 0,
      "z": 13,
      "name": "Rock_Volcanic"
    },
    {
      "x": -20,
      "y": 1,
      "z": 13,
      "name": "Rock_Volcanic"
    },
    {
      "x": -20,
      "y": 2,
      "z": 13,
      "name": "Rock_Volcanic"
    },
    {
      "x": -20,
      "y": 3,
      "z": 13,
      "name": "Rock_Volcanic"
    },
    {
      "x": -20,
      "y": 4,
      "z": 13,
      "name": "Rock_Volcanic"
    },
    {
      "x": -20,
      "y": 5,
      "z": 13,
      "name": "Rock_Volcanic"
    },
    {
      "x": -20,
      "y": 6,
      "z": 13,
      "name": "Rock_Volcanic"
    },
    {
      "x": -20,
      "y": 7,
      "z": 13,
      "name": "Rock_Volcanic"
    },
    {
      "x": -20,
      "y": 8,
      "z": 13,
      "name": "Rock_Volcanic"
    },
    {
      "x": -20,
      "y": 9,
      "z": 13,
      "name": "Rock_Basalt"
    },
    {
      "x": -20,
      "y": 10,
      "z": 13,
      "name": "Rock_Basalt"
    },
    {
      "x": -20,
      "y": 11,
      "z": 13,
      "name": "Rock_Basalt"
    },
    {
      "x": -20,
      "y": -1,
      "z": 14,
      "name": "Rock_Basalt"
    },
    {
      "x": -20,
      "y": 0,
      "z": 14,
      "name": "Rock_Basalt"
    },
    {
      "x": -20,
      "y": 1,
      "z": 14,
      "name": "Rock_Volcanic"
    },
    {
      "x": -20,
      "y": 2,
      "z": 14,
      "name": "Rock_Volcanic"
    },
    {
      "x": -20,
      "y": 3,
      "z": 14,
      "name": "Rock_Volcanic"
    },
    {
      "x": -20,
      "y": 4,
      "z": 14,
      "name": "Rock_Volcanic"
    },
    {
      "x": -20,
      "y": 5,
      "z": 14,
      "name": "Rock_Volcanic"
    },
    {
      "x": -20,
      "y": 6,
      "z": 14,
      "name": "Rock_Volcanic"
    },
    {
      "x": -20,
      "y": 7,
      "z": 14,
      "name": "Rock_Volcanic"
    },
    {
      "x": -20,
      "y": 8,
      "z": 14,
      "name": "Rock_Basalt"
    },
    {
      "x": -20,
      "y": 9,
      "z": 14,
      "name": "Rock_Basalt"
    },
    {
      "x": -20,
      "y": 10,
      "z": 14,
      "name": "Rock_Basalt"
    },
    {
      "x": -20,
      "y": 0,
      "z": 15,
      "name": "Rock_Basalt"
    },
    {
      "x": -20,
      "y": 1,
      "z": 15,
      "name": "Rock_Basalt"
    },
    {
      "x": -20,
      "y": 2,
      "z": 15,
      "name": "Rock_Basalt"
    },
    {
      "x": -20,
      "y": 3,
      "z": 15,
      "name": "Rock_Volcanic"
    },
    {
      "x": -20,
      "y": 4,
      "z": 15,
      "name": "Rock_Volcanic"
    },
    {
      "x": -20,
      "y": 5,
      "z": 15,
      "name": "Rock_Basalt"
    },
    {
      "x": -20,
      "y": 6,
      "z": 15,
      "name": "Rock_Basalt"
    },
    {
      "x": -20,
      "y": 7,
      "z": 15,
      "name": "Rock_Basalt"
    },
    {
      "x": -20,
      "y": 8,
      "z": 15,
      "name": "Rock_Basalt"
    },
    {
      "x": -20,
      "y": 1,
      "z": 16,
      "name": "Rock_Basalt"
    },
    {
      "x": -20,
      "y": 2,
      "z": 16,
      "name": "Rock_Basalt"
    },
    {
      "x": -20,
      "y": 3,
      "z": 16,
      "name": "Rock_Basalt"
    },
    {
      "x": -20,
      "y": 4,
      "z": 16,
      "name": "Rock_Basalt"
    },
    {
      "x": -20,
      "y": 5,
      "z": 16,
      "name": "Rock_Basalt"
    },
    {
      "x": -20,
      "y": 6,
      "z": 16,
      "name": "Rock_Basalt"
    },
    {
      "x": -19,
      "y": -2,
      "z": -14,
      "name": "Rock_Basalt"
    },
    {
      "x": -19,
      "y": -1,
      "z": -14,
      "name": "Rock_Basalt"
    },
    {
      "x": -19,
      "y": 0,
      "z": -14,
      "name": "Rock_Basalt"
    },
    {
      "x": -19,
      "y": 1,
      "z": -14,
      "name": "Rock_Basalt"
    },
    {
      "x": -19,
      "y": -3,
      "z": -13,
      "name": "Rock_Basalt"
    },
    {
      "x": -19,
      "y": -2,
      "z": -13,
      "name": "Rock_Basalt"
    },
    {
      "x": -19,
      "y": -1,
      "z": -13,
      "name": "Rock_Basalt"
    },
    {
      "x": -19,
      "y": 0,
      "z": -13,
      "name": "Rock_Basalt"
    },
    {
      "x": -19,
      "y": 1,
      "z": -13,
      "name": "Rock_Basalt"
    },
    {
      "x": -19,
      "y": 2,
      "z": -13,
      "name": "Rock_Basalt"
    },
    {
      "x": -19,
      "y": 3,
      "z": -13,
      "name": "Rock_Basalt"
    },
    {
      "x": -19,
      "y": -4,
      "z": -12,
      "name": "Rock_Basalt"
    },
    {
      "x": -19,
      "y": -3,
      "z": -12,
      "name": "Rock_Basalt"
    },
    {
      "x": -19,
      "y": -2,
      "z": -12,
      "name": "Rock_Basalt"
    },
    {
      "x": -19,
      "y": -1,
      "z": -12,
      "name": "Rock_Basalt"
    },
    {
      "x": -19,
      "y": 0,
      "z": -12,
      "name": "Rock_Basalt"
    },
    {
      "x": -19,
      "y": 1,
      "z": -12,
      "name": "Rock_Basalt"
    },
    {
      "x": -19,
      "y": -5,
      "z": -11,
      "name": "Rock_Basalt"
    },
    {
      "x": -19,
      "y": -4,
      "z": -11,
      "name": "Rock_Basalt"
    },
    {
      "x": -19,
      "y": -3,
      "z": -11,
      "name": "Rock_Basalt"
    },
    {
      "x": -19,
      "y": -2,
      "z": -11,
      "name": "Rock_Basalt"
    },
    {
      "x": -19,
      "y": -1,
      "z": -11,
      "name": "Rock_Basalt"
    },
    {
      "x": -19,
      "y": 0,
      "z": -11,
      "name": "Rock_Basalt"
    },
    {
      "x": -19,
      "y": -5,
      "z": -10,
      "name": "Rock_Basalt"
    },
    {
      "x": -19,
      "y": -4,
      "z": -10,
      "name": "Rock_Basalt"
    },
    {
      "x": -19,
      "y": -3,
      "z": -10,
      "name": "Rock_Basalt"
    },
    {
      "x": -19,
      "y": -2,
      "z": -10,
      "name": "Rock_Basalt"
    },
    {
      "x": -19,
      "y": 5,
      "z": -10,
      "name": "Rock_Basalt"
    },
    {
      "x": -19,
      "y": 6,
      "z": -10,
      "name": "Rock_Basalt"
    },
    {
      "x": -19,
      "y": 7,
      "z": -10,
      "name": "Rock_Basalt"
    },
    {
      "x": -19,
      "y": -5,
      "z": -9,
      "name": "Rock_Basalt"
    },
    {
      "x": -19,
      "y": -4,
      "z": -9,
      "name": "Rock_Basalt"
    },
    {
      "x": -19,
      "y": -3,
      "z": -9,
      "name": "Rock_Basalt"
    },
    {
      "x": -19,
      "y": 5,
      "z": -9,
      "name": "Rock_Basalt"
    },
    {
      "x": -19,
      "y": 6,
      "z": -9,
      "name": "Rock_Basalt"
    },
    {
      "x": -19,
      "y": 7,
      "z": -9,
      "name": "Rock_Basalt"
    },
    {
      "x": -19,
      "y": 8,
      "z": -9,
      "name": "Rock_Basalt"
    },
    {
      "x": -19,
      "y": 9,
      "z": -9,
      "name": "Rock_Basalt"
    },
    {
      "x": -19,
      "y": 3,
      "z": -8,
      "name": "Rock_Volcanic"
    },
    {
      "x": -19,
      "y": 4,
      "z": -8,
      "name": "Rock_Volcanic"
    },
    {
      "x": -19,
      "y": 5,
      "z": -8,
      "name": "Rock_Volcanic"
    },
    {
      "x": -19,
      "y": 6,
      "z": -8,
      "name": "Rock_Volcanic"
    },
    {
      "x": -19,
      "y": 7,
      "z": -8,
      "name": "Rock_Basalt"
    },
    {
      "x": -19,
      "y": 8,
      "z": -8,
      "name": "Rock_Basalt"
    },
    {
      "x": -19,
      "y": 9,
      "z": -8,
      "name": "Rock_Basalt"
    },
    {
      "x": -19,
      "y": 10,
      "z": -8,
      "name": "Rock_Basalt"
    },
    {
      "x": -19,
      "y": 2,
      "z": -7,
      "name": "Rock_Volcanic"
    },
    {
      "x": -19,
      "y": 3,
      "z": -7,
      "name": "Rock_Volcanic"
    },
    {
      "x": -19,
      "y": 4,
      "z": -7,
      "name": "Rock_Volcanic"
    },
    {
      "x": -19,
      "y": 5,
      "z": -7,
      "name": "Rock_Volcanic"
    },
    {
      "x": -19,
      "y": 6,
      "z": -7,
      "name": "Rock_Volcanic"
    },
    {
      "x": -19,
      "y": 7,
      "z": -7,
      "name": "Rock_Volcanic"
    },
    {
      "x": -19,
      "y": 8,
      "z": -7,
      "name": "Rock_Volcanic"
    },
    {
      "x": -19,
      "y": 9,
      "z": -7,
      "name": "Rock_Basalt"
    },
    {
      "x": -19,
      "y": 10,
      "z": -7,
      "name": "Rock_Basalt"
    },
    {
      "x": -19,
      "y": 11,
      "z": -7,
      "name": "Rock_Basalt"
    },
    {
      "x": -19,
      "y": 5,
      "z": -6,
      "name": "Rock_Volcanic"
    },
    {
      "x": -19,
      "y": 6,
      "z": -6,
      "name": "Rock_Volcanic"
    },
    {
      "x": -19,
      "y": 7,
      "z": -6,
      "name": "Rock_Volcanic"
    },
    {
      "x": -19,
      "y": 8,
      "z": -6,
      "name": "Rock_Volcanic"
    },
    {
      "x": -19,
      "y": 9,
      "z": -6,
      "name": "Rock_Volcanic"
    },
    {
      "x": -19,
      "y": 10,
      "z": -6,
      "name": "Rock_Basalt"
    },
    {
      "x": -19,
      "y": 11,
      "z": -6,
      "name": "Rock_Basalt"
    },
    {
      "x": -19,
      "y": 12,
      "z": -6,
      "name": "Rock_Basalt"
    },
    {
      "x": -19,
      "y": 13,
      "z": -6,
      "name": "Rock_Basalt"
    },
    {
      "x": -19,
      "y": 8,
      "z": -5,
      "name": "Rock_Volcanic"
    },
    {
      "x": -19,
      "y": 9,
      "z": -5,
      "name": "Rock_Volcanic"
    },
    {
      "x": -19,
      "y": 10,
      "z": -5,
      "name": "Rock_Volcanic"
    },
    {
      "x": -19,
      "y": 11,
      "z": -5,
      "name": "Rock_Basalt"
    },
    {
      "x": -19,
      "y": 12,
      "z": -5,
      "name": "Rock_Basalt"
    },
    {
      "x": -19,
      "y": 13,
      "z": -5,
      "name": "Rock_Basalt"
    },
    {
      "x": -19,
      "y": 14,
      "z": -5,
      "name": "Rock_Basalt"
    },
    {
      "x": -19,
      "y": 9,
      "z": -4,
      "name": "Rock_Volcanic"
    },
    {
      "x": -19,
      "y": 10,
      "z": -4,
      "name": "Rock_Volcanic"
    },
    {
      "x": -19,
      "y": 11,
      "z": -4,
      "name": "Rock_Volcanic"
    },
    {
      "x": -19,
      "y": 12,
      "z": -4,
      "name": "Rock_Basalt"
    },
    {
      "x": -19,
      "y": 13,
      "z": -4,
      "name": "Rock_Basalt"
    },
    {
      "x": -19,
      "y": 14,
      "z": -4,
      "name": "Rock_Basalt"
    },
    {
      "x": -19,
      "y": 15,
      "z": -4,
      "name": "Rock_Basalt"
    },
    {
      "x": -19,
      "y": 10,
      "z": -3,
      "name": "Rock_Volcanic"
    },
    {
      "x": -19,
      "y": 11,
      "z": -3,
      "name": "Rock_Volcanic"
    },
    {
      "x": -19,
      "y": 12,
      "z": -3,
      "name": "Rock_Volcanic"
    },
    {
      "x": -19,
      "y": 13,
      "z": -3,
      "name": "Rock_Basalt"
    },
    {
      "x": -19,
      "y": 14,
      "z": -3,
      "name": "Rock_Basalt"
    },
    {
      "x": -19,
      "y": 15,
      "z": -3,
      "name": "Rock_Basalt"
    },
    {
      "x": -19,
      "y": 10,
      "z": -2,
      "name": "Rock_Volcanic"
    },
    {
      "x": -19,
      "y": 11,
      "z": -2,
      "name": "Rock_Volcanic"
    },
    {
      "x": -19,
      "y": 12,
      "z": -2,
      "name": "Rock_Volcanic"
    },
    {
      "x": -19,
      "y": 13,
      "z": -2,
      "name": "Rock_Basalt"
    },
    {
      "x": -19,
      "y": 14,
      "z": -2,
      "name": "Rock_Basalt"
    },
    {
      "x": -19,
      "y": 15,
      "z": -2,
      "name": "Rock_Basalt"
    },
    {
      "x": -19,
      "y": 16,
      "z": -2,
      "name": "Rock_Basalt"
    },
    {
      "x": -19,
      "y": 11,
      "z": -1,
      "name": "Rock_Volcanic"
    },
    {
      "x": -19,
      "y": 12,
      "z": -1,
      "name": "Rock_Volcanic"
    },
    {
      "x": -19,
      "y": 13,
      "z": -1,
      "name": "Rock_Basalt"
    },
    {
      "x": -19,
      "y": 14,
      "z": -1,
      "name": "Rock_Basalt"
    },
    {
      "x": -19,
      "y": 15,
      "z": -1,
      "name": "Rock_Basalt"
    },
    {
      "x": -19,
      "y": 16,
      "z": -1,
      "name": "Rock_Basalt"
    },
    {
      "x": -19,
      "y": 17,
      "z": -1,
      "name": "Rock_Basalt"
    },
    {
      "x": -19,
      "y": 11,
      "z": 0,
      "name": "Rock_Volcanic"
    },
    {
      "x": -19,
      "y": 12,
      "z": 0,
      "name": "Rock_Volcanic"
    },
    {
      "x": -19,
      "y": 13,
      "z": 0,
      "name": "Rock_Volcanic"
    },
    {
      "x": -19,
      "y": 14,
      "z": 0,
      "name": "Rock_Basalt"
    },
    {
      "x": -19,
      "y": 15,
      "z": 0,
      "name": "Rock_Basalt"
    },
    {
      "x": -19,
      "y": 16,
      "z": 0,
      "name": "Rock_Basalt"
    },
    {
      "x": -19,
      "y": 17,
      "z": 0,
      "name": "Rock_Basalt"
    },
    {
      "x": -19,
      "y": 18,
      "z": 0,
      "name": "Rock_Basalt"
    },
    {
      "x": -19,
      "y": 12,
      "z": 1,
      "name": "Rock_Volcanic"
    },
    {
      "x": -19,
      "y": 13,
      "z": 1,
      "name": "Rock_Volcanic"
    },
    {
      "x": -19,
      "y": 14,
      "z": 1,
      "name": "Rock_Basalt"
    },
    {
      "x": -19,
      "y": 15,
      "z": 1,
      "name": "Rock_Basalt"
    },
    {
      "x": -19,
      "y": 16,
      "z": 1,
      "name": "Rock_Basalt"
    },
    {
      "x": -19,
      "y": 17,
      "z": 1,
      "name": "Rock_Basalt"
    },
    {
      "x": -19,
      "y": 18,
      "z": 1,
      "name": "Rock_Basalt"
    },
    {
      "x": -19,
      "y": 12,
      "z": 2,
      "name": "Rock_Volcanic"
    },
    {
      "x": -19,
      "y": 13,
      "z": 2,
      "name": "Rock_Volcanic"
    },
    {
      "x": -19,
      "y": 14,
      "z": 2,
      "name": "Rock_Basalt"
    },
    {
      "x": -19,
      "y": 15,
      "z": 2,
      "name": "Rock_Basalt"
    },
    {
      "x": -19,
      "y": 16,
      "z": 2,
      "name": "Rock_Basalt"
    },
    {
      "x": -19,
      "y": 17,
      "z": 2,
      "name": "Rock_Basalt"
    },
    {
      "x": -19,
      "y": 18,
      "z": 2,
      "name": "Rock_Basalt"
    },
    {
      "x": -19,
      "y": 12,
      "z": 3,
      "name": "Rock_Volcanic"
    },
    {
      "x": -19,
      "y": 13,
      "z": 3,
      "name": "Rock_Volcanic"
    },
    {
      "x": -19,
      "y": 14,
      "z": 3,
      "name": "Rock_Basalt"
    },
    {
      "x": -19,
      "y": 15,
      "z": 3,
      "name": "Rock_Basalt"
    },
    {
      "x": -19,
      "y": 16,
      "z": 3,
      "name": "Rock_Basalt"
    },
    {
      "x": -19,
      "y": 17,
      "z": 3,
      "name": "Rock_Basalt"
    },
    {
      "x": -19,
      "y": 12,
      "z": 4,
      "name": "Rock_Volcanic"
    },
    {
      "x": -19,
      "y": 13,
      "z": 4,
      "name": "Rock_Volcanic"
    },
    {
      "x": -19,
      "y": 14,
      "z": 4,
      "name": "Rock_Basalt"
    },
    {
      "x": -19,
      "y": 15,
      "z": 4,
      "name": "Rock_Basalt"
    },
    {
      "x": -19,
      "y": 16,
      "z": 4,
      "name": "Rock_Basalt"
    },
    {
      "x": -19,
      "y": 11,
      "z": 5,
      "name": "Rock_Volcanic"
    },
    {
      "x": -19,
      "y": 12,
      "z": 5,
      "name": "Rock_Volcanic"
    },
    {
      "x": -19,
      "y": 13,
      "z": 5,
      "name": "Rock_Volcanic"
    },
    {
      "x": -19,
      "y": 14,
      "z": 5,
      "name": "Rock_Basalt"
    },
    {
      "x": -19,
      "y": 15,
      "z": 5,
      "name": "Rock_Basalt"
    },
    {
      "x": -19,
      "y": 11,
      "z": 6,
      "name": "Rock_Volcanic"
    },
    {
      "x": -19,
      "y": 12,
      "z": 6,
      "name": "Rock_Volcanic"
    },
    {
      "x": -19,
      "y": 13,
      "z": 6,
      "name": "Rock_Basalt"
    },
    {
      "x": -19,
      "y": 14,
      "z": 6,
      "name": "Rock_Basalt"
    },
    {
      "x": -19,
      "y": 13,
      "z": 7,
      "name": "Rock_Basalt"
    },
    {
      "x": -19,
      "y": 14,
      "z": 7,
      "name": "Rock_Basalt"
    },
    {
      "x": -19,
      "y": -4,
      "z": 9,
      "name": "Rock_Volcanic"
    },
    {
      "x": -19,
      "y": -4,
      "z": 10,
      "name": "Rock_Volcanic"
    },
    {
      "x": -19,
      "y": -3,
      "z": 10,
      "name": "Rock_Volcanic"
    },
    {
      "x": -19,
      "y": -5,
      "z": 11,
      "name": "Rock_Basalt"
    },
    {
      "x": -19,
      "y": -4,
      "z": 11,
      "name": "Rock_Basalt"
    },
    {
      "x": -19,
      "y": -3,
      "z": 11,
      "name": "Rock_Volcanic"
    },
    {
      "x": -19,
      "y": -2,
      "z": 11,
      "name": "Rock_Volcanic"
    },
    {
      "x": -19,
      "y": -4,
      "z": 12,
      "name": "Rock_Basalt"
    },
    {
      "x": -19,
      "y": -3,
      "z": 12,
      "name": "Rock_Basalt"
    },
    {
      "x": -19,
      "y": -2,
      "z": 12,
      "name": "Rock_Volcanic"
    },
    {
      "x": -19,
      "y": -1,
      "z": 12,
      "name": "Rock_Volcanic"
    },
    {
      "x": -19,
      "y": -3,
      "z": 13,
      "name": "Rock_Basalt"
    },
    {
      "x": -19,
      "y": -2,
      "z": 13,
      "name": "Rock_Basalt"
    },
    {
      "x": -19,
      "y": -1,
      "z": 13,
      "name": "Rock_Volcanic"
    },
    {
      "x": -19,
      "y": 0,
      "z": 13,
      "name": "Rock_Volcanic"
    },
    {
      "x": -19,
      "y": 8,
      "z": 13,
      "name": "Rock_Volcanic"
    },
    {
      "x": -19,
      "y": 11,
      "z": 13,
      "name": "Rock_Basalt"
    },
    {
      "x": -19,
      "y": 12,
      "z": 13,
      "name": "Rock_Basalt"
    },
    {
      "x": -19,
