{
  "version": 8,
  "blockIdVersion": 8,
  "anchorX": 3,
  "anchorY": 8,
  "anchorZ": 7,
  "blocks": [
    {
      "x": 2,
      "y": 8,
      "z": 6,
      "name": "Plant_Coral_Block_Blue"
    },
    {
      "x": 2,
      "y": 9,
      "z": 6,
      "name": "Plant_Coral_Block_Purple"
    },
    {
      "x": 2,
      "y": 10,
      "z": 6,
      "name": "Rock_Crystal_Purple_Large"
    },
    {
      "x": 2,
      "y": 6,
      "z": 7,
      "name": "Plant_Coral_Block_Blue"
    },
    {
      "x": 2,
      "y": 7,
      "z": 7,
      "name": "Plant_Coral_Block_Blue"
    },
    {
      "x": 2,
      "y": 8,
      "z": 7,
      "name": "Plant_Coral_Block_Blue"
    },
    {
      "x": 2,
      "y": 9,
      "z": 7,
      "name": "Plant_Coral_Block_Blue"
    },
    {
      "x": 2,
      "y": 10,
      "z": 7,
      "name": "Plant_Coral_Block_Blue"
    },
    {
      "x": 2,
      "y": 11,
      "z": 7,
      "name": "Plant_Coral_Block_Purple"
    },
    {
      "x": 2,
      "y": 12,
      "z": 7,
      "name": "Plant_Coral_Block_Purple"
    },
    {
      "x": 2,
      "y": 13,
      "z": 7,
      "name": "Plant_Coral_Block_Purple"
    },
    {
      "x": 2,
      "y": 14,
      "z": 7,
      "name": "Rock_Crystal_Purple_Large"
    },
    {
      "x": 2,
      "y": 7,
      "z": 8,
      "name": "Plant_Coral_Block_Blue"
    },
    {
      "x": 2,
      "y": 8,
      "z": 8,
      "name": "Plant_Coral_Block_Blue"
    },
    {
      "x": 2,
      "y": 9,
      "z": 8,
      "name": "Plant_Coral_Block_Blue"
    },
    {
      "x": 2,
      "y": 10,
      "z": 8,
      "name": "Plant_Coral_Block_Purple"
    },
    {
      "x": 2,
      "y": 11,
      "z": 8,
      "name": "Rock_Crystal_Purple_Small"
    },
    {
      "x": 3,
      "y": 6,
      "z": 6,
      "name": "Plant_Coral_Block_Blue"
    },
    {
      "x": 3,
      "y": 7,
      "z": 6,
      "name": "Plant_Coral_Block_Blue"
    },
    {
      "x": 3,
      "y": 8,
      "z": 6,
      "name": "Plant_Coral_Block_Blue"
    },
    {
      "x": 3,
      "y": 9,
      "z": 6,
      "name": "Plant_Coral_Block_Blue"
    },
    {
      "x": 3,
      "y": 10,
      "z": 6,
      "name": "Plant_Coral_Block_Purple"
    },
    {
      "x": 3,
      "y": 11,
      "z": 6,
      "name": "Plant_Coral_Block_Purple"
    },
    {
      "x": 3,
      "y": 12,
      "z": 6,
      "name": "Plant_Coral_Block_Purple"
    },
    {
      "x": 3,
      "y": 13,
      "z": 6,
      "name": "Plant_Coral_Block_Purple"
    },
    {
      "x": 3,
      "y": 14,
      "z": 6,
      "name": "Plant_Coral_Block_Purple"
    },
    {
      "x": 3,
      "y": 4,
      "z": 7,
      "name": "Plant_Coral_Block_Blue"
    },
    {
      "x": 3,
      "y": 5,
      "z": 7,
      "name": "Plant_Coral_Block_Blue"
    },
    {
      "x": 3,
      "y": 6,
      "z": 7,
      "name": "Plant_Coral_Block_Blue"
    },
    {
      "x": 3,
      "y": 7,
      "z": 7,
      "name": "Plant_Coral_Block_Blue"
    },
    {
      "x": 3,
      "y": 8,
      "z": 7,
      "name": "Plant_Coral_Block_Blue"
    },
    {
      "x": 3,
      "y": 9,
      "z": 7,
      "name": "Plant_Coral_Block_Blue"
    },
    {
      "x": 3,
      "y": 10,
      "z": 7,
      "name": "Plant_Coral_Block_Blue"
    },
    {
      "x": 3,
      "y": 11,
      "z": 7,
      "name": "Plant_Coral_Block_Blue"
    },
    {
      "x": 3,
      "y": 12,
      "z": 7,
      "name": "Plant_Coral_Block_Blue"
    },
    {
      "x": 3,
      "y": 13,
      "z": 7,
      "name": "Plant_Coral_Block_Purple"
    },
    {
      "x": 3,
      "y": 14,
      "z": 7,
      "name": "Plant_Coral_Block_Purple"
    },
    {
      "x": 3,
      "y": 15,
      "z": 7,
      "name": "Plant_Coral_Block_Purple"
    },
    {
      "x": 3,
      "y": 16,
      "z": 7,
      "name": "Plant_Coral_Block_Purple"
    },
    {
      "x": 3,
      "y": 17,
      "z": 7,
      "name": "Rock_Crystal_Purple_Large"
    },
    {
      "x": 3,
      "y": 5,
      "z": 8,
      "name": "Plant_Coral_Block_Blue"
    },
    {
      "x": 3,
      "y": 6,
      "z": 8,
      "name": "Plant_Coral_Block_Blue"
    },
    {
      "x": 3,
      "y": 7,
      "z": 8,
      "name": "Plant_Coral_Block_Blue"
    },
    {
      "x": 3,
      "y": 8,
      "z": 8,
      "name": "Plant_Coral_Block_Blue"
    },
    {
      "x": 3,
      "y": 9,
      "z": 8,
      "name": "Plant_Coral_Block_Blue"
    },
    {
      "x": 3,
      "y": 10,
      "z": 8,
      "name": "Plant_Coral_Block_Blue"
    },
    {
      "x": 3,
      "y": 11,
      "z": 8,
      "name": "Plant_Coral_Block_Purple"
    },
    {
      "x": 3,
      "y": 12,
      "z": 8,
      "name": "Plant_Coral_Block_Purple"
    },
    {
      "x": 3,
      "y": 13,
      "z": 8,
      "name": "Rock_Crystal_Purple_Small"
    },
    {
      "x": 4,
      "y": 8,
      "z": 6,
      "name": "Plant_Coral_Block_Blue"
    },
    {
      "x": 4,
      "y": 9,
      "z": 6,
      "name": "Plant_Coral_Block_Blue"
    },
    {
      "x": 4,
      "y": 10,
      "z": 6,
      "name": "Plant_Coral_Block_Purple"
    },
    {
      "x": 4,
      "y": 11,
      "z": 6,
      "name": "Plant_Coral_Block_Purple"
    },
    {
      "x": 4,
      "y": 12,
      "z": 6,
      "name": "Plant_Coral_Block_Purple"
    },
    {
      "x": 4,
      "y": 13,
      "z": 6,
      "name": "Rock_Crystal_Purple_Large"
    },
    {
      "x": 4,
      "y": 7,
      "z": 7,
      "name": "Plant_Coral_Block_Blue"
    },
    {
      "x": 4,
      "y": 8,
      "z": 7,
      "name": "Plant_Coral_Block_Blue"
    },
    {
      "x": 4,
      "y": 9,
      "z": 7,
      "name": "Plant_Coral_Block_Blue"
    },
    {
      "x": 4,
      "y": 10,
      "z": 7,
      "name": "Plant_Coral_Block_Blue"
    },
    {
      "x": 4,
      "y": 11,
      "z": 7,
      "name": "Plant_Coral_Block_Blue"
    },
    {
      "x": 4,
      "y": 12,
      "z": 7,
      "name": "Plant_Coral_Block_Purple"
    },
    {
      "x": 4,
      "y": 13,
      "z": 7,
      "name": "Plant_Coral_Block_Purple"
    },
    {
      "x": 4,
      "y": 14,
      "z": 7,
      "name": "Plant_Coral_Block_Purple"
    },
    {
      "x": 4,
      "y": 15,
      "z": 7,
      "name": "Plant_Coral_Block_Purple"
    },
    {
      "x": 4,
      "y": 16,
      "z": 7,
      "name": "Rock_Crystal_Purple_Medium"
    },
    {
      "x": 4,
      "y": 7,
      "z": 8,
      "name": "Plant_Coral_Block_Blue"
    },
    {
      "x": 4,
      "y": 8,
      "z": 8,
      "name": "Plant_Coral_Block_Purple"
    },
    {
      "x": 4,
      "y": 9,
      "z": 8,
      "name": "Plant_Coral_Block_Purple"
    },
    {
      "x": 4,
      "y": 10,
      "z": 8,
      "name": "Rock_Crystal_Purple_Large"
    }
  ]
}