{
  "version": 8,
  "blockIdVersion": 8,
  "anchorX": 9,
  "anchorY": 11,
  "anchorZ": 9,
  "blocks": [
    {
      "x": 5,
      "y": 10,
      "z": 7,
      "name": "Rock_Basalt"
    },
    {
      "x": 5,
      "y": 11,
      "z": 7,
      "name": "Rock_Basalt"
    },
    {
      "x": 5,
      "y": 12,
      "z": 7,
      "name": "Rock_Basalt"
    },
    {
      "x": 5,
      "y": 13,
      "z": 7,
      "name": "Rock_Basalt"
    },
    {
      "x": 5,
      "y": 9,
      "z": 8,
      "name": "Rock_Basalt"
    },
    {
      "x": 5,
      "y": 10,
      "z": 8,
      "name": "Rock_Basalt"
    },
    {
      "x": 5,
      "y": 11,
      "z": 8,
      "name": "Rock_Basalt"
    },
    {
      "x": 5,
      "y": 12,
      "z": 8,
      "name": "Rock_Basalt"
    },
    {
      "x": 5,
      "y": 13,
      "z": 8,
      "name": "Rock_Basalt"
    },
    {
      "x": 5,
      "y": 9,
      "z": 9,
      "name": "Rock_Basalt"
    },
    {
      "x": 5,
      "y": 10,
      "z": 9,
      "name": "Rock_Basalt"
    },
    {
      "x": 5,
      "y": 11,
      "z": 9,
      "name": "Rock_Basalt"
    },
    {
      "x": 5,
      "y": 12,
      "z": 9,
      "name": "Rock_Basalt"
    },
    {
      "x": 5,
      "y": 13,
      "z": 9,
      "name": "Rock_Basalt"
    },
    {
      "x": 5,
      "y": 10,
      "z": 10,
      "name": "Rock_Basalt"
    },
    {
      "x": 5,
      "y": 11,
      "z": 10,
      "name": "Rock_Basalt"
    },
    {
      "x": 5,
      "y": 12,
      "z": 10,
      "name": "Rock_Basalt"
    },
    {
      "x": 6,
      "y": 11,
      "z": 6,
      "name": "Rock_Basalt"
    },
    {
      "x": 6,
      "y": 12,
      "z": 6,
      "name": "Rock_Basalt"
    },
    {
      "x": 6,
      "y": 13,
      "z": 6,
      "name": "Rock_Basalt"
    },
    {
      "x": 6,
      "y": 9,
      "z": 7,
      "name": "Rock_Basalt"
    },
    {
      "x": 6,
      "y": 10,
      "z": 7,
      "name": "Rock_Basalt"
    },
    {
      "x": 6,
      "y": 11,
      "z": 7,
      "name": "Rock_Basalt"
    },
    {
      "x": 6,
      "y": 12,
      "z": 7,
      "name": "Rock_Basalt"
    },
    {
      "x": 6,
      "y": 13,
      "z": 7,
      "name": "Rock_Basalt"
    },
    {
      "x": 6,
      "y": 14,
      "z": 7,
      "name": "Rock_Basalt"
    },
    {
      "x": 6,
      "y": 8,
      "z": 8,
      "name": "Rock_Basalt"
    },
    {
      "x": 6,
      "y": 9,
      "z": 8,
      "name": "Rock_Basalt"
    },
    {
      "x": 6,
      "y": 10,
      "z": 8,
      "name": "Rock_Basalt"
    },
    {
      "x": 6,
      "y": 11,
      "z": 8,
      "name": "Rock_Basalt"
    },
    {
      "x": 6,
      "y": 12,
      "z": 8,
      "name": "Rock_Basalt"
    },
    {
      "x": 6,
      "y": 13,
      "z": 8,
      "name": "Rock_Basalt"
    },
    {
      "x": 6,
      "y": 14,
      "z": 8,
      "name": "Rock_Basalt"
    },
    {
      "x": 6,
      "y": 8,
      "z": 9,
      "name": "Rock_Basalt"
    },
    {
      "x": 6,
      "y": 9,
      "z": 9,
      "name": "Rock_Basalt"
    },
    {
      "x": 6,
      "y": 10,
      "z": 9,
      "name": "Rock_Basalt"
    },
    {
      "x": 6,
      "y": 11,
      "z": 9,
      "name": "Rock_Basalt"
    },
    {
      "x": 6,
      "y": 12,
      "z": 9,
      "name": "Rock_Basalt"
    },
    {
      "x": 6,
      "y": 13,
      "z": 9,
      "name": "Rock_Basalt"
    },
    {
      "x": 6,
      "y": 14,
      "z": 9,
      "name": "Rock_Basalt"
    },
    {
      "x": 6,
      "y": 15,
      "z": 9,
      "name": "Rock_Basalt"
    },
    {
      "x": 6,
      "y": 9,
      "z": 10,
      "name": "Rock_Basalt"
    },
    {
      "x": 6,
      "y": 10,
      "z": 10,
      "name": "Rock_Basalt"
    },
    {
      "x": 6,
      "y": 11,
      "z": 10,
      "name": "Rock_Basalt"
    },
    {
      "x": 6,
      "y": 12,
      "z": 10,
      "name": "Rock_Basalt"
    },
    {
      "x": 6,
      "y": 13,
      "z": 10,
      "name": "Rock_Basalt"
    },
    {
      "x": 6,
      "y": 14,
      "z": 10,
      "name": "Rock_Basalt"
    },
    {
      "x": 6,
      "y": 15,
      "z": 10,
      "name": "Rock_Basalt"
    },
    {
      "x": 6,
      "y": 10,
      "z": 11,
      "name": "Rock_Basalt"
    },
    {
      "x": 6,
      "y": 11,
      "z": 11,
      "name": "Rock_Basalt"
    },
    {
      "x": 6,
      "y": 12,
      "z": 11,
      "name": "Rock_Basalt"
    },
    {
      "x": 6,
      "y": 13,
      "z": 11,
      "name": "Rock_Basalt"
    },
    {
      "x": 6,
      "y": 14,
      "z": 11,
      "name": "Rock_Basalt"
    },
    {
      "x": 7,
      "y": 12,
      "z": 5,
      "name": "Rock_Basalt"
    },
    {
      "x": 7,
      "y": 13,
      "z": 5,
      "name": "Rock_Basalt"
    },
    {
      "x": 7,
      "y": 14,
      "z": 5,
      "name": "Rock_Basalt"
    },
    {
      "x": 7,
      "y": 9,
      "z": 6,
      "name": "Rock_Basalt"
    },
    {
      "x": 7,
      "y": 10,
      "z": 6,
      "name": "Rock_Basalt"
    },
    {
      "x": 7,
      "y": 11,
      "z": 6,
      "name": "Rock_Basalt"
    },
    {
      "x": 7,
      "y": 12,
      "z": 6,
      "name": "Rock_Basalt"
    },
    {
      "x": 7,
      "y": 13,
      "z": 6,
      "name": "Rock_Basalt"
    },
    {
      "x": 7,
      "y": 14,
      "z": 6,
      "name": "Rock_Basalt"
    },
    {
      "x": 7,
      "y": 7,
      "z": 7,
      "name": "Rock_Basalt"
    },
    {
      "x": 7,
      "y": 8,
      "z": 7,
      "name": "Rock_Basalt"
    },
    {
      "x": 7,
      "y": 9,
      "z": 7,
      "name": "Rock_Basalt"
    },
    {
      "x": 7,
      "y": 10,
      "z": 7,
      "name": "Rock_Basalt"
    },
    {
      "x": 7,
      "y": 11,
      "z": 7,
      "name": "Rock_Basalt"
    },
    {
      "x": 7,
      "y": 12,
      "z": 7,
      "name": "Rock_Basalt"
    },
    {
      "x": 7,
      "y": 13,
      "z": 7,
      "name": "Rock_Basalt"
    },
    {
      "x": 7,
      "y": 14,
      "z": 7,
      "name": "Rock_Basalt"
    },
    {
      "x": 7,
      "y": 7,
      "z": 8,
      "name": "Rock_Basalt"
    },
    {
      "x": 7,
      "y": 8,
      "z": 8,
      "name": "Rock_Basalt"
    },
    {
      "x": 7,
      "y": 9,
      "z": 8,
      "name": "Rock_Basalt"
    },
    {
      "x": 7,
      "y": 10,
      "z": 8,
      "name": "Rock_Basalt"
    },
    {
      "x": 7,
      "y": 11,
      "z": 8,
      "name": "Rock_Basalt"
    },
    {
      "x": 7,
      "y": 12,
      "z": 8,
      "name": "Rock_Basalt"
    },
    {
      "x": 7,
      "y": 13,
      "z": 8,
      "name": "Rock_Basalt"
    },
    {
      "x": 7,
      "y": 14,
      "z": 8,
      "name": "Rock_Basalt"
    },
    {
      "x": 7,
      "y": 15,
      "z": 8,
      "name": "Rock_Basalt"
    },
    {
      "x": 7,
      "y": 16,
      "z": 8,
      "name": "Rock_Basalt"
    },
    {
      "x": 7,
      "y": 7,
      "z": 9,
      "name": "Rock_Basalt"
    },
    {
      "x": 7,
      "y": 8,
      "z": 9,
      "name": "Rock_Basalt"
    },
    {
      "x": 7,
      "y": 9,
      "z": 9,
      "name": "Rock_Basalt"
    },
    {
      "x": 7,
      "y": 10,
      "z": 9,
      "name": "Rock_Basalt"
    },
    {
      "x": 7,
      "y": 11,
      "z": 9,
      "name": "Rock_Basalt"
    },
    {
      "x": 7,
      "y": 12,
      "z": 9,
      "name": "Rock_Basalt"
    },
    {
      "x": 7,
      "y": 13,
      "z": 9,
      "name": "Rock_Basalt"
    },
    {
      "x": 7,
      "y": 14,
      "z": 9,
      "name": "Rock_Basalt"
    },
    {
      "x": 7,
      "y": 15,
      "z": 9,
      "name": "Rock_Basalt"
    },
    {
      "x": 7,
      "y": 16,
      "z": 9,
      "name": "Rock_Basalt"
    },
    {
      "x": 7,
      "y": 7,
      "z": 10,
      "name": "Rock_Basalt"
    },
    {
      "x": 7,
      "y": 8,
      "z": 10,
      "name": "Rock_Basalt"
    },
    {
      "x": 7,
      "y": 9,
      "z": 10,
      "name": "Rock_Basalt"
    },
    {
      "x": 7,
      "y": 10,
      "z": 10,
      "name": "Rock_Basalt"
    },
    {
      "x": 7,
      "y": 11,
      "z": 10,
      "name": "Rock_Basalt"
    },
    {
      "x": 7,
      "y": 12,
      "z": 10,
      "name": "Rock_Basalt"
    },
    {
      "x": 7,
      "y": 13,
      "z": 10,
      "name": "Rock_Basalt"
    },
    {
      "x": 7,
      "y": 14,
      "z": 10,
      "name": "Rock_Basalt"
    },
    {
      "x": 7,
      "y": 15,
      "z": 10,
      "name": "Rock_Basalt"
    },
    {
      "x": 7,
      "y": 8,
      "z": 11,
      "name": "Rock_Basalt"
    },
    {
      "x": 7,
      "y": 9,
      "z": 11,
      "name": "Rock_Basalt"
    },
    {
      "x": 7,
      "y": 10,
      "z": 11,
      "name": "Rock_Basalt"
    },
    {
      "x": 7,
      "y": 11,
      "z": 11,
      "name": "Rock_Basalt"
    },
    {
      "x": 7,
      "y": 12,
      "z": 11,
      "name": "Rock_Basalt"
    },
    {
      "x": 7,
      "y": 13,
      "z": 11,
      "name": "Rock_Basalt"
    },
    {
      "x": 7,
      "y": 14,
      "z": 11,
      "name": "Rock_Basalt"
    },
    {
      "x": 7,
      "y": 15,
      "z": 11,
      "name": "Rock_Basalt"
    },
    {
      "x": 7,
      "y": 10,
      "z": 12,
      "name": "Rock_Basalt"
    },
    {
      "x": 7,
      "y": 11,
      "z": 12,
      "name": "Rock_Basalt"
    },
    {
      "x": 7,
      "y": 12,
      "z": 12,
      "name": "Rock_Basalt"
    },
    {
      "x": 7,
      "y": 13,
      "z": 12,
      "name": "Rock_Basalt"
    },
    {
      "x": 8,
      "y": 11,
      "z": 5,
      "name": "Rock_Basalt"
    },
    {
      "x": 8,
      "y": 12,
      "z": 5,
      "name": "Rock_Basalt"
    },
    {
      "x": 8,
      "y": 13,
      "z": 5,
      "name": "Rock_Basalt"
    },
    {
      "x": 8,
      "y": 14,
      "z": 5,
      "name": "Rock_Basalt"
    },
    {
      "x": 8,
      "y": 15,
      "z": 5,
      "name": "Rock_Basalt"
    },
    {
      "x": 8,
      "y": 8,
      "z": 6,
      "name": "Rock_Basalt"
    },
    {
      "x": 8,
      "y": 9,
      "z": 6,
      "name": "Rock_Basalt"
    },
    {
      "x": 8,
      "y": 10,
      "z": 6,
      "name": "Rock_Basalt"
    },
    {
      "x": 8,
      "y": 11,
      "z": 6,
      "name": "Rock_Basalt"
    },
    {
      "x": 8,
      "y": 12,
      "z": 6,
      "name": "Rock_Basalt"
    },
    {
      "x": 8,
      "y": 13,
      "z": 6,
      "name": "Rock_Basalt"
    },
    {
      "x": 8,
      "y": 14,
      "z": 6,
      "name": "Rock_Basalt"
    },
    {
      "x": 8,
      "y": 15,
      "z": 6,
      "name": "Rock_Basalt"
    },
    {
      "x": 8,
      "y": 16,
      "z": 6,
      "name": "Rock_Basalt"
    },
    {
      "x": 8,
      "y": 7,
      "z": 7,
      "name": "Rock_Basalt"
    },
    {
      "x": 8,
      "y": 8,
      "z": 7,
      "name": "Rock_Basalt"
    },
    {
      "x": 8,
      "y": 9,
      "z": 7,
      "name": "Rock_Basalt"
    },
    {
      "x": 8,
      "y": 10,
      "z": 7,
      "name": "Rock_Basalt"
    },
    {
      "x": 8,
      "y": 11,
      "z": 7,
      "name": "Rock_Basalt"
    },
    {
      "x": 8,
      "y": 12,
      "z": 7,
      "name": "Rock_Basalt"
    },
    {
      "x": 8,
      "y": 13,
      "z": 7,
      "name": "Rock_Basalt"
    },
    {
      "x": 8,
      "y": 14,
      "z": 7,
      "name": "Rock_Basalt"
    },
    {
      "x": 8,
      "y": 15,
      "z": 7,
      "name": "Rock_Basalt"
    },
    {
      "x": 8,
      "y": 16,
      "z": 7,
      "name": "Rock_Basalt"
    },
    {
      "x": 8,
      "y": 7,
      "z": 8,
      "name": "Rock_Basalt"
    },
    {
      "x": 8,
      "y": 8,
      "z": 8,
      "name": "Rock_Basalt"
    },
    {
      "x": 8,
      "y": 9,
      "z": 8,
      "name": "Rock_Basalt"
    },
    {
      "x": 8,
      "y": 10,
      "z": 8,
      "name": "Rock_Basalt"
    },
    {
      "x": 8,
      "y": 11,
      "z": 8,
      "name": "Rock_Basalt"
    },
    {
      "x": 8,
      "y": 12,
      "z": 8,
      "name": "Rock_Basalt"
    },
    {
      "x": 8,
      "y": 13,
      "z": 8,
      "name": "Rock_Basalt"
    },
    {
      "x": 8,
      "y": 14,
      "z": 8,
      "name": "Rock_Basalt"
    },
    {
      "x": 8,
      "y": 15,
      "z": 8,
      "name": "Rock_Basalt"
    },
    {
      "x": 8,
      "y": 16,
      "z": 8,
      "name": "Rock_Basalt"
    },
    {
      "x": 8,
      "y": 7,
      "z": 9,
      "name": "Rock_Basalt"
    },
    {
      "x": 8,
      "y": 8,
      "z": 9,
      "name": "Rock_Basalt"
    },
    {
      "x": 8,
      "y": 9,
      "z": 9,
      "name": "Rock_Basalt"
    },
    {
      "x": 8,
      "y": 10,
      "z": 9,
      "name": "Rock_Basalt"
    },
    {
      "x": 8,
      "y": 11,
      "z": 9,
      "name": "Rock_Basalt"
    },
    {
      "x": 8,
      "y": 12,
      "z": 9,
      "name": "Rock_Basalt"
    },
    {
      "x": 8,
      "y": 13,
      "z": 9,
      "name": "Rock_Basalt"
    },
    {
      "x": 8,
      "y": 14,
      "z": 9,
      "name": "Rock_Basalt"
    },
    {
      "x": 8,
      "y": 15,
      "z": 9,
      "name": "Rock_Basalt"
    },
    {
      "x": 8,
      "y": 16,
      "z": 9,
      "name": "Rock_Basalt"
    },
    {
      "x": 8,
      "y": 7,
      "z": 10,
      "name": "Rock_Basalt"
    },
    {
      "x": 8,
      "y": 8,
      "z": 10,
      "name": "Rock_Basalt"
    },
    {
      "x": 8,
      "y": 9,
      "z": 10,
      "name": "Rock_Basalt"
    },
    {
      "x": 8,
      "y": 10,
      "z": 10,
      "name": "Rock_Basalt"
    },
    {
      "x": 8,
      "y": 11,
      "z": 10,
      "name": "Rock_Basalt"
    },
    {
      "x": 8,
      "y": 12,
      "z": 10,
      "name": "Rock_Basalt"
    },
    {
      "x": 8,
      "y": 13,
      "z": 10,
      "name": "Rock_Basalt"
    },
    {
      "x": 8,
      "y": 14,
      "z": 10,
      "name": "Rock_Basalt"
    },
    {
      "x": 8,
      "y": 15,
      "z": 10,
      "name": "Rock_Basalt"
    },
    {
      "x": 8,
      "y": 16,
      "z": 10,
      "name": "Rock_Basalt"
    },
    {
      "x": 8,
      "y": 7,
      "z": 11,
      "name": "Rock_Basalt"
    },
    {
      "x": 8,
      "y": 8,
      "z": 11,
      "name": "Rock_Basalt"
    },
    {
      "x": 8,
      "y": 9,
      "z": 11,
      "name": "Rock_Basalt"
    },
    {
      "x": 8,
      "y": 10,
      "z": 11,
      "name": "Rock_Basalt"
    },
    {
      "x": 8,
      "y": 11,
      "z": 11,
      "name": "Rock_Basalt"
    },
    {
      "x": 8,
      "y": 12,
      "z": 11,
      "name": "Rock_Basalt"
    },
    {
      "x": 8,
      "y": 13,
      "z": 11,
      "name": "Rock_Basalt"
    },
    {
      "x": 8,
      "y": 14,
      "z": 11,
      "name": "Rock_Basalt"
    },
    {
      "x": 8,
      "y": 15,
      "z": 11,
      "name": "Rock_Basalt"
    },
    {
      "x": 8,
      "y": 9,
      "z": 12,
      "name": "Rock_Basalt"
    },
    {
      "x": 8,
      "y": 10,
      "z": 12,
      "name": "Rock_Basalt"
    },
    {
      "x": 8,
      "y": 11,
      "z": 12,
      "name": "Rock_Basalt"
    },
    {
      "x": 8,
      "y": 12,
      "z": 12,
      "name": "Rock_Basalt"
    },
    {
      "x": 8,
      "y": 13,
      "z": 12,
      "name": "Rock_Basalt"
    },
    {
      "x": 8,
      "y": 14,
      "z": 12,
      "name": "Rock_Basalt"
    },
    {
      "x": 8,
      "y": 11,
      "z": 13,
      "name": "Rock_Basalt"
    },
    {
      "x": 8,
      "y": 12,
      "z": 13,
      "name": "Rock_Basalt"
    },
    {
      "x": 8,
      "y": 13,
      "z": 13,
      "name": "Rock_Basalt"
    },
    {
      "x": 9,
      "y": 13,
      "z": 4,
      "name": "Rock_Basalt"
    },
    {
      "x": 9,
      "y": 14,
      "z": 4,
      "name": "Rock_Basalt"
    },
    {
      "x": 9,
      "y": 15,
      "z": 4,
      "name": "Rock_Basalt"
    },
    {
      "x": 9,
      "y": 11,
      "z": 5,
      "name": "Rock_Basalt"
    },
    {
      "x": 9,
      "y": 12,
      "z": 5,
      "name": "Rock_Basalt"
    },
    {
      "x": 9,
      "y": 13,
      "z": 5,
      "name": "Rock_Basalt"
    },
    {
      "x": 9,
      "y": 14,
      "z": 5,
      "name": "Rock_Basalt"
    },
    {
      "x": 9,
      "y": 15,
      "z": 5,
      "name": "Rock_Basalt"
    },
    {
      "x": 9,
      "y": 16,
      "z": 5,
      "name": "Rock_Basalt"
    },
    {
      "x": 9,
      "y": 8,
      "z": 6,
      "name": "Rock_Basalt"
    },
    {
      "x": 9,
      "y": 9,
      "z": 6,
      "name": "Rock_Basalt"
    },
    {
      "x": 9,
      "y": 11,
      "z": 6,
      "name": "Rock_Basalt"
    },
    {
      "x": 9,
      "y": 12,
      "z": 6,
      "name": "Rock_Basalt"
    },
    {
      "x": 9,
      "y": 13,
      "z": 6,
      "name": "Rock_Basalt"
    },
    {
      "x": 9,
      "y": 14,
      "z": 6,
      "name": "Rock_Basalt"
    },
    {
      "x": 9,
      "y": 15,
      "z": 6,
      "name": "Rock_Basalt"
    },
    {
      "x": 9,
      "y": 16,
      "z": 6,
      "name": "Rock_Basalt"
    },
    {
      "x": 9,
      "y": 17,
      "z": 6,
      "name": "Rock_Basalt"
    },
    {
      "x": 9,
      "y": 7,
      "z": 7,
      "name": "Rock_Basalt"
    },
    {
      "x": 9,
      "y": 8,
      "z": 7,
      "name": "Rock_Basalt"
    },
    {
      "x": 9,
      "y": 9,
      "z": 7,
      "name": "Rock_Basalt"
    },
    {
      "x": 9,
      "y": 10,
      "z": 7,
      "name": "Rock_Basalt"
    },
    {
      "x": 9,
      "y": 11,
      "z": 7,
      "name": "Rock_Basalt"
    },
    {
      "x": 9,
      "y": 12,
      "z": 7,
      "name": "Rock_Basalt"
    },
    {
      "x": 9,
      "y": 13,
      "z": 7,
      "name": "Rock_Basalt"
    },
    {
      "x": 9,
      "y": 14,
      "z": 7,
      "name": "Rock_Basalt"
    },
    {
      "x": 9,
      "y": 15,
      "z": 7,
      "name": "Rock_Basalt"
    },
    {
      "x": 9,
      "y": 16,
      "z": 7,
      "name": "Rock_Basalt"
    },
    {
      "x": 9,
      "y": 17,
      "z": 7,
      "name": "Rock_Basalt"
    },
    {
      "x": 9,
      "y": 7,
      "z": 8,
      "name": "Rock_Basalt"
    },
    {
      "x": 9,
      "y": 8,
      "z": 8,
      "name": "Rock_Basalt"
    },
    {
      "x": 9,
      "y": 9,
      "z": 8,
      "name": "Rock_Basalt"
    },
    {
      "x": 9,
      "y": 10,
      "z": 8,
      "name": "Rock_Basalt"
    },
    {
      "x": 9,
      "y": 11,
      "z": 8,
      "name": "Rock_Basalt"
    },
    {
      "x": 9,
      "y": 12,
      "z": 8,
      "name": "Rock_Basalt"
    },
    {
      "x": 9,
      "y": 13,
      "z": 8,
      "name": "Rock_Basalt"
    },
    {
      "x": 9,
      "y": 14,
      "z": 8,
      "name": "Rock_Basalt"
    },
    {
      "x": 9,
      "y": 15,
      "z": 8,
      "name": "Rock_Basalt"
    },
    {
      "x": 9,
      "y": 16,
      "z": 8,
      "name": "Rock_Basalt"
    },
    {
      "x": 9,
      "y": 17,
      "z": 8,
      "name": "Rock_Basalt"
    },
    {
      "x": 9,
      "y": 7,
      "z": 9,
      "name": "Rock_Basalt"
    },
    {
      "x": 9,
      "y": 8,
      "z": 9,
      "name": "Rock_Basalt"
    },
    {
      "x": 9,
      "y": 9,
      "z": 9,
      "name": "Rock_Basalt"
    },
    {
      "x": 9,
      "y": 10,
      "z": 9,
      "name": "Rock_Basalt"
    },
    {
      "x": 9,
      "y": 11,
      "z": 9,
      "name": "Rock_Basalt"
    },
    {
      "x": 9,
      "y": 12,
      "z": 9,
      "name": "Rock_Basalt"
    },
    {
      "x": 9,
      "y": 13,
      "z": 9,
      "name": "Rock_Basalt"
    },
    {
      "x": 9,
      "y": 14,
      "z": 9,
      "name": "Rock_Basalt"
    },
    {
      "x": 9,
      "y": 15,
      "z": 9,
      "name": "Rock_Basalt"
    },
    {
      "x": 9,
      "y": 16,
      "z": 9,
      "name": "Rock_Basalt"
    },
    {
      "x": 9,
      "y": 17,
      "z": 9,
      "name": "Rock_Basalt"
    },
    {
      "x": 9,
      "y": 7,
      "z": 10,
      "name": "Rock_Basalt"
    },
    {
      "x": 9,
      "y": 8,
      "z": 10,
      "name": "Rock_Basalt"
    },
    {
      "x": 9,
      "y": 9,
      "z": 10,
      "name": "Rock_Basalt"
    },
    {
      "x": 9,
      "y": 10,
      "z": 10,
      "name": "Rock_Basalt"
    },
    {
      "x": 9,
      "y": 11,
      "z": 10,
      "name": "Rock_Basalt"
    },
    {
      "x": 9,
      "y": 12,
      "z": 10,
      "name": "Rock_Basalt"
    },
    {
      "x": 9,
      "y": 13,
      "z": 10,
      "name": "Rock_Basalt"
    },
    {
      "x": 9,
      "y": 14,
      "z": 10,
      "name": "Rock_Basalt"
    },
    {
      "x": 9,
      "y": 15,
      "z": 10,
      "name": "Rock_Basalt"
    },
    {
      "x": 9,
      "y": 16,
      "z": 10,
      "name": "Rock_Basalt"
    },
    {
      "x": 9,
      "y": 7,
      "z": 11,
      "name": "Rock_Basalt"
    },
    {
      "x": 9,
      "y": 8,
      "z": 11,
      "name": "Rock_Basalt"
    },
    {
      "x": 9,
      "y": 9,
      "z": 11,
      "name": "Rock_Basalt"
    },
    {
      "x": 9,
      "y": 10,
      "z": 11,
      "name": "Rock_Basalt"
    },
    {
      "x": 9,
      "y": 11,
      "z": 11,
      "name": "Rock_Basalt"
    },
    {
      "x": 9,
      "y": 12,
      "z": 11,
      "name": "Rock_Basalt"
    },
    {
      "x": 9,
      "y": 13,
      "z": 11,
      "name": "Rock_Basalt"
    },
    {
      "x": 9,
      "y": 14,
      "z": 11,
      "name": "Rock_Basalt"
    },
    {
      "x": 9,
      "y": 15,
      "z": 11,
      "name": "Rock_Basalt"
    },
    {
      "x": 9,
      "y": 16,
      "z": 11,
      "name": "Rock_Basalt"
    },
    {
      "x": 9,
      "y": 9,
      "z": 12,
      "name": "Rock_Basalt"
    },
    {
      "x": 9,
      "y": 10,
      "z": 12,
      "name": "Rock_Basalt"
    },
    {
      "x": 9,
      "y": 11,
      "z": 12,
      "name": "Rock_Basalt"
    },
    {
      "x": 9,
      "y": 12,
      "z": 12,
      "name": "Rock_Basalt"
    },
    {
      "x": 9,
      "y": 13,
      "z": 12,
      "name": "Rock_Basalt"
    },
    {
      "x": 9,
      "y": 14,
      "z": 12,
      "name": "Rock_Basalt"
    },
    {
      "x": 9,
      "y": 15,
      "z": 12,
      "name": "Rock_Basalt"
    },
    {
      "x": 9,
      "y": 10,
      "z": 13,
      "name": "Rock_Basalt"
    },
    {
      "x": 9,
      "y": 11,
      "z": 13,
      "name": "Rock_Basalt"
    },
    {
      "x": 9,
      "y": 12,
      "z": 13,
      "name": "Rock_Basalt"
    },
    {
      "x": 9,
      "y": 13,
      "z": 13,
      "name": "Rock_Basalt"
    },
    {
      "x": 10,
      "y": 13,
      "z": 4,
      "name": "Rock_Basalt"
    },
    {
      "x": 10,
      "y": 14,
      "z": 4,
      "name": "Rock_Basalt"
    },
    {
      "x": 10,
      "y": 15,
      "z": 4,
      "name": "Rock_Basalt"
    },
    {
      "x": 10,
      "y": 13,
      "z": 5,
      "name": "Rock_Basalt"
    },
    {
      "x": 10,
      "y": 14,
      "z": 5,
      "name": "Rock_Basalt"
    },
    {
      "x": 10,
      "y": 15,
      "z": 5,
      "name": "Rock_Basalt"
    },
    {
      "x": 10,
      "y": 16,
      "z": 5,
      "name": "Rock_Basalt"
    },
    {
      "x": 10,
      "y": 13,
      "z": 6,
      "name": "Rock_Basalt"
    },
    {
      "x": 10,
      "y": 14,
      "z": 6,
      "name": "Rock_Basalt"
    },
    {
      "x": 10,
      "y": 15,
      "z": 6,
      "name": "Rock_Basalt"
    },
    {
      "x": 10,
      "y": 16,
      "z": 6,
      "name": "Rock_Basalt"
    },
    {
      "x": 10,
      "y": 17,
      "z": 6,
      "name": "Rock_Basalt"
    },
    {
      "x": 10,
      "y": 7,
      "z": 7,
      "name": "Rock_Basalt"
    },
    {
      "x": 10,
      "y": 8,
      "z": 7,
      "name": "Rock_Basalt"
    },
    {
      "x": 10,
      "y": 11,
      "z": 7,
      "name": "Rock_Basalt"
    },
    {
      "x": 10,
      "y": 12,
      "z": 7,
      "name": "Rock_Basalt"
    },
    {
      "x": 10,
      "y": 13,
      "z": 7,
      "name": "Rock_Basalt"
    },
    {
      "x": 10,
      "y": 14,
      "z": 7,
      "name": "Rock_Basalt"
    },
    {
      "x": 10,
      "y": 15,
      "z": 7,
      "name": "Rock_Basalt"
    },
    {
      "x": 10,
      "y": 16,
      "z": 7,
      "name": "Rock_Basalt"
    },
    {
      "x": 10,
      "y": 17,
      "z": 7,
      "name": "Rock_Basalt"
    },
    {
      "x": 10,
      "y": 7,
      "z": 8,
      "name": "Rock_Basalt"
    },
    {
      "x": 10,
      "y": 8,
      "z": 8,
      "name": "Rock_Basalt"
    },
    {
      "x": 10,
      "y": 9,
      "z": 8,
      "name": "Rock_Basalt"
    },
    {
      "x": 10,
      "y": 10,
      "z": 8,
      "name": "Rock_Basalt"
    },
    {
      "x": 10,
      "y": 11,
      "z": 8,
      "name": "Rock_Basalt"
    },
    {
      "x": 10,
      "y": 12,
      "z": 8,
      "name": "Rock_Basalt"
    },
    {
      "x": 10,
      "y": 13,
      "z": 8,
      "name": "Rock_Basalt"
    },
    {
      "x": 10,
      "y": 14,
      "z": 8,
      "name": "Rock_Basalt"
    },
    {
      "x": 10,
      "y": 15,
      "z": 8,
      "name": "Rock_Basalt"
    },
    {
      "x": 10,
      "y": 16,
      "z": 8,
      "name": "Rock_Basalt"
    },
    {
      "x": 10,
      "y": 17,
      "z": 8,
      "name": "Rock_Basalt"
    },
    {
      "x": 10,
      "y": 7,
      "z": 9,
      "name": "Rock_Basalt"
    },
    {
      "x": 10,
      "y": 8,
      "z": 9,
      "name": "Rock_Basalt"
    },
    {
      "x": 10,
      "y": 9,
      "z": 9,
      "name": "Rock_Basalt"
    },
    {
      "x": 10,
      "y": 10,
      "z": 9,
      "name": "Rock_Basalt"
    },
    {
      "x": 10,
      "y": 11,
      "z": 9,
      "name": "Rock_Basalt"
    },
    {
      "x": 10,
      "y": 12,
      "z": 9,
      "name": "Rock_Basalt"
    },
    {
      "x": 10,
      "y": 13,
      "z": 9,
      "name": "Rock_Basalt"
    },
    {
      "x": 10,
      "y": 14,
      "z": 9,
      "name": "Rock_Basalt"
    },
    {
      "x": 10,
      "y": 15,
      "z": 9,
      "name": "Rock_Basalt"
    },
    {
      "x": 10,
      "y": 16,
      "z": 9,
      "name": "Rock_Basalt"
    },
    {
      "x": 10,
      "y": 17,
      "z": 9,
      "name": "Rock_Basalt"
    },
    {
      "x": 10,
      "y": 7,
      "z": 10,
      "name": "Rock_Basalt"
    },
    {
      "x": 10,
      "y": 8,
      "z": 10,
      "name": "Rock_Basalt"
    },
    {
      "x": 10,
      "y": 9,
      "z": 10,
      "name": "Rock_Basalt"
    },
    {
      "x": 10,
      "y": 10,
      "z": 10,
      "name": "Rock_Basalt"
    },
    {
      "x": 10,
      "y": 11,
      "z": 10,
      "name": "Rock_Basalt"
    },
    {
      "x": 10,
      "y": 12,
      "z": 10,
      "name": "Rock_Basalt"
    },
    {
      "x": 10,
      "y": 13,
      "z": 10,
      "name": "Rock_Basalt"
    },
    {
      "x": 10,
      "y": 14,
      "z": 10,
      "name": "Rock_Basalt"
    },
    {
      "x": 10,
      "y": 15,
      "z": 10,
      "name": "Rock_Basalt"
    },
    {
      "x": 10,
      "y": 16,
      "z": 10,
      "name": "Rock_Basalt"
    },
    {
      "x": 10,
      "y": 7,
      "z": 11,
      "name": "Rock_Basalt"
    },
    {
      "x": 10,
      "y": 8,
      "z": 11,
      "name": "Rock_Basalt"
    },
    {
      "x": 10,
      "y": 9,
      "z": 11,
      "name": "Rock_Basalt"
    },
    {
      "x": 10,
      "y": 10,
      "z": 11,
      "name": "Rock_Basalt"
    },
    {
      "x": 10,
      "y": 11,
      "z": 11,
      "name": "Rock_Basalt"
    },
    {
      "x": 10,
      "y": 12,
      "z": 11,
      "name": "Rock_Basalt"
    },
    {
      "x": 10,
      "y": 13,
      "z": 11,
      "name": "Rock_Basalt"
    },
    {
      "x": 10,
      "y": 14,
      "z": 11,
      "name": "Rock_Basalt"
    },
    {
      "x": 10,
      "y": 15,
      "z": 11,
      "name": "Rock_Basalt"
    },
    {
      "x": 10,
      "y": 16,
      "z": 11,
      "name": "Rock_Basalt"
    },
    {
      "x": 10,
      "y": 9,
      "z": 12,
      "name": "Rock_Basalt"
    },
    {
      "x": 10,
      "y": 10,
      "z": 12,
      "name": "Rock_Basalt"
    },
    {
      "x": 10,
      "y": 11,
      "z": 12,
      "name": "Rock_Basalt"
    },
    {
      "x": 10,
      "y": 12,
      "z": 12,
      "name": "Rock_Basalt"
    },
    {
      "x": 10,
      "y": 13,
      "z": 12,
      "name": "Rock_Basalt"
    },
    {
      "x": 10,
      "y": 14,
      "z": 12,
      "name": "Rock_Basalt"
    },
    {
      "x": 10,
      "y": 15,
      "z": 12,
      "name": "Rock_Basalt"
    },
    {
      "x": 10,
      "y": 10,
      "z": 13,
      "name": "Rock_Basalt"
    },
    {
      "x": 10,
      "y": 11,
      "z": 13,
      "name": "Rock_Basalt"
    },
    {
      "x": 10,
      "y": 12,
      "z": 13,
      "name": "Rock_Basalt"
    },
    {
      "x": 11,
      "y": 14,
      "z": 4,
      "name": "Rock_Basalt"
    },
    {
      "x": 11,
      "y": 14,
      "z": 5,
      "name": "Rock_Basalt"
    },
    {
      "x": 11,
      "y": 15,
      "z": 5,
      "name": "Rock_Basalt"
    },
    {
      "x": 11,
      "y": 16,
      "z": 5,
      "name": "Rock_Basalt"
    },
    {
      "x": 11,
      "y": 13,
      "z": 6,
      "name": "Rock_Basalt"
    },
    {
      "x": 11,
      "y": 14,
      "z": 6,
      "name": "Rock_Basalt"
    },
    {
      "x": 11,
      "y": 15,
      "z": 6,
      "name": "Rock_Basalt"
    },
    {
      "x": 11,
      "y": 16,
      "z": 6,
      "name": "Rock_Basalt"
    },
    {
      "x": 11,
      "y": 12,
      "z": 7,
      "name": "Rock_Basalt"
    },
    {
      "x": 11,
      "y": 13,
      "z": 7,
      "name": "Rock_Basalt"
    },
    {
      "x": 11,
      "y": 14,
      "z": 7,
      "name": "Rock_Basalt"
    },
    {
      "x": 11,
      "y": 15,
      "z": 7,
      "name": "Rock_Basalt"
    },
    {
      "x": 11,
      "y": 16,
      "z": 7,
      "name": "Rock_Basalt"
    },
    {
      "x": 11,
      "y": 17,
      "z": 7,
      "name": "Rock_Basalt"
    },
    {
      "x": 11,
      "y": 7,
      "z": 8,
      "name": "Rock_Basalt"
    },
    {
      "x": 11,
      "y": 8,
      "z": 8,
      "name": "Rock_Basalt"
    },
    {
      "x": 11,
      "y": 9,
      "z": 8,
      "name": "Rock_Basalt"
    },
    {
      "x": 11,
      "y": 10,
      "z": 8,
      "name": "Rock_Basalt"
    },
    {
      "x": 11,
      "y": 11,
      "z": 8,
      "name": "Rock_Basalt"
    },
    {
      "x": 11,
      "y": 12,
      "z": 8,
      "name": "Rock_Basalt"
    },
    {
      "x": 11,
      "y": 13,
      "z": 8,
      "name": "Rock_Basalt"
    },
    {
      "x": 11,
      "y": 14,
      "z": 8,
      "name": "Rock_Basalt"
    },
    {
      "x": 11,
      "y": 15,
      "z": 8,
      "name": "Rock_Basalt"
    },
    {
      "x": 11,
      "y": 16,
      "z": 8,
      "name": "Rock_Basalt"
    },
    {
      "x": 11,
      "y": 17,
      "z": 8,
      "name": "Rock_Basalt"
    },
    {
      "x": 11,
      "y": 7,
      "z": 9,
      "name": "Rock_Basalt"
    },
    {
      "x": 11,
      "y": 8,
      "z": 9,
      "name": "Rock_Basalt"
    },
    {
      "x": 11,
      "y": 9,
      "z": 9,
      "name": "Rock_Basalt"
    },
    {
      "x": 11,
      "y": 10,
      "z": 9,
      "name": "Rock_Basalt"
    },
    {
      "x": 11,
      "y": 11,
      "z": 9,
      "name": "Rock_Basalt"
    },
    {
      "x": 11,
      "y": 12,
      "z": 9,
      "name": "Rock_Basalt"
    },
    {
      "x": 11,
      "y": 13,
      "z": 9,
      "name": "Rock_Basalt"
    },
    {
      "x": 11,
      "y": 14,
      "z": 9,
      "name": "Rock_Basalt"
    },
    {
      "x": 11,
      "y": 15,
      "z": 9,
      "name": "Rock_Basalt"
    },
    {
      "x": 11,
      "y": 16,
      "z": 9,
      "name": "Rock_Basalt"
    },
    {
      "x": 11,
      "y": 17,
      "z": 9,
      "name": "Rock_Basalt"
    },
    {
      "x": 11,
      "y": 7,
      "z": 10,
      "name": "Rock_Basalt"
    },
    {
      "x": 11,
      "y": 8,
      "z": 10,
      "name": "Rock_Basalt"
    },
    {
      "x": 11,
      "y": 9,
      "z": 10,
      "name": "Rock_Basalt"
    },
    {
      "x": 11,
      "y": 10,
      "z": 10,
      "name": "Rock_Basalt"
    },
    {
      "x": 11,
      "y": 11,
      "z": 10,
      "name": "Rock_Basalt"
    },
    {
      "x": 11,
      "y": 12,
      "z": 10,
      "name": "Rock_Basalt"
    },
    {
      "x": 11,
      "y": 13,
      "z": 10,
      "name": "Rock_Basalt"
    },
    {
      "x": 11,
      "y": 16,
      "z": 10,
      "name": "Rock_Basalt"
    },
    {
      "x": 11,
      "y": 8,
      "z": 11,
      "name": "Rock_Basalt"
    },
    {
      "x": 11,
      "y": 9,
      "z": 11,
      "name": "Rock_Basalt"
    },
    {
      "x": 11,
      "y": 10,
      "z": 11,
      "name": "Rock_Basalt"
    },
    {
      "x": 11,
      "y": 11,
      "z": 11,
      "name": "Rock_Basalt"
    },
    {
      "x": 11,
      "y": 12,
      "z": 11,
      "name": "Rock_Basalt"
    },
    {
      "x": 11,
      "y": 13,
      "z": 11,
      "name": "Rock_Basalt"
    },
    {
      "x": 11,
      "y": 14,
      "z": 11,
      "name": "Rock_Basalt"
    },
    {
      "x": 11,
      "y": 10,
      "z": 12,
      "name": "Rock_Basalt"
    },
    {
      "x": 11,
      "y": 11,
      "z": 12,
      "name": "Rock_Basalt"
    },
    {
      "x": 11,
      "y": 12,
      "z": 12,
      "name": "Rock_Basalt"
    },
    {
      "x": 11,
      "y": 13,
      "z": 12,
      "name": "Rock_Basalt"
    },
    {
      "x": 11,
      "y": 14,
      "z": 12,
      "name": "Rock_Basalt"
    },
    {
      "x": 12,
      "y": 14,
      "z": 5,
      "name": "Rock_Basalt"
    },
    {
      "x": 12,
      "y": 15,
      "z": 5,
      "name": "Rock_Basalt"
    },
    {
      "x": 12,
      "y": 14,
      "z": 6,
      "name": "Rock_Basalt"
    },
    {
      "x": 12,
      "y": 15,
      "z": 6,
      "name": "Rock_Basalt"
    },
    {
      "x": 12,
      "y": 16,
      "z": 6,
      "name": "Rock_Basalt"
    },
    {
      "x": 12,
      "y": 13,
      "z": 7,
      "name": "Rock_Basalt"
    },
    {
      "x": 12,
      "y": 14,
      "z": 7,
      "name": "Rock_Basalt"
    },
    {
      "x": 12,
      "y": 15,
      "z": 7,
      "name": "Rock_Basalt"
    },
    {
      "x": 12,
      "y": 16,
      "z": 7,
      "name": "Rock_Basalt"
    },
    {
      "x": 12,
      "y": 8,
      "z": 8,
      "name": "Rock_Basalt"
    },
    {
      "x": 12,
      "y": 9,
      "z": 8,
      "name": "Rock_Basalt"
    },
    {
      "x": 12,
      "y": 11,
      "z": 8,
      "name": "Rock_Basalt"
    },
    {
      "x": 12,
      "y": 12,
      "z": 8,
      "name": "Rock_Basalt"
    },
    {
      "x": 12,
      "y": 13,
      "z": 8,
      "name": "Rock_Basalt"
    },
    {
      "x": 12,
      "y": 14,
      "z": 8,
      "name": "Rock_Basalt"
    },
    {
      "x": 12,
      "y": 15,
      "z": 8,
      "name": "Rock_Basalt"
    },
    {
      "x": 12,
      "y": 16,
      "z": 8,
      "name": "Rock_Basalt"
    },
    {
      "x": 12,
      "y": 8,
      "z": 9,
      "name": "Rock_Basalt"
    },
    {
      "x": 12,
      "y": 9,
      "z": 9,
      "name": "Rock_Basalt"
    },
    {
      "x": 12,
      "y": 10,
      "z": 9,
      "name": "Rock_Basalt"
    },
    {
      "x": 12,
      "y": 11,
      "z": 9,
      "name": "Rock_Basalt"
    },
    {
      "x": 12,
      "y": 12,
      "z": 9,
      "name": "Rock_Basalt"
    },
    {
      "x": 12,
      "y": 13,
      "z": 9,
      "name": "Rock_Basalt"
    },
    {
      "x": 12,
      "y": 14,
      "z": 9,
      "name": "Rock_Basalt"
    },
    {
      "x": 12,
      "y": 8,
      "z": 10,
      "name": "Rock_Basalt"
    },
    {
      "x": 12,
      "y": 9,
      "z": 10,
      "name": "Rock_Basalt"
    },
    {
      "x": 12,
      "y": 10,
      "z": 10,
      "name": "Rock_Basalt"
    },
    {
      "x": 12,
      "y": 11,
      "z": 10,
      "name": "Rock_Basalt"
    },
    {
      "x": 12,
      "y": 12,
      "z": 10,
      "name": "Rock_Basalt"
    },
    {
      "x": 12,
      "y": 9,
      "z": 11,
      "name": "Rock_Basalt"
    },
    {
      "x": 12,
      "y": 10,
      "z": 11,
      "name": "Rock_Basalt"
    },
    {
      "x": 12,
      "y": 11,
      "z": 11,
      "name": "Rock_Basalt"
    },
    {
      "x": 13,
      "y": 14,
      "z": 6,
      "name": "Rock_Basalt"
    },
    {
      "x": 13,
      "y": 15,
      "z": 6,
      "name": "Rock_Basalt"
    },
    {
      "x": 13,
      "y": 13,
      "z": 7,
      "name": "Rock_Basalt"
    },
    {
      "x": 13,
      "y": 14,
      "z": 7,
      "name": "Rock_Basalt"
    },
    {
      "x": 13,
      "y": 15,
      "z": 7,
      "name": "Rock_Basalt"
    },
    {
      "x": 13,
      "y": 12,
      "z": 8,
      "name": "Rock_Basalt"
    },
    {
      "x": 13,
      "y": 13,
      "z": 8,
      "name": "Rock_Basalt"
    },
    {
      "x": 13,
      "y": 14,
      "z": 8,
      "name": "Rock_Basalt"
    },
    {
      "x": 13,
      "y": 15,
      "z": 8,
      "name": "Rock_Basalt"
    },
    {
      "x": 13,
      "y": 10,
      "z": 9,
      "name": "Rock_Basalt"
    },
    {
      "x": 13,
      "y": 11,
      "z": 9,
      "name": "Rock_Basalt"
    },
    {
      "x": 13,
      "y": 12,
      "z": 9,
      "name": "Rock_Basalt"
    },
    {
      "x": 13,
      "y": 13,
      "z": 9,
      "name": "Rock_Basalt"
    },
    {
      "x": 13,
      "y": 14,
      "z": 9,
      "name": "Rock_Basalt"
    },
    {
      "x": 13,
      "y": 11,
      "z": 10,
      "name": "Rock_Basalt"
    },
    {
      "x": 13,
      "y": 12,
      "z": 10,
      "name": "Rock_Basalt"
    },
    {
      "x": 13,
      "y": 13,
      "z": 10,
      "name": "Rock_Basalt"
    }
  ]
}