{
  "version": 8,
  "blockIdVersion": 8,
  "anchorX": 9,
  "anchorY": 7,
  "anchorZ": 7,
  "blocks": [
    {
      "x": 5,
      "y": 7,
      "z": 7,
      "name": "Rock_Basalt"
    },
    {
      "x": 5,
      "y": 8,
      "z": 7,
      "name": "Rock_Basalt"
    },
    {
      "x": 5,
      "y": 9,
      "z": 7,
      "name": "Rock_Basalt"
    },
    {
      "x": 5,
      "y": 10,
      "z": 7,
      "name": "Rock_Basalt"
    },
    {
      "x": 5,
      "y": 7,
      "z": 8,
      "name": "Rock_Basalt"
    },
    {
      "x": 5,
      "y": 8,
      "z": 8,
      "name": "Rock_Basalt"
    },
    {
      "x": 5,
      "y": 9,
      "z": 8,
      "name": "Rock_Basalt"
    },
    {
      "x": 5,
      "y": 10,
      "z": 8,
      "name": "Rock_Basalt"
    },
    {
      "x": 5,
      "y": 8,
      "z": 9,
      "name": "Rock_Basalt"
    },
    {
      "x": 5,
      "y": 9,
      "z": 9,
      "name": "Rock_Basalt"
    },
    {
      "x": 6,
      "y": 5,
      "z": 4,
      "name": "Rock_Basalt"
    },
    {
      "x": 6,
      "y": 6,
      "z": 4,
      "name": "Rock_Basalt"
    },
    {
      "x": 6,
      "y": 4,
      "z": 5,
      "name": "Rock_Basalt"
    },
    {
      "x": 6,
      "y": 5,
      "z": 5,
      "name": "Rock_Basalt"
    },
    {
      "x": 6,
      "y": 6,
      "z": 5,
      "name": "Rock_Basalt"
    },
    {
      "x": 6,
      "y": 7,
      "z": 5,
      "name": "Rock_Basalt"
    },
    {
      "x": 6,
      "y": 4,
      "z": 6,
      "name": "Rock_Basalt"
    },
    {
      "x": 6,
      "y": 5,
      "z": 6,
      "name": "Rock_Basalt"
    },
    {
      "x": 6,
      "y": 6,
      "z": 6,
      "name": "Rock_Basalt"
    },
    {
      "x": 6,
      "y": 7,
      "z": 6,
      "name": "Rock_Basalt"
    },
    {
      "x": 6,
      "y": 4,
      "z": 7,
      "name": "Rock_Basalt"
    },
    {
      "x": 6,
      "y": 5,
      "z": 7,
      "name": "Rock_Basalt"
    },
    {
      "x": 6,
      "y": 6,
      "z": 7,
      "name": "Rock_Basalt"
    },
    {
      "x": 6,
      "y": 7,
      "z": 7,
      "name": "Rock_Basalt"
    },
    {
      "x": 6,
      "y": 8,
      "z": 7,
      "name": "Rock_Basalt"
    },
    {
      "x": 6,
      "y": 9,
      "z": 7,
      "name": "Rock_Basalt"
    },
    {
      "x": 6,
      "y": 10,
      "z": 7,
      "name": "Rock_Basalt"
    },
    {
      "x": 6,
      "y": 4,
      "z": 8,
      "name": "Rock_Basalt"
    },
    {
      "x": 6,
      "y": 5,
      "z": 8,
      "name": "Rock_Basalt"
    },
    {
      "x": 6,
      "y": 6,
      "z": 8,
      "name": "Rock_Basalt"
    },
    {
      "x": 6,
      "y": 7,
      "z": 8,
      "name": "Rock_Basalt"
    },
    {
      "x": 6,
      "y": 8,
      "z": 8,
      "name": "Rock_Basalt"
    },
    {
      "x": 6,
      "y": 9,
      "z": 8,
      "name": "Rock_Basalt"
    },
    {
      "x": 6,
      "y": 10,
      "z": 8,
      "name": "Rock_Basalt"
    },
    {
      "x": 6,
      "y": 5,
      "z": 9,
      "name": "Rock_Basalt"
    },
    {
      "x": 6,
      "y": 6,
      "z": 9,
      "name": "Rock_Basalt"
    },
    {
      "x": 6,
      "y": 7,
      "z": 9,
      "name": "Rock_Basalt"
    },
    {
      "x": 6,
      "y": 8,
      "z": 9,
      "name": "Rock_Basalt"
    },
    {
      "x": 6,
      "y": 9,
      "z": 9,
      "name": "Rock_Basalt"
    },
    {
      "x": 6,
      "y": 10,
      "z": 9,
      "name": "Rock_Basalt"
    },
    {
      "x": 6,
      "y": 7,
      "z": 10,
      "name": "Rock_Basalt"
    },
    {
      "x": 6,
      "y": 8,
      "z": 10,
      "name": "Rock_Basalt"
    },
    {
      "x": 6,
      "y": 9,
      "z": 10,
      "name": "Rock_Basalt"
    },
    {
      "x": 6,
      "y": 8,
      "z": 11,
      "name": "Rock_Basalt"
    },
    {
      "x": 6,
      "y": 9,
      "z": 11,
      "name": "Rock_Basalt"
    },
    {
      "x": 7,
      "y": 5,
      "z": 3,
      "name": "Rock_Basalt"
    },
    {
      "x": 7,
      "y": 6,
      "z": 3,
      "name": "Rock_Basalt"
    },
    {
      "x": 7,
      "y": 4,
      "z": 4,
      "name": "Rock_Basalt"
    },
    {
      "x": 7,
      "y": 5,
      "z": 4,
      "name": "Rock_Basalt"
    },
    {
      "x": 7,
      "y": 6,
      "z": 4,
      "name": "Rock_Basalt"
    },
    {
      "x": 7,
      "y": 3,
      "z": 5,
      "name": "Rock_Basalt"
    },
    {
      "x": 7,
      "y": 4,
      "z": 5,
      "name": "Rock_Basalt"
    },
    {
      "x": 7,
      "y": 5,
      "z": 5,
      "name": "Rock_Basalt"
    },
    {
      "x": 7,
      "y": 6,
      "z": 5,
      "name": "Rock_Basalt"
    },
    {
      "x": 7,
      "y": 7,
      "z": 5,
      "name": "Rock_Basalt"
    },
    {
      "x": 7,
      "y": 3,
      "z": 6,
      "name": "Rock_Basalt"
    },
    {
      "x": 7,
      "y": 4,
      "z": 6,
      "name": "Rock_Basalt"
    },
    {
      "x": 7,
      "y": 5,
      "z": 6,
      "name": "Rock_Basalt"
    },
    {
      "x": 7,
      "y": 6,
      "z": 6,
      "name": "Rock_Basalt"
    },
    {
      "x": 7,
      "y": 7,
      "z": 6,
      "name": "Rock_Basalt"
    },
    {
      "x": 7,
      "y": 11,
      "z": 6,
      "name": "Rock_Basalt"
    },
    {
      "x": 7,
      "y": 12,
      "z": 6,
      "name": "Rock_Basalt"
    },
    {
      "x": 7,
      "y": 3,
      "z": 7,
      "name": "Rock_Basalt"
    },
    {
      "x": 7,
      "y": 4,
      "z": 7,
      "name": "Rock_Basalt"
    },
    {
      "x": 7,
      "y": 5,
      "z": 7,
      "name": "Rock_Basalt"
    },
    {
      "x": 7,
      "y": 6,
      "z": 7,
      "name": "Rock_Basalt"
    },
    {
      "x": 7,
      "y": 7,
      "z": 7,
      "name": "Rock_Basalt"
    },
    {
      "x": 7,
      "y": 9,
      "z": 7,
      "name": "Rock_Basalt"
    },
    {
      "x": 7,
      "y": 10,
      "z": 7,
      "name": "Rock_Basalt"
    },
    {
      "x": 7,
      "y": 11,
      "z": 7,
      "name": "Rock_Basalt"
    },
    {
      "x": 7,
      "y": 12,
      "z": 7,
      "name": "Rock_Basalt"
    },
    {
      "x": 7,
      "y": 3,
      "z": 8,
      "name": "Rock_Basalt"
    },
    {
      "x": 7,
      "y": 4,
      "z": 8,
      "name": "Rock_Basalt"
    },
    {
      "x": 7,
      "y": 5,
      "z": 8,
      "name": "Rock_Basalt"
    },
    {
      "x": 7,
      "y": 6,
      "z": 8,
      "name": "Rock_Basalt"
    },
    {
      "x": 7,
      "y": 7,
      "z": 8,
      "name": "Rock_Basalt"
    },
    {
      "x": 7,
      "y": 8,
      "z": 8,
      "name": "Rock_Basalt"
    },
    {
      "x": 7,
      "y": 9,
      "z": 8,
      "name": "Rock_Basalt"
    },
    {
      "x": 7,
      "y": 10,
      "z": 8,
      "name": "Rock_Basalt"
    },
    {
      "x": 7,
      "y": 11,
      "z": 8,
      "name": "Rock_Basalt"
    },
    {
      "x": 7,
      "y": 4,
      "z": 9,
      "name": "Rock_Basalt"
    },
    {
      "x": 7,
      "y": 5,
      "z": 9,
      "name": "Rock_Basalt"
    },
    {
      "x": 7,
      "y": 6,
      "z": 9,
      "name": "Rock_Basalt"
    },
    {
      "x": 7,
      "y": 7,
      "z": 9,
      "name": "Rock_Basalt"
    },
    {
      "x": 7,
      "y": 8,
      "z": 9,
      "name": "Rock_Basalt"
    },
    {
      "x": 7,
      "y": 9,
      "z": 9,
      "name": "Rock_Basalt"
    },
    {
      "x": 7,
      "y": 10,
      "z": 9,
      "name": "Rock_Basalt"
    },
    {
      "x": 7,
      "y": 5,
      "z": 10,
      "name": "Rock_Basalt"
    },
    {
      "x": 7,
      "y": 6,
      "z": 10,
      "name": "Rock_Basalt"
    },
    {
      "x": 7,
      "y": 7,
      "z": 10,
      "name": "Rock_Basalt"
    },
    {
      "x": 7,
      "y": 8,
      "z": 10,
      "name": "Rock_Basalt"
    },
    {
      "x": 7,
      "y": 9,
      "z": 10,
      "name": "Rock_Basalt"
    },
    {
      "x": 7,
      "y": 6,
      "z": 11,
      "name": "Rock_Basalt"
    },
    {
      "x": 7,
      "y": 7,
      "z": 11,
      "name": "Rock_Basalt"
    },
    {
      "x": 7,
      "y": 8,
      "z": 11,
      "name": "Rock_Basalt"
    },
    {
      "x": 7,
      "y": 9,
      "z": 11,
      "name": "Rock_Basalt"
    },
    {
      "x": 7,
      "y": 8,
      "z": 12,
      "name": "Rock_Basalt"
    },
    {
      "x": 8,
      "y": 4,
      "z": 3,
      "name": "Rock_Basalt"
    },
    {
      "x": 8,
      "y": 5,
      "z": 3,
      "name": "Rock_Basalt"
    },
    {
      "x": 8,
      "y": 6,
      "z": 3,
      "name": "Rock_Basalt"
    },
    {
      "x": 8,
      "y": 3,
      "z": 4,
      "name": "Rock_Basalt"
    },
    {
      "x": 8,
      "y": 4,
      "z": 4,
      "name": "Rock_Basalt"
    },
    {
      "x": 8,
      "y": 5,
      "z": 4,
      "name": "Rock_Basalt"
    },
    {
      "x": 8,
      "y": 6,
      "z": 4,
      "name": "Rock_Basalt"
    },
    {
      "x": 8,
      "y": 7,
      "z": 4,
      "name": "Rock_Basalt"
    },
    {
      "x": 8,
      "y": 3,
      "z": 5,
      "name": "Rock_Basalt"
    },
    {
      "x": 8,
      "y": 4,
      "z": 5,
      "name": "Rock_Basalt"
    },
    {
      "x": 8,
      "y": 5,
      "z": 5,
      "name": "Rock_Basalt"
    },
    {
      "x": 8,
      "y": 6,
      "z": 5,
      "name": "Rock_Basalt"
    },
    {
      "x": 8,
      "y": 7,
      "z": 5,
      "name": "Rock_Basalt"
    },
    {
      "x": 8,
      "y": 10,
      "z": 5,
      "name": "Rock_Basalt"
    },
    {
      "x": 8,
      "y": 11,
      "z": 5,
      "name": "Rock_Basalt"
    },
    {
      "x": 8,
      "y": 3,
      "z": 6,
      "name": "Rock_Basalt"
    },
    {
      "x": 8,
      "y": 4,
      "z": 6,
      "name": "Rock_Basalt"
    },
    {
      "x": 8,
      "y": 5,
      "z": 6,
      "name": "Rock_Basalt"
    },
    {
      "x": 8,
      "y": 6,
      "z": 6,
      "name": "Rock_Basalt"
    },
    {
      "x": 8,
      "y": 10,
      "z": 6,
      "name": "Rock_Basalt"
    },
    {
      "x": 8,
      "y": 11,
      "z": 6,
      "name": "Rock_Basalt"
    },
    {
      "x": 8,
      "y": 12,
      "z": 6,
      "name": "Rock_Basalt"
    },
    {
      "x": 8,
      "y": 3,
      "z": 7,
      "name": "Rock_Basalt"
    },
    {
      "x": 8,
      "y": 4,
      "z": 7,
      "name": "Rock_Basalt"
    },
    {
      "x": 8,
      "y": 5,
      "z": 7,
      "name": "Rock_Basalt"
    },
    {
      "x": 8,
      "y": 6,
      "z": 7,
      "name": "Rock_Basalt"
    },
    {
      "x": 8,
      "y": 9,
      "z": 7,
      "name": "Rock_Basalt"
    },
    {
      "x": 8,
      "y": 10,
      "z": 7,
      "name": "Rock_Basalt"
    },
    {
      "x": 8,
      "y": 11,
      "z": 7,
      "name": "Rock_Basalt"
    },
    {
      "x": 8,
      "y": 12,
      "z": 7,
      "name": "Rock_Basalt"
    },
    {
      "x": 8,
      "y": 3,
      "z": 8,
      "name": "Rock_Basalt"
    },
    {
      "x": 8,
      "y": 4,
      "z": 8,
      "name": "Rock_Basalt"
    },
    {
      "x": 8,
      "y": 5,
      "z": 8,
      "name": "Rock_Basalt"
    },
    {
      "x": 8,
      "y": 6,
      "z": 8,
      "name": "Rock_Basalt"
    },
    {
      "x": 8,
      "y": 7,
      "z": 8,
      "name": "Rock_Basalt"
    },
    {
      "x": 8,
      "y": 8,
      "z": 8,
      "name": "Rock_Basalt"
    },
    {
      "x": 8,
      "y": 9,
      "z": 8,
      "name": "Rock_Basalt"
    },
    {
      "x": 8,
      "y": 10,
      "z": 8,
      "name": "Rock_Basalt"
    },
    {
      "x": 8,
      "y": 11,
      "z": 8,
      "name": "Rock_Basalt"
    },
    {
      "x": 8,
      "y": 12,
      "z": 8,
      "name": "Rock_Basalt"
    },
    {
      "x": 8,
      "y": 3,
      "z": 9,
      "name": "Rock_Basalt"
    },
    {
      "x": 8,
      "y": 4,
      "z": 9,
      "name": "Rock_Basalt"
    },
    {
      "x": 8,
      "y": 5,
      "z": 9,
      "name": "Rock_Basalt"
    },
    {
      "x": 8,
      "y": 6,
      "z": 9,
      "name": "Rock_Basalt"
    },
    {
      "x": 8,
      "y": 7,
      "z": 9,
      "name": "Rock_Basalt"
    },
    {
      "x": 8,
      "y": 8,
      "z": 9,
      "name": "Rock_Basalt"
    },
    {
      "x": 8,
      "y": 9,
      "z": 9,
      "name": "Rock_Basalt"
    },
    {
      "x": 8,
      "y": 10,
      "z": 9,
      "name": "Rock_Basalt"
    },
    {
      "x": 8,
      "y": 11,
      "z": 9,
      "name": "Rock_Basalt"
    },
    {
      "x": 8,
      "y": 12,
      "z": 9,
      "name": "Rock_Basalt"
    },
    {
      "x": 8,
      "y": 4,
      "z": 10,
      "name": "Rock_Basalt"
    },
    {
      "x": 8,
      "y": 5,
      "z": 10,
      "name": "Rock_Basalt"
    },
    {
      "x": 8,
      "y": 6,
      "z": 10,
      "name": "Rock_Basalt"
    },
    {
      "x": 8,
      "y": 7,
      "z": 10,
      "name": "Rock_Basalt"
    },
    {
      "x": 8,
      "y": 8,
      "z": 10,
      "name": "Rock_Basalt"
    },
    {
      "x": 8,
      "y": 9,
      "z": 10,
      "name": "Rock_Basalt"
    },
    {
      "x": 8,
      "y": 10,
      "z": 10,
      "name": "Rock_Basalt"
    },
    {
      "x": 8,
      "y": 12,
      "z": 10,
      "name": "Rock_Basalt"
    },
    {
      "x": 8,
      "y": 6,
      "z": 11,
      "name": "Rock_Basalt"
    },
    {
      "x": 8,
      "y": 7,
      "z": 11,
      "name": "Rock_Basalt"
    },
    {
      "x": 8,
      "y": 8,
      "z": 11,
      "name": "Rock_Basalt"
    },
    {
      "x": 8,
      "y": 9,
      "z": 11,
      "name": "Rock_Basalt"
    },
    {
      "x": 8,
      "y": 7,
      "z": 12,
      "name": "Rock_Basalt"
    },
    {
      "x": 8,
      "y": 8,
      "z": 12,
      "name": "Rock_Basalt"
    },
    {
      "x": 9,
      "y": 4,
      "z": 3,
      "name": "Rock_Basalt"
    },
    {
      "x": 9,
      "y": 5,
      "z": 3,
      "name": "Rock_Basalt"
    },
    {
      "x": 9,
      "y": 4,
      "z": 4,
      "name": "Rock_Basalt"
    },
    {
      "x": 9,
      "y": 5,
      "z": 4,
      "name": "Rock_Basalt"
    },
    {
      "x": 9,
      "y": 6,
      "z": 4,
      "name": "Rock_Basalt"
    },
    {
      "x": 9,
      "y": 7,
      "z": 4,
      "name": "Rock_Basalt"
    },
    {
      "x": 9,
      "y": 8,
      "z": 4,
      "name": "Rock_Basalt"
    },
    {
      "x": 9,
      "y": 9,
      "z": 4,
      "name": "Rock_Basalt"
    },
    {
      "x": 9,
      "y": 10,
      "z": 4,
      "name": "Rock_Basalt"
    },
    {
      "x": 9,
      "y": 3,
      "z": 5,
      "name": "Rock_Basalt"
    },
    {
      "x": 9,
      "y": 4,
      "z": 5,
      "name": "Rock_Basalt"
    },
    {
      "x": 9,
      "y": 5,
      "z": 5,
      "name": "Rock_Basalt"
    },
    {
      "x": 9,
      "y": 6,
      "z": 5,
      "name": "Rock_Basalt"
    },
    {
      "x": 9,
      "y": 7,
      "z": 5,
      "name": "Rock_Basalt"
    },
    {
      "x": 9,
      "y": 8,
      "z": 5,
      "name": "Rock_Basalt"
    },
    {
      "x": 9,
      "y": 9,
      "z": 5,
      "name": "Rock_Basalt"
    },
    {
      "x": 9,
      "y": 10,
      "z": 5,
      "name": "Rock_Basalt"
    },
    {
      "x": 9,
      "y": 11,
      "z": 5,
      "name": "Rock_Basalt"
    },
    {
      "x": 9,
      "y": 3,
      "z": 6,
      "name": "Rock_Basalt"
    },
    {
      "x": 9,
      "y": 4,
      "z": 6,
      "name": "Rock_Basalt"
    },
    {
      "x": 9,
      "y": 5,
      "z": 6,
      "name": "Rock_Basalt"
    },
    {
      "x": 9,
      "y": 6,
      "z": 6,
      "name": "Rock_Basalt"
    },
    {
      "x": 9,
      "y": 7,
      "z": 6,
      "name": "Rock_Basalt"
    },
    {
      "x": 9,
      "y": 8,
      "z": 6,
      "name": "Rock_Basalt"
    },
    {
      "x": 9,
      "y": 9,
      "z": 6,
      "name": "Rock_Basalt"
    },
    {
      "x": 9,
      "y": 10,
      "z": 6,
      "name": "Rock_Basalt"
    },
    {
      "x": 9,
      "y": 11,
      "z": 6,
      "name": "Rock_Basalt"
    },
    {
      "x": 9,
      "y": 12,
      "z": 6,
      "name": "Rock_Basalt"
    },
    {
      "x": 9,
      "y": 3,
      "z": 7,
      "name": "Rock_Basalt"
    },
    {
      "x": 9,
      "y": 4,
      "z": 7,
      "name": "Rock_Basalt"
    },
    {
      "x": 9,
      "y": 5,
      "z": 7,
      "name": "Rock_Basalt"
    },
    {
      "x": 9,
      "y": 6,
      "z": 7,
      "name": "Rock_Basalt"
    },
    {
      "x": 9,
      "y": 7,
      "z": 7,
      "name": "Rock_Basalt"
    },
    {
      "x": 9,
      "y": 9,
      "z": 7,
      "name": "Rock_Basalt"
    },
    {
      "x": 9,
      "y": 10,
      "z": 7,
      "name": "Rock_Basalt"
    },
    {
      "x": 9,
      "y": 11,
      "z": 7,
      "name": "Rock_Basalt"
    },
    {
      "x": 9,
      "y": 12,
      "z": 7,
      "name": "Rock_Basalt"
    },
    {
      "x": 9,
      "y": 3,
      "z": 8,
      "name": "Rock_Basalt"
    },
    {
      "x": 9,
      "y": 4,
      "z": 8,
      "name": "Rock_Basalt"
    },
    {
      "x": 9,
      "y": 5,
      "z": 8,
      "name": "Rock_Basalt"
    },
    {
      "x": 9,
      "y": 6,
      "z": 8,
      "name": "Rock_Basalt"
    },
    {
      "x": 9,
      "y": 7,
      "z": 8,
      "name": "Rock_Basalt"
    },
    {
      "x": 9,
      "y": 8,
      "z": 8,
      "name": "Rock_Basalt"
    },
    {
      "x": 9,
      "y": 9,
      "z": 8,
      "name": "Rock_Basalt"
    },
    {
      "x": 9,
      "y": 10,
      "z": 8,
      "name": "Rock_Basalt"
    },
    {
      "x": 9,
      "y": 11,
      "z": 8,
      "name": "Rock_Basalt"
    },
    {
      "x": 9,
      "y": 12,
      "z": 8,
      "name": "Rock_Basalt"
    },
    {
      "x": 9,
      "y": 3,
      "z": 9,
      "name": "Rock_Basalt"
    },
    {
      "x": 9,
      "y": 4,
      "z": 9,
      "name": "Rock_Basalt"
    },
    {
      "x": 9,
      "y": 5,
      "z": 9,
      "name": "Rock_Basalt"
    },
    {
      "x": 9,
      "y": 6,
      "z": 9,
      "name": "Rock_Basalt"
    },
    {
      "x": 9,
      "y": 7,
      "z": 9,
      "name": "Rock_Basalt"
    },
    {
      "x": 9,
      "y": 8,
      "z": 9,
      "name": "Rock_Basalt"
    },
    {
      "x": 9,
      "y": 9,
      "z": 9,
      "name": "Rock_Basalt"
    },
    {
      "x": 9,
      "y": 10,
      "z": 9,
      "name": "Rock_Basalt"
    },
    {
      "x": 9,
      "y": 11,
      "z": 9,
      "name": "Rock_Basalt"
    },
    {
      "x": 9,
      "y": 12,
      "z": 9,
      "name": "Rock_Basalt"
    },
    {
      "x": 9,
      "y": 4,
      "z": 10,
      "name": "Rock_Basalt"
    },
    {
      "x": 9,
      "y": 5,
      "z": 10,
      "name": "Rock_Basalt"
    },
    {
      "x": 9,
      "y": 6,
      "z": 10,
      "name": "Rock_Basalt"
    },
    {
      "x": 9,
      "y": 7,
      "z": 10,
      "name": "Rock_Basalt"
    },
    {
      "x": 9,
      "y": 8,
      "z": 10,
      "name": "Rock_Basalt"
    },
    {
      "x": 9,
      "y": 9,
      "z": 10,
      "name": "Rock_Basalt"
    },
    {
      "x": 9,
      "y": 10,
      "z": 10,
      "name": "Rock_Basalt"
    },
    {
      "x": 9,
      "y": 11,
      "z": 10,
      "name": "Rock_Basalt"
    },
    {
      "x": 9,
      "y": 12,
      "z": 10,
      "name": "Rock_Basalt"
    },
    {
      "x": 9,
      "y": 5,
      "z": 11,
      "name": "Rock_Basalt"
    },
    {
      "x": 9,
      "y": 6,
      "z": 11,
      "name": "Rock_Basalt"
    },
    {
      "x": 9,
      "y": 7,
      "z": 11,
      "name": "Rock_Basalt"
    },
    {
      "x": 9,
      "y": 8,
      "z": 11,
      "name": "Rock_Basalt"
    },
    {
      "x": 9,
      "y": 11,
      "z": 11,
      "name": "Rock_Basalt"
    },
    {
      "x": 9,
      "y": 12,
      "z": 11,
      "name": "Rock_Basalt"
    },
    {
      "x": 9,
      "y": 7,
      "z": 12,
      "name": "Rock_Basalt"
    },
    {
      "x": 9,
      "y": 8,
      "z": 12,
      "name": "Rock_Basalt"
    },
    {
      "x": 10,
      "y": 8,
      "z": 3,
      "name": "Rock_Basalt"
    },
    {
      "x": 10,
      "y": 9,
      "z": 3,
      "name": "Rock_Basalt"
    },
    {
      "x": 10,
      "y": 4,
      "z": 4,
      "name": "Rock_Basalt"
    },
    {
      "x": 10,
      "y": 5,
      "z": 4,
      "name": "Rock_Basalt"
    },
    {
      "x": 10,
      "y": 6,
      "z": 4,
      "name": "Rock_Basalt"
    },
    {
      "x": 10,
      "y": 7,
      "z": 4,
      "name": "Rock_Basalt"
    },
    {
      "x": 10,
      "y": 8,
      "z": 4,
      "name": "Rock_Basalt"
    },
    {
      "x": 10,
      "y": 9,
      "z": 4,
      "name": "Rock_Basalt"
    },
    {
      "x": 10,
      "y": 10,
      "z": 4,
      "name": "Rock_Basalt"
    },
    {
      "x": 10,
      "y": 3,
      "z": 5,
      "name": "Rock_Basalt"
    },
    {
      "x": 10,
      "y": 4,
      "z": 5,
      "name": "Rock_Basalt"
    },
    {
      "x": 10,
      "y": 5,
      "z": 5,
      "name": "Rock_Basalt"
    },
    {
      "x": 10,
      "y": 6,
      "z": 5,
      "name": "Rock_Basalt"
    },
    {
      "x": 10,
      "y": 7,
      "z": 5,
      "name": "Rock_Basalt"
    },
    {
      "x": 10,
      "y": 8,
      "z": 5,
      "name": "Rock_Basalt"
    },
    {
      "x": 10,
      "y": 9,
      "z": 5,
      "name": "Rock_Basalt"
    },
    {
      "x": 10,
      "y": 10,
      "z": 5,
      "name": "Rock_Basalt"
    },
    {
      "x": 10,
      "y": 11,
      "z": 5,
      "name": "Rock_Basalt"
    },
    {
      "x": 10,
      "y": 3,
      "z": 6,
      "name": "Rock_Basalt"
    },
    {
      "x": 10,
      "y": 4,
      "z": 6,
      "name": "Rock_Basalt"
    },
    {
      "x": 10,
      "y": 5,
      "z": 6,
      "name": "Rock_Basalt"
    },
    {
      "x": 10,
      "y": 6,
      "z": 6,
      "name": "Rock_Basalt"
    },
    {
      "x": 10,
      "y": 7,
      "z": 6,
      "name": "Rock_Basalt"
    },
    {
      "x": 10,
      "y": 8,
      "z": 6,
      "name": "Rock_Basalt"
    },
    {
      "x": 10,
      "y": 9,
      "z": 6,
      "name": "Rock_Basalt"
    },
    {
      "x": 10,
      "y": 10,
      "z": 6,
      "name": "Rock_Basalt"
    },
    {
      "x": 10,
      "y": 11,
      "z": 6,
      "name": "Rock_Basalt"
    },
    {
      "x": 10,
      "y": 12,
      "z": 6,
      "name": "Rock_Basalt"
    },
    {
      "x": 10,
      "y": 3,
      "z": 7,
      "name": "Rock_Basalt"
    },
    {
      "x": 10,
      "y": 4,
      "z": 7,
      "name": "Rock_Basalt"
    },
    {
      "x": 10,
      "y": 5,
      "z": 7,
      "name": "Rock_Basalt"
    },
    {
      "x": 10,
      "y": 6,
      "z": 7,
      "name": "Rock_Basalt"
    },
    {
      "x": 10,
      "y": 7,
      "z": 7,
      "name": "Rock_Basalt"
    },
    {
      "x": 10,
      "y": 8,
      "z": 7,
      "name": "Rock_Basalt"
    },
    {
      "x": 10,
      "y": 9,
      "z": 7,
      "name": "Rock_Basalt"
    },
    {
      "x": 10,
      "y": 10,
      "z": 7,
      "name": "Rock_Basalt"
    },
    {
      "x": 10,
      "y": 11,
      "z": 7,
      "name": "Rock_Basalt"
    },
    {
      "x": 10,
      "y": 12,
      "z": 7,
      "name": "Rock_Basalt"
    },
    {
      "x": 10,
      "y": 3,
      "z": 8,
      "name": "Rock_Basalt"
    },
    {
      "x": 10,
      "y": 4,
      "z": 8,
      "name": "Rock_Basalt"
    },
    {
      "x": 10,
      "y": 5,
      "z": 8,
      "name": "Rock_Basalt"
    },
    {
      "x": 10,
      "y": 6,
      "z": 8,
      "name": "Rock_Basalt"
    },
    {
      "x": 10,
      "y": 7,
      "z": 8,
      "name": "Rock_Basalt"
    },
    {
      "x": 10,
      "y": 8,
      "z": 8,
      "name": "Rock_Basalt"
    },
    {
      "x": 10,
      "y": 9,
      "z": 8,
      "name": "Rock_Basalt"
    },
    {
      "x": 10,
      "y": 10,
      "z": 8,
      "name": "Rock_Basalt"
    },
    {
      "x": 10,
      "y": 11,
      "z": 8,
      "name": "Rock_Basalt"
    },
    {
      "x": 10,
      "y": 12,
      "z": 8,
      "name": "Rock_Basalt"
    },
    {
      "x": 10,
      "y": 3,
      "z": 9,
      "name": "Rock_Basalt"
    },
    {
      "x": 10,
      "y": 4,
      "z": 9,
      "name": "Rock_Basalt"
    },
    {
      "x": 10,
      "y": 5,
      "z": 9,
      "name": "Rock_Basalt"
    },
    {
      "x": 10,
      "y": 6,
      "z": 9,
      "name": "Rock_Basalt"
    },
    {
      "x": 10,
      "y": 7,
      "z": 9,
      "name": "Rock_Basalt"
    },
    {
      "x": 10,
      "y": 8,
      "z": 9,
      "name": "Rock_Basalt"
    },
    {
      "x": 10,
      "y": 9,
      "z": 9,
      "name": "Rock_Basalt"
    },
    {
      "x": 10,
      "y": 10,
      "z": 9,
      "name": "Rock_Basalt"
    },
    {
      "x": 10,
      "y": 11,
      "z": 9,
      "name": "Rock_Basalt"
    },
    {
      "x": 10,
      "y": 12,
      "z": 9,
      "name": "Rock_Basalt"
    },
    {
      "x": 10,
      "y": 4,
      "z": 10,
      "name": "Rock_Basalt"
    },
    {
      "x": 10,
      "y": 5,
      "z": 10,
      "name": "Rock_Basalt"
    },
    {
      "x": 10,
      "y": 6,
      "z": 10,
      "name": "Rock_Basalt"
    },
    {
      "x": 10,
      "y": 7,
      "z": 10,
      "name": "Rock_Basalt"
    },
    {
      "x": 10,
      "y": 8,
      "z": 10,
      "name": "Rock_Basalt"
    },
    {
      "x": 10,
      "y": 10,
      "z": 10,
      "name": "Rock_Basalt"
    },
    {
      "x": 10,
      "y": 11,
      "z": 10,
      "name": "Rock_Basalt"
    },
    {
      "x": 10,
      "y": 12,
      "z": 10,
      "name": "Rock_Basalt"
    },
    {
      "x": 10,
      "y": 5,
      "z": 11,
      "name": "Rock_Basalt"
    },
    {
      "x": 10,
      "y": 6,
      "z": 11,
      "name": "Rock_Basalt"
    },
    {
      "x": 10,
      "y": 7,
      "z": 11,
      "name": "Rock_Basalt"
    },
    {
      "x": 10,
      "y": 11,
      "z": 11,
      "name": "Rock_Basalt"
    },
    {
      "x": 10,
      "y": 12,
      "z": 11,
      "name": "Rock_Basalt"
    },
    {
      "x": 11,
      "y": 8,
      "z": 3,
      "name": "Rock_Basalt"
    },
    {
      "x": 11,
      "y": 9,
      "z": 3,
      "name": "Rock_Basalt"
    },
    {
      "x": 11,
      "y": 10,
      "z": 3,
      "name": "Rock_Basalt"
    },
    {
      "x": 11,
      "y": 5,
      "z": 4,
      "name": "Rock_Basalt"
    },
    {
      "x": 11,
      "y": 6,
      "z": 4,
      "name": "Rock_Basalt"
    },
    {
      "x": 11,
      "y": 7,
      "z": 4,
      "name": "Rock_Basalt"
    },
    {
      "x": 11,
      "y": 8,
      "z": 4,
      "name": "Rock_Basalt"
    },
    {
      "x": 11,
      "y": 9,
      "z": 4,
      "name": "Rock_Basalt"
    },
    {
      "x": 11,
      "y": 10,
      "z": 4,
      "name": "Rock_Basalt"
    },
    {
      "x": 11,
      "y": 4,
      "z": 5,
      "name": "Rock_Basalt"
    },
    {
      "x": 11,
      "y": 5,
      "z": 5,
      "name": "Rock_Basalt"
    },
    {
      "x": 11,
      "y": 6,
      "z": 5,
      "name": "Rock_Basalt"
    },
    {
      "x": 11,
      "y": 7,
      "z": 5,
      "name": "Rock_Basalt"
    },
    {
      "x": 11,
      "y": 8,
      "z": 5,
      "name": "Rock_Basalt"
    },
    {
      "x": 11,
      "y": 9,
      "z": 5,
      "name": "Rock_Basalt"
    },
    {
      "x": 11,
      "y": 10,
      "z": 5,
      "name": "Rock_Basalt"
    },
    {
      "x": 11,
      "y": 11,
      "z": 5,
      "name": "Rock_Basalt"
    },
    {
      "x": 11,
      "y": 3,
      "z": 6,
      "name": "Rock_Basalt"
    },
    {
      "x": 11,
      "y": 4,
      "z": 6,
      "name": "Rock_Basalt"
    },
    {
      "x": 11,
      "y": 5,
      "z": 6,
      "name": "Rock_Basalt"
    },
    {
      "x": 11,
      "y": 6,
      "z": 6,
      "name": "Rock_Basalt"
    },
    {
      "x": 11,
      "y": 7,
      "z": 6,
      "name": "Rock_Basalt"
    },
    {
      "x": 11,
      "y": 8,
      "z": 6,
      "name": "Rock_Basalt"
    },
    {
      "x": 11,
      "y": 9,
      "z": 6,
      "name": "Rock_Basalt"
    },
    {
      "x": 11,
      "y": 10,
      "z": 6,
      "name": "Rock_Basalt"
    },
    {
      "x": 11,
      "y": 11,
      "z": 6,
      "name": "Rock_Basalt"
    },
    {
      "x": 11,
      "y": 3,
      "z": 7,
      "name": "Rock_Basalt"
    },
    {
      "x": 11,
      "y": 4,
      "z": 7,
      "name": "Rock_Basalt"
    },
    {
      "x": 11,
      "y": 5,
      "z": 7,
      "name": "Rock_Basalt"
    },
    {
      "x": 11,
      "y": 6,
      "z": 7,
      "name": "Rock_Basalt"
    },
    {
      "x": 11,
      "y": 7,
      "z": 7,
      "name": "Rock_Basalt"
    },
    {
      "x": 11,
      "y": 8,
      "z": 7,
      "name": "Rock_Basalt"
    },
    {
      "x": 11,
      "y": 9,
      "z": 7,
      "name": "Rock_Basalt"
    },
    {
      "x": 11,
      "y": 10,
      "z": 7,
      "name": "Rock_Basalt"
    },
    {
      "x": 11,
      "y": 11,
      "z": 7,
      "name": "Rock_Basalt"
    },
    {
      "x": 11,
      "y": 12,
      "z": 7,
      "name": "Rock_Basalt"
    },
    {
      "x": 11,
      "y": 3,
      "z": 8,
      "name": "Rock_Basalt"
    },
    {
      "x": 11,
      "y": 4,
      "z": 8,
      "name": "Rock_Basalt"
    },
    {
      "x": 11,
      "y": 5,
      "z": 8,
      "name": "Rock_Basalt"
    },
    {
      "x": 11,
      "y": 6,
      "z": 8,
      "name": "Rock_Basalt"
    },
    {
      "x": 11,
      "y": 8,
      "z": 8,
      "name": "Rock_Basalt"
    },
    {
      "x": 11,
      "y": 9,
      "z": 8,
      "name": "Rock_Basalt"
    },
    {
      "x": 11,
      "y": 10,
      "z": 8,
      "name": "Rock_Basalt"
    },
    {
      "x": 11,
      "y": 11,
      "z": 8,
      "name": "Rock_Basalt"
    },
    {
      "x": 11,
      "y": 12,
      "z": 8,
      "name": "Rock_Basalt"
    },
    {
      "x": 11,
      "y": 3,
      "z": 9,
      "name": "Rock_Basalt"
    },
    {
      "x": 11,
      "y": 4,
      "z": 9,
      "name": "Rock_Basalt"
    },
    {
      "x": 11,
      "y": 5,
      "z": 9,
      "name": "Rock_Basalt"
    },
    {
      "x": 11,
      "y": 6,
      "z": 9,
      "name": "Rock_Basalt"
    },
    {
      "x": 11,
      "y": 7,
      "z": 9,
      "name": "Rock_Basalt"
    },
    {
      "x": 11,
      "y": 8,
      "z": 9,
      "name": "Rock_Basalt"
    },
    {
      "x": 11,
      "y": 9,
      "z": 9,
      "name": "Rock_Basalt"
    },
    {
      "x": 11,
      "y": 10,
      "z": 9,
      "name": "Rock_Basalt"
    },
    {
      "x": 11,
      "y": 11,
      "z": 9,
      "name": "Rock_Basalt"
    },
    {
      "x": 11,
      "y": 12,
      "z": 9,
      "name": "Rock_Basalt"
    },
    {
      "x": 11,
      "y": 4,
      "z": 10,
      "name": "Rock_Basalt"
    },
    {
      "x": 11,
      "y": 5,
      "z": 10,
      "name": "Rock_Basalt"
    },
    {
      "x": 11,
      "y": 6,
      "z": 10,
      "name": "Rock_Basalt"
    },
    {
      "x": 11,
      "y": 10,
      "z": 10,
      "name": "Rock_Basalt"
    },
    {
      "x": 11,
      "y": 11,
      "z": 10,
      "name": "Rock_Basalt"
    },
    {
      "x": 11,
      "y": 12,
      "z": 10,
      "name": "Rock_Basalt"
    },
    {
      "x": 12,
      "y": 9,
      "z": 3,
      "name": "Rock_Basalt"
    },
    {
      "x": 12,
      "y": 10,
      "z": 3,
      "name": "Rock_Basalt"
    },
    {
      "x": 12,
      "y": 7,
      "z": 4,
      "name": "Rock_Basalt"
    },
    {
      "x": 12,
      "y": 8,
      "z": 4,
      "name": "Rock_Basalt"
    },
    {
      "x": 12,
      "y": 9,
      "z": 4,
      "name": "Rock_Basalt"
    },
    {
      "x": 12,
      "y": 10,
      "z": 4,
      "name": "Rock_Basalt"
    },
    {
      "x": 12,
      "y": 5,
      "z": 5,
      "name": "Rock_Basalt"
    },
    {
      "x": 12,
      "y": 6,
      "z": 5,
      "name": "Rock_Basalt"
    },
    {
      "x": 12,
      "y": 7,
      "z": 5,
      "name": "Rock_Basalt"
    },
    {
      "x": 12,
      "y": 8,
      "z": 5,
      "name": "Rock_Basalt"
    },
    {
      "x": 12,
      "y": 9,
      "z": 5,
      "name": "Rock_Basalt"
    },
    {
      "x": 12,
      "y": 10,
      "z": 5,
      "name": "Rock_Basalt"
    },
    {
      "x": 12,
      "y": 11,
      "z": 5,
      "name": "Rock_Basalt"
    },
    {
      "x": 12,
      "y": 4,
      "z": 6,
      "name": "Rock_Basalt"
    },
    {
      "x": 12,
      "y": 5,
      "z": 6,
      "name": "Rock_Basalt"
    },
    {
      "x": 12,
      "y": 6,
      "z": 6,
      "name": "Rock_Basalt"
    },
    {
      "x": 12,
      "y": 7,
      "z": 6,
      "name": "Rock_Basalt"
    },
    {
      "x": 12,
      "y": 8,
      "z": 6,
      "name": "Rock_Basalt"
    },
    {
      "x": 12,
      "y": 9,
      "z": 6,
      "name": "Rock_Basalt"
    },
    {
      "x": 12,
      "y": 10,
      "z": 6,
      "name": "Rock_Basalt"
    },
    {
      "x": 12,
      "y": 11,
      "z": 6,
      "name": "Rock_Basalt"
    },
    {
      "x": 12,
      "y": 4,
      "z": 7,
      "name": "Rock_Basalt"
    },
    {
      "x": 12,
      "y": 5,
      "z": 7,
      "name": "Rock_Basalt"
    },
    {
      "x": 12,
      "y": 7,
      "z": 7,
      "name": "Rock_Basalt"
    },
    {
      "x": 12,
      "y": 8,
      "z": 7,
      "name": "Rock_Basalt"
    },
    {
      "x": 12,
      "y": 9,
      "z": 7,
      "name": "Rock_Basalt"
    },
    {
      "x": 12,
      "y": 10,
      "z": 7,
      "name": "Rock_Basalt"
    },
    {
      "x": 12,
      "y": 11,
      "z": 7,
      "name": "Rock_Basalt"
    },
    {
      "x": 12,
      "y": 4,
      "z": 8,
      "name": "Rock_Basalt"
    },
    {
      "x": 12,
      "y": 5,
      "z": 8,
      "name": "Rock_Basalt"
    },
    {
      "x": 12,
      "y": 8,
      "z": 8,
      "name": "Rock_Basalt"
    },
    {
      "x": 12,
      "y": 9,
      "z": 8,
      "name": "Rock_Basalt"
    },
    {
      "x": 12,
      "y": 10,
      "z": 8,
      "name": "Rock_Basalt"
    },
    {
      "x": 12,
      "y": 11,
      "z": 8,
      "name": "Rock_Basalt"
    },
    {
      "x": 12,
      "y": 12,
      "z": 8,
      "name": "Rock_Basalt"
    },
    {
      "x": 12,
      "y": 4,
      "z": 9,
      "name": "Rock_Basalt"
    },
    {
      "x": 12,
      "y": 5,
      "z": 9,
      "name": "Rock_Basalt"
    },
    {
      "x": 12,
      "y": 6,
      "z": 9,
      "name": "Rock_Basalt"
    },
    {
      "x": 12,
      "y": 10,
      "z": 9,
      "name": "Rock_Basalt"
    },
    {
      "x": 12,
      "y": 11,
      "z": 9,
      "name": "Rock_Basalt"
    },
    {
      "x": 12,
      "y": 12,
      "z": 9,
      "name": "Rock_Basalt"
    },
    {
      "x": 12,
      "y": 5,
      "z": 10,
      "name": "Rock_Basalt"
    },
    {
      "x": 12,
      "y": 11,
      "z": 10,
      "name": "Rock_Basalt"
    },
    {
      "x": 13,
      "y": 9,
      "z": 4,
      "name": "Rock_Basalt"
    },
    {
      "x": 13,
      "y": 10,
      "z": 4,
      "name": "Rock_Basalt"
    },
    {
      "x": 13,
      "y": 7,
      "z": 5,
      "name": "Rock_Basalt"
    },
    {
      "x": 13,
      "y": 8,
      "z": 5,
      "name": "Rock_Basalt"
    },
    {
      "x": 13,
      "y": 9,
      "z": 5,
      "name": "Rock_Basalt"
    },
    {
      "x": 13,
      "y": 10,
      "z": 5,
      "name": "Rock_Basalt"
    },
    {
      "x": 13,
      "y": 5,
      "z": 6,
      "name": "Rock_Basalt"
    },
    {
      "x": 13,
      "y": 7,
      "z": 6,
      "name": "Rock_Basalt"
    },
    {
      "x": 13,
      "y": 8,
      "z": 6,
      "name": "Rock_Basalt"
    },
    {
      "x": 13,
      "y": 9,
      "z": 6,
      "name": "Rock_Basalt"
    },
    {
      "x": 13,
      "y": 10,
      "z": 6,
      "name": "Rock_Basalt"
    },
    {
      "x": 13,
      "y": 11,
      "z": 6,
      "name": "Rock_Basalt"
    },
    {
      "x": 13,
      "y": 4,
      "z": 7,
      "name": "Rock_Basalt"
    },
    {
      "x": 13,
      "y": 5,
      "z": 7,
      "name": "Rock_Basalt"
    },
    {
      "x": 13,
      "y": 7,
      "z": 7,
      "name": "Rock_Basalt"
    },
    {
      "x": 13,
      "y": 8,
      "z": 7,
      "name": "Rock_Basalt"
    },
    {
      "x": 13,
      "y": 9,
      "z": 7,
      "name": "Rock_Basalt"
    },
    {
      "x": 13,
      "y": 10,
      "z": 7,
      "name": "Rock_Basalt"
    },
    {
      "x": 13,
      "y": 11,
      "z": 7,
      "name": "Rock_Basalt"
    },
    {
      "x": 13,
      "y": 4,
      "z": 8,
      "name": "Rock_Basalt"
    },
    {
      "x": 13,
      "y": 5,
      "z": 8,
      "name": "Rock_Basalt"
    },
    {
      "x": 13,
      "y": 8,
      "z": 8,
      "name": "Rock_Basalt"
    },
    {
      "x": 13,
      "y": 9,
      "z": 8,
      "name": "Rock_Basalt"
    },
    {
      "x": 13,
      "y": 10,
      "z": 8,
      "name": "Rock_Basalt"
    },
    {
      "x": 13,
      "y": 11,
      "z": 8,
      "name": "Rock_Basalt"
    },
    {
      "x": 13,
      "y": 5,
      "z": 9,
      "name": "Rock_Basalt"
    },
    {
      "x": 13,
      "y": 10,
      "z": 9,
      "name": "Rock_Basalt"
    },
    {
      "x": 14,
      "y": 8,
      "z": 5,
      "name": "Rock_Basalt"
    },
    {
      "x": 14,
      "y": 9,
      "z": 5,
      "name": "Rock_Basalt"
    },
    {
      "x": 14,
      "y": 10,
      "z": 5,
      "name": "Rock_Basalt"
    },
    {
      "x": 14,
      "y": 7,
      "z": 6,
      "name": "Rock_Basalt"
    },
    {
      "x": 14,
      "y": 8,
      "z": 6,
      "name": "Rock_Basalt"
    },
    {
      "x": 14,
      "y": 9,
      "z": 6,
      "name": "Rock_Basalt"
    },
    {
      "x": 14,
      "y": 10,
      "z": 6,
      "name": "Rock_Basalt"
    },
    {
      "x": 14,
      "y": 8,
      "z": 7,
      "name": "Rock_Basalt"
    },
    {
      "x": 14,
      "y": 9,
      "z": 7,
      "name": "Rock_Basalt"
    }
  ]
}