{
  "version": 8,
  "blockIdVersion": 8,
  "anchorX": -2,
  "anchorY": 9,
  "anchorZ": 4,
  "blocks": [
    {
      "x": -4,
      "y": 1,
      "z": -1,
      "name": "Rock_Stone_Cobble"
    },
    {
      "x": -4,
      "y": 2,
      "z": -1,
      "name": "Rock_Stone_Cobble"
    },
    {
      "x": -4,
      "y": 3,
      "z": -1,
      "name": "Rock_Stone_Cobble"
    },
    {
      "x": -4,
      "y": 4,
      "z": -1,
      "name": "Rock_Stone_Cobble"
    },
    {
      "x": -4,
      "y": 5,
      "z": -1,
      "name": "Rock_Stone_Cobble"
    },
    {
      "x": -4,
      "y": 6,
      "z": -1,
      "name": "Rock_Stone_Cobble"
    },
    {
      "x": -4,
      "y": 7,
      "z": -1,
      "name": "Rock_Stone_Cobble"
    },
    {
      "x": -4,
      "y": 1,
      "z": 0,
      "name": "Rock_Stone_Cobble"
    },
    {
      "x": -4,
      "y": 2,
      "z": 0,
      "name": "Rock_Stone_Cobble"
    },
    {
      "x": -4,
      "y": 3,
      "z": 0,
      "name": "Rock_Stone_Cobble"
    },
    {
      "x": -4,
      "y": 4,
      "z": 0,
      "name": "Rock_Stone_Cobble"
    },
    {
      "x": -4,
      "y": 5,
      "z": 0,
      "name": "Rock_Stone_Cobble"
    },
    {
      "x": -4,
      "y": 6,
      "z": 0,
      "name": "Rock_Stone_Cobble"
    },
    {
      "x": -4,
      "y": 7,
      "z": 0,
      "name": "Rock_Stone_Cobble"
    },
    {
      "x": -4,
      "y": 8,
      "z": 0,
      "name": "Rock_Stone_Cobble"
    },
    {
      "x": -4,
      "y": 1,
      "z": 1,
      "name": "Rock_Stone_Cobble"
    },
    {
      "x": -4,
      "y": 2,
      "z": 1,
      "name": "Rock_Stone_Cobble"
    },
    {
      "x": -4,
      "y": 3,
      "z": 1,
      "name": "Rock_Stone_Cobble"
    },
    {
      "x": -4,
      "y": 4,
      "z": 1,
      "name": "Rock_Stone_Cobble"
    },
    {
      "x": -4,
      "y": 5,
      "z": 1,
      "name": "Rock_Stone_Cobble"
    },
    {
      "x": -4,
      "y": 6,
      "z": 1,
      "name": "Rock_Stone_Cobble"
    },
    {
      "x": -4,
      "y": 7,
      "z": 1,
      "name": "Rock_Stone_Cobble"
    },
    {
      "x": -4,
      "y": 8,
      "z": 1,
      "name": "Rock_Stone_Cobble"
    },
    {
      "x": -4,
      "y": 9,
      "z": 1,
      "name": "Rock_Stone_Cobble"
    },
    {
      "x": -4,
      "y": 1,
      "z": 2,
      "name": "Rock_Stone_Cobble"
    },
    {
      "x": -4,
      "y": 2,
      "z": 2,
      "name": "Rock_Stone_Cobble"
    },
    {
      "x": -4,
      "y": 3,
      "z": 2,
      "name": "Rock_Stone_Cobble"
    },
    {
      "x": -4,
      "y": 4,
      "z": 2,
      "name": "Rock_Stone_Cobble"
    },
    {
      "x": -4,
      "y": 5,
      "z": 2,
      "name": "Rock_Stone_Cobble"
    },
    {
      "x": -4,
      "y": 6,
      "z": 2,
      "name": "Rock_Stone_Cobble"
    },
    {
      "x": -4,
      "y": 7,
      "z": 2,
      "name": "Rock_Stone_Cobble"
    },
    {
      "x": -4,
      "y": 8,
      "z": 2,
      "name": "Rock_Stone_Cobble"
    },
    {
      "x": -4,
      "y": 9,
      "z": 2,
      "name": "Rock_Stone_Cobble"
    },
    {
      "x": -4,
      "y": 10,
      "z": 2,
      "name": "Rock_Stone_Cobble"
    },
    {
      "x": -4,
      "y": 1,
      "z": 3,
      "name": "Rock_Stone_Cobble"
    },
    {
      "x": -4,
      "y": 2,
      "z": 3,
      "name": "Rock_Stone_Cobble"
    },
    {
      "x": -4,
      "y": 3,
      "z": 3,
      "name": "Rock_Stone_Cobble"
    },
    {
      "x": -4,
      "y": 4,
      "z": 3,
      "name": "Rock_Stone_Cobble"
    },
    {
      "x": -4,
      "y": 5,
      "z": 3,
      "name": "Rock_Stone_Cobble"
    },
    {
      "x": -4,
      "y": 6,
      "z": 3,
      "name": "Rock_Stone_Cobble"
    },
    {
      "x": -4,
      "y": 7,
      "z": 3,
      "name": "Rock_Stone_Cobble"
    },
    {
      "x": -4,
      "y": 8,
      "z": 3,
      "name": "Rock_Stone_Cobble"
    },
    {
      "x": -4,
      "y": 9,
      "z": 3,
      "name": "Rock_Stone_Cobble"
    },
    {
      "x": -4,
      "y": 10,
      "z": 3,
      "name": "Rock_Stone_Cobble"
    },
    {
      "x": -4,
      "y": 0,
      "z": 4,
      "name": "Rock_Stone_Cobble"
    },
    {
      "x": -4,
      "y": 1,
      "z": 4,
      "name": "Rock_Stone_Cobble"
    },
    {
      "x": -4,
      "y": 2,
      "z": 4,
      "name": "Rock_Stone_Cobble"
    },
    {
      "x": -4,
      "y": 3,
      "z": 4,
      "name": "Rock_Stone_Cobble"
    },
    {
      "x": -4,
      "y": 4,
      "z": 4,
      "name": "Rock_Stone_Cobble"
    },
    {
      "x": -4,
      "y": 5,
      "z": 4,
      "name": "Rock_Stone_Cobble"
    },
    {
      "x": -4,
      "y": 6,
      "z": 4,
      "name": "Rock_Stone_Cobble"
    },
    {
      "x": -4,
      "y": 7,
      "z": 4,
      "name": "Rock_Stone_Cobble"
    },
    {
      "x": -4,
      "y": 8,
      "z": 4,
      "name": "Rock_Stone_Cobble"
    },
    {
      "x": -4,
      "y": 9,
      "z": 4,
      "name": "Rock_Stone_Cobble"
    },
    {
      "x": -4,
      "y": 10,
      "z": 4,
      "name": "Rock_Stone_Cobble"
    },
    {
      "x": -4,
      "y": 11,
      "z": 4,
      "name": "Rock_Stone_Cobble"
    },
    {
      "x": -3,
      "y": 1,
      "z": -1,
      "name": "Rock_Stone_Cobble"
    },
    {
      "x": -3,
      "y": 2,
      "z": -1,
      "name": "Wood_Hardwood_Stairs",
      "rotation": 2
    },
    {
      "x": -3,
      "y": 3,
      "z": -1,
      "name": "Empty"
    },
    {
      "x": -3,
      "y": 4,
      "z": -1,
      "name": "Empty"
    },
    {
      "x": -3,
      "y": 5,
      "z": -1,
      "name": "Empty"
    },
    {
      "x": -3,
      "y": 6,
      "z": -1,
      "name": "Empty"
    },
    {
      "x": -3,
      "y": 7,
      "z": -1,
      "name": "Rock_Stone_Cobble"
    },
    {
      "x": -3,
      "y": 1,
      "z": 0,
      "name": "Rock_Stone_Cobble"
    },
    {
      "x": -3,
      "y": 2,
      "z": 0,
      "name": "Wood_Hardwood_Planks"
    },
    {
      "x": -3,
      "y": 3,
      "z": 0,
      "name": "Wood_Hardwood_Stairs",
      "rotation": 2
    },
    {
      "x": -3,
      "y": 4,
      "z": 0,
      "name": "Empty"
    },
    {
      "x": -3,
      "y": 5,
      "z": 0,
      "name": "Empty"
    },
    {
      "x": -3,
      "y": 6,
      "z": 0,
      "name": "Empty"
    },
    {
      "x": -3,
      "y": 7,
      "z": 0,
      "name": "Empty"
    },
    {
      "x": -3,
      "y": 8,
      "z": 0,
      "name": "Rock_Stone_Cobble"
    },
    {
      "x": -3,
      "y": 1,
      "z": 1,
      "name": "Rock_Stone_Cobble"
    },
    {
      "x": -3,
      "y": 2,
      "z": 1,
      "name": "Wood_Hardwood_Planks"
    },
    {
      "x": -3,
      "y": 3,
      "z": 1,
      "name": "Wood_Hardwood_Planks"
    },
    {
      "x": -3,
      "y": 4,
      "z": 1,
      "name": "Wood_Hardwood_Stairs",
      "rotation": 2
    },
    {
      "x": -3,
      "y": 5,
      "z": 1,
      "name": "Empty"
    },
    {
      "x": -3,
      "y": 6,
      "z": 1,
      "name": "Empty"
    },
    {
      "x": -3,
      "y": 7,
      "z": 1,
      "name": "Empty"
    },
    {
      "x": -3,
      "y": 8,
      "z": 1,
      "name": "Empty"
    },
    {
      "x": -3,
      "y": 9,
      "z": 1,
      "name": "Rock_Stone_Cobble"
    },
    {
      "x": -3,
      "y": 1,
      "z": 2,
      "name": "Rock_Stone_Cobble"
    },
    {
      "x": -3,
      "y": 2,
      "z": 2,
      "name": "Wood_Hardwood_Planks"
    },
    {
      "x": -3,
      "y": 3,
      "z": 2,
      "name": "Wood_Hardwood_Planks"
    },
    {
      "x": -3,
      "y": 4,
      "z": 2,
      "name": "Wood_Hardwood_Planks"
    },
    {
      "x": -3,
      "y": 5,
      "z": 2,
      "name": "Wood_Hardwood_Stairs",
      "rotation": 2
    },
    {
      "x": -3,
      "y": 6,
      "z": 2,
      "name": "Empty"
    },
    {
      "x": -3,
      "y": 7,
      "z": 2,
      "name": "Empty"
    },
    {
      "x": -3,
      "y": 8,
      "z": 2,
      "name": "Empty"
    },
    {
      "x": -3,
      "y": 9,
      "z": 2,
      "name": "Rock_Stone_Cobble"
    },
    {
      "x": -3,
      "y": 10,
      "z": 2,
      "name": "Rock_Stone_Cobble"
    },
    {
      "x": -3,
      "y": 1,
      "z": 3,
      "name": "Rock_Stone_Cobble"
    },
    {
      "x": -3,
      "y": 2,
      "z": 3,
      "name": "Wood_Hardwood_Planks"
    },
    {
      "x": -3,
      "y": 3,
      "z": 3,
      "name": "Wood_Hardwood_Planks"
    },
    {
      "x": -3,
      "y": 4,
      "z": 3,
      "name": "Wood_Hardwood_Planks"
    },
    {
      "x": -3,
      "y": 5,
      "z": 3,
      "name": "Wood_Hardwood_Planks"
    },
    {
      "x": -3,
      "y": 6,
      "z": 3,
      "name": "Wood_Hardwood_Stairs",
      "rotation": 2
    },
    {
      "x": -3,
      "y": 7,
      "z": 3,
      "name": "Empty"
    },
    {
      "x": -3,
      "y": 8,
      "z": 3,
      "name": "Empty"
    },
    {
      "x": -3,
      "y": 9,
      "z": 3,
      "name": "Empty"
    },
    {
      "x": -3,
      "y": 10,
      "z": 3,
      "name": "Rock_Stone_Cobble"
    },
    {
      "x": -3,
      "y": 11,
      "z": 3,
      "name": "Rock_Stone_Cobble"
    },
    {
      "x": -3,
      "y": 1,
      "z": 4,
      "name": "Rock_Stone_Cobble"
    },
    {
      "x": -3,
      "y": 2,
      "z": 4,
      "name": "Wood_Hardwood_Planks"
    },
    {
      "x": -3,
      "y": 3,
      "z": 4,
      "name": "Wood_Hardwood_Planks"
    },
    {
      "x": -3,
      "y": 4,
      "z": 4,
      "name": "Wood_Hardwood_Planks"
    },
    {
      "x": -3,
      "y": 5,
      "z": 4,
      "name": "Wood_Hardwood_Planks"
    },
    {
      "x": -3,
      "y": 6,
      "z": 4,
      "name": "Wood_Hardwood_Planks"
    },
    {
      "x": -3,
      "y": 7,
      "z": 4,
      "name": "Wood_Hardwood_Stairs",
      "rotation": 2
    },
    {
      "x": -3,
      "y": 8,
      "z": 4,
      "name": "Empty"
    },
    {
      "x": -3,
      "y": 9,
      "z": 4,
      "name": "Empty"
    },
    {
      "x": -3,
      "y": 10,
      "z": 4,
      "name": "Empty"
    },
    {
      "x": -3,
      "y": 11,
      "z": 4,
      "name": "Rock_Stone_Cobble"
    },
    {
      "x": -2,
      "y": 1,
      "z": -1,
      "name": "Rock_Stone_Cobble"
    },
    {
      "x": -2,
      "y": 2,
      "z": -1,
      "name": "Wood_Hardwood_Stairs",
      "rotation": 2
    },
    {
      "x": -2,
      "y": 3,
      "z": -1,
      "name": "Empty"
    },
    {
      "x": -2,
      "y": 4,
      "z": -1,
      "name": "Empty"
    },
    {
      "x": -2,
      "y": 5,
      "z": -1,
      "name": "Empty"
    },
    {
      "x": -2,
      "y": 6,
      "z": -1,
      "name": "Empty"
    },
    {
      "x": -2,
      "y": 7,
      "z": -1,
      "name": "Rock_Stone_Cobble"
    },
    {
      "x": -2,
      "y": 1,
      "z": 0,
      "name": "Rock_Stone_Cobble"
    },
    {
      "x": -2,
      "y": 2,
      "z": 0,
      "name": "Wood_Hardwood_Planks"
    },
    {
      "x": -2,
      "y": 3,
      "z": 0,
      "name": "Wood_Hardwood_Stairs",
      "rotation": 2
    },
    {
      "x": -2,
      "y": 4,
      "z": 0,
      "name": "Empty"
    },
    {
      "x": -2,
      "y": 5,
      "z": 0,
      "name": "Empty"
    },
    {
      "x": -2,
      "y": 6,
      "z": 0,
      "name": "Empty"
    },
    {
      "x": -2,
      "y": 7,
      "z": 0,
      "name": "Empty"
    },
    {
      "x": -2,
      "y": 8,
      "z": 0,
      "name": "Rock_Stone_Cobble"
    },
    {
      "x": -2,
      "y": 1,
      "z": 1,
      "name": "Rock_Stone_Cobble"
    },
    {
      "x": -2,
      "y": 2,
      "z": 1,
      "name": "Wood_Hardwood_Planks"
    },
    {
      "x": -2,
      "y": 3,
      "z": 1,
      "name": "Wood_Hardwood_Planks"
    },
    {
      "x": -2,
      "y": 4,
      "z": 1,
      "name": "Wood_Hardwood_Stairs",
      "rotation": 2
    },
    {
      "x": -2,
      "y": 5,
      "z": 1,
      "name": "Empty"
    },
    {
      "x": -2,
      "y": 6,
      "z": 1,
      "name": "Empty"
    },
    {
      "x": -2,
      "y": 7,
      "z": 1,
      "name": "Empty"
    },
    {
      "x": -2,
      "y": 8,
      "z": 1,
      "name": "Empty"
    },
    {
      "x": -2,
      "y": 9,
      "z": 1,
      "name": "Rock_Stone_Cobble"
    },
    {
      "x": -2,
      "y": 1,
      "z": 2,
      "name": "Rock_Stone_Cobble"
    },
    {
      "x": -2,
      "y": 2,
      "z": 2,
      "name": "Wood_Hardwood_Planks"
    },
    {
      "x": -2,
      "y": 3,
      "z": 2,
      "name": "Wood_Hardwood_Planks"
    },
    {
      "x": -2,
      "y": 4,
      "z": 2,
      "name": "Wood_Hardwood_Planks"
    },
    {
      "x": -2,
      "y": 5,
      "z": 2,
      "name": "Wood_Hardwood_Stairs",
      "rotation": 2
    },
    {
      "x": -2,
      "y": 6,
      "z": 2,
      "name": "Empty"
    },
    {
      "x": -2,
      "y": 7,
      "z": 2,
      "name": "Empty"
    },
    {
      "x": -2,
      "y": 8,
      "z": 2,
      "name": "Empty"
    },
    {
      "x": -2,
      "y": 9,
      "z": 2,
      "name": "Empty"
    },
    {
      "x": -2,
      "y": 10,
      "z": 2,
      "name": "Rock_Stone_Cobble"
    },
    {
      "x": -2,
      "y": 1,
      "z": 3,
      "name": "Rock_Stone_Cobble"
    },
    {
      "x": -2,
      "y": 2,
      "z": 3,
      "name": "Wood_Hardwood_Planks"
    },
    {
      "x": -2,
      "y": 3,
      "z": 3,
      "name": "Wood_Hardwood_Planks"
    },
    {
      "x": -2,
      "y": 4,
      "z": 3,
      "name": "Wood_Hardwood_Planks"
    },
    {
      "x": -2,
      "y": 5,
      "z": 3,
      "name": "Wood_Hardwood_Planks"
    },
    {
      "x": -2,
      "y": 6,
      "z": 3,
      "name": "Wood_Hardwood_Stairs",
      "rotation": 2
    },
    {
      "x": -2,
      "y": 7,
      "z": 3,
      "name": "Empty"
    },
    {
      "x": -2,
      "y": 8,
      "z": 3,
      "name": "Empty"
    },
    {
      "x": -2,
      "y": 9,
      "z": 3,
      "name": "Empty"
    },
    {
      "x": -2,
      "y": 10,
      "z": 3,
      "name": "Empty"
    },
    {
      "x": -2,
      "y": 11,
      "z": 3,
      "name": "Rock_Stone_Cobble"
    },
    {
      "x": -2,
      "y": 1,
      "z": 4,
      "name": "Rock_Stone_Cobble"
    },
    {
      "x": -2,
      "y": 2,
      "z": 4,
      "name": "Wood_Hardwood_Planks"
    },
    {
      "x": -2,
      "y": 3,
      "z": 4,
      "name": "Wood_Hardwood_Planks"
    },
    {
      "x": -2,
      "y": 4,
      "z": 4,
      "name": "Wood_Hardwood_Planks"
    },
    {
      "x": -2,
      "y": 5,
      "z": 4,
      "name": "Wood_Hardwood_Planks"
    },
    {
      "x": -2,
      "y": 6,
      "z": 4,
      "name": "Wood_Hardwood_Planks"
    },
    {
      "x": -2,
      "y": 7,
      "z": 4,
      "name": "Wood_Hardwood_Stairs",
      "rotation": 2
    },
    {
      "x": -2,
      "y": 8,
      "z": 4,
      "name": "Empty"
    },
    {
      "x": -2,
      "y": 9,
      "z": 4,
      "name": "Empty"
    },
    {
      "x": -2,
      "y": 10,
      "z": 4,
      "name": "Empty"
    },
    {
      "x": -2,
      "y": 11,
      "z": 4,
      "name": "Rock_Stone_Cobble"
    },
    {
      "x": -1,
      "y": 1,
      "z": -1,
      "name": "Rock_Stone_Cobble"
    },
    {
      "x": -1,
      "y": 2,
      "z": -1,
      "name": "Wood_Hardwood_Stairs",
      "rotation": 2
    },
    {
      "x": -1,
      "y": 3,
      "z": -1,
      "name": "Empty"
    },
    {
      "x": -1,
      "y": 4,
      "z": -1,
      "name": "Empty"
    },
    {
      "x": -1,
      "y": 5,
      "z": -1,
      "name": "Empty"
    },
    {
      "x": -1,
      "y": 6,
      "z": -1,
      "name": "Rock_Stone_Cobble"
    },
    {
      "x": -1,
      "y": 7,
      "z": -1,
      "name": "Rock_Stone_Cobble"
    },
    {
      "x": -1,
      "y": 1,
      "z": 0,
      "name": "Rock_Stone_Cobble"
    },
    {
      "x": -1,
      "y": 2,
      "z": 0,
      "name": "Wood_Hardwood_Planks"
    },
    {
      "x": -1,
      "y": 3,
      "z": 0,
      "name": "Wood_Hardwood_Stairs",
      "rotation": 2
    },
    {
      "x": -1,
      "y": 4,
      "z": 0,
      "name": "Empty"
    },
    {
      "x": -1,
      "y": 5,
      "z": 0,
      "name": "Empty"
    },
    {
      "x": -1,
      "y": 6,
      "z": 0,
      "name": "Empty"
    },
    {
      "x": -1,
      "y": 7,
      "z": 0,
      "name": "Empty"
    },
    {
      "x": -1,
      "y": 8,
      "z": 0,
      "name": "Rock_Stone_Cobble"
    },
    {
      "x": -1,
      "y": 1,
      "z": 1,
      "name": "Rock_Stone_Cobble"
    },
    {
      "x": -1,
      "y": 2,
      "z": 1,
      "name": "Wood_Hardwood_Planks"
    },
    {
      "x": -1,
      "y": 3,
      "z": 1,
      "name": "Wood_Hardwood_Planks"
    },
    {
      "x": -1,
      "y": 4,
      "z": 1,
      "name": "Wood_Hardwood_Stairs",
      "rotation": 2
    },
    {
      "x": -1,
      "y": 5,
      "z": 1,
      "name": "Empty"
    },
    {
      "x": -1,
      "y": 6,
      "z": 1,
      "name": "Empty"
    },
    {
      "x": -1,
      "y": 7,
      "z": 1,
      "name": "Empty"
    },
    {
      "x": -1,
      "y": 8,
      "z": 1,
      "name": "Rock_Stone_Cobble"
    },
    {
      "x": -1,
      "y": 9,
      "z": 1,
      "name": "Rock_Stone_Cobble"
    },
    {
      "x": -1,
      "y": 1,
      "z": 2,
      "name": "Rock_Stone_Cobble"
    },
    {
      "x": -1,
      "y": 2,
      "z": 2,
      "name": "Wood_Hardwood_Planks"
    },
    {
      "x": -1,
      "y": 3,
      "z": 2,
      "name": "Wood_Hardwood_Planks"
    },
    {
      "x": -1,
      "y": 4,
      "z": 2,
      "name": "Wood_Hardwood_Planks"
    },
    {
      "x": -1,
      "y": 5,
      "z": 2,
      "name": "Wood_Hardwood_Stairs",
      "rotation": 2
    },
    {
      "x": -1,
      "y": 6,
      "z": 2,
      "name": "Empty"
    },
    {
      "x": -1,
      "y": 7,
      "z": 2,
      "name": "Empty"
    },
    {
      "x": -1,
      "y": 8,
      "z": 2,
      "name": "Empty"
    },
    {
      "x": -1,
      "y": 9,
      "z": 2,
      "name": "Rock_Stone_Cobble"
    },
    {
      "x": -1,
      "y": 10,
      "z": 2,
      "name": "Rock_Stone_Cobble"
    },
    {
      "x": -1,
      "y": 1,
      "z": 3,
      "name": "Rock_Stone_Cobble"
    },
    {
      "x": -1,
      "y": 2,
      "z": 3,
      "name": "Wood_Hardwood_Planks"
    },
    {
      "x": -1,
      "y": 3,
      "z": 3,
      "name": "Wood_Hardwood_Planks"
    },
    {
      "x": -1,
      "y": 4,
      "z": 3,
      "name": "Wood_Hardwood_Planks"
    },
    {
      "x": -1,
      "y": 5,
      "z": 3,
      "name": "Wood_Hardwood_Planks"
    },
    {
      "x": -1,
      "y": 6,
      "z": 3,
      "name": "Wood_Hardwood_Stairs",
      "rotation": 2
    },
    {
      "x": -1,
      "y": 7,
      "z": 3,
      "name": "Empty"
    },
    {
      "x": -1,
      "y": 8,
      "z": 3,
      "name": "Empty"
    },
    {
      "x": -1,
      "y": 9,
      "z": 3,
      "name": "Empty"
    },
    {
      "x": -1,
      "y": 10,
      "z": 3,
      "name": "Empty"
    },
    {
      "x": -1,
      "y": 11,
      "z": 3,
      "name": "Rock_Stone_Cobble"
    },
    {
      "x": -1,
      "y": 1,
      "z": 4,
      "name": "Rock_Stone_Cobble"
    },
    {
      "x": -1,
      "y": 2,
      "z": 4,
      "name": "Wood_Hardwood_Planks"
    },
    {
      "x": -1,
      "y": 3,
      "z": 4,
      "name": "Wood_Hardwood_Planks"
    },
    {
      "x": -1,
      "y": 4,
      "z": 4,
      "name": "Wood_Hardwood_Planks"
    },
    {
      "x": -1,
      "y": 5,
      "z": 4,
      "name": "Wood_Hardwood_Planks"
    },
    {
      "x": -1,
      "y": 6,
      "z": 4,
      "name": "Wood_Hardwood_Planks"
    },
    {
      "x": -1,
      "y": 7,
      "z": 4,
      "name": "Wood_Hardwood_Stairs",
      "rotation": 2
    },
    {
      "x": -1,
      "y": 8,
      "z": 4,
      "name": "Empty"
    },
    {
      "x": -1,
      "y": 9,
      "z": 4,
      "name": "Empty"
    },
    {
      "x": -1,
      "y": 10,
      "z": 4,
      "name": "Empty"
    },
    {
      "x": -1,
      "y": 11,
      "z": 4,
      "name": "Rock_Stone_Cobble"
    },
    {
      "x": 0,
      "y": 1,
      "z": -1,
      "name": "Rock_Stone_Cobble"
    },
    {
      "x": 0,
      "y": 2,
      "z": -1,
      "name": "Rock_Stone_Cobble"
    },
    {
      "x": 0,
      "y": 3,
      "z": -1,
      "name": "Rock_Stone_Cobble"
    },
    {
      "x": 0,
      "y": 4,
      "z": -1,
      "name": "Rock_Stone_Cobble"
    },
    {
      "x": 0,
      "y": 5,
      "z": -1,
      "name": "Rock_Stone_Cobble"
    },
    {
      "x": 0,
      "y": 6,
      "z": -1,
      "name": "Rock_Stone_Cobble"
    },
    {
      "x": 0,
      "y": 7,
      "z": -1,
      "name": "Rock_Stone_Cobble"
    },
    {
      "x": 0,
      "y": 1,
      "z": 0,
      "name": "Rock_Stone_Cobble"
    },
    {
      "x": 0,
      "y": 2,
      "z": 0,
      "name": "Rock_Stone_Cobble"
    },
    {
      "x": 0,
      "y": 3,
      "z": 0,
      "name": "Rock_Stone_Cobble"
    },
    {
      "x": 0,
      "y": 4,
      "z": 0,
      "name": "Rock_Stone_Cobble"
    },
    {
      "x": 0,
      "y": 5,
      "z": 0,
      "name": "Rock_Stone_Cobble"
    },
    {
      "x": 0,
      "y": 6,
      "z": 0,
      "name": "Rock_Stone_Cobble"
    },
    {
      "x": 0,
      "y": 7,
      "z": 0,
      "name": "Rock_Stone_Cobble"
    },
    {
      "x": 0,
      "y": 8,
      "z": 0,
      "name": "Rock_Stone_Cobble"
    },
    {
      "x": 0,
      "y": 1,
      "z": 1,
      "name": "Rock_Stone_Cobble"
    },
    {
      "x": 0,
      "y": 2,
      "z": 1,
      "name": "Rock_Stone_Cobble"
    },
    {
      "x": 0,
      "y": 3,
      "z": 1,
      "name": "Rock_Stone_Cobble"
    },
    {
      "x": 0,
      "y": 4,
      "z": 1,
      "name": "Rock_Stone_Cobble"
    },
    {
      "x": 0,
      "y": 5,
      "z": 1,
      "name": "Rock_Stone_Cobble"
    },
    {
      "x": 0,
      "y": 6,
      "z": 1,
      "name": "Rock_Stone_Cobble"
    },
    {
      "x": 0,
      "y": 7,
      "z": 1,
      "name": "Rock_Stone_Cobble"
    },
    {
      "x": 0,
      "y": 8,
      "z": 1,
      "name": "Rock_Stone_Cobble"
    },
    {
      "x": 0,
      "y": 9,
      "z": 1,
      "name": "Rock_Stone_Cobble"
    },
    {
      "x": 0,
      "y": 1,
      "z": 2,
      "name": "Rock_Stone_Cobble"
    },
    {
      "x": 0,
      "y": 2,
      "z": 2,
      "name": "Rock_Stone_Cobble"
    },
    {
      "x": 0,
      "y": 3,
      "z": 2,
      "name": "Rock_Stone_Cobble"
    },
    {
      "x": 0,
      "y": 4,
      "z": 2,
      "name": "Rock_Stone_Cobble"
    },
    {
      "x": 0,
      "y": 5,
      "z": 2,
      "name": "Rock_Stone_Cobble"
    },
    {
      "x": 0,
      "y": 6,
      "z": 2,
      "name": "Rock_Stone_Cobble"
    },
    {
      "x": 0,
      "y": 7,
      "z": 2,
      "name": "Rock_Stone_Cobble"
    },
    {
      "x": 0,
      "y": 8,
      "z": 2,
      "name": "Rock_Stone_Cobble"
    },
    {
      "x": 0,
      "y": 9,
      "z": 2,
      "name": "Rock_Stone_Cobble"
    },
    {
      "x": 0,
      "y": 1,
      "z": 3,
      "name": "Rock_Stone_Cobble"
    },
    {
      "x": 0,
      "y": 2,
      "z": 3,
      "name": "Rock_Stone_Cobble"
    },
    {
      "x": 0,
      "y": 3,
      "z": 3,
      "name": "Rock_Stone_Cobble"
    },
    {
      "x": 0,
      "y": 4,
      "z": 3,
      "name": "Rock_Stone_Cobble"
    },
    {
      "x": 0,
      "y": 5,
      "z": 3,
      "name": "Rock_Stone_Cobble"
    },
    {
      "x": 0,
      "y": 6,
      "z": 3,
      "name": "Rock_Stone_Cobble"
    },
    {
      "x": 0,
      "y": 7,
      "z": 3,
      "name": "Rock_Stone_Cobble"
    },
    {
      "x": 0,
      "y": 8,
      "z": 3,
      "name": "Rock_Stone_Cobble"
    },
    {
      "x": 0,
      "y": 9,
      "z": 3,
      "name": "Rock_Stone_Cobble"
    },
    {
      "x": 0,
      "y": 10,
      "z": 3,
      "name": "Rock_Stone_Cobble"
    },
    {
      "x": 0,
      "y": 11,
      "z": 3,
      "name": "Rock_Stone_Cobble"
    },
    {
      "x": 0,
      "y": 0,
      "z": 4,
      "name": "Rock_Stone_Cobble"
    },
    {
      "x": 0,
      "y": 1,
      "z": 4,
      "name": "Rock_Stone_Cobble"
    },
    {
      "x": 0,
      "y": 2,
      "z": 4,
      "name": "Rock_Stone_Cobble"
    },
    {
      "x": 0,
      "y": 3,
      "z": 4,
      "name": "Rock_Stone_Cobble"
    },
    {
      "x": 0,
      "y": 4,
      "z": 4,
      "name": "Rock_Stone_Cobble"
    },
    {
      "x": 0,
      "y": 5,
      "z": 4,
      "name": "Rock_Stone_Cobble"
    },
    {
      "x": 0,
      "y": 6,
      "z": 4,
      "name": "Rock_Stone_Cobble"
    },
    {
      "x": 0,
      "y": 7,
      "z": 4,
      "name": "Rock_Stone_Cobble"
    },
    {
      "x": 0,
      "y": 8,
      "z": 4,
      "name": "Rock_Stone_Cobble"
    },
    {
      "x": 0,
      "y": 9,
      "z": 4,
      "name": "Rock_Stone_Cobble"
    },
    {
      "x": 0,
      "y": 10,
      "z": 4,
      "name": "Rock_Stone_Cobble"
    },
    {
      "x": 0,
      "y": 11,
      "z": 4,
      "name": "Rock_Stone_Cobble"
    }
  ]
}