{
  "version": 8,
  "blockIdVersion": 8,
  "anchorX": 1,
  "anchorY": 30,
  "anchorZ": 1,
  "blocks": [
    {
      "x": -3,
      "y": 28,
      "z": -1,
      "name": "Rock_Basalt"
    },
    {
      "x": -3,
      "y": 29,
      "z": -1,
      "name": "Rock_Basalt"
    },
    {
      "x": -3,
      "y": 25,
      "z": 0,
      "name": "Rock_Basalt"
    },
    {
      "x": -3,
      "y": 26,
      "z": 0,
      "name": "Rock_Basalt"
    },
    {
      "x": -3,
      "y": 27,
      "z": 0,
      "name": "Rock_Basalt"
    },
    {
      "x": -3,
      "y": 28,
      "z": 0,
      "name": "Rock_Basalt"
    },
    {
      "x": -3,
      "y": 29,
      "z": 0,
      "name": "Rock_Basalt"
    },
    {
      "x": -3,
      "y": 30,
      "z": 0,
      "name": "Rock_Basalt"
    },
    {
      "x": -3,
      "y": 24,
      "z": 1,
      "name": "Rock_Basalt"
    },
    {
      "x": -3,
      "y": 25,
      "z": 1,
      "name": "Rock_Basalt"
    },
    {
      "x": -3,
      "y": 26,
      "z": 1,
      "name": "Rock_Basalt"
    },
    {
      "x": -3,
      "y": 27,
      "z": 1,
      "name": "Rock_Basalt"
    },
    {
      "x": -3,
      "y": 28,
      "z": 1,
      "name": "Rock_Basalt"
    },
    {
      "x": -3,
      "y": 29,
      "z": 1,
      "name": "Rock_Basalt"
    },
    {
      "x": -3,
      "y": 30,
      "z": 1,
      "name": "Rock_Basalt"
    },
    {
      "x": -3,
      "y": 31,
      "z": 1,
      "name": "Rock_Basalt"
    },
    {
      "x": -3,
      "y": 24,
      "z": 2,
      "name": "Rock_Basalt"
    },
    {
      "x": -3,
      "y": 25,
      "z": 2,
      "name": "Rock_Basalt"
    },
    {
      "x": -3,
      "y": 26,
      "z": 2,
      "name": "Rock_Basalt"
    },
    {
      "x": -3,
      "y": 27,
      "z": 2,
      "name": "Rock_Basalt"
    },
    {
      "x": -3,
      "y": 28,
      "z": 2,
      "name": "Rock_Basalt"
    },
    {
      "x": -3,
      "y": 29,
      "z": 2,
      "name": "Rock_Basalt"
    },
    {
      "x": -3,
      "y": 30,
      "z": 2,
      "name": "Rock_Basalt"
    },
    {
      "x": -3,
      "y": 31,
      "z": 2,
      "name": "Rock_Basalt"
    },
    {
      "x": -3,
      "y": 27,
      "z": 3,
      "name": "Rock_Basalt"
    },
    {
      "x": -3,
      "y": 28,
      "z": 3,
      "name": "Rock_Basalt"
    },
    {
      "x": -3,
      "y": 29,
      "z": 3,
      "name": "Rock_Basalt"
    },
    {
      "x": -3,
      "y": 30,
      "z": 3,
      "name": "Rock_Basalt"
    },
    {
      "x": -2,
      "y": 27,
      "z": -2,
      "name": "Rock_Basalt"
    },
    {
      "x": -2,
      "y": 28,
      "z": -2,
      "name": "Rock_Basalt"
    },
    {
      "x": -2,
      "y": 29,
      "z": -2,
      "name": "Rock_Basalt"
    },
    {
      "x": -2,
      "y": 23,
      "z": -1,
      "name": "Rock_Basalt"
    },
    {
      "x": -2,
      "y": 24,
      "z": -1,
      "name": "Rock_Basalt"
    },
    {
      "x": -2,
      "y": 25,
      "z": -1,
      "name": "Rock_Basalt"
    },
    {
      "x": -2,
      "y": 26,
      "z": -1,
      "name": "Rock_Basalt"
    },
    {
      "x": -2,
      "y": 27,
      "z": -1,
      "name": "Rock_Basalt"
    },
    {
      "x": -2,
      "y": 28,
      "z": -1,
      "name": "Rock_Basalt"
    },
    {
      "x": -2,
      "y": 29,
      "z": -1,
      "name": "Rock_Basalt"
    },
    {
      "x": -2,
      "y": 30,
      "z": -1,
      "name": "Rock_Basalt"
    },
    {
      "x": -2,
      "y": 31,
      "z": -1,
      "name": "Rock_Basalt"
    },
    {
      "x": -2,
      "y": 22,
      "z": 0,
      "name": "Rock_Basalt"
    },
    {
      "x": -2,
      "y": 23,
      "z": 0,
      "name": "Rock_Basalt"
    },
    {
      "x": -2,
      "y": 24,
      "z": 0,
      "name": "Rock_Basalt"
    },
    {
      "x": -2,
      "y": 25,
      "z": 0,
      "name": "Rock_Basalt"
    },
    {
      "x": -2,
      "y": 26,
      "z": 0,
      "name": "Rock_Basalt"
    },
    {
      "x": -2,
      "y": 27,
      "z": 0,
      "name": "Rock_Basalt"
    },
    {
      "x": -2,
      "y": 28,
      "z": 0,
      "name": "Rock_Basalt"
    },
    {
      "x": -2,
      "y": 29,
      "z": 0,
      "name": "Rock_Basalt"
    },
    {
      "x": -2,
      "y": 30,
      "z": 0,
      "name": "Rock_Basalt"
    },
    {
      "x": -2,
      "y": 31,
      "z": 0,
      "name": "Rock_Basalt"
    },
    {
      "x": -2,
      "y": 32,
      "z": 0,
      "name": "Rock_Basalt"
    },
    {
      "x": -2,
      "y": 22,
      "z": 1,
      "name": "Rock_Basalt"
    },
    {
      "x": -2,
      "y": 23,
      "z": 1,
      "name": "Rock_Basalt"
    },
    {
      "x": -2,
      "y": 24,
      "z": 1,
      "name": "Rock_Basalt"
    },
    {
      "x": -2,
      "y": 25,
      "z": 1,
      "name": "Rock_Basalt"
    },
    {
      "x": -2,
      "y": 26,
      "z": 1,
      "name": "Rock_Basalt"
    },
    {
      "x": -2,
      "y": 27,
      "z": 1,
      "name": "Rock_Basalt"
    },
    {
      "x": -2,
      "y": 28,
      "z": 1,
      "name": "Rock_Basalt"
    },
    {
      "x": -2,
      "y": 29,
      "z": 1,
      "name": "Rock_Basalt"
    },
    {
      "x": -2,
      "y": 30,
      "z": 1,
      "name": "Rock_Basalt"
    },
    {
      "x": -2,
      "y": 31,
      "z": 1,
      "name": "Rock_Basalt"
    },
    {
      "x": -2,
      "y": 32,
      "z": 1,
      "name": "Rock_Basalt"
    },
    {
      "x": -2,
      "y": 33,
      "z": 1,
      "name": "Rock_Basalt"
    },
    {
      "x": -2,
      "y": 22,
      "z": 2,
      "name": "Rock_Basalt"
    },
    {
      "x": -2,
      "y": 23,
      "z": 2,
      "name": "Rock_Basalt"
    },
    {
      "x": -2,
      "y": 24,
      "z": 2,
      "name": "Rock_Basalt"
    },
    {
      "x": -2,
      "y": 25,
      "z": 2,
      "name": "Rock_Basalt"
    },
    {
      "x": -2,
      "y": 26,
      "z": 2,
      "name": "Rock_Basalt"
    },
    {
      "x": -2,
      "y": 27,
      "z": 2,
      "name": "Rock_Basalt"
    },
    {
      "x": -2,
      "y": 28,
      "z": 2,
      "name": "Rock_Basalt"
    },
    {
      "x": -2,
      "y": 29,
      "z": 2,
      "name": "Rock_Basalt"
    },
    {
      "x": -2,
      "y": 30,
      "z": 2,
      "name": "Rock_Basalt"
    },
    {
      "x": -2,
      "y": 31,
      "z": 2,
      "name": "Rock_Basalt"
    },
    {
      "x": -2,
      "y": 32,
      "z": 2,
      "name": "Rock_Basalt"
    },
    {
      "x": -2,
      "y": 33,
      "z": 2,
      "name": "Rock_Basalt"
    },
    {
      "x": -2,
      "y": 23,
      "z": 3,
      "name": "Rock_Basalt"
    },
    {
      "x": -2,
      "y": 24,
      "z": 3,
      "name": "Rock_Basalt"
    },
    {
      "x": -2,
      "y": 25,
      "z": 3,
      "name": "Rock_Basalt"
    },
    {
      "x": -2,
      "y": 26,
      "z": 3,
      "name": "Rock_Basalt"
    },
    {
      "x": -2,
      "y": 27,
      "z": 3,
      "name": "Rock_Basalt"
    },
    {
      "x": -2,
      "y": 28,
      "z": 3,
      "name": "Rock_Basalt"
    },
    {
      "x": -2,
      "y": 29,
      "z": 3,
      "name": "Rock_Basalt"
    },
    {
      "x": -2,
      "y": 30,
      "z": 3,
      "name": "Rock_Basalt"
    },
    {
      "x": -2,
      "y": 31,
      "z": 3,
      "name": "Rock_Basalt"
    },
    {
      "x": -2,
      "y": 32,
      "z": 3,
      "name": "Rock_Basalt"
    },
    {
      "x": -2,
      "y": 28,
      "z": 4,
      "name": "Rock_Basalt"
    },
    {
      "x": -2,
      "y": 29,
      "z": 4,
      "name": "Rock_Basalt"
    },
    {
      "x": -2,
      "y": 30,
      "z": 4,
      "name": "Rock_Basalt"
    },
    {
      "x": -1,
      "y": 28,
      "z": -3,
      "name": "Rock_Basalt"
    },
    {
      "x": -1,
      "y": 29,
      "z": -3,
      "name": "Rock_Basalt"
    },
    {
      "x": -1,
      "y": 30,
      "z": -3,
      "name": "Rock_Basalt"
    },
    {
      "x": -1,
      "y": 24,
      "z": -2,
      "name": "Rock_Basalt"
    },
    {
      "x": -1,
      "y": 25,
      "z": -2,
      "name": "Rock_Basalt"
    },
    {
      "x": -1,
      "y": 26,
      "z": -2,
      "name": "Rock_Basalt"
    },
    {
      "x": -1,
      "y": 27,
      "z": -2,
      "name": "Rock_Basalt"
    },
    {
      "x": -1,
      "y": 28,
      "z": -2,
      "name": "Rock_Basalt"
    },
    {
      "x": -1,
      "y": 29,
      "z": -2,
      "name": "Rock_Basalt"
    },
    {
      "x": -1,
      "y": 30,
      "z": -2,
      "name": "Rock_Basalt"
    },
    {
      "x": -1,
      "y": 31,
      "z": -2,
      "name": "Rock_Basalt"
    },
    {
      "x": -1,
      "y": 21,
      "z": -1,
      "name": "Rock_Basalt"
    },
    {
      "x": -1,
      "y": 22,
      "z": -1,
      "name": "Rock_Basalt"
    },
    {
      "x": -1,
      "y": 23,
      "z": -1,
      "name": "Rock_Basalt"
    },
    {
      "x": -1,
      "y": 24,
      "z": -1,
      "name": "Rock_Basalt"
    },
    {
      "x": -1,
      "y": 25,
      "z": -1,
      "name": "Rock_Basalt"
    },
    {
      "x": -1,
      "y": 26,
      "z": -1,
      "name": "Rock_Basalt"
    },
    {
      "x": -1,
      "y": 27,
      "z": -1,
      "name": "Rock_Basalt"
    },
    {
      "x": -1,
      "y": 28,
      "z": -1,
      "name": "Rock_Basalt"
    },
    {
      "x": -1,
      "y": 29,
      "z": -1,
      "name": "Rock_Basalt"
    },
    {
      "x": -1,
      "y": 30,
      "z": -1,
      "name": "Rock_Basalt"
    },
    {
      "x": -1,
      "y": 31,
      "z": -1,
      "name": "Rock_Basalt"
    },
    {
      "x": -1,
      "y": 32,
      "z": -1,
      "name": "Rock_Basalt"
    },
    {
      "x": -1,
      "y": 33,
      "z": -1,
      "name": "Rock_Basalt"
    },
    {
      "x": -1,
      "y": 20,
      "z": 0,
      "name": "Rock_Basalt"
    },
    {
      "x": -1,
      "y": 21,
      "z": 0,
      "name": "Rock_Basalt"
    },
    {
      "x": -1,
      "y": 22,
      "z": 0,
      "name": "Rock_Basalt"
    },
    {
      "x": -1,
      "y": 23,
      "z": 0,
      "name": "Rock_Basalt"
    },
    {
      "x": -1,
      "y": 24,
      "z": 0,
      "name": "Rock_Basalt"
    },
    {
      "x": -1,
      "y": 25,
      "z": 0,
      "name": "Rock_Basalt"
    },
    {
      "x": -1,
      "y": 26,
      "z": 0,
      "name": "Rock_Basalt"
    },
    {
      "x": -1,
      "y": 27,
      "z": 0,
      "name": "Rock_Basalt"
    },
    {
      "x": -1,
      "y": 28,
      "z": 0,
      "name": "Rock_Basalt"
    },
    {
      "x": -1,
      "y": 29,
      "z": 0,
      "name": "Rock_Basalt"
    },
    {
      "x": -1,
      "y": 30,
      "z": 0,
      "name": "Rock_Basalt"
    },
    {
      "x": -1,
      "y": 31,
      "z": 0,
      "name": "Rock_Basalt"
    },
    {
      "x": -1,
      "y": 32,
      "z": 0,
      "name": "Rock_Basalt"
    },
    {
      "x": -1,
      "y": 33,
      "z": 0,
      "name": "Rock_Basalt"
    },
    {
      "x": -1,
      "y": 18,
      "z": 1,
      "name": "Rock_Basalt"
    },
    {
      "x": -1,
      "y": 19,
      "z": 1,
      "name": "Rock_Basalt"
    },
    {
      "x": -1,
      "y": 20,
      "z": 1,
      "name": "Rock_Basalt"
    },
    {
      "x": -1,
      "y": 21,
      "z": 1,
      "name": "Rock_Basalt"
    },
    {
      "x": -1,
      "y": 22,
      "z": 1,
      "name": "Rock_Basalt"
    },
    {
      "x": -1,
      "y": 23,
      "z": 1,
      "name": "Rock_Basalt"
    },
    {
      "x": -1,
      "y": 24,
      "z": 1,
      "name": "Rock_Basalt"
    },
    {
      "x": -1,
      "y": 25,
      "z": 1,
      "name": "Rock_Basalt"
    },
    {
      "x": -1,
      "y": 26,
      "z": 1,
      "name": "Rock_Basalt"
    },
    {
      "x": -1,
      "y": 27,
      "z": 1,
      "name": "Rock_Basalt"
    },
    {
      "x": -1,
      "y": 28,
      "z": 1,
      "name": "Rock_Basalt"
    },
    {
      "x": -1,
      "y": 29,
      "z": 1,
      "name": "Rock_Basalt"
    },
    {
      "x": -1,
      "y": 30,
      "z": 1,
      "name": "Rock_Basalt"
    },
    {
      "x": -1,
      "y": 31,
      "z": 1,
      "name": "Rock_Basalt"
    },
    {
      "x": -1,
      "y": 32,
      "z": 1,
      "name": "Rock_Basalt"
    },
    {
      "x": -1,
      "y": 33,
      "z": 1,
      "name": "Rock_Basalt"
    },
    {
      "x": -1,
      "y": 34,
      "z": 1,
      "name": "Rock_Basalt"
    },
    {
      "x": -1,
      "y": 18,
      "z": 2,
      "name": "Rock_Basalt"
    },
    {
      "x": -1,
      "y": 19,
      "z": 2,
      "name": "Rock_Basalt"
    },
    {
      "x": -1,
      "y": 20,
      "z": 2,
      "name": "Rock_Basalt"
    },
    {
      "x": -1,
      "y": 21,
      "z": 2,
      "name": "Rock_Basalt"
    },
    {
      "x": -1,
      "y": 22,
      "z": 2,
      "name": "Rock_Basalt"
    },
    {
      "x": -1,
      "y": 23,
      "z": 2,
      "name": "Rock_Basalt"
    },
    {
      "x": -1,
      "y": 24,
      "z": 2,
      "name": "Rock_Basalt"
    },
    {
      "x": -1,
      "y": 25,
      "z": 2,
      "name": "Rock_Basalt"
    },
    {
      "x": -1,
      "y": 26,
      "z": 2,
      "name": "Rock_Basalt"
    },
    {
      "x": -1,
      "y": 27,
      "z": 2,
      "name": "Rock_Basalt"
    },
    {
      "x": -1,
      "y": 28,
      "z": 2,
      "name": "Rock_Basalt"
    },
    {
      "x": -1,
      "y": 29,
      "z": 2,
      "name": "Rock_Basalt"
    },
    {
      "x": -1,
      "y": 30,
      "z": 2,
      "name": "Rock_Basalt"
    },
    {
      "x": -1,
      "y": 31,
      "z": 2,
      "name": "Rock_Basalt"
    },
    {
      "x": -1,
      "y": 32,
      "z": 2,
      "name": "Rock_Basalt"
    },
    {
      "x": -1,
      "y": 33,
      "z": 2,
      "name": "Rock_Basalt"
    },
    {
      "x": -1,
      "y": 20,
      "z": 3,
      "name": "Rock_Basalt"
    },
    {
      "x": -1,
      "y": 21,
      "z": 3,
      "name": "Rock_Basalt"
    },
    {
      "x": -1,
      "y": 22,
      "z": 3,
      "name": "Rock_Basalt"
    },
    {
      "x": -1,
      "y": 23,
      "z": 3,
      "name": "Rock_Basalt"
    },
    {
      "x": -1,
      "y": 24,
      "z": 3,
      "name": "Rock_Basalt"
    },
    {
      "x": -1,
      "y": 25,
      "z": 3,
      "name": "Rock_Basalt"
    },
    {
      "x": -1,
      "y": 26,
      "z": 3,
      "name": "Rock_Basalt"
    },
    {
      "x": -1,
      "y": 27,
      "z": 3,
      "name": "Rock_Basalt"
    },
    {
      "x": -1,
      "y": 28,
      "z": 3,
      "name": "Rock_Basalt"
    },
    {
      "x": -1,
      "y": 29,
      "z": 3,
      "name": "Rock_Basalt"
    },
    {
      "x": -1,
      "y": 30,
      "z": 3,
      "name": "Rock_Basalt"
    },
    {
      "x": -1,
      "y": 31,
      "z": 3,
      "name": "Rock_Basalt"
    },
    {
      "x": -1,
      "y": 32,
      "z": 3,
      "name": "Rock_Basalt"
    },
    {
      "x": -1,
      "y": 33,
      "z": 3,
      "name": "Rock_Basalt"
    },
    {
      "x": -1,
      "y": 22,
      "z": 4,
      "name": "Rock_Basalt"
    },
    {
      "x": -1,
      "y": 23,
      "z": 4,
      "name": "Rock_Basalt"
    },
    {
      "x": -1,
      "y": 24,
      "z": 4,
      "name": "Rock_Basalt"
    },
    {
      "x": -1,
      "y": 25,
      "z": 4,
      "name": "Rock_Basalt"
    },
    {
      "x": -1,
      "y": 26,
      "z": 4,
      "name": "Rock_Basalt"
    },
    {
      "x": -1,
      "y": 27,
      "z": 4,
      "name": "Rock_Basalt"
    },
    {
      "x": -1,
      "y": 28,
      "z": 4,
      "name": "Rock_Basalt"
    },
    {
      "x": -1,
      "y": 29,
      "z": 4,
      "name": "Rock_Basalt"
    },
    {
      "x": -1,
      "y": 30,
      "z": 4,
      "name": "Rock_Basalt"
    },
    {
      "x": -1,
      "y": 31,
      "z": 4,
      "name": "Rock_Basalt"
    },
    {
      "x": 0,
      "y": 26,
      "z": -3,
      "name": "Rock_Basalt"
    },
    {
      "x": 0,
      "y": 27,
      "z": -3,
      "name": "Rock_Basalt"
    },
    {
      "x": 0,
      "y": 28,
      "z": -3,
      "name": "Rock_Basalt"
    },
    {
      "x": 0,
      "y": 29,
      "z": -3,
      "name": "Rock_Basalt"
    },
    {
      "x": 0,
      "y": 30,
      "z": -3,
      "name": "Rock_Basalt"
    },
    {
      "x": 0,
      "y": 24,
      "z": -2,
      "name": "Rock_Basalt"
    },
    {
      "x": 0,
      "y": 25,
      "z": -2,
      "name": "Rock_Basalt"
    },
    {
      "x": 0,
      "y": 26,
      "z": -2,
      "name": "Rock_Basalt"
    },
    {
      "x": 0,
      "y": 27,
      "z": -2,
      "name": "Rock_Basalt"
    },
    {
      "x": 0,
      "y": 28,
      "z": -2,
      "name": "Rock_Basalt"
    },
    {
      "x": 0,
      "y": 29,
      "z": -2,
      "name": "Rock_Basalt"
    },
    {
      "x": 0,
      "y": 30,
      "z": -2,
      "name": "Rock_Basalt"
    },
    {
      "x": 0,
      "y": 31,
      "z": -2,
      "name": "Rock_Basalt"
    },
    {
      "x": 0,
      "y": 32,
      "z": -2,
      "name": "Rock_Basalt"
    },
    {
      "x": 0,
      "y": 19,
      "z": -1,
      "name": "Rock_Basalt"
    },
    {
      "x": 0,
      "y": 20,
      "z": -1,
      "name": "Rock_Basalt"
    },
    {
      "x": 0,
      "y": 21,
      "z": -1,
      "name": "Rock_Basalt"
    },
    {
      "x": 0,
      "y": 22,
      "z": -1,
      "name": "Rock_Basalt"
    },
    {
      "x": 0,
      "y": 23,
      "z": -1,
      "name": "Rock_Basalt"
    },
    {
      "x": 0,
      "y": 24,
      "z": -1,
      "name": "Rock_Basalt"
    },
    {
      "x": 0,
      "y": 25,
      "z": -1,
      "name": "Rock_Basalt"
    },
    {
      "x": 0,
      "y": 26,
      "z": -1,
      "name": "Rock_Basalt"
    },
    {
      "x": 0,
      "y": 27,
      "z": -1,
      "name": "Rock_Basalt"
    },
    {
      "x": 0,
      "y": 28,
      "z": -1,
      "name": "Rock_Basalt"
    },
    {
      "x": 0,
      "y": 29,
      "z": -1,
      "name": "Rock_Basalt"
    },
    {
      "x": 0,
      "y": 30,
      "z": -1,
      "name": "Rock_Basalt"
    },
    {
      "x": 0,
      "y": 31,
      "z": -1,
      "name": "Rock_Basalt"
    },
    {
      "x": 0,
      "y": 32,
      "z": -1,
      "name": "Rock_Basalt"
    },
    {
      "x": 0,
      "y": 33,
      "z": -1,
      "name": "Rock_Basalt"
    },
    {
      "x": 0,
      "y": 16,
      "z": 0,
      "name": "Rock_Basalt"
    },
    {
      "x": 0,
      "y": 17,
      "z": 0,
      "name": "Rock_Basalt"
    },
    {
      "x": 0,
      "y": 18,
      "z": 0,
      "name": "Rock_Basalt"
    },
    {
      "x": 0,
      "y": 19,
      "z": 0,
      "name": "Rock_Basalt"
    },
    {
      "x": 0,
      "y": 20,
      "z": 0,
      "name": "Rock_Basalt"
    },
    {
      "x": 0,
      "y": 21,
      "z": 0,
      "name": "Rock_Basalt"
    },
    {
      "x": 0,
      "y": 22,
      "z": 0,
      "name": "Rock_Basalt"
    },
    {
      "x": 0,
      "y": 23,
      "z": 0,
      "name": "Rock_Basalt"
    },
    {
      "x": 0,
      "y": 24,
      "z": 0,
      "name": "Rock_Basalt"
    },
    {
      "x": 0,
      "y": 25,
      "z": 0,
      "name": "Rock_Basalt"
    },
    {
      "x": 0,
      "y": 26,
      "z": 0,
      "name": "Rock_Basalt"
    },
    {
      "x": 0,
      "y": 27,
      "z": 0,
      "name": "Rock_Basalt"
    },
    {
      "x": 0,
      "y": 28,
      "z": 0,
      "name": "Rock_Basalt"
    },
    {
      "x": 0,
      "y": 29,
      "z": 0,
      "name": "Rock_Basalt"
    },
    {
      "x": 0,
      "y": 30,
      "z": 0,
      "name": "Rock_Basalt"
    },
    {
      "x": 0,
      "y": 31,
      "z": 0,
      "name": "Rock_Basalt"
    },
    {
      "x": 0,
      "y": 32,
      "z": 0,
      "name": "Rock_Basalt"
    },
    {
      "x": 0,
      "y": 33,
      "z": 0,
      "name": "Rock_Basalt"
    },
    {
      "x": 0,
      "y": 34,
      "z": 0,
      "name": "Rock_Basalt"
    },
    {
      "x": 0,
      "y": 14,
      "z": 1,
      "name": "Rock_Basalt"
    },
    {
      "x": 0,
      "y": 15,
      "z": 1,
      "name": "Rock_Basalt"
    },
    {
      "x": 0,
      "y": 16,
      "z": 1,
      "name": "Rock_Basalt"
    },
    {
      "x": 0,
      "y": 17,
      "z": 1,
      "name": "Rock_Basalt"
    },
    {
      "x": 0,
      "y": 18,
      "z": 1,
      "name": "Rock_Basalt"
    },
    {
      "x": 0,
      "y": 19,
      "z": 1,
      "name": "Rock_Basalt"
    },
    {
      "x": 0,
      "y": 20,
      "z": 1,
      "name": "Rock_Basalt"
    },
    {
      "x": 0,
      "y": 21,
      "z": 1,
      "name": "Rock_Basalt"
    },
    {
      "x": 0,
      "y": 22,
      "z": 1,
      "name": "Rock_Basalt"
    },
    {
      "x": 0,
      "y": 23,
      "z": 1,
      "name": "Rock_Basalt"
    },
    {
      "x": 0,
      "y": 24,
      "z": 1,
      "name": "Rock_Basalt"
    },
    {
      "x": 0,
      "y": 25,
      "z": 1,
      "name": "Rock_Basalt"
    },
    {
      "x": 0,
      "y": 26,
      "z": 1,
      "name": "Rock_Basalt"
    },
    {
      "x": 0,
      "y": 27,
      "z": 1,
      "name": "Rock_Basalt"
    },
    {
      "x": 0,
      "y": 28,
      "z": 1,
      "name": "Rock_Basalt"
    },
    {
      "x": 0,
      "y": 29,
      "z": 1,
      "name": "Rock_Basalt"
    },
    {
      "x": 0,
      "y": 30,
      "z": 1,
      "name": "Rock_Basalt"
    },
    {
      "x": 0,
      "y": 31,
      "z": 1,
      "name": "Rock_Basalt"
    },
    {
      "x": 0,
      "y": 32,
      "z": 1,
      "name": "Rock_Basalt"
    },
    {
      "x": 0,
      "y": 33,
      "z": 1,
      "name": "Rock_Basalt"
    },
    {
      "x": 0,
      "y": 34,
      "z": 1,
      "name": "Rock_Basalt"
    },
    {
      "x": 0,
      "y": 16,
      "z": 2,
      "name": "Rock_Basalt"
    },
    {
      "x": 0,
      "y": 17,
      "z": 2,
      "name": "Rock_Basalt"
    },
    {
      "x": 0,
      "y": 18,
      "z": 2,
      "name": "Rock_Basalt"
    },
    {
      "x": 0,
      "y": 19,
      "z": 2,
      "name": "Rock_Basalt"
    },
    {
      "x": 0,
      "y": 20,
      "z": 2,
      "name": "Rock_Basalt"
    },
    {
      "x": 0,
      "y": 21,
      "z": 2,
      "name": "Rock_Basalt"
    },
    {
      "x": 0,
      "y": 22,
      "z": 2,
      "name": "Rock_Basalt"
    },
    {
      "x": 0,
      "y": 23,
      "z": 2,
      "name": "Rock_Basalt"
    },
    {
      "x": 0,
      "y": 24,
      "z": 2,
      "name": "Rock_Basalt"
    },
    {
      "x": 0,
      "y": 25,
      "z": 2,
      "name": "Rock_Basalt"
    },
    {
      "x": 0,
      "y": 26,
      "z": 2,
      "name": "Rock_Basalt"
    },
    {
      "x": 0,
      "y": 27,
      "z": 2,
      "name": "Rock_Basalt"
    },
    {
      "x": 0,
      "y": 28,
      "z": 2,
      "name": "Rock_Basalt"
    },
    {
      "x": 0,
      "y": 29,
      "z": 2,
      "name": "Rock_Basalt"
    },
    {
      "x": 0,
      "y": 30,
      "z": 2,
      "name": "Rock_Basalt"
    },
    {
      "x": 0,
      "y": 31,
      "z": 2,
      "name": "Rock_Basalt"
    },
    {
      "x": 0,
      "y": 32,
      "z": 2,
      "name": "Rock_Basalt"
    },
    {
      "x": 0,
      "y": 33,
      "z": 2,
      "name": "Rock_Basalt"
    },
    {
      "x": 0,
      "y": 34,
      "z": 2,
      "name": "Rock_Basalt"
    },
    {
      "x": 0,
      "y": 18,
      "z": 3,
      "name": "Rock_Basalt"
    },
    {
      "x": 0,
      "y": 19,
      "z": 3,
      "name": "Rock_Basalt"
    },
    {
      "x": 0,
      "y": 20,
      "z": 3,
      "name": "Rock_Basalt"
    },
    {
      "x": 0,
      "y": 21,
      "z": 3,
      "name": "Rock_Basalt"
    },
    {
      "x": 0,
      "y": 22,
      "z": 3,
      "name": "Rock_Basalt"
    },
    {
      "x": 0,
      "y": 23,
      "z": 3,
      "name": "Rock_Basalt"
    },
    {
      "x": 0,
      "y": 24,
      "z": 3,
      "name": "Rock_Basalt"
    },
    {
      "x": 0,
      "y": 25,
      "z": 3,
      "name": "Rock_Basalt"
    },
    {
      "x": 0,
      "y": 26,
      "z": 3,
      "name": "Rock_Basalt"
    },
    {
      "x": 0,
      "y": 27,
      "z": 3,
      "name": "Rock_Basalt"
    },
    {
      "x": 0,
      "y": 28,
      "z": 3,
      "name": "Rock_Basalt"
    },
    {
      "x": 0,
      "y": 29,
      "z": 3,
      "name": "Rock_Basalt"
    },
    {
      "x": 0,
      "y": 30,
      "z": 3,
      "name": "Rock_Basalt"
    },
    {
      "x": 0,
      "y": 31,
      "z": 3,
      "name": "Rock_Basalt"
    },
    {
      "x": 0,
      "y": 32,
      "z": 3,
      "name": "Rock_Basalt"
    },
    {
      "x": 0,
      "y": 33,
      "z": 3,
      "name": "Rock_Basalt"
    },
    {
      "x": 0,
      "y": 22,
      "z": 4,
      "name": "Rock_Basalt"
    },
    {
      "x": 0,
      "y": 23,
      "z": 4,
      "name": "Rock_Basalt"
    },
    {
      "x": 0,
      "y": 24,
      "z": 4,
      "name": "Rock_Basalt"
    },
    {
      "x": 0,
      "y": 25,
      "z": 4,
      "name": "Rock_Basalt"
    },
    {
      "x": 0,
      "y": 26,
      "z": 4,
      "name": "Rock_Basalt"
    },
    {
      "x": 0,
      "y": 27,
      "z": 4,
      "name": "Rock_Basalt"
    },
    {
      "x": 0,
      "y": 28,
      "z": 4,
      "name": "Rock_Basalt"
    },
    {
      "x": 0,
      "y": 29,
      "z": 4,
      "name": "Rock_Basalt"
    },
    {
      "x": 0,
      "y": 30,
      "z": 4,
      "name": "Rock_Basalt"
    },
    {
      "x": 0,
      "y": 31,
      "z": 4,
      "name": "Rock_Basalt"
    },
    {
      "x": 0,
      "y": 32,
      "z": 4,
      "name": "Rock_Basalt"
    },
    {
      "x": 0,
      "y": 25,
      "z": 5,
      "name": "Rock_Basalt"
    },
    {
      "x": 0,
      "y": 26,
      "z": 5,
      "name": "Rock_Basalt"
    },
    {
      "x": 0,
      "y": 27,
      "z": 5,
      "name": "Rock_Basalt"
    },
    {
      "x": 0,
      "y": 28,
      "z": 5,
      "name": "Rock_Basalt"
    },
    {
      "x": 0,
      "y": 29,
      "z": 5,
      "name": "Rock_Basalt"
    },
    {
      "x": 1,
      "y": 26,
      "z": -3,
      "name": "Rock_Basalt"
    },
    {
      "x": 1,
      "y": 27,
      "z": -3,
      "name": "Rock_Basalt"
    },
    {
      "x": 1,
      "y": 28,
      "z": -3,
      "name": "Rock_Basalt"
    },
    {
      "x": 1,
      "y": 29,
      "z": -3,
      "name": "Rock_Basalt"
    },
    {
      "x": 1,
      "y": 30,
      "z": -3,
      "name": "Rock_Basalt"
    },
    {
      "x": 1,
      "y": 31,
      "z": -3,
      "name": "Rock_Basalt"
    },
    {
      "x": 1,
      "y": 23,
      "z": -2,
      "name": "Rock_Basalt"
    },
    {
      "x": 1,
      "y": 24,
      "z": -2,
      "name": "Rock_Basalt"
    },
    {
      "x": 1,
      "y": 25,
      "z": -2,
      "name": "Rock_Basalt"
    },
    {
      "x": 1,
      "y": 26,
      "z": -2,
      "name": "Rock_Basalt"
    },
    {
      "x": 1,
      "y": 27,
      "z": -2,
      "name": "Rock_Basalt"
    },
    {
      "x": 1,
      "y": 28,
      "z": -2,
      "name": "Rock_Basalt"
    },
    {
      "x": 1,
      "y": 29,
      "z": -2,
      "name": "Rock_Basalt"
    },
    {
      "x": 1,
      "y": 30,
      "z": -2,
      "name": "Rock_Basalt"
    },
    {
      "x": 1,
      "y": 31,
      "z": -2,
      "name": "Rock_Basalt"
    },
    {
      "x": 1,
      "y": 32,
      "z": -2,
      "name": "Rock_Basalt"
    },
    {
      "x": 1,
      "y": 19,
      "z": -1,
      "name": "Rock_Basalt"
    },
    {
      "x": 1,
      "y": 20,
      "z": -1,
      "name": "Rock_Basalt"
    },
    {
      "x": 1,
      "y": 21,
      "z": -1,
      "name": "Rock_Basalt"
    },
    {
      "x": 1,
      "y": 22,
      "z": -1,
      "name": "Rock_Basalt"
    },
    {
      "x": 1,
      "y": 23,
      "z": -1,
      "name": "Rock_Basalt"
    },
    {
      "x": 1,
      "y": 24,
      "z": -1,
      "name": "Rock_Basalt"
    },
    {
      "x": 1,
      "y": 25,
      "z": -1,
      "name": "Rock_Basalt"
    },
    {
      "x": 1,
      "y": 26,
      "z": -1,
      "name": "Rock_Basalt"
    },
    {
      "x": 1,
      "y": 27,
      "z": -1,
      "name": "Rock_Basalt"
    },
    {
      "x": 1,
      "y": 28,
      "z": -1,
      "name": "Rock_Basalt"
    },
    {
      "x": 1,
      "y": 29,
      "z": -1,
      "name": "Rock_Basalt"
    },
    {
      "x": 1,
      "y": 30,
      "z": -1,
      "name": "Rock_Basalt"
    },
    {
      "x": 1,
      "y": 31,
      "z": -1,
      "name": "Rock_Basalt"
    },
    {
      "x": 1,
      "y": 32,
      "z": -1,
      "name": "Rock_Basalt"
    },
    {
      "x": 1,
      "y": 33,
      "z": -1,
      "name": "Rock_Basalt"
    },
    {
      "x": 1,
      "y": 14,
      "z": 0,
      "name": "Rock_Basalt"
    },
    {
      "x": 1,
      "y": 15,
      "z": 0,
      "name": "Rock_Basalt"
    },
    {
      "x": 1,
      "y": 16,
      "z": 0,
      "name": "Rock_Basalt"
    },
    {
      "x": 1,
      "y": 17,
      "z": 0,
      "name": "Rock_Basalt"
    },
    {
      "x": 1,
      "y": 18,
      "z": 0,
      "name": "Rock_Basalt"
    },
    {
      "x": 1,
      "y": 19,
      "z": 0,
      "name": "Rock_Basalt"
    },
    {
      "x": 1,
      "y": 20,
      "z": 0,
      "name": "Rock_Basalt"
    },
    {
      "x": 1,
      "y": 21,
      "z": 0,
      "name": "Rock_Basalt"
    },
    {
      "x": 1,
      "y": 22,
      "z": 0,
      "name": "Rock_Basalt"
    },
    {
      "x": 1,
      "y": 23,
      "z": 0,
      "name": "Rock_Basalt"
    },
    {
      "x": 1,
      "y": 24,
      "z": 0,
      "name": "Rock_Basalt"
    },
    {
      "x": 1,
      "y": 25,
      "z": 0,
      "name": "Rock_Basalt"
    },
    {
      "x": 1,
      "y": 26,
      "z": 0,
      "name": "Rock_Basalt"
    },
    {
      "x": 1,
      "y": 27,
      "z": 0,
      "name": "Rock_Basalt"
    },
    {
      "x": 1,
      "y": 28,
      "z": 0,
      "name": "Rock_Basalt"
    },
    {
      "x": 1,
      "y": 29,
      "z": 0,
      "name": "Rock_Basalt"
    },
    {
      "x": 1,
      "y": 30,
      "z": 0,
      "name": "Rock_Basalt"
    },
    {
      "x": 1,
      "y": 31,
      "z": 0,
      "name": "Rock_Basalt"
    },
    {
      "x": 1,
      "y": 32,
      "z": 0,
      "name": "Rock_Basalt"
    },
    {
      "x": 1,
      "y": 33,
      "z": 0,
      "name": "Rock_Basalt"
    },
    {
      "x": 1,
      "y": 34,
      "z": 0,
      "name": "Rock_Basalt"
    },
    {
      "x": 1,
      "y": 11,
      "z": 1,
      "name": "Rock_Basalt"
    },
    {
      "x": 1,
      "y": 12,
      "z": 1,
      "name": "Rock_Basalt"
    },
    {
      "x": 1,
      "y": 13,
      "z": 1,
      "name": "Rock_Basalt"
    },
    {
      "x": 1,
      "y": 14,
      "z": 1,
      "name": "Rock_Basalt"
    },
    {
      "x": 1,
      "y": 15,
      "z": 1,
      "name": "Rock_Basalt"
    },
    {
      "x": 1,
      "y": 16,
      "z": 1,
      "name": "Rock_Basalt"
    },
    {
      "x": 1,
      "y": 17,
      "z": 1,
      "name": "Rock_Basalt"
    },
    {
      "x": 1,
      "y": 18,
      "z": 1,
      "name": "Rock_Basalt"
    },
    {
      "x": 1,
      "y": 19,
      "z": 1,
      "name": "Rock_Basalt"
    },
    {
      "x": 1,
      "y": 20,
      "z": 1,
      "name": "Rock_Basalt"
    },
    {
      "x": 1,
      "y": 21,
      "z": 1,
      "name": "Rock_Basalt"
    },
    {
      "x": 1,
      "y": 22,
      "z": 1,
      "name": "Rock_Basalt"
    },
    {
      "x": 1,
      "y": 23,
      "z": 1,
      "name": "Rock_Basalt"
    },
    {
      "x": 1,
      "y": 24,
      "z": 1,
      "name": "Rock_Basalt"
    },
    {
      "x": 1,
      "y": 25,
      "z": 1,
      "name": "Rock_Basalt"
    },
    {
      "x": 1,
      "y": 26,
      "z": 1,
      "name": "Rock_Basalt"
    },
    {
      "x": 1,
      "y": 27,
      "z": 1,
      "name": "Rock_Basalt"
    },
    {
      "x": 1,
      "y": 28,
      "z": 1,
      "name": "Rock_Basalt"
    },
    {
      "x": 1,
      "y": 29,
      "z": 1,
      "name": "Rock_Basalt"
    },
    {
      "x": 1,
      "y": 30,
      "z": 1,
      "name": "Rock_Basalt"
    },
    {
      "x": 1,
      "y": 31,
      "z": 1,
      "name": "Rock_Basalt"
    },
    {
      "x": 1,
      "y": 32,
      "z": 1,
      "name": "Rock_Basalt"
    },
    {
      "x": 1,
      "y": 33,
      "z": 1,
      "name": "Rock_Basalt"
    },
    {
      "x": 1,
      "y": 34,
      "z": 1,
      "name": "Rock_Basalt"
    },
    {
      "x": 1,
      "y": 14,
      "z": 2,
      "name": "Rock_Basalt"
    },
    {
      "x": 1,
      "y": 15,
      "z": 2,
      "name": "Rock_Basalt"
    },
    {
      "x": 1,
      "y": 16,
      "z": 2,
      "name": "Rock_Basalt"
    },
    {
      "x": 1,
      "y": 17,
      "z": 2,
      "name": "Rock_Basalt"
    },
    {
      "x": 1,
      "y": 18,
      "z": 2,
      "name": "Rock_Basalt"
    },
    {
      "x": 1,
      "y": 19,
      "z": 2,
      "name": "Rock_Basalt"
    },
    {
      "x": 1,
      "y": 20,
      "z": 2,
      "name": "Rock_Basalt"
    },
    {
      "x": 1,
      "y": 21,
      "z": 2,
      "name": "Rock_Basalt"
    },
    {
      "x": 1,
      "y": 22,
      "z": 2,
      "name": "Rock_Basalt"
    },
    {
      "x": 1,
      "y": 23,
      "z": 2,
      "name": "Rock_Basalt"
    },
    {
      "x": 1,
      "y": 24,
      "z": 2,
      "name": "Rock_Basalt"
    },
    {
      "x": 1,
      "y": 25,
      "z": 2,
      "name": "Rock_Basalt"
    },
    {
      "x": 1,
      "y": 26,
      "z": 2,
      "name": "Rock_Basalt"
    },
    {
      "x": 1,
      "y": 27,
      "z": 2,
      "name": "Rock_Basalt"
    },
    {
      "x": 1,
      "y": 28,
      "z": 2,
      "name": "Rock_Basalt"
    },
    {
      "x": 1,
      "y": 29,
      "z": 2,
      "name": "Rock_Basalt"
    },
    {
      "x": 1,
      "y": 30,
      "z": 2,
      "name": "Rock_Basalt"
    },
    {
      "x": 1,
      "y": 31,
      "z": 2,
      "name": "Rock_Basalt"
    },
    {
      "x": 1,
      "y": 32,
      "z": 2,
      "name": "Rock_Basalt"
    },
    {
      "x": 1,
      "y": 33,
      "z": 2,
      "name": "Rock_Basalt"
    },
    {
      "x": 1,
      "y": 34,
      "z": 2,
      "name": "Rock_Basalt"
    },
    {
      "x": 1,
      "y": 18,
      "z": 3,
      "name": "Rock_Basalt"
    },
    {
      "x": 1,
      "y": 19,
      "z": 3,
      "name": "Rock_Basalt"
    },
    {
      "x": 1,
      "y": 20,
      "z": 3,
      "name": "Rock_Basalt"
    },
    {
      "x": 1,
      "y": 21,
      "z": 3,
      "name": "Rock_Basalt"
    },
    {
      "x": 1,
      "y": 22,
      "z": 3,
      "name": "Rock_Basalt"
    },
    {
      "x": 1,
      "y": 23,
      "z": 3,
      "name": "Rock_Basalt"
    },
    {
      "x": 1,
      "y": 24,
      "z": 3,
      "name": "Rock_Basalt"
    },
    {
      "x": 1,
      "y": 25,
      "z": 3,
      "name": "Rock_Basalt"
    },
    {
      "x": 1,
      "y": 26,
      "z": 3,
      "name": "Rock_Basalt"
    },
    {
      "x": 1,
      "y": 27,
      "z": 3,
      "name": "Rock_Basalt"
    },
    {
      "x": 1,
      "y": 28,
      "z": 3,
      "name": "Rock_Basalt"
    },
    {
      "x": 1,
      "y": 29,
      "z": 3,
      "name": "Rock_Basalt"
    },
    {
      "x": 1,
      "y": 30,
      "z": 3,
      "name": "Rock_Basalt"
    },
    {
      "x": 1,
      "y": 31,
      "z": 3,
      "name": "Rock_Basalt"
    },
    {
      "x": 1,
      "y": 32,
      "z": 3,
      "name": "Rock_Basalt"
    },
    {
      "x": 1,
      "y": 33,
      "z": 3,
      "name": "Rock_Basalt"
    },
    {
      "x": 1,
      "y": 23,
      "z": 4,
      "name": "Rock_Basalt"
    },
    {
      "x": 1,
      "y": 24,
      "z": 4,
      "name": "Rock_Basalt"
    },
    {
      "x": 1,
      "y": 25,
      "z": 4,
      "name": "Rock_Basalt"
    },
    {
      "x": 1,
      "y": 26,
      "z": 4,
      "name": "Rock_Basalt"
    },
    {
      "x": 1,
      "y": 27,
      "z": 4,
      "name": "Rock_Basalt"
    },
    {
      "x": 1,
      "y": 28,
      "z": 4,
      "name": "Rock_Basalt"
    },
    {
      "x": 1,
      "y": 29,
      "z": 4,
      "name": "Rock_Basalt"
    },
    {
      "x": 1,
      "y": 30,
      "z": 4,
      "name": "Rock_Basalt"
    },
    {
      "x": 1,
      "y": 31,
      "z": 4,
      "name": "Rock_Basalt"
    },
    {
      "x": 1,
      "y": 32,
      "z": 4,
      "name": "Rock_Basalt"
    },
    {
      "x": 1,
      "y": 25,
      "z": 5,
      "name": "Rock_Basalt"
    },
    {
      "x": 1,
      "y": 26,
      "z": 5,
      "name": "Rock_Basalt"
    },
    {
      "x": 1,
      "y": 27,
      "z": 5,
      "name": "Rock_Basalt"
    },
    {
      "x": 1,
      "y": 28,
      "z": 5,
      "name": "Rock_Basalt"
    },
    {
      "x": 1,
      "y": 29,
      "z": 5,
      "name": "Rock_Basalt"
    },
    {
      "x": 2,
      "y": 28,
      "z": -3,
      "name": "Rock_Basalt"
    },
    {
      "x": 2,
      "y": 29,
      "z": -3,
      "name": "Rock_Basalt"
    },
    {
      "x": 2,
      "y": 24,
      "z": -2,
      "name": "Rock_Basalt"
    },
    {
      "x": 2,
      "y": 25,
      "z": -2,
      "name": "Rock_Basalt"
    },
    {
      "x": 2,
      "y": 26,
      "z": -2,
      "name": "Rock_Basalt"
    },
    {
      "x": 2,
      "y": 27,
      "z": -2,
      "name": "Rock_Basalt"
    },
    {
      "x": 2,
      "y": 28,
      "z": -2,
      "name": "Rock_Basalt"
    },
    {
      "x": 2,
      "y": 29,
      "z": -2,
      "name": "Rock_Basalt"
    },
    {
      "x": 2,
      "y": 30,
      "z": -2,
      "name": "Rock_Basalt"
    },
    {
      "x": 2,
      "y": 31,
      "z": -2,
      "name": "Rock_Basalt"
    },
    {
      "x": 2,
      "y": 20,
      "z": -1,
      "name": "Rock_Basalt"
    },
    {
      "x": 2,
      "y": 21,
      "z": -1,
      "name": "Rock_Basalt"
    },
    {
      "x": 2,
      "y": 22,
      "z": -1,
      "name": "Rock_Basalt"
    },
    {
      "x": 2,
      "y": 23,
      "z": -1,
      "name": "Rock_Basalt"
    },
    {
      "x": 2,
      "y": 24,
      "z": -1,
      "name": "Rock_Basalt"
    },
    {
      "x": 2,
      "y": 25,
      "z": -1,
      "name": "Rock_Basalt"
    },
    {
      "x": 2,
      "y": 26,
      "z": -1,
      "name": "Rock_Basalt"
    },
    {
      "x": 2,
      "y": 27,
      "z": -1,
      "name": "Rock_Basalt"
    },
    {
      "x": 2,
      "y": 28,
      "z": -1,
      "name": "Rock_Basalt"
    },
    {
      "x": 2,
      "y": 29,
      "z": -1,
      "name": "Rock_Basalt"
    },
    {
      "x": 2,
      "y": 30,
      "z": -1,
      "name": "Rock_Basalt"
    },
    {
      "x": 2,
      "y": 31,
      "z": -1,
      "name": "Rock_Basalt"
    },
    {
      "x": 2,
      "y": 32,
      "z": -1,
      "name": "Rock_Basalt"
    },
    {
      "x": 2,
      "y": 33,
      "z": -1,
      "name": "Rock_Basalt"
    },
    {
      "x": 2,
      "y": 15,
      "z": 0,
      "name": "Rock_Basalt"
    },
    {
      "x": 2,
      "y": 16,
      "z": 0,
      "name": "Rock_Basalt"
    },
    {
      "x": 2,
      "y": 17,
      "z": 0,
      "name": "Rock_Basalt"
    },
    {
      "x": 2,
      "y": 18,
      "z": 0,
      "name": "Rock_Basalt"
    },
    {
      "x": 2,
      "y": 19,
      "z": 0,
      "name": "Rock_Basalt"
    },
    {
      "x": 2,
      "y": 20,
      "z": 0,
      "name": "Rock_Basalt"
    },
    {
      "x": 2,
      "y": 21,
      "z": 0,
      "name": "Rock_Basalt"
    },
    {
      "x": 2,
      "y": 22,
      "z": 0,
      "name": "Rock_Basalt"
    },
    {
      "x": 2,
      "y": 23,
      "z": 0,
      "name": "Rock_Basalt"
    },
    {
      "x": 2,
      "y": 24,
      "z": 0,
      "name": "Rock_Basalt"
    },
    {
      "x": 2,
      "y": 25,
      "z": 0,
      "name": "Rock_Basalt"
    },
    {
      "x": 2,
      "y": 26,
      "z": 0,
      "name": "Rock_Basalt"
    },
    {
      "x": 2,
      "y": 27,
      "z": 0,
      "name": "Rock_Basalt"
    },
    {
      "x": 2,
      "y": 28,
      "z": 0,
      "name": "Rock_Basalt"
    },
    {
      "x": 2,
      "y": 29,
      "z": 0,
      "name": "Rock_Basalt"
    },
    {
      "x": 2,
      "y": 30,
      "z": 0,
      "name": "Rock_Basalt"
    },
    {
      "x": 2,
      "y": 31,
      "z": 0,
      "name": "Rock_Basalt"
    },
    {
      "x": 2,
      "y": 32,
      "z": 0,
      "name": "Rock_Basalt"
    },
    {
      "x": 2,
      "y": 33,
      "z": 0,
      "name": "Rock_Basalt"
    },
    {
      "x": 2,
      "y": 13,
      "z": 1,
      "name": "Rock_Basalt"
    },
    {
      "x": 2,
      "y": 14,
      "z": 1,
      "name": "Rock_Basalt"
    },
    {
      "x": 2,
      "y": 15,
      "z": 1,
      "name": "Rock_Basalt"
    },
    {
      "x": 2,
      "y": 16,
      "z": 1,
      "name": "Rock_Basalt"
    },
    {
      "x": 2,
      "y": 17,
      "z": 1,
      "name": "Rock_Basalt"
    },
    {
      "x": 2,
      "y": 18,
      "z": 1,
      "name": "Rock_Basalt"
    },
    {
      "x": 2,
      "y": 19,
      "z": 1,
      "name": "Rock_Basalt"
    },
    {
      "x": 2,
      "y": 20,
      "z": 1,
      "name": "Rock_Basalt"
    },
    {
      "x": 2,
      "y": 21,
      "z": 1,
      "name": "Rock_Basalt"
    },
    {
      "x": 2,
      "y": 22,
      "z": 1,
      "name": "Rock_Basalt"
    },
    {
      "x": 2,
      "y": 23,
      "z": 1,
      "name": "Rock_Basalt"
    },
    {
      "x": 2,
      "y": 24,
      "z": 1,
      "name": "Rock_Basalt"
    },
    {
      "x": 2,
      "y": 25,
      "z": 1,
      "name": "Rock_Basalt"
    },
    {
      "x": 2,
      "y": 26,
      "z": 1,
      "name": "Rock_Basalt"
    },
    {
      "x": 2,
      "y": 27,
      "z": 1,
      "name": "Rock_Basalt"
    },
    {
      "x": 2,
      "y": 28,
      "z": 1,
      "name": "Rock_Basalt"
    },
    {
      "x": 2,
      "y": 29,
      "z": 1,
      "name": "Rock_Basalt"
    },
    {
      "x": 2,
      "y": 30,
      "z": 1,
      "name": "Rock_Basalt"
    },
    {
      "x": 2,
      "y": 31,
      "z": 1,
      "name": "Rock_Basalt"
    },
    {
      "x": 2,
      "y": 32,
      "z": 1,
      "name": "Rock_Basalt"
    },
    {
      "x": 2,
      "y": 33,
      "z": 1,
      "name": "Rock_Basalt"
    },
    {
      "x": 2,
      "y": 34,
      "z": 1,
      "name": "Rock_Basalt"
    },
    {
      "x": 2,
      "y": 16,
      "z": 2,
      "name": "Rock_Basalt"
    },
    {
      "x": 2,
      "y": 17,
      "z": 2,
      "name": "Rock_Basalt"
    },
    {
      "x": 2,
      "y": 18,
      "z": 2,
      "name": "Rock_Basalt"
    },
    {
      "x": 2,
      "y": 19,
      "z": 2,
      "name": "Rock_Basalt"
    },
    {
      "x": 2,
      "y": 20,
      "z": 2,
      "name": "Rock_Basalt"
    },
    {
      "x": 2,
      "y": 21,
      "z": 2,
      "name": "Rock_Basalt"
    },
    {
      "x": 2,
      "y": 22,
      "z": 2,
      "name": "Rock_Basalt"
    },
    {
      "x": 2,
      "y": 23,
      "z": 2,
      "name": "Rock_Basalt"
    },
    {
      "x": 2,
      "y": 24,
      "z": 2,
      "name": "Rock_Basalt"
    },
    {
      "x": 2,
      "y": 25,
      "z": 2,
      "name": "Rock_Basalt"
    },
    {
      "x": 2,
      "y": 26,
      "z": 2,
      "name": "Rock_Basalt"
    },
    {
      "x": 2,
      "y": 27,
      "z": 2,
      "name": "Rock_Basalt"
    },
    {
      "x": 2,
      "y": 28,
      "z": 2,
      "name": "Rock_Basalt"
    },
    {
      "x": 2,
      "y": 29,
      "z": 2,
      "name": "Rock_Basalt"
    },
    {
      "x": 2,
      "y": 30,
      "z": 2,
      "name": "Rock_Basalt"
    },
    {
      "x": 2,
      "y": 31,
      "z": 2,
      "name": "Rock_Basalt"
    },
    {
      "x": 2,
      "y": 32,
      "z": 2,
      "name": "Rock_Basalt"
    },
    {
      "x": 2,
      "y": 33,
      "z": 2,
      "name": "Rock_Basalt"
    },
    {
      "x": 2,
      "y": 19,
      "z": 3,
      "name": "Rock_Basalt"
    },
    {
      "x": 2,
      "y": 20,
      "z": 3,
      "name": "Rock_Basalt"
    },
    {
      "x": 2,
      "y": 21,
      "z": 3,
      "name": "Rock_Basalt"
    },
    {
      "x": 2,
      "y": 22,
      "z": 3,
      "name": "Rock_Basalt"
    },
    {
      "x": 2,
      "y": 23,
      "z": 3,
      "name": "Rock_Basalt"
    },
    {
      "x": 2,
      "y": 24,
      "z": 3,
      "name": "Rock_Basalt"
    },
    {
      "x": 2,
      "y": 25,
      "z": 3,
      "name": "Rock_Basalt"
    },
    {
      "x": 2,
      "y": 26,
      "z": 3,
      "name": "Rock_Basalt"
    },
    {
      "x": 2,
      "y": 27,
      "z": 3,
      "name": "Rock_Basalt"
    },
    {
      "x": 2,
      "y": 28,
      "z": 3,
      "name": "Rock_Basalt"
    },
    {
      "x": 2,
      "y": 29,
      "z": 3,
      "name": "Rock_Basalt"
    },
    {
      "x": 2,
      "y": 30,
      "z": 3,
      "name": "Rock_Basalt"
    },
    {
      "x": 2,
      "y": 31,
      "z": 3,
      "name": "Rock_Basalt"
    },
    {
      "x": 2,
      "y": 32,
      "z": 3,
      "name": "Rock_Basalt"
    },
    {
      "x": 2,
      "y": 24,
      "z": 4,
      "name": "Rock_Basalt"
    },
    {
      "x": 2,
      "y": 25,
      "z": 4,
      "name": "Rock_Basalt"
    },
    {
      "x": 2,
      "y": 26,
      "z": 4,
      "name": "Rock_Basalt"
    },
    {
      "x": 2,
      "y": 27,
      "z": 4,
      "name": "Rock_Basalt"
    },
    {
      "x": 2,
      "y": 28,
      "z": 4,
      "name": "Rock_Basalt"
    },
    {
      "x": 2,
      "y": 29,
      "z": 4,
      "name": "Rock_Basalt"
    },
    {
      "x": 2,
      "y": 30,
      "z": 4,
      "name": "Rock_Basalt"
    },
    {
      "x": 2,
      "y": 31,
      "z": 4,
      "name": "Rock_Basalt"
    },
    {
      "x": 2,
      "y": 27,
      "z": 5,
      "name": "Rock_Basalt"
    },
    {
      "x": 2,
      "y": 28,
      "z": 5,
      "name": "Rock_Basalt"
    },
    {
      "x": 2,
      "y": 29,
      "z": 5,
      "name": "Rock_Basalt"
    },
    {
      "x": 3,
      "y": 26,
      "z": -2,
      "name": "Rock_Basalt"
    },
    {
      "x": 3,
      "y": 27,
      "z": -2,
      "name": "Rock_Basalt"
    },
    {
      "x": 3,
      "y": 28,
      "z": -2,
      "name": "Rock_Basalt"
    },
    {
      "x": 3,
      "y": 29,
      "z": -2,
      "name": "Rock_Basalt"
    },
    {
      "x": 3,
      "y": 30,
      "z": -2,
      "name": "Rock_Basalt"
    },
    {
      "x": 3,
      "y": 22,
      "z": -1,
      "name": "Rock_Basalt"
    },
    {
      "x": 3,
      "y": 23,
      "z": -1,
      "name": "Rock_Basalt"
    },
    {
      "x": 3,
      "y": 24,
      "z": -1,
      "name": "Rock_Basalt"
    },
    {
      "x": 3,
      "y": 25,
      "z": -1,
      "name": "Rock_Basalt"
    },
    {
      "x": 3,
      "y": 26,
      "z": -1,
      "name": "Rock_Basalt"
    },
    {
      "x": 3,
      "y": 27,
      "z": -1,
      "name": "Rock_Basalt"
    },
    {
      "x": 3,
      "y": 28,
      "z": -1,
      "name": "Rock_Basalt"
    },
    {
      "x": 3,
      "y": 29,
      "z": -1,
      "name": "Rock_Basalt"
    },
    {
      "x": 3,
      "y": 30,
      "z": -1,
      "name": "Rock_Basalt"
    },
    {
      "x": 3,
      "y": 31,
      "z": -1,
      "name": "Rock_Basalt"
    },
    {
      "x": 3,
      "y": 32,
      "z": -1,
      "name": "Rock_Basalt"
    },
    {
      "x": 3,
      "y": 20,
      "z": 0,
      "name": "Rock_Basalt"
    },
    {
      "x": 3,
      "y": 21,
      "z": 0,
      "name": "Rock_Basalt"
    },
    {
      "x": 3,
      "y": 22,
      "z": 0,
      "name": "Rock_Basalt"
    },
    {
      "x": 3,
      "y": 23,
      "z": 0,
      "name": "Rock_Basalt"
    },
    {
      "x": 3,
      "y": 24,
      "z": 0,
      "name": "Rock_Basalt"
    },
    {
      "x": 3,
      "y": 25,
      "z": 0,
      "name": "Rock_Basalt"
    },
    {
      "x": 3,
      "y": 26,
      "z": 0,
      "name": "Rock_Basalt"
    },
    {
      "x": 3,
      "y": 27,
      "z": 0,
      "name": "Rock_Basalt"
    },
    {
      "x": 3,
      "y": 28,
      "z": 0,
      "name": "Rock_Basalt"
    },
    {
      "x": 3,
      "y": 29,
      "z": 0,
      "name": "Rock_Basalt"
    },
    {
      "x": 3,
      "y": 30,
      "z": 0,
      "name": "Rock_Basalt"
    },
    {
      "x": 3,
      "y": 31,
      "z": 0,
      "name": "Rock_Basalt"
    },
    {
      "x": 3,
      "y": 32,
      "z": 0,
      "name": "Rock_Basalt"
    },
    {
      "x": 3,
      "y": 19,
      "z": 1,
      "name": "Rock_Basalt"
    },
    {
      "x": 3,
      "y": 20,
      "z": 1,
      "name": "Rock_Basalt"
    },
    {
      "x": 3,
      "y": 21,
      "z": 1,
      "name": "Rock_Basalt"
    },
    {
      "x": 3,
      "y": 22,
      "z": 1,
      "name": "Rock_Basalt"
    },
    {
      "x": 3,
      "y": 23,
      "z": 1,
      "name": "Rock_Basalt"
    },
    {
      "x": 3,
      "y": 24,
      "z": 1,
      "name": "Rock_Basalt"
    },
    {
      "x": 3,
      "y": 25,
      "z": 1,
      "name": "Rock_Basalt"
    },
    {
      "x": 3,
      "y": 26,
      "z": 1,
      "name": "Rock_Basalt"
    },
    {
      "x": 3,
      "y": 27,
      "z": 1,
      "name": "Rock_Basalt"
    },
    {
      "x": 3,
      "y": 28,
      "z": 1,
      "name": "Rock_Basalt"
    },
    {
      "x": 3,
      "y": 29,
      "z": 1,
      "name": "Rock_Basalt"
    },
    {
      "x": 3,
      "y": 30,
      "z": 1,
      "name": "Rock_Basalt"
    },
    {
      "x": 3,
      "y": 31,
      "z": 1,
      "name": "Rock_Basalt"
    },
    {
      "x": 3,
      "y": 32,
      "z": 1,
      "name": "Rock_Basalt"
    },
    {
      "x": 3,
      "y": 33,
      "z": 1,
      "name": "Rock_Basalt"
    },
    {
      "x": 3,
      "y": 20,
      "z": 2,
      "name": "Rock_Basalt"
    },
    {
      "x": 3,
      "y": 21,
      "z": 2,
      "name": "Rock_Basalt"
    },
    {
      "x": 3,
      "y": 22,
      "z": 2,
      "name": "Rock_Basalt"
    },
    {
      "x": 3,
      "y": 23,
      "z": 2,
      "name": "Rock_Basalt"
    },
    {
      "x": 3,
      "y": 24,
      "z": 2,
      "name": "Rock_Basalt"
    },
    {
      "x": 3,
      "y": 25,
      "z": 2,
      "name": "Rock_Basalt"
    },
    {
      "x": 3,
      "y": 26,
      "z": 2,
      "name": "Rock_Basalt"
    },
    {
      "x": 3,
      "y": 27,
      "z": 2,
      "name": "Rock_Basalt"
    },
    {
      "x": 3,
      "y": 28,
      "z": 2,
      "name": "Rock_Basalt"
    },
    {
      "x": 3,
      "y": 29,
      "z": 2,
      "name": "Rock_Basalt"
    },
    {
      "x": 3,
      "y": 30,
      "z": 2,
      "name": "Rock_Basalt"
    },
    {
      "x": 3,
      "y": 31,
      "z": 2,
      "name": "Rock_Basalt"
    },
    {
      "x": 3,
      "y": 32,
      "z": 2,
      "name": "Rock_Basalt"
    },
    {
      "x": 3,
      "y": 22,
      "z": 3,
      "name": "Rock_Basalt"
    },
    {
      "x": 3,
      "y": 23,
      "z": 3,
      "name": "Rock_Basalt"
    },
    {
      "x": 3,
      "y": 24,
      "z": 3,
      "name": "Rock_Basalt"
    },
    {
      "x": 3,
      "y": 25,
      "z": 3,
      "name": "Rock_Basalt"
    },
    {
      "x": 3,
      "y": 26,
      "z": 3,
      "name": "Rock_Basalt"
    },
    {
      "x": 3,
      "y": 27,
      "z": 3,
      "name": "Rock_Basalt"
    },
    {
      "x": 3,
      "y": 28,
      "z": 3,
      "name": "Rock_Basalt"
    },
    {
      "x": 3,
      "y": 29,
      "z": 3,
      "name": "Rock_Basalt"
    },
    {
      "x": 3,
      "y": 30,
      "z": 3,
      "name": "Rock_Basalt"
    },
    {
      "x": 3,
      "y": 31,
      "z": 3,
      "name": "Rock_Basalt"
    },
    {
      "x": 3,
      "y": 26,
      "z": 4,
      "name": "Rock_Basalt"
    },
    {
      "x": 3,
      "y": 27,
      "z": 4,
      "name": "Rock_Basalt"
    },
    {
      "x": 3,
      "y": 28,
      "z": 4,
      "name": "Rock_Basalt"
    },
    {
      "x": 3,
      "y": 29,
      "z": 4,
      "name": "Rock_Basalt"
    },
    {
      "x": 3,
      "y": 30,
      "z": 4,
      "name": "Rock_Basalt"
    },
    {
      "x": 4,
      "y": 28,
      "z": -2,
      "name": "Rock_Basalt"
    },
    {
      "x": 4,
      "y": 29,
      "z": -2,
      "name": "Rock_Basalt"
    },
    {
      "x": 4,
      "y": 26,
      "z": -1,
      "name": "Rock_Basalt"
    },
    {
      "x": 4,
      "y": 27,
      "z": -1,
      "name": "Rock_Basalt"
    },
    {
      "x": 4,
      "y": 28,
      "z": -1,
      "name": "Rock_Basalt"
    },
    {
      "x": 4,
      "y": 29,
      "z": -1,
      "name": "Rock_Basalt"
    },
    {
      "x": 4,
      "y": 30,
      "z": -1,
      "name": "Rock_Basalt"
    },
    {
      "x": 4,
      "y": 24,
      "z": 0,
      "name": "Rock_Basalt"
    },
    {
      "x": 4,
      "y": 25,
      "z": 0,
      "name": "Rock_Basalt"
    },
    {
      "x": 4,
      "y": 26,
      "z": 0,
      "name": "Rock_Basalt"
    },
    {
      "x": 4,
      "y": 27,
      "z": 0,
      "name": "Rock_Basalt"
    },
    {
      "x": 4,
      "y": 28,
      "z": 0,
      "name": "Rock_Basalt"
    },
    {
      "x": 4,
      "y": 29,
      "z": 0,
      "name": "Rock_Basalt"
    },
    {
      "x": 4,
      "y": 30,
      "z": 0,
      "name": "Rock_Basalt"
    },
    {
      "x": 4,
      "y": 31,
      "z": 0,
      "name": "Rock_Basalt"
    },
    {
      "x": 4,
      "y": 32,
      "z": 0,
      "name": "Rock_Basalt"
    },
    {
      "x": 4,
      "y": 24,
      "z": 1,
      "name": "Rock_Basalt"
    },
    {
      "x": 4,
      "y": 25,
      "z": 1,
      "name": "Rock_Basalt"
    },
    {
      "x": 4,
      "y": 26,
      "z": 1,
      "name": "Rock_Basalt"
    },
    {
      "x": 4,
      "y": 27,
      "z": 1,
      "name": "Rock_Basalt"
    },
    {
      "x": 4,
      "y": 28,
      "z": 1,
      "name": "Rock_Basalt"
    },
    {
      "x": 4,
      "y": 29,
      "z": 1,
      "name": "Rock_Basalt"
    },
    {
      "x": 4,
      "y": 30,
      "z": 1,
      "name": "Rock_Basalt"
    },
    {
      "x": 4,
      "y": 31,
      "z": 1,
      "name": "Rock_Basalt"
    },
    {
      "x": 4,
      "y": 32,
      "z": 1,
      "name": "Rock_Basalt"
    },
    {
      "x": 4,
      "y": 25,
      "z": 2,
      "name": "Rock_Basalt"
    },
    {
      "x": 4,
      "y": 26,
      "z": 2,
      "name": "Rock_Basalt"
    },
    {
      "x": 4,
      "y": 27,
      "z": 2,
      "name": "Rock_Basalt"
    },
    {
      "x": 4,
      "y": 28,
      "z": 2,
      "name": "Rock_Basalt"
    },
    {
      "x": 4,
      "y": 29,
      "z": 2,
      "name": "Rock_Basalt"
    },
    {
      "x": 4,
      "y": 30,
      "z": 2,
      "name": "Rock_Basalt"
    },
    {
      "x": 4,
      "y": 31,
      "z": 2,
      "name": "Rock_Basalt"
    },
    {
      "x": 4,
      "y": 32,
      "z": 2,
      "name": "Rock_Basalt"
    },
    {
      "x": 4,
      "y": 26,
      "z": 3,
      "name": "Rock_Basalt"
    },
    {
      "x": 4,
      "y": 27,
      "z": 3,
      "name": "Rock_Basalt"
    },
    {
      "x": 4,
      "y": 28,
      "z": 3,
      "name": "Rock_Basalt"
    }
  ]
}