{
  "version": 8,
  "blockIdVersion": 8,
  "anchorX": 3,
  "anchorY": 46,
  "anchorZ": 21,
  "blocks": [
    {
      "x": -6,
      "y": 45,
      "z": 3,
      "name": "Rock_Sandstone_Cobble"
    },
    {
      "x": -6,
      "y": 46,
      "z": 3,
      "name": "Rock_Sandstone_Cobble"
    },
    {
      "x": -6,
      "y": 47,
      "z": 3,
      "name": "Rock_Sandstone_Brick_Ornate"
    },
    {
      "x": -6,
      "y": 48,
      "z": 3,
      "name": "Rock_Sandstone_Cobble"
    },
    {
      "x": -6,
      "y": 49,
      "z": 3,
      "name": "Rock_Sandstone_Cobble"
    },
    {
      "x": -6,
      "y": 50,
      "z": 3,
      "name": "Rock_Sandstone_Cobble"
    },
    {
      "x": -6,
      "y": 51,
      "z": 3,
      "name": "Rock_Sandstone_Cobble"
    },
    {
      "x": -6,
      "y": 45,
      "z": 4,
      "name": "Rock_Sandstone_Cobble"
    },
    {
      "x": -6,
      "y": 46,
      "z": 4,
      "name": "Rock_Sandstone_Cobble"
    },
    {
      "x": -6,
      "y": 47,
      "z": 4,
      "name": "Rock_Sandstone_Brick_Ornate"
    },
    {
      "x": -6,
      "y": 48,
      "z": 4,
      "name": "Rock_Sandstone_Cobble"
    },
    {
      "x": -6,
      "y": 49,
      "z": 4,
      "name": "Rock_Sandstone_Cobble"
    },
    {
      "x": -6,
      "y": 50,
      "z": 4,
      "name": "Rock_Sandstone_Cobble"
    },
    {
      "x": -6,
      "y": 51,
      "z": 4,
      "name": "Rock_Sandstone_Cobble"
    },
    {
      "x": -6,
      "y": 45,
      "z": 5,
      "name": "Rock_Sandstone_Cobble"
    },
    {
      "x": -6,
      "y": 46,
      "z": 5,
      "name": "Cloth_Block_Wool_Orange"
    },
    {
      "x": -6,
      "y": 47,
      "z": 5,
      "name": "Empty"
    },
    {
      "x": -6,
      "y": 48,
      "z": 5,
      "name": "Empty"
    },
    {
      "x": -6,
      "y": 49,
      "z": 5,
      "name": "Empty"
    },
    {
      "x": -6,
      "y": 50,
      "z": 5,
      "name": "Rock_Sandstone_Cobble"
    },
    {
      "x": -6,
      "y": 51,
      "z": 5,
      "name": "Rock_Sandstone_Cobble"
    },
    {
      "x": -6,
      "y": 45,
      "z": 6,
      "name": "Rock_Sandstone_Cobble"
    },
    {
      "x": -6,
      "y": 46,
      "z": 6,
      "name": "Cloth_Block_Wool_Orange"
    },
    {
      "x": -6,
      "y": 47,
      "z": 6,
      "name": "Empty"
    },
    {
      "x": -6,
      "y": 48,
      "z": 6,
      "name": "Empty"
    },
    {
      "x": -6,
      "y": 49,
      "z": 6,
      "name": "Empty"
    },
    {
      "x": -6,
      "y": 50,
      "z": 6,
      "name": "Rock_Sandstone_Cobble"
    },
    {
      "x": -6,
      "y": 51,
      "z": 6,
      "name": "Rock_Sandstone_Cobble"
    },
    {
      "x": -6,
      "y": 45,
      "z": 7,
      "name": "Rock_Sandstone_Cobble"
    },
    {
      "x": -6,
      "y": 46,
      "z": 7,
      "name": "Wood_Goldenwood_Planks"
    },
    {
      "x": -6,
      "y": 47,
      "z": 7,
      "name": "Empty"
    },
    {
      "x": -6,
      "y": 48,
      "z": 7,
      "name": "Empty"
    },
    {
      "x": -6,
      "y": 49,
      "z": 7,
      "name": "Empty"
    },
    {
      "x": -6,
      "y": 50,
      "z": 7,
      "name": "Rock_Sandstone_Cobble"
    },
    {
      "x": -6,
      "y": 51,
      "z": 7,
      "name": "Rock_Sandstone_Cobble"
    },
    {
      "x": -6,
      "y": 45,
      "z": 8,
      "name": "Rock_Sandstone_Cobble"
    },
    {
      "x": -6,
      "y": 46,
      "z": 8,
      "name": "Rock_Sandstone_Cobble"
    },
    {
      "x": -6,
      "y": 47,
      "z": 8,
      "name": "Rock_Sandstone_Brick_Ornate"
    },
    {
      "x": -6,
      "y": 48,
      "z": 8,
      "name": "Rock_Sandstone_Cobble"
    },
    {
      "x": -6,
      "y": 49,
      "z": 8,
      "name": "Rock_Sandstone_Cobble"
    },
    {
      "x": -6,
      "y": 50,
      "z": 8,
      "name": "Rock_Sandstone_Cobble"
    },
    {
      "x": -6,
      "y": 51,
      "z": 8,
      "name": "Rock_Sandstone_Cobble"
    },
    {
      "x": -6,
      "y": 45,
      "z": 9,
      "name": "Rock_Sandstone_Cobble"
    },
    {
      "x": -6,
      "y": 46,
      "z": 9,
      "name": "Rock_Sandstone_Cobble"
    },
    {
      "x": -6,
      "y": 47,
      "z": 9,
      "name": "Rock_Sandstone_Brick_Ornate"
    },
    {
      "x": -6,
      "y": 48,
      "z": 9,
      "name": "Rock_Sandstone_Cobble"
    },
    {
      "x": -6,
      "y": 49,
      "z": 9,
      "name": "Rock_Sandstone_Cobble"
    },
    {
      "x": -6,
      "y": 50,
      "z": 9,
      "name": "Rock_Sandstone_Cobble"
    },
    {
      "x": -6,
      "y": 51,
      "z": 9,
      "name": "Rock_Sandstone_Cobble"
    },
    {
      "x": -6,
      "y": 45,
      "z": 10,
      "name": "Rock_Sandstone_Cobble"
    },
    {
      "x": -6,
      "y": 46,
      "z": 10,
      "name": "Rock_Sandstone_Cobble"
    },
    {
      "x": -6,
      "y": 47,
      "z": 10,
      "name": "Rock_Sandstone_Brick_Ornate"
    },
    {
      "x": -6,
      "y": 48,
      "z": 10,
      "name": "Rock_Sandstone_Cobble"
    },
    {
      "x": -6,
      "y": 49,
      "z": 10,
      "name": "Rock_Sandstone_Cobble"
    },
    {
      "x": -6,
      "y": 50,
      "z": 10,
      "name": "Rock_Sandstone_Cobble"
    },
    {
      "x": -6,
      "y": 51,
      "z": 10,
      "name": "Rock_Sandstone_Cobble"
    },
    {
      "x": -6,
      "y": 45,
      "z": 11,
      "name": "Rock_Sandstone_Cobble"
    },
    {
      "x": -6,
      "y": 46,
      "z": 11,
      "name": "Rock_Sandstone_Cobble"
    },
    {
      "x": -6,
      "y": 47,
      "z": 11,
      "name": "Rock_Sandstone_Brick_Ornate"
    },
    {
      "x": -6,
      "y": 48,
      "z": 11,
      "name": "Rock_Sandstone_Cobble"
    },
    {
      "x": -6,
      "y": 49,
      "z": 11,
      "name": "Rock_Sandstone_Cobble"
    },
    {
      "x": -6,
      "y": 50,
      "z": 11,
      "name": "Rock_Sandstone_Cobble"
    },
    {
      "x": -6,
      "y": 51,
      "z": 11,
      "name": "Rock_Sandstone_Cobble"
    },
    {
      "x": -6,
      "y": 45,
      "z": 12,
      "name": "Rock_Sandstone_Cobble"
    },
    {
      "x": -6,
      "y": 46,
      "z": 12,
      "name": "Rock_Sandstone_Cobble"
    },
    {
      "x": -6,
      "y": 47,
      "z": 12,
      "name": "Rock_Sandstone_Brick_Ornate"
    },
    {
      "x": -6,
      "y": 48,
      "z": 12,
      "name": "Rock_Sandstone_Cobble"
    },
    {
      "x": -6,
      "y": 49,
      "z": 12,
      "name": "Rock_Sandstone_Cobble"
    },
    {
      "x": -6,
      "y": 50,
      "z": 12,
      "name": "Rock_Sandstone_Cobble"
    },
    {
      "x": -6,
      "y": 51,
      "z": 12,
      "name": "Rock_Sandstone_Cobble"
    },
    {
      "x": -6,
      "y": 45,
      "z": 13,
      "name": "Rock_Sandstone_Cobble"
    },
    {
      "x": -6,
      "y": 46,
      "z": 13,
      "name": "Rock_Sandstone_Cobble"
    },
    {
      "x": -6,
      "y": 47,
      "z": 13,
      "name": "Rock_Sandstone_Brick_Ornate"
    },
    {
      "x": -6,
      "y": 48,
      "z": 13,
      "name": "Rock_Sandstone_Cobble"
    },
    {
      "x": -6,
      "y": 49,
      "z": 13,
      "name": "Rock_Sandstone_Cobble"
    },
    {
      "x": -6,
      "y": 50,
      "z": 13,
      "name": "Rock_Sandstone_Cobble"
    },
    {
      "x": -6,
      "y": 51,
      "z": 13,
      "name": "Rock_Sandstone_Cobble"
    },
    {
      "x": -6,
      "y": 45,
      "z": 14,
      "name": "Rock_Sandstone_Cobble"
    },
    {
      "x": -6,
      "y": 46,
      "z": 14,
      "name": "Rock_Sandstone_Cobble"
    },
    {
      "x": -6,
      "y": 47,
      "z": 14,
      "name": "Rock_Sandstone_Brick_Ornate"
    },
    {
      "x": -6,
      "y": 48,
      "z": 14,
      "name": "Rock_Sandstone_Cobble"
    },
    {
      "x": -6,
      "y": 49,
      "z": 14,
      "name": "Rock_Sandstone_Cobble"
    },
    {
      "x": -6,
      "y": 50,
      "z": 14,
      "name": "Rock_Sandstone_Cobble"
    },
    {
      "x": -6,
      "y": 51,
      "z": 14,
      "name": "Rock_Sandstone_Cobble"
    },
    {
      "x": -6,
      "y": 45,
      "z": 15,
      "name": "Rock_Sandstone_Cobble"
    },
    {
      "x": -6,
      "y": 46,
      "z": 15,
      "name": "Rock_Sandstone_Cobble"
    },
    {
      "x": -6,
      "y": 47,
      "z": 15,
      "name": "Rock_Sandstone_Brick_Ornate"
    },
    {
      "x": -6,
      "y": 48,
      "z": 15,
      "name": "Rock_Sandstone_Cobble"
    },
    {
      "x": -6,
      "y": 49,
      "z": 15,
      "name": "Rock_Sandstone_Cobble"
    },
    {
      "x": -6,
      "y": 50,
      "z": 15,
      "name": "Rock_Sandstone_Cobble"
    },
    {
      "x": -6,
      "y": 51,
      "z": 15,
      "name": "Rock_Sandstone_Cobble"
    },
    {
      "x": -6,
      "y": 45,
      "z": 16,
      "name": "Rock_Sandstone_Cobble"
    },
    {
      "x": -6,
      "y": 46,
      "z": 16,
      "name": "Rock_Sandstone_Cobble"
    },
    {
      "x": -6,
      "y": 47,
      "z": 16,
      "name": "Rock_Sandstone_Brick_Ornate"
    },
    {
      "x": -6,
      "y": 48,
      "z": 16,
      "name": "Rock_Sandstone_Cobble"
    },
    {
      "x": -6,
      "y": 49,
      "z": 16,
      "name": "Rock_Sandstone_Cobble"
    },
    {
      "x": -6,
      "y": 50,
      "z": 16,
      "name": "Rock_Sandstone_Cobble"
    },
    {
      "x": -6,
      "y": 51,
      "z": 16,
      "name": "Rock_Sandstone_Cobble"
    },
    {
      "x": -6,
      "y": 45,
      "z": 17,
      "name": "Rock_Sandstone_Cobble"
    },
    {
      "x": -6,
      "y": 46,
      "z": 17,
      "name": "Rock_Sandstone_Cobble"
    },
    {
      "x": -6,
      "y": 47,
      "z": 17,
      "name": "Rock_Sandstone_Brick_Ornate"
    },
    {
      "x": -6,
      "y": 48,
      "z": 17,
      "name": "Rock_Sandstone_Cobble"
    },
    {
      "x": -6,
      "y": 49,
      "z": 17,
      "name": "Rock_Sandstone_Cobble"
    },
    {
      "x": -6,
      "y": 50,
      "z": 17,
      "name": "Rock_Sandstone_Cobble"
    },
    {
      "x": -6,
      "y": 51,
      "z": 17,
      "name": "Rock_Sandstone_Cobble"
    },
    {
      "x": -6,
      "y": 45,
      "z": 18,
      "name": "Rock_Sandstone_Cobble"
    },
    {
      "x": -6,
      "y": 46,
      "z": 18,
      "name": "Rock_Sandstone_Cobble"
    },
    {
      "x": -6,
      "y": 47,
      "z": 18,
      "name": "Rock_Sandstone_Brick_Ornate"
    },
    {
      "x": -6,
      "y": 48,
      "z": 18,
      "name": "Rock_Sandstone_Cobble"
    },
    {
      "x": -6,
      "y": 49,
      "z": 18,
      "name": "Rock_Sandstone_Cobble"
    },
    {
      "x": -6,
      "y": 50,
      "z": 18,
      "name": "Rock_Sandstone_Cobble"
    },
    {
      "x": -6,
      "y": 51,
      "z": 18,
      "name": "Rock_Sandstone_Cobble"
    },
    {
      "x": -6,
      "y": 45,
      "z": 19,
      "name": "Rock_Sandstone_Cobble"
    },
    {
      "x": -6,
      "y": 46,
      "z": 19,
      "name": "Rock_Sandstone_Cobble"
    },
    {
      "x": -6,
      "y": 47,
      "z": 19,
      "name": "Rock_Sandstone_Brick_Ornate"
    },
    {
      "x": -6,
      "y": 48,
      "z": 19,
      "name": "Rock_Sandstone_Cobble"
    },
    {
      "x": -6,
      "y": 49,
      "z": 19,
      "name": "Rock_Sandstone_Cobble"
    },
    {
      "x": -6,
      "y": 50,
      "z": 19,
      "name": "Rock_Sandstone_Cobble"
    },
    {
      "x": -6,
      "y": 51,
      "z": 19,
      "name": "Rock_Sandstone_Cobble"
    },
    {
      "x": -6,
      "y": 45,
      "z": 20,
      "name": "Rock_Sandstone_Cobble"
    },
    {
      "x": -6,
      "y": 46,
      "z": 20,
      "name": "Rock_Sandstone_Cobble"
    },
    {
      "x": -6,
      "y": 47,
      "z": 20,
      "name": "Rock_Sandstone_Brick_Ornate"
    },
    {
      "x": -6,
      "y": 48,
      "z": 20,
      "name": "Rock_Sandstone_Cobble"
    },
    {
      "x": -6,
      "y": 49,
      "z": 20,
      "name": "Rock_Sandstone_Cobble"
    },
    {
      "x": -6,
      "y": 50,
      "z": 20,
      "name": "Rock_Sandstone_Cobble"
    },
    {
      "x": -6,
      "y": 51,
      "z": 20,
      "name": "Rock_Sandstone_Cobble"
    },
    {
      "x": -5,
      "y": 45,
      "z": 3,
      "name": "Rock_Sandstone_Cobble"
    },
    {
      "x": -5,
      "y": 46,
      "z": 3,
      "name": "Rock_Sandstone_Cobble"
    },
    {
      "x": -5,
      "y": 47,
      "z": 3,
      "name": "Rock_Sandstone_Brick_Ornate"
    },
    {
      "x": -5,
      "y": 48,
      "z": 3,
      "name": "Rock_Sandstone_Cobble"
    },
    {
      "x": -5,
      "y": 49,
      "z": 3,
      "name": "Rock_Sandstone_Cobble"
    },
    {
      "x": -5,
      "y": 50,
      "z": 3,
      "name": "Rock_Sandstone_Cobble"
    },
    {
      "x": -5,
      "y": 51,
      "z": 3,
      "name": "Rock_Sandstone_Cobble"
    },
    {
      "x": -5,
      "y": 45,
      "z": 4,
      "name": "Rock_Sandstone_Cobble"
    },
    {
      "x": -5,
      "y": 46,
      "z": 4,
      "name": "Wood_Goldenwood_Planks"
    },
    {
      "x": -5,
      "y": 47,
      "z": 4,
      "name": "Empty"
    },
    {
      "x": -5,
      "y": 48,
      "z": 4,
      "name": "Empty"
    },
    {
      "x": -5,
      "y": 49,
      "z": 4,
      "name": "Empty"
    },
    {
      "x": -5,
      "y": 50,
      "z": 4,
      "name": "Wood_Goldenwood_Planks"
    },
    {
      "x": -5,
      "y": 51,
      "z": 4,
      "name": "Wood_Goldenwood_Planks"
    },
    {
      "x": -5,
      "y": 45,
      "z": 5,
      "name": "Rock_Sandstone_Cobble"
    },
    {
      "x": -5,
      "y": 46,
      "z": 5,
      "name": "Cloth_Block_Wool_Orange"
    },
    {
      "x": -5,
      "y": 47,
      "z": 5,
      "name": "Empty"
    },
    {
      "x": -5,
      "y": 48,
      "z": 5,
      "name": "Empty"
    },
    {
      "x": -5,
      "y": 49,
      "z": 5,
      "name": "Empty"
    },
    {
      "x": -5,
      "y": 50,
      "z": 5,
      "name": "Wood_Goldenwood_Planks_Half",
      "rotation": 5
    },
    {
      "x": -5,
      "y": 51,
      "z": 5,
      "name": "Wood_Goldenwood_Planks"
    },
    {
      "x": -5,
      "y": 45,
      "z": 6,
      "name": "Rock_Sandstone_Cobble"
    },
    {
      "x": -5,
      "y": 46,
      "z": 6,
      "name": "Cloth_Block_Wool_Orange"
    },
    {
      "x": -5,
      "y": 47,
      "z": 6,
      "name": "Cloth_Roof_Red_Flat"
    },
    {
      "x": -5,
      "y": 48,
      "z": 6,
      "name": "Empty"
    },
    {
      "x": -5,
      "y": 49,
      "z": 6,
      "name": "Empty"
    },
    {
      "x": -5,
      "y": 50,
      "z": 6,
      "name": "Wood_Goldenwood_Planks_Half",
      "rotation": 5
    },
    {
      "x": -5,
      "y": 51,
      "z": 6,
      "name": "Wood_Goldenwood_Planks"
    },
    {
      "x": -5,
      "y": 45,
      "z": 7,
      "name": "Rock_Sandstone_Cobble"
    },
    {
      "x": -5,
      "y": 46,
      "z": 7,
      "name": "Wood_Goldenwood_Planks"
    },
    {
      "x": -5,
      "y": 47,
      "z": 7,
      "name": "Cloth_Roof_Red_Flat"
    },
    {
      "x": -5,
      "y": 48,
      "z": 7,
      "name": "Empty"
    },
    {
      "x": -5,
      "y": 49,
      "z": 7,
      "name": "Empty"
    },
    {
      "x": -5,
      "y": 50,
      "z": 7,
      "name": "Wood_Goldenwood_Planks_Half",
      "rotation": 5
    },
    {
      "x": -5,
      "y": 51,
      "z": 7,
      "name": "Wood_Goldenwood_Planks"
    },
    {
      "x": -5,
      "y": 45,
      "z": 8,
      "name": "Rock_Sandstone_Cobble"
    },
    {
      "x": -5,
      "y": 46,
      "z": 8,
      "name": "Wood_Goldenwood_Planks"
    },
    {
      "x": -5,
      "y": 47,
      "z": 8,
      "name": "Furniture_Village_Counter",
      "rotation": 1
    },
    {
      "x": -5,
      "y": 48,
      "z": 8,
      "name": "Deco_Iron_Stack",
      "rotation": 1
    },
    {
      "x": -5,
      "y": 49,
      "z": 8,
      "name": "Empty"
    },
    {
      "x": -5,
      "y": 50,
      "z": 8,
      "name": "Wood_Goldenwood_Planks_Half",
      "rotation": 5
    },
    {
      "x": -5,
      "y": 51,
      "z": 8,
      "name": "Wood_Goldenwood_Planks"
    },
    {
      "x": -5,
      "y": 45,
      "z": 9,
      "name": "Rock_Sandstone_Cobble"
    },
    {
      "x": -5,
      "y": 46,
      "z": 9,
      "name": "Wood_Goldenwood_Planks"
    },
    {
      "x": -5,
      "y": 47,
      "z": 9,
      "name": "Furniture_Village_Counter",
      "filler": 32,
      "rotation": 1
    },
    {
      "x": -5,
      "y": 48,
      "z": 9,
      "name": "Furniture_Lumberjack_Shelf",
      "rotation": 1
    },
    {
      "x": -5,
      "y": 49,
      "z": 9,
      "name": "Empty"
    },
    {
      "x": -5,
      "y": 50,
      "z": 9,
      "name": "Wood_Goldenwood_Planks_Half",
      "rotation": 5
    },
    {
      "x": -5,
      "y": 51,
      "z": 9,
      "name": "Wood_Goldenwood_Planks"
    },
    {
      "x": -5,
      "y": 45,
      "z": 10,
      "name": "Rock_Sandstone_Cobble"
    },
    {
      "x": -5,
      "y": 46,
      "z": 10,
      "name": "Wood_Goldenwood_Planks"
    },
    {
      "x": -5,
      "y": 47,
      "z": 10,
      "name": "Empty"
    },
    {
      "x": -5,
      "y": 48,
      "z": 10,
      "name": "Furniture_Lumberjack_Shelf",
      "rotation": 1
    },
    {
      "x": -5,
      "y": 49,
      "z": 10,
      "name": "Deco_Iron_Stack",
      "rotation": 1
    },
    {
      "x": -5,
      "y": 50,
      "z": 10,
      "name": "Wood_Goldenwood_Planks_Half",
      "rotation": 5
    },
    {
      "x": -5,
      "y": 51,
      "z": 10,
      "name": "Wood_Goldenwood_Planks"
    },
    {
      "x": -5,
      "y": 45,
      "z": 11,
      "name": "Rock_Sandstone_Cobble"
    },
    {
      "x": -5,
      "y": 46,
      "z": 11,
      "name": "Wood_Goldenwood_Planks"
    },
    {
      "x": -5,
      "y": 47,
      "z": 11,
      "name": "Furniture_Jungle_Planter"
    },
    {
      "x": -5,
      "y": 48,
      "z": 11,
      "name": "Plant_Bush_Arid"
    },
    {
      "x": -5,
      "y": 49,
      "z": 11,
      "name": "Plant_Bush_Arid"
    },
    {
      "x": -5,
      "y": 50,
      "z": 11,
      "name": "Wood_Goldenwood_Planks"
    },
    {
      "x": -5,
      "y": 51,
      "z": 11,
      "name": "Wood_Goldenwood_Planks"
    },
    {
      "x": -5,
      "y": 45,
      "z": 12,
      "name": "Rock_Sandstone_Cobble"
    },
    {
      "x": -5,
      "y": 46,
      "z": 12,
      "name": "Wood_Goldenwood_Planks"
    },
    {
      "x": -5,
      "y": 47,
      "z": 12,
      "name": "Rock_Sandstone_Brick_Ornate"
    },
    {
      "x": -5,
      "y": 48,
      "z": 12,
      "name": "Empty"
    },
    {
      "x": -5,
      "y": 49,
      "z": 12,
      "name": "Empty"
    },
    {
      "x": -5,
      "y": 50,
      "z": 12,
      "name": "Rock_Sandstone_Cobble"
    },
    {
      "x": -5,
      "y": 51,
      "z": 12,
      "name": "Wood_Goldenwood_Planks"
    },
    {
      "x": -5,
      "y": 45,
      "z": 13,
      "name": "Rock_Sandstone_Cobble"
    },
    {
      "x": -5,
      "y": 46,
      "z": 13,
      "name": "Wood_Goldenwood_Planks"
    },
    {
      "x": -5,
      "y": 47,
      "z": 13,
      "name": "Empty"
    },
    {
      "x": -5,
      "y": 48,
      "z": 13,
      "name": "Furniture_Village_Painting_2x2",
      "rotation": 1
    },
    {
      "x": -5,
      "y": 49,
      "z": 13,
      "name": "Furniture_Village_Painting_2x2",
      "filler": 1024,
      "rotation": 1
    },
    {
      "x": -5,
      "y": 50,
      "z": 13,
      "name": "Wood_Goldenwood_Planks"
    },
    {
      "x": -5,
      "y": 51,
      "z": 13,
      "name": "Wood_Goldenwood_Planks"
    },
    {
      "x": -5,
      "y": 45,
      "z": 14,
      "name": "Rock_Sandstone_Cobble"
    },
    {
      "x": -5,
      "y": 46,
      "z": 14,
      "name": "Wood_Goldenwood_Planks"
    },
    {
      "x": -5,
      "y": 47,
      "z": 14,
      "name": "Empty"
    },
    {
      "x": -5,
      "y": 48,
      "z": 14,
      "name": "Furniture_Village_Painting_2x2",
      "filler": 32,
      "rotation": 1
    },
    {
      "x": -5,
      "y": 49,
      "z": 14,
      "name": "Furniture_Village_Painting_2x2",
      "filler": 1056,
      "rotation": 1
    },
    {
      "x": -5,
      "y": 50,
      "z": 14,
      "name": "Wood_Goldenwood_Planks_Half",
      "rotation": 5
    },
    {
      "x": -5,
      "y": 51,
      "z": 14,
      "name": "Wood_Goldenwood_Planks"
    },
    {
      "x": -5,
      "y": 45,
      "z": 15,
      "name": "Rock_Sandstone_Cobble"
    },
    {
      "x": -5,
      "y": 46,
      "z": 15,
      "name": "Wood_Goldenwood_Planks"
    },
    {
      "x": -5,
      "y": 47,
      "z": 15,
      "name": "Furniture_Village_Bookcase",
      "rotation": 1
    },
    {
      "x": -5,
      "y": 48,
      "z": 15,
      "name": "Furniture_Village_Bookcase",
      "rotation": 1
    },
    {
      "x": -5,
      "y": 49,
      "z": 15,
      "name": "Furniture_Village_Bookcase",
      "rotation": 1
    },
    {
      "x": -5,
      "y": 50,
      "z": 15,
      "name": "Wood_Goldenwood_Planks_Half",
      "rotation": 5
    },
    {
      "x": -5,
      "y": 51,
      "z": 15,
      "name": "Wood_Goldenwood_Planks"
    },
    {
      "x": -5,
      "y": 45,
      "z": 16,
      "name": "Rock_Sandstone_Cobble"
    },
    {
      "x": -5,
      "y": 46,
      "z": 16,
      "name": "Wood_Goldenwood_Planks"
    },
    {
      "x": -5,
      "y": 47,
      "z": 16,
      "name": "Furniture_Village_Bookcase",
      "rotation": 1
    },
    {
      "x": -5,
      "y": 48,
      "z": 16,
      "name": "Furniture_Village_Bookcase",
      "rotation": 1
    },
    {
      "x": -5,
      "y": 49,
      "z": 16,
      "name": "Furniture_Village_Bookcase",
      "rotation": 1
    },
    {
      "x": -5,
      "y": 50,
      "z": 16,
      "name": "Wood_Goldenwood_Planks_Half",
      "rotation": 5
    },
    {
      "x": -5,
      "y": 51,
      "z": 16,
      "name": "Wood_Goldenwood_Planks"
    },
    {
      "x": -5,
      "y": 45,
      "z": 17,
      "name": "Rock_Sandstone_Cobble"
    },
    {
      "x": -5,
      "y": 46,
      "z": 17,
      "name": "Wood_Goldenwood_Planks"
    },
    {
      "x": -5,
      "y": 47,
      "z": 17,
      "name": "Empty"
    },
    {
      "x": -5,
      "y": 48,
      "z": 17,
      "name": "Empty"
    },
    {
      "x": -5,
      "y": 49,
      "z": 17,
      "name": "Empty"
    },
    {
      "x": -5,
      "y": 50,
      "z": 17,
      "name": "Wood_Goldenwood_Planks_Half",
      "rotation": 5
    },
    {
      "x": -5,
      "y": 51,
      "z": 17,
      "name": "Wood_Goldenwood_Planks"
    },
    {
      "x": -5,
      "y": 45,
      "z": 18,
      "name": "Rock_Sandstone_Cobble"
    },
    {
      "x": -5,
      "y": 46,
      "z": 18,
      "name": "Wood_Goldenwood_Planks"
    },
    {
      "x": -5,
      "y": 47,
      "z": 18,
      "name": "Empty"
    },
    {
      "x": -5,
      "y": 48,
      "z": 18,
      "name": "Empty"
    },
    {
      "x": -5,
      "y": 49,
      "z": 18,
      "name": "Empty"
    },
    {
      "x": -5,
      "y": 50,
      "z": 18,
      "name": "Wood_Goldenwood_Planks_Half",
      "rotation": 5
    },
    {
      "x": -5,
      "y": 51,
      "z": 18,
      "name": "Wood_Goldenwood_Planks"
    },
    {
      "x": -5,
      "y": 45,
      "z": 19,
      "name": "Rock_Sandstone_Cobble"
    },
    {
      "x": -5,
      "y": 46,
      "z": 19,
      "name": "Wood_Goldenwood_Planks"
    },
    {
      "x": -5,
      "y": 47,
      "z": 19,
      "name": "Furniture_Tavern_Planter"
    },
    {
      "x": -5,
      "y": 48,
      "z": 19,
      "name": "*Plant_Crop_Aubergine_Block_State_Definitions_StageFinal",
      "components": {
        "Components": {
          "FarmingBlock": {}
        }
      }
    },
    {
      "x": -5,
      "y": 49,
      "z": 19,
      "name": "Empty"
    },
    {
      "x": -5,
      "y": 50,
      "z": 19,
      "name": "Wood_Goldenwood_Planks"
    },
    {
      "x": -5,
      "y": 51,
      "z": 19,
      "name": "Wood_Goldenwood_Planks"
    },
    {
      "x": -5,
      "y": 45,
      "z": 20,
      "name": "Rock_Sandstone_Cobble"
    },
    {
      "x": -5,
      "y": 46,
      "z": 20,
      "name": "Rock_Sandstone_Cobble"
    },
    {
      "x": -5,
      "y": 47,
      "z": 20,
      "name": "Rock_Sandstone_Brick_Ornate"
    },
    {
      "x": -5,
      "y": 48,
      "z": 20,
      "name": "Rock_Sandstone_Cobble"
    },
    {
      "x": -5,
      "y": 49,
      "z": 20,
      "name": "Rock_Sandstone_Cobble"
    },
    {
      "x": -5,
      "y": 50,
      "z": 20,
      "name": "Rock_Sandstone_Cobble"
    },
    {
      "x": -5,
      "y": 51,
      "z": 20,
      "name": "Rock_Sandstone_Cobble"
    },
    {
      "x": -4,
      "y": 45,
      "z": 3,
      "name": "Rock_Sandstone_Cobble"
    },
    {
      "x": -4,
      "y": 46,
      "z": 3,
      "name": "Rock_Sandstone_Cobble"
    },
    {
      "x": -4,
      "y": 47,
      "z": 3,
      "name": "Rock_Sandstone_Brick_Ornate"
    },
    {
      "x": -4,
      "y": 48,
      "z": 3,
      "name": "Rock_Sandstone_Cobble"
    },
    {
      "x": -4,
      "y": 49,
      "z": 3,
      "name": "Rock_Sandstone_Cobble"
    },
    {
      "x": -4,
      "y": 50,
      "z": 3,
      "name": "Rock_Sandstone_Cobble"
    },
    {
      "x": -4,
      "y": 51,
      "z": 3,
      "name": "Rock_Sandstone_Cobble"
    },
    {
      "x": -4,
      "y": 45,
      "z": 4,
      "name": "Rock_Sandstone_Cobble"
    },
    {
      "x": -4,
      "y": 46,
      "z": 4,
      "name": "Wood_Goldenwood_Planks"
    },
    {
      "x": -4,
      "y": 47,
      "z": 4,
      "name": "Furniture_Village_Bookcase"
    },
    {
      "x": -4,
      "y": 48,
      "z": 4,
      "name": "Furniture_Village_Bookcase"
    },
    {
      "x": -4,
      "y": 49,
      "z": 4,
      "name": "Furniture_Village_Bookcase"
    },
    {
      "x": -4,
      "y": 50,
      "z": 4,
      "name": "Wood_Goldenwood_Planks_Half",
      "rotation": 4
    },
    {
      "x": -4,
      "y": 51,
      "z": 4,
      "name": "Wood_Goldenwood_Planks"
    },
    {
      "x": -4,
      "y": 45,
      "z": 5,
      "name": "Rock_Sandstone_Cobble"
    },
    {
      "x": -4,
      "y": 46,
      "z": 5,
      "name": "Cloth_Block_Wool_Orange"
    },
    {
      "x": -4,
      "y": 47,
      "z": 5,
      "name": "Empty"
    },
    {
      "x": -4,
      "y": 48,
      "z": 5,
      "name": "Empty"
    },
    {
      "x": -4,
      "y": 49,
      "z": 5,
      "name": "Empty"
    },
    {
      "x": -4,
      "y": 50,
      "z": 5,
      "name": "Empty"
    },
    {
      "x": -4,
      "y": 51,
      "z": 5,
      "name": "Wood_Goldenwood_Planks"
    },
    {
      "x": -4,
      "y": 45,
      "z": 6,
      "name": "Rock_Sandstone_Cobble"
    },
    {
      "x": -4,
      "y": 46,
      "z": 6,
      "name": "Cloth_Block_Wool_Orange"
    },
    {
      "x": -4,
      "y": 47,
      "z": 6,
      "name": "Cloth_Roof_Red_Flat"
    },
    {
      "x": -4,
      "y": 48,
      "z": 6,
      "name": "Empty"
    },
    {
      "x": -4,
      "y": 49,
      "z": 6,
      "name": "Furniture_Tavern_Chandelier",
      "filler": 32767
    },
    {
      "x": -4,
      "y": 50,
      "z": 6,
      "name": "Furniture_Tavern_Chandelier",
      "filler": 1023
    },
    {
      "x": -4,
      "y": 51,
      "z": 6,
      "name": "Wood_Goldenwood_Planks"
    },
    {
      "x": -4,
      "y": 45,
      "z": 7,
      "name": "Rock_Sandstone_Cobble"
    },
    {
      "x": -4,
      "y": 46,
      "z": 7,
      "name": "Wood_Goldenwood_Planks"
    },
    {
      "x": -4,
      "y": 47,
      "z": 7,
      "name": "Cloth_Roof_Red_Flat"
    },
    {
      "x": -4,
      "y": 48,
      "z": 7,
      "name": "Empty"
    },
    {
      "x": -4,
      "y": 49,
      "z": 7,
      "name": "Furniture_Tavern_Chandelier",
      "filler": 31775
    },
    {
      "x": -4,
      "y": 50,
      "z": 7,
      "name": "Furniture_Tavern_Chandelier",
      "filler": 31
    },
    {
      "x": -4,
      "y": 51,
      "z": 7,
      "name": "Wood_Goldenwood_Planks"
    },
    {
      "x": -4,
      "y": 45,
      "z": 8,
      "name": "Rock_Sandstone_Cobble"
    },
    {
      "x": -4,
      "y": 46,
      "z": 8,
      "name": "Wood_Goldenwood_Planks"
    },
    {
      "x": -4,
      "y": 47,
      "z": 8,
      "name": "Empty"
    },
    {
      "x": -4,
      "y": 48,
      "z": 8,
      "name": "Empty"
    },
    {
      "x": -4,
      "y": 49,
      "z": 8,
      "name": "Furniture_Tavern_Chandelier",
      "filler": 31807
    },
    {
      "x": -4,
      "y": 50,
      "z": 8,
      "name": "Furniture_Tavern_Chandelier",
      "filler": 63
    },
    {
      "x": -4,
      "y": 51,
      "z": 8,
      "name": "Wood_Goldenwood_Planks"
    },
    {
      "x": -4,
      "y": 45,
      "z": 9,
      "name": "Rock_Sandstone_Cobble"
    },
    {
      "x": -4,
      "y": 46,
      "z": 9,
      "name": "Wood_Goldenwood_Planks"
    },
    {
      "x": -4,
      "y": 47,
      "z": 9,
      "name": "Furniture_Desert_Chair",
      "rotation": 3
    },
    {
      "x": -4,
      "y": 48,
      "z": 9,
      "name": "Empty"
    },
    {
      "x": -4,
      "y": 49,
      "z": 9,
      "name": "Empty"
    },
    {
      "x": -4,
      "y": 50,
      "z": 9,
      "name": "Empty"
    },
    {
      "x": -4,
      "y": 51,
      "z": 9,
      "name": "Wood_Goldenwood_Planks"
    },
    {
      "x": -4,
      "y": 45,
      "z": 10,
      "name": "Rock_Sandstone_Cobble"
    },
    {
      "x": -4,
      "y": 46,
      "z": 10,
      "name": "Wood_Goldenwood_Planks"
    },
    {
      "x": -4,
      "y": 47,
      "z": 10,
      "name": "Empty"
    },
    {
      "x": -4,
      "y": 48,
      "z": 10,
      "name": "Empty"
    },
    {
      "x": -4,
      "y": 49,
      "z": 10,
      "name": "Empty"
    },
    {
      "x": -4,
      "y": 50,
      "z": 10,
      "name": "Empty"
    },
    {
      "x": -4,
      "y": 51,
      "z": 10,
      "name": "Wood_Goldenwood_Planks"
    },
    {
      "x": -4,
      "y": 45,
      "z": 11,
      "name": "Rock_Sandstone_Cobble"
    },
    {
      "x": -4,
      "y": 46,
      "z": 11,
      "name": "Wood_Goldenwood_Planks"
    },
    {
      "x": -4,
      "y": 47,
      "z": 11,
      "name": "Furniture_Village_Shelf_Full",
      "rotation": 2
    },
    {
      "x": -4,
      "y": 48,
      "z": 11,
      "name": "Furniture_Village_Shelf_Full",
      "rotation": 2
    },
    {
      "x": -4,
      "y": 49,
      "z": 11,
      "name": "Furniture_Village_Shelf_Full",
      "rotation": 2
    },
    {
      "x": -4,
      "y": 50,
      "z": 11,
      "name": "Wood_Goldenwood_Planks_Half",
      "rotation": 6
    },
    {
      "x": -4,
      "y": 51,
      "z": 11,
      "name": "Wood_Goldenwood_Planks"
    },
    {
      "x": -4,
      "y": 45,
      "z": 12,
      "name": "Rock_Sandstone_Cobble"
    },
    {
      "x": -4,
      "y": 46,
      "z": 12,
      "name": "Wood_Goldenwood_Planks"
    },
    {
      "x": -4,
      "y": 47,
      "z": 12,
      "name": "Rock_Sandstone_Brick_Ornate"
    },
    {
      "x": -4,
      "y": 48,
      "z": 12,
      "name": "Rock_Sandstone_Cobble"
    },
    {
      "x": -4,
      "y": 49,
      "z": 12,
      "name": "Rock_Sandstone_Cobble"
    },
    {
      "x": -4,
      "y": 50,
      "z": 12,
      "name": "Rock_Sandstone_Cobble"
    },
    {
      "x": -4,
      "y": 51,
      "z": 12,
      "name": "Wood_Goldenwood_Planks"
    },
    {
      "x": -4,
      "y": 45,
      "z": 13,
      "name": "Rock_Sandstone_Cobble"
    },
    {
      "x": -4,
      "y": 46,
      "z": 13,
      "name": "Wood_Goldenwood_Planks"
    },
    {
      "x": -4,
      "y": 47,
      "z": 13,
      "name": "Empty"
    },
    {
      "x": -4,
      "y": 48,
      "z": 13,
      "name": "Empty"
    },
    {
      "x": -4,
      "y": 49,
      "z": 13,
      "name": "Empty"
    },
    {
      "x": -4,
      "y": 50,
      "z": 13,
      "name": "Wood_Goldenwood_Planks_Half",
      "rotation": 4
    },
    {
      "x": -4,
      "y": 51,
      "z": 13,
      "name": "Wood_Goldenwood_Planks"
    },
    {
      "x": -4,
      "y": 45,
      "z": 14,
      "name": "Rock_Sandstone_Cobble"
    },
    {
      "x": -4,
      "y": 46,
      "z": 14,
      "name": "Wood_Goldenwood_Planks"
    },
    {
      "x": -4,
      "y": 47,
      "z": 14,
      "name": "Empty"
    },
    {
      "x": -4,
      "y": 48,
      "z": 14,
      "name": "Empty"
    },
    {
      "x": -4,
      "y": 49,
      "z": 14,
      "name": "Empty"
    },
    {
      "x": -4,
      "y": 50,
      "z": 14,
      "name": "Empty"
    },
    {
      "x": -4,
      "y": 51,
      "z": 14,
      "name": "Wood_Goldenwood_Planks"
    },
    {
      "x": -4,
      "y": 45,
      "z": 15,
      "name": "Rock_Sandstone_Cobble"
    },
    {
      "x": -4,
      "y": 46,
      "z": 15,
      "name": "Wood_Goldenwood_Planks"
    },
    {
      "x": -4,
      "y": 47,
      "z": 15,
      "name": "Empty"
    },
    {
      "x": -4,
      "y": 48,
      "z": 15,
      "name": "Empty"
    },
    {
      "x": -4,
      "y": 49,
      "z": 15,
      "name": "Empty"
    },
    {
      "x": -4,
      "y": 50,
      "z": 15,
      "name": "Empty"
    },
    {
      "x": -4,
      "y": 51,
      "z": 15,
      "name": "Wood_Goldenwood_Planks"
    },
    {
      "x": -4,
      "y": 45,
      "z": 16,
      "name": "Rock_Sandstone_Cobble"
    },
    {
      "x": -4,
      "y": 46,
      "z": 16,
      "name": "Wood_Goldenwood_Planks"
    },
    {
      "x": -4,
      "y": 47,
      "z": 16,
      "name": "Empty"
    },
    {
      "x": -4,
      "y": 48,
      "z": 16,
      "name": "Empty"
    },
    {
      "x": -4,
      "y": 49,
      "z": 16,
      "name": "Empty"
    },
    {
      "x": -4,
      "y": 50,
      "z": 16,
      "name": "Empty"
    },
    {
      "x": -4,
      "y": 51,
      "z": 16,
      "name": "Wood_Goldenwood_Planks"
    },
    {
      "x": -4,
      "y": 45,
      "z": 17,
      "name": "Rock_Sandstone_Cobble"
    },
    {
      "x": -4,
      "y": 46,
      "z": 17,
      "name": "Wood_Goldenwood_Planks"
    },
    {
      "x": -4,
      "y": 47,
      "z": 17,
      "name": "Empty"
    },
    {
      "x": -4,
      "y": 48,
      "z": 17,
      "name": "Empty"
    },
    {
      "x": -4,
      "y": 49,
      "z": 17,
      "name": "Empty"
    },
    {
      "x": -4,
      "y": 50,
      "z": 17,
      "name": "Empty"
    },
    {
      "x": -4,
      "y": 51,
      "z": 17,
      "name": "Wood_Goldenwood_Planks"
    },
    {
      "x": -4,
      "y": 45,
      "z": 18,
      "name": "Rock_Sandstone_Cobble"
    },
    {
      "x": -4,
      "y": 46,
      "z": 18,
      "name": "Wood_Goldenwood_Planks"
    },
    {
      "x": -4,
      "y": 47,
      "z": 18,
      "name": "Empty"
    },
    {
      "x": -4,
      "y": 48,
      "z": 18,
      "name": "Empty"
    },
    {
      "x": -4,
      "y": 49,
      "z": 18,
      "name": "Empty"
    },
    {
      "x": -4,
      "y": 50,
      "z": 18,
      "name": "Empty"
    },
    {
      "x": -4,
      "y": 51,
      "z": 18,
      "name": "Wood_Goldenwood_Planks"
    },
    {
      "x": -4,
      "y": 45,
      "z": 19,
      "name": "Empty"
    },
    {
      "x": -4,
      "y": 46,
      "z": 19,
      "name": "Empty"
    },
    {
      "x": -4,
      "y": 47,
      "z": 19,
      "name": "Empty"
    },
    {
      "x": -4,
      "y": 48,
      "z": 19,
      "name": "Empty"
    },
    {
      "x": -4,
      "y": 49,
      "z": 19,
      "name": "Empty"
    },
    {
      "x": -4,
      "y": 50,
      "z": 19,
      "name": "Wood_Goldenwood_Planks_Half",
      "rotation": 6
    },
    {
      "x": -4,
      "y": 51,
      "z": 19,
      "name": "Wood_Goldenwood_Planks"
    },
    {
      "x": -4,
      "y": 45,
      "z": 20,
      "name": "Rock_Sandstone_Cobble"
    },
    {
      "x": -4,
      "y": 46,
      "z": 20,
      "name": "Rock_Sandstone_Cobble"
    },
    {
      "x": -4,
      "y": 47,
      "z": 20,
      "name": "Rock_Sandstone_Brick_Ornate"
    },
    {
      "x": -4,
      "y": 48,
      "z": 20,
      "name": "Rock_Sandstone_Cobble"
    },
    {
      "x": -4,
      "y": 49,
      "z": 20,
      "name": "Rock_Sandstone_Cobble"
    },
    {
      "x": -4,
      "y": 50,
      "z": 20,
      "name": "Rock_Sandstone_Cobble"
    },
    {
      "x": -4,
      "y": 51,
      "z": 20,
      "name": "Rock_Sandstone_Cobble"
    },
    {
      "x": -3,
      "y": 45,
      "z": 3,
      "name": "Rock_Sandstone_Cobble"
    },
    {
      "x": -3,
      "y": 46,
      "z": 3,
      "name": "Rock_Sandstone_Cobble"
    },
    {
      "x": -3,
      "y": 47,
      "z": 3,
      "name": "Rock_Sandstone_Brick_Ornate"
    },
    {
      "x": -3,
      "y": 48,
      "z": 3,
      "name": "Rock_Sandstone_Cobble"
    },
    {
      "x": -3,
      "y": 49,
      "z": 3,
      "name": "Rock_Sandstone_Cobble"
    },
    {
      "x": -3,
      "y": 50,
      "z": 3,
      "name": "Rock_Sandstone_Cobble"
    },
    {
      "x": -3,
      "y": 51,
      "z": 3,
      "name": "Rock_Sandstone_Cobble"
    },
    {
      "x": -3,
      "y": 45,
      "z": 4,
      "name": "Rock_Sandstone_Cobble"
    },
    {
      "x": -3,
      "y": 46,
      "z": 4,
      "name": "Wood_Goldenwood_Planks"
    },
    {
      "x": -3,
      "y": 47,
      "z": 4,
      "name": "Furniture_Village_Bookcase"
    },
    {
      "x": -3,
      "y": 48,
      "z": 4,
      "name": "Furniture_Village_Bookcase"
    },
    {
      "x": -3,
      "y": 49,
      "z": 4,
      "name": "Furniture_Village_Bookcase"
    },
    {
      "x": -3,
      "y": 50,
      "z": 4,
      "name": "Wood_Goldenwood_Planks_Half",
      "rotation": 4
    },
    {
      "x": -3,
      "y": 51,
      "z": 4,
      "name": "Wood_Goldenwood_Planks"
    },
    {
      "x": -3,
      "y": 45,
      "z": 5,
      "name": "Rock_Sandstone_Cobble"
    },
    {
      "x": -3,
      "y": 46,
      "z": 5,
      "name": "Cloth_Block_Wool_Orange"
    },
    {
      "x": -3,
      "y": 47,
      "z": 5,
      "name": "Empty"
    },
    {
      "x": -3,
      "y": 48,
      "z": 5,
      "name": "Empty"
    },
    {
      "x": -3,
      "y": 49,
      "z": 5,
      "name": "Empty"
    },
    {
      "x": -3,
      "y": 50,
      "z": 5,
      "name": "Empty"
    },
    {
      "x": -3,
      "y": 51,
      "z": 5,
      "name": "Wood_Goldenwood_Planks"
    },
    {
      "x": -3,
      "y": 45,
      "z": 6,
      "name": "Rock_Sandstone_Cobble"
    },
    {
      "x": -3,
      "y": 46,
      "z": 6,
      "name": "Cloth_Block_Wool_Orange"
    },
    {
      "x": -3,
      "y": 47,
      "z": 6,
      "name": "Cloth_Roof_Red_Flat"
    },
    {
      "x": -3,
      "y": 48,
      "z": 6,
      "name": "Empty"
    },
    {
      "x": -3,
      "y": 49,
      "z": 6,
      "name": "Furniture_Tavern_Chandelier",
      "filler": 32736
    },
    {
      "x": -3,
      "y": 50,
      "z": 6,
      "name": "Furniture_Tavern_Chandelier",
      "filler": 992
    },
    {
      "x": -3,
      "y": 51,
      "z": 6,
      "name": "Wood_Goldenwood_Planks"
    },
    {
      "x": -3,
      "y": 45,
      "z": 7,
      "name": "Rock_Sandstone_Cobble"
    },
    {
      "x": -3,
      "y": 46,
      "z": 7,
      "name": "Wood_Goldenwood_Planks"
    },
    {
      "x": -3,
      "y": 47,
      "z": 7,
      "name": "Cloth_Roof_Red_Flat"
    },
    {
      "x": -3,
      "y": 48,
      "z": 7,
      "name": "Empty"
    },
    {
      "x": -3,
      "y": 49,
      "z": 7,
      "name": "Furniture_Tavern_Chandelier",
      "filler": 31744
    },
    {
      "x": -3,
      "y": 50,
      "z": 7,
      "name": "Furniture_Tavern_Chandelier"
    },
    {
      "x": -3,
      "y": 51,
      "z": 7,
      "name": "Wood_Goldenwood_Planks"
    },
    {
      "x": -3,
      "y": 45,
      "z": 8,
      "name": "Rock_Sandstone_Cobble"
    },
    {
      "x": -3,
      "y": 46,
      "z": 8,
      "name": "Wood_Goldenwood_Planks"
    },
    {
      "x": -3,
      "y": 47,
      "z": 8,
      "name": "Empty"
    },
    {
      "x": -3,
      "y": 48,
      "z": 8,
      "name": "Empty"
    },
    {
      "x": -3,
      "y": 49,
      "z": 8,
      "name": "Furniture_Tavern_Chandelier",
      "filler": 31776
    },
    {
      "x": -3,
      "y": 50,
      "z": 8,
      "name": "Furniture_Tavern_Chandelier",
      "filler": 32
    },
    {
      "x": -3,
      "y": 51,
      "z": 8,
      "name": "Wood_Goldenwood_Planks"
    },
    {
      "x": -3,
      "y": 45,
      "z": 9,
      "name": "Rock_Sandstone_Cobble"
    },
    {
      "x": -3,
      "y": 46,
      "z": 9,
      "name": "Wood_Goldenwood_Planks"
    },
    {
      "x": -3,
      "y": 47,
      "z": 9,
      "name": "Empty"
    },
    {
      "x": -3,
      "y": 48,
      "z": 9,
      "name": "Empty"
    },
    {
      "x": -3,
      "y": 49,
      "z": 9,
      "name": "Empty"
    },
    {
      "x": -3,
      "y": 50,
      "z": 9,
      "name": "Empty"
    },
    {
      "x": -3,
      "y": 51,
      "z": 9,
      "name": "Wood_Goldenwood_Planks"
    },
    {
      "x": -3,
      "y": 45,
      "z": 10,
      "name": "Rock_Sandstone_Cobble"
    },
    {
      "x": -3,
      "y": 46,
      "z": 10,
      "name": "Wood_Goldenwood_Planks"
    },
    {
      "x": -3,
      "y": 47,
      "z": 10,
      "name": "Deco_Pot_Clay_Broken"
    },
    {
      "x": -3,
      "y": 48,
      "z": 10,
      "name": "Empty"
    },
    {
      "x": -3,
      "y": 49,
      "z": 10,
      "name": "Empty"
    },
    {
      "x": -3,
      "y": 50,
      "z": 10,
      "name": "Empty"
    },
    {
      "x": -3,
      "y": 51,
      "z": 10,
      "name": "Wood_Goldenwood_Planks"
    },
    {
      "x": -3,
      "y": 45,
      "z": 11,
      "name": "Rock_Sandstone_Cobble"
    },
    {
      "x": -3,
      "y": 46,
      "z": 11,
      "name": "Wood_Goldenwood_Planks"
    },
    {
      "x": -3,
      "y": 47,
      "z": 11,
      "name": "Furniture_Village_Bookcase",
      "rotation": 2
    },
    {
      "x": -3,
      "y": 48,
      "z": 11,
      "name": "Furniture_Village_Bookcase",
      "rotation": 2
    },
    {
      "x": -3,
      "y": 49,
      "z": 11,
      "name": "Furniture_Village_Bookcase",
      "rotation": 2
    },
    {
      "x": -3,
      "y": 50,
      "z": 11,
      "name": "Wood_Goldenwood_Planks_Half",
      "rotation": 6
    },
    {
      "x": -3,
      "y": 51,
      "z": 11,
      "name": "Wood_Goldenwood_Planks"
    },
    {
      "x": -3,
      "y": 45,
      "z": 12,
      "name": "Rock_Sandstone_Cobble"
    },
    {
      "x": -3,
      "y": 46,
      "z": 12,
      "name": "Wood_Goldenwood_Planks"
    },
    {
      "x": -3,
      "y": 47,
      "z": 12,
      "name": "Rock_Sandstone_Brick_Ornate"
    },
    {
      "x": -3,
      "y": 48,
      "z": 12,
      "name": "Rock_Sandstone_Cobble"
    },
    {
      "x": -3,
      "y": 49,
      "z": 12,
      "name": "Rock_Sandstone_Cobble"
    },
    {
      "x": -3,
      "y": 50,
      "z": 12,
      "name": "Rock_Sandstone_Cobble"
    },
    {
      "x": -3,
      "y": 51,
      "z": 12,
      "name": "Wood_Goldenwood_Planks"
    },
    {
      "x": -3,
      "y": 45,
      "z": 13,
      "name": "Rock_Sandstone_Cobble"
    },
    {
      "x": -3,
      "y": 46,
      "z": 13,
      "name": "Wood_Goldenwood_Planks"
    },
    {
      "x": -3,
      "y": 47,
      "z": 13,
      "name": "Block_Spawner_Block",
      "components": {
        "Components": {
          "BlockSpawner": {
            "BlockSpawnerId": "Zone2_Encounters_Tier3"
          }
        }
      },
      "rotation": 2
    },
    {
      "x": -3,
      "y": 48,
      "z": 13,
      "name": "Empty"
    },
    {
      "x": -3,
      "y": 49,
      "z": 13,
      "name": "Empty"
    },
    {
      "x": -3,
      "y": 50,
      "z": 13,
      "name": "Wood_Goldenwood_Planks"
    },
    {
      "x": -3,
      "y": 51,
      "z": 13,
      "name": "Wood_Goldenwood_Planks"
    },
    {
      "x": -3,
      "y": 45,
      "z": 14,
      "name": "Rock_Sandstone_Cobble"
    },
    {
      "x": -3,
      "y": 46,
      "z": 14,
      "name": "Wood_Goldenwood_Planks"
    },
    {
      "x": -3,
      "y": 47,
      "z": 14,
      "name": "Furniture_Village_Bookcase",
      "rotation": 3
    },
    {
      "x": -3,
      "y": 48,
      "z": 14,
      "name": "Furniture_Village_Bookcase",
      "rotation": 3
    },
    {
      "x": -3,
      "y": 49,
      "z": 14,
      "name": "Furniture_Village_Bookcase",
      "rotation": 3
    },
    {
      "x": -3,
      "y": 50,
      "z": 14,
      "name": "Wood_Goldenwood_Planks_Half",
      "rotation": 7
    },
    {
      "x": -3,
      "y": 51,
      "z": 14,
      "name": "Wood_Goldenwood_Planks"
    },
    {
      "x": -3,
      "y": 45,
      "z": 15,
      "name": "Rock_Sandstone_Cobble"
    },
    {
      "x": -3,
      "y": 46,
      "z": 15,
      "name": "Wood_Goldenwood_Planks"
    },
    {
      "x": -3,
      "y": 47,
      "z": 15,
      "name": "Furniture_Village_Counter",
      "filler": 992,
      "rotation": 3
    },
    {
      "x": -3,
      "y": 48,
      "z": 15,
      "name": "Furniture_Village_Bookcase",
      "rotation": 3
    },
    {
      "x": -3,
      "y": 49,
      "z": 15,
      "name": "Furniture_Village_Bookcase",
      "rotation": 3
    },
    {
      "x": -3,
      "y": 50,
      "z": 15,
      "name": "Wood_Goldenwood_Planks_Half",
      "rotation": 7
    },
    {
      "x": -3,
      "y": 51,
      "z": 15,
      "name": "Wood_Goldenwood_Planks"
    },
    {
      "x": -3,
      "y": 45,
      "z": 16,
      "name": "Rock_Sandstone_Cobble"
    },
    {
      "x": -3,
      "y": 46,
      "z": 16,
      "name": "Wood_Goldenwood_Planks"
    },
    {
      "x": -3,
      "y": 47,
      "z": 16,
      "name": "Furniture_Village_Counter",
      "rotation": 3
    },
    {
      "x": -3,
      "y": 48,
      "z": 16,
      "name": "Deco_Mug"
    },
    {
      "x": -3,
      "y": 49,
      "z": 16,
      "name": "Empty"
    },
    {
      "x": -3,
      "y": 50,
      "z": 16,
      "name": "Wood_Goldenwood_Planks_Half",
      "rotation": 7
    },
    {
      "x": -3,
      "y": 51,
      "z": 16,
      "name": "Wood_Goldenwood_Planks"
    },
    {
      "x": -3,
      "y": 45,
      "z": 17,
      "name": "Rock_Sandstone_Cobble"
    },
    {
      "x": -3,
      "y": 46,
      "z": 17,
      "name": "Wood_Goldenwood_Planks"
    },
    {
      "x": -3,
      "y": 47,
      "z": 17,
      "name": "Empty"
    },
    {
      "x": -3,
      "y": 48,
      "z": 17,
      "name": "Furniture_Lumberjack_Shelf",
      "rotation": 3
    },
    {
      "x": -3,
      "y": 49,
      "z": 17,
      "name": "Empty"
    },
    {
      "x": -3,
      "y": 50,
      "z": 17,
      "name": "Wood_Goldenwood_Planks_Half",
      "rotation": 7
    },
    {
      "x": -3,
      "y": 51,
      "z": 17,
      "name": "Wood_Goldenwood_Planks"
    },
    {
      "x": -3,
      "y": 45,
      "z": 18,
      "name": "Rock_Sandstone_Cobble"
    },
    {
      "x": -3,
      "y": 46,
      "z": 18,
      "name": "Wood_Goldenwood_Planks"
    },
    {
      "x": -3,
      "y": 47,
      "z": 18,
      "name": "Empty"
    },
    {
      "x": -3,
      "y": 48,
      "z": 18,
      "name": "Furniture_Lumberjack_Shelf",
      "rotation": 3
    },
    {
      "x": -3,
      "y": 49,
      "z": 18,
      "name": "Rock_Crystal_Blue_Small"
    },
    {
      "x": -3,
      "y": 50,
      "z": 18,
      "name": "Wood_Goldenwood_Planks_Half",
      "rotation": 7
    },
    {
      "x": -3,
      "y": 51,
      "z": 18,
      "name": "Wood_Goldenwood_Planks"
    },
    {
      "x": -3,
      "y": 45,
      "z": 19,
      "name": "Empty"
    },
    {
      "x": -3,
      "y": 46,
      "z": 19,
      "name": "Empty"
    },
    {
      "x": -3,
      "y": 47,
      "z": 19,
      "name": "Empty"
    },
    {
      "x": -3,
      "y": 48,
      "z": 19,
      "name": "Empty"
    },
    {
      "x": -3,
      "y": 49,
      "z": 19,
      "name": "Empty"
    },
    {
      "x": -3,
      "y": 50,
      "z": 19,
      "name": "Wood_Goldenwood_Planks"
    },
    {
      "x": -3,
      "y": 51,
      "z": 19,
      "name": "Wood_Goldenwood_Planks"
    },
    {
      "x": -3,
      "y": 45,
      "z": 20,
      "name": "Rock_Sandstone_Cobble"
    },
    {
      "x": -3,
      "y": 46,
      "z": 20,
      "name": "Rock_Sandstone_Cobble"
    },
    {
      "x": -3,
      "y": 47,
      "z": 20,
      "name": "Rock_Sandstone_Brick_Ornate"
    },
    {
      "x": -3,
      "y": 48,
      "z": 20,
      "name": "Rock_Sandstone_Cobble"
    },
    {
      "x": -3,
      "y": 49,
      "z": 20,
      "name": "Rock_Sandstone_Cobble"
    },
    {
      "x": -3,
      "y": 50,
      "z": 20,
      "name": "Rock_Sandstone_Cobble"
    },
    {
      "x": -3,
      "y": 51,
      "z": 20,
      "name": "Rock_Sandstone_Cobble"
    },
    {
      "x": -2,
      "y": 45,
      "z": 3,
      "name": "Rock_Sandstone_Cobble"
    },
    {
      "x": -2,
      "y": 46,
      "z": 3,
      "name": "Rock_Sandstone_Cobble"
    },
    {
      "x": -2,
      "y": 47,
      "z": 3,
      "name": "Rock_Sandstone_Brick_Ornate"
    },
    {
      "x": -2,
      "y": 48,
      "z": 3,
      "name": "Rock_Sandstone_Cobble"
    },
    {
      "x": -2,
      "y": 49,
      "z": 3,
      "name": "Rock_Sandstone_Cobble"
    },
    {
      "x": -2,
      "y": 50,
      "z": 3,
      "name": "Rock_Sandstone_Cobble"
    },
    {
      "x": -2,
      "y": 51,
      "z": 3,
      "name": "Rock_Sandstone_Cobble"
    },
    {
      "x": -2,
      "y": 45,
      "z": 4,
      "name": "Rock_Sandstone_Cobble"
    },
    {
      "x": -2,
      "y": 46,
      "z": 4,
      "name": "Wood_Goldenwood_Planks"
    },
    {
      "x": -2,
      "y": 47,
      "z": 4,
      "name": "Furniture_Village_Bookcase"
    },
    {
      "x": -2,
      "y": 48,
      "z": 4,
      "name": "Furniture_Village_Bookcase"
    },
    {
      "x": -2,
      "y": 49,
      "z": 4,
      "name": "Furniture_Village_Bookcase"
    },
    {
      "x": -2,
      "y": 50,
      "z": 4,
      "name": "Wood_Goldenwood_Planks_Half",
      "rotation": 4
    },
    {
      "x": -2,
      "y": 51,
      "z": 4,
      "name": "Wood_Goldenwood_Planks"
    },
    {
      "x": -2,
      "y": 45,
      "z": 5,
      "name": "Rock_Sandstone_Cobble"
    },
    {
      "x": -2,
      "y": 46,
      "z": 5,
      "name": "Cloth_Block_Wool_Orange"
    },
    {
      "x": -2,
      "y": 47,
      "z": 5,
      "name": "Empty"
    },
    {
      "x": -2,
      "y": 48,
      "z": 5,
      "name": "Empty"
    },
    {
      "x": -2,
      "y": 49,
      "z": 5,
      "name": "Empty"
    },
    {
      "x": -2,
      "y": 50,
      "z": 5,
      "name": "Empty"
    },
    {
      "x": -2,
      "y": 51,
      "z": 5,
      "name": "Wood_Goldenwood_Planks"
    },
    {
      "x": -2,
      "y": 45,
      "z": 6,
      "name": "Rock_Sandstone_Cobble"
    },
    {
      "x": -2,
      "y": 46,
      "z": 6,
      "name": "Cloth_Block_Wool_Orange"
    },
    {
      "x": -2,
      "y": 47,
      "z": 6,
      "name": "Empty"
    },
    {
      "x": -2,
      "y": 48,
      "z": 6,
      "name": "Empty"
    },
    {
      "x": -2,
      "y": 49,
      "z": 6,
      "name": "Furniture_Tavern_Chandelier",
      "filler": 32737
    },
    {
      "x": -2,
      "y": 50,
      "z": 6,
      "name": "Furniture_Tavern_Chandelier",
      "filler": 993
    },
    {
      "x": -2,
      "y": 51,
      "z": 6,
      "name": "Wood_Goldenwood_Planks"
    },
    {
      "x": -2,
      "y": 45,
      "z": 7,
      "name": "Rock_Sandstone_Cobble"
    },
    {
      "x": -2,
      "y": 46,
      "z": 7,
      "name": "Wood_Goldenwood_Planks"
    },
    {
      "x": -2,
      "y": 47,
      "z": 7,
      "name": "Empty"
    },
    {
      "x": -2,
      "y": 48,
      "z": 7,
      "name": "Empty"
    },
    {
      "x": -2,
      "y": 49,
      "z": 7,
      "name": "Furniture_Tavern_Chandelier",
      "filler": 31745
    },
    {
      "x": -2,
      "y": 50,
      "z": 7,
      "name": "Furniture_Tavern_Chandelier",
      "filler": 1
    },
    {
      "x": -2,
      "y": 51,
      "z": 7,
      "name": "Wood_Goldenwood_Planks"
    },
    {
      "x": -2,
      "y": 45,
      "z": 8,
      "name": "Rock_Sandstone_Cobble"
    },
    {
      "x": -2,
      "y": 46,
      "z": 8,
      "name": "Wood_Goldenwood_Planks"
    },
    {
      "x": -2,
      "y": 47,
      "z": 8,
      "name": "Empty"
    },
    {
      "x": -2,
      "y": 48,
      "z": 8,
      "name": "Empty"
    },
    {
      "x": -2,
      "y": 49,
      "z": 8,
      "name": "Furniture_Tavern_Chandelier",
      "filler": 31777
    },
    {
      "x": -2,
      "y": 50,
      "z": 8,
      "name": "Furniture_Tavern_Chandelier",
      "filler": 33
    },
    {
      "x": -2,
      "y": 51,
      "z": 8,
      "name": "Wood_Goldenwood_Planks"
    },
    {
      "x": -2,
      "y": 45,
      "z": 9,
      "name": "Rock_Sandstone_Cobble"
    },
    {
      "x": -2,
      "y": 46,
      "z": 9,
      "name": "Wood_Goldenwood_Planks"
    },
    {
      "x": -2,
      "y": 47,
      "z": 9,
      "name": "Empty"
    },
    {
      "x": -2,
      "y": 48,
      "z": 9,
      "name": "Empty"
    },
    {
      "x": -2,
      "y": 49,
      "z": 9,
      "name": "Empty"
    },
    {
      "x": -2,
      "y": 50,
      "z": 9,
      "name": "Empty"
    },
    {
      "x": -2,
      "y": 51,
      "z": 9,
      "name": "Wood_Goldenwood_Planks"
    },
    {
      "x": -2,
      "y": 45,
      "z": 10,
      "name": "Rock_Sandstone_Cobble"
    },
    {
      "x": -2,
      "y": 46,
      "z": 10,
      "name": "Wood_Goldenwood_Planks"
    },
    {
      "x": -2,
      "y": 47,
      "z": 10,
      "name": "Empty"
    },
    {
      "x": -2,
      "y": 48,
      "z": 10,
      "name": "Empty"
    },
    {
      "x": -2,
      "y": 49,
      "z": 10,
      "name": "Empty"
    },
    {
      "x": -2,
      "y": 50,
      "z": 10,
      "name": "Empty"
    },
    {
      "x": -2,
      "y": 51,
      "z": 10,
      "name": "Wood_Goldenwood_Planks"
    },
    {
      "x": -2,
      "y": 45,
      "z": 11,
      "name": "Rock_Sandstone_Cobble"
    },
    {
      "x": -2,
      "y": 46,
      "z": 11,
      "name": "Wood_Goldenwood_Planks"
    },
    {
      "x": -2,
      "y": 47,
      "z": 11,
      "name": "Furniture_Village_Pot"
    },
    {
      "x": -2,
      "y": 48,
      "z": 11,
      "name": "Empty"
    },
    {
      "x": -2,
      "y": 49,
      "z": 11,
      "name": "Empty"
    },
    {
      "x": -2,
      "y": 50,
      "z": 11,
      "name": "Wood_Goldenwood_Planks_Half",
      "rotation": 6
    },
    {
      "x": -2,
      "y": 51,
      "z": 11,
      "name": "Wood_Goldenwood_Planks"
    },
    {
      "x": -2,
      "y": 45,
      "z": 12,
      "name": "Rock_Sandstone_Cobble"
    },
    {
      "x": -2,
      "y": 46,
      "z": 12,
      "name": "Wood_Goldenwood_Planks"
    },
    {
      "x": -2,
      "y": 47,
      "z": 12,
      "name": "Rock_Sandstone_Brick_Ornate"
    },
    {
      "x": -2,
      "y": 48,
      "z": 12,
      "name": "Rock_Sandstone_Cobble"
    },
    {
      "x": -2,
      "y": 49,
      "z": 12,
      "name": "Rock_Sandstone_Cobble"
    },
    {
      "x": -2,
      "y": 50,
      "z": 12,
      "name": "Rock_Sandstone_Cobble"
    },
    {
      "x": -2,
      "y": 51,
      "z": 12,
      "name": "Wood_Goldenwood_Planks"
    },
    {
      "x": -2,
      "y": 45,
      "z": 13,
      "name": "Rock_Sandstone_Cobble"
    },
    {
      "x": -2,
      "y": 46,
      "z": 13,
      "name": "Wood_Goldenwood_Planks"
    },
    {
      "x": -2,
      "y": 47,
      "z": 13,
      "name": "Rock_Sandstone_Brick_Ornate"
    },
    {
      "x": -2,
      "y": 48,
      "z": 13,
      "name": "Rock_Sandstone_Cobble"
    },
    {
      "x": -2,
      "y": 49,
      "z": 13,
      "name": "Rock_Sandstone_Cobble"
    },
    {
      "x": -2,
      "y": 50,
      "z": 13,
      "name": "Rock_Sandstone_Cobble"
    },
    {
      "x": -2,
      "y": 51,
      "z": 13,
      "name": "Wood_Goldenwood_Planks"
    },
    {
      "x": -2,
      "y": 45,
      "z": 14,
      "name": "Rock_Sandstone_Cobble"
    },
    {
      "x": -2,
      "y": 46,
      "z": 14,
      "name": "Wood_Goldenwood_Planks"
    },
    {
      "x": -2,
      "y": 47,
      "z": 14,
      "name": "Rock_Sandstone_Brick_Ornate"
    },
    {
      "x": -2,
      "y": 48,
      "z": 14,
      "name": "Rock_Sandstone_Cobble"
    },
    {
      "x": -2,
      "y": 49,
      "z": 14,
      "name": "Rock_Sandstone_Cobble"
    },
    {
      "x": -2,
      "y": 50,
      "z": 14,
      "name": "Rock_Sandstone_Cobble"
    },
    {
      "x": -2,
      "y": 51,
      "z": 14,
      "name": "Wood_Goldenwood_Planks"
    },
    {
      "x": -2,
      "y": 45,
      "z": 15,
      "name": "Rock_Sandstone_Cobble"
    },
    {
      "x": -2,
      "y": 46,
      "z": 15,
      "name": "Wood_Goldenwood_Planks"
    },
    {
      "x": -2,
      "y": 47,
      "z": 15,
      "name": "Rock_Sandstone_Brick_Ornate"
    },
    {
      "x": -2,
      "y": 48,
      "z": 15,
      "name": "Rock_Sandstone_Cobble"
    },
    {
      "x": -2,
      "y": 49,
      "z": 15,
      "name": "Rock_Sandstone_Cobble"
    },
    {
      "x": -2,
      "y": 50,
      "z": 15,
      "name": "Rock_Sandstone_Cobble"
    },
    {
      "x": -2,
      "y": 51,
      "z": 15,
      "name": "Wood_Goldenwood_Planks"
    },
    {
      "x": -2,
      "y": 45,
      "z": 16,
      "name": "Rock_Sandstone_Cobble"
    },
    {
      "x": -2,
      "y": 46,
      "z": 16,
      "name": "Wood_Goldenwood_Planks"
    },
    {
      "x": -2,
      "y": 47,
      "z": 16,
      "name": "Rock_Sandstone_Brick_Ornate"
    },
    {
      "x": -2,
      "y": 48,
      "z": 16,
      "name": "Rock_Sandstone_Cobble"
    },
    {
      "x": -2,
      "y": 49,
      "z": 16,
      "name": "Rock_Sandstone_Cobble"
    },
    {
      "x": -2,
      "y": 50,
      "z": 16,
      "name": "Rock_Sandstone_Cobble"
    },
    {
      "x": -2,
      "y": 51,
      "z": 16,
      "name": "Wood_Goldenwood_Planks"
    },
    {
      "x": -2,
      "y": 45,
      "z": 17,
      "name": "Rock_Sandstone_Cobble"
    },
    {
      "x": -2,
      "y": 46,
      "z": 17,
      "name": "Wood_Goldenwood_Planks"
    },
    {
      "x": -2,
      "y": 47,
      "z": 17,
      "name": "Rock_Sandstone_Brick_Ornate"
    },
    {
      "x": -2,
      "y": 48,
      "z": 17,
      "name": "Rock_Sandstone_Cobble"
    },
    {
      "x": -2,
      "y": 49,
      "z": 17,
      "name": "Rock_Sandstone_Cobble"
    },
    {
      "x": -2,
      "y": 50,
      "z": 17,
      "name": "Rock_Sandstone_Cobble"
    },
    {
      "x": -2,
      "y": 51,
      "z": 17,
      "name": "Wood_Goldenwood_Planks"
    },
    {
      "x": -2,
      "y": 45,
      "z": 18,
      "name": "Rock_Sandstone_Cobble"
    },
    {
      "x": -2,
      "y": 46,
      "z": 18,
      "name": "Wood_Goldenwood_Planks"
    },
    {
      "x": -2,
      "y": 47,
      "z": 18,
      "name": "Rock_Sandstone_Brick_Ornate"
    },
    {
      "x": -2,
      "y": 48,
      "z": 18,
      "name": "Rock_Sandstone_Cobble"
    },
    {
      "x": -2,
      "y": 49,
      "z": 18,
      "name": "Rock_Sandstone_Cobble"
    },
    {
      "x": -2,
      "y": 50,
      "z": 18,
      "name": "Rock_Sandstone_Cobble"
    },
    {
      "x": -2,
      "y": 51,
      "z": 18,
      "name": "Wood_Goldenwood_Planks"
    },
    {
      "x": -2,
      "y": 45,
      "z": 19,
      "name": "Rock_Sandstone_Cobble"
    },
    {
      "x": -2,
      "y": 46,
      "z": 19,
      "name": "Wood_Goldenwood_Planks"
    },
    {
      "x": -2,
      "y": 47,
      "z": 19,
      "name": "Rock_Sandstone_Brick_Ornate"
    },
    {
      "x": -2,
      "y": 48,
      "z": 19,
      "name": "Rock_Sandstone_Cobble"
    },
    {
      "x": -2,
      "y": 49,
      "z": 19,
      "name": "Rock_Sandstone_Cobble"
    },
    {
      "x": -2,
      "y": 50,
      "z": 19,
      "name": "Rock_Sandstone_Cobble"
    },
    {
      "x": -2,
      "y": 51,
      "z": 19,
      "name": "Wood_Goldenwood_Planks"
    },
    {
      "x": -2,
      "y": 45,
      "z": 20,
      "name": "Rock_Sandstone_Cobble"
    },
    {
      "x": -2,
      "y": 46,
      "z": 20,
      "name": "Rock_Sandstone_Cobble"
    },
    {
      "x": -2,
      "y": 47,
      "z": 20,
      "name": "Rock_Sandstone_Brick_Ornate"
    },
    {
      "x": -2,
      "y": 48,
      "z": 20,
      "name": "Rock_Sandstone_Cobble"
    },
    {
      "x": -2,
      "y": 49,
      "z": 20,
      "name": "Rock_Sandstone_Cobble"
    },
    {
      "x": -2,
      "y": 50,
      "z": 20,
      "name": "Rock_Sandstone_Cobble"
    },
    {
      "x": -2,
      "y": 51,
      "z": 20,
      "name": "Rock_Sandstone_Cobble"
    },
    {
      "x": -1,
      "y": 45,
      "z": 3,
      "name": "Rock_Sandstone_Cobble"
    },
    {
      "x": -1,
      "y": 46,
      "z": 3,
      "name": "Rock_Sandstone_Cobble"
    },
    {
      "x": -1,
      "y": 47,
      "z": 3,
      "name": "Rock_Sandstone_Brick_Ornate"
    },
    {
      "x": -1,
      "y": 48,
      "z": 3,
      "name": "Rock_Sandstone_Cobble"
    },
    {
      "x": -1,
      "y": 49,
      "z": 3,
      "name": "Rock_Sandstone_Cobble"
    },
    {
      "x": -1,
      "y": 50,
      "z": 3,
      "name": "Rock_Sandstone_Cobble"
    },
    {
      "x": -1,
      "y": 51,
      "z": 3,
      "name": "Rock_Sandstone_Cobble"
    },
    {
      "x": -1,
      "y": 45,
      "z": 4,
      "name": "Rock_Sandstone_Cobble"
    },
    {
      "x": -1,
      "y": 46,
      "z": 4,
      "name": "Wood_Goldenwood_Planks"
    },
    {
      "x": -1,
      "y": 47,
      "z": 4,
      "name": "Furniture_Jungle_Planter"
    },
    {
      "x": -1,
      "y": 48,
      "z": 4,
      "name": "*Plant_Crop_Carrot_Block_State_Definitions_StageFinal",
      "components": {
        "Components": {
          "FarmingBlock": {}
        }
      }
    },
    {
      "x": -1,
      "y": 49,
      "z": 4,
      "name": "Empty"
    },
    {
      "x": -1,
      "y": 50,
      "z": 4,
      "name": "Wood_Goldenwood_Planks"
    },
    {
      "x": -1,
      "y": 51,
      "z": 4,
      "name": "Wood_Goldenwood_Planks"
    },
    {
      "x": -1,
      "y": 45,
      "z": 5,
      "name": "Rock_Sandstone_Cobble"
    },
    {
      "x": -1,
      "y": 46,
      "z": 5,
      "name": "Wood_Goldenwood_Planks"
    },
    {
      "x": -1,
      "y": 47,
      "z": 5,
      "name": "Empty"
    },
    {
      "x": -1,
      "y": 48,
      "z": 5,
      "name": "Furniture_Lumberjack_Shelf",
      "rotation": 3
    },
    {
      "x": -1,
      "y": 49,
      "z": 5,
      "name": "Empty"
    },
    {
      "x": -1,
      "y": 50,
      "z": 5,
      "name": "Wood_Goldenwood_Planks_Half",
      "rotation": 7
    },
    {
      "x": -1,
      "y": 51,
      "z": 5,
      "name": "Wood_Goldenwood_Planks"
    },
    {
      "x": -1,
      "y": 45,
      "z": 6,
      "name": "Rock_Sandstone_Cobble"
    },
    {
      "x": -1,
      "y": 46,
      "z": 6,
      "name": "Wood_Goldenwood_Planks"
    },
    {
      "x": -1,
      "y": 47,
      "z": 6,
      "name": "Empty"
    },
    {
      "x": -1,
      "y": 48,
      "z": 6,
      "name": "Furniture_Lumberjack_Shelf",
      "rotation": 3
    },
    {
      "x": -1,
      "y": 49,
      "z": 6,
      "name": "Rock_Crystal_Purple_Small"
    },
    {
      "x": -1,
      "y": 50,
      "z": 6,
      "name": "Wood_Goldenwood_Planks_Half",
      "rotation": 7
    },
    {
      "x": -1,
      "y": 51,
      "z": 6,
      "name": "Wood_Goldenwood_Planks"
    },
    {
      "x": -1,
      "y": 45,
      "z": 7,
      "name": "Rock_Sandstone_Cobble"
    },
    {
      "x": -1,
      "y": 46,
      "z": 7,
      "name": "Wood_Goldenwood_Planks"
    },
    {
      "x": -1,
      "y": 47,
      "z": 7,
      "name": "Bench_Furnace",
      "components": {
        "Components": {
          "processingBench": {
            "Position": {
              "X": 31,
              "Y": 47,
              "Z": 7
            },
            "TierLevel": 1,
            "UpgradeItems": [],
            "Progress": 0.0,
            "FuelTime": 0.0,
            "Active": false,
            "NextExtra": -1
          }
        }
      },
      "filler": 992,
      "rotation": 3
    },
    {
      "x": -1,
      "y": 48,
      "z": 7,
      "name": "Bench_Furnace",
      "components": {
        "Components": {
          "processingBench": {
            "Position": {
              "X": 31,
              "Y": 48,
              "Z": 7
            },
            "TierLevel": 1,
            "UpgradeItems": [],
            "Progress": 0.0,
            "FuelTime": 0.0,
            "Active": false,
            "NextExtra": -1
          }
        }
      },
      "filler": 2016,
      "rotation": 3
    },
    {
      "x": -1,
      "y": 49,
      "z": 7,
      "name": "Empty"
    },
    {
      "x": -1,
      "y": 50,
      "z": 7,
      "name": "Wood_Goldenwood_Planks_Half",
      "rotation": 7
    },
    {
      "x": -1,
      "y": 51,
      "z": 7,
      "name": "Wood_Goldenwood_Planks"
    },
    {
      "x": -1,
      "y": 45,
      "z": 8,
      "name": "Rock_Sandstone_Cobble"
    },
    {
      "x": -1,
      "y": 46,
      "z": 8,
      "name": "Wood_Goldenwood_Planks"
    },
    {
      "x": -1,
      "y": 47,
      "z": 8,
      "name": "Bench_Furnace",
      "components": {
        "Components": {
          "processingBench": {
            "TierLevel": 1,
            "UpgradeItems": [],
            "InputContainer": {
              "Id": "Simple",
              "Capacity": 2,
              "Items": {}
            },
            "FuelContainer": {
              "Id": "Simple",
              "Capacity": 2,
              "Items": {}
            },
            "OutputContainer": {
              "Id": "Simple",
              "Capacity": 4,
              "Items": {}
            },
            "Progress": 0.0,
            "FuelTime": 0.0,
            "Active": false,
            "NextExtra": 4
          }
        }
      },
      "rotation": 3
    },
    {
      "x": -1,
      "y": 48,
      "z": 8,
      "name": "Bench_Furnace",
      "components": {
        "Components": {
          "processingBench": {
            "Position": {
              "X": 31,
              "Y": 48,
              "Z": 8
            },
            "TierLevel": 1,
            "UpgradeItems": [],
            "Progress": 0.0,
            "FuelTime": 0.0,
            "Active": false,
            "NextExtra": -1
          }
        }
      },
      "filler": 1024,
      "rotation": 3
    },
    {
      "x": -1,
      "y": 49,
      "z": 8,
      "name": "Empty"
    },
    {
      "x": -1,
      "y": 50,
      "z": 8,
      "name": "Wood_Goldenwood_Planks_Half",
      "rotation": 7
    },
    {
      "x": -1,
      "y": 51,
      "z": 8,
      "name": "Wood_Goldenwood_Planks"
    },
    {
      "x": -1,
      "y": 45,
      "z": 9,
      "name": "Rock_Sandstone_Cobble"
    },
    {
      "x": -1,
      "y": 46,
      "z": 9,
      "name": "Wood_Goldenwood_Planks"
    },
    {
      "x": -1,
      "y": 47,
      "z": 9,
      "name": "Empty"
    },
    {
      "x": -1,
      "y": 48,
      "z": 9,
      "name": "Empty"
    },
    {
      "x": -1,
      "y": 49,
      "z": 9,
      "name": "Empty"
    },
    {
      "x": -1,
      "y": 50,
      "z": 9,
      "name": "Wood_Goldenwood_Planks_Half",
      "rotation": 7
    },
    {
      "x": -1,
      "y": 51,
      "z": 9,
      "name": "Wood_Goldenwood_Planks"
    },
    {
      "x": -1,
      "y": 45,
      "z": 10,
      "name": "Rock_Sandstone_Cobble"
    },
    {
      "x": -1,
      "y": 46,
      "z": 10,
      "name": "Wood_Goldenwood_Planks"
    },
    {
      "x": -1,
      "y": 47,
      "z": 10,
      "name": "Empty"
    },
    {
      "x": -1,
      "y": 48,
      "z": 10,
      "name": "Empty"
    },
    {
      "x": -1,
      "y": 49,
      "z": 10,
      "name": "Empty"
    },
    {
      "x": -1,
      "y": 50,
      "z": 10,
      "name": "Empty"
    },
    {
      "x": -1,
      "y": 51,
      "z": 10,
      "name": "Wood_Goldenwood_Planks"
    },
    {
      "x": -1,
      "y": 45,
      "z": 11,
      "name": "Rock_Sandstone_Cobble"
    },
    {
      "x": -1,
      "y": 46,
      "z": 11,
      "name": "Wood_Goldenwood_Planks"
    },
    {
      "x": -1,
      "y": 47,
      "z": 11,
      "name": "Empty"
    },
    {
      "x": -1,
      "y": 48,
      "z": 11,
      "name": "Empty"
    },
    {
      "x": -1,
      "y": 49,
      "z": 11,
      "name": "Empty"
    },
    {
      "x": -1,
      "y": 50,
      "z": 11,
      "name": "Empty"
    },
    {
      "x": -1,
      "y": 51,
      "z": 11,
      "name": "Wood_Goldenwood_Planks"
    },
    {
      "x": -1,
      "y": 45,
      "z": 12,
      "name": "Rock_Sandstone_Cobble"
    },
    {
      "x": -1,
      "y": 46,
      "z": 12,
      "name": "Wood_Goldenwood_Planks"
    },
    {
      "x": -1,
      "y": 47,
      "z": 12,
      "name": "Empty"
    },
    {
      "x": -1,
      "y": 48,
      "z": 12,
      "name": "Empty"
    },
    {
      "x": -1,
      "y": 49,
      "z": 12,
      "name": "Empty"
    },
    {
      "x": -1,
      "y": 50,
      "z": 12,
      "name": "Wood_Goldenwood_Planks_Half",
      "rotation": 5
    },
    {
      "x": -1,
      "y": 51,
      "z": 12,
      "name": "Wood_Goldenwood_Planks"
    },
    {
      "x": -1,
      "y": 45,
      "z": 13,
      "name": "Rock_Sandstone_Cobble"
    },
    {
      "x": -1,
      "y": 46,
      "z": 13,
      "name": "Wood_Goldenwood_Planks"
    },
    {
      "x": -1,
      "y": 47,
      "z": 13,
      "name": "Furniture_Lumberjack_Shelf",
      "rotation": 1
    },
    {
      "x": -1,
      "y": 48,
      "z": 13,
      "name": "Plant_Flower_Water_Purple"
    },
    {
      "x": -1,
      "y": 49,
      "z": 13,
      "name": "Empty"
    },
    {
      "x": -1,
      "y": 50,
      "z": 13,
      "name": "Wood_Goldenwood_Planks_Half",
      "rotation": 5
    },
    {
      "x": -1,
      "y": 51,
      "z": 13,
      "name": "Wood_Goldenwood_Planks"
    },
    {
      "x": -1,
      "y": 45,
      "z": 14,
      "name": "Rock_Sandstone_Cobble"
    },
    {
      "x": -1,
      "y": 46,
      "z": 14,
      "name": "Wood_Goldenwood_Planks"
    },
    {
      "x": -1,
      "y": 47,
      "z": 14,
      "name": "Empty"
    },
    {
      "x": -1,
      "y": 48,
      "z": 14,
      "name": "Furniture_Lumberjack_Shelf",
      "rotation": 1
    },
    {
      "x": -1,
      "y": 49,
      "z": 14,
      "name": "Empty"
    },
    {
      "x": -1,
      "y": 50,
      "z": 14,
      "name": "Wood_Goldenwood_Planks_Half",
      "rotation": 5
    },
    {
      "x": -1,
      "y": 51,
      "z": 14,
      "name": "Wood_Goldenwood_Planks"
    },
    {
      "x": -1,
      "y": 45,
      "z": 15,
      "name": "Rock_Sandstone_Cobble"
    },
    {
      "x": -1,
      "y": 46,
      "z": 15,
      "name": "Wood_Goldenwood_Planks"
    },
    {
      "x": -1,
      "y": 47,
      "z": 15,
      "name": "Furniture_Desert_Chair",
      "rotation": 1
    },
    {
      "x": -1,
      "y": 48,
      "z": 15,
      "name": "Empty"
    },
    {
      "x": -1,
      "y": 49,
      "z": 15,
      "name": "Empty"
    },
    {
      "x": -1,
      "y": 50,
      "z": 15,
      "name": "Wood_Goldenwood_Planks_Half",
      "rotation": 5
    },
    {
      "x": -1,
      "y": 51,
      "z": 15,
      "name": "Wood_Goldenwood_Planks"
    },
    {
      "x": -1,
      "y": 45,
      "z": 16,
      "name": "Rock_Sandstone_Cobble"
    },
    {
      "x": -1,
      "y": 46,
      "z": 16,
      "name": "Wood_Goldenwood_Planks"
    },
    {
      "x": -1,
      "y": 47,
      "z": 16,
      "name": "Furniture_Village_Shelf_Full",
      "rotation": 1
    },
    {
      "x": -1,
      "y": 48,
      "z": 16,
      "name": "Furniture_Village_Shelf_Full",
      "rotation": 1
    },
    {
      "x": -1,
      "y": 49,
      "z": 16,
      "name": "Furniture_Village_Shelf_Full",
      "rotation": 1
    },
    {
      "x": -1,
      "y": 50,
      "z": 16,
      "name": "Wood_Goldenwood_Planks_Half",
      "rotation": 5
    },
    {
      "x": -1,
      "y": 51,
      "z": 16,
      "name": "Wood_Goldenwood_Planks"
    },
    {
      "x": -1,
      "y": 45,
      "z": 17,
      "name": "Rock_Sandstone_Cobble"
    },
    {
      "x": -1,
      "y": 46,
      "z": 17,
      "name": "Wood_Goldenwood_Planks"
    },
    {
      "x": -1,
      "y": 47,
      "z": 17,
      "name": "Furniture_Village_Counter",
      "rotation": 1
    },
    {
      "x": -1,
      "y": 48,
      "z": 17,
      "name": "Furniture_Village_Counter",
      "rotation": 1
    },
    {
      "x": -1,
      "y": 49,
      "z": 17,
      "name": "*Plant_Crop_Lettuce_Block_State_Definitions_StageFinal",
      "components": {
        "Components": {
          "FarmingBlock": {}
        }
      }
    },
    {
      "x": -1,
      "y": 50,
      "z": 17,
      "name": "Wood_Goldenwood_Planks_Half",
      "rotation": 5
    },
    {
      "x": -1,
      "y": 51,
      "z": 17,
      "name": "Wood_Goldenwood_Planks"
    },
    {
      "x": -1,
      "y": 45,
      "z": 18,
      "name": "Rock_Sandstone_Cobble"
    },
    {
      "x": -1,
      "y": 46,
      "z": 18,
      "name": "Wood_Goldenwood_Planks"
    },
    {
      "x": -1,
      "y": 47,
      "z": 18,
      "name": "Furniture_Village_Counter",
      "filler": 32,
      "rotation": 1
    },
    {
      "x": -1,
      "y": 48,
      "z": 18,
      "name": "Furniture_Village_Counter",
      "filler": 32,
      "rotation": 1
    },
    {
      "x": -1,
      "y": 49,
      "z": 18,
      "name": "Deco_Coral_Shell"
    },
    {
      "x": -1,
      "y": 50,
      "z": 18,
      "name": "Wood_Goldenwood_Planks_Half",
      "rotation": 5
    },
    {
      "x": -1,
      "y": 51,
      "z": 18,
      "name": "Wood_Goldenwood_Planks"
    },
    {
      "x": -1,
      "y": 45,
      "z": 19,
      "name": "Rock_Sandstone_Cobble"
    },
    {
      "x": -1,
      "y": 46,
      "z": 19,
      "name": "Wood_Goldenwood_Planks"
    },
    {
      "x": -1,
      "y": 47,
      "z": 19,
      "name": "Empty"
    },
    {
      "x": -1,
      "y": 48,
      "z": 19,
      "name": "Empty"
    },
    {
      "x": -1,
      "y": 49,
      "z": 19,
      "name": "Empty"
    },
    {
      "x": -1,
      "y": 50,
      "z": 19,
      "name": "Wood_Goldenwood_Planks"
    },
    {
      "x": -1,
      "y": 51,
      "z": 19,
      "name": "Wood_Goldenwood_Planks"
    },
    {
      "x": -1,
      "y": 45,
      "z": 20,
      "name": "Rock_Sandstone_Cobble"
    },
    {
      "x": -1,
      "y": 46,
      "z": 20,
      "name": "Wood_Goldenwood_Planks"
    },
    {
      "x": -1,
      "y": 47,
      "z": 20,
      "name": "Empty"
    },
    {
      "x": -1,
      "y": 48,
      "z": 20,
      "name": "Empty"
    },
    {
      "x": -1,
      "y": 49,
      "z": 20,
      "name": "Empty"
    },
    {
      "x": -1,
      "y": 50,
      "z": 20,
      "name": "Rock_Sandstone_Cobble"
    },
    {
      "x": -1,
      "y": 51,
      "z": 20,
      "name": "Rock_Sandstone_Cobble"
    },
    {
      "x": 0,
      "y": 45,
      "z": 3,
      "name": "Rock_Sandstone_Cobble"
    },
    {
      "x": 0,
      "y": 46,
      "z": 3,
      "name": "Rock_Sandstone_Cobble"
    },
    {
      "x": 0,
      "y": 47,
      "z": 3,
      "name": "Rock_Sandstone_Brick_Ornate"
    },
    {
      "x": 0,
      "y": 48,
      "z": 3,
      "name": "Rock_Sandstone_Cobble"
    },
    {
      "x": 0,
      "y": 49,
      "z": 3,
      "name": "Rock_Sandstone_Cobble"
    },
    {
      "x": 0,
      "y": 50,
      "z": 3,
      "name": "Rock_Sandstone_Cobble"
    },
    {
      "x": 0,
      "y": 51,
      "z": 3,
      "name": "Rock_Sandstone_Cobble"
    },
    {
      "x": 0,
      "y": 45,
      "z": 4,
      "name": "Rock_Sandstone_Cobble"
    },
    {
      "x": 0,
      "y": 46,
      "z": 4,
      "name": "Wood_Goldenwood_Planks"
    },
    {
      "x": 0,
      "y": 47,
      "z": 4,
      "name": "Rock_Sandstone_Brick_Ornate"
    },
    {
      "x": 0,
      "y": 48,
      "z": 4,
      "name": "Rock_Sandstone_Cobble"
    },
    {
      "x": 0,
      "y": 49,
      "z": 4,
      "name": "Rock_Sandstone_Cobble"
    },
    {
      "x": 0,
      "y": 50,
      "z": 4,
      "name": "Rock_Sandstone_Cobble"
    },
    {
      "x": 0,
      "y": 51,
      "z": 4,
      "name": "Wood_Goldenwood_Planks"
    },
    {
      "x": 0,
      "y": 45,
      "z": 5,
      "name": "Rock_Sandstone_Cobble"
    },
    {
      "x": 0,
      "y": 46,
      "z": 5,
      "name": "Wood_Goldenwood_Planks"
    },
    {
      "x": 0,
      "y": 47,
      "z": 5,
      "name": "Rock_Sandstone_Brick_Ornate"
    },
    {
      "x": 0,
      "y": 48,
      "z": 5,
      "name": "Rock_Sandstone_Cobble"
    },
    {
      "x": 0,
      "y": 49,
      "z": 5,
      "name": "Rock_Sandstone_Cobble"
    },
    {
      "x": 0,
      "y": 50,
      "z": 5,
      "name": "Rock_Sandstone_Cobble"
    },
    {
      "x": 0,
      "y": 51,
      "z": 5,
      "name": "Wood_Goldenwood_Planks"
    },
    {
      "x": 0,
      "y": 45,
      "z": 6,
      "name": "Rock_Sandstone_Cobble"
    },
    {
      "x": 0,
      "y": 46,
      "z": 6,
      "name": "Wood_Goldenwood_Planks"
    },
    {
      "x": 0,
      "y": 47,
      "z": 6,
      "name": "Rock_Sandstone_Brick_Ornate"
    },
    {
      "x": 0,
      "y": 48,
      "z": 6,
      "name": "Rock_Sandstone_Cobble"
    },
    {
      "x": 0,
      "y": 49,
      "z": 6,
      "name": "Rock_Sandstone_Cobble"
    },
    {
      "x": 0,
      "y": 50,
      "z": 6,
      "name": "Rock_Sandstone_Cobble"
    },
    {
      "x": 0,
      "y": 51,
      "z": 6,
      "name": "Wood_Goldenwood_Planks"
    },
    {
      "x": 0,
      "y": 45,
      "z": 7,
      "name": "Rock_Sandstone_Cobble"
    },
    {
      "x": 0,
      "y": 46,
      "z": 7,
      "name": "Wood_Goldenwood_Planks"
    },
    {
      "x": 0,
      "y": 47,
      "z": 7,
      "name": "Rock_Sandstone_Brick_Ornate"
    },
    {
      "x": 0,
      "y": 48,
      "z": 7,
      "name": "Rock_Sandstone_Cobble"
    },
    {
      "x": 0,
      "y": 49,
      "z": 7,
      "name": "Rock_Sandstone_Cobble"
    },
    {
      "x": 0,
      "y": 50,
      "z": 7,
      "name": "Rock_Sandstone_Cobble"
    },
    {
      "x": 0,
      "y": 51,
      "z": 7,
      "name": "Wood_Goldenwood_Planks"
    },
    {
      "x": 0,
      "y": 45,
      "z": 8,
      "name": "Rock_Sandstone_Cobble"
    },
    {
      "x": 0,
      "y": 46,
      "z": 8,
      "name": "Wood_Goldenwood_Planks"
    },
    {
      "x": 0,
      "y": 47,
      "z": 8,
      "name": "Rock_Sandstone_Brick_Ornate"
    },
    {
      "x": 0,
      "y": 48,
      "z": 8,
      "name": "Rock_Sandstone_Cobble"
    },
    {
      "x": 0,
      "y": 49,
      "z": 8,
      "name": "Rock_Sandstone_Cobble"
    },
    {
      "x": 0,
      "y": 50,
      "z": 8,
      "name": "Rock_Sandstone_Cobble"
    },
    {
      "x": 0,
      "y": 51,
      "z": 8,
      "name": "Wood_Goldenwood_Planks"
    },
    {
      "x": 0,
      "y": 45,
      "z": 9,
      "name": "Rock_Sandstone_Cobble"
    },
    {
      "x": 0,
      "y": 46,
      "z": 9,
      "name": "Wood_Goldenwood_Planks"
    },
    {
      "x": 0,
      "y": 47,
      "z": 9,
      "name": "Rock_Sandstone_Brick_Ornate"
    },
    {
      "x": 0,
      "y": 48,
      "z": 9,
      "name": "Rock_Sandstone_Cobble"
    },
    {
      "x": 0,
      "y": 49,
      "z": 9,
      "name": "Rock_Sandstone_Cobble"
    },
    {
      "x": 0,
      "y": 50,
      "z": 9,
      "name": "Rock_Sandstone_Cobble"
    },
    {
      "x": 0,
      "y": 51,
      "z": 9,
      "name": "Wood_Goldenwood_Planks"
    },
    {
      "x": 0,
      "y": 45,
      "z": 10,
      "name": "Rock_Sandstone_Cobble"
    },
    {
      "x": 0,
      "y": 46,
      "z": 10,
      "name": "Wood_Goldenwood_Planks"
    },
    {
      "x": 0,
      "y": 47,
      "z": 10,
      "name": "Empty"
    },
    {
      "x": 0,
      "y": 48,
      "z": 10,
      "name": "Empty"
    },
    {
      "x": 0,
      "y": 49,
      "z": 10,
      "name": "Empty"
    },
    {
      "x": 0,
      "y": 50,
      "z": 10,
      "name": "Wood_Goldenwood_Planks_Half",
      "rotation": 4
    },
    {
      "x": 0,
      "y": 51,
      "z": 10,
      "name": "Wood_Goldenwood_Planks"
    },
    {
      "x": 0,
      "y": 45,
      "z": 11,
      "name": "Rock_Sandstone_Cobble"
    },
    {
      "x": 0,
      "y": 46,
      "z": 11,
      "name": "Wood_Goldenwood_Planks"
    },
    {
      "x": 0,
      "y": 47,
      "z": 11,
      "name": "Empty"
    },
    {
      "x": 0,
      "y": 48,
      "z": 11,
      "name": "Empty"
    },
    {
      "x": 0,
      "y": 49,
      "z": 11,
      "name": "Empty"
    },
    {
      "x": 0,
      "y": 50,
      "z": 11,
      "name": "Empty"
    },
    {
      "x": 0,
      "y": 51,
      "z": 11,
      "name": "Wood_Goldenwood_Planks"
    },
    {
      "x": 0,
      "y": 45,
      "z": 12,
      "name": "Rock_Sandstone_Cobble"
    },
    {
      "x": 0,
      "y": 46,
      "z": 12,
      "name": "Wood_Goldenwood_Planks"
    },
    {
      "x": 0,
      "y": 47,
      "z": 12,
      "name": "Empty"
    },
    {
      "x": 0,
      "y": 48,
      "z": 12,
      "name": "Empty"
    },
    {
      "x": 0,
      "y": 49,
      "z": 12,
      "name": "Empty"
    },
    {
      "x": 0,
      "y": 50,
      "z": 12,
      "name": "Empty"
    },
    {
      "x": 0,
      "y": 51,
      "z": 12,
      "name": "Wood_Goldenwood_Planks"
    },
    {
      "x": 0,
      "y": 45,
      "z": 13,
      "name": "Rock_Sandstone_Cobble"
    },
    {
      "x": 0,
      "y": 46,
      "z": 13,
      "name": "Wood_Goldenwood_Planks"
    },
    {
      "x": 0,
      "y": 47,
      "z": 13,
      "name": "Empty"
    },
    {
      "x": 0,
      "y": 48,
      "z": 13,
      "name": "Empty"
    },
    {
      "x": 0,
      "y": 49,
      "z": 13,
      "name": "Empty"
    },
    {
      "x": 0,
      "y": 50,
      "z": 13,
      "name": "Empty"
    },
    {
      "x": 0,
      "y": 51,
      "z": 13,
      "name": "Wood_Goldenwood_Planks"
    },
    {
      "x": 0,
      "y": 45,
      "z": 14,
      "name": "Rock_Sandstone_Cobble"
    },
    {
      "x": 0,
      "y": 46,
      "z": 14,
      "name": "Wood_Goldenwood_Planks"
    },
    {
      "x": 0,
      "y": 47,
      "z": 14,
      "name": "Empty"
    },
    {
      "x": 0,
      "y": 48,
      "z": 14,
      "name": "Empty"
    },
    {
      "x": 0,
      "y": 49,
      "z": 14,
      "name": "Furniture_Tavern_Chandelier",
      "filler": 32767
    },
    {
      "x": 0,
      "y": 50,
      "z": 14,
      "name": "Furniture_Tavern_Chandelier",
      "filler": 1023
    },
    {
      "x": 0,
      "y": 51,
      "z": 14,
      "name": "Wood_Goldenwood_Planks"
    },
    {
      "x": 0,
      "y": 45,
      "z": 15,
      "name": "Rock_Sandstone_Cobble"
    },
    {
      "x": 0,
      "y": 46,
      "z": 15,
      "name": "Cloth_Block_Wool_Black"
    },
    {
      "x": 0,
      "y": 47,
      "z": 15,
      "name": "Furniture_Desert_Table"
    },
    {
      "x": 0,
      "y": 48,
      "z": 15,
      "name": "Empty"
    },
    {
      "x": 0,
      "y": 49,
      "z": 15,
      "name": "Furniture_Tavern_Chandelier",
      "filler": 31775
    },
    {
      "x": 0,
      "y": 50,
      "z": 15,
      "name": "Furniture_Tavern_Chandelier",
      "filler": 31
    },
    {
      "x": 0,
      "y": 51,
      "z": 15,
      "name": "Wood_Goldenwood_Planks"
    },
    {
      "x": 0,
      "y": 45,
      "z": 16,
      "name": "Rock_Sandstone_Cobble"
    },
    {
      "x": 0,
      "y": 46,
      "z": 16,
      "name": "Cloth_Block_Wool_Black"
    },
    {
      "x": 0,
      "y": 47,
      "z": 16,
      "name": "Furniture_Desert_Table",
      "filler": 32
    },
    {
      "x": 0,
      "y": 48,
      "z": 16,
      "name": "Empty"
    },
    {
      "x": 0,
      "y": 49,
      "z": 16,
      "name": "Furniture_Tavern_Chandelier",
      "filler": 31807
    },
    {
      "x": 0,
      "y": 50,
      "z": 16,
      "name": "Furniture_Tavern_Chandelier",
      "filler": 63
    },
    {
      "x": 0,
      "y": 51,
      "z": 16,
      "name": "Wood_Goldenwood_Planks"
    },
    {
      "x": 0,
      "y": 45,
      "z": 17,
      "name": "Rock_Sandstone_Cobble"
    },
    {
      "x": 0,
      "y": 46,
      "z": 17,
      "name": "Cloth_Block_Wool_Black"
    },
    {
      "x": 0,
      "y": 47,
      "z": 17,
      "name": "Empty"
    },
    {
      "x": 0,
      "y": 48,
      "z": 17,
      "name": "Empty"
    },
    {
      "x": 0,
      "y": 49,
      "z": 17,
      "name": "Empty"
    },
    {
      "x": 0,
      "y": 50,
      "z": 17,
      "name": "Empty"
    },
    {
      "x": 0,
      "y": 51,
      "z": 17,
      "name": "Wood_Goldenwood_Planks"
    },
    {
      "x": 0,
      "y": 45,
      "z": 18,
      "name": "Rock_Sandstone_Cobble"
    },
    {
      "x": 0,
      "y": 46,
      "z": 18,
      "name": "Cloth_Block_Wool_Black"
    },
    {
      "x": 0,
      "y": 47,
      "z": 18,
      "name": "Empty"
    },
    {
      "x": 0,
      "y": 48,
      "z": 18,
      "name": "Empty"
    },
    {
      "x": 0,
      "y": 49,
      "z": 18,
      "name": "Empty"
    },
    {
      "x": 0,
      "y": 50,
      "z": 18,
      "name": "Empty"
    },
    {
      "x": 0,
      "y": 51,
      "z": 18,
      "name": "Wood_Goldenwood_Planks"
    },
    {
      "x": 0,
      "y": 45,
      "z": 19,
      "name": "Rock_Sandstone_Cobble"
    },
    {
      "x": 0,
      "y": 46,
      "z": 19,
      "name": "Wood_Goldenwood_Planks"
    },
    {
      "x": 0,
      "y": 47,
      "z": 19,
      "name": "Empty"
    },
    {
      "x": 0,
      "y": 48,
      "z": 19,
      "name": "Empty"
    },
    {
      "x": 0,
      "y": 49,
      "z": 19,
      "name": "Empty"
    },
    {
      "x": 0,
      "y": 50,
      "z": 19,
      "name": "Wood_Goldenwood_Planks_Half",
      "rotation": 6
    },
    {
      "x": 0,
      "y": 51,
      "z": 19,
      "name": "Wood_Goldenwood_Planks"
    },
    {
      "x": 0,
      "y": 45,
      "z": 20,
      "name": "Rock_Sandstone_Cobble"
    },
    {
      "x": 0,
      "y": 46,
      "z": 20,
      "name": "Wood_Goldenwood_Planks"
    },
    {
      "x": 0,
      "y": 47,
      "z": 20,
      "name": "Empty"
    },
    {
      "x": 0,
      "y": 48,
      "z": 20,
      "name": "Empty"
    },
    {
      "x": 0,
      "y": 49,
      "z": 20,
      "name": "Empty"
    },
    {
      "x": 0,
      "y": 50,
      "z": 20,
      "name": "Rock_Sandstone_Cobble"
    },
    {
      "x": 0,
      "y": 51,
      "z": 20,
      "name": "Rock_Sandstone_Cobble"
    },
    {
      "x": 1,
      "y": 45,
      "z": 3,
      "name": "Rock_Sandstone_Cobble"
    },
    {
      "x": 1,
      "y": 46,
      "z": 3,
      "name": "Rock_Sandstone_Cobble"
    },
    {
      "x": 1,
      "y": 47,
      "z": 3,
      "name": "Rock_Sandstone_Brick_Ornate"
    },
    {
      "x": 1,
      "y": 48,
      "z": 3,
      "name": "Rock_Sandstone_Cobble"
    },
    {
      "x": 1,
      "y": 49,
      "z": 3,
      "name": "Rock_Sandstone_Cobble"
    },
    {
      "x": 1,
      "y": 50,
      "z": 3,
      "name": "Rock_Sandstone_Cobble"
    },
    {
      "x": 1,
      "y": 51,
      "z": 3,
      "name": "Rock_Sandstone_Cobble"
    },
    {
      "x": 1,
      "y": 45,
      "z": 4,
      "name": "Rock_Sandstone_Cobble"
    },
    {
      "x": 1,
      "y": 46,
      "z": 4,
      "name": "Wood_Goldenwood_Planks"
    },
    {
      "x": 1,
      "y": 47,
      "z": 4,
      "name": "Empty"
    },
    {
      "x": 1,
      "y": 48,
      "z": 4,
      "name": "Furniture_Lumberjack_Shelf"
    },
    {
      "x": 1,
      "y": 49,
      "z": 4,
      "name": "Furniture_Ancient_Pot"
    },
    {
      "x": 1,
      "y": 50,
      "z": 4,
      "name": "Wood_Goldenwood_Planks"
    },
    {
      "x": 1,
      "y": 51,
      "z": 4,
      "name": "Wood_Goldenwood_Planks"
    },
    {
      "x": 1,
      "y": 45,
      "z": 5,
      "name": "Rock_Sandstone_Cobble"
    },
    {
      "x": 1,
      "y": 46,
      "z": 5,
      "name": "Wood_Goldenwood_Planks"
    },
    {
      "x": 1,
      "y": 47,
      "z": 5,
      "name": "Furniture_Village_Bookcase",
      "rotation": 1
    },
    {
      "x": 1,
      "y": 48,
      "z": 5,
      "name": "Furniture_Village_Bookcase",
      "rotation": 1
    },
    {
      "x": 1,
      "y": 49,
      "z": 5,
      "name": "Furniture_Village_Bookcase",
      "rotation": 1
    },
    {
      "x": 1,
      "y": 50,
      "z": 5,
      "name": "Wood_Goldenwood_Planks_Half",
      "rotation": 5
    },
    {
      "x": 1,
      "y": 51,
      "z": 5,
      "name": "Wood_Goldenwood_Planks"
    },
    {
      "x": 1,
      "y": 45,
      "z": 6,
      "name": "Rock_Sandstone_Cobble"
    },
    {
      "x": 1,
      "y": 46,
      "z": 6,
      "name": "Wood_Goldenwood_Planks"
    },
    {
      "x": 1,
      "y": 47,
      "z": 6,
      "name": "Furniture_Village_Bookcase",
      "rotation": 1
    },
    {
      "x": 1,
      "y": 48,
      "z": 6,
      "name": "Furniture_Village_Bookcase",
      "rotation": 1
    },
    {
      "x": 1,
      "y": 49,
      "z": 6,
      "name": "Furniture_Village_Bookcase",
      "rotation": 1
    },
    {
      "x": 1,
      "y": 50,
      "z": 6,
      "name": "Wood_Goldenwood_Planks_Half",
      "rotation": 5
    },
    {
      "x": 1,
      "y": 51,
      "z": 6,
      "name": "Wood_Goldenwood_Planks"
    },
    {
      "x": 1,
      "y": 45,
      "z": 7,
      "name": "Rock_Sandstone_Cobble"
    },
    {
      "x": 1,
      "y": 46,
      "z": 7,
      "name": "Wood_Goldenwood_Planks"
    },
    {
      "x": 1,
      "y": 47,
      "z": 7,
      "name": "Furniture_Village_Counter",
      "rotation": 1
    },
    {
      "x": 1,
      "y": 48,
      "z": 7,
      "name": "Empty"
    },
    {
      "x": 1,
      "y": 49,
      "z": 7,
      "name": "Empty"
    },
    {
      "x": 1,
      "y": 50,
      "z": 7,
      "name": "Wood_Goldenwood_Planks_Half",
      "rotation": 5
    },
    {
      "x": 1,
      "y": 51,
      "z": 7,
      "name": "Wood_Goldenwood_Planks"
    },
    {
      "x": 1,
      "y": 45,
      "z": 8,
      "name": "Rock_Sandstone_Cobble"
    },
    {
      "x": 1,
      "y": 46,
      "z": 8,
      "name": "Wood_Goldenwood_Planks"
    },
    {
      "x": 1,
      "y": 47,
      "z": 8,
      "name": "Furniture_Village_Counter",
      "filler": 32,
      "rotation": 1
    },
    {
      "x": 1,
      "y": 48,
      "z": 8,
      "name": "*Plant_Crop_Cauliflower_Block_State_Definitions_StageFinal",
      "components": {
        "Components": {
          "FarmingBlock": {}
        }
      }
    },
    {
      "x": 1,
      "y": 49,
      "z": 8,
      "name": "Empty"
    },
    {
      "x": 1,
      "y": 50,
      "z": 8,
      "name": "Wood_Goldenwood_Planks"
    },
    {
      "x": 1,
      "y": 51,
      "z": 8,
      "name": "Wood_Goldenwood_Planks"
    },
    {
      "x": 1,
      "y": 45,
      "z": 9,
      "name": "Rock_Sandstone_Cobble"
    },
    {
      "x": 1,
      "y": 46,
      "z": 9,
      "name": "Wood_Goldenwood_Planks"
    },
    {
      "x": 1,
      "y": 47,
      "z": 9,
      "name": "Rock_Sandstone_Brick_Ornate"
    },
    {
      "x": 1,
      "y": 48,
      "z": 9,
      "name": "Rock_Sandstone_Cobble"
    },
    {
      "x": 1,
      "y": 49,
      "z": 9,
      "name": "Rock_Sandstone_Cobble"
    },
    {
      "x": 1,
      "y": 50,
      "z": 9,
      "name": "Rock_Sandstone_Cobble"
    },
    {
      "x": 1,
      "y": 51,
      "z": 9,
      "name": "Wood_Goldenwood_Planks"
    },
    {
      "x": 1,
      "y": 45,
      "z": 10,
      "name": "Rock_Sandstone_Cobble"
    },
    {
      "x": 1,
      "y": 46,
      "z": 10,
      "name": "Wood_Goldenwood_Planks"
    },
    {
      "x": 1,
      "y": 47,
      "z": 10,
      "name": "Furniture_Village_Bookcase"
    },
    {
      "x": 1,
      "y": 48,
      "z": 10,
      "name": "Furniture_Village_Bookcase"
    },
    {
      "x": 1,
      "y": 49,
      "z": 10,
      "name": "Furniture_Village_Bookcase"
    },
    {
      "x": 1,
      "y": 50,
      "z": 10,
      "name": "Wood_Goldenwood_Planks_Half",
      "rotation": 4
    },
    {
      "x": 1,
      "y": 51,
      "z": 10,
      "name": "Wood_Goldenwood_Planks"
    },
    {
      "x": 1,
      "y": 45,
      "z": 11,
      "name": "Rock_Sandstone_Cobble"
    },
    {
      "x": 1,
      "y": 46,
      "z": 11,
      "name": "Wood_Goldenwood_Planks"
    },
    {
      "x": 1,
      "y": 47,
      "z": 11,
      "name": "Empty"
    },
    {
      "x": 1,
      "y": 48,
      "z": 11,
      "name": "Empty"
    },
    {
      "x": 1,
      "y": 49,
      "z": 11,
      "name": "Empty"
    },
    {
      "x": 1,
      "y": 50,
      "z": 11,
      "name": "Empty"
    },
    {
      "x": 1,
      "y": 51,
      "z": 11,
      "name": "Wood_Goldenwood_Planks"
    },
    {
      "x": 1,
      "y": 45,
      "z": 12,
      "name": "Rock_Sandstone_Cobble"
    },
    {
      "x": 1,
      "y": 46,
      "z": 12,
      "name": "Wood_Goldenwood_Planks"
    },
    {
      "x": 1,
      "y": 47,
      "z": 12,
      "name": "Empty"
    },
    {
      "x": 1,
      "y": 48,
      "z": 12,
      "name": "Empty"
    },
    {
      "x": 1,
      "y": 49,
      "z": 12,
      "name": "Empty"
    },
    {
      "x": 1,
      "y": 50,
      "z": 12,
      "name": "Empty"
    },
    {
      "x": 1,
      "y": 51,
      "z": 12,
      "name": "Wood_Goldenwood_Planks"
    },
    {
      "x": 1,
      "y": 45,
      "z": 13,
      "name": "Rock_Sandstone_Cobble"
    },
    {
      "x": 1,
      "y": 46,
      "z": 13,
      "name": "Wood_Goldenwood_Planks"
    },
    {
      "x": 1,
      "y": 47,
      "z": 13,
      "name": "Empty"
    },
    {
      "x": 1,
      "y": 48,
      "z": 13,
      "name": "Empty"
    },
    {
      "x": 1,
      "y": 49,
      "z": 13,
      "name": "Empty"
    },
    {
      "x": 1,
      "y": 50,
      "z": 13,
      "name": "Empty"
    },
    {
      "x": 1,
      "y": 51,
      "z": 13,
      "name": "Wood_Goldenwood_Planks"
    },
    {
      "x": 1,
      "y": 45,
      "z": 14,
      "name": "Rock_Sandstone_Cobble"
    },
    {
      "x": 1,
      "y": 46,
      "z": 14,
      "name": "Wood_Goldenwood_Planks"
    },
    {
      "x": 1,
      "y": 47,
      "z": 14,
      "name": "Empty"
    },
    {
      "x": 1,
      "y": 48,
      "z": 14,
      "name": "Empty"
    },
    {
      "x": 1,
      "y": 49,
      "z": 14,
      "name": "Furniture_Tavern_Chandelier",
      "filler": 32736
    },
    {
      "x": 1,
      "y": 50,
      "z": 14,
      "name": "Furniture_Tavern_Chandelier",
      "filler": 992
    },
    {
      "x": 1,
      "y": 51,
      "z": 14,
      "name": "Wood_Goldenwood_Planks"
    },
    {
      "x": 1,
      "y": 45,
      "z": 15,
      "name": "Rock_Sandstone_Cobble"
    },
    {
      "x": 1,
      "y": 46,
      "z": 15,
      "name": "Cloth_Block_Wool_Black"
    },
    {
      "x": 1,
      "y": 47,
      "z": 15,
      "name": "Furniture_Desert_Table",
      "filler": 1
    },
    {
      "x": 1,
      "y": 48,
      "z": 15,
      "name": "Recipe_Book_Magic_Air"
    },
    {
      "x": 1,
      "y": 49,
      "z": 15,
      "name": "Furniture_Tavern_Chandelier",
      "filler": 31744
    },
    {
      "x": 1,
      "y": 50,
      "z": 15,
      "name": "Furniture_Tavern_Chandelier"
    },
    {
      "x": 1,
      "y": 51,
      "z": 15,
      "name": "Wood_Goldenwood_Planks"
    },
    {
      "x": 1,
      "y": 45,
      "z": 16,
      "name": "Rock_Sandstone_Cobble"
    },
    {
      "x": 1,
      "y": 46,
      "z": 16,
      "name": "Cloth_Block_Wool_Black"
    },
    {
      "x": 1,
      "y": 47,
      "z": 16,
      "name": "Furniture_Desert_Table",
      "filler": 33
    },
    {
      "x": 1,
      "y": 48,
      "z": 16,
      "name": "Empty"
    },
    {
      "x": 1,
      "y": 49,
      "z": 16,
      "name": "Furniture_Tavern_Chandelier",
      "filler": 31776
    },
    {
      "x": 1,
      "y": 50,
      "z": 16,
      "name": "Furniture_Tavern_Chandelier",
      "filler": 32
    },
    {
      "x": 1,
      "y": 51,
      "z": 16,
      "name": "Wood_Goldenwood_Planks"
    },
    {
      "x": 1,
      "y": 45,
      "z": 17,
      "name": "Rock_Sandstone_Cobble"
    },
    {
      "x": 1,
      "y": 46,
      "z": 17,
      "name": "Cloth_Block_Wool_Black"
    },
    {
      "x": 1,
      "y": 47,
      "z": 17,
      "name": "Empty"
    },
    {
      "x": 1,
      "y": 48,
      "z": 17,
      "name": "Empty"
    },
    {
      "x": 1,
      "y": 49,
      "z": 17,
      "name": "Empty"
    },
    {
      "x": 1,
      "y": 50,
      "z": 17,
      "name": "Empty"
    },
    {
      "x": 1,
      "y": 51,
      "z": 17,
      "name": "Wood_Goldenwood_Planks"
    },
    {
      "x": 1,
      "y": 45,
      "z": 18,
      "name": "Rock_Sandstone_Cobble"
    },
    {
      "x": 1,
      "y": 46,
      "z": 18,
      "name": "Cloth_Block_Wool_Black"
    },
    {
      "x": 1,
      "y": 47,
      "z": 18,
      "name": "Empty"
    },
    {
      "x": 1,
      "y": 48,
      "z": 18,
      "name": "Empty"
    },
    {
      "x": 1,
      "y": 49,
      "z": 18,
      "name": "Empty"
    },
    {
      "x": 1,
      "y": 50,
      "z": 18,
      "name": "Empty"
    },
    {
      "x": 1,
      "y": 51,
      "z": 18,
      "name": "Wood_Goldenwood_Planks"
    },
    {
      "x": 1,
      "y": 45,
      "z": 19,
      "name": "Rock_Sandstone_Cobble"
    },
    {
      "x": 1,
      "y": 46,
      "z": 19,
      "name": "Wood_Goldenwood_Planks"
    },
    {
      "x": 1,
      "y": 47,
      "z": 19,
      "name": "Empty"
    },
    {
      "x": 1,
      "y": 48,
      "z": 19,
      "name": "Empty"
    },
    {
      "x": 1,
      "y": 49,
      "z": 19,
      "name": "Empty"
    },
    {
      "x": 1,
      "y": 50,
      "z": 19,
      "name": "Wood_Goldenwood_Planks_Half",
      "rotation": 6
    },
    {
      "x": 1,
      "y": 51,
      "z": 19,
      "name": "Wood_Goldenwood_Planks"
    },
    {
      "x": 1,
      "y": 45,
      "z": 20,
      "name": "Rock_Sandstone_Cobble"
    },
    {
      "x": 1,
      "y": 46,
      "z": 20,
      "name": "Wood_Goldenwood_Planks"
    },
    {
      "x": 1,
      "y": 47,
      "z": 20,
      "name": "Empty"
    },
    {
      "x": 1,
      "y": 48,
      "z": 20,
      "name": "Empty"
    },
    {
      "x": 1,
      "y": 49,
      "z": 20,
      "name": "Empty"
    },
    {
      "x": 1,
      "y": 50,
      "z": 20,
      "name": "Rock_Sandstone_Cobble"
    },
    {
      "x": 1,
      "y": 51,
      "z": 20,
      "name": "Rock_Sandstone_Cobble"
    },
    {
      "x": 2,
      "y": 45,
      "z": 3,
      "name": "Rock_Sandstone_Cobble"
    },
    {
      "x": 2,
      "y": 46,
      "z": 3,
      "name": "Rock_Sandstone_Cobble"
    },
    {
      "x": 2,
      "y": 47,
      "z": 3,
      "name": "Rock_Sandstone_Brick_Ornate"
    },
    {
      "x": 2,
      "y": 48,
      "z": 3,
      "name": "Rock_Sandstone_Cobble"
    },
    {
      "x": 2,
      "y": 49,
      "z": 3,
      "name": "Rock_Sandstone_Cobble"
    },
    {
      "x": 2,
      "y": 50,
      "z": 3,
