{
  "version": 8,
  "blockIdVersion": 8,
  "anchorX": 0,
  "anchorY": 0,
  "anchorZ": 0,
  "blocks": [
    {
      "x": -8,
      "y": -6,
      "z": -16,
      "name": "Rock_Shale"
    },
    {
      "x": -8,
      "y": -5,
      "z": -16,
      "name": "Rock_Shale"
    },
    {
      "x": -8,
      "y": -4,
      "z": -16,
      "name": "Rock_Shale"
    },
    {
      "x": -8,
      "y": -3,
      "z": -16,
      "name": "Rock_Shale"
    },
    {
      "x": -8,
      "y": -2,
      "z": -16,
      "name": "Rock_Shale"
    },
    {
      "x": -8,
      "y": -1,
      "z": -16,
      "name": "Rock_Shale"
    },
    {
      "x": -8,
      "y": 0,
      "z": -16,
      "name": "Rock_Shale"
    },
    {
      "x": -8,
      "y": 1,
      "z": -16,
      "name": "Rock_Shale"
    },
    {
      "x": -8,
      "y": 2,
      "z": -16,
      "name": "Rock_Shale"
    },
    {
      "x": -8,
      "y": 3,
      "z": -16,
      "name": "Rock_Shale"
    },
    {
      "x": -8,
      "y": 4,
      "z": -16,
      "name": "Rock_Shale"
    },
    {
      "x": -8,
      "y": 5,
      "z": -16,
      "name": "Rock_Shale"
    },
    {
      "x": -8,
      "y": 6,
      "z": -16,
      "name": "Rock_Shale"
    },
    {
      "x": -8,
      "y": 7,
      "z": -16,
      "name": "Rock_Shale"
    },
    {
      "x": -8,
      "y": 8,
      "z": -16,
      "name": "Rock_Shale"
    },
    {
      "x": -8,
      "y": 9,
      "z": -16,
      "name": "Rock_Shale"
    },
    {
      "x": -8,
      "y": 10,
      "z": -16,
      "name": "Rock_Shale"
    },
    {
      "x": -8,
      "y": 11,
      "z": -16,
      "name": "Rock_Shale"
    },
    {
      "x": -8,
      "y": -6,
      "z": -15,
      "name": "Rock_Shale"
    },
    {
      "x": -8,
      "y": -5,
      "z": -15,
      "name": "Rock_Shale"
    },
    {
      "x": -8,
      "y": -4,
      "z": -15,
      "name": "Rock_Shale"
    },
    {
      "x": -8,
      "y": -3,
      "z": -15,
      "name": "Rock_Shale"
    },
    {
      "x": -8,
      "y": -2,
      "z": -15,
      "name": "Rock_Shale"
    },
    {
      "x": -8,
      "y": -1,
      "z": -15,
      "name": "Rock_Shale"
    },
    {
      "x": -8,
      "y": 0,
      "z": -15,
      "name": "Rock_Shale"
    },
    {
      "x": -8,
      "y": 1,
      "z": -15,
      "name": "Rock_Shale"
    },
    {
      "x": -8,
      "y": 2,
      "z": -15,
      "name": "Rock_Shale"
    },
    {
      "x": -8,
      "y": 3,
      "z": -15,
      "name": "Rock_Shale"
    },
    {
      "x": -8,
      "y": 4,
      "z": -15,
      "name": "Rock_Shale"
    },
    {
      "x": -8,
      "y": 5,
      "z": -15,
      "name": "Rock_Shale"
    },
    {
      "x": -8,
      "y": 6,
      "z": -15,
      "name": "Rock_Shale"
    },
    {
      "x": -8,
      "y": 7,
      "z": -15,
      "name": "Rock_Shale"
    },
    {
      "x": -8,
      "y": 8,
      "z": -15,
      "name": "Rock_Shale"
    },
    {
      "x": -8,
      "y": 9,
      "z": -15,
      "name": "Rock_Shale"
    },
    {
      "x": -8,
      "y": 10,
      "z": -15,
      "name": "Rock_Shale"
    },
    {
      "x": -8,
      "y": 11,
      "z": -15,
      "name": "Rock_Shale"
    },
    {
      "x": -8,
      "y": -6,
      "z": -14,
      "name": "Rock_Shale"
    },
    {
      "x": -8,
      "y": -5,
      "z": -14,
      "name": "Rock_Shale"
    },
    {
      "x": -8,
      "y": -4,
      "z": -14,
      "name": "Rock_Shale"
    },
    {
      "x": -8,
      "y": -3,
      "z": -14,
      "name": "Rock_Shale"
    },
    {
      "x": -8,
      "y": -2,
      "z": -14,
      "name": "Rock_Shale"
    },
    {
      "x": -8,
      "y": -1,
      "z": -14,
      "name": "Rock_Shale"
    },
    {
      "x": -8,
      "y": 0,
      "z": -14,
      "name": "Rock_Shale"
    },
    {
      "x": -8,
      "y": 1,
      "z": -14,
      "name": "Rock_Shale"
    },
    {
      "x": -8,
      "y": 2,
      "z": -14,
      "name": "Rock_Shale"
    },
    {
      "x": -8,
      "y": 3,
      "z": -14,
      "name": "Rock_Shale"
    },
    {
      "x": -8,
      "y": 4,
      "z": -14,
      "name": "Rock_Shale"
    },
    {
      "x": -8,
      "y": 5,
      "z": -14,
      "name": "Rock_Shale"
    },
    {
      "x": -8,
      "y": 6,
      "z": -14,
      "name": "Rock_Shale"
    },
    {
      "x": -8,
      "y": 7,
      "z": -14,
      "name": "Rock_Shale"
    },
    {
      "x": -8,
      "y": 8,
      "z": -14,
      "name": "Rock_Shale"
    },
    {
      "x": -8,
      "y": 9,
      "z": -14,
      "name": "Rock_Shale"
    },
    {
      "x": -8,
      "y": 10,
      "z": -14,
      "name": "Rock_Shale"
    },
    {
      "x": -8,
      "y": 11,
      "z": -14,
      "name": "Rock_Shale"
    },
    {
      "x": -8,
      "y": -6,
      "z": -13,
      "name": "Rock_Shale"
    },
    {
      "x": -8,
      "y": -5,
      "z": -13,
      "name": "Rock_Shale"
    },
    {
      "x": -8,
      "y": -4,
      "z": -13,
      "name": "Rock_Shale"
    },
    {
      "x": -8,
      "y": -3,
      "z": -13,
      "name": "Rock_Shale"
    },
    {
      "x": -8,
      "y": -2,
      "z": -13,
      "name": "Rock_Shale"
    },
    {
      "x": -8,
      "y": -1,
      "z": -13,
      "name": "Rock_Shale"
    },
    {
      "x": -8,
      "y": 0,
      "z": -13,
      "name": "Rock_Shale"
    },
    {
      "x": -8,
      "y": 1,
      "z": -13,
      "name": "Rock_Shale"
    },
    {
      "x": -8,
      "y": 2,
      "z": -13,
      "name": "Rock_Shale"
    },
    {
      "x": -8,
      "y": 3,
      "z": -13,
      "name": "Rock_Shale"
    },
    {
      "x": -8,
      "y": 4,
      "z": -13,
      "name": "Rock_Shale"
    },
    {
      "x": -8,
      "y": 5,
      "z": -13,
      "name": "Rock_Shale"
    },
    {
      "x": -8,
      "y": 6,
      "z": -13,
      "name": "Rock_Shale"
    },
    {
      "x": -8,
      "y": 7,
      "z": -13,
      "name": "Rock_Shale"
    },
    {
      "x": -8,
      "y": 8,
      "z": -13,
      "name": "Rock_Shale"
    },
    {
      "x": -8,
      "y": 9,
      "z": -13,
      "name": "Rock_Shale"
    },
    {
      "x": -8,
      "y": 10,
      "z": -13,
      "name": "Rock_Shale"
    },
    {
      "x": -8,
      "y": 11,
      "z": -13,
      "name": "Rock_Shale"
    },
    {
      "x": -8,
      "y": -6,
      "z": -12,
      "name": "Rock_Shale"
    },
    {
      "x": -8,
      "y": -5,
      "z": -12,
      "name": "Rock_Shale"
    },
    {
      "x": -8,
      "y": -4,
      "z": -12,
      "name": "Rock_Shale"
    },
    {
      "x": -8,
      "y": -3,
      "z": -12,
      "name": "Rock_Shale"
    },
    {
      "x": -8,
      "y": -2,
      "z": -12,
      "name": "Rock_Shale"
    },
    {
      "x": -8,
      "y": -1,
      "z": -12,
      "name": "Rock_Shale"
    },
    {
      "x": -8,
      "y": 0,
      "z": -12,
      "name": "Rock_Shale"
    },
    {
      "x": -8,
      "y": 1,
      "z": -12,
      "name": "Rock_Shale"
    },
    {
      "x": -8,
      "y": 2,
      "z": -12,
      "name": "Rock_Shale"
    },
    {
      "x": -8,
      "y": 3,
      "z": -12,
      "name": "Rock_Shale"
    },
    {
      "x": -8,
      "y": 4,
      "z": -12,
      "name": "Rock_Shale"
    },
    {
      "x": -8,
      "y": 5,
      "z": -12,
      "name": "Rock_Shale"
    },
    {
      "x": -8,
      "y": 6,
      "z": -12,
      "name": "Rock_Shale"
    },
    {
      "x": -8,
      "y": 7,
      "z": -12,
      "name": "Rock_Shale"
    },
    {
      "x": -8,
      "y": 8,
      "z": -12,
      "name": "Rock_Shale"
    },
    {
      "x": -8,
      "y": 9,
      "z": -12,
      "name": "Rock_Shale"
    },
    {
      "x": -8,
      "y": 10,
      "z": -12,
      "name": "Rock_Shale"
    },
    {
      "x": -8,
      "y": 11,
      "z": -12,
      "name": "Rock_Shale"
    },
    {
      "x": -8,
      "y": -6,
      "z": -11,
      "name": "Rock_Shale"
    },
    {
      "x": -8,
      "y": -5,
      "z": -11,
      "name": "Rock_Shale"
    },
    {
      "x": -8,
      "y": -4,
      "z": -11,
      "name": "Rock_Shale"
    },
    {
      "x": -8,
      "y": -3,
      "z": -11,
      "name": "Rock_Shale"
    },
    {
      "x": -8,
      "y": -2,
      "z": -11,
      "name": "Rock_Shale"
    },
    {
      "x": -8,
      "y": -1,
      "z": -11,
      "name": "Rock_Shale"
    },
    {
      "x": -8,
      "y": 0,
      "z": -11,
      "name": "Rock_Shale"
    },
    {
      "x": -8,
      "y": 1,
      "z": -11,
      "name": "Rock_Shale"
    },
    {
      "x": -8,
      "y": 2,
      "z": -11,
      "name": "Rock_Shale"
    },
    {
      "x": -8,
      "y": 3,
      "z": -11,
      "name": "Rock_Shale"
    },
    {
      "x": -8,
      "y": 4,
      "z": -11,
      "name": "Rock_Shale"
    },
    {
      "x": -8,
      "y": 5,
      "z": -11,
      "name": "Rock_Shale"
    },
    {
      "x": -8,
      "y": 6,
      "z": -11,
      "name": "Rock_Shale"
    },
    {
      "x": -8,
      "y": 7,
      "z": -11,
      "name": "Rock_Shale"
    },
    {
      "x": -8,
      "y": 8,
      "z": -11,
      "name": "Rock_Shale"
    },
    {
      "x": -8,
      "y": 9,
      "z": -11,
      "name": "Rock_Shale"
    },
    {
      "x": -8,
      "y": 10,
      "z": -11,
      "name": "Rock_Shale"
    },
    {
      "x": -8,
      "y": 11,
      "z": -11,
      "name": "Rock_Shale"
    },
    {
      "x": -8,
      "y": -6,
      "z": -10,
      "name": "Rock_Shale"
    },
    {
      "x": -8,
      "y": -5,
      "z": -10,
      "name": "Rock_Shale"
    },
    {
      "x": -8,
      "y": -4,
      "z": -10,
      "name": "Rock_Shale"
    },
    {
      "x": -8,
      "y": -3,
      "z": -10,
      "name": "Rock_Shale"
    },
    {
      "x": -8,
      "y": -2,
      "z": -10,
      "name": "Rock_Shale"
    },
    {
      "x": -8,
      "y": -1,
      "z": -10,
      "name": "Rock_Shale"
    },
    {
      "x": -8,
      "y": 0,
      "z": -10,
      "name": "Rock_Shale"
    },
    {
      "x": -8,
      "y": 1,
      "z": -10,
      "name": "Rock_Shale"
    },
    {
      "x": -8,
      "y": 2,
      "z": -10,
      "name": "Rock_Shale"
    },
    {
      "x": -8,
      "y": 3,
      "z": -10,
      "name": "Rock_Shale"
    },
    {
      "x": -8,
      "y": 4,
      "z": -10,
      "name": "Rock_Shale"
    },
    {
      "x": -8,
      "y": 5,
      "z": -10,
      "name": "Rock_Shale"
    },
    {
      "x": -8,
      "y": 6,
      "z": -10,
      "name": "Rock_Shale"
    },
    {
      "x": -8,
      "y": 7,
      "z": -10,
      "name": "Rock_Shale"
    },
    {
      "x": -8,
      "y": 8,
      "z": -10,
      "name": "Rock_Shale"
    },
    {
      "x": -8,
      "y": 9,
      "z": -10,
      "name": "Rock_Shale"
    },
    {
      "x": -8,
      "y": -6,
      "z": -9,
      "name": "Rock_Shale"
    },
    {
      "x": -8,
      "y": -5,
      "z": -9,
      "name": "Rock_Shale"
    },
    {
      "x": -8,
      "y": -4,
      "z": -9,
      "name": "Rock_Shale"
    },
    {
      "x": -8,
      "y": -3,
      "z": -9,
      "name": "Rock_Shale"
    },
    {
      "x": -8,
      "y": -2,
      "z": -9,
      "name": "Rock_Shale"
    },
    {
      "x": -8,
      "y": -1,
      "z": -9,
      "name": "Rock_Shale"
    },
    {
      "x": -8,
      "y": 0,
      "z": -9,
      "name": "Rock_Shale"
    },
    {
      "x": -8,
      "y": 1,
      "z": -9,
      "name": "Rock_Shale"
    },
    {
      "x": -8,
      "y": 2,
      "z": -9,
      "name": "Rock_Shale"
    },
    {
      "x": -8,
      "y": 3,
      "z": -9,
      "name": "Rock_Shale"
    },
    {
      "x": -8,
      "y": 4,
      "z": -9,
      "name": "Rock_Shale"
    },
    {
      "x": -8,
      "y": 5,
      "z": -9,
      "name": "Rock_Shale"
    },
    {
      "x": -8,
      "y": 6,
      "z": -9,
      "name": "Rock_Shale"
    },
    {
      "x": -8,
      "y": 7,
      "z": -9,
      "name": "Rock_Shale"
    },
    {
      "x": -8,
      "y": 8,
      "z": -9,
      "name": "Rock_Shale"
    },
    {
      "x": -8,
      "y": -6,
      "z": -8,
      "name": "Rock_Shale"
    },
    {
      "x": -8,
      "y": -5,
      "z": -8,
      "name": "Rock_Shale"
    },
    {
      "x": -8,
      "y": -4,
      "z": -8,
      "name": "Rock_Shale"
    },
    {
      "x": -8,
      "y": -3,
      "z": -8,
      "name": "Rock_Shale"
    },
    {
      "x": -8,
      "y": -2,
      "z": -8,
      "name": "Rock_Shale"
    },
    {
      "x": -8,
      "y": -1,
      "z": -8,
      "name": "Rock_Shale"
    },
    {
      "x": -8,
      "y": 0,
      "z": -8,
      "name": "Rock_Shale"
    },
    {
      "x": -8,
      "y": 1,
      "z": -8,
      "name": "Rock_Shale"
    },
    {
      "x": -8,
      "y": 2,
      "z": -8,
      "name": "Rock_Shale"
    },
    {
      "x": -8,
      "y": 3,
      "z": -8,
      "name": "Rock_Shale"
    },
    {
      "x": -8,
      "y": 4,
      "z": -8,
      "name": "Rock_Shale"
    },
    {
      "x": -8,
      "y": 5,
      "z": -8,
      "name": "Rock_Shale"
    },
    {
      "x": -8,
      "y": 6,
      "z": -8,
      "name": "Rock_Shale"
    },
    {
      "x": -8,
      "y": 7,
      "z": -8,
      "name": "Rock_Shale"
    },
    {
      "x": -8,
      "y": 8,
      "z": -8,
      "name": "Rock_Shale"
    },
    {
      "x": -8,
      "y": -6,
      "z": -7,
      "name": "Rock_Shale"
    },
    {
      "x": -8,
      "y": -5,
      "z": -7,
      "name": "Rock_Shale"
    },
    {
      "x": -8,
      "y": -4,
      "z": -7,
      "name": "Rock_Shale"
    },
    {
      "x": -8,
      "y": -3,
      "z": -7,
      "name": "Rock_Shale"
    },
    {
      "x": -8,
      "y": -2,
      "z": -7,
      "name": "Rock_Shale"
    },
    {
      "x": -8,
      "y": -1,
      "z": -7,
      "name": "Rock_Shale"
    },
    {
      "x": -8,
      "y": 0,
      "z": -7,
      "name": "Rock_Shale"
    },
    {
      "x": -8,
      "y": 1,
      "z": -7,
      "name": "Rock_Shale"
    },
    {
      "x": -8,
      "y": 2,
      "z": -7,
      "name": "Rock_Shale"
    },
    {
      "x": -8,
      "y": 3,
      "z": -7,
      "name": "Rock_Shale"
    },
    {
      "x": -8,
      "y": 4,
      "z": -7,
      "name": "Rock_Shale"
    },
    {
      "x": -8,
      "y": 5,
      "z": -7,
      "name": "Rock_Shale"
    },
    {
      "x": -8,
      "y": 6,
      "z": -7,
      "name": "Rock_Shale"
    },
    {
      "x": -8,
      "y": 7,
      "z": -7,
      "name": "Rock_Shale"
    },
    {
      "x": -8,
      "y": -6,
      "z": -6,
      "name": "Rock_Shale"
    },
    {
      "x": -8,
      "y": -5,
      "z": -6,
      "name": "Rock_Shale"
    },
    {
      "x": -8,
      "y": -4,
      "z": -6,
      "name": "Rock_Shale"
    },
    {
      "x": -8,
      "y": -3,
      "z": -6,
      "name": "Rock_Shale"
    },
    {
      "x": -8,
      "y": -2,
      "z": -6,
      "name": "Rock_Shale"
    },
    {
      "x": -8,
      "y": -1,
      "z": -6,
      "name": "Rock_Shale"
    },
    {
      "x": -8,
      "y": 0,
      "z": -6,
      "name": "Rock_Shale"
    },
    {
      "x": -8,
      "y": 1,
      "z": -6,
      "name": "Rock_Shale"
    },
    {
      "x": -8,
      "y": 2,
      "z": -6,
      "name": "Rock_Shale"
    },
    {
      "x": -8,
      "y": 3,
      "z": -6,
      "name": "Rock_Shale"
    },
    {
      "x": -8,
      "y": 4,
      "z": -6,
      "name": "Rock_Shale"
    },
    {
      "x": -8,
      "y": 5,
      "z": -6,
      "name": "Rock_Shale"
    },
    {
      "x": -8,
      "y": 6,
      "z": -6,
      "name": "Rock_Shale"
    },
    {
      "x": -8,
      "y": 7,
      "z": -6,
      "name": "Rock_Shale"
    },
    {
      "x": -8,
      "y": -6,
      "z": -5,
      "name": "Rock_Shale"
    },
    {
      "x": -8,
      "y": -5,
      "z": -5,
      "name": "Rock_Shale"
    },
    {
      "x": -8,
      "y": -4,
      "z": -5,
      "name": "Rock_Shale"
    },
    {
      "x": -8,
      "y": -3,
      "z": -5,
      "name": "Rock_Shale"
    },
    {
      "x": -8,
      "y": -2,
      "z": -5,
      "name": "Rock_Shale"
    },
    {
      "x": -8,
      "y": -1,
      "z": -5,
      "name": "Rock_Shale"
    },
    {
      "x": -8,
      "y": 0,
      "z": -5,
      "name": "Rock_Shale"
    },
    {
      "x": -8,
      "y": 1,
      "z": -5,
      "name": "Rock_Shale"
    },
    {
      "x": -8,
      "y": 2,
      "z": -5,
      "name": "Rock_Shale"
    },
    {
      "x": -8,
      "y": 3,
      "z": -5,
      "name": "Rock_Shale"
    },
    {
      "x": -8,
      "y": 4,
      "z": -5,
      "name": "Rock_Shale"
    },
    {
      "x": -8,
      "y": 5,
      "z": -5,
      "name": "Rock_Shale"
    },
    {
      "x": -8,
      "y": 6,
      "z": -5,
      "name": "Rock_Shale"
    },
    {
      "x": -8,
      "y": 7,
      "z": -5,
      "name": "Rock_Shale"
    },
    {
      "x": -8,
      "y": -6,
      "z": -4,
      "name": "Rock_Shale"
    },
    {
      "x": -8,
      "y": -5,
      "z": -4,
      "name": "Rock_Shale"
    },
    {
      "x": -8,
      "y": -4,
      "z": -4,
      "name": "Rock_Shale"
    },
    {
      "x": -8,
      "y": -3,
      "z": -4,
      "name": "Rock_Shale"
    },
    {
      "x": -8,
      "y": -2,
      "z": -4,
      "name": "Rock_Shale"
    },
    {
      "x": -8,
      "y": -1,
      "z": -4,
      "name": "Rock_Shale"
    },
    {
      "x": -8,
      "y": 0,
      "z": -4,
      "name": "Rock_Shale"
    },
    {
      "x": -8,
      "y": 1,
      "z": -4,
      "name": "Rock_Shale"
    },
    {
      "x": -8,
      "y": 2,
      "z": -4,
      "name": "Rock_Shale"
    },
    {
      "x": -8,
      "y": 3,
      "z": -4,
      "name": "Rock_Shale"
    },
    {
      "x": -8,
      "y": 4,
      "z": -4,
      "name": "Rock_Shale"
    },
    {
      "x": -8,
      "y": 5,
      "z": -4,
      "name": "Rock_Shale"
    },
    {
      "x": -8,
      "y": 6,
      "z": -4,
      "name": "Rock_Shale"
    },
    {
      "x": -8,
      "y": 7,
      "z": -4,
      "name": "Rock_Shale"
    },
    {
      "x": -8,
      "y": -6,
      "z": -3,
      "name": "Rock_Shale"
    },
    {
      "x": -8,
      "y": -5,
      "z": -3,
      "name": "Rock_Shale"
    },
    {
      "x": -8,
      "y": -4,
      "z": -3,
      "name": "Rock_Shale"
    },
    {
      "x": -8,
      "y": -3,
      "z": -3,
      "name": "Rock_Shale"
    },
    {
      "x": -8,
      "y": -2,
      "z": -3,
      "name": "Rock_Shale"
    },
    {
      "x": -8,
      "y": -1,
      "z": -3,
      "name": "Rock_Shale"
    },
    {
      "x": -8,
      "y": 0,
      "z": -3,
      "name": "Rock_Shale"
    },
    {
      "x": -8,
      "y": 1,
      "z": -3,
      "name": "Rock_Shale"
    },
    {
      "x": -8,
      "y": 2,
      "z": -3,
      "name": "Rock_Shale"
    },
    {
      "x": -8,
      "y": 3,
      "z": -3,
      "name": "Rock_Shale"
    },
    {
      "x": -8,
      "y": 4,
      "z": -3,
      "name": "Rock_Shale"
    },
    {
      "x": -8,
      "y": 5,
      "z": -3,
      "name": "Rock_Shale"
    },
    {
      "x": -8,
      "y": 6,
      "z": -3,
      "name": "Rock_Shale"
    },
    {
      "x": -8,
      "y": 7,
      "z": -3,
      "name": "Rock_Shale"
    },
    {
      "x": -8,
      "y": 8,
      "z": -3,
      "name": "Rock_Shale"
    },
    {
      "x": -8,
      "y": -6,
      "z": -2,
      "name": "Rock_Shale"
    },
    {
      "x": -8,
      "y": -5,
      "z": -2,
      "name": "Rock_Shale"
    },
    {
      "x": -8,
      "y": -4,
      "z": -2,
      "name": "Rock_Shale"
    },
    {
      "x": -8,
      "y": -3,
      "z": -2,
      "name": "Rock_Shale"
    },
    {
      "x": -8,
      "y": -2,
      "z": -2,
      "name": "Rock_Shale"
    },
    {
      "x": -8,
      "y": -1,
      "z": -2,
      "name": "Rock_Shale"
    },
    {
      "x": -8,
      "y": 0,
      "z": -2,
      "name": "Rock_Shale"
    },
    {
      "x": -8,
      "y": 1,
      "z": -2,
      "name": "Rock_Shale"
    },
    {
      "x": -8,
      "y": 2,
      "z": -2,
      "name": "Rock_Shale"
    },
    {
      "x": -8,
      "y": 3,
      "z": -2,
      "name": "Rock_Shale"
    },
    {
      "x": -8,
      "y": 4,
      "z": -2,
      "name": "Rock_Shale"
    },
    {
      "x": -8,
      "y": 5,
      "z": -2,
      "name": "Rock_Shale"
    },
    {
      "x": -8,
      "y": 6,
      "z": -2,
      "name": "Rock_Shale"
    },
    {
      "x": -8,
      "y": 7,
      "z": -2,
      "name": "Rock_Shale"
    },
    {
      "x": -8,
      "y": 8,
      "z": -2,
      "name": "Rock_Shale"
    },
    {
      "x": -8,
      "y": 9,
      "z": -2,
      "name": "Rock_Shale"
    },
    {
      "x": -8,
      "y": -6,
      "z": -1,
      "name": "Rock_Shale"
    },
    {
      "x": -8,
      "y": -5,
      "z": -1,
      "name": "Rock_Shale"
    },
    {
      "x": -8,
      "y": -4,
      "z": -1,
      "name": "Rock_Shale"
    },
    {
      "x": -8,
      "y": -3,
      "z": -1,
      "name": "Rock_Shale"
    },
    {
      "x": -8,
      "y": -2,
      "z": -1,
      "name": "Rock_Shale"
    },
    {
      "x": -8,
      "y": -1,
      "z": -1,
      "name": "Rock_Shale"
    },
    {
      "x": -8,
      "y": 0,
      "z": -1,
      "name": "Rock_Shale"
    },
    {
      "x": -8,
      "y": 1,
      "z": -1,
      "name": "Rock_Shale"
    },
    {
      "x": -8,
      "y": 2,
      "z": -1,
      "name": "Rock_Shale"
    },
    {
      "x": -8,
      "y": 3,
      "z": -1,
      "name": "Rock_Shale"
    },
    {
      "x": -8,
      "y": 4,
      "z": -1,
      "name": "Rock_Shale"
    },
    {
      "x": -8,
      "y": 5,
      "z": -1,
      "name": "Rock_Shale"
    },
    {
      "x": -8,
      "y": 6,
      "z": -1,
      "name": "Rock_Shale"
    },
    {
      "x": -8,
      "y": 7,
      "z": -1,
      "name": "Rock_Shale"
    },
    {
      "x": -8,
      "y": 8,
      "z": -1,
      "name": "Rock_Shale"
    },
    {
      "x": -8,
      "y": 9,
      "z": -1,
      "name": "Rock_Shale"
    },
    {
      "x": -8,
      "y": -6,
      "z": 0,
      "name": "Rock_Shale"
    },
    {
      "x": -8,
      "y": -5,
      "z": 0,
      "name": "Rock_Shale"
    },
    {
      "x": -8,
      "y": -4,
      "z": 0,
      "name": "Rock_Shale"
    },
    {
      "x": -8,
      "y": -3,
      "z": 0,
      "name": "Rock_Shale"
    },
    {
      "x": -8,
      "y": -2,
      "z": 0,
      "name": "Rock_Shale"
    },
    {
      "x": -8,
      "y": -1,
      "z": 0,
      "name": "Rock_Shale"
    },
    {
      "x": -8,
      "y": 0,
      "z": 0,
      "name": "Rock_Shale"
    },
    {
      "x": -8,
      "y": 1,
      "z": 0,
      "name": "Rock_Shale"
    },
    {
      "x": -8,
      "y": 2,
      "z": 0,
      "name": "Rock_Shale"
    },
    {
      "x": -8,
      "y": 3,
      "z": 0,
      "name": "Rock_Shale"
    },
    {
      "x": -8,
      "y": 4,
      "z": 0,
      "name": "Rock_Shale"
    },
    {
      "x": -8,
      "y": 5,
      "z": 0,
      "name": "Rock_Shale"
    },
    {
      "x": -8,
      "y": 6,
      "z": 0,
      "name": "Rock_Shale"
    },
    {
      "x": -8,
      "y": 7,
      "z": 0,
      "name": "Rock_Shale"
    },
    {
      "x": -8,
      "y": 8,
      "z": 0,
      "name": "Rock_Shale"
    },
    {
      "x": -8,
      "y": 9,
      "z": 0,
      "name": "Rock_Shale"
    },
    {
      "x": -7,
      "y": -6,
      "z": -16,
      "name": "Rock_Shale"
    },
    {
      "x": -7,
      "y": -5,
      "z": -16,
      "name": "Rock_Shale"
    },
    {
      "x": -7,
      "y": -4,
      "z": -16,
      "name": "Rock_Shale"
    },
    {
      "x": -7,
      "y": -3,
      "z": -16,
      "name": "Rock_Shale"
    },
    {
      "x": -7,
      "y": -2,
      "z": -16,
      "name": "Rock_Shale"
    },
    {
      "x": -7,
      "y": -1,
      "z": -16,
      "name": "Rock_Shale"
    },
    {
      "x": -7,
      "y": 0,
      "z": -16,
      "name": "Rock_Shale"
    },
    {
      "x": -7,
      "y": 1,
      "z": -16,
      "name": "Rock_Shale"
    },
    {
      "x": -7,
      "y": 2,
      "z": -16,
      "name": "Rock_Shale"
    },
    {
      "x": -7,
      "y": 3,
      "z": -16,
      "name": "Rock_Shale"
    },
    {
      "x": -7,
      "y": 4,
      "z": -16,
      "name": "Rock_Shale"
    },
    {
      "x": -7,
      "y": 5,
      "z": -16,
      "name": "Rock_Shale"
    },
    {
      "x": -7,
      "y": 6,
      "z": -16,
      "name": "Rock_Shale"
    },
    {
      "x": -7,
      "y": 7,
      "z": -16,
      "name": "Rock_Shale"
    },
    {
      "x": -7,
      "y": 8,
      "z": -16,
      "name": "Rock_Shale"
    },
    {
      "x": -7,
      "y": 9,
      "z": -16,
      "name": "Rock_Shale"
    },
    {
      "x": -7,
      "y": 10,
      "z": -16,
      "name": "Rock_Shale"
    },
    {
      "x": -7,
      "y": 11,
      "z": -16,
      "name": "Rock_Shale"
    },
    {
      "x": -7,
      "y": -6,
      "z": -15,
      "name": "Rock_Shale"
    },
    {
      "x": -7,
      "y": -5,
      "z": -15,
      "name": "Rock_Shale"
    },
    {
      "x": -7,
      "y": -4,
      "z": -15,
      "name": "Rock_Shale"
    },
    {
      "x": -7,
      "y": -3,
      "z": -15,
      "name": "Rock_Shale"
    },
    {
      "x": -7,
      "y": -2,
      "z": -15,
      "name": "Rock_Shale"
    },
    {
      "x": -7,
      "y": -1,
      "z": -15,
      "name": "Rock_Shale"
    },
    {
      "x": -7,
      "y": 0,
      "z": -15,
      "name": "Rock_Basalt_Cobble"
    },
    {
      "x": -7,
      "y": 1,
      "z": -15,
      "name": "Rock_Basalt_Cobble"
    },
    {
      "x": -7,
      "y": 2,
      "z": -15,
      "name": "Rock_Basalt_Cobble"
    },
    {
      "x": -7,
      "y": 3,
      "z": -15,
      "name": "Rock_Basalt_Cobble"
    },
    {
      "x": -7,
      "y": 4,
      "z": -15,
      "name": "Rock_Basalt_Cobble"
    },
    {
      "x": -7,
      "y": 5,
      "z": -15,
      "name": "Rock_Basalt_Cobble"
    },
    {
      "x": -7,
      "y": 6,
      "z": -15,
      "name": "Rock_Basalt_Cobble"
    },
    {
      "x": -7,
      "y": 7,
      "z": -15,
      "name": "Empty"
    },
    {
      "x": -7,
      "y": 8,
      "z": -15,
      "name": "Rock_Shale"
    },
    {
      "x": -7,
      "y": 9,
      "z": -15,
      "name": "Rock_Shale"
    },
    {
      "x": -7,
      "y": 10,
      "z": -15,
      "name": "Rock_Shale"
    },
    {
      "x": -7,
      "y": 11,
      "z": -15,
      "name": "Rock_Shale"
    },
    {
      "x": -7,
      "y": -6,
      "z": -14,
      "name": "Rock_Shale"
    },
    {
      "x": -7,
      "y": -5,
      "z": -14,
      "name": "Rock_Shale"
    },
    {
      "x": -7,
      "y": -4,
      "z": -14,
      "name": "Rock_Shale"
    },
    {
      "x": -7,
      "y": -3,
      "z": -14,
      "name": "Rock_Shale"
    },
    {
      "x": -7,
      "y": -2,
      "z": -14,
      "name": "Rock_Shale"
    },
    {
      "x": -7,
      "y": -1,
      "z": -14,
      "name": "Rock_Shale"
    },
    {
      "x": -7,
      "y": 0,
      "z": -14,
      "name": "Rock_Basalt_Cobble"
    },
    {
      "x": -7,
      "y": 1,
      "z": -14,
      "name": "Rock_Basalt_Cobble"
    },
    {
      "x": -7,
      "y": 2,
      "z": -14,
      "name": "Rock_Basalt_Cobble"
    },
    {
      "x": -7,
      "y": 3,
      "z": -14,
      "name": "Rock_Basalt_Cobble"
    },
    {
      "x": -7,
      "y": 4,
      "z": -14,
      "name": "Rock_Basalt_Cobble"
    },
    {
      "x": -7,
      "y": 5,
      "z": -14,
      "name": "Rock_Basalt_Cobble"
    },
    {
      "x": -7,
      "y": 6,
      "z": -14,
      "name": "Rock_Basalt_Cobble"
    },
    {
      "x": -7,
      "y": 7,
      "z": -14,
      "name": "Empty"
    },
    {
      "x": -7,
      "y": 8,
      "z": -14,
      "name": "Empty"
    },
    {
      "x": -7,
      "y": 9,
      "z": -14,
      "name": "Rock_Shale"
    },
    {
      "x": -7,
      "y": 10,
      "z": -14,
      "name": "Rock_Shale"
    },
    {
      "x": -7,
      "y": 11,
      "z": -14,
      "name": "Rock_Shale"
    },
    {
      "x": -7,
      "y": -6,
      "z": -13,
      "name": "Rock_Shale"
    },
    {
      "x": -7,
      "y": -5,
      "z": -13,
      "name": "Rock_Shale"
    },
    {
      "x": -7,
      "y": -4,
      "z": -13,
      "name": "Rock_Shale"
    },
    {
      "x": -7,
      "y": -3,
      "z": -13,
      "name": "Rock_Shale"
    },
    {
      "x": -7,
      "y": -2,
      "z": -13,
      "name": "Rock_Shale"
    },
    {
      "x": -7,
      "y": -1,
      "z": -13,
      "name": "Rock_Shale"
    },
    {
      "x": -7,
      "y": 0,
      "z": -13,
      "name": "Rock_Basalt_Cobble"
    },
    {
      "x": -7,
      "y": 1,
      "z": -13,
      "name": "Rock_Basalt_Cobble"
    },
    {
      "x": -7,
      "y": 2,
      "z": -13,
      "name": "Rock_Basalt_Cobble"
    },
    {
      "x": -7,
      "y": 3,
      "z": -13,
      "name": "Rock_Basalt_Cobble"
    },
    {
      "x": -7,
      "y": 4,
      "z": -13,
      "name": "Rock_Basalt_Cobble"
    },
    {
      "x": -7,
      "y": 5,
      "z": -13,
      "name": "Rock_Basalt_Cobble"
    },
    {
      "x": -7,
      "y": 6,
      "z": -13,
      "name": "Rock_Basalt_Cobble"
    },
    {
      "x": -7,
      "y": 7,
      "z": -13,
      "name": "Empty"
    },
    {
      "x": -7,
      "y": 8,
      "z": -13,
      "name": "Empty"
    },
    {
      "x": -7,
      "y": 9,
      "z": -13,
      "name": "Empty"
    },
    {
      "x": -7,
      "y": 10,
      "z": -13,
      "name": "Rock_Shale"
    },
    {
      "x": -7,
      "y": 11,
      "z": -13,
      "name": "Rock_Shale"
    },
    {
      "x": -7,
      "y": -6,
      "z": -12,
      "name": "Rock_Shale"
    },
    {
      "x": -7,
      "y": -5,
      "z": -12,
      "name": "Rock_Shale"
    },
    {
      "x": -7,
      "y": -4,
      "z": -12,
      "name": "Rock_Shale"
    },
    {
      "x": -7,
      "y": -3,
      "z": -12,
      "name": "Rock_Shale"
    },
    {
      "x": -7,
      "y": -2,
      "z": -12,
      "name": "Rock_Shale"
    },
    {
      "x": -7,
      "y": -1,
      "z": -12,
      "name": "Rock_Shale"
    },
    {
      "x": -7,
      "y": 0,
      "z": -12,
      "name": "Rock_Basalt_Cobble"
    },
    {
      "x": -7,
      "y": 1,
      "z": -12,
      "name": "Rock_Basalt_Cobble"
    },
    {
      "x": -7,
      "y": 2,
      "z": -12,
      "name": "Rock_Basalt_Cobble"
    },
    {
      "x": -7,
      "y": 3,
      "z": -12,
      "name": "Rock_Basalt_Cobble"
    },
    {
      "x": -7,
      "y": 4,
      "z": -12,
      "name": "Rock_Basalt_Cobble"
    },
    {
      "x": -7,
      "y": 5,
      "z": -12,
      "name": "Rock_Basalt_Cobble"
    },
    {
      "x": -7,
      "y": 6,
      "z": -12,
      "name": "Rock_Basalt_Cobble"
    },
    {
      "x": -7,
      "y": 7,
      "z": -12,
      "name": "Empty"
    },
    {
      "x": -7,
      "y": 8,
      "z": -12,
      "name": "Empty"
    },
    {
      "x": -7,
      "y": 9,
      "z": -12,
      "name": "Empty"
    },
    {
      "x": -7,
      "y": 10,
      "z": -12,
      "name": "Rock_Shale"
    },
    {
      "x": -7,
      "y": 11,
      "z": -12,
      "name": "Rock_Shale"
    },
    {
      "x": -7,
      "y": -6,
      "z": -11,
      "name": "Rock_Shale"
    },
    {
      "x": -7,
      "y": -5,
      "z": -11,
      "name": "Rock_Shale"
    },
    {
      "x": -7,
      "y": -4,
      "z": -11,
      "name": "Rock_Shale"
    },
    {
      "x": -7,
      "y": -3,
      "z": -11,
      "name": "Rock_Shale"
    },
    {
      "x": -7,
      "y": -2,
      "z": -11,
      "name": "Rock_Shale"
    },
    {
      "x": -7,
      "y": -1,
      "z": -11,
      "name": "Rock_Shale"
    },
    {
      "x": -7,
      "y": 0,
      "z": -11,
      "name": "Rock_Basalt_Cobble"
    },
    {
      "x": -7,
      "y": 1,
      "z": -11,
      "name": "Rock_Basalt_Cobble"
    },
    {
      "x": -7,
      "y": 2,
      "z": -11,
      "name": "Rock_Basalt_Cobble"
    },
    {
      "x": -7,
      "y": 3,
      "z": -11,
      "name": "Rock_Basalt_Cobble"
    },
    {
      "x": -7,
      "y": 4,
      "z": -11,
      "name": "Empty"
    },
    {
      "x": -7,
      "y": 5,
      "z": -11,
      "name": "Empty"
    },
    {
      "x": -7,
      "y": 6,
      "z": -11,
      "name": "Empty"
    },
    {
      "x": -7,
      "y": 7,
      "z": -11,
      "name": "Empty"
    },
    {
      "x": -7,
      "y": 8,
      "z": -11,
      "name": "Empty"
    },
    {
      "x": -7,
      "y": 9,
      "z": -11,
      "name": "Empty"
    },
    {
      "x": -7,
      "y": 10,
      "z": -11,
      "name": "Empty"
    },
    {
      "x": -7,
      "y": 11,
      "z": -11,
      "name": "Rock_Shale"
    },
    {
      "x": -7,
      "y": -6,
      "z": -10,
      "name": "Rock_Shale"
    },
    {
      "x": -7,
      "y": -5,
      "z": -10,
      "name": "Rock_Shale"
    },
    {
      "x": -7,
      "y": -4,
      "z": -10,
      "name": "Rock_Shale"
    },
    {
      "x": -7,
      "y": -3,
      "z": -10,
      "name": "Rock_Shale"
    },
    {
      "x": -7,
      "y": -2,
      "z": -10,
      "name": "Rock_Shale"
    },
    {
      "x": -7,
      "y": -1,
      "z": -10,
      "name": "Rock_Shale"
    },
    {
      "x": -7,
      "y": 0,
      "z": -10,
      "name": "Rock_Basalt_Cobble"
    },
    {
      "x": -7,
      "y": 1,
      "z": -10,
      "name": "Empty"
    },
    {
      "x": -7,
      "y": 2,
      "z": -10,
      "name": "Empty"
    },
    {
      "x": -7,
      "y": 3,
      "z": -10,
      "name": "Empty"
    },
    {
      "x": -7,
      "y": 4,
      "z": -10,
      "name": "Empty"
    },
    {
      "x": -7,
      "y": 5,
      "z": -10,
      "name": "Empty"
    },
    {
      "x": -7,
      "y": 6,
      "z": -10,
      "name": "Empty"
    },
    {
      "x": -7,
      "y": 7,
      "z": -10,
      "name": "Empty"
    },
    {
      "x": -7,
      "y": 8,
      "z": -10,
      "name": "Empty"
    },
    {
      "x": -7,
      "y": 9,
      "z": -10,
      "name": "Rock_Shale"
    },
    {
      "x": -7,
      "y": 10,
      "z": -10,
      "name": "Rock_Shale"
    },
    {
      "x": -7,
      "y": 11,
      "z": -10,
      "name": "Rock_Shale"
    },
    {
      "x": -7,
      "y": -6,
      "z": -9,
      "name": "Rock_Shale"
    },
    {
      "x": -7,
      "y": -5,
      "z": -9,
      "name": "Rock_Shale"
    },
    {
      "x": -7,
      "y": -4,
      "z": -9,
      "name": "Rock_Shale"
    },
    {
      "x": -7,
      "y": -3,
      "z": -9,
      "name": "Rock_Shale"
    },
    {
      "x": -7,
      "y": -2,
      "z": -9,
      "name": "Rock_Shale"
    },
    {
      "x": -7,
      "y": -1,
      "z": -9,
      "name": "Rock_Shale"
    },
    {
      "x": -7,
      "y": 0,
      "z": -9,
      "name": "Rock_Basalt_Cobble"
    },
    {
      "x": -7,
      "y": 1,
      "z": -9,
      "name": "Empty"
    },
    {
      "x": -7,
      "y": 2,
      "z": -9,
      "name": "Empty"
    },
    {
      "x": -7,
      "y": 3,
      "z": -9,
      "name": "Empty"
    },
    {
      "x": -7,
      "y": 4,
      "z": -9,
      "name": "Empty"
    },
    {
      "x": -7,
      "y": 5,
      "z": -9,
      "name": "Empty"
    },
    {
      "x": -7,
      "y": 6,
      "z": -9,
      "name": "Empty"
    },
    {
      "x": -7,
      "y": 7,
      "z": -9,
      "name": "Empty"
    },
    {
      "x": -7,
      "y": 8,
      "z": -9,
      "name": "Rock_Shale"
    },
    {
      "x": -7,
      "y": 9,
      "z": -9,
      "name": "Rock_Shale"
    },
    {
      "x": -7,
      "y": -6,
      "z": -8,
      "name": "Rock_Shale"
    },
    {
      "x": -7,
      "y": -5,
      "z": -8,
      "name": "Rock_Shale"
    },
    {
      "x": -7,
      "y": -4,
      "z": -8,
      "name": "Rock_Shale"
    },
    {
      "x": -7,
      "y": -3,
      "z": -8,
      "name": "Rock_Shale"
    },
    {
      "x": -7,
      "y": -2,
      "z": -8,
      "name": "Rock_Shale"
    },
    {
      "x": -7,
      "y": -1,
      "z": -8,
      "name": "Rock_Shale"
    },
    {
      "x": -7,
      "y": 0,
      "z": -8,
      "name": "Rock_Basalt_Cobble"
    },
    {
      "x": -7,
      "y": 1,
      "z": -8,
      "name": "Empty"
    },
    {
      "x": -7,
      "y": 2,
      "z": -8,
      "name": "Empty"
    },
    {
      "x": -7,
      "y": 3,
      "z": -8,
      "name": "Empty"
    },
    {
      "x": -7,
      "y": 4,
      "z": -8,
      "name": "Empty"
    },
    {
      "x": -7,
      "y": 5,
      "z": -8,
      "name": "Empty"
    },
    {
      "x": -7,
      "y": 6,
      "z": -8,
      "name": "Empty"
    },
    {
      "x": -7,
      "y": 7,
      "z": -8,
      "name": "Empty"
    },
    {
      "x": -7,
      "y": 8,
      "z": -8,
      "name": "Rock_Shale"
    },
    {
      "x": -7,
      "y": 9,
      "z": -8,
      "name": "Rock_Shale"
    },
    {
      "x": -7,
      "y": -6,
      "z": -7,
      "name": "Rock_Shale"
    },
    {
      "x": -7,
      "y": -5,
      "z": -7,
      "name": "Rock_Shale"
    },
    {
      "x": -7,
      "y": -4,
      "z": -7,
      "name": "Rock_Shale"
    },
    {
      "x": -7,
      "y": -3,
      "z": -7,
      "name": "Rock_Shale"
    },
    {
      "x": -7,
      "y": -2,
      "z": -7,
      "name": "Rock_Shale"
    },
    {
      "x": -7,
      "y": -1,
      "z": -7,
      "name": "Rock_Shale"
    },
    {
      "x": -7,
      "y": 0,
      "z": -7,
      "name": "Rock_Basalt_Cobble"
    },
    {
      "x": -7,
      "y": 1,
      "z": -7,
      "name": "Empty"
    },
    {
      "x": -7,
      "y": 2,
      "z": -7,
      "name": "Empty"
    },
    {
      "x": -7,
      "y": 3,
      "z": -7,
      "name": "Empty"
    },
    {
      "x": -7,
      "y": 4,
      "z": -7,
      "name": "Empty"
    },
    {
      "x": -7,
      "y": 5,
      "z": -7,
      "name": "Empty"
    },
    {
      "x": -7,
      "y": 6,
      "z": -7,
      "name": "Empty"
    },
    {
      "x": -7,
      "y": 7,
      "z": -7,
      "name": "Rock_Shale"
    },
    {
      "x": -7,
      "y": 8,
      "z": -7,
      "name": "Rock_Shale"
    },
    {
      "x": -7,
      "y": -6,
      "z": -6,
      "name": "Rock_Shale"
    },
    {
      "x": -7,
      "y": -5,
      "z": -6,
      "name": "Rock_Shale"
    },
    {
      "x": -7,
      "y": -4,
      "z": -6,
      "name": "Rock_Shale"
    },
    {
      "x": -7,
      "y": -3,
      "z": -6,
      "name": "Rock_Shale"
    },
    {
      "x": -7,
      "y": -2,
      "z": -6,
      "name": "Rock_Shale"
    },
    {
      "x": -7,
      "y": -1,
      "z": -6,
      "name": "Rock_Shale"
    },
    {
      "x": -7,
      "y": 0,
      "z": -6,
      "name": "Rock_Basalt_Cobble"
    },
    {
      "x": -7,
      "y": 1,
      "z": -6,
      "name": "Empty"
    },
    {
      "x": -7,
      "y": 2,
      "z": -6,
      "name": "Empty"
    },
    {
      "x": -7,
      "y": 3,
      "z": -6,
      "name": "Empty"
    },
    {
      "x": -7,
      "y": 4,
      "z": -6,
      "name": "Empty"
    },
    {
      "x": -7,
      "y": 5,
      "z": -6,
      "name": "Empty"
    },
    {
      "x": -7,
      "y": 6,
      "z": -6,
      "name": "Empty"
    },
    {
      "x": -7,
      "y": 7,
      "z": -6,
      "name": "Rock_Shale"
    },
    {
      "x": -7,
      "y": 8,
      "z": -6,
      "name": "Rock_Shale"
    },
    {
      "x": -7,
      "y": -6,
      "z": -5,
      "name": "Rock_Shale"
    },
    {
      "x": -7,
      "y": -5,
      "z": -5,
      "name": "Rock_Shale"
    },
    {
      "x": -7,
      "y": -4,
      "z": -5,
      "name": "Rock_Shale"
    },
    {
      "x": -7,
      "y": -3,
      "z": -5,
      "name": "Rock_Shale"
    },
    {
      "x": -7,
      "y": -2,
      "z": -5,
      "name": "Rock_Shale"
    },
    {
      "x": -7,
      "y": -1,
      "z": -5,
      "name": "Rock_Shale"
    },
    {
      "x": -7,
      "y": 0,
      "z": -5,
      "name": "Rock_Shale"
    },
    {
      "x": -7,
      "y": 1,
      "z": -5,
      "name": "Rock_Shale"
    },
    {
      "x": -7,
      "y": 2,
      "z": -5,
      "name": "Rock_Shale"
    },
    {
      "x": -7,
      "y": 3,
      "z": -5,
      "name": "Empty"
    },
    {
      "x": -7,
      "y": 4,
      "z": -5,
      "name": "Empty"
    },
    {
      "x": -7,
      "y": 5,
      "z": -5,
      "name": "Rock_Shale"
    },
    {
      "x": -7,
      "y": 6,
      "z": -5,
      "name": "Rock_Shale"
    },
    {
      "x": -7,
      "y": 7,
      "z": -5,
      "name": "Rock_Shale"
    },
    {
      "x": -7,
      "y": 8,
      "z": -5,
      "name": "Rock_Shale"
    },
    {
      "x": -7,
      "y": -6,
      "z": -4,
      "name": "Rock_Shale"
    },
    {
      "x": -7,
      "y": -5,
      "z": -4,
      "name": "Rock_Shale"
    },
    {
      "x": -7,
      "y": -4,
      "z": -4,
      "name": "Rock_Shale"
    },
    {
      "x": -7,
      "y": -3,
      "z": -4,
      "name": "Rock_Shale"
    },
    {
      "x": -7,
      "y": -2,
      "z": -4,
      "name": "Rock_Shale"
    },
    {
      "x": -7,
      "y": -1,
      "z": -4,
      "name": "Rock_Shale"
    },
    {
      "x": -7,
      "y": 0,
      "z": -4,
      "name": "Rock_Shale"
    },
    {
      "x": -7,
      "y": 1,
      "z": -4,
      "name": "Rock_Shale"
    },
    {
      "x": -7,
      "y": 2,
      "z": -4,
      "name": "Empty"
    },
    {
      "x": -7,
      "y": 3,
      "z": -4,
      "name": "Empty"
    },
    {
      "x": -7,
      "y": 4,
      "z": -4,
      "name": "Empty"
    },
    {
      "x": -7,
      "y": 5,
      "z": -4,
      "name": "Empty"
    },
    {
      "x": -7,
      "y": 6,
      "z": -4,
      "name": "Rock_Shale"
    },
    {
      "x": -7,
      "y": 7,
      "z": -4,
      "name": "Rock_Shale"
    },
    {
      "x": -7,
      "y": 8,
      "z": -4,
      "name": "Rock_Shale"
    },
    {
      "x": -7,
      "y": -6,
      "z": -3,
      "name": "Rock_Shale"
    },
    {
      "x": -7,
      "y": -5,
      "z": -3,
      "name": "Rock_Shale"
    },
    {
      "x": -7,
      "y": -4,
      "z": -3,
      "name": "Rock_Shale"
    },
    {
      "x": -7,
      "y": -3,
      "z": -3,
      "name": "Rock_Shale"
    },
    {
      "x": -7,
      "y": -2,
      "z": -3,
      "name": "Rock_Shale"
    },
    {
      "x": -7,
      "y": -1,
      "z": -3,
      "name": "Rock_Shale"
    },
    {
      "x": -7,
      "y": 0,
      "z": -3,
      "name": "Rock_Basalt_Cobble"
    },
    {
      "x": -7,
      "y": 1,
      "z": -3,
      "name": "Empty"
    },
    {
      "x": -7,
      "y": 2,
      "z": -3,
      "name": "Empty"
    },
    {
      "x": -7,
      "y": 3,
      "z": -3,
      "name": "Empty"
    },
    {
      "x": -7,
      "y": 4,
      "z": -3,
      "name": "Empty"
    },
    {
      "x": -7,
      "y": 5,
      "z": -3,
      "name": "Empty"
    },
    {
      "x": -7,
      "y": 6,
      "z": -3,
      "name": "Empty"
    },
    {
      "x": -7,
      "y": 7,
      "z": -3,
      "name": "Empty"
    },
    {
      "x": -7,
      "y": 8,
      "z": -3,
      "name": "Rock_Shale"
    },
    {
      "x": -7,
      "y": -6,
      "z": -2,
      "name": "Rock_Shale"
    },
    {
      "x": -7,
      "y": -5,
      "z": -2,
      "name": "Rock_Shale"
    },
    {
      "x": -7,
      "y": -4,
      "z": -2,
      "name": "Rock_Shale"
    },
    {
      "x": -7,
      "y": -3,
      "z": -2,
      "name": "Rock_Shale"
    },
    {
      "x": -7,
      "y": -2,
      "z": -2,
      "name": "Rock_Shale"
    },
    {
      "x": -7,
      "y": -1,
      "z": -2,
      "name": "Rock_Shale"
    },
    {
      "x": -7,
      "y": 0,
      "z": -2,
      "name": "Rock_Basalt_Cobble"
    },
    {
      "x": -7,
      "y": 1,
      "z": -2,
      "name": "Empty"
    },
    {
      "x": -7,
      "y": 2,
      "z": -2,
      "name": "Empty"
    },
    {
      "x": -7,
      "y": 3,
      "z": -2,
      "name": "Empty"
    },
    {
      "x": -7,
      "y": 4,
      "z": -2,
      "name": "Empty"
    },
    {
      "x": -7,
      "y": 5,
      "z": -2,
      "name": "Empty"
    },
    {
      "x": -7,
      "y": 6,
      "z": -2,
      "name": "Empty"
    },
    {
      "x": -7,
      "y": 7,
      "z": -2,
      "name": "Empty"
    },
    {
      "x": -7,
      "y": 8,
      "z": -2,
      "name": "Rock_Shale"
    },
    {
      "x": -7,
      "y": 9,
      "z": -2,
      "name": "Rock_Shale"
    },
    {
      "x": -7,
      "y": -6,
      "z": -1,
      "name": "Rock_Shale"
    },
    {
      "x": -7,
      "y": -5,
      "z": -1,
      "name": "Rock_Shale"
    },
    {
      "x": -7,
      "y": -4,
      "z": -1,
      "name": "Rock_Shale"
    },
    {
      "x": -7,
      "y": -3,
      "z": -1,
      "name": "Rock_Shale"
    },
    {
      "x": -7,
      "y": -2,
      "z": -1,
      "name": "Rock_Shale"
    },
    {
      "x": -7,
      "y": -1,
      "z": -1,
      "name": "Rock_Shale"
    },
    {
      "x": -7,
      "y": 0,
      "z": -1,
      "name": "Rock_Basalt_Cobble"
    },
    {
      "x": -7,
      "y": 1,
      "z": -1,
      "name": "Rock_Basalt_Cobble"
    },
    {
      "x": -7,
      "y": 2,
      "z": -1,
      "name": "Rock_Basalt_Cobble"
    },
    {
      "x": -7,
      "y": 3,
      "z": -1,
      "name": "Rock_Basalt_Cobble"
    },
    {
      "x": -7,
      "y": 4,
      "z": -1,
      "name": "Rock_Basalt_Cobble_Half"
    },
    {
      "x": -7,
      "y": 5,
      "z": -1,
      "name": "Empty"
    },
    {
      "x": -7,
      "y": 6,
      "z": -1,
      "name": "Empty"
    },
    {
      "x": -7,
      "y": 7,
      "z": -1,
      "name": "Empty"
    },
    {
      "x": -7,
      "y": 8,
      "z": -1,
      "name": "Rock_Shale"
    },
    {
      "x": -7,
      "y": 9,
      "z": -1,
      "name": "Rock_Shale"
    },
    {
      "x": -7,
      "y": -6,
      "z": 0,
      "name": "Rock_Shale"
    },
    {
      "x": -7,
      "y": -5,
      "z": 0,
      "name": "Rock_Shale"
    },
    {
      "x": -7,
      "y": -4,
      "z": 0,
      "name": "Rock_Shale"
    },
    {
      "x": -7,
      "y": -3,
      "z": 0,
      "name": "Rock_Shale"
    },
    {
      "x": -7,
      "y": -2,
      "z": 0,
      "name": "Rock_Shale"
    },
    {
      "x": -7,
      "y": -1,
      "z": 0,
      "name": "Rock_Shale"
    },
    {
      "x": -7,
      "y": 0,
      "z": 0,
      "name": "Rock_Shale"
    },
    {
      "x": -7,
      "y": 1,
      "z": 0,
      "name": "Rock_Shale"
    },
    {
      "x": -7,
      "y": 2,
      "z": 0,
      "name": "Rock_Shale"
    },
    {
      "x": -7,
      "y": 3,
      "z": 0,
      "name": "Rock_Shale"
    },
    {
      "x": -7,
      "y": 4,
      "z": 0,
      "name": "Rock_Shale"
    },
    {
      "x": -7,
      "y": 5,
      "z": 0,
      "name": "Rock_Shale"
    },
    {
      "x": -7,
      "y": 6,
      "z": 0,
      "name": "Rock_Shale"
    },
    {
      "x": -7,
      "y": 7,
      "z": 0,
      "name": "Rock_Shale"
    },
    {
      "x": -7,
      "y": 8,
      "z": 0,
      "name": "Rock_Shale"
    },
    {
      "x": -7,
      "y": 9,
      "z": 0,
      "name": "Rock_Shale"
    },
    {
      "x": -6,
      "y": -6,
      "z": -16,
      "name": "Rock_Shale"
    },
    {
      "x": -6,
      "y": -5,
      "z": -16,
      "name": "Rock_Shale"
    },
    {
      "x": -6,
      "y": -4,
      "z": -16,
      "name": "Rock_Shale"
    },
    {
      "x": -6,
      "y": -3,
      "z": -16,
      "name": "Rock_Shale"
    },
    {
      "x": -6,
      "y": -2,
      "z": -16,
      "name": "Rock_Shale"
    },
    {
      "x": -6,
      "y": -1,
      "z": -16,
      "name": "Rock_Shale"
    },
    {
      "x": -6,
      "y": 0,
      "z": -16,
      "name": "Rock_Shale"
    },
    {
      "x": -6,
      "y": 1,
      "z": -16,
      "name": "Rock_Shale"
    },
    {
      "x": -6,
      "y": 2,
      "z": -16,
      "name": "Rock_Shale"
    },
    {
      "x": -6,
      "y": 3,
      "z": -16,
      "name": "Rock_Shale"
    },
    {
      "x": -6,
      "y": 4,
      "z": -16,
      "name": "Rock_Shale"
    },
    {
      "x": -6,
      "y": 5,
      "z": -16,
      "name": "Rock_Shale"
    },
    {
      "x": -6,
      "y": 6,
      "z": -16,
      "name": "Rock_Shale"
    },
    {
      "x": -6,
      "y": 7,
      "z": -16,
      "name": "Rock_Shale"
    },
    {
      "x": -6,
      "y": 8,
      "z": -16,
      "name": "Rock_Shale"
    },
    {
      "x": -6,
      "y": 9,
      "z": -16,
      "name": "Rock_Shale"
    },
    {
      "x": -6,
      "y": 10,
      "z": -16,
      "name": "Rock_Shale"
    },
    {
      "x": -6,
      "y": 11,
      "z": -16,
      "name": "Rock_Shale"
    },
    {
      "x": -6,
      "y": -6,
      "z": -15,
      "name": "Rock_Shale"
    },
    {
      "x": -6,
      "y": -5,
      "z": -15,
      "name": "Rock_Shale"
    },
    {
      "x": -6,
      "y": -4,
      "z": -15,
      "name": "Rock_Shale"
    },
    {
      "x": -6,
      "y": -3,
      "z": -15,
      "name": "Rock_Shale"
    },
    {
      "x": -6,
      "y": -2,
      "z": -15,
      "name": "Rock_Shale"
    },
    {
      "x": -6,
      "y": -1,
      "z": -15,
      "name": "Rock_Shale"
    },
    {
      "x": -6,
      "y": 0,
      "z": -15,
      "name": "Rock_Basalt_Cobble"
    },
    {
      "x": -6,
      "y": 1,
      "z": -15,
      "name": "Rock_Basalt_Cobble"
    },
    {
      "x": -6,
      "y": 2,
      "z": -15,
      "name": "Rock_Basalt_Cobble"
    },
    {
      "x": -6,
      "y": 3,
      "z": -15,
      "name": "Rock_Basalt_Cobble"
    },
    {
      "x": -6,
      "y": 4,
      "z": -15,
      "name": "Rock_Basalt_Cobble"
    },
    {
      "x": -6,
      "y": 5,
      "z": -15,
      "name": "Rock_Basalt_Cobble"
    },
    {
      "x": -6,
      "y": 6,
      "z": -15,
      "name": "Rock_Basalt_Cobble"
    },
    {
      "x": -6,
      "y": 7,
      "z": -15,
      "name": "Empty"
    },
    {
      "x": -6,
      "y": 8,
      "z": -15,
      "name": "Empty"
    },
    {
      "x": -6,
      "y": 9,
      "z": -15,
      "name": "Rock_Shale"
    },
    {
      "x": -6,
      "y": 10,
      "z": -15,
      "name": "Rock_Shale"
    },
    {
      "x": -6,
      "y": 11,
      "z": -15,
      "name": "Rock_Shale"
    },
    {
      "x": -6,
      "y": -6,
      "z": -14,
      "name": "Rock_Shale"
    },
    {
      "x": -6,
      "y": -5,
      "z": -14,
      "name": "Rock_Shale"
    },
    {
      "x": -6,
      "y": -4,
      "z": -14,
      "name": "Rock_Shale"
    },
    {
      "x": -6,
      "y": -3,
      "z": -14,
      "name": "Rock_Shale"
    },
    {
      "x": -6,
      "y": -2,
      "z": -14,
      "name": "Rock_Shale"
    },
    {
      "x": -6,
      "y": -1,
      "z": -14,
      "name": "Rock_Shale"
    },
    {
      "x": -6,
      "y": 0,
      "z": -14,
      "name": "Rock_Basalt_Cobble"
    },
    {
      "x": -6,
      "y": 1,
      "z": -14,
      "name": "Rock_Basalt_Cobble"
    },
    {
      "x": -6,
      "y": 2,
      "z": -14,
      "name": "Rock_Basalt_Cobble"
    },
    {
      "x": -6,
      "y": 3,
      "z": -14,
      "name": "Rock_Basalt_Cobble"
    },
    {
      "x": -6,
      "y": 4,
      "z": -14,
      "name": "Rock_Basalt_Cobble"
    },
    {
      "x": -6,
      "y": 5,
      "z": -14,
      "name": "Rock_Basalt_Cobble"
    },
    {
      "x": -6,
      "y": 6,
      "z": -14,
      "name": "Rock_Basalt_Cobble"
    },
    {
      "x": -6,
      "y": 7,
      "z": -14,
      "name": "Empty"
    },
    {
      "x": -6,
      "y": 8,
      "z": -14,
      "name": "Empty"
    },
    {
      "x": -6,
      "y": 9,
      "z": -14,
      "name": "Empty"
    },
    {
      "x": -6,
      "y": 10,
      "z": -14,
      "name": "Rock_Shale"
    },
    {
      "x": -6,
      "y": 11,
      "z": -14,
      "name": "Rock_Shale"
    },
    {
      "x": -6,
      "y": -6,
      "z": -13,
      "name": "Rock_Shale"
    },
    {
      "x": -6,
      "y": -5,
      "z": -13,
      "name": "Rock_Shale"
    },
    {
      "x": -6,
      "y": -4,
      "z": -13,
      "name": "Rock_Shale"
    },
    {
      "x": -6,
      "y": -3,
      "z": -13,
      "name": "Rock_Shale"
    },
    {
      "x": -6,
      "y": -2,
      "z": -13,
      "name": "Rock_Shale"
    },
    {
      "x": -6,
      "y": -1,
      "z": -13,
      "name": "Rock_Shale"
    },
    {
      "x": -6,
      "y": 0,
      "z": -13,
      "name": "Rock_Basalt_Cobble"
    },
    {
      "x": -6,
      "y": 1,
      "z": -13,
      "name": "Rock_Basalt_Cobble"
    },
    {
      "x": -6,
      "y": 2,
      "z": -13,
      "name": "Rock_Basalt_Cobble"
    },
    {
      "x": -6,
      "y": 3,
      "z": -13,
      "name": "Rock_Basalt_Cobble"
    },
    {
      "x": -6,
      "y": 4,
      "z": -13,
      "name": "Rock_Basalt_Cobble"
    },
    {
      "x": -6,
      "y": 5,
      "z": -13,
      "name": "Rock_Basalt_Cobble"
    },
    {
      "x": -6,
      "y": 6,
      "z": -13,
      "name": "Rock_Basalt_Cobble"
    },
    {
      "x": -6,
      "y": 7,
      "z": -13,
      "name": "Empty"
    },
    {
      "x": -6,
      "y": 8,
      "z": -13,
      "name": "Empty"
    },
    {
      "x": -6,
      "y": 9,
      "z": -13,
      "name": "Empty"
    },
    {
      "x": -6,
      "y": 10,
      "z": -13,
      "name": "Empty"
    },
    {
      "x": -6,
      "y": 11,
      "z": -13,
      "name": "Rock_Shale"
    },
    {
      "x": -6,
      "y": -6,
      "z": -12,
      "name": "Rock_Shale"
    },
    {
      "x": -6,
      "y": -5,
      "z": -12,
      "name": "Rock_Shale"
    },
    {
      "x": -6,
      "y": -4,
      "z": -12,
      "name": "Rock_Shale"
    },
    {
      "x": -6,
      "y": -3,
      "z": -12,
      "name": "Rock_Shale"
    },
    {
      "x": -6,
      "y": -2,
      "z": -12,
      "name": "Rock_Shale"
    },
    {
      "x": -6,
      "y": -1,
      "z": -12,
      "name": "Rock_Shale"
    },
    {
      "x": -6,
      "y": 0,
      "z": -12,
      "name": "Rock_Basalt_Cobble"
    },
    {
      "x": -6,
      "y": 1,
      "z": -12,
      "name": "Rock_Basalt_Cobble"
    },
    {
      "x": -6,
      "y": 2,
      "z": -12,
      "name": "Rock_Basalt_Cobble"
    },
    {
      "x": -6,
      "y": 3,
      "z": -12,
      "name": "Rock_Basalt_Cobble"
    },
    {
      "x": -6,
      "y": 4,
      "z": -12,
      "name": "Empty"
    },
    {
      "x": -6,
      "y": 5,
      "z": -12,
      "name": "Empty"
    },
    {
      "x": -6,
      "y": 6,
      "z": -12,
      "name": "Empty"
    },
    {
      "x": -6,
      "y": 7,
      "z": -12,
      "name": "Empty"
    },
    {
      "x": -6,
      "y": 8,
      "z": -12,
      "name": "Empty"
    },
    {
      "x": -6,
      "y": 9,
      "z": -12,
      "name": "Empty"
    },
    {
      "x": -6,
      "y": 10,
      "z": -12,
      "name": "Empty"
    },
    {
      "x": -6,
      "y": 11,
      "z": -12,
      "name": "Rock_Shale"
    },
    {
      "x": -6,
      "y": -6,
      "z": -11,
      "name": "Rock_Shale"
    },
    {
      "x": -6,
      "y": -5,
      "z": -11,
      "name": "Rock_Shale"
    },
    {
      "x": -6,
      "y": -4,
      "z": -11,
      "name": "Rock_Shale"
    },
    {
      "x": -6,
      "y": -3,
      "z": -11,
      "name": "Rock_Shale"
    },
    {
      "x": -6,
      "y": -2,
      "z": -11,
      "name": "Rock_Shale"
    },
    {
      "x": -6,
      "y": -1,
      "z": -11,
      "name": "Rock_Shale"
    },
    {
      "x": -6,
      "y": 0,
      "z": -11,
      "name": "Rock_Basalt_Cobble"
    },
    {
      "x": -6,
      "y": 1,
      "z": -11,
      "name": "Rock_Basalt_Cobble"
    },
    {
      "x": -6,
      "y": 2,
      "z": -11,
      "name": "Rock_Basalt_Cobble"
    },
    {
      "x": -6,
      "y": 3,
      "z": -11,
      "name": "Rock_Basalt_Cobble"
    },
    {
      "x": -6,
      "y": 4,
      "z": -11,
      "name": "Empty"
    },
    {
      "x": -6,
      "y": 5,
      "z": -11,
      "name": "Empty"
    },
    {
      "x": -6,
      "y": 6,
      "z": -11,
      "name": "Empty"
    },
    {
      "x": -6,
      "y": 7,
      "z": -11,
      "name": "Empty"
    },
    {
      "x": -6,
      "y": 8,
      "z": -11,
      "name": "Empty"
    },
    {
      "x": -6,
      "y": 9,
      "z": -11,
      "name": "Empty"
    },
    {
      "x": -6,
      "y": 10,
      "z": -11,
      "name": "Empty"
    },
    {
      "x": -6,
      "y": 11,
      "z": -11,
      "name": "Rock_Shale"
    },
    {
      "x": -6,
      "y": -6,
      "z": -10,
      "name": "Rock_Shale"
    },
    {
      "x": -6,
      "y": -5,
      "z": -10,
      "name": "Rock_Shale"
    },
    {
      "x": -6,
      "y": -4,
      "z": -10,
      "name": "Rock_Shale"
    },
    {
      "x": -6,
      "y": -3,
      "z": -10,
      "name": "Rock_Shale"
    },
    {
      "x": -6,
      "y": -2,
      "z": -10,
      "name": "Rock_Shale"
    },
    {
      "x": -6,
      "y": -1,
      "z": -10,
      "name": "Rock_Shale"
    },
    {
      "x": -6,
      "y": 0,
      "z": -10,
      "name": "Rock_Basalt_Cobble"
    },
    {
      "x": -6,
      "y": 1,
      "z": -10,
      "name": "Rock_Basalt_Cobble"
    },
    {
      "x": -6,
      "y": 2,
      "z": -10,
      "name": "Rock_Basalt_Cobble"
    },
    {
      "x": -6,
      "y": 3,
      "z": -10,
      "name": "Rock_Basalt_Cobble_Half"
    },
    {
      "x": -6,
      "y": 4,
      "z": -10,
      "name": "Empty"
    },
    {
      "x": -6,
      "y": 5,
      "z": -10,
      "name": "Empty"
    },
    {
      "x": -6,
      "y": 6,
      "z": -10,
      "name": "Empty"
    },
    {
      "x": -6,
      "y": 7,
      "z": -10,
      "name": "Empty"
    },
    {
      "x": -6,
      "y": 8,
      "z": -10,
      "name": "Empty"
    },
    {
      "x": -6,
      "y": 9,
      "z": -10,
      "name": "Empty"
    },
    {
      "x": -6,
      "y": 10,
      "z": -10,
      "name": "Empty"
    },
    {
      "x": -6,
      "y": -6,
      "z": -9,
      "name": "Rock_Shale"
    },
    {
      "x": -6,
      "y": -5,
      "z": -9,
      "name": "Rock_Shale"
    },
    {
      "x": -6,
      "y": -4,
      "z": -9,
      "name": "Rock_Shale"
    },
    {
      "x": -6,
      "y": -2,
      "z": -9,
      "name": "Empty"
    },
    {
      "x": -6,
      "y": -1,
      "z": -9,
      "name": "Empty"
    },
    {
      "x": -6,
      "y": 0,
      "z": -9,
      "name": "Empty"
    },
    {
      "x": -6,
      "y": 1,
      "z": -9,
      "name": "Empty"
    },
    {
      "x": -6,
      "y": 2,
      "z": -9,
      "name": "Empty"
    },
    {
      "x": -6,
      "y": 3,
      "z": -9,
      "name": "Empty"
    },
    {
      "x": -6,
      "y": 4,
      "z": -9,
      "name": "Empty"
    },
    {
      "x": -6,
      "y": 5,
      "z": -9,
      "name": "Empty"
    },
    {
      "x": -6,
      "y": 6,
      "z": -9,
      "name": "Empty"
    },
    {
      "x": -6,
      "y": 7,
      "z": -9,
      "name": "Empty"
    },
    {
      "x": -6,
      "y": 8,
      "z": -9,
      "name": "Empty"
    },
    {
      "x": -6,
      "y": 9,
      "z": -9,
      "name": "Empty"
    },
    {
      "x": -6,
      "y": -6,
      "z": -8,
      "name": "Rock_Shale"
    },
    {
      "x": -6,
      "y": -5,
      "z": -8,
      "name": "Rock_Shale"
    },
    {
      "x": -6,
      "y": -4,
      "z": -8,
      "name": "Rock_Shale"
    },
    {
      "x": -6,
      "y": -2,
      "z": -8,
      "name": "Empty"
    },
    {
      "x": -6,
      "y": -1,
      "z": -8,
      "name": "Empty"
    },
    {
      "x": -6,
      "y": 0,
      "z": -8,
      "name": "Empty"
    },
    {
      "x": -6,
      "y": 1,
      "z": -8,
      "name": "Empty"
    },
    {
      "x": -6,
      "y": 2,
      "z": -8,
      "name": "Empty"
    },
    {
      "x": -6,
      "y": 3,
      "z": -8,
      "name": "Empty"
    },
    {
      "x": -6,
      "y": 4,
      "z": -8,
      "name": "Empty"
    },
    {
      "x": -6,
      "y": 5,
      "z": -8,
      "name": "Empty"
    },
    {
      "x": -6,
      "y": 6,
      "z": -8,
      "name": "Empty"
    },
    {
      "x": -6,
      "y": 7,
      "z": -8,
      "name": "Empty"
    },
    {
      "x": -6,
      "y": 8,
      "z": -8,
      "name": "Empty"
    },
    {
      "x": -6,
      "y": 9,
      "z": -8,
      "name": "Empty"
    },
    {
      "x": -6,
      "y": -6,
      "z": -7,
      "name": "Rock_Shale"
    },
    {
      "x": -6,
      "y": -5,
      "z": -7,
      "name": "Rock_Shale"
    },
    {
      "x": -6,
      "y": -4,
      "z": -7,
      "name": "Rock_Shale"
    },
    {
      "x": -6,
      "y": -3,
      "z": -7,
      "name": "Rock_Shale"
    },
    {
      "x": -6,
      "y": -2,
      "z": -7,
      "name": "Rock_Shale"
    },
    {
      "x": -6,
      "y": -1,
      "z": -7,
      "name": "Rock_Shale"
    },
    {
      "x": -6,
      "y": 0,
      "z": -7,
      "name": "Rock_Basalt_Cobble"
    },
    {
      "x": -6,
      "y": 1,
      "z": -7,
      "name": "Empty"
    },
    {
      "x": -6,
      "y": 2,
      "z": -7,
      "name": "Empty"
    },
    {
      "x": -6,
      "y": 3,
      "z": -7,
      "name": "Empty"
    },
    {
      "x": -6,
      "y": 4,
      "z": -7,
      "name": "Empty"
    },
    {
      "x": -6,
      "y": 5,
      "z": -7,
      "name": "Empty"
    },
    {
      "x": -6,
      "y": 6,
      "z": -7,
      "name": "Rock_Shale_Stalactites_Small",
      "rotation": 8
    },
    {
      "x": -6,
      "y": 7,
      "z": -7,
      "name": "Rock_Shale"
    },
    {
      "x": -6,
      "y": 8,
      "z": -7,
      "name": "Empty"
    },
    {
      "x": -6,
      "y": -6,
      "z": -6,
      "name": "Rock_Shale"
    },
    {
      "x": -6,
      "y": -5,
      "z": -6,
      "name": "Rock_Shale"
    },
    {
      "x": -6,
      "y": -4,
      "z": -6,
      "name": "Rock_Shale"
    },
    {
      "x": -6,
      "y": -3,
      "z": -6,
      "name": "Rock_Shale"
    },
    {
      "x": -6,
      "y": -2,
      "z": -6,
      "name": "Rock_Shale"
    },
    {
      "x": -6,
      "y": -1,
      "z": -6,
      "name": "Rock_Shale"
    },
    {
      "x": -6,
      "y": 0,
      "z": -6,
      "name": "Rock_Basalt_Cobble"
    },
    {
      "x": -6,
      "y": 1,
      "z": -6,
      "name": "Empty"
    },
    {
      "x": -6,
      "y": 2,
      "z": -6,
      "name": "Empty"
    },
    {
      "x": -6,
      "y": 3,
      "z": -6,
      "name": "Empty"
    },
    {
      "x": -6,
      "y": 4,
      "z": -6,
      "name": "Empty"
    },
    {
      "x": -6,
      "y": 5,
      "z": -6,
      "name": "Empty"
    },
    {
      "x": -6,
      "y": 6,
      "z": -6,
      "name": "Empty"
    },
    {
      "x": -6,
      "y": 7,
      "z": -6,
      "name": "Rock_Shale"
    },
    {
      "x": -6,
      "y": 8,
      "z": -6,
      "name": "Rock_Shale"
    },
    {
      "x": -6,
      "y": -6,
      "z": -5,
      "name": "Rock_Shale"
    },
    {
      "x": -6,
      "y": -5,
      "z": -5,
      "name": "Rock_Shale"
    },
    {
      "x": -6,
      "y": -4,
      "z": -5,
      "name": "Rock_Shale"
    },
    {
      "x": -6,
      "y": -2,
      "z": -5,
      "name": "Empty"
    },
    {
      "x": -6,
      "y": -1,
      "z": -5,
      "name": "Empty"
    },
    {
      "x": -6,
      "y": 0,
      "z": -5,
      "name": "Empty"
    },
    {
      "x": -6,
      "y": 1,
      "z": -5,
      "name": "Empty"
    },
    {
      "x": -6,
      "y": 2,
      "z": -5,
      "name": "Empty"
    },
    {
      "x": -6,
      "y": 3,
      "z": -5,
      "name": "Rock_Shale_Stalactites_Large",
      "filler": 31744,
      "rotation": 8
    },
    {
      "x": -6,
      "y": 4,
      "z": -5,
      "name": "Rock_Shale_Stalactites_Large",
      "rotation": 8
    },
    {
      "x": -6,
      "y": 5,
      "z": -5,
      "name": "Rock_Shale"
    },
    {
      "x": -6,
      "y": 6,
      "z": -5,
      "name": "Rock_Shale"
    },
    {
      "x": -6,
      "y": 7,
      "z": -5,
      "name": "Rock_Shale"
    },
    {
      "x": -6,
      "y": 8,
      "z": -5,
      "name": "Rock_Shale"
    },
    {
      "x": -6,
      "y": -6,
      "z": -4,
      "name": "Rock_Shale"
    },
    {
      "x": -6,
      "y": -5,
      "z": -4,
      "name": "Rock_Shale"
    },
    {
      "x": -6,
      "y": -4,
      "z": -4,
      "name": "Rock_Shale"
    },
    {
      "x": -6,
      "y": -2,
      "z": -4,
      "name": "Empty"
    },
    {
      "x": -6,
      "y": -1,
      "z": -4,
      "name": "Empty"
    },
    {
      "x": -6,
      "y": 0,
      "z": -4,
      "name": "Empty"
    },
    {
      "x": -6,
      "y": 1,
      "z": -4,
      "name": "Empty"
    },
    {
      "x": -6,
      "y": 2,
      "z": -4,
      "name": "Empty"
    },
    {
      "x": -6,
      "y": 3,
      "z": -4,
      "name": "Empty"
    },
    {
      "x": -6,
      "y": 4,
      "z": -4,
      "name": "Empty"
    },
    {
      "x": -6,
      "y": 5,
      "z": -4,
      "name": "Empty"
    },
    {
      "x": -6,
      "y": 6,
      "z": -4,
      "name": "Empty"
    },
    {
      "x": -6,
      "y": 7,
      "z": -4,
      "name": "Rock_Shale"
    },
    {
      "x": -6,
      "y": 8,
      "z": -4,
      "name": "Rock_Shale"
    },
    {
      "x": -6,
      "y": -6,
      "z": -3,
      "name": "Rock_Shale"
    },
    {
      "x": -6,
      "y": -5,
      "z": -3,
      "name": "Rock_Shale"
    },
    {
      "x": -6,
      "y": -4,
      "z": -3,
      "name": "Rock_Shale"
    },
    {
      "x": -6,
      "y": -3,
      "z": -3,
      "name": "Rock_Shale"
    },
    {
      "x": -6,
      "y": -2,
      "z": -3,
      "name": "Rock_Shale"
    },
    {
      "x": -6,
      "y": -1,
      "z": -3,
      "name": "Rock_Shale"
    },
    {
      "x": -6,
      "y": 0,
      "z": -3,
      "name": "Rock_Basalt_Cobble"
    },
    {
      "x": -6,
      "y": 1,
      "z": -3,
      "name": "Empty"
    },
    {
      "x": -6,
      "y": 2,
      "z": -3,
      "name": "Empty"
    },
    {
      "x": -6,
      "y": 3,
      "z": -3,
      "name": "Empty"
    },
    {
      "x": -6,
      "y": 4,
      "z": -3,
      "name": "Empty"
    },
    {
      "x": -6,
      "y": 5,
      "z": -3,
      "name": "Empty"
    },
    {
      "x": -6,
      "y": 6,
      "z": -3,
      "name": "Empty"
    },
    {
      "x": -6,
      "y": 7,
      "z": -3,
      "name": "Empty"
    },
    {
      "x": -6,
      "y": 8,
      "z": -3,
      "name": "Rock_Shale"
    },
    {
      "x": -6,
      "y": 9,
      "z": -3,
      "name": "Rock_Shale"
    },
    {
      "x": -6,
      "y": -6,
      "z": -2,
      "name": "Rock_Shale"
    },
    {
      "x": -6,
      "y": -5,
      "z": -2,
      "name": "Rock_Shale"
    },
    {
      "x": -6,
      "y": -4,
      "z": -2,
      "name": "Rock_Shale"
    },
    {
      "x": -6,
      "y": -3,
      "z": -2,
      "name": "Rock_Shale"
    },
    {
      "x": -6,
      "y": -2,
      "z": -2,
      "name": "Rock_Shale"
    },
    {
      "x": -6,
      "y": -1,
      "z": -2,
      "name": "Rock_Shale"
    },
    {
      "x": -6,
      "y": 0,
      "z": -2,
      "name": "Rock_Basalt_Cobble"
    },
    {
      "x": -6,
      "y": 1,
      "z": -2,
      "name": "Empty"
    },
    {
      "x": -6,
      "y": 2,
      "z": -2,
      "name": "Empty"
    },
    {
      "x": -6,
      "y": 3,
      "z": -2,
      "name": "Empty"
    },
    {
      "x": -6,
      "y": 4,
      "z": -2,
      "name": "Empty"
    },
    {
      "x": -6,
      "y": 5,
      "z": -2,
      "name": "Empty"
    },
    {
      "x": -6,
      "y": 6,
      "z": -2,
      "name": "Empty"
    },
    {
      "x": -6,
      "y": 7,
      "z": -2,
      "name": "Empty"
    },
    {
      "x": -6,
      "y": 8,
      "z": -2,
      "name": "Rock_Shale"
    },
    {
      "x": -6,
      "y": 9,
      "z": -2,
      "name": "Rock_Shale"
    },
    {
      "x": -6,
      "y": -6,
      "z": -1,
      "name": "Rock_Shale"
    },
    {
      "x": -6,
      "y": -5,
      "z": -1,
      "name": "Rock_Shale"
    },
    {
      "x": -6,
      "y": -4,
      "z": -1,
      "name": "Rock_Shale"
    },
    {
      "x": -6,
      "y": -3,
      "z": -1,
      "name": "Rock_Shale"
    },
    {
      "x": -6,
      "y": -2,
      "z": -1,
      "name": "Rock_Shale"
    },
    {
      "x": -6,
      "y": -1,
      "z": -1,
      "name": "Rock_Shale"
    },
    {
      "x": -6,
      "y": 0,
      "z": -1,
      "name": "Rock_Basalt_Cobble"
    },
    {
      "x": -6,
      "y": 1,
      "z": -1,
      "name": "Rock_Basalt_Cobble"
    },
    {
      "x": -6,
      "y": 2,
      "z": -1,
      "name": "Rock_Basalt_Cobble"
    },
    {
      "x": -6,
      "y": 3,
      "z": -1,
      "name": "Rock_Basalt_Cobble"
    },
    {
      "x": -6,
      "y": 4,
      "z": -1,
      "name": "Rock_Basalt_Cobble_Half"
    },
    {
      "x": -6,
      "y": 5,
      "z": -1,
      "name": "Empty"
    },
    {
      "x": -6,
      "y": 6,
      "z": -1,
      "name": "Empty"
    },
    {
      "x": -6,
      "y": 7,
      "z": -1,
      "name": "Empty"
    },
    {
      "x": -6,
      "y": 8,
      "z": -1,
      "name": "Rock_Shale"
    },
    {
      "x": -6,
      "y": 9,
      "z": -1,
      "name": "Rock_Shale"
    },
    {
      "x": -6,
      "y": -6,
      "z": 0,
      "name": "Rock_Shale"
    },
    {
      "x": -6,
      "y": -5,
      "z": 0,
      "name": "Rock_Shale"
    },
    {
      "x": -6,
      "y": -4,
      "z": 0,
      "name": "Rock_Shale"
    },
    {
      "x": -6,
      "y": -3,
      "z": 0,
      "name": "Rock_Shale"
    },
    {
      "x": -6,
      "y": -2,
      "z": 0,
      "name": "Rock_Shale"
    },
    {
      "x": -6,
      "y": -1,
      "z": 0,
      "name": "Rock_Shale"
    },
    {
      "x": -6,
      "y": 0,
      "z": 0,
      "name": "Rock_Shale"
    },
    {
      "x": -6,
      "y": 1,
      "z": 0,
      "name": "Rock_Shale"
    },
    {
      "x": -6,
      "y": 2,
      "z": 0,
      "name": "Rock_Shale"
    },
    {
      "x": -6,
      "y": 3,
      "z": 0,
      "name": "Rock_Shale"
    },
    {
      "x": -6,
      "y": 4,
      "z": 0,
      "name": "Rock_Shale"
    },
    {
      "x": -6,
      "y": 5,
      "z": 0,
      "name": "Rock_Shale"
    },
    {
      "x": -6,
      "y": 6,
      "z": 0,
      "name": "Rock_Shale"
    },
    {
      "x": -6,
      "y": 7,
      "z": 0,
      "name": "Rock_Shale"
    },
    {
      "x": -6,
      "y": 8,
      "z": 0,
      "name": "Rock_Shale"
    },
    {
      "x": -6,
      "y": 9,
      "z": 0,
      "name": "Rock_Shale"
    },
    {
      "x": -5,
      "y": -6,
      "z": -16,
      "name": "Rock_Shale"
    },
    {
      "x": -5,
      "y": -5,
      "z": -16,
      "name": "Rock_Shale"
    },
    {
      "x": -5,
      "y": -4,
      "z": -16,
      "name": "Rock_Shale"
    },
    {
      "x": -5,
      "y": -3,
      "z": -16,
      "name": "Rock_Shale"
    },
    {
      "x": -5,
      "y": -2,
      "z": -16,
      "name": "Rock_Shale"
    },
    {
      "x": -5,
      "y": -1,
      "z": -16,
      "name": "Rock_Shale"
    },
    {
      "x": -5,
      "y": 0,
      "z": -16,
      "name": "Rock_Shale"
    },
    {
      "x": -5,
      "y": 1,
      "z": -16,
      "name": "Rock_Shale"
    },
    {
      "x": -5,
      "y": 2,
      "z": -16,
      "name": "Rock_Shale"
    },
    {
      "x": -5,
      "y": 3,
      "z": -16,
      "name": "Rock_Shale"
    },
    {
      "x": -5,
      "y": 4,
      "z": -16,
      "name": "Rock_Shale"
    },
    {
      "x": -5,
      "y": 5,
      "z": -16,
      "name": "Rock_Shale"
    },
    {
      "x": -5,
      "y": 6,
      "z": -16,
      "name": "Rock_Shale"
    },
    {
      "x": -5,
      "y": 7,
      "z": -16,
      "name": "Rock_Shale"
    },
    {
      "x": -5,
      "y": 8,
      "z": -16,
      "name": "Rock_Shale"
    },
    {
      "x": -5,
      "y": 9,
      "z": -16,
      "name": "Rock_Shale"
    },
    {
      "x": -5,
      "y": 10,
      "z": -16,
      "name": "Rock_Shale"
    },
    {
      "x": -5,
      "y": 11,
      "z": -16,
      "name": "Rock_Shale"
    },
    {
      "x": -5,
      "y": -6,
      "z": -15,
      "name": "Rock_Shale"
    },
    {
      "x": -5,
      "y": -5,
      "z": -15,
      "name": "Rock_Shale"
    },
    {
      "x": -5,
      "y": -4,
      "z": -15,
      "name": "Rock_Shale"
    },
    {
      "x": -5,
      "y": -3,
      "z": -15,
      "name": "Rock_Shale"
    },
    {
      "x": -5,
      "y": -2,
      "z": -15,
      "name": "Rock_Shale"
    },
    {
      "x": -5,
      "y": -1,
      "z": -15,
      "name": "Rock_Shale"
    },
    {
      "x": -5,
      "y": 0,
      "z": -15,
      "name": "Rock_Shale"
    },
    {
      "x": -5,
      "y": 1,
      "z": -15,
      "name": "Rock_Shale"
    },
    {
      "x": -5,
      "y": 2,
      "z": -15,
      "name": "Rock_Shale"
    },
    {
      "x": -5,
      "y": 3,
      "z": -15,
      "name": "Rock_Shale"
    },
    {
      "x": -5,
      "y": 4,
      "z": -15,
      "name": "Rock_Shale"
    },
    {
      "x": -5,
      "y": 5,
      "z": -15,
      "name": "Rock_Shale"
    },
    {
      "x": -5,
      "y": 6,
      "z": -15,
      "name": "Rock_Shale"
    },
    {
      "x": -5,
      "y": 7,
      "z": -15,
      "name": "Rock_Shale"
    },
    {
      "x": -5,
      "y": 8,
      "z": -15,
      "name": "Rock_Shale"
    },
    {
      "x": -5,
      "y": 9,
      "z": -15,
      "name": "Rock_Shale"
    },
    {
      "x": -5,
      "y": 10,
      "z": -15,
      "name": "Rock_Shale"
    },
    {
      "x": -5,
      "y": 11,
      "z": -15,
      "name": "Rock_Shale"
    },
    {
      "x": -5,
      "y": -6,
      "z": -14,
      "name": "Rock_Shale"
    },
    {
      "x": -5,
      "y": -5,
      "z": -14,
      "name": "Rock_Shale"
    },
    {
      "x": -5,
      "y": -4,
      "z": -14,
      "name": "Rock_Shale"
    },
    {
      "x": -5,
      "y": -3,
      "z": -14,
      "name": "Rock_Shale"
    },
    {
      "x": -5,
      "y": -2,
      "z": -14,
      "name": "Rock_Shale"
    },
    {
      "x": -5,
      "y": -1,
      "z": -14,
      "name": "Rock_Shale"
    },
    {
      "x": -5,
      "y": 0,
      "z": -14,
      "name": "Rock_Shale"
    },
    {
      "x": -5,
      "y": 1,
      "z": -14,
      "name": "Rock_Shale"
    },
    {
      "x": -5,
      "y": 2,
      "z": -14,
      "name": "Rock_Shale"
    },
    {
      "x": -5,
      "y": 3,
      "z": -14,
      "name": "Rock_Shale"
    },
    {
      "x": -5,
      "y": 4,
      "z": -14,
      "name": "Rock_Shale"
    },
    {
      "x": -5,
      "y": 5,
      "z": -14,
      "name": "Rock_Shale"
    },
    {
      "x": -5,
      "y": 6,
      "z": -14,
      "name": "Rock_Shale"
    },
    {
      "x": -5,
      "y": 7,
      "z": -14,
      "name": "Rock_Shale"
    },
    {
      "x": -5,
      "y": 8,
      "z": -14,
      "name": "Rock_Shale"
    },
    {
      "x": -5,
      "y": 9,
      "z": -14,
      "name": "Rock_Shale"
    },
    {
      "x": -5,
      "y": 10,
      "z": -14,
      "name": "Rock_Shale"
    },
    {
      "x": -5,
      "y": 11,
      "z": -14,
      "name": "Rock_Shale"
    },
    {
      "x": -5,
      "y": -6,
      "z": -13,
      "name": "Rock_Shale"
    },
    {
      "x": -5,
      "y": -5,
      "z": -13,
      "name": "Rock_Shale"
    },
    {
      "x": -5,
      "y": -4,
      "z": -13,
      "name": "Rock_Shale"
    },
    {
      "x": -5,
      "y": -3,
      "z": -13,
      "name": "Rock_Shale"
    },
    {
      "x": -5,
      "y": -2,
      "z": -13,
      "name": "Rock_Shale"
    },
    {
      "x": -5,
      "y": -1,
      "z": -13,
      "name": "Rock_Shale"
    },
    {
      "x": -5,
      "y": 0,
      "z": -13,
      "name": "Rock_Shale"
    },
    {
      "x": -5,
      "y": 1,
      "z": -13,
      "name": "Rock_Shale"
    },
    {
      "x": -5,
      "y": 2,
      "z": -13,
      "name": "Rock_Shale"
    },
    {
      "x": -5,
      "y": 3,
      "z": -13,
      "name": "Rock_Shale"
    },
    {
      "x": -5,
      "y": 4,
      "z": -13,
      "name": "Empty"
    },
    {
      "x": -5,
      "y": 5,
      "z": -13,
      "name": "Empty"
    },
    {
      "x": -5,
      "y": 6,
      "z": -13,
      "name": "Rock_Shale"
    },
    {
      "x": -5,
      "y": 7,
      "z": -13,
      "name": "Rock_Shale"
    },
    {
      "x": -5,
      "y": 8,
      "z": -13,
      "name": "Rock_Shale"
    },
    {
      "x": -5,
      "y": 9,
      "z": -13,
      "name": "Rock_Shale"
    },
    {
      "x": -5,
      "y": 10,
      "z": -13,
      "name": "Rock_Shale"
    },
    {
      "x": -5,
      "y": 11,
      "z": -13,
      "name": "Rock_Shale"
    },
    {
      "x": -5,
      "y": -6,
      "z": -12,
      "name": "Rock_Shale"
    },
    {
      "x": -5,
      "y": -5,
      "z": -12,
      "name": "Rock_Shale"
    },
    {
      "x": -5,
      "y": -4,
      "z": -12,
      "name": "Rock_Shale"
    },
    {
      "x": -5,
      "y": -3,
      "z": -12,
      "name": "Rock_Shale"
    },
    {
      "x": -5,
      "y": -2,
      "z": -12,
      "name": "Rock_Shale"
    },
    {
      "x": -5,
      "y": -1,
      "z": -12,
      "name": "Rock_Shale"
    },
    {
      "x": -5,
      "y": 0,
      "z": -12,
      "name": "Rock_Shale"
    },
    {
      "x": -5,
      "y": 1,
      "z": -12,
      "name": "Rock_Shale"
    },
    {
      "x": -5,
      "y": 2,
      "z": -12,
      "name": "Rock_Shale"
    },
    {
      "x": -5,
      "y": 3,
      "z": -12,
      "name": "Empty"
    },
    {
      "x": -5,
      "y": 4,
      "z": -12,
      "name": "Empty"
    },
    {
      "x": -5,
      "y": 5,
      "z": -12,
      "name": "Empty"
    },
    {
      "x": -5,
      "y": 6,
      "z": -12,
      "name": "Empty"
    },
    {
      "x": -5,
      "y": 7,
      "z": -12,
      "name": "Empty"
    },
    {
      "x": -5,
      "y": 8,
      "z": -12,
      "name": "Empty"
    },
    {
      "x": -5,
      "y": 9,
      "z": -12,
      "name": "Empty"
    },
    {
      "x": -5,
      "y": 10,
      "z": -12,
      "name": "Empty"
    },
    {
      "x": -5,
      "y": 11,
      "z": -12,
      "name": "Rock_Shale"
    },
    {
      "x": -5,
      "y": -6,
      "z": -11,
      "name": "Rock_Shale"
    },
    {
      "x": -5,
      "y": -5,
      "z": -11,
      "name": "Rock_Shale"
    },
    {
      "x": -5,
      "y": -4,
      "z": -11,
      "name": "Rock_Shale"
    },
    {
      "x": -5,
      "y": -3,
      "z": -11,
      "name": "Rock_Shale"
    },
    {
      "x": -5,
      "y": -2,
      "z": -11,
      "name": "Rock_Shale"
    },
    {
      "x": -5,
      "y": -1,
      "z": -11,
      "name": "Rock_Shale"
    },
    {
      "x": -5,
      "y": 0,
      "z": -11,
      "name": "Rock_Basalt_Cobble"
    },
    {
      "x": -5,
      "y": 1,
      "z": -11,
      "name": "Rock_Basalt_Cobble"
    },
    {
      "x": -5,
      "y": 2,
      "z": -11,
      "name": "Rock_Basalt_Cobble"
    },
    {
      "x": -5,
      "y": 3,
      "z": -11,
      "name": "Rock_Basalt_Cobble_Half"
    },
    {
      "x": -5,
      "y": 4,
      "z": -11,
      "name": "Empty"
    },
    {
      "x": -5,
      "y": 5,
      "z": -11,
      "name": "Empty"
    },
    {
      "x": -5,
      "y": 6,
      "z": -11,
      "name": "Empty"
    },
    {
      "x": -5,
      "y": 7,
      "z": -11,
      "name": "Empty"
    },
    {
      "x": -5,
      "y": 8,
      "z": -11,
      "name": "Empty"
    },
    {
      "x": -5,
      "y": 9,
      "z": -11,
      "name": "Empty"
    },
    {
      "x": -5,
      "y": 10,
      "z": -11,
      "name": "Empty"
    },
    {
      "x": -5,
      "y": 11,
      "z": -11,
      "name": "Rock_Shale"
    },
    {
      "x": -5,
      "y": -6,
      "z": -10,
      "name": "Rock_Shale"
    },
    {
      "x": -5,
      "y": -5,
      "z": -10,
      "name": "Rock_Shale"
    },
    {
      "x": -5,
      "y": -4,
      "z": -10,
      "name": "Rock_Shale"
    },
    {
      "x": -5,
      "y": -3,
      "z": -10,
      "name": "Rock_Shale"
    },
    {
      "x": -5,
      "y": -2,
      "z": -10,
      "name": "Rock_Shale"
    },
    {
      "x": -5,
      "y": -1,
      "z": -10,
      "name": "Rock_Shale"
    },
    {
      "x": -5,
      "y": 0,
      "z": -10,
      "name": "Rock_Basalt_Cobble"
    },
    {
      "x": -5,
      "y": 1,
      "z": -10,
      "name": "Rock_Basalt_Cobble"
    },
    {
      "x": -5,
      "y": 2,
      "z": -10,
      "name": "Rock_Basalt_Cobble"
    },
    {
      "x": -5,
      "y": 3,
      "z": -10,
      "name": "Rock_Basalt_Cobble_Half"
    },
    {
      "x": -5,
      "y": 4,
      "z": -10,
      "name": "Empty"
    },
    {
      "x": -5,
      "y": 5,
      "z": -10,
      "name": "Empty"
    },
    {
      "x": -5,
      "y": 6,
      "z": -10,
      "name": "Empty"
    },
    {
      "x": -5,
      "y": 7,
      "z": -10,
      "name": "Empty"
    },
    {
      "x": -5,
      "y": 8,
      "z": -10,
      "name": "Empty"
    },
    {
      "x": -5,
      "y": 9,
      "z": -10,
      "name": "Empty"
    },
    {
      "x": -5,
      "y": 10,
      "z": -10,
      "name": "Empty"
    },
    {
      "x": -5,
      "y": -6,
      "z": -9,
      "name": "Rock_Shale"
    },
    {
      "x": -5,
      "y": -5,
      "z": -9,
      "name": "Rock_Shale"
    },
    {
      "x": -5,
      "y": -4,
      "z": -9,
      "name": "Rock_Shale"
    },
    {
      "x": -5,
      "y": -3,
      "z": -9,
      "name": "Rock_Shale"
    },
    {
      "x": -5,
      "y": -2,
      "z": -9,
      "name": "Rock_Shale"
    },
    {
      "x": -5,
      "y": -1,
      "z": -9,
      "name": "Rock_Shale"
    },
    {
      "x": -5,
      "y": 0,
      "z": -9,
      "name": "Rock_Basalt_Cobble"
    },
    {
      "x": -5,
      "y": 1,
      "z": -9,
      "name": "Rock_Basalt_Cobble"
    },
    {
      "x": -5,
      "y": 2,
      "z": -9,
      "name": "Rock_Basalt_Cobble"
    },
    {
      "x": -5,
      "y": 3,
      "z": -9,
      "name": "Rock_Basalt_Cobble_Half"
    },
    {
      "x": -5,
      "y": 4,
      "z": -9,
      "name": "Empty"
    },
    {
      "x": -5,
      "y": 5,
      "z": -9,
      "name": "Empty"
    },
    {
      "x": -5,
      "y": 6,
      "z": -9,
      "name": "Empty"
    },
    {
      "x": -5,
      "y": 7,
      "z": -9,
      "name": "Empty"
    },
    {
      "x": -5,
      "y": 8,
      "z": -9,
      "name": "Empty"
    },
    {
      "x": -5,
      "y": 9,
      "z": -9,
      "name": "Empty"
    },
    {
      "x": -5,
      "y": 10,
      "z": -9,
      "name": "Empty"
    },
    {
      "x": -5,
      "y": -6,
      "z": -8,
      "name": "Rock_Shale"
    },
    {
      "x": -5,
      "y": -5,
      "z": -8,
      "name": "Rock_Shale"
    },
    {
      "x": -5,
      "y": -2,
      "z": -8,
      "name": "Empty"
    },
    {
      "x": -5,
      "y": -1,
      "z": -8,
      "name": "Empty"
    },
    {
      "x": -5,
      "y": 0,
      "z": -8,
      "name": "Empty"
    },
    {
      "x": -5,
      "y": 1,
      "z": -8,
      "name": "Empty"
    },
    {
      "x": -5,
      "y": 2,
      "z": -8,
      "name": "Empty"
    },
    {
      "x": -5,
      "y": 3,
      "z": -8,
      "name": "Empty"
    },
    {
      "x": -5,
      "y": 4,
      "z": -8,
      "name": "Empty"
    },
    {
      "x": -5,
      "y": 5,
      "z": -8,
      "name": "Empty"
    },
    {
      "x": -5,
      "y": 6,
      "z": -8,
      "name": "Empty"
    },
    {
      "x": -5,
      "y": 7,
      "z": -8,
      "name": "Empty"
    },
    {
      "x": -5,
      "y": 8,
      "z": -8,
      "name": "Empty"
    },
    {
      "x": -5,
      "y": 9,
      "z": -8,
      "name": "Empty"
    },
    {
      "x": -5,
      "y": -6,
      "z": -7,
      "name": "Rock_Shale"
    },
    {
      "x": -5,
      "y": -5,
      "z": -7,
      "name": "Rock_Shale"
    },
    {
      "x": -5,
      "y": -2,
      "z": -7,
      "name": "Empty"
    },
    {
      "x": -5,
      "y": -1,
      "z": -7,
      "name": "Empty"
    },
    {
      "x": -5,
      "y": 0,
      "z": -7,
      "name": "Empty"
    },
    {
      "x": -5,
      "y": 1,
      "z": -7,
      "name": "Empty"
    },
    {
      "x": -5,
      "y": 2,
      "z": -7,
      "name": "Empty"
    },
    {
      "x": -5,
      "y": 3,
      "z": -7,
      "name": "Empty"
    },
    {
      "x": -5,
      "y": 4,
      "z": -7,
      "name": "Empty"
    },
    {
      "x": -5,
      "y": 5,
      "z": -7,
      "name": "Empty"
    },
    {
      "x": -5,
      "y": 6,
      "z": -7,
      "name": "Empty"
    },
    {
      "x": -5,
      "y": 7,
      "z": -7,
      "name": "Empty"
    },
    {
      "x": -5,
      "y": 8,
      "z": -7,
      "name": "Empty"
    },
    {
      "x": -5,
      "y": 9,
      "z": -7,
      "name": "Empty"
    },
    {
      "x": -5,
      "y": -6,
      "z": -6,
      "name": "Rock_Shale"
    },
    {
      "x": -5,
      "y": -5,
      "z": -6,
      "name": "Rock_Shale"
    },
    {
      "x": -5,
      "y": -2,
      "z": -6,
      "name": "Empty"
    },
    {
      "x": -5,
      "y": -1,
      "z": -6,
      "name": "Empty"
    },
    {
      "x": -5,
      "y": 0,
      "z": -6,
      "name": "Empty"
    },
    {
      "x": -5,
      "y": 1,
      "z": -6,
      "name": "Empty"
    },
    {
      "x": -5,
      "y": 2,
      "z": -6,
      "name": "Empty"
    },
    {
      "x": -5,
      "y": 3,
      "z": -6,
      "name": "Empty"
    },
    {
      "x": -5,
      "y": 4,
      "z": -6,
      "name": "Empty"
    },
    {
      "x": -5,
      "y": 5,
      "z": -6,
      "name": "Rock_Shale_Stalactites_Large",
      "filler": 31744,
      "rotation": 8
    },
    {
      "x": -5,
      "y": 6,
      "z": -6,
      "name": "Rock_Shale_Stalactites_Large",
      "rotation": 8
    },
    {
      "x": -5,
      "y": 7,
      "z": -6,
      "name": "Rock_Shale"
    },
    {
      "x": -5,
      "y": 8,
      "z": -6,
      "name": "Rock_Shale"
    },
    {
      "x": -5,
      "y": -6,
      "z": -5,
      "name": "Rock_Shale"
    },
    {
      "x": -5,
      "y": -5,
      "z": -5,
      "name": "Rock_Shale"
    },
    {
      "x": -5,
      "y": -4,
      "z": -5,
      "name": "Rock_Shale"
    },
    {
      "x": -5,
      "y": -2,
      "z": -5,
      "name": "Empty"
    },
    {
      "x": -5,
      "y": -1,
      "z": -5,
      "name": "Empty"
    },
    {
      "x": -5,
      "y": 0,
      "z": -5,
      "name": "Empty"
    },
    {
      "x": -5,
      "y": 1,
      "z": -5,
      "name": "Empty"
    },
    {
      "x": -5,
      "y": 2,
      "z": -5,
      "name": "Empty"
    },
    {
      "x": -5,
      "y": 3,
      "z": -5,
      "name": "Empty"
    },
    {
      "x": -5,
      "y": 4,
      "z": -5,
      "name": "Empty"
    },
    {
      "x": -5,
      "y": 5,
      "z": -5,
      "name": "Empty"
    },
    {
      "x": -5,
      "y": 6,
      "z": -5,
      "name": "Rock_Shale"
    },
    {
      "x": -5,
      "y": 7,
      "z": -5,
      "name": "Rock_Shale"
    },
    {
      "x": -5,
      "y": 8,
      "z": -5,
      "name": "Rock_Shale"
    },
    {
      "x": -5,
      "y": -6,
      "z": -4,
      "name": "Rock_Shale"
    },
    {
      "x": -5,
      "y": -5,
      "z": -4,
      "name": "Rock_Shale"
    },
    {
      "x": -5,
      "y": -4,
      "z": -4,
      "name": "Rock_Shale"
    },
    {
      "x": -5,
      "y": -3,
      "z": -4,
      "name": "Rock_Shale"
    },
    {
      "x": -5,
      "y": -2,
      "z": -4,
      "name": "Rock_Shale"
    },
    {
      "x": -5,
      "y": -1,
      "z": -4,
      "name": "Rock_Shale"
    },
    {
      "x": -5,
      "y": 0,
      "z": -4,
      "name": "Rock_Basalt_Cobble"
    },
    {
      "x": -5,
      "y": 1,
      "z": -4,
      "name": "Empty"
    },
    {
      "x": -5,
      "y": 2,
      "z": -4,
      "name": "Empty"
    },
    {
      "x": -5,
      "y": 3,
      "z": -4,
      "name": "Empty"
    },
    {
      "x": -5,
      "y": 4,
      "z": -4,
      "name": "Empty"
    },
    {
      "x": -5,
      "y": 5,
      "z": -4,
      "name": "Empty"
    },
    {
      "x": -5,
      "y": 6,
      "z": -4,
      "name": "Empty"
    },
    {
      "x": -5,
      "y": 7,
      "z": -4,
      "name": "Rock_Shale"
    },
    {
      "x": -5,
      "y": 8,
      "z": -4,
      "name": "Rock_Shale"
    },
    {
      "x": -5,
      "y": 9,
      "z": -4,
      "name": "Rock_Shale"
    },
    {
      "x": -5,
      "y": -6,
      "z": -3,
      "name": "Rock_Shale"
    },
    {
      "x": -5,
      "y": -5,
      "z": -3,
      "name": "Rock_Shale"
    },
    {
      "x": -5,
      "y": -4,
      "z": -3,
      "name": "Rock_Shale"
    },
    {
      "x": -5,
      "y": -3,
      "z": -3,
      "name": "Rock_Shale"
    },
    {
      "x": -5,
      "y": -2,
      "z": -3,
      "name": "Rock_Shale"
    },
    {
      "x": -5,
      "y": -1,
      "z": -3,
      "name": "Rock_Shale"
    },
    {
      "x": -5,
      "y": 0,
      "z": -3,
      "name": "Rock_Basalt_Cobble"
    },
    {
      "x": -5,
      "y": 1,
      "z": -3,
      "name": "Empty"
    },
    {
      "x": -5,
      "y": 2,
      "z": -3,
      "name": "Empty"
    },
    {
      "x": -5,
      "y": 3,
      "z": -3,
      "name": "Empty"
    },
    {
      "x": -5,
      "y": 4,
      "z": -3,
      "name": "Empty"
    },
    {
      "x": -5,
      "y": 5,
      "z": -3,
      "name": "Empty"
    },
    {
      "x": -5,
      "y": 6,
      "z": -3,
      "name": "Empty"
    },
    {
      "x": -5,
      "y": 7,
      "z": -3,
      "name": "Empty"
    },
    {
      "x": -5,
      "y": 8,
      "z": -3,
      "name": "Rock_Shale"
    },
    {
      "x": -5,
      "y": 9,
      "z": -3,
      "name": "Rock_Shale"
    },
    {
      "x": -5,
      "y": 10,
      "z": -3,
      "name": "Rock_Shale"
    },
    {
      "x": -5,
      "y": -6,
      "z": -2,
      "name": "Rock_Shale"
    },
    {
      "x": -5,
      "y": -5,
      "z": -2,
      "name": "Rock_Shale"
    },
    {
      "x": -5,
      "y": -4,
      "z": -2,
      "name": "Rock_Shale"
    },
    {
      "x": -5,
      "y": -3,
      "z": -2,
      "name": "Rock_Shale"
    },
    {
      "x": -5,
      "y": -2,
      "z": -2,
      "name": "Rock_Shale"
    },
    {
      "x": -5,
      "y": -1,
      "z": -2,
      "name": "Rock_Shale"
    },
    {
      "x": -5,
      "y": 0,
      "z": -2,
      "name": "Rock_Basalt_Cobble"
    },
    {
      "x": -5,
      "y": 1,
      "z": -2,
      "name": "Rock_Basalt_Cobble"
    },
    {
      "x": -5,
      "y": 2,
      "z": -2,
      "name": "Rock_Basalt_Cobble"
    },
    {
      "x": -5,
      "y": 3,
      "z": -2,
      "name": "Rock_Basalt_Cobble"
    },
    {
      "x": -5,
      "y": 4,
      "z": -2,
      "name": "Rock_Basalt_Cobble_Half"
    },
    {
      "x": -5,
      "y": 5,
      "z": -2,
      "name": "Empty"
    },
    {
      "x": -5,
      "y": 6,
      "z": -2,
      "name": "Empty"
    },
    {
      "x": -5,
      "y": 7,
      "z": -2,
      "name": "Empty"
    },
    {
      "x": -5,
      "y": 8,
      "z": -2,
      "name": "Empty"
    },
    {
      "x": -5,
      "y": 9,
      "z": -2,
      "name": "Rock_Shale"
    },
    {
      "x": -5,
      "y": 10,
      "z": -2,
      "name": "Rock_Shale"
    },
    {
      "x": -5,
      "y": -6,
      "z": -1,
      "name": "Rock_Shale"
    },
    {
      "x": -5,
      "y": -5,
      "z": -1,
      "name": "Rock_Shale"
    },
    {
      "x": -5,
      "y": -4,
      "z": -1,
      "name": "Rock_Shale"
    },
    {
      "x": -5,
      "y": -3,
      "z": -1,
      "name": "Rock_Shale"
    },
    {
      "x": -5,
      "y": -2,
      "z": -1,
      "name": "Rock_Shale"
    },
    {
      "x": -5,
      "y": -1,
      "z": -1,
      "name": "Rock_Shale"
    },
    {
      "x": -5,
      "y": 0,
      "z": -1,
      "name": "Rock_Basalt_Cobble"
    },
    {
      "x": -5,
      "y": 1,
      "z": -1,
      "name": "Rock_Basalt_Cobble"
    },
    {
      "x": -5,
      "y": 2,
      "z": -1,
      "name": "Rock_Basalt_Cobble"
    },
    {
      "x": -5,
      "y": 3,
      "z": -1,
      "name": "Rock_Basalt_Cobble"
    },
    {
      "x": -5,
      "y": 4,
      "z": -1,
      "name": "Rock_Basalt_Cobble_Half"
    },
    {
      "x": -5,
      "y": 5,
      "z": -1,
      "name": "Empty"
    },
    {
      "x": -5,
      "y": 6,
      "z": -1,
      "name": "Empty"
    },
    {
      "x": -5,
      "y": 7,
      "z": -1,
      "name": "Empty"
    },
    {
      "x": -5,
      "y": 8,
      "z": -1,
      "name": "Empty"
    },
    {
      "x": -5,
      "y": 9,
      "z": -1,
      "name": "Rock_Shale"
    },
    {
      "x": -5,
      "y": 10,
      "z": -1,
      "name": "Rock_Shale"
    },
    {
      "x": -5,
      "y": -6,
      "z": 0,
      "name": "Rock_Shale"
    },
    {
      "x": -5,
      "y": -5,
      "z": 0,
      "name": "Rock_Shale"
    },
    {
      "x": -5,
      "y": -4,
      "z": 0,
      "name": "Rock_Shale"
    },
    {
      "x": -5,
      "y": -3,
      "z": 0,
      "name": "Rock_Shale"
    },
    {
      "x": -5,
      "y": -2,
      "z": 0,
      "name": "Rock_Shale"
    },
    {
      "x": -5,
      "y": -1,
      "z": 0,
      "name": "Rock_Shale"
    },
    {
      "x": -5,
      "y": 0,
      "z": 0,
      "name": "Rock_Shale"
    },
    {
      "x": -5,
      "y": 1,
      "z": 0,
      "name": "Rock_Shale"
    },
    {
      "x": -5,
      "y": 2,
      "z": 0,
      "name": "Rock_Shale"
    },
    {
      "x": -5,
      "y": 3,
      "z": 0,
      "name": "Rock_Shale"
    },
    {
      "x": -5,
      "y": 4,
      "z": 0,
      "name": "Rock_Shale"
    },
    {
      "x": -5,
      "y": 5,
      "z": 0,
      "name": "Rock_Shale"
    },
    {
      "x": -5,
      "y": 6,
      "z": 0,
      "name": "Rock_Shale"
    },
    {
      "x": -5,
      "y": 7,
      "z": 0,
      "name": "Rock_Shale"
    },
    {
      "x": -5,
      "y": 8,
      "z": 0,
      "name": "Rock_Shale"
    },
    {
      "x": -5,
      "y": 9,
      "z": 0,
      "name": "Rock_Shale"
    },
    {
      "x": -5,
      "y": 10,
      "z": 0,
      "name": "Rock_Shale"
    },
    {
      "x": -4,
      "y": -6,
      "z": -16,
      "name": "Rock_Shale"
    },
    {
      "x": -4,
      "y": -5,
      "z": -16,
      "name": "Rock_Shale"
    },
    {
      "x": -4,
      "y": -4,
      "z": -16,
      "name": "Rock_Shale"
    },
    {
      "x": -4,
      "y": -3,
      "z": -16,
      "name": "Rock_Shale"
    },
    {
      "x": -4,
      "y": -2,
      "z": -16,
      "name": "Rock_Shale"
    },
    {
      "x": -4,
      "y": -1,
      "z": -16,
      "name": "Rock_Shale"
    },
    {
      "x": -4,
      "y": 0,
      "z": -16,
      "name": "Rock_Shale"
    },
    {
      "x": -4,
      "y": 1,
      "z": -16,
      "name": "Rock_Shale"
    },
    {
      "x": -4,
      "y": 2,
      "z": -16,
      "name": "Rock_Shale"
    },
    {
      "x": -4,
      "y": 3,
      "z": -16,
      "name": "Rock_Shale"
    },
    {
      "x": -4,
      "y": 4,
      "z": -16,
      "name": "Rock_Shale"
    },
    {
      "x": -4,
      "y": 5,
      "z": -16,
      "name": "Rock_Shale"
    },
    {
      "x": -4,
      "y": 6,
      "z": -16,
      "name": "Rock_Shale"
    },
    {
      "x": -4,
      "y": 7,
      "z": -16,
      "name": "Rock_Shale"
    },
    {
      "x": -4,
      "y": 8,
      "z": -16,
      "name": "Rock_Shale"
    },
    {
      "x": -4,
      "y": -6,
      "z": -15,
      "name": "Rock_Shale"
    },
    {
      "x": -4,
      "y": -5,
      "z": -15,
      "name": "Rock_Shale"
    },
    {
      "x": -4,
      "y": -4,
      "z": -15,
      "name": "Rock_Shale"
    },
    {
      "x": -4,
      "y": -3,
      "z": -15,
      "name": "Rock_Shale"
    },
    {
      "x": -4,
      "y": -2,
      "z": -15,
      "name": "Rock_Shale"
    },
    {
      "x": -4,
      "y": -1,
      "z": -15,
      "name": "Rock_Shale"
    },
    {
      "x": -4,
      "y": 0,
      "z": -15,
      "name": "Rock_Shale"
    },
    {
      "x": -4,
      "y": 1,
      "z": -15,
      "name": "Rock_Shale"
    },
    {
      "x": -4,
      "y": 2,
      "z": -15,
      "name": "Rock_Shale"
    },
    {
      "x": -4,
      "y": 3,
      "z": -15,
      "name": "Rock_Shale"
    },
    {
      "x": -4,
      "y": 4,
      "z": -15,
      "name": "Rock_Shale"
    },
    {
      "x": -4,
      "y": 5,
      "z": -15,
      "name": "Rock_Shale"
    },
    {
      "x": -4,
      "y": 6,
      "z": -15,
      "name": "Rock_Shale"
    },
    {
      "x": -4,
      "y": 7,
      "z": -15,
      "name": "Rock_Shale"
    },
    {
      "x": -4,
      "y": 8,
      "z": -15,
      "name": "Rock_Shale"
    },
    {
      "x": -4,
      "y": -6,
      "z": -14,
      "name": "Rock_Shale"
    },
    {
      "x": -4,
      "y": -5,
      "z": -14,
      "name": "Rock_Shale"
    },
    {
      "x": -4,
      "y": -4,
      "z": -14,
      "name": "Rock_Shale"
    },
    {
      "x": -4,
      "y": -3,
      "z": -14,
      "name": "Rock_Shale"
    },
    {
      "x": -4,
      "y": -2,
      "z": -14,
      "name": "Rock_Shale"
    },
    {
      "x": -4,
      "y": -1,
      "z": -14,
      "name": "Rock_Shale"
    },
    {
      "x": -4,
      "y": 0,
      "z": -14,
      "name": "Rock_Shale"
    },
    {
      "x": -4,
      "y": 1,
      "z": -14,
      "name": "Rock_Shale"
    },
    {
      "x": -4,
      "y": 2,
      "z": -14,
      "name": "Rock_Shale"
    },
    {
      "x": -4,
      "y": 3,
      "z": -14,
      "name": "Rock_Shale"
    },
    {
      "x": -4,
      "y": 4,
      "z": -14,
      "name": "Rock_Shale"
    },
    {
      "x": -4,
      "y": 5,
      "z": -14,
      "name": "Rock_Shale"
    },
    {
      "x": -4,
      "y": 6,
      "z": -14,
      "name": "Rock_Shale"
    },
    {
      "x": -4,
      "y": 7,
      "z": -14,
      "name": "Rock_Shale"
    },
    {
      "x": -4,
      "y": 8,
      "z": -14,
      "name": "Rock_Shale"
    },
    {
      "x": -4,
      "y": 9,
      "z": -14,
      "name": "Empty"
    },
    {
      "x": -4,
      "y": 10,
      "z": -14,
      "name": "Empty"
    },
    {
      "x": -4,
      "y": -6,
      "z": -13,
      "name": "Rock_Shale"
    },
    {
      "x": -4,
      "y": -5,
      "z": -13,
      "name": "Rock_Shale"
    },
    {
      "x": -4,
      "y": -4,
      "z": -13,
      "name": "Rock_Shale"
    },
    {
      "x": -4,
      "y": -3,
      "z": -13,
      "name": "Rock_Shale"
    },
    {
      "x": -4,
      "y": -2,
      "z": -13,
      "name": "Rock_Shale"
    },
    {
      "x": -4,
      "y": -1,
      "z": -13,
      "name": "Rock_Shale"
    },
    {
      "x": -4,
      "y": 0,
      "z": -13,
      "name": "Rock_Shale"
    },
    {
      "x": -4,
      "y": 1,
      "z": -13,
      "name": "Empty"
    },
    {
      "x": -4,
      "y": 2,
      "z": -13,
      "name": "Empty"
    },
    {
      "x": -4,
      "y": 3,
      "z": -13,
      "name": "Empty"
    },
    {
      "x": -4,
      "y": 4,
      "z": -13,
      "name": "Empty"
    },
    {
      "x": -4,
      "y": 5,
      "z": -13,
      "name": "Empty"
    },
    {
      "x": -4,
      "y": 6,
      "z": -13,
      "name": "Empty"
    },
    {
      "x": -4,
      "y": 7,
      "z": -13,
      "name": "Rock_Shale"
    },
    {
      "x": -4,
      "y": 8,
      "z": -13,
      "name": "Rock_Shale"
    },
    {
      "x": -4,
      "y": 9,
      "z": -13,
      "name": "Rock_Shale"
    },
    {
      "x": -4,
      "y": 10,
      "z": -13,
      "name": "Rock_Shale"
    },
    {
      "x": -4,
      "y": 11,
      "z": -13,
      "name": "Rock_Shale"
    },
    {
      "x": -4,
      "y": -6,
      "z": -12,
      "name": "Rock_Shale"
    },
    {
      "x": -4,
      "y": -5,
      "z": -12,
      "name": "Rock_Shale"
    },
    {
      "x": -4,
      "y": -4,
      "z": -12,
