{
  "version": 8,
  "blockIdVersion": 8,
  "anchorX": 0,
  "anchorY": 10,
  "anchorZ": 5,
  "blocks": [
    {
      "x": -9,
      "y": 7,
      "z": -2,
      "name": "Rock_Stone"
    },
    {
      "x": -9,
      "y": 8,
      "z": -2,
      "name": "Rock_Stone"
    },
    {
      "x": -9,
      "y": 9,
      "z": -2,
      "name": "Rock_Stone"
    },
    {
      "x": -9,
      "y": 6,
      "z": -1,
      "name": "Rock_Stone"
    },
    {
      "x": -9,
      "y": 7,
      "z": -1,
      "name": "Rock_Stone"
    },
    {
      "x": -9,
      "y": 8,
      "z": -1,
      "name": "Rock_Stone"
    },
    {
      "x": -9,
      "y": 9,
      "z": -1,
      "name": "Rock_Stone"
    },
    {
      "x": -9,
      "y": 10,
      "z": -1,
      "name": "Rock_Stone"
    },
    {
      "x": -9,
      "y": 11,
      "z": -1,
      "name": "Rock_Stone"
    },
    {
      "x": -9,
      "y": 7,
      "z": 0,
      "name": "Rock_Stone"
    },
    {
      "x": -9,
      "y": 8,
      "z": 0,
      "name": "Rock_Stone"
    },
    {
      "x": -9,
      "y": 9,
      "z": 0,
      "name": "Rock_Stone"
    },
    {
      "x": -9,
      "y": 10,
      "z": 0,
      "name": "Rock_Stone"
    },
    {
      "x": -9,
      "y": 11,
      "z": 0,
      "name": "Rock_Stone"
    },
    {
      "x": -9,
      "y": 7,
      "z": 1,
      "name": "Rock_Stone"
    },
    {
      "x": -9,
      "y": 8,
      "z": 1,
      "name": "Rock_Stone"
    },
    {
      "x": -9,
      "y": 9,
      "z": 1,
      "name": "Rock_Stone"
    },
    {
      "x": -8,
      "y": 7,
      "z": -3,
      "name": "Rock_Stone"
    },
    {
      "x": -8,
      "y": 8,
      "z": -3,
      "name": "Rock_Stone"
    },
    {
      "x": -8,
      "y": 9,
      "z": -3,
      "name": "Rock_Stone"
    },
    {
      "x": -8,
      "y": 10,
      "z": -3,
      "name": "Rock_Stone"
    },
    {
      "x": -8,
      "y": 6,
      "z": -2,
      "name": "Rock_Stone"
    },
    {
      "x": -8,
      "y": 7,
      "z": -2,
      "name": "Rock_Stone"
    },
    {
      "x": -8,
      "y": 8,
      "z": -2,
      "name": "Rock_Stone"
    },
    {
      "x": -8,
      "y": 9,
      "z": -2,
      "name": "Rock_Stone"
    },
    {
      "x": -8,
      "y": 10,
      "z": -2,
      "name": "Rock_Stone"
    },
    {
      "x": -8,
      "y": 11,
      "z": -2,
      "name": "Rock_Stone"
    },
    {
      "x": -8,
      "y": 12,
      "z": -2,
      "name": "Rock_Stone"
    },
    {
      "x": -8,
      "y": 13,
      "z": -2,
      "name": "Rock_Stone"
    },
    {
      "x": -8,
      "y": 5,
      "z": -1,
      "name": "Rock_Stone"
    },
    {
      "x": -8,
      "y": 6,
      "z": -1,
      "name": "Rock_Stone"
    },
    {
      "x": -8,
      "y": 7,
      "z": -1,
      "name": "Rock_Stone"
    },
    {
      "x": -8,
      "y": 8,
      "z": -1,
      "name": "Rock_Stone"
    },
    {
      "x": -8,
      "y": 9,
      "z": -1,
      "name": "Rock_Stone"
    },
    {
      "x": -8,
      "y": 10,
      "z": -1,
      "name": "Rock_Stone"
    },
    {
      "x": -8,
      "y": 11,
      "z": -1,
      "name": "Rock_Stone"
    },
    {
      "x": -8,
      "y": 12,
      "z": -1,
      "name": "Rock_Stone"
    },
    {
      "x": -8,
      "y": 13,
      "z": -1,
      "name": "Rock_Stone"
    },
    {
      "x": -8,
      "y": 14,
      "z": -1,
      "name": "Rock_Stone"
    },
    {
      "x": -8,
      "y": 5,
      "z": 0,
      "name": "Rock_Stone"
    },
    {
      "x": -8,
      "y": 6,
      "z": 0,
      "name": "Rock_Stone"
    },
    {
      "x": -8,
      "y": 7,
      "z": 0,
      "name": "Rock_Stone"
    },
    {
      "x": -8,
      "y": 8,
      "z": 0,
      "name": "Rock_Stone"
    },
    {
      "x": -8,
      "y": 9,
      "z": 0,
      "name": "Rock_Stone"
    },
    {
      "x": -8,
      "y": 10,
      "z": 0,
      "name": "Rock_Stone"
    },
    {
      "x": -8,
      "y": 11,
      "z": 0,
      "name": "Rock_Stone"
    },
    {
      "x": -8,
      "y": 12,
      "z": 0,
      "name": "Rock_Stone"
    },
    {
      "x": -8,
      "y": 13,
      "z": 0,
      "name": "Rock_Stone"
    },
    {
      "x": -8,
      "y": 14,
      "z": 0,
      "name": "Soil_Dirt"
    },
    {
      "x": -8,
      "y": 15,
      "z": 0,
      "name": "Soil_Grass"
    },
    {
      "x": -8,
      "y": 5,
      "z": 1,
      "name": "Rock_Stone"
    },
    {
      "x": -8,
      "y": 6,
      "z": 1,
      "name": "Rock_Stone"
    },
    {
      "x": -8,
      "y": 7,
      "z": 1,
      "name": "Rock_Stone"
    },
    {
      "x": -8,
      "y": 8,
      "z": 1,
      "name": "Rock_Stone"
    },
    {
      "x": -8,
      "y": 9,
      "z": 1,
      "name": "Rock_Stone"
    },
    {
      "x": -8,
      "y": 10,
      "z": 1,
      "name": "Rock_Stone"
    },
    {
      "x": -8,
      "y": 11,
      "z": 1,
      "name": "Rock_Stone"
    },
    {
      "x": -8,
      "y": 12,
      "z": 1,
      "name": "Rock_Stone"
    },
    {
      "x": -8,
      "y": 13,
      "z": 1,
      "name": "Rock_Stone_Mossy"
    },
    {
      "x": -8,
      "y": 14,
      "z": 1,
      "name": "Rock_Stone_Mossy"
    },
    {
      "x": -8,
      "y": 15,
      "z": 1,
      "name": "Soil_Grass"
    },
    {
      "x": -8,
      "y": 16,
      "z": 1,
      "name": "Plant_Grass_Sharp_Short"
    },
    {
      "x": -8,
      "y": 6,
      "z": 2,
      "name": "Rock_Stone"
    },
    {
      "x": -8,
      "y": 7,
      "z": 2,
      "name": "Rock_Stone"
    },
    {
      "x": -8,
      "y": 8,
      "z": 2,
      "name": "Rock_Stone"
    },
    {
      "x": -8,
      "y": 9,
      "z": 2,
      "name": "Rock_Stone"
    },
    {
      "x": -8,
      "y": 10,
      "z": 2,
      "name": "Rock_Stone"
    },
    {
      "x": -8,
      "y": 11,
      "z": 2,
      "name": "Rock_Stone"
    },
    {
      "x": -8,
      "y": 12,
      "z": 2,
      "name": "Rock_Stone_Mossy"
    },
    {
      "x": -8,
      "y": 13,
      "z": 2,
      "name": "Rock_Stone_Mossy"
    },
    {
      "x": -8,
      "y": 14,
      "z": 2,
      "name": "Rock_Stone_Mossy"
    },
    {
      "x": -8,
      "y": 8,
      "z": 3,
      "name": "Rock_Stone"
    },
    {
      "x": -8,
      "y": 9,
      "z": 3,
      "name": "Rock_Stone"
    },
    {
      "x": -8,
      "y": 10,
      "z": 3,
      "name": "Rock_Stone"
    },
    {
      "x": -8,
      "y": 11,
      "z": 3,
      "name": "Rock_Stone_Mossy"
    },
    {
      "x": -8,
      "y": 12,
      "z": 3,
      "name": "Rock_Stone_Mossy"
    },
    {
      "x": -7,
      "y": 9,
      "z": -4,
      "name": "Rock_Stone"
    },
    {
      "x": -7,
      "y": 10,
      "z": -4,
      "name": "Rock_Stone"
    },
    {
      "x": -7,
      "y": 5,
      "z": -3,
      "name": "Rock_Stone"
    },
    {
      "x": -7,
      "y": 6,
      "z": -3,
      "name": "Rock_Stone"
    },
    {
      "x": -7,
      "y": 7,
      "z": -3,
      "name": "Rock_Stone"
    },
    {
      "x": -7,
      "y": 8,
      "z": -3,
      "name": "Rock_Stone"
    },
    {
      "x": -7,
      "y": 9,
      "z": -3,
      "name": "Rock_Stone"
    },
    {
      "x": -7,
      "y": 10,
      "z": -3,
      "name": "Rock_Stone"
    },
    {
      "x": -7,
      "y": 11,
      "z": -3,
      "name": "Rock_Stone"
    },
    {
      "x": -7,
      "y": 12,
      "z": -3,
      "name": "Rock_Stone"
    },
    {
      "x": -7,
      "y": 4,
      "z": -2,
      "name": "Rock_Stone"
    },
    {
      "x": -7,
      "y": 5,
      "z": -2,
      "name": "Rock_Stone"
    },
    {
      "x": -7,
      "y": 6,
      "z": -2,
      "name": "Rock_Stone"
    },
    {
      "x": -7,
      "y": 7,
      "z": -2,
      "name": "Rock_Stone"
    },
    {
      "x": -7,
      "y": 8,
      "z": -2,
      "name": "Rock_Stone"
    },
    {
      "x": -7,
      "y": 9,
      "z": -2,
      "name": "Rock_Stone"
    },
    {
      "x": -7,
      "y": 10,
      "z": -2,
      "name": "Rock_Stone"
    },
    {
      "x": -7,
      "y": 11,
      "z": -2,
      "name": "Rock_Stone"
    },
    {
      "x": -7,
      "y": 12,
      "z": -2,
      "name": "Rock_Stone"
    },
    {
      "x": -7,
      "y": 13,
      "z": -2,
      "name": "Rock_Stone"
    },
    {
      "x": -7,
      "y": 14,
      "z": -2,
      "name": "Rock_Stone"
    },
    {
      "x": -7,
      "y": 15,
      "z": -2,
      "name": "Soil_Grass"
    },
    {
      "x": -7,
      "y": 3,
      "z": -1,
      "name": "Rock_Stone"
    },
    {
      "x": -7,
      "y": 4,
      "z": -1,
      "name": "Rock_Stone"
    },
    {
      "x": -7,
      "y": 5,
      "z": -1,
      "name": "Rock_Stone"
    },
    {
      "x": -7,
      "y": 6,
      "z": -1,
      "name": "Rock_Stone"
    },
    {
      "x": -7,
      "y": 7,
      "z": -1,
      "name": "Rock_Stone"
    },
    {
      "x": -7,
      "y": 8,
      "z": -1,
      "name": "Rock_Stone"
    },
    {
      "x": -7,
      "y": 9,
      "z": -1,
      "name": "Rock_Stone"
    },
    {
      "x": -7,
      "y": 10,
      "z": -1,
      "name": "Rock_Stone"
    },
    {
      "x": -7,
      "y": 11,
      "z": -1,
      "name": "Rock_Stone"
    },
    {
      "x": -7,
      "y": 12,
      "z": -1,
      "name": "Rock_Stone"
    },
    {
      "x": -7,
      "y": 13,
      "z": -1,
      "name": "Rock_Stone"
    },
    {
      "x": -7,
      "y": 14,
      "z": -1,
      "name": "Soil_Dirt"
    },
    {
      "x": -7,
      "y": 15,
      "z": -1,
      "name": "Soil_Dirt"
    },
    {
      "x": -7,
      "y": 16,
      "z": -1,
      "name": "Soil_Grass"
    },
    {
      "x": -7,
      "y": 3,
      "z": 0,
      "name": "Rock_Stone"
    },
    {
      "x": -7,
      "y": 4,
      "z": 0,
      "name": "Rock_Stone"
    },
    {
      "x": -7,
      "y": 5,
      "z": 0,
      "name": "Rock_Stone"
    },
    {
      "x": -7,
      "y": 6,
      "z": 0,
      "name": "Rock_Stone"
    },
    {
      "x": -7,
      "y": 7,
      "z": 0,
      "name": "Rock_Stone"
    },
    {
      "x": -7,
      "y": 8,
      "z": 0,
      "name": "Rock_Stone"
    },
    {
      "x": -7,
      "y": 9,
      "z": 0,
      "name": "Rock_Stone"
    },
    {
      "x": -7,
      "y": 10,
      "z": 0,
      "name": "Rock_Stone"
    },
    {
      "x": -7,
      "y": 11,
      "z": 0,
      "name": "Rock_Stone"
    },
    {
      "x": -7,
      "y": 12,
      "z": 0,
      "name": "Rock_Stone"
    },
    {
      "x": -7,
      "y": 13,
      "z": 0,
      "name": "Rock_Stone"
    },
    {
      "x": -7,
      "y": 14,
      "z": 0,
      "name": "Soil_Dirt"
    },
    {
      "x": -7,
      "y": 15,
      "z": 0,
      "name": "Soil_Dirt"
    },
    {
      "x": -7,
      "y": 16,
      "z": 0,
      "name": "Soil_Grass"
    },
    {
      "x": -7,
      "y": 4,
      "z": 1,
      "name": "Rock_Stone"
    },
    {
      "x": -7,
      "y": 5,
      "z": 1,
      "name": "Rock_Stone"
    },
    {
      "x": -7,
      "y": 6,
      "z": 1,
      "name": "Rock_Stone"
    },
    {
      "x": -7,
      "y": 7,
      "z": 1,
      "name": "Rock_Stone"
    },
    {
      "x": -7,
      "y": 8,
      "z": 1,
      "name": "Rock_Stone"
    },
    {
      "x": -7,
      "y": 9,
      "z": 1,
      "name": "Rock_Stone"
    },
    {
      "x": -7,
      "y": 10,
      "z": 1,
      "name": "Rock_Stone"
    },
    {
      "x": -7,
      "y": 11,
      "z": 1,
      "name": "Rock_Stone"
    },
    {
      "x": -7,
      "y": 12,
      "z": 1,
      "name": "Rock_Stone"
    },
    {
      "x": -7,
      "y": 13,
      "z": 1,
      "name": "Rock_Stone"
    },
    {
      "x": -7,
      "y": 14,
      "z": 1,
      "name": "Soil_Dirt"
    },
    {
      "x": -7,
      "y": 15,
      "z": 1,
      "name": "Soil_Dirt"
    },
    {
      "x": -7,
      "y": 16,
      "z": 1,
      "name": "Soil_Grass"
    },
    {
      "x": -7,
      "y": 4,
      "z": 2,
      "name": "Rock_Stone"
    },
    {
      "x": -7,
      "y": 5,
      "z": 2,
      "name": "Rock_Stone"
    },
    {
      "x": -7,
      "y": 6,
      "z": 2,
      "name": "Rock_Stone"
    },
    {
      "x": -7,
      "y": 7,
      "z": 2,
      "name": "Rock_Stone"
    },
    {
      "x": -7,
      "y": 8,
      "z": 2,
      "name": "Rock_Stone"
    },
    {
      "x": -7,
      "y": 9,
      "z": 2,
      "name": "Rock_Stone"
    },
    {
      "x": -7,
      "y": 10,
      "z": 2,
      "name": "Rock_Stone"
    },
    {
      "x": -7,
      "y": 11,
      "z": 2,
      "name": "Rock_Stone"
    },
    {
      "x": -7,
      "y": 12,
      "z": 2,
      "name": "Rock_Stone"
    },
    {
      "x": -7,
      "y": 13,
      "z": 2,
      "name": "Rock_Stone_Mossy"
    },
    {
      "x": -7,
      "y": 14,
      "z": 2,
      "name": "Rock_Stone_Mossy"
    },
    {
      "x": -7,
      "y": 15,
      "z": 2,
      "name": "Soil_Grass"
    },
    {
      "x": -7,
      "y": 5,
      "z": 3,
      "name": "Rock_Stone"
    },
    {
      "x": -7,
      "y": 6,
      "z": 3,
      "name": "Rock_Stone"
    },
    {
      "x": -7,
      "y": 7,
      "z": 3,
      "name": "Rock_Stone"
    },
    {
      "x": -7,
      "y": 8,
      "z": 3,
      "name": "Rock_Stone"
    },
    {
      "x": -7,
      "y": 9,
      "z": 3,
      "name": "Rock_Stone"
    },
    {
      "x": -7,
      "y": 10,
      "z": 3,
      "name": "Rock_Stone"
    },
    {
      "x": -7,
      "y": 11,
      "z": 3,
      "name": "Rock_Stone"
    },
    {
      "x": -7,
      "y": 12,
      "z": 3,
      "name": "Rock_Stone_Mossy"
    },
    {
      "x": -7,
      "y": 13,
      "z": 3,
      "name": "Rock_Stone_Mossy"
    },
    {
      "x": -7,
      "y": 14,
      "z": 3,
      "name": "Rock_Stone_Mossy"
    },
    {
      "x": -7,
      "y": 15,
      "z": 3,
      "name": "Rock_Stone_Mossy"
    },
    {
      "x": -7,
      "y": 2,
      "z": 4,
      "name": "Rock_Stone"
    },
    {
      "x": -7,
      "y": 3,
      "z": 4,
      "name": "Rock_Stone"
    },
    {
      "x": -7,
      "y": 7,
      "z": 4,
      "name": "Rock_Stone"
    },
    {
      "x": -7,
      "y": 8,
      "z": 4,
      "name": "Rock_Stone"
    },
    {
      "x": -7,
      "y": 9,
      "z": 4,
      "name": "Rock_Stone"
    },
    {
      "x": -7,
      "y": 10,
      "z": 4,
      "name": "Rock_Stone"
    },
    {
      "x": -7,
      "y": 11,
      "z": 4,
      "name": "Rock_Stone"
    },
    {
      "x": -7,
      "y": 12,
      "z": 4,
      "name": "Rock_Stone_Mossy"
    },
    {
      "x": -7,
      "y": 13,
      "z": 4,
      "name": "Rock_Stone_Mossy"
    },
    {
      "x": -7,
      "y": 14,
      "z": 4,
      "name": "Rock_Stone_Mossy"
    },
    {
      "x": -7,
      "y": 2,
      "z": 5,
      "name": "Rock_Stone"
    },
    {
      "x": -7,
      "y": 3,
      "z": 5,
      "name": "Rock_Stone"
    },
    {
      "x": -7,
      "y": 4,
      "z": 5,
      "name": "Rock_Stone"
    },
    {
      "x": -7,
      "y": 5,
      "z": 5,
      "name": "Rock_Stone"
    },
    {
      "x": -7,
      "y": 1,
      "z": 6,
      "name": "Rock_Stone"
    },
    {
      "x": -7,
      "y": 2,
      "z": 6,
      "name": "Rock_Stone"
    },
    {
      "x": -7,
      "y": 3,
      "z": 6,
      "name": "Rock_Stone"
    },
    {
      "x": -7,
      "y": 4,
      "z": 6,
      "name": "Rock_Stone"
    },
    {
      "x": -7,
      "y": 5,
      "z": 6,
      "name": "Rock_Stone"
    },
    {
      "x": -7,
      "y": 6,
      "z": 6,
      "name": "Rock_Stone"
    },
    {
      "x": -7,
      "y": 2,
      "z": 7,
      "name": "Rock_Stone"
    },
    {
      "x": -7,
      "y": 3,
      "z": 7,
      "name": "Rock_Stone"
    },
    {
      "x": -7,
      "y": 4,
      "z": 7,
      "name": "Rock_Stone"
    },
    {
      "x": -7,
      "y": 3,
      "z": 8,
      "name": "Rock_Stone"
    },
    {
      "x": -6,
      "y": 9,
      "z": -4,
      "name": "Rock_Stone"
    },
    {
      "x": -6,
      "y": 10,
      "z": -4,
      "name": "Rock_Stone"
    },
    {
      "x": -6,
      "y": 11,
      "z": -4,
      "name": "Rock_Stone"
    },
    {
      "x": -6,
      "y": 12,
      "z": -4,
      "name": "Rock_Stone"
    },
    {
      "x": -6,
      "y": 13,
      "z": -4,
      "name": "Rock_Stone_Mossy"
    },
    {
      "x": -6,
      "y": 5,
      "z": -3,
      "name": "Rock_Stone"
    },
    {
      "x": -6,
      "y": 6,
      "z": -3,
      "name": "Rock_Stone"
    },
    {
      "x": -6,
      "y": 7,
      "z": -3,
      "name": "Rock_Crystal_Green_Small",
      "components": {
        "Components": {
          "FarmingBlock": {}
        }
      },
      "rotation": 7
    },
    {
      "x": -6,
      "y": 8,
      "z": -3,
      "name": "Rock_Crystal_Green_Medium",
      "components": {
        "Components": {
          "FarmingBlock": {}
        }
      },
      "rotation": 8
    },
    {
      "x": -6,
      "y": 9,
      "z": -3,
      "name": "Rock_Stone"
    },
    {
      "x": -6,
      "y": 10,
      "z": -3,
      "name": "Rock_Stone"
    },
    {
      "x": -6,
      "y": 11,
      "z": -3,
      "name": "Rock_Stone"
    },
    {
      "x": -6,
      "y": 12,
      "z": -3,
      "name": "Rock_Stone_Mossy"
    },
    {
      "x": -6,
      "y": 13,
      "z": -3,
      "name": "Rock_Stone_Mossy"
    },
    {
      "x": -6,
      "y": 14,
      "z": -3,
      "name": "Rock_Stone_Mossy"
    },
    {
      "x": -6,
      "y": 15,
      "z": -3,
      "name": "Rock_Stone"
    },
    {
      "x": -6,
      "y": 16,
      "z": -3,
      "name": "Plant_Moss_Rug_Green"
    },
    {
      "x": -6,
      "y": 2,
      "z": -2,
      "name": "Rock_Stone"
    },
    {
      "x": -6,
      "y": 3,
      "z": -2,
      "name": "Rock_Stone"
    },
    {
      "x": -6,
      "y": 4,
      "z": -2,
      "name": "Rock_Stone"
    },
    {
      "x": -6,
      "y": 5,
      "z": -2,
      "name": "Rock_Stone"
    },
    {
      "x": -6,
      "y": 6,
      "z": -2,
      "name": "Rock_Stone"
    },
    {
      "x": -6,
      "y": 7,
      "z": -2,
      "name": "Rock_Stone"
    },
    {
      "x": -6,
      "y": 8,
      "z": -2,
      "name": "Rock_Stone"
    },
    {
      "x": -6,
      "y": 9,
      "z": -2,
      "name": "Rock_Stone"
    },
    {
      "x": -6,
      "y": 10,
      "z": -2,
      "name": "Rock_Stone"
    },
    {
      "x": -6,
      "y": 11,
      "z": -2,
      "name": "Rock_Stone"
    },
    {
      "x": -6,
      "y": 12,
      "z": -2,
      "name": "Rock_Stone"
    },
    {
      "x": -6,
      "y": 13,
      "z": -2,
      "name": "Rock_Stone_Mossy"
    },
    {
      "x": -6,
      "y": 14,
      "z": -2,
      "name": "Rock_Stone"
    },
    {
      "x": -6,
      "y": 15,
      "z": -2,
      "name": "Rock_Stone"
    },
    {
      "x": -6,
      "y": 16,
      "z": -2,
      "name": "Soil_Grass"
    },
    {
      "x": -6,
      "y": 2,
      "z": -1,
      "name": "Rock_Stone"
    },
    {
      "x": -6,
      "y": 3,
      "z": -1,
      "name": "Rock_Stone"
    },
    {
      "x": -6,
      "y": 4,
      "z": -1,
      "name": "Rock_Stone"
    },
    {
      "x": -6,
      "y": 5,
      "z": -1,
      "name": "Rock_Stone"
    },
    {
      "x": -6,
      "y": 6,
      "z": -1,
      "name": "Rock_Stone"
    },
    {
      "x": -6,
      "y": 7,
      "z": -1,
      "name": "Rock_Stone"
    },
    {
      "x": -6,
      "y": 8,
      "z": -1,
      "name": "Rock_Stone"
    },
    {
      "x": -6,
      "y": 9,
      "z": -1,
      "name": "Rock_Stone"
    },
    {
      "x": -6,
      "y": 10,
      "z": -1,
      "name": "Rock_Stone"
    },
    {
      "x": -6,
      "y": 11,
      "z": -1,
      "name": "Rock_Stone"
    },
    {
      "x": -6,
      "y": 12,
      "z": -1,
      "name": "Rock_Stone"
    },
    {
      "x": -6,
      "y": 13,
      "z": -1,
      "name": "Rock_Stone"
    },
    {
      "x": -6,
      "y": 14,
      "z": -1,
      "name": "Rock_Stone"
    },
    {
      "x": -6,
      "y": 15,
      "z": -1,
      "name": "Soil_Dirt"
    },
    {
      "x": -6,
      "y": 16,
      "z": -1,
      "name": "Soil_Grass"
    },
    {
      "x": -6,
      "y": 2,
      "z": 0,
      "name": "Rock_Stone"
    },
    {
      "x": -6,
      "y": 3,
      "z": 0,
      "name": "Rock_Stone"
    },
    {
      "x": -6,
      "y": 4,
      "z": 0,
      "name": "Rock_Stone"
    },
    {
      "x": -6,
      "y": 5,
      "z": 0,
      "name": "Rock_Stone"
    },
    {
      "x": -6,
      "y": 6,
      "z": 0,
      "name": "Rock_Stone"
    },
    {
      "x": -6,
      "y": 7,
      "z": 0,
      "name": "Rock_Stone"
    },
    {
      "x": -6,
      "y": 8,
      "z": 0,
      "name": "Rock_Stone"
    },
    {
      "x": -6,
      "y": 9,
      "z": 0,
      "name": "Rock_Stone"
    },
    {
      "x": -6,
      "y": 10,
      "z": 0,
      "name": "Rock_Stone"
    },
    {
      "x": -6,
      "y": 11,
      "z": 0,
      "name": "Rock_Stone"
    },
    {
      "x": -6,
      "y": 12,
      "z": 0,
      "name": "Rock_Stone"
    },
    {
      "x": -6,
      "y": 13,
      "z": 0,
      "name": "Rock_Stone"
    },
    {
      "x": -6,
      "y": 14,
      "z": 0,
      "name": "Soil_Dirt"
    },
    {
      "x": -6,
      "y": 15,
      "z": 0,
      "name": "Soil_Dirt"
    },
    {
      "x": -6,
      "y": 16,
      "z": 0,
      "name": "Soil_Grass"
    },
    {
      "x": -6,
      "y": 17,
      "z": 0,
      "name": "Plant_Grass_Sharp"
    },
    {
      "x": -6,
      "y": 2,
      "z": 1,
      "name": "Rock_Stone"
    },
    {
      "x": -6,
      "y": 3,
      "z": 1,
      "name": "Rock_Stone"
    },
    {
      "x": -6,
      "y": 4,
      "z": 1,
      "name": "Rock_Stone"
    },
    {
      "x": -6,
      "y": 5,
      "z": 1,
      "name": "Rock_Stone"
    },
    {
      "x": -6,
      "y": 6,
      "z": 1,
      "name": "Rock_Stone"
    },
    {
      "x": -6,
      "y": 7,
      "z": 1,
      "name": "Rock_Stone"
    },
    {
      "x": -6,
      "y": 8,
      "z": 1,
      "name": "Rock_Stone"
    },
    {
      "x": -6,
      "y": 9,
      "z": 1,
      "name": "Rock_Stone"
    },
    {
      "x": -6,
      "y": 10,
      "z": 1,
      "name": "Rock_Stone"
    },
    {
      "x": -6,
      "y": 11,
      "z": 1,
      "name": "Rock_Stone"
    },
    {
      "x": -6,
      "y": 12,
      "z": 1,
      "name": "Rock_Stone"
    },
    {
      "x": -6,
      "y": 13,
      "z": 1,
      "name": "Rock_Stone"
    },
    {
      "x": -6,
      "y": 14,
      "z": 1,
      "name": "Rock_Stone"
    },
    {
      "x": -6,
      "y": 15,
      "z": 1,
      "name": "Soil_Dirt"
    },
    {
      "x": -6,
      "y": 16,
      "z": 1,
      "name": "Soil_Grass"
    },
    {
      "x": -6,
      "y": 17,
      "z": 1,
      "name": "Plant_Flower_Common_Yellow2"
    },
    {
      "x": -6,
      "y": 2,
      "z": 2,
      "name": "Rock_Stone"
    },
    {
      "x": -6,
      "y": 3,
      "z": 2,
      "name": "Rock_Stone"
    },
    {
      "x": -6,
      "y": 4,
      "z": 2,
      "name": "Rock_Stone"
    },
    {
      "x": -6,
      "y": 5,
      "z": 2,
      "name": "Rock_Stone"
    },
    {
      "x": -6,
      "y": 6,
      "z": 2,
      "name": "Rock_Stone"
    },
    {
      "x": -6,
      "y": 7,
      "z": 2,
      "name": "Rock_Stone"
    },
    {
      "x": -6,
      "y": 8,
      "z": 2,
      "name": "Rock_Stone"
    },
    {
      "x": -6,
      "y": 9,
      "z": 2,
      "name": "Rock_Stone"
    },
    {
      "x": -6,
      "y": 10,
      "z": 2,
      "name": "Rock_Stone"
    },
    {
      "x": -6,
      "y": 11,
      "z": 2,
      "name": "Rock_Stone"
    },
    {
      "x": -6,
      "y": 12,
      "z": 2,
      "name": "Rock_Stone"
    },
    {
      "x": -6,
      "y": 13,
      "z": 2,
      "name": "Rock_Stone"
    },
    {
      "x": -6,
      "y": 14,
      "z": 2,
      "name": "Rock_Stone"
    },
    {
      "x": -6,
      "y": 15,
      "z": 2,
      "name": "Rock_Stone"
    },
    {
      "x": -6,
      "y": 16,
      "z": 2,
      "name": "Soil_Grass"
    },
    {
      "x": -6,
      "y": 17,
      "z": 2,
      "name": "Plant_Grass_Sharp_Short"
    },
    {
      "x": -6,
      "y": 2,
      "z": 3,
      "name": "Rock_Stone"
    },
    {
      "x": -6,
      "y": 3,
      "z": 3,
      "name": "Rock_Stone"
    },
    {
      "x": -6,
      "y": 4,
      "z": 3,
      "name": "Rock_Stone"
    },
    {
      "x": -6,
      "y": 5,
      "z": 3,
      "name": "Rock_Stone"
    },
    {
      "x": -6,
      "y": 6,
      "z": 3,
      "name": "Rock_Stone"
    },
    {
      "x": -6,
      "y": 7,
      "z": 3,
      "name": "Rock_Stone"
    },
    {
      "x": -6,
      "y": 8,
      "z": 3,
      "name": "Rock_Stone"
    },
    {
      "x": -6,
      "y": 9,
      "z": 3,
      "name": "Rock_Stone"
    },
    {
      "x": -6,
      "y": 10,
      "z": 3,
      "name": "Rock_Stone"
    },
    {
      "x": -6,
      "y": 11,
      "z": 3,
      "name": "Rock_Stone"
    },
    {
      "x": -6,
      "y": 12,
      "z": 3,
      "name": "Rock_Stone"
    },
    {
      "x": -6,
      "y": 13,
      "z": 3,
      "name": "Rock_Stone"
    },
    {
      "x": -6,
      "y": 14,
      "z": 3,
      "name": "Rock_Stone_Mossy"
    },
    {
      "x": -6,
      "y": 15,
      "z": 3,
      "name": "Rock_Stone_Mossy"
    },
    {
      "x": -6,
      "y": 1,
      "z": 4,
      "name": "Rock_Stone"
    },
    {
      "x": -6,
      "y": 2,
      "z": 4,
      "name": "Rock_Stone"
    },
    {
      "x": -6,
      "y": 3,
      "z": 4,
      "name": "Rock_Stone"
    },
    {
      "x": -6,
      "y": 4,
      "z": 4,
      "name": "Rock_Stone"
    },
    {
      "x": -6,
      "y": 5,
      "z": 4,
      "name": "Rock_Stone"
    },
    {
      "x": -6,
      "y": 6,
      "z": 4,
      "name": "Rock_Stone"
    },
    {
      "x": -6,
      "y": 7,
      "z": 4,
      "name": "Rock_Stone"
    },
    {
      "x": -6,
      "y": 8,
      "z": 4,
      "name": "Rock_Stone"
    },
    {
      "x": -6,
      "y": 9,
      "z": 4,
      "name": "Rock_Stone"
    },
    {
      "x": -6,
      "y": 10,
      "z": 4,
      "name": "Rock_Stone"
    },
    {
      "x": -6,
      "y": 11,
      "z": 4,
      "name": "Rock_Stone"
    },
    {
      "x": -6,
      "y": 12,
      "z": 4,
      "name": "Rock_Stone"
    },
    {
      "x": -6,
      "y": 13,
      "z": 4,
      "name": "Rock_Stone_Mossy"
    },
    {
      "x": -6,
      "y": 14,
      "z": 4,
      "name": "Rock_Stone_Mossy"
    },
    {
      "x": -6,
      "y": 15,
      "z": 4,
      "name": "Rock_Stone_Mossy"
    },
    {
      "x": -6,
      "y": 1,
      "z": 5,
      "name": "Rock_Stone"
    },
    {
      "x": -6,
      "y": 2,
      "z": 5,
      "name": "Rock_Stone"
    },
    {
      "x": -6,
      "y": 3,
      "z": 5,
      "name": "Rock_Stone"
    },
    {
      "x": -6,
      "y": 4,
      "z": 5,
      "name": "Rock_Stone"
    },
    {
      "x": -6,
      "y": 5,
      "z": 5,
      "name": "Rock_Stone"
    },
    {
      "x": -6,
      "y": 6,
      "z": 5,
      "name": "Rock_Stone"
    },
    {
      "x": -6,
      "y": 7,
      "z": 5,
      "name": "Rock_Stone"
    },
    {
      "x": -6,
      "y": 8,
      "z": 5,
      "name": "Rock_Stone"
    },
    {
      "x": -6,
      "y": 9,
      "z": 5,
      "name": "Rock_Stone"
    },
    {
      "x": -6,
      "y": 10,
      "z": 5,
      "name": "Rock_Stone"
    },
    {
      "x": -6,
      "y": 1,
      "z": 6,
      "name": "Rock_Stone"
    },
    {
      "x": -6,
      "y": 2,
      "z": 6,
      "name": "Rock_Stone"
    },
    {
      "x": -6,
      "y": 3,
      "z": 6,
      "name": "Rock_Stone"
    },
    {
      "x": -6,
      "y": 4,
      "z": 6,
      "name": "Rock_Stone"
    },
    {
      "x": -6,
      "y": 5,
      "z": 6,
      "name": "Rock_Stone"
    },
    {
      "x": -6,
      "y": 6,
      "z": 6,
      "name": "Rock_Stone"
    },
    {
      "x": -6,
      "y": 7,
      "z": 6,
      "name": "Rock_Stone_Mossy"
    },
    {
      "x": -6,
      "y": 8,
      "z": 6,
      "name": "Rock_Stone"
    },
    {
      "x": -6,
      "y": 1,
      "z": 7,
      "name": "Rock_Stone"
    },
    {
      "x": -6,
      "y": 2,
      "z": 7,
      "name": "Rock_Stone"
    },
    {
      "x": -6,
      "y": 3,
      "z": 7,
      "name": "Rock_Stone"
    },
    {
      "x": -6,
      "y": 4,
      "z": 7,
      "name": "Rock_Stone"
    },
    {
      "x": -6,
      "y": 5,
      "z": 7,
      "name": "Rock_Stone"
    },
    {
      "x": -6,
      "y": 6,
      "z": 7,
      "name": "Rock_Stone_Mossy"
    },
    {
      "x": -6,
      "y": 7,
      "z": 7,
      "name": "Rock_Stone_Mossy"
    },
    {
      "x": -6,
      "y": 2,
      "z": 8,
      "name": "Rock_Stone"
    },
    {
      "x": -6,
      "y": 3,
      "z": 8,
      "name": "Rock_Stone"
    },
    {
      "x": -6,
      "y": 4,
      "z": 8,
      "name": "Rock_Stone"
    },
    {
      "x": -6,
      "y": 5,
      "z": 8,
      "name": "Rock_Stone_Mossy"
    },
    {
      "x": -6,
      "y": 6,
      "z": 8,
      "name": "Rock_Stone_Mossy"
    },
    {
      "x": -5,
      "y": 25,
      "z": -5,
      "name": "Plant_Leaves_Beech"
    },
    {
      "x": -5,
      "y": 4,
      "z": -4,
      "name": "Rock_Stone"
    },
    {
      "x": -5,
      "y": 5,
      "z": -4,
      "name": "Rock_Stone"
    },
    {
      "x": -5,
      "y": 6,
      "z": -4,
      "name": "Rock_Stone"
    },
    {
      "x": -5,
      "y": 7,
      "z": -4,
      "name": "Rock_Stone"
    },
    {
      "x": -5,
      "y": 11,
      "z": -4,
      "name": "Rock_Stone"
    },
    {
      "x": -5,
      "y": 12,
      "z": -4,
      "name": "Rock_Stone"
    },
    {
      "x": -5,
      "y": 13,
      "z": -4,
      "name": "Rock_Stone"
    },
    {
      "x": -5,
      "y": 25,
      "z": -4,
      "name": "Plant_Leaves_Beech"
    },
    {
      "x": -5,
      "y": 26,
      "z": -4,
      "name": "Plant_Leaves_Beech"
    },
    {
      "x": -5,
      "y": 2,
      "z": -3,
      "name": "Rock_Stone"
    },
    {
      "x": -5,
      "y": 3,
      "z": -3,
      "name": "Rock_Stone"
    },
    {
      "x": -5,
      "y": 4,
      "z": -3,
      "name": "Rock_Stone"
    },
    {
      "x": -5,
      "y": 5,
      "z": -3,
      "name": "Rock_Stone"
    },
    {
      "x": -5,
      "y": 6,
      "z": -3,
      "name": "Rock_Stone"
    },
    {
      "x": -5,
      "y": 7,
      "z": -3,
      "name": "Rock_Stone"
    },
    {
      "x": -5,
      "y": 8,
      "z": -3,
      "name": "Rock_Crystal_Green_Small",
      "components": {
        "Components": {
          "FarmingBlock": {}
        }
      }
    },
    {
      "x": -5,
      "y": 9,
      "z": -3,
      "name": "Rock_Crystal_Green_Medium",
      "components": {
        "Components": {
          "FarmingBlock": {}
        }
      },
      "rotation": 6
    },
    {
      "x": -5,
      "y": 10,
      "z": -3,
      "name": "Rock_Stone"
    },
    {
      "x": -5,
      "y": 11,
      "z": -3,
      "name": "Rock_Stone"
    },
    {
      "x": -5,
      "y": 12,
      "z": -3,
      "name": "Rock_Stone"
    },
    {
      "x": -5,
      "y": 13,
      "z": -3,
      "name": "Rock_Stone_Mossy"
    },
    {
      "x": -5,
      "y": 14,
      "z": -3,
      "name": "Rock_Stone"
    },
    {
      "x": -5,
      "y": 15,
      "z": -3,
      "name": "Rock_Stone"
    },
    {
      "x": -5,
      "y": 16,
      "z": -3,
      "name": "Rock_Stone"
    },
    {
      "x": -5,
      "y": 17,
      "z": -3,
      "name": "Plant_Moss_Rug_Green"
    },
    {
      "x": -5,
      "y": 25,
      "z": -3,
      "name": "Plant_Leaves_Beech"
    },
    {
      "x": -5,
      "y": 26,
      "z": -3,
      "name": "Plant_Leaves_Beech"
    },
    {
      "x": -5,
      "y": 27,
      "z": -3,
      "name": "Plant_Leaves_Beech"
    },
    {
      "x": -5,
      "y": 1,
      "z": -2,
      "name": "Rock_Stone"
    },
    {
      "x": -5,
      "y": 2,
      "z": -2,
      "name": "Rock_Stone"
    },
    {
      "x": -5,
      "y": 3,
      "z": -2,
      "name": "Rock_Stone"
    },
    {
      "x": -5,
      "y": 4,
      "z": -2,
      "name": "Rock_Stone"
    },
    {
      "x": -5,
      "y": 5,
      "z": -2,
      "name": "Rock_Stone"
    },
    {
      "x": -5,
      "y": 6,
      "z": -2,
      "name": "Rock_Stone"
    },
    {
      "x": -5,
      "y": 7,
      "z": -2,
      "name": "Rock_Stone"
    },
    {
      "x": -5,
      "y": 8,
      "z": -2,
      "name": "Rock_Stone"
    },
    {
      "x": -5,
      "y": 9,
      "z": -2,
      "name": "Rock_Stone"
    },
    {
      "x": -5,
      "y": 10,
      "z": -2,
      "name": "Rock_Stone"
    },
    {
      "x": -5,
      "y": 11,
      "z": -2,
      "name": "Rock_Stone"
    },
    {
      "x": -5,
      "y": 12,
      "z": -2,
      "name": "Rock_Stone"
    },
    {
      "x": -5,
      "y": 13,
      "z": -2,
      "name": "Rock_Stone"
    },
    {
      "x": -5,
      "y": 14,
      "z": -2,
      "name": "Rock_Stone"
    },
    {
      "x": -5,
      "y": 15,
      "z": -2,
      "name": "Rock_Stone"
    },
    {
      "x": -5,
      "y": 16,
      "z": -2,
      "name": "Rock_Stone"
    },
    {
      "x": -5,
      "y": 17,
      "z": -2,
      "name": "Plant_Moss_Rug_Green"
    },
    {
      "x": -5,
      "y": 25,
      "z": -2,
      "name": "Plant_Leaves_Beech"
    },
    {
      "x": -5,
      "y": 27,
      "z": -2,
      "name": "Plant_Leaves_Beech"
    },
    {
      "x": -5,
      "y": 1,
      "z": -1,
      "name": "Rock_Stone"
    },
    {
      "x": -5,
      "y": 2,
      "z": -1,
      "name": "Rock_Stone"
    },
    {
      "x": -5,
      "y": 3,
      "z": -1,
      "name": "Rock_Stone"
    },
    {
      "x": -5,
      "y": 4,
      "z": -1,
      "name": "Rock_Stone"
    },
    {
      "x": -5,
      "y": 5,
      "z": -1,
      "name": "Rock_Stone"
    },
    {
      "x": -5,
      "y": 6,
      "z": -1,
      "name": "Rock_Stone"
    },
    {
      "x": -5,
      "y": 7,
      "z": -1,
      "name": "Rock_Stone"
    },
    {
      "x": -5,
      "y": 8,
      "z": -1,
      "name": "Rock_Stone"
    },
    {
      "x": -5,
      "y": 9,
      "z": -1,
      "name": "Rock_Stone"
    },
    {
      "x": -5,
      "y": 10,
      "z": -1,
      "name": "Rock_Stone"
    },
    {
      "x": -5,
      "y": 11,
      "z": -1,
      "name": "Rock_Stone"
    },
    {
      "x": -5,
      "y": 12,
      "z": -1,
      "name": "Rock_Stone"
    },
    {
      "x": -5,
      "y": 13,
      "z": -1,
      "name": "Rock_Stone"
    },
    {
      "x": -5,
      "y": 14,
      "z": -1,
      "name": "Rock_Stone"
    },
    {
      "x": -5,
      "y": 15,
      "z": -1,
      "name": "Rock_Stone"
    },
    {
      "x": -5,
      "y": 16,
      "z": -1,
      "name": "Soil_Dirt"
    },
    {
      "x": -5,
      "y": 17,
      "z": -1,
      "name": "Soil_Grass"
    },
    {
      "x": -5,
      "y": 18,
      "z": -1,
      "name": "Plant_Grass_Sharp"
    },
    {
      "x": -5,
      "y": 25,
      "z": -1,
      "name": "Plant_Leaves_Beech"
    },
    {
      "x": -5,
      "y": 26,
      "z": -1,
      "name": "Plant_Leaves_Beech"
    },
    {
      "x": -5,
      "y": 1,
      "z": 0,
      "name": "Rock_Stone"
    },
    {
      "x": -5,
      "y": 2,
      "z": 0,
      "name": "Rock_Stone"
    },
    {
      "x": -5,
      "y": 3,
      "z": 0,
      "name": "Rock_Stone"
    },
    {
      "x": -5,
      "y": 4,
      "z": 0,
      "name": "Rock_Stone"
    },
    {
      "x": -5,
      "y": 5,
      "z": 0,
      "name": "Rock_Stone"
    },
    {
      "x": -5,
      "y": 6,
      "z": 0,
      "name": "Rock_Stone"
    },
    {
      "x": -5,
      "y": 7,
      "z": 0,
      "name": "Rock_Stone"
    },
    {
      "x": -5,
      "y": 8,
      "z": 0,
      "name": "Rock_Stone"
    },
    {
      "x": -5,
      "y": 9,
      "z": 0,
      "name": "Rock_Stone"
    },
    {
      "x": -5,
      "y": 10,
      "z": 0,
      "name": "Rock_Stone"
    },
    {
      "x": -5,
      "y": 11,
      "z": 0,
      "name": "Rock_Stone"
    },
    {
      "x": -5,
      "y": 12,
      "z": 0,
      "name": "Rock_Stone"
    },
    {
      "x": -5,
      "y": 13,
      "z": 0,
      "name": "Rock_Stone"
    },
    {
      "x": -5,
      "y": 14,
      "z": 0,
      "name": "Rock_Stone"
    },
    {
      "x": -5,
      "y": 15,
      "z": 0,
      "name": "Soil_Dirt"
    },
    {
      "x": -5,
      "y": 16,
      "z": 0,
      "name": "Soil_Dirt"
    },
    {
      "x": -5,
      "y": 17,
      "z": 0,
      "name": "Soil_Grass"
    },
    {
      "x": -5,
      "y": 1,
      "z": 1,
      "name": "Rock_Stone"
    },
    {
      "x": -5,
      "y": 2,
      "z": 1,
      "name": "Rock_Stone"
    },
    {
      "x": -5,
      "y": 3,
      "z": 1,
      "name": "Rock_Stone"
    },
    {
      "x": -5,
      "y": 4,
      "z": 1,
      "name": "Rock_Stone"
    },
    {
      "x": -5,
      "y": 5,
      "z": 1,
      "name": "Rock_Stone"
    },
    {
      "x": -5,
      "y": 6,
      "z": 1,
      "name": "Rock_Stone"
    },
    {
      "x": -5,
      "y": 7,
      "z": 1,
      "name": "Rock_Stone"
    },
    {
      "x": -5,
      "y": 8,
      "z": 1,
      "name": "Rock_Stone"
    },
    {
      "x": -5,
      "y": 9,
      "z": 1,
      "name": "Rock_Stone"
    },
    {
      "x": -5,
      "y": 10,
      "z": 1,
      "name": "Rock_Stone"
    },
    {
      "x": -5,
      "y": 11,
      "z": 1,
      "name": "Rock_Stone"
    },
    {
      "x": -5,
      "y": 12,
      "z": 1,
      "name": "Rock_Stone"
    },
    {
      "x": -5,
      "y": 13,
      "z": 1,
      "name": "Rock_Stone"
    },
    {
      "x": -5,
      "y": 14,
      "z": 1,
      "name": "Rock_Stone"
    },
    {
      "x": -5,
      "y": 15,
      "z": 1,
      "name": "Rock_Stone"
    },
    {
      "x": -5,
      "y": 16,
      "z": 1,
      "name": "Rock_Stone"
    },
    {
      "x": -5,
      "y": 17,
      "z": 1,
      "name": "Rock_Stone"
    },
    {
      "x": -5,
      "y": 2,
      "z": 2,
      "name": "Rock_Stone"
    },
    {
      "x": -5,
      "y": 3,
      "z": 2,
      "name": "Rock_Stone"
    },
    {
      "x": -5,
      "y": 4,
      "z": 2,
      "name": "Rock_Stone"
    },
    {
      "x": -5,
      "y": 5,
      "z": 2,
      "name": "Rock_Stone"
    },
    {
      "x": -5,
      "y": 6,
      "z": 2,
      "name": "Rock_Stone"
    },
    {
      "x": -5,
      "y": 7,
      "z": 2,
      "name": "Rock_Stone"
    },
    {
      "x": -5,
      "y": 8,
      "z": 2,
      "name": "Rock_Stone"
    },
    {
      "x": -5,
      "y": 9,
      "z": 2,
      "name": "Rock_Stone"
    },
    {
      "x": -5,
      "y": 10,
      "z": 2,
      "name": "Rock_Stone"
    },
    {
      "x": -5,
      "y": 11,
      "z": 2,
      "name": "Rock_Stone"
    },
    {
      "x": -5,
      "y": 12,
      "z": 2,
      "name": "Rock_Stone"
    },
    {
      "x": -5,
      "y": 13,
      "z": 2,
      "name": "Rock_Stone"
    },
    {
      "x": -5,
      "y": 14,
      "z": 2,
      "name": "Rock_Stone"
    },
    {
      "x": -5,
      "y": 15,
      "z": 2,
      "name": "Soil_Dirt"
    },
    {
      "x": -5,
      "y": 16,
      "z": 2,
      "name": "Rock_Stone"
    },
    {
      "x": -5,
      "y": 17,
      "z": 2,
      "name": "Rubble_Stone"
    },
    {
      "x": -5,
      "y": 1,
      "z": 3,
      "name": "Rock_Stone"
    },
    {
      "x": -5,
      "y": 2,
      "z": 3,
      "name": "Rock_Stone"
    },
    {
      "x": -5,
      "y": 3,
      "z": 3,
      "name": "Rock_Stone"
    },
    {
      "x": -5,
      "y": 4,
      "z": 3,
      "name": "Rock_Stone"
    },
    {
      "x": -5,
      "y": 5,
      "z": 3,
      "name": "Rock_Stone"
    },
    {
      "x": -5,
      "y": 6,
      "z": 3,
      "name": "Rock_Stone"
    },
    {
      "x": -5,
      "y": 7,
      "z": 3,
      "name": "Rock_Stone"
    },
    {
      "x": -5,
      "y": 8,
      "z": 3,
      "name": "Rock_Stone"
    },
    {
      "x": -5,
      "y": 9,
      "z": 3,
      "name": "Rock_Stone"
    },
    {
      "x": -5,
      "y": 10,
      "z": 3,
      "name": "Rock_Stone"
    },
    {
      "x": -5,
      "y": 11,
      "z": 3,
      "name": "Rock_Stone"
    },
    {
      "x": -5,
      "y": 12,
      "z": 3,
      "name": "Rock_Stone"
    },
    {
      "x": -5,
      "y": 13,
      "z": 3,
      "name": "Rock_Stone"
    },
    {
      "x": -5,
      "y": 14,
      "z": 3,
      "name": "Rock_Stone_Mossy"
    },
    {
      "x": -5,
      "y": 15,
      "z": 3,
      "name": "Rock_Stone_Mossy"
    },
    {
      "x": -5,
      "y": 16,
      "z": 3,
      "name": "Soil_Grass"
    },
    {
      "x": -5,
      "y": 17,
      "z": 3,
      "name": "Plant_Flower_Common_Yellow2"
    },
    {
      "x": -5,
      "y": 1,
      "z": 4,
      "name": "Rock_Stone"
    },
    {
      "x": -5,
      "y": 2,
      "z": 4,
      "name": "Rock_Stone"
    },
    {
      "x": -5,
      "y": 3,
      "z": 4,
      "name": "Rock_Stone"
    },
    {
      "x": -5,
      "y": 4,
      "z": 4,
      "name": "Rock_Stone"
    },
    {
      "x": -5,
      "y": 5,
      "z": 4,
      "name": "Rock_Stone"
    },
    {
      "x": -5,
      "y": 6,
      "z": 4,
      "name": "Rock_Stone"
    },
    {
      "x": -5,
      "y": 7,
      "z": 4,
      "name": "Rock_Stone"
    },
    {
      "x": -5,
      "y": 8,
      "z": 4,
      "name": "Rock_Stone"
    },
    {
      "x": -5,
      "y": 9,
      "z": 4,
      "name": "Rock_Stone"
    },
    {
      "x": -5,
      "y": 10,
      "z": 4,
      "name": "Rock_Stone"
    },
    {
      "x": -5,
      "y": 11,
      "z": 4,
      "name": "Rock_Stone"
    },
    {
      "x": -5,
      "y": 12,
      "z": 4,
      "name": "Rock_Stone"
    },
    {
      "x": -5,
      "y": 13,
      "z": 4,
      "name": "Rock_Stone"
    },
    {
      "x": -5,
      "y": 14,
      "z": 4,
      "name": "Rock_Stone_Mossy"
    },
    {
      "x": -5,
      "y": 15,
      "z": 4,
      "name": "Rock_Stone_Mossy"
    },
    {
      "x": -5,
      "y": 1,
      "z": 5,
      "name": "Rock_Stone"
    },
    {
      "x": -5,
      "y": 2,
      "z": 5,
      "name": "Rock_Stone"
    },
    {
      "x": -5,
      "y": 3,
      "z": 5,
      "name": "Rock_Stone"
    },
    {
      "x": -5,
      "y": 4,
      "z": 5,
      "name": "Rock_Stone"
    },
    {
      "x": -5,
      "y": 5,
      "z": 5,
      "name": "Rock_Stone"
    },
    {
      "x": -5,
      "y": 6,
      "z": 5,
      "name": "Rock_Stone"
    },
    {
      "x": -5,
      "y": 7,
      "z": 5,
      "name": "Rock_Stone"
    },
    {
      "x": -5,
      "y": 8,
      "z": 5,
      "name": "Rock_Stone"
    },
    {
      "x": -5,
      "y": 9,
      "z": 5,
      "name": "Rock_Stone"
    },
    {
      "x": -5,
      "y": 10,
      "z": 5,
      "name": "Rock_Stone"
    },
    {
      "x": -5,
      "y": 11,
      "z": 5,
      "name": "Rock_Stone"
    },
    {
      "x": -5,
      "y": 12,
      "z": 5,
      "name": "Plant_Moss_Block_Green"
    },
    {
      "x": -5,
      "y": 1,
      "z": 6,
      "name": "Rock_Stone"
    },
    {
      "x": -5,
      "y": 2,
      "z": 6,
      "name": "Rock_Stone"
    },
    {
      "x": -5,
      "y": 3,
      "z": 6,
      "name": "Rock_Stone"
    },
    {
      "x": -5,
      "y": 4,
      "z": 6,
      "name": "Rock_Stone"
    },
    {
      "x": -5,
      "y": 5,
      "z": 6,
      "name": "Rock_Stone"
    },
    {
      "x": -5,
      "y": 6,
      "z": 6,
      "name": "Rock_Stone"
    },
    {
      "x": -5,
      "y": 7,
      "z": 6,
      "name": "Rock_Stone"
    },
    {
      "x": -5,
      "y": 8,
      "z": 6,
      "name": "Rock_Stone_Mossy"
    },
    {
      "x": -5,
      "y": 9,
      "z": 6,
      "name": "Rock_Stone"
    },
    {
      "x": -5,
      "y": 10,
      "z": 6,
      "name": "Rock_Stone_Mossy"
    },
    {
      "x": -5,
      "y": 1,
      "z": 7,
      "name": "Rock_Stone"
    },
    {
      "x": -5,
      "y": 2,
      "z": 7,
      "name": "Rock_Stone"
    },
    {
      "x": -5,
      "y": 3,
      "z": 7,
      "name": "Rock_Stone"
    },
    {
      "x": -5,
      "y": 4,
      "z": 7,
      "name": "Rock_Stone"
    },
    {
      "x": -5,
      "y": 5,
      "z": 7,
      "name": "Rock_Stone"
    },
    {
      "x": -5,
      "y": 6,
      "z": 7,
      "name": "Rock_Stone"
    },
    {
      "x": -5,
      "y": 7,
      "z": 7,
      "name": "Rock_Stone_Mossy"
    },
    {
      "x": -5,
      "y": 8,
      "z": 7,
      "name": "Rock_Stone_Mossy"
    },
    {
      "x": -5,
      "y": 9,
      "z": 7,
      "name": "Rock_Stone_Mossy"
    },
    {
      "x": -5,
      "y": 1,
      "z": 8,
      "name": "Rock_Stone"
    },
    {
      "x": -5,
      "y": 2,
      "z": 8,
      "name": "Rock_Stone"
    },
    {
      "x": -5,
      "y": 3,
      "z": 8,
      "name": "Rock_Stone"
    },
    {
      "x": -5,
      "y": 4,
      "z": 8,
      "name": "Rock_Stone"
    },
    {
      "x": -5,
      "y": 5,
      "z": 8,
      "name": "Rock_Stone"
    },
    {
      "x": -5,
      "y": 6,
      "z": 8,
      "name": "Rock_Stone_Mossy"
    },
    {
      "x": -5,
      "y": 7,
      "z": 8,
      "name": "Rock_Stone_Mossy"
    },
    {
      "x": -4,
      "y": 12,
      "z": -7,
      "name": "Rock_Stone"
    },
    {
      "x": -4,
      "y": 13,
      "z": -7,
      "name": "Rock_Stone"
    },
    {
      "x": -4,
      "y": 14,
      "z": -7,
      "name": "Rock_Stone"
    },
    {
      "x": -4,
      "y": 10,
      "z": -6,
      "name": "Rock_Stone"
    },
    {
      "x": -4,
      "y": 11,
      "z": -6,
      "name": "Rock_Stone"
    },
    {
      "x": -4,
      "y": 12,
      "z": -6,
      "name": "Rock_Stone"
    },
    {
      "x": -4,
      "y": 13,
      "z": -6,
      "name": "Rock_Stone"
    },
    {
      "x": -4,
      "y": 14,
      "z": -6,
      "name": "Rock_Stone"
    },
    {
      "x": -4,
      "y": 15,
      "z": -6,
      "name": "Rock_Stone"
    },
    {
      "x": -4,
      "y": 4,
      "z": -5,
      "name": "Rock_Stone_Mossy"
    },
    {
      "x": -4,
      "y": 5,
      "z": -5,
      "name": "Rock_Stone_Mossy"
    },
    {
      "x": -4,
      "y": 6,
      "z": -5,
      "name": "Rock_Stone"
    },
    {
      "x": -4,
      "y": 7,
      "z": -5,
      "name": "Rock_Stone"
    },
    {
      "x": -4,
      "y": 10,
      "z": -5,
      "name": "Rock_Stone"
    },
    {
      "x": -4,
      "y": 11,
      "z": -5,
      "name": "Rock_Stone"
    },
    {
      "x": -4,
      "y": 12,
      "z": -5,
      "name": "Rock_Stone"
    },
    {
      "x": -4,
      "y": 13,
      "z": -5,
      "name": "Rock_Stone"
    },
    {
      "x": -4,
      "y": 14,
      "z": -5,
      "name": "Rock_Stone"
    },
    {
      "x": -4,
      "y": 15,
      "z": -5,
      "name": "Rock_Stone"
    },
    {
      "x": -4,
      "y": 16,
      "z": -5,
      "name": "Rock_Stone"
    },
    {
      "x": -4,
      "y": 17,
      "z": -5,
      "name": "Rock_Stone"
    },
    {
      "x": -4,
      "y": 18,
      "z": -5,
      "name": "Rock_Stone"
    },
    {
      "x": -4,
      "y": 25,
      "z": -5,
      "name": "Plant_Leaves_Beech"
    },
    {
      "x": -4,
      "y": 27,
      "z": -5,
      "name": "Plant_Leaves_Beech"
    },
    {
      "x": -4,
      "y": 28,
      "z": -5,
      "name": "Plant_Leaves_Beech"
    },
    {
      "x": -4,
      "y": 2,
      "z": -4,
      "name": "Rock_Stone"
    },
    {
      "x": -4,
      "y": 3,
      "z": -4,
      "name": "Rock_Stone"
    },
    {
      "x": -4,
      "y": 4,
      "z": -4,
      "name": "Rock_Stone_Mossy"
    },
    {
      "x": -4,
      "y": 5,
      "z": -4,
      "name": "Rock_Stone"
    },
    {
      "x": -4,
      "y": 6,
      "z": -4,
      "name": "Rock_Stone"
    },
    {
      "x": -4,
      "y": 7,
      "z": -4,
      "name": "Rock_Stone"
    },
    {
      "x": -4,
      "y": 8,
      "z": -4,
      "name": "Rock_Stone"
    },
    {
      "x": -4,
      "y": 10,
      "z": -4,
      "name": "Rock_Stone"
    },
    {
      "x": -4,
      "y": 11,
      "z": -4,
      "name": "Rock_Stone"
    },
    {
      "x": -4,
      "y": 12,
      "z": -4,
      "name": "Rock_Stone"
    },
    {
      "x": -4,
      "y": 13,
      "z": -4,
      "name": "Rock_Stone"
    },
    {
      "x": -4,
      "y": 14,
      "z": -4,
      "name": "Rock_Stone"
    },
    {
      "x": -4,
      "y": 15,
      "z": -4,
      "name": "Rock_Stone"
    },
    {
      "x": -4,
      "y": 16,
      "z": -4,
      "name": "Rock_Stone"
    },
    {
      "x": -4,
      "y": 17,
      "z": -4,
      "name": "Rock_Stone"
    },
    {
      "x": -4,
      "y": 25,
      "z": -4,
      "name": "Plant_Leaves_Beech"
    },
    {
      "x": -4,
      "y": 26,
      "z": -4,
      "name": "Plant_Leaves_Beech"
    },
    {
      "x": -4,
      "y": 27,
      "z": -4,
      "name": "Plant_Leaves_Beech"
    },
    {
      "x": -4,
      "y": 28,
      "z": -4,
      "name": "Plant_Leaves_Beech"
    },
    {
      "x": -4,
      "y": 29,
      "z": -4,
      "name": "Plant_Leaves_Beech"
    },
    {
      "x": -4,
      "y": 30,
      "z": -4,
      "name": "Plant_Leaves_Beech"
    },
    {
      "x": -4,
      "y": 0,
      "z": -3,
      "name": "Rock_Stone"
    },
    {
      "x": -4,
      "y": 1,
      "z": -3,
      "name": "Rock_Stone"
    },
    {
      "x": -4,
      "y": 2,
      "z": -3,
      "name": "Rock_Stone"
    },
    {
      "x": -4,
      "y": 3,
      "z": -3,
      "name": "Rock_Stone"
    },
    {
      "x": -4,
      "y": 4,
      "z": -3,
      "name": "Rock_Stone"
    },
    {
      "x": -4,
      "y": 5,
      "z": -3,
      "name": "Rock_Stone"
    },
    {
      "x": -4,
      "y": 6,
      "z": -3,
      "name": "Rock_Stone"
    },
    {
      "x": -4,
      "y": 7,
      "z": -3,
      "name": "Rock_Stone"
    },
    {
      "x": -4,
      "y": 8,
      "z": -3,
      "name": "Rock_Stone"
    },
    {
      "x": -4,
      "y": 9,
      "z": -3,
      "name": "Rock_Stone"
    },
    {
      "x": -4,
      "y": 10,
      "z": -3,
      "name": "Rock_Stone"
    },
    {
      "x": -4,
      "y": 11,
      "z": -3,
      "name": "Rock_Stone"
    },
    {
      "x": -4,
      "y": 12,
      "z": -3,
      "name": "Rock_Stone"
    },
    {
      "x": -4,
      "y": 13,
      "z": -3,
      "name": "Rock_Stone"
    },
    {
      "x": -4,
      "y": 14,
      "z": -3,
      "name": "Rock_Stone"
    },
    {
      "x": -4,
      "y": 15,
      "z": -3,
      "name": "Rock_Stone"
    },
    {
      "x": -4,
      "y": 16,
      "z": -3,
      "name": "Rock_Stone"
    },
    {
      "x": -4,
      "y": 17,
      "z": -3,
      "name": "Plant_Moss_Rug_Green"
    },
    {
      "x": -4,
      "y": 25,
      "z": -3,
      "name": "Wood_Beech_Branch_Long",
      "rotation": 5
    },
    {
      "x": -4,
      "y": 26,
      "z": -3,
      "name": "Plant_Leaves_Beech"
    },
    {
      "x": -4,
      "y": 27,
      "z": -3,
      "name": "Plant_Leaves_Beech"
    },
    {
      "x": -4,
      "y": 28,
      "z": -3,
      "name": "Plant_Leaves_Beech"
    },
    {
      "x": -4,
      "y": 30,
      "z": -3,
      "name": "Plant_Leaves_Beech"
    },
    {
      "x": -4,
      "y": 31,
      "z": -3,
      "name": "Plant_Leaves_Beech"
    },
    {
      "x": -4,
      "y": 0,
      "z": -2,
      "name": "Rock_Stone"
    },
    {
      "x": -4,
      "y": 1,
      "z": -2,
      "name": "Rock_Stone"
    },
    {
      "x": -4,
      "y": 2,
      "z": -2,
      "name": "Rock_Stone"
    },
    {
      "x": -4,
      "y": 3,
      "z": -2,
      "name": "Rock_Stone"
    },
    {
      "x": -4,
      "y": 4,
      "z": -2,
      "name": "Rock_Stone"
    },
    {
      "x": -4,
      "y": 5,
      "z": -2,
      "name": "Rock_Stone"
    },
    {
      "x": -4,
      "y": 6,
      "z": -2,
      "name": "Rock_Stone"
    },
    {
      "x": -4,
      "y": 7,
      "z": -2,
      "name": "Rock_Stone"
    },
    {
      "x": -4,
      "y": 8,
      "z": -2,
      "name": "Rock_Stone"
    },
    {
      "x": -4,
      "y": 9,
      "z": -2,
      "name": "Rock_Stone"
    },
    {
      "x": -4,
      "y": 10,
      "z": -2,
      "name": "Rock_Stone"
    },
    {
      "x": -4,
      "y": 11,
      "z": -2,
      "name": "Rock_Stone"
    },
    {
      "x": -4,
      "y": 12,
      "z": -2,
      "name": "Rock_Stone"
    },
    {
      "x": -4,
      "y": 13,
      "z": -2,
      "name": "Rock_Stone"
    },
    {
      "x": -4,
      "y": 14,
      "z": -2,
      "name": "Rock_Stone"
    },
    {
      "x": -4,
      "y": 15,
      "z": -2,
      "name": "Rock_Stone"
    },
    {
      "x": -4,
      "y": 16,
      "z": -2,
      "name": "Rock_Stone"
    },
    {
      "x": -4,
      "y": 17,
      "z": -2,
      "name": "Soil_Grass"
    },
    {
      "x": -4,
      "y": 25,
      "z": -2,
      "name": "Plant_Leaves_Beech"
    },
    {
      "x": -4,
      "y": 26,
      "z": -2,
      "name": "Plant_Leaves_Beech"
    },
    {
      "x": -4,
      "y": 27,
      "z": -2,
      "name": "Plant_Leaves_Beech"
    },
    {
      "x": -4,
      "y": 0,
      "z": -1,
      "name": "Rock_Stone"
    },
    {
      "x": -4,
      "y": 1,
      "z": -1,
      "name": "Rock_Stone"
    },
    {
      "x": -4,
      "y": 2,
      "z": -1,
      "name": "Rock_Stone"
    },
    {
      "x": -4,
      "y": 3,
      "z": -1,
      "name": "Rock_Stone"
    },
    {
      "x": -4,
      "y": 4,
      "z": -1,
      "name": "Rock_Stone"
    },
    {
      "x": -4,
      "y": 5,
      "z": -1,
      "name": "Rock_Stone"
    },
    {
      "x": -4,
      "y": 6,
      "z": -1,
      "name": "Rock_Stone"
    },
    {
      "x": -4,
      "y": 7,
      "z": -1,
      "name": "Rock_Stone"
    },
    {
      "x": -4,
      "y": 8,
      "z": -1,
      "name": "Rock_Stone"
    },
    {
      "x": -4,
      "y": 9,
      "z": -1,
      "name": "Rock_Stone"
    },
    {
      "x": -4,
      "y": 10,
      "z": -1,
      "name": "Rock_Stone"
    },
    {
      "x": -4,
      "y": 11,
      "z": -1,
      "name": "Rock_Stone"
    },
    {
      "x": -4,
      "y": 12,
      "z": -1,
      "name": "Rock_Stone"
    },
    {
      "x": -4,
      "y": 13,
      "z": -1,
      "name": "Rock_Stone"
    },
    {
      "x": -4,
      "y": 14,
      "z": -1,
      "name": "Rock_Stone"
    },
    {
      "x": -4,
      "y": 15,
      "z": -1,
      "name": "Rock_Stone"
    },
    {
      "x": -4,
      "y": 16,
      "z": -1,
      "name": "Rock_Stone"
    },
    {
      "x": -4,
      "y": 17,
      "z": -1,
      "name": "Soil_Grass"
    },
    {
      "x": -4,
      "y": 18,
      "z": -1,
      "name": "Plant_Grass_Sharp_Tall"
    },
    {
      "x": -4,
      "y": 19,
      "z": -1,
      "name": "Plant_Grass_Sharp_Tall",
      "filler": 1024
    },
    {
      "x": -4,
      "y": 25,
      "z": -1,
      "name": "Plant_Leaves_Beech"
    },
    {
      "x": -4,
      "y": 26,
      "z": -1,
      "name": "Plant_Leaves_Beech"
    },
    {
      "x": -4,
      "y": 27,
      "z": -1,
      "name": "Plant_Leaves_Beech"
    },
    {
      "x": -4,
      "y": 1,
      "z": 0,
      "name": "Rock_Stone"
    },
    {
      "x": -4,
      "y": 2,
      "z": 0,
      "name": "Rock_Stone"
    },
    {
      "x": -4,
      "y": 3,
      "z": 0,
      "name": "Rock_Stone"
    },
    {
      "x": -4,
      "y": 4,
      "z": 0,
      "name": "Rock_Stone"
    },
    {
      "x": -4,
      "y": 5,
      "z": 0,
      "name": "Rock_Stone"
    },
    {
      "x": -4,
      "y": 6,
      "z": 0,
      "name": "Rock_Stone"
    },
    {
      "x": -4,
      "y": 7,
      "z": 0,
      "name": "Rock_Stone"
    },
    {
      "x": -4,
      "y": 8,
      "z": 0,
      "name": "Rock_Stone"
    },
    {
      "x": -4,
      "y": 9,
      "z": 0,
      "name": "Rock_Stone"
    },
    {
      "x": -4,
      "y": 10,
      "z": 0,
      "name": "Rock_Stone"
    },
    {
      "x": -4,
      "y": 11,
      "z": 0,
      "name": "Rock_Stone"
    },
    {
      "x": -4,
      "y": 12,
      "z": 0,
      "name": "Rock_Stone"
    },
    {
      "x": -4,
      "y": 13,
      "z": 0,
      "name": "Rock_Stone"
    },
    {
      "x": -4,
      "y": 14,
      "z": 0,
      "name": "Rock_Stone"
    },
    {
      "x": -4,
      "y": 15,
      "z": 0,
      "name": "Rock_Stone"
    },
    {
      "x": -4,
      "y": 16,
      "z": 0,
      "name": "Soil_Dirt"
    },
    {
      "x": -4,
      "y": 17,
      "z": 0,
      "name": "Soil_Grass"
    },
    {
      "x": -4,
      "y": 18,
      "z": 0,
      "name": "Plant_Grass_Sharp"
    },
    {
      "x": -4,
      "y": 1,
      "z": 1,
      "name": "Rock_Stone"
    },
    {
      "x": -4,
      "y": 2,
      "z": 1,
      "name": "Rock_Stone"
    },
    {
      "x": -4,
      "y": 3,
      "z": 1,
      "name": "Rock_Stone"
    },
    {
      "x": -4,
      "y": 4,
      "z": 1,
      "name": "Rock_Stone"
    },
    {
      "x": -4,
      "y": 5,
      "z": 1,
      "name": "Rock_Stone"
    },
    {
      "x": -4,
      "y": 6,
      "z": 1,
      "name": "Rock_Stone"
    },
    {
      "x": -4,
      "y": 7,
      "z": 1,
      "name": "Rock_Stone"
    },
    {
      "x": -4,
      "y": 8,
      "z": 1,
      "name": "Rock_Stone"
    },
    {
      "x": -4,
      "y": 9,
      "z": 1,
      "name": "Rock_Stone"
    },
    {
      "x": -4,
      "y": 10,
      "z": 1,
      "name": "Rock_Stone"
    },
    {
      "x": -4,
      "y": 11,
      "z": 1,
      "name": "Rock_Stone"
    },
    {
      "x": -4,
      "y": 12,
      "z": 1,
      "name": "Rock_Stone"
    },
    {
      "x": -4,
      "y": 13,
      "z": 1,
      "name": "Rock_Stone"
    },
    {
      "x": -4,
      "y": 14,
      "z": 1,
      "name": "Rock_Stone"
    },
    {
      "x": -4,
      "y": 15,
      "z": 1,
      "name": "Soil_Dirt"
    },
    {
      "x": -4,
      "y": 16,
      "z": 1,
      "name": "Rock_Stone"
    },
    {
      "x": -4,
      "y": 17,
      "z": 1,
      "name": "Rock_Stone"
    },
    {
      "x": -4,
      "y": 18,
      "z": 1,
      "name": "Rock_Stone"
    },
    {
      "x": -4,
      "y": 1,
      "z": 2,
      "name": "Rock_Stone"
    },
    {
      "x": -4,
      "y": 2,
      "z": 2,
      "name": "Rock_Stone"
    },
    {
      "x": -4,
      "y": 3,
      "z": 2,
      "name": "Rock_Stone"
    },
    {
      "x": -4,
      "y": 4,
      "z": 2,
      "name": "Rock_Stone"
    },
    {
      "x": -4,
      "y": 5,
      "z": 2,
      "name": "Rock_Stone"
    },
    {
      "x": -4,
      "y": 6,
      "z": 2,
      "name": "Rock_Stone"
    },
    {
      "x": -4,
      "y": 7,
      "z": 2,
      "name": "Rock_Stone"
    },
    {
      "x": -4,
      "y": 8,
      "z": 2,
      "name": "Rock_Stone"
    },
    {
      "x": -4,
      "y": 9,
      "z": 2,
      "name": "Rock_Stone"
    },
    {
      "x": -4,
      "y": 10,
      "z": 2,
      "name": "Rock_Stone"
    },
    {
      "x": -4,
      "y": 11,
      "z": 2,
      "name": "Rock_Stone"
    },
    {
      "x": -4,
      "y": 12,
      "z": 2,
      "name": "Rock_Stone"
    },
    {
      "x": -4,
      "y": 13,
      "z": 2,
      "name": "Rock_Stone"
    },
    {
      "x": -4,
      "y": 14,
      "z": 2,
      "name": "Rock_Stone_Mossy"
    },
    {
      "x": -4,
      "y": 15,
      "z": 2,
      "name": "Rock_Stone"
    },
    {
      "x": -4,
      "y": 16,
      "z": 2,
      "name": "Rock_Stone"
    },
    {
      "x": -4,
      "y": 17,
      "z": 2,
      "name": "Rock_Stone"
    },
    {
      "x": -4,
      "y": 18,
      "z": 2,
      "name": "Rock_Stone"
    },
    {
      "x": -4,
      "y": 1,
      "z": 3,
      "name": "Rock_Stone"
    },
    {
      "x": -4,
      "y": 2,
      "z": 3,
      "name": "Rock_Stone"
    },
    {
      "x": -4,
      "y": 3,
      "z": 3,
      "name": "Rock_Stone"
    },
    {
      "x": -4,
      "y": 4,
      "z": 3,
      "name": "Rock_Stone"
    },
    {
      "x": -4,
      "y": 5,
      "z": 3,
      "name": "Rock_Stone"
    },
    {
      "x": -4,
      "y": 6,
      "z": 3,
      "name": "Rock_Stone"
    },
    {
      "x": -4,
      "y": 7,
      "z": 3,
      "name": "Rock_Stone"
    },
    {
      "x": -4,
      "y": 8,
      "z": 3,
      "name": "Rock_Stone"
    },
    {
      "x": -4,
      "y": 9,
      "z": 3,
      "name": "Rock_Stone"
    },
    {
      "x": -4,
      "y": 10,
      "z": 3,
      "name": "Rock_Stone"
    },
    {
      "x": -4,
      "y": 11,
      "z": 3,
      "name": "Rock_Stone"
    },
    {
      "x": -4,
      "y": 12,
      "z": 3,
      "name": "Rock_Stone"
    },
    {
      "x": -4,
      "y": 13,
      "z": 3,
      "name": "Rock_Stone_Mossy"
    },
    {
      "x": -4,
      "y": 14,
      "z": 3,
      "name": "Rock_Stone_Mossy"
    },
    {
      "x": -4,
      "y": 15,
      "z": 3,
      "name": "Rock_Stone_Mossy"
    },
    {
      "x": -4,
      "y": 16,
      "z": 3,
      "name": "Soil_Grass"
    },
    {
      "x": -4,
      "y": 1,
      "z": 4,
      "name": "Rock_Stone"
    },
    {
      "x": -4,
      "y": 2,
      "z": 4,
      "name": "Rock_Stone"
    },
    {
      "x": -4,
      "y": 3,
      "z": 4,
      "name": "Rock_Stone"
    },
    {
      "x": -4,
      "y": 4,
      "z": 4,
      "name": "Rock_Stone"
    },
    {
      "x": -4,
      "y": 5,
      "z": 4,
      "name": "Rock_Stone"
    },
    {
      "x": -4,
      "y": 6,
      "z": 4,
      "name": "Rock_Stone"
    },
    {
      "x": -4,
      "y": 7,
      "z": 4,
      "name": "Rock_Stone"
    },
    {
      "x": -4,
      "y": 8,
      "z": 4,
      "name": "Rock_Stone"
    },
    {
      "x": -4,
      "y": 9,
      "z": 4,
      "name": "Rock_Stone"
    },
    {
      "x": -4,
      "y": 10,
      "z": 4,
      "name": "Rock_Stone"
    },
    {
      "x": -4,
      "y": 11,
      "z": 4,
      "name": "Rock_Stone"
    },
    {
      "x": -4,
      "y": 12,
      "z": 4,
      "name": "Rock_Stone"
    },
    {
      "x": -4,
      "y": 13,
      "z": 4,
      "name": "Plant_Moss_Block_Green"
    },
    {
      "x": -4,
      "y": 14,
      "z": 4,
      "name": "Plant_Moss_Rug_Green"
    },
    {
      "x": -4,
      "y": 1,
      "z": 5,
      "name": "Rock_Stone"
    },
    {
      "x": -4,
      "y": 2,
      "z": 5,
      "name": "Rock_Stone"
    },
    {
      "x": -4,
      "y": 3,
      "z": 5,
      "name": "Rock_Stone"
    },
    {
      "x": -4,
      "y": 4,
      "z": 5,
      "name": "Rock_Stone"
    },
    {
      "x": -4,
      "y": 5,
      "z": 5,
      "name": "Rock_Stone"
    },
    {
      "x": -4,
      "y": 6,
      "z": 5,
      "name": "Rock_Stone"
    },
    {
      "x": -4,
      "y": 7,
      "z": 5,
      "name": "Rock_Stone"
    },
    {
      "x": -4,
      "y": 8,
      "z": 5,
      "name": "Rock_Stone"
    },
    {
      "x": -4,
      "y": 9,
      "z": 5,
      "name": "Rock_Stone"
    },
    {
      "x": -4,
      "y": 10,
      "z": 5,
      "name": "Rock_Stone_Mossy"
    },
    {
      "x": -4,
      "y": 11,
      "z": 5,
      "name": "Rock_Stone"
    },
    {
      "x": -4,
      "y": 12,
      "z": 5,
      "name": "Plant_Moss_Block_Green"
    },
    {
      "x": -4,
      "y": 1,
      "z": 6,
      "name": "Rock_Stone"
    },
    {
      "x": -4,
      "y": 2,
      "z": 6,
      "name": "Rock_Stone"
    },
    {
      "x": -4,
      "y": 3,
      "z": 6,
      "name": "Rock_Stone"
    },
    {
      "x": -4,
      "y": 4,
      "z": 6,
      "name": "Rock_Stone"
    },
    {
      "x": -4,
      "y": 5,
      "z": 6,
      "name": "Rock_Stone"
    },
    {
      "x": -4,
      "y": 6,
      "z": 6,
      "name": "Rock_Stone"
    },
    {
      "x": -4,
      "y": 7,
      "z": 6,
      "name": "Rock_Stone"
    },
    {
      "x": -4,
      "y": 8,
      "z": 6,
      "name": "Rock_Stone_Mossy"
    },
    {
      "x": -4,
      "y": 9,
      "z": 6,
      "name": "Rock_Stone_Mossy"
    },
    {
      "x": -4,
      "y": 10,
      "z": 6,
      "name": "Rock_Stone_Mossy"
    },
    {
      "x": -4,
      "y": 11,
      "z": 6,
      "name": "Rock_Stone_Mossy"
    },
    {
      "x": -4,
      "y": 1,
      "z": 7,
      "name": "Rock_Stone"
    },
    {
      "x": -4,
      "y": 2,
      "z": 7,
      "name": "Rock_Stone"
    },
    {
      "x": -4,
      "y": 3,
      "z": 7,
      "name": "Rock_Stone"
    },
    {
      "x": -4,
      "y": 4,
      "z": 7,
      "name": "Rock_Stone"
    },
    {
      "x": -4,
      "y": 5,
      "z": 7,
      "name": "Rock_Stone"
    },
    {
      "x": -4,
      "y": 6,
      "z": 7,
      "name": "Rock_Stone"
    },
    {
      "x": -4,
      "y": 7,
      "z": 7,
      "name": "Rock_Stone_Mossy"
    },
    {
      "x": -4,
      "y": 8,
      "z": 7,
      "name": "Rock_Stone_Mossy"
    },
    {
      "x": -4,
      "y": 9,
      "z": 7,
      "name": "Rock_Stone_Mossy"
    },
    {
      "x": -4,
      "y": 1,
      "z": 8,
      "name": "Rock_Stone"
    },
    {
      "x": -4,
      "y": 2,
      "z": 8,
      "name": "Rock_Stone"
    },
    {
      "x": -4,
      "y": 3,
      "z": 8,
      "name": "Rock_Stone"
    },
    {
      "x": -4,
      "y": 4,
      "z": 8,
      "name": "Rock_Stone"
    },
    {
      "x": -4,
      "y": 5,
      "z": 8,
      "name": "Rock_Stone"
    },
    {
      "x": -4,
      "y": 6,
      "z": 8,
      "name": "Rock_Stone"
    },
    {
      "x": -3,
      "y": 11,
      "z": -8,
      "name": "Rock_Stone"
    },
    {
      "x": -3,
      "y": 12,
      "z": -8,
      "name": "Rock_Stone_Mossy"
    },
    {
      "x": -3,
      "y": 13,
      "z": -8,
      "name": "Rock_Stone_Mossy"
    },
    {
      "x": -3,
      "y": 14,
      "z": -8,
      "name": "Rock_Stone_Mossy"
    },
    {
      "x": -3,
      "y": 8,
      "z": -7,
      "name": "Rock_Stone"
    },
    {
      "x": -3,
      "y": 9,
      "z": -7,
      "name": "Rock_Stone"
    },
    {
      "x": -3,
      "y": 10,
      "z": -7,
      "name": "Rock_Stone"
    },
    {
      "x": -3,
      "y": 11,
      "z": -7,
      "name": "Rock_Stone"
    },
    {
      "x": -3,
      "y": 12,
      "z": -7,
      "name": "Rock_Stone"
    },
    {
      "x": -3,
      "y": 13,
      "z": -7,
      "name": "Rock_Stone_Mossy"
    },
    {
      "x": -3,
      "y": 14,
      "z": -7,
      "name": "Rock_Stone"
    },
    {
      "x": -3,
      "y": 15,
      "z": -7,
      "name": "Rock_Stone"
    },
    {
      "x": -3,
      "y": 7,
      "z": -6,
      "name": "Rock_Stone"
    },
    {
      "x": -3,
      "y": 8,
      "z": -6,
      "name": "Rock_Stone"
    },
    {
      "x": -3,
      "y": 9,
      "z": -6,
      "name": "Rock_Stone"
    },
    {
      "x": -3,
      "y": 10,
      "z": -6,
      "name": "Rock_Stone"
    },
    {
      "x": -3,
      "y": 11,
      "z": -6,
      "name": "Rock_Stone"
    },
    {
      "x": -3,
      "y": 12,
      "z": -6,
      "name": "Rock_Stone"
    },
    {
      "x": -3,
      "y": 13,
      "z": -6,
      "name": "Rock_Stone"
    },
    {
      "x": -3,
      "y": 14,
      "z": -6,
      "name": "Rock_Stone"
    },
    {
      "x": -3,
      "y": 15,
      "z": -6,
      "name": "Rock_Stone"
    },
    {
      "x": -3,
      "y": 16,
      "z": -6,
      "name": "Rock_Stone"
    },
    {
      "x": -3,
      "y": 17,
      "z": -6,
      "name": "Rock_Stone"
    },
    {
      "x": -3,
      "y": 18,
      "z": -6,
      "name": "Rock_Stone"
    },
    {
      "x": -3,
      "y": 28,
      "z": -6,
      "name": "Plant_Leaves_Beech"
    },
    {
      "x": -3,
      "y": 29,
      "z": -6,
      "name": "Plant_Leaves_Beech"
    },
    {
      "x": -3,
      "y": 2,
      "z": -5,
      "name": "Rock_Stone_Mossy"
    },
    {
      "x": -3,
      "y": 3,
      "z": -5,
      "name": "Rock_Stone_Mossy"
    },
    {
      "x": -3,
      "y": 4,
      "z": -5,
      "name": "Rock_Stone_Mossy"
    },
    {
      "x": -3,
      "y": 5,
      "z": -5,
      "name": "Rock_Stone_Mossy"
    },
    {
      "x": -3,
      "y": 6,
      "z": -5,
      "name": "Rock_Stone_Mossy"
    },
    {
      "x": -3,
      "y": 7,
      "z": -5,
      "name": "Rock_Stone"
    },
    {
      "x": -3,
      "y": 8,
      "z": -5,
      "name": "Rock_Stone"
    },
    {
      "x": -3,
      "y": 9,
      "z": -5,
      "name": "Rock_Stone"
    },
    {
      "x": -3,
      "y": 10,
      "z": -5,
      "name": "Rock_Stone"
    },
    {
      "x": -3,
      "y": 11,
      "z": -5,
      "name": "Rock_Stone"
    },
    {
      "x": -3,
      "y": 12,
      "z": -5,
      "name": "Rock_Stone"
    },
    {
      "x": -3,
      "y": 13,
      "z": -5,
      "name": "Rock_Stone"
    },
    {
      "x": -3,
      "y": 14,
      "z": -5,
      "name": "Rock_Stone"
    },
    {
      "x": -3,
      "y": 15,
      "z": -5,
      "name": "Rock_Stone"
    },
    {
      "x": -3,
      "y": 16,
      "z": -5,
      "name": "Rock_Stone"
    },
    {
      "x": -3,
      "y": 17,
      "z": -5,
      "name": "Rock_Stone"
    },
    {
      "x": -3,
      "y": 18,
      "z": -5,
      "name": "Rock_Stone"
    },
    {
      "x": -3,
      "y": 19,
      "z": -5,
      "name": "Soil_Dirt"
    },
    {
      "x": -3,
      "y": 20,
      "z": -5,
      "name": "Soil_Grass"
    },
    {
      "x": -3,
      "y": 28,
      "z": -5,
      "name": "Plant_Leaves_Beech"
    },
    {
      "x": -3,
      "y": 29,
      "z": -5,
      "name": "Plant_Leaves_Beech"
    },
    {
      "x": -3,
      "y": 30,
      "z": -5,
      "name": "Plant_Leaves_Beech"
    },
    {
      "x": -3,
      "y": 1,
      "z": -4,
      "name": "Rock_Stone"
    },
    {
      "x": -3,
      "y": 2,
      "z": -4,
      "name": "Rock_Stone"
    },
    {
      "x": -3,
      "y": 3,
      "z": -4,
      "name": "Rock_Stone_Mossy"
    },
    {
      "x": -3,
      "y": 4,
      "z": -4,
      "name": "Rock_Stone_Mossy"
    },
    {
      "x": -3,
      "y": 5,
      "z": -4,
      "name": "Rock_Stone_Mossy"
    },
    {
      "x": -3,
      "y": 6,
      "z": -4,
      "name": "Rock_Stone"
    },
    {
      "x": -3,
      "y": 7,
      "z": -4,
      "name": "Rock_Stone"
    },
    {
      "x": -3,
      "y": 8,
      "z": -4,
      "name": "Rock_Stone"
    },
    {
      "x": -3,
      "y": 9,
      "z": -4,
      "name": "Rock_Stone"
    },
    {
      "x": -3,
      "y": 10,
      "z": -4,
      "name": "Rock_Stone"
    },
    {
      "x": -3,
      "y": 11,
      "z": -4,
      "name": "Rock_Stone"
    },
    {
      "x": -3,
      "y": 12,
      "z": -4,
      "name": "Rock_Stone"
    },
    {
      "x": -3,
      "y": 13,
      "z": -4,
      "name": "Rock_Stone"
    },
    {
      "x": -3,
      "y": 14,
      "z": -4,
      "name": "Rock_Stone"
    },
    {
      "x": -3,
      "y": 15,
      "z": -4,
      "name": "Rock_Stone"
    },
    {
      "x": -3,
      "y": 16,
      "z": -4,
      "name": "Rock_Stone"
    },
    {
      "x": -3,
      "y": 17,
      "z": -4,
      "name": "Rock_Stone"
    },
    {
      "x": -3,
      "y": 18,
      "z": -4,
      "name": "Soil_Dirt"
    },
    {
      "x": -3,
      "y": 19,
      "z": -4,
      "name": "Soil_Dirt"
    },
    {
      "x": -3,
      "y": 20,
      "z": -4,
      "name": "Soil_Grass"
    },
    {
      "x": -3,
      "y": 21,
      "z": -4,
      "name": "Plant_Grass_Sharp_Tall"
    },
    {
      "x": -3,
      "y": 22,
      "z": -4,
      "name": "Plant_Grass_Sharp_Tall",
      "filler": 1024
    },
    {
      "x": -3,
      "y": 28,
      "z": -4,
      "name": "Plant_Leaves_Beech"
    },
    {
      "x": -3,
      "y": 29,
      "z": -4,
      "name": "Plant_Leaves_Beech"
    },
    {
      "x": -3,
      "y": 30,
      "z": -4,
      "name": "Plant_Leaves_Beech"
    },
    {
      "x": -3,
      "y": 31,
      "z": -4,
      "name": "Plant_Leaves_Beech"
    },
    {
      "x": -3,
      "y": 34,
      "z": -4,
      "name": "Plant_Leaves_Beech"
    },
    {
      "x": -3,
      "y": 0,
      "z": -3,
      "name": "Rock_Stone"
    },
    {
      "x": -3,
      "y": 1,
      "z": -3,
      "name": "Rock_Stone"
    },
    {
      "x": -3,
      "y": 2,
      "z": -3,
      "name": "Rock_Stone"
    },
    {
      "x": -3,
      "y": 3,
      "z": -3,
      "name": "Rock_Stone"
    },
    {
      "x": -3,
      "y": 4,
      "z": -3,
      "name": "Rock_Stone_Mossy"
    },
    {
      "x": -3,
      "y": 5,
      "z": -3,
      "name": "Rock_Stone"
    },
    {
      "x": -3,
      "y": 6,
      "z": -3,
      "name": "Rock_Stone"
    },
    {
      "x": -3,
      "y": 7,
      "z": -3,
      "name": "Rock_Stone"
    },
    {
      "x": -3,
      "y": 8,
      "z": -3,
      "name": "Rock_Stone"
    },
    {
      "x": -3,
      "y": 9,
      "z": -3,
      "name": "Rock_Stone"
    },
    {
      "x": -3,
      "y": 10,
      "z": -3,
      "name": "Rock_Stone"
    },
    {
      "x": -3,
      "y": 11,
      "z": -3,
      "name": "Rock_Stone"
    },
    {
      "x": -3,
      "y": 12,
      "z": -3,
      "name": "Rock_Stone"
    },
    {
      "x": -3,
      "y": 13,
      "z": -3,
      "name": "Rock_Stone"
    },
    {
      "x": -3,
      "y": 14,
      "z": -3,
      "name": "Rock_Stone"
    },
    {
      "x": -3,
      "y": 15,
      "z": -3,
      "name": "Rock_Stone"
    },
    {
      "x": -3,
      "y": 16,
      "z": -3,
      "name": "Rock_Stone"
    },
    {
      "x": -3,
      "y": 17,
      "z": -3,
      "name": "Rock_Stone"
    },
    {
      "x": -3,
      "y": 18,
      "z": -3,
      "name": "Rock_Stone"
    },
    {
      "x": -3,
      "y": 19,
      "z": -3,
      "name": "Soil_Dirt"
    },
    {
      "x": -3,
      "y": 20,
      "z": -3,
      "name": "Soil_Grass"
    },
    {
      "x": -3,
      "y": 21,
      "z": -3,
      "name": "Plant_Grass_Sharp_Tall"
    },
    {
      "x": -3,
      "y": 22,
      "z": -3,
      "name": "Plant_Grass_Sharp_Tall",
      "filler": 1024
    },
    {
      "x": -3,
      "y": 25,
      "z": -3,
      "name": "Wood_Beech_Branch_Long",
      "rotation": 5
    },
    {
      "x": -3,
      "y": 30,
      "z": -3,
      "name": "Plant_Leaves_Beech"
    },
    {
      "x": -3,
      "y": 31,
      "z": -3,
      "name": "Plant_Leaves_Beech"
    },
    {
      "x": -3,
      "y": 34,
      "z": -3,
      "name": "Plant_Leaves_Beech"
    },
    {
      "x": -3,
      "y": 35,
      "z": -3,
      "name": "Plant_Leaves_Beech"
    },
    {
      "x": -3,
      "y": 0,
      "z": -2,
      "name": "Rock_Stone"
    },
    {
      "x": -3,
      "y": 1,
      "z": -2,
      "name": "Rock_Stone"
    },
    {
      "x": -3,
      "y": 2,
      "z": -2,
      "name": "Rock_Stone"
    },
    {
      "x": -3,
      "y": 3,
      "z": -2,
      "name": "Rock_Stone"
    },
    {
      "x": -3,
      "y": 4,
      "z": -2,
      "name": "Rock_Stone"
    },
    {
      "x": -3,
      "y": 5,
      "z": -2,
      "name": "Rock_Stone"
    },
    {
      "x": -3,
      "y": 6,
      "z": -2,
      "name": "Rock_Stone"
    },
    {
      "x": -3,
      "y": 7,
      "z": -2,
      "name": "Rock_Stone"
    },
    {
      "x": -3,
      "y": 8,
      "z": -2,
      "name": "Rock_Stone"
    },
    {
      "x": -3,
      "y": 9,
      "z": -2,
      "name": "Rock_Stone"
    },
    {
      "x": -3,
      "y": 10,
      "z": -2,
      "name": "Rock_Stone"
    },
    {
      "x": -3,
      "y": 11,
      "z": -2,
      "name": "Rock_Stone"
    },
    {
      "x": -3,
      "y": 12,
      "z": -2,
      "name": "Rock_Stone"
    },
    {
      "x": -3,
      "y": 13,
      "z": -2,
      "name": "Rock_Stone"
    },
    {
      "x": -3,
      "y": 14,
      "z": -2,
      "name": "Rock_Stone"
    },
    {
      "x": -3,
      "y": 15,
      "z": -2,
      "name": "Rock_Stone"
    },
    {
      "x": -3,
      "y": 16,
      "z": -2,
      "name": "Rock_Stone"
    },
    {
      "x": -3,
      "y": 17,
      "z": -2,
      "name": "Soil_Grass"
    },
    {
      "x": -3,
      "y": 30,
      "z": -2,
      "name": "Plant_Leaves_Beech"
    },
    {
      "x": -3,
      "y": 31,
      "z": -2,
      "name": "Plant_Leaves_Beech"
    },
    {
      "x": -3,
      "y": 34,
      "z": -2,
      "name": "Plant_Leaves_Beech"
    },
    {
      "x": -3,
      "y": 35,
      "z": -2,
      "name": "Plant_Leaves_Beech"
    },
    {
      "x": -3,
      "y": 0,
      "z": -1,
      "name": "Rock_Stone"
    },
    {
      "x": -3,
      "y": 1,
      "z": -1,
      "name": "Rock_Stone"
    },
    {
      "x": -3,
      "y": 2,
      "z": -1,
      "name": "Rock_Stone"
    },
    {
      "x": -3,
      "y": 3,
      "z": -1,
      "name": "Rock_Stone"
    },
    {
      "x": -3,
      "y": 4,
      "z": -1,
      "name": "Rock_Stone"
    },
    {
      "x": -3,
      "y": 5,
      "z": -1,
      "name": "Rock_Stone"
    },
    {
      "x": -3,
      "y": 6,
      "z": -1,
      "name": "Rock_Stone"
    },
    {
      "x": -3,
      "y": 7,
      "z": -1,
      "name": "Rock_Stone"
    },
    {
      "x": -3,
      "y": 8,
      "z": -1,
      "name": "Rock_Stone"
    },
    {
      "x": -3,
      "y": 9,
      "z": -1,
      "name": "Rock_Stone"
    },
    {
      "x": -3,
      "y": 10,
      "z": -1,
      "name": "Rock_Stone"
    },
    {
      "x": -3,
      "y": 11,
      "z": -1,
      "name": "Rock_Stone"
    },
    {
      "x": -3,
      "y": 12,
      "z": -1,
      "name": "Rock_Stone"
    },
    {
      "x": -3,
      "y": 13,
      "z": -1,
      "name": "Rock_Stone"
    },
    {
      "x": -3,
      "y": 14,
      "z": -1,
      "name": "Rock_Stone"
    },
    {
      "x": -3,
      "y": 15,
      "z": -1,
      "name": "Rock_Stone"
    },
    {
      "x": -3,
      "y": 16,
      "z": -1,
      "name": "Rock_Stone"
    },
    {
      "x": -3,
      "y": 17,
      "z": -1,
      "name": "Soil_Grass"
    },
    {
      "x": -3,
      "y": 18,
      "z": -1,
      "name": "Plant_Grass_Sharp_Tall"
    },
    {
      "x": -3,
      "y": 19,
      "z": -1,
      "name": "Plant_Grass_Sharp_Tall",
      "filler": 1024
    },
    {
      "x": -3,
      "y": 29,
      "z": -1,
      "name": "Plant_Leaves_Beech"
    },
    {
      "x": -3,
      "y": 30,
      "z": -1,
      "name": "Plant_Leaves_Beech"
    },
    {
      "x": -3,
      "y": 34,
      "z": -1,
      "name": "Plant_Leaves_Beech"
    },
    {
      "x": -3,
      "y": 0,
      "z": 0,
      "name": "Rock_Stone"
    },
    {
      "x": -3,
      "y": 1,
      "z": 0,
      "name": "Rock_Stone"
    },
    {
      "x": -3,
      "y": 2,
      "z": 0,
      "name": "Rock_Stone"
    },
    {
      "x": -3,
      "y": 3,
      "z": 0,
      "name": "Rock_Stone"
    },
    {
      "x": -3,
      "y": 4,
      "z": 0,
      "name": "Rock_Stone"
    },
    {
      "x": -3,
      "y": 5,
      "z": 0,
      "name": "Rock_Stone"
    },
    {
      "x": -3,
      "y": 6,
      "z": 0,
      "name": "Rock_Stone"
    },
    {
      "x": -3,
      "y": 7,
      "z": 0,
      "name": "Rock_Stone"
    },
    {
      "x": -3,
      "y": 8,
      "z": 0,
      "name": "Rock_Stone"
    },
    {
      "x": -3,
      "y": 9,
      "z": 0,
      "name": "Rock_Stone"
    },
    {
      "x": -3,
      "y": 10,
      "z": 0,
      "name": "Rock_Stone"
    },
    {
      "x": -3,
      "y": 11,
      "z": 0,
      "name": "Rock_Stone"
    },
    {
      "x": -3,
      "y": 12,
      "z": 0,
      "name": "Rock_Stone"
    },
    {
      "x": -3,
      "y": 13,
      "z": 0,
      "name": "Rock_Stone"
    },
    {
      "x": -3,
      "y": 14,
      "z": 0,
      "name": "Rock_Stone"
    },
    {
      "x": -3,
      "y": 15,
      "z": 0,
      "name": "Rock_Stone"
    },
    {
      "x": -3,
      "y": 16,
      "z": 0,
      "name": "Rock_Stone"
    },
    {
      "x": -3,
      "y": 17,
      "z": 0,
      "name": "Soil_Grass"
    },
    {
      "x": -3,
      "y": 18,
      "z": 0,
      "name": "Plant_Grass_Sharp_Tall"
    },
    {
      "x": -3,
      "y": 19,
      "z": 0,
      "name": "Plant_Grass_Sharp_Tall",
      "filler": 1024
    },
    {
      "x": -3,
      "y": 29,
      "z": 0,
      "name": "Plant_Leaves_Beech"
    },
    {
      "x": -3,
      "y": 0,
      "z": 1,
      "name": "Rock_Quartzite_Brick"
    },
    {
      "x": -3,
      "y": 1,
      "z": 1,
      "name": "Rock_Quartzite_Brick"
    },
    {
      "x": -3,
      "y": 2,
      "z": 1,
      "name": "Rock_Quartzite_Brick"
    },
    {
      "x": -3,
      "y": 3,
      "z": 1,
      "name": "Rock_Quartzite_Brick"
    },
    {
      "x": -3,
      "y": 4,
      "z": 1,
      "name": "Rock_Quartzite_Brick"
    },
    {
      "x": -3,
      "y": 5,
      "z": 1,
      "name": "Rock_Quartzite_Brick"
    },
    {
      "x": -3,
      "y": 6,
      "z": 1,
      "name": "Rock_Stone"
    },
    {
      "x": -3,
      "y": 7,
      "z": 1,
      "name": "Rock_Stone"
    },
    {
      "x": -3,
      "y": 8,
      "z": 1,
      "name": "Rock_Stone"
    },
    {
      "x": -3,
      "y": 9,
      "z": 1,
      "name": "Rock_Stone"
    },
    {
      "x": -3,
      "y": 10,
      "z": 1,
      "name": "Rock_Stone"
    },
    {
      "x": -3,
      "y": 11,
      "z": 1,
      "name": "Rock_Stone_Brick_Smooth"
    },
    {
      "x": -3,
      "y": 12,
      "z": 1,
      "name": "Rock_Stone_Brick"
    },
    {
      "x": -3,
      "y": 13,
      "z": 1,
      "name": "Rock_Stone_Brick"
    },
    {
      "x": -3,
      "y": 14,
      "z": 1,
      "name": "Rock_Stone"
    },
    {
      "x": -3,
      "y": 15,
      "z": 1,
      "name": "Rock_Stone"
    },
    {
      "x": -3,
      "y": 16,
      "z": 1,
      "name": "Soil_Dirt"
    },
    {
      "x": -3,
      "y": 17,
      "z": 1,
      "name": "Rock_Stone"
    },
    {
      "x": -3,
      "y": 18,
      "z": 1,
      "name": "Rock_Stone"
    },
    {
      "x": -3,
      "y": 25,
      "z": 1,
      "name": "Plant_Leaves_Beech"
    },
    {
      "x": -3,
      "y": 0,
      "z": 2,
      "name": "Rock_Quartzite_Brick"
    },
    {
      "x": -3,
      "y": 1,
      "z": 2,
      "name": "Rock_Quartzite_Brick"
    },
    {
      "x": -3,
      "y": 2,
      "z": 2,
      "name": "Rock_Quartzite_Brick"
    },
    {
      "x": -3,
      "y": 3,
      "z": 2,
      "name": "Rock_Quartzite_Brick"
    },
    {
      "x": -3,
      "y": 4,
      "z": 2,
      "name": "Rock_Quartzite_Brick"
    },
    {
      "x": -3,
      "y": 5,
      "z": 2,
      "name": "Rock_Stone"
    },
    {
      "x": -3,
      "y": 6,
      "z": 2,
      "name": "Rock_Stone_Brick_Smooth"
    },
    {
      "x": -3,
      "y": 7,
      "z": 2,
      "name": "Rock_Stone_Brick_Smooth"
    },
    {
      "x": -3,
      "y": 8,
      "z": 2,
      "name": "Rock_Stone_Brick_Smooth"
    },
    {
      "x": -3,
      "y": 9,
      "z": 2,
      "name": "Rock_Stone_Brick_Smooth"
    },
    {
      "x": -3,
      "y": 10,
      "z": 2,
      "name": "Rock_Stone_Brick_Smooth"
    },
    {
      "x": -3,
      "y": 11,
      "z": 2,
      "name": "Rock_Stone_Brick_Smooth"
    },
    {
      "x": -3,
      "y": 12,
      "z": 2,
      "name": "Rock_Stone_Brick"
    },
    {
      "x": -3,
      "y": 13,
      "z": 2,
      "name": "Rock_Stone"
    },
    {
      "x": -3,
      "y": 14,
      "z": 2,
      "name": "Rock_Stone"
    },
    {
      "x": -3,
      "y": 15,
      "z": 2,
      "name": "Rock_Stone"
    },
    {
      "x": -3,
      "y": 16,
      "z": 2,
      "name": "Rock_Stone"
    },
    {
      "x": -3,
      "y": 17,
      "z": 2,
      "name": "Rock_Stone"
    },
    {
      "x": -3,
      "y": 0,
      "z": 3,
      "name": "Rock_Quartzite_Brick"
    },
    {
      "x": -3,
      "y": 1,
      "z": 3,
      "name": "Rock_Quartzite_Brick"
    },
    {
      "x": -3,
      "y": 2,
      "z": 3,
      "name": "Rock_Quartzite_Brick"
    },
    {
      "x": -3,
      "y": 3,
      "z": 3,
      "name": "Rock_Stone"
    },
    {
      "x": -3,
      "y": 4,
      "z": 3,
      "name": "Rock_Stone"
    },
    {
      "x": -3,
      "y": 5,
      "z": 3,
      "name": "Rock_Stone"
    },
    {
      "x": -3,
      "y": 6,
      "z": 3,
      "name": "Rock_Stone"
    },
    {
      "x": -3,
      "y": 7,
      "z": 3,
      "name": "Rock_Stone"
    },
    {
      "x": -3,
      "y": 8,
      "z": 3,
      "name": "Rock_Stone"
    },
    {
      "x": -3,
      "y": 9,
      "z": 3,
      "name": "Rock_Stone"
    },
    {
      "x": -3,
      "y": 10,
      "z": 3,
      "name": "Rock_Stone"
    },
    {
      "x": -3,
      "y": 11,
      "z": 3,
      "name": "Rock_Stone"
    },
    {
      "x": -3,
      "y": 12,
      "z": 3,
      "name": "Rock_Stone"
    },
    {
      "x": -3,
      "y": 13,
      "z": 3,
      "name": "Rock_Stone"
    },
    {
      "x": -3,
      "y": 14,
      "z": 3,
      "name": "Plant_Moss_Rug_Green"
    },
    {
      "x": -3,
      "y": 0,
      "z": 4,
      "name": "Rock_Quartzite_Brick"
    },
    {
      "x": -3,
      "y": 1,
      "z": 4,
      "name": "Rock_Quartzite_Brick"
    },
    {
      "x": -3,
      "y": 2,
      "z": 4,
      "name": "Rock_Stone"
    },
    {
      "x": -3,
      "y": 3,
      "z": 4,
      "name": "Rock_Stone"
    },
    {
      "x": -3,
      "y": 4,
      "z": 4,
      "name": "Rock_Stone"
    },
    {
      "x": -3,
      "y": 5,
      "z": 4,
      "name": "Rock_Stone"
    },
    {
      "x": -3,
      "y": 6,
      "z": 4,
      "name": "Rock_Stone"
    },
    {
      "x": -3,
      "y": 7,
      "z": 4,
      "name": "Rock_Stone"
    },
    {
      "x": -3,
      "y": 8,
      "z": 4,
      "name": "Rock_Stone"
    },
    {
      "x": -3,
      "y": 9,
      "z": 4,
      "name": "Rock_Stone"
    },
    {
      "x": -3,
      "y": 10,
      "z": 4,
      "name": "Rock_Stone"
    },
    {
      "x": -3,
      "y": 11,
      "z": 4,
      "name": "Rock_Stone_Cobble"
    },
    {
      "x": -3,
      "y": 12,
      "z": 4,
      "name": "Plant_Moss_Block_Green"
    },
    {
      "x": -3,
      "y": 1,
      "z": 5,
      "name": "Rock_Stone"
    },
    {
      "x": -3,
      "y": 2,
      "z": 5,
      "name": "Rock_Stone"
    },
    {
      "x": -3,
      "y": 3,
      "z": 5,
      "name": "Rock_Stone"
    },
    {
      "x": -3,
      "y": 4,
      "z": 5,
      "name": "Rock_Stone"
    },
    {
      "x": -3,
      "y": 5,
      "z": 5,
      "name": "Rock_Stone"
    },
    {
      "x": -3,
      "y": 6,
      "z": 5,
      "name": "Rock_Stone"
    },
    {
      "x": -3,
      "y": 7,
      "z": 5,
      "name": "Rock_Stone"
    },
    {
      "x": -3,
      "y": 8,
      "z": 5,
      "name": "Rock_Stone"
    },
    {
      "x": -3,
      "y": 9,
      "z": 5,
      "name": "Rock_Stone"
    },
    {
      "x": -3,
      "y": 10,
      "z": 5,
      "name": "Rock_Stone"
    },
    {
      "x": -3,
      "y": 11,
      "z": 5,
      "name": "Soil_Grass"
    },
    {
      "x": -3,
      "y": 12,
      "z": 5,
      "name": "Plant_Moss_Rug_Green"
    },
    {
      "x": -3,
      "y": 1,
      "z": 6,
      "name": "Rock_Stone"
    },
    {
      "x": -3,
      "y": 2,
      "z": 6,
      "name": "Rock_Stone"
    },
    {
      "x": -3,
      "y": 3,
      "z": 6,
      "name": "Rock_Stone"
    },
    {
      "x": -3,
      "y": 4,
      "z": 6,
      "name": "Rock_Stone"
    },
    {
      "x": -3,
      "y": 5,
      "z": 6,
      "name": "Rock_Stone"
    },
    {
      "x": -3,
      "y": 6,
      "z": 6,
      "name": "Rock_Stone"
    },
    {
      "x": -3,
      "y": 7,
      "z": 6,
      "name": "Rock_Stone_Mossy"
    },
    {
      "x": -3,
      "y": 8,
      "z": 6,
      "name": "Rock_Stone"
    },
    {
      "x": -3,
      "y": 9,
      "z": 6,
      "name": "Rock_Stone"
    },
    {
      "x": -3,
      "y": 10,
      "z": 6,
      "name": "Rock_Stone_Mossy"
    },
    {
      "x": -3,
      "y": 11,
      "z": 6,
      "name": "Soil_Grass"
    },
    {
      "x": -3,
      "y": 12,
      "z": 6,
      "name": "*Plant_Crop_Berry_Block_State_Definitions_StageFinal",
      "components": {
        "Components": {
          "FarmingBlock": {
            "LastTickGameTime": "0001-01-01T12:00:00Z"
          }
        }
      }
    },
    {
      "x": -3,
      "y": 1,
      "z": 7,
      "name": "Rock_Stone"
    },
    {
      "x": -3,
      "y": 2,
      "z": 7,
      "name": "Rock_Stone"
    },
    {
      "x": -3,
      "y": 3,
      "z": 7,
      "name": "Rock_Stone"
    },
    {
      "x": -3,
      "y": 4,
      "z": 7,
      "name": "Rock_Stone"
    },
    {
      "x": -3,
      "y": 5,
      "z": 7,
      "name": "Rock_Stone"
    },
    {
      "x": -3,
      "y": 6,
      "z": 7,
      "name": "Rock_Stone_Mossy"
    },
    {
      "x": -3,
      "y": 7,
      "z": 7,
      "name": "Rock_Stone_Mossy"
    },
    {
      "x": -3,
      "y": 8,
      "z": 7,
      "name": "Rock_Stone_Mossy"
    },
    {
      "x": -3,
      "y": 2,
      "z": 8,
      "name": "Rock_Stone"
    },
    {
      "x": -3,
      "y": 3,
      "z": 8,
      "name": "Rock_Stone"
    },
    {
      "x": -3,
      "y": 4,
      "z": 8,
      "name": "Rock_Stone"
    },
    {
      "x": -3,
      "y": 5,
      "z": 8,
      "name": "Rock_Stone"
    },
    {
      "x": -2,
      "y": 9,
      "z": -9,
      "name": "Rock_Stone"
    },
    {
      "x": -2,
      "y": 10,
      "z": -9,
      "name": "Rock_Stone"
    },
    {
      "x": -2,
      "y": 11,
      "z": -9,
      "name": "Rock_Stone"
    },
    {
      "x": -2,
      "y": 12,
      "z": -9,
      "name": "Rock_Stone_Mossy"
    },
    {
      "x": -2,
      "y": 13,
      "z": -9,
      "name": "Rock_Stone_Mossy"
    },
    {
      "x": -2,
      "y": 14,
      "z": -9,
      "name": "Rock_Stone_Mossy"
    },
    {
      "x": -2,
      "y": 7,
      "z": -8,
      "name": "Rock_Stone"
    },
    {
      "x": -2,
      "y": 8,
      "z": -8,
      "name": "Rock_Stone"
    },
    {
      "x": -2,
      "y": 9,
      "z": -8,
      "name": "Rock_Stone"
    },
    {
      "x": -2,
      "y": 10,
      "z": -8,
      "name": "Rock_Stone"
    },
    {
      "x": -2,
      "y": 11,
      "z": -8,
      "name": "Rock_Stone"
    },
    {
      "x": -2,
      "y": 12,
      "z": -8,
      "name": "Rock_Stone"
    },
    {
      "x": -2,
      "y": 13,
      "z": -8,
      "name": "Rock_Stone_Mossy"
    },
    {
      "x": -2,
      "y": 14,
      "z": -8,
      "name": "Rock_Stone_Mossy"
    },
    {
      "x": -2,
      "y": 15,
      "z": -8,
      "name": "Rubble_Stone_Medium"
    },
    {
      "x": -2,
      "y": 7,
      "z": -7,
      "name": "Rock_Stone_Mossy"
    },
    {
      "x": -2,
      "y": 8,
      "z": -7,
      "name": "Rock_Stone"
    },
    {
      "x": -2,
      "y": 9,
      "z": -7,
      "name": "Rock_Stone"
    },
    {
      "x": -2,
      "y": 10,
      "z": -7,
      "name": "Rock_Stone"
    },
    {
      "x": -2,
      "y": 11,
      "z": -7,
      "name": "Rock_Stone"
    },
    {
      "x": -2,
      "y": 12,
      "z": -7,
      "name": "Rock_Stone"
    },
    {
      "x": -2,
      "y": 13,
      "z": -7,
      "name": "Rock_Stone"
    },
    {
      "x": -2,
      "y": 14,
      "z": -7,
      "name": "Rock_Stone"
    },
    {
      "x": -2,
      "y": 15,
      "z": -7,
      "name": "Rock_Stone"
    },
    {
      "x": -2,
      "y": 16,
      "z": -7,
      "name": "Rock_Stone"
    },
    {
      "x": -2,
      "y": 17,
      "z": -7,
      "name": "Rock_Stone"
    },
    {
      "x": -2,
      "y": 18,
      "z": -7,
      "name": "Rock_Stone"
    },
    {
      "x": -2,
      "y": 5,
      "z": -6,
      "name": "Rock_Stone_Mossy"
    },
    {
      "x": -2,
      "y": 6,
      "z": -6,
      "name": "Rock_Stone_Mossy"
    },
    {
      "x": -2,
      "y": 7,
      "z": -6,
      "name": "Rock_Stone"
    },
    {
      "x": -2,
      "y": 8,
      "z": -6,
      "name": "Rock_Stone"
    },
    {
      "x": -2,
      "y": 9,
      "z": -6,
      "name": "Rock_Stone"
    },
    {
      "x": -2,
      "y": 10,
      "z": -6,
      "name": "Rock_Stone"
    },
    {
      "x": -2,
      "y": 11,
      "z": -6,
      "name": "Rock_Stone"
    },
    {
      "x": -2,
      "y": 12,
      "z": -6,
      "name": "Rock_Stone"
    },
    {
      "x": -2,
      "y": 13,
      "z": -6,
      "name": "Rock_Stone"
    },
    {
      "x": -2,
      "y": 14,
      "z": -6,
      "name": "Rock_Stone"
    },
    {
      "x": -2,
      "y": 15,
      "z": -6,
      "name": "Rock_Stone"
    },
    {
      "x": -2,
      "y": 16,
      "z": -6,
      "name": "Rock_Stone"
    },
    {
      "x": -2,
      "y": 17,
      "z": -6,
      "name": "Rock_Stone"
    },
    {
      "x": -2,
      "y": 18,
      "z": -6,
      "name": "Rock_Stone"
    },
    {
      "x": -2,
      "y": 19,
      "z": -6,
      "name": "Soil_Grass"
    },
    {
      "x": -2,
      "y": 27,
      "z": -6,
      "name": "Plant_Leaves_Beech"
    },
    {
      "x": -2,
      "y": 28,
      "z": -6,
      "name": "Plant_Leaves_Beech"
    },
    {
      "x": -2,
      "y": 29,
      "z": -6,
      "name": "Plant_Leaves_Beech"
    },
    {
      "x": -2,
      "y": 33,
      "z": -6,
      "name": "Plant_Leaves_Beech"
    },
    {
      "x": -2,
      "y": 2,
      "z": -5,
      "name": "Rock_Stone_Mossy"
    },
    {
      "x": -2,
      "y": 3,
      "z": -5,
      "name": "Rock_Stone_Mossy"
    },
    {
      "x": -2,
      "y": 4,
      "z": -5,
      "name": "Rock_Stone_Mossy"
    },
    {
      "x": -2,
      "y": 5,
      "z": -5,
      "name": "Rock_Stone_Mossy"
    },
    {
      "x": -2,
      "y": 6,
      "z": -5,
      "name": "Rock_Stone_Mossy"
    },
    {
      "x": -2,
      "y": 7,
      "z": -5,
      "name": "Rock_Stone"
    },
    {
      "x": -2,
      "y": 8,
      "z": -5,
      "name": "Rock_Stone"
    },
    {
      "x": -2,
      "y": 9,
      "z": -5,
      "name": "Rock_Stone"
    },
    {
      "x": -2,
      "y": 10,
      "z": -5,
      "name": "Rock_Stone"
    },
    {
      "x": -2,
      "y": 11,
      "z": -5,
      "name": "Rock_Stone"
    },
    {
      "x": -2,
      "y": 12,
      "z": -5,
      "name": "Rock_Stone"
    },
    {
      "x": -2,
      "y": 13,
      "z": -5,
      "name": "Rock_Stone"
    },
    {
      "x": -2,
      "y": 14,
      "z": -5,
      "name": "Rock_Stone"
    },
    {
      "x": -2,
      "y": 15,
      "z": -5,
      "name": "Rock_Stone"
    },
    {
      "x": -2,
      "y": 16,
      "z": -5,
      "name": "Rock_Stone"
    },
    {
      "x": -2,
      "y": 17,
      "z": -5,
      "name": "Rock_Stone"
    },
    {
      "x": -2,
      "y": 18,
      "z": -5,
      "name": "Soil_Dirt"
    },
    {
      "x": -2,
      "y": 19,
      "z": -5,
      "name": "Soil_Dirt"
    },
    {
      "x": -2,
      "y": 20,
      "z": -5,
      "name": "Soil_Grass"
    },
    {
      "x": -2,
      "y": 21,
      "z": -5,
      "name": "Plant_Grass_Sharp_Short"
    },
    {
      "x": -2,
      "y": 28,
      "z": -5,
      "name": "Plant_Leaves_Beech"
    },
    {
      "x": -2,
      "y": 29,
      "z": -5,
      "name": "Plant_Leaves_Beech"
    },
    {
      "x": -2,
      "y": 30,
      "z": -5,
      "name": "Plant_Leaves_Beech"
    },
    {
      "x": -2,
      "y": 33,
      "z": -5,
      "name": "Plant_Leaves_Beech"
    },
    {
      "x": -2,
      "y": 34,
      "z": -5,
      "name": "Plant_Leaves_Beech"
    },
    {
      "x": -2,
      "y": 1,
      "z": -4,
      "name": "Rock_Stone_Mossy"
    },
    {
      "x": -2,
      "y": 2,
      "z": -4,
      "name": "Rock_Stone_Mossy"
    },
    {
      "x": -2,
      "y": 3,
      "z": -4,
      "name": "Rock_Stone_Mossy"
    },
    {
      "x": -2,
      "y": 4,
      "z": -4,
      "name": "Rock_Stone_Mossy"
    },
    {
      "x": -2,
      "y": 5,
      "z": -4,
      "name": "Rock_Stone_Mossy"
    },
    {
      "x": -2,
      "y": 6,
      "z": -4,
      "name": "Rock_Stone_Mossy"
    },
    {
      "x": -2,
      "y": 7,
      "z": -4,
      "name": "Rock_Stone"
    },
    {
      "x": -2,
      "y": 8,
      "z": -4,
      "name": "Rock_Stone"
    },
    {
      "x": -2,
      "y": 9,
      "z": -4,
      "name": "Rock_Stone"
    },
    {
      "x": -2,
      "y": 10,
      "z": -4,
      "name": "Rock_Stone"
    },
    {
      "x": -2,
      "y": 11,
      "z": -4,
      "name": "Rock_Stone"
    },
    {
      "x": -2,
      "y": 12,
      "z": -4,
      "name": "Rock_Stone"
    },
    {
      "x": -2,
      "y": 13,
      "z": -4,
      "name": "Rock_Stone"
    },
    {
      "x": -2,
      "y": 14,
      "z": -4,
      "name": "Rock_Stone"
    },
    {
      "x": -2,
      "y": 15,
      "z": -4,
      "name": "Rock_Stone"
    },
    {
      "x": -2,
      "y": 16,
      "z": -4,
      "name": "Rock_Stone"
    },
    {
      "x": -2,
      "y": 17,
      "z": -4,
      "name": "Soil_Dirt"
    },
    {
      "x": -2,
      "y": 18,
      "z": -4,
      "name": "Soil_Dirt"
    },
    {
      "x": -2,
      "y": 19,
      "z": -4,
      "name": "Soil_Dirt"
    },
    {
      "x": -2,
      "y": 20,
      "z": -4,
      "name": "Soil_Grass"
    },
    {
      "x": -2,
      "y": 21,
      "z": -4,
      "name": "Plant_Grass_Sharp"
    },
    {
      "x": -2,
      "y": 28,
      "z": -4,
      "name": "Plant_Leaves_Beech"
    },
    {
      "x": -2,
      "y": 29,
      "z": -4,
      "name": "Plant_Leaves_Beech"
    },
    {
      "x": -2,
      "y": 30,
      "z": -4,
      "name": "Plant_Leaves_Beech"
    },
    {
      "x": -2,
      "y": 31,
      "z": -4,
      "name": "Plant_Leaves_Beech"
    },
    {
      "x": -2,
      "y": 34,
      "z": -4,
      "name": "Plant_Leaves_Beech"
    },
    {
      "x": -2,
      "y": 35,
      "z": -4,
      "name": "Plant_Leaves_Beech"
    },
    {
      "x": -2,
      "y": 0,
      "z": -3,
      "name": "Rock_Stone"
    },
    {
      "x": -2,
      "y": 1,
      "z": -3,
      "name": "Rock_Stone"
    },
    {
      "x": -2,
      "y": 2,
      "z": -3,
      "name": "Rock_Stone_Mossy"
    },
    {
      "x": -2,
      "y": 3,
      "z": -3,
      "name": "Rock_Stone_Mossy"
    },
    {
      "x": -2,
      "y": 4,
      "z": -3,
      "name": "Rock_Stone_Mossy"
    },
    {
      "x": -2,
      "y": 5,
      "z": -3,
      "name": "Rock_Stone_Mossy"
    },
    {
      "x": -2,
      "y": 6,
      "z": -3,
      "name": "Rock_Stone"
    },
    {
      "x": -2,
      "y": 7,
      "z": -3,
      "name": "Rock_Stone"
    },
    {
      "x": -2,
      "y": 8,
      "z": -3,
      "name": "Rock_Stone"
    },
    {
      "x": -2,
      "y": 9,
      "z": -3,
      "name": "Rock_Stone"
    },
    {
      "x": -2,
      "y": 10,
      "z": -3,
      "name": "Rock_Stone"
    },
    {
      "x": -2,
      "y": 11,
      "z": -3,
      "name": "Rock_Stone"
    },
    {
      "x": -2,
      "y": 12,
      "z": -3,
      "name": "Rock_Stone"
    },
    {
      "x": -2,
      "y": 13,
      "z": -3,
      "name": "Rock_Stone"
    },
    {
      "x": -2,
      "y": 14,
      "z": -3,
      "name": "Rock_Stone"
    },
    {
      "x": -2,
      "y": 15,
      "z": -3,
      "name": "Rock_Stone"
    },
    {
      "x": -2,
      "y": 16,
      "z": -3,
      "name": "Rock_Stone"
    },
    {
      "x": -2,
      "y": 17,
      "z": -3,
      "name": "Rock_Stone"
    },
    {
      "x": -2,
      "y": 18,
      "z": -3,
      "name": "Soil_Dirt"
    },
    {
      "x": -2,
      "y": 19,
      "z": -3,
      "name": "Soil_Dirt"
    },
    {
      "x": -2,
      "y": 20,
      "z": -3,
      "name": "Soil_Grass"
    },
    {
      "x": -2,
      "y": 21,
      "z": -3,
      "name": "Plant_Grass_Sharp_Tall"
    },
    {
      "x": -2,
      "y": 22,
      "z": -3,
      "name": "Plant_Grass_Sharp_Tall",
      "filler": 1024
    },
    {
      "x": -2,
      "y": 25,
      "z": -3,
      "name": "Wood_Beech_Branch_Long",
      "rotation": 5
    },
    {
      "x": -2,
      "y": 30,
