{
  "version": 8,
  "blockIdVersion": 10,
  "anchorX": 1,
  "anchorY": 4,
  "anchorZ": 1,
  "blocks": [
    {
      "x": -10,
      "y": 36,
      "z": -1,
      "name": "Plant_Leaves_Fig_Blue"
    },
    {
      "x": -10,
      "y": 38,
      "z": -1,
      "name": "Plant_Leaves_Fig_Blue"
    },
    {
      "x": -10,
      "y": 36,
      "z": 0,
      "name": "Plant_Leaves_Fig_Blue"
    },
    {
      "x": -10,
      "y": 37,
      "z": 0,
      "name": "Plant_Leaves_Fig_Blue"
    },
    {
      "x": -10,
      "y": 38,
      "z": 0,
      "name": "Plant_Leaves_Fig_Blue"
    },
    {
      "x": -10,
      "y": 37,
      "z": 1,
      "name": "Plant_Leaves_Fig_Blue"
    },
    {
      "x": -10,
      "y": 38,
      "z": 1,
      "name": "Plant_Leaves_Fig_Blue"
    },
    {
      "x": -10,
      "y": 39,
      "z": 1,
      "name": "Plant_Leaves_Fig_Blue"
    },
    {
      "x": -10,
      "y": 38,
      "z": 2,
      "name": "Plant_Leaves_Fig_Blue"
    },
    {
      "x": -9,
      "y": 36,
      "z": -3,
      "name": "Plant_Leaves_Fig_Blue"
    },
    {
      "x": -9,
      "y": 38,
      "z": -3,
      "name": "Plant_Leaves_Fig_Blue"
    },
    {
      "x": -9,
      "y": 39,
      "z": -3,
      "name": "Plant_Leaves_Fig_Blue"
    },
    {
      "x": -9,
      "y": 35,
      "z": -2,
      "name": "Plant_Leaves_Fig_Blue"
    },
    {
      "x": -9,
      "y": 36,
      "z": -2,
      "name": "Plant_Leaves_Fig_Blue"
    },
    {
      "x": -9,
      "y": 37,
      "z": -2,
      "name": "Plant_Leaves_Fig_Blue"
    },
    {
      "x": -9,
      "y": 38,
      "z": -2,
      "name": "Plant_Leaves_Fig_Blue"
    },
    {
      "x": -9,
      "y": 35,
      "z": -1,
      "name": "Plant_Leaves_Fig_Blue"
    },
    {
      "x": -9,
      "y": 36,
      "z": -1,
      "name": "Plant_Leaves_Fig_Blue"
    },
    {
      "x": -9,
      "y": 37,
      "z": -1,
      "name": "Plant_Leaves_Fig_Blue"
    },
    {
      "x": -9,
      "y": 38,
      "z": -1,
      "name": "Plant_Leaves_Fig_Blue"
    },
    {
      "x": -9,
      "y": 39,
      "z": -1,
      "name": "Plant_Leaves_Fig_Blue"
    },
    {
      "x": -9,
      "y": 40,
      "z": -1,
      "name": "Plant_Leaves_Fig_Blue"
    },
    {
      "x": -9,
      "y": 40,
      "z": 0,
      "name": "Plant_Leaves_Fig_Blue"
    },
    {
      "x": -9,
      "y": 37,
      "z": 2,
      "name": "Plant_Leaves_Fig_Blue"
    },
    {
      "x": -9,
      "y": 38,
      "z": 2,
      "name": "Plant_Leaves_Fig_Blue"
    },
    {
      "x": -9,
      "y": 39,
      "z": 2,
      "name": "Plant_Leaves_Fig_Blue"
    },
    {
      "x": -9,
      "y": 40,
      "z": 2,
      "name": "Plant_Leaves_Fig_Blue"
    },
    {
      "x": -9,
      "y": 37,
      "z": 3,
      "name": "Plant_Leaves_Fig_Blue"
    },
    {
      "x": -9,
      "y": 38,
      "z": 3,
      "name": "Plant_Leaves_Fig_Blue"
    },
    {
      "x": -9,
      "y": 39,
      "z": 3,
      "name": "Plant_Leaves_Fig_Blue"
    },
    {
      "x": -9,
      "y": 38,
      "z": 4,
      "name": "Plant_Leaves_Fig_Blue"
    },
    {
      "x": -8,
      "y": 34,
      "z": -4,
      "name": "Plant_Leaves_Fig_Blue"
    },
    {
      "x": -8,
      "y": 35,
      "z": -4,
      "name": "Plant_Leaves_Fig_Blue"
    },
    {
      "x": -8,
      "y": 36,
      "z": -4,
      "name": "Plant_Leaves_Fig_Blue"
    },
    {
      "x": -8,
      "y": 37,
      "z": -4,
      "name": "Plant_Leaves_Fig_Blue"
    },
    {
      "x": -8,
      "y": 38,
      "z": -4,
      "name": "Plant_Leaves_Fig_Blue"
    },
    {
      "x": -8,
      "y": 36,
      "z": -3,
      "name": "Plant_Leaves_Fig_Blue"
    },
    {
      "x": -8,
      "y": 37,
      "z": -3,
      "name": "Plant_Leaves_Fig_Blue"
    },
    {
      "x": -8,
      "y": 38,
      "z": -3,
      "name": "Plant_Leaves_Fig_Blue"
    },
    {
      "x": -8,
      "y": 39,
      "z": -3,
      "name": "Plant_Leaves_Fig_Blue"
    },
    {
      "x": -8,
      "y": 40,
      "z": -3,
      "name": "Plant_Leaves_Fig_Blue"
    },
    {
      "x": -8,
      "y": 38,
      "z": -2,
      "name": "Plant_Leaves_Fig_Blue"
    },
    {
      "x": -8,
      "y": 40,
      "z": -2,
      "name": "Plant_Leaves_Fig_Blue"
    },
    {
      "x": -8,
      "y": 39,
      "z": -1,
      "name": "Wood_Fig_Blue_Branch_Corner",
      "rotation": 3
    },
    {
      "x": -8,
      "y": 40,
      "z": -1,
      "name": "Plant_Leaves_Fig_Blue"
    },
    {
      "x": -8,
      "y": 40,
      "z": 0,
      "name": "Plant_Leaves_Fig_Blue"
    },
    {
      "x": -8,
      "y": 40,
      "z": 1,
      "name": "Plant_Leaves_Fig_Blue"
    },
    {
      "x": -8,
      "y": 39,
      "z": 2,
      "name": "Wood_Fig_Blue_Branch_Corner",
      "rotation": 3
    },
    {
      "x": -8,
      "y": 40,
      "z": 2,
      "name": "Wood_Fig_Blue_Branch_Long"
    },
    {
      "x": -8,
      "y": 41,
      "z": 2,
      "name": "Plant_Leaves_Fig_Blue"
    },
    {
      "x": -8,
      "y": 40,
      "z": 3,
      "name": "Plant_Leaves_Fig_Blue"
    },
    {
      "x": -8,
      "y": 37,
      "z": 4,
      "name": "Plant_Leaves_Fig_Blue"
    },
    {
      "x": -8,
      "y": 38,
      "z": 4,
      "name": "Plant_Leaves_Fig_Blue"
    },
    {
      "x": -8,
      "y": 39,
      "z": 4,
      "name": "Plant_Leaves_Fig_Blue"
    },
    {
      "x": -7,
      "y": 36,
      "z": -5,
      "name": "Plant_Leaves_Fig_Blue"
    },
    {
      "x": -7,
      "y": 37,
      "z": -5,
      "name": "Plant_Leaves_Fig_Blue"
    },
    {
      "x": -7,
      "y": 38,
      "z": -5,
      "name": "Plant_Leaves_Fig_Blue"
    },
    {
      "x": -7,
      "y": 34,
      "z": -4,
      "name": "Plant_Leaves_Fig_Blue"
    },
    {
      "x": -7,
      "y": 35,
      "z": -4,
      "name": "Plant_Leaves_Fig_Blue"
    },
    {
      "x": -7,
      "y": 38,
      "z": -4,
      "name": "Plant_Leaves_Fig_Blue"
    },
    {
      "x": -7,
      "y": 39,
      "z": -4,
      "name": "Plant_Leaves_Fig_Blue"
    },
    {
      "x": -7,
      "y": 39,
      "z": -3,
      "name": "Plant_Leaves_Fig_Blue"
    },
    {
      "x": -7,
      "y": 40,
      "z": -3,
      "name": "Plant_Leaves_Fig_Blue"
    },
    {
      "x": -7,
      "y": 40,
      "z": -2,
      "name": "Plant_Leaves_Fig_Blue"
    },
    {
      "x": -7,
      "y": 39,
      "z": -1,
      "name": "Wood_Fig_Blue_Branch_Long",
      "rotation": 5
    },
    {
      "x": -7,
      "y": 40,
      "z": -1,
      "name": "Plant_Leaves_Fig_Blue"
    },
    {
      "x": -7,
      "y": 40,
      "z": 0,
      "name": "Plant_Leaves_Fig_Blue"
    },
    {
      "x": -7,
      "y": 41,
      "z": 0,
      "name": "Plant_Leaves_Fig_Blue"
    },
    {
      "x": -7,
      "y": 39,
      "z": 2,
      "name": "Wood_Fig_Blue_Branch_Long",
      "rotation": 5
    },
    {
      "x": -7,
      "y": 40,
      "z": 2,
      "name": "Plant_Leaves_Fig_Blue"
    },
    {
      "x": -7,
      "y": 41,
      "z": 2,
      "name": "Plant_Leaves_Fig_Blue"
    },
    {
      "x": -7,
      "y": 40,
      "z": 3,
      "name": "Plant_Leaves_Fig_Blue"
    },
    {
      "x": -7,
      "y": 38,
      "z": 4,
      "name": "Plant_Leaves_Fig_Blue"
    },
    {
      "x": -7,
      "y": 39,
      "z": 4,
      "name": "Plant_Leaves_Fig_Blue"
    },
    {
      "x": -7,
      "y": 37,
      "z": 5,
      "name": "Plant_Leaves_Fig_Blue"
    },
    {
      "x": -7,
      "y": 38,
      "z": 5,
      "name": "Plant_Leaves_Fig_Blue"
    },
    {
      "x": -6,
      "y": 35,
      "z": -6,
      "name": "Plant_Leaves_Fig_Blue"
    },
    {
      "x": -6,
      "y": 36,
      "z": -6,
      "name": "Plant_Leaves_Fig_Blue"
    },
    {
      "x": -6,
      "y": 37,
      "z": -6,
      "name": "Plant_Leaves_Fig_Blue"
    },
    {
      "x": -6,
      "y": 34,
      "z": -5,
      "name": "Plant_Leaves_Fig_Blue"
    },
    {
      "x": -6,
      "y": 35,
      "z": -5,
      "name": "Plant_Leaves_Fig_Blue"
    },
    {
      "x": -6,
      "y": 36,
      "z": -5,
      "name": "Plant_Leaves_Fig_Blue"
    },
    {
      "x": -6,
      "y": 37,
      "z": -5,
      "name": "Plant_Leaves_Fig_Blue"
    },
    {
      "x": -6,
      "y": 38,
      "z": -5,
      "name": "Plant_Leaves_Fig_Blue"
    },
    {
      "x": -6,
      "y": 39,
      "z": -5,
      "name": "Plant_Leaves_Fig_Blue"
    },
    {
      "x": -6,
      "y": 34,
      "z": -4,
      "name": "Plant_Leaves_Fig_Blue"
    },
    {
      "x": -6,
      "y": 35,
      "z": -4,
      "name": "Plant_Leaves_Fig_Blue"
    },
    {
      "x": -6,
      "y": 38,
      "z": -4,
      "name": "Plant_Leaves_Fig_Blue"
    },
    {
      "x": -6,
      "y": 39,
      "z": -4,
      "name": "Plant_Leaves_Fig_Blue"
    },
    {
      "x": -6,
      "y": 40,
      "z": -4,
      "name": "Plant_Leaves_Fig_Blue"
    },
    {
      "x": -6,
      "y": 41,
      "z": -2,
      "name": "Plant_Leaves_Fig_Blue"
    },
    {
      "x": -6,
      "y": 39,
      "z": -1,
      "name": "Wood_Fig_Blue_Branch_Long",
      "rotation": 5
    },
    {
      "x": -6,
      "y": 41,
      "z": -1,
      "name": "Plant_Leaves_Fig_Blue"
    },
    {
      "x": -6,
      "y": 41,
      "z": 0,
      "name": "Plant_Leaves_Fig_Blue"
    },
    {
      "x": -6,
      "y": 39,
      "z": 2,
      "name": "Wood_Fig_Blue_Branch_Long",
      "rotation": 5
    },
    {
      "x": -6,
      "y": 41,
      "z": 2,
      "name": "Plant_Leaves_Fig_Blue"
    },
    {
      "x": -6,
      "y": 40,
      "z": 3,
      "name": "Plant_Leaves_Fig_Blue"
    },
    {
      "x": -6,
      "y": 41,
      "z": 3,
      "name": "Plant_Leaves_Fig_Blue"
    },
    {
      "x": -6,
      "y": 39,
      "z": 4,
      "name": "Plant_Leaves_Fig_Blue"
    },
    {
      "x": -6,
      "y": 40,
      "z": 4,
      "name": "Plant_Leaves_Fig_Blue"
    },
    {
      "x": -6,
      "y": 37,
      "z": 5,
      "name": "Plant_Leaves_Fig_Blue"
    },
    {
      "x": -6,
      "y": 38,
      "z": 5,
      "name": "Plant_Leaves_Fig_Blue"
    },
    {
      "x": -5,
      "y": 39,
      "z": -8,
      "name": "Plant_Leaves_Fig_Blue"
    },
    {
      "x": -5,
      "y": 40,
      "z": -8,
      "name": "Plant_Leaves_Fig_Blue"
    },
    {
      "x": -5,
      "y": 36,
      "z": -7,
      "name": "Plant_Leaves_Fig_Blue"
    },
    {
      "x": -5,
      "y": 37,
      "z": -7,
      "name": "Plant_Leaves_Fig_Blue"
    },
    {
      "x": -5,
      "y": 38,
      "z": -7,
      "name": "Plant_Leaves_Fig_Blue"
    },
    {
      "x": -5,
      "y": 39,
      "z": -7,
      "name": "Plant_Leaves_Fig_Blue"
    },
    {
      "x": -5,
      "y": 35,
      "z": -6,
      "name": "Plant_Leaves_Fig_Blue"
    },
    {
      "x": -5,
      "y": 36,
      "z": -6,
      "name": "Plant_Leaves_Fig_Blue"
    },
    {
      "x": -5,
      "y": 37,
      "z": -6,
      "name": "Plant_Leaves_Fig_Blue"
    },
    {
      "x": -5,
      "y": 38,
      "z": -6,
      "name": "Plant_Leaves_Fig_Blue"
    },
    {
      "x": -5,
      "y": 39,
      "z": -6,
      "name": "Plant_Leaves_Fig_Blue"
    },
    {
      "x": -5,
      "y": 40,
      "z": -6,
      "name": "Plant_Leaves_Fig_Blue"
    },
    {
      "x": -5,
      "y": 38,
      "z": -5,
      "name": "Plant_Leaves_Fig_Blue"
    },
    {
      "x": -5,
      "y": 38,
      "z": -4,
      "name": "Plant_Leaves_Fig_Blue"
    },
    {
      "x": -5,
      "y": 39,
      "z": -4,
      "name": "Plant_Leaves_Fig_Blue"
    },
    {
      "x": -5,
      "y": 40,
      "z": -4,
      "name": "Plant_Leaves_Fig_Blue"
    },
    {
      "x": -5,
      "y": 38,
      "z": -3,
      "name": "Wood_Fig_Blue_Branch_Corner",
      "rotation": 2
    },
    {
      "x": -5,
      "y": 39,
      "z": -3,
      "name": "Wood_Fig_Blue_Branch_Long"
    },
    {
      "x": -5,
      "y": 42,
      "z": -3,
      "name": "Plant_Leaves_Fig_Blue"
    },
    {
      "x": -5,
      "y": 38,
      "z": -2,
      "name": "Wood_Fig_Blue_Branch_Long",
      "rotation": 4
    },
    {
      "x": -5,
      "y": 41,
      "z": -2,
      "name": "Plant_Leaves_Fig_Blue"
    },
    {
      "x": -5,
      "y": 42,
      "z": -2,
      "name": "Plant_Leaves_Fig_Blue"
    },
    {
      "x": -5,
      "y": 43,
      "z": -2,
      "name": "Plant_Leaves_Fig_Blue"
    },
    {
      "x": -5,
      "y": 38,
      "z": -1,
      "name": "Wood_Fig_Blue_Trunk_Full"
    },
    {
      "x": -5,
      "y": 39,
      "z": -1,
      "name": "Wood_Fig_Blue_Trunk_Full"
    },
    {
      "x": -5,
      "y": 40,
      "z": -1,
      "name": "Wood_Fig_Blue_Branch_Long"
    },
    {
      "x": -5,
      "y": 41,
      "z": -1,
      "name": "Plant_Leaves_Fig_Blue"
    },
    {
      "x": -5,
      "y": 42,
      "z": -1,
      "name": "Plant_Leaves_Fig_Blue"
    },
    {
      "x": -5,
      "y": 38,
      "z": 0,
      "name": "Wood_Fig_Blue_Trunk_Full"
    },
    {
      "x": -5,
      "y": 39,
      "z": 0,
      "name": "Wood_Fig_Blue_Trunk_Full"
    },
    {
      "x": -5,
      "y": 39,
      "z": 1,
      "name": "Wood_Fig_Blue_Trunk_Full"
    },
    {
      "x": -5,
      "y": 41,
      "z": 1,
      "name": "Plant_Leaves_Fig_Blue"
    },
    {
      "x": -5,
      "y": 39,
      "z": 2,
      "name": "Wood_Fig_Blue_Trunk_Full"
    },
    {
      "x": -5,
      "y": 40,
      "z": 2,
      "name": "Wood_Fig_Blue_Branch_Long"
    },
    {
      "x": -5,
      "y": 41,
      "z": 2,
      "name": "Plant_Leaves_Fig_Blue"
    },
    {
      "x": -5,
      "y": 41,
      "z": 3,
      "name": "Plant_Leaves_Fig_Blue"
    },
    {
      "x": -5,
      "y": 39,
      "z": 4,
      "name": "Plant_Leaves_Fig_Blue"
    },
    {
      "x": -5,
      "y": 40,
      "z": 4,
      "name": "Plant_Leaves_Fig_Blue"
    },
    {
      "x": -5,
      "y": 42,
      "z": 5,
      "name": "Plant_Leaves_Fig_Blue"
    },
    {
      "x": -5,
      "y": 42,
      "z": 6,
      "name": "Plant_Leaves_Fig_Blue"
    },
    {
      "x": -5,
      "y": 40,
      "z": 7,
      "name": "Plant_Leaves_Fig_Blue"
    },
    {
      "x": -5,
      "y": 41,
      "z": 7,
      "name": "Plant_Leaves_Fig_Blue"
    },
    {
      "x": -5,
      "y": 42,
      "z": 7,
      "name": "Plant_Leaves_Fig_Blue"
    },
    {
      "x": -5,
      "y": 43,
      "z": 7,
      "name": "Plant_Leaves_Fig_Blue"
    },
    {
      "x": -5,
      "y": 40,
      "z": 8,
      "name": "Plant_Leaves_Fig_Blue"
    },
    {
      "x": -5,
      "y": 41,
      "z": 8,
      "name": "Plant_Leaves_Fig_Blue"
    },
    {
      "x": -5,
      "y": 42,
      "z": 8,
      "name": "Plant_Leaves_Fig_Blue"
    },
    {
      "x": -4,
      "y": 36,
      "z": -10,
      "name": "Plant_Leaves_Fig_Blue"
    },
    {
      "x": -4,
      "y": 37,
      "z": -10,
      "name": "Plant_Leaves_Fig_Blue"
    },
    {
      "x": -4,
      "y": 38,
      "z": -10,
      "name": "Plant_Leaves_Fig_Blue"
    },
    {
      "x": -4,
      "y": 39,
      "z": -10,
      "name": "Plant_Leaves_Fig_Blue"
    },
    {
      "x": -4,
      "y": 36,
      "z": -9,
      "name": "Plant_Leaves_Fig_Blue"
    },
    {
      "x": -4,
      "y": 37,
      "z": -9,
      "name": "Plant_Leaves_Fig_Blue"
    },
    {
      "x": -4,
      "y": 38,
      "z": -9,
      "name": "Plant_Leaves_Fig_Blue"
    },
    {
      "x": -4,
      "y": 39,
      "z": -9,
      "name": "Plant_Leaves_Fig_Blue"
    },
    {
      "x": -4,
      "y": 40,
      "z": -9,
      "name": "Plant_Leaves_Fig_Blue"
    },
    {
      "x": -4,
      "y": 41,
      "z": -9,
      "name": "Plant_Leaves_Fig_Blue"
    },
    {
      "x": -4,
      "y": 38,
      "z": -8,
      "name": "Plant_Leaves_Fig_Blue"
    },
    {
      "x": -4,
      "y": 39,
      "z": -8,
      "name": "Plant_Leaves_Fig_Blue"
    },
    {
      "x": -4,
      "y": 40,
      "z": -8,
      "name": "Plant_Leaves_Fig_Blue"
    },
    {
      "x": -4,
      "y": 39,
      "z": -7,
      "name": "Plant_Leaves_Fig_Blue"
    },
    {
      "x": -4,
      "y": 39,
      "z": -6,
      "name": "Plant_Leaves_Fig_Blue"
    },
    {
      "x": -4,
      "y": 40,
      "z": -6,
      "name": "Plant_Leaves_Fig_Blue"
    },
    {
      "x": -4,
      "y": 41,
      "z": -6,
      "name": "Plant_Leaves_Fig_Blue"
    },
    {
      "x": -4,
      "y": 39,
      "z": -5,
      "name": "Plant_Leaves_Fig_Blue"
    },
    {
      "x": -4,
      "y": 42,
      "z": -5,
      "name": "Plant_Leaves_Fig_Blue"
    },
    {
      "x": -4,
      "y": 38,
      "z": -4,
      "name": "Plant_Leaves_Fig_Blue"
    },
    {
      "x": -4,
      "y": 42,
      "z": -4,
      "name": "Plant_Leaves_Fig_Blue"
    },
    {
      "x": -4,
      "y": 43,
      "z": -4,
      "name": "Plant_Leaves_Fig_Blue"
    },
    {
      "x": -4,
      "y": 42,
      "z": -2,
      "name": "Wood_Fig_Blue_Branch_Corner",
      "rotation": 3
    },
    {
      "x": -4,
      "y": 43,
      "z": -2,
      "name": "Plant_Leaves_Fig_Blue"
    },
    {
      "x": -4,
      "y": 44,
      "z": -2,
      "name": "Plant_Leaves_Fig_Blue"
    },
    {
      "x": -4,
      "y": 42,
      "z": -1,
      "name": "Plant_Leaves_Fig_Blue"
    },
    {
      "x": -4,
      "y": 43,
      "z": -1,
      "name": "Plant_Leaves_Fig_Blue"
    },
    {
      "x": -4,
      "y": 38,
      "z": 0,
      "name": "Wood_Fig_Blue_Trunk_Full"
    },
    {
      "x": -4,
      "y": 42,
      "z": 0,
      "name": "Plant_Leaves_Fig_Blue"
    },
    {
      "x": -4,
      "y": 30,
      "z": 2,
      "name": "Plant_Leaves_Fig_Blue"
    },
    {
      "x": -4,
      "y": 29,
      "z": 3,
      "name": "Plant_Leaves_Fig_Blue"
    },
    {
      "x": -4,
      "y": 30,
      "z": 3,
      "name": "Plant_Leaves_Fig_Blue"
    },
    {
      "x": -4,
      "y": 31,
      "z": 3,
      "name": "Plant_Leaves_Fig_Blue"
    },
    {
      "x": -4,
      "y": 29,
      "z": 4,
      "name": "Plant_Leaves_Fig_Blue"
    },
    {
      "x": -4,
      "y": 30,
      "z": 4,
      "name": "Plant_Leaves_Fig_Blue"
    },
    {
      "x": -4,
      "y": 31,
      "z": 4,
      "name": "Plant_Leaves_Fig_Blue"
    },
    {
      "x": -4,
      "y": 39,
      "z": 4,
      "name": "Plant_Leaves_Fig_Blue"
    },
    {
      "x": -4,
      "y": 42,
      "z": 4,
      "name": "Plant_Leaves_Fig_Blue"
    },
    {
      "x": -4,
      "y": 30,
      "z": 5,
      "name": "Plant_Leaves_Fig_Blue"
    },
    {
      "x": -4,
      "y": 31,
      "z": 5,
      "name": "Plant_Leaves_Fig_Blue"
    },
    {
      "x": -4,
      "y": 42,
      "z": 5,
      "name": "Plant_Leaves_Fig_Blue"
    },
    {
      "x": -4,
      "y": 43,
      "z": 5,
      "name": "Plant_Leaves_Fig_Blue"
    },
    {
      "x": -4,
      "y": 30,
      "z": 6,
      "name": "Plant_Leaves_Fig_Blue"
    },
    {
      "x": -4,
      "y": 42,
      "z": 6,
      "name": "Plant_Leaves_Fig_Blue"
    },
    {
      "x": -4,
      "y": 43,
      "z": 6,
      "name": "Plant_Leaves_Fig_Blue"
    },
    {
      "x": -4,
      "y": 44,
      "z": 6,
      "name": "Plant_Leaves_Fig_Blue"
    },
    {
      "x": -4,
      "y": 42,
      "z": 7,
      "name": "Plant_Leaves_Fig_Blue"
    },
    {
      "x": -4,
      "y": 43,
      "z": 7,
      "name": "Plant_Leaves_Fig_Blue"
    },
    {
      "x": -4,
      "y": 44,
      "z": 7,
      "name": "Plant_Leaves_Fig_Blue"
    },
    {
      "x": -4,
      "y": 41,
      "z": 8,
      "name": "Plant_Leaves_Fig_Blue"
    },
    {
      "x": -4,
      "y": 42,
      "z": 8,
      "name": "Plant_Leaves_Fig_Blue"
    },
    {
      "x": -4,
      "y": 43,
      "z": 8,
      "name": "Plant_Leaves_Fig_Blue"
    },
    {
      "x": -4,
      "y": 39,
      "z": 9,
      "name": "Plant_Leaves_Fig_Blue"
    },
    {
      "x": -4,
      "y": 40,
      "z": 9,
      "name": "Plant_Leaves_Fig_Blue"
    },
    {
      "x": -4,
      "y": 41,
      "z": 9,
      "name": "Plant_Leaves_Fig_Blue"
    },
    {
      "x": -4,
      "y": 42,
      "z": 9,
      "name": "Plant_Leaves_Fig_Blue"
    },
    {
      "x": -4,
      "y": 43,
      "z": 9,
      "name": "Plant_Leaves_Fig_Blue"
    },
    {
      "x": -4,
      "y": 40,
      "z": 10,
      "name": "Plant_Leaves_Fig_Blue"
    },
    {
      "x": -4,
      "y": 41,
      "z": 10,
      "name": "Plant_Leaves_Fig_Blue"
    },
    {
      "x": -3,
      "y": 39,
      "z": -11,
      "name": "Plant_Leaves_Fig_Blue"
    },
    {
      "x": -3,
      "y": 38,
      "z": -10,
      "name": "Plant_Leaves_Fig_Blue"
    },
    {
      "x": -3,
      "y": 39,
      "z": -10,
      "name": "Plant_Leaves_Fig_Blue"
    },
    {
      "x": -3,
      "y": 40,
      "z": -10,
      "name": "Plant_Leaves_Fig_Blue"
    },
    {
      "x": -3,
      "y": 36,
      "z": -9,
      "name": "Plant_Leaves_Fig_Blue"
    },
    {
      "x": -3,
      "y": 37,
      "z": -9,
      "name": "Plant_Leaves_Fig_Blue"
    },
    {
      "x": -3,
      "y": 38,
      "z": -9,
      "name": "Plant_Leaves_Fig_Blue"
    },
    {
      "x": -3,
      "y": 39,
      "z": -9,
      "name": "Plant_Leaves_Fig_Blue"
    },
    {
      "x": -3,
      "y": 40,
      "z": -9,
      "name": "Plant_Leaves_Fig_Blue"
    },
    {
      "x": -3,
      "y": 39,
      "z": -8,
      "name": "Wood_Fig_Blue_Branch_Corner",
      "rotation": 3
    },
    {
      "x": -3,
      "y": 40,
      "z": -8,
      "name": "Wood_Fig_Blue_Branch_Long"
    },
    {
      "x": -3,
      "y": 41,
      "z": -8,
      "name": "Plant_Leaves_Fig_Blue"
    },
    {
      "x": -3,
      "y": 39,
      "z": -7,
      "name": "Plant_Leaves_Fig_Blue"
    },
    {
      "x": -3,
      "y": 40,
      "z": -7,
      "name": "Plant_Leaves_Fig_Blue"
    },
    {
      "x": -3,
      "y": 41,
      "z": -7,
      "name": "Plant_Leaves_Fig_Blue"
    },
    {
      "x": -3,
      "y": 38,
      "z": -6,
      "name": "Wood_Fig_Blue_Branch_Corner",
      "rotation": 3
    },
    {
      "x": -3,
      "y": 39,
      "z": -6,
      "name": "Wood_Fig_Blue_Branch_Long"
    },
    {
      "x": -3,
      "y": 40,
      "z": -6,
      "name": "Plant_Leaves_Fig_Blue"
    },
    {
      "x": -3,
      "y": 39,
      "z": -5,
      "name": "Plant_Leaves_Fig_Blue"
    },
    {
      "x": -3,
      "y": 42,
      "z": -5,
      "name": "Plant_Leaves_Fig_Blue"
    },
    {
      "x": -3,
      "y": 43,
      "z": -5,
      "name": "Plant_Leaves_Fig_Blue"
    },
    {
      "x": -3,
      "y": 42,
      "z": -4,
      "name": "Plant_Leaves_Fig_Blue"
    },
    {
      "x": -3,
      "y": 43,
      "z": -4,
      "name": "Plant_Leaves_Fig_Blue"
    },
    {
      "x": -3,
      "y": 44,
      "z": -4,
      "name": "Plant_Leaves_Fig_Blue"
    },
    {
      "x": -3,
      "y": 44,
      "z": -3,
      "name": "Plant_Leaves_Fig_Blue"
    },
    {
      "x": -3,
      "y": 42,
      "z": -2,
      "name": "Wood_Fig_Blue_Branch_Long",
      "rotation": 5
    },
    {
      "x": -3,
      "y": 38,
      "z": -1,
      "name": "Wood_Fig_Blue_Trunk_Full"
    },
    {
      "x": -3,
      "y": 42,
      "z": -1,
      "name": "Plant_Leaves_Fig_Blue"
    },
    {
      "x": -3,
      "y": 43,
      "z": -1,
      "name": "Plant_Leaves_Fig_Blue"
    },
    {
      "x": -3,
      "y": 44,
      "z": -1,
      "name": "Plant_Leaves_Fig_Blue"
    },
    {
      "x": -3,
      "y": 38,
      "z": 0,
      "name": "Wood_Fig_Blue_Trunk_Full"
    },
    {
      "x": -3,
      "y": 42,
      "z": 0,
      "name": "Plant_Leaves_Fig_Blue"
    },
    {
      "x": -3,
      "y": 43,
      "z": 0,
      "name": "Plant_Leaves_Fig_Blue"
    },
    {
      "x": -3,
      "y": 30,
      "z": 1,
      "name": "Plant_Leaves_Fig_Blue"
    },
    {
      "x": -3,
      "y": 42,
      "z": 1,
      "name": "Plant_Leaves_Fig_Blue"
    },
    {
      "x": -3,
      "y": 30,
      "z": 2,
      "name": "Plant_Leaves_Fig_Blue"
    },
    {
      "x": -3,
      "y": 31,
      "z": 2,
      "name": "Plant_Leaves_Fig_Blue"
    },
    {
      "x": -3,
      "y": 31,
      "z": 3,
      "name": "Plant_Leaves_Fig_Blue"
    },
    {
      "x": -3,
      "y": 30,
      "z": 4,
      "name": "Wood_Fig_Blue_Branch_Corner",
      "rotation": 3
    },
    {
      "x": -3,
      "y": 31,
      "z": 4,
      "name": "Plant_Leaves_Fig_Blue"
    },
    {
      "x": -3,
      "y": 32,
      "z": 4,
      "name": "Plant_Leaves_Fig_Blue"
    },
    {
      "x": -3,
      "y": 43,
      "z": 4,
      "name": "Plant_Leaves_Fig_Blue"
    },
    {
      "x": -3,
      "y": 30,
      "z": 5,
      "name": "Plant_Leaves_Fig_Blue"
    },
    {
      "x": -3,
      "y": 32,
      "z": 5,
      "name": "Plant_Leaves_Fig_Blue"
    },
    {
      "x": -3,
      "y": 40,
      "z": 5,
      "name": "Wood_Fig_Blue_Trunk_Full"
    },
    {
      "x": -3,
      "y": 43,
      "z": 5,
      "name": "Plant_Leaves_Fig_Blue"
    },
    {
      "x": -3,
      "y": 29,
      "z": 6,
      "name": "Plant_Leaves_Fig_Blue"
    },
    {
      "x": -3,
      "y": 30,
      "z": 6,
      "name": "Plant_Leaves_Fig_Blue"
    },
    {
      "x": -3,
      "y": 31,
      "z": 6,
      "name": "Plant_Leaves_Fig_Blue"
    },
    {
      "x": -3,
      "y": 40,
      "z": 6,
      "name": "Wood_Fig_Blue_Trunk_Full"
    },
    {
      "x": -3,
      "y": 41,
      "z": 6,
      "name": "Wood_Fig_Blue_Branch_Long"
    },
    {
      "x": -3,
      "y": 42,
      "z": 6,
      "name": "Wood_Fig_Blue_Branch_Long"
    },
    {
      "x": -3,
      "y": 43,
      "z": 6,
      "name": "Plant_Leaves_Fig_Blue"
    },
    {
      "x": -3,
      "y": 44,
      "z": 6,
      "name": "Plant_Leaves_Fig_Blue"
    },
    {
      "x": -3,
      "y": 45,
      "z": 6,
      "name": "Plant_Leaves_Fig_Blue"
    },
    {
      "x": -3,
      "y": 30,
      "z": 7,
      "name": "Plant_Leaves_Fig_Blue"
    },
    {
      "x": -3,
      "y": 43,
      "z": 7,
      "name": "Plant_Leaves_Fig_Blue"
    },
    {
      "x": -3,
      "y": 44,
      "z": 7,
      "name": "Plant_Leaves_Fig_Blue"
    },
    {
      "x": -3,
      "y": 45,
      "z": 7,
      "name": "Plant_Leaves_Fig_Blue"
    },
    {
      "x": -3,
      "y": 41,
      "z": 8,
      "name": "Plant_Leaves_Fig_Blue"
    },
    {
      "x": -3,
      "y": 42,
      "z": 8,
      "name": "Plant_Leaves_Fig_Blue"
    },
    {
      "x": -3,
      "y": 43,
      "z": 8,
      "name": "Plant_Leaves_Fig_Blue"
    },
    {
      "x": -3,
      "y": 44,
      "z": 8,
      "name": "Plant_Leaves_Fig_Blue"
    },
    {
      "x": -3,
      "y": 42,
      "z": 9,
      "name": "Plant_Leaves_Fig_Blue"
    },
    {
      "x": -3,
      "y": 43,
      "z": 9,
      "name": "Plant_Leaves_Fig_Blue"
    },
    {
      "x": -3,
      "y": 44,
      "z": 9,
      "name": "Plant_Leaves_Fig_Blue"
    },
    {
      "x": -3,
      "y": 39,
      "z": 10,
      "name": "Plant_Leaves_Fig_Blue"
    },
    {
      "x": -3,
      "y": 40,
      "z": 10,
      "name": "Plant_Leaves_Fig_Blue"
    },
    {
      "x": -3,
      "y": 41,
      "z": 10,
      "name": "Plant_Leaves_Fig_Blue"
    },
    {
      "x": -3,
      "y": 42,
      "z": 10,
      "name": "Plant_Leaves_Fig_Blue"
    },
    {
      "x": -3,
      "y": 43,
      "z": 10,
      "name": "Plant_Leaves_Fig_Blue"
    },
    {
      "x": -3,
      "y": 40,
      "z": 11,
      "name": "Plant_Leaves_Fig_Blue"
    },
    {
      "x": -3,
      "y": 41,
      "z": 11,
      "name": "Plant_Leaves_Fig_Blue"
    },
    {
      "x": -3,
      "y": 42,
      "z": 11,
      "name": "Plant_Leaves_Fig_Blue"
    },
    {
      "x": -2,
      "y": 36,
      "z": -11,
      "name": "Plant_Leaves_Fig_Blue"
    },
    {
      "x": -2,
      "y": 37,
      "z": -11,
      "name": "Plant_Leaves_Fig_Blue"
    },
    {
      "x": -2,
      "y": 38,
      "z": -11,
      "name": "Plant_Leaves_Fig_Blue"
    },
    {
      "x": -2,
      "y": 39,
      "z": -11,
      "name": "Plant_Leaves_Fig_Blue"
    },
    {
      "x": -2,
      "y": 39,
      "z": -10,
      "name": "Plant_Leaves_Fig_Blue"
    },
    {
      "x": -2,
      "y": 40,
      "z": -10,
      "name": "Plant_Leaves_Fig_Blue"
    },
    {
      "x": -2,
      "y": 41,
      "z": -10,
      "name": "Plant_Leaves_Fig_Blue"
    },
    {
      "x": -2,
      "y": 41,
      "z": -9,
      "name": "Plant_Leaves_Fig_Blue"
    },
    {
      "x": -2,
      "y": 39,
      "z": -8,
      "name": "Wood_Fig_Blue_Branch_Long",
      "rotation": 5
    },
    {
      "x": -2,
      "y": 40,
      "z": -8,
      "name": "Plant_Leaves_Fig_Blue"
    },
    {
      "x": -2,
      "y": 41,
      "z": -8,
      "name": "Plant_Leaves_Fig_Blue"
    },
    {
      "x": -2,
      "y": 42,
      "z": -8,
      "name": "Plant_Leaves_Fig_Blue"
    },
    {
      "x": -2,
      "y": 38,
      "z": -6,
      "name": "Wood_Fig_Blue_Branch_Long",
      "rotation": 5
    },
    {
      "x": -2,
      "y": 40,
      "z": -6,
      "name": "Plant_Leaves_Fig_Blue"
    },
    {
      "x": -2,
      "y": 42,
      "z": -6,
      "name": "Plant_Leaves_Fig_Blue"
    },
    {
      "x": -2,
      "y": 42,
      "z": -5,
      "name": "Plant_Leaves_Fig_Blue"
    },
    {
      "x": -2,
      "y": 43,
      "z": -5,
      "name": "Plant_Leaves_Fig_Blue"
    },
    {
      "x": -2,
      "y": 44,
      "z": -5,
      "name": "Plant_Leaves_Fig_Blue"
    },
    {
      "x": -2,
      "y": 43,
      "z": -4,
      "name": "Plant_Leaves_Fig_Blue"
    },
    {
      "x": -2,
      "y": 45,
      "z": -3,
      "name": "Plant_Leaves_Fig_Blue"
    },
    {
      "x": -2,
      "y": 42,
      "z": -2,
      "name": "Wood_Fig_Blue_Branch_Long",
      "rotation": 5
    },
    {
      "x": -2,
      "y": 45,
      "z": -2,
      "name": "Plant_Leaves_Fig_Blue"
    },
    {
      "x": -2,
      "y": 37,
      "z": -1,
      "name": "Wood_Fig_Blue_Trunk_Full"
    },
    {
      "x": -2,
      "y": 38,
      "z": -1,
      "name": "Wood_Fig_Blue_Trunk_Full"
    },
    {
      "x": -2,
      "y": 45,
      "z": -1,
      "name": "Plant_Leaves_Fig_Blue"
    },
    {
      "x": -2,
      "y": 43,
      "z": 0,
      "name": "Plant_Leaves_Fig_Blue"
    },
    {
      "x": -2,
      "y": 44,
      "z": 0,
      "name": "Plant_Leaves_Fig_Blue"
    },
    {
      "x": -2,
      "y": 2,
      "z": 1,
      "name": "Wood_Fig_Blue_Branch_Long"
    },
    {
      "x": -2,
      "y": 3,
      "z": 1,
      "name": "Wood_Fig_Blue_Branch_Long"
    },
    {
      "x": -2,
      "y": 4,
      "z": 1,
      "name": "Wood_Fig_Blue_Branch_Long"
    },
    {
      "x": -2,
      "y": 5,
      "z": 1,
      "name": "Wood_Fig_Blue_Branch_Corner",
      "rotation": 9
    },
    {
      "x": -2,
      "y": 29,
      "z": 1,
      "name": "Plant_Leaves_Fig_Blue"
    },
    {
      "x": -2,
      "y": 30,
      "z": 1,
      "name": "Plant_Leaves_Fig_Blue"
    },
    {
      "x": -2,
      "y": 42,
      "z": 1,
      "name": "Plant_Leaves_Fig_Blue"
    },
    {
      "x": -2,
      "y": 2,
      "z": 2,
      "name": "Wood_Fig_Blue_Branch_Long"
    },
    {
      "x": -2,
      "y": 3,
      "z": 2,
      "name": "Wood_Fig_Blue_Branch_Long"
    },
    {
      "x": -2,
      "y": 4,
      "z": 2,
      "name": "Wood_Fig_Blue_Branch_Corner",
      "rotation": 9
    },
    {
      "x": -2,
      "y": 32,
      "z": 2,
      "name": "Plant_Leaves_Fig_Blue"
    },
    {
      "x": -2,
      "y": 32,
      "z": 3,
      "name": "Plant_Leaves_Fig_Blue"
    },
    {
      "x": -2,
      "y": 43,
      "z": 3,
      "name": "Plant_Leaves_Fig_Blue"
    },
    {
      "x": -2,
      "y": 30,
      "z": 4,
      "name": "Wood_Fig_Blue_Branch_Long",
      "rotation": 5
    },
    {
      "x": -2,
      "y": 32,
      "z": 4,
      "name": "Plant_Leaves_Fig_Blue"
    },
    {
      "x": -2,
      "y": 43,
      "z": 4,
      "name": "Plant_Leaves_Fig_Blue"
    },
    {
      "x": -2,
      "y": 32,
      "z": 5,
      "name": "Plant_Leaves_Fig_Blue"
    },
    {
      "x": -2,
      "y": 40,
      "z": 5,
      "name": "Wood_Fig_Blue_Trunk_Full"
    },
    {
      "x": -2,
      "y": 44,
      "z": 5,
      "name": "Plant_Leaves_Fig_Blue"
    },
    {
      "x": -2,
      "y": 28,
      "z": 6,
      "name": "Plant_Leaves_Fig_Blue"
    },
    {
      "x": -2,
      "y": 29,
      "z": 6,
      "name": "Plant_Leaves_Fig_Blue"
    },
    {
      "x": -2,
      "y": 32,
      "z": 6,
      "name": "Plant_Leaves_Fig_Blue"
    },
    {
      "x": -2,
      "y": 44,
      "z": 6,
      "name": "Plant_Leaves_Fig_Blue"
    },
    {
      "x": -2,
      "y": 45,
      "z": 6,
      "name": "Plant_Leaves_Fig_Blue"
    },
    {
      "x": -2,
      "y": 29,
      "z": 7,
      "name": "Plant_Leaves_Fig_Blue"
    },
    {
      "x": -2,
      "y": 30,
      "z": 7,
      "name": "Plant_Leaves_Fig_Blue"
    },
    {
      "x": -2,
      "y": 44,
      "z": 7,
      "name": "Plant_Leaves_Fig_Blue"
    },
    {
      "x": -2,
      "y": 41,
      "z": 8,
      "name": "Wood_Fig_Blue_Branch_Long",
      "rotation": 5
    },
    {
      "x": -2,
      "y": 44,
      "z": 8,
      "name": "Plant_Leaves_Fig_Blue"
    },
    {
      "x": -2,
      "y": 45,
      "z": 8,
      "name": "Plant_Leaves_Fig_Blue"
    },
    {
      "x": -2,
      "y": 42,
      "z": 10,
      "name": "Plant_Leaves_Fig_Blue"
    },
    {
      "x": -2,
      "y": 41,
      "z": 11,
      "name": "Plant_Leaves_Fig_Blue"
    },
    {
      "x": -2,
      "y": 42,
      "z": 11,
      "name": "Plant_Leaves_Fig_Blue"
    },
    {
      "x": -2,
      "y": 43,
      "z": 11,
      "name": "Plant_Leaves_Fig_Blue"
    },
    {
      "x": -1,
      "y": 36,
      "z": -12,
      "name": "Plant_Leaves_Fig_Blue"
    },
    {
      "x": -1,
      "y": 37,
      "z": -12,
      "name": "Plant_Leaves_Fig_Blue"
    },
    {
      "x": -1,
      "y": 38,
      "z": -12,
      "name": "Plant_Leaves_Fig_Blue"
    },
    {
      "x": -1,
      "y": 39,
      "z": -12,
      "name": "Plant_Leaves_Fig_Blue"
    },
    {
      "x": -1,
      "y": 39,
      "z": -11,
      "name": "Plant_Leaves_Fig_Blue"
    },
    {
      "x": -1,
      "y": 41,
      "z": -11,
      "name": "Plant_Leaves_Fig_Blue"
    },
    {
      "x": -1,
      "y": 41,
      "z": -10,
      "name": "Plant_Leaves_Fig_Blue"
    },
    {
      "x": -1,
      "y": 42,
      "z": -10,
      "name": "Plant_Leaves_Fig_Blue"
    },
    {
      "x": -1,
      "y": 42,
      "z": -9,
      "name": "Plant_Leaves_Fig_Blue"
    },
    {
      "x": -1,
      "y": 39,
      "z": -8,
      "name": "Wood_Fig_Blue_Trunk_Full"
    },
    {
      "x": -1,
      "y": 41,
      "z": -8,
      "name": "Plant_Leaves_Fig_Blue"
    },
    {
      "x": -1,
      "y": 42,
      "z": -8,
      "name": "Plant_Leaves_Fig_Blue"
    },
    {
      "x": -1,
      "y": 39,
      "z": -7,
      "name": "Wood_Fig_Blue_Trunk_Full"
    },
    {
      "x": -1,
      "y": 38,
      "z": -6,
      "name": "Wood_Fig_Blue_Trunk_Full"
    },
    {
      "x": -1,
      "y": 39,
      "z": -6,
      "name": "Wood_Fig_Blue_Trunk_Full"
    },
    {
      "x": -1,
      "y": 42,
      "z": -6,
      "name": "Plant_Leaves_Fig_Blue"
    },
    {
      "x": -1,
      "y": 43,
      "z": -6,
      "name": "Plant_Leaves_Fig_Blue"
    },
    {
      "x": -1,
      "y": 38,
      "z": -5,
      "name": "Wood_Fig_Blue_Trunk_Full"
    },
    {
      "x": -1,
      "y": 42,
      "z": -5,
      "name": "Plant_Leaves_Fig_Blue"
    },
    {
      "x": -1,
      "y": 43,
      "z": -5,
      "name": "Plant_Leaves_Fig_Blue"
    },
    {
      "x": -1,
      "y": 44,
      "z": -5,
      "name": "Plant_Leaves_Fig_Blue"
    },
    {
      "x": -1,
      "y": 42,
      "z": -4,
      "name": "Wood_Fig_Blue_Branch_Corner",
      "rotation": 2
    },
    {
      "x": -1,
      "y": 43,
      "z": -4,
      "name": "Plant_Leaves_Fig_Blue"
    },
    {
      "x": -1,
      "y": 44,
      "z": -4,
      "name": "Plant_Leaves_Fig_Blue"
    },
    {
      "x": -1,
      "y": 42,
      "z": -3,
      "name": "Wood_Fig_Blue_Branch_Long",
      "rotation": 4
    },
    {
      "x": -1,
      "y": 44,
      "z": -3,
      "name": "Plant_Leaves_Fig_Blue"
    },
    {
      "x": -1,
      "y": 45,
      "z": -3,
      "name": "Plant_Leaves_Fig_Blue"
    },
    {
      "x": -1,
      "y": 41,
      "z": -2,
      "name": "Wood_Fig_Blue_Trunk_Full"
    },
    {
      "x": -1,
      "y": 42,
      "z": -2,
      "name": "Wood_Fig_Blue_Trunk_Full"
    },
    {
      "x": -1,
      "y": 43,
      "z": -2,
      "name": "Wood_Fig_Blue_Branch_Long"
    },
    {
      "x": -1,
      "y": 44,
      "z": -2,
      "name": "Wood_Fig_Blue_Branch_Long"
    },
    {
      "x": -1,
      "y": 45,
      "z": -2,
      "name": "Plant_Leaves_Fig_Blue"
    },
    {
      "x": -1,
      "y": 37,
      "z": -1,
      "name": "Wood_Fig_Blue_Trunk_Full"
    },
    {
      "x": -1,
      "y": 38,
      "z": -1,
      "name": "Wood_Fig_Blue_Trunk_Full"
    },
    {
      "x": -1,
      "y": 41,
      "z": -1,
      "name": "Wood_Fig_Blue_Trunk_Full"
    },
    {
      "x": -1,
      "y": 42,
      "z": -1,
      "name": "Wood_Fig_Blue_Trunk_Full"
    },
    {
      "x": -1,
      "y": 44,
      "z": -1,
      "name": "Plant_Leaves_Fig_Blue"
    },
    {
      "x": -1,
      "y": 45,
      "z": -1,
      "name": "Plant_Leaves_Fig_Blue"
    },
    {
      "x": -1,
      "y": 2,
      "z": 0,
      "name": "Wood_Fig_Blue_Branch_Long"
    },
    {
      "x": -1,
      "y": 3,
      "z": 0,
      "name": "Wood_Fig_Blue_Branch_Long"
    },
    {
      "x": -1,
      "y": 4,
      "z": 0,
      "name": "Wood_Fig_Blue_Branch_Corner",
      "rotation": 9
    },
    {
      "x": -1,
      "y": 42,
      "z": 0,
      "name": "Wood_Fig_Blue_Branch_Corner"
    },
    {
      "x": -1,
      "y": 43,
      "z": 0,
      "name": "Plant_Leaves_Fig_Blue"
    },
    {
      "x": -1,
      "y": 44,
      "z": 0,
      "name": "Plant_Leaves_Fig_Blue"
    },
    {
      "x": -1,
      "y": 2,
      "z": 1,
      "name": "Wood_Fig_Blue_Trunk"
    },
    {
      "x": -1,
      "y": 3,
      "z": 1,
      "name": "Wood_Fig_Blue_Trunk"
    },
    {
      "x": -1,
      "y": 4,
      "z": 1,
      "name": "Wood_Fig_Blue_Trunk"
    },
    {
      "x": -1,
      "y": 5,
      "z": 1,
      "name": "Wood_Fig_Blue_Trunk_Full"
    },
    {
      "x": -1,
      "y": 6,
      "z": 1,
      "name": "Wood_Fig_Blue_Branch_Long"
    },
    {
      "x": -1,
      "y": 7,
      "z": 1,
      "name": "Wood_Fig_Blue_Branch_Long"
    },
    {
      "x": -1,
      "y": 8,
      "z": 1,
      "name": "Wood_Fig_Blue_Branch_Corner",
      "rotation": 9
    },
    {
      "x": -1,
      "y": 31,
      "z": 1,
      "name": "Plant_Leaves_Fig_Blue"
    },
    {
      "x": -1,
      "y": 32,
      "z": 1,
      "name": "Plant_Leaves_Fig_Blue"
    },
    {
      "x": -1,
      "y": 42,
      "z": 1,
      "name": "Plant_Leaves_Fig_Blue"
    },
    {
      "x": -1,
      "y": 43,
      "z": 1,
      "name": "Plant_Leaves_Fig_Blue"
    },
    {
      "x": -1,
      "y": 2,
      "z": 2,
      "name": "Wood_Fig_Blue_Trunk"
    },
    {
      "x": -1,
      "y": 3,
      "z": 2,
      "name": "Wood_Fig_Blue_Trunk"
    },
    {
      "x": -1,
      "y": 4,
      "z": 2,
      "name": "Wood_Fig_Blue_Trunk_Full"
    },
    {
      "x": -1,
      "y": 5,
      "z": 2,
      "name": "Wood_Fig_Blue_Branch_Long"
    },
    {
      "x": -1,
      "y": 6,
      "z": 2,
      "name": "Wood_Fig_Blue_Branch_Corner",
      "rotation": 9
    },
    {
      "x": -1,
      "y": 32,
      "z": 2,
      "name": "Plant_Leaves_Fig_Blue"
    },
    {
      "x": -1,
      "y": 42,
      "z": 2,
      "name": "Plant_Leaves_Fig_Blue"
    },
    {
      "x": -1,
      "y": 43,
      "z": 2,
      "name": "Plant_Leaves_Fig_Blue"
    },
    {
      "x": -1,
      "y": 2,
      "z": 3,
      "name": "Wood_Fig_Blue_Branch_Long"
    },
    {
      "x": -1,
      "y": 3,
      "z": 3,
      "name": "Wood_Fig_Blue_Branch_Long"
    },
    {
      "x": -1,
      "y": 4,
      "z": 3,
      "name": "Wood_Fig_Blue_Branch_Corner",
      "rotation": 10
    },
    {
      "x": -1,
      "y": 33,
      "z": 3,
      "name": "Plant_Leaves_Fig_Blue"
    },
    {
      "x": -1,
      "y": 30,
      "z": 4,
      "name": "Wood_Fig_Blue_Branch_Long",
      "rotation": 5
    },
    {
      "x": -1,
      "y": 33,
      "z": 4,
      "name": "Plant_Leaves_Fig_Blue"
    },
    {
      "x": -1,
      "y": 38,
      "z": 4,
      "name": "Wood_Fig_Blue_Trunk_Full"
    },
    {
      "x": -1,
      "y": 44,
      "z": 4,
      "name": "Plant_Leaves_Fig_Blue"
    },
    {
      "x": -1,
      "y": 32,
      "z": 5,
      "name": "Plant_Leaves_Fig_Blue"
    },
    {
      "x": -1,
      "y": 39,
      "z": 5,
      "name": "Wood_Fig_Blue_Trunk_Full"
    },
    {
      "x": -1,
      "y": 40,
      "z": 5,
      "name": "Wood_Fig_Blue_Trunk_Full"
    },
    {
      "x": -1,
      "y": 45,
      "z": 5,
      "name": "Plant_Leaves_Fig_Blue"
    },
    {
      "x": -1,
      "y": 28,
      "z": 6,
      "name": "Plant_Leaves_Fig_Blue"
    },
    {
      "x": -1,
      "y": 29,
      "z": 6,
      "name": "Plant_Leaves_Fig_Blue"
    },
    {
      "x": -1,
      "y": 32,
      "z": 6,
      "name": "Plant_Leaves_Fig_Blue"
    },
    {
      "x": -1,
      "y": 45,
      "z": 6,
      "name": "Plant_Leaves_Fig_Blue"
    },
    {
      "x": -1,
      "y": 46,
      "z": 6,
      "name": "Plant_Leaves_Fig_Blue"
    },
    {
      "x": -1,
      "y": 28,
      "z": 7,
      "name": "Plant_Leaves_Fig_Blue"
    },
    {
      "x": -1,
      "y": 30,
      "z": 7,
      "name": "Plant_Leaves_Fig_Blue"
    },
    {
      "x": -1,
      "y": 31,
      "z": 7,
      "name": "Plant_Leaves_Fig_Blue"
    },
    {
      "x": -1,
      "y": 45,
      "z": 7,
      "name": "Plant_Leaves_Fig_Blue"
    },
    {
      "x": -1,
      "y": 46,
      "z": 7,
      "name": "Plant_Leaves_Fig_Blue"
    },
    {
      "x": -1,
      "y": 30,
      "z": 8,
      "name": "Plant_Leaves_Fig_Blue"
    },
    {
      "x": -1,
      "y": 41,
      "z": 8,
      "name": "Wood_Fig_Blue_Branch_Long",
      "rotation": 5
    },
    {
      "x": -1,
      "y": 45,
      "z": 8,
      "name": "Plant_Leaves_Fig_Blue"
    },
    {
      "x": -1,
      "y": 44,
      "z": 9,
      "name": "Plant_Leaves_Fig_Blue"
    },
    {
      "x": -1,
      "y": 44,
      "z": 10,
      "name": "Plant_Leaves_Fig_Blue"
    },
    {
      "x": -1,
      "y": 39,
      "z": 11,
      "name": "Plant_Leaves_Fig_Blue"
    },
    {
      "x": -1,
      "y": 42,
      "z": 11,
      "name": "Plant_Leaves_Fig_Blue"
    },
    {
      "x": -1,
      "y": 44,
      "z": 11,
      "name": "Plant_Leaves_Fig_Blue"
    },
    {
      "x": -1,
      "y": 40,
      "z": 12,
      "name": "Plant_Leaves_Fig_Blue"
    },
    {
      "x": -1,
      "y": 41,
      "z": 12,
      "name": "Plant_Leaves_Fig_Blue"
    },
    {
      "x": -1,
      "y": 42,
      "z": 12,
      "name": "Plant_Leaves_Fig_Blue"
    },
    {
      "x": 0,
      "y": 36,
      "z": -12,
      "name": "Plant_Leaves_Fig_Blue"
    },
    {
      "x": 0,
      "y": 37,
      "z": -12,
      "name": "Plant_Leaves_Fig_Blue"
    },
    {
      "x": 0,
      "y": 38,
      "z": -12,
      "name": "Plant_Leaves_Fig_Blue"
    },
    {
      "x": 0,
      "y": 39,
      "z": -12,
      "name": "Plant_Leaves_Fig_Blue"
    },
    {
      "x": 0,
      "y": 40,
      "z": -12,
      "name": "Plant_Leaves_Fig_Blue"
    },
    {
      "x": 0,
      "y": 39,
      "z": -11,
      "name": "Wood_Fig_Blue_Branch_Corner",
      "rotation": 2
    },
    {
      "x": 0,
      "y": 40,
      "z": -11,
      "name": "Wood_Fig_Blue_Branch_Long"
    },
    {
      "x": 0,
      "y": 41,
      "z": -11,
      "name": "Plant_Leaves_Fig_Blue"
    },
    {
      "x": 0,
      "y": 39,
      "z": -10,
      "name": "Wood_Fig_Blue_Branch_Long",
      "rotation": 4
    },
    {
      "x": 0,
      "y": 41,
      "z": -10,
      "name": "Plant_Leaves_Fig_Blue"
    },
    {
      "x": 0,
      "y": 42,
      "z": -10,
      "name": "Plant_Leaves_Fig_Blue"
    },
    {
      "x": 0,
      "y": 39,
      "z": -9,
      "name": "Wood_Fig_Blue_Trunk_Full"
    },
    {
      "x": 0,
      "y": 42,
      "z": -9,
      "name": "Plant_Leaves_Fig_Blue"
    },
    {
      "x": 0,
      "y": 39,
      "z": -8,
      "name": "Wood_Fig_Blue_Trunk_Full"
    },
    {
      "x": 0,
      "y": 40,
      "z": -8,
      "name": "Wood_Fig_Blue_Branch_Long"
    },
    {
      "x": 0,
      "y": 41,
      "z": -8,
      "name": "Wood_Fig_Blue_Branch_Long"
    },
    {
      "x": 0,
      "y": 42,
      "z": -8,
      "name": "Plant_Leaves_Fig_Blue"
    },
    {
      "x": 0,
      "y": 42,
      "z": -6,
      "name": "Plant_Leaves_Fig_Blue"
    },
    {
      "x": 0,
      "y": 38,
      "z": -5,
      "name": "Wood_Fig_Blue_Trunk_Full"
    },
    {
      "x": 0,
      "y": 42,
      "z": -5,
      "name": "Plant_Leaves_Fig_Blue"
    },
    {
      "x": 0,
      "y": 43,
      "z": -5,
      "name": "Plant_Leaves_Fig_Blue"
    },
    {
      "x": 0,
      "y": 38,
      "z": -4,
      "name": "Wood_Fig_Blue_Trunk_Full"
    },
    {
      "x": 0,
      "y": 42,
      "z": -4,
      "name": "Plant_Leaves_Fig_Blue"
    },
    {
      "x": 0,
      "y": 44,
      "z": -4,
      "name": "Plant_Leaves_Fig_Blue"
    },
    {
      "x": 0,
      "y": 37,
      "z": -3,
      "name": "Wood_Fig_Blue_Trunk_Full"
    },
    {
      "x": 0,
      "y": 38,
      "z": -3,
      "name": "Wood_Fig_Blue_Trunk_Full"
    },
    {
      "x": 0,
      "y": 44,
      "z": -3,
      "name": "Plant_Leaves_Fig_Blue"
    },
    {
      "x": 0,
      "y": 45,
      "z": -3,
      "name": "Plant_Leaves_Fig_Blue"
    },
    {
      "x": 0,
      "y": 45,
      "z": -2,
      "name": "Plant_Leaves_Fig_Blue"
    },
    {
      "x": 0,
      "y": 2,
      "z": -1,
      "name": "Wood_Fig_Blue_Branch_Long"
    },
    {
      "x": 0,
      "y": 3,
      "z": -1,
      "name": "Wood_Fig_Blue_Branch_Long"
    },
    {
      "x": 0,
      "y": 4,
      "z": -1,
      "name": "Wood_Fig_Blue_Branch_Long"
    },
    {
      "x": 0,
      "y": 5,
      "z": -1,
      "name": "Wood_Fig_Blue_Branch_Long"
    },
    {
      "x": 0,
      "y": 6,
      "z": -1,
      "name": "Wood_Fig_Blue_Branch_Corner",
      "rotation": 8
    },
    {
      "x": 0,
      "y": 37,
      "z": -1,
      "name": "Wood_Fig_Blue_Trunk_Full"
    },
    {
      "x": 0,
      "y": 41,
      "z": -1,
      "name": "Wood_Fig_Blue_Trunk_Full"
    },
    {
      "x": 0,
      "y": 44,
      "z": -1,
      "name": "Plant_Leaves_Fig_Blue"
    },
    {
      "x": 0,
      "y": 45,
      "z": -1,
      "name": "Plant_Leaves_Fig_Blue"
    },
    {
      "x": 0,
      "y": 2,
      "z": 0,
      "name": "Wood_Fig_Blue_Trunk"
    },
    {
      "x": 0,
      "y": 3,
      "z": 0,
      "name": "Wood_Fig_Blue_Trunk"
    },
    {
      "x": 0,
      "y": 4,
      "z": 0,
      "name": "Wood_Fig_Blue_Trunk"
    },
    {
      "x": 0,
      "y": 5,
      "z": 0,
      "name": "Wood_Fig_Blue_Trunk"
    },
    {
      "x": 0,
      "y": 6,
      "z": 0,
      "name": "Wood_Fig_Blue_Trunk_Full"
    },
    {
      "x": 0,
      "y": 7,
      "z": 0,
      "name": "Wood_Fig_Blue_Branch_Long"
    },
    {
      "x": 0,
      "y": 8,
      "z": 0,
      "name": "Wood_Fig_Blue_Branch_Corner",
      "rotation": 8
    },
    {
      "x": 0,
      "y": 2,
      "z": 1,
      "name": "Wood_Fig_Blue_Trunk"
    },
    {
      "x": 0,
      "y": 3,
      "z": 1,
      "name": "Wood_Fig_Blue_Trunk"
    },
    {
      "x": 0,
      "y": 4,
      "z": 1,
      "name": "Wood_Fig_Blue_Trunk"
    },
    {
      "x": 0,
      "y": 5,
      "z": 1,
      "name": "Wood_Fig_Blue_Trunk"
    },
    {
      "x": 0,
      "y": 6,
      "z": 1,
      "name": "Wood_Fig_Blue_Trunk"
    },
    {
      "x": 0,
      "y": 7,
      "z": 1,
      "name": "Wood_Fig_Blue_Trunk"
    },
    {
      "x": 0,
      "y": 8,
      "z": 1,
      "name": "Wood_Fig_Blue_Trunk_Full"
    },
    {
      "x": 0,
      "y": 9,
      "z": 1,
      "name": "Wood_Fig_Blue_Branch_Long"
    },
    {
      "x": 0,
      "y": 10,
      "z": 1,
      "name": "Wood_Fig_Blue_Branch_Long"
    },
    {
      "x": 0,
      "y": 11,
      "z": 1,
      "name": "Wood_Fig_Blue_Branch_Corner",
      "rotation": 9
    },
    {
      "x": 0,
      "y": 42,
      "z": 1,
      "name": "Plant_Leaves_Fig_Blue"
    },
    {
      "x": 0,
      "y": 43,
      "z": 1,
      "name": "Plant_Leaves_Fig_Blue"
    },
    {
      "x": 0,
      "y": 44,
      "z": 1,
      "name": "Plant_Leaves_Fig_Blue"
    },
    {
      "x": 0,
      "y": 2,
      "z": 2,
      "name": "Wood_Fig_Blue_Trunk"
    },
    {
      "x": 0,
      "y": 3,
      "z": 2,
      "name": "Wood_Fig_Blue_Trunk"
    },
    {
      "x": 0,
      "y": 4,
      "z": 2,
      "name": "Wood_Fig_Blue_Trunk"
    },
    {
      "x": 0,
      "y": 5,
      "z": 2,
      "name": "Wood_Fig_Blue_Trunk"
    },
    {
      "x": 0,
      "y": 6,
      "z": 2,
      "name": "Wood_Fig_Blue_Trunk"
    },
    {
      "x": 0,
      "y": 7,
      "z": 2,
      "name": "Wood_Fig_Blue_Trunk"
    },
    {
      "x": 0,
      "y": 8,
      "z": 2,
      "name": "Wood_Fig_Blue_Trunk"
    },
    {
      "x": 0,
      "y": 9,
      "z": 2,
      "name": "Wood_Fig_Blue_Trunk_Full"
    },
    {
      "x": 0,
      "y": 10,
      "z": 2,
      "name": "Wood_Fig_Blue_Branch_Long"
    },
    {
      "x": 0,
      "y": 11,
      "z": 2,
      "name": "Wood_Fig_Blue_Branch_Long"
    },
    {
      "x": 0,
      "y": 12,
      "z": 2,
      "name": "Wood_Fig_Blue_Branch_Long"
    },
    {
      "x": 0,
      "y": 13,
      "z": 2,
      "name": "Wood_Fig_Blue_Branch_Corner",
      "rotation": 9
    },
    {
      "x": 0,
      "y": 42,
      "z": 2,
      "name": "Plant_Leaves_Fig_Blue"
    },
    {
      "x": 0,
      "y": 2,
      "z": 3,
      "name": "Wood_Fig_Blue_Trunk"
    },
    {
      "x": 0,
      "y": 3,
      "z": 3,
      "name": "Wood_Fig_Blue_Trunk"
    },
    {
      "x": 0,
      "y": 4,
      "z": 3,
      "name": "Wood_Fig_Blue_Trunk"
    },
    {
      "x": 0,
      "y": 5,
      "z": 3,
      "name": "Wood_Fig_Blue_Trunk"
    },
    {
      "x": 0,
      "y": 6,
      "z": 3,
      "name": "Wood_Fig_Blue_Trunk_Full"
    },
    {
      "x": 0,
      "y": 7,
      "z": 3,
      "name": "Wood_Fig_Blue_Branch_Long"
    },
    {
      "x": 0,
      "y": 8,
      "z": 3,
      "name": "Wood_Fig_Blue_Branch_Corner",
      "rotation": 9
    },
    {
      "x": 0,
      "y": 29,
      "z": 3,
      "name": "Wood_Fig_Blue_Trunk_Full"
    },
    {
      "x": 0,
      "y": 30,
      "z": 3,
      "name": "Wood_Fig_Blue_Trunk_Full"
    },
    {
      "x": 0,
      "y": 33,
      "z": 3,
      "name": "Plant_Leaves_Fig_Blue"
    },
    {
      "x": 0,
      "y": 36,
      "z": 3,
      "name": "Wood_Fig_Blue_Trunk_Full"
    },
    {
      "x": 0,
      "y": 37,
      "z": 3,
      "name": "Wood_Fig_Blue_Trunk"
    },
    {
      "x": 0,
      "y": 38,
      "z": 3,
      "name": "Wood_Fig_Blue_Trunk_Full"
    },
    {
      "x": 0,
      "y": 2,
      "z": 4,
      "name": "Wood_Fig_Blue_Branch_Long"
    },
    {
      "x": 0,
      "y": 3,
      "z": 4,
      "name": "Wood_Fig_Blue_Branch_Long"
    },
    {
      "x": 0,
      "y": 4,
      "z": 4,
      "name": "Wood_Fig_Blue_Branch_Long"
    },
    {
      "x": 0,
      "y": 5,
      "z": 4,
      "name": "Wood_Fig_Blue_Branch_Long"
    },
    {
      "x": 0,
      "y": 6,
      "z": 4,
      "name": "Wood_Fig_Blue_Branch_Corner",
      "rotation": 10
    },
    {
      "x": 0,
      "y": 30,
      "z": 4,
      "name": "Wood_Fig_Blue_Trunk_Full"
    },
    {
      "x": 0,
      "y": 33,
      "z": 4,
      "name": "Plant_Leaves_Fig_Blue"
    },
    {
      "x": 0,
      "y": 38,
      "z": 4,
      "name": "Wood_Fig_Blue_Trunk_Full"
    },
    {
      "x": 0,
      "y": 39,
      "z": 4,
      "name": "Wood_Fig_Blue_Trunk_Full"
    },
    {
      "x": 0,
      "y": 44,
      "z": 4,
      "name": "Plant_Leaves_Fig_Blue"
    },
    {
      "x": 0,
      "y": 45,
      "z": 4,
      "name": "Plant_Leaves_Fig_Blue"
    },
    {
      "x": 0,
      "y": 30,
      "z": 5,
      "name": "Wood_Fig_Blue_Branch_Long",
      "rotation": 4
    },
    {
      "x": 0,
      "y": 33,
      "z": 5,
      "name": "Plant_Leaves_Fig_Blue"
    },
    {
      "x": 0,
      "y": 40,
      "z": 5,
      "name": "Wood_Fig_Blue_Trunk_Full"
    },
    {
      "x": 0,
      "y": 30,
      "z": 6,
      "name": "Wood_Fig_Blue_Branch_Corner"
    },
    {
      "x": 0,
      "y": 31,
      "z": 6,
      "name": "Plant_Leaves_Fig_Blue"
    },
    {
      "x": 0,
      "y": 32,
      "z": 6,
      "name": "Plant_Leaves_Fig_Blue"
    },
    {
      "x": 0,
      "y": 40,
      "z": 6,
      "name": "Wood_Fig_Blue_Trunk_Full"
    },
    {
      "x": 0,
      "y": 41,
      "z": 6,
      "name": "Wood_Fig_Blue_Trunk_Full"
    },
    {
      "x": 0,
      "y": 45,
      "z": 6,
      "name": "Plant_Leaves_Fig_Blue"
    },
    {
      "x": 0,
      "y": 46,
      "z": 6,
      "name": "Plant_Leaves_Fig_Blue"
    },
    {
      "x": 0,
      "y": 30,
      "z": 7,
      "name": "Plant_Leaves_Fig_Blue"
    },
    {
      "x": 0,
      "y": 31,
      "z": 7,
      "name": "Plant_Leaves_Fig_Blue"
    },
    {
      "x": 0,
      "y": 32,
      "z": 7,
      "name": "Plant_Leaves_Fig_Blue"
    },
    {
      "x": 0,
      "y": 41,
      "z": 7,
      "name": "Wood_Fig_Blue_Trunk_Full"
    },
    {
      "x": 0,
      "y": 42,
      "z": 7,
      "name": "Wood_Fig_Blue_Branch_Long"
    },
    {
      "x": 0,
      "y": 43,
      "z": 7,
      "name": "Wood_Fig_Blue_Branch_Long"
    },
    {
      "x": 0,
      "y": 44,
      "z": 7,
      "name": "Wood_Fig_Blue_Branch_Long"
    },
    {
      "x": 0,
      "y": 45,
      "z": 7,
      "name": "Plant_Leaves_Fig_Blue"
    },
    {
      "x": 0,
      "y": 46,
      "z": 7,
      "name": "Plant_Leaves_Fig_Blue"
    },
    {
      "x": 0,
      "y": 30,
      "z": 8,
      "name": "Plant_Leaves_Fig_Blue"
    },
    {
      "x": 0,
      "y": 31,
      "z": 8,
      "name": "Plant_Leaves_Fig_Blue"
    },
    {
      "x": 0,
      "y": 41,
      "z": 8,
      "name": "Wood_Fig_Blue_Trunk_Full"
    },
    {
      "x": 0,
      "y": 45,
      "z": 8,
      "name": "Plant_Leaves_Fig_Blue"
    },
    {
      "x": 0,
      "y": 46,
      "z": 8,
      "name": "Plant_Leaves_Fig_Blue"
    },
    {
      "x": 0,
      "y": 45,
      "z": 9,
      "name": "Plant_Leaves_Fig_Blue"
    },
    {
      "x": 0,
      "y": 44,
      "z": 10,
      "name": "Plant_Leaves_Fig_Blue"
    },
    {
      "x": 0,
      "y": 45,
      "z": 10,
      "name": "Plant_Leaves_Fig_Blue"
    },
    {
      "x": 0,
      "y": 39,
      "z": 11,
      "name": "Plant_Leaves_Fig_Blue"
    },
    {
      "x": 0,
      "y": 40,
      "z": 11,
      "name": "Plant_Leaves_Fig_Blue"
    },
    {
      "x": 0,
      "y": 43,
      "z": 11,
      "name": "Plant_Leaves_Fig_Blue"
    },
    {
      "x": 0,
      "y": 44,
      "z": 11,
      "name": "Plant_Leaves_Fig_Blue"
    },
    {
      "x": 0,
      "y": 40,
      "z": 12,
      "name": "Plant_Leaves_Fig_Blue"
    },
    {
      "x": 0,
      "y": 41,
      "z": 12,
      "name": "Plant_Leaves_Fig_Blue"
    },
    {
      "x": 0,
      "y": 42,
      "z": 12,
      "name": "Plant_Leaves_Fig_Blue"
    },
    {
      "x": 0,
      "y": 43,
      "z": 12,
      "name": "Plant_Leaves_Fig_Blue"
    },
    {
      "x": 1,
      "y": 37,
      "z": -12,
      "name": "Plant_Leaves_Fig_Blue"
    },
    {
      "x": 1,
      "y": 38,
      "z": -12,
      "name": "Plant_Leaves_Fig_Blue"
    },
    {
      "x": 1,
      "y": 39,
      "z": -12,
      "name": "Plant_Leaves_Fig_Blue"
    },
    {
      "x": 1,
      "y": 40,
      "z": -12,
      "name": "Plant_Leaves_Fig_Blue"
    },
    {
      "x": 1,
      "y": 39,
      "z": -11,
      "name": "Plant_Leaves_Fig_Blue"
    },
    {
      "x": 1,
      "y": 41,
      "z": -11,
      "name": "Plant_Leaves_Fig_Blue"
    },
    {
      "x": 1,
      "y": 41,
      "z": -10,
      "name": "Plant_Leaves_Fig_Blue"
    },
    {
      "x": 1,
      "y": 41,
      "z": -9,
      "name": "Plant_Leaves_Fig_Blue"
    },
    {
      "x": 1,
      "y": 42,
      "z": -9,
      "name": "Plant_Leaves_Fig_Blue"
    },
    {
      "x": 1,
      "y": 39,
      "z": -8,
      "name": "Wood_Fig_Blue_Branch_Long",
      "rotation": 5
    },
    {
      "x": 1,
      "y": 42,
      "z": -8,
      "name": "Plant_Leaves_Fig_Blue"
    },
    {
      "x": 1,
      "y": 42,
      "z": -7,
      "name": "Plant_Leaves_Fig_Blue"
    },
    {
      "x": 1,
      "y": 42,
      "z": -5,
      "name": "Plant_Leaves_Fig_Blue"
    },
    {
      "x": 1,
      "y": 38,
      "z": -4,
      "name": "Wood_Fig_Blue_Branch_Corner",
      "rotation": 1
    },
    {
      "x": 1,
      "y": 42,
      "z": -4,
      "name": "Plant_Leaves_Fig_Blue"
    },
    {
      "x": 1,
      "y": 43,
      "z": -4,
      "name": "Plant_Leaves_Fig_Blue"
    },
    {
      "x": 1,
      "y": 44,
      "z": -4,
      "name": "Plant_Leaves_Fig_Blue"
    },
    {
      "x": 1,
      "y": 37,
      "z": -3,
      "name": "Wood_Fig_Blue_Trunk_Full"
    },
    {
      "x": 1,
      "y": 44,
      "z": -3,
      "name": "Plant_Leaves_Fig_Blue"
    },
    {
      "x": 1,
      "y": 37,
      "z": -2,
      "name": "Wood_Fig_Blue_Trunk_Full"
    },
    {
      "x": 1,
      "y": 44,
      "z": -2,
      "name": "Plant_Leaves_Fig_Blue"
    },
    {
      "x": 1,
      "y": 45,
      "z": -2,
      "name": "Plant_Leaves_Fig_Blue"
    },
    {
      "x": 1,
      "y": 36,
      "z": -1,
      "name": "Wood_Fig_Blue_Trunk_Full"
    },
    {
      "x": 1,
      "y": 37,
      "z": -1,
      "name": "Wood_Fig_Blue_Trunk_Full"
    },
    {
      "x": 1,
      "y": 41,
      "z": -1,
      "name": "Wood_Fig_Blue_Trunk_Full"
    },
    {
      "x": 1,
      "y": 44,
      "z": -1,
      "name": "Plant_Leaves_Fig_Blue"
    },
    {
      "x": 1,
      "y": 2,
      "z": 0,
      "name": "Wood_Fig_Blue_Trunk"
    },
    {
      "x": 1,
      "y": 3,
      "z": 0,
      "name": "Wood_Fig_Blue_Trunk"
    },
    {
      "x": 1,
      "y": 4,
      "z": 0,
      "name": "Wood_Fig_Blue_Trunk"
    },
    {
      "x": 1,
      "y": 5,
      "z": 0,
      "name": "Wood_Fig_Blue_Trunk"
    },
    {
      "x": 1,
      "y": 6,
      "z": 0,
      "name": "Wood_Fig_Blue_Trunk"
    },
    {
      "x": 1,
      "y": 7,
      "z": 0,
      "name": "Wood_Fig_Blue_Trunk_Full"
    },
    {
      "x": 1,
      "y": 8,
      "z": 0,
      "name": "Wood_Fig_Blue_Branch_Long"
    },
    {
      "x": 1,
      "y": 9,
      "z": 0,
      "name": "Wood_Fig_Blue_Branch_Long"
    },
    {
      "x": 1,
      "y": 10,
      "z": 0,
      "name": "Wood_Fig_Blue_Branch_Corner",
      "rotation": 8
    },
    {
      "x": 1,
      "y": 36,
      "z": 0,
      "name": "Wood_Fig_Blue_Trunk_Full"
    },
    {
      "x": 1,
      "y": 37,
      "z": 0,
      "name": "Wood_Fig_Blue_Trunk_Full"
    },
    {
      "x": 1,
      "y": 40,
      "z": 0,
      "name": "Wood_Fig_Blue_Trunk_Full"
    },
    {
      "x": 1,
      "y": 41,
      "z": 0,
      "name": "Wood_Fig_Blue_Trunk_Full"
    },
    {
      "x": 1,
      "y": 2,
      "z": 1,
      "name": "Wood_Fig_Blue_Trunk"
    },
    {
      "x": 1,
      "y": 3,
      "z": 1,
      "name": "Wood_Fig_Blue_Trunk"
    },
    {
      "x": 1,
      "y": 4,
      "z": 1,
      "name": "Wood_Fig_Blue_Trunk"
    },
    {
      "x": 1,
      "y": 5,
      "z": 1,
      "name": "Wood_Fig_Blue_Trunk"
    },
    {
      "x": 1,
      "y": 6,
      "z": 1,
      "name": "Wood_Fig_Blue_Trunk"
    },
    {
      "x": 1,
      "y": 7,
      "z": 1,
      "name": "Wood_Fig_Blue_Trunk"
    },
    {
      "x": 1,
      "y": 8,
      "z": 1,
      "name": "Wood_Fig_Blue_Trunk"
    },
    {
      "x": 1,
      "y": 9,
      "z": 1,
      "name": "Wood_Fig_Blue_Trunk"
    },
    {
      "x": 1,
      "y": 10,
      "z": 1,
      "name": "Wood_Fig_Blue_Trunk"
    },
    {
      "x": 1,
      "y": 11,
      "z": 1,
      "name": "Wood_Fig_Blue_Trunk"
    },
    {
      "x": 1,
      "y": 12,
      "z": 1,
      "name": "Wood_Fig_Blue_Trunk"
    },
    {
      "x": 1,
      "y": 13,
      "z": 1,
      "name": "Wood_Fig_Blue_Trunk"
    },
    {
      "x": 1,
      "y": 14,
      "z": 1,
      "name": "Wood_Fig_Blue_Trunk"
    },
    {
      "x": 1,
      "y": 15,
      "z": 1,
      "name": "Wood_Fig_Blue_Trunk"
    },
    {
      "x": 1,
      "y": 16,
      "z": 1,
      "name": "Wood_Fig_Blue_Trunk"
    },
    {
      "x": 1,
      "y": 17,
      "z": 1,
      "name": "Wood_Fig_Blue_Trunk"
    },
    {
      "x": 1,
      "y": 18,
      "z": 1,
      "name": "Wood_Fig_Blue_Trunk"
    },
    {
      "x": 1,
      "y": 19,
      "z": 1,
      "name": "Wood_Fig_Blue_Trunk"
    },
    {
      "x": 1,
      "y": 20,
      "z": 1,
      "name": "Wood_Fig_Blue_Trunk"
    },
    {
      "x": 1,
      "y": 21,
      "z": 1,
      "name": "Wood_Fig_Blue_Trunk"
    },
    {
      "x": 1,
      "y": 22,
      "z": 1,
      "name": "Wood_Fig_Blue_Trunk"
    },
    {
      "x": 1,
      "y": 23,
      "z": 1,
      "name": "Wood_Fig_Blue_Trunk"
    },
    {
      "x": 1,
      "y": 24,
      "z": 1,
      "name": "Wood_Fig_Blue_Trunk"
    },
    {
      "x": 1,
      "y": 25,
      "z": 1,
      "name": "Wood_Fig_Blue_Trunk"
    },
    {
      "x": 1,
      "y": 26,
      "z": 1,
      "name": "Wood_Fig_Blue_Trunk"
    },
    {
      "x": 1,
      "y": 27,
      "z": 1,
      "name": "Wood_Fig_Blue_Trunk"
    },
    {
      "x": 1,
      "y": 28,
      "z": 1,
      "name": "Wood_Fig_Blue_Trunk"
    },
    {
      "x": 1,
      "y": 29,
      "z": 1,
      "name": "Wood_Fig_Blue_Trunk"
    },
    {
      "x": 1,
      "y": 30,
      "z": 1,
      "name": "Wood_Fig_Blue_Trunk"
    },
    {
      "x": 1,
      "y": 31,
      "z": 1,
      "name": "Wood_Fig_Blue_Trunk_Full"
    },
    {
      "x": 1,
      "y": 42,
      "z": 1,
      "name": "Plant_Leaves_Fig_Blue"
    },
    {
      "x": 1,
      "y": 2,
      "z": 2,
      "name": "Wood_Fig_Blue_Trunk"
    },
    {
      "x": 1,
      "y": 3,
      "z": 2,
      "name": "Wood_Fig_Blue_Trunk"
    },
    {
      "x": 1,
      "y": 4,
      "z": 2,
      "name": "Wood_Fig_Blue_Trunk"
    },
    {
      "x": 1,
      "y": 5,
      "z": 2,
      "name": "Wood_Fig_Blue_Trunk"
    },
    {
      "x": 1,
      "y": 6,
      "z": 2,
      "name": "Wood_Fig_Blue_Trunk"
    },
    {
      "x": 1,
      "y": 7,
      "z": 2,
      "name": "Wood_Fig_Blue_Trunk"
    },
    {
      "x": 1,
      "y": 8,
      "z": 2,
      "name": "Wood_Fig_Blue_Trunk"
    },
    {
      "x": 1,
      "y": 9,
      "z": 2,
      "name": "Wood_Fig_Blue_Trunk"
    },
    {
      "x": 1,
      "y": 10,
      "z": 2,
      "name": "Wood_Fig_Blue_Trunk"
    },
    {
      "x": 1,
      "y": 11,
      "z": 2,
      "name": "Wood_Fig_Blue_Trunk"
    },
    {
      "x": 1,
      "y": 12,
      "z": 2,
      "name": "Wood_Fig_Blue_Trunk"
    },
    {
      "x": 1,
      "y": 13,
      "z": 2,
      "name": "Wood_Fig_Blue_Trunk"
    },
    {
      "x": 1,
      "y": 14,
      "z": 2,
      "name": "Wood_Fig_Blue_Trunk"
    },
    {
      "x": 1,
      "y": 15,
      "z": 2,
      "name": "Wood_Fig_Blue_Trunk"
    },
    {
      "x": 1,
      "y": 16,
      "z": 2,
      "name": "Wood_Fig_Blue_Trunk"
    },
    {
      "x": 1,
      "y": 17,
      "z": 2,
      "name": "Wood_Fig_Blue_Trunk"
    },
    {
      "x": 1,
      "y": 18,
      "z": 2,
      "name": "Wood_Fig_Blue_Trunk"
    },
    {
      "x": 1,
      "y": 19,
      "z": 2,
      "name": "Wood_Fig_Blue_Trunk"
    },
    {
      "x": 1,
      "y": 20,
      "z": 2,
      "name": "Wood_Fig_Blue_Trunk"
    },
    {
      "x": 1,
      "y": 21,
      "z": 2,
      "name": "Wood_Fig_Blue_Trunk"
    },
    {
      "x": 1,
      "y": 22,
      "z": 2,
      "name": "Wood_Fig_Blue_Trunk"
    },
    {
      "x": 1,
      "y": 23,
      "z": 2,
      "name": "Wood_Fig_Blue_Trunk"
    },
    {
      "x": 1,
      "y": 24,
      "z": 2,
      "name": "Wood_Fig_Blue_Trunk"
    },
    {
      "x": 1,
      "y": 25,
      "z": 2,
      "name": "Wood_Fig_Blue_Trunk"
    },
    {
      "x": 1,
      "y": 26,
      "z": 2,
      "name": "Wood_Fig_Blue_Trunk"
    },
    {
      "x": 1,
      "y": 27,
      "z": 2,
      "name": "Wood_Fig_Blue_Trunk"
    },
    {
      "x": 1,
      "y": 28,
      "z": 2,
      "name": "Wood_Fig_Blue_Trunk"
    },
    {
      "x": 1,
      "y": 29,
      "z": 2,
      "name": "Wood_Fig_Blue_Trunk"
    },
    {
      "x": 1,
      "y": 30,
      "z": 2,
      "name": "Wood_Fig_Blue_Trunk"
    },
    {
      "x": 1,
      "y": 31,
      "z": 2,
      "name": "Wood_Fig_Blue_Trunk"
    },
    {
      "x": 1,
      "y": 32,
      "z": 2,
      "name": "Wood_Fig_Blue_Trunk"
    },
    {
      "x": 1,
      "y": 33,
      "z": 2,
      "name": "Wood_Fig_Blue_Trunk"
    },
    {
      "x": 1,
      "y": 34,
      "z": 2,
      "name": "Wood_Fig_Blue_Trunk"
    },
    {
      "x": 1,
      "y": 35,
      "z": 2,
      "name": "Wood_Fig_Blue_Trunk"
    },
    {
      "x": 1,
      "y": 36,
      "z": 2,
      "name": "Wood_Fig_Blue_Trunk_Full"
    },
    {
      "x": 1,
      "y": 42,
      "z": 2,
      "name": "Plant_Leaves_Fig_Blue"
    },
    {
      "x": 1,
      "y": 2,
      "z": 3,
      "name": "Wood_Fig_Blue_Trunk"
    },
    {
      "x": 1,
      "y": 3,
      "z": 3,
      "name": "Wood_Fig_Blue_Trunk"
    },
    {
      "x": 1,
      "y": 4,
      "z": 3,
      "name": "Wood_Fig_Blue_Trunk"
    },
    {
      "x": 1,
      "y": 5,
      "z": 3,
      "name": "Wood_Fig_Blue_Trunk"
    },
    {
      "x": 1,
      "y": 6,
      "z": 3,
      "name": "Wood_Fig_Blue_Trunk"
    },
    {
      "x": 1,
      "y": 7,
      "z": 3,
      "name": "Wood_Fig_Blue_Trunk"
    },
    {
      "x": 1,
      "y": 8,
      "z": 3,
      "name": "Wood_Fig_Blue_Trunk_Full"
    },
    {
      "x": 1,
      "y": 9,
      "z": 3,
      "name": "Wood_Fig_Blue_Branch_Long"
    },
    {
      "x": 1,
      "y": 10,
      "z": 3,
      "name": "Wood_Fig_Blue_Branch_Long"
    },
    {
      "x": 1,
      "y": 11,
      "z": 3,
      "name": "Wood_Fig_Blue_Branch_Long"
    },
    {
      "x": 1,
      "y": 12,
      "z": 3,
      "name": "Wood_Fig_Blue_Branch_Corner",
      "rotation": 10
    },
    {
      "x": 1,
      "y": 27,
      "z": 3,
      "name": "Wood_Fig_Blue_Trunk_Full"
    },
    {
      "x": 1,
      "y": 28,
      "z": 3,
      "name": "Wood_Fig_Blue_Trunk"
    },
    {
      "x": 1,
      "y": 29,
      "z": 3,
      "name": "Wood_Fig_Blue_Trunk_Full"
    },
    {
      "x": 1,
      "y": 33,
      "z": 3,
      "name": "Wood_Fig_Blue_Trunk_Full"
    },
    {
      "x": 1,
      "y": 34,
      "z": 3,
      "name": "Wood_Fig_Blue_Trunk"
    },
    {
      "x": 1,
      "y": 35,
      "z": 3,
      "name": "Wood_Fig_Blue_Trunk"
    },
    {
      "x": 1,
      "y": 36,
      "z": 3,
      "name": "Wood_Fig_Blue_Trunk"
    },
    {
      "x": 1,
      "y": 37,
      "z": 3,
      "name": "Wood_Fig_Blue_Trunk_Full"
    },
    {
      "x": 1,
      "y": 2,
      "z": 4,
      "name": "Wood_Fig_Blue_Trunk"
    },
    {
      "x": 1,
      "y": 3,
      "z": 4,
      "name": "Wood_Fig_Blue_Trunk"
    },
    {
      "x": 1,
      "y": 4,
      "z": 4,
      "name": "Wood_Fig_Blue_Trunk_Full"
    },
    {
      "x": 1,
      "y": 30,
      "z": 4,
      "name": "Wood_Fig_Blue_Branch_Corner",
      "rotation": 1
    },
    {
      "x": 1,
      "y": 31,
      "z": 4,
      "name": "Wood_Fig_Blue_Branch_Long"
    },
    {
      "x": 1,
      "y": 32,
      "z": 4,
      "name": "Wood_Fig_Blue_Branch_Long"
    },
    {
      "x": 1,
      "y": 33,
      "z": 4,
      "name": "Plant_Leaves_Fig_Blue"
    },
    {
      "x": 1,
      "y": 44,
      "z": 4,
      "name": "Plant_Leaves_Fig_Blue"
    },
    {
      "x": 1,
      "y": 2,
      "z": 5,
      "name": "Wood_Fig_Blue_Branch_Long"
    },
    {
      "x": 1,
      "y": 3,
      "z": 5,
      "name": "Wood_Fig_Blue_Branch_Long"
    },
    {
      "x": 1,
      "y": 4,
      "z": 5,
      "name": "Wood_Fig_Blue_Branch_Corner",
      "rotation": 10
    },
    {
      "x": 1,
      "y": 33,
      "z": 5,
      "name": "Plant_Leaves_Fig_Blue"
    },
    {
      "x": 1,
      "y": 44,
      "z": 5,
      "name": "Plant_Leaves_Fig_Blue"
    },
    {
      "x": 1,
      "y": 29,
      "z": 6,
      "name": "Plant_Leaves_Fig_Blue"
    },
    {
      "x": 1,
      "y": 29,
      "z": 7,
      "name": "Plant_Leaves_Fig_Blue"
    },
    {
      "x": 1,
      "y": 30,
      "z": 7,
      "name": "Plant_Leaves_Fig_Blue"
    },
    {
      "x": 1,
      "y": 32,
      "z": 7,
      "name": "Plant_Leaves_Fig_Blue"
    },
    {
      "x": 1,
      "y": 45,
      "z": 7,
      "name": "Plant_Leaves_Fig_Blue"
    },
    {
      "x": 1,
      "y": 46,
      "z": 7,
      "name": "Plant_Leaves_Fig_Blue"
    },
    {
      "x": 1,
      "y": 30,
      "z": 8,
      "name": "Plant_Leaves_Fig_Blue"
    },
    {
      "x": 1,
      "y": 41,
      "z": 8,
      "name": "Wood_Fig_Blue_Trunk_Full"
    },
    {
      "x": 1,
      "y": 42,
      "z": 8,
      "name": "Wood_Fig_Blue_Trunk_Full"
    },
    {
      "x": 1,
      "y": 45,
      "z": 8,
      "name": "Plant_Leaves_Fig_Blue"
    },
    {
      "x": 1,
      "y": 46,
      "z": 8,
      "name": "Plant_Leaves_Fig_Blue"
    },
    {
      "x": 1,
      "y": 42,
      "z": 9,
      "name": "Wood_Fig_Blue_Trunk_Full"
    },
    {
      "x": 1,
      "y": 45,
      "z": 9,
      "name": "Plant_Leaves_Fig_Blue"
    },
    {
      "x": 1,
      "y": 39,
      "z": 10,
      "name": "Plant_Leaves_Fig_Blue"
    },
    {
      "x": 1,
      "y": 42,
      "z": 10,
      "name": "Wood_Fig_Blue_Branch_Long",
      "rotation": 4
    },
    {
      "x": 1,
      "y": 45,
      "z": 10,
      "name": "Plant_Leaves_Fig_Blue"
    },
    {
      "x": 1,
      "y": 39,
      "z": 11,
      "name": "Plant_Leaves_Fig_Blue"
    },
    {
      "x": 1,
      "y": 40,
      "z": 11,
      "name": "Plant_Leaves_Fig_Blue"
    },
    {
      "x": 1,
      "y": 41,
      "z": 11,
      "name": "Plant_Leaves_Fig_Blue"
    },
    {
      "x": 1,
      "y": 42,
      "z": 11,
      "name": "Wood_Fig_Blue_Branch_Corner"
    },
    {
      "x": 1,
      "y": 43,
      "z": 11,
      "name": "Wood_Fig_Blue_Branch_Long"
    },
    {
      "x": 1,
      "y": 44,
      "z": 11,
      "name": "Plant_Leaves_Fig_Blue"
    },
    {
      "x": 1,
      "y": 42,
      "z": 12,
      "name": "Plant_Leaves_Fig_Blue"
    },
    {
      "x": 1,
      "y": 43,
      "z": 12,
      "name": "Plant_Leaves_Fig_Blue"
    },
    {
      "x": 2,
      "y": 36,
      "z": -11,
      "name": "Plant_Leaves_Fig_Blue"
    },
    {
      "x": 2,
      "y": 37,
      "z": -11,
      "name": "Plant_Leaves_Fig_Blue"
    },
    {
      "x": 2,
      "y": 38,
      "z": -11,
      "name": "Plant_Leaves_Fig_Blue"
    },
    {
      "x": 2,
      "y": 39,
      "z": -11,
      "name": "Plant_Leaves_Fig_Blue"
    },
    {
      "x": 2,
      "y": 40,
      "z": -11,
      "name": "Plant_Leaves_Fig_Blue"
    },
    {
      "x": 2,
      "y": 38,
      "z": -10,
      "name": "Plant_Leaves_Fig_Blue"
    },
    {
      "x": 2,
      "y": 39,
      "z": -10,
      "name": "Plant_Leaves_Fig_Blue"
    },
    {
      "x": 2,
      "y": 39,
      "z": -9,
      "name": "Plant_Leaves_Fig_Blue"
    },
    {
      "x": 2,
      "y": 39,
      "z": -8,
      "name": "Wood_Fig_Blue_Branch_Corner",
      "rotation": 1
    },
    {
      "x": 2,
      "y": 40,
      "z": -8,
      "name": "Wood_Fig_Blue_Branch_Long"
    },
    {
      "x": 2,
      "y": 41,
      "z": -8,
      "name": "Plant_Leaves_Fig_Blue"
    },
    {
      "x": 2,
      "y": 42,
      "z": -7,
      "name": "Plant_Leaves_Fig_Blue"
    },
    {
      "x": 2,
      "y": 42,
      "z": -4,
      "name": "Plant_Leaves_Fig_Blue"
    },
    {
      "x": 2,
      "y": 43,
      "z": -4,
      "name": "Plant_Leaves_Fig_Blue"
    },
    {
      "x": 2,
      "y": 42,
      "z": -3,
      "name": "Plant_Leaves_Fig_Blue"
    },
    {
      "x": 2,
      "y": 44,
      "z": -3,
      "name": "Plant_Leaves_Fig_Blue"
    },
    {
      "x": 2,
      "y": 43,
      "z": -2,
      "name": "Plant_Leaves_Fig_Blue"
    },
    {
      "x": 2,
      "y": 4,
      "z": -1,
      "name": "Wood_Fig_Blue_Trunk_Full"
    },
    {
      "x": 2,
      "y": 5,
      "z": -1,
      "name": "Wood_Fig_Blue_Branch_Long"
    },
    {
      "x": 2,
      "y": 6,
      "z": -1,
      "name": "Wood_Fig_Blue_Branch_Long"
    },
    {
      "x": 2,
      "y": 7,
      "z": -1,
      "name": "Wood_Fig_Blue_Branch_Long"
    },
    {
      "x": 2,
      "y": 8,
      "z": -1,
      "name": "Wood_Fig_Blue_Branch_Corner",
      "rotation": 8
    },
    {
      "x": 2,
      "y": 35,
      "z": -1,
      "name": "Wood_Fig_Blue_Trunk_Full"
    },
    {
      "x": 2,
      "y": 36,
      "z": -1,
      "name": "Wood_Fig_Blue_Trunk"
    },
    {
      "x": 2,
      "y": 37,
      "z": -1,
      "name": "Wood_Fig_Blue_Trunk_Full"
    },
    {
      "x": 2,
      "y": 43,
      "z": -1,
      "name": "Plant_Leaves_Fig_Blue"
    },
    {
      "x": 2,
      "y": 2,
      "z": 0,
      "name": "Wood_Fig_Blue_Trunk"
    },
    {
      "x": 2,
      "y": 3,
      "z": 0,
      "name": "Wood_Fig_Blue_Trunk"
    },
    {
      "x": 2,
      "y": 4,
      "z": 0,
      "name": "Wood_Fig_Blue_Trunk"
    },
    {
      "x": 2,
      "y": 5,
      "z": 0,
      "name": "Wood_Fig_Blue_Trunk"
    },
    {
      "x": 2,
      "y": 6,
      "z": 0,
      "name": "Wood_Fig_Blue_Trunk"
    },
    {
      "x": 2,
      "y": 7,
      "z": 0,
      "name": "Wood_Fig_Blue_Trunk"
    },
    {
      "x": 2,
      "y": 8,
      "z": 0,
      "name": "Wood_Fig_Blue_Trunk_Full"
    },
    {
      "x": 2,
      "y": 9,
      "z": 0,
      "name": "Wood_Fig_Blue_Branch_Long"
    },
    {
      "x": 2,
      "y": 10,
      "z": 0,
      "name": "Wood_Fig_Blue_Branch_Corner",
      "rotation": 8
    },
    {
      "x": 2,
      "y": 32,
      "z": 0,
      "name": "Wood_Fig_Blue_Trunk_Full"
    },
    {
      "x": 2,
      "y": 33,
      "z": 0,
      "name": "Wood_Fig_Blue_Trunk"
    },
    {
      "x": 2,
      "y": 34,
      "z": 0,
      "name": "Wood_Fig_Blue_Trunk"
    },
    {
      "x": 2,
      "y": 35,
      "z": 0,
      "name": "Wood_Fig_Blue_Trunk"
    },
    {
      "x": 2,
      "y": 36,
      "z": 0,
      "name": "Wood_Fig_Blue_Trunk"
    },
    {
      "x": 2,
      "y": 37,
      "z": 0,
      "name": "Wood_Fig_Blue_Trunk"
    },
    {
      "x": 2,
      "y": 38,
      "z": 0,
      "name": "Wood_Fig_Blue_Trunk"
    },
    {
      "x": 2,
      "y": 39,
      "z": 0,
      "name": "Wood_Fig_Blue_Trunk"
    },
    {
      "x": 2,
      "y": 40,
      "z": 0,
      "name": "Wood_Fig_Blue_Trunk_Full"
    },
    {
      "x": 2,
      "y": 42,
      "z": 0,
      "name": "Plant_Leaves_Fig_Blue"
    },
    {
      "x": 2,
      "y": 43,
      "z": 0,
      "name": "Plant_Leaves_Fig_Blue"
    },
    {
      "x": 2,
      "y": 2,
      "z": 1,
      "name": "Wood_Fig_Blue_Trunk"
    },
    {
      "x": 2,
      "y": 3,
      "z": 1,
      "name": "Wood_Fig_Blue_Trunk"
    },
    {
      "x": 2,
      "y": 4,
      "z": 1,
      "name": "Wood_Fig_Blue_Trunk"
    },
    {
      "x": 2,
      "y": 5,
      "z": 1,
      "name": "Wood_Fig_Blue_Trunk"
    },
    {
      "x": 2,
      "y": 6,
      "z": 1,
      "name": "Wood_Fig_Blue_Trunk"
    },
    {
      "x": 2,
      "y": 7,
      "z": 1,
      "name": "Wood_Fig_Blue_Trunk"
    },
    {
      "x": 2,
      "y": 8,
      "z": 1,
      "name": "Wood_Fig_Blue_Trunk"
    },
    {
      "x": 2,
      "y": 9,
      "z": 1,
      "name": "Wood_Fig_Blue_Trunk"
    },
    {
      "x": 2,
      "y": 10,
      "z": 1,
      "name": "Wood_Fig_Blue_Trunk"
    },
    {
      "x": 2,
      "y": 11,
      "z": 1,
      "name": "Wood_Fig_Blue_Trunk"
    },
    {
      "x": 2,
      "y": 12,
      "z": 1,
      "name": "Wood_Fig_Blue_Trunk"
    },
    {
      "x": 2,
      "y": 13,
      "z": 1,
      "name": "Wood_Fig_Blue_Trunk"
    },
    {
      "x": 2,
      "y": 14,
      "z": 1,
      "name": "Wood_Fig_Blue_Trunk"
    },
    {
      "x": 2,
      "y": 15,
      "z": 1,
      "name": "Wood_Fig_Blue_Trunk"
    },
    {
      "x": 2,
      "y": 16,
      "z": 1,
      "name": "Wood_Fig_Blue_Trunk"
    },
    {
      "x": 2,
      "y": 17,
      "z": 1,
      "name": "Wood_Fig_Blue_Trunk"
    },
    {
      "x": 2,
      "y": 18,
      "z": 1,
      "name": "Wood_Fig_Blue_Trunk"
    },
    {
      "x": 2,
      "y": 19,
      "z": 1,
      "name": "Wood_Fig_Blue_Trunk"
    },
    {
      "x": 2,
      "y": 20,
      "z": 1,
      "name": "Wood_Fig_Blue_Trunk"
    },
    {
      "x": 2,
      "y": 21,
      "z": 1,
      "name": "Wood_Fig_Blue_Trunk"
    },
    {
      "x": 2,
      "y": 22,
      "z": 1,
      "name": "Wood_Fig_Blue_Trunk"
    },
    {
      "x": 2,
      "y": 23,
      "z": 1,
      "name": "Wood_Fig_Blue_Trunk"
    },
    {
      "x": 2,
      "y": 24,
      "z": 1,
      "name": "Wood_Fig_Blue_Trunk"
    },
    {
      "x": 2,
      "y": 25,
      "z": 1,
      "name": "Wood_Fig_Blue_Trunk"
    },
    {
      "x": 2,
      "y": 26,
      "z": 1,
      "name": "Wood_Fig_Blue_Trunk"
    },
    {
      "x": 2,
      "y": 27,
      "z": 1,
      "name": "Wood_Fig_Blue_Trunk"
    },
    {
      "x": 2,
      "y": 28,
      "z": 1,
      "name": "Wood_Fig_Blue_Trunk"
    },
    {
      "x": 2,
      "y": 29,
      "z": 1,
      "name": "Wood_Fig_Blue_Trunk"
    },
    {
      "x": 2,
      "y": 30,
      "z": 1,
      "name": "Wood_Fig_Blue_Trunk"
    },
    {
      "x": 2,
      "y": 31,
      "z": 1,
      "name": "Wood_Fig_Blue_Trunk"
    },
    {
      "x": 2,
      "y": 32,
      "z": 1,
      "name": "Wood_Fig_Blue_Trunk"
    },
    {
      "x": 2,
      "y": 33,
      "z": 1,
      "name": "Wood_Fig_Blue_Trunk"
    },
    {
      "x": 2,
      "y": 34,
      "z": 1,
      "name": "Wood_Fig_Blue_Trunk"
    },
    {
      "x": 2,
      "y": 35,
      "z": 1,
      "name": "Wood_Fig_Blue_Trunk_Full"
    },
    {
      "x": 2,
      "y": 42,
      "z": 1,
      "name": "Plant_Leaves_Fig_Blue"
    },
    {
      "x": 2,
      "y": 2,
      "z": 2,
      "name": "Wood_Fig_Blue_Trunk"
    },
    {
      "x": 2,
      "y": 3,
      "z": 2,
      "name": "Wood_Fig_Blue_Trunk"
    },
    {
      "x": 2,
      "y": 4,
      "z": 2,
      "name": "Wood_Fig_Blue_Trunk"
    },
    {
      "x": 2,
      "y": 5,
      "z": 2,
      "name": "Wood_Fig_Blue_Trunk"
    },
    {
      "x": 2,
      "y": 6,
      "z": 2,
      "name": "Wood_Fig_Blue_Trunk"
    },
    {
      "x": 2,
      "y": 7,
      "z": 2,
      "name": "Wood_Fig_Blue_Trunk"
    },
    {
      "x": 2,
      "y": 8,
      "z": 2,
      "name": "Wood_Fig_Blue_Trunk"
    },
    {
      "x": 2,
      "y": 9,
      "z": 2,
      "name": "Wood_Fig_Blue_Trunk"
    },
    {
      "x": 2,
      "y": 10,
      "z": 2,
      "name": "Wood_Fig_Blue_Trunk"
    },
    {
      "x": 2,
      "y": 11,
      "z": 2,
      "name": "Wood_Fig_Blue_Trunk"
    },
    {
      "x": 2,
      "y": 12,
      "z": 2,
      "name": "Wood_Fig_Blue_Trunk"
    },
    {
      "x": 2,
      "y": 13,
      "z": 2,
      "name": "Wood_Fig_Blue_Trunk"
    },
    {
      "x": 2,
      "y": 14,
      "z": 2,
      "name": "Wood_Fig_Blue_Trunk"
    },
    {
      "x": 2,
      "y": 15,
      "z": 2,
      "name": "Wood_Fig_Blue_Trunk"
    },
    {
      "x": 2,
      "y": 16,
      "z": 2,
      "name": "Wood_Fig_Blue_Trunk"
    },
    {
      "x": 2,
      "y": 17,
      "z": 2,
      "name": "Wood_Fig_Blue_Trunk"
    },
    {
      "x": 2,
      "y": 18,
      "z": 2,
      "name": "Wood_Fig_Blue_Trunk"
    },
    {
      "x": 2,
      "y": 19,
      "z": 2,
      "name": "Wood_Fig_Blue_Trunk"
    },
    {
      "x": 2,
      "y": 20,
      "z": 2,
      "name": "Wood_Fig_Blue_Trunk"
    },
    {
      "x": 2,
      "y": 21,
      "z": 2,
      "name": "Wood_Fig_Blue_Trunk"
    },
    {
      "x": 2,
      "y": 22,
      "z": 2,
      "name": "Wood_Fig_Blue_Trunk"
    },
    {
      "x": 2,
      "y": 23,
      "z": 2,
      "name": "Wood_Fig_Blue_Trunk"
    },
    {
      "x": 2,
      "y": 24,
      "z": 2,
      "name": "Wood_Fig_Blue_Trunk"
    },
    {
      "x": 2,
      "y": 25,
      "z": 2,
      "name": "Wood_Fig_Blue_Trunk"
    },
    {
      "x": 2,
      "y": 26,
      "z": 2,
      "name": "Wood_Fig_Blue_Trunk"
    },
    {
      "x": 2,
      "y": 27,
      "z": 2,
      "name": "Wood_Fig_Blue_Trunk"
    },
    {
      "x": 2,
      "y": 28,
      "z": 2,
      "name": "Wood_Fig_Blue_Trunk"
    },
    {
      "x": 2,
      "y": 29,
      "z": 2,
      "name": "Wood_Fig_Blue_Trunk"
    },
    {
      "x": 2,
      "y": 30,
      "z": 2,
      "name": "Wood_Fig_Blue_Trunk"
    },
    {
      "x": 2,
      "y": 31,
      "z": 2,
      "name": "Wood_Fig_Blue_Trunk"
    },
    {
      "x": 2,
      "y": 32,
      "z": 2,
      "name": "Wood_Fig_Blue_Trunk"
    },
    {
      "x": 2,
      "y": 33,
      "z": 2,
      "name": "Wood_Fig_Blue_Trunk_Full"
    },
    {
      "x": 2,
      "y": 2,
      "z": 3,
      "name": "Wood_Fig_Blue_Trunk"
    },
    {
      "x": 2,
      "y": 3,
      "z": 3,
      "name": "Wood_Fig_Blue_Trunk"
    },
    {
      "x": 2,
      "y": 4,
      "z": 3,
      "name": "Wood_Fig_Blue_Trunk"
    },
    {
      "x": 2,
      "y": 5,
      "z": 3,
      "name": "Wood_Fig_Blue_Trunk"
    },
    {
      "x": 2,
      "y": 6,
      "z": 3,
      "name": "Wood_Fig_Blue_Trunk"
    },
    {
      "x": 2,
      "y": 7,
      "z": 3,
      "name": "Wood_Fig_Blue_Trunk"
    },
    {
      "x": 2,
      "y": 8,
      "z": 3,
      "name": "Wood_Fig_Blue_Trunk"
    },
    {
      "x": 2,
      "y": 9,
      "z": 3,
      "name": "Wood_Fig_Blue_Trunk_Full"
    },
    {
      "x": 2,
      "y": 10,
      "z": 3,
      "name": "Wood_Fig_Blue_Branch_Long"
    },
    {
      "x": 2,
      "y": 11,
      "z": 3,
      "name": "Wood_Fig_Blue_Branch_Long"
    },
    {
      "x": 2,
      "y": 12,
      "z": 3,
      "name": "Wood_Fig_Blue_Branch_Long"
    },
    {
      "x": 2,
      "y": 13,
      "z": 3,
      "name": "Wood_Fig_Blue_Branch_Corner",
      "rotation": 10
    },
    {
      "x": 2,
      "y": 2,
      "z": 4,
      "name": "Wood_Fig_Blue_Trunk"
    },
    {
      "x": 2,
      "y": 3,
      "z": 4,
      "name": "Wood_Fig_Blue_Trunk"
    },
    {
      "x": 2,
      "y": 4,
      "z": 4,
      "name": "Wood_Fig_Blue_Trunk"
    },
    {
      "x": 2,
      "y": 5,
      "z": 4,
      "name": "Wood_Fig_Blue_Trunk"
    },
    {
      "x": 2,
      "y": 6,
      "z": 4,
      "name": "Wood_Fig_Blue_Trunk_Full"
    },
    {
      "x": 2,
      "y": 7,
      "z": 4,
      "name": "Wood_Fig_Blue_Branch_Long"
    },
    {
      "x": 2,
      "y": 8,
      "z": 4,
      "name": "Wood_Fig_Blue_Branch_Long"
    },
    {
      "x": 2,
      "y": 9,
      "z": 4,
      "name": "Wood_Fig_Blue_Branch_Corner",
      "rotation": 10
    },
    {
      "x": 2,
      "y": 2,
      "z": 5,
      "name": "Wood_Fig_Blue_Branch_Long"
    },
    {
      "x": 2,
      "y": 3,
      "z": 5,
      "name": "Wood_Fig_Blue_Branch_Long"
    },
    {
      "x": 2,
      "y": 4,
      "z": 5,
      "name": "Wood_Fig_Blue_Branch_Long"
    },
    {
      "x": 2,
      "y": 5,
      "z": 5,
      "name": "Wood_Fig_Blue_Branch_Long"
    },
    {
      "x": 2,
      "y": 6,
      "z": 5,
      "name": "Wood_Fig_Blue_Branch_Corner",
      "rotation": 10
    },
    {
      "x": 2,
      "y": 29,
      "z": 5,
      "name": "Plant_Leaves_Fig_Blue"
    },
    {
      "x": 2,
      "y": 32,
      "z": 5,
      "name": "Plant_Leaves_Fig_Blue"
    },
    {
      "x": 2,
      "y": 44,
      "z": 5,
      "name": "Plant_Leaves_Fig_Blue"
    },
    {
      "x": 2,
      "y": 29,
      "z": 6,
      "name": "Plant_Leaves_Fig_Blue"
    },
    {
      "x": 2,
      "y": 30,
      "z": 6,
      "name": "Plant_Leaves_Fig_Blue"
    },
    {
      "x": 2,
      "y": 31,
      "z": 6,
      "name": "Plant_Leaves_Fig_Blue"
    },
    {
      "x": 2,
      "y": 32,
      "z": 6,
      "name": "Plant_Leaves_Fig_Blue"
    },
    {
      "x": 2,
      "y": 44,
      "z": 6,
      "name": "Plant_Leaves_Fig_Blue"
    },
    {
      "x": 2,
      "y": 45,
      "z": 6,
      "name": "Plant_Leaves_Fig_Blue"
    },
    {
      "x": 2,
      "y": 30,
      "z": 7,
      "name": "Plant_Leaves_Fig_Blue"
    },
    {
      "x": 2,
      "y": 31,
      "z": 7,
      "name": "Plant_Leaves_Fig_Blue"
    },
    {
      "x": 2,
      "y": 44,
      "z": 7,
      "name": "Plant_Leaves_Fig_Blue"
    },
    {
      "x": 2,
      "y": 45,
      "z": 7,
      "name": "Plant_Leaves_Fig_Blue"
    },
    {
      "x": 2,
      "y": 44,
      "z": 8,
      "name": "Plant_Leaves_Fig_Blue"
    },
    {
      "x": 2,
      "y": 42,
      "z": 9,
      "name": "Wood_Fig_Blue_Branch_Long",
      "rotation": 5
    },
    {
      "x": 2,
      "y": 44,
      "z": 9,
      "name": "Plant_Leaves_Fig_Blue"
    },
    {
      "x": 2,
      "y": 45,
      "z": 9,
      "name": "Plant_Leaves_Fig_Blue"
    },
    {
      "x": 2,
      "y": 39,
      "z": 10,
      "name": "Plant_Leaves_Fig_Blue"
    },
    {
      "x": 2,
      "y": 43,
      "z": 10,
      "name": "Plant_Leaves_Fig_Blue"
    },
    {
      "x": 2,
      "y": 44,
      "z": 10,
      "name": "Plant_Leaves_Fig_Blue"
    },
    {
      "x": 2,
      "y": 40,
      "z": 11,
      "name": "Plant_Leaves_Fig_Blue"
    },
    {
      "x": 2,
      "y": 41,
      "z": 11,
      "name": "Plant_Leaves_Fig_Blue"
    },
    {
      "x": 2,
      "y": 42,
      "z": 11,
      "name": "Plant_Leaves_Fig_Blue"
    },
    {
      "x": 2,
      "y": 43,
      "z": 11,
      "name": "Plant_Leaves_Fig_Blue"
    },
    {
      "x": 2,
      "y": 44,
      "z": 11,
      "name": "Plant_Leaves_Fig_Blue"
    },
    {
      "x": 3,
      "y": 38,
      "z": -11,
      "name": "Plant_Leaves_Fig_Blue"
    },
    {
      "x": 3,
      "y": 39,
      "z": -11,
      "name": "Plant_Leaves_Fig_Blue"
    },
    {
      "x": 3,
      "y": 37,
      "z": -10,
      "name": "Plant_Leaves_Fig_Blue"
    },
    {
      "x": 3,
      "y": 38,
      "z": -10,
      "name": "Plant_Leaves_Fig_Blue"
    },
    {
      "x": 3,
      "y": 39,
      "z": -10,
      "name": "Plant_Leaves_Fig_Blue"
    },
    {
      "x": 3,
      "y": 40,
      "z": -10,
      "name": "Plant_Leaves_Fig_Blue"
    },
    {
      "x": 3,
      "y": 37,
      "z": -9,
      "name": "Plant_Leaves_Fig_Blue"
    },
    {
      "x": 3,
      "y": 38,
      "z": -9,
      "name": "Plant_Leaves_Fig_Blue"
    },
    {
      "x": 3,
      "y": 39,
      "z": -9,
      "name": "Plant_Leaves_Fig_Blue"
    },
    {
      "x": 3,
      "y": 40,
      "z": -9,
      "name": "Plant_Leaves_Fig_Blue"
    },
    {
      "x": 3,
      "y": 41,
      "z": -9,
      "name": "Plant_Leaves_Fig_Blue"
    },
    {
      "x": 3,
      "y": 37,
      "z": -8,
      "name": "Plant_Leaves_Fig_Blue"
    },
    {
      "x": 3,
      "y": 38,
      "z": -8,
      "name": "Plant_Leaves_Fig_Blue"
    },
    {
      "x": 3,
      "y": 39,
      "z": -8,
      "name": "Plant_Leaves_Fig_Blue"
    },
    {
      "x": 3,
      "y": 39,
      "z": -7,
      "name": "Plant_Leaves_Fig_Blue"
    },
    {
      "x": 3,
      "y": 40,
      "z": -7,
      "name": "Plant_Leaves_Fig_Blue"
    },
    {
      "x": 3,
      "y": 41,
      "z": -7,
      "name": "Plant_Leaves_Fig_Blue"
    },
    {
      "x": 3,
      "y": 42,
      "z": -3,
      "name": "Plant_Leaves_Fig_Blue"
    },
    {
      "x": 3,
      "y": 43,
      "z": -2,
      "name": "Plant_Leaves_Fig_Blue"
    },
    {
      "x": 3,
      "y": 2,
      "z": -1,
      "name": "Wood_Fig_Blue_Branch_Long"
    },
    {
      "x": 3,
      "y": 3,
      "z": -1,
      "name": "Wood_Fig_Blue_Branch_Long"
    },
    {
      "x": 3,
      "y": 4,
      "z": -1,
      "name": "Wood_Fig_Blue_Branch_Long"
    },
    {
      "x": 3,
      "y": 5,
      "z": -1,
      "name": "Wood_Fig_Blue_Branch_Long"
    },
    {
      "x": 3,
      "y": 6,
      "z": -1,
      "name": "Wood_Fig_Blue_Branch_Corner",
      "rotation": 8
    },
    {
      "x": 3,
      "y": 43,
      "z": -1,
      "name": "Plant_Leaves_Fig_Blue"
    },
    {
      "x": 3,
      "y": 2,
      "z": 0,
      "name": "Wood_Fig_Blue_Trunk"
    },
    {
      "x": 3,
      "y": 3,
      "z": 0,
      "name": "Wood_Fig_Blue_Trunk"
    },
    {
      "x": 3,
      "y": 4,
      "z": 0,
      "name": "Wood_Fig_Blue_Trunk"
    },
    {
      "x": 3,
      "y": 5,
      "z": 0,
      "name": "Wood_Fig_Blue_Trunk"
    },
    {
      "x": 3,
      "y": 6,
      "z": 0,
      "name": "Wood_Fig_Blue_Trunk_Full"
    },
    {
      "x": 3,
      "y": 7,
      "z": 0,
      "name": "Wood_Fig_Blue_Branch_Corner",
      "rotation": 8
    },
    {
      "x": 3,
      "y": 2,
      "z": 1,
      "name": "Wood_Fig_Blue_Trunk"
    },
    {
      "x": 3,
      "y": 3,
      "z": 1,
      "name": "Wood_Fig_Blue_Trunk"
    },
    {
      "x": 3,
      "y": 4,
      "z": 1,
      "name": "Wood_Fig_Blue_Trunk"
    },
    {
      "x": 3,
      "y": 5,
      "z": 1,
      "name": "Wood_Fig_Blue_Trunk"
    },
    {
      "x": 3,
      "y": 6,
      "z": 1,
      "name": "Wood_Fig_Blue_Trunk"
    },
    {
      "x": 3,
      "y": 7,
      "z": 1,
      "name": "Wood_Fig_Blue_Trunk"
    },
    {
      "x": 3,
      "y": 8,
      "z": 1,
      "name": "Wood_Fig_Blue_Trunk"
    },
    {
      "x": 3,
      "y": 9,
      "z": 1,
      "name": "Wood_Fig_Blue_Trunk_Full"
    },
    {
      "x": 3,
      "y": 10,
      "z": 1,
      "name": "Wood_Fig_Blue_Branch_Long"
    },
    {
      "x": 3,
      "y": 11,
      "z": 1,
      "name": "Wood_Fig_Blue_Branch_Long"
    },
    {
      "x": 3,
      "y": 12,
      "z": 1,
      "name": "Wood_Fig_Blue_Branch_Corner",
      "rotation": 11
    },
    {
      "x": 3,
      "y": 26,
      "z": 1,
      "name": "Wood_Fig_Blue_Branch_Corner",
      "rotation": 1
    },
    {
      "x": 3,
      "y": 30,
      "z": 1,
      "name": "Wood_Fig_Blue_Trunk_Full"
    },
    {
      "x": 3,
      "y": 31,
      "z": 1,
      "name": "Wood_Fig_Blue_Trunk"
    },
    {
      "x": 3,
      "y": 32,
      "z": 1,
      "name": "Wood_Fig_Blue_Trunk"
    },
    {
      "x": 3,
      "y": 33,
      "z": 1,
      "name": "Wood_Fig_Blue_Trunk_Full"
    },
    {
      "x": 3,
      "y": 2,
      "z": 2,
      "name": "Wood_Fig_Blue_Trunk"
    },
    {
      "x": 3,
      "y": 3,
      "z": 2,
      "name": "Wood_Fig_Blue_Trunk"
    },
    {
      "x": 3,
      "y": 4,
      "z": 2,
      "name": "Wood_Fig_Blue_Trunk"
    },
    {
      "x": 3,
      "y": 5,
      "z": 2,
      "name": "Wood_Fig_Blue_Trunk"
    },
    {
      "x": 3,
      "y": 6,
      "z": 2,
      "name": "Wood_Fig_Blue_Trunk"
    },
    {
      "x": 3,
      "y": 7,
      "z": 2,
      "name": "Wood_Fig_Blue_Trunk"
    },
    {
      "x": 3,
      "y": 8,
      "z": 2,
      "name": "Wood_Fig_Blue_Trunk_Full"
    },
    {
      "x": 3,
      "y": 9,
      "z": 2,
      "name": "Wood_Fig_Blue_Branch_Long"
    },
    {
      "x": 3,
      "y": 10,
      "z": 2,
      "name": "Wood_Fig_Blue_Branch_Long"
    },
    {
      "x": 3,
      "y": 11,
      "z": 2,
      "name": "Wood_Fig_Blue_Branch_Corner",
      "rotation": 11
    },
    {
      "x": 3,
      "y": 2,
      "z": 3,
      "name": "Wood_Fig_Blue_Trunk"
    },
    {
      "x": 3,
      "y": 3,
      "z": 3,
      "name": "Wood_Fig_Blue_Trunk"
    },
    {
      "x": 3,
      "y": 4,
      "z": 3,
      "name": "Wood_Fig_Blue_Trunk"
    },
    {
      "x": 3,
      "y": 5,
      "z": 3,
      "name": "Wood_Fig_Blue_Trunk"
    },
    {
      "x": 3,
      "y": 6,
      "z": 3,
      "name": "Wood_Fig_Blue_Trunk"
    },
    {
      "x": 3,
      "y": 7,
      "z": 3,
      "name": "Wood_Fig_Blue_Trunk_Full"
    },
    {
      "x": 3,
      "y": 8,
      "z": 3,
      "name": "Wood_Fig_Blue_Branch_Corner",
      "rotation": 10
    },
    {
      "x": 3,
      "y": 2,
      "z": 4,
      "name": "Wood_Fig_Blue_Branch_Long"
    },
    {
      "x": 3,
      "y": 3,
      "z": 4,
      "name": "Wood_Fig_Blue_Branch_Long"
    },
    {
      "x": 3,
      "y": 4,
      "z": 4,
      "name": "Wood_Fig_Blue_Branch_Long"
    },
    {
      "x": 3,
      "y": 5,
      "z": 4,
      "name": "Wood_Fig_Blue_Branch_Long"
    },
    {
      "x": 3,
      "y": 6,
      "z": 4,
      "name": "Wood_Fig_Blue_Branch_Long"
    },
    {
      "x": 3,
      "y": 7,
      "z": 4,
      "name": "Wood_Fig_Blue_Branch_Corner",
      "rotation": 10
    },
    {
      "x": 3,
      "y": 29,
      "z": 4,
      "name": "Plant_Leaves_Fig_Blue"
    },
    {
      "x": 3,
      "y": 30,
      "z": 4,
      "name": "Plant_Leaves_Fig_Blue"
    },
    {
      "x": 3,
      "y": 31,
      "z": 4,
      "name": "Plant_Leaves_Fig_Blue"
    },
    {
      "x": 3,
      "y": 29,
      "z": 5,
      "name": "Plant_Leaves_Fig_Blue"
    },
    {
      "x": 3,
      "y": 30,
      "z": 5,
      "name": "Plant_Leaves_Fig_Blue"
    },
    {
      "x": 3,
      "y": 31,
      "z": 5,
      "name": "Plant_Leaves_Fig_Blue"
    },
    {
      "x": 3,
      "y": 32,
      "z": 5,
      "name": "Plant_Leaves_Fig_Blue"
    },
    {
      "x": 3,
      "y": 30,
      "z": 6,
      "name": "Plant_Leaves_Fig_Blue"
    },
    {
      "x": 3,
      "y": 31,
      "z": 6,
      "name": "Plant_Leaves_Fig_Blue"
    },
    {
      "x": 3,
      "y": 44,
      "z": 7,
      "name": "Plant_Leaves_Fig_Blue"
    },
    {
      "x": 3,
      "y": 44,
      "z": 8,
      "name": "Plant_Leaves_Fig_Blue"
    },
    {
      "x": 3,
      "y": 42,
      "z": 9,
      "name": "Wood_Fig_Blue_Branch_Corner",
      "rotation": 1
    },
    {
      "x": 3,
      "y": 43,
      "z": 9,
      "name": "Wood_Fig_Blue_Branch_Long"
    },
    {
      "x": 3,
      "y": 44,
      "z": 9,
      "name": "Plant_Leaves_Fig_Blue"
    },
    {
      "x": 3,
      "y": 39,
      "z": 10,
      "name": "Plant_Leaves_Fig_Blue"
    },
    {
      "x": 3,
      "y": 40,
      "z": 10,
      "name": "Plant_Leaves_Fig_Blue"
    },
    {
      "x": 3,
      "y": 42,
      "z": 10,
      "name": "Plant_Leaves_Fig_Blue"
    },
    {
      "x": 3,
      "y": 40,
      "z": 11,
      "name": "Plant_Leaves_Fig_Blue"
    },
    {
      "x": 3,
      "y": 42,
      "z": 11,
      "name": "Plant_Leaves_Fig_Blue"
    },
    {
      "x": 3,
      "y": 43,
      "z": 11,
      "name": "Plant_Leaves_Fig_Blue"
    },
    {
      "x": 4,
      "y": 37,
      "z": -9,
      "name": "Plant_Leaves_Fig_Blue"
    },
    {
      "x": 4,
      "y": 38,
      "z": -9,
      "name": "Plant_Leaves_Fig_Blue"
    },
    {
      "x": 4,
      "y": 39,
      "z": -9,
      "name": "Plant_Leaves_Fig_Blue"
    },
    {
      "x": 4,
      "y": 37,
      "z": -8,
      "name": "Plant_Leaves_Fig_Blue"
    },
    {
      "x": 4,
      "y": 38,
      "z": -8,
      "name": "Plant_Leaves_Fig_Blue"
    },
    {
      "x": 4,
      "y": 39,
      "z": -8,
      "name": "Plant_Leaves_Fig_Blue"
    },
    {
      "x": 4,
      "y": 40,
      "z": -8,
      "name": "Plant_Leaves_Fig_Blue"
    },
    {
      "x": 4,
      "y": 34,
      "z": 0,
      "name": "Wood_Fig_Blue_Trunk_Full"
    },
    {
      "x": 4,
      "y": 35,
      "z": 0,
      "name": "Wood_Fig_Blue_Trunk_Full"
    },
    {
      "x": 4,
      "y": 2,
      "z": 1,
      "name": "Wood_Fig_Blue_Trunk"
    },
    {
      "x": 4,
      "y": 3,
      "z": 1,
      "name": "Wood_Fig_Blue_Trunk"
    },
    {
      "x": 4,
      "y": 4,
      "z": 1,
      "name": "Wood_Fig_Blue_Trunk"
    },
    {
      "x": 4,
      "y": 5,
      "z": 1,
      "name": "Wood_Fig_Blue_Trunk_Full"
    },
    {
      "x": 4,
      "y": 6,
      "z": 1,
      "name": "Wood_Fig_Blue_Branch_Long"
    },
    {
      "x": 4,
      "y": 7,
      "z": 1,
      "name": "Wood_Fig_Blue_Branch_Corner",
      "rotation": 11
    },
    {
      "x": 4,
      "y": 32,
      "z": 1,
      "name": "Wood_Fig_Blue_Trunk_Full"
    },
    {
      "x": 4,
      "y": 33,
      "z": 1,
      "name": "Wood_Fig_Blue_Trunk"
    },
    {
      "x": 4,
      "y": 34,
      "z": 1,
      "name": "Wood_Fig_Blue_Trunk_Full"
    },
    {
      "x": 4,
      "y": 2,
      "z": 2,
      "name": "Wood_Fig_Blue_Trunk"
    },
    {
      "x": 4,
      "y": 3,
      "z": 2,
      "name": "Wood_Fig_Blue_Trunk"
    },
    {
      "x": 4,
      "y": 4,
      "z": 2,
      "name": "Wood_Fig_Blue_Trunk_Full"
    },
    {
      "x": 4,
      "y": 5,
      "z": 2,
      "name": "Wood_Fig_Blue_Branch_Long"
    },
    {
      "x": 4,
      "y": 6,
      "z": 2,
      "name": "Wood_Fig_Blue_Branch_Corner",
      "rotation": 11
    },
    {
      "x": 4,
      "y": 41,
      "z": 7,
      "name": "Plant_Leaves_Fig_Blue"
    },
    {
      "x": 4,
      "y": 40,
      "z": 8,
      "name": "Plant_Leaves_Fig_Blue"
    },
    {
      "x": 4,
      "y": 42,
      "z": 8,
      "name": "Plant_Leaves_Fig_Blue"
    },
    {
      "x": 4,
      "y": 39,
      "z": 9,
      "name": "Plant_Leaves_Fig_Blue"
    },
    {
      "x": 4,
      "y": 40,
      "z": 9,
      "name": "Plant_Leaves_Fig_Blue"
    },
    {
      "x": 4,
      "y": 42,
      "z": 9,
      "name": "Plant_Leaves_Fig_Blue"
    },
    {
      "x": 4,
      "y": 43,
      "z": 9,
      "name": "Plant_Leaves_Fig_Blue"
    },
    {
      "x": 4,
      "y": 42,
      "z": 10,
      "name": "Plant_Leaves_Fig_Blue"
    },
    {
      "x": 5,
      "y": 40,
      "z": -6,
      "name": "Plant_Leaves_Fig_Blue"
    },
    {
      "x": 5,
      "y": 39,
      "z": -5,
      "name": "Plant_Leaves_Fig_Blue"
    },
    {
      "x": 5,
      "y": 40,
      "z": -5,
      "name": "Plant_Leaves_Fig_Blue"
    },
    {
      "x": 5,
      "y": 39,
      "z": -4,
      "name": "Plant_Leaves_Fig_Blue"
    },
    {
      "x": 5,
      "y": 40,
      "z": -4,
      "name": "Plant_Leaves_Fig_Blue"
    },
    {
      "x": 5,
      "y": 41,
      "z": -4,
      "name": "Plant_Leaves_Fig_Blue"
    },
    {
      "x": 5,
      "y": 42,
      "z": -2,
      "name": "Plant_Leaves_Fig_Blue"
    },
    {
      "x": 5,
      "y": 42,
      "z": -1,
      "name": "Plant_Leaves_Fig_Blue"
    },
    {
      "x": 5,
      "y": 35,
      "z": 0,
      "name": "Wood_Fig_Blue_Trunk_Full"
    },
    {
      "x": 5,
      "y": 36,
      "z": 0,
      "name": "Wood_Fig_Blue_Trunk_Full"
    },
    {
      "x": 5,
      "y": 42,
      "z": 0,
      "name": "Plant_Leaves_Fig_Blue"
    },
    {
      "x": 5,
      "y": 2,
      "z": 1,
      "name": "Wood_Fig_Blue_Branch_Long"
    },
    {
      "x": 5,
      "y": 3,
      "z": 1,
      "name": "Wood_Fig_Blue_Branch_Long"
    },
    {
      "x": 5,
      "y": 4,
      "z": 1,
      "name": "Wood_Fig_Blue_Branch_Long"
    },
    {
      "x": 5,
      "y": 5,
      "z": 1,
      "name": "Wood_Fig_Blue_Branch_Corner",
      "rotation": 11
    },
    {
      "x": 5,
      "y": 2,
      "z": 2,
      "name": "Wood_Fig_Blue_Branch_Long"
    },
    {
      "x": 5,
      "y": 3,
      "z": 2,
      "name": "Wood_Fig_Blue_Branch_Long"
    },
    {
      "x": 5,
      "y": 4,
      "z": 2,
      "name": "Wood_Fig_Blue_Branch_Corner",
      "rotation": 11
    },
    {
      "x": 5,
      "y": 43,
      "z": 6,
      "name": "Plant_Leaves_Fig_Blue"
    },
    {
      "x": 5,
      "y": 42,
      "z": 7,
      "name": "Plant_Leaves_Fig_Blue"
    },
    {
      "x": 5,
