{
  "version": 8,
  "blockIdVersion": 10,
  "anchorX": 8,
  "anchorY": 6,
  "anchorZ": 6,
  "blocks": [
    {
      "x": 5,
      "y": 16,
      "z": 3,
      "name": "Plant_Coral_Block_Green"
    },
    {
      "x": 5,
      "y": 17,
      "z": 3,
      "name": "Plant_Coral_Block_Green"
    },
    {
      "x": 5,
      "y": 16,
      "z": 4,
      "name": "Plant_Coral_Block_Green"
    },
    {
      "x": 5,
      "y": 17,
      "z": 4,
      "name": "Plant_Coral_Block_Green"
    },
    {
      "x": 5,
      "y": 18,
      "z": 4,
      "name": "Plant_Coral_Block_Green"
    },
    {
      "x": 6,
      "y": 16,
      "z": 3,
      "name": "Plant_Coral_Block_Green"
    },
    {
      "x": 6,
      "y": 17,
      "z": 3,
      "name": "Plant_Coral_Block_Green"
    },
    {
      "x": 6,
      "y": 18,
      "z": 3,
      "name": "Plant_Coral_Block_Green"
    },
    {
      "x": 6,
      "y": 12,
      "z": 4,
      "name": "Wood_Petrified_Trunk_Full"
    },
    {
      "x": 6,
      "y": 13,
      "z": 4,
      "name": "Wood_Petrified_Trunk_Full"
    },
    {
      "x": 6,
      "y": 14,
      "z": 4,
      "name": "Wood_Petrified_Trunk_Full"
    },
    {
      "x": 6,
      "y": 15,
      "z": 4,
      "name": "Wood_Petrified_Trunk_Full"
    },
    {
      "x": 6,
      "y": 16,
      "z": 4,
      "name": "Wood_Petrified_Trunk_Full"
    },
    {
      "x": 6,
      "y": 17,
      "z": 4,
      "name": "Plant_Coral_Block_Green"
    },
    {
      "x": 6,
      "y": 18,
      "z": 4,
      "name": "Plant_Coral_Block_Green"
    },
    {
      "x": 6,
      "y": 9,
      "z": 5,
      "name": "Wood_Petrified_Trunk_Full"
    },
    {
      "x": 6,
      "y": 10,
      "z": 5,
      "name": "Wood_Petrified_Trunk_Full"
    },
    {
      "x": 6,
      "y": 11,
      "z": 5,
      "name": "Wood_Petrified_Trunk_Full"
    },
    {
      "x": 6,
      "y": 12,
      "z": 5,
      "name": "Wood_Petrified_Trunk_Full"
    },
    {
      "x": 6,
      "y": 13,
      "z": 5,
      "name": "Wood_Petrified_Trunk_Full"
    },
    {
      "x": 6,
      "y": 14,
      "z": 5,
      "name": "Wood_Petrified_Trunk_Full"
    },
    {
      "x": 6,
      "y": 14,
      "z": 8,
      "name": "Plant_Coral_Block_Green"
    },
    {
      "x": 6,
      "y": 15,
      "z": 8,
      "name": "Plant_Coral_Block_Green"
    },
    {
      "x": 6,
      "y": 16,
      "z": 8,
      "name": "Plant_Coral_Block_Green"
    },
    {
      "x": 6,
      "y": 14,
      "z": 9,
      "name": "Plant_Coral_Block_Green"
    },
    {
      "x": 6,
      "y": 15,
      "z": 9,
      "name": "Plant_Coral_Block_Green"
    },
    {
      "x": 7,
      "y": 5,
      "z": 5,
      "name": "Wood_Petrified_Trunk_Full"
    },
    {
      "x": 7,
      "y": 6,
      "z": 5,
      "name": "Wood_Petrified_Trunk_Full"
    },
    {
      "x": 7,
      "y": 7,
      "z": 5,
      "name": "Wood_Petrified_Trunk_Full"
    },
    {
      "x": 7,
      "y": 8,
      "z": 5,
      "name": "Wood_Petrified_Trunk_Full"
    },
    {
      "x": 7,
      "y": 9,
      "z": 5,
      "name": "Wood_Petrified_Trunk_Full"
    },
    {
      "x": 7,
      "y": 13,
      "z": 5,
      "name": "Wood_Petrified_Trunk_Full"
    },
    {
      "x": 7,
      "y": 14,
      "z": 5,
      "name": "Wood_Petrified_Trunk_Full"
    },
    {
      "x": 7,
      "y": 6,
      "z": 6,
      "name": "Wood_Petrified_Trunk_Full"
    },
    {
      "x": 7,
      "y": 7,
      "z": 6,
      "name": "Wood_Petrified_Trunk_Full"
    },
    {
      "x": 7,
      "y": 8,
      "z": 6,
      "name": "Wood_Petrified_Trunk_Full"
    },
    {
      "x": 7,
      "y": 9,
      "z": 6,
      "name": "Wood_Petrified_Trunk_Full"
    },
    {
      "x": 7,
      "y": 10,
      "z": 6,
      "name": "Wood_Petrified_Trunk_Full"
    },
    {
      "x": 7,
      "y": 11,
      "z": 6,
      "name": "Wood_Petrified_Trunk_Full"
    },
    {
      "x": 7,
      "y": 14,
      "z": 6,
      "name": "Wood_Petrified_Trunk_Full"
    },
    {
      "x": 7,
      "y": 15,
      "z": 6,
      "name": "Wood_Petrified_Trunk_Full"
    },
    {
      "x": 7,
      "y": 16,
      "z": 6,
      "name": "Wood_Petrified_Trunk_Full"
    },
    {
      "x": 7,
      "y": 17,
      "z": 6,
      "name": "Wood_Petrified_Trunk_Full"
    },
    {
      "x": 7,
      "y": 19,
      "z": 6,
      "name": "Plant_Coral_Block_Green"
    },
    {
      "x": 7,
      "y": 20,
      "z": 6,
      "name": "Plant_Coral_Block_Green"
    },
    {
      "x": 7,
      "y": 10,
      "z": 7,
      "name": "Wood_Petrified_Trunk_Full"
    },
    {
      "x": 7,
      "y": 11,
      "z": 7,
      "name": "Wood_Petrified_Trunk_Full"
    },
    {
      "x": 7,
      "y": 12,
      "z": 7,
      "name": "Wood_Petrified_Trunk_Full"
    },
    {
      "x": 7,
      "y": 19,
      "z": 7,
      "name": "Plant_Coral_Block_Green"
    },
    {
      "x": 7,
      "y": 12,
      "z": 8,
      "name": "Wood_Petrified_Trunk_Full"
    },
    {
      "x": 7,
      "y": 13,
      "z": 8,
      "name": "Wood_Petrified_Trunk_Full"
    },
    {
      "x": 7,
      "y": 14,
      "z": 8,
      "name": "Wood_Petrified_Trunk_Full"
    },
    {
      "x": 7,
      "y": 15,
      "z": 8,
      "name": "Plant_Coral_Block_Green"
    },
    {
      "x": 7,
      "y": 16,
      "z": 8,
      "name": "Plant_Coral_Block_Green"
    },
    {
      "x": 7,
      "y": 14,
      "z": 9,
      "name": "Plant_Coral_Block_Green"
    },
    {
      "x": 7,
      "y": 15,
      "z": 9,
      "name": "Plant_Coral_Block_Green"
    },
    {
      "x": 7,
      "y": 16,
      "z": 9,
      "name": "Plant_Coral_Block_Green"
    },
    {
      "x": 8,
      "y": 10,
      "z": 3,
      "name": "Wood_Petrified_Trunk_Full"
    },
    {
      "x": 8,
      "y": 11,
      "z": 3,
      "name": "Wood_Petrified_Trunk_Full"
    },
    {
      "x": 8,
      "y": 12,
      "z": 3,
      "name": "Wood_Petrified_Trunk_Full"
    },
    {
      "x": 8,
      "y": 9,
      "z": 4,
      "name": "Wood_Petrified_Trunk_Full"
    },
    {
      "x": 8,
      "y": 10,
      "z": 4,
      "name": "Wood_Petrified_Trunk_Full"
    },
    {
      "x": 8,
      "y": 11,
      "z": 4,
      "name": "Wood_Petrified_Trunk_Full"
    },
    {
      "x": 8,
      "y": 3,
      "z": 5,
      "name": "Wood_Petrified_Trunk_Full"
    },
    {
      "x": 8,
      "y": 4,
      "z": 5,
      "name": "Wood_Petrified_Trunk_Full"
    },
    {
      "x": 8,
      "y": 5,
      "z": 5,
      "name": "Wood_Petrified_Trunk_Full"
    },
    {
      "x": 8,
      "y": 6,
      "z": 5,
      "name": "Wood_Petrified_Trunk_Full"
    },
    {
      "x": 8,
      "y": 7,
      "z": 5,
      "name": "Wood_Petrified_Trunk_Full"
    },
    {
      "x": 8,
      "y": 8,
      "z": 5,
      "name": "Wood_Petrified_Trunk_Full"
    },
    {
      "x": 8,
      "y": 9,
      "z": 5,
      "name": "Wood_Petrified_Trunk_Full"
    },
    {
      "x": 8,
      "y": 18,
      "z": 5,
      "name": "Plant_Coral_Block_Green"
    },
    {
      "x": 8,
      "y": 19,
      "z": 5,
      "name": "Plant_Coral_Block_Green"
    },
    {
      "x": 8,
      "y": 20,
      "z": 5,
      "name": "Plant_Coral_Block_Green"
    },
    {
      "x": 8,
      "y": 21,
      "z": 5,
      "name": "Plant_Coral_Block_Green"
    },
    {
      "x": 8,
      "y": 5,
      "z": 6,
      "name": "Wood_Petrified_Trunk_Full"
    },
    {
      "x": 8,
      "y": 6,
      "z": 6,
      "name": "Wood_Petrified_Trunk_Full"
    },
    {
      "x": 8,
      "y": 7,
      "z": 6,
      "name": "Wood_Petrified_Trunk_Full"
    },
    {
      "x": 8,
      "y": 8,
      "z": 6,
      "name": "Wood_Petrified_Trunk_Full"
    },
    {
      "x": 8,
      "y": 9,
      "z": 6,
      "name": "Wood_Petrified_Trunk_Full"
    },
    {
      "x": 8,
      "y": 10,
      "z": 6,
      "name": "Wood_Petrified_Trunk_Full"
    },
    {
      "x": 8,
      "y": 17,
      "z": 6,
      "name": "Wood_Petrified_Trunk_Full"
    },
    {
      "x": 8,
      "y": 18,
      "z": 6,
      "name": "Wood_Petrified_Trunk_Full"
    },
    {
      "x": 8,
      "y": 19,
      "z": 6,
      "name": "Wood_Petrified_Trunk_Full"
    },
    {
      "x": 8,
      "y": 20,
      "z": 6,
      "name": "Plant_Coral_Block_Green"
    },
    {
      "x": 8,
      "y": 21,
      "z": 6,
      "name": "Plant_Coral_Block_Green"
    },
    {
      "x": 8,
      "y": 19,
      "z": 7,
      "name": "Plant_Coral_Block_Green"
    },
    {
      "x": 8,
      "y": 20,
      "z": 7,
      "name": "Plant_Coral_Block_Green"
    },
    {
      "x": 8,
      "y": 21,
      "z": 7,
      "name": "Plant_Coral_Block_Green"
    },
    {
      "x": 9,
      "y": 14,
      "z": 2,
      "name": "Plant_Coral_Block_Green"
    },
    {
      "x": 9,
      "y": 15,
      "z": 2,
      "name": "Plant_Coral_Block_Green"
    },
    {
      "x": 9,
      "y": 16,
      "z": 2,
      "name": "Plant_Coral_Block_Green"
    },
    {
      "x": 9,
      "y": 12,
      "z": 3,
      "name": "Wood_Petrified_Trunk_Full"
    },
    {
      "x": 9,
      "y": 13,
      "z": 3,
      "name": "Wood_Petrified_Trunk_Full"
    },
    {
      "x": 9,
      "y": 14,
      "z": 3,
      "name": "Wood_Petrified_Trunk_Full"
    },
    {
      "x": 9,
      "y": 15,
      "z": 3,
      "name": "Wood_Petrified_Trunk_Full"
    },
    {
      "x": 9,
      "y": 16,
      "z": 3,
      "name": "Plant_Coral_Block_Green"
    },
    {
      "x": 9,
      "y": 18,
      "z": 5,
      "name": "Plant_Coral_Block_Green"
    },
    {
      "x": 9,
      "y": 19,
      "z": 5,
      "name": "Plant_Coral_Block_Green"
    },
    {
      "x": 9,
      "y": 20,
      "z": 5,
      "name": "Plant_Coral_Block_Green"
    },
    {
      "x": 9,
      "y": 4,
      "z": 6,
      "name": "Wood_Petrified_Trunk_Full"
    },
    {
      "x": 9,
      "y": 5,
      "z": 6,
      "name": "Wood_Petrified_Trunk_Full"
    },
    {
      "x": 9,
      "y": 6,
      "z": 6,
      "name": "Wood_Petrified_Trunk_Full"
    },
    {
      "x": 9,
      "y": 7,
      "z": 6,
      "name": "Wood_Petrified_Trunk_Full"
    },
    {
      "x": 9,
      "y": 10,
      "z": 6,
      "name": "Wood_Petrified_Trunk_Full"
    },
    {
      "x": 9,
      "y": 11,
      "z": 6,
      "name": "Wood_Petrified_Trunk_Full"
    },
    {
      "x": 9,
      "y": 12,
      "z": 6,
      "name": "Wood_Petrified_Trunk_Full"
    },
    {
      "x": 9,
      "y": 13,
      "z": 6,
      "name": "Plant_Coral_Block_Green"
    },
    {
      "x": 9,
      "y": 14,
      "z": 6,
      "name": "Plant_Coral_Block_Green"
    },
    {
      "x": 9,
      "y": 18,
      "z": 6,
      "name": "Plant_Coral_Block_Green"
    },
    {
      "x": 9,
      "y": 19,
      "z": 6,
      "name": "Plant_Coral_Block_Green"
    },
    {
      "x": 9,
      "y": 20,
      "z": 6,
      "name": "Plant_Coral_Block_Green"
    },
    {
      "x": 9,
      "y": 21,
      "z": 6,
      "name": "Plant_Coral_Block_Green"
    },
    {
      "x": 9,
      "y": 12,
      "z": 7,
      "name": "Plant_Coral_Block_Green"
    },
    {
      "x": 9,
      "y": 13,
      "z": 7,
      "name": "Plant_Coral_Block_Green"
    },
    {
      "x": 9,
      "y": 14,
      "z": 7,
      "name": "Plant_Coral_Block_Green"
    },
    {
      "x": 9,
      "y": 19,
      "z": 7,
      "name": "Plant_Coral_Block_Green"
    },
    {
      "x": 9,
      "y": 20,
      "z": 7,
      "name": "Plant_Coral_Block_Green"
    },
    {
      "x": 10,
      "y": 14,
      "z": 2,
      "name": "Plant_Coral_Block_Green"
    },
    {
      "x": 10,
      "y": 15,
      "z": 2,
      "name": "Plant_Coral_Block_Green"
    },
    {
      "x": 10,
      "y": 14,
      "z": 3,
      "name": "Plant_Coral_Block_Green"
    },
    {
      "x": 10,
      "y": 15,
      "z": 3,
      "name": "Plant_Coral_Block_Green"
    },
    {
      "x": 10,
      "y": 16,
      "z": 3,
      "name": "Plant_Coral_Block_Green"
    },
    {
      "x": 10,
      "y": 12,
      "z": 6,
      "name": "Plant_Coral_Block_Green"
    },
    {
      "x": 10,
      "y": 13,
      "z": 6,
      "name": "Plant_Coral_Block_Green"
    },
    {
      "x": 10,
      "y": 14,
      "z": 6,
      "name": "Plant_Coral_Block_Green"
    },
    {
      "x": 10,
      "y": 12,
      "z": 7,
      "name": "Plant_Coral_Block_Green"
    },
    {
      "x": 10,
      "y": 13,
      "z": 7,
      "name": "Plant_Coral_Block_Green"
    }
  ]
}