{
  "version": 8,
  "blockIdVersion": 10,
  "anchorX": -3,
  "anchorY": 12,
  "anchorZ": -1,
  "blocks": [
    {
      "x": -16,
      "y": 28,
      "z": -2,
      "name": "Plant_Leaves_Jungle"
    },
    {
      "x": -16,
      "y": 27,
      "z": -1,
      "name": "Plant_Leaves_Jungle"
    },
    {
      "x": -16,
      "y": 28,
      "z": -1,
      "name": "Plant_Leaves_Jungle"
    },
    {
      "x": -16,
      "y": 28,
      "z": 0,
      "name": "Plant_Leaves_Jungle"
    },
    {
      "x": -16,
      "y": 28,
      "z": 1,
      "name": "Plant_Leaves_Jungle"
    },
    {
      "x": -15,
      "y": 28,
      "z": -3,
      "name": "Plant_Leaves_Jungle"
    },
    {
      "x": -15,
      "y": 28,
      "z": -2,
      "name": "Plant_Leaves_Jungle"
    },
    {
      "x": -15,
      "y": 29,
      "z": -2,
      "name": "Plant_Leaves_Jungle"
    },
    {
      "x": -15,
      "y": 26,
      "z": -1,
      "name": "Plant_Leaves_Jungle"
    },
    {
      "x": -15,
      "y": 27,
      "z": -1,
      "name": "Plant_Leaves_Jungle"
    },
    {
      "x": -15,
      "y": 28,
      "z": -1,
      "name": "Plant_Leaves_Jungle"
    },
    {
      "x": -15,
      "y": 25,
      "z": 0,
      "name": "Plant_Leaves_Jungle"
    },
    {
      "x": -15,
      "y": 26,
      "z": 0,
      "name": "Plant_Leaves_Jungle"
    },
    {
      "x": -15,
      "y": 27,
      "z": 0,
      "name": "Plant_Leaves_Jungle"
    },
    {
      "x": -15,
      "y": 28,
      "z": 0,
      "name": "Plant_Leaves_Jungle"
    },
    {
      "x": -15,
      "y": 29,
      "z": 0,
      "name": "Plant_Leaves_Jungle"
    },
    {
      "x": -15,
      "y": 26,
      "z": 1,
      "name": "Plant_Leaves_Jungle"
    },
    {
      "x": -15,
      "y": 27,
      "z": 1,
      "name": "Plant_Leaves_Jungle"
    },
    {
      "x": -15,
      "y": 28,
      "z": 1,
      "name": "Plant_Leaves_Jungle"
    },
    {
      "x": -15,
      "y": 28,
      "z": 2,
      "name": "Plant_Leaves_Jungle"
    },
    {
      "x": -15,
      "y": 27,
      "z": 3,
      "name": "Plant_Leaves_Jungle"
    },
    {
      "x": -15,
      "y": 28,
      "z": 3,
      "name": "Plant_Leaves_Jungle"
    },
    {
      "x": -14,
      "y": 27,
      "z": -4,
      "name": "Plant_Leaves_Jungle"
    },
    {
      "x": -14,
      "y": 28,
      "z": -4,
      "name": "Plant_Leaves_Jungle"
    },
    {
      "x": -14,
      "y": 25,
      "z": -3,
      "name": "Plant_Leaves_Jungle"
    },
    {
      "x": -14,
      "y": 26,
      "z": -3,
      "name": "Plant_Leaves_Jungle"
    },
    {
      "x": -14,
      "y": 27,
      "z": -3,
      "name": "Plant_Leaves_Jungle"
    },
    {
      "x": -14,
      "y": 28,
      "z": -3,
      "name": "Plant_Leaves_Jungle"
    },
    {
      "x": -14,
      "y": 29,
      "z": -3,
      "name": "Plant_Leaves_Jungle"
    },
    {
      "x": -14,
      "y": 30,
      "z": -1,
      "name": "Plant_Leaves_Jungle"
    },
    {
      "x": -14,
      "y": 27,
      "z": 0,
      "name": "Wood_Jungle_Branch_Corner",
      "rotation": 3
    },
    {
      "x": -14,
      "y": 28,
      "z": 0,
      "name": "Wood_Jungle_Branch_Long"
    },
    {
      "x": -14,
      "y": 29,
      "z": 0,
      "name": "Plant_Leaves_Jungle"
    },
    {
      "x": -14,
      "y": 30,
      "z": 0,
      "name": "Plant_Leaves_Jungle"
    },
    {
      "x": -14,
      "y": 30,
      "z": 1,
      "name": "Plant_Leaves_Jungle"
    },
    {
      "x": -14,
      "y": 27,
      "z": 2,
      "name": "Plant_Leaves_Jungle"
    },
    {
      "x": -14,
      "y": 28,
      "z": 2,
      "name": "Plant_Leaves_Jungle"
    },
    {
      "x": -14,
      "y": 29,
      "z": 2,
      "name": "Plant_Leaves_Jungle"
    },
    {
      "x": -14,
      "y": 26,
      "z": 3,
      "name": "Plant_Leaves_Jungle"
    },
    {
      "x": -14,
      "y": 27,
      "z": 3,
      "name": "Plant_Leaves_Jungle"
    },
    {
      "x": -14,
      "y": 28,
      "z": 3,
      "name": "Plant_Leaves_Jungle"
    },
    {
      "x": -14,
      "y": 27,
      "z": 4,
      "name": "Plant_Leaves_Jungle"
    },
    {
      "x": -13,
      "y": 26,
      "z": -5,
      "name": "Plant_Leaves_Jungle"
    },
    {
      "x": -13,
      "y": 27,
      "z": -5,
      "name": "Plant_Leaves_Jungle"
    },
    {
      "x": -13,
      "y": 28,
      "z": -5,
      "name": "Plant_Leaves_Jungle"
    },
    {
      "x": -13,
      "y": 26,
      "z": -4,
      "name": "Plant_Leaves_Jungle"
    },
    {
      "x": -13,
      "y": 27,
      "z": -4,
      "name": "Plant_Leaves_Jungle"
    },
    {
      "x": -13,
      "y": 27,
      "z": -3,
      "name": "Plant_Leaves_Jungle"
    },
    {
      "x": -13,
      "y": 30,
      "z": -3,
      "name": "Plant_Leaves_Jungle"
    },
    {
      "x": -13,
      "y": 27,
      "z": 0,
      "name": "Wood_Jungle_Branch_Long",
      "rotation": 5
    },
    {
      "x": -13,
      "y": 30,
      "z": 0,
      "name": "Plant_Leaves_Jungle"
    },
    {
      "x": -13,
      "y": 30,
      "z": 1,
      "name": "Plant_Leaves_Jungle"
    },
    {
      "x": -13,
      "y": 28,
      "z": 2,
      "name": "Plant_Leaves_Jungle"
    },
    {
      "x": -13,
      "y": 29,
      "z": 3,
      "name": "Plant_Leaves_Jungle"
    },
    {
      "x": -13,
      "y": 25,
      "z": 4,
      "name": "Plant_Leaves_Jungle"
    },
    {
      "x": -13,
      "y": 26,
      "z": 4,
      "name": "Plant_Leaves_Jungle"
    },
    {
      "x": -13,
      "y": 27,
      "z": 4,
      "name": "Plant_Leaves_Jungle"
    },
    {
      "x": -13,
      "y": 28,
      "z": 4,
      "name": "Plant_Leaves_Jungle"
    },
    {
      "x": -12,
      "y": 24,
      "z": -5,
      "name": "Plant_Leaves_Jungle"
    },
    {
      "x": -12,
      "y": 25,
      "z": -5,
      "name": "Plant_Leaves_Jungle"
    },
    {
      "x": -12,
      "y": 27,
      "z": -5,
      "name": "Plant_Leaves_Jungle"
    },
    {
      "x": -12,
      "y": 25,
      "z": -4,
      "name": "Plant_Leaves_Jungle"
    },
    {
      "x": -12,
      "y": 27,
      "z": -4,
      "name": "Plant_Leaves_Jungle"
    },
    {
      "x": -12,
      "y": 28,
      "z": -4,
      "name": "Plant_Leaves_Jungle"
    },
    {
      "x": -12,
      "y": 29,
      "z": -4,
      "name": "Plant_Leaves_Jungle"
    },
    {
      "x": -12,
      "y": 27,
      "z": -3,
      "name": "Wood_Jungle_Branch_Long",
      "rotation": 4
    },
    {
      "x": -12,
      "y": 28,
      "z": -3,
      "name": "Plant_Leaves_Jungle"
    },
    {
      "x": -12,
      "y": 29,
      "z": -3,
      "name": "Plant_Leaves_Jungle"
    },
    {
      "x": -12,
      "y": 30,
      "z": -3,
      "name": "Plant_Leaves_Jungle"
    },
    {
      "x": -12,
      "y": 27,
      "z": -2,
      "name": "Wood_Jungle_Branch_Long",
      "rotation": 4
    },
    {
      "x": -12,
      "y": 30,
      "z": -2,
      "name": "Plant_Leaves_Jungle"
    },
    {
      "x": -12,
      "y": 27,
      "z": -1,
      "name": "Wood_Jungle_Branch_Long",
      "rotation": 4
    },
    {
      "x": -12,
      "y": 30,
      "z": -1,
      "name": "Plant_Leaves_Jungle"
    },
    {
      "x": -12,
      "y": 27,
      "z": 0,
      "name": "Wood_Jungle_Trunk_Full"
    },
    {
      "x": -12,
      "y": 30,
      "z": 0,
      "name": "Plant_Leaves_Jungle"
    },
    {
      "x": -12,
      "y": 29,
      "z": 2,
      "name": "Plant_Leaves_Jungle"
    },
    {
      "x": -12,
      "y": 30,
      "z": 2,
      "name": "Plant_Leaves_Jungle"
    },
    {
      "x": -12,
      "y": 28,
      "z": 3,
      "name": "Plant_Leaves_Jungle"
    },
    {
      "x": -12,
      "y": 29,
      "z": 3,
      "name": "Plant_Leaves_Jungle"
    },
    {
      "x": -12,
      "y": 25,
      "z": 4,
      "name": "Plant_Leaves_Jungle"
    },
    {
      "x": -12,
      "y": 26,
      "z": 4,
      "name": "Plant_Leaves_Jungle"
    },
    {
      "x": -12,
      "y": 27,
      "z": 4,
      "name": "Plant_Leaves_Jungle"
    },
    {
      "x": -12,
      "y": 28,
      "z": 4,
      "name": "Plant_Leaves_Jungle"
    },
    {
      "x": -12,
      "y": 29,
      "z": 4,
      "name": "Plant_Leaves_Jungle"
    },
    {
      "x": -12,
      "y": 27,
      "z": 5,
      "name": "Plant_Leaves_Jungle"
    },
    {
      "x": -12,
      "y": 28,
      "z": 5,
      "name": "Plant_Leaves_Jungle"
    },
    {
      "x": -11,
      "y": 25,
      "z": -5,
      "name": "Plant_Leaves_Jungle"
    },
    {
      "x": -11,
      "y": 26,
      "z": -5,
      "name": "Plant_Leaves_Jungle"
    },
    {
      "x": -11,
      "y": 27,
      "z": -5,
      "name": "Plant_Leaves_Jungle"
    },
    {
      "x": -11,
      "y": 28,
      "z": -5,
      "name": "Plant_Leaves_Jungle"
    },
    {
      "x": -11,
      "y": 29,
      "z": -5,
      "name": "Plant_Leaves_Jungle"
    },
    {
      "x": -11,
      "y": 25,
      "z": -4,
      "name": "Plant_Leaves_Jungle"
    },
    {
      "x": -11,
      "y": 27,
      "z": -4,
      "name": "Plant_Leaves_Jungle"
    },
    {
      "x": -11,
      "y": 30,
      "z": -3,
      "name": "Plant_Leaves_Jungle"
    },
    {
      "x": -11,
      "y": 30,
      "z": -2,
      "name": "Plant_Leaves_Jungle"
    },
    {
      "x": -11,
      "y": 27,
      "z": 0,
      "name": "Wood_Jungle_Trunk_Full"
    },
    {
      "x": -11,
      "y": 28,
      "z": 0,
      "name": "Wood_Jungle_Branch_Long"
    },
    {
      "x": -11,
      "y": 29,
      "z": 0,
      "name": "Wood_Jungle_Branch_Long"
    },
    {
      "x": -11,
      "y": 30,
      "z": 0,
      "name": "Plant_Leaves_Jungle"
    },
    {
      "x": -11,
      "y": 27,
      "z": 1,
      "name": "Wood_Jungle_Branch_Long",
      "rotation": 4
    },
    {
      "x": -11,
      "y": 27,
      "z": 2,
      "name": "Wood_Jungle_Branch_Long",
      "rotation": 4
    },
    {
      "x": -11,
      "y": 27,
      "z": 3,
      "name": "Wood_Jungle_Branch_Corner"
    },
    {
      "x": -11,
      "y": 28,
      "z": 3,
      "name": "Plant_Leaves_Jungle"
    },
    {
      "x": -11,
      "y": 29,
      "z": 3,
      "name": "Plant_Leaves_Jungle"
    },
    {
      "x": -11,
      "y": 25,
      "z": 4,
      "name": "Plant_Leaves_Jungle"
    },
    {
      "x": -11,
      "y": 27,
      "z": 4,
      "name": "Plant_Leaves_Jungle"
    },
    {
      "x": -11,
      "y": 28,
      "z": 4,
      "name": "Plant_Leaves_Jungle"
    },
    {
      "x": -11,
      "y": 24,
      "z": 5,
      "name": "Plant_Leaves_Jungle"
    },
    {
      "x": -11,
      "y": 25,
      "z": 5,
      "name": "Plant_Leaves_Jungle"
    },
    {
      "x": -11,
      "y": 26,
      "z": 5,
      "name": "Plant_Leaves_Jungle"
    },
    {
      "x": -11,
      "y": 27,
      "z": 5,
      "name": "Plant_Leaves_Jungle"
    },
    {
      "x": -10,
      "y": 22,
      "z": -10,
      "name": "Plant_Leaves_Jungle"
    },
    {
      "x": -10,
      "y": 23,
      "z": -10,
      "name": "Plant_Leaves_Jungle"
    },
    {
      "x": -10,
      "y": 24,
      "z": -10,
      "name": "Plant_Leaves_Jungle"
    },
    {
      "x": -10,
      "y": 25,
      "z": -10,
      "name": "Plant_Leaves_Jungle"
    },
    {
      "x": -10,
      "y": 26,
      "z": -10,
      "name": "Plant_Leaves_Jungle"
    },
    {
      "x": -10,
      "y": 24,
      "z": -9,
      "name": "Plant_Leaves_Jungle"
    },
    {
      "x": -10,
      "y": 27,
      "z": -9,
      "name": "Plant_Leaves_Jungle"
    },
    {
      "x": -10,
      "y": 25,
      "z": -8,
      "name": "Plant_Leaves_Jungle"
    },
    {
      "x": -10,
      "y": 26,
      "z": -8,
      "name": "Plant_Leaves_Jungle"
    },
    {
      "x": -10,
      "y": 27,
      "z": -8,
      "name": "Plant_Leaves_Jungle"
    },
    {
      "x": -10,
      "y": 28,
      "z": -8,
      "name": "Plant_Leaves_Jungle"
    },
    {
      "x": -10,
      "y": 26,
      "z": -7,
      "name": "Plant_Leaves_Jungle"
    },
    {
      "x": -10,
      "y": 27,
      "z": -7,
      "name": "Plant_Leaves_Jungle"
    },
    {
      "x": -10,
      "y": 28,
      "z": -7,
      "name": "Plant_Leaves_Jungle"
    },
    {
      "x": -10,
      "y": 28,
      "z": -6,
      "name": "Plant_Leaves_Jungle"
    },
    {
      "x": -10,
      "y": 30,
      "z": -3,
      "name": "Plant_Leaves_Jungle"
    },
    {
      "x": -10,
      "y": 29,
      "z": -1,
      "name": "Plant_Leaves_Jungle"
    },
    {
      "x": -10,
      "y": 30,
      "z": -1,
      "name": "Plant_Leaves_Jungle"
    },
    {
      "x": -10,
      "y": 26,
      "z": 0,
      "name": "Wood_Jungle_Trunk_Full"
    },
    {
      "x": -10,
      "y": 27,
      "z": 0,
      "name": "Wood_Jungle_Trunk_Full"
    },
    {
      "x": -10,
      "y": 30,
      "z": 0,
      "name": "Plant_Leaves_Jungle"
    },
    {
      "x": -10,
      "y": 30,
      "z": 1,
      "name": "Plant_Leaves_Jungle"
    },
    {
      "x": -10,
      "y": 29,
      "z": 2,
      "name": "Plant_Leaves_Jungle"
    },
    {
      "x": -10,
      "y": 30,
      "z": 2,
      "name": "Plant_Leaves_Jungle"
    },
    {
      "x": -10,
      "y": 28,
      "z": 3,
      "name": "Plant_Leaves_Jungle"
    },
    {
      "x": -10,
      "y": 29,
      "z": 3,
      "name": "Plant_Leaves_Jungle"
    },
    {
      "x": -10,
      "y": 27,
      "z": 4,
      "name": "Plant_Leaves_Jungle"
    },
    {
      "x": -10,
      "y": 28,
      "z": 4,
      "name": "Plant_Leaves_Jungle"
    },
    {
      "x": -10,
      "y": 29,
      "z": 4,
      "name": "Plant_Leaves_Jungle"
    },
    {
      "x": -10,
      "y": 24,
      "z": 5,
      "name": "Plant_Leaves_Jungle"
    },
    {
      "x": -10,
      "y": 25,
      "z": 5,
      "name": "Plant_Leaves_Jungle"
    },
    {
      "x": -10,
      "y": 26,
      "z": 5,
      "name": "Plant_Leaves_Jungle"
    },
    {
      "x": -10,
      "y": 27,
      "z": 5,
      "name": "Plant_Leaves_Jungle"
    },
    {
      "x": -9,
      "y": 24,
      "z": -11,
      "name": "Plant_Leaves_Jungle"
    },
    {
      "x": -9,
      "y": 25,
      "z": -11,
      "name": "Plant_Leaves_Jungle"
    },
    {
      "x": -9,
      "y": 26,
      "z": -11,
      "name": "Plant_Leaves_Jungle"
    },
    {
      "x": -9,
      "y": 27,
      "z": -11,
      "name": "Plant_Leaves_Jungle"
    },
    {
      "x": -9,
      "y": 24,
      "z": -10,
      "name": "Plant_Leaves_Jungle"
    },
    {
      "x": -9,
      "y": 25,
      "z": -10,
      "name": "Plant_Leaves_Jungle"
    },
    {
      "x": -9,
      "y": 26,
      "z": -10,
      "name": "Plant_Leaves_Jungle"
    },
    {
      "x": -9,
      "y": 27,
      "z": -10,
      "name": "Plant_Leaves_Jungle"
    },
    {
      "x": -9,
      "y": 28,
      "z": -10,
      "name": "Plant_Leaves_Jungle"
    },
    {
      "x": -9,
      "y": 27,
      "z": -9,
      "name": "Plant_Leaves_Jungle"
    },
    {
      "x": -9,
      "y": 28,
      "z": -9,
      "name": "Plant_Leaves_Jungle"
    },
    {
      "x": -9,
      "y": 29,
      "z": -9,
      "name": "Plant_Leaves_Jungle"
    },
    {
      "x": -9,
      "y": 28,
      "z": -8,
      "name": "Plant_Leaves_Jungle"
    },
    {
      "x": -9,
      "y": 29,
      "z": -8,
      "name": "Plant_Leaves_Jungle"
    },
    {
      "x": -9,
      "y": 28,
      "z": -7,
      "name": "Plant_Leaves_Jungle"
    },
    {
      "x": -9,
      "y": 28,
      "z": -6,
      "name": "Plant_Leaves_Jungle"
    },
    {
      "x": -9,
      "y": 29,
      "z": -6,
      "name": "Plant_Leaves_Jungle"
    },
    {
      "x": -9,
      "y": 25,
      "z": 0,
      "name": "Wood_Jungle_Roots"
    },
    {
      "x": -9,
      "y": 26,
      "z": 0,
      "name": "Wood_Jungle_Trunk_Full"
    },
    {
      "x": -9,
      "y": 30,
      "z": 1,
      "name": "Plant_Leaves_Jungle"
    },
    {
      "x": -9,
      "y": 29,
      "z": 2,
      "name": "Plant_Leaves_Jungle"
    },
    {
      "x": -9,
      "y": 31,
      "z": 2,
      "name": "Plant_Leaves_Jungle"
    },
    {
      "x": -9,
      "y": 32,
      "z": 2,
      "name": "Plant_Leaves_Jungle"
    },
    {
      "x": -9,
      "y": 33,
      "z": 2,
      "name": "Plant_Leaves_Jungle"
    },
    {
      "x": -9,
      "y": 27,
      "z": 3,
      "name": "Plant_Leaves_Jungle"
    },
    {
      "x": -9,
      "y": 28,
      "z": 3,
      "name": "Plant_Leaves_Jungle"
    },
    {
      "x": -9,
      "y": 33,
      "z": 3,
      "name": "Plant_Leaves_Jungle"
    },
    {
      "x": -9,
      "y": 27,
      "z": 4,
      "name": "Plant_Leaves_Jungle"
    },
    {
      "x": -9,
      "y": 33,
      "z": 4,
      "name": "Plant_Leaves_Jungle"
    },
    {
      "x": -9,
      "y": 26,
      "z": 5,
      "name": "Plant_Leaves_Jungle"
    },
    {
      "x": -9,
      "y": 27,
      "z": 5,
      "name": "Plant_Leaves_Jungle"
    },
    {
      "x": -8,
      "y": 25,
      "z": -12,
      "name": "Plant_Leaves_Jungle"
    },
    {
      "x": -8,
      "y": 25,
      "z": -11,
      "name": "Plant_Leaves_Jungle"
    },
    {
      "x": -8,
      "y": 26,
      "z": -11,
      "name": "Plant_Leaves_Jungle"
    },
    {
      "x": -8,
      "y": 27,
      "z": -11,
      "name": "Plant_Leaves_Jungle"
    },
    {
      "x": -8,
      "y": 28,
      "z": -11,
      "name": "Plant_Leaves_Jungle"
    },
    {
      "x": -8,
      "y": 28,
      "z": -10,
      "name": "Plant_Leaves_Jungle"
    },
    {
      "x": -8,
      "y": 29,
      "z": -10,
      "name": "Plant_Leaves_Jungle"
    },
    {
      "x": -8,
      "y": 29,
      "z": -9,
      "name": "Plant_Leaves_Jungle"
    },
    {
      "x": -8,
      "y": 26,
      "z": -8,
      "name": "Wood_Jungle_Branch_Corner",
      "rotation": 3
    },
    {
      "x": -8,
      "y": 27,
      "z": -8,
      "name": "Wood_Jungle_Branch_Long"
    },
    {
      "x": -8,
      "y": 28,
      "z": -8,
      "name": "Wood_Jungle_Branch_Long"
    },
    {
      "x": -8,
      "y": 29,
      "z": -8,
      "name": "Plant_Leaves_Jungle"
    },
    {
      "x": -8,
      "y": 30,
      "z": -8,
      "name": "Plant_Leaves_Jungle"
    },
    {
      "x": -8,
      "y": 25,
      "z": -1,
      "name": "Wood_Jungle_Trunk_Full"
    },
    {
      "x": -8,
      "y": 26,
      "z": -1,
      "name": "Wood_Jungle_Trunk_Full"
    },
    {
      "x": -8,
      "y": 26,
      "z": 0,
      "name": "Wood_Jungle_Trunk_Full"
    },
    {
      "x": -8,
      "y": 33,
      "z": 0,
      "name": "Plant_Leaves_Jungle"
    },
    {
      "x": -8,
      "y": 30,
      "z": 1,
      "name": "Plant_Leaves_Jungle"
    },
    {
      "x": -8,
      "y": 33,
      "z": 1,
      "name": "Plant_Leaves_Jungle"
    },
    {
      "x": -8,
      "y": 34,
      "z": 1,
      "name": "Plant_Leaves_Jungle"
    },
    {
      "x": -8,
      "y": 30,
      "z": 2,
      "name": "Plant_Leaves_Jungle"
    },
    {
      "x": -8,
      "y": 32,
      "z": 2,
      "name": "Plant_Leaves_Jungle"
    },
    {
      "x": -8,
      "y": 33,
      "z": 2,
      "name": "Plant_Leaves_Jungle"
    },
    {
      "x": -8,
      "y": 34,
      "z": 2,
      "name": "Plant_Leaves_Jungle"
    },
    {
      "x": -8,
      "y": 35,
      "z": 2,
      "name": "Plant_Leaves_Jungle"
    },
    {
      "x": -8,
      "y": 27,
      "z": 3,
      "name": "Plant_Leaves_Jungle"
    },
    {
      "x": -8,
      "y": 34,
      "z": 3,
      "name": "Plant_Leaves_Jungle"
    },
    {
      "x": -8,
      "y": 34,
      "z": 4,
      "name": "Plant_Leaves_Jungle"
    },
    {
      "x": -8,
      "y": 35,
      "z": 4,
      "name": "Plant_Leaves_Jungle"
    },
    {
      "x": -8,
      "y": 32,
      "z": 5,
      "name": "Plant_Leaves_Jungle"
    },
    {
      "x": -8,
      "y": 22,
      "z": 7,
      "name": "Plant_Leaves_Jungle"
    },
    {
      "x": -8,
      "y": 23,
      "z": 7,
      "name": "Plant_Leaves_Jungle"
    },
    {
      "x": -8,
      "y": 24,
      "z": 7,
      "name": "Plant_Leaves_Jungle"
    },
    {
      "x": -8,
      "y": 21,
      "z": 8,
      "name": "Plant_Leaves_Jungle"
    },
    {
      "x": -8,
      "y": 22,
      "z": 8,
      "name": "Plant_Leaves_Jungle"
    },
    {
      "x": -8,
      "y": 23,
      "z": 8,
      "name": "Plant_Leaves_Jungle"
    },
    {
      "x": -8,
      "y": 24,
      "z": 8,
      "name": "Plant_Leaves_Jungle"
    },
    {
      "x": -8,
      "y": 22,
      "z": 9,
      "name": "Plant_Leaves_Jungle"
    },
    {
      "x": -8,
      "y": 23,
      "z": 9,
      "name": "Plant_Leaves_Jungle"
    },
    {
      "x": -7,
      "y": 25,
      "z": -12,
      "name": "Plant_Leaves_Jungle"
    },
    {
      "x": -7,
      "y": 26,
      "z": -12,
      "name": "Plant_Leaves_Jungle"
    },
    {
      "x": -7,
      "y": 27,
      "z": -12,
      "name": "Plant_Leaves_Jungle"
    },
    {
      "x": -7,
      "y": 27,
      "z": -11,
      "name": "Plant_Leaves_Jungle"
    },
    {
      "x": -7,
      "y": 28,
      "z": -11,
      "name": "Plant_Leaves_Jungle"
    },
    {
      "x": -7,
      "y": 26,
      "z": -10,
      "name": "Wood_Jungle_Branch_Corner",
      "rotation": 2
    },
    {
      "x": -7,
      "y": 27,
      "z": -10,
      "name": "Wood_Jungle_Branch_Long"
    },
    {
      "x": -7,
      "y": 28,
      "z": -10,
      "name": "Wood_Jungle_Branch_Long"
    },
    {
      "x": -7,
      "y": 29,
      "z": -10,
      "name": "Plant_Leaves_Jungle"
    },
    {
      "x": -7,
      "y": 26,
      "z": -9,
      "name": "Wood_Jungle_Branch_Long",
      "rotation": 4
    },
    {
      "x": -7,
      "y": 29,
      "z": -9,
      "name": "Plant_Leaves_Jungle"
    },
    {
      "x": -7,
      "y": 30,
      "z": -9,
      "name": "Plant_Leaves_Jungle"
    },
    {
      "x": -7,
      "y": 26,
      "z": -8,
      "name": "Wood_Jungle_Trunk_Full"
    },
    {
      "x": -7,
      "y": 29,
      "z": -8,
      "name": "Plant_Leaves_Jungle"
    },
    {
      "x": -7,
      "y": 30,
      "z": -8,
      "name": "Plant_Leaves_Jungle"
    },
    {
      "x": -7,
      "y": 26,
      "z": -7,
      "name": "Wood_Jungle_Trunk_Full"
    },
    {
      "x": -7,
      "y": 30,
      "z": -7,
      "name": "Plant_Leaves_Jungle"
    },
    {
      "x": -7,
      "y": 30,
      "z": -6,
      "name": "Plant_Leaves_Jungle"
    },
    {
      "x": -7,
      "y": 25,
      "z": -1,
      "name": "Wood_Jungle_Trunk_Full"
    },
    {
      "x": -7,
      "y": 32,
      "z": -1,
      "name": "Plant_Leaves_Jungle"
    },
    {
      "x": -7,
      "y": 33,
      "z": -1,
      "name": "Plant_Leaves_Jungle"
    },
    {
      "x": -7,
      "y": 34,
      "z": 0,
      "name": "Plant_Leaves_Jungle"
    },
    {
      "x": -7,
      "y": 35,
      "z": 0,
      "name": "Plant_Leaves_Jungle"
    },
    {
      "x": -7,
      "y": 35,
      "z": 1,
      "name": "Plant_Leaves_Jungle"
    },
    {
      "x": -7,
      "y": 29,
      "z": 2,
      "name": "Plant_Leaves_Jungle"
    },
    {
      "x": -7,
      "y": 30,
      "z": 2,
      "name": "Plant_Leaves_Jungle"
    },
    {
      "x": -7,
      "y": 32,
      "z": 2,
      "name": "Wood_Jungle_Branch_Long",
      "rotation": 5
    },
    {
      "x": -7,
      "y": 34,
      "z": 2,
      "name": "Plant_Leaves_Jungle"
    },
    {
      "x": -7,
      "y": 35,
      "z": 2,
      "name": "Plant_Leaves_Jungle"
    },
    {
      "x": -7,
      "y": 36,
      "z": 2,
      "name": "Plant_Leaves_Jungle"
    },
    {
      "x": -7,
      "y": 35,
      "z": 3,
      "name": "Plant_Leaves_Jungle"
    },
    {
      "x": -7,
      "y": 35,
      "z": 4,
      "name": "Plant_Leaves_Jungle"
    },
    {
      "x": -7,
      "y": 32,
      "z": 5,
      "name": "Plant_Leaves_Jungle"
    },
    {
      "x": -7,
      "y": 33,
      "z": 5,
      "name": "Plant_Leaves_Jungle"
    },
    {
      "x": -7,
      "y": 34,
      "z": 5,
      "name": "Plant_Leaves_Jungle"
    },
    {
      "x": -7,
      "y": 32,
      "z": 6,
      "name": "Plant_Leaves_Jungle"
    },
    {
      "x": -7,
      "y": 33,
      "z": 6,
      "name": "Plant_Leaves_Jungle"
    },
    {
      "x": -7,
      "y": 23,
      "z": 7,
      "name": "Plant_Leaves_Jungle"
    },
    {
      "x": -7,
      "y": 25,
      "z": 7,
      "name": "Plant_Leaves_Jungle"
    },
    {
      "x": -7,
      "y": 21,
      "z": 8,
      "name": "Plant_Leaves_Jungle"
    },
    {
      "x": -7,
      "y": 22,
      "z": 8,
      "name": "Plant_Leaves_Jungle"
    },
    {
      "x": -7,
      "y": 23,
      "z": 8,
      "name": "Plant_Leaves_Jungle"
    },
    {
      "x": -7,
      "y": 19,
      "z": 9,
      "name": "Plant_Leaves_Jungle"
    },
    {
      "x": -7,
      "y": 20,
      "z": 9,
      "name": "Plant_Leaves_Jungle"
    },
    {
      "x": -7,
      "y": 21,
      "z": 9,
      "name": "Plant_Leaves_Jungle"
    },
    {
      "x": -7,
      "y": 22,
      "z": 9,
      "name": "Plant_Leaves_Jungle"
    },
    {
      "x": -7,
      "y": 25,
      "z": 9,
      "name": "Plant_Leaves_Jungle"
    },
    {
      "x": -7,
      "y": 20,
      "z": 10,
      "name": "Plant_Leaves_Jungle"
    },
    {
      "x": -7,
      "y": 21,
      "z": 10,
      "name": "Plant_Leaves_Jungle"
    },
    {
      "x": -7,
      "y": 22,
      "z": 10,
      "name": "Plant_Leaves_Jungle"
    },
    {
      "x": -7,
      "y": 21,
      "z": 11,
      "name": "Plant_Leaves_Jungle"
    },
    {
      "x": -7,
      "y": 22,
      "z": 11,
      "name": "Plant_Leaves_Jungle"
    },
    {
      "x": -6,
      "y": 26,
      "z": -12,
      "name": "Plant_Leaves_Jungle"
    },
    {
      "x": -6,
      "y": 27,
      "z": -12,
      "name": "Plant_Leaves_Jungle"
    },
    {
      "x": -6,
      "y": 27,
      "z": -11,
      "name": "Plant_Leaves_Jungle"
    },
    {
      "x": -6,
      "y": 28,
      "z": -11,
      "name": "Plant_Leaves_Jungle"
    },
    {
      "x": -6,
      "y": 29,
      "z": -11,
      "name": "Plant_Leaves_Jungle"
    },
    {
      "x": -6,
      "y": 28,
      "z": -10,
      "name": "Plant_Leaves_Jungle"
    },
    {
      "x": -6,
      "y": 29,
      "z": -10,
      "name": "Plant_Leaves_Jungle"
    },
    {
      "x": -6,
      "y": 30,
      "z": -9,
      "name": "Plant_Leaves_Jungle"
    },
    {
      "x": -6,
      "y": 25,
      "z": -7,
      "name": "Wood_Jungle_Roots"
    },
    {
      "x": -6,
      "y": 26,
      "z": -7,
      "name": "Wood_Jungle_Trunk_Full"
    },
    {
      "x": -6,
      "y": 27,
      "z": -7,
      "name": "Wood_Jungle_Branch_Long"
    },
    {
      "x": -6,
      "y": 28,
      "z": -7,
      "name": "Wood_Jungle_Branch_Long"
    },
    {
      "x": -6,
      "y": 29,
      "z": -7,
      "name": "Wood_Jungle_Branch_Long"
    },
    {
      "x": -6,
      "y": 30,
      "z": -7,
      "name": "Plant_Leaves_Jungle"
    },
    {
      "x": -6,
      "y": 31,
      "z": -7,
      "name": "Plant_Leaves_Jungle"
    },
    {
      "x": -6,
      "y": 32,
      "z": -7,
      "name": "Plant_Leaves_Jungle"
    },
    {
      "x": -6,
      "y": 26,
      "z": -6,
      "name": "Wood_Jungle_Trunk_Full"
    },
    {
      "x": -6,
      "y": 29,
      "z": -6,
      "name": "Plant_Leaves_Jungle"
    },
    {
      "x": -6,
      "y": 30,
      "z": -6,
      "name": "Plant_Leaves_Jungle"
    },
    {
      "x": -6,
      "y": 31,
      "z": -6,
      "name": "Plant_Leaves_Jungle"
    },
    {
      "x": -6,
      "y": 32,
      "z": -6,
      "name": "Plant_Leaves_Jungle"
    },
    {
      "x": -6,
      "y": 30,
      "z": -5,
      "name": "Plant_Leaves_Jungle"
    },
    {
      "x": -6,
      "y": 31,
      "z": -5,
      "name": "Plant_Leaves_Jungle"
    },
    {
      "x": -6,
      "y": 32,
      "z": -5,
      "name": "Plant_Leaves_Jungle"
    },
    {
      "x": -6,
      "y": 33,
      "z": -5,
      "name": "Plant_Leaves_Jungle"
    },
    {
      "x": -6,
      "y": 30,
      "z": -4,
      "name": "Plant_Leaves_Jungle"
    },
    {
      "x": -6,
      "y": 32,
      "z": -4,
      "name": "Plant_Leaves_Jungle"
    },
    {
      "x": -6,
      "y": 31,
      "z": -3,
      "name": "Plant_Leaves_Jungle"
    },
    {
      "x": -6,
      "y": 24,
      "z": -1,
      "name": "Wood_Jungle_Trunk_Full"
    },
    {
      "x": -6,
      "y": 25,
      "z": -1,
      "name": "Wood_Jungle_Trunk_Full"
    },
    {
      "x": -6,
      "y": 31,
      "z": -1,
      "name": "Plant_Leaves_Jungle"
    },
    {
      "x": -6,
      "y": 32,
      "z": -1,
      "name": "Plant_Leaves_Jungle"
    },
    {
      "x": -6,
      "y": 33,
      "z": -1,
      "name": "Plant_Leaves_Jungle"
    },
    {
      "x": -6,
      "y": 34,
      "z": -1,
      "name": "Plant_Leaves_Jungle"
    },
    {
      "x": -6,
      "y": 10,
      "z": 0,
      "name": "Wood_Jungle_Trunk"
    },
    {
      "x": -6,
      "y": 11,
      "z": 0,
      "name": "Wood_Jungle_Trunk"
    },
    {
      "x": -6,
      "y": 12,
      "z": 0,
      "name": "Wood_Jungle_Trunk_Full"
    },
    {
      "x": -6,
      "y": 13,
      "z": 0,
      "name": "Wood_Jungle_Branch_Long"
    },
    {
      "x": -6,
      "y": 14,
      "z": 0,
      "name": "Wood_Jungle_Branch_Corner",
      "rotation": 9
    },
    {
      "x": -6,
      "y": 34,
      "z": 0,
      "name": "Plant_Leaves_Jungle"
    },
    {
      "x": -6,
      "y": 35,
      "z": 0,
      "name": "Plant_Leaves_Jungle"
    },
    {
      "x": -6,
      "y": 35,
      "z": 1,
      "name": "Plant_Leaves_Jungle"
    },
    {
      "x": -6,
      "y": 36,
      "z": 1,
      "name": "Plant_Leaves_Jungle"
    },
    {
      "x": -6,
      "y": 32,
      "z": 2,
      "name": "Wood_Jungle_Branch_Long",
      "rotation": 5
    },
    {
      "x": -6,
      "y": 35,
      "z": 2,
      "name": "Plant_Leaves_Jungle"
    },
    {
      "x": -6,
      "y": 36,
      "z": 2,
      "name": "Plant_Leaves_Jungle"
    },
    {
      "x": -6,
      "y": 36,
      "z": 4,
      "name": "Plant_Leaves_Jungle"
    },
    {
      "x": -6,
      "y": 33,
      "z": 5,
      "name": "Plant_Leaves_Jungle"
    },
    {
      "x": -6,
      "y": 35,
      "z": 5,
      "name": "Plant_Leaves_Jungle"
    },
    {
      "x": -6,
      "y": 25,
      "z": 6,
      "name": "Plant_Leaves_Jungle"
    },
    {
      "x": -6,
      "y": 33,
      "z": 6,
      "name": "Plant_Leaves_Jungle"
    },
    {
      "x": -6,
      "y": 34,
      "z": 6,
      "name": "Plant_Leaves_Jungle"
    },
    {
      "x": -6,
      "y": 25,
      "z": 7,
      "name": "Plant_Leaves_Jungle"
    },
    {
      "x": -6,
      "y": 33,
      "z": 7,
      "name": "Plant_Leaves_Jungle"
    },
    {
      "x": -6,
      "y": 34,
      "z": 7,
      "name": "Plant_Leaves_Jungle"
    },
    {
      "x": -6,
      "y": 21,
      "z": 8,
      "name": "Wood_Jungle_Branch_Corner",
      "rotation": 3
    },
    {
      "x": -6,
      "y": 22,
      "z": 8,
      "name": "Wood_Jungle_Branch_Long"
    },
    {
      "x": -6,
      "y": 23,
      "z": 8,
      "name": "Wood_Jungle_Branch_Long"
    },
    {
      "x": -6,
      "y": 24,
      "z": 8,
      "name": "Plant_Leaves_Jungle"
    },
    {
      "x": -6,
      "y": 22,
      "z": 9,
      "name": "Plant_Leaves_Jungle"
    },
    {
      "x": -6,
      "y": 24,
      "z": 9,
      "name": "Plant_Leaves_Jungle"
    },
    {
      "x": -6,
      "y": 25,
      "z": 9,
      "name": "Plant_Leaves_Jungle"
    },
    {
      "x": -6,
      "y": 22,
      "z": 10,
      "name": "Plant_Leaves_Jungle"
    },
    {
      "x": -6,
      "y": 23,
      "z": 10,
      "name": "Plant_Leaves_Jungle"
    },
    {
      "x": -6,
      "y": 24,
      "z": 10,
      "name": "Plant_Leaves_Jungle"
    },
    {
      "x": -6,
      "y": 21,
      "z": 11,
      "name": "Plant_Leaves_Jungle"
    },
    {
      "x": -6,
      "y": 22,
      "z": 11,
      "name": "Plant_Leaves_Jungle"
    },
    {
      "x": -6,
      "y": 23,
      "z": 11,
      "name": "Plant_Leaves_Jungle"
    },
    {
      "x": -6,
      "y": 24,
      "z": 11,
      "name": "Plant_Leaves_Jungle"
    },
    {
      "x": -6,
      "y": 20,
      "z": 12,
      "name": "Plant_Leaves_Jungle"
    },
    {
      "x": -6,
      "y": 21,
      "z": 12,
      "name": "Plant_Leaves_Jungle"
    },
    {
      "x": -6,
      "y": 22,
      "z": 12,
      "name": "Plant_Leaves_Jungle"
    },
    {
      "x": -6,
      "y": 20,
      "z": 13,
      "name": "Plant_Leaves_Jungle"
    },
    {
      "x": -6,
      "y": 21,
      "z": 13,
      "name": "Plant_Leaves_Jungle"
    },
    {
      "x": -5,
      "y": 27,
      "z": -12,
      "name": "Plant_Leaves_Jungle"
    },
    {
      "x": -5,
      "y": 28,
      "z": -11,
      "name": "Plant_Leaves_Jungle"
    },
    {
      "x": -5,
      "y": 28,
      "z": -10,
      "name": "Plant_Leaves_Jungle"
    },
    {
      "x": -5,
      "y": 29,
      "z": -10,
      "name": "Plant_Leaves_Jungle"
    },
    {
      "x": -5,
      "y": 28,
      "z": -9,
      "name": "Plant_Leaves_Jungle"
    },
    {
      "x": -5,
      "y": 29,
      "z": -9,
      "name": "Plant_Leaves_Jungle"
    },
    {
      "x": -5,
      "y": 31,
      "z": -8,
      "name": "Plant_Leaves_Jungle"
    },
    {
      "x": -5,
      "y": 32,
      "z": -8,
      "name": "Plant_Leaves_Jungle"
    },
    {
      "x": -5,
      "y": 30,
      "z": -7,
      "name": "Plant_Leaves_Jungle"
    },
    {
      "x": -5,
      "y": 31,
      "z": -7,
      "name": "Plant_Leaves_Jungle"
    },
    {
      "x": -5,
      "y": 32,
      "z": -7,
      "name": "Plant_Leaves_Jungle"
    },
    {
      "x": -5,
      "y": 33,
      "z": -7,
      "name": "Plant_Leaves_Jungle"
    },
    {
      "x": -5,
      "y": 26,
      "z": -6,
      "name": "Wood_Jungle_Trunk_Full"
    },
    {
      "x": -5,
      "y": 30,
      "z": -6,
      "name": "Plant_Leaves_Jungle"
    },
    {
      "x": -5,
      "y": 33,
      "z": -6,
      "name": "Plant_Leaves_Jungle"
    },
    {
      "x": -5,
      "y": 24,
      "z": -5,
      "name": "Wood_Jungle_Roots"
    },
    {
      "x": -5,
      "y": 25,
      "z": -5,
      "name": "Wood_Jungle_Trunk_Full"
    },
    {
      "x": -5,
      "y": 26,
      "z": -5,
      "name": "Wood_Jungle_Trunk_Full"
    },
    {
      "x": -5,
      "y": 30,
      "z": -5,
      "name": "Wood_Jungle_Branch_Corner",
      "rotation": 3
    },
    {
      "x": -5,
      "y": 31,
      "z": -5,
      "name": "Wood_Jungle_Branch_Long"
    },
    {
      "x": -5,
      "y": 32,
      "z": -5,
      "name": "Plant_Leaves_Jungle"
    },
    {
      "x": -5,
      "y": 33,
      "z": -5,
      "name": "Plant_Leaves_Jungle"
    },
    {
      "x": -5,
      "y": 25,
      "z": -4,
      "name": "Wood_Jungle_Trunk_Full"
    },
    {
      "x": -5,
      "y": 32,
      "z": -4,
      "name": "Plant_Leaves_Jungle"
    },
    {
      "x": -5,
      "y": 30,
      "z": -3,
      "name": "Plant_Leaves_Jungle"
    },
    {
      "x": -5,
      "y": 31,
      "z": -3,
      "name": "Plant_Leaves_Jungle"
    },
    {
      "x": -5,
      "y": 32,
      "z": -3,
      "name": "Plant_Leaves_Jungle"
    },
    {
      "x": -5,
      "y": 33,
      "z": -3,
      "name": "Plant_Leaves_Jungle"
    },
    {
      "x": -5,
      "y": 10,
      "z": -2,
      "name": "Wood_Jungle_Branch_Long"
    },
    {
      "x": -5,
      "y": 11,
      "z": -2,
      "name": "Wood_Jungle_Branch_Long"
    },
    {
      "x": -5,
      "y": 12,
      "z": -2,
      "name": "Wood_Jungle_Branch_Long"
    },
    {
      "x": -5,
      "y": 13,
      "z": -2,
      "name": "Wood_Jungle_Branch_Corner",
      "rotation": 8
    },
    {
      "x": -5,
      "y": 31,
      "z": -2,
      "name": "Plant_Leaves_Jungle"
    },
    {
      "x": -5,
      "y": 10,
      "z": -1,
      "name": "Wood_Jungle_Trunk"
    },
    {
      "x": -5,
      "y": 11,
      "z": -1,
      "name": "Wood_Jungle_Trunk"
    },
    {
      "x": -5,
      "y": 12,
      "z": -1,
      "name": "Wood_Jungle_Trunk"
    },
    {
      "x": -5,
      "y": 13,
      "z": -1,
      "name": "Wood_Jungle_Trunk_Full"
    },
    {
      "x": -5,
      "y": 14,
      "z": -1,
      "name": "Wood_Jungle_Branch_Long"
    },
    {
      "x": -5,
      "y": 15,
      "z": -1,
      "name": "Wood_Jungle_Branch_Long"
    },
    {
      "x": -5,
      "y": 16,
      "z": -1,
      "name": "Wood_Jungle_Branch_Corner",
      "rotation": 9
    },
    {
      "x": -5,
      "y": 23,
      "z": -1,
      "name": "Wood_Jungle_Trunk_Full"
    },
    {
      "x": -5,
      "y": 24,
      "z": -1,
      "name": "Wood_Jungle_Trunk_Full"
    },
    {
      "x": -5,
      "y": 35,
      "z": -1,
      "name": "Plant_Leaves_Jungle"
    },
    {
      "x": -5,
      "y": 10,
      "z": 0,
      "name": "Wood_Jungle_Trunk"
    },
    {
      "x": -5,
      "y": 11,
      "z": 0,
      "name": "Wood_Jungle_Trunk"
    },
    {
      "x": -5,
      "y": 12,
      "z": 0,
      "name": "Wood_Jungle_Trunk"
    },
    {
      "x": -5,
      "y": 13,
      "z": 0,
      "name": "Wood_Jungle_Trunk"
    },
    {
      "x": -5,
      "y": 14,
      "z": 0,
      "name": "Wood_Jungle_Trunk_Full"
    },
    {
      "x": -5,
      "y": 15,
      "z": 0,
      "name": "Wood_Jungle_Branch_Long"
    },
    {
      "x": -5,
      "y": 16,
      "z": 0,
      "name": "Wood_Jungle_Branch_Corner",
      "rotation": 9
    },
    {
      "x": -5,
      "y": 34,
      "z": 0,
      "name": "Plant_Leaves_Jungle"
    },
    {
      "x": -5,
      "y": 35,
      "z": 0,
      "name": "Plant_Leaves_Jungle"
    },
    {
      "x": -5,
      "y": 10,
      "z": 1,
      "name": "Wood_Jungle_Branch_Long"
    },
    {
      "x": -5,
      "y": 11,
      "z": 1,
      "name": "Wood_Jungle_Branch_Long"
    },
    {
      "x": -5,
      "y": 12,
      "z": 1,
      "name": "Wood_Jungle_Branch_Long"
    },
    {
      "x": -5,
      "y": 13,
      "z": 1,
      "name": "Wood_Jungle_Branch_Long"
    },
    {
      "x": -5,
      "y": 14,
      "z": 1,
      "name": "Wood_Jungle_Branch_Corner",
      "rotation": 10
    },
    {
      "x": -5,
      "y": 36,
      "z": 1,
      "name": "Plant_Leaves_Jungle"
    },
    {
      "x": -5,
      "y": 29,
      "z": 2,
      "name": "Wood_Jungle_Trunk_Full"
    },
    {
      "x": -5,
      "y": 30,
      "z": 2,
      "name": "Wood_Jungle_Trunk"
    },
    {
      "x": -5,
      "y": 31,
      "z": 2,
      "name": "Wood_Jungle_Trunk"
    },
    {
      "x": -5,
      "y": 32,
      "z": 2,
      "name": "Wood_Jungle_Trunk"
    },
    {
      "x": -5,
      "y": 33,
      "z": 2,
      "name": "Wood_Jungle_Trunk_Full"
    },
    {
      "x": -5,
      "y": 34,
      "z": 2,
      "name": "Wood_Jungle_Branch_Long"
    },
    {
      "x": -5,
      "y": 35,
      "z": 2,
      "name": "Wood_Jungle_Branch_Long"
    },
    {
      "x": -5,
      "y": 36,
      "z": 2,
      "name": "Plant_Leaves_Jungle"
    },
    {
      "x": -5,
      "y": 33,
      "z": 3,
      "name": "Wood_Jungle_Branch_Long",
      "rotation": 4
    },
    {
      "x": -5,
      "y": 36,
      "z": 3,
      "name": "Plant_Leaves_Jungle"
    },
    {
      "x": -5,
      "y": 33,
      "z": 4,
      "name": "Wood_Jungle_Branch_Long",
      "rotation": 4
    },
    {
      "x": -5,
      "y": 36,
      "z": 4,
      "name": "Plant_Leaves_Jungle"
    },
    {
      "x": -5,
      "y": 33,
      "z": 5,
      "name": "Wood_Jungle_Branch_Corner"
    },
    {
      "x": -5,
      "y": 34,
      "z": 5,
      "name": "Wood_Jungle_Branch_Long"
    },
    {
      "x": -5,
      "y": 35,
      "z": 5,
      "name": "Plant_Leaves_Jungle"
    },
    {
      "x": -5,
      "y": 34,
      "z": 6,
      "name": "Plant_Leaves_Jungle"
    },
    {
      "x": -5,
      "y": 35,
      "z": 6,
      "name": "Plant_Leaves_Jungle"
    },
    {
      "x": -5,
      "y": 25,
      "z": 7,
      "name": "Plant_Leaves_Jungle"
    },
    {
      "x": -5,
      "y": 31,
      "z": 7,
      "name": "Plant_Leaves_Jungle"
    },
    {
      "x": -5,
      "y": 32,
      "z": 7,
      "name": "Plant_Leaves_Jungle"
    },
    {
      "x": -5,
      "y": 33,
      "z": 7,
      "name": "Plant_Leaves_Jungle"
    },
    {
      "x": -5,
      "y": 34,
      "z": 7,
      "name": "Plant_Leaves_Jungle"
    },
    {
      "x": -5,
      "y": 21,
      "z": 8,
      "name": "Wood_Jungle_Branch_Long",
      "rotation": 5
    },
    {
      "x": -5,
      "y": 24,
      "z": 8,
      "name": "Plant_Leaves_Jungle"
    },
    {
      "x": -5,
      "y": 25,
      "z": 8,
      "name": "Plant_Leaves_Jungle"
    },
    {
      "x": -5,
      "y": 24,
      "z": 9,
      "name": "Plant_Leaves_Jungle"
    },
    {
      "x": -5,
      "y": 25,
      "z": 9,
      "name": "Plant_Leaves_Jungle"
    },
    {
      "x": -5,
      "y": 24,
      "z": 10,
      "name": "Plant_Leaves_Jungle"
    },
    {
      "x": -5,
      "y": 25,
      "z": 10,
      "name": "Plant_Leaves_Jungle"
    },
    {
      "x": -5,
      "y": 21,
      "z": 11,
      "name": "Plant_Leaves_Jungle"
    },
    {
      "x": -5,
      "y": 25,
      "z": 11,
      "name": "Plant_Leaves_Jungle"
    },
    {
      "x": -5,
      "y": 21,
      "z": 12,
      "name": "Plant_Leaves_Jungle"
    },
    {
      "x": -5,
      "y": 22,
      "z": 12,
      "name": "Plant_Leaves_Jungle"
    },
    {
      "x": -5,
      "y": 25,
      "z": 12,
      "name": "Plant_Leaves_Jungle"
    },
    {
      "x": -5,
      "y": 21,
      "z": 13,
      "name": "Plant_Leaves_Jungle"
    },
    {
      "x": -5,
      "y": 22,
      "z": 13,
      "name": "Plant_Leaves_Jungle"
    },
    {
      "x": -4,
      "y": 28,
      "z": -10,
      "name": "Plant_Leaves_Jungle"
    },
    {
      "x": -4,
      "y": 28,
      "z": -9,
      "name": "Plant_Leaves_Jungle"
    },
    {
      "x": -4,
      "y": 29,
      "z": -9,
      "name": "Plant_Leaves_Jungle"
    },
    {
      "x": -4,
      "y": 31,
      "z": -9,
      "name": "Plant_Leaves_Jungle"
    },
    {
      "x": -4,
      "y": 30,
      "z": -8,
      "name": "Plant_Leaves_Jungle"
    },
    {
      "x": -4,
      "y": 31,
      "z": -8,
      "name": "Plant_Leaves_Jungle"
    },
    {
      "x": -4,
      "y": 28,
      "z": -7,
      "name": "Plant_Leaves_Jungle"
    },
    {
      "x": -4,
      "y": 29,
      "z": -7,
      "name": "Plant_Leaves_Jungle"
    },
    {
      "x": -4,
      "y": 30,
      "z": -7,
      "name": "Plant_Leaves_Jungle"
    },
    {
      "x": -4,
      "y": 31,
      "z": -7,
      "name": "Plant_Leaves_Jungle"
    },
    {
      "x": -4,
      "y": 33,
      "z": -7,
      "name": "Plant_Leaves_Jungle"
    },
    {
      "x": -4,
      "y": 34,
      "z": -6,
      "name": "Plant_Leaves_Jungle"
    },
    {
      "x": -4,
      "y": 30,
      "z": -5,
      "name": "Wood_Jungle_Branch_Long",
      "rotation": 5
    },
    {
      "x": -4,
      "y": 34,
      "z": -5,
      "name": "Plant_Leaves_Jungle"
    },
    {
      "x": -4,
      "y": 24,
      "z": -4,
      "name": "Wood_Jungle_Trunk_Full"
    },
    {
      "x": -4,
      "y": 25,
      "z": -4,
      "name": "Wood_Jungle_Trunk_Full"
    },
    {
      "x": -4,
      "y": 34,
      "z": -4,
      "name": "Plant_Leaves_Jungle"
    },
    {
      "x": -4,
      "y": 24,
      "z": -3,
      "name": "Wood_Jungle_Trunk_Full"
    },
    {
      "x": -4,
      "y": 25,
      "z": -3,
      "name": "Wood_Jungle_Trunk_Full"
    },
    {
      "x": -4,
      "y": 33,
      "z": -3,
      "name": "Plant_Leaves_Jungle"
    },
    {
      "x": -4,
      "y": 10,
      "z": -2,
      "name": "Wood_Jungle_Trunk"
    },
    {
      "x": -4,
      "y": 11,
      "z": -2,
      "name": "Wood_Jungle_Trunk"
    },
    {
      "x": -4,
      "y": 12,
      "z": -2,
      "name": "Wood_Jungle_Trunk"
    },
    {
      "x": -4,
      "y": 13,
      "z": -2,
      "name": "Wood_Jungle_Trunk_Full"
    },
    {
      "x": -4,
      "y": 14,
      "z": -2,
      "name": "Wood_Jungle_Branch_Long"
    },
    {
      "x": -4,
      "y": 15,
      "z": -2,
      "name": "Wood_Jungle_Branch_Long"
    },
    {
      "x": -4,
      "y": 16,
      "z": -2,
      "name": "Wood_Jungle_Branch_Long"
    },
    {
      "x": -4,
      "y": 17,
      "z": -2,
      "name": "Wood_Jungle_Branch_Corner",
      "rotation": 8
    },
    {
      "x": -4,
      "y": 23,
      "z": -2,
      "name": "Wood_Jungle_Trunk_Full"
    },
    {
      "x": -4,
      "y": 24,
      "z": -2,
      "name": "Wood_Jungle_Trunk_Full"
    },
    {
      "x": -4,
      "y": 33,
      "z": -2,
      "name": "Plant_Leaves_Jungle"
    },
    {
      "x": -4,
      "y": 10,
      "z": -1,
      "name": "Wood_Jungle_Trunk"
    },
    {
      "x": -4,
      "y": 11,
      "z": -1,
      "name": "Wood_Jungle_Trunk"
    },
    {
      "x": -4,
      "y": 12,
      "z": -1,
      "name": "Wood_Jungle_Trunk"
    },
    {
      "x": -4,
      "y": 13,
      "z": -1,
      "name": "Wood_Jungle_Trunk"
    },
    {
      "x": -4,
      "y": 14,
      "z": -1,
      "name": "Wood_Jungle_Trunk"
    },
    {
      "x": -4,
      "y": 15,
      "z": -1,
      "name": "Wood_Jungle_Trunk"
    },
    {
      "x": -4,
      "y": 16,
      "z": -1,
      "name": "Wood_Jungle_Trunk"
    },
    {
      "x": -4,
      "y": 17,
      "z": -1,
      "name": "Wood_Jungle_Trunk"
    },
    {
      "x": -4,
      "y": 18,
      "z": -1,
      "name": "Wood_Jungle_Trunk"
    },
    {
      "x": -4,
      "y": 19,
      "z": -1,
      "name": "Wood_Jungle_Trunk"
    },
    {
      "x": -4,
      "y": 20,
      "z": -1,
      "name": "Wood_Jungle_Trunk"
    },
    {
      "x": -4,
      "y": 21,
      "z": -1,
      "name": "Wood_Jungle_Trunk"
    },
    {
      "x": -4,
      "y": 22,
      "z": -1,
      "name": "Wood_Jungle_Trunk_Full"
    },
    {
      "x": -4,
      "y": 23,
      "z": -1,
      "name": "Wood_Jungle_Trunk_Full"
    },
    {
      "x": -4,
      "y": 24,
      "z": -1,
      "name": "Wood_Jungle_Trunk_Full"
    },
    {
      "x": -4,
      "y": 35,
      "z": -1,
      "name": "Plant_Leaves_Jungle"
    },
    {
      "x": -4,
      "y": 10,
      "z": 0,
      "name": "Wood_Jungle_Trunk"
    },
    {
      "x": -4,
      "y": 11,
      "z": 0,
      "name": "Wood_Jungle_Trunk"
    },
    {
      "x": -4,
      "y": 12,
      "z": 0,
      "name": "Wood_Jungle_Trunk"
    },
    {
      "x": -4,
      "y": 13,
      "z": 0,
      "name": "Wood_Jungle_Trunk"
    },
    {
      "x": -4,
      "y": 14,
      "z": 0,
      "name": "Wood_Jungle_Trunk"
    },
    {
      "x": -4,
      "y": 15,
      "z": 0,
      "name": "Wood_Jungle_Trunk"
    },
    {
      "x": -4,
      "y": 16,
      "z": 0,
      "name": "Wood_Jungle_Trunk"
    },
    {
      "x": -4,
      "y": 17,
      "z": 0,
      "name": "Wood_Jungle_Trunk"
    },
    {
      "x": -4,
      "y": 18,
      "z": 0,
      "name": "Wood_Jungle_Trunk"
    },
    {
      "x": -4,
      "y": 19,
      "z": 0,
      "name": "Wood_Jungle_Trunk"
    },
    {
      "x": -4,
      "y": 20,
      "z": 0,
      "name": "Wood_Jungle_Trunk"
    },
    {
      "x": -4,
      "y": 21,
      "z": 0,
      "name": "Wood_Jungle_Trunk_Full"
    },
    {
      "x": -4,
      "y": 22,
      "z": 0,
      "name": "Wood_Jungle_Trunk"
    },
    {
      "x": -4,
      "y": 23,
      "z": 0,
      "name": "Wood_Jungle_Trunk_Full"
    },
    {
      "x": -4,
      "y": 24,
      "z": 0,
      "name": "Wood_Jungle_Trunk_Full"
    },
    {
      "x": -4,
      "y": 25,
      "z": 0,
      "name": "Wood_Jungle_Trunk"
    },
    {
      "x": -4,
      "y": 26,
      "z": 0,
      "name": "Wood_Jungle_Trunk_Full"
    },
    {
      "x": -4,
      "y": 36,
      "z": 0,
      "name": "Plant_Leaves_Jungle"
    },
    {
      "x": -4,
      "y": 10,
      "z": 1,
      "name": "Wood_Jungle_Trunk"
    },
    {
      "x": -4,
      "y": 11,
      "z": 1,
      "name": "Wood_Jungle_Trunk"
    },
    {
      "x": -4,
      "y": 12,
      "z": 1,
      "name": "Wood_Jungle_Trunk"
    },
    {
      "x": -4,
      "y": 13,
      "z": 1,
      "name": "Wood_Jungle_Trunk_Full"
    },
    {
      "x": -4,
      "y": 14,
      "z": 1,
      "name": "Wood_Jungle_Branch_Long"
    },
    {
      "x": -4,
      "y": 15,
      "z": 1,
      "name": "Wood_Jungle_Branch_Long"
    },
    {
      "x": -4,
      "y": 16,
      "z": 1,
      "name": "Wood_Jungle_Branch_Long"
    },
    {
      "x": -4,
      "y": 17,
      "z": 1,
      "name": "Wood_Jungle_Branch_Long"
    },
    {
      "x": -4,
      "y": 18,
      "z": 1,
      "name": "Wood_Jungle_Branch_Corner",
      "rotation": 10
    },
    {
      "x": -4,
      "y": 21,
      "z": 1,
      "name": "Wood_Jungle_Trunk_Full"
    },
    {
      "x": -4,
      "y": 22,
      "z": 1,
      "name": "Wood_Jungle_Trunk_Full"
    },
    {
      "x": -4,
      "y": 26,
      "z": 1,
      "name": "Wood_Jungle_Trunk_Full"
    },
    {
      "x": -4,
      "y": 27,
      "z": 1,
      "name": "Wood_Jungle_Trunk"
    },
    {
      "x": -4,
      "y": 28,
      "z": 1,
      "name": "Wood_Jungle_Trunk"
    },
    {
      "x": -4,
      "y": 29,
      "z": 1,
      "name": "Wood_Jungle_Trunk_Full"
    },
    {
      "x": -4,
      "y": 36,
      "z": 1,
      "name": "Plant_Leaves_Jungle"
    },
    {
      "x": -4,
      "y": 22,
      "z": 2,
      "name": "Wood_Jungle_Trunk_Full"
    },
    {
      "x": -4,
      "y": 29,
      "z": 2,
      "name": "Wood_Jungle_Trunk_Full"
    },
    {
      "x": -4,
      "y": 36,
      "z": 2,
      "name": "Plant_Leaves_Jungle"
    },
    {
      "x": -4,
      "y": 22,
      "z": 3,
      "name": "Wood_Jungle_Trunk_Full"
    },
    {
      "x": -4,
      "y": 22,
      "z": 4,
      "name": "Wood_Jungle_Trunk_Full"
    },
    {
      "x": -4,
      "y": 36,
      "z": 4,
      "name": "Plant_Leaves_Jungle"
    },
    {
      "x": -4,
      "y": 25,
      "z": 5,
      "name": "Plant_Leaves_Jungle"
    },
    {
      "x": -4,
      "y": 35,
      "z": 5,
      "name": "Plant_Leaves_Jungle"
    },
    {
      "x": -4,
      "y": 36,
      "z": 5,
      "name": "Plant_Leaves_Jungle"
    },
    {
      "x": -4,
      "y": 25,
      "z": 6,
      "name": "Plant_Leaves_Jungle"
    },
    {
      "x": -4,
      "y": 34,
      "z": 6,
      "name": "Plant_Leaves_Jungle"
    },
    {
      "x": -4,
      "y": 35,
      "z": 6,
      "name": "Plant_Leaves_Jungle"
    },
    {
      "x": -4,
      "y": 32,
      "z": 7,
      "name": "Plant_Leaves_Jungle"
    },
    {
      "x": -4,
      "y": 33,
      "z": 7,
      "name": "Plant_Leaves_Jungle"
    },
    {
      "x": -4,
      "y": 34,
      "z": 7,
      "name": "Plant_Leaves_Jungle"
    },
    {
      "x": -4,
      "y": 21,
      "z": 8,
      "name": "Wood_Jungle_Branch_Long",
      "rotation": 5
    },
    {
      "x": -4,
      "y": 25,
      "z": 8,
      "name": "Plant_Leaves_Jungle"
    },
    {
      "x": -4,
      "y": 26,
      "z": 8,
      "name": "Plant_Leaves_Jungle"
    },
    {
      "x": -4,
      "y": 25,
      "z": 9,
      "name": "Plant_Leaves_Jungle"
    },
    {
      "x": -4,
      "y": 26,
      "z": 9,
      "name": "Plant_Leaves_Jungle"
    },
    {
      "x": -4,
      "y": 25,
      "z": 10,
      "name": "Plant_Leaves_Jungle"
    },
    {
      "x": -4,
      "y": 24,
      "z": 12,
      "name": "Plant_Leaves_Jungle"
    },
    {
      "x": -4,
      "y": 20,
      "z": 13,
      "name": "Plant_Leaves_Jungle"
    },
    {
      "x": -4,
      "y": 21,
      "z": 13,
      "name": "Plant_Leaves_Jungle"
    },
    {
      "x": -4,
      "y": 22,
      "z": 13,
      "name": "Plant_Leaves_Jungle"
    },
    {
      "x": -4,
      "y": 23,
      "z": 13,
      "name": "Plant_Leaves_Jungle"
    },
    {
      "x": -4,
      "y": 18,
      "z": 14,
      "name": "Plant_Leaves_Jungle"
    },
    {
      "x": -4,
      "y": 19,
      "z": 14,
      "name": "Plant_Leaves_Jungle"
    },
    {
      "x": -4,
      "y": 20,
      "z": 14,
      "name": "Plant_Leaves_Jungle"
    },
    {
      "x": -4,
      "y": 21,
      "z": 14,
      "name": "Plant_Leaves_Jungle"
    },
    {
      "x": -3,
      "y": 28,
      "z": -9,
      "name": "Plant_Leaves_Jungle"
    },
    {
      "x": -3,
      "y": 29,
      "z": -9,
      "name": "Plant_Leaves_Jungle"
    },
    {
      "x": -3,
      "y": 30,
      "z": -9,
      "name": "Plant_Leaves_Jungle"
    },
    {
      "x": -3,
      "y": 31,
      "z": -9,
      "name": "Plant_Leaves_Jungle"
    },
    {
      "x": -3,
      "y": 32,
      "z": -9,
      "name": "Plant_Leaves_Jungle"
    },
    {
      "x": -3,
      "y": 28,
      "z": -8,
      "name": "Plant_Leaves_Jungle"
    },
    {
      "x": -3,
      "y": 29,
      "z": -8,
      "name": "Plant_Leaves_Jungle"
    },
    {
      "x": -3,
      "y": 33,
      "z": -8,
      "name": "Plant_Leaves_Jungle"
    },
    {
      "x": -3,
      "y": 28,
      "z": -7,
      "name": "Plant_Leaves_Jungle"
    },
    {
      "x": -3,
      "y": 29,
      "z": -7,
      "name": "Plant_Leaves_Jungle"
    },
    {
      "x": -3,
      "y": 33,
      "z": -7,
      "name": "Plant_Leaves_Jungle"
    },
    {
      "x": -3,
      "y": 34,
      "z": -7,
      "name": "Plant_Leaves_Jungle"
    },
    {
      "x": -3,
      "y": 28,
      "z": -6,
      "name": "Plant_Leaves_Jungle"
    },
    {
      "x": -3,
      "y": 33,
      "z": -6,
      "name": "Plant_Leaves_Jungle"
    },
    {
      "x": -3,
      "y": 34,
      "z": -6,
      "name": "Plant_Leaves_Jungle"
    },
    {
      "x": -3,
      "y": 30,
      "z": -5,
      "name": "Wood_Jungle_Branch_Long",
      "rotation": 5
    },
    {
      "x": -3,
      "y": 27,
      "z": -4,
      "name": "Wood_Jungle_Trunk_Full"
    },
    {
      "x": -3,
      "y": 28,
      "z": -4,
      "name": "Wood_Jungle_Trunk"
    },
    {
      "x": -3,
      "y": 29,
      "z": -4,
      "name": "Wood_Jungle_Trunk_Full"
    },
    {
      "x": -3,
      "y": 34,
      "z": -4,
      "name": "Plant_Leaves_Jungle"
    },
    {
      "x": -3,
      "y": 10,
      "z": -3,
      "name": "Wood_Jungle_Trunk"
    },
    {
      "x": -3,
      "y": 11,
      "z": -3,
      "name": "Wood_Jungle_Trunk"
    },
    {
      "x": -3,
      "y": 12,
      "z": -3,
      "name": "Wood_Jungle_Trunk_Full"
    },
    {
      "x": -3,
      "y": 13,
      "z": -3,
      "name": "Wood_Jungle_Branch_Long"
    },
    {
      "x": -3,
      "y": 14,
      "z": -3,
      "name": "Wood_Jungle_Branch_Long"
    },
    {
      "x": -3,
      "y": 15,
      "z": -3,
      "name": "Wood_Jungle_Branch_Corner",
      "rotation": 8
    },
    {
      "x": -3,
      "y": 26,
      "z": -3,
      "name": "Wood_Jungle_Trunk_Full"
    },
    {
      "x": -3,
      "y": 27,
      "z": -3,
      "name": "Wood_Jungle_Trunk_Full"
    },
    {
      "x": -3,
      "y": 34,
      "z": -3,
      "name": "Plant_Leaves_Jungle"
    },
    {
      "x": -3,
      "y": 10,
      "z": -2,
      "name": "Wood_Jungle_Trunk"
    },
    {
      "x": -3,
      "y": 11,
      "z": -2,
      "name": "Wood_Jungle_Trunk"
    },
    {
      "x": -3,
      "y": 12,
      "z": -2,
      "name": "Wood_Jungle_Trunk"
    },
    {
      "x": -3,
      "y": 13,
      "z": -2,
      "name": "Wood_Jungle_Trunk"
    },
    {
      "x": -3,
      "y": 14,
      "z": -2,
      "name": "Wood_Jungle_Trunk"
    },
    {
      "x": -3,
      "y": 15,
      "z": -2,
      "name": "Wood_Jungle_Trunk_Full"
    },
    {
      "x": -3,
      "y": 16,
      "z": -2,
      "name": "Wood_Jungle_Branch_Long"
    },
    {
      "x": -3,
      "y": 17,
      "z": -2,
      "name": "Wood_Jungle_Branch_Long"
    },
    {
      "x": -3,
      "y": 18,
      "z": -2,
      "name": "Wood_Jungle_Branch_Corner",
      "rotation": 8
    },
    {
      "x": -3,
      "y": 22,
      "z": -2,
      "name": "Wood_Jungle_Trunk_Full"
    },
    {
      "x": -3,
      "y": 23,
      "z": -2,
      "name": "Wood_Jungle_Trunk_Full"
    },
    {
      "x": -3,
      "y": 24,
      "z": -2,
      "name": "Wood_Jungle_Trunk_Full"
    },
    {
      "x": -3,
      "y": 25,
      "z": -2,
      "name": "Wood_Jungle_Trunk_Full"
    },
    {
      "x": -3,
      "y": 26,
      "z": -2,
      "name": "Wood_Jungle_Trunk_Full"
    },
    {
      "x": -3,
      "y": 33,
      "z": -2,
      "name": "Plant_Leaves_Jungle"
    },
    {
      "x": -3,
      "y": 10,
      "z": -1,
      "name": "Wood_Jungle_Trunk"
    },
    {
      "x": -3,
      "y": 11,
      "z": -1,
      "name": "Wood_Jungle_Trunk"
    },
    {
      "x": -3,
      "y": 12,
      "z": -1,
      "name": "Wood_Jungle_Trunk"
    },
    {
      "x": -3,
      "y": 13,
      "z": -1,
      "name": "Wood_Jungle_Trunk"
    },
    {
      "x": -3,
      "y": 14,
      "z": -1,
      "name": "Wood_Jungle_Trunk"
    },
    {
      "x": -3,
      "y": 15,
      "z": -1,
      "name": "Wood_Jungle_Trunk"
    },
    {
      "x": -3,
      "y": 16,
      "z": -1,
      "name": "Wood_Jungle_Trunk"
    },
    {
      "x": -3,
      "y": 17,
      "z": -1,
      "name": "Wood_Jungle_Trunk"
    },
    {
      "x": -3,
      "y": 18,
      "z": -1,
      "name": "Wood_Jungle_Trunk"
    },
    {
      "x": -3,
      "y": 19,
      "z": -1,
      "name": "Wood_Jungle_Trunk"
    },
    {
      "x": -3,
      "y": 20,
      "z": -1,
      "name": "Wood_Jungle_Trunk"
    },
    {
      "x": -3,
      "y": 21,
      "z": -1,
      "name": "Wood_Jungle_Trunk"
    },
    {
      "x": -3,
      "y": 22,
      "z": -1,
      "name": "Wood_Jungle_Trunk"
    },
    {
      "x": -3,
      "y": 23,
      "z": -1,
      "name": "Wood_Jungle_Trunk_Full"
    },
    {
      "x": -3,
      "y": 24,
      "z": -1,
      "name": "Wood_Jungle_Trunk_Full"
    },
    {
      "x": -3,
      "y": 25,
      "z": -1,
      "name": "Wood_Jungle_Trunk_Full"
    },
    {
      "x": -3,
      "y": 35,
      "z": -1,
      "name": "Plant_Leaves_Jungle"
    },
    {
      "x": -3,
      "y": 10,
      "z": 0,
      "name": "Wood_Jungle_Trunk"
    },
    {
      "x": -3,
      "y": 11,
      "z": 0,
      "name": "Wood_Jungle_Trunk"
    },
    {
      "x": -3,
      "y": 12,
      "z": 0,
      "name": "Wood_Jungle_Trunk"
    },
    {
      "x": -3,
      "y": 13,
      "z": 0,
      "name": "Wood_Jungle_Trunk"
    },
    {
      "x": -3,
      "y": 14,
      "z": 0,
      "name": "Wood_Jungle_Trunk"
    },
    {
      "x": -3,
      "y": 15,
      "z": 0,
      "name": "Wood_Jungle_Trunk"
    },
    {
      "x": -3,
      "y": 16,
      "z": 0,
      "name": "Wood_Jungle_Trunk"
    },
    {
      "x": -3,
      "y": 17,
      "z": 0,
      "name": "Wood_Jungle_Trunk"
    },
    {
      "x": -3,
      "y": 18,
      "z": 0,
      "name": "Wood_Jungle_Trunk"
    },
    {
      "x": -3,
      "y": 19,
      "z": 0,
      "name": "Wood_Jungle_Trunk"
    },
    {
      "x": -3,
      "y": 20,
      "z": 0,
      "name": "Wood_Jungle_Trunk"
    },
    {
      "x": -3,
      "y": 21,
      "z": 0,
      "name": "Wood_Jungle_Trunk"
    },
    {
      "x": -3,
      "y": 22,
      "z": 0,
      "name": "Wood_Jungle_Trunk_Full"
    },
    {
      "x": -3,
      "y": 23,
      "z": 0,
      "name": "Wood_Jungle_Trunk"
    },
    {
      "x": -3,
      "y": 24,
      "z": 0,
      "name": "Wood_Jungle_Trunk_Full"
    },
    {
      "x": -3,
      "y": 35,
      "z": 0,
      "name": "Plant_Leaves_Jungle"
    },
    {
      "x": -3,
      "y": 10,
      "z": 1,
      "name": "Wood_Jungle_Trunk"
    },
    {
      "x": -3,
      "y": 11,
      "z": 1,
      "name": "Wood_Jungle_Trunk"
    },
    {
      "x": -3,
      "y": 12,
      "z": 1,
      "name": "Wood_Jungle_Trunk"
    },
    {
      "x": -3,
      "y": 13,
      "z": 1,
      "name": "Wood_Jungle_Trunk"
    },
    {
      "x": -3,
      "y": 14,
      "z": 1,
      "name": "Wood_Jungle_Trunk"
    },
    {
      "x": -3,
      "y": 15,
      "z": 1,
      "name": "Wood_Jungle_Trunk_Full"
    },
    {
      "x": -3,
      "y": 16,
      "z": 1,
      "name": "Wood_Jungle_Branch_Long"
    },
    {
      "x": -3,
      "y": 17,
      "z": 1,
      "name": "Wood_Jungle_Branch_Long"
    },
    {
      "x": -3,
      "y": 18,
      "z": 1,
      "name": "Wood_Jungle_Branch_Long"
    },
    {
      "x": -3,
      "y": 19,
      "z": 1,
      "name": "Wood_Jungle_Branch_Corner",
      "rotation": 10
    },
    {
      "x": -3,
      "y": 10,
      "z": 2,
      "name": "Wood_Jungle_Branch_Long"
    },
    {
      "x": -3,
      "y": 11,
      "z": 2,
      "name": "Wood_Jungle_Branch_Long"
    },
    {
      "x": -3,
      "y": 12,
      "z": 2,
      "name": "Wood_Jungle_Branch_Long"
    },
    {
      "x": -3,
      "y": 13,
      "z": 2,
      "name": "Wood_Jungle_Branch_Long"
    },
    {
      "x": -3,
      "y": 14,
      "z": 2,
      "name": "Wood_Jungle_Branch_Long"
    },
    {
      "x": -3,
      "y": 15,
      "z": 2,
      "name": "Wood_Jungle_Branch_Corner",
      "rotation": 10
    },
    {
      "x": -3,
      "y": 36,
      "z": 2,
      "name": "Plant_Leaves_Jungle"
    },
    {
      "x": -3,
      "y": 36,
      "z": 3,
      "name": "Plant_Leaves_Jungle"
    },
    {
      "x": -3,
      "y": 22,
      "z": 4,
      "name": "Wood_Jungle_Trunk_Full"
    },
    {
      "x": -3,
      "y": 36,
      "z": 4,
      "name": "Plant_Leaves_Jungle"
    },
    {
      "x": -3,
      "y": 21,
      "z": 5,
      "name": "Wood_Jungle_Roots"
    },
    {
      "x": -3,
      "y": 22,
      "z": 5,
      "name": "Wood_Jungle_Trunk_Full"
    },
    {
      "x": -3,
      "y": 35,
      "z": 5,
      "name": "Plant_Leaves_Jungle"
    },
    {
      "x": -3,
      "y": 21,
      "z": 6,
      "name": "Wood_Jungle_Trunk_Full"
    },
    {
      "x": -3,
      "y": 22,
      "z": 6,
      "name": "Wood_Jungle_Trunk_Full"
    },
    {
      "x": -3,
      "y": 25,
      "z": 6,
      "name": "Plant_Leaves_Jungle"
    },
    {
      "x": -3,
      "y": 34,
      "z": 6,
      "name": "Plant_Leaves_Jungle"
    },
    {
      "x": -3,
      "y": 35,
      "z": 6,
      "name": "Plant_Leaves_Jungle"
    },
    {
      "x": -3,
      "y": 21,
      "z": 7,
      "name": "Wood_Jungle_Trunk_Full"
    },
    {
      "x": -3,
      "y": 25,
      "z": 7,
      "name": "Plant_Leaves_Jungle"
    },
    {
      "x": -3,
      "y": 26,
      "z": 7,
      "name": "Plant_Leaves_Jungle"
    },
    {
      "x": -3,
      "y": 30,
      "z": 7,
      "name": "Plant_Leaves_Jungle"
    },
    {
      "x": -3,
      "y": 32,
      "z": 7,
      "name": "Plant_Leaves_Jungle"
    },
    {
      "x": -3,
      "y": 33,
      "z": 7,
      "name": "Plant_Leaves_Jungle"
    },
    {
      "x": -3,
      "y": 34,
      "z": 7,
      "name": "Plant_Leaves_Jungle"
    },
    {
      "x": -3,
      "y": 21,
      "z": 8,
      "name": "Wood_Jungle_Trunk_Full"
    },
    {
      "x": -3,
      "y": 22,
      "z": 8,
      "name": "Wood_Jungle_Branch_Long"
    },
    {
      "x": -3,
      "y": 23,
      "z": 8,
      "name": "Wood_Jungle_Branch_Long"
    },
    {
      "x": -3,
      "y": 24,
      "z": 8,
      "name": "Wood_Jungle_Branch_Long"
    },
    {
      "x": -3,
      "y": 25,
      "z": 8,
      "name": "Plant_Leaves_Jungle"
    },
    {
      "x": -3,
      "y": 26,
      "z": 8,
      "name": "Plant_Leaves_Jungle"
    },
    {
      "x": -3,
      "y": 21,
      "z": 9,
      "name": "Wood_Jungle_Trunk_Full"
    },
    {
      "x": -3,
      "y": 22,
      "z": 9,
      "name": "Wood_Jungle_Branch_Long"
    },
    {
      "x": -3,
      "y": 23,
      "z": 9,
      "name": "Wood_Jungle_Branch_Corner",
      "rotation": 8
    },
    {
      "x": -3,
      "y": 25,
      "z": 9,
      "name": "Plant_Leaves_Jungle"
    },
    {
      "x": -3,
      "y": 26,
      "z": 9,
      "name": "Plant_Leaves_Jungle"
    },
    {
      "x": -3,
      "y": 21,
      "z": 10,
      "name": "Wood_Jungle_Branch_Long",
      "rotation": 4
    },
    {
      "x": -3,
      "y": 23,
      "z": 10,
      "name": "Wood_Jungle_Branch_Corner"
    },
    {
      "x": -3,
      "y": 24,
      "z": 10,
      "name": "Plant_Leaves_Jungle"
    },
    {
      "x": -3,
      "y": 25,
      "z": 10,
      "name": "Plant_Leaves_Jungle"
    },
    {
      "x": -3,
      "y": 26,
      "z": 10,
      "name": "Plant_Leaves_Jungle"
    },
    {
      "x": -3,
      "y": 21,
      "z": 11,
      "name": "Wood_Jungle_Branch_Long",
      "rotation": 4
    },
    {
      "x": -3,
      "y": 24,
      "z": 11,
      "name": "Plant_Leaves_Jungle"
    },
    {
      "x": -3,
      "y": 25,
      "z": 11,
      "name": "Plant_Leaves_Jungle"
    },
    {
      "x": -3,
      "y": 21,
      "z": 12,
      "name": "Wood_Jungle_Branch_Long",
      "rotation": 4
    },
    {
      "x": -3,
      "y": 24,
      "z": 12,
      "name": "Plant_Leaves_Jungle"
    },
    {
      "x": -3,
      "y": 25,
      "z": 12,
      "name": "Plant_Leaves_Jungle"
    },
    {
      "x": -3,
      "y": 21,
      "z": 13,
      "name": "Plant_Leaves_Jungle"
    },
    {
      "x": -3,
      "y": 22,
      "z": 13,
      "name": "Plant_Leaves_Jungle"
    },
    {
      "x": -3,
      "y": 24,
      "z": 13,
      "name": "Plant_Leaves_Jungle"
    },
    {
      "x": -3,
      "y": 19,
      "z": 14,
      "name": "Plant_Leaves_Jungle"
    },
    {
      "x": -3,
      "y": 20,
      "z": 14,
      "name": "Plant_Leaves_Jungle"
    },
    {
      "x": -3,
      "y": 21,
      "z": 14,
      "name": "Plant_Leaves_Jungle"
    },
    {
      "x": -2,
      "y": 31,
      "z": -9,
      "name": "Plant_Leaves_Jungle"
    },
    {
      "x": -2,
      "y": 32,
      "z": -9,
      "name": "Plant_Leaves_Jungle"
    },
    {
      "x": -2,
      "y": 28,
      "z": -8,
      "name": "Plant_Leaves_Jungle"
    },
    {
      "x": -2,
      "y": 32,
      "z": -8,
      "name": "Plant_Leaves_Jungle"
    },
    {
      "x": -2,
      "y": 33,
      "z": -8,
      "name": "Plant_Leaves_Jungle"
    },
    {
      "x": -2,
      "y": 31,
      "z": -7,
      "name": "Wood_Jungle_Branch_Corner",
      "rotation": 2
    },
    {
      "x": -2,
      "y": 32,
      "z": -7,
      "name": "Wood_Jungle_Branch_Long"
    },
    {
      "x": -2,
      "y": 33,
      "z": -7,
      "name": "Plant_Leaves_Jungle"
    },
    {
      "x": -2,
      "y": 34,
      "z": -7,
      "name": "Plant_Leaves_Jungle"
    },
    {
      "x": -2,
      "y": 31,
      "z": -6,
      "name": "Wood_Jungle_Branch_Long",
      "rotation": 4
    },
    {
      "x": -2,
      "y": 34,
      "z": -6,
      "name": "Plant_Leaves_Jungle"
    },
    {
      "x": -2,
      "y": 29,
      "z": -5,
      "name": "Wood_Jungle_Trunk_Full"
    },
    {
      "x": -2,
      "y": 30,
      "z": -5,
      "name": "Wood_Jungle_Trunk"
    },
    {
      "x": -2,
      "y": 31,
      "z": -5,
      "name": "Wood_Jungle_Trunk_Full"
    },
    {
      "x": -2,
      "y": 32,
      "z": -5,
      "name": "Wood_Jungle_Branch_Long"
    },
    {
      "x": -2,
      "y": 33,
      "z": -5,
      "name": "Wood_Jungle_Branch_Long"
    },
    {
      "x": -2,
      "y": 34,
      "z": -5,
      "name": "Plant_Leaves_Jungle"
    },
    {
      "x": -2,
      "y": 29,
      "z": -4,
      "name": "Wood_Jungle_Trunk_Full"
    },
    {
      "x": -2,
      "y": 34,
      "z": -4,
      "name": "Plant_Leaves_Jungle"
    },
    {
      "x": -2,
      "y": 31,
      "z": -3,
      "name": "Plant_Leaves_Jungle"
    },
    {
      "x": -2,
      "y": 33,
      "z": -3,
      "name": "Plant_Leaves_Jungle"
    },
    {
      "x": -2,
      "y": 10,
      "z": -2,
      "name": "Wood_Jungle_Trunk"
    },
    {
      "x": -2,
      "y": 11,
      "z": -2,
      "name": "Wood_Jungle_Trunk"
    },
    {
      "x": -2,
      "y": 12,
      "z": -2,
      "name": "Wood_Jungle_Trunk_Full"
    },
    {
      "x": -2,
      "y": 13,
      "z": -2,
      "name": "Wood_Jungle_Branch_Long"
    },
    {
      "x": -2,
      "y": 14,
      "z": -2,
      "name": "Wood_Jungle_Branch_Long"
    },
    {
      "x": -2,
      "y": 15,
      "z": -2,
      "name": "Wood_Jungle_Branch_Corner",
      "rotation": 8
    },
    {
      "x": -2,
      "y": 23,
      "z": -2,
      "name": "Wood_Jungle_Trunk_Full"
    },
    {
      "x": -2,
      "y": 33,
      "z": -2,
      "name": "Plant_Leaves_Jungle"
    },
    {
      "x": -2,
      "y": 10,
      "z": -1,
      "name": "Wood_Jungle_Trunk"
    },
    {
      "x": -2,
      "y": 11,
      "z": -1,
      "name": "Wood_Jungle_Trunk"
    },
    {
      "x": -2,
      "y": 12,
      "z": -1,
      "name": "Wood_Jungle_Trunk"
    },
    {
      "x": -2,
      "y": 13,
      "z": -1,
      "name": "Wood_Jungle_Trunk"
    },
    {
      "x": -2,
      "y": 14,
      "z": -1,
      "name": "Wood_Jungle_Trunk"
    },
    {
      "x": -2,
      "y": 15,
      "z": -1,
      "name": "Wood_Jungle_Trunk_Full"
    },
    {
      "x": -2,
      "y": 16,
      "z": -1,
      "name": "Wood_Jungle_Branch_Long"
    },
    {
      "x": -2,
      "y": 17,
      "z": -1,
      "name": "Wood_Jungle_Branch_Corner",
      "rotation": 11
    },
    {
      "x": -2,
      "y": 22,
      "z": -1,
      "name": "Wood_Jungle_Trunk_Full"
    },
    {
      "x": -2,
      "y": 23,
      "z": -1,
      "name": "Wood_Jungle_Trunk_Full"
    },
    {
      "x": -2,
      "y": 24,
      "z": -1,
      "name": "Wood_Jungle_Trunk_Full"
    },
    {
      "x": -2,
      "y": 25,
      "z": -1,
      "name": "Wood_Jungle_Trunk_Full"
    },
    {
      "x": -2,
      "y": 26,
      "z": -1,
      "name": "Wood_Jungle_Trunk_Full"
    },
    {
      "x": -2,
      "y": 33,
      "z": -1,
      "name": "Plant_Leaves_Jungle"
    },
    {
      "x": -2,
      "y": 10,
      "z": 0,
      "name": "Wood_Jungle_Trunk"
    },
    {
      "x": -2,
      "y": 11,
      "z": 0,
      "name": "Wood_Jungle_Trunk"
    },
    {
      "x": -2,
      "y": 12,
      "z": 0,
      "name": "Wood_Jungle_Trunk"
    },
    {
      "x": -2,
      "y": 13,
      "z": 0,
      "name": "Wood_Jungle_Trunk"
    },
    {
      "x": -2,
      "y": 14,
      "z": 0,
      "name": "Wood_Jungle_Trunk_Full"
    },
    {
      "x": -2,
      "y": 15,
      "z": 0,
      "name": "Wood_Jungle_Branch_Long"
    },
    {
      "x": -2,
      "y": 16,
      "z": 0,
      "name": "Wood_Jungle_Branch_Long"
    },
    {
      "x": -2,
      "y": 17,
      "z": 0,
      "name": "Wood_Jungle_Branch_Long"
    },
    {
      "x": -2,
      "y": 18,
      "z": 0,
      "name": "Wood_Jungle_Branch_Corner",
      "rotation": 11
    },
    {
      "x": -2,
      "y": 20,
      "z": 0,
      "name": "Wood_Jungle_Trunk_Full"
    },
    {
      "x": -2,
      "y": 23,
      "z": 0,
      "name": "Wood_Jungle_Trunk_Full"
    },
    {
      "x": -2,
      "y": 24,
      "z": 0,
      "name": "Wood_Jungle_Trunk_Full"
    },
    {
      "x": -2,
      "y": 33,
      "z": 0,
      "name": "Plant_Leaves_Jungle"
    },
    {
      "x": -2,
      "y": 35,
      "z": 0,
      "name": "Plant_Leaves_Jungle"
    },
    {
      "x": -2,
      "y": 23,
      "z": 1,
      "name": "Wood_Jungle_Trunk_Full"
    },
    {
      "x": -2,
      "y": 33,
      "z": 1,
      "name": "Plant_Leaves_Jungle"
    },
    {
      "x": -2,
      "y": 36,
      "z": 1,
      "name": "Plant_Leaves_Jungle"
    },
    {
      "x": -2,
      "y": 36,
      "z": 2,
      "name": "Plant_Leaves_Jungle"
    },
    {
      "x": -2,
      "y": 35,
      "z": 3,
      "name": "Plant_Leaves_Jungle"
    },
    {
      "x": -2,
      "y": 35,
      "z": 4,
      "name": "Plant_Leaves_Jungle"
    },
    {
      "x": -2,
      "y": 30,
      "z": 5,
      "name": "Plant_Leaves_Jungle"
    },
    {
      "x": -2,
      "y": 33,
      "z": 5,
      "name": "Plant_Leaves_Jungle"
    },
    {
      "x": -2,
      "y": 34,
      "z": 5,
      "name": "Plant_Leaves_Jungle"
    },
    {
      "x": -2,
      "y": 35,
      "z": 5,
      "name": "Plant_Leaves_Jungle"
    },
    {
      "x": -2,
      "y": 25,
      "z": 6,
      "name": "Plant_Leaves_Jungle"
    },
    {
      "x": -2,
      "y": 30,
      "z": 6,
      "name": "Plant_Leaves_Jungle"
    },
    {
      "x": -2,
      "y": 31,
      "z": 6,
      "name": "Plant_Leaves_Jungle"
    },
    {
      "x": -2,
      "y": 33,
      "z": 6,
      "name": "Plant_Leaves_Jungle"
    },
    {
      "x": -2,
      "y": 34,
      "z": 6,
      "name": "Plant_Leaves_Jungle"
    },
    {
      "x": -2,
      "y": 35,
      "z": 6,
      "name": "Plant_Leaves_Jungle"
    },
    {
      "x": -2,
      "y": 25,
      "z": 7,
      "name": "Plant_Leaves_Jungle"
    },
    {
      "x": -2,
      "y": 30,
      "z": 7,
      "name": "Plant_Leaves_Jungle"
    },
    {
      "x": -2,
      "y": 31,
      "z": 7,
      "name": "Plant_Leaves_Jungle"
    },
    {
      "x": -2,
      "y": 33,
      "z": 7,
      "name": "Plant_Leaves_Jungle"
    },
    {
      "x": -2,
      "y": 25,
      "z": 8,
      "name": "Plant_Leaves_Jungle"
    },
    {
      "x": -2,
      "y": 30,
      "z": 8,
      "name": "Plant_Leaves_Jungle"
    },
    {
      "x": -2,
      "y": 21,
      "z": 9,
      "name": "Wood_Jungle_Branch_Long",
      "rotation": 5
    },
    {
      "x": -2,
      "y": 25,
      "z": 10,
      "name": "Plant_Leaves_Jungle"
    },
    {
      "x": -2,
      "y": 21,
      "z": 12,
      "name": "Plant_Leaves_Jungle"
    },
    {
      "x": -2,
      "y": 24,
      "z": 12,
      "name": "Plant_Leaves_Jungle"
    },
    {
      "x": -2,
      "y": 21,
      "z": 13,
      "name": "Plant_Leaves_Jungle"
    },
    {
      "x": -2,
      "y": 22,
      "z": 13,
      "name": "Plant_Leaves_Jungle"
    },
    {
      "x": -2,
      "y": 23,
      "z": 13,
      "name": "Plant_Leaves_Jungle"
    },
    {
      "x": -2,
      "y": 24,
      "z": 13,
      "name": "Plant_Leaves_Jungle"
    },
    {
      "x": -2,
      "y": 21,
      "z": 14,
      "name": "Plant_Leaves_Jungle"
    },
    {
      "x": -1,
      "y": 30,
      "z": -9,
      "name": "Plant_Leaves_Jungle"
    },
    {
      "x": -1,
      "y": 31,
      "z": -9,
      "name": "Plant_Leaves_Jungle"
    },
    {
      "x": -1,
      "y": 31,
      "z": -8,
      "name": "Plant_Leaves_Jungle"
    },
    {
      "x": -1,
      "y": 32,
      "z": -8,
      "name": "Plant_Leaves_Jungle"
    },
    {
      "x": -1,
      "y": 33,
      "z": -8,
      "name": "Plant_Leaves_Jungle"
    },
    {
      "x": -1,
      "y": 34,
      "z": -7,
      "name": "Plant_Leaves_Jungle"
    },
    {
      "x": -1,
      "y": 34,
      "z": -6,
      "name": "Plant_Leaves_Jungle"
    },
    {
      "x": -1,
      "y": 34,
      "z": -5,
      "name": "Plant_Leaves_Jungle"
    },
    {
      "x": -1,
      "y": 31,
      "z": -4,
      "name": "Plant_Leaves_Jungle"
    },
    {
      "x": -1,
      "y": 30,
      "z": -3,
      "name": "Plant_Leaves_Jungle"
    },
    {
      "x": -1,
      "y": 31,
      "z": -3,
      "name": "Plant_Leaves_Jungle"
    },
    {
      "x": -1,
      "y": 32,
      "z": -3,
      "name": "Plant_Leaves_Jungle"
    },
    {
      "x": -1,
      "y": 33,
      "z": -3,
      "name": "Plant_Leaves_Jungle"
    },
    {
      "x": -1,
      "y": 23,
      "z": -2,
      "name": "Wood_Jungle_Trunk_Full"
    },
    {
      "x": -1,
      "y": 33,
      "z": -2,
      "name": "Plant_Leaves_Jungle"
    },
    {
      "x": -1,
      "y": 10,
      "z": -1,
      "name": "Wood_Jungle_Branch_Long"
    },
    {
      "x": -1,
      "y": 11,
      "z": -1,
      "name": "Wood_Jungle_Branch_Long"
    },
    {
      "x": -1,
      "y": 12,
      "z": -1,
      "name": "Wood_Jungle_Branch_Long"
    },
    {
      "x": -1,
      "y": 13,
      "z": -1,
      "name": "Wood_Jungle_Branch_Long"
    },
    {
      "x": -1,
      "y": 14,
      "z": -1,
      "name": "Wood_Jungle_Branch_Long"
    },
    {
      "x": -1,
      "y": 15,
      "z": -1,
      "name": "Wood_Jungle_Branch_Corner",
      "rotation": 11
    },
    {
      "x": -1,
      "y": 26,
      "z": -1,
      "name": "Wood_Jungle_Trunk_Full"
    },
    {
      "x": -1,
      "y": 27,
      "z": -1,
      "name": "Wood_Jungle_Trunk_Full"
    },
    {
      "x": -1,
      "y": 28,
      "z": -1,
      "name": "Wood_Jungle_Trunk_Full"
    },
    {
      "x": -1,
      "y": 34,
      "z": -1,
      "name": "Plant_Leaves_Jungle"
    },
    {
      "x": -1,
      "y": 10,
      "z": 0,
      "name": "Wood_Jungle_Branch_Long"
    },
    {
      "x": -1,
      "y": 11,
      "z": 0,
      "name": "Wood_Jungle_Branch_Long"
    },
    {
      "x": -1,
      "y": 12,
      "z": 0,
      "name": "Wood_Jungle_Branch_Long"
    },
    {
      "x": -1,
      "y": 13,
      "z": 0,
      "name": "Wood_Jungle_Branch_Long"
    },
    {
      "x": -1,
      "y": 14,
      "z": 0,
      "name": "Wood_Jungle_Branch_Corner",
      "rotation": 11
    },
    {
      "x": -1,
      "y": 20,
      "z": 0,
      "name": "Wood_Jungle_Trunk_Full"
    },
    {
      "x": -1,
      "y": 24,
      "z": 0,
      "name": "Wood_Jungle_Trunk_Full"
    },
    {
      "x": -1,
      "y": 25,
      "z": 0,
      "name": "Wood_Jungle_Trunk_Full"
    },
    {
      "x": -1,
      "y": 33,
      "z": 0,
      "name": "Plant_Leaves_Jungle"
    },
    {
      "x": -1,
      "y": 35,
      "z": 0,
      "name": "Plant_Leaves_Jungle"
    },
    {
      "x": -1,
      "y": 23,
      "z": 1,
      "name": "Wood_Jungle_Trunk_Full"
    },
    {
      "x": -1,
      "y": 24,
      "z": 1,
      "name": "Wood_Jungle_Trunk_Full"
    },
    {
      "x": -1,
      "y": 25,
      "z": 1,
      "name": "Wood_Jungle_Trunk_Full"
    },
    {
      "x": -1,
      "y": 26,
      "z": 1,
      "name": "Wood_Jungle_Trunk_Full"
    },
    {
      "x": -1,
      "y": 33,
      "z": 1,
      "name": "Plant_Leaves_Jungle"
    },
    {
      "x": -1,
      "y": 35,
      "z": 1,
      "name": "Plant_Leaves_Jungle"
    },
    {
      "x": -1,
      "y": 26,
      "z": 2,
      "name": "Wood_Jungle_Trunk_Full"
    },
    {
      "x": -1,
      "y": 27,
      "z": 2,
      "name": "Wood_Jungle_Trunk_Full"
    },
    {
      "x": -1,
      "y": 33,
      "z": 2,
      "name": "Plant_Leaves_Jungle"
    },
    {
      "x": -1,
      "y": 26,
      "z": 3,
      "name": "Wood_Jungle_Trunk_Full"
    },
    {
      "x": -1,
      "y": 27,
      "z": 3,
      "name": "Wood_Jungle_Trunk_Full"
    },
    {
      "x": -1,
      "y": 32,
      "z": 3,
      "name": "Plant_Leaves_Jungle"
    },
    {
      "x": -1,
      "y": 33,
      "z": 3,
      "name": "Plant_Leaves_Jungle"
    },
    {
      "x": -1,
      "y": 34,
      "z": 3,
      "name": "Plant_Leaves_Jungle"
    },
    {
      "x": -1,
      "y": 35,
      "z": 3,
      "name": "Plant_Leaves_Jungle"
    },
    {
      "x": -1,
      "y": 33,
      "z": 4,
      "name": "Plant_Leaves_Jungle"
    },
    {
      "x": -1,
      "y": 34,
      "z": 4,
      "name": "Plant_Leaves_Jungle"
    },
    {
      "x": -1,
      "y": 35,
      "z": 4,
      "name": "Plant_Leaves_Jungle"
    },
    {
      "x": -1,
      "y": 25,
      "z": 5,
      "name": "Plant_Leaves_Jungle"
    },
    {
      "x": -1,
      "y": 33,
      "z": 5,
      "name": "Plant_Leaves_Jungle"
    },
    {
      "x": -1,
      "y": 34,
      "z": 5,
      "name": "Plant_Leaves_Jungle"
    },
    {
      "x": -1,
      "y": 25,
      "z": 6,
      "name": "Plant_Leaves_Jungle"
    },
    {
      "x": -1,
      "y": 30,
      "z": 6,
      "name": "Plant_Leaves_Jungle"
    },
    {
      "x": -1,
      "y": 31,
      "z": 6,
      "name": "Plant_Leaves_Jungle"
    },
    {
      "x": -1,
      "y": 32,
      "z": 6,
      "name": "Plant_Leaves_Jungle"
    },
    {
      "x": -1,
      "y": 33,
      "z": 6,
      "name": "Plant_Leaves_Jungle"
    },
    {
      "x": -1,
      "y": 25,
      "z": 7,
      "name": "Plant_Leaves_Jungle"
    },
    {
      "x": -1,
      "y": 32,
      "z": 7,
      "name": "Plant_Leaves_Jungle"
    },
    {
      "x": -1,
      "y": 25,
      "z": 8,
      "name": "Plant_Leaves_Jungle"
    },
    {
      "x": -1,
      "y": 30,
      "z": 8,
      "name": "Plant_Leaves_Jungle"
    },
    {
      "x": -1,
      "y": 31,
      "z": 8,
      "name": "Plant_Leaves_Jungle"
    },
    {
      "x": -1,
      "y": 21,
      "z": 9,
      "name": "Wood_Jungle_Branch_Long",
      "rotation": 5
    },
    {
      "x": -1,
      "y": 30,
      "z": 9,
      "name": "Plant_Leaves_Jungle"
    },
    {
      "x": -1,
      "y": 21,
      "z": 11,
      "name": "Plant_Leaves_Jungle"
    },
    {
      "x": -1,
      "y": 23,
      "z": 11,
      "name": "Plant_Leaves_Jungle"
    },
    {
      "x": -1,
      "y": 24,
      "z": 11,
      "name": "Plant_Leaves_Jungle"
    },
    {
      "x": -1,
      "y": 21,
      "z": 12,
      "name": "Plant_Leaves_Jungle"
    },
    {
      "x": -1,
      "y": 23,
      "z": 12,
      "name": "Plant_Leaves_Jungle"
    },
    {
      "x": -1,
      "y": 24,
      "z": 12,
      "name": "Plant_Leaves_Jungle"
    },
    {
      "x": -1,
      "y": 21,
      "z": 13,
      "name": "Plant_Leaves_Jungle"
    },
    {
      "x": -1,
      "y": 22,
      "z": 13,
      "name": "Plant_Leaves_Jungle"
    },
    {
      "x": 0,
      "y": 31,
      "z": -8,
      "name": "Plant_Leaves_Jungle"
    },
    {
      "x": 0,
      "y": 32,
      "z": -7,
      "name": "Plant_Leaves_Jungle"
    },
    {
      "x": 0,
      "y": 33,
      "z": -7,
      "name": "Plant_Leaves_Jungle"
    },
    {
      "x": 0,
      "y": 32,
      "z": -6,
      "name": "Plant_Leaves_Jungle"
    },
    {
      "x": 0,
      "y": 33,
      "z": -6,
      "name": "Plant_Leaves_Jungle"
    },
    {
      "x": 0,
      "y": 34,
      "z": -6,
      "name": "Plant_Leaves_Jungle"
    },
    {
      "x": 0,
      "y": 33,
      "z": -5,
      "name": "Plant_Leaves_Jungle"
    },
    {
      "x": 0,
      "y": 30,
      "z": -4,
      "name": "Plant_Leaves_Jungle"
    },
    {
      "x": 0,
      "y": 32,
      "z": -4,
      "name": "Plant_Leaves_Jungle"
    },
    {
      "x": 0,
      "y": 33,
      "z": -4,
      "name": "Plant_Leaves_Jungle"
    },
    {
      "x": 0,
      "y": 32,
      "z": -3,
      "name": "Plant_Leaves_Jungle"
    },
    {
      "x": 0,
      "y": 33,
      "z": -3,
      "name": "Plant_Leaves_Jungle"
    },
    {
      "x": 0,
      "y": 23,
      "z": -2,
      "name": "Wood_Jungle_Trunk_Full"
    },
    {
      "x": 0,
      "y": 24,
      "z": -2,
      "name": "Wood_Jungle_Trunk_Full"
    },
    {
      "x": 0,
      "y": 34,
      "z": -2,
      "name": "Plant_Leaves_Jungle"
    },
    {
      "x": 0,
      "y": 26,
      "z": -1,
      "name": "Wood_Jungle_Roots"
    },
    {
      "x": 0,
      "y": 27,
      "z": -1,
      "name": "Wood_Jungle_Trunk_Full"
    },
    {
      "x": 0,
      "y": 28,
      "z": -1,
      "name": "Wood_Jungle_Trunk_Full"
    },
    {
      "x": 0,
      "y": 29,
      "z": -1,
      "name": "Wood_Jungle_Trunk_Full"
    },
    {
      "x": 0,
      "y": 34,
      "z": -1,
      "name": "Plant_Leaves_Jungle"
    },
    {
      "x": 0,
      "y": 20,
      "z": 0,
      "name": "Wood_Jungle_Trunk_Full"
    },
    {
      "x": 0,
      "y": 29,
      "z": 0,
      "name": "Wood_Jungle_Trunk_Full"
    },
    {
      "x": 0,
      "y": 34,
      "z": 0,
      "name": "Plant_Leaves_Jungle"
    },
    {
      "x": 0,
      "y": 20,
      "z": 1,
      "name": "Wood_Jungle_Trunk_Full"
    },
    {
      "x": 0,
      "y": 33,
      "z": 2,
      "name": "Plant_Leaves_Jungle"
    },
    {
      "x": 0,
      "y": 27,
      "z": 3,
      "name": "Wood_Jungle_Trunk_Full"
    },
    {
      "x": 0,
      "y": 32,
      "z": 3,
      "name": "Plant_Leaves_Jungle"
    },
    {
      "x": 0,
      "y": 33,
      "z": 3,
      "name": "Plant_Leaves_Jungle"
    },
    {
      "x": 0,
      "y": 26,
      "z": 4,
      "name": "Wood_Jungle_Roots"
    },
    {
      "x": 0,
      "y": 27,
      "z": 4,
      "name": "Wood_Jungle_Trunk_Full"
    },
    {
      "x": 0,
      "y": 28,
      "z": 4,
      "name": "Wood_Jungle_Trunk_Full"
    },
    {
      "x": 0,
      "y": 31,
      "z": 4,
      "name": "Plant_Leaves_Jungle"
    },
    {
      "x": 0,
      "y": 32,
      "z": 4,
      "name": "Plant_Leaves_Jungle"
    },
    {
      "x": 0,
      "y": 33,
      "z": 4,
      "name": "Plant_Leaves_Jungle"
    },
    {
      "x": 0,
      "y": 28,
      "z": 5,
      "name": "Wood_Jungle_Trunk_Full"
    },
    {
      "x": 0,
      "y": 32,
      "z": 5,
      "name": "Plant_Leaves_Jungle"
    },
    {
      "x": 0,
      "y": 32,
      "z": 6,
      "name": "Plant_Leaves_Jungle"
    },
    {
      "x": 0,
      "y": 25,
      "z": 7,
      "name": "Plant_Leaves_Jungle"
    },
    {
      "x": 0,
      "y": 22,
      "z": 8,
      "name": "Plant_Leaves_Jungle"
    },
    {
      "x": 0,
      "y": 30,
      "z": 8,
      "name": "Plant_Leaves_Jungle"
    },
    {
      "x": 0,
      "y": 31,
      "z": 8,
      "name": "Plant_Leaves_Jungle"
    },
    {
      "x": 0,
      "y": 21,
      "z": 9,
      "name": "Wood_Jungle_Branch_Corner",
      "rotation": 1
    },
    {
      "x": 0,
      "y": 22,
      "z": 9,
      "name": "Plant_Leaves_Jungle"
    },
    {
      "x": 0,
      "y": 24,
      "z": 9,
      "name": "Plant_Leaves_Jungle"
    },
    {
      "x": 0,
      "y": 30,
      "z": 9,
      "name": "Plant_Leaves_Jungle"
    },
    {
      "x": 0,
      "y": 31,
      "z": 9,
      "name": "Plant_Leaves_Jungle"
    },
    {
      "x": 0,
      "y": 21,
      "z": 10,
      "name": "Plant_Leaves_Jungle"
    },
    {
      "x": 0,
      "y": 24,
      "z": 10,
      "name": "Plant_Leaves_Jungle"
    },
    {
      "x": 0,
      "y": 30,
      "z": 10,
      "name": "Plant_Leaves_Jungle"
    },
    {
      "x": 0,
      "y": 21,
      "z": 11,
      "name": "Plant_Leaves_Jungle"
    },
    {
      "x": 0,
      "y": 22,
      "z": 11,
      "name": "Plant_Leaves_Jungle"
    },
    {
      "x": 0,
      "y": 29,
      "z": 11,
      "name": "Plant_Leaves_Jungle"
    },
    {
      "x": 0,
      "y": 20,
      "z": 12,
      "name": "Plant_Leaves_Jungle"
    },
    {
      "x": 0,
      "y": 21,
      "z": 12,
      "name": "Plant_Leaves_Jungle"
    },
    {
      "x": 0,
      "y": 21,
      "z": 13,
      "name": "Plant_Leaves_Jungle"
    },
    {
      "x": 1,
      "y": 31,
      "z": -7,
      "name": "Plant_Leaves_Jungle"
    },
    {
      "x": 1,
      "y": 29,
      "z": -6,
      "name": "Plant_Leaves_Jungle"
    },
    {
      "x": 1,
      "y": 30,
      "z": -6,
      "name": "Plant_Leaves_Jungle"
    },
    {
      "x": 1,
      "y": 31,
      "z": -6,
      "name": "Plant_Leaves_Jungle"
    },
    {
      "x": 1,
      "y": 32,
      "z": -6,
      "name": "Plant_Leaves_Jungle"
    },
    {
      "x": 1,
      "y": 33,
      "z": -5,
      "name": "Plant_Leaves_Jungle"
    },
    {
      "x": 1,
      "y": 30,
      "z": -4,
      "name": "Plant_Leaves_Jungle"
    },
    {
      "x": 1,
      "y": 31,
      "z": -4,
      "name": "Plant_Leaves_Jungle"
    },
    {
      "x": 1,
      "y": 32,
      "z": -4,
      "name": "Plant_Leaves_Jungle"
    },
    {
      "x": 1,
      "y": 33,
      "z": -4,
      "name": "Plant_Leaves_Jungle"
    },
    {
      "x": 1,
      "y": 24,
      "z": -3,
      "name": "Wood_Jungle_Trunk_Full"
    },
    {
      "x": 1,
      "y": 30,
      "z": -3,
      "name": "Wood_Jungle_Branch_Corner",
      "rotation": 2
    },
    {
      "x": 1,
      "y": 31,
      "z": -3,
      "name": "Wood_Jungle_Branch_Long"
    },
    {
      "x": 1,
      "y": 32,
      "z": -3,
      "name": "Plant_Leaves_Jungle"
    },
    {
      "x": 1,
      "y": 33,
      "z": -3,
      "name": "Plant_Leaves_Jungle"
    },
    {
      "x": 1,
      "y": 24,
      "z": -2,
      "name": "Wood_Jungle_Trunk_Full"
    },
    {
      "x": 1,
      "y": 30,
      "z": -2,
      "name": "Wood_Jungle_Branch_Long",
      "rotation": 4
    },
    {
      "x": 1,
      "y": 34,
      "z": -2,
      "name": "Plant_Leaves_Jungle"
    },
    {
      "x": 1,
      "y": 30,
      "z": -1,
      "name": "Wood_Jungle_Branch_Long",
      "rotation": 4
    },
    {
      "x": 1,
      "y": 29,
      "z": 0,
      "name": "Wood_Jungle_Trunk_Full"
    },
    {
      "x": 1,
      "y": 30,
      "z": 0,
      "name": "Wood_Jungle_Trunk"
    },
    {
      "x": 1,
      "y": 31,
      "z": 0,
      "name": "Wood_Jungle_Trunk_Full"
    },
    {
      "x": 1,
      "y": 32,
      "z": 0,
      "name": "Wood_Jungle_Branch_Long"
    },
    {
      "x": 1,
      "y": 33,
      "z": 0,
      "name": "Wood_Jungle_Branch_Long"
    },
    {
      "x": 1,
      "y": 34,
      "z": 0,
      "name": "Plant_Leaves_Jungle"
    },
    {
      "x": 1,
      "y": 20,
      "z": 1,
      "name": "Wood_Jungle_Trunk_Full"
    },
    {
      "x": 1,
      "y": 34,
      "z": 1,
      "name": "Plant_Leaves_Jungle"
    },
    {
      "x": 1,
      "y": 33,
      "z": 2,
      "name": "Plant_Leaves_Jungle"
    },
    {
      "x": 1,
      "y": 33,
      "z": 3,
      "name": "Plant_Leaves_Jungle"
    },
    {
      "x": 1,
      "y": 28,
      "z": 5,
      "name": "Wood_Jungle_Trunk_Full"
    },
    {
      "x": 1,
      "y": 32,
      "z": 5,
      "name": "Plant_Leaves_Jungle"
    },
    {
      "x": 1,
      "y": 27,
      "z": 6,
      "name": "Wood_Jungle_Roots"
    },
    {
      "x": 1,
      "y": 28,
      "z": 6,
      "name": "Wood_Jungle_Trunk_Full"
    },
    {
      "x": 1,
      "y": 29,
      "z": 6,
      "name": "Wood_Jungle_Branch_Long"
    },
    {
      "x": 1,
      "y": 30,
      "z": 6,
      "name": "Wood_Jungle_Branch_Long"
    },
    {
      "x": 1,
      "y": 31,
      "z": 6,
      "name": "Wood_Jungle_Branch_Long"
    },
    {
      "x": 1,
      "y": 32,
      "z": 6,
      "name": "Plant_Leaves_Jungle"
    },
    {
      "x": 1,
      "y": 21,
      "z": 7,
      "name": "Plant_Leaves_Jungle"
    },
    {
      "x": 1,
      "y": 21,
      "z": 8,
      "name": "Plant_Leaves_Jungle"
    },
    {
      "x": 1,
      "y": 22,
      "z": 8,
      "name": "Plant_Leaves_Jungle"
    },
    {
      "x": 1,
      "y": 32,
      "z": 8,
      "name": "Plant_Leaves_Jungle"
    },
    {
      "x": 1,
      "y": 21,
      "z": 9,
      "name": "Plant_Leaves_Jungle"
    },
    {
      "x": 1,
      "y": 22,
      "z": 9,
      "name": "Plant_Leaves_Jungle"
    },
    {
      "x": 1,
      "y": 23,
      "z": 9,
      "name": "Plant_Leaves_Jungle"
    },
    {
      "x": 1,
      "y": 30,
      "z": 9,
      "name": "Plant_Leaves_Jungle"
    },
    {
      "x": 1,
      "y": 31,
      "z": 9,
      "name": "Plant_Leaves_Jungle"
    },
    {
      "x": 1,
      "y": 21,
      "z": 10,
      "name": "Plant_Leaves_Jungle"
    },
    {
      "x": 1,
      "y": 29,
      "z": 10,
      "name": "Plant_Leaves_Jungle"
    },
    {
      "x": 1,
      "y": 30,
      "z": 10,
      "name": "Plant_Leaves_Jungle"
    },
    {
      "x": 1,
      "y": 31,
      "z": 10,
      "name": "Plant_Leaves_Jungle"
    },
    {
      "x": 1,
      "y": 20,
      "z": 11,
      "name": "Plant_Leaves_Jungle"
    },
    {
      "x": 1,
      "y": 21,
      "z": 11,
      "name": "Plant_Leaves_Jungle"
    },
    {
      "x": 1,
      "y": 22,
      "z": 11,
      "name": "Plant_Leaves_Jungle"
    },
    {
      "x": 1,
      "y": 23,
      "z": 11,
      "name": "Plant_Leaves_Jungle"
    },
    {
      "x": 1,
      "y": 28,
      "z": 11,
      "name": "Plant_Leaves_Jungle"
    },
    {
      "x": 1,
      "y": 29,
      "z": 11,
      "name": "Plant_Leaves_Jungle"
    },
    {
      "x": 1,
      "y": 19,
      "z": 12,
      "name": "Plant_Leaves_Jungle"
    },
    {
      "x": 1,
      "y": 20,
      "z": 12,
      "name": "Plant_Leaves_Jungle"
    },
    {
      "x": 1,
      "y": 22,
      "z": 12,
      "name": "Plant_Leaves_Jungle"
    },
    {
      "x": 2,
      "y": 25,
      "z": -6,
      "name": "Plant_Leaves_Jungle"
    },
    {
      "x": 2,
      "y": 26,
      "z": -5,
      "name": "Plant_Leaves_Jungle"
    },
    {
      "x": 2,
      "y": 29,
      "z": -4,
      "name": "Plant_Leaves_Jungle"
    },
    {
      "x": 2,
      "y": 30,
      "z": -4,
      "name": "Plant_Leaves_Jungle"
    },
    {
      "x": 2,
      "y": 31,
      "z": -4,
      "name": "Plant_Leaves_Jungle"
    },
    {
      "x": 2,
      "y": 32,
      "z": -4,
      "name": "Plant_Leaves_Jungle"
    },
    {
      "x": 2,
      "y": 24,
      "z": -3,
      "name": "Wood_Jungle_Trunk_Full"
    },
    {
      "x": 2,
      "y": 25,
      "z": -3,
      "name": "Wood_Jungle_Trunk_Full"
    },
    {
      "x": 2,
      "y": 33,
      "z": -3,
      "name": "Plant_Leaves_Jungle"
    },
    {
      "x": 2,
      "y": 34,
      "z": -2,
      "name": "Plant_Leaves_Jungle"
    },
    {
      "x": 2,
      "y": 33,
      "z": -1,
      "name": "Plant_Leaves_Jungle"
    },
    {
      "x": 2,
      "y": 34,
      "z": -1,
      "name": "Plant_Leaves_Jungle"
    },
    {
      "x": 2,
      "y": 31,
      "z": 0,
      "name": "Wood_Jungle_Branch_Long",
      "rotation": 5
    },
    {
      "x": 2,
      "y": 34,
      "z": 0,
      "name": "Plant_Leaves_Jungle"
    },
    {
      "x": 2,
      "y": 20,
      "z": 1,
      "name": "Wood_Jungle_Trunk_Full"
    },
    {
      "x": 2,
      "y": 34,
      "z": 1,
      "name": "Plant_Leaves_Jungle"
    },
    {
      "x": 2,
      "y": 32,
      "z": 2,
      "name": "Plant_Leaves_Jungle"
    },
    {
      "x": 2,
      "y": 33,
      "z": 2,
      "name": "Plant_Leaves_Jungle"
    },
    {
      "x": 2,
      "y": 34,
      "z": 2,
      "name": "Plant_Leaves_Jungle"
    },
    {
      "x": 2,
      "y": 29,
      "z": 3,
      "name": "Plant_Leaves_Jungle"
    },
    {
      "x": 2,
      "y": 30,
      "z": 3,
      "name": "Plant_Leaves_Jungle"
    },
    {
      "x": 2,
      "y": 31,
      "z": 3,
      "name": "Plant_Leaves_Jungle"
    },
    {
      "x": 2,
      "y": 32,
      "z": 3,
      "name": "Plant_Leaves_Jungle"
    },
    {
      "x": 2,
      "y": 26,
      "z": 5,
      "name": "Plant_Leaves_Jungle"
    },
    {
      "x": 2,
      "y": 32,
      "z": 5,
      "name": "Plant_Leaves_Jungle"
    },
    {
      "x": 2,
      "y": 28,
      "z": 6,
      "name": "Wood_Jungle_Trunk_Full"
    },
    {
      "x": 2,
      "y": 32,
      "z": 6,
      "name": "Plant_Leaves_Jungle"
    },
    {
      "x": 2,
      "y": 28,
      "z": 7,
      "name": "Wood_Jungle_Trunk_Full"
    },
    {
      "x": 2,
      "y": 31,
      "z": 7,
      "name": "Plant_Leaves_Jungle"
    },
    {
      "x": 2,
      "y": 32,
      "z": 7,
      "name": "Plant_Leaves_Jungle"
    },
    {
      "x": 2,
      "y": 20,
      "z": 8,
      "name": "Plant_Leaves_Jungle"
    },
    {
      "x": 2,
      "y": 21,
      "z": 8,
      "name": "Plant_Leaves_Jungle"
    },
    {
      "x": 2,
      "y": 28,
      "z": 8,
      "name": "Wood_Jungle_Branch_Long",
      "rotation": 4
    },
    {
      "x": 2,
      "y": 31,
      "z": 8,
      "name": "Plant_Leaves_Jungle"
    },
    {
      "x": 2,
      "y": 32,
      "z": 8,
      "name": "Plant_Leaves_Jungle"
    },
    {
      "x": 2,
      "y": 28,
      "z": 9,
      "name": "Wood_Jungle_Branch_Corner"
    },
    {
      "x": 2,
      "y": 29,
      "z": 9,
      "name": "Wood_Jungle_Branch_Long"
    },
    {
      "x": 2,
      "y": 30,
      "z": 9,
      "name": "Wood_Jungle_Branch_Long"
    },
    {
      "x": 2,
      "y": 31,
      "z": 9,
      "name": "Plant_Leaves_Jungle"
    },
    {
      "x": 2,
      "y": 21,
      "z": 10,
      "name": "Plant_Leaves_Jungle"
    },
    {
      "x": 2,
      "y": 29,
      "z": 10,
      "name": "Plant_Leaves_Jungle"
    },
    {
      "x": 2,
      "y": 30,
      "z": 10,
      "name": "Plant_Leaves_Jungle"
    },
    {
      "x": 2,
      "y": 27,
      "z": 11,
      "name": "Plant_Leaves_Jungle"
    },
    {
      "x": 2,
      "y": 28,
      "z": 11,
      "name": "Plant_Leaves_Jungle"
    },
    {
      "x": 2,
      "y": 29,
      "z": 11,
      "name": "Plant_Leaves_Jungle"
    },
    {
      "x": 3,
      "y": 25,
      "z": -7,
      "name": "Plant_Leaves_Jungle"
    },
    {
      "x": 3,
      "y": 25,
      "z": -6,
      "name": "Plant_Leaves_Jungle"
    },
    {
      "x": 3,
      "y": 26,
      "z": -6,
      "name": "Plant_Leaves_Jungle"
    },
    {
      "x": 3,
      "y": 26,
      "z": -5,
      "name": "Plant_Leaves_Jungle"
    },
    {
      "x": 3,
      "y": 30,
      "z": -4,
      "name": "Plant_Leaves_Jungle"
    },
    {
      "x": 3,
      "y": 31,
      "z": -4,
      "name": "Plant_Leaves_Jungle"
    },
    {
      "x": 3,
      "y": 32,
      "z": -4,
      "name": "Plant_Leaves_Jungle"
    },
    {
      "x": 3,
      "y": 24,
      "z": -3,
      "name": "Wood_Jungle_Trunk_Full"
    },
    {
      "x": 3,
      "y": 25,
      "z": -3,
      "name": "Wood_Jungle_Trunk_Full"
    },
    {
      "x": 3,
      "y": 30,
      "z": -3,
      "name": "Plant_Leaves_Jungle"
    },
    {
      "x": 3,
      "y": 31,
      "z": -3,
      "name": "Plant_Leaves_Jungle"
    },
    {
      "x": 3,
      "y": 32,
      "z": -3,
      "name": "Plant_Leaves_Jungle"
    },
    {
      "x": 3,
      "y": 33,
      "z": -3,
      "name": "Plant_Leaves_Jungle"
    },
    {
      "x": 3,
      "y": 31,
      "z": -2,
      "name": "Plant_Leaves_Jungle"
    },
    {
      "x": 3,
      "y": 33,
      "z": -2,
      "name": "Plant_Leaves_Jungle"
    },
    {
      "x": 3,
      "y": 33,
      "z": -1,
      "name": "Plant_Leaves_Jungle"
    },
    {
      "x": 3,
      "y": 34,
      "z": -1,
      "name": "Plant_Leaves_Jungle"
    },
    {
      "x": 3,
      "y": 31,
      "z": 0,
      "name": "Wood_Jungle_Branch_Corner",
      "rotation": 1
    },
    {
      "x": 3,
      "y": 32,
      "z": 0,
      "name": "Wood_Jungle_Branch_Long"
    },
    {
      "x": 3,
      "y": 33,
      "z": 0,
      "name": "Plant_Leaves_Jungle"
    },
    {
      "x": 3,
      "y": 34,
      "z": 0,
      "name": "Plant_Leaves_Jungle"
    },
    {
      "x": 3,
      "y": 20,
      "z": 1,
      "name": "Wood_Jungle_Trunk_Full"
    },
    {
      "x": 3,
      "y": 21,
      "z": 1,
      "name": "Wood_Jungle_Trunk_Full"
    },
    {
      "x": 3,
      "y": 34,
      "z": 1,
      "name": "Plant_Leaves_Jungle"
    },
    {
      "x": 3,
      "y": 21,
      "z": 2,
      "name": "Wood_Jungle_Trunk_Full"
    },
    {
      "x": 3,
      "y": 32,
      "z": 2,
      "name": "Plant_Leaves_Jungle"
    },
    {
      "x": 3,
      "y": 33,
      "z": 2,
      "name": "Plant_Leaves_Jungle"
    },
    {
      "x": 3,
      "y": 31,
      "z": 3,
      "name": "Plant_Leaves_Jungle"
    },
    {
      "x": 3,
      "y": 26,
      "z": 4,
      "name": "Plant_Leaves_Jungle"
    },
    {
      "x": 3,
      "y": 26,
      "z": 5,
      "name": "Plant_Leaves_Jungle"
    },
    {
      "x": 3,
      "y": 26,
      "z": 6,
      "name": "Plant_Leaves_Jungle"
    },
    {
      "x": 3,
      "y": 28,
      "z": 7,
      "name": "Wood_Jungle_Branch_Corner",
      "rotation": 1
    },
    {
      "x": 3,
      "y": 29,
      "z": 7,
      "name": "Wood_Jungle_Branch_Long"
    },
    {
      "x": 3,
      "y": 30,
      "z": 7,
      "name": "Wood_Jungle_Branch_Long"
    },
    {
      "x": 3,
      "y": 31,
      "z": 7,
      "name": "Plant_Leaves_Jungle"
    },
    {
      "x": 3,
      "y": 32,
      "z": 7,
      "name": "Plant_Leaves_Jungle"
    },
    {
      "x": 3,
      "y": 31,
      "z": 8,
      "name": "Plant_Leaves_Jungle"
    },
    {
      "x": 3,
      "y": 30,
      "z": 9,
      "name": "Plant_Leaves_Jungle"
    },
    {
      "x": 3,
      "y": 31,
      "z": 9,
      "name": "Plant_Leaves_Jungle"
    },
    {
      "x": 3,
      "y": 27,
      "z": 10,
      "name": "Plant_Leaves_Jungle"
    },
    {
