{
  "version": 8,
  "blockIdVersion": 8,
  "anchorX": -1,
  "anchorY": 4,
  "anchorZ": -1,
  "blocks": [
    {
      "x": -9,
      "y": 14,
      "z": -4,
      "name": "Plant_Coral_Block_Violet"
    },
    {
      "x": -9,
      "y": 15,
      "z": -4,
      "name": "Plant_Coral_Block_Violet"
    },
    {
      "x": -9,
      "y": 16,
      "z": -4,
      "name": "Plant_Coral_Block_Violet"
    },
    {
      "x": -9,
      "y": 9,
      "z": -3,
      "name": "Plant_Coral_Block_Violet"
    },
    {
      "x": -9,
      "y": 10,
      "z": -3,
      "name": "Plant_Coral_Block_Violet"
    },
    {
      "x": -9,
      "y": 11,
      "z": -3,
      "name": "Plant_Coral_Block_Violet"
    },
    {
      "x": -9,
      "y": 12,
      "z": -3,
      "name": "Plant_Coral_Block_Violet"
    },
    {
      "x": -9,
      "y": 13,
      "z": -3,
      "name": "Plant_Coral_Block_Violet"
    },
    {
      "x": -9,
      "y": 14,
      "z": -3,
      "name": "Plant_Coral_Block_Violet"
    },
    {
      "x": -9,
      "y": 15,
      "z": -3,
      "name": "Plant_Coral_Block_Violet"
    },
    {
      "x": -9,
      "y": 16,
      "z": -3,
      "name": "Plant_Coral_Block_Violet"
    },
    {
      "x": -9,
      "y": 17,
      "z": -3,
      "name": "Plant_Coral_Block_Violet"
    },
    {
      "x": -9,
      "y": 18,
      "z": -3,
      "name": "Plant_Coral_Block_Violet"
    },
    {
      "x": -9,
      "y": 19,
      "z": -3,
      "name": "Plant_Coral_Block_Violet"
    },
    {
      "x": -9,
      "y": 9,
      "z": -2,
      "name": "Plant_Coral_Block_Violet"
    },
    {
      "x": -9,
      "y": 10,
      "z": -2,
      "name": "Plant_Coral_Block_Violet"
    },
    {
      "x": -9,
      "y": 11,
      "z": -2,
      "name": "Plant_Coral_Block_Violet"
    },
    {
      "x": -9,
      "y": 12,
      "z": -2,
      "name": "Plant_Coral_Block_Violet"
    },
    {
      "x": -9,
      "y": 13,
      "z": -2,
      "name": "Plant_Coral_Block_Violet"
    },
    {
      "x": -9,
      "y": 14,
      "z": -2,
      "name": "Plant_Coral_Block_Violet"
    },
    {
      "x": -9,
      "y": 15,
      "z": -2,
      "name": "Plant_Coral_Block_Violet"
    },
    {
      "x": -9,
      "y": 16,
      "z": -2,
      "name": "Plant_Coral_Block_Violet"
    },
    {
      "x": -9,
      "y": 17,
      "z": -2,
      "name": "Plant_Coral_Block_Violet"
    },
    {
      "x": -9,
      "y": 18,
      "z": -2,
      "name": "Plant_Coral_Block_Violet"
    },
    {
      "x": -9,
      "y": 19,
      "z": -2,
      "name": "Plant_Coral_Block_Violet"
    },
    {
      "x": -9,
      "y": 10,
      "z": -1,
      "name": "Plant_Coral_Block_Violet"
    },
    {
      "x": -9,
      "y": 11,
      "z": -1,
      "name": "Plant_Coral_Block_Violet"
    },
    {
      "x": -9,
      "y": 12,
      "z": -1,
      "name": "Plant_Coral_Block_Violet"
    },
    {
      "x": -9,
      "y": 13,
      "z": -1,
      "name": "Plant_Coral_Block_Violet"
    },
    {
      "x": -9,
      "y": 17,
      "z": -1,
      "name": "Plant_Coral_Block_Violet"
    },
    {
      "x": -9,
      "y": 18,
      "z": -1,
      "name": "Plant_Coral_Block_Violet"
    },
    {
      "x": -9,
      "y": 19,
      "z": -1,
      "name": "Plant_Coral_Block_Violet"
    },
    {
      "x": -8,
      "y": 14,
      "z": -5,
      "name": "Plant_Coral_Block_Violet"
    },
    {
      "x": -8,
      "y": 15,
      "z": -5,
      "name": "Plant_Coral_Block_Violet"
    },
    {
      "x": -8,
      "y": 16,
      "z": -5,
      "name": "Plant_Coral_Block_Violet"
    },
    {
      "x": -8,
      "y": 4,
      "z": -4,
      "name": "Plant_Coral_Block_Violet"
    },
    {
      "x": -8,
      "y": 5,
      "z": -4,
      "name": "Plant_Coral_Block_Violet"
    },
    {
      "x": -8,
      "y": 6,
      "z": -4,
      "name": "Plant_Coral_Block_Violet"
    },
    {
      "x": -8,
      "y": 10,
      "z": -4,
      "name": "Plant_Coral_Block_Violet"
    },
    {
      "x": -8,
      "y": 11,
      "z": -4,
      "name": "Plant_Coral_Block_Violet"
    },
    {
      "x": -8,
      "y": 12,
      "z": -4,
      "name": "Plant_Coral_Block_Violet"
    },
    {
      "x": -8,
      "y": 13,
      "z": -4,
      "name": "Plant_Coral_Block_Violet"
    },
    {
      "x": -8,
      "y": 14,
      "z": -4,
      "name": "Rock_Slate"
    },
    {
      "x": -8,
      "y": 15,
      "z": -4,
      "name": "Rock_Slate"
    },
    {
      "x": -8,
      "y": 16,
      "z": -4,
      "name": "Rock_Slate"
    },
    {
      "x": -8,
      "y": 17,
      "z": -4,
      "name": "Plant_Coral_Block_Violet"
    },
    {
      "x": -8,
      "y": 18,
      "z": -4,
      "name": "Plant_Coral_Block_Violet"
    },
    {
      "x": -8,
      "y": 19,
      "z": -4,
      "name": "Plant_Coral_Block_Violet"
    },
    {
      "x": -8,
      "y": 4,
      "z": -3,
      "name": "Plant_Coral_Block_Violet"
    },
    {
      "x": -8,
      "y": 5,
      "z": -3,
      "name": "Plant_Coral_Block_Violet"
    },
    {
      "x": -8,
      "y": 6,
      "z": -3,
      "name": "Plant_Coral_Block_Violet"
    },
    {
      "x": -8,
      "y": 7,
      "z": -3,
      "name": "Plant_Coral_Block_Violet"
    },
    {
      "x": -8,
      "y": 8,
      "z": -3,
      "name": "Plant_Coral_Block_Violet"
    },
    {
      "x": -8,
      "y": 9,
      "z": -3,
      "name": "Plant_Coral_Block_Violet"
    },
    {
      "x": -8,
      "y": 10,
      "z": -3,
      "name": "Rock_Slate"
    },
    {
      "x": -8,
      "y": 11,
      "z": -3,
      "name": "Rock_Slate"
    },
    {
      "x": -8,
      "y": 12,
      "z": -3,
      "name": "Rock_Slate"
    },
    {
      "x": -8,
      "y": 13,
      "z": -3,
      "name": "Rock_Slate"
    },
    {
      "x": -8,
      "y": 14,
      "z": -3,
      "name": "Rock_Slate"
    },
    {
      "x": -8,
      "y": 15,
      "z": -3,
      "name": "Rock_Slate"
    },
    {
      "x": -8,
      "y": 16,
      "z": -3,
      "name": "Rock_Slate"
    },
    {
      "x": -8,
      "y": 17,
      "z": -3,
      "name": "Rock_Slate"
    },
    {
      "x": -8,
      "y": 4,
      "z": -2,
      "name": "Plant_Coral_Block_Violet"
    },
    {
      "x": -8,
      "y": 5,
      "z": -2,
      "name": "Plant_Coral_Block_Violet"
    },
    {
      "x": -8,
      "y": 6,
      "z": -2,
      "name": "Plant_Coral_Block_Violet"
    },
    {
      "x": -8,
      "y": 7,
      "z": -2,
      "name": "Plant_Coral_Block_Violet"
    },
    {
      "x": -8,
      "y": 8,
      "z": -2,
      "name": "Plant_Coral_Block_Violet"
    },
    {
      "x": -8,
      "y": 9,
      "z": -2,
      "name": "Plant_Coral_Block_Violet"
    },
    {
      "x": -8,
      "y": 10,
      "z": -2,
      "name": "Rock_Slate"
    },
    {
      "x": -8,
      "y": 11,
      "z": -2,
      "name": "Rock_Slate"
    },
    {
      "x": -8,
      "y": 12,
      "z": -2,
      "name": "Rock_Slate"
    },
    {
      "x": -8,
      "y": 13,
      "z": -2,
      "name": "Rock_Slate"
    },
    {
      "x": -8,
      "y": 14,
      "z": -2,
      "name": "Rock_Slate"
    },
    {
      "x": -8,
      "y": 15,
      "z": -2,
      "name": "Rock_Slate"
    },
    {
      "x": -8,
      "y": 16,
      "z": -2,
      "name": "Rock_Slate"
    },
    {
      "x": -8,
      "y": 17,
      "z": -2,
      "name": "Rock_Slate"
    },
    {
      "x": -8,
      "y": 7,
      "z": -1,
      "name": "Plant_Coral_Block_Violet"
    },
    {
      "x": -8,
      "y": 8,
      "z": -1,
      "name": "Plant_Coral_Block_Violet"
    },
    {
      "x": -8,
      "y": 9,
      "z": -1,
      "name": "Plant_Coral_Block_Violet"
    },
    {
      "x": -8,
      "y": 10,
      "z": -1,
      "name": "Rock_Slate"
    },
    {
      "x": -8,
      "y": 11,
      "z": -1,
      "name": "Rock_Slate"
    },
    {
      "x": -8,
      "y": 12,
      "z": -1,
      "name": "Rock_Slate"
    },
    {
      "x": -8,
      "y": 13,
      "z": -1,
      "name": "Rock_Slate"
    },
    {
      "x": -8,
      "y": 14,
      "z": -1,
      "name": "Plant_Coral_Block_Violet"
    },
    {
      "x": -8,
      "y": 15,
      "z": -1,
      "name": "Plant_Coral_Block_Violet"
    },
    {
      "x": -8,
      "y": 16,
      "z": -1,
      "name": "Plant_Coral_Block_Violet"
    },
    {
      "x": -8,
      "y": 17,
      "z": -1,
      "name": "Rock_Slate"
    },
    {
      "x": -8,
      "y": 18,
      "z": -1,
      "name": "Rock_Slate"
    },
    {
      "x": -8,
      "y": 10,
      "z": 0,
      "name": "Plant_Coral_Block_Violet"
    },
    {
      "x": -8,
      "y": 11,
      "z": 0,
      "name": "Plant_Coral_Block_Violet"
    },
    {
      "x": -8,
      "y": 12,
      "z": 0,
      "name": "Plant_Coral_Block_Violet"
    },
    {
      "x": -8,
      "y": 13,
      "z": 0,
      "name": "Plant_Coral_Block_Violet"
    },
    {
      "x": -8,
      "y": 14,
      "z": 0,
      "name": "Plant_Coral_Block_Violet"
    },
    {
      "x": -8,
      "y": 15,
      "z": 0,
      "name": "Plant_Coral_Block_Violet"
    },
    {
      "x": -8,
      "y": 16,
      "z": 0,
      "name": "Plant_Coral_Block_Violet"
    },
    {
      "x": -8,
      "y": 17,
      "z": 0,
      "name": "Plant_Coral_Block_Violet"
    },
    {
      "x": -8,
      "y": 18,
      "z": 0,
      "name": "Plant_Coral_Block_Violet"
    },
    {
      "x": -8,
      "y": 19,
      "z": 0,
      "name": "Plant_Coral_Block_Violet"
    },
    {
      "x": -7,
      "y": 4,
      "z": -5,
      "name": "Plant_Coral_Block_Violet"
    },
    {
      "x": -7,
      "y": 5,
      "z": -5,
      "name": "Plant_Coral_Block_Violet"
    },
    {
      "x": -7,
      "y": 6,
      "z": -5,
      "name": "Plant_Coral_Block_Violet"
    },
    {
      "x": -7,
      "y": 7,
      "z": -5,
      "name": "Plant_Coral_Block_Violet"
    },
    {
      "x": -7,
      "y": 13,
      "z": -5,
      "name": "Plant_Coral_Block_Violet"
    },
    {
      "x": -7,
      "y": 14,
      "z": -5,
      "name": "Plant_Coral_Block_Violet"
    },
    {
      "x": -7,
      "y": 15,
      "z": -5,
      "name": "Plant_Coral_Block_Violet"
    },
    {
      "x": -7,
      "y": 16,
      "z": -5,
      "name": "Plant_Coral_Block_Violet"
    },
    {
      "x": -7,
      "y": 17,
      "z": -5,
      "name": "Plant_Coral_Block_Violet"
    },
    {
      "x": -7,
      "y": 0,
      "z": -4,
      "name": "Plant_Coral_Block_Violet"
    },
    {
      "x": -7,
      "y": 1,
      "z": -4,
      "name": "Plant_Coral_Block_Violet"
    },
    {
      "x": -7,
      "y": 2,
      "z": -4,
      "name": "Plant_Coral_Block_Violet"
    },
    {
      "x": -7,
      "y": 3,
      "z": -4,
      "name": "Plant_Coral_Block_Violet"
    },
    {
      "x": -7,
      "y": 4,
      "z": -4,
      "name": "Rock_Slate"
    },
    {
      "x": -7,
      "y": 5,
      "z": -4,
      "name": "Rock_Slate"
    },
    {
      "x": -7,
      "y": 6,
      "z": -4,
      "name": "Rock_Slate"
    },
    {
      "x": -7,
      "y": 7,
      "z": -4,
      "name": "Plant_Coral_Block_Violet"
    },
    {
      "x": -7,
      "y": 8,
      "z": -4,
      "name": "Plant_Coral_Block_Violet"
    },
    {
      "x": -7,
      "y": 9,
      "z": -4,
      "name": "Plant_Coral_Block_Violet"
    },
    {
      "x": -7,
      "y": 10,
      "z": -4,
      "name": "Plant_Coral_Block_Violet"
    },
    {
      "x": -7,
      "y": 11,
      "z": -4,
      "name": "Plant_Coral_Block_Violet"
    },
    {
      "x": -7,
      "y": 12,
      "z": -4,
      "name": "Plant_Coral_Block_Violet"
    },
    {
      "x": -7,
      "y": 13,
      "z": -4,
      "name": "Plant_Coral_Block_Violet"
    },
    {
      "x": -7,
      "y": 14,
      "z": -4,
      "name": "Rock_Slate"
    },
    {
      "x": -7,
      "y": 15,
      "z": -4,
      "name": "Rock_Slate"
    },
    {
      "x": -7,
      "y": 16,
      "z": -4,
      "name": "Rock_Slate"
    },
    {
      "x": -7,
      "y": 17,
      "z": -4,
      "name": "Plant_Coral_Block_Violet"
    },
    {
      "x": -7,
      "y": 18,
      "z": -4,
      "name": "Plant_Coral_Block_Violet"
    },
    {
      "x": -7,
      "y": 19,
      "z": -4,
      "name": "Plant_Coral_Block_Violet"
    },
    {
      "x": -7,
      "y": 0,
      "z": -3,
      "name": "Plant_Coral_Block_Violet"
    },
    {
      "x": -7,
      "y": 1,
      "z": -3,
      "name": "Plant_Coral_Block_Violet"
    },
    {
      "x": -7,
      "y": 2,
      "z": -3,
      "name": "Plant_Coral_Block_Violet"
    },
    {
      "x": -7,
      "y": 3,
      "z": -3,
      "name": "Plant_Coral_Block_Violet"
    },
    {
      "x": -7,
      "y": 4,
      "z": -3,
      "name": "Rock_Slate"
    },
    {
      "x": -7,
      "y": 5,
      "z": -3,
      "name": "Rock_Slate"
    },
    {
      "x": -7,
      "y": 6,
      "z": -3,
      "name": "Rock_Slate"
    },
    {
      "x": -7,
      "y": 7,
      "z": -3,
      "name": "Rock_Slate"
    },
    {
      "x": -7,
      "y": 8,
      "z": -3,
      "name": "Rock_Slate"
    },
    {
      "x": -7,
      "y": 9,
      "z": -3,
      "name": "Rock_Slate"
    },
    {
      "x": -7,
      "y": 10,
      "z": -3,
      "name": "Rock_Slate"
    },
    {
      "x": -7,
      "y": 11,
      "z": -3,
      "name": "Rock_Slate"
    },
    {
      "x": -7,
      "y": 12,
      "z": -3,
      "name": "Rock_Slate"
    },
    {
      "x": -7,
      "y": 13,
      "z": -3,
      "name": "Rock_Slate"
    },
    {
      "x": -7,
      "y": 14,
      "z": -3,
      "name": "Rock_Slate"
    },
    {
      "x": -7,
      "y": 15,
      "z": -3,
      "name": "Rock_Slate"
    },
    {
      "x": -7,
      "y": 16,
      "z": -3,
      "name": "Rock_Slate"
    },
    {
      "x": -7,
      "y": 17,
      "z": -3,
      "name": "Rock_Slate"
    },
    {
      "x": -7,
      "y": 0,
      "z": -2,
      "name": "Plant_Coral_Block_Violet"
    },
    {
      "x": -7,
      "y": 1,
      "z": -2,
      "name": "Plant_Coral_Block_Violet"
    },
    {
      "x": -7,
      "y": 2,
      "z": -2,
      "name": "Plant_Coral_Block_Violet"
    },
    {
      "x": -7,
      "y": 3,
      "z": -2,
      "name": "Plant_Coral_Block_Violet"
    },
    {
      "x": -7,
      "y": 4,
      "z": -2,
      "name": "Rock_Slate"
    },
    {
      "x": -7,
      "y": 5,
      "z": -2,
      "name": "Rock_Slate"
    },
    {
      "x": -7,
      "y": 6,
      "z": -2,
      "name": "Rock_Slate"
    },
    {
      "x": -7,
      "y": 7,
      "z": -2,
      "name": "Rock_Slate"
    },
    {
      "x": -7,
      "y": 8,
      "z": -2,
      "name": "Rock_Slate"
    },
    {
      "x": -7,
      "y": 9,
      "z": -2,
      "name": "Rock_Slate"
    },
    {
      "x": -7,
      "y": 10,
      "z": -2,
      "name": "Rock_Slate"
    },
    {
      "x": -7,
      "y": 11,
      "z": -2,
      "name": "Rock_Slate"
    },
    {
      "x": -7,
      "y": 12,
      "z": -2,
      "name": "Rock_Slate"
    },
    {
      "x": -7,
      "y": 13,
      "z": -2,
      "name": "Rock_Slate"
    },
    {
      "x": -7,
      "y": 14,
      "z": -2,
      "name": "Rock_Slate"
    },
    {
      "x": -7,
      "y": 15,
      "z": -2,
      "name": "Rock_Slate"
    },
    {
      "x": -7,
      "y": 16,
      "z": -2,
      "name": "Rock_Slate"
    },
    {
      "x": -7,
      "y": 17,
      "z": -2,
      "name": "Rock_Slate"
    },
    {
      "x": -7,
      "y": 18,
      "z": -2,
      "name": "Rock_Slate"
    },
    {
      "x": -7,
      "y": 4,
      "z": -1,
      "name": "Plant_Coral_Block_Violet"
    },
    {
      "x": -7,
      "y": 5,
      "z": -1,
      "name": "Plant_Coral_Block_Violet"
    },
    {
      "x": -7,
      "y": 6,
      "z": -1,
      "name": "Plant_Coral_Block_Violet"
    },
    {
      "x": -7,
      "y": 7,
      "z": -1,
      "name": "Rock_Slate"
    },
    {
      "x": -7,
      "y": 8,
      "z": -1,
      "name": "Rock_Slate"
    },
    {
      "x": -7,
      "y": 9,
      "z": -1,
      "name": "Rock_Slate"
    },
    {
      "x": -7,
      "y": 10,
      "z": -1,
      "name": "Rock_Slate"
    },
    {
      "x": -7,
      "y": 11,
      "z": -1,
      "name": "Rock_Slate"
    },
    {
      "x": -7,
      "y": 12,
      "z": -1,
      "name": "Rock_Slate"
    },
    {
      "x": -7,
      "y": 13,
      "z": -1,
      "name": "Rock_Slate"
    },
    {
      "x": -7,
      "y": 14,
      "z": -1,
      "name": "Plant_Coral_Block_Violet"
    },
    {
      "x": -7,
      "y": 15,
      "z": -1,
      "name": "Plant_Coral_Block_Violet"
    },
    {
      "x": -7,
      "y": 16,
      "z": -1,
      "name": "Plant_Coral_Block_Violet"
    },
    {
      "x": -7,
      "y": 17,
      "z": -1,
      "name": "Rock_Slate"
    },
    {
      "x": -7,
      "y": 18,
      "z": -1,
      "name": "Rock_Slate"
    },
    {
      "x": -7,
      "y": 7,
      "z": 0,
      "name": "Plant_Coral_Block_Violet"
    },
    {
      "x": -7,
      "y": 8,
      "z": 0,
      "name": "Plant_Coral_Block_Violet"
    },
    {
      "x": -7,
      "y": 9,
      "z": 0,
      "name": "Plant_Coral_Block_Violet"
    },
    {
      "x": -7,
      "y": 10,
      "z": 0,
      "name": "Plant_Coral_Block_Violet"
    },
    {
      "x": -7,
      "y": 11,
      "z": 0,
      "name": "Plant_Coral_Block_Violet"
    },
    {
      "x": -7,
      "y": 12,
      "z": 0,
      "name": "Plant_Coral_Block_Violet"
    },
    {
      "x": -7,
      "y": 13,
      "z": 0,
      "name": "Plant_Coral_Block_Violet"
    },
    {
      "x": -7,
      "y": 14,
      "z": 0,
      "name": "Plant_Coral_Block_Violet"
    },
    {
      "x": -7,
      "y": 15,
      "z": 0,
      "name": "Plant_Coral_Block_Violet"
    },
    {
      "x": -7,
      "y": 16,
      "z": 0,
      "name": "Plant_Coral_Block_Violet"
    },
    {
      "x": -7,
      "y": 17,
      "z": 0,
      "name": "Plant_Coral_Block_Violet"
    },
    {
      "x": -7,
      "y": 18,
      "z": 0,
      "name": "Plant_Coral_Block_Violet"
    },
    {
      "x": -7,
      "y": 19,
      "z": 0,
      "name": "Plant_Coral_Block_Violet"
    },
    {
      "x": -7,
      "y": 20,
      "z": 0,
      "name": "Plant_Coral_Block_Violet"
    },
    {
      "x": -6,
      "y": 0,
      "z": -5,
      "name": "Plant_Coral_Block_Violet"
    },
    {
      "x": -6,
      "y": 1,
      "z": -5,
      "name": "Plant_Coral_Block_Violet"
    },
    {
      "x": -6,
      "y": 2,
      "z": -5,
      "name": "Plant_Coral_Block_Violet"
    },
    {
      "x": -6,
      "y": 3,
      "z": -5,
      "name": "Plant_Coral_Block_Violet"
    },
    {
      "x": -6,
      "y": 4,
      "z": -5,
      "name": "Plant_Coral_Block_Violet"
    },
    {
      "x": -6,
      "y": 5,
      "z": -5,
      "name": "Plant_Coral_Block_Violet"
    },
    {
      "x": -6,
      "y": 6,
      "z": -5,
      "name": "Plant_Coral_Block_Violet"
    },
    {
      "x": -6,
      "y": 7,
      "z": -5,
      "name": "Plant_Coral_Block_Violet"
    },
    {
      "x": -6,
      "y": 13,
      "z": -5,
      "name": "Plant_Coral_Block_Violet"
    },
    {
      "x": -6,
      "y": 14,
      "z": -5,
      "name": "Plant_Coral_Block_Violet"
    },
    {
      "x": -6,
      "y": 15,
      "z": -5,
      "name": "Plant_Coral_Block_Violet"
    },
    {
      "x": -6,
      "y": 16,
      "z": -5,
      "name": "Plant_Coral_Block_Violet"
    },
    {
      "x": -6,
      "y": 17,
      "z": -5,
      "name": "Plant_Coral_Block_Violet"
    },
    {
      "x": -6,
      "y": 0,
      "z": -4,
      "name": "Rock_Slate"
    },
    {
      "x": -6,
      "y": 1,
      "z": -4,
      "name": "Rock_Slate"
    },
    {
      "x": -6,
      "y": 2,
      "z": -4,
      "name": "Rock_Slate"
    },
    {
      "x": -6,
      "y": 3,
      "z": -4,
      "name": "Rock_Slate"
    },
    {
      "x": -6,
      "y": 4,
      "z": -4,
      "name": "Rock_Slate"
    },
    {
      "x": -6,
      "y": 5,
      "z": -4,
      "name": "Rock_Slate"
    },
    {
      "x": -6,
      "y": 6,
      "z": -4,
      "name": "Rock_Slate"
    },
    {
      "x": -6,
      "y": 7,
      "z": -4,
      "name": "Plant_Coral_Block_Violet"
    },
    {
      "x": -6,
      "y": 8,
      "z": -4,
      "name": "Plant_Coral_Block_Violet"
    },
    {
      "x": -6,
      "y": 9,
      "z": -4,
      "name": "Plant_Coral_Block_Violet"
    },
    {
      "x": -6,
      "y": 10,
      "z": -4,
      "name": "Plant_Coral_Block_Violet"
    },
    {
      "x": -6,
      "y": 11,
      "z": -4,
      "name": "Plant_Coral_Block_Violet"
    },
    {
      "x": -6,
      "y": 12,
      "z": -4,
      "name": "Plant_Coral_Block_Violet"
    },
    {
      "x": -6,
      "y": 13,
      "z": -4,
      "name": "Plant_Coral_Block_Violet"
    },
    {
      "x": -6,
      "y": 14,
      "z": -4,
      "name": "Rock_Slate"
    },
    {
      "x": -6,
      "y": 15,
      "z": -4,
      "name": "Rock_Slate"
    },
    {
      "x": -6,
      "y": 16,
      "z": -4,
      "name": "Rock_Slate"
    },
    {
      "x": -6,
      "y": 17,
      "z": -4,
      "name": "Plant_Coral_Block_Violet"
    },
    {
      "x": -6,
      "y": 18,
      "z": -4,
      "name": "Plant_Coral_Block_Violet"
    },
    {
      "x": -6,
      "y": 19,
      "z": -4,
      "name": "Plant_Coral_Block_Violet"
    },
    {
      "x": -6,
      "y": 0,
      "z": -3,
      "name": "Rock_Slate"
    },
    {
      "x": -6,
      "y": 1,
      "z": -3,
      "name": "Rock_Slate"
    },
    {
      "x": -6,
      "y": 2,
      "z": -3,
      "name": "Rock_Slate"
    },
    {
      "x": -6,
      "y": 3,
      "z": -3,
      "name": "Rock_Slate"
    },
    {
      "x": -6,
      "y": 4,
      "z": -3,
      "name": "Rock_Slate"
    },
    {
      "x": -6,
      "y": 5,
      "z": -3,
      "name": "Rock_Slate"
    },
    {
      "x": -6,
      "y": 6,
      "z": -3,
      "name": "Rock_Slate"
    },
    {
      "x": -6,
      "y": 7,
      "z": -3,
      "name": "Rock_Slate"
    },
    {
      "x": -6,
      "y": 8,
      "z": -3,
      "name": "Rock_Slate"
    },
    {
      "x": -6,
      "y": 9,
      "z": -3,
      "name": "Rock_Slate"
    },
    {
      "x": -6,
      "y": 10,
      "z": -3,
      "name": "Rock_Slate"
    },
    {
      "x": -6,
      "y": 11,
      "z": -3,
      "name": "Rock_Slate"
    },
    {
      "x": -6,
      "y": 12,
      "z": -3,
      "name": "Rock_Slate"
    },
    {
      "x": -6,
      "y": 13,
      "z": -3,
      "name": "Rock_Slate"
    },
    {
      "x": -6,
      "y": 14,
      "z": -3,
      "name": "Rock_Slate"
    },
    {
      "x": -6,
      "y": 15,
      "z": -3,
      "name": "Rock_Slate"
    },
    {
      "x": -6,
      "y": 16,
      "z": -3,
      "name": "Rock_Slate"
    },
    {
      "x": -6,
      "y": 17,
      "z": -3,
      "name": "Rock_Slate"
    },
    {
      "x": -6,
      "y": 0,
      "z": -2,
      "name": "Rock_Slate"
    },
    {
      "x": -6,
      "y": 1,
      "z": -2,
      "name": "Rock_Slate"
    },
    {
      "x": -6,
      "y": 2,
      "z": -2,
      "name": "Rock_Slate"
    },
    {
      "x": -6,
      "y": 3,
      "z": -2,
      "name": "Rock_Slate"
    },
    {
      "x": -6,
      "y": 4,
      "z": -2,
      "name": "Rock_Slate"
    },
    {
      "x": -6,
      "y": 5,
      "z": -2,
      "name": "Rock_Slate"
    },
    {
      "x": -6,
      "y": 6,
      "z": -2,
      "name": "Rock_Slate"
    },
    {
      "x": -6,
      "y": 7,
      "z": -2,
      "name": "Rock_Slate"
    },
    {
      "x": -6,
      "y": 8,
      "z": -2,
      "name": "Rock_Slate"
    },
    {
      "x": -6,
      "y": 9,
      "z": -2,
      "name": "Rock_Slate"
    },
    {
      "x": -6,
      "y": 10,
      "z": -2,
      "name": "Rock_Slate"
    },
    {
      "x": -6,
      "y": 11,
      "z": -2,
      "name": "Rock_Slate"
    },
    {
      "x": -6,
      "y": 12,
      "z": -2,
      "name": "Rock_Slate"
    },
    {
      "x": -6,
      "y": 13,
      "z": -2,
      "name": "Rock_Slate"
    },
    {
      "x": -6,
      "y": 14,
      "z": -2,
      "name": "Rock_Slate"
    },
    {
      "x": -6,
      "y": 15,
      "z": -2,
      "name": "Rock_Slate"
    },
    {
      "x": -6,
      "y": 16,
      "z": -2,
      "name": "Rock_Slate"
    },
    {
      "x": -6,
      "y": 17,
      "z": -2,
      "name": "Rock_Slate"
    },
    {
      "x": -6,
      "y": 18,
      "z": -2,
      "name": "Rock_Slate"
    },
    {
      "x": -6,
      "y": 0,
      "z": -1,
      "name": "Plant_Coral_Block_Violet"
    },
    {
      "x": -6,
      "y": 1,
      "z": -1,
      "name": "Plant_Coral_Block_Violet"
    },
    {
      "x": -6,
      "y": 2,
      "z": -1,
      "name": "Plant_Coral_Block_Violet"
    },
    {
      "x": -6,
      "y": 3,
      "z": -1,
      "name": "Plant_Coral_Block_Violet"
    },
    {
      "x": -6,
      "y": 4,
      "z": -1,
      "name": "Plant_Coral_Block_Violet"
    },
    {
      "x": -6,
      "y": 5,
      "z": -1,
      "name": "Plant_Coral_Block_Violet"
    },
    {
      "x": -6,
      "y": 6,
      "z": -1,
      "name": "Plant_Coral_Block_Violet"
    },
    {
      "x": -6,
      "y": 7,
      "z": -1,
      "name": "Rock_Slate"
    },
    {
      "x": -6,
      "y": 8,
      "z": -1,
      "name": "Rock_Slate"
    },
    {
      "x": -6,
      "y": 9,
      "z": -1,
      "name": "Rock_Slate"
    },
    {
      "x": -6,
      "y": 10,
      "z": -1,
      "name": "Rock_Slate"
    },
    {
      "x": -6,
      "y": 11,
      "z": -1,
      "name": "Rock_Slate"
    },
    {
      "x": -6,
      "y": 12,
      "z": -1,
      "name": "Rock_Slate"
    },
    {
      "x": -6,
      "y": 13,
      "z": -1,
      "name": "Rock_Slate"
    },
    {
      "x": -6,
      "y": 14,
      "z": -1,
      "name": "Plant_Coral_Block_Violet"
    },
    {
      "x": -6,
      "y": 15,
      "z": -1,
      "name": "Plant_Coral_Block_Violet"
    },
    {
      "x": -6,
      "y": 16,
      "z": -1,
      "name": "Plant_Coral_Block_Violet"
    },
    {
      "x": -6,
      "y": 17,
      "z": -1,
      "name": "Rock_Slate"
    },
    {
      "x": -6,
      "y": 18,
      "z": -1,
      "name": "Rock_Slate"
    },
    {
      "x": -6,
      "y": 19,
      "z": -1,
      "name": "Rock_Slate"
    },
    {
      "x": -6,
      "y": 6,
      "z": 0,
      "name": "Plant_Coral_Block_Violet"
    },
    {
      "x": -6,
      "y": 7,
      "z": 0,
      "name": "Plant_Coral_Block_Violet"
    },
    {
      "x": -6,
      "y": 8,
      "z": 0,
      "name": "Plant_Coral_Block_Violet"
    },
    {
      "x": -6,
      "y": 9,
      "z": 0,
      "name": "Plant_Coral_Block_Violet"
    },
    {
      "x": -6,
      "y": 10,
      "z": 0,
      "name": "Plant_Coral_Block_Violet"
    },
    {
      "x": -6,
      "y": 11,
      "z": 0,
      "name": "Plant_Coral_Block_Violet"
    },
    {
      "x": -6,
      "y": 12,
      "z": 0,
      "name": "Plant_Coral_Block_Violet"
    },
    {
      "x": -6,
      "y": 13,
      "z": 0,
      "name": "Plant_Coral_Block_Violet"
    },
    {
      "x": -6,
      "y": 17,
      "z": 0,
      "name": "Plant_Coral_Block_Violet"
    },
    {
      "x": -6,
      "y": 18,
      "z": 0,
      "name": "Plant_Coral_Block_Violet"
    },
    {
      "x": -6,
      "y": 19,
      "z": 0,
      "name": "Plant_Coral_Block_Violet"
    },
    {
      "x": -6,
      "y": 20,
      "z": 0,
      "name": "Plant_Coral_Block_Violet"
    },
    {
      "x": -5,
      "y": 0,
      "z": -5,
      "name": "Plant_Coral_Block_Violet"
    },
    {
      "x": -5,
      "y": 1,
      "z": -5,
      "name": "Plant_Coral_Block_Violet"
    },
    {
      "x": -5,
      "y": 2,
      "z": -5,
      "name": "Plant_Coral_Block_Violet"
    },
    {
      "x": -5,
      "y": 3,
      "z": -5,
      "name": "Plant_Coral_Block_Violet"
    },
    {
      "x": -5,
      "y": 4,
      "z": -5,
      "name": "Plant_Coral_Block_Violet"
    },
    {
      "x": -5,
      "y": 5,
      "z": -5,
      "name": "Plant_Coral_Block_Violet"
    },
    {
      "x": -5,
      "y": 6,
      "z": -5,
      "name": "Plant_Coral_Block_Violet"
    },
    {
      "x": -5,
      "y": 0,
      "z": -4,
      "name": "Rock_Slate"
    },
    {
      "x": -5,
      "y": 1,
      "z": -4,
      "name": "Rock_Slate"
    },
    {
      "x": -5,
      "y": 2,
      "z": -4,
      "name": "Rock_Slate"
    },
    {
      "x": -5,
      "y": 3,
      "z": -4,
      "name": "Rock_Slate"
    },
    {
      "x": -5,
      "y": 4,
      "z": -4,
      "name": "Rock_Slate"
    },
    {
      "x": -5,
      "y": 5,
      "z": -4,
      "name": "Rock_Slate"
    },
    {
      "x": -5,
      "y": 6,
      "z": -4,
      "name": "Rock_Slate"
    },
    {
      "x": -5,
      "y": 7,
      "z": -4,
      "name": "Plant_Coral_Block_Violet"
    },
    {
      "x": -5,
      "y": 8,
      "z": -4,
      "name": "Plant_Coral_Block_Violet"
    },
    {
      "x": -5,
      "y": 9,
      "z": -4,
      "name": "Plant_Coral_Block_Violet"
    },
    {
      "x": -5,
      "y": 14,
      "z": -4,
      "name": "Plant_Coral_Block_Violet"
    },
    {
      "x": -5,
      "y": 15,
      "z": -4,
      "name": "Plant_Coral_Block_Violet"
    },
    {
      "x": -5,
      "y": 16,
      "z": -4,
      "name": "Plant_Coral_Block_Violet"
    },
    {
      "x": -5,
      "y": 0,
      "z": -3,
      "name": "Rock_Slate"
    },
    {
      "x": -5,
      "y": 1,
      "z": -3,
      "name": "Rock_Slate"
    },
    {
      "x": -5,
      "y": 2,
      "z": -3,
      "name": "Rock_Slate"
    },
    {
      "x": -5,
      "y": 3,
      "z": -3,
      "name": "Rock_Slate"
    },
    {
      "x": -5,
      "y": 4,
      "z": -3,
      "name": "Rock_Slate"
    },
    {
      "x": -5,
      "y": 5,
      "z": -3,
      "name": "Rock_Slate"
    },
    {
      "x": -5,
      "y": 6,
      "z": -3,
      "name": "Rock_Slate"
    },
    {
      "x": -5,
      "y": 7,
      "z": -3,
      "name": "Rock_Slate"
    },
    {
      "x": -5,
      "y": 8,
      "z": -3,
      "name": "Rock_Slate"
    },
    {
      "x": -5,
      "y": 9,
      "z": -3,
      "name": "Rock_Slate"
    },
    {
      "x": -5,
      "y": 10,
      "z": -3,
      "name": "Plant_Coral_Block_Violet"
    },
    {
      "x": -5,
      "y": 11,
      "z": -3,
      "name": "Plant_Coral_Block_Violet"
    },
    {
      "x": -5,
      "y": 12,
      "z": -3,
      "name": "Plant_Coral_Block_Violet"
    },
    {
      "x": -5,
      "y": 13,
      "z": -3,
      "name": "Plant_Coral_Block_Violet"
    },
    {
      "x": -5,
      "y": 14,
      "z": -3,
      "name": "Plant_Coral_Block_Violet"
    },
    {
      "x": -5,
      "y": 15,
      "z": -3,
      "name": "Plant_Coral_Block_Violet"
    },
    {
      "x": -5,
      "y": 16,
      "z": -3,
      "name": "Plant_Coral_Block_Violet"
    },
    {
      "x": -5,
      "y": 17,
      "z": -3,
      "name": "Plant_Coral_Block_Violet"
    },
    {
      "x": -5,
      "y": 18,
      "z": -3,
      "name": "Plant_Coral_Block_Violet"
    },
    {
      "x": -5,
      "y": 19,
      "z": -3,
      "name": "Plant_Coral_Block_Violet"
    },
    {
      "x": -5,
      "y": 0,
      "z": -2,
      "name": "Rock_Slate"
    },
    {
      "x": -5,
      "y": 1,
      "z": -2,
      "name": "Rock_Slate"
    },
    {
      "x": -5,
      "y": 2,
      "z": -2,
      "name": "Rock_Slate"
    },
    {
      "x": -5,
      "y": 3,
      "z": -2,
      "name": "Rock_Slate"
    },
    {
      "x": -5,
      "y": 4,
      "z": -2,
      "name": "Rock_Slate"
    },
    {
      "x": -5,
      "y": 5,
      "z": -2,
      "name": "Rock_Slate"
    },
    {
      "x": -5,
      "y": 6,
      "z": -2,
      "name": "Rock_Slate"
    },
    {
      "x": -5,
      "y": 7,
      "z": -2,
      "name": "Rock_Slate"
    },
    {
      "x": -5,
      "y": 8,
      "z": -2,
      "name": "Rock_Slate"
    },
    {
      "x": -5,
      "y": 9,
      "z": -2,
      "name": "Rock_Slate"
    },
    {
      "x": -5,
      "y": 10,
      "z": -2,
      "name": "Plant_Coral_Block_Violet"
    },
    {
      "x": -5,
      "y": 11,
      "z": -2,
      "name": "Plant_Coral_Block_Violet"
    },
    {
      "x": -5,
      "y": 12,
      "z": -2,
      "name": "Plant_Coral_Block_Violet"
    },
    {
      "x": -5,
      "y": 13,
      "z": -2,
      "name": "Plant_Coral_Block_Violet"
    },
    {
      "x": -5,
      "y": 14,
      "z": -2,
      "name": "Plant_Coral_Block_Violet"
    },
    {
      "x": -5,
      "y": 15,
      "z": -2,
      "name": "Plant_Coral_Block_Violet"
    },
    {
      "x": -5,
      "y": 16,
      "z": -2,
      "name": "Plant_Coral_Block_Violet"
    },
    {
      "x": -5,
      "y": 17,
      "z": -2,
      "name": "Plant_Coral_Block_Violet"
    },
    {
      "x": -5,
      "y": 18,
      "z": -2,
      "name": "Plant_Coral_Block_Violet"
    },
    {
      "x": -5,
      "y": 19,
      "z": -2,
      "name": "Plant_Coral_Block_Violet"
    },
    {
      "x": -5,
      "y": 20,
      "z": -2,
      "name": "Plant_Coral_Block_Violet"
    },
    {
      "x": -5,
      "y": 0,
      "z": -1,
      "name": "Plant_Coral_Block_Violet"
    },
    {
      "x": -5,
      "y": 1,
      "z": -1,
      "name": "Plant_Coral_Block_Violet"
    },
    {
      "x": -5,
      "y": 2,
      "z": -1,
      "name": "Plant_Coral_Block_Violet"
    },
    {
      "x": -5,
      "y": 3,
      "z": -1,
      "name": "Plant_Coral_Block_Violet"
    },
    {
      "x": -5,
      "y": 4,
      "z": -1,
      "name": "Plant_Coral_Block_Violet"
    },
    {
      "x": -5,
      "y": 5,
      "z": -1,
      "name": "Plant_Coral_Block_Violet"
    },
    {
      "x": -5,
      "y": 6,
      "z": -1,
      "name": "Plant_Coral_Block_Violet"
    },
    {
      "x": -5,
      "y": 7,
      "z": -1,
      "name": "Rock_Slate"
    },
    {
      "x": -5,
      "y": 8,
      "z": -1,
      "name": "Rock_Slate"
    },
    {
      "x": -5,
      "y": 9,
      "z": -1,
      "name": "Rock_Slate"
    },
    {
      "x": -5,
      "y": 10,
      "z": -1,
      "name": "Plant_Coral_Block_Violet"
    },
    {
      "x": -5,
      "y": 11,
      "z": -1,
      "name": "Plant_Coral_Block_Violet"
    },
    {
      "x": -5,
      "y": 12,
      "z": -1,
      "name": "Plant_Coral_Block_Violet"
    },
    {
      "x": -5,
      "y": 13,
      "z": -1,
      "name": "Plant_Coral_Block_Violet"
    },
    {
      "x": -5,
      "y": 17,
      "z": -1,
      "name": "Plant_Coral_Block_Violet"
    },
    {
      "x": -5,
      "y": 18,
      "z": -1,
      "name": "Plant_Coral_Block_Violet"
    },
    {
      "x": -5,
      "y": 19,
      "z": -1,
      "name": "Plant_Coral_Block_Violet"
    },
    {
      "x": -5,
      "y": 20,
      "z": -1,
      "name": "Plant_Coral_Block_Violet"
    },
    {
      "x": -5,
      "y": 6,
      "z": 0,
      "name": "Plant_Coral_Block_Violet"
    },
    {
      "x": -5,
      "y": 7,
      "z": 0,
      "name": "Plant_Coral_Block_Violet"
    },
    {
      "x": -5,
      "y": 8,
      "z": 0,
      "name": "Plant_Coral_Block_Violet"
    },
    {
      "x": -5,
      "y": 9,
      "z": 0,
      "name": "Plant_Coral_Block_Violet"
    },
    {
      "x": -4,
      "y": 0,
      "z": -5,
      "name": "Plant_Coral_Block_Violet"
    },
    {
      "x": -4,
      "y": 1,
      "z": -5,
      "name": "Plant_Coral_Block_Violet"
    },
    {
      "x": -4,
      "y": 2,
      "z": -5,
      "name": "Plant_Coral_Block_Violet"
    },
    {
      "x": -4,
      "y": 3,
      "z": -5,
      "name": "Plant_Coral_Block_Violet"
    },
    {
      "x": -4,
      "y": 0,
      "z": -4,
      "name": "Rock_Slate"
    },
    {
      "x": -4,
      "y": 1,
      "z": -4,
      "name": "Rock_Slate"
    },
    {
      "x": -4,
      "y": 2,
      "z": -4,
      "name": "Rock_Slate"
    },
    {
      "x": -4,
      "y": 3,
      "z": -4,
      "name": "Rock_Slate"
    },
    {
      "x": -4,
      "y": 4,
      "z": -4,
      "name": "Plant_Coral_Block_Violet"
    },
    {
      "x": -4,
      "y": 5,
      "z": -4,
      "name": "Plant_Coral_Block_Violet"
    },
    {
      "x": -4,
      "y": 6,
      "z": -4,
      "name": "Plant_Coral_Block_Violet"
    },
    {
      "x": -4,
      "y": 0,
      "z": -3,
      "name": "Rock_Slate"
    },
    {
      "x": -4,
      "y": 1,
      "z": -3,
      "name": "Rock_Slate"
    },
    {
      "x": -4,
      "y": 2,
      "z": -3,
      "name": "Rock_Slate"
    },
    {
      "x": -4,
      "y": 3,
      "z": -3,
      "name": "Rock_Slate"
    },
    {
      "x": -4,
      "y": 4,
      "z": -3,
      "name": "Plant_Coral_Block_Violet"
    },
    {
      "x": -4,
      "y": 5,
      "z": -3,
      "name": "Plant_Coral_Block_Violet"
    },
    {
      "x": -4,
      "y": 6,
      "z": -3,
      "name": "Plant_Coral_Block_Violet"
    },
    {
      "x": -4,
      "y": 7,
      "z": -3,
      "name": "Plant_Coral_Block_Violet"
    },
    {
      "x": -4,
      "y": 8,
      "z": -3,
      "name": "Plant_Coral_Block_Violet"
    },
    {
      "x": -4,
      "y": 9,
      "z": -3,
      "name": "Plant_Coral_Block_Violet"
    },
    {
      "x": -4,
      "y": 0,
      "z": -2,
      "name": "Rock_Slate"
    },
    {
      "x": -4,
      "y": 1,
      "z": -2,
      "name": "Rock_Slate"
    },
    {
      "x": -4,
      "y": 2,
      "z": -2,
      "name": "Rock_Slate"
    },
    {
      "x": -4,
      "y": 3,
      "z": -2,
      "name": "Rock_Slate"
    },
    {
      "x": -4,
      "y": 4,
      "z": -2,
      "name": "Plant_Coral_Block_Violet"
    },
    {
      "x": -4,
      "y": 5,
      "z": -2,
      "name": "Plant_Coral_Block_Violet"
    },
    {
      "x": -4,
      "y": 6,
      "z": -2,
      "name": "Plant_Coral_Block_Violet"
    },
    {
      "x": -4,
      "y": 7,
      "z": -2,
      "name": "Plant_Coral_Block_Violet"
    },
    {
      "x": -4,
      "y": 8,
      "z": -2,
      "name": "Plant_Coral_Block_Violet"
    },
    {
      "x": -4,
      "y": 9,
      "z": -2,
      "name": "Plant_Coral_Block_Violet"
    },
    {
      "x": -4,
      "y": 0,
      "z": -1,
      "name": "Plant_Coral_Block_Violet"
    },
    {
      "x": -4,
      "y": 1,
      "z": -1,
      "name": "Plant_Coral_Block_Violet"
    },
    {
      "x": -4,
      "y": 2,
      "z": -1,
      "name": "Plant_Coral_Block_Violet"
    },
    {
      "x": -4,
      "y": 3,
      "z": -1,
      "name": "Plant_Coral_Block_Violet"
    },
    {
      "x": -4,
      "y": 7,
      "z": -1,
      "name": "Plant_Coral_Block_Violet"
    },
    {
      "x": -4,
      "y": 8,
      "z": -1,
      "name": "Plant_Coral_Block_Violet"
    },
    {
      "x": -4,
      "y": 9,
      "z": -1,
      "name": "Plant_Coral_Block_Violet"
    },
    {
      "x": -3,
      "y": 0,
      "z": -4,
      "name": "Plant_Coral_Block_Violet"
    },
    {
      "x": -3,
      "y": 1,
      "z": -4,
      "name": "Plant_Coral_Block_Violet"
    },
    {
      "x": -3,
      "y": 2,
      "z": -4,
      "name": "Plant_Coral_Block_Violet"
    },
    {
      "x": -3,
      "y": 3,
      "z": -4,
      "name": "Plant_Coral_Block_Violet"
    },
    {
      "x": -3,
      "y": 0,
      "z": -3,
      "name": "Plant_Coral_Block_Violet"
    },
    {
      "x": -3,
      "y": 1,
      "z": -3,
      "name": "Plant_Coral_Block_Violet"
    },
    {
      "x": -3,
      "y": 2,
      "z": -3,
      "name": "Plant_Coral_Block_Violet"
    },
    {
      "x": -3,
      "y": 3,
      "z": -3,
      "name": "Plant_Coral_Block_Violet"
    },
    {
      "x": -3,
      "y": 4,
      "z": -3,
      "name": "Plant_Coral_Block_Violet"
    },
    {
      "x": -3,
      "y": 5,
      "z": -3,
      "name": "Plant_Coral_Block_Violet"
    },
    {
      "x": -3,
      "y": 6,
      "z": -3,
      "name": "Plant_Coral_Block_Violet"
    },
    {
      "x": -3,
      "y": 7,
      "z": -3,
      "name": "Plant_Coral_Block_Violet"
    },
    {
      "x": -3,
      "y": 0,
      "z": -2,
      "name": "Plant_Coral_Block_Violet"
    },
    {
      "x": -3,
      "y": 1,
      "z": -2,
      "name": "Plant_Coral_Block_Violet"
    },
    {
      "x": -3,
      "y": 2,
      "z": -2,
      "name": "Plant_Coral_Block_Violet"
    },
    {
      "x": -3,
      "y": 3,
      "z": -2,
      "name": "Plant_Coral_Block_Violet"
    },
    {
      "x": -3,
      "y": 4,
      "z": -2,
      "name": "Plant_Coral_Block_Violet"
    },
    {
      "x": -3,
      "y": 5,
      "z": -2,
      "name": "Plant_Coral_Block_Violet"
    },
    {
      "x": -3,
      "y": 6,
      "z": -2,
      "name": "Plant_Coral_Block_Violet"
    },
    {
      "x": -3,
      "y": 7,
      "z": -2,
      "name": "Plant_Coral_Block_Violet"
    },
    {
      "x": -3,
      "y": 0,
      "z": -1,
      "name": "Plant_Coral_Block_Violet"
    },
    {
      "x": -3,
      "y": 1,
      "z": -1,
      "name": "Plant_Coral_Block_Violet"
    },
    {
      "x": -3,
      "y": 2,
      "z": -1,
      "name": "Plant_Coral_Block_Violet"
    },
    {
      "x": -3,
      "y": 3,
      "z": -1,
      "name": "Plant_Coral_Block_Violet"
    },
    {
      "x": -3,
      "y": 4,
      "z": -1,
      "name": "Plant_Coral_Block_Violet"
    },
    {
      "x": -3,
      "y": 5,
      "z": -1,
      "name": "Plant_Coral_Block_Violet"
    },
    {
      "x": -3,
      "y": 6,
      "z": -1,
      "name": "Plant_Coral_Block_Violet"
    },
    {
      "x": -3,
      "y": 0,
      "z": 0,
      "name": "Plant_Coral_Block_Violet"
    },
    {
      "x": -3,
      "y": 1,
      "z": 0,
      "name": "Plant_Coral_Block_Violet"
    },
    {
      "x": -3,
      "y": 2,
      "z": 0,
      "name": "Plant_Coral_Block_Violet"
    },
    {
      "x": -3,
      "y": 3,
      "z": 0,
      "name": "Plant_Coral_Block_Violet"
    },
    {
      "x": -2,
      "y": 3,
      "z": -4,
      "name": "Plant_Coral_Block_Violet"
    },
    {
      "x": -2,
      "y": 4,
      "z": -4,
      "name": "Plant_Coral_Block_Violet"
    },
    {
      "x": -2,
      "y": 5,
      "z": -4,
      "name": "Plant_Coral_Block_Violet"
    },
    {
      "x": -2,
      "y": 6,
      "z": -4,
      "name": "Plant_Coral_Block_Violet"
    },
    {
      "x": -2,
      "y": 16,
      "z": -4,
      "name": "Plant_Coral_Block_Violet"
    },
    {
      "x": -2,
      "y": 17,
      "z": -4,
      "name": "Plant_Coral_Block_Violet"
    },
    {
      "x": -2,
      "y": 18,
      "z": -4,
      "name": "Plant_Coral_Block_Violet"
    },
    {
      "x": -2,
      "y": 19,
      "z": -4,
      "name": "Plant_Coral_Block_Violet"
    },
    {
      "x": -2,
      "y": 0,
      "z": -3,
      "name": "Plant_Coral_Block_Violet"
    },
    {
      "x": -2,
      "y": 1,
      "z": -3,
      "name": "Plant_Coral_Block_Violet"
    },
    {
      "x": -2,
      "y": 2,
      "z": -3,
      "name": "Plant_Coral_Block_Violet"
    },
    {
      "x": -2,
      "y": 3,
      "z": -3,
      "name": "Plant_Coral_Block_Violet"
    },
    {
      "x": -2,
      "y": 4,
      "z": -3,
      "name": "Rock_Slate"
    },
    {
      "x": -2,
      "y": 5,
      "z": -3,
      "name": "Rock_Slate"
    },
    {
      "x": -2,
      "y": 6,
      "z": -3,
      "name": "Rock_Slate"
    },
    {
      "x": -2,
      "y": 7,
      "z": -3,
      "name": "Plant_Coral_Block_Violet"
    },
    {
      "x": -2,
      "y": 8,
      "z": -3,
      "name": "Plant_Coral_Block_Violet"
    },
    {
      "x": -2,
      "y": 9,
      "z": -3,
      "name": "Plant_Coral_Block_Violet"
    },
    {
      "x": -2,
      "y": 13,
      "z": -3,
      "name": "Plant_Coral_Block_Violet"
    },
    {
      "x": -2,
      "y": 14,
      "z": -3,
      "name": "Plant_Coral_Block_Violet"
    },
    {
      "x": -2,
      "y": 15,
      "z": -3,
      "name": "Plant_Coral_Block_Violet"
    },
    {
      "x": -2,
      "y": 16,
      "z": -3,
      "name": "Plant_Coral_Block_Violet"
    },
    {
      "x": -2,
      "y": 17,
      "z": -3,
      "name": "Plant_Coral_Block_Violet"
    },
    {
      "x": -2,
      "y": 18,
      "z": -3,
      "name": "Plant_Coral_Block_Violet"
    },
    {
      "x": -2,
      "y": 19,
      "z": -3,
      "name": "Plant_Coral_Block_Violet"
    },
    {
      "x": -2,
      "y": 0,
      "z": -2,
      "name": "Rock_Slate"
    },
    {
      "x": -2,
      "y": 1,
      "z": -2,
      "name": "Rock_Slate"
    },
    {
      "x": -2,
      "y": 2,
      "z": -2,
      "name": "Rock_Slate"
    },
    {
      "x": -2,
      "y": 3,
      "z": -2,
      "name": "Rock_Slate"
    },
    {
      "x": -2,
      "y": 4,
      "z": -2,
      "name": "Rock_Slate"
    },
    {
      "x": -2,
      "y": 5,
      "z": -2,
      "name": "Rock_Slate"
    },
    {
      "x": -2,
      "y": 6,
      "z": -2,
      "name": "Rock_Slate"
    },
    {
      "x": -2,
      "y": 7,
      "z": -2,
      "name": "Plant_Coral_Block_Violet"
    },
    {
      "x": -2,
      "y": 8,
      "z": -2,
      "name": "Plant_Coral_Block_Violet"
    },
    {
      "x": -2,
      "y": 9,
      "z": -2,
      "name": "Plant_Coral_Block_Violet"
    },
    {
      "x": -2,
      "y": 10,
      "z": -2,
      "name": "Plant_Coral_Block_Violet"
    },
    {
      "x": -2,
      "y": 11,
      "z": -2,
      "name": "Plant_Coral_Block_Violet"
    },
    {
      "x": -2,
      "y": 12,
      "z": -2,
      "name": "Plant_Coral_Block_Violet"
    },
    {
      "x": -2,
      "y": 13,
      "z": -2,
      "name": "Plant_Coral_Block_Violet"
    },
    {
      "x": -2,
      "y": 14,
      "z": -2,
      "name": "Plant_Coral_Block_Violet"
    },
    {
      "x": -2,
      "y": 15,
      "z": -2,
      "name": "Plant_Coral_Block_Violet"
    },
    {
      "x": -2,
      "y": 16,
      "z": -2,
      "name": "Plant_Coral_Block_Violet"
    },
    {
      "x": -2,
      "y": 17,
      "z": -2,
      "name": "Plant_Coral_Block_Violet"
    },
    {
      "x": -2,
      "y": 18,
      "z": -2,
      "name": "Plant_Coral_Block_Violet"
    },
    {
      "x": -2,
      "y": 0,
      "z": -1,
      "name": "Rock_Slate"
    },
    {
      "x": -2,
      "y": 1,
      "z": -1,
      "name": "Rock_Slate"
    },
    {
      "x": -2,
      "y": 2,
      "z": -1,
      "name": "Rock_Slate"
    },
    {
      "x": -2,
      "y": 3,
      "z": -1,
      "name": "Rock_Slate"
    },
    {
      "x": -2,
      "y": 4,
      "z": -1,
      "name": "Rock_Slate"
    },
    {
      "x": -2,
      "y": 5,
      "z": -1,
      "name": "Rock_Slate"
    },
    {
      "x": -2,
      "y": 6,
      "z": -1,
      "name": "Rock_Slate"
    },
    {
      "x": -2,
      "y": 7,
      "z": -1,
      "name": "Plant_Coral_Block_Violet"
    },
    {
      "x": -2,
      "y": 8,
      "z": -1,
      "name": "Plant_Coral_Block_Violet"
    },
    {
      "x": -2,
      "y": 9,
      "z": -1,
      "name": "Plant_Coral_Block_Violet"
    },
    {
      "x": -2,
      "y": 10,
      "z": -1,
      "name": "Plant_Coral_Block_Violet"
    },
    {
      "x": -2,
      "y": 11,
      "z": -1,
      "name": "Plant_Coral_Block_Violet"
    },
    {
      "x": -2,
      "y": 12,
      "z": -1,
      "name": "Plant_Coral_Block_Violet"
    },
    {
      "x": -2,
      "y": 13,
      "z": -1,
      "name": "Plant_Coral_Block_Violet"
    },
    {
      "x": -2,
      "y": 14,
      "z": -1,
      "name": "Plant_Coral_Block_Violet"
    },
    {
      "x": -2,
      "y": 15,
      "z": -1,
      "name": "Plant_Coral_Block_Violet"
    },
    {
      "x": -2,
      "y": 0,
      "z": 0,
      "name": "Rock_Slate"
    },
    {
      "x": -2,
      "y": 1,
      "z": 0,
      "name": "Rock_Slate"
    },
    {
      "x": -2,
      "y": 2,
      "z": 0,
      "name": "Rock_Slate"
    },
    {
      "x": -2,
      "y": 3,
      "z": 0,
      "name": "Rock_Slate"
    },
    {
      "x": -2,
      "y": 4,
      "z": 0,
      "name": "Plant_Coral_Block_Violet"
    },
    {
      "x": -2,
      "y": 5,
      "z": 0,
      "name": "Plant_Coral_Block_Violet"
    },
    {
      "x": -2,
      "y": 6,
      "z": 0,
      "name": "Plant_Coral_Block_Violet"
    },
    {
      "x": -2,
      "y": 10,
      "z": 0,
      "name": "Plant_Coral_Block_Violet"
    },
    {
      "x": -2,
      "y": 11,
      "z": 0,
      "name": "Plant_Coral_Block_Violet"
    },
    {
      "x": -2,
      "y": 12,
      "z": 0,
      "name": "Plant_Coral_Block_Violet"
    },
    {
      "x": -2,
      "y": 0,
      "z": 1,
      "name": "Plant_Coral_Block_Violet"
    },
    {
      "x": -2,
      "y": 1,
      "z": 1,
      "name": "Plant_Coral_Block_Violet"
    },
    {
      "x": -2,
      "y": 2,
      "z": 1,
      "name": "Plant_Coral_Block_Violet"
    },
    {
      "x": -2,
      "y": 3,
      "z": 1,
      "name": "Plant_Coral_Block_Violet"
    },
    {
      "x": -2,
      "y": 4,
      "z": 1,
      "name": "Plant_Coral_Block_Violet"
    },
    {
      "x": -1,
      "y": 15,
      "z": -5,
      "name": "Plant_Coral_Block_Violet"
    },
    {
      "x": -1,
      "y": 16,
      "z": -5,
      "name": "Plant_Coral_Block_Violet"
    },
    {
      "x": -1,
      "y": 17,
      "z": -5,
      "name": "Plant_Coral_Block_Violet"
    },
    {
      "x": -1,
      "y": 18,
      "z": -5,
      "name": "Plant_Coral_Block_Violet"
    },
    {
      "x": -1,
      "y": 3,
      "z": -4,
      "name": "Plant_Coral_Block_Violet"
    },
    {
      "x": -1,
      "y": 4,
      "z": -4,
      "name": "Plant_Coral_Block_Violet"
    },
    {
      "x": -1,
      "y": 5,
      "z": -4,
      "name": "Plant_Coral_Block_Violet"
    },
    {
      "x": -1,
      "y": 6,
      "z": -4,
      "name": "Plant_Coral_Block_Violet"
    },
    {
      "x": -1,
      "y": 7,
      "z": -4,
      "name": "Plant_Coral_Block_Violet"
    },
    {
      "x": -1,
      "y": 8,
      "z": -4,
      "name": "Plant_Coral_Block_Violet"
    },
    {
      "x": -1,
      "y": 9,
      "z": -4,
      "name": "Plant_Coral_Block_Violet"
    },
    {
      "x": -1,
      "y": 13,
      "z": -4,
      "name": "Plant_Coral_Block_Violet"
    },
    {
      "x": -1,
      "y": 14,
      "z": -4,
      "name": "Plant_Coral_Block_Violet"
    },
    {
      "x": -1,
      "y": 15,
      "z": -4,
      "name": "Plant_Coral_Block_Violet"
    },
    {
      "x": -1,
      "y": 16,
      "z": -4,
      "name": "Rock_Slate"
    },
    {
      "x": -1,
      "y": 17,
      "z": -4,
      "name": "Rock_Slate"
    },
    {
      "x": -1,
      "y": 18,
      "z": -4,
      "name": "Rock_Slate"
    },
    {
      "x": -1,
      "y": 19,
      "z": -4,
      "name": "Plant_Coral_Block_Violet"
    },
    {
      "x": -1,
      "y": 20,
      "z": -4,
      "name": "Plant_Coral_Block_Violet"
    },
    {
      "x": -1,
      "y": 21,
      "z": -4,
      "name": "Plant_Coral_Block_Violet"
    },
    {
      "x": -1,
      "y": 0,
      "z": -3,
      "name": "Plant_Coral_Block_Violet"
    },
    {
      "x": -1,
      "y": 1,
      "z": -3,
      "name": "Plant_Coral_Block_Violet"
    },
    {
      "x": -1,
      "y": 2,
      "z": -3,
      "name": "Plant_Coral_Block_Violet"
    },
    {
      "x": -1,
      "y": 3,
      "z": -3,
      "name": "Plant_Coral_Block_Violet"
    },
    {
      "x": -1,
      "y": 4,
      "z": -3,
      "name": "Rock_Slate"
    },
    {
      "x": -1,
      "y": 5,
      "z": -3,
      "name": "Rock_Slate"
    },
    {
      "x": -1,
      "y": 6,
      "z": -3,
      "name": "Rock_Slate"
    },
    {
      "x": -1,
      "y": 7,
      "z": -3,
      "name": "Rock_Slate"
    },
    {
      "x": -1,
      "y": 8,
      "z": -3,
      "name": "Rock_Slate"
    },
    {
      "x": -1,
      "y": 9,
      "z": -3,
      "name": "Rock_Slate"
    },
    {
      "x": -1,
      "y": 10,
      "z": -3,
      "name": "Plant_Coral_Block_Violet"
    },
    {
      "x": -1,
      "y": 11,
      "z": -3,
      "name": "Plant_Coral_Block_Violet"
    },
    {
      "x": -1,
      "y": 12,
      "z": -3,
      "name": "Plant_Coral_Block_Violet"
    },
    {
      "x": -1,
      "y": 13,
      "z": -3,
      "name": "Rock_Slate"
    },
    {
      "x": -1,
      "y": 14,
      "z": -3,
      "name": "Rock_Slate"
    },
    {
      "x": -1,
      "y": 15,
      "z": -3,
      "name": "Rock_Slate"
    },
    {
      "x": -1,
      "y": 16,
      "z": -3,
      "name": "Rock_Slate"
    },
    {
      "x": -1,
      "y": 17,
      "z": -3,
      "name": "Rock_Slate"
    },
    {
      "x": -1,
      "y": 18,
      "z": -3,
      "name": "Rock_Slate"
    },
    {
      "x": -1,
      "y": 19,
      "z": -3,
      "name": "Plant_Coral_Block_Violet"
    },
    {
      "x": -1,
      "y": 20,
      "z": -3,
      "name": "Plant_Coral_Block_Violet"
    },
    {
      "x": -1,
      "y": 21,
      "z": -3,
      "name": "Plant_Coral_Block_Violet"
    },
    {
      "x": -1,
      "y": 22,
      "z": -3,
      "name": "Plant_Coral_Block_Violet"
    },
    {
      "x": -1,
      "y": 23,
      "z": -3,
      "name": "Plant_Coral_Block_Violet"
    },
    {
      "x": -1,
      "y": 24,
      "z": -3,
      "name": "Plant_Coral_Block_Violet"
    },
    {
      "x": -1,
      "y": 0,
      "z": -2,
      "name": "Rock_Slate"
    },
    {
      "x": -1,
      "y": 1,
      "z": -2,
      "name": "Rock_Slate"
    },
    {
      "x": -1,
      "y": 2,
      "z": -2,
      "name": "Rock_Slate"
    },
    {
      "x": -1,
      "y": 3,
      "z": -2,
      "name": "Rock_Slate"
    },
    {
      "x": -1,
      "y": 4,
      "z": -2,
      "name": "Rock_Slate"
    },
    {
      "x": -1,
      "y": 5,
      "z": -2,
      "name": "Rock_Slate"
    },
    {
      "x": -1,
      "y": 6,
      "z": -2,
      "name": "Rock_Slate"
    },
    {
      "x": -1,
      "y": 7,
      "z": -2,
      "name": "Rock_Slate"
    },
    {
      "x": -1,
      "y": 8,
      "z": -2,
      "name": "Rock_Slate"
    },
    {
      "x": -1,
      "y": 9,
      "z": -2,
      "name": "Rock_Slate"
    },
    {
      "x": -1,
      "y": 10,
      "z": -2,
      "name": "Rock_Slate"
    },
    {
      "x": -1,
      "y": 11,
      "z": -2,
      "name": "Rock_Slate"
    },
    {
      "x": -1,
      "y": 12,
      "z": -2,
      "name": "Rock_Slate"
    },
    {
      "x": -1,
      "y": 13,
      "z": -2,
      "name": "Rock_Slate"
    },
    {
      "x": -1,
      "y": 14,
      "z": -2,
      "name": "Rock_Slate"
    },
    {
      "x": -1,
      "y": 15,
      "z": -2,
      "name": "Rock_Slate"
    },
    {
      "x": -1,
      "y": 16,
      "z": -2,
      "name": "Rock_Slate"
    },
    {
      "x": -1,
      "y": 17,
      "z": -2,
      "name": "Rock_Slate"
    },
    {
      "x": -1,
      "y": 18,
      "z": -2,
      "name": "Rock_Slate"
    },
    {
      "x": -1,
      "y": 19,
      "z": -2,
      "name": "Plant_Coral_Block_Violet"
    },
    {
      "x": -1,
      "y": 20,
      "z": -2,
      "name": "Plant_Coral_Block_Violet"
    },
    {
      "x": -1,
      "y": 21,
      "z": -2,
      "name": "Plant_Coral_Block_Violet"
    },
    {
      "x": -1,
      "y": 22,
      "z": -2,
      "name": "Plant_Coral_Block_Violet"
    },
    {
      "x": -1,
      "y": 23,
      "z": -2,
      "name": "Plant_Coral_Block_Violet"
    },
    {
      "x": -1,
      "y": 24,
      "z": -2,
      "name": "Plant_Coral_Block_Violet"
    },
    {
      "x": -1,
      "y": 0,
      "z": -1,
      "name": "Rock_Slate"
    },
    {
      "x": -1,
      "y": 1,
      "z": -1,
      "name": "Rock_Slate"
    },
    {
      "x": -1,
      "y": 2,
      "z": -1,
      "name": "Rock_Slate"
    },
    {
      "x": -1,
      "y": 3,
      "z": -1,
      "name": "Rock_Slate"
    },
    {
      "x": -1,
      "y": 4,
      "z": -1,
      "name": "Plant_Coral_Block_Violet"
    },
    {
      "x": -1,
      "y": 5,
      "z": -1,
      "name": "Rock_Slate"
    },
    {
      "x": -1,
      "y": 6,
      "z": -1,
      "name": "Rock_Slate"
    },
    {
      "x": -1,
      "y": 7,
      "z": -1,
      "name": "Rock_Slate"
    },
    {
      "x": -1,
      "y": 8,
      "z": -1,
      "name": "Rock_Slate"
    },
    {
      "x": -1,
      "y": 9,
      "z": -1,
      "name": "Rock_Slate"
    },
    {
      "x": -1,
      "y": 10,
      "z": -1,
      "name": "Rock_Slate"
    },
    {
      "x": -1,
      "y": 11,
      "z": -1,
      "name": "Rock_Slate"
    },
    {
      "x": -1,
      "y": 12,
      "z": -1,
      "name": "Rock_Slate"
    },
    {
      "x": -1,
      "y": 13,
      "z": -1,
      "name": "Rock_Slate"
    },
    {
      "x": -1,
      "y": 14,
      "z": -1,
      "name": "Rock_Slate"
    },
    {
      "x": -1,
      "y": 15,
      "z": -1,
      "name": "Rock_Slate"
    },
    {
      "x": -1,
      "y": 16,
      "z": -1,
      "name": "Plant_Coral_Block_Violet"
    },
    {
      "x": -1,
      "y": 17,
      "z": -1,
      "name": "Plant_Coral_Block_Violet"
    },
    {
      "x": -1,
      "y": 18,
      "z": -1,
      "name": "Plant_Coral_Block_Violet"
    },
    {
      "x": -1,
      "y": 22,
      "z": -1,
      "name": "Plant_Coral_Block_Violet"
    },
    {
      "x": -1,
      "y": 23,
      "z": -1,
      "name": "Plant_Coral_Block_Violet"
    },
    {
      "x": -1,
      "y": 0,
      "z": 0,
      "name": "Rock_Slate"
    },
    {
      "x": -1,
      "y": 1,
      "z": 0,
      "name": "Rock_Slate"
    },
    {
      "x": -1,
      "y": 2,
      "z": 0,
      "name": "Rock_Slate"
    },
    {
      "x": -1,
      "y": 3,
      "z": 0,
      "name": "Rock_Slate"
    },
    {
      "x": -1,
      "y": 4,
      "z": 0,
      "name": "Plant_Coral_Block_Violet"
    },
    {
      "x": -1,
      "y": 5,
      "z": 0,
      "name": "Plant_Coral_Block_Violet"
    },
    {
      "x": -1,
      "y": 6,
      "z": 0,
      "name": "Plant_Coral_Block_Violet"
    },
    {
      "x": -1,
      "y": 7,
      "z": 0,
      "name": "Plant_Coral_Block_Violet"
    },
    {
      "x": -1,
      "y": 8,
      "z": 0,
      "name": "Plant_Coral_Block_Violet"
    },
    {
      "x": -1,
      "y": 9,
      "z": 0,
      "name": "Plant_Coral_Block_Violet"
    },
    {
      "x": -1,
      "y": 10,
      "z": 0,
      "name": "Rock_Slate"
    },
    {
      "x": -1,
      "y": 11,
      "z": 0,
      "name": "Rock_Slate"
    },
    {
      "x": -1,
      "y": 12,
      "z": 0,
      "name": "Rock_Slate"
    },
    {
      "x": -1,
      "y": 13,
      "z": 0,
      "name": "Plant_Coral_Block_Violet"
    },
    {
      "x": -1,
      "y": 14,
      "z": 0,
      "name": "Plant_Coral_Block_Violet"
    },
    {
      "x": -1,
      "y": 15,
      "z": 0,
      "name": "Plant_Coral_Block_Violet"
    },
    {
      "x": -1,
      "y": 0,
      "z": 1,
      "name": "Plant_Coral_Block_Violet"
    },
    {
      "x": -1,
      "y": 1,
      "z": 1,
      "name": "Plant_Coral_Block_Violet"
    },
    {
      "x": -1,
      "y": 2,
      "z": 1,
      "name": "Plant_Coral_Block_Violet"
    },
    {
      "x": -1,
      "y": 3,
      "z": 1,
      "name": "Plant_Coral_Block_Violet"
    },
    {
      "x": -1,
      "y": 4,
      "z": 1,
      "name": "Plant_Coral_Block_Violet"
    },
    {
      "x": -1,
      "y": 9,
      "z": 1,
      "name": "Plant_Coral_Block_Violet"
    },
    {
      "x": -1,
      "y": 10,
      "z": 1,
      "name": "Plant_Coral_Block_Violet"
    },
    {
      "x": -1,
      "y": 11,
      "z": 1,
      "name": "Plant_Coral_Block_Violet"
    },
    {
      "x": -1,
      "y": 12,
      "z": 1,
      "name": "Plant_Coral_Block_Violet"
    },
    {
      "x": -1,
      "y": 0,
      "z": 2,
      "name": "Plant_Coral_Block_Violet"
    },
    {
      "x": -1,
      "y": 1,
      "z": 2,
      "name": "Plant_Coral_Block_Violet"
    },
    {
      "x": -1,
      "y": 2,
      "z": 2,
      "name": "Plant_Coral_Block_Violet"
    },
    {
      "x": -1,
      "y": 3,
      "z": 2,
      "name": "Plant_Coral_Block_Violet"
    },
    {
      "x": -1,
      "y": 0,
      "z": 3,
      "name": "Plant_Coral_Block_Violet"
    },
    {
      "x": -1,
      "y": 1,
      "z": 3,
      "name": "Plant_Coral_Block_Violet"
    },
    {
      "x": -1,
      "y": 2,
      "z": 3,
      "name": "Plant_Coral_Block_Violet"
    },
    {
      "x": -1,
      "y": 3,
      "z": 3,
      "name": "Plant_Coral_Block_Violet"
    },
    {
      "x": -1,
      "y": 0,
      "z": 4,
      "name": "Plant_Coral_Block_Violet"
    },
    {
      "x": -1,
      "y": 1,
      "z": 4,
      "name": "Plant_Coral_Block_Violet"
    },
    {
      "x": -1,
      "y": 2,
      "z": 4,
      "name": "Plant_Coral_Block_Violet"
    },
    {
      "x": -1,
      "y": 3,
      "z": 4,
      "name": "Plant_Coral_Block_Violet"
    },
    {
      "x": 0,
      "y": 0,
      "z": -6,
      "name": "Plant_Coral_Block_Violet"
    },
    {
      "x": 0,
      "y": 1,
      "z": -6,
      "name": "Plant_Coral_Block_Violet"
    },
    {
      "x": 0,
      "y": 2,
      "z": -6,
      "name": "Plant_Coral_Block_Violet"
    },
    {
      "x": 0,
      "y": 0,
      "z": -5,
      "name": "Plant_Coral_Block_Violet"
    },
    {
      "x": 0,
      "y": 1,
      "z": -5,
      "name": "Plant_Coral_Block_Violet"
    },
    {
      "x": 0,
      "y": 2,
      "z": -5,
      "name": "Plant_Coral_Block_Violet"
    },
    {
      "x": 0,
      "y": 15,
      "z": -5,
      "name": "Plant_Coral_Block_Violet"
    },
    {
      "x": 0,
      "y": 16,
      "z": -5,
      "name": "Plant_Coral_Block_Violet"
    },
    {
      "x": 0,
      "y": 17,
      "z": -5,
      "name": "Plant_Coral_Block_Violet"
    },
    {
      "x": 0,
      "y": 18,
      "z": -5,
      "name": "Plant_Coral_Block_Violet"
    },
    {
      "x": 0,
      "y": 19,
      "z": -5,
      "name": "Plant_Coral_Block_Violet"
    },
    {
      "x": 0,
      "y": 20,
      "z": -5,
      "name": "Plant_Coral_Block_Violet"
    },
    {
      "x": 0,
      "y": 21,
      "z": -5,
      "name": "Plant_Coral_Block_Violet"
    },
    {
      "x": 0,
      "y": 0,
      "z": -4,
      "name": "Plant_Coral_Block_Violet"
    },
    {
      "x": 0,
      "y": 1,
      "z": -4,
      "name": "Plant_Coral_Block_Violet"
    },
    {
      "x": 0,
      "y": 2,
      "z": -4,
      "name": "Plant_Coral_Block_Violet"
    },
    {
      "x": 0,
      "y": 4,
      "z": -4,
      "name": "Plant_Coral_Block_Violet"
    },
    {
      "x": 0,
      "y": 5,
      "z": -4,
      "name": "Plant_Coral_Block_Violet"
    },
    {
      "x": 0,
      "y": 6,
      "z": -4,
      "name": "Plant_Coral_Block_Violet"
    },
    {
      "x": 0,
      "y": 7,
      "z": -4,
      "name": "Plant_Coral_Block_Violet"
    },
    {
      "x": 0,
      "y": 8,
      "z": -4,
      "name": "Plant_Coral_Block_Violet"
    },
    {
      "x": 0,
      "y": 9,
      "z": -4,
      "name": "Plant_Coral_Block_Violet"
    },
    {
      "x": 0,
      "y": 13,
      "z": -4,
      "name": "Plant_Coral_Block_Violet"
    },
    {
      "x": 0,
      "y": 14,
      "z": -4,
      "name": "Plant_Coral_Block_Violet"
    },
    {
      "x": 0,
      "y": 15,
      "z": -4,
      "name": "Plant_Coral_Block_Violet"
    },
    {
      "x": 0,
      "y": 16,
      "z": -4,
      "name": "Rock_Slate"
    },
    {
      "x": 0,
      "y": 17,
      "z": -4,
      "name": "Rock_Slate"
    },
    {
      "x": 0,
      "y": 18,
      "z": -4,
      "name": "Rock_Slate"
    },
    {
      "x": 0,
      "y": 19,
      "z": -4,
      "name": "Rock_Slate"
    },
    {
      "x": 0,
      "y": 20,
      "z": -4,
      "name": "Rock_Slate"
    },
    {
      "x": 0,
      "y": 21,
      "z": -4,
      "name": "Rock_Slate"
    },
    {
      "x": 0,
      "y": 22,
      "z": -4,
      "name": "Plant_Coral_Block_Violet"
    },
    {
      "x": 0,
      "y": 23,
      "z": -4,
      "name": "Plant_Coral_Block_Violet"
    },
    {
      "x": 0,
      "y": 24,
      "z": -4,
      "name": "Plant_Coral_Block_Violet"
    },
    {
      "x": 0,
      "y": 0,
      "z": -3,
      "name": "Plant_Coral_Block_Violet"
    },
    {
      "x": 0,
      "y": 1,
      "z": -3,
      "name": "Plant_Coral_Block_Violet"
    },
    {
      "x": 0,
      "y": 2,
      "z": -3,
      "name": "Plant_Coral_Block_Violet"
    },
    {
      "x": 0,
      "y": 3,
      "z": -3,
      "name": "Plant_Coral_Block_Violet"
    },
    {
      "x": 0,
      "y": 4,
      "z": -3,
      "name": "Rock_Slate"
    },
    {
      "x": 0,
      "y": 5,
      "z": -3,
      "name": "Rock_Slate"
    },
    {
      "x": 0,
      "y": 6,
      "z": -3,
      "name": "Rock_Slate"
    },
    {
      "x": 0,
      "y": 7,
      "z": -3,
      "name": "Rock_Slate"
    },
    {
      "x": 0,
      "y": 8,
      "z": -3,
      "name": "Rock_Slate"
    },
    {
      "x": 0,
      "y": 9,
      "z": -3,
      "name": "Rock_Slate"
    },
    {
      "x": 0,
      "y": 10,
      "z": -3,
      "name": "Plant_Coral_Block_Violet"
    },
    {
      "x": 0,
      "y": 11,
      "z": -3,
      "name": "Plant_Coral_Block_Violet"
    },
    {
      "x": 0,
      "y": 12,
      "z": -3,
      "name": "Plant_Coral_Block_Violet"
    },
    {
      "x": 0,
      "y": 13,
      "z": -3,
      "name": "Rock_Slate"
    },
    {
      "x": 0,
      "y": 14,
      "z": -3,
      "name": "Rock_Slate"
    },
    {
      "x": 0,
      "y": 15,
      "z": -3,
      "name": "Rock_Slate"
    },
    {
      "x": 0,
      "y": 16,
      "z": -3,
      "name": "Rock_Slate"
    },
    {
      "x": 0,
      "y": 17,
      "z": -3,
      "name": "Rock_Slate"
    },
    {
      "x": 0,
      "y": 18,
      "z": -3,
      "name": "Rock_Slate"
    },
    {
      "x": 0,
      "y": 19,
      "z": -3,
      "name": "Rock_Slate"
    },
    {
      "x": 0,
      "y": 20,
      "z": -3,
      "name": "Rock_Slate"
    },
    {
      "x": 0,
      "y": 21,
      "z": -3,
      "name": "Rock_Slate"
    },
    {
      "x": 0,
      "y": 22,
      "z": -3,
      "name": "Rock_Slate"
    },
    {
      "x": 0,
      "y": 23,
      "z": -3,
      "name": "Rock_Slate"
    },
    {
      "x": 0,
      "y": 0,
      "z": -2,
      "name": "Rock_Slate"
    },
    {
      "x": 0,
      "y": 1,
      "z": -2,
      "name": "Rock_Slate"
    },
    {
      "x": 0,
      "y": 2,
      "z": -2,
      "name": "Rock_Slate"
    },
    {
      "x": 0,
      "y": 3,
      "z": -2,
      "name": "Rock_Slate"
    },
    {
      "x": 0,
      "y": 4,
      "z": -2,
      "name": "Rock_Slate"
    },
    {
      "x": 0,
      "y": 5,
      "z": -2,
      "name": "Rock_Slate"
    },
    {
      "x": 0,
      "y": 6,
      "z": -2,
      "name": "Rock_Slate"
    },
    {
      "x": 0,
      "y": 7,
      "z": -2,
      "name": "Rock_Slate"
    },
    {
      "x": 0,
      "y": 8,
      "z": -2,
      "name": "Rock_Slate"
    },
    {
      "x": 0,
      "y": 9,
      "z": -2,
      "name": "Rock_Slate"
    },
    {
      "x": 0,
      "y": 10,
      "z": -2,
      "name": "Rock_Slate"
    },
    {
      "x": 0,
      "y": 11,
      "z": -2,
      "name": "Rock_Slate"
    },
    {
      "x": 0,
      "y": 12,
      "z": -2,
      "name": "Rock_Slate"
    },
    {
      "x": 0,
      "y": 13,
      "z": -2,
      "name": "Rock_Slate"
    },
    {
      "x": 0,
      "y": 14,
      "z": -2,
      "name": "Rock_Slate"
    },
    {
      "x": 0,
      "y": 15,
      "z": -2,
      "name": "Rock_Slate"
    },
    {
      "x": 0,
      "y": 16,
      "z": -2,
      "name": "Rock_Slate"
    },
    {
      "x": 0,
      "y": 17,
      "z": -2,
      "name": "Rock_Slate"
    },
    {
      "x": 0,
      "y": 18,
      "z": -2,
      "name": "Rock_Slate"
    },
    {
      "x": 0,
      "y": 19,
      "z": -2,
      "name": "Rock_Slate"
    },
    {
      "x": 0,
      "y": 20,
      "z": -2,
      "name": "Rock_Slate"
    },
    {
      "x": 0,
      "y": 21,
      "z": -2,
      "name": "Rock_Slate"
    },
    {
      "x": 0,
      "y": 22,
      "z": -2,
      "name": "Rock_Slate"
    },
    {
      "x": 0,
      "y": 0,
      "z": -1,
      "name": "Rock_Slate"
    },
    {
      "x": 0,
      "y": 1,
      "z": -1,
      "name": "Rock_Slate"
    },
    {
      "x": 0,
      "y": 2,
      "z": -1,
      "name": "Rock_Slate"
    },
    {
      "x": 0,
      "y": 3,
      "z": -1,
      "name": "Rock_Slate"
    },
    {
      "x": 0,
      "y": 4,
      "z": -1,
      "name": "Rock_Slate"
    },
    {
      "x": 0,
      "y": 5,
      "z": -1,
      "name": "Rock_Slate"
    },
    {
      "x": 0,
      "y": 6,
      "z": -1,
      "name": "Rock_Slate"
    },
    {
      "x": 0,
      "y": 7,
      "z": -1,
      "name": "Rock_Slate"
    },
    {
      "x": 0,
      "y": 8,
      "z": -1,
      "name": "Rock_Slate"
    },
    {
      "x": 0,
      "y": 9,
      "z": -1,
      "name": "Rock_Slate"
    },
    {
      "x": 0,
      "y": 10,
      "z": -1,
      "name": "Rock_Slate"
    },
    {
      "x": 0,
      "y": 11,
      "z": -1,
      "name": "Rock_Slate"
    },
    {
      "x": 0,
      "y": 12,
      "z": -1,
      "name": "Rock_Slate"
    },
    {
      "x": 0,
      "y": 13,
      "z": -1,
      "name": "Rock_Slate"
    },
    {
      "x": 0,
      "y": 14,
      "z": -1,
      "name": "Rock_Slate"
    },
    {
      "x": 0,
      "y": 15,
      "z": -1,
      "name": "Rock_Slate"
    },
    {
      "x": 0,
      "y": 16,
      "z": -1,
      "name": "Plant_Coral_Block_Violet"
    },
    {
      "x": 0,
      "y": 17,
      "z": -1,
      "name": "Plant_Coral_Block_Violet"
    },
    {
      "x": 0,
      "y": 18,
      "z": -1,
      "name": "Plant_Coral_Block_Violet"
    },
    {
      "x": 0,
      "y": 19,
      "z": -1,
      "name": "Plant_Coral_Block_Violet"
    },
    {
      "x": 0,
      "y": 20,
      "z": -1,
      "name": "Plant_Coral_Block_Violet"
    },
    {
      "x": 0,
      "y": 21,
      "z": -1,
      "name": "Plant_Coral_Block_Violet"
    },
    {
      "x": 0,
      "y": 22,
      "z": -1,
      "name": "Rock_Slate"
    },
    {
      "x": 0,
      "y": 0,
      "z": 0,
      "name": "Rock_Slate"
    },
    {
      "x": 0,
      "y": 1,
      "z": 0,
      "name": "Rock_Slate"
    },
    {
      "x": 0,
      "y": 2,
      "z": 0,
      "name": "Rock_Slate"
    },
    {
      "x": 0,
      "y": 3,
      "z": 0,
      "name": "Rock_Slate"
    },
    {
      "x": 0,
      "y": 4,
      "z": 0,
      "name": "Plant_Coral_Block_Violet"
    },
    {
      "x": 0,
      "y": 5,
      "z": 0,
      "name": "Plant_Coral_Block_Violet"
    },
    {
      "x": 0,
      "y": 6,
      "z": 0,
      "name": "Plant_Coral_Block_Violet"
    },
    {
      "x": 0,
      "y": 7,
      "z": 0,
      "name": "Plant_Coral_Block_Violet"
    },
    {
      "x": 0,
      "y": 8,
      "z": 0,
      "name": "Plant_Coral_Block_Violet"
    },
    {
      "x": 0,
      "y": 9,
      "z": 0,
      "name": "Plant_Coral_Block_Violet"
    },
    {
      "x": 0,
      "y": 10,
      "z": 0,
      "name": "Rock_Slate"
    },
    {
      "x": 0,
      "y": 11,
      "z": 0,
      "name": "Rock_Slate"
    },
    {
      "x": 0,
      "y": 12,
      "z": 0,
      "name": "Rock_Slate"
    },
    {
      "x": 0,
      "y": 13,
      "z": 0,
      "name": "Plant_Coral_Block_Violet"
    },
    {
      "x": 0,
      "y": 14,
      "z": 0,
      "name": "Plant_Coral_Block_Violet"
    },
    {
      "x": 0,
      "y": 15,
      "z": 0,
      "name": "Plant_Coral_Block_Violet"
    },
    {
      "x": 0,
      "y": 16,
      "z": 0,
      "name": "Plant_Coral_Block_Violet"
    },
    {
      "x": 0,
      "y": 22,
      "z": 0,
      "name": "Plant_Coral_Block_Violet"
    },
    {
      "x": 0,
      "y": 23,
      "z": 0,
      "name": "Plant_Coral_Block_Violet"
    },
    {
      "x": 0,
      "y": 0,
      "z": 1,
      "name": "Plant_Coral_Block_Violet"
    },
    {
      "x": 0,
      "y": 1,
      "z": 1,
      "name": "Plant_Coral_Block_Violet"
    },
    {
      "x": 0,
      "y": 2,
      "z": 1,
      "name": "Plant_Coral_Block_Violet"
    },
    {
      "x": 0,
      "y": 3,
      "z": 1,
      "name": "Plant_Coral_Block_Violet"
    },
    {
      "x": 0,
      "y": 9,
      "z": 1,
      "name": "Plant_Coral_Block_Violet"
    },
    {
      "x": 0,
      "y": 10,
      "z": 1,
      "name": "Plant_Coral_Block_Violet"
    },
    {
      "x": 0,
      "y": 11,
      "z": 1,
      "name": "Plant_Coral_Block_Violet"
    },
    {
      "x": 0,
      "y": 12,
      "z": 1,
      "name": "Plant_Coral_Block_Violet"
    },
    {
      "x": 0,
      "y": 13,
      "z": 1,
      "name": "Plant_Coral_Block_Violet"
    },
    {
      "x": 0,
      "y": 0,
      "z": 2,
      "name": "Rock_Slate"
    },
    {
      "x": 0,
      "y": 1,
      "z": 2,
      "name": "Rock_Slate"
    },
    {
      "x": 0,
      "y": 2,
      "z": 2,
      "name": "Rock_Slate"
    },
    {
      "x": 0,
      "y": 3,
      "z": 2,
      "name": "Rock_Slate"
    },
    {
      "x": 0,
      "y": 4,
      "z": 2,
      "name": "Plant_Coral_Block_Violet"
    },
    {
      "x": 0,
      "y": 5,
      "z": 2,
      "name": "Plant_Coral_Block_Violet"
    },
    {
      "x": 0,
      "y": 6,
      "z": 2,
      "name": "Plant_Coral_Block_Violet"
    },
    {
      "x": 0,
      "y": 7,
      "z": 2,
      "name": "Plant_Coral_Block_Violet"
    },
    {
      "x": 0,
      "y": 0,
      "z": 3,
      "name": "Rock_Slate"
    },
    {
      "x": 0,
      "y": 1,
      "z": 3,
      "name": "Rock_Slate"
    },
    {
      "x": 0,
      "y": 2,
      "z": 3,
      "name": "Rock_Slate"
    },
    {
      "x": 0,
      "y": 3,
      "z": 3,
      "name": "Rock_Slate"
    },
    {
      "x": 0,
      "y": 4,
      "z": 3,
      "name": "Plant_Coral_Block_Violet"
    },
    {
      "x": 0,
      "y": 5,
      "z": 3,
      "name": "Plant_Coral_Block_Violet"
    },
    {
      "x": 0,
      "y": 6,
      "z": 3,
      "name": "Plant_Coral_Block_Violet"
    },
    {
      "x": 0,
      "y": 7,
      "z": 3,
      "name": "Plant_Coral_Block_Violet"
    },
    {
      "x": 0,
      "y": 8,
      "z": 3,
      "name": "Plant_Coral_Block_Violet"
    },
    {
      "x": 0,
      "y": 9,
      "z": 3,
      "name": "Plant_Coral_Block_Violet"
    },
    {
      "x": 0,
      "y": 10,
      "z": 3,
      "name": "Plant_Coral_Block_Violet"
    },
    {
      "x": 0,
      "y": 0,
      "z": 4,
      "name": "Rock_Slate"
    },
    {
      "x": 0,
      "y": 1,
      "z": 4,
      "name": "Rock_Slate"
    },
    {
      "x": 0,
      "y": 2,
      "z": 4,
      "name": "Rock_Slate"
    },
    {
      "x": 0,
      "y": 3,
      "z": 4,
      "name": "Rock_Slate"
    },
    {
      "x": 0,
      "y": 4,
      "z": 4,
      "name": "Plant_Coral_Block_Violet"
    },
    {
      "x": 0,
      "y": 5,
      "z": 4,
      "name": "Plant_Coral_Block_Violet"
    },
    {
      "x": 0,
      "y": 6,
      "z": 4,
      "name": "Plant_Coral_Block_Violet"
    },
    {
      "x": 0,
      "y": 7,
      "z": 4,
      "name": "Plant_Coral_Block_Violet"
    },
    {
      "x": 0,
      "y": 8,
      "z": 4,
      "name": "Plant_Coral_Block_Violet"
    },
    {
      "x": 0,
      "y": 9,
      "z": 4,
      "name": "Plant_Coral_Block_Violet"
    },
    {
      "x": 0,
      "y": 10,
      "z": 4,
      "name": "Plant_Coral_Block_Violet"
    },
    {
      "x": 0,
      "y": 11,
      "z": 4,
      "name": "Plant_Coral_Block_Violet"
    },
    {
      "x": 0,
      "y": 0,
      "z": 5,
      "name": "Plant_Coral_Block_Violet"
    },
    {
      "x": 0,
      "y": 1,
      "z": 5,
      "name": "Plant_Coral_Block_Violet"
    },
    {
      "x": 0,
      "y": 2,
      "z": 5,
      "name": "Plant_Coral_Block_Violet"
    },
    {
      "x": 0,
      "y": 3,
      "z": 5,
      "name": "Plant_Coral_Block_Violet"
    },
    {
      "x": 0,
      "y": 8,
      "z": 5,
      "name": "Plant_Coral_Block_Violet"
    },
    {
      "x": 0,
      "y": 9,
      "z": 5,
      "name": "Plant_Coral_Block_Violet"
    },
    {
      "x": 0,
      "y": 10,
      "z": 5,
      "name": "Plant_Coral_Block_Violet"
    },
    {
      "x": 0,
      "y": 11,
      "z": 5,
      "name": "Plant_Coral_Block_Violet"
    },
    {
      "x": 1,
      "y": 0,
      "z": -7,
      "name": "Plant_Coral_Block_Violet"
    },
    {
      "x": 1,
      "y": 1,
      "z": -7,
      "name": "Plant_Coral_Block_Violet"
    },
    {
      "x": 1,
      "y": 2,
      "z": -7,
      "name": "Plant_Coral_Block_Violet"
    },
    {
      "x": 1,
      "y": 6,
      "z": -7,
      "name": "Plant_Coral_Block_Violet"
    },
    {
      "x": 1,
      "y": 7,
      "z": -7,
      "name": "Plant_Coral_Block_Violet"
    },
    {
      "x": 1,
      "y": 8,
      "z": -7,
      "name": "Plant_Coral_Block_Violet"
    },
    {
      "x": 1,
      "y": 0,
      "z": -6,
      "name": "Rock_Slate"
    },
    {
      "x": 1,
      "y": 1,
      "z": -6,
      "name": "Rock_Slate"
    },
    {
      "x": 1,
      "y": 2,
      "z": -6,
      "name": "Rock_Slate"
    },
    {
      "x": 1,
      "y": 3,
      "z": -6,
      "name": "Plant_Coral_Block_Violet"
    },
    {
      "x": 1,
      "y": 4,
      "z": -6,
      "name": "Plant_Coral_Block_Violet"
    },
    {
      "x": 1,
      "y": 5,
      "z": -6,
      "name": "Plant_Coral_Block_Violet"
    },
    {
      "x": 1,
      "y": 6,
      "z": -6,
      "name": "Plant_Coral_Block_Violet"
    },
    {
      "x": 1,
      "y": 7,
      "z": -6,
      "name": "Plant_Coral_Block_Violet"
    },
    {
      "x": 1,
      "y": 8,
      "z": -6,
      "name": "Plant_Coral_Block_Violet"
    },
    {
      "x": 1,
      "y": 0,
      "z": -5,
      "name": "Rock_Slate"
    },
    {
      "x": 1,
      "y": 1,
      "z": -5,
      "name": "Rock_Slate"
    },
    {
      "x": 1,
      "y": 2,
      "z": -5,
      "name": "Rock_Slate"
    },
    {
      "x": 1,
      "y": 3,
      "z": -5,
      "name": "Plant_Coral_Block_Violet"
    },
    {
      "x": 1,
      "y": 4,
      "z": -5,
      "name": "Plant_Coral_Block_Violet"
    },
    {
      "x": 1,
      "y": 5,
      "z": -5,
      "name": "Plant_Coral_Block_Violet"
    },
    {
      "x": 1,
      "y": 6,
      "z": -5,
      "name": "Plant_Coral_Block_Violet"
    },
    {
      "x": 1,
      "y": 7,
      "z": -5,
      "name": "Plant_Coral_Block_Violet"
    },
    {
      "x": 1,
      "y": 8,
      "z": -5,
      "name": "Plant_Coral_Block_Violet"
    },
    {
      "x": 1,
      "y": 16,
      "z": -5,
      "name": "Plant_Coral_Block_Violet"
    },
    {
      "x": 1,
      "y": 17,
      "z": -5,
      "name": "Plant_Coral_Block_Violet"
    },
    {
      "x": 1,
      "y": 18,
      "z": -5,
      "name": "Plant_Coral_Block_Violet"
    },
    {
      "x": 1,
      "y": 19,
      "z": -5,
      "name": "Plant_Coral_Block_Violet"
    },
    {
      "x": 1,
      "y": 20,
      "z": -5,
      "name": "Plant_Coral_Block_Violet"
    },
    {
      "x": 1,
      "y": 21,
      "z": -5,
      "name": "Plant_Coral_Block_Violet"
    },
    {
      "x": 1,
      "y": 0,
      "z": -4,
      "name": "Rock_Slate"
    },
    {
      "x": 1,
      "y": 1,
      "z": -4,
      "name": "Rock_Slate"
    },
    {
      "x": 1,
      "y": 2,
      "z": -4,
      "name": "Rock_Slate"
    },
    {
      "x": 1,
      "y": 3,
      "z": -4,
      "name": "Plant_Coral_Block_Violet"
    },
    {
      "x": 1,
      "y": 4,
      "z": -4,
      "name": "Plant_Coral_Block_Violet"
    },
    {
      "x": 1,
      "y": 5,
      "z": -4,
      "name": "Plant_Coral_Block_Violet"
    },
    {
      "x": 1,
      "y": 7,
      "z": -4,
      "name": "Plant_Coral_Block_Violet"
    },
    {
      "x": 1,
      "y": 8,
      "z": -4,
      "name": "Plant_Coral_Block_Violet"
    },
    {
      "x": 1,
      "y": 9,
      "z": -4,
      "name": "Plant_Coral_Block_Violet"
    },
    {
      "x": 1,
      "y": 13,
      "z": -4,
      "name": "Plant_Coral_Block_Violet"
    },
    {
      "x": 1,
      "y": 14,
      "z": -4,
      "name": "Plant_Coral_Block_Violet"
    },
    {
      "x": 1,
      "y": 15,
      "z": -4,
      "name": "Plant_Coral_Block_Violet"
    },
    {
      "x": 1,
      "y": 16,
      "z": -4,
      "name": "Rock_Slate"
    },
    {
      "x": 1,
      "y": 17,
      "z": -4,
      "name": "Rock_Slate"
    },
    {
      "x": 1,
      "y": 18,
      "z": -4,
      "name": "Rock_Slate"
    },
    {
      "x": 1,
      "y": 19,
      "z": -4,
      "name": "Rock_Slate"
    },
    {
      "x": 1,
      "y": 20,
      "z": -4,
      "name": "Rock_Slate"
    },
    {
      "x": 1,
      "y": 21,
      "z": -4,
      "name": "Rock_Slate"
    },
    {
      "x": 1,
      "y": 22,
      "z": -4,
      "name": "Plant_Coral_Block_Violet"
    },
    {
      "x": 1,
      "y": 23,
      "z": -4,
      "name": "Plant_Coral_Block_Violet"
    },
    {
      "x": 1,
      "y": 24,
      "z": -4,
      "name": "Plant_Coral_Block_Violet"
    },
    {
      "x": 1,
      "y": 25,
      "z": -4,
      "name": "Plant_Coral_Block_Violet"
    },
    {
      "x": 1,
      "y": 0,
      "z": -3,
      "name": "Plant_Coral_Block_Violet"
    },
    {
      "x": 1,
      "y": 1,
      "z": -3,
      "name": "Plant_Coral_Block_Violet"
    },
    {
      "x": 1,
      "y": 2,
      "z": -3,
      "name": "Plant_Coral_Block_Violet"
    },
    {
      "x": 1,
      "y": 4,
      "z": -3,
      "name": "Plant_Coral_Block_Violet"
    },
    {
      "x": 1,
      "y": 5,
      "z": -3,
      "name": "Plant_Coral_Block_Violet"
    },
    {
      "x": 1,
      "y": 6,
      "z": -3,
      "name": "Plant_Coral_Block_Violet"
    },
    {
      "x": 1,
      "y": 7,
      "z": -3,
      "name": "Rock_Slate"
    },
    {
      "x": 1,
      "y": 8,
      "z": -3,
      "name": "Rock_Slate"
    },
    {
      "x": 1,
      "y": 9,
      "z": -3,
      "name": "Rock_Slate"
    },
    {
      "x": 1,
      "y": 10,
      "z": -3,
      "name": "Plant_Coral_Block_Violet"
    },
    {
      "x": 1,
      "y": 11,
      "z": -3,
      "name": "Plant_Coral_Block_Violet"
    },
    {
      "x": 1,
      "y": 12,
      "z": -3,
      "name": "Plant_Coral_Block_Violet"
    },
    {
      "x": 1,
      "y": 13,
      "z": -3,
      "name": "Rock_Slate"
    },
    {
      "x": 1,
      "y": 14,
      "z": -3,
      "name": "Rock_Slate"
    },
    {
      "x": 1,
      "y": 15,
      "z": -3,
      "name": "Rock_Slate"
    },
    {
      "x": 1,
      "y": 16,
      "z": -3,
      "name": "Rock_Slate"
    },
    {
      "x": 1,
      "y": 17,
      "z": -3,
      "name": "Rock_Slate"
    },
    {
      "x": 1,
      "y": 18,
      "z": -3,
      "name": "Rock_Slate"
    },
    {
      "x": 1,
      "y": 19,
      "z": -3,
      "name": "Rock_Slate"
    },
    {
      "x": 1,
      "y": 20,
      "z": -3,
      "name": "Rock_Slate"
    },
    {
      "x": 1,
      "y": 21,
      "z": -3,
      "name": "Rock_Slate"
    },
    {
      "x": 1,
      "y": 22,
      "z": -3,
      "name": "Rock_Slate"
    },
    {
      "x": 1,
      "y": 23,
      "z": -3,
      "name": "Rock_Slate"
    },
    {
      "x": 1,
      "y": 0,
      "z": -2,
      "name": "Plant_Coral_Block_Violet"
    },
    {
      "x": 1,
      "y": 1,
      "z": -2,
      "name": "Plant_Coral_Block_Violet"
    },
    {
      "x": 1,
      "y": 2,
      "z": -2,
      "name": "Plant_Coral_Block_Violet"
    },
    {
      "x": 1,
      "y": 3,
      "z": -2,
      "name": "Plant_Coral_Block_Violet"
    },
    {
      "x": 1,
      "y": 4,
      "z": -2,
      "name": "Plant_Coral_Block_Violet"
    },
    {
      "x": 1,
      "y": 5,
      "z": -2,
      "name": "Plant_Coral_Block_Violet"
    },
    {
      "x": 1,
      "y": 6,
      "z": -2,
      "name": "Plant_Coral_Block_Violet"
    },
    {
      "x": 1,
      "y": 7,
      "z": -2,
      "name": "Rock_Slate"
    },
    {
      "x": 1,
      "y": 8,
      "z": -2,
      "name": "Rock_Slate"
    },
    {
      "x": 1,
      "y": 9,
      "z": -2,
      "name": "Rock_Slate"
    },
    {
      "x": 1,
      "y": 10,
      "z": -2,
      "name": "Rock_Slate"
    },
    {
      "x": 1,
      "y": 11,
      "z": -2,
      "name": "Rock_Slate"
    },
    {
      "x": 1,
      "y": 12,
      "z": -2,
      "name": "Rock_Slate"
    },
    {
      "x": 1,
      "y": 13,
      "z": -2,
      "name": "Rock_Slate"
    },
    {
      "x": 1,
      "y": 14,
      "z": -2,
      "name": "Rock_Slate"
    },
    {
      "x": 1,
      "y": 15,
      "z": -2,
      "name": "Rock_Slate"
    },
    {
      "x": 1,
      "y": 16,
      "z": -2,
      "name": "Rock_Slate"
    },
    {
      "x": 1,
      "y": 17,
      "z": -2,
      "name": "Rock_Slate"
    },
    {
      "x": 1,
      "y": 18,
      "z": -2,
      "name": "Rock_Slate"
    },
    {
      "x": 1,
      "y": 19,
      "z": -2,
      "name": "Rock_Slate"
    },
    {
      "x": 1,
      "y": 20,
      "z": -2,
      "name": "Rock_Slate"
    },
    {
      "x": 1,
      "y": 21,
      "z": -2,
      "name": "Rock_Slate"
    },
    {
      "x": 1,
      "y": 22,
      "z": -2,
      "name": "Rock_Slate"
    },
    {
      "x": 1,
      "y": 23,
      "z": -2,
      "name": "Rock_Slate"
    },
    {
      "x": 1,
      "y": 0,
      "z": -1,
      "name": "Plant_Coral_Block_Violet"
    },
    {
      "x": 1,
      "y": 1,
      "z": -1,
      "name": "Plant_Coral_Block_Violet"
    },
    {
      "x": 1,
      "y": 2,
      "z": -1,
      "name": "Plant_Coral_Block_Violet"
    },
    {
      "x": 1,
      "y": 3,
      "z": -1,
      "name": "Plant_Coral_Block_Violet"
    },
    {
      "x": 1,
      "y": 4,
      "z": -1,
      "name": "Plant_Coral_Block_Violet"
    },
    {
      "x": 1,
      "y": 5,
      "z": -1,
      "name": "Plant_Coral_Block_Violet"
    },
    {
      "x": 1,
      "y": 6,
      "z": -1,
      "name": "Plant_Coral_Block_Violet"
    },
    {
      "x": 1,
      "y": 7,
      "z": -1,
      "name": "Rock_Slate"
    },
    {
      "x": 1,
      "y": 8,
      "z": -1,
      "name": "Rock_Slate"
    },
    {
      "x": 1,
      "y": 9,
      "z": -1,
      "name": "Rock_Slate"
    },
    {
      "x": 1,
      "y": 10,
      "z": -1,
      "name": "Rock_Slate"
    },
    {
      "x": 1,
      "y": 11,
      "z": -1,
      "name": "Rock_Slate"
    },
    {
      "x": 1,
      "y": 12,
      "z": -1,
      "name": "Rock_Slate"
    },
    {
      "x": 1,
      "y": 13,
      "z": -1,
      "name": "Rock_Slate"
    },
    {
      "x": 1,
      "y": 14,
      "z": -1,
      "name": "Rock_Slate"
    },
    {
      "x": 1,
      "y": 15,
      "z": -1,
      "name": "Rock_Slate"
    },
    {
      "x": 1,
      "y": 16,
      "z": -1,
      "name": "Plant_Coral_Block_Violet"
    },
    {
      "x": 1,
      "y": 17,
      "z": -1,
      "name": "Plant_Coral_Block_Violet"
    },
    {
      "x": 1,
      "y": 18,
      "z": -1,
      "name": "Plant_Coral_Block_Violet"
    },
    {
      "x": 1,
      "y": 19,
      "z": -1,
      "name": "Plant_Coral_Block_Violet"
    },
    {
      "x": 1,
      "y": 20,
      "z": -1,
      "name": "Plant_Coral_Block_Violet"
    },
    {
      "x": 1,
      "y": 21,
      "z": -1,
      "name": "Plant_Coral_Block_Violet"
    },
    {
      "x": 1,
      "y": 22,
      "z": -1,
      "name": "Rock_Slate"
    },
    {
      "x": 1,
      "y": 0,
      "z": 0,
      "name": "Plant_Coral_Block_Violet"
    },
    {
      "x": 1,
      "y": 1,
      "z": 0,
      "name": "Plant_Coral_Block_Violet"
    },
    {
      "x": 1,
      "y": 2,
      "z": 0,
      "name": "Plant_Coral_Block_Violet"
    },
    {
      "x": 1,
      "y": 3,
      "z": 0,
      "name": "Plant_Coral_Block_Violet"
    },
    {
      "x": 1,
      "y": 7,
      "z": 0,
      "name": "Plant_Coral_Block_Violet"
    },
    {
      "x": 1,
      "y": 8,
      "z": 0,
      "name": "Plant_Coral_Block_Violet"
    },
    {
      "x": 1,
      "y": 9,
      "z": 0,
      "name": "Plant_Coral_Block_Violet"
    },
    {
      "x": 1,
      "y": 10,
      "z": 0,
      "name": "Rock_Slate"
    },
    {
      "x": 1,
      "y": 11,
      "z": 0,
      "name": "Rock_Slate"
    },
    {
      "x": 1,
      "y": 12,
      "z": 0,
      "name": "Rock_Slate"
    },
    {
      "x": 1,
      "y": 13,
      "z": 0,
      "name": "Plant_Coral_Block_Violet"
    },
    {
      "x": 1,
      "y": 14,
      "z": 0,
      "name": "Plant_Coral_Block_Violet"
    },
    {
      "x": 1,
      "y": 15,
      "z": 0,
      "name": "Plant_Coral_Block_Violet"
    },
    {
      "x": 1,
      "y": 16,
      "z": 0,
      "name": "Plant_Coral_Block_Violet"
    },
    {
      "x": 1,
      "y": 21,
      "z": 0,
      "name": "Plant_Coral_Block_Violet"
    },
    {
      "x": 1,
      "y": 22,
      "z": 0,
      "name": "Plant_Coral_Block_Violet"
    },
    {
      "x": 1,
      "y": 23,
      "z": 0,
      "name": "Plant_Coral_Block_Violet"
    },
    {
      "x": 1,
      "y": 24,
      "z": 0,
      "name": "Plant_Coral_Block_Violet"
    },
    {
      "x": 1,
      "y": 0,
      "z": 1,
      "name": "Plant_Coral_Block_Violet"
    },
    {
      "x": 1,
      "y": 1,
      "z": 1,
      "name": "Plant_Coral_Block_Violet"
    },
    {
      "x": 1,
      "y": 2,
      "z": 1,
      "name": "Plant_Coral_Block_Violet"
    },
    {
      "x": 1,
      "y": 3,
      "z": 1,
      "name": "Plant_Coral_Block_Violet"
    },
    {
      "x": 1,
      "y": 4,
      "z": 1,
      "name": "Plant_Coral_Block_Violet"
    },
    {
      "x": 1,
      "y": 5,
      "z": 1,
      "name": "Plant_Coral_Block_Violet"
    },
    {
      "x": 1,
      "y": 6,
      "z": 1,
      "name": "Plant_Coral_Block_Violet"
    },
    {
      "x": 1,
      "y": 7,
      "z": 1,
      "name": "Plant_Coral_Block_Violet"
    },
    {
      "x": 1,
      "y": 10,
      "z": 1,
      "name": "Plant_Coral_Block_Violet"
    },
    {
      "x": 1,
      "y": 11,
      "z": 1,
      "name": "Plant_Coral_Block_Violet"
    },
    {
      "x": 1,
      "y": 12,
      "z": 1,
      "name": "Plant_Coral_Block_Violet"
    },
    {
      "x": 1,
      "y": 13,
      "z": 1,
      "name": "Plant_Coral_Block_Violet"
    },
    {
      "x": 1,
      "y": 0,
      "z": 2,
      "name": "Rock_Slate"
    },
    {
      "x": 1,
      "y": 1,
      "z": 2,
      "name": "Rock_Slate"
    },
    {
      "x": 1,
      "y": 2,
      "z": 2,
      "name": "Rock_Slate"
    },
    {
      "x": 1,
      "y": 3,
      "z": 2,
      "name": "Rock_Slate"
    },
    {
      "x": 1,
      "y": 4,
      "z": 2,
      "name": "Rock_Slate"
    },
    {
      "x": 1,
      "y": 5,
      "z": 2,
      "name": "Rock_Slate"
    },
    {
      "x": 1,
      "y": 6,
      "z": 2,
      "name": "Rock_Slate"
    },
    {
      "x": 1,
      "y": 7,
      "z": 2,
      "name": "Rock_Slate"
    },
    {
      "x": 1,
      "y": 8,
      "z": 2,
      "name": "Plant_Coral_Block_Violet"
    },
    {
      "x": 1,
      "y": 9,
      "z": 2,
      "name": "Plant_Coral_Block_Violet"
    },
    {
      "x": 1,
      "y": 10,
      "z": 2,
      "name": "Plant_Coral_Block_Violet"
    },
    {
      "x": 1,
      "y": 0,
      "z": 3,
      "name": "Rock_Slate"
    },
    {
      "x": 1,
      "y": 1,
      "z": 3,
      "name": "Rock_Slate"
    },
    {
      "x": 1,
      "y": 2,
      "z": 3,
      "name": "Rock_Slate"
    },
    {
      "x": 1,
      "y": 3,
      "z": 3,
      "name": "Rock_Slate"
    },
    {
      "x": 1,
      "y": 4,
      "z": 3,
      "name": "Rock_Slate"
    },
    {
      "x": 1,
      "y": 5,
      "z": 3,
      "name": "Rock_Slate"
    },
    {
      "x": 1,
      "y": 6,
      "z": 3,
      "name": "Rock_Slate"
    },
    {
      "x": 1,
      "y": 7,
      "z": 3,
      "name": "Rock_Slate"
    },
    {
      "x": 1,
      "y": 8,
      "z": 3,
      "name": "Rock_Slate"
    },
    {
      "x": 1,
      "y": 9,
      "z": 3,
      "name": "Rock_Slate"
    },
    {
      "x": 1,
      "y": 10,
      "z": 3,
      "name": "Rock_Slate"
    },
    {
      "x": 1,
      "y": 11,
      "z": 3,
      "name": "Plant_Coral_Block_Violet"
    },
    {
      "x": 1,
      "y": 12,
      "z": 3,
      "name": "Plant_Coral_Block_Violet"
    },
    {
      "x": 1,
      "y": 13,
      "z": 3,
      "name": "Plant_Coral_Block_Violet"
    },
    {
      "x": 1,
      "y": 14,
      "z": 3,
      "name": "Plant_Coral_Block_Violet"
    },
    {
      "x": 1,
      "y": 0,
      "z": 4,
      "name": "Rock_Slate"
    },
    {
      "x": 1,
      "y": 1,
      "z": 4,
      "name": "Rock_Slate"
    },
    {
      "x": 1,
      "y": 2,
      "z": 4,
      "name": "Rock_Slate"
    },
    {
      "x": 1,
      "y": 3,
      "z": 4,
      "name": "Rock_Slate"
    },
    {
      "x": 1,
      "y": 4,
      "z": 4,
      "name": "Rock_Slate"
    },
    {
      "x": 1,
      "y": 5,
      "z": 4,
      "name": "Rock_Slate"
    },
    {
      "x": 1,
      "y": 6,
      "z": 4,
      "name": "Rock_Slate"
    },
    {
      "x": 1,
      "y": 7,
      "z": 4,
      "name": "Rock_Slate"
    },
    {
      "x": 1,
      "y": 8,
      "z": 4,
      "name": "Rock_Slate"
    },
    {
      "x": 1,
      "y": 9,
      "z": 4,
      "name": "Rock_Slate"
    },
    {
      "x": 1,
      "y": 10,
      "z": 4,
      "name": "Rock_Slate"
    },
    {
      "x": 1,
      "y": 11,
      "z": 4,
      "name": "Plant_Coral_Block_Violet"
    },
    {
      "x": 1,
      "y": 12,
      "z": 4,
      "name": "Plant_Coral_Block_Violet"
    },
    {
      "x": 1,
      "y": 13,
      "z": 4,
      "name": "Plant_Coral_Block_Violet"
    },
    {
      "x": 1,
      "y": 14,
      "z": 4,
      "name": "Plant_Coral_Block_Violet"
    },
    {
      "x": 1,
      "y": 0,
      "z": 5,
      "name": "Plant_Coral_Block_Violet"
    },
    {
      "x": 1,
      "y": 1,
      "z": 5,
      "name": "Plant_Coral_Block_Violet"
    },
    {
      "x": 1,
      "y": 2,
      "z": 5,
      "name": "Plant_Coral_Block_Violet"
    },
    {
      "x": 1,
      "y": 3,
      "z": 5,
      "name": "Plant_Coral_Block_Violet"
    },
    {
      "x": 1,
      "y": 4,
      "z": 5,
      "name": "Plant_Coral_Block_Violet"
    },
    {
      "x": 1,
      "y": 5,
      "z": 5,
      "name": "Plant_Coral_Block_Violet"
    },
    {
      "x": 1,
      "y": 6,
      "z": 5,
      "name": "Plant_Coral_Block_Violet"
    },
    {
      "x": 1,
      "y": 7,
      "z": 5,
      "name": "Plant_Coral_Block_Violet"
    },
    {
      "x": 1,
      "y": 8,
      "z": 5,
      "name": "Rock_Slate"
    },
    {
      "x": 1,
      "y": 9,
      "z": 5,
      "name": "Rock_Slate"
    },
    {
      "x": 1,
      "y": 10,
      "z": 5,
      "name": "Rock_Slate"
    },
    {
      "x": 1,
      "y": 11,
      "z": 5,
      "name": "Plant_Coral_Block_Violet"
    },
    {
      "x": 1,
      "y": 12,
      "z": 5,
      "name": "Plant_Coral_Block_Violet"
    },
    {
      "x": 1,
      "y": 13,
      "z": 5,
      "name": "Plant_Coral_Block_Violet"
    },
    {
      "x": 1,
      "y": 14,
      "z": 5,
      "name": "Plant_Coral_Block_Violet"
    },
    {
      "x": 1,
      "y": 7,
      "z": 6,
      "name": "Plant_Coral_Block_Violet"
    },
    {
      "x": 1,
      "y": 8,
      "z": 6,
      "name": "Plant_Coral_Block_Violet"
    },
    {
      "x": 1,
      "y": 9,
      "z": 6,
      "name": "Plant_Coral_Block_Violet"
    },
    {
      "x": 1,
      "y": 10,
      "z": 6,
      "name": "Plant_Coral_Block_Violet"
    },
    {
      "x": 2,
      "y": 5,
      "z": -8,
      "name": "Plant_Coral_Block_Violet"
    },
    {
      "x": 2,
      "y": 6,
      "z": -8,
      "name": "Plant_Coral_Block_Violet"
    },
    {
      "x": 2,
      "y": 7,
      "z": -8,
      "name": "Plant_Coral_Block_Violet"
    },
    {
      "x": 2,
      "y": 8,
      "z": -8,
      "name": "Plant_Coral_Block_Violet"
    },
    {
      "x": 2,
      "y": 0,
      "z": -7,
      "name": "Plant_Coral_Block_Violet"
    },
    {
      "x": 2,
      "y": 1,
      "z": -7,
      "name": "Plant_Coral_Block_Violet"
    },
    {
      "x": 2,
      "y": 2,
      "z": -7,
      "name": "Plant_Coral_Block_Violet"
    },
    {
      "x": 2,
      "y": 3,
      "z": -7,
      "name": "Plant_Coral_Block_Violet"
    },
    {
      "x": 2,
      "y": 4,
      "z": -7,
      "name": "Plant_Coral_Block_Violet"
    },
    {
      "x": 2,
      "y": 5,
      "z": -7,
      "name": "Plant_Coral_Block_Violet"
    },
    {
      "x": 2,
      "y": 6,
      "z": -7,
      "name": "Rock_Slate"
    },
    {
      "x": 2,
      "y": 7,
      "z": -7,
      "name": "Rock_Slate"
    },
    {
      "x": 2,
      "y": 8,
      "z": -7,
      "name": "Rock_Slate"
    },
    {
      "x": 2,
      "y": 9,
      "z": -7,
      "name": "Plant_Coral_Block_Violet"
    },
    {
      "x": 2,
      "y": 10,
      "z": -7,
      "name": "Plant_Coral_Block_Violet"
    },
    {
      "x": 2,
      "y": 11,
      "z": -7,
      "name": "Plant_Coral_Block_Violet"
    },
    {
      "x": 2,
      "y": 0,
      "z": -6,
      "name": "Rock_Slate"
    },
    {
      "x": 2,
      "y": 1,
      "z": -6,
      "name": "Rock_Slate"
    },
    {
      "x": 2,
      "y": 2,
      "z": -6,
      "name": "Rock_Slate"
    },
    {
      "x": 2,
      "y": 3,
      "z": -6,
      "name": "Rock_Slate"
    },
    {
      "x": 2,
      "y": 4,
      "z": -6,
      "name": "Rock_Slate"
    },
    {
      "x": 2,
      "y": 5,
      "z": -6,
      "name": "Rock_Slate"
    },
    {
      "x": 2,
      "y": 6,
      "z": -6,
      "name": "Rock_Slate"
    },
    {
      "x": 2,
      "y": 7,
      "z": -6,
      "name": "Rock_Slate"
    },
    {
      "x": 2,
      "y": 8,
      "z": -6,
      "name": "Rock_Slate"
    },
    {
      "x": 2,
      "y": 9,
      "z": -6,
      "name": "Plant_Coral_Block_Violet"
    },
    {
      "x": 2,
      "y": 10,
      "z": -6,
      "name": "Plant_Coral_Block_Violet"
    },
    {
      "x": 2,
      "y": 11,
      "z": -6,
      "name": "Plant_Coral_Block_Violet"
    },
    {
      "x": 2,
      "y": 12,
      "z": -6,
      "name": "Plant_Coral_Block_Violet"
    },
    {
      "x": 2,
      "y": 0,
      "z": -5,
      "name": "Rock_Slate"
    },
    {
      "x": 2,
      "y": 1,
      "z": -5,
      "name": "Rock_Slate"
    },
    {
      "x": 2,
      "y": 2,
      "z": -5,
      "name": "Rock_Slate"
    },
    {
      "x": 2,
      "y": 3,
      "z": -5,
      "name": "Rock_Slate"
    },
    {
      "x": 2,
      "y": 4,
      "z": -5,
      "name": "Rock_Slate"
    },
    {
      "x": 2,
      "y": 5,
      "z": -5,
      "name": "Rock_Slate"
    },
    {
      "x": 2,
      "y": 6,
      "z": -5,
      "name": "Rock_Slate"
    },
    {
      "x": 2,
      "y": 7,
      "z": -5,
      "name": "Rock_Slate"
    },
    {
      "x": 2,
      "y": 8,
      "z": -5,
      "name": "Rock_Slate"
    },
    {
      "x": 2,
      "y": 9,
      "z": -5,
      "name": "Plant_Coral_Block_Violet"
    },
    {
      "x": 2,
      "y": 10,
      "z": -5,
      "name": "Plant_Coral_Block_Violet"
    },
    {
      "x": 2,
      "y": 11,
      "z": -5,
      "name": "Plant_Coral_Block_Violet"
    },
    {
      "x": 2,
      "y": 12,
      "z": -5,
      "name": "Plant_Coral_Block_Violet"
    },
    {
      "x": 2,
      "y": 19,
      "z": -5,
      "name": "Plant_Coral_Block_Violet"
    },
    {
      "x": 2,
      "y": 20,
      "z": -5,
      "name": "Plant_Coral_Block_Violet"
    },
    {
      "x": 2,
      "y": 21,
      "z": -5,
      "name": "Plant_Coral_Block_Violet"
    },
    {
      "x": 2,
      "y": 0,
      "z": -4,
      "name": "Rock_Slate"
    },
    {
      "x": 2,
      "y": 1,
      "z": -4,
      "name": "Rock_Slate"
    },
    {
      "x": 2,
      "y": 2,
      "z": -4,
      "name": "Rock_Slate"
    },
    {
      "x": 2,
      "y": 3,
      "z": -4,
      "name": "Rock_Slate"
    },
    {
      "x": 2,
      "y": 4,
      "z": -4,
      "name": "Rock_Slate"
    },
    {
      "x": 2,
      "y": 5,
      "z": -4,
      "name": "Rock_Slate"
    },
    {
      "x": 2,
      "y": 6,
      "z": -4,
      "name": "Plant_Coral_Block_Violet"
    },
    {
